{"action": "update", "arg": {"instType": "SPOT", "channel": "books", "instId": "BTCUSDT"}, "data": [{"asks": [["84029.41", "0.967081"], ["84029.99", "0"], ["84084.91", "0.001837"], ["84145.40", "4.894387"], ["84153.90", "5.438208"], ["84162.40", "5.166297"], ["84170.90", "4.622477"], ["84179.40", "4.169293"], ["84187.90", "4.713114"], ["84196.40", "4.259930"], ["84204.90", "4.350566"], ["84213.40", "3.988019"], ["84221.90", "5.075661"], ["84230.40", "4.078656"], ["84238.90", "5.528845"], ["84247.40", "5.619481"], ["84255.90", "3.897382"], ["84264.40", "5.256934"], ["84281.40", "4.985024"], ["84289.90", "4.531840"], ["84298.40", "4.803750"], ["84306.90", "4.441203"]], "bids": [["84019.00", "0.012360"], ["84016.40", "0.009000"], ["84013.30", "0"], ["84007.80", "0"], ["83979.00", "0.000015"], ["83977.20", "5.256934"], ["83977.00", "0.000032"], ["83968.70", "5.438208"], ["83960.20", "4.894387"], ["83951.70", "5.166297"], ["83943.20", "4.713114"], ["83934.70", "4.078656"], ["83926.20", "5.075661"], ["83917.70", "4.169293"], ["83909.20", "5.528845"], ["83900.70", "4.441203"], ["83892.20", "4.622477"], ["83883.70", "3.988019"], ["83875.20", "4.531840"], ["83866.70", "5.619481"], ["83858.20", "4.803750"], ["83849.70", "4.350566"], ["83841.20", "3.897382"], ["83832.70", "5.347571"], ["83824.20", "4.985024"], ["83815.70", "4.259930"]], "checksum": -1116578869, "ts": "1742555355262"}], "ts": 1742555355266, "record_time": 1742555355.292913, "EXCHANGE": "BITGET"}
{"action": "update", "arg": {"instType": "SPOT", "channel": "books", "instId": "BTCUSDT"}, "data": [{"asks": [["84029.97", "0.088149"], ["84087.40", "0.003118"], ["84089.40", "0.008206"], ["84091.40", "0.021593"], ["84093.40", "0.056824"], ["84095.40", "0.149538"], ["84097.40", "0.393521"], ["84099.40", "1.035582"], ["84101.40", "2.725216"], ["84103.40", "7.171435"], ["84106.30", "0.034710"], ["84107.40", "0.071520"], ["84109.00", "0"], ["84111.70", "0.161250"], ["84111.80", "0"], ["84117.20", "0.107070"], ["84117.30", "2.674740"], ["84145.40", "5.347571"], ["84153.90", "4.169293"], ["84162.40", "4.803750"], ["84170.90", "5.256934"], ["84179.40", "4.259930"], ["84187.90", "5.528845"], ["84196.40", "4.531840"], ["84204.90", "4.713114"], ["84213.40", "4.441203"], ["84221.90", "4.985024"], ["84230.40", "3.897382"], ["84238.90", "3.988019"], ["84247.40", "5.075661"], ["84255.90", "4.894387"], ["84264.40", "5.166297"], ["84272.90", "4.078656"], ["84281.40", "4.622477"], ["84289.90", "5.438208"], ["84298.40", "4.350566"], ["84306.90", "5.619481"], ["84520.00", "0"], ["84520.50", "0"]], "bids": [["84029.20", "0.043308"], ["84027.20", "0.113967"], ["84025.20", "0.299914"], ["84023.20", "0.789248"], ["84021.20", "2.076967"], ["84019.20", "5.465703"], ["84019.00", "0.006060"], ["84007.80", "0.120000"], ["83968.70", "4.078656"], ["83960.20", "4.169293"], ["83951.70", "4.531840"], ["83943.20", "5.438208"], ["83934.70", "3.897382"], ["83926.20", "4.441203"], ["83917.70", "5.619481"], ["83909.20", "5.347571"], ["83900.70", "4.803750"], ["83892.20", "4.985024"], ["83875.20", "4.350566"], ["83866.70", "5.075661"], ["83858.20", "4.713114"], ["83849.70", "4.259930"], ["83841.20", "4.622477"], ["83832.70", "5.166297"], ["83824.20", "4.894387"], ["83815.70", "5.528845"], ["83659.49", "0"]], "checksum": 808424976, "ts": "1742555355475"}], "ts": 1742555355480, "record_time": 1742555355.517695, "EXCHANGE": "BITGET"}
{"action": "update", "arg": {"instType": "SPOT", "channel": "books", "instId": "BTCUSDT"}, "data": [{"asks": [["84029.41", "0.627081"], ["84085.40", "0.001108"], ["84087.40", "0.002792"], ["84089.40", "0.007346"], ["84091.40", "0.019332"], ["84093.40", "0.050873"], ["84095.40", "0.133878"], ["84097.40", "0.352309"], ["84099.40", "0.927131"], ["84101.40", "2.439817"], ["84103.40", "6.420571"], ["84103.80", "0.960090"], ["84105.00", "0.202830"], ["84107.00", "0.072900"], ["84107.40", "0"], ["84108.10", "0.067980"], ["84110.10", "0.067800"], ["84110.20", "0"], ["84112.20", "0"], ["84115.50", "0.045540"], ["84117.50", "0.070080"], ["84117.60", "0.534660"], ["84145.40", "4.169293"], ["84153.90", "4.078656"], ["84162.40", "4.622477"], ["84179.40", "3.988019"], ["84187.90", "3.897382"], ["84196.40", "4.441203"], ["84204.90", "4.350566"], ["84213.40", "5.528845"], ["84230.40", "4.803750"], ["84238.90", "4.894387"], ["84247.40", "5.619481"], ["84255.90", "4.531840"], ["84272.90", "5.438208"], ["84281.40", "4.713114"], ["84289.90", "5.347571"], ["84298.40", "5.075661"], ["84306.90", "4.259930"], ["84518.98", "0"]], "bids": [["84029.20", "0.070765"], ["84027.20", "0.186224"], ["84025.20", "0.490063"], ["84023.20", "1.289638"], ["84021.20", "3.393785"], ["84019.20", "8.931013"], ["84019.10", "0.435270"], ["84018.70", "0.813930"], ["84017.90", "0.068370"], ["84007.70", "0.120000"], ["83977.20", "4.441203"], ["83968.70", "4.350566"], ["83960.20", "4.713114"], ["83951.70", "5.528845"], ["83934.70", "5.256934"], ["83926.20", "4.078656"], ["83917.70", "5.075661"], ["83909.20", "3.897382"], ["83900.70", "4.985024"], ["83892.20", "5.619481"], ["83883.70", "4.169293"], ["83875.20", "3.988019"], ["83866.70", "4.259930"], ["83858.20", "4.531840"], ["83849.70", "4.894387"], ["83824.20", "4.803750"], ["83815.70", "5.347571"], ["83659.61", "0"]], "checksum": 941873220, "ts": "1742555355678"}], "ts": 1742555355685, "record_time": 1742555355.712962, "EXCHANGE": "BITGET"}
{"action": "update", "arg": {"instType": "SPOT", "channel": "books", "instId": "BTCUSDT"}, "data": [{"asks": [["84029.41", "0.627051"], ["84029.95", "0.088149"], ["84029.97", "0"], ["84059.21", "0.119867"], ["84062.45", "0"], ["84108.60", "0.217290"], ["84117.60", "0.609030"], ["84145.40", "5.438208"], ["84153.90", "3.988019"], ["84162.40", "4.169293"], ["84170.90", "4.531840"], ["84179.40", "4.803750"], ["84187.90", "4.622477"], ["84196.40", "5.166297"], ["84204.90", "5.075661"], ["84213.40", "5.347571"], ["84221.90", "4.259930"], ["84230.40", "5.256934"], ["84247.40", "3.897382"], ["84255.90", "5.619481"], ["84264.40", "4.713114"], ["84272.90", "4.985024"], ["84281.40", "4.441203"], ["84289.90", "4.078656"], ["84298.40", "4.350566"], ["84306.90", "5.528845"]], "bids": [["84015.10", "0"], ["84010.90", "0.071370"], ["84007.70", "0"], ["84001.95", "0"], ["83998.71", "0.259901"], ["83977.20", "4.803750"], ["83977.00", "0.000017"], ["83968.70", "5.528845"], ["83960.20", "5.256934"], ["83951.70", "5.075661"], ["83943.20", "4.985024"], ["83934.70", "4.259930"], ["83926.20", "4.531840"], ["83917.70", "4.622477"], ["83909.20", "5.619481"], ["83900.70", "4.078656"], ["83892.20", "5.347571"], ["83883.70", "5.438208"], ["83875.20", "3.897382"], ["83866.70", "4.350566"], ["83858.20", "4.441203"], ["83841.20", "5.166297"], ["83832.70", "4.713114"], ["83824.20", "4.169293"], ["83815.70", "3.988019"], ["83659.61", "0.000454"]], "checksum": 1714081262, "ts": "1742555355884"}], "ts": 1742555355886, "record_time": 1742555355.913123, "EXCHANGE": "BITGET"}
{"action": "update", "arg": {"instType": "SPOT", "channel": "books", "instId": "BTCUSDT"}, "data": [{"asks": [["84029.41", "0.967051"], ["84081.74", "0.753854"], ["84087.40", "0.002667"], ["84089.40", "0.007019"], ["84091.40", "0.018472"], ["84093.40", "0.048610"], ["84095.40", "0.127922"], ["84097.40", "0.336636"], ["84099.40", "0.885884"], ["84101.40", "2.331274"], ["84103.40", "6.135136"], ["84103.80", "1.208010"], ["84105.00", "0.203610"], ["84105.30", "0.918660"], ["84106.60", "0.034440"], ["84106.70", "0.056550"], ["84107.00", "0.072720"], ["84107.60", "0.015000"], ["84108.10", "0.067800"], ["84108.60", "0.217110"], ["84117.50", "0"], ["84117.60", "0"], ["84145.40", "4.350566"], ["84153.90", "5.619481"], ["84162.40", "3.897382"], ["84170.90", "4.713114"], ["84179.40", "4.894387"], ["84187.90", "4.441203"], ["84196.40", "5.347571"], ["84204.90", "4.078656"], ["84213.40", "4.985024"], ["84221.90", "4.803750"], ["84230.40", "5.528845"], ["84238.90", "5.256934"], ["84247.40", "5.166297"], ["84255.90", "4.622477"], ["84264.40", "3.988019"], ["84272.90", "4.531840"], ["84281.40", "5.438208"], ["84289.90", "4.169293"], ["84298.40", "4.259930"], ["84306.90", "5.075661"], ["84517.86", "0"]], "bids": [["84018.60", "2.356950"], ["84017.90", "0.068190"], ["84017.60", "0.035040"], ["84016.90", "0"], ["84016.40", "0"], ["84009.80", "0.153580"], ["84007.70", "0.120000"], ["83985.60", "0"], ["83980.30", "0.199851"], ["83978.00", "0"], ["83977.20", "5.528845"], ["83968.70", "5.347571"], ["83960.20", "3.897382"], ["83951.70", "5.256934"], ["83934.70", "5.619481"], ["83926.20", "5.075661"], ["83917.70", "4.259930"], ["83909.20", "4.622477"], ["83900.70", "4.894387"], ["83892.20", "5.166297"], ["83883.70", "4.713114"], ["83875.20", "4.078656"], ["83866.70", "4.803750"], ["83858.20", "4.350566"], ["83849.70", "4.531840"], ["83841.20", "4.441203"], ["83832.70", "4.169293"], ["83824.20", "5.438208"]], "checksum": -1861821494, "ts": "1742555356089"}], "ts": 1742555356094, "record_time": 1742555356.1304, "EXCHANGE": "BITGET"}
{"action": "update", "arg": {"instType": "SPOT", "channel": "books", "instId": "BTCUSDT"}, "data": [{"asks": [["84106.30", "0.022710"], ["84106.60", "0"], ["84106.70", "0.056730"], ["84107.00", "0.072900"], ["84107.60", "0.030000"], ["84108.10", "0.067980"], ["84108.60", "0.217290"], ["84116.40", "2.723370"], ["84117.50", "0.070080"], ["84117.60", "0.609030"], ["84145.40", "5.347571"], ["84153.90", "4.894387"], ["84162.40", "5.075661"], ["84170.90", "4.622477"], ["84179.40", "4.169293"], ["84187.90", "5.528845"], ["84196.40", "4.441203"], ["84204.90", "5.619481"], ["84213.40", "5.438208"], ["84221.90", "4.259930"], ["84230.40", "4.713114"], ["84238.90", "4.531840"], ["84247.40", "4.803750"], ["84255.90", "5.256934"], ["84264.40", "4.350566"], ["84272.90", "3.988019"], ["84281.40", "4.078656"], ["84289.90", "4.985024"], ["84298.40", "3.897382"], ["84306.90", "5.166297"], ["84517.54", "0"]], "bids": [["84029.20", "0.058698"], ["84027.52", "0.000019"], ["84027.20", "0.154468"], ["84026.34", "0"], ["84025.20", "0.406494"], ["84023.20", "1.069722"], ["84021.20", "2.815057"], ["84019.20", "7.408045"], ["83977.20", "5.256934"], ["83968.70", "5.528845"], ["83960.20", "4.894387"], ["83951.70", "4.713114"], ["83943.20", "3.988019"], ["83934.70", "4.803750"], ["83926.20", "4.259930"], ["83917.70", "5.347571"], ["83909.20", "4.985024"], ["83900.70", "5.438208"], ["83892.20", "4.350566"], ["83883.70", "4.622477"], ["83875.20", "4.169293"], ["83866.70", "5.075661"], ["83858.20", "3.897382"], ["83849.70", "5.166297"], ["83841.20", "4.078656"], ["83832.70", "4.441203"], ["83824.20", "4.531840"], ["83815.70", "5.619481"]], "checksum": -257220881, "ts": "1742555356305"}], "ts": 1742555356308, "record_time": 1742555356.335096, "EXCHANGE": "BITGET"}
{"action": "update", "arg": {"instType": "SPOT", "channel": "books", "instId": "BTCUSDT"}, "data": [{"asks": [["84029.42", "0.000117"], ["84029.93", "0.088149"], ["84029.95", "0"], ["84099.40", "0.886013"], ["84101.40", "2.331613"], ["84103.40", "6.135824"], ["84105.10", "0.025020"], ["84108.60", "0.217110"], ["84145.40", "5.619481"], ["84153.90", "4.259930"], ["84162.40", "5.438208"], ["84170.90", "4.894387"], ["84179.40", "5.256934"], ["84187.90", "4.622477"], ["84196.40", "5.528845"], ["84204.90", "3.897382"], ["84213.40", "4.441203"], ["84221.90", "3.988019"], ["84238.90", "4.985024"], ["84247.40", "5.166297"], ["84255.90", "5.075661"], ["84264.40", "4.531840"], ["84272.90", "4.803750"], ["84281.40", "4.169293"], ["84289.90", "4.350566"], ["84298.40", "4.078656"], ["84306.90", "5.347571"], ["84516.67", "0"]], "bids": [["84029.20", "0.065703"], ["84027.20", "0.172904"], ["84025.20", "0.455009"], ["84023.20", "1.197393"], ["84021.20", "3.151035"], ["84019.20", "8.292196"], ["83979.00", "0.000032"], ["83978.00", "0.000015"], ["83977.20", "5.528845"], ["83968.70", "4.622477"], ["83960.20", "4.259930"], ["83951.70", "5.166297"], ["83943.20", "5.347571"], ["83934.70", "4.713114"], ["83926.20", "3.988019"], ["83917.70", "5.619481"], ["83909.20", "3.897382"], ["83900.70", "5.256934"], ["83892.20", "4.169293"], ["83883.70", "5.438208"], ["83875.20", "4.894387"], ["83858.20", "4.078656"], ["83849.70", "4.803750"], ["83841.20", "4.441203"], ["83832.70", "4.350566"], ["83824.20", "4.985024"], ["83815.70", "4.531840"], ["83659.61", "0"]], "checksum": 1963444797, "ts": "1742555356520"}], "ts": 1742555356523, "record_time": 1742555356.549816, "EXCHANGE": "BITGET"}
{"action": "update", "arg": {"instType": "SPOT", "channel": "books", "instId": "BTCUSDT"}, "data": [{"asks": [["84087.40", "0.002784"], ["84089.40", "0.007325"], ["84091.40", "0.019277"], ["84093.40", "0.050729"], ["84095.40", "0.133498"], ["84097.40", "0.351311"], ["84099.40", "0.924501"], ["84101.40", "2.432897"], ["84103.40", "6.402362"], ["84105.10", "0"], ["84108.60", "0.217290"], ["84145.40", "5.347571"], ["84153.90", "3.897382"], ["84162.40", "4.894387"], ["84170.90", "4.350566"], ["84179.40", "5.619481"], ["84187.90", "4.803750"], ["84196.40", "4.078656"], ["84204.90", "3.988019"], ["84213.40", "4.985024"], ["84221.90", "4.531840"], ["84230.40", "4.259930"], ["84238.90", "5.075661"], ["84247.40", "4.169293"], ["84255.90", "5.528845"], ["84264.40", "4.622477"], ["84272.90", "5.438208"], ["84281.40", "4.713114"], ["84289.90", "5.166297"], ["84298.40", "4.441203"], ["84306.90", "5.256934"], ["84516.67", "0.000010"]], "bids": [["84029.20", "0.065957"], ["84027.20", "0.173571"], ["84025.20", "0.456767"], ["84023.20", "1.202018"], ["84021.20", "3.163206"], ["84019.20", "8.324225"], ["84004.90", "0"], ["83999.60", "0.000396"], ["83975.50", "0"], ["83968.70", "4.441203"], ["83960.20", "5.256934"], ["83951.70", "4.078656"], ["83943.20", "4.350566"], ["83934.70", "3.988019"], ["83926.20", "5.166297"], ["83917.70", "5.347571"], ["83909.20", "5.619481"], ["83900.70", "4.803750"], ["83892.20", "4.531840"], ["83883.70", "4.622477"], ["83875.20", "5.075661"], ["83866.70", "4.713114"], ["83858.20", "4.169293"], ["83849.70", "4.259930"], ["83841.20", "4.985024"], ["83832.70", "4.894387"], ["83824.20", "3.897382"], ["83815.70", "5.438208"], ["83659.61", "0.000454"]], "checksum": -1396130344, "ts": "1742555356721"}], "ts": 1742555356725, "record_time": 1742555356.752562, "EXCHANGE": "BITGET"}
{"action": "update", "arg": {"instType": "SPOT", "channel": "books", "instId": "BTCUSDT"}, "data": [{"asks": [["84029.91", "0.088149"], ["84029.93", "0"], ["84088.65", "0.010000"], ["84097.40", "0.351185"], ["84099.40", "0.924171"], ["84101.40", "2.432028"], ["84103.40", "6.400074"], ["84145.40", "5.256934"], ["84153.90", "4.622477"], ["84162.40", "4.350566"], ["84170.90", "4.713114"], ["84179.40", "5.347571"], ["84187.90", "3.897382"], ["84196.40", "4.985024"], ["84204.90", "4.259930"], ["84213.40", "5.075661"], ["84221.90", "5.438208"], ["84230.40", "5.166297"], ["84238.90", "4.441203"], ["84247.40", "5.528845"], ["84255.90", "4.894387"], ["84264.40", "4.169293"], ["84272.90", "5.619481"], ["84281.40", "3.988019"], ["84289.90", "4.078656"], ["84298.40", "4.803750"], ["84306.90", "4.531840"], ["84516.67", "0"]], "bids": [["84029.40", "1.041410"], ["83977.20", "3.988019"], ["83970.20", "0.000948"], ["83968.70", "4.713114"], ["83960.20", "4.985024"], ["83951.70", "4.894387"], ["83943.20", "4.622477"], ["83934.70", "4.259930"], ["83926.20", "5.256934"], ["83917.70", "4.441203"], ["83909.20", "3.897382"], ["83900.70", "4.078656"], ["83892.20", "5.347571"], ["83883.70", "5.528845"], ["83875.20", "5.438208"], ["83866.70", "4.169293"], ["83858.20", "4.803750"], ["83849.70", "5.619481"], ["83841.20", "5.166297"], ["83832.70", "4.350566"], ["83824.20", "5.075661"], ["83815.70", "4.531840"], ["83659.61", "0"]], "checksum": 1557809820, "ts": "1742555356924"}], "ts": 1742555356930, "record_time": 1742555356.955315, "EXCHANGE": "BITGET"}
{"action": "update", "arg": {"instType": "SPOT", "channel": "books", "instId": "BTCUSDT"}, "data": [{"asks": [["84075.66", "0.110505"], ["84101.40", "2.432141"], ["84103.40", "6.400372"], ["84105.20", "0.025440"], ["84106.69", "0"], ["84108.60", "0.217110"], ["84145.40", "3.897382"], ["84153.90", "4.894387"], ["84162.40", "4.713114"], ["84170.90", "4.985024"], ["84179.40", "4.622477"], ["84187.90", "4.078656"], ["84196.40", "4.259930"], ["84204.90", "5.166297"], ["84213.40", "4.350566"], ["84221.90", "4.531840"], ["84230.40", "5.619481"], ["84238.90", "5.075661"], ["84247.40", "5.438208"], ["84255.90", "4.169293"], ["84264.40", "5.528845"], ["84272.90", "5.347571"], ["84281.40", "4.441203"], ["84289.90", "3.988019"], ["84298.40", "5.256934"], ["84306.90", "4.803750"]], "bids": [["84007.82", "0"], ["84005.86", "0.004019"], ["83977.20", "4.259930"], ["83976.33", "0"], ["83973.61", "0.003598"], ["83968.70", "4.078656"], ["83960.20", "5.166297"], ["83951.70", "3.897382"], ["83943.20", "5.256934"], ["83934.70", "4.985024"], ["83926.20", "5.347571"], ["83917.70", "4.531840"], ["83909.20", "5.075661"], ["83900.70", "4.350566"], ["83892.20", "5.438208"], ["83883.70", "5.619481"], ["83875.20", "5.528845"], ["83866.70", "4.894387"], ["83858.20", "3.988019"], ["83849.70", "4.803750"], ["83841.20", "4.622477"], ["83832.70", "4.441203"], ["83824.20", "4.713114"], ["83815.70", "4.169293"]], "checksum": 1557809820, "ts": "1742555357126"}], "ts": 1742555357129, "record_time": 1742555357.15835, "EXCHANGE": "BITGET"}
{"action": "update", "arg": {"instType": "SPOT", "channel": "books", "instId": "BTCUSDT"}, "data": [{"asks": [["84029.42", "0.000100"], ["84103.40", "6.400186"], ["84105.20", "0"], ["84108.60", "0.217290"], ["84145.40", "4.713114"], ["84153.90", "5.438208"], ["84162.40", "5.528845"], ["84170.90", "4.078656"], ["84179.40", "4.894387"], ["84187.90", "4.259930"], ["84196.40", "5.166297"], ["84204.90", "3.988019"], ["84213.40", "4.531840"], ["84221.90", "5.075661"], ["84230.40", "5.347571"], ["84238.90", "4.622477"], ["84247.40", "5.619481"], ["84255.90", "4.441203"], ["84264.40", "4.350566"], ["84272.90", "4.985024"], ["84281.40", "4.803750"], ["84289.90", "5.256934"], ["84298.40", "4.169293"], ["84306.90", "3.897382"], ["84516.67", "0.000010"]], "bids": [["84029.20", "0.065222"], ["84027.20", "0.171636"], ["84025.20", "0.451674"], ["84023.20", "1.188616"], ["84021.20", "3.127937"], ["84019.20", "8.231411"], ["83977.20", "4.350566"], ["83977.00", "0"], ["83960.20", "5.347571"], ["83951.70", "3.988019"], ["83943.20", "4.531840"], ["83934.70", "3.897382"], ["83926.20", "5.256934"], ["83917.70", "4.985024"], ["83900.70", "4.441203"], ["83875.20", "4.713114"], ["83858.20", "4.169293"], ["83849.70", "5.166297"], ["83841.20", "4.259930"], ["83832.70", "4.622477"], ["83824.20", "5.528845"], ["83815.70", "4.803750"], ["83659.61", "0.000454"]], "checksum": -1216793052, "ts": "1742555357330"}], "ts": 1742555357334, "record_time": 1742555357.373794, "EXCHANGE": "BITGET"}
