{"action": "update", "arg": {"instType": "SPOT", "channel": "books", "instId": "BTCUSDT"}, "data": [{"asks": [["84290.66", "0.243265"], ["84291.21", "0"], ["84297.24", "0.139991"], ["84300.56", "0.029010"], ["84301.16", "0"], ["84322.22", "0.001807"], ["84324.83", "0"], ["84334.10", "0.001727"], ["84336.10", "0.004543"], ["84338.10", "0.011955"], ["84340.10", "0.031462"], ["84341.07", "0.031812"], ["84342.10", "0.083035"], ["84344.10", "0.218513"], ["84344.60", "0.001025"], ["84345.50", "0.001011"], ["84347.10", "0"], ["84347.40", "0.399690"], ["84348.20", "0"], ["84349.30", "0.219360"], ["84349.60", "0"], ["84350.20", "0.746160"], ["84351.50", "0"], ["84353.30", "0.081540"], ["84354.00", "0"], ["84354.60", "0.258030"], ["84354.70", "0.015150"], ["84355.00", "0.142500"], ["84355.50", "0.032910"], ["84355.80", "0.015120"], ["84356.10", "0.357810"], ["84356.40", "0"], ["84356.60", "0"], ["84357.20", "0"], ["84357.50", "0"], ["84360.00", "0.120000"], ["84360.40", "3.592380"], ["84386.30", "5.332311"], ["84394.80", "4.338151"], ["84403.30", "5.513067"], ["84411.80", "4.880420"], ["84420.30", "4.609286"], ["84428.80", "4.247773"], ["84437.30", "4.067017"], ["84445.80", "5.241933"], ["84454.30", "4.428529"], ["84462.80", "3.886261"], ["84471.30", "4.157395"], ["84479.80", "3.976639"], ["84488.30", "5.603445"], ["84496.80", "5.422689"], ["84505.30", "4.970798"], ["84513.80", "5.061176"], ["84522.30", "5.151555"], ["84530.80", "4.699664"], ["84547.80", "4.790042"], ["84866.40", "0"]], "bids": [["84290.65", "0.466828"], ["84288.78", "0.139991"], ["84279.74", "0.047500"], ["84279.73", "0.540371"], ["84277.70", "0.001309"], ["84277.19", "0"], ["84276.62", "0.003006"], ["84275.70", "0.003447"], ["84273.70", "0.009071"], ["84271.70", "0.023869"], ["84271.24", "0.192855"], ["84269.70", "0.062815"], ["84268.32", "0.003036"], ["84267.70", "0.165302"], ["84266.89", "0.247978"], ["84265.70", "0.435005"], ["84263.70", "1.144751"], ["84262.63", "0.007315"], ["84261.70", "3.012502"], ["84259.70", "7.927636"], ["84259.20", "0"], ["84258.90", "2.484930"], ["84258.80", "2.349090"], ["84258.50", "0.001005"], ["84258.30", "0.001014"], ["84258.00", "0.035580"], ["84256.50", "4.641420"], ["84255.60", "0"], ["84254.30", "0.525660"], ["84253.20", "0.915540"], ["84252.90", "0.035580"], ["84251.80", "0.069780"], ["84251.30", "0.410370"], ["84250.80", "0.383400"], ["84248.30", "0.038460"], ["84248.00", "1.515810"], ["84247.00", "0.035580"], ["84246.20", "0.441300"], ["84244.90", "0.177960"], ["84243.30", "0.090000"], ["84242.90", "0.597390"], ["84241.88", "0.061945"], ["84241.80", "0.083640"], ["84241.30", "0"], ["84241.20", "0"], ["84240.30", "0"], ["84239.60", "0"], ["84239.30", "0"], ["84239.20", "0"], ["84238.60", "0"], ["84238.40", "0"], ["84238.20", "0"], ["84237.80", "0"], ["84217.50", "4.338151"], ["84209.00", "4.880420"], ["84200.50", "3.976639"], ["84192.00", "4.247773"], ["84183.50", "5.603445"], ["84175.00", "4.067017"], ["84166.50", "4.609286"], ["84158.00", "4.790042"], ["84149.50", "5.151555"], ["84141.00", "4.699664"], ["84132.50", "4.428529"], ["84124.00", "3.886261"], ["84115.50", "4.157395"], ["84107.00", "5.513067"], ["84098.50", "4.970798"], ["84090.00", "4.518908"], ["84073.00", "5.422689"], ["84064.50", "5.332311"], ["84056.00", "5.061176"], ["84034.53", "0"], ["83894.17", "0"]], "checksum": -1221467860, "ts": "1742142233372"}], "ts": 1742142233376, "record_time": 1742142232.484026}
{"action": "update", "arg": {"instType": "SPOT", "channel": "books", "instId": "BTCUSDT"}, "data": [{"asks": [["84296.10", "0"], ["84304.95", "0.003017"], ["84305.65", "0"], ["84306.24", "0"], ["84306.53", "0"], ["84307.13", "0"], ["84307.22", "0"], ["84307.73", "0.317619"], ["84308.07", "0"], ["84308.34", "0"], ["84308.59", "0"], ["84309.42", "0.035952"], ["84309.59", "0"], ["84310.17", "0"], ["84310.42", "0"], ["84311.58", "0.057076"], ["84311.59", "0"], ["84313.00", "0"], ["84313.06", "0"], ["84314.51", "0.006356"], ["84314.56", "0.006356"], ["84315.29", "0"], ["84315.38", "0.006356"], ["84315.80", "0.016427"], ["84316.14", "0.016428"], ["84316.82", "0.006356"], ["84317.34", "0.119843"], ["84317.46", "0"], ["84317.54", "0.010984"], ["84317.78", "0"], ["84318.31", "0.035964"], ["84318.33", "0.012713"], ["84319.38", "0.009989"], ["84319.63", "0.119895"], ["84320.79", "0.119879"], ["84321.74", "0.009989"], ["84321.92", "0.015892"], ["84324.20", "0.006356"], ["84326.21", "0.015891"], ["84326.62", "0.010986"], ["84334.10", "0.001417"], ["84336.10", "0.003729"], ["84338.10", "0.009812"], ["84340.10", "0.025822"], ["84342.10", "0.067952"], ["84344.10", "0.178820"], ["84344.70", "0.010350"], ["84345.10", "0.001710"], ["84349.30", "0"], ["84350.20", "0"], ["84352.50", "3.195420"], ["84353.30", "0"], ["84356.10", "0.195720"], ["84357.60", "0"], ["84359.70", "0.469080"], ["84360.00", "0.002000"], ["84360.40", "3.532380"], ["84360.80", "0.013860"], ["84361.50", "2.669430"], ["84386.30", "5.241933"], ["84394.80", "4.970798"], ["84403.30", "4.428529"], ["84411.80", "5.151555"], ["84420.30", "3.976639"], ["84428.80", "4.067017"], ["84437.30", "4.609286"], ["84445.80", "5.513067"], ["84454.30", "4.880420"], ["84462.80", "4.338151"], ["84471.30", "5.603445"], ["84479.80", "5.422689"], ["84488.30", "4.790042"], ["84496.80", "3.886261"], ["84505.30", "4.518908"], ["84513.80", "5.332311"], ["84522.30", "4.699664"], ["84530.80", "5.061176"], ["84539.30", "4.247773"], ["84547.80", "4.157395"], ["84864.69", "0"], ["84864.86", "0"], ["84864.99", "0"], ["84866.10", "0"]], "bids": [["84290.65", "0.670463"], ["84289.72", "0.568563"], ["84287.93", "0.055144"], ["84283.95", "0.062760"], ["84279.74", "0.145566"], ["84279.73", "0.268921"], ["84277.70", "0.001460"], ["84275.70", "0.003842"], ["84273.71", "0.013401"], ["84273.70", "0.010111"], ["84272.51", "0"], ["84271.70", "0.026609"], ["84269.70", "0.070023"], ["84268.20", "0.015770"], ["84267.83", "0.016459"], ["84267.75", "0.005937"], ["84267.70", "0.184270"], ["84267.03", "0.007119"], ["84266.99", "0.017077"], ["84266.80", "0.006564"], ["84266.41", "0.028805"], ["84266.08", "0.008987"], ["84265.93", "0.227652"], ["84265.70", "0.484922"], ["84265.66", "0.007932"], ["84264.79", "0.017330"], ["84264.55", "0.008282"], ["84264.39", "0.025082"], ["84263.70", "1.275984"], ["84263.54", "0.012648"], ["84263.22", "0"], ["84262.90", "0.018518"], ["84262.75", "0.052103"], ["84261.70", "3.357851"], ["84261.30", "0.271876"], ["84260.72", "0.076006"], ["84260.44", "0.222711"], ["84260.20", "0.021106"], ["84259.70", "8.836451"], ["84259.49", "0"], ["84259.30", "0"], ["84258.99", "0"], ["84258.62", "0.012438"], ["84258.60", "0.915540"], ["84258.54", "0"], ["84258.15", "0"], ["84258.13", "0"], ["84257.80", "0.212100"], ["84257.49", "0"], ["84257.33", "0"], ["84257.18", "0"], ["84257.09", "0.073499"], ["84256.76", "0"], ["84256.53", "0"], ["84255.82", "0.056634"], ["84255.71", "0"], ["84254.64", "0"], ["84254.30", "0.366060"], ["84254.06", "0"], ["84253.56", "0"], ["84253.20", "0"], ["84252.40", "0.090000"], ["84252.10", "0"], ["84251.81", "0"], ["84251.80", "0.069600"], ["84251.53", "0"], ["84251.24", "0"], ["84249.72", "0"], ["84248.35", "0"], ["84248.00", "0.104490"], ["84247.20", "0.269760"], ["84246.98", "0"], ["84243.10", "0.090000"], ["84241.88", "0"], ["84241.80", "0"], ["84241.50", "0"], ["84217.50", "4.518908"], ["84200.50", "4.428529"], ["84192.00", "5.332311"], ["84183.50", "4.338151"], ["84175.00", "3.976639"], ["84169.00", "0.012717"], ["84166.50", "5.241933"], ["84158.00", "5.151555"], ["84149.50", "4.067017"], ["84141.00", "5.513067"], ["84132.50", "4.609286"], ["84124.00", "4.247773"], ["84115.50", "4.970798"], ["84107.00", "4.790042"], ["84098.50", "3.886261"], ["84090.00", "5.061176"], ["84081.50", "4.699664"], ["84064.50", "4.157395"], ["84056.00", "5.603445"], ["83895.00", "0"], ["83894.74", "0"]], "checksum": -2055311083, "ts": "1742142233575"}], "ts": 1742142233579, "record_time": 1742142232.688034}
{"action": "update", "arg": {"instType": "SPOT", "channel": "books", "instId": "BTCUSDT"}, "data": [{"asks": [["84290.66", "0.307076"], ["84300.56", "0"], ["84307.63", "0"], ["84307.73", "0.233685"], ["84311.58", "0"], ["84319.53", "0.017795"], ["84320.59", "0.669340"], ["84332.78", "0.012680"], ["84334.10", "0.001041"], ["84336.10", "0.001613"], ["84338.10", "0.004245"], ["84340.10", "0.011171"], ["84342.10", "0.029396"], ["84344.10", "0.077357"], ["84344.70", "0"], ["84344.90", "0.021330"], ["84352.50", "3.195810"], ["84354.50", "0.637530"], ["84356.10", "0.183210"], ["84361.40", "0.142500"], ["84386.30", "4.067017"], ["84394.80", "5.513067"], ["84403.30", "5.332311"], ["84411.80", "4.790042"], ["84420.30", "5.603445"], ["84428.80", "4.247773"], ["84437.30", "5.241933"], ["84445.80", "5.422689"], ["84454.30", "4.699664"], ["84462.80", "5.061176"], ["84471.30", "4.157395"], ["84479.80", "3.886261"], ["84488.30", "4.609286"], ["84496.80", "5.151555"], ["84505.30", "3.976639"], ["84513.80", "4.970798"], ["84522.30", "4.518908"], ["84530.80", "4.880420"], ["84539.30", "4.338151"], ["84547.80", "4.428529"], ["84860.00", "0"], ["84862.90", "0"]], "bids": [["84290.65", "1.023595"], ["84279.75", "0.030926"], ["84279.74", "0.047500"], ["84272.86", "0.754217"], ["84266.64", "0"], ["84263.70", "1.275849"], ["84261.70", "3.357498"], ["84259.70", "8.835521"], ["84257.80", "0.212280"], ["84253.20", "0.090000"], ["84253.10", "0.090000"], ["84251.50", "0.090000"], ["84250.50", "0.090000"], ["84249.80", "0.090000"], ["84248.90", "0.090000"], ["84248.80", "0.090000"], ["84248.20", "0.090000"], ["84248.10", "0.009180"], ["84248.00", "0.206340"], ["84246.50", "0.090000"], ["84243.50", "0"], ["84243.30", "0"], ["84243.10", "0"], ["84242.90", "0"], ["84242.00", "0"], ["84217.50", "5.332311"], ["84209.00", "4.790042"], ["84200.50", "4.609286"], ["84192.00", "5.151555"], ["84175.00", "4.880420"], ["84166.50", "4.518908"], ["84158.00", "3.976639"], ["84149.50", "5.603445"], ["84141.00", "4.699664"], ["84132.50", "4.428529"], ["84124.00", "5.061176"], ["84115.50", "5.513067"], ["84107.00", "5.241933"], ["84090.00", "4.247773"], ["84081.50", "4.157395"], ["84064.50", "4.970798"], ["84056.00", "4.067017"], ["83899.58", "0"], ["83898.68", "0"], ["83896.11", "0"], ["83896.00", "0"], ["83895.65", "0"]], "checksum": 549537159, "ts": "1742142233777"}], "ts": 1742142233780, "record_time": 1742142232.889043}
{"action": "update", "arg": {"instType": "SPOT", "channel": "books", "instId": "BTCUSDT"}, "data": [{"asks": [["84290.66", "0.203170"], ["84290.70", "0"], ["84290.71", "0"], ["84290.72", "0"], ["84290.73", "0"], ["84290.78", "0"], ["84290.81", "0"], ["84291.65", "0"], ["84291.66", "0"], ["84291.67", "0"], ["84291.68", "0"], ["84291.70", "0"], ["84291.71", "0"], ["84291.72", "0"], ["84291.75", "0"], ["84296.65", "0.004595"], ["84296.70", "0.008962"], ["84296.72", "0.001230"], ["84296.73", "0.004974"], ["84297.65", "0.000078"], ["84297.67", "0.007955"], ["84297.68", "0.007385"], ["84297.70", "0.015631"], ["84297.75", "0.004739"], ["84297.98", "0.005541"], ["84298.00", "0.010074"], ["84298.03", "0.000245"], ["84298.06", "0.006307"], ["84298.12", "0.001066"], ["84298.81", "0.009191"], ["84298.88", "0.008506"], ["84298.94", "0.004830"], ["84298.99", "0.005626"], ["84303.15", "0"], ["84309.26", "0"], ["84310.01", "0"], ["84312.12", "0.017161"], ["84315.95", "0.209200"], ["84323.32", "0.148098"], ["84324.10", "0"], ["84326.10", "0"], ["84328.10", "0"], ["84328.30", "0.001017"], ["84330.10", "0"], ["84330.30", "0.001009"], ["84332.10", "0"], ["84332.30", "0.001033"], ["84334.10", "0"], ["84334.30", "0.001044"], ["84336.10", "0"], ["84336.30", "0.001045"], ["84338.10", "0"], ["84338.30", "0.001007"], ["84340.10", "0"], ["84340.30", "0.001044"], ["84342.10", "0"], ["84342.30", "0.001533"], ["84344.10", "0"], ["84344.30", "0.004190"], ["84344.60", "0"], ["84344.90", "0"], ["84345.00", "0"], ["84345.10", "0"], ["84345.50", "0"], ["84346.30", "0.011026"], ["84346.90", "0"], ["84347.00", "0"], ["84347.40", "0"], ["84348.30", "0.029016"], ["84348.50", "0.038730"], ["84350.20", "0.001350"], ["84350.50", "0.001045"], ["84352.00", "0.001008"], ["84352.50", "0"], ["84354.50", "0"], ["84354.60", "0"], ["84354.70", "0"], ["84355.00", "0"], ["84355.50", "0"], ["84355.80", "0"], ["84358.30", "0.032910"], ["84359.70", "0.727110"], ["84361.10", "0.015090"], ["84361.90", "0.015150"], ["84362.20", "0.078210"], ["84362.60", "0.410370"], ["84363.00", "0.288000"], ["84363.70", "0.383400"], ["84386.30", "0"], ["84390.40", "4.157190"], ["84394.80", "0"], ["84398.90", "5.332048"], ["84403.30", "0"], ["84407.40", "5.422421"], ["84411.80", "0"], ["84415.90", "4.880179"], ["84420.30", "0"], ["84424.40", "3.886069"], ["84428.80", "0"], ["84432.90", "4.699432"], ["84437.30", "0"], ["84441.40", "5.603169"], ["84445.80", "0"], ["84449.90", "5.241674"], ["84454.30", "0"], ["84458.40", "4.247564"], ["84462.80", "0"], ["84466.90", "5.151300"], ["84471.30", "0"], ["84475.40", "4.518685"], ["84479.80", "0"], ["84483.90", "4.428311"], ["84488.30", "0"], ["84492.40", "5.060927"], ["84496.80", "0"], ["84500.90", "5.512795"], ["84505.30", "0"], ["84509.40", "4.789806"], ["84513.80", "0"], ["84517.90", "4.337937"], ["84522.30", "0"], ["84526.40", "4.970553"], ["84530.80", "0"], ["84534.90", "3.976442"], ["84539.30", "0"], ["84543.40", "4.609058"], ["84547.80", "0"], ["84551.90", "4.066816"], ["84860.00", "0.000169"], ["84862.90", "0.000169"]], "bids": [["84283.80", "0.001039"], ["84281.80", "0.001000"], ["84279.80", "0.002121"], ["84279.70", "0"], ["84277.80", "0.005582"], ["84277.70", "0"], ["84276.62", "0"], ["84275.80", "0.014690"], ["84275.70", "0"], ["84273.80", "0.038658"], ["84273.70", "0"], ["84272.56", "0.001230"], ["84272.55", "0.008539"], ["84272.47", "0.007515"], ["84271.80", "0.101731"], ["84271.70", "0"], ["84271.24", "0"], ["84271.21", "0.007646"], ["84271.08", "0.007346"], ["84270.94", "0.006213"], ["84270.89", "0.007443"], ["84270.87", "0.006540"], ["84270.77", "0.001199"], ["84270.14", "0.008147"], ["84269.80", "0.267714"], ["84269.70", "0"], ["84269.64", "0.008988"], ["84269.58", "0.008556"], ["84268.78", "0.002064"], ["84268.70", "0.007873"], ["84268.51", "0.007475"], ["84268.32", "0"], ["84267.80", "0.704509"], ["84267.70", "0"], ["84267.26", "0.007953"], ["84266.90", "0.068536"], ["84265.80", "1.853972"], ["84265.70", "0"], ["84265.42", "0.005552"], ["84265.35", "0.000875"], ["84265.34", "0.005089"], ["84265.31", "0"], ["84265.30", "0"], ["84265.27", "0.008156"], ["84265.26", "0"], ["84265.22", "0"], ["84265.20", "0"], ["84264.58", "0.002949"], ["84264.10", "0.004935"], ["84264.00", "0.009635"], ["84263.80", "4.878873"], ["84263.79", "0"], ["84263.70", "0"], ["84263.68", "0"], ["84263.63", "0.056356"], ["84263.61", "0"], ["84263.60", "0.001024"], ["84263.53", "0"], ["84263.30", "0.001045"], ["84263.00", "2.348970"], ["84262.86", "0"], ["84262.70", "0.001012"], ["84262.50", "0.968220"], ["84262.38", "0.010235"], ["84261.80", "0.069780"], ["84261.70", "0"], ["84261.60", "0"], ["84261.58", "0"], ["84261.25", "0"], ["84261.23", "0"], ["84260.90", "0.035580"], ["84260.60", "0.177960"], ["84260.10", "0.018030"], ["84259.70", "2.344470"], ["84258.90", "0"], ["84258.80", "0"], ["84258.60", "2.085180"], ["84258.50", "0"], ["84258.30", "0"], ["84258.16", "0"], ["84258.14", "0"], ["84258.09", "0"], ["84258.01", "0"], ["84258.00", "0"], ["84257.80", "0.212100"], ["84256.60", "0"], ["84256.50", "1.350360"], ["84256.41", "0"], ["84255.80", "0.105180"], ["84254.30", "1.564380"], ["84253.60", "0.177960"], ["84252.90", "0"], ["84251.20", "0.038460"], ["84250.50", "3.784380"], ["84249.90", "0.035580"], ["84248.70", "0.177960"], ["84248.30", "0"], ["84248.20", "0"], ["84248.10", "0"], ["84248.00", "0"], ["84247.80", "0"], ["84247.20", "0"], ["84247.00", "0"], ["84246.77", "0.008208"], ["84246.50", "0"], ["84246.35", "0.017794"], ["84246.20", "0"], ["84245.80", "0"], ["84245.00", "0"], ["84244.90", "0"], ["84242.21", "0.007186"], ["84240.88", "0.007585"], ["84239.52", "0"], ["84234.97", "0"], ["84234.92", "0"], ["84234.49", "0"], ["84221.70", "3.976442"], ["84217.50", "0"], ["84213.20", "5.512795"], ["84209.00", "0"], ["84204.70", "5.060927"], ["84200.50", "0"], ["84196.20", "5.332048"], ["84192.00", "0"], ["84187.70", "4.066816"], ["84183.50", "0"], ["84179.20", "4.337937"], ["84175.00", "0"], ["84170.70", "4.699432"], ["84166.50", "0"], ["84162.20", "4.157190"], ["84158.00", "0"], ["84153.70", "5.241674"], ["84149.50", "0"], ["84145.20", "5.603169"], ["84141.00", "0"], ["84136.70", "4.880179"], ["84132.50", "0"], ["84128.20", "3.886069"], ["84124.00", "0"], ["84119.70", "4.247564"], ["84115.50", "0"], ["84111.20", "4.428311"], ["84107.00", "0"], ["84102.70", "5.151300"], ["84098.50", "0"], ["84094.20", "5.422421"], ["84090.00", "0"], ["84085.70", "4.789806"], ["84081.50", "0"], ["84077.20", "4.609058"], ["84073.00", "0"], ["84068.70", "4.518685"], ["84064.50", "0"], ["84060.20", "4.970553"], ["84056.00", "0"], ["84032.00", "0"], ["83899.58", "0.000010"], ["83898.68", "0.000010"], ["83896.11", "0.000094"], ["83896.00", "0.000133"]], "checksum": 1573211547, "ts": "1742142233980"}], "ts": 1742142233983, "record_time": 1742142233.092553}
{"action": "update", "arg": {"instType": "SPOT", "channel": "books", "instId": "BTCUSDT"}, "data": [{"asks": [["84291.14", "0"], ["84296.19", "0.063806"], ["84296.65", "0"], ["84296.70", "0"], ["84296.72", "0"], ["84296.73", "0"], ["84297.24", "0"], ["84297.65", "0"], ["84297.67", "0"], ["84297.68", "0"], ["84297.70", "0"], ["84297.75", "0"], ["84298.81", "0"], ["84298.94", "0.009550"], ["84300.57", "0"], ["84303.73", "0.569696"], ["84303.74", "0"], ["84305.58", "0.080082"], ["84306.13", "0"], ["84307.73", "0"], ["84308.19", "0"], ["84309.38", "0"], ["84309.42", "0"], ["84309.65", "0"], ["84309.82", "0"], ["84310.92", "0"], ["84311.50", "0"], ["84311.91", "0.001205"], ["84312.13", "0"], ["84312.36", "0"], ["84312.77", "0"], ["84312.79", "0"], ["84312.93", "0"], ["84313.76", "0.119869"], ["84314.99", "0.035952"], ["84315.36", "0.006356"], ["84316.45", "0.006356"], ["84316.54", "0.010985"], ["84317.93", "0.006356"], ["84318.46", "0.006356"], ["84320.60", "0"], ["84322.22", "0"], ["84323.18", "0.075300"], ["84327.16", "0.001807"], ["84342.30", "0.001021"], ["84344.30", "0.001014"], ["84346.30", "0.001032"], ["84348.30", "0.002716"], ["84348.80", "0.001001"], ["84351.40", "0.001011"], ["84352.00", "0"], ["84352.30", "0.393570"], ["84354.00", "0.249600"], ["84354.10", "0.821760"], ["84358.10", "0.258030"], ["84359.70", "0.469080"], ["84361.10", "0"], ["84362.60", "0"], ["84363.70", "0"], ["84366.83", "0"], ["84390.40", "5.151300"], ["84398.90", "4.066816"], ["84407.40", "3.886069"], ["84415.90", "4.247564"], ["84424.40", "4.428311"], ["84432.90", "5.241674"], ["84441.40", "5.332048"], ["84449.90", "5.512795"], ["84458.40", "4.970553"], ["84466.90", "4.518685"], ["84475.40", "5.603169"], ["84483.90", "5.060927"], ["84492.40", "4.609058"], ["84500.90", "4.880179"], ["84509.40", "4.157190"], ["84523.39", "0"], ["84526.40", "4.789806"], ["84543.40", "5.422421"], ["84551.90", "4.699432"], ["84566.67", "0.031835"], ["84864.69", "0.000052"], ["84864.86", "0.000041"], ["84864.99", "0.000033"], ["84866.10", "0.000064"], ["84866.40", "0.000018"], ["84867.80", "0.000095"], ["84868.42", "0.000031"], ["84868.52", "0.000013"], ["84868.65", "0.000035"], ["84869.57", "0.000932"], ["84871.66", "0.000078"], ["84871.79", "0.000014"], ["84873.84", "0.000057"], ["84874.79", "0.000096"], ["84875.00", "0.000959"], ["84875.78", "0.000038"]], "bids": [["84290.65", "1.078737"], ["84287.93", "0"], ["84279.80", "0.002760"], ["84277.80", "0.007265"], ["84275.80", "0.019118"], ["84274.42", "0.003069"], ["84273.81", "0.022277"], ["84273.80", "0.050311"], ["84273.71", "0"], ["84272.53", "0.006490"], ["84272.45", "0.247978"], ["84271.80", "0.132395"], ["84271.21", "0"], ["84271.16", "0.084431"], ["84269.80", "0.348409"], ["84269.64", "0"], ["84269.58", "0"], ["84268.67", "0.056349"], ["84268.20", "0.023085"], ["84267.80", "0.916865"], ["84267.26", "0"], ["84266.89", "0"], ["84265.80", "2.412803"], ["84265.59", "0"], ["84264.98", "0"], ["84264.37", "0"], ["84264.10", "0"], ["84264.00", "0"], ["84263.86", "0"], ["84263.82", "0.008676"], ["84263.80", "6.349482"], ["84263.63", "0"], ["84263.30", "0"], ["84263.00", "2.349390"], ["84262.87", "0"], ["84262.63", "0"], ["84262.50", "0.602670"], ["84262.38", "0"], ["84261.02", "0"], ["84259.70", "4.913400"], ["84259.20", "0.462780"], ["84256.50", "1.760730"], ["84254.10", "0.023737"], ["84251.30", "0"], ["84250.50", "4.033260"], ["84240.88", "0"], ["84239.67", "0"], ["84221.70", "4.428311"], ["84213.20", "5.332048"], ["84204.70", "5.512795"], ["84196.20", "4.880179"], ["84187.70", "5.422421"], ["84179.20", "3.886069"], ["84170.70", "3.976442"], ["84162.20", "4.970553"], ["84153.70", "4.789806"], ["84145.20", "5.151300"], ["84136.70", "4.247564"], ["84128.20", "5.603169"], ["84119.70", "5.060927"], ["84111.20", "4.157190"], ["84102.70", "4.609058"], ["84094.20", "5.241674"], ["84085.70", "4.518685"], ["84077.20", "4.337937"], ["84068.70", "4.066816"], ["84060.20", "4.699432"], ["83895.65", "0.000013"], ["83895.00", "0.006121"], ["83894.74", "0.000068"], ["83894.17", "0.000022"], ["83893.81", "0.000010"], ["83893.64", "0.000039"], ["83893.62", "0.000137"], ["83892.29", "0.000143"], ["83891.43", "0.000455"], ["83891.30", "0.000010"], ["83888.89", "0.000163"], ["83888.86", "0.000371"], ["83887.29", "0.000586"]], "checksum": 967468180, "ts": "1742142234181"}], "ts": 1742142234186, "record_time": 1742142233.294562}
{"action": "update", "arg": {"instType": "SPOT", "channel": "books", "instId": "BTCUSDT"}, "data": [{"asks": [["84301.96", "0.004595"], ["84302.01", "0.008962"], ["84302.05", "0.001230"], ["84302.98", "0.000078"], ["84303.00", "0.007385"], ["84303.01", "0.147927"], ["84303.02", "0.001162"], ["84303.04", "0.007359"], ["84303.07", "0.004739"], ["84303.73", "0.024930"], ["84307.52", "0.209200"], ["84308.35", "0.002907"], ["84316.43", "0.006356"], ["84316.70", "0.006356"], ["84319.31", "0.006356"], ["84319.47", "0.006356"], ["84319.82", "0.006356"], ["84320.26", "0.006356"], ["84320.59", "0"], ["84328.30", "0"], ["84330.30", "0"], ["84338.30", "0.002282"], ["84340.30", "0.006006"], ["84342.30", "0.015805"], ["84344.30", "0.041591"], ["84346.30", "0.109451"], ["84348.30", "0.288030"], ["84348.50", "0"], ["84348.80", "0"], ["84350.20", "0"], ["84350.30", "0.757972"], ["84350.50", "0"], ["84351.40", "0"], ["84352.30", "1.994664"], ["84353.10", "0.001012"], ["84353.40", "0.001012"], ["84353.90", "0.001009"], ["84354.00", "0.326220"], ["84354.10", "0.821940"], ["84358.30", "0"], ["84360.40", "1.865760"], ["84361.50", "0"], ["84361.90", "0"], ["84364.10", "0.985470"], ["84364.30", "4.634220"], ["84364.80", "0.117000"], ["84365.00", "0.035550"], ["84365.10", "1.350000"], ["84365.60", "0.180000"], ["84390.40", "0"], ["84394.50", "4.789574"], ["84398.90", "0"], ["84403.00", "3.976250"], ["84407.40", "0"], ["84411.50", "5.422160"], ["84415.90", "0"], ["84420.00", "4.970313"], ["84424.40", "0"], ["84428.50", "4.518466"], ["84432.90", "0"], ["84437.00", "4.337728"], ["84441.40", "0"], ["84445.50", "4.428097"], ["84449.90", "0"], ["84451.13", "0.209200"], ["84454.00", "3.885881"], ["84458.40", "0"], ["84462.50", "5.512529"], ["84466.90", "0"], ["84471.00", "5.602898"], ["84475.40", "0"], ["84479.50", "4.699205"], ["84483.90", "0"], ["84488.00", "5.060682"], ["84492.40", "0"], ["84496.50", "5.331790"], ["84500.90", "0"], ["84505.00", "5.151052"], ["84509.40", "0"], ["84513.50", "4.066620"], ["84517.90", "0"], ["84522.00", "4.879944"], ["84526.40", "0"], ["84530.50", "5.241421"], ["84534.90", "0"], ["84539.00", "4.156989"], ["84543.40", "0"], ["84547.50", "4.608836"], ["84551.90", "0"], ["84556.00", "4.247358"], ["84864.86", "0"], ["84864.99", "0"], ["84866.10", "0"], ["84866.40", "0"], ["84867.80", "0"], ["84868.42", "0"], ["84868.52", "0"], ["84868.65", "0"], ["84869.57", "0"], ["84871.66", "0"], ["84871.79", "0"], ["84873.84", "0"], ["84874.79", "0"], ["84875.00", "0"], ["84875.78", "0"]], "bids": [["84287.90", "0.001011"], ["84285.90", "0.001007"], ["84284.18", "0.003006"], ["84283.90", "0.002593"], ["84283.80", "0"], ["84281.90", "0.006826"], ["84281.80", "0"], ["84280.62", "0.313274"], ["84279.90", "0.017839"], ["84279.80", "0"], ["84279.75", "0.016430"], ["84277.90", "0.046944"], ["84277.80", "0"], ["84276.50", "0.007646"], ["84275.90", "0.123537"], ["84275.80", "0"], ["84274.91", "0.008988"], ["84274.88", "0.008556"], ["84274.21", "0.189653"], ["84273.90", "0.325098"], ["84273.80", "0"], ["84272.57", "0.007953"], ["84272.47", "0.007728"], ["84272.02", "0.017834"], ["84271.90", "0.855521"], ["84271.80", "0"], ["84271.42", "0.018259"], ["84269.90", "2.251370"], ["84269.80", "0"], ["84269.30", "0.009635"], ["84269.24", "0.017060"], ["84268.06", "0.008164"], ["84267.90", "5.924658"], ["84267.80", "0"], ["84267.68", "0.010234"], ["84266.20", "0.036000"], ["84266.10", "0.001000"], ["84265.80", "0"], ["84264.70", "0.275010"], ["84264.40", "0.001040"], ["84264.20", "0.142500"], ["84263.90", "0.806370"], ["84263.80", "1.422660"], ["84263.60", "0"], ["84263.00", "4.778070"], ["84262.70", "0"], ["84262.50", "0"], ["84261.80", "0.069600"], ["84260.60", "0.177780"], ["84259.70", "4.745250"], ["84259.20", "0.462600"], ["84258.60", "1.679670"], ["84256.50", "1.775520"], ["84251.40", "0"], ["84251.20", "0"], ["84250.80", "0"], ["84250.50", "0"], ["84249.90", "0"], ["84249.80", "0"], ["84248.90", "0"], ["84248.80", "0"], ["84248.70", "0"], ["84246.15", "0.007585"], ["84225.70", "4.066620"], ["84221.70", "0"], ["84217.20", "5.060682"], ["84213.20", "0"], ["84208.70", "4.247358"], ["84204.70", "0"], ["84200.20", "5.422160"], ["84196.20", "0"], ["84191.70", "4.970313"], ["84187.70", "0"], ["84183.20", "4.699205"], ["84179.20", "0"], ["84174.70", "4.518466"], ["84170.70", "0"], ["84168.00", "0.000121"], ["84166.20", "4.156989"], ["84162.20", "0"], ["84157.70", "4.337728"], ["84153.70", "0"], ["84149.20", "4.879944"], ["84145.20", "0"], ["84140.70", "5.241421"], ["84136.70", "0"], ["84132.20", "4.608836"], ["84128.20", "0"], ["84123.70", "3.976250"], ["84119.70", "0"], ["84115.20", "5.512529"], ["84111.20", "0"], ["84106.70", "5.151052"], ["84102.70", "0"], ["84098.20", "4.428097"], ["84094.20", "0"], ["84089.70", "3.885881"], ["84085.70", "0"], ["84081.20", "4.789574"], ["84077.20", "0"], ["84072.70", "5.331790"], ["84068.70", "0"], ["84064.20", "5.602898"], ["84060.20", "0"], ["83894.17", "0"], ["83893.81", "0"], ["83893.64", "0"], ["83893.62", "0"], ["83892.29", "0"], ["83891.43", "0"], ["83891.30", "0"], ["83888.89", "0"], ["83888.86", "0"], ["83887.29", "0"]], "checksum": 729386036, "ts": "1742142234383"}], "ts": 1742142234386, "record_time": 1742142233.494711}
{"action": "update", "arg": {"instType": "SPOT", "channel": "books", "instId": "BTCUSDT"}, "data": [{"asks": [["84302.06", "0.004974"], ["84302.54", "0.030015"], ["84303.00", "0.080671"], ["84303.04", "0.014469"], ["84303.06", "0.009191"], ["84303.73", "0"], ["84315.14", "1.894531"], ["84332.01", "2.229559"], ["84342.30", "0.015990"], ["84344.30", "0.042078"], ["84346.30", "0.110732"], ["84348.30", "0.291400"], ["84350.30", "0.766843"], ["84352.30", "2.018007"], ["84352.80", "0.886140"], ["84352.90", "0.675600"], ["84354.00", "0"], ["84354.10", "0"], ["84354.70", "2.348580"], ["84357.10", "0.258030"], ["84358.10", "0"], ["84358.20", "0.076650"], ["84363.60", "0.032910"], ["84364.30", "6.413520"], ["84365.00", "0"], ["84365.10", "0"], ["84365.60", "0"], ["84394.50", "4.156989"], ["84403.00", "4.789574"], ["84411.50", "5.241421"], ["84420.00", "5.331790"], ["84428.50", "4.608836"], ["84437.00", "4.970313"], ["84445.50", "3.885881"], ["84454.00", "4.518466"], ["84462.50", "3.976250"], ["84471.00", "5.060682"], ["84479.50", "4.428097"], ["84488.00", "4.699205"], ["84496.50", "5.602898"], ["84522.00", "5.422160"], ["84530.50", "4.337728"], ["84539.00", "4.247358"], ["84547.50", "4.879944"], ["84556.00", "5.512529"], ["84862.90", "0"], ["84864.69", "0"]], "bids": [["84285.90", "0.001114"], ["84283.90", "0.002900"], ["84281.90", "0.007632"], ["84280.63", "0.143593"], ["84279.90", "0.020299"], ["84279.75", "0"], ["84277.90", "0.053419"], ["84276.15", "0.003036"], ["84275.90", "0.140574"], ["84274.21", "0"], ["84273.90", "0.369934"], ["84273.81", "0"], ["84271.90", "0.973510"], ["84269.90", "2.561867"], ["84269.39", "0.004935"], ["84267.90", "6.741756"], ["84264.60", "0.276930"], ["84264.50", "0.707610"], ["84264.40", "0"], ["84263.90", "0"], ["84263.80", "0"], ["84259.70", "4.681560"], ["84256.60", "0.038460"], ["84253.10", "0.267960"], ["84251.80", "0"], ["84251.50", "0"], ["84246.08", "0"], ["84225.70", "4.156989"], ["84217.20", "5.331790"], ["84208.70", "4.970313"], ["84200.20", "4.337728"], ["84191.70", "3.976250"], ["84183.20", "5.060682"], ["84174.70", "3.885881"], ["84172.21", "0"], ["84166.20", "4.608836"], ["84157.70", "5.151052"], ["84149.20", "4.789574"], ["84140.70", "4.428097"], ["84132.20", "4.247358"], ["84123.70", "4.879944"], ["84115.20", "4.066620"], ["84106.70", "5.512529"], ["84098.20", "5.241421"], ["84089.70", "4.699205"], ["84081.20", "5.422160"], ["84072.70", "4.518466"], ["83894.17", "0.000022"], ["83893.81", "0.000010"], ["83893.64", "0.000039"], ["83893.62", "0.000137"]], "checksum": 669382920, "ts": "1742142234586"}], "ts": 1742142234590, "record_time": 1742142233.697705}
{"action": "update", "arg": {"instType": "SPOT", "channel": "books", "instId": "BTCUSDT"}, "data": [{"asks": [["84296.01", "0.063807"], ["84296.19", "0"], ["84307.51", "0.157623"], ["84341.07", "0"], ["84352.30", "2.018267"], ["84355.00", "0.142500"], ["84356.40", "0.258030"], ["84357.10", "0.197885"], ["84364.80", "0"], ["84394.50", "4.970313"], ["84403.00", "4.428097"], ["84411.50", "5.602898"], ["84420.00", "4.879944"], ["84428.50", "4.699205"], ["84437.00", "3.976250"], ["84445.50", "4.337728"], ["84454.00", "4.156989"], ["84462.50", "5.331790"], ["84471.00", "5.422160"], ["84479.50", "4.518466"], ["84488.00", "5.060682"], ["84496.50", "4.247358"], ["84505.00", "4.789574"], ["84513.50", "3.885881"], ["84522.00", "5.241421"], ["84530.50", "5.512529"], ["84539.00", "4.066620"], ["84547.50", "4.608836"], ["84556.00", "5.151052"], ["84860.00", "0"]], "bids": [["84290.65", "0.869537"], ["84275.91", "0.170016"], ["84272.86", "0"], ["84267.90", "6.742016"], ["84266.20", "0.036420"], ["84225.70", "5.241421"], ["84217.20", "5.602898"], ["84208.70", "4.247358"], ["84204.01", "0.057629"], ["84200.20", "4.879944"], ["84191.70", "5.422160"], ["84183.20", "4.518466"], ["84166.20", "4.156989"], ["84157.70", "4.337728"], ["84149.20", "4.066620"], ["84140.70", "4.699205"], ["84132.20", "5.151052"], ["84123.70", "4.970313"], ["84115.20", "4.428097"], ["84106.70", "3.976250"], ["84098.20", "5.512529"], ["84089.70", "5.331790"], ["84081.20", "4.608836"], ["84072.70", "4.789574"], ["84064.20", "5.060682"], ["84047.49", "0"]], "checksum": -1558739514, "ts": "1742142234786"}], "ts": 1742142234794, "record_time": 1742142233.902207}
{"action": "update", "arg": {"instType": "SPOT", "channel": "books", "instId": "BTCUSDT"}, "data": [{"asks": [["84298.98", "0.022206"], ["84323.32", "0"], ["84328.08", "0.031812"], ["84336.30", "0.001092"], ["84338.30", "0.002875"], ["84340.30", "0.007566"], ["84342.30", "0.019909"], ["84344.30", "0.052392"], ["84346.30", "0.138062"], ["84348.30", "0.363322"], ["84350.30", "0.956109"], ["84352.30", "2.516078"], ["84352.70", "0.270180"], ["84352.80", "0.886320"], ["84352.90", "0.675780"], ["84353.40", "0"], ["84353.90", "0"], ["84354.70", "2.348760"], ["84356.40", "0"], ["84357.80", "0.269760"], ["84359.10", "0.031290"], ["84361.70", "0.410370"], ["84364.30", "6.662400"], ["84394.50", "4.428097"], ["84403.00", "3.885881"], ["84411.50", "4.789574"], ["84420.00", "5.422160"], ["84428.50", "4.156989"], ["84437.00", "4.879944"], ["84445.50", "4.518466"], ["84451.13", "0"], ["84454.00", "5.060682"], ["84462.50", "4.337728"], ["84471.00", "4.970313"], ["84479.50", "4.608836"], ["84488.00", "5.331790"], ["84496.50", "5.602898"], ["84505.00", "5.241421"], ["84513.50", "5.512529"], ["84522.00", "5.151052"], ["84530.50", "3.976250"], ["84539.00", "4.247358"], ["84547.50", "4.699205"], ["84556.00", "4.066620"], ["84859.29", "0"]], "bids": [["84290.65", "0.612087"], ["84289.72", "0.000164"], ["84288.78", "0"], ["84285.90", "0.001004"], ["84284.40", "0.191832"], ["84283.95", "0"], ["84283.94", "0"], ["84283.90", "0.001030"], ["84281.90", "0.001075"], ["84279.90", "0.002828"], ["84277.90", "0.007444"], ["84275.90", "0.019590"], ["84273.90", "0.051551"], ["84272.86", "0.553471"], ["84271.90", "0.135662"], ["84269.90", "0.357005"], ["84267.90", "0.939486"], ["84266.20", "0.035460"], ["84264.70", "0.001014"], ["84264.60", "0.277320"], ["84264.20", "0"], ["84263.00", "0.581670"], ["84261.80", "0"], ["84260.90", "0.310170"], ["84260.10", "0"], ["84259.70", "0"], ["84259.50", "0.009000"], ["84259.20", "0.462780"], ["84258.60", "1.282380"], ["84257.80", "0.142500"], ["84256.50", "0.015150"], ["84251.80", "0.069600"], ["84251.50", "0.090000"], ["84251.40", "0.142500"], ["84251.00", "1.350000"], ["84250.80", "0.383400"], ["84250.60", "0.987180"], ["84250.50", "3.784380"], ["84225.70", "4.156989"], ["84217.20", "3.885881"], ["84208.70", "5.422160"], ["84200.20", "4.066620"], ["84191.70", "4.518466"], ["84183.20", "4.608836"], ["84174.70", "5.512529"], ["84166.20", "3.976250"], ["84157.70", "4.970313"], ["84149.20", "5.331790"], ["84140.70", "4.247358"], ["84132.20", "4.879944"], ["84123.70", "4.337728"], ["84115.20", "5.060682"], ["84106.70", "5.241421"], ["84106.37", "0.175023"], ["84098.20", "5.151052"], ["84089.70", "4.428097"], ["84081.20", "4.699205"], ["84072.70", "5.602898"], ["84064.20", "4.789574"], ["83894.17", "0"], ["83893.81", "0"], ["83893.64", "0"], ["83893.62", "0"]], "checksum": -378382197, "ts": "1742142234989"}], "ts": 1742142234993, "record_time": 1742142234.101701}
{"action": "update", "arg": {"instType": "SPOT", "channel": "books", "instId": "BTCUSDT"}, "data": [{"asks": [["84290.66", "0.746909"], ["84296.00", "0.026112"], ["84296.01", "0"], ["84320.76", "0.148098"], ["84329.86", "0.010000"], ["84330.80", "0.001004"], ["84332.30", "0"], ["84332.80", "0.001165"], ["84334.30", "0"], ["84334.80", "0.002957"], ["84336.30", "0"], ["84336.80", "0.007781"], ["84338.30", "0"], ["84338.45", "0.027943"], ["84338.80", "0.020477"], ["84340.30", "0"], ["84340.80", "0.053887"], ["84342.30", "0"], ["84342.80", "0.141808"], ["84344.30", "0"], ["84344.80", "0.373178"], ["84346.30", "0"], ["84346.80", "0.982048"], ["84348.30", "0"], ["84348.80", "2.584337"], ["84350.30", "0"], ["84350.80", "6.800885"], ["84352.20", "0.070410"], ["84352.30", "10.882860"], ["84352.70", "0.269940"], ["84352.80", "0"], ["84352.90", "0"], ["84353.10", "0"], ["84353.50", "0.985650"], ["84354.00", "0.035850"], ["84354.20", "0.076830"], ["84354.70", "0.249060"], ["84356.00", "0.410370"], ["84356.10", "0.624990"], ["84357.40", "1.779300"], ["84359.70", "0"], ["84361.70", "0"], ["84362.30", "0.015180"], ["84362.70", "0.015120"], ["84362.80", "1.075560"], ["84364.10", "0"], ["84364.30", "0"], ["84393.00", "5.602999"], ["84394.50", "0"], ["84401.50", "4.337806"], ["84403.00", "0"], ["84410.00", "5.060774"], ["84411.50", "0"], ["84418.50", "3.976322"], ["84420.00", "0.002000"], ["84427.00", "4.789661"], ["84428.50", "0"], ["84435.50", "4.608919"], ["84437.00", "0"], ["84444.00", "5.512628"], ["84445.50", "0"], ["84452.50", "4.247435"], ["84454.00", "0"], ["84461.00", "5.241515"], ["84462.50", "0"], ["84469.50", "4.518548"], ["84471.00", "0"], ["84478.00", "4.880032"], ["84479.50", "0"], ["84486.50", "5.422257"], ["84488.00", "0.000532"], ["84495.00", "4.066693"], ["84496.50", "0"], ["84503.50", "4.699290"], ["84505.00", "0"], ["84512.00", "4.970403"], ["84513.50", "0"], ["84520.50", "5.151145"], ["84522.00", "0"], ["84529.00", "4.428177"], ["84530.50", "0"], ["84537.50", "5.331886"], ["84539.00", "0"], ["84546.00", "3.885951"], ["84547.50", "0"], ["84554.50", "4.157064"], ["84556.00", "0"], ["84850.00", "0"], ["84851.66", "0"], ["84852.81", "0"], ["84852.94", "0"], ["84853.56", "0"], ["84857.14", "0"], ["84858.75", "0"]], "bids": [["84290.65", "0.623735"], ["84289.72", "0.391786"], ["84287.90", "0"], ["84286.40", "0.001046"], ["84285.90", "0"], ["84284.59", "0.139967"], ["84284.41", "0.059083"], ["84284.18", "0"], ["84283.90", "0"], ["84282.40", "0.001031"], ["84282.22", "0.010000"], ["84281.90", "0"], ["84280.40", "0.001267"], ["84280.13", "0.000070"], ["84279.90", "0"], ["84278.40", "0.003335"], ["84277.90", "0"], ["84276.40", "0.008931"], ["84276.15", "0"], ["84275.91", "0"], ["84275.90", "0"], ["84274.40", "0.023502"], ["84273.90", "0"], ["84272.40", "0.061849"], ["84271.90", "0"], ["84270.40", "0.162759"], ["84269.90", "0"], ["84268.80", "0"], ["84268.40", "0.428314"], ["84267.90", "0"], ["84266.40", "1.127141"], ["84266.20", "0"], ["84266.10", "0"], ["84265.67", "0.013638"], ["84264.70", "0"], ["84264.60", "0.001019"], ["84264.50", "0.001028"], ["84264.40", "0.001034"], ["84263.40", "0.097860"], ["84263.00", "0"], ["84260.90", "0.035580"], ["84260.60", "0"], ["84259.70", "0.052260"], ["84259.20", "0"], ["84258.60", "0"], ["84257.80", "0.202890"], ["84255.80", "0"], ["84254.30", "0"], ["84253.70", "0.035580"], ["84253.60", "0"], ["84253.20", "0"], ["84253.10", "0"], ["84251.80", "0.302490"], ["84251.00", "0"], ["84250.60", "0"], ["84250.50", "0.090000"], ["84249.50", "0.180660"], ["84249.00", "0.780810"], ["84248.80", "0.915360"], ["84248.20", "0.090000"], ["84248.10", "0.009180"], ["84248.00", "0.056010"], ["84247.80", "0.069600"], ["84246.50", "0.090000"], ["84246.20", "0.458130"], ["84245.00", "0.142500"], ["84237.65", "0"], ["84225.70", "0"], ["84224.20", "5.422257"], ["84217.20", "0"], ["84215.70", "4.428177"], ["84208.70", "0"], ["84207.20", "5.060774"], ["84200.20", "0"], ["84198.70", "5.331886"], ["84191.70", "0"], ["84190.20", "3.976322"], ["84183.20", "0"], ["84181.70", "5.241515"], ["84174.70", "0"], ["84173.20", "4.157064"], ["84167.00", "0"], ["84166.20", "0"], ["84164.70", "4.970403"], ["84157.70", "0"], ["84156.20", "4.608919"], ["84149.20", "0"], ["84147.70", "5.151145"], ["84140.70", "0"], ["84139.20", "5.602999"], ["84132.20", "0"], ["84130.70", "4.247435"], ["84123.70", "0"], ["84122.20", "4.337806"], ["84115.20", "0"], ["84113.70", "4.880032"], ["84106.70", "0"], ["84105.20", "5.512628"], ["84098.20", "0"], ["84096.70", "4.518548"], ["84089.70", "0"], ["84088.20", "4.789661"], ["84081.20", "0"], ["84079.70", "4.699290"], ["84072.70", "0"], ["84071.20", "4.066693"], ["84064.20", "0"], ["84062.70", "3.885951"], ["83894.17", "0.000022"], ["83893.81", "0.000010"]], "checksum": -1584045301, "ts": "1742142235192"}], "ts": 1742142235196, "record_time": 1742142234.304666}
{"action": "update", "arg": {"instType": "SPOT", "channel": "books", "instId": "BTCUSDT"}, "data": [{"asks": [["84294.32", "0.063808"], ["84296.00", "0.006970"], ["84299.09", "0.209200"], ["84301.96", "0"], ["84302.01", "0"], ["84302.05", "0"], ["84302.06", "0"], ["84302.98", "0"], ["84303.00", "0.073286"], ["84303.01", "0"], ["84303.02", "0"], ["84303.04", "0"], ["84303.06", "0"], ["84303.07", "0"], ["84305.58", "0"], ["84313.76", "0"], ["84314.99", "0"], ["84316.43", "0"], ["84316.54", "0"], ["84316.70", "0"], ["84319.31", "0"], ["84319.82", "0"], ["84320.26", "0"], ["84325.30", "0.001046"], ["84327.16", "0"], ["84327.30", "0.001036"], ["84329.30", "0.002058"], ["84330.80", "0"], ["84331.30", "0.005417"], ["84332.80", "0"], ["84333.30", "0.014256"], ["84334.80", "0"], ["84335.30", "0.037516"], ["84336.80", "0"], ["84337.30", "0.098725"], ["84338.80", "0"], ["84339.30", "0.259804"], ["84340.80", "0"], ["84341.30", "0.683694"], ["84342.80", "0"], ["84343.30", "1.799195"], ["84344.80", "0"], ["84345.30", "4.734723"], ["84346.20", "0.142440"], ["84346.70", "1.779480"], ["84346.80", "0"], ["84347.20", "0.052830"], ["84348.00", "12.247710"], ["84348.20", "0.069780"], ["84348.30", "1.079220"], ["84348.50", "0.052830"], ["84348.60", "0.142680"], ["84348.80", "0"], ["84348.90", "0.052830"], ["84349.00", "0.319770"], ["84349.50", "0.052830"], ["84350.20", "0.069600"], ["84350.80", "2.832030"], ["84350.90", "0.410370"], ["84352.00", "0.035580"], ["84352.20", "0.069600"], ["84352.30", "8.337840"], ["84352.70", "0.269760"], ["84353.50", "0.985470"], ["84354.00", "0"], ["84354.20", "0.076650"], ["84354.70", "0.248880"], ["84356.00", "0"], ["84357.80", "0"], ["84357.90", "0.035580"], ["84358.90", "0.015180"], ["84359.10", "0"], ["84359.40", "0.015120"], ["84360.40", "0"], ["84360.80", "0"], ["84361.40", "0"], ["84362.20", "0"], ["84362.30", "0"], ["84362.70", "0"], ["84362.80", "0"], ["84363.00", "0"], ["84363.60", "0"], ["84387.50", "4.789973"], ["84393.00", "0"], ["84396.00", "5.151481"], ["84401.50", "0"], ["84404.50", "3.886205"], ["84410.00", "0"], ["84413.00", "4.699596"], ["84418.50", "0"], ["84421.50", "5.061104"], ["84427.00", "0"], ["84430.00", "5.422611"], ["84435.50", "0"], ["84438.50", "4.338089"], ["84444.00", "0"], ["84447.00", "4.066958"], ["84452.50", "0"], ["84455.50", "5.332234"], ["84461.00", "0"], ["84464.00", "4.157335"], ["84469.50", "0"], ["84472.50", "4.880350"], ["84478.00", "0"], ["84481.00", "5.241857"], ["84486.50", "0"], ["84489.50", "3.976582"], ["84495.00", "0"], ["84498.00", "4.428466"], ["84503.50", "0"], ["84506.50", "4.247712"], ["84512.00", "0"], ["84515.00", "4.518843"], ["84520.50", "0"], ["84523.50", "5.603365"], ["84529.00", "0"], ["84532.00", "4.970727"], ["84537.50", "0"], ["84540.50", "4.609220"], ["84546.00", "0"], ["84549.00", "5.512988"], ["84554.50", "0"], ["84850.00", "0.000031"], ["84851.66", "0.000029"], ["84852.81", "0.000115"], ["84852.94", "0.000065"], ["84853.56", "0.000050"], ["84857.14", "0.000347"], ["84858.75", "0.000285"], ["84859.29", "0.000036"], ["84860.00", "0.000169"], ["84862.90", "0.000169"], ["84864.69", "0.000052"], ["84864.86", "0.000041"], ["84864.99", "0.000033"]], "bids": [["84290.65", "0.555913"], ["84289.72", "0.000164"], ["84286.40", "0"], ["84284.60", "0.102849"], ["84284.41", "0"], ["84282.40", "0"], ["84280.90", "0.001033"], ["84280.40", "0"], ["84280.13", "0"], ["84278.90", "0.001033"], ["84278.40", "0"], ["84276.90", "0.001050"], ["84276.50", "0"], ["84276.40", "0"], ["84274.91", "0"], ["84274.90", "0.001048"], ["84274.88", "0"], ["84274.40", "0"], ["84272.90", "0.001577"], ["84272.57", "0"], ["84272.45", "0"], ["84272.40", "0"], ["84272.02", "0"], ["84271.42", "0"], ["84271.16", "0"], ["84270.90", "0.004150"], ["84270.40", "0"], ["84269.39", "0"], ["84269.30", "0"], ["84269.24", "0"], ["84268.90", "0.010920"], ["84268.67", "0"], ["84268.40", "0"], ["84268.06", "0"], ["84267.68", "0"], ["84266.40", "0"], ["84264.90", "0.075625"], ["84264.60", "0"], ["84264.58", "0"], ["84264.50", "0"], ["84264.40", "0"], ["84263.40", "0"], ["84262.90", "0.199014"], ["84260.90", "0.523720"], ["84259.70", "0.052680"], ["84259.20", "0.035580"], ["84257.90", "0.096960"], ["84257.80", "0"], ["84256.60", "0"], ["84254.20", "0.035580"], ["84253.70", "0"], ["84252.70", "0.528750"], ["84252.40", "1.440000"], ["84251.80", "0"], ["84250.00", "2.349150"], ["84249.50", "0"], ["84249.00", "0.350670"], ["84248.20", "0.125580"], ["84247.70", "0.090000"], ["84247.50", "0.090000"], ["84246.15", "0"], ["84245.30", "0.177960"], ["84224.20", "0"], ["84218.70", "5.512988"], ["84215.70", "0"], ["84210.20", "3.886205"], ["84207.20", "0"], ["84201.70", "4.970727"], ["84198.70", "0"], ["84193.20", "3.976582"], ["84190.20", "0"], ["84184.70", "4.518843"], ["84181.70", "0"], ["84176.20", "4.066958"], ["84173.20", "0"], ["84167.70", "4.789973"], ["84164.70", "0"], ["84159.20", "4.699596"], ["84156.20", "0"], ["84150.70", "5.332234"], ["84147.70", "0"], ["84142.20", "4.338089"], ["84139.20", "0"], ["84133.70", "5.151481"], ["84130.70", "0"], ["84125.20", "5.241857"], ["84122.20", "0"], ["84116.70", "4.157335"], ["84113.70", "0"], ["84108.20", "5.422611"], ["84105.20", "0"], ["84099.70", "4.428466"], ["84096.70", "0"], ["84091.20", "4.880350"], ["84088.20", "0"], ["84082.70", "5.061104"], ["84079.70", "0"], ["84074.20", "5.603365"], ["84071.20", "0"], ["84065.70", "4.609220"], ["84062.70", "0"], ["84057.20", "4.247712"], ["83893.64", "0.000039"], ["83893.62", "0.000137"], ["83892.29", "0.000143"], ["83891.43", "0.000455"], ["83891.30", "0.000010"], ["83888.89", "0.000163"], ["83888.86", "0.000371"], ["83887.29", "0.000586"], ["83887.11", "0.000075"], ["83886.91", "0.000145"], ["83885.98", "0.000018"], ["83885.71", "0.000069"], ["83884.62", "0.000014"], ["83884.55", "0.000048"], ["83884.30", "0.000161"], ["83882.98", "0.000188"], ["83882.92", "0.002384"], ["83881.99", "0.000038"], ["83880.00", "0.020454"], ["83877.97", "0.000023"]], "checksum": -1978280778, "ts": "1742142235392"}], "ts": 1742142235399, "record_time": 1742142234.508073}
{"action": "update", "arg": {"instType": "SPOT", "channel": "books", "instId": "BTCUSDT"}, "data": [{"asks": [["84293.48", "0.139965"], ["84294.88", "0.004595"], ["84294.94", "0.004974"], ["84294.96", "0.001230"], ["84295.89", "0.000078"], ["84295.92", "0.015340"], ["84295.94", "0.001162"], ["84295.95", "0.014469"], ["84295.97", "0.009191"], ["84296.00", "0"], ["84296.01", "0.004739"], ["84299.09", "0"], ["84300.05", "0.080082"], ["84303.00", "0"], ["84306.78", "0.001205"], ["84308.12", "0.119869"], ["84309.29", "0.006356"], ["84309.36", "0.035952"], ["84309.56", "0.006356"], ["84311.12", "0.010985"], ["84311.91", "0"], ["84312.29", "0.006356"], ["84312.35", "0.006356"], ["84312.42", "0.006356"], ["84312.64", "0.006356"], ["84312.68", "0.006356"], ["84317.93", "0"], ["84319.47", "0"], ["84320.40", "0.001807"], ["84321.00", "0.010000"], ["84329.30", "0.001011"], ["84329.86", "0"], ["84331.30", "0.001449"], ["84333.30", "0.003813"], ["84335.30", "0.010035"], ["84337.30", "0.026406"], ["84338.45", "0"], ["84339.30", "0.069491"], ["84341.30", "0.182871"], ["84343.30", "0.481239"], ["84345.30", "1.266418"], ["84346.20", "0.892830"], ["84346.50", "2.349420"], ["84346.70", "0"], ["84347.20", "0"], ["84348.00", "4.703640"], ["84348.20", "0"], ["84348.30", "0"], ["84348.50", "0"], ["84348.60", "0"], ["84348.90", "0"], ["84349.00", "0.012300"], ["84349.30", "0.744480"], ["84349.50", "0"], ["84350.20", "0"], ["84350.80", "0.186720"], ["84350.90", "0"], ["84352.00", "0"], ["84352.20", "0"], ["84352.30", "7.944960"], ["84352.70", "0"], ["84356.30", "0.410370"], ["84360.20", "0.032910"], ["84360.40", "1.865760"], ["84360.70", "0.120000"], ["84387.50", "4.699596"], ["84396.00", "3.976582"], ["84404.50", "4.789973"], ["84413.00", "4.609220"], ["84421.50", "4.247712"], ["84430.00", "5.332234"], ["84438.50", "4.880350"], ["84447.00", "4.338089"], ["84455.50", "5.061104"], ["84464.00", "4.066958"], ["84472.50", "4.970727"], ["84481.00", "4.428466"], ["84489.50", "5.512988"], ["84498.00", "4.518843"], ["84506.50", "5.422611"], ["84515.00", "4.157335"], ["84523.50", "3.886205"], ["84532.00", "5.151481"], ["84540.50", "5.603365"], ["84549.00", "5.241857"], ["84853.56", "0"], ["84857.14", "0"], ["84858.75", "0"], ["84859.29", "0"], ["84860.00", "0"], ["84862.90", "0"], ["84864.69", "0"], ["84864.86", "0"], ["84864.99", "0"]], "bids": [["84290.65", "0.986993"], ["84289.72", "0.568563"], ["84288.77", "0.055143"], ["84277.03", "0.003006"], ["84276.90", "0.001890"], ["84274.90", "0.004974"], ["84273.59", "0.010679"], ["84272.90", "0.013089"], ["84270.90", "0.034445"], ["84269.38", "0.007646"], ["84268.90", "0.090644"], ["84268.20", "0.015770"], ["84267.73", "0.008988"], ["84267.71", "0.008556"], ["84266.90", "0.238537"], ["84266.82", "0.247978"], ["84265.53", "0.084431"], ["84265.49", "0.007953"], ["84264.90", "0.627729"], ["84264.89", "0.017834"], ["84264.28", "0.018259"], ["84263.25", "0.056349"], ["84262.90", "1.651919"], ["84262.56", "0.007315"], ["84262.35", "0.017060"], ["84262.27", "0.004935"], ["84262.17", "0.009635"], ["84260.93", "0.008164"], ["84260.90", "4.347155"], ["84260.50", "0.010234"], ["84259.70", "0.102030"], ["84259.40", "0.001020"], ["84259.38", "0.002949"], ["84259.20", "0"], ["84257.90", "0.174600"], ["84257.80", "0.212280"], ["84256.50", "0"], ["84255.80", "0.069780"], ["84252.70", "0.807480"], ["84252.40", "1.350000"], ["84251.50", "0"], ["84250.60", "0.015180"], ["84250.50", "0"], ["84250.00", "1.139850"], ["84249.00", "0"], ["84248.20", "0.100860"], ["84247.70", "0"], ["84247.50", "0"], ["84246.50", "0"], ["84246.20", "0.315600"], ["84245.30", "0"], ["84242.90", "0.830370"], ["84242.30", "0.030000"], ["84242.00", "2.674140"], ["84241.80", "0.014040"], ["84241.50", "3.694380"], ["84238.98", "0.007585"], ["84224.73", "0"], ["84218.70", "4.609220"], ["84210.20", "5.422611"], ["84201.70", "4.338089"], ["84176.20", "4.157335"], ["84167.70", "5.512988"], ["84159.20", "4.789973"], ["84150.70", "3.886205"], ["84142.20", "4.699596"], ["84133.70", "5.603365"], ["84125.20", "4.880350"], ["84116.70", "4.970727"], ["84108.20", "5.241857"], ["84099.70", "4.247712"], ["84091.20", "4.066958"], ["84082.70", "5.332234"], ["84074.20", "5.151481"], ["84065.70", "4.428466"], ["84057.20", "5.061104"], ["83893.62", "0"], ["83892.29", "0"], ["83891.43", "0"], ["83891.30", "0"], ["83888.89", "0"], ["83888.86", "0"], ["83887.29", "0"], ["83887.11", "0"], ["83886.91", "0"], ["83885.98", "0"], ["83885.71", "0"], ["83884.62", "0"], ["83884.55", "0"], ["83884.30", "0"], ["83882.98", "0"], ["83882.92", "0"], ["83881.99", "0"], ["83880.00", "0"], ["83877.97", "0"]], "checksum": -877624732, "ts": "1742142235597"}], "ts": 1742142235600, "record_time": 1742142234.70903}
{"action": "update", "arg": {"instType": "SPOT", "channel": "books", "instId": "BTCUSDT"}, "data": [{"asks": [["84290.66", "0.810720"], ["84293.47", "0.061132"], ["84294.32", "0"], ["84294.90", "0.008962"], ["84295.91", "0.020440"], ["84331.30", "0.001768"], ["84333.30", "0.004769"], ["84335.30", "0.012550"], ["84337.30", "0.033026"], ["84339.30", "0.086911"], ["84341.30", "0.228712"], ["84343.30", "0.601876"], ["84345.30", "1.583883"], ["84346.10", "0.696480"], ["84346.20", "0.403380"], ["84346.50", "0"], ["84348.00", "0.777180"], ["84349.00", "0"], ["84349.30", "0"], ["84350.80", "0.186540"], ["84352.30", "0.437070"], ["84353.50", "0"], ["84355.10", "0.469080"], ["84356.30", "0"], ["84360.70", "0"], ["84360.80", "0.013860"], ["84361.40", "0.142500"], ["84362.00", "0.410370"], ["84362.20", "0.078210"], ["84387.50", "3.976582"], ["84396.00", "4.970727"], ["84404.50", "3.886205"], ["84413.00", "4.157335"], ["84421.50", "5.603365"], ["84438.50", "5.151481"], ["84447.00", "4.428466"], ["84455.50", "5.241857"], ["84464.00", "4.880350"], ["84472.50", "5.422611"], ["84481.00", "4.789973"], ["84489.50", "4.518843"], ["84498.00", "4.699596"], ["84506.50", "4.066958"], ["84515.00", "5.512988"], ["84523.50", "4.247712"], ["84532.00", "5.061104"], ["84540.50", "4.338089"], ["84549.00", "4.609220"], ["84852.81", "0"], ["84852.94", "0"]], "bids": [["84290.65", "0.568593"], ["84286.88", "0.000070"], ["84266.90", "0.238634"], ["84264.90", "0.627984"], ["84262.90", "1.652739"], ["84260.90", "4.349312"], ["84260.40", "0.001049"], ["84259.70", "0.873900"], ["84257.90", "0.174180"], ["84257.80", "0.142680"], ["84257.30", "0.704070"], ["84255.90", "2.349150"], ["84253.60", "0.178140"], ["84252.70", "0.567780"], ["84250.00", "0.346680"], ["84248.90", "0.410370"], ["84244.10", "0.462600"], ["84244.00", "0.030000"], ["84242.70", "0.090000"], ["84242.30", "0"], ["84242.00", "0"], ["84241.80", "0"], ["84241.50", "0"], ["84218.70", "5.241857"], ["84210.20", "4.428466"], ["84201.70", "4.157335"], ["84193.20", "5.061104"], ["84184.70", "4.247712"], ["84176.20", "4.518843"], ["84167.70", "4.789973"], ["84159.20", "4.699596"], ["84150.70", "4.970727"], ["84142.20", "5.332234"], ["84133.70", "5.512988"], ["84125.20", "4.338089"], ["84116.70", "4.609220"], ["84108.20", "4.066958"], ["84099.70", "5.603365"], ["84091.20", "5.151481"], ["84082.70", "3.976582"], ["84074.20", "4.880350"], ["84065.70", "5.422611"], ["84057.20", "3.886205"], ["83895.00", "0"], ["83894.74", "0"], ["83894.17", "0"], ["83893.81", "0"], ["83893.64", "0"]], "checksum": 513468518, "ts": "1742142235800"}], "ts": 1742142235803, "record_time": 1742142234.910616}
{"action": "update", "arg": {"instType": "SPOT", "channel": "books", "instId": "BTCUSDT"}, "data": [{"asks": [["84293.47", "0.041990"], ["84331.30", "0.002379"], ["84333.30", "0.006260"], ["84335.30", "0.016474"], ["84337.30", "0.043352"], ["84339.30", "0.114086"], ["84341.30", "0.300226"], ["84343.30", "0.790068"], ["84345.30", "2.079127"], ["84346.10", "1.004910"], ["84346.20", "0.330480"], ["84348.00", "0.119820"], ["84348.60", "0.142500"], ["84350.20", "0.069600"], ["84352.30", "0.651930"], ["84353.70", "1.350000"], ["84356.10", "1.035360"], ["84356.50", "0.032910"], ["84359.50", "0.985470"], ["84359.60", "0.117000"], ["84360.20", "0"], ["84360.80", "0"], ["84361.40", "0"], ["84362.00", "0"], ["84362.20", "0"], ["84387.50", "3.886205"], ["84396.00", "4.157335"], ["84404.50", "4.247712"], ["84413.00", "4.970727"], ["84421.50", "5.332234"], ["84430.00", "4.789973"], ["84438.50", "4.518843"], ["84447.00", "5.151481"], ["84455.50", "5.603365"], ["84464.00", "3.976582"], ["84481.00", "5.241857"], ["84489.50", "4.338089"], ["84498.00", "4.609220"], ["84506.50", "5.512988"], ["84515.00", "4.066958"], ["84523.50", "4.428466"], ["84540.50", "4.880350"], ["84549.00", "4.699596"], ["84635.91", "0"], ["84640.32", "1.646092"], ["84851.66", "0"]], "bids": [["84288.83", "0.055143"], ["84288.77", "0"], ["84286.88", "0"], ["84283.60", "0.000070"], ["84276.90", "0.001681"], ["84274.90", "0.004423"], ["84272.90", "0.011640"], ["84270.90", "0.030632"], ["84268.99", "0.003036"], ["84268.90", "0.080611"], ["84266.90", "0.212134"], ["84264.90", "0.557991"], ["84262.90", "1.468398"], ["84260.90", "3.864206"], ["84259.50", "0"], ["84259.20", "0.035580"], ["84255.90", "2.348970"], ["84255.80", "0"], ["84253.60", "0.177960"], ["84252.70", "0.567600"], ["84249.60", "0.038460"], ["84249.40", "0.090870"], ["84248.90", "0"], ["84247.70", "0.090000"], ["84247.60", "0.090000"], ["84246.20", "0.482010"], ["84244.30", "0.090000"], ["84244.00", "0"], ["84242.90", "0"], ["84242.70", "0"], ["84218.70", "4.970727"], ["84210.20", "5.151481"], ["84201.70", "5.603365"], ["84193.20", "3.976582"], ["84184.70", "4.518843"], ["84176.20", "5.241857"], ["84170.98", "0"], ["84169.00", "0.012838"], ["84167.70", "4.247712"], ["84159.20", "5.422611"], ["84150.70", "4.066958"], ["84142.20", "5.061104"], ["84133.70", "4.609220"], ["84125.20", "4.789973"], ["84116.70", "4.338089"], ["84108.20", "4.699596"], ["84099.70", "4.880350"], ["84091.20", "5.512988"], ["84082.70", "3.886205"], ["84074.20", "4.428466"], ["84065.70", "5.332234"], ["84057.20", "4.157335"], ["83965.88", "1.671907"], ["83961.52", "0"]], "checksum": -2068755631, "ts": "1742142236000"}], "ts": 1742142236006, "record_time": 1742142235.114032}
{"action": "update", "arg": {"instType": "SPOT", "channel": "books", "instId": "BTCUSDT"}, "data": [{"asks": [["84298.98", "0.037527"], ["84343.30", "0.790174"], ["84345.30", "2.079406"], ["84346.10", "1.005120"], ["84348.00", "0.233670"], ["84350.20", "0"], ["84350.80", "0.186120"], ["84351.00", "0.430050"], ["84360.30", "0.180000"], ["84360.40", "1.660890"], ["84387.50", "4.157335"], ["84396.00", "4.338089"], ["84404.50", "5.332234"], ["84413.00", "4.789973"], ["84421.50", "4.970727"], ["84430.00", "5.241857"], ["84438.50", "5.061104"], ["84447.00", "5.422611"], ["84455.50", "3.886205"], ["84464.00", "4.066958"], ["84472.50", "5.603365"], ["84481.00", "4.880350"], ["84489.50", "3.976582"], ["84498.00", "4.518843"], ["84515.00", "4.609220"], ["84532.00", "5.151481"], ["84540.50", "4.247712"], ["84850.00", "0"]], "bids": [["84266.90", "0.211964"], ["84264.90", "0.557800"], ["84262.90", "1.468094"], ["84260.90", "3.863406"], ["84259.70", "0.874530"], ["84259.20", "0.035790"], ["84258.80", "0.414990"], ["84248.40", "0.090000"], ["84247.50", "0.090000"], ["84245.30", "0.030000"], ["84245.00", "0"], ["84244.30", "0"], ["84244.10", "0"], ["84218.70", "4.428466"], ["84210.20", "5.422611"], ["84201.70", "5.061104"], ["84193.20", "4.066958"], ["84184.70", "3.976582"], ["84176.20", "4.609220"], ["84167.70", "5.151481"], ["84159.20", "5.332234"], ["84150.70", "4.789973"], ["84142.20", "4.880350"], ["84133.70", "4.157335"], ["84125.20", "4.338089"], ["84116.70", "5.512988"], ["84108.20", "4.970727"], ["84099.70", "5.241857"], ["84091.20", "4.247712"], ["84082.70", "4.699596"], ["84074.20", "5.603365"], ["84065.70", "3.886205"], ["84057.20", "4.518843"], ["83895.65", "0"]], "checksum": -472291588, "ts": "1742142236213"}], "ts": 1742142236216, "record_time": 1742142235.324047}
{"action": "update", "arg": {"instType": "SPOT", "channel": "books", "instId": "BTCUSDT"}, "data": [{"asks": [["84293.47", "0"], ["84295.91", "0"], ["84304.94", "0.001267"], ["84307.52", "0"], ["84328.08", "0"], ["84331.30", "0.001030"], ["84333.30", "0.001255"], ["84335.30", "0.003302"], ["84337.30", "0.008690"], ["84339.30", "0.022868"], ["84341.30", "0.060179"], ["84343.30", "0.158365"], ["84345.30", "0.416752"], ["84346.10", "0.310110"], ["84346.20", "0.001018"], ["84348.60", "0"], ["84350.70", "2.348700"], ["84352.30", "0.282150"], ["84353.70", "0"], ["84354.20", "0.007050"], ["84354.60", "0.015180"], ["84355.00", "0.157590"], ["84358.90", "0"], ["84359.40", "0"], ["84387.50", "5.422611"], ["84396.00", "4.066958"], ["84404.50", "5.151481"], ["84413.00", "4.247712"], ["84421.50", "4.518843"], ["84430.00", "5.603365"], ["84438.50", "4.338089"], ["84447.00", "5.241857"], ["84451.13", "0.209200"], ["84455.50", "5.332234"], ["84464.00", "4.699596"], ["84472.50", "4.157335"], ["84481.00", "4.428466"], ["84489.50", "4.970727"], ["84498.00", "5.512988"], ["84506.50", "4.609220"], ["84515.00", "3.976582"], ["84523.50", "4.789973"], ["84532.00", "4.880350"], ["84540.50", "5.061104"], ["84549.00", "3.886205"], ["84850.00", "0.000031"], ["84851.66", "0.000029"], ["84852.81", "0.000115"], ["84852.94", "0.000065"]], "bids": [["84290.65", "0.985913"], ["84288.83", "0"], ["84284.40", "0"], ["84283.60", "0"], ["84276.90", "0.002048"], ["84274.90", "0.005390"], ["84272.90", "0.014186"], ["84270.90", "0.037331"], ["84268.90", "0.098240"], ["84266.90", "0.258526"], ["84264.90", "0.680332"], ["84262.90", "1.790345"], ["84260.90", "4.711436"], ["84259.70", "0.874740"], ["84259.10", "2.348880"], ["84257.80", "0.142500"], ["84257.30", "0"], ["84256.80", "0.690840"], ["84255.90", "0"], ["84255.80", "0.069600"], ["84245.30", "0"], ["84210.20", "4.247712"], ["84201.70", "4.066958"], ["84193.20", "4.338089"], ["84184.70", "5.332234"], ["84176.20", "4.970727"], ["84167.70", "5.512988"], ["84159.20", "4.880350"], ["84150.70", "5.603365"], ["84142.20", "4.518843"], ["84133.70", "3.976582"], ["84125.20", "5.151481"], ["84116.70", "4.157335"], ["84108.20", "4.609220"], ["84099.70", "4.699596"], ["84091.20", "5.061104"], ["84082.70", "5.241857"], ["84074.20", "3.886205"], ["84065.70", "4.789973"], ["84057.20", "5.422611"], ["83895.65", "0.000013"], ["83895.00", "0.006121"], ["83894.74", "0.000068"]], "checksum": 2106777642, "ts": "1742142236413"}], "ts": 1742142236417, "record_time": 1742142235.524086}
{"action": "update", "arg": {"instType": "SPOT", "channel": "books", "instId": "BTCUSDT"}, "data": [{"asks": [["84290.66", "0.810181"], ["84290.67", "0.000100"], ["84290.68", "0.000100"], ["84290.69", "0.000100"], ["84293.48", "0"], ["84298.22", "0.139958"], ["84298.98", "0"], ["84312.12", "0.583375"], ["84333.30", "0.001036"], ["84335.30", "0.001603"], ["84336.77", "0.031812"], ["84337.30", "0.004219"], ["84339.30", "0.011104"], ["84341.30", "0.029032"], ["84343.30", "0.076398"], ["84345.30", "0.201047"], ["84345.50", "0.001038"], ["84346.10", "0.001020"], ["84348.00", "0"], ["84349.00", "0.010980"], ["84350.70", "0"], ["84350.80", "0.009180"], ["84352.30", "0.198450"], ["84352.40", "0.009000"], ["84354.70", "0"], ["84356.10", "1.505280"], ["84357.40", "0"], ["84357.90", "0"], ["84358.20", "0.007050"], ["84358.50", "2.348460"], ["84359.20", "1.779300"], ["84359.60", "0"], ["84360.30", "0"], ["84360.40", "0"], ["84387.50", "4.609220"], ["84396.00", "3.976582"], ["84404.50", "5.512988"], ["84413.00", "5.422611"], ["84421.50", "4.066958"], ["84430.00", "4.428466"], ["84438.50", "4.699596"], ["84447.00", "4.338089"], ["84455.50", "4.970727"], ["84464.00", "5.241857"], ["84472.50", "5.151481"], ["84481.00", "5.332234"], ["84489.50", "4.880350"], ["84498.00", "4.789973"], ["84506.50", "3.886205"], ["84515.00", "4.157335"], ["84523.50", "4.247712"], ["84532.00", "5.061104"], ["84540.50", "4.518843"], ["84549.00", "5.603365"]], "bids": [["84290.65", "0.985983"], ["84288.90", "0.055143"], ["84284.60", "0.044990"], ["84284.59", "0"], ["84282.22", "0"], ["84277.31", "0.190600"], ["84274.90", "0.005264"], ["84272.90", "0.013854"], ["84270.90", "0.036457"], ["84268.90", "0.095941"], ["84266.90", "0.252580"], ["84264.90", "0.664928"], ["84262.90", "1.749811"], ["84260.90", "4.604765"], ["84259.70", "0.874320"], ["84259.40", "0"], ["84259.20", "0.035580"], ["84259.10", "2.349060"], ["84258.80", "0.415170"], ["84257.90", "0.495780"], ["84257.80", "0.142680"], ["84256.80", "0"], ["84254.20", "1.857210"], ["84252.70", "0"], ["84252.30", "0.117060"], ["84250.00", "0.219240"], ["84248.80", "0"], ["84218.70", "4.970727"], ["84210.20", "5.603365"], ["84203.53", "0.072042"], ["84193.20", "5.332234"], ["84184.70", "4.428466"], ["84176.20", "5.422611"], ["84167.70", "3.976582"], ["84159.20", "4.157335"], ["84150.70", "5.151481"], ["84142.20", "5.061104"], ["84133.70", "4.609220"], ["84125.20", "4.789973"], ["84116.70", "4.518843"], ["84108.20", "3.886205"], ["84099.70", "5.512988"], ["84091.20", "4.247712"], ["84074.20", "4.880350"], ["84065.70", "4.338089"], ["84057.20", "4.699596"], ["83894.17", "0.000022"], ["83893.81", "0.000010"]], "checksum": -41469669, "ts": "1742142236613"}], "ts": 1742142236618, "record_time": 1742142235.725787}
{"action": "update", "arg": {"instType": "SPOT", "channel": "books", "instId": "BTCUSDT"}, "data": [{"asks": [["84300.05", "0"], ["84304.87", "0.080082"], ["84307.52", "0.209200"], ["84308.12", "0"], ["84311.12", "0"], ["84312.86", "0.119869"], ["84316.15", "0.010985"], ["84333.30", "0.001905"], ["84335.30", "0.005014"], ["84337.30", "0.013195"], ["84339.30", "0.034722"], ["84341.30", "0.091375"], ["84343.30", "0.240460"], ["84345.30", "0.632791"], ["84346.70", "0.344580"], ["84349.00", "0.052080"], ["84350.30", "0.919140"], ["84350.80", "0.009000"], ["84352.30", "0.896850"], ["84353.00", "2.348640"], ["84355.00", "0.015090"], ["84355.10", "0"], ["84356.10", "0.583200"], ["84358.50", "0"], ["84359.50", "0"], ["84360.40", "1.865760"], ["84375.26", "0"], ["84387.50", "5.422611"], ["84396.00", "5.332234"], ["84404.50", "4.338089"], ["84413.00", "4.970727"], ["84421.50", "5.061104"], ["84430.00", "4.789973"], ["84438.50", "4.880350"], ["84447.00", "4.247712"], ["84455.50", "5.241857"], ["84464.00", "4.157335"], ["84472.50", "4.428466"], ["84481.00", "3.976582"], ["84489.50", "4.066958"], ["84498.00", "4.518843"], ["84506.50", "4.699596"], ["84515.00", "3.886205"], ["84523.50", "5.603365"], ["84532.00", "5.151481"], ["84540.50", "5.512988"], ["84549.00", "4.609220"], ["84852.94", "0"]], "bids": [["84290.65", "1.124335"], ["84284.60", "0"], ["84278.90", "0.001143"], ["84277.32", "0.071876"], ["84276.90", "0.003008"], ["84274.90", "0.007915"], ["84273.59", "0"], ["84272.90", "0.020829"], ["84271.55", "0.247978"], ["84270.90", "0.054813"], ["84268.90", "0.144244"], ["84268.27", "0.056349"], ["84266.90", "0.379591"], ["84266.82", "0"], ["84264.90", "0.998923"], ["84263.25", "0"], ["84262.90", "2.628745"], ["84260.90", "6.917749"], ["84259.70", "0.052680"], ["84257.90", "0.495960"], ["84254.20", "0.710460"], ["84253.30", "0.383310"], ["84252.00", "0.410370"], ["84250.80", "0"], ["84249.10", "0.030000"], ["84246.20", "0"], ["84218.70", "4.880350"], ["84210.20", "5.512988"], ["84203.53", "0"], ["84201.70", "3.976582"], ["84193.20", "4.699596"], ["84184.70", "5.151481"], ["84168.00", "0"], ["84167.70", "5.061104"], ["84159.20", "4.247712"], ["84150.70", "4.789973"], ["84142.20", "4.066958"], ["84125.20", "5.603365"], ["84116.70", "5.332234"], ["84108.20", "4.428466"], ["84099.70", "4.157335"], ["84091.20", "4.970727"], ["84082.70", "4.338089"], ["84074.20", "5.241857"], ["84065.70", "3.886205"], ["84057.20", "4.518843"], ["83893.64", "0.000039"], ["83893.62", "0.000137"]], "checksum": -2035499895, "ts": "1742142236824"}], "ts": 1742142236827, "record_time": 1742142235.935588}
{"action": "update", "arg": {"instType": "SPOT", "channel": "books", "instId": "BTCUSDT"}, "data": [{"asks": [["84298.93", "0.019143"], ["84333.30", "0.002103"], ["84335.30", "0.005411"], ["84337.30", "0.014238"], ["84339.30", "0.037469"], ["84341.30", "0.098602"], ["84343.30", "0.259481"], ["84345.30", "0.682843"], ["84346.70", "0.344760"], ["84347.00", "0.730230"], ["84349.00", "0.051900"], ["84350.30", "0.831390"], ["84350.50", "2.348700"], ["84350.80", "0.023010"], ["84352.30", "0.057690"], ["84353.00", "0"], ["84355.00", "0.157590"], ["84357.90", "0.028140"], ["84360.40", "0"], ["84387.50", "4.157335"], ["84396.00", "5.241857"], ["84404.50", "5.151481"], ["84413.00", "5.603365"], ["84421.50", "4.789973"], ["84430.00", "4.699596"], ["84438.50", "3.976582"], ["84447.00", "4.338089"], ["84455.50", "4.880350"], ["84464.00", "4.609220"], ["84472.50", "5.061104"], ["84481.00", "4.518843"], ["84498.00", "4.247712"], ["84506.50", "4.970727"], ["84515.00", "5.332234"], ["84523.50", "5.422611"], ["84532.00", "3.886205"], ["84549.00", "4.428466"], ["84851.66", "0"], ["84852.81", "0"]], "bids": [["84288.97", "0.055143"], ["84288.90", "0"], ["84278.90", "0.001018"], ["84276.90", "0.002565"], ["84274.90", "0.006751"], ["84272.90", "0.017765"], ["84272.86", "0.711772"], ["84270.90", "0.046750"], ["84268.90", "0.123025"], ["84266.90", "0.323752"], ["84264.90", "0.851978"], ["84262.90", "2.242047"], ["84260.90", "5.900125"], ["84254.20", "1.037250"], ["84252.60", "0.987180"], ["84251.40", "0.172500"], ["84249.10", "0"], ["84218.70", "4.157335"], ["84210.20", "5.603365"], ["84201.70", "4.247712"], ["84193.20", "5.241857"], ["84184.70", "4.066958"], ["84176.20", "4.699596"], ["84167.70", "4.428466"], ["84159.20", "4.880350"], ["84150.70", "4.609220"], ["84142.20", "4.518843"], ["84133.70", "5.061104"], ["84125.20", "5.512988"], ["84116.70", "3.976582"], ["84108.20", "5.151481"], ["84099.70", "4.970727"], ["84091.20", "5.422611"], ["84082.70", "4.789973"], ["84074.20", "3.886205"], ["84065.70", "4.338089"], ["84057.20", "5.332234"]], "checksum": 1729618490, "ts": "1742142237025"}], "ts": 1742142237029, "record_time": 1742142236.136703}
{"action": "update", "arg": {"instType": "SPOT", "channel": "books", "instId": "BTCUSDT"}, "data": [{"asks": [["84298.93", "0"], ["84304.86", "0.025291"], ["84304.94", "0"], ["84333.30", "0.001675"], ["84335.30", "0.004408"], ["84337.30", "0.011600"], ["84339.30", "0.030526"], ["84341.30", "0.080331"], ["84343.30", "0.211397"], ["84345.30", "0.556307"], ["84346.10", "0.001290"], ["84346.20", "0"], ["84349.00", "0.099960"], ["84350.80", "0.056640"], ["84360.40", "2.287740"], ["84387.50", "4.609220"], ["84396.00", "4.066958"], ["84404.50", "4.428466"], ["84413.00", "4.157335"], ["84421.50", "4.880350"], ["84430.00", "5.512988"], ["84438.50", "5.061104"], ["84447.00", "5.603365"], ["84455.50", "4.247712"], ["84464.00", "3.976582"], ["84472.50", "3.886205"], ["84481.00", "4.699596"], ["84489.50", "4.338089"], ["84498.00", "5.241857"], ["84506.50", "4.518843"], ["84515.00", "4.970727"], ["84523.50", "5.332234"], ["84532.00", "5.151481"], ["84540.50", "5.422611"], ["84549.00", "4.789973"], ["84851.66", "0.000029"]], "bids": [["84290.65", "0.706025"], ["84276.90", "0.002558"], ["84274.90", "0.006730"], ["84272.90", "0.017712"], ["84270.90", "0.046610"], ["84268.90", "0.122656"], ["84266.90", "0.322780"], ["84264.90", "0.849421"], ["84262.90", "2.235319"], ["84260.90", "5.882417"], ["84254.90", "0.915360"], ["84252.30", "0.147240"], ["84251.40", "0.142500"], ["84218.70", "5.422611"], ["84210.20", "4.880350"], ["84201.70", "3.886205"], ["84193.20", "4.970727"], ["84184.70", "4.518843"], ["84176.20", "5.332234"], ["84167.70", "4.699596"], ["84159.20", "4.157335"], ["84142.20", "4.338089"], ["84133.70", "4.428466"], ["84125.20", "5.061104"], ["84116.70", "5.151481"], ["84108.20", "5.512988"], ["84099.70", "5.603365"], ["84091.20", "4.066958"], ["84082.70", "4.247712"], ["84074.20", "5.241857"], ["84065.70", "3.976582"], ["84057.20", "4.789973"], ["83893.62", "0"]], "checksum": -2100459773, "ts": "1742142237230"}], "ts": 1742142237233, "record_time": 1742142236.340903}
{"action": "update", "arg": {"instType": "SPOT", "channel": "books", "instId": "BTCUSDT"}, "data": [{"asks": [["84290.66", "0.810820"], ["84298.93", "0.019143"], ["84331.30", "0.001037"], ["84333.30", "0.001851"], ["84335.30", "0.004870"], ["84337.30", "0.012815"], ["84339.30", "0.033726"], ["84341.30", "0.088751"], ["84343.30", "0.233555"], ["84345.30", "0.614618"], ["84346.10", "0.001050"], ["84346.70", "0.674010"], ["84347.00", "0"], ["84349.00", "0.185850"], ["84350.30", "0.146070"], ["84350.50", "0"], ["84354.60", "0"], ["84355.50", "0.015180"], ["84360.40", "0"], ["84387.50", "4.880350"], ["84396.00", "3.886205"], ["84404.50", "4.518843"], ["84413.00", "4.247712"], ["84421.50", "3.976582"], ["84430.00", "4.609220"], ["84438.50", "5.151481"], ["84447.00", "4.066958"], ["84455.50", "5.061104"], ["84464.00", "5.422611"], ["84472.50", "5.241857"], ["84481.00", "5.332234"], ["84489.50", "4.699596"], ["84498.00", "4.428466"], ["84506.50", "4.789973"], ["84515.00", "4.157335"], ["84523.50", "5.603365"], ["84532.00", "5.512988"], ["84540.50", "4.338089"], ["84549.00", "4.970727"], ["84852.81", "0.000115"], ["84852.94", "0.000065"]], "bids": [["84290.65", "0.915065"], ["84276.90", "0.001639"], ["84274.90", "0.004311"], ["84272.90", "0.011345"], ["84270.90", "0.029855"], ["84268.90", "0.078566"], ["84266.90", "0.206754"], ["84264.90", "0.544090"], ["84262.90", "1.431814"], ["84260.90", "3.767932"], ["84259.70", "0.053100"], ["84259.10", "1.007250"], ["84258.80", "0.414990"], ["84258.00", "2.348910"], ["84257.90", "0.316830"], ["84257.80", "0.142500"], ["84252.90", "0.462600"], ["84252.30", "0.117060"], ["84252.00", "0"], ["84251.50", "0.030000"], ["84248.70", "0.410370"], ["84248.10", "0"], ["84248.00", "0"], ["84247.80", "0"], ["84247.70", "0"], ["84247.60", "0"], ["84247.50", "0"], ["84218.70", "4.157335"], ["84210.20", "4.518843"], ["84201.70", "4.789973"], ["84193.20", "5.332234"], ["84184.70", "4.247712"], ["84176.20", "5.422611"], ["84176.00", "0.000165"], ["84167.70", "4.338089"], ["84159.20", "4.609220"], ["84150.70", "3.886205"], ["84142.20", "5.241857"], ["84133.70", "4.970727"], ["84125.20", "4.066958"], ["84116.70", "5.061104"], ["84108.20", "3.976582"], ["84091.20", "5.512988"], ["84082.70", "4.428466"], ["84074.20", "4.880350"], ["84065.70", "4.699596"], ["84057.20", "5.151481"], ["83893.62", "0.000137"], ["83892.29", "0.000143"]], "checksum": 1055566560, "ts": "1742142237433"}], "ts": 1742142237437, "record_time": 1742142236.549365}
{"action": "update", "arg": {"instType": "SPOT", "channel": "books", "instId": "BTCUSDT"}, "data": [{"asks": [["84290.66", "0.203270"], ["84295.95", "0.007359"], ["84298.93", "0"], ["84304.86", "0"], ["84304.87", "0"], ["84306.78", "0"], ["84307.52", "0"], ["84309.29", "0"], ["84309.36", "0"], ["84309.56", "0"], ["84312.29", "0"], ["84312.35", "0"], ["84312.42", "0"], ["84312.64", "0"], ["84312.68", "0"], ["84314.51", "0"], ["84314.56", "0"], ["84315.38", "0"], ["84315.94", "0.200034"], ["84318.13", "0.006356"], ["84318.31", "0"], ["84318.32", "0"], ["84318.33", "0.006357"], ["84319.63", "0"], ["84320.40", "0"], ["84320.79", "0"], ["84321.00", "0"], ["84325.17", "0.001807"], ["84333.30", "0.001048"], ["84335.30", "0.001015"], ["84337.30", "0.001898"], ["84339.30", "0.004995"], ["84341.30", "0.013145"], ["84343.30", "0.034591"], ["84345.30", "0.091028"], ["84346.70", "0"], ["84347.90", "0.046410"], ["84349.00", "0"], ["84350.30", "0.376920"], ["84350.80", "0.056820"], ["84350.90", "0.829770"], ["84356.10", "0"], ["84357.90", "0"], ["84359.20", "0"], ["84360.40", "2.492610"], ["84360.80", "0.013860"], ["84396.00", "4.338089"], ["84404.50", "5.061104"], ["84413.00", "5.241857"], ["84421.50", "4.609220"], ["84430.00", "4.247712"], ["84438.50", "4.970727"], ["84447.00", "4.428466"], ["84455.50", "4.518843"], ["84459.56", "0.209200"], ["84464.00", "4.157335"], ["84472.50", "4.699596"], ["84481.00", "5.422611"], ["84489.50", "5.512988"], ["84498.00", "5.151481"], ["84506.50", "3.886205"], ["84515.00", "4.066958"], ["84523.50", "5.332234"], ["84532.00", "3.976582"], ["84540.50", "4.789973"], ["84549.00", "5.603365"], ["84853.56", "0.000050"], ["84857.14", "0.000347"], ["84858.75", "0.000285"], ["84859.29", "0.000036"], ["84860.00", "0.000169"], ["84862.90", "0.000169"], ["84864.69", "0.000052"], ["84864.86", "0.000041"], ["84864.99", "0.000033"], ["84866.10", "0.000064"], ["84866.40", "0.000018"], ["84867.80", "0.000095"], ["84868.42", "0.000031"], ["84868.52", "0.000013"], ["84868.65", "0.000035"], ["84869.57", "0.000932"], ["84871.66", "0.000078"], ["84871.79", "0.000014"], ["84873.84", "0.000057"]], "bids": [["84290.65", "1.124425"], ["84289.72", "0.568399"], ["84289.71", "0"], ["84289.02", "0.055143"], ["84288.97", "0"], ["84277.03", "0"], ["84276.90", "0.001845"], ["84274.90", "0.004855"], ["84272.90", "0.012775"], ["84272.85", "0"], ["84270.90", "0.033619"], ["84268.99", "0"], ["84268.90", "0.088471"], ["84268.20", "0"], ["84267.83", "0"], ["84267.75", "0"], ["84267.30", "0.197876"], ["84267.03", "0"], ["84266.99", "0"], ["84266.90", "0.232817"], ["84266.80", "0"], ["84265.66", "0"], ["84265.53", "0"], ["84264.90", "0.612678"], ["84264.89", "0"], ["84264.79", "0"], ["84264.28", "0"], ["84263.54", "0"], ["84262.90", "1.612310"], ["84262.56", "0"], ["84262.35", "0"], ["84261.30", "0"], ["84260.93", "0"], ["84260.90", "4.242920"], ["84260.50", "3.661680"], ["84260.44", "0"], ["84259.80", "0.069990"], ["84259.70", "0.052260"], ["84259.38", "0"], ["84259.10", "0"], ["84258.80", "0.415170"], ["84258.00", "0"], ["84257.90", "0.317010"], ["84257.80", "0.142680"], ["84257.63", "0"], ["84255.80", "0.069780"], ["84254.90", "1.092660"], ["84250.00", "0.402330"], ["84248.10", "0.009180"], ["84248.00", "0.056010"], ["84247.80", "0.069600"], ["84247.70", "0.090000"], ["84247.60", "0.090000"], ["84241.98", "0"], ["84237.80", "0.207047"], ["84230.30", "0"], ["84218.70", "4.609220"], ["84210.20", "4.066958"], ["84201.70", "4.970727"], ["84193.20", "4.789973"], ["84184.70", "4.338089"], ["84176.20", "4.518843"], ["84167.70", "3.886205"], ["84167.00", "0.000121"], ["84159.20", "4.699596"], ["84150.70", "3.976582"], ["84142.20", "5.151481"], ["84133.70", "5.603365"], ["84125.20", "4.247712"], ["84108.20", "4.880350"], ["84099.70", "5.512988"], ["84091.20", "5.241857"], ["84082.70", "4.157335"], ["84074.20", "5.332234"], ["84065.70", "5.422611"], ["84057.20", "4.428466"], ["83891.43", "0.000455"], ["83891.30", "0.000010"], ["83888.89", "0.000163"], ["83888.86", "0.000371"], ["83887.29", "0.000586"], ["83887.11", "0.000075"], ["83886.91", "0.000145"], ["83885.98", "0.000018"], ["83885.71", "0.000069"], ["83884.62", "0.000014"], ["83884.55", "0.000048"], ["83884.30", "0.000161"], ["83882.98", "0.000188"], ["83882.92", "0.002384"], ["83881.99", "0.000038"], ["83880.00", "0.020454"], ["83877.97", "0.000023"], ["83877.55", "0.000010"], ["83877.42", "0.000054"]], "checksum": -1869205542, "ts": "1742142237633"}], "ts": 1742142237637, "record_time": 1742142236.745594}
{"action": "update", "arg": {"instType": "SPOT", "channel": "books", "instId": "BTCUSDT"}, "data": [{"asks": [["84290.66", "0.202677"], ["84294.88", "0"], ["84294.90", "0"], ["84294.94", "0"], ["84294.96", "0"], ["84295.89", "0"], ["84295.92", "0"], ["84295.94", "0"], ["84295.95", "0"], ["84295.97", "0"], ["84296.01", "0"], ["84301.77", "0.004595"], ["84301.79", "0.008962"], ["84301.83", "0.004974"], ["84301.84", "0.001230"], ["84302.75", "0.000078"], ["84302.78", "0.015340"], ["84302.80", "0.001162"], ["84302.82", "0.007110"], ["84302.83", "0.016550"], ["84302.87", "0.004739"], ["84302.89", "0"], ["84307.51", "0.094863"], ["84307.52", "0.209200"], ["84309.71", "0.080082"], ["84311.66", "0.001827"], ["84312.86", "0"], ["84315.13", "0.001205"], ["84315.80", "0"], ["84315.94", "0"], ["84316.15", "0"], ["84316.82", "0"], ["84317.54", "0"], ["84317.83", "0.119869"], ["84318.33", "0"], ["84319.03", "0.006356"], ["84319.09", "0.035952"], ["84319.17", "0.006356"], ["84319.38", "0"], ["84320.77", "0.006356"], ["84320.91", "0.006356"], ["84321.18", "0.010985"], ["84321.81", "0.006356"], ["84321.95", "0.012712"], ["84322.02", "0.006356"], ["84322.36", "0.016427"], ["84322.45", "0.006356"], ["84322.70", "0.006356"], ["84324.28", "0.010984"], ["84324.38", "0.006357"], ["84324.85", "0.006356"], ["84325.30", "0"], ["84325.91", "0.009989"], ["84326.32", "0.119895"], ["84327.30", "0"], ["84327.38", "0.119881"], ["84327.51", "0.119879"], ["84329.30", "0"], ["84331.30", "0"], ["84332.20", "0.001029"], ["84333.30", "0"], ["84334.20", "0.001010"], ["84335.30", "0"], ["84336.20", "0.001015"], ["84337.30", "0"], ["84338.20", "0.001017"], ["84339.30", "0"], ["84340.20", "0.001521"], ["84341.30", "0"], ["84342.20", "0.004003"], ["84343.30", "0"], ["84344.20", "0.010534"], ["84345.30", "0"], ["84345.50", "0"], ["84346.10", "0"], ["84346.20", "0.027720"], ["84347.90", "0"], ["84348.20", "0.072947"], ["84350.20", "0.191967"], ["84350.30", "0"], ["84350.80", "0"], ["84350.90", "0"], ["84351.00", "0"], ["84352.20", "0.505176"], ["84352.30", "0"], ["84352.90", "0.001049"], ["84353.00", "0.103110"], ["84353.10", "0.001035"], ["84353.40", "0.001041"], ["84355.00", "0"], ["84355.50", "0"], ["84356.50", "0"], ["84356.60", "0.430050"], ["84359.80", "3.053370"], ["84361.40", "0.321000"], ["84361.70", "0.015180"], ["84362.10", "0.015150"], ["84362.20", "0.078210"], ["84362.30", "0.469080"], ["84363.60", "0.035550"], ["84364.30", "6.313140"], ["84387.50", "0"], ["84394.40", "4.518473"], ["84396.00", "0"], ["84402.90", "5.151060"], ["84404.50", "0"], ["84411.40", "5.331799"], ["84413.00", "0"], ["84419.90", "3.885887"], ["84421.50", "0"], ["84428.40", "4.428104"], ["84430.00", "0"], ["84436.90", "4.789582"], ["84438.50", "0"], ["84445.40", "4.066626"], ["84447.00", "0"], ["84453.90", "5.060690"], ["84455.50", "0"], ["84462.40", "5.602907"], ["84464.00", "0"], ["84470.90", "5.241429"], ["84472.50", "0"], ["84479.40", "4.608843"], ["84481.00", "0"], ["84487.90", "4.337734"], ["84489.50", "0"], ["84496.40", "4.247365"], ["84498.00", "0"], ["84504.90", "3.976257"], ["84506.50", "0"], ["84513.40", "4.879951"], ["84515.00", "0"], ["84521.90", "4.970321"], ["84523.50", "0"], ["84530.40", "4.156996"], ["84532.00", "0"], ["84538.90", "5.422168"], ["84540.50", "0"], ["84547.40", "4.699212"], ["84549.00", "0"], ["84555.90", "5.512537"], ["84858.75", "0"], ["84859.29", "0"], ["84860.00", "0"], ["84862.90", "0"], ["84864.69", "0"], ["84864.86", "0"], ["84864.99", "0"], ["84866.10", "0"], ["84866.40", "0"], ["84867.80", "0"], ["84868.42", "0"], ["84868.52", "0"], ["84868.65", "0"], ["84869.57", "0"], ["84871.66", "0"], ["84871.79", "0"], ["84873.84", "0"]], "bids": [["84290.65", "2.809662"], ["84289.72", "0.016543"], ["84287.80", "0.001019"], ["84285.80", "0.001028"], ["84285.37", "0.003006"], ["84283.80", "0.001039"], ["84281.80", "0.002314"], ["84281.40", "2.549325"], ["84280.90", "0"], ["84279.80", "0.006088"], ["84278.90", "0"], ["84277.80", "0.016022"], ["84276.90", "0"], ["84276.53", "0.247978"], ["84276.23", "0.007646"], ["84275.80", "0.042164"], ["84275.26", "0.084431"], ["84274.90", "0"], ["84274.60", "0.008986"], ["84274.59", "0.008556"], ["84274.50", "0.017834"], ["84274.40", "0.015770"], ["84274.26", "0.016459"], ["84274.18", "0.005937"], ["84274.02", "0.018259"], ["84273.80", "0.110956"], ["84273.42", "0.017077"], ["84273.30", "0.056349"], ["84273.23", "0.007119"], ["84273.20", "0.006564"], ["84273.12", "0.002062"], ["84273.00", "0.007873"], ["84272.90", "0"], ["84272.86", "0"], ["84272.36", "0.007953"], ["84272.28", "0.007315"], ["84272.13", "0.007932"], ["84271.95", "0.008987"], ["84271.87", "0.017060"], ["84271.80", "0.291991"], ["84271.55", "0"], ["84271.18", "0.017330"], ["84270.94", "0.031295"], ["84270.90", "0"], ["84270.69", "0.008164"], ["84270.60", "0.008282"], ["84270.06", "0.012648"], ["84269.80", "0.768398"], ["84269.49", "0.052103"], ["84269.43", "0.018518"], ["84269.38", "0"], ["84269.01", "0.009635"], ["84268.90", "0"], ["84268.78", "0"], ["84268.70", "0"], ["84268.27", "0"], ["84267.99", "0.271876"], ["84267.80", "2.022099"], ["84267.73", "0"], ["84267.71", "0"], ["84267.63", "0.002949"], ["84267.39", "0.010234"], ["84267.15", "0.222711"], ["84266.90", "0.068536"], ["84266.69", "0.263305"], ["84266.60", "3.214020"], ["84266.10", "0.035580"], ["84266.08", "0"], ["84265.80", "0.069780"], ["84265.49", "0"], ["84264.90", "0"], ["84264.60", "0.001041"], ["84264.55", "0"], ["84264.40", "0.415170"], ["84264.39", "0"], ["84264.20", "0.142680"], ["84263.80", "0.069780"], ["84263.50", "1.080270"], ["84262.90", "0"], ["84262.75", "0"], ["84262.70", "1.941120"], ["84262.27", "0"], ["84262.17", "0"], ["84261.80", "0.069780"], ["84261.60", "1.350180"], ["84261.40", "0.009120"], ["84261.00", "0.035580"], ["84260.90", "1.603740"], ["84260.80", "0.915360"], ["84260.50", "0"], ["84260.40", "0"], ["84259.80", "0.069600"], ["84259.70", "0.052080"], ["84259.20", "0"], ["84258.80", "0.132480"], ["84257.90", "0"], ["84257.80", "0.142500"], ["84256.71", "0.023937"], ["84255.80", "0.069600"], ["84255.70", "0.015150"], ["84255.10", "0.035580"], ["84254.90", "0.177120"], ["84254.20", "0.674880"], ["84254.00", "0.410370"], ["84253.80", "0.090000"], ["84252.90", "0"], ["84252.60", "0"], ["84252.40", "1.388460"], ["84251.80", "0.177960"], ["84251.70", "0.180000"], ["84251.50", "0"], ["84251.40", "0"], ["84250.60", "0"], ["84250.00", "0"], ["84249.60", "0"], ["84249.40", "0"], ["84248.70", "0"], ["84248.40", "0"], ["84248.20", "0"], ["84248.10", "0"], ["84248.00", "0"], ["84247.80", "0"], ["84247.70", "0"], ["84247.60", "0"], ["84245.87", "0.007582"], ["84238.98", "0"], ["84225.60", "4.879951"], ["84218.70", "0"], ["84217.10", "5.602907"], ["84210.20", "0"], ["84208.60", "4.699212"], ["84202.95", "0.072042"], ["84201.70", "0"], ["84200.10", "3.976257"], ["84193.20", "0"], ["84191.60", "4.518473"], ["84184.70", "0"], ["84183.10", "5.151060"], ["84176.20", "0"], ["84174.60", "5.331799"], ["84167.70", "0"], ["84166.10", "5.422168"], ["84159.20", "0"], ["84157.60", "5.241429"], ["84150.70", "0"], ["84149.10", "4.428104"], ["84142.20", "0"], ["84140.60", "5.512537"], ["84133.70", "0"], ["84132.10", "4.970321"], ["84125.20", "0"], ["84123.60", "4.247365"], ["84116.70", "0"], ["84115.10", "3.885887"], ["84108.20", "0"], ["84106.60", "4.789582"], ["84099.70", "0"], ["84098.10", "4.608843"], ["84091.20", "0"], ["84089.60", "4.066626"], ["84082.70", "0"], ["84081.10", "4.337734"], ["84074.20", "0"], ["84072.60", "5.060690"], ["84065.70", "0"], ["84064.10", "4.156996"], ["84057.20", "0"], ["83893.81", "0"], ["83893.64", "0"], ["83893.62", "0"], ["83892.29", "0"], ["83891.43", "0"], ["83891.30", "0"], ["83888.89", "0"], ["83888.86", "0"], ["83887.29", "0"], ["83887.11", "0"], ["83886.91", "0"], ["83885.98", "0"], ["83885.71", "0"], ["83884.62", "0"], ["83884.55", "0"], ["83884.30", "0"], ["83882.98", "0"], ["83882.92", "0"], ["83881.99", "0"], ["83880.00", "0"], ["83877.97", "0"], ["83877.55", "0"], ["83877.42", "0"]], "checksum": -1965286937, "ts": "1742142237835"}], "ts": 1742142237839, "record_time": 1742142236.947642}
{"action": "update", "arg": {"instType": "SPOT", "channel": "books", "instId": "BTCUSDT"}, "data": [{"asks": [["84290.66", "0.744735"], ["84298.21", "0.041987"], ["84299.09", "0.209200"], ["84321.72", "0.031812"], ["84336.20", "0.002336"], ["84336.77", "0"], ["84338.20", "0.006148"], ["84340.20", "0.016180"], ["84342.20", "0.042577"], ["84344.20", "0.112046"], ["84346.20", "0.294857"], ["84348.20", "0.775939"], ["84350.20", "2.041945"], ["84352.20", "5.373540"], ["84352.40", "0"], ["84352.80", "0.001043"], ["84353.00", "0.425490"], ["84354.40", "3.096810"], ["84355.00", "0.142680"], ["84355.50", "0.269940"], ["84356.20", "0.069780"], ["84356.50", "0.249900"], ["84358.90", "0.035580"], ["84359.80", "0"], ["84361.40", "0.142500"], ["84361.70", "0.425550"], ["84362.30", "0"], ["84362.70", "0.180000"], ["84364.30", "2.028180"], ["84394.40", "4.970321"], ["84402.90", "4.428104"], ["84411.40", "4.066626"], ["84419.90", "5.331799"], ["84428.40", "4.699212"], ["84436.90", "4.337734"], ["84445.40", "3.976257"], ["84453.90", "5.512537"], ["84459.56", "0"], ["84470.90", "4.608843"], ["84479.40", "4.247365"], ["84487.90", "3.885887"], ["84496.40", "5.422168"], ["84504.90", "4.518473"], ["84513.40", "4.156996"], ["84521.90", "5.151060"], ["84530.40", "5.060690"], ["84538.90", "4.879951"], ["84547.40", "5.241429"], ["84555.90", "4.789582"], ["84850.00", "0"], ["84851.66", "0"], ["84852.81", "0"], ["84852.94", "0"], ["84853.56", "0"], ["84857.14", "0"]], "bids": [["84290.65", "2.600462"], ["84289.02", "0"], ["84285.81", "0.001522"], ["84285.37", "0"], ["84281.80", "0.001032"], ["84281.40", "0"], ["84279.80", "0.001032"], ["84277.80", "0.001009"], ["84275.80", "0.001037"], ["84273.80", "0.001014"], ["84273.24", "0.003036"], ["84271.80", "0.001117"], ["84269.80", "0.002940"], ["84269.08", "0.004935"], ["84267.80", "0.007738"], ["84267.63", "0"], ["84266.60", "0"], ["84266.20", "0.079530"], ["84266.10", "0"], ["84265.80", "0"], ["84265.30", "0.001002"], ["84264.60", "0.001017"], ["84264.50", "0.001620"], ["84264.20", "0"], ["84263.80", "0"], ["84263.50", "0"], ["84262.80", "0.347460"], ["84262.70", "0"], ["84261.80", "0"], ["84261.60", "0"], ["84260.90", "0.018060"], ["84260.80", "0"], ["84259.80", "0"], ["84259.30", "0.009000"], ["84258.80", "0.369840"], ["84255.80", "0"], ["84255.10", "0.950940"], ["84254.20", "1.143660"], ["84254.00", "0"], ["84253.80", "0"], ["84253.60", "0"], ["84251.80", "0"], ["84251.70", "0"], ["84251.60", "0.462600"], ["84251.40", "0.142500"], ["84251.20", "0.030000"], ["84250.90", "0.177960"], ["84250.00", "0.219240"], ["84249.40", "0.090870"], ["84225.60", "5.151060"], ["84217.10", "4.247365"], ["84208.60", "5.602907"], ["84202.95", "0"], ["84200.10", "4.789582"], ["84191.60", "5.331799"], ["84183.10", "5.060690"], ["84174.60", "4.608843"], ["84166.10", "3.885887"], ["84157.60", "4.699212"], ["84149.10", "4.970321"], ["84132.10", "4.156996"], ["84123.60", "4.518473"], ["84115.10", "4.879951"], ["84106.60", "4.066626"], ["84098.10", "4.428104"], ["84089.60", "5.241429"], ["84072.60", "3.976257"], ["84064.10", "5.422168"], ["83893.81", "0.000010"], ["83893.64", "0.000039"], ["83893.62", "0.000137"], ["83892.29", "0.000143"], ["83891.43", "0.000455"], ["83891.30", "0.000010"], ["83888.89", "0.000163"], ["83888.86", "0.000371"]], "checksum": -1278685656, "ts": "1742142238036"}], "ts": 1742142238040, "record_time": 1742142237.147864}
{"action": "update", "arg": {"instType": "SPOT", "channel": "books", "instId": "BTCUSDT"}, "data": [{"asks": [["84290.66", "0.745374"], ["84292.45", "0.063809"], ["84299.08", "0.096224"], ["84299.09", "0"], ["84303.14", "0.080082"], ["84308.56", "0.001205"], ["84309.71", "0"], ["84311.27", "0.119869"], ["84312.38", "0.006356"], ["84312.52", "0.006356"], ["84312.69", "0.035952"], ["84314.05", "0.006356"], ["84314.50", "0.017341"], ["84315.00", "0.006356"], ["84315.13", "0"], ["84315.24", "0.006356"], ["84315.38", "0.006356"], ["84315.61", "0.006356"], ["84315.71", "0.016427"], ["84315.79", "0.006356"], ["84316.16", "0.006356"], ["84317.71", "0.006357"], ["84317.83", "0"], ["84317.87", "0.010984"], ["84318.14", "0.006356"], ["84319.03", "0"], ["84319.09", "0"], ["84319.17", "0"], ["84319.20", "0.009989"], ["84319.88", "0.119895"], ["84320.77", "0"], ["84320.86", "0.119879"], ["84320.91", "0"], ["84321.18", "0"], ["84321.81", "0"], ["84321.95", "0"], ["84322.02", "0"], ["84322.36", "0"], ["84322.45", "0"], ["84322.70", "0"], ["84324.28", "0"], ["84324.38", "0"], ["84324.85", "0"], ["84325.91", "0"], ["84326.32", "0"], ["84327.51", "0"], ["84328.90", "0.001046"], ["84330.90", "0.001707"], ["84332.20", "0"], ["84332.90", "0.004596"], ["84334.20", "0"], ["84334.90", "0.012084"], ["84336.20", "0"], ["84336.90", "0.031799"], ["84338.20", "0"], ["84338.90", "0.083683"], ["84340.20", "0"], ["84340.90", "0.220419"], ["84342.20", "0"], ["84342.90", "0.580050"], ["84344.20", "0"], ["84344.90", "1.526446"], ["84346.20", "0"], ["84346.90", "4.016963"], ["84348.20", "0"], ["84348.90", "10.570957"], ["84350.20", "0.069780"], ["84350.90", "0.001046"], ["84352.20", "5.825640"], ["84352.80", "0"], ["84352.90", "0"], ["84353.00", "0.425280"], ["84353.10", "0"], ["84353.40", "0"], ["84354.20", "0.076830"], ["84354.40", "0"], ["84355.60", "0.035580"], ["84355.90", "0.985470"], ["84356.20", "0.069600"], ["84356.50", "0.143250"], ["84358.90", "0"], ["84359.40", "0.015090"], ["84360.00", "0.032910"], ["84360.20", "0.015150"], ["84361.50", "0.035550"], ["84361.70", "0.410370"], ["84362.10", "0"], ["84363.60", "0"], ["84364.30", "0.248880"], ["84391.00", "5.512755"], ["84394.40", "0"], ["84399.50", "4.699398"], ["84402.90", "0"], ["84408.00", "3.886041"], ["84411.40", "0"], ["84416.50", "4.970517"], ["84419.90", "0"], ["84425.00", "4.066787"], ["84428.40", "0"], ["84433.50", "4.157160"], ["84436.90", "0"], ["84442.00", "4.609025"], ["84445.40", "0"], ["84450.50", "4.789771"], ["84453.90", "0"], ["84459.00", "4.428279"], ["84462.40", "0"], ["84467.50", "5.332009"], ["84470.90", "0"], ["84476.00", "5.060890"], ["84479.40", "0"], ["84484.50", "3.976414"], ["84487.90", "0"], ["84493.00", "5.241636"], ["84496.40", "0"], ["84501.50", "4.247533"], ["84504.90", "0"], ["84510.00", "4.518652"], ["84513.40", "0"], ["84518.50", "4.880144"], ["84521.90", "0"], ["84527.00", "5.151263"], ["84530.40", "0"], ["84535.50", "5.422382"], ["84538.90", "0"], ["84544.00", "5.603128"], ["84547.40", "0"], ["84552.50", "4.337906"], ["84555.90", "0"], ["84849.88", "0"]], "bids": [["84290.65", "2.655604"], ["84289.72", "0"], ["84287.80", "0"], ["84285.81", "0"], ["84285.80", "0"], ["84284.40", "0.001008"], ["84284.37", "0.000070"], ["84283.80", "0"], ["84282.40", "0.001018"], ["84281.80", "0"], ["84280.40", "0.001045"], ["84279.80", "0"], ["84278.40", "0.001415"], ["84277.80", "0"], ["84277.32", "0.195091"], ["84276.53", "0"], ["84276.40", "0.003723"], ["84275.80", "0"], ["84275.26", "0"], ["84274.50", "0"], ["84274.40", "0.009798"], ["84274.26", "0"], ["84274.18", "0"], ["84274.02", "0"], ["84274.00", "2.549435"], ["84273.80", "0"], ["84273.42", "0"], ["84273.30", "0"], ["84273.23", "0"], ["84273.20", "0"], ["84272.40", "0.025785"], ["84272.28", "0"], ["84272.13", "0"], ["84271.95", "0"], ["84271.87", "0"], ["84271.80", "0"], ["84271.18", "0"], ["84270.94", "0.006213"], ["84270.69", "0"], ["84270.60", "0"], ["84270.40", "0.067854"], ["84270.06", "0"], ["84269.96", "0.247978"], ["84269.80", "0"], ["84269.49", "0"], ["84269.43", "0"], ["84268.86", "0.084431"], ["84268.40", "0.178562"], ["84267.99", "0"], ["84267.85", "0.017834"], ["84267.80", "0"], ["84267.77", "0.005937"], ["84267.69", "0.015770"], ["84267.45", "0.016459"], ["84267.37", "0.018259"], ["84267.15", "0"], ["84266.79", "0.006564"], ["84266.63", "0.056349"], ["84266.61", "0.017077"], ["84266.52", "0.007119"], ["84266.40", "0.469902"], ["84266.20", "0"], ["84265.88", "0.007315"], ["84265.42", "0.022471"], ["84265.31", "0.017060"], ["84265.30", "0"], ["84264.77", "0.017330"], ["84264.60", "0"], ["84264.50", "0"], ["84264.40", "1.236584"], ["84264.30", "0.025082"], ["84264.04", "0.008164"], ["84263.93", "0.008282"], ["84263.50", "0.001006"], ["84263.35", "0.012648"], ["84263.30", "0.001260"], ["84263.10", "0.352920"], ["84263.08", "0.052103"], ["84262.80", "0.036570"], ["84262.78", "0.002949"], ["84262.72", "0.018518"], ["84262.70", "0.107430"], ["84261.56", "0.271876"], ["84261.40", "0"], ["84261.00", "0"], ["84260.50", "0.222711"], ["84259.70", "0.052260"], ["84258.80", "0.706620"], ["84258.00", "0.009030"], ["84256.00", "1.350000"], ["84255.10", "0"], ["84254.90", "0"], ["84254.60", "2.349030"], ["84254.20", "0.674880"], ["84252.40", "0.038460"], ["84251.80", "0.030000"], ["84251.20", "0.915360"], ["84250.90", "0"], ["84250.00", "0.533460"], ["84248.70", "0.410370"], ["84248.30", "0.090000"], ["84248.20", "0.065280"], ["84248.10", "0.009180"], ["84248.00", "0.056010"], ["84225.60", "0"], ["84222.30", "4.428279"], ["84217.10", "0"], ["84213.80", "3.976414"], ["84208.60", "0"], ["84205.30", "5.603128"], ["84200.10", "0"], ["84196.80", "5.332009"], ["84191.60", "0"], ["84188.30", "4.699398"], ["84183.10", "0"], ["84179.80", "4.157160"], ["84174.60", "0"], ["84171.30", "4.337906"], ["84166.10", "0"], ["84162.80", "3.886041"], ["84157.60", "0"], ["84154.30", "5.151263"], ["84149.10", "0"], ["84145.80", "5.512755"], ["84140.60", "0"], ["84137.30", "4.789771"], ["84132.10", "0"], ["84128.80", "5.060890"], ["84123.60", "0"], ["84120.30", "4.970517"], ["84115.10", "0"], ["84111.80", "5.241636"], ["84106.60", "0"], ["84103.30", "5.422382"], ["84098.10", "0"], ["84094.80", "4.609025"], ["84089.60", "0"], ["84086.30", "4.518652"], ["84081.10", "0"], ["84077.80", "4.066787"], ["84072.60", "0"], ["84069.30", "4.247533"], ["84064.10", "0.000014"], ["84060.80", "4.880144"], ["83891.43", "0"], ["83891.30", "0"], ["83888.89", "0"], ["83888.86", "0"]], "checksum": -1791518860, "ts": "1742142238241"}], "ts": 1742142238244, "record_time": 1742142237.352585}
{"action": "update", "arg": {"instType": "SPOT", "channel": "books", "instId": "BTCUSDT"}, "data": [{"asks": [["84292.44", "0.019143"], ["84299.08", "0"], ["84328.90", "0.001174"], ["84330.90", "0.001915"], ["84332.90", "0.005040"], ["84334.90", "0.013263"], ["84336.90", "0.034904"], ["84338.90", "0.091852"], ["84340.90", "0.241715"], ["84342.90", "0.636093"], ["84343.91", "0"], ["84344.01", "0.001597"], ["84344.90", "1.673928"], ["84345.84", "0.001597"], ["84345.85", "0"], ["84346.90", "4.405075"], ["84348.90", "11.592431"], ["84350.20", "0.070020"], ["84350.90", "0.001230"], ["84351.40", "0.001013"], ["84351.60", "0.433170"], ["84352.20", "1.408740"], ["84352.40", "0.009000"], ["84355.00", "0.142500"], ["84355.50", "0.269760"], ["84356.50", "1.067790"], ["84356.60", "0"], ["84357.30", "1.350000"], ["84359.20", "1.779300"], ["84362.70", "0"], ["84364.30", "0"], ["84391.00", "5.332009"], ["84399.50", "5.151263"], ["84408.00", "4.609025"], ["84416.50", "4.157160"], ["84425.00", "4.880144"], ["84433.50", "4.428279"], ["84442.00", "3.886041"], ["84450.50", "5.422382"], ["84459.00", "5.241636"], ["84467.50", "4.247533"], ["84476.00", "4.699398"], ["84484.50", "5.603128"], ["84493.00", "4.337906"], ["84501.50", "4.970517"], ["84510.00", "4.066787"], ["84518.50", "5.060890"], ["84527.00", "3.976414"], ["84535.50", "4.518652"], ["84544.00", "4.789771"], ["84552.50", "5.512755"], ["84847.58", "0"], ["84847.82", "0"]], "bids": [["84278.40", "0.001008"], ["84277.32", "0.820837"], ["84276.40", "0.001418"], ["84274.40", "0.003732"], ["84272.40", "0.009820"], ["84270.40", "0.025842"], ["84268.40", "0.068005"], ["84266.40", "0.178962"], ["84264.40", "0.470952"], ["84263.30", "0.001025"], ["84263.10", "0.353340"], ["84262.80", "0.036780"], ["84260.90", "0"], ["84259.70", "0.110970"], ["84258.80", "1.072200"], ["84258.10", "0.413400"], ["84257.00", "2.348940"], ["84256.00", "0"], ["84254.60", "0"], ["84251.80", "0"], ["84251.60", "0.492600"], ["84233.43", "0.001189"], ["84233.32", "0"], ["84231.39", "0"], ["84231.38", "0.001180"], ["84222.30", "5.151263"], ["84213.80", "4.699398"], ["84205.30", "5.512755"], ["84196.80", "5.241636"], ["84188.30", "5.332009"], ["84179.80", "4.247533"], ["84171.30", "4.880144"], ["84169.00", "0.012717"], ["84162.80", "4.428279"], ["84154.30", "4.337906"], ["84145.80", "5.603128"], ["84137.30", "4.157160"], ["84128.80", "4.789771"], ["84120.30", "4.518652"], ["84111.80", "3.976414"], ["84103.30", "3.886041"], ["84094.80", "5.422382"], ["84086.30", "4.066787"], ["84077.80", "4.970517"], ["84069.30", "5.060890"], ["84060.80", "4.609025"], ["83891.43", "0.000455"], ["83891.30", "0.000010"]], "checksum": 1379094980, "ts": "1742142238442"}], "ts": 1742142238446, "record_time": 1742142237.554078}
{"action": "update", "arg": {"instType": "SPOT", "channel": "books", "instId": "BTCUSDT"}, "data": [{"asks": [["84299.09", "0.209200"], ["84301.14", "0.032864"], ["84303.74", "0.003017"], ["84304.95", "0"], ["84332.90", "0.004876"], ["84334.90", "0.012832"], ["84336.90", "0.033768"], ["84338.90", "0.088862"], ["84340.90", "0.233848"], ["84342.90", "0.615388"], ["84344.90", "1.619443"], ["84346.90", "4.261693"], ["84348.90", "11.214982"], ["84351.60", "0.562920"], ["84352.10", "0.641670"], ["84352.20", "0.191610"], ["84354.20", "0.076650"], ["84362.20", "0"], ["84391.00", "5.603128"], ["84399.50", "4.066787"], ["84416.50", "4.518652"], ["84425.00", "3.886041"], ["84433.50", "4.699398"], ["84442.00", "5.422382"], ["84450.50", "3.976414"], ["84467.50", "5.060890"], ["84476.00", "5.512755"], ["84484.50", "4.970517"], ["84493.00", "5.151263"], ["84501.50", "4.157160"], ["84510.00", "5.332009"], ["84518.50", "4.428279"], ["84527.00", "4.337906"], ["84535.50", "4.247533"], ["84552.50", "4.880144"], ["84846.55", "0"], ["84846.85", "0"]], "bids": [["84270.90", "0.089145"], ["84264.40", "0.471212"], ["84263.10", "0.354270"], ["84260.90", "0.058710"], ["84259.70", "0.052260"], ["84256.00", "1.350000"], ["84253.60", "0.177960"], ["84252.10", "0.030360"], ["84251.60", "0.462600"], ["84248.10", "0"], ["84248.00", "0"], ["84222.30", "4.157160"], ["84213.80", "4.247533"], ["84205.30", "5.603128"], ["84196.80", "4.428279"], ["84188.30", "5.060890"], ["84179.80", "4.970517"], ["84171.30", "3.886041"], ["84162.80", "5.241636"], ["84154.30", "5.332009"], ["84145.80", "4.518652"], ["84137.30", "3.976414"], ["84128.80", "5.422382"], ["84120.30", "4.880144"], ["84111.80", "5.512755"], ["84103.30", "4.066787"], ["84094.80", "4.337906"], ["84086.30", "4.609025"], ["84077.80", "4.699398"], ["84069.30", "4.789771"], ["84060.80", "5.151263"], ["83892.29", "0"], ["83891.43", "0"], ["83891.30", "0"]], "checksum": -1382592417, "ts": "1742142238647"}], "ts": 1742142238649, "record_time": 1742142237.756588}
{"action": "update", "arg": {"instType": "SPOT", "channel": "books", "instId": "BTCUSDT"}, "data": [{"asks": [["84292.39", "0.063809"], ["84292.45", "0"], ["84299.08", "0.096224"], ["84301.14", "0"], ["84324.80", "0.010000"], ["84346.90", "4.261820"], ["84348.90", "11.215316"], ["84350.20", "0.069780"], ["84350.50", "0.035580"], ["84351.60", "0.563280"], ["84352.10", "0.641850"], ["84352.20", "0.191310"], ["84359.40", "0.132090"], ["84360.20", "0.195150"], ["84361.30", "0.135000"], ["84391.00", "4.157160"], ["84399.50", "5.241636"], ["84408.00", "3.886041"], ["84416.50", "5.512755"], ["84425.00", "5.603128"], ["84442.00", "5.332009"], ["84450.50", "4.337906"], ["84459.00", "5.151263"], ["84467.50", "5.422382"], ["84476.00", "4.428279"], ["84484.50", "3.976414"], ["84493.00", "4.970517"], ["84501.50", "4.880144"], ["84510.00", "4.066787"], ["84518.50", "4.789771"], ["84527.00", "4.609025"], ["84535.50", "5.060890"], ["84544.00", "4.518652"], ["84552.50", "4.247533"], ["84845.00", "0"], ["84845.94", "0"], ["84846.15", "0"]], "bids": [["84285.93", "0.010000"], ["84277.31", "0"], ["84274.40", "0.003876"], ["84272.40", "0.010200"], ["84270.40", "0.026841"], ["84268.40", "0.070635"], ["84266.40", "0.185882"], ["84264.41", "0.373529"], ["84264.40", "0.489161"], ["84263.30", "0"], ["84263.10", "0"], ["84262.80", "0.002430"], ["84262.70", "0.107610"], ["84262.50", "0.001033"], ["84261.70", "0.591750"], ["84260.90", "0.058890"], ["84259.70", "0.052080"], ["84258.80", "0.174510"], ["84257.70", "0.035580"], ["84257.00", "0"], ["84256.00", "0"], ["84254.30", "1.333650"], ["84254.20", "2.349030"], ["84251.80", "0.035580"], ["84248.20", "0"], ["84222.30", "4.428279"], ["84213.80", "4.880144"], ["84205.30", "5.332009"], ["84196.80", "4.337906"], ["84188.30", "4.699398"], ["84179.80", "5.422382"], ["84171.30", "4.970517"], ["84162.80", "5.603128"], ["84154.30", "3.976414"], ["84145.80", "5.060890"], ["84137.30", "5.512755"], ["84128.80", "5.241636"], ["84120.30", "4.789771"], ["84111.80", "4.066787"], ["84103.30", "4.609025"], ["84094.80", "5.151263"], ["84086.30", "4.518652"], ["84077.80", "4.247533"], ["84069.30", "3.886041"], ["84060.80", "4.157160"], ["83893.62", "0"]], "checksum": 948595824, "ts": "1742142238863"}], "ts": 1742142238866, "record_time": 1742142237.974039}
{"action": "update", "arg": {"instType": "SPOT", "channel": "books", "instId": "BTCUSDT"}, "data": [{"asks": [["84292.38", "0.019143"], ["84292.44", "0"], ["84305.41", "0.012680"], ["84332.78", "0"], ["84338.90", "0.088753"], ["84340.90", "0.233561"], ["84342.90", "0.614633"], ["84344.90", "1.617456"], ["84346.90", "4.256462"], ["84348.90", "11.201478"], ["84349.40", "0.001012"], ["84350.20", "0.070200"], ["84350.50", "0.036000"], ["84350.90", "0.001020"], ["84351.60", "0.563490"], ["84352.20", "0.178800"], ["84353.30", "0.025350"], ["84359.80", "0.198000"], ["84359.90", "0.090000"], ["84361.30", "0"], ["84361.40", "0"], ["84361.50", "0"], ["84361.70", "0"], ["84391.00", "4.699398"], ["84399.50", "3.976414"], ["84408.00", "4.428279"], ["84416.50", "4.157160"], ["84425.00", "5.422382"], ["84433.50", "5.060890"], ["84442.00", "4.880144"], ["84450.50", "5.151263"], ["84459.00", "4.789771"], ["84467.50", "5.603128"], ["84476.00", "5.512755"], ["84484.50", "4.247533"], ["84493.00", "3.886041"], ["84501.50", "5.332009"], ["84510.00", "4.609025"], ["84518.50", "5.241636"], ["84527.00", "4.518652"], ["84535.50", "4.337906"], ["84544.00", "4.970517"], ["84552.50", "4.066787"], ["84640.32", "0"], ["84643.89", "1.695719"]], "bids": [["84290.65", "2.515647"], ["84285.94", "0.003629"], ["84284.37", "0"], ["84278.81", "0.003006"], ["84278.25", "0.000070"], ["84274.42", "0"], ["84263.70", "0.001009"], ["84263.60", "0.355830"], ["84263.20", "0.692790"], ["84262.80", "0"], ["84262.70", "0.107430"], ["84262.50", "0"], ["84261.70", "0"], ["84259.70", "0.052260"], ["84258.80", "0.174690"], ["84254.30", "1.333440"], ["84253.30", "0"], ["84252.50", "0.030000"], ["84252.10", "0"], ["84248.30", "0"], ["84222.30", "4.970517"], ["84213.80", "5.603128"], ["84205.30", "4.247533"], ["84196.80", "4.789771"], ["84188.30", "3.886041"], ["84179.80", "5.060890"], ["84171.30", "4.880144"], ["84165.91", "0.125294"], ["84162.80", "4.337906"], ["84154.30", "5.241636"], ["84145.80", "3.976414"], ["84137.30", "4.157160"], ["84128.80", "5.422382"], ["84120.30", "5.332009"], ["84111.80", "4.518652"], ["84107.82", "0"], ["84103.30", "5.151263"], ["84094.80", "4.609025"], ["84086.30", "4.066787"], ["84077.80", "4.699398"], ["84069.30", "5.512755"], ["84060.80", "4.428279"], ["83969.42", "1.622280"], ["83965.88", "0"], ["83893.62", "0.000137"]], "checksum": -433822255, "ts": "1742142239069"}], "ts": 1742142239072, "record_time": 1742142238.180041}
{"action": "update", "arg": {"instType": "SPOT", "channel": "books", "instId": "BTCUSDT"}, "data": [{"asks": [["84292.32", "0.063809"], ["84292.38", "0"], ["84292.39", "0"], ["84299.09", "0"], ["84303.13", "0.028734"], ["84305.41", "0"], ["84308.35", "0"], ["84313.16", "0.006356"], ["84313.85", "0.006356"], ["84315.32", "0.016428"], ["84315.36", "0"], ["84316.14", "0"], ["84316.23", "0.006356"], ["84316.45", "0.119843"], ["84317.34", "0"], ["84318.46", "0"], ["84321.29", "0.009989"], ["84321.74", "0"], ["84323.33", "0.006356"], ["84324.20", "0"], ["84325.32", "0.015891"], ["84325.94", "0.010986"], ["84326.21", "0"], ["84326.62", "0"], ["84348.90", "11.201032"], ["84391.00", "3.886041"], ["84399.50", "5.422382"], ["84408.00", "4.066787"], ["84416.50", "5.060890"], ["84425.00", "5.151263"], ["84433.50", "4.518652"], ["84442.00", "4.157160"], ["84450.50", "4.247533"], ["84459.00", "5.332009"], ["84467.50", "4.337906"], ["84476.00", "4.699398"], ["84484.50", "4.970517"], ["84493.00", "4.880144"], ["84500.00", "0.011053"], ["84501.50", "5.241636"], ["84518.50", "5.603128"], ["84527.00", "4.789771"], ["84535.50", "4.428279"], ["84544.00", "3.976414"], ["84552.50", "5.512755"], ["84845.00", "0.000025"], ["84845.94", "0.000008"], ["84846.15", "0.004277"]], "bids": [["84289.50", "0.139927"], ["84277.93", "0.198329"], ["84266.41", "0"], ["84265.93", "0"], ["84265.59", "0.028805"], ["84265.04", "0.227652"], ["84264.30", "0.834810"], ["84263.60", "0.356490"], ["84263.20", "0.001290"], ["84261.10", "0.058890"], ["84260.90", "0"], ["84260.20", "0"], ["84259.76", "0.021106"], ["84258.62", "0"], ["84258.10", "0.413580"], ["84257.75", "0.012438"], ["84257.09", "0"], ["84256.20", "0.073499"], ["84256.00", "1.350000"], ["84255.82", "0"], ["84255.13", "0.056634"], ["84254.10", "0"], ["84252.50", "0"], ["84252.20", "0.023737"], ["84251.40", "0.525720"], ["84250.60", "0.030000"], ["84222.30", "4.157160"], ["84213.80", "5.422382"], ["84205.30", "4.699398"], ["84196.80", "4.247533"], ["84188.30", "5.060890"], ["84179.80", "4.609025"], ["84171.30", "5.603128"], ["84168.00", "0.000121"], ["84162.80", "5.241636"], ["84154.30", "3.976414"], ["84145.80", "4.518652"], ["84137.30", "4.789771"], ["84128.80", "3.886041"], ["84111.80", "5.512755"], ["84103.30", "4.337906"], ["84094.80", "4.428279"], ["84086.30", "4.880144"], ["84077.80", "4.066787"], ["84069.30", "4.970517"], ["84060.80", "5.151263"], ["83894.17", "0"], ["83893.81", "0"], ["83893.64", "0"], ["83893.62", "0"]], "checksum": -1903174281, "ts": "1742142239271"}], "ts": 1742142239274, "record_time": 1742142238.382041}
{"action": "update", "arg": {"instType": "SPOT", "channel": "books", "instId": "BTCUSDT"}, "data": [{"asks": [["84299.08", "0.033464"], ["84302.87", "0.007646"], ["84312.52", "0.019036"], ["84350.50", "0.001043"], ["84353.00", "0.425100"], ["84353.30", "0"], ["84357.30", "1.365090"], ["84357.70", "0.015150"], ["84359.40", "0.117000"], ["84360.20", "0.180000"], ["84391.00", "5.603128"], ["84399.50", "5.332009"], ["84408.00", "4.970517"], ["84416.50", "5.151263"], ["84425.00", "4.066787"], ["84442.00", "5.241636"], ["84450.50", "5.060890"], ["84459.00", "4.337906"], ["84467.50", "4.609025"], ["84476.00", "4.157160"], ["84484.50", "4.428279"], ["84493.00", "3.886041"], ["84501.50", "5.422382"], ["84510.00", "4.789771"], ["84518.50", "3.976414"], ["84527.00", "5.512755"], ["84535.50", "4.699398"], ["84544.00", "4.247533"], ["84552.50", "4.880144"]], "bids": [["84289.51", "0.041978"], ["84264.30", "0.836910"], ["84263.60", "0.355230"], ["84263.20", "0"], ["84262.80", "0.003780"], ["84262.70", "0.107610"], ["84258.80", "0.568500"], ["84258.10", "0.413400"], ["84250.60", "0"], ["84250.50", "0.030000"], ["84248.70", "0"], ["84222.30", "5.512755"], ["84213.80", "4.789771"], ["84205.30", "4.518652"], ["84196.80", "4.970517"], ["84188.30", "3.886041"], ["84179.80", "5.422382"], ["84171.30", "3.976414"], ["84162.80", "4.157160"], ["84154.30", "4.337906"], ["84145.80", "5.603128"], ["84137.30", "5.241636"], ["84128.80", "5.060890"], ["84120.30", "4.609025"], ["84111.80", "5.332009"], ["84103.30", "4.428279"], ["84094.80", "5.151263"], ["84086.30", "4.066787"], ["84077.80", "4.880144"], ["84069.30", "4.699398"], ["84060.80", "4.247533"]], "checksum": 600009056, "ts": "1742142239471"}], "ts": 1742142239477, "record_time": 1742142238.585543}
{"action": "update", "arg": {"instType": "SPOT", "channel": "books", "instId": "BTCUSDT"}, "data": [{"asks": [["84307.51", "0.181216"], ["84346.90", "4.256491"], ["84348.90", "11.201292"], ["84391.00", "5.332009"], ["84399.50", "5.603128"], ["84408.00", "4.880144"], ["84416.50", "4.428279"], ["84425.00", "5.512755"], ["84442.00", "5.151263"], ["84450.50", "3.976414"], ["84459.00", "5.060890"], ["84476.00", "4.066787"], ["84484.50", "4.789771"], ["84493.00", "4.247533"], ["84501.50", "4.337906"], ["84510.00", "4.157160"], ["84518.50", "3.886041"], ["84527.00", "4.699398"], ["84535.50", "4.970517"], ["84544.00", "5.422382"], ["84552.50", "5.241636"]], "bids": [["84290.65", "2.515807"], ["84280.63", "0.231997"], ["84271.07", "0.003069"], ["84264.41", "0"], ["84222.30", "4.337906"], ["84213.80", "5.603128"], ["84205.30", "3.976414"], ["84188.30", "4.428279"], ["84179.80", "5.060890"], ["84171.30", "4.699398"], ["84162.80", "4.247533"], ["84154.30", "5.332009"], ["84145.80", "5.422382"], ["84137.30", "4.880144"], ["84128.80", "4.157160"], ["84120.30", "4.789771"], ["84111.80", "4.609025"], ["84103.30", "4.518652"], ["84094.80", "4.066787"], ["84086.30", "3.886041"], ["84077.80", "5.151263"], ["84069.30", "5.512755"], ["84060.80", "5.241636"]], "checksum": 1679577880, "ts": "1742142239679"}], "ts": 1742142239683, "record_time": 1742142238.790253}
{"action": "update", "arg": {"instType": "SPOT", "channel": "books", "instId": "BTCUSDT"}, "data": [{"asks": [["84292.26", "0.063809"], ["84292.32", "0"], ["84300.00", "0.002198"], ["84321.15", "0.015892"], ["84321.72", "0"], ["84321.92", "0"], ["84328.90", "0.001003"], ["84330.70", "0.031812"], ["84330.90", "0.001636"], ["84332.00", "0.668868"], ["84332.90", "0.004307"], ["84334.90", "0.011205"], ["84336.90", "0.029485"], ["84338.90", "0.077592"], ["84340.90", "0.204191"], ["84342.90", "0.537345"], ["84344.90", "1.414065"], ["84346.90", "3.721225"], ["84348.90", "9.792695"], ["84350.20", "0.001013"], ["84351.60", "0.563700"], ["84354.20", "0.007050"], ["84355.50", "0"], ["84355.89", "1.110296"], ["84360.40", "0"], ["84360.80", "0"], ["84391.00", "5.151263"], ["84399.50", "5.241636"], ["84408.00", "4.428279"], ["84416.50", "3.976414"], ["84425.00", "4.066787"], ["84433.50", "4.337906"], ["84442.00", "4.970517"], ["84450.50", "3.886041"], ["84459.00", "4.699398"], ["84467.50", "4.518652"], ["84476.00", "5.332009"], ["84484.50", "5.603128"], ["84493.00", "4.157160"], ["84500.00", "0.010855"], ["84501.50", "4.247533"], ["84510.00", "5.060890"], ["84518.50", "4.880144"], ["84527.00", "5.422382"], ["84535.50", "4.609025"], ["84544.00", "4.789771"], ["84552.50", "5.512755"], ["84846.55", "0.000019"]], "bids": [["84280.40", "0.001247"], ["84278.40", "0.003284"], ["84278.25", "0"], ["84276.40", "0.008642"], ["84274.40", "0.022740"], ["84272.40", "0.059844"], ["84270.40", "0.157484"], ["84268.40", "0.414430"], ["84266.90", "0.308054"], ["84266.40", "1.090607"], ["84264.40", "2.870017"], ["84264.30", "1.267530"], ["84264.20", "0.142710"], ["84263.60", "0.354600"], ["84263.50", "0"], ["84262.80", "0.035580"], ["84260.72", "0"], ["84259.96", "0.076006"], ["84259.70", "0.052080"], ["84258.80", "3.851730"], ["84256.00", "2.043150"], ["84254.20", "0"], ["84251.70", "0.030000"], ["84251.60", "4.157370"], ["84250.50", "0"], ["84250.00", "0"], ["84249.40", "0"], ["84222.30", "4.157160"], ["84213.80", "4.880144"], ["84205.30", "5.422382"], ["84196.80", "4.789771"], ["84188.30", "4.518652"], ["84171.30", "4.609025"], ["84162.80", "4.970517"], ["84154.30", "4.699398"], ["84145.80", "3.976414"], ["84137.30", "5.332009"], ["84128.80", "5.241636"], ["84120.30", "5.603128"], ["84111.80", "4.428279"], ["84103.30", "3.886041"], ["84094.80", "5.151263"], ["84086.30", "4.247533"], ["84077.80", "4.066787"], ["84069.30", "4.337906"], ["84060.80", "5.512755"], ["83894.17", "0.000022"], ["83893.81", "0.000010"], ["83893.64", "0.000039"], ["83893.62", "0.000137"]], "checksum": -303899416, "ts": "1742142239879"}], "ts": 1742142239883, "record_time": 1742142238.990337}
{"action": "update", "arg": {"instType": "SPOT", "channel": "books", "instId": "BTCUSDT"}, "data": [{"asks": [["84298.21", "0"], ["84299.08", "0"], ["84307.52", "0"], ["84334.90", "0.011498"], ["84336.90", "0.030257"], ["84338.90", "0.079624"], ["84340.90", "0.209537"], ["84342.90", "0.551413"], ["84344.90", "1.451087"], ["84346.90", "3.818649"], ["84348.90", "10.049078"], ["84349.70", "0.482610"], ["84350.90", "0"], ["84351.40", "0"], ["84351.60", "0.433140"], ["84355.00", "0.412260"], ["84360.20", "0"], ["84391.00", "5.332009"], ["84399.50", "5.151263"], ["84408.00", "3.976414"], ["84416.50", "4.337906"], ["84425.00", "4.699398"], ["84433.50", "4.970517"], ["84442.00", "4.518652"], ["84450.50", "4.066787"], ["84459.00", "4.789771"], ["84467.50", "4.428279"], ["84476.00", "5.603128"], ["84484.50", "4.247533"], ["84493.00", "5.060890"], ["84501.50", "5.512755"], ["84510.00", "4.880144"], ["84518.50", "4.609025"], ["84527.00", "4.157160"], ["84535.50", "5.241636"], ["84544.00", "5.422382"], ["84552.50", "3.886041"], ["84846.85", "0.000176"], ["84847.58", "0.000039"], ["84847.82", "0.000671"], ["84849.88", "0.000030"], ["84850.00", "0.000031"]], "bids": [["84290.65", "2.515537"], ["84280.40", "0.001006"], ["84278.84", "0.000070"], ["84278.40", "0.002542"], ["84276.40", "0.006690"], ["84274.40", "0.017606"], ["84272.40", "0.046331"], ["84270.40", "0.121923"], ["84268.40", "0.320851"], ["84266.40", "0.844343"], ["84264.40", "2.221956"], ["84264.30", "0.837330"], ["84264.20", "0.001036"], ["84263.60", "0.355020"], ["84262.70", "0.107430"], ["84261.10", "0"], ["84260.90", "0.058710"], ["84258.80", "0"], ["84256.30", "3.671340"], ["84253.30", "0.274590"], ["84252.70", "0.030000"], ["84251.70", "0"], ["84251.40", "0.537720"], ["84251.20", "0"], ["84222.30", "5.060890"], ["84213.80", "3.886041"], ["84205.30", "4.699398"], ["84196.80", "4.247533"], ["84188.30", "4.609025"], ["84179.80", "4.970517"], ["84171.30", "5.422382"], ["84167.00", "0"], ["84162.80", "5.151263"], ["84154.30", "5.241636"], ["84145.80", "5.332009"], ["84137.30", "3.976414"], ["84128.80", "4.157160"], ["84120.30", "4.518652"], ["84111.80", "4.337906"], ["84103.30", "4.789771"], ["84094.80", "5.512755"], ["84086.30", "5.603128"], ["84069.30", "4.428279"], ["84060.80", "4.880144"]], "checksum": 1891980884, "ts": "1742142240083"}], "ts": 1742142240087, "record_time": 1742142239.202421}
{"action": "update", "arg": {"instType": "SPOT", "channel": "books", "instId": "BTCUSDT"}, "data": [{"asks": [["84292.26", "0"], ["84307.51", "0.094863"], ["84307.52", "0.209200"], ["84312.52", "0.006356"], ["84315.56", "0.012680"], ["84324.80", "0"], ["84330.90", "0.001023"], ["84332.90", "0.001036"], ["84334.90", "0.001854"], ["84336.90", "0.004878"], ["84338.90", "0.012837"], ["84340.90", "0.033783"], ["84342.90", "0.088901"], ["84344.90", "0.233950"], ["84346.90", "0.615658"], ["84348.90", "1.620153"], ["84349.40", "0.558750"], ["84349.70", "0.001048"], ["84349.80", "0.087690"], ["84349.90", "2.348700"], ["84350.20", "0"], ["84350.50", "0"], ["84352.10", "0.398790"], ["84352.20", "0.934410"], ["84353.00", "0"], ["84355.00", "0.142500"], ["84355.60", "0"], ["84356.20", "0"], ["84356.50", "0.143250"], ["84359.20", "0"], ["84360.20", "0.180000"], ["84391.00", "5.422382"], ["84399.50", "4.066787"], ["84408.00", "4.337906"], ["84416.50", "4.609025"], ["84425.00", "4.518652"], ["84433.50", "4.428279"], ["84442.00", "5.241636"], ["84450.50", "5.603128"], ["84459.00", "5.060890"], ["84459.56", "0.209200"], ["84467.50", "4.699398"], ["84476.00", "3.886041"], ["84484.50", "5.332009"], ["84493.00", "3.976414"], ["84501.50", "4.247533"], ["84510.00", "5.151263"], ["84518.50", "5.512755"], ["84535.50", "4.880144"], ["84544.00", "4.970517"], ["84552.50", "4.789771"], ["84851.66", "0.000029"], ["84852.81", "0.000115"]], "bids": [["84290.65", "2.724737"], ["84282.26", "0.000070"], ["84280.40", "0.001022"], ["84278.84", "0"], ["84278.40", "0.002546"], ["84276.40", "0.006700"], ["84274.40", "0.017632"], ["84272.40", "0.046401"], ["84270.40", "0.122108"], ["84268.40", "0.321337"], ["84266.40", "0.845622"], ["84264.40", "2.225323"], ["84264.30", "1.275030"], ["84264.20", "0.142710"], ["84263.60", "0.354600"], ["84262.70", "0.199290"], ["84261.10", "0.058710"], ["84260.90", "0"], ["84260.80", "2.348850"], ["84259.80", "0.069600"], ["84256.30", "1.371360"], ["84253.30", "0"], ["84251.20", "0.915360"], ["84222.30", "4.970517"], ["84213.80", "4.518652"], ["84205.30", "4.247533"], ["84196.80", "5.060890"], ["84188.30", "4.880144"], ["84179.80", "5.332009"], ["84171.30", "4.157160"], ["84162.80", "4.066787"], ["84154.30", "4.609025"], ["84145.80", "4.699398"], ["84137.30", "4.428279"], ["84128.80", "3.886041"], ["84120.30", "4.789771"], ["84106.37", "0"], ["84103.30", "5.151263"], ["84094.80", "5.241636"], ["84077.80", "5.512755"], ["84069.30", "3.976414"], ["84060.80", "5.422382"], ["83893.62", "0"]], "checksum": -1640594622, "ts": "1742142240284"}], "ts": 1742142240292, "record_time": 1742142239.399854}
{"action": "update", "arg": {"instType": "SPOT", "channel": "books", "instId": "BTCUSDT"}, "data": [{"asks": [["84290.66", "0.502174"], ["84292.21", "0.063809"], ["84307.52", "0"], ["84334.90", "0.001311"], ["84336.90", "0.003657"], ["84338.90", "0.009623"], ["84340.90", "0.025324"], ["84342.90", "0.066643"], ["84344.90", "0.175374"], ["84346.90", "0.461512"], ["84348.90", "1.214506"], ["84349.40", "0.930990"], ["84349.80", "0.178440"], ["84349.90", "0"], ["84352.10", "0.596520"], ["84352.40", "0.267030"], ["84353.40", "0.178830"], ["84355.00", "2.348580"], ["84355.89", "0"], ["84356.00", "0.667320"], ["84356.50", "0"], ["84357.30", "0.015090"], ["84359.80", "0"], ["84359.90", "0"], ["84391.00", "5.151263"], ["84399.50", "4.157160"], ["84416.50", "5.060890"], ["84425.00", "5.422382"], ["84433.50", "4.247533"], ["84450.50", "4.789771"], ["84459.00", "5.603128"], ["84467.50", "4.518652"], ["84476.00", "4.609025"], ["84484.50", "3.886041"], ["84493.00", "4.428279"], ["84501.50", "4.066787"], ["84510.00", "4.880144"], ["84527.00", "4.970517"], ["84535.50", "3.976414"], ["84544.00", "5.332009"], ["84552.50", "4.699398"], ["84852.94", "0.000065"], ["84853.56", "0.000050"], ["84857.14", "0.000347"]], "bids": [["84282.26", "0"], ["84280.40", "0.001695"], ["84278.40", "0.004462"], ["84276.40", "0.011741"], ["84274.40", "0.030896"], ["84272.40", "0.081306"], ["84270.40", "0.213964"], ["84268.40", "0.563062"], ["84266.40", "1.481742"], ["84264.40", "3.899323"], ["84264.30", "2.080860"], ["84261.10", "0"], ["84260.80", "0"], ["84259.00", "0.274590"], ["84258.60", "1.072740"], ["84257.10", "0.915360"], ["84256.30", "0"], ["84252.80", "0.030000"], ["84252.70", "0"], ["84251.20", "0"], ["84222.30", "4.337906"], ["84213.80", "5.060890"], ["84205.30", "5.241636"], ["84196.80", "3.886041"], ["84188.30", "4.699398"], ["84179.80", "3.976414"], ["84171.30", "5.151263"], ["84162.80", "4.789771"], ["84154.30", "4.970517"], ["84145.80", "4.880144"], ["84137.30", "5.512755"], ["84128.80", "4.157160"], ["84120.30", "4.428279"], ["84111.80", "4.247533"], ["84103.30", "4.066787"], ["84094.80", "5.603128"], ["84086.30", "4.518652"], ["84077.80", "4.609025"], ["84069.30", "5.422382"], ["84060.80", "5.332009"], ["83893.62", "0.000137"], ["83892.29", "0.000143"]], "checksum": -774216159, "ts": "1742142240486"}], "ts": 1742142240494, "record_time": 1742142239.601732}
{"action": "update", "arg": {"instType": "SPOT", "channel": "books", "instId": "BTCUSDT"}, "data": [{"asks": [["84290.66", "0"], ["84292.21", "0"], ["84298.22", "0"], ["84301.15", "0"], ["84303.13", "0"], ["84303.14", "0"], ["84307.51", "0"], ["84311.27", "0"], ["84315.56", "0"], ["84315.95", "0"], ["84316.23", "0"], ["84320.76", "0"], ["84330.70", "0"], ["84334.90", "0.001042"], ["84336.90", "0.001045"], ["84338.90", "0.001489"], ["84340.90", "0.003920"], ["84342.90", "0.010314"], ["84344.90", "0.027143"], ["84346.90", "0.071429"], ["84348.90", "0.187972"], ["84349.40", "0.001470"], ["84349.80", "0.178620"], ["84352.10", "0"], ["84352.20", "0.755790"], ["84352.30", "0.012000"], ["84352.40", "0.009000"], ["84355.00", "0"], ["84355.90", "0"], ["84356.50", "0.178830"], ["84357.50", "0.258030"], ["84359.40", "0"], ["84360.20", "0"], ["84360.40", "2.492610"], ["84360.80", "0.013860"], ["84391.00", "5.241636"], ["84399.16", "0"], ["84408.00", "4.699398"], ["84425.00", "4.609025"], ["84433.50", "3.886041"], ["84442.00", "4.880144"], ["84450.50", "5.151263"], ["84459.00", "5.422382"], ["84467.50", "5.512755"], ["84476.00", "5.603128"], ["84484.50", "4.066787"], ["84493.00", "4.970517"], ["84501.50", "3.976414"], ["84510.00", "5.332009"], ["84518.50", "4.518652"], ["84527.00", "4.789771"], ["84535.50", "4.247533"], ["84544.00", "4.428279"], ["84552.50", "4.337906"], ["84858.75", "0.000285"], ["84859.29", "0.000036"], ["84860.00", "0.000169"], ["84862.90", "0.000169"], ["84864.69", "0.000052"], ["84864.86", "0.000041"], ["84864.99", "0.000033"], ["84866.10", "0.000064"], ["84866.40", "0.000018"], ["84867.80", "0.000095"], ["84868.42", "0.000031"], ["84868.52", "0.000013"], ["84868.65", "0.000035"], ["84869.57", "0.000932"]], "bids": [["84290.66", "0.119900"], ["84290.65", "2.720889"], ["84280.40", "0.002345"], ["84278.81", "0"], ["84278.40", "0.006171"], ["84276.40", "0.016241"], ["84274.40", "0.042738"], ["84274.00", "0"], ["84273.24", "0"], ["84272.40", "0.112469"], ["84271.07", "0"], ["84270.90", "0.134438"], ["84270.40", "0.295971"], ["84269.96", "0"], ["84268.40", "0.778872"], ["84266.40", "2.049664"], ["84264.77", "0"], ["84264.40", "5.393851"], ["84264.30", "1.722480"], ["84264.20", "0.142890"], ["84263.80", "0.274800"], ["84263.70", "0"], ["84263.60", "0.354570"], ["84262.78", "0"], ["84262.70", "0.361170"], ["84259.80", "0.069780"], ["84259.00", "0"], ["84256.00", "1.350000"], ["84252.90", "0.177150"], ["84250.00", "0.533460"], ["84249.40", "0.090870"], ["84222.30", "5.422382"], ["84213.80", "5.241636"], ["84205.30", "4.066787"], ["84196.80", "4.337906"], ["84188.30", "5.512755"], ["84179.80", "5.332009"], ["84171.30", "4.789771"], ["84162.80", "5.603128"], ["84154.30", "5.060890"], ["84145.80", "4.247533"], ["84137.30", "4.518652"], ["84128.80", "4.428279"], ["84120.30", "5.151263"], ["84111.80", "4.699398"], ["84103.30", "4.157160"], ["84100.81", "0.179853"], ["84094.80", "4.609025"], ["84086.30", "4.880144"], ["84077.80", "3.976414"], ["84069.30", "4.970517"], ["84060.80", "3.886041"], ["83891.43", "0.000455"], ["83891.30", "0.000010"], ["83888.89", "0.000163"]], "checksum": -62729120, "ts": "1742142240686"}], "ts": 1742142240693, "record_time": 1742142239.801155}
{"action": "update", "arg": {"instType": "SPOT", "channel": "books", "instId": "BTCUSDT"}, "data": [{"asks": [["84290.67", "0"], ["84290.70", "0.000100"], ["84290.71", "0.000100"], ["84295.44", "0.063807"], ["84304.58", "0.139904"], ["84309.87", "0.080082"], ["84312.12", "0"], ["84312.38", "0"], ["84312.52", "0"], ["84312.69", "0"], ["84313.16", "0"], ["84313.85", "0"], ["84314.05", "0"], ["84314.50", "0"], ["84315.00", "0"], ["84315.23", "0.014632"], ["84315.24", "0"], ["84315.32", "0"], ["84315.38", "0"], ["84315.61", "0"], ["84315.71", "0"], ["84315.79", "0"], ["84316.16", "0"], ["84316.44", "0.053304"], ["84316.45", "0"], ["84317.71", "0"], ["84317.87", "0"], ["84318.13", "0"], ["84318.14", "0.119869"], ["84319.20", "0"], ["84319.53", "0"], ["84319.88", "0"], ["84319.96", "0.006356"], ["84320.09", "0.006356"], ["84320.19", "0.035952"], ["84320.86", "0"], ["84321.15", "0"], ["84321.29", "0"], ["84321.44", "0.006356"], ["84322.03", "0.006356"], ["84322.13", "0.006356"], ["84322.31", "0.010985"], ["84322.47", "0.006356"], ["84322.97", "0.012712"], ["84323.09", "0.012680"], ["84323.13", "0.006356"], ["84323.22", "0.006356"], ["84323.28", "0.016427"], ["84323.32", "0.016428"], ["84323.33", "0"], ["84323.38", "0.006356"], ["84323.62", "0.006356"], ["84323.84", "0.006356"], ["84324.14", "0.006356"], ["84324.20", "0.119843"], ["84325.17", "0"], ["84325.32", "0"], ["84325.42", "0.006357"], ["84325.83", "0.010984"], ["84325.94", "0"], ["84326.11", "0.006356"], ["84327.15", "0.009989"], ["84327.85", "0.119895"], ["84328.80", "0.009989"], ["84328.82", "0.119879"], ["84328.90", "0"], ["84329.29", "0.015892"], ["84330.90", "0"], ["84331.00", "0.017792"], ["84331.40", "0.006356"], ["84331.85", "0.148098"], ["84332.20", "0.001029"], ["84332.57", "0.001807"], ["84332.90", "0"], ["84333.06", "0.015891"], ["84334.20", "0.010986"], ["84334.90", "0"], ["84336.20", "0.001012"], ["84336.27", "0.010000"], ["84336.90", "0"], ["84338.20", "0.001018"], ["84338.90", "0"], ["84340.20", "0.001130"], ["84340.90", "0"], ["84342.20", "0.002794"], ["84342.90", "0"], ["84344.20", "0.007353"], ["84344.90", "0"], ["84346.20", "0.019350"], ["84346.90", "0"], ["84348.20", "0.050921"], ["84348.90", "0"], ["84349.40", "0"], ["84349.70", "0"], ["84349.80", "0"], ["84350.20", "0.134002"], ["84351.60", "0"], ["84352.20", "0.352637"], ["84352.30", "0.012420"], ["84352.40", "0.009630"], ["84353.10", "0.001001"], ["84353.40", "0.179010"], ["84356.00", "0"], ["84357.30", "0"], ["84357.50", "0.415890"], ["84357.70", "0"], ["84360.00", "0.002000"], ["84360.40", "0.204870"], ["84360.50", "0.015150"], ["84360.80", "0.028950"], ["84362.20", "0.078210"], ["84363.10", "0.032910"], ["84364.20", "0.708870"], ["84364.30", "0.391920"], ["84365.30", "0.258030"], ["84365.90", "0.469080"], ["84391.00", "0"], ["84394.40", "5.602908"], ["84399.50", "0"], ["84400.46", "0"], ["84402.90", "5.151060"], ["84408.00", "0"], ["84411.40", "3.885888"], ["84416.50", "0"], ["84419.90", "4.789582"], ["84425.00", "0"], ["84427.05", "0.072042"], ["84427.41", "0.072042"], ["84428.40", "4.879952"], ["84433.50", "0"], ["84436.90", "5.422169"], ["84442.00", "0"], ["84445.40", "5.060691"], ["84450.50", "0"], ["84453.90", "4.066627"], ["84459.00", "0"], ["84462.40", "5.512538"], ["84467.50", "0"], ["84467.99", "0.209200"], ["84470.90", "4.970321"], ["84476.00", "0"], ["84479.40", "4.337735"], ["84484.50", "0"], ["84487.90", "5.241430"], ["84493.00", "0"], ["84496.40", "4.428104"], ["84501.50", "0"], ["84504.90", "5.331799"], ["84510.00", "0"], ["84513.40", "4.247366"], ["84518.50", "0"], ["84521.90", "4.518474"], ["84527.00", "0"], ["84530.40", "4.608843"], ["84535.50", "0"], ["84538.90", "4.156996"], ["84544.00", "0"], ["84547.40", "4.699213"], ["84552.50", "0"], ["84555.90", "3.976257"], ["84862.90", "0"], ["84864.69", "0"], ["84864.86", "0"], ["84864.99", "0"], ["84866.10", "0"], ["84866.40", "0"], ["84867.80", "0"], ["84868.42", "0"], ["84868.52", "0"], ["84868.65", "0"], ["84869.57", "0"]], "bids": [["84290.67", "2.273281"], ["84290.66", "1.732684"], ["84290.65", "0.000164"], ["84289.51", "0"], ["84287.80", "0.001197"], ["84285.93", "0"], ["84285.80", "0.001954"], ["84284.48", "2.549278"], ["84284.40", "0"], ["84283.80", "0.005365"], ["84282.40", "0"], ["84281.80", "0.014118"], ["84280.40", "0"], ["84279.80", "0.037153"], ["84279.73", "0.221421"], ["84278.40", "0"], ["84277.80", "0.097770"], ["84277.32", "0.035930"], ["84276.84", "0.247978"], ["84276.40", "0"], ["84276.35", "0.084431"], ["84275.80", "0.257291"], ["84275.75", "0.005937"], ["84275.66", "0.015770"], ["84275.43", "0.016459"], ["84275.41", "0.017834"], ["84274.95", "0.018259"], ["84274.76", "0.006564"], ["84274.58", "0.017077"], ["84274.49", "0.007119"], ["84274.43", "0.056349"], ["84274.40", "0"], ["84273.80", "0.677081"], ["84273.59", "0.028805"], ["84273.39", "0.015247"], ["84273.09", "0.008987"], ["84272.90", "0.017060"], ["84272.78", "0.227652"], ["84272.40", "0"], ["84271.86", "0.042412"], ["84271.80", "1.781792"], ["84271.63", "0.008282"], ["84271.62", "0.008164"], ["84271.32", "0.012648"], ["84271.04", "0.052103"], ["84270.90", "0.089145"], ["84270.67", "0.018518"], ["84270.40", "0"], ["84269.80", "4.688925"], ["84269.52", "0.271876"], ["84268.86", "0"], ["84268.46", "0.222711"], ["84268.40", "0"], ["84268.37", "0.002949"], ["84268.09", "0.076006"], ["84267.85", "0"], ["84267.80", "12.339277"], ["84267.77", "0"], ["84267.70", "0.406590"], ["84267.69", "0"], ["84267.60", "0.001025"], ["84267.45", "0"], ["84267.40", "0.001031"], ["84267.37", "0"], ["84267.26", "0.021106"], ["84267.20", "5.068860"], ["84267.10", "0.405570"], ["84266.90", "0.068536"], ["84266.79", "0"], ["84266.63", "0"], ["84266.61", "0"], ["84266.52", "0"], ["84266.40", "0"], ["84266.10", "0.035580"], ["84266.00", "0.414900"], ["84265.88", "0"], ["84265.82", "0.012438"], ["84265.80", "0.069600"], ["84265.67", "0"], ["84265.59", "0"], ["84265.42", "0.005552"], ["84265.31", "0"], ["84265.04", "0"], ["84264.60", "0.915360"], ["84264.40", "1.489620"], ["84264.30", "0"], ["84264.20", "0.142500"], ["84264.04", "0"], ["84263.93", "0.073499"], ["84263.80", "0.069600"], ["84263.60", "0"], ["84263.39", "0.056634"], ["84263.35", "0"], ["84263.08", "0"], ["84262.80", "0.157980"], ["84262.72", "0"], ["84262.70", "0"], ["84261.56", "0"], ["84261.00", "0.035580"], ["84260.50", "0.269760"], ["84259.96", "0"], ["84259.80", "0.069600"], ["84259.76", "0"], ["84259.70", "0.142080"], ["84259.10", "0.015120"], ["84258.60", "0.585600"], ["84258.10", "0"], ["84257.75", "0"], ["84257.70", "0"], ["84257.45", "0"], ["84257.30", "0.025350"], ["84257.10", "0"], ["84256.80", "0.038460"], ["84256.20", "0"], ["84255.70", "0"], ["84255.13", "0"], ["84255.10", "0.062760"], ["84254.41", "0"], ["84254.30", "2.797830"], ["84252.90", "0"], ["84252.80", "0"], ["84252.40", "0"], ["84252.30", "0"], ["84251.80", "0"], ["84251.60", "0"], ["84251.40", "0"], ["84250.00", "0"], ["84249.40", "0"], ["84240.20", "0.013678"], ["84225.60", "5.331799"], ["84222.30", "0"], ["84217.10", "4.608843"], ["84213.80", "0"], ["84208.73", "0.072042"], ["84208.60", "4.156996"], ["84205.30", "0"], ["84200.10", "5.512538"], ["84196.80", "0"], ["84191.60", "5.060691"], ["84188.30", "0"], ["84183.10", "5.241430"], ["84179.80", "0"], ["84174.60", "4.066627"], ["84171.30", "0"], ["84169.00", "0.012838"], ["84166.10", "3.976257"], ["84162.80", "0"], ["84157.60", "5.602908"], ["84154.30", "0"], ["84149.10", "5.151060"], ["84145.80", "0"], ["84140.60", "4.970321"], ["84137.30", "0"], ["84132.10", "4.879952"], ["84128.80", "0"], ["84123.60", "3.885888"], ["84120.30", "0"], ["84115.10", "5.422169"], ["84111.80", "0"], ["84106.60", "4.789582"], ["84103.30", "0"], ["84098.10", "4.247366"], ["84094.80", "0"], ["84089.60", "4.428104"], ["84086.30", "0"], ["84081.10", "4.699213"], ["84077.80", "0"], ["84072.60", "4.337735"], ["84069.30", "0"], ["84064.10", "4.518474"], ["84060.80", "0"], ["83891.30", "0"], ["83888.89", "0"]], "checksum": -1949180417, "ts": "1742142240902"}], "ts": 1742142240906, "record_time": 1742142240.016069}
{"action": "update", "arg": {"instType": "SPOT", "channel": "books", "instId": "BTCUSDT"}, "data": [{"asks": [["84290.68", "0"], ["84290.69", "0"], ["84290.70", "0"], ["84290.71", "0"], ["84295.44", "0"], ["84297.98", "0"], ["84298.00", "0"], ["84298.03", "0"], ["84298.06", "0"], ["84298.12", "0"], ["84298.88", "0"], ["84298.94", "0"], ["84298.99", "0"], ["84300.00", "0"], ["84301.77", "0"], ["84301.79", "0"], ["84301.83", "0"], ["84301.84", "0"], ["84302.54", "0"], ["84302.75", "0"], ["84302.78", "0"], ["84302.80", "0"], ["84302.82", "0"], ["84302.83", "0"], ["84302.87", "0"], ["84303.74", "0"], ["84304.58", "0"], ["84307.74", "0"], ["84308.56", "0"], ["84309.87", "0"], ["84310.85", "0.000443"], ["84311.66", "0"], ["84313.78", "0.002907"], ["84315.13", "0.007385"], ["84315.14", "0"], ["84315.17", "0.007110"], ["84315.23", "0"], ["84316.44", "0"], ["84316.91", "0.003017"], ["84318.14", "0"], ["84319.96", "0"], ["84320.09", "0"], ["84320.19", "0"], ["84321.44", "0"], ["84322.03", "0"], ["84322.13", "0"], ["84322.31", "0"], ["84322.47", "0"], ["84322.97", "0"], ["84323.09", "0"], ["84323.13", "0"], ["84323.18", "0"], ["84323.22", "0"], ["84323.28", "0"], ["84323.32", "0"], ["84323.38", "0"], ["84323.62", "0"], ["84323.84", "0"], ["84324.14", "0"], ["84324.20", "0"], ["84324.72", "0"], ["84325.42", "0"], ["84325.83", "0"], ["84326.11", "0"], ["84327.15", "0"], ["84327.38", "0"], ["84327.85", "0"], ["84328.80", "0"], ["84328.82", "0"], ["84329.29", "0"], ["84330.13", "0.006356"], ["84331.00", "0"], ["84331.40", "0"], ["84331.61", "0.006356"], ["84331.85", "0"], ["84332.01", "0"], ["84332.02", "0.006356"], ["84332.08", "0.006356"], ["84332.20", "0"], ["84332.52", "0.075500"], ["84332.57", "0"], ["84333.06", "0"], ["84334.20", "0"], ["84336.20", "0"], ["84336.27", "0"], ["84336.74", "0.009989"], ["84338.20", "0"], ["84338.96", "0.009989"], ["84340.20", "0"], ["84342.20", "0"], ["84342.74", "0.001807"], ["84344.01", "0"], ["84344.20", "0"], ["84345.84", "0"], ["84345.90", "0.001003"], ["84346.20", "0"], ["84347.90", "0.001049"], ["84348.20", "0"], ["84349.90", "0.001034"], ["84350.20", "0"], ["84351.90", "0.001012"], ["84352.20", "0"], ["84352.30", "0"], ["84352.40", "0"], ["84353.10", "0"], ["84353.40", "0"], ["84353.90", "0.001013"], ["84354.20", "0"], ["84355.90", "0.001030"], ["84356.50", "0"], ["84357.50", "0"], ["84357.90", "0.001018"], ["84358.20", "0"], ["84359.90", "0.001047"], ["84360.40", "0"], ["84360.50", "0"], ["84360.80", "0"], ["84361.90", "0.001034"], ["84362.20", "0"], ["84363.10", "0"], ["84363.90", "0.001022"], ["84364.20", "0"], ["84364.30", "0"], ["84365.30", "0"], ["84365.90", "0.001039"], ["84366.20", "0.007260"], ["84366.30", "0.001005"], ["84367.10", "0.010350"], ["84367.20", "0.001009"], ["84368.00", "0.001024"], ["84368.60", "0.015090"], ["84368.70", "0.090300"], ["84369.10", "0.009000"], ["84370.20", "0.007050"], ["84370.50", "0.071250"], ["84373.50", "0.178140"], ["84374.20", "0.007050"], ["84374.60", "0.090000"], ["84376.00", "0.012660"], ["84376.10", "0.258030"], ["84376.40", "0.117000"], ["84376.90", "0.060000"], ["84377.30", "0.069870"], ["84377.50", "0.009000"], ["84378.00", "0.198000"], ["84378.20", "0.007050"], ["84378.80", "0.099000"], ["84379.50", "0.360000"], ["84379.70", "0.469080"], ["84380.60", "0.985470"], ["84386.40", "0"], ["84394.40", "0"], ["84399.47", "0"], ["84402.90", "0"], ["84408.10", "4.969511"], ["84411.40", "0"], ["84416.60", "5.059866"], ["84419.90", "0"], ["84425.10", "3.975609"], ["84427.20", "0.304146"], ["84428.40", "0"], ["84431.42", "0.057629"], ["84433.60", "4.065964"], ["84436.90", "0"], ["84442.10", "4.337028"], ["84445.40", "0"], ["84450.60", "4.246673"], ["84453.90", "0"], ["84459.10", "4.427383"], ["84462.40", "0"], ["84467.60", "4.517738"], ["84470.90", "0"], ["84476.10", "5.511640"], ["84476.42", "0.209200"], ["84479.40", "0"], ["84484.60", "5.240576"], ["84487.90", "0"], ["84493.10", "4.879157"], ["84496.40", "0"], ["84501.60", "4.608092"], ["84504.90", "0"], ["84510.10", "3.885254"], ["84513.40", "0"], ["84518.60", "4.698447"], ["84521.90", "0"], ["84527.10", "5.601995"], ["84530.40", "0"], ["84535.60", "5.150221"], ["84538.90", "0"], ["84544.10", "5.330930"], ["84547.40", "0"], ["84552.60", "4.156319"], ["84555.90", "0"], ["84561.10", "4.788802"], ["84569.60", "5.421285"], ["84862.90", "0.000169"], ["84864.69", "0.000052"], ["84864.86", "0.000041"], ["84864.99", "0.000033"], ["84866.10", "0.000064"], ["84866.40", "0.000018"], ["84867.80", "0.000095"], ["84868.42", "0.000031"], ["84868.52", "0.000013"], ["84868.65", "0.000035"], ["84869.57", "0.000932"], ["84871.66", "0.000078"], ["84871.79", "0.000014"], ["84873.84", "0.000057"], ["84874.79", "0.000096"], ["84875.00", "0.000959"], ["84875.78", "0.000038"], ["84876.03", "0.000161"], ["84879.10", "0.000009"], ["84879.37", "0.000009"], ["84879.59", "0.000173"], ["84880.00", "0.025078"], ["84880.89", "0.000065"], ["84882.35", "0.000417"], ["84883.65", "0.000008"], ["84883.72", "0.000010"], ["84883.84", "0.000040"], ["84885.24", "0.000112"], ["84885.53", "0.000022"], ["84886.01", "0.000023"], ["84886.02", "0.000054"], ["84886.96", "0.000013"], ["84887.65", "0.000019"], ["84888.00", "0.000010"], ["84888.68", "0.000013"], ["84888.89", "0.000113"], ["84889.87", "0.000010"], ["84890.00", "0.000118"], ["84892.02", "0.000099"], ["84892.76", "0.000096"], ["84892.78", "0.000013"], ["84894.73", "0.000019"], ["84894.74", "0.000208"], ["84895.69", "0.000135"], ["84895.83", "0.000019"], ["84897.50", "0.000031"], ["84899.08", "0.000072"], ["84899.44", "0.000026"], ["84900.00", "0.005252"], ["84901.15", "0.000019"], ["84903.27", "0.000007"], ["84903.57", "0.000128"]], "bids": [["84301.50", "0.001034"], ["84299.99", "0.412037"], ["84299.50", "0.001043"], ["84299.09", "0.209200"], ["84297.50", "0.001035"], ["84295.50", "0.001021"], ["84295.43", "0.053200"], ["84294.89", "0.223490"], ["84293.50", "0.002171"], ["84291.50", "0.005713"], ["84290.67", "0.761208"], ["84290.66", "0.879874"], ["84290.65", "0"], ["84287.80", "0"], ["84287.50", "0.039565"], ["84286.22", "0.015770"], ["84285.94", "0.766525"], ["84285.80", "0"], ["84285.78", "0.007475"], ["84285.50", "0.104119"], ["84285.35", "0.005937"], ["84285.11", "0.018259"], ["84284.48", "0"], ["84283.80", "0"], ["84283.50", "0.273998"], ["84282.12", "0.007950"], ["84281.92", "0.008147"], ["84281.80", "0"], ["84281.50", "0.721048"], ["84280.80", "1.750740"], ["84280.70", "1.824510"], ["84280.63", "0"], ["84280.30", "8.636520"], ["84280.26", "0.018518"], ["84279.90", "4.656840"], ["84279.80", "0.069600"], ["84279.73", "0.209200"], ["84278.60", "2.266140"], ["84277.93", "0"], ["84277.80", "2.992200"], ["84277.00", "0.142680"], ["84276.84", "0"], ["84276.50", "3.694380"], ["84276.35", "0"], ["84276.23", "0"], ["84276.00", "0.463020"], ["84275.80", "0.069600"], ["84275.75", "0"], ["84275.66", "0"], ["84275.43", "0"], ["84275.41", "0"], ["84274.95", "0"], ["84274.76", "0"], ["84274.60", "0"], ["84274.59", "0"], ["84274.58", "0"], ["84274.49", "0"], ["84274.43", "0"], ["84273.80", "0"], ["84273.59", "0"], ["84273.58", "0"], ["84273.39", "0"], ["84273.12", "0"], ["84273.10", "3.129300"], ["84273.09", "0"], ["84273.00", "0"], ["84272.90", "0"], ["84272.78", "0"], ["84272.56", "0"], ["84272.55", "0"], ["84272.53", "0"], ["84272.47", "0"], ["84272.36", "0"], ["84272.10", "3.513780"], ["84271.86", "0"], ["84271.80", "0.339360"], ["84271.63", "0"], ["84271.62", "0"], ["84271.32", "0"], ["84271.08", "0"], ["84271.04", "0"], ["84270.94", "0"], ["84270.90", "0"], ["84270.89", "0"], ["84270.87", "0"], ["84270.77", "0"], ["84270.67", "0"], ["84270.60", "0.142500"], ["84270.40", "0.706950"], ["84270.14", "0"], ["84269.92", "0.023737"], ["84269.80", "0.071010"], ["84269.52", "0"], ["84269.08", "0"], ["84269.01", "0"], ["84268.51", "0"], ["84268.46", "0"], ["84268.37", "0"], ["84268.09", "0"], ["84267.80", "12.711900"], ["84267.70", "0"], ["84267.60", "0"], ["84267.40", "0"], ["84267.39", "0"], ["84267.30", "0.015090"], ["84267.26", "0"], ["84267.20", "2.589600"], ["84267.10", "0"], ["84266.90", "0"], ["84266.69", "0"], ["84266.10", "0"], ["84266.00", "0"], ["84265.82", "0"], ["84265.80", "0"], ["84265.42", "0"], ["84265.35", "0"], ["84265.34", "0"], ["84265.27", "0"], ["84264.60", "0"], ["84264.40", "0"], ["84264.20", "0"], ["84263.93", "0"], ["84263.82", "0"], ["84263.80", "0"], ["84263.39", "0"], ["84262.80", "0"], ["84261.00", "0"], ["84260.50", "0"], ["84259.80", "0"], ["84259.70", "0"], ["84259.30", "0"], ["84259.10", "0"], ["84259.06", "0.017792"], ["84258.60", "0"], ["84258.00", "0"], ["84257.80", "0"], ["84257.30", "0"], ["84256.80", "0"], ["84256.71", "0"], ["84256.00", "0"], ["84255.10", "0"], ["84254.30", "0"], ["84253.60", "0"], ["84253.05", "0.013678"], ["84252.20", "0"], ["84246.77", "0"], ["84246.35", "0"], ["84245.87", "0"], ["84242.21", "0"], ["84241.75", "0.016216"], ["84240.20", "0"], ["84239.30", "4.246673"], ["84237.80", "0"], ["84237.66", "0"], ["84233.43", "0"], ["84231.38", "0"], ["84230.80", "4.969511"], ["84225.60", "0"], ["84222.30", "5.240576"], ["84217.10", "0"], ["84213.80", "4.517738"], ["84208.60", "0"], ["84205.30", "4.698447"], ["84200.10", "0"], ["84196.80", "4.337028"], ["84191.60", "0"], ["84188.30", "4.788802"], ["84183.10", "0"], ["84179.80", "5.511640"], ["84174.60", "0"], ["84171.30", "3.975609"], ["84166.10", "0"], ["84162.80", "4.065964"], ["84157.60", "0"], ["84154.30", "5.330930"], ["84149.10", "0"], ["84145.80", "5.059866"], ["84140.60", "0"], ["84137.30", "5.150221"], ["84132.10", "0"], ["84128.80", "4.427383"], ["84123.60", "0"], ["84120.30", "5.601995"], ["84115.10", "0"], ["84111.80", "5.421285"], ["84106.60", "0"], ["84103.30", "3.885254"], ["84098.10", "0"], ["84094.80", "4.879157"], ["84089.60", "0"], ["84086.30", "4.156319"], ["84081.10", "0"], ["84077.80", "4.608092"], ["84072.60", "0"], ["84064.10", "0.000014"], ["84042.96", "0"], ["84041.61", "0.000423"], ["83891.30", "0.000010"], ["83888.89", "0.000163"], ["83888.86", "0.000371"], ["83887.29", "0.000586"], ["83887.11", "0.000075"], ["83886.91", "0.000145"], ["83885.98", "0.000018"], ["83885.71", "0.000069"], ["83884.62", "0.000014"], ["83884.55", "0.000048"], ["83884.30", "0.000161"], ["83882.98", "0.000188"], ["83882.92", "0.002384"], ["83881.99", "0.000038"], ["83880.00", "0.020454"], ["83877.97", "0.000023"], ["83877.55", "0.000010"], ["83877.42", "0.000054"], ["83877.29", "0.000024"], ["83877.05", "0.000008"], ["83876.25", "0.000028"], ["83876.12", "0.000681"], ["83875.99", "0.000299"], ["83875.49", "0.000723"], ["83875.16", "0.000179"], ["83875.00", "0.000145"], ["83874.55", "0.000145"], ["83874.15", "0.000150"], ["83873.87", "0.000041"], ["83873.52", "0.000135"], ["83870.97", "0.000194"], ["83870.95", "0.000078"], ["83870.78", "0.000019"], ["83870.00", "0.000121"], ["83869.57", "0.000035"], ["83868.82", "0.000017"], ["83866.67", "0.000138"], ["83865.80", "0.000098"], ["83865.10", "0.000134"], ["83864.54", "0.000009"], ["83863.64", "0.000012"], ["83863.52", "0.000510"], ["83860.29", "0.000041"], ["83860.10", "0.000023"], ["83860.00", "0.000024"], ["83859.94", "0.000058"], ["83859.35", "0.000051"], ["83859.25", "0.000115"], ["83858.82", "0.000105"], ["83857.50", "0.000025"], ["83857.14", "0.000431"], ["83857.13", "0.000019"], ["83856.00", "0.000010"], ["83855.78", "0.000009"], ["83855.44", "0.000008"], ["83855.42", "0.000564"], ["83854.95", "0.000462"], ["83854.17", "0.000039"], ["83854.00", "0.500470"], ["83853.33", "0.000125"], ["83852.50", "0.000043"], ["83852.40", "0.000011"], ["83852.30", "0.000029"], ["83852.19", "0.000009"], ["83851.85", "0.000011"], ["83851.84", "0.000219"], ["83850.00", "0.002875"], ["83848.94", "0.000007"], ["83848.38", "0.000042"]], "checksum": -1849088729, "ts": "1742142241107"}], "ts": 1742142241113, "record_time": 1742142240.230599}
{"action": "update", "arg": {"instType": "SPOT", "channel": "books", "instId": "BTCUSDT"}, "data": [{"asks": [["84310.85", "0"], ["84313.78", "0"], ["84315.13", "0"], ["84315.17", "0"], ["84316.91", "0"], ["84318.94", "0.063792"], ["84325.44", "0.009638"], ["84325.48", "0.001230"], ["84325.50", "0.000245"], ["84325.73", "0.004974"], ["84326.24", "0.004595"], ["84326.35", "0.001066"], ["84326.48", "0.007627"], ["84326.50", "0.001923"], ["84326.52", "0.008506"], ["84326.53", "0.007955"], ["84326.54", "0.007359"], ["84326.56", "0.009191"], ["84326.59", "0.004739"], ["84327.28", "0.080082"], ["84327.32", "0.007463"], ["84327.33", "0.000443"], ["84327.36", "0.007110"], ["84329.72", "0.001827"], ["84330.12", "0.007627"], ["84330.13", "0"], ["84331.61", "0"], ["84332.00", "0"], ["84332.02", "0"], ["84332.08", "0"], ["84332.51", "0.022650"], ["84332.52", "0"], ["84332.86", "0.001205"], ["84334.12", "0.119869"], ["84334.29", "0.139901"], ["84336.67", "0.006356"], ["84336.73", "0.005993"], ["84336.74", "0"], ["84338.79", "0.016428"], ["84338.96", "0"], ["84339.09", "0.035952"], ["84339.70", "0.016427"], ["84341.55", "0.063330"], ["84341.67", "0.006356"], ["84341.81", "0.006356"], ["84342.04", "0.006356"], ["84342.14", "0.006356"], ["84342.45", "0.006356"], ["84342.74", "0"], ["84342.86", "0.006356"], ["84343.05", "0.006356"], ["84343.13", "0.119843"], ["84343.17", "0.119895"], ["84343.60", "0.006356"], ["84343.69", "0.017790"], ["84344.49", "0.119879"], ["84344.64", "0.006357"], ["84345.13", "0.015892"], ["84345.90", "0"], ["84346.81", "0.009989"], ["84347.86", "0.119881"], ["84347.90", "0"], ["84348.27", "0.009989"], ["84348.93", "0.313209"], ["84349.02", "0.012680"], ["84349.20", "0.015891"], ["84349.90", "0"], ["84350.91", "0.006356"], ["84351.90", "0"], ["84353.87", "0.010986"], ["84353.90", "0"], ["84354.64", "0.001807"], ["84355.90", "0"], ["84355.98", "0.075500"], ["84356.90", "0.001012"], ["84357.09", "0.014843"], ["84357.90", "0"], ["84358.90", "0.001028"], ["84359.90", "0"], ["84360.90", "0.001021"], ["84361.90", "0"], ["84362.90", "0.002277"], ["84363.90", "0"], ["84364.57", "0.001597"], ["84364.90", "0.005994"], ["84365.90", "0"], ["84366.20", "0"], ["84366.30", "0"], ["84366.48", "0.001597"], ["84366.90", "0.015772"], ["84367.10", "0"], ["84367.20", "0"], ["84368.00", "0"], ["84368.60", "0"], ["84368.70", "0"], ["84368.90", "0.041505"], ["84369.10", "0"], ["84370.20", "0"], ["84370.50", "0"], ["84370.90", "0.109225"], ["84372.90", "0.287433"], ["84373.50", "0"], ["84374.20", "0"], ["84374.60", "0"], ["84374.90", "0.756403"], ["84376.00", "0"], ["84376.10", "0"], ["84376.40", "0"], ["84376.90", "1.990535"], ["84377.00", "0.001010"], ["84377.30", "0.001043"], ["84377.50", "0.009420"], ["84378.00", "0.001008"], ["84378.20", "0.007260"], ["84378.30", "0.014310"], ["84378.80", "0"], ["84379.50", "0"], ["84379.70", "0"], ["84380.60", "0"], ["84382.20", "0.120240"], ["84382.67", "0.010000"], ["84385.50", "0.871950"], ["84386.20", "0.007050"], ["84387.00", "0.154830"], ["84387.30", "0.032880"], ["84387.50", "2.347680"], ["84388.90", "0.420390"], ["84389.60", "0.035550"], ["84389.70", "0.875220"], ["84390.20", "0.013710"], ["84391.30", "0.575910"], ["84392.10", "0.985470"], ["84392.20", "0.284910"], ["84393.10", "0.469080"], ["84393.20", "1.429650"], ["84393.40", "0.142500"], ["84408.10", "0"], ["84409.00", "0"], ["84416.60", "0"], ["84419.10", "5.420578"], ["84425.10", "0"], ["84427.60", "4.968863"], ["84433.60", "0"], ["84436.10", "5.239892"], ["84442.10", "0"], ["84444.60", "4.336462"], ["84450.60", "0"], ["84453.10", "4.788177"], ["84457.72", "0.125283"], ["84459.10", "0"], ["84461.60", "4.607491"], ["84467.60", "0"], ["84470.10", "4.878520"], ["84476.10", "0"], ["84478.60", "4.697834"], ["84484.60", "0"], ["84487.10", "3.975091"], ["84493.10", "0"], ["84495.60", "4.065434"], ["84501.60", "0"], ["84504.10", "4.246120"], ["84510.10", "0"], ["84512.60", "4.155777"], ["84518.60", "0"], ["84521.10", "4.517148"], ["84527.10", "0"], ["84529.60", "5.330235"], ["84535.60", "0"], ["84538.10", "4.426805"], ["84544.10", "0"], ["84546.60", "5.149549"], ["84552.60", "0"], ["84555.10", "5.059206"], ["84561.10", "0"], ["84563.60", "5.510921"], ["84569.60", "0"], ["84572.10", "5.601264"], ["84580.60", "3.884748"], ["84643.89", "0"], ["84672.06", "1.635429"], ["84871.66", "0"], ["84871.79", "0"], ["84873.84", "0"], ["84874.79", "0"], ["84875.00", "0"], ["84875.78", "0"], ["84876.03", "0"], ["84879.10", "0"], ["84879.37", "0"], ["84879.59", "0"], ["84880.00", "0"], ["84880.89", "0"], ["84882.35", "0"], ["84883.65", "0"], ["84883.72", "0"], ["84883.84", "0"], ["84885.24", "0"], ["84885.53", "0"], ["84886.01", "0"], ["84886.02", "0"], ["84886.96", "0"], ["84887.65", "0"], ["84888.00", "0"], ["84888.68", "0"], ["84888.89", "0"], ["84889.87", "0"], ["84890.00", "0"], ["84892.02", "0"], ["84892.76", "0"], ["84892.78", "0"], ["84894.73", "0"], ["84894.74", "0"], ["84895.69", "0"], ["84895.83", "0"], ["84897.50", "0"], ["84899.08", "0"], ["84899.44", "0"], ["84900.00", "0"], ["84901.15", "0"], ["84903.27", "0"], ["84903.57", "0"]], "bids": [["84316.90", "0.289974"], ["84315.13", "1.133800"], ["84315.12", "0.100700"], ["84312.50", "0.001026"], ["84310.50", "0.001008"], ["84309.93", "0.209200"], ["84308.50", "0.002361"], ["84306.50", "0.005963"], ["84305.72", "0.223490"], ["84305.71", "0.209200"], ["84304.50", "0.015693"], ["84302.50", "0.041297"], ["84301.76", "0.047500"], ["84301.51", "0.465790"], ["84301.50", "0.000160"], ["84300.63", "0.015154"], ["84300.61", "0.000213"], ["84300.50", "0.108677"], ["84300.00", "0.013739"], ["84299.99", "0.063073"], ["84299.89", "0.001230"], ["84299.84", "0.006487"], ["84299.50", "0"], ["84298.98", "0.007345"], ["84298.93", "0.008986"], ["84298.91", "0.006213"], ["84298.87", "0.008556"], ["84298.50", "0.285992"], ["84298.44", "0.008147"], ["84297.98", "0.001199"], ["84297.71", "0.002062"], ["84297.50", "0"], ["84296.62", "0.247933"], ["84296.50", "0.752610"], ["84296.26", "0.007950"], ["84296.21", "0.007475"], ["84295.62", "0.017831"], ["84295.50", "0"], ["84295.43", "0"], ["84295.41", "0.005936"], ["84295.30", "0.015767"], ["84295.25", "0.084415"], ["84295.16", "0.018256"], ["84294.90", "0.067047"], ["84294.89", "0"], ["84294.50", "1.980553"], ["84294.24", "0.017074"], ["84294.13", "0.007117"], ["84293.62", "0.006563"], ["84293.56", "0.005552"], ["84293.50", "0"], ["84293.03", "0.007931"], ["84292.70", "0.004935"], ["84292.65", "0.000875"], ["84292.64", "0.005088"], ["84292.50", "5.211980"], ["84292.40", "0.017327"], ["84292.36", "0.017056"], ["84292.30", "0.001043"], ["84292.29", "0.016300"], ["84292.00", "2.055030"], ["84291.90", "0.028290"], ["84291.73", "0.008676"], ["84291.70", "0.405510"], ["84291.50", "0"], ["84290.84", "0.008281"], ["84290.71", "0.052094"], ["84290.68", "0.368330"], ["84290.67", "0.071535"], ["84290.66", "0.562332"], ["84290.07", "0.056349"], ["84289.80", "0.142680"], ["84289.51", "0.042337"], ["84289.50", "0"], ["84289.44", "0.002948"], ["84289.20", "0.065070"], ["84289.10", "2.348070"], ["84289.04", "0.028805"], ["84288.40", "0.405750"], ["84288.27", "0.025082"], ["84287.80", "0.985140"], ["84287.70", "0.410370"], ["84287.50", "0"], ["84287.20", "5.739480"], ["84287.15", "0.263256"], ["84286.72", "0.021103"], ["84286.22", "0"], ["84286.10", "1.779300"], ["84286.00", "0.811140"], ["84285.94", "0.003629"], ["84285.90", "0.462600"], ["84285.80", "0.069600"], ["84285.78", "0"], ["84285.50", "0"], ["84285.35", "0"], ["84285.31", "0.012436"], ["84285.11", "0"], ["84284.83", "0.271876"], ["84284.60", "0.025350"], ["84283.92", "0.076006"], ["84283.80", "0.069600"], ["84283.79", "0.222711"], ["84283.50", "0"], ["84282.50", "0.177960"], ["84282.12", "0"], ["84281.92", "0"], ["84281.87", "0.012648"], ["84281.80", "3.960870"], ["84281.50", "0.267210"], ["84281.00", "0.038430"], ["84280.80", "0"], ["84280.71", "0.713824"], ["84280.70", "0"], ["84280.62", "0"], ["84280.30", "1.779300"], ["84280.26", "0"], ["84279.90", "2.123970"], ["84279.74", "0"], ["84278.60", "0"], ["84277.80", "0.069600"], ["84277.40", "2.669430"], ["84277.00", "0.142500"], ["84276.20", "0.410370"], ["84276.00", "0"], ["84275.80", "0"], ["84275.06", "0.073499"], ["84274.35", "0.008206"], ["84274.16", "0.023937"], ["84273.10", "0"], ["84272.10", "0"], ["84271.80", "0"], ["84270.77", "0.017789"], ["84270.60", "0"], ["84270.40", "0"], ["84269.80", "0"], ["84269.35", "0.007181"], ["84267.80", "0"], ["84267.30", "0"], ["84267.20", "0"], ["84259.06", "0"], ["84256.79", "0.020085"], ["84253.95", "0.001189"], ["84251.99", "0.001180"], ["84250.30", "4.697834"], ["84241.80", "5.239892"], ["84241.75", "0"], ["84239.30", "0"], ["84233.30", "5.149549"], ["84230.80", "0"], ["84224.80", "5.510921"], ["84222.30", "0"], ["84216.30", "4.788177"], ["84213.80", "0"], ["84207.80", "4.517148"], ["84205.30", "0"], ["84199.30", "4.607491"], ["84196.80", "0"], ["84190.80", "4.878520"], ["84188.30", "0"], ["84182.30", "4.426805"], ["84179.80", "0"], ["84173.80", "5.601264"], ["84171.30", "0"], ["84165.30", "4.968863"], ["84162.80", "0"], ["84156.80", "4.155777"], ["84154.30", "0"], ["84148.30", "5.059206"], ["84145.80", "0"], ["84139.80", "5.420578"], ["84137.30", "0"], ["84131.30", "4.336462"], ["84128.80", "0"], ["84122.80", "3.884748"], ["84120.30", "0"], ["84114.30", "3.975091"], ["84111.80", "0"], ["84107.01", "0.000860"], ["84106.44", "0.000860"], ["84105.80", "5.330235"], ["84103.30", "0"], ["84097.30", "4.246120"], ["84094.80", "0"], ["84088.80", "4.065434"], ["84086.30", "0"], ["84077.80", "0"], ["84051.39", "0"], ["83997.37", "1.682570"], ["83969.42", "0"], ["83885.98", "0"], ["83885.71", "0"], ["83884.62", "0"], ["83884.55", "0"], ["83884.30", "0"], ["83882.98", "0"], ["83882.92", "0"], ["83881.99", "0"], ["83880.00", "0"], ["83877.97", "0"], ["83877.55", "0"], ["83877.42", "0"], ["83877.29", "0"], ["83877.05", "0"], ["83876.25", "0"], ["83876.12", "0"], ["83875.99", "0"], ["83875.49", "0"], ["83875.16", "0"], ["83875.00", "0"], ["83874.55", "0"], ["83874.15", "0"], ["83873.87", "0"], ["83873.52", "0"], ["83870.97", "0"], ["83870.95", "0"], ["83870.78", "0"], ["83870.00", "0"], ["83869.57", "0"], ["83868.82", "0"], ["83866.67", "0"], ["83865.80", "0"], ["83865.10", "0"], ["83864.54", "0"], ["83863.64", "0"], ["83863.52", "0"], ["83860.29", "0"], ["83860.10", "0"], ["83860.00", "0"], ["83859.94", "0"], ["83859.35", "0"], ["83859.25", "0"], ["83858.82", "0"], ["83857.50", "0"], ["83857.14", "0"], ["83857.13", "0"], ["83856.00", "0"], ["83855.78", "0"], ["83855.44", "0"], ["83855.42", "0"], ["83854.95", "0"], ["83854.17", "0"], ["83854.00", "0"], ["83853.33", "0"], ["83852.50", "0"], ["83852.40", "0"], ["83852.30", "0"], ["83852.19", "0"], ["83851.85", "0"], ["83851.84", "0"], ["83850.00", "0"], ["83848.94", "0"], ["83848.38", "0"]], "checksum": 576176005, "ts": "1742142241312"}], "ts": 1742142241319, "record_time": 1742142240.429046}
{"action": "update", "arg": {"instType": "SPOT", "channel": "books", "instId": "BTCUSDT"}, "data": [{"asks": [["84318.92", "0.599900"], ["84318.93", "0.101439"], ["84318.94", "0"], ["84323.68", "0.030015"], ["84326.21", "0.008962"], ["84326.31", "0.006307"], ["84326.51", "0.039854"], ["84327.33", "0.001605"], ["84327.37", "0.005183"], ["84329.71", "0.001148"], ["84330.12", "0"], ["84331.04", "0.002807"], ["84335.75", "1.894011"], ["84336.67", "0"], ["84339.46", "0.006356"], ["84339.58", "0.006356"], ["84340.35", "0.006356"], ["84341.78", "0.010985"], ["84341.88", "0.006356"], ["84343.41", "0.006356"], ["84343.79", "0.006356"], ["84344.75", "0.010984"], ["84345.76", "0.006356"], ["84352.62", "2.230079"], ["84357.09", "0"], ["84360.90", "0.001212"], ["84362.90", "0.003389"], ["84364.90", "0.008919"], ["84366.90", "0.023471"], ["84368.90", "0.061764"], ["84370.90", "0.162537"], ["84372.90", "0.427731"], ["84374.90", "1.125608"], ["84376.90", "2.961957"], ["84377.50", "0.009210"], ["84378.30", "0.013860"], ["84382.20", "0.894270"], ["84384.70", "2.347740"], ["84385.50", "0.142860"], ["84387.50", "0"], ["84393.20", "0"], ["84393.40", "0"], ["84419.10", "4.426805"], ["84427.60", "4.336462"], ["84436.10", "5.420578"], ["84444.60", "4.246120"], ["84453.10", "3.884748"], ["84461.60", "5.330235"], ["84470.10", "4.788177"], ["84478.60", "4.065434"], ["84487.10", "5.510921"], ["84495.60", "3.975091"], ["84504.10", "4.968863"], ["84512.60", "5.149549"], ["84521.10", "4.607491"], ["84529.60", "4.697834"], ["84538.10", "4.878520"], ["84546.60", "5.239892"], ["84555.10", "4.517148"], ["84563.60", "5.601264"], ["84572.10", "4.155777"], ["84580.60", "5.059206"], ["84858.75", "0"], ["84859.29", "0"], ["84860.00", "0"], ["84862.90", "0"], ["84864.69", "0"], ["84864.86", "0"], ["84864.99", "0"], ["84866.10", "0"], ["84866.40", "0"], ["84867.80", "0"], ["84868.42", "0"], ["84868.52", "0"], ["84868.65", "0"], ["84869.57", "0"]], "bids": [["84318.46", "1.133800"], ["84318.45", "0.256700"], ["84316.91", "0.022680"], ["84316.90", "0.264482"], ["84315.14", "0.370658"], ["84315.13", "0"], ["84315.12", "0"], ["84313.55", "0.005548"], ["84312.76", "1.894011"], ["84309.94", "0.063468"], ["84308.50", "0.002266"], ["84305.72", "0"], ["84305.71", "0"], ["84301.51", "0.313209"], ["84301.50", "0"], ["84300.66", "0.008532"], ["84299.23", "0.003035"], ["84298.83", "0.007443"], ["84298.76", "0.006535"], ["84297.60", "0.000436"], ["84297.13", "0.007870"], ["84296.50", "0.752360"], ["84295.89", "2.548773"], ["84295.09", "0.016453"], ["84294.50", "1.979895"], ["84293.41", "0.009635"], ["84293.36", "0.008151"], ["84292.50", "5.210251"], ["84292.40", "3.849630"], ["84292.00", "0.001015"], ["84291.90", "0"], ["84291.69", "0.227578"], ["84291.59", "0.010234"], ["84291.10", "0.008161"], ["84290.95", "0.012644"], ["84290.68", "0"], ["84289.90", "0.058710"], ["84289.80", "0.142500"], ["84289.20", "0"], ["84289.10", "0"], ["84287.80", "0.915360"], ["84287.70", "0"], ["84287.20", "0.956070"], ["84285.95", "0.356634"], ["84285.94", "0"], ["84285.10", "0.063900"], ["84284.60", "0"], ["84283.05", "0.056615"], ["84282.85", "0.073475"], ["84282.70", "0.410370"], ["84281.87", "0"], ["84281.50", "0.264480"], ["84280.71", "0"], ["84278.00", "0.090000"], ["84277.10", "0.090000"], ["84276.20", "0.500370"], ["84275.80", "0.069600"], ["84275.06", "0"], ["84270.06", "0.007582"], ["84256.79", "0"], ["84250.30", "3.975091"], ["84241.80", "4.697834"], ["84233.30", "4.878520"], ["84224.80", "4.065434"], ["84199.30", "4.336462"], ["84190.80", "4.246120"], ["84182.30", "5.330235"], ["84173.80", "4.426805"], ["84165.30", "5.059206"], ["84148.30", "5.510921"], ["84139.80", "5.239892"], ["84131.30", "4.607491"], ["84122.80", "5.601264"], ["84114.30", "5.149549"], ["84105.80", "5.420578"], ["84097.30", "4.968863"], ["84088.80", "3.884748"], ["84059.82", "0"], ["84009.56", "0"], ["83894.74", "0"], ["83894.17", "0"], ["83893.81", "0"], ["83893.64", "0"], ["83893.62", "0"], ["83892.29", "0"], ["83891.43", "0"], ["83891.30", "0"], ["83888.89", "0"], ["83888.86", "0"], ["83887.29", "0"], ["83887.11", "0"], ["83886.91", "0"]], "checksum": -1777132428, "ts": "1742142241515"}], "ts": 1742142241519, "record_time": 1742142240.626552}
{"action": "update", "arg": {"instType": "SPOT", "channel": "books", "instId": "BTCUSDT"}, "data": [{"asks": [["84318.91", "0.701339"], ["84318.92", "0"], ["84318.93", "0"], ["84329.06", "0.139898"], ["84332.51", "0.636825"], ["84334.29", "0"], ["84336.73", "0.025613"], ["84349.02", "0"], ["84350.84", "0.031812"], ["84360.90", "0.001371"], ["84362.90", "0.003610"], ["84364.90", "0.009500"], ["84366.77", "0.027943"], ["84366.90", "0.024998"], ["84368.90", "0.065786"], ["84370.90", "0.173121"], ["84372.90", "0.455580"], ["84374.90", "1.198895"], ["84376.90", "3.154988"], ["84380.60", "0.185760"], ["84382.10", "3.120450"], ["84382.20", "0.147780"], ["84382.67", "0"], ["84383.70", "0.035550"], ["84384.70", "0"], ["84385.50", "0.220950"], ["84386.80", "0.177960"], ["84393.10", "0"], ["84419.10", "4.155777"], ["84427.60", "4.065434"], ["84436.10", "4.607491"], ["84444.60", "4.336462"], ["84450.00", "0.002000"], ["84453.10", "4.697834"], ["84470.10", "4.426805"], ["84478.60", "4.878520"], ["84487.10", "5.601264"], ["84495.60", "5.239892"], ["84504.10", "4.246120"], ["84512.60", "5.510921"], ["84521.10", "5.420578"], ["84529.60", "3.975091"], ["84538.10", "5.149549"], ["84546.60", "5.059206"], ["84555.10", "3.884748"], ["84563.60", "4.517148"], ["84572.10", "4.968863"], ["84580.60", "4.788177"], ["84853.56", "0"], ["84857.14", "0"]], "bids": [["84318.90", "0.799870"], ["84318.47", "0.497278"], ["84318.46", "0.000160"], ["84318.45", "0"], ["84316.91", "0.010164"], ["84316.90", "0.055122"], ["84315.14", "0.523843"], ["84313.87", "0.012680"], ["84308.50", "0.001655"], ["84306.51", "0.006497"], ["84306.50", "0.004355"], ["84306.37", "0.190834"], ["84304.50", "0.011460"], ["84302.50", "0.030159"], ["84300.50", "0.079366"], ["84299.42", "0.003068"], ["84298.50", "0.208858"], ["84296.50", "0.549625"], ["84294.50", "1.446381"], ["84292.50", "3.806267"], ["84292.40", "0.017327"], ["84290.80", "0.035550"], ["84290.67", "0.023727"], ["84290.12", "0.018512"], ["84289.90", "0.058890"], ["84289.80", "3.257220"], ["84288.60", "0.274770"], ["84288.40", "0.405570"], ["84287.20", "0.628800"], ["84286.10", "0"], ["84285.80", "0.035550"], ["84284.80", "0.688140"], ["84283.40", "0.142500"], ["84282.70", "0"], ["84281.90", "0.383160"], ["84279.90", "2.159520"], ["84279.80", "0.075210"], ["84277.40", "0"], ["84277.10", "0"], ["84277.00", "0"], ["84276.50", "0"], ["84276.20", "0"], ["84275.80", "0"], ["84250.30", "4.968863"], ["84241.80", "4.155777"], ["84233.30", "4.336462"], ["84224.80", "4.788177"], ["84216.30", "5.330235"], ["84207.80", "4.607491"], ["84199.30", "4.697834"], ["84182.30", "4.426805"], ["84173.80", "3.884748"], ["84168.00", "0"], ["84165.30", "5.239892"], ["84156.80", "5.149549"], ["84148.30", "4.065434"], ["84139.80", "5.059206"], ["84131.30", "5.601264"], ["84122.80", "5.420578"], ["84114.30", "4.517148"], ["84105.80", "4.878520"], ["84097.30", "5.510921"], ["84088.80", "3.975091"], ["83895.65", "0"], ["83895.00", "0"]], "checksum": -1438732107, "ts": "1742142241714"}], "ts": 1742142241719, "record_time": 1742142240.827812}
{"action": "update", "arg": {"instType": "SPOT", "channel": "books", "instId": "BTCUSDT"}, "data": [{"asks": [["84318.91", "0.889697"], ["84319.78", "0.063792"], ["84326.51", "0"], ["84334.11", "0.014843"], ["84334.97", "0.012680"], ["84366.90", "0.024879"], ["84368.90", "0.065470"], ["84370.90", "0.172290"], ["84372.90", "0.453633"], ["84374.90", "1.193771"], ["84376.90", "3.141503"], ["84385.90", "0.025350"], ["84419.10", "3.884748"], ["84427.60", "5.601264"], ["84436.10", "4.878520"], ["84444.60", "4.607491"], ["84453.10", "4.336462"], ["84461.60", "4.155777"], ["84470.10", "4.968863"], ["84478.60", "4.788177"], ["84487.10", "3.975091"], ["84495.60", "5.510921"], ["84504.10", "5.420578"], ["84512.60", "4.426805"], ["84521.10", "4.517148"], ["84529.60", "4.246120"], ["84538.10", "5.239892"], ["84546.60", "5.330235"], ["84555.10", "5.059206"], ["84563.60", "4.065434"], ["84572.10", "5.149549"], ["84580.60", "4.697834"], ["84851.66", "0"], ["84852.81", "0"], ["84852.94", "0"]], "bids": [["84318.90", "1.640972"], ["84318.48", "0.168817"], ["84318.47", "0.139899"], ["84318.46", "0"], ["84316.90", "0"], ["84306.50", "0.004476"], ["84304.50", "0.011780"], ["84302.50", "0.031000"], ["84300.50", "0.081580"], ["84298.50", "0.214683"], ["84296.50", "0.564956"], ["84294.50", "1.486725"], ["84292.50", "3.912436"], ["84290.66", "0.209200"], ["84288.60", "0.274590"], ["84288.40", "0"], ["84287.80", "0"], ["84287.20", "0.375270"], ["84286.00", "0"], ["84282.50", "0"], ["84281.70", "0.915360"], ["84281.50", "0.086520"], ["84277.70", "0.177960"], ["84277.40", "2.669430"], ["84277.32", "0"], ["84250.30", "5.239892"], ["84241.80", "5.601264"], ["84233.30", "3.884748"], ["84224.80", "5.330235"], ["84216.30", "4.246120"], ["84207.80", "4.336462"], ["84199.30", "5.510921"], ["84190.80", "5.059206"], ["84182.30", "4.607491"], ["84173.80", "4.426805"], ["84165.30", "5.420578"], ["84156.80", "4.788177"], ["84148.30", "3.975091"], ["84139.80", "4.517148"], ["84131.30", "4.155777"], ["84122.80", "4.878520"], ["84114.30", "4.065434"], ["84105.80", "4.968863"], ["84097.30", "4.697834"], ["84088.80", "5.149549"], ["83895.65", "0.000013"], ["83895.00", "0.006121"], ["83894.74", "0.000068"]], "checksum": 1750327892, "ts": "1742142241915"}], "ts": 1742142241919, "record_time": 1742142241.026864}
{"action": "update", "arg": {"instType": "SPOT", "channel": "books", "instId": "BTCUSDT"}, "data": [{"asks": [["84318.91", "0.889594"], ["84329.05", "0.043960"], ["84329.71", "0"], ["84334.97", "0"], ["84337.81", "0.012680"], ["84343.80", "0.148098"], ["84360.90", "0.001012"], ["84362.90", "0.002663"], ["84364.90", "0.007007"], ["84366.90", "0.018441"], ["84368.90", "0.048528"], ["84370.90", "0.127705"], ["84372.90", "0.336065"], ["84374.90", "0.884384"], ["84376.90", "2.327325"], ["84377.50", "0.001021"], ["84380.60", "0"], ["84382.10", "0"], ["84382.20", "0.078180"], ["84383.70", "0"], ["84388.60", "0.410370"], ["84388.90", "0.180390"], ["84389.70", "1.220790"], ["84390.70", "0.240000"], ["84392.10", "0"], ["84392.20", "0"], ["84400.55", "0"], ["84419.10", "5.420578"], ["84427.60", "3.975091"], ["84436.10", "4.336462"], ["84444.60", "4.065434"], ["84453.10", "4.788177"], ["84461.60", "4.968863"], ["84470.10", "4.878520"], ["84478.60", "4.517148"], ["84487.10", "5.601264"], ["84495.60", "4.246120"], ["84504.10", "4.697834"], ["84512.60", "5.330235"], ["84521.10", "4.155777"], ["84529.60", "4.607491"], ["84538.10", "3.884748"], ["84546.60", "5.149549"], ["84555.10", "5.239892"], ["84563.60", "5.059206"], ["84572.10", "5.510921"], ["84580.60", "4.426805"], ["84851.66", "0.000029"], ["84852.81", "0.000115"], ["84852.94", "0.000065"]], "bids": [["84318.48", "0.045019"], ["84313.87", "0"], ["84308.50", "0.002257"], ["84306.50", "0.005939"], ["84304.50", "0.015629"], ["84302.50", "0.041129"], ["84300.50", "0.108233"], ["84298.50", "0.284825"], ["84296.50", "0.749540"], ["84294.50", "1.972474"], ["84292.50", "5.190721"], ["84292.40", "3.603870"], ["84292.30", "0"], ["84292.00", "0"], ["84290.70", "0.414420"], ["84289.90", "0.058710"], ["84289.80", "0.142500"], ["84284.10", "0.009000"], ["84282.50", "0.177960"], ["84277.40", "0.248880"], ["84265.86", "0"], ["84250.30", "5.420578"], ["84241.80", "5.330235"], ["84233.30", "4.065434"], ["84224.80", "4.517148"], ["84216.30", "3.975091"], ["84207.80", "5.239892"], ["84199.30", "4.155777"], ["84190.80", "4.697834"], ["84182.30", "4.968863"], ["84178.55", "0.005930"], ["84173.80", "3.884748"], ["84165.30", "5.601264"], ["84156.80", "4.246120"], ["84148.30", "4.336462"], ["84139.80", "4.878520"], ["84131.30", "4.426805"], ["84122.80", "4.788177"], ["84114.30", "5.059206"], ["84105.80", "4.607491"], ["84097.30", "5.149549"], ["84088.80", "5.510921"]], "checksum": -1219197115, "ts": "1742142242119"}], "ts": 1742142242124, "record_time": 1742142241.23405}
{"action": "update", "arg": {"instType": "SPOT", "channel": "books", "instId": "BTCUSDT"}, "data": [{"asks": [["84319.75", "0.063792"], ["84319.78", "0"], ["84326.47", "0.044623"], ["84362.90", "0.002089"], ["84364.90", "0.005497"], ["84366.90", "0.014466"], ["84368.90", "0.038067"], ["84370.90", "0.100177"], ["84372.90", "0.263623"], ["84374.90", "0.693745"], ["84376.90", "1.825534"], ["84377.70", "0.924360"], ["84378.00", "0"], ["84378.20", "0.007050"], ["84380.60", "0.142500"], ["84380.70", "2.347860"], ["84382.20", "0.147780"], ["84383.70", "0.024180"], ["84388.90", "0.060390"], ["84390.70", "0"], ["84390.90", "0.120000"], ["84419.10", "5.239892"], ["84427.60", "5.601264"], ["84436.10", "4.246120"], ["84444.60", "3.884748"], ["84461.60", "4.878520"], ["84470.10", "4.968863"], ["84478.60", "3.975091"], ["84484.86", "0.209200"], ["84487.10", "4.065434"], ["84495.60", "5.059206"], ["84504.10", "5.149549"], ["84521.10", "5.510921"], ["84529.60", "4.517148"], ["84538.10", "4.426805"], ["84546.60", "4.336462"], ["84555.10", "4.607491"], ["84563.60", "5.420578"], ["84572.10", "4.697834"], ["84580.60", "4.155777"], ["84849.88", "0"], ["84850.00", "0"], ["84851.66", "0"], ["84852.81", "0"], ["84852.94", "0"]], "bids": [["84318.90", "1.464452"], ["84308.50", "0.001892"], ["84307.67", "0.003005"], ["84306.51", "0.062908"], ["84306.50", "0.004980"], ["84304.50", "0.013106"], ["84302.50", "0.034489"], ["84300.50", "0.090760"], ["84298.50", "0.238841"], ["84296.50", "0.628529"], ["84294.50", "1.654025"], ["84292.50", "4.352586"], ["84292.40", "1.255500"], ["84290.70", "0.414600"], ["84289.90", "0.058890"], ["84289.80", "2.490720"], ["84288.70", "0.274590"], ["84288.60", "0"], ["84285.10", "0.063120"], ["84282.50", "0"], ["84279.90", "2.337720"], ["84279.80", "0.069600"], ["84277.40", "0"], ["84250.30", "4.697834"], ["84241.80", "4.426805"], ["84233.30", "4.878520"], ["84224.80", "5.330235"], ["84216.30", "5.149549"], ["84207.80", "5.510921"], ["84199.30", "5.420578"], ["84190.80", "5.239892"], ["84182.30", "4.065434"], ["84165.30", "4.968863"], ["84156.80", "4.517148"], ["84148.30", "4.788177"], ["84139.80", "5.601264"], ["84131.30", "4.336462"], ["84122.80", "4.246120"], ["84114.30", "3.975091"], ["84097.30", "5.059206"], ["84088.80", "4.155777"], ["83894.17", "0.000022"]], "checksum": -757323398, "ts": "1742142242323"}], "ts": 1742142242327, "record_time": 1742142241.434049}
{"action": "update", "arg": {"instType": "SPOT", "channel": "books", "instId": "BTCUSDT"}, "data": [{"asks": [["84318.91", "0.888128"], ["84341.55", "0.246764"], ["84376.90", "1.825553"], ["84377.70", "1.644720"], ["84382.20", "0.200910"], ["84390.20", "0.006660"], ["84390.90", "0"], ["84391.30", "0"], ["84419.10", "4.968863"], ["84427.60", "5.239892"], ["84436.10", "4.697834"], ["84444.60", "4.336462"], ["84453.10", "5.330235"], ["84461.60", "3.884748"], ["84470.10", "3.975091"], ["84478.60", "5.510921"], ["84487.10", "4.607491"], ["84495.60", "5.149549"], ["84504.10", "5.059206"], ["84512.60", "4.246120"], ["84521.10", "4.878520"], ["84529.60", "4.788177"], ["84538.10", "4.517148"], ["84546.60", "4.155777"], ["84555.10", "4.065434"], ["84572.10", "4.426805"], ["84580.60", "5.601264"], ["84849.88", "0.000030"], ["84850.00", "0.000031"]], "bids": [["84301.52", "0.212912"], ["84299.99", "0"], ["84250.30", "5.239892"], ["84233.30", "3.884748"], ["84224.80", "5.059206"], ["84216.30", "4.246120"], ["84207.80", "4.065434"], ["84199.30", "5.601264"], ["84190.80", "5.149549"], ["84182.30", "4.517148"], ["84173.80", "4.788177"], ["84167.00", "0.000121"], ["84165.30", "5.420578"], ["84156.80", "5.330235"], ["84148.30", "4.336462"], ["84139.80", "4.607491"], ["84131.30", "5.510921"], ["84122.80", "4.968863"], ["84114.30", "4.155777"], ["84105.80", "4.878520"], ["84097.30", "3.975091"], ["84088.80", "4.697834"], ["83894.17", "0"]], "checksum": 1899967365, "ts": "1742142242533"}], "ts": 1742142242571, "record_time": 1742142241.680065}
{"action": "update", "arg": {"instType": "SPOT", "channel": "books", "instId": "BTCUSDT"}, "data": [{"asks": [["84326.47", "0"], ["84337.81", "0"], ["84352.61", "0.669024"], ["84362.90", "0.002826"], ["84364.90", "0.007436"], ["84366.90", "0.019701"], ["84368.90", "0.051844"], ["84370.90", "0.136431"], ["84372.90", "0.359030"], ["84374.90", "0.944815"], ["84376.90", "2.486355"], ["84390.20", "0.013710"], ["84390.90", "0.120000"], ["84419.10", "5.330235"], ["84427.60", "3.884748"], ["84436.10", "5.510921"], ["84444.60", "4.968863"], ["84453.10", "4.788177"], ["84461.60", "4.607491"], ["84470.10", "5.149549"], ["84478.60", "5.059206"], ["84487.10", "5.601264"], ["84495.60", "4.426805"], ["84504.10", "4.155777"], ["84512.60", "4.336462"], ["84521.10", "5.239892"], ["84529.60", "5.420578"], ["84538.10", "4.697834"], ["84546.60", "4.246120"], ["84563.60", "4.517148"], ["84572.10", "4.878520"], ["84580.60", "3.975091"]], "bids": [["84318.90", "1.444452"], ["84308.50", "0.001552"], ["84306.50", "0.004083"], ["84304.50", "0.010746"], ["84302.50", "0.028278"], ["84300.50", "0.074416"], ["84298.50", "0.195833"], ["84296.50", "0.515348"], ["84294.50", "1.356179"], ["84292.51", "0.520443"], ["84292.50", "3.568894"], ["84292.40", "0.017327"], ["84291.70", "0.755730"], ["84290.80", "0.032880"], ["84289.90", "0.058710"], ["84289.80", "0.142500"], ["84287.20", "1.013730"], ["84287.00", "2.348100"], ["84285.10", "0"], ["84282.50", "0.177960"], ["84281.50", "0.015150"], ["84279.80", "0"], ["84278.00", "0"], ["84277.80", "0"], ["84277.70", "0"], ["84241.80", "4.065434"], ["84233.30", "4.246120"], ["84224.80", "3.884748"], ["84216.30", "5.059206"], ["84207.80", "4.155777"], ["84199.30", "4.517148"], ["84190.80", "4.878520"], ["84182.30", "5.601264"], ["84173.80", "4.697834"], ["84165.30", "5.149549"], ["84156.80", "4.607491"], ["84148.30", "3.975091"], ["84139.80", "4.788177"], ["84131.30", "4.426805"], ["84122.80", "5.330235"], ["84114.30", "4.336462"], ["84105.80", "5.510921"], ["84097.30", "4.968863"], ["84088.80", "5.420578"], ["83992.30", "0.209200"], ["83894.17", "0.000022"]], "checksum": -253595870, "ts": "1742142242734"}], "ts": 1742142242744, "record_time": 1742142241.851932}
{"action": "update", "arg": {"instType": "SPOT", "channel": "books", "instId": "BTCUSDT"}, "data": [{"asks": [["84318.91", "0.864537"], ["84319.71", "0.063792"], ["84319.75", "0"], ["84326.47", "0.044623"], ["84337.67", "0.012680"], ["84362.90", "0.002168"], ["84364.90", "0.005705"], ["84366.90", "0.015013"], ["84368.90", "0.039507"], ["84370.90", "0.103832"], ["84372.90", "0.273241"], ["84374.90", "0.719056"], ["84376.90", "1.892252"], ["84377.70", "0.925590"], ["84380.70", "0"], ["84382.20", "0.078180"], ["84382.50", "3.053670"], ["84383.70", "0"], ["84385.90", "0"], ["84389.30", "0.025350"], ["84427.60", "4.788177"], ["84436.10", "5.059206"], ["84444.60", "5.149549"], ["84453.10", "4.968863"], ["84461.60", "4.336462"], ["84470.10", "4.155777"], ["84478.60", "4.607491"], ["84495.60", "4.065434"], ["84504.10", "4.697834"], ["84512.60", "3.975091"], ["84521.10", "5.510921"], ["84529.60", "4.517148"], ["84538.10", "4.878520"], ["84546.60", "5.420578"], ["84555.10", "4.246120"], ["84563.60", "5.239892"], ["84572.10", "4.426805"], ["84580.60", "3.884748"], ["84850.00", "0"]], "bids": [["84318.90", "1.235252"], ["84318.48", "0.044638"], ["84308.50", "0.001768"], ["84306.50", "0.004652"], ["84304.50", "0.012243"], ["84302.50", "0.032219"], ["84300.50", "0.084787"], ["84298.50", "0.223124"], ["84296.50", "0.587167"], ["84294.50", "1.545178"], ["84292.50", "4.066258"], ["84291.70", "1.448190"], ["84290.70", "0.414420"], ["84289.90", "0"], ["84289.80", "2.490540"], ["84287.20", "0.375270"], ["84287.00", "0"], ["84285.95", "0"], ["84283.20", "0.064980"], ["84282.50", "0"], ["84279.80", "0.069600"], ["84250.30", "5.510921"], ["84241.80", "4.426805"], ["84224.80", "5.420578"], ["84216.30", "4.878520"], ["84207.80", "5.149549"], ["84199.30", "5.330235"], ["84190.80", "4.336462"], ["84182.30", "3.975091"], ["84173.80", "4.788177"], ["84165.30", "3.884748"], ["84156.80", "4.155777"], ["84148.30", "5.239892"], ["84139.80", "5.059206"], ["84131.30", "5.601264"], ["84122.80", "4.517148"], ["84114.30", "4.607491"], ["84105.80", "4.968863"], ["84097.30", "4.697834"], ["84088.80", "4.065434"], ["83893.81", "0.000010"], ["83893.64", "0.000039"]], "checksum": 798399606, "ts": "1742142242939"}], "ts": 1742142242943, "record_time": 1742142242.051053}
{"action": "update", "arg": {"instType": "SPOT", "channel": "books", "instId": "BTCUSDT"}, "data": [{"asks": [["84318.91", "0.849632"], ["84326.47", "0"], ["84327.35", "0.209200"], ["84332.86", "0"], ["84334.12", "0"], ["84337.67", "0"], ["84338.02", "0.012680"], ["84338.10", "0.001205"], ["84338.91", "0.119869"], ["84357.10", "0"], ["84362.90", "0.002482"], ["84364.90", "0.006532"], ["84366.90", "0.017190"], ["84368.90", "0.045235"], ["84370.90", "0.119041"], ["84372.90", "0.313266"], ["84374.90", "0.824383"], ["84376.90", "2.169430"], ["84377.70", "0.967980"], ["84380.60", "0"], ["84382.20", "0.147960"], ["84382.50", "3.054270"], ["84388.20", "0.197885"], ["84388.90", "0"], ["84391.10", "0.060000"], ["84419.10", "4.878520"], ["84427.60", "4.155777"], ["84436.10", "4.517148"], ["84444.60", "4.246120"], ["84453.10", "4.065434"], ["84461.60", "5.420578"], ["84470.10", "5.149549"], ["84478.60", "4.426805"], ["84487.10", "4.697834"], ["84495.60", "3.884748"], ["84504.10", "4.788177"], ["84521.10", "4.336462"], ["84529.60", "5.059206"], ["84538.10", "5.239892"], ["84546.60", "4.607491"], ["84555.10", "4.968863"], ["84563.60", "5.330235"], ["84572.10", "5.510921"], ["84580.60", "5.601264"], ["84850.00", "0.000031"]], "bids": [["84318.90", "3.081614"], ["84312.76", "0"], ["84304.70", "2.548669"], ["84304.50", "0.012351"], ["84302.50", "0.032502"], ["84300.50", "0.085533"], ["84298.50", "0.225086"], ["84296.50", "0.592333"], ["84295.89", "0"], ["84294.90", "0.455173"], ["84294.83", "0.056330"], ["84294.50", "1.558770"], ["84292.50", "4.102025"], ["84291.20", "0.197876"], ["84290.70", "0.414600"], ["84290.07", "0"], ["84289.80", "2.490720"], ["84289.40", "0.274590"], ["84288.70", "0"], ["84286.80", "0.695100"], ["84284.80", "0"], ["84282.50", "0.177960"], ["84261.70", "0.207047"], ["84250.30", "4.246120"], ["84241.80", "4.065434"], ["84233.30", "5.601264"], ["84216.30", "5.510921"], ["84207.80", "3.884748"], ["84199.30", "4.155777"], ["84190.80", "4.607491"], ["84182.30", "4.878520"], ["84173.80", "5.239892"], ["84165.30", "4.517148"], ["84156.80", "4.697834"], ["84148.30", "5.330235"], ["84131.30", "3.975091"], ["84122.80", "4.426805"], ["84114.30", "4.788177"], ["84105.80", "5.149549"], ["84097.30", "4.336462"], ["84088.80", "4.968863"], ["83893.81", "0"], ["83893.64", "0"]], "checksum": -2116893352, "ts": "1742142243143"}], "ts": 1742142243147, "record_time": 1742142242.254492}
{"action": "update", "arg": {"instType": "SPOT", "channel": "books", "instId": "BTCUSDT"}, "data": [{"asks": [["84318.91", "0.850271"], ["84327.35", "0"], ["84340.91", "0.148098"], ["84343.80", "0"], ["84350.84", "0"], ["84360.90", "0.001046"], ["84361.79", "0.031812"], ["84362.90", "0.002282"], ["84364.90", "0.006005"], ["84366.77", "0"], ["84366.90", "0.015803"], ["84368.90", "0.041587"], ["84370.90", "0.109438"], ["84372.90", "0.287994"], ["84374.90", "0.757881"], ["84376.90", "1.994422"], ["84380.60", "0.142680"], ["84381.60", "0.258210"], ["84382.20", "0.236160"], ["84382.30", "0.469080"], ["84382.50", "0"], ["84385.50", "0.513180"], ["84386.50", "0.985470"], ["84419.10", "4.426805"], ["84427.60", "4.878520"], ["84436.10", "4.968863"], ["84444.60", "5.059206"], ["84453.10", "4.607491"], ["84461.60", "5.601264"], ["84470.10", "4.065434"], ["84478.60", "5.149549"], ["84487.10", "4.517148"], ["84495.60", "5.420578"], ["84504.10", "5.239892"], ["84512.60", "4.246120"], ["84521.10", "3.975091"], ["84529.60", "4.155777"], ["84538.10", "4.336462"], ["84546.60", "3.884748"], ["84555.10", "5.510921"], ["84563.60", "4.788177"], ["84572.10", "4.697834"], ["84580.60", "5.330235"], ["84850.00", "0"]], "bids": [["84318.90", "3.310654"], ["84316.91", "0.000164"], ["84315.14", "0.001972"], ["84308.50", "0.001001"], ["84306.50", "0.001959"], ["84306.42", "0.010000"], ["84304.50", "0.005156"], ["84302.50", "0.013569"], ["84300.50", "0.035707"], ["84298.50", "0.093965"], ["84296.50", "0.247277"], ["84294.50", "0.650730"], ["84292.50", "1.712446"], ["84291.70", "0.652080"], ["84290.80", "0.035550"], ["84289.80", "0.212280"], ["84289.40", "0"], ["84287.90", "0.274590"], ["84287.80", "0.069600"], ["84287.20", "0.090090"], ["84286.80", "0"], ["84285.90", "0"], ["84285.80", "0.025320"], ["84284.10", "3.107940"], ["84283.80", "0"], ["84283.40", "0.157650"], ["84283.20", "0"], ["84283.00", "0.015120"], ["84281.80", "0.987180"], ["84279.90", "2.159520"], ["84278.00", "0.090000"], ["84277.80", "0.069600"], ["84277.70", "0.177960"], ["84250.30", "4.336462"], ["84241.80", "4.968863"], ["84233.30", "3.975091"], ["84224.80", "3.884748"], ["84216.30", "4.697834"], ["84207.80", "4.878520"], ["84199.30", "4.517148"], ["84190.80", "4.788177"], ["84182.30", "4.426805"], ["84173.80", "5.149549"], ["84169.00", "0.012717"], ["84165.30", "5.059206"], ["84156.80", "5.510921"], ["84139.80", "4.155777"], ["84131.30", "4.607491"], ["84122.80", "5.420578"], ["84114.30", "5.601264"], ["84105.80", "4.246120"], ["84097.30", "4.065434"], ["84088.80", "5.239892"], ["83894.74", "0"], ["83894.17", "0"]], "checksum": -1589384985, "ts": "1742142243345"}], "ts": 1742142243349, "record_time": 1742142242.456716}
{"action": "update", "arg": {"instType": "SPOT", "channel": "books", "instId": "BTCUSDT"}, "data": [{"asks": [["84318.91", "0.222440"], ["84319.71", "0"], ["84327.35", "0.209200"], ["84329.05", "0"], ["84332.51", "0"], ["84335.74", "0.568203"], ["84338.02", "0"], ["84340.91", "0"], ["84348.20", "0.148098"], ["84348.84", "0.012680"], ["84356.90", "0"], ["84358.20", "0.001016"], ["84358.90", "0"], ["84360.20", "0.001046"], ["84360.90", "0"], ["84362.20", "0.001428"], ["84362.90", "0"], ["84364.20", "0.003760"], ["84364.90", "0"], ["84366.20", "0.009894"], ["84366.90", "0"], ["84368.20", "0.026037"], ["84368.90", "0"], ["84370.20", "0.068517"], ["84370.90", "0"], ["84372.20", "0.180310"], ["84372.90", "0"], ["84374.20", "0.474500"], ["84374.90", "0"], ["84376.20", "1.248682"], ["84376.90", "0"], ["84377.00", "0"], ["84377.30", "0"], ["84377.50", "0"], ["84377.70", "0"], ["84378.20", "3.286006"], ["84378.30", "0.015330"], ["84378.80", "0.001040"], ["84378.90", "0.001025"], ["84379.90", "0.002070"], ["84380.60", "0.142920"], ["84381.60", "0"], ["84382.20", "0.147780"], ["84382.30", "0"], ["84384.20", "0.069600"], ["84385.00", "0.035550"], ["84385.50", "0"], ["84386.50", "0"], ["84386.70", "1.350000"], ["84386.80", "0"], ["84387.50", "0.258030"], ["84388.60", "0"], ["84389.30", "0"], ["84389.70", "0.875220"], ["84390.90", "0"], ["84391.10", "0"], ["84391.30", "0.575910"], ["84392.10", "0.180000"], ["84392.20", "0.240000"], ["84419.10", "0"], ["84420.40", "4.155712"], ["84427.60", "0"], ["84428.90", "3.975029"], ["84436.10", "0"], ["84437.40", "4.517078"], ["84444.60", "0"], ["84445.90", "3.884687"], ["84453.10", "0"], ["84454.40", "5.510835"], ["84461.60", "0"], ["84462.90", "5.601177"], ["84470.10", "0"], ["84471.40", "4.607420"], ["84478.60", "0"], ["84479.90", "4.968786"], ["84487.10", "0"], ["84488.40", "5.149469"], ["84495.60", "0"], ["84496.90", "5.239811"], ["84504.10", "0"], ["84505.40", "4.878444"], ["84512.60", "0"], ["84513.90", "4.697761"], ["84521.10", "0"], ["84522.40", "4.426737"], ["84529.60", "0"], ["84530.90", "4.788103"], ["84538.10", "0"], ["84539.40", "5.330152"], ["84546.60", "0"], ["84547.90", "4.065370"], ["84555.10", "0"], ["84556.40", "4.246054"], ["84563.60", "0"], ["84564.90", "4.336395"], ["84572.10", "0"], ["84573.40", "5.059128"], ["84580.60", "0"], ["84581.90", "5.420494"], ["84850.00", "0.000031"], ["84851.66", "0.000029"], ["84852.81", "0.000115"], ["84852.94", "0.000065"], ["84853.56", "0.000050"]], "bids": [["84318.90", "3.088934"], ["84313.80", "0.001021"], ["84312.50", "0"], ["84311.80", "0.001029"], ["84310.50", "0"], ["84309.80", "0.001037"], ["84308.50", "0"], ["84307.80", "0.001051"], ["84306.51", "0.251871"], ["84306.50", "0"], ["84305.80", "0.002765"], ["84304.50", "0"], ["84303.80", "0.007277"], ["84302.50", "0"], ["84301.80", "0.019150"], ["84300.50", "0"], ["84299.80", "0.050395"], ["84298.50", "0"], ["84297.80", "0.132619"], ["84296.50", "0"], ["84295.80", "0.348997"], ["84294.90", "0.067047"], ["84294.50", "0"], ["84293.80", "0.918412"], ["84293.50", "0.001027"], ["84293.30", "0.001035"], ["84293.20", "0.001047"], ["84292.51", "0"], ["84292.50", "0.898530"], ["84291.70", "0.405270"], ["84290.80", "0"], ["84290.70", "0.414420"], ["84290.67", "0.011863"], ["84289.80", "0"], ["84289.10", "0.915360"], ["84287.90", "0.037800"], ["84287.80", "0"], ["84287.20", "0"], ["84285.10", "0.425490"], ["84284.70", "0.015120"], ["84284.60", "0.015210"], ["84284.10", "1.196730"], ["84283.40", "0.142500"], ["84283.00", "0"], ["84281.80", "0"], ["84281.70", "0"], ["84281.50", "0"], ["84280.50", "0.063030"], ["84277.80", "0.139620"], ["84251.60", "4.517078"], ["84250.30", "0"], ["84243.10", "4.155712"], ["84241.80", "0"], ["84234.60", "5.510835"], ["84233.30", "0"], ["84226.10", "5.239811"], ["84224.80", "0"], ["84217.60", "4.878444"], ["84216.30", "0"], ["84209.10", "4.968786"], ["84207.80", "0"], ["84200.60", "5.330152"], ["84199.30", "0"], ["84192.10", "3.884687"], ["84190.80", "0"], ["84183.60", "4.607420"], ["84182.30", "0"], ["84175.10", "3.975029"], ["84173.80", "0"], ["84166.60", "5.420494"], ["84165.30", "0"], ["84158.10", "4.065370"], ["84156.80", "0"], ["84149.60", "4.246054"], ["84148.30", "0"], ["84141.10", "5.059128"], ["84139.80", "0"], ["84132.60", "5.601177"], ["84131.30", "0"], ["84124.10", "4.426737"], ["84122.80", "0"], ["84115.60", "4.697761"], ["84114.30", "0"], ["84107.10", "4.336395"], ["84105.80", "0"], ["84098.60", "4.788103"], ["84097.30", "0"], ["84090.10", "5.149469"], ["84088.80", "0"]], "checksum": -300035333, "ts": "1742142243546"}], "ts": 1742142243551, "record_time": 1742142242.658897}
{"action": "update", "arg": {"instType": "SPOT", "channel": "books", "instId": "BTCUSDT"}, "data": [{"asks": [["84318.91", "0.765540"], ["84327.35", "0"], ["84358.57", "0.031812"], ["84361.79", "0"], ["84362.20", "0.001000"], ["84364.20", "0.001314"], ["84366.20", "0.003457"], ["84368.20", "0.009098"], ["84370.20", "0.023942"], ["84372.20", "0.063005"], ["84374.20", "0.165802"], ["84376.20", "0.436322"], ["84378.20", "1.148215"], ["84378.30", "0.016650"], ["84379.40", "0.001004"], ["84379.90", "0.001860"], ["84380.30", "0.133110"], ["84380.40", "0.258030"], ["84380.60", "0"], ["84382.20", "0.155250"], ["84384.20", "0"], ["84385.00", "0"], ["84386.70", "0.820980"], ["84386.80", "0.177960"], ["84387.50", "0"], ["84388.80", "0.269760"], ["84389.30", "0.981300"], ["84389.70", "0.629040"], ["84390.10", "0.410370"], ["84390.40", "0.171750"], ["84392.20", "0.524910"], ["84392.40", "0.421380"], ["84420.40", "5.510835"], ["84428.90", "4.155712"], ["84445.90", "4.788103"], ["84454.40", "3.884687"], ["84462.90", "4.065370"], ["84471.40", "5.330152"], ["84479.90", "5.601177"], ["84488.40", "3.975029"], ["84496.90", "5.059128"], ["84505.40", "4.426737"], ["84513.90", "5.239811"], ["84522.40", "4.697761"], ["84530.90", "4.878444"], ["84539.40", "4.246054"], ["84547.90", "4.607420"], ["84556.40", "5.420494"], ["84564.90", "4.968786"], ["84573.40", "5.149469"], ["84581.90", "4.336395"], ["84851.66", "0"], ["84852.81", "0"], ["84852.94", "0"], ["84853.56", "0"]], "bids": [["84318.90", "3.277974"], ["84309.80", "0.001414"], ["84307.80", "0.003721"], ["84306.51", "0.796380"], ["84305.80", "0.009793"], ["84303.80", "0.025772"], ["84301.80", "0.067821"], ["84299.80", "0.178475"], ["84297.80", "0.469670"], ["84295.80", "1.235974"], ["84294.90", "0"], ["84293.80", "3.252563"], ["84293.70", "0.001026"], ["84293.60", "0.001000"], ["84293.50", "0.745410"], ["84293.30", "0"], ["84293.20", "0"], ["84292.50", "0.436110"], ["84292.10", "0.171150"], ["84291.70", "0"], ["84291.40", "0.058710"], ["84289.80", "0.212100"], ["84289.10", "0"], ["84287.90", "1.195920"], ["84286.50", "0.274590"], ["84285.40", "1.350000"], ["84285.10", "0.015120"], ["84284.10", "1.100070"], ["84283.20", "0.916620"], ["84283.00", "0.450030"], ["84277.70", "0"], ["84251.60", "4.607420"], ["84243.10", "5.239811"], ["84234.60", "5.149469"], ["84226.10", "4.788103"], ["84217.60", "5.420494"], ["84209.10", "3.975029"], ["84208.73", "0"], ["84200.60", "5.510835"], ["84192.10", "5.059128"], ["84183.60", "4.155712"], ["84175.10", "3.884687"], ["84166.60", "4.517078"], ["84165.00", "0"], ["84158.10", "5.601177"], ["84149.60", "4.336395"], ["84141.10", "5.330152"], ["84132.60", "4.697761"], ["84124.10", "4.246054"], ["84115.60", "4.878444"], ["84107.10", "4.065370"], ["84098.60", "4.968786"], ["84090.10", "4.426737"], ["83895.00", "0"]], "checksum": -1691364688, "ts": "1742142243750"}], "ts": 1742142243755, "record_time": 1742142242.862932}
{"action": "update", "arg": {"instType": "SPOT", "channel": "books", "instId": "BTCUSDT"}, "data": [{"asks": [["84318.91", "0"], ["84323.68", "0"], ["84324.85", "0.063016"], ["84325.44", "0"], ["84325.48", "0"], ["84325.50", "0"], ["84325.73", "0"], ["84326.21", "0"], ["84326.24", "0"], ["84326.31", "0"], ["84326.35", "0"], ["84326.48", "0"], ["84326.50", "0"], ["84326.52", "0"], ["84326.53", "0"], ["84326.54", "0"], ["84326.56", "0"], ["84326.59", "0"], ["84327.28", "0"], ["84327.32", "0"], ["84327.33", "0"], ["84327.36", "0"], ["84327.37", "0"], ["84329.06", "0"], ["84329.72", "0"], ["84331.32", "0.004595"], ["84331.37", "0.001230"], ["84331.38", "0.000245"], ["84331.42", "0.006307"], ["84331.43", "0.001066"], ["84332.43", "0.001923"], ["84332.44", "0.007385"], ["84332.45", "0.000078"], ["84332.46", "0.008949"], ["84332.48", "0.015631"], ["84332.49", "0.009191"], ["84332.51", "0.005183"], ["84334.28", "0.080082"], ["84335.75", "0"], ["84336.73", "0.059483"], ["84338.79", "0"], ["84339.70", "0"], ["84341.56", "0"], ["84343.17", "0"], ["84344.49", "0"], ["84345.13", "0"], ["84346.83", "0.016428"], ["84346.94", "0.016427"], ["84348.20", "0"], ["84348.84", "0"], ["84350.47", "0.119895"], ["84351.59", "0.119879"], ["84352.62", "0"], ["84352.73", "0.015892"], ["84355.51", "0.012680"], ["84358.20", "0"], ["84358.57", "0"], ["84360.20", "0"], ["84364.20", "0.001070"], ["84366.20", "0.001031"], ["84368.20", "0.001024"], ["84368.29", "0.031812"], ["84370.20", "0.002572"], ["84372.20", "0.006770"], ["84374.20", "0.017814"], ["84376.20", "0.046880"], ["84378.20", "0.123369"], ["84378.30", "0"], ["84378.80", "0"], ["84378.90", "0"], ["84379.40", "0"], ["84379.90", "0"], ["84380.20", "0.324654"], ["84380.30", "0"], ["84380.40", "0"], ["84382.20", "0.854354"], ["84382.30", "0.001040"], ["84383.10", "0.001650"], ["84383.40", "0.001043"], ["84383.80", "0.003360"], ["84386.70", "0.078750"], ["84386.80", "0"], ["84387.00", "0"], ["84387.30", "0"], ["84387.90", "0.258030"], ["84388.80", "0"], ["84389.30", "0"], ["84389.60", "0"], ["84389.70", "0.470850"], ["84390.10", "0"], ["84390.40", "0"], ["84392.40", "0"], ["84393.00", "0.012480"], ["84393.20", "0.079650"], ["84393.30", "0.032880"], ["84393.40", "0.142500"], ["84393.80", "0.718170"], ["84393.90", "10.012830"], ["84394.20", "0.124050"], ["84420.40", "0"], ["84424.40", "4.065179"], ["84428.90", "0"], ["84432.90", "4.787878"], ["84437.40", "0"], ["84441.40", "3.974842"], ["84445.90", "0"], ["84449.90", "4.245854"], ["84454.40", "0"], ["84458.40", "4.336191"], ["84462.90", "0"], ["84466.90", "4.697540"], ["84471.40", "0"], ["84475.40", "4.968552"], ["84479.90", "0"], ["84483.90", "5.420239"], ["84488.40", "0"], ["84492.40", "5.329901"], ["84496.90", "0"], ["84500.90", "4.878215"], ["84505.40", "0"], ["84509.40", "5.058889"], ["84513.90", "0"], ["84517.90", "4.155516"], ["84522.40", "0"], ["84526.40", "5.149227"], ["84530.90", "0"], ["84534.90", "4.607203"], ["84539.40", "0"], ["84543.40", "4.516866"], ["84547.90", "0"], ["84551.90", "4.426528"], ["84556.40", "0"], ["84560.40", "5.510576"], ["84564.90", "0"], ["84568.90", "5.600913"], ["84573.40", "0"], ["84577.40", "3.884504"], ["84581.90", "0"], ["84585.90", "5.239564"], ["84851.66", "0.000029"], ["84852.81", "0.000115"], ["84852.94", "0.000065"], ["84853.56", "0.000050"], ["84857.14", "0.000347"], ["84858.75", "0.000285"], ["84859.29", "0.000036"], ["84860.00", "0.000169"], ["84862.90", "0.000169"], ["84864.69", "0.000052"], ["84864.86", "0.000041"], ["84864.99", "0.000033"], ["84866.10", "0.000064"], ["84866.40", "0.000018"], ["84867.80", "0.000095"], ["84868.42", "0.000031"], ["84868.52", "0.000013"], ["84868.65", "0.000035"], ["84869.57", "0.000932"]], "bids": [["84318.90", "3.291240"], ["84318.67", "0.005548"], ["84317.80", "0.001006"], ["84315.80", "0.001042"], ["84313.80", "0.001917"], ["84313.55", "0"], ["84311.80", "0.004829"], ["84309.80", "0.012708"], ["84307.80", "0.033442"], ["84307.67", "0"], ["84306.42", "0"], ["84305.80", "0.088005"], ["84305.71", "0.009760"], ["84305.63", "0.007641"], ["84303.92", "0.007345"], ["84303.85", "0.008986"], ["84303.83", "0.006213"], ["84303.82", "0.007436"], ["84303.80", "0.231591"], ["84303.78", "0.008549"], ["84303.76", "0.006535"], ["84303.75", "0.001199"], ["84303.51", "0.008139"], ["84302.27", "0.007870"], ["84301.84", "0.007475"], ["84301.80", "0.609449"], ["84300.66", "0"], ["84300.63", "0"], ["84300.61", "0"], ["84299.89", "0"], ["84299.84", "0"], ["84299.80", "1.603814"], ["84299.23", "0"], ["84298.98", "0"], ["84298.93", "0"], ["84298.91", "0"], ["84298.87", "0"], ["84298.83", "0"], ["84298.76", "0"], ["84298.56", "0.005548"], ["84298.52", "0.004935"], ["84298.48", "0.005963"], ["84298.46", "0.009627"], ["84298.44", "0"], ["84298.41", "0.008151"], ["84297.98", "0"], ["84297.81", "0.376270"], ["84297.80", "4.220563"], ["84297.71", "0"], ["84297.70", "0.001003"], ["84297.40", "3.753180"], ["84297.13", "0"], ["84297.08", "0.028795"], ["84296.71", "0.008667"], ["84296.26", "0"], ["84296.21", "0"], ["84296.20", "0.143100"], ["84296.10", "0.035550"], ["84296.00", "0.414510"], ["84295.90", "2.348040"], ["84295.80", "0.069780"], ["84295.51", "0.025073"], ["84295.00", "0.274770"], ["84293.80", "2.115720"], ["84293.73", "0.002948"], ["84293.70", "0"], ["84293.60", "0"], ["84293.56", "0"], ["84293.50", "0"], ["84293.41", "0"], ["84293.36", "0"], ["84292.70", "0"], ["84292.65", "0"], ["84292.64", "0"], ["84292.50", "0.435930"], ["84292.30", "0.197876"], ["84292.12", "0.271785"], ["84292.10", "0.035550"], ["84292.00", "0.652800"], ["84291.73", "0"], ["84291.59", "0"], ["84291.51", "0.075981"], ["84291.40", "0"], ["84291.30", "0.030210"], ["84291.22", "0.222637"], ["84291.20", "0"], ["84291.00", "0.009000"], ["84290.70", "0"], ["84290.20", "0.916620"], ["84289.44", "0"], ["84289.10", "0.015150"], ["84289.04", "0"], ["84288.27", "0"], ["84287.90", "0.721380"], ["84286.70", "0.038430"], ["84286.50", "0"], ["84285.40", "3.129300"], ["84285.10", "0"], ["84284.83", "0"], ["84284.70", "0"], ["84284.60", "0"], ["84283.92", "0"], ["84283.79", "0"], ["84283.52", "0.023729"], ["84283.20", "0"], ["84281.90", "0.560250"], ["84281.00", "0"], ["84280.90", "0.009000"], ["84279.91", "0.008206"], ["84279.90", "2.123970"], ["84279.80", "0.410370"], ["84278.00", "0"], ["84277.80", "0"], ["84275.09", "0.007181"], ["84275.06", "0.007582"], ["84274.35", "0"], ["84270.06", "0"], ["84269.92", "0"], ["84269.35", "0"], ["84262.80", "0.207047"], ["84261.70", "0"], ["84255.60", "5.329901"], ["84251.60", "0"], ["84247.10", "4.065179"], ["84243.10", "0"], ["84238.60", "5.149227"], ["84234.60", "0"], ["84230.10", "5.510576"], ["84226.10", "0"], ["84221.60", "4.155516"], ["84219.68", "0.072042"], ["84217.60", "0"], ["84213.10", "5.058889"], ["84209.10", "0"], ["84204.60", "5.420239"], ["84200.60", "0"], ["84196.10", "4.697540"], ["84192.10", "0"], ["84187.60", "4.245854"], ["84183.60", "0"], ["84179.10", "4.336191"], ["84175.10", "0"], ["84170.60", "3.884504"], ["84166.60", "0"], ["84162.10", "4.607203"], ["84158.10", "0"], ["84153.60", "4.426528"], ["84149.60", "0"], ["84145.10", "4.878215"], ["84141.10", "0"], ["84136.60", "4.787878"], ["84132.60", "0"], ["84128.10", "4.516866"], ["84124.10", "0"], ["84119.60", "3.974842"], ["84115.60", "0"], ["84111.10", "5.239564"], ["84107.10", "0"], ["84102.60", "4.968552"], ["84098.60", "0"], ["84094.10", "5.600913"], ["84090.10", "0"], ["83895.00", "0.006121"], ["83894.74", "0.000068"], ["83894.17", "0.000022"], ["83893.81", "0.000010"], ["83893.64", "0.000039"]], "checksum": 376893029, "ts": "1742142243951"}], "ts": 1742142243960, "record_time": 1742142243.068898}
