{"action": "update", "arg": {"instType": "SPOT", "channel": "books", "instId": "BTCUSDT"}, "data": [{"asks": [["84293.15", "1.200579"], ["84294.13", "0.004595"], ["84294.26", "0.010074"], ["84294.28", "0.001066"], ["84294.29", "0.000245"], ["84294.33", "0.008962"], ["84294.34", "0.006307"], ["84294.97", "0.019142"], ["84294.98", "0"], ["84295.24", "0.018859"], ["84295.25", "0.005183"], ["84295.26", "0.007385"], ["84295.28", "0.007705"], ["84295.29", "0.007359"], ["84297.38", "0.080382"], ["84299.57", "0.068142"], ["84299.88", "0.140052"], ["84302.50", "0.148098"], ["84303.10", "0.009610"], ["84304.94", "0"], ["84304.96", "0.001205"], ["84305.17", "0.119869"], ["84306.43", "0.035952"], ["84307.36", "0.006356"], ["84307.46", "0.006356"], ["84307.58", "0.006356"], ["84307.73", "0.006356"], ["84308.22", "0.006356"], ["84308.30", "0.010985"], ["84308.79", "0"], ["84308.80", "0.012712"], ["84309.13", "0.006356"], ["84309.36", "0.016428"], ["84309.39", "0.006356"], ["84309.79", "0.006356"], ["84309.94", "0.006356"], ["84310.13", "0.119843"], ["84310.75", "0.006356"], ["84310.83", "0.006356"], ["84310.85", "0.006356"], ["84311.28", "0.006357"], ["84311.95", "0.006356"], ["84312.85", "0.010984"], ["84313.05", "0.009989"], ["84314.11", "0.119895"], ["84314.98", "0.015892"], ["84315.15", "0.119881"], ["84315.48", "0.119879"], ["84315.62", "0.009989"], ["84316.19", "0"], ["84317.71", "0.006356"], ["84319.39", "0.001807"], ["84319.94", "0"], ["84320.90", "0.015891"], ["84321.63", "0.010986"], ["84324.10", "0.001023"], ["84324.71", "0"], ["84326.10", "0.001028"], ["84328.10", "0.002206"], ["84328.64", "0.010000"], ["84330.10", "0.005805"], ["84331.80", "0"], ["84332.10", "0.015026"], ["84333.80", "0"], ["84334.10", "0.039544"], ["84334.69", "0.029802"], ["84335.80", "0"], ["84336.10", "0.104061"], ["84337.80", "0"], ["84338.10", "0.273845"], ["84339.80", "0"], ["84340.10", "0.720866"], ["84341.80", "0"], ["84342.10", "1.897016"], ["84343.80", "0"], ["84344.10", "4.992147"], ["84344.20", "0.070020"], ["84344.60", "2.034480"], ["84344.70", "0.001002"], ["84345.10", "2.437830"], ["84345.80", "0.035580"], ["84346.20", "0.069600"], ["84347.70", "0.444120"], ["84347.80", "0"], ["84348.20", "0.626100"], ["84348.50", "0.015150"], ["84348.60", "0.142500"], ["84348.90", "1.000590"], ["84349.80", "0"], ["84349.90", "0.379290"], ["84350.20", "0.069600"], ["84350.80", "0.035580"], ["84351.80", "6.775980"], ["84352.10", "0"], ["84352.30", "0"], ["84353.00", "0.248880"], ["84353.20", "0.410370"], ["84353.50", "0"], ["84356.00", "0.651750"], ["84356.70", "0.035580"], ["84357.10", "0"], ["84357.50", "0"], ["84358.50", "0"], ["84359.20", "1.779300"], ["84360.60", "0"], ["84360.80", "0"], ["84361.40", "0"], ["84361.80", "0"], ["84362.20", "0"], ["84362.90", "0"], ["84363.00", "0"], ["84363.40", "0"], ["84364.30", "0"], ["84375.26", "0"], ["84386.30", "4.338151"], ["84394.00", "0"], ["84394.80", "4.157395"], ["84402.50", "0"], ["84403.30", "4.247773"], ["84411.00", "0"], ["84411.80", "5.603445"], ["84419.50", "0"], ["84420.30", "4.609286"], ["84428.00", "0"], ["84428.80", "5.422689"], ["84436.50", "0"], ["84437.30", "3.976639"], ["84445.00", "0"], ["84445.80", "3.886261"], ["84453.50", "0"], ["84454.30", "4.970798"], ["84462.00", "0"], ["84462.80", "5.241933"], ["84470.50", "0"], ["84471.30", "4.518908"], ["84479.00", "0"], ["84479.80", "5.332311"], ["84487.50", "0"], ["84488.30", "4.699664"], ["84496.00", "0"], ["84496.80", "5.151555"], ["84504.50", "0"], ["84505.30", "5.513067"], ["84513.00", "0"], ["84513.80", "4.428529"], ["84521.50", "0"], ["84522.30", "4.067017"], ["84530.00", "0"], ["84530.80", "5.061176"], ["84538.50", "0"], ["84539.30", "4.880420"], ["84547.00", "0"], ["84547.80", "4.790042"], ["84555.50", "0"], ["84851.66", "0"], ["84852.81", "0"], ["84852.94", "0"], ["84853.56", "0"], ["84857.14", "0"], ["84858.75", "0"], ["84859.29", "0"], ["84860.00", "0"], ["84862.90", "0"], ["84864.69", "0"], ["84864.86", "0"], ["84864.99", "0"], ["84866.10", "0"], ["84866.40", "0"], ["84867.80", "0"], ["84868.42", "0"], ["84868.52", "0"], ["84868.65", "0"], ["84869.57", "0"], ["84871.66", "0"], ["84871.79", "0"], ["84873.84", "0"], ["84874.79", "0"], ["84875.00", "0"], ["84875.78", "0"], ["84876.03", "0"], ["84879.10", "0"], ["84879.37", "0"], ["84879.59", "0"], ["84880.00", "0"], ["84880.89", "0"], ["84882.35", "0"], ["84883.65", "0"], ["84883.72", "0"], ["84883.84", "0"], ["84885.24", "0"], ["84885.53", "0"], ["84886.01", "0"], ["84886.02", "0"], ["84886.96", "0"], ["84887.65", "0"], ["84888.00", "0"], ["84888.68", "0"], ["84888.89", "0"], ["84889.87", "0"], ["84890.00", "0"]], "bids": [["84293.14", "0.202211"], ["84293.13", "0.000100"], ["84293.12", "0.000100"], ["84293.11", "0.000100"], ["84289.46", "0.140052"], ["84289.35", "0.010000"], ["84289.05", "0.012680"], ["84287.40", "0"], ["84287.21", "0.055144"], ["84285.95", "0"], ["84285.72", "0.353132"], ["84285.40", "0"], ["84283.40", "0"], ["84281.40", "0"], ["84279.70", "0.001019"], ["84279.40", "0"], ["84277.70", "0.001005"], ["84277.40", "0"], ["84277.11", "0"], ["84275.70", "0.001006"], ["84275.68", "0.003006"], ["84275.40", "0"], ["84275.24", "0"], ["84275.22", "0"], ["84273.70", "0.001020"], ["84273.40", "0"], ["84272.79", "0"], ["84272.63", "0.171566"], ["84272.38", "0.000070"], ["84271.70", "0.001935"], ["84271.40", "0"], ["84269.70", "0.005093"], ["84269.40", "0"], ["84269.17", "0.000213"], ["84269.16", "0.007513"], ["84269.10", "0.008535"], ["84267.70", "0.013403"], ["84267.52", "0.008555"], ["84267.48", "0.008986"], ["84267.45", "0.006535"], ["84267.44", "0.006213"], ["84267.40", "0"], ["84267.30", "0"], ["84267.21", "0.001199"], ["84266.80", "0"], ["84266.70", "0"], ["84266.47", "0.007870"], ["84266.43", "0.008142"], ["84265.70", "0.035012"], ["84265.50", "0"], ["84265.00", "0"], ["84264.90", "0"], ["84264.84", "0.007474"], ["84264.82", "0.007950"], ["84264.28", "0.018258"], ["84263.87", "0.247971"], ["84263.70", "0.092138"], ["84262.79", "0.017833"], ["84262.61", "0.084428"], ["84262.05", "0.011489"], ["84261.99", "0.004935"], ["84261.96", "0.000875"], ["84261.90", "0.005088"], ["84261.70", "0.242468"], ["84261.53", "0.016458"], ["84261.22", "0.015769"], ["84261.09", "0.006564"], ["84260.78", "0.017059"], ["84260.75", "0.017076"], ["84260.70", "0"], ["84260.43", "0.056347"], ["84260.35", "0.008672"], ["84260.08", "0.007118"], ["84259.70", "0.638073"], ["84259.66", "0.007315"], ["84259.63", "0.028804"], ["84259.40", "0.003840"], ["84259.30", "0.001025"], ["84259.20", "0.091290"], ["84259.08", "0.017330"], ["84259.06", "0.008987"], ["84258.99", "0.008164"], ["84258.72", "0.227645"], ["84258.60", "0"], ["84258.40", "0"], ["84258.06", "0.052102"], ["84257.90", "0"], ["84257.80", "0"], ["84257.51", "0.008282"], ["84257.17", "0.012647"], ["84257.00", "0"], ["84256.58", "0.018517"], ["84256.53", "0.002949"], ["84256.30", "0"], ["84255.79", "0.271868"], ["84255.14", "0.222705"], ["84254.80", "0.015090"], ["84254.50", "0.065460"], ["84254.47", "0.263297"], ["84254.09", "0.021106"], ["84253.80", "0"], ["84253.79", "0.076004"], ["84253.70", "0.152790"], ["84253.60", "0"], ["84252.89", "0.012438"], ["84251.40", "0.142500"], ["84251.20", "0.177960"], ["84251.16", "0.073497"], ["84250.88", "0"], ["84250.50", "0.009000"], ["84250.10", "0.464820"], ["84249.80", "0.177780"], ["84249.60", "0.415530"], ["84249.53", "0.056632"], ["84249.40", "0.915360"], ["84248.90", "0.383520"], ["84248.20", "0.265440"], ["84247.00", "0.035580"], ["84246.30", "0.030000"], ["84246.10", "0.922500"], ["84246.00", "0.012360"], ["84245.80", "0.069600"], ["84243.31", "0.008206"], ["84238.75", "0.007182"], ["84225.20", "0"], ["84217.50", "5.603445"], ["84216.70", "0"], ["84209.00", "4.247773"], ["84208.20", "0"], ["84200.50", "5.241933"], ["84199.70", "0"], ["84192.00", "4.518908"], ["84191.20", "0"], ["84183.50", "5.513067"], ["84182.70", "0"], ["84175.00", "4.699664"], ["84174.20", "0"], ["84166.50", "3.976639"], ["84165.70", "0"], ["84158.00", "4.157395"], ["84157.20", "0"], ["84149.50", "4.428529"], ["84148.70", "0"], ["84141.00", "4.880420"], ["84140.20", "0"], ["84132.50", "4.609286"], ["84131.70", "0"], ["84124.00", "5.061176"], ["84123.20", "0"], ["84115.50", "4.790042"], ["84114.70", "0"], ["84107.00", "3.886261"], ["84106.20", "0"], ["84098.50", "4.338151"], ["84097.70", "0"], ["84090.00", "4.970798"], ["84089.20", "0"], ["84081.50", "5.332311"], ["84080.70", "0"], ["84073.00", "4.067017"], ["84072.20", "0"], ["84064.50", "5.151555"], ["84063.70", "0"], ["84056.00", "5.422689"], ["83885.98", "0"], ["83885.71", "0"], ["83884.62", "0"], ["83884.55", "0"], ["83884.30", "0"], ["83882.98", "0"], ["83882.92", "0"], ["83881.99", "0"], ["83880.00", "0"], ["83877.97", "0"], ["83877.55", "0"], ["83877.42", "0"], ["83877.29", "0"], ["83877.05", "0"], ["83876.25", "0"], ["83876.12", "0"], ["83875.99", "0"], ["83875.49", "0"], ["83875.16", "0"], ["83875.00", "0"], ["83874.55", "0"], ["83874.15", "0"], ["83873.87", "0"], ["83873.52", "0"], ["83870.97", "0"], ["83870.95", "0"], ["83870.78", "0"], ["83870.00", "0"], ["83869.57", "0"], ["83868.82", "0"], ["83866.67", "0"], ["83865.80", "0"], ["83865.10", "0"], ["83864.54", "0"], ["83863.64", "0"], ["83863.52", "0"], ["83860.29", "0"], ["83860.10", "0"], ["83860.00", "0"], ["83859.94", "0"], ["83859.35", "0"], ["83859.25", "0"], ["83858.82", "0"], ["83857.50", "0"], ["83857.14", "0"], ["83857.13", "0"], ["83856.00", "0"], ["83855.78", "0"], ["83855.44", "0"], ["83855.42", "0"], ["83854.95", "0"], ["83854.17", "0"], ["83854.00", "0"]], "checksum": -1716224629, "ts": "1742142216320"}], "ts": 1742142216328, "record_time": 1742142215.436941}
{"action": "update", "arg": {"instType": "SPOT", "channel": "books", "instId": "BTCUSDT"}, "data": [{"asks": [["84293.15", "1.340630"], ["84294.27", "0.005541"], ["84294.30", "0.004974"], ["84294.31", "0.001230"], ["84294.97", "0.035669"], ["84295.22", "0.007955"], ["84295.23", "0.000443"], ["84295.24", "0.020782"], ["84295.25", "0.012293"], ["84295.28", "0.012444"], ["84299.55", "0.003017"], ["84299.88", "0"], ["84300.47", "0.001827"], ["84309.35", "0"], ["84309.66", "0"], ["84310.58", "0"], ["84328.10", "0.002337"], ["84330.10", "0.006408"], ["84332.10", "0.016864"], ["84332.98", "0.031812"], ["84334.10", "0.044379"], ["84334.69", "0"], ["84336.10", "0.116786"], ["84338.10", "0.307332"], ["84340.10", "0.808768"], ["84342.10", "2.128337"], ["84344.10", "5.600888"], ["84344.60", "1.493400"], ["84345.10", "2.349060"], ["84351.80", "5.535150"], ["84354.10", "0.117000"], ["84354.50", "0.687030"], ["84354.80", "0.180000"], ["84355.80", "0.135000"], ["84358.20", "0"], ["84359.20", "0"], ["84360.40", "0"], ["84366.83", "0.209200"], ["84386.30", "5.422689"], ["84394.80", "4.699664"], ["84403.30", "4.970798"], ["84411.80", "4.518908"], ["84420.30", "5.241933"], ["84428.80", "4.880420"], ["84437.30", "5.332311"], ["84454.30", "5.513067"], ["84462.80", "3.976639"], ["84471.30", "4.247773"], ["84479.80", "4.338151"], ["84488.30", "4.428529"], ["84496.80", "4.067017"], ["84505.30", "4.609286"], ["84513.80", "5.151555"], ["84522.30", "5.061176"], ["84530.80", "5.603445"], ["84539.30", "4.157395"], ["84846.85", "0"], ["84847.58", "0"], ["84847.82", "0"], ["84849.88", "0"], ["84850.00", "0"]], "bids": [["84289.46", "0"], ["84286.07", "1.894626"], ["84285.73", "0.105940"], ["84285.10", "0.140051"], ["84277.52", "0"], ["84272.63", "0"], ["84272.38", "0"], ["84271.70", "0.001003"], ["84269.70", "0.001038"], ["84269.21", "2.549577"], ["84269.11", "0.001228"], ["84269.09", "0.007641"], ["84269.07", "0.006487"], ["84267.70", "0.002162"], ["84267.51", "0.007437"], ["84267.48", "0.016330"], ["84266.89", "0.003036"], ["84266.65", "0.002062"], ["84265.70", "0.005690"], ["84263.70", "0.014974"], ["84261.95", "0.008149"], ["84261.86", "0.009630"], ["84261.70", "0.039404"], ["84260.20", "0.010234"], ["84259.70", "0.103695"], ["84259.20", "0.091470"], ["84257.90", "1.180260"], ["84257.30", "0.305700"], ["84255.63", "0"], ["84255.09", "0"], ["84254.80", "0.055230"], ["84253.70", "0.142530"], ["84253.60", "0.177960"], ["84252.90", "0.008700"], ["84251.20", "0"], ["84248.80", "0.265440"], ["84248.20", "0"], ["84247.33", "0.023737"], ["84247.00", "0"], ["84246.10", "1.292760"], ["84245.80", "0"], ["84244.06", "0.023936"], ["84238.76", "0.007582"], ["84222.41", "0.209200"], ["84217.50", "5.422689"], ["84209.00", "5.513067"], ["84200.50", "4.067017"], ["84192.00", "4.338151"], ["84183.50", "3.886261"], ["84182.71", "0"], ["84175.00", "4.609286"], ["84166.50", "4.518908"], ["84158.00", "5.332311"], ["84149.50", "4.699664"], ["84141.00", "4.247773"], ["84132.50", "4.880420"], ["84115.50", "5.241933"], ["84107.00", "5.151555"], ["84098.50", "4.157395"], ["84081.50", "3.976639"], ["84073.00", "4.790042"], ["84064.50", "5.603445"], ["84056.00", "4.428529"], ["83893.81", "0"], ["83893.64", "0"], ["83893.62", "0"], ["83892.29", "0"], ["83891.43", "0"], ["83891.30", "0"], ["83888.89", "0"], ["83888.86", "0"], ["83887.29", "0"], ["83887.11", "0"], ["83886.91", "0"]], "checksum": -894372743, "ts": "1742142216522"}], "ts": 1742142216527, "record_time": 1742142215.634381}
{"action": "update", "arg": {"instType": "SPOT", "channel": "books", "instId": "BTCUSDT"}, "data": [{"asks": [["84293.15", "1.489308"], ["84294.13", "0"], ["84294.26", "0"], ["84294.27", "0"], ["84294.28", "0"], ["84294.29", "0"], ["84294.30", "0"], ["84294.31", "0"], ["84294.33", "0"], ["84294.34", "0"], ["84295.22", "0"], ["84295.23", "0"], ["84295.24", "0"], ["84295.25", "0"], ["84295.26", "0"], ["84295.28", "0"], ["84295.29", "0"], ["84299.28", "0.002907"], ["84299.57", "0.108824"], ["84299.58", "0"], ["84305.17", "0"], ["84305.98", "0.017798"], ["84306.43", "0"], ["84307.36", "0"], ["84307.46", "0"], ["84307.58", "0"], ["84307.73", "0"], ["84308.22", "0"], ["84308.30", "0"], ["84308.80", "0"], ["84309.13", "0"], ["84309.36", "0"], ["84309.39", "0"], ["84309.79", "0"], ["84309.94", "0"], ["84310.13", "0"], ["84310.75", "0"], ["84310.83", "0"], ["84310.85", "0"], ["84311.28", "0"], ["84311.95", "0"], ["84312.61", "0"], ["84312.67", "0"], ["84312.85", "0"], ["84313.05", "0"], ["84314.11", "0"], ["84314.98", "0"], ["84315.02", "0"], ["84315.48", "0"], ["84315.62", "0"], ["84317.71", "0"], ["84318.09", "0"], ["84319.39", "0"], ["84320.90", "0"], ["84321.63", "0"], ["84325.57", "0.026414"], ["84328.10", "0.002638"], ["84329.53", "0"], ["84330.10", "0.006943"], ["84332.10", "0.018271"], ["84332.98", "0"], ["84334.10", "0.048081"], ["84336.10", "0.126528"], ["84338.10", "0.332970"], ["84338.43", "0"], ["84340.10", "0.876237"], ["84342.10", "2.305885"], ["84344.10", "6.068120"], ["84344.60", "1.720350"], ["84345.10", "2.348850"], ["84345.20", "0.270030"], ["84350.26", "0"], ["84351.80", "5.531400"], ["84352.11", "0"], ["84353.00", "0.318930"], ["84354.90", "0.032910"], ["84355.60", "0.198000"], ["84355.70", "0.090000"], ["84356.70", "0"], ["84357.70", "0"], ["84386.30", "5.241933"], ["84394.80", "5.603445"], ["84403.30", "4.338151"], ["84411.80", "4.699664"], ["84420.30", "3.976639"], ["84428.80", "4.970798"], ["84437.30", "4.067017"], ["84445.80", "5.061176"], ["84454.30", "4.428529"], ["84462.80", "4.247773"], ["84471.30", "5.151555"], ["84479.80", "3.886261"], ["84488.30", "5.422689"], ["84496.80", "4.609286"], ["84505.30", "4.157395"], ["84513.80", "4.518908"], ["84522.30", "5.332311"], ["84530.80", "4.790042"], ["84539.30", "4.880420"], ["84547.80", "5.513067"], ["84846.85", "0.000176"], ["84847.58", "0.000039"], ["84847.82", "0.000671"], ["84849.88", "0.000030"], ["84850.00", "0.000031"], ["84851.66", "0.000029"], ["84852.81", "0.000115"], ["84852.94", "0.000065"], ["84853.56", "0.000050"], ["84857.14", "0.000347"], ["84858.75", "0.000285"], ["84859.29", "0.000036"], ["84860.00", "0.000169"], ["84862.90", "0.000169"], ["84864.69", "0.000052"], ["84864.86", "0.000041"], ["84864.99", "0.000033"], ["84866.10", "0.000064"], ["84866.40", "0.000018"], ["84867.80", "0.000095"], ["84868.42", "0.000031"], ["84868.52", "0.000013"], ["84868.65", "0.000035"], ["84869.57", "0.000932"], ["84871.66", "0.000078"], ["84871.79", "0.000014"], ["84873.84", "0.000057"], ["84874.79", "0.000096"], ["84875.00", "0.000959"], ["84875.78", "0.000038"], ["84876.03", "0.000161"], ["84879.10", "0.000009"], ["84879.37", "0.000009"], ["84879.59", "0.000173"], ["84880.00", "0.025078"], ["84880.89", "0.000065"], ["84882.35", "0.000417"], ["84883.65", "0.000008"], ["84883.72", "0.000010"], ["84883.84", "0.000040"], ["84885.24", "0.000112"], ["84885.53", "0.000022"], ["84886.01", "0.000023"], ["84886.02", "0.000054"], ["84886.96", "0.000013"], ["84887.65", "0.000019"], ["84888.00", "0.000010"], ["84888.68", "0.000013"], ["84888.89", "0.000113"], ["84889.87", "0.000010"], ["84890.00", "0.000118"]], "bids": [["84293.14", "0.000100"], ["84291.54", "0"], ["84289.05", "0"], ["84287.21", "0"], ["84286.07", "0"], ["84285.73", "0"], ["84285.72", "0"], ["84285.10", "0"], ["84281.75", "0"], ["84281.74", "0"], ["84281.62", "0"], ["84277.51", "0"], ["84275.68", "0"], ["84269.21", "0"], ["84269.17", "0"], ["84269.16", "0"], ["84269.11", "0"], ["84269.10", "0"], ["84269.09", "0"], ["84269.08", "0"], ["84269.07", "0"], ["84267.70", "0.001596"], ["84267.52", "0"], ["84267.51", "0"], ["84267.48", "0"], ["84267.45", "0"], ["84267.44", "0"], ["84267.21", "0"], ["84266.89", "0"], ["84266.65", "0"], ["84266.47", "0"], ["84266.43", "0"], ["84265.70", "0.004200"], ["84264.84", "0"], ["84264.82", "0"], ["84264.28", "0"], ["84263.87", "0"], ["84263.70", "0.011052"], ["84262.79", "0"], ["84262.61", "0"], ["84262.05", "0"], ["84261.99", "0"], ["84261.96", "0"], ["84261.95", "0"], ["84261.90", "0"], ["84261.86", "0"], ["84261.70", "0.029085"], ["84261.53", "0"], ["84261.22", "0"], ["84261.19", "0"], ["84261.09", "0"], ["84260.78", "0"], ["84260.75", "0"], ["84260.43", "0"], ["84260.35", "0"], ["84260.20", "0"], ["84260.08", "0"], ["84259.70", "0.076539"], ["84259.66", "0"], ["84259.63", "0"], ["84259.20", "0.083358"], ["84259.08", "0"], ["84259.06", "0"], ["84258.99", "0"], ["84258.72", "0"], ["84258.06", "0"], ["84257.90", "0"], ["84257.51", "0"], ["84257.30", "0"], ["84257.17", "0"], ["84256.58", "0"], ["84256.53", "0"], ["84255.79", "0"], ["84255.14", "0"], ["84254.09", "0"], ["84253.79", "0"], ["84252.90", "0.019650"], ["84252.89", "0"], ["84251.40", "0"], ["84251.16", "0"], ["84249.53", "0"], ["84249.00", "0.265440"], ["84248.90", "0.421980"], ["84248.80", "0"], ["84247.30", "0.030000"], ["84246.30", "0"], ["84246.10", "0"], ["84246.00", "0"], ["84243.31", "0"], ["84239.67", "0"], ["84238.76", "0"], ["84238.75", "0"], ["84237.64", "0"], ["84217.50", "4.518908"], ["84209.00", "5.151555"], ["84200.50", "5.513067"], ["84192.00", "4.699664"], ["84183.50", "4.970798"], ["84179.68", "0"], ["84175.00", "4.247773"], ["84169.00", "0.012838"], ["84166.50", "4.338151"], ["84164.00", "0.000159"], ["84158.00", "4.609286"], ["84149.50", "4.428529"], ["84141.00", "5.061176"], ["84132.50", "4.790042"], ["84124.00", "3.976639"], ["84115.50", "4.880420"], ["84107.00", "5.241933"], ["84098.50", "5.603445"], ["84090.00", "4.157395"], ["84081.50", "3.886261"], ["84073.00", "5.422689"], ["84064.50", "5.332311"], ["84056.00", "4.067017"], ["83893.81", "0.000010"], ["83893.64", "0.000039"], ["83893.62", "0.000137"], ["83892.29", "0.000143"], ["83891.43", "0.000455"], ["83891.30", "0.000010"], ["83888.89", "0.000163"], ["83888.86", "0.000371"], ["83887.29", "0.000586"], ["83887.11", "0.000075"], ["83886.91", "0.000145"], ["83885.98", "0.000018"], ["83885.71", "0.000069"], ["83884.62", "0.000014"], ["83884.55", "0.000048"], ["83884.30", "0.000161"], ["83882.98", "0.000188"], ["83882.92", "0.002384"], ["83881.99", "0.000038"], ["83880.00", "0.020454"], ["83877.97", "0.000023"], ["83877.55", "0.000010"], ["83877.42", "0.000054"], ["83877.29", "0.000024"], ["83877.05", "0.000008"], ["83876.25", "0.000028"], ["83876.12", "0.000681"], ["83875.99", "0.000299"], ["83875.49", "0.000723"], ["83875.16", "0.000179"], ["83875.00", "0.000145"], ["83874.55", "0.000145"], ["83874.15", "0.000150"], ["83873.87", "0.000041"], ["83873.52", "0.000135"], ["83870.97", "0.000194"], ["83870.95", "0.000078"], ["83870.78", "0.000019"], ["83870.00", "0.000121"], ["83869.57", "0.000035"], ["83868.82", "0.000017"], ["83866.67", "0.000138"], ["83865.80", "0.000098"], ["83865.10", "0.000134"], ["83864.54", "0.000009"], ["83863.64", "0.000012"], ["83863.52", "0.000510"], ["83860.29", "0.000041"], ["83860.10", "0.000023"], ["83860.00", "0.000024"], ["83859.94", "0.000058"], ["83859.35", "0.000051"], ["83859.25", "0.000115"], ["83858.82", "0.000105"], ["83857.50", "0.000025"], ["83857.14", "0.000431"], ["83857.13", "0.000019"], ["83856.00", "0.000010"], ["83855.78", "0.000009"], ["83855.44", "0.000008"], ["83855.42", "0.000564"], ["83854.95", "0.000462"], ["83854.17", "0.000039"], ["83854.00", "0.500470"], ["83853.33", "0.000125"], ["83852.50", "0.000043"], ["83852.40", "0.000011"], ["83852.30", "0.000029"], ["83852.19", "0.000009"], ["83851.85", "0.000011"], ["83851.84", "0.000219"], ["83850.00", "0.002875"], ["83848.94", "0.000007"], ["83848.38", "0.000042"], ["83848.17", "0.000217"], ["83846.22", "0.000018"], ["83846.15", "0.000075"], ["83845.92", "0.000111"], ["83845.30", "0.000573"], ["83844.83", "0.000008"]], "checksum": 634278412, "ts": "1742142216723"}], "ts": 1742142216730, "record_time": 1742142215.841248}
{"action": "update", "arg": {"instType": "SPOT", "channel": "books", "instId": "BTCUSDT"}, "data": [{"asks": [["84267.06", "0.330826"], ["84272.30", "1.133800"], ["84272.31", "0.267000"], ["84275.16", "0.004595"], ["84275.27", "0.005541"], ["84276.22", "0.001162"], ["84276.25", "0.007627"], ["84278.48", "0.010074"], ["84278.50", "0.006204"], ["84278.51", "0.000245"], ["84278.53", "0.008962"], ["84278.56", "0.006307"], ["84279.38", "0.000443"], ["84279.39", "0.001923"], ["84279.40", "0.009191"], ["84279.44", "0.000078"], ["84279.45", "0.007359"], ["84279.82", "0.080382"], ["84280.23", "0.209200"], ["84280.86", "0.209200"], ["84282.94", "0.047500"], ["84282.95", "0.000356"], ["84288.93", "0.203170"], ["84289.94", "0.001205"], ["84293.14", "0.241200"], ["84293.15", "0.661826"], ["84293.58", "0.119869"], ["84293.91", "0.017800"], ["84294.70", "0.313205"], ["84294.97", "0.019142"], ["84295.77", "0.006356"], ["84295.86", "0.006356"], ["84296.10", "0.035952"], ["84296.74", "0.010985"], ["84296.76", "0.006356"], ["84297.26", "0.006356"], ["84297.27", "0.006356"], ["84297.38", "0"], ["84297.44", "0.006356"], ["84297.79", "0.022784"], ["84297.95", "0.006356"], ["84298.10", "0.006356"], ["84298.20", "0.006356"], ["84298.33", "0.006356"], ["84298.49", "0.006356"], ["84298.54", "0.119843"], ["84299.09", "0.016427"], ["84299.23", "0.006356"], ["84299.71", "0.006357"], ["84299.78", "0.006356"], ["84301.18", "0.010984"], ["84302.70", "0.009989"], ["84302.87", "0.001807"], ["84302.98", "0.119881"], ["84302.99", "0.119895"], ["84303.10", "0.005701"], ["84303.31", "0.119879"], ["84303.41", "0.015892"], ["84304.02", "0.009989"], ["84304.96", "0"], ["84305.00", "0.001044"], ["84305.98", "0"], ["84307.00", "0.001035"], ["84307.38", "0.015891"], ["84309.00", "0.001775"], ["84309.54", "0.010986"], ["84311.00", "0.004670"], ["84312.50", "0"], ["84312.66", "0"], ["84313.00", "0.012291"], ["84315.00", "0.032344"], ["84315.15", "0"], ["84317.00", "0.085116"], ["84319.00", "0.223989"], ["84321.00", "0.589445"], ["84323.00", "1.551172"], ["84324.10", "0"], ["84325.00", "4.082030"], ["84326.10", "0"], ["84327.10", "0.052650"], ["84327.30", "0.052650"], ["84328.10", "0"], ["84328.20", "1.297320"], ["84328.26", "0.001597"], ["84328.30", "0.001022"], ["84328.39", "0.001597"], ["84328.64", "0"], ["84329.40", "0.142500"], ["84329.52", "0"], ["84330.10", "0"], ["84330.20", "0.069600"], ["84331.70", "9.578190"], ["84332.00", "1.079040"], ["84332.10", "0"], ["84332.20", "0.069600"], ["84332.90", "0.654450"], ["84333.30", "0.405570"], ["84333.60", "1.755570"], ["84334.10", "0"], ["84334.20", "0.069600"], ["84334.50", "0.015180"], ["84335.10", "0.015120"], ["84335.50", "5.711700"], ["84335.80", "0.142500"], ["84336.10", "0"], ["84336.20", "0.069600"], ["84336.40", "0.355770"], ["84336.70", "0.171750"], ["84336.90", "1.150200"], ["84337.10", "0.410370"], ["84338.10", "0"], ["84338.20", "0.069600"], ["84339.10", "2.312040"], ["84339.20", "1.176300"], ["84340.10", "0"], ["84340.20", "0.069600"], ["84341.60", "1.779300"], ["84342.10", "0"], ["84342.20", "1.627320"], ["84343.30", "0.160890"], ["84343.60", "1.268340"], ["84344.10", "0"], ["84344.20", "0"], ["84344.60", "0"], ["84344.70", "0"], ["84345.10", "0"], ["84345.20", "0"], ["84345.80", "0"], ["84346.20", "0"], ["84347.70", "0"], ["84348.20", "0"], ["84348.50", "0"], ["84348.60", "0"], ["84348.90", "0"], ["84349.90", "0"], ["84350.20", "0"], ["84350.80", "0"], ["84351.80", "0"], ["84352.20", "0"], ["84352.40", "0"], ["84353.00", "0"], ["84353.20", "0"], ["84353.39", "0.072042"], ["84353.57", "0.072042"], ["84354.10", "0"], ["84354.20", "0"], ["84354.50", "0"], ["84354.80", "0"], ["84354.90", "0"], ["84355.00", "0"], ["84355.40", "0"], ["84355.60", "0"], ["84355.70", "0"], ["84355.80", "0"], ["84356.00", "0.197885"], ["84356.20", "0"], ["84367.10", "4.067938"], ["84375.60", "5.423917"], ["84384.10", "5.604714"], ["84385.55", "0"], ["84385.61", "0"], ["84386.30", "0"], ["84392.60", "4.971924"], ["84394.80", "0"], ["84395.97", "0"], ["84401.10", "4.429532"], ["84403.30", "0"], ["84409.60", "4.248735"], ["84411.80", "0"], ["84418.10", "4.519931"], ["84420.30", "0"], ["84426.60", "3.887140"], ["84428.80", "0"], ["84435.10", "5.243119"], ["84437.30", "0"], ["84443.60", "5.333518"], ["84445.80", "0"], ["84452.10", "5.514315"], ["84454.30", "0"], ["84460.60", "4.791126"], ["84462.80", "0"], ["84469.10", "4.158336"], ["84471.30", "0"], ["84477.60", "5.062322"], ["84479.80", "0"], ["84486.10", "4.881525"], ["84488.30", "0"], ["84494.60", "5.152721"], ["84496.80", "0"], ["84503.10", "3.977539"], ["84505.30", "0"], ["84511.60", "4.700728"], ["84513.80", "0"], ["84520.10", "4.339133"], ["84522.30", "0"], ["84528.60", "4.610329"], ["84530.80", "0"], ["84539.30", "0"], ["84547.80", "0"], ["84619.94", "1.586857"], ["84646.85", "0"], ["84847.82", "0"], ["84849.88", "0"], ["84850.00", "0"], ["84851.66", "0"], ["84852.81", "0"], ["84852.94", "0"], ["84853.56", "0"], ["84857.14", "0"], ["84858.75", "0"], ["84859.29", "0"], ["84860.00", "0"], ["84862.90", "0"], ["84864.69", "0"], ["84864.86", "0"], ["84864.99", "0"], ["84866.10", "0"], ["84866.40", "0"], ["84867.80", "0"], ["84868.42", "0"], ["84868.52", "0"], ["84868.65", "0"], ["84869.57", "0"], ["84871.66", "0"], ["84871.79", "0"], ["84873.84", "0"], ["84874.79", "0"], ["84875.00", "0"], ["84875.78", "0"], ["84876.03", "0"], ["84879.10", "0"], ["84879.37", "0"], ["84879.59", "0"], ["84880.00", "0"], ["84880.89", "0"], ["84882.35", "0"], ["84883.65", "0"], ["84883.72", "0"], ["84883.84", "0"], ["84885.24", "0"], ["84885.53", "0"], ["84886.01", "0"], ["84886.02", "0"], ["84886.96", "0"], ["84887.65", "0"], ["84888.00", "0"], ["84888.68", "0"], ["84888.89", "0"], ["84889.87", "0"], ["84890.00", "0"]], "bids": [["84293.14", "0"], ["84293.13", "0"], ["84293.12", "0"], ["84293.11", "0"], ["84289.35", "0"], ["84279.70", "0"], ["84277.70", "0"], ["84275.70", "0"], ["84273.70", "0"], ["84271.70", "0"], ["84269.70", "0"], ["84267.70", "0"], ["84265.70", "0"], ["84264.52", "0.047500"], ["84263.70", "0"], ["84263.21", "0.140038"], ["84262.77", "0.012680"], ["84261.70", "0"], ["84260.60", "0.001044"], ["84259.70", "0"], ["84259.40", "0"], ["84259.33", "0"], ["84259.30", "0"], ["84259.20", "0"], ["84259.00", "0"], ["84258.60", "0.001049"], ["84256.60", "0.001034"], ["84254.80", "0"], ["84254.60", "0.001035"], ["84254.50", "0"], ["84254.47", "0"], ["84254.40", "0"], ["84254.10", "0"], ["84253.70", "0"], ["84253.60", "0"], ["84253.36", "0.000213"], ["84253.31", "0.008535"], ["84253.27", "0.007641"], ["84253.26", "0.006487"], ["84252.90", "0"], ["84252.60", "0.001027"], ["84252.30", "0"], ["84251.82", "0.008555"], ["84251.78", "0.008986"], ["84251.74", "0.006213"], ["84251.51", "0.001199"], ["84251.20", "0.017833"], ["84251.08", "0.005937"], ["84250.88", "0.209200"], ["84250.77", "0.018258"], ["84250.75", "0.016458"], ["84250.60", "0.002704"], ["84250.50", "0"], ["84250.17", "0.007513"], ["84250.10", "0"], ["84249.80", "0"], ["84249.78", "0.007118"], ["84249.73", "0.017076"], ["84249.66", "0.015769"], ["84249.60", "0"], ["84249.56", "0.006564"], ["84249.40", "0"], ["84249.06", "0.007474"], ["84249.00", "0"], ["84248.90", "0"], ["84248.60", "0.007116"], ["84248.57", "0.007437"], ["84248.07", "0.036119"], ["84247.90", "0.017059"], ["84247.68", "0.025081"], ["84247.60", "0.007932"], ["84247.49", "0.017330"], ["84247.48", "0.002062"], ["84247.47", "0.008987"], ["84247.45", "0.008142"], ["84247.33", "0"], ["84247.30", "0"], ["84247.13", "0.227645"], ["84246.60", "0.018725"], ["84246.40", "0.052102"], ["84246.26", "0.253523"], ["84246.24", "0.018517"], ["84246.11", "0.005088"], ["84245.95", "0.008282"], ["84245.00", "0.012647"], ["84244.90", "0.084428"], ["84244.60", "0.049277"], ["84244.51", "0.008672"], ["84244.10", "0.271868"], ["84244.06", "0"], ["84242.97", "0.222705"], ["84242.96", "0.008149"], ["84242.86", "0.009630"], ["84242.82", "0.056347"], ["84242.60", "0.129677"], ["84242.51", "0.021106"], ["84242.31", "0.263297"], ["84242.23", "0.076004"], ["84241.43", "0.008164"], ["84241.28", "0.010234"], ["84240.60", "0.341254"], ["84240.10", "0.009420"], ["84239.90", "0.030840"], ["84239.30", "0.197876"], ["84238.80", "0.001012"], ["84238.75", "0.056632"], ["84238.60", "0.265770"], ["84238.00", "0"], ["84237.80", "0.019680"], ["84237.70", "0.562080"], ["84236.39", "0"], ["84235.95", "0.073497"], ["84235.32", "0.012438"], ["84232.80", "0.274590"], ["84232.50", "0.512700"], ["84232.26", "0.023737"], ["84232.20", "0.142500"], ["84231.80", "0.915360"], ["84230.40", "0.012540"], ["84229.40", "0.462600"], ["84229.30", "2.658510"], ["84229.00", "0.023936"], ["84228.70", "1.061130"], ["84226.70", "2.669430"], ["84225.80", "0.142500"], ["84225.70", "2.349810"], ["84225.00", "3.010260"], ["84223.05", "0.007181"], ["84223.01", "0"], ["84222.70", "0.090000"], ["84220.90", "0.090000"], ["84220.70", "2.669430"], ["84217.69", "0.001189"], ["84217.50", "0"], ["84213.95", "0.001180"], ["84211.16", "0.017801"], ["84209.80", "0.207047"], ["84209.00", "0"], ["84200.50", "0"], ["84198.50", "5.423917"], ["84192.00", "0"], ["84190.00", "3.887140"], ["84183.50", "0"], ["84181.50", "4.700728"], ["84175.00", "0"], ["84173.00", "5.243119"], ["84166.50", "0"], ["84164.50", "5.333518"], ["84158.00", "0"], ["84156.00", "5.604714"], ["84153.35", "0.072042"], ["84149.50", "0"], ["84147.50", "4.519931"], ["84141.00", "0"], ["84139.00", "4.791126"], ["84132.50", "0"], ["84130.50", "5.152721"], ["84124.00", "0"], ["84122.00", "4.067938"], ["84115.50", "0"], ["84113.50", "4.248735"], ["84107.00", "0"], ["84105.00", "4.971924"], ["84098.50", "0"], ["84096.50", "4.339133"], ["84090.00", "0"], ["84088.00", "4.610329"], ["84081.50", "0"], ["84079.50", "3.977539"], ["84073.00", "0"], ["84071.00", "4.158336"], ["84064.50", "0"], ["84062.50", "4.429532"], ["84056.00", "0"], ["84054.00", "4.881525"], ["84045.50", "5.514315"], ["84037.00", "5.062322"], ["83972.36", "0"], ["83945.67", "1.731142"], ["83874.55", "0"], ["83874.15", "0"], ["83873.87", "0"], ["83873.52", "0"], ["83870.97", "0"], ["83870.95", "0"], ["83870.78", "0"], ["83870.00", "0"], ["83869.57", "0"], ["83868.82", "0"], ["83866.67", "0"], ["83865.80", "0"], ["83865.10", "0"], ["83864.54", "0"], ["83863.64", "0"], ["83863.52", "0"], ["83860.29", "0"], ["83860.10", "0"], ["83860.00", "0"], ["83859.94", "0"], ["83859.35", "0"], ["83859.25", "0"], ["83858.82", "0"], ["83857.50", "0"], ["83857.14", "0"], ["83857.13", "0"], ["83856.00", "0"], ["83855.78", "0"], ["83855.44", "0"], ["83855.42", "0"], ["83854.95", "0"], ["83854.17", "0"], ["83854.00", "0"], ["83853.33", "0"], ["83852.50", "0"], ["83852.40", "0"], ["83852.30", "0"], ["83852.19", "0"], ["83851.85", "0"], ["83851.84", "0"], ["83850.00", "0"], ["83848.94", "0"], ["83848.38", "0"], ["83848.17", "0"], ["83846.22", "0"], ["83846.15", "0"], ["83845.92", "0"], ["83845.30", "0"], ["83844.83", "0"]], "checksum": 63374732, "ts": "1742142216929"}], "ts": 1742142216933, "record_time": 1742142216.042253}
{"action": "update", "arg": {"instType": "SPOT", "channel": "books", "instId": "BTCUSDT"}, "data": [{"asks": [["84264.52", "0.805360"], ["84264.53", "0.203170"], ["84267.05", "0.147001"], ["84267.06", "0.000479"], ["84272.02", "0.010000"], ["84272.29", "0.420240"], ["84272.30", "0"], ["84272.31", "0"], ["84272.94", "0.140037"], ["84273.27", "0.030015"], ["84273.30", "0.010074"], ["84273.32", "0.001230"], ["84273.33", "0.004974"], ["84273.34", "0.000245"], ["84273.36", "0.008962"], ["84273.38", "0.006307"], ["84274.21", "0.000443"], ["84274.22", "0.001923"], ["84274.23", "0.009191"], ["84274.24", "0.005183"], ["84274.29", "0.007359"], ["84275.15", "0.005678"], ["84275.31", "0.001066"], ["84276.17", "0.007955"], ["84276.19", "0.008506"], ["84276.21", "0.007385"], ["84276.22", "0.008272"], ["84276.24", "0.004739"], ["84278.48", "0"], ["84278.50", "0"], ["84278.51", "0"], ["84278.53", "0"], ["84278.56", "0"], ["84279.38", "0"], ["84279.39", "0"], ["84279.40", "0"], ["84279.44", "0"], ["84279.45", "0"], ["84279.81", "0.149635"], ["84280.32", "0.002907"], ["84281.36", "0.003017"], ["84282.28", "0.001827"], ["84282.93", "0.014357"], ["84284.90", "1.895031"], ["84287.40", "0.119869"], ["84288.66", "0.035952"], ["84288.93", "0"], ["84289.29", "0.209200"], ["84289.59", "0.006356"], ["84289.69", "0.006356"], ["84290.58", "0.006356"], ["84291.02", "0.006356"], ["84291.27", "0.006356"], ["84291.60", "0.006356"], ["84291.66", "0.006356"], ["84291.78", "0.006356"], ["84291.86", "0.010985"], ["84291.93", "0.006356"], ["84292.24", "0.006356"], ["84292.32", "0.006356"], ["84292.34", "0.006356"], ["84293.13", "0.312209"], ["84293.14", "0"], ["84293.15", "0.402402"], ["84293.58", "0"], ["84293.63", "0.006356"], ["84293.85", "0.006357"], ["84294.02", "0.010984"], ["84294.97", "0"], ["84295.77", "0"], ["84295.86", "0"], ["84296.10", "0"], ["84296.20", "0.009989"], ["84296.74", "0"], ["84296.76", "0"], ["84296.82", "0.119895"], ["84296.90", "0.009989"], ["84297.26", "0"], ["84297.27", "0"], ["84297.44", "0"], ["84297.79", "0.016428"], ["84297.95", "0"], ["84298.10", "0"], ["84298.20", "0"], ["84298.33", "0"], ["84298.49", "0"], ["84299.23", "0"], ["84299.28", "0"], ["84299.55", "0"], ["84299.71", "0"], ["84300.47", "0"], ["84300.88", "0.006356"], ["84301.18", "0"], ["84301.76", "2.229059"], ["84302.70", "0"], ["84302.99", "0"], ["84303.00", "0.001005"], ["84303.10", "0"], ["84304.02", "0"], ["84307.00", "0.002042"], ["84309.00", "0.005374"], ["84309.15", "0"], ["84311.00", "0.014143"], ["84312.31", "0.026414"], ["84313.00", "0.037219"], ["84315.00", "0.097945"], ["84317.00", "0.257750"], ["84319.00", "0.678287"], ["84321.00", "1.784967"], ["84323.00", "4.697281"], ["84323.10", "0.001041"], ["84323.20", "0.001007"], ["84324.30", "0.001021"], ["84324.50", "4.905960"], ["84324.70", "0.035580"], ["84325.00", "5.241030"], ["84325.57", "0"], ["84327.10", "0"], ["84327.30", "0"], ["84328.20", "0.069600"], ["84328.30", "0"], ["84329.40", "0.230370"], ["84329.80", "0.015120"], ["84331.70", "3.167880"], ["84332.90", "0.248880"], ["84333.30", "0"], ["84333.60", "1.350000"], ["84334.50", "0"], ["84335.10", "0"], ["84335.50", "7.491390"], ["84338.90", "0.009000"], ["84339.10", "1.793880"], ["84339.20", "0"], ["84340.00", "0.117000"], ["84340.10", "0.009000"], ["84340.80", "0.180000"], ["84341.30", "2.562480"], ["84342.20", "0"], ["84343.30", "0"], ["84343.60", "0"], ["84351.79", "0"], ["84365.10", "5.333642"], ["84367.10", "0"], ["84373.60", "4.429635"], ["84375.26", "0.209200"], ["84375.60", "0"], ["84382.10", "4.158433"], ["84384.10", "0"], ["84390.60", "5.152841"], ["84392.60", "0"], ["84393.34", "0.002935"], ["84399.10", "5.243241"], ["84401.10", "0"], ["84407.60", "4.248834"], ["84409.60", "0"], ["84416.10", "5.514443"], ["84418.10", "0"], ["84424.60", "3.977631"], ["84426.60", "0"], ["84433.10", "4.972039"], ["84434.27", "0"], ["84435.10", "0"], ["84441.60", "4.881638"], ["84442.70", "0"], ["84443.60", "0"], ["84450.10", "5.062440"], ["84452.10", "0"], ["84458.60", "4.610436"], ["84460.60", "0"], ["84467.10", "4.339234"], ["84469.10", "0"], ["84475.60", "4.700837"], ["84477.60", "0"], ["84484.10", "4.520036"], ["84486.10", "0"], ["84492.60", "5.424043"], ["84494.60", "0"], ["84501.10", "4.068032"], ["84503.10", "0"], ["84509.60", "5.604844"], ["84511.60", "0"], ["84518.10", "4.791238"], ["84520.10", "0"], ["84526.60", "3.887231"], ["84528.60", "0"], ["84835.53", "0"], ["84835.91", "0"], ["84837.38", "0"], ["84838.70", "0"], ["84838.71", "0"], ["84839.83", "0"], ["84840.00", "0"], ["84841.58", "0"], ["84842.11", "0"], ["84844.53", "0"], ["84845.00", "0"], ["84845.94", "0"], ["84846.15", "0"], ["84846.55", "0"], ["84846.85", "0"], ["84847.58", "0"]], "bids": [["84264.52", "0"], ["84264.51", "1.895031"], ["84263.24", "0.139810"], ["84263.23", "0"], ["84263.21", "0"], ["84262.77", "0"], ["84262.01", "0.031443"], ["84260.60", "0"], ["84259.32", "0.063385"], ["84259.31", "0"], ["84259.30", "2.550107"], ["84258.18", "0.000070"], ["84253.36", "0"], ["84253.32", "0.007107"], ["84253.31", "0"], ["84253.27", "0"], ["84253.26", "0"], ["84251.82", "0"], ["84251.78", "0"], ["84251.74", "0"], ["84251.51", "0"], ["84251.20", "0"], ["84251.08", "0"], ["84250.95", "0.096366"], ["84250.77", "0"], ["84250.75", "0"], ["84250.60", "0.001037"], ["84250.11", "0.001228"], ["84249.78", "0"], ["84249.73", "0"], ["84249.56", "0"], ["84249.06", "0"], ["84248.60", "0.002947"], ["84248.56", "0.007344"], ["84248.53", "0.003070"], ["84248.18", "0.000213"], ["84248.13", "0.008535"], ["84248.07", "0.028804"], ["84247.99", "0.006535"], ["84247.90", "0"], ["84247.60", "0"], ["84247.49", "0"], ["84247.47", "0"], ["84247.14", "0.303232"], ["84246.63", "0.008555"], ["84246.62", "0.313205"], ["84246.60", "0.007754"], ["84246.59", "0.008986"], ["84246.55", "0.006213"], ["84246.40", "0"], ["84246.32", "0.001199"], ["84246.26", "0.247971"], ["84246.24", "0"], ["84246.11", "0"], ["84245.95", "0"], ["84245.85", "0.007950"], ["84245.18", "0.007870"], ["84245.03", "0.017839"], ["84244.91", "0.005939"], ["84244.60", "0.020406"], ["84244.59", "0.018264"], ["84244.58", "0.016464"], ["84244.51", "0"], ["84244.10", "0"], ["84243.96", "0.006566"], ["84243.89", "0.007474"], ["84243.56", "0.017082"], ["84243.53", "0.007121"], ["84242.93", "0.000875"], ["84242.61", "0.014295"], ["84242.60", "0.053701"], ["84242.51", "0"], ["84241.89", "0.017335"], ["84241.88", "0.007318"], ["84241.72", "0.017065"], ["84241.61", "0.008990"], ["84241.60", "0.007935"], ["84241.08", "0.005552"], ["84241.02", "0.004935"], ["84240.95", "0.186831"], ["84240.93", "0.005088"], ["84240.60", "0.141318"], ["84240.10", "0"], ["84240.09", "0.008285"], ["84239.90", "0"], ["84239.74", "0.018523"], ["84239.36", "0.008672"], ["84239.25", "0.052118"], ["84238.80", "0"], ["84238.60", "0.371888"], ["84238.40", "0.002950"], ["84238.00", "0.001590"], ["84237.90", "0.001037"], ["84237.70", "0"], ["84237.52", "0.271956"], ["84235.38", "0.021113"], ["84233.70", "0.081150"], ["84232.80", "0"], ["84231.90", "0.035580"], ["84230.82", "0.010000"], ["84230.40", "0"], ["84230.10", "0.177960"], ["84229.30", "0.525120"], ["84228.80", "0.274590"], ["84226.70", "0.090000"], ["84226.00", "0.013140"], ["84225.80", "0.232500"], ["84225.70", "0"], ["84225.20", "0.090000"], ["84225.00", "0.663780"], ["84224.80", "0.090000"], ["84224.40", "0.043860"], ["84224.30", "0.008206"], ["84223.05", "0"], ["84222.70", "0"], ["84220.90", "0"], ["84220.70", "0"], ["84219.79", "0.007582"], ["84217.86", "0.007181"], ["84213.99", "0"], ["84205.25", "0.002935"], ["84198.50", "0"], ["84196.50", "5.333642"], ["84190.00", "0"], ["84188.00", "5.604844"], ["84181.50", "0"], ["84179.50", "4.972039"], ["84173.00", "0"], ["84171.00", "3.887231"], ["84164.50", "0"], ["84162.50", "4.339234"], ["84156.00", "0"], ["84154.00", "4.881638"], ["84147.50", "0"], ["84145.50", "4.610436"], ["84139.00", "0"], ["84137.00", "4.791238"], ["84130.50", "0"], ["84128.50", "4.158433"], ["84122.00", "0"], ["84120.00", "5.243241"], ["84113.50", "0"], ["84111.50", "5.514443"], ["84105.00", "0"], ["84103.00", "5.062440"], ["84096.50", "0"], ["84094.50", "4.700837"], ["84088.00", "0.000022"], ["84086.00", "5.152841"], ["84079.50", "0"], ["84077.50", "4.068032"], ["84071.00", "0"], ["84069.00", "5.424043"], ["84062.50", "0.000276"], ["84060.50", "4.248834"], ["84054.00", "0"], ["84052.00", "4.520036"], ["84045.50", "0"], ["84043.50", "3.977631"], ["84037.00", "0"], ["84035.00", "4.429635"], ["83884.30", "0"], ["83882.98", "0"], ["83882.92", "0"], ["83881.99", "0"], ["83880.00", "0"], ["83877.97", "0"], ["83877.55", "0"], ["83877.42", "0"], ["83877.29", "0"], ["83877.05", "0"], ["83876.25", "0"], ["83876.12", "0"], ["83875.99", "0"], ["83875.49", "0"], ["83875.16", "0"], ["83875.00", "0"]], "checksum": -549512565, "ts": "1742142217130"}], "ts": 1742142217133, "record_time": 1742142216.24249}
{"action": "update", "arg": {"instType": "SPOT", "channel": "books", "instId": "BTCUSDT"}, "data": [{"asks": [["84264.52", "1.102332"], ["84264.53", "0"], ["84264.83", "0.007955"], ["84264.84", "0.001923"], ["84264.85", "0.008506"], ["84264.87", "0.017738"], ["84264.89", "0.007110"], ["84264.90", "0.000078"], ["84264.91", "0.007359"], ["84267.04", "0.044244"], ["84267.05", "0"], ["84267.06", "0"], ["84268.14", "0.080382"], ["84269.40", "0.140036"], ["84272.02", "0"], ["84272.29", "0"], ["84272.93", "0.060553"], ["84272.94", "0"], ["84273.27", "0"], ["84273.30", "0"], ["84273.32", "0"], ["84273.33", "0"], ["84273.34", "0"], ["84273.36", "0"], ["84273.38", "0"], ["84274.21", "0"], ["84274.22", "0"], ["84274.23", "0"], ["84274.24", "0"], ["84274.29", "0"], ["84275.16", "0"], ["84275.27", "0"], ["84275.31", "0.001205"], ["84275.54", "1.895337"], ["84275.92", "0.119869"], ["84276.17", "0"], ["84276.19", "0"], ["84276.21", "0"], ["84276.22", "0"], ["84276.24", "0"], ["84276.25", "0"], ["84277.18", "0.035952"], ["84278.25", "0.006356"], ["84279.12", "0.006356"], ["84279.28", "0.031812"], ["84279.56", "0.006356"], ["84279.82", "0"], ["84280.14", "0.006356"], ["84280.20", "0.006356"], ["84280.23", "0"], ["84280.30", "0.006356"], ["84280.78", "0.006356"], ["84281.09", "0.017803"], ["84281.47", "0.016427"], ["84281.54", "0.006356"], ["84281.84", "0.006356"], ["84281.86", "0.006356"], ["84283.37", "0.006357"], ["84283.85", "0.010984"], ["84284.74", "0.009989"], ["84284.90", "0"], ["84285.20", "0.016428"], ["84285.66", "0.119895"], ["84285.94", "0.119843"], ["84285.95", "0.119881"], ["84286.29", "0.119879"], ["84286.41", "0.009989"], ["84287.03", "0.015892"], ["84287.40", "0"], ["84287.61", "0.006356"], ["84288.66", "0"], ["84289.21", "0.006356"], ["84289.59", "0"], ["84289.69", "0"], ["84289.94", "0"], ["84290.58", "0"], ["84291.02", "0"], ["84291.04", "0.015891"], ["84291.27", "0"], ["84291.60", "0"], ["84291.66", "0"], ["84291.78", "0"], ["84291.86", "0"], ["84291.89", "0.010986"], ["84291.93", "0"], ["84292.19", "0.001807"], ["84292.24", "0"], ["84292.32", "0"], ["84292.34", "0"], ["84292.39", "2.228753"], ["84293.13", "0"], ["84293.15", "0.077401"], ["84293.63", "0"], ["84293.70", "0.001035"], ["84293.85", "0"], ["84293.91", "0"], ["84294.02", "0"], ["84294.69", "0.171806"], ["84295.70", "0.001042"], ["84296.20", "0"], ["84296.82", "0"], ["84296.90", "0"], ["84297.03", "0.075000"], ["84297.70", "0.002887"], ["84297.79", "0"], ["84298.54", "0"], ["84299.09", "0"], ["84299.70", "0.007598"], ["84299.78", "0"], ["84300.88", "0"], ["84301.70", "0.019995"], ["84301.76", "0"], ["84302.50", "0"], ["84302.87", "0"], ["84302.98", "0"], ["84303.00", "0"], ["84303.31", "0"], ["84303.41", "0"], ["84303.70", "0.052619"], ["84305.00", "0"], ["84305.70", "0.138471"], ["84307.00", "0"], ["84307.38", "0"], ["84307.70", "0.364397"], ["84309.00", "0"], ["84309.54", "0"], ["84309.70", "0.958939"], ["84310.59", "0.001597"], ["84311.00", "0"], ["84311.70", "2.523523"], ["84313.00", "0"], ["84313.70", "6.640851"], ["84313.80", "0.001025"], ["84314.10", "0.001047"], ["84314.50", "0.001017"], ["84315.00", "0"], ["84315.20", "0.521700"], ["84316.20", "0.069810"], ["84316.60", "0.142710"], ["84316.90", "0.405570"], ["84317.00", "0"], ["84318.10", "1.080930"], ["84318.20", "0.069600"], ["84319.00", "0"], ["84320.20", "0.069600"], ["84321.00", "0"], ["84322.20", "0.241350"], ["84322.40", "6.909900"], ["84323.00", "4.568040"], ["84323.10", "0"], ["84323.20", "0"], ["84324.20", "0.069600"], ["84324.30", "0"], ["84324.50", "0"], ["84325.00", "1.393770"], ["84325.80", "0.985470"], ["84326.50", "0.197885"], ["84328.20", "0.230490"], ["84328.26", "0"], ["84328.60", "0.410370"], ["84329.40", "0.837600"], ["84329.80", "0"], ["84329.90", "1.779300"], ["84330.50", "0.355920"], ["84331.70", "3.746250"], ["84331.90", "1.079040"], ["84332.00", "0"], ["84332.70", "2.669430"], ["84332.80", "0.248880"], ["84332.90", "0"], ["84333.60", "0"], ["84334.20", "0"], ["84335.50", "0"], ["84335.80", "0"], ["84336.20", "0"], ["84336.40", "0"], ["84336.70", "0"], ["84336.90", "0"], ["84337.10", "0"], ["84338.20", "0"], ["84338.90", "0"], ["84339.10", "0"], ["84340.00", "0"], ["84340.10", "0"], ["84340.20", "0"], ["84340.80", "0"], ["84341.30", "0"], ["84341.60", "0"], ["84355.80", "4.791770"], ["84356.00", "0"], ["84364.30", "5.605467"], ["84365.10", "0"], ["84372.80", "4.430127"], ["84373.60", "0"], ["84381.30", "4.520538"], ["84382.10", "0"], ["84389.80", "5.063002"], ["84390.60", "0"], ["84398.30", "4.339716"], ["84399.10", "0"], ["84406.80", "5.424645"], ["84407.60", "0"], ["84415.30", "5.334234"], ["84416.10", "0"], ["84423.80", "3.887662"], ["84424.60", "0"], ["84425.84", "0"], ["84432.30", "3.978073"], ["84433.10", "0"], ["84440.80", "4.972591"], ["84441.60", "0"], ["84449.30", "5.515056"], ["84450.10", "0"], ["84457.80", "4.882181"], ["84458.60", "0"], ["84466.30", "4.249305"], ["84467.10", "0"], ["84474.80", "4.158895"], ["84475.60", "0"], ["84483.30", "4.610948"], ["84484.10", "0"], ["84491.80", "5.153413"], ["84492.60", "0"], ["84500.30", "4.701359"], ["84501.10", "0"], ["84508.80", "5.243824"], ["84509.60", "0"], ["84517.30", "4.068484"], ["84518.10", "0"], ["84526.60", "0"], ["84835.53", "0.000093"], ["84835.91", "0.000024"], ["84837.38", "0.000008"], ["84838.70", "0.000078"], ["84838.71", "0.000214"], ["84839.83", "0.000098"], ["84840.00", "0.000436"], ["84841.58", "0.000008"], ["84842.11", "0.000068"], ["84844.53", "0.000423"], ["84845.00", "0.000025"], ["84845.94", "0.000008"], ["84846.15", "0.004277"], ["84846.55", "0.000019"], ["84846.85", "0.000176"], ["84847.58", "0.000039"], ["84847.82", "0.000671"], ["84849.88", "0.000030"], ["84850.00", "0.000031"], ["84851.66", "0.000029"], ["84852.81", "0.000115"], ["84852.94", "0.000065"], ["84853.56", "0.000050"], ["84857.14", "0.000347"], ["84858.75", "0.000285"], ["84859.29", "0.000036"]], "bids": [["84264.51", "0.203170"], ["84263.24", "0"], ["84259.32", "0"], ["84259.30", "0"], ["84258.60", "0"], ["84258.18", "0"], ["84257.15", "1.895337"], ["84256.60", "0"], ["84254.60", "0"], ["84253.32", "0"], ["84252.60", "0"], ["84252.21", "0.000070"], ["84250.60", "0"], ["84250.17", "0"], ["84250.11", "0"], ["84249.66", "0"], ["84249.30", "0.001007"], ["84248.60", "0"], ["84248.57", "0"], ["84248.56", "0"], ["84248.53", "0"], ["84248.18", "0"], ["84248.13", "0"], ["84248.07", "0"], ["84247.99", "0"], ["84247.68", "0"], ["84247.48", "0"], ["84247.45", "0"], ["84247.30", "0.001032"], ["84247.13", "0"], ["84246.63", "0"], ["84246.60", "0"], ["84246.59", "0"], ["84246.55", "0.012680"], ["84246.32", "0"], ["84246.26", "0"], ["84245.85", "0"], ["84245.30", "0.001035"], ["84245.18", "0"], ["84245.03", "0"], ["84245.00", "0"], ["84244.91", "0"], ["84244.90", "0"], ["84244.60", "0"], ["84244.59", "0"], ["84244.58", "0"], ["84243.96", "0"], ["84243.89", "0"], ["84243.56", "0"], ["84243.53", "0"], ["84243.30", "0.001039"], ["84242.97", "0"], ["84242.96", "0"], ["84242.93", "0"], ["84242.86", "0"], ["84242.83", "0.336125"], ["84242.82", "0"], ["84242.60", "0"], ["84242.31", "0"], ["84242.23", "0"], ["84241.89", "0"], ["84241.88", "0"], ["84241.72", "0"], ["84241.61", "0"], ["84241.60", "0"], ["84241.43", "0"], ["84241.30", "0.001822"], ["84241.28", "0"], ["84241.08", "0"], ["84241.02", "0"], ["84240.95", "0"], ["84240.93", "0"], ["84240.60", "0"], ["84240.30", "2.550508"], ["84240.09", "0"], ["84239.74", "0"], ["84239.36", "0"], ["84239.30", "0.004793"], ["84239.25", "0"], ["84238.80", "0.007513"], ["84238.78", "0.001228"], ["84238.75", "0"], ["84238.74", "0.008535"], ["84238.70", "0.006487"], ["84238.60", "0"], ["84238.40", "0"], ["84238.00", "0"], ["84237.90", "0"], ["84237.80", "0"], ["84237.52", "0"], ["84237.30", "0.012614"], ["84237.22", "0.006213"], ["84237.20", "0.007344"], ["84237.17", "0.007437"], ["84237.14", "0.006535"], ["84236.92", "0.001199"], ["84236.09", "0.008142"], ["84236.01", "0.002062"], ["84235.95", "0"], ["84235.84", "0.017082"], ["84235.48", "0.028814"], ["84235.38", "0"], ["84235.32", "0"], ["84235.30", "0.033195"], ["84234.64", "0.248055"], ["84234.54", "0.227723"], ["84234.51", "0.015424"], ["84233.70", "0"], ["84233.45", "0.005939"], ["84233.37", "0.084457"], ["84233.30", "0.087354"], ["84233.22", "0.015774"], ["84233.17", "0.018265"], ["84233.12", "0.016464"], ["84232.84", "0.012652"], ["84232.54", "0.056367"], ["84232.51", "0.006566"], ["84232.50", "0"], ["84232.26", "0"], ["84232.20", "0"], ["84232.08", "0.007121"], ["84231.90", "0"], ["84231.80", "0"], ["84231.72", "0.005552"], ["84231.59", "0.000875"], ["84231.58", "0.008149"], ["84231.55", "0.005088"], ["84231.48", "0.009630"], ["84231.30", "0.229880"], ["84231.14", "0.008990"], ["84231.12", "0.007935"], ["84230.92", "0.017336"], ["84230.82", "0"], ["84230.42", "0.007318"], ["84230.25", "0.017065"], ["84230.10", "0"], ["84230.08", "0.025089"], ["84230.00", "0.008672"], ["84229.89", "0.010234"], ["84229.81", "0.008166"], ["84229.62", "0.008285"], ["84229.40", "0"], ["84229.31", "0.126798"], ["84229.30", "0.604946"], ["84229.00", "0"], ["84228.80", "0.378990"], ["84228.70", "0.002700"], ["84228.40", "0.001025"], ["84228.30", "0.653190"], ["84228.28", "0.018524"], ["84227.36", "0.271960"], ["84226.89", "0.002951"], ["84226.70", "0"], ["84226.00", "0"], ["84225.97", "0.222780"], ["84225.86", "0.076030"], ["84225.80", "0.142680"], ["84225.28", "0.263387"], ["84225.20", "0"], ["84225.00", "0.379410"], ["84224.80", "0"], ["84224.40", "0.013860"], ["84224.30", "0"], ["84223.66", "0.012442"], ["84223.40", "0.915360"], ["84223.10", "0.047430"], ["84222.00", "0.009000"], ["84221.95", "0.073522"], ["84221.50", "0.274590"], ["84221.12", "0.056651"], ["84220.70", "0.509340"], ["84219.79", "0"], ["84219.40", "0.142500"], ["84219.00", "0.383490"], ["84218.80", "0.030000"], ["84218.20", "1.061130"], ["84218.18", "0.023745"], ["84217.86", "0"], ["84217.69", "0"], ["84217.50", "0.462600"], ["84216.40", "0.090000"], ["84215.80", "0.012330"], ["84215.10", "0.090000"], ["84214.84", "0.023944"], ["84214.80", "4.163040"], ["84214.70", "0.177960"], ["84213.00", "1.350000"], ["84212.30", "5.077170"], ["84209.80", "0"], ["84208.53", "0.007181"], ["84200.04", "0.001190"], ["84196.50", "0"], ["84188.00", "0"], ["84187.20", "5.515056"], ["84179.50", "0"], ["84178.70", "4.158895"], ["84171.00", "0"], ["84170.20", "4.972591"], ["84162.50", "0.000031"], ["84161.70", "5.243824"], ["84154.00", "0"], ["84153.20", "3.978073"], ["84145.50", "0"], ["84144.70", "4.701359"], ["84137.00", "0"], ["84136.20", "4.520538"], ["84128.50", "0"], ["84127.70", "4.610948"], ["84120.00", "0.000302"], ["84119.20", "4.249305"], ["84111.50", "0"], ["84110.70", "4.068484"], ["84103.00", "0"], ["84102.20", "4.339716"], ["84094.50", "0"], ["84093.70", "5.334234"], ["84086.00", "0"], ["84085.20", "5.605467"], ["84077.50", "0"], ["84076.70", "5.063002"], ["84069.00", "0"], ["84068.20", "4.430127"], ["84060.50", "0"], ["84059.70", "4.791770"], ["84052.00", "0"], ["84051.20", "4.882181"], ["84043.50", "0"], ["84042.70", "3.887662"], ["84035.00", "0"], ["84034.20", "5.424645"], ["84025.70", "5.153413"], ["83992.38", "0.209200"], ["83884.30", "0.000161"], ["83882.98", "0.000188"], ["83882.92", "0.002384"], ["83881.99", "0.000038"], ["83880.00", "0.020454"], ["83877.97", "0.000023"], ["83877.55", "0.000010"], ["83877.42", "0.000054"]], "checksum": 1226762932, "ts": "1742142217340"}], "ts": 1742142217348, "record_time": 1742142216.458083}
{"action": "update", "arg": {"instType": "SPOT", "channel": "books", "instId": "BTCUSDT"}, "data": [{"asks": [["84255.26", "0.004595"], ["84255.31", "1.086300"], ["84255.32", "0.005541"], ["84255.34", "0.010074"], ["84255.36", "0.004974"], ["84255.41", "0.001475"], ["84255.42", "0.006307"], ["84255.44", "0.008962"], ["84255.45", "0.001066"], ["84256.24", "0.007955"], ["84256.26", "0.000443"], ["84256.28", "0.001162"], ["84256.29", "0.011114"], ["84256.31", "0.007110"], ["84256.32", "0.014986"], ["84256.33", "0.009922"], ["84256.34", "0.000078"], ["84259.80", "0.080382"], ["84262.02", "0.418400"], ["84264.51", "0.598789"], ["84264.52", "0.729104"], ["84264.83", "0"], ["84264.84", "0"], ["84264.85", "0"], ["84264.87", "0"], ["84264.89", "0"], ["84264.90", "0"], ["84264.91", "0"], ["84265.51", "0.001205"], ["84266.13", "0.119869"], ["84267.04", "0.024115"], ["84268.14", "0"], ["84268.36", "0.006356"], ["84268.84", "0.035952"], ["84269.39", "0.042011"], ["84269.40", "0"], ["84269.91", "0.006356"], ["84270.50", "0.006356"], ["84271.15", "0.006356"], ["84271.27", "0.006356"], ["84271.71", "0.006356"], ["84271.79", "0.006356"], ["84271.95", "0.006356"], ["84272.34", "0.006356"], ["84272.43", "0.148098"], ["84272.83", "0.010985"], ["84272.86", "0.006356"], ["84272.93", "0.006356"], ["84273.13", "0.016427"], ["84273.20", "0.006356"], ["84273.52", "0.006356"], ["84273.99", "0.006356"], ["84274.56", "0.006356"], ["84275.03", "0.006357"], ["84275.15", "0.613709"], ["84275.31", "0"], ["84275.50", "0.010984"], ["84275.54", "0"], ["84275.92", "0"], ["84276.15", "0.119881"], ["84276.88", "0.009989"], ["84277.18", "0"], ["84277.32", "0.119895"], ["84277.35", "0.016428"], ["84277.80", "0.313205"], ["84277.92", "0.029802"], ["84277.95", "0.119879"], ["84278.07", "0.009989"], ["84278.09", "0.119843"], ["84278.25", "0"], ["84278.54", "0.001807"], ["84279.12", "0"], ["84279.19", "0.015892"], ["84279.28", "0"], ["84279.56", "0"], ["84279.81", "0"], ["84280.14", "0"], ["84280.20", "0"], ["84280.30", "0"], ["84280.78", "0"], ["84281.09", "0"], ["84281.36", "0"], ["84281.47", "0"], ["84281.54", "0"], ["84281.56", "0.006356"], ["84281.84", "0"], ["84281.86", "0"], ["84282.21", "0.015891"], ["84282.28", "0"], ["84282.58", "0.010986"], ["84282.94", "0"], ["84282.95", "0"], ["84283.37", "0"], ["84283.85", "0"], ["84284.74", "0"], ["84285.10", "0.001006"], ["84285.20", "0"], ["84285.66", "0"], ["84285.94", "0"], ["84285.95", "0"], ["84286.29", "0"], ["84286.41", "0"], ["84287.03", "0"], ["84287.10", "0.001033"], ["84287.61", "0"], ["84287.69", "0.010000"], ["84287.82", "0.075000"], ["84289.10", "0.002923"], ["84289.21", "0"], ["84291.04", "0"], ["84291.10", "0.007690"], ["84291.89", "0"], ["84292.19", "0"], ["84292.39", "0"], ["84293.10", "0.020237"], ["84293.15", "0"], ["84293.70", "0"], ["84294.69", "0"], ["84294.70", "0"], ["84295.10", "0.053256"], ["84295.70", "0"], ["84297.10", "0.140148"], ["84297.70", "0"], ["84299.10", "0.368810"], ["84299.42", "0.026414"], ["84299.57", "0"], ["84299.70", "0"], ["84301.10", "0.970552"], ["84301.70", "0"], ["84303.10", "2.554086"], ["84303.70", "0"], ["84305.10", "6.721277"], ["84305.70", "0"], ["84306.20", "0.070020"], ["84307.50", "0.405990"], ["84307.70", "0"], ["84307.90", "1.350630"], ["84308.20", "1.849530"], ["84308.30", "0.578640"], ["84308.80", "1.753950"], ["84308.90", "0.064110"], ["84309.32", "0.001597"], ["84309.40", "1.995000"], ["84309.70", "0"], ["84310.20", "0.212100"], ["84310.30", "0.160890"], ["84311.60", "0.410370"], ["84311.70", "0"], ["84312.20", "0.069600"], ["84312.31", "0"], ["84313.70", "7.099770"], ["84313.80", "0"], ["84314.10", "0"], ["84314.20", "0.070770"], ["84314.50", "0.015090"], ["84315.20", "0"], ["84315.23", "0"], ["84316.20", "0.069600"], ["84316.60", "0.562500"], ["84316.90", "0"], ["84317.10", "0.015150"], ["84318.10", "0.503970"], ["84320.30", "0.985470"], ["84321.50", "0.693300"], ["84322.20", "0.069600"], ["84322.40", "5.844930"], ["84323.00", "4.323270"], ["84323.20", "0.480000"], ["84323.60", "0.177960"], ["84324.70", "0"], ["84325.00", "1.329060"], ["84325.80", "0"], ["84328.20", "0"], ["84328.39", "0"], ["84328.60", "0"], ["84329.40", "0"], ["84329.90", "0"], ["84330.20", "0"], ["84330.50", "0"], ["84331.70", "0"], ["84331.90", "0"], ["84332.20", "0"], ["84332.70", "0"], ["84332.80", "0"], ["84347.20", "5.606037"], ["84355.70", "3.888059"], ["84355.80", "0"], ["84364.20", "4.973098"], ["84364.30", "0"], ["84370.12", "0.057629"], ["84372.70", "5.425198"], ["84372.80", "0"], ["84381.20", "5.153938"], ["84381.30", "0"], ["84389.70", "3.978479"], ["84389.80", "0"], ["84393.34", "0"], ["84398.20", "4.430579"], ["84398.30", "0"], ["84403.37", "0"], ["84406.70", "4.159319"], ["84406.80", "0"], ["84415.20", "4.068899"], ["84415.30", "0"], ["84417.41", "0"], ["84423.70", "5.515618"], ["84423.80", "0"], ["84432.20", "4.701838"], ["84432.30", "0"], ["84440.70", "4.611418"], ["84440.80", "0"], ["84449.20", "4.249739"], ["84449.30", "0"], ["84457.70", "4.882678"], ["84457.80", "0"], ["84466.20", "5.334778"], ["84466.30", "0"], ["84474.70", "4.792258"], ["84474.80", "0"], ["84483.20", "4.340159"], ["84483.30", "0"], ["84491.70", "4.520998"], ["84491.80", "0"], ["84500.20", "5.063518"], ["84500.30", "0"], ["84508.70", "5.244358"], ["84508.80", "0"], ["84517.30", "0"], ["84851.66", "0"], ["84852.81", "0"], ["84852.94", "0"], ["84853.56", "0"], ["84857.14", "0"], ["84858.75", "0"], ["84859.29", "0"]], "bids": [["84264.51", "0"], ["84262.01", "0"], ["84257.15", "0"], ["84252.21", "0"], ["84250.95", "0"], ["84250.88", "0"], ["84249.30", "0"], ["84247.30", "0"], ["84247.14", "0"], ["84246.62", "0"], ["84246.55", "0"], ["84245.30", "0"], ["84244.20", "0.010000"], ["84243.30", "0"], ["84242.83", "0"], ["84242.61", "0"], ["84241.30", "0"], ["84240.70", "0.001022"], ["84240.31", "0.827912"], ["84240.30", "0"], ["84239.30", "0"], ["84238.80", "0"], ["84238.78", "0"], ["84238.74", "0"], ["84238.70", "0.001047"], ["84238.01", "0"], ["84237.30", "0"], ["84237.22", "0"], ["84237.20", "0"], ["84237.17", "0"], ["84237.14", "0"], ["84236.92", "0"], ["84236.70", "0.001019"], ["84236.41", "0.003008"], ["84236.09", "0"], ["84236.01", "0"], ["84235.84", "0"], ["84235.48", "0"], ["84235.30", "0"], ["84234.70", "0.001010"], ["84234.65", "0.318401"], ["84234.64", "0"], ["84234.54", "0"], ["84234.51", "0"], ["84233.45", "0"], ["84233.37", "0"], ["84233.30", "0"], ["84233.22", "0"], ["84233.17", "0"], ["84233.12", "0.140034"], ["84232.84", "0"], ["84232.70", "0.001034"], ["84232.54", "0"], ["84232.51", "0"], ["84232.08", "0"], ["84231.72", "0"], ["84231.59", "0"], ["84231.58", "0"], ["84231.55", "0"], ["84231.48", "0"], ["84231.30", "0"], ["84231.14", "0"], ["84231.12", "0"], ["84230.92", "0"], ["84230.70", "0.001027"], ["84230.42", "0"], ["84230.25", "0.001228"], ["84230.22", "0.007726"], ["84230.18", "0.007641"], ["84230.08", "0"], ["84230.00", "0"], ["84229.89", "0"], ["84229.81", "0"], ["84229.62", "0"], ["84229.30", "0"], ["84228.80", "0"], ["84228.74", "0.006213"], ["84228.70", "0.008555"], ["84228.68", "0.008986"], ["84228.65", "0.007344"], ["84228.59", "0.007437"], ["84228.55", "0.006535"], ["84228.40", "0"], ["84228.30", "0"], ["84228.28", "0"], ["84227.64", "0.028814"], ["84227.51", "0.008142"], ["84227.42", "0.002062"], ["84227.38", "0.003037"], ["84227.36", "0"], ["84227.17", "0.007871"], ["84226.89", "0"], ["84226.70", "0.227723"], ["84226.00", "0.007950"], ["84225.98", "0.007474"], ["84225.97", "0"], ["84225.86", "0"], ["84225.80", "0"], ["84225.60", "0.005939"], ["84225.37", "0.015774"], ["84225.28", "0.016464"], ["84225.03", "0.084457"], ["84225.00", "0"], ["84224.98", "0.056367"], ["84224.85", "0.248055"], ["84224.83", "0.018265"], ["84224.70", "0.001016"], ["84224.40", "0"], ["84224.23", "0.007121"], ["84223.81", "0.017839"], ["84223.66", "0"], ["84223.40", "0"], ["84223.27", "0.007935"], ["84223.10", "0.004935"], ["84223.01", "0.008149"], ["84222.90", "0.009630"], ["84222.80", "0.026072"], ["84222.70", "0.001035"], ["84222.60", "0.197876"], ["84222.58", "0.017336"], ["84222.44", "0.012680"], ["84222.00", "0"], ["84221.95", "0"], ["84221.91", "0.017065"], ["84221.74", "0.025089"], ["84221.50", "0"], ["84221.47", "0.008166"], ["84221.28", "0.008285"], ["84221.12", "0"], ["84220.70", "0.001019"], ["84220.44", "0.018524"], ["84219.80", "0.012652"], ["84219.50", "0.001022"], ["84219.40", "0.001021"], ["84219.29", "0.052119"], ["84219.02", "0.271960"], ["84219.00", "0"], ["84218.80", "0"], ["84218.60", "0.002951"], ["84218.20", "0.001260"], ["84218.02", "0.076030"], ["84217.63", "0.222780"], ["84217.50", "0"], ["84216.70", "0.001001"], ["84216.48", "0.313205"], ["84216.40", "0.001015"], ["84216.02", "0.012442"], ["84216.00", "0.001000"], ["84215.90", "0.063780"], ["84215.80", "0"], ["84215.49", "0.263387"], ["84215.10", "0"], ["84215.00", "0.073110"], ["84214.80", "0"], ["84214.70", "0"], ["84213.95", "0"], ["84213.12", "0.073522"], ["84213.00", "0"], ["84212.30", "0"], ["84212.00", "0.021600"], ["84211.82", "0.056651"], ["84211.16", "0"], ["84208.60", "0.090000"], ["84208.53", "0"], ["84208.40", "0.015780"], ["84207.00", "0.013860"], ["84205.25", "0"], ["84204.45", "0.008206"], ["84204.10", "1.350000"], ["84200.40", "0.012660"], ["84200.05", "0.007181"], ["84199.86", "0.007582"], ["84199.80", "0.071220"], ["84199.10", "1.186710"], ["84198.90", "0.090000"], ["84198.40", "0.177960"], ["84197.50", "0.060000"], ["84197.00", "0.090000"], ["84196.70", "2.669430"], ["84196.30", "1.076280"], ["84195.60", "1.756890"], ["84194.90", "0.001180"], ["84193.10", "0.207047"], ["84187.20", "0"], ["84178.70", "0"], ["84178.60", "4.340159"], ["84170.20", "0"], ["84170.10", "5.244358"], ["84169.62", "0"], ["84168.00", "0"], ["84161.70", "0"], ["84161.60", "3.888059"], ["84153.35", "0"], ["84153.20", "0"], ["84153.10", "4.882678"], ["84144.70", "0"], ["84144.60", "4.068899"], ["84136.20", "0"], ["84136.10", "5.334778"], ["84127.70", "0"], ["84127.60", "4.611418"], ["84123.05", "0.072042"], ["84119.20", "0"], ["84119.10", "4.973098"], ["84110.70", "0"], ["84110.60", "5.606038"], ["84107.82", "0.125282"], ["84102.20", "0"], ["84102.10", "5.425198"], ["84093.70", "0"], ["84093.60", "3.978479"], ["84085.20", "0"], ["84085.10", "5.063518"], ["84076.70", "0.209200"], ["84076.60", "5.515617"], ["84068.20", "0"], ["84068.10", "4.430579"], ["84059.70", "0"], ["84059.60", "4.249739"], ["84051.20", "0"], ["84051.10", "5.153938"], ["84042.70", "0"], ["84042.60", "4.520998"], ["84034.20", "0"], ["84034.10", "4.701838"], ["84026.10", "0.209200"], ["84025.70", "0"], ["84025.60", "4.159319"], ["84017.10", "4.792258"], ["83877.29", "0.000024"], ["83877.05", "0.000008"], ["83876.25", "0.000028"], ["83876.12", "0.000681"], ["83875.99", "0.000299"], ["83875.49", "0.000723"], ["83875.16", "0.000179"], ["83875.00", "0.000145"]], "checksum": -1740580400, "ts": "1742142217546"}], "ts": 1742142217550, "record_time": 1742142216.65961}
{"action": "update", "arg": {"instType": "SPOT", "channel": "books", "instId": "BTCUSDT"}, "data": [{"asks": [["84244.21", "0.626118"], ["84251.04", "0.203170"], ["84251.22", "0.034703"], ["84255.25", "0.187534"], ["84255.26", "0.005074"], ["84255.30", "0.353241"], ["84255.31", "0"], ["84256.27", "0.008506"], ["84260.09", "0.002907"], ["84264.51", "0.004844"], ["84264.52", "0.142674"], ["84266.84", "0.017806"], ["84267.04", "0"], ["84270.45", "0.209200"], ["84273.04", "0.031812"], ["84275.15", "0"], ["84276.72", "0.075000"], ["84280.32", "0"], ["84282.93", "0"], ["84287.10", "0.001688"], ["84287.69", "0"], ["84289.10", "0.004621"], ["84291.10", "0.012162"], ["84293.10", "0.032006"], ["84295.10", "0.084226"], ["84297.10", "0.221648"], ["84299.10", "0.583283"], ["84301.10", "1.534955"], ["84303.10", "4.039355"], ["84305.10", "10.629881"], ["84307.50", "0.001021"], ["84307.90", "1.114470"], ["84308.20", "1.849320"], ["84308.30", "0.120000"], ["84308.80", "0.351300"], ["84308.90", "0.985470"], ["84309.40", "0.989100"], ["84310.30", "0"], ["84313.50", "1.350000"], ["84313.60", "1.716900"], ["84313.70", "5.899650"], ["84314.30", "0.117000"], ["84314.80", "0.526350"], ["84315.10", "0.180000"], ["84315.60", "0.014250"], ["84316.20", "0.237510"], ["84316.30", "1.005900"], ["84318.10", "0.211950"], ["84318.60", "0.117000"], ["84319.40", "0.010560"], ["84319.50", "0.025350"], ["84319.90", "0.160890"], ["84320.20", "0.186600"], ["84320.30", "0"], ["84321.00", "0.177960"], ["84321.50", "0"], ["84322.40", "0"], ["84323.00", "0"], ["84323.20", "0"], ["84323.60", "0"], ["84324.20", "0"], ["84325.00", "0"], ["84347.20", "5.153938"], ["84355.70", "4.340159"], ["84364.20", "4.159319"], ["84372.70", "5.606038"], ["84381.20", "5.244358"], ["84389.70", "5.063518"], ["84398.20", "3.978479"], ["84406.70", "4.068899"], ["84415.20", "4.882678"], ["84423.70", "4.792258"], ["84440.70", "5.334778"], ["84449.20", "5.425198"], ["84457.70", "4.611418"], ["84466.20", "4.973098"], ["84474.70", "5.515618"], ["84483.20", "4.249739"], ["84491.70", "4.430579"], ["84500.20", "4.520998"], ["84508.70", "3.888059"], ["84845.94", "0"], ["84846.15", "0"], ["84846.55", "0"], ["84846.85", "0"], ["84847.58", "0"], ["84847.82", "0"], ["84849.88", "0"], ["84850.00", "0"]], "bids": [["84244.20", "0.264378"], ["84240.31", "0"], ["84239.98", "0.062760"], ["84234.65", "0"], ["84230.70", "0.002753"], ["84230.21", "0.008535"], ["84230.16", "0.006487"], ["84229.31", "0"], ["84228.41", "0.001199"], ["84225.56", "0.186853"], ["84224.70", "0.050172"], ["84222.70", "0.132030"], ["84221.92", "0.014295"], ["84221.60", "0.007319"], ["84221.48", "0.008672"], ["84221.33", "0.010234"], ["84220.70", "0.347448"], ["84220.50", "0.001050"], ["84220.00", "0.001037"], ["84219.90", "0.372930"], ["84219.50", "0.001008"], ["84218.20", "0"], ["84216.70", "0"], ["84216.40", "0"], ["84216.10", "1.101720"], ["84216.08", "0.021113"], ["84216.00", "0"], ["84215.90", "0"], ["84215.00", "0.073290"], ["84214.00", "0.035580"], ["84213.00", "0.142500"], ["84209.60", "0.038460"], ["84208.80", "0.065400"], ["84208.60", "0"], ["84208.40", "0"], ["84208.10", "0.013170"], ["84206.60", "0.142500"], ["84205.50", "0.071310"], ["84205.10", "1.190520"], ["84204.10", "2.440200"], ["84203.60", "2.350440"], ["84203.20", "0.090000"], ["84201.60", "0.027120"], ["84201.40", "0.090000"], ["84200.40", "0"], ["84199.80", "0"], ["84199.10", "0"], ["84198.90", "0"], ["84198.40", "0"], ["84197.50", "0"], ["84197.00", "0"], ["84196.70", "0"], ["84196.30", "0"], ["84195.60", "0"], ["84185.90", "0.017806"], ["84178.60", "4.792258"], ["84161.60", "4.159319"], ["84153.10", "4.520998"], ["84144.60", "4.882678"], ["84136.10", "3.978479"], ["84127.60", "3.888059"], ["84119.10", "4.701838"], ["84102.10", "4.068899"], ["84100.39", "0"], ["84093.60", "4.611418"], ["84085.10", "4.973098"], ["84076.60", "5.425198"], ["84068.10", "4.249739"], ["84059.60", "5.334778"], ["84051.10", "4.430579"], ["84042.60", "5.515618"], ["84034.10", "5.153938"], ["84025.60", "5.063518"], ["84017.10", "4.340159"], ["83876.25", "0"], ["83876.12", "0"], ["83875.99", "0"], ["83875.49", "0"], ["83875.16", "0"], ["83875.00", "0"]], "checksum": 1112071631, "ts": "1742142217749"}], "ts": 1742142217753, "record_time": 1742142216.861547}
{"action": "update", "arg": {"instType": "SPOT", "channel": "books", "instId": "BTCUSDT"}, "data": [{"asks": [["84244.21", "0.782267"], ["84248.75", "0.063836"], ["84248.92", "0.140033"], ["84251.03", "0.071362"], ["84251.04", "0"], ["84255.24", "0.102099"], ["84255.25", "0.047500"], ["84255.26", "0.004595"], ["84255.30", "0"], ["84255.33", "0.030015"], ["84256.31", "0.014495"], ["84264.52", "0.078847"], ["84267.55", "0.010000"], ["84269.61", "1.895578"], ["84273.04", "0"], ["84277.92", "0"], ["84281.53", "0.031812"], ["84285.10", "0.001126"], ["84286.42", "0.029802"], ["84286.46", "2.228512"], ["84287.10", "0.001708"], ["84289.10", "0.004495"], ["84291.10", "0.011829"], ["84293.10", "0.031129"], ["84295.10", "0.081919"], ["84297.10", "0.215575"], ["84299.10", "0.567303"], ["84301.10", "1.492903"], ["84303.10", "3.928691"], ["84305.10", "10.338661"], ["84306.80", "0.001043"], ["84307.90", "1.288920"], ["84308.20", "1.848900"], ["84311.80", "0.035580"], ["84313.50", "1.359000"], ["84314.80", "0.795360"], ["84316.00", "0.288000"], ["84317.70", "0.035580"], ["84318.10", "0.349170"], ["84319.40", "0.136560"], ["84319.50", "0"], ["84319.90", "0"], ["84320.20", "0"], ["84321.00", "0"], ["84322.20", "0"], ["84347.20", "3.888059"], ["84355.70", "3.978479"], ["84364.20", "4.701838"], ["84372.70", "5.515618"], ["84381.20", "4.159319"], ["84389.70", "4.973098"], ["84398.20", "4.068899"], ["84406.70", "4.520998"], ["84423.70", "4.249739"], ["84432.20", "5.153938"], ["84440.70", "5.244358"], ["84449.20", "4.430579"], ["84457.70", "5.606038"], ["84466.20", "4.792258"], ["84474.70", "5.425198"], ["84483.20", "4.340159"], ["84491.70", "5.334778"], ["84500.20", "4.611418"], ["84508.70", "5.063518"], ["84840.00", "0"], ["84841.58", "0"], ["84842.11", "0"], ["84844.53", "0"], ["84845.00", "0"]], "bids": [["84244.20", "0.467548"], ["84243.50", "1.895578"], ["84240.32", "0.353132"], ["84238.71", "0.001522"], ["84234.70", "0.001407"], ["84233.13", "0.042320"], ["84232.70", "0.003703"], ["84230.70", "0.009743"], ["84228.70", "0.025641"], ["84226.65", "2.550824"], ["84224.70", "0.177569"], ["84223.46", "0.006568"], ["84223.14", "0.005552"], ["84223.06", "0.000875"], ["84222.97", "0.005088"], ["84222.70", "0.467287"], ["84220.70", "1.229702"], ["84220.10", "0.651510"], ["84220.00", "0.001590"], ["84219.90", "0.372720"], ["84219.40", "0"], ["84216.10", "0"], ["84215.10", "0.075930"], ["84212.30", "0.009000"], ["84212.00", "0.059670"], ["84208.10", "2.350320"], ["84205.90", "1.083780"], ["84205.10", "0.915360"], ["84204.10", "2.053230"], ["84203.80", "0.009000"], ["84203.60", "0"], ["84201.60", "0"], ["84201.40", "0"], ["84178.60", "4.520998"], ["84170.10", "4.882678"], ["84161.60", "5.244358"], ["84153.10", "3.888059"], ["84144.60", "5.153938"], ["84136.10", "4.159319"], ["84127.60", "4.430579"], ["84119.10", "4.068899"], ["84110.60", "5.515618"], ["84102.10", "3.978479"], ["84093.60", "4.792258"], ["84085.10", "4.611418"], ["84076.60", "5.063518"], ["84068.10", "4.701838"], ["84051.10", "4.249739"], ["84042.60", "4.340159"], ["84034.10", "5.425198"], ["84025.60", "5.606038"], ["84017.10", "4.973098"], ["83882.98", "0"], ["83882.92", "0"], ["83881.99", "0"], ["83880.00", "0"], ["83877.97", "0"], ["83877.55", "0"], ["83877.42", "0"], ["83877.29", "0"], ["83877.05", "0"]], "checksum": -367497120, "ts": "1742142217949"}], "ts": 1742142217954, "record_time": 1742142217.062002}
{"action": "update", "arg": {"instType": "SPOT", "channel": "books", "instId": "BTCUSDT"}, "data": [{"asks": [["84244.21", "0.849168"], ["84251.03", "0.010411"], ["84255.24", "0.014414"], ["84307.60", "0.416430"], ["84307.90", "1.288710"], ["84314.80", "0.623610"], ["84316.40", "0.702300"], ["84347.20", "4.520998"], ["84355.70", "3.888059"], ["84364.20", "4.792258"], ["84372.70", "4.973098"], ["84381.20", "4.340159"], ["84389.70", "5.606038"], ["84398.20", "4.159319"], ["84406.70", "5.425198"], ["84415.20", "4.249739"], ["84423.70", "5.244358"], ["84432.20", "4.068899"], ["84440.70", "5.334778"], ["84449.20", "5.153938"], ["84457.70", "5.515618"], ["84466.20", "5.063518"], ["84474.70", "4.430579"], ["84483.20", "3.978479"], ["84491.70", "4.701838"], ["84508.70", "4.882678"], ["84838.71", "0"], ["84839.83", "0"]], "bids": [["84244.20", "0.467904"], ["84243.66", "0.000070"], ["84243.51", "0.737680"], ["84239.98", "0"], ["84233.12", "0"], ["84220.10", "0.651930"], ["84220.00", "0.001380"], ["84219.00", "0.022740"], ["84214.00", "0"], ["84213.00", "0.142680"], ["84210.20", "0.413100"], ["84208.10", "3.399240"], ["84205.90", "0"], ["84201.60", "0.027120"], ["84178.60", "3.978479"], ["84165.00", "0"], ["84161.60", "5.153938"], ["84153.10", "5.063518"], ["84144.60", "4.611418"], ["84136.10", "4.792258"], ["84127.60", "4.520998"], ["84119.10", "4.973098"], ["84110.60", "4.701838"], ["84102.10", "4.340159"], ["84093.60", "5.606038"], ["84085.10", "4.430579"], ["84076.60", "4.159319"], ["84068.10", "5.244358"], ["84059.60", "5.425198"], ["84051.10", "4.068899"], ["84047.49", "0.171087"], ["84042.60", "5.334778"], ["84034.10", "3.888059"], ["84025.60", "5.515618"], ["84017.10", "4.249739"], ["83884.30", "0"]], "checksum": -1613080003, "ts": "1742142218164"}], "ts": 1742142218171, "record_time": 1742142217.278496}
{"action": "update", "arg": {"instType": "SPOT", "channel": "books", "instId": "BTCUSDT"}, "data": [{"asks": [["84255.24", "0.071165"], ["84264.52", "0.066167"], ["84266.41", "0.012680"], ["84287.82", "0"], ["84305.10", "10.338791"], ["84307.10", "0.001029"], ["84307.40", "0.001039"], ["84307.60", "0.416220"], ["84307.90", "1.288500"], ["84312.40", "0.015180"], ["84312.80", "0.015120"], ["84314.20", "0"], ["84314.50", "0"], ["84316.40", "0"], ["84317.10", "0"], ["84347.20", "4.249739"], ["84355.70", "5.606038"], ["84364.20", "4.882678"], ["84372.70", "5.515618"], ["84381.20", "4.430579"], ["84389.70", "5.153938"], ["84398.20", "4.340159"], ["84406.70", "4.792258"], ["84415.20", "4.701838"], ["84423.70", "3.888059"], ["84432.20", "5.425198"], ["84449.20", "4.068899"], ["84457.70", "4.973098"], ["84466.20", "4.520998"], ["84474.70", "3.978479"], ["84483.20", "5.063518"], ["84491.70", "4.159319"], ["84508.70", "5.244358"]], "bids": [["84243.66", "0"], ["84242.09", "0.010000"], ["84239.38", "0.140031"], ["84233.13", "0.001111"], ["84230.70", "0.009634"], ["84228.70", "0.025354"], ["84226.98", "0.003070"], ["84224.70", "0.175582"], ["84222.70", "0.462056"], ["84220.70", "1.215938"], ["84219.00", "0.035580"], ["84214.00", "0.026100"], ["84213.00", "0.142500"], ["84212.00", "0.179280"], ["84208.10", "3.398820"], ["84201.60", "0"], ["84178.60", "4.882678"], ["84170.10", "4.159319"], ["84167.00", "0.000121"], ["84161.60", "4.520998"], ["84153.10", "5.153938"], ["84144.60", "4.340159"], ["84136.10", "5.244358"], ["84127.60", "5.606038"], ["84123.05", "0"], ["84119.10", "5.063518"], ["84110.60", "4.068899"], ["84102.10", "4.611418"], ["84093.60", "4.430579"], ["84085.10", "4.792258"], ["84076.60", "4.249739"], ["84068.10", "4.701838"], ["84059.60", "5.515618"], ["84051.10", "4.973098"], ["84042.60", "3.888059"], ["84034.10", "3.978479"], ["84025.60", "5.334778"], ["84017.10", "5.425198"], ["83884.62", "0"], ["83884.55", "0"]], "checksum": -1417512926, "ts": "1742142218364"}], "ts": 1742142218369, "record_time": 1742142217.476262}
{"action": "update", "arg": {"instType": "SPOT", "channel": "books", "instId": "BTCUSDT"}, "data": [{"asks": [["84248.60", "0.063836"], ["84248.74", "0.071572"], ["84248.75", "0"], ["84251.03", "0"], ["84272.43", "0"], ["84289.10", "0.004680"], ["84291.10", "0.012317"], ["84293.10", "0.032412"], ["84295.10", "0.085297"], ["84297.03", "0"], ["84297.10", "0.224465"], ["84299.10", "0.590698"], ["84301.10", "1.554247"], ["84303.10", "4.090125"], ["84305.10", "10.763485"], ["84306.80", "0.018210"], ["84309.40", "0.927000"], ["84311.00", "0.064320"], ["84314.20", "0.070050"], ["84319.40", "0"], ["84355.70", "5.425198"], ["84372.70", "4.701838"], ["84381.20", "5.334778"], ["84389.70", "4.430579"], ["84398.20", "5.063518"], ["84406.70", "5.244358"], ["84415.20", "4.159319"], ["84423.70", "4.340159"], ["84432.20", "5.606038"], ["84440.70", "4.520998"], ["84449.20", "4.611418"], ["84457.70", "5.515618"], ["84466.20", "4.068899"], ["84483.20", "5.153938"], ["84491.70", "3.888059"], ["84500.20", "4.792258"], ["84508.70", "4.973098"], ["84838.71", "0.000214"]], "bids": [["84244.20", "0.258704"], ["84239.39", "0.043532"], ["84238.71", "0"], ["84234.70", "0.001197"], ["84232.70", "0.003150"], ["84230.70", "0.008288"], ["84228.70", "0.021811"], ["84224.70", "0.151046"], ["84222.70", "0.397490"], ["84222.60", "0"], ["84220.70", "1.046269"], ["84220.10", "0.001020"], ["84219.50", "0"], ["84219.00", "0.019530"], ["84215.10", "0.197876"], ["84215.00", "0.073110"], ["84208.10", "3.399030"], ["84203.20", "0"], ["84193.10", "0"], ["84190.00", "0.000071"], ["84178.60", "4.068899"], ["84170.10", "5.606038"], ["84161.60", "5.153938"], ["84153.10", "4.249739"], ["84144.60", "3.978479"], ["84136.10", "5.425198"], ["84127.60", "4.159319"], ["84119.10", "4.340159"], ["84110.60", "4.430579"], ["84102.10", "5.334778"], ["84093.60", "4.882678"], ["84085.10", "3.888059"], ["84076.60", "4.973098"], ["84068.10", "4.792258"], ["84059.60", "5.244358"], ["84051.10", "4.520998"], ["84042.60", "5.515618"], ["84034.10", "4.611418"], ["84025.60", "5.063518"], ["84017.10", "4.701838"], ["83884.62", "0.000014"], ["83884.55", "0.000048"], ["83884.30", "0.000161"]], "checksum": 482527285, "ts": "1742142218565"}], "ts": 1742142218568, "record_time": 1742142217.676725}
{"action": "update", "arg": {"instType": "SPOT", "channel": "books", "instId": "BTCUSDT"}, "data": [{"asks": [["84248.74", "0.052421"], ["84295.10", "0.085404"], ["84297.10", "0.224747"], ["84299.10", "0.591440"], ["84301.10", "1.556420"], ["84303.10", "4.095842"], ["84305.10", "10.778533"], ["84306.80", "0.017460"], ["84347.20", "3.978479"], ["84364.20", "5.606038"], ["84372.70", "4.973098"], ["84381.20", "4.701838"], ["84389.70", "4.249739"], ["84398.20", "4.430579"], ["84406.70", "5.515618"], ["84415.20", "4.792258"], ["84423.70", "5.153938"], ["84432.20", "5.063518"], ["84440.70", "5.334778"], ["84449.20", "5.244358"], ["84457.70", "3.888059"], ["84466.20", "4.159319"], ["84474.70", "4.068899"], ["84483.20", "4.520998"], ["84491.70", "4.611418"], ["84500.20", "4.882678"], ["84508.70", "4.340159"]], "bids": [["84244.20", "0.467904"], ["84242.43", "0.000070"], ["84230.85", "0.108488"], ["84230.70", "0.008456"], ["84228.70", "0.022253"], ["84224.70", "0.154105"], ["84222.70", "0.405541"], ["84220.70", "1.067212"], ["84219.00", "0.001020"], ["84216.70", "0.839490"], ["84208.10", "3.412620"], ["84178.60", "4.792258"], ["84170.10", "5.425198"], ["84166.00", "0.000159"], ["84161.60", "5.334778"], ["84153.10", "5.515618"], ["84144.60", "4.701838"], ["84136.10", "4.430579"], ["84127.60", "3.888059"], ["84110.60", "3.978479"], ["84102.10", "4.611418"], ["84093.60", "4.249739"], ["84085.10", "5.606038"], ["84068.10", "5.063518"], ["84059.60", "4.068899"], ["84051.10", "5.153938"], ["84042.60", "4.882678"], ["84034.10", "5.244358"], ["84025.60", "4.159319"], ["84017.10", "4.520998"], ["83885.71", "0"], ["83884.62", "0"], ["83884.55", "0"], ["83884.30", "0"]], "checksum": -1580445994, "ts": "1742142218768"}], "ts": 1742142218771, "record_time": 1742142217.878955}
{"action": "update", "arg": {"instType": "SPOT", "channel": "books", "instId": "BTCUSDT"}, "data": [{"asks": [["84248.43", "0.063837"], ["84248.60", "0"], ["84248.74", "0"], ["84259.79", "0.024987"], ["84306.80", "0.007350"], ["84311.00", "0.064890"], ["84314.20", "0"], ["84347.20", "5.153938"], ["84364.20", "4.882678"], ["84372.70", "5.244358"], ["84381.20", "5.606038"], ["84389.70", "4.611418"], ["84398.20", "4.973098"], ["84406.70", "4.340159"], ["84415.20", "3.978479"], ["84423.70", "4.701838"], ["84440.70", "3.888059"], ["84449.20", "4.068899"], ["84457.70", "4.430579"], ["84466.20", "4.792258"], ["84474.70", "5.334778"], ["84491.70", "4.159319"], ["84500.20", "4.249739"], ["84508.70", "5.515618"], ["84839.83", "0.000098"]], "bids": [["84244.20", "1.064201"], ["84240.32", "0"], ["84234.70", "0.001312"], ["84232.70", "0.003452"], ["84230.70", "0.008953"], ["84228.70", "0.023561"], ["84226.66", "0.608132"], ["84224.70", "0.163167"], ["84222.70", "0.429388"], ["84220.70", "1.129969"], ["84218.30", "0.590340"], ["84216.70", "0"], ["84208.40", "0.021600"], ["84208.10", "3.412410"], ["84203.20", "0.090000"], ["84178.60", "3.888059"], ["84170.10", "5.153938"], ["84161.60", "4.249739"], ["84144.60", "5.606038"], ["84136.10", "5.425198"], ["84127.60", "4.340159"], ["84119.10", "4.430579"], ["84110.60", "4.159319"], ["84102.10", "5.063518"], ["84093.60", "4.792258"], ["84085.10", "4.973098"], ["84076.60", "5.244358"], ["84068.10", "4.882678"], ["84051.10", "4.520998"], ["84042.60", "3.978479"], ["84034.10", "5.334778"], ["84025.60", "4.701838"], ["84017.10", "4.611418"], ["83886.91", "0"], ["83885.98", "0"]], "checksum": 1469696062, "ts": "1742142218969"}], "ts": 1742142218972, "record_time": 1742142218.080211}
{"action": "update", "arg": {"instType": "SPOT", "channel": "books", "instId": "BTCUSDT"}, "data": [{"asks": [["84255.25", "0"], ["84262.01", "0.146823"], ["84262.02", "0.209200"], ["84281.53", "0"], ["84285.10", "0.001004"], ["84286.42", "0"], ["84287.10", "0.001025"], ["84289.10", "0.002697"], ["84291.10", "0.007097"], ["84293.10", "0.018678"], ["84294.53", "0.031812"], ["84295.10", "0.049152"], ["84297.10", "0.129346"], ["84299.10", "0.340386"], ["84301.10", "0.895752"], ["84303.10", "2.357242"], ["84305.10", "6.203267"], ["84306.20", "0.001007"], ["84306.60", "0.001037"], ["84306.80", "0.001039"], ["84307.50", "0"], ["84308.20", "0"], ["84309.40", "0"], ["84310.20", "0.142500"], ["84311.00", "0"], ["84311.60", "0"], ["84311.80", "0.014670"], ["84312.20", "0"], ["84313.50", "0.009000"], ["84313.70", "5.722560"], ["84317.70", "0.445950"], ["84319.40", "0.136560"], ["84319.50", "0.025350"], ["84320.10", "0.177960"], ["84347.20", "4.068899"], ["84355.70", "3.888059"], ["84364.20", "5.606038"], ["84372.70", "4.159319"], ["84381.20", "5.425198"], ["84389.70", "5.244358"], ["84398.20", "5.153938"], ["84406.70", "4.882678"], ["84415.20", "4.701838"], ["84423.70", "4.340159"], ["84432.20", "4.249739"], ["84440.70", "5.515618"], ["84449.20", "3.978479"], ["84457.70", "5.063518"], ["84466.20", "4.611418"], ["84474.70", "4.973098"], ["84491.70", "5.334778"], ["84500.20", "4.430579"], ["84508.70", "4.792258"], ["84840.00", "0.000436"], ["84841.58", "0.000008"], ["84842.11", "0.000068"]], "bids": [["84234.70", "0.002154"], ["84232.70", "0.005668"], ["84230.70", "0.014916"], ["84228.70", "0.039252"], ["84224.70", "0.271828"], ["84222.70", "0.715338"], ["84222.44", "0"], ["84220.70", "1.882469"], ["84220.40", "1.188570"], ["84220.00", "0"], ["84219.90", "0.372330"], ["84219.40", "0.142500"], ["84219.00", "0.035580"], ["84218.30", "0"], ["84215.80", "0.069600"], ["84215.00", "0.134430"], ["84212.70", "2.350200"], ["84208.40", "0.030000"], ["84208.10", "1.048500"], ["84203.80", "0"], ["84203.20", "0"], ["84178.60", "4.068899"], ["84170.10", "4.792258"], ["84169.00", "0.012717"], ["84161.60", "5.334778"], ["84153.10", "4.611418"], ["84144.60", "4.340159"], ["84136.10", "4.973098"], ["84127.60", "4.249739"], ["84119.10", "4.159319"], ["84110.60", "5.153938"], ["84102.10", "5.515618"], ["84093.60", "4.882678"], ["84085.10", "5.063518"], ["84076.60", "4.520998"], ["84068.10", "4.701838"], ["84059.60", "5.606038"], ["84051.10", "5.244358"], ["84042.60", "5.425198"], ["84034.10", "3.888059"], ["84025.60", "4.430579"], ["84017.10", "3.978479"], ["83886.91", "0.000145"]], "checksum": -242090197, "ts": "1742142219168"}], "ts": 1742142219175, "record_time": 1742142218.283158}
{"action": "update", "arg": {"instType": "SPOT", "channel": "books", "instId": "BTCUSDT"}, "data": [{"asks": [["84255.24", "0.056915"], ["84261.07", "0.209200"], ["84262.01", "0"], ["84289.10", "0.002567"], ["84291.10", "0.006756"], ["84293.10", "0.017778"], ["84295.10", "0.046784"], ["84297.10", "0.123116"], ["84299.10", "0.323990"], ["84301.10", "0.852604"], ["84303.10", "2.243694"], ["84305.10", "5.904328"], ["84307.60", "0.683640"], ["84307.90", "0"], ["84308.90", "0"], ["84312.40", "0.484260"], ["84313.50", "1.359000"], ["84314.80", "1.609080"], ["84315.10", "0"], ["84315.60", "0"], ["84316.00", "0"], ["84316.20", "0.102510"], ["84316.30", "0"], ["84319.50", "0.088650"], ["84320.20", "0.186600"], ["84320.30", "0.099000"], ["84320.40", "0.102540"], ["84347.20", "4.882678"], ["84355.70", "4.159319"], ["84364.20", "5.334778"], ["84372.70", "5.425198"], ["84381.20", "5.606038"], ["84389.70", "4.973098"], ["84406.70", "5.244358"], ["84415.20", "4.792258"], ["84423.70", "3.978479"], ["84432.20", "4.611418"], ["84440.70", "4.068899"], ["84449.20", "4.249739"], ["84466.20", "3.888059"], ["84474.70", "5.515618"], ["84483.20", "4.340159"], ["84491.70", "4.701838"], ["84508.70", "4.520998"], ["84844.53", "0.000423"], ["84845.00", "0.000025"], ["84845.94", "0.000008"]], "bids": [["84244.20", "1.064431"], ["84242.43", "0"], ["84237.28", "0.012680"], ["84234.71", "0.002347"], ["84234.70", "0.002020"], ["84233.13", "0"], ["84232.70", "0.005316"], ["84230.70", "0.013988"], ["84228.70", "0.036811"], ["84225.56", "0"], ["84224.70", "0.254924"], ["84222.70", "0.670852"], ["84220.70", "1.765400"], ["84220.40", "1.230960"], ["84215.10", "0.786690"], ["84212.00", "0.586230"], ["84211.30", "0.462600"], ["84210.90", "0.915360"], ["84208.10", "0.068730"], ["84206.50", "0.410370"], ["84205.10", "0"], ["84204.10", "0"], ["84178.60", "5.063518"], ["84170.10", "4.520998"], ["84161.60", "3.888059"], ["84153.10", "5.606038"], ["84144.60", "5.425198"], ["84136.10", "4.068899"], ["84127.60", "4.611418"], ["84119.10", "4.882678"], ["84110.60", "3.978479"], ["84102.10", "4.792258"], ["84093.60", "4.340159"], ["84085.10", "4.973098"], ["84076.60", "4.430579"], ["84059.60", "4.159319"], ["84051.10", "4.249739"], ["84042.60", "5.515618"], ["84034.10", "5.334778"], ["84025.60", "5.244358"], ["84017.10", "5.153938"]], "checksum": 207934711, "ts": "1742142219368"}], "ts": 1742142219372, "record_time": 1742142218.48062}
{"action": "update", "arg": {"instType": "SPOT", "channel": "books", "instId": "BTCUSDT"}, "data": [{"asks": [["84244.21", "0.503170"], ["84244.23", "0.000100"], ["84248.28", "0.063837"], ["84248.43", "0"], ["84248.92", "0"], ["84255.24", "0.014414"], ["84255.48", "0.140039"], ["84261.06", "0.146823"], ["84261.07", "0"], ["84262.02", "0"], ["84266.41", "0"], ["84266.84", "0"], ["84267.55", "0"], ["84279.17", "0.017804"], ["84283.70", "0.012680"], ["84289.10", "0.001037"], ["84291.10", "0.001036"], ["84293.10", "0.002456"], ["84294.53", "0"], ["84295.10", "0.006462"], ["84297.10", "0.017007"], ["84299.10", "0.044753"], ["84301.10", "0.117771"], ["84303.10", "0.309925"], ["84305.10", "0.815591"], ["84305.80", "0.001016"], ["84306.50", "0.065910"], ["84306.80", "0"], ["84307.10", "0"], ["84307.40", "0"], ["84307.60", "1.214370"], ["84308.30", "0"], ["84308.80", "0"], ["84310.20", "2.349810"], ["84311.80", "0"], ["84313.50", "0.009000"], ["84313.60", "1.182990"], ["84313.70", "0.248880"], ["84314.30", "0"], ["84314.80", "0.629190"], ["84316.20", "0.032910"], ["84316.60", "0.142500"], ["84317.70", "0.035580"], ["84318.10", "0.146580"], ["84318.60", "0"], ["84319.40", "0.010560"], ["84319.50", "0.286830"], ["84319.70", "0.063540"], ["84320.10", "0"], ["84320.20", "0.069600"], ["84320.30", "0"], ["84320.40", "0.012540"], ["84321.00", "1.299120"], ["84321.90", "0.009000"], ["84322.20", "0.069600"], ["84347.20", "4.973098"], ["84355.70", "4.701838"], ["84364.20", "5.425198"], ["84372.70", "4.068899"], ["84381.20", "3.978479"], ["84389.70", "5.606038"], ["84398.20", "4.249739"], ["84406.70", "3.888059"], ["84415.20", "4.340159"], ["84423.70", "4.520998"], ["84432.20", "4.159319"], ["84440.70", "5.153938"], ["84449.20", "4.430579"], ["84457.70", "4.611418"], ["84466.20", "4.792258"], ["84474.70", "5.244358"], ["84483.20", "5.334778"], ["84491.70", "4.882678"], ["84500.20", "5.515618"], ["84508.70", "5.063518"], ["84846.15", "0.004277"], ["84846.55", "0.000019"], ["84846.85", "0.000176"], ["84847.58", "0.000039"], ["84847.82", "0.000671"], ["84849.88", "0.000030"]], "bids": [["84244.20", "1.217150"], ["84243.50", "0"], ["84239.38", "0"], ["84237.28", "0"], ["84236.70", "0.001338"], ["84236.41", "0"], ["84234.70", "0.003520"], ["84232.70", "0.009263"], ["84230.70", "0.024377"], ["84228.70", "0.064151"], ["84227.38", "0"], ["84226.65", "0"], ["84224.70", "0.444515"], ["84222.70", "1.169775"], ["84220.70", "3.078356"], ["84219.40", "0.391230"], ["84218.90", "2.350020"], ["84217.10", "0.915360"], ["84215.10", "0.197876"], ["84215.00", "0"], ["84212.70", "0"], ["84210.90", "0"], ["84208.10", "0.183240"], ["84206.00", "0.060000"], ["84205.50", "0.090000"], ["84198.80", "0.017804"], ["84185.90", "0"], ["84178.60", "4.611418"], ["84170.10", "5.606038"], ["84164.00", "0"], ["84162.56", "0.072042"], ["84161.60", "4.159319"], ["84153.10", "4.701838"], ["84144.60", "4.520998"], ["84136.10", "5.425198"], ["84127.60", "5.334778"], ["84119.10", "5.063518"], ["84110.60", "4.792258"], ["84102.10", "5.244358"], ["84093.60", "5.153938"], ["84085.10", "4.882678"], ["84076.60", "4.340159"], ["84068.10", "4.430579"], ["84059.60", "5.515618"], ["84042.60", "3.888059"], ["84034.10", "3.978479"], ["84025.60", "4.973098"], ["84017.10", "4.068899"], ["83885.98", "0.000018"], ["83885.71", "0.000069"], ["83884.62", "0.000014"], ["83884.55", "0.000048"], ["83884.30", "0.000161"], ["83882.98", "0.000188"]], "checksum": -841201699, "ts": "1742142219578"}], "ts": 1742142219581, "record_time": 1742142218.690019}
{"action": "update", "arg": {"instType": "SPOT", "channel": "books", "instId": "BTCUSDT"}, "data": [{"asks": [["84244.21", "0.502100"], ["84244.22", "0.000100"], ["84244.24", "0.000100"], ["84261.06", "0.021303"], ["84266.13", "0"], ["84271.36", "0.119869"], ["84278.54", "0"], ["84307.60", "3.878280"], ["84307.80", "0.595140"], ["84307.90", "0.344550"], ["84310.20", "0.507030"], ["84313.60", "0"], ["84314.80", "0.065340"], ["84317.70", "0.026700"], ["84318.10", "0.529470"], ["84319.40", "0"], ["84319.50", "0"], ["84321.40", "0.117000"], ["84322.40", "1.779300"], ["84347.20", "4.701838"], ["84355.70", "4.159319"], ["84364.20", "4.882678"], ["84372.70", "4.340159"], ["84381.20", "4.249739"], ["84389.70", "4.068899"], ["84398.20", "3.978479"], ["84406.70", "4.792258"], ["84415.20", "5.153938"], ["84423.70", "4.430579"], ["84432.20", "5.063518"], ["84440.70", "5.425198"], ["84449.20", "5.334778"], ["84457.70", "4.520998"], ["84466.20", "5.244358"], ["84474.70", "5.515618"], ["84483.20", "5.606038"], ["84491.70", "4.973098"], ["84500.20", "3.888059"], ["84508.70", "4.611418"], ["84847.82", "0"], ["84849.88", "0"]], "bids": [["84244.20", "3.112627"], ["84243.51", "0.066067"], ["84240.73", "0.003008"], ["84239.39", "0"], ["84236.70", "0.001788"], ["84235.54", "2.550691"], ["84234.70", "0.004705"], ["84234.62", "0.182196"], ["84232.70", "0.012382"], ["84231.77", "0.003037"], ["84230.70", "0.032583"], ["84230.08", "0.248115"], ["84228.70", "0.085745"], ["84226.66", "0"], ["84224.85", "0"], ["84224.70", "0.593807"], ["84222.70", "1.562650"], ["84220.70", "4.112237"], ["84220.40", "2.233860"], ["84218.90", "0"], ["84217.80", "0.069600"], ["84216.60", "2.350080"], ["84212.00", "0.331320"], ["84205.50", "0.161310"], ["84178.60", "5.063518"], ["84170.10", "3.978479"], ["84161.60", "5.425198"], ["84153.10", "4.973098"], ["84144.60", "4.792258"], ["84136.10", "4.159319"], ["84119.10", "4.520998"], ["84110.60", "5.244358"], ["84102.10", "4.701838"], ["84085.10", "5.515618"], ["84076.60", "3.888059"], ["84068.10", "4.611418"], ["84059.60", "5.606038"], ["84051.10", "4.430579"], ["84042.60", "4.340159"], ["84034.10", "4.068899"], ["84025.60", "4.249739"], ["84017.10", "4.882678"], ["83884.55", "0"], ["83884.30", "0"], ["83882.98", "0"]], "checksum": -178431349, "ts": "1742142219779"}], "ts": 1742142219783, "record_time": 1742142218.891}
{"action": "update", "arg": {"instType": "SPOT", "channel": "books", "instId": "BTCUSDT"}, "data": [{"asks": [["84244.21", "0"], ["84248.28", "0"], ["84255.24", "0"], ["84255.48", "0"], ["84259.79", "0"], ["84268.83", "0.010786"], ["84270.45", "0"], ["84283.59", "0.001807"], ["84285.10", "0"], ["84286.50", "0.001012"], ["84287.10", "0"], ["84288.50", "0.001003"], ["84289.10", "0"], ["84290.50", "0.001035"], ["84291.10", "0"], ["84292.50", "0.001005"], ["84293.10", "0"], ["84294.50", "0.001015"], ["84295.10", "0"], ["84296.50", "0.001004"], ["84297.10", "0"], ["84298.50", "0.001044"], ["84299.10", "0"], ["84300.50", "0.002221"], ["84301.10", "0"], ["84302.50", "0.005844"], ["84303.10", "0"], ["84304.50", "0.015380"], ["84305.10", "0"], ["84305.80", "0"], ["84306.20", "0"], ["84306.50", "0.040474"], ["84307.60", "1.351350"], ["84307.80", "0"], ["84307.90", "0"], ["84310.20", "0.227340"], ["84311.40", "2.349780"], ["84316.60", "0"], ["84318.20", "0"], ["84320.20", "0"], ["84322.20", "0"], ["84322.40", "5.518170"], ["84323.00", "4.283760"], ["84323.10", "0.090000"], ["84323.60", "1.183860"], ["84323.70", "0.180000"], ["84323.90", "0.410370"], ["84347.20", "0"], ["84348.70", "5.605941"], ["84355.70", "0"], ["84357.20", "4.340083"], ["84364.20", "0"], ["84365.70", "3.887991"], ["84372.70", "0"], ["84374.20", "4.068828"], ["84381.20", "0"], ["84382.70", "4.701757"], ["84389.70", "0"], ["84391.20", "3.978410"], ["84398.20", "0"], ["84399.70", "4.159247"], ["84406.70", "0"], ["84408.20", "5.063431"], ["84415.20", "0"], ["84416.70", "5.244267"], ["84423.70", "0"], ["84425.20", "5.153849"], ["84432.20", "0"], ["84433.70", "5.334686"], ["84440.70", "0"], ["84442.20", "4.973012"], ["84449.20", "0"], ["84450.70", "4.882594"], ["84457.70", "0"], ["84459.20", "4.520920"], ["84466.20", "0"], ["84467.70", "4.430502"], ["84474.70", "0"], ["84476.20", "4.792175"], ["84483.20", "0"], ["84484.70", "5.515522"], ["84491.70", "0"], ["84493.20", "4.249665"], ["84500.20", "0"], ["84501.70", "5.425104"], ["84508.70", "0"], ["84510.20", "4.611339"], ["84602.51", "1.732870"], ["84619.94", "0"], ["84847.82", "0.000671"], ["84849.88", "0.000030"], ["84850.00", "0.000031"], ["84851.66", "0.000029"], ["84852.81", "0.000115"], ["84852.94", "0.000065"], ["84853.56", "0.000050"]], "bids": [["84244.21", "0.569779"], ["84244.20", "3.132627"], ["84242.20", "0.001036"], ["84240.70", "0"], ["84240.20", "0.001029"], ["84238.70", "0"], ["84238.20", "0.001001"], ["84236.70", "0"], ["84236.20", "0.001843"], ["84235.55", "0.765207"], ["84234.70", "0"], ["84234.20", "0.004850"], ["84232.70", "0"], ["84232.20", "0.012765"], ["84230.70", "0"], ["84230.20", "0.033591"], ["84228.70", "0.008555"], ["84228.20", "0.088397"], ["84226.20", "0.232623"], ["84224.70", "0"], ["84224.20", "0.612166"], ["84222.70", "0"], ["84222.20", "1.610965"], ["84221.80", "0.852900"], ["84221.40", "0.860100"], ["84220.70", "5.753430"], ["84220.50", "0"], ["84220.40", "1.548720"], ["84220.10", "0"], ["84219.80", "0.069600"], ["84219.00", "2.385600"], ["84218.60", "0"], ["84216.60", "0.776850"], ["84216.48", "0"], ["84212.30", "0.099000"], ["84212.00", "0.469710"], ["84211.90", "0.410370"], ["84211.50", "0.090000"], ["84211.40", "0.090000"], ["84211.30", "0.552600"], ["84208.90", "0.090000"], ["84208.40", "0"], ["84208.10", "0"], ["84207.00", "0"], ["84206.60", "0"], ["84206.50", "0"], ["84206.00", "0"], ["84205.50", "0"], ["84180.00", "5.063431"], ["84178.60", "0"], ["84171.50", "4.973012"], ["84170.10", "0"], ["84168.00", "0.000121"], ["84163.00", "4.701757"], ["84161.60", "0"], ["84154.50", "4.792175"], ["84153.10", "0"], ["84146.00", "4.340083"], ["84144.60", "0"], ["84137.50", "5.515522"], ["84136.10", "0"], ["84129.00", "5.605941"], ["84127.60", "0"], ["84120.50", "5.334686"], ["84119.10", "0"], ["84112.00", "3.887991"], ["84110.60", "0"], ["84103.50", "4.430502"], ["84102.10", "0"], ["84095.00", "5.153849"], ["84093.60", "0"], ["84086.50", "4.249665"], ["84085.10", "0"], ["84078.00", "4.520920"], ["84076.60", "0"], ["84069.50", "4.068828"], ["84068.10", "0"], ["84061.00", "3.978410"], ["84059.60", "0"], ["84052.50", "5.425104"], ["84051.10", "0"], ["84044.00", "4.611339"], ["84042.60", "0"], ["84035.50", "4.159247"], ["84034.10", "0"], ["84027.00", "4.882594"], ["84025.60", "0"], ["84018.50", "5.244267"], ["84017.10", "0"], ["83945.67", "0"], ["83928.38", "1.585129"], ["83884.62", "0"]], "checksum": 907078814, "ts": "1742142219980"}], "ts": 1742142219983, "record_time": 1742142219.092015}
{"action": "update", "arg": {"instType": "SPOT", "channel": "books", "instId": "BTCUSDT"}, "data": [{"asks": [["84244.22", "0"], ["84244.25", "0.000100"], ["84244.26", "0.000100"], ["84250.68", "0.063835"], ["84251.22", "0"], ["84259.80", "0"], ["84261.06", "0"], ["84264.51", "0.024694"], ["84264.81", "0.080382"], ["84265.51", "0"], ["84268.36", "0"], ["84268.82", "0.014847"], ["84269.50", "0.209200"], ["84270.50", "0"], ["84271.15", "0"], ["84271.23", "0.001205"], ["84272.86", "0"], ["84274.11", "0.006356"], ["84274.56", "0"], ["84276.26", "0.006356"], ["84276.92", "0.006356"], ["84278.62", "0.006356"], ["84280.10", "0.006356"], ["84286.50", "0"], ["84287.60", "0.001025"], ["84288.50", "0"], ["84289.60", "0.001036"], ["84290.50", "0"], ["84291.60", "0.001029"], ["84292.50", "0"], ["84293.32", "0.031812"], ["84293.60", "0.001888"], ["84294.50", "0"], ["84295.60", "0.004967"], ["84295.77", "0.010000"], ["84296.50", "0"], ["84297.60", "0.013073"], ["84298.50", "0"], ["84299.60", "0.034402"], ["84300.50", "0"], ["84301.60", "0.090531"], ["84302.50", "0"], ["84303.60", "0.238239"], ["84304.50", "0"], ["84305.60", "0.626946"], ["84306.50", "0"], ["84306.60", "0"], ["84307.60", "1.649857"], ["84307.70", "0.780360"], ["84307.90", "0.001800"], ["84308.30", "0.001036"], ["84309.90", "0.001011"], ["84310.20", "0"], ["84311.30", "0.072150"], ["84311.40", "0"], ["84312.40", "0"], ["84312.80", "0"], ["84313.20", "0.924630"], ["84313.70", "0"], ["84314.20", "0.339570"], ["84314.80", "0"], ["84315.50", "0.258030"], ["84315.70", "0.015060"], ["84316.10", "1.365210"], ["84316.20", "0"], ["84317.30", "0.015060"], ["84317.70", "0"], ["84318.50", "0.032910"], ["84319.70", "0"], ["84320.30", "0.031980"], ["84320.70", "0.469080"], ["84321.00", "1.164120"], ["84321.10", "0.065340"], ["84323.60", "0"], ["84323.70", "0"], ["84323.90", "0"], ["84348.70", "0"], ["84349.80", "4.249610"], ["84357.20", "0"], ["84358.30", "5.153782"], ["84365.70", "0"], ["84366.80", "5.425034"], ["84374.20", "0"], ["84375.30", "4.159193"], ["84382.70", "0"], ["84383.80", "4.068776"], ["84391.20", "0"], ["84392.30", "5.063365"], ["84399.70", "0"], ["84400.80", "4.430444"], ["84408.20", "0"], ["84409.30", "3.887941"], ["84416.70", "0"], ["84417.41", "0.209200"], ["84417.80", "3.978358"], ["84425.20", "0"], ["84426.30", "4.520862"], ["84433.70", "0"], ["84434.80", "4.792113"], ["84442.20", "0"], ["84443.30", "5.605868"], ["84450.70", "0"], ["84451.80", "4.340027"], ["84459.20", "0"], ["84460.30", "5.244199"], ["84467.70", "0"], ["84468.80", "4.972948"], ["84476.20", "0"], ["84477.30", "5.334617"], ["84484.70", "0"], ["84485.80", "5.515451"], ["84493.20", "0"], ["84494.30", "4.611279"], ["84501.70", "0"], ["84502.80", "4.882531"], ["84510.20", "0"], ["84511.30", "4.701696"], ["84849.88", "0"], ["84850.00", "0"], ["84851.66", "0"], ["84852.81", "0"], ["84852.94", "0"], ["84853.56", "0"]], "bids": [["84244.22", "3.924606"], ["84244.21", "1.046783"], ["84244.20", "0.160465"], ["84243.51", "0"], ["84243.30", "0.001048"], ["84242.20", "0"], ["84241.30", "0.001003"], ["84240.20", "0"], ["84239.30", "0.001936"], ["84238.20", "0"], ["84237.30", "0.005096"], ["84236.20", "0"], ["84235.30", "0.013410"], ["84235.04", "0.313238"], ["84234.71", "0.060561"], ["84234.20", "0"], ["84233.30", "0.035290"], ["84232.20", "0"], ["84231.30", "0.092869"], ["84230.20", "0"], ["84229.56", "0.017844"], ["84229.30", "0.244390"], ["84228.97", "0.006568"], ["84228.56", "0.017086"], ["84228.20", "0"], ["84227.30", "0.643132"], ["84226.20", "0"], ["84225.33", "0.012655"], ["84225.30", "1.692616"], ["84224.20", "0"], ["84223.81", "0"], ["84223.46", "0"], ["84223.30", "4.454254"], ["84223.20", "0.672360"], ["84222.84", "0.002951"], ["84222.80", "0.008990"], ["84222.20", "0.001050"], ["84221.80", "0.344190"], ["84221.60", "0.035580"], ["84221.40", "0"], ["84220.70", "0.567990"], ["84220.40", "0"], ["84219.00", "0"], ["84216.80", "0.009060"], ["84216.60", "0.491460"], ["84216.50", "0.013140"], ["84214.80", "1.350000"], ["84214.00", "0"], ["84213.20", "0.090000"], ["84212.30", "0.137460"], ["84212.10", "0.383490"], ["84210.20", "0"], ["84209.60", "0"], ["84208.90", "0"], ["84208.80", "0"], ["84181.10", "4.520862"], ["84180.00", "0"], ["84172.60", "4.159193"], ["84171.50", "0"], ["84164.10", "5.605868"], ["84163.00", "0"], ["84162.56", "0"], ["84155.60", "4.340027"], ["84154.50", "0"], ["84147.10", "4.430444"], ["84146.00", "0"], ["84138.60", "4.249610"], ["84137.50", "0"], ["84130.10", "4.792113"], ["84129.00", "0"], ["84121.60", "3.887941"], ["84120.50", "0"], ["84113.10", "3.978358"], ["84112.00", "0"], ["84104.60", "5.515451"], ["84103.50", "0"], ["84096.10", "4.701696"], ["84095.00", "0"], ["84087.60", "4.972948"], ["84086.50", "0"], ["84079.10", "4.882531"], ["84078.00", "0"], ["84070.60", "5.334617"], ["84069.50", "0"], ["84062.10", "4.611279"], ["84061.00", "0"], ["84053.60", "4.068776"], ["84052.50", "0"], ["84045.10", "5.063365"], ["84044.00", "0"], ["84036.60", "5.153782"], ["84035.50", "0"], ["84028.10", "5.244199"], ["84027.00", "0"], ["84019.60", "5.425034"], ["84018.50", "0"], ["83885.98", "0"], ["83885.71", "0"]], "checksum": -38770481, "ts": "1742142220182"}], "ts": 1742142220187, "record_time": 1742142219.295912}
{"action": "update", "arg": {"instType": "SPOT", "channel": "books", "instId": "BTCUSDT"}, "data": [{"asks": [["84259.74", "0.140036"], ["84293.60", "0.001037"], ["84295.60", "0.001089"], ["84297.60", "0.002864"], ["84299.60", "0.007537"], ["84301.60", "0.019834"], ["84303.60", "0.052197"], ["84305.60", "0.137360"], ["84307.60", "0.361472"], ["84307.70", "0.001530"], ["84311.90", "3.348360"], ["84313.20", "0.709170"], ["84313.90", "0.679140"], ["84314.20", "0"], ["84315.50", "0"], ["84316.10", "0.015210"], ["84320.30", "0"], ["84321.40", "0"], ["84321.50", "0.106830"], ["84323.00", "4.085760"], ["84323.10", "0"], ["84323.60", "0.177960"], ["84349.80", "3.887941"], ["84358.30", "4.792113"], ["84366.80", "3.978358"], ["84375.30", "5.515451"], ["84383.80", "4.882531"], ["84392.30", "5.244199"], ["84400.80", "4.701696"], ["84409.30", "4.972948"], ["84417.80", "4.430444"], ["84426.30", "5.063365"], ["84434.80", "4.249610"], ["84443.30", "4.611279"], ["84451.80", "5.334617"], ["84460.30", "4.520862"], ["84468.80", "4.159193"], ["84477.30", "5.153782"], ["84485.80", "5.605868"], ["84494.30", "4.068776"], ["84502.80", "5.425034"], ["84511.30", "4.340027"]], "bids": [["84244.22", "4.148024"], ["84244.21", "0.830773"], ["84242.09", "0"], ["84239.30", "0.002543"], ["84237.30", "0.006691"], ["84235.30", "0.017609"], ["84234.71", "0"], ["84233.30", "0.046339"], ["84231.30", "0.121944"], ["84230.85", "0"], ["84229.30", "0.320906"], ["84227.30", "0.844490"], ["84225.30", "2.222342"], ["84223.30", "5.848268"], ["84223.20", "1.714860"], ["84221.80", "0.069600"], ["84221.70", "2.349930"], ["84220.70", "0.549990"], ["84219.90", "0"], ["84210.20", "0.413100"], ["84181.10", "4.701696"], ["84165.00", "0.000159"], ["84155.60", "4.882531"], ["84147.10", "4.249610"], ["84138.60", "5.063365"], ["84130.10", "4.068776"], ["84121.60", "5.334617"], ["84113.10", "5.515451"], ["84104.60", "4.972948"], ["84096.10", "5.153782"], ["84087.60", "4.611279"], ["84079.10", "3.887941"], ["84070.60", "4.520862"], ["84062.10", "3.978358"], ["84053.60", "5.425034"], ["84045.10", "4.792113"], ["84036.60", "4.340027"], ["84028.10", "4.430444"], ["84019.60", "5.244199"], ["83885.98", "0.000018"]], "checksum": 1785343784, "ts": "1742142220398"}], "ts": 1742142220403, "record_time": 1742142219.510989}
{"action": "update", "arg": {"instType": "SPOT", "channel": "books", "instId": "BTCUSDT"}, "data": [{"asks": [["84250.46", "0.063835"], ["84250.68", "0"], ["84269.50", "0"], ["84297.60", "0.002850"], ["84299.60", "0.007500"], ["84301.60", "0.019736"], ["84303.60", "0.051939"], ["84305.60", "0.136681"], ["84307.60", "0.359687"], ["84311.90", "0"], ["84313.20", "0.925050"], ["84313.90", "0"], ["84314.10", "3.443970"], ["84317.00", "0.258030"], ["84318.10", "0.248010"], ["84321.00", "0.178650"], ["84321.50", "0"], ["84321.60", "0.106830"], ["84349.80", "4.159193"], ["84358.30", "5.334617"], ["84366.80", "4.068776"], ["84375.30", "4.701696"], ["84383.80", "4.430444"], ["84392.30", "5.515451"], ["84400.80", "4.611279"], ["84409.30", "4.520862"], ["84417.80", "4.882531"], ["84426.30", "5.153782"], ["84434.80", "4.972948"], ["84443.30", "5.244199"], ["84451.80", "4.340027"], ["84460.30", "5.425034"], ["84468.80", "5.063365"], ["84477.30", "3.887941"], ["84485.80", "4.249610"], ["84494.30", "3.978358"], ["84502.80", "4.792113"], ["84511.30", "5.605868"], ["84849.88", "0.000030"]], "bids": [["84244.21", "0.615696"], ["84239.30", "0.002829"], ["84237.30", "0.007446"], ["84235.30", "0.019594"], ["84235.05", "0.187989"], ["84233.30", "0.051710"], ["84231.30", "0.136079"], ["84230.09", "0.128910"], ["84229.30", "0.358105"], ["84227.30", "0.942381"], ["84226.98", "0"], ["84225.30", "2.479949"], ["84223.30", "6.526182"], ["84223.20", "2.630640"], ["84220.70", "0.163500"], ["84217.10", "0"], ["84211.30", "0.090000"], ["84211.20", "0.030000"], ["84181.10", "4.340027"], ["84172.60", "3.887941"], ["84164.10", "3.978358"], ["84155.60", "4.159193"], ["84147.10", "4.701696"], ["84138.60", "5.515451"], ["84130.10", "4.792113"], ["84121.60", "4.972948"], ["84113.10", "4.068776"], ["84104.60", "5.334617"], ["84096.10", "4.611279"], ["84087.60", "5.063365"], ["84079.10", "4.249610"], ["84062.10", "5.605868"], ["84053.60", "5.153782"], ["84045.10", "5.244199"], ["84036.60", "5.425034"], ["84019.60", "4.882531"], ["83885.98", "0"]], "checksum": 110703150, "ts": "1742142220601"}], "ts": 1742142220606, "record_time": 1742142219.713992}
{"action": "update", "arg": {"instType": "SPOT", "channel": "books", "instId": "BTCUSDT"}, "data": [{"asks": [["84244.23", "0"], ["84244.24", "0"], ["84260.09", "0"], ["84264.51", "0.004844"], ["84269.04", "0.002907"], ["84293.32", "0"], ["84299.42", "0"], ["84301.60", "0.019635"], ["84303.60", "0.051670"], ["84305.60", "0.135974"], ["84307.60", "0.357827"], ["84307.70", "0.001049"], ["84309.90", "0"], ["84311.30", "0.001043"], ["84311.40", "0.025830"], ["84313.20", "0"], ["84314.10", "0"], ["84314.30", "2.349690"], ["84317.00", "0"], ["84321.00", "0"], ["84321.50", "0.258030"], ["84321.60", "0"], ["84325.00", "0.250020"], ["84325.20", "5.338860"], ["84325.70", "0.410370"], ["84349.80", "4.972948"], ["84358.30", "5.244199"], ["84366.80", "4.340027"], ["84375.30", "5.063365"], ["84383.80", "4.159193"], ["84392.30", "5.605868"], ["84400.80", "5.334617"], ["84409.30", "3.887941"], ["84417.80", "5.153782"], ["84426.30", "5.515451"], ["84434.80", "4.701696"], ["84443.30", "4.068776"], ["84451.80", "3.978358"], ["84460.30", "4.430444"], ["84468.80", "4.882531"], ["84477.30", "5.425034"], ["84485.80", "4.792113"], ["84494.30", "4.249610"], ["84502.80", "4.611279"], ["84511.30", "4.520862"], ["84850.00", "0.000031"], ["84851.66", "0.000029"], ["84852.81", "0.000115"], ["84852.94", "0.000065"]], "bids": [["84244.24", "3.690911"], ["84244.23", "0.034300"], ["84244.22", "0.851043"], ["84244.21", "0.353296"], ["84241.30", "0.001137"], ["84239.30", "0.002992"], ["84237.30", "0.007873"], ["84236.60", "0.003037"], ["84235.30", "0.020719"], ["84233.30", "0.054524"], ["84231.77", "0"], ["84231.30", "0.143484"], ["84229.30", "0.377590"], ["84227.30", "0.993659"], ["84225.30", "2.614892"], ["84223.30", "6.881182"], ["84222.40", "0.001010"], ["84222.20", "0"], ["84221.92", "0"], ["84214.80", "1.706520"], ["84214.20", "0.269760"], ["84213.50", "0.030000"], ["84212.80", "0.120000"], ["84211.80", "0.240000"], ["84211.30", "0"], ["84211.20", "0"], ["84210.20", "0"], ["84181.10", "4.701696"], ["84172.60", "4.249610"], ["84167.00", "0"], ["84164.10", "4.068776"], ["84159.95", "0.072042"], ["84155.60", "4.611279"], ["84147.10", "5.153782"], ["84138.60", "4.882531"], ["84130.10", "4.520862"], ["84121.60", "3.978358"], ["84113.10", "4.972948"], ["84104.60", "5.515451"], ["84096.10", "3.887941"], ["84087.60", "5.244199"], ["84079.10", "5.063365"], ["84070.60", "4.792113"], ["84062.10", "5.334617"], ["84053.60", "4.340027"], ["84045.10", "5.605868"], ["84036.60", "4.159193"], ["84028.10", "5.425034"], ["84019.60", "4.430444"], ["83887.11", "0"], ["83886.91", "0"]], "checksum": -894938764, "ts": "1742142220802"}], "ts": 1742142220807, "record_time": 1742142219.915492}
{"action": "update", "arg": {"instType": "SPOT", "channel": "books", "instId": "BTCUSDT"}, "data": [{"asks": [["84250.46", "0"], ["84264.51", "0.048809"], ["84268.84", "0"], ["84269.54", "0.209200"], ["84269.91", "0"], ["84271.27", "0"], ["84271.71", "0"], ["84271.79", "0"], ["84271.95", "0"], ["84272.34", "0"], ["84272.93", "0"], ["84273.13", "0"], ["84273.20", "0"], ["84273.52", "0"], ["84273.99", "0"], ["84274.76", "0.035952"], ["84275.01", "0.006356"], ["84275.03", "0"], ["84276.15", "0"], ["84276.28", "0.006356"], ["84276.61", "0.006356"], ["84277.32", "0"], ["84277.35", "0.022784"], ["84277.70", "0.006356"], ["84277.74", "0.006356"], ["84277.83", "0.006356"], ["84277.95", "0"], ["84278.07", "0"], ["84278.79", "0.006356"], ["84278.94", "0.016427"], ["84279.02", "0.006356"], ["84279.19", "0"], ["84279.40", "0.006356"], ["84280.92", "0.006357"], ["84281.56", "0"], ["84282.21", "0"], ["84282.36", "0.119895"], ["84282.58", "0"], ["84282.99", "0.119879"], ["84283.48", "0.119881"], ["84283.59", "0"], ["84283.88", "0.009989"], ["84284.08", "0.015892"], ["84286.86", "0.006356"], ["84287.00", "0.031812"], ["84288.65", "0.015891"], ["84289.06", "0.010986"], ["84289.28", "0.001807"], ["84293.60", "0.001849"], ["84295.60", "0.004867"], ["84297.60", "0.012809"], ["84299.60", "0.033706"], ["84301.60", "0.088701"], ["84303.60", "0.233424"], ["84305.60", "0.614273"], ["84307.60", "1.616507"], ["84309.40", "3.217530"], ["84310.30", "0.445920"], ["84311.30", "0"], ["84311.40", "0.090210"], ["84313.50", "0"], ["84314.30", "0"], ["84315.30", "0.391950"], ["84316.60", "0.142500"], ["84320.00", "0.410370"], ["84321.50", "0"], ["84323.10", "0.106830"], ["84324.20", "0.171750"], ["84324.50", "1.350000"], ["84325.00", "0"], ["84325.20", "0"], ["84325.70", "0"], ["84349.80", "4.792113"], ["84358.30", "5.605868"], ["84366.80", "4.701696"], ["84375.30", "4.882531"], ["84383.80", "5.425034"], ["84392.30", "4.972948"], ["84400.80", "5.244199"], ["84409.30", "4.520862"], ["84417.41", "0"], ["84417.80", "4.249610"], ["84426.30", "4.611279"], ["84434.80", "3.887941"], ["84443.30", "5.515451"], ["84451.80", "4.159193"], ["84460.30", "4.068776"], ["84468.80", "5.334617"], ["84477.30", "4.340027"], ["84485.80", "5.153782"], ["84494.30", "3.978358"], ["84502.80", "4.430444"], ["84511.30", "5.063365"]], "bids": [["84244.24", "3.927421"], ["84244.23", "0.508059"], ["84244.22", "0.299877"], ["84244.20", "0.160395"], ["84241.30", "0.001171"], ["84239.30", "0.003083"], ["84237.30", "0.008112"], ["84235.55", "0"], ["84235.30", "0.021347"], ["84235.05", "0"], ["84233.30", "0.056178"], ["84231.30", "0.147835"], ["84230.95", "0.084477"], ["84230.62", "0.005940"], ["84230.29", "0.016468"], ["84230.27", "0.015778"], ["84230.09", "0"], ["84229.93", "0.018269"], ["84229.30", "0.389041"], ["84229.04", "0.007123"], ["84228.68", "0.017978"], ["84228.07", "0.007937"], ["84227.99", "0.007319"], ["84227.78", "0.017069"], ["84227.59", "0.017340"], ["84227.55", "0.025095"], ["84227.30", "1.023791"], ["84227.29", "0.008168"], ["84227.16", "0.008287"], ["84225.80", "0.052132"], ["84225.60", "0"], ["84225.37", "0"], ["84225.30", "2.694187"], ["84225.28", "0"], ["84225.03", "0"], ["84224.83", "0"], ["84224.23", "0"], ["84224.06", "0.272026"], ["84223.30", "7.089967"], ["84223.27", "0"], ["84223.20", "1.863060"], ["84222.91", "0.076048"], ["84222.82", "0.263450"], ["84222.80", "0"], ["84222.66", "0.222834"], ["84222.58", "0"], ["84222.38", "0.021118"], ["84221.91", "0"], ["84221.74", "0"], ["84221.70", "0.274590"], ["84221.47", "0"], ["84221.31", "0.012445"], ["84221.28", "0"], ["84220.70", "0.970590"], ["84219.56", "0.073539"], ["84219.29", "0"], ["84219.02", "0"], ["84218.28", "0.056665"], ["84218.02", "0"], ["84217.63", "0"], ["84217.00", "2.350080"], ["84216.90", "0.408810"], ["84216.08", "0"], ["84216.02", "0"], ["84215.60", "0.030000"], ["84215.49", "0"], ["84214.20", "0"], ["84213.50", "0"], ["84213.12", "0"], ["84212.80", "0"], ["84212.10", "0.669930"], ["84212.00", "0.021600"], ["84211.90", "0"], ["84211.82", "0"], ["84211.80", "0"], ["84211.30", "0.090000"], ["84181.10", "4.520862"], ["84172.60", "5.153782"], ["84164.10", "5.244199"], ["84159.95", "0"], ["84155.60", "4.068776"], ["84147.10", "4.792113"], ["84138.60", "5.334617"], ["84130.10", "4.249610"], ["84121.60", "4.430444"], ["84113.10", "5.515451"], ["84104.60", "4.882531"], ["84096.10", "4.340027"], ["84087.60", "4.972948"], ["84079.10", "4.159193"], ["84070.60", "3.978358"], ["84062.10", "5.605868"], ["84053.60", "5.425034"], ["84045.10", "3.887941"], ["84036.60", "5.063365"], ["84028.10", "4.701696"], ["84019.60", "4.611279"], ["83887.11", "0.000075"], ["83886.91", "0.000145"], ["83885.98", "0.000018"], ["83885.71", "0.000069"], ["83884.62", "0.000014"]], "checksum": -83049903, "ts": "1742142221010"}], "ts": 1742142221015, "record_time": 1742142220.123505}
{"action": "update", "arg": {"instType": "SPOT", "channel": "books", "instId": "BTCUSDT"}, "data": [{"asks": [["84244.25", "0"], ["84244.27", "0.000100"], ["84244.28", "0.000100"], ["84244.29", "0.000100"], ["84250.22", "0.063835"], ["84268.81", "0.005326"], ["84268.83", "0"], ["84272.83", "0"], ["84277.58", "0.010985"], ["84293.60", "0.001007"], ["84295.60", "0.001058"], ["84297.60", "0.002786"], ["84299.60", "0.007331"], ["84301.60", "0.019293"], ["84303.60", "0.050771"], ["84305.60", "0.133606"], ["84307.60", "0.351596"], ["84309.40", "3.217950"], ["84312.30", "0.306360"], ["84313.10", "0.258030"], ["84313.50", "0.633480"], ["84315.30", "0.056520"], ["84318.10", "0.568440"], ["84320.00", "0"], ["84321.00", "0.985470"], ["84323.60", "0"], ["84324.20", "0"], ["84324.50", "0"], ["84349.80", "5.605868"], ["84358.30", "4.701696"], ["84366.80", "4.972948"], ["84375.30", "4.340027"], ["84383.80", "4.520862"], ["84392.30", "4.159193"], ["84400.80", "4.068776"], ["84409.30", "5.425034"], ["84426.30", "3.978358"], ["84434.80", "5.153782"], ["84443.30", "5.244199"], ["84451.80", "5.063365"], ["84460.30", "4.611279"], ["84477.30", "4.882531"], ["84485.80", "4.430444"], ["84494.30", "3.887941"], ["84502.80", "5.515451"], ["84511.30", "4.792113"], ["84851.66", "0"], ["84852.81", "0"], ["84852.94", "0"]], "bids": [["84244.25", "3.637109"], ["84244.24", "0.898608"], ["84244.23", "0.034300"], ["84244.22", "0"], ["84244.21", "0.000164"], ["84239.30", "0.002958"], ["84237.30", "0.007783"], ["84235.55", "0.622243"], ["84235.30", "0.020484"], ["84233.30", "0.053905"], ["84231.30", "0.141855"], ["84229.72", "0.056380"], ["84229.30", "0.373303"], ["84227.30", "0.982631"], ["84225.30", "2.585658"], ["84224.98", "0"], ["84223.30", "6.804364"], ["84223.20", "0.755130"], ["84219.30", "2.349990"], ["84217.40", "0.915360"], ["84217.00", "0"], ["84216.60", "0.872880"], ["84215.90", "0.462600"], ["84215.60", "0"], ["84215.40", "1.061130"], ["84213.90", "0.030000"], ["84212.10", "0.286440"], ["84212.00", "0"], ["84211.50", "0"], ["84211.40", "0"], ["84211.30", "0"], ["84181.10", "4.430444"], ["84172.60", "4.882531"], ["84166.00", "0"], ["84164.10", "4.340027"], ["84147.10", "4.701696"], ["84138.60", "5.244199"], ["84130.10", "5.063365"], ["84121.60", "5.605868"], ["84113.10", "4.520862"], ["84104.60", "5.425034"], ["84096.10", "3.887941"], ["84070.60", "5.515451"], ["84062.10", "4.249610"], ["84053.60", "5.153782"], ["84045.10", "3.978358"], ["84036.60", "4.611279"], ["84028.10", "5.334617"], ["84019.60", "4.792113"], ["83884.55", "0.000048"]], "checksum": 832301043, "ts": "1742142221222"}], "ts": 1742142221228, "record_time": 1742142220.3358}
{"action": "update", "arg": {"instType": "SPOT", "channel": "books", "instId": "BTCUSDT"}, "data": [{"asks": [["84244.26", "0"], ["84244.27", "0"], ["84244.28", "0"], ["84244.29", "0"], ["84250.22", "0"], ["84255.26", "0"], ["84255.32", "0"], ["84255.33", "0"], ["84255.34", "0"], ["84255.36", "0"], ["84255.41", "0"], ["84255.42", "0"], ["84255.44", "0"], ["84255.45", "0"], ["84256.24", "0"], ["84256.26", "0"], ["84256.27", "0"], ["84256.28", "0"], ["84256.29", "0"], ["84256.31", "0"], ["84256.32", "0"], ["84256.33", "0"], ["84256.34", "0"], ["84259.74", "0"], ["84264.50", "1.086300"], ["84264.51", "0"], ["84264.52", "0.054331"], ["84264.70", "0.004595"], ["84264.74", "0.010074"], ["84264.79", "0.001230"], ["84264.81", "0.005541"], ["84264.84", "0.000245"], ["84264.86", "0.004974"], ["84264.88", "0.008962"], ["84264.89", "0.001066"], ["84264.91", "0.006307"], ["84265.87", "0.007385"], ["84265.88", "0.013581"], ["84265.89", "0.002001"], ["84265.90", "0.016133"], ["84265.91", "0.017712"], ["84265.93", "0.011849"], ["84268.81", "0"], ["84269.39", "0"], ["84269.54", "0"], ["84269.61", "0"], ["84270.50", "0.080382"], ["84271.23", "0"], ["84271.36", "0"], ["84274.11", "0"], ["84274.76", "0"], ["84275.01", "0"], ["84275.50", "0"], ["84276.26", "0"], ["84276.28", "0"], ["84276.61", "0"], ["84276.72", "0"], ["84276.88", "0"], ["84276.92", "0"], ["84277.35", "0"], ["84277.58", "0"], ["84277.70", "0"], ["84277.74", "0"], ["84277.83", "0"], ["84278.09", "0"], ["84278.33", "0.119869"], ["84278.62", "0"], ["84278.79", "0"], ["84278.94", "0"], ["84279.02", "0"], ["84279.40", "0"], ["84279.72", "0.006356"], ["84280.10", "0"], ["84280.72", "0.001205"], ["84280.92", "0"], ["84282.29", "0.035952"], ["84282.36", "0"], ["84282.81", "0.010985"], ["84282.99", "0"], ["84283.88", "0"], ["84284.08", "0"], ["84284.16", "0.006356"], ["84284.54", "0.006356"], ["84284.64", "0.119843"], ["84284.76", "0.006356"], ["84285.05", "0.010984"], ["84285.24", "0.006356"], ["84286.39", "0.009989"], ["84286.46", "0"], ["84286.51", "0.006356"], ["84286.55", "0.016428"], ["84287.00", "0"], ["84287.60", "0"], ["84287.99", "0.006356"], ["84288.45", "0.006357"], ["84289.60", "0"], ["84290.17", "0.119879"], ["84291.60", "0"], ["84293.60", "0"], ["84295.00", "0.001018"], ["84295.60", "0"], ["84297.00", "0.001023"], ["84297.60", "0"], ["84299.00", "0.001025"], ["84299.60", "0"], ["84301.00", "0.001003"], ["84301.60", "0"], ["84303.00", "0.001028"], ["84303.60", "0"], ["84305.00", "0.001049"], ["84305.60", "0"], ["84307.00", "0.001985"], ["84307.60", "0"], ["84307.70", "0"], ["84307.90", "0"], ["84308.30", "0"], ["84309.00", "0.005225"], ["84309.40", "0"], ["84310.30", "0"], ["84311.00", "0.013749"], ["84311.40", "0"], ["84312.30", "0"], ["84313.00", "0.036181"], ["84313.10", "0"], ["84313.50", "0"], ["84315.00", "0.095213"], ["84315.30", "0.003750"], ["84315.40", "0.107040"], ["84315.60", "0.001007"], ["84315.70", "0"], ["84316.10", "0"], ["84316.60", "0"], ["84318.10", "0"], ["84318.50", "0.015150"], ["84318.90", "0.015150"], ["84320.40", "0"], ["84320.70", "0.711570"], ["84321.00", "0"], ["84321.10", "0.323370"], ["84322.40", "1.023240"], ["84323.00", "3.694380"], ["84323.10", "0"], ["84323.60", "0.177960"], ["84325.00", "0.250020"], ["84325.70", "0.410370"], ["84325.90", "0.014040"], ["84327.40", "0.117000"], ["84328.10", "0.180000"], ["84328.60", "1.748790"], ["84328.90", "1.183470"], ["84329.00", "0.090000"], ["84329.40", "0.142500"], ["84329.70", "2.669430"], ["84329.90", "1.779300"], ["84330.40", "0.009000"], ["84331.00", "0.025350"], ["84331.40", "1.005900"], ["84349.80", "0"], ["84357.10", "4.610876"], ["84358.30", "0"], ["84365.60", "4.339648"], ["84366.80", "0"], ["84374.10", "4.068420"], ["84375.30", "0"], ["84382.60", "5.424560"], ["84383.80", "0"], ["84391.10", "3.978010"], ["84392.30", "0"], ["84399.60", "3.887601"], ["84400.80", "0"], ["84408.10", "5.514969"], ["84409.30", "0"], ["84416.60", "5.243741"], ["84417.41", "0.209200"], ["84417.80", "0"], ["84425.10", "4.430057"], ["84426.30", "0"], ["84433.60", "4.520466"], ["84434.80", "0"], ["84442.10", "5.153332"], ["84443.30", "0"], ["84450.60", "4.882104"], ["84451.80", "0"], ["84459.10", "5.062922"], ["84460.30", "0"], ["84467.60", "5.605378"], ["84468.80", "0"], ["84476.10", "4.972513"], ["84477.30", "0"], ["84484.60", "4.701285"], ["84485.80", "0"], ["84493.10", "4.158829"], ["84494.30", "0"], ["84501.60", "5.334150"], ["84502.80", "0"], ["84510.10", "4.249238"], ["84511.30", "0"], ["84518.60", "4.791694"], ["84851.66", "0.000029"], ["84852.81", "0.000115"], ["84852.94", "0.000065"], ["84853.56", "0.000050"], ["84857.14", "0.000347"], ["84858.75", "0.000285"], ["84859.29", "0.000036"], ["84860.00", "0.000169"], ["84862.90", "0.000169"], ["84864.69", "0.000052"], ["84864.86", "0.000041"], ["84864.99", "0.000033"], ["84866.10", "0.000064"], ["84866.40", "0.000018"], ["84867.80", "0.000095"], ["84868.42", "0.000031"], ["84868.52", "0.000013"], ["84868.65", "0.000035"], ["84869.57", "0.000932"], ["84871.66", "0.000078"], ["84871.79", "0.000014"], ["84873.84", "0.000057"], ["84874.79", "0.000096"], ["84875.00", "0.000959"]], "bids": [["84252.67", "0.209200"], ["84250.60", "0.001030"], ["84248.60", "0.001060"], ["84248.47", "0.203170"], ["84246.60", "0.002791"], ["84244.60", "0.007345"], ["84244.25", "2.714385"], ["84244.24", "0.353132"], ["84244.23", "0"], ["84244.21", "0"], ["84244.20", "0.140395"], ["84243.30", "0"], ["84242.60", "0.019328"], ["84241.30", "0"], ["84240.60", "0.050864"], ["84239.62", "0.001230"], ["84239.58", "0.008538"], ["84239.57", "0.000213"], ["84239.56", "0.007513"], ["84239.54", "0.006487"], ["84239.46", "0.007641"], ["84239.30", "0"], ["84238.60", "0.133851"], ["84238.48", "0.084477"], ["84237.84", "0.007344"], ["84237.77", "0.008986"], ["84237.75", "0.008555"], ["84237.70", "0.006213"], ["84237.68", "0.007442"], ["84237.48", "0.016468"], ["84237.30", "0"], ["84237.04", "0.248115"], ["84236.92", "0.008147"], ["84236.85", "0.006568"], ["84236.83", "0.028821"], ["84236.64", "0.002062"], ["84236.60", "0.349202"], ["84236.43", "0.007871"], ["84236.06", "0.007123"], ["84235.52", "0.007319"], ["84235.43", "0.007950"], ["84235.42", "0.007474"], ["84235.30", "0"], ["84235.05", "0.060124"], ["84235.00", "0.025095"], ["84234.95", "0.056380"], ["84234.77", "0.017340"], ["84234.69", "0.008287"], ["84234.60", "0.926945"], ["84233.30", "0"], ["84233.24", "0.227777"], ["84232.60", "2.439329"], ["84232.47", "0.004935"], ["84232.46", "0.005552"], ["84232.39", "0.005088"], ["84232.36", "0.000875"], ["84232.33", "0.017784"], ["84231.30", "0"], ["84230.95", "0"], ["84230.66", "0.008674"], ["84230.62", "0"], ["84230.60", "6.419288"], ["84230.38", "0.010234"], ["84230.29", "0"], ["84230.27", "0"], ["84230.25", "0"], ["84230.22", "0"], ["84230.21", "0"], ["84230.18", "0"], ["84230.16", "0"], ["84230.08", "0"], ["84229.94", "0.018528"], ["84229.93", "0"], ["84229.91", "0.021118"], ["84229.84", "0.298882"], ["84229.80", "0.071280"], ["84229.72", "0"], ["84229.56", "0"], ["84229.50", "0.001008"], ["84229.40", "0.282840"], ["84229.30", "0"], ["84229.04", "0"], ["84229.00", "0.001049"], ["84228.97", "0"], ["84228.90", "0.035580"], ["84228.74", "0"], ["84228.70", "0"], ["84228.68", "0"], ["84228.65", "0"], ["84228.59", "0"], ["84228.56", "0"], ["84228.55", "0"], ["84228.41", "0"], ["84228.07", "0"], ["84227.99", "0"], ["84227.80", "0.069600"], ["84227.78", "0"], ["84227.64", "0"], ["84227.59", "0"], ["84227.55", "0"], ["84227.51", "0"], ["84227.50", "0.274590"], ["84227.42", "0"], ["84227.30", "0"], ["84227.29", "0"], ["84227.17", "0"], ["84227.16", "0"], ["84227.10", "4.191660"], ["84227.00", "1.510800"], ["84226.70", "0"], ["84226.40", "0.280500"], ["84226.00", "0"], ["84225.98", "0"], ["84225.90", "1.721430"], ["84225.80", "0.212100"], ["84225.40", "0.915360"], ["84225.33", "0"], ["84225.30", "0"], ["84224.50", "0.064950"], ["84224.06", "0"], ["84223.90", "0.013140"], ["84223.80", "2.957850"], ["84223.30", "5.246790"], ["84223.20", "0.177960"], ["84223.14", "0"], ["84223.10", "0"], ["84223.06", "0"], ["84223.01", "0"], ["84222.97", "0"], ["84222.91", "0"], ["84222.90", "0"], ["84222.84", "0"], ["84222.66", "0"], ["84222.40", "0"], ["84222.38", "0"], ["84221.70", "0"], ["84221.60", "0"], ["84221.48", "0"], ["84221.33", "0"], ["84220.70", "0.114120"], ["84220.44", "0"], ["84219.40", "0.142500"], ["84219.30", "0"], ["84218.80", "0.072480"], ["84217.40", "0"], ["84216.90", "0"], ["84216.50", "0"], ["84216.30", "0.410370"], ["84215.90", "0"], ["84215.40", "0"], ["84215.00", "0.030000"], ["84214.80", "1.528560"], ["84213.90", "0"], ["84213.82", "0.008206"], ["84213.20", "0"], ["84213.00", "0"], ["84212.30", "0"], ["84212.10", "0"], ["84209.15", "0.007181"], ["84209.06", "0.007582"], ["84204.45", "0"], ["84200.05", "0"], ["84199.86", "0"], ["84188.50", "4.430057"], ["84181.10", "0"], ["84180.00", "5.334150"], ["84172.60", "0"], ["84171.50", "5.243741"], ["84164.10", "0"], ["84163.00", "4.520466"], ["84160.36", "0.072042"], ["84155.60", "0"], ["84154.50", "3.887601"], ["84147.10", "0"], ["84146.00", "4.249238"], ["84138.60", "0"], ["84137.50", "3.978010"], ["84130.10", "0"], ["84129.00", "4.882104"], ["84121.60", "0"], ["84120.50", "5.605378"], ["84113.10", "0"], ["84112.00", "4.701285"], ["84104.60", "0"], ["84103.50", "4.339648"], ["84096.10", "0"], ["84095.00", "4.158829"], ["84087.60", "0"], ["84086.50", "5.062922"], ["84079.10", "0"], ["84078.00", "4.068420"], ["84070.60", "0"], ["84069.50", "4.791694"], ["84062.10", "0"], ["84061.00", "5.514969"], ["84053.60", "0"], ["84052.50", "4.972513"], ["84045.10", "0"], ["84044.00", "4.610876"], ["84036.60", "0"], ["84035.50", "5.424560"], ["84028.10", "0"], ["84027.00", "5.153332"], ["84019.60", "0"], ["83884.30", "0.000161"], ["83882.98", "0.000188"], ["83882.92", "0.002384"], ["83881.99", "0.000038"], ["83880.00", "0.020454"], ["83877.97", "0.000023"], ["83877.55", "0.000010"], ["83877.42", "0.000054"]], "checksum": 1753310410, "ts": "1742142221426"}], "ts": 1742142221432, "record_time": 1742142220.540808}
{"action": "update", "arg": {"instType": "SPOT", "channel": "books", "instId": "BTCUSDT"}, "data": [{"asks": [["84264.49", "1.086300"], ["84264.50", "0"], ["84274.84", "0.003017"], ["84276.24", "0.001827"], ["84277.79", "0.200292"], ["84279.17", "0"], ["84280.86", "0"], ["84282.36", "0.006356"], ["84283.47", "0.006356"], ["84283.54", "0.006356"], ["84283.70", "0"], ["84284.80", "0.006356"], ["84285.36", "0.006356"], ["84285.97", "0.006356"], ["84286.40", "0.016427"], ["84286.53", "0.006356"], ["84286.86", "0"], ["84286.94", "0.006356"], ["84289.28", "0"], ["84289.55", "0.119895"], ["84291.02", "0.015892"], ["84291.34", "0.017801"], ["84291.42", "0.009989"], ["84293.40", "0.006356"], ["84295.77", "0"], ["84295.85", "0.001807"], ["84297.00", "0.075000"], ["84307.00", "0.001845"], ["84309.00", "0.004853"], ["84309.55", "0.031812"], ["84311.00", "0.012771"], ["84313.00", "0.033608"], ["84313.59", "0.026414"], ["84315.00", "0.088443"], ["84315.40", "0.001035"], ["84317.30", "0"], ["84318.50", "0"], ["84318.90", "0"], ["84320.70", "0"], ["84321.10", "0"], ["84322.40", "0"], ["84323.00", "0"], ["84323.60", "0"], ["84324.50", "3.203730"], ["84324.70", "0.015060"], ["84325.00", "0.178860"], ["84325.70", "0"], ["84325.90", "0.029190"], ["84326.30", "0.015090"], ["84327.40", "0"], ["84327.80", "0.258030"], ["84328.10", "0"], ["84328.60", "0.481920"], ["84328.90", "0"], ["84329.00", "0"], ["84329.70", "0"], ["84329.90", "0"], ["84330.00", "0.469080"], ["84331.40", "0"], ["84331.70", "3.422070"], ["84332.80", "0.248880"], ["84332.90", "0.261000"], ["84333.80", "2.669430"], ["84334.50", "0.012420"], ["84334.80", "0.180000"], ["84335.40", "0.010650"], ["84353.39", "0"], ["84353.57", "0"], ["84357.10", "4.791694"], ["84365.60", "5.062922"], ["84374.10", "5.334150"], ["84379.96", "0.072042"], ["84380.39", "0.072042"], ["84382.60", "4.701285"], ["84391.10", "4.249238"], ["84399.60", "5.605378"], ["84408.10", "4.339648"], ["84416.60", "4.068420"], ["84433.60", "3.887601"], ["84442.10", "5.243741"], ["84450.60", "4.972513"], ["84459.10", "5.514969"], ["84467.60", "5.153332"], ["84476.10", "4.158829"], ["84484.60", "4.520466"], ["84493.10", "3.978010"], ["84501.60", "4.610876"], ["84510.10", "5.424560"], ["84518.60", "4.882104"], ["84868.42", "0"], ["84868.52", "0"], ["84868.65", "0"], ["84869.57", "0"], ["84871.66", "0"], ["84871.79", "0"], ["84873.84", "0"], ["84874.79", "0"], ["84875.00", "0"]], "bids": [["84264.48", "0.418400"], ["84261.31", "0.647400"], ["84256.89", "0.203170"], ["84252.68", "0.220372"], ["84252.67", "0.418560"], ["84248.60", "0.001733"], ["84248.48", "0.060951"], ["84248.47", "0"], ["84246.60", "0.004561"], ["84244.60", "0.012003"], ["84244.26", "0.014965"], ["84244.25", "0.541750"], ["84244.20", "0.000356"], ["84242.60", "0.031586"], ["84242.19", "0.003070"], ["84240.73", "0"], ["84240.60", "0.083122"], ["84238.60", "0.218741"], ["84237.80", "0.005940"], ["84237.71", "0.017844"], ["84237.49", "0.001199"], ["84237.43", "0.018269"], ["84237.20", "0.015778"], ["84236.60", "0.575496"], ["84236.43", "0.024957"], ["84236.21", "0.008992"], ["84235.54", "0"], ["84235.31", "0.017069"], ["84235.25", "0.007937"], ["84234.79", "0.008168"], ["84234.62", "0"], ["84234.60", "1.514465"], ["84233.22", "0.012655"], ["84232.98", "0.052132"], ["84232.60", "3.985433"], ["84232.29", "0.002950"], ["84231.24", "0.272025"], ["84230.60", "10.487982"], ["84229.80", "0.070230"], ["84229.40", "0.282210"], ["84229.00", "0"], ["84227.84", "0.012443"], ["84227.80", "1.718040"], ["84227.50", "0"], ["84227.10", "0"], ["84225.90", "1.510800"], ["84225.40", "0"], ["84223.80", "2.496090"], ["84223.30", "3.039690"], ["84221.90", "0.410370"], ["84221.31", "0"], ["84220.70", "0.213720"], ["84220.40", "0.030000"], ["84218.40", "0.090000"], ["84218.20", "0.120000"], ["84217.70", "0.060000"], ["84217.50", "0.090000"], ["84216.50", "0.090000"], ["84216.30", "0"], ["84215.00", "0"], ["84214.80", "0"], ["84210.71", "0.017801"], ["84198.80", "0"], ["84180.00", "4.068420"], ["84171.50", "3.978010"], ["84169.00", "0.012838"], ["84163.00", "5.153332"], ["84154.50", "4.520466"], ["84146.00", "4.791694"], ["84137.50", "4.610876"], ["84129.00", "5.605378"], ["84120.50", "5.062922"], ["84112.00", "4.158829"], ["84103.50", "3.887601"], ["84095.00", "5.334150"], ["84086.50", "4.882104"], ["84078.00", "4.701285"], ["84069.50", "5.514969"], ["84061.00", "5.424560"], ["84044.00", "5.243741"], ["84035.50", "4.339648"], ["84027.00", "4.249238"], ["83992.38", "0"], ["83887.29", "0"], ["83887.11", "0"], ["83886.91", "0"], ["83885.98", "0"], ["83885.71", "0"], ["83884.62", "0"], ["83884.55", "0"], ["83884.30", "0"], ["83882.98", "0"], ["83882.92", "0"], ["83881.99", "0"], ["83880.00", "0"], ["83877.97", "0"], ["83877.55", "0"], ["83877.42", "0"]], "checksum": -1190743348, "ts": "1742142221629"}], "ts": 1742142221633, "record_time": 1742142220.741111}
{"action": "update", "arg": {"instType": "SPOT", "channel": "books", "instId": "BTCUSDT"}, "data": [{"asks": [["84264.49", "0"], ["84264.52", "0"], ["84264.70", "0"], ["84264.74", "0"], ["84264.79", "0"], ["84264.81", "0"], ["84264.84", "0"], ["84264.86", "0"], ["84264.88", "0"], ["84264.89", "0"], ["84264.91", "0"], ["84265.87", "0"], ["84265.88", "0"], ["84265.89", "0"], ["84265.90", "0"], ["84265.91", "0"], ["84265.93", "0"], ["84268.82", "0"], ["84269.04", "0"], ["84270.50", "0"], ["84274.14", "0.004595"], ["84274.20", "0.010074"], ["84274.24", "0.005541"], ["84274.25", "0.001230"], ["84274.29", "0.011281"], ["84274.30", "0.000245"], ["84274.31", "0.008962"], ["84274.32", "0.001066"], ["84274.69", "0.030015"], ["84275.29", "0.001923"], ["84275.30", "0.008506"], ["84275.31", "0.008398"], ["84275.33", "0.012568"], ["84275.34", "0.010353"], ["84275.35", "0.007705"], ["84275.36", "0.019208"], ["84275.73", "0.140036"], ["84277.79", "0"], ["84278.33", "0"], ["84279.72", "0"], ["84280.59", "0.080382"], ["84280.72", "0"], ["84282.29", "0"], ["84282.36", "0"], ["84282.41", "0.002907"], ["84282.81", "0"], ["84283.47", "0.086644"], ["84283.48", "0"], ["84283.54", "0"], ["84284.16", "0"], ["84284.54", "0"], ["84284.64", "0"], ["84284.76", "0"], ["84284.80", "0"], ["84285.05", "0"], ["84285.24", "0"], ["84285.36", "0"], ["84285.97", "0"], ["84286.39", "0"], ["84286.40", "0"], ["84286.51", "0"], ["84286.53", "0"], ["84286.55", "0"], ["84286.94", "0"], ["84287.99", "0"], ["84288.42", "0.119869"], ["84288.45", "0"], ["84288.55", "0.001205"], ["84288.65", "0"], ["84288.97", "1.895076"], ["84289.06", "0"], ["84289.28", "0.134692"], ["84289.29", "0"], ["84289.55", "0"], ["84289.68", "0.035952"], ["84289.75", "0.006356"], ["84289.81", "0.006356"], ["84290.17", "0"], ["84291.02", "0"], ["84291.30", "0.006356"], ["84291.37", "0.006356"], ["84291.42", "0"], ["84291.98", "0.006356"], ["84292.21", "0.010985"], ["84292.37", "0.006356"], ["84292.59", "0.006356"], ["84292.62", "0.006356"], ["84292.63", "0.006356"], ["84292.75", "0.006356"], ["84293.24", "0.016428"], ["84293.40", "0"], ["84293.63", "0.006356"], ["84293.79", "0.016427"], ["84293.80", "0.006356"], ["84293.92", "0.006356"], ["84294.21", "0.012680"], ["84294.34", "0.006356"], ["84294.72", "0.119843"], ["84295.00", "0"], ["84295.14", "0.006357"], ["84295.58", "0.010984"], ["84295.82", "0.006356"], ["84295.85", "0"], ["84296.72", "0.119895"], ["84296.92", "0.009989"], ["84297.18", "0.119879"], ["84298.40", "0.119881"], ["84298.80", "0.009989"], ["84298.85", "0.015892"], ["84299.00", "0"], ["84301.00", "0"], ["84301.22", "0.006356"], ["84302.82", "0.001807"], ["84303.00", "0"], ["84303.57", "0.015891"], ["84304.07", "0.010986"], ["84304.50", "0.001013"], ["84305.00", "0"], ["84305.83", "2.229014"], ["84306.50", "0.001006"], ["84307.00", "0"], ["84308.39", "0.010000"], ["84308.50", "0.001016"], ["84309.00", "0"], ["84309.32", "0"], ["84309.55", "0"], ["84310.50", "0.001046"], ["84310.59", "0"], ["84311.00", "0"], ["84312.50", "0.001045"], ["84313.00", "0"], ["84313.59", "0"], ["84314.50", "0.001002"], ["84315.00", "0"], ["84315.30", "0"], ["84315.40", "0"], ["84315.60", "0"], ["84316.50", "0.001004"], ["84318.50", "0.001041"], ["84320.50", "0.001050"], ["84321.90", "0"], ["84322.50", "0.001029"], ["84324.50", "0.001042"], ["84324.60", "0.001026"], ["84324.70", "0.001032"], ["84325.00", "0.179910"], ["84325.20", "0.001043"], ["84325.90", "0.014250"], ["84326.30", "0"], ["84326.60", "0.053550"], ["84326.85", "0.001597"], ["84327.80", "0"], ["84328.14", "0.001597"], ["84328.60", "0"], ["84329.40", "0"], ["84330.00", "0.002000"], ["84331.00", "0"], ["84331.70", "0.493830"], ["84331.90", "0.258030"], ["84332.30", "0.446610"], ["84332.50", "0.732840"], ["84332.80", "0"], ["84332.90", "0.009000"], ["84333.10", "0.015150"], ["84333.80", "0"], ["84334.00", "0.015090"], ["84334.60", "0.015090"], ["84334.80", "0"], ["84335.40", "0"], ["84335.50", "1.149810"], ["84335.80", "0.142500"], ["84338.70", "2.669430"], ["84338.90", "0.009000"], ["84339.10", "2.333850"], ["84339.90", "3.694380"], ["84340.60", "0.315000"], ["84340.70", "0.090000"], ["84357.10", "0"], ["84365.60", "0"], ["84366.60", "4.067963"], ["84374.10", "0"], ["84375.10", "4.429560"], ["84382.60", "0"], ["84383.60", "4.248761"], ["84391.10", "0"], ["84392.10", "5.604749"], ["84399.60", "0"], ["84400.60", "4.519959"], ["84408.10", "0"], ["84409.10", "5.152754"], ["84416.60", "0"], ["84417.60", "5.514350"], ["84425.10", "0"], ["84425.84", "0.209200"], ["84426.10", "4.700757"], ["84433.60", "0"], ["84434.60", "5.243152"], ["84442.10", "0"], ["84443.10", "5.423951"], ["84450.60", "0"], ["84451.60", "4.339161"], ["84459.10", "0"], ["84460.10", "4.791156"], ["84467.60", "0"], ["84468.60", "4.610358"], ["84476.10", "0"], ["84477.10", "5.333551"], ["84484.60", "0"], ["84485.60", "3.887165"], ["84493.10", "0"], ["84494.10", "3.977564"], ["84501.60", "0"], ["84502.60", "4.971955"], ["84510.10", "0"], ["84511.10", "4.881556"], ["84518.60", "0"], ["84519.60", "4.158362"], ["84528.10", "5.062354"], ["84864.69", "0"], ["84864.86", "0"], ["84864.99", "0"], ["84866.10", "0"], ["84866.40", "0"], ["84867.80", "0"]], "bids": [["84270.56", "0.035500"], ["84264.48", "0.700092"], ["84262.51", "0.140027"], ["84261.32", "0.194220"], ["84261.31", "0"], ["84260.10", "0.001036"], ["84258.10", "0.001476"], ["84256.90", "0.060951"], ["84256.89", "0"], ["84256.10", "0.003883"], ["84254.10", "0.010218"], ["84252.69", "0.191680"], ["84252.68", "0.047500"], ["84252.67", "0.209200"], ["84252.11", "0.186201"], ["84252.10", "0.026891"], ["84251.65", "0.313259"], ["84250.60", "0"], ["84250.35", "0.003037"], ["84250.10", "0.070764"], ["84249.04", "0.001230"], ["84249.02", "0.000213"], ["84249.01", "0.007513"], ["84249.00", "0.008538"], ["84248.96", "0.006487"], ["84248.91", "0.007641"], ["84248.60", "0"], ["84248.48", "0"], ["84248.10", "0.186223"], ["84247.27", "0.007344"], ["84247.23", "0.008986"], ["84247.21", "0.008556"], ["84247.19", "0.006535"], ["84247.17", "0.006213"], ["84247.15", "0.007442"], ["84247.12", "0.248073"], ["84246.60", "0"], ["84246.38", "0.008147"], ["84246.10", "0.490060"], ["84245.98", "0.002062"], ["84245.86", "0.084457"], ["84245.76", "0.007871"], ["84245.62", "0.005939"], ["84245.30", "0.016464"], ["84245.09", "0.017839"], ["84245.02", "0.015774"], ["84244.86", "0.007950"], ["84244.84", "0.007474"], ["84244.81", "0.018265"], ["84244.67", "0.006566"], ["84244.60", "0"], ["84244.35", "0.056367"], ["84244.26", "0.032047"], ["84244.25", "0.529880"], ["84244.20", "0"], ["84244.10", "1.289630"], ["84243.88", "0.007121"], ["84243.53", "0.028814"], ["84243.32", "0.227723"], ["84243.07", "0.007935"], ["84242.90", "0.016308"], ["84242.69", "0.017065"], ["84242.60", "0"], ["84242.59", "0.017336"], ["84242.38", "0.025089"], ["84242.19", "0"], ["84242.18", "0.008166"], ["84242.10", "3.393764"], ["84241.92", "0.005554"], ["84241.89", "0.004935"], ["84241.82", "0.000875"], ["84241.80", "0.005088"], ["84241.79", "0.008149"], ["84241.74", "0.009635"], ["84241.38", "0.008285"], ["84241.31", "0.197876"], ["84241.05", "0.012652"], ["84240.81", "0.052119"], ["84240.60", "0"], ["84240.46", "0.018524"], ["84240.10", "8.930957"], ["84240.07", "0.011624"], ["84240.00", "0.287730"], ["84239.84", "0.010234"], ["84239.70", "0.448590"], ["84239.62", "0"], ["84239.58", "0"], ["84239.57", "0"], ["84239.56", "0"], ["84239.54", "0"], ["84239.46", "0"], ["84239.40", "2.349450"], ["84239.30", "0.177960"], ["84238.60", "0.142500"], ["84238.48", "0"], ["84238.41", "0.271960"], ["84238.40", "0.035580"], ["84237.84", "0"], ["84237.80", "0.069600"], ["84237.77", "0"], ["84237.75", "0"], ["84237.73", "0.263387"], ["84237.71", "0"], ["84237.70", "0"], ["84237.68", "0"], ["84237.67", "0.076030"], ["84237.49", "0"], ["84237.48", "0"], ["84237.43", "0"], ["84237.29", "0.021113"], ["84237.20", "0"], ["84237.04", "0"], ["84236.92", "0"], ["84236.85", "0.222780"], ["84236.83", "0"], ["84236.64", "0"], ["84236.60", "0"], ["84236.43", "0"], ["84236.21", "0"], ["84236.20", "1.210920"], ["84236.06", "0"], ["84235.80", "0.069600"], ["84235.66", "0.012442"], ["84235.55", "0"], ["84235.52", "0"], ["84235.43", "0"], ["84235.42", "0"], ["84235.31", "0"], ["84235.25", "0"], ["84235.04", "0"], ["84235.00", "0"], ["84234.95", "0"], ["84234.79", "0"], ["84234.77", "0"], ["84234.69", "0"], ["84234.60", "0"], ["84234.47", "0.073527"], ["84233.30", "0.013140"], ["84233.29", "0.056651"], ["84233.24", "0"], ["84233.22", "0"], ["84232.98", "0"], ["84232.60", "0"], ["84232.47", "0"], ["84232.46", "0"], ["84232.39", "0"], ["84232.36", "0"], ["84232.33", "0"], ["84232.29", "0"], ["84232.10", "0.021720"], ["84231.24", "0"], ["84231.20", "0.269760"], ["84230.70", "1.625700"], ["84230.66", "0"], ["84230.60", "1.119540"], ["84230.38", "0"], ["84229.94", "0"], ["84229.91", "0"], ["84229.84", "0"], ["84229.80", "0.069600"], ["84229.50", "0"], ["84229.40", "0"], ["84228.90", "0"], ["84228.40", "0.383490"], ["84227.90", "0.410370"], ["84227.84", "0"], ["84227.80", "0.069600"], ["84227.20", "0.120000"], ["84227.00", "2.565060"], ["84226.60", "0.090000"], ["84226.40", "0"], ["84226.20", "0.060000"], ["84225.00", "2.759430"], ["84224.80", "0.090000"], ["84224.60", "0.240000"], ["84224.50", "0.094950"], ["84224.10", "2.488920"], ["84224.00", "2.669430"], ["84223.90", "0"], ["84223.80", "1.419600"], ["84223.30", "1.510800"], ["84223.23", "0.008206"], ["84223.20", "0"], ["84222.82", "0"], ["84221.90", "0"], ["84221.80", "0"], ["84220.70", "0"], ["84220.40", "0"], ["84219.80", "0"], ["84219.56", "0"], ["84219.40", "0"], ["84218.80", "0"], ["84218.56", "0.007181"], ["84218.47", "0.007582"], ["84218.40", "0"], ["84218.28", "0"], ["84218.20", "0"], ["84217.80", "0"], ["84217.70", "0"], ["84217.57", "0.001190"], ["84217.50", "0"], ["84216.80", "0"], ["84216.60", "0"], ["84216.50", "0"], ["84215.80", "0"], ["84215.10", "0"], ["84213.82", "0"], ["84212.41", "0.001180"], ["84212.10", "0.207047"], ["84209.15", "0"], ["84209.06", "0"], ["84200.04", "0"], ["84198.00", "5.243152"], ["84194.90", "0"], ["84189.50", "4.791156"], ["84188.50", "0"], ["84181.00", "5.604749"], ["84180.00", "0"], ["84172.50", "5.152753"], ["84171.50", "0"], ["84164.00", "4.519959"], ["84163.00", "0"], ["84155.50", "4.700758"], ["84154.50", "0"], ["84147.00", "5.333551"], ["84146.00", "0"], ["84138.50", "5.062354"], ["84137.50", "0"], ["84130.00", "4.067963"], ["84129.00", "0"], ["84121.50", "5.514350"], ["84120.50", "0"], ["84113.00", "3.887165"], ["84112.00", "0"], ["84104.50", "3.977564"], ["84103.50", "0"], ["84096.00", "4.248761"], ["84095.00", "0"], ["84087.50", "4.339161"], ["84086.50", "0"], ["84079.00", "4.158362"], ["84078.00", "0"], ["84070.50", "5.423951"], ["84069.50", "0"], ["84062.00", "4.429560"], ["84061.00", "0"], ["84053.50", "4.610358"], ["84052.50", "0"], ["84045.00", "4.881556"], ["84044.00", "0"], ["84036.50", "4.971955"], ["84035.50", "0"], ["84027.00", "0"], ["84026.10", "0"], ["83888.86", "0"]], "checksum": 777488900, "ts": "1742142221830"}], "ts": 1742142221838, "record_time": 1742142220.947905}
{"action": "update", "arg": {"instType": "SPOT", "channel": "books", "instId": "BTCUSDT"}, "data": [{"asks": [["84274.14", "0.035500"], ["84274.20", "0"], ["84274.24", "0"], ["84274.25", "0"], ["84274.29", "0"], ["84274.30", "0"], ["84274.31", "0"], ["84274.32", "0"], ["84274.68", "0.599900"], ["84274.84", "0"], ["84275.29", "0"], ["84275.30", "0"], ["84275.31", "0"], ["84275.33", "0"], ["84275.34", "0"], ["84275.35", "0"], ["84275.36", "0"], ["84275.73", "0"], ["84276.24", "0"], ["84280.59", "0"], ["84281.95", "0.010074"], ["84282.03", "0.000245"], ["84282.09", "0.001066"], ["84283.05", "0.007385"], ["84283.06", "0.016461"], ["84283.07", "0.000443"], ["84283.09", "0.007627"], ["84283.10", "0.007359"], ["84283.46", "0.025993"], ["84283.47", "0"], ["84286.07", "0.080382"], ["84288.11", "0.003017"], ["84288.41", "0.014847"], ["84288.42", "0"], ["84288.55", "0"], ["84289.28", "0"], ["84289.55", "0.001827"], ["84289.68", "0"], ["84291.00", "0.209200"], ["84292.21", "0"], ["84293.90", "0.119869"], ["84294.03", "0.001205"], ["84295.16", "0.035952"], ["84296.67", "0.010985"], ["84302.82", "0"], ["84304.50", "0"], ["84306.50", "0"], ["84308.39", "0"], ["84308.50", "0"], ["84308.90", "0.001807"], ["84310.50", "0"], ["84312.20", "0.001042"], ["84312.50", "0"], ["84314.20", "0.001022"], ["84314.50", "0"], ["84316.20", "0.001507"], ["84316.50", "0"], ["84317.86", "0.031812"], ["84318.20", "0.003966"], ["84318.50", "0"], ["84320.20", "0.010435"], ["84320.50", "0"], ["84321.86", "0.026414"], ["84322.20", "0.027205"], ["84322.50", "0"], ["84324.20", "0.071593"], ["84324.50", "0"], ["84324.60", "0"], ["84324.70", "0"], ["84325.00", "0"], ["84325.20", "0"], ["84325.90", "0"], ["84326.20", "0.188401"], ["84326.60", "0"], ["84328.20", "0.495793"], ["84330.20", "1.304717"], ["84330.40", "0"], ["84331.70", "0"], ["84331.90", "0"], ["84332.20", "3.433467"], ["84332.30", "0.001001"], ["84332.50", "0.001037"], ["84332.80", "0.001007"], ["84332.90", "0.009210"], ["84333.10", "0.090600"], ["84334.00", "0"], ["84334.50", "0"], ["84334.60", "0"], ["84335.10", "0.258030"], ["84335.50", "0.206430"], ["84338.20", "0.069600"], ["84338.70", "0.469080"], ["84338.90", "0"], ["84339.00", "0.035580"], ["84340.60", "0"], ["84340.70", "1.350000"], ["84341.30", "1.127520"], ["84341.60", "1.794420"], ["84341.90", "0.985470"], ["84342.20", "0.142500"], ["84342.80", "0.015120"], ["84343.20", "0.015120"], ["84343.40", "0.013860"], ["84343.50", "0.025350"], ["84343.60", "0.585900"], ["84344.50", "0.180000"], ["84344.60", "0.035580"], ["84344.70", "0.064110"], ["84345.10", "0.178260"], ["84345.50", "0.135000"], ["84346.20", "0.060000"], ["84346.70", "1.779300"], ["84366.60", "0"], ["84374.30", "5.061888"], ["84375.10", "0"], ["84382.80", "4.157980"], ["84383.60", "0"], ["84391.30", "5.152279"], ["84392.10", "0"], ["84399.80", "5.423452"], ["84400.60", "0"], ["84408.30", "4.429152"], ["84409.10", "0"], ["84416.80", "3.886807"], ["84417.60", "0"], ["84425.30", "5.333061"], ["84426.10", "0"], ["84433.80", "4.971498"], ["84434.27", "0.209200"], ["84434.60", "0"], ["84442.30", "4.338762"], ["84443.10", "0"], ["84450.80", "5.513843"], ["84451.60", "0"], ["84459.30", "4.790716"], ["84460.10", "0"], ["84467.80", "5.604234"], ["84468.60", "0"], ["84476.30", "4.067589"], ["84477.10", "0"], ["84484.80", "4.881107"], ["84485.60", "0"], ["84493.30", "4.609934"], ["84494.10", "0"], ["84501.80", "4.519543"], ["84502.60", "0"], ["84510.30", "5.242670"], ["84511.10", "0"], ["84518.80", "4.700325"], ["84519.60", "0"], ["84527.30", "4.248371"], ["84528.10", "0"], ["84535.80", "3.977198"], ["84859.29", "0"], ["84860.00", "0"], ["84862.90", "0"]], "bids": [["84274.13", "0.447870"], ["84273.49", "0.000070"], ["84270.57", "0.012680"], ["84270.56", "1.895176"], ["84270.33", "0.140035"], ["84267.80", "0.001030"], ["84265.80", "0.001020"], ["84264.49", "0.252036"], ["84264.48", "0.484082"], ["84263.80", "0.001005"], ["84262.51", "0"], ["84261.80", "0.002820"], ["84261.65", "0.003007"], ["84261.32", "0"], ["84260.10", "0"], ["84259.80", "0.007420"], ["84258.10", "0"], ["84257.80", "0.019527"], ["84256.90", "0"], ["84256.78", "0.001230"], ["84256.74", "0.008538"], ["84256.72", "0.000213"], ["84256.71", "0.006487"], ["84256.49", "2.550089"], ["84256.10", "0"], ["84255.80", "0.051387"], ["84255.04", "0.007344"], ["84254.93", "0.008556"], ["84254.91", "0.008986"], ["84254.88", "0.006213"], ["84254.15", "0.008147"], ["84254.10", "0"], ["84253.80", "0.135229"], ["84253.55", "0.002062"], ["84252.69", "0"], ["84252.60", "0.255982"], ["84252.10", "0"], ["84251.80", "0.355866"], ["84251.34", "0.084449"], ["84250.35", "0"], ["84250.10", "0"], ["84249.80", "0.936489"], ["84249.65", "0.004935"], ["84249.62", "0.005554"], ["84249.57", "0.005088"], ["84249.54", "0.000875"], ["84249.48", "0.009635"], ["84249.04", "0"], ["84249.02", "0"], ["84249.01", "0"], ["84249.00", "0"], ["84248.96", "0"], ["84248.91", "0"], ["84248.80", "0.056361"], ["84248.10", "0"], ["84247.85", "0.008674"], ["84247.80", "2.464444"], ["84247.30", "0.001040"], ["84247.27", "0"], ["84247.23", "0"], ["84247.21", "0"], ["84247.20", "0.384390"], ["84247.19", "0"], ["84247.17", "0"], ["84247.15", "0"], ["84247.12", "0"], ["84246.38", "0"], ["84246.10", "0"], ["84245.98", "0"], ["84245.86", "0"], ["84245.76", "0"], ["84245.00", "0.142500"], ["84244.86", "0"], ["84244.84", "0"], ["84244.35", "0"], ["84244.25", "0"], ["84244.24", "0.551008"], ["84244.10", "0.274590"], ["84242.10", "0.915360"], ["84241.92", "0"], ["84241.89", "0"], ["84241.82", "0"], ["84241.80", "0"], ["84241.79", "0"], ["84241.74", "0"], ["84241.50", "3.217500"], ["84241.31", "0"], ["84240.80", "0.987180"], ["84240.10", "0.685020"], ["84240.07", "0"], ["84240.00", "0.462600"], ["84239.84", "0"], ["84239.70", "0"], ["84239.40", "1.350000"], ["84238.40", "0"], ["84236.20", "0.295560"], ["84234.71", "0.023742"], ["84233.30", "0"], ["84233.20", "0.801960"], ["84232.80", "0.023942"], ["84232.30", "0.090000"], ["84232.20", "0.090000"], ["84232.10", "0"], ["84231.20", "0.177720"], ["84230.70", "0"], ["84230.60", "0.608970"], ["84230.40", "0.177960"], ["84229.20", "0.038460"], ["84227.90", "0"], ["84227.80", "0"], ["84227.20", "0"], ["84227.00", "0"], ["84226.60", "0"], ["84226.34", "0.007181"], ["84226.20", "0"], ["84225.90", "0"], ["84225.80", "0"], ["84225.00", "0"], ["84224.80", "0"], ["84224.60", "0"], ["84224.50", "0"], ["84224.10", "0"], ["84224.00", "0"], ["84223.80", "0"], ["84223.30", "0"], ["84223.23", "0"], ["84218.56", "0"], ["84218.47", "0"], ["84218.18", "0"], ["84215.20", "0.207047"], ["84214.84", "0"], ["84212.10", "0"], ["84205.70", "5.333061"], ["84198.00", "0"], ["84197.20", "4.609934"], ["84189.50", "0"], ["84188.70", "4.881107"], ["84181.00", "0"], ["84180.20", "4.790716"], ["84172.50", "0"], ["84171.70", "5.513843"], ["84164.00", "0.000159"], ["84163.20", "4.700325"], ["84155.50", "0"], ["84154.70", "4.157980"], ["84147.00", "0"], ["84146.20", "4.971498"], ["84138.50", "0"], ["84137.70", "3.886807"], ["84130.00", "0"], ["84129.20", "4.519543"], ["84121.50", "0"], ["84120.70", "4.338762"], ["84113.00", "0"], ["84112.20", "4.248371"], ["84104.50", "0.310308"], ["84103.70", "4.067589"], ["84096.00", "0"], ["84095.20", "5.604234"], ["84087.50", "0.000021"], ["84086.70", "5.152279"], ["84079.00", "0"], ["84078.20", "5.242670"], ["84070.50", "0"], ["84069.70", "4.429152"], ["84062.00", "0"], ["84061.20", "5.423452"], ["84053.50", "0"], ["84052.70", "5.061888"], ["84045.00", "0"], ["84044.20", "3.977198"], ["84036.50", "0"], ["83888.86", "0.000371"], ["83887.29", "0.000586"], ["83887.11", "0.000075"], ["83886.91", "0.000145"], ["83885.98", "0.000018"], ["83885.71", "0.000069"], ["83884.62", "0.000014"], ["83884.55", "0.000048"], ["83884.30", "0.000161"], ["83882.98", "0.000188"], ["83882.92", "0.002384"], ["83881.99", "0.000038"], ["83880.00", "0.020454"], ["83877.97", "0.000023"], ["83877.55", "0.000010"], ["83877.42", "0.000054"]], "checksum": 453726046, "ts": "1742142222036"}], "ts": 1742142222040, "record_time": 1742142221.151742}
{"action": "update", "arg": {"instType": "SPOT", "channel": "books", "instId": "BTCUSDT"}, "data": [{"asks": [["84274.14", "1.349109"], ["84274.67", "0.188975"], ["84274.68", "0"], ["84277.80", "0"], ["84281.91", "0.004595"], ["84281.97", "0.001230"], ["84282.00", "0.005541"], ["84282.02", "0.004974"], ["84282.04", "0.006307"], ["84282.05", "0.008962"], ["84282.08", "0.012974"], ["84283.04", "0.001923"], ["84283.06", "0.021722"], ["84283.08", "0.010353"], ["84283.10", "0.014469"], ["84283.11", "0.004739"], ["84283.46", "0"], ["84286.07", "0"], ["84288.96", "0.572885"], ["84289.75", "0"], ["84289.81", "0"], ["84290.99", "0.140965"], ["84293.90", "0"], ["84293.92", "0"], ["84294.21", "0"], ["84295.23", "0.006356"], ["84295.29", "0.006356"], ["84295.47", "0.313259"], ["84299.40", "0.006356"], ["84305.65", "0.148098"], ["84306.08", "0.029802"], ["84308.90", "0"], ["84311.70", "0.001041"], ["84312.20", "0"], ["84313.70", "0.001042"], ["84314.20", "0"], ["84315.70", "0.001028"], ["84316.20", "0"], ["84317.70", "0.001009"], ["84317.86", "0"], ["84318.20", "0"], ["84319.70", "0.002176"], ["84320.20", "0"], ["84321.70", "0.005727"], ["84322.20", "0"], ["84323.70", "0.015072"], ["84324.20", "0"], ["84325.70", "0.039661"], ["84326.20", "0"], ["84327.70", "0.104372"], ["84328.20", "0"], ["84329.70", "0.274662"], ["84330.20", "0"], ["84331.70", "0.722796"], ["84331.90", "1.470330"], ["84332.20", "14.927880"], ["84332.30", "0"], ["84332.50", "0"], ["84332.80", "0"], ["84334.20", "0.069600"], ["84339.00", "0.007560"], ["84344.50", "0"], ["84344.70", "0"], ["84345.10", "0"], ["84345.50", "0"], ["84346.20", "0"], ["84346.70", "0"], ["84373.80", "4.429180"], ["84374.30", "0"], ["84382.30", "4.971529"], ["84382.80", "0"], ["84390.80", "5.513877"], ["84391.30", "0"], ["84399.30", "5.061920"], ["84399.80", "0"], ["84407.80", "4.700355"], ["84408.30", "0"], ["84416.30", "4.338789"], ["84416.80", "0"], ["84424.80", "3.886832"], ["84425.30", "0"], ["84425.84", "0"], ["84433.30", "5.423486"], ["84433.80", "0"], ["84434.27", "0"], ["84441.80", "4.248398"], ["84442.30", "0"], ["84450.30", "5.604269"], ["84450.80", "0"], ["84458.80", "4.158006"], ["84459.30", "0"], ["84467.30", "5.152312"], ["84467.80", "0"], ["84475.80", "5.333095"], ["84476.30", "0"], ["84484.30", "4.881137"], ["84484.80", "0"], ["84492.80", "5.242703"], ["84493.30", "0"], ["84501.30", "3.977223"], ["84501.80", "0"], ["84509.80", "4.067615"], ["84510.30", "0"], ["84518.30", "4.790746"], ["84518.80", "0"], ["84526.80", "4.609963"], ["84527.30", "0"], ["84535.30", "4.519572"], ["84535.80", "0"]], "bids": [["84274.13", "0.223494"], ["84273.49", "0"], ["84270.57", "0"], ["84270.56", "1.895016"], ["84270.33", "0"], ["84267.80", "0"], ["84267.30", "0.001033"], ["84265.80", "0"], ["84265.30", "0.001009"], ["84264.49", "0"], ["84264.48", "0.000356"], ["84263.80", "0"], ["84263.30", "0.001045"], ["84261.80", "0"], ["84261.30", "0.001020"], ["84259.80", "0"], ["84259.30", "0.001027"], ["84257.81", "0.010799"], ["84257.80", "0"], ["84257.30", "0.001013"], ["84256.69", "0.007513"], ["84256.66", "0.007641"], ["84255.80", "0"], ["84255.30", "0.001035"], ["84254.91", "0.015521"], ["84254.83", "0.007442"], ["84254.73", "0.001199"], ["84253.80", "0"], ["84253.30", "0.001032"], ["84253.28", "0.007871"], ["84252.60", "0.007950"], ["84252.57", "0.007474"], ["84251.80", "0"], ["84251.30", "0.001001"], ["84250.57", "0.017837"], ["84250.29", "0.018262"], ["84249.80", "0"], ["84249.49", "0.008149"], ["84249.30", "0.001040"], ["84247.83", "0.012680"], ["84247.80", "0"], ["84247.65", "0.008165"], ["84247.50", "0.010234"], ["84247.20", "0.242700"], ["84246.70", "0.001001"], ["84245.54", "0.002950"], ["84245.09", "0"], ["84245.00", "0.020070"], ["84244.81", "0"], ["84244.24", "0.197876"], ["84242.18", "0"], ["84241.60", "1.626180"], ["84241.50", "0"], ["84240.10", "0.006150"], ["84239.40", "0"], ["84239.30", "0"], ["84238.60", "0"], ["84237.80", "0"], ["84236.20", "0"], ["84235.80", "0"], ["84234.00", "0.090000"], ["84233.00", "0.090000"], ["84232.20", "0.232500"], ["84232.10", "0.090000"], ["84230.95", "0.008206"], ["84230.60", "0.367470"], ["84230.40", "0"], ["84229.80", "0"], ["84229.70", "0.090000"], ["84229.50", "0.030000"], ["84228.90", "0.090000"], ["84228.10", "4.560540"], ["84228.00", "2.759430"], ["84227.90", "0.090000"], ["84227.80", "0.069600"], ["84226.18", "0.007582"], ["84205.70", "0"], ["84205.20", "4.158006"], ["84197.20", "0"], ["84196.70", "5.513877"], ["84188.70", "0"], ["84188.20", "5.152312"], ["84180.20", "0"], ["84179.70", "5.242703"], ["84171.70", "0"], ["84171.20", "3.977223"], ["84163.20", "0"], ["84162.70", "5.423486"], ["84154.70", "0"], ["84154.20", "4.429180"], ["84146.20", "0"], ["84145.70", "4.700355"], ["84137.70", "0"], ["84137.20", "4.338789"], ["84129.20", "0"], ["84128.70", "5.604269"], ["84120.70", "0"], ["84120.20", "4.519572"], ["84112.20", "0"], ["84111.70", "4.790746"], ["84103.70", "0"], ["84103.20", "4.067615"], ["84095.20", "0"], ["84094.70", "4.881137"], ["84086.70", "0"], ["84086.20", "4.971529"], ["84078.20", "0"], ["84077.70", "5.061920"], ["84069.70", "0"], ["84069.20", "4.248398"], ["84061.20", "0"], ["84060.70", "3.886832"], ["84052.70", "0"], ["84052.20", "5.333095"], ["84044.20", "0"], ["84043.70", "4.609963"], ["83992.38", "0.209200"], ["83885.98", "0"], ["83885.71", "0"], ["83884.62", "0"], ["83884.55", "0"], ["83884.30", "0"], ["83882.98", "0"], ["83882.92", "0"], ["83881.99", "0"], ["83880.00", "0"], ["83877.97", "0"], ["83877.55", "0"], ["83877.42", "0"]], "checksum": 733931168, "ts": "1742142222237"}], "ts": 1742142222243, "record_time": 1742142221.359179}
{"action": "update", "arg": {"instType": "SPOT", "channel": "books", "instId": "BTCUSDT"}, "data": [{"asks": [["84274.14", "1.462342"], ["84274.67", "0.009005"], ["84275.59", "0.140033"], ["84281.42", "0.080382"], ["84281.91", "0"], ["84281.95", "0"], ["84281.97", "0"], ["84282.00", "0"], ["84282.02", "0"], ["84282.03", "0"], ["84282.04", "0"], ["84282.05", "0"], ["84282.08", "0.020168"], ["84282.09", "0"], ["84282.57", "0.209200"], ["84282.77", "0.001205"], ["84283.04", "0"], ["84283.05", "0"], ["84283.06", "0"], ["84283.07", "0"], ["84283.08", "0"], ["84283.09", "0"], ["84283.10", "0"], ["84283.11", "0"], ["84284.97", "0.035952"], ["84285.09", "0.006356"], ["84285.15", "0.006356"], ["84285.63", "0.006356"], ["84286.26", "0.006356"], ["84286.59", "0.010985"], ["84286.85", "0.006356"], ["84288.24", "0.006356"], ["84288.78", "0.031812"], ["84289.25", "0.119869"], ["84289.26", "0.006356"], ["84290.26", "0.006356"], ["84290.99", "0"], ["84291.37", "0"], ["84291.98", "0"], ["84292.59", "0"], ["84293.80", "0"], ["84294.03", "0"], ["84295.16", "0"], ["84295.23", "0"], ["84295.29", "0"], ["84295.82", "0"], ["84296.67", "0"], ["84299.10", "0.001017"], ["84299.40", "0"], ["84301.10", "0.001292"], ["84303.10", "0.003204"], ["84305.10", "0.008431"], ["84307.10", "0.022187"], ["84309.10", "0.058386"], ["84311.10", "0.153648"], ["84311.70", "0"], ["84313.07", "0.010000"], ["84313.10", "0.404337"], ["84313.70", "0"], ["84315.10", "1.064044"], ["84315.70", "0"], ["84317.10", "2.800115"], ["84317.70", "0"], ["84319.10", "7.368725"], ["84319.70", "0"], ["84320.40", "0.350700"], ["84320.90", "0.001008"], ["84321.70", "0"], ["84323.00", "0.273690"], ["84323.70", "0"], ["84325.60", "0.258030"], ["84325.70", "0"], ["84325.80", "0.035580"], ["84326.90", "0.052650"], ["84327.70", "0"], ["84328.50", "0.015060"], ["84329.70", "9.005400"], ["84330.10", "0.410370"], ["84330.20", "0.102510"], ["84331.60", "6.239400"], ["84331.70", "1.888770"], ["84331.90", "0"], ["84332.20", "1.420350"], ["84332.90", "0.009000"], ["84333.10", "0"], ["84335.10", "0"], ["84335.50", "0.508680"], ["84335.90", "0.177960"], ["84336.10", "0.985470"], ["84336.30", "0.117000"], ["84337.90", "0.060000"], ["84338.10", "0.171750"], ["84338.70", "0"], ["84339.00", "0"], ["84339.30", "0.106800"], ["84339.40", "0.198000"], ["84339.50", "0.090000"], ["84339.90", "0"], ["84340.70", "0"], ["84341.30", "0"], ["84341.60", "0"], ["84341.90", "0"], ["84342.20", "0"], ["84342.80", "0"], ["84343.20", "0"], ["84343.40", "0"], ["84343.50", "0"], ["84343.60", "0"], ["84344.60", "0"], ["84361.20", "5.605108"], ["84369.70", "4.610654"], ["84373.80", "0"], ["84378.20", "4.881868"], ["84382.30", "0"], ["84386.70", "5.062678"], ["84390.80", "0"], ["84395.20", "4.520249"], ["84399.30", "0"], ["84403.70", "4.068224"], ["84407.80", "0"], ["84412.20", "4.972273"], ["84416.30", "0"], ["84420.70", "3.977819"], ["84424.80", "0"], ["84429.20", "4.701058"], ["84433.30", "0"], ["84437.70", "4.249034"], ["84441.80", "0"], ["84446.20", "4.339439"], ["84450.30", "0"], ["84454.70", "4.429844"], ["84458.80", "0"], ["84463.20", "4.791463"], ["84467.30", "0"], ["84471.70", "5.243488"], ["84475.80", "0"], ["84480.20", "5.424298"], ["84484.30", "0"], ["84488.70", "5.514703"], ["84492.80", "0"], ["84497.20", "5.333893"], ["84501.30", "0"], ["84505.70", "5.153083"], ["84509.80", "0"], ["84514.20", "3.887414"], ["84518.30", "0"], ["84522.70", "4.158629"], ["84526.80", "0"], ["84535.30", "0"], ["84859.29", "0.000036"], ["84860.00", "0.000169"], ["84862.90", "0.000169"], ["84864.69", "0.000052"], ["84864.86", "0.000041"], ["84864.99", "0.000033"], ["84866.10", "0.000064"], ["84866.40", "0.000018"], ["84867.80", "0.000095"]], "bids": [["84274.13", "0.203270"], ["84274.12", "0.000100"], ["84274.11", "0.000100"], ["84274.10", "0.000100"], ["84272.95", "0.010000"], ["84267.30", "0"], ["84266.95", "0.140033"], ["84265.30", "0"], ["84264.48", "0"], ["84263.30", "0"], ["84261.65", "0"], ["84261.30", "0"], ["84259.30", "0"], ["84257.30", "0"], ["84256.78", "0"], ["84256.74", "0"], ["84256.72", "0"], ["84256.71", "0"], ["84256.69", "0"], ["84256.66", "0"], ["84256.50", "0.866591"], ["84255.39", "0.353132"], ["84255.30", "0"], ["84255.04", "0"], ["84254.93", "0"], ["84254.91", "0"], ["84254.88", "0"], ["84254.83", "0"], ["84254.73", "0"], ["84254.70", "0.001025"], ["84254.15", "0"], ["84253.55", "0"], ["84253.30", "0"], ["84253.28", "0"], ["84252.70", "0.001045"], ["84252.60", "0"], ["84252.57", "0"], ["84251.34", "0"], ["84251.30", "0"], ["84250.70", "0.001835"], ["84250.57", "0"], ["84250.29", "0"], ["84249.65", "0"], ["84249.62", "0"], ["84249.57", "0"], ["84249.54", "0"], ["84249.49", "0"], ["84249.48", "0"], ["84249.30", "0"], ["84248.80", "0"], ["84248.70", "0.004827"], ["84247.96", "0.248027"], ["84247.85", "0"], ["84247.65", "0"], ["84247.50", "0"], ["84247.30", "0"], ["84247.20", "0"], ["84246.70", "0.012704"], ["84245.54", "0"], ["84245.30", "0"], ["84245.02", "0"], ["84245.00", "0"], ["84244.70", "0.033430"], ["84244.10", "0"], ["84243.88", "0"], ["84243.58", "0.007717"], ["84243.55", "0.008751"], ["84243.54", "0.007513"], ["84243.50", "0.007641"], ["84243.07", "0"], ["84242.70", "0.087975"], ["84242.10", "0"], ["84241.85", "0.007344"], ["84241.72", "0.008556"], ["84241.71", "0.006535"], ["84241.66", "0.007442"], ["84241.64", "0.001199"], ["84241.60", "0"], ["84241.15", "0.084447"], ["84241.05", "0"], ["84240.98", "0.008147"], ["84240.80", "0"], ["84240.70", "0.231513"], ["84240.43", "0.017837"], ["84240.26", "0.002062"], ["84240.10", "0"], ["84240.00", "0"], ["84239.58", "0.016462"], ["84239.51", "0.018262"], ["84239.42", "0.007950"], ["84239.41", "0.007474"], ["84239.29", "0.015773"], ["84238.73", "0.056360"], ["84238.70", "0.609245"], ["84238.15", "0.007120"], ["84237.52", "0.008165"], ["84237.51", "0.007934"], ["84236.70", "1.603277"], ["84236.47", "0.004935"], ["84236.39", "0.005088"], ["84236.35", "0.000875"], ["84236.32", "0.008149"], ["84235.67", "0.002950"], ["84235.49", "0.012650"], ["84234.70", "4.219150"], ["84234.66", "0.008674"], ["84234.35", "0.010234"], ["84234.20", "0.276030"], ["84234.00", "0"], ["84233.20", "0.392190"], ["84233.00", "0.035580"], ["84232.40", "0.001014"], ["84232.30", "0"], ["84232.20", "0.142680"], ["84232.10", "0"], ["84231.80", "0.987360"], ["84231.20", "0"], ["84230.95", "0"], ["84230.60", "0.093690"], ["84229.80", "0.532200"], ["84229.70", "0"], ["84229.50", "0"], ["84229.20", "0"], ["84228.90", "0"], ["84228.10", "0.510090"], ["84228.00", "0.013140"], ["84227.90", "0"], ["84227.80", "0"], ["84227.10", "0.012000"], ["84226.60", "0.090000"], ["84226.34", "0"], ["84226.30", "1.350000"], ["84226.18", "0"], ["84226.00", "0.090000"], ["84225.80", "0.142500"], ["84225.00", "0.278250"], ["84224.40", "0.014040"], ["84224.10", "0.065580"], ["84223.90", "0.090000"], ["84223.70", "0.090000"], ["84223.60", "0.038460"], ["84223.30", "0.048210"], ["84223.20", "0.186960"], ["84222.70", "0.090000"], ["84220.70", "0.267900"], ["84220.40", "0.090000"], ["84219.60", "0.090000"], ["84217.78", "0.008206"], ["84213.15", "0.007181"], ["84205.20", "0"], ["84196.70", "0"], ["84192.60", "4.881868"], ["84188.20", "0"], ["84184.10", "4.791463"], ["84179.70", "0"], ["84175.60", "4.429844"], ["84171.20", "0"], ["84168.00", "0"], ["84167.10", "4.701058"], ["84162.70", "0"], ["84158.60", "5.153083"], ["84154.20", "0"], ["84150.10", "4.520249"], ["84145.70", "0"], ["84141.60", "5.424298"], ["84137.20", "0"], ["84133.10", "4.068224"], ["84128.70", "0"], ["84124.60", "5.605108"], ["84120.20", "0"], ["84116.10", "4.610654"], ["84111.70", "0"], ["84107.60", "5.514703"], ["84103.20", "0"], ["84099.10", "5.062678"], ["84094.70", "0"], ["84090.60", "3.977819"], ["84086.20", "0"], ["84082.10", "4.158629"], ["84077.70", "0"], ["84073.60", "3.887414"], ["84069.20", "0"], ["84065.10", "5.333893"], ["84060.70", "0"], ["84056.60", "5.243488"], ["84052.20", "0"], ["84048.10", "4.249034"], ["84043.70", "0"], ["84039.60", "4.972273"], ["84031.10", "4.339439"]], "checksum": -14269366, "ts": "1742142222437"}], "ts": 1742142222444, "record_time": 1742142221.553052}
{"action": "update", "arg": {"instType": "SPOT", "channel": "books", "instId": "BTCUSDT"}, "data": [{"asks": [["84274.14", "1.548402"], ["84274.67", "0.049889"], ["84275.23", "0.080382"], ["84277.43", "0.003017"], ["84278.92", "0.001827"], ["84281.42", "0"], ["84283.06", "0.119869"], ["84285.05", "0.006356"], ["84286.12", "0.006356"], ["84286.41", "0.006356"], ["84287.27", "0.006356"], ["84288.11", "0"], ["84288.16", "0.006356"], ["84288.31", "0.119843"], ["84288.78", "0.038169"], ["84289.25", "0"], ["84289.55", "0"], ["84290.51", "0.009989"], ["84291.30", "0"], ["84292.37", "0"], ["84292.63", "0"], ["84293.63", "0"], ["84294.34", "0"], ["84294.72", "0"], ["84295.14", "0"], ["84296.01", "0.001807"], ["84296.92", "0"], ["84311.10", "0.153793"], ["84313.10", "0.404719"], ["84315.10", "1.065051"], ["84317.10", "2.802766"], ["84319.10", "7.375811"], ["84320.40", "0"], ["84320.90", "0"], ["84321.86", "0"], ["84322.50", "0.388950"], ["84323.00", "0.142770"], ["84325.60", "0"], ["84326.90", "0"], ["84328.20", "0.001035"], ["84329.40", "0.142500"], ["84329.70", "7.723560"], ["84330.70", "0.985470"], ["84331.60", "4.217640"], ["84335.50", "0.291030"], ["84336.10", "0"], ["84337.00", "0.180000"], ["84338.10", "0.306750"], ["84339.70", "0.120000"], ["84339.90", "3.694380"], ["84361.20", "4.520249"], ["84369.70", "4.339439"], ["84378.20", "4.068224"], ["84386.70", "4.881868"], ["84395.20", "4.158629"], ["84403.70", "5.243488"], ["84420.70", "5.153083"], ["84437.70", "5.062678"], ["84446.20", "4.791463"], ["84454.70", "5.514703"], ["84463.20", "5.333893"], ["84471.70", "3.887414"], ["84480.20", "5.605108"], ["84488.70", "4.429844"], ["84497.20", "4.249034"], ["84505.70", "5.424298"], ["84514.20", "3.977819"], ["84522.70", "4.610654"], ["84867.80", "0"]], "bids": [["84274.13", "0.202539"], ["84266.95", "0"], ["84265.31", "0.000164"], ["84262.06", "0.140031"], ["84257.81", "0"], ["84253.54", "0.000070"], ["84252.12", "0.151837"], ["84250.70", "0.001587"], ["84248.70", "0.004178"], ["84247.96", "0"], ["84246.70", "0.010874"], ["84245.62", "0"], ["84244.70", "0.028769"], ["84244.67", "0"], ["84244.26", "0.014965"], ["84244.24", "0"], ["84243.32", "0"], ["84242.90", "0.007318"], ["84242.70", "0.075709"], ["84242.59", "0"], ["84241.81", "0.008986"], ["84241.77", "0.248027"], ["84241.75", "0.006213"], ["84241.38", "0"], ["84240.70", "0.199233"], ["84240.46", "0"], ["84240.03", "0.007871"], ["84239.38", "0.005938"], ["84238.70", "0.524297"], ["84238.43", "0.006565"], ["84238.04", "0.017080"], ["84236.91", "0.227697"], ["84236.70", "1.379730"], ["84236.54", "0.008989"], ["84236.49", "0.005554"], ["84236.42", "0.017334"], ["84236.34", "0.009635"], ["84235.02", "0.008284"], ["84234.70", "3.630869"], ["84234.20", "0.001020"], ["84234.05", "0.018522"], ["84233.20", "0.242520"], ["84232.20", "0.142920"], ["84231.80", "0"], ["84229.80", "0.806790"], ["84228.10", "0.720390"], ["84228.00", "0.026130"], ["84226.40", "0.915360"], ["84225.00", "0.550890"], ["84224.00", "2.349870"], ["84223.10", "0.987180"], ["84220.70", "0"], ["84220.40", "0"], ["84219.60", "0"], ["84215.20", "0"], ["84213.09", "0.007582"], ["84207.20", "0.207047"], ["84192.60", "4.429844"], ["84184.10", "4.068224"], ["84175.60", "5.333893"], ["84160.36", "0"], ["84158.60", "4.610654"], ["84155.47", "0.072042"], ["84150.10", "5.424298"], ["84141.60", "4.249034"], ["84133.10", "3.977819"], ["84116.10", "4.158629"], ["84107.60", "3.887414"], ["84090.60", "4.791463"], ["84082.10", "4.972273"], ["84073.60", "4.520249"], ["84065.10", "4.339439"], ["84056.60", "5.153083"], ["84048.10", "5.514703"], ["84039.60", "4.881868"], ["84031.10", "5.243488"], ["83892.29", "0"], ["83891.43", "0"], ["83891.30", "0"], ["83888.89", "0"], ["83888.86", "0"], ["83887.29", "0"], ["83887.11", "0"], ["83886.91", "0"]], "checksum": -831063270, "ts": "1742142222639"}], "ts": 1742142222645, "record_time": 1742142221.753584}
{"action": "update", "arg": {"instType": "SPOT", "channel": "books", "instId": "BTCUSDT"}, "data": [{"asks": [["84274.14", "1.339202"], ["84274.67", "0.069798"], ["84284.90", "0.012680"], ["84287.12", "0.006356"], ["84287.25", "0.006356"], ["84288.78", "0.006357"], ["84292.62", "0"], ["84292.75", "0"], ["84301.10", "0.001188"], ["84303.10", "0.003030"], ["84305.10", "0.007973"], ["84307.10", "0.020981"], ["84309.10", "0.055214"], ["84309.16", "0.026414"], ["84311.10", "0.145301"], ["84313.10", "0.382370"], ["84315.10", "1.006236"], ["84317.10", "2.647991"], ["84319.10", "6.968397"], ["84319.60", "0.038070"], ["84320.10", "0.001045"], ["84322.30", "0.378270"], ["84322.50", "0"], ["84325.80", "0.007710"], ["84328.20", "0"], ["84329.70", "6.348210"], ["84330.70", "0.988320"], ["84331.70", "1.924350"], ["84333.60", "0.025350"], ["84339.70", "0"], ["84339.90", "0"], ["84361.20", "4.791463"], ["84369.70", "4.610654"], ["84378.20", "5.514703"], ["84386.70", "4.068224"], ["84395.20", "5.605108"], ["84403.70", "4.158629"], ["84412.20", "4.429844"], ["84420.70", "4.881868"], ["84429.20", "4.339439"], ["84437.70", "5.243488"], ["84446.20", "4.520249"], ["84454.70", "4.249034"], ["84463.20", "5.062678"], ["84480.20", "5.424298"], ["84488.70", "4.701058"], ["84497.20", "3.977819"], ["84505.70", "4.972273"], ["84514.20", "5.333893"], ["84522.70", "5.153083"], ["84866.10", "0"], ["84866.40", "0"]], "bids": [["84262.07", "0.042009"], ["84261.85", "0.055162"], ["84258.65", "0.000070"], ["84253.54", "0"], ["84244.88", "0.003070"], ["84242.90", "0"], ["84242.69", "0"], ["84240.70", "0.199009"], ["84238.70", "0.523709"], ["84237.41", "0.007317"], ["84237.20", "0.017063"], ["84236.70", "1.378183"], ["84234.70", "3.626795"], ["84230.60", "0.169260"], ["84228.10", "1.403010"], ["84226.60", "2.439810"], ["84224.00", "0"], ["84192.60", "4.972273"], ["84184.10", "4.339439"], ["84175.60", "3.977819"], ["84167.10", "5.605108"], ["84165.00", "0"], ["84158.60", "4.881868"], ["84150.10", "4.610654"], ["84141.60", "5.424298"], ["84133.10", "4.701058"], ["84124.60", "4.158629"], ["84116.10", "5.243488"], ["84107.60", "4.429844"], ["84099.10", "4.249034"], ["84090.60", "5.153083"], ["84082.10", "5.333893"], ["84073.60", "4.791463"], ["84065.10", "4.520249"], ["84056.60", "3.887414"], ["84048.10", "4.068224"], ["84039.60", "5.514703"], ["84031.10", "5.062678"], ["83893.62", "0"]], "checksum": 655212598, "ts": "1742142222846"}], "ts": 1742142222851, "record_time": 1742142221.959221}
{"action": "update", "arg": {"instType": "SPOT", "channel": "books", "instId": "BTCUSDT"}, "data": [{"asks": [["84275.59", "0"], ["84282.08", "0.119650"], ["84297.58", "0.031812"], ["84315.10", "1.006430"], ["84317.10", "2.648500"], ["84319.10", "6.969736"], ["84322.30", "0.571200"], ["84325.60", "0.685500"], ["84332.20", "1.419600"], ["84335.90", "0.188730"], ["84339.10", "0"], ["84339.30", "0"], ["84339.40", "0"], ["84339.50", "0"], ["84361.20", "3.887414"], ["84369.70", "5.062678"], ["84378.20", "4.881868"], ["84386.70", "5.153083"], ["84395.20", "5.424298"], ["84403.70", "5.605108"], ["84412.20", "4.610654"], ["84420.70", "4.249034"], ["84437.70", "4.791463"], ["84446.20", "3.977819"], ["84454.70", "4.972273"], ["84463.20", "4.701058"], ["84471.70", "4.068224"], ["84480.20", "5.243488"], ["84488.70", "4.158629"], ["84497.20", "4.429844"], ["84505.70", "4.520249"], ["84522.70", "5.514703"], ["84866.10", "0.000064"], ["84866.40", "0.000018"], ["84867.80", "0.000095"]], "bids": [["84248.70", "0.004325"], ["84246.70", "0.011383"], ["84244.93", "0.003037"], ["84244.70", "0.029953"], ["84242.70", "0.078825"], ["84240.70", "0.207435"], ["84238.70", "0.545881"], ["84238.44", "0.440888"], ["84236.70", "1.436529"], ["84234.70", "3.780338"], ["84230.00", "0.274590"], ["84229.80", "0.532200"], ["84227.10", "0"], ["84192.60", "5.153083"], ["84184.10", "5.514703"], ["84175.60", "4.429844"], ["84167.10", "4.972273"], ["84167.00", "0.000121"], ["84158.60", "4.610654"], ["84150.10", "5.243488"], ["84141.60", "4.339439"], ["84133.10", "4.791463"], ["84124.60", "5.605108"], ["84116.10", "5.424298"], ["84107.60", "4.158629"], ["84099.10", "5.333893"], ["84090.60", "3.887414"], ["84082.10", "5.062678"], ["84073.60", "4.068224"], ["84065.10", "4.701058"], ["84056.60", "4.249034"], ["84048.10", "3.977819"], ["84039.60", "4.520249"], ["84031.10", "4.881868"], ["83894.17", "0"], ["83893.81", "0"], ["83893.64", "0"]], "checksum": -1681478711, "ts": "1742142223047"}], "ts": 1742142223051, "record_time": 1742142222.159606}
{"action": "update", "arg": {"instType": "SPOT", "channel": "books", "instId": "BTCUSDT"}, "data": [{"asks": [["84274.14", "1.491057"], ["84274.67", "0.034024"], ["84283.75", "0.012680"], ["84284.90", "0"], ["84307.10", "0.021095"], ["84309.10", "0.055472"], ["84311.10", "0.146086"], ["84313.10", "0.384437"], ["84315.10", "1.011675"], ["84317.10", "2.662304"], ["84319.10", "7.006062"], ["84319.60", "0.117330"], ["84322.00", "0.269760"], ["84322.30", "0.571620"], ["84323.00", "0.142710"], ["84324.30", "0.407160"], ["84325.80", "0.035580"], ["84330.70", "0.985470"], ["84361.20", "5.153083"], ["84369.70", "5.514703"], ["84378.20", "5.424298"], ["84386.70", "4.068224"], ["84395.20", "4.701058"], ["84403.70", "4.972273"], ["84412.20", "5.062678"], ["84420.70", "4.339439"], ["84429.20", "5.243488"], ["84446.20", "3.887414"], ["84454.70", "4.249034"], ["84463.20", "4.429844"], ["84471.70", "3.977819"], ["84480.20", "4.881868"], ["84488.70", "5.605108"], ["84497.20", "4.610654"], ["84505.70", "5.333893"], ["84514.20", "4.520249"], ["84522.70", "4.158629"], ["84602.51", "0"], ["84613.99", "1.724657"], ["84866.40", "0"], ["84867.80", "0"]], "bids": [["84262.28", "0.055162"], ["84261.85", "0"], ["84253.75", "0.003007"], ["84250.70", "0.001178"], ["84248.70", "0.003099"], ["84246.70", "0.008157"], ["84244.70", "0.021465"], ["84242.70", "0.056487"], ["84241.78", "0.260127"], ["84240.70", "0.148650"], ["84238.70", "0.391185"], ["84236.70", "1.029433"], ["84234.70", "2.709034"], ["84234.50", "0.001030"], ["84234.20", "0"], ["84233.20", "0.445440"], ["84232.60", "0.001021"], ["84232.50", "0.427230"], ["84232.40", "0"], ["84232.20", "0"], ["84230.60", "0.169440"], ["84230.00", "0.274770"], ["84229.80", "0.462780"], ["84221.50", "0.030000"], ["84220.70", "0.402780"], ["84220.40", "0.090000"], ["84192.60", "4.339439"], ["84175.60", "5.243488"], ["84167.10", "5.424298"], ["84158.60", "5.153083"], ["84150.10", "4.068224"], ["84141.60", "4.610654"], ["84133.10", "4.972273"], ["84124.60", "4.249034"], ["84116.10", "5.605108"], ["84107.60", "3.977819"], ["84099.10", "4.429844"], ["84090.60", "4.881868"], ["84082.10", "5.333893"], ["84073.60", "4.158629"], ["84065.10", "3.887414"], ["84056.60", "5.062678"], ["84048.10", "4.520249"], ["84039.60", "4.791463"], ["84031.10", "4.701058"], ["83939.76", "1.593342"], ["83928.38", "0"], ["83896.11", "0"], ["83896.00", "0"], ["83895.65", "0"], ["83895.00", "0"], ["83894.74", "0"]], "checksum": -1960885873, "ts": "1742142223247"}], "ts": 1742142223251, "record_time": 1742142222.359022}
{"action": "update", "arg": {"instType": "SPOT", "channel": "books", "instId": "BTCUSDT"}, "data": [{"asks": [["84283.75", "0"], ["84290.99", "0.077957"], ["84305.65", "0"], ["84317.10", "2.662155"], ["84319.10", "7.005671"], ["84319.60", "0.296400"], ["84321.20", "0.258030"], ["84321.80", "0.001015"], ["84322.30", "0.313170"], ["84323.00", "0.142500"], ["84338.20", "0"], ["84361.20", "5.333893"], ["84369.70", "3.977819"], ["84378.20", "4.520249"], ["84386.70", "4.701058"], ["84395.20", "4.791463"], ["84403.70", "5.243488"], ["84412.20", "4.158629"], ["84420.70", "4.249034"], ["84429.20", "4.429844"], ["84437.70", "4.881868"], ["84446.20", "5.062678"], ["84454.70", "4.972273"], ["84463.20", "5.514703"], ["84471.70", "4.068224"], ["84480.20", "5.605108"], ["84488.70", "5.424298"], ["84497.20", "3.887414"], ["84505.70", "4.339439"], ["84514.20", "5.153083"], ["84522.70", "4.610654"]], "bids": [["84274.13", "0.201470"], ["84258.65", "0"], ["84248.70", "0.003226"], ["84247.84", "0.019012"], ["84246.70", "0.008490"], ["84244.70", "0.022340"], ["84242.70", "0.058790"], ["84240.70", "0.154710"], ["84238.70", "0.407133"], ["84238.44", "0"], ["84236.70", "1.071403"], ["84234.70", "2.819481"], ["84232.20", "0.142500"], ["84229.80", "0.069600"], ["84228.40", "0.383670"], ["84228.10", "1.391280"], ["84226.90", "2.349780"], ["84226.60", "0.090000"], ["84223.50", "0.030000"], ["84223.40", "0.462600"], ["84221.50", "0"], ["84192.60", "4.610654"], ["84184.10", "4.520249"], ["84175.60", "3.977819"], ["84167.10", "4.972273"], ["84166.00", "0.000159"], ["84158.40", "0.072042"], ["84155.47", "0"], ["84150.10", "5.605108"], ["84141.60", "4.068224"], ["84133.10", "4.881868"], ["84124.60", "4.791463"], ["84116.10", "4.701058"], ["84107.60", "4.429844"], ["84099.10", "3.887414"], ["84090.60", "4.339439"], ["84065.10", "5.514703"], ["84056.60", "5.424298"], ["84048.10", "5.243488"], ["84039.60", "5.062678"], ["84031.10", "4.249034"], ["83900.00", "0"], ["83899.58", "0"], ["83898.68", "0"]], "checksum": -1188445481, "ts": "1742142223447"}], "ts": 1742142223455, "record_time": 1742142222.562975}
{"action": "update", "arg": {"instType": "SPOT", "channel": "books", "instId": "BTCUSDT"}, "data": [{"asks": [["84274.14", "1.503737"], ["84282.37", "0.148098"], ["84305.82", "0.683973"], ["84315.10", "1.011869"], ["84317.10", "2.662813"], ["84319.10", "7.007401"], ["84320.90", "0.258030"], ["84321.20", "0"], ["84325.80", "0.016740"], ["84361.20", "3.977819"], ["84369.70", "3.887414"], ["84378.20", "4.339439"], ["84386.70", "4.972273"], ["84395.20", "4.249034"], ["84412.20", "4.429844"], ["84420.70", "5.333893"], ["84429.20", "4.881868"], ["84437.70", "5.605108"], ["84446.20", "4.791463"], ["84454.70", "4.610654"], ["84463.20", "5.424298"], ["84471.70", "4.520249"], ["84480.20", "5.153083"], ["84488.70", "5.062678"], ["84497.20", "4.158629"], ["84505.70", "4.701058"], ["84514.20", "5.514703"], ["84522.70", "4.068224"], ["84864.99", "0"], ["84866.10", "0"]], "bids": [["84262.87", "0.000070"], ["84238.42", "0.161749"], ["84233.20", "0.242520"], ["84229.80", "0"], ["84226.60", "0"], ["84226.00", "0"], ["84225.00", "0.460890"], ["84223.50", "0"], ["84222.70", "0"], ["84222.10", "0.030000"], ["84220.00", "0.026100"], ["84219.60", "0.180000"], ["84192.60", "5.333893"], ["84184.10", "4.249034"], ["84175.60", "4.520249"], ["84167.10", "4.701058"], ["84158.60", "5.605108"], ["84158.40", "0"], ["84150.10", "5.153083"], ["84141.60", "4.339439"], ["84124.60", "4.610654"], ["84116.10", "5.243488"], ["84107.60", "4.068224"], ["84090.60", "4.791463"], ["84082.10", "4.429844"], ["84073.60", "4.972273"], ["84065.10", "5.062678"], ["84056.60", "5.514703"], ["84048.10", "5.424298"], ["84039.60", "4.158629"], ["84031.10", "3.977819"], ["83900.00", "0.002977"]], "checksum": -1041236072, "ts": "1742142223647"}], "ts": 1742142223651, "record_time": 1742142222.758997}
{"action": "update", "arg": {"instType": "SPOT", "channel": "books", "instId": "BTCUSDT"}, "data": [{"asks": [["84274.14", "1.491057"], ["84282.37", "0"], ["84288.58", "0.148098"], ["84305.10", "0.008208"], ["84306.08", "0"], ["84307.10", "0.021598"], ["84309.10", "0.056839"], ["84311.10", "0.149574"], ["84313.09", "0.481652"], ["84313.10", "0.393616"], ["84315.10", "1.035832"], ["84317.10", "2.725873"], ["84319.10", "7.173350"], ["84320.90", "0.258210"], ["84321.80", "0"], ["84338.10", "0"], ["84361.20", "3.887414"], ["84369.70", "5.333893"], ["84378.20", "4.249034"], ["84386.70", "4.881868"], ["84395.20", "5.153083"], ["84412.20", "4.068224"], ["84420.70", "5.605108"], ["84429.20", "4.429844"], ["84437.70", "4.610654"], ["84446.20", "5.062678"], ["84454.70", "5.514703"], ["84463.20", "4.158629"], ["84471.70", "5.424298"], ["84480.20", "4.339439"], ["84488.70", "4.520249"], ["84497.20", "4.791463"], ["84505.70", "3.977819"], ["84514.20", "4.972273"], ["84522.70", "4.701058"], ["84864.99", "0.000033"], ["84866.10", "0.000064"]], "bids": [["84262.71", "0.055162"], ["84262.28", "0"], ["84250.70", "0.001954"], ["84248.70", "0.005141"], ["84246.70", "0.013530"], ["84244.70", "0.035604"], ["84242.70", "0.093695"], ["84240.70", "0.246566"], ["84238.70", "0.648859"], ["84236.70", "1.707523"], ["84234.70", "4.493481"], ["84229.80", "0.069600"], ["84221.30", "0.090000"], ["84220.40", "0.180000"], ["84220.00", "0"], ["84219.60", "0"], ["84192.60", "4.158629"], ["84184.10", "5.424298"], ["84175.60", "4.339439"], ["84169.00", "0.012717"], ["84167.10", "4.972273"], ["84158.60", "5.153083"], ["84150.10", "5.333893"], ["84141.60", "5.243488"], ["84133.10", "4.610654"], ["84124.60", "5.514703"], ["84116.10", "4.068224"], ["84107.60", "4.791463"], ["84090.60", "4.881868"], ["84082.10", "5.605108"], ["84073.60", "4.249034"], ["84065.10", "4.701058"], ["84056.60", "4.429844"], ["84048.10", "3.977819"], ["84039.60", "4.520249"], ["84031.10", "5.062678"]], "checksum": 19263930, "ts": "1742142223849"}], "ts": 1742142223852, "record_time": 1742142222.960998}
{"action": "update", "arg": {"instType": "SPOT", "channel": "books", "instId": "BTCUSDT"}, "data": [{"asks": [["84295.46", "0.237755"], ["84311.10", "0.149437"], ["84313.10", "0.393255"], ["84315.10", "1.034881"], ["84315.53", "0.029802"], ["84317.10", "2.723371"], ["84319.10", "7.166561"], ["84319.60", "0.001012"], ["84320.70", "0.016080"], ["84320.90", "0.001025"], ["84322.00", "0"], ["84324.90", "0.258030"], ["84325.80", "0"], ["84331.70", "0.845310"], ["84335.50", "1.044330"], ["84337.00", "0"], ["84337.90", "0"], ["84361.20", "4.791463"], ["84369.70", "4.339439"], ["84378.20", "4.972273"], ["84386.70", "5.514703"], ["84395.20", "3.887414"], ["84403.70", "4.610654"], ["84412.20", "5.333893"], ["84420.70", "5.062678"], ["84429.20", "4.068224"], ["84437.70", "5.153083"], ["84446.20", "5.424298"], ["84454.70", "4.429844"], ["84463.20", "5.243488"], ["84471.70", "5.605108"], ["84480.20", "4.158629"], ["84497.20", "3.977819"], ["84505.70", "4.881868"], ["84514.20", "4.701058"], ["84522.70", "4.249034"]], "bids": [["84262.87", "0"], ["84252.11", "0"], ["84250.70", "0.001384"], ["84248.70", "0.003643"], ["84246.70", "0.009587"], ["84244.70", "0.025229"], ["84242.70", "0.066391"], ["84240.70", "0.174715"], ["84238.70", "0.459775"], ["84236.70", "1.209936"], ["84234.70", "3.184041"], ["84233.20", "0.352020"], ["84231.30", "0.274590"], ["84230.60", "0.320670"], ["84230.00", "0"], ["84229.00", "3.901260"], ["84228.40", "0.383490"], ["84228.10", "0"], ["84226.90", "0"], ["84223.10", "1.017180"], ["84222.10", "0"], ["84220.00", "0.026100"], ["84192.60", "4.429844"], ["84184.10", "4.068224"], ["84175.60", "4.881868"], ["84167.10", "4.701058"], ["84163.85", "0.072042"], ["84158.60", "5.424298"], ["84150.10", "3.887414"], ["84141.60", "4.158629"], ["84133.10", "3.977819"], ["84124.60", "5.333893"], ["84116.10", "4.791463"], ["84107.60", "4.610654"], ["84099.10", "5.514703"], ["84090.60", "4.972273"], ["84082.10", "5.153083"], ["84073.60", "5.062678"], ["84065.10", "4.339439"], ["84056.60", "4.249034"], ["84048.10", "5.605108"], ["84031.10", "5.243488"], ["83899.58", "0.000010"], ["83898.68", "0.000010"]], "checksum": -1076611178, "ts": "1742142224052"}], "ts": 1742142224056, "record_time": 1742142223.164262}
{"action": "update", "arg": {"instType": "SPOT", "channel": "books", "instId": "BTCUSDT"}, "data": [{"asks": [["84284.07", "0.012680"], ["84305.10", "0.007751"], ["84307.10", "0.020396"], ["84309.09", "0.069807"], ["84309.10", "0.053675"], ["84311.10", "0.141249"], ["84313.10", "0.371891"], ["84315.10", "0.978420"], ["84317.10", "2.574787"], ["84319.10", "6.775757"], ["84320.70", "0.042660"], ["84324.30", "0.665190"], ["84324.90", "0"], ["84329.70", "6.333150"], ["84337.00", "0.180000"], ["84361.20", "5.243488"], ["84369.70", "5.605108"], ["84378.20", "5.062678"], ["84386.70", "5.333893"], ["84395.20", "5.514703"], ["84403.70", "4.701058"], ["84412.20", "4.249034"], ["84420.70", "4.068224"], ["84429.20", "4.520249"], ["84437.70", "4.791463"], ["84454.70", "4.881868"], ["84463.20", "4.429844"], ["84471.70", "4.339439"], ["84480.20", "3.887414"], ["84488.70", "5.153083"], ["84505.70", "4.158629"], ["84514.20", "4.610654"], ["84522.70", "4.972273"], ["84864.99", "0"], ["84866.10", "0"]], "bids": [["84274.13", "0.201630"], ["84265.49", "0.000070"], ["84262.71", "0"], ["84252.12", "0.095486"], ["84242.70", "0.066579"], ["84240.70", "0.175208"], ["84238.70", "0.461073"], ["84236.70", "1.213349"], ["84234.70", "3.193025"], ["84223.70", "0.120000"], ["84223.10", "0.987180"], ["84220.00", "0"], ["84192.60", "5.153083"], ["84184.10", "4.972273"], ["84175.60", "4.429844"], ["84167.10", "5.424298"], ["84164.00", "0"], ["84163.85", "0"], ["84158.60", "5.514703"], ["84150.10", "4.520249"], ["84141.60", "4.068224"], ["84133.10", "4.158629"], ["84124.60", "5.243488"], ["84116.10", "3.977819"], ["84107.60", "5.333893"], ["84099.10", "5.605108"], ["84090.60", "4.610654"], ["84082.10", "4.339439"], ["84065.10", "3.887414"], ["84056.60", "4.791463"], ["84048.10", "4.249034"], ["84039.60", "4.881868"], ["84031.10", "4.701058"], ["83896.11", "0.000094"], ["83896.00", "0.000133"], ["83895.65", "0.000013"]], "checksum": -1574479813, "ts": "1742142224253"}], "ts": 1742142224259, "record_time": 1742142223.367621}
{"action": "update", "arg": {"instType": "SPOT", "channel": "books", "instId": "BTCUSDT"}, "data": [{"asks": [["84284.07", "0"], ["84301.10", "0.001412"], ["84301.57", "0.062760"], ["84303.10", "0.003716"], ["84305.10", "0.009779"], ["84307.10", "0.025735"], ["84309.10", "0.067723"], ["84311.10", "0.178218"], ["84313.07", "0"], ["84313.10", "0.468995"], ["84315.10", "1.234197"], ["84317.10", "3.247887"], ["84319.10", "8.547072"], ["84320.70", "0.121620"], ["84322.80", "0.258030"], ["84324.30", "0.407160"], ["84325.80", "0.014460"], ["84327.40", "0.269760"], ["84328.40", "0.015180"], ["84328.80", "0.015060"], ["84335.90", "0.177960"], ["84336.30", "0"], ["84337.00", "0"], ["84361.20", "4.429844"], ["84369.70", "5.424298"], ["84378.20", "4.701058"], ["84386.70", "4.520249"], ["84395.20", "4.972273"], ["84403.70", "4.068224"], ["84412.20", "5.062678"], ["84420.70", "4.610654"], ["84429.20", "4.249034"], ["84437.70", "5.605108"], ["84446.20", "5.514703"], ["84454.70", "5.333893"], ["84463.20", "4.158629"], ["84471.70", "4.881868"], ["84480.20", "5.153083"], ["84488.70", "5.243488"], ["84497.20", "4.791463"], ["84505.70", "3.887414"], ["84514.20", "3.977819"], ["84522.70", "4.339439"], ["84864.69", "0"], ["84864.86", "0"]], "bids": [["84272.95", "0"], ["84270.56", "0"], ["84265.49", "0"], ["84263.09", "0.055162"], ["84256.49", "0"], ["84253.61", "0.184828"], ["84250.70", "0.001226"], ["84248.70", "0.003226"], ["84246.70", "0.008488"], ["84244.70", "0.022338"], ["84242.70", "0.058784"], ["84240.70", "0.154695"], ["84238.70", "0.407093"], ["84238.42", "0.216643"], ["84236.70", "1.071297"], ["84234.70", "2.819202"], ["84233.20", "0.352860"], ["84233.00", "0.035790"], ["84232.50", "0.427440"], ["84232.20", "0"], ["84229.80", "0"], ["84229.00", "1.550670"], ["84226.30", "0"], ["84220.00", "0.026100"], ["84192.60", "4.972273"], ["84184.10", "4.520249"], ["84175.60", "4.610654"], ["84167.10", "5.605108"], ["84158.60", "3.977819"], ["84150.10", "5.424298"], ["84141.60", "4.339439"], ["84133.10", "4.701058"], ["84124.60", "4.881868"], ["84116.10", "4.791463"], ["84107.60", "5.153083"], ["84099.10", "5.062678"], ["84090.60", "5.514703"], ["84082.10", "5.333893"], ["84073.60", "4.249034"], ["84065.10", "4.068224"], ["84056.60", "3.887414"], ["84048.10", "4.429844"], ["84039.60", "5.243488"], ["84031.10", "4.158629"], ["83895.00", "0.006121"], ["83894.74", "0.000068"], ["83894.17", "0.000022"], ["83893.81", "0.000010"]], "checksum": -854283618, "ts": "1742142224455"}], "ts": 1742142224458, "record_time": 1742142223.566009}
{"action": "update", "arg": {"instType": "SPOT", "channel": "books", "instId": "BTCUSDT"}, "data": [{"asks": [["84301.10", "0.001293"], ["84302.59", "0.029802"], ["84303.10", "0.003401"], ["84305.10", "0.008950"], ["84307.10", "0.023554"], ["84309.10", "0.061983"], ["84311.10", "0.163113"], ["84313.10", "0.429246"], ["84315.10", "1.129780"], ["84315.53", "0"], ["84317.09", "0.492452"], ["84317.10", "2.973105"], ["84319.10", "7.823960"], ["84319.80", "0.383550"], ["84320.70", "0.121410"], ["84320.90", "0"], ["84322.80", "0"], ["84325.40", "0.682560"], ["84325.60", "0"], ["84325.80", "0.035580"], ["84329.70", "5.683380"], ["84332.30", "0.171750"], ["84361.20", "4.791463"], ["84369.70", "5.153083"], ["84378.20", "4.881868"], ["84386.70", "5.514703"], ["84403.70", "3.977819"], ["84412.20", "5.243488"], ["84420.70", "5.062678"], ["84429.20", "5.333893"], ["84437.70", "4.158629"], ["84446.20", "4.520249"], ["84454.70", "4.701058"], ["84463.20", "3.887414"], ["84471.70", "4.249034"], ["84480.20", "5.424298"], ["84488.70", "4.610654"], ["84497.20", "4.429844"], ["84505.70", "5.605108"], ["84514.20", "4.339439"], ["84522.70", "4.068224"], ["84862.90", "0"]], "bids": [["84274.13", "0.201470"], ["84264.72", "1.895115"], ["84260.62", "0.000070"], ["84256.50", "0.239921"], ["84247.86", "2.550217"], ["84246.70", "0.008288"], ["84244.70", "0.021810"], ["84242.70", "0.057289"], ["84240.70", "0.150760"], ["84238.70", "0.396739"], ["84236.70", "1.044050"], ["84234.70", "2.747499"], ["84233.20", "0.243360"], ["84231.30", "0"], ["84229.00", "0.440790"], ["84228.20", "0.274590"], ["84225.00", "1.300560"], ["84223.70", "0.090000"], ["84221.10", "2.349960"], ["84192.60", "5.514703"], ["84184.10", "4.881868"], ["84175.60", "4.339439"], ["84168.00", "0.000121"], ["84167.10", "3.887414"], ["84158.60", "4.791463"], ["84141.60", "3.977819"], ["84133.10", "5.333893"], ["84124.60", "5.605108"], ["84116.10", "4.972273"], ["84107.60", "4.429844"], ["84099.10", "4.068224"], ["84090.60", "5.243488"], ["84082.10", "4.701058"], ["84073.60", "4.610654"], ["84065.10", "4.158629"], ["84056.60", "4.249034"], ["84048.10", "5.062678"], ["84039.60", "4.520249"], ["84031.10", "5.153083"], ["83895.65", "0"], ["83895.00", "0"], ["83894.74", "0"], ["83894.17", "0"], ["83893.81", "0"]], "checksum": 81052576, "ts": "1742142224656"}], "ts": 1742142224660, "record_time": 1742142223.770062}
{"action": "update", "arg": {"instType": "SPOT", "channel": "books", "instId": "BTCUSDT"}, "data": [{"asks": [["84282.19", "0.012680"], ["84288.58", "0"], ["84305.10", "0.009001"], ["84307.10", "0.023687"], ["84309.10", "0.062335"], ["84311.10", "0.164038"], ["84313.10", "0.431679"], ["84315.10", "1.135997"], ["84317.10", "2.989467"], ["84319.10", "7.867019"], ["84319.60", "0.152850"], ["84319.80", "0.001009"], ["84320.10", "0"], ["84320.70", "0.121590"], ["84322.30", "0.313350"], ["84323.00", "0.142680"], ["84324.30", "0.407340"], ["84325.40", "0.682740"], ["84331.70", "0.376230"], ["84335.90", "0"], ["84361.20", "4.249034"], ["84369.70", "4.610654"], ["84378.20", "4.339439"], ["84386.70", "3.977819"], ["84395.20", "5.062678"], ["84403.70", "5.605108"], ["84412.20", "5.514703"], ["84420.70", "5.153083"], ["84429.20", "4.791463"], ["84437.70", "4.881868"], ["84446.20", "3.887414"], ["84463.20", "4.158629"], ["84471.70", "5.243488"], ["84480.20", "4.972273"], ["84488.70", "5.333893"], ["84497.20", "5.424298"], ["84505.70", "4.429844"], ["84514.20", "4.520249"], ["84862.90", "0.000169"], ["84864.69", "0.000052"]], "bids": [["84263.51", "0.055161"], ["84263.09", "0"], ["84262.87", "0.000070"], ["84260.62", "0"], ["84250.70", "0.001024"], ["84248.70", "0.001699"], ["84247.87", "0.784220"], ["84247.84", "0"], ["84246.70", "0.004470"], ["84244.70", "0.011764"], ["84242.70", "0.030958"], ["84240.70", "0.081469"], ["84238.70", "0.214392"], ["84238.42", "0.161749"], ["84236.70", "0.564189"], ["84235.05", "0"], ["84234.70", "1.484596"], ["84233.20", "0.449070"], ["84233.00", "0.035580"], ["84232.60", "0.760470"], ["84232.50", "0.427230"], ["84230.60", "0.320850"], ["84229.00", "0.440970"], ["84225.50", "0.030000"], ["84225.00", "1.270560"], ["84220.00", "0"], ["84219.60", "0.090000"], ["84192.60", "4.701058"], ["84184.10", "5.605108"], ["84175.60", "3.977819"], ["84167.10", "4.429844"], ["84158.60", "4.158629"], ["84141.60", "5.062678"], ["84124.60", "5.153083"], ["84116.10", "4.068224"], ["84107.60", "4.972273"], ["84099.10", "5.243488"], ["84090.60", "4.520249"], ["84082.10", "4.610654"], ["84073.60", "4.249034"], ["84065.10", "4.791463"], ["84056.60", "5.514703"], ["84048.10", "3.887414"], ["84039.60", "4.881868"], ["84031.10", "4.339439"]], "checksum": 648466212, "ts": "1742142224862"}], "ts": 1742142224865, "record_time": 1742142223.973}
{"action": "update", "arg": {"instType": "SPOT", "channel": "books", "instId": "BTCUSDT"}, "data": [{"asks": [["84274.14", "1.503737"], ["84280.80", "0.148098"], ["84282.19", "0"], ["84307.10", "0.023899"], ["84309.10", "0.062892"], ["84311.10", "0.165505"], ["84313.10", "0.435538"], ["84315.10", "1.146303"], ["84317.10", "3.016587"], ["84319.10", "7.938536"], ["84319.60", "0.001009"], ["84319.80", "0"], ["84322.30", "0.482340"], ["84322.70", "0.469080"], ["84335.20", "0.198000"], ["84335.30", "0.090000"], ["84335.80", "0"], ["84369.70", "5.062678"], ["84378.20", "3.977819"], ["84386.70", "4.972273"], ["84395.20", "5.424298"], ["84403.70", "4.881868"], ["84412.20", "5.605108"], ["84420.70", "4.429844"], ["84429.20", "3.887414"], ["84437.70", "4.701058"], ["84446.20", "4.520249"], ["84454.70", "4.791463"], ["84463.20", "4.610654"], ["84471.70", "5.514703"], ["84480.20", "4.158629"], ["84488.70", "5.153083"], ["84497.20", "5.333893"], ["84505.70", "5.243488"], ["84514.20", "4.339439"], ["84864.69", "0"]], "bids": [["84248.70", "0.002606"], ["84246.70", "0.006860"], ["84244.70", "0.018051"], ["84242.70", "0.047382"], ["84240.70", "0.124689"], ["84238.70", "0.328129"], ["84236.70", "0.863498"], ["84234.70", "2.272362"], ["84234.20", "0.001039"], ["84234.10", "1.099650"], ["84233.20", "0.001014"], ["84232.60", "0"], ["84229.00", "0.882060"], ["84226.30", "1.350000"], ["84223.30", "2.398110"], ["84221.10", "0"], ["84220.40", "0"], ["84219.60", "0"], ["84192.60", "5.153083"], ["84184.10", "5.424298"], ["84175.60", "4.429844"], ["84167.10", "4.881868"], ["84165.00", "0.000159"], ["84158.60", "4.791463"], ["84150.10", "5.062678"], ["84141.60", "3.887414"], ["84133.10", "5.514703"], ["84124.60", "4.520249"], ["84116.10", "4.339439"], ["84107.60", "4.249034"], ["84099.10", "4.610654"], ["84090.60", "4.701058"], ["84082.10", "4.972273"], ["84073.60", "5.243488"], ["84065.10", "4.158629"], ["84056.60", "4.068224"], ["84048.10", "5.605108"], ["84039.60", "5.333893"], ["84031.10", "3.977819"]], "checksum": 787154674, "ts": "1742142225063"}], "ts": 1742142225066, "record_time": 1742142224.174015}
{"action": "update", "arg": {"instType": "SPOT", "channel": "books", "instId": "BTCUSDT"}, "data": [{"asks": [["84274.14", "1.491057"], ["84280.79", "0.044429"], ["84315.10", "1.146327"], ["84317.10", "3.016651"], ["84319.10", "7.938685"], ["84324.30", "0.407160"], ["84325.40", "0.682560"], ["84334.20", "0"], ["84335.20", "0"], ["84335.30", "0"], ["84335.50", "0"], ["84361.20", "3.887414"], ["84369.70", "4.791463"], ["84386.70", "4.249034"], ["84395.20", "5.333893"], ["84403.70", "4.610654"], ["84412.20", "4.158629"], ["84420.70", "4.701058"], ["84429.20", "5.153083"], ["84437.70", "5.605108"], ["84446.20", "4.881868"], ["84454.70", "4.972273"], ["84463.20", "5.424298"], ["84471.70", "5.243488"], ["84480.20", "5.514703"], ["84488.70", "4.429844"], ["84497.20", "4.520249"], ["84505.70", "4.068224"], ["84522.70", "5.062678"], ["84864.69", "0.000052"], ["84864.86", "0.000041"], ["84864.99", "0.000033"]], "bids": [["84240.70", "0.124572"], ["84238.70", "0.327823"], ["84236.70", "0.862692"], ["84234.70", "2.270093"], ["84234.10", "0.236310"], ["84227.10", "0.030000"], ["84225.50", "0"], ["84192.60", "3.887414"], ["84184.10", "5.605108"], ["84175.60", "4.610654"], ["84167.10", "5.062678"], ["84158.60", "4.158629"], ["84150.10", "4.339439"], ["84141.60", "5.424298"], ["84133.10", "4.429844"], ["84124.60", "4.701058"], ["84116.10", "4.791463"], ["84107.60", "4.972273"], ["84099.10", "5.243488"], ["84090.60", "4.520249"], ["84082.10", "4.881868"], ["84073.60", "4.249034"], ["84065.10", "5.514703"], ["84056.60", "5.153083"], ["84048.10", "4.068224"]], "checksum": -1839267150, "ts": "1742142225267"}], "ts": 1742142225272, "record_time": 1742142224.381507}
