{"event": "subscribe", "arg": {"instType": "SPOT", "channel": "books", "instId": "BTCUSDT"}, "record_time": 1742554938.794711, "EXCHANGE": "BITGET"}
{"action": "snapshot", "arg": {"instType": "SPOT", "channel": "books", "instId": "BTCUSDT"}, "data": [{"asks": [["84090.00", "0.265143"], ["84090.01", "0.000220"], ["84090.02", "0.000100"], ["84090.03", "0.000100"], ["84094.98", "0.035480"], ["84097.76", "0.086100"], ["84103.08", "0.000222"], ["84109.20", "0.059955"], ["84109.21", "0.016008"], ["84109.24", "0.005575"], ["84109.27", "0.000865"], ["84109.29", "0.006307"], ["84109.35", "0.007162"], ["84110.39", "0.014272"], ["84110.40", "0.112995"], ["84113.40", "0.172440"], ["84113.41", "0.209200"], ["84115.51", "0.224100"], ["84115.80", "0.035952"], ["84116.07", "0.119870"], ["84117.49", "0.035961"], ["84117.89", "0.194312"], ["84117.90", "0.313967"], ["84117.93", "0.006356"], ["84117.97", "0.006356"], ["84118.09", "0.006356"], ["84118.22", "0.017444"], ["84119.35", "0.006356"], ["84119.46", "0.010984"], ["84119.47", "0.006356"], ["84120.00", "0.002000"], ["84120.44", "0.006356"], ["84121.02", "0.006356"], ["84121.04", "0.006356"], ["84121.40", "0.119883"], ["84121.50", "0.006356"], ["84121.53", "0.006356"], ["84121.77", "0.119867"], ["84122.16", "0.016429"], ["84122.94", "0.016429"], ["84123.07", "0.006357"], ["84124.39", "0.545578"], ["84124.40", "1.531031"], ["84124.70", "0.119850"], ["84124.75", "0.010985"], ["84124.86", "0.009990"], ["84124.97", "0.010988"], ["84125.73", "0.119858"], ["84125.98", "0.015892"], ["84126.21", "0.070525"], ["84126.22", "0.209200"], ["84126.38", "0.009989"], ["84127.18", "0.015895"], ["84130.73", "0.003742"], ["84130.74", "0.012472"], ["84137.08", "0.053092"], ["84137.09", "0.209200"], ["84142.90", "0.000958"], ["84146.96", "0.054254"], ["84146.97", "0.180847"], ["84149.99", "0.001099"], ["84150.00", "0.002064"], ["84150.84", "0.001598"], ["84152.37", "0.836222"], ["84152.38", "3.568246"], ["84152.91", "0.001597"], ["84154.10", "0.001033"], ["84156.10", "0.001040"], ["84158.10", "0.001707"], ["84160.10", "0.004492"], ["84161.41", "0.712915"], ["84161.58", "0.209200"], ["84162.10", "0.011562"], ["84164.10", "0.030426"], ["84166.10", "0.080068"], ["84168.10", "0.210705"], ["84170.10", "0.554486"], ["84172.10", "1.459174"], ["84172.50", "0.207473"], ["84174.10", "3.839933"], ["84174.40", "0.059460"], ["84174.51", "0.000388"], ["84175.00", "0.971880"], ["84175.21", "0.405582"], ["84175.70", "2.354700"], ["84177.00", "0.075000"], ["84177.40", "0.150000"], ["84177.60", "0.070560"], ["84177.80", "0.240000"], ["84178.40", "0.015000"], ["84178.41", "0.209200"], ["84178.80", "0.030000"], ["84179.00", "1.306440"], ["84179.90", "0.144510"], ["84180.00", "0.002000"], ["84180.30", "0.102840"], ["84180.60", "1.069320"], ["84180.80", "0.035640"], ["84181.20", "0.120000"], ["84181.70", "1.130520"], ["84182.10", "0.120180"], ["84182.30", "0.534660"], ["84182.90", "0.300000"], ["84183.00", "0.156000"], ["84183.24", "1.781827"], ["84183.40", "0.301050"], ["84183.50", "0.612810"], ["84183.80", "0.120000"], ["84184.10", "0.453360"], ["84184.30", "0.010770"], ["84184.40", "0.480000"], ["84184.50", "0.027000"], ["84186.81", "0.209200"], ["84188.00", "0.000202"], ["84190.00", "0.001000"], ["84195.21", "0.209200"], ["84203.61", "0.209200"], ["84208.62", "0.125592"], ["84209.64", "0.001810"], ["84210.00", "0.002000"], ["84212.01", "0.209200"], ["84213.46", "0.000163"], ["84216.10", "4.980838"], ["84218.83", "0.003620"], ["84220.41", "0.209200"], ["84220.57", "0.057001"], ["84222.80", "0.001428"], ["84224.16", "0.010000"], ["84224.60", "4.437474"], ["84225.80", "0.301470"], ["84228.81", "0.209200"], ["84232.06", "0.011010"], ["84233.10", "5.071398"], ["84233.38", "0.001273"], ["84234.12", "0.000044"], ["84237.21", "0.209200"], ["84240.00", "0.002000"], ["84241.60", "5.343080"], ["84242.91", "0.071253"], ["84245.00", "0.000149"], ["84250.00", "0.000684"], ["84250.10", "4.709156"], ["84252.44", "0.000143"], ["84253.92", "0.209200"], ["84258.20", "0.296868"], ["84258.60", "4.528034"], ["84259.99", "0.000017"], ["84266.08", "0.000016"], ["84266.67", "0.000078"], ["84267.10", "4.890277"], ["84269.24", "0.000032"], ["84270.00", "0.002692"], ["84270.70", "0.209200"], ["84270.98", "0.000052"], ["84272.72", "0.000105"], ["84275.00", "0.000671"], ["84275.60", "3.984670"], ["84279.10", "0.209200"], ["84280.00", "0.001261"], ["84284.10", "4.256352"], ["84285.00", "0.000031"], ["84285.71", "0.000010"], ["84285.95", "0.000028"], ["84286.79", "0.000016"], ["84286.96", "0.024945"], ["84287.50", "0.209276"], ["84288.30", "0.001469"], ["84288.89", "0.000361"], ["84291.53", "0.162362"], ["84292.60", "5.433641"], ["84294.68", "0.000019"], ["84295.90", "0.209200"], ["84297.06", "0.000035"], ["84300.00", "0.023631"], ["84301.10", "5.614762"], ["84304.31", "0.209200"], ["84307.00", "0.000113"], ["84307.23", "0.000008"], ["84309.09", "0.000010"], ["84309.60", "4.075231"], ["84310.34", "0.000331"], ["84310.35", "0.000146"], ["84311.11", "0.000025"], ["84312.50", "0.000125"], ["84312.72", "0.209200"], ["84313.03", "0.000024"], ["84314.97", "0.000008"], ["84316.67", "0.000322"], ["84317.24", "0.000135"], ["84317.40", "0.000010"], ["84318.10", "5.524202"], ["84318.59", "0.000027"], ["84319.15", "0.000137"], ["84319.18", "0.000039"], ["84320.00", "0.000019"], ["84321.13", "0.209200"], ["84322.11", "0.000008"], ["84324.32", "0.000059"], ["84325.00", "0.002294"], ["84325.07", "0.000161"], ["84326.09", "0.000010"], ["84326.42", "0.000023"], ["84326.60", "4.799716"], ["84327.14", "0.000039"], ["84327.73", "0.041940"], ["84328.95", "0.000174"], ["84329.54", "0.209200"], ["84329.64", "0.000026"], ["84330.00", "0.002000"], ["84332.00", "0.000008"], ["84333.33", "0.002262"], ["84333.36", "0.000010"], ["84333.38", "0.000008"], ["84334.48", "0.000096"], ["84334.77", "0.000022"], ["84335.10", "4.346913"], ["84335.90", "0.300375"], ["84336.00", "0.000133"], ["84336.23", "0.000013"], ["84336.29", "0.000010"], ["84336.34", "0.000176"], ["84337.25", "0.000067"], ["84337.35", "0.000008"], ["84337.79", "0.001720"], ["84337.95", "0.209200"], ["84338.46", "0.000015"], ["84339.21", "0.000010"], ["84339.29", "0.000029"], ["84339.62", "0.000051"], ["84340.00", "0.018287"], ["84340.72", "0.000066"], ["84341.01", "0.000008"], ["84342.11", "0.000051"], ["84342.63", "0.000009"], ["84342.70", "0.000423"], ["84343.07", "0.000014"], ["84343.60", "5.161959"], ["84343.70", "0.000075"], ["84343.75", "0.000012"], ["84343.97", "0.000188"], ["84346.36", "0.209200"], ["84346.43", "0.000128"], ["84346.94", "0.000085"], ["84347.69", "0.000009"], ["84347.83", "0.016818"], ["84348.21", "0.000036"], ["84348.27", "0.012402"], ["84348.62", "0.000072"], ["84350.00", "0.002253"], ["84350.79", "0.000033"], ["84352.10", "4.165792"], ["84354.58", "0.000115"], ["84354.64", "0.000018"], ["84354.77", "0.209200"], ["84354.82", "0.000078"], ["84354.84", "0.000194"], ["84356.98", "0.000048"], ["84357.14", "0.000273"], ["84358.10", "0.001403"], ["84358.29", "0.000024"], ["84359.83", "0.000010"], ["84360.00", "0.002661"], ["84360.60", "4.618595"], ["84363.18", "0.209200"], ["84363.63", "0.000057"], ["84363.64", "0.000078"], ["84366.14", "0.000162"], ["84366.15", "0.000061"], ["84366.19", "0.000022"], ["84366.60", "0.000011"], ["84366.96", "0.000018"], ["84367.10", "0.000014"], ["84367.82", "0.000476"], ["84368.38", "0.000009"], ["84368.42", "0.000284"], ["84369.10", "3.894110"], ["84370.00", "0.000052"], ["84370.59", "0.000071"], ["84370.97", "0.000020"], ["84371.59", "0.209200"], ["84371.86", "0.000012"], ["84375.00", "0.004006"], ["84376.31", "0.000016"], ["84377.60", "5.252520"], ["84378.11", "0.000008"], ["84378.38", "0.000009"], ["84378.45", "0.000015"], ["84380.00", "0.032216"], ["84381.82", "0.000008"], ["84382.00", "0.000035"], ["84382.35", "0.000071"], ["84383.41", "0.000053"], ["84383.69", "0.000248"], ["84384.38", "0.000424"], ["84384.61", "0.000008"], ["84386.19", "0.000019"], ["84386.67", "0.000013"], ["84387.50", "0.006969"], ["84387.76", "0.000024"], ["84389.61", "0.000088"], ["84389.90", "0.000012"], ["84390.00", "0.002000"], ["84390.01", "0.000387"], ["84391.30", "0.000018"], ["84393.31", "0.000050"], ["84396.55", "0.000016"], ["84396.98", "0.007500"], ["84397.59", "0.000008"], ["84397.69", "0.000275"], ["84398.26", "0.000068"], ["84399.54", "0.000030"], ["84399.91", "0.000018"], ["84399.99", "0.000022"], ["84400.00", "0.060615"], ["84400.18", "0.000024"], ["84402.40", "0.001273"], ["84403.39", "0.000023"], ["84403.76", "0.000099"], ["84403.98", "0.007500"], ["84404.26", "0.000137"], ["84404.28", "0.000039"], ["84405.00", "0.000402"], ["84406.06", "0.000008"], ["84406.83", "0.000064"], ["84407.50", "0.000031"], ["84410.00", "0.000059"], ["84410.04", "0.000025"], ["84411.11", "0.000361"], ["84411.43", "0.000008"], ["84411.76", "0.000101"], ["84411.77", "0.000020"], ["84412.50", "0.000049"], ["84413.04", "0.000010"], ["84413.33", "0.000073"], ["84413.79", "0.000135"], ["84414.29", "0.000074"], ["84414.41", "0.000051"], ["84415.09", "0.000008"], ["84416.67", "0.000355"], ["84418.34", "0.000046"], ["84419.69", "0.000023"], ["84420.00", "0.002640"], ["84420.17", "0.041940"], ["84422.71", "0.000010"], ["84423.08", "0.000067"], ["84423.53", "0.000105"], ["84424.00", "0.000022"], ["84424.12", "0.000146"], ["84425.00", "0.002205"], ["84425.69", "0.000314"], ["84426.68", "0.000101"], ["84427.08", "0.000014"], ["84427.92", "0.000323"], ["84428.57", "0.000057"], ["84429.82", "0.000022"], ["84430.50", "0.000113"], ["84430.74", "0.000010"], ["84430.77", "0.000015"], ["84431.23", "0.000039"], ["84432.43", "0.000008"], ["84433.33", "0.000347"], ["84434.78", "0.000008"], ["84435.26", "0.000161"], ["84436.26", "0.000009"], ["84437.14", "0.000017"], ["84437.50", "0.000725"], ["84437.75", "0.000013"], ["84438.44", "0.000176"], ["84440.00", "0.000544"], ["84442.54", "0.000096"], ["84443.07", "0.000423"], ["84444.25", "0.000013"], ["84444.41", "0.000371"], ["84444.44", "0.000574"], ["84444.92", "0.000022"], ["84446.04", "0.000016"], ["84446.38", "0.000013"], ["84446.43", "0.000036"], ["84447.80", "0.000718"], ["84448.75", "0.000066"], ["84448.98", "0.000085"], ["84449.11", "0.000028"], ["84449.34", "0.000010"], ["84450.00", "0.010457"], ["84451.88", "0.000010"], ["84452.66", "0.000009"], ["84453.76", "0.000054"], ["84454.43", "0.000061"], ["84454.53", "0.000019"], ["84454.55", "0.000083"], ["84454.60", "0.000093"], ["84455.31", "0.000028"], ["84456.14", "0.000033"], ["84456.52", "0.002633"], ["84457.00", "0.000009"], ["84457.40", "0.002343"], ["84458.06", "0.000020"], ["84458.72", "0.000072"], ["84458.82", "0.000071"], ["84458.97", "0.000153"], ["84459.08", "0.000008"], ["84459.22", "0.000188"], ["84459.69", "0.000051"], ["84460.00", "0.000622"], ["84460.23", "0.000010"], ["84460.49", "0.000009"], ["84460.87", "0.000069"], ["84460.91", "0.000012"], ["84461.00", "0.000008"], ["84462.00", "1.706479"], ["84462.50", "0.000076"], ["84464.28", "0.000008"], ["84465.83", "0.000016"], ["84466.67", "0.000157"], ["84470.34", "0.000017"], ["84470.59", "0.000071"], ["84471.30", "0.510950"], ["84473.14", "0.000126"], ["84473.68", "0.000192"], ["84474.78", "0.000099"], ["84475.00", "0.009271"], ["84475.81", "0.000039"], ["84476.97", "0.000063"], ["84477.61", "0.000095"], ["84477.67", "0.000008"], ["84478.74", "0.000036"], ["84479.37", "0.000090"], ["84480.00", "0.003246"], ["84481.00", "0.000069"], ["84481.77", "0.000011"], ["84482.67", "0.000133"], ["84482.76", "0.000016"], ["84485.20", "0.000537"], ["84485.39", "0.000020"], ["84485.71", "0.000128"], ["84485.98", "0.000034"], ["84486.49", "0.000009"], ["84486.82", "0.000135"], ["84487.00", "0.000119"], ["84487.16", "0.000035"], ["84487.32", "0.000024"], ["84487.95", "0.000008"], ["84488.88", "0.000025"], ["84489.36", "0.000137"], ["84489.39", "0.000039"], ["84489.80", "0.000010"], ["84490.00", "0.007510"], ["84490.13", "0.000093"], ["84490.91", "0.000018"], ["84491.26", "0.000008"], ["84491.87", "0.000019"], ["84492.06", "0.000009"], ["84496.43", "0.000273"], ["84496.66", "0.004837"], ["84496.73", "0.000043"], ["84497.14", "0.000008"], ["84497.26", "0.000010"], ["84500.00", "0.124015"], ["84500.03", "0.000010"], ["84500.04", "0.000008"], ["84500.11", "0.000012"], ["84501.24", "0.000010"], ["84501.28", "0.000019"], ["84501.32", "0.000326"], ["84501.99", "0.000009"], ["84503.33", "0.010000"], ["84503.57", "0.000074"], ["84504.50", "0.000051"], ["84504.74", "0.000013"], ["84506.54", "0.000008"], ["84508.00", "0.001210"], ["84508.37", "0.000050"], ["84508.46", "0.000013"], ["84508.47", "0.000023"], ["84510.00", "0.000402"], ["84510.34", "0.000135"], ["84512.00", "0.000012"], ["84512.19", "0.000016"], ["84512.61", "0.041940"], ["84512.95", "0.000023"], ["84514.29", "0.000059"], ["84516.67", "0.000010"], ["84517.54", "0.000022"], ["84517.86", "0.000016"], ["84518.98", "0.000029"], ["84520.00", "0.000318"], ["84520.50", "0.000238"], ["84520.67", "0.002384"], ["84521.85", "0.000033"], ["84522.06", "0.000041"], ["84523.08", "0.000015"], ["84523.48", "0.000015"], ["84523.81", "0.000024"], ["84524.00", "0.000035"], ["84524.83", "0.000009"], ["84525.00", "0.003286"], ["84525.82", "0.000099"], ["84527.47", "0.000608"], ["84528.57", "0.000008"], ["84530.00", "0.000031"]], "bids": [["84089.99", "1.871558"], ["84089.80", "9.284599"], ["84089.19", "2.327940"], ["84089.18", "0.253588"], ["84089.13", "0.008895"], ["84089.12", "0.010333"], ["84089.00", "0.001058"], ["84088.69", "0.008534"], ["84088.68", "0.005581"], ["84088.64", "0.009862"], ["84088.62", "0.004827"], ["84088.60", "0.005169"], ["84088.58", "0.005117"], ["84088.40", "0.001036"], ["84088.20", "0.036690"], ["84088.10", "3.703170"], ["84087.90", "0.068190"], ["84087.40", "1.350000"], ["84086.30", "0.072030"], ["84085.90", "0.090540"], ["84085.20", "0.823770"], ["84084.70", "0.144510"], ["84083.97", "0.276676"], ["84083.96", "0.000357"], ["84083.90", "0.092731"], ["84083.80", "0.073680"], ["84083.50", "0.004140"], ["84083.30", "0.305400"], ["84083.20", "0.006060"], ["84083.10", "0.035640"], ["84082.30", "0.015000"], ["84081.90", "0.067800"], ["84081.80", "0.248820"], ["84081.71", "0.313967"], ["84081.52", "0.008268"], ["84080.50", "0.231990"], ["84080.10", "0.120000"], ["84079.90", "0.067800"], ["84079.89", "0.008059"], ["84079.70", "0.072300"], ["84079.20", "0.132570"], ["84078.70", "0.072570"], ["84078.50", "0.072690"], ["84077.90", "0.067980"], ["84077.70", "2.243070"], ["84077.20", "0.009810"], ["84077.00", "0.223163"], ["84076.00", "0.000015"], ["84075.70", "0.153580"], ["84075.44", "0.089463"], ["84075.00", "0.000015"], ["84074.87", "0.247526"], ["84074.00", "0.000015"], ["84073.76", "0.083919"], ["84073.36", "0.017813"], ["84073.06", "0.018250"], ["84073.00", "0.000015"], ["84072.54", "0.028858"], ["84072.51", "0.005945"], ["84072.22", "0.008426"], ["84072.06", "0.008012"], ["84072.03", "0.006471"], ["84072.00", "0.008611"], ["84071.80", "0.008319"], ["84071.70", "0.055642"], ["84071.64", "0.025178"], ["84071.30", "0.009209"], ["84071.24", "0.006905"], ["84071.19", "0.007304"], ["84071.08", "0.017099"], ["84071.00", "0.000015"], ["84070.99", "3.051386"], ["84070.87", "0.007130"], ["84070.82", "0.007338"], ["84070.42", "0.007941"], ["84070.39", "0.008992"], ["84070.10", "0.224827"], ["84070.09", "0.051950"], ["84070.00", "0.000015"], ["84069.90", "0.017346"], ["84069.86", "0.008183"], ["84069.00", "0.000015"], ["84068.59", "0.209200"], ["84068.52", "0.018512"], ["84068.40", "0.012652"], ["84068.14", "0.004016"], ["84068.00", "0.000015"], ["84067.00", "0.000015"], ["84066.50", "0.268311"], ["84066.12", "0.076094"], ["84066.00", "0.000015"], ["84065.52", "0.222615"], ["84065.00", "0.000015"], ["84064.99", "0.021124"], ["84064.23", "0.008092"], ["84064.13", "0.008263"], ["84064.08", "0.005051"], ["84064.00", "0.000015"], ["84063.00", "0.000015"], ["84062.00", "0.000015"], ["84061.23", "0.259732"], ["84061.00", "0.000015"], ["84060.00", "0.183734"], ["84059.00", "0.000032"], ["84058.57", "0.000876"], ["84058.00", "0.000032"], ["84057.60", "0.000396"], ["84057.02", "0.073197"], ["84057.00", "0.000032"], ["84056.37", "0.713806"], ["84056.00", "0.000032"], ["84055.00", "0.000032"], ["84054.34", "0.056358"], ["84054.00", "0.000032"], ["84053.90", "0.010000"], ["84053.20", "0.000700"], ["84053.00", "0.000032"], ["84052.62", "0.017444"], ["84052.00", "0.000032"], ["84051.59", "0.209200"], ["84051.00", "0.000032"], ["84050.32", "0.006120"], ["84050.00", "0.000032"], ["84049.00", "0.000032"], ["84048.39", "0.007435"], ["84048.00", "0.000032"], ["84047.80", "5.614762"], ["84047.00", "0.000032"], ["84046.20", "0.200459"], ["84046.00", "0.000032"], ["84045.42", "0.008572"], ["84045.00", "0.000956"], ["84044.00", "0.000032"], ["84043.45", "0.007651"], ["84043.43", "0.007247"], ["84043.23", "0.007337"], ["84043.00", "0.000032"], ["84042.00", "0.000032"], ["84041.38", "0.003596"], ["84041.00", "0.000032"], ["84040.51", "0.001175"], ["84040.00", "0.001261"], ["84039.99", "0.209200"], ["84039.30", "4.980838"], ["84039.00", "0.000032"], ["84038.71", "0.001172"], ["84038.00", "0.000032"], ["84037.00", "0.000032"], ["84036.00", "0.000032"], ["84035.30", "0.010000"], ["84035.00", "0.000032"], ["84034.00", "0.000032"], ["84031.40", "0.209200"], ["84030.80", "5.071398"], ["84030.00", "0.002924"], ["84028.20", "0.000948"], ["84027.00", "0.000017"], ["84026.00", "0.000015"], ["84022.30", "4.618595"], ["84021.58", "0.209200"], ["84020.00", "0.001231"], ["84018.01", "0.001810"], ["84015.00", "0.000924"], ["84013.80", "4.256352"], ["84013.17", "0.209200"], ["84010.79", "0.000957"], ["84009.60", "0.003620"], ["84009.48", "0.071253"], ["84005.30", "4.437474"], ["84004.76", "0.209200"], ["84004.26", "0.003975"], ["84000.00", "0.003107"], ["83999.88", "0.057001"], ["83996.80", "5.343080"], ["83995.80", "0.209200"], ["83988.30", "4.165792"], ["83986.40", "0.209200"], ["83985.00", "0.000924"], ["83980.00", "0.001231"], ["83979.80", "5.161959"], ["83975.60", "0.209200"], ["83973.72", "0.012375"], ["83971.30", "5.252520"], ["83970.00", "0.004067"], ["83968.50", "0.303578"], ["83968.10", "0.024945"], ["83964.20", "0.209200"], ["83962.80", "4.799716"], ["83961.06", "0.125589"], ["83960.00", "0.001231"], ["83955.00", "0.000924"], ["83954.30", "4.709156"], ["83951.10", "0.209200"], ["83950.44", "0.005950"], ["83946.24", "0.010010"], ["83945.80", "5.524202"], ["83940.00", "0.003231"], ["83938.51", "0.209200"], ["83937.30", "3.984670"], ["83932.20", "0.001459"], ["83929.10", "0.300943"], ["83928.80", "4.528034"], ["83925.07", "0.209200"], ["83922.80", "0.001475"], ["83920.30", "4.075231"], ["83920.00", "0.001231"], ["83915.77", "0.209200"], ["83911.80", "5.433641"], ["83910.00", "0.002924"], ["83907.35", "0.209200"], ["83903.30", "4.890277"], ["83901.30", "0.308119"], ["83900.21", "0.005950"], ["83898.93", "0.209200"], ["83895.00", "0.000924"], ["83894.80", "4.346913"], ["83890.51", "0.209200"], ["83886.30", "3.894110"], ["83882.09", "0.209200"], ["83880.00", "0.003231"], ["83877.01", "0.000023"], ["83875.16", "0.000179"], ["83875.00", "0.000704"], ["83873.52", "0.000135"], ["83872.93", "0.001720"], ["83872.00", "0.001184"], ["83868.70", "0.001444"], ["83868.39", "0.002014"], ["83866.67", "0.002945"], ["83865.00", "0.000924"], ["83862.50", "0.006969"], ["83860.29", "0.000041"], ["83860.00", "0.001234"], ["83859.54", "0.000008"], ["83857.14", "0.000079"], ["83857.13", "0.000019"], ["83856.11", "0.010000"], ["83854.55", "0.000009"], ["83854.17", "0.000020"], ["83852.94", "0.000071"], ["83852.50", "0.000043"], ["83851.85", "0.000011"], ["83851.84", "0.000219"], ["83850.00", "0.003028"], ["83848.39", "0.000020"], ["83846.15", "0.000111"], ["83844.83", "0.000008"], ["83842.11", "0.000033"], ["83841.18", "0.000071"], ["83840.00", "0.001282"], ["83839.72", "0.000033"], ["83839.18", "0.000016"], ["83837.84", "0.000009"], ["83837.59", "0.000012"], ["83836.36", "0.000008"], ["83835.56", "0.000009"], ["83835.00", "0.000926"], ["83831.11", "0.000011"], ["83830.59", "0.000010"], ["83830.00", "0.000063"], ["83828.57", "0.000016"], ["83826.67", "0.000073"], ["83825.00", "0.000672"], ["83822.12", "0.000067"], ["83820.00", "0.003247"], ["83818.18", "0.001526"], ["83818.17", "0.000029"], ["83816.67", "0.000010"], ["83816.28", "0.000009"], ["83816.00", "0.000008"], ["83815.79", "0.000022"], ["83815.75", "0.000009"], ["83815.37", "0.000022"], ["83813.00", "0.000113"], ["83810.74", "0.000019"], ["83810.41", "0.000264"], ["83808.53", "0.000039"], ["83808.51", "0.000137"], ["83807.88", "0.000051"], ["83807.53", "0.000010"], ["83805.00", "0.000926"], ["83804.35", "0.000010"], ["83803.57", "0.000016"], ["83802.81", "0.000022"], ["83800.91", "0.000012"], ["83800.00", "0.039884"], ["83799.34", "0.000093"], ["83796.61", "0.001213"], ["83795.00", "0.000031"], ["83794.17", "0.000096"], ["83793.10", "0.000016"], ["83791.03", "0.000996"], ["83791.02", "0.000632"], ["83790.15", "0.000024"], ["83790.00", "0.003033"], ["83789.60", "0.000363"], ["83789.29", "0.000074"], ["83788.99", "1.611520"], ["83787.88", "0.000010"], ["83785.71", "0.000081"], ["83784.62", "0.000015"], ["83784.36", "0.000069"], ["83784.02", "0.000022"], ["83783.78", "0.000059"], ["83783.12", "0.000008"], ["83780.48", "0.000016"], ["83780.00", "0.001547"], ["83779.93", "0.000028"], ["83778.35", "0.011010"], ["83777.78", "0.000679"], ["83777.60", "0.000013"], ["83777.18", "0.000013"], ["83775.00", "0.009183"], ["83774.10", "0.000161"], ["83773.31", "0.000154"], ["83773.11", "0.041940"], ["83772.88", "0.000023"], ["83769.28", "0.000972"], ["83768.46", "0.000008"], ["83768.00", "0.000012"], ["83766.84", "0.000023"], ["83765.06", "0.000008"], ["83764.71", "0.000071"], ["83763.64", "0.000010"], ["83762.50", "0.000076"], ["83761.90", "0.000024"], ["83761.29", "0.000020"], ["83760.00", "0.001718"], ["83758.93", "0.000036"], ["83758.00", "0.000353"], ["83757.40", "0.000537"], ["83756.08", "0.000099"], ["83755.56", "0.000134"], ["83754.70", "0.000013"], ["83754.39", "0.000033"], ["83752.94", "0.000071"], ["83752.37", "0.000119"], ["83752.09", "0.000314"], ["83752.00", "0.000034"], ["83750.67", "0.000146"], ["83750.00", "0.041680"], ["83749.66", "0.000016"], ["83749.50", "0.000069"], ["83749.33", "0.000133"], ["83748.54", "0.000012"], ["83746.09", "0.000010"], ["83745.16", "0.000389"], ["83745.00", "0.000926"], ["83743.29", "0.001451"], ["83743.20", "0.506997"], ["83740.69", "0.001536"], ["83740.51", "0.000423"], ["83740.00", "0.001311"], ["83739.60", "0.000048"], ["83739.28", "0.000051"], ["83739.13", "0.000008"], ["83737.93", "0.000135"], ["83737.37", "0.000012"], ["83737.00", "0.000009"], ["83736.94", "0.000104"], ["83736.84", "0.000183"], ["83736.33", "0.000025"], ["83735.70", "0.002419"], ["83734.69", "0.000085"], ["83733.33", "0.003222"], ["83732.10", "0.000009"], ["83731.48", "0.000124"], ["83730.00", "0.002926"], ["83729.73", "0.000009"], ["83729.39", "0.000008"], ["83729.32", "0.000035"], ["83728.57", "0.000017"], ["83728.37", "0.001273"], ["83728.07", "0.000022"], ["83727.71", "0.000009"], ["83727.27", "0.000082"], ["83726.20", "0.000016"], ["83725.00", "0.002501"], ["83723.72", "0.000176"], ["83723.64", "0.000009"], ["83723.61", "0.000883"], ["83723.43", "0.000039"], ["83723.40", "0.000205"], ["83721.56", "0.000015"], ["83720.00", "0.003671"], ["83719.46", "0.000053"], ["83718.75", "0.000012"], ["83717.93", "0.000065"], ["83717.46", "0.000009"], ["83717.45", "0.000040"], ["83717.39", "0.000010"], ["83715.48", "0.000010"], ["83715.00", "0.000926"], ["83714.29", "0.009987"], ["83714.28", "0.000836"], ["83713.80", "0.000024"], ["83713.71", "0.000323"], ["83713.40", "0.000161"], ["83711.93", "0.000018"], ["83710.00", "0.000023"], ["83709.88", "0.000107"], ["83707.07", "0.000067"], ["83706.90", "0.000016"], ["83706.67", "0.000013"], ["83705.85", "0.000019"], ["83705.32", "0.000065"], ["83705.18", "0.000009"], ["83703.75", "0.000364"], ["83703.70", "0.000499"], ["83703.00", "0.000024"], ["83702.93", "0.000050"], ["83702.60", "0.000039"], ["83702.50", "0.000033"], ["83702.48", "0.000057"], ["83701.92", "0.000067"], ["83701.28", "0.000248"], ["83700.00", "0.007170"], ["83699.88", "0.000008"], ["83697.23", "0.000095"], ["83695.65", "0.003535"], ["83695.63", "0.000011"], ["83693.69", "0.000051"], ["83692.52", "0.000066"], ["83692.38", "0.000007"], ["83692.31", "0.000031"], ["83691.74", "0.000653"], ["83690.84", "0.000162"], ["83690.48", "0.000248"], ["83689.78", "0.001684"], ["83689.50", "0.000113"], ["83688.89", "0.000009"], ["83688.07", "0.000072"], ["83687.50", "0.006969"], ["83687.00", "0.000008"], ["83686.11", "0.000096"], ["83685.00", "0.000926"], ["83684.21", "0.000102"], ["83683.67", "0.000184"], ["83681.82", "0.000175"], ["83680.67", "0.041940"], ["83680.00", "0.001718"], ["83679.44", "0.000361"], ["83678.41", "0.000010"], ["83678.08", "0.000145"], ["83677.37", "0.000008"], ["83676.47", "0.000080"], ["83675.68", "0.000008"], ["83675.62", "0.000011"], ["83675.36", "0.000013"], ["83675.20", "0.000018"], ["83675.00", "0.002674"], ["83674.70", "0.000008"], ["83674.19", "0.000020"], ["83674.00", "0.001195"], ["83673.87", "0.000022"], ["83673.58", "0.000023"], ["83672.96", "0.002168"], ["83672.50", "0.000031"], ["83672.25", "0.004023"], ["83672.00", "0.000035"], ["83671.36", "0.000099"], ["83670.59", "0.000105"], ["83670.05", "0.000033"], ["83670.00", "0.004426"], ["83669.66", "0.000010"], ["83669.58", "0.000251"], ["83669.09", "0.000135"], ["83667.80", "0.000023"], ["83667.23", "0.012503"], ["83666.67", "0.052199"], ["83666.66", "0.000513"], ["83666.65", "0.000122"], ["83666.00", "0.271427"], ["83664.71", "0.000071"], ["83664.19", "0.000073"], ["83663.98", "0.000008"], ["83663.95", "0.000022"], ["83663.91", "0.000161"], ["83662.50", "0.000077"], ["83661.97", "0.000052"], ["83661.60", "0.000042"], ["83661.08", "0.004152"], ["83660.71", "0.000309"], ["83660.14", "0.000016"], ["83660.00", "0.001273"], ["83659.61", "0.000454"], ["83659.49", "0.000012"], ["83659.44", "0.000613"], ["83658.54", "0.000036"], ["83656.60", "0.000607"], ["83655.00", "0.000926"], ["83654.23", "0.000009"], ["83653.94", "0.000133"], ["83653.67", "0.001695"], ["83653.31", "0.000015"], ["83652.80", "0.000119"], ["83652.48", "0.000188"], ["83651.65", "0.000018"], ["83651.16", "0.000896"], ["83650.84", "0.003326"]], "checksum": 0, "ts": "1742554938613"}], "ts": 1742554938774, "record_time": 1742554938.868946, "EXCHANGE": "BITGET"}
{"action": "update", "arg": {"instType": "SPOT", "channel": "books", "instId": "BTCUSDT"}, "data": [{"asks": [["84155.51", "0.010000"], ["84158.10", "0.001566"], ["84160.10", "0.004119"], ["84162.10", "0.010839"], ["84164.10", "0.028526"], ["84166.10", "0.075067"], ["84168.10", "0.197545"], ["84170.10", "0.519855"], ["84172.10", "1.368040"], ["84174.10", "3.600104"], ["84174.40", "0.269400"], ["84175.10", "0.001000"], ["84176.70", "0.049230"], ["84179.00", "1.233870"], ["84184.50", "0.348090"], ["84216.10", "4.890277"], ["84224.60", "4.528034"], ["84233.10", "4.165792"], ["84241.60", "4.256352"], ["84250.10", "5.343080"], ["84258.60", "4.980838"], ["84267.10", "5.614762"], ["84275.60", "5.433641"], ["84284.10", "5.071398"], ["84292.60", "4.618595"], ["84301.10", "4.799716"], ["84309.60", "4.437474"], ["84326.60", "3.894110"], ["84335.10", "4.709156"], ["84343.60", "4.346913"], ["84352.10", "3.984670"], ["84360.60", "5.252520"], ["84369.10", "5.161959"], ["84377.60", "4.075231"], ["84527.47", "0"], ["84528.57", "0"], ["84530.00", "0"]], "bids": [["84089.80", "10.433707"], ["84078.50", "0"], ["84076.70", "0.120000"], ["84047.80", "4.165792"], ["84039.30", "5.161959"], ["84030.80", "4.346913"], ["84022.30", "5.433641"], ["84013.80", "4.618595"], ["84005.30", "4.890277"], ["83988.30", "3.984670"], ["83979.80", "4.437474"], ["83971.30", "5.071398"], ["83962.80", "5.614762"], ["83954.30", "4.256352"], ["83945.80", "5.252520"], ["83937.30", "3.894110"], ["83928.80", "4.799716"], ["83920.30", "4.528034"], ["83911.80", "4.980838"], ["83903.30", "4.075231"], ["83894.80", "4.709156"], ["83886.30", "5.524202"]], "checksum": -958755524, "ts": "1742554938813"}], "ts": 1742554938818, "record_time": 1742554938.870282, "EXCHANGE": "BITGET"}
{"action": "update", "arg": {"instType": "SPOT", "channel": "books", "instId": "BTCUSDT"}, "data": [{"asks": [["84090.00", "0.274543"], ["84090.01", "0.000100"], ["84097.76", "0"], ["84146.97", "0"], ["84174.10", "3.599863"], ["84179.50", "0.071250"], ["84182.30", "0.607110"], ["84182.50", "1.350000"], ["84184.40", "0"], ["84184.50", "0"], ["84216.10", "4.075231"], ["84233.10", "5.433641"], ["84241.60", "4.618595"], ["84250.10", "3.984670"], ["84258.60", "4.709156"], ["84267.10", "4.980838"], ["84275.60", "4.890277"], ["84284.10", "4.165792"], ["84292.60", "5.071398"], ["84301.10", "5.524202"], ["84309.60", "5.161959"], ["84318.10", "3.894110"], ["84326.60", "4.437474"], ["84335.10", "5.252520"], ["84352.10", "5.614762"], ["84360.60", "5.343080"], ["84369.10", "4.256352"], ["84377.60", "4.799716"], ["84527.47", "0.000608"], ["84528.57", "0.000008"]], "bids": [["84089.80", "9.284581"], ["84088.20", "0.014010"], ["84087.40", "1.350210"], ["84077.20", "0.032280"], ["84047.80", "5.433641"], ["84039.30", "5.343080"], ["84039.00", "0.000017"], ["84038.00", "0.000017"], ["84037.00", "0.000017"], ["84036.00", "0.000017"], ["84035.00", "0.000017"], ["84034.00", "0.000017"], ["84030.80", "4.618595"], ["84026.00", "0"], ["84022.30", "5.161959"], ["84013.80", "5.524202"], ["84005.30", "4.165792"], ["83996.80", "4.799716"], ["83979.80", "4.709156"], ["83971.30", "4.890277"], ["83962.80", "4.256352"], ["83954.30", "4.437474"], ["83937.30", "4.346913"], ["83928.80", "4.528034"], ["83920.30", "5.614762"], ["83911.80", "5.071398"], ["83903.30", "3.894110"], ["83894.80", "4.980838"], ["83886.30", "4.075231"], ["83650.00", "0.032056"]], "checksum": -274290479, "ts": "1742554939016"}], "ts": 1742554939020, "record_time": 1742554939.05442, "EXCHANGE": "BITGET"}
{"action": "update", "arg": {"instType": "SPOT", "channel": "books", "instId": "BTCUSDT"}, "data": [{"asks": [["84090.00", "0.301443"], ["84097.49", "0.086101"], ["84146.96", "0"], ["84147.41", "0.174928"], ["84170.10", "0.519990"], ["84172.10", "1.368301"], ["84174.10", "3.600588"], ["84174.20", "0.001038"], ["84175.10", "0"], ["84184.30", "0"], ["84224.60", "4.346913"], ["84233.10", "5.161959"], ["84241.60", "4.890277"], ["84250.10", "3.894110"], ["84258.60", "4.528034"], ["84275.60", "5.524202"], ["84292.60", "4.618595"], ["84301.10", "5.071398"], ["84309.60", "4.799716"], ["84318.10", "4.256352"], ["84326.60", "5.433641"], ["84343.60", "5.614762"], ["84352.10", "4.709156"], ["84360.60", "4.437474"], ["84369.10", "3.984670"], ["84377.60", "5.343080"], ["84462.00", "0"], ["84468.50", "1.710746"]], "bids": [["84089.80", "9.283520"], ["84077.70", "2.824890"], ["84077.20", "0"], ["84076.50", "0.120000"], ["84047.80", "4.075231"], ["84039.30", "5.614762"], ["84030.80", "5.071398"], ["84022.30", "4.165792"], ["84013.80", "5.252520"], ["84005.30", "4.528034"], ["83996.80", "5.433641"], ["83988.30", "5.343080"], ["83979.80", "4.799716"], ["83971.30", "5.161959"], ["83962.80", "4.346913"], ["83945.80", "4.618595"], ["83937.30", "3.894110"], ["83928.80", "4.980838"], ["83920.30", "3.984670"], ["83911.80", "4.256352"], ["83903.30", "4.709156"], ["83894.80", "4.890277"], ["83886.30", "5.524202"], ["83795.43", "1.607253"], ["83788.99", "0"]], "checksum": -1664439950, "ts": "1742554939217"}], "ts": 1742554939225, "record_time": 1742554939.249863, "EXCHANGE": "BITGET"}
{"action": "update", "arg": {"instType": "SPOT", "channel": "books", "instId": "BTCUSDT"}, "data": [{"asks": [["84090.00", "0.308443"], ["84098.41", "0.209200"], ["84147.40", "0.053577"], ["84149.99", "0"], ["84170.10", "0.519595"], ["84172.10", "1.367354"], ["84174.10", "3.598300"], ["84208.62", "0"], ["84216.10", "5.614762"], ["84224.60", "5.071398"], ["84233.10", "4.980838"], ["84241.60", "3.894110"], ["84250.10", "3.984670"], ["84258.60", "5.343080"], ["84267.10", "4.618595"], ["84275.60", "4.437474"], ["84284.10", "5.524202"], ["84292.60", "4.346913"], ["84301.10", "5.252520"], ["84309.60", "4.165792"], ["84318.10", "4.528034"], ["84326.60", "4.709156"], ["84335.10", "5.433641"], ["84343.60", "4.799716"], ["84352.10", "4.256352"], ["84360.60", "4.075231"], ["84369.10", "5.161959"], ["84377.60", "4.890277"]], "bids": [["84089.80", "9.283781"], ["84088.20", "0.015330"], ["84077.20", "0.030960"], ["84076.50", "0"], ["84047.80", "4.437474"], ["84039.30", "4.980838"], ["84030.80", "5.161959"], ["84022.30", "4.890277"], ["84013.80", "4.709156"], ["84005.30", "4.075231"], ["83996.80", "3.894110"], ["83988.30", "4.165792"], ["83979.80", "4.618595"], ["83971.30", "5.433641"], ["83962.80", "5.614762"], ["83954.30", "4.528034"], ["83945.80", "4.799716"], ["83937.30", "5.343080"], ["83928.80", "4.346913"], ["83920.30", "5.071398"], ["83911.80", "5.524202"], ["83903.30", "4.256352"], ["83894.80", "3.984670"], ["83886.30", "5.252520"]], "checksum": -525991227, "ts": "1742554939425"}], "ts": 1742554939428, "record_time": 1742554939.525097, "EXCHANGE": "BITGET"}
{"action": "update", "arg": {"instType": "SPOT", "channel": "books", "instId": "BTCUSDT"}, "data": [{"asks": [["84090.00", "0.311943"], ["84097.20", "0.086101"], ["84097.49", "0"], ["84124.97", "0"], ["84130.02", "0.010988"], ["84158.10", "0.001928"], ["84160.10", "0.005073"], ["84162.10", "0.013351"], ["84164.10", "0.035135"], ["84166.10", "0.092461"], ["84168.10", "0.243318"], ["84170.10", "0.640310"], ["84172.10", "1.685025"], ["84174.10", "4.434277"], ["84216.10", "3.984670"], ["84231.38", "0.125578"], ["84233.10", "5.161959"], ["84241.60", "4.256352"], ["84250.10", "3.894110"], ["84258.60", "5.252520"], ["84267.10", "4.528034"], ["84275.60", "4.799716"], ["84284.10", "4.980838"], ["84292.60", "4.075231"], ["84301.10", "5.614762"], ["84309.60", "4.890277"], ["84318.10", "5.524202"], ["84326.60", "4.346913"], ["84335.10", "4.709156"], ["84343.60", "4.437474"], ["84352.10", "4.618595"], ["84360.60", "5.343080"], ["84369.10", "5.433641"], ["84377.60", "4.165792"], ["84528.57", "0"]], "bids": [["84089.80", "9.284469"], ["84059.38", "0.056349"], ["84054.34", "0"], ["84047.80", "5.614762"], ["84039.30", "3.894110"], ["84030.80", "4.165792"], ["84022.30", "4.256352"], ["84013.80", "5.343080"], ["84005.30", "4.437474"], ["83996.80", "5.252520"], ["83988.30", "4.346913"], ["83979.80", "4.890277"], ["83971.30", "4.799716"], ["83962.80", "4.980838"], ["83954.30", "4.709156"], ["83945.80", "5.161959"], ["83937.30", "4.618595"], ["83928.80", "4.528034"], ["83911.80", "3.984670"], ["83903.30", "5.433641"], ["83894.80", "4.075231"], ["83886.30", "5.524202"]], "checksum": 614813924, "ts": "1742554939624"}], "ts": 1742554939627, "record_time": 1742554939.65244, "EXCHANGE": "BITGET"}
{"action": "update", "arg": {"instType": "SPOT", "channel": "books", "instId": "BTCUSDT"}, "data": [{"asks": [["84121.77", "0"], ["84125.14", "0.119867"], ["84125.98", "0"], ["84129.29", "0.015892"], ["84142.90", "0"], ["84158.10", "0.002628"], ["84160.10", "0.006914"], ["84162.10", "0.018195"], ["84162.30", "0.000958"], ["84164.10", "0.047882"], ["84166.10", "0.126004"], ["84168.10", "0.331590"], ["84170.10", "0.872605"], ["84172.10", "2.296329"], ["84174.10", "6.042973"], ["84175.80", "0.012780"], ["84176.70", "0"], ["84178.30", "0.015000"], ["84184.10", "0"], ["84216.10", "4.709156"], ["84224.60", "4.165792"], ["84233.10", "4.075231"], ["84241.60", "5.614762"], ["84250.10", "5.433641"], ["84258.60", "3.894110"], ["84267.10", "5.161959"], ["84275.60", "4.980838"], ["84284.10", "4.346913"], ["84292.60", "5.343080"], ["84301.10", "4.437474"], ["84309.60", "4.799716"], ["84318.10", "4.256352"], ["84326.60", "5.252520"], ["84335.10", "4.890277"], ["84343.60", "4.528034"], ["84360.60", "5.524202"], ["84369.10", "3.984670"], ["84377.60", "5.071398"]], "bids": [["84089.80", "8.445721"], ["84088.20", "0.001001"], ["84088.00", "0.000015"], ["84087.00", "0.000015"], ["84086.00", "0.000015"], ["84085.00", "0.000015"], ["84076.70", "0"], ["84070.59", "0.004016"], ["84068.14", "0"], ["84065.50", "0.000396"], ["84064.59", "0.259713"], ["84061.23", "0"], ["84060.34", "0.073192"], ["84057.60", "0"], ["84057.02", "0"], ["84047.80", "4.980838"], ["84039.30", "4.346913"], ["84036.10", "0.000948"], ["84033.00", "0.000015"], ["84030.80", "5.161959"], ["84028.20", "0"], ["84022.30", "4.890277"], ["84013.80", "3.984670"], ["84005.30", "5.343080"], ["83996.80", "4.165792"], ["83988.30", "4.437474"], ["83979.80", "4.799716"], ["83971.30", "4.256352"], ["83962.80", "5.524202"], ["83954.30", "4.528034"], ["83945.80", "5.252520"], ["83937.30", "3.894110"], ["83928.80", "4.709156"], ["83920.30", "5.614762"], ["83911.80", "4.075231"], ["83903.30", "5.071398"], ["83894.80", "5.433641"], ["83886.30", "4.618595"], ["83651.65", "0"], ["83651.16", "0"], ["83650.84", "0"], ["83650.00", "0"]], "checksum": 379846027, "ts": "1742554939847"}], "ts": 1742554939850, "record_time": 1742554939.875874, "EXCHANGE": "BITGET"}
{"action": "update", "arg": {"instType": "SPOT", "channel": "books", "instId": "BTCUSDT"}, "data": [{"asks": [["84090.00", "0.311398"], ["84160.10", "0.007043"], ["84162.10", "0.018535"], ["84164.10", "0.048776"], ["84166.10", "0.128519"], ["84168.10", "0.338207"], ["84170.10", "0.890017"], ["84172.10", "2.342152"], ["84174.10", "6.163556"], ["84174.40", "0.521670"], ["84175.80", "0.035520"], ["84184.10", "0.453360"], ["84216.10", "5.343080"], ["84224.60", "4.346913"], ["84233.10", "5.524202"], ["84241.60", "4.709156"], ["84250.10", "4.528034"], ["84258.60", "5.161959"], ["84267.10", "4.437474"], ["84275.60", "3.984670"], ["84284.10", "4.256352"], ["84292.60", "4.799716"], ["84301.10", "4.890277"], ["84309.60", "5.433641"], ["84318.10", "3.894110"], ["84326.60", "4.618595"], ["84335.10", "4.075231"], ["84343.60", "5.614762"], ["84352.10", "4.165792"], ["84360.60", "5.252520"], ["84369.10", "4.980838"], ["84527.47", "0"]], "bids": [["84089.80", "7.088348"], ["84089.70", "0.058830"], ["84088.10", "3.072420"], ["84087.90", "0.068010"], ["84087.40", "0"], ["84047.80", "4.346913"], ["84039.30", "5.161959"], ["84030.80", "4.709156"], ["84022.30", "3.984670"], ["84013.80", "4.437474"], ["84005.30", "5.524202"], ["83996.80", "5.433641"], ["83988.30", "4.165792"], ["83979.80", "4.980838"], ["83971.30", "5.071398"], ["83962.80", "4.890277"], ["83954.30", "4.618595"], ["83945.80", "4.256352"], ["83937.30", "4.799716"], ["83928.80", "4.528034"], ["83920.30", "5.252520"], ["83911.80", "5.343080"], ["83903.30", "3.894110"], ["83894.80", "5.614762"], ["83886.30", "4.075231"]], "checksum": 2095718681, "ts": "1742554940048"}], "ts": 1742554940053, "record_time": 1742554940.076265, "EXCHANGE": "BITGET"}
{"action": "update", "arg": {"instType": "SPOT", "channel": "books", "instId": "BTCUSDT"}, "data": [{"asks": [["84090.00", "0.311375"], ["84096.96", "0.086101"], ["84097.20", "0"], ["84174.10", "6.163798"], ["84175.80", "0.016380"], ["84184.10", "0"], ["84216.10", "5.071398"], ["84224.60", "4.618595"], ["84233.10", "4.890277"], ["84241.60", "5.614762"], ["84250.10", "4.346913"], ["84267.10", "4.528034"], ["84275.60", "4.709156"], ["84284.10", "4.165792"], ["84301.10", "4.437474"], ["84309.60", "5.252520"], ["84326.60", "3.984670"], ["84335.10", "5.524202"], ["84343.60", "4.075231"], ["84352.10", "4.980838"], ["84360.60", "5.343080"], ["84369.10", "5.433641"], ["84377.60", "4.256352"], ["84527.47", "0.000608"]], "bids": [["84089.81", "2.327606"], ["84089.80", "7.429510"], ["84089.70", "0.001042"], ["84089.19", "0"], ["84086.30", "0.072240"], ["84082.30", "0"], ["84047.80", "4.890277"], ["84039.30", "5.343080"], ["84030.80", "5.614762"], ["84022.30", "4.799716"], ["84013.80", "4.709156"], ["84005.30", "4.346913"], ["83996.80", "5.524202"], ["83988.30", "4.528034"], ["83979.80", "4.165792"], ["83971.30", "4.618595"], ["83962.80", "4.437474"], ["83954.30", "4.980838"], ["83937.30", "5.252520"], ["83928.80", "5.161959"], ["83920.30", "4.075231"], ["83911.80", "5.433641"], ["83903.30", "5.071398"], ["83894.80", "3.894110"], ["83886.30", "3.984670"], ["83651.65", "0.000018"]], "checksum": 1635164286, "ts": "1742554940265"}], "ts": 1742554940268, "record_time": 1742554940.290501, "EXCHANGE": "BITGET"}
{"action": "update", "arg": {"instType": "SPOT", "channel": "books", "instId": "BTCUSDT"}, "data": [{"asks": [["84158.10", "0.002162"], ["84160.10", "0.005690"], ["84162.10", "0.014973"], ["84164.10", "0.039402"], ["84166.10", "0.103690"], ["84168.10", "0.272869"], ["84170.10", "0.718075"], ["84172.10", "1.889672"], ["84174.10", "4.972822"], ["84216.10", "3.984670"], ["84224.60", "4.075231"], ["84233.10", "5.071398"], ["84241.60", "4.165792"], ["84250.10", "5.433641"], ["84258.60", "5.524202"], ["84275.60", "4.890277"], ["84284.10", "4.437474"], ["84292.60", "5.614762"], ["84301.10", "4.709156"], ["84318.10", "4.618595"], ["84326.60", "4.256352"], ["84335.10", "4.980838"], ["84343.60", "3.894110"], ["84352.10", "4.346913"], ["84360.60", "5.161959"], ["84369.10", "4.799716"], ["84377.60", "5.343080"]], "bids": [["84089.80", "8.266528"], ["84039.30", "4.346913"], ["84030.80", "5.252520"], ["84022.30", "5.524202"], ["84013.80", "4.980838"], ["84005.30", "4.709156"], ["83996.80", "5.071398"], ["83988.30", "4.256352"], ["83979.80", "5.614762"], ["83971.30", "4.437474"], ["83962.80", "3.894110"], ["83954.30", "4.528034"], ["83945.80", "4.618595"], ["83937.30", "4.799716"], ["83928.80", "5.343080"], ["83903.30", "5.161959"], ["83894.80", "4.165792"]], "checksum": 1288638558, "ts": "1742554940478"}], "ts": 1742554940482, "record_time": 1742554940.512685, "EXCHANGE": "BITGET"}
{"action": "update", "arg": {"instType": "SPOT", "channel": "books", "instId": "BTCUSDT"}, "data": [{"asks": [["84094.98", "0"], ["84096.72", "0.086101"], ["84096.96", "0"], ["84156.10", "0.001174"], ["84158.10", "0.003089"], ["84160.10", "0.008129"], ["84162.10", "0.021169"], ["84164.10", "0.055708"], ["84166.10", "0.146599"], ["84168.10", "0.385787"], ["84170.10", "1.015229"], ["84172.10", "2.671654"], ["84174.10", "7.030670"], ["84174.50", "0.001047"], ["84175.00", "0.970860"], ["84175.80", "0.035640"], ["84176.50", "0.144510"], ["84178.10", "0.067800"], ["84179.90", "0"], ["84183.80", "0"], ["84216.10", "4.165792"], ["84224.60", "4.437474"], ["84233.10", "5.161959"], ["84241.60", "4.980838"], ["84250.10", "3.984670"], ["84258.60", "4.890277"], ["84267.10", "5.252520"], ["84275.60", "5.343080"], ["84284.10", "4.618595"], ["84292.60", "4.528034"], ["84301.10", "4.075231"], ["84309.60", "4.709156"], ["84318.10", "5.524202"], ["84326.60", "3.894110"], ["84335.10", "5.071398"], ["84343.60", "4.256352"], ["84352.10", "4.799716"], ["84360.60", "5.433641"], ["84369.10", "4.346913"], ["84377.60", "5.614762"]], "bids": [["84089.80", "5.810101"], ["84088.40", "0"], ["84088.20", "0"], ["84088.10", "3.139530"], ["84087.90", "0.067800"], ["84086.30", "0.072030"], ["84084.70", "0"], ["84083.80", "0"], ["84081.30", "0.217530"], ["84079.70", "0"], ["84078.70", "0"], ["84078.40", "0.072060"], ["84077.20", "0"], ["84047.80", "5.161959"], ["84039.30", "4.799716"], ["84030.80", "4.528034"], ["84022.30", "3.894110"], ["84013.80", "4.709156"], ["84005.30", "4.980838"], ["83996.80", "5.252520"], ["83988.30", "4.437474"], ["83979.80", "4.890277"], ["83971.30", "5.343080"], ["83962.80", "4.075231"], ["83954.30", "4.618595"], ["83945.80", "4.346913"], ["83937.30", "5.614762"], ["83928.80", "5.433641"], ["83920.30", "5.524202"], ["83911.80", "4.256352"], ["83903.30", "4.165792"], ["83894.80", "3.984670"], ["83886.30", "5.071398"], ["83651.16", "0.000896"], ["83650.84", "0.003326"], ["83650.00", "0.032056"], ["83648.96", "0.000030"], ["83647.46", "0.000224"]], "checksum": 198593046, "ts": "1742554940691"}], "ts": 1742554940695, "record_time": 1742554940.718173, "EXCHANGE": "BITGET"}
{"action": "update", "arg": {"instType": "SPOT", "channel": "books", "instId": "BTCUSDT"}, "data": [{"asks": [["84090.01", "0.000220"], ["84093.75", "0.028559"], ["84156.10", "0.001052"], ["84158.10", "0.002767"], ["84160.10", "0.007281"], ["84162.10", "0.019162"], ["84164.10", "0.050425"], ["84166.10", "0.132698"], ["84168.10", "0.349205"], ["84170.10", "0.918960"], ["84172.10", "2.418316"], ["84174.10", "6.363990"], ["84174.50", "0"], ["84175.00", "0.971880"], ["84176.50", "0"], ["84177.40", "0.150330"], ["84179.40", "0.144510"], ["84183.80", "0.120000"], ["84216.10", "3.894110"], ["84224.60", "4.890277"], ["84233.10", "3.984670"], ["84241.60", "4.075231"], ["84250.10", "4.980838"], ["84258.60", "4.528034"], ["84267.10", "4.165792"], ["84275.60", "5.161959"], ["84284.10", "4.437474"], ["84292.60", "4.799716"], ["84301.10", "4.709156"], ["84309.60", "5.343080"], ["84318.10", "4.256352"], ["84326.60", "4.618595"], ["84335.10", "5.433641"], ["84343.60", "5.252520"], ["84352.10", "5.524202"], ["84360.60", "4.346913"], ["84369.10", "5.614762"], ["84377.60", "5.071398"], ["84527.47", "0"]], "bids": [["84089.80", "5.870904"], ["84088.10", "3.072420"], ["84087.90", "0.068010"], ["84084.10", "0.144510"], ["84081.30", "0.073020"], ["84078.40", "0"], ["84077.20", "0.030960"], ["84047.80", "3.894110"], ["84039.30", "5.343080"], ["84039.00", "0.000032"], ["84030.80", "4.890277"], ["84022.30", "5.614762"], ["84013.80", "4.980838"], ["84005.30", "4.256352"], ["83996.80", "5.071398"], ["83988.30", "4.075231"], ["83979.80", "5.524202"], ["83971.30", "4.618595"], ["83962.80", "4.799716"], ["83954.30", "4.437474"], ["83945.80", "4.709156"], ["83937.30", "3.984670"], ["83928.80", "4.346913"], ["83920.30", "4.528034"], ["83911.80", "4.165792"], ["83903.30", "5.252520"], ["83894.80", "5.161959"], ["83886.30", "5.433641"], ["83647.46", "0"]], "checksum": -1299059139, "ts": "1742554940893"}], "ts": 1742554940896, "record_time": 1742554940.923629, "EXCHANGE": "BITGET"}
{"action": "update", "arg": {"instType": "SPOT", "channel": "books", "instId": "BTCUSDT"}, "data": [{"asks": [["84170.10", "0.919210"], ["84172.10", "2.418973"], ["84174.10", "6.365720"], ["84184.10", "0.453360"], ["84224.60", "5.433641"], ["84250.10", "4.890277"], ["84258.60", "4.980838"], ["84267.10", "5.071398"], ["84275.60", "4.709156"], ["84284.10", "4.346913"], ["84292.60", "4.618595"], ["84301.10", "5.614762"], ["84309.60", "4.437474"], ["84318.10", "4.799716"], ["84326.60", "5.524202"], ["84335.10", "4.256352"], ["84343.60", "4.528034"], ["84352.10", "5.252520"], ["84360.60", "5.161959"], ["84369.10", "5.343080"], ["84377.60", "4.165792"], ["84525.82", "0"]], "bids": [["84089.80", "5.870662"], ["84047.80", "4.709156"], ["84039.30", "4.618595"], ["84022.30", "5.433641"], ["84013.80", "4.165792"], ["84005.30", "5.071398"], ["83996.80", "5.252520"], ["83988.30", "5.161959"], ["83979.80", "4.980838"], ["83971.30", "3.984670"], ["83954.30", "3.894110"], ["83945.80", "4.346913"], ["83937.30", "4.437474"], ["83928.80", "4.075231"], ["83920.30", "5.614762"], ["83911.80", "5.524202"], ["83903.30", "5.343080"], ["83894.80", "4.528034"], ["83886.30", "4.256352"]], "checksum": -1641904428, "ts": "1742554941097"}], "ts": 1742554941101, "record_time": 1742554941.125111, "EXCHANGE": "BITGET"}
{"action": "update", "arg": {"instType": "SPOT", "channel": "books", "instId": "BTCUSDT"}, "data": [{"asks": [["84096.45", "0.086102"], ["84096.72", "0"], ["84130.74", "0"], ["84155.51", "0"], ["84158.10", "0.002436"], ["84160.10", "0.006411"], ["84162.10", "0.017036"], ["84164.10", "0.044833"], ["84166.10", "0.117981"], ["84168.10", "0.310477"], ["84170.10", "0.817043"], ["84172.10", "2.150114"], ["84174.10", "5.658194"], ["84216.10", "4.437474"], ["84224.60", "5.161959"], ["84233.10", "4.528034"], ["84241.60", "5.071398"], ["84250.10", "4.709156"], ["84258.60", "4.165792"], ["84267.10", "5.614762"], ["84275.60", "5.433641"], ["84292.60", "4.799716"], ["84301.10", "4.980838"], ["84309.60", "3.894110"], ["84318.10", "4.075231"], ["84326.60", "4.256352"], ["84335.10", "4.618595"], ["84343.60", "5.524202"], ["84360.60", "4.890277"], ["84369.10", "3.984670"], ["84377.60", "5.343080"], ["84525.82", "0.000099"], ["84527.47", "0.000608"]], "bids": [["84082.30", "0.015000"], ["84077.20", "0"], ["84047.80", "4.618595"], ["84039.30", "5.252520"], ["84030.80", "5.614762"], ["84022.30", "5.071398"], ["84013.80", "4.890277"], ["84005.30", "4.165792"], ["83996.80", "5.433641"], ["83988.30", "4.075231"], ["83979.80", "4.799716"], ["83971.30", "4.437474"], ["83962.80", "5.343080"], ["83954.30", "4.256352"], ["83945.80", "5.524202"], ["83937.30", "4.709156"], ["83928.80", "4.980838"], ["83920.30", "3.984670"], ["83911.80", "3.894110"], ["83903.30", "4.528034"], ["83894.80", "5.161959"], ["83886.30", "4.346913"]], "checksum": 440646255, "ts": "1742554941298"}], "ts": 1742554941302, "record_time": 1742554941.335171, "EXCHANGE": "BITGET"}
{"action": "update", "arg": {"instType": "SPOT", "channel": "books", "instId": "BTCUSDT"}, "data": [{"asks": [["84090.00", "0.314875"], ["84098.40", "0.062760"], ["84130.73", "0"], ["84147.41", "0"], ["84152.37", "0"], ["84162.10", "0.016870"], ["84164.10", "0.044395"], ["84166.10", "0.116829"], ["84168.10", "0.307444"], ["84170.10", "0.809063"], ["84172.10", "2.129115"], ["84174.10", "5.602766"], ["84174.20", "0.373860"], ["84174.40", "0.003960"], ["84184.10", "0"], ["84216.10", "5.161959"], ["84224.60", "4.709156"], ["84233.10", "5.524202"], ["84241.60", "4.799716"], ["84250.10", "5.071398"], ["84267.10", "5.252520"], ["84275.60", "4.346913"], ["84284.10", "3.984670"], ["84292.60", "4.980838"], ["84301.10", "4.528034"], ["84309.60", "5.614762"], ["84318.10", "4.618595"], ["84326.60", "4.437474"], ["84335.10", "4.890277"], ["84343.60", "5.433641"], ["84352.10", "3.894110"], ["84360.60", "5.343080"], ["84369.10", "4.075231"], ["84377.60", "4.256352"], ["84528.57", "0.000008"], ["84530.00", "0.000031"], ["84533.01", "0.000591"]], "bids": [["84089.80", "7.132672"], ["84047.80", "4.437474"], ["84039.30", "4.346913"], ["84030.80", "4.799716"], ["84022.30", "4.980838"], ["84013.80", "5.433641"], ["84005.30", "4.618595"], ["83996.80", "5.343080"], ["83988.30", "4.165792"], ["83979.80", "4.528034"], ["83971.30", "3.984670"], ["83962.80", "4.709156"], ["83954.30", "3.894110"], ["83945.80", "5.252520"], ["83937.30", "5.614762"], ["83928.80", "5.071398"], ["83920.30", "4.890277"], ["83911.80", "5.161959"], ["83903.30", "4.256352"], ["83894.80", "5.524202"], ["83886.30", "4.075231"]], "checksum": 1156464677, "ts": "1742554941500"}], "ts": 1742554941504, "record_time": 1742554941.536391, "EXCHANGE": "BITGET"}
{"action": "update", "arg": {"instType": "SPOT", "channel": "books", "instId": "BTCUSDT"}, "data": [{"asks": [["84090.00", "0.318375"], ["84090.01", "0.000202"], ["84096.45", "0"], ["84114.34", "0.119870"], ["84115.67", "0.035961"], ["84116.07", "0"], ["84116.29", "0.006356"], ["84116.41", "0.006356"], ["84116.73", "0.006356"], ["84117.49", "0"], ["84117.66", "0.010984"], ["84117.93", "0"], ["84117.97", "0"], ["84118.05", "0.006356"], ["84118.09", "0"], ["84118.20", "0.006356"], ["84118.65", "0.006356"], ["84118.81", "0.016429"], ["84119.20", "0.006356"], ["84119.35", "0"], ["84119.38", "0.006356"], ["84119.46", "0"], ["84119.47", "0"], ["84119.54", "0.119883"], ["84119.69", "0.006356"], ["84119.86", "0.006356"], ["84120.44", "0"], ["84121.02", "0"], ["84121.04", "0"], ["84121.40", "0.010985"], ["84121.43", "0.006357"], ["84121.50", "0"], ["84121.53", "0"], ["84121.99", "0.009990"], ["84122.16", "0"], ["84122.88", "0.119850"], ["84123.07", "0"], ["84123.94", "0.119858"], ["84124.34", "0.015895"], ["84124.56", "0.009989"], ["84124.70", "0"], ["84124.75", "0"], ["84124.86", "0"], ["84125.73", "0"], ["84126.38", "0"], ["84127.18", "0"], ["84131.94", "0.012472"], ["84147.40", "0"], ["84152.37", "0.777539"], ["84172.10", "2.128867"], ["84174.10", "5.602283"], ["84216.10", "4.980838"], ["84224.60", "4.799716"], ["84233.10", "3.894110"], ["84241.60", "4.618595"], ["84250.10", "4.165792"], ["84258.60", "5.524202"], ["84267.10", "4.256352"], ["84275.60", "5.614762"], ["84284.10", "4.346913"], ["84292.60", "5.433641"], ["84301.10", "4.890277"], ["84309.60", "4.437474"], ["84318.10", "4.709156"], ["84326.60", "5.343080"], ["84335.10", "5.071398"], ["84343.60", "3.984670"], ["84352.10", "4.528034"], ["84360.60", "5.161959"], ["84369.10", "5.252520"], ["84377.60", "4.075231"]], "bids": [["84082.00", "0.000017"], ["84081.00", "0.000017"], ["84080.00", "0.000017"], ["84079.00", "0.000017"], ["84078.00", "0.000017"], ["84077.00", "0.223180"], ["84076.00", "0.000032"], ["84075.00", "0.000032"], ["84074.87", "0"], ["84074.00", "0.000032"], ["84073.76", "0"], ["84073.36", "0"], ["84073.14", "0.247509"], ["84073.06", "0"], ["84073.00", "0.000032"], ["84072.54", "0"], ["84072.51", "0"], ["84072.00", "0.008628"], ["84071.95", "0.083913"], ["84071.72", "0.017811"], ["84071.70", "0"], ["84071.51", "0.018249"], ["84071.15", "0.005944"], ["84071.08", "0"], ["84071.00", "0.000032"], ["84070.87", "0"], ["84070.82", "0"], ["84070.42", "0"], ["84070.39", "0"], ["84070.10", "0"], ["84070.09", "0"], ["84070.00", "0.000032"], ["84069.90", "0"], ["84069.89", "0.055638"], ["84069.86", "0"], ["84069.78", "0.017098"], ["84069.60", "0.007129"], ["84069.19", "0.028855"], ["84069.03", "0.007337"], ["84069.00", "0.000032"], ["84068.76", "0.008991"], ["84068.58", "0.007940"], ["84068.52", "0"], ["84068.40", "0"], ["84068.24", "0.224811"], ["84068.22", "0.008182"], ["84068.06", "0.017345"], ["84068.00", "0.000032"], ["84067.00", "0.000032"], ["84066.77", "0.012651"], ["84066.74", "0.051947"], ["84066.50", "0"], ["84066.12", "0"], ["84066.00", "0.000032"], ["84065.65", "0.018511"], ["84065.52", "0"], ["84065.00", "0.000032"], ["84064.99", "0"], ["84064.69", "0.268292"], ["84064.00", "0.000032"], ["84063.73", "0.222599"], ["84063.28", "0.076088"], ["84063.17", "0.021123"], ["84063.00", "0.000032"], ["84062.00", "0.000032"], ["84061.00", "0.000032"], ["84060.00", "0.183751"], ["84058.57", "0"], ["84056.79", "0.000876"], ["84047.80", "4.618595"], ["84040.00", "0.001246"], ["84039.30", "4.165792"], ["84033.00", "0.000017"], ["84030.80", "4.437474"], ["84022.30", "4.528034"], ["84005.30", "5.343080"], ["83996.80", "4.799716"], ["83988.30", "4.075231"], ["83979.80", "5.252520"], ["83971.30", "4.346913"], ["83962.80", "5.071398"], ["83945.80", "5.614762"], ["83937.30", "5.161959"], ["83928.80", "4.890277"], ["83920.30", "4.980838"], ["83911.80", "4.709156"], ["83903.30", "5.524202"], ["83894.80", "3.984670"], ["83886.30", "4.256352"], ["83651.65", "0"], ["83651.16", "0"], ["83650.84", "0"], ["83650.00", "0"], ["83648.96", "0"]], "checksum": -821704436, "ts": "1742554941729"}], "ts": 1742554941732, "record_time": 1742554941.776769, "EXCHANGE": "BITGET"}
{"action": "update", "arg": {"instType": "SPOT", "channel": "books", "instId": "BTCUSDT"}, "data": [{"asks": [["84096.24", "0.086102"], ["84113.99", "0.035952"], ["84115.80", "0"], ["84119.43", "0.016429"], ["84122.94", "0"], ["84144.90", "0.176814"], ["84178.30", "0"], ["84184.10", "0.453360"], ["84216.10", "5.161959"], ["84224.60", "5.343080"], ["84233.10", "4.709156"], ["84241.60", "4.799716"], ["84250.10", "4.075231"], ["84258.60", "3.984670"], ["84267.10", "4.346913"], ["84275.60", "4.618595"], ["84284.10", "5.524202"], ["84301.10", "4.528034"], ["84309.60", "5.252520"], ["84318.10", "4.980838"], ["84326.60", "4.165792"], ["84335.10", "4.437474"], ["84343.60", "4.890277"], ["84352.10", "5.614762"], ["84360.60", "4.256352"], ["84369.10", "3.894110"], ["84377.60", "5.071398"], ["84530.00", "0"], ["84533.01", "0"]], "bids": [["84089.80", "6.768466"], ["84078.40", "0.071340"], ["84077.70", "1.474890"], ["84075.44", "0"], ["84073.63", "0.089456"], ["84071.64", "0"], ["84068.13", "0.025176"], ["84047.80", "4.528034"], ["84041.38", "0"], ["84039.30", "4.618595"], ["84038.41", "0.003596"], ["84030.80", "4.165792"], ["84022.30", "3.894110"], ["84013.80", "4.256352"], ["84005.30", "5.071398"], ["83996.80", "4.346913"], ["83988.30", "5.433641"], ["83979.80", "4.980838"], ["83971.30", "4.075231"], ["83962.80", "4.437474"], ["83954.30", "5.252520"], ["83937.30", "5.524202"], ["83928.80", "4.799716"], ["83920.30", "4.709156"], ["83911.80", "3.984670"], ["83903.30", "5.161959"], ["83894.80", "4.890277"], ["83886.30", "5.343080"], ["83652.48", "0"]], "checksum": -788841706, "ts": "1742554941930"}], "ts": 1742554941933, "record_time": 1742554941.970101, "EXCHANGE": "BITGET"}
{"action": "update", "arg": {"instType": "SPOT", "channel": "books", "instId": "BTCUSDT"}, "data": [{"asks": [["84090.00", "0.849407"], ["84136.10", "0.000043"], ["84158.10", "0.002796"], ["84160.10", "0.007356"], ["84162.10", "0.019358"], ["84164.10", "0.050943"], ["84166.10", "0.134060"], ["84168.10", "0.352791"], ["84170.10", "0.928395"], ["84172.10", "2.443146"], ["84174.10", "6.429332"], ["84216.10", "5.252520"], ["84224.60", "5.524202"], ["84233.10", "4.256352"], ["84241.60", "4.890277"], ["84250.10", "4.528034"], ["84258.60", "4.346913"], ["84267.10", "3.894110"], ["84275.60", "4.075231"], ["84284.10", "5.161959"], ["84292.60", "4.437474"], ["84301.10", "4.980838"], ["84309.60", "5.343080"], ["84318.10", "5.071398"], ["84326.60", "5.614762"], ["84335.10", "3.984670"], ["84343.60", "4.709156"], ["84352.10", "4.618595"], ["84360.60", "4.799716"], ["84369.10", "4.165792"], ["84377.60", "5.433641"], ["84528.57", "0"]], "bids": [["84089.80", "5.278810"], ["84089.50", "0.024210"], ["84089.00", "0.000015"], ["84047.80", "3.984670"], ["84039.30", "4.346913"], ["84030.80", "4.528034"], ["84022.30", "4.799716"], ["84013.80", "4.075231"], ["84005.30", "4.709156"], ["83996.80", "4.890277"], ["83988.30", "5.071398"], ["83979.80", "4.256352"], ["83971.30", "4.618595"], ["83962.80", "4.165792"], ["83954.30", "5.614762"], ["83945.80", "5.433641"], ["83928.80", "5.252520"], ["83920.30", "4.980838"], ["83911.80", "5.343080"], ["83894.80", "4.437474"], ["83886.30", "3.894110"], ["83652.80", "0"]], "checksum": -491910771, "ts": "1742554942130"}], "ts": 1742554942134, "record_time": 1742554942.208212, "EXCHANGE": "BITGET"}
{"action": "update", "arg": {"instType": "SPOT", "channel": "books", "instId": "BTCUSDT"}, "data": [{"asks": [["84090.01", "0.000100"], ["84096.02", "0.086102"], ["84096.24", "0"], ["84158.10", "0.002553"], ["84160.10", "0.006915"], ["84162.10", "0.018197"], ["84164.10", "0.047888"], ["84166.10", "0.126019"], ["84168.10", "0.331630"], ["84170.10", "0.872710"], ["84172.10", "2.296605"], ["84174.10", "6.043698"], ["84174.20", "0.458400"], ["84175.00", "0.970860"], ["84184.10", "0"], ["84216.10", "4.618595"], ["84224.60", "5.252520"], ["84233.10", "4.165792"], ["84241.60", "4.980838"], ["84250.10", "3.894110"], ["84258.60", "5.524202"], ["84267.10", "5.071398"], ["84275.60", "5.433641"], ["84292.60", "4.528034"], ["84301.10", "4.346913"], ["84318.10", "4.890277"], ["84326.60", "4.256352"], ["84335.10", "4.799716"], ["84352.10", "4.437474"], ["84360.60", "4.075231"], ["84369.10", "3.984670"], ["84377.60", "5.614762"], ["84528.57", "0.000008"]], "bids": [["84089.80", "4.741717"], ["84089.50", "0.047250"], ["84088.10", "2.928390"], ["84087.90", "0.067800"], ["84047.80", "5.433641"], ["84040.00", "0.001229"], ["84039.30", "4.980838"], ["84039.00", "0.000015"], ["84038.00", "0"], ["84037.00", "0"], ["84036.00", "0"], ["84035.00", "0"], ["84034.00", "0"], ["84030.80", "4.799716"], ["84027.00", "0"], ["84022.30", "5.071398"], ["84013.80", "4.618595"], ["84005.30", "4.256352"], ["83996.80", "5.252520"], ["83988.30", "4.709156"], ["83979.80", "3.984670"], ["83971.30", "4.075231"], ["83962.80", "5.614762"], ["83954.30", "3.894110"], ["83945.80", "4.437474"], ["83937.30", "4.165792"], ["83928.80", "5.524202"], ["83920.30", "4.346913"], ["83911.80", "4.528034"], ["83903.30", "5.343080"], ["83894.80", "4.890277"], ["83886.30", "5.161959"], ["83652.80", "0.000119"], ["83652.48", "0.000188"], ["83651.65", "0.000018"], ["83651.16", "0.000896"], ["83650.84", "0.003326"], ["83650.00", "0.032056"]], "checksum": -1255646727, "ts": "1742554942357"}], "ts": 1742554942361, "record_time": 1742554942.403563, "EXCHANGE": "BITGET"}
{"action": "update", "arg": {"instType": "SPOT", "channel": "books", "instId": "BTCUSDT"}, "data": [{"asks": [["84131.94", "0"], ["84160.10", "0.006717"], ["84162.10", "0.017677"], ["84164.10", "0.046518"], ["84166.10", "0.122415"], ["84168.10", "0.322145"], ["84170.10", "0.847751"], ["84172.10", "2.230922"], ["84174.10", "5.870848"], ["84181.70", "1.201830"], ["84183.80", "0"], ["84216.10", "5.614762"], ["84224.60", "5.524202"], ["84233.10", "4.346913"], ["84241.60", "3.984670"], ["84250.10", "5.252520"], ["84258.60", "5.343080"], ["84267.10", "4.075231"], ["84275.60", "4.528034"], ["84284.10", "4.980838"], ["84292.60", "4.256352"], ["84301.10", "4.890277"], ["84309.60", "5.071398"], ["84318.10", "4.709156"], ["84326.60", "4.165792"], ["84335.10", "5.161959"], ["84343.60", "3.894110"], ["84352.10", "4.799716"], ["84360.60", "5.433641"], ["84369.10", "4.618595"], ["84377.60", "4.437474"], ["84530.00", "0.000031"], ["84533.01", "0.000591"]], "bids": [["84089.80", "4.492160"], ["84047.80", "4.165792"], ["84038.00", "0.000015"], ["84030.80", "4.528034"], ["84022.30", "3.984670"], ["84013.80", "4.346913"], ["84005.30", "5.071398"], ["83996.80", "5.161959"], ["83988.30", "4.618595"], ["83979.80", "5.433641"], ["83971.30", "5.252520"], ["83962.80", "4.890277"], ["83954.30", "4.075231"], ["83945.80", "4.799716"], ["83937.30", "5.524202"], ["83928.80", "5.343080"], ["83920.30", "4.437474"], ["83911.80", "4.256352"], ["83903.30", "3.894110"], ["83894.80", "5.614762"], ["83886.30", "4.709156"], ["83650.00", "0"]], "checksum": 22938123, "ts": "1742554942561"}], "ts": 1742554942564, "record_time": 1742554942.601161, "EXCHANGE": "BITGET"}
{"action": "update", "arg": {"instType": "SPOT", "channel": "books", "instId": "BTCUSDT"}, "data": [{"asks": [["84093.75", "0"], ["84096.02", "0"], ["84131.99", "0.012472"], ["84148.15", "0.001598"], ["84150.84", "0"], ["84160.10", "0.006851"], ["84162.10", "0.018028"], ["84164.10", "0.047443"], ["84166.10", "0.124850"], ["84168.10", "0.328553"], ["84170.10", "0.864612"], ["84172.10", "2.275295"], ["84174.10", "5.987619"], ["84181.70", "1.130520"], ["84183.80", "0.120000"], ["84216.10", "4.528034"], ["84224.60", "5.161959"], ["84233.10", "5.071398"], ["84241.60", "4.346913"], ["84250.10", "3.984670"], ["84258.60", "4.980838"], ["84267.10", "4.890277"], ["84275.60", "5.252520"], ["84284.10", "4.618595"], ["84291.53", "0"], ["84292.60", "5.343080"], ["84301.10", "4.437474"], ["84309.60", "3.894110"], ["84318.10", "5.433641"], ["84326.60", "4.075231"], ["84335.10", "4.709156"], ["84343.60", "4.256352"], ["84352.10", "5.524202"], ["84360.60", "4.165792"], ["84369.10", "4.799716"], ["84377.60", "5.614762"], ["84533.33", "0.003186"]], "bids": [["84089.80", "4.595669"], ["84047.80", "4.709156"], ["84040.51", "0"], ["84039.30", "5.071398"], ["84037.82", "0.001175"], ["84030.80", "4.075231"], ["84022.30", "4.165792"], ["84013.80", "4.618595"], ["84005.30", "3.894110"], ["83996.80", "5.252520"], ["83988.30", "5.614762"], ["83979.80", "5.343080"], ["83971.30", "4.256352"], ["83962.80", "4.980838"], ["83954.30", "4.890277"], ["83945.80", "5.433641"], ["83928.80", "3.984670"], ["83920.30", "4.799716"], ["83911.80", "4.346913"], ["83903.30", "4.528034"], ["83894.80", "4.437474"], ["83886.30", "5.161959"]], "checksum": -1808436666, "ts": "1742554942761"}], "ts": 1742554942764, "record_time": 1742554942.817816, "EXCHANGE": "BITGET"}
{"action": "update", "arg": {"instType": "SPOT", "channel": "books", "instId": "BTCUSDT"}, "data": [{"asks": [["84092.83", "0.028555"], ["84095.80", "0.086102"], ["84108.25", "0.112979"], ["84110.40", "0"], ["84131.98", "0.012472"], ["84131.99", "0"], ["84216.10", "4.709156"], ["84224.60", "4.799716"], ["84233.10", "3.984670"], ["84250.10", "5.524202"], ["84258.60", "5.252520"], ["84267.10", "5.161959"], ["84275.60", "5.614762"], ["84284.10", "4.980838"], ["84292.60", "4.528034"], ["84301.10", "4.256352"], ["84305.95", "0.160417"], ["84309.60", "4.075231"], ["84318.10", "3.894110"], ["84326.60", "4.437474"], ["84335.10", "4.165792"], ["84343.60", "5.343080"], ["84352.10", "4.890277"], ["84360.60", "4.618595"], ["84369.10", "5.433641"], ["84377.60", "5.071398"], ["84530.00", "0"], ["84533.01", "0"], ["84533.33", "0"]], "bids": [["84047.80", "4.075231"], ["84039.30", "5.433641"], ["84032.00", "0.000017"], ["84030.80", "4.528034"], ["84022.30", "5.161959"], ["84013.80", "4.437474"], ["84005.30", "5.524202"], ["83996.80", "4.165792"], ["83988.30", "3.984670"], ["83979.80", "4.799716"], ["83962.80", "5.252520"], ["83945.80", "4.980838"], ["83937.30", "3.894110"], ["83928.80", "4.709156"], ["83920.30", "4.618595"], ["83911.80", "5.343080"], ["83903.30", "4.346913"], ["83894.80", "5.071398"], ["83886.30", "5.614762"], ["83650.84", "0"]], "checksum": 2057481148, "ts": "1742554942973"}], "ts": 1742554942980, "record_time": 1742554943.021596, "EXCHANGE": "BITGET"}
{"action": "update", "arg": {"instType": "SPOT", "channel": "books", "instId": "BTCUSDT"}, "data": [{"asks": [["84108.24", "0.033894"], ["84109.20", "0.001980"], ["84150.10", "0.001597"], ["84152.48", "0.010000"], ["84152.91", "0"], ["84158.10", "0.002656"], ["84160.10", "0.006989"], ["84162.10", "0.018542"], ["84164.10", "0.048793"], ["84166.10", "0.128404"], ["84168.10", "0.337906"], ["84170.10", "0.889225"], ["84172.10", "2.340067"], ["84174.10", "6.158069"], ["84174.20", "0.373860"], ["84175.00", "0.971880"], ["84184.10", "0.453360"], ["84216.10", "5.071398"], ["84224.60", "4.346913"], ["84233.10", "5.433641"], ["84241.60", "4.165792"], ["84250.10", "4.709156"], ["84258.60", "3.894110"], ["84267.10", "5.252520"], ["84275.60", "4.075231"], ["84284.10", "3.984670"], ["84292.60", "4.890277"], ["84301.10", "5.614762"], ["84309.60", "4.618595"], ["84318.10", "5.161959"], ["84326.60", "5.524202"], ["84335.10", "5.343080"], ["84343.60", "4.799716"], ["84352.10", "4.437474"], ["84360.60", "4.980838"], ["84369.10", "4.256352"], ["84377.60", "4.528034"], ["84525.82", "0"], ["84527.47", "0"], ["84528.57", "0"]], "bids": [["84089.80", "4.359970"], ["84089.60", "0.001007"], ["84089.50", "0.303660"], ["84088.20", "0.064380"], ["84077.90", "0"], ["84077.70", "0"], ["84047.80", "4.346913"], ["84039.30", "5.524202"], ["84039.00", "0"], ["84038.71", "0"], ["84035.91", "0.001172"], ["84030.80", "3.984670"], ["84022.30", "4.709156"], ["84013.80", "5.161959"], ["84005.30", "5.071398"], ["83996.80", "5.614762"], ["83988.30", "4.980838"], ["83979.80", "5.343080"], ["83971.30", "3.894110"], ["83962.80", "5.433641"], ["83954.30", "5.252520"], ["83945.80", "4.256352"], ["83937.30", "4.528034"], ["83928.80", "4.618595"], ["83920.30", "4.165792"], ["83911.80", "4.799716"], ["83903.30", "4.075231"], ["83894.80", "4.890277"], ["83886.30", "4.437474"], ["83650.84", "0.003326"]], "checksum": 1555705092, "ts": "1742554943200"}], "ts": 1742554943203, "record_time": 1742554943.251472, "EXCHANGE": "BITGET"}
{"action": "update", "arg": {"instType": "SPOT", "channel": "books", "instId": "BTCUSDT"}, "data": [{"asks": [["84095.57", "0.086102"], ["84095.80", "0"], ["84109.20", "0.014809"], ["84162.10", "0.018178"], ["84164.10", "0.047837"], ["84166.10", "0.125888"], ["84168.10", "0.331284"], ["84170.10", "0.871799"], ["84172.10", "2.294209"], ["84174.10", "6.037393"], ["84178.30", "0.015000"], ["84184.10", "0"], ["84216.10", "4.618595"], ["84224.60", "4.980838"], ["84233.10", "4.528034"], ["84241.60", "5.524202"], ["84250.10", "5.252520"], ["84258.60", "5.161959"], ["84267.10", "3.894110"], ["84275.60", "5.343080"], ["84284.10", "4.346913"], ["84292.60", "4.075231"], ["84301.10", "4.890277"], ["84309.60", "4.709156"], ["84318.10", "5.433641"], ["84326.60", "4.256352"], ["84335.10", "4.799716"], ["84343.60", "4.437474"], ["84352.10", "4.165792"], ["84360.60", "5.614762"], ["84369.10", "5.071398"], ["84377.60", "3.984670"]], "bids": [["84089.80", "4.368656"], ["84082.30", "0"], ["84077.90", "0.067980"], ["84060.00", "0.185751"], ["84047.80", "5.071398"], ["84039.30", "5.161959"], ["84030.80", "4.709156"], ["84022.30", "4.980838"], ["84013.80", "4.618595"], ["84005.30", "4.437474"], ["83988.30", "5.524202"], ["83979.80", "4.075231"], ["83971.30", "4.799716"], ["83962.80", "4.256352"], ["83945.80", "5.343080"], ["83937.30", "4.165792"], ["83928.80", "4.890277"], ["83920.30", "3.894110"], ["83911.80", "3.984670"], ["83903.30", "4.346913"], ["83894.80", "5.433641"], ["83886.30", "4.528034"]], "checksum": -1022320367, "ts": "1742554943405"}], "ts": 1742554943410, "record_time": 1742554943.445461, "EXCHANGE": "BITGET"}
{"action": "update", "arg": {"instType": "SPOT", "channel": "books", "instId": "BTCUSDT"}, "data": [{"asks": [["84131.97", "0.003742"], ["84160.10", "0.006851"], ["84162.10", "0.018029"], ["84164.10", "0.047444"], ["84166.10", "0.124854"], ["84168.10", "0.328563"], ["84170.10", "0.864639"], ["84172.10", "2.275366"], ["84174.10", "5.987805"], ["84216.10", "4.256352"], ["84224.60", "5.161959"], ["84233.10", "4.618595"], ["84250.10", "4.528034"], ["84258.60", "5.433641"], ["84267.10", "4.075231"], ["84275.60", "4.890277"], ["84292.60", "4.165792"], ["84301.10", "3.984670"], ["84309.60", "4.437474"], ["84318.10", "3.894110"], ["84326.60", "4.799716"], ["84335.10", "5.252520"], ["84343.60", "4.980838"], ["84352.10", "5.343080"], ["84360.60", "4.709156"], ["84377.60", "5.614762"], ["84525.00", "0"]], "bids": [["84089.99", "1.868390"], ["84089.80", "4.365978"], ["84047.80", "4.618595"], ["84039.30", "3.894110"], ["84033.00", "0"], ["84030.80", "4.256352"], ["84022.30", "4.165792"], ["84013.80", "4.890277"], ["84005.30", "5.161959"], ["83996.80", "5.071398"], ["83988.30", "4.799716"], ["83979.80", "5.614762"], ["83971.30", "5.433641"], ["83962.80", "4.346913"], ["83954.30", "5.343080"], ["83945.80", "5.524202"], ["83937.30", "4.980838"], ["83928.80", "4.528034"], ["83920.30", "4.437474"], ["83911.80", "5.252520"], ["83903.30", "4.075231"], ["83894.80", "3.984670"], ["83886.30", "4.709156"], ["83650.00", "0.032056"]], "checksum": -844453304, "ts": "1742554943611"}], "ts": 1742554943614, "record_time": 1742554943.647531, "EXCHANGE": "BITGET"}
{"action": "update", "arg": {"instType": "SPOT", "channel": "books", "instId": "BTCUSDT"}, "data": [{"asks": [["84095.57", "0"], ["84156.09", "0.001112"], ["84162.10", "0.017779"], ["84164.10", "0.046787"], ["84166.10", "0.123124"], ["84168.10", "0.324011"], ["84170.10", "0.852660"], ["84172.10", "2.243843"], ["84174.10", "5.904849"], ["84216.10", "4.346913"], ["84224.60", "5.343080"], ["84233.10", "5.161959"], ["84241.60", "4.618595"], ["84250.10", "5.614762"], ["84258.60", "4.165792"], ["84267.10", "5.252520"], ["84275.60", "4.075231"], ["84284.10", "4.980838"], ["84292.60", "4.256352"], ["84301.10", "5.524202"], ["84309.60", "4.890277"], ["84318.10", "4.799716"], ["84326.60", "4.528034"], ["84335.10", "5.071398"], ["84343.60", "4.709156"], ["84352.10", "3.984670"], ["84360.60", "5.433641"], ["84369.10", "3.894110"], ["84377.60", "4.437474"]], "bids": [["84089.80", "4.365569"], ["84047.80", "5.433641"], ["84039.30", "4.075231"], ["84022.30", "4.618595"], ["84013.80", "5.161959"], ["84005.30", "5.524202"], ["83996.80", "4.980838"], ["83988.30", "5.252520"], ["83979.80", "4.709156"], ["83971.30", "5.614762"], ["83962.80", "4.799716"], ["83954.30", "3.984670"], ["83945.80", "4.437474"], ["83937.30", "5.071398"], ["83928.80", "4.346913"], ["83920.30", "5.343080"], ["83911.80", "4.528034"], ["83903.30", "3.894110"], ["83894.80", "4.165792"], ["83886.30", "4.890277"]], "checksum": -1693930618, "ts": "1742554943829"}], "ts": 1742554943832, "record_time": 1742554943.866832, "EXCHANGE": "BITGET"}
{"action": "update", "arg": {"instType": "SPOT", "channel": "books", "instId": "BTCUSDT"}, "data": [{"asks": [["84090.00", "1.267807"], ["84090.01", "0.000220"], ["84092.83", "0"], ["84095.39", "0.086103"], ["84109.21", "0"], ["84109.24", "0"], ["84109.29", "0"], ["84109.35", "0"], ["84117.66", "0"], ["84144.90", "0"], ["84149.50", "0.001023"], ["84151.50", "0.001048"], ["84152.48", "0"], ["84153.50", "0.001998"], ["84154.10", "0"], ["84155.50", "0.005258"], ["84156.10", "0"], ["84157.50", "0.013835"], ["84158.10", "0"], ["84159.50", "0.036409"], ["84160.10", "0"], ["84161.41", "0"], ["84161.50", "0.095812"], ["84162.10", "0"], ["84163.50", "0.252138"], ["84164.10", "0"], ["84165.50", "0.663521"], ["84166.10", "0"], ["84167.50", "1.746107"], ["84168.10", "0"], ["84169.50", "4.595018"], ["84170.00", "0.167700"], ["84170.10", "10.607970"], ["84170.20", "3.741120"], ["84170.80", "7.421250"], ["84170.90", "0.075180"], ["84172.10", "0.068190"], ["84172.50", "0.642240"], ["84173.20", "0.107400"], ["84174.10", "2.255820"], ["84174.20", "0.748410"], ["84175.00", "0.970050"], ["84175.60", "0.269760"], ["84175.70", "0"], ["84175.80", "0"], ["84175.90", "0.453360"], ["84176.00", "0.070560"], ["84176.40", "0.144510"], ["84176.50", "2.673330"], ["84177.00", "0"], ["84177.40", "0"], ["84177.60", "0"], ["84177.80", "0"], ["84179.40", "0"], ["84180.60", "0"], ["84180.80", "0"], ["84182.00", "1.069320"], ["84182.09", "0.006398"], ["84182.30", "0"], ["84182.50", "0"], ["84182.90", "0"], ["84183.00", "0"], ["84183.40", "0"], ["84183.50", "0"], ["84183.80", "0"], ["84211.50", "5.071676"], ["84216.10", "0"], ["84220.00", "3.984889"], ["84224.60", "0"], ["84228.50", "4.890545"], ["84233.10", "0"], ["84237.00", "5.162242"], ["84241.60", "0"], ["84245.50", "5.433939"], ["84250.10", "0"], ["84254.00", "3.894323"], ["84258.60", "0"], ["84262.50", "4.618848"], ["84267.10", "0"], ["84271.00", "4.347151"], ["84275.60", "0"], ["84279.50", "4.075454"], ["84284.10", "0"], ["84288.00", "4.256585"], ["84292.60", "0"], ["84296.50", "4.709414"], ["84301.10", "0"], ["84305.00", "4.166020"], ["84309.60", "0"], ["84313.50", "5.524504"], ["84318.10", "0"], ["84322.00", "4.799979"], ["84326.60", "0"], ["84330.50", "4.528282"], ["84335.10", "0"], ["84339.00", "5.615070"], ["84343.60", "0"], ["84347.50", "5.252808"], ["84352.10", "0"], ["84356.00", "5.343373"], ["84360.60", "0"], ["84364.50", "4.437717"], ["84369.10", "0"], ["84373.00", "4.981111"], ["84377.60", "0"], ["84525.00", "0.003286"], ["84525.82", "0.000099"], ["84527.47", "0.000608"], ["84528.57", "0.000008"], ["84530.00", "0.000031"], ["84533.01", "0.000591"], ["84533.33", "0.003186"], ["84534.53", "0.000461"], ["84535.32", "0.000039"]], "bids": [["84089.99", "0.408105"], ["84089.80", "0"], ["84089.70", "0"], ["84089.60", "0"], ["84089.50", "0"], ["84089.20", "0.030347"], ["84088.20", "0"], ["84088.10", "0"], ["84087.90", "0"], ["84087.20", "0.079862"], ["84086.30", "0"], ["84085.90", "0"], ["84085.20", "0.210161"], ["84085.00", "0.001050"], ["84084.50", "0.001040"], ["84084.40", "0.001029"], ["84084.10", "0.001039"], ["84083.97", "0.040023"], ["84083.70", "0.001041"], ["84083.50", "0.004350"], ["84083.30", "0.305790"], ["84083.10", "0"], ["84082.00", "0.022710"], ["84081.90", "0.068190"], ["84081.80", "0.249210"], ["84081.52", "0"], ["84081.40", "0.263100"], ["84081.30", "0"], ["84081.00", "0.144690"], ["84080.50", "0.232170"], ["84080.10", "0"], ["84079.89", "0"], ["84079.70", "0.066120"], ["84079.20", "0.619200"], ["84077.70", "1.474890"], ["84076.70", "0.120000"], ["84076.50", "0.240000"], ["84076.40", "0.120000"], ["84075.90", "0.548370"], ["84075.02", "0.027453"], ["84074.90", "0.009000"], ["84074.20", "0.120000"], ["84072.22", "0"], ["84072.06", "0"], ["84072.03", "0"], ["84072.00", "0.000032"], ["84071.80", "0"], ["84071.30", "0"], ["84071.24", "0"], ["84071.19", "0"], ["84069.89", "0"], ["84064.23", "0"], ["84064.13", "0"], ["84064.08", "0"], ["84048.39", "0"], ["84047.80", "0"], ["84045.42", "0"], ["84043.45", "0"], ["84043.43", "0"], ["84043.23", "0"], ["84043.20", "4.437717"], ["84040.00", "0.001244"], ["84039.30", "0"], ["84034.70", "4.166020"], ["84030.80", "0"], ["84026.20", "5.524504"], ["84022.30", "0"], ["84017.70", "4.256585"], ["84013.80", "0"], ["84009.20", "5.343373"], ["84005.30", "0"], ["84000.70", "4.347151"], ["83996.80", "0"], ["83992.20", "5.162242"], ["83988.30", "0"], ["83983.70", "5.433939"], ["83979.80", "0"], ["83975.20", "5.071676"], ["83971.30", "0"], ["83966.70", "5.615070"], ["83962.80", "0"], ["83958.20", "5.252808"], ["83954.30", "0"], ["83949.70", "4.618848"], ["83945.80", "0"], ["83941.20", "4.981111"], ["83937.30", "0"], ["83932.70", "4.075454"], ["83928.80", "0"], ["83924.20", "3.894323"], ["83920.30", "0"], ["83915.70", "4.528282"], ["83911.80", "0"], ["83907.20", "4.890545"], ["83903.30", "0"], ["83898.70", "3.984889"], ["83894.80", "0"], ["83890.20", "4.799979"], ["83886.30", "0"], ["83881.70", "4.709414"], ["83648.96", "0.000030"], ["83647.46", "0.000224"], ["83647.06", "0.000040"], ["83646.67", "0.000018"], ["83645.83", "0.000014"], ["83644.86", "0.000034"], ["83644.33", "0.000013"], ["83643.18", "0.000052"], ["83641.86", "0.000379"], ["83641.62", "0.002925"], ["83641.38", "0.000135"], ["83641.00", "0.000082"], ["83640.35", "0.000022"], ["83640.15", "0.000423"], ["83640.00", "0.002013"]], "checksum": 1432742438, "ts": "1742554944030"}], "ts": 1742554944038, "record_time": 1742554944.075125, "EXCHANGE": "BITGET"}
{"action": "update", "arg": {"instType": "SPOT", "channel": "books", "instId": "BTCUSDT"}, "data": [{"asks": [["84090.00", "2.056804"], ["84092.82", "0.000222"], ["84095.38", "0.025831"], ["84098.08", "0.112975"], ["84100.21", "0.000865"], ["84100.23", "0.006601"], ["84101.44", "0.009407"], ["84101.51", "0.006307"], ["84101.72", "0.005575"], ["84103.08", "0"], ["84103.64", "0.007162"], ["84103.75", "0.035952"], ["84103.99", "0.119870"], ["84105.04", "0.035961"], ["84105.36", "0.006356"], ["84105.89", "0.006356"], ["84106.20", "0.006356"], ["84107.13", "0.006356"], ["84107.28", "0.006356"], ["84107.88", "0.016429"], ["84108.25", "0"], ["84108.38", "0.006356"], ["84108.68", "0.006356"], ["84108.70", "0.010984"], ["84108.82", "0.006356"], ["84108.97", "0.016429"], ["84109.02", "0.119883"], ["84109.17", "0.006356"], ["84109.20", "0.001980"], ["84109.27", "0"], ["84109.32", "0.006356"], ["84110.39", "0"], ["84110.45", "0.010985"], ["84110.87", "0.006357"], ["84111.75", "0.009990"], ["84112.75", "0.119850"], ["84113.42", "0.119858"], ["84113.65", "0.119867"], ["84113.70", "0.015895"], ["84113.99", "0"], ["84114.04", "0.009989"], ["84114.33", "0.012472"], ["84114.34", "0"], ["84115.67", "0"], ["84116.29", "0"], ["84116.41", "0"], ["84116.73", "0"], ["84117.44", "0.015892"], ["84118.05", "0"], ["84118.20", "0"], ["84118.65", "0"], ["84118.66", "0.010988"], ["84118.81", "0"], ["84119.20", "0"], ["84119.38", "0"], ["84119.43", "0"], ["84119.54", "0"], ["84119.69", "0"], ["84119.86", "0"], ["84121.40", "0"], ["84121.43", "0"], ["84121.99", "0"], ["84122.88", "0"], ["84123.94", "0"], ["84124.34", "0"], ["84124.56", "0"], ["84125.14", "0"], ["84129.29", "0"], ["84130.02", "0"], ["84131.98", "0"], ["84146.20", "0.001415"], ["84148.20", "0.002309"], ["84149.50", "0"], ["84150.20", "0.006075"], ["84151.50", "0"], ["84152.20", "0.015988"], ["84152.37", "0"], ["84153.50", "0"], ["84153.56", "0.712982"], ["84154.20", "0.042074"], ["84155.50", "0"], ["84156.20", "0.110720"], ["84157.50", "0"], ["84158.20", "0.291368"], ["84159.50", "0"], ["84160.20", "0.766758"], ["84161.50", "0"], ["84162.20", "2.017786"], ["84163.50", "0"], ["84164.20", "5.309962"], ["84165.50", "0"], ["84166.20", "13.973585"], ["84166.80", "0.006060"], ["84167.20", "7.466340"], ["84167.50", "0.254820"], ["84168.10", "0.067980"], ["84169.20", "0.143220"], ["84169.50", "1.525830"], ["84170.00", "0"], ["84170.10", "0.067980"], ["84170.20", "0"], ["84170.80", "1.969890"], ["84170.90", "0"], ["84171.00", "0.004140"], ["84172.10", "0.067980"], ["84173.30", "0.473070"], ["84173.90", "0.120000"], ["84174.10", "1.539420"], ["84174.20", "0.035640"], ["84174.40", "0"], ["84174.70", "0.071310"], ["84175.20", "0.071310"], ["84175.60", "1.177290"], ["84175.90", "0"], ["84176.40", "0"], ["84177.00", "0.178290"], ["84177.20", "0.249120"], ["84177.70", "0.024930"], ["84178.40", "0"], ["84178.80", "0.178200"], ["84179.00", "5.162730"], ["84179.50", "0"], ["84180.10", "0.035640"], ["84180.40", "2.568420"], ["84181.20", "0"], ["84181.70", "0"], ["84182.00", "0"], ["84182.10", "0"], ["84208.30", "5.434148"], ["84209.47", "0.071253"], ["84211.50", "0"], ["84216.80", "4.981302"], ["84220.00", "0"], ["84221.19", "0.125569"], ["84225.30", "4.075611"], ["84228.50", "0"], ["84231.38", "0"], ["84233.80", "5.343579"], ["84237.00", "0"], ["84242.30", "4.437888"], ["84242.91", "0"], ["84245.50", "0"], ["84250.80", "4.800164"], ["84254.00", "0"], ["84259.30", "5.253010"], ["84262.50", "0"], ["84267.80", "4.890733"], ["84271.00", "0"], ["84276.30", "5.071872"], ["84279.50", "0"], ["84284.80", "5.162441"], ["84288.00", "0"], ["84293.30", "4.528457"], ["84296.50", "0"], ["84301.80", "3.985042"], ["84305.00", "0"], ["84310.30", "5.615286"], ["84313.50", "0"], ["84318.80", "4.619026"], ["84322.00", "0"], ["84327.30", "4.347319"], ["84330.50", "0"], ["84335.80", "5.524717"], ["84339.00", "0"], ["84344.30", "4.166180"], ["84347.50", "0"], ["84352.80", "3.894473"], ["84356.00", "0"], ["84361.30", "4.256749"], ["84364.50", "0"], ["84369.80", "4.709595"], ["84373.00", "0"], ["84524.83", "0"], ["84525.00", "0"], ["84525.82", "0"], ["84527.47", "0"], ["84528.57", "0"], ["84530.00", "0"], ["84533.01", "0"], ["84533.33", "0"], ["84534.53", "0"], ["84535.32", "0"]], "bids": [["84089.99", "0.446555"], ["84089.98", "0.000100"], ["84089.97", "0.000100"], ["84089.96", "0.000100"], ["84089.81", "0"], ["84089.20", "0"], ["84089.18", "0.035676"], ["84089.13", "0"], ["84089.12", "0"], ["84089.07", "0.007749"], ["84088.92", "0.010000"], ["84088.91", "0.009713"], ["84088.69", "0"], ["84088.68", "0"], ["84088.64", "0"], ["84088.62", "0"], ["84088.60", "0"], ["84088.58", "0"], ["84088.00", "0.001039"], ["84087.69", "0.009587"], ["84087.66", "0.014155"], ["84087.64", "0.007466"], ["84087.63", "0.007793"], ["84087.62", "0.008499"], ["84087.44", "0.041059"], ["84087.20", "0"], ["84086.00", "0.001025"], ["84085.20", "0"], ["84085.00", "0.000015"], ["84084.50", "0"], ["84084.40", "0"], ["84084.10", "0"], ["84084.00", "0.001037"], ["84083.97", "0.025963"], ["84083.70", "0"], ["84083.59", "0.008711"], ["84083.54", "0.008895"], ["84083.53", "0.008534"], ["84083.52", "0.015442"], ["84083.50", "0"], ["84083.47", "0.015160"], ["84083.44", "0.005169"], ["84083.43", "0.005117"], ["84083.30", "0"], ["84083.20", "0"], ["84082.05", "0.012472"], ["84082.00", "0.002344"], ["84081.90", "0.006480"], ["84081.80", "0.001050"], ["84081.60", "0.001017"], ["84081.40", "0"], ["84081.14", "0.021425"], ["84081.00", "0.000017"], ["84080.50", "0.233010"], ["84080.00", "0.003960"], ["84079.90", "0"], ["84079.70", "0"], ["84079.20", "0"], ["84078.40", "0"], ["84077.90", "0"], ["84077.80", "0.441240"], ["84077.70", "0"], ["84077.40", "0.022770"], ["84076.84", "0.019223"], ["84076.70", "0"], ["84076.50", "0"], ["84076.40", "0"], ["84075.90", "0.112980"], ["84075.60", "1.070610"], ["84075.46", "0.008267"], ["84075.02", "0"], ["84074.20", "0"], ["84073.90", "0.068010"], ["84073.63", "0"], ["84073.14", "0"], ["84072.60", "0.878280"], ["84072.50", "0.072210"], ["84072.11", "0.008057"], ["84071.95", "0"], ["84071.90", "0.067800"], ["84071.72", "0"], ["84071.51", "0"], ["84071.15", "0"], ["84070.70", "2.673330"], ["84070.59", "0"], ["84070.50", "0.007800"], ["84069.90", "0.067800"], ["84069.78", "0"], ["84069.60", "0"], ["84069.40", "1.284090"], ["84069.19", "0"], ["84069.03", "0"], ["84069.00", "0.066540"], ["84068.76", "0"], ["84068.70", "0.003750"], ["84068.58", "0"], ["84068.40", "0.938010"], ["84068.24", "0"], ["84068.22", "0"], ["84068.13", "0"], ["84068.06", "0"], ["84067.90", "0.067800"], ["84067.80", "0.012600"], ["84066.77", "0"], ["84066.74", "0"], ["84066.39", "0.027453"], ["84065.65", "0"], ["84065.12", "0.006470"], ["84064.69", "0"], ["84064.59", "0"], ["84063.73", "0"], ["84063.57", "0.008426"], ["84063.51", "0.009208"], ["84063.45", "0.006905"], ["84063.41", "0.007304"], ["84063.39", "0.089456"], ["84063.37", "0.008595"], ["84063.30", "0.008319"], ["84063.28", "0"], ["84063.17", "0"], ["84062.78", "0.247509"], ["84062.15", "0.008012"], ["84061.93", "0.055638"], ["84061.31", "0.083913"], ["84060.99", "0.018249"], ["84060.80", "0.017811"], ["84060.63", "0.005944"], ["84060.34", "0"], ["84059.38", "0"], ["84058.87", "0.017098"], ["84058.77", "0.007337"], ["84058.68", "0.007129"], ["84058.50", "0.004016"], ["84058.27", "0.028855"], ["84058.21", "0.008991"], ["84058.06", "0.007940"], ["84057.73", "0.224811"], ["84057.69", "0.008182"], ["84057.68", "0.025176"], ["84057.54", "0.017345"], ["84056.61", "0.008092"], ["84056.34", "0.008263"], ["84056.30", "0.005051"], ["84056.21", "0.012651"], ["84055.80", "0.051947"], ["84055.42", "0.018511"], ["84054.57", "0.268292"], ["84053.22", "0.222599"], ["84053.11", "0.259713"], ["84052.66", "0.021123"], ["84052.65", "0.076088"], ["84048.49", "0.073192"], ["84048.03", "0.056349"], ["84043.20", "0"], ["84040.60", "0.007432"], ["84040.00", "0.001261"], ["84039.90", "4.347319"], ["84039.41", "0.008570"], ["84036.86", "0.007650"], ["84036.76", "0.007246"], ["84034.70", "0"], ["84034.30", "0.007334"], ["84031.40", "4.800164"], ["84026.20", "0"], ["84022.90", "4.075611"], ["84017.70", "0"], ["84014.40", "4.981302"], ["84009.20", "0"], ["84005.90", "5.524717"], ["84000.70", "0"], ["83997.40", "3.985042"], ["83992.20", "0"], ["83988.90", "5.615286"], ["83983.70", "0"], ["83980.40", "4.166180"], ["83975.20", "0"], ["83971.90", "5.434148"], ["83966.70", "0"], ["83963.40", "4.619026"], ["83958.20", "0"], ["83954.90", "4.256749"], ["83949.70", "0"], ["83946.40", "5.343579"], ["83941.20", "0"], ["83937.90", "3.894473"], ["83932.70", "0"], ["83929.40", "5.071872"], ["83924.20", "0"], ["83920.90", "5.253010"], ["83915.70", "0"], ["83912.40", "4.709595"], ["83907.20", "0"], ["83903.90", "5.162441"], ["83898.70", "0"], ["83895.40", "4.890733"], ["83890.20", "0"], ["83886.90", "4.528457"], ["83881.70", "0"], ["83878.40", "4.437888"], ["83656.60", "0"], ["83655.00", "0"], ["83654.23", "0"], ["83653.94", "0"], ["83653.67", "0"], ["83653.31", "0"], ["83652.80", "0"], ["83652.48", "0"], ["83651.65", "0"], ["83651.16", "0"], ["83650.84", "0"], ["83650.00", "0"], ["83648.96", "0"], ["83647.46", "0"], ["83647.06", "0"], ["83646.67", "0"], ["83645.83", "0"], ["83644.86", "0"], ["83644.33", "0"], ["83643.18", "0"], ["83641.86", "0"], ["83641.62", "0"], ["83641.38", "0"], ["83641.00", "0"], ["83640.35", "0"], ["83640.15", "0"], ["83640.00", "0"]], "checksum": -602737795, "ts": "1742554944230"}], "ts": 1742554944236, "record_time": 1742554944.27192, "EXCHANGE": "BITGET"}
{"action": "update", "arg": {"instType": "SPOT", "channel": "books", "instId": "BTCUSDT"}, "data": [{"asks": [["84090.00", "2.157196"], ["84092.82", "0"], ["84095.39", "0"], ["84098.07", "0.098892"], ["84098.08", "0"], ["84098.40", "0"], ["84100.23", "0"], ["84101.44", "0"], ["84101.51", "0"], ["84103.64", "0"], ["84103.74", "0.046747"], ["84103.75", "0"], ["84103.99", "0"], ["84105.04", "0"], ["84105.36", "0"], ["84105.89", "0"], ["84106.20", "0"], ["84107.13", "0"], ["84107.28", "0"], ["84107.88", "0"], ["84108.38", "0"], ["84108.68", "0"], ["84108.70", "0"], ["84108.82", "0"], ["84108.97", "0"], ["84109.02", "0"], ["84109.17", "0"], ["84109.32", "0"], ["84110.45", "0"], ["84110.87", "0"], ["84111.75", "0"], ["84112.75", "0"], ["84113.42", "0"], ["84113.70", "0"], ["84114.04", "0"], ["84117.44", "0"], ["84117.89", "0"], ["84118.66", "0"], ["84124.40", "0"], ["84131.97", "0"], ["84138.63", "0.176322"], ["84148.15", "0"], ["84148.20", "0.002171"], ["84150.10", "0"], ["84150.20", "0.005711"], ["84152.20", "0.015029"], ["84152.38", "0"], ["84154.20", "0.039551"], ["84156.20", "0.104081"], ["84158.20", "0.273898"], ["84160.20", "0.720785"], ["84162.20", "1.897060"], ["84164.20", "4.992263"], ["84166.20", "13.137533"], ["84167.20", "5.211810"], ["84169.50", "1.525440"], ["84169.60", "0.120000"], ["84169.80", "0.070770"], ["84170.50", "0.120000"], ["84170.80", "1.053600"], ["84172.10", "0.067800"], ["84172.50", "0.642060"], ["84173.80", "0.228000"], ["84174.70", "0.287310"], ["84174.90", "0.192000"], ["84175.60", "1.357290"], ["84176.00", "0"], ["84176.80", "0.035640"], ["84178.30", "0"], ["84178.80", "0"], ["84179.00", "0"], ["84180.10", "0"], ["84180.30", "0"], ["84180.40", "0"], ["84208.30", "5.615286"], ["84216.80", "3.985042"], ["84225.30", "5.343579"], ["84233.80", "4.166180"], ["84242.30", "5.071872"], ["84250.80", "4.256749"], ["84259.30", "4.709595"], ["84267.80", "4.437888"], ["84276.30", "4.981302"], ["84284.80", "4.890733"], ["84293.30", "5.524717"], ["84301.80", "4.619026"], ["84310.30", "4.075611"], ["84318.80", "4.800164"], ["84327.30", "5.253010"], ["84335.80", "4.528457"], ["84344.30", "5.162441"], ["84352.80", "4.347319"], ["84361.30", "5.434148"], ["84369.80", "3.894473"], ["84524.83", "0.000009"], ["84525.00", "0.003286"], ["84525.82", "0.000099"], ["84527.47", "0.000608"], ["84528.57", "0.000008"], ["84530.00", "0.000031"], ["84533.01", "0.000591"], ["84533.33", "0.003186"], ["84534.53", "0.000461"], ["84535.32", "0.000039"], ["84536.36", "0.000053"], ["84537.04", "0.000958"], ["84538.75", "0.000011"], ["84540.00", "0.001092"], ["84540.54", "0.000184"], ["84540.97", "0.000065"], ["84541.67", "0.000198"], ["84542.37", "0.001213"], ["84543.27", "0.000067"], ["84543.43", "0.000423"], ["84543.86", "0.000033"], ["84543.93", "0.000010"], ["84544.64", "0.000036"], ["84545.16", "0.000020"], ["84545.45", "0.001774"], ["84545.63", "0.000008"], ["84547.06", "0.000071"], ["84549.65", "0.000030"], ["84549.96", "0.000012"], ["84550.00", "0.009759"], ["84550.60", "0.000096"], ["84551.02", "0.000085"], ["84552.59", "0.000009"], ["84552.95", "0.000009"], ["84553.04", "0.000129"], ["84554.00", "0.000113"], ["84555.00", "0.005926"], ["84555.08", "0.000022"]], "bids": [["84089.99", "0.030333"], ["84089.18", "0"], ["84089.07", "0"], ["84088.92", "0"], ["84088.91", "0"], ["84087.69", "0"], ["84087.62", "0"], ["84087.44", "0"], ["84084.00", "0.002474"], ["84083.52", "0"], ["84083.47", "0"], ["84083.44", "0"], ["84083.43", "0"], ["84082.05", "0"], ["84082.00", "0.006510"], ["84080.50", "0.233490"], ["84078.70", "0.396990"], ["84078.50", "0.072270"], ["84077.80", "0"], ["84076.70", "0.896130"], ["84075.90", "0.068010"], ["84075.70", "0"], ["84075.60", "0"], ["84075.46", "0"], ["84073.90", "0.067800"], ["84072.61", "0.307914"], ["84072.60", "1.491660"], ["84070.99", "0"], ["84069.50", "2.355120"], ["84069.40", "0.707220"], ["84068.40", "1.058010"], ["84067.90", "0"], ["84067.80", "0"], ["84063.57", "0"], ["84063.51", "0"], ["84063.45", "0"], ["84063.41", "0"], ["84063.39", "0"], ["84062.78", "0"], ["84062.16", "0.014842"], ["84062.15", "0"], ["84061.93", "0"], ["84061.31", "0"], ["84060.99", "0"], ["84060.80", "0"], ["84060.63", "0"], ["84058.87", "0"], ["84058.77", "0"], ["84058.68", "0"], ["84058.27", "0"], ["84058.21", "0"], ["84058.06", "0"], ["84057.73", "0"], ["84057.69", "0"], ["84057.68", "0"], ["84057.54", "0"], ["84056.79", "0"], ["84056.34", "0"], ["84056.21", "0"], ["84055.80", "0"], ["84055.42", "0"], ["84054.57", "0"], ["84053.22", "0"], ["84052.66", "0"], ["84052.65", "0"], ["84048.49", "0"], ["84048.03", "0"], ["84046.20", "0"], ["84040.60", "0"], ["84039.90", "5.071872"], ["84037.82", "0"], ["84036.86", "0"], ["84035.91", "0"], ["84034.30", "0"], ["84031.40", "5.434148"], ["84022.90", "4.890733"], ["84014.40", "4.619026"], ["84005.90", "4.075611"], ["83997.40", "5.253010"], ["83988.90", "5.524717"], ["83980.40", "5.343579"], ["83971.90", "3.985042"], ["83963.40", "4.528457"], ["83954.90", "4.800164"], ["83946.40", "4.437888"], ["83929.40", "4.166180"], ["83920.90", "4.256749"], ["83912.40", "4.981302"], ["83903.90", "4.709595"], ["83895.40", "5.615286"], ["83886.90", "5.162441"], ["83878.40", "4.347319"], ["83656.60", "0.000607"], ["83655.00", "0.000926"], ["83654.23", "0.000009"], ["83653.94", "0.000133"], ["83653.67", "0.001695"], ["83653.31", "0.000015"], ["83652.80", "0.000119"], ["83652.48", "0.000188"], ["83651.65", "0.000018"], ["83651.16", "0.000896"], ["83650.84", "0.003326"], ["83650.00", "0.032056"], ["83648.96", "0.000030"], ["83647.46", "0.000224"], ["83647.06", "0.000040"], ["83646.67", "0.000018"], ["83645.83", "0.000014"], ["83644.86", "0.000034"], ["83644.33", "0.000013"], ["83643.18", "0.000052"], ["83641.86", "0.000379"], ["83641.62", "0.002925"], ["83641.38", "0.000135"], ["83641.00", "0.000082"], ["83640.35", "0.000022"], ["83640.15", "0.000423"], ["83640.00", "0.002013"], ["83639.71", "0.000041"], ["83639.70", "0.000010"], ["83639.15", "0.000009"], ["83638.32", "0.000039"], ["83638.30", "0.000137"], ["83637.17", "0.000027"], ["83636.36", "0.000179"], ["83635.64", "0.000030"], ["83634.09", "0.000124"], ["83634.05", "0.000008"], ["83633.88", "0.000071"], ["83633.63", "0.000521"], ["83633.61", "0.000059"], ["83633.40", "0.000076"], ["83633.33", "0.000970"], ["83633.19", "0.007264"], ["83632.65", "0.000085"], ["83632.10", "0.000012"], ["83632.02", "0.000459"], ["83631.58", "0.000330"], ["83631.57", "0.000019"], ["83631.53", "0.000009"], ["83631.09", "0.002040"], ["83630.43", "0.000010"], ["83629.43", "0.000025"]], "checksum": 2114396504, "ts": "1742554944436"}], "ts": 1742554944440, "record_time": 1742554944.464837, "EXCHANGE": "BITGET"}
{"action": "update", "arg": {"instType": "SPOT", "channel": "books", "instId": "BTCUSDT"}, "data": [{"asks": [["84090.00", "2.066078"], ["84090.01", "0.000100"], ["84090.62", "0.009407"], ["84090.67", "0.000865"], ["84090.69", "0.012908"], ["84090.71", "0.005575"], ["84090.81", "0.007162"], ["84092.55", "0.112975"], ["84095.29", "0.035952"], ["84095.38", "0"], ["84095.84", "0.119870"], ["84096.97", "0.035961"], ["84097.61", "0.006356"], ["84097.74", "0.006356"], ["84098.06", "0.006356"], ["84098.07", "0.063020"], ["84099.14", "0.010984"], ["84099.38", "0.006356"], ["84099.54", "0.006356"], ["84099.91", "0.006356"], ["84100.14", "0.016429"], ["84100.21", "0"], ["84100.54", "0.006356"], ["84100.68", "0.006356"], ["84100.87", "0.119883"], ["84100.90", "0.016429"], ["84101.02", "0.006356"], ["84101.17", "0.006356"], ["84101.72", "0"], ["84102.71", "0.010985"], ["84102.72", "0.006357"], ["84103.29", "0.009990"], ["84103.74", "0"], ["84103.86", "0.119867"], ["84104.29", "0.119850"], ["84104.95", "0.119858"], ["84105.34", "0.017446"], ["84105.63", "0.015895"], ["84106.28", "0.009989"], ["84108.24", "0"], ["84108.44", "1.531031"], ["84109.20", "0"], ["84109.70", "0.015892"], ["84110.19", "0.010988"], ["84113.65", "0"], ["84118.22", "0"], ["84124.39", "0"], ["84129.08", "0.001598"], ["84131.51", "0.001597"], ["84136.42", "3.568855"], ["84136.70", "0.001152"], ["84138.70", "0.001880"], ["84140.70", "0.004946"], ["84142.70", "0.013016"], ["84144.03", "0.713063"], ["84144.70", "0.034517"], ["84146.20", "0"], ["84146.70", "0.090832"], ["84148.20", "0"], ["84148.70", "0.239033"], ["84150.20", "0"], ["84150.70", "0.629034"], ["84152.20", "0"], ["84152.70", "1.655353"], ["84153.56", "0"], ["84154.20", "0"], ["84154.70", "4.356192"], ["84156.20", "0"], ["84156.70", "11.463664"], ["84157.10", "0.070350"], ["84157.70", "0.003480"], ["84157.90", "0.269940"], ["84158.10", "1.882530"], ["84158.20", "0"], ["84158.40", "0.035640"], ["84158.50", "0.405750"], ["84160.10", "0.473730"], ["84160.20", "0.071190"], ["84161.00", "0.100860"], ["84161.60", "0.534840"], ["84161.70", "0.003960"], ["84162.10", "0.067980"], ["84162.20", "0"], ["84163.10", "0.178200"], ["84163.90", "0.146250"], ["84164.10", "0.067800"], ["84164.20", "1.618980"], ["84164.40", "1.079040"], ["84164.80", "1.364220"], ["84166.20", "4.454070"], ["84167.20", "0.427320"], ["84167.50", "2.069160"], ["84167.60", "2.673330"], ["84168.10", "0.067800"], ["84168.40", "0.071310"], ["84169.20", "0.107400"], ["84169.50", "0.120000"], ["84169.80", "0"], ["84170.10", "0.067800"], ["84170.70", "0.156000"], ["84170.80", "0"], ["84171.00", "0"], ["84172.10", "0"], ["84172.50", "0.207473"], ["84173.20", "0"], ["84173.30", "0"], ["84173.80", "0"], ["84173.90", "0"], ["84174.10", "0"], ["84174.20", "0"], ["84174.70", "0"], ["84174.90", "0"], ["84175.00", "0"], ["84175.20", "0"], ["84175.60", "0"], ["84176.50", "0"], ["84176.80", "0"], ["84177.00", "0"], ["84177.20", "0"], ["84177.70", "0"], ["84178.10", "0"], ["84198.80", "4.710129"], ["84207.30", "5.253605"], ["84208.30", "0"], ["84215.80", "5.525343"], ["84216.80", "0"], ["84224.30", "4.076073"], ["84225.30", "0"], ["84232.80", "4.528970"], ["84233.80", "0"], ["84241.30", "4.891287"], ["84242.30", "0"], ["84249.80", "5.072446"], ["84250.80", "0"], ["84258.30", "4.347811"], ["84259.30", "0"], ["84266.80", "5.163026"], ["84267.80", "0"], ["84275.30", "4.800708"], ["84276.30", "0"], ["84283.80", "4.981867"], ["84284.80", "0"], ["84292.30", "4.438390"], ["84293.30", "0"], ["84300.80", "4.257232"], ["84301.80", "0"], ["84309.30", "5.344184"], ["84310.30", "0"], ["84317.80", "5.434764"], ["84318.80", "0"], ["84326.30", "4.619549"], ["84327.30", "0"], ["84334.80", "4.166652"], ["84335.80", "0"], ["84343.30", "3.894914"], ["84344.30", "0"], ["84351.80", "5.615923"], ["84352.80", "0"], ["84360.30", "3.985494"], ["84361.30", "0"], ["84369.80", "0"], ["84534.53", "0"], ["84535.32", "0"], ["84536.36", "0"], ["84537.04", "0"], ["84538.75", "0"], ["84540.00", "0"], ["84540.54", "0"], ["84540.97", "0"], ["84541.67", "0"], ["84542.37", "0"], ["84543.27", "0"], ["84543.43", "0"], ["84543.86", "0"], ["84543.93", "0"], ["84544.64", "0"], ["84545.16", "0"], ["84545.45", "0"], ["84545.63", "0"], ["84547.06", "0"], ["84549.65", "0"], ["84549.96", "0"], ["84550.00", "0"], ["84550.60", "0"], ["84551.02", "0"], ["84552.59", "0"], ["84552.95", "0"], ["84553.04", "0"], ["84554.00", "0"], ["84555.00", "0"], ["84555.08", "0"]], "bids": [["84089.99", "0.030100"], ["84088.50", "0.001032"], ["84088.00", "0.000015"], ["84087.66", "0"], ["84087.64", "0"], ["84087.63", "0"], ["84086.50", "0.001033"], ["84086.00", "0.000015"], ["84085.58", "0.012472"], ["84084.67", "0.112975"], ["84084.50", "0.001024"], ["84084.00", "0"], ["84083.97", "0.017839"], ["84083.59", "0"], ["84083.54", "0"], ["84083.53", "0"], ["84082.50", "0.001037"], ["84082.00", "0.000017"], ["84081.90", "0"], ["84081.80", "0"], ["84081.60", "0"], ["84080.50", "0.001046"], ["84080.00", "0.000017"], ["84079.93", "0.000233"], ["84078.70", "0"], ["84078.50", "0.001003"], ["84078.16", "0.009583"], ["84078.12", "0.008236"], ["84078.11", "0.005919"], ["84078.10", "0.058243"], ["84078.09", "0.017793"], ["84078.08", "0.016248"], ["84077.40", "0"], ["84076.84", "0"], ["84076.70", "0"], ["84076.50", "0.002178"], ["84075.90", "0"], ["84074.90", "0"], ["84074.50", "0.005732"], ["84074.05", "0.008711"], ["84074.00", "0.017461"], ["84073.99", "0.005581"], ["84073.93", "0.015160"], ["84073.91", "0.005169"], ["84073.90", "0"], ["84073.89", "0.005117"], ["84072.60", "0"], ["84072.50", "0.015085"], ["84072.30", "0.016050"], ["84072.11", "0"], ["84071.90", "0.001042"], ["84071.30", "0.001008"], ["84070.70", "0.001005"], ["84069.90", "0.068190"], ["84069.50", "0"], ["84069.40", "0"], ["84069.00", "0.000032"], ["84068.70", "0"], ["84068.40", "0"], ["84067.90", "0.124620"], ["84067.55", "0.019223"], ["84066.60", "0.021900"], ["84065.80", "0.079770"], ["84065.12", "0"], ["84065.00", "0.877680"], ["84064.60", "0.009000"], ["84063.37", "0"], ["84063.30", "0"], ["84062.92", "0.008267"], ["84061.30", "2.673330"], ["84061.29", "0.008057"], ["84061.10", "0.240000"], ["84060.60", "1.037940"], ["84059.90", "0.035670"], ["84058.50", "0"], ["84058.30", "2.355450"], ["84058.10", "1.926720"], ["84058.00", "0.009000"], ["84056.61", "0"], ["84056.30", "0"], ["84056.20", "3.051770"], ["84054.93", "0.089456"], ["84054.64", "0.247509"], ["84053.50", "0.153580"], ["84053.25", "0.083913"], ["84053.11", "0"], ["84053.05", "0.017811"], ["84052.85", "0.018249"], ["84052.74", "0.008426"], ["84052.69", "0.009208"], ["84052.63", "0.006905"], ["84052.62", "0"], ["84052.60", "0.008012"], ["84052.59", "0.007304"], ["84052.57", "0.006470"], ["84052.54", "0.008595"], ["84052.49", "0.005944"], ["84052.47", "0.008319"], ["84051.38", "0.055638"], ["84051.13", "0.017098"], ["84050.94", "0.007129"], ["84050.53", "0.028855"], ["84050.31", "0.007337"], ["84050.07", "0.008991"], ["84049.92", "0.007940"], ["84049.62", "0.025176"], ["84049.59", "0.224811"], ["84049.55", "0.008182"], ["84049.40", "0.017345"], ["84049.22", "0.004016"], ["84048.07", "0.012651"], ["84048.06", "0.051947"], ["84046.96", "0.018511"], ["84046.11", "0.268292"], ["84045.61", "0.008092"], ["84045.52", "0.008263"], ["84045.48", "0.005051"], ["84044.91", "0.021123"], ["84044.75", "0.222599"], ["84044.59", "0.076088"], ["84043.32", "0.259713"], ["84040.75", "0.073192"], ["84039.90", "0"], ["84039.75", "0.017446"], ["84039.57", "0.056349"], ["84039.41", "0"], ["84038.41", "0"], ["84038.29", "0.000876"], ["84038.00", "0"], ["84036.76", "0"], ["84031.40", "0.209200"], ["84030.40", "5.434764"], ["84029.78", "0.007432"], ["84026.83", "0.008570"], ["84024.00", "0.208109"], ["84023.98", "0.007246"], ["84023.80", "0.007334"], ["84022.90", "0"], ["84021.90", "4.800708"], ["84018.77", "0.001175"], ["84018.11", "0.003596"], ["84017.34", "0.001172"], ["84014.40", "0"], ["84013.40", "4.619549"], ["84005.90", "0"], ["84004.90", "4.710129"], ["83997.40", "0"], ["83996.40", "4.257232"], ["83988.90", "0"], ["83987.90", "4.166652"], ["83980.40", "0"], ["83979.40", "5.163026"], ["83971.90", "0"], ["83970.90", "3.985494"], ["83963.40", "0"], ["83962.40", "4.528970"], ["83954.90", "0"], ["83953.90", "5.072446"], ["83946.40", "0"], ["83945.40", "5.615923"], ["83937.90", "0"], ["83936.90", "4.076073"], ["83929.40", "0"], ["83928.40", "4.891287"], ["83920.90", "0"], ["83919.90", "3.894914"], ["83912.40", "0"], ["83911.40", "4.347811"], ["83903.90", "0"], ["83902.90", "4.981867"], ["83895.40", "0"], ["83894.40", "5.344184"], ["83886.90", "0"], ["83885.90", "5.525343"], ["83878.40", "0"], ["83877.40", "5.253605"], ["83868.90", "4.438390"], ["83656.60", "0"], ["83655.00", "0"], ["83654.23", "0"], ["83653.94", "0"], ["83653.67", "0"], ["83653.31", "0"], ["83652.80", "0"], ["83652.48", "0"], ["83651.65", "0"], ["83651.16", "0"], ["83650.84", "0"], ["83650.00", "0"], ["83648.96", "0"], ["83647.46", "0"], ["83647.06", "0"], ["83646.67", "0"], ["83645.83", "0"], ["83644.86", "0"], ["83644.33", "0"], ["83643.18", "0"], ["83641.86", "0"], ["83641.62", "0"], ["83641.38", "0"], ["83641.00", "0"], ["83640.35", "0"], ["83640.15", "0"], ["83640.00", "0"], ["83639.71", "0"], ["83639.70", "0"], ["83639.15", "0"], ["83638.32", "0"], ["83638.30", "0"], ["83637.17", "0"], ["83636.36", "0"], ["83635.64", "0"], ["83634.09", "0"], ["83634.05", "0"], ["83633.88", "0"], ["83633.63", "0"], ["83633.61", "0"], ["83633.40", "0"], ["83633.33", "0"], ["83633.19", "0"], ["83632.65", "0"], ["83632.10", "0"], ["83632.02", "0"], ["83631.58", "0"], ["83631.57", "0"], ["83631.53", "0"], ["83631.09", "0"], ["83630.43", "0"], ["83629.43", "0"]], "checksum": 1821358996, "ts": "1742554944637"}], "ts": 1742554944645, "record_time": 1742554944.673125, "EXCHANGE": "BITGET"}
{"action": "update", "arg": {"instType": "SPOT", "channel": "books", "instId": "BTCUSDT"}, "data": [{"asks": [["84090.00", "2.066435"], ["84090.61", "0.010775"], ["84092.54", "0.080639"], ["84133.60", "0.001357"], ["84135.60", "0.002203"], ["84136.70", "0"], ["84137.60", "0.005798"], ["84138.63", "0"], ["84138.70", "0"], ["84139.60", "0.015258"], ["84140.70", "0"], ["84141.60", "0.040154"], ["84142.70", "0"], ["84143.60", "0.105668"], ["84144.70", "0"], ["84145.60", "0.278072"], ["84146.70", "0"], ["84147.60", "0.731770"], ["84148.70", "0"], ["84149.60", "1.925709"], ["84150.70", "0"], ["84151.60", "5.067657"], ["84152.70", "0"], ["84153.60", "13.335940"], ["84154.60", "0.001740"], ["84154.70", "0.001009"], ["84156.10", "0.067980"], ["84156.60", "0.001013"], ["84156.70", "12.349800"], ["84157.10", "0.141540"], ["84157.70", "0"], ["84157.90", "0"], ["84158.10", "0.532170"], ["84158.40", "0"], ["84158.50", "0.405570"], ["84160.10", "0.473370"], ["84160.20", "0"], ["84161.00", "0.100680"], ["84161.60", "0.534660"], ["84161.70", "0"], ["84162.70", "0.156000"], ["84163.90", "0.120000"], ["84164.20", "1.282500"], ["84164.30", "0.473070"], ["84164.80", "1.350000"], ["84166.12", "1.782189"], ["84166.20", "0.385140"], ["84166.90", "0.192000"], ["84167.50", "1.298580"], ["84168.10", "0.067980"], ["84169.50", "0.155640"], ["84170.10", "0"], ["84170.50", "0"], ["84170.70", "0"], ["84183.24", "0"], ["84195.60", "4.891470"], ["84198.80", "0"], ["84204.10", "5.163218"], ["84207.30", "0"], ["84212.60", "3.985642"], ["84215.80", "0"], ["84221.10", "4.166808"], ["84224.30", "0"], ["84229.60", "5.616132"], ["84232.80", "0"], ["84238.10", "4.982053"], ["84241.30", "0"], ["84246.60", "4.257391"], ["84249.80", "0"], ["84255.10", "4.710305"], ["84258.30", "0"], ["84263.60", "5.525549"], ["84266.80", "0"], ["84272.10", "4.529139"], ["84275.30", "0"], ["84280.60", "4.619722"], ["84283.80", "0"], ["84289.10", "5.072636"], ["84292.30", "0"], ["84297.60", "5.344384"], ["84300.80", "0"], ["84306.10", "4.076225"], ["84309.30", "0"], ["84314.60", "4.347973"], ["84317.80", "0"], ["84323.10", "5.253801"], ["84326.30", "0"], ["84331.60", "3.895060"], ["84334.80", "0"], ["84340.10", "4.800887"], ["84343.30", "0"], ["84348.60", "4.438556"], ["84351.80", "0"], ["84357.10", "5.434967"], ["84360.30", "0"], ["84533.33", "0"]], "bids": [["84089.30", "0.001044"], ["84088.50", "0"], ["84087.30", "0.001041"], ["84086.50", "0"], ["84085.30", "0.001259"], ["84084.67", "0"], ["84084.50", "0"], ["84083.97", "0"], ["84083.30", "0.003313"], ["84082.50", "0"], ["84081.71", "0"], ["84081.30", "0.008720"], ["84081.14", "0"], ["84080.68", "0.112975"], ["84080.50", "0"], ["84079.30", "0.022947"], ["84078.50", "0"], ["84078.10", "0.017179"], ["84077.30", "0.060386"], ["84076.50", "0"], ["84075.30", "0.158912"], ["84074.50", "0"], ["84073.30", "0.418188"], ["84072.61", "0"], ["84072.50", "0"], ["84072.30", "0"], ["84072.10", "0.021425"], ["84071.90", "0"], ["84071.30", "1.100494"], ["84070.85", "0.009861"], ["84070.70", "0"], ["84070.50", "0"], ["84069.90", "0"], ["84069.30", "2.896039"], ["84069.00", "0.082590"], ["84068.90", "0.001530"], ["84067.90", "0.068400"], ["84066.51", "0.313923"], ["84065.80", "0.072480"], ["84065.00", "0.675360"], ["84063.90", "0.067800"], ["84060.50", "0.486630"], ["84059.90", "0"], ["84059.60", "0.006240"], ["84059.50", "0.120000"], ["84058.70", "0.072090"], ["84058.60", "0.120000"], ["84058.30", "0"], ["84057.70", "0.120000"], ["84056.80", "0.534660"], ["84030.40", "0"], ["84027.30", "5.344384"], ["84021.90", "0"], ["84018.80", "5.616132"], ["84013.40", "0"], ["84010.30", "4.800887"], ["84004.90", "0"], ["84001.80", "3.895060"], ["83996.40", "0"], ["83993.30", "4.529139"], ["83987.90", "0"], ["83984.80", "5.434967"], ["83979.40", "0"], ["83976.30", "5.253801"], ["83970.90", "0"], ["83967.80", "3.985642"], ["83962.40", "0"], ["83959.30", "4.076225"], ["83953.90", "0"], ["83950.80", "4.166808"], ["83945.40", "0"], ["83942.30", "4.347973"], ["83936.90", "0"], ["83933.80", "5.525549"], ["83928.40", "0"], ["83925.30", "5.072636"], ["83919.90", "0"], ["83916.80", "4.438556"], ["83911.40", "0"], ["83908.30", "4.982053"], ["83902.90", "0"], ["83899.80", "4.891470"], ["83894.40", "0"], ["83891.30", "5.163218"], ["83885.90", "0"], ["83882.80", "4.619722"], ["83877.40", "0"], ["83874.30", "4.710305"], ["83868.90", "0"], ["83865.80", "4.257391"], ["83659.44", "0"], ["83658.54", "0"]], "checksum": 630716814, "ts": "1742554944841"}], "ts": 1742554944845, "record_time": 1742554944.897152, "EXCHANGE": "BITGET"}
{"action": "update", "arg": {"instType": "SPOT", "channel": "books", "instId": "BTCUSDT"}, "data": [{"asks": [["84100.86", "0.160779"], ["84126.76", "0.178756"], ["84137.60", "0.005599"], ["84139.60", "0.014733"], ["84141.60", "0.038771"], ["84143.60", "0.102028"], ["84145.60", "0.268495"], ["84147.60", "0.706566"], ["84149.60", "1.859386"], ["84151.60", "4.893120"], ["84153.60", "12.876631"], ["84154.70", "0"], ["84156.10", "0.068220"], ["84156.30", "0.144930"], ["84156.60", "0.001032"], ["84156.70", "9.723570"], ["84158.10", "0.532350"], ["84158.50", "0.405750"], ["84160.10", "0.473550"], ["84160.90", "0.120000"], ["84161.80", "0.120000"], ["84162.60", "0.300000"], ["84164.20", "1.644660"], ["84165.20", "0.228000"], ["84166.00", "0.216000"], ["84166.80", "0.198060"], ["84166.90", "0.372000"], ["84167.50", "1.045440"], ["84167.60", "0"], ["84168.10", "0"], ["84168.40", "0"], ["84169.20", "0"], ["84169.50", "0"], ["84169.60", "0"], ["84182.09", "0"], ["84195.60", "4.982053"], ["84204.10", "4.347973"], ["84212.60", "4.257391"], ["84221.10", "4.619722"], ["84229.60", "4.076225"], ["84238.10", "4.166808"], ["84246.60", "5.072636"], ["84255.10", "5.434967"], ["84272.10", "5.344384"], ["84280.60", "3.985642"], ["84289.10", "4.438556"], ["84297.60", "3.895060"], ["84306.10", "4.529139"], ["84314.60", "5.163218"], ["84323.10", "4.710305"], ["84331.60", "5.616132"], ["84340.10", "4.891470"], ["84348.60", "4.800887"], ["84357.10", "5.253801"]], "bids": [["84085.30", "0.002269"], ["84083.30", "0.005969"], ["84081.30", "0.015709"], ["84079.30", "0.041340"], ["84078.10", "0.112476"], ["84077.30", "0.108788"], ["84075.30", "0.286286"], ["84073.30", "0.753384"], ["84071.30", "1.982588"], ["84069.30", "5.217337"], ["84069.00", "0.082290"], ["84067.90", "0.068190"], ["84066.80", "0.283200"], ["84065.80", "0.144570"], ["84065.00", "0.675150"], ["84063.00", "0.070080"], ["84060.90", "0.144510"], ["84058.10", "1.782210"], ["84056.80", "0"], ["84032.00", "0"], ["84027.30", "4.710305"], ["84018.80", "4.076225"], ["84010.30", "5.434967"], ["84001.80", "4.347973"], ["83993.30", "4.257391"], ["83984.80", "5.616132"], ["83976.30", "4.800887"], ["83967.80", "4.166808"], ["83959.30", "3.985642"], ["83950.80", "5.525549"], ["83942.30", "4.982053"], ["83933.80", "4.891470"], ["83925.30", "4.438556"], ["83916.80", "5.072636"], ["83908.30", "4.529139"], ["83899.80", "5.253801"], ["83891.30", "5.344384"], ["83882.80", "3.895060"], ["83874.30", "4.619722"], ["83865.80", "5.163218"], ["83740.69", "0"], ["83659.44", "0.000613"]], "checksum": -1481516383, "ts": "1742554945045"}], "ts": 1742554945049, "record_time": 1742554945.085895, "EXCHANGE": "BITGET"}
{"action": "update", "arg": {"instType": "SPOT", "channel": "books", "instId": "BTCUSDT"}, "data": [{"asks": [["84108.43", "0.459309"], ["84133.60", "0.001201"], ["84135.60", "0.001959"], ["84137.60", "0.005156"], ["84139.60", "0.013568"], ["84141.60", "0.035705"], ["84143.60", "0.093960"], ["84145.60", "0.247139"], ["84147.60", "0.650367"], ["84149.60", "1.711493"], ["84151.60", "4.503927"], ["84153.60", "11.852441"], ["84154.90", "0.001023"], ["84155.70", "0.001035"], ["84156.60", "0"], ["84156.70", "8.711340"], ["84157.10", "0.071190"], ["84157.50", "0.070590"], ["84158.50", "0.405570"], ["84160.00", "0.004140"], ["84160.10", "0.473370"], ["84160.30", "0.035640"], ["84162.00", "0.009000"], ["84163.90", "0.146430"], ["84164.20", "1.657020"], ["84166.20", "0.214350"], ["84166.80", "0"], ["84166.90", "0"], ["84167.20", "0"], ["84167.50", "0"], ["84195.60", "5.163218"], ["84204.10", "5.434967"], ["84212.60", "4.982053"], ["84221.10", "4.257391"], ["84229.60", "4.166808"], ["84238.10", "4.529139"], ["84246.60", "5.616132"], ["84255.10", "4.076225"], ["84263.60", "4.710305"], ["84272.10", "4.800887"], ["84280.60", "4.891470"], ["84289.10", "3.895060"], ["84297.60", "4.438556"], ["84306.10", "5.253801"], ["84314.60", "3.985642"], ["84323.10", "4.619722"], ["84331.60", "5.344384"], ["84340.10", "5.525549"], ["84348.60", "5.072636"], ["84357.10", "4.347973"], ["84530.00", "0"], ["84533.01", "0"]], "bids": [["84089.99", "0.042572"], ["84085.58", "0"], ["84085.30", "0.002298"], ["84083.30", "0.006046"], ["84081.30", "0.015910"], ["84079.30", "0.041869"], ["84077.30", "0.110181"], ["84075.46", "0.041065"], ["84075.31", "0.335517"], ["84075.30", "0.289951"], ["84073.30", "0.763028"], ["84071.30", "2.007969"], ["84069.30", "5.284130"], ["84069.00", "0.152430"], ["84067.70", "0.011580"], ["84066.80", "0.283410"], ["84065.80", "0.143940"], ["84065.10", "0.066150"], ["84062.60", "0.035640"], ["84058.10", "0"], ["84058.00", "0.000032"], ["84057.70", "0"], ["84027.30", "3.985642"], ["84018.80", "4.529139"], ["84010.30", "5.072636"], ["84001.80", "5.616132"], ["83984.80", "4.800887"], ["83976.30", "3.895060"], ["83967.80", "5.344384"], ["83959.30", "5.163218"], ["83950.80", "4.982053"], ["83942.30", "5.434967"], ["83933.80", "4.076225"], ["83925.30", "5.525549"], ["83916.80", "5.253801"], ["83908.30", "4.710305"], ["83899.80", "4.438556"], ["83891.30", "4.347973"], ["83882.80", "4.619722"], ["83874.30", "4.891470"], ["83865.80", "4.166808"], ["83753.63", "0.001535"], ["83659.61", "0"], ["83659.49", "0"], ["83659.44", "0"]], "checksum": 725739592, "ts": "1742554945246"}], "ts": 1742554945251, "record_time": 1742554945.295353, "EXCHANGE": "BITGET"}
{"action": "update", "arg": {"instType": "SPOT", "channel": "books", "instId": "BTCUSDT"}, "data": [{"asks": [["84117.89", "0.094790"], ["84136.10", "0"], ["84143.60", "0.094211"], ["84145.60", "0.247926"], ["84147.60", "0.652436"], ["84149.60", "1.716937"], ["84151.60", "4.518254"], ["84153.60", "11.890143"], ["84154.60", "0"], ["84154.90", "0"], ["84155.20", "0.001034"], ["84155.70", "0"], ["84156.60", "0.001046"], ["84156.70", "8.711670"], ["84158.10", "0.349950"], ["84158.50", "0"], ["84160.10", "0.067800"], ["84164.20", "1.644660"], ["84166.20", "0.270570"], ["84166.80", "0.198060"], ["84166.90", "0.372000"], ["84195.60", "4.710305"], ["84204.10", "3.895060"], ["84212.60", "4.438556"], ["84221.10", "4.076225"], ["84229.60", "3.985642"], ["84238.10", "4.982053"], ["84246.60", "4.166808"], ["84255.10", "4.257391"], ["84263.60", "5.253801"], ["84272.10", "4.891470"], ["84280.60", "4.619722"], ["84289.10", "5.525549"], ["84297.60", "5.434967"], ["84306.10", "4.529139"], ["84314.60", "5.616132"], ["84323.10", "4.347973"], ["84340.10", "5.072636"], ["84348.60", "4.800887"], ["84357.10", "5.163218"], ["84447.89", "1.653917"], ["84468.50", "0"]], "bids": [["84079.30", "0.041738"], ["84077.30", "0.109835"], ["84075.30", "0.289040"], ["84073.30", "0.760633"], ["84071.31", "1.896792"], ["84071.30", "2.001664"], ["84069.30", "5.267539"], ["84067.70", "0"], ["84039.00", "0.000015"], ["84027.30", "4.982053"], ["84018.80", "5.525549"], ["84010.30", "4.438556"], ["84001.80", "4.076225"], ["83993.30", "4.166808"], ["83984.80", "4.710305"], ["83976.30", "5.616132"], ["83967.80", "4.619722"], ["83959.30", "5.434967"], ["83950.80", "4.800887"], ["83942.30", "4.529139"], ["83933.80", "5.253801"], ["83925.30", "3.895060"], ["83916.80", "5.163218"], ["83908.30", "4.891470"], ["83899.80", "5.344384"], ["83882.80", "3.985642"], ["83874.30", "4.257391"], ["83865.80", "5.072636"], ["83795.43", "0"], ["83774.99", "1.664082"], ["83660.00", "0"]], "checksum": 1571434286, "ts": "1742554945451"}], "ts": 1742554945454, "record_time": 1742554945.485176, "EXCHANGE": "BITGET"}
{"action": "update", "arg": {"instType": "SPOT", "channel": "books", "instId": "BTCUSDT"}, "data": [{"asks": [["84141.60", "0.035824"], ["84147.59", "0.711431"], ["84155.20", "0.001049"], ["84164.20", "1.657350"], ["84195.60", "4.347973"], ["84204.10", "4.076225"], ["84212.60", "5.253801"], ["84217.51", "0.071045"], ["84221.10", "3.895060"], ["84229.60", "4.891470"], ["84238.10", "4.438556"], ["84246.60", "5.344384"], ["84255.10", "5.525549"], ["84263.60", "4.529139"], ["84272.10", "5.072636"], ["84280.60", "5.434967"], ["84289.10", "5.163218"], ["84297.60", "5.616132"], ["84306.10", "4.619722"], ["84314.60", "3.985642"], ["84323.10", "4.982053"], ["84331.60", "4.166808"], ["84340.10", "4.257391"], ["84348.60", "4.710305"], ["84357.10", "4.800887"], ["84527.47", "0"], ["84528.57", "0"]], "bids": [["84075.98", "0.041065"], ["84075.46", "0"], ["84074.49", "0.028180"], ["84067.55", "0"], ["84050.32", "0"], ["84039.00", "0.000032"], ["84027.30", "4.529139"], ["84018.80", "4.347973"], ["84010.30", "4.710305"], ["84007.22", "0.071045"], ["84001.80", "4.891470"], ["83993.30", "3.985642"], ["83984.80", "5.163218"], ["83976.30", "4.982053"], ["83967.80", "4.076225"], ["83959.30", "4.166808"], ["83950.80", "5.434967"], ["83942.30", "5.072636"], ["83925.30", "5.344384"], ["83916.80", "4.438556"], ["83908.30", "4.800887"], ["83899.80", "4.619722"], ["83891.30", "5.616132"], ["83882.80", "3.895060"], ["83874.30", "5.525549"], ["83865.80", "4.257391"]], "checksum": 1571434286, "ts": "1742554945666"}], "ts": 1742554945670, "record_time": 1742554945.698393, "EXCHANGE": "BITGET"}
{"action": "update", "arg": {"instType": "SPOT", "channel": "books", "instId": "BTCUSDT"}, "data": [{"asks": [["84151.60", "4.518438"], ["84153.60", "11.890627"], ["84155.20", "0.015540"], ["84155.70", "0.001017"], ["84156.60", "0"], ["84157.50", "0"], ["84157.70", "0.015000"], ["84158.60", "0.072330"], ["84163.90", "0.120000"], ["84166.80", "0.006060"], ["84166.90", "0"], ["84172.49", "0.058578"], ["84195.60", "4.619722"], ["84204.10", "4.257391"], ["84212.60", "5.525549"], ["84221.10", "4.076225"], ["84229.60", "5.253801"], ["84238.10", "5.434967"], ["84246.60", "4.982053"], ["84255.10", "4.891470"], ["84263.60", "4.800887"], ["84272.10", "5.344384"], ["84280.60", "4.438556"], ["84289.10", "4.529139"], ["84297.60", "5.163218"], ["84306.10", "4.166808"], ["84323.10", "5.616132"], ["84331.60", "4.710305"], ["84340.10", "5.072636"], ["84348.60", "3.895060"], ["84357.10", "4.347973"], ["84525.82", "0"]], "bids": [["84080.68", "0"], ["84079.30", "0.041846"], ["84077.30", "0.110123"], ["84075.30", "0.289795"], ["84073.30", "0.762620"], ["84073.06", "0.019223"], ["84071.30", "2.006895"], ["84069.30", "5.281303"], ["84065.50", "0"], ["84056.05", "0.006124"], ["84043.50", "0.000396"], ["84036.10", "0"], ["84027.30", "4.982053"], ["84018.80", "4.166808"], ["84014.10", "0.000948"], ["84010.30", "4.619722"], ["84001.80", "5.434967"], ["83993.30", "5.525549"], ["83984.80", "4.347973"], ["83976.30", "5.616132"], ["83967.80", "5.253801"], ["83959.30", "5.072636"], ["83950.80", "4.800887"], ["83942.30", "3.985642"], ["83933.80", "5.344384"], ["83925.30", "4.438556"], ["83916.80", "5.163218"], ["83908.30", "4.710305"], ["83899.80", "4.257391"], ["83891.30", "4.529139"], ["83882.80", "4.891470"], ["83874.30", "3.895060"], ["83865.80", "4.076225"], ["83660.14", "0"]], "checksum": -840409446, "ts": "1742554945869"}], "ts": 1742554945873, "record_time": 1742554945.90728, "EXCHANGE": "BITGET"}
{"action": "update", "arg": {"instType": "SPOT", "channel": "books", "instId": "BTCUSDT"}, "data": [{"asks": [["84131.62", "0.010000"], ["84145.60", "0.248092"], ["84147.60", "0.652875"], ["84149.60", "1.718091"], ["84151.60", "4.521294"], ["84153.60", "11.898141"], ["84155.20", "0"], ["84155.70", "0"], ["84156.10", "0.068400"], ["84156.30", "0.145110"], ["84156.60", "0.001046"], ["84156.70", "8.712030"], ["84158.10", "0.350130"], ["84158.60", "0"], ["84160.10", "0.067980"], ["84160.90", "0.120180"], ["84161.00", "0.100860"], ["84161.60", "0.534840"], ["84164.20", "1.644660"], ["84166.80", "0.198060"], ["84166.90", "0.372000"], ["84167.20", "0.427320"], ["84195.60", "4.529139"], ["84204.10", "5.616132"], ["84212.60", "4.076225"], ["84221.10", "5.344384"], ["84229.60", "5.525549"], ["84238.10", "4.891470"], ["84246.60", "5.072636"], ["84255.10", "4.257391"], ["84263.60", "4.710305"], ["84272.10", "3.985642"], ["84280.60", "5.434967"], ["84289.10", "4.619722"], ["84297.60", "4.438556"], ["84306.10", "4.347973"], ["84314.60", "5.253801"], ["84323.10", "5.163218"], ["84331.60", "4.800887"], ["84340.10", "4.982053"], ["84357.10", "4.166808"], ["84525.00", "0"]], "bids": [["84085.30", "0.002148"], ["84083.30", "0.005652"], ["84081.30", "0.014873"], ["84080.83", "0.112975"], ["84079.30", "0.039140"], ["84077.30", "0.102999"], ["84075.30", "0.270911"], ["84073.30", "0.712924"], ["84071.30", "1.876116"], ["84069.30", "4.937147"], ["84066.80", "0.283590"], ["84065.80", "0.071850"], ["84063.00", "0.000032"], ["84062.90", "0.071880"], ["84058.10", "1.782210"], ["84027.30", "4.891470"], ["84018.80", "3.895060"], ["84010.30", "5.253801"], ["84001.80", "4.076225"], ["83993.30", "4.800887"], ["83984.80", "5.163218"], ["83976.30", "5.072636"], ["83967.80", "4.982053"], ["83959.30", "4.257391"], ["83950.80", "4.710305"], ["83942.30", "4.347973"], ["83933.80", "5.616132"], ["83925.30", "5.434967"], ["83916.80", "4.166808"], ["83908.30", "3.985642"], ["83899.80", "4.619722"], ["83891.30", "5.525549"], ["83882.80", "5.344384"], ["83874.30", "4.438556"], ["83865.80", "4.529139"], ["83661.60", "0"], ["83661.08", "0"], ["83660.71", "0"]], "checksum": -1071826943, "ts": "1742554946078"}], "ts": 1742554946081, "record_time": 1742554946.103376, "EXCHANGE": "BITGET"}
{"action": "update", "arg": {"instType": "SPOT", "channel": "books", "instId": "BTCUSDT"}, "data": [{"asks": [["84090.00", "2.066333"], ["84149.60", "1.717839"], ["84151.60", "4.520629"], ["84153.60", "11.896393"], ["84158.60", "0.069930"], ["84161.60", "0.534660"], ["84167.20", "0.249120"], ["84195.60", "5.072636"], ["84204.10", "5.163218"], ["84212.60", "4.982053"], ["84221.10", "3.985642"], ["84229.60", "4.166808"], ["84238.10", "5.616132"], ["84246.60", "4.800887"], ["84255.10", "3.895060"], ["84263.60", "5.434967"], ["84272.10", "4.347973"], ["84280.60", "5.344384"], ["84289.10", "4.076225"], ["84297.60", "5.525549"], ["84306.10", "4.438556"], ["84323.10", "4.710305"], ["84331.60", "4.257391"], ["84340.10", "4.529139"], ["84348.60", "4.891470"], ["84357.10", "4.619722"], ["84524.83", "0"]], "bids": [["84089.99", "0.032572"], ["84076.50", "0.041065"], ["84075.98", "0"], ["84060.20", "0.071280"], ["84058.10", "0"], ["84040.00", "0.001244"], ["84027.30", "5.072636"], ["84010.30", "4.800887"], ["84001.80", "4.347973"], ["83993.30", "5.616132"], ["83984.80", "4.619722"], ["83976.30", "5.525549"], ["83967.80", "4.438556"], ["83959.30", "4.166808"], ["83950.80", "4.257391"], ["83942.30", "4.076225"], ["83933.80", "4.891470"], ["83925.30", "5.344384"], ["83916.80", "4.710305"], ["83908.30", "5.434967"], ["83899.80", "3.985642"], ["83891.30", "5.253801"], ["83882.80", "5.163218"], ["83874.30", "4.529139"], ["83865.80", "4.982053"]], "checksum": 1380211870, "ts": "1742554946280"}], "ts": 1742554946292, "record_time": 1742554946.325006, "EXCHANGE": "BITGET"}
{"action": "update", "arg": {"instType": "SPOT", "channel": "books", "instId": "BTCUSDT"}, "data": [{"asks": [["84090.00", "2.066453"], ["84126.21", "0.108051"], ["84126.76", "0"], ["84153.60", "11.896616"], ["84195.60", "4.257391"], ["84204.10", "5.525549"], ["84212.60", "5.434967"], ["84221.10", "5.072636"], ["84229.60", "4.710305"], ["84238.10", "5.163218"], ["84246.60", "4.166808"], ["84255.10", "5.616132"], ["84263.60", "4.891470"], ["84272.10", "3.895060"], ["84280.60", "4.619722"], ["84289.10", "4.982053"], ["84297.60", "4.800887"], ["84306.10", "4.347973"], ["84314.60", "4.438556"], ["84323.10", "4.529139"], ["84331.60", "5.344384"], ["84340.10", "5.253801"], ["84348.60", "4.076225"], ["84357.10", "3.985642"], ["84524.83", "0.000009"]], "bids": [["84079.30", "0.039010"], ["84078.10", "0.017179"], ["84077.30", "0.102659"], ["84075.30", "0.270156"], ["84073.30", "0.710937"], ["84071.30", "1.870885"], ["84069.30", "4.923383"], ["84066.60", "0.013290"], ["84038.00", "0.000015"], ["84027.30", "4.891470"], ["84018.80", "3.985642"], ["84010.30", "4.257391"], ["84001.80", "5.072636"], ["83993.30", "3.895060"], ["83984.80", "4.076225"], ["83976.30", "5.434967"], ["83967.80", "4.529139"], ["83959.30", "4.982053"], ["83950.80", "5.344384"], ["83942.30", "4.438556"], ["83933.80", "4.619722"], ["83925.30", "5.616132"], ["83916.80", "4.800887"], ["83908.30", "5.525549"], ["83899.80", "4.166808"], ["83891.30", "5.163218"], ["83882.80", "4.710305"], ["83874.30", "5.253801"], ["83865.80", "4.347973"], ["83661.97", "0"]], "checksum": 2145797511, "ts": "1742554946495"}], "ts": 1742554946498, "record_time": 1742554946.525127, "EXCHANGE": "BITGET"}
{"action": "update", "arg": {"instType": "SPOT", "channel": "books", "instId": "BTCUSDT"}, "data": [{"asks": [["84125.98", "0.182311"], ["84126.21", "0.070525"], ["84195.60", "4.166808"], ["84204.10", "4.438556"], ["84212.60", "5.616132"], ["84221.10", "4.800887"], ["84229.60", "4.891470"], ["84238.10", "5.072636"], ["84246.60", "4.347973"], ["84255.10", "4.529139"], ["84263.60", "5.344384"], ["84272.10", "4.076225"], ["84280.60", "3.895060"], ["84289.10", "4.710305"], ["84297.60", "5.434967"], ["84306.10", "4.982053"], ["84314.60", "5.163218"], ["84323.10", "5.525549"], ["84331.60", "4.257391"], ["84348.60", "4.619722"], ["84524.83", "0"]], "bids": [["84081.30", "0.014725"], ["84079.30", "0.038750"], ["84077.30", "0.101973"], ["84076.96", "0.041064"], ["84076.50", "0"], ["84075.30", "0.268352"], ["84073.30", "0.706188"], ["84071.30", "1.858389"], ["84069.30", "4.890498"], ["84065.00", "0.127800"], ["84061.30", "0"], ["84058.10", "1.782210"], ["84058.00", "0.009000"], ["84038.00", "0.000032"], ["84027.30", "4.438556"], ["84018.80", "4.166808"], ["84010.30", "5.072636"], ["84001.80", "3.985642"], ["83993.30", "4.891470"], ["83984.80", "5.616132"], ["83976.30", "5.344384"], ["83967.80", "4.800887"], ["83959.30", "4.076225"], ["83950.80", "4.619722"], ["83942.30", "3.895060"], ["83933.80", "4.347973"], ["83925.30", "4.529139"], ["83916.80", "5.163218"], ["83908.30", "5.253801"], ["83899.80", "4.710305"], ["83891.30", "4.982053"], ["83882.80", "4.257391"], ["83874.30", "5.525549"], ["83865.80", "5.434967"]], "checksum": -1405252614, "ts": "1742554946701"}], "ts": 1742554946705, "record_time": 1742554946.728294, "EXCHANGE": "BITGET"}
{"action": "update", "arg": {"instType": "SPOT", "channel": "books", "instId": "BTCUSDT"}, "data": [{"asks": [["84195.60", "5.434967"], ["84204.10", "4.619722"], ["84212.60", "3.985642"], ["84221.10", "5.163218"], ["84229.60", "5.616132"], ["84238.10", "4.800887"], ["84246.60", "4.529139"], ["84255.10", "4.891470"], ["84263.60", "4.076225"], ["84272.10", "3.895060"], ["84280.60", "4.166808"], ["84289.10", "5.525549"], ["84297.60", "4.347973"], ["84306.10", "5.344384"], ["84314.60", "4.438556"], ["84323.10", "5.253801"], ["84331.60", "4.982053"], ["84340.10", "4.710305"], ["84348.60", "5.072636"], ["84357.10", "4.257391"]], "bids": [["84077.30", "0.102205"], ["84075.30", "0.268962"], ["84073.30", "0.707794"], ["84071.30", "1.862616"], ["84069.30", "4.901621"], ["84027.30", "4.619722"], ["84018.80", "4.347973"], ["84010.30", "5.616132"], ["84001.80", "4.891470"], ["83993.30", "3.985642"], ["83984.80", "3.895060"], ["83976.30", "4.438556"], ["83959.30", "5.434967"], ["83950.80", "4.076225"], ["83942.30", "5.253801"], ["83933.80", "4.529139"], ["83925.30", "4.166808"], ["83916.80", "5.344384"], ["83908.30", "5.163218"], ["83874.30", "5.072636"], ["83865.80", "5.525549"]], "checksum": -1405252614, "ts": "1742554946915"}], "ts": 1742554946948, "record_time": 1742554946.971781, "EXCHANGE": "BITGET"}
{"action": "update", "arg": {"instType": "SPOT", "channel": "books", "instId": "BTCUSDT"}, "data": [{"asks": [["84090.00", "2.066333"], ["84195.60", "3.985642"], ["84204.10", "3.895060"], ["84212.60", "4.982053"], ["84229.60", "4.800887"], ["84238.10", "4.891470"], ["84246.60", "4.076225"], ["84255.10", "5.344384"], ["84263.60", "5.253801"], ["84272.10", "4.347973"], ["84289.10", "5.072636"], ["84297.60", "4.257391"], ["84306.10", "5.616132"], ["84314.60", "4.710305"], ["84323.10", "5.525549"], ["84331.60", "4.438556"], ["84340.10", "5.434967"], ["84348.60", "4.619722"], ["84357.10", "4.529139"]], "bids": [["84078.10", "0.137341"], ["84039.00", "0.000017"], ["84027.30", "4.800887"], ["84018.80", "5.616132"], ["84010.30", "4.257391"], ["84001.80", "4.347973"], ["83984.80", "5.344384"], ["83976.30", "5.072636"], ["83967.80", "4.438556"], ["83959.30", "4.982053"], ["83950.80", "5.525549"], ["83942.30", "5.434967"], ["83933.80", "3.895060"], ["83925.30", "4.529139"], ["83916.80", "5.163218"], ["83908.30", "5.253801"], ["83891.30", "4.891470"], ["83882.80", "4.076225"], ["83874.30", "4.166808"], ["83865.80", "4.619722"]], "checksum": -1032049153, "ts": "1742554947126"}], "ts": 1742554947130, "record_time": 1742554947.152179, "EXCHANGE": "BITGET"}
{"action": "update", "arg": {"instType": "SPOT", "channel": "books", "instId": "BTCUSDT"}, "data": [{"asks": [["84158.00", "0.022620"], ["84161.00", "0.100680"], ["84195.60", "4.982053"], ["84204.10", "4.529139"], ["84212.60", "5.163218"], ["84221.10", "4.891470"], ["84229.60", "3.895060"], ["84238.10", "4.166808"], ["84246.60", "4.347973"], ["84255.10", "5.253801"], ["84263.60", "4.257391"], ["84272.10", "4.800887"], ["84280.60", "5.525549"], ["84289.10", "5.434967"], ["84297.60", "4.619722"], ["84306.10", "4.076225"], ["84323.10", "5.616132"], ["84331.60", "5.344384"], ["84340.10", "4.438556"], ["84348.60", "3.985642"], ["84357.10", "5.072636"], ["84524.00", "0"]], "bids": [["84077.40", "0.041064"], ["84077.30", "0.101973"], ["84076.96", "0"], ["84075.30", "0.268352"], ["84073.30", "0.706188"], ["84071.30", "1.858389"], ["84069.30", "4.890498"], ["84061.20", "0.022710"], ["84027.30", "4.982053"], ["84018.80", "4.710305"], ["84010.30", "4.438556"], ["84001.80", "5.344384"], ["83993.30", "5.525549"], ["83984.80", "3.985642"], ["83976.30", "5.163218"], ["83967.80", "4.257391"], ["83959.30", "4.347973"], ["83950.80", "5.616132"], ["83942.30", "4.076225"], ["83933.80", "5.253801"], ["83925.30", "4.800887"], ["83916.80", "4.166808"], ["83908.30", "4.891470"], ["83899.80", "4.619722"], ["83891.30", "4.529139"], ["83882.80", "3.895060"], ["83874.30", "5.434967"], ["83865.80", "5.072636"], ["83662.50", "0"]], "checksum": -1032049153, "ts": "1742554947344"}], "ts": 1742554947346, "record_time": 1742554947.3691, "EXCHANGE": "BITGET"}
{"action": "update", "arg": {"instType": "SPOT", "channel": "books", "instId": "BTCUSDT"}, "data": [{"asks": [["84125.97", "0.054693"], ["84156.70", "6.929820"], ["84158.60", "0"], ["84195.60", "5.163218"], ["84204.10", "3.895060"], ["84212.60", "5.434967"], ["84221.10", "4.076225"], ["84229.60", "5.072636"], ["84238.10", "5.253801"], ["84246.60", "5.344384"], ["84255.10", "4.800887"], ["84263.60", "4.438556"], ["84272.10", "5.616132"], ["84280.60", "4.347973"], ["84289.10", "4.982053"], ["84297.60", "4.529139"], ["84306.10", "4.166808"], ["84314.60", "5.525549"], ["84323.10", "4.710305"], ["84331.60", "4.891470"], ["84340.10", "3.985642"], ["84348.60", "4.257391"], ["84357.10", "4.619722"]], "bids": [["84083.30", "0.005844"], ["84081.30", "0.015378"], ["84079.30", "0.040468"], ["84077.30", "0.106495"], ["84075.30", "0.280250"], ["84073.30", "0.737499"], ["84073.06", "0"], ["84071.30", "1.940788"], ["84069.30", "5.107337"], ["84062.90", "0"], ["84060.20", "0"], ["84039.00", "0"], ["84027.30", "4.800887"], ["84018.80", "5.434967"], ["84010.30", "5.616132"], ["84001.80", "5.163218"], ["83993.30", "4.619722"], ["83984.80", "4.529139"], ["83976.30", "5.253801"], ["83967.80", "5.525549"], ["83959.30", "4.710305"], ["83950.80", "4.076225"], ["83942.30", "5.344384"], ["83933.80", "4.891470"], ["83925.30", "3.895060"], ["83916.80", "4.982053"], ["83908.30", "4.438556"], ["83899.80", "4.257391"], ["83891.30", "4.347973"], ["83882.80", "4.166808"], ["83874.30", "3.985642"], ["83662.50", "0.000077"], ["83661.97", "0.000052"], ["83661.60", "0.000042"], ["83661.08", "0.004152"]], "checksum": 1504312067, "ts": "1742554947548"}], "ts": 1742554947551, "record_time": 1742554947.582594, "EXCHANGE": "BITGET"}
{"action": "update", "arg": {"instType": "SPOT", "channel": "books", "instId": "BTCUSDT"}, "data": [{"asks": [["84090.00", "2.066200"], ["84145.60", "0.247900"], ["84147.60", "0.652368"], ["84149.60", "1.716760"], ["84151.59", "0.004997"], ["84151.60", "4.517788"], ["84153.60", "11.888915"], ["84156.70", "6.378480"], ["84164.30", "0.485490"], ["84164.40", "0"], ["84204.10", "5.344384"], ["84212.60", "4.619722"], ["84221.10", "5.253801"], ["84229.60", "4.438556"], ["84238.10", "4.076225"], ["84246.60", "4.710305"], ["84255.10", "5.434967"], ["84263.60", "3.985642"], ["84272.10", "4.891470"], ["84280.60", "4.800887"], ["84289.10", "4.257391"], ["84306.10", "5.616132"], ["84314.60", "3.895060"], ["84323.10", "4.347973"], ["84331.60", "5.072636"], ["84340.10", "5.525549"], ["84348.60", "4.166808"], ["84357.10", "4.982053"]], "bids": [["84077.88", "0.041064"], ["84077.40", "0"], ["84077.30", "0.106665"], ["84077.19", "0.019223"], ["84075.30", "0.280699"], ["84073.30", "0.738681"], ["84071.30", "1.943898"], ["84069.30", "5.115521"], ["84037.00", "0.000015"], ["84027.30", "5.253801"], ["84018.80", "5.616132"], ["84010.30", "4.619722"], ["84001.80", "4.438556"], ["83993.30", "4.166808"], ["83984.80", "5.072636"], ["83976.30", "5.525549"], ["83967.80", "4.347973"], ["83959.30", "3.895060"], ["83950.80", "4.800887"], ["83942.30", "4.529139"], ["83933.80", "4.076225"], ["83925.30", "4.257391"], ["83908.30", "4.710305"], ["83899.80", "4.891470"], ["83891.30", "5.344384"], ["83882.80", "3.985642"], ["83874.30", "5.434967"], ["83865.80", "5.163218"], ["83661.60", "0"], ["83661.08", "0"]], "checksum": -1594240885, "ts": "1742554947765"}], "ts": 1742554947769, "record_time": 1742554947.838757, "EXCHANGE": "BITGET"}
{"action": "update", "arg": {"instType": "SPOT", "channel": "books", "instId": "BTCUSDT"}, "data": [{"asks": [["84149.60", "1.716657"], ["84151.60", "4.517519"], ["84153.60", "11.888209"], ["84195.60", "4.800887"], ["84204.10", "4.438556"], ["84212.60", "4.710305"], ["84221.10", "4.076225"], ["84229.60", "5.525549"], ["84238.10", "5.072636"], ["84246.60", "5.253801"], ["84255.10", "4.257391"], ["84263.60", "4.982053"], ["84272.10", "5.616132"], ["84280.60", "4.529139"], ["84289.10", "4.619722"], ["84297.60", "4.166808"], ["84306.10", "5.163218"], ["84314.60", "4.891470"], ["84323.10", "3.985642"], ["84331.60", "5.344384"], ["84340.10", "3.895060"], ["84348.60", "5.434967"], ["84357.10", "4.347973"]], "bids": [["84079.30", "0.040610"], ["84077.30", "0.106868"], ["84075.30", "0.281232"], ["84073.30", "0.740325"], ["84071.30", "1.948224"], ["84069.30", "5.126904"], ["84062.90", "0.074310"], ["84057.70", "0.120000"], ["84027.30", "4.619722"], ["84018.80", "5.163218"], ["84010.30", "4.982053"], ["84001.80", "5.072636"], ["83993.30", "4.800887"], ["83984.80", "4.347973"], ["83976.30", "4.710305"], ["83967.80", "3.985642"], ["83959.30", "5.253801"], ["83950.80", "5.434967"], ["83942.30", "5.344384"], ["83916.80", "4.891470"], ["83908.30", "5.616132"], ["83899.80", "3.895060"], ["83891.30", "5.525549"], ["83882.80", "4.438556"], ["83874.30", "4.166808"], ["83865.80", "4.529139"], ["83662.50", "0"], ["83661.97", "0"]], "checksum": 355633913, "ts": "1742554947970"}], "ts": 1742554947973, "record_time": 1742554948.015374, "EXCHANGE": "BITGET"}
{"action": "update", "arg": {"instType": "SPOT", "channel": "books", "instId": "BTCUSDT"}, "data": [{"asks": [["84090.00", "2.066302"], ["84160.90", "0.120000"], ["84195.60", "4.438556"], ["84204.10", "5.344384"], ["84212.60", "3.985642"], ["84221.10", "5.434967"], ["84238.10", "5.616132"], ["84246.60", "4.347973"], ["84255.10", "4.891470"], ["84263.60", "4.166808"], ["84272.10", "4.800887"], ["84280.60", "4.619722"], ["84289.10", "3.895060"], ["84297.60", "5.163218"], ["84306.10", "4.076225"], ["84314.60", "5.072636"], ["84323.10", "5.253801"], ["84331.60", "4.982053"], ["84340.10", "4.710305"], ["84348.60", "4.529139"], ["84357.10", "4.257391"]], "bids": [["84063.80", "0.144510"], ["84060.90", "0"], ["84060.20", "0.070290"], ["84057.70", "0"], ["84040.00", "0.001261"], ["84027.30", "5.344384"], ["84018.80", "4.619722"], ["84010.30", "3.895060"], ["84001.80", "5.163218"], ["83993.30", "5.253801"], ["83984.80", "4.710305"], ["83976.30", "3.985642"], ["83967.80", "4.438556"], ["83959.30", "4.891470"], ["83950.80", "4.800887"], ["83942.30", "4.982053"], ["83933.80", "5.072636"], ["83925.30", "4.076225"], ["83916.80", "5.525549"], ["83908.30", "4.257391"], ["83899.80", "5.616132"], ["83891.30", "4.166808"], ["83882.80", "4.529139"], ["83874.30", "4.347973"], ["83865.80", "5.434967"]], "checksum": 902315771, "ts": "1742554948179"}], "ts": 1742554948183, "record_time": 1742554948.218335, "EXCHANGE": "BITGET"}
{"action": "update", "arg": {"instType": "SPOT", "channel": "books", "instId": "BTCUSDT"}, "data": [{"asks": [["84090.00", "2.066435"], ["84195.60", "5.072636"], ["84204.10", "4.982053"], ["84212.60", "5.525549"], ["84229.60", "4.710305"], ["84238.10", "4.800887"], ["84246.60", "4.529139"], ["84255.10", "4.619722"], ["84263.60", "4.347973"], ["84272.10", "5.616132"], ["84280.60", "4.166808"], ["84289.10", "4.891470"], ["84297.60", "4.076225"], ["84306.10", "3.895060"], ["84314.60", "3.985642"], ["84331.60", "4.438556"], ["84340.10", "5.344384"], ["84348.60", "4.257391"], ["84357.10", "5.163218"]], "bids": [["84085.45", "0.010000"], ["84085.30", "0.002348"], ["84083.30", "0.006180"], ["84081.30", "0.016263"], ["84079.30", "0.042797"], ["84078.33", "0.041064"], ["84077.88", "0"], ["84077.30", "0.112623"], ["84075.30", "0.296377"], ["84073.30", "0.779938"], ["84071.30", "2.052470"], ["84069.30", "5.401235"], ["84027.30", "4.166808"], ["84010.30", "5.616132"], ["84001.80", "5.525549"], ["83993.30", "4.529139"], ["83984.80", "5.253801"], ["83976.30", "4.438556"], ["83967.80", "4.710305"], ["83959.30", "5.434967"], ["83950.80", "4.257391"], ["83942.30", "3.985642"], ["83933.80", "5.163218"], ["83925.30", "4.347973"], ["83916.80", "4.891470"], ["83908.30", "5.344384"], ["83899.80", "4.982053"], ["83891.30", "5.072636"], ["83882.80", "3.895060"], ["83874.30", "4.800887"], ["83865.80", "4.076225"], ["83663.91", "0"]], "checksum": 2020914757, "ts": "1742554948391"}], "ts": 1742554948395, "record_time": 1742554948.4411, "EXCHANGE": "BITGET"}
{"action": "update", "arg": {"instType": "SPOT", "channel": "books", "instId": "BTCUSDT"}, "data": [{"asks": [["84099.14", "0"], ["84109.69", "0.008064"], ["84156.10", "0.068220"], ["84156.30", "0.001014"], ["84156.70", "5.235270"], ["84159.80", "0.144510"], ["84165.30", "1.069320"], ["84167.20", "0"], ["84195.60", "4.076225"], ["84204.10", "5.344384"], ["84212.60", "5.434967"], ["84221.10", "5.072636"], ["84229.60", "4.438556"], ["84238.10", "4.257391"], ["84246.60", "4.619722"], ["84255.10", "3.895060"], ["84263.60", "5.616132"], ["84272.10", "4.891470"], ["84289.10", "4.982053"], ["84297.60", "3.985642"], ["84305.95", "0"], ["84306.10", "5.163218"], ["84314.60", "4.710305"], ["84323.10", "4.347973"], ["84331.60", "4.800887"], ["84340.10", "4.529139"], ["84348.60", "5.253801"], ["84357.10", "5.525549"]], "bids": [["84087.30", "0.001179"], ["84085.30", "0.003101"], ["84083.30", "0.008160"], ["84081.30", "0.021474"], ["84079.30", "0.056512"], ["84077.30", "0.148716"], ["84075.30", "0.391358"], ["84073.30", "1.029888"], ["84071.30", "2.710231"], ["84069.30", "7.132189"], ["84065.10", "0"], ["84057.80", "0.178200"], ["84051.38", "0"], ["84038.00", "0.000017"], ["84027.30", "5.344384"], ["84018.80", "4.347973"], ["84001.80", "4.982053"], ["83984.80", "4.076225"], ["83976.30", "5.525549"], ["83967.80", "3.985642"], ["83950.80", "4.438556"], ["83942.30", "4.891470"], ["83933.80", "4.710305"], ["83925.30", "3.895060"], ["83916.80", "4.166808"], ["83908.30", "5.072636"], ["83899.80", "4.619722"], ["83891.30", "5.253801"], ["83882.80", "4.800887"], ["83874.30", "5.163218"], ["83865.80", "4.257391"], ["83663.91", "0.000161"]], "checksum": 390697300, "ts": "1742554948592"}], "ts": 1742554948595, "record_time": 1742554948.636649, "EXCHANGE": "BITGET"}
{"action": "update", "arg": {"instType": "SPOT", "channel": "books", "instId": "BTCUSDT"}, "data": [{"asks": [["84095.84", "0"], ["84100.78", "0.119870"], ["84104.08", "0.010984"], ["84125.98", "0"], ["84136.41", "0.708364"], ["84137.08", "0.000039"], ["84151.59", "0"], ["84156.09", "0"], ["84156.70", "5.235690"], ["84172.49", "0"], ["84195.60", "5.072636"], ["84204.10", "5.525549"], ["84212.60", "4.710305"], ["84221.10", "3.895060"], ["84229.60", "4.529139"], ["84238.10", "5.253801"], ["84246.60", "5.616132"], ["84255.10", "4.076225"], ["84263.60", "5.344384"], ["84272.10", "4.166808"], ["84280.60", "5.163218"], ["84289.10", "4.891470"], ["84297.60", "4.982053"], ["84306.10", "5.434967"], ["84314.60", "4.257391"], ["84331.60", "4.438556"], ["84340.10", "3.985642"], ["84348.60", "4.800887"], ["84357.10", "4.619722"], ["84524.00", "0.000035"], ["84524.83", "0.000009"]], "bids": [["84087.30", "0.001040"], ["84085.30", "0.002737"], ["84083.30", "0.007203"], ["84081.30", "0.018955"], ["84079.30", "0.049880"], ["84078.33", "0"], ["84077.30", "0.131093"], ["84075.30", "0.344980"], ["84073.30", "0.907843"], ["84071.30", "2.389062"], ["84069.30", "6.287005"], ["84069.20", "0.006240"], ["84068.90", "0.001009"], ["84059.60", "0"], ["84059.58", "0.247509"], ["84057.80", "0"], ["84056.32", "0.055638"], ["84054.64", "0"], ["84038.00", "0"], ["84027.30", "3.895060"], ["84018.80", "5.072636"], ["84010.30", "5.525549"], ["84001.80", "5.253801"], ["83993.30", "5.163218"], ["83984.80", "4.619722"], ["83976.30", "5.434967"], ["83967.80", "4.347973"], ["83959.30", "5.616132"], ["83950.80", "4.982053"], ["83942.30", "4.257391"], ["83933.80", "4.891470"], ["83925.30", "4.438556"], ["83916.80", "4.076225"], ["83908.30", "4.710305"], ["83899.80", "3.985642"], ["83891.30", "4.166808"], ["83882.80", "5.344384"], ["83874.30", "4.800887"], ["83865.80", "4.529139"], ["83662.50", "0.000077"], ["83661.97", "0.000052"]], "checksum": -387049672, "ts": "1742554948803"}], "ts": 1742554948806, "record_time": 1742554948.843099, "EXCHANGE": "BITGET"}
{"action": "update", "arg": {"instType": "SPOT", "channel": "books", "instId": "BTCUSDT"}, "data": [{"asks": [["84092.54", "0.044678"], ["84114.33", "0"], ["84125.97", "0"], ["84126.44", "0.012472"], ["84147.59", "0"], ["84195.60", "3.985642"], ["84204.10", "4.710305"], ["84212.60", "5.344384"], ["84221.10", "4.800887"], ["84229.60", "4.347973"], ["84238.10", "4.076225"], ["84246.60", "3.895060"], ["84255.10", "4.619722"], ["84263.60", "4.257391"], ["84272.10", "4.438556"], ["84280.60", "5.434967"], ["84287.20", "0.169097"], ["84289.10", "5.072636"], ["84297.60", "5.525549"], ["84306.10", "5.616132"], ["84314.60", "5.163218"], ["84323.10", "4.529139"], ["84331.60", "4.982053"], ["84340.10", "5.253801"], ["84348.60", "4.166808"], ["84357.10", "4.891470"], ["84525.00", "0.003286"]], "bids": [["84078.75", "0.041064"], ["84073.30", "0.908029"], ["84071.30", "2.389670"], ["84069.30", "6.288604"], ["84069.20", "0.082290"], ["84069.00", "0.003960"], ["84068.90", "0"], ["84067.90", "0.068010"], ["84066.80", "0"], ["84065.00", "0.128010"], ["84058.28", "0.004016"], ["84058.10", "0"], ["84058.00", "0.000032"], ["84049.22", "0"], ["84027.30", "4.076225"], ["84018.80", "4.982053"], ["84010.30", "3.895060"], ["84001.80", "4.710305"], ["83993.30", "5.344384"], ["83984.80", "5.525549"], ["83976.30", "4.347973"], ["83967.80", "4.800887"], ["83959.30", "5.253801"], ["83950.80", "4.619722"], ["83933.80", "5.616132"], ["83925.30", "4.891470"], ["83916.80", "3.985642"], ["83908.30", "4.529139"], ["83899.80", "4.438556"], ["83882.80", "5.163218"], ["83874.30", "5.072636"], ["83865.80", "5.434967"], ["83661.60", "0.000042"], ["83661.08", "0.004152"]], "checksum": -55360266, "ts": "1742554949007"}], "ts": 1742554949010, "record_time": 1742554949.046029, "EXCHANGE": "BITGET"}
{"action": "update", "arg": {"instType": "SPOT", "channel": "books", "instId": "BTCUSDT"}, "data": [{"asks": [["84098.07", "0.105306"], ["84126.50", "0.184262"], ["84195.60", "5.344384"], ["84204.10", "4.257391"], ["84212.60", "5.525549"], ["84221.10", "4.076225"], ["84229.60", "3.985642"], ["84238.10", "5.163218"], ["84246.60", "4.982053"], ["84263.60", "4.710305"], ["84272.10", "5.253801"], ["84280.60", "4.891470"], ["84289.10", "4.529139"], ["84297.60", "4.166808"], ["84306.10", "4.438556"], ["84314.60", "5.616132"], ["84323.10", "5.434967"], ["84331.60", "3.895060"], ["84340.10", "4.347973"], ["84348.60", "4.800887"], ["84357.10", "5.072636"], ["84525.00", "0"]], "bids": [["84069.20", "0.054090"], ["84053.70", "0.153580"], ["84053.50", "0"], ["84027.30", "4.982053"], ["84024.20", "0.200459"], ["84024.00", "0.007650"], ["84018.80", "5.616132"], ["84010.30", "4.710305"], ["84001.80", "3.895060"], ["83993.30", "5.163218"], ["83976.30", "5.253801"], ["83967.80", "4.438556"], ["83959.30", "4.347973"], ["83950.80", "4.257391"], ["83942.30", "3.985642"], ["83933.80", "4.619722"], ["83925.30", "4.529139"], ["83916.80", "4.800887"], ["83908.30", "5.072636"], ["83899.80", "5.344384"], ["83891.30", "5.434967"], ["83882.80", "4.076225"], ["83874.30", "4.891470"], ["83865.80", "4.166808"], ["83661.08", "0"]], "checksum": 1379196676, "ts": "1742554949211"}], "ts": 1742554949214, "record_time": 1742554949.245871, "EXCHANGE": "BITGET"}
{"action": "update", "arg": {"instType": "SPOT", "channel": "books", "instId": "BTCUSDT"}, "data": [{"asks": [["84090.01", "0.000220"], ["84133.60", "0.001009"], ["84135.60", "0.001646"], ["84137.60", "0.004333"], ["84139.60", "0.011402"], ["84141.60", "0.030004"], ["84143.60", "0.078958"], ["84145.60", "0.207784"], ["84147.60", "0.546801"], ["84149.60", "1.438949"], ["84151.60", "3.786710"], ["84153.60", "9.965024"], ["84156.70", "4.781580"], ["84158.10", "0.349950"], ["84158.50", "0.072630"], ["84160.10", "0.067800"], ["84166.20", "0.163170"], ["84166.80", "0.006060"], ["84166.90", "0"], ["84178.40", "0.063360"], ["84195.60", "4.982053"], ["84204.10", "5.616132"], ["84221.10", "4.529139"], ["84229.60", "5.344384"], ["84238.10", "4.076225"], ["84246.60", "3.895060"], ["84255.10", "4.347973"], ["84272.10", "4.619722"], ["84289.10", "4.800887"], ["84297.60", "4.257391"], ["84306.10", "5.072636"], ["84314.60", "3.985642"], ["84323.10", "4.166808"], ["84331.60", "5.253801"], ["84340.10", "4.438556"], ["84348.60", "5.163218"], ["84357.10", "5.434967"], ["84524.83", "0"]], "bids": [["84087.30", "0.001242"], ["84085.30", "0.003270"], ["84083.30", "0.008604"], ["84081.30", "0.022643"], ["84079.30", "0.059588"], ["84079.20", "0.041063"], ["84078.75", "0"], ["84077.30", "0.156809"], ["84075.30", "0.412656"], ["84073.30", "1.085936"], ["84071.30", "2.857727"], ["84069.30", "7.520333"], ["84066.60", "0.158880"], ["84065.00", "0.127800"], ["84064.50", "0.178200"], ["84063.80", "0"], ["84039.00", "0.000032"], ["84027.30", "5.163218"], ["84018.80", "5.253801"], ["84010.30", "4.891470"], ["84001.80", "4.347973"], ["83993.30", "3.985642"], ["83984.80", "5.072636"], ["83976.30", "5.616132"], ["83959.30", "4.529139"], ["83950.80", "4.619722"], ["83942.30", "5.344384"], ["83933.80", "4.710305"], ["83925.30", "4.076225"], ["83916.80", "5.434967"], ["83908.30", "4.166808"], ["83899.80", "4.257391"], ["83891.30", "4.982053"], ["83882.80", "3.895060"], ["83874.30", "4.800887"], ["83865.80", "5.525549"], ["83661.60", "0"]], "checksum": -1081261230, "ts": "1742554949416"}], "ts": 1742554949428, "record_time": 1742554949.456617, "EXCHANGE": "BITGET"}
{"action": "update", "arg": {"instType": "SPOT", "channel": "books", "instId": "BTCUSDT"}, "data": [{"asks": [["84126.21", "0.113444"], ["84145.60", "0.207603"], ["84147.60", "0.546323"], ["84149.60", "1.437693"], ["84151.60", "3.783401"], ["84153.60", "9.956320"], ["84156.70", "4.302750"], ["84158.10", "0.551820"], ["84161.80", "0.573360"], ["84166.20", "0.106950"], ["84166.80", "0"], ["84195.60", "4.800887"], ["84204.10", "4.710305"], ["84212.60", "4.529139"], ["84221.10", "3.985642"], ["84229.60", "5.525549"], ["84238.10", "4.619722"], ["84246.60", "4.257391"], ["84255.10", "5.163218"], ["84263.60", "5.434967"], ["84272.10", "5.072636"], ["84280.60", "3.895060"], ["84289.10", "5.253801"], ["84297.60", "4.438556"], ["84306.10", "4.891470"], ["84314.60", "5.616132"], ["84331.60", "4.347973"], ["84340.10", "5.344384"], ["84348.60", "4.982053"], ["84357.10", "4.076225"], ["84524.83", "0.000009"]], "bids": [["84077.19", "0"], ["84073.30", "1.085910"], ["84071.30", "2.857656"], ["84069.30", "7.520147"], ["84069.20", "0.091470"], ["84065.00", "0.614430"], ["84060.60", "0.744720"], ["84060.50", "0"], ["84058.10", "1.782210"], ["84027.30", "5.344384"], ["84018.80", "4.347973"], ["84010.30", "5.616132"], ["84001.80", "4.982053"], ["83993.30", "5.072636"], ["83984.80", "5.163218"], ["83976.30", "4.619722"], ["83967.80", "3.985642"], ["83959.30", "5.434967"], ["83950.80", "5.525549"], ["83942.30", "4.257391"], ["83933.80", "5.253801"], ["83925.30", "4.800887"], ["83916.80", "4.076225"], ["83908.30", "4.891470"], ["83899.80", "3.895060"], ["83891.30", "4.529139"], ["83882.80", "4.438556"], ["83874.30", "4.710305"], ["83865.80", "4.166808"], ["83661.60", "0.000042"]], "checksum": -1081261230, "ts": "1742554949621"}], "ts": 1742554949625, "record_time": 1742554949.647276, "EXCHANGE": "BITGET"}
{"action": "update", "arg": {"instType": "SPOT", "channel": "books", "instId": "BTCUSDT"}, "data": [{"asks": [["84117.90", "0"], ["84135.60", "0.001487"], ["84137.60", "0.003913"], ["84139.60", "0.010299"], ["84141.60", "0.027101"], ["84143.60", "0.071320"], ["84145.60", "0.187684"], ["84147.60", "0.493905"], ["84149.60", "1.299751"], ["84151.59", "0.058502"], ["84151.60", "3.420396"], ["84153.60", "9.001042"], ["84158.50", "0"], ["84160.40", "0.073440"], ["84195.60", "5.344384"], ["84204.10", "5.253801"], ["84212.60", "4.166808"], ["84229.60", "4.076225"], ["84238.10", "4.800887"], ["84246.60", "4.347973"], ["84255.10", "4.710305"], ["84272.10", "4.257391"], ["84280.60", "5.163218"], ["84289.10", "4.529139"], ["84306.10", "5.072636"], ["84314.60", "5.525549"], ["84323.10", "4.619722"], ["84331.60", "4.982053"], ["84340.10", "3.895060"], ["84348.60", "5.616132"], ["84357.10", "4.891470"]], "bids": [["84089.99", "0.062752"], ["84083.30", "0.008745"], ["84081.30", "0.023014"], ["84080.18", "0.019223"], ["84079.30", "0.060562"], ["84077.30", "0.159373"], ["84075.30", "0.419404"], ["84073.30", "1.103695"], ["84071.30", "2.904460"], ["84069.30", "7.643317"], ["84069.20", "0.353130"], ["84065.80", "0.071640"], ["84065.00", "0.821430"], ["84058.00", "0.009000"], ["84057.80", "0.178200"], ["84027.30", "5.616132"], ["84018.80", "5.525549"], ["84010.30", "3.985642"], ["84001.80", "5.253801"], ["83993.30", "5.344384"], ["83984.80", "3.895060"], ["83976.30", "5.163218"], ["83967.80", "4.982053"], ["83959.30", "4.166808"], ["83950.80", "5.434967"], ["83942.30", "4.438556"], ["83933.80", "4.800887"], ["83925.30", "4.076225"], ["83916.80", "4.529139"], ["83908.30", "4.710305"], ["83899.80", "4.347973"], ["83891.30", "4.619722"], ["83882.80", "4.257391"], ["83874.30", "5.072636"], ["83865.80", "4.891470"], ["83661.97", "0"], ["83661.60", "0"]], "checksum": 1040517297, "ts": "1742554949822"}], "ts": 1742554949827, "record_time": 1742554949.850419, "EXCHANGE": "BITGET"}
{"action": "update", "arg": {"instType": "SPOT", "channel": "books", "instId": "BTCUSDT"}, "data": [{"asks": [["84090.00", "2.066333"], ["84095.29", "0"], ["84096.97", "0"], ["84097.61", "0"], ["84097.74", "0"], ["84098.06", "0"], ["84099.38", "0"], ["84099.54", "0"], ["84099.91", "0"], ["84100.14", "0"], ["84100.54", "0"], ["84100.68", "0"], ["84100.87", "0"], ["84100.90", "0"], ["84101.02", "0"], ["84101.17", "0"], ["84101.35", "0.035952"], ["84102.71", "0"], ["84102.72", "0"], ["84103.03", "0.035961"], ["84103.29", "0"], ["84103.59", "0.006356"], ["84103.74", "0.006356"], ["84103.86", "0"], ["84104.09", "0.006356"], ["84104.29", "0"], ["84104.48", "0.313932"], ["84104.95", "0"], ["84105.14", "0.006356"], ["84105.30", "0.006356"], ["84105.63", "0"], ["84106.00", "0.006356"], ["84106.11", "0.016429"], ["84106.28", "0"], ["84106.30", "0.006356"], ["84106.63", "0.006356"], ["84106.64", "0.119883"], ["84106.80", "0.006356"], ["84106.85", "0.016429"], ["84107.13", "0.006356"], ["84108.65", "0.010985"], ["84108.66", "0.006357"], ["84109.35", "0.009990"], ["84109.70", "0"], ["84110.19", "0"], ["84110.28", "0.119850"], ["84111.19", "0.119858"], ["84111.53", "0.119867"], ["84111.69", "0.015895"], ["84111.80", "0.009989"], ["84115.72", "0.015892"], ["84116.42", "0.010988"], ["84117.89", "0"], ["84131.51", "0"], ["84137.98", "0.001597"], ["84141.60", "0.026842"], ["84143.60", "0.070637"], ["84145.60", "0.185887"], ["84147.60", "0.489176"], ["84149.60", "1.287304"], ["84151.60", "3.387643"], ["84153.60", "8.914850"], ["84154.50", "0.001041"], ["84154.60", "0.485130"], ["84156.10", "0.067800"], ["84157.70", "0"], ["84159.80", "0"], ["84161.00", "0"], ["84163.00", "0.144510"], ["84166.20", "0.163170"], ["84195.60", "5.072636"], ["84204.09", "0.031430"], ["84204.10", "5.525549"], ["84221.10", "3.895060"], ["84229.60", "5.163218"], ["84238.10", "3.985642"], ["84246.60", "4.438556"], ["84255.10", "4.257391"], ["84263.60", "4.076225"], ["84272.10", "4.619722"], ["84280.60", "4.347973"], ["84289.10", "5.434967"], ["84297.60", "4.982053"], ["84306.10", "4.529139"], ["84314.60", "5.616132"], ["84323.10", "4.710305"], ["84331.60", "4.800887"], ["84340.10", "5.253801"], ["84348.60", "4.891470"], ["84357.10", "5.344384"], ["84524.83", "0"]], "bids": [["84089.99", "0.271952"], ["84079.57", "0.041063"], ["84079.20", "0"], ["84071.30", "2.904609"], ["84069.30", "7.643707"], ["84069.20", "0.352920"], ["84060.99", "0.089456"], ["84059.31", "0.083913"], ["84059.03", "0.017811"], ["84058.84", "0.018249"], ["84058.51", "0.005944"], ["84056.88", "0.017098"], ["84056.70", "0.007129"], ["84056.50", "0.028855"], ["84056.39", "0.007337"], ["84056.01", "0.008991"], ["84055.68", "0.007940"], ["84055.56", "0.025176"], ["84055.50", "0.008182"], ["84055.35", "0.224811"], ["84055.18", "0.017345"], ["84054.93", "0"], ["84054.01", "0.012651"], ["84054.00", "0.051979"], ["84053.25", "0"], ["84053.05", "0"], ["84053.02", "0.018511"], ["84052.85", "0"], ["84052.49", "0"], ["84052.09", "0.268292"], ["84051.13", "0"], ["84050.99", "0.482312"], ["84050.94", "0"], ["84050.65", "0.076088"], ["84050.53", "0"], ["84050.42", "0.021123"], ["84050.31", "0"], ["84050.07", "0"], ["84049.92", "0"], ["84049.62", "0"], ["84049.59", "0"], ["84049.55", "0"], ["84049.40", "0"], ["84048.07", "0"], ["84048.06", "0"], ["84046.96", "0"], ["84046.77", "0.073192"], ["84046.11", "0"], ["84045.79", "0.056349"], ["84044.91", "0"], ["84044.75", "0"], ["84044.59", "0"], ["84044.22", "0.000876"], ["84043.32", "0"], ["84040.75", "0"], ["84039.57", "0"], ["84038.29", "0"], ["84027.30", "5.163218"], ["84025.52", "0.003596"], ["84023.80", "0.008506"], ["84018.80", "4.529139"], ["84018.11", "0"], ["84017.34", "0"], ["84010.30", "4.438556"], ["84001.80", "4.891470"], ["83993.30", "5.616132"], ["83984.80", "5.525549"], ["83976.30", "4.982053"], ["83967.80", "3.985642"], ["83959.30", "4.800887"], ["83950.80", "4.619722"], ["83942.30", "5.344384"], ["83933.80", "5.072636"], ["83925.30", "3.895060"], ["83916.80", "4.257391"], ["83899.80", "4.166808"], ["83891.30", "5.253801"], ["83882.80", "4.347973"], ["83874.30", "4.076225"], ["83865.80", "5.434967"], ["83661.97", "0.000052"], ["83661.60", "0.000042"], ["83661.08", "0.004152"]], "checksum": 1538612571, "ts": "1742554950027"}], "ts": 1742554950031, "record_time": 1742554950.057249, "EXCHANGE": "BITGET"}
{"action": "update", "arg": {"instType": "SPOT", "channel": "books", "instId": "BTCUSDT"}, "data": [{"asks": [["84090.00", "2.126333"], ["84090.01", "0.000100"], ["84129.08", "0"], ["84136.14", "0.001598"], ["84139.60", "0.010135"], ["84141.60", "0.026670"], ["84143.60", "0.070183"], ["84145.60", "0.184694"], ["84147.60", "0.486036"], ["84149.60", "1.279043"], ["84151.60", "3.365902"], ["84153.60", "8.857636"], ["84195.60", "5.616132"], ["84204.10", "5.072636"], ["84212.60", "3.985642"], ["84229.60", "4.529139"], ["84238.10", "5.434967"], ["84246.60", "4.166808"], ["84255.10", "4.710305"], ["84263.60", "5.163218"], ["84272.10", "4.438556"], ["84280.60", "4.800887"], ["84289.10", "4.257391"], ["84297.60", "5.253801"], ["84306.10", "4.982053"], ["84314.60", "4.891470"], ["84323.10", "4.619722"], ["84331.60", "4.076225"], ["84340.10", "5.525549"], ["84348.60", "4.347973"]], "bids": [["84079.30", "0.060776"], ["84077.30", "0.159936"], ["84075.30", "0.420885"], ["84073.30", "1.107592"], ["84071.30", "2.914716"], ["84069.30", "7.670305"], ["84037.00", "0"], ["84027.30", "5.434967"], ["84025.83", "0.001175"], ["84018.80", "5.344384"], ["84018.77", "0"], ["84010.30", "4.982053"], ["84001.80", "3.895060"], ["83993.30", "5.163218"], ["83984.80", "5.616132"], ["83976.30", "4.438556"], ["83967.80", "4.891470"], ["83959.30", "4.529139"], ["83942.30", "3.985642"], ["83933.80", "4.347973"], ["83925.30", "4.166808"], ["83916.80", "4.710305"], ["83908.30", "4.257391"], ["83899.80", "5.253801"], ["83891.30", "4.076225"], ["83882.80", "5.072636"], ["83874.30", "5.525549"], ["83865.80", "4.800887"], ["83660.71", "0.000309"]], "checksum": 2048932501, "ts": "1742554950230"}], "ts": 1742554950234, "record_time": 1742554950.25726, "EXCHANGE": "BITGET"}
{"action": "update", "arg": {"instType": "SPOT", "channel": "books", "instId": "BTCUSDT"}, "data": [{"asks": [["84151.60", "3.366156"], ["84153.60", "8.858306"], ["84156.30", "0"], ["84156.70", "2.543250"], ["84166.20", "0.091860"], ["84166.40", "0.027030"], ["84166.80", "0.198060"], ["84166.90", "0.180000"], ["84195.60", "4.800887"], ["84204.10", "5.616132"], ["84212.60", "4.076225"], ["84221.10", "5.525549"], ["84229.60", "4.438556"], ["84238.10", "3.985642"], ["84246.60", "4.710305"], ["84255.10", "4.982053"], ["84272.10", "4.347973"], ["84280.60", "4.529139"], ["84306.10", "5.344384"], ["84314.60", "5.434967"], ["84323.10", "4.891470"], ["84331.60", "4.619722"], ["84340.10", "5.072636"], ["84348.60", "3.895060"], ["84357.10", "4.166808"], ["84523.81", "0"], ["84524.00", "0"]], "bids": [["84087.30", "0.001442"], ["84085.30", "0.003795"], ["84083.30", "0.009986"], ["84081.30", "0.026280"], ["84079.30", "0.069159"], ["84077.30", "0.181997"], ["84075.30", "0.478939"], ["84073.30", "1.260365"], ["84071.30", "3.316751"], ["84069.30", "8.728292"], ["84027.30", "3.895060"], ["84018.80", "4.710305"], ["84010.30", "4.438556"], ["84001.80", "4.347973"], ["83993.30", "5.253801"], ["83984.80", "4.982053"], ["83976.30", "5.344384"], ["83967.80", "5.616132"], ["83959.30", "5.434967"], ["83950.80", "4.891470"], ["83942.30", "4.619722"], ["83933.80", "3.985642"], ["83925.30", "5.072636"], ["83916.80", "4.166808"], ["83908.30", "5.163218"], ["83899.80", "5.525549"], ["83891.30", "4.800887"], ["83882.80", "4.529139"], ["83874.30", "4.257391"], ["83865.80", "4.076225"]], "checksum": 1116221742, "ts": "1742554950431"}], "ts": 1742554950434, "record_time": 1742554950.488631, "EXCHANGE": "BITGET"}
{"action": "update", "arg": {"instType": "SPOT", "channel": "books", "instId": "BTCUSDT"}, "data": [{"asks": [["84090.00", "2.125732"], ["84109.69", "0.114630"], ["84131.62", "0"], ["84135.60", "0.001792"], ["84137.60", "0.004716"], ["84139.60", "0.012412"], ["84141.60", "0.032662"], ["84143.60", "0.085953"], ["84145.60", "0.226193"], ["84147.60", "0.595245"], ["84149.60", "1.566433"], ["84151.60", "4.122192"], ["84153.60", "10.847873"], ["84154.50", "0"], ["84154.60", "0"], ["84154.90", "0.001042"], ["84156.10", "0.068220"], ["84166.80", "0.006060"], ["84166.90", "0"], ["84195.60", "4.076225"], ["84204.10", "5.253801"], ["84212.60", "3.985642"], ["84221.10", "4.982053"], ["84229.60", "5.072636"], ["84238.10", "3.895060"], ["84246.60", "4.257391"], ["84255.10", "4.619722"], ["84263.60", "5.525549"], ["84272.10", "4.529139"], ["84280.60", "4.166808"], ["84289.10", "4.800887"], ["84297.60", "5.344384"], ["84306.10", "5.163218"], ["84314.60", "4.710305"], ["84323.10", "4.347973"], ["84331.60", "4.438556"], ["84340.10", "4.891470"], ["84348.60", "5.616132"], ["84357.10", "5.434967"], ["84523.81", "0.000024"], ["84524.00", "0.000035"], ["84524.83", "0.000009"]], "bids": [["84089.99", "0.032572"], ["84087.30", "0.001109"], ["84085.45", "0"], ["84085.30", "0.002917"], ["84083.30", "0.007677"], ["84081.30", "0.020201"], ["84079.98", "0.041063"], ["84079.57", "0"], ["84079.30", "0.053161"], ["84077.30", "0.139897"], ["84075.31", "0.511922"], ["84075.30", "0.368152"], ["84073.30", "0.968820"], ["84071.31", "0.431132"], ["84071.30", "2.549527"], ["84069.30", "6.709280"], ["84069.20", "0.001050"], ["84068.60", "0.234720"], ["84064.50", "0"], ["84062.90", "0"], ["84060.20", "0"], ["84057.70", "0.120000"], ["84038.00", "0.000017"], ["84027.30", "4.438556"], ["84018.80", "5.253801"], ["84010.30", "5.072636"], ["84001.80", "4.529139"], ["83993.30", "4.347973"], ["83984.80", "5.344384"], ["83976.30", "4.076225"], ["83959.30", "3.895060"], ["83950.80", "4.710305"], ["83942.30", "4.891470"], ["83925.30", "5.525549"], ["83916.80", "5.163218"], ["83908.30", "5.434967"], ["83899.80", "4.982053"], ["83882.80", "4.257391"], ["83874.30", "4.619722"], ["83865.80", "4.166808"], ["83660.14", "0.000016"]], "checksum": 1015352522, "ts": "1742554950647"}], "ts": 1742554950651, "record_time": 1742554950.675134, "EXCHANGE": "BITGET"}
{"action": "update", "arg": {"instType": "SPOT", "channel": "books", "instId": "BTCUSDT"}, "data": [{"asks": [["84090.00", "2.126333"], ["84136.41", "0.755090"], ["84147.60", "0.595434"], ["84149.60", "1.566932"], ["84151.60", "4.123507"], ["84153.60", "10.851184"], ["84154.90", "0"], ["84156.70", "2.543670"], ["84158.90", "0.072360"], ["84160.30", "0.180150"], ["84163.00", "0"], ["84166.80", "0.198060"], ["84166.90", "0.180000"], ["84178.40", "0"], ["84195.60", "4.982053"], ["84204.10", "4.076225"], ["84209.64", "0"], ["84218.83", "0"], ["84221.10", "4.257391"], ["84229.60", "4.710305"], ["84238.10", "5.344384"], ["84246.60", "4.166808"], ["84255.10", "5.163218"], ["84263.60", "3.895060"], ["84272.10", "4.891470"], ["84280.60", "5.072636"], ["84289.10", "4.529139"], ["84297.60", "5.616132"], ["84306.10", "4.619722"], ["84314.60", "4.347973"], ["84323.10", "4.438556"], ["84331.60", "5.434967"], ["84340.10", "5.525549"], ["84348.60", "4.800887"], ["84357.10", "5.253801"], ["84525.00", "0.003286"], ["84525.82", "0.000099"], ["84527.47", "0.000608"]], "bids": [["84085.30", "0.002745"], ["84083.30", "0.007224"], ["84081.30", "0.019012"], ["84079.30", "0.050032"], ["84077.30", "0.131662"], ["84075.30", "0.346480"], ["84073.30", "0.911531"], ["84071.30", "2.398766"], ["84069.30", "6.312542"], ["84068.60", "0.234930"], ["84067.20", "0.064380"], ["84066.60", "0.158670"], ["84059.30", "0.071310"], ["84058.20", "0.012570"], ["84058.10", "0"], ["84058.00", "0.000032"], ["84057.80", "0"], ["84057.70", "0"], ["84038.00", "0.000032"], ["84027.30", "4.710305"], ["84018.80", "5.525549"], ["84018.01", "0"], ["84010.30", "4.529139"], ["84009.60", "0"], ["84001.80", "5.163218"], ["83993.30", "4.076225"], ["83984.80", "5.434967"], ["83976.30", "5.072636"], ["83967.80", "5.344384"], ["83959.30", "5.253801"], ["83950.80", "4.619722"], ["83942.30", "4.257391"], ["83933.80", "4.166808"], ["83925.30", "5.616132"], ["83916.80", "3.895060"], ["83908.30", "4.982053"], ["83899.80", "4.347973"], ["83891.30", "4.891470"], ["83882.80", "4.800887"], ["83874.30", "3.985642"], ["83865.80", "4.438556"], ["83660.00", "0.001273"], ["83659.61", "0.000454"]], "checksum": -1061955291, "ts": "1742554950847"}], "ts": 1742554950851, "record_time": 1742554950.873832, "EXCHANGE": "BITGET"}
{"action": "update", "arg": {"instType": "SPOT", "channel": "books", "instId": "BTCUSDT"}, "data": [{"asks": [["84144.03", "0"], ["84147.60", "0.595074"], ["84149.60", "1.565984"], ["84151.60", "4.121012"], ["84153.60", "10.844767"], ["84166.12", "0"], ["84195.60", "5.525549"], ["84201.10", "0.001810"], ["84204.10", "4.982053"], ["84209.52", "0.003620"], ["84212.60", "5.434967"], ["84221.10", "4.166808"], ["84229.60", "3.985642"], ["84238.10", "4.800887"], ["84246.60", "5.072636"], ["84255.10", "4.347973"], ["84263.60", "4.438556"], ["84280.60", "4.529139"], ["84289.10", "4.619722"], ["84297.60", "4.710305"], ["84306.10", "4.257391"], ["84314.60", "5.163218"], ["84323.10", "5.616132"], ["84331.60", "4.076225"], ["84340.10", "3.895060"], ["84348.60", "5.344384"]], "bids": [["84080.34", "0.041063"], ["84079.98", "0"], ["84039.00", "0.000015"], ["84018.80", "4.076225"], ["84010.30", "3.895060"], ["84004.20", "0.001810"], ["84001.80", "5.072636"], ["83994.09", "0.003620"], ["83993.30", "4.166808"], ["83984.80", "5.525549"], ["83976.30", "4.982053"], ["83967.80", "5.616132"], ["83959.30", "4.529139"], ["83950.80", "5.434967"], ["83942.30", "5.163218"], ["83933.80", "4.438556"], ["83925.30", "5.344384"], ["83916.80", "4.619722"], ["83908.30", "3.985642"], ["83899.80", "4.257391"], ["83891.30", "5.253801"], ["83874.30", "4.891470"], ["83865.80", "4.347973"], ["83660.00", "0"], ["83659.61", "0"]], "checksum": 1697894542, "ts": "1742554951050"}], "ts": 1742554951052, "record_time": 1742554951.106219, "EXCHANGE": "BITGET"}
{"action": "update", "arg": {"instType": "SPOT", "channel": "books", "instId": "BTCUSDT"}, "data": [{"asks": [["84195.60", "4.529139"], ["84204.10", "5.163218"], ["84212.60", "5.616132"], ["84221.10", "4.800887"], ["84229.60", "4.619722"], ["84238.10", "3.985642"], ["84246.60", "4.710305"], ["84255.10", "4.982053"], ["84263.60", "5.525549"], ["84272.10", "4.347973"], ["84280.60", "5.434967"], ["84289.10", "5.344384"], ["84297.60", "4.076225"], ["84306.10", "5.253801"], ["84314.60", "4.166808"], ["84323.10", "4.257391"], ["84331.60", "4.891470"], ["84340.10", "4.438556"], ["84348.60", "5.072636"], ["84357.10", "3.895060"]], "bids": [["84059.30", "0"], ["84058.10", "1.782210"], ["84027.30", "5.616132"], ["84018.80", "5.163218"], ["84010.30", "4.257391"], ["84001.80", "4.076225"], ["83993.30", "4.891470"], ["83984.80", "4.982053"], ["83976.30", "5.072636"], ["83967.80", "5.434967"], ["83959.30", "5.525549"], ["83950.80", "5.253801"], ["83942.30", "4.347973"], ["83933.80", "4.800887"], ["83925.30", "4.438556"], ["83916.80", "4.710305"], ["83908.30", "4.166808"], ["83899.80", "3.895060"], ["83891.30", "3.985642"], ["83882.80", "4.529139"], ["83874.30", "4.619722"], ["83865.80", "5.344384"]], "checksum": 1697894542, "ts": "1742554951252"}], "ts": 1742554951255, "record_time": 1742554951.276994, "EXCHANGE": "BITGET"}
{"action": "update", "arg": {"instType": "SPOT", "channel": "books", "instId": "BTCUSDT"}, "data": [{"asks": [["84126.50", "0"], ["84158.90", "0"], ["84195.60", "4.076225"], ["84204.10", "5.072636"], ["84212.60", "4.529139"], ["84221.10", "5.616132"], ["84238.10", "4.891470"], ["84246.60", "5.253801"], ["84255.10", "4.166808"], ["84263.60", "4.800887"], ["84272.10", "4.710305"], ["84280.60", "4.257391"], ["84289.10", "5.163218"], ["84297.60", "5.434967"], ["84306.10", "3.895060"], ["84314.60", "4.982053"], ["84323.10", "5.525549"], ["84331.60", "4.438556"], ["84340.10", "3.985642"], ["84348.60", "4.347973"], ["84357.10", "5.344384"], ["84528.57", "0.000008"], ["84530.00", "0.000031"]], "bids": [["84085.30", "0.003109"], ["84083.30", "0.008180"], ["84081.30", "0.021527"], ["84079.30", "0.056649"], ["84077.30", "0.149078"], ["84075.30", "0.392310"], ["84073.30", "1.032394"], ["84071.30", "2.716826"], ["84069.30", "7.149542"], ["84067.20", "0"], ["84066.60", "0.158880"], ["84062.40", "0.071730"], ["84059.30", "0.072150"], ["84058.10", "0"], ["84027.30", "5.072636"], ["84018.80", "5.253801"], ["84010.30", "3.895060"], ["84001.80", "4.619722"], ["83993.30", "4.982053"], ["83984.80", "4.347973"], ["83976.30", "4.166808"], ["83967.80", "5.163218"], ["83959.30", "3.985642"], ["83950.80", "5.344384"], ["83942.30", "4.891470"], ["83933.80", "4.710305"], ["83925.30", "4.076225"], ["83916.80", "5.616132"], ["83908.30", "4.529139"], ["83899.80", "5.434967"], ["83891.30", "4.438556"], ["83882.80", "4.257391"], ["83874.30", "5.525549"], ["83865.80", "4.800887"]], "checksum": 678627933, "ts": "1742554951454"}], "ts": 1742554951458, "record_time": 1742554951.50275, "EXCHANGE": "BITGET"}
{"action": "update", "arg": {"instType": "SPOT", "channel": "books", "instId": "BTCUSDT"}, "data": [{"asks": [["84090.00", "2.126435"], ["84126.21", "0.070525"], ["84140.89", "0.713089"], ["84166.12", "1.782189"], ["84195.60", "5.616132"], ["84204.10", "4.438556"], ["84212.60", "4.076225"], ["84221.10", "4.710305"], ["84238.10", "5.344384"], ["84246.60", "4.800887"], ["84255.10", "5.163218"], ["84263.60", "4.347973"], ["84272.10", "5.253801"], ["84280.60", "4.891470"], ["84289.10", "3.985642"], ["84297.60", "4.166808"], ["84314.60", "4.529139"], ["84323.10", "5.434967"], ["84331.60", "5.072636"], ["84340.10", "4.982053"], ["84348.60", "4.257391"], ["84357.10", "5.525549"], ["84528.57", "0"], ["84530.00", "0"]], "bids": [["84082.47", "0.019223"], ["84080.66", "0.041063"], ["84080.34", "0"], ["84080.18", "0"], ["84073.30", "1.032647"], ["84071.30", "2.717490"], ["84069.30", "7.151291"], ["84069.20", "0.306510"], ["84068.90", "0.003900"], ["84068.60", "0"], ["84058.10", "1.782210"], ["84039.00", "0"], ["84037.00", "0.000017"], ["84027.30", "4.619722"], ["84010.30", "5.163218"], ["84001.80", "5.344384"], ["83993.30", "5.434967"], ["83984.80", "4.076225"], ["83967.80", "5.072636"], ["83950.80", "3.895060"], ["83942.30", "4.347973"], ["83933.80", "5.616132"], ["83925.30", "5.525549"], ["83916.80", "4.438556"], ["83908.30", "4.710305"], ["83899.80", "4.800887"], ["83891.30", "4.891470"], ["83882.80", "4.982053"], ["83874.30", "4.529139"], ["83865.80", "4.257391"], ["83660.14", "0"]], "checksum": 834711972, "ts": "1742554951663"}], "ts": 1742554951666, "record_time": 1742554951.688954, "EXCHANGE": "BITGET"}
{"action": "update", "arg": {"instType": "SPOT", "channel": "books", "instId": "BTCUSDT"}, "data": [{"asks": [["84126.51", "0.181320"], ["84149.60", "1.566229"], ["84151.60", "4.121655"], ["84153.60", "10.846460"], ["84166.20", "0.089130"], ["84195.60", "4.891470"], ["84204.10", "4.076225"], ["84212.60", "5.525549"], ["84221.10", "5.434967"], ["84229.60", "4.800887"], ["84246.60", "4.257391"], ["84255.10", "5.616132"], ["84272.10", "5.072636"], ["84280.60", "4.619722"], ["84297.60", "5.163218"], ["84306.10", "4.438556"], ["84323.10", "5.253801"], ["84331.60", "4.982053"], ["84340.10", "3.895060"], ["84348.60", "4.710305"], ["84357.10", "4.166808"], ["84527.47", "0"]], "bids": [["84085.30", "0.002745"], ["84083.30", "0.007222"], ["84081.30", "0.019007"], ["84079.30", "0.050018"], ["84077.30", "0.131625"], ["84075.30", "0.346382"], ["84073.30", "0.911531"], ["84071.30", "2.398766"], ["84069.30", "6.312542"], ["84068.90", "0"], ["84068.60", "0.015780"], ["84058.10", "0"], ["84027.30", "5.616132"], ["84018.80", "5.525549"], ["84010.30", "4.347973"], ["84001.80", "4.891470"], ["83993.30", "4.982053"], ["83984.80", "4.529139"], ["83976.30", "4.257391"], ["83967.80", "3.895060"], ["83959.30", "5.434967"], ["83950.80", "5.344384"], ["83942.30", "5.072636"], ["83933.80", "4.800887"], ["83925.30", "4.710305"], ["83916.80", "5.253801"], ["83908.30", "3.985642"], ["83899.80", "5.163218"], ["83891.30", "4.619722"], ["83882.80", "4.076225"], ["83874.30", "4.438556"], ["83865.80", "4.166808"], ["83660.14", "0.000016"]], "checksum": -1630008971, "ts": "1742554951865"}], "ts": 1742554951868, "record_time": 1742554951.890294, "EXCHANGE": "BITGET"}
{"action": "update", "arg": {"instType": "SPOT", "channel": "books", "instId": "BTCUSDT"}, "data": [{"asks": [["84126.21", "0.112082"], ["84129.27", "0.010000"], ["84133.60", "0.001141"], ["84137.60", "0.004897"], ["84139.60", "0.012888"], ["84141.60", "0.033916"], ["84143.60", "0.089252"], ["84145.60", "0.235036"], ["84147.60", "0.618517"], ["84149.60", "1.627675"], ["84151.60", "4.283356"], ["84153.60", "11.271991"], ["84157.70", "0.015000"], ["84158.90", "0.070620"], ["84164.20", "2.281530"], ["84164.30", "0.473070"], ["84164.40", "2.568900"], ["84166.80", "0.006060"], ["84166.90", "0"], ["84195.60", "5.616132"], ["84204.10", "5.253801"], ["84212.60", "4.619722"], ["84229.60", "3.895060"], ["84238.10", "4.166808"], ["84246.60", "5.344384"], ["84255.10", "4.710305"], ["84263.60", "4.982053"], ["84272.10", "5.163218"], ["84280.60", "4.800887"], ["84289.10", "4.257391"], ["84297.60", "4.891470"], ["84306.10", "4.076225"], ["84314.60", "5.072636"], ["84323.10", "4.529139"], ["84331.60", "4.438556"], ["84340.10", "5.525549"], ["84348.60", "4.347973"], ["84357.10", "3.985642"], ["84524.83", "0"], ["84525.00", "0"], ["84525.82", "0"]], "bids": [["84085.30", "0.001260"], ["84083.30", "0.003315"], ["84082.47", "0"], ["84081.30", "0.008724"], ["84079.30", "0.022957"], ["84078.10", "0.017179"], ["84077.30", "0.060415"], ["84075.85", "0.019223"], ["84075.31", "0.176405"], ["84075.30", "0.158987"], ["84073.30", "0.418185"], ["84071.30", "1.100488"], ["84069.30", "2.896020"], ["84069.20", "0.001021"], ["84068.60", "0.035220"], ["84066.60", "0.013290"], ["84066.50", "0.009000"], ["84065.80", "0.071850"], ["84065.00", "0.735240"], ["84062.70", "0.144510"], ["84062.60", "0"], ["84062.40", "0"], ["84059.30", "0"], ["84058.70", "0"], ["84058.20", "0"], ["84027.30", "5.253801"], ["84018.80", "3.895060"], ["84010.30", "4.982053"], ["84001.80", "5.072636"], ["83993.30", "4.257391"], ["83984.80", "5.434967"], ["83976.30", "4.529139"], ["83967.80", "5.525549"], ["83959.30", "4.800887"], ["83950.80", "4.166808"], ["83942.30", "4.619722"], ["83933.80", "4.438556"], ["83925.30", "5.163218"], ["83916.80", "4.347973"], ["83908.30", "4.710305"], ["83899.80", "4.891470"], ["83891.30", "5.344384"], ["83874.30", "3.985642"], ["83865.80", "5.616132"], ["83660.00", "0.001273"], ["83659.61", "0.000454"], ["83659.49", "0.000012"]], "checksum": 1741916681, "ts": "1742554952065"}], "ts": 1742554952070, "record_time": 1742554952.092891, "EXCHANGE": "BITGET"}
{"action": "update", "arg": {"instType": "SPOT", "channel": "books", "instId": "BTCUSDT"}, "data": [{"asks": [["84090.00", "2.126453"], ["84154.40", "0.001037"], ["84156.70", "2.543250"], ["84157.50", "0.144510"], ["84160.00", "0"], ["84160.30", "0.035640"], ["84161.80", "0.120000"], ["84166.20", "0.100440"], ["84166.80", "0.198060"], ["84195.60", "4.891470"], ["84204.10", "4.529139"], ["84212.60", "4.800887"], ["84221.10", "4.257391"], ["84238.10", "4.347973"], ["84246.60", "3.985642"], ["84255.10", "5.434967"], ["84263.60", "5.525549"], ["84272.10", "5.616132"], ["84280.60", "4.166808"], ["84289.10", "5.163218"], ["84297.60", "4.619722"], ["84314.60", "4.710305"], ["84323.10", "5.072636"], ["84340.10", "5.253801"], ["84348.60", "5.344384"], ["84357.10", "4.982053"], ["84524.00", "0"]], "bids": [["84089.99", "0.000100"], ["84085.30", "0.001004"], ["84083.38", "0.012472"], ["84083.30", "0.001042"], ["84081.30", "0.001055"], ["84081.08", "0.041062"], ["84080.66", "0"], ["84079.90", "0.010000"], ["84079.30", "0.001041"], ["84077.30", "0.001030"], ["84075.31", "0"], ["84075.30", "0.001574"], ["84074.49", "0"], ["84073.30", "0.004142"], ["84071.30", "0.010899"], ["84069.30", "0.028681"], ["84069.00", "0.000032"], ["84068.60", "0"], ["84067.90", "0"], ["84065.00", "0.249030"], ["84063.90", "0.068010"], ["84062.80", "0.011100"], ["84062.70", "0"], ["84061.60", "1.037370"], ["84059.90", "0.144510"], ["84059.80", "0.074460"], ["84038.00", "0.000015"], ["84037.00", "0.000032"], ["84027.30", "3.895060"], ["84018.80", "4.347973"], ["84010.30", "5.072636"], ["84001.80", "4.257391"], ["83993.30", "5.525549"], ["83984.80", "4.800887"], ["83976.30", "4.982053"], ["83967.80", "5.163218"], ["83959.30", "5.344384"], ["83950.80", "5.616132"], ["83942.30", "4.710305"], ["83933.80", "4.891470"], ["83925.30", "4.619722"], ["83916.80", "4.076225"], ["83908.30", "4.438556"], ["83899.80", "5.253801"], ["83891.30", "3.985642"], ["83882.80", "5.434967"], ["83874.30", "4.529139"], ["83865.80", "4.166808"], ["83659.49", "0"]], "checksum": -104850873, "ts": "1742554952269"}], "ts": 1742554952272, "record_time": 1742554952.336127, "EXCHANGE": "BITGET"}
{"action": "update", "arg": {"instType": "SPOT", "channel": "books", "instId": "BTCUSDT"}, "data": [{"asks": [["84089.99", "2.426440"], ["84090.00", "0.762338"], ["84090.62", "0"], ["84090.67", "0"], ["84090.69", "0"], ["84090.71", "0"], ["84090.81", "0"], ["84101.47", "0.012472"], ["84108.44", "0"], ["84126.44", "0"], ["84129.30", "0.001505"], ["84131.30", "0.002456"], ["84133.30", "0.006464"], ["84133.60", "0"], ["84135.30", "0.017009"], ["84135.60", "0"], ["84136.42", "0"], ["84136.60", "0.713126"], ["84137.30", "0.044761"], ["84137.60", "0"], ["84139.30", "0.117791"], ["84139.60", "0"], ["84140.89", "0"], ["84141.30", "0.309977"], ["84141.60", "0"], ["84143.30", "0.815730"], ["84143.60", "0"], ["84145.30", "2.146658"], ["84145.60", "0"], ["84147.30", "5.649099"], ["84147.60", "0"], ["84149.30", "14.866050"], ["84149.60", "0"], ["84150.10", "0.067980"], ["84151.60", "0"], ["84152.10", "0.067980"], ["84152.20", "0.001040"], ["84152.80", "0.071640"], ["84153.30", "0.001040"], ["84153.50", "7.752150"], ["84153.60", "1.696080"], ["84154.20", "0.144690"], ["84154.40", "0"], ["84156.10", "0.067980"], ["84156.60", "0"], ["84156.70", "1.593840"], ["84156.90", "0.453540"], ["84157.10", "0"], ["84157.50", "0"], ["84158.00", "0"], ["84158.10", "0.349950"], ["84163.50", "0.269760"], ["84166.00", "0"], ["84166.20", "0"], ["84166.40", "0"], ["84166.80", "0"], ["84175.21", "0"], ["84191.30", "4.529370"], ["84195.60", "0"], ["84199.80", "4.801132"], ["84204.10", "0"], ["84208.30", "4.891720"], ["84212.60", "0"], ["84216.80", "4.982307"], ["84221.10", "0"], ["84225.30", "3.985846"], ["84229.60", "0"], ["84233.80", "5.163482"], ["84238.10", "0"], ["84242.30", "5.435244"], ["84246.60", "0"], ["84250.80", "3.895258"], ["84255.10", "0"], ["84259.30", "5.616419"], ["84263.60", "0"], ["84267.80", "5.072894"], ["84272.10", "0"], ["84276.30", "5.344656"], ["84280.60", "0"], ["84284.80", "4.076433"], ["84289.10", "0"], ["84293.30", "4.710545"], ["84297.60", "0"], ["84301.80", "5.525831"], ["84306.10", "0"], ["84310.30", "4.167020"], ["84314.60", "0"], ["84318.80", "4.348195"], ["84323.10", "0"], ["84327.30", "4.619957"], ["84331.60", "0"], ["84335.80", "5.254069"], ["84340.10", "0"], ["84344.30", "4.438783"], ["84348.60", "0"], ["84352.80", "4.257608"], ["84357.10", "0"], ["84524.00", "0.000035"], ["84524.83", "0.000009"], ["84525.00", "0.003286"], ["84525.82", "0.000099"], ["84527.47", "0.000608"], ["84528.57", "0.000008"]], "bids": [["84089.99", "0"], ["84089.95", "0.000100"], ["84089.30", "0"], ["84087.30", "0"], ["84085.30", "0"], ["84085.00", "0.001015"], ["84083.96", "0"], ["84083.30", "0"], ["84083.00", "0.001001"], ["84081.30", "0"], ["84081.08", "0"], ["84081.00", "0.001011"], ["84080.83", "0"], ["84079.30", "0"], ["84079.00", "0.002445"], ["84078.16", "0"], ["84078.12", "0"], ["84078.11", "0"], ["84078.10", "0"], ["84078.09", "0"], ["84078.08", "0"], ["84077.30", "0"], ["84075.30", "0"], ["84075.00", "0.016933"], ["84074.05", "0"], ["84074.00", "0.000032"], ["84073.99", "0"], ["84073.93", "0"], ["84073.91", "0"], ["84073.89", "0"], ["84073.30", "0"], ["84073.00", "0.044560"], ["84071.31", "0"], ["84071.30", "0"], ["84071.13", "0.015917"], ["84071.10", "0.008499"], ["84071.00", "0.126847"], ["84070.94", "0.017179"], ["84070.93", "0.008236"], ["84070.92", "0.007793"], ["84070.88", "0.007749"], ["84069.30", "0"], ["84069.20", "0"], ["84069.00", "0.308590"], ["84067.03", "0.008711"], ["84067.00", "0.812078"], ["84066.95", "0.010333"], ["84066.83", "0.005581"], ["84066.82", "0.008532"], ["84066.75", "0.004826"], ["84066.73", "0.010286"], ["84066.60", "0"], ["84066.50", "0"], ["84065.80", "0"], ["84065.00", "2.137047"], ["84064.80", "0.001032"], ["84064.60", "0.009840"], ["84064.50", "0.858780"], ["84063.90", "0.068190"], ["84063.43", "0.028180"], ["84062.92", "0"], ["84062.16", "0"], ["84061.60", "1.037550"], ["84061.29", "0"], ["84061.20", "0"], ["84061.10", "0.240180"], ["84060.60", "0.744900"], ["84060.20", "0.486630"], ["84058.30", "0.022770"], ["84058.20", "0.012570"], ["84058.10", "1.782210"], ["84058.00", "0.009000"], ["84057.70", "0.120000"], ["84056.80", "0.534660"], ["84056.30", "0.120000"], ["84056.00", "0.090000"], ["84055.95", "0.008267"], ["84055.70", "0.004350"], ["84055.60", "1.568460"], ["84055.30", "0.120000"], ["84055.20", "1.425780"], ["84054.31", "0.008057"], ["84052.74", "0"], ["84052.69", "0"], ["84052.63", "0"], ["84052.60", "0"], ["84052.59", "0"], ["84052.57", "0"], ["84052.54", "0"], ["84052.47", "0"], ["84046.06", "0.008425"], ["84045.90", "0.006470"], ["84045.88", "0.008595"], ["84045.72", "0.009208"], ["84045.62", "0.007303"], ["84045.61", "0"], ["84045.52", "0"], ["84045.48", "0"], ["84038.64", "0.008092"], ["84038.55", "0.008263"], ["84038.51", "0.005051"], ["84029.78", "0"], ["84027.30", "0"], ["84026.83", "0"], ["84024.00", "0"], ["84023.98", "0"], ["84023.80", "0.001172"], ["84023.00", "4.710545"], ["84022.78", "0.007432"], ["84019.87", "0.008570"], ["84018.80", "0"], ["84017.33", "0.007650"], ["84017.31", "0.007246"], ["84017.14", "0.007334"], ["84014.50", "4.257608"], ["84010.30", "0"], ["84006.00", "5.254069"], ["84001.80", "0"], ["83997.50", "5.616419"], ["83993.30", "0"], ["83989.00", "5.525831"], ["83984.80", "0"], ["83980.50", "4.076433"], ["83976.30", "0"], ["83972.00", "5.344656"], ["83967.80", "0"], ["83963.50", "4.891720"], ["83959.30", "0"], ["83955.00", "4.167020"], ["83950.80", "0"], ["83946.50", "3.985846"], ["83942.30", "0"], ["83938.00", "4.348195"], ["83933.80", "0"], ["83929.50", "4.529370"], ["83925.30", "0"], ["83921.00", "4.619957"], ["83916.80", "0"], ["83912.50", "4.438783"], ["83908.30", "0"], ["83904.00", "4.982307"], ["83899.80", "0"], ["83895.50", "5.163482"], ["83891.30", "0"], ["83887.00", "3.895258"], ["83882.80", "0"], ["83878.50", "4.801132"], ["83874.30", "0"], ["83870.00", "5.435244"], ["83865.80", "0"], ["83861.50", "5.072894"], ["83659.49", "0.000012"], ["83659.44", "0.000613"], ["83658.54", "0.000036"], ["83656.60", "0.000607"], ["83655.00", "0.000926"], ["83654.23", "0.000009"], ["83653.94", "0.000133"], ["83653.67", "0.001695"]], "checksum": 1191794838, "ts": "1742554952470"}], "ts": 1742554952473, "record_time": 1742554952.522011, "EXCHANGE": "BITGET"}
{"action": "update", "arg": {"instType": "SPOT", "channel": "books", "instId": "BTCUSDT"}, "data": [{"asks": [["84089.99", "2.718878"], ["84090.00", "0.477424"], ["84090.61", "0"], ["84101.47", "0"], ["84106.10", "0.058652"], ["84108.43", "0"], ["84108.68", "0.012472"], ["84135.30", "0.016868"], ["84136.41", "0"], ["84137.30", "0.044389"], ["84139.30", "0.116814"], ["84141.30", "0.307405"], ["84143.30", "0.808959"], ["84145.30", "2.128839"], ["84147.30", "5.602210"], ["84149.30", "14.742658"], ["84149.80", "0.006060"], ["84150.10", "0.138480"], ["84152.10", "0.068400"], ["84152.20", "0"], ["84152.80", "0.071460"], ["84153.30", "0"], ["84153.50", "0.023190"], ["84153.60", "1.659750"], ["84156.70", "1.413000"], ["84156.90", "0.453360"], ["84159.90", "0.024930"], ["84164.80", "0"], ["84165.20", "0"], ["84165.30", "0"], ["84191.30", "4.167020"], ["84199.80", "4.891720"], ["84204.09", "0"], ["84208.30", "5.072894"], ["84216.80", "4.710545"], ["84225.30", "4.619957"], ["84233.80", "4.076433"], ["84242.30", "5.254069"], ["84250.80", "3.985846"], ["84259.30", "4.438783"], ["84267.80", "5.163482"], ["84276.30", "3.895258"], ["84284.80", "4.801132"], ["84293.30", "5.616419"], ["84301.80", "5.435244"], ["84310.30", "5.344656"], ["84327.30", "5.525831"], ["84335.80", "4.257608"], ["84344.30", "4.529370"], ["84352.80", "4.982307"], ["84530.00", "0.000031"], ["84533.01", "0.000591"], ["84533.33", "0.003186"], ["84534.53", "0.000461"], ["84535.32", "0.000039"], ["84536.36", "0.000053"]], "bids": [["84080.63", "0.112975"], ["84077.13", "0.041064"], ["84073.00", "0.044769"], ["84071.01", "0.208656"], ["84071.00", "0.117813"], ["84069.00", "0.310035"], ["84067.00", "0.815880"], ["84066.98", "0.008894"], ["84065.00", "2.147054"], ["84064.60", "0.009420"], ["84064.50", "0.858570"], ["84063.90", "0.068010"], ["84063.00", "0.813840"], ["84061.60", "0"], ["84061.50", "0.071190"], ["84061.40", "0.274860"], ["84061.10", "0.240000"], ["84060.60", "0.744720"], ["84059.70", "0.066150"], ["84056.60", "1.350000"], ["84055.70", "0"], ["84055.60", "0"], ["84055.30", "0"], ["84055.20", "0"], ["84054.32", "0.013533"], ["84045.93", "0.008012"], ["84045.76", "0.008317"], ["84045.66", "0.006904"], ["84023.00", "4.257608"], ["84014.50", "3.985846"], ["84006.00", "4.167020"], ["83997.50", "5.163482"], ["83989.00", "4.619957"], ["83980.50", "4.348195"], ["83972.00", "5.525831"], ["83963.50", "4.982307"], ["83955.00", "5.072894"], ["83946.50", "4.891720"], ["83938.00", "4.710545"], ["83929.50", "3.895258"], ["83921.00", "5.435244"], ["83912.50", "4.801132"], ["83904.00", "4.438783"], ["83895.50", "4.529370"], ["83887.00", "5.254069"], ["83878.50", "5.344656"], ["83870.00", "5.616419"], ["83861.50", "4.076433"], ["83659.44", "0"], ["83658.54", "0"], ["83656.60", "0"], ["83655.00", "0"], ["83654.23", "0"], ["83653.94", "0"], ["83653.67", "0"]], "checksum": 1118596313, "ts": "1742554952670"}], "ts": 1742554952677, "record_time": 1742554952.709401, "EXCHANGE": "BITGET"}
{"action": "update", "arg": {"instType": "SPOT", "channel": "books", "instId": "BTCUSDT"}, "data": [{"asks": [["84089.99", "2.151000"], ["84090.00", "0.470424"], ["84099.60", "1.531031"], ["84128.58", "3.569042"], ["84141.30", "0.307304"], ["84143.30", "0.808694"], ["84145.30", "2.128141"], ["84147.30", "5.600372"], ["84149.30", "14.737822"], ["84150.10", "0.620640"], ["84152.10", "0.067980"], ["84152.20", "0.001036"], ["84158.02", "0.404946"], ["84164.80", "1.350000"], ["84166.12", "0"], ["84199.80", "4.710545"], ["84208.30", "5.525831"], ["84216.80", "3.895258"], ["84242.30", "4.438783"], ["84250.80", "4.529370"], ["84259.30", "4.891720"], ["84267.80", "4.982307"], ["84276.30", "4.348195"], ["84284.80", "5.163482"], ["84293.30", "5.254069"], ["84301.80", "4.257608"], ["84310.30", "5.072894"], ["84318.80", "5.344656"], ["84327.30", "3.985846"], ["84335.80", "4.801132"], ["84344.30", "5.435244"], ["84352.80", "5.616419"], ["84533.33", "0"], ["84534.53", "0"], ["84535.32", "0"], ["84536.36", "0"]], "bids": [["84075.00", "0.017199"], ["84073.00", "0.045261"], ["84071.00", "0.119106"], ["84069.00", "0.313682"], ["84067.00", "0.825479"], ["84065.00", "2.172313"], ["84055.70", "0.004350"], ["84039.00", "0.000017"], ["84023.00", "4.167020"], ["84014.50", "5.254069"], ["84006.00", "5.344656"], ["83997.50", "4.801132"], ["83989.00", "4.348195"], ["83980.50", "5.435244"], ["83972.00", "4.619957"], ["83963.50", "4.529370"], ["83955.00", "3.985846"], ["83938.00", "5.163482"], ["83929.50", "5.616419"], ["83921.00", "4.257608"], ["83912.50", "4.710545"], ["83904.00", "4.982307"], ["83895.50", "3.895258"], ["83887.00", "4.438783"], ["83878.50", "5.525831"], ["83870.00", "5.072894"], ["83659.61", "0"], ["83659.49", "0"]], "checksum": -1296097486, "ts": "1742554952875"}], "ts": 1742554952880, "record_time": 1742554952.924146, "EXCHANGE": "BITGET"}
{"action": "update", "arg": {"instType": "SPOT", "channel": "books", "instId": "BTCUSDT"}, "data": [{"asks": [["84089.99", "2.396840"], ["84098.07", "0.544867"], ["84126.21", "0.697088"], ["84145.30", "2.127919"], ["84147.30", "5.599785"], ["84149.30", "14.736278"], ["84161.83", "1.782280"], ["84191.30", "4.076433"], ["84199.80", "4.982307"], ["84208.30", "4.801132"], ["84216.80", "4.619957"], ["84225.30", "4.167020"], ["84233.80", "5.072894"], ["84242.30", "4.348195"], ["84250.80", "4.891720"], ["84259.30", "5.435244"], ["84267.80", "5.616419"], ["84276.30", "4.257608"], ["84284.80", "4.529370"], ["84293.30", "5.344656"], ["84301.80", "5.254069"], ["84310.30", "4.710545"], ["84318.80", "5.163482"], ["84327.30", "3.895258"], ["84335.80", "3.985846"], ["84344.30", "5.525831"], ["84352.80", "4.438783"], ["84533.01", "0"]], "bids": [["84023.00", "4.891720"], ["84014.50", "4.076433"], ["84006.00", "4.529370"], ["83997.50", "5.254069"], ["83989.00", "4.257608"], ["83980.50", "4.438783"], ["83972.00", "4.801132"], ["83963.50", "3.985846"], ["83955.00", "4.710545"], ["83946.50", "4.167020"], ["83938.00", "5.616419"], ["83929.50", "4.619957"], ["83921.00", "5.163482"], ["83912.50", "5.525831"], ["83895.50", "4.348195"], ["83887.00", "5.344656"], ["83878.50", "3.895258"], ["83872.00", "0"], ["83870.00", "5.435244"], ["83861.50", "5.072894"], ["83659.61", "0.000454"]], "checksum": -2018701365, "ts": "1742554953078"}], "ts": 1742554953082, "record_time": 1742554953.119416, "EXCHANGE": "BITGET"}
{"action": "update", "arg": {"instType": "SPOT", "channel": "books", "instId": "BTCUSDT"}, "data": [{"asks": [["84089.99", "2.103400"], ["84090.00", "0.470304"], ["84108.68", "0"], ["84111.01", "0.012472"], ["84129.30", "0.001363"], ["84131.30", "0.002223"], ["84133.30", "0.005852"], ["84135.30", "0.015398"], ["84137.30", "0.040521"], ["84139.30", "0.106634"], ["84141.30", "0.280616"], ["84143.30", "0.738464"], ["84145.30", "1.943326"], ["84147.30", "5.114016"], ["84149.30", "13.457937"], ["84191.30", "5.435244"], ["84199.80", "5.525831"], ["84208.30", "4.076433"], ["84216.80", "5.344656"], ["84225.30", "3.985846"], ["84233.80", "4.167020"], ["84242.30", "5.616419"], ["84250.80", "4.619957"], ["84259.30", "4.348195"], ["84267.80", "4.710545"], ["84276.30", "4.891720"], ["84284.80", "4.982307"], ["84293.30", "5.163482"], ["84301.80", "4.257608"], ["84310.30", "4.801132"], ["84318.80", "5.072894"], ["84327.30", "4.438783"], ["84335.80", "3.895258"], ["84344.30", "5.254069"], ["84352.80", "4.529370"]], "bids": [["84077.62", "0.041064"], ["84077.13", "0"], ["84075.00", "0.017026"], ["84073.00", "0.044804"], ["84071.00", "0.117906"], ["84069.00", "0.310279"], ["84067.00", "0.816524"], ["84065.00", "2.148746"], ["84064.60", "0.001039"], ["84064.50", "1.061130"], ["84064.10", "1.038030"], ["84063.00", "0.000032"], ["84058.30", "0"], ["84055.60", "1.367970"], ["84038.00", "0"], ["84023.00", "5.254069"], ["84014.50", "5.344656"], ["84006.00", "4.167020"], ["83997.50", "4.257608"], ["83989.00", "3.985846"], ["83980.50", "4.076433"], ["83972.00", "3.895258"], ["83963.50", "4.710545"], ["83955.00", "5.072894"], ["83946.50", "4.438783"], ["83938.00", "4.348195"], ["83929.50", "5.525831"], ["83921.00", "4.801132"], ["83912.50", "5.163482"], ["83904.00", "5.616419"], ["83895.50", "4.529370"], ["83887.00", "4.982307"], ["83878.50", "4.891720"], ["83870.00", "4.619957"], ["83861.50", "5.435244"]], "checksum": -1566459728, "ts": "1742554953279"}], "ts": 1742554953282, "record_time": 1742554953.304748, "EXCHANGE": "BITGET"}
{"action": "update", "arg": {"instType": "SPOT", "channel": "books", "instId": "BTCUSDT"}, "data": [{"asks": [["84089.99", "2.349240"], ["84145.30", "1.943189"], ["84147.30", "5.113656"], ["84149.30", "13.456988"], ["84191.30", "4.348195"], ["84199.80", "5.616419"], ["84208.30", "4.891720"], ["84216.80", "4.167020"], ["84225.30", "4.619957"], ["84233.80", "5.163482"], ["84242.30", "5.072894"], ["84250.80", "4.257608"], ["84259.30", "3.985846"], ["84267.80", "5.525831"], ["84276.30", "4.982307"], ["84284.80", "5.344656"], ["84293.30", "5.254069"], ["84301.80", "4.529370"], ["84310.30", "5.435244"], ["84318.80", "4.438783"], ["84327.30", "4.801132"], ["84335.80", "4.076433"], ["84344.30", "3.895258"], ["84352.80", "4.710545"]], "bids": [["84065.00", "2.148877"], ["84060.80", "0.015000"], ["84023.00", "4.982307"], ["84014.50", "4.619957"], ["84006.00", "5.163482"], ["83997.50", "5.435244"], ["83989.00", "4.076433"], ["83980.50", "4.529370"], ["83972.00", "4.891720"], ["83963.50", "4.167020"], ["83955.00", "5.616419"], ["83946.50", "4.348195"], ["83938.00", "5.072894"], ["83929.50", "4.801132"], ["83921.00", "3.985846"], ["83912.50", "4.710545"], ["83904.00", "5.525831"], ["83895.50", "5.254069"], ["83887.00", "3.895258"], ["83878.50", "4.257608"], ["83870.00", "5.344656"], ["83861.50", "4.438783"], ["83659.61", "0"]], "checksum": 222295195, "ts": "1742554953485"}], "ts": 1742554953490, "record_time": 1742554953.559658, "EXCHANGE": "BITGET"}
{"action": "update", "arg": {"instType": "SPOT", "channel": "books", "instId": "BTCUSDT"}, "data": [{"asks": [["84147.30", "5.113854"], ["84149.30", "13.457509"], ["84199.80", "5.072894"], ["84208.30", "4.529370"], ["84216.80", "4.801132"], ["84225.30", "5.435244"], ["84233.80", "4.710545"], ["84242.30", "4.982307"], ["84250.80", "5.254069"], ["84259.30", "5.344656"], ["84267.80", "4.619957"], ["84276.30", "5.616419"], ["84284.80", "3.895258"], ["84293.30", "4.076433"], ["84301.80", "3.985846"], ["84310.30", "4.167020"], ["84318.80", "4.257608"], ["84327.30", "4.891720"], ["84335.80", "5.163482"], ["84344.30", "4.438783"], ["84352.80", "5.525831"]], "bids": [["84077.62", "0"], ["84069.00", "0.310053"], ["84067.00", "0.815930"], ["84065.00", "2.147184"], ["84037.00", "0.000015"], ["84023.00", "3.895258"], ["84014.50", "4.710545"], ["84006.00", "5.525831"], ["83997.50", "4.982307"], ["83989.00", "5.616419"], ["83980.50", "5.435244"], ["83972.00", "5.344656"], ["83963.50", "4.891720"], ["83955.00", "4.529370"], ["83946.50", "4.619957"], ["83938.00", "4.257608"], ["83929.50", "4.076433"], ["83921.00", "4.438783"], ["83912.50", "5.254069"], ["83904.00", "5.163482"], ["83895.50", "4.348195"], ["83887.00", "3.985846"], ["83878.50", "4.801132"], ["83870.00", "4.167020"], ["83861.50", "5.072894"], ["83659.61", "0.000454"]], "checksum": -2001986877, "ts": "1742554953689"}], "ts": 1742554953691, "record_time": 1742554953.75506, "EXCHANGE": "BITGET"}
{"action": "update", "arg": {"instType": "SPOT", "channel": "books", "instId": "BTCUSDT"}, "data": [{"asks": [["84089.99", "2.411140"], ["84153.50", "0.038190"], ["84157.70", "0"], ["84191.30", "4.982307"], ["84199.80", "4.438783"], ["84208.30", "4.619957"], ["84216.80", "5.254069"], ["84225.30", "4.167020"], ["84233.80", "5.435244"], ["84242.30", "4.257608"], ["84250.80", "4.348195"], ["84259.30", "3.985846"], ["84267.80", "5.344656"], ["84276.30", "3.895258"], ["84284.80", "4.076433"], ["84293.30", "5.616419"], ["84301.80", "5.525831"], ["84310.30", "4.801132"], ["84318.80", "5.163482"], ["84327.30", "4.529370"], ["84335.80", "4.710545"], ["84344.30", "5.072894"], ["84352.80", "4.891720"], ["84533.01", "0.000591"]], "bids": [["84078.05", "0.041064"], ["84075.00", "0.017174"], ["84073.00", "0.045196"], ["84071.00", "0.118936"], ["84069.00", "0.312989"], ["84067.00", "0.823655"], ["84065.00", "2.167514"], ["84023.00", "4.076433"], ["84014.50", "3.985846"], ["84006.00", "4.891720"], ["83997.50", "4.710545"], ["83989.00", "5.525831"], ["83980.50", "5.072894"], ["83972.00", "4.257608"], ["83963.50", "5.344656"], ["83955.00", "5.163482"], ["83946.50", "4.529370"], ["83938.00", "4.982307"], ["83929.50", "4.167020"], ["83912.50", "4.619957"], ["83904.00", "3.895258"], ["83895.50", "4.801132"], ["83887.00", "5.435244"], ["83878.50", "5.616419"], ["83870.00", "4.348195"], ["83861.50", "5.254069"], ["83659.61", "0"]], "checksum": 518610168, "ts": "1742554953891"}], "ts": 1742554953894, "record_time": 1742554953.916177, "EXCHANGE": "BITGET"}
{"action": "update", "arg": {"instType": "SPOT", "channel": "books", "instId": "BTCUSDT"}, "data": [{"asks": [["84089.99", "2.920540"], ["84100.78", "0"], ["84102.39", "0.119870"], ["84104.08", "0"], ["84105.67", "0.010984"], ["84111.01", "0"], ["84126.51", "0"], ["84191.30", "4.348195"], ["84199.80", "4.619957"], ["84208.30", "5.072894"], ["84216.80", "4.167020"], ["84225.30", "5.435244"], ["84233.80", "5.254069"], ["84242.30", "5.163482"], ["84250.80", "4.891720"], ["84259.30", "4.801132"], ["84267.80", "4.710545"], ["84276.30", "4.529370"], ["84284.80", "4.982307"], ["84301.80", "4.257608"], ["84310.30", "4.438783"], ["84318.80", "5.344656"], ["84327.30", "3.985846"], ["84335.80", "5.525831"], ["84344.30", "4.076433"], ["84352.80", "3.895258"], ["84533.33", "0.003186"], ["84534.53", "0.000461"]], "bids": [["84080.63", "0"], ["84077.00", "0.013980"], ["84071.01", "0"], ["84069.00", "0.313233"], ["84067.00", "0.824299"], ["84065.00", "2.169206"], ["84062.40", "0.004016"], ["84061.19", "0.247509"], ["84059.58", "0"], ["84058.28", "0"], ["84057.92", "0.055638"], ["84056.32", "0"], ["84056.30", "0"], ["84056.20", "0"], ["84055.30", "0.120000"], ["84039.00", "0.000032"], ["84023.00", "3.895258"], ["84014.50", "4.438783"], ["84006.00", "5.072894"], ["83997.50", "3.985846"], ["83989.00", "5.616419"], ["83980.50", "5.525831"], ["83972.00", "4.982307"], ["83955.00", "4.529370"], ["83946.50", "5.163482"], ["83938.00", "4.167020"], ["83929.50", "4.619957"], ["83921.00", "4.348195"], ["83912.50", "5.435244"], ["83904.00", "4.257608"], ["83895.50", "5.254069"], ["83887.00", "4.891720"], ["83878.50", "4.801132"], ["83870.00", "4.076433"], ["83861.50", "4.710545"], ["83659.61", "0.000454"], ["83659.49", "0.000012"], ["83659.44", "0.000613"]], "checksum": -1805819274, "ts": "1742554954090"}], "ts": 1742554954093, "record_time": 1742554954.115556, "EXCHANGE": "BITGET"}
