{"action": "update", "arg": {"instType": "SPOT", "channel": "books", "instId": "BTCUSDT"}, "data": [{"asks": [["83918.03", "1.434884"], ["83918.36", "0.034195"], ["83930.27", "0.013838"], ["83935.11", "0.010995"], ["83937.57", "0"], ["83938.35", "0.017482"], ["83941.10", "0"], ["83949.07", "0"], ["83951.49", "0"], ["83957.80", "0.001550"], ["83959.80", "0.002528"], ["83961.80", "0.006653"], ["83963.80", "0.017509"], ["83964.40", "0"], ["83965.80", "0.046076"], ["83966.40", "0"], ["83967.80", "0.121253"], ["83968.40", "0"], ["83969.80", "0.319085"], ["83970.40", "0"], ["83971.80", "0.839698"], ["83972.40", "0"], ["83973.80", "2.209732"], ["83974.40", "0"], ["83975.80", "5.815084"], ["83976.40", "0"], ["83977.80", "15.302852"], ["83978.00", "0.048930"], ["83978.40", "1.230600"], ["83978.50", "10.615950"], ["83979.30", "1.325370"], ["83979.60", "0.745260"], ["83980.00", "0.042480"], ["83980.20", "0.035730"], ["83980.40", "0"], ["83981.20", "0.107580"], ["83981.90", "0.014550"], ["83982.00", "0.042480"], ["83982.40", "0"], ["83983.70", "0.090000"], ["83983.80", "0.437910"], ["83984.00", "0.042300"], ["83984.10", "5.970450"], ["83984.20", "2.141970"], ["83984.40", "3.686940"], ["83984.50", "0"], ["83984.60", "0"], ["83985.20", "0.323490"], ["83986.00", "0.042300"], ["83986.90", "0.071460"], ["83987.00", "0.250620"], ["83987.40", "0.120000"], ["83987.60", "0.986640"], ["83987.70", "0.285960"], ["83987.90", "2.680320"], ["83988.00", "0.042300"], ["83988.10", "0"], ["83988.60", "0"], ["83988.80", "0.192000"], ["83989.30", "0"], ["83989.70", "0"], ["83989.80", "0.279570"], ["83990.00", "0"], ["83991.10", "0"], ["83991.80", "0"], ["83992.00", "0"], ["83992.20", "0"], ["83992.40", "0"], ["83992.80", "0"], ["83993.60", "0"], ["83995.00", "0"], ["83995.10", "0"], ["83995.20", "0"], ["83995.40", "0"], ["83995.50", "0"], ["84019.80", "4.084756"], ["84026.40", "0"], ["84028.20", "4.447846"], ["84034.80", "0"], ["84036.60", "5.083252"], ["84043.20", "0"], ["84045.00", "4.357073"], ["84051.60", "0"], ["84053.40", "3.903212"], ["84060.00", "0.002000"], ["84061.80", "5.627886"], ["84068.40", "0"], ["84070.20", "4.175529"], ["84076.80", "0"], ["84078.60", "4.810935"], ["84085.20", "0"], ["84087.00", "4.538618"], ["84093.60", "0"], ["84095.40", "4.901707"], ["84102.00", "0"], ["84103.80", "5.264797"], ["84110.40", "0"], ["84112.20", "5.446342"], ["84118.80", "0"], ["84120.60", "5.355569"], ["84127.20", "0"], ["84129.00", "5.537114"], ["84135.60", "0"], ["84137.40", "4.992480"], ["84144.00", "0"], ["84145.80", "4.720163"], ["84152.40", "0"], ["84154.20", "4.266301"], ["84160.80", "0"], ["84162.60", "3.993984"], ["84169.20", "0"], ["84171.00", "4.629390"], ["84177.60", "0"], ["84179.40", "5.174024"], ["84186.00", "0"]], "bids": [["83918.02", "0.283560"], ["83916.40", "0"], ["83915.66", "0"], ["83914.83", "0"], ["83914.71", "0"], ["83914.40", "0"], ["83914.33", "0"], ["83913.80", "0.001023"], ["83912.40", "0"], ["83911.80", "0.001018"], ["83910.41", "0"], ["83910.40", "0"], ["83909.80", "0.001003"], ["83909.63", "0.013838"], ["83908.70", "0.007599"], ["83908.40", "0"], ["83908.21", "0.006542"], ["83907.80", "0.001044"], ["83906.40", "0"], ["83906.38", "0.113969"], ["83905.80", "0.001014"], ["83904.51", "0.009904"], ["83904.40", "0"], ["83904.26", "0"], ["83903.80", "0.002200"], ["83902.40", "0"], ["83901.80", "0.005790"], ["83900.51", "0"], ["83900.40", "0"], ["83900.30", "0"], ["83899.80", "0.015237"], ["83899.77", "0"], ["83899.67", "0"], ["83899.64", "0"], ["83899.63", "0"], ["83898.85", "0"], ["83898.20", "0"], ["83897.80", "0.040097"], ["83897.22", "0"], ["83897.21", "0"], ["83897.20", "0"], ["83897.18", "0"], ["83897.17", "0"], ["83897.08", "0.333582"], ["83897.07", "0"], ["83897.02", "0"], ["83896.83", "0"], ["83896.70", "0"], ["83896.31", "0"], ["83896.00", "0"], ["83895.92", "0"], ["83895.91", "0"], ["83895.90", "0"], ["83895.88", "0"], ["83895.82", "0"], ["83895.80", "0.105518"], ["83895.74", "0"], ["83895.50", "0"], ["83895.44", "0"], ["83895.40", "0"], ["83895.30", "0"], ["83895.20", "0"], ["83894.50", "0"], ["83893.80", "0.277679"], ["83893.78", "0.008279"], ["83893.70", "0"], ["83893.50", "0.001036"], ["83893.43", "0"], ["83893.40", "0.006240"], ["83893.20", "0"], ["83892.80", "0.001002"], ["83892.59", "0"], ["83892.58", "0"], ["83892.50", "0"], ["83892.12", "0.008074"], ["83892.10", "0.001039"], ["83892.00", "0.001009"], ["83891.90", "0.217470"], ["83891.60", "0"], ["83891.29", "0"], ["83891.24", "0"], ["83891.18", "0"], ["83890.50", "0.420390"], ["83890.30", "0.015000"], ["83890.10", "0"], ["83890.08", "0"], ["83890.00", "0"], ["83889.90", "0"], ["83889.75", "0.006599"], ["83889.73", "0.009262"], ["83889.71", "0.008029"], ["83889.69", "0.008530"], ["83889.68", "0.006316"], ["83889.67", "0.005946"], ["83889.64", "0.007202"], ["83889.60", "0"], ["83889.58", "0.009422"], ["83889.57", "0.010062"], ["83889.54", "0.008482"], ["83889.26", "0.008263"], ["83889.25", "0.007828"], ["83889.24", "0.006978"], ["83889.20", "0.017585"], ["83889.11", "0.009567"], ["83889.09", "0.007389"], ["83889.00", "0.070770"], ["83888.79", "0.008605"], ["83888.75", "0"], ["83888.74", "0"], ["83888.71", "0"], ["83888.56", "0"], ["83888.41", "0"], ["83888.30", "0.012420"], ["83888.00", "0.042510"], ["83887.45", "0.055637"], ["83886.90", "0.425100"], ["83886.80", "0.045000"], ["83886.54", "0.018589"], ["83886.50", "0.186450"], ["83886.30", "0.045000"], ["83886.00", "0.042300"], ["83885.72", "0"], ["83885.60", "0.066450"], ["83885.50", "0.487590"], ["83885.30", "0.160920"], ["83885.00", "0.093000"], ["83884.00", "0.042300"], ["83883.61", "0"], ["83883.60", "0.026910"], ["83883.10", "0.007800"], ["83882.55", "0.008778"], ["83882.54", "0.010362"], ["83882.40", "0.489000"], ["83882.15", "0.008556"], ["83882.10", "0.648870"], ["83882.06", "0.005181"], ["83882.05", "0.008109"], ["83882.01", "0.008316"], ["83882.00", "0.042300"], ["83881.87", "0.008933"], ["83881.36", "0.005062"], ["83881.35", "0.005129"], ["83880.90", "0.536970"], ["83876.81", "0.024948"], ["83873.02", "0"], ["83872.90", "0.017482"], ["83871.22", "0"], ["83871.14", "0"], ["83871.01", "0"], ["83869.77", "0"], ["83867.00", "0.000281"], ["83866.34", "0.007448"], ["83866.00", "0.000160"], ["83863.47", "0.008588"], ["83861.16", "0.007260"], ["83861.09", "0.007665"], ["83860.99", "0.007350"], ["83858.40", "0"], ["83851.80", "4.992480"], ["83850.00", "0.002000"], ["83843.40", "4.357073"], ["83841.60", "0"], ["83835.00", "5.537114"], ["83833.20", "0"], ["83826.60", "3.903212"], ["83824.80", "0"], ["83818.20", "4.447846"], ["83816.40", "0"], ["83809.80", "5.627886"], ["83808.00", "0"], ["83801.40", "4.629390"], ["83799.60", "0"], ["83793.00", "4.266301"], ["83791.20", "0"], ["83784.60", "5.446342"], ["83782.80", "0"], ["83776.20", "4.175529"], ["83774.40", "0"], ["83767.80", "5.083252"], ["83766.00", "0"], ["83759.40", "4.810935"], ["83757.60", "0"], ["83751.00", "4.084756"], ["83749.20", "0"], ["83742.60", "4.901707"], ["83740.80", "0"], ["83734.20", "5.264797"], ["83732.40", "0"], ["83725.80", "3.993984"], ["83724.00", "0"], ["83717.40", "5.174024"], ["83715.60", "0"], ["83709.00", "4.720163"], ["83707.20", "0"], ["83700.60", "4.538618"], ["83698.80", "0"], ["83692.20", "5.355569"], ["83444.44", "0"], ["83444.38", "0"], ["83444.27", "0"], ["83443.53", "0"], ["83442.50", "0"], ["83441.56", "0"]], "checksum": 527352715, "ts": "1742577166402"}], "ts": 1742577166405, "record_time": 1742577166.609378, "EXCHANGE": "BITGET"}
{"action": "update", "arg": {"instType": "SPOT", "channel": "books", "instId": "BTCUSDT"}, "data": [{"asks": [["83930.26", "0.004151"], ["83930.27", "0"], ["83931.44", "0.035971"], ["83931.84", "0.119905"], ["83932.86", "0.035972"], ["83933.32", "0.006357"], ["83933.45", "0.006357"], ["83933.99", "0.006357"], ["83934.31", "0.006357"], ["83934.32", "0.006357"], ["83935.05", "0.006357"], ["83936.07", "0.006357"], ["83936.19", "0.006357"], ["83936.30", "0.006357"], ["83936.31", "0.006357"], ["83936.66", "0.016429"], ["83936.71", "0.006357"], ["83937.04", "0.006357"], ["83937.55", "0"], ["83937.56", "0"], ["83937.89", "0"], ["83938.00", "0.013838"], ["83938.02", "0.006357"], ["83938.33", "0.010993"], ["83938.34", "0.006357"], ["83939.17", "0"], ["83939.36", "0.009990"], ["83939.67", "0"], ["83939.75", "0"], ["83940.01", "0.209200"], ["83940.07", "0.119850"], ["83940.39", "0"], ["83940.40", "0"], ["83941.11", "0.119858"], ["83941.38", "0"], ["83941.68", "0.009989"], ["83942.12", "0"], ["83942.23", "0"], ["83942.57", "0"], ["83942.67", "0"], ["83943.01", "0"], ["83943.06", "0"], ["83943.10", "0"], ["83944.05", "0"], ["83944.68", "0"], ["83944.69", "0"], ["83945.39", "0"], ["83946.38", "0"], ["83947.19", "0"], ["83947.98", "0"], ["83951.48", "0"], ["83957.80", "0.001657"], ["83959.80", "0.002703"], ["83961.02", "0"], ["83961.80", "0.007342"], ["83963.80", "0.019320"], ["83965.80", "0.051030"], ["83967.80", "0.134288"], ["83969.80", "0.353389"], ["83971.80", "0.929973"], ["83973.80", "2.447297"], ["83975.80", "6.440256"], ["83977.80", "16.948041"], ["83978.00", "0.048750"], ["83978.40", "0"], ["83978.50", "7.344840"], ["83979.30", "1.325190"], ["83979.60", "0"], ["83980.00", "0.042300"], ["83981.20", "0"], ["83981.40", "0.071970"], ["83981.60", "0.465780"], ["83982.00", "0.042300"], ["83982.60", "0.015150"], ["83983.10", "0.070740"], ["83983.70", "0.378000"], ["83984.10", "3.688080"], ["83984.40", "1.551780"], ["83984.60", "0.204000"], ["83985.40", "0.432000"], ["83985.50", "0.192000"], ["83987.60", "1.850790"], ["83987.70", "0.280500"], ["83988.00", "0"], ["83988.80", "0"], ["83989.80", "0"], ["83999.35", "0.000179"], ["84011.83", "0"], ["84019.80", "4.901707"], ["84036.60", "4.720163"], ["84045.00", "5.083252"], ["84053.40", "4.538618"], ["84061.80", "4.992480"], ["84070.20", "4.266301"], ["84078.60", "4.084756"], ["84087.00", "5.446342"], ["84095.40", "5.174024"], ["84103.80", "4.357073"], ["84112.20", "5.264797"], ["84120.60", "5.627886"], ["84129.00", "5.355569"], ["84137.40", "3.993984"], ["84145.80", "4.629390"], ["84154.20", "3.903212"], ["84162.60", "4.810935"], ["84171.00", "4.175529"], ["84179.40", "5.537114"], ["84341.00", "0.002997"]], "bids": [["83907.80", "0.002434"], ["83905.80", "0.006405"], ["83905.77", "0.163014"], ["83903.80", "0.016855"], ["83902.41", "0"], ["83901.80", "0.044357"], ["83899.80", "0.116728"], ["83897.80", "0.307180"], ["83897.27", "0"], ["83897.08", "0"], ["83896.77", "0"], ["83895.80", "0.808127"], ["83895.53", "0"], ["83895.19", "0"], ["83894.94", "0"], ["83894.53", "0"], ["83894.24", "0"], ["83893.91", "0"], ["83893.80", "2.126650"], ["83893.70", "0.001680"], ["83893.61", "0"], ["83893.21", "0"], ["83892.60", "0.028875"], ["83892.50", "0.855870"], ["83892.39", "0"], ["83892.15", "0"], ["83892.10", "0"], ["83892.05", "0"], ["83892.00", "0.517050"], ["83891.82", "0"], ["83891.57", "0"], ["83891.53", "0"], ["83891.16", "0.089673"], ["83890.72", "0.247543"], ["83890.51", "0"], ["83890.50", "0.420210"], ["83890.15", "0"], ["83890.13", "0"], ["83890.10", "0.070950"], ["83889.23", "0.083637"], ["83889.17", "0"], ["83889.00", "0.070560"], ["83888.84", "0.017826"], ["83888.64", "0.018273"], ["83888.51", "0.005950"], ["83888.31", "0"], ["83888.30", "0"], ["83888.16", "0.015750"], ["83888.00", "0.042300"], ["83887.83", "0.016433"], ["83887.55", "0.006572"], ["83887.15", "0.017124"], ["83887.11", "0"], ["83886.72", "0"], ["83886.56", "0.007347"], ["83886.50", "0.252360"], ["83886.34", "0.017114"], ["83885.80", "0.007956"], ["83885.78", "0.009010"], ["83885.60", "0.489300"], ["83885.52", "0.008200"], ["83885.50", "0"], ["83885.47", "0.025199"], ["83885.18", "0.017376"], ["83885.00", "0"], ["83884.49", "0.008290"], ["83883.80", "0.012674"], ["83883.78", "0.051846"], ["83883.14", "0.018549"], ["83882.10", "0"], ["83882.01", "0.277157"], ["83882.00", "0"], ["83881.03", "0.223055"], ["83880.90", "0"], ["83880.42", "0.021166"], ["83851.80", "4.629390"], ["83843.68", "0"], ["83843.40", "5.627886"], ["83835.00", "4.810935"], ["83831.23", "0.000172"], ["83826.60", "5.264797"], ["83818.20", "4.992480"], ["83809.80", "4.447846"], ["83801.40", "3.903212"], ["83793.00", "5.083252"], ["83784.60", "4.720163"], ["83776.20", "5.537114"], ["83767.80", "4.538618"], ["83759.40", "4.266301"], ["83751.00", "4.175529"], ["83734.20", "4.357073"], ["83725.80", "4.084756"], ["83717.40", "3.993984"], ["83709.00", "5.174024"], ["83700.60", "5.355569"], ["83692.20", "5.446342"], ["83444.44", "0.000105"], ["83444.38", "0.000025"], ["83444.27", "0.000028"], ["83443.53", "0.000161"], ["83442.50", "0.000113"], ["83441.56", "0.000024"]], "checksum": 338010454, "ts": "1742577166621"}], "ts": 1742577166624, "record_time": 1742577166.819182, "EXCHANGE": "BITGET"}
{"action": "update", "arg": {"instType": "SPOT", "channel": "books", "instId": "BTCUSDT"}, "data": [{"asks": [["83928.96", "3.187643"], ["83930.26", "0.046244"], ["84019.80", "5.355569"], ["84028.20", "5.174024"], ["84036.60", "4.266301"], ["84045.00", "4.357073"], ["84053.40", "4.901707"], ["84061.80", "3.993984"], ["84070.20", "4.538618"], ["84078.60", "3.903212"], ["84087.00", "4.447846"], ["84095.40", "4.992480"], ["84103.80", "4.720163"], ["84112.20", "5.537114"], ["84120.60", "4.175529"], ["84129.00", "4.084756"], ["84137.40", "5.264797"], ["84145.80", "4.810935"], ["84154.20", "5.083252"], ["84162.60", "4.629390"], ["84171.00", "5.627886"], ["84179.40", "5.446342"], ["84341.00", "0"]], "bids": [["83918.02", "0.331160"], ["83909.64", "0.009124"], ["83907.80", "0.001557"], ["83905.80", "0.004099"], ["83903.80", "0.010786"], ["83901.80", "0.028384"], ["83899.80", "0.074695"], ["83897.80", "0.196566"], ["83896.64", "0.764714"], ["83895.80", "0.517278"], ["83893.80", "1.361260"], ["83888.88", "0.005601"], ["83888.52", "0.009326"], ["83888.00", "0.057300"], ["83885.60", "0.298380"], ["83881.33", "0.004861"], ["83881.17", "0.005612"], ["83851.80", "4.175529"], ["83843.40", "3.903212"], ["83835.00", "4.538618"], ["83826.60", "4.629390"], ["83818.20", "4.810935"], ["83809.80", "5.083252"], ["83801.40", "5.264797"], ["83793.00", "4.901707"], ["83784.60", "4.357073"], ["83776.20", "5.174024"], ["83767.80", "5.446342"], ["83759.40", "4.720163"], ["83751.00", "4.447846"], ["83742.60", "4.992480"], ["83734.20", "5.355569"], ["83725.80", "4.266301"], ["83717.40", "4.084756"], ["83709.00", "5.627886"], ["83700.60", "3.993984"], ["83692.20", "5.537114"], ["83444.44", "0"], ["83444.38", "0"], ["83444.27", "0"], ["83443.53", "0"], ["83442.50", "0"], ["83441.56", "0"]], "checksum": 1594297038, "ts": "1742577166823"}], "ts": 1742577166829, "record_time": 1742577167.022388, "EXCHANGE": "BITGET"}
{"action": "update", "arg": {"instType": "SPOT", "channel": "books", "instId": "BTCUSDT"}, "data": [{"asks": [["83928.95", "1.003056"], ["83930.26", "0"], ["83935.64", "0.006356"], ["83935.86", "0.006357"], ["83941.58", "0"], ["83948.53", "0.177312"], ["83980.20", "0"], ["83983.10", "0"], ["83988.00", "0.042300"], ["83988.80", "0.180000"], ["84019.80", "4.992480"], ["84028.20", "4.447846"], ["84036.60", "4.538618"], ["84045.00", "4.720163"], ["84053.40", "5.174024"], ["84061.80", "5.083252"], ["84070.20", "5.355569"], ["84078.60", "4.175529"], ["84087.00", "5.446342"], ["84095.40", "4.901707"], ["84103.80", "4.357073"], ["84112.20", "4.629390"], ["84120.60", "5.537114"], ["84129.00", "5.264797"], ["84137.40", "3.993984"], ["84145.80", "4.084756"], ["84154.20", "4.810935"], ["84162.60", "5.627886"], ["84171.00", "4.266301"], ["84179.40", "3.903212"], ["84340.46", "0"], ["84340.72", "0"]], "bids": [["83918.02", "0.749560"], ["83911.92", "0.038260"], ["83909.80", "0.001145"], ["83907.80", "0.003012"], ["83905.80", "0.007925"], ["83903.80", "0.020856"], ["83901.80", "0.054886"], ["83900.11", "0.083865"], ["83899.80", "0.144435"], ["83897.80", "0.380092"], ["83895.80", "1.000242"], ["83893.80", "2.632346"], ["83893.70", "0.440790"], ["83893.08", "0"], ["83892.50", "0"], ["83892.00", "0.000121"], ["83891.30", "0.207810"], ["83887.36", "0.007141"], ["83885.60", "0.592500"], ["83885.40", "1.350000"], ["83882.10", "0.648870"], ["83882.00", "0.042300"], ["83851.80", "4.084756"], ["83843.40", "4.629390"], ["83835.00", "3.993984"], ["83826.60", "5.537114"], ["83818.20", "4.447846"], ["83809.80", "5.446342"], ["83793.00", "4.992480"], ["83776.20", "4.266301"], ["83767.80", "4.175529"], ["83759.40", "4.810935"], ["83751.00", "5.174024"], ["83742.60", "4.538618"], ["83734.20", "5.083252"], ["83725.80", "5.355569"], ["83717.40", "4.901707"], ["83709.00", "3.903212"], ["83700.60", "4.720163"], ["83692.20", "5.627886"], ["83447.31", "0"], ["83447.17", "0"], ["83446.43", "0"], ["83445.30", "0"], ["83445.16", "0"]], "checksum": 2017164726, "ts": "1742577167034"}], "ts": 1742577167038, "record_time": 1742577167.229802, "EXCHANGE": "BITGET"}
{"action": "update", "arg": {"instType": "SPOT", "channel": "books", "instId": "BTCUSDT"}, "data": [{"asks": [["83918.03", "1.241499"], ["83932.85", "0.039997"], ["83940.00", "0.136708"], ["83957.80", "0.001684"], ["83959.80", "0.002748"], ["83961.80", "0.007232"], ["83962.10", "0.598334"], ["83963.80", "0.019031"], ["83965.80", "0.050082"], ["83967.80", "0.131793"], ["83969.80", "0.346826"], ["83971.80", "0.912700"], ["83973.80", "2.401842"], ["83975.80", "6.320637"], ["83977.80", "16.633255"], ["83978.50", "2.831700"], ["83984.10", "2.338080"], ["83984.20", "0"], ["83984.90", "2.359860"], ["83985.70", "1.072110"], ["83986.20", "1.350000"], ["83986.90", "0"], ["83987.40", "0"], ["84019.80", "5.174024"], ["84028.20", "5.627886"], ["84036.60", "3.993984"], ["84045.00", "5.083252"], ["84053.40", "5.446342"], ["84061.80", "4.992480"], ["84070.20", "4.447846"], ["84078.60", "4.266301"], ["84087.00", "3.903212"], ["84095.40", "5.355569"], ["84103.80", "5.537114"], ["84112.20", "5.264797"], ["84120.60", "4.720163"], ["84129.00", "4.175529"], ["84137.40", "4.629390"], ["84145.80", "4.538618"], ["84154.20", "4.357073"], ["84162.60", "4.810935"], ["84171.00", "4.084756"], ["84179.40", "4.901707"], ["84340.00", "0"]], "bids": [["83912.51", "0.078280"], ["83907.80", "0.003142"], ["83905.80", "0.008266"], ["83903.80", "0.021754"], ["83901.80", "0.057247"], ["83899.80", "0.150651"], ["83897.80", "0.396449"], ["83896.65", "0.384598"], ["83895.80", "1.043286"], ["83894.01", "1.330383"], ["83893.80", "2.745490"], ["83891.00", "0.009000"], ["83890.30", "0"], ["83888.70", "0.160920"], ["83885.30", "0"], ["83882.10", "1.204050"], ["83867.00", "0.000121"], ["83851.80", "5.264797"], ["83843.40", "4.810935"], ["83835.00", "4.720163"], ["83826.60", "4.266301"], ["83818.20", "3.993984"], ["83809.80", "4.357073"], ["83807.65", "0"], ["83801.40", "4.629390"], ["83794.74", "0.125833"], ["83793.00", "4.447846"], ["83784.60", "5.174024"], ["83776.20", "4.992480"], ["83759.40", "5.083252"], ["83751.00", "5.627886"], ["83742.60", "4.901707"], ["83734.20", "5.446342"], ["83717.40", "5.537114"], ["83709.00", "4.084756"], ["83700.60", "4.538618"], ["83692.20", "3.903212"], ["83448.00", "0"], ["83447.32", "0"]], "checksum": -1438691370, "ts": "1742577167237"}], "ts": 1742577167241, "record_time": 1742577167.434598, "EXCHANGE": "BITGET"}
{"action": "update", "arg": {"instType": "SPOT", "channel": "books", "instId": "BTCUSDT"}, "data": [{"asks": [["83918.03", "1.225684"], ["83963.80", "0.018775"], ["83965.80", "0.049409"], ["83967.80", "0.130025"], ["83969.80", "0.342171"], ["83971.80", "0.900448"], ["83973.80", "2.369601"], ["83975.80", "6.235793"], ["83977.80", "16.409980"], ["83988.80", "0.372000"], ["84019.80", "4.720163"], ["84028.20", "4.901707"], ["84036.60", "4.266301"], ["84045.00", "3.993984"], ["84053.40", "5.355569"], ["84061.80", "5.627886"], ["84070.20", "5.174024"], ["84078.60", "4.992480"], ["84095.40", "4.084756"], ["84112.20", "4.357073"], ["84120.60", "5.264797"], ["84129.00", "4.538618"], ["84137.40", "5.083252"], ["84145.80", "4.629390"], ["84154.20", "4.175529"], ["84171.00", "4.447846"], ["84179.40", "5.446342"]], "bids": [["83912.12", "0.038260"], ["83911.92", "0"], ["83899.80", "0.150791"], ["83897.80", "0.396819"], ["83895.80", "1.044262"], ["83893.80", "2.748057"], ["83890.51", "0.114147"], ["83868.00", "0"], ["83851.80", "4.810935"], ["83843.40", "5.446342"], ["83835.00", "4.175529"], ["83826.60", "4.629390"], ["83818.20", "4.992480"], ["83809.80", "4.901707"], ["83801.40", "3.903212"], ["83793.00", "4.357073"], ["83784.60", "4.266301"], ["83776.20", "4.084756"], ["83767.80", "4.447846"], ["83759.40", "3.993984"], ["83751.00", "4.720163"], ["83742.60", "4.538618"], ["83734.20", "5.537114"], ["83725.80", "5.083252"], ["83717.40", "5.174024"], ["83709.00", "5.627886"], ["83700.60", "5.264797"], ["83692.20", "5.355569"]], "checksum": -143221239, "ts": "1742577167449"}], "ts": 1742577167452, "record_time": 1742577167.645002, "EXCHANGE": "BITGET"}
{"action": "update", "arg": {"instType": "SPOT", "channel": "books", "instId": "BTCUSDT"}, "data": [{"asks": [["84019.80", "4.810935"], ["84028.20", "5.083252"], ["84036.60", "4.901707"], ["84045.00", "4.357073"], ["84053.40", "4.084756"], ["84061.80", "5.174024"], ["84070.20", "3.903212"], ["84087.00", "4.629390"], ["84095.40", "5.355569"], ["84103.80", "5.627886"], ["84112.20", "5.537114"], ["84120.60", "4.175529"], ["84137.40", "4.447846"], ["84145.80", "3.993984"], ["84154.20", "5.446342"], ["84162.60", "5.264797"], ["84171.00", "4.266301"], ["84179.40", "4.720163"], ["84271.52", "1.597331"], ["84278.17", "0"]], "bids": [["83909.80", "0.001728"], ["83907.80", "0.004547"], ["83905.80", "0.011967"], ["83903.80", "0.031491"], ["83901.80", "0.082872"], ["83899.80", "0.218083"], ["83897.80", "0.573902"], ["83895.80", "1.510269"], ["83893.80", "3.974392"], ["83851.80", "5.537114"], ["83843.40", "4.720163"], ["83835.00", "4.538618"], ["83826.60", "4.266301"], ["83818.20", "4.084756"], ["83809.80", "5.083252"], ["83801.40", "4.175529"], ["83793.00", "4.629390"], ["83784.60", "3.903212"], ["83776.20", "4.810935"], ["83767.80", "4.992480"], ["83759.40", "5.446342"], ["83751.00", "4.447846"], ["83742.60", "5.355569"], ["83734.20", "4.901707"], ["83725.80", "4.357073"], ["83717.40", "5.627886"], ["83709.00", "5.264797"], ["83700.60", "3.993984"], ["83692.20", "5.174024"], ["83606.62", "0"], ["83600.03", "1.720668"]], "checksum": 764868356, "ts": "1742577167672"}], "ts": 1742577167676, "record_time": 1742577167.868337, "EXCHANGE": "BITGET"}
{"action": "update", "arg": {"instType": "SPOT", "channel": "books", "instId": "BTCUSDT"}, "data": [{"asks": [["83957.80", "0.001482"], ["83959.80", "0.002419"], ["83961.80", "0.006364"], ["83963.80", "0.016747"], ["83965.80", "0.044072"], ["83967.80", "0.115980"], ["83969.80", "0.305210"], ["83971.80", "0.803185"], ["83973.80", "2.113643"], ["83975.80", "5.562219"], ["83977.80", "14.637158"], ["84019.80", "4.266301"], ["84028.20", "5.264797"], ["84045.00", "4.629390"], ["84053.40", "4.992480"], ["84070.20", "4.175529"], ["84078.60", "4.538618"], ["84087.00", "3.903212"], ["84095.40", "4.084756"], ["84103.80", "5.083252"], ["84112.20", "4.810935"], ["84120.60", "4.720163"], ["84129.00", "5.627886"], ["84137.40", "5.537114"], ["84145.80", "5.446342"], ["84154.20", "3.993984"], ["84162.60", "5.355569"], ["84171.00", "4.357073"], ["84179.40", "4.447846"]], "bids": [["83912.36", "0.038260"], ["83912.12", "0"], ["83900.11", "0.116399"], ["83868.00", "0.000160"], ["83851.80", "4.357073"], ["83843.40", "4.992480"], ["83835.00", "4.810935"], ["83826.60", "5.264797"], ["83818.20", "4.266301"], ["83809.80", "4.901707"], ["83801.40", "5.446342"], ["83793.00", "3.903212"], ["83784.60", "5.174024"], ["83776.20", "4.720163"], ["83767.80", "5.083252"], ["83759.40", "4.175529"], ["83751.00", "4.084756"], ["83742.60", "5.627886"], ["83734.20", "5.355569"], ["83725.80", "3.993984"], ["83717.40", "5.537114"], ["83709.00", "4.629390"], ["83700.60", "4.447846"], ["83692.20", "4.538618"], ["83448.14", "0"]], "checksum": 1058898890, "ts": "1742577167884"}], "ts": 1742577167887, "record_time": 1742577168.079565, "EXCHANGE": "BITGET"}
{"event": "subscribe", "arg": {"instType": "SPOT", "channel": "books", "instId": "BTCUSDT"}, "record_time": 1742584881.356451, "EXCHANGE": "BITGET"}
{"action": "snapshot", "arg": {"instType": "SPOT", "channel": "books", "instId": "BTCUSDT"}, "data": [{"asks": [["84057.01", "1.679778"], ["84058.01", "0.099305"], ["84059.80", "0.327210"], ["84064.01", "0.511997"], ["84065.00", "0.203708"], ["84065.01", "0.209200"], ["84065.37", "0.314026"], ["84069.99", "0.007736"], ["84070.00", "0.014743"], ["84074.53", "0.018026"], ["84074.54", "0.060087"], ["84076.32", "0.109519"], ["84077.01", "0.220195"], ["84079.21", "0.035957"], ["84080.24", "0.037037"], ["84080.62", "0.035972"], ["84081.12", "0.006357"], ["84081.27", "0.006357"], ["84081.29", "0.006357"], ["84081.93", "0.006357"], ["84082.13", "0.006357"], ["84082.80", "0.006357"], ["84082.90", "0.006356"], ["84083.10", "0.006357"], ["84083.65", "0.006357"], ["84083.68", "0.016429"], ["84083.84", "0.006357"], ["84084.07", "0.006357"], ["84084.12", "0.006357"], ["84084.28", "0.119901"], ["84084.61", "0.006357"], ["84084.75", "0.176046"], ["84084.76", "0.006357"], ["84084.83", "0.016429"], ["84084.87", "0.183834"], ["84085.84", "0.006357"], ["84085.90", "0.006357"], ["84086.01", "0.209200"], ["84086.12", "0.010993"], ["84086.33", "0.009990"], ["84087.74", "0.017452"], ["84088.74", "0.015895"], ["84088.86", "0.119858"], ["84089.63", "0.009989"], ["84089.73", "0.119905"], ["84091.36", "0.006356"], ["84091.50", "0.001029"], ["84093.50", "0.001181"], ["84093.73", "0.015896"], ["84093.77", "0.065200"], ["84094.41", "0.062760"], ["84094.42", "0.209200"], ["84094.48", "0.010988"], ["84095.50", "0.003108"], ["84097.50", "0.008180"], ["84099.50", "0.021651"], ["84100.42", "0.713432"], ["84101.50", "0.056976"], ["84103.50", "0.149937"], ["84105.50", "0.394570"], ["84106.89", "0.024290"], ["84107.22", "0.067994"], ["84107.23", "0.209200"], ["84107.50", "1.038343"], ["84107.98", "0.020428"], ["84108.15", "0.000179"], ["84109.50", "2.732482"], ["84109.78", "0.020107"], ["84111.50", "7.190741"], ["84111.70", "0.001042"], ["84111.90", "0.006900"], ["84112.00", "4.885200"], ["84112.10", "5.125890"], ["84112.54", "0.001598"], ["84113.10", "0.035670"], ["84113.70", "0.420180"], ["84113.80", "1.758480"], ["84114.10", "0.067980"], ["84114.15", "0.001598"], ["84114.29", "1.054852"], ["84114.60", "0.657150"], ["84114.80", "1.426470"], ["84114.90", "1.079040"], ["84116.00", "0.022650"], ["84116.10", "0.067800"], ["84117.30", "0.066840"], ["84118.10", "0.035670"], ["84118.20", "1.131150"], ["84118.50", "1.059600"], ["84118.90", "0.269760"], ["84119.50", "0.318030"], ["84120.00", "0.211244"], ["84120.10", "0.067800"], ["84120.40", "1.096410"], ["84120.70", "0.472890"], ["84120.80", "0.421770"], ["84121.00", "1.600620"], ["84121.10", "0.480000"], ["84121.80", "0.071340"], ["84122.10", "0.199800"], ["84122.70", "0.120000"], ["84123.80", "0.144000"], ["84124.01", "1.783081"], ["84124.10", "0.035670"], ["84132.00", "0.063376"], ["84132.01", "0.209200"], ["84139.00", "0.000976"], ["84142.86", "0.000514"], ["84146.26", "0.209200"], ["84150.00", "0.002000"], ["84153.50", "4.259522"], ["84154.67", "0.209200"], ["84155.00", "0.000253"], ["84162.00", "4.440778"], ["84163.08", "0.209200"], ["84170.50", "5.347059"], ["84170.80", "0.196628"], ["84171.95", "0.209200"], ["84176.54", "0.071668"], ["84177.92", "0.071678"], ["84179.00", "4.168894"], ["84180.00", "0.002000"], ["84180.37", "0.209200"], ["84187.50", "5.618943"], ["84196.00", "4.984547"], ["84197.21", "0.209200"], ["84198.38", "0.057335"], ["84200.00", "0.000017"], ["84204.50", "5.075175"], ["84207.58", "0.209200"], ["84207.76", "0.125593"], ["84210.00", "0.002000"], ["84213.00", "5.165803"], ["84215.98", "0.209200"], ["84221.50", "4.893918"], ["84230.00", "3.987637"], ["84232.04", "0.209200"], ["84238.50", "4.078265"], ["84240.00", "0.002000"], ["84240.46", "0.209200"], ["84247.00", "5.528315"], ["84248.21", "0.011010"], ["84248.86", "0.209200"], ["84250.00", "0.000023"], ["84251.91", "0.162679"], ["84255.50", "3.897009"], ["84257.26", "0.209200"], ["84264.00", "4.350150"], ["84265.67", "0.209200"], ["84270.00", "0.002000"], ["84272.50", "5.256431"], ["84274.08", "0.209200"], ["84280.00", "0.000269"], ["84281.00", "4.622034"], ["84282.49", "0.209200"], ["84285.00", "0.001450"], ["84289.50", "4.531406"], ["84290.00", "0.000269"], ["84290.90", "0.209200"], ["84298.00", "5.437687"], ["84299.31", "0.209200"], ["84299.50", "0.296078"], ["84299.90", "0.001450"], ["84300.00", "0.002302"], ["84302.80", "0.300112"], ["84306.50", "4.803290"], ["84307.72", "0.209200"], ["84310.00", "0.000268"], ["84310.35", "0.000146"], ["84315.00", "4.712662"], ["84316.13", "0.209200"], ["84318.59", "0.000027"], ["84319.61", "0.027677"], ["84320.00", "0.000268"], ["84326.00", "0.000237"], ["84327.10", "0.001444"], ["84329.80", "0.001720"], ["84330.00", "0.002268"], ["84332.86", "0.209200"], ["84333.33", "0.000014"], ["84340.00", "0.000268"], ["84341.27", "0.209200"], ["84344.90", "0.301368"], ["84348.27", "0.012402"], ["84349.68", "0.209200"], ["84350.00", "0.000861"], ["84350.79", "0.000033"], ["84358.09", "0.209200"], ["84360.00", "0.002130"], ["84363.63", "0.041544"], ["84363.64", "0.000062"], ["84366.14", "0.000162"], ["84366.15", "0.000061"], ["84366.19", "0.000022"], ["84367.10", "0.000014"], ["84370.00", "0.000320"], ["84375.00", "0.000191"], ["84376.31", "0.000016"], ["84380.00", "0.000268"], ["84383.69", "0.000248"], ["84387.50", "0.006969"], ["84387.76", "0.000024"], ["84389.61", "0.000088"], ["84390.00", "0.002521"], ["84390.01", "0.000387"], ["84391.30", "0.000018"], ["84391.46", "0.000242"], ["84393.22", "0.000029"], ["84393.31", "0.000050"], ["84393.33", "0.000008"], ["84393.94", "0.000067"], ["84394.47", "0.000274"], ["84395.60", "0.000024"], ["84396.55", "0.000016"], ["84397.40", "0.000772"], ["84397.59", "0.000008"], ["84397.69", "0.000275"], ["84398.26", "0.000068"], ["84399.54", "0.000030"], ["84399.91", "0.000018"], ["84399.99", "0.000022"], ["84400.00", "0.019868"], ["84400.18", "0.000024"], ["84401.16", "0.000896"], ["84402.40", "0.001273"], ["84403.39", "0.000023"], ["84403.57", "0.000010"], ["84403.76", "0.000099"], ["84404.26", "0.000137"], ["84404.28", "0.000039"], ["84405.00", "0.000520"], ["84406.06", "0.000008"], ["84406.25", "0.000150"], ["84406.83", "0.000064"], ["84407.50", "0.000031"], ["84408.98", "0.000162"], ["84409.01", "0.000036"], ["84409.06", "0.000021"], ["84409.72", "0.003619"], ["84410.00", "0.000328"], ["84411.11", "0.000361"], ["84411.43", "0.000008"], ["84411.76", "0.000101"], ["84411.77", "0.000020"], ["84412.39", "1.651224"], ["84412.50", "0.000049"], ["84413.04", "0.000010"], ["84413.24", "0.000009"], ["84413.33", "0.000073"], ["84413.79", "0.000135"], ["84413.97", "0.000013"], ["84414.41", "0.000061"], ["84415.09", "0.000008"], ["84416.67", "0.000355"], ["84418.34", "0.000046"], ["84419.36", "0.000109"], ["84419.69", "0.000023"], ["84420.00", "0.003801"], ["84420.17", "0.041940"], ["84422.71", "0.000010"], ["84423.08", "0.000067"], ["84423.53", "0.000105"], ["84424.00", "0.000022"], ["84424.12", "0.000146"], ["84424.24", "0.000175"], ["84424.43", "0.000014"], ["84425.00", "0.002205"], ["84425.57", "0.000143"], ["84425.69", "0.000314"], ["84426.68", "0.000101"], ["84427.08", "0.000014"], ["84427.92", "0.000323"], ["84427.93", "0.000441"], ["84428.57", "0.000913"], ["84429.82", "0.000022"], ["84430.50", "0.000113"], ["84430.77", "0.000290"], ["84431.23", "0.000039"], ["84432.43", "0.000008"], ["84432.50", "0.000020"], ["84433.33", "0.000512"], ["84434.78", "0.000008"], ["84435.00", "0.000403"], ["84435.26", "0.000161"], ["84436.26", "0.000009"], ["84437.14", "0.000017"], ["84437.50", "0.000725"], ["84437.75", "0.000013"], ["84438.44", "0.000176"], ["84439.03", "0.000033"], ["84440.00", "0.118910"], ["84440.24", "0.000085"], ["84442.54", "0.000096"], ["84443.07", "0.000423"], ["84443.95", "0.000016"], ["84444.00", "0.000178"], ["84444.25", "0.000013"], ["84444.41", "0.000371"], ["84444.44", "0.001607"], ["84444.92", "0.000022"], ["84446.04", "0.000016"], ["84446.38", "0.000013"], ["84446.43", "0.000036"], ["84447.80", "0.000718"], ["84447.82", "0.001130"], ["84448.75", "0.000066"], ["84448.98", "0.000085"], ["84449.11", "0.000028"], ["84449.34", "0.000010"], ["84450.00", "0.011281"], ["84450.60", "0.209200"], ["84451.88", "0.000010"], ["84452.66", "0.000009"], ["84453.76", "0.000054"], ["84454.43", "0.000061"], ["84454.53", "0.000019"], ["84454.55", "0.000083"], ["84454.60", "0.000093"], ["84455.31", "0.000028"], ["84456.14", "0.000033"], ["84456.52", "0.002633"], ["84457.00", "0.000009"], ["84458.06", "0.000020"], ["84458.72", "0.000072"], ["84458.82", "0.000071"], ["84458.97", "0.000153"], ["84459.08", "0.000008"], ["84459.22", "0.000188"], ["84459.69", "0.000051"], ["84460.00", "0.001293"], ["84460.23", "0.000010"], ["84460.49", "0.000009"], ["84460.86", "0.000040"], ["84460.87", "0.000069"], ["84460.91", "0.000012"], ["84461.00", "0.000008"], ["84461.88", "0.000062"], ["84462.50", "0.000076"], ["84463.79", "0.000052"], ["84464.28", "0.000008"], ["84465.00", "0.000665"], ["84465.83", "0.000016"], ["84466.67", "0.000166"], ["84468.09", "0.000009"], ["84470.00", "0.000269"], ["84470.34", "0.000017"], ["84470.59", "0.000080"], ["84473.14", "0.000126"], ["84473.68", "0.000192"], ["84475.00", "0.007068"], ["84475.81", "0.000039"], ["84476.97", "0.000063"], ["84477.61", "0.000095"], ["84477.65", "0.000735"], ["84477.67", "0.000008"], ["84478.74", "0.000036"], ["84479.37", "0.004857"], ["84480.00", "0.005797"], ["84481.00", "0.000069"], ["84481.77", "0.000011"], ["84482.67", "0.000133"], ["84482.76", "0.000016"], ["84483.71", "0.000653"], ["84485.20", "0.000537"], ["84485.39", "0.000020"], ["84485.71", "0.000128"], ["84485.98", "0.000034"], ["84486.00", "0.000597"], ["84486.49", "0.000009"], ["84486.79", "0.000080"], ["84486.82", "0.000135"], ["84487.00", "0.000119"], ["84487.16", "0.000035"], ["84487.32", "0.000024"], ["84487.95", "0.000008"], ["84489.36", "0.000137"], ["84489.39", "0.000039"], ["84489.80", "0.000010"], ["84490.00", "0.007510"], ["84490.13", "0.000093"], ["84490.32", "0.000008"], ["84490.91", "0.000018"], ["84491.26", "0.000008"], ["84491.87", "0.000019"], ["84492.06", "0.000009"], ["84495.48", "0.000504"], ["84496.43", "0.000273"], ["84496.73", "0.000043"], ["84497.14", "0.000008"], ["84497.26", "0.000010"], ["84500.00", "0.033841"], ["84500.03", "0.000010"], ["84500.04", "0.000023"], ["84500.11", "0.000012"], ["84500.49", "0.000081"], ["84501.01", "0.000044"], ["84501.24", "0.000010"], ["84501.28", "0.000019"], ["84501.99", "0.000009"], ["84504.50", "0.000061"], ["84504.74", "0.000013"], ["84506.54", "0.000008"], ["84506.67", "0.000008"], ["84508.00", "0.007441"], ["84508.37", "0.000050"], ["84508.46", "0.000013"], ["84508.47", "0.000023"], ["84510.00", "0.002000"], ["84510.01", "0.000372"], ["84510.34", "0.000135"], ["84510.37", "0.000095"], ["84510.67", "0.000143"], ["84512.00", "0.000012"], ["84512.61", "0.041940"], ["84512.95", "0.000023"], ["84514.29", "0.000059"], ["84515.38", "0.000275"], ["84516.21", "0.000013"], ["84516.67", "0.000536"], ["84516.79", "0.000144"], ["84517.42", "0.000082"], ["84517.54", "0.000022"], ["84517.86", "0.000016"], ["84518.98", "0.000029"], ["84520.00", "0.000318"], ["84520.50", "0.000238"], ["84520.67", "0.002384"], ["84521.74", "0.000364"], ["84521.85", "0.000033"], ["84522.06", "0.000041"], ["84523.08", "0.000015"], ["84523.48", "0.000015"], ["84523.81", "0.000024"], ["84524.00", "0.000035"], ["84524.83", "0.000009"], ["84525.00", "0.000010"], ["84525.82", "0.000099"], ["84527.47", "0.000608"], ["84528.57", "0.000008"], ["84530.00", "0.000031"], ["84533.01", "0.000591"], ["84533.33", "0.003177"], ["84534.53", "0.000461"], ["84535.32", "0.000039"], ["84536.36", "0.000053"], ["84537.04", "0.000958"], ["84538.75", "0.000011"], ["84540.00", "0.000021"], ["84540.54", "0.000184"], ["84540.94", "0.000106"], ["84540.97", "0.000065"], ["84540.99", "0.000354"], ["84541.67", "0.000198"], ["84542.37", "0.001213"], ["84543.27", "0.000067"], ["84543.35", "0.000023"], ["84543.43", "0.000423"], ["84543.63", "0.000010"], ["84543.64", "0.000018"], ["84543.86", "0.000033"], ["84543.93", "0.000010"], ["84544.64", "0.000036"], ["84545.16", "0.000020"], ["84545.44", "0.000008"], ["84545.45", "0.001823"], ["84545.46", "0.000056"], ["84545.63", "0.000008"], ["84547.06", "0.000071"], ["84549.54", "0.000019"], ["84549.65", "0.000030"], ["84549.91", "0.002462"], ["84549.96", "0.000012"], ["84550.00", "0.006911"], ["84550.60", "0.000096"], ["84551.02", "0.000085"], ["84552.59", "0.000009"], ["84552.95", "0.000009"], ["84553.04", "0.001768"], ["84553.07", "0.000011"], ["84553.08", "0.000012"], ["84554.00", "0.000113"], ["84555.08", "0.000022"], ["84555.35", "0.000016"], ["84555.54", "0.000075"], ["84555.56", "0.000130"], ["84555.60", "0.000016"], ["84556.52", "0.000013"], ["84556.79", "0.000066"], ["84557.29", "0.000014"], ["84558.82", "0.000089"], ["84559.10", "0.000036"], ["84559.47", "0.000010"], ["84560.00", "0.000265"], ["84561.11", "0.000134"], ["84561.58", "0.003678"], ["84562.50", "0.006969"], ["84565.22", "0.003438"], ["84566.67", "0.001061"], ["84567.79", "0.000009"], ["84568.60", "0.000018"]], "bids": [["84057.00", "0.000281"], ["84056.00", "0.000281"], ["84055.00", "0.000281"], ["84054.00", "0.000281"], ["84053.00", "0.000281"], ["84052.94", "0.010367"], ["84052.00", "0.000281"], ["84051.00", "0.000281"], ["84050.00", "0.000281"], ["84049.00", "0.000281"], ["84048.00", "0.000281"], ["84047.30", "0.001022"], ["84047.00", "0.000281"], ["84046.77", "0.010000"], ["84046.00", "0.000281"], ["84045.30", "0.001042"], ["84045.00", "0.000281"], ["84044.00", "0.000281"], ["84043.30", "0.001033"], ["84043.00", "0.000281"], ["84042.00", "0.000281"], ["84041.30", "0.001024"], ["84041.01", "0.004030"], ["84041.00", "0.000281"], ["84040.00", "0.000281"], ["84039.31", "0.111681"], ["84039.30", "0.001730"], ["84039.18", "0.209200"], ["84039.00", "0.000281"], ["84038.86", "0.089519"], ["84038.00", "0.000281"], ["84037.30", "0.004552"], ["84037.00", "0.000281"], ["84036.97", "0.009888"], ["84036.91", "0.083486"], ["84036.72", "0.017794"], ["84036.33", "0.005939"], ["84036.23", "0.018239"], ["84036.01", "0.378308"], ["84036.00", "0.000281"], ["84035.70", "0.015722"], ["84035.56", "0.016403"], ["84035.30", "0.011978"], ["84035.22", "0.006560"], ["84035.00", "0.000281"], ["84034.65", "0.017092"], ["84034.52", "0.007128"], ["84034.24", "0.007333"], ["84034.09", "0.028823"], ["84034.00", "0.000281"], ["84033.72", "0.017083"], ["84033.55", "0.025153"], ["84033.51", "0.007941"], ["84033.47", "0.008994"], ["84033.30", "0.031522"], ["84033.15", "0.008186"], ["84033.00", "0.224921"], ["84032.99", "0.017345"], ["84032.51", "0.262098"], ["84032.37", "0.000200"], ["84032.21", "0.008275"], ["84032.00", "0.000281"], ["84031.48", "0.051752"], ["84031.30", "0.082952"], ["84031.27", "0.012652"], ["84031.00", "0.000281"], ["84030.01", "0.018516"], ["84030.00", "0.002281"], ["84029.61", "0.006169"], ["84029.30", "0.218295"], ["84029.27", "0.055540"], ["84029.21", "0.258762"], ["84029.00", "0.000281"], ["84028.68", "0.222650"], ["84028.43", "0.209200"], ["84028.27", "0.021128"], ["84028.00", "0.000160"], ["84027.71", "0.076109"], ["84027.30", "0.574461"], ["84027.10", "0.006270"], ["84027.00", "0.000160"], ["84026.90", "0.001031"], ["84026.80", "0.001022"], ["84026.60", "0.001018"], ["84026.40", "0.001015"], ["84026.30", "0.092040"], ["84026.00", "0.101790"], ["84025.96", "0.012437"], ["84025.00", "0.000160"], ["84024.81", "0.073059"], ["84024.60", "0.009030"], ["84024.51", "0.008061"], ["84024.00", "0.000160"], ["84023.87", "0.056367"], ["84023.80", "0.444030"], ["84023.20", "0.170700"], ["84023.10", "0.009000"], ["84023.00", "0.071160"], ["84022.98", "0.314053"], ["84022.38", "0.000877"], ["84022.18", "0.017452"], ["84022.00", "0.000160"], ["84021.70", "0.066210"], ["84021.00", "0.000160"], ["84020.90", "0.120000"], ["84020.60", "0.035670"], ["84020.00", "0.000160"], ["84019.89", "0.008248"], ["84019.77", "0.007816"], ["84019.20", "0.120000"], ["84019.14", "0.005689"], ["84019.00", "0.000160"], ["84018.90", "0.084900"], ["84018.53", "0.009243"], ["84018.18", "0.007375"], ["84018.07", "0.008012"], ["84018.05", "0.010045"], ["84018.02", "0.008590"], ["84018.01", "0.006305"], ["84018.00", "0.882600"], ["84017.96", "0.006586"], ["84017.94", "0.008516"], ["84017.70", "0.420000"], ["84017.60", "0.009548"], ["84017.55", "0.014730"], ["84017.51", "0.009309"], ["84017.30", "0.446760"], ["84017.00", "0.000160"], ["84016.70", "0.120000"], ["84016.64", "0.017794"], ["84016.40", "0.240000"], ["84016.00", "0.000160"], ["84015.80", "0.120000"], ["84015.00", "0.120000"], ["84014.90", "0.209200"], ["84014.00", "0.000160"], ["84013.00", "0.000160"], ["84010.77", "0.008761"], ["84010.71", "0.010343"], ["84010.49", "0.008539"], ["84010.46", "0.005053"], ["84010.42", "0.005118"], ["84004.12", "0.003597"], ["84002.26", "0.001175"], ["84002.00", "0.209200"], ["84000.00", "0.003172"], ["83998.01", "0.983294"], ["83993.59", "0.209200"], ["83991.84", "0.008572"], ["83989.33", "0.007246"], ["83989.22", "0.007337"], ["83985.30", "4.350150"], ["83977.83", "0.000172"], ["83977.14", "0.209200"], ["83976.80", "4.078265"], ["83976.72", "0.071678"], ["83975.44", "0.071668"], ["83972.27", "0.010010"], ["83970.00", "0.002000"], ["83968.68", "0.057335"], ["83968.30", "5.618943"], ["83967.63", "0.005950"], ["83962.50", "0.209200"], ["83960.00", "0.000269"], ["83959.80", "4.168894"], ["83959.56", "0.000388"], ["83957.22", "0.000024"], ["83954.10", "0.209200"], ["83953.09", "0.000038"], ["83952.38", "0.000039"], ["83951.30", "5.165803"], ["83950.63", "0.000008"], ["83950.00", "0.007769"], ["83948.26", "0.000028"], ["83947.37", "0.000020"], ["83947.00", "0.207210"], ["83946.83", "0.012418"], ["83945.95", "0.000009"], ["83945.45", "0.000018"], ["83945.00", "0.000008"], ["83943.85", "0.012418"], ["83942.80", "5.528315"], ["83942.61", "0.209200"], ["83941.61", "0.000014"], ["83941.18", "0.000080"], ["83940.00", "0.002269"], ["83938.35", "0.125592"], ["83937.50", "0.000084"], ["83936.50", "0.000113"], ["83935.48", "0.000020"], ["83934.30", "4.712662"], ["83934.19", "0.209200"], ["83933.33", "0.000013"], ["83930.00", "0.000269"], ["83929.82", "0.000033"], ["83929.41", "0.000071"], ["83928.70", "0.000016"], ["83928.57", "0.000010"], ["83926.71", "0.000052"], ["83926.63", "0.000012"], ["83925.83", "0.000019"], ["83925.80", "4.531406"], ["83925.78", "0.209200"], ["83923.08", "0.000283"], ["83922.22", "0.000363"], ["83920.00", "0.000588"], ["83918.14", "0.000035"], ["83917.50", "0.000031"], ["83917.37", "0.209200"], ["83917.30", "5.347059"], ["83916.00", "0.000012"], ["83915.40", "0.000971"], ["83914.93", "0.000143"], ["83914.47", "0.000093"], ["83913.04", "0.016818"], ["83910.00", "0.002269"], ["83909.09", "0.000113"], ["83909.08", "0.000057"], ["83908.96", "0.209200"], ["83908.80", "3.987637"], ["83908.04", "0.000315"], ["83907.85", "0.000009"], ["83906.16", "0.000016"], ["83905.71", "0.000017"], ["83904.85", "0.000009"], ["83904.35", "0.000032"], ["83904.00", "0.000012"], ["83903.51", "0.000022"], ["83902.23", "0.000096"], ["83902.09", "0.001720"], ["83901.67", "0.000019"], ["83900.55", "0.209200"], ["83900.30", "5.437687"], ["83900.00", "0.011643"], ["83899.58", "0.000010"], ["83896.37", "0.001273"], ["83896.00", "0.000133"], ["83894.74", "0.000068"], ["83894.17", "0.000022"], ["83893.81", "0.000010"], ["83893.64", "0.000039"], ["83893.62", "0.000137"], ["83892.86", "0.000016"], ["83892.29", "0.000143"], ["83891.89", "0.000008"], ["83891.80", "4.622034"], ["83891.30", "0.000010"], ["83891.08", "0.000053"], ["83890.00", "0.000617"], ["83888.91", "0.000010"], ["83888.89", "0.000105"], ["83888.00", "0.005960"], ["83887.11", "0.000075"], ["83885.98", "0.000018"], ["83884.30", "0.000161"], ["83883.30", "4.984547"], ["83883.18", "0.001538"], ["83880.00", "0.020938"], ["83879.31", "0.000016"], ["83877.29", "0.000024"], ["83876.92", "0.000015"], ["83875.16", "0.000179"], ["83875.00", "0.000543"], ["83874.80", "4.803290"], ["83873.87", "0.000061"], ["83873.52", "0.000135"], ["83870.97", "0.000194"], ["83870.95", "0.000078"], ["83870.00", "0.000617"], ["83866.67", "0.003906"], ["83866.30", "5.075175"], ["83865.55", "0.041940"], ["83864.54", "0.000009"], ["83862.50", "0.006969"], ["83860.45", "0.000274"], ["83860.29", "0.000041"], ["83860.10", "0.000023"], ["83860.00", "0.000617"], ["83859.54", "0.000008"], ["83859.35", "0.000051"], ["83859.26", "0.000115"], ["83858.06", "0.000008"], ["83857.80", "4.893918"], ["83857.14", "0.000139"], ["83857.13", "0.000019"], ["83856.90", "0.312614"], ["83855.44", "0.000008"], ["83855.42", "0.000008"], ["83854.55", "0.000017"], ["83854.17", "0.000020"], ["83853.09", "0.000033"], ["83852.94", "0.000080"], ["83852.50", "0.000043"], ["83851.85", "0.000011"], ["83851.84", "0.000219"], ["83850.00", "0.003304"], ["83849.30", "5.256431"], ["83848.39", "0.000020"], ["83846.15", "0.000111"], ["83844.83", "0.000008"], ["83843.95", "0.000067"], ["83842.11", "0.000216"], ["83841.18", "0.000071"], ["83840.88", "0.000423"], ["83840.80", "4.259522"], ["83840.00", "0.000684"], ["83839.72", "0.000033"], ["83839.18", "0.000016"], ["83838.46", "0.000275"], ["83837.84", "0.000009"], ["83837.59", "0.000012"], ["83837.10", "0.001457"], ["83836.73", "0.000085"], ["83836.36", "0.000008"], ["83835.56", "0.000009"], ["83834.48", "0.000135"], ["83834.30", "0.304409"], ["83833.82", "0.000013"], ["83833.37", "0.000008"], ["83833.36", "0.000010"], ["83833.33", "0.000035"], ["83832.30", "4.440778"], ["83831.82", "0.000008"], ["83831.11", "0.000011"], ["83830.59", "0.000010"], ["83830.00", "0.000680"], ["83829.82", "0.000143"], ["83828.57", "0.000016"], ["83828.20", "0.305869"], ["83826.67", "0.000081"], ["83825.83", "0.000176"], ["83825.60", "0.001485"], ["83823.80", "3.897009"], ["83822.22", "0.000025"], ["83822.12", "0.000067"], ["83820.00", "0.002651"], ["83818.18", "0.001568"], ["83818.17", "0.000029"], ["83816.67", "0.000010"], ["83816.28", "0.000009"], ["83816.00", "0.000008"], ["83815.79", "0.000031"], ["83815.75", "0.000009"], ["83815.37", "0.000022"], ["83814.00", "0.000035"], ["83813.00", "0.000113"], ["83810.74", "0.000019"], ["83810.00", "0.000617"], ["83808.53", "0.000039"], ["83808.51", "0.000137"], ["83807.88", "0.000051"], ["83807.53", "0.000010"], ["83806.69", "0.000039"], ["83804.55", "0.000192"], ["83804.35", "0.000010"], ["83804.33", "0.011010"], ["83803.57", "0.000016"], ["83802.81", "0.000022"], ["83800.55", "0.000066"], ["83800.50", "0.000013"], ["83800.00", "1.552467"], ["83799.34", "0.016608"], ["83798.37", "0.000008"], ["83798.34", "0.000015"], ["83798.17", "0.000072"], ["83796.61", "0.001213"], ["83795.00", "0.000031"], ["83794.17", "0.000096"], ["83793.10", "0.000016"], ["83790.79", "0.000011"], ["83790.15", "0.000024"], ["83790.00", "0.002724"], ["83789.29", "0.000128"], ["83788.55", "0.000010"], ["83787.88", "0.000010"], ["83785.71", "0.000081"], ["83785.51", "0.000013"], ["83784.62", "0.000015"], ["83784.36", "0.000069"], ["83784.02", "0.000022"], ["83783.78", "0.000493"], ["83783.12", "0.000008"], ["83781.88", "0.000175"], ["83781.30", "0.001130"], ["83781.09", "0.000008"], ["83780.00", "0.001180"], ["83779.93", "0.000028"], ["83777.78", "0.000679"], ["83777.60", "0.000013"], ["83777.18", "0.000013"], ["83775.00", "0.006969"], ["83774.10", "0.000161"], ["83773.31", "0.000154"], ["83773.11", "0.041940"], ["83772.88", "0.000023"], ["83770.00", "0.000619"], ["83768.46", "0.000008"], ["83768.00", "0.000012"], ["83767.74", "0.000008"], ["83767.73", "0.000188"], ["83766.84", "0.000023"], ["83765.06", "0.000008"], ["83764.71", "0.000080"], ["83763.64", "0.000010"], ["83762.50", "0.000076"], ["83761.90", "0.000024"], ["83761.29", "0.000020"], ["83760.00", "0.003130"], ["83759.85", "0.000026"], ["83758.93", "0.000036"], ["83757.40", "0.000537"], ["83756.52", "0.000018"], ["83755.56", "0.000134"], ["83754.70", "0.000013"], ["83754.39", "0.000033"], ["83753.85", "0.000275"], ["83753.04", "0.000030"], ["83752.94", "0.000071"], ["83752.09", "0.000314"], ["83752.00", "0.000034"], ["83751.00", "0.010000"], ["83750.67", "0.000146"], ["83750.00", "0.005896"], ["83749.66", "0.000016"], ["83749.65", "0.001535"], ["83749.50", "0.000069"], ["83749.33", "0.000133"], ["83748.54", "0.000012"], ["83746.09", "0.000010"], ["83745.16", "0.000389"], ["83744.71", "0.000143"], ["83740.51", "0.000423"], ["83740.00", "0.000683"], ["83739.78", "1.666775"], ["83739.60", "0.000048"], ["83739.28", "0.000051"], ["83739.13", "0.000008"], ["83737.93", "0.000135"], ["83737.00", "0.000009"], ["83736.84", "0.000183"], ["83734.69", "0.000085"], ["83733.33", "0.003205"], ["83732.10", "0.000009"], ["83731.48", "0.000124"], ["83730.00", "0.002619"], ["83729.73", "0.000009"], ["83729.39", "0.000008"], ["83729.32", "0.000035"], ["83728.57", "0.000017"], ["83728.37", "0.001273"], ["83728.07", "0.000022"], ["83727.71", "0.000009"], ["83727.27", "0.000082"], ["83726.20", "0.000016"], ["83725.00", "0.000286"], ["83723.72", "0.000176"], ["83723.64", "0.000009"], ["83723.43", "0.000039"], ["83723.40", "0.000205"], ["83720.00", "0.003020"], ["83719.46", "0.000053"], ["83718.53", "0.006306"], ["83717.93", "0.000065"], ["83717.46", "0.000009"], ["83717.39", "0.000010"], ["83715.48", "0.000010"], ["83714.29", "0.000123"], ["83713.80", "0.000024"], ["83713.71", "0.000323"], ["83713.64", "0.000192"], ["83713.33", "0.000008"], ["83710.00", "0.000642"], ["83706.90", "0.000016"], ["83706.67", "0.000013"], ["83705.85", "0.000019"], ["83705.32", "0.000065"], ["83705.18", "0.000009"], ["83703.75", "0.000363"], ["83703.70", "0.000441"], ["83703.00", "0.000024"], ["83702.93", "0.000050"], ["83702.60", "0.000039"], ["83702.50", "0.000033"], ["83702.48", "0.000057"], ["83701.92", "0.000067"], ["83701.28", "0.000248"], ["83700.59", "0.002370"], ["83700.00", "0.007065"], ["83699.88", "0.000008"], ["83698.25", "0.000013"], ["83697.23", "0.000095"], ["83695.65", "0.003457"], ["83695.63", "0.000011"], ["83693.69", "0.000061"], ["83692.52", "0.000066"], ["83692.38", "0.000007"], ["83692.31", "0.000031"], ["83690.84", "0.000162"], ["83690.48", "0.000248"], ["83690.00", "0.000619"]], "checksum": 0, "ts": "1742584881047"}], "ts": 1742584881197, "record_time": 1742584881.360453, "EXCHANGE": "BITGET"}
{"action": "update", "arg": {"instType": "SPOT", "channel": "books", "instId": "BTCUSDT"}, "data": [{"asks": [["84057.01", "2.281097"], ["84059.79", "0.098163"], ["84059.80", "0"], ["84064.00", "0.310567"], ["84064.01", "0.247558"], ["84065.00", "0"], ["84069.99", "0.003787"], ["84073.34", "0.035957"], ["84073.69", "0.119905"], ["84074.95", "0.035972"], ["84076.25", "0.006357"], ["84076.32", "0"], ["84077.00", "0.076846"], ["84077.23", "0.006356"], ["84078.30", "0.006357"], ["84078.39", "0.006357"], ["84078.52", "0.006357"], ["84078.87", "0.006357"], ["84078.94", "0.006357"], ["84079.21", "0"], ["84079.93", "0.006357"], ["84080.62", "0"], ["84081.93", "0"], ["84082.12", "0.119850"], ["84082.80", "0"], ["84082.90", "0"], ["84083.15", "0.010000"], ["84083.84", "0"], ["84084.07", "0"], ["84084.12", "0"], ["84084.61", "0"], ["84084.76", "0"], ["84085.74", "0.065100"], ["84085.84", "0"], ["84088.85", "0.077141"], ["84093.50", "0.001337"], ["84095.50", "0.003519"], ["84097.50", "0.009261"], ["84099.50", "0.024371"], ["84100.41", "0.214030"], ["84101.50", "0.064134"], ["84103.50", "0.168774"], ["84105.50", "0.444142"], ["84107.50", "1.168574"], ["84109.50", "3.075195"], ["84111.50", "8.092618"], ["84111.90", "0.006480"], ["84112.00", "2.609970"], ["84112.10", "5.125080"], ["84113.10", "0.034710"], ["84113.80", "1.758300"], ["84114.10", "0.067800"], ["84114.29", "0.088254"], ["84114.40", "0.070230"], ["84114.60", "0.656970"], ["84115.00", "0.066840"], ["84117.30", "0"], ["84118.20", "0.350700"], ["84118.50", "0"], ["84132.00", "0"], ["84153.50", "4.622034"], ["84162.00", "3.897009"], ["84170.50", "4.440778"], ["84179.00", "3.987637"], ["84187.50", "4.350150"], ["84196.00", "5.347059"], ["84204.50", "5.437687"], ["84213.00", "4.803290"], ["84230.00", "4.168894"], ["84238.50", "5.165803"], ["84247.00", "4.712662"], ["84255.50", "5.618943"], ["84264.00", "4.078265"], ["84272.50", "5.075175"], ["84281.00", "4.259522"], ["84289.50", "5.528315"], ["84298.00", "4.531406"], ["84306.50", "5.256431"], ["84315.00", "4.984547"], ["84565.22", "0"], ["84566.67", "0"], ["84567.79", "0"], ["84568.60", "0"]], "bids": [["84046.77", "0"], ["84039.30", "0.001104"], ["84038.86", "0"], ["84037.30", "0.002365"], ["84036.91", "0"], ["84036.01", "0"], ["84035.70", "0"], ["84035.30", "0.006224"], ["84035.22", "0"], ["84034.65", "0"], ["84034.24", "0"], ["84033.51", "0"], ["84033.47", "0"], ["84033.30", "0.016379"], ["84033.15", "0"], ["84032.99", "0.089533"], ["84032.21", "0"], ["84031.30", "0.043102"], ["84031.25", "0.083499"], ["84030.02", "0.015724"], ["84029.41", "0.006561"], ["84029.30", "0.113427"], ["84028.98", "0.017095"], ["84028.71", "0.007335"], ["84027.92", "0.007942"], ["84027.79", "0.008995"], ["84027.33", "0.008187"], ["84027.30", "0.298493"], ["84027.26", "0.017348"], ["84026.30", "0.089580"], ["84026.00", "0.101610"], ["84024.80", "0.388020"], ["84024.60", "2.365620"], ["84024.03", "0.008262"], ["84023.96", "0.268374"], ["84023.80", "0.443820"], ["84023.70", "0.076170"], ["84023.30", "0.831900"], ["84023.20", "0.170490"], ["84023.00", "0.086160"], ["84018.15", "0.015655"], ["84018.07", "0.013945"], ["84018.05", "0.015636"], ["84018.02", "0.017996"], ["84017.93", "0.005952"], ["84017.69", "0.009786"], ["84017.30", "0.566760"], ["84016.70", "0"], ["84016.40", "0"], ["84015.80", "0"], ["84015.00", "0.000160"], ["84014.00", "0"], ["84010.90", "0.008917"], ["84010.60", "0.008301"], ["84010.59", "0.005173"], ["84010.58", "0.005601"], ["84010.52", "0.004851"], ["84010.50", "0.008092"], ["83994.85", "0.007435"], ["83989.43", "0.007651"], ["83985.30", "4.168894"], ["83976.80", "4.893918"], ["83968.30", "4.440778"], ["83959.80", "3.897009"], ["83951.30", "4.350150"], ["83942.80", "5.437687"], ["83934.30", "4.531406"], ["83925.80", "5.618943"], ["83917.30", "4.622034"], ["83908.80", "4.712662"], ["83900.30", "5.528315"], ["83891.80", "5.347059"], ["83883.30", "5.165803"], ["83866.30", "4.078265"], ["83857.80", "4.259522"], ["83849.30", "3.987637"], ["83840.80", "5.256431"], ["83832.30", "5.075175"], ["83823.80", "4.984547"], ["83695.65", "0"], ["83695.63", "0"], ["83693.69", "0"], ["83692.52", "0"], ["83692.38", "0"], ["83692.31", "0"], ["83690.84", "0"], ["83690.48", "0"], ["83690.00", "0"]], "checksum": -1265606980, "ts": "1742584881250"}], "ts": 1742584881254, "record_time": 1742584881.361957, "EXCHANGE": "BITGET"}
{"action": "update", "arg": {"instType": "SPOT", "channel": "books", "instId": "BTCUSDT"}, "data": [{"asks": [["84057.01", "1.956242"], ["84058.01", "0"], ["84059.79", "0"], ["84064.00", "0.231235"], ["84064.01", "0.233720"], ["84068.53", "2.192317"], ["84076.98", "0.006357"], ["84083.15", "0"], ["84093.77", "0"], ["84096.90", "2.557699"], ["84099.50", "0.024176"], ["84101.50", "0.063621"], ["84103.50", "0.167422"], ["84105.50", "0.440586"], ["84107.22", "0.371946"], ["84107.50", "1.159437"], ["84109.50", "3.051150"], ["84109.78", "0.996757"], ["84111.50", "8.029527"], ["84112.10", "3.775080"], ["84113.10", "0.019440"], ["84113.80", "0.688440"], ["84114.40", "0"], ["84114.90", "0"], ["84124.20", "2.179890"], ["84124.30", "0.015960"], ["84126.32", "2.826232"], ["84153.50", "5.618943"], ["84162.00", "3.987637"], ["84170.50", "4.168894"], ["84179.00", "5.165803"], ["84187.50", "3.897009"], ["84196.00", "5.437687"], ["84204.50", "4.440778"], ["84213.00", "4.893918"], ["84221.50", "4.622034"], ["84230.00", "5.256431"], ["84238.50", "4.712662"], ["84247.00", "4.078265"], ["84255.50", "5.347059"], ["84264.00", "4.984547"], ["84272.50", "5.528315"], ["84281.00", "4.803290"], ["84289.50", "4.259522"], ["84306.50", "5.075175"], ["84315.00", "4.350150"], ["84480.00", "0.005529"]], "bids": [["84052.07", "0.035633"], ["84039.30", "0.002221"], ["84037.30", "0.005845"], ["84035.30", "0.015382"], ["84033.30", "0.040478"], ["84031.30", "0.106520"], ["84029.30", "0.280317"], ["84027.30", "0.737676"], ["84026.80", "0.440190"], ["84026.50", "2.356350"], ["84026.40", "0"], ["84025.60", "0.031650"], ["84025.50", "0.845520"], ["84024.80", "0"], ["84024.60", "0.009030"], ["84023.30", "0"], ["84021.70", "0"], ["84016.70", "0.120000"], ["84016.40", "0.120000"], ["84006.65", "0.023495"], ["83985.30", "5.347059"], ["83976.80", "4.803290"], ["83968.30", "4.350150"], ["83959.80", "5.528315"], ["83951.30", "4.078265"], ["83942.80", "4.622034"], ["83934.30", "4.984547"], ["83925.80", "5.256431"], ["83917.30", "5.618943"], ["83908.80", "3.897009"], ["83900.30", "4.712662"], ["83891.80", "3.987637"], ["83883.30", "5.075175"], ["83874.80", "5.165803"], ["83866.30", "4.168894"], ["83857.80", "4.440778"], ["83849.30", "4.259522"], ["83840.80", "5.437687"], ["83832.30", "4.893918"], ["83823.80", "4.531406"], ["83699.88", "0"], ["83698.25", "0"], ["83697.23", "0"]], "checksum": -810051072, "ts": "1742584881452"}], "ts": 1742584881455, "record_time": 1742584881.564501, "EXCHANGE": "BITGET"}
{"action": "update", "arg": {"instType": "SPOT", "channel": "books", "instId": "BTCUSDT"}, "data": [{"asks": [["84057.01", "2.055543"], ["84067.42", "0.013838"], ["84068.52", "0.662118"], ["84069.99", "0"], ["84106.89", "0"], ["84113.10", "0"], ["84118.20", "0.343230"], ["84119.90", "0.009000"], ["84153.50", "4.078265"], ["84162.00", "4.168894"], ["84170.50", "5.256431"], ["84179.00", "5.437687"], ["84187.50", "4.622034"], ["84196.00", "4.984547"], ["84204.50", "5.165803"], ["84221.50", "5.618943"], ["84230.00", "4.259522"], ["84238.50", "5.528315"], ["84247.00", "4.440778"], ["84255.50", "3.897009"], ["84264.00", "5.075175"], ["84272.50", "4.531406"], ["84281.00", "4.712662"], ["84289.50", "4.803290"], ["84298.00", "4.350150"], ["84306.50", "5.347059"], ["84315.00", "3.987637"]], "bids": [["84057.00", "0.015281"], ["84045.23", "0.010000"], ["84041.30", "0.002454"], ["84039.30", "0.006459"], ["84037.30", "0.016997"], ["84035.30", "0.044727"], ["84033.30", "0.117704"], ["84031.30", "0.309747"], ["84029.30", "0.815124"], ["84027.30", "2.145064"], ["84026.50", "2.358270"], ["84025.60", "0.023940"], ["84023.20", "0"], ["84020.91", "0.023495"], ["84018.00", "1.675020"], ["84016.40", "0.240000"], ["84007.84", "0.025716"], ["84006.65", "0"], ["83985.30", "4.622034"], ["83976.80", "3.987637"], ["83968.30", "4.078265"], ["83959.80", "4.440778"], ["83951.30", "5.437687"], ["83942.80", "4.712662"], ["83934.30", "4.531406"], ["83925.80", "5.075175"], ["83917.30", "4.893918"], ["83908.80", "5.256431"], ["83900.30", "5.165803"], ["83891.80", "5.347059"], ["83883.30", "4.259522"], ["83874.80", "4.803290"], ["83866.30", "5.528315"], ["83857.80", "4.350150"], ["83849.30", "4.168894"], ["83840.80", "5.618943"], ["83832.30", "3.897009"], ["83823.80", "4.984547"], ["83700.00", "0"]], "checksum": -1807034964, "ts": "1742584881656"}], "ts": 1742584881659, "record_time": 1742584881.768374, "EXCHANGE": "BITGET"}
{"action": "update", "arg": {"instType": "SPOT", "channel": "books", "instId": "BTCUSDT"}, "data": [{"asks": [["84057.01", "2.382753"], ["84073.68", "0.064789"], ["84074.53", "0"], ["84103.50", "0.167523"], ["84105.50", "0.440850"], ["84107.50", "1.160133"], ["84109.50", "3.052980"], ["84111.50", "8.034158"], ["84153.50", "5.347059"], ["84162.00", "5.075175"], ["84170.50", "4.712662"], ["84179.00", "5.256431"], ["84187.50", "4.984547"], ["84196.00", "3.987637"], ["84204.50", "4.078265"], ["84213.00", "5.165803"], ["84221.50", "4.803290"], ["84230.00", "3.897009"], ["84238.50", "4.168894"], ["84247.00", "4.350150"], ["84255.50", "5.618943"], ["84264.00", "4.259522"], ["84281.00", "4.893918"], ["84289.50", "5.528315"], ["84298.00", "4.440778"], ["84306.50", "5.437687"], ["84315.00", "4.622034"]], "bids": [["84052.07", "0"], ["84039.32", "0.098371"], ["84029.30", "0.815244"], ["84027.30", "2.145380"], ["84027.10", "0.902550"], ["84026.60", "0"], ["84026.50", "2.356560"], ["84026.00", "0.101400"], ["84025.50", "0"], ["84018.50", "0.160590"], ["84016.70", "0.618420"], ["84012.00", "0.000160"], ["84011.00", "0.000160"], ["84010.00", "0.000160"], ["84009.00", "0.000160"], ["84008.00", "0.000160"], ["84007.00", "0.000160"], ["83985.30", "3.987637"], ["83976.80", "5.165803"], ["83968.30", "4.350150"], ["83959.80", "4.712662"], ["83951.30", "4.168894"], ["83942.80", "5.437687"], ["83934.30", "4.622034"], ["83917.30", "4.078265"], ["83908.80", "4.531406"], ["83900.30", "4.893918"], ["83883.30", "4.440778"], ["83874.80", "5.618943"], ["83866.30", "4.803290"], ["83857.80", "4.259522"], ["83849.30", "3.897009"], ["83840.80", "5.528315"], ["83832.30", "5.256431"], ["83702.50", "0"], ["83702.48", "0"], ["83701.92", "0"], ["83701.28", "0"], ["83700.59", "0"]], "checksum": 1537033769, "ts": "1742584881858"}], "ts": 1742584881862, "record_time": 1742584881.971091, "EXCHANGE": "BITGET"}
{"action": "update", "arg": {"instType": "SPOT", "channel": "books", "instId": "BTCUSDT"}, "data": [{"asks": [["84084.87", "0"], ["84095.50", "0.003378"], ["84096.89", "0.991370"], ["84097.50", "0.008891"], ["84099.50", "0.023397"], ["84100.41", "0"], ["84101.50", "0.061571"], ["84103.50", "0.162029"], ["84105.50", "0.426392"], ["84107.50", "1.122085"], ["84109.50", "2.952855"], ["84109.78", "0.020107"], ["84111.50", "7.770671"], ["84117.00", "0.424800"], ["84153.50", "4.893918"], ["84162.00", "5.528315"], ["84170.50", "5.165803"], ["84179.00", "4.622034"], ["84187.50", "4.803290"], ["84196.00", "3.897009"], ["84204.50", "5.347059"], ["84213.00", "4.168894"], ["84221.50", "4.350150"], ["84230.00", "4.259522"], ["84238.50", "5.437687"], ["84247.00", "4.712662"], ["84255.50", "5.256431"], ["84264.00", "5.075175"], ["84272.50", "4.078265"], ["84281.00", "5.618943"], ["84289.50", "4.984547"], ["84298.00", "4.531406"], ["84306.50", "3.987637"], ["84315.00", "4.440778"]], "bids": [["84052.24", "0.035633"], ["84041.30", "0.002716"], ["84039.30", "0.007147"], ["84037.30", "0.018806"], ["84036.73", "0.047094"], ["84035.30", "0.049490"], ["84033.30", "0.130135"], ["84031.30", "0.342461"], ["84029.30", "0.901212"], ["84027.30", "2.371612"], ["84027.20", "0.001035"], ["84026.80", "0.439980"], ["84026.30", "0.089370"], ["84016.40", "0.120000"], ["83985.30", "4.622034"], ["83976.80", "4.168894"], ["83968.30", "4.259522"], ["83959.80", "4.440778"], ["83951.30", "3.897009"], ["83942.80", "5.528315"], ["83934.30", "4.893918"], ["83925.80", "4.531406"], ["83917.30", "5.618943"], ["83908.80", "5.256431"], ["83900.30", "5.347059"], ["83891.80", "4.350150"], ["83883.30", "5.437687"], ["83874.80", "5.075175"], ["83872.00", "0.001184"], ["83866.30", "4.078265"], ["83857.80", "4.803290"], ["83849.30", "3.987637"], ["83840.80", "4.712662"], ["83832.30", "5.165803"], ["83703.70", "0"], ["83703.00", "0"], ["83702.93", "0"], ["83702.60", "0"]], "checksum": -1893362962, "ts": "1742584882063"}], "ts": 1742584882066, "record_time": 1742584882.175535, "EXCHANGE": "BITGET"}
{"action": "update", "arg": {"instType": "SPOT", "channel": "books", "instId": "BTCUSDT"}, "data": [{"asks": [["84084.75", "0.100656"], ["84116.40", "0.070590"], ["84116.90", "0.368040"], ["84118.20", "0.165840"], ["84124.30", "0"], ["84153.50", "5.618943"], ["84162.00", "4.259522"], ["84170.50", "5.437687"], ["84179.00", "4.350150"], ["84187.50", "5.075175"], ["84196.00", "4.531406"], ["84213.00", "4.893918"], ["84221.50", "4.168894"], ["84230.00", "5.528315"], ["84238.50", "4.712662"], ["84247.00", "3.897009"], ["84264.00", "4.078265"], ["84272.50", "4.440778"], ["84281.00", "4.984547"], ["84289.50", "4.622034"], ["84298.00", "4.803290"], ["84306.50", "5.165803"], ["84315.00", "3.987637"], ["84562.50", "0"]], "bids": [["84041.30", "0.002587"], ["84039.30", "0.006808"], ["84037.30", "0.017916"], ["84035.30", "0.047147"], ["84033.30", "0.124069"], ["84031.30", "0.326499"], ["84029.30", "0.859207"], ["84027.30", "2.261072"], ["83985.30", "5.075175"], ["83976.80", "4.350150"], ["83968.30", "5.347059"], ["83959.80", "4.893918"], ["83951.30", "5.437687"], ["83942.80", "4.168894"], ["83934.30", "5.618943"], ["83925.80", "4.984547"], ["83917.30", "4.259522"], ["83908.80", "4.622034"], ["83900.30", "3.897009"], ["83891.80", "4.803290"], ["83883.30", "4.440778"], ["83874.80", "5.528315"], ["83866.30", "5.256431"], ["83857.80", "4.712662"], ["83849.30", "4.531406"], ["83840.80", "5.165803"], ["83832.30", "3.987637"], ["83823.80", "4.078265"]], "checksum": 2083256319, "ts": "1742584882266"}], "ts": 1742584882269, "record_time": 1742584882.37856, "EXCHANGE": "BITGET"}
{"action": "update", "arg": {"instType": "SPOT", "channel": "books", "instId": "BTCUSDT"}, "data": [{"asks": [["84057.01", "2.395007"], ["84079.27", "0.175347"], ["84109.78", "0.403239"], ["84117.70", "0.070200"], ["84153.50", "5.165803"], ["84162.00", "4.712662"], ["84170.50", "5.618943"], ["84179.00", "5.347059"], ["84187.50", "5.437687"], ["84196.00", "4.622034"], ["84204.50", "3.897009"], ["84213.00", "5.256431"], ["84221.50", "4.350150"], ["84230.00", "4.984547"], ["84238.50", "4.803290"], ["84247.00", "3.987637"], ["84255.50", "4.168894"], ["84264.00", "5.075175"], ["84272.50", "5.528315"], ["84281.00", "4.893918"], ["84289.50", "4.259522"], ["84298.00", "4.440778"], ["84306.50", "4.078265"], ["84315.00", "4.531406"], ["84465.00", "0.000547"], ["84561.11", "0"], ["84561.58", "0"]], "bids": [["84052.24", "0"], ["84027.20", "0.003570"], ["84026.90", "0"], ["83968.30", "4.168894"], ["83959.80", "4.622034"], ["83951.30", "4.893918"], ["83942.80", "5.347059"], ["83934.30", "4.440778"], ["83925.80", "4.259522"], ["83917.30", "4.531406"], ["83908.80", "4.712662"], ["83900.30", "4.803290"], ["83891.80", "5.618943"], ["83883.30", "5.437687"], ["83874.80", "4.984547"], ["83866.30", "5.165803"], ["83857.80", "3.897009"], ["83849.30", "5.528315"], ["83840.80", "4.078265"], ["83832.30", "5.256431"], ["83823.80", "3.987637"], ["83703.70", "0.000441"], ["83703.00", "0.000024"]], "checksum": 2125989553, "ts": "1742584882468"}], "ts": 1742584882471, "record_time": 1742584882.580711, "EXCHANGE": "BITGET"}
{"action": "update", "arg": {"instType": "SPOT", "channel": "books", "instId": "BTCUSDT"}, "data": [{"asks": [["84077.00", "0.120499"], ["84095.50", "0.003763"], ["84097.50", "0.009903"], ["84099.50", "0.026060"], ["84101.50", "0.068579"], ["84103.50", "0.180471"], ["84105.50", "0.474926"], ["84107.50", "1.249805"], ["84109.50", "3.288959"], ["84111.50", "8.655157"], ["84114.29", "0"], ["84116.40", "0"], ["84124.30", "0.015960"], ["84153.50", "3.897009"], ["84162.00", "4.984547"], ["84170.50", "4.712662"], ["84179.00", "5.618943"], ["84187.50", "5.256431"], ["84196.00", "5.075175"], ["84204.50", "4.259522"], ["84213.00", "4.531406"], ["84221.50", "4.078265"], ["84230.00", "4.350150"], ["84238.50", "4.893918"], ["84247.00", "5.347059"], ["84255.50", "4.440778"], ["84264.00", "5.437687"], ["84272.50", "3.987637"], ["84281.00", "5.165803"], ["84289.50", "4.803290"], ["84298.00", "4.168894"], ["84306.50", "4.622034"], ["84315.00", "5.528315"], ["84561.11", "0.000134"]], "bids": [["84057.00", "0.015121"], ["84053.89", "0.010367"], ["84052.94", "0"], ["84052.43", "0.035633"], ["84041.30", "0.002282"], ["84039.30", "0.006005"], ["84037.30", "0.015803"], ["84035.30", "0.041586"], ["84033.30", "0.109437"], ["84031.30", "0.287992"], ["84029.30", "0.757873"], ["84027.30", "1.994645"], ["84027.20", "0.024870"], ["83985.30", "5.618943"], ["83976.80", "5.075175"], ["83968.30", "4.893918"], ["83959.80", "5.437687"], ["83951.30", "4.984547"], ["83942.80", "5.256431"], ["83934.30", "4.803290"], ["83925.80", "5.528315"], ["83917.30", "4.350150"], ["83908.80", "4.259522"], ["83900.30", "3.987637"], ["83891.80", "4.168894"], ["83883.30", "4.078265"], ["83874.80", "3.897009"], ["83866.30", "4.622034"], ["83857.80", "4.531406"], ["83849.30", "4.712662"], ["83840.80", "5.347059"], ["83832.30", "4.440778"], ["83823.80", "5.165803"], ["83703.00", "0"]], "checksum": 951241570, "ts": "1742584882680"}], "ts": 1742584882683, "record_time": 1742584882.791725, "EXCHANGE": "BITGET"}
{"action": "update", "arg": {"instType": "SPOT", "channel": "books", "instId": "BTCUSDT"}, "data": [{"asks": [["84057.01", "2.416900"], ["84067.42", "0"], ["84081.16", "0.013838"], ["84095.50", "0.003378"], ["84097.50", "0.008891"], ["84099.50", "0.023397"], ["84101.49", "0.074715"], ["84101.50", "0.061572"], ["84103.50", "0.162031"], ["84105.50", "0.426396"], ["84107.50", "1.122096"], ["84109.50", "2.952883"], ["84111.50", "7.770745"], ["84112.20", "0.099510"], ["84113.10", "0.029370"], ["84116.40", "0.070710"], ["84118.20", "0.138180"], ["84124.10", "0"], ["84124.20", "0"], ["84124.30", "0"], ["84153.50", "4.984547"], ["84162.00", "4.893918"], ["84170.50", "5.347059"], ["84179.00", "4.350150"], ["84187.50", "4.622034"], ["84196.00", "4.712662"], ["84204.50", "3.897009"], ["84221.50", "5.437687"], ["84230.00", "5.256431"], ["84238.50", "4.168894"], ["84247.00", "4.803290"], ["84255.50", "3.987637"], ["84264.00", "4.440778"], ["84272.50", "5.165803"], ["84281.00", "4.259522"], ["84289.50", "4.078265"], ["84298.00", "5.528315"], ["84306.50", "5.618943"], ["84315.00", "5.075175"], ["84561.11", "0"]], "bids": [["84041.30", "0.002138"], ["84039.30", "0.005627"], ["84037.30", "0.014806"], ["84035.30", "0.038965"], ["84033.30", "0.102537"], ["84031.30", "0.269836"], ["84029.30", "0.710093"], ["84027.30", "1.868668"], ["84027.20", "0.050700"], ["84027.10", "0.006690"], ["84025.60", "0"], ["83985.30", "4.622034"], ["83976.80", "5.256431"], ["83968.30", "3.897009"], ["83959.80", "4.531406"], ["83951.30", "4.168894"], ["83942.80", "4.440778"], ["83934.30", "4.259522"], ["83925.80", "4.984547"], ["83917.30", "4.893918"], ["83908.80", "4.803290"], ["83900.30", "5.165803"], ["83891.80", "5.347059"], ["83883.30", "5.618943"], ["83874.80", "5.528315"], ["83866.30", "3.987637"], ["83857.80", "4.712662"], ["83849.30", "5.075175"], ["83840.80", "5.437687"], ["83832.30", "4.078265"], ["83823.80", "4.350150"], ["83703.00", "0.000024"]], "checksum": -32563025, "ts": "1742584882881"}], "ts": 1742584882884, "record_time": 1742584882.994225, "EXCHANGE": "BITGET"}
{"action": "update", "arg": {"instType": "SPOT", "channel": "books", "instId": "BTCUSDT"}, "data": [{"asks": [["84080.24", "0.051848"], ["84093.50", "0.001174"], ["84095.50", "0.003090"], ["84097.50", "0.008132"], ["84099.50", "0.021400"], ["84101.50", "0.056316"], ["84103.50", "0.148200"], ["84105.50", "0.389999"], ["84107.50", "1.026313"], ["84109.50", "2.700824"], ["84109.78", "0.020107"], ["84111.50", "7.107432"], ["84112.20", "0"], ["84113.10", "0"], ["84116.40", "0"], ["84119.40", "1.069860"], ["84153.50", "4.078265"], ["84162.00", "3.897009"], ["84170.50", "4.803290"], ["84179.00", "4.984547"], ["84187.50", "5.165803"], ["84196.00", "4.168894"], ["84204.50", "4.531406"], ["84207.76", "0"], ["84213.00", "5.256431"], ["84221.50", "3.987637"], ["84230.00", "4.622034"], ["84238.50", "4.350150"], ["84247.00", "5.528315"], ["84255.50", "5.075175"], ["84264.00", "5.437687"], ["84272.50", "4.893918"], ["84281.00", "5.347059"], ["84289.50", "4.440778"], ["84298.00", "5.618943"], ["84306.50", "4.259522"], ["84315.00", "4.712662"], ["84561.11", "0.000134"], ["84561.58", "0.003678"], ["84562.50", "0.006969"]], "bids": [["84052.58", "0.035633"], ["84052.43", "0"], ["84041.30", "0.002367"], ["84039.30", "0.006227"], ["84037.30", "0.016387"], ["84035.30", "0.043124"], ["84033.30", "0.113485"], ["84031.30", "0.298644"], ["84029.30", "0.785905"], ["84027.30", "2.068171"], ["84026.00", "0.970290"], ["84016.40", "0"], ["83985.30", "4.078265"], ["83976.80", "4.168894"], ["83968.30", "5.528315"], ["83959.80", "4.893918"], ["83951.30", "5.165803"], ["83942.80", "5.256431"], ["83934.30", "3.897009"], ["83925.80", "4.531406"], ["83917.30", "4.803290"], ["83908.80", "4.622034"], ["83900.30", "5.347059"], ["83891.80", "4.440778"], ["83883.30", "4.984547"], ["83874.80", "4.712662"], ["83866.30", "5.618943"], ["83857.80", "5.075175"], ["83849.30", "4.259522"], ["83840.80", "4.350150"], ["83832.30", "5.437687"], ["83823.80", "3.987637"], ["83702.93", "0.000050"]], "checksum": -26331418, "ts": "1742584883083"}], "ts": 1742584883087, "record_time": 1742584883.196403, "EXCHANGE": "BITGET"}
{"action": "update", "arg": {"instType": "SPOT", "channel": "books", "instId": "BTCUSDT"}, "data": [{"asks": [["84093.50", "0.001178"], ["84095.50", "0.003101"], ["84097.50", "0.008160"], ["84099.50", "0.021473"], ["84101.50", "0.056507"], ["84103.50", "0.148703"], ["84105.50", "0.391325"], ["84107.50", "1.029802"], ["84109.50", "2.710006"], ["84109.78", "0.270060"], ["84111.50", "7.131593"], ["84112.80", "0.100920"], ["84116.90", "0.655710"], ["84153.50", "4.622034"], ["84162.00", "4.712662"], ["84167.16", "0.125630"], ["84170.50", "4.168894"], ["84179.00", "4.078265"], ["84196.00", "4.984547"], ["84204.50", "4.440778"], ["84213.00", "3.897009"], ["84221.50", "4.350150"], ["84230.00", "5.256431"], ["84238.50", "3.987637"], ["84247.00", "4.893918"], ["84255.50", "4.803290"], ["84264.00", "5.528315"], ["84272.50", "5.347059"], ["84281.00", "5.618943"], ["84289.50", "5.075175"], ["84298.00", "5.437687"], ["84315.00", "4.531406"], ["84561.58", "0"], ["84562.50", "0"]], "bids": [["84053.89", "0"], ["84014.00", "0.000160"], ["84006.00", "0.000160"], ["83985.30", "5.528315"], ["83976.80", "4.350150"], ["83968.30", "4.984547"], ["83959.80", "4.440778"], ["83951.30", "5.618943"], ["83942.80", "5.075175"], ["83934.30", "5.347059"], ["83925.80", "4.803290"], ["83917.30", "5.256431"], ["83908.80", "4.259522"], ["83900.30", "5.437687"], ["83891.80", "4.712662"], ["83883.30", "4.893918"], ["83874.80", "3.897009"], ["83866.30", "4.078265"], ["83857.80", "4.622034"], ["83849.30", "4.531406"], ["83840.80", "5.165803"], ["83832.30", "3.987637"], ["83823.80", "4.168894"], ["83702.93", "0"]], "checksum": -351910854, "ts": "1742584883284"}], "ts": 1742584883288, "record_time": 1742584883.39638, "EXCHANGE": "BITGET"}
{"action": "update", "arg": {"instType": "SPOT", "channel": "books", "instId": "BTCUSDT"}, "data": [{"asks": [["84153.50", "5.347059"], ["84162.00", "5.618943"], ["84170.50", "4.350150"], ["84179.00", "5.437687"], ["84187.50", "4.531406"], ["84196.00", "4.440778"], ["84204.50", "5.528315"], ["84213.00", "5.075175"], ["84221.50", "3.987637"], ["84230.00", "4.259522"], ["84238.50", "4.078265"], ["84247.00", "4.712662"], ["84251.91", "0"], ["84264.00", "3.897009"], ["84272.50", "5.256431"], ["84281.00", "4.622034"], ["84289.50", "4.984547"], ["84298.00", "5.165803"], ["84306.50", "4.893918"], ["84315.00", "4.168894"], ["84561.58", "0.003678"]], "bids": [["84054.17", "0.010367"], ["84052.58", "0"], ["83985.30", "4.168894"], ["83976.80", "4.440778"], ["83968.30", "5.437687"], ["83959.80", "5.618943"], ["83951.30", "4.622034"], ["83942.80", "4.531406"], ["83934.30", "4.803290"], ["83925.80", "5.165803"], ["83917.30", "3.987637"], ["83908.80", "5.528315"], ["83900.30", "5.075175"], ["83891.80", "4.078265"], ["83883.30", "3.897009"], ["83874.80", "4.259522"], ["83866.30", "4.712662"], ["83857.80", "5.256431"], ["83849.30", "4.893918"], ["83840.80", "5.347059"], ["83832.30", "4.984547"], ["83823.80", "4.350150"]], "checksum": -1394467200, "ts": "1742584883492"}], "ts": 1742584883495, "record_time": 1742584883.604774, "EXCHANGE": "BITGET"}
{"action": "update", "arg": {"instType": "SPOT", "channel": "books", "instId": "BTCUSDT"}, "data": [{"asks": [["84092.06", "0.010000"], ["84093.50", "0.001572"], ["84095.50", "0.004137"], ["84097.50", "0.010886"], ["84099.50", "0.028647"], ["84101.50", "0.075387"], ["84103.50", "0.198387"], ["84105.50", "0.522070"], ["84107.50", "1.373869"], ["84109.50", "3.615444"], ["84111.50", "9.514328"], ["84114.80", "0"], ["84153.50", "5.075175"], ["84162.00", "3.987637"], ["84170.50", "3.897009"], ["84179.00", "4.712662"], ["84187.50", "4.622034"], ["84196.00", "5.256431"], ["84204.50", "4.984547"], ["84213.00", "4.803290"], ["84221.50", "5.437687"], ["84230.00", "4.168894"], ["84238.50", "4.531406"], ["84247.00", "4.350150"], ["84255.50", "5.528315"], ["84264.00", "5.347059"], ["84272.50", "5.618943"], ["84281.00", "4.893918"], ["84289.50", "4.078265"], ["84306.50", "4.440778"], ["84315.00", "4.259522"]], "bids": [["84052.74", "0.035633"], ["84033.30", "0.113228"], ["84031.30", "0.297967"], ["84029.30", "0.784124"], ["84027.30", "2.063484"], ["83985.30", "5.528315"], ["83976.80", "5.165803"], ["83968.30", "5.256431"], ["83959.80", "4.350150"], ["83951.30", "4.440778"], ["83942.80", "4.712662"], ["83934.30", "4.078265"], ["83925.80", "4.622034"], ["83917.30", "5.347059"], ["83908.80", "3.987637"], ["83900.30", "4.893918"], ["83891.80", "4.531406"], ["83883.30", "5.075175"], ["83874.80", "4.984547"], ["83866.30", "5.618943"], ["83857.80", "4.259522"], ["83849.30", "4.168894"], ["83840.80", "5.437687"], ["83832.30", "4.803290"], ["83823.80", "3.897009"], ["83703.00", "0"]], "checksum": -197754959, "ts": "1742584883696"}], "ts": 1742584883698, "record_time": 1742584883.807297, "EXCHANGE": "BITGET"}
{"action": "update", "arg": {"instType": "SPOT", "channel": "books", "instId": "BTCUSDT"}, "data": [{"asks": [["84057.01", "2.425805"], ["84112.00", "1.735170"], ["84113.10", "0.004650"], ["84116.40", "0.070860"], ["84153.50", "4.984547"], ["84162.00", "5.256431"], ["84170.50", "4.893918"], ["84179.00", "4.078265"], ["84187.50", "5.075175"], ["84196.00", "5.347059"], ["84204.50", "4.803290"], ["84213.00", "5.165803"], ["84221.50", "4.712662"], ["84230.00", "4.622034"], ["84241.14", "0.169564"], ["84247.00", "5.618943"], ["84255.50", "3.987637"], ["84264.00", "4.168894"], ["84272.50", "4.440778"], ["84281.00", "4.259522"], ["84289.50", "4.350150"], ["84298.00", "5.528315"], ["84306.50", "3.897009"], ["84315.00", "5.437687"], ["84560.00", "0"], ["84561.11", "0"], ["84561.58", "0"]], "bids": [["84045.23", "0"], ["84007.00", "0"], ["83985.30", "4.984547"], ["83976.80", "4.622034"], ["83968.30", "4.168894"], ["83959.80", "4.803290"], ["83951.30", "5.528315"], ["83942.80", "5.075175"], ["83934.30", "5.618943"], ["83925.80", "5.347059"], ["83917.30", "4.531406"], ["83908.80", "4.440778"], ["83900.30", "4.350150"], ["83891.80", "3.897009"], ["83883.30", "5.256431"], ["83874.80", "4.259522"], ["83866.30", "4.712662"], ["83857.80", "4.078265"], ["83849.30", "5.437687"], ["83840.80", "5.165803"], ["83832.30", "3.987637"], ["83823.80", "4.893918"], ["83703.00", "0.000024"], ["83702.93", "0.000050"]], "checksum": -2005203645, "ts": "1742584883897"}], "ts": 1742584883900, "record_time": 1742584884.014274, "EXCHANGE": "BITGET"}
{"action": "update", "arg": {"instType": "SPOT", "channel": "books", "instId": "BTCUSDT"}, "data": [{"asks": [["84076.58", "0.006357"], ["84076.83", "0.006357"], ["84077.39", "0.006357"], ["84077.74", "0.006357"], ["84078.67", "0.006357"], ["84079.12", "0.006357"], ["84079.18", "0.016429"], ["84079.69", "0.119901"], ["84080.11", "0.016429"], ["84081.12", "0"], ["84081.27", "0"], ["84081.29", "0"], ["84081.40", "0.010993"], ["84081.79", "0.006357"], ["84082.13", "0"], ["84082.26", "0.009990"], ["84083.10", "0"], ["84083.65", "0"], ["84083.68", "0"], ["84084.18", "0.119858"], ["84084.28", "0"], ["84084.63", "0.015895"], ["84084.83", "0"], ["84085.21", "0.009989"], ["84085.90", "0"], ["84086.12", "0"], ["84086.33", "0"], ["84086.78", "0.006356"], ["84088.74", "0"], ["84088.86", "0"], ["84089.63", "0"], ["84091.36", "0"], ["84108.73", "0.001598"], ["84110.56", "0.001598"], ["84112.54", "0"], ["84114.15", "0"], ["84114.60", "0.536970"], ["84153.50", "4.712662"], ["84162.00", "4.350150"], ["84179.00", "5.256431"], ["84187.50", "4.622034"], ["84196.00", "4.440778"], ["84204.50", "5.347059"], ["84213.00", "3.897009"], ["84221.50", "4.531406"], ["84230.00", "5.528315"], ["84238.50", "4.259522"], ["84255.50", "5.165803"], ["84264.00", "4.984547"], ["84272.50", "5.075175"], ["84281.00", "5.437687"], ["84289.50", "4.168894"], ["84298.00", "3.987637"], ["84306.50", "4.803290"], ["84315.00", "4.078265"], ["84405.65", "1.722358"], ["84412.39", "0"]], "bids": [["84052.88", "0.035633"], ["84052.74", "0"], ["84036.72", "0"], ["84036.33", "0"], ["84036.23", "0"], ["84035.56", "0"], ["84034.52", "0"], ["84034.09", "0"], ["84033.72", "0"], ["84033.55", "0"], ["84033.00", "0.000281"], ["84032.28", "0.017797"], ["84031.83", "0.005940"], ["84031.70", "0.018242"], ["84031.48", "0"], ["84031.27", "0"], ["84031.17", "0.016406"], ["84030.09", "0.007129"], ["84030.01", "0"], ["84029.59", "0.028827"], ["84029.19", "0.017086"], ["84028.84", "0.025157"], ["84028.68", "0"], ["84028.42", "0.224676"], ["84028.27", "0"], ["84027.71", "0"], ["84027.15", "0.012653"], ["84026.77", "0.051761"], ["84025.96", "0"], ["84025.94", "0.018518"], ["84024.00", "0.222846"], ["84023.85", "0.021131"], ["84023.61", "0.076118"], ["84021.39", "0.012439"], ["84002.26", "0"], ["84000.00", "0.002000"], ["83998.45", "0.001175"], ["83996.42", "0.001172"], ["83985.30", "5.347059"], ["83976.80", "4.531406"], ["83968.30", "5.256431"], ["83959.80", "3.897009"], ["83951.30", "3.987637"], ["83942.80", "4.712662"], ["83934.30", "4.259522"], ["83925.80", "4.803290"], ["83917.30", "4.168894"], ["83908.80", "4.893918"], ["83900.30", "4.622034"], ["83891.80", "4.078265"], ["83883.30", "5.075175"], ["83874.80", "5.528315"], ["83866.30", "5.618943"], ["83857.80", "4.440778"], ["83849.30", "4.984547"], ["83840.80", "5.437687"], ["83832.30", "5.165803"], ["83823.80", "4.350150"], ["83739.78", "0"], ["83733.08", "1.595641"], ["83702.93", "0"]], "checksum": -2127017481, "ts": "1742584884099"}], "ts": 1742584884103, "record_time": 1742584884.240945, "EXCHANGE": "BITGET"}
{"action": "update", "arg": {"instType": "SPOT", "channel": "books", "instId": "BTCUSDT"}, "data": [{"asks": [["84057.01", "2.456632"], ["84088.85", "0.039280"], ["84112.10", "1.418400"], ["84112.80", "0.101130"], ["84115.40", "2.356200"], ["84153.50", "5.256431"], ["84162.00", "3.987637"], ["84170.50", "5.075175"], ["84179.00", "4.984547"], ["84187.50", "4.531406"], ["84196.00", "5.165803"], ["84204.50", "4.078265"], ["84213.00", "4.259522"], ["84221.50", "5.618943"], ["84230.00", "5.347059"], ["84238.50", "5.528315"], ["84247.00", "4.712662"], ["84255.50", "4.350150"], ["84264.00", "4.893918"], ["84272.50", "3.897009"], ["84281.00", "4.803290"], ["84289.50", "5.437687"], ["84298.00", "4.168894"], ["84306.50", "4.440778"], ["84315.00", "4.622034"], ["84559.47", "0"]], "bids": [["84036.73", "0"], ["83976.80", "4.168894"], ["83968.30", "5.437687"], ["83959.80", "4.259522"], ["83942.80", "4.803290"], ["83934.30", "4.078265"], ["83925.80", "4.893918"], ["83917.30", "4.531406"], ["83908.80", "5.165803"], ["83900.30", "3.897009"], ["83891.80", "5.528315"], ["83883.30", "5.618943"], ["83874.80", "4.984547"], ["83866.30", "4.622034"], ["83857.80", "4.712662"], ["83849.30", "5.075175"], ["83840.80", "4.440778"], ["83832.30", "4.350150"], ["83823.80", "5.256431"], ["83749.65", "0"], ["83702.93", "0.000050"], ["83702.60", "0.000039"]], "checksum": 318654539, "ts": "1742584884305"}], "ts": 1742584884308, "record_time": 1742584884.41657, "EXCHANGE": "BITGET"}
{"action": "update", "arg": {"instType": "SPOT", "channel": "books", "instId": "BTCUSDT"}, "data": [{"asks": [["84113.79", "0.037519"], ["84153.50", "5.437687"], ["84162.00", "5.347059"], ["84179.00", "5.165803"], ["84187.50", "4.078265"], ["84196.00", "4.168894"], ["84204.50", "4.440778"], ["84221.50", "3.987637"], ["84230.00", "4.803290"], ["84238.50", "4.622034"], ["84247.00", "4.984547"], ["84255.50", "4.712662"], ["84264.00", "3.897009"], ["84272.50", "5.528315"], ["84281.00", "4.350150"], ["84289.50", "5.256431"], ["84298.00", "4.531406"], ["84306.50", "4.893918"], ["84315.00", "5.618943"], ["84559.10", "0"]], "bids": [["84057.00", "0.015281"], ["83985.30", "4.803290"], ["83976.80", "4.712662"], ["83968.30", "4.259522"], ["83959.80", "5.437687"], ["83951.30", "5.347059"], ["83942.80", "4.440778"], ["83925.80", "5.165803"], ["83917.30", "4.984547"], ["83908.80", "3.897009"], ["83900.30", "4.893918"], ["83891.80", "5.256431"], ["83883.30", "5.528315"], ["83874.80", "4.531406"], ["83866.30", "4.168894"], ["83857.80", "4.350150"], ["83848.20", "0.203519"], ["83840.80", "4.622034"], ["83832.30", "3.987637"], ["83823.80", "5.618943"], ["83720.77", "0.001536"], ["83702.93", "0"], ["83702.60", "0"]], "checksum": -1504430558, "ts": "1742584884507"}], "ts": 1742584884510, "record_time": 1742584884.619505, "EXCHANGE": "BITGET"}
{"action": "update", "arg": {"instType": "SPOT", "channel": "books", "instId": "BTCUSDT"}, "data": [{"asks": [["84093.50", "0.001433"], ["84095.50", "0.003773"], ["84097.50", "0.009928"], ["84099.50", "0.026127"], ["84101.50", "0.068755"], ["84103.50", "0.180934"], ["84105.50", "0.476143"], ["84107.50", "1.253006"], ["84109.50", "3.297384"], ["84111.50", "8.677086"], ["84112.80", "0.101880"], ["84113.10", "0"], ["84153.50", "4.350150"], ["84162.00", "4.531406"], ["84170.50", "5.618943"], ["84179.00", "4.984547"], ["84187.50", "4.803290"], ["84196.00", "4.259522"], ["84204.50", "5.347059"], ["84213.00", "4.078265"], ["84221.50", "5.075175"], ["84230.00", "5.437687"], ["84238.50", "4.893918"], ["84247.00", "4.712662"], ["84255.50", "5.528315"], ["84264.00", "3.987637"], ["84272.50", "5.165803"], ["84281.00", "4.168894"], ["84289.50", "4.622034"], ["84298.00", "5.256431"], ["84306.50", "4.440778"], ["84315.00", "3.897009"], ["84559.10", "0.000036"]], "bids": [["84053.05", "0.035633"], ["84052.88", "0"], ["84037.31", "0.021157"], ["83985.30", "5.256431"], ["83976.80", "4.803290"], ["83968.30", "4.893918"], ["83959.80", "5.165803"], ["83951.30", "4.259522"], ["83942.80", "3.897009"], ["83934.30", "4.622034"], ["83925.80", "5.347059"], ["83917.30", "3.987637"], ["83908.80", "4.350150"], ["83900.30", "4.531406"], ["83891.80", "5.618943"], ["83883.30", "5.075175"], ["83874.80", "4.440778"], ["83866.30", "4.712662"], ["83857.80", "4.168894"], ["83849.30", "5.528315"], ["83840.80", "5.437687"], ["83832.30", "4.078265"], ["83823.80", "4.984547"], ["83703.00", "0"]], "checksum": -1278909547, "ts": "1742584884712"}], "ts": 1742584884715, "record_time": 1742584884.824416, "EXCHANGE": "BITGET"}
{"action": "update", "arg": {"instType": "SPOT", "channel": "books", "instId": "BTCUSDT"}, "data": [{"asks": [["84093.50", "0.001015"], ["84095.50", "0.002211"], ["84097.50", "0.005818"], ["84099.50", "0.015310"], ["84101.50", "0.040289"], ["84103.50", "0.106025"], ["84105.50", "0.279014"], ["84107.50", "0.734247"], ["84109.50", "1.932229"], ["84111.50", "5.084812"], ["84112.00", "0.961500"], ["84112.10", "0.068010"], ["84112.80", "0"], ["84113.70", "0.420390"], ["84113.80", "0.688650"], ["84115.40", "0"], ["84116.40", "0"], ["84116.90", "1.245660"], ["84118.20", "0.102510"], ["84118.90", "0"], ["84119.00", "2.356110"], ["84124.10", "0.035670"], ["84124.20", "2.179890"], ["84124.30", "0.015960"], ["84153.50", "5.618943"], ["84162.00", "4.259522"], ["84170.50", "4.168894"], ["84179.00", "5.347059"], ["84187.50", "4.440778"], ["84196.00", "5.528315"], ["84204.50", "4.712662"], ["84221.50", "4.531406"], ["84230.00", "5.075175"], ["84247.00", "3.897009"], ["84255.50", "4.803290"], ["84264.00", "5.437687"], ["84272.50", "4.350150"], ["84281.00", "4.622034"], ["84289.50", "3.987637"], ["84306.50", "4.984547"], ["84315.00", "5.165803"], ["84460.00", "0.000756"]], "bids": [["84043.30", "0.001499"], ["84041.30", "0.003944"], ["84039.30", "0.010381"], ["84037.30", "0.027317"], ["84035.30", "0.071887"], ["84033.30", "0.189176"], ["84033.00", "0.257962"], ["84031.30", "0.497831"], ["84029.30", "1.310082"], ["84027.30", "3.447584"], ["84027.20", "0.001029"], ["84026.30", "0.089580"], ["84026.00", "0.101400"], ["84025.60", "0.030720"], ["84023.00", "0.191640"], ["84021.90", "0.068100"], ["83985.30", "4.259522"], ["83976.80", "4.078265"], ["83968.30", "4.984547"], ["83959.80", "3.897009"], ["83951.30", "5.075175"], ["83942.80", "4.712662"], ["83934.30", "5.165803"], ["83925.80", "5.528315"], ["83917.30", "5.618943"], ["83908.80", "5.347059"], ["83900.30", "4.893918"], ["83891.80", "3.987637"], ["83883.30", "4.622034"], ["83866.30", "4.168894"], ["83857.80", "5.437687"], ["83849.30", "5.256431"], ["83840.80", "4.803290"], ["83832.30", "4.350150"], ["83823.80", "4.531406"], ["83703.75", "0"], ["83703.70", "0"]], "checksum": 280090386, "ts": "1742584884917"}], "ts": 1742584884922, "record_time": 1742584885.045891, "EXCHANGE": "BITGET"}
{"action": "update", "arg": {"instType": "SPOT", "channel": "books", "instId": "BTCUSDT"}, "data": [{"asks": [["84101.49", "0"], ["84112.00", "0.556440"], ["84112.40", "0.330810"], ["84112.50", "0.321990"], ["84113.70", "0.420000"], ["84113.80", "0"], ["84117.20", "2.356140"], ["84118.20", "0.124770"], ["84119.00", "0"], ["84124.30", "0"], ["84153.49", "0.074715"], ["84153.50", "4.984547"], ["84162.00", "5.437687"], ["84179.00", "4.893918"], ["84187.50", "5.347059"], ["84196.00", "4.712662"], ["84204.50", "4.531406"], ["84213.00", "5.618943"], ["84221.50", "4.350150"], ["84230.00", "4.078265"], ["84238.50", "5.075175"], ["84247.00", "5.528315"], ["84255.50", "4.440778"], ["84264.00", "5.165803"], ["84272.50", "4.622034"], ["84281.00", "3.897009"], ["84306.50", "4.259522"], ["84315.00", "4.803290"], ["84465.00", "0.000144"]], "bids": [["84053.18", "0.035633"], ["84053.05", "0"], ["84037.31", "0.030420"], ["84006.00", "0"], ["83985.30", "5.256431"], ["83976.80", "5.347059"], ["83968.30", "5.528315"], ["83959.80", "5.618943"], ["83951.30", "4.531406"], ["83942.80", "4.350150"], ["83934.30", "4.984547"], ["83925.80", "4.893918"], ["83917.30", "4.078265"], ["83908.80", "5.075175"], ["83900.30", "3.987637"], ["83891.80", "4.803290"], ["83883.30", "4.440778"], ["83874.80", "4.168894"], ["83866.30", "5.437687"], ["83857.80", "4.712662"], ["83849.30", "4.622034"], ["83840.80", "5.165803"], ["83832.30", "4.259522"], ["83823.80", "3.897009"], ["83703.75", "0.000363"]], "checksum": 1961361343, "ts": "1742584885126"}], "ts": 1742584885129, "record_time": 1742584885.239002, "EXCHANGE": "BITGET"}
{"action": "update", "arg": {"instType": "SPOT", "channel": "books", "instId": "BTCUSDT"}, "data": [{"asks": [["84095.50", "0.002575"], ["84097.50", "0.006775"], ["84099.50", "0.017830"], ["84101.50", "0.046922"], ["84103.50", "0.123478"], ["84105.50", "0.324941"], ["84107.50", "0.855110"], ["84109.50", "2.250289"], ["84111.50", "5.921812"], ["84111.90", "0.397380"], ["84112.00", "0.556230"], ["84112.40", "0"], ["84112.50", "0"], ["84113.70", "0.420210"], ["84118.20", "0.138180"], ["84124.30", "0.015960"], ["84124.40", "0.009600"], ["84153.50", "4.350150"], ["84162.00", "4.531406"], ["84170.50", "4.622034"], ["84179.00", "5.256431"], ["84187.50", "4.168894"], ["84196.00", "5.618943"], ["84204.50", "5.528315"], ["84213.00", "5.165803"], ["84221.50", "4.803290"], ["84230.00", "5.075175"], ["84238.50", "5.347059"], ["84247.00", "5.437687"], ["84264.00", "3.987637"], ["84272.50", "4.712662"], ["84281.00", "4.893918"], ["84289.50", "4.984547"], ["84298.00", "3.897009"], ["84306.50", "4.078265"], ["84315.00", "4.259522"], ["84470.00", "0"], ["84559.47", "0.000010"]], "bids": [["84057.00", "0.015100"], ["84045.31", "0.001100"], ["84043.30", "0.001136"], ["84041.30", "0.002990"], ["84039.30", "0.007869"], ["84037.30", "0.020709"], ["84035.30", "0.054496"], ["84033.30", "0.143410"], ["84031.30", "0.377395"], ["84029.30", "0.993146"], ["84027.30", "2.613542"], ["84023.00", "0.176640"], ["83985.30", "4.259522"], ["83976.80", "4.803290"], ["83968.30", "4.531406"], ["83959.80", "4.350150"], ["83951.30", "4.440778"], ["83942.80", "5.165803"], ["83934.30", "4.893918"], ["83925.80", "5.437687"], ["83917.30", "3.897009"], ["83908.80", "4.168894"], ["83900.30", "5.528315"], ["83891.80", "5.075175"], ["83883.30", "5.256431"], ["83874.80", "3.987637"], ["83866.30", "4.078265"], ["83849.30", "4.984547"], ["83840.80", "5.347059"], ["83832.30", "4.622034"], ["83823.80", "5.618943"], ["83703.75", "0"]], "checksum": -856960374, "ts": "1742584885330"}], "ts": 1742584885338, "record_time": 1742584885.455682, "EXCHANGE": "BITGET"}
{"action": "update", "arg": {"instType": "SPOT", "channel": "books", "instId": "BTCUSDT"}, "data": [{"asks": [["84084.97", "0.119905"], ["84088.84", "0.015896"], ["84089.66", "0.010988"], ["84089.73", "0"], ["84093.73", "0"], ["84094.48", "0"], ["84095.50", "0.002191"], ["84097.50", "0.005766"], ["84099.50", "0.015174"], ["84101.50", "0.039931"], ["84103.50", "0.105081"], ["84105.50", "0.276531"], ["84107.50", "0.727713"], ["84109.50", "1.915032"], ["84109.78", "0.382294"], ["84111.50", "5.039558"], ["84112.00", "0.349500"], ["84153.50", "3.987637"], ["84162.00", "4.440778"], ["84170.50", "4.893918"], ["84179.00", "4.531406"], ["84187.50", "5.347059"], ["84196.00", "5.437687"], ["84213.00", "5.075175"], ["84221.50", "4.984547"], ["84230.00", "4.168894"], ["84238.50", "4.622034"], ["84247.00", "5.165803"], ["84255.50", "5.618943"], ["84264.00", "4.078265"], ["84272.50", "5.256431"], ["84281.00", "4.259522"], ["84289.50", "4.803290"], ["84298.00", "4.350150"], ["84306.50", "3.897009"], ["84315.00", "4.712662"]], "bids": [["84041.01", "0"], ["84035.46", "0.004030"], ["84029.21", "0"], ["84028.44", "0.867892"], ["84024.81", "0"], ["84024.45", "0.258784"], ["84023.87", "0"], ["84022.38", "0"], ["84019.92", "0.073065"], ["84019.05", "0.056371"], ["84017.38", "0.000877"], ["84004.12", "0"], ["83998.86", "0.003597"], ["83985.30", "4.078265"], ["83976.80", "5.165803"], ["83968.30", "5.618943"], ["83959.80", "4.440778"], ["83951.30", "5.075175"], ["83942.80", "3.897009"], ["83934.30", "4.350150"], ["83925.80", "3.987637"], ["83917.30", "4.803290"], ["83900.30", "4.531406"], ["83891.80", "4.622034"], ["83874.80", "5.437687"], ["83866.30", "5.347059"], ["83857.80", "4.893918"], ["83849.30", "4.259522"], ["83840.80", "4.984547"], ["83832.30", "5.528315"], ["83823.80", "4.712662"], ["83705.18", "0"]], "checksum": 1679135450, "ts": "1742584885530"}], "ts": 1742584885534, "record_time": 1742584885.643268, "EXCHANGE": "BITGET"}
{"action": "update", "arg": {"instType": "SPOT", "channel": "books", "instId": "BTCUSDT"}, "data": [{"asks": [["84084.17", "0.169127"], ["84084.75", "0"], ["84088.85", "0"], ["84124.20", "3.435150"], ["84153.49", "0"], ["84153.50", "4.168894"], ["84162.00", "4.803290"], ["84170.50", "5.256431"], ["84179.00", "5.437687"], ["84187.50", "5.165803"], ["84196.00", "4.893918"], ["84204.50", "4.078265"], ["84213.00", "5.528315"], ["84221.50", "4.350150"], ["84230.00", "4.984547"], ["84238.50", "3.987637"], ["84247.00", "3.897009"], ["84255.50", "4.440778"], ["84264.00", "5.075175"], ["84272.50", "5.618943"], ["84281.00", "4.531406"], ["84289.50", "4.712662"], ["84298.00", "4.622034"], ["84306.50", "5.347059"], ["84315.00", "4.259522"], ["84560.00", "0.000265"], ["84561.11", "0.000134"]], "bids": [["84053.31", "0.035633"], ["84053.18", "0"], ["84043.30", "0.001759"], ["84041.30", "0.004628"], ["84039.30", "0.012179"], ["84037.30", "0.032050"], ["84035.30", "0.084344"], ["84033.30", "0.221957"], ["84031.30", "0.584098"], ["84029.30", "1.537099"], ["84027.30", "4.044998"], ["84007.00", "0.000160"], ["83985.30", "3.987637"], ["83976.80", "5.347059"], ["83968.30", "5.165803"], ["83959.80", "5.075175"], ["83951.30", "4.259522"], ["83942.80", "4.168894"], ["83934.30", "4.078265"], ["83925.80", "5.437687"], ["83917.30", "4.712662"], ["83908.80", "5.256431"], ["83900.30", "4.622034"], ["83891.80", "4.893918"], ["83883.30", "4.803290"], ["83874.80", "5.618943"], ["83866.30", "4.350150"], ["83857.80", "5.528315"], ["83849.30", "4.531406"], ["83840.80", "4.440778"], ["83832.30", "4.984547"], ["83823.80", "3.897009"], ["83705.32", "0"]], "checksum": -499999734, "ts": "1742584885734"}], "ts": 1742584885737, "record_time": 1742584885.846633, "EXCHANGE": "BITGET"}
{"action": "update", "arg": {"instType": "SPOT", "channel": "books", "instId": "BTCUSDT"}, "data": [{"asks": [["84115.20", "2.356200"], ["84117.20", "0"], ["84153.50", "4.531406"], ["84162.00", "5.347059"], ["84170.50", "4.078265"], ["84179.00", "4.984547"], ["84187.50", "4.259522"], ["84196.00", "5.528315"], ["84204.50", "5.256431"], ["84213.00", "5.075175"], ["84221.50", "3.987637"], ["84230.00", "5.618943"], ["84238.50", "5.437687"], ["84247.00", "5.165803"], ["84255.50", "4.622034"], ["84264.00", "4.350150"], ["84272.50", "3.897009"], ["84281.00", "4.440778"], ["84289.50", "4.168894"], ["84298.00", "4.893918"], ["84306.50", "4.803290"], ["84315.00", "4.712662"]], "bids": [["84054.17", "0"], ["84045.31", "0"], ["84043.30", "0.001136"], ["84041.30", "0.002990"], ["84039.30", "0.007869"], ["84037.30", "0.020709"], ["84035.30", "0.054496"], ["84033.30", "0.143410"], ["84031.30", "0.377395"], ["84029.30", "0.993146"], ["84027.30", "2.613542"], ["84027.10", "0.029940"], ["83985.30", "4.350150"], ["83976.80", "4.622034"], ["83968.30", "5.347059"], ["83959.80", "4.803290"], ["83951.30", "5.618943"], ["83942.80", "4.259522"], ["83934.30", "3.987637"], ["83925.80", "4.712662"], ["83917.30", "5.075175"], ["83908.80", "4.168894"], ["83900.30", "5.437687"], ["83891.80", "4.984547"], ["83883.30", "5.256431"], ["83874.80", "4.893918"], ["83866.30", "4.531406"], ["83857.80", "4.078265"], ["83849.30", "4.440778"], ["83840.80", "5.165803"], ["83832.30", "3.897009"], ["83823.80", "5.528315"], ["83705.32", "0.000065"], ["83705.18", "0.000009"]], "checksum": -786463364, "ts": "1742584885939"}], "ts": 1742584885942, "record_time": 1742584886.053394, "EXCHANGE": "BITGET"}
{"action": "update", "arg": {"instType": "SPOT", "channel": "books", "instId": "BTCUSDT"}, "data": [{"asks": [["84092.06", "0"], ["84103.50", "0.105082"], ["84105.50", "0.276532"], ["84107.50", "0.727715"], ["84109.50", "1.915039"], ["84111.50", "5.039577"], ["84112.00", "1.012830"], ["84116.90", "0.620790"], ["84153.50", "5.075175"], ["84162.00", "5.165803"], ["84170.50", "5.347059"], ["84179.00", "5.256431"], ["84196.00", "5.437687"], ["84204.50", "3.897009"], ["84213.00", "5.618943"], ["84221.50", "4.803290"], ["84230.00", "4.440778"], ["84238.50", "4.622034"], ["84247.00", "4.168894"], ["84255.50", "4.712662"], ["84264.00", "5.528315"], ["84272.50", "4.350150"], ["84281.00", "4.531406"], ["84289.50", "4.984547"], ["84306.50", "4.078265"], ["84315.00", "3.987637"], ["84561.58", "0.003678"]], "bids": [["84055.05", "0.010367"], ["84053.31", "0"], ["84048.85", "0.010000"], ["84031.30", "0.377548"], ["84030.00", "0.002160"], ["84029.30", "0.993549"], ["84028.44", "0.017106"], ["84027.30", "2.614602"], ["84023.00", "0.071160"], ["83985.30", "5.165803"], ["83976.80", "4.350150"], ["83968.30", "4.984547"], ["83959.80", "5.437687"], ["83951.30", "4.893918"], ["83942.80", "4.440778"], ["83934.30", "4.622034"], ["83925.80", "5.618943"], ["83917.30", "3.897009"], ["83908.80", "5.075175"], ["83900.30", "5.528315"], ["83891.80", "4.168894"], ["83883.30", "5.347059"], ["83874.80", "4.259522"], ["83866.30", "4.078265"], ["83857.80", "4.712662"], ["83849.30", "4.803290"], ["83840.80", "3.987637"], ["83832.30", "4.531406"], ["83823.80", "5.256431"], ["83705.18", "0"]], "checksum": -1811649440, "ts": "1742584886139"}], "ts": 1742584886143, "record_time": 1742584886.25207, "EXCHANGE": "BITGET"}
{"action": "update", "arg": {"instType": "SPOT", "channel": "books", "instId": "BTCUSDT"}, "data": [{"asks": [["84057.01", "2.403432"], ["84095.50", "0.002523"], ["84097.50", "0.006638"], ["84099.50", "0.017469"], ["84101.50", "0.045971"], ["84103.50", "0.120977"], ["84105.50", "0.318361"], ["84107.50", "0.837792"], ["84109.50", "2.204714"], ["84111.50", "5.801879"], ["84123.50", "0.057900"], ["84124.40", "0"], ["84153.50", "4.350150"], ["84162.00", "5.528315"], ["84170.50", "3.897009"], ["84179.00", "4.259522"], ["84187.50", "4.622034"], ["84196.00", "5.256431"], ["84204.50", "4.078265"], ["84221.50", "4.440778"], ["84230.00", "4.893918"], ["84238.50", "4.531406"], ["84247.00", "5.075175"], ["84255.50", "5.347059"], ["84264.00", "4.803290"], ["84272.50", "3.987637"], ["84281.00", "4.984547"], ["84289.50", "4.712662"], ["84298.00", "5.437687"], ["84306.50", "4.168894"], ["84315.00", "5.165803"]], "bids": [["84053.46", "0.035633"], ["84035.30", "0.054246"], ["84033.30", "0.142754"], ["84031.30", "0.375669"], ["84029.30", "0.988601"], ["84028.44", "0.868992"], ["84027.30", "2.601582"], ["83985.30", "3.987637"], ["83976.80", "4.622034"], ["83968.30", "4.803290"], ["83959.80", "5.528315"], ["83951.30", "4.350150"], ["83942.80", "4.078265"], ["83934.30", "4.893918"], ["83925.80", "5.437687"], ["83900.30", "4.984547"], ["83891.80", "5.256431"], ["83874.80", "4.440778"], ["83866.30", "4.712662"], ["83857.80", "4.531406"], ["83849.30", "4.168894"], ["83840.80", "4.259522"], ["83832.30", "5.618943"], ["83823.80", "5.165803"], ["83705.32", "0"]], "checksum": 340848519, "ts": "1742584886355"}], "ts": 1742584886358, "record_time": 1742584886.471637, "EXCHANGE": "BITGET"}
{"action": "update", "arg": {"instType": "SPOT", "channel": "books", "instId": "BTCUSDT"}, "data": [{"asks": [["84073.34", "0"], ["84073.69", "0"], ["84074.60", "0.035957"], ["84074.95", "0"], ["84075.06", "0.119905"], ["84076.25", "0"], ["84076.32", "0.035972"], ["84076.98", "0"], ["84077.01", "0.209200"], ["84077.23", "0"], ["84077.58", "0.006357"], ["84078.28", "0.006357"], ["84078.30", "0"], ["84078.33", "0.010995"], ["84078.39", "0"], ["84078.52", "0"], ["84078.59", "0.006356"], ["84078.87", "0"], ["84078.94", "0"], ["84079.32", "0.006357"], ["84079.76", "0.006357"], ["84079.79", "0.006357"], ["84079.93", "0"], ["84080.24", "0.058205"], ["84080.28", "0.006357"], ["84081.19", "0.006357"], ["84082.12", "0"], ["84083.51", "0.119850"], ["84088.83", "0.008374"], ["84153.50", "5.528315"], ["84162.00", "5.618943"], ["84170.50", "4.350150"], ["84179.00", "5.256431"], ["84196.00", "5.165803"], ["84204.50", "4.803290"], ["84213.00", "4.531406"], ["84221.50", "4.259522"], ["84230.00", "4.078265"], ["84238.50", "4.440778"], ["84247.00", "5.437687"], ["84255.50", "4.712662"], ["84264.00", "5.075175"], ["84272.50", "5.347059"], ["84281.00", "4.168894"], ["84289.50", "4.893918"], ["84298.00", "3.987637"], ["84306.50", "4.984547"], ["84315.00", "3.897009"], ["84561.58", "0"]], "bids": [["84034.25", "0.089533"], ["84033.88", "0.247134"], ["84032.99", "0"], ["84032.61", "0.083499"], ["84032.51", "0.014985"], ["84031.35", "0.015724"], ["84031.25", "0"], ["84030.70", "0.006561"], ["84030.59", "0.055545"], ["84030.35", "0.017095"], ["84030.02", "0"], ["84029.73", "0.007335"], ["84029.41", "0"], ["84029.27", "0"], ["84029.19", "0.025028"], ["84029.16", "0.008995"], ["84028.98", "0"], ["84028.71", "0"], ["84028.67", "0.008187"], ["84028.63", "0.017348"], ["84027.92", "0"], ["84027.79", "0"], ["84027.57", "0.008276"], ["84027.33", "0"], ["84027.26", "0"], ["84025.35", "0.268397"], ["84023.96", "0"], ["84006.00", "0.000160"], ["83985.30", "5.256431"], ["83976.80", "5.165803"], ["83968.30", "4.712662"], ["83959.80", "4.168894"], ["83951.30", "4.440778"], ["83942.80", "3.897009"], ["83934.30", "4.531406"], ["83925.80", "5.075175"], ["83917.30", "5.618943"], ["83908.80", "5.347059"], ["83900.30", "4.803290"], ["83891.80", "4.893918"], ["83883.30", "4.984547"], ["83874.80", "5.437687"], ["83866.30", "4.078265"], ["83857.80", "4.259522"], ["83849.30", "4.350150"], ["83840.80", "5.528315"], ["83832.30", "4.622034"], ["83823.80", "3.987637"], ["83706.67", "0"], ["83705.85", "0"]], "checksum": 1042926963, "ts": "1742584886563"}], "ts": 1742584886569, "record_time": 1742584886.680031, "EXCHANGE": "BITGET"}
{"action": "update", "arg": {"instType": "SPOT", "channel": "books", "instId": "BTCUSDT"}, "data": [{"asks": [["84095.50", "0.002886"], ["84097.50", "0.007596"], ["84099.50", "0.019989"], ["84101.50", "0.052601"], ["84103.50", "0.138426"], ["84105.50", "0.364279"], ["84107.50", "0.958627"], ["84109.50", "2.522704"], ["84111.50", "6.638693"], ["84122.90", "0.026880"], ["84153.50", "5.075175"], ["84162.00", "4.350150"], ["84170.50", "5.528315"], ["84179.00", "4.984547"], ["84187.50", "4.712662"], ["84204.50", "4.531406"], ["84213.00", "4.440778"], ["84221.50", "4.078265"], ["84230.00", "3.987637"], ["84238.50", "5.618943"], ["84247.00", "5.256431"], ["84255.50", "4.622034"], ["84264.00", "4.259522"], ["84281.00", "4.803290"], ["84289.50", "3.897009"], ["84298.00", "4.893918"], ["84306.50", "4.168894"], ["84315.00", "5.437687"], ["84561.11", "0"]], "bids": [["84053.58", "0.035633"], ["84053.46", "0"], ["84037.31", "0.124197"], ["84028.00", "0.000281"], ["84027.00", "0.000281"], ["84025.00", "0.000281"], ["84024.00", "0.222967"], ["84022.00", "0.000281"], ["84021.00", "0.000281"], ["84020.00", "0.000281"], ["84019.00", "0.000281"], ["84017.00", "0.000281"], ["84016.00", "0.000281"], ["84015.00", "0.000281"], ["84014.00", "0.000281"], ["84013.00", "0.000281"], ["84012.00", "0.000281"], ["84011.00", "0.000281"], ["84010.00", "0.000281"], ["84009.00", "0.000281"], ["84008.00", "0.000281"], ["83985.30", "5.347059"], ["83976.80", "5.618943"], ["83968.30", "5.165803"], ["83959.80", "4.350150"], ["83951.30", "4.803290"], ["83942.80", "4.622034"], ["83934.30", "5.256431"], ["83925.80", "4.259522"], ["83917.30", "4.078265"], ["83908.80", "4.893918"], ["83900.30", "4.531406"], ["83891.80", "3.897009"], ["83883.30", "4.712662"], ["83874.80", "4.984547"], ["83866.30", "5.528315"], ["83857.80", "5.437687"], ["83849.30", "3.987637"], ["83840.80", "4.440778"], ["83832.30", "5.075175"], ["83823.80", "4.168894"]], "checksum": 450646052, "ts": "1742584886764"}], "ts": 1742584886768, "record_time": 1742584886.876326, "EXCHANGE": "BITGET"}
{"action": "update", "arg": {"instType": "SPOT", "channel": "books", "instId": "BTCUSDT"}, "data": [{"asks": [["84093.50", "0.001280"], ["84095.50", "0.003482"], ["84097.50", "0.009162"], ["84099.50", "0.024111"], ["84101.50", "0.063450"], ["84103.50", "0.166975"], ["84105.50", "0.439407"], ["84107.50", "1.156335"], ["84109.50", "3.042986"], ["84111.50", "8.007858"], ["84113.10", "0.035880"], ["84113.50", "0.269760"], ["84113.70", "0.420000"], ["84116.40", "0.071700"], ["84117.00", "0"], ["84124.20", "0"], ["84124.30", "0"], ["84153.50", "3.987637"], ["84162.00", "4.803290"], ["84170.50", "3.897009"], ["84187.50", "5.075175"], ["84196.00", "4.893918"], ["84204.50", "5.437687"], ["84213.00", "4.622034"], ["84221.50", "5.347059"], ["84230.00", "4.259522"], ["84238.50", "4.168894"], ["84247.00", "5.618943"], ["84255.50", "4.078265"], ["84264.00", "5.256431"], ["84272.50", "4.440778"], ["84281.00", "4.712662"], ["84289.50", "5.165803"], ["84298.00", "5.528315"], ["84306.50", "4.531406"], ["84315.00", "4.350150"], ["84460.00", "0.000063"]], "bids": [["84057.00", "0.000160"], ["84055.05", "0"], ["84043.30", "0.001019"], ["84041.30", "0.001013"], ["84039.30", "0.001006"], ["84037.30", "0.001796"], ["84035.30", "0.004727"], ["84033.30", "0.012439"], ["84031.30", "0.032735"], ["84029.30", "0.086145"], ["84027.30", "0.226697"], ["84027.10", "0.006690"], ["84026.00", "0.101610"], ["84025.60", "0"], ["84025.20", "0.226350"], ["84023.80", "0.510060"], ["83985.30", "4.440778"], ["83976.80", "4.984547"], ["83968.30", "4.803290"], ["83959.80", "5.075175"], ["83951.30", "5.618943"], ["83942.80", "5.165803"], ["83934.30", "3.987637"], ["83925.80", "5.437687"], ["83917.30", "4.259522"], ["83908.80", "4.622034"], ["83900.30", "4.168894"], ["83891.80", "4.531406"], ["83883.30", "4.350150"], ["83874.80", "3.897009"], ["83866.30", "4.893918"], ["83857.80", "4.078265"], ["83849.30", "5.256431"], ["83840.80", "5.528315"], ["83832.30", "5.347059"], ["83823.80", "4.712662"], ["83706.67", "0.000013"]], "checksum": -1201051218, "ts": "1742584886977"}], "ts": 1742584886980, "record_time": 1742584887.088358, "EXCHANGE": "BITGET"}
{"action": "update", "arg": {"instType": "SPOT", "channel": "books", "instId": "BTCUSDT"}, "data": [{"asks": [["84057.01", "2.076222"], ["84079.27", "0"], ["84081.16", "0"], ["84107.50", "1.156195"], ["84109.50", "3.042618"], ["84111.50", "8.006891"], ["84112.00", "1.012620"], ["84113.10", "0.035670"], ["84116.40", "0"], ["84124.10", "0"], ["84153.50", "4.984547"], ["84162.00", "5.528315"], ["84170.50", "4.712662"], ["84179.00", "3.987637"], ["84187.50", "4.440778"], ["84196.00", "4.803290"], ["84204.50", "5.075175"], ["84213.00", "4.893918"], ["84221.50", "4.622034"], ["84230.00", "4.078265"], ["84238.50", "5.347059"], ["84247.00", "4.531406"], ["84255.50", "5.256431"], ["84264.00", "4.259522"], ["84272.50", "5.618943"], ["84281.00", "3.897009"], ["84289.50", "4.168894"], ["84298.00", "5.437687"], ["84306.50", "5.165803"], ["84561.11", "0.000134"], ["84561.58", "0.003678"], ["84562.50", "0.006969"], ["84565.22", "0.003438"]], "bids": [["84057.00", "0.608489"], ["84053.58", "0"], ["84039.30", "0.001724"], ["84037.30", "0.004537"], ["84035.30", "0.011941"], ["84033.30", "0.031423"], ["84033.00", "0.101354"], ["84031.30", "0.082692"], ["84029.30", "0.217609"], ["84027.30", "0.572396"], ["84024.50", "0.009000"], ["84024.00", "0.977820"], ["84016.70", "0.498420"], ["84007.84", "0"], ["84007.00", "0"], ["83985.30", "4.893918"], ["83976.80", "5.256431"], ["83968.30", "5.165803"], ["83959.80", "3.987637"], ["83951.30", "5.347059"], ["83942.80", "5.618943"], ["83934.30", "4.078265"], ["83925.80", "4.622034"], ["83917.30", "5.528315"], ["83908.80", "5.437687"], ["83900.30", "4.259522"], ["83891.80", "4.984547"], ["83883.30", "4.168894"], ["83874.80", "4.803290"], ["83866.30", "5.075175"], ["83857.80", "4.712662"], ["83849.30", "3.897009"], ["83840.80", "4.531406"], ["83832.30", "4.350150"], ["83823.80", "4.440778"], ["83705.85", "0.000019"], ["83705.32", "0.000065"]], "checksum": 556399786, "ts": "1742584887184"}], "ts": 1742584887187, "record_time": 1742584887.298292, "EXCHANGE": "BITGET"}
{"action": "update", "arg": {"instType": "SPOT", "channel": "books", "instId": "BTCUSDT"}, "data": [{"asks": [["84057.01", "2.403432"], ["84093.50", "0.001041"], ["84095.50", "0.002064"], ["84097.50", "0.005431"], ["84098.89", "0.013838"], ["84099.50", "0.014038"], ["84101.50", "0.036943"], ["84103.50", "0.097217"], ["84105.50", "0.255836"], ["84107.50", "0.673252"], ["84109.50", "1.771714"], ["84111.50", "4.662406"], ["84111.70", "0.027420"], ["84111.90", "0.006690"], ["84112.00", "0.349290"], ["84113.10", "0"], ["84113.50", "0"], ["84113.70", "0.420210"], ["84115.20", "0"], ["84116.60", "0.490320"], ["84118.20", "0.132930"], ["84120.00", "0.424800"], ["84124.10", "0.035670"], ["84124.20", "3.435150"], ["84152.71", "0.010000"], ["84153.50", "4.712662"], ["84162.00", "4.622034"], ["84170.50", "4.350150"], ["84179.00", "4.078265"], ["84187.50", "4.168894"], ["84196.00", "5.618943"], ["84204.50", "4.893918"], ["84213.00", "5.528315"], ["84221.50", "5.075175"], ["84230.00", "5.347059"], ["84238.50", "3.987637"], ["84247.00", "5.256431"], ["84255.50", "4.259522"], ["84264.00", "4.440778"], ["84272.50", "4.531406"], ["84281.00", "5.437687"], ["84289.50", "3.897009"], ["84298.00", "4.803290"], ["84315.00", "4.984547"], ["84562.50", "0"], ["84565.22", "0"]], "bids": [["84055.34", "0.010367"], ["84053.72", "0.035633"], ["84043.30", "0.002291"], ["84041.30", "0.005776"], ["84039.30", "0.015199"], ["84037.30", "0.039998"], ["84035.30", "0.105259"], ["84033.30", "0.276996"], ["84031.30", "0.728937"], ["84029.30", "1.918255"], ["84028.44", "0"], ["84027.30", "5.048040"], ["84026.10", "0.128580"], ["84026.00", "0.101400"], ["84025.60", "0.035670"], ["84025.20", "0.446670"], ["84024.00", "0.222967"], ["84023.80", "0.443820"], ["84023.20", "0.025716"], ["84021.90", "0.173040"], ["84018.00", "2.448540"], ["83985.30", "3.897009"], ["83976.80", "3.987637"], ["83959.80", "4.259522"], ["83953.94", "0.005855"], ["83951.30", "4.168894"], ["83942.80", "5.528315"], ["83934.30", "4.440778"], ["83917.30", "5.347059"], ["83908.80", "5.256431"], ["83900.30", "4.984547"], ["83891.80", "4.350150"], ["83883.30", "5.437687"], ["83866.30", "5.618943"], ["83857.80", "4.893918"], ["83849.30", "4.078265"], ["83832.30", "4.712662"], ["83823.80", "5.075175"], ["83710.00", "0"], ["83706.90", "0"], ["83706.67", "0"], ["83705.85", "0"], ["83705.32", "0"]], "checksum": -563526712, "ts": "1742584887385"}], "ts": 1742584887388, "record_time": 1742584887.502624, "EXCHANGE": "BITGET"}
{"action": "update", "arg": {"instType": "SPOT", "channel": "books", "instId": "BTCUSDT"}, "data": [{"asks": [["84079.32", "0.187709"], ["84095.50", "0.001947"], ["84097.50", "0.005355"], ["84099.50", "0.014093"], ["84101.50", "0.037085"], ["84103.50", "0.097471"], ["84105.50", "0.256504"], ["84107.22", "0.067994"], ["84107.50", "0.675011"], ["84109.50", "1.776344"], ["84109.78", "0.648681"], ["84111.50", "4.674589"], ["84111.70", "0.001024"], ["84112.00", "0.348660"], ["84118.20", "0.379230"], ["84120.40", "1.659360"], ["84121.00", "3.956670"], ["84124.10", "0"], ["84124.20", "0"], ["84153.50", "4.350150"], ["84162.00", "3.987637"], ["84170.50", "4.440778"], ["84179.00", "5.165803"], ["84187.50", "3.897009"], ["84196.00", "5.437687"], ["84204.50", "5.075175"], ["84213.00", "4.531406"], ["84221.50", "4.803290"], ["84230.00", "4.984547"], ["84238.50", "5.528315"], ["84247.00", "4.712662"], ["84255.50", "4.078265"], ["84264.00", "5.256431"], ["84272.50", "5.347059"], ["84281.00", "4.893918"], ["84289.50", "4.259522"], ["84298.00", "5.618943"], ["84306.50", "4.622034"], ["84315.00", "4.168894"], ["84562.50", "0.006969"], ["84565.22", "0.003438"]], "bids": [["84045.31", "0.001337"], ["84043.30", "0.001864"], ["84041.30", "0.004905"], ["84039.30", "0.012908"], ["84037.30", "0.033969"], ["84035.30", "0.089393"], ["84033.30", "0.235245"], ["84031.30", "0.619064"], ["84029.30", "1.629118"], ["84027.30", "4.287151"], ["83985.30", "4.350150"], ["83976.80", "5.347059"], ["83968.30", "5.075175"], ["83959.80", "4.712662"], ["83951.30", "4.803290"], ["83942.80", "4.531406"], ["83934.30", "5.437687"], ["83925.80", "4.440778"], ["83917.30", "4.078265"], ["83908.80", "4.622034"], ["83900.30", "4.168894"], ["83891.80", "5.165803"], ["83883.30", "3.987637"], ["83874.80", "5.256431"], ["83866.30", "5.528315"], ["83857.80", "3.897009"], ["83849.30", "5.618943"], ["83840.80", "4.984547"], ["83832.30", "4.259522"], ["83823.80", "4.893918"], ["83713.33", "0"]], "checksum": 1939903594, "ts": "1742584887586"}], "ts": 1742584887588, "record_time": 1742584887.700666, "EXCHANGE": "BITGET"}
{"action": "update", "arg": {"instType": "SPOT", "channel": "books", "instId": "BTCUSDT"}, "data": [{"asks": [["84153.50", "4.893918"], ["84170.50", "4.531406"], ["84179.00", "4.350150"], ["84187.50", "5.347059"], ["84196.00", "3.897009"], ["84204.50", "4.803290"], ["84213.00", "4.622034"], ["84221.50", "5.618943"], ["84230.00", "5.165803"], ["84238.50", "4.078265"], ["84255.50", "4.259522"], ["84264.00", "5.528315"], ["84272.50", "5.256431"], ["84281.00", "4.168894"], ["84289.50", "4.440778"], ["84298.00", "5.075175"], ["84306.50", "5.437687"], ["84315.00", "4.984547"]], "bids": [["84053.83", "0.035633"], ["84053.72", "0"], ["84033.00", "0.264619"], ["84031.30", "0.618818"], ["84030.00", "0.002281"], ["84029.30", "1.628467"], ["84027.30", "4.285440"], ["84007.00", "0.000121"], ["84005.00", "0.000160"], ["83985.30", "4.803290"], ["83976.80", "3.987637"], ["83968.30", "3.897009"], ["83959.80", "5.347059"], ["83951.30", "4.984547"], ["83942.80", "4.440778"], ["83934.30", "4.259522"], ["83925.80", "5.528315"], ["83917.30", "5.618943"], ["83908.80", "4.712662"], ["83900.30", "5.075175"], ["83883.30", "4.350150"], ["83874.80", "4.622034"], ["83866.30", "4.531406"], ["83857.80", "4.168894"], ["83849.30", "4.078265"], ["83840.80", "5.437687"], ["83832.30", "5.256431"], ["83713.71", "0"], ["83713.64", "0"]], "checksum": -1094362346, "ts": "1742584887787"}], "ts": 1742584887790, "record_time": 1742584887.898547, "EXCHANGE": "BITGET"}
{"action": "update", "arg": {"instType": "SPOT", "channel": "books", "instId": "BTCUSDT"}, "data": [{"asks": [["84107.50", "0.674892"], ["84109.50", "1.776033"], ["84111.50", "4.673771"], ["84123.10", "0.192000"], ["84153.50", "4.531406"], ["84170.50", "5.528315"], ["84179.00", "5.256431"], ["84187.50", "4.350150"], ["84196.00", "5.165803"], ["84204.50", "4.168894"], ["84213.00", "4.803290"], ["84221.50", "4.984547"], ["84230.00", "5.347059"], ["84247.00", "3.897009"], ["84255.50", "4.893918"], ["84264.00", "4.259522"], ["84272.50", "4.440778"], ["84281.00", "4.622034"], ["84289.50", "5.075175"], ["84298.00", "4.712662"], ["84315.00", "5.618943"], ["84565.22", "0"]], "bids": [["84028.43", "0.976421"], ["83985.30", "5.528315"], ["83976.80", "4.893918"], ["83968.30", "5.347059"], ["83959.80", "3.987637"], ["83951.30", "5.618943"], ["83942.80", "4.712662"], ["83938.35", "0"], ["83934.30", "4.350150"], ["83925.80", "5.075175"], ["83917.30", "3.897009"], ["83914.20", "0.125636"], ["83908.80", "5.437687"], ["83900.30", "5.165803"], ["83891.80", "4.259522"], ["83883.30", "4.531406"], ["83874.80", "4.168894"], ["83866.30", "4.440778"], ["83857.80", "4.078265"], ["83849.30", "5.256431"], ["83840.80", "4.984547"], ["83832.30", "4.803290"], ["83823.80", "4.622034"]], "checksum": -1094362346, "ts": "1742584887991"}], "ts": 1742584887994, "record_time": 1742584888.10168, "EXCHANGE": "BITGET"}
{"action": "update", "arg": {"instType": "SPOT", "channel": "books", "instId": "BTCUSDT"}, "data": [{"asks": [["84095.00", "0.010000"], ["84095.50", "0.002396"], ["84097.50", "0.006305"], ["84099.50", "0.016592"], ["84101.50", "0.043663"], ["84103.50", "0.114902"], ["84105.50", "0.302375"], ["84107.50", "0.795723"], ["84109.50", "2.094008"], ["84111.50", "5.510548"], ["84116.90", "1.192410"], ["84118.20", "0.384480"], ["84119.20", "2.356110"], ["84120.40", "1.096410"], ["84121.00", "1.600620"], ["84123.40", "0.064860"], ["84123.80", "0"], ["84153.50", "4.078265"], ["84162.00", "5.437687"], ["84170.50", "3.897009"], ["84179.00", "3.987637"], ["84187.50", "5.165803"], ["84196.00", "4.893918"], ["84204.50", "4.984547"], ["84213.00", "5.075175"], ["84221.50", "4.350150"], ["84230.00", "4.803290"], ["84238.50", "4.531406"], ["84247.00", "4.712662"], ["84255.50", "4.440778"], ["84272.50", "5.347059"], ["84281.00", "4.168894"], ["84289.50", "5.256431"], ["84298.00", "5.528315"], ["84306.50", "5.618943"], ["84315.00", "4.622034"], ["84561.58", "0"], ["84562.50", "0"]], "bids": [["84057.00", "0.608400"], ["84055.53", "0.010376"], ["84055.34", "0"], ["84048.85", "0"], ["84045.31", "0"], ["84043.30", "0.001541"], ["84041.30", "0.004055"], ["84039.30", "0.010670"], ["84037.30", "0.028080"], ["84035.30", "0.073894"], ["84033.30", "0.194459"], ["84031.30", "0.511733"], ["84029.30", "1.346666"], ["84027.30", "3.543858"], ["84027.20", "0.350490"], ["84027.10", "0.006480"], ["84027.00", "0.066690"], ["84026.30", "0.089370"], ["84026.10", "0.128370"], ["84025.20", "0"], ["84024.50", "0"], ["84023.20", "0"], ["84023.00", "0.086160"], ["84018.00", "1.675020"], ["84011.68", "0.025716"], ["84006.00", "0"], ["83985.30", "4.531406"], ["83976.80", "5.347059"], ["83968.30", "5.528315"], ["83959.80", "5.437687"], ["83951.30", "4.350150"], ["83942.80", "5.075175"], ["83934.30", "4.259522"], ["83925.80", "4.078265"], ["83917.30", "4.622034"], ["83908.80", "5.256431"], ["83900.30", "4.803290"], ["83891.80", "5.165803"], ["83883.30", "4.440778"], ["83874.80", "3.987637"], ["83866.30", "4.168894"], ["83857.80", "3.897009"], ["83849.30", "4.893918"], ["83832.30", "4.712662"], ["83823.80", "5.618943"], ["83713.71", "0.000323"], ["83713.64", "0.000192"], ["83713.33", "0.000008"], ["83710.00", "0.000642"], ["83706.90", "0.000016"]], "checksum": 2111411571, "ts": "1742584888192"}], "ts": 1742584888196, "record_time": 1742584888.305907, "EXCHANGE": "BITGET"}
{"action": "update", "arg": {"instType": "SPOT", "channel": "books", "instId": "BTCUSDT"}, "data": [{"asks": [["84097.50", "0.006560"], ["84099.50", "0.017265"], ["84101.50", "0.045432"], ["84103.50", "0.119558"], ["84105.50", "0.314491"], ["84107.50", "0.827607"], ["84109.50", "2.177912"], ["84111.50", "5.731348"], ["84114.70", "0.022710"], ["84116.00", "0"], ["84153.50", "5.165803"], ["84162.00", "4.622034"], ["84179.00", "5.256431"], ["84187.50", "4.168894"], ["84196.00", "4.350150"], ["84213.00", "5.437687"], ["84221.50", "4.259522"], ["84230.00", "5.528315"], ["84238.50", "4.078265"], ["84247.00", "4.531406"], ["84255.50", "4.712662"], ["84264.00", "4.893918"], ["84272.50", "3.987637"], ["84281.00", "5.347059"], ["84289.50", "5.075175"], ["84298.00", "4.803290"], ["84306.50", "4.440778"], ["84315.00", "5.618943"]], "bids": [["84053.94", "0.035633"], ["84053.83", "0"], ["84029.30", "1.346553"], ["84028.43", "0.977758"], ["84027.30", "3.543560"], ["83985.30", "4.259522"], ["83976.80", "4.984547"], ["83968.30", "5.618943"], ["83959.80", "5.347059"], ["83951.30", "5.256431"], ["83942.80", "5.528315"], ["83934.30", "4.893918"], ["83925.80", "5.165803"], ["83917.30", "4.168894"], ["83908.80", "5.437687"], ["83900.30", "4.440778"], ["83891.80", "4.078265"], ["83883.30", "5.075175"], ["83874.80", "4.622034"], ["83866.30", "4.350150"], ["83857.80", "3.987637"], ["83849.30", "3.897009"], ["83840.80", "4.531406"], ["83823.80", "4.803290"]], "checksum": 1094125443, "ts": "1742584888410"}], "ts": 1742584888413, "record_time": 1742584888.522174, "EXCHANGE": "BITGET"}
{"action": "update", "arg": {"instType": "SPOT", "channel": "books", "instId": "BTCUSDT"}, "data": [{"asks": [["84107.22", "0.309204"], ["84153.50", "4.168894"], ["84162.00", "5.256431"], ["84170.50", "4.984547"], ["84179.00", "4.259522"], ["84187.50", "3.987637"], ["84196.00", "5.528315"], ["84204.50", "5.618943"], ["84213.00", "4.803290"], ["84221.50", "5.075175"], ["84230.00", "4.350150"], ["84238.50", "5.437687"], ["84247.00", "4.440778"], ["84255.50", "3.897009"], ["84272.50", "5.165803"], ["84281.00", "4.622034"], ["84289.50", "4.712662"], ["84298.00", "4.078265"], ["84306.50", "4.531406"], ["84315.00", "5.347059"]], "bids": [["84027.30", "3.543821"], ["83985.30", "5.618943"], ["83976.80", "4.350150"], ["83968.30", "4.259522"], ["83959.80", "5.256431"], ["83951.30", "5.437687"], ["83942.80", "4.622034"], ["83934.30", "4.168894"], ["83917.30", "4.893918"], ["83908.80", "5.528315"], ["83900.30", "4.078265"], ["83891.80", "3.987637"], ["83883.30", "4.984547"], ["83874.80", "5.347059"], ["83866.30", "4.803290"], ["83857.80", "4.712662"], ["83840.80", "5.075175"], ["83832.30", "4.531406"], ["83823.80", "4.440778"]], "checksum": 1094125443, "ts": "1742584888611"}], "ts": 1742584888615, "record_time": 1742584888.730103, "EXCHANGE": "BITGET"}
{"action": "update", "arg": {"instType": "SPOT", "channel": "books", "instId": "BTCUSDT"}, "data": [{"asks": [["84095.50", "0.002128"], ["84097.50", "0.005600"], ["84099.50", "0.014737"], ["84101.50", "0.038780"], ["84103.50", "0.102054"], ["84105.50", "0.268563"], ["84107.50", "0.706744"], ["84109.50", "1.859852"], ["84109.78", "0.382294"], ["84111.50", "4.894348"], ["84114.30", "0.490320"], ["84116.60", "0"], ["84153.50", "4.712662"], ["84162.00", "4.440778"], ["84170.50", "5.618943"], ["84179.00", "4.168894"], ["84187.50", "5.437687"], ["84196.00", "4.622034"], ["84204.50", "4.803290"], ["84213.00", "3.987637"], ["84221.50", "5.256431"], ["84230.00", "4.984547"], ["84238.50", "4.893918"], ["84247.00", "4.350150"], ["84264.00", "4.259522"], ["84272.50", "5.528315"], ["84281.00", "5.075175"], ["84289.50", "5.165803"], ["84298.00", "5.347059"], ["84306.50", "4.078265"], ["84315.00", "4.531406"]], "bids": [["84053.94", "0"], ["84007.00", "0.000281"], ["83985.30", "4.078265"], ["83976.80", "3.987637"], ["83968.30", "4.531406"], ["83959.80", "4.712662"], ["83951.30", "5.528315"], ["83942.80", "5.165803"], ["83934.30", "4.350150"], ["83925.80", "3.897009"], ["83917.30", "5.256431"], ["83908.80", "4.168894"], ["83900.30", "5.347059"], ["83891.80", "4.893918"], ["83883.30", "4.440778"], ["83874.80", "5.618943"], ["83866.30", "5.075175"], ["83857.80", "4.984547"], ["83849.30", "5.437687"], ["83840.80", "4.259522"], ["83832.30", "4.803290"], ["83823.80", "4.622034"], ["83706.67", "0.000013"]], "checksum": -1881454618, "ts": "1742584888815"}], "ts": 1742584888819, "record_time": 1742584888.92794, "EXCHANGE": "BITGET"}
{"action": "update", "arg": {"instType": "SPOT", "channel": "books", "instId": "BTCUSDT"}, "data": [{"asks": [["84057.01", "2.403251"], ["84153.50", "4.078265"], ["84162.00", "4.984547"], ["84170.50", "4.168894"], ["84179.00", "5.618943"], ["84187.50", "5.256431"], ["84196.00", "5.347059"], ["84204.50", "5.437687"], ["84213.00", "4.350150"], ["84221.50", "3.987637"], ["84230.00", "4.440778"], ["84238.50", "4.259522"], ["84247.00", "5.165803"], ["84255.50", "4.622034"], ["84264.00", "3.897009"], ["84272.50", "4.712662"], ["84281.00", "4.803290"], ["84289.50", "4.531406"], ["84298.00", "5.075175"], ["84306.50", "5.528315"], ["84315.00", "4.893918"]], "bids": [["84054.04", "0.035633"], ["84006.00", "0.000121"], ["83985.30", "4.168894"], ["83976.80", "5.528315"], ["83968.30", "3.987637"], ["83959.80", "4.893918"], ["83951.30", "4.803290"], ["83942.80", "4.622034"], ["83934.30", "5.075175"], ["83925.80", "4.440778"], ["83917.30", "4.984547"], ["83908.80", "4.531406"], ["83900.30", "4.712662"], ["83891.80", "4.259522"], ["83883.30", "5.256431"], ["83866.30", "3.897009"], ["83857.80", "5.437687"], ["83849.30", "5.347059"], ["83840.80", "4.350150"], ["83832.30", "4.078265"], ["83823.80", "5.165803"], ["83706.90", "0"], ["83706.67", "0"]], "checksum": -114214999, "ts": "1742584889017"}], "ts": 1742584889021, "record_time": 1742584889.135258, "EXCHANGE": "BITGET"}
{"action": "update", "arg": {"instType": "SPOT", "channel": "books", "instId": "BTCUSDT"}, "data": [{"asks": [["84057.01", "2.403238"], ["84076.58", "0"], ["84076.83", "0"], ["84077.05", "0.006357"], ["84077.10", "0.006357"], ["84077.39", "0"], ["84077.58", "0.012714"], ["84077.74", "0"], ["84078.01", "0.006357"], ["84078.67", "0"], ["84079.00", "0.006357"], ["84079.12", "0"], ["84079.18", "0"], ["84079.44", "0.016429"], ["84079.62", "0.006357"], ["84079.69", "0"], ["84080.11", "0"], ["84080.24", "0.178106"], ["84080.40", "0.016429"], ["84081.40", "0"], ["84081.79", "0"], ["84081.93", "0.010993"], ["84082.09", "0.006357"], ["84082.26", "0"], ["84082.80", "0.009990"], ["84084.18", "0"], ["84084.63", "0"], ["84084.73", "0.119858"], ["84085.15", "0.015895"], ["84085.21", "0"], ["84085.44", "0.009989"], ["84086.78", "0"], ["84087.31", "0.006356"], ["84095.50", "0.001946"], ["84097.50", "0.005122"], ["84099.50", "0.013479"], ["84101.50", "0.035470"], ["84103.50", "0.093343"], ["84105.50", "0.245640"], ["84107.50", "0.646420"], ["84108.73", "0"], ["84109.19", "0.001598"], ["84109.50", "1.701105"], ["84110.56", "0"], ["84110.98", "0.001598"], ["84111.50", "4.476592"], ["84153.50", "4.259522"], ["84162.00", "5.347059"], ["84179.00", "4.803290"], ["84187.50", "5.618943"], ["84196.00", "4.531406"], ["84204.50", "4.984547"], ["84213.00", "4.440778"], ["84221.50", "4.622034"], ["84230.00", "4.712662"], ["84238.50", "5.165803"], ["84247.00", "4.893918"], ["84255.50", "5.528315"], ["84272.50", "5.075175"], ["84281.00", "5.256431"], ["84289.50", "3.987637"], ["84298.00", "4.350150"], ["84306.50", "5.437687"], ["84315.00", "4.078265"], ["84561.58", "0.003678"], ["84562.50", "0.006969"]], "bids": [["84032.50", "0.017797"], ["84032.28", "0"], ["84032.21", "0.018242"], ["84032.03", "0.005940"], ["84031.83", "0"], ["84031.70", "0"], ["84031.45", "0.016406"], ["84031.17", "0"], ["84030.42", "0.007129"], ["84030.09", "0"], ["84029.85", "0.028827"], ["84029.69", "0.017086"], ["84029.59", "0"], ["84029.19", "0.007942"], ["84029.13", "0.025157"], ["84028.97", "0.224676"], ["84028.84", "0"], ["84028.42", "0"], ["84027.45", "0.012653"], ["84027.29", "0.051761"], ["84027.15", "0"], ["84027.00", "0.000281"], ["84026.77", "0"], ["84026.49", "0.018518"], ["84026.30", "0.089580"], ["84025.94", "0"], ["84024.55", "0.222686"], ["84024.13", "0.076118"], ["84024.08", "0.021131"], ["84024.00", "0.000281"], ["84023.85", "0"], ["84023.61", "0"], ["84021.92", "0.012439"], ["84021.39", "0"], ["83998.91", "0.001175"], ["83998.45", "0"], ["83996.83", "0.001172"], ["83996.42", "0"], ["83985.30", "5.075175"], ["83976.80", "4.531406"], ["83968.30", "5.256431"], ["83959.80", "3.987637"], ["83951.30", "4.893918"], ["83942.80", "5.165803"], ["83934.30", "4.803290"], ["83925.80", "4.078265"], ["83917.30", "4.350150"], ["83908.80", "3.897009"], ["83900.30", "4.168894"], ["83891.80", "4.712662"], ["83883.30", "4.984547"], ["83866.30", "5.528315"], ["83857.80", "4.440778"], ["83840.80", "4.622034"], ["83832.30", "4.259522"], ["83823.80", "5.437687"], ["83713.33", "0"], ["83710.00", "0"]], "checksum": -1141846699, "ts": "1742584889223"}], "ts": 1742584889227, "record_time": 1742584889.336308, "EXCHANGE": "BITGET"}
{"action": "update", "arg": {"instType": "SPOT", "channel": "books", "instId": "BTCUSDT"}, "data": [{"asks": [["84080.23", "0.090777"], ["84080.24", "0.126258"], ["84099.50", "0.013718"], ["84101.50", "0.036100"], ["84103.50", "0.095001"], ["84105.50", "0.250002"], ["84107.50", "0.657899"], ["84109.50", "1.731313"], ["84111.50", "4.556089"], ["84153.50", "4.712662"], ["84162.00", "3.897009"], ["84170.50", "4.078265"], ["84187.50", "4.350150"], ["84196.00", "5.618943"], ["84204.50", "4.168894"], ["84213.00", "3.987637"], ["84221.50", "5.165803"], ["84230.00", "4.893918"], ["84238.50", "5.347059"], ["84247.00", "5.075175"], ["84255.50", "4.259522"], ["84264.00", "4.531406"], ["84272.50", "5.437687"], ["84281.00", "5.528315"], ["84289.50", "4.440778"], ["84298.00", "4.622034"], ["84306.50", "4.984547"], ["84315.00", "5.256431"], ["84562.50", "0"]], "bids": [["84054.14", "0.035633"], ["84054.04", "0"], ["84023.00", "0.101160"], ["83985.30", "3.897009"], ["83976.80", "5.165803"], ["83968.30", "4.803290"], ["83959.80", "5.528315"], ["83951.30", "4.350150"], ["83942.80", "4.531406"], ["83934.30", "5.347059"], ["83925.80", "5.618943"], ["83917.30", "4.168894"], ["83908.80", "4.259522"], ["83900.30", "5.256431"], ["83891.80", "4.984547"], ["83883.30", "4.712662"], ["83874.80", "4.622034"], ["83866.30", "4.078265"], ["83857.80", "3.987637"], ["83849.30", "4.893918"], ["83840.80", "5.075175"], ["83832.30", "5.437687"], ["83823.80", "4.440778"]], "checksum": -369152789, "ts": "1742584889428"}], "ts": 1742584889431, "record_time": 1742584889.540051, "EXCHANGE": "BITGET"}
{"action": "update", "arg": {"instType": "SPOT", "channel": "books", "instId": "BTCUSDT"}, "data": [{"asks": [["84079.32", "0.006357"], ["84095.50", "0.002219"], ["84097.50", "0.005840"], ["84099.50", "0.015367"], ["84101.49", "0.039330"], ["84101.50", "0.040440"], ["84103.50", "0.106422"], ["84105.50", "0.280057"], ["84107.50", "0.736992"], ["84109.50", "1.939452"], ["84111.50", "5.103821"], ["84111.80", "0.012840"], ["84111.90", "0.006480"], ["84118.20", "0.348810"], ["84146.15", "0.001810"], ["84155.22", "0.003620"], ["84162.00", "4.622034"], ["84170.50", "5.075175"], ["84179.00", "4.984547"], ["84187.50", "4.078265"], ["84196.00", "4.803290"], ["84204.50", "5.528315"], ["84213.00", "4.893918"], ["84221.50", "4.350150"], ["84230.00", "4.259522"], ["84238.50", "5.256431"], ["84247.00", "5.347059"], ["84255.50", "5.437687"], ["84264.00", "3.897009"], ["84272.50", "5.618943"], ["84281.00", "3.987637"], ["84289.50", "4.531406"], ["84298.00", "5.165803"], ["84306.50", "4.440778"], ["84315.00", "4.168894"], ["84559.47", "0"], ["84560.00", "0"], ["84561.11", "0"], ["84561.58", "0"]], "bids": [["84043.30", "0.002164"], ["84041.30", "0.005693"], ["84039.30", "0.014982"], ["84037.30", "0.039427"], ["84035.30", "0.103756"], ["84033.30", "0.273042"], ["84031.30", "0.718532"], ["84029.30", "1.890874"], ["84027.30", "4.975984"], ["84007.00", "0.000160"], ["84005.00", "0"], ["83985.30", "3.987637"], ["83976.80", "4.350150"], ["83968.30", "4.531406"], ["83959.80", "4.893918"], ["83956.86", "0.001810"], ["83951.30", "5.347059"], ["83948.46", "0.003620"], ["83942.80", "5.165803"], ["83934.30", "4.168894"], ["83925.80", "4.622034"], ["83917.30", "5.618943"], ["83908.80", "4.078265"], ["83900.30", "5.528315"], ["83891.80", "4.440778"], ["83883.30", "4.984547"], ["83874.80", "5.256431"], ["83866.30", "4.712662"], ["83857.80", "3.897009"], ["83849.30", "4.259522"], ["83832.30", "4.803290"], ["83823.80", "5.437687"], ["83713.64", "0"]], "checksum": 1307621678, "ts": "1742584889628"}], "ts": 1742584889630, "record_time": 1742584889.739625, "EXCHANGE": "BITGET"}
{"action": "update", "arg": {"instType": "SPOT", "channel": "books", "instId": "BTCUSDT"}, "data": [{"asks": [["84079.24", "0.179483"], ["84103.50", "0.106318"], ["84105.50", "0.279786"], ["84107.50", "0.736277"], ["84109.50", "1.937572"], ["84111.50", "5.098874"], ["84153.50", "4.622034"], ["84162.00", "4.984547"], ["84170.50", "4.712662"], ["84179.00", "5.437687"], ["84187.50", "4.803290"], ["84196.00", "4.893918"], ["84204.50", "4.078265"], ["84213.00", "4.531406"], ["84221.50", "5.618943"], ["84230.00", "4.350150"], ["84238.50", "4.259522"], ["84247.00", "3.987637"], ["84255.50", "4.168894"], ["84264.00", "5.075175"], ["84272.50", "4.440778"], ["84281.00", "5.347059"], ["84289.50", "5.256431"], ["84298.00", "5.528315"], ["84306.50", "3.897009"], ["84315.00", "5.165803"], ["84559.10", "0"]], "bids": [["84054.14", "0"], ["84027.30", "4.975853"], ["83985.30", "4.350150"], ["83976.80", "4.893918"], ["83968.30", "4.712662"], ["83959.80", "4.803290"], ["83951.30", "4.984547"], ["83942.80", "4.259522"], ["83925.80", "3.987637"], ["83917.30", "4.078265"], ["83908.80", "4.531406"], ["83900.30", "5.165803"], ["83891.80", "5.075175"], ["83883.30", "5.618943"], ["83874.80", "4.440778"], ["83866.30", "5.347059"], ["83857.80", "5.528315"], ["83849.30", "3.897009"], ["83840.80", "5.437687"], ["83832.30", "5.256431"], ["83823.80", "4.622034"], ["83713.64", "0.000192"]], "checksum": 220254052, "ts": "1742584889832"}], "ts": 1742584889837, "record_time": 1742584889.946207, "EXCHANGE": "BITGET"}
{"action": "update", "arg": {"instType": "SPOT", "channel": "books", "instId": "BTCUSDT"}, "data": [{"asks": [["84095.50", "0.002033"], ["84097.50", "0.005349"], ["84099.50", "0.014076"], ["84101.50", "0.037043"], ["84103.50", "0.097483"], ["84105.50", "0.256534"], ["84107.50", "0.675088"], ["84109.50", "1.776549"], ["84111.50", "4.675129"], ["84111.80", "0.001027"], ["84153.50", "4.078265"], ["84162.00", "3.987637"], ["84170.50", "4.531406"], ["84179.00", "5.075175"], ["84187.50", "4.350150"], ["84196.00", "5.618943"], ["84204.50", "4.168894"], ["84213.00", "4.712662"], ["84221.50", "3.897009"], ["84230.00", "5.528315"], ["84238.50", "4.803290"], ["84247.00", "5.256431"], ["84255.50", "4.893918"], ["84264.00", "4.622034"], ["84272.50", "4.259522"], ["84289.50", "4.440778"], ["84298.00", "4.984547"], ["84306.50", "5.165803"], ["84315.00", "5.437687"]], "bids": [["84054.26", "0.035632"], ["84043.30", "0.001541"], ["84041.30", "0.004054"], ["84039.30", "0.010670"], ["84037.30", "0.028078"], ["84035.30", "0.073890"], ["84033.30", "0.194448"], ["84031.30", "0.511703"], ["84029.30", "1.346589"], ["84027.30", "3.543653"], ["83985.30", "5.528315"], ["83976.80", "5.437687"], ["83968.30", "3.987637"], ["83959.80", "5.075175"], ["83951.30", "4.078265"], ["83942.80", "5.165803"], ["83925.80", "4.622034"], ["83917.30", "4.440778"], ["83908.80", "5.618943"], ["83900.30", "4.893918"], ["83891.80", "3.897009"], ["83883.30", "4.984547"], ["83874.80", "4.259522"], ["83866.30", "5.256431"], ["83857.80", "5.347059"], ["83849.30", "4.803290"], ["83840.80", "4.531406"], ["83832.30", "4.350150"], ["83823.80", "4.712662"], ["83713.64", "0"]], "checksum": 605018676, "ts": "1742584890035"}], "ts": 1742584890039, "record_time": 1742584890.157417, "EXCHANGE": "BITGET"}
{"action": "update", "arg": {"instType": "SPOT", "channel": "books", "instId": "BTCUSDT"}, "data": [{"asks": [["84095.00", "0"], ["84114.30", "0"], ["84118.20", "0.353640"], ["84123.80", "0.144000"], ["84153.50", "4.893918"], ["84162.00", "4.259522"], ["84170.50", "3.987637"], ["84179.00", "4.078265"], ["84187.50", "4.622034"], ["84196.00", "5.165803"], ["84213.00", "4.350150"], ["84221.50", "5.256431"], ["84230.00", "4.440778"], ["84247.00", "4.984547"], ["84255.50", "4.531406"], ["84264.00", "5.075175"], ["84272.50", "4.712662"], ["84281.00", "3.897009"], ["84289.50", "5.528315"], ["84298.00", "5.347059"], ["84306.50", "5.618943"], ["84559.10", "0.000036"]], "bids": [["84049.52", "0.010000"], ["84023.00", "0.086160"], ["84006.00", "0.000281"], ["84005.00", "0.000121"], ["83985.30", "4.078265"], ["83976.80", "4.440778"], ["83968.30", "4.803290"], ["83959.80", "5.437687"], ["83951.30", "4.893918"], ["83942.80", "5.528315"], ["83934.30", "4.350150"], ["83925.80", "4.712662"], ["83917.30", "5.165803"], ["83908.80", "3.897009"], ["83900.30", "5.347059"], ["83891.80", "4.984547"], ["83883.30", "5.618943"], ["83866.30", "5.075175"], ["83857.80", "4.622034"], ["83849.30", "4.531406"], ["83840.80", "4.168894"], ["83832.30", "5.256431"], ["83823.80", "3.987637"], ["83713.80", "0"], ["83713.71", "0"]], "checksum": 1717416505, "ts": "1742584890245"}], "ts": 1742584890249, "record_time": 1742584890.360904, "EXCHANGE": "BITGET"}
{"action": "update", "arg": {"instType": "SPOT", "channel": "books", "instId": "BTCUSDT"}, "data": [{"asks": [["84095.50", "0.002165"], ["84097.50", "0.005697"], ["84099.50", "0.014992"], ["84101.50", "0.039452"], ["84103.50", "0.103821"], ["84105.50", "0.273215"], ["84107.50", "0.718986"], ["84109.50", "1.892068"], ["84111.50", "4.979127"], ["84153.50", "4.078265"], ["84162.00", "4.984547"], ["84170.50", "5.528315"], ["84179.00", "5.618943"], ["84187.50", "5.075175"], ["84196.00", "4.803290"], ["84204.50", "4.893918"], ["84213.00", "4.622034"], ["84221.50", "5.347059"], ["84238.50", "5.437687"], ["84247.00", "4.259522"], ["84255.50", "3.897009"], ["84264.00", "3.987637"], ["84272.50", "4.531406"], ["84281.00", "5.165803"], ["84289.50", "5.256431"], ["84298.00", "4.350150"], ["84306.50", "4.712662"], ["84315.00", "4.168894"]], "bids": [["84054.35", "0.035632"], ["84054.26", "0"], ["83985.30", "3.987637"], ["83976.80", "3.897009"], ["83968.30", "4.622034"], ["83959.80", "5.528315"], ["83951.30", "4.803290"], ["83942.80", "4.440778"], ["83934.30", "4.893918"], ["83925.80", "5.075175"], ["83917.30", "4.712662"], ["83908.80", "4.350150"], ["83891.80", "5.437687"], ["83883.30", "5.256431"], ["83874.80", "5.165803"], ["83866.30", "4.259522"], ["83857.80", "4.531406"], ["83849.30", "5.618943"], ["83840.80", "4.984547"], ["83832.30", "4.078265"], ["83823.80", "4.168894"]], "checksum": -1655256494, "ts": "1742584890445"}], "ts": 1742584890452, "record_time": 1742584890.565606, "EXCHANGE": "BITGET"}
{"action": "update", "arg": {"instType": "SPOT", "channel": "books", "instId": "BTCUSDT"}, "data": [{"asks": [["84097.50", "0.005891"], ["84099.50", "0.015502"], ["84101.50", "0.040795"], ["84103.50", "0.107354"], ["84105.50", "0.282512"], ["84107.50", "0.743451"], ["84109.50", "1.956451"], ["84111.50", "5.148554"], ["84118.20", "0.350370"], ["84153.50", "5.165803"], ["84162.00", "4.440778"], ["84170.50", "5.347059"], ["84179.00", "5.437687"], ["84187.50", "4.803290"], ["84196.00", "4.168894"], ["84204.50", "3.897009"], ["84213.00", "5.528315"], ["84221.50", "4.259522"], ["84230.00", "4.984547"], ["84238.50", "5.256431"], ["84247.00", "4.350150"], ["84255.50", "4.893918"], ["84264.00", "5.618943"], ["84272.50", "5.075175"], ["84281.00", "4.078265"], ["84289.50", "4.622034"], ["84298.00", "3.987637"], ["84306.50", "4.531406"], ["84315.00", "4.712662"]], "bids": [["84043.30", "0.002012"], ["84041.30", "0.005295"], ["84039.30", "0.013934"], ["84037.30", "0.036667"], ["84035.30", "0.096493"], ["84033.30", "0.253929"], ["84031.30", "0.668234"], ["84029.30", "1.758512"], ["84027.30", "4.627661"], ["83985.30", "5.528315"], ["83976.80", "4.259522"], ["83968.30", "4.803290"], ["83959.80", "3.987637"], ["83951.30", "4.078265"], ["83942.80", "5.437687"], ["83934.30", "3.897009"], ["83925.80", "4.168894"], ["83917.30", "5.347059"], ["83908.80", "5.618943"], ["83900.30", "5.165803"], ["83891.80", "5.075175"], ["83883.30", "4.712662"], ["83874.80", "5.256431"], ["83866.30", "4.440778"], ["83857.80", "4.350150"], ["83849.30", "4.984547"], ["83840.80", "4.531406"], ["83832.30", "4.622034"], ["83823.80", "4.893918"]], "checksum": 84821838, "ts": "1742584890647"}], "ts": 1742584890649, "record_time": 1742584890.76189, "EXCHANGE": "BITGET"}
{"action": "update", "arg": {"instType": "SPOT", "channel": "books", "instId": "BTCUSDT"}, "data": [{"asks": [["84097.50", "0.005475"], ["84099.50", "0.014406"], ["84101.50", "0.037912"], ["84103.50", "0.099769"], ["84105.50", "0.262549"], ["84107.50", "0.690919"], ["84109.50", "1.818208"], ["84111.50", "4.784757"], ["84117.50", "2.356140"], ["84118.20", "0.348810"], ["84119.20", "0"], ["84153.50", "5.347059"], ["84162.00", "5.618943"], ["84170.50", "4.531406"], ["84179.00", "4.168894"], ["84187.50", "4.259522"], ["84196.00", "4.350150"], ["84204.50", "5.256431"], ["84213.00", "4.984547"], ["84221.50", "4.803290"], ["84230.00", "4.893918"], ["84238.50", "4.078265"], ["84247.00", "4.440778"], ["84255.50", "5.528315"], ["84264.00", "3.897009"], ["84272.50", "3.987637"], ["84281.00", "4.622034"], ["84289.50", "5.165803"], ["84298.00", "5.437687"], ["84306.50", "4.712662"], ["84315.00", "5.075175"]], "bids": [["84054.35", "0"], ["84043.30", "0.001541"], ["84041.30", "0.004054"], ["84039.30", "0.010670"], ["84037.30", "0.028078"], ["84035.30", "0.073890"], ["84033.30", "0.194448"], ["84031.30", "0.511703"], ["84029.30", "1.346589"], ["84027.30", "3.543653"], ["84007.00", "0"], ["83985.30", "5.075175"], ["83976.80", "5.347059"], ["83968.30", "5.165803"], ["83959.80", "4.803290"], ["83951.30", "4.712662"], ["83942.80", "4.259522"], ["83934.30", "5.618943"], ["83925.80", "4.622034"], ["83917.30", "4.984547"], ["83908.80", "4.168894"], ["83900.30", "5.528315"], ["83891.80", "3.987637"], ["83883.30", "3.897009"], ["83866.30", "5.437687"], ["83857.80", "4.893918"], ["83849.30", "4.078265"], ["83840.80", "4.440778"], ["83832.30", "4.531406"], ["83823.80", "4.350150"], ["83713.80", "0.000024"], ["83713.71", "0.000323"]], "checksum": -450273390, "ts": "1742584890859"}], "ts": 1742584890862, "record_time": 1742584890.97457, "EXCHANGE": "BITGET"}
{"action": "update", "arg": {"instType": "SPOT", "channel": "books", "instId": "BTCUSDT"}, "data": [{"asks": [["84090.00", "0.002000"], ["84107.36", "0.000179"], ["84108.15", "0"], ["84153.50", "4.803290"], ["84162.00", "5.075175"], ["84170.50", "5.165803"], ["84179.00", "3.897009"], ["84187.50", "3.987637"], ["84196.00", "4.531406"], ["84204.50", "4.622034"], ["84213.00", "4.350150"], ["84221.50", "4.893918"], ["84230.00", "4.984547"], ["84238.50", "4.259522"], ["84247.00", "5.256431"], ["84255.50", "4.168894"], ["84264.00", "5.618943"], ["84272.50", "4.712662"], ["84281.00", "4.440778"], ["84289.50", "5.437687"], ["84298.00", "4.078265"], ["84306.50", "5.528315"], ["84315.00", "5.347059"], ["84559.10", "0"]], "bids": [["84054.46", "0.035632"], ["84006.00", "0.000160"], ["83985.30", "4.984547"], ["83977.83", "0"], ["83977.05", "0.000172"], ["83976.80", "4.622034"], ["83968.30", "4.531406"], ["83959.80", "3.897009"], ["83951.30", "4.350150"], ["83934.30", "4.893918"], ["83925.80", "4.440778"], ["83917.30", "5.165803"], ["83908.80", "5.618943"], ["83900.30", "4.803290"], ["83891.80", "5.347059"], ["83883.30", "3.987637"], ["83874.80", "4.078265"], ["83866.30", "4.712662"], ["83857.80", "5.256431"], ["83849.30", "5.528315"], ["83840.80", "5.075175"], ["83832.30", "5.437687"], ["83823.80", "4.168894"], ["83713.71", "0"]], "checksum": 1359802876, "ts": "1742584891075"}], "ts": 1742584891085, "record_time": 1742584891.197308, "EXCHANGE": "BITGET"}
{"action": "update", "arg": {"instType": "SPOT", "channel": "books", "instId": "BTCUSDT"}, "data": [{"asks": [["84097.50", "0.005631"], ["84099.50", "0.014817"], ["84101.50", "0.038992"], ["84103.50", "0.102612"], ["84105.50", "0.270031"], ["84107.50", "0.710609"], ["84109.50", "1.870023"], ["84111.50", "4.921114"], ["84118.20", "0.350370"], ["84153.50", "5.347059"], ["84162.00", "5.528315"], ["84170.50", "4.168894"], ["84179.00", "5.165803"], ["84187.50", "4.712662"], ["84196.00", "4.803290"], ["84204.50", "5.437687"], ["84213.00", "4.259522"], ["84230.00", "4.440778"], ["84238.50", "5.618943"], ["84247.00", "4.622034"], ["84255.50", "5.256431"], ["84264.00", "4.078265"], ["84272.50", "4.984547"], ["84281.00", "3.897009"], ["84289.50", "4.350150"], ["84298.00", "4.531406"], ["84306.50", "3.987637"], ["84315.00", "5.075175"]], "bids": [["84056.04", "0.010376"], ["84055.53", "0"], ["84005.00", "0.000281"], ["83985.30", "5.347059"], ["83976.80", "3.897009"], ["83968.30", "5.437687"], ["83959.80", "4.078265"], ["83951.30", "4.440778"], ["83942.80", "4.350150"], ["83934.30", "4.168894"], ["83925.80", "4.803290"], ["83917.30", "4.531406"], ["83908.80", "5.075175"], ["83900.30", "4.712662"], ["83891.80", "5.528315"], ["83883.30", "5.256431"], ["83874.80", "5.165803"], ["83866.30", "5.618943"], ["83857.80", "4.984547"], ["83849.30", "4.622034"], ["83840.80", "4.259522"], ["83832.30", "4.893918"], ["83823.80", "3.987637"]], "checksum": 680554574, "ts": "1742584891291"}], "ts": 1742584891295, "record_time": 1742584891.404561, "EXCHANGE": "BITGET"}
{"action": "update", "arg": {"instType": "SPOT", "channel": "books", "instId": "BTCUSDT"}, "data": [{"asks": [["84097.50", "0.005475"], ["84099.50", "0.014406"], ["84101.50", "0.037912"], ["84103.50", "0.099769"], ["84105.50", "0.262549"], ["84107.50", "0.690919"], ["84109.50", "1.818208"], ["84111.50", "4.784757"], ["84118.20", "0.355470"], ["84153.50", "5.618943"], ["84162.00", "5.075175"], ["84170.50", "4.440778"], ["84179.00", "4.168894"], ["84187.50", "4.622034"], ["84196.00", "4.259522"], ["84204.50", "4.078265"], ["84213.00", "3.987637"], ["84221.50", "5.347059"], ["84230.00", "4.984547"], ["84238.50", "5.165803"], ["84247.00", "4.893918"], ["84255.50", "5.437687"], ["84264.00", "4.712662"], ["84272.50", "5.256431"], ["84281.00", "4.803290"], ["84289.50", "3.897009"], ["84306.50", "5.528315"], ["84315.00", "4.350150"]], "bids": [["84054.55", "0.035632"], ["84054.46", "0"], ["84037.30", "0.028180"], ["84035.30", "0.074158"], ["84033.30", "0.195152"], ["84031.30", "0.513560"], ["84029.30", "1.351472"], ["84027.30", "3.556506"], ["84023.00", "0.071160"], ["84016.70", "0.618420"], ["83985.30", "3.897009"], ["83976.80", "5.347059"], ["83968.30", "4.350150"], ["83959.80", "5.256431"], ["83951.30", "4.893918"], ["83942.80", "4.803290"], ["83934.30", "4.440778"], ["83925.80", "4.531406"], ["83917.30", "5.075175"], ["83908.80", "4.078265"], ["83900.30", "5.528315"], ["83891.80", "3.987637"], ["83883.30", "5.437687"], ["83874.80", "4.622034"], ["83866.30", "5.165803"], ["83857.80", "4.712662"], ["83849.30", "4.259522"], ["83840.80", "4.168894"], ["83832.30", "5.618943"], ["83823.80", "4.984547"]], "checksum": -744814555, "ts": "1742584891508"}], "ts": 1742584891512, "record_time": 1742584891.621806, "EXCHANGE": "BITGET"}
{"action": "update", "arg": {"instType": "SPOT", "channel": "books", "instId": "BTCUSDT"}, "data": [{"asks": [["84109.50", "1.818321"], ["84111.50", "4.785055"], ["84122.80", "0.204000"], ["84123.80", "0"], ["84153.50", "4.984547"], ["84162.00", "4.712662"], ["84170.50", "5.165803"], ["84179.00", "4.350150"], ["84187.50", "4.893918"], ["84196.00", "4.803290"], ["84204.50", "5.528315"], ["84213.00", "5.256431"], ["84230.00", "3.987637"], ["84238.50", "4.622034"], ["84247.00", "5.075175"], ["84255.50", "4.168894"], ["84264.00", "4.440778"], ["84272.50", "4.259522"], ["84281.00", "3.897009"], ["84289.50", "5.618943"], ["84298.00", "5.437687"], ["84306.50", "4.531406"], ["84315.00", "4.078265"]], "bids": [["84031.30", "0.513457"], ["84029.30", "1.351204"], ["84027.30", "3.555799"], ["83985.30", "4.622034"], ["83976.80", "4.350150"], ["83968.30", "5.347059"], ["83959.80", "4.531406"], ["83951.30", "5.528315"], ["83942.80", "3.897009"], ["83934.30", "4.712662"], ["83925.80", "5.437687"], ["83917.30", "5.618943"], ["83900.30", "4.168894"], ["83883.30", "4.440778"], ["83874.80", "4.803290"], ["83857.80", "4.984547"], ["83849.30", "5.256431"], ["83840.80", "4.259522"], ["83832.30", "5.075175"], ["83823.80", "4.893918"]], "checksum": -744814555, "ts": "1742584891713"}], "ts": 1742584891716, "record_time": 1742584891.824356, "EXCHANGE": "BITGET"}
{"action": "update", "arg": {"instType": "SPOT", "channel": "books", "instId": "BTCUSDT"}, "data": [{"asks": [["84057.01", "2.400878"], ["84107.50", "0.690707"], ["84109.50", "1.817649"], ["84111.50", "4.783288"], ["84153.50", "4.350150"], ["84162.00", "4.259522"], ["84170.50", "4.440778"], ["84179.00", "5.347059"], ["84187.50", "5.437687"], ["84196.00", "5.618943"], ["84204.50", "4.803290"], ["84213.00", "4.984547"], ["84221.50", "3.897009"], ["84238.50", "5.075175"], ["84247.00", "5.528315"], ["84255.50", "5.256431"], ["84264.00", "4.712662"], ["84272.50", "4.078265"], ["84281.00", "4.622034"], ["84289.50", "4.168894"], ["84298.00", "5.165803"], ["84306.50", "4.893918"], ["84315.00", "4.531406"]], "bids": [["84007.00", "0.000121"], ["84006.00", "0"], ["83985.30", "5.165803"], ["83976.80", "4.259522"], ["83959.80", "5.618943"], ["83951.30", "5.256431"], ["83942.80", "4.893918"], ["83934.30", "4.350150"], ["83925.80", "5.075175"], ["83917.30", "4.440778"], ["83908.80", "4.531406"], ["83900.30", "5.528315"], ["83891.80", "4.803290"], ["83883.30", "4.984547"], ["83874.80", "3.987637"], ["83866.30", "3.897009"], ["83857.80", "4.622034"], ["83849.30", "4.078265"], ["83840.80", "4.712662"], ["83832.30", "4.168894"], ["83823.80", "5.437687"]], "checksum": 1825469738, "ts": "1742584891919"}], "ts": 1742584891923, "record_time": 1742584892.031909, "EXCHANGE": "BITGET"}
{"action": "update", "arg": {"instType": "SPOT", "channel": "books", "instId": "BTCUSDT"}, "data": [{"asks": [["84057.01", "2.400738"], ["84074.60", "0"], ["84074.73", "0.035957"], ["84075.06", "0"], ["84075.18", "0.119905"], ["84076.32", "0"], ["84076.45", "0.035972"], ["84077.58", "0.006357"], ["84077.70", "0.006357"], ["84078.28", "0"], ["84078.33", "0"], ["84078.39", "0.006357"], ["84078.48", "0.010995"], ["84078.59", "0"], ["84078.71", "0.006356"], ["84079.24", "0"], ["84079.32", "0"], ["84079.47", "0.006357"], ["84079.76", "0"], ["84079.79", "0"], ["84079.89", "0.006357"], ["84079.93", "0.006357"], ["84080.24", "0.119901"], ["84080.28", "0"], ["84080.39", "0.006357"], ["84080.40", "0.022786"], ["84081.19", "0"], ["84081.36", "0.006357"], ["84083.51", "0"], ["84083.66", "0.119850"], ["84084.97", "0"], ["84085.03", "0.119905"], ["84088.84", "0"], ["84089.10", "0.015896"], ["84089.66", "0"], ["84089.90", "0.010988"], ["84118.20", "0.348810"], ["84121.90", "0.132000"], ["84123.50", "0"], ["84153.50", "4.984547"], ["84162.00", "5.075175"], ["84170.50", "4.168894"], ["84179.00", "5.618943"], ["84187.50", "3.897009"], ["84196.00", "5.437687"], ["84204.50", "5.528315"], ["84213.00", "5.256431"], ["84221.50", "4.622034"], ["84230.00", "4.893918"], ["84238.50", "5.347059"], ["84247.00", "5.165803"], ["84255.50", "4.803290"], ["84264.00", "4.350150"], ["84272.50", "4.440778"], ["84281.00", "3.987637"], ["84289.50", "4.259522"], ["84298.00", "4.531406"], ["84306.50", "4.712662"], ["84315.00", "4.078265"]], "bids": [["84054.63", "0.035632"], ["84054.55", "0"], ["84039.30", "0.010533"], ["84037.30", "0.027720"], ["84035.46", "0"], ["84035.30", "0.072946"], ["84034.67", "0.004030"], ["84034.39", "0.089533"], ["84034.25", "0"], ["84033.99", "0.247134"], ["84033.88", "0"], ["84033.30", "0.191964"], ["84032.74", "0.083499"], ["84032.61", "0"], ["84031.47", "0.015724"], ["84031.35", "0"], ["84031.30", "0.505169"], ["84030.82", "0.006561"], ["84030.74", "0.055545"], ["84030.70", "0"], ["84030.59", "0"], ["84030.46", "0.017095"], ["84030.35", "0"], ["84029.88", "0.007335"], ["84029.73", "0"], ["84029.30", "1.329392"], ["84029.29", "0.008995"], ["84029.19", "0"], ["84029.16", "0"], ["84028.79", "0.008187"], ["84028.78", "0.017348"], ["84028.67", "0"], ["84028.63", "0"], ["84027.74", "0.008276"], ["84027.57", "0"], ["84027.30", "3.498400"], ["84025.50", "0.268397"], ["84025.35", "0"], ["84024.51", "0.266845"], ["84024.45", "0"], ["84020.17", "0.073065"], ["84019.92", "0"], ["84019.30", "0.056371"], ["84019.05", "0"], ["84017.63", "0.000877"], ["84017.38", "0"], ["83999.13", "0.003597"], ["83998.86", "0"], ["83985.30", "5.618943"], ["83976.80", "4.531406"], ["83968.30", "4.803290"], ["83959.80", "4.440778"], ["83951.30", "4.622034"], ["83942.80", "4.168894"], ["83934.30", "5.256431"], ["83925.80", "4.259522"], ["83917.30", "3.987637"], ["83908.80", "3.897009"], ["83900.30", "4.893918"], ["83891.80", "5.347059"], ["83883.30", "5.437687"], ["83874.80", "4.350150"], ["83866.30", "4.078265"], ["83857.80", "5.165803"], ["83849.30", "5.075175"], ["83840.80", "4.984547"], ["83832.30", "5.528315"], ["83823.80", "4.712662"], ["83713.71", "0.000323"], ["83713.64", "0.000192"]], "checksum": 618272463, "ts": "1742584892123"}], "ts": 1742584892132, "record_time": 1742584892.243635, "EXCHANGE": "BITGET"}
{"action": "update", "arg": {"instType": "SPOT", "channel": "books", "instId": "BTCUSDT"}, "data": [{"asks": [["84077.00", "0.076846"], ["84079.24", "0.183762"], ["84095.50", "0.002579"], ["84095.84", "0.010000"], ["84097.50", "0.006788"], ["84099.50", "0.017862"], ["84101.50", "0.047006"], ["84103.50", "0.123699"], ["84105.50", "0.325525"], ["84107.50", "0.856643"], ["84109.50", "2.254324"], ["84111.50", "5.932433"], ["84118.20", "0.373170"], ["84153.50", "4.893918"], ["84162.00", "5.437687"], ["84170.50", "4.803290"], ["84179.00", "4.984547"], ["84187.50", "5.347059"], ["84196.00", "4.440778"], ["84204.50", "5.256431"], ["84213.00", "4.350150"], ["84221.50", "5.528315"], ["84230.00", "4.622034"], ["84238.50", "4.259522"], ["84247.00", "5.075175"], ["84255.50", "5.618943"], ["84264.00", "3.987637"], ["84272.50", "3.897009"], ["84281.00", "4.712662"], ["84289.50", "4.168894"], ["84298.00", "4.078265"], ["84306.50", "4.531406"], ["84315.00", "5.165803"], ["84557.29", "0"], ["84558.82", "0"]], "bids": [["84049.52", "0"], ["84031.30", "0.505376"], ["84029.33", "0.007942"], ["84029.30", "1.329936"], ["84027.30", "3.499832"], ["84027.20", "0.001050"], ["84027.10", "0.006060"], ["84026.10", "0.128580"], ["83985.30", "4.531406"], ["83976.80", "4.622034"], ["83968.30", "4.440778"], ["83959.80", "4.893918"], ["83951.30", "4.803290"], ["83942.80", "4.984547"], ["83925.80", "3.897009"], ["83917.30", "5.347059"], ["83908.80", "5.437687"], ["83900.30", "4.259522"], ["83891.80", "3.987637"], ["83883.30", "5.528315"], ["83874.80", "5.165803"], ["83866.30", "5.618943"], ["83857.80", "4.350150"], ["83840.80", "4.168894"], ["83832.30", "4.712662"], ["83823.80", "4.078265"]], "checksum": -814415278, "ts": "1742584892337"}], "ts": 1742584892340, "record_time": 1742584892.449891, "EXCHANGE": "BITGET"}
{"action": "update", "arg": {"instType": "SPOT", "channel": "books", "instId": "BTCUSDT"}, "data": [{"asks": [["84057.01", "1.817960"], ["84064.51", "0.043788"], ["84077.00", "0.135581"], ["84095.50", "0.001025"], ["84097.50", "0.001898"], ["84099.50", "0.004997"], ["84101.50", "0.013148"], ["84103.50", "0.034602"], ["84105.50", "0.091058"], ["84107.50", "0.239625"], ["84109.50", "0.630593"], ["84111.50", "1.659455"], ["84111.60", "0.001022"], ["84111.90", "0.006270"], ["84112.00", "0.054510"], ["84112.10", "0"], ["84113.70", "0"], ["84114.10", "0"], ["84114.20", "0.015000"], ["84114.30", "0.045210"], ["84114.40", "0.030210"], ["84114.60", "0"], ["84115.00", "0.067050"], ["84115.90", "0.190740"], ["84116.90", "0.620790"], ["84117.40", "0.490320"], ["84117.50", "0.120000"], ["84117.60", "0.126210"], ["84118.10", "0"], ["84118.20", "0.249330"], ["84120.00", "0.211244"], ["84120.20", "0.240000"], ["84120.40", "0.577170"], ["84120.70", "0"], ["84121.00", "0.250620"], ["84121.10", "0"], ["84121.80", "0"], ["84122.70", "0"], ["84123.10", "0"], ["84123.40", "0"], ["84162.00", "4.078265"], ["84170.50", "4.168894"], ["84179.00", "4.440778"], ["84187.50", "3.987637"], ["84196.00", "5.528315"], ["84204.50", "5.618943"], ["84213.00", "5.347059"], ["84221.50", "4.259522"], ["84230.00", "4.350150"], ["84238.50", "3.897009"], ["84255.50", "5.437687"], ["84264.00", "4.984547"], ["84272.50", "4.622034"], ["84281.00", "4.803290"], ["84289.50", "5.256431"], ["84298.00", "4.712662"], ["84306.50", "5.165803"], ["84315.00", "4.531406"], ["84557.29", "0.000014"], ["84558.82", "0.000089"]], "bids": [["84057.00", "1.037176"], ["84056.04", "0"], ["84054.63", "0"], ["84045.30", "0.001383"], ["84043.30", "0.003639"], ["84041.30", "0.009578"], ["84039.95", "0.111699"], ["84039.31", "0"], ["84039.30", "0.025205"], ["84037.30", "0.066329"], ["84035.30", "0.174550"], ["84033.30", "0.459527"], ["84031.30", "1.209281"], ["84029.30", "3.182317"], ["84027.30", "8.374520"], ["84027.01", "0.025716"], ["84026.80", "0.440160"], ["84026.70", "0.004500"], ["84026.50", "3.332310"], ["84025.90", "0.068100"], ["84025.00", "0.160590"], ["84020.91", "0"], ["84020.60", "0.063330"], ["84018.50", "0"], ["84018.00", "3.417270"], ["84017.30", "0.120000"], ["84016.70", "0"], ["84011.68", "0"], ["84007.00", "0.000281"], ["84005.00", "0.000160"], ["83985.30", "4.078265"], ["83976.80", "4.984547"], ["83968.30", "4.259522"], ["83959.80", "5.618943"], ["83951.30", "4.531406"], ["83942.80", "4.622034"], ["83934.30", "5.347059"], ["83925.80", "4.893918"], ["83917.30", "5.256431"], ["83900.30", "4.440778"], ["83891.80", "5.528315"], ["83883.30", "4.803290"], ["83874.80", "5.075175"], ["83866.30", "5.165803"], ["83857.80", "4.712662"], ["83849.30", "4.168894"], ["83840.80", "3.897009"], ["83832.30", "3.987637"], ["83823.80", "4.350150"], ["83713.33", "0.000008"], ["83710.00", "0.000642"], ["83706.90", "0.000016"]], "checksum": -1351179797, "ts": "1742584892539"}], "ts": 1742584892544, "record_time": 1742584892.655625, "EXCHANGE": "BITGET"}
{"action": "update", "arg": {"instType": "SPOT", "channel": "books", "instId": "BTCUSDT"}, "data": [{"asks": [["84057.01", "0.565972"], ["84057.02", "0.000100"], ["84057.03", "0.000100"], ["84057.04", "0.000100"], ["84064.51", "0"], ["84074.73", "0"], ["84075.18", "0"], ["84076.45", "0"], ["84077.05", "0"], ["84077.10", "0"], ["84077.58", "0"], ["84077.70", "0"], ["84078.01", "0"], ["84078.39", "0"], ["84078.48", "0"], ["84078.71", "0"], ["84079.00", "0"], ["84079.24", "0"], ["84079.44", "0"], ["84079.47", "0"], ["84079.62", "0"], ["84079.89", "0"], ["84079.93", "0"], ["84080.24", "0"], ["84080.39", "0"], ["84080.40", "0"], ["84081.36", "0"], ["84081.93", "0"], ["84082.09", "0"], ["84082.80", "0"], ["84083.66", "0"], ["84084.73", "0"], ["84085.03", "0"], ["84085.15", "0"], ["84085.44", "0"], ["84087.31", "0"], ["84089.10", "0"], ["84089.39", "0.006357"], ["84089.90", "0"], ["84091.50", "0"], ["84093.50", "0"], ["84094.70", "0.001021"], ["84095.50", "0"], ["84095.84", "0"], ["84096.70", "0.001009"], ["84097.50", "0"], ["84098.70", "0.001006"], ["84099.50", "0"], ["84100.70", "0.001045"], ["84101.49", "0"], ["84101.50", "0"], ["84102.70", "0.001022"], ["84103.50", "0"], ["84104.70", "0.001009"], ["84105.50", "0"], ["84106.70", "0.001048"], ["84107.22", "0.067994"], ["84107.36", "0"], ["84107.50", "0"], ["84108.70", "0.001041"], ["84109.50", "0"], ["84110.70", "0.002305"], ["84111.50", "0"], ["84111.60", "0"], ["84111.70", "0"], ["84111.80", "0"], ["84111.90", "0"], ["84112.00", "0"], ["84112.70", "0.006064"], ["84113.79", "0.212376"], ["84114.20", "0"], ["84114.30", "0"], ["84114.40", "0"], ["84114.70", "0.015959"], ["84115.00", "0.001590"], ["84115.90", "0.191970"], ["84116.10", "0"], ["84116.90", "0"], ["84117.40", "0"], ["84117.50", "0"], ["84117.60", "0.066600"], ["84117.70", "0.070410"], ["84118.20", "0.249720"], ["84119.40", "0"], ["84119.50", "0"], ["84120.10", "0.068190"], ["84120.20", "0"], ["84120.40", "1.074420"], ["84121.00", "0"], ["84121.90", "0"], ["84122.10", "0.067800"], ["84122.80", "0"], ["84123.40", "0.064860"], ["84123.50", "0.057900"], ["84124.10", "0.037590"], ["84124.20", "4.846650"], ["84124.30", "0.030960"], ["84124.40", "0.039600"], ["84124.50", "0.015000"], ["84124.60", "0.030000"], ["84125.30", "0.030000"], ["84125.40", "0.071340"], ["84126.00", "0.546210"], ["84126.10", "0.067980"], ["84126.90", "0.031230"], ["84127.00", "0.180000"], ["84127.30", "0.053520"], ["84153.50", "0"], ["84156.70", "4.531234"], ["84162.00", "0"], ["84165.20", "5.074981"], ["84167.16", "0"], ["84170.50", "0"], ["84173.70", "5.618729"], ["84179.00", "0"], ["84182.20", "5.256231"], ["84187.50", "0"], ["84190.70", "5.437480"], ["84196.00", "0"], ["84199.20", "5.346855"], ["84204.50", "0"], ["84207.70", "4.168735"], ["84213.00", "0"], ["84216.20", "3.896861"], ["84221.50", "0"], ["84224.70", "4.803107"], ["84230.00", "0"], ["84233.20", "4.078110"], ["84238.50", "0"], ["84241.70", "4.712483"], ["84247.00", "0"], ["84250.20", "5.165606"], ["84255.50", "0"], ["84258.70", "4.621858"], ["84264.00", "0"], ["84267.20", "4.984357"], ["84272.50", "0"], ["84275.70", "4.259360"], ["84281.00", "0"], ["84284.20", "3.987486"], ["84289.50", "0"], ["84292.70", "5.528105"], ["84298.00", "0"], ["84301.20", "4.893732"], ["84306.50", "0"], ["84309.70", "4.349984"], ["84315.00", "0"], ["84318.20", "4.440609"], ["84559.10", "0.000036"], ["84559.47", "0.000010"], ["84560.00", "0.000265"], ["84561.11", "0.000134"], ["84561.58", "0.003678"], ["84562.50", "0.006969"], ["84565.22", "0.003438"], ["84566.67", "0.001061"], ["84567.79", "0.000009"], ["84568.60", "0.000018"], ["84568.81", "0.000072"], ["84568.97", "0.000024"], ["84569.23", "0.000009"], ["84569.56", "0.006305"], ["84570.51", "0.000170"], ["84570.99", "0.000053"], ["84571.43", "0.010009"], ["84571.75", "0.001273"], ["84571.82", "0.000046"], ["84571.91", "0.000222"], ["84572.75", "0.000009"], ["84573.59", "0.000177"], ["84573.83", "0.000215"], ["84574.47", "0.000372"], ["84574.50", "0.000039"], ["84574.67", "0.000010"], ["84574.98", "0.000037"], ["84575.00", "0.000015"], ["84577.11", "0.000008"], ["84577.78", "0.000009"], ["84578.31", "0.000008"], ["84578.95", "0.000183"], ["84579.76", "0.000051"], ["84580.65", "0.000008"], ["84580.67", "0.000013"], ["84582.14", "0.000011"], ["84583.28", "0.000010"], ["84583.33", "0.000009"]], "bids": [["84057.00", "1.066581"], ["84054.73", "0.035632"], ["84050.50", "0.001206"], ["84048.50", "0.001967"], ["84047.30", "0"], ["84046.50", "0.005177"], ["84045.31", "0.001844"], ["84045.30", "0"], ["84044.50", "0.013624"], ["84043.30", "0"], ["84042.50", "0.035853"], ["84041.30", "0"], ["84040.50", "0.094350"], ["84039.95", "0"], ["84039.32", "0"], ["84039.30", "0"], ["84038.50", "0.248290"], ["84037.54", "0.008995"], ["84037.30", "0"], ["84036.97", "0"], ["84036.50", "0.653393"], ["84035.76", "0.008276"], ["84035.30", "0"], ["84034.67", "0"], ["84034.50", "1.719456"], ["84034.39", "0"], ["84033.99", "0"], ["84033.43", "0.023495"], ["84033.30", "0"], ["84032.74", "0"], ["84032.51", "0"], ["84032.50", "4.524884"], ["84032.21", "0"], ["84032.03", "0"], ["84031.47", "0"], ["84031.45", "0"], ["84031.30", "0"], ["84030.82", "0"], ["84030.74", "0"], ["84030.50", "11.907590"], ["84030.46", "0"], ["84030.42", "0"], ["84030.10", "0.030420"], ["84029.90", "0.068400"], ["84029.88", "0"], ["84029.85", "0"], ["84029.69", "0"], ["84029.33", "0"], ["84029.30", "0.275520"], ["84029.29", "0"], ["84029.13", "0"], ["84028.97", "0"], ["84028.80", "0.035670"], ["84028.79", "0"], ["84028.78", "0"], ["84028.50", "0.001038"], ["84028.30", "4.726980"], ["84028.00", "0.160980"], ["84027.90", "0.067980"], ["84027.74", "0"], ["84027.45", "0"], ["84027.30", "3.599610"], ["84027.29", "0"], ["84027.20", "0"], ["84027.01", "0"], ["84026.80", "0.439950"], ["84026.50", "0"], ["84026.49", "0"], ["84026.30", "0.089190"], ["84026.10", "0"], ["84025.60", "0"], ["84025.50", "0"], ["84025.00", "0.000281"], ["84024.80", "0.076170"], ["84024.55", "0"], ["84024.51", "0"], ["84024.13", "0"], ["84024.08", "0"], ["84024.03", "0"], ["84023.70", "0"], ["84023.60", "0.269760"], ["84021.92", "0"], ["84021.90", "0.172380"], ["84021.70", "0.090000"], ["84020.60", "0.027660"], ["84020.17", "0"], ["84019.89", "0"], ["84019.77", "0"], ["84019.30", "0"], ["84019.14", "0"], ["84018.80", "0.488400"], ["84018.60", "2.570790"], ["84018.53", "0"], ["84018.18", "0"], ["84018.15", "0"], ["84018.07", "0"], ["84018.05", "0"], ["84018.02", "0"], ["84018.01", "0"], ["84017.96", "0"], ["84017.94", "0"], ["84017.93", "0"], ["84017.70", "0"], ["84017.69", "0"], ["84017.60", "0"], ["84017.55", "0"], ["84017.51", "0"], ["84016.70", "0.120000"], ["84016.60", "0.071340"], ["84010.90", "0"], ["84010.77", "0"], ["84010.71", "0"], ["84010.60", "0"], ["84010.59", "0"], ["84010.58", "0"], ["84010.52", "0"], ["84010.50", "0"], ["84010.49", "0"], ["84010.46", "0"], ["84010.42", "0"], ["83994.85", "0"], ["83991.84", "0"], ["83989.43", "0"], ["83989.33", "0"], ["83989.22", "0"], ["83988.50", "4.259360"], ["83985.30", "0"], ["83980.00", "4.349984"], ["83977.05", "0"], ["83976.80", "0"], ["83971.50", "5.165606"], ["83968.30", "0"], ["83963.00", "5.437480"], ["83959.80", "0"], ["83954.50", "4.078110"], ["83951.30", "0"], ["83946.00", "4.712483"], ["83942.80", "0"], ["83937.50", "4.803107"], ["83934.30", "0"], ["83929.00", "4.893732"], ["83925.80", "0"], ["83920.50", "4.531234"], ["83917.30", "0"], ["83912.00", "4.168735"], ["83908.80", "0"], ["83903.50", "3.896861"], ["83900.30", "0"], ["83895.00", "5.074981"], ["83891.80", "0"], ["83886.50", "5.256231"], ["83883.30", "0"], ["83878.00", "5.618729"], ["83874.80", "0"], ["83869.50", "3.987486"], ["83866.30", "0"], ["83861.00", "5.346855"], ["83857.80", "0"], ["83852.50", "4.984357"], ["83849.30", "0"], ["83844.00", "4.440609"], ["83840.80", "0"], ["83835.50", "4.621858"], ["83832.30", "0"], ["83827.00", "5.528105"], ["83823.80", "0"], ["83706.67", "0.000013"], ["83705.85", "0.000019"], ["83705.32", "0.000065"], ["83705.18", "0.000009"], ["83703.75", "0.000363"], ["83703.70", "0.000441"], ["83703.00", "0.000024"], ["83702.93", "0.000050"], ["83702.60", "0.000039"], ["83702.50", "0.000033"], ["83702.48", "0.000057"], ["83701.92", "0.000067"], ["83701.28", "0.000248"], ["83700.59", "0.002370"], ["83700.00", "0.007065"], ["83699.88", "0.000008"], ["83698.25", "0.000013"], ["83697.23", "0.000095"], ["83695.65", "0.003457"], ["83695.63", "0.000011"], ["83693.69", "0.000061"], ["83692.52", "0.000066"], ["83692.38", "0.000007"], ["83692.31", "0.000031"], ["83690.84", "0.000162"], ["83690.48", "0.000248"], ["83690.00", "0.000619"], ["83689.50", "0.000113"], ["83688.89", "0.000009"], ["83688.07", "0.000072"], ["83687.50", "0.006969"], ["83687.00", "0.000008"], ["83686.11", "0.000096"], ["83684.21", "0.000102"], ["83683.67", "0.000184"], ["83680.67", "0.041940"], ["83680.00", "0.001081"], ["83678.41", "0.000010"], ["83678.08", "0.000145"], ["83677.42", "0.000008"], ["83677.37", "0.000008"], ["83676.47", "0.000089"], ["83675.68", "0.000008"], ["83675.62", "0.000011"], ["83675.36", "0.000013"], ["83675.20", "0.000018"], ["83675.00", "0.000358"], ["83674.70", "0.000008"], ["83674.19", "0.000020"], ["83673.87", "0.000022"], ["83673.58", "0.000023"], ["83672.50", "0.000031"], ["83672.00", "0.000035"], ["83671.36", "0.000099"], ["83670.59", "0.000105"], ["83670.05", "0.000033"], ["83670.00", "0.002619"], ["83669.66", "0.000010"], ["83669.23", "0.000275"], ["83669.09", "0.000135"], ["83667.80", "0.000023"], ["83667.23", "0.012503"]], "checksum": 1466235940, "ts": "1742584892755"}], "ts": 1742584892759, "record_time": 1742584892.869577, "EXCHANGE": "BITGET"}
{"action": "update", "arg": {"instType": "SPOT", "channel": "books", "instId": "BTCUSDT"}, "data": [{"asks": [["84057.01", "0.677671"], ["84058.20", "0.001896"], ["84059.29", "0.000584"], ["84069.35", "0.043788"], ["84070.00", "0"], ["84073.68", "0.018026"], ["84077.00", "0.076846"], ["84080.23", "0"], ["84084.17", "0"], ["84084.25", "0.035957"], ["84084.85", "0.119905"], ["84085.34", "0.006357"], ["84086.16", "0.006357"], ["84086.17", "0.035972"], ["84086.65", "0.006357"], ["84087.17", "0.006357"], ["84087.32", "0.006357"], ["84087.64", "0.006357"], ["84088.02", "0.006357"], ["84088.20", "0.010995"], ["84088.38", "0.006356"], ["84088.61", "0.006357"], ["84088.83", "0"], ["84089.08", "0.016429"], ["84089.24", "0.006357"], ["84089.32", "0.006357"], ["84089.61", "0.006357"], ["84089.94", "0.119901"], ["84089.99", "0.016429"], ["84090.03", "0.006357"], ["84090.11", "0.006357"], ["84090.17", "0.010993"], ["84090.22", "0.006357"], ["84091.01", "0.009990"], ["84091.26", "0.182458"], ["84092.99", "0.119850"], ["84094.40", "0.119858"], ["84094.65", "0.119905"], ["84094.70", "0"], ["84094.75", "0.015895"], ["84095.05", "0.009989"], ["84096.70", "0"], ["84097.01", "0.006356"], ["84098.20", "0.001040"], ["84098.70", "0"], ["84098.82", "0.015896"], ["84099.63", "0.010988"], ["84100.20", "0.001014"], ["84100.70", "0"], ["84102.20", "0.001024"], ["84102.70", "0"], ["84104.20", "0.001036"], ["84104.70", "0"], ["84106.20", "0.001036"], ["84106.70", "0"], ["84107.98", "0"], ["84108.20", "0.001240"], ["84108.70", "0"], ["84109.78", "0"], ["84110.20", "0.003262"], ["84110.70", "0"], ["84112.20", "0.008586"], ["84112.70", "0"], ["84113.79", "0.037519"], ["84114.20", "0.022593"], ["84114.70", "0"], ["84115.00", "0"], ["84115.90", "0"], ["84116.20", "0.059456"], ["84117.60", "0"], ["84117.70", "0"], ["84118.20", "0.156463"], ["84118.40", "0.001019"], ["84119.90", "0.009840"], ["84120.10", "0.001920"], ["84120.40", "0"], ["84120.68", "0.000179"], ["84120.80", "0"], ["84121.70", "0.067230"], ["84121.80", "0.871680"], ["84122.10", "0.068190"], ["84123.00", "0.213270"], ["84123.30", "0.066180"], ["84123.40", "0.550560"], ["84124.20", "1.673460"], ["84125.20", "0.424530"], ["84125.30", "0.015000"], ["84125.40", "0"], ["84125.60", "0.318120"], ["84126.90", "0.130950"], ["84156.70", "0"], ["84160.20", "4.984148"], ["84165.20", "0"], ["84168.70", "4.168560"], ["84173.70", "0"], ["84174.22", "0.125644"], ["84176.54", "0"], ["84177.20", "4.077939"], ["84182.20", "0"], ["84185.70", "4.349802"], ["84190.70", "0"], ["84194.20", "4.802906"], ["84199.20", "0"], ["84202.70", "4.712286"], ["84205.26", "0.071668"], ["84207.70", "0"], ["84211.20", "5.527873"], ["84216.20", "0"], ["84219.70", "4.531044"], ["84224.70", "0"], ["84228.20", "4.893527"], ["84233.20", "0"], ["84236.70", "5.256011"], ["84241.70", "0"], ["84245.20", "3.896698"], ["84250.20", "0"], ["84253.70", "4.621665"], ["84258.70", "0"], ["84262.20", "5.437252"], ["84267.20", "0"], ["84270.70", "3.987319"], ["84275.70", "0"], ["84279.20", "4.440423"], ["84284.20", "0"], ["84287.70", "5.346632"], ["84292.70", "0"], ["84296.20", "5.618494"], ["84301.20", "0"], ["84304.70", "5.165390"], ["84309.70", "0"], ["84313.20", "5.074769"], ["84318.20", "0"], ["84321.70", "4.259181"], ["84566.67", "0"], ["84567.79", "0"], ["84568.60", "0"], ["84568.81", "0"], ["84568.97", "0"], ["84569.23", "0"], ["84569.56", "0"], ["84570.51", "0"], ["84570.99", "0"], ["84571.43", "0"], ["84571.75", "0"], ["84571.82", "0"], ["84571.91", "0"], ["84572.75", "0"], ["84573.59", "0"], ["84573.83", "0"], ["84574.47", "0"], ["84574.50", "0"], ["84574.67", "0"], ["84574.98", "0"], ["84575.00", "0"], ["84577.11", "0"], ["84577.78", "0"], ["84578.31", "0"], ["84578.95", "0"], ["84579.76", "0"], ["84580.65", "0"], ["84580.67", "0"], ["84582.14", "0"], ["84583.28", "0"], ["84583.33", "0"]], "bids": [["84057.00", "1.086581"], ["84056.01", "0.014316"], ["84055.23", "0.010000"], ["84054.74", "0.010690"], ["84054.00", "0.001328"], ["84052.00", "0.002313"], ["84050.50", "0"], ["84050.00", "0.006088"], ["84049.64", "0.023495"], ["84048.50", "0"], ["84048.00", "0.016021"], ["84046.87", "0.111699"], ["84046.50", "0"], ["84046.00", "0.042161"], ["84044.50", "0"], ["84044.24", "0.004030"], ["84044.00", "0.110950"], ["84043.90", "0.089533"], ["84043.66", "0.247134"], ["84042.50", "0"], ["84042.46", "0.083499"], ["84042.10", "0.017797"], ["84042.00", "0.291972"], ["84041.61", "0.005940"], ["84041.09", "0.015724"], ["84040.50", "0"], ["84040.45", "0.073787"], ["84040.13", "0.017095"], ["84040.00", "0.768349"], ["84039.59", "0.016406"], ["84039.48", "0.028827"], ["84039.38", "0.017086"], ["84039.05", "0.007942"], ["84038.98", "0.006561"], ["84038.71", "0.025157"], ["84038.66", "0.224676"], ["84038.56", "0.007129"], ["84038.50", "0.017348"], ["84038.41", "0.008187"], ["84038.04", "0.007335"], ["84038.00", "2.021970"], ["84036.50", "0"], ["84036.00", "5.320974"], ["84035.58", "0.012653"], ["84035.53", "0.051761"], ["84034.69", "0.018518"], ["84034.50", "0"], ["84034.21", "0.222686"], ["84034.13", "0.258784"], ["84034.00", "14.002564"], ["84033.90", "0.068400"], ["84033.72", "0.076118"], ["84033.68", "0.021131"], ["84033.50", "0.001049"], ["84033.43", "0"], ["84033.40", "8.872860"], ["84033.36", "0.268397"], ["84033.20", "1.079220"], ["84032.50", "0"], ["84031.90", "0.067980"], ["84031.70", "0.170700"], ["84031.61", "0.012439"], ["84031.60", "0.160770"], ["84031.58", "0.017794"], ["84030.99", "0.008265"], ["84030.60", "1.569510"], ["84030.50", "0.547710"], ["84030.40", "0.076170"], ["84030.10", "0"], ["84029.90", "0.067800"], ["84029.89", "0.073065"], ["84029.30", "0"], ["84029.29", "0.008061"], ["84029.10", "0.084510"], ["84029.01", "0.056371"], ["84028.80", "0"], ["84028.50", "0"], ["84028.30", "1.620660"], ["84028.00", "0.000281"], ["84027.90", "0.067800"], ["84027.30", "3.453300"], ["84026.80", "0"], ["84026.70", "0.040170"], ["84026.00", "0.119220"], ["84025.80", "0.120000"], ["84025.69", "0.008015"], ["84025.68", "0.008468"], ["84025.59", "0.008591"], ["84025.49", "0.005954"], ["84024.80", "0"], ["84024.74", "0.009550"], ["84024.72", "0.008249"], ["84024.71", "0.007376"], ["84024.69", "0.014733"], ["84024.66", "0.015001"], ["84024.63", "0.007816"], ["84023.80", "0"], ["84023.60", "0.120000"], ["84023.31", "0.009245"], ["84022.80", "0.005935"], ["84022.72", "0.006305"], ["84022.65", "0.008516"], ["84022.60", "1.502070"], ["84022.50", "2.570670"], ["84022.23", "0.010046"], ["84021.90", "0.068100"], ["84021.70", "0"], ["84020.90", "0"], ["84020.60", "0"], ["84019.20", "0"], ["84018.90", "0"], ["84018.80", "0"], ["84018.60", "0"], ["84018.45", "0.008919"], ["84018.00", "0.000281"], ["84017.63", "0.009419"], ["84017.60", "0.005173"], ["84017.59", "0.013904"], ["84017.57", "0.005120"], ["84017.54", "0.004853"], ["84017.52", "0.005053"], ["84017.30", "0"], ["84016.70", "0"], ["84016.64", "0"], ["84016.60", "0"], ["84015.61", "0.008764"], ["84015.43", "0.010345"], ["84001.85", "0.007435"], ["83998.89", "0.008574"], ["83994.17", "0.007248"], ["83994.07", "0.007337"], ["83994.06", "0.007652"], ["83992.00", "5.256011"], ["83990.34", "0.000172"], ["83988.50", "0"], ["83983.50", "4.712286"], ["83980.00", "0"], ["83975.00", "5.346632"], ["83971.50", "0"], ["83966.50", "4.802906"], ["83963.00", "0"], ["83958.00", "5.527873"], ["83954.50", "0"], ["83949.50", "5.165390"], ["83946.00", "0"], ["83941.00", "4.168560"], ["83937.50", "0.000084"], ["83932.50", "4.077939"], ["83929.00", "0"], ["83924.00", "4.259181"], ["83920.50", "0"], ["83915.50", "4.440423"], ["83912.00", "0"], ["83907.00", "4.621665"], ["83903.50", "0"], ["83898.50", "4.531044"], ["83895.00", "0"], ["83890.00", "4.893527"], ["83886.50", "0"], ["83881.50", "5.437252"], ["83878.00", "0"], ["83873.00", "3.987319"], ["83869.50", "0"], ["83864.50", "4.349802"], ["83861.00", "0"], ["83856.00", "4.984148"], ["83852.50", "0.000043"], ["83847.50", "5.618494"], ["83844.00", "0"], ["83839.00", "3.896698"], ["83835.50", "0"], ["83830.50", "5.074769"], ["83827.00", "0"], ["83702.50", "0"], ["83702.48", "0"], ["83701.92", "0"], ["83701.28", "0"], ["83700.59", "0"], ["83700.00", "0"], ["83699.88", "0"], ["83698.25", "0"], ["83697.23", "0"], ["83695.65", "0"], ["83695.63", "0"], ["83693.69", "0"], ["83692.52", "0"], ["83692.38", "0"], ["83692.31", "0"], ["83690.84", "0"], ["83690.48", "0"], ["83690.00", "0"], ["83689.50", "0"], ["83688.89", "0"], ["83688.07", "0"], ["83687.50", "0"], ["83687.00", "0"], ["83686.11", "0"], ["83684.21", "0"], ["83683.67", "0"], ["83680.67", "0"], ["83680.00", "0"], ["83678.41", "0"], ["83678.08", "0"], ["83677.42", "0"], ["83677.37", "0"], ["83676.47", "0"], ["83675.68", "0"], ["83675.62", "0"], ["83675.36", "0"], ["83675.20", "0"], ["83675.00", "0"], ["83674.70", "0"], ["83674.19", "0"], ["83673.87", "0"], ["83673.58", "0"], ["83672.50", "0"], ["83672.00", "0"], ["83671.36", "0"], ["83670.59", "0"], ["83670.05", "0"], ["83670.00", "0"], ["83669.66", "0"], ["83669.23", "0"], ["83669.09", "0"], ["83667.80", "0"], ["83667.23", "0"]], "checksum": -1046932723, "ts": "1742584892956"}], "ts": 1742584892959, "record_time": 1742584893.073484, "EXCHANGE": "BITGET"}
{"action": "update", "arg": {"instType": "SPOT", "channel": "books", "instId": "BTCUSDT"}, "data": [{"asks": [["84057.01", "0.655778"], ["84064.01", "0.024520"], ["84084.24", "0.014667"], ["84084.84", "0.150937"], ["84113.79", "0"], ["84114.20", "0.022709"], ["84116.20", "0.059668"], ["84118.20", "0.157263"], ["84119.70", "0.001012"], ["84120.10", "0.001290"], ["84121.80", "0"], ["84123.00", "0.494250"], ["84126.90", "0.031230"], ["84127.50", "0.075570"], ["84127.60", "2.674650"], ["84128.40", "0.240000"], ["84168.70", "5.527873"], ["84185.70", "5.165390"], ["84202.70", "3.896698"], ["84211.20", "4.893527"], ["84219.70", "4.621665"], ["84228.20", "4.259181"], ["84236.70", "3.987319"], ["84245.20", "5.437252"], ["84253.70", "5.074769"], ["84262.20", "4.712286"], ["84270.70", "4.440423"], ["84279.20", "4.168560"], ["84287.70", "5.256011"], ["84304.70", "5.346632"], ["84313.20", "4.531044"], ["84321.70", "4.349802"], ["84561.11", "0"], ["84561.58", "0"], ["84562.50", "0"], ["84565.22", "0"]], "bids": [["84057.00", "1.122212"], ["84056.02", "0.018153"], ["84054.74", "0"], ["84054.73", "0"], ["84054.00", "0.001447"], ["84050.00", "0.006343"], ["84048.00", "0.016694"], ["84047.85", "0.025716"], ["84046.00", "0.043930"], ["84044.00", "0.115605"], ["84042.00", "0.304224"], ["84040.00", "0.800590"], ["84038.00", "2.106816"], ["84036.00", "5.544252"], ["84034.00", "14.590138"], ["84033.40", "7.325130"], ["84030.60", "0.775620"], ["84030.50", "0.547890"], ["84028.00", "0.120000"], ["84027.30", "3.031470"], ["84026.80", "0.488400"], ["84026.40", "0.120000"], ["84026.30", "0.209190"], ["84026.29", "0.007190"], ["84026.20", "0.005592"], ["84026.18", "0.006587"], ["84026.15", "0.009408"], ["84025.32", "0.009789"], ["84023.00", "0.120000"], ["84022.60", "0"], ["84022.50", "0"], ["84021.90", "0"], ["84018.17", "0.008095"], ["84005.00", "0"], ["83992.00", "4.802906"], ["83983.50", "4.893527"], ["83975.00", "5.527873"], ["83966.50", "5.618494"], ["83958.00", "3.896698"], ["83949.50", "4.621665"], ["83941.00", "4.984148"], ["83932.50", "4.712286"], ["83924.00", "4.077939"], ["83915.50", "5.256011"], ["83907.00", "4.440423"], ["83898.50", "5.346632"], ["83890.00", "5.437252"], ["83881.50", "5.165390"], ["83873.00", "5.074769"], ["83856.00", "3.987319"], ["83847.50", "4.259181"], ["83839.00", "4.168560"], ["83830.50", "4.531044"], ["83703.70", "0"], ["83703.00", "0"], ["83702.93", "0"], ["83702.60", "0"]], "checksum": 118535284, "ts": "1742584893156"}], "ts": 1742584893160, "record_time": 1742584893.268724, "EXCHANGE": "BITGET"}
{"action": "update", "arg": {"instType": "SPOT", "channel": "books", "instId": "BTCUSDT"}, "data": [{"asks": [["84057.01", "0.339110"], ["84064.00", "0"], ["84064.01", "0.012624"], ["84065.01", "0"], ["84069.35", "0"], ["84073.67", "0.043788"], ["84091.26", "0"], ["84098.20", "0"], ["84098.89", "0"], ["84100.10", "0.001021"], ["84100.20", "0"], ["84100.42", "0"], ["84102.10", "0.001020"], ["84102.20", "0"], ["84104.10", "0.001018"], ["84104.20", "0"], ["84106.10", "0.001049"], ["84106.20", "0"], ["84108.10", "0.001021"], ["84108.20", "0"], ["84109.19", "0"], ["84110.10", "0.001025"], ["84110.20", "0"], ["84110.98", "0"], ["84112.10", "0.001017"], ["84112.20", "0"], ["84112.66", "0.010000"], ["84114.10", "0.001006"], ["84114.20", "0"], ["84116.10", "0.001014"], ["84116.20", "0"], ["84118.10", "0.001044"], ["84118.20", "0"], ["84118.40", "0"], ["84119.70", "0"], ["84119.90", "0"], ["84120.10", "0.001432"], ["84120.30", "0.006270"], ["84121.00", "0.010560"], ["84121.70", "0.001047"], ["84122.10", "0"], ["84123.00", "0"], ["84123.30", "0.175230"], ["84123.40", "0.132480"], ["84123.50", "0.058290"], ["84124.10", "0.037800"], ["84124.30", "0.015960"], ["84124.40", "0.009600"], ["84124.50", "0"], ["84124.60", "0"], ["84125.30", "0"], ["84125.60", "0"], ["84126.10", "0"], ["84126.14", "0.001598"], ["84127.00", "0"], ["84127.83", "0.001598"], ["84128.00", "0.901020"], ["84128.20", "0.045000"], ["84128.40", "0"], ["84129.10", "1.821780"], ["84129.70", "0.490320"], ["84130.10", "0.067800"], ["84130.50", "0.067440"], ["84160.20", "0"], ["84162.10", "5.527749"], ["84168.70", "0"], ["84170.60", "4.349704"], ["84177.20", "0"], ["84177.92", "0"], ["84179.10", "5.618368"], ["84185.70", "0"], ["84187.60", "4.712180"], ["84194.20", "0"], ["84196.10", "4.077848"], ["84202.70", "0"], ["84204.33", "0.071678"], ["84204.60", "5.437130"], ["84211.20", "0"], ["84213.10", "4.802798"], ["84219.70", "0"], ["84221.60", "4.984036"], ["84228.20", "0"], ["84230.10", "3.896610"], ["84236.70", "0"], ["84238.60", "5.346511"], ["84245.20", "0"], ["84247.10", "4.259085"], ["84253.70", "0"], ["84255.60", "4.530942"], ["84262.20", "0"], ["84264.10", "4.893417"], ["84270.70", "0"], ["84272.60", "4.440323"], ["84279.20", "0"], ["84281.10", "3.987229"], ["84287.70", "0"], ["84289.60", "5.165274"], ["84296.20", "0"], ["84298.10", "5.255893"], ["84304.70", "0"], ["84306.60", "4.621561"], ["84313.20", "0"], ["84315.10", "5.074655"], ["84321.70", "0"], ["84323.60", "4.168467"], ["84405.65", "0"], ["84412.39", "1.718136"], ["84450.60", "0"], ["84561.11", "0.000134"], ["84561.58", "0.003678"], ["84562.50", "0.006969"], ["84565.22", "0.003438"], ["84566.67", "0.001061"], ["84567.79", "0.000009"], ["84568.60", "0.000018"], ["84568.81", "0.000072"], ["84568.97", "0.000024"], ["84569.23", "0.000009"]], "bids": [["84057.00", "1.147928"], ["84056.02", "0.007463"], ["84055.90", "0.001015"], ["84054.00", "0.000281"], ["84053.90", "0.001350"], ["84053.00", "0.111980"], ["84052.00", "0.000281"], ["84051.90", "0.003554"], ["84050.00", "0.000281"], ["84049.90", "0.009351"], ["84048.00", "0.000281"], ["84047.90", "0.024608"], ["84047.85", "0"], ["84046.87", "0"], ["84046.00", "0.000281"], ["84045.90", "0.064758"], ["84044.00", "0.000281"], ["84043.90", "0.170417"], ["84042.00", "0.010171"], ["84041.90", "0.448465"], ["84040.00", "0.000281"], ["84039.90", "1.180171"], ["84038.00", "0.000281"], ["84037.90", "3.105715"], ["84036.00", "0.000281"], ["84035.90", "8.172933"], ["84035.80", "1.230420"], ["84035.70", "22.306230"], ["84035.50", "0.006630"], ["84035.20", "0.001005"], ["84034.20", "2.889780"], ["84034.00", "5.545020"], ["84033.90", "0.067980"], ["84033.50", "0"], ["84033.40", "0"], ["84032.10", "0.076350"], ["84031.90", "0.067800"], ["84031.70", "0"], ["84031.60", "0"], ["84030.80", "0.090000"], ["84030.60", "0.775440"], ["84030.50", "0.127710"], ["84030.40", "0"], ["84029.30", "0.356790"], ["84028.80", "0.480000"], ["84028.74", "0.009245"], ["84028.19", "0.010046"], ["84028.16", "0.006305"], ["84028.14", "0.005935"], ["84028.09", "0.008516"], ["84027.30", "2.323470"], ["84027.10", "0"], ["84026.70", "0.178410"], ["84026.40", "0.240000"], ["84026.10", "2.570550"], ["84023.60", "0"], ["84023.31", "0"], ["84023.10", "0"], ["84023.00", "0.000281"], ["84022.80", "0"], ["84022.72", "0"], ["84022.65", "0"], ["84022.23", "0"], ["84020.86", "0.010345"], ["84020.84", "0.008764"], ["84015.84", "0.001175"], ["84015.61", "0"], ["84015.43", "0"], ["84013.67", "0.001172"], ["84006.00", "0.000121"], ["83999.61", "0.007248"], ["83999.50", "0.007652"], ["83999.49", "0.007337"], ["83998.91", "0"], ["83996.83", "0"], ["83994.17", "0"], ["83994.07", "0"], ["83994.06", "0"], ["83993.90", "5.618368"], ["83992.00", "0"], ["83985.40", "4.621561"], ["83983.50", "0"], ["83976.90", "4.712180"], ["83975.00", "0"], ["83968.40", "4.259085"], ["83966.50", "0"], ["83964.30", "0.207210"], ["83959.90", "3.896610"], ["83958.00", "0"], ["83951.40", "4.802798"], ["83949.50", "0"], ["83947.00", "0"], ["83942.90", "3.987229"], ["83941.00", "0"], ["83934.40", "4.530942"], ["83932.50", "0"], ["83925.90", "4.168467"], ["83924.00", "0"], ["83917.40", "5.527749"], ["83915.50", "0"], ["83908.90", "5.346511"], ["83907.00", "0"], ["83900.40", "5.074655"], ["83898.50", "0"], ["83891.90", "4.349704"], ["83890.00", "0.000617"], ["83883.40", "4.984036"], ["83881.50", "0"], ["83874.90", "5.255893"], ["83873.00", "0"], ["83866.40", "5.437130"], ["83865.50", "0.203519"], ["83864.50", "0"], ["83857.90", "4.077848"], ["83856.00", "0"], ["83849.40", "4.893417"], ["83848.20", "0"], ["83847.50", "0"], ["83840.90", "5.165274"], ["83839.00", "0"], ["83832.40", "4.440323"], ["83830.50", "0"], ["83739.78", "1.599863"], ["83733.08", "0"], ["83714.29", "0"], ["83713.80", "0"], ["83713.71", "0"], ["83713.64", "0"], ["83713.33", "0"], ["83710.00", "0"], ["83706.90", "0"], ["83706.67", "0"], ["83705.85", "0"], ["83705.32", "0"], ["83705.18", "0"], ["83703.75", "0"]], "checksum": 128593513, "ts": "1742584893359"}], "ts": 1742584893363, "record_time": 1742584893.484855, "EXCHANGE": "BITGET"}
{"action": "update", "arg": {"instType": "SPOT", "channel": "books", "instId": "BTCUSDT"}, "data": [{"asks": [["84057.01", "0.011900"], ["84058.20", "0"], ["84059.29", "0"], ["84064.03", "0.001896"], ["84064.52", "0.000584"], ["84065.79", "0.111699"], ["84068.52", "0"], ["84068.53", "0"], ["84073.66", "0.031163"], ["84073.68", "0"], ["84084.25", "0"], ["84084.85", "0"], ["84085.34", "0"], ["84086.16", "0"], ["84086.17", "0"], ["84086.65", "0"], ["84087.17", "0"], ["84087.32", "0"], ["84087.64", "0"], ["84087.74", "0"], ["84088.02", "0"], ["84088.20", "0"], ["84088.38", "0"], ["84088.61", "0"], ["84089.24", "0"], ["84089.39", "0"], ["84089.61", "0"], ["84090.03", "0"], ["84090.17", "0"], ["84090.22", "0"], ["84090.92", "0.119905"], ["84091.01", "0"], ["84091.15", "0.035957"], ["84092.26", "0.035972"], ["84092.99", "0.006357"], ["84093.38", "0.006357"], ["84093.52", "0.006357"], ["84094.04", "0.006357"], ["84094.06", "0.006357"], ["84094.47", "0.006356"], ["84094.49", "0.006357"], ["84094.58", "0.010995"], ["84095.48", "0.006357"], ["84095.74", "0.006357"], ["84095.89", "0.006357"], ["84096.01", "0.006357"], ["84096.08", "0.006357"], ["84097.76", "0.006357"], ["84097.86", "0.010993"], ["84098.32", "0.017450"], ["84098.54", "0.006357"], ["84098.57", "0.009990"], ["84099.88", "0.119850"], ["84100.10", "0"], ["84102.10", "0"], ["84103.40", "0.001010"], ["84104.10", "0"], ["84105.40", "0.001015"], ["84106.10", "0"], ["84107.40", "0.001037"], ["84108.10", "0"], ["84109.40", "0.001048"], ["84110.10", "0"], ["84110.74", "0.713345"], ["84111.40", "0.001028"], ["84112.10", "0"], ["84113.40", "0.001050"], ["84114.10", "0"], ["84115.40", "0.001038"], ["84116.10", "0"], ["84117.40", "0.001050"], ["84118.10", "0"], ["84119.40", "0.001006"], ["84120.10", "0"], ["84120.30", "0"], ["84121.00", "0"], ["84121.40", "0.001505"], ["84121.70", "0"], ["84122.90", "0"], ["84123.30", "0"], ["84123.40", "0.003962"], ["84123.50", "0.059550"], ["84124.10", "0.039000"], ["84124.20", "0"], ["84124.30", "0.016620"], ["84125.20", "0"], ["84126.00", "0.009240"], ["84126.90", "0.031440"], ["84127.00", "0.067230"], ["84127.30", "0.053910"], ["84127.60", "0"], ["84128.00", "0"], ["84128.20", "0"], ["84129.10", "0"], ["84129.30", "0.160350"], ["84129.70", "0"], ["84130.10", "0"], ["84130.40", "0.414060"], ["84130.50", "0"], ["84130.60", "0.121620"], ["84130.90", "0.044490"], ["84131.40", "0.436290"], ["84131.70", "0.013380"], ["84132.10", "0.067800"], ["84132.60", "0.045000"], ["84132.70", "0.009000"], ["84132.80", "0.045000"], ["84133.40", "0.508560"], ["84134.10", "0.039510"], ["84134.50", "0.019080"], ["84135.20", "0.113520"], ["84135.30", "0.490320"], ["84135.50", "0.360000"], ["84135.80", "0.023160"], ["84162.10", "0"], ["84165.40", "4.983838"], ["84170.60", "0"], ["84173.90", "4.711992"], ["84179.10", "0"], ["84182.40", "4.349532"], ["84187.60", "0"], ["84190.90", "4.168301"], ["84196.10", "0"], ["84199.40", "5.255684"], ["84204.60", "0"], ["84207.90", "5.165069"], ["84213.10", "0"], ["84216.40", "4.802608"], ["84221.60", "0"], ["84224.90", "5.618145"], ["84230.10", "0"], ["84233.40", "4.258916"], ["84238.60", "0"], ["84241.90", "5.527530"], ["84247.10", "0"], ["84250.40", "5.436914"], ["84255.60", "0"], ["84258.90", "4.621377"], ["84264.10", "0"], ["84267.40", "4.530762"], ["84272.60", "0"], ["84275.90", "3.987071"], ["84281.10", "0"], ["84284.40", "3.896455"], ["84289.60", "0"], ["84292.90", "5.074453"], ["84298.10", "0"], ["84301.40", "4.440147"], ["84306.60", "0"], ["84309.90", "4.077686"], ["84315.10", "0"], ["84318.40", "5.346299"], ["84323.60", "0"], ["84326.90", "4.893223"], ["84568.81", "0"], ["84568.97", "0"], ["84569.23", "0"]], "bids": [["84057.00", "1.283122"], ["84055.90", "0"], ["84055.23", "0"], ["84055.20", "0.006123"], ["84053.90", "0"], ["84053.20", "0.016112"], ["84053.01", "0.034829"], ["84053.00", "0.000281"], ["84051.90", "0"], ["84051.20", "0.042401"], ["84050.80", "0.089533"], ["84049.90", "0"], ["84049.73", "0.247134"], ["84049.64", "0"], ["84049.20", "0.111580"], ["84048.96", "0.017797"], ["84048.54", "0.083499"], ["84048.47", "0.005940"], ["84048.10", "0.018242"], ["84047.92", "0.016406"], ["84047.90", "0"], ["84047.23", "0.009890"], ["84047.20", "0.293633"], ["84047.14", "0.015724"], ["84046.89", "0.007129"], ["84046.83", "0.055545"], ["84046.48", "0.006561"], ["84046.40", "0.007335"], ["84046.22", "0.017095"], ["84045.90", "0"], ["84045.28", "0.007942"], ["84045.20", "0.772717"], ["84045.13", "0.008995"], ["84044.46", "0.008187"], ["84044.12", "0.008276"], ["84043.90", "0.012653"], ["84043.66", "0"], ["84043.21", "0.051761"], ["84043.20", "2.033465"], ["84042.46", "0"], ["84042.24", "0.018518"], ["84042.10", "0"], ["84042.00", "0.000281"], ["84041.90", "0"], ["84041.70", "0.268397"], ["84041.61", "0"], ["84041.26", "0.314110"], ["84041.20", "5.351225"], ["84041.09", "0"], ["84040.45", "0"], ["84040.13", "0"], ["84039.90", "0"], ["84039.59", "0"], ["84039.20", "14.082172"], ["84039.10", "0.001014"], ["84039.05", "0"], ["84038.98", "0"], ["84038.70", "0.107730"], ["84038.56", "0"], ["84038.41", "0"], ["84038.04", "0"], ["84037.90", "0.068370"], ["84037.54", "0"], ["84037.50", "7.154100"], ["84036.90", "0.120180"], ["84036.83", "0.008265"], ["84036.80", "1.753740"], ["84035.90", "0.067980"], ["84035.80", "0.071340"], ["84035.76", "0"], ["84035.70", "2.678310"], ["84035.60", "0.076170"], ["84035.58", "0"], ["84035.53", "0"], ["84035.50", "0.006030"], ["84035.20", "0"], ["84035.12", "0.008061"], ["84034.69", "0"], ["84034.20", "0"], ["84034.00", "2.440500"], ["84033.90", "0.067800"], ["84033.70", "0.120000"], ["84033.50", "0.428970"], ["84033.36", "0"], ["84033.20", "1.079040"], ["84033.10", "0.356760"], ["84033.04", "0.000877"], ["84032.80", "0.120000"], ["84032.75", "0.017450"], ["84032.20", "0.071340"], ["84032.10", "0"], ["84031.70", "0.015000"], ["84031.58", "0"], ["84031.52", "0.015658"], ["84031.48", "0.008591"], ["84031.43", "0.012179"], ["84031.38", "0.009408"], ["84031.34", "0.005954"], ["84030.99", "0"], ["84030.70", "5.059050"], ["84030.60", "2.722290"], ["84030.59", "0.009550"], ["84030.56", "0.008249"], ["84030.54", "0.017165"], ["84030.53", "0.014733"], ["84030.51", "0.005690"], ["84030.50", "2.802360"], ["84030.47", "0.007816"], ["84030.30", "0.120000"], ["84029.90", "1.852230"], ["84029.29", "0"], ["84028.30", "0"], ["84028.00", "0.000281"], ["84027.90", "0"], ["84027.30", "0"], ["84026.80", "0"], ["84026.70", "0"], ["84026.40", "0"], ["84026.30", "0"], ["84026.29", "0"], ["84026.20", "0"], ["84026.18", "0"], ["84026.15", "0"], ["84026.10", "0"], ["84026.00", "0.000281"], ["84025.90", "0"], ["84025.80", "0"], ["84025.69", "0"], ["84025.68", "0"], ["84025.59", "0"], ["84025.49", "0"], ["84025.32", "0"], ["84024.74", "0"], ["84024.72", "0"], ["84024.71", "0"], ["84024.69", "0"], ["84024.66", "0"], ["84024.63", "0"], ["84024.60", "0"], ["84024.31", "0.008919"], ["84023.46", "0.008542"], ["84023.43", "0.013475"], ["84023.42", "0.005602"], ["84023.40", "0.005120"], ["84023.39", "0.008095"], ["84023.37", "0.009906"], ["84022.98", "0"], ["84022.18", "0"], ["84018.45", "0"], ["84018.17", "0"], ["84017.63", "0"], ["84017.60", "0"], ["84017.59", "0"], ["84017.57", "0"], ["84017.54", "0"], ["84017.52", "0"], ["84007.69", "0.007435"], ["84006.00", "0.000281"], ["84004.74", "0.008574"], ["84001.85", "0"], ["83998.89", "0"], ["83998.01", "0"], ["83997.20", "4.077686"], ["83993.90", "0"], ["83988.70", "5.255684"], ["83985.40", "0"], ["83980.20", "4.802608"], ["83976.90", "0"], ["83971.70", "5.436914"], ["83968.40", "0"], ["83963.20", "3.896455"], ["83959.90", "0"], ["83954.70", "4.893223"], ["83951.40", "0"], ["83946.20", "4.349532"], ["83942.90", "0"], ["83937.70", "3.987071"], ["83934.40", "0"], ["83929.20", "4.530762"], ["83925.90", "0"], ["83920.70", "4.983838"], ["83917.40", "0"], ["83912.20", "4.440147"], ["83908.90", "0"], ["83903.70", "4.711992"], ["83900.40", "0"], ["83895.20", "4.168301"], ["83891.90", "0"], ["83886.70", "5.165069"], ["83883.40", "0"], ["83878.20", "5.527530"], ["83874.90", "0"], ["83869.70", "5.346299"], ["83866.40", "0"], ["83861.20", "4.621377"], ["83857.90", "0"], ["83852.70", "4.258916"], ["83849.40", "0"], ["83844.20", "5.074453"], ["83840.90", "0"], ["83835.70", "5.618145"], ["83832.40", "0"], ["83714.29", "0.000123"], ["83713.80", "0.000024"], ["83713.71", "0.000323"], ["83713.64", "0.000192"]], "checksum": -807889897, "ts": "1742584893561"}], "ts": 1742584893565, "record_time": 1742584893.680337, "EXCHANGE": "BITGET"}
