{"action": "update", "arg": {"instType": "SPOT", "channel": "books", "instId": "BTCUSDT"}, "data": [{"asks": [["83996.30", "1.278519"], ["83998.30", "3.364524"], ["84000.30", "8.854009"], ["84007.00", "0.017280"], ["84042.30", "3.992916"], ["84059.10", "4.265160"], ["84067.50", "5.535633"], ["84075.90", "5.263389"], ["84084.30", "4.355908"], ["84092.70", "4.628153"], ["84101.10", "4.446656"], ["84109.50", "4.809649"], ["84126.30", "5.444885"], ["84134.70", "4.537404"], ["84143.10", "5.081893"], ["84151.50", "3.902168"], ["84159.90", "4.718901"], ["84168.30", "4.900397"], ["84176.70", "5.172641"], ["84185.10", "4.991145"], ["84193.50", "4.083664"], ["84201.90", "5.354137"]], "bids": [["83936.47", "0.003640"], ["83935.11", "0.038710"], ["83934.94", "0"], ["83916.20", "4.041985"], ["83916.10", "0.061470"], ["83908.70", "0"], ["83905.60", "0.015000"], ["83904.90", "0.120000"], ["83874.20", "4.174412"], ["83865.80", "4.537404"], ["83849.00", "4.265160"], ["83832.20", "4.355908"], ["83823.80", "4.809649"], ["83815.40", "4.991145"], ["83807.00", "5.626381"], ["83798.60", "4.900397"], ["83790.20", "5.172641"], ["83781.80", "4.446656"], ["83773.40", "4.628153"], ["83765.00", "5.535633"], ["83756.60", "3.992916"], ["83748.20", "5.354137"], ["83739.80", "4.083664"], ["83731.40", "4.718901"], ["83723.00", "5.263389"], ["83714.60", "5.081893"], ["83530.00", "0.000305"], ["83520.00", "0.003146"], ["83448.28", "0"], ["83448.14", "0"]], "checksum": 444142806, "ts": "1742576920843"}], "ts": 1742576920845, "record_time": 1742576921.040922, "EXCHANGE": "BITGET"}
{"action": "update", "arg": {"instType": "SPOT", "channel": "books", "instId": "BTCUSDT"}, "data": [{"asks": [["83940.00", "1.451320"], ["83998.36", "0"], ["84012.80", "1.785442"], ["84042.30", "3.902168"], ["84050.70", "5.626381"], ["84059.10", "4.809649"], ["84067.50", "3.992916"], ["84075.90", "4.900397"], ["84084.30", "5.535633"], ["84092.70", "4.174412"], ["84101.10", "4.991145"], ["84109.50", "5.444885"], ["84117.90", "5.354137"], ["84126.30", "4.083664"], ["84134.70", "4.265160"], ["84143.10", "4.537404"], ["84151.50", "5.172641"], ["84159.90", "4.355908"], ["84168.30", "4.718901"], ["84176.70", "4.446656"], ["84185.10", "5.263389"], ["84193.50", "5.081893"], ["84201.90", "4.628153"], ["84320.00", "0.000098"]], "bids": [["83936.47", "0.014798"], ["83922.20", "0.222005"], ["83920.20", "0.584224"], ["83918.20", "1.537431"], ["83916.20", "4.045872"], ["83874.20", "4.083664"], ["83865.80", "4.991145"], ["83857.40", "5.081893"], ["83849.00", "4.718901"], ["83840.60", "4.628153"], ["83823.80", "5.263389"], ["83815.40", "4.174412"], ["83807.00", "3.992916"], ["83798.60", "3.902168"], ["83790.20", "4.265160"], ["83781.80", "4.900397"], ["83773.40", "5.626381"], ["83765.00", "5.354137"], ["83756.60", "5.535633"], ["83748.20", "4.809649"], ["83739.80", "4.537404"], ["83731.40", "4.446656"], ["83723.00", "5.444885"], ["83714.60", "5.172641"], ["83520.00", "0.002876"]], "checksum": -1695951361, "ts": "1742576921049"}], "ts": 1742576921053, "record_time": 1742576921.262453, "EXCHANGE": "BITGET"}
{"action": "update", "arg": {"instType": "SPOT", "channel": "books", "instId": "BTCUSDT"}, "data": [{"asks": [["83959.80", "0"], ["83962.89", "0.006357"], ["84042.30", "5.172641"], ["84050.70", "4.809649"], ["84059.10", "5.535633"], ["84067.50", "4.537404"], ["84075.90", "3.992916"], ["84084.30", "5.626381"], ["84092.70", "4.446656"], ["84101.10", "4.174412"], ["84109.50", "5.354137"], ["84117.90", "4.718901"], ["84126.30", "5.263389"], ["84134.70", "5.444885"], ["84143.10", "5.081893"], ["84151.50", "4.991145"], ["84159.90", "4.265160"], ["84168.30", "4.355908"], ["84176.70", "4.628153"], ["84185.10", "4.900397"], ["84193.50", "4.083664"], ["84201.90", "3.902168"], ["84320.00", "0.000636"]], "bids": [["83935.28", "0.038710"], ["83935.11", "0"], ["83932.20", "0.002241"], ["83930.20", "0.005897"], ["83928.20", "0.015519"], ["83926.20", "0.040840"], ["83924.20", "0.107475"], ["83922.20", "0.282828"], ["83920.20", "0.744284"], ["83918.20", "1.958642"], ["83916.20", "5.154320"], ["83912.74", "0.013709"], ["83912.51", "0.007345"], ["83912.09", "0.017110"], ["83911.95", "0.009008"], ["83911.35", "0.017372"], ["83910.03", "0"], ["83909.51", "0"], ["83909.41", "0"], ["83908.92", "0"], ["83908.05", "0"], ["83874.20", "3.992916"], ["83868.00", "0"], ["83865.80", "4.537404"], ["83857.40", "5.263389"], ["83849.00", "4.809649"], ["83840.60", "4.083664"], ["83832.20", "5.535633"], ["83823.80", "4.174412"], ["83815.40", "5.626381"], ["83807.00", "5.172641"], ["83798.60", "4.446656"], ["83790.20", "4.718901"], ["83781.80", "4.355908"], ["83773.40", "4.628153"], ["83765.00", "4.265160"], ["83756.60", "3.902168"], ["83748.20", "4.991145"], ["83739.80", "5.354137"], ["83731.40", "5.444885"], ["83723.00", "4.900397"], ["83714.60", "5.081893"], ["83448.28", "0.000151"], ["83448.14", "0.000070"]], "checksum": 2104832540, "ts": "1742576921267"}], "ts": 1742576921269, "record_time": 1742576921.464408, "EXCHANGE": "BITGET"}
{"action": "update", "arg": {"instType": "SPOT", "channel": "books", "instId": "BTCUSDT"}, "data": [{"asks": [["83940.01", "0.000100"], ["83994.30", "0.485826"], ["84000.30", "8.853805"], ["84042.30", "5.535633"], ["84050.70", "4.083664"], ["84059.10", "4.628153"], ["84067.50", "4.718901"], ["84075.90", "4.265160"], ["84084.30", "4.355908"], ["84092.70", "5.354137"], ["84101.10", "5.172641"], ["84109.50", "5.263389"], ["84117.90", "5.626381"], ["84126.30", "5.444885"], ["84134.70", "4.991145"], ["84143.10", "3.992916"], ["84151.50", "4.446656"], ["84159.90", "4.537404"], ["84168.30", "3.902168"], ["84176.70", "4.174412"], ["84185.10", "5.081893"], ["84193.50", "4.809649"], ["84201.90", "4.900397"], ["84325.00", "0.000325"]], "bids": [["83939.99", "0.541499"], ["83917.62", "0.450692"], ["83913.61", "0.010615"], ["83888.00", "0"], ["83874.20", "5.626381"], ["83865.80", "5.535633"], ["83857.40", "5.444885"], ["83849.00", "5.354137"], ["83840.60", "4.446656"], ["83832.20", "4.628153"], ["83823.80", "5.263389"], ["83815.40", "4.355908"], ["83807.00", "3.902168"], ["83798.60", "4.809649"], ["83790.20", "4.991145"], ["83781.80", "4.174412"], ["83773.40", "4.718901"], ["83765.00", "5.081893"], ["83756.60", "4.083664"], ["83748.20", "4.537404"], ["83739.80", "4.900397"], ["83731.40", "3.992916"], ["83723.00", "4.265160"], ["83714.60", "5.172641"], ["83448.00", "0.000012"]], "checksum": 1429409615, "ts": "1742576921469"}], "ts": 1742576921473, "record_time": 1742576921.668959, "EXCHANGE": "BITGET"}
{"action": "update", "arg": {"instType": "SPOT", "channel": "books", "instId": "BTCUSDT"}, "data": [{"asks": [["83984.30", "0.003704"], ["83986.30", "0.009747"], ["83988.30", "0.025651"], ["83990.30", "0.067501"], ["83992.30", "0.177635"], ["83994.30", "0.467461"], ["83996.30", "1.230161"], ["83998.30", "3.237264"], ["84000.30", "8.519116"], ["84007.00", "0"], ["84042.30", "4.537404"], ["84050.70", "5.444885"], ["84059.10", "3.992916"], ["84067.50", "4.446656"], ["84084.30", "5.263389"], ["84092.70", "3.902168"], ["84101.10", "4.991145"], ["84109.50", "5.535633"], ["84117.90", "4.718901"], ["84126.30", "5.081893"], ["84134.70", "4.174412"], ["84143.10", "5.172641"], ["84151.50", "4.900397"], ["84159.90", "4.355908"], ["84168.30", "4.809649"], ["84176.70", "5.354137"], ["84185.10", "5.626381"], ["84193.50", "4.083664"], ["84201.90", "4.628153"], ["84325.00", "0.001670"], ["84330.00", "0.002118"], ["84346.43", "0.000128"]], "bids": [["83935.28", "0"], ["83930.20", "0.006003"], ["83928.20", "0.015799"], ["83926.20", "0.041576"], ["83924.20", "0.109411"], ["83922.20", "0.287924"], ["83920.20", "0.757695"], ["83918.20", "1.993932"], ["83917.62", "1.266772"], ["83916.20", "5.247190"], ["83874.20", "4.718901"], ["83865.80", "5.172641"], ["83857.40", "4.900397"], ["83849.00", "5.081893"], ["83840.60", "5.444885"], ["83832.20", "4.446656"], ["83815.40", "3.902168"], ["83807.00", "4.174412"], ["83798.60", "4.628153"], ["83781.80", "4.265160"], ["83773.40", "4.083664"], ["83765.00", "3.992916"], ["83756.60", "5.626381"], ["83739.80", "4.809649"], ["83731.40", "5.535633"], ["83723.00", "5.354137"], ["83714.60", "4.355908"], ["83580.35", "0"], ["83447.32", "0.000009"], ["83447.31", "0.000008"]], "checksum": -1684837472, "ts": "1742576921677"}], "ts": 1742576921682, "record_time": 1742576921.87768, "EXCHANGE": "BITGET"}
{"action": "update", "arg": {"instType": "SPOT", "channel": "books", "instId": "BTCUSDT"}, "data": [{"asks": [["83940.00", "1.242120"], ["83940.01", "0.002399"], ["83940.14", "0"], ["83940.55", "0"], ["83943.41", "0.114297"], ["83978.83", "0"], ["83982.30", "0.001032"], ["83984.30", "0.002716"], ["83986.30", "0.007148"], ["83988.30", "0.018810"], ["83990.30", "0.049501"], ["83992.30", "0.130264"], ["83994.30", "0.342800"], ["83996.30", "0.902106"], ["83998.30", "2.373965"], ["84000.30", "6.247275"], ["84002.00", "0.078660"], ["84005.00", "0.420690"], ["84005.90", "0"], ["84007.80", "0"], ["84009.40", "0"], ["84013.40", "0.384000"], ["84042.30", "5.172641"], ["84050.70", "4.628153"], ["84059.10", "4.446656"], ["84067.50", "5.263389"], ["84084.30", "5.626381"], ["84092.70", "5.535633"], ["84101.10", "4.809649"], ["84109.50", "4.537404"], ["84117.90", "5.354137"], ["84126.30", "4.355908"], ["84134.70", "5.081893"], ["84143.10", "4.991145"], ["84151.50", "3.902168"], ["84159.90", "4.083664"], ["84168.30", "4.174412"], ["84176.70", "4.718901"], ["84185.10", "5.444885"], ["84193.50", "3.992916"], ["84201.90", "4.900397"], ["84340.00", "0.018983"], ["84346.94", "0.000085"], ["84346.97", "0.000030"], ["84347.55", "0.000095"], ["84347.69", "0.000009"]], "bids": [["83939.99", "0.959899"], ["83936.47", "0.003640"], ["83935.44", "0.038710"], ["83932.20", "0.001870"], ["83930.20", "0.004921"], ["83928.20", "0.012950"], ["83926.20", "0.034078"], ["83924.20", "0.089680"], ["83922.20", "0.236001"], ["83920.20", "0.621055"], ["83918.20", "1.634355"], ["83916.20", "4.300934"], ["83903.00", "0.000032"], ["83901.48", "0"], ["83889.00", "0.000015"], ["83874.20", "5.263389"], ["83865.80", "4.265160"], ["83857.40", "5.172641"], ["83849.00", "4.991145"], ["83840.60", "4.355908"], ["83832.20", "4.174412"], ["83823.80", "4.446656"], ["83815.40", "3.992916"], ["83807.00", "5.354137"], ["83798.60", "5.535633"], ["83790.20", "5.444885"], ["83781.80", "4.083664"], ["83773.40", "4.718901"], ["83765.00", "4.537404"], ["83756.60", "5.081893"], ["83748.20", "5.626381"], ["83739.80", "4.628153"], ["83731.40", "4.900397"], ["83723.00", "4.809649"], ["83714.60", "3.902168"], ["83447.31", "0"]], "checksum": 705340707, "ts": "1742576921880"}], "ts": 1742576921884, "record_time": 1742576922.079792, "EXCHANGE": "BITGET"}
{"action": "update", "arg": {"instType": "SPOT", "channel": "books", "instId": "BTCUSDT"}, "data": [{"asks": [["83940.00", "1.446420"], ["83943.40", "0.034289"], ["83984.30", "0.002139"], ["83986.30", "0.005630"], ["83988.30", "0.014814"], ["83990.30", "0.038985"], ["83992.30", "0.102592"], ["83994.30", "0.269979"], ["83996.30", "0.710472"], ["83998.30", "1.869663"], ["84000.30", "4.920165"], ["84002.00", "0.136980"], ["84004.40", "0.258120"], ["84005.50", "0.224130"], ["84008.60", "0.701430"], ["84012.10", "0"], ["84042.30", "4.355908"], ["84050.70", "4.991145"], ["84059.10", "5.626381"], ["84067.50", "4.900397"], ["84075.90", "5.172641"], ["84084.30", "4.174412"], ["84092.70", "4.537404"], ["84101.10", "4.718901"], ["84109.50", "4.265160"], ["84117.90", "5.263389"], ["84126.30", "4.446656"], ["84143.10", "5.444885"], ["84151.50", "4.083664"], ["84159.90", "3.992916"], ["84168.30", "3.902168"], ["84176.70", "5.535633"], ["84185.10", "5.354137"], ["84193.50", "4.809649"], ["84201.90", "4.628153"], ["84347.69", "0"]], "bids": [["83939.99", "0.541499"], ["83936.47", "0.014798"], ["83934.20", "0.001207"], ["83932.20", "0.003177"], ["83930.20", "0.008359"], ["83928.20", "0.021786"], ["83926.20", "0.057330"], ["83924.20", "0.150868"], ["83922.20", "0.397022"], ["83920.20", "1.044794"], ["83918.20", "2.749459"], ["83916.20", "7.235419"], ["83914.00", "0.916980"], ["83911.30", "0.017850"], ["83911.00", "2.302560"], ["83910.60", "0.240000"], ["83909.91", "0.026355"], ["83908.50", "0.357300"], ["83908.20", "0.191460"], ["83906.40", "0.071460"], ["83906.00", "0.128760"], ["83905.90", "0.008605"], ["83905.60", "0"], ["83904.90", "0"], ["83889.00", "0.000032"], ["83874.20", "4.355908"], ["83865.80", "5.172641"], ["83857.40", "5.354137"], ["83849.00", "4.809649"], ["83840.60", "3.902168"], ["83832.20", "5.081893"], ["83823.80", "4.991145"], ["83807.00", "4.174412"], ["83798.60", "5.263389"], ["83756.60", "4.446656"], ["83748.20", "4.265160"], ["83739.80", "5.626381"], ["83723.00", "5.535633"], ["83714.60", "4.628153"], ["83448.00", "0"], ["83447.32", "0"]], "checksum": -2388567, "ts": "1742576922081"}], "ts": 1742576922085, "record_time": 1742576922.279937, "EXCHANGE": "BITGET"}
{"action": "update", "arg": {"instType": "SPOT", "channel": "books", "instId": "BTCUSDT"}, "data": [{"asks": [["83958.99", "0"], ["83960.64", "0.006356"], ["83961.55", "0.006357"], ["83962.76", "0.006357"], ["83980.11", "0.192168"], ["83982.30", "0.001156"], ["83984.30", "0.003041"], ["83986.30", "0.008004"], ["83986.50", "0.010000"], ["83988.30", "0.021062"], ["83990.30", "0.055661"], ["83992.30", "0.146474"], ["83994.30", "0.385343"], ["83996.30", "1.014060"], ["83998.30", "2.668580"], ["84000.30", "7.022579"], ["84000.60", "0.587070"], ["84002.00", "0.078660"], ["84004.00", "0.111090"], ["84004.40", "0.183180"], ["84005.50", "0"], ["84006.80", "0.071370"], ["84007.00", "0.019980"], ["84007.10", "0.100950"], ["84008.60", "1.205640"], ["84009.70", "2.144580"], ["84042.30", "4.537404"], ["84050.70", "5.263389"], ["84059.10", "4.446656"], ["84067.50", "4.718901"], ["84075.90", "4.265160"], ["84084.30", "4.355908"], ["84092.70", "5.444885"], ["84101.10", "4.900397"], ["84109.50", "3.992916"], ["84117.90", "4.083664"], ["84126.30", "4.174412"], ["84134.70", "4.809649"], ["84143.10", "5.535633"], ["84151.50", "5.172641"], ["84159.90", "5.081893"], ["84168.30", "4.991145"], ["84176.70", "4.628153"], ["84185.10", "3.902168"], ["84193.50", "5.626381"], ["84201.90", "5.354137"], ["84343.97", "0"], ["84344.77", "0"], ["84345.79", "0"], ["84346.43", "0"], ["84346.94", "0"], ["84346.97", "0"], ["84347.55", "0"]], "bids": [["83936.46", "0"], ["83935.62", "0.038710"], ["83935.44", "0"], ["83934.20", "0.001048"], ["83932.20", "0.002759"], ["83930.20", "0.007125"], ["83928.20", "0.018749"], ["83926.20", "0.049341"], ["83924.20", "0.129845"], ["83922.20", "0.341698"], ["83920.20", "0.899203"], ["83918.20", "2.366324"], ["83916.20", "6.226908"], ["83914.00", "0.467310"], ["83912.58", "0.024948"], ["83912.30", "0"], ["83911.30", "0"], ["83910.60", "0.718530"], ["83910.30", "0.022680"], ["83909.40", "0.550530"], ["83908.50", "0"], ["83906.00", "0.057300"], ["83874.20", "4.718901"], ["83865.80", "4.355908"], ["83857.40", "4.174412"], ["83849.00", "5.354137"], ["83840.60", "4.809649"], ["83823.80", "4.446656"], ["83815.40", "5.172641"], ["83807.00", "4.991145"], ["83798.60", "4.083664"], ["83790.20", "4.900397"], ["83781.80", "4.628153"], ["83773.40", "4.537404"], ["83765.00", "5.444885"], ["83756.60", "3.992916"], ["83739.80", "3.902168"], ["83731.40", "5.263389"], ["83714.60", "5.626381"], ["83448.00", "0.000012"]], "checksum": 1339124562, "ts": "1742576922290"}], "ts": 1742576922296, "record_time": 1742576922.492658, "EXCHANGE": "BITGET"}
{"action": "update", "arg": {"instType": "SPOT", "channel": "books", "instId": "BTCUSDT"}, "data": [{"asks": [["83986.30", "0.007747"], ["83988.30", "0.020564"], ["83990.30", "0.054114"], ["83992.30", "0.142406"], ["83994.30", "0.374752"], ["83996.30", "0.986189"], ["83998.30", "2.595235"], ["84000.30", "6.829567"], ["84004.40", "0.270870"], ["84006.80", "0"], ["84042.30", "3.902168"], ["84050.70", "5.535633"], ["84059.10", "5.354137"], ["84067.50", "4.174412"], ["84075.90", "3.992916"], ["84084.30", "4.809649"], ["84092.70", "5.172641"], ["84101.10", "5.444885"], ["84109.50", "5.081893"], ["84117.90", "5.626381"], ["84126.30", "5.263389"], ["84134.70", "4.628153"], ["84143.10", "4.718901"], ["84151.50", "4.355908"], ["84159.90", "4.446656"], ["84168.30", "4.900397"], ["84176.70", "4.537404"], ["84185.10", "4.265160"], ["84193.50", "4.083664"], ["84201.90", "4.991145"], ["84343.97", "0.000188"]], "bids": [["83916.20", "6.227038"], ["83874.20", "4.991145"], ["83865.80", "4.083664"], ["83857.40", "5.081893"], ["83849.00", "3.992916"], ["83840.60", "4.265160"], ["83832.20", "4.174412"], ["83823.80", "3.902168"], ["83815.40", "5.535633"], ["83807.00", "4.446656"], ["83798.60", "4.537404"], ["83790.20", "5.354137"], ["83781.80", "5.172641"], ["83773.40", "4.718901"], ["83765.00", "4.355908"], ["83756.60", "5.263389"], ["83748.20", "4.900397"], ["83739.80", "5.626381"], ["83731.40", "4.809649"], ["83723.00", "5.444885"], ["83714.60", "4.628153"]], "checksum": 1339124562, "ts": "1742576922511"}], "ts": 1742576922514, "record_time": 1742576922.709324, "EXCHANGE": "BITGET"}
{"action": "update", "arg": {"instType": "SPOT", "channel": "books", "instId": "BTCUSDT"}, "data": [{"asks": [["83940.00", "1.560716"], ["83940.01", "0.000100"], ["83943.41", "0"], ["83996.30", "0.986028"], ["83998.30", "2.594811"], ["84000.30", "6.828451"], ["84007.00", "0"], ["84013.70", "1.982700"], ["84042.30", "4.446656"], ["84050.70", "5.444885"], ["84059.10", "4.718901"], ["84067.50", "4.537404"], ["84075.90", "4.900397"], ["84084.30", "5.081893"], ["84092.70", "5.626381"], ["84101.10", "4.809649"], ["84109.50", "4.265160"], ["84117.90", "4.355908"], ["84126.30", "4.174412"], ["84134.70", "5.354137"], ["84143.10", "3.902168"], ["84151.50", "4.991145"], ["84159.90", "5.263389"], ["84168.30", "4.628153"], ["84176.70", "3.992916"], ["84185.10", "5.172641"], ["84201.90", "5.535633"], ["84344.77", "0.000361"]], "bids": [["83909.91", "0"], ["83900.93", "0.026355"], ["83890.00", "0.000017"], ["83887.00", "0"], ["83874.20", "4.809649"], ["83867.00", "0"], ["83865.80", "4.991145"], ["83857.40", "5.626381"], ["83849.00", "4.355908"], ["83840.60", "4.174412"], ["83832.20", "3.902168"], ["83823.80", "4.628153"], ["83815.40", "4.446656"], ["83807.00", "5.172641"], ["83790.20", "3.992916"], ["83781.80", "5.081893"], ["83773.40", "5.535633"], ["83765.00", "4.265160"], ["83756.60", "4.718901"], ["83748.20", "5.263389"], ["83739.80", "4.083664"], ["83731.40", "5.444885"], ["83723.00", "5.354137"], ["83714.60", "4.900397"], ["83447.32", "0.000009"], ["83447.31", "0.000008"]], "checksum": 1216572270, "ts": "1742576922710"}], "ts": 1742576922713, "record_time": 1742576922.908418, "EXCHANGE": "BITGET"}
{"action": "update", "arg": {"instType": "SPOT", "channel": "books", "instId": "BTCUSDT"}, "data": [{"asks": [["83940.14", "0.001376"], ["83943.40", "0"], ["83959.75", "0"], ["83962.35", "0.006357"], ["83982.30", "0.001291"], ["83984.30", "0.003398"], ["83986.30", "0.008941"], ["83988.30", "0.023528"], ["83990.30", "0.061917"], ["83992.30", "0.162939"], ["83994.30", "0.428788"], ["83996.30", "1.128388"], ["83998.30", "2.969444"], ["84000.30", "7.814325"], ["84042.30", "5.354137"], ["84050.70", "4.718901"], ["84059.10", "4.900397"], ["84067.50", "3.902168"], ["84075.90", "4.174412"], ["84084.30", "4.355908"], ["84092.70", "4.446656"], ["84101.10", "4.083664"], ["84109.50", "5.263389"], ["84117.90", "4.537404"], ["84126.30", "5.535633"], ["84134.70", "4.628153"], ["84143.10", "5.081893"], ["84151.50", "4.809649"], ["84159.90", "5.626381"], ["84168.30", "4.265160"], ["84176.70", "5.172641"], ["84185.10", "4.991145"], ["84193.50", "3.992916"], ["84201.90", "5.444885"]], "bids": [["83935.77", "0.038710"], ["83935.62", "0"], ["83906.40", "0"], ["83905.60", "0.015000"], ["83874.20", "4.718901"], ["83865.80", "5.354137"], ["83857.40", "5.081893"], ["83849.00", "5.263389"], ["83840.60", "4.809649"], ["83832.20", "5.535633"], ["83823.80", "3.992916"], ["83815.40", "4.991145"], ["83807.00", "4.265160"], ["83798.60", "4.083664"], ["83790.20", "4.446656"], ["83781.80", "5.626381"], ["83773.40", "3.902168"], ["83765.00", "5.172641"], ["83756.60", "4.628153"], ["83748.20", "5.444885"], ["83739.80", "4.537404"], ["83731.40", "4.174412"], ["83723.00", "4.355908"]], "checksum": -1435086884, "ts": "1742576922927"}], "ts": 1742576922930, "record_time": 1742576923.125294, "EXCHANGE": "BITGET"}
{"action": "update", "arg": {"instType": "SPOT", "channel": "books", "instId": "BTCUSDT"}, "data": [{"asks": [["83940.00", "1.446420"], ["83986.30", "0.008686"], ["83988.30", "0.022856"], ["83990.30", "0.060147"], ["83992.30", "0.158284"], ["83994.30", "0.416536"], ["83996.30", "1.096148"], ["83998.30", "2.884599"], ["84000.30", "7.591051"], ["84013.70", "0"], ["84042.30", "4.537404"], ["84059.10", "4.265160"], ["84067.50", "5.354137"], ["84075.90", "4.446656"], ["84084.30", "4.991145"], ["84092.70", "4.809649"], ["84101.10", "4.900397"], ["84109.50", "3.902168"], ["84117.90", "5.263389"], ["84126.30", "5.444885"], ["84134.70", "5.081893"], ["84143.10", "3.992916"], ["84151.50", "4.083664"], ["84159.90", "4.628153"], ["84168.30", "5.535633"], ["84176.70", "4.174412"], ["84185.10", "4.355908"], ["84193.50", "5.626381"], ["84201.90", "5.172641"], ["84345.79", "0.000034"]], "bids": [["83939.99", "0.541151"], ["83932.20", "0.002322"], ["83930.20", "0.006110"], ["83928.20", "0.016079"], ["83926.20", "0.042314"], ["83924.20", "0.111352"], ["83922.20", "0.293032"], ["83920.20", "0.771137"], ["83918.20", "2.029308"], ["83916.20", "5.340283"], ["83916.00", "0.042960"], ["83911.00", "3.732810"], ["83905.60", "0"], ["83874.20", "5.354137"], ["83865.80", "4.537404"], ["83857.40", "5.172641"], ["83840.60", "4.265160"], ["83832.20", "4.446656"], ["83823.80", "4.991145"], ["83815.40", "4.083664"], ["83807.00", "3.902168"], ["83798.60", "4.628153"], ["83790.20", "5.535633"], ["83781.80", "3.992916"], ["83773.40", "4.174412"], ["83765.00", "5.444885"], ["83756.60", "5.626381"], ["83748.20", "5.081893"], ["83739.80", "4.900397"], ["83731.40", "4.718901"], ["83723.00", "4.809649"], ["83714.60", "4.355908"], ["83447.17", "0.000008"]], "checksum": 1116468746, "ts": "1742576923148"}], "ts": 1742576923153, "record_time": 1742576923.348764, "EXCHANGE": "BITGET"}
{"action": "update", "arg": {"instType": "SPOT", "channel": "books", "instId": "BTCUSDT"}, "data": [{"asks": [["83940.00", "1.560712"], ["83940.01", "0.004414"], ["83957.88", "0"], ["83958.11", "0"], ["83958.40", "0"], ["83959.31", "0"], ["83959.66", "0.035972"], ["83960.30", "0.006357"], ["83960.34", "0"], ["83960.61", "0.006357"], ["83961.10", "0.006357"], ["83962.82", "0.006357"], ["83965.10", "0"], ["83966.88", "0.119850"], ["83982.30", "0.001130"], ["83984.30", "0.002974"], ["83986.30", "0.007827"], ["83988.30", "0.020596"], ["83990.30", "0.054200"], ["83992.30", "0.142633"], ["83994.30", "0.375350"], ["83996.30", "0.987764"], ["83998.30", "2.599377"], ["84000.30", "6.840466"], ["84007.20", "0"], ["84023.16", "0.000179"], ["84042.30", "4.628153"], ["84050.70", "5.354137"], ["84059.10", "4.355908"], ["84067.50", "4.083664"], ["84075.90", "4.174412"], ["84084.30", "4.446656"], ["84092.70", "5.626381"], ["84101.10", "5.535633"], ["84109.50", "5.263389"], ["84117.90", "4.265160"], ["84134.70", "4.718901"], ["84143.10", "4.809649"], ["84151.50", "5.172641"], ["84159.90", "4.991145"], ["84168.30", "4.537404"], ["84176.70", "5.081893"], ["84185.10", "3.902168"], ["84193.50", "3.992916"], ["84201.90", "4.900397"]], "bids": [["83935.77", "0"], ["83926.20", "0.042483"], ["83924.20", "0.111797"], ["83922.20", "0.294202"], ["83920.20", "0.774218"], ["83918.20", "2.037160"], ["83916.20", "5.360948"], ["83916.02", "0.083615"], ["83914.80", "0.005948"], ["83914.59", "0.016428"], ["83914.44", "0.015746"], ["83914.23", "0"], ["83912.81", "0"], ["83912.62", "0"], ["83912.28", "0.007953"], ["83912.24", "0"], ["83909.81", "0"], ["83908.80", "0.268771"], ["83907.01", "0"], ["83888.00", "0.000017"], ["83874.20", "5.444885"], ["83865.80", "5.535633"], ["83857.40", "4.628153"], ["83853.64", "0.000172"], ["83849.00", "4.900397"], ["83840.60", "4.809649"], ["83837.72", "0"], ["83832.20", "5.081893"], ["83823.80", "4.174412"], ["83815.40", "3.992916"], ["83807.00", "4.718901"], ["83798.60", "3.902168"], ["83790.20", "4.083664"], ["83781.80", "4.355908"], ["83773.40", "4.265160"], ["83765.00", "4.991145"], ["83756.60", "5.172641"], ["83748.20", "5.354137"], ["83739.80", "5.263389"], ["83731.40", "4.537404"], ["83723.00", "5.626381"], ["83714.60", "4.446656"]], "checksum": -893587849, "ts": "1742576923353"}], "ts": 1742576923358, "record_time": 1742576923.557586, "EXCHANGE": "BITGET"}
{"action": "update", "arg": {"instType": "SPOT", "channel": "books", "instId": "BTCUSDT"}, "data": [{"asks": [["83982.30", "0.001269"], ["83984.30", "0.003338"], ["83986.30", "0.008784"], ["83988.30", "0.023116"], ["83990.30", "0.060833"], ["83992.30", "0.160086"], ["83994.30", "0.421278"], ["83996.30", "1.108626"], ["83998.30", "2.917437"], ["84000.30", "7.677466"], ["84008.00", "0.073260"], ["84042.30", "4.174412"], ["84050.70", "5.263389"], ["84059.10", "4.991145"], ["84067.50", "3.992916"], ["84075.90", "4.083664"], ["84084.30", "4.809649"], ["84092.70", "5.354137"], ["84101.10", "4.355908"], ["84109.50", "5.444885"], ["84117.90", "5.172641"], ["84126.30", "4.265160"], ["84134.70", "4.537404"], ["84143.10", "4.718901"], ["84151.50", "4.446656"], ["84159.90", "4.900397"], ["84168.30", "5.535633"], ["84176.70", "5.626381"], ["84185.10", "4.628153"], ["84193.50", "3.902168"], ["84201.90", "5.081893"], ["84345.79", "0"]], "bids": [["83936.47", "0"], ["83935.94", "0.038710"], ["83928.20", "0.015941"], ["83926.20", "0.041949"], ["83924.20", "0.110277"], ["83922.20", "0.290203"], ["83920.20", "0.763692"], ["83918.20", "2.009715"], ["83916.20", "5.288724"], ["83913.61", "0.014798"], ["83888.00", "0.000032"], ["83874.20", "4.900397"], ["83865.80", "4.174412"], ["83849.00", "4.446656"], ["83840.60", "5.626381"], ["83832.20", "3.992916"], ["83823.80", "3.902168"], ["83815.40", "5.172641"], ["83807.00", "4.083664"], ["83798.60", "5.444885"], ["83790.20", "4.537404"], ["83781.80", "4.809649"], ["83773.40", "5.263389"], ["83765.00", "4.265160"], ["83756.60", "4.991145"], ["83748.20", "4.355908"], ["83739.80", "5.535633"], ["83731.40", "5.081893"], ["83723.00", "4.718901"], ["83714.60", "5.354137"]], "checksum": 998400437, "ts": "1742576923557"}], "ts": 1742576923559, "record_time": 1742576923.754125, "EXCHANGE": "BITGET"}
{"action": "update", "arg": {"instType": "SPOT", "channel": "books", "instId": "BTCUSDT"}, "data": [{"asks": [["83982.30", "0.001015"], ["83984.30", "0.002670"], ["83986.30", "0.007026"], ["83988.30", "0.018492"], ["83990.30", "0.048662"], ["83992.30", "0.128057"], ["83994.30", "0.336993"], ["83996.30", "0.886824"], ["83998.30", "2.333748"], ["84000.30", "6.141441"], ["84001.90", "0.049020"], ["84004.00", "0.110880"], ["84004.40", "0.285870"], ["84007.10", "0"], ["84008.00", "0"], ["84042.30", "3.902168"], ["84050.70", "4.628153"], ["84059.10", "4.809649"], ["84067.50", "4.991145"], ["84075.90", "5.263389"], ["84084.30", "5.081893"], ["84092.70", "4.718901"], ["84101.10", "4.083664"], ["84126.30", "4.537404"], ["84134.70", "4.355908"], ["84143.10", "5.354137"], ["84151.50", "5.535633"], ["84168.30", "3.992916"], ["84176.70", "4.174412"], ["84185.10", "4.265160"], ["84193.50", "4.446656"], ["84201.90", "5.626381"], ["84345.79", "0.000034"]], "bids": [["83935.95", "0.011927"], ["83874.20", "4.083664"], ["83865.80", "4.900397"], ["83857.40", "5.535633"], ["83849.00", "5.081893"], ["83840.60", "5.172641"], ["83823.80", "4.628153"], ["83815.40", "4.537404"], ["83807.00", "4.446656"], ["83798.60", "5.626381"], ["83790.20", "4.718901"], ["83781.80", "4.991145"], ["83765.00", "4.174412"], ["83756.60", "4.355908"], ["83748.20", "5.354137"], ["83739.80", "3.902168"], ["83731.40", "4.265160"], ["83723.00", "5.444885"], ["83714.60", "4.809649"], ["83447.17", "0"]], "checksum": -1107448385, "ts": "1742576923759"}], "ts": 1742576923761, "record_time": 1742576923.957963, "EXCHANGE": "BITGET"}
{"action": "update", "arg": {"instType": "SPOT", "channel": "books", "instId": "BTCUSDT"}, "data": [{"asks": [["83940.01", "0.000100"], ["83986.30", "0.006816"], ["83988.30", "0.017936"], ["83990.30", "0.047199"], ["83992.30", "0.124209"], ["83994.30", "0.326865"], ["83996.30", "0.860173"], ["83998.30", "2.263612"], ["84000.30", "5.956873"], ["84000.60", "0.182220"], ["84001.90", "0.208080"], ["84002.90", "0.062820"], ["84004.40", "0.202800"], ["84010.50", "0.072420"], ["84013.40", "0"], ["84042.30", "4.265160"], ["84050.70", "3.902168"], ["84059.10", "4.628153"], ["84067.50", "4.900397"], ["84075.90", "4.991145"], ["84084.30", "4.355908"], ["84092.70", "4.083664"], ["84101.10", "4.718901"], ["84109.50", "5.535633"], ["84126.30", "4.809649"], ["84134.70", "4.446656"], ["84143.10", "5.081893"], ["84151.50", "4.174412"], ["84159.90", "5.626381"], ["84168.30", "4.537404"], ["84176.70", "3.992916"], ["84185.10", "5.444885"], ["84193.50", "5.354137"], ["84201.90", "5.263389"], ["84345.79", "0"]], "bids": [["83936.08", "0.038710"], ["83935.94", "0"], ["83928.20", "0.016107"], ["83926.20", "0.042386"], ["83924.20", "0.111542"], ["83922.20", "0.293532"], ["83920.20", "0.772453"], ["83918.20", "2.032771"], ["83916.20", "5.349397"], ["83890.00", "0"], ["83889.00", "0.000015"], ["83874.20", "4.628153"], ["83865.80", "4.537404"], ["83857.40", "4.809649"], ["83849.00", "5.172641"], ["83840.60", "3.992916"], ["83832.20", "5.354137"], ["83823.80", "5.263389"], ["83815.40", "4.991145"], ["83807.00", "5.081893"], ["83798.60", "5.535633"], ["83790.20", "4.083664"], ["83781.80", "3.902168"], ["83773.40", "4.355908"], ["83765.00", "5.444885"], ["83756.60", "4.718901"], ["83748.20", "4.900397"], ["83739.80", "4.174412"], ["83723.00", "5.626381"], ["83714.60", "4.446656"], ["83447.17", "0.000008"]], "checksum": -2029984042, "ts": "1742576923963"}], "ts": 1742576923966, "record_time": 1742576924.161458, "EXCHANGE": "BITGET"}
{"action": "update", "arg": {"instType": "SPOT", "channel": "books", "instId": "BTCUSDT"}, "data": [{"asks": [["83984.30", "0.002269"], ["83986.30", "0.005969"], ["83988.30", "0.015708"], ["83990.30", "0.041337"], ["83992.30", "0.108781"], ["83994.30", "0.286268"], ["83996.30", "0.753335"], ["83998.30", "1.982461"], ["84000.30", "5.217002"], ["84001.90", "0"], ["84002.90", "0.223050"], ["84004.00", "0.111090"], ["84004.40", "0.282330"], ["84010.50", "0"], ["84013.40", "0.384000"], ["84042.30", "4.446656"], ["84050.70", "5.354137"], ["84059.10", "3.992916"], ["84067.50", "4.355908"], ["84075.90", "4.083664"], ["84084.30", "3.902168"], ["84092.70", "4.991145"], ["84101.10", "4.174412"], ["84109.50", "4.809649"], ["84117.90", "5.444885"], ["84126.30", "4.537404"], ["84134.70", "4.265160"], ["84143.10", "5.535633"], ["84151.50", "5.081893"], ["84159.90", "5.172641"], ["84168.30", "4.718901"], ["84176.70", "5.626381"], ["84185.10", "4.900397"], ["84193.50", "4.628153"], ["84345.79", "0.000034"]], "bids": [["83939.99", "0.750351"], ["83936.09", "0.011927"], ["83935.95", "0"], ["83932.20", "0.002489"], ["83930.20", "0.006549"], ["83928.20", "0.017234"], ["83926.20", "0.045353"], ["83924.20", "0.119349"], ["83922.20", "0.314077"], ["83920.20", "0.826519"], ["83918.20", "2.175050"], ["83916.20", "5.723815"], ["83909.40", "0"], ["83905.60", "0.015000"], ["83874.20", "5.354137"], ["83865.80", "4.174412"], ["83857.40", "4.537404"], ["83849.00", "4.355908"], ["83840.60", "4.628153"], ["83832.20", "5.263389"], ["83823.80", "5.081893"], ["83815.40", "4.446656"], ["83807.00", "5.535633"], ["83798.60", "5.444885"], ["83781.80", "4.991145"], ["83773.40", "4.718901"], ["83765.00", "5.172641"], ["83756.60", "5.626381"], ["83748.20", "3.902168"], ["83739.80", "4.900397"], ["83723.00", "3.992916"], ["83714.60", "4.809649"]], "checksum": 447361715, "ts": "1742576924165"}], "ts": 1742576924167, "record_time": 1742576924.362944, "EXCHANGE": "BITGET"}
{"action": "update", "arg": {"instType": "SPOT", "channel": "books", "instId": "BTCUSDT"}, "data": [{"asks": [["83956.57", "0"], ["83957.00", "0"], ["83957.86", "0.035971"], ["83958.29", "0.119905"], ["83958.93", "0"], ["83959.11", "0"], ["83960.24", "0"], ["83960.29", "0.006357"], ["83960.38", "0"], ["83960.46", "0.123957"], ["83960.64", "0"], ["83961.40", "0"], ["83961.54", "0.006357"], ["83961.60", "0.010995"], ["83961.85", "0.006356"], ["83962.03", "0"], ["83962.29", "0"], ["83962.46", "0"], ["83962.68", "0.016429"], ["83963.20", "0"], ["83963.32", "0.119901"], ["83963.65", "0.016429"], ["83963.82", "0.006357"], ["83963.83", "0"], ["83963.98", "0"], ["83964.49", "0.006357"], ["83964.74", "0"], ["83965.05", "0.108207"], ["83965.33", "0.010993"], ["83966.04", "0.009990"], ["83966.67", "0"], ["83966.73", "0"], ["83966.90", "0"], ["83967.27", "0"], ["83967.96", "0.119905"], ["83968.10", "0.119858"], ["83968.19", "0.015895"], ["83968.56", "0.009989"], ["83969.20", "0"], ["83970.41", "0.006356"], ["83971.05", "0"], ["83971.80", "0"], ["83972.34", "0.015896"], ["83973.02", "0.010988"], ["83986.30", "0.006004"], ["83986.50", "0"], ["83988.30", "0.015801"], ["83990.30", "0.041582"], ["83992.30", "0.109426"], ["83994.30", "0.287961"], ["83996.30", "0.757794"], ["83998.30", "1.994194"], ["84000.30", "5.247878"], ["84000.60", "0.118470"], ["84002.50", "1.016550"], ["84004.00", "0.110880"], ["84012.40", "0.012480"], ["84013.40", "0"], ["84042.30", "5.626381"], ["84050.70", "4.991145"], ["84059.10", "4.900397"], ["84067.50", "3.992916"], ["84075.90", "4.446656"], ["84084.30", "4.355908"], ["84092.70", "5.263389"], ["84101.10", "4.083664"], ["84109.50", "5.172641"], ["84126.30", "4.809649"], ["84143.10", "4.628153"], ["84151.50", "5.535633"], ["84159.90", "5.354137"], ["84168.30", "4.174412"], ["84176.70", "4.718901"], ["84185.10", "4.537404"], ["84193.50", "3.902168"], ["84201.90", "5.081893"], ["84346.43", "0.000128"], ["84346.94", "0.000085"]], "bids": [["83939.99", "0.551151"], ["83936.08", "0"], ["83932.20", "0.002910"], ["83930.20", "0.007658"], ["83928.20", "0.020152"], ["83926.20", "0.053032"], ["83924.20", "0.139716"], ["83922.20", "0.367675"], ["83920.20", "0.967566"], ["83918.20", "2.546226"], ["83917.57", "0.089650"], ["83917.16", "0.247478"], ["83916.77", "0.004035"], ["83916.28", "0"], ["83916.20", "6.700594"], ["83915.87", "0"], ["83915.81", "0.017822"], ["83915.64", "0.018268"], ["83914.46", "0"], ["83914.45", "0"], ["83914.28", "0"], ["83914.03", "0.006570"], ["83913.92", "0.055622"], ["83913.67", "0.017119"], ["83913.16", "0.028867"], ["83912.74", "0.007139"], ["83912.70", "0"], ["83912.46", "0"], ["83912.45", "0.025192"], ["83912.28", "0.016151"], ["83912.12", "0.224990"], ["83911.87", "0"], ["83911.09", "0"], ["83910.94", "0.008288"], ["83910.93", "0"], ["83910.83", "0"], ["83910.77", "0.051833"], ["83910.60", "0.240000"], ["83910.49", "0.012671"], ["83909.80", "0.018544"], ["83909.65", "0"], ["83909.42", "0"], ["83909.27", "0"], ["83908.51", "0"], ["83908.00", "0.223028"], ["83907.52", "0.259144"], ["83907.28", "0.021161"], ["83907.25", "0.076224"], ["83906.63", "0"], ["83906.23", "0"], ["83905.96", "0.006978"], ["83905.11", "0.012457"], ["83904.90", "0.120000"], ["83903.89", "0"], ["83903.51", "0.073167"], ["83902.51", "0.056450"], ["83902.22", "0"], ["83901.29", "0"], ["83900.83", "0.000878"], ["83899.64", "0"], ["83882.43", "0.003602"], ["83881.14", "0"], ["83874.20", "4.900397"], ["83865.80", "5.444885"], ["83857.40", "4.628153"], ["83849.00", "4.083664"], ["83840.60", "4.991145"], ["83832.20", "3.902168"], ["83823.80", "5.535633"], ["83815.40", "4.355908"], ["83807.00", "4.265160"], ["83798.60", "3.992916"], ["83790.20", "4.809649"], ["83781.80", "5.081893"], ["83773.40", "5.263389"], ["83765.00", "5.626381"], ["83756.60", "4.537404"], ["83748.20", "5.354137"], ["83739.80", "4.174412"], ["83731.40", "5.172641"], ["83723.00", "4.446656"], ["83714.60", "4.718901"], ["83530.00", "0.000035"], ["83447.17", "0"]], "checksum": 1256866700, "ts": "1742576924366"}], "ts": 1742576924369, "record_time": 1742576924.565302, "EXCHANGE": "BITGET"}
{"action": "update", "arg": {"instType": "SPOT", "channel": "books", "instId": "BTCUSDT"}, "data": [{"asks": [["83954.82", "0.010791"], ["83958.85", "0"], ["83961.59", "0"], ["83962.81", "0.006357"], ["83980.11", "0"], ["83988.30", "0.015981"], ["83990.30", "0.042055"], ["83992.30", "0.110669"], ["83994.30", "0.291234"], ["83996.30", "0.766407"], ["83998.30", "2.016861"], ["84000.30", "5.307529"], ["84000.60", "0.418350"], ["84001.50", "0.893400"], ["84002.00", "0.077970"], ["84002.50", "0"], ["84010.50", "0.069780"], ["84042.30", "5.444885"], ["84050.70", "3.902168"], ["84059.10", "5.535633"], ["84067.50", "4.537404"], ["84075.90", "5.263389"], ["84084.30", "5.172641"], ["84092.70", "4.446656"], ["84101.10", "4.355908"], ["84109.50", "4.265160"], ["84117.90", "4.083664"], ["84126.30", "4.900397"], ["84134.70", "4.809649"], ["84143.10", "3.992916"], ["84151.50", "4.628153"], ["84159.90", "4.718901"], ["84168.30", "5.626381"], ["84176.70", "4.991145"], ["84185.10", "5.354137"], ["84193.50", "5.081893"], ["84201.90", "4.174412"], ["84346.97", "0.000030"]], "bids": [["83939.99", "0.760351"], ["83936.21", "0.038710"], ["83936.09", "0"], ["83932.20", "0.002621"], ["83930.20", "0.006897"], ["83928.20", "0.018149"], ["83926.20", "0.047762"], ["83924.20", "0.125501"], ["83922.20", "0.330266"], ["83920.20", "0.869122"], ["83918.20", "2.287163"], ["83916.20", "6.018848"], ["83905.60", "0.027510"], ["83889.00", "0"], ["83887.00", "0.000017"], ["83874.20", "4.628153"], ["83865.80", "4.083664"], ["83857.40", "5.535633"], ["83849.00", "4.446656"], ["83840.60", "5.081893"], ["83832.20", "5.172641"], ["83823.80", "4.537404"], ["83815.40", "4.265160"], ["83807.00", "3.992916"], ["83798.60", "3.902168"], ["83790.20", "4.991145"], ["83781.80", "5.354137"], ["83773.40", "4.900397"], ["83765.00", "4.174412"], ["83756.60", "5.444885"], ["83748.20", "5.626381"], ["83739.80", "4.809649"], ["83731.40", "5.263389"], ["83723.00", "4.718901"], ["83714.60", "4.355908"]], "checksum": 1970461815, "ts": "1742576924577"}], "ts": 1742576924580, "record_time": 1742576924.80542, "EXCHANGE": "BITGET"}
{"action": "update", "arg": {"instType": "SPOT", "channel": "books", "instId": "BTCUSDT"}, "data": [{"asks": [["83940.00", "1.560364"], ["83958.28", "0.100598"], ["83980.54", "0.192639"], ["84042.30", "4.991145"], ["84050.70", "5.444885"], ["84059.10", "5.081893"], ["84067.50", "4.265160"], ["84075.90", "4.628153"], ["84084.30", "4.537404"], ["84092.70", "5.263389"], ["84101.10", "4.718901"], ["84109.50", "4.174412"], ["84117.90", "4.900397"], ["84126.30", "4.809649"], ["84134.70", "5.354137"], ["84151.50", "5.535633"], ["84159.90", "3.902168"], ["84168.30", "5.172641"], ["84176.70", "4.083664"], ["84185.10", "4.446656"], ["84193.50", "4.355908"], ["84201.90", "5.626381"], ["84346.94", "0"], ["84346.97", "0"]], "bids": [["83936.22", "0.012256"], ["83928.20", "0.018000"], ["83926.20", "0.047367"], ["83924.20", "0.124650"], ["83922.20", "0.328027"], ["83920.20", "0.863229"], ["83918.20", "2.271655"], ["83916.20", "5.978040"], ["83874.20", "5.626381"], ["83865.80", "4.628153"], ["83857.40", "4.809649"], ["83849.00", "3.992916"], ["83840.60", "4.355908"], ["83832.20", "4.991145"], ["83823.80", "4.265160"], ["83815.40", "4.718901"], ["83807.00", "5.444885"], ["83798.60", "5.081893"], ["83790.20", "4.900397"], ["83781.80", "3.902168"], ["83773.40", "5.354137"], ["83765.00", "5.263389"], ["83756.60", "4.537404"], ["83748.20", "4.446656"], ["83739.80", "4.174412"], ["83731.40", "4.083664"], ["83723.00", "5.535633"], ["83714.60", "5.172641"], ["83520.00", "0.002606"], ["83447.31", "0"]], "checksum": 1511306016, "ts": "1742576924793"}], "ts": 1742576924797, "record_time": 1742576924.993307, "EXCHANGE": "BITGET"}
{"event": "subscribe", "arg": {"instType": "SPOT", "channel": "books", "instId": "BTCUSDT"}, "record_time": 1742577042.87768, "EXCHANGE": "BITGET"}
{"action": "snapshot", "arg": {"instType": "SPOT", "channel": "books", "instId": "BTCUSDT"}, "data": [{"asks": [["83970.01", "2.152148"], ["83970.21", "0.262400"], ["83971.96", "0.336946"], ["83971.97", "0.260162"], ["83971.98", "0.000100"], ["83971.99", "0.000100"], ["83972.00", "0.000100"], ["83973.26", "0.035971"], ["83973.65", "0.119905"], ["83975.83", "0.035972"], ["83976.09", "0.012714"], ["83976.48", "0.006357"], ["83976.63", "0.006357"], ["83976.76", "0.006357"], ["83977.07", "0.006357"], ["83977.24", "0.006357"], ["83977.26", "0.006356"], ["83977.54", "0.010995"], ["83977.74", "0.016429"], ["83977.84", "0.006357"], ["83978.10", "0.006357"], ["83978.27", "0.038979"], ["83978.28", "0.129930"], ["83978.34", "0.006357"], ["83978.72", "0.119901"], ["83979.29", "0.006357"], ["83979.57", "0.016429"], ["83979.66", "0.006357"], ["83979.86", "0.006357"], ["83979.96", "0.002381"], ["83980.20", "0.006357"], ["83981.18", "0.006357"], ["83981.28", "0.010993"], ["83981.46", "0.009990"], ["83982.59", "0.035955"], ["83982.60", "0.119850"], ["83983.64", "0.015895"], ["83983.72", "0.009989"], ["83984.05", "0.119858"], ["83984.18", "1.026669"], ["83985.95", "0.017472"], ["83986.00", "0.006356"], ["83987.43", "0.087772"], ["83995.14", "0.209200"], ["83996.38", "0.013838"], ["83996.86", "0.314355"], ["84001.04", "0.117200"], ["84006.03", "0.044733"], ["84006.31", "0.209200"], ["84009.20", "0.001368"], ["84011.20", "0.002232"], ["84012.28", "0.010000"], ["84013.20", "0.005874"], ["84013.62", "0.001598"], ["84015.20", "0.015457"], ["84015.79", "0.062760"], ["84015.80", "0.209200"], ["84016.57", "0.714144"], ["84017.20", "0.040894"], ["84018.50", "0.000976"], ["84019.20", "0.107616"], ["84019.65", "0.001598"], ["84021.20", "0.283200"], ["84023.20", "0.745264"], ["84025.20", "1.961219"], ["84025.82", "0.209200"], ["84027.20", "5.161103"], ["84029.20", "13.581850"], ["84029.30", "7.685670"], ["84029.40", "0.001025"], ["84030.00", "0.042480"], ["84030.10", "4.288650"], ["84030.90", "0.035700"], ["84031.10", "1.537080"], ["84031.30", "0.926190"], ["84031.60", "1.111380"], ["84032.00", "1.650060"], ["84032.20", "0.467700"], ["84032.50", "0.257400"], ["84033.10", "0.069510"], ["84033.50", "0.257400"], ["84034.00", "1.701570"], ["84034.21", "0.001989"], ["84034.22", "0.209200"], ["84035.20", "0.392400"], ["84035.30", "0.276000"], ["84035.90", "2.001300"], ["84036.00", "0.327300"], ["84036.10", "0.107400"], ["84036.30", "0.580380"], ["84036.50", "0.006030"], ["84037.00", "0.432000"], ["84037.10", "0.192000"], ["84037.20", "0.098520"], ["84037.90", "0.323610"], ["84038.00", "4.654230"], ["84039.80", "0.178680"], ["84040.00", "0.697350"], ["84042.82", "0.209200"], ["84044.02", "0.894734"], ["84050.00", "0.000694"], ["84050.32", "1.784645"], ["84052.01", "0.209200"], ["84060.00", "0.002000"], ["84061.10", "0.000179"], ["84063.20", "0.062814"], ["84063.21", "0.209200"], ["84070.00", "0.001279"], ["84071.20", "4.989424"], ["84071.61", "0.209200"], ["84079.60", "5.080141"], ["84081.19", "0.209200"], ["84081.60", "0.000027"], ["84084.82", "0.057335"], ["84085.76", "0.001810"], ["84088.00", "4.354407"], ["84089.59", "0.209200"], ["84090.00", "0.002000"], ["84090.37", "0.071668"], ["84095.34", "0.071678"], ["84096.40", "4.535840"], ["84098.51", "0.003620"], ["84101.11", "0.209200"], ["84104.80", "3.900823"], ["84108.90", "0.001450"], ["84111.50", "0.296078"], ["84113.20", "4.626557"], ["84114.71", "0.203800"], ["84120.00", "0.002000"], ["84120.31", "0.000018"], ["84120.42", "0.000008"], ["84121.21", "0.000010"], ["84121.60", "5.170858"], ["84121.90", "0.000124"], ["84121.93", "0.000069"], ["84122.10", "0.000042"], ["84122.11", "0.000023"], ["84122.15", "0.125742"], ["84124.00", "0.000175"], ["84124.14", "0.000135"], ["84124.65", "0.000066"], ["84125.00", "0.007748"], ["84125.55", "0.209200"], ["84126.51", "0.000008"], ["84127.27", "0.000010"], ["84128.44", "0.000072"], ["84129.03", "0.000008"], ["84129.07", "0.000020"], ["84130.00", "4.717274"], ["84130.43", "0.003446"], ["84132.13", "0.000176"], ["84132.80", "0.000008"], ["84132.97", "0.000104"], ["84133.33", "0.002817"], ["84133.94", "0.209200"], ["84136.28", "0.000011"], ["84137.93", "0.000024"], ["84138.40", "4.898708"], ["84138.74", "0.000024"], ["84139.90", "0.000023"], ["84140.00", "0.000630"], ["84140.96", "0.000013"], ["84141.97", "0.000423"], ["84142.33", "0.209200"], ["84142.86", "0.042208"], ["84144.14", "0.000061"], ["84144.15", "0.000053"], ["84144.74", "0.000093"], ["84146.80", "4.263690"], ["84148.30", "0.000060"], ["84148.94", "0.000137"], ["84148.96", "0.000039"], ["84150.00", "0.002747"], ["84150.08", "0.000019"], ["84150.33", "0.000008"], ["84150.72", "0.209200"], ["84151.40", "0.001450"], ["84151.59", "0.000020"], ["84151.79", "0.000036"], ["84152.17", "0.000010"], ["84153.84", "0.000008"], ["84153.85", "0.000023"], ["84155.20", "3.991540"], ["84155.83", "0.000019"], ["84156.01", "0.000019"], ["84157.75", "0.027677"], ["84157.89", "0.000183"], ["84159.01", "0.000149"], ["84159.09", "0.000042"], ["84159.11", "0.209200"], ["84159.59", "0.000036"], ["84159.60", "0.300112"], ["84159.62", "0.000099"], ["84160.00", "0.001138"], ["84160.71", "0.000016"], ["84162.16", "0.000009"], ["84162.50", "0.000031"], ["84163.18", "0.000050"], ["84163.60", "5.533725"], ["84163.64", "0.000008"], ["84163.92", "0.000010"], ["84164.43", "0.011010"], ["84165.59", "0.000054"], ["84166.55", "0.000008"], ["84166.67", "0.000699"], ["84166.69", "0.000010"], ["84166.71", "0.000008"], ["84167.50", "0.209200"], ["84168.50", "0.000008"], ["84169.49", "0.001213"], ["84170.00", "0.000725"], ["84170.25", "0.000143"], ["84170.47", "0.000013"], ["84170.56", "0.000009"], ["84171.43", "0.000016"], ["84171.59", "0.001720"], ["84172.00", "4.807991"], ["84173.62", "0.000024"], ["84173.91", "0.000020"], ["84174.51", "0.000388"], ["84174.57", "0.000010"], ["84174.61", "0.000043"], ["84175.73", "0.000010"], ["84175.89", "0.209200"], ["84176.47", "0.000040"], ["84177.20", "0.000064"], ["84179.10", "0.000008"], ["84180.00", "0.002639"], ["84180.09", "0.000033"], ["84180.40", "5.352292"], ["84181.09", "0.000030"], ["84181.81", "0.001547"], ["84181.82", "0.000060"], ["84182.16", "0.000048"], ["84182.69", "0.000067"], ["84183.27", "0.000009"], ["84183.50", "0.000113"], ["84183.67", "0.000010"], ["84184.17", "0.000009"], ["84184.29", "0.209200"], ["84188.80", "5.624442"], ["84188.89", "0.000025"], ["84189.33", "0.000133"], ["84189.45", "0.000023"], ["84190.00", "0.000670"], ["84190.54", "0.169446"], ["84191.18", "0.000041"], ["84192.00", "0.001184"], ["84192.12", "0.000288"], ["84192.69", "0.209200"], ["84192.98", "0.000033"], ["84193.22", "0.000023"], ["84193.77", "0.000012"], ["84193.99", "0.000209"], ["84194.12", "0.000071"], ["84195.96", "0.000038"], ["84196.77", "0.000020"], ["84197.20", "5.261575"], ["84197.27", "0.000016"], ["84198.00", "0.001012"], ["84198.35", "0.000057"], ["84198.45", "0.000008"], ["84200.00", "0.013254"], ["84200.01", "0.000246"], ["84201.09", "0.209200"], ["84203.00", "0.000008"], ["84203.59", "0.000061"], ["84204.08", "0.000184"], ["84205.60", "5.443008"], ["84205.61", "0.000034"], ["84205.79", "0.000135"], ["84205.88", "0.000080"], ["84206.90", "0.000008"], ["84207.14", "0.000128"], ["84207.69", "0.000009"], ["84208.00", "0.000012"], ["84209.48", "0.000013"], ["84209.49", "0.209200"], ["84209.68", "0.000019"], ["84209.82", "0.000047"], ["84210.00", "0.002618"], ["84210.30", "0.001444"], ["84210.53", "0.000009"], ["84212.00", "0.000012"], ["84212.47", "0.000009"], ["84212.50", "0.006969"], ["84214.00", "4.082256"], ["84214.29", "0.000033"], ["84214.50", "0.301368"], ["84214.88", "0.000161"], ["84215.69", "0.000008"], ["84216.22", "0.000008"], ["84216.67", "0.000970"], ["84216.87", "0.000008"], ["84217.48", "0.000095"], ["84217.86", "0.000273"], ["84217.89", "0.209200"], ["84219.35", "0.000008"], ["84219.55", "0.000349"], ["84220.00", "0.000618"], ["84220.69", "0.000135"], ["84222.00", "0.000081"], ["84222.03", "0.000013"], ["84222.22", "0.000907"], ["84222.40", "4.172973"], ["84223.05", "0.000039"], ["84223.65", "0.000178"], ["84223.89", "0.000008"], ["84224.11", "0.000277"], ["84224.14", "0.000016"], ["84224.62", "0.000022"], ["84225.00", "0.000107"], ["84225.86", "0.007944"], ["84225.88", "0.000024"], ["84226.09", "0.000013"], ["84226.29", "0.209200"], ["84226.42", "0.000096"], ["84228.57", "0.000013"], ["84228.72", "0.000188"], ["84229.07", "0.000010"], ["84229.39", "0.000020"], ["84230.00", "0.000640"], ["84230.76", "0.000008"], ["84230.77", "0.000111"], ["84230.80", "4.445124"], ["84232.69", "0.000066"], ["84233.16", "0.000023"], ["84233.34", "0.000119"], ["84233.38", "0.001273"], ["84233.43", "0.000015"], ["84233.87", "0.000039"], ["84234.04", "0.000137"], ["84234.07", "0.000039"], ["84234.23", "0.000698"], ["84235.23", "0.000051"], ["84235.29", "0.042045"], ["84235.93", "0.000046"], ["84238.10", "0.000024"], ["84238.53", "0.000072"], ["84238.89", "0.000134"], ["84239.00", "0.000240"], ["84239.11", "0.000011"], ["84239.13", "0.000010"], ["84240.00", "0.003183"], ["84242.34", "0.000423"], ["84242.60", "0.000537"], ["84244.90", "0.000085"], ["84246.15", "0.000015"], ["84249.42", "0.000030"], ["84250.00", "0.067266"], ["84251.44", "0.000011"], ["84252.44", "0.000143"], ["84252.50", "0.000025"], ["84254.39", "0.000022"], ["84254.55", "0.000009"], ["84255.35", "0.000143"], ["84256.00", "0.000022"], ["84256.79", "0.000314"], ["84257.14", "0.000145"], ["84258.91", "0.000036"], ["84259.12", "0.000009"], ["84259.87", "0.000093"], ["84259.99", "0.000017"], ["84260.00", "0.000676"], ["84260.87", "0.000008"], ["84263.15", "0.000019"], ["84263.16", "0.000183"], ["84264.71", "0.000009"], ["84266.08", "0.000016"], ["84266.67", "0.002976"], ["84267.78", "0.000010"], ["84268.56", "0.000013"], ["84269.24", "0.000032"], ["84270.00", "0.002641"], ["84270.27", "0.000009"], ["84270.80", "0.000018"], ["84270.96", "0.000055"], ["84270.98", "0.000052"], ["84271.10", "0.000019"], ["84271.34", "0.000026"], ["84272.72", "0.000105"], ["84272.73", "0.000492"], ["84273.33", "0.000013"], ["84276.28", "0.000009"], ["84277.78", "0.000011"], ["84278.24", "0.000050"], ["84278.38", "0.000199"], ["84279.36", "0.000009"], ["84279.98", "0.000239"], ["84280.00", "0.001334"], ["84280.70", "0.000033"], ["84280.74", "0.000047"], ["84281.69", "0.000099"], ["84282.35", "0.000071"], ["84282.39", "0.000135"], ["84282.82", "0.000012"], ["84283.33", "0.000010"], ["84283.87", "0.000020"], ["84285.00", "0.000031"], ["84285.68", "0.000178"], ["84285.71", "0.000347"], ["84285.95", "0.000028"], ["84286.00", "0.000119"], ["84286.67", "0.000009"], ["84286.73", "0.000057"], ["84286.79", "0.000016"], ["84287.50", "0.000076"], ["84288.00", "0.003000"], ["84288.89", "0.000361"], ["84289.58", "0.000008"], ["84290.00", "0.000617"], ["84293.56", "0.000063"], ["84294.12", "0.000080"], ["84294.20", "0.000128"], ["84294.68", "0.000019"], ["84296.87", "0.000014"], ["84297.06", "0.000035"], ["84298.07", "0.000811"], ["84298.31", "0.000023"], ["84298.41", "0.000009"], ["84298.64", "0.000088"], ["84300.00", "0.023791"], ["84301.40", "0.000023"], ["84301.47", "0.000041"], ["84302.88", "0.000067"], ["84303.00", "0.296549"], ["84306.66", "0.000145"], ["84307.00", "0.000113"], ["84307.23", "0.000008"], ["84309.09", "0.000010"], ["84309.60", "0.002450"], ["84309.68", "0.000062"], ["84309.96", "0.000011"], ["84310.00", "0.000348"], ["84310.34", "0.000331"], ["84310.35", "0.000146"], ["84311.11", "0.000025"], ["84311.16", "0.000008"], ["84311.31", "0.002260"], ["84311.72", "0.000013"], ["84312.50", "0.000125"], ["84313.03", "0.000024"], ["84314.97", "0.000008"], ["84315.00", "0.000404"], ["84315.74", "0.000051"], ["84316.67", "0.000322"], ["84317.24", "0.000135"], ["84317.40", "0.000010"], ["84318.18", "0.000012"], ["84318.59", "0.000027"], ["84319.15", "0.000137"], ["84319.18", "0.000039"], ["84320.00", "0.000905"], ["84321.87", "0.000919"], ["84322.11", "0.000008"], ["84324.32", "0.000069"], ["84325.00", "0.002340"], ["84325.07", "0.000161"], ["84326.09", "0.000010"], ["84326.42", "0.000023"], ["84327.14", "0.000039"], ["84327.73", "0.041940"], ["84328.95", "0.000174"], ["84329.64", "0.000026"], ["84330.00", "0.002521"], ["84332.00", "0.511323"], ["84332.56", "0.000009"], ["84333.32", "0.000047"], ["84333.33", "0.003953"], ["84333.36", "0.000010"], ["84333.38", "0.000008"], ["84334.48", "0.000096"], ["84334.77", "0.000022"], ["84336.00", "0.000133"], ["84336.23", "0.000013"], ["84336.29", "0.000010"], ["84336.34", "0.000176"], ["84337.25", "0.000067"], ["84337.35", "0.000008"], ["84337.50", "0.000010"], ["84338.26", "0.000023"], ["84338.46", "0.000015"], ["84339.21", "0.000010"], ["84339.29", "0.000029"], ["84339.50", "0.000323"], ["84339.62", "0.000051"], ["84340.00", "0.019520"], ["84340.46", "0.000143"], ["84340.72", "0.000066"], ["84341.00", "0.002997"], ["84341.01", "0.000008"], ["84342.11", "0.000051"], ["84342.63", "0.000009"], ["84342.70", "0.000423"], ["84343.02", "0.000338"], ["84343.07", "0.000014"], ["84343.70", "0.000075"], ["84343.97", "0.000188"], ["84344.77", "0.000361"], ["84345.00", "0.000806"]], "bids": [["83970.00", "0.000004"], ["83965.10", "0.001028"], ["83963.10", "0.001045"], ["83961.10", "0.001044"], ["83959.45", "0.314355"], ["83959.10", "0.001036"], ["83957.47", "0.007593"], ["83957.10", "0.001028"], ["83956.34", "0.010000"], ["83956.22", "0.006539"], ["83955.10", "0.001004"], ["83953.23", "0.009897"], ["83953.10", "0.001005"], ["83951.10", "0.001048"], ["83949.91", "0.061457"], ["83949.18", "0.013838"], ["83949.10", "0.001040"], ["83948.40", "0.064927"], ["83948.39", "0.209200"], ["83947.46", "0.006213"], ["83947.10", "0.001010"], ["83945.10", "0.002455"], ["83944.80", "0.001002"], ["83944.40", "0.001041"], ["83943.50", "0.001005"], ["83942.90", "0.001024"], ["83942.00", "0.752460"], ["83941.78", "0.006206"], ["83941.30", "0.253950"], ["83940.89", "0.008274"], ["83940.80", "2.358930"], ["83940.50", "0.117300"], ["83940.20", "0.240000"], ["83940.00", "0.464070"], ["83939.91", "0.209200"], ["83939.90", "0.954750"], ["83939.30", "0.012240"], ["83939.24", "0.008069"], ["83939.10", "0.220950"], ["83936.43", "0.714826"], ["83936.40", "0.089280"], ["83936.10", "0.066360"], ["83935.82", "0.009798"], ["83935.79", "0.006973"], ["83935.70", "0.007383"], ["83935.69", "0.009559"], ["83935.60", "0.120000"], ["83935.40", "0.009000"], ["83935.26", "0.007775"], ["83934.70", "0.045000"], ["83934.10", "0.030000"], ["83934.00", "0.120000"], ["83933.96", "0.010057"], ["83933.94", "0.008477"], ["83933.93", "0.008601"], ["83933.90", "0.006311"], ["83933.80", "0.015000"], ["83933.79", "0.009255"], ["83933.78", "0.008024"], ["83933.63", "0.005941"], ["83933.49", "0.008525"], ["83933.26", "0.007197"], ["83933.20", "0.160920"], ["83933.15", "0.006594"], ["83933.08", "0.009417"], ["83932.96", "0.089618"], ["83932.60", "0.120000"], ["83932.52", "0.247390"], ["83932.20", "0.961890"], ["83932.18", "0.083585"], ["83932.10", "0.000200"], ["83931.65", "0.018261"], ["83931.59", "0.017815"], ["83931.13", "0.005946"], ["83930.56", "0.016422"], ["83930.09", "0.209200"], ["83929.92", "0.015740"], ["83929.85", "0.055601"], ["83929.24", "0.006568"], ["83929.07", "0.017113"], ["83928.93", "0.005177"], ["83928.91", "0.008551"], ["83928.85", "0.004857"], ["83928.75", "0.007950"], ["83928.72", "0.007136"], ["83928.66", "0.008102"], ["83928.36", "0.025182"], ["83928.31", "0.015537"], ["83928.23", "0.017104"], ["83928.21", "0.028857"], ["83928.11", "0.017365"], ["83928.06", "0.005058"], ["83927.80", "0.009005"], ["83927.50", "0.224909"], ["83926.71", "0.051813"], ["83926.63", "0.008285"], ["83926.61", "0.012666"], ["83926.60", "0.010355"], ["83926.54", "0.008773"], ["83925.21", "0.018538"], ["83924.87", "0.268669"], ["83923.94", "0.222912"], ["83922.69", "0.076197"], ["83922.43", "0.021153"], ["83921.67", "0.002073"], ["83920.69", "0.012452"], ["83920.46", "0.017472"], ["83918.00", "0.209200"], ["83917.00", "0.000160"], ["83916.00", "0.000121"], ["83912.99", "0.007443"], ["83910.07", "0.008582"], ["83910.00", "0.002000"], ["83906.20", "0.209200"], ["83905.62", "0.001173"], ["83905.43", "0.007257"], ["83905.09", "0.007345"], ["83903.83", "0.000385"], ["83903.47", "0.001176"], ["83903.10", "5.624442"], ["83899.04", "0.001810"], ["83898.80", "0.003601"], ["83896.83", "0.209200"], ["83894.70", "3.991540"], ["83892.18", "0.000172"], ["83891.60", "0.000971"], ["83890.65", "0.003620"], ["83888.70", "0.010010"], ["83886.30", "4.717274"], ["83885.36", "0.071678"], ["83883.63", "0.071668"], ["83881.03", "0.209200"], ["83880.00", "0.002000"], ["83877.90", "5.533725"], ["83874.86", "0.057335"], ["83872.28", "0.209200"], ["83869.50", "5.080141"], ["83866.31", "0.125751"], ["83863.87", "0.209200"], ["83861.10", "5.443008"], ["83858.70", "0.000061"], ["83856.79", "0.005960"], ["83855.47", "0.209200"], ["83852.70", "5.170858"], ["83850.00", "0.002000"], ["83847.07", "0.209200"], ["83844.43", "0.000100"], ["83844.30", "4.354407"], ["83838.67", "0.209200"], ["83835.90", "5.261575"], ["83831.57", "0.012430"], ["83829.04", "0.012430"], ["83827.50", "4.989424"], ["83820.00", "0.007600"], ["83819.10", "4.807991"], ["83815.37", "0.000022"], ["83810.70", "4.172973"], ["83810.00", "0.000270"], ["83808.45", "0.001720"], ["83802.81", "0.000022"], ["83802.30", "5.352292"], ["83801.90", "0.304409"], ["83800.00", "0.000387"], ["83793.90", "4.535840"], ["83790.00", "0.002270"], ["83785.50", "4.626557"], ["83780.00", "0.000270"], ["83779.93", "0.000028"], ["83777.10", "4.898708"], ["83773.31", "0.000154"], ["83770.00", "0.000270"], ["83768.70", "3.900823"], ["83767.90", "0.001457"], ["83767.54", "0.027677"], ["83762.50", "0.000076"], ["83760.30", "4.082256"], ["83760.00", "0.002281"], ["83754.70", "0.000013"], ["83751.90", "4.445124"], ["83751.34", "0.000487"], ["83750.67", "0.000146"], ["83750.00", "0.000270"], ["83749.66", "0.000016"], ["83749.50", "0.000069"], ["83745.16", "0.000389"], ["83744.30", "0.001434"], ["83743.50", "4.263690"], ["83740.00", "0.000322"], ["83737.00", "0.000009"], ["83730.00", "0.002270"], ["83729.32", "0.000035"], ["83728.57", "0.000017"], ["83728.37", "0.001273"], ["83727.27", "0.000066"], ["83726.20", "0.000016"], ["83723.40", "0.000068"], ["83720.92", "0.011010"], ["83720.00", "0.002671"], ["83717.48", "0.005970"], ["83713.71", "0.000323"], ["83710.00", "0.000293"], ["83705.85", "0.000019"], ["83703.75", "0.000364"], ["83703.70", "0.000425"], ["83702.50", "0.000033"], ["83701.28", "0.000248"], ["83700.80", "0.311180"], ["83700.00", "0.004213"], ["83690.84", "0.000162"], ["83690.00", "0.000270"], ["83689.50", "0.000113"], ["83687.50", "0.006969"], ["83687.00", "0.000008"], ["83686.11", "0.000096"], ["83680.00", "0.000368"], ["83677.37", "0.000008"], ["83676.47", "0.000080"], ["83675.68", "0.000008"], ["83675.00", "0.000076"], ["83674.19", "0.000020"], ["83673.87", "0.000022"], ["83672.50", "0.000031"], ["83670.05", "0.000033"], ["83670.00", "0.002270"], ["83669.66", "0.000010"], ["83669.09", "0.000135"], ["83667.23", "0.012503"], ["83666.67", "0.000146"], ["83664.71", "0.000071"], ["83663.91", "0.000161"], ["83662.97", "0.000149"], ["83660.14", "0.000016"], ["83660.00", "0.000270"], ["83659.60", "0.000143"], ["83659.49", "0.000012"], ["83654.23", "0.000009"], ["83650.00", "0.000353"], ["83648.40", "0.001485"], ["83648.13", "1.717310"], ["83646.67", "0.000018"], ["83642.10", "0.305869"], ["83640.35", "0.000022"], ["83640.00", "0.003066"], ["83639.71", "0.000041"], ["83639.15", "0.000009"], ["83638.32", "0.000039"], ["83638.30", "0.000137"], ["83637.17", "0.000027"], ["83636.36", "0.041598"], ["83636.07", "0.001537"], ["83633.33", "0.000970"], ["83631.53", "0.000009"], ["83630.43", "0.000010"], ["83630.00", "0.000619"], ["83629.03", "0.000039"], ["83629.02", "0.000078"], ["83625.00", "0.000356"], ["83623.43", "0.000010"], ["83621.62", "0.000009"], ["83620.70", "0.000146"], ["83620.69", "0.000016"], ["83620.00", "0.000667"], ["83619.21", "0.000051"], ["83618.18", "0.000008"], ["83617.90", "0.000364"], ["83616.67", "0.000322"], ["83615.85", "0.000024"], ["83611.93", "0.000028"], ["83610.00", "0.002619"], ["83608.30", "0.493274"], ["83607.60", "0.000014"], ["83603.60", "0.000061"], ["83603.26", "0.000010"], ["83602.67", "0.000133"], ["83600.00", "0.015433"], ["83598.51", "0.000039"], ["83596.01", "0.000013"], ["83594.44", "0.000134"], ["83593.33", "0.000013"], ["83590.00", "0.000619"], ["83588.24", "0.042020"], ["83587.50", "0.000076"], ["83587.10", "0.000028"], ["83586.96", "0.002633"], ["83586.29", "0.000008"], ["83584.53", "0.000314"], ["83584.34", "0.000008"], ["83584.00", "0.000022"], ["83583.85", "0.000052"], ["83583.33", "0.000010"], ["83581.82", "0.000010"], ["83581.73", "0.000067"], ["83581.30", "0.001130"], ["83580.56", "0.000019"], ["83580.31", "0.000023"], ["83580.00", "0.002642"], ["83578.95", "0.000033"], ["83578.04", "0.000096"], ["83577.78", "0.000025"], ["83576.47", "0.000071"], ["83574.50", "0.000143"], ["83571.43", "0.000104"], ["83571.42", "0.000008"], ["83570.62", "0.000016"], ["83570.45", "0.000012"], ["83570.00", "0.000059"], ["83569.08", "0.000093"], ["83568.28", "0.000010"], ["83567.57", "0.000008"], ["83566.00", "0.000113"], ["83565.22", "0.000021"], ["83563.71", "0.000022"], ["83562.71", "0.000023"], ["83562.50", "0.000761"], ["83560.71", "0.001273"], ["83560.00", "0.000331"], ["83558.43", "0.000019"], ["83558.00", "0.000008"], ["83556.15", "0.000024"], ["83555.56", "0.000105"], ["83555.38", "0.000013"], ["83553.72", "0.000161"], ["83553.21", "0.000039"], ["83553.19", "0.000137"], ["83552.63", "0.000051"], ["83551.42", "0.000017"], ["83550.58", "0.000009"], ["83550.00", "0.002130"], ["83546.24", "0.000016"], ["83545.82", "0.000009"], ["83545.45", "0.000113"], ["83544.83", "0.000135"], ["83544.33", "0.000008"], ["83543.48", "0.000010"], ["83542.86", "0.000013"], ["83540.93", "0.000035"], ["83540.15", "0.000014"], ["83540.00", "0.000012"], ["83539.78", "0.000423"], ["83539.45", "0.000033"], ["83539.43", "0.000009"], ["83537.50", "0.000016"], ["83537.23", "0.000188"], ["83535.71", "0.000016"], ["83534.48", "0.000016"], ["83533.68", "0.000144"], ["83533.33", "0.000151"], ["83532.05", "0.000364"], ["83532.00", "0.002409"], ["83531.38", "0.000010"], ["83531.31", "0.000390"], ["83530.61", "0.000085"], ["83530.39", "0.000043"], ["83530.00", "0.000035"], ["83529.41", "0.000085"], ["83528.71", "0.000024"], ["83528.11", "0.000179"], ["83527.05", "0.000008"], ["83526.32", "0.000183"], ["83523.81", "0.000009"], ["83523.06", "0.000022"], ["83521.43", "0.000273"], ["83521.12", "0.000022"], ["83520.00", "0.002606"], ["83519.52", "0.000176"], ["83516.67", "0.000970"], ["83514.80", "0.000537"], ["83514.29", "0.000009"], ["83513.51", "0.000070"], ["83512.50", "0.006969"], ["83511.11", "0.000009"], ["83510.71", "0.000128"], ["83510.49", "0.000019"], ["83509.09", "0.000008"], ["83508.29", "0.000015"], ["83508.06", "0.000039"], ["83507.69", "0.000015"], ["83507.21", "0.000297"], ["83506.49", "0.000088"], ["83505.74", "0.000315"], ["83502.04", "0.000016"], ["83500.72", "0.000033"], ["83500.04", "0.000008"], ["83500.02", "0.000010"], ["83500.01", "0.000119"], ["83500.00", "0.015549"], ["83499.14", "0.000051"], ["83498.85", "0.000030"], ["83498.52", "0.000013"], ["83497.26", "0.000010"], ["83496.77", "0.000008"], ["83496.48", "0.000008"], ["83495.80", "0.041940"], ["83495.20", "0.000008"], ["83494.42", "0.000039"], ["83493.98", "0.000008"], ["83493.77", "0.000013"], ["83491.92", "0.000009"], ["83491.23", "0.000033"], ["83490.00", "0.002000"], ["83489.39", "0.000143"], ["83488.85", "0.000459"], ["83488.30", "0.000065"], ["83488.24", "0.000071"], ["83487.05", "0.000023"], ["83486.67", "0.000008"], ["83486.37", "0.000008"], ["83485.71", "0.000016"], ["83485.00", "0.000012"], ["83483.48", "0.000424"], ["83482.76", "0.000008"], ["83482.35", "0.000105"], ["83481.47", "0.000219"], ["83481.40", "0.000012"], ["83481.09", "0.000016"], ["83480.00", "0.000021"], ["83478.26", "0.016818"], ["83477.27", "0.000042"], ["83476.45", "0.000067"], ["83476.19", "0.000024"], ["83474.95", "0.000026"], ["83474.17", "0.000460"], ["83473.68", "0.000242"], ["83472.80", "0.000050"], ["83472.51", "0.000063"], ["83472.00", "0.000012"], ["83470.00", "0.000052"], ["83469.98", "0.000096"], ["83468.61", "0.000061"], ["83468.10", "0.000039"], ["83468.09", "0.000137"], ["83467.89", "0.000072"], ["83466.67", "0.002827"], ["83465.47", "0.000019"], ["83464.91", "0.000022"], ["83464.65", "0.000135"], ["83464.29", "0.000036"], ["83463.89", "0.000026"], ["83462.50", "0.000025"], ["83462.01", "0.000009"], ["83461.54", "0.000178"], ["83461.53", "0.000008"], ["83460.43", "0.000010"], ["83460.00", "0.002021"], ["83459.46", "0.000008"], ["83458.33", "0.000218"], ["83458.15", "0.000010"], ["83458.10", "0.000011"], ["83457.63", "0.000023"], ["83456.52", "0.000010"], ["83456.00", "0.000133"], ["83455.56", "0.000025"], ["83455.07", "0.000013"], ["83454.55", "0.000027"], ["83454.54", "0.001547"], ["83454.53", "0.000057"], ["83453.95", "0.000093"], ["83453.56", "0.000022"], ["83452.83", "0.000008"], ["83451.33", "0.000010"], ["83450.00", "0.005575"], ["83448.28", "0.000151"], ["83448.14", "0.000070"], ["83448.00", "0.000012"], ["83447.32", "0.000009"], ["83447.31", "0.000008"], ["83447.17", "0.000008"], ["83446.43", "0.000016"], ["83445.30", "0.000011"], ["83445.16", "0.000054"], ["83444.44", "0.000105"], ["83444.38", "0.000025"], ["83444.27", "0.000028"], ["83443.53", "0.000161"], ["83442.50", "0.000113"], ["83441.56", "0.000024"], ["83440.00", "0.000460"], ["83439.42", "0.000423"], ["83439.33", "0.000010"], ["83437.50", "0.000009"], ["83437.10", "0.000095"], ["83433.33", "0.000134"], ["83433.12", "0.000544"], ["83433.00", "0.000075"], ["83432.57", "0.000155"], ["83431.37", "0.000008"], ["83430.00", "0.002012"], ["83429.00", "0.000008"], ["83428.57", "0.000212"], ["83427.23", "0.000099"], ["83425.93", "0.000011"], ["83425.00", "0.006969"], ["83423.73", "0.001213"], ["83423.42", "0.000061"], ["83421.99", "0.000188"], ["83421.05", "0.000260"], ["83420.00", "0.018057"], ["83419.12", "0.000041"], ["83417.42", "0.000176"], ["83417.32", "0.000018"]], "checksum": 0, "ts": "1742577042618"}], "ts": 1742577042684, "record_time": 1742577042.928203, "EXCHANGE": "BITGET"}
{"action": "update", "arg": {"instType": "SPOT", "channel": "books", "instId": "BTCUSDT"}, "data": [{"asks": [["83970.01", "2.395657"], ["83970.20", "0.198863"], ["83971.96", "0"], ["83982.74", "0.119905"], ["83984.18", "0"], ["83984.61", "0.010988"], ["83985.95", "0.033368"], ["83987.43", "0"], ["84001.08", "0.180861"], ["84006.10", "0.001695"], ["84008.10", "0.002765"], ["84009.20", "0"], ["84010.10", "0.007276"], ["84011.20", "0"], ["84012.10", "0.019149"], ["84013.20", "0"], ["84014.10", "0.050392"], ["84015.20", "0"], ["84016.10", "0.132609"], ["84017.20", "0"], ["84018.10", "0.348971"], ["84019.20", "0"], ["84020.10", "0.918346"], ["84021.20", "0"], ["84022.10", "2.416700"], ["84023.19", "0.241934"], ["84023.20", "0"], ["84024.10", "6.359737"], ["84025.20", "0"], ["84026.10", "16.735964"], ["84026.20", "0.001004"], ["84026.70", "0.001040"], ["84026.80", "0.001008"], ["84027.00", "0.001014"], ["84027.10", "2.329230"], ["84027.20", "0"], ["84027.80", "0.035700"], ["84028.00", "0.042480"], ["84028.90", "2.358810"], ["84029.20", "5.739030"], ["84029.30", "0"], ["84029.40", "0"], ["84030.00", "0.112170"], ["84030.10", "0"], ["84030.30", "0.073230"], ["84030.60", "0.022800"], ["84030.90", "0"], ["84031.00", "1.747290"], ["84031.10", "1.942230"], ["84031.30", "0"], ["84031.60", "0.656970"], ["84032.00", "1.649700"], ["84032.40", "0.027660"], ["84033.10", "0"], ["84034.00", "2.188680"], ["84034.60", "0.196628"], ["84035.20", "0.596400"], ["84035.50", "0.180000"], ["84035.90", "1.965600"], ["84036.30", "0.574950"], ["84037.90", "0"], ["84038.00", "0"], ["84039.80", "0"], ["84040.00", "0"], ["84043.71", "0.000179"], ["84061.10", "0"], ["84068.10", "5.261770"], ["84071.20", "0"], ["84076.50", "4.445288"], ["84079.60", "0"], ["84084.90", "4.989609"], ["84088.00", "0"], ["84093.30", "5.624650"], ["84096.40", "0"], ["84101.70", "3.900967"], ["84104.80", "0"], ["84110.10", "4.354568"], ["84113.20", "0"], ["84118.50", "4.626729"], ["84121.60", "0"], ["84126.90", "4.536008"], ["84130.00", "0.060049"], ["84135.30", "4.263848"], ["84138.40", "0"], ["84143.70", "4.082408"], ["84146.80", "0"], ["84152.10", "5.443210"], ["84155.20", "0"], ["84160.50", "5.352490"], ["84163.60", "0"], ["84168.90", "5.080329"], ["84172.00", "0"], ["84177.30", "4.898889"], ["84180.40", "0"], ["84185.70", "4.808169"], ["84188.80", "0"], ["84194.10", "4.717449"], ["84197.20", "0"], ["84202.50", "3.991687"], ["84205.60", "0"], ["84210.90", "4.173128"], ["84214.00", "0"], ["84219.30", "5.171050"], ["84222.40", "0"], ["84227.70", "5.533930"], ["84230.80", "0"], ["84320.01", "1.600689"], ["84342.11", "0"], ["84342.63", "0"], ["84342.70", "0"], ["84343.02", "0"], ["84343.07", "0"], ["84343.70", "0"], ["84343.97", "0"], ["84344.77", "0"], ["84345.00", "0"]], "bids": [["83965.10", "0"], ["83963.10", "0"], ["83962.00", "0.001001"], ["83961.10", "0"], ["83960.00", "0.001033"], ["83959.10", "0"], ["83958.00", "0.001031"], ["83957.10", "0"], ["83956.00", "0.001092"], ["83955.10", "0"], ["83954.21", "0.038687"], ["83954.00", "0.001484"], ["83953.31", "0.114049"], ["83953.24", "0.003585"], ["83953.10", "0"], ["83952.00", "0.003905"], ["83951.10", "0"], ["83950.00", "0.010275"], ["83949.91", "0"], ["83949.10", "0"], ["83948.00", "0.027040"], ["83947.10", "0"], ["83946.00", "0.071159"], ["83945.10", "0"], ["83944.80", "0"], ["83944.40", "0"], ["83944.00", "0.187260"], ["83943.50", "0"], ["83943.06", "0.386729"], ["83942.90", "0"], ["83942.00", "0.492788"], ["83941.90", "0.001029"], ["83941.50", "0.002610"], ["83941.30", "0.001004"], ["83940.80", "0"], ["83940.50", "0"], ["83940.20", "0.100800"], ["83940.00", "0.002122"], ["83939.90", "0"], ["83939.10", "0.221130"], ["83938.10", "0.073590"], ["83937.50", "0.204856"], ["83937.20", "0.071970"], ["83936.10", "0.187860"], ["83935.61", "0.013639"], ["83935.60", "0.186360"], ["83934.90", "0.420000"], ["83934.70", "0"], ["83934.40", "0.444660"], ["83934.10", "0"], ["83934.00", "0.026610"], ["83933.80", "0"], ["83932.27", "0.007823"], ["83932.20", "1.462620"], ["83932.13", "0.009320"], ["83932.11", "0.008258"], ["83932.10", "0.497850"], ["83931.20", "0.536970"], ["83930.90", "0.240000"], ["83930.80", "0.985650"], ["83930.70", "0.018590"], ["83930.02", "0.005598"], ["83929.40", "1.178250"], ["83929.20", "1.786860"], ["83925.03", "0.008310"], ["83925.01", "0.005124"], ["83924.89", "0.005608"], ["83923.92", "0.004034"], ["83923.01", "0.008928"], ["83922.30", "0.259052"], ["83920.11", "0.024948"], ["83918.20", "0.073141"], ["83916.00", "0.000281"], ["83914.88", "0.000878"], ["83914.09", "0.056430"], ["83908.10", "0.207210"], ["83903.10", "0"], ["83901.49", "0.007660"], ["83900.00", "3.991687"], ["83894.70", "0"], ["83892.18", "0"], ["83891.60", "3.900967"], ["83886.30", "0"], ["83883.20", "4.989609"], ["83877.90", "0"], ["83874.82", "0.000172"], ["83874.80", "5.261770"], ["83869.50", "0"], ["83866.40", "5.624650"], ["83861.10", "0"], ["83858.00", "4.173128"], ["83852.70", "0"], ["83849.60", "4.717449"], ["83844.30", "0"], ["83841.20", "4.536008"], ["83835.90", "0"], ["83832.80", "5.443210"], ["83827.50", "0"], ["83824.40", "5.080329"], ["83819.10", "0"], ["83816.00", "4.354568"], ["83810.70", "0"], ["83807.60", "4.898889"], ["83802.30", "0"], ["83799.20", "5.533930"], ["83793.90", "0"], ["83790.80", "4.082408"], ["83785.50", "0"], ["83782.40", "4.808169"], ["83777.10", "0"], ["83774.00", "5.352490"], ["83768.70", "0"], ["83765.60", "4.263848"], ["83760.30", "0"], ["83757.20", "4.445288"], ["83751.90", "0"], ["83748.80", "5.171050"], ["83743.50", "0"], ["83740.40", "4.626729"], ["83437.50", "0"], ["83437.10", "0"], ["83433.33", "0"], ["83433.12", "0"], ["83433.00", "0"], ["83432.57", "0"], ["83431.37", "0"], ["83430.00", "0"], ["83429.00", "0"], ["83428.57", "0"], ["83427.23", "0"], ["83425.93", "0"], ["83425.00", "0"], ["83423.73", "0"], ["83423.42", "0"], ["83421.99", "0"], ["83421.05", "0"], ["83420.00", "0"], ["83419.12", "0"], ["83417.42", "0"], ["83417.32", "0"]], "checksum": 180516148, "ts": "1742577042829"}], "ts": 1742577042833, "record_time": 1742577043.028248, "EXCHANGE": "BITGET"}
{"action": "update", "arg": {"instType": "SPOT", "channel": "books", "instId": "BTCUSDT"}, "data": [{"asks": [["83976.52", "3.185871"], ["83978.27", "0.071984"], ["84005.13", "3.716849"], ["84034.00", "1.814280"], ["84035.90", "0"], ["84037.50", "0.240000"], ["84068.10", "4.173128"], ["84084.90", "5.080329"], ["84093.30", "5.261770"], ["84101.70", "3.991687"], ["84110.10", "4.263848"], ["84118.50", "4.082408"], ["84126.90", "4.626729"], ["84135.30", "5.624650"], ["84143.70", "5.443210"], ["84152.10", "4.536008"], ["84160.50", "5.171050"], ["84168.90", "4.717449"], ["84177.30", "4.989609"], ["84185.70", "3.900967"], ["84194.10", "4.354568"], ["84202.50", "5.352490"], ["84210.90", "4.808169"], ["84219.30", "5.533930"], ["84227.70", "4.898889"], ["84341.00", "0"], ["84341.01", "0"]], "bids": [["83962.01", "0.047600"], ["83953.32", "0.041438"], ["83953.24", "0"], ["83943.06", "0"], ["83940.14", "0.764289"], ["83938.50", "1.041810"], ["83938.10", "0.073410"], ["83937.20", "0.596790"], ["83935.40", "0"], ["83929.20", "0"], ["83918.00", "0.209321"], ["83900.00", "5.533930"], ["83891.60", "5.171050"], ["83883.20", "4.717449"], ["83874.80", "4.263848"], ["83866.40", "5.080329"], ["83849.60", "5.352490"], ["83841.20", "3.900967"], ["83832.80", "4.445288"], ["83824.40", "4.354568"], ["83816.00", "4.808169"], ["83807.60", "3.991687"], ["83799.20", "4.898889"], ["83790.80", "5.443210"], ["83782.40", "4.989609"], ["83774.00", "4.082408"], ["83765.60", "5.624650"], ["83757.20", "4.536008"], ["83748.80", "5.261770"]], "checksum": 1206446918, "ts": "1742577043029"}], "ts": 1742577043032, "record_time": 1742577043.225842, "EXCHANGE": "BITGET"}
{"action": "update", "arg": {"instType": "SPOT", "channel": "books", "instId": "BTCUSDT"}, "data": [{"asks": [["83970.20", "0"], ["83976.51", "1.054194"], ["83978.27", "0"], ["84034.00", "1.327170"], ["84068.10", "4.808169"], ["84076.50", "3.900967"], ["84084.90", "4.082408"], ["84093.30", "5.171050"], ["84101.70", "4.263848"], ["84110.10", "4.354568"], ["84118.50", "5.533930"], ["84135.30", "4.445288"], ["84143.70", "5.261770"], ["84152.10", "5.624650"], ["84160.50", "4.173128"], ["84168.90", "4.536008"], ["84177.30", "5.443210"], ["84185.70", "4.717449"], ["84190.54", "0"], ["84194.10", "4.898889"], ["84210.90", "4.989609"], ["84219.30", "3.991687"], ["84227.70", "5.080329"], ["84341.00", "0.002997"], ["84341.01", "0.000008"]], "bids": [["83962.02", "0.047600"], ["83956.35", "0.017341"], ["83954.21", "0"], ["83954.00", "0.001796"], ["83952.00", "0.004728"], ["83950.00", "0.012442"], ["83948.00", "0.032742"], ["83946.00", "0.086162"], ["83944.00", "0.226741"], ["83942.00", "0.596688"], ["83941.80", "0.001021"], ["83940.20", "0"], ["83940.00", "0.492690"], ["83939.40", "0.831180"], ["83938.50", "0"], ["83937.20", "0.071970"], ["83936.60", "0.160920"], ["83933.20", "0"], ["83929.40", "2.141970"], ["83900.00", "4.173128"], ["83891.60", "4.536008"], ["83883.20", "4.082408"], ["83874.80", "4.808169"], ["83866.40", "4.989609"], ["83858.00", "5.261770"], ["83849.60", "4.445288"], ["83841.20", "5.080329"], ["83832.80", "5.443210"], ["83824.40", "3.900967"], ["83816.00", "4.717449"], ["83807.60", "4.263848"], ["83799.20", "5.533930"], ["83790.80", "4.354568"], ["83782.40", "4.898889"], ["83774.00", "4.626729"], ["83765.60", "5.352490"], ["83757.20", "5.171050"], ["83748.80", "3.991687"], ["83740.40", "5.624650"], ["83439.33", "0"]], "checksum": 1604462031, "ts": "1742577043230"}], "ts": 1742577043233, "record_time": 1742577043.428323, "EXCHANGE": "BITGET"}
{"action": "update", "arg": {"instType": "SPOT", "channel": "books", "instId": "BTCUSDT"}, "data": [{"asks": [["83970.01", "2.395347"], ["83971.96", "0.115205"], ["83982.59", "0.067432"], ["84008.10", "0.002908"], ["84010.10", "0.007652"], ["84012.10", "0.020138"], ["84014.10", "0.052995"], ["84016.10", "0.139460"], ["84018.10", "0.367000"], ["84020.10", "0.965790"], ["84022.10", "2.541551"], ["84024.10", "6.688293"], ["84026.10", "17.600771"], ["84027.10", "2.329440"], ["84027.80", "0.035910"], ["84028.00", "0.042690"], ["84028.90", "2.359020"], ["84030.00", "0.111990"], ["84030.30", "0.071220"], ["84031.10", "1.834650"], ["84032.80", "0.035700"], ["84036.30", "0.612570"], ["84037.50", "0"], ["84068.10", "3.900967"], ["84076.50", "4.354568"], ["84084.90", "5.624650"], ["84093.30", "3.991687"], ["84101.70", "5.261770"], ["84110.10", "5.171050"], ["84118.50", "4.717449"], ["84126.90", "4.989609"], ["84135.30", "4.626729"], ["84143.70", "4.173128"], ["84152.10", "5.080329"], ["84160.50", "5.443210"], ["84168.90", "4.898889"], ["84177.30", "4.082408"], ["84185.70", "5.533930"], ["84194.10", "5.352490"], ["84202.50", "4.536008"], ["84210.90", "4.263848"], ["84219.30", "4.445288"], ["84227.70", "4.808169"], ["84341.01", "0"]], "bids": [["83962.03", "0.047600"], ["83962.01", "0"], ["83956.35", "0"], ["83954.80", "0.038687"], ["83954.00", "0.002158"], ["83953.41", "0.114048"], ["83953.31", "0"], ["83952.00", "0.005680"], ["83950.00", "0.014948"], ["83948.00", "0.039335"], ["83946.00", "0.103515"], ["83944.00", "0.272408"], ["83942.00", "0.716863"], ["83940.00", "0.492900"], ["83939.40", "0"], ["83939.10", "0.221160"], ["83938.10", "0.073620"], ["83937.20", "0.070020"], ["83932.60", "0"], ["83932.20", "2.042640"], ["83930.90", "0"], ["83930.80", "0.865470"], ["83929.40", "3.320220"], ["83929.20", "1.786860"], ["83928.60", "0.045000"], ["83900.00", "3.991687"], ["83891.60", "4.354568"], ["83883.20", "4.898889"], ["83866.40", "5.171050"], ["83858.00", "4.717449"], ["83849.60", "5.080329"], ["83841.20", "5.443210"], ["83832.80", "4.173128"], ["83824.40", "5.261770"], ["83816.00", "4.445288"], ["83807.60", "4.989609"], ["83799.20", "4.082408"], ["83790.80", "5.352490"], ["83782.40", "4.536008"], ["83774.00", "3.900967"], ["83765.60", "4.626729"], ["83757.20", "5.624650"], ["83748.80", "4.263848"], ["83740.40", "5.533930"], ["83439.33", "0.000010"]], "checksum": -4612217, "ts": "1742577043449"}], "ts": 1742577043455, "record_time": 1742577043.649986, "EXCHANGE": "BITGET"}
{"action": "update", "arg": {"instType": "SPOT", "channel": "books", "instId": "BTCUSDT"}, "data": [{"asks": [["83970.01", "2.395657"], ["83984.04", "0.051171"], ["84024.10", "6.688505"], ["84026.10", "17.601329"], ["84026.50", "2.359920"], ["84027.10", "2.329020"], ["84028.90", "0"], ["84030.00", "0.112170"], ["84031.60", "0.536970"], ["84037.50", "0.240000"], ["84068.10", "4.808169"], ["84076.50", "5.171050"], ["84084.90", "3.991687"], ["84093.30", "4.354568"], ["84101.70", "4.173128"], ["84110.10", "5.261770"], ["84118.50", "4.082408"], ["84126.90", "5.533930"], ["84143.70", "5.443210"], ["84152.10", "4.898889"], ["84160.37", "0.171545"], ["84160.50", "5.624650"], ["84168.90", "4.717449"], ["84177.30", "4.989609"], ["84185.70", "5.080329"], ["84194.10", "3.900967"], ["84210.90", "5.352490"], ["84227.70", "4.263848"], ["84340.46", "0"], ["84340.72", "0"], ["84341.00", "0"]], "bids": [["83962.04", "0.047600"], ["83962.02", "0"], ["83954.00", "0.001012"], ["83953.32", "0"], ["83952.00", "0.001005"], ["83950.00", "0.001049"], ["83948.00", "0.001039"], ["83946.00", "0.001029"], ["83944.00", "0.002403"], ["83942.00", "0.006324"], ["83940.00", "0.002122"], ["83939.10", "0.221340"], ["83938.60", "0.995730"], ["83938.10", "0.073800"], ["83937.20", "0"], ["83937.10", "0.070050"], ["83936.60", "0.161130"], ["83936.10", "0.568230"], ["83929.40", "2.141970"], ["83920.11", "0"], ["83917.00", "0"], ["83900.00", "4.989609"], ["83891.60", "3.991687"], ["83883.20", "5.261770"], ["83874.80", "5.443210"], ["83858.00", "4.536008"], ["83849.60", "4.082408"], ["83841.20", "4.263848"], ["83832.80", "4.717449"], ["83824.40", "3.900967"], ["83816.00", "5.624650"], ["83807.60", "4.808169"], ["83799.20", "4.898889"], ["83782.40", "4.173128"], ["83774.00", "4.626729"], ["83765.60", "5.080329"], ["83757.20", "4.445288"], ["83748.80", "5.533930"], ["83740.40", "4.354568"], ["83437.50", "0.000009"], ["83437.10", "0.000095"]], "checksum": 1182525581, "ts": "1742577043661"}], "ts": 1742577043665, "record_time": 1742577043.858058, "EXCHANGE": "BITGET"}
{"action": "update", "arg": {"instType": "SPOT", "channel": "books", "instId": "BTCUSDT"}, "data": [{"asks": [["83970.01", "2.401557"], ["84005.12", "0.543013"], ["84006.03", "0"], ["84022.10", "2.541337"], ["84023.19", "0"], ["84024.10", "6.687727"], ["84026.10", "17.599283"], ["84027.10", "1.745730"], ["84076.50", "5.443210"], ["84084.90", "4.445288"], ["84093.30", "4.989609"], ["84101.70", "4.536008"], ["84110.10", "4.082408"], ["84118.50", "4.173128"], ["84135.30", "3.991687"], ["84143.70", "4.354568"], ["84152.10", "5.352490"], ["84160.50", "4.626729"], ["84168.90", "4.263848"], ["84177.30", "5.080329"], ["84185.70", "4.898889"], ["84194.10", "4.717449"], ["84202.50", "3.900967"], ["84210.90", "5.171050"], ["84219.30", "5.624650"], ["84227.70", "5.261770"], ["84340.46", "0.000143"]], "bids": [["83962.05", "0.577100"], ["83962.04", "0"], ["83962.03", "0"], ["83955.32", "0.038687"], ["83954.80", "0"], ["83940.10", "0.098850"], ["83938.10", "0.073620"], ["83936.60", "0.160920"], ["83928.60", "0"], ["83916.00", "0.000160"], ["83900.00", "3.900967"], ["83891.60", "4.717449"], ["83883.20", "4.263848"], ["83874.80", "4.445288"], ["83866.40", "5.533930"], ["83858.00", "4.082408"], ["83849.60", "4.173128"], ["83841.20", "4.626729"], ["83832.80", "5.261770"], ["83824.40", "5.352490"], ["83816.00", "4.354568"], ["83807.60", "5.171050"], ["83790.80", "4.808169"], ["83784.00", "0.001184"], ["83782.40", "3.991687"], ["83774.00", "5.443210"], ["83765.60", "5.624650"], ["83757.20", "4.536008"], ["83748.80", "4.989609"], ["83740.40", "5.080329"]], "checksum": -1422746073, "ts": "1742577043862"}], "ts": 1742577043867, "record_time": 1742577044.059768, "EXCHANGE": "BITGET"}
{"action": "update", "arg": {"instType": "SPOT", "channel": "books", "instId": "BTCUSDT"}, "data": [{"asks": [["84006.10", "0.001905"], ["84008.10", "0.003109"], ["84010.10", "0.008182"], ["84012.10", "0.021753"], ["84014.10", "0.057245"], ["84016.10", "0.150645"], ["84018.10", "0.396432"], ["84020.10", "1.043244"], ["84022.10", "2.745377"], ["84024.10", "7.224676"], ["84026.10", "19.012306"], ["84026.50", "0.001021"], ["84029.20", "5.739240"], ["84030.00", "2.470770"], ["84068.10", "4.445288"], ["84076.50", "5.533930"], ["84084.90", "5.624650"], ["84093.30", "4.536008"], ["84101.70", "5.080329"], ["84110.10", "4.354568"], ["84118.50", "4.263848"], ["84126.90", "4.626729"], ["84135.30", "5.261770"], ["84143.70", "4.082408"], ["84152.10", "4.989609"], ["84160.50", "5.352490"], ["84168.90", "5.443210"], ["84177.30", "4.808169"], ["84185.70", "5.171050"], ["84194.10", "4.898889"], ["84202.50", "4.173128"], ["84210.90", "3.991687"], ["84219.30", "4.717449"], ["84227.70", "3.900967"]], "bids": [["83962.06", "1.068500"], ["83962.05", "0.529500"], ["83956.00", "0.001497"], ["83954.00", "0.003940"], ["83952.00", "0.010368"], ["83950.00", "0.027286"], ["83948.00", "0.071805"], ["83946.00", "0.188960"], ["83944.00", "0.497262"], ["83942.00", "1.308584"], ["83939.90", "0.523980"], ["83938.60", "0.995550"], ["83938.10", "0.073410"], ["83937.10", "0.073050"], ["83915.00", "0.000160"], ["83900.00", "4.536008"], ["83891.60", "3.991687"], ["83883.20", "4.717449"], ["83874.80", "4.626729"], ["83866.40", "4.808169"], ["83858.00", "3.900967"], ["83849.60", "5.533930"], ["83841.20", "4.263848"], ["83832.80", "4.082408"], ["83824.40", "5.624650"], ["83816.00", "5.080329"], ["83807.60", "4.989609"], ["83790.80", "4.354568"], ["83782.40", "4.445288"], ["83774.00", "5.352490"], ["83765.60", "5.171050"], ["83757.20", "4.173128"], ["83748.80", "5.261770"], ["83740.40", "5.443210"], ["83439.33", "0"], ["83437.50", "0"], ["83437.10", "0"]], "checksum": 306459591, "ts": "1742577044076"}], "ts": 1742577044079, "record_time": 1742577044.272633, "EXCHANGE": "BITGET"}
{"action": "update", "arg": {"instType": "SPOT", "channel": "books", "instId": "BTCUSDT"}, "data": [{"asks": [["84006.10", "0.001802"], ["84008.10", "0.002940"], ["84010.10", "0.007736"], ["84012.10", "0.020360"], ["84014.10", "0.053578"], ["84016.10", "0.140994"], ["84018.10", "0.371037"], ["84020.10", "0.976413"], ["84022.10", "2.569508"], ["84024.10", "6.761864"], ["84026.10", "17.794378"], ["84030.00", "0.111990"], ["84030.30", "0"], ["84032.00", "1.392300"], ["84032.50", "0"], ["84033.30", "2.358510"], ["84033.50", "0.150000"], ["84035.20", "0.461400"], ["84036.00", "0.192300"], ["84068.10", "5.261770"], ["84076.50", "5.171050"], ["84084.90", "4.173128"], ["84093.30", "5.624650"], ["84101.70", "4.989609"], ["84110.10", "3.900967"], ["84118.50", "3.991687"], ["84126.90", "5.080329"], ["84135.30", "5.533930"], ["84152.10", "4.717449"], ["84160.50", "5.443210"], ["84168.90", "4.445288"], ["84177.30", "4.898889"], ["84185.70", "4.536008"], ["84194.10", "4.808169"], ["84202.50", "5.352490"], ["84210.90", "4.354568"], ["84219.30", "4.263848"], ["84227.70", "4.626729"], ["84340.72", "0.000066"]], "bids": [["83962.07", "1.068500"], ["83962.05", "0"], ["83961.60", "0.209200"], ["83956.00", "0.001009"], ["83955.32", "0"], ["83954.00", "0.001922"], ["83952.00", "0.005057"], ["83950.00", "0.013310"], ["83948.00", "0.035026"], ["83946.00", "0.092172"], ["83944.00", "0.242560"], ["83942.00", "0.638315"], ["83941.10", "0.475170"], ["83939.90", "0"], ["83939.80", "0.764370"], ["83939.10", "0.221160"], ["83938.60", "0"], ["83900.00", "4.354568"], ["83891.60", "4.989609"], ["83883.20", "4.808169"], ["83874.80", "5.080329"], ["83866.40", "4.717449"], ["83858.00", "5.352490"], ["83849.60", "4.263848"], ["83841.20", "5.261770"], ["83832.80", "4.173128"], ["83824.40", "4.082408"], ["83816.00", "5.443210"], ["83807.60", "5.171050"], ["83790.80", "4.536008"], ["83782.40", "5.533930"], ["83774.00", "3.900967"], ["83765.60", "4.445288"], ["83757.20", "4.626729"], ["83748.80", "3.991687"], ["83740.40", "5.624650"]], "checksum": -2091412350, "ts": "1742577044281"}], "ts": 1742577044283, "record_time": 1742577044.477006, "EXCHANGE": "BITGET"}
{"action": "update", "arg": {"instType": "SPOT", "channel": "books", "instId": "BTCUSDT"}, "data": [{"asks": [["84012.28", "0"], ["84026.10", "17.794508"], ["84027.80", "0.017220"], ["84029.20", "5.639250"], ["84068.10", "5.443210"], ["84076.50", "3.900967"], ["84084.90", "5.080329"], ["84093.30", "4.082408"], ["84101.70", "5.352490"], ["84110.10", "4.173128"], ["84118.50", "4.536008"], ["84126.90", "4.445288"], ["84143.70", "3.991687"], ["84152.10", "5.624650"], ["84160.50", "4.808169"], ["84168.90", "4.717449"], ["84185.70", "4.263848"], ["84194.10", "4.989609"], ["84202.50", "5.171050"], ["84219.30", "4.626729"], ["84227.70", "5.261770"], ["84341.00", "0.002997"]], "bids": [["83962.08", "1.068500"], ["83962.06", "0"], ["83961.60", "0"], ["83956.34", "0"], ["83955.87", "0.038686"], ["83954.00", "0.001027"], ["83952.00", "0.002589"], ["83950.00", "0.006814"], ["83948.00", "0.017930"], ["83946.00", "0.047184"], ["83944.00", "0.124171"], ["83942.00", "0.326765"], ["83941.70", "0.001012"], ["83941.30", "0"], ["83939.80", "0"], ["83938.10", "0.073620"], ["83934.00", "0"], ["83928.60", "0.045000"], ["83928.30", "0.480000"], ["83900.00", "5.533930"], ["83891.60", "5.443210"], ["83883.20", "4.898889"], ["83874.80", "4.173128"], ["83866.40", "5.171050"], ["83858.00", "4.536008"], ["83849.60", "5.624650"], ["83841.20", "5.080329"], ["83832.80", "4.626729"], ["83824.40", "3.900967"], ["83816.00", "4.808169"], ["83807.60", "4.354568"], ["83799.20", "4.082408"], ["83790.80", "5.352490"], ["83782.40", "5.261770"], ["83774.00", "4.717449"], ["83765.60", "4.263848"], ["83757.20", "3.991687"], ["83748.80", "4.445288"], ["83740.40", "4.989609"], ["83439.33", "0.000010"]], "checksum": -1420294840, "ts": "1742577044495"}], "ts": 1742577044501, "record_time": 1742577044.700187, "EXCHANGE": "BITGET"}
{"action": "update", "arg": {"instType": "SPOT", "channel": "books", "instId": "BTCUSDT"}, "data": [{"asks": [["84006.10", "0.002406"], ["84008.10", "0.003926"], ["84010.10", "0.010552"], ["84012.10", "0.027770"], ["84014.10", "0.073078"], ["84016.10", "0.192310"], ["84018.10", "0.506081"], ["84020.10", "1.331791"], ["84022.10", "3.504712"], ["84024.10", "9.222927"], ["84026.10", "24.270861"], ["84026.30", "0.006240"], ["84026.80", "0"], ["84027.00", "0"], ["84027.10", "0"], ["84027.80", "0.035910"], ["84028.30", "0.071820"], ["84028.80", "0.071610"], ["84029.20", "0"], ["84030.00", "0.112170"], ["84030.30", "0.072480"], ["84030.70", "0.178770"], ["84031.00", "0.959250"], ["84031.10", "0.405330"], ["84031.60", "0.715560"], ["84033.30", "0"], ["84033.80", "0.192000"], ["84036.50", "0"], ["84037.90", "0.323610"], ["84068.10", "3.900968"], ["84076.50", "5.624651"], ["84084.90", "3.991688"], ["84093.30", "5.080330"], ["84101.70", "4.626729"], ["84110.10", "5.443211"], ["84118.50", "4.536009"], ["84126.90", "4.898890"], ["84135.30", "5.533931"], ["84143.70", "5.261770"], ["84152.10", "4.082408"], ["84160.50", "5.352490"], ["84168.90", "4.989610"], ["84177.30", "4.173128"], ["84185.70", "5.171050"], ["84194.10", "4.354569"], ["84202.50", "4.717449"], ["84210.90", "4.808169"], ["84219.30", "4.445289"], ["84227.70", "4.263848"], ["84341.00", "0"]], "bids": [["83962.08", "0"], ["83962.07", "0"], ["83952.00", "0.001001"], ["83950.00", "0.001002"], ["83948.00", "0.001011"], ["83946.00", "0.001022"], ["83944.00", "0.001013"], ["83942.00", "0.002046"], ["83941.70", "0.008700"], ["83941.50", "0.001023"], ["83941.10", "0"], ["83940.10", "0"], ["83939.10", "0.221340"], ["83937.10", "0"], ["83936.60", "0.071340"], ["83936.40", "0.089490"], ["83936.10", "1.252080"], ["83935.60", "0.066360"], ["83933.90", "0.160920"], ["83932.20", "1.262850"], ["83931.10", "0.120000"], ["83929.20", "0"], ["83928.30", "0"], ["83917.00", "0.000121"], ["83916.00", "0"], ["83900.00", "4.808169"], ["83891.60", "5.171050"], ["83883.20", "5.443211"], ["83874.80", "5.533931"], ["83866.40", "4.626729"], ["83858.00", "4.082408"], ["83849.60", "5.624651"], ["83841.20", "4.354569"], ["83832.80", "4.898890"], ["83824.40", "4.536009"], ["83816.00", "4.173128"], ["83807.60", "4.989610"], ["83799.20", "5.080330"], ["83790.80", "3.991688"], ["83774.00", "5.352490"], ["83765.60", "3.900968"], ["83757.20", "4.717449"], ["83748.80", "4.263848"], ["83740.40", "4.445289"], ["83437.50", "0.000009"], ["83437.10", "0.000095"], ["83433.33", "0.000134"], ["83433.12", "0.000544"], ["83433.00", "0.000075"], ["83432.57", "0.000155"]], "checksum": 183973501, "ts": "1742577044711"}], "ts": 1742577044714, "record_time": 1742577044.907976, "EXCHANGE": "BITGET"}
{"action": "update", "arg": {"instType": "SPOT", "channel": "books", "instId": "BTCUSDT"}, "data": [{"asks": [["83962.01", "0.901476"], ["83970.01", "0.894192"], ["83970.21", "0"], ["83991.07", "0.120900"], ["84005.12", "0.231743"], ["84014.10", "0.073249"], ["84016.10", "0.192762"], ["84018.10", "0.507267"], ["84020.10", "1.334914"], ["84022.10", "3.512931"], ["84024.10", "9.244555"], ["84026.10", "24.327777"], ["84029.50", "0.276000"], ["84030.20", "0.204180"], ["84031.00", "0.959070"], ["84031.10", "0.609150"], ["84031.20", "0.228000"], ["84034.40", "0.180870"], ["84035.20", "0.257400"], ["84035.30", "0.420000"], ["84037.20", "0"], ["84037.50", "0"], ["84037.90", "0"], ["84063.20", "0"], ["84068.10", "4.263848"], ["84076.50", "4.354569"], ["84084.90", "5.624651"], ["84093.30", "4.626729"], ["84101.70", "4.536009"], ["84110.10", "4.082408"], ["84118.50", "4.717449"], ["84135.30", "4.989610"], ["84143.70", "3.991688"], ["84152.10", "5.443211"], ["84160.50", "5.533931"], ["84168.90", "4.445289"], ["84177.30", "5.261770"], ["84194.10", "3.900968"], ["84202.50", "4.808169"], ["84210.90", "4.173128"], ["84219.30", "5.080330"], ["84226.29", "0"], ["84227.70", "5.352490"]], "bids": [["83970.00", "0"], ["83962.00", "0.001036"], ["83956.34", "0.038690"], ["83955.87", "0"], ["83942.00", "0.002790"], ["83939.40", "0.100380"], ["83937.90", "0.784500"], ["83937.20", "0.390390"], ["83936.60", "0"], ["83936.40", "0.089280"], ["83936.10", "0.187860"], ["83932.20", "0"], ["83932.10", "0.012690"], ["83931.20", "1.007880"], ["83929.40", "0"], ["83928.30", "0.480000"], ["83900.00", "5.080330"], ["83891.60", "4.354569"], ["83883.20", "5.171050"], ["83874.80", "4.717449"], ["83866.40", "5.443211"], ["83858.00", "5.533931"], ["83849.60", "4.263848"], ["83841.20", "4.808169"], ["83832.80", "4.989610"], ["83824.40", "3.900968"], ["83816.00", "4.536009"], ["83807.60", "4.626729"], ["83799.20", "5.352490"], ["83790.80", "4.898890"], ["83774.00", "3.991688"], ["83765.60", "4.173128"], ["83757.20", "4.082408"], ["83748.80", "5.624651"]], "checksum": 1248023881, "ts": "1742577044917"}], "ts": 1742577044921, "record_time": 1742577045.123531, "EXCHANGE": "BITGET"}
{"action": "update", "arg": {"instType": "SPOT", "channel": "books", "instId": "BTCUSDT"}, "data": [{"asks": [["83962.01", "1.285942"], ["83970.00", "0.173567"], ["83970.01", "0.316827"], ["83971.98", "0"], ["83971.99", "0"], ["83972.00", "0"], ["83979.96", "0"], ["83993.66", "0.010000"], ["84001.04", "0"], ["84014.10", "0.073062"], ["84016.10", "0.192268"], ["84018.10", "0.505970"], ["84020.10", "1.331499"], ["84022.10", "3.503944"], ["84024.10", "9.220906"], ["84026.10", "24.265541"], ["84029.50", "0.276180"], ["84035.30", "0.516000"], ["84037.00", "0"], ["84068.10", "3.900968"], ["84076.50", "5.443211"], ["84084.90", "4.626729"], ["84093.30", "3.991688"], ["84101.70", "5.171050"], ["84110.10", "4.173128"], ["84118.50", "4.263848"], ["84135.30", "5.352490"], ["84143.70", "5.261770"], ["84152.10", "4.082408"], ["84160.50", "4.989610"], ["84168.90", "4.354569"], ["84177.30", "5.533931"], ["84185.70", "4.536009"], ["84194.10", "4.445289"], ["84210.90", "4.717449"], ["84227.70", "5.624651"], ["84341.00", "0.002997"], ["84341.01", "0.000008"], ["84342.11", "0.000051"], ["84342.63", "0.000009"]], "bids": [["83962.00", "0.028946"], ["83953.42", "0.037784"], ["83944.00", "0.001159"], ["83942.00", "0.003050"], ["83939.40", "0"], ["83936.40", "0.089490"], ["83933.20", "0.026190"], ["83883.20", "5.443211"], ["83879.20", "0.000971"], ["83874.80", "4.989610"], ["83866.40", "4.445289"], ["83849.60", "4.536009"], ["83841.20", "4.898890"], ["83832.80", "4.173128"], ["83824.40", "4.082408"], ["83816.00", "5.171050"], ["83807.60", "4.808169"], ["83799.20", "4.263848"], ["83790.80", "5.352490"], ["83782.40", "4.626729"], ["83774.00", "5.261770"], ["83765.60", "3.900968"], ["83757.20", "4.717449"], ["83748.80", "3.991688"], ["83740.40", "5.624651"], ["83433.00", "0"], ["83432.57", "0"]], "checksum": 1023864848, "ts": "1742577045121"}], "ts": 1742577045125, "record_time": 1742577045.321372, "EXCHANGE": "BITGET"}
{"action": "update", "arg": {"instType": "SPOT", "channel": "books", "instId": "BTCUSDT"}, "data": [{"asks": [["83970.00", "0"], ["83995.13", "0.062760"], ["83996.85", "0.094307"], ["84003.30", "0.001485"], ["84005.30", "0.002424"], ["84006.10", "0"], ["84007.30", "0.006378"], ["84008.10", "0"], ["84009.30", "0.016785"], ["84010.10", "0"], ["84010.64", "0.714195"], ["84011.30", "0.044169"], ["84012.10", "0"], ["84013.30", "0.116235"], ["84014.10", "0"], ["84015.30", "0.305882"], ["84016.10", "0"], ["84016.57", "0"], ["84017.30", "0.804952"], ["84018.10", "0"], ["84019.30", "2.118295"], ["84020.10", "0"], ["84021.30", "5.574461"], ["84022.10", "0"], ["84023.30", "14.669634"], ["84023.40", "16.941780"], ["84023.50", "0.001046"], ["84024.00", "0.042900"], ["84024.10", "0"], ["84025.00", "0.015660"], ["84025.20", "0.001041"], ["84026.00", "0.042690"], ["84026.10", "8.505690"], ["84026.20", "0"], ["84026.30", "0.006030"], ["84026.50", "0"], ["84026.70", "0"], ["84027.10", "0.069690"], ["84027.80", "0"], ["84028.00", "0.042480"], ["84028.30", "0.071610"], ["84029.20", "2.358630"], ["84029.50", "0.276000"], ["84030.00", "0.078000"], ["84030.20", "0.204000"], ["84030.30", "0.072300"], ["84030.70", "0.178590"], ["84031.00", "0.958440"], ["84032.40", "0"], ["84032.80", "0"], ["84033.90", "0.191100"], ["84034.40", "0.180000"], ["84035.30", "0.300000"], ["84035.50", "0"], ["84036.00", "0"], ["84036.10", "0"], ["84036.30", "0"], ["84037.10", "0"], ["84065.30", "4.536161"], ["84068.10", "0"], ["84073.70", "4.989777"], ["84076.50", "0"], ["84082.10", "4.717607"], ["84084.90", "0"], ["84090.50", "4.354714"], ["84093.30", "0"], ["84098.90", "5.171223"], ["84101.70", "0"], ["84107.30", "3.901098"], ["84110.10", "0"], ["84115.70", "5.443393"], ["84118.50", "0"], ["84124.10", "4.173268"], ["84126.90", "0"], ["84132.50", "4.263991"], ["84135.30", "0"], ["84140.90", "4.626884"], ["84143.70", "0"], ["84149.30", "4.082545"], ["84152.10", "0"], ["84157.70", "3.991821"], ["84160.50", "0"], ["84166.10", "4.808330"], ["84168.90", "0"], ["84174.50", "5.534116"], ["84177.30", "0"], ["84182.90", "4.445437"], ["84185.70", "0"], ["84191.30", "5.352670"], ["84194.10", "0"], ["84199.70", "5.624839"], ["84202.50", "0"], ["84208.10", "5.080500"], ["84210.90", "0"], ["84216.50", "4.899054"], ["84219.30", "0"], ["84224.90", "5.261946"], ["84227.70", "0"]], "bids": [["83962.00", "0.027910"], ["83960.00", "0"], ["83959.20", "0.001023"], ["83958.00", "0"], ["83957.47", "0"], ["83957.20", "0.001035"], ["83956.34", "0"], ["83956.22", "0"], ["83956.00", "0"], ["83955.20", "0.001005"], ["83954.00", "0"], ["83953.23", "0"], ["83953.20", "0.001344"], ["83952.00", "0"], ["83951.20", "0.003535"], ["83950.00", "0"], ["83949.20", "0.009304"], ["83948.00", "0"], ["83947.20", "0.024484"], ["83946.00", "0"], ["83945.20", "0.064430"], ["83944.00", "0"], ["83943.20", "0.169555"], ["83942.00", "0"], ["83941.91", "0.005394"], ["83941.90", "0"], ["83941.80", "0"], ["83941.70", "0"], ["83941.50", "0"], ["83941.20", "0.446196"], ["83940.89", "0"], ["83940.15", "0.801188"], ["83939.30", "0"], ["83939.24", "0"], ["83939.20", "1.174199"], ["83939.10", "0.224340"], ["83938.60", "0.484860"], ["83938.20", "0.001026"], ["83938.10", "0"], ["83937.90", "0"], ["83937.20", "0"], ["83936.40", "0.089670"], ["83936.10", "0"], ["83935.82", "0"], ["83935.79", "0"], ["83935.70", "0"], ["83935.69", "0"], ["83935.60", "0.118740"], ["83935.30", "0.073590"], ["83935.26", "0"], ["83934.20", "0.066360"], ["83933.96", "0"], ["83933.94", "0"], ["83933.93", "0"], ["83933.79", "0"], ["83933.78", "0"], ["83933.63", "0"], ["83933.49", "0"], ["83933.26", "0"], ["83933.20", "0"], ["83933.15", "0"], ["83933.08", "0"], ["83928.93", "0"], ["83928.91", "0"], ["83928.85", "0"], ["83928.66", "0"], ["83928.60", "0.057630"], ["83928.06", "0"], ["83927.90", "0.120000"], ["83927.80", "0.485160"], ["83927.72", "0.007197"], ["83927.70", "0.045000"], ["83927.60", "1.240020"], ["83927.00", "0.009000"], ["83926.70", "0.621180"], ["83926.60", "0"], ["83926.54", "0"], ["83925.80", "0.240000"], ["83917.00", "0.000281"], ["83914.00", "0.000160"], ["83913.00", "0.000160"], ["83912.99", "0"], ["83912.00", "0.000160"], ["83910.07", "0"], ["83905.43", "0"], ["83905.09", "0"], ["83900.00", "0"], ["83897.20", "4.899054"], ["83891.60", "0"], ["83888.80", "5.080500"], ["83883.20", "0"], ["83880.40", "4.263991"], ["83874.80", "0"], ["83872.00", "4.626884"], ["83866.40", "0"], ["83863.60", "5.534116"], ["83858.00", "0"], ["83855.20", "5.352670"], ["83849.60", "0"], ["83846.80", "5.624839"], ["83841.20", "0"], ["83838.40", "5.171223"], ["83832.80", "0"], ["83830.00", "4.445437"], ["83824.40", "0"], ["83821.60", "4.717607"], ["83816.00", "0"], ["83813.20", "5.443393"], ["83807.60", "0"], ["83804.80", "4.989777"], ["83799.20", "0"], ["83796.40", "5.261946"], ["83790.80", "0"], ["83788.00", "4.536161"], ["83782.40", "0"], ["83779.60", "3.901098"], ["83774.00", "0"], ["83771.20", "3.991821"], ["83765.60", "0"], ["83762.80", "4.808330"], ["83757.20", "0"], ["83754.40", "4.173268"], ["83748.80", "0"], ["83746.00", "4.354714"], ["83740.40", "0"], ["83737.60", "4.082545"], ["83433.00", "0.000075"], ["83432.57", "0.000155"], ["83431.37", "0.000008"], ["83430.00", "0.002012"], ["83429.00", "0.000008"], ["83428.57", "0.000212"], ["83427.23", "0.000099"], ["83425.93", "0.000011"], ["83425.00", "0.006969"], ["83423.73", "0.001213"], ["83423.42", "0.000061"], ["83421.99", "0.000188"], ["83421.05", "0.000260"], ["83420.00", "0.018057"], ["83419.12", "0.000041"], ["83417.42", "0.000176"], ["83417.32", "0.000018"], ["83417.31", "0.000314"], ["83416.00", "0.000022"], ["83415.96", "0.000146"], ["83415.38", "0.000015"], ["83415.25", "0.000013"], ["83414.20", "0.003950"], ["83413.40", "0.000013"], ["83412.50", "0.000076"]], "checksum": 1476131970, "ts": "1742577045326"}], "ts": 1742577045329, "record_time": 1742577045.523235, "EXCHANGE": "BITGET"}
{"action": "update", "arg": {"instType": "SPOT", "channel": "books", "instId": "BTCUSDT"}, "data": [{"asks": [["83962.01", "1.421824"], ["83993.66", "0"], ["84001.07", "0.054704"], ["84005.30", "0.002571"], ["84007.30", "0.006765"], ["84009.30", "0.017693"], ["84011.30", "0.046561"], ["84013.30", "0.122643"], ["84015.30", "0.322745"], ["84017.30", "0.849329"], ["84019.30", "2.235075"], ["84021.30", "5.881778"], ["84023.30", "15.478362"], ["84023.40", "9.197670"], ["84024.00", "0.042690"], ["84025.00", "0"], ["84025.20", "0"], ["84026.10", "5.894610"], ["84028.00", "0.042300"], ["84028.30", "0"], ["84028.80", "0"], ["84029.20", "0"], ["84030.30", "0"], ["84031.00", "1.657020"], ["84031.10", "2.967720"], ["84034.00", "0.993780"], ["84034.80", "0.012570"], ["84035.30", "0"], ["84065.30", "5.171223"], ["84073.70", "5.261946"], ["84082.10", "4.445437"], ["84090.50", "5.443393"], ["84098.90", "4.717607"], ["84107.30", "4.899054"], ["84115.70", "4.536161"], ["84124.10", "4.082545"], ["84132.50", "4.173268"], ["84140.90", "4.354714"], ["84149.30", "4.626884"], ["84157.70", "5.080500"], ["84166.10", "5.534116"], ["84174.50", "5.624839"], ["84182.90", "3.901098"], ["84191.30", "4.808330"], ["84199.70", "4.263991"], ["84208.10", "4.989777"], ["84216.50", "3.991821"], ["84224.90", "5.352670"], ["84342.70", "0.000423"], ["84343.02", "0.000338"], ["84343.07", "0.000014"], ["84343.70", "0.000075"], ["84343.97", "0.000188"], ["84344.77", "0.000361"]], "bids": [["83962.00", "0.075510"], ["83953.72", "0.038691"], ["83951.20", "0.003730"], ["83950.84", "0.007593"], ["83949.67", "0.006539"], ["83949.20", "0.009816"], ["83947.20", "0.025832"], ["83946.60", "0.009897"], ["83945.20", "0.067977"], ["83943.20", "0.178992"], ["83941.91", "0.135046"], ["83941.20", "0.471033"], ["83939.20", "1.239560"], ["83936.60", "0.071280"], ["83935.60", "0.118530"], ["83935.30", "0.073410"], ["83935.00", "0.015000"], ["83934.57", "0.008274"], ["83932.87", "0.008069"], ["83931.20", "1.359030"], ["83930.80", "2.215470"], ["83929.54", "0.007383"], ["83929.52", "0.007775"], ["83929.49", "0.009559"], ["83929.48", "0.006973"], ["83929.46", "0.009798"], ["83927.69", "0.008024"], ["83927.63", "0.008477"], ["83927.62", "0.008601"], ["83927.59", "0.016369"], ["83927.53", "0.009417"], ["83927.51", "0.008525"], ["83926.70", "0"], ["83925.80", "0"], ["83922.39", "0.005177"], ["83922.35", "0.008102"], ["83922.34", "0.008551"], ["83922.32", "0.005058"], ["83922.31", "0.004857"], ["83920.51", "0.010355"], ["83920.45", "0.008773"], ["83918.00", "0.209200"], ["83906.67", "0.007443"], ["83903.76", "0.008582"], ["83899.12", "0.007257"], ["83898.93", "0.007345"], ["83888.80", "4.808330"], ["83880.40", "5.534116"], ["83872.00", "4.445437"], ["83863.60", "5.352670"], ["83855.20", "5.080500"], ["83846.80", "3.991821"], ["83830.00", "4.354714"], ["83813.20", "4.263991"], ["83804.80", "5.443393"], ["83796.40", "4.989777"], ["83788.00", "5.261946"], ["83779.60", "4.173268"], ["83771.20", "4.082545"], ["83762.80", "4.536161"], ["83754.40", "4.626884"], ["83746.00", "5.624839"], ["83737.60", "3.901098"], ["83437.10", "0"], ["83433.33", "0"], ["83433.12", "0"], ["83433.00", "0"], ["83432.57", "0"], ["83431.37", "0"], ["83430.00", "0"], ["83429.00", "0"], ["83428.57", "0"], ["83427.23", "0"], ["83425.93", "0"], ["83425.00", "0"], ["83423.73", "0"], ["83423.42", "0"], ["83421.99", "0"], ["83421.05", "0"], ["83420.00", "0"], ["83419.12", "0"], ["83417.42", "0"], ["83417.32", "0"], ["83417.31", "0"], ["83416.00", "0"], ["83415.96", "0"], ["83415.38", "0"], ["83415.25", "0"], ["83414.20", "0"], ["83413.40", "0"], ["83412.50", "0"]], "checksum": -575022216, "ts": "1742577045529"}], "ts": 1742577045531, "record_time": 1742577045.724939, "EXCHANGE": "BITGET"}
{"action": "update", "arg": {"instType": "SPOT", "channel": "books", "instId": "BTCUSDT"}, "data": [{"asks": [["83991.06", "0.036270"], ["84003.30", "0.001685"], ["84005.30", "0.002749"], ["84007.30", "0.007235"], ["84009.30", "0.019039"], ["84011.30", "0.050102"], ["84013.30", "0.131849"], ["84015.30", "0.346969"], ["84017.30", "0.913078"], ["84019.30", "2.402835"], ["84021.30", "6.323252"], ["84023.30", "16.640137"], ["84023.40", "1.771980"], ["84023.50", "0"], ["84027.10", "0.675030"], ["84030.00", "0.057240"], ["84030.70", "0"], ["84031.00", "0.958440"], ["84031.10", "0.609150"], ["84031.60", "0.536970"], ["84032.50", "2.358540"], ["84033.50", "0"], ["84034.00", "1.234950"], ["84035.20", "0.107400"], ["84035.30", "0.144000"], ["84065.30", "4.354714"], ["84073.70", "5.624839"], ["84082.10", "4.808330"], ["84090.50", "3.901098"], ["84098.90", "4.445437"], ["84107.30", "5.261946"], ["84115.70", "4.626884"], ["84124.10", "4.717607"], ["84132.50", "4.989777"], ["84140.90", "4.173268"], ["84149.30", "5.443393"], ["84166.10", "4.899054"], ["84174.50", "4.536161"], ["84182.90", "5.171223"], ["84191.30", "4.263991"], ["84199.70", "3.991821"], ["84208.10", "5.352670"], ["84216.50", "4.082545"], ["84224.90", "5.534116"], ["84317.17", "1.585636"], ["84320.01", "0"]], "bids": [["83962.00", "0.292610"], ["83955.20", "0.001168"], ["83953.20", "0.003073"], ["83951.20", "0.008088"], ["83949.20", "0.021283"], ["83947.20", "0.056010"], ["83945.20", "0.147394"], ["83943.20", "0.387878"], ["83941.20", "1.020732"], ["83939.20", "2.686138"], ["83938.40", "0.350460"], ["83938.20", "0"], ["83936.40", "0.089460"], ["83935.60", "0.639120"], ["83934.20", "0"], ["83931.21", "1.051824"], ["83931.20", "4.202460"], ["83912.13", "0.024948"], ["83888.80", "4.445437"], ["83880.40", "4.354714"], ["83872.00", "4.808330"], ["83863.60", "4.263991"], ["83855.20", "4.626884"], ["83846.80", "4.536161"], ["83838.40", "3.901098"], ["83830.00", "4.082545"], ["83821.60", "3.991821"], ["83813.20", "5.261946"], ["83804.80", "5.534116"], ["83796.40", "4.173268"], ["83788.00", "4.717607"], ["83779.60", "5.171223"], ["83771.20", "4.989777"], ["83762.80", "5.352670"], ["83754.40", "5.080500"], ["83737.60", "5.443393"], ["83648.13", "0"], ["83645.32", "1.732363"], ["83437.50", "0"]], "checksum": -344058276, "ts": "1742577045739"}], "ts": 1742577045742, "record_time": 1742577045.936583, "EXCHANGE": "BITGET"}
{"action": "update", "arg": {"instType": "SPOT", "channel": "books", "instId": "BTCUSDT"}, "data": [{"asks": [["83962.01", "1.386324"], ["84005.12", "0.299336"], ["84011.30", "0.050312"], ["84013.30", "0.132399"], ["84015.30", "0.348419"], ["84017.30", "0.916891"], ["84019.30", "2.412873"], ["84021.30", "6.349665"], ["84023.30", "16.709645"], ["84026.10", "5.579760"], ["84027.10", "0.069690"], ["84030.00", "0.078000"], ["84030.10", "0.100290"], ["84031.00", "1.558440"], ["84034.00", "0.736380"], ["84035.30", "0.300000"], ["84065.30", "5.352670"], ["84073.70", "4.082545"], ["84082.10", "5.624839"], ["84085.76", "0"], ["84090.50", "4.173268"], ["84098.51", "0"], ["84107.30", "5.080500"], ["84115.70", "4.263991"], ["84124.10", "3.991821"], ["84132.50", "4.626884"], ["84140.90", "4.354714"], ["84149.30", "5.171223"], ["84157.70", "5.261946"], ["84166.10", "4.536161"], ["84174.50", "3.901098"], ["84182.90", "4.899054"], ["84191.30", "4.989777"], ["84199.70", "4.717607"], ["84208.10", "4.808330"], ["84216.50", "5.443393"], ["84345.00", "0.000806"]], "bids": [["83954.04", "0.038691"], ["83953.72", "0"], ["83945.20", "0.147211"], ["83943.20", "0.387398"], ["83941.91", "0.291201"], ["83941.20", "1.019467"], ["83939.20", "2.682808"], ["83936.60", "0.232200"], ["83933.90", "0"], ["83932.49", "0.004034"], ["83931.21", "0.870764"], ["83927.00", "0"], ["83923.92", "0"], ["83899.04", "0"], ["83897.20", "5.534116"], ["83890.65", "0"], ["83888.80", "5.352670"], ["83880.40", "5.624839"], ["83872.00", "4.354714"], ["83863.60", "5.080500"], ["83855.20", "4.173268"], ["83846.80", "4.808330"], ["83838.40", "5.171223"], ["83830.00", "4.263991"], ["83821.60", "4.445437"], ["83804.80", "4.536161"], ["83796.40", "4.082545"], ["83788.00", "5.443393"], ["83779.60", "4.626884"], ["83771.20", "4.717607"], ["83762.80", "3.901098"], ["83754.40", "4.989777"], ["83746.00", "4.899054"], ["83737.60", "3.991821"], ["83437.50", "0.000009"], ["83437.10", "0.000095"], ["83433.33", "0.000134"], ["83433.12", "0.000544"]], "checksum": 465451429, "ts": "1742577045942"}], "ts": 1742577045944, "record_time": 1742577046.138746, "EXCHANGE": "BITGET"}
{"action": "update", "arg": {"instType": "SPOT", "channel": "books", "instId": "BTCUSDT"}, "data": [{"asks": [["84007.30", "0.007400"], ["84009.30", "0.019472"], ["84011.30", "0.051243"], ["84013.30", "0.134849"], ["84015.30", "0.354868"], ["84017.30", "0.933861"], ["84019.30", "2.457366"], ["84021.30", "6.466754"], ["84023.30", "17.017772"], ["84026.10", "5.894610"], ["84065.30", "4.173268"], ["84073.70", "5.534116"], ["84082.10", "4.899054"], ["84090.50", "4.989777"], ["84098.90", "5.261946"], ["84107.30", "5.624839"], ["84115.70", "5.080500"], ["84124.10", "3.901098"], ["84132.50", "4.717607"], ["84140.90", "4.808330"], ["84149.30", "4.626884"], ["84157.70", "4.082545"], ["84166.10", "5.352670"], ["84174.50", "4.445437"], ["84182.90", "4.536161"], ["84191.30", "5.443393"], ["84199.70", "3.991821"], ["84208.10", "5.171223"], ["84216.50", "4.263991"], ["84224.90", "4.354714"]], "bids": [["83954.05", "0.011607"], ["83943.20", "0.387295"], ["83941.20", "1.019199"], ["83939.20", "2.682101"], ["83937.50", "0.361830"], ["83936.60", "0.231990"], ["83935.60", "0.638940"], ["83931.20", "1.656360"], ["83930.80", "0.865470"], ["83916.00", "0.000121"], ["83915.00", "0.000281"], ["83914.00", "0.000281"], ["83913.00", "0.000281"], ["83912.00", "0.000281"], ["83897.20", "5.443393"], ["83888.80", "4.445437"], ["83880.40", "5.080500"], ["83872.00", "4.717607"], ["83863.60", "3.991821"], ["83855.20", "4.263991"], ["83846.80", "4.899054"], ["83838.40", "3.901098"], ["83830.00", "5.352670"], ["83821.60", "5.171223"], ["83813.20", "4.354714"], ["83804.80", "4.808330"], ["83796.40", "4.173268"], ["83788.00", "5.261946"], ["83779.60", "4.536161"], ["83771.20", "5.624839"], ["83762.80", "4.989777"], ["83754.40", "4.626884"], ["83746.00", "4.082545"], ["83737.60", "5.534116"], ["83433.33", "0"], ["83433.12", "0"]], "checksum": -228319381, "ts": "1742577046149"}], "ts": 1742577046153, "record_time": 1742577046.34697, "EXCHANGE": "BITGET"}
{"action": "update", "arg": {"instType": "SPOT", "channel": "books", "instId": "BTCUSDT"}, "data": [{"asks": [["83962.01", "1.398124"], ["83970.00", "0.095048"], ["84015.79", "0"], ["84028.20", "0.022710"], ["84030.60", "0"], ["84059.90", "0.001810"], ["84065.30", "4.263991"], ["84068.30", "0.003620"], ["84073.70", "4.445437"], ["84082.10", "5.080500"], ["84090.50", "5.443393"], ["84098.90", "4.808330"], ["84107.30", "4.899054"], ["84115.70", "4.626884"], ["84124.10", "5.534116"], ["84132.50", "4.354714"], ["84140.90", "5.624839"], ["84149.30", "3.991821"], ["84157.70", "4.173268"], ["84166.10", "4.082545"], ["84174.50", "5.352670"], ["84182.90", "5.171223"], ["84191.30", "4.536161"], ["84199.70", "3.901098"], ["84208.10", "4.989777"], ["84216.50", "5.261946"], ["84224.90", "4.717607"], ["84344.77", "0"], ["84345.00", "0"]], "bids": [["83962.00", "0.340210"], ["83943.21", "0.470657"], ["83941.91", "0"], ["83941.20", "1.019064"], ["83939.20", "2.681748"], ["83931.21", "0"], ["83931.20", "1.013760"], ["83916.00", "0.000281"], ["83912.13", "0"], ["83910.00", "0.002160"], ["83897.20", "4.445437"], ["83888.80", "4.808330"], ["83880.40", "5.534116"], ["83874.87", "0.001810"], ["83872.00", "5.171223"], ["83866.48", "0.003620"], ["83863.60", "4.082545"], ["83855.20", "4.173268"], ["83846.80", "3.901098"], ["83838.40", "4.717607"], ["83830.00", "4.354714"], ["83821.60", "5.624839"], ["83813.20", "5.443393"], ["83804.80", "4.626884"], ["83796.40", "5.352670"], ["83788.00", "3.991821"], ["83771.20", "4.263991"], ["83762.80", "5.080500"], ["83754.40", "4.899054"], ["83746.00", "4.989777"], ["83737.60", "5.261946"], ["83570.00", "0.000138"]], "checksum": -909211586, "ts": "1742577046358"}], "ts": 1742577046362, "record_time": 1742577046.555817, "EXCHANGE": "BITGET"}
{"action": "update", "arg": {"instType": "SPOT", "channel": "books", "instId": "BTCUSDT"}, "data": [{"asks": [["84011.50", "0.001598"], ["84019.65", "0"], ["84065.30", "5.080500"], ["84073.70", "5.352670"], ["84082.10", "4.626884"], ["84090.50", "4.445437"], ["84098.90", "5.171223"], ["84107.30", "4.173268"], ["84115.70", "5.534116"], ["84122.15", "0"], ["84124.10", "4.989777"], ["84132.50", "4.899054"], ["84140.90", "4.808330"], ["84149.30", "5.443393"], ["84157.70", "4.082545"], ["84166.10", "3.901098"], ["84174.50", "5.624839"], ["84182.90", "5.261946"], ["84191.30", "3.991821"], ["84199.70", "4.717607"], ["84208.10", "4.536161"], ["84216.50", "4.263991"], ["84224.90", "4.354714"], ["84344.77", "0.000361"]], "bids": [["83962.00", "0.549410"], ["83954.31", "0.038691"], ["83954.04", "0"], ["83940.15", "1.423506"], ["83931.20", "1.359150"], ["83930.80", "2.215470"], ["83905.62", "0"], ["83897.49", "0.001173"], ["83897.20", "4.626884"], ["83888.80", "5.171223"], ["83880.40", "3.901098"], ["83872.00", "4.717607"], ["83863.60", "5.352670"], ["83855.20", "4.808330"], ["83846.80", "4.173268"], ["83838.40", "4.989777"], ["83830.00", "5.080500"], ["83821.60", "5.534116"], ["83813.20", "5.261946"], ["83804.80", "4.263991"], ["83796.40", "5.443393"], ["83788.00", "4.354714"], ["83779.60", "4.899054"], ["83771.20", "4.536161"], ["83762.80", "4.445437"], ["83754.40", "4.082545"], ["83746.00", "3.991821"], ["83737.60", "5.624839"]], "checksum": -2089350528, "ts": "1742577046558"}], "ts": 1742577046563, "record_time": 1742577046.756224, "EXCHANGE": "BITGET"}
{"action": "update", "arg": {"instType": "SPOT", "channel": "books", "instId": "BTCUSDT"}, "data": [{"asks": [["84003.30", "0.001554"], ["84005.30", "0.002598"], ["84007.30", "0.006672"], ["84009.30", "0.017560"], ["84011.30", "0.046210"], ["84013.30", "0.121605"], ["84015.30", "0.320012"], ["84017.30", "0.842139"], ["84019.30", "2.216153"], ["84021.30", "5.831984"], ["84023.30", "15.347325"], ["84028.60", "0.493230"], ["84028.80", "0.605340"], ["84030.00", "0.049470"], ["84031.00", "0.958440"], ["84032.50", "0"], ["84034.00", "1.236630"], ["84034.40", "2.538480"], ["84035.20", "0"], ["84035.30", "0"], ["84065.30", "4.082545"], ["84082.10", "4.808330"], ["84090.50", "5.443393"], ["84092.03", "0.125751"], ["84098.90", "4.173268"], ["84107.30", "4.263991"], ["84115.70", "4.626884"], ["84124.10", "4.717607"], ["84140.90", "4.445437"], ["84149.30", "5.080500"], ["84157.70", "4.989777"], ["84166.10", "4.536161"], ["84182.90", "3.901098"], ["84191.30", "5.171223"], ["84199.70", "4.354714"], ["84208.10", "5.261946"], ["84216.50", "5.534116"], ["84224.90", "3.991821"]], "bids": [["83962.00", "0.758610"], ["83959.46", "0.076416"], ["83954.05", "0"], ["83943.20", "0.387502"], ["83941.20", "1.019743"], ["83939.20", "2.683534"], ["83936.44", "0.082288"], ["83932.80", "0.026490"], ["83911.70", "0.024948"], ["83897.20", "4.263991"], ["83888.80", "4.354714"], ["83880.40", "5.352670"], ["83872.00", "3.991821"], ["83863.60", "3.901098"], ["83855.20", "5.261946"], ["83846.80", "4.989777"], ["83838.40", "4.536161"], ["83821.60", "5.624839"], ["83813.20", "4.445437"], ["83804.80", "4.173268"], ["83796.40", "4.899054"], ["83788.00", "4.717607"], ["83779.60", "4.082545"], ["83771.20", "5.171223"], ["83762.80", "4.808330"], ["83754.40", "5.534116"], ["83746.00", "5.443393"], ["83737.60", "4.626884"], ["83439.33", "0"], ["83437.50", "0"], ["83437.10", "0"]], "checksum": 535760259, "ts": "1742577046777"}], "ts": 1742577046781, "record_time": 1742577046.974717, "EXCHANGE": "BITGET"}
{"action": "update", "arg": {"instType": "SPOT", "channel": "books", "instId": "BTCUSDT"}, "data": [{"asks": [["84003.30", "0.001119"], ["84005.30", "0.001826"], ["84007.30", "0.004805"], ["84009.30", "0.012645"], ["84010.14", "0.001598"], ["84011.30", "0.033276"], ["84013.30", "0.087569"], ["84013.62", "0"], ["84015.30", "0.230445"], ["84017.30", "0.606433"], ["84019.30", "1.595878"], ["84021.30", "4.199679"], ["84023.30", "11.051785"], ["84023.40", "1.232160"], ["84030.00", "0.042300"], ["84030.10", "0"], ["84035.30", "0.144000"], ["84073.70", "5.080500"], ["84082.10", "4.989777"], ["84090.50", "4.899054"], ["84098.90", "4.717607"], ["84107.30", "5.352670"], ["84115.70", "3.901098"], ["84124.10", "4.536161"], ["84132.50", "3.991821"], ["84140.90", "4.263991"], ["84149.30", "4.445437"], ["84157.70", "4.354714"], ["84166.10", "5.261946"], ["84182.90", "4.626884"], ["84199.70", "5.534116"], ["84208.10", "5.443393"], ["84216.50", "4.808330"], ["84224.90", "4.173268"]], "bids": [["83955.20", "0.001425"], ["83954.61", "0.038691"], ["83954.32", "0.011607"], ["83954.31", "0"], ["83953.20", "0.003750"], ["83951.20", "0.009869"], ["83949.20", "0.025971"], ["83947.20", "0.068343"], ["83945.20", "0.179850"], ["83943.20", "0.473291"], ["83941.20", "1.245502"], ["83939.20", "3.277636"], ["83938.70", "0.371400"], ["83938.40", "0.349830"], ["83936.40", "0.089280"], ["83935.60", "0.404910"], ["83934.00", "0.042300"], ["83931.20", "4.202460"], ["83927.60", "0.006594"], ["83912.00", "0.000121"], ["83903.47", "0"], ["83899.99", "0.001177"], ["83897.20", "4.173268"], ["83888.80", "4.717607"], ["83880.40", "5.171223"], ["83872.00", "5.261946"], ["83863.60", "5.624839"], ["83855.20", "4.445437"], ["83846.80", "4.082545"], ["83838.40", "3.991821"], ["83830.00", "4.536161"], ["83821.60", "4.263991"], ["83813.20", "4.626884"], ["83804.80", "3.901098"], ["83796.40", "5.352670"], ["83788.00", "4.899054"], ["83779.60", "5.443393"], ["83771.20", "4.354714"], ["83762.80", "5.534116"], ["83754.40", "5.080500"], ["83746.00", "4.989777"], ["83737.60", "4.808330"], ["83441.56", "0"], ["83440.00", "0"], ["83439.42", "0"]], "checksum": -264208044, "ts": "1742577046977"}], "ts": 1742577046981, "record_time": 1742577047.173516, "EXCHANGE": "BITGET"}
{"action": "update", "arg": {"instType": "SPOT", "channel": "books", "instId": "BTCUSDT"}, "data": [{"asks": [["84001.08", "0"], ["84005.30", "0.001972"], ["84007.30", "0.005190"], ["84009.30", "0.013659"], ["84011.30", "0.035945"], ["84013.30", "0.094453"], ["84015.30", "0.248560"], ["84017.30", "0.654106"], ["84019.30", "1.721331"], ["84021.30", "4.529817"], ["84023.30", "11.920573"], ["84065.30", "4.536161"], ["84073.70", "5.534116"], ["84082.10", "5.261946"], ["84090.50", "3.991821"], ["84098.90", "3.901098"], ["84107.30", "5.171223"], ["84115.70", "4.808330"], ["84124.10", "4.082545"], ["84132.50", "4.899054"], ["84149.30", "5.352670"], ["84157.70", "4.626884"], ["84166.10", "4.354714"], ["84174.50", "4.717607"], ["84182.90", "5.080500"], ["84191.30", "4.445437"], ["84199.70", "5.624839"], ["84216.50", "4.989777"], ["84345.00", "0.000806"]], "bids": [["83955.20", "0.001998"], ["83954.62", "0.011607"], ["83954.32", "0"], ["83953.20", "0.005257"], ["83951.20", "0.013835"], ["83949.20", "0.036406"], ["83947.20", "0.095806"], ["83945.20", "0.252121"], ["83943.20", "0.663478"], ["83941.20", "1.745782"], ["83939.20", "4.594163"], ["83939.10", "0.632520"], ["83938.70", "0.254130"], ["83938.60", "0.484020"], ["83938.40", "0"], ["83937.50", "0.361620"], ["83927.70", "0.015196"], ["83913.09", "0.024669"], ["83897.20", "5.080500"], ["83888.80", "4.263991"], ["83880.40", "4.354714"], ["83872.00", "4.717607"], ["83863.60", "4.989777"], ["83855.20", "4.899054"], ["83846.80", "5.352670"], ["83830.00", "5.171223"], ["83821.60", "5.261946"], ["83813.20", "4.082545"], ["83796.40", "4.808330"], ["83788.00", "4.173268"], ["83779.60", "4.536161"], ["83771.20", "5.624839"], ["83762.80", "5.443393"], ["83754.40", "4.626884"], ["83746.00", "5.534116"], ["83737.60", "4.445437"]], "checksum": -133560907, "ts": "1742577047183"}], "ts": 1742577047187, "record_time": 1742577047.381317, "EXCHANGE": "BITGET"}
{"action": "update", "arg": {"instType": "SPOT", "channel": "books", "instId": "BTCUSDT"}, "data": [{"asks": [["83962.01", "0.685182"], ["83970.01", "0.231401"], ["83973.26", "0"], ["83973.65", "0"], ["83975.83", "0"], ["83976.09", "0"], ["83976.48", "0"], ["83976.63", "0"], ["83976.76", "0"], ["83977.07", "0"], ["83977.24", "0"], ["83977.26", "0"], ["83977.54", "0"], ["83977.74", "0"], ["83977.84", "0"], ["83978.10", "0"], ["83978.34", "0"], ["83978.72", "0"], ["83979.29", "0"], ["83979.66", "0"], ["83980.20", "0"], ["83980.32", "0.119905"], ["83981.18", "0"], ["83981.28", "0.046965"], ["83981.46", "0"], ["83981.94", "0.006357"], ["83982.60", "0"], ["83982.67", "0.006357"], ["83983.12", "0.006357"], ["83983.64", "0"], ["83983.72", "0"], ["83983.76", "0.010995"], ["83983.84", "0.006357"], ["83983.87", "0.006356"], ["83984.29", "0.006357"], ["83984.61", "0"], ["83984.79", "0.006357"], ["83985.14", "0.006357"], ["83985.69", "0.006357"], ["83985.95", "0.017472"], ["83986.00", "0"], ["83986.59", "0.006357"], ["83987.22", "0.006357"], ["83987.96", "0.009990"], ["83992.46", "0.006356"], ["83993.35", "0.010988"], ["83999.55", "0.176996"], ["84001.07", "0"], ["84003.30", "0.001045"], ["84005.30", "0.001000"], ["84007.30", "0.001035"], ["84009.30", "0.002213"], ["84009.87", "0.010000"], ["84011.30", "0.005822"], ["84013.30", "0.015322"], ["84015.30", "0.040321"], ["84017.30", "0.106107"], ["84019.30", "0.279231"], ["84021.30", "0.734818"], ["84023.30", "1.933730"], ["84023.40", "0.390570"], ["84026.10", "3.000000"], ["84028.00", "0.186270"], ["84028.60", "0.583230"], ["84029.00", "0.059910"], ["84031.00", "0.404580"], ["84031.60", "0"], ["84032.00", "0.042300"], ["84034.00", "0.369690"], ["84034.40", "0.180000"], ["84034.50", "1.072110"], ["84035.30", "0.300000"], ["84065.30", "4.989777"], ["84073.70", "4.899054"], ["84082.10", "5.352670"], ["84098.90", "4.263991"], ["84107.30", "4.536161"], ["84115.70", "5.624839"], ["84124.10", "4.354714"], ["84132.50", "5.080500"], ["84140.90", "3.901098"], ["84149.30", "5.443393"], ["84157.70", "5.171223"], ["84166.10", "5.534116"], ["84174.50", "4.808330"], ["84182.90", "4.626884"], ["84191.30", "4.082545"], ["84199.70", "4.445437"], ["84208.10", "4.173268"], ["84216.50", "5.261946"], ["84224.90", "4.717607"], ["84345.79", "0.000034"], ["84346.43", "0.000128"], ["84346.94", "0.000085"], ["84346.97", "0.000030"], ["84347.55", "0.000095"], ["84347.69", "0.000009"], ["84347.83", "0.016818"], ["84348.21", "0.000036"]], "bids": [["83962.00", "0.782210"], ["83955.20", "0.002568"], ["83953.41", "0"], ["83953.20", "0.006552"], ["83951.20", "0.017242"], ["83949.20", "0.045373"], ["83949.18", "0"], ["83947.20", "0.119403"], ["83945.20", "0.314219"], ["83943.21", "0.665808"], ["83943.20", "0.826892"], ["83941.20", "2.176032"], ["83940.15", "0.801188"], ["83939.48", "0.089626"], ["83939.20", "5.726401"], ["83939.18", "0.247414"], ["83939.10", "1.147920"], ["83938.70", "0"], ["83938.60", "0.483840"], ["83937.62", "0.083593"], ["83937.50", "0.204856"], ["83937.17", "0.005946"], ["83936.60", "0.087674"], ["83936.50", "0.485340"], ["83936.40", "0.089460"], ["83936.07", "0.055608"], ["83936.00", "0.269760"], ["83935.68", "0.017115"], ["83935.50", "0.357150"], ["83935.31", "0.007137"], ["83935.30", "0.091260"], ["83934.76", "0.007343"], ["83934.59", "0.007951"], ["83934.25", "0.009005"], ["83934.14", "0.017367"], ["83933.03", "0.008285"], ["83933.00", "0.178590"], ["83932.96", "0"], ["83932.64", "0.012668"], ["83932.52", "0"], ["83932.18", "0"], ["83931.70", "0.018539"], ["83931.59", "0"], ["83931.13", "0"], ["83930.56", "0"], ["83930.50", "0.017850"], ["83929.92", "0"], ["83929.85", "0"], ["83929.30", "0.071430"], ["83929.24", "0"], ["83929.07", "0"], ["83928.75", "0"], ["83928.72", "0"], ["83928.40", "0.071430"], ["83928.31", "0.008195"], ["83928.30", "0"], ["83928.27", "0.024948"], ["83928.23", "0"], ["83928.21", "0"], ["83928.11", "0"], ["83927.90", "0"], ["83927.80", "0"], ["83927.50", "0"], ["83926.63", "0"], ["83926.61", "0"], ["83925.21", "0"], ["83924.87", "0"], ["83922.83", "0.056435"], ["83922.69", "0"], ["83922.43", "0"], ["83921.59", "0.024669"], ["83920.69", "0"], ["83918.00", "0.209321"], ["83914.09", "0"], ["83913.09", "0"], ["83911.70", "0"], ["83911.00", "0.000121"], ["83898.80", "0"], ["83897.20", "4.717607"], ["83888.80", "4.173268"], ["83880.40", "5.261946"], ["83872.00", "4.354714"], ["83863.60", "4.263991"], ["83855.20", "5.080500"], ["83846.80", "5.534116"], ["83838.40", "4.899054"], ["83830.00", "5.352670"], ["83821.60", "5.171223"], ["83813.20", "3.901098"], ["83804.80", "4.626884"], ["83796.40", "5.624839"], ["83788.00", "4.989777"], ["83779.60", "4.808330"], ["83771.20", "4.536161"], ["83762.80", "4.445437"], ["83754.40", "4.082545"], ["83746.00", "3.991821"], ["83737.60", "5.443393"], ["83441.56", "0.000024"], ["83440.00", "0.000460"], ["83439.42", "0.000423"], ["83439.33", "0.000010"], ["83437.50", "0.000009"], ["83437.10", "0.000095"], ["83433.33", "0.000134"], ["83433.12", "0.000544"]], "checksum": -659625103, "ts": "1742577047393"}], "ts": 1742577047397, "record_time": 1742577047.590817, "EXCHANGE": "BITGET"}
{"action": "update", "arg": {"instType": "SPOT", "channel": "books", "instId": "BTCUSDT"}, "data": [{"asks": [["83962.01", "0.685282"], ["83962.02", "0.000100"], ["83962.03", "0.000100"], ["83962.04", "0.000100"], ["83964.48", "0.114052"], ["83970.00", "0.069420"], ["83971.96", "0"], ["83979.57", "0"], ["83979.78", "0.035971"], ["83981.28", "0.035972"], ["83982.03", "0.006357"], ["83982.59", "0.035955"], ["83982.69", "0.006357"], ["83983.35", "0.006357"], ["83984.05", "0"], ["83984.32", "0.016429"], ["83984.73", "0.006357"], ["83985.38", "0.136330"], ["83987.08", "0.010993"], ["83988.50", "0.119850"], ["83989.85", "0.119858"], ["83990.17", "0.009989"], ["83990.27", "0.015895"], ["83994.03", "0.015896"], ["84009.30", "0.002553"], ["84011.30", "0.006716"], ["84013.30", "0.017674"], ["84015.30", "0.046511"], ["84017.30", "0.122398"], ["84019.30", "0.322099"], ["84021.30", "0.847630"], ["84023.30", "2.230605"], ["84023.40", "0.390990"], ["84025.60", "1.503570"], ["84026.00", "0.042300"], ["84026.10", "0.017970"], ["84027.10", "0.069510"], ["84028.60", "0"], ["84028.80", "0"], ["84029.50", "0"], ["84030.20", "0"], ["84031.00", "0.570300"], ["84031.10", "0.405150"], ["84031.20", "0"], ["84032.20", "0"], ["84032.50", "0.090000"], ["84033.20", "1.429500"], ["84033.80", "0"], ["84034.00", "1.101060"], ["84034.40", "0"], ["84034.60", "0.605340"], ["84034.70", "0.495960"], ["84035.30", "0"], ["84035.90", "0.035700"], ["84036.00", "0.318300"], ["84036.20", "0.204000"], ["84036.30", "0.288240"], ["84036.50", "0.323640"], ["84065.30", "3.991821"], ["84073.70", "5.171223"], ["84082.10", "4.626884"], ["84090.50", "4.899054"], ["84098.90", "4.717607"], ["84107.30", "4.082545"], ["84115.70", "5.534116"], ["84124.10", "5.080500"], ["84132.50", "5.352670"], ["84149.30", "4.989777"], ["84157.70", "4.536161"], ["84166.10", "4.263991"], ["84174.50", "5.443393"], ["84182.90", "4.445437"], ["84191.30", "4.354714"], ["84199.70", "4.808330"], ["84224.90", "5.624839"], ["84343.02", "0"], ["84343.07", "0"], ["84343.70", "0"], ["84343.97", "0"], ["84344.77", "0"], ["84345.00", "0"], ["84345.79", "0"], ["84346.43", "0"], ["84346.94", "0"], ["84346.97", "0"], ["84347.55", "0"], ["84347.69", "0"], ["84347.83", "0"], ["84348.21", "0"]], "bids": [["83957.58", "0.114052"], ["83955.20", "0.002552"], ["83954.88", "0.038691"], ["83954.61", "0"], ["83953.42", "0.011378"], ["83953.20", "0.006716"], ["83951.20", "0.017672"], ["83949.20", "0.046507"], ["83947.20", "0.122386"], ["83945.20", "0.322069"], ["83943.20", "0.847326"], ["83941.20", "2.229806"], ["83939.20", "5.867909"], ["83939.10", "0.957300"], ["83938.60", "0.484020"], ["83937.53", "0.017817"], ["83936.60", "0.071250"], ["83936.51", "0.015742"], ["83936.50", "0"], ["83936.00", "0.269940"], ["83935.83", "0.006568"], ["83935.60", "0.405090"], ["83935.50", "0.357330"], ["83935.00", "0"], ["83934.90", "0"], ["83934.86", "0.017106"], ["83934.79", "0.028860"], ["83934.17", "0.250116"], ["83933.80", "0.178590"], ["83932.50", "0.051819"], ["83932.10", "0.000200"], ["83932.00", "0.357210"], ["83930.90", "0.357210"], ["83930.40", "0.268701"], ["83929.74", "0.222938"], ["83929.32", "0.076204"], ["83928.88", "0.021155"], ["83928.36", "0"], ["83928.30", "0.480000"], ["83927.14", "0.012454"], ["83926.71", "0"], ["83923.94", "0"], ["83909.00", "0.000160"], ["83904.42", "0.003601"], ["83897.20", "3.991821"], ["83888.80", "4.082545"], ["83880.40", "4.989777"], ["83872.00", "5.171223"], ["83863.60", "4.717607"], ["83855.20", "4.173268"], ["83846.80", "5.443393"], ["83838.40", "4.536161"], ["83830.00", "4.263991"], ["83821.60", "4.354714"], ["83813.20", "5.624839"], ["83804.80", "4.899054"], ["83796.40", "4.626884"], ["83788.00", "5.261946"], ["83779.60", "4.445437"], ["83771.20", "5.534116"], ["83762.80", "5.080500"], ["83754.40", "3.901098"], ["83746.00", "5.352670"], ["83737.60", "4.808330"], ["83444.44", "0"], ["83444.38", "0"], ["83444.27", "0"], ["83443.53", "0"], ["83442.50", "0"], ["83441.56", "0"], ["83440.00", "0"], ["83439.42", "0"], ["83439.33", "0"], ["83437.50", "0"], ["83437.10", "0"], ["83433.33", "0"], ["83433.12", "0"]], "checksum": 233718493, "ts": "1742577047643"}], "ts": 1742577047647, "record_time": 1742577047.841685, "EXCHANGE": "BITGET"}
{"action": "update", "arg": {"instType": "SPOT", "channel": "books", "instId": "BTCUSDT"}, "data": [{"asks": [["83964.47", "0.034216"], ["83979.86", "0"], ["83982.74", "0"], ["83985.34", "0.006357"], ["83989.80", "0.119905"], ["84025.60", "1.236090"], ["84026.00", "0.042480"], ["84026.10", "0.017790"], ["84065.30", "4.354714"], ["84073.70", "4.717607"], ["84082.10", "5.443393"], ["84090.50", "4.082545"], ["84098.90", "3.991821"], ["84107.30", "4.536161"], ["84115.70", "5.261946"], ["84124.10", "4.173268"], ["84132.50", "4.626884"], ["84149.30", "4.899054"], ["84157.70", "5.080500"], ["84166.10", "5.352670"], ["84174.50", "4.263991"], ["84182.90", "5.171223"], ["84191.30", "4.989777"], ["84199.70", "4.445437"], ["84208.10", "5.534116"], ["84216.50", "5.624839"], ["84224.90", "4.808330"], ["84342.70", "0"]], "bids": [["83957.59", "0.046899"], ["83954.62", "0"], ["83953.20", "0.006970"], ["83951.20", "0.018343"], ["83949.20", "0.048271"], ["83947.20", "0.127029"], ["83945.20", "0.334287"], ["83943.20", "0.879701"], ["83941.20", "2.315003"], ["83939.20", "6.092114"], ["83937.14", "0.018263"], ["83933.79", "0.008196"], ["83931.65", "0"], ["83929.34", "0.259076"], ["83928.90", "0.017850"], ["83928.31", "0"], ["83928.30", "0"], ["83925.17", "0.073148"], ["83922.74", "0.000878"], ["83922.30", "0"], ["83918.20", "0"], ["83914.88", "0"], ["83888.80", "4.989777"], ["83880.40", "5.624839"], ["83855.20", "5.534116"], ["83846.80", "3.901098"], ["83838.40", "5.352670"], ["83830.00", "4.445437"], ["83821.60", "4.536161"], ["83813.20", "4.626884"], ["83804.80", "5.080500"], ["83796.40", "4.899054"], ["83788.00", "4.354714"], ["83779.60", "4.082545"], ["83771.20", "5.261946"], ["83762.80", "5.443393"], ["83754.40", "4.263991"], ["83746.00", "4.808330"], ["83737.60", "4.173268"]], "checksum": 176652214, "ts": "1742577047844"}], "ts": 1742577047847, "record_time": 1742577048.040873, "EXCHANGE": "BITGET"}
{"action": "update", "arg": {"instType": "SPOT", "channel": "books", "instId": "BTCUSDT"}, "data": [{"asks": [["83964.47", "0"], ["83971.96", "0.078049"], ["83982.59", "0"], ["84009.30", "0.002434"], ["84011.30", "0.006403"], ["84013.30", "0.016850"], ["84015.30", "0.044343"], ["84017.30", "0.116693"], ["84019.30", "0.307085"], ["84021.30", "0.808120"], ["84023.30", "2.126631"], ["84073.70", "3.901098"], ["84082.10", "4.989777"], ["84090.50", "5.534116"], ["84098.90", "5.261946"], ["84107.30", "4.808330"], ["84115.70", "5.624839"], ["84124.10", "5.171223"], ["84132.50", "4.445437"], ["84140.90", "5.443393"], ["84149.30", "5.080500"], ["84157.70", "4.899054"], ["84166.10", "4.082545"], ["84174.50", "4.717607"], ["84182.90", "4.173268"], ["84191.30", "4.263991"], ["84199.70", "5.352670"], ["84208.10", "3.991821"], ["84216.50", "4.536161"], ["84224.90", "4.626884"], ["84342.70", "0.000423"]], "bids": [["83962.00", "0.802210"], ["83957.20", "0.001208"], ["83955.20", "0.003178"], ["83955.12", "0.038690"], ["83954.88", "0"], ["83953.20", "0.008364"], ["83951.20", "0.022010"], ["83949.20", "0.057921"], ["83948.40", "0.097586"], ["83947.20", "0.152425"], ["83945.20", "0.401116"], ["83943.20", "1.055570"], ["83941.20", "2.777816"], ["83939.20", "7.310042"], ["83897.20", "4.445437"], ["83880.40", "4.717607"], ["83872.00", "3.901098"], ["83863.60", "4.354714"], ["83855.20", "5.443393"], ["83846.80", "5.080500"], ["83838.40", "5.534116"], ["83830.00", "4.808330"], ["83821.60", "4.263991"], ["83804.80", "5.171223"], ["83796.40", "4.536161"], ["83788.00", "4.899054"], ["83779.60", "5.261946"], ["83771.20", "5.352670"], ["83762.80", "4.082545"], ["83754.40", "3.991821"], ["83746.00", "4.173268"], ["83737.60", "5.624839"]], "checksum": 1298995249, "ts": "1742577048047"}], "ts": 1742577048049, "record_time": 1742577048.24284, "EXCHANGE": "BITGET"}
{"action": "update", "arg": {"instType": "SPOT", "channel": "books", "instId": "BTCUSDT"}, "data": [{"asks": [["83962.01", "0.476082"], ["83970.01", "0.209200"], ["83980.31", "0.056299"], ["84021.30", "0.807985"], ["84023.30", "2.126278"], ["84023.40", "0.001016"], ["84026.00", "0.042690"], ["84035.90", "0"], ["84065.30", "4.899054"], ["84073.70", "5.261946"], ["84082.10", "5.171223"], ["84090.50", "4.445437"], ["84098.90", "4.808330"], ["84107.30", "3.991821"], ["84115.70", "4.263991"], ["84124.10", "4.989777"], ["84132.50", "4.082545"], ["84140.90", "4.626884"], ["84149.30", "5.534116"], ["84157.70", "5.352670"], ["84166.10", "3.901098"], ["84191.30", "5.080500"], ["84199.70", "4.536161"], ["84208.10", "5.624839"], ["84216.50", "4.354714"], ["84224.90", "5.443393"]], "bids": [["83949.20", "0.058022"], ["83947.20", "0.152690"], ["83945.20", "0.401816"], ["83943.21", "0.018324"], ["83943.20", "1.057217"], ["83941.20", "2.782148"], ["83939.20", "7.321444"], ["83912.00", "0"], ["83910.00", "0.002000"], ["83897.20", "5.080500"], ["83888.80", "4.717607"], ["83880.40", "4.173268"], ["83872.00", "4.899054"], ["83863.60", "4.989777"], ["83855.20", "4.354714"], ["83846.80", "5.261946"], ["83838.40", "4.445437"], ["83830.00", "4.536161"], ["83821.60", "5.624839"], ["83813.20", "3.901098"], ["83804.80", "4.626884"], ["83796.40", "5.352670"], ["83788.00", "4.808330"], ["83779.60", "4.082545"], ["83771.20", "3.991821"], ["83762.80", "5.443393"], ["83754.40", "5.534116"], ["83746.00", "4.263991"], ["83737.60", "5.171223"], ["83444.44", "0.000105"]], "checksum": -179637349, "ts": "1742577048279"}], "ts": 1742577048282, "record_time": 1742577048.47504, "EXCHANGE": "BITGET"}
{"action": "update", "arg": {"instType": "SPOT", "channel": "books", "instId": "BTCUSDT"}, "data": [{"asks": [["84005.12", "0.688430"], ["84009.30", "0.002102"], ["84011.30", "0.005534"], ["84013.30", "0.014561"], ["84015.30", "0.038319"], ["84017.30", "0.100841"], ["84019.30", "0.265632"], ["84021.30", "0.699032"], ["84023.30", "1.839559"], ["84025.60", "0.856170"], ["84025.90", "0.399480"], ["84026.10", "0"], ["84027.10", "0.069720"], ["84034.00", "1.757970"], ["84035.90", "0.016650"], ["84065.30", "5.171223"], ["84073.70", "5.080500"], ["84082.10", "5.261946"], ["84090.50", "4.173268"], ["84098.90", "5.624839"], ["84115.70", "4.808330"], ["84124.10", "4.354714"], ["84132.50", "5.534116"], ["84140.90", "4.989777"], ["84149.30", "4.445437"], ["84157.70", "4.717607"], ["84166.10", "5.443393"], ["84174.50", "4.263991"], ["84182.90", "4.626884"], ["84191.30", "5.352670"], ["84208.10", "3.901098"], ["84216.50", "4.082545"], ["84224.90", "4.899054"], ["84342.70", "0"]], "bids": [["83957.20", "0.001451"], ["83955.20", "0.003987"], ["83955.12", "0"], ["83953.20", "0.010491"], ["83951.20", "0.027607"], ["83949.20", "0.072651"], ["83947.20", "0.191186"], ["83945.20", "0.503123"], ["83943.21", "1.151381"], ["83943.20", "1.324006"], ["83941.20", "3.484227"], ["83939.20", "9.169019"], ["83936.44", "0"], ["83897.20", "5.443393"], ["83888.80", "3.991821"], ["83872.00", "5.080500"], ["83863.60", "5.534116"], ["83855.20", "4.263991"], ["83846.80", "5.171223"], ["83838.40", "4.808330"], ["83821.60", "4.899054"], ["83813.20", "4.354714"], ["83804.80", "4.445437"], ["83796.40", "5.624839"], ["83788.00", "4.717607"], ["83779.60", "5.261946"], ["83771.20", "3.901098"], ["83762.80", "4.989777"], ["83754.40", "4.626884"], ["83746.00", "5.352670"], ["83737.60", "4.082545"], ["83444.38", "0.000025"], ["83444.27", "0.000028"]], "checksum": 822779795, "ts": "1742577048483"}], "ts": 1742577048487, "record_time": 1742577048.688091, "EXCHANGE": "BITGET"}
{"action": "update", "arg": {"instType": "SPOT", "channel": "books", "instId": "BTCUSDT"}, "data": [{"asks": [["84035.90", "0"], ["84037.00", "0.432000"], ["84065.30", "5.080500"], ["84073.70", "5.624839"], ["84082.10", "4.354714"], ["84090.50", "4.263991"], ["84098.90", "4.626884"], ["84107.30", "4.173268"], ["84115.70", "4.445437"], ["84124.10", "5.443393"], ["84132.50", "5.261946"], ["84140.90", "5.352670"], ["84149.30", "4.717607"], ["84157.70", "5.171223"], ["84166.10", "4.989777"], ["84174.50", "4.899054"], ["84182.90", "4.082545"], ["84191.30", "3.901098"], ["84199.70", "3.991821"], ["84208.10", "4.808330"], ["84216.50", "4.536161"], ["84224.90", "5.534116"]], "bids": [["83955.35", "0.038690"], ["83897.20", "4.989777"], ["83888.80", "4.445437"], ["83880.40", "5.443393"], ["83872.00", "4.717607"], ["83863.60", "4.536161"], ["83855.20", "5.171223"], ["83846.80", "4.173268"], ["83838.40", "5.261946"], ["83830.00", "4.082545"], ["83821.60", "3.901098"], ["83813.20", "5.080500"], ["83804.80", "4.808330"], ["83796.40", "4.899054"], ["83788.00", "4.263991"], ["83779.60", "4.354714"], ["83771.20", "4.626884"], ["83762.80", "5.352670"], ["83754.40", "5.624839"], ["83746.00", "5.534116"], ["83737.60", "3.991821"], ["83444.27", "0"]], "checksum": -962040454, "ts": "1742577048697"}], "ts": 1742577048703, "record_time": 1742577048.896688, "EXCHANGE": "BITGET"}
{"action": "update", "arg": {"instType": "SPOT", "channel": "books", "instId": "BTCUSDT"}, "data": [{"asks": [["83962.01", "0.894482"], ["84007.30", "0.001210"], ["84009.30", "0.003182"], ["84011.30", "0.008374"], ["84013.30", "0.022037"], ["84015.30", "0.057994"], ["84017.30", "0.152614"], ["84019.30", "0.401616"], ["84021.30", "1.056885"], ["84023.30", "2.781277"], ["84023.40", "0.411480"], ["84024.00", "0.042510"], ["84024.70", "1.008210"], ["84025.60", "0"], ["84025.90", "0"], ["84027.10", "0.069510"], ["84031.00", "0.924240"], ["84031.70", "1.350000"], ["84033.90", "0.012420"], ["84035.00", "2.358450"], ["84035.90", "0.035700"], ["84037.00", "0"], ["84065.30", "5.624839"], ["84073.70", "4.445437"], ["84082.10", "3.991821"], ["84090.50", "4.989777"], ["84098.90", "3.901098"], ["84107.30", "4.899054"], ["84115.70", "5.171223"], ["84124.10", "5.261946"], ["84132.50", "4.082545"], ["84140.90", "5.534116"], ["84149.30", "4.263991"], ["84157.70", "4.354714"], ["84166.10", "4.717607"], ["84174.50", "4.173268"], ["84182.90", "5.352670"], ["84191.30", "4.808330"], ["84199.70", "4.536161"], ["84208.10", "5.443393"], ["84216.50", "4.626884"], ["84224.90", "5.080500"], ["84342.63", "0"]], "bids": [["83957.20", "0.001314"], ["83955.20", "0.003459"], ["83953.20", "0.009102"], ["83951.20", "0.023952"], ["83949.20", "0.063034"], ["83947.20", "0.165877"], ["83945.20", "0.436518"], ["83943.20", "1.148734"], ["83941.20", "3.022984"], ["83939.20", "7.955220"], ["83912.00", "0.000160"], ["83910.00", "0.002121"], ["83897.20", "4.899054"], ["83888.80", "5.534116"], ["83880.40", "4.808330"], ["83872.00", "3.991821"], ["83855.20", "5.624839"], ["83846.80", "4.082545"], ["83830.00", "4.989777"], ["83821.60", "4.626884"], ["83813.20", "4.445437"], ["83804.80", "5.443393"], ["83796.40", "4.263991"], ["83788.00", "5.171223"], ["83779.60", "5.080500"], ["83771.20", "4.354714"], ["83762.80", "4.173268"], ["83754.40", "3.901098"], ["83746.00", "4.717607"], ["83737.60", "5.352670"], ["83570.00", "0.000408"], ["83444.38", "0"]], "checksum": 558303355, "ts": "1742577048906"}], "ts": 1742577048909, "record_time": 1742577049.102896, "EXCHANGE": "BITGET"}
{"action": "update", "arg": {"instType": "SPOT", "channel": "books", "instId": "BTCUSDT"}, "data": [{"asks": [["83964.47", "0.034216"], ["84007.30", "0.001415"], ["84009.30", "0.003724"], ["84011.30", "0.009798"], ["84013.30", "0.025786"], ["84015.30", "0.067858"], ["84017.30", "0.178574"], ["84019.30", "0.469931"], ["84021.30", "1.236659"], ["84023.30", "3.254368"], ["84026.00", "0.042480"], ["84036.20", "0.303180"], ["84065.30", "5.080500"], ["84073.70", "5.171223"], ["84082.10", "5.443393"], ["84090.50", "4.445437"], ["84098.90", "5.352670"], ["84107.30", "4.989777"], ["84115.70", "4.899054"], ["84124.10", "3.901098"], ["84132.50", "4.717607"], ["84140.90", "4.808330"], ["84149.30", "4.173268"], ["84166.10", "5.261946"], ["84174.50", "4.263991"], ["84182.90", "4.536161"], ["84191.30", "4.626884"], ["84199.70", "5.624839"], ["84208.10", "3.991821"], ["84216.50", "4.082545"], ["84224.90", "5.534116"], ["84342.11", "0"]], "bids": [["83955.61", "0.038690"], ["83955.35", "0"], ["83951.20", "0.023840"], ["83949.20", "0.062737"], ["83947.20", "0.165099"], ["83945.20", "0.434471"], ["83943.20", "1.143343"], ["83941.20", "3.008798"], ["83939.20", "7.917890"], ["83936.40", "0.089280"], ["83936.00", "0"], ["83935.50", "0.357150"], ["83935.00", "0.015000"], ["83928.40", "0"], ["83921.59", "0"], ["83913.11", "0.024669"], ["83897.20", "3.901098"], ["83880.40", "4.445437"], ["83872.00", "5.624839"], ["83863.60", "4.082545"], ["83855.20", "5.261946"], ["83846.80", "4.536161"], ["83838.40", "4.717607"], ["83830.00", "5.443393"], ["83821.60", "4.173268"], ["83813.20", "5.080500"], ["83804.80", "4.899054"], ["83796.40", "4.989777"], ["83788.00", "3.991821"], ["83779.60", "4.263991"], ["83771.20", "4.808330"], ["83762.80", "5.171223"], ["83754.40", "4.354714"], ["83746.00", "5.352670"], ["83737.60", "4.626884"], ["83444.38", "0.000025"]], "checksum": 352825887, "ts": "1742577049142"}], "ts": 1742577049144, "record_time": 1742577049.338287, "EXCHANGE": "BITGET"}
{"action": "update", "arg": {"instType": "SPOT", "channel": "books", "instId": "BTCUSDT"}, "data": [{"asks": [["83962.01", "0.685282"], ["84028.20", "0"], ["84030.40", "0.022650"], ["84065.30", "4.536161"], ["84073.70", "4.354714"], ["84082.10", "3.991821"], ["84090.50", "5.352670"], ["84098.90", "5.624839"], ["84107.30", "3.901098"], ["84115.70", "5.534116"], ["84124.10", "4.445437"], ["84132.50", "5.261946"], ["84140.90", "5.080500"], ["84149.30", "4.899054"], ["84157.70", "4.173268"], ["84166.10", "4.717607"], ["84174.50", "4.989777"], ["84182.90", "4.808330"], ["84191.30", "5.171223"], ["84199.70", "4.263991"], ["84208.10", "4.626884"], ["84224.90", "5.443393"]], "bids": [["83951.20", "0.023983"], ["83949.20", "0.063115"], ["83947.20", "0.166092"], ["83945.20", "0.437084"], ["83943.20", "1.150222"], ["83941.20", "3.026900"], ["83939.20", "7.965524"], ["83933.80", "0"], ["83932.00", "0"], ["83931.70", "0.357210"], ["83930.90", "0"], ["83928.40", "0.071430"], ["83897.20", "5.352670"], ["83888.80", "4.989777"], ["83880.40", "4.263991"], ["83872.00", "3.991821"], ["83863.60", "5.534116"], ["83855.20", "5.171223"], ["83846.80", "4.445437"], ["83838.40", "3.901098"], ["83830.00", "4.082545"], ["83821.60", "4.626884"], ["83813.20", "4.354714"], ["83804.80", "4.717607"], ["83796.40", "5.624839"], ["83788.00", "4.808330"], ["83779.60", "5.080500"], ["83771.20", "5.261946"], ["83762.80", "4.536161"], ["83754.40", "5.443393"], ["83746.00", "4.173268"], ["83737.60", "4.899054"], ["83444.27", "0.000028"], ["83443.53", "0.000161"]], "checksum": 1015400289, "ts": "1742577049350"}], "ts": 1742577049354, "record_time": 1742577049.548894, "EXCHANGE": "BITGET"}
{"action": "update", "arg": {"instType": "SPOT", "channel": "books", "instId": "BTCUSDT"}, "data": [{"asks": [["83988.49", "0.151919"], ["83991.06", "0"], ["84005.12", "0"], ["84017.30", "0.178473"], ["84019.30", "0.469665"], ["84021.30", "1.235960"], ["84023.30", "3.252526"], ["84065.30", "4.445437"], ["84073.70", "3.901098"], ["84082.10", "5.261946"], ["84090.50", "4.717607"], ["84098.90", "4.989777"], ["84107.30", "4.536161"], ["84124.10", "4.899054"], ["84132.50", "4.082545"], ["84140.90", "4.808330"], ["84149.30", "3.991821"], ["84157.70", "5.624839"], ["84166.10", "5.443393"], ["84174.50", "5.080500"], ["84182.90", "4.173268"], ["84199.70", "4.354714"], ["84208.10", "4.263991"], ["84216.50", "4.626884"], ["84224.90", "5.352670"], ["84342.11", "0.000051"]], "bids": [["83955.84", "0.038690"], ["83955.61", "0"], ["83945.20", "0.436908"], ["83943.20", "1.149760"], ["83941.20", "3.025684"], ["83939.20", "7.962325"], ["83935.00", "0.030000"], ["83909.00", "0"], ["83897.20", "4.808330"], ["83888.80", "4.445437"], ["83880.40", "5.171223"], ["83872.00", "4.899054"], ["83863.60", "4.173268"], ["83855.20", "4.263991"], ["83846.80", "4.717607"], ["83838.40", "3.991821"], ["83830.00", "4.536161"], ["83821.60", "5.443393"], ["83813.20", "4.626884"], ["83804.80", "5.352670"], ["83796.40", "5.080500"], ["83788.00", "5.261946"], ["83779.60", "5.534116"], ["83771.20", "4.989777"], ["83762.80", "4.082545"], ["83754.40", "3.901098"], ["83746.00", "5.624839"], ["83737.60", "4.354714"], ["83442.50", "0.000113"]], "checksum": 678646287, "ts": "1742577049568"}], "ts": 1742577049570, "record_time": 1742577049.763551, "EXCHANGE": "BITGET"}
{"action": "update", "arg": {"instType": "SPOT", "channel": "books", "instId": "BTCUSDT"}, "data": [{"asks": [["83999.55", "0"], ["84021.29", "0.538565"], ["84065.30", "4.989777"], ["84073.70", "4.899054"], ["84082.10", "4.173268"], ["84090.50", "5.261946"], ["84098.90", "4.717607"], ["84115.70", "4.082545"], ["84124.10", "4.354714"], ["84132.50", "4.808330"], ["84140.90", "4.626884"], ["84149.30", "5.080500"], ["84157.70", "4.263991"], ["84166.10", "5.171223"], ["84174.50", "3.991821"], ["84182.90", "3.901098"], ["84191.30", "5.534116"], ["84199.70", "5.624839"], ["84208.10", "5.352670"], ["84216.50", "4.445437"], ["84224.90", "5.443393"]], "bids": [["83955.20", "0.003295"], ["83953.20", "0.008670"], ["83951.20", "0.022816"], ["83949.20", "0.060041"], ["83947.20", "0.158003"], ["83945.20", "0.415798"], ["83943.20", "1.094206"], ["83941.20", "2.879489"], ["83939.20", "7.577603"], ["83933.70", "0.621180"], ["83911.00", "0"], ["83897.20", "5.443393"], ["83888.80", "4.354714"], ["83880.40", "5.624839"], ["83872.00", "3.991821"], ["83863.60", "5.352670"], ["83855.20", "4.717607"], ["83846.80", "4.808330"], ["83838.40", "4.899054"], ["83830.00", "4.082545"], ["83821.60", "5.534116"], ["83813.20", "3.901098"], ["83804.80", "5.080500"], ["83796.40", "4.989777"], ["83788.00", "4.263991"], ["83779.60", "4.173268"], ["83771.20", "4.626884"], ["83762.80", "4.536161"], ["83754.40", "4.445437"], ["83746.00", "5.261946"], ["83737.60", "5.171223"]], "checksum": -1873849286, "ts": "1742577049777"}], "ts": 1742577049780, "record_time": 1742577049.973714, "EXCHANGE": "BITGET"}
{"action": "update", "arg": {"instType": "SPOT", "channel": "books", "instId": "BTCUSDT"}, "data": [{"asks": [["84002.55", "0.177832"], ["84009.87", "0"], ["84065.30", "4.717607"], ["84073.70", "5.080500"], ["84082.10", "4.263991"], ["84090.50", "5.443393"], ["84098.90", "4.626884"], ["84107.30", "4.445437"], ["84115.70", "4.536161"], ["84124.10", "5.352670"], ["84132.50", "5.261946"], ["84140.90", "4.899054"], ["84149.30", "5.624839"], ["84157.70", "4.808330"], ["84166.10", "3.991821"], ["84174.50", "5.171223"], ["84182.90", "4.354714"], ["84191.30", "3.901098"], ["84199.70", "4.082545"], ["84208.10", "5.534116"], ["84216.50", "4.989777"], ["84224.90", "4.173268"]], "bids": [["83897.20", "4.445437"], ["83888.80", "5.352670"], ["83880.40", "4.808330"], ["83879.20", "0"], ["83872.00", "5.080500"], ["83863.60", "4.354714"], ["83855.20", "4.263991"], ["83846.80", "5.171223"], ["83838.40", "5.261946"], ["83830.00", "5.624839"], ["83821.60", "5.443393"], ["83804.80", "4.626884"], ["83796.40", "5.534116"], ["83788.00", "3.991821"], ["83771.20", "4.082545"], ["83762.80", "4.989777"], ["83754.40", "4.717607"], ["83746.00", "4.536161"], ["83737.60", "4.899054"], ["83441.56", "0.000024"]], "checksum": -1873849286, "ts": "1742577049979"}], "ts": 1742577049981, "record_time": 1742577050.174357, "EXCHANGE": "BITGET"}
{"action": "update", "arg": {"instType": "SPOT", "channel": "books", "instId": "BTCUSDT"}, "data": [{"asks": [["84017.30", "0.178792"], ["84019.30", "0.470506"], ["84021.30", "1.238172"], ["84023.30", "3.258348"], ["84065.30", "4.989777"], ["84073.70", "4.717607"], ["84082.10", "4.354714"], ["84090.50", "5.080500"], ["84098.90", "4.536161"], ["84107.30", "5.624839"], ["84115.70", "4.808330"], ["84124.10", "4.082545"], ["84132.50", "3.991821"], ["84140.90", "3.901098"], ["84149.30", "5.443393"], ["84157.70", "4.626884"], ["84166.10", "4.899054"], ["84174.50", "5.261946"], ["84182.90", "4.263991"], ["84191.30", "4.445437"], ["84199.70", "5.534116"], ["84208.10", "5.352670"], ["84216.50", "4.173268"], ["84224.90", "5.171223"]], "bids": [["83962.00", "0.801519"], ["83956.05", "0.038690"], ["83955.84", "0"], ["83949.20", "0.060142"], ["83947.20", "0.158267"], ["83945.20", "0.416492"], ["83943.20", "1.096032"], ["83941.20", "2.884295"], ["83939.20", "7.590251"], ["83910.00", "0.002281"], ["83897.20", "5.534116"], ["83888.80", "5.624839"], ["83886.00", "0.000971"], ["83880.40", "3.901098"], ["83872.00", "5.171223"], ["83863.60", "4.173268"], ["83855.20", "5.080500"], ["83846.80", "4.626884"], ["83838.40", "4.536161"], ["83830.00", "4.445437"], ["83821.60", "4.899054"], ["83813.20", "4.082545"], ["83804.80", "5.352670"], ["83796.40", "3.991821"], ["83788.00", "5.443393"], ["83779.60", "4.354714"], ["83771.20", "4.263991"], ["83762.80", "4.808330"], ["83754.40", "5.261946"], ["83746.00", "4.717607"], ["83737.60", "4.989777"], ["83570.00", "0.000678"], ["83441.56", "0"]], "checksum": 378418815, "ts": "1742577050181"}], "ts": 1742577050184, "record_time": 1742577050.377786, "EXCHANGE": "BITGET"}
{"action": "update", "arg": {"instType": "SPOT", "channel": "books", "instId": "BTCUSDT"}, "data": [{"asks": [["84013.30", "0.025990"], ["84015.30", "0.068396"], ["84017.30", "0.179988"], ["84019.30", "0.473653"], ["84021.30", "1.246456"], ["84023.30", "3.280147"], ["84065.30", "5.080500"], ["84082.10", "4.536161"], ["84090.50", "5.352670"], ["84098.90", "4.989777"], ["84107.30", "5.443393"], ["84115.70", "5.261946"], ["84124.10", "3.901098"], ["84132.50", "5.171223"], ["84140.90", "4.082545"], ["84149.30", "4.899054"], ["84157.70", "4.263991"], ["84166.10", "4.445437"], ["84174.50", "4.626884"], ["84182.90", "4.808330"], ["84191.30", "4.173268"], ["84199.70", "3.991821"], ["84208.10", "4.354714"], ["84216.50", "5.624839"], ["84224.90", "5.534116"]], "bids": [["83949.20", "0.059849"], ["83947.20", "0.157498"], ["83945.20", "0.414469"], ["83943.20", "1.090706"], ["83941.20", "2.870279"], ["83939.20", "7.553367"], ["83897.20", "4.536161"], ["83888.80", "4.445437"], ["83880.40", "5.443393"], ["83872.00", "5.352670"], ["83863.60", "5.080500"], ["83855.20", "3.991821"], ["83846.80", "4.173268"], ["83838.40", "5.624839"], ["83830.00", "3.901098"], ["83821.60", "4.082545"], ["83813.20", "4.263991"], ["83804.80", "5.534116"], ["83796.40", "5.171223"], ["83788.00", "4.717607"], ["83771.20", "4.989777"], ["83762.80", "4.899054"], ["83754.40", "4.626884"], ["83746.00", "5.261946"], ["83737.60", "4.808330"]], "checksum": -1064451529, "ts": "1742577050390"}], "ts": 1742577050394, "record_time": 1742577050.58686, "EXCHANGE": "BITGET"}
{"action": "update", "arg": {"instType": "SPOT", "channel": "books", "instId": "BTCUSDT"}, "data": [{"asks": [["84002.54", "0.053663"], ["84065.30", "4.354714"], ["84073.70", "4.263991"], ["84082.10", "5.261946"], ["84090.50", "4.082545"], ["84098.90", "5.171223"], ["84107.30", "3.901098"], ["84115.70", "5.534116"], ["84124.10", "4.626884"], ["84132.50", "4.808330"], ["84140.90", "4.173268"], ["84149.30", "4.536161"], ["84157.70", "5.624839"], ["84166.10", "4.899054"], ["84174.50", "5.443393"], ["84182.90", "4.445437"], ["84191.30", "5.080500"], ["84208.10", "4.717607"], ["84216.50", "5.352670"], ["84224.90", "4.989777"], ["84342.11", "0"]], "bids": [["83956.05", "0"], ["83939.20", "7.553162"], ["83912.00", "0.000281"], ["83888.80", "5.624839"], ["83880.40", "4.354714"], ["83872.00", "4.808330"], ["83863.60", "4.989777"], ["83855.20", "4.717607"], ["83846.80", "5.261946"], ["83838.40", "4.263991"], ["83830.00", "4.445437"], ["83821.60", "5.080500"], ["83813.20", "4.173268"], ["83804.80", "5.171223"], ["83796.40", "4.899054"], ["83788.00", "5.534116"], ["83779.60", "3.901098"], ["83771.20", "4.626884"], ["83762.80", "5.443393"], ["83754.40", "5.352670"], ["83746.00", "3.991821"], ["83737.60", "4.082545"], ["83441.56", "0.000024"]], "checksum": 15400021, "ts": "1742577050590"}], "ts": 1742577050593, "record_time": 1742577050.787157, "EXCHANGE": "BITGET"}
{"action": "update", "arg": {"instType": "SPOT", "channel": "books", "instId": "BTCUSDT"}, "data": [{"asks": [["83962.01", "0.912877"], ["84007.30", "0.002419"], ["84009.30", "0.006365"], ["84011.30", "0.016749"], ["84013.30", "0.044078"], ["84015.30", "0.115995"], ["84017.30", "0.305250"], ["84019.30", "0.803289"], ["84021.30", "2.113919"], ["84023.30", "5.562683"], ["84024.70", "0"], ["84028.00", "0.042300"], ["84029.00", "0"], ["84030.00", "0.068820"], ["84037.00", "0.432000"], ["84065.30", "5.624839"], ["84073.70", "3.901098"], ["84082.10", "4.082545"], ["84090.50", "5.352670"], ["84098.90", "4.354714"], ["84107.30", "5.261946"], ["84115.70", "4.536161"], ["84124.10", "4.263991"], ["84132.50", "5.080500"], ["84149.30", "4.989777"], ["84157.70", "4.717607"], ["84166.10", "4.626884"], ["84174.50", "5.171223"], ["84182.90", "4.808330"], ["84191.30", "3.991821"], ["84199.70", "4.899054"], ["84208.10", "4.445437"], ["84216.50", "5.443393"], ["84224.90", "5.534116"], ["84342.11", "0.000051"]], "bids": [["83962.00", "0.638781"], ["83957.20", "0.001186"], ["83956.28", "0.038690"], ["83955.20", "0.003120"], ["83954.36", "0.013838"], ["83953.20", "0.008212"], ["83951.20", "0.021610"], ["83949.20", "0.056868"], ["83947.20", "0.149654"], ["83945.20", "0.393825"], ["83943.20", "1.036383"], ["83941.20", "2.727322"], ["83939.20", "7.177163"], ["83935.50", "0.178560"], ["83931.70", "0.018539"], ["83897.20", "4.173268"], ["83888.80", "4.445437"], ["83880.40", "4.899054"], ["83872.00", "3.901098"], ["83846.80", "5.624839"], ["83838.40", "4.808330"], ["83830.00", "4.082545"], ["83821.60", "5.534116"], ["83813.20", "5.171223"], ["83804.80", "4.263991"], ["83796.40", "5.443393"], ["83788.00", "5.080500"], ["83779.60", "4.354714"], ["83771.20", "3.991821"], ["83762.80", "5.352670"], ["83754.40", "4.536161"], ["83746.00", "5.261946"], ["83737.60", "4.626884"], ["83442.50", "0"], ["83441.56", "0"]], "checksum": 14697980, "ts": "1742577050811"}], "ts": 1742577050813, "record_time": 1742577051.006918, "EXCHANGE": "BITGET"}
{"action": "update", "arg": {"instType": "SPOT", "channel": "books", "instId": "BTCUSDT"}, "data": [{"asks": [["84005.30", "0.001120"], ["84007.30", "0.002948"], ["84009.30", "0.007758"], ["84011.30", "0.020416"], ["84013.30", "0.053725"], ["84015.30", "0.141384"], ["84017.30", "0.372061"], ["84019.30", "0.979110"], ["84021.30", "2.576604"], ["84023.30", "6.780537"], ["84065.30", "4.445437"], ["84073.70", "4.717607"], ["84082.10", "5.443393"], ["84090.50", "5.534116"], ["84098.90", "5.352670"], ["84107.30", "3.901098"], ["84115.70", "4.808330"], ["84124.10", "4.173268"], ["84132.50", "4.989777"], ["84140.90", "4.082545"], ["84149.30", "4.626884"], ["84157.70", "3.991821"], ["84166.10", "5.261946"], ["84174.50", "4.263991"], ["84182.90", "4.354714"], ["84191.30", "5.624839"], ["84199.70", "4.536161"], ["84208.10", "5.171223"], ["84216.50", "5.080500"], ["84224.90", "4.899054"]], "bids": [["83951.20", "0.021740"], ["83949.20", "0.057212"], ["83947.20", "0.150346"], ["83945.20", "0.395647"], ["83943.20", "1.041177"], ["83941.20", "2.739939"], ["83939.20", "7.210364"], ["83936.90", "0.178590"], ["83935.60", "0.404910"], ["83928.90", "0"], ["83912.00", "0.000121"], ["83897.20", "4.808330"], ["83888.80", "5.624839"], ["83880.40", "5.171223"], ["83872.00", "4.989777"], ["83863.60", "4.354714"], ["83855.20", "5.261946"], ["83846.80", "4.536161"], ["83838.40", "5.080500"], ["83830.00", "4.263991"], ["83821.60", "4.899054"], ["83813.20", "4.173268"], ["83804.80", "5.534116"], ["83796.40", "4.717607"], ["83788.00", "4.445437"], ["83779.60", "3.901098"], ["83771.20", "5.443393"], ["83762.80", "4.626884"], ["83754.40", "5.352670"], ["83746.00", "4.082545"], ["83737.60", "3.991821"]], "checksum": -137053049, "ts": "1742577051023"}], "ts": 1742577051027, "record_time": 1742577051.219962, "EXCHANGE": "BITGET"}
{"action": "update", "arg": {"instType": "SPOT", "channel": "books", "instId": "BTCUSDT"}, "data": [{"asks": [["83962.01", "0.947341"], ["84005.30", "0.001361"], ["84007.30", "0.003582"], ["84009.30", "0.009425"], ["84011.30", "0.024802"], ["84013.30", "0.065269"], ["84015.30", "0.171761"], ["84017.30", "0.452002"], ["84019.30", "1.189481"], ["84021.30", "3.130212"], ["84023.30", "8.237401"], ["84031.00", "1.587540"], ["84033.00", "2.358510"], ["84034.00", "1.101060"], ["84035.00", "0"], ["84065.30", "5.261946"], ["84073.70", "4.989777"], ["84082.10", "4.536161"], ["84090.50", "4.354714"], ["84098.90", "4.082545"], ["84107.30", "4.173268"], ["84115.70", "3.991821"], ["84124.10", "5.171223"], ["84132.50", "5.624839"], ["84140.90", "5.080500"], ["84157.70", "3.901098"], ["84166.10", "4.263991"], ["84174.50", "5.443393"], ["84182.90", "4.899054"], ["84191.30", "4.717607"], ["84199.70", "5.534116"], ["84208.10", "4.808330"], ["84216.50", "5.352670"], ["84224.90", "4.445437"]], "bids": [["83959.46", "0"], ["83957.20", "0.001074"], ["83956.49", "0.038690"], ["83956.28", "0"], ["83955.20", "0.002827"], ["83953.20", "0.007439"], ["83951.20", "0.019575"], ["83949.20", "0.051515"], ["83947.20", "0.135565"], ["83945.20", "0.356749"], ["83943.20", "0.938814"], ["83941.20", "2.470563"], ["83939.20", "6.501481"], ["83939.10", "0.222720"], ["83938.60", "0.483840"], ["83938.20", "0.010170"], ["83936.90", "0"], ["83936.60", "0.071280"], ["83935.50", "0"], ["83935.30", "0.073410"], ["83933.60", "0.485160"], ["83933.00", "0"], ["83928.40", "0"], ["83928.27", "0"], ["83917.57", "0.024948"], ["83897.20", "5.624839"], ["83888.80", "4.717607"], ["83880.40", "5.534116"], ["83872.00", "4.354714"], ["83863.60", "4.899054"], ["83855.20", "3.901098"], ["83846.80", "4.808330"], ["83838.40", "5.352670"], ["83830.00", "4.989777"], ["83821.60", "5.443393"], ["83813.20", "3.991821"], ["83804.80", "4.082545"], ["83796.40", "4.536161"], ["83788.00", "4.173268"], ["83779.60", "5.261946"], ["83771.20", "4.445437"], ["83754.40", "4.263991"], ["83746.00", "5.171223"], ["83737.60", "5.080500"], ["83442.50", "0.000113"], ["83441.56", "0.000024"], ["83440.00", "0.000460"]], "checksum": -1352254187, "ts": "1742577051240"}], "ts": 1742577051243, "record_time": 1742577051.436638, "EXCHANGE": "BITGET"}
{"action": "update", "arg": {"instType": "SPOT", "channel": "books", "instId": "BTCUSDT"}, "data": [{"asks": [["83971.97", "0.245283"], ["84005.30", "0.001207"], ["84007.30", "0.003176"], ["84009.30", "0.008357"], ["84011.30", "0.021992"], ["84013.30", "0.057874"], ["84015.30", "0.152299"], ["84017.30", "0.400788"], ["84019.30", "1.054705"], ["84021.30", "2.775540"], ["84023.30", "7.304053"], ["84034.21", "0"], ["84065.30", "5.534116"], ["84073.70", "3.901098"], ["84082.10", "4.899054"], ["84090.50", "4.717607"], ["84098.90", "4.536161"], ["84107.30", "3.991821"], ["84115.70", "4.354714"], ["84124.10", "4.082545"], ["84132.50", "4.445437"], ["84140.90", "5.624839"], ["84149.30", "4.263991"], ["84157.70", "5.443393"], ["84166.10", "4.626884"], ["84174.50", "4.808330"], ["84182.90", "4.173268"], ["84191.30", "5.171223"], ["84199.70", "5.352670"], ["84208.10", "4.989777"], ["84216.50", "5.080500"], ["84224.90", "5.261946"], ["84342.63", "0.000009"]], "bids": [["83951.20", "0.019676"], ["83949.20", "0.051778"], ["83947.20", "0.136257"], ["83945.20", "0.358571"], ["83943.20", "0.943608"], ["83941.20", "2.483179"], ["83939.20", "6.534682"], ["83939.02", "0.004034"], ["83935.00", "0.015000"], ["83932.49", "0"], ["83909.00", "0.000160"], ["83897.20", "5.171223"], ["83888.80", "4.263991"], ["83880.40", "4.989777"], ["83872.00", "4.445437"], ["83866.31", "0"], ["83863.60", "3.901098"], ["83855.20", "4.536161"], ["83846.80", "3.991821"], ["83846.03", "0.125764"], ["83838.40", "4.082545"], ["83830.00", "4.173268"], ["83821.60", "5.261946"], ["83813.20", "4.717607"], ["83804.80", "5.443393"], ["83796.40", "4.899054"], ["83788.00", "5.624839"], ["83779.60", "4.354714"], ["83771.20", "5.080500"], ["83762.80", "5.534116"], ["83754.40", "5.352670"], ["83746.00", "4.808330"], ["83737.60", "4.626884"], ["83440.00", "0"]], "checksum": -342751331, "ts": "1742577051442"}], "ts": 1742577051444, "record_time": 1742577051.63796, "EXCHANGE": "BITGET"}
{"action": "update", "arg": {"instType": "SPOT", "channel": "books", "instId": "BTCUSDT"}, "data": [{"asks": [["83962.01", "0.961208"], ["84005.12", "0.432043"], ["84021.29", "0"], ["84065.30", "4.354714"], ["84073.70", "4.717607"], ["84082.10", "4.445437"], ["84090.50", "4.808330"], ["84107.30", "5.171223"], ["84115.70", "4.989777"], ["84124.10", "5.080500"], ["84132.50", "4.899054"], ["84140.90", "4.626884"], ["84149.30", "4.173268"], ["84157.70", "4.263991"], ["84166.10", "5.352670"], ["84174.50", "5.534116"], ["84182.90", "5.443393"], ["84191.30", "5.624839"], ["84199.70", "5.261946"], ["84208.10", "3.991821"], ["84216.50", "3.901098"], ["84224.90", "4.082545"]], "bids": [["83956.49", "0"], ["83938.20", "0"], ["83929.90", "0.120000"], ["83897.20", "5.534116"], ["83888.80", "4.445437"], ["83880.40", "4.082545"], ["83872.00", "4.626884"], ["83863.60", "4.899054"], ["83855.20", "5.352670"], ["83846.80", "4.354714"], ["83838.40", "4.717607"], ["83830.00", "4.808330"], ["83821.60", "4.536161"], ["83813.20", "5.443393"], ["83804.80", "4.263991"], ["83796.40", "4.173268"], ["83788.00", "5.171223"], ["83779.60", "5.080500"], ["83771.20", "4.989777"], ["83762.80", "3.991821"], ["83754.40", "3.901098"], ["83746.00", "5.261946"], ["83737.60", "5.624839"], ["83440.00", "0.000460"]], "checksum": 899845918, "ts": "1742577051661"}], "ts": 1742577051663, "record_time": 1742577051.884733, "EXCHANGE": "BITGET"}
{"action": "update", "arg": {"instType": "SPOT", "channel": "books", "instId": "BTCUSDT"}, "data": [{"asks": [["83962.01", "0.949259"], ["84009.30", "0.008474"], ["84011.30", "0.022298"], ["84011.50", "0"], ["84013.30", "0.058680"], ["84015.30", "0.154421"], ["84017.30", "0.406372"], ["84017.71", "0.001598"], ["84019.30", "1.069400"], ["84021.30", "2.814209"], ["84023.30", "7.405590"], ["84065.30", "4.536161"], ["84073.70", "5.534116"], ["84082.10", "4.717607"], ["84090.50", "4.989777"], ["84098.90", "4.808330"], ["84107.30", "5.352670"], ["84115.70", "5.443393"], ["84124.10", "3.901098"], ["84132.50", "4.263991"], ["84140.90", "4.173268"], ["84149.30", "4.445437"], ["84157.70", "4.626884"], ["84166.10", "5.171223"], ["84174.50", "4.899054"], ["84182.90", "4.082545"], ["84191.30", "3.991821"], ["84199.70", "4.354714"], ["84208.10", "5.261946"], ["84216.50", "5.624839"], ["84224.90", "5.080500"]], "bids": [["83962.00", "0.628781"], ["83956.67", "0.038690"], ["83943.20", "0.943853"], ["83941.20", "2.483822"], ["83939.20", "6.536375"], ["83930.00", "0.120000"], ["83913.11", "0"], ["83903.69", "0.001173"], ["83897.49", "0"], ["83897.20", "3.991821"], ["83888.80", "4.263991"], ["83880.40", "3.901098"], ["83872.00", "4.717607"], ["83863.60", "5.080500"], ["83855.20", "4.445437"], ["83846.80", "5.171223"], ["83838.40", "4.808330"], ["83830.00", "4.626884"], ["83821.60", "4.354714"], ["83813.20", "5.352670"], ["83804.80", "4.899054"], ["83796.40", "5.624839"], ["83788.00", "4.536161"], ["83779.60", "4.082545"], ["83771.20", "5.261946"], ["83762.80", "5.443393"], ["83754.40", "5.534116"], ["83746.00", "4.173268"], ["83737.60", "4.989777"], ["83440.00", "0"]], "checksum": 1583728407, "ts": "1742577051886"}], "ts": 1742577051890, "record_time": 1742577052.083333, "EXCHANGE": "BITGET"}
{"action": "update", "arg": {"instType": "SPOT", "channel": "books", "instId": "BTCUSDT"}, "data": [{"asks": [["83962.01", "0.942058"], ["84000.00", "0.002000"], ["84002.55", "0"], ["84009.30", "0.008524"], ["84010.14", "0"], ["84011.30", "0.022432"], ["84013.30", "0.059031"], ["84015.30", "0.155345"], ["84015.81", "0.001598"], ["84017.30", "0.408804"], ["84019.30", "1.075800"], ["84021.30", "2.831052"], ["84023.30", "7.450137"], ["84030.99", "0.011949"], ["84065.30", "4.354714"], ["84073.70", "5.624839"], ["84082.10", "5.261946"], ["84090.50", "5.443393"], ["84098.90", "4.899054"], ["84107.30", "5.080500"], ["84115.70", "3.901098"], ["84124.10", "4.717607"], ["84132.50", "5.534116"], ["84140.90", "4.445437"], ["84149.30", "4.173268"], ["84157.70", "5.171223"], ["84166.10", "4.808330"], ["84174.50", "4.989777"], ["84182.90", "4.263991"], ["84191.30", "4.626884"], ["84199.70", "4.082545"], ["84208.10", "4.536161"], ["84216.50", "3.991821"], ["84224.90", "5.352670"], ["84342.63", "0"]], "bids": [["83945.20", "0.358733"], ["83943.20", "0.944032"], ["83941.20", "2.484296"], ["83939.20", "6.537621"], ["83938.30", "0.006240"], ["83928.60", "0.012630"], ["83905.66", "0.001177"], ["83899.99", "0"], ["83897.20", "4.354714"], ["83888.80", "4.626884"], ["83872.00", "5.080500"], ["83863.60", "3.991821"], ["83846.80", "4.173268"], ["83838.40", "5.352670"], ["83830.00", "4.808330"], ["83821.60", "5.624839"], ["83813.20", "5.171223"], ["83804.80", "4.263991"], ["83796.40", "4.989777"], ["83788.00", "5.261946"], ["83779.60", "4.536161"], ["83771.20", "4.717607"], ["83746.00", "4.899054"], ["83737.60", "4.082545"], ["83441.56", "0"]], "checksum": -2007464113, "ts": "1742577052091"}], "ts": 1742577052094, "record_time": 1742577052.287865, "EXCHANGE": "BITGET"}
{"action": "update", "arg": {"instType": "SPOT", "channel": "books", "instId": "BTCUSDT"}, "data": [{"asks": [["83962.01", "1.002007"], ["84002.54", "0"], ["84004.33", "0.010000"], ["84015.30", "0.155597"], ["84017.30", "0.409465"], ["84019.30", "1.077540"], ["84021.30", "2.835632"], ["84023.30", "7.462190"], ["84065.29", "0.060864"], ["84065.30", "3.901098"], ["84073.70", "5.080500"], ["84082.10", "4.263991"], ["84090.50", "4.989777"], ["84098.90", "5.352670"], ["84107.30", "4.626884"], ["84115.70", "4.082545"], ["84124.10", "3.991821"], ["84149.30", "5.171223"], ["84157.70", "4.354714"], ["84166.10", "4.717607"], ["84174.50", "5.624839"], ["84182.90", "4.899054"], ["84191.30", "4.808330"], ["84199.70", "5.443393"], ["84208.10", "4.173268"], ["84216.50", "5.261946"], ["84224.90", "4.536161"], ["84342.11", "0"]], "bids": [["83962.00", "0.837981"], ["83956.87", "0.038690"], ["83956.67", "0"], ["83947.46", "0"], ["83938.60", "0.489960"], ["83938.30", "0"], ["83928.60", "0"], ["83910.00", "0.002121"], ["83897.20", "5.534116"], ["83888.80", "5.080500"], ["83880.40", "4.899054"], ["83872.00", "4.989777"], ["83863.60", "4.263991"], ["83846.80", "3.901098"], ["83838.40", "4.536161"], ["83830.00", "5.261946"], ["83821.60", "5.443393"], ["83813.20", "4.082545"], ["83804.80", "4.808330"], ["83796.40", "4.626884"], ["83788.00", "5.352670"], ["83779.60", "4.354714"], ["83771.20", "3.991821"], ["83762.80", "4.173268"], ["83754.40", "5.171223"], ["83746.00", "5.624839"], ["83737.60", "4.717607"], ["83441.56", "0.000024"], ["83440.00", "0.000460"], ["83439.42", "0.000423"]], "checksum": -1398165023, "ts": "1742577052296"}], "ts": 1742577052298, "record_time": 1742577052.492896, "EXCHANGE": "BITGET"}
{"action": "update", "arg": {"instType": "SPOT", "channel": "books", "instId": "BTCUSDT"}, "data": [{"asks": [["83962.01", "1.001894"], ["83993.35", "0"], ["83994.80", "0.010988"], ["84001.13", "0.179909"], ["84005.30", "0.001025"], ["84007.30", "0.002696"], ["84009.30", "0.007096"], ["84011.30", "0.018674"], ["84013.30", "0.049141"], ["84015.30", "0.129320"], ["84017.30", "0.340316"], ["84019.30", "0.895566"], ["84021.30", "2.356754"], ["84023.30", "6.201984"], ["84028.10", "0.022770"], ["84030.00", "0.056550"], ["84030.40", "0"], ["84065.30", "4.989777"], ["84082.10", "5.534116"], ["84090.50", "5.261946"], ["84098.90", "3.901098"], ["84107.30", "4.445437"], ["84115.70", "5.443393"], ["84124.10", "4.808330"], ["84132.50", "4.263991"], ["84140.90", "5.624839"], ["84149.30", "3.991821"], ["84157.70", "4.626884"], ["84166.10", "5.352670"], ["84174.50", "4.536161"], ["84191.30", "4.717607"], ["84199.70", "4.173268"], ["84208.10", "4.354714"], ["84216.50", "4.082545"], ["84224.90", "5.171223"], ["84341.01", "0"]], "bids": [["83959.46", "0.094613"], ["83947.58", "0.006195"], ["83945.20", "0.358744"], ["83943.20", "0.944065"], ["83941.20", "2.484381"], ["83939.20", "6.537844"], ["83938.60", "0.483840"], ["83931.70", "0.120000"], ["83930.00", "0.240000"], ["83928.60", "0.012630"], ["83924.27", "0.056435"], ["83922.83", "0"], ["83897.20", "5.624839"], ["83888.80", "4.354714"], ["83880.40", "4.626884"], ["83872.00", "3.991821"], ["83863.60", "5.261946"], ["83855.20", "3.901098"], ["83846.80", "4.989777"], ["83838.40", "4.808330"], ["83830.00", "5.171223"], ["83821.60", "4.445437"], ["83813.20", "4.899054"], ["83804.80", "4.263991"], ["83796.40", "5.080500"], ["83788.00", "5.443393"], ["83779.60", "4.536161"], ["83771.20", "5.534116"], ["83762.80", "4.717607"], ["83754.40", "4.082545"], ["83746.00", "5.352670"], ["83737.60", "4.173268"], ["83441.56", "0"], ["83440.00", "0"], ["83439.42", "0"]], "checksum": -864409663, "ts": "1742577052519"}], "ts": 1742577052523, "record_time": 1742577052.71734, "EXCHANGE": "BITGET"}
{"action": "update", "arg": {"instType": "SPOT", "channel": "books", "instId": "BTCUSDT"}, "data": [{"asks": [["83980.11", "0.119905"], ["83980.32", "0"], ["83981.28", "0"], ["83981.51", "0.035972"], ["83981.94", "0"], ["83981.98", "0.006357"], ["83982.03", "0"], ["83982.14", "0.006357"], ["83982.54", "0.006357"], ["83982.57", "0.006357"], ["83982.67", "0"], ["83982.69", "0"], ["83983.01", "0.006357"], ["83983.12", "0"], ["83983.35", "0"], ["83983.51", "0.006357"], ["83983.61", "0.010995"], ["83983.68", "0.006356"], ["83983.74", "0.006357"], ["83983.76", "0"], ["83983.84", "0"], ["83983.87", "0"], ["83984.23", "0.016429"], ["83984.29", "0"], ["83984.32", "0"], ["83984.49", "0.006357"], ["83984.52", "0.006357"], ["83984.73", "0"], ["83984.79", "0"], ["83985.00", "0.006357"], ["83985.06", "0.006357"], ["83985.14", "0"], ["83985.17", "0.119901"], ["83985.38", "0.016429"], ["83985.55", "0.006357"], ["83985.69", "0"], ["83986.41", "0.006357"], ["83986.59", "0"], ["83987.07", "0.010993"], ["83987.08", "0.006357"], ["83987.22", "0"], ["83987.76", "0.009990"], ["83987.96", "0"], ["83988.50", "0"], ["83988.67", "0.119850"], ["83989.84", "0.119858"], ["83989.85", "0"], ["83990.06", "0.015895"], ["83990.17", "0"], ["83990.27", "0"], ["83990.37", "0.009989"], ["83992.27", "0.006356"], ["83992.46", "0"], ["84005.12", "0.444907"], ["84007.30", "0.002327"], ["84009.30", "0.006123"], ["84011.30", "0.016113"], ["84013.30", "0.042402"], ["84015.30", "0.111586"], ["84017.30", "0.293646"], ["84019.30", "0.772754"], ["84021.30", "2.033563"], ["84023.30", "5.351480"], ["84065.30", "5.352670"], ["84082.10", "4.717607"], ["84090.50", "4.626884"], ["84107.30", "5.624839"], ["84115.70", "5.261946"], ["84124.10", "5.534116"], ["84132.50", "4.536161"], ["84140.90", "4.989777"], ["84149.30", "4.899054"], ["84157.70", "4.445437"], ["84166.10", "5.443393"], ["84174.50", "4.082545"], ["84182.90", "4.263991"], ["84191.30", "4.808330"], ["84199.70", "3.991821"], ["84208.10", "5.171223"], ["84216.50", "4.173268"], ["84224.90", "4.354714"], ["84341.00", "0"]], "bids": [["83962.00", "1.047181"], ["83956.87", "0"], ["83939.18", "0"], ["83938.97", "0.247414"], ["83938.00", "0.004290"], ["83937.85", "0.083593"], ["83937.62", "0"], ["83937.53", "0"], ["83937.48", "0.017817"], ["83937.17", "0"], ["83937.03", "0.005946"], ["83936.51", "0"], ["83936.49", "0.016424"], ["83936.39", "0.015742"], ["83936.07", "0"], ["83935.99", "0.006568"], ["83935.93", "0.055608"], ["83935.83", "0"], ["83935.68", "0"], ["83935.49", "0.017115"], ["83935.31", "0"], ["83935.21", "0.007137"], ["83934.96", "0.007343"], ["83934.86", "0"], ["83934.79", "0"], ["83934.76", "0"], ["83934.69", "0.028860"], ["83934.65", "0.017106"], ["83934.59", "0"], ["83934.52", "0.007951"], ["83934.45", "0.009005"], ["83934.25", "0"], ["83934.17", "0"], ["83934.16", "0.025185"], ["83934.14", "0"], ["83933.96", "0.224931"], ["83933.03", "0"], ["83932.85", "0.008285"], ["83932.64", "0"], ["83932.50", "0.064487"], ["83931.51", "0.018539"], ["83930.57", "0.268701"], ["83930.40", "0"], ["83929.74", "0"], ["83929.73", "0.222938"], ["83929.32", "0"], ["83929.10", "0.076204"], ["83929.08", "0.021155"], ["83928.88", "0"], ["83928.60", "0"], ["83927.14", "0"], ["83926.95", "0.012454"], ["83904.42", "0"], ["83904.22", "0.003601"], ["83897.20", "5.261946"], ["83888.80", "4.536161"], ["83880.40", "3.901098"], ["83872.00", "4.989777"], ["83863.60", "4.263991"], ["83855.20", "4.082545"], ["83846.80", "4.808330"], ["83838.40", "4.354714"], ["83830.00", "4.899054"], ["83821.60", "4.626884"], ["83813.20", "3.991821"], ["83804.80", "4.717607"], ["83796.40", "5.624839"], ["83788.00", "5.534116"], ["83779.60", "5.080500"], ["83771.20", "5.171223"], ["83762.80", "4.173268"], ["83754.40", "5.443393"], ["83746.00", "4.445437"], ["83737.60", "5.352670"]], "checksum": 1115761368, "ts": "1742577052719"}], "ts": 1742577052723, "record_time": 1742577052.919496, "EXCHANGE": "BITGET"}
{"action": "update", "arg": {"instType": "SPOT", "channel": "books", "instId": "BTCUSDT"}, "data": [{"asks": [["83962.01", "0.961781"], ["83979.78", "0"], ["83979.93", "0.035971"], ["83980.10", "0.056299"], ["83980.31", "0"], ["83985.34", "0"], ["83985.50", "0.006357"], ["83989.80", "0"], ["83989.96", "0.119905"], ["83994.03", "0"], ["83994.19", "0.015896"], ["84005.30", "0.001296"], ["84007.30", "0.003412"], ["84009.30", "0.008978"], ["84011.30", "0.023628"], ["84013.30", "0.062179"], ["84015.30", "0.163629"], ["84017.30", "0.430601"], ["84019.30", "1.133162"], ["84021.30", "2.982003"], ["84023.30", "7.847377"], ["84025.00", "0.035700"], ["84030.00", "0.078000"], ["84031.10", "2.763720"], ["84033.00", "0"], ["84037.00", "0"], ["84043.71", "0"], ["84049.41", "0.000179"], ["84065.30", "4.989777"], ["84073.70", "5.443393"], ["84082.10", "5.261946"], ["84090.50", "4.263991"], ["84098.90", "4.445437"], ["84107.30", "5.534116"], ["84115.70", "5.080500"], ["84124.10", "3.901098"], ["84132.50", "5.352670"], ["84140.90", "4.536161"], ["84149.30", "5.171223"], ["84157.70", "4.626884"], ["84166.10", "4.717607"], ["84174.50", "4.899054"], ["84182.90", "4.354714"], ["84191.30", "4.082545"], ["84199.70", "4.808330"], ["84208.10", "5.624839"], ["84224.90", "3.991821"], ["84341.00", "0.002997"]], "bids": [["83962.00", "0.581181"], ["83959.46", "0"], ["83957.59", "0"], ["83957.06", "0.038690"], ["83955.20", "0.002546"], ["83953.20", "0.006701"], ["83951.20", "0.017635"], ["83949.20", "0.046406"], ["83947.20", "0.122122"], ["83945.20", "0.321375"], ["83944.30", "0.204856"], ["83943.20", "0.845723"], ["83941.20", "2.225586"], ["83939.63", "0.089626"], ["83939.48", "0"], ["83939.20", "5.856805"], ["83938.80", "0.052050"], ["83937.50", "0"], ["83937.31", "0.018263"], ["83937.14", "0"], ["83935.00", "0"], ["83933.95", "0.008196"], ["83933.79", "0"], ["83931.20", "1.146600"], ["83930.80", "0.865470"], ["83930.50", "0"], ["83929.51", "0.259076"], ["83929.34", "0"], ["83929.30", "0"], ["83928.60", "0.057630"], ["83925.35", "0.073148"], ["83925.17", "0"], ["83922.95", "0.000878"], ["83922.74", "0"], ["83912.00", "0.000281"], ["83908.10", "0"], ["83897.20", "4.354714"], ["83888.80", "4.082545"], ["83880.51", "0.000172"], ["83880.40", "5.080500"], ["83874.82", "0"], ["83872.00", "5.352670"], ["83863.60", "4.173268"], ["83855.20", "4.445437"], ["83846.80", "4.626884"], ["83838.40", "5.443393"], ["83830.00", "4.717607"], ["83821.60", "3.991821"], ["83813.20", "5.261946"], ["83804.80", "4.899054"], ["83796.40", "4.808330"], ["83788.00", "4.536161"], ["83779.60", "5.171223"], ["83771.20", "3.901098"], ["83762.80", "5.624839"], ["83754.40", "4.263991"], ["83746.00", "4.989777"], ["83737.60", "5.534116"], ["83441.56", "0.000024"], ["83440.00", "0.000460"], ["83439.42", "0.000423"]], "checksum": -1945588345, "ts": "1742577052924"}], "ts": 1742577052926, "record_time": 1742577053.134466, "EXCHANGE": "BITGET"}
{"action": "update", "arg": {"instType": "SPOT", "channel": "books", "instId": "BTCUSDT"}, "data": [{"asks": [["83962.01", "1.053186"], ["83970.31", "0.013838"], ["83996.38", "0"], ["84005.30", "0.001422"], ["84007.30", "0.003744"], ["84009.30", "0.009851"], ["84011.30", "0.025924"], ["84013.30", "0.068221"], ["84015.30", "0.179530"], ["84017.30", "0.472447"], ["84019.30", "1.243281"], ["84021.30", "3.271791"], ["84023.30", "8.609977"], ["84030.60", "0.073230"], ["84031.00", "2.124510"], ["84036.30", "0"], ["84036.50", "0"], ["84065.30", "5.261946"], ["84073.70", "5.352670"], ["84082.10", "4.989777"], ["84090.50", "5.534116"], ["84098.90", "4.536161"], ["84107.30", "4.808330"], ["84115.70", "4.263991"], ["84124.10", "5.171223"], ["84132.50", "3.991821"], ["84140.90", "4.626884"], ["84149.30", "4.717607"], ["84157.70", "4.082545"], ["84166.10", "4.899054"], ["84174.50", "4.445437"], ["84182.90", "5.080500"], ["84191.30", "4.354714"], ["84199.70", "3.901098"], ["84208.10", "4.173268"], ["84216.50", "5.624839"], ["84224.90", "5.443393"], ["84341.01", "0.000008"]], "bids": [["83962.00", "0.046981"], ["83957.58", "0"], ["83955.20", "0.002430"], ["83954.36", "0"], ["83953.20", "0.006397"], ["83951.20", "0.016832"], ["83949.20", "0.044297"], ["83947.20", "0.116569"], ["83945.20", "0.306761"], ["83943.20", "0.807267"], ["83941.37", "0.013838"], ["83941.20", "2.124387"], ["83940.15", "0.830810"], ["83939.20", "5.590490"], ["83938.80", "0.235350"], ["83937.20", "0.052050"], ["83936.60", "0.071070"], ["83935.30", "0.234330"], ["83935.00", "0.015000"], ["83929.90", "0"], ["83928.60", "0"], ["83897.20", "5.261946"], ["83888.80", "4.173268"], ["83880.40", "3.901098"], ["83872.00", "5.171223"], ["83863.60", "4.626884"], ["83855.20", "5.352670"], ["83846.80", "4.989777"], ["83838.40", "4.445437"], ["83830.00", "4.263991"], ["83821.60", "4.808330"], ["83813.20", "5.624839"], ["83804.80", "4.354714"], ["83796.40", "4.717607"], ["83788.00", "3.991821"], ["83779.60", "5.534116"], ["83771.20", "4.536161"], ["83762.80", "5.080500"], ["83754.40", "5.443393"], ["83746.00", "4.082545"], ["83737.60", "4.899054"], ["83439.33", "0.000010"]], "checksum": 393476749, "ts": "1742577053129"}], "ts": 1742577053132, "record_time": 1742577053.334278, "EXCHANGE": "BITGET"}
{"action": "update", "arg": {"instType": "SPOT", "channel": "books", "instId": "BTCUSDT"}, "data": [{"asks": [["83970.31", "0"], ["83974.60", "0.013838"], ["84003.30", "0.001499"], ["84005.30", "0.002445"], ["84007.30", "0.006631"], ["84009.30", "0.017450"], ["84011.30", "0.045920"], ["84013.30", "0.120844"], ["84015.30", "0.318009"], ["84017.30", "0.836866"], ["84019.30", "2.202279"], ["84021.30", "5.795470"], ["84023.30", "15.251237"], ["84023.40", "0.511860"], ["84026.20", "2.358690"], ["84027.10", "0.069690"], ["84028.90", "0.467700"], ["84030.30", "0.279570"], ["84031.00", "1.200270"], ["84031.10", "0.405150"], ["84031.30", "0.269760"], ["84032.00", "0.246300"], ["84032.10", "0.228000"], ["84033.20", "0"], ["84034.60", "0.196628"], ["84034.70", "0"], ["84034.80", "0"], ["84035.40", "0.180000"], ["84036.00", "0.042300"], ["84036.20", "0.204000"], ["84036.30", "0.288240"], ["84065.30", "5.443393"], ["84073.70", "4.082545"], ["84082.10", "5.171223"], ["84090.50", "5.080500"], ["84098.90", "3.991821"], ["84107.30", "5.261946"], ["84115.70", "3.901098"], ["84124.10", "4.899054"], ["84132.50", "4.445437"], ["84140.90", "4.536161"], ["84149.30", "5.534116"], ["84157.70", "4.717607"], ["84166.10", "4.354714"], ["84174.50", "4.173268"], ["84182.90", "4.626884"], ["84191.30", "4.989777"], ["84199.70", "4.808330"], ["84208.10", "5.624839"], ["84216.50", "4.263991"], ["84224.90", "5.352670"], ["84340.46", "0"], ["84340.72", "0"], ["84341.00", "0"], ["84341.01", "0"]], "bids": [["83957.23", "0.038690"], ["83957.06", "0"], ["83955.20", "0.001276"], ["83953.42", "0"], ["83953.20", "0.003238"], ["83952.58", "0.114057"], ["83951.21", "0.009289"], ["83951.20", "0.008522"], ["83949.20", "0.022426"], ["83947.20", "0.059017"], ["83945.20", "0.155308"], ["83943.20", "0.408704"], ["83941.20", "1.075538"], ["83940.15", "0"], ["83939.20", "2.830492"], ["83939.10", "0.222360"], ["83938.80", "0"], ["83938.60", "0"], ["83937.20", "0"], ["83936.60", "0"], ["83936.40", "0.089490"], ["83935.70", "0.120210"], ["83935.60", "0.240600"], ["83935.30", "0.073410"], ["83935.00", "0.075000"], ["83934.60", "0.831210"], ["83933.70", "0"], ["83933.60", "0"], ["83932.90", "0.066360"], ["83932.80", "0"], ["83932.40", "0.065970"], ["83931.60", "0.160920"], ["83929.90", "0.120000"], ["83928.60", "0.012630"], ["83917.57", "0"], ["83888.80", "3.901098"], ["83880.40", "5.624839"], ["83872.00", "4.626884"], ["83863.60", "4.808330"], ["83855.20", "4.354714"], ["83846.80", "4.082545"], ["83830.00", "5.171223"], ["83821.60", "4.989777"], ["83813.20", "4.173268"], ["83804.80", "4.263991"], ["83796.40", "5.352670"], ["83779.60", "4.899054"], ["83762.80", "5.534116"], ["83754.40", "4.717607"], ["83746.00", "5.443393"], ["83737.60", "5.080500"], ["83437.50", "0.000009"]], "checksum": -1632584768, "ts": "1742577053344"}], "ts": 1742577053347, "record_time": 1742577053.541789, "EXCHANGE": "BITGET"}
{"action": "update", "arg": {"instType": "SPOT", "channel": "books", "instId": "BTCUSDT"}, "data": [{"asks": [["83962.01", "0.975733"], ["84015.30", "0.318110"], ["84017.30", "0.837130"], ["84019.30", "2.202974"], ["84021.30", "5.797301"], ["84023.30", "15.256055"], ["84029.80", "0.204000"], ["84031.00", "1.532850"], ["84033.10", "0.192000"], ["84034.80", "0.156000"], ["84034.90", "0.216000"], ["84035.90", "0"], ["84036.00", "0"], ["84036.20", "0"], ["84036.30", "0"], ["84065.30", "4.445437"], ["84073.70", "5.352670"], ["84082.10", "5.261946"], ["84090.50", "3.991821"], ["84098.90", "4.173268"], ["84107.30", "4.989777"], ["84115.70", "4.626884"], ["84124.10", "5.534116"], ["84132.50", "5.443393"], ["84140.90", "4.263991"], ["84149.30", "4.536161"], ["84166.10", "5.624839"], ["84174.50", "4.354714"], ["84182.90", "4.899054"], ["84191.30", "5.171223"], ["84199.70", "4.082545"], ["84208.10", "3.901098"], ["84216.50", "4.808330"], ["84224.90", "5.080500"]], "bids": [["83951.21", "0.006796"], ["83943.21", "0.103494"], ["83941.20", "1.075686"], ["83939.21", "0.832899"], ["83939.20", "2.830753"], ["83935.70", "0.512430"], ["83935.60", "0.240390"], ["83935.50", "0.912840"], ["83934.60", "0"], ["83928.60", "0.057630"], ["83909.00", "0"], ["83897.20", "5.080500"], ["83888.80", "3.991821"], ["83880.40", "4.989777"], ["83872.00", "4.082545"], ["83863.60", "5.624839"], ["83855.20", "3.901098"], ["83846.80", "4.173268"], ["83838.40", "4.808330"], ["83830.00", "5.352670"], ["83821.60", "5.534116"], ["83813.20", "4.717607"], ["83804.80", "4.354714"], ["83796.40", "4.263991"], ["83788.00", "4.626884"], ["83771.20", "5.171223"], ["83762.80", "4.445437"], ["83754.40", "5.261946"], ["83737.60", "4.536161"]], "checksum": -171738344, "ts": "1742577053544"}], "ts": 1742577053550, "record_time": 1742577053.754509, "EXCHANGE": "BITGET"}
{"action": "update", "arg": {"instType": "SPOT", "channel": "books", "instId": "BTCUSDT"}, "data": [{"asks": [["84001.12", "0.054422"], ["84013.30", "0.120994"], ["84015.30", "0.318406"], ["84017.30", "0.837910"], ["84019.30", "2.205026"], ["84021.30", "5.802701"], ["84023.30", "15.270265"], ["84034.00", "0.829680"], ["84065.30", "4.808330"], ["84073.70", "5.624839"], ["84082.10", "3.901098"], ["84090.50", "4.082545"], ["84098.90", "4.717607"], ["84107.30", "4.354714"], ["84115.70", "5.443393"], ["84124.10", "5.080500"], ["84132.50", "5.171223"], ["84140.90", "3.991821"], ["84149.30", "5.261946"], ["84157.70", "4.626884"], ["84166.10", "5.534116"], ["84174.50", "4.989777"], ["84182.90", "4.173268"], ["84191.30", "4.899054"], ["84199.70", "4.445437"], ["84208.10", "4.263991"], ["84216.50", "4.536161"], ["84224.90", "5.352670"], ["84340.00", "0"]], "bids": [["83952.59", "0.041013"], ["83951.21", "0"], ["83945.20", "0.155145"], ["83943.20", "0.408277"], ["83941.20", "1.074414"], ["83939.20", "2.827405"], ["83937.10", "1.058610"], ["83936.20", "0.361830"], ["83935.70", "0.511800"], ["83935.50", "0"], ["83897.20", "4.445437"], ["83888.80", "5.443393"], ["83880.40", "4.536161"], ["83872.00", "4.626884"], ["83855.20", "4.354714"], ["83846.80", "4.808330"], ["83838.40", "5.261946"], ["83830.00", "5.171223"], ["83821.60", "4.717607"], ["83813.20", "3.901098"], ["83804.80", "4.173268"], ["83796.40", "4.899054"], ["83788.00", "5.080500"], ["83779.60", "4.082545"], ["83771.20", "3.991821"], ["83762.80", "4.263991"], ["83754.40", "5.352670"], ["83746.00", "5.534116"], ["83737.60", "4.989777"], ["83437.50", "0"]], "checksum": -251958083, "ts": "1742577053749"}], "ts": 1742577053753, "record_time": 1742577053.946207, "EXCHANGE": "BITGET"}
{"action": "update", "arg": {"instType": "SPOT", "channel": "books", "instId": "BTCUSDT"}, "data": [{"asks": [["84026.19", "0.005527"], ["84026.20", "0"], ["84028.50", "2.358630"], ["84065.30", "4.263991"], ["84073.70", "4.626884"], ["84082.10", "4.536161"], ["84090.50", "3.991821"], ["84098.90", "5.534116"], ["84115.70", "4.989777"], ["84124.10", "4.808330"], ["84132.50", "5.352670"], ["84140.90", "5.171223"], ["84149.30", "5.443393"], ["84157.70", "4.173268"], ["84166.10", "3.901098"], ["84174.50", "4.082545"], ["84182.90", "5.624839"], ["84191.30", "5.080500"], ["84199.70", "4.899054"], ["84208.10", "4.717607"], ["84216.50", "5.261946"], ["84224.90", "4.445437"], ["84339.62", "0"]], "bids": [["83957.39", "0.038690"], ["83957.23", "0"], ["83952.58", "0"], ["83951.92", "0.010000"], ["83943.21", "0.437884"], ["83932.90", "0.134760"], ["83897.20", "5.171223"], ["83888.80", "4.445437"], ["83880.40", "5.352670"], ["83872.00", "4.263991"], ["83863.60", "4.989777"], ["83855.20", "4.899054"], ["83838.40", "3.901098"], ["83830.00", "4.717607"], ["83821.60", "4.173268"], ["83813.20", "5.261946"], ["83804.80", "4.082545"], ["83796.40", "5.624839"], ["83788.00", "5.534116"], ["83779.60", "4.536161"], ["83771.20", "5.080500"], ["83762.80", "4.354714"], ["83754.40", "3.991821"], ["83746.00", "4.626884"], ["83737.60", "5.443393"]], "checksum": 1508837197, "ts": "1742577053958"}], "ts": 1742577053963, "record_time": 1742577054.159105, "EXCHANGE": "BITGET"}
{"action": "update", "arg": {"instType": "SPOT", "channel": "books", "instId": "BTCUSDT"}, "data": [{"asks": [["84009.30", "0.017557"], ["84011.30", "0.046202"], ["84013.30", "0.121584"], ["84015.30", "0.319957"], ["84017.30", "0.841992"], ["84019.30", "2.215770"], ["84021.30", "5.830973"], ["84023.30", "15.344665"], ["84065.30", "4.626884"], ["84073.70", "3.901098"], ["84082.10", "4.717607"], ["84090.50", "5.443393"], ["84098.90", "4.899054"], ["84107.30", "4.536161"], ["84115.70", "5.624839"], ["84124.10", "3.991821"], ["84132.50", "4.263991"], ["84140.90", "4.989777"], ["84149.30", "5.261946"], ["84166.10", "5.171223"], ["84174.50", "4.354714"], ["84182.90", "4.445437"], ["84191.30", "5.534116"], ["84199.70", "4.082545"], ["84208.10", "4.808330"], ["84216.50", "5.080500"], ["84224.90", "5.352670"]], "bids": [["83952.59", "0.009796"], ["83951.57", "0.114056"], ["83910.00", "0.002281"], ["83897.20", "3.901098"], ["83888.80", "4.536161"], ["83880.40", "5.443393"], ["83872.00", "5.261946"], ["83863.60", "5.624839"], ["83855.20", "4.082545"], ["83846.80", "4.989777"], ["83838.40", "5.534116"], ["83821.60", "5.080500"], ["83813.20", "4.899054"], ["83804.80", "3.991821"], ["83796.40", "5.352670"], ["83788.00", "4.173268"], ["83779.60", "4.263991"], ["83771.20", "4.626884"], ["83762.80", "5.171223"], ["83754.40", "4.354714"], ["83746.00", "4.445437"], ["83737.60", "4.808330"], ["83439.33", "0"]], "checksum": -344115108, "ts": "1742577054161"}], "ts": 1742577054165, "record_time": 1742577054.358903, "EXCHANGE": "BITGET"}
{"action": "update", "arg": {"instType": "SPOT", "channel": "books", "instId": "BTCUSDT"}, "data": [{"asks": [["83962.01", "0.960419"], ["84004.33", "0"], ["84025.70", "0.022680"], ["84028.10", "0"], ["84052.00", "0.003365"], ["84065.30", "5.443393"], ["84073.70", "5.624839"], ["84082.10", "5.080500"], ["84090.50", "3.901098"], ["84098.90", "4.082545"], ["84107.30", "4.717607"], ["84115.70", "5.352670"], ["84124.10", "4.808330"], ["84132.50", "4.173268"], ["84149.30", "5.534116"], ["84157.70", "4.899054"], ["84166.10", "4.263991"], ["84174.50", "5.171223"], ["84182.90", "4.536161"], ["84191.30", "3.991821"], ["84199.70", "5.261946"], ["84208.10", "4.626884"], ["84216.50", "4.445437"], ["84224.90", "4.354714"]], "bids": [["83957.39", "0"], ["83952.59", "0.042789"], ["83897.20", "4.808330"], ["83888.80", "4.717607"], ["83880.40", "5.171223"], ["83872.00", "5.624839"], ["83863.60", "4.899054"], ["83855.20", "4.626884"], ["83846.80", "5.534116"], ["83838.40", "5.261946"], ["83830.00", "4.082545"], ["83821.60", "4.445437"], ["83813.20", "3.991821"], ["83804.80", "3.901098"], ["83796.40", "4.536161"], ["83779.60", "5.080500"], ["83771.20", "4.989777"], ["83762.80", "5.352670"], ["83754.40", "5.443393"], ["83746.00", "4.354714"], ["83737.60", "4.263991"], ["83439.33", "0.000010"]], "checksum": 1643261602, "ts": "1742577054369"}], "ts": 1742577054372, "record_time": 1742577054.565737, "EXCHANGE": "BITGET"}
{"action": "update", "arg": {"instType": "SPOT", "channel": "books", "instId": "BTCUSDT"}, "data": [{"asks": [["83974.60", "0"], ["84001.13", "0"], ["84013.30", "0.121764"], ["84015.30", "0.320433"], ["84017.30", "0.843244"], ["84019.30", "2.219062"], ["84021.30", "5.839638"], ["84023.30", "15.367469"], ["84065.30", "5.624839"], ["84073.70", "3.901098"], ["84082.10", "4.173268"], ["84090.50", "4.989777"], ["84098.90", "4.808330"], ["84107.30", "5.080500"], ["84115.70", "4.354714"], ["84124.10", "4.445437"], ["84132.50", "5.534116"], ["84140.90", "4.899054"], ["84149.30", "3.991821"], ["84157.70", "4.082545"], ["84160.37", "0"], ["84166.10", "4.626884"], ["84174.50", "5.443393"], ["84182.90", "4.263991"], ["84191.30", "5.352670"], ["84199.70", "4.536161"], ["84208.10", "4.717607"], ["84216.50", "5.261946"], ["84224.90", "5.171223"], ["84339.62", "0.000051"], ["84340.00", "0.019520"], ["84340.46", "0.000143"]], "bids": [["83962.00", "0.581181"], ["83957.55", "0.038690"], ["83939.21", "1.242807"], ["83939.20", "2.827274"], ["83897.20", "4.989777"], ["83888.80", "4.354714"], ["83880.40", "5.352670"], ["83872.00", "5.261946"], ["83863.60", "5.171223"], ["83855.20", "4.808330"], ["83846.80", "4.626884"], ["83838.40", "4.717607"], ["83830.00", "3.901098"], ["83821.60", "4.173268"], ["83813.20", "5.443393"], ["83804.80", "4.082545"], ["83788.00", "4.899054"], ["83771.20", "4.445437"], ["83762.80", "5.534116"], ["83754.40", "3.991821"], ["83746.00", "5.624839"], ["83439.33", "0"]], "checksum": 1481965169, "ts": "1742577054571"}], "ts": 1742577054573, "record_time": 1742577054.766251, "EXCHANGE": "BITGET"}
{"action": "update", "arg": {"instType": "SPOT", "channel": "books", "instId": "BTCUSDT"}, "data": [{"asks": [["83962.01", "1.088707"], ["83984.82", "0.013838"], ["84001.12", "0"], ["84003.30", "0.001311"], ["84005.30", "0.002138"], ["84007.30", "0.005627"], ["84009.30", "0.014807"], ["84011.30", "0.038967"], ["84013.30", "0.102546"], ["84015.30", "0.269857"], ["84017.30", "0.710150"], ["84019.30", "1.868816"], ["84021.30", "4.917935"], ["84023.30", "12.941936"], ["84023.40", "0.411480"], ["84024.00", "0.042690"], ["84026.50", "0.099660"], ["84027.10", "0.069510"], ["84028.50", "0"], ["84030.60", "4.084590"], ["84031.00", "0.536970"], ["84031.30", "0"], ["84033.20", "0.027660"], ["84035.40", "0"], ["84065.29", "0"], ["84065.30", "5.261946"], ["84073.70", "4.899054"], ["84082.10", "5.534116"], ["84090.50", "3.991821"], ["84098.90", "4.626884"], ["84107.30", "4.082545"], ["84115.70", "3.901098"], ["84124.10", "5.624839"], ["84132.50", "4.808330"], ["84140.90", "4.536161"], ["84149.30", "4.173268"], ["84157.70", "4.263991"], ["84166.10", "4.717607"], ["84174.50", "5.080500"], ["84182.90", "5.352670"], ["84191.30", "4.989777"], ["84199.70", "5.443393"], ["84208.10", "4.354714"], ["84216.50", "5.171223"], ["84224.90", "4.445437"], ["84340.72", "0.000066"], ["84341.00", "0.002997"]], "bids": [["83962.00", "0.561181"], ["83953.20", "0.003491"], ["83951.20", "0.009185"], ["83949.20", "0.024171"], ["83947.20", "0.063608"], ["83945.20", "0.167390"], ["83943.20", "0.440499"], ["83941.20", "1.159208"], ["83939.20", "3.050549"], ["83938.50", "1.049340"], ["83938.40", "0.099630"], ["83938.20", "0.397470"], ["83938.00", "0.236610"], ["83937.10", "0"], ["83936.44", "0.270089"], ["83936.40", "0.089280"], ["83936.20", "0.361620"], ["83935.70", "0.120000"], ["83934.90", "0.072420"], ["83932.40", "0"], ["83912.00", "0.000121"], ["83897.20", "5.080500"], ["83888.80", "5.534116"], ["83880.40", "4.717607"], ["83872.00", "4.989777"], ["83855.20", "5.624839"], ["83846.80", "5.352670"], ["83838.40", "4.626884"], ["83830.00", "4.899054"], ["83821.60", "4.082545"], ["83813.20", "3.901098"], ["83804.80", "5.443393"], ["83788.00", "5.261946"], ["83779.60", "3.991821"], ["83771.20", "4.354714"], ["83762.80", "4.808330"], ["83754.40", "4.173268"], ["83746.00", "4.445437"], ["83441.56", "0"], ["83440.00", "0"], ["83439.42", "0"]], "checksum": -2038398649, "ts": "1742577054772"}], "ts": 1742577054777, "record_time": 1742577055.000224, "EXCHANGE": "BITGET"}
{"action": "update", "arg": {"instType": "SPOT", "channel": "books", "instId": "BTCUSDT"}, "data": [{"asks": [["83962.01", "1.048471"], ["83996.74", "0.187139"], ["84065.30", "5.624839"], ["84073.70", "4.717607"], ["84082.10", "5.443393"], ["84090.50", "5.534116"], ["84098.90", "4.536161"], ["84107.30", "5.352670"], ["84115.70", "4.263991"], ["84124.10", "4.445437"], ["84132.50", "4.626884"], ["84140.90", "4.354714"], ["84155.80", "0.167113"], ["84157.70", "3.991821"], ["84166.10", "5.080500"], ["84174.50", "4.808330"], ["84182.90", "4.989777"], ["84191.30", "4.082545"], ["84199.70", "4.899054"], ["84208.10", "5.171223"], ["84216.50", "3.901098"], ["84224.90", "5.261946"], ["84340.72", "0"], ["84341.00", "0"]], "bids": [["83957.73", "0.038690"], ["83957.55", "0"], ["83928.60", "0.012630"], ["83897.20", "4.263991"], ["83888.80", "5.624839"], ["83880.40", "4.808330"], ["83872.00", "5.443393"], ["83863.60", "5.261946"], ["83855.20", "5.080500"], ["83846.80", "4.717607"], ["83838.40", "4.989777"], ["83830.00", "3.991821"], ["83821.60", "5.171223"], ["83813.20", "4.536161"], ["83804.80", "5.352670"], ["83796.40", "5.534116"], ["83788.00", "4.899054"], ["83779.60", "3.901098"], ["83771.20", "4.173268"], ["83762.80", "4.626884"], ["83754.40", "4.082545"], ["83737.60", "4.354714"]], "checksum": 204686441, "ts": "1742577054973"}], "ts": 1742577054977, "record_time": 1742577055.17148, "EXCHANGE": "BITGET"}
{"action": "update", "arg": {"instType": "SPOT", "channel": "books", "instId": "BTCUSDT"}, "data": [{"asks": [["83996.73", "0.151048"], ["83996.85", "0"], ["84065.30", "5.534116"], ["84073.70", "4.082545"], ["84082.10", "4.899054"], ["84090.50", "3.991821"], ["84098.90", "4.808330"], ["84107.30", "5.080500"], ["84115.70", "5.352670"], ["84124.10", "5.443393"], ["84132.50", "5.261946"], ["84140.90", "4.536161"], ["84149.30", "4.626884"], ["84157.70", "5.624839"], ["84166.10", "4.354714"], ["84174.50", "4.989777"], ["84182.90", "4.173268"], ["84191.30", "4.445437"], ["84199.70", "5.171223"], ["84208.10", "4.263991"], ["84216.50", "4.717607"], ["84224.90", "3.901098"]], "bids": [["83939.20", "3.050698"], ["83935.00", "0.060000"], ["83928.60", "0.057630"], ["83897.20", "5.443393"], ["83888.80", "3.991821"], ["83880.40", "4.626884"], ["83872.00", "3.901098"], ["83863.60", "5.171223"], ["83855.20", "4.899054"], ["83846.80", "5.624839"], ["83838.40", "4.536161"], ["83830.00", "4.717607"], ["83821.60", "4.173268"], ["83813.20", "4.263991"], ["83804.80", "5.080500"], ["83796.40", "4.989777"], ["83788.00", "5.352670"], ["83779.60", "5.534116"], ["83771.20", "4.445437"], ["83762.80", "4.082545"], ["83754.40", "5.261946"], ["83746.00", "4.354714"], ["83737.60", "4.808330"]], "checksum": 204686441, "ts": "1742577055174"}], "ts": 1742577055177, "record_time": 1742577055.370383, "EXCHANGE": "BITGET"}
{"action": "update", "arg": {"instType": "SPOT", "channel": "books", "instId": "BTCUSDT"}, "data": [{"asks": [["84003.30", "0.001477"], ["84005.30", "0.002410"], ["84007.30", "0.006343"], ["84009.30", "0.016692"], ["84011.30", "0.043925"], ["84013.30", "0.115592"], ["84015.30", "0.304190"], ["84017.30", "0.800499"], ["84019.30", "2.106577"], ["84021.30", "5.543623"], ["84023.30", "14.588482"], ["84028.70", "2.358630"], ["84030.60", "1.018470"], ["84065.30", "4.899054"], ["84073.70", "4.808330"], ["84082.10", "4.173268"], ["84090.50", "4.445437"], ["84098.90", "5.534116"], ["84115.70", "4.989777"], ["84124.10", "4.626884"], ["84132.50", "4.354714"], ["84149.30", "5.171223"], ["84157.70", "4.082545"], ["84166.10", "4.717607"], ["84174.50", "5.261946"], ["84182.90", "3.901098"], ["84191.30", "5.624839"], ["84199.70", "3.991821"], ["84208.10", "5.352670"], ["84216.50", "5.443393"], ["84224.90", "4.263991"], ["84340.46", "0"]], "bids": [["83957.73", "0"], ["83953.20", "0.003235"], ["83951.20", "0.008513"], ["83949.20", "0.022403"], ["83947.20", "0.058956"], ["83945.20", "0.155146"], ["83943.20", "0.408280"], ["83941.20", "1.074421"], ["83939.20", "2.827237"], ["83938.50", "0"], ["83938.40", "0"], ["83938.20", "0"], ["83938.00", "0.236820"], ["83936.40", "0.089490"], ["83936.20", "0.361830"], ["83931.60", "0.187800"], ["83909.00", "0.000160"], ["83897.20", "3.901098"], ["83888.80", "5.171223"], ["83880.40", "4.989777"], ["83872.00", "5.443393"], ["83863.60", "5.261946"], ["83855.20", "4.354714"], ["83846.80", "5.352670"], ["83838.40", "4.626884"], ["83821.60", "4.445437"], ["83813.20", "5.080500"], ["83804.80", "4.082545"], ["83796.40", "5.534116"], ["83788.00", "3.991821"], ["83779.60", "5.624839"], ["83771.20", "4.899054"], ["83762.80", "4.173268"], ["83754.40", "4.263991"], ["83746.00", "4.808330"], ["83737.60", "4.536161"], ["83441.56", "0.000024"], ["83440.00", "0.000460"], ["83439.42", "0.000423"]], "checksum": 627869561, "ts": "1742577055379"}], "ts": 1742577055383, "record_time": 1742577055.575968, "EXCHANGE": "BITGET"}
