{"action": "update", "arg": {"instType": "SPOT", "channel": "books", "instId": "BTCUSDT"}, "data": [{"asks": [["84086.38", "0.182388"], ["84088.47", "0"], ["84093.10", "0.010000"], ["84126.09", "0.041849"], ["84160.20", "5.256011"], ["84168.70", "5.165390"], ["84177.20", "3.896698"], ["84185.70", "5.074769"], ["84194.20", "3.987319"], ["84211.20", "4.077939"], ["84219.70", "4.893527"], ["84228.20", "4.984148"], ["84236.70", "4.259181"], ["84245.20", "4.712286"], ["84253.70", "4.168560"], ["84262.20", "4.531044"], ["84270.70", "4.349802"], ["84279.20", "5.618494"], ["84287.70", "5.527873"], ["84296.20", "4.621665"], ["84304.70", "5.346632"], ["84313.20", "4.802906"], ["84321.70", "4.440423"], ["84536.36", "0"], ["84537.04", "0"]], "bids": [["84054.00", "0.010000"], ["84053.85", "0"], ["84048.56", "0"], ["84003.00", "0.000017"], ["83992.00", "4.893527"], ["83983.50", "4.349802"], ["83966.50", "3.987319"], ["83958.00", "4.259181"], ["83949.50", "4.802906"], ["83941.00", "5.437252"], ["83932.50", "4.077939"], ["83924.00", "4.531044"], ["83915.50", "5.527873"], ["83907.00", "5.165390"], ["83898.50", "5.346632"], ["83890.00", "4.168560"], ["83881.50", "5.618494"], ["83873.00", "4.984148"], ["83864.50", "3.896698"], ["83856.00", "4.621665"], ["83847.50", "4.440423"], ["83839.00", "4.712286"], ["83830.50", "5.074769"], ["83651.65", "0.000018"], ["83651.16", "0.000896"]], "checksum": -2024207132, "ts": "1742555178212"}], "ts": 1742555178214, "record_time": 1742555178.237664, "EXCHANGE": "BITGET"}
{"action": "update", "arg": {"instType": "SPOT", "channel": "books", "instId": "BTCUSDT"}, "data": [{"asks": [["84102.20", "0.006708"], ["84104.20", "0.017651"], ["84106.20", "0.046451"], ["84108.20", "0.122239"], ["84110.20", "0.321681"], ["84112.20", "0.846530"], ["84114.20", "2.227711"], ["84116.20", "5.862397"], ["84118.20", "15.427361"], ["84160.20", "4.440423"], ["84168.70", "4.984148"], ["84177.20", "4.259181"], ["84185.70", "5.256011"], ["84194.20", "4.802906"], ["84202.70", "5.074769"], ["84211.20", "5.165390"], ["84219.70", "5.346632"], ["84228.20", "4.531044"], ["84236.70", "4.621665"], ["84245.20", "5.618494"], ["84253.70", "4.712286"], ["84262.20", "5.437252"], ["84270.70", "5.527873"], ["84279.20", "3.896698"], ["84287.70", "3.987319"], ["84296.20", "4.349802"], ["84304.70", "4.077939"], ["84313.20", "4.893527"], ["84321.70", "4.168560"]], "bids": [["84053.86", "0.041107"], ["84049.83", "0.027856"], ["84034.00", "1.887491"], ["84029.80", "0.066420"], ["83992.00", "4.984148"], ["83983.50", "4.531044"], ["83975.00", "4.168560"], ["83966.50", "5.074769"], ["83958.00", "5.437252"], ["83949.50", "5.165390"], ["83941.00", "3.987319"], ["83924.00", "5.618494"], ["83915.50", "5.346632"], ["83907.00", "4.621665"], ["83898.50", "5.527873"], ["83890.00", "4.259181"], ["83881.50", "4.349802"], ["83873.00", "4.802906"], ["83864.50", "5.256011"], ["83856.00", "4.440423"], ["83847.50", "4.712286"], ["83839.00", "4.893527"], ["83830.50", "3.896698"], ["83651.65", "0"], ["83651.16", "0"]], "checksum": -1137359053, "ts": "1742555178413"}], "ts": 1742555178416, "record_time": 1742555178.447644, "EXCHANGE": "BITGET"}
{"action": "update", "arg": {"instType": "SPOT", "channel": "books", "instId": "BTCUSDT"}, "data": [{"asks": [["84054.01", "1.361896"], ["84102.20", "0.006836"], ["84104.20", "0.017991"], ["84106.20", "0.047344"], ["84108.20", "0.124590"], ["84110.20", "0.327867"], ["84112.20", "0.862809"], ["84114.20", "2.270550"], ["84116.20", "5.975132"], ["84118.20", "15.724031"], ["84160.20", "5.074769"], ["84168.70", "5.527873"], ["84185.70", "4.077939"], ["84194.20", "4.984148"], ["84202.70", "5.618494"], ["84211.20", "4.893527"], ["84219.70", "4.531044"], ["84228.20", "3.987319"], ["84236.70", "4.802906"], ["84245.20", "4.621665"], ["84253.70", "4.168560"], ["84262.20", "4.440423"], ["84270.70", "5.165390"], ["84279.20", "5.346632"], ["84287.70", "4.349802"], ["84296.20", "4.712286"], ["84304.70", "3.896698"], ["84313.20", "5.437252"], ["84321.70", "5.256011"]], "bids": [["84044.00", "0.015112"], ["84042.00", "0.039769"], ["84040.00", "0.104654"], ["84038.00", "0.275406"], ["84036.00", "0.724753"], ["84034.00", "1.907244"], ["84030.40", "0.835320"], ["84029.80", "0.066210"], ["84029.70", "0.732060"], ["84029.30", "0"], ["84023.40", "0.949170"], ["84002.00", "0.000032"], ["83992.00", "4.531044"], ["83983.50", "5.074769"], ["83975.00", "5.256011"], ["83966.50", "4.077939"], ["83958.00", "3.987319"], ["83949.50", "5.527873"], ["83941.00", "4.893527"], ["83932.50", "4.984148"], ["83924.00", "4.349802"], ["83915.50", "4.440423"], ["83907.00", "3.896698"], ["83898.50", "4.168560"], ["83890.00", "5.437252"], ["83881.50", "4.802906"], ["83873.00", "5.346632"], ["83864.50", "4.712286"], ["83856.00", "4.259181"], ["83847.50", "4.621665"], ["83839.00", "5.618494"], ["83830.50", "5.165390"]], "checksum": 594874707, "ts": "1742555178613"}], "ts": 1742555178624, "record_time": 1742555178.660838, "EXCHANGE": "BITGET"}
{"action": "update", "arg": {"instType": "SPOT", "channel": "books", "instId": "BTCUSDT"}, "data": [{"asks": [["84074.12", "0"], ["84074.49", "0.119870"], ["84077.68", "0.010984"], ["84077.84", "0"], ["84078.05", "0.006356"], ["84078.24", "0.006356"], ["84078.34", "0"], ["84078.71", "0.016429"], ["84079.35", "0"], ["84079.75", "0.006356"], ["84082.66", "0"], ["84083.03", "0.119850"], ["84083.78", "0"], ["84084.15", "0.119867"], ["84087.95", "0"], ["84088.36", "0.015892"], ["84088.90", "0"], ["84089.27", "0.010988"], ["84108.02", "0"], ["84108.65", "0.001598"], ["84110.04", "0"], ["84110.64", "0.001597"], ["84160.20", "4.802906"], ["84168.70", "4.893527"], ["84177.20", "4.077939"], ["84185.70", "5.256011"], ["84194.20", "4.531044"], ["84202.70", "4.440423"], ["84211.20", "5.618494"], ["84219.70", "5.437252"], ["84228.20", "5.165390"], ["84236.70", "4.349802"], ["84245.20", "4.984148"], ["84253.70", "4.621665"], ["84262.20", "5.074769"], ["84270.70", "3.896698"], ["84279.20", "3.987319"], ["84287.70", "5.346632"], ["84296.20", "4.259181"], ["84304.70", "5.527873"], ["84313.20", "4.712286"], ["84321.70", "4.168560"], ["84535.32", "0"]], "bids": [["84033.27", "0.247615"], ["84032.94", "0"], ["84031.73", "0"], ["84031.66", "0.004018"], ["84029.66", "0.007132"], ["84029.43", "0"], ["84029.25", "0"], ["84029.12", "0.028868"], ["84028.75", "0"], ["84024.87", "0.268406"], ["84024.49", "0"], ["84023.63", "0.259825"], ["84023.26", "0"], ["84019.43", "0.073223"], ["84019.03", "0"], ["84018.66", "0.056373"], ["84018.29", "0"], ["83998.38", "0.001176"], ["83997.74", "0"], ["83996.49", "0.001173"], ["83995.89", "0"], ["83992.00", "5.437252"], ["83983.50", "5.165390"], ["83975.00", "5.074769"], ["83966.50", "4.440423"], ["83958.00", "3.896698"], ["83949.50", "4.259181"], ["83941.00", "5.256011"], ["83932.50", "3.987319"], ["83924.00", "4.531044"], ["83915.50", "5.527873"], ["83907.00", "4.712286"], ["83898.50", "4.984148"], ["83890.00", "5.618494"], ["83881.50", "5.346632"], ["83873.00", "4.621665"], ["83864.50", "4.349802"], ["83856.00", "4.077939"], ["83847.50", "4.893527"], ["83839.00", "4.168560"], ["83830.50", "4.802906"], ["83651.65", "0.000018"]], "checksum": -1876977456, "ts": "1742555178818"}], "ts": 1742555178821, "record_time": 1742555178.848308, "EXCHANGE": "BITGET"}
{"action": "update", "arg": {"instType": "SPOT", "channel": "books", "instId": "BTCUSDT"}, "data": [{"asks": [["84080.44", "0.116080"], ["84084.14", "0.098442"], ["84084.30", "0"], ["84110.20", "0.327741"], ["84112.20", "0.862475"], ["84114.20", "2.269672"], ["84116.20", "5.972820"], ["84118.20", "15.717949"], ["84160.20", "4.168560"], ["84168.70", "4.349802"], ["84177.20", "4.440423"], ["84185.70", "3.896698"], ["84194.20", "4.621665"], ["84202.70", "5.618494"], ["84211.20", "3.987319"], ["84219.70", "5.256011"], ["84228.20", "4.077939"], ["84236.70", "5.165390"], ["84245.20", "5.437252"], ["84253.70", "5.346632"], ["84270.70", "4.802906"], ["84279.20", "4.893527"], ["84287.70", "4.531044"], ["84296.20", "4.712286"], ["84304.70", "4.984148"], ["84313.20", "5.527873"], ["84321.70", "4.259181"]], "bids": [["84044.00", "0.014954"], ["84042.00", "0.039354"], ["84040.00", "0.103563"], ["84038.00", "0.272535"], ["84036.00", "0.717197"], ["84034.00", "1.887361"], ["84031.70", "0.807180"], ["84030.40", "0.070200"], ["84004.00", "0.000015"], ["83992.00", "5.165390"], ["83983.50", "5.074769"], ["83975.00", "4.440423"], ["83966.50", "5.618494"], ["83958.00", "4.349802"], ["83949.50", "4.802906"], ["83941.00", "3.987319"], ["83932.50", "4.984148"], ["83924.00", "3.896698"], ["83915.50", "5.256011"], ["83907.00", "4.893527"], ["83898.50", "5.527873"], ["83890.00", "4.621665"], ["83881.50", "4.531044"], ["83873.00", "4.259181"], ["83864.50", "5.437252"], ["83847.50", "5.346632"], ["83830.50", "4.712286"], ["83652.48", "0"], ["83651.65", "0"]], "checksum": 945556517, "ts": "1742555179033"}], "ts": 1742555179034, "record_time": 1742555179.06419, "EXCHANGE": "BITGET"}
{"action": "update", "arg": {"instType": "SPOT", "channel": "books", "instId": "BTCUSDT"}, "data": [{"asks": [["84108.20", "0.124330"], ["84110.19", "0.048447"], ["84110.20", "0.327186"], ["84112.20", "0.861016"], ["84114.20", "2.265831"], ["84116.20", "5.962713"], ["84118.20", "15.691351"], ["84160.20", "3.987319"], ["84168.70", "4.712286"], ["84177.20", "5.437252"], ["84185.70", "4.077939"], ["84194.20", "5.074769"], ["84202.70", "4.168560"], ["84211.20", "5.165390"], ["84219.70", "4.984148"], ["84228.20", "5.346632"], ["84236.70", "4.349802"], ["84245.20", "5.256011"], ["84253.70", "4.893527"], ["84262.20", "5.527873"], ["84270.70", "4.531044"], ["84279.20", "4.802906"], ["84287.70", "4.440423"], ["84296.20", "5.618494"], ["84304.70", "3.896698"], ["84313.20", "4.259181"], ["84321.70", "4.621665"], ["84534.53", "0"]], "bids": [["84054.00", "0.020000"], ["84053.86", "0"], ["84040.00", "0.103438"], ["84038.00", "0.272204"], ["84036.00", "0.716328"], ["84034.00", "1.885073"], ["84003.00", "0"], ["83992.00", "4.621665"], ["83983.50", "5.618494"], ["83975.00", "5.256011"], ["83966.50", "4.440423"], ["83958.00", "5.165390"], ["83949.50", "3.987319"], ["83941.00", "4.712286"], ["83932.50", "4.077939"], ["83924.00", "4.893527"], ["83915.50", "5.346632"], ["83907.00", "4.168560"], ["83898.50", "4.259181"], ["83890.00", "4.531044"], ["83881.50", "4.984148"], ["83873.00", "5.437252"], ["83864.50", "4.802906"], ["83856.00", "3.896698"], ["83847.50", "5.074769"], ["83839.00", "4.349802"], ["83830.50", "5.527873"], ["83652.48", "0.000188"], ["83651.65", "0.000018"]], "checksum": 1057497075, "ts": "1742555179237"}], "ts": 1742555179240, "record_time": 1742555179.264332, "EXCHANGE": "BITGET"}
{"action": "update", "arg": {"instType": "SPOT", "channel": "books", "instId": "BTCUSDT"}, "data": [{"asks": [["84116.20", "5.962551"], ["84118.20", "15.690923"], ["84120.50", "0.035670"], ["84160.20", "4.984148"], ["84168.70", "4.349802"], ["84177.20", "4.621665"], ["84185.70", "4.531044"], ["84194.20", "5.618494"], ["84202.70", "5.165390"], ["84211.20", "5.527873"], ["84219.70", "3.896698"], ["84228.20", "4.440423"], ["84236.70", "5.256011"], ["84245.20", "4.893527"], ["84253.70", "4.168560"], ["84262.20", "4.077939"], ["84270.70", "5.437252"], ["84279.20", "3.987319"], ["84287.70", "5.346632"], ["84296.20", "4.259181"], ["84304.70", "5.074769"], ["84313.20", "4.802906"], ["84321.70", "4.712286"], ["84533.33", "0"]], "bids": [["84053.87", "0.041107"], ["84044.00", "0.015082"], ["84042.00", "0.039688"], ["84040.00", "0.104442"], ["84038.00", "0.274847"], ["84036.00", "0.723283"], ["84034.00", "1.903375"], ["84016.96", "0.000876"], ["84016.61", "0"], ["83998.52", "0.003597"], ["83998.15", "0"], ["83992.00", "4.259181"], ["83983.50", "5.437252"], ["83975.00", "4.621665"], ["83966.50", "4.802906"], ["83958.00", "5.074769"], ["83949.50", "4.984148"], ["83941.00", "4.893527"], ["83932.50", "4.531044"], ["83924.00", "4.349802"], ["83907.00", "5.165390"], ["83898.50", "5.527873"], ["83890.00", "5.256011"], ["83881.50", "4.712286"], ["83873.00", "3.896698"], ["83864.50", "3.987319"], ["83856.00", "4.168560"], ["83847.50", "4.440423"], ["83839.00", "5.618494"], ["83830.50", "4.077939"], ["83651.65", "0"]], "checksum": -481378100, "ts": "1742555179439"}], "ts": 1742555179443, "record_time": 1742555179.471831, "EXCHANGE": "BITGET"}
{"action": "update", "arg": {"instType": "SPOT", "channel": "books", "instId": "BTCUSDT"}, "data": [{"asks": [["84054.01", "1.359514"], ["84106.20", "0.047241"], ["84114.20", "2.265613"], ["84116.20", "5.962141"], ["84118.20", "15.689844"], ["84125.80", "0.263670"], ["84126.90", "0.079500"], ["84160.20", "4.440423"], ["84168.70", "5.437252"], ["84177.20", "4.984148"], ["84185.70", "4.621665"], ["84194.20", "4.712286"], ["84202.70", "3.987319"], ["84211.20", "4.077939"], ["84219.70", "4.802906"], ["84228.20", "5.074769"], ["84236.70", "5.527873"], ["84245.20", "5.165390"], ["84253.70", "4.531044"], ["84262.20", "5.256011"], ["84270.70", "4.168560"], ["84279.20", "4.259181"], ["84287.70", "4.893527"], ["84296.20", "4.349802"], ["84304.70", "5.346632"], ["84313.20", "5.618494"], ["84321.70", "3.896698"], ["84533.01", "0"]], "bids": [["84050.80", "0.027856"], ["84049.83", "0"], ["84034.00", "1.903524"], ["84031.70", "0"], ["84029.80", "0.066420"], ["84029.70", "0.514650"], ["84025.40", "0"], ["84004.00", "0.000032"], ["84002.00", "0.000017"], ["83992.00", "4.440423"], ["83983.50", "4.712286"], ["83975.00", "4.259181"], ["83966.50", "5.165390"], ["83958.00", "4.168560"], ["83949.50", "4.531044"], ["83941.00", "5.618494"], ["83932.50", "4.621665"], ["83924.00", "5.256011"], ["83915.50", "5.074769"], ["83907.00", "3.896698"], ["83898.50", "4.349802"], ["83890.00", "5.346632"], ["83881.50", "3.987319"], ["83873.00", "5.437252"], ["83864.50", "4.984148"], ["83856.00", "5.527873"], ["83847.50", "4.802906"], ["83839.00", "4.893527"], ["83651.65", "0.000018"], ["83651.16", "0.000896"]], "checksum": 1690438891, "ts": "1742555179654"}], "ts": 1742555179658, "record_time": 1742555179.684227, "EXCHANGE": "BITGET"}
{"action": "update", "arg": {"instType": "SPOT", "channel": "books", "instId": "BTCUSDT"}, "data": [{"asks": [["84160.20", "5.256011"], ["84168.70", "4.349802"], ["84177.20", "4.259181"], ["84185.70", "5.618494"], ["84194.20", "4.531044"], ["84202.70", "4.077939"], ["84211.20", "5.527873"], ["84219.70", "4.168560"], ["84228.20", "5.437252"], ["84236.70", "4.440423"], ["84245.20", "3.987319"], ["84253.70", "5.165390"], ["84262.20", "4.984148"], ["84270.70", "5.346632"], ["84279.20", "4.712286"], ["84296.20", "4.621665"], ["84304.70", "3.896698"], ["84313.20", "4.802906"], ["84321.70", "5.074769"]], "bids": [["84045.85", "0"], ["83992.00", "4.168560"], ["83983.50", "4.349802"], ["83975.00", "5.346632"], ["83966.50", "4.802906"], ["83958.00", "4.984148"], ["83949.50", "4.893527"], ["83941.00", "3.987319"], ["83915.50", "5.165390"], ["83907.00", "5.618494"], ["83898.50", "4.531044"], ["83890.00", "5.074769"], ["83881.50", "3.896698"], ["83873.00", "4.259181"], ["83864.50", "5.437252"], ["83856.00", "4.077939"], ["83847.50", "4.440423"], ["83839.00", "4.712286"], ["83830.50", "5.527873"], ["83650.84", "0.003326"]], "checksum": -1831489030, "ts": "1742555179862"}], "ts": 1742555179867, "record_time": 1742555179.896664, "EXCHANGE": "BITGET"}
{"action": "update", "arg": {"instType": "SPOT", "channel": "books", "instId": "BTCUSDT"}, "data": [{"asks": [["84054.00", "1.269400"], ["84054.01", "0.773434"], ["84059.01", "0"], ["84088.35", "0.012406"], ["84098.20", "0.001768"], ["84100.20", "0.002884"], ["84102.20", "0.007591"], ["84104.20", "0.019976"], ["84106.20", "0.052567"], ["84108.20", "0.138334"], ["84110.20", "0.364038"], ["84112.20", "0.957995"], ["84114.20", "2.521040"], ["84116.20", "6.634314"], ["84118.20", "17.458723"], ["84122.50", "3.430860"], ["84124.50", "3.217230"], ["84124.60", "0.071340"], ["84126.90", "0"], ["84160.20", "4.531044"], ["84168.70", "5.165390"], ["84177.20", "5.256011"], ["84185.70", "5.074769"], ["84194.20", "5.618494"], ["84202.70", "4.440423"], ["84211.20", "4.621665"], ["84219.70", "4.712286"], ["84228.20", "4.168560"], ["84236.70", "5.527873"], ["84245.20", "4.259181"], ["84253.70", "4.349802"], ["84262.20", "5.346632"], ["84270.70", "4.984148"], ["84279.20", "3.896698"], ["84287.70", "4.802906"], ["84296.20", "4.077939"], ["84304.70", "4.893527"], ["84313.20", "3.987319"], ["84321.70", "5.437252"], ["84530.00", "0"]], "bids": [["84054.00", "0"], ["84048.00", "0.001030"], ["84046.00", "0.002611"], ["84044.00", "0.006871"], ["84042.00", "0.018083"], ["84040.00", "0.047392"], ["84038.00", "0.124717"], ["84036.31", "0"], ["84036.00", "0.328203"], ["84034.00", "0.863691"], ["84029.90", "0.006600"], ["84029.80", "0.017105"], ["84029.70", "0"], ["84028.10", "0.074820"], ["84027.50", "0.381870"], ["84027.20", "2.083740"], ["84027.00", "0.000032"], ["84026.90", "0.066240"], ["84026.00", "0.000032"], ["84024.50", "2.356380"], ["84023.20", "0.045540"], ["84022.80", "1.518360"], ["83992.00", "4.349802"], ["83983.50", "5.618494"], ["83975.00", "3.987319"], ["83966.50", "4.621665"], ["83949.50", "4.077939"], ["83941.00", "4.440423"], ["83932.50", "5.256011"], ["83924.00", "4.893527"], ["83915.50", "4.531044"], ["83907.00", "4.168560"], ["83898.50", "5.346632"], ["83890.00", "5.165390"], ["83881.50", "4.802906"], ["83873.00", "5.437252"], ["83864.50", "4.259181"], ["83856.00", "5.527873"], ["83847.50", "5.074769"], ["83839.00", "3.896698"], ["83830.50", "4.712286"]], "checksum": 514238602, "ts": "1742555180074"}], "ts": 1742555180076, "record_time": 1742555180.103716, "EXCHANGE": "BITGET"}
{"action": "update", "arg": {"instType": "SPOT", "channel": "books", "instId": "BTCUSDT"}, "data": [{"asks": [["84053.99", "0.222000"], ["84054.00", "0.900672"], ["84054.01", "0.027093"], ["84054.74", "0"], ["84059.00", "0.067068"], ["84059.89", "0"], ["84126.70", "0"], ["84160.20", "4.893527"], ["84168.70", "4.531044"], ["84177.20", "4.984148"], ["84185.70", "5.165390"], ["84194.20", "4.168560"], ["84202.70", "5.256011"], ["84211.20", "5.346632"], ["84219.70", "3.896698"], ["84228.20", "4.621665"], ["84236.70", "4.077939"], ["84245.20", "5.074769"], ["84253.70", "4.712286"], ["84262.20", "4.259181"], ["84270.70", "3.987319"], ["84279.20", "5.618494"], ["84296.20", "5.527873"], ["84304.70", "4.440423"], ["84313.20", "4.349802"], ["84530.00", "0.000031"], ["84533.01", "0.000591"]], "bids": [["84053.99", "0"], ["84053.96", "0.000100"], ["84053.95", "0.000100"], ["84040.08", "0"], ["84036.01", "0.404658"], ["84034.00", "0.863821"], ["84033.41", "0.313822"], ["84027.50", "0.261870"], ["84026.70", "0"], ["84024.51", "0.726008"], ["84022.60", "0.240000"], ["84022.50", "0.120000"], ["83992.00", "5.618494"], ["83983.50", "4.349802"], ["83966.50", "5.527873"], ["83958.00", "4.259181"], ["83949.50", "4.440423"], ["83941.00", "4.168560"], ["83932.50", "4.621665"], ["83924.00", "5.346632"], ["83915.50", "4.712286"], ["83907.00", "4.893527"], ["83898.50", "5.437252"], ["83890.00", "5.256011"], ["83881.50", "3.896698"], ["83873.00", "5.074769"], ["83864.50", "5.165390"], ["83856.00", "4.077939"], ["83847.50", "4.802906"], ["83839.00", "4.531044"], ["83830.50", "4.984148"], ["83651.65", "0"], ["83651.16", "0"], ["83650.84", "0"]], "checksum": 1835655726, "ts": "1742555180275"}], "ts": 1742555180278, "record_time": 1742555180.301781, "EXCHANGE": "BITGET"}
{"action": "update", "arg": {"instType": "SPOT", "channel": "books", "instId": "BTCUSDT"}, "data": [{"asks": [["84053.99", "2.243368"], ["84054.00", "0.451672"], ["84068.22", "0"], ["84086.38", "0"], ["84093.10", "0"], ["84103.84", "0.305356"], ["84119.20", "0.001740"], ["84119.80", "0.035880"], ["84126.50", "0"], ["84126.60", "0"], ["84160.20", "4.531044"], ["84168.70", "4.802906"], ["84177.20", "5.437252"], ["84185.70", "5.346632"], ["84194.20", "4.621665"], ["84202.70", "4.168560"], ["84211.20", "4.712286"], ["84219.70", "4.077939"], ["84228.20", "5.165390"], ["84236.70", "5.618494"], ["84253.70", "4.440423"], ["84262.20", "4.893527"], ["84270.70", "5.527873"], ["84279.20", "3.896698"], ["84287.70", "5.256011"], ["84296.20", "4.349802"], ["84304.70", "4.984148"], ["84313.20", "3.987319"], ["84321.70", "4.259181"], ["84533.33", "0.003186"], ["84534.53", "0.000461"], ["84535.32", "0.000039"], ["84536.36", "0.000053"]], "bids": [["84053.88", "0.041107"], ["84053.87", "0"], ["84044.00", "0.006974"], ["84042.00", "0.018352"], ["84040.00", "0.048295"], ["84038.00", "0.127091"], ["84036.90", "0.134225"], ["84036.01", "0"], ["84036.00", "0.334451"], ["84034.00", "0.880133"], ["84028.20", "1.206570"], ["84028.10", "0.074610"], ["84027.50", "0.261660"], ["84027.30", "0.442980"], ["84027.20", "1.124790"], ["84022.50", "0"], ["84003.00", "0.000015"], ["83992.00", "4.893527"], ["83983.50", "5.437252"], ["83975.00", "4.621665"], ["83958.00", "3.896698"], ["83949.50", "4.349802"], ["83941.00", "5.346632"], ["83932.50", "4.259181"], ["83924.00", "4.531044"], ["83915.50", "4.802906"], ["83907.00", "4.168560"], ["83898.50", "4.440423"], ["83890.00", "4.984148"], ["83881.50", "5.618494"], ["83873.00", "5.256011"], ["83864.50", "4.712286"], ["83847.50", "5.165390"], ["83839.00", "3.987319"], ["83830.50", "5.074769"], ["83652.48", "0"]], "checksum": -1471880708, "ts": "1742555180477"}], "ts": 1742555180486, "record_time": 1742555180.508416, "EXCHANGE": "BITGET"}
{"action": "update", "arg": {"instType": "SPOT", "channel": "books", "instId": "BTCUSDT"}, "data": [{"asks": [["84053.99", "1.498434"], ["84054.00", "0.262400"], ["84060.13", "0.314071"], ["84068.21", "0.066780"], ["84084.14", "0"], ["84086.36", "0.177729"], ["84118.20", "17.458592"], ["84119.20", "0.003480"], ["84124.90", "0.005220"], ["84126.09", "0.107461"], ["84126.10", "0.026310"], ["84168.70", "5.527873"], ["84185.70", "5.074769"], ["84194.20", "5.618494"], ["84202.70", "5.165390"], ["84211.20", "4.621665"], ["84219.70", "4.802906"], ["84228.20", "4.984148"], ["84236.70", "4.440423"], ["84245.20", "3.987319"], ["84253.70", "4.712286"], ["84262.20", "3.896698"], ["84270.70", "5.346632"], ["84279.20", "4.168560"], ["84287.70", "4.259181"], ["84296.20", "4.893527"], ["84304.70", "4.077939"], ["84313.20", "5.256011"], ["84321.70", "4.349802"], ["84535.32", "0"], ["84536.36", "0"]], "bids": [["84050.80", "0"], ["84050.13", "0.027856"], ["84036.00", "0.334204"], ["84034.00", "0.879482"], ["84028.21", "0.987669"], ["84028.20", "1.206210"], ["84028.10", "0.074820"], ["84027.21", "0"], ["84022.50", "0.120000"], ["83992.00", "4.621665"], ["83983.50", "4.531044"], ["83975.00", "4.259181"], ["83966.50", "4.712286"], ["83958.00", "4.893527"], ["83941.00", "3.987319"], ["83932.50", "4.984148"], ["83924.00", "5.346632"], ["83915.50", "5.437252"], ["83907.00", "4.440423"], ["83898.50", "5.256011"], ["83890.00", "4.802906"], ["83881.50", "5.074769"], ["83873.00", "3.896698"], ["83864.50", "5.165390"], ["83856.00", "5.618494"], ["83847.50", "4.168560"], ["83839.00", "5.527873"], ["83830.50", "4.077939"], ["83652.80", "0"]], "checksum": 52513843, "ts": "1742555180678"}], "ts": 1742555180681, "record_time": 1742555180.706419, "EXCHANGE": "BITGET"}
{"action": "update", "arg": {"instType": "SPOT", "channel": "books", "instId": "BTCUSDT"}, "data": [{"asks": [["84053.99", "1.715403"], ["84122.50", "2.575470"], ["84124.10", "1.970940"], ["84126.09", "0.041849"], ["84160.20", "4.621665"], ["84168.70", "3.896698"], ["84177.20", "4.893527"], ["84185.70", "4.440423"], ["84194.20", "5.346632"], ["84202.70", "3.987319"], ["84211.20", "4.984148"], ["84219.70", "4.259181"], ["84228.20", "5.618494"], ["84236.70", "4.712286"], ["84245.20", "5.074769"], ["84253.70", "4.531044"], ["84262.20", "5.165390"], ["84270.70", "5.256011"], ["84279.20", "5.527873"], ["84287.70", "4.349802"], ["84296.20", "4.802906"], ["84313.20", "4.168560"], ["84321.70", "5.437252"]], "bids": [["84029.10", "0.489600"], ["84028.10", "0.074610"], ["84027.30", "0"], ["84022.50", "0"], ["83992.00", "3.987319"], ["83983.50", "5.256011"], ["83975.00", "4.168560"], ["83958.00", "5.527873"], ["83949.50", "5.165390"], ["83941.00", "4.349802"], ["83932.50", "4.621665"], ["83924.00", "4.893527"], ["83898.50", "5.074769"], ["83890.00", "5.346632"], ["83881.50", "4.259181"], ["83873.00", "4.984148"], ["83864.50", "4.077939"], ["83856.00", "4.802906"], ["83847.50", "5.618494"], ["83839.00", "3.896698"], ["83830.50", "4.531044"], ["83652.80", "0.000119"]], "checksum": -430229881, "ts": "1742555180882"}], "ts": 1742555180886, "record_time": 1742555180.908638, "EXCHANGE": "BITGET"}
{"action": "update", "arg": {"instType": "SPOT", "channel": "books", "instId": "BTCUSDT"}, "data": [{"asks": [["84053.99", "1.456664"], ["84059.00", "0.148598"], ["84084.14", "0.097044"], ["84126.00", "0"], ["84126.10", "0.166440"], ["84168.70", "5.165390"], ["84177.20", "5.256011"], ["84185.70", "5.074769"], ["84194.20", "5.618494"], ["84202.70", "4.712286"], ["84211.20", "3.987319"], ["84228.20", "4.440423"], ["84236.70", "5.346632"], ["84245.20", "5.527873"], ["84253.70", "4.893527"], ["84262.20", "4.077939"], ["84270.70", "3.896698"], ["84279.20", "4.349802"], ["84287.70", "4.168560"], ["84304.70", "5.437252"], ["84313.20", "4.531044"], ["84321.70", "4.984148"]], "bids": [["83992.00", "4.077939"], ["83983.50", "5.437252"], ["83975.00", "4.440423"], ["83966.50", "3.987319"], ["83958.00", "4.712286"], ["83949.50", "5.618494"], ["83941.00", "4.259181"], ["83932.50", "3.896698"], ["83924.00", "5.346632"], ["83915.50", "4.984148"], ["83907.00", "4.531044"], ["83898.50", "4.893527"], ["83890.00", "5.527873"], ["83881.50", "4.621665"], ["83873.00", "4.349802"], ["83864.50", "5.074769"], ["83847.50", "5.256011"], ["83839.00", "5.165390"], ["83830.50", "4.168560"]], "checksum": 803032390, "ts": "1742555181096"}], "ts": 1742555181101, "record_time": 1742555181.123689, "EXCHANGE": "BITGET"}
{"action": "update", "arg": {"instType": "SPOT", "channel": "books", "instId": "BTCUSDT"}, "data": [{"asks": [["84053.99", "1.706004"], ["84114.19", "0.379659"], ["84160.20", "4.893527"], ["84177.20", "5.074769"], ["84185.70", "3.896698"], ["84202.70", "5.256011"], ["84211.20", "4.712286"], ["84228.20", "4.802906"], ["84236.70", "4.984148"], ["84245.20", "4.440423"], ["84253.70", "5.527873"], ["84262.20", "3.987319"], ["84270.70", "5.437252"], ["84279.20", "4.621665"], ["84296.20", "5.346632"], ["84304.70", "4.077939"], ["84321.70", "4.349802"], ["84534.53", "0"]], "bids": [["84024.80", "0.155250"], ["83992.00", "5.437252"], ["83983.50", "4.349802"], ["83975.00", "5.256011"], ["83966.50", "4.984148"], ["83958.00", "5.346632"], ["83949.50", "5.165390"], ["83941.00", "4.168560"], ["83932.50", "5.527873"], ["83924.00", "4.531044"], ["83915.50", "5.618494"], ["83907.00", "4.712286"], ["83898.50", "4.621665"], ["83890.00", "4.802906"], ["83881.50", "4.893527"], ["83873.00", "3.896698"], ["83864.50", "4.259181"], ["83856.00", "3.987319"], ["83847.50", "4.440423"], ["83839.00", "5.074769"], ["83830.50", "4.077939"]], "checksum": -1472966741, "ts": "1742555181319"}], "ts": 1742555181322, "record_time": 1742555181.344508, "EXCHANGE": "BITGET"}
{"action": "update", "arg": {"instType": "SPOT", "channel": "books", "instId": "BTCUSDT"}, "data": [{"asks": [["84053.99", "1.962143"], ["84054.00", "0.209200"], ["84106.20", "0.052433"], ["84108.20", "0.137983"], ["84110.20", "0.363113"], ["84112.20", "0.955560"], ["84114.20", "2.514631"], ["84116.20", "6.617592"], ["84118.20", "17.414715"], ["84126.10", "0"], ["84160.19", "0.009085"], ["84160.20", "3.987319"], ["84168.70", "4.349802"], ["84177.20", "5.346632"], ["84194.20", "4.984148"], ["84202.70", "4.621665"], ["84211.20", "4.168560"], ["84219.70", "4.531044"], ["84228.20", "5.527873"], ["84236.70", "5.437252"], ["84245.20", "4.259181"], ["84253.70", "4.712286"], ["84262.20", "5.165390"], ["84270.70", "5.074769"], ["84279.20", "4.440423"], ["84287.70", "5.618494"], ["84296.20", "4.893527"], ["84313.20", "4.802906"], ["84321.70", "5.256011"]], "bids": [["84044.00", "0.006842"], ["84042.00", "0.018007"], ["84040.00", "0.047385"], ["84038.00", "0.124698"], ["84036.00", "0.328153"], ["84034.00", "0.863561"], ["84025.20", "0.045540"], ["84023.20", "0.021132"], ["83992.00", "3.896698"], ["83983.50", "4.259181"], ["83975.00", "4.621665"], ["83966.50", "5.527873"], ["83958.00", "5.437252"], ["83949.50", "4.712286"], ["83941.00", "4.984148"], ["83932.50", "4.440423"], ["83924.00", "5.618494"], ["83915.50", "5.165390"], ["83907.00", "5.256011"], ["83898.50", "3.987319"], ["83890.00", "4.893527"], ["83881.50", "4.349802"], ["83873.00", "4.077939"], ["83864.50", "4.168560"], ["83856.00", "5.074769"], ["83847.50", "4.531044"], ["83839.00", "4.802906"], ["83830.50", "5.346632"], ["83652.80", "0"]], "checksum": -685151327, "ts": "1742555181524"}], "ts": 1742555181528, "record_time": 1742555181.559201, "EXCHANGE": "BITGET"}
{"action": "update", "arg": {"instType": "SPOT", "channel": "books", "instId": "BTCUSDT"}, "data": [{"asks": [["84053.99", "2.207983"], ["84160.20", "5.074769"], ["84168.70", "4.893527"], ["84177.20", "4.712286"], ["84185.70", "4.984148"], ["84194.20", "5.165390"], ["84202.70", "4.259181"], ["84211.20", "4.531044"], ["84219.70", "5.618494"], ["84228.20", "5.346632"], ["84236.70", "3.896698"], ["84245.20", "4.077939"], ["84253.70", "5.256011"], ["84262.20", "5.437252"], ["84270.70", "5.527873"], ["84279.20", "4.621665"], ["84287.70", "3.987319"], ["84296.20", "4.802906"], ["84304.70", "4.349802"], ["84313.20", "4.168560"], ["84321.70", "4.440423"]], "bids": [["84051.03", "0.027856"], ["84050.13", "0"], ["83992.00", "3.987319"], ["83983.50", "3.896698"], ["83975.00", "4.440423"], ["83966.50", "4.621665"], ["83958.00", "5.165390"], ["83949.50", "4.349802"], ["83941.00", "4.893527"], ["83932.50", "4.802906"], ["83924.00", "4.259181"], ["83915.50", "4.168560"], ["83898.50", "4.077939"], ["83890.00", "5.527873"], ["83881.50", "4.984148"], ["83873.00", "5.346632"], ["83864.50", "5.074769"], ["83856.00", "5.618494"], ["83839.00", "5.437252"], ["83830.50", "4.712286"]], "checksum": 648180035, "ts": "1742555181734"}], "ts": 1742555181737, "record_time": 1742555181.767956, "EXCHANGE": "BITGET"}
{"action": "update", "arg": {"instType": "SPOT", "channel": "books", "instId": "BTCUSDT"}, "data": [{"asks": [["84053.99", "2.257844"], ["84098.20", "0.001649"], ["84100.20", "0.002691"], ["84102.20", "0.007080"], ["84104.20", "0.018632"], ["84106.20", "0.049031"], ["84108.20", "0.129029"], ["84110.20", "0.339552"], ["84112.20", "0.893556"], ["84114.20", "2.351463"], ["84116.20", "6.188063"], ["84118.20", "16.284374"], ["84160.20", "4.531044"], ["84168.70", "5.618494"], ["84177.20", "5.437252"], ["84185.70", "4.349802"], ["84194.20", "4.621665"], ["84202.70", "4.077939"], ["84211.20", "4.802906"], ["84219.70", "3.896698"], ["84228.20", "4.984148"], ["84236.70", "5.165390"], ["84245.20", "3.987319"], ["84253.70", "4.712286"], ["84262.20", "5.527873"], ["84270.70", "5.256011"], ["84279.20", "5.346632"], ["84287.70", "4.893527"], ["84296.20", "4.168560"], ["84304.70", "5.074769"], ["84313.20", "4.259181"]], "bids": [["84053.89", "0.041107"], ["84053.88", "0"], ["84045.41", "0.010000"], ["84044.00", "0.006952"], ["84042.00", "0.018296"], ["84040.00", "0.048145"], ["84038.00", "0.126699"], ["84036.00", "0.333419"], ["84034.00", "0.877418"], ["83992.00", "4.621665"], ["83975.00", "4.802906"], ["83966.50", "5.165390"], ["83958.00", "4.077939"], ["83949.50", "4.531044"], ["83941.00", "5.074769"], ["83932.50", "4.440423"], ["83924.00", "5.618494"], ["83915.50", "4.259181"], ["83898.50", "3.987319"], ["83890.00", "4.984148"], ["83881.50", "4.168560"], ["83864.50", "5.527873"], ["83856.00", "4.712286"], ["83847.50", "5.437252"], ["83839.00", "4.893527"], ["83830.50", "4.349802"], ["83653.31", "0"]], "checksum": -690088130, "ts": "1742555181936"}], "ts": 1742555181938, "record_time": 1742555181.960281, "EXCHANGE": "BITGET"}
{"action": "update", "arg": {"instType": "SPOT", "channel": "books", "instId": "BTCUSDT"}, "data": [{"asks": [["84053.91", "0.891540"], ["84053.93", "0.242658"], ["84053.98", "0.048867"], ["84053.99", "0.738671"], ["84054.00", "0"], ["84054.75", "0"], ["84102.20", "0.006941"], ["84103.84", "0.749422"], ["84104.20", "0.018265"], ["84106.20", "0.048066"], ["84108.20", "0.126489"], ["84110.20", "0.332867"], ["84112.20", "0.875966"], ["84114.20", "2.305173"], ["84116.20", "6.066246"], ["84118.20", "15.963803"], ["84118.89", "0"], ["84120.40", "0"], ["84126.09", "0"], ["84126.10", "0.026310"], ["84160.19", "0"], ["84160.20", "3.896698"], ["84168.70", "4.712286"], ["84177.20", "4.802906"], ["84185.70", "5.256011"], ["84194.20", "5.346632"], ["84202.70", "4.621665"], ["84211.20", "4.259181"], ["84219.70", "5.074769"], ["84228.20", "4.168560"], ["84236.70", "5.527873"], ["84245.20", "4.077939"], ["84253.70", "4.531044"], ["84262.20", "4.893527"], ["84270.70", "5.618494"], ["84279.20", "5.437252"], ["84287.70", "3.987319"], ["84296.20", "4.440423"], ["84304.70", "4.984148"], ["84313.20", "5.165390"], ["84321.70", "4.349802"], ["84534.53", "0.000461"], ["84535.32", "0.000039"]], "bids": [["84053.98", "0"], ["84053.97", "0"], ["84053.96", "0"], ["84053.95", "0"], ["84053.90", "0.008041"], ["84051.03", "0"], ["84046.00", "0.002913"], ["84044.00", "0.007668"], ["84042.00", "0.020178"], ["84040.00", "0.053100"], ["84038.00", "0.139736"], ["84036.00", "0.367501"], ["84034.00", "0.967107"], ["84026.20", "2.356350"], ["84024.50", "0"], ["83992.00", "4.168560"], ["83983.50", "4.349802"], ["83975.00", "4.712286"], ["83958.00", "5.618494"], ["83949.50", "4.984148"], ["83941.00", "4.802906"], ["83932.50", "5.527873"], ["83924.00", "4.259181"], ["83915.50", "4.077939"], ["83907.00", "3.896698"], ["83898.50", "4.531044"], ["83890.00", "5.346632"], ["83881.50", "5.437252"], ["83873.00", "5.256011"], ["83864.50", "4.893527"], ["83856.00", "4.440423"], ["83847.50", "5.074769"], ["83839.00", "3.987319"], ["83830.50", "4.621665"], ["83653.31", "0.000015"], ["83652.80", "0.000119"], ["83652.48", "0.000188"], ["83651.65", "0.000018"], ["83651.16", "0.000896"]], "checksum": 2120730383, "ts": "1742555182137"}], "ts": 1742555182139, "record_time": 1742555182.164258, "EXCHANGE": "BITGET"}
{"action": "update", "arg": {"instType": "SPOT", "channel": "books", "instId": "BTCUSDT"}, "data": [{"asks": [["84053.91", "1.391484"], ["84053.98", "0.183243"], ["84053.99", "0.222988"], ["84103.84", "0.305356"], ["84108.20", "0.126612"], ["84110.20", "0.333189"], ["84112.20", "0.876814"], ["84114.19", "0"], ["84114.20", "2.307405"], ["84116.20", "6.072119"], ["84118.20", "15.979260"], ["84126.21", "0.062760"], ["84160.20", "4.531044"], ["84168.70", "5.256011"], ["84177.20", "4.893527"], ["84185.70", "4.802906"], ["84202.70", "5.074769"], ["84211.20", "5.165390"], ["84219.70", "5.618494"], ["84228.20", "3.987319"], ["84236.70", "4.621665"], ["84253.70", "4.259181"], ["84262.20", "5.527873"], ["84270.70", "4.349802"], ["84279.20", "4.984148"], ["84287.70", "4.440423"], ["84296.20", "4.712286"], ["84304.70", "3.896698"], ["84313.20", "4.168560"], ["84321.70", "5.437252"]], "bids": [["84050.83", "0.027856"], ["84040.00", "0.052885"], ["84038.00", "0.139172"], ["84036.01", "0.447473"], ["84036.00", "0.366243"], ["84034.00", "0.963796"], ["84028.21", "1.451775"], ["84026.20", "0"], ["84024.51", "0"], ["84024.50", "2.356380"], ["83992.00", "3.896698"], ["83983.50", "5.256011"], ["83975.00", "4.349802"], ["83966.50", "3.987319"], ["83958.00", "5.074769"], ["83941.00", "4.621665"], ["83932.50", "5.618494"], ["83924.00", "5.165390"], ["83907.00", "5.346632"], ["83890.00", "5.437252"], ["83881.50", "4.893527"], ["83873.00", "4.259181"], ["83864.50", "4.440423"], ["83856.00", "4.168560"], ["83847.50", "5.527873"], ["83839.00", "4.712286"], ["83830.50", "4.802906"], ["83651.16", "0"]], "checksum": -880078406, "ts": "1742555182343"}], "ts": 1742555182346, "record_time": 1742555182.371793, "EXCHANGE": "BITGET"}
{"action": "update", "arg": {"instType": "SPOT", "channel": "books", "instId": "BTCUSDT"}, "data": [{"asks": [["84053.92", "0.156313"], ["84053.98", "0"], ["84090.47", "0.010000"], ["84119.20", "0.001740"], ["84121.10", "0.269760"], ["84126.10", "0"], ["84160.20", "4.802906"], ["84161.64", "0"], ["84170.05", "0"], ["84177.20", "5.618494"], ["84185.70", "4.168560"], ["84194.20", "4.893527"], ["84202.70", "4.349802"], ["84211.20", "4.077939"], ["84219.70", "5.165390"], ["84228.20", "4.531044"], ["84236.70", "4.440423"], ["84245.20", "3.896698"], ["84262.20", "5.437252"], ["84270.70", "4.984148"], ["84279.20", "5.346632"], ["84287.70", "4.621665"], ["84304.70", "3.987319"], ["84313.20", "5.074769"], ["84321.70", "5.527873"], ["84536.36", "0.000053"]], "bids": [["84042.00", "0.020019"], ["84040.67", "0"], ["84040.00", "0.052681"], ["84038.00", "0.138635"], ["84036.00", "0.364829"], ["84034.00", "0.960076"], ["84032.24", "0.028180"], ["84028.21", "0.987669"], ["84024.51", "0.533463"], ["83992.00", "5.074769"], ["83983.50", "5.165390"], ["83975.00", "3.987319"], ["83974.24", "0"], ["83966.50", "5.618494"], ["83965.83", "0"], ["83958.00", "5.346632"], ["83949.50", "5.256011"], ["83941.00", "3.896698"], ["83932.50", "5.527873"], ["83924.00", "4.802906"], ["83907.00", "4.168560"], ["83898.50", "4.440423"], ["83890.00", "4.531044"], ["83881.50", "4.984148"], ["83873.00", "5.437252"], ["83864.50", "4.712286"], ["83856.00", "4.893527"], ["83847.50", "4.259181"], ["83839.00", "4.349802"], ["83830.50", "4.621665"], ["83651.16", "0.000896"]], "checksum": 565487066, "ts": "1742555182544"}], "ts": 1742555182548, "record_time": 1742555182.576002, "EXCHANGE": "BITGET"}
{"action": "update", "arg": {"instType": "SPOT", "channel": "books", "instId": "BTCUSDT"}, "data": [{"asks": [["84086.36", "0"], ["84100.20", "0.002530"], ["84102.20", "0.006659"], ["84104.20", "0.017524"], ["84106.20", "0.046115"], ["84108.20", "0.121356"], ["84110.20", "0.319358"], ["84112.20", "0.840416"], ["84114.20", "2.211620"], ["84116.20", "5.819805"], ["84118.20", "15.315277"], ["84154.73", "0.001810"], ["84160.20", "3.896698"], ["84163.14", "0.003620"], ["84168.70", "5.437252"], ["84177.20", "5.527873"], ["84185.69", "0.032379"], ["84185.70", "4.349802"], ["84194.20", "4.531044"], ["84202.70", "5.256011"], ["84211.20", "5.165390"], ["84219.70", "4.168560"], ["84228.20", "5.074769"], ["84236.70", "4.712286"], ["84245.20", "4.893527"], ["84253.70", "4.984148"], ["84262.20", "4.077939"], ["84270.70", "4.259181"], ["84279.20", "4.802906"], ["84287.70", "3.987319"], ["84296.20", "5.618494"], ["84304.70", "4.440423"], ["84313.20", "4.621665"], ["84321.70", "5.346632"], ["84535.32", "0"], ["84536.36", "0"]], "bids": [["84051.70", "0.027856"], ["84050.83", "0"], ["83992.00", "5.437252"], ["83983.50", "4.893527"], ["83975.00", "5.527873"], ["83966.50", "3.987319"], ["83964.63", "0.001810"], ["83958.00", "3.896698"], ["83956.23", "0.003620"], ["83949.50", "4.259181"], ["83941.00", "5.074769"], ["83932.50", "4.802906"], ["83924.00", "4.984148"], ["83915.50", "5.165390"], ["83907.00", "5.256011"], ["83890.00", "4.077939"], ["83881.50", "4.621665"], ["83873.00", "4.531044"], ["83864.50", "4.349802"], ["83856.00", "5.618494"], ["83847.50", "5.346632"], ["83839.00", "4.168560"], ["83830.50", "4.712286"], ["83651.65", "0"], ["83651.16", "0"]], "checksum": -1554883677, "ts": "1742555182752"}], "ts": 1742555182757, "record_time": 1742555182.780846, "EXCHANGE": "BITGET"}
{"action": "update", "arg": {"instType": "SPOT", "channel": "books", "instId": "BTCUSDT"}, "data": [{"asks": [["84084.14", "0"], ["84160.20", "5.165390"], ["84168.70", "4.077939"], ["84177.20", "3.896698"], ["84185.70", "4.440423"], ["84194.20", "5.346632"], ["84202.70", "4.168560"], ["84211.20", "4.984148"], ["84219.70", "5.074769"], ["84228.20", "4.712286"], ["84236.70", "3.987319"], ["84245.20", "4.531044"], ["84253.70", "4.802906"], ["84262.20", "5.618494"], ["84270.70", "5.527873"], ["84279.20", "4.893527"], ["84287.70", "5.256011"], ["84296.20", "4.259181"], ["84304.70", "4.621665"], ["84313.20", "5.437252"], ["84321.70", "4.349802"], ["84535.32", "0.000039"]], "bids": [["84036.90", "0.021425"], ["84036.00", "0.364702"], ["84034.00", "0.959741"], ["83992.00", "4.802906"], ["83983.50", "4.259181"], ["83975.00", "4.984148"], ["83966.50", "5.165390"], ["83958.00", "5.074769"], ["83949.50", "4.893527"], ["83941.00", "4.168560"], ["83932.50", "4.621665"], ["83924.00", "5.256011"], ["83915.50", "4.077939"], ["83907.00", "5.437252"], ["83898.50", "3.896698"], ["83890.00", "3.987319"], ["83881.50", "4.531044"], ["83873.00", "5.527873"], ["83864.50", "4.440423"], ["83856.00", "5.346632"], ["83847.50", "4.712286"], ["83839.00", "5.618494"], ["83830.50", "4.349802"]], "checksum": -1554883677, "ts": "1742555182959"}], "ts": 1742555182966, "record_time": 1742555182.989645, "EXCHANGE": "BITGET"}
{"action": "update", "arg": {"instType": "SPOT", "channel": "books", "instId": "BTCUSDT"}, "data": [{"asks": [["84084.14", "0.043725"], ["84086.36", "0.175469"], ["84098.20", "0.001522"], ["84104.20", "0.017523"], ["84106.20", "0.046113"], ["84108.20", "0.121351"], ["84110.20", "0.319344"], ["84112.20", "0.840379"], ["84114.20", "2.211523"], ["84116.20", "5.819798"], ["84118.20", "15.315259"], ["84160.20", "3.896698"], ["84168.70", "4.531044"], ["84177.20", "5.074769"], ["84185.70", "4.802906"], ["84194.20", "5.437252"], ["84202.70", "5.346632"], ["84219.70", "4.168560"], ["84228.20", "4.893527"], ["84236.70", "5.256011"], ["84245.20", "4.259181"], ["84248.21", "0"], ["84253.70", "5.165390"], ["84262.20", "4.712286"], ["84279.20", "5.618494"], ["84287.70", "4.621665"], ["84296.20", "4.077939"], ["84304.70", "4.440423"], ["84313.20", "3.987319"], ["84535.32", "0"]], "bids": [["84042.00", "0.020225"], ["84040.00", "0.053223"], ["84038.00", "0.140061"], ["84036.97", "0.112799"], ["84036.00", "0.368582"], ["84034.00", "0.969953"], ["83992.00", "4.077939"], ["83983.50", "3.987319"], ["83975.00", "5.256011"], ["83966.50", "4.168560"], ["83958.00", "5.618494"], ["83949.50", "5.437252"], ["83941.00", "5.346632"], ["83932.50", "4.440423"], ["83924.00", "4.531044"], ["83915.50", "4.802906"], ["83907.00", "4.349802"], ["83890.00", "5.074769"], ["83881.50", "4.984148"], ["83864.50", "4.259181"], ["83856.00", "4.893527"], ["83847.50", "4.621665"], ["83839.00", "4.712286"], ["83830.50", "5.165390"], ["83652.48", "0"]], "checksum": -1150751993, "ts": "1742555183170"}], "ts": 1742555183178, "record_time": 1742555183.219642, "EXCHANGE": "BITGET"}
{"action": "update", "arg": {"instType": "SPOT", "channel": "books", "instId": "BTCUSDT"}, "data": [{"asks": [["84053.91", "1.394984"], ["84110.19", "0.196904"], ["84160.20", "4.259181"], ["84168.70", "5.256011"], ["84177.20", "4.712286"], ["84185.70", "5.165390"], ["84194.20", "4.168560"], ["84202.70", "4.531044"], ["84211.20", "4.621665"], ["84219.70", "3.896698"], ["84228.20", "5.437252"], ["84236.70", "5.074769"], ["84245.20", "4.077939"], ["84253.70", "4.440423"], ["84262.20", "4.984148"], ["84279.20", "3.987319"], ["84287.70", "4.893527"], ["84296.20", "4.349802"], ["84304.70", "4.802906"], ["84313.20", "5.618494"], ["84321.70", "5.346632"]], "bids": [["84046.00", "0.002744"], ["84044.00", "0.007222"], ["84042.00", "0.019005"], ["84040.00", "0.050014"], ["84038.00", "0.131614"], ["84036.00", "0.346353"], ["84034.00", "0.911456"], ["83992.00", "3.987319"], ["83983.50", "5.256011"], ["83975.00", "4.349802"], ["83966.50", "4.440423"], ["83958.00", "4.259181"], ["83949.50", "4.621665"], ["83941.00", "5.165390"], ["83932.50", "4.802906"], ["83924.00", "5.437252"], ["83915.50", "4.893527"], ["83907.00", "5.074769"], ["83898.50", "4.077939"], ["83890.00", "3.896698"], ["83881.50", "5.618494"], ["83873.00", "5.346632"], ["83864.50", "4.531044"], ["83856.00", "4.712286"], ["83847.50", "5.527873"], ["83839.00", "4.168560"], ["83830.50", "4.984148"]], "checksum": -235795666, "ts": "1742555183383"}], "ts": 1742555183387, "record_time": 1742555183.40887, "EXCHANGE": "BITGET"}
{"action": "update", "arg": {"instType": "SPOT", "channel": "books", "instId": "BTCUSDT"}, "data": [{"asks": [["84053.91", "1.462784"], ["84074.01", "0"], ["84074.09", "0.035952"], ["84075.64", "0"], ["84075.74", "0.035961"], ["84076.16", "0"], ["84076.22", "0.006356"], ["84076.28", "0"], ["84076.37", "0.006356"], ["84076.65", "0"], ["84076.71", "0.006356"], ["84077.68", "0"], ["84077.78", "0.010984"], ["84078.61", "0"], ["84078.70", "0.006356"], ["84079.15", "0"], ["84079.22", "0.012712"], ["84079.49", "0"], ["84079.52", "0"], ["84079.56", "0.016429"], ["84079.57", "0.119883"], ["84079.66", "0"], ["84079.73", "0.006356"], ["84081.11", "0"], ["84081.12", "0"], ["84081.21", "0.010985"], ["84081.24", "0.006357"], ["84081.95", "0"], ["84082.05", "0.009990"], ["84083.97", "0"], ["84084.03", "0.119858"], ["84084.36", "0"], ["84084.44", "0.015895"], ["84084.56", "0"], ["84084.62", "0.009989"], ["84102.20", "0.006533"], ["84104.20", "0.017191"], ["84106.20", "0.045240"], ["84108.20", "0.119052"], ["84110.20", "0.313296"], ["84112.20", "0.824462"], ["84114.20", "2.169637"], ["84116.20", "5.709573"], ["84118.20", "15.025192"], ["84160.20", "4.621665"], ["84168.70", "4.168560"], ["84177.20", "5.437252"], ["84185.70", "5.346632"], ["84194.20", "5.074769"], ["84202.70", "4.259181"], ["84211.20", "5.165390"], ["84228.20", "4.712286"], ["84236.70", "4.077939"], ["84245.20", "4.531044"], ["84246.84", "0.167130"], ["84262.20", "5.618494"], ["84270.70", "5.256011"], ["84279.20", "4.893527"], ["84287.70", "4.984148"], ["84296.20", "5.527873"], ["84304.70", "3.987319"], ["84313.20", "4.802906"], ["84321.70", "4.349802"], ["84534.53", "0"]], "bids": [["84033.75", "0.089495"], ["84033.66", "0"], ["84032.04", "0.083949"], ["84031.93", "0"], ["84031.67", "0.017819"], ["84031.61", "0"], ["84031.49", "0.018257"], ["84031.39", "0"], ["84031.15", "0.005947"], ["84031.09", "0"], ["84030.04", "0.055662"], ["84029.94", "0"], ["84029.11", "0.007340"], ["84029.01", "0"], ["84028.62", "0.330974"], ["84028.55", "0"], ["84028.30", "0.224908"], ["84028.28", "0.025187"], ["84028.25", "0"], ["84028.22", "0"], ["84028.13", "0.017353"], ["84028.12", "0.008186"], ["84028.07", "0"], ["84028.05", "0"], ["84026.60", "0.012657"], ["84026.57", "0.051969"], ["84026.48", "0"], ["84025.73", "0.018519"], ["84025.63", "0"], ["84023.85", "0.222694"], ["84023.79", "0"], ["84023.41", "0.076121"], ["84023.34", "0"], ["84023.26", "0.021132"], ["84023.20", "0"], ["83992.00", "4.259181"], ["83983.50", "4.440423"], ["83975.00", "4.712286"], ["83966.50", "5.256011"], ["83958.00", "5.165390"], ["83949.50", "4.802906"], ["83941.00", "4.077939"], ["83932.50", "5.527873"], ["83924.00", "4.168560"], ["83907.00", "4.531044"], ["83898.50", "5.618494"], ["83881.50", "5.346632"], ["83873.00", "4.984148"], ["83864.50", "5.074769"], ["83856.00", "4.621665"], ["83847.50", "4.349802"], ["83839.00", "5.437252"], ["83830.50", "3.987319"]], "checksum": -397609804, "ts": "1742555183593"}], "ts": 1742555183597, "record_time": 1742555183.629099, "EXCHANGE": "BITGET"}
{"action": "update", "arg": {"instType": "SPOT", "channel": "books", "instId": "BTCUSDT"}, "data": [{"asks": [["84102.20", "0.006652"], ["84104.20", "0.017505"], ["84106.20", "0.046065"], ["84108.20", "0.121224"], ["84110.20", "0.319011"], ["84112.20", "0.839502"], ["84114.20", "2.209216"], ["84116.20", "5.813727"], ["84118.20", "15.299281"], ["84160.20", "3.987319"], ["84168.70", "3.896698"], ["84185.70", "5.165390"], ["84194.20", "4.259181"], ["84202.70", "5.074769"], ["84211.20", "4.440423"], ["84219.70", "5.527873"], ["84228.20", "4.621665"], ["84245.20", "4.802906"], ["84253.70", "5.346632"], ["84262.20", "4.712286"], ["84270.70", "4.168560"], ["84279.20", "4.349802"], ["84287.70", "5.618494"], ["84296.20", "4.531044"], ["84304.70", "4.893527"], ["84313.20", "5.256011"], ["84321.70", "4.984148"]], "bids": [["83992.00", "5.437252"], ["83983.50", "4.984148"], ["83966.50", "4.531044"], ["83958.00", "3.987319"], ["83949.50", "4.259181"], ["83941.00", "4.349802"], ["83932.50", "5.256011"], ["83924.00", "5.346632"], ["83915.50", "5.527873"], ["83907.00", "4.077939"], ["83898.50", "4.893527"], ["83881.50", "4.440423"], ["83873.00", "4.168560"], ["83864.50", "5.618494"], ["83856.00", "4.802906"], ["83847.50", "4.621665"], ["83839.00", "5.074769"], ["83830.50", "5.165390"]], "checksum": -397609804, "ts": "1742555183794"}], "ts": 1742555183798, "record_time": 1742555183.820186, "EXCHANGE": "BITGET"}
{"action": "update", "arg": {"instType": "SPOT", "channel": "books", "instId": "BTCUSDT"}, "data": [{"asks": [["84110.20", "0.319144"], ["84112.20", "0.839851"], ["84114.20", "2.209976"], ["84116.20", "5.815727"], ["84118.20", "15.304545"], ["84160.20", "4.168560"], ["84168.70", "5.527873"], ["84177.20", "4.893527"], ["84185.70", "4.621665"], ["84194.20", "5.256011"], ["84202.70", "4.712286"], ["84211.20", "4.349802"], ["84219.70", "4.440423"], ["84228.20", "4.259181"], ["84245.20", "4.531044"], ["84253.70", "5.165390"], ["84262.20", "4.802906"], ["84270.70", "4.984148"], ["84279.20", "5.346632"], ["84287.70", "3.987319"], ["84296.20", "5.437252"], ["84304.70", "5.074769"], ["84313.20", "5.618494"], ["84321.70", "3.896698"]], "bids": [["84051.70", "0"], ["84051.68", "0.027856"], ["84045.41", "0"], ["84042.00", "0.018792"], ["84040.00", "0.049453"], ["84038.00", "0.130140"], ["84036.00", "0.342473"], ["84034.00", "0.901244"], ["84028.20", "0.101160"], ["83992.00", "4.712286"], ["83983.50", "5.165390"], ["83975.00", "4.168560"], ["83966.50", "4.349802"], ["83958.00", "3.896698"], ["83949.50", "5.437252"], ["83941.00", "4.531044"], ["83932.50", "4.077939"], ["83924.00", "5.618494"], ["83915.50", "4.440423"], ["83907.00", "3.987319"], ["83890.00", "5.256011"], ["83881.50", "4.259181"], ["83873.00", "5.527873"], ["83864.50", "5.074769"], ["83856.00", "4.621665"], ["83847.50", "5.346632"], ["83839.00", "4.802906"], ["83830.50", "4.984148"], ["83652.48", "0.000188"]], "checksum": -1119829159, "ts": "1742555184003"}], "ts": 1742555184005, "record_time": 1742555184.033446, "EXCHANGE": "BITGET"}
{"action": "update", "arg": {"instType": "SPOT", "channel": "books", "instId": "BTCUSDT"}, "data": [{"asks": [["84052.01", "0.231176"], ["84053.73", "0.005575"], ["84053.90", "0.008040"], ["84053.91", "0.833700"], ["84053.92", "0"], ["84053.99", "0.209200"], ["84054.01", "0.000234"], ["84069.01", "0.221095"], ["84074.49", "0"], ["84075.12", "0"], ["84076.22", "0.012712"], ["84078.05", "0"], ["84078.24", "0"], ["84078.71", "0"], ["84079.75", "0"], ["84083.03", "0"], ["84084.14", "0.090900"], ["84084.15", "0"], ["84088.36", "0"], ["84088.61", "0"], ["84089.27", "0"], ["84098.30", "0.000958"], ["84100.20", "0.002638"], ["84102.20", "0.006942"], ["84103.85", "0"], ["84104.20", "0.018270"], ["84106.20", "0.048078"], ["84108.20", "0.126522"], ["84108.40", "0.207473"], ["84108.65", "0"], ["84110.20", "0.332952"], ["84110.64", "0"], ["84112.20", "0.876190"], ["84114.20", "2.305761"], ["84116.20", "6.067793"], ["84118.20", "15.967877"], ["84141.96", "0"], ["84160.20", "4.712286"], ["84165.70", "0"], ["84168.70", "5.437252"], ["84171.60", "0.302898"], ["84176.90", "0"], ["84177.20", "5.346632"], ["84185.69", "0"], ["84185.70", "4.168560"], ["84194.20", "4.349802"], ["84202.70", "5.165390"], ["84202.75", "0"], ["84202.86", "0"], ["84211.20", "5.074769"], ["84219.70", "4.893527"], ["84222.00", "0.001469"], ["84228.20", "4.077939"], ["84236.70", "4.621665"], ["84245.20", "5.527873"], ["84253.70", "4.531044"], ["84262.20", "3.987319"], ["84264.10", "0"], ["84279.20", "4.802906"], ["84287.70", "5.618494"], ["84296.20", "4.440423"], ["84304.70", "4.259181"], ["84313.20", "5.256011"], ["84315.70", "0"], ["84339.10", "0"], ["84347.20", "0.000860"], ["84419.90", "0.002343"], ["84534.53", "0.000461"], ["84535.32", "0.000039"], ["84536.36", "0.000053"], ["84537.04", "0.000958"], ["84538.75", "0.000011"], ["84540.00", "0.001092"], ["84540.54", "0.000184"], ["84540.97", "0.000065"], ["84541.67", "0.000198"], ["84542.37", "0.001213"], ["84543.27", "0.000067"], ["84543.43", "0.000423"], ["84543.86", "0.000033"], ["84543.93", "0.000010"], ["84544.64", "0.000036"], ["84545.16", "0.000020"]], "bids": [["84053.90", "0"], ["84053.89", "0"], ["84053.20", "0"], ["84053.00", "0"], ["84051.68", "0"], ["84039.99", "0"], ["84038.33", "0"], ["84036.97", "0"], ["84036.01", "0"], ["84033.41", "0"], ["84033.27", "0"], ["84031.66", "0"], ["84029.80", "0"], ["84029.66", "0"], ["84029.12", "0"], ["84028.21", "0"], ["84024.87", "0"], ["84024.30", "0.772620"], ["84023.63", "0"], ["84022.60", "0"], ["84019.43", "0"], ["84018.66", "0"], ["84011.70", "0.153580"], ["84001.50", "0.000396"], ["83998.38", "0"], ["83996.49", "0"], ["83992.00", "5.527873"], ["83983.50", "4.077939"], ["83975.00", "3.896698"], ["83972.10", "0.000948"], ["83966.50", "4.893527"], ["83958.00", "4.802906"], ["83949.50", "4.349802"], ["83941.00", "4.712286"], ["83939.60", "0"], ["83932.50", "5.256011"], ["83928.50", "0"], ["83924.00", "5.165390"], ["83917.50", "0.001459"], ["83915.50", "4.984148"], ["83907.00", "4.168560"], ["83898.50", "5.074769"], ["83890.00", "5.346632"], ["83881.50", "5.618494"], ["83873.00", "4.531044"], ["83872.00", "0"], ["83864.50", "3.987319"], ["83862.00", "0"], ["83856.00", "5.437252"], ["83847.50", "4.440423"], ["83840.90", "0"], ["83839.00", "4.621665"], ["83830.50", "4.259181"], ["83829.70", "0"], ["83810.41", "0"], ["83699.00", "0.002419"], ["83651.65", "0.000018"], ["83651.16", "0.000896"], ["83650.84", "0.003326"], ["83650.00", "0.032056"], ["83648.96", "0.000030"], ["83647.46", "0.000224"], ["83647.06", "0.000040"], ["83646.67", "0.000018"], ["83645.83", "0.000014"], ["83644.86", "0.000034"], ["83644.33", "0.000013"], ["83643.18", "0.000052"], ["83641.86", "0.000379"], ["83641.62", "0.002925"], ["83641.38", "0.000135"], ["83641.00", "0.000082"], ["83640.35", "0.000022"], ["83640.15", "0.000423"], ["83640.00", "0.002013"], ["83639.71", "0.000041"], ["83639.70", "0.000010"], ["83639.15", "0.000009"], ["83638.32", "0.000039"], ["83638.30", "0.000137"]], "checksum": 2088267995, "ts": "1742555184204"}], "ts": 1742555184207, "record_time": 1742555184.231977, "EXCHANGE": "BITGET"}
{"action": "update", "arg": {"instType": "SPOT", "channel": "books", "instId": "BTCUSDT"}, "data": [{"asks": [["84051.01", "2.450072"], ["84052.01", "0.876300"], ["84053.11", "0.007162"], ["84053.25", "0.006307"], ["84053.84", "0.000865"], ["84053.90", "0.296588"], ["84053.91", "0.001505"], ["84053.99", "0"], ["84054.92", "0"], ["84058.99", "0.014337"], ["84060.60", "0.012472"], ["84070.96", "0.119870"], ["84074.44", "0.006356"], ["84074.53", "0.006356"], ["84075.11", "0"], ["84075.21", "0.016429"], ["84079.49", "0.119850"], ["84080.39", "0.119867"], ["84080.44", "0"], ["84084.14", "0.043725"], ["84084.57", "0.015892"], ["84085.44", "0.010988"], ["84088.35", "0"], ["84090.47", "0"], ["84094.10", "0.001262"], ["84096.10", "0.002060"], ["84098.10", "0.005644"], ["84098.20", "0"], ["84100.10", "0.014854"], ["84100.20", "0"], ["84102.10", "0.039089"], ["84102.20", "0"], ["84103.84", "0"], ["84104.10", "0.102865"], ["84104.20", "0"], ["84105.58", "0.001598"], ["84106.10", "0.270698"], ["84106.20", "0"], ["84107.37", "0.001597"], ["84108.10", "0.712364"], ["84108.20", "0"], ["84110.10", "1.874641"], ["84110.20", "0"], ["84112.10", "4.933266"], ["84112.20", "0"], ["84114.10", "12.982279"], ["84114.20", "0"], ["84114.50", "0.006030"], ["84114.60", "9.050100"], ["84114.70", "0.001740"], ["84114.80", "0.107790"], ["84115.10", "0.001740"], ["84115.60", "1.350390"], ["84115.80", "0.035670"], ["84116.10", "0.067980"], ["84116.20", "0"], ["84116.40", "0.035670"], ["84116.50", "0.257790"], ["84117.00", "0.120180"], ["84117.10", "2.406900"], ["84117.60", "0.442620"], ["84118.10", "0.140970"], ["84118.20", "3.544110"], ["84118.80", "0"], ["84118.90", "0"], ["84119.20", "0"], ["84119.40", "0"], ["84119.80", "0"], ["84119.90", "0"], ["84120.10", "0.067800"], ["84120.50", "0"], ["84120.80", "0.035670"], ["84121.70", "0"], ["84122.30", "1.976580"], ["84122.50", "1.335120"], ["84123.10", "0"], ["84124.10", "0"], ["84124.20", "0"], ["84124.50", "0"], ["84124.60", "0"], ["84124.90", "0"], ["84125.00", "0"], ["84125.80", "0"], ["84156.10", "3.896887"], ["84160.20", "0"], ["84164.60", "4.712514"], ["84168.31", "0.071253"], ["84168.70", "0"], ["84169.98", "0.071045"], ["84173.10", "5.618767"], ["84177.20", "0"], ["84181.60", "4.168763"], ["84185.70", "0"], ["84190.10", "5.165641"], ["84194.20", "0"], ["84198.60", "4.350013"], ["84202.70", "0"], ["84207.10", "5.528142"], ["84211.20", "0"], ["84215.60", "5.346891"], ["84219.70", "0"], ["84224.10", "4.984390"], ["84228.20", "0"], ["84232.60", "4.440638"], ["84236.70", "0"], ["84241.10", "4.621889"], ["84245.20", "0"], ["84249.60", "4.803139"], ["84253.70", "0"], ["84258.10", "4.531264"], ["84262.20", "0"], ["84266.60", "4.893765"], ["84270.70", "0.209200"], ["84275.10", "5.437516"], ["84279.20", "0"], ["84283.60", "3.987512"], ["84287.70", "0"], ["84292.10", "4.259388"], ["84296.20", "0"], ["84299.00", "0.001720"], ["84300.60", "5.256266"], ["84304.70", "0"], ["84309.10", "4.078137"], ["84313.20", "0"], ["84317.60", "5.075015"], ["84321.70", "0"], ["84337.95", "0"], ["84347.20", "0"], ["84540.00", "0"], ["84540.54", "0"], ["84540.97", "0"], ["84541.67", "0"], ["84542.37", "0"], ["84543.27", "0"], ["84543.43", "0"], ["84543.86", "0"], ["84543.93", "0"], ["84544.64", "0"], ["84545.16", "0"]], "bids": [["84052.00", "0"], ["84050.00", "0.000032"], ["84049.90", "0.001029"], ["84048.00", "0.000032"], ["84047.90", "0.001000"], ["84046.00", "0.000032"], ["84045.90", "0.001011"], ["84044.00", "0.000032"], ["84043.90", "0.001028"], ["84043.11", "0.027856"], ["84042.00", "0.000032"], ["84041.90", "0.001038"], ["84041.04", "0"], ["84040.00", "0.011262"], ["84039.90", "0.001047"], ["84038.00", "0.000032"], ["84037.90", "0.001022"], ["84036.00", "0.000032"], ["84035.90", "0.001593"], ["84035.73", "0.112797"], ["84034.00", "0.000032"], ["84033.90", "0.004192"], ["84033.70", "0"], ["84033.60", "0"], ["84033.40", "0"], ["84031.90", "0.011033"], ["84030.40", "0"], ["84029.90", "0.029035"], ["84029.80", "0.006270"], ["84029.78", "0.247615"], ["84029.50", "0.006210"], ["84029.40", "0.001012"], ["84029.21", "0.012472"], ["84029.20", "0.001026"], ["84029.10", "0.001039"], ["84028.20", "0"], ["84028.10", "0"], ["84027.66", "0.004018"], ["84027.50", "0"], ["84027.20", "0"], ["84026.90", "0.070140"], ["84026.29", "0.017105"], ["84025.86", "0.007132"], ["84025.62", "0.028868"], ["84025.20", "0"], ["84024.80", "0.085770"], ["84024.50", "0"], ["84024.30", "0"], ["84023.67", "0"], ["84023.40", "0"], ["84022.80", "0.498990"], ["84022.60", "0.240210"], ["84022.50", "0.120000"], ["84022.40", "0.535200"], ["84021.90", "0.007050"], ["84021.80", "0.120000"], ["84021.70", "0.009000"], ["84021.40", "0.237090"], ["84021.32", "0.268407"], ["84020.90", "0.120000"], ["84020.30", "0.012510"], ["84020.10", "0.120000"], ["84019.90", "0.071370"], ["84019.88", "0.259825"], ["84019.40", "0.066240"], ["84018.50", "0.120000"], ["84018.40", "0.120000"], ["84018.30", "0.120000"], ["84018.10", "0.060630"], ["84015.64", "0.073223"], ["84014.95", "0.033926"], ["84014.84", "0.056374"], ["83995.31", "0.001176"], ["83993.23", "0.001173"], ["83992.00", "0"], ["83987.90", "4.531264"], ["83983.50", "0"], ["83982.20", "0.200459"], ["83979.40", "4.621889"], ["83975.00", "0"], ["83970.90", "5.256266"], ["83966.50", "0"], ["83962.40", "3.987512"], ["83958.00", "0"], ["83953.90", "5.346891"], ["83949.50", "0"], ["83945.40", "4.712514"], ["83941.00", "0"], ["83936.90", "5.165641"], ["83932.50", "0"], ["83928.40", "4.440638"], ["83924.00", "0"], ["83921.20", "0.303578"], ["83919.90", "3.896887"], ["83915.50", "0"], ["83911.40", "4.078137"], ["83907.00", "0"], ["83902.90", "5.075015"], ["83898.50", "0"], ["83894.40", "5.437516"], ["83890.00", "0"], ["83885.90", "4.168763"], ["83881.50", "0"], ["83877.40", "5.528142"], ["83873.00", "0"], ["83868.90", "4.803139"], ["83864.50", "0"], ["83860.40", "4.259388"], ["83856.00", "0"], ["83851.90", "4.350013"], ["83848.45", "0.209200"], ["83847.50", "0"], ["83843.40", "4.893765"], ["83839.00", "0"], ["83834.90", "4.984390"], ["83830.50", "0"], ["83826.40", "5.618767"], ["83654.23", "0"], ["83653.94", "0"], ["83653.67", "0"], ["83653.31", "0"], ["83652.80", "0"], ["83652.48", "0"], ["83651.65", "0"], ["83651.16", "0"], ["83650.84", "0"], ["83650.00", "0"], ["83648.96", "0"], ["83647.46", "0"], ["83647.06", "0"], ["83646.67", "0"], ["83645.83", "0"], ["83644.86", "0"], ["83644.33", "0"], ["83643.18", "0"], ["83641.86", "0"], ["83641.62", "0"], ["83641.38", "0"], ["83641.00", "0"], ["83640.35", "0"], ["83640.15", "0"], ["83640.00", "0"], ["83639.71", "0"], ["83639.70", "0"], ["83639.15", "0"], ["83638.32", "0"], ["83638.30", "0"]], "checksum": 1903699054, "ts": "1742555184411"}], "ts": 1742555184415, "record_time": 1742555184.445144, "EXCHANGE": "BITGET"}
{"action": "update", "arg": {"instType": "SPOT", "channel": "books", "instId": "BTCUSDT"}, "data": [{"asks": [["84049.01", "0.535707"], ["84049.45", "0.132520"], ["84049.91", "0.369700"], ["84050.01", "0.245840"], ["84051.01", "0.457524"], ["84052.01", "0.198877"], ["84053.11", "0"], ["84053.25", "0"], ["84053.73", "0"], ["84053.84", "0"], ["84053.90", "0"], ["84053.93", "0"], ["84057.31", "1.531031"], ["84060.60", "0"], ["84063.01", "0"], ["84066.74", "0.035952"], ["84068.21", "0.093942"], ["84068.57", "0.035961"], ["84068.95", "0.006356"], ["84069.01", "0.209200"], ["84069.11", "0.006356"], ["84069.44", "0.006356"], ["84069.93", "0.012472"], ["84070.56", "0.010984"], ["84071.53", "0.006356"], ["84071.87", "0.006356"], ["84071.95", "0.006356"], ["84072.20", "0.016429"], ["84072.31", "0.119883"], ["84072.60", "0.006356"], ["84073.97", "0.006357"], ["84074.04", "0.010985"], ["84074.09", "0"], ["84074.82", "0.009990"], ["84075.74", "0"], ["84076.22", "0.006356"], ["84076.37", "0"], ["84076.71", "0"], ["84076.76", "0.119858"], ["84077.08", "0.015895"], ["84077.35", "0.009989"], ["84077.78", "0"], ["84078.70", "0"], ["84079.22", "0"], ["84079.56", "0"], ["84079.57", "0"], ["84079.73", "0"], ["84081.21", "0"], ["84081.24", "0"], ["84082.05", "0"], ["84084.03", "0"], ["84084.44", "0"], ["84084.62", "0"], ["84084.80", "3.570717"], ["84087.00", "0.001007"], ["84089.00", "0.001630"], ["84091.00", "0.004289"], ["84093.00", "0.011287"], ["84094.10", "0"], ["84094.29", "0.713484"], ["84095.00", "0.029704"], ["84096.10", "0"], ["84097.00", "0.078167"], ["84098.10", "0"], ["84099.00", "0.205702"], ["84100.10", "0"], ["84101.00", "0.541321"], ["84102.10", "0"], ["84103.00", "1.424529"], ["84104.10", "0"], ["84105.00", "3.748761"], ["84105.51", "0"], ["84106.10", "0"], ["84107.00", "9.865161"], ["84107.30", "0.001039"], ["84107.50", "0.001740"], ["84107.70", "0.001018"], ["84107.90", "0.001036"], ["84108.00", "0.001740"], ["84108.10", "0"], ["84108.60", "0.035880"], ["84108.70", "0.120390"], ["84108.80", "0.022710"], ["84109.30", "0.035880"], ["84109.90", "0.731070"], ["84110.10", "0.067800"], ["84110.50", "0.073230"], ["84110.90", "0.534660"], ["84111.00", "0.478560"], ["84112.10", "0.067800"], ["84113.70", "0.035670"], ["84114.10", "5.445510"], ["84114.22", "0.403271"], ["84114.60", "0"], ["84114.70", "0"], ["84114.80", "0.107400"], ["84115.10", "0"], ["84115.60", "1.350000"], ["84115.80", "0"], ["84116.10", "0.067800"], ["84116.40", "0"], ["84116.50", "0.257610"], ["84117.00", "2.352030"], ["84117.10", "2.406540"], ["84117.60", "0.441450"], ["84118.10", "0.067800"], ["84118.20", "0.888840"], ["84119.00", "0.007050"], ["84119.51", "1.783177"], ["84120.10", "0"], ["84120.80", "0"], ["84120.90", "0"], ["84121.10", "0"], ["84121.30", "0"], ["84121.60", "0"], ["84122.30", "0"], ["84122.40", "0"], ["84122.50", "0"], ["84123.30", "0"], ["84123.40", "0"], ["84139.45", "0.534826"], ["84139.46", "0"], ["84149.00", "5.528611"], ["84156.10", "0"], ["84157.50", "4.803547"], ["84164.59", "0.421068"], ["84164.60", "0"], ["84166.00", "4.894180"], ["84173.10", "0"], ["84174.50", "4.259750"], ["84181.60", "0"], ["84183.00", "4.531649"], ["84190.10", "0"], ["84191.50", "5.347345"], ["84198.60", "0"], ["84200.00", "4.441016"], ["84207.10", "0"], ["84208.50", "5.619244"], ["84215.60", "0"], ["84217.00", "4.350383"], ["84224.10", "0"], ["84225.50", "5.256712"], ["84232.60", "0"], ["84234.00", "4.169117"], ["84241.10", "0"], ["84242.50", "5.437978"], ["84249.60", "0"], ["84251.00", "4.078484"], ["84258.10", "0"], ["84259.50", "3.987851"], ["84262.10", "0.001403"], ["84266.60", "0"], ["84268.00", "4.622282"], ["84275.10", "0"], ["84276.50", "3.897218"], ["84283.60", "0"], ["84285.00", "5.166079"], ["84292.10", "0"], ["84293.50", "4.712914"], ["84300.60", "0"], ["84302.00", "4.984813"], ["84309.10", "0"], ["84310.50", "5.075446"], ["84317.60", "0"], ["84358.10", "0"], ["84534.53", "0"], ["84535.32", "0"], ["84536.36", "0"], ["84537.04", "0"], ["84538.75", "0"]], "bids": [["84051.00", "0"], ["84050.00", "0"], ["84049.90", "0"], ["84047.90", "0"], ["84045.90", "0"], ["84043.90", "0"], ["84042.80", "0.001004"], ["84041.90", "0"], ["84040.80", "0.001038"], ["84040.16", "0"], ["84040.10", "0"], ["84040.00", "0.001261"], ["84039.90", "0"], ["84039.60", "0"], ["84039.58", "0"], ["84039.55", "0"], ["84039.53", "0"], ["84039.51", "0"], ["84038.80", "0.001145"], ["84037.90", "0"], ["84036.80", "0.003012"], ["84036.07", "0"], ["84035.93", "0"], ["84035.90", "0"], ["84035.88", "0"], ["84035.43", "0"], ["84035.40", "0"], ["84035.39", "0"], ["84035.38", "0"], ["84035.37", "0"], ["84035.33", "0"], ["84034.80", "0.007926"], ["84033.90", "0"], ["84033.75", "0"], ["84032.80", "0.020857"], ["84032.66", "0"], ["84032.04", "0"], ["84031.90", "0"], ["84031.68", "0.193743"], ["84031.67", "0"], ["84031.49", "0"], ["84031.15", "0"], ["84030.80", "0.054889"], ["84030.04", "0.008503"], ["84029.97", "0.005921"], ["84029.90", "0"], ["84029.86", "0.010001"], ["84029.80", "0"], ["84029.50", "0"], ["84029.40", "0"], ["84029.20", "0"], ["84029.15", "0.009717"], ["84029.11", "0"], ["84029.10", "0"], ["84029.09", "0.016035"], ["84029.07", "0.009589"], ["84029.06", "0.007469"], ["84029.04", "0.007752"], ["84029.00", "0.000032"], ["84028.80", "0.144443"], ["84028.63", "0.247114"], ["84028.62", "0.314035"], ["84028.30", "0"], ["84028.28", "0"], ["84028.13", "0"], ["84028.12", "0"], ["84026.90", "0"], ["84026.80", "0.380240"], ["84026.60", "0"], ["84026.57", "0"], ["84026.40", "0.089498"], ["84025.90", "0"], ["84025.86", "0.016029"], ["84025.78", "0.010336"], ["84025.75", "0.008713"], ["84025.73", "0"], ["84024.95", "0.009864"], ["84024.94", "0"], ["84024.92", "0.010288"], ["84024.90", "0.008537"], ["84024.87", "0.089536"], ["84024.85", "0.004828"], ["84024.80", "1.000631"], ["84024.51", "0.699196"], ["84024.41", "0.017820"], ["84024.23", "0.018257"], ["84023.89", "0.005947"], ["84023.85", "0"], ["84023.41", "0"], ["84023.30", "0"], ["84023.26", "0"], ["84022.82", "0.055664"], ["84022.80", "2.633239"], ["84022.60", "0.243360"], ["84022.50", "0.121230"], ["84022.40", "0.679890"], ["84021.95", "0.007340"], ["84021.80", "0.120390"], ["84021.60", "0.006162"], ["84021.40", "0"], ["84021.36", "0.008995"], ["84021.27", "0.007944"], ["84021.04", "0.224915"], ["84020.99", "0.008186"], ["84020.94", "0.025188"], ["84020.90", "1.097280"], ["84020.87", "0.017353"], ["84020.30", "0"], ["84019.41", "0.051971"], ["84019.40", "0.274860"], ["84019.34", "0.012657"], ["84018.51", "0.018520"], ["84018.00", "0.015000"], ["84017.90", "0.022230"], ["84017.70", "5.063340"], ["84017.50", "1.858380"], ["84017.20", "1.426530"], ["84017.10", "0.525630"], ["84016.96", "0"], ["84016.90", "0.006000"], ["84016.70", "0.120000"], ["84016.59", "0.222702"], ["84016.10", "2.392290"], ["84016.06", "0.076124"], ["84016.00", "0.021165"], ["84015.90", "0.120000"], ["84015.05", "0"], ["84015.03", "0"], ["84014.96", "0"], ["84014.95", "0.027453"], ["84014.85", "0.008269"], ["84014.81", "0"], ["84014.60", "0.420000"], ["84014.11", "0"], ["84014.05", "0"], ["84013.97", "0"], ["84013.19", "0.008061"], ["84009.80", "0.000876"], ["84007.04", "0"], ["84007.01", "0"], ["84006.90", "0"], ["84005.72", "0.008322"], ["84005.71", "0.008015"], ["84005.65", "0.008428"], ["84005.64", "0.006474"], ["84005.53", "0.008598"], ["84004.19", "0.009212"], ["84004.09", "0.006906"], ["84004.07", "0.007305"], ["83998.52", "0"], ["83997.08", "0.005053"], ["83997.01", "0.008267"], ["83996.96", "0.008095"], ["83991.23", "0"], ["83991.11", "0.003597"], ["83988.28", "0"], ["83987.90", "0"], ["83986.45", "0"], ["83986.42", "0"], ["83986.38", "0"], ["83981.26", "0.007436"], ["83980.80", "4.078484"], ["83979.40", "0"], ["83978.35", "0.008574"], ["83977.13", "0.007338"], ["83977.07", "0.014902"], ["83972.30", "5.528611"], ["83970.90", "0"], ["83963.80", "5.075446"], ["83962.40", "0"], ["83955.30", "4.712914"], ["83953.90", "0"], ["83946.80", "5.166079"], ["83945.40", "0"], ["83938.30", "4.169117"], ["83936.90", "0"], ["83929.80", "3.897218"], ["83928.40", "0"], ["83921.30", "5.619244"], ["83919.90", "0"], ["83912.80", "5.256712"], ["83911.40", "0"], ["83904.30", "4.803547"], ["83902.90", "0"], ["83895.80", "4.622282"], ["83894.40", "0"], ["83887.30", "4.894180"], ["83885.90", "0"], ["83878.80", "5.347345"], ["83877.40", "0"], ["83870.30", "4.984813"], ["83868.90", "0"], ["83861.80", "4.441016"], ["83860.40", "0"], ["83853.30", "3.987851"], ["83851.90", "0"], ["83844.80", "4.531649"], ["83843.40", "0"], ["83836.30", "4.259750"], ["83834.90", "0"], ["83827.80", "4.350383"], ["83826.40", "0"], ["83819.30", "5.437978"], ["83654.23", "0.000009"], ["83653.94", "0.000133"]], "checksum": -870686388, "ts": "1742555184614"}], "ts": 1742555184619, "record_time": 1742555184.648522, "EXCHANGE": "BITGET"}
{"action": "update", "arg": {"instType": "SPOT", "channel": "books", "instId": "BTCUSDT"}, "data": [{"asks": [["84049.01", "1.296701"], ["84049.45", "0"], ["84049.91", "0"], ["84050.01", "0"], ["84051.01", "0.446404"], ["84052.01", "0"], ["84089.00", "0.001496"], ["84091.00", "0.003936"], ["84093.00", "0.010359"], ["84095.00", "0.027260"], ["84097.00", "0.071738"], ["84099.00", "0.188784"], ["84101.00", "0.496800"], ["84103.00", "1.307367"], ["84105.00", "3.440441"], ["84107.00", "9.053792"], ["84108.70", "0.120210"], ["84109.90", "0.730860"], ["84114.10", "3.635160"], ["84114.80", "0"], ["84115.40", "0.009990"], ["84117.00", "2.351040"], ["84117.10", "1.327500"], ["84117.60", "0.291390"], ["84118.20", "0.738780"], ["84118.60", "0.356940"], ["84139.45", "0"], ["84157.50", "3.897218"], ["84166.00", "4.350383"], ["84174.50", "4.803547"], ["84183.00", "5.437978"], ["84191.50", "4.622282"], ["84200.00", "4.531649"], ["84208.50", "5.075446"], ["84217.00", "4.894180"], ["84225.50", "4.712914"], ["84234.00", "5.347345"], ["84242.50", "5.619244"], ["84251.00", "5.256712"], ["84259.50", "4.259750"], ["84268.00", "4.169117"], ["84276.50", "4.441016"], ["84285.00", "4.078484"], ["84293.50", "3.987851"], ["84310.50", "5.166079"], ["84534.53", "0.000461"], ["84535.32", "0.000039"], ["84536.36", "0.000053"], ["84537.04", "0.000958"]], "bids": [["84049.00", "0.000100"], ["84048.99", "0.154613"], ["84048.98", "0.000100"], ["84048.97", "0.000100"], ["84048.00", "0"], ["84047.00", "0"], ["84042.81", "0.041115"], ["84038.80", "0.001952"], ["84036.80", "0.005135"], ["84034.80", "0.013515"], ["84032.80", "0.035566"], ["84031.68", "0.013738"], ["84030.80", "0.093595"], ["84028.80", "0.246302"], ["84026.80", "0.648163"], ["84024.80", "1.705692"], ["84024.51", "1.814807"], ["84022.80", "4.488664"], ["84022.40", "0.508710"], ["84021.70", "0"], ["84019.60", "0.070860"], ["84019.30", "0.069540"], ["84018.31", "0.230367"], ["84018.10", "0.045540"], ["83980.80", "4.894180"], ["83972.30", "4.531649"], ["83963.80", "5.256712"], ["83955.30", "5.528611"], ["83946.80", "5.075446"], ["83938.30", "5.437978"], ["83921.30", "4.078484"], ["83912.80", "5.347345"], ["83904.30", "4.441016"], ["83895.80", "4.712914"], ["83887.30", "5.166079"], ["83878.80", "3.987851"], ["83870.30", "4.622282"], ["83861.80", "5.619244"], ["83853.30", "4.169117"], ["83844.80", "4.803547"], ["83836.30", "4.350383"], ["83827.80", "4.984813"], ["83819.30", "4.259750"], ["83656.60", "0"], ["83655.00", "0"], ["83654.23", "0"], ["83653.94", "0"]], "checksum": 1196831615, "ts": "1742555184831"}], "ts": 1742555184835, "record_time": 1742555184.858534, "EXCHANGE": "BITGET"}
{"action": "update", "arg": {"instType": "SPOT", "channel": "books", "instId": "BTCUSDT"}, "data": [{"asks": [["84049.00", "0.761000"], ["84049.01", "1.344992"], ["84057.30", "0.459309"], ["84065.85", "0.015367"], ["84086.36", "0"], ["84089.00", "0.001281"], ["84091.00", "0.003371"], ["84093.00", "0.008871"], ["84095.00", "0.023345"], ["84097.00", "0.061433"], ["84099.00", "0.161666"], ["84101.00", "0.425437"], ["84103.00", "1.119571"], ["84105.00", "2.946239"], ["84107.00", "7.753261"], ["84108.00", "0"], ["84108.60", "0.016770"], ["84109.90", "0.731070"], ["84114.10", "3.332550"], ["84116.50", "0.107400"], ["84117.00", "1.759500"], ["84119.90", "2.674740"], ["84120.10", "0.067800"], ["84120.80", "0.035670"], ["84149.00", "4.803547"], ["84157.50", "5.528611"], ["84166.00", "5.347345"], ["84174.50", "4.894180"], ["84183.00", "4.622282"], ["84191.50", "4.169117"], ["84200.00", "3.897218"], ["84208.50", "5.619244"], ["84217.00", "4.078484"], ["84225.50", "4.350383"], ["84234.00", "4.984813"], ["84242.50", "4.259750"], ["84251.00", "4.531649"], ["84259.50", "5.166079"], ["84268.00", "5.256712"], ["84276.50", "4.712914"], ["84285.00", "4.441016"], ["84293.50", "5.437978"], ["84302.00", "3.987851"], ["84310.50", "5.075446"], ["84401.13", "1.657327"], ["84412.39", "0"], ["84535.32", "0"], ["84536.36", "0"], ["84537.04", "0"]], "bids": [["84049.00", "0"], ["84048.99", "0.000100"], ["84038.80", "0.002149"], ["84036.80", "0.005656"], ["84034.80", "0.014884"], ["84032.80", "0.039168"], ["84031.41", "0.173347"], ["84030.80", "0.103073"], ["84028.80", "0.271246"], ["84028.63", "0"], ["84026.80", "0.713805"], ["84024.80", "1.878434"], ["84022.80", "4.943248"], ["84022.00", "0.786150"], ["84021.80", "0.120180"], ["84020.90", "0.120000"], ["84018.31", "0"], ["83980.80", "5.347345"], ["83972.30", "4.441016"], ["83963.80", "5.528611"], ["83955.30", "5.619244"], ["83946.80", "5.256712"], ["83938.30", "4.894180"], ["83929.80", "5.437978"], ["83921.30", "4.984813"], ["83912.80", "3.897218"], ["83904.30", "4.078484"], ["83887.30", "4.169117"], ["83878.80", "4.803547"], ["83870.30", "4.350383"], ["83861.80", "4.622282"], ["83853.30", "4.259750"], ["83844.80", "4.531649"], ["83836.30", "3.987851"], ["83827.80", "5.166079"], ["83819.30", "5.075446"], ["83739.78", "0"], ["83728.60", "1.660672"], ["83656.60", "0.000607"], ["83655.00", "0.000926"]], "checksum": 2086058819, "ts": "1742555185041"}], "ts": 1742555185045, "record_time": 1742555185.067366, "EXCHANGE": "BITGET"}
{"action": "update", "arg": {"instType": "SPOT", "channel": "books", "instId": "BTCUSDT"}, "data": [{"asks": [["84049.00", "2.122999"], ["84049.01", "1.035085"], ["84051.01", "0.237204"], ["84077.60", "0.179510"], ["84084.14", "0.816343"], ["84091.00", "0.003514"], ["84093.00", "0.009040"], ["84095.00", "0.023789"], ["84097.00", "0.062604"], ["84099.00", "0.164747"], ["84101.00", "0.433546"], ["84103.00", "1.140910"], ["84105.00", "3.002395"], ["84107.00", "7.901038"], ["84107.90", "0"], ["84108.60", "0"], ["84108.70", "0.120630"], ["84109.90", "0.731490"], ["84110.19", "0"], ["84110.50", "0.118770"], ["84114.10", "3.709650"], ["84115.40", "1.359990"], ["84115.60", "0"], ["84120.90", "0.462270"], ["84121.10", "0.269760"], ["84121.60", "0.120000"], ["84126.21", "0"], ["84149.00", "4.531649"], ["84157.50", "4.712914"], ["84164.59", "0"], ["84166.00", "4.169117"], ["84174.50", "3.987851"], ["84183.00", "4.803547"], ["84191.50", "5.437978"], ["84200.00", "5.166079"], ["84208.50", "5.347345"], ["84217.00", "3.897218"], ["84222.00", "0.298337"], ["84234.00", "5.619244"], ["84242.50", "4.441016"], ["84251.00", "5.528611"], ["84259.50", "4.894180"], ["84268.00", "4.259750"], ["84276.50", "5.075446"], ["84285.00", "4.622282"], ["84293.50", "4.984813"], ["84302.00", "4.078484"], ["84310.50", "5.256712"], ["84416.40", "0.510950"], ["84535.32", "0.000039"]], "bids": [["84048.99", "0.186247"], ["84042.81", "0"], ["84038.80", "0.002309"], ["84036.80", "0.006077"], ["84034.80", "0.015992"], ["84032.80", "0.042083"], ["84030.80", "0.110746"], ["84028.81", "0.414949"], ["84028.80", "0.291437"], ["84028.62", "0"], ["84026.80", "0.766939"], ["84024.80", "2.018261"], ["84022.80", "5.311211"], ["84022.60", "0.251070"], ["84022.40", "0.508080"], ["84021.10", "0.013140"], ["84019.40", "0"], ["84017.50", "1.792140"], ["83980.80", "5.075446"], ["83972.30", "3.987851"], ["83963.80", "4.712914"], ["83955.30", "5.528611"], ["83946.80", "4.894180"], ["83938.30", "5.256712"], ["83921.30", "5.619244"], ["83904.30", "4.622282"], ["83895.80", "4.169117"], ["83887.30", "4.078484"], ["83870.30", "5.166079"], ["83861.80", "4.441016"], ["83853.30", "4.531649"], ["83844.80", "4.984813"], ["83836.30", "4.259750"], ["83827.80", "5.347345"], ["83819.30", "4.350383"], ["83702.70", "0.506997"]], "checksum": 1152707530, "ts": "1742555185242"}], "ts": 1742555185246, "record_time": 1742555185.269702, "EXCHANGE": "BITGET"}
{"action": "update", "arg": {"instType": "SPOT", "channel": "books", "instId": "BTCUSDT"}, "data": [{"asks": [["84049.00", "2.759666"], ["84049.01", "0.384366"], ["84051.00", "0.001062"], ["84093.00", "0.009494"], ["84095.00", "0.024984"], ["84097.00", "0.065748"], ["84099.00", "0.173022"], ["84101.00", "0.455321"], ["84103.00", "1.198213"], ["84105.00", "3.153190"], ["84107.00", "8.297869"], ["84108.80", "0"], ["84109.30", "0.036510"], ["84109.90", "0.854370"], ["84110.60", "0.022710"], ["84114.10", "3.706950"], ["84118.60", "0"], ["84149.00", "5.619244"], ["84157.50", "5.437978"], ["84166.00", "4.803547"], ["84183.00", "5.166079"], ["84191.50", "5.075446"], ["84200.00", "4.169117"], ["84208.50", "4.350383"], ["84217.00", "4.984813"], ["84225.50", "5.528611"], ["84234.00", "4.531649"], ["84251.00", "4.894180"], ["84259.50", "3.897218"], ["84268.00", "4.712914"], ["84276.50", "4.078484"], ["84285.00", "5.256712"], ["84293.50", "5.347345"], ["84302.00", "4.259750"], ["84310.50", "4.622282"]], "bids": [["84043.03", "0.041115"], ["84038.80", "0.002790"], ["84036.80", "0.007342"], ["84034.80", "0.019320"], ["84032.80", "0.050844"], ["84030.80", "0.133798"], ["84028.80", "0.352100"], ["84026.80", "0.926717"], ["84024.80", "2.438728"], ["84022.80", "6.417707"], ["84022.60", "0.605610"], ["84022.50", "0.120600"], ["84022.04", "0.314077"], ["84022.00", "0.785940"], ["83980.80", "4.894180"], ["83972.30", "5.256712"], ["83963.80", "5.166079"], ["83955.30", "3.987851"], ["83946.80", "4.531649"], ["83938.30", "4.078484"], ["83929.80", "3.897218"], ["83921.30", "4.169117"], ["83912.80", "4.350383"], ["83904.30", "4.984813"], ["83895.80", "4.259750"], ["83887.30", "5.075446"], ["83878.80", "5.528611"], ["83870.30", "5.619244"], ["83864.00", "0.001184"], ["83861.80", "5.347345"], ["83853.30", "4.803547"], ["83844.80", "4.622282"], ["83836.30", "5.437978"], ["83827.80", "4.712914"], ["83819.30", "4.441016"], ["83658.54", "0"], ["83656.60", "0"], ["83655.00", "0"]], "checksum": -936825695, "ts": "1742555185444"}], "ts": 1742555185448, "record_time": 1742555185.473234, "EXCHANGE": "BITGET"}
{"action": "update", "arg": {"instType": "SPOT", "channel": "books", "instId": "BTCUSDT"}, "data": [{"asks": [["84049.00", "2.830966"], ["84051.00", "0.071550"], ["84089.00", "0.001443"], ["84091.00", "0.003798"], ["84093.00", "0.009996"], ["84095.00", "0.026305"], ["84097.00", "0.069224"], ["84099.00", "0.182167"], ["84101.00", "0.479388"], ["84103.00", "1.261547"], ["84105.00", "3.319861"], ["84107.00", "8.736476"], ["84108.60", "0.036300"], ["84109.00", "0.070080"], ["84109.30", "0.035880"], ["84109.90", "0.853950"], ["84117.00", "1.639500"], ["84121.10", "0"], ["84121.60", "0"], ["84149.00", "3.897218"], ["84157.50", "4.803547"], ["84166.00", "5.166079"], ["84174.50", "4.441016"], ["84183.00", "5.256712"], ["84191.50", "3.987851"], ["84200.00", "4.712914"], ["84208.50", "5.437978"], ["84225.50", "4.078484"], ["84234.00", "4.894180"], ["84242.50", "5.347345"], ["84251.00", "4.531649"], ["84259.50", "4.169117"], ["84268.00", "5.075446"], ["84276.50", "5.619244"], ["84285.00", "4.622282"], ["84293.50", "4.259750"], ["84302.00", "4.350383"], ["84310.50", "5.528611"]], "bids": [["84038.80", "0.002290"], ["84036.80", "0.006026"], ["84034.80", "0.015858"], ["84032.80", "0.041731"], ["84031.41", "0"], ["84030.80", "0.109819"], ["84028.80", "0.288998"], ["84026.80", "0.760520"], ["84024.80", "2.001368"], ["84022.80", "5.266757"], ["84021.10", "0"], ["84019.60", "0.071850"], ["84017.50", "0.009000"], ["84014.30", "1.428030"], ["83980.80", "4.984813"], ["83972.30", "5.437978"], ["83963.80", "4.894180"], ["83955.30", "4.169117"], ["83946.80", "5.075446"], ["83938.30", "3.897218"], ["83929.80", "4.531649"], ["83921.30", "5.347345"], ["83912.80", "5.619244"], ["83904.30", "5.528611"], ["83895.80", "4.712914"], ["83887.30", "4.622282"], ["83878.80", "5.166079"], ["83870.30", "4.078484"], ["83861.80", "4.803547"], ["83853.30", "4.259750"], ["83844.80", "5.256712"], ["83836.30", "4.441016"], ["83827.80", "4.350383"], ["83819.30", "3.987851"], ["83658.54", "0.000036"]], "checksum": 911395360, "ts": "1742555185651"}], "ts": 1742555185656, "record_time": 1742555185.678769, "EXCHANGE": "BITGET"}
{"action": "update", "arg": {"instType": "SPOT", "channel": "books", "instId": "BTCUSDT"}, "data": [{"asks": [["84089.00", "0.001549"], ["84091.00", "0.004077"], ["84093.00", "0.010729"], ["84095.00", "0.028368"], ["84097.00", "0.074654"], ["84099.00", "0.196457"], ["84101.00", "0.516993"], ["84103.00", "1.360338"], ["84105.00", "3.579836"], ["84107.00", "9.420621"], ["84115.00", "0.356940"], ["84116.60", "0.356940"], ["84117.50", "0.356940"], ["84118.20", "0.665070"], ["84120.10", "0"], ["84120.80", "0"], ["84120.90", "0"], ["84149.00", "4.531649"], ["84157.50", "5.075446"], ["84166.00", "4.622282"], ["84174.50", "4.169117"], ["84183.00", "3.987851"], ["84191.50", "5.256712"], ["84208.50", "4.441016"], ["84217.00", "5.166079"], ["84223.85", "0.010000"], ["84225.50", "3.897218"], ["84234.00", "4.350383"], ["84242.50", "4.078484"], ["84251.00", "5.528611"], ["84259.50", "4.984813"], ["84268.00", "5.347345"], ["84276.50", "4.894180"], ["84285.00", "5.437978"], ["84293.50", "4.803547"], ["84302.00", "5.619244"], ["84310.50", "4.259750"], ["84535.32", "0"]], "bids": [["84043.25", "0.041115"], ["84043.03", "0"], ["84038.80", "0.001686"], ["84036.80", "0.004437"], ["84035.61", "0.010000"], ["84034.80", "0.011676"], ["84032.80", "0.030726"], ["84031.41", "0.178214"], ["84030.80", "0.080858"], ["84028.80", "0.212785"], ["84026.80", "0.559960"], ["84024.80", "1.473579"], ["84024.51", "0.699196"], ["84022.80", "3.877840"], ["84022.60", "0.243780"], ["84022.50", "0.121020"], ["84022.00", "0.786150"], ["84020.30", "0.054270"], ["84019.60", "0"], ["84014.30", "0.651060"], ["83980.80", "4.803547"], ["83972.30", "5.075446"], ["83955.30", "4.441016"], ["83946.80", "5.528611"], ["83938.30", "3.987851"], ["83929.80", "5.166079"], ["83921.30", "5.437978"], ["83912.80", "4.622282"], ["83904.30", "4.078484"], ["83895.80", "4.531649"], ["83887.30", "4.712914"], ["83878.80", "4.259750"], ["83870.30", "4.350383"], ["83861.80", "5.619244"], ["83853.30", "4.169117"], ["83844.80", "4.984813"], ["83836.30", "5.256712"], ["83827.80", "3.897218"], ["83819.30", "5.347345"], ["83659.44", "0"], ["83658.54", "0"]], "checksum": -602533436, "ts": "1742555185858"}], "ts": 1742555185860, "record_time": 1742555185.886747, "EXCHANGE": "BITGET"}
{"action": "update", "arg": {"instType": "SPOT", "channel": "books", "instId": "BTCUSDT"}, "data": [{"asks": [["84049.00", "2.828607"], ["84069.93", "0"], ["84073.62", "0.012472"], ["84105.00", "3.579956"], ["84107.00", "9.420937"], ["84118.20", "0.640140"], ["84137.09", "0"], ["84149.00", "3.897218"], ["84157.50", "4.712914"], ["84166.00", "4.984813"], ["84174.50", "4.803547"], ["84183.00", "4.531649"], ["84200.00", "5.075446"], ["84208.50", "4.350383"], ["84217.00", "4.169117"], ["84225.50", "5.619244"], ["84234.00", "4.622282"], ["84242.50", "5.528611"], ["84251.00", "5.437978"], ["84259.50", "5.347345"], ["84268.00", "3.987851"], ["84276.50", "4.441016"], ["84285.00", "4.894180"], ["84293.50", "4.078484"], ["84302.00", "5.166079"], ["84535.32", "0.000039"]], "bids": [["84038.80", "0.002050"], ["84037.48", "0.010000"], ["84036.80", "0.005393"], ["84034.80", "0.014192"], ["84032.80", "0.037349"], ["84030.80", "0.098286"], ["84028.81", "0.284222"], ["84028.80", "0.258649"], ["84026.80", "0.680653"], ["84024.80", "1.791194"], ["84022.80", "4.713668"], ["84021.00", "0.299610"], ["84020.30", "0.312750"], ["84018.70", "0.071010"], ["84014.30", "0"], ["83980.80", "4.984813"], ["83972.30", "5.528611"], ["83963.80", "5.166079"], ["83955.30", "3.897218"], ["83946.80", "4.169117"], ["83938.30", "4.803547"], ["83929.80", "5.437978"], ["83921.30", "4.894180"], ["83912.80", "4.712914"], ["83904.30", "5.619244"], ["83895.80", "4.078484"], ["83887.30", "5.075446"], ["83878.80", "4.441016"], ["83870.30", "5.256712"], ["83861.80", "3.987851"], ["83853.30", "4.350383"], ["83844.80", "4.622282"], ["83836.30", "4.531649"], ["83827.80", "5.347345"], ["83819.30", "4.259750"], ["83659.49", "0"]], "checksum": 66816242, "ts": "1742555186065"}], "ts": 1742555186069, "record_time": 1742555186.091613, "EXCHANGE": "BITGET"}
{"action": "update", "arg": {"instType": "SPOT", "channel": "books", "instId": "BTCUSDT"}, "data": [{"asks": [["84080.38", "0.098060"], ["84095.06", "0"], ["84149.00", "4.894180"], ["84157.50", "5.166079"], ["84166.00", "5.256712"], ["84183.00", "4.078484"], ["84191.50", "5.528611"], ["84200.00", "5.619244"], ["84208.50", "4.984813"], ["84217.00", "5.075446"], ["84225.50", "4.259750"], ["84234.00", "4.712914"], ["84242.50", "4.441016"], ["84251.00", "4.350383"], ["84259.50", "3.897218"], ["84268.00", "5.437978"], ["84276.50", "4.622282"], ["84285.00", "5.347345"], ["84293.50", "4.531649"], ["84302.00", "3.987851"], ["84310.50", "4.169117"]], "bids": [["84043.25", "0"], ["84035.73", "0"], ["84034.80", "0.014326"], ["84032.80", "0.037700"], ["84030.80", "0.099211"], ["84028.80", "0.261081"], ["84026.80", "0.687057"], ["84024.80", "1.808044"], ["84024.51", "1.829856"], ["84022.80", "4.758010"], ["83980.80", "5.528611"], ["83972.30", "4.803547"], ["83963.80", "3.987851"], ["83955.30", "4.350383"], ["83938.30", "4.984813"], ["83929.80", "5.166079"], ["83921.30", "5.256712"], ["83912.80", "4.894180"], ["83904.30", "4.078484"], ["83895.80", "5.619244"], ["83887.30", "4.712914"], ["83878.80", "3.897218"], ["83870.30", "4.622282"], ["83861.80", "5.075446"], ["83853.30", "4.531649"], ["83844.80", "4.441016"], ["83836.30", "5.437978"], ["83659.49", "0.000012"], ["83659.44", "0.000613"]], "checksum": -1481440127, "ts": "1742555186266"}], "ts": 1742555186275, "record_time": 1742555186.297341, "EXCHANGE": "BITGET"}
{"action": "update", "arg": {"instType": "SPOT", "channel": "books", "instId": "BTCUSDT"}, "data": [{"asks": [["84058.99", "0"], ["84083.63", "0.010000"], ["84093.00", "0.010992"], ["84095.00", "0.028926"], ["84097.00", "0.076121"], ["84099.00", "0.200320"], ["84101.00", "0.527157"], ["84103.00", "1.387255"], ["84105.00", "3.650820"], ["84107.00", "9.607421"], ["84108.30", "0.046170"], ["84108.60", "0.035880"], ["84108.70", "0.120210"], ["84109.30", "0.035670"], ["84109.90", "0.853530"], ["84110.50", "0.073230"], ["84114.10", "3.406320"], ["84114.70", "0.120000"], ["84117.50", "0.713880"], ["84118.20", "0"], ["84119.00", "0"], ["84119.90", "0"], ["84149.00", "4.984813"], ["84157.50", "4.078484"], ["84174.50", "4.350383"], ["84183.00", "4.169117"], ["84191.50", "5.619244"], ["84200.00", "4.894180"], ["84208.50", "5.528611"], ["84217.00", "4.622282"], ["84225.50", "3.987851"], ["84234.00", "5.437978"], ["84242.50", "4.712914"], ["84251.00", "3.897218"], ["84259.50", "4.531649"], ["84268.00", "4.803547"], ["84276.50", "4.441016"], ["84285.00", "5.166079"], ["84293.50", "5.075446"], ["84302.00", "4.259750"], ["84310.50", "5.347345"], ["84536.36", "0.000053"]], "bids": [["84048.99", "0.196238"], ["84043.47", "0.041114"], ["84038.80", "0.001537"], ["84036.80", "0.004044"], ["84034.80", "0.010643"], ["84033.70", "0.112795"], ["84032.80", "0.028007"], ["84031.41", "0"], ["84030.80", "0.073703"], ["84028.80", "0.193955"], ["84026.80", "0.510409"], ["84024.80", "1.343182"], ["84022.80", "3.534688"], ["84022.60", "0.002970"], ["84022.50", "0.001045"], ["84021.80", "0"], ["84021.00", "0.299820"], ["84020.90", "0"], ["84020.30", "0.312960"], ["84020.10", "0"], ["84018.50", "0.015000"], ["84018.40", "0"], ["84018.30", "0"], ["84018.10", "0"], ["84017.70", "4.432410"], ["84017.20", "0"], ["84017.10", "0.060000"], ["84016.70", "0"], ["84015.90", "0"], ["84015.10", "0.120000"], ["84014.30", "0.366090"], ["84013.90", "0.007050"], ["84013.60", "0.120000"], ["83980.80", "5.075446"], ["83972.30", "5.347345"], ["83963.80", "5.437978"], ["83955.30", "4.803547"], ["83946.80", "4.259750"], ["83938.30", "5.619244"], ["83929.80", "5.528611"], ["83921.30", "4.441016"], ["83912.80", "4.712914"], ["83904.30", "4.350383"], ["83895.80", "5.166079"], ["83887.30", "4.531649"], ["83878.80", "4.078484"], ["83870.30", "3.897218"], ["83861.80", "5.256712"], ["83853.30", "3.987851"], ["83844.80", "4.984813"], ["83836.30", "4.894180"], ["83827.80", "4.169117"], ["83819.30", "4.622282"], ["83658.54", "0.000036"], ["83656.60", "0.000607"], ["83655.00", "0.000926"], ["83654.23", "0.000009"]], "checksum": 216287653, "ts": "1742555186465"}], "ts": 1742555186469, "record_time": 1742555186.497391, "EXCHANGE": "BITGET"}
{"action": "update", "arg": {"instType": "SPOT", "channel": "books", "instId": "BTCUSDT"}, "data": [{"asks": [["84043.03", "0.006601"], ["84043.12", "1.583297"], ["84044.79", "0.245840"], ["84048.99", "0.348480"], ["84049.00", "1.124220"], ["84049.01", "0.139666"], ["84051.00", "0"], ["84051.01", "0.221455"], ["84054.01", "0"], ["84055.41", "0.017457"], ["84064.79", "0.119870"], ["84065.86", "0"], ["84067.26", "0.006356"], ["84067.94", "0.016429"], ["84069.95", "0.006356"], ["84070.96", "0"], ["84072.22", "0.119850"], ["84074.44", "0"], ["84074.53", "0"], ["84075.21", "0"], ["84076.22", "0"], ["84079.49", "0"], ["84087.00", "0.001205"], ["84089.00", "0.001965"], ["84091.00", "0.005171"], ["84093.00", "0.013609"], ["84095.00", "0.035812"], ["84097.00", "0.094243"], ["84099.00", "0.248007"], ["84101.00", "0.652651"], ["84103.00", "1.717504"], ["84105.00", "4.519745"], ["84107.00", "11.894068"], ["84107.50", "0.002070"], ["84107.70", "0"], ["84108.00", "0.048090"], ["84108.10", "0.068190"], ["84108.30", "0"], ["84108.70", "0.120390"], ["84109.30", "0.305640"], ["84110.20", "0.178290"], ["84110.60", "0.343350"], ["84111.00", "0"], ["84114.10", "3.145440"], ["84117.00", "3.010710"], ["84117.10", "0.257610"], ["84117.60", "0"], ["84118.10", "0"], ["84149.00", "5.075446"], ["84157.50", "3.897218"], ["84166.00", "4.169117"], ["84174.50", "5.256712"], ["84183.00", "4.984813"], ["84191.50", "4.259750"], ["84200.00", "3.987851"], ["84208.50", "4.078484"], ["84217.00", "5.437978"], ["84225.50", "4.622282"], ["84234.00", "4.441016"], ["84242.50", "5.347345"], ["84251.00", "5.528611"], ["84259.50", "4.894180"], ["84276.50", "4.531649"], ["84285.00", "5.619244"], ["84293.50", "4.350383"], ["84302.00", "5.166079"], ["84310.50", "4.712914"], ["84537.04", "0.000958"]], "bids": [["84048.99", "0"], ["84048.98", "0"], ["84048.97", "0"], ["84046.00", "0"], ["84045.00", "0"], ["84044.00", "0"], ["84043.47", "0"], ["84043.11", "0"], ["84038.80", "0.001008"], ["84038.29", "0.027856"], ["84037.48", "0"], ["84036.90", "0"], ["84036.80", "0.002407"], ["84034.80", "0.006336"], ["84033.70", "0"], ["84032.80", "0.016674"], ["84032.24", "0"], ["84030.80", "0.043879"], ["84029.78", "0"], ["84029.21", "0"], ["84028.81", "0"], ["84028.80", "0.115470"], ["84027.34", "0.021425"], ["84026.80", "0.303868"], ["84026.29", "0"], ["84025.86", "0.008897"], ["84025.62", "0"], ["84024.80", "0.799652"], ["84022.80", "2.104348"], ["84022.60", "0.247629"], ["84022.40", "0"], ["84022.00", "0.000032"], ["84021.68", "0"], ["84021.32", "0"], ["84021.00", "0.000032"], ["84020.62", "0.028180"], ["84020.30", "0"], ["84019.90", "0.071760"], ["84019.40", "0.012472"], ["84019.30", "0.069750"], ["84019.02", "0.017106"], ["84018.86", "0.007133"], ["84018.70", "0"], ["84018.35", "0.028870"], ["84018.00", "0.000032"], ["84017.90", "0.007230"], ["84017.71", "0.178214"], ["84017.70", "0"], ["84017.10", "0"], ["84016.80", "0.319110"], ["84016.10", "0"], ["84016.00", "0.120000"], ["84014.60", "0"], ["84014.30", "0"], ["84014.06", "0.268422"], ["84013.60", "0.066240"], ["84012.50", "0.581820"], ["84012.00", "0.534660"], ["84011.50", "0.120000"], ["84011.30", "0.045540"], ["84011.00", "0.015150"], ["84010.90", "0.240000"], ["84010.31", "3.053566"], ["84000.31", "0"], ["83989.86", "0.017457"], ["83983.60", "0"], ["83980.80", "4.441016"], ["83977.82", "0"], ["83972.30", "5.437978"], ["83963.80", "5.347345"], ["83955.30", "4.622282"], ["83951.63", "0.071045"], ["83950.26", "0"], ["83946.80", "4.169117"], ["83938.30", "4.078484"], ["83929.80", "4.259750"], ["83921.30", "3.897218"], ["83904.30", "5.166079"], ["83895.80", "4.984813"], ["83887.30", "5.528611"], ["83878.80", "3.987851"], ["83870.30", "5.256712"], ["83861.80", "4.894180"], ["83853.30", "5.619244"], ["83844.80", "4.531649"], ["83836.30", "4.803547"], ["83827.80", "5.075446"], ["83819.30", "4.350383"], ["83653.94", "0.000133"], ["83653.67", "0.001695"], ["83653.31", "0.000015"], ["83652.80", "0.000119"], ["83652.48", "0.000188"], ["83651.65", "0.000018"], ["83651.16", "0.000896"], ["83650.84", "0.003326"], ["83650.00", "0.032056"], ["83648.96", "0.000030"], ["83647.46", "0.000224"], ["83647.06", "0.000040"], ["83646.67", "0.000018"], ["83645.83", "0.000014"]], "checksum": 1341179121, "ts": "1742555186666"}], "ts": 1742555186668, "record_time": 1742555186.692422, "EXCHANGE": "BITGET"}
{"action": "update", "arg": {"instType": "SPOT", "channel": "books", "instId": "BTCUSDT"}, "data": [{"asks": [["84043.01", "2.016294"], ["84043.02", "0.122202"], ["84043.10", "0.000865"], ["84043.11", "0.460879"], ["84043.12", "0"], ["84044.79", "0"], ["84048.99", "0.295280"], ["84049.00", "0.110896"], ["84049.01", "0"], ["84065.85", "0.005236"], ["84067.44", "0.006356"], ["84071.68", "0.200100"], ["84079.32", "0"], ["84084.14", "0.043725"], ["84087.00", "0.001025"], ["84089.00", "0.001477"], ["84091.00", "0.003768"], ["84093.00", "0.009917"], ["84095.00", "0.026097"], ["84097.00", "0.068676"], ["84099.00", "0.180726"], ["84101.00", "0.475595"], ["84103.00", "1.251567"], ["84105.00", "3.293596"], ["84107.00", "8.667358"], ["84108.60", "0"], ["84108.70", "0.120210"], ["84109.00", "0"], ["84109.30", "0.035880"], ["84109.90", "0.853740"], ["84113.30", "0.120000"], ["84113.60", "0.120000"], ["84114.80", "1.069890"], ["84115.00", "0.656940"], ["84116.30", "0.035670"], ["84116.50", "0"], ["84117.10", "0"], ["84117.50", "0"], ["84149.00", "4.350383"], ["84157.50", "5.347345"], ["84166.00", "4.259750"], ["84174.50", "4.531649"], ["84183.00", "4.712914"], ["84191.50", "4.169117"], ["84200.00", "5.437978"], ["84208.50", "4.803547"], ["84217.00", "4.984813"], ["84225.50", "4.078484"], ["84234.00", "5.256712"], ["84242.50", "3.987851"], ["84251.00", "4.622282"], ["84259.50", "5.528611"], ["84268.00", "4.441016"], ["84276.50", "3.897218"], ["84285.00", "5.166079"], ["84293.50", "5.075446"], ["84302.00", "5.619244"], ["84310.50", "4.894180"], ["84537.04", "0"]], "bids": [["84043.00", "0.250066"], ["84038.80", "0.002605"], ["84036.80", "0.006854"], ["84034.80", "0.018038"], ["84033.93", "0.028180"], ["84032.80", "0.047468"], ["84030.80", "0.124915"], ["84028.81", "0.168696"], ["84028.80", "0.328724"], ["84026.82", "0.112795"], ["84026.80", "0.865063"], ["84024.80", "2.276483"], ["84024.51", "0.699196"], ["84022.80", "5.990744"], ["84021.31", "0"], ["84021.00", "0.151380"], ["84020.62", "0"], ["84019.30", "0.069930"], ["84018.70", "0.282690"], ["84018.00", "0.255180"], ["84017.90", "0.077910"], ["84017.71", "0"], ["84017.10", "0.045540"], ["84016.80", "0.120000"], ["84016.10", "0.024120"], ["84014.95", "0"], ["84013.60", "0"], ["84012.50", "0.323790"], ["84012.00", "0.654660"], ["84011.90", "0.120000"], ["84011.50", "0"], ["84011.30", "0"], ["84011.00", "0.000032"], ["84010.90", "0"], ["84009.40", "0.714205"], ["84001.50", "0"], ["83993.50", "0.000396"], ["83980.80", "5.347345"], ["83972.30", "4.531649"], ["83972.10", "0"], ["83964.10", "0.000948"], ["83963.80", "5.075446"], ["83955.30", "5.166079"], ["83951.58", "0.057001"], ["83946.80", "4.984813"], ["83940.37", "0.012355"], ["83938.30", "5.437978"], ["83929.80", "4.078484"], ["83921.30", "3.987851"], ["83912.80", "4.441016"], ["83904.30", "5.256712"], ["83895.80", "4.803547"], ["83887.30", "4.622282"], ["83878.80", "4.894180"], ["83870.30", "3.897218"], ["83861.80", "4.350383"], ["83853.30", "4.259750"], ["83844.80", "4.169117"], ["83836.30", "4.712914"], ["83827.80", "5.528611"], ["83819.30", "5.619244"], ["83788.72", "0.000254"], ["83647.06", "0"], ["83646.67", "0"], ["83645.83", "0"]], "checksum": 495756184, "ts": "1742555186870"}], "ts": 1742555186882, "record_time": 1742555186.952896, "EXCHANGE": "BITGET"}
{"action": "update", "arg": {"instType": "SPOT", "channel": "books", "instId": "BTCUSDT"}, "data": [{"asks": [["84043.01", "2.043374"], ["84043.10", "0.139129"], ["84043.11", "0.006307"], ["84048.98", "0.088584"], ["84051.00", "0.066888"], ["84080.38", "0"], ["84082.70", "0"], ["84089.00", "0.001282"], ["84091.00", "0.003373"], ["84093.00", "0.008877"], ["84095.00", "0.023361"], ["84097.00", "0.061477"], ["84099.00", "0.161780"], ["84101.00", "0.425737"], ["84103.00", "1.120360"], ["84105.00", "2.948317"], ["84106.99", "0.559285"], ["84107.00", "7.758618"], ["84107.50", "0.001740"], ["84108.00", "0.001009"], ["84108.10", "0.068610"], ["84109.30", "0.036060"], ["84109.90", "0.853950"], ["84110.10", "0.113340"], ["84114.50", "0.162030"], ["84116.90", "0.228000"], ["84117.00", "0"], ["84149.00", "4.803547"], ["84157.50", "5.437978"], ["84166.00", "5.166079"], ["84174.50", "5.075446"], ["84191.50", "4.894180"], ["84200.00", "3.897218"], ["84208.50", "5.619244"], ["84217.00", "4.531649"], ["84225.50", "3.987851"], ["84234.00", "4.984813"], ["84242.50", "4.350383"], ["84259.50", "4.078484"], ["84276.50", "5.347345"], ["84285.00", "5.528611"], ["84293.50", "4.259750"], ["84302.00", "5.256712"], ["84310.50", "4.169117"], ["84536.36", "0"]], "bids": [["84043.00", "0.250166"], ["84042.99", "0.000100"], ["84042.98", "0.000100"], ["84042.97", "0.000100"], ["84038.80", "0.002847"], ["84036.80", "0.007491"], ["84034.80", "0.019715"], ["84032.80", "0.051882"], ["84031.41", "0.084148"], ["84030.80", "0.136530"], ["84028.81", "0.413783"], ["84028.80", "0.359291"], ["84027.67", "0.027453"], ["84026.80", "0.945502"], ["84024.80", "2.488162"], ["84024.51", "1.672898"], ["84022.80", "6.547795"], ["84019.40", "0.045750"], ["84019.30", "0.069540"], ["84018.70", "0.605940"], ["84018.00", "0.000032"], ["84017.10", "0"], ["84016.20", "2.356620"], ["84014.50", "1.094400"], ["84012.50", "0"], ["83980.80", "4.803547"], ["83972.30", "5.166079"], ["83955.30", "5.256712"], ["83946.80", "4.350383"], ["83938.30", "4.441016"], ["83929.80", "5.619244"], ["83921.30", "4.712914"], ["83912.80", "4.259750"], ["83904.30", "4.169117"], ["83895.80", "4.622282"], ["83887.30", "5.437978"], ["83878.80", "3.897218"], ["83870.30", "4.894180"], ["83861.80", "5.347345"], ["83853.30", "4.531649"], ["83844.80", "3.987851"], ["83836.30", "4.984813"], ["83819.30", "4.078484"], ["83651.16", "0"], ["83650.84", "0"], ["83650.00", "0"], ["83648.96", "0"], ["83647.46", "0"]], "checksum": -381994942, "ts": "1742555187074"}], "ts": 1742555187078, "record_time": 1742555187.100162, "EXCHANGE": "BITGET"}
{"action": "update", "arg": {"instType": "SPOT", "channel": "books", "instId": "BTCUSDT"}, "data": [{"asks": [["84043.02", "0.133496"], ["84043.10", "0.000865"], ["84043.60", "0.086676"], ["84048.99", "0.209200"], ["84101.00", "0.425738"], ["84103.00", "1.120364"], ["84105.00", "2.948324"], ["84107.00", "7.758748"], ["84108.60", "0.007020"], ["84109.90", "0.854160"], ["84117.00", "3.010710"], ["84149.00", "5.619244"], ["84166.00", "4.622282"], ["84174.50", "4.712914"], ["84183.00", "3.987851"], ["84191.50", "5.528611"], ["84200.00", "4.078484"], ["84208.50", "5.166079"], ["84217.00", "4.894180"], ["84225.50", "4.803547"], ["84234.00", "4.350383"], ["84242.50", "4.259750"], ["84251.00", "3.897218"], ["84259.50", "4.169117"], ["84268.00", "5.075446"], ["84276.50", "4.984813"], ["84285.00", "5.256712"], ["84293.50", "4.441016"], ["84302.00", "4.531649"], ["84310.50", "5.347345"], ["84533.33", "0"], ["84534.53", "0"], ["84535.32", "0"]], "bids": [["84043.00", "0.496006"], ["84038.80", "0.002430"], ["84036.80", "0.006397"], ["84034.80", "0.016834"], ["84032.80", "0.044298"], ["84030.80", "0.116574"], ["84028.80", "0.306775"], ["84027.60", "0.112798"], ["84026.82", "0"], ["84026.80", "0.807302"], ["84024.80", "2.124627"], ["84022.80", "5.591123"], ["84019.89", "0.173888"], ["84018.70", "1.182420"], ["84014.50", "0.387390"], ["84012.60", "0.476280"], ["83980.80", "4.350383"], ["83972.30", "4.169117"], ["83963.80", "3.987851"], ["83955.30", "4.531649"], ["83946.80", "5.166079"], ["83938.30", "5.619244"], ["83929.80", "5.437978"], ["83921.30", "3.897218"], ["83912.80", "4.078484"], ["83904.30", "5.528611"], ["83895.80", "4.259750"], ["83887.30", "5.256712"], ["83878.80", "4.712914"], ["83870.30", "4.622282"], ["83853.30", "4.803547"], ["83844.80", "5.075446"], ["83836.30", "4.894180"], ["83827.80", "4.441016"], ["83819.30", "4.984813"], ["83730.63", "0"], ["83651.65", "0"]], "checksum": 1422759357, "ts": "1742555187308"}], "ts": 1742555187314, "record_time": 1742555187.335962, "EXCHANGE": "BITGET"}
{"action": "update", "arg": {"instType": "SPOT", "channel": "books", "instId": "BTCUSDT"}, "data": [{"asks": [["84043.02", "0.158982"], ["84048.98", "0"], ["84077.60", "0"], ["84107.00", "7.758878"], ["84107.50", "0"], ["84108.60", "0.016950"], ["84108.70", "0.120630"], ["84109.30", "0"], ["84109.90", "0.854370"], ["84117.50", "0.713880"], ["84149.00", "4.441016"], ["84157.50", "4.531649"], ["84166.00", "4.259750"], ["84174.50", "5.437978"], ["84183.00", "5.619244"], ["84191.50", "4.350383"], ["84208.50", "4.712914"], ["84225.50", "5.528611"], ["84234.00", "4.622282"], ["84242.50", "5.075446"], ["84251.00", "5.347345"], ["84259.50", "5.166079"], ["84268.00", "4.803547"], ["84276.50", "5.256712"], ["84285.00", "4.984813"], ["84293.50", "3.987851"], ["84302.00", "3.897218"], ["84310.50", "4.169117"], ["84533.33", "0.003186"], ["84534.53", "0.000461"], ["84535.32", "0.000039"]], "bids": [["84039.39", "0.027856"], ["84038.80", "0.002659"], ["84038.29", "0"], ["84036.80", "0.006997"], ["84034.80", "0.018415"], ["84032.80", "0.048459"], ["84030.80", "0.127525"], ["84028.80", "0.335592"], ["84026.80", "0.883137"], ["84024.80", "2.324043"], ["84022.80", "6.115903"], ["83980.80", "4.622282"], ["83972.30", "4.984813"], ["83963.80", "5.619244"], ["83955.30", "4.259750"], ["83946.80", "4.350383"], ["83938.30", "5.528611"], ["83929.80", "5.256712"], ["83921.30", "5.437978"], ["83912.80", "4.712914"], ["83904.30", "4.441016"], ["83895.80", "4.531649"], ["83887.30", "5.075446"], ["83878.80", "4.078484"], ["83870.30", "3.987851"], ["83844.80", "4.894180"], ["83836.30", "5.166079"], ["83827.80", "4.169117"], ["83819.30", "3.897218"], ["83706.82", "0.001536"], ["83652.48", "0"]], "checksum": -845072044, "ts": "1742555187532"}], "ts": 1742555187536, "record_time": 1742555187.563677, "EXCHANGE": "BITGET"}
{"action": "update", "arg": {"instType": "SPOT", "channel": "books", "instId": "BTCUSDT"}, "data": [{"asks": [["84043.58", "0.086676"], ["84043.60", "0"], ["84048.98", "0.062760"], ["84077.18", "0.180263"], ["84089.00", "0.001420"], ["84091.00", "0.003737"], ["84093.00", "0.009835"], ["84095.00", "0.025882"], ["84097.00", "0.068111"], ["84099.00", "0.179238"], ["84101.00", "0.471680"], ["84103.00", "1.241264"], ["84105.00", "3.266483"], ["84107.00", "8.596009"], ["84108.10", "0.068430"], ["84108.70", "0"], ["84109.00", "0.071400"], ["84149.00", "4.622282"], ["84157.50", "3.987851"], ["84166.00", "4.712914"], ["84174.50", "4.350383"], ["84183.00", "4.441016"], ["84191.50", "5.256712"], ["84200.00", "5.437978"], ["84208.50", "4.078484"], ["84217.00", "5.528611"], ["84225.50", "4.894180"], ["84234.00", "4.169117"], ["84251.00", "4.803547"], ["84259.50", "4.259750"], ["84268.00", "3.897218"], ["84276.50", "5.166079"], ["84285.00", "4.531649"], ["84293.50", "4.984813"], ["84302.00", "5.619244"], ["84310.50", "5.347345"], ["84534.53", "0"], ["84535.32", "0"]], "bids": [["84043.00", "0.286806"], ["84038.80", "0.002295"], ["84036.80", "0.006040"], ["84034.80", "0.015894"], ["84032.80", "0.041828"], ["84030.80", "0.110072"], ["84028.80", "0.289664"], ["84026.80", "0.762274"], ["84024.80", "2.005983"], ["84022.80", "5.278903"], ["84018.70", "0.515850"], ["84016.20", "0"], ["84014.50", "1.188870"], ["84014.30", "2.356680"], ["83972.30", "5.256712"], ["83963.80", "4.078484"], ["83955.30", "5.437978"], ["83946.80", "4.441016"], ["83938.30", "4.259750"], ["83929.80", "5.528611"], ["83921.30", "5.075446"], ["83912.80", "3.897218"], ["83904.30", "4.984813"], ["83895.80", "5.166079"], ["83887.30", "4.803547"], ["83878.80", "5.619244"], ["83870.30", "5.347345"], ["83861.80", "3.987851"], ["83853.30", "4.169117"], ["83844.80", "4.712914"], ["83836.30", "4.531649"], ["83827.80", "4.350383"], ["83819.30", "4.894180"]], "checksum": 1708325009, "ts": "1742555187733"}], "ts": 1742555187737, "record_time": 1742555187.772214, "EXCHANGE": "BITGET"}
{"action": "update", "arg": {"instType": "SPOT", "channel": "books", "instId": "BTCUSDT"}, "data": [{"asks": [["84043.01", "2.073123"], ["84048.98", "0.088184"], ["84093.00", "0.009834"], ["84095.00", "0.025881"], ["84097.00", "0.068107"], ["84099.00", "0.179228"], ["84101.00", "0.471653"], ["84103.00", "1.241194"], ["84105.00", "3.266300"], ["84107.00", "8.595525"], ["84107.80", "0.001034"], ["84107.90", "0.073740"], ["84108.60", "0"], ["84109.00", "0"], ["84149.00", "4.712914"], ["84157.50", "3.897218"], ["84166.00", "5.075446"], ["84174.50", "5.166079"], ["84183.00", "4.803547"], ["84191.50", "4.078484"], ["84200.00", "5.256712"], ["84208.50", "5.619244"], ["84217.00", "4.894180"], ["84225.50", "4.441016"], ["84234.00", "5.347345"], ["84242.50", "3.987851"], ["84251.00", "4.169117"], ["84259.50", "4.350383"], ["84268.00", "5.528611"], ["84276.50", "4.259750"], ["84285.00", "4.984813"], ["84293.50", "5.437978"], ["84302.00", "4.531649"], ["84310.50", "4.622282"]], "bids": [["84043.00", "0.496006"], ["84038.80", "0.002803"], ["84036.80", "0.007377"], ["84034.80", "0.019413"], ["84032.80", "0.051086"], ["84030.80", "0.134437"], ["84028.80", "0.353783"], ["84026.80", "0.931006"], ["84024.80", "2.450016"], ["84022.80", "6.447411"], ["83980.80", "5.437978"], ["83972.30", "4.078484"], ["83963.80", "4.622282"], ["83955.30", "5.256712"], ["83946.80", "5.619244"], ["83938.30", "4.350383"], ["83929.80", "4.712914"], ["83921.30", "5.347345"], ["83912.80", "4.803547"], ["83904.30", "5.528611"], ["83895.80", "4.894180"], ["83887.30", "5.075446"], ["83878.80", "4.984813"], ["83870.30", "4.441016"], ["83853.30", "4.259750"], ["83844.80", "3.897218"], ["83827.80", "4.169117"], ["83819.30", "5.166079"]], "checksum": 2095331716, "ts": "1742555187939"}], "ts": 1742555187943, "record_time": 1742555187.965687, "EXCHANGE": "BITGET"}
{"action": "update", "arg": {"instType": "SPOT", "channel": "books", "instId": "BTCUSDT"}, "data": [{"asks": [["84043.01", "2.130423"], ["84076.75", "0.160562"], ["84089.00", "0.001282"], ["84091.00", "0.003373"], ["84093.00", "0.008877"], ["84095.00", "0.023360"], ["84097.00", "0.061475"], ["84099.00", "0.161776"], ["84101.00", "0.425725"], ["84102.99", "0.507769"], ["84103.00", "1.120331"], ["84105.00", "2.948240"], ["84106.99", "0"], ["84107.00", "7.758320"], ["84117.60", "0.033780"], ["84149.00", "5.528611"], ["84157.50", "5.619244"], ["84166.00", "4.259750"], ["84174.50", "4.169117"], ["84200.00", "4.350383"], ["84208.50", "5.166079"], ["84217.00", "5.347345"], ["84225.50", "4.712914"], ["84234.00", "4.894180"], ["84242.50", "4.622282"], ["84251.00", "4.984813"], ["84259.50", "4.441016"], ["84268.00", "5.256712"], ["84276.50", "4.531649"], ["84285.00", "5.437978"], ["84293.50", "3.897218"], ["84302.00", "5.075446"], ["84310.50", "3.987851"], ["84360.00", "0.003064"], ["84533.01", "0"], ["84533.33", "0"]], "bids": [["84038.80", "0.002659"], ["84036.80", "0.006997"], ["84034.80", "0.018415"], ["84032.80", "0.048459"], ["84030.80", "0.127525"], ["84028.80", "0.335592"], ["84026.80", "0.883137"], ["84024.80", "2.324043"], ["84022.80", "6.116052"], ["83980.80", "4.169117"], ["83972.30", "3.897218"], ["83963.80", "4.441016"], ["83955.30", "4.259750"], ["83946.80", "5.075446"], ["83938.30", "5.347345"], ["83929.80", "4.350383"], ["83921.30", "3.987851"], ["83904.30", "4.531649"], ["83895.80", "4.712914"], ["83887.30", "5.619244"], ["83878.80", "5.256712"], ["83870.30", "4.078484"], ["83861.80", "5.437978"], ["83853.30", "5.166079"], ["83844.80", "5.528611"], ["83836.30", "4.894180"], ["83827.80", "4.622282"], ["83819.30", "4.984813"]], "checksum": -2003583116, "ts": "1742555188141"}], "ts": 1742555188143, "record_time": 1742555188.166149, "EXCHANGE": "BITGET"}
{"action": "update", "arg": {"instType": "SPOT", "channel": "books", "instId": "BTCUSDT"}, "data": [{"asks": [["84043.56", "0.086676"], ["84043.58", "0"], ["84083.63", "0"], ["84091.00", "0.003247"], ["84093.00", "0.008545"], ["84095.00", "0.022487"], ["84097.00", "0.059177"], ["84099.00", "0.155728"], ["84101.00", "0.409809"], ["84103.00", "1.078445"], ["84105.00", "2.838212"], ["84107.00", "7.468979"], ["84108.80", "0.060420"], ["84109.90", "0.854160"], ["84117.50", "0"], ["84117.60", "0"], ["84157.50", "5.075446"], ["84166.00", "4.169117"], ["84174.50", "4.894180"], ["84183.00", "4.078484"], ["84191.50", "5.256712"], ["84200.00", "5.619244"], ["84208.50", "4.712914"], ["84225.50", "4.803547"], ["84234.00", "4.531649"], ["84242.50", "5.166079"], ["84251.00", "4.622282"], ["84259.50", "5.437978"], ["84268.00", "3.987851"], ["84276.50", "4.259750"], ["84285.00", "4.350383"], ["84293.50", "4.441016"], ["84302.00", "3.897218"], ["84310.50", "4.984813"], ["84533.01", "0.000591"], ["84533.33", "0.003186"]], "bids": [["84043.00", "0.513647"], ["84018.70", "0.785520"], ["84016.10", "2.380740"], ["84014.30", "0"], ["83980.80", "4.803547"], ["83972.30", "4.350383"], ["83963.80", "5.528611"], ["83955.30", "4.984813"], ["83946.80", "5.619244"], ["83938.30", "4.712914"], ["83929.80", "3.897218"], ["83921.30", "4.078484"], ["83912.80", "5.166079"], ["83904.30", "5.256712"], ["83895.80", "4.169117"], ["83887.30", "4.531649"], ["83878.80", "5.347345"], ["83870.30", "4.894180"], ["83861.80", "3.987851"], ["83853.30", "4.622282"], ["83844.80", "5.075446"], ["83836.30", "4.441016"], ["83827.80", "5.437978"], ["83819.30", "4.259750"], ["83652.48", "0.000188"]], "checksum": -652090006, "ts": "1742555188345"}], "ts": 1742555188348, "record_time": 1742555188.375905, "EXCHANGE": "BITGET"}
{"action": "update", "arg": {"instType": "SPOT", "channel": "books", "instId": "BTCUSDT"}, "data": [{"asks": [["84107.00", "7.469109"], ["84115.10", "0.015000"], ["84149.00", "4.078484"], ["84157.50", "5.437978"], ["84166.00", "4.803547"], ["84174.50", "4.712914"], ["84183.00", "5.528611"], ["84191.50", "3.897218"], ["84200.00", "4.894180"], ["84208.50", "5.256712"], ["84217.00", "4.984813"], ["84225.50", "5.619244"], ["84234.00", "4.350383"], ["84242.50", "3.987851"], ["84251.00", "5.075446"], ["84259.50", "5.166079"], ["84268.00", "5.347345"], ["84276.50", "4.622282"], ["84285.00", "4.531649"], ["84302.00", "4.169117"], ["84310.50", "4.259750"], ["84533.33", "0"]], "bids": [["84039.39", "0"], ["84018.70", "1.544280"], ["84018.50", "0"], ["84014.50", "0.387390"], ["83980.80", "5.619244"], ["83972.30", "4.984813"], ["83963.80", "4.622282"], ["83955.30", "4.803547"], ["83946.80", "4.894180"], ["83938.30", "4.259750"], ["83929.80", "4.350383"], ["83921.30", "5.256712"], ["83912.80", "3.897218"], ["83904.30", "5.528611"], ["83895.80", "5.347345"], ["83887.30", "4.169117"], ["83878.80", "5.437978"], ["83870.30", "5.166079"], ["83861.80", "4.441016"], ["83853.30", "4.712914"], ["83844.80", "4.078484"], ["83836.30", "4.531649"], ["83827.80", "3.987851"], ["83819.30", "5.075446"], ["83651.65", "0.000018"], ["83651.16", "0.000896"]], "checksum": -168503444, "ts": "1742555188544"}], "ts": 1742555188547, "record_time": 1742555188.569928, "EXCHANGE": "BITGET"}
{"action": "update", "arg": {"instType": "SPOT", "channel": "books", "instId": "BTCUSDT"}, "data": [{"asks": [["84043.54", "0.086710"], ["84043.56", "0"], ["84091.00", "0.003396"], ["84093.00", "0.008937"], ["84095.00", "0.023520"], ["84097.00", "0.061893"], ["84099.00", "0.162876"], ["84101.00", "0.428622"], ["84103.00", "1.127954"], ["84105.00", "2.968298"], ["84107.00", "7.811312"], ["84149.00", "4.984813"], ["84157.50", "5.166079"], ["84166.00", "3.987851"], ["84174.50", "4.078484"], ["84183.00", "4.803547"], ["84191.50", "5.256712"], ["84208.50", "3.897218"], ["84217.00", "5.437978"], ["84225.50", "4.712914"], ["84234.00", "4.622282"], ["84242.50", "5.528611"], ["84246.84", "0"], ["84251.00", "4.350383"], ["84259.50", "4.259750"], ["84276.50", "5.075446"], ["84285.00", "4.169117"], ["84293.50", "5.619244"], ["84302.00", "4.531649"], ["84310.50", "4.441016"], ["84533.33", "0.003186"]], "bids": [["84040.27", "0.027856"], ["84011.70", "0.120000"], ["84003.70", "0.153580"], ["83982.20", "0"], ["83980.80", "4.531649"], ["83974.20", "0.200459"], ["83972.30", "3.987851"], ["83963.80", "4.803547"], ["83955.30", "4.894180"], ["83946.80", "5.166079"], ["83938.30", "4.441016"], ["83929.80", "5.347345"], ["83921.30", "4.078484"], ["83895.80", "4.169117"], ["83887.30", "4.259750"], ["83878.80", "4.622282"], ["83870.30", "5.075446"], ["83861.80", "4.712914"], ["83853.30", "4.350383"], ["83844.80", "5.256712"], ["83836.30", "5.437978"], ["83827.80", "4.984813"], ["83819.30", "5.619244"], ["83651.65", "0"], ["83651.16", "0"]], "checksum": 1120246334, "ts": "1742555188747"}], "ts": 1742555188750, "record_time": 1742555188.773896, "EXCHANGE": "BITGET"}
{"action": "update", "arg": {"instType": "SPOT", "channel": "books", "instId": "BTCUSDT"}, "data": [{"asks": [["84110.60", "0.700320"], ["84115.00", "0.300000"], ["84115.40", "1.361880"], ["84149.00", "4.622282"], ["84157.50", "4.984813"], ["84166.00", "5.619244"], ["84174.50", "5.256712"], ["84183.00", "5.347345"], ["84191.50", "5.166079"], ["84200.00", "4.441016"], ["84208.50", "4.894180"], ["84217.00", "4.078484"], ["84225.50", "4.803547"], ["84234.00", "5.528611"], ["84242.50", "3.897218"], ["84251.00", "5.437978"], ["84259.50", "4.712914"], ["84268.00", "5.075446"], ["84276.50", "4.531649"], ["84293.50", "4.350383"], ["84302.00", "3.987851"], ["84310.50", "4.259750"]], "bids": [["84042.08", "0.010000"], ["83972.30", "5.166079"], ["83963.80", "4.169117"], ["83955.30", "3.897218"], ["83946.80", "4.078484"], ["83938.30", "5.619244"], ["83929.80", "4.984813"], ["83921.30", "3.987851"], ["83912.80", "5.256712"], ["83904.30", "4.350383"], ["83895.80", "4.259750"], ["83887.30", "4.803547"], ["83878.80", "5.437978"], ["83870.30", "5.528611"], ["83861.80", "4.441016"], ["83853.30", "4.712914"], ["83844.80", "5.075446"], ["83836.30", "4.894180"], ["83827.80", "5.347345"], ["83819.30", "4.622282"], ["83652.48", "0"]], "checksum": 1052177407, "ts": "1742555188947"}], "ts": 1742555188951, "record_time": 1742555188.978525, "EXCHANGE": "BITGET"}
{"action": "update", "arg": {"instType": "SPOT", "channel": "books", "instId": "BTCUSDT"}, "data": [{"asks": [["84071.67", "0.154540"], ["84089.00", "0.001175"], ["84091.00", "0.003114"], ["84093.00", "0.008196"], ["84095.00", "0.021412"], ["84097.00", "0.056349"], ["84099.00", "0.148287"], ["84101.00", "0.390229"], ["84102.99", "0"], ["84103.00", "1.026918"], ["84105.00", "2.702414"], ["84107.00", "7.111617"], ["84108.80", "0.165990"], ["84109.60", "0.063030"], ["84109.90", "0.853950"], ["84117.00", "0"], ["84149.00", "5.437978"], ["84157.50", "5.075446"], ["84166.00", "5.347345"], ["84174.50", "3.897218"], ["84183.00", "4.622282"], ["84191.50", "4.259750"], ["84200.00", "5.528611"], ["84208.50", "4.803547"], ["84217.00", "4.531649"], ["84225.50", "5.166079"], ["84234.00", "4.441016"], ["84237.53", "0.165256"], ["84242.50", "4.169117"], ["84251.00", "3.987851"], ["84259.50", "4.894180"], ["84268.00", "4.984813"], ["84276.50", "4.078484"], ["84285.00", "4.712914"], ["84293.50", "5.619244"], ["84302.00", "4.350383"], ["84310.50", "5.256712"], ["84533.33", "0"]], "bids": [["84036.80", "0.007202"], ["84034.80", "0.018953"], ["84032.80", "0.049875"], ["84030.80", "0.131252"], ["84028.80", "0.345399"], ["84026.80", "0.908945"], ["84024.80", "2.391959"], ["84022.80", "6.294631"], ["83980.80", "4.441016"], ["83963.80", "5.347345"], ["83955.30", "4.803547"], ["83946.80", "5.256712"], ["83938.30", "4.169117"], ["83929.80", "4.622282"], ["83921.30", "5.619244"], ["83912.80", "3.987851"], ["83904.30", "5.437978"], ["83887.30", "3.897218"], ["83878.80", "4.712914"], ["83870.30", "5.075446"], ["83861.80", "4.894180"], ["83853.30", "4.078484"], ["83844.80", "5.528611"], ["83836.30", "4.531649"], ["83827.80", "4.350383"], ["83819.30", "4.984813"]], "checksum": 554146471, "ts": "1742555189157"}], "ts": 1742555189159, "record_time": 1742555189.26081, "EXCHANGE": "BITGET"}
{"action": "update", "arg": {"instType": "SPOT", "channel": "books", "instId": "BTCUSDT"}, "data": [{"asks": [["84043.52", "0.086710"], ["84043.54", "0"], ["84098.19", "0.044622"], ["84107.80", "0"], ["84107.90", "0"], ["84108.80", "0.166410"], ["84109.90", "0.854160"], ["84117.00", "1.639500"], ["84149.00", "5.619244"], ["84157.50", "5.347345"], ["84166.00", "4.712914"], ["84183.00", "4.894180"], ["84191.50", "4.531649"], ["84200.00", "5.256712"], ["84208.50", "4.350383"], ["84217.00", "4.259750"], ["84225.50", "5.075446"], ["84234.00", "4.169117"], ["84242.50", "4.803547"], ["84251.00", "5.437978"], ["84259.50", "5.166079"], ["84268.00", "4.622282"], ["84276.50", "3.987851"], ["84285.00", "4.078484"], ["84293.50", "4.441016"], ["84302.00", "5.528611"], ["84310.50", "4.984813"], ["84533.33", "0.003186"]], "bids": [["84032.80", "0.050139"], ["84030.80", "0.131943"], ["84028.80", "0.347220"], ["84026.80", "0.913736"], ["84024.80", "2.404569"], ["84022.80", "6.327813"], ["83980.80", "5.619244"], ["83972.30", "4.169117"], ["83963.80", "5.256712"], ["83946.80", "4.078484"], ["83938.30", "5.347345"], ["83929.80", "4.894180"], ["83921.30", "3.987851"], ["83912.80", "4.350383"], ["83904.30", "4.441016"], ["83895.80", "4.984813"], ["83887.30", "4.259750"], ["83878.80", "5.075446"], ["83870.30", "5.166079"], ["83861.80", "5.528611"], ["83853.30", "4.712914"], ["83844.80", "5.437978"], ["83836.30", "4.622282"], ["83827.80", "4.531649"], ["83819.30", "3.897218"]], "checksum": 1178625426, "ts": "1742555189381"}], "ts": 1742555189383, "record_time": 1742555189.409206, "EXCHANGE": "BITGET"}
{"action": "update", "arg": {"instType": "SPOT", "channel": "books", "instId": "BTCUSDT"}, "data": [{"asks": [["84101.00", "0.390099"], ["84103.00", "1.026576"], ["84105.00", "2.701517"], ["84107.00", "7.109255"], ["84126.21", "0.062760"], ["84149.00", "4.078484"], ["84157.50", "3.897218"], ["84166.00", "3.987851"], ["84174.50", "4.441016"], ["84183.00", "4.169117"], ["84200.00", "4.350383"], ["84208.50", "5.075446"], ["84217.00", "5.256712"], ["84225.50", "4.984813"], ["84234.00", "4.803547"], ["84242.50", "4.259750"], ["84251.00", "4.622282"], ["84259.50", "4.894180"], ["84268.00", "4.712914"], ["84276.50", "5.347345"], ["84285.00", "5.166079"], ["84293.50", "5.528611"], ["84302.00", "5.437978"], ["84310.50", "5.619244"], ["84533.33", "0"]], "bids": [["84040.39", "0.027856"], ["84040.27", "0"], ["84028.80", "0.346985"], ["84026.80", "0.913119"], ["84024.80", "2.402943"], ["84022.80", "6.323535"], ["83980.80", "5.437978"], ["83972.30", "5.619244"], ["83963.80", "4.350383"], ["83955.30", "5.528611"], ["83946.80", "4.803547"], ["83938.30", "3.987851"], ["83929.80", "3.897218"], ["83921.30", "4.531649"], ["83912.80", "4.169117"], ["83904.30", "5.256712"], ["83895.80", "4.712914"], ["83887.30", "4.894180"], ["83878.80", "4.622282"], ["83870.30", "5.075446"], ["83861.80", "4.078484"], ["83853.30", "4.259750"], ["83844.80", "4.441016"], ["83836.30", "5.166079"], ["83827.80", "5.347345"], ["83819.30", "4.984813"]], "checksum": -2018447391, "ts": "1742555189602"}], "ts": 1742555189605, "record_time": 1742555189.628387, "EXCHANGE": "BITGET"}
{"action": "update", "arg": {"instType": "SPOT", "channel": "books", "instId": "BTCUSDT"}, "data": [{"asks": [["84043.52", "0"], ["84091.00", "0.002965"], ["84093.00", "0.007803"], ["84095.00", "0.020534"], ["84097.00", "0.054035"], ["84099.00", "0.142199"], ["84101.00", "0.374207"], ["84103.00", "0.984755"], ["84105.00", "2.591461"], ["84107.00", "6.819634"], ["84108.50", "0.001029"], ["84108.60", "0.295800"], ["84108.80", "0"], ["84109.60", "0"], ["84109.90", "0.854370"], ["84115.10", "0.021870"], ["84115.40", "1.359990"], ["84149.00", "5.437978"], ["84157.49", "0.246534"], ["84157.50", "4.350383"], ["84166.00", "4.622282"], ["84174.50", "4.894180"], ["84183.00", "3.897218"], ["84191.50", "3.987851"], ["84200.00", "4.259750"], ["84208.50", "4.169117"], ["84217.00", "5.528611"], ["84225.50", "4.078484"], ["84234.00", "5.347345"], ["84242.50", "4.712914"], ["84251.00", "4.531649"], ["84259.50", "5.256712"], ["84268.00", "4.803547"], ["84276.50", "4.441016"], ["84293.50", "4.984813"], ["84302.00", "5.619244"], ["84310.50", "5.075446"]], "bids": [["84019.30", "0.076440"], ["83980.80", "4.894180"], ["83972.30", "4.441016"], ["83963.80", "4.712914"], ["83955.30", "5.256712"], ["83946.80", "5.166079"], ["83938.30", "5.619244"], ["83929.80", "5.528611"], ["83921.30", "3.897218"], ["83912.80", "4.531649"], ["83904.30", "4.622282"], ["83895.80", "4.984813"], ["83887.30", "4.169117"], ["83878.80", "5.347345"], ["83870.30", "4.803547"], ["83861.80", "4.259750"], ["83853.30", "4.078484"], ["83844.80", "5.437978"], ["83836.30", "4.350383"], ["83827.80", "3.987851"], ["83819.30", "5.075446"]], "checksum": -2003077057, "ts": "1742555189813"}], "ts": 1742555189815, "record_time": 1742555189.838248, "EXCHANGE": "BITGET"}
{"action": "update", "arg": {"instType": "SPOT", "channel": "books", "instId": "BTCUSDT"}, "data": [{"asks": [["84043.02", "0.133496"], ["84043.50", "0.086710"], ["84077.18", "0"], ["84089.00", "0.001368"], ["84091.00", "0.003600"], ["84093.00", "0.009474"], ["84095.00", "0.024932"], ["84097.00", "0.065612"], ["84099.00", "0.172663"], ["84101.00", "0.454374"], ["84103.00", "1.195723"], ["84105.00", "3.146638"], ["84107.00", "8.280627"], ["84107.80", "0.001013"], ["84107.90", "0.072300"], ["84108.10", "0.071370"], ["84108.50", "0"], ["84109.90", "0.853740"], ["84115.40", "1.359000"], ["84117.00", "0"], ["84149.00", "5.166079"], ["84157.50", "4.622282"], ["84166.00", "4.712914"], ["84174.50", "3.987851"], ["84183.00", "4.350383"], ["84191.50", "5.619244"], ["84200.00", "4.169117"], ["84208.50", "4.803547"], ["84217.00", "5.437978"], ["84225.50", "4.984813"], ["84234.00", "4.441016"], ["84242.50", "3.897218"], ["84251.00", "4.259750"], ["84259.50", "5.075446"], ["84268.00", "5.256712"], ["84276.50", "4.531649"], ["84285.00", "4.894180"], ["84293.50", "5.528611"], ["84302.00", "4.078484"], ["84310.50", "5.347345"]], "bids": [["84038.80", "0.002761"], ["84034.80", "0.019125"], ["84032.80", "0.050330"], ["84030.80", "0.132446"], ["84028.80", "0.348544"], ["84026.80", "0.917220"], ["84024.80", "2.413736"], ["84022.80", "6.351937"], ["83980.80", "4.803547"], ["83972.30", "3.897218"], ["83963.80", "4.169117"], ["83955.30", "5.166079"], ["83946.80", "4.350383"], ["83938.30", "4.259750"], ["83929.80", "5.256712"], ["83921.30", "4.984813"], ["83919.35", "0"], ["83912.80", "4.712914"], ["83904.30", "5.619244"], ["83895.80", "4.441016"], ["83887.30", "5.075446"], ["83878.80", "5.528611"], ["83870.30", "4.622282"], ["83861.80", "5.437978"], ["83853.30", "4.531649"], ["83844.80", "4.894180"], ["83836.30", "3.987851"], ["83827.80", "4.078484"], ["83819.30", "5.347345"], ["83652.48", "0.000188"]], "checksum": 687491942, "ts": "1742555190014"}], "ts": 1742555190021, "record_time": 1742555190.10163, "EXCHANGE": "BITGET"}
{"action": "update", "arg": {"instType": "SPOT", "channel": "books", "instId": "BTCUSDT"}, "data": [{"asks": [["84043.02", "0.158992"], ["84076.75", "0"], ["84077.18", "0.176639"], ["84097.74", "0.001598"], ["84099.39", "0.001597"], ["84105.58", "0"], ["84107.37", "0"], ["84108.60", "0.349350"], ["84109.90", "0.853530"], ["84149.00", "4.078484"], ["84157.50", "5.256712"], ["84166.00", "4.622282"], ["84174.50", "4.259750"], ["84183.00", "5.347345"], ["84191.50", "5.075446"], ["84200.00", "5.437978"], ["84208.50", "5.619244"], ["84217.00", "4.531649"], ["84225.50", "5.166079"], ["84234.00", "3.897218"], ["84242.50", "4.712914"], ["84251.00", "5.528611"], ["84259.50", "4.894180"], ["84268.00", "4.350383"], ["84276.50", "4.441016"], ["84285.00", "4.169117"], ["84293.50", "4.803547"], ["84302.00", "4.984813"], ["84310.50", "3.987851"]], "bids": [["84026.80", "0.917118"], ["84024.80", "2.413468"], ["84022.80", "6.351491"], ["83995.31", "0"], ["83993.23", "0"], ["83987.48", "0.001176"], ["83985.26", "0.001173"], ["83980.80", "3.987851"], ["83972.30", "5.075446"], ["83963.80", "4.078484"], ["83955.30", "4.803547"], ["83946.80", "4.259750"], ["83938.30", "4.531649"], ["83929.80", "4.441016"], ["83921.30", "5.619244"], ["83907.25", "0.125640"], ["83904.30", "5.437978"], ["83895.80", "3.897218"], ["83887.30", "4.350383"], ["83870.30", "4.984813"], ["83861.80", "5.347345"], ["83853.30", "4.622282"], ["83844.80", "5.166079"], ["83836.30", "5.256712"], ["83827.80", "4.894180"], ["83819.30", "4.169117"], ["83652.48", "0"]], "checksum": 1940206586, "ts": "1742555190234"}], "ts": 1742555190236, "record_time": 1742555190.259669, "EXCHANGE": "BITGET"}
{"action": "update", "arg": {"instType": "SPOT", "channel": "books", "instId": "BTCUSDT"}, "data": [{"asks": [["84043.48", "0.086710"], ["84043.50", "0"], ["84076.75", "0.159474"], ["84087.22", "0.010000"], ["84107.00", "8.280367"], ["84149.00", "4.441016"], ["84157.50", "4.894180"], ["84166.00", "4.169117"], ["84174.50", "4.350383"], ["84183.00", "4.531649"], ["84191.50", "5.256712"], ["84200.00", "5.166079"], ["84208.50", "4.803547"], ["84217.00", "3.897218"], ["84225.50", "5.347345"], ["84234.00", "4.984813"], ["84242.50", "4.259750"], ["84251.00", "4.078484"], ["84259.50", "5.075446"], ["84268.00", "5.619244"], ["84276.50", "5.437978"], ["84285.00", "4.712914"], ["84293.50", "5.528611"], ["84302.00", "3.987851"], ["84310.50", "4.622282"], ["84530.00", "0"], ["84533.01", "0"]], "bids": [["84040.39", "0"], ["83980.80", "4.803547"], ["83972.30", "3.987851"], ["83963.80", "4.169117"], ["83955.30", "4.259750"], ["83946.80", "5.347345"], ["83938.30", "5.075446"], ["83929.80", "5.528611"], ["83921.30", "3.897218"], ["83912.80", "4.441016"], ["83904.30", "4.984813"], ["83895.80", "4.078484"], ["83887.30", "4.531649"], ["83878.80", "5.256712"], ["83870.30", "5.619244"], ["83861.80", "4.622282"], ["83853.30", "5.437978"], ["83836.30", "4.350383"], ["83827.80", "4.712914"], ["83819.30", "4.894180"], ["83652.48", "0.000188"]], "checksum": -841316554, "ts": "1742555190440"}], "ts": 1742555190442, "record_time": 1742555190.465687, "EXCHANGE": "BITGET"}
{"action": "update", "arg": {"instType": "SPOT", "channel": "books", "instId": "BTCUSDT"}, "data": [{"asks": [["84043.01", "2.128064"], ["84102.99", "0.310372"], ["84107.00", "8.280664"], ["84107.80", "0"], ["84107.90", "0"], ["84108.50", "0.073530"], ["84149.00", "3.897218"], ["84157.49", "0"], ["84157.50", "4.441016"], ["84166.00", "4.350383"], ["84174.50", "5.256712"], ["84183.00", "4.259750"], ["84191.50", "4.803547"], ["84200.00", "4.169117"], ["84208.50", "3.987851"], ["84217.00", "5.437978"], ["84225.50", "5.528611"], ["84234.00", "4.712914"], ["84242.50", "4.078484"], ["84251.00", "5.619244"], ["84259.50", "5.166079"], ["84268.00", "4.984813"], ["84276.50", "4.531649"], ["84285.00", "4.894180"], ["84293.50", "5.347345"], ["84302.00", "4.622282"], ["84310.50", "5.075446"], ["84530.00", "0.000031"]], "bids": [["84041.32", "0.027856"], ["84028.80", "0.348321"], ["84026.80", "0.916634"], ["84024.80", "2.412196"], ["84022.80", "6.347882"], ["84011.70", "0"], ["83980.80", "4.712914"], ["83972.30", "5.166079"], ["83963.80", "4.259750"], ["83955.30", "4.531649"], ["83938.30", "4.894180"], ["83929.80", "3.987851"], ["83921.30", "4.803547"], ["83912.80", "4.169117"], ["83904.30", "4.441016"], ["83895.80", "4.622282"], ["83887.30", "5.437978"], ["83878.80", "3.897218"], ["83870.30", "5.528611"], ["83861.80", "5.075446"], ["83853.30", "5.619244"], ["83844.80", "4.078484"], ["83836.30", "4.984813"], ["83827.80", "4.350383"], ["83819.30", "5.256712"]], "checksum": -562775857, "ts": "1742555190643"}], "ts": 1742555190646, "record_time": 1742555190.670553, "EXCHANGE": "BITGET"}
{"action": "update", "arg": {"instType": "SPOT", "channel": "books", "instId": "BTCUSDT"}, "data": [{"asks": [["84043.48", "0"], ["84063.47", "0.035952"], ["84064.93", "0.035961"], ["84065.37", "0.006356"], ["84065.53", "0.006356"], ["84065.86", "0.006356"], ["84066.74", "0"], ["84067.23", "0.010984"], ["84068.17", "0.006356"], ["84068.37", "0.006356"], ["84068.57", "0"], ["84068.60", "0.006356"], ["84068.73", "0.119883"], ["84068.93", "0.006356"], ["84068.94", "0.016429"], ["84068.95", "0"], ["84069.11", "0"], ["84069.44", "0"], ["84070.33", "0.010985"], ["84070.39", "0.006357"], ["84070.56", "0"], ["84071.50", "0.009990"], ["84071.53", "0"], ["84071.87", "0"], ["84071.95", "0"], ["84072.20", "0"], ["84072.31", "0"], ["84072.60", "0"], ["84073.18", "0.119858"], ["84073.33", "0.119867"], ["84073.77", "0.009989"], ["84073.82", "0.015895"], ["84073.97", "0"], ["84074.04", "0"], ["84074.82", "0"], ["84076.76", "0"], ["84077.08", "0"], ["84077.35", "0"], ["84077.68", "0.015892"], ["84078.60", "0.010988"], ["84080.39", "0"], ["84084.57", "0"], ["84085.44", "0"], ["84149.00", "5.437978"], ["84157.50", "4.803547"], ["84166.00", "4.441016"], ["84174.50", "4.894180"], ["84183.00", "4.531649"], ["84191.50", "5.347345"], ["84200.00", "5.256712"], ["84208.50", "4.622282"], ["84217.00", "4.712914"], ["84225.50", "4.078484"], ["84234.00", "5.619244"], ["84242.50", "4.259750"], ["84251.00", "4.169117"], ["84259.50", "4.984813"], ["84268.00", "4.350383"], ["84276.50", "5.166079"], ["84285.00", "5.075446"], ["84293.50", "3.897218"], ["84302.00", "5.528611"], ["84310.50", "3.987851"], ["84533.01", "0.000591"]], "bids": [["84040.80", "0.001170"], ["84038.80", "0.003079"], ["84036.80", "0.008103"], ["84034.80", "0.021324"], ["84032.80", "0.056115"], ["84030.80", "0.147671"], ["84028.80", "0.388608"], ["84027.66", "0"], ["84026.80", "1.022652"], ["84026.40", "0"], ["84024.87", "0.005584"], ["84024.80", "2.691191"], ["84024.41", "0"], ["84024.23", "0"], ["84023.89", "0"], ["84023.13", "0.089506"], ["84022.82", "0"], ["84022.80", "7.082080"], ["84021.95", "0"], ["84021.36", "0"], ["84021.27", "0"], ["84021.22", "0.083960"], ["84021.04", "0"], ["84020.99", "0"], ["84020.94", "0"], ["84020.87", "0"], ["84020.83", "0.017821"], ["84020.73", "0.004018"], ["84020.65", "0.018259"], ["84020.31", "0.005948"], ["84019.88", "0"], ["84019.50", "0.055669"], ["84019.41", "0"], ["84019.34", "0"], ["84018.59", "0.007341"], ["84018.51", "0"], ["84018.01", "0.007945"], ["84017.78", "0.008996"], ["84017.67", "0.025190"], ["84017.46", "0.224937"], ["84017.32", "0.008187"], ["84017.29", "0.017355"], ["84016.59", "0"], ["84016.06", "0"], ["84015.76", "0.012658"], ["84015.70", "0.051976"], ["84015.64", "0"], ["84015.19", "0.018521"], ["84014.84", "0"], ["84013.01", "0.222723"], ["84012.82", "0.259859"], ["84012.80", "0.076131"], ["84012.42", "0.021135"], ["84009.80", "0"], ["84008.76", "0.073233"], ["84008.01", "0.056381"], ["84006.35", "0.000877"], ["83991.11", "0"], ["83987.85", "0.003598"], ["83980.80", "4.441016"], ["83972.30", "3.897218"], ["83963.80", "4.622282"], ["83955.30", "4.078484"], ["83946.80", "5.166079"], ["83938.30", "5.619244"], ["83929.80", "4.712914"], ["83921.30", "4.169117"], ["83912.80", "4.350383"], ["83904.30", "4.259750"], ["83895.80", "4.984813"], ["83887.30", "5.528611"], ["83878.80", "4.531649"], ["83870.30", "3.987851"], ["83861.80", "5.256712"], ["83853.30", "5.347345"], ["83844.80", "5.075446"], ["83836.30", "4.803547"], ["83827.80", "5.437978"], ["83819.30", "4.894180"], ["83652.80", "0"], ["83652.48", "0"]], "checksum": -981939057, "ts": "1742555190869"}], "ts": 1742555190873, "record_time": 1742555190.896555, "EXCHANGE": "BITGET"}
{"action": "update", "arg": {"instType": "SPOT", "channel": "books", "instId": "BTCUSDT"}, "data": [{"asks": [["84043.02", "0.133496"], ["84043.47", "0.086710"], ["84065.85", "0"], ["84103.00", "1.195956"], ["84105.00", "3.147253"], ["84107.00", "8.282245"], ["84108.60", "0.295800"], ["84108.70", "0.053550"], ["84149.00", "3.987851"], ["84157.50", "4.894180"], ["84166.00", "5.528611"], ["84174.50", "4.803547"], ["84183.00", "4.350383"], ["84191.50", "4.078484"], ["84200.00", "4.984813"], ["84208.50", "5.437978"], ["84225.50", "4.622282"], ["84234.00", "5.075446"], ["84251.00", "5.166079"], ["84259.50", "5.347345"], ["84268.00", "5.619244"], ["84276.50", "4.169117"], ["84285.00", "3.897218"], ["84293.50", "4.441016"], ["84302.00", "4.531649"], ["84310.50", "5.256712"], ["84533.01", "0"]], "bids": [["84042.08", "0"], ["83980.80", "4.078484"], ["83972.30", "5.256712"], ["83963.80", "5.437978"], ["83955.30", "4.712914"], ["83946.80", "3.987851"], ["83938.30", "4.259750"], ["83929.80", "5.075446"], ["83921.30", "4.894180"], ["83904.30", "4.531649"], ["83895.80", "4.169117"], ["83887.30", "5.347345"], ["83878.80", "5.528611"], ["83870.30", "3.897218"], ["83861.80", "4.622282"], ["83853.30", "4.803547"], ["83844.80", "5.619244"], ["83836.30", "5.166079"], ["83827.80", "4.984813"], ["83819.30", "4.441016"], ["83652.80", "0.000119"]], "checksum": -1870771491, "ts": "1742555191088"}], "ts": 1742555191091, "record_time": 1742555191.116958, "EXCHANGE": "BITGET"}
{"action": "update", "arg": {"instType": "SPOT", "channel": "books", "instId": "BTCUSDT"}, "data": [{"asks": [["84043.02", "0.158992"], ["84108.70", "0"], ["84109.90", "0.853740"], ["84117.00", "1.639500"], ["84149.00", "4.441016"], ["84157.50", "5.437978"], ["84166.00", "3.897218"], ["84174.50", "3.987851"], ["84183.00", "5.166079"], ["84191.50", "5.347345"], ["84200.00", "4.259750"], ["84208.50", "5.075446"], ["84217.00", "4.803547"], ["84225.50", "4.531649"], ["84234.00", "4.350383"], ["84242.50", "5.256712"], ["84251.00", "4.622282"], ["84259.50", "4.894180"], ["84268.00", "4.169117"], ["84276.50", "4.712914"], ["84285.00", "5.528611"], ["84293.50", "4.984813"], ["84302.00", "5.619244"], ["84310.50", "4.078484"]], "bids": [["84040.80", "0.001044"], ["84038.80", "0.002748"], ["84036.80", "0.007230"], ["84034.80", "0.019028"], ["84032.80", "0.050072"], ["84030.80", "0.131770"], ["84028.80", "0.346762"], ["84027.67", "0"], ["84026.80", "0.912533"], ["84024.80", "2.401403"], ["84022.80", "6.319480"], ["84018.89", "0.027453"], ["83980.80", "4.712914"], ["83972.30", "5.619244"], ["83963.80", "5.347345"], ["83955.30", "4.350383"], ["83938.30", "4.078484"], ["83929.80", "4.622282"], ["83921.30", "3.897218"], ["83912.80", "4.803547"], ["83904.30", "4.259750"], ["83895.80", "5.437978"], ["83887.30", "5.166079"], ["83878.80", "4.531649"], ["83870.30", "4.169117"], ["83861.80", "5.256712"], ["83853.30", "4.984813"], ["83844.80", "5.075446"], ["83836.30", "5.528611"], ["83827.80", "4.894180"]], "checksum": 1611059330, "ts": "1742555191302"}], "ts": 1742555191306, "record_time": 1742555191.334668, "EXCHANGE": "BITGET"}
{"action": "update", "arg": {"instType": "SPOT", "channel": "books", "instId": "BTCUSDT"}, "data": [{"asks": [["84043.45", "0.086710"], ["84043.47", "0"], ["84064.78", "0.052470"], ["84149.00", "4.169117"], ["84157.50", "5.347345"], ["84166.00", "5.166079"], ["84174.50", "5.256712"], ["84183.00", "4.259750"], ["84191.50", "4.894180"], ["84200.00", "5.437978"], ["84208.50", "4.531649"], ["84217.00", "4.441016"], ["84225.50", "5.075446"], ["84234.00", "5.619244"], ["84242.50", "4.622282"], ["84251.00", "5.528611"], ["84259.50", "4.078484"], ["84268.00", "4.803547"], ["84276.50", "3.897218"], ["84285.00", "4.350383"], ["84293.50", "4.712914"], ["84302.00", "4.984813"], ["84310.50", "3.987851"], ["84530.00", "0"]], "bids": [["84032.80", "0.050282"], ["84030.80", "0.132320"], ["84028.80", "0.348212"], ["84026.80", "0.916347"], ["84024.80", "2.411439"], ["84022.80", "6.345706"], ["83980.80", "5.166079"], ["83972.30", "3.897218"], ["83963.80", "4.894180"], ["83955.30", "4.441016"], ["83946.80", "4.078484"], ["83938.30", "4.622282"], ["83929.80", "5.347345"], ["83921.30", "4.531649"], ["83904.30", "3.987851"], ["83895.80", "5.528611"], ["83887.30", "4.169117"], ["83878.80", "5.075446"], ["83870.30", "5.437978"], ["83861.80", "5.619244"], ["83844.80", "4.712914"], ["83836.30", "4.259750"], ["83827.80", "5.256712"], ["83819.30", "4.350383"]], "checksum": 496859373, "ts": "1742555191502"}], "ts": 1742555191505, "record_time": 1742555191.526728, "EXCHANGE": "BITGET"}
{"action": "update", "arg": {"instType": "SPOT", "channel": "books", "instId": "BTCUSDT"}, "data": [{"asks": [["84094.28", "0.284285"], ["84126.21", "0"], ["84149.00", "4.622282"], ["84157.50", "4.803547"], ["84166.00", "5.256712"], ["84174.50", "5.437978"], ["84183.00", "5.166079"], ["84191.50", "4.984813"], ["84200.00", "5.619244"], ["84208.50", "4.894180"], ["84217.00", "4.259750"], ["84225.50", "5.528611"], ["84234.00", "5.075446"], ["84242.50", "4.350383"], ["84251.00", "4.169117"], ["84259.50", "3.897218"], ["84268.00", "4.078484"], ["84276.50", "4.441016"], ["84285.00", "4.712914"], ["84293.50", "3.987851"], ["84302.00", "5.347345"], ["84310.50", "4.531649"]], "bids": [["83980.80", "4.894180"], ["83972.30", "4.803547"], ["83963.80", "4.259750"], ["83955.30", "5.166079"], ["83938.30", "5.619244"], ["83929.80", "5.075446"], ["83912.80", "4.622282"], ["83904.30", "3.897218"], ["83895.80", "5.256712"], ["83887.30", "3.987851"], ["83878.80", "4.350383"], ["83870.30", "4.984813"], ["83861.80", "4.169117"], ["83853.30", "4.441016"], ["83836.30", "5.347345"], ["83827.80", "5.437978"], ["83819.30", "5.528611"]], "checksum": 496859373, "ts": "1742555191711"}], "ts": 1742555191714, "record_time": 1742555191.812845, "EXCHANGE": "BITGET"}
{"action": "update", "arg": {"instType": "SPOT", "channel": "books", "instId": "BTCUSDT"}, "data": [{"asks": [["84043.44", "0.086710"], ["84043.45", "0"], ["84102.99", "0"], ["84108.80", "0.053550"], ["84109.90", "0.853530"], ["84117.00", "0"], ["84149.00", "5.619244"], ["84157.50", "4.712914"], ["84166.00", "5.075446"], ["84174.50", "4.984813"], ["84183.00", "5.256712"], ["84191.50", "4.894180"], ["84200.00", "5.166079"], ["84208.50", "4.259750"], ["84217.00", "4.531649"], ["84225.50", "4.622282"], ["84234.00", "4.078484"], ["84242.50", "5.347345"], ["84251.00", "4.441016"], ["84268.00", "5.528611"], ["84276.50", "5.437978"], ["84285.00", "4.169117"], ["84293.50", "4.803547"], ["84302.00", "3.987851"], ["84310.50", "4.350383"], ["84530.00", "0.000031"]], "bids": [["83980.80", "5.347345"], ["83972.30", "3.897218"], ["83963.80", "5.256712"], ["83938.30", "4.803547"], ["83929.80", "4.712914"], ["83921.30", "4.894180"], ["83912.80", "4.984813"], ["83904.30", "5.528611"], ["83895.80", "4.350383"], ["83887.30", "4.441016"], ["83878.80", "5.619244"], ["83870.30", "3.987851"], ["83861.80", "4.622282"], ["83853.30", "5.437978"], ["83844.80", "4.169117"], ["83836.30", "5.075446"], ["83827.80", "4.531649"], ["83819.30", "4.259750"]], "checksum": 2142806859, "ts": "1742555191913"}], "ts": 1742555191915, "record_time": 1742555191.943299, "EXCHANGE": "BITGET"}
{"action": "update", "arg": {"instType": "SPOT", "channel": "books", "instId": "BTCUSDT"}, "data": [{"asks": [["84077.18", "0"], ["84109.40", "0.071670"], ["84116.90", "0"], ["84157.50", "5.437978"], ["84166.00", "4.441016"], ["84174.50", "4.169117"], ["84183.00", "4.350383"], ["84191.50", "4.803547"], ["84200.00", "5.528611"], ["84208.50", "5.075446"], ["84217.00", "4.894180"], ["84225.50", "3.897218"], ["84234.00", "4.259750"], ["84251.00", "4.622282"], ["84259.50", "5.256712"], ["84268.00", "3.987851"], ["84276.50", "4.984813"], ["84285.00", "4.531649"], ["84293.50", "5.166079"], ["84302.00", "4.712914"], ["84310.50", "4.078484"], ["84533.01", "0.000591"]], "bids": [["84024.80", "2.411192"], ["84022.80", "6.345241"], ["83980.80", "5.075446"], ["83972.30", "5.347345"], ["83963.80", "4.622282"], ["83955.30", "3.987851"], ["83946.80", "4.894180"], ["83938.30", "4.078484"], ["83929.80", "4.803547"], ["83921.30", "5.437978"], ["83912.80", "5.528611"], ["83904.30", "5.619244"], ["83895.80", "5.166079"], ["83887.30", "3.897218"], ["83878.80", "4.350383"], ["83870.30", "4.441016"], ["83861.80", "4.531649"], ["83853.30", "4.259750"], ["83844.80", "4.712914"], ["83836.30", "4.169117"], ["83827.80", "4.984813"], ["83819.30", "5.256712"]], "checksum": 2142806859, "ts": "1742555192134"}], "ts": 1742555192138, "record_time": 1742555192.19344, "EXCHANGE": "BITGET"}
{"action": "update", "arg": {"instType": "SPOT", "channel": "books", "instId": "BTCUSDT"}, "data": [{"asks": [["84076.75", "0"], ["84087.22", "0"], ["84126.21", "0.062760"], ["84149.00", "4.078484"], ["84157.50", "4.894180"], ["84166.00", "4.984813"], ["84174.50", "5.528611"], ["84183.00", "3.897218"], ["84191.50", "5.256712"], ["84200.00", "5.166079"], ["84208.50", "4.712914"], ["84217.00", "4.259750"], ["84225.50", "4.350383"], ["84234.00", "5.075446"], ["84242.50", "5.437978"], ["84251.00", "4.441016"], ["84259.50", "5.347345"], ["84276.50", "4.169117"], ["84285.00", "4.622282"], ["84293.50", "5.619244"], ["84302.00", "4.803547"], ["84310.50", "4.531649"], ["84525.00", "0.003689"], ["84533.33", "0.003186"]], "bids": [["84032.80", "0.050065"], ["84030.80", "0.131751"], ["84028.80", "0.346711"], ["84026.80", "0.912399"], ["84024.80", "2.401049"], ["84022.80", "6.318550"], ["83980.80", "4.984813"], ["83972.30", "4.259750"], ["83963.80", "5.075446"], ["83955.30", "5.528611"], ["83946.80", "4.531649"], ["83938.30", "5.256712"], ["83929.80", "4.350383"], ["83921.30", "5.347345"], ["83912.80", "4.803547"], ["83904.30", "4.169117"], ["83895.80", "4.622282"], ["83887.30", "3.987851"], ["83878.80", "4.441016"], ["83870.30", "4.712914"], ["83861.80", "5.619244"], ["83853.30", "4.078484"], ["83844.80", "4.894180"], ["83836.30", "3.897218"], ["83827.80", "5.437978"], ["83819.30", "5.166079"]], "checksum": 280255570, "ts": "1742555192335"}], "ts": 1742555192338, "record_time": 1742555192.401101, "EXCHANGE": "BITGET"}
{"action": "update", "arg": {"instType": "SPOT", "channel": "books", "instId": "BTCUSDT"}, "data": [{"asks": [["84043.42", "0.086710"], ["84043.44", "0"], ["84077.17", "0.176173"], ["84079.67", "0.062760"], ["84089.00", "0.001507"], ["84091.00", "0.003965"], ["84093.00", "0.010434"], ["84095.00", "0.027457"], ["84097.00", "0.072257"], ["84099.00", "0.190149"], ["84101.00", "0.500391"], ["84103.00", "1.316819"], ["84105.00", "3.465313"], ["84107.00", "9.119245"], ["84108.80", "0"], ["84111.60", "0.071370"], ["84116.60", "0"], ["84149.00", "3.987851"], ["84166.00", "5.166079"], ["84183.00", "4.531649"], ["84191.50", "5.347345"], ["84200.00", "4.441016"], ["84208.50", "5.437978"], ["84217.00", "3.897218"], ["84225.50", "5.619244"], ["84234.00", "4.259750"], ["84242.50", "4.078484"], ["84251.00", "4.350383"], ["84259.50", "4.984813"], ["84268.00", "5.256712"], ["84276.50", "5.075446"], ["84285.00", "4.803547"], ["84293.50", "4.712914"], ["84302.00", "4.169117"], ["84310.50", "4.622282"], ["84533.33", "0"]], "bids": [["84038.80", "0.002220"], ["84036.80", "0.005843"], ["84034.80", "0.015376"], ["84032.80", "0.040464"], ["84030.80", "0.106483"], ["84028.80", "0.280218"], ["84026.80", "0.737416"], ["84024.80", "1.940569"], ["84022.80", "5.106760"], ["84021.00", "0.078480"], ["84017.90", "0.007230"], ["84011.70", "0.120000"], ["84002.00", "0"], ["83980.80", "4.078484"], ["83972.30", "4.803547"], ["83963.80", "5.256712"], ["83955.30", "5.347345"], ["83946.80", "5.528611"], ["83938.30", "4.712914"], ["83929.80", "4.441016"], ["83921.30", "5.437978"], ["83912.80", "4.622282"], ["83904.30", "4.259750"], ["83895.80", "3.987851"], ["83887.30", "4.894180"], ["83878.80", "3.897218"], ["83870.30", "5.619244"], ["83861.80", "5.166079"], ["83853.30", "4.350383"], ["83844.80", "5.075446"], ["83836.30", "4.984813"], ["83827.80", "4.169117"], ["83819.30", "4.531649"]], "checksum": -2028529347, "ts": "1742555192537"}], "ts": 1742555192542, "record_time": 1742555192.567245, "EXCHANGE": "BITGET"}
{"action": "update", "arg": {"instType": "SPOT", "channel": "books", "instId": "BTCUSDT"}, "data": [{"asks": [["84089.00", "0.001632"], ["84091.00", "0.004297"], ["84093.00", "0.011306"], ["84095.00", "0.029753"], ["84097.00", "0.078299"], ["84099.00", "0.206050"], ["84101.00", "0.542237"], ["84102.99", "0.075567"], ["84103.00", "1.426939"], ["84105.00", "3.755101"], ["84107.00", "9.881845"], ["84109.40", "0.071880"], ["84109.80", "0.973860"], ["84109.90", "0.405570"], ["84116.60", "0.356940"], ["84149.00", "4.531649"], ["84157.50", "4.350383"], ["84166.00", "4.712914"], ["84174.50", "4.169117"], ["84183.00", "4.078484"], ["84191.50", "5.256712"], ["84200.00", "5.619244"], ["84208.50", "5.528611"], ["84217.00", "5.075446"], ["84225.50", "5.166079"], ["84234.00", "3.987851"], ["84242.50", "5.347345"], ["84251.00", "3.897218"], ["84259.50", "4.441016"], ["84268.00", "4.622282"], ["84276.50", "4.803547"], ["84285.00", "4.984813"], ["84293.50", "4.259750"], ["84302.00", "4.894180"], ["84310.50", "5.437978"], ["84528.57", "0"], ["84530.00", "0"], ["84533.01", "0"]], "bids": [["84022.80", "5.106890"], ["84021.00", "0.078060"], ["84020.00", "0.009000"], ["84019.30", "0.076650"], ["84011.70", "0"], ["83980.80", "4.712914"], ["83972.30", "4.259750"], ["83963.80", "4.169117"], ["83955.30", "4.350383"], ["83946.80", "4.531649"], ["83938.30", "5.347345"], ["83929.80", "5.256712"], ["83921.30", "5.166079"], ["83912.80", "5.075446"], ["83904.30", "4.441016"], ["83895.80", "4.078484"], ["83887.30", "3.897218"], ["83878.80", "5.437978"], ["83870.30", "4.894180"], ["83861.80", "4.622282"], ["83853.30", "5.528611"], ["83844.80", "4.803547"], ["83836.30", "5.619244"], ["83827.80", "3.987851"], ["83819.30", "4.984813"], ["83652.48", "0.000188"]], "checksum": -2028529347, "ts": "1742555192738"}], "ts": 1742555192740, "record_time": 1742555192.77126, "EXCHANGE": "BITGET"}
{"action": "update", "arg": {"instType": "SPOT", "channel": "books", "instId": "BTCUSDT"}, "data": [{"asks": [["84043.42", "0"], ["84109.80", "0.704100"], ["84116.90", "0.228000"], ["84149.00", "4.803547"], ["84157.50", "5.256712"], ["84166.00", "4.078484"], ["84174.50", "5.619244"], ["84183.00", "4.350383"], ["84191.50", "5.347345"], ["84200.00", "4.441016"], ["84208.50", "4.169117"], ["84217.00", "5.166079"], ["84225.50", "4.712914"], ["84234.00", "5.437978"], ["84242.50", "4.622282"], ["84251.00", "5.528611"], ["84259.50", "4.259750"], ["84268.00", "4.531649"], ["84276.50", "4.894180"], ["84285.00", "3.897218"], ["84293.50", "3.987851"], ["84302.00", "4.984813"], ["84310.50", "5.075446"]], "bids": [["84043.00", "0.511288"], ["84032.80", "0.040658"], ["84030.80", "0.106996"], ["84028.80", "0.281569"], ["84026.80", "0.740969"], ["84024.80", "1.949920"], ["84022.80", "5.131368"], ["83972.30", "5.166079"], ["83963.80", "4.622282"], ["83955.30", "5.619244"], ["83946.80", "3.897218"], ["83929.80", "4.984813"], ["83921.30", "4.169117"], ["83904.30", "3.987851"], ["83895.80", "4.803547"], ["83887.30", "4.531649"], ["83870.30", "5.256712"], ["83861.80", "4.894180"], ["83844.80", "4.350383"], ["83836.30", "4.441016"], ["83827.80", "4.259750"], ["83819.30", "4.078484"]], "checksum": -1400098096, "ts": "1742555192945"}], "ts": 1742555192948, "record_time": 1742555192.970357, "EXCHANGE": "BITGET"}
{"action": "update", "arg": {"instType": "SPOT", "channel": "books", "instId": "BTCUSDT"}, "data": [{"asks": [["84043.02", "0.133496"], ["84043.41", "0.086745"], ["84063.56", "0.119870"], ["84064.79", "0"], ["84067.11", "0.006356"], ["84067.26", "0"], ["84067.28", "0.006356"], ["84067.44", "0"], ["84067.78", "0.016429"], ["84067.94", "0"], ["84068.80", "0.006356"], ["84069.95", "0"], ["84149.00", "5.166079"], ["84157.50", "4.984813"], ["84166.00", "4.803547"], ["84183.00", "4.531649"], ["84191.50", "4.259750"], ["84200.00", "5.528611"], ["84208.50", "4.078484"], ["84217.00", "4.712914"], ["84225.50", "4.350383"], ["84234.00", "5.256712"], ["84242.50", "4.441016"], ["84251.00", "4.894180"], ["84259.50", "3.987851"], ["84268.00", "5.347345"], ["84276.50", "4.622282"], ["84293.50", "5.075446"], ["84302.00", "4.169117"], ["84310.50", "5.437978"], ["84527.47", "0"]], "bids": [["84037.54", "0.010000"], ["84022.60", "0.002970"], ["84022.38", "0.247647"], ["84019.02", "0"], ["84018.87", "0.017107"], ["84018.86", "0"], ["84018.71", "0.007133"], ["84018.35", "0"], ["84018.20", "0.028872"], ["84003.00", "0.000032"], ["84001.00", "0.000017"], ["84000.00", "0.003124"], ["83999.00", "0.000017"], ["83998.00", "0.000017"], ["83997.00", "0.000017"], ["83996.00", "0.000017"], ["83995.00", "0.000017"], ["83994.00", "0.000017"], ["83980.80", "5.528611"], ["83972.30", "4.622282"], ["83963.80", "4.350383"], ["83955.30", "5.347345"], ["83946.80", "5.437978"], ["83938.30", "3.987851"], ["83929.80", "4.712914"], ["83912.80", "5.619244"], ["83904.30", "5.166079"], ["83895.80", "4.894180"], ["83887.30", "4.803547"], ["83878.80", "4.531649"], ["83870.30", "5.075446"], ["83861.80", "4.078484"], ["83853.30", "5.256712"], ["83844.80", "3.897218"], ["83836.30", "4.259750"], ["83827.80", "4.984813"], ["83819.30", "4.441016"], ["83658.54", "0"], ["83656.60", "0"], ["83655.00", "0"], ["83654.23", "0"], ["83653.94", "0"], ["83653.67", "0"], ["83653.31", "0"], ["83652.80", "0"], ["83652.48", "0"]], "checksum": -605386105, "ts": "1742555193145"}], "ts": 1742555193150, "record_time": 1742555193.194439, "EXCHANGE": "BITGET"}
{"action": "update", "arg": {"instType": "SPOT", "channel": "books", "instId": "BTCUSDT"}, "data": [{"asks": [["84043.02", "0.159003"], ["84064.78", "0"], ["84091.00", "0.004422"], ["84093.00", "0.011637"], ["84095.00", "0.030626"], ["84097.00", "0.080857"], ["84099.00", "0.212781"], ["84101.00", "0.559949"], ["84103.00", "1.473552"], ["84105.00", "3.877766"], ["84107.00", "10.204648"], ["84149.00", "4.531649"], ["84157.50", "5.166079"], ["84166.00", "3.897218"], ["84174.50", "4.712914"], ["84183.00", "4.259750"], ["84191.50", "5.437978"], ["84200.00", "4.894180"], ["84208.50", "4.169117"], ["84217.00", "4.984813"], ["84234.00", "5.075446"], ["84242.50", "4.078484"], ["84251.00", "5.256712"], ["84259.50", "4.803547"], ["84268.00", "5.528611"], ["84285.00", "3.987851"], ["84293.50", "5.347345"], ["84302.00", "4.441016"], ["84310.50", "5.619244"], ["84527.47", "0.000608"]], "bids": [["84041.48", "0.027856"], ["84041.32", "0"], ["84036.80", "0.005619"], ["84034.80", "0.014788"], ["84032.80", "0.038915"], ["84031.41", "0"], ["84030.80", "0.102408"], ["84028.80", "0.269495"], ["84026.80", "0.709196"], ["84024.80", "1.866305"], ["84022.80", "4.911330"], ["84011.70", "0.120000"], ["83980.80", "4.441016"], ["83972.30", "5.437978"], ["83963.80", "5.075446"], ["83955.30", "5.528611"], ["83946.80", "3.897218"], ["83938.30", "5.166079"], ["83929.80", "4.894180"], ["83921.30", "4.984813"], ["83912.80", "4.531649"], ["83904.30", "4.803547"], ["83895.80", "5.619244"], ["83887.30", "5.256712"], ["83878.80", "4.169117"], ["83870.30", "4.259750"], ["83861.80", "4.712914"], ["83853.30", "3.987851"], ["83844.80", "4.622282"], ["83836.30", "4.350383"], ["83827.80", "5.347345"], ["83819.30", "4.078484"]], "checksum": 665527890, "ts": "1742555193363"}], "ts": 1742555193365, "record_time": 1742555193.401065, "EXCHANGE": "BITGET"}
{"action": "update", "arg": {"instType": "SPOT", "channel": "books", "instId": "BTCUSDT"}, "data": [{"asks": [["84043.01", "2.240863"], ["84043.02", "0.046208"], ["84043.39", "0.086745"], ["84043.41", "0"], ["84077.16", "0.123676"], ["84079.67", "0"], ["84105.00", "3.877526"], ["84107.00", "10.204016"], ["84109.80", "0.526830"], ["84110.30", "0.320670"], ["84110.60", "0.379680"], ["84149.00", "4.259750"], ["84157.50", "4.441016"], ["84166.00", "5.166079"], ["84174.50", "5.347345"], ["84183.00", "3.897218"], ["84191.50", "3.987851"], ["84200.00", "4.350383"], ["84208.50", "4.803547"], ["84217.00", "4.712914"], ["84225.50", "4.984813"], ["84242.50", "4.622282"], ["84251.00", "4.531649"], ["84259.50", "4.894180"], ["84268.00", "4.078484"], ["84276.50", "4.169117"], ["84285.00", "5.437978"], ["84293.50", "5.528611"], ["84302.00", "5.256712"], ["84527.47", "0"]], "bids": [["84021.00", "0.152160"], ["84019.89", "0.258560"], ["84019.30", "0.076440"], ["84004.00", "0.000017"], ["83980.80", "5.619244"], ["83972.30", "5.166079"], ["83963.80", "3.897218"], ["83955.30", "4.350383"], ["83946.80", "4.169117"], ["83938.30", "4.894180"], ["83929.80", "5.347345"], ["83912.80", "4.803547"], ["83904.30", "3.987851"], ["83895.80", "4.531649"], ["83887.30", "5.528611"], ["83878.80", "5.256712"], ["83870.30", "4.441016"], ["83861.80", "4.622282"], ["83853.30", "5.437978"], ["83844.80", "5.075446"], ["83836.30", "4.078484"], ["83827.80", "4.259750"], ["83819.30", "4.712914"]], "checksum": -1511452349, "ts": "1742555193566"}], "ts": 1742555193571, "record_time": 1742555193.596767, "EXCHANGE": "BITGET"}
{"action": "update", "arg": {"instType": "SPOT", "channel": "books", "instId": "BTCUSDT"}, "data": [{"asks": [["84072.16", "0.119850"], ["84072.22", "0"], ["84093.00", "0.011753"], ["84095.00", "0.030929"], ["84097.00", "0.081394"], ["84099.00", "0.214195"], ["84101.00", "0.563670"], ["84103.00", "1.483341"], ["84105.00", "3.903529"], ["84107.00", "10.272445"], ["84149.00", "4.894180"], ["84157.50", "5.347345"], ["84174.50", "5.256712"], ["84183.00", "4.078484"], ["84191.50", "4.531649"], ["84200.00", "5.437978"], ["84208.50", "4.441016"], ["84225.50", "5.619244"], ["84234.00", "4.984813"], ["84242.50", "4.803547"], ["84251.00", "3.987851"], ["84259.50", "4.622282"], ["84268.00", "4.169117"], ["84276.50", "5.075446"], ["84285.00", "4.350383"], ["84293.50", "4.259750"], ["84302.00", "5.528611"], ["84310.50", "3.897218"]], "bids": [["84038.80", "0.002207"], ["84036.80", "0.005809"], ["84034.80", "0.015287"], ["84032.80", "0.040229"], ["84030.80", "0.105866"], ["84028.80", "0.278593"], ["84026.80", "0.733140"], ["84024.80", "1.929317"], ["84022.80", "5.077149"], ["84014.06", "0"], ["84014.00", "0.268474"], ["83980.80", "4.441016"], ["83972.30", "4.169117"], ["83963.80", "5.256712"], ["83955.30", "4.894180"], ["83946.80", "5.437978"], ["83938.30", "5.528611"], ["83929.80", "5.075446"], ["83921.30", "4.712914"], ["83912.80", "4.984813"], ["83904.30", "4.531649"], ["83895.80", "4.622282"], ["83887.30", "3.897218"], ["83878.80", "3.987851"], ["83870.30", "5.166079"], ["83861.80", "4.078484"], ["83853.30", "5.347345"], ["83844.80", "4.259750"], ["83836.30", "4.803547"], ["83827.80", "5.619244"], ["83819.30", "4.350383"], ["83658.54", "0.000036"]], "checksum": -1342424609, "ts": "1742555193769"}], "ts": 1742555193773, "record_time": 1742555193.819252, "EXCHANGE": "BITGET"}
{"action": "update", "arg": {"instType": "SPOT", "channel": "books", "instId": "BTCUSDT"}, "data": [{"asks": [["84043.39", "0"], ["84077.17", "0"], ["84091.00", "0.004232"], ["84093.00", "0.011136"], ["84095.00", "0.029306"], ["84097.00", "0.077121"], ["84099.00", "0.202951"], ["84101.00", "0.534080"], ["84103.00", "1.405476"], ["84105.00", "3.698621"], ["84107.00", "9.733213"], ["84149.00", "3.987851"], ["84157.50", "5.528611"], ["84166.00", "4.531649"], ["84174.50", "4.894180"], ["84191.50", "3.897218"], ["84208.50", "4.259750"], ["84217.00", "4.350383"], ["84225.50", "4.169117"], ["84234.00", "4.712914"], ["84242.50", "5.347345"], ["84251.00", "5.075446"], ["84259.50", "5.256712"], ["84268.00", "4.803547"], ["84276.50", "4.622282"], ["84285.00", "5.166079"], ["84293.50", "5.619244"], ["84302.00", "4.984813"], ["84310.50", "4.441016"], ["84527.47", "0.000608"], ["84528.57", "0.000008"]], "bids": [["84042.26", "0.027856"], ["84041.48", "0"], ["84021.00", "0.078060"], ["84019.30", "0.076650"], ["84017.50", "0.078720"], ["84011.70", "0"], ["84002.00", "0.000017"], ["83993.00", "0.000017"], ["83980.80", "5.075446"], ["83972.30", "4.078484"], ["83963.80", "3.897218"], ["83955.30", "4.531649"], ["83946.80", "4.350383"], ["83938.30", "5.619244"], ["83929.80", "5.166079"], ["83921.30", "4.803547"], ["83912.80", "5.437978"], ["83904.30", "5.256712"], ["83895.80", "4.169117"], ["83887.30", "5.528611"], ["83878.80", "4.259750"], ["83870.30", "4.894180"], ["83861.80", "3.987851"], ["83853.30", "4.622282"], ["83844.80", "4.441016"], ["83836.30", "4.712914"], ["83827.80", "5.347345"], ["83819.30", "4.984813"], ["83658.54", "0"]], "checksum": -1610988992, "ts": "1742555193972"}], "ts": 1742555193975, "record_time": 1742555193.998442, "EXCHANGE": "BITGET"}
{"action": "update", "arg": {"instType": "SPOT", "channel": "books", "instId": "BTCUSDT"}, "data": [{"asks": [["84043.02", "0.020701"], ["84043.38", "0.086745"], ["84077.16", "0"], ["84091.00", "0.004079"], ["84093.00", "0.010950"], ["84095.00", "0.028816"], ["84097.00", "0.075831"], ["84099.00", "0.199554"], ["84101.00", "0.525142"], ["84103.00", "1.381953"], ["84105.00", "3.636719"], ["84107.00", "9.570314"], ["84145.49", "0.062760"], ["84149.00", "5.347345"], ["84157.50", "4.259750"], ["84166.00", "4.169117"], ["84174.50", "5.075446"], ["84183.00", "4.712914"], ["84191.50", "5.528611"], ["84200.00", "3.897218"], ["84208.50", "5.166079"], ["84217.00", "4.803547"], ["84225.50", "5.437978"], ["84234.00", "5.619244"], ["84242.50", "4.350383"], ["84251.00", "3.987851"], ["84259.50", "4.894180"], ["84268.00", "4.622282"], ["84276.50", "4.441016"], ["84285.00", "4.078484"], ["84293.50", "4.531649"], ["84310.50", "5.256712"], ["84528.57", "0"]], "bids": [["84036.80", "0.005689"], ["84034.80", "0.014971"], ["84032.80", "0.039397"], ["84031.41", "0.102744"], ["84030.80", "0.103552"], ["84028.80", "0.272506"], ["84026.80", "0.717119"], ["84024.80", "1.887156"], ["84022.80", "4.966200"], ["84020.00", "0.001263"], ["84011.70", "0.120000"], ["83980.80", "4.712914"], ["83972.30", "5.075446"], ["83955.30", "3.987851"], ["83946.80", "4.803547"], ["83938.30", "4.441016"], ["83929.80", "4.622282"], ["83921.30", "4.894180"], ["83912.80", "4.350383"], ["83904.30", "4.078484"], ["83895.80", "5.347345"], ["83887.30", "4.531649"], ["83878.80", "5.528611"], ["83870.30", "4.259750"], ["83861.80", "4.984813"], ["83853.30", "5.437978"], ["83844.80", "5.166079"], ["83836.30", "5.619244"], ["83827.80", "4.169117"], ["83819.30", "5.256712"], ["83659.49", "0"], ["83659.44", "0"]], "checksum": 1615713833, "ts": "1742555194173"}], "ts": 1742555194177, "record_time": 1742555194.247912, "EXCHANGE": "BITGET"}
{"action": "update", "arg": {"instType": "SPOT", "channel": "books", "instId": "BTCUSDT"}, "data": [{"asks": [["84043.02", "0.046208"], ["84077.19", "0.175164"], ["84089.00", "0.001497"], ["84091.00", "0.003941"], ["84093.00", "0.010371"], ["84095.00", "0.027292"], ["84097.00", "0.071821"], ["84099.00", "0.189001"], ["84101.00", "0.497371"], ["84103.00", "1.308871"], ["84105.00", "3.444399"], ["84107.00", "9.064208"], ["84108.70", "0.053580"], ["84109.40", "0.071670"], ["84116.90", "0"], ["84149.00", "4.622282"], ["84157.50", "5.437978"], ["84166.00", "4.441016"], ["84174.50", "3.897218"], ["84183.00", "4.078484"], ["84191.50", "4.894180"], ["84200.00", "4.984813"], ["84217.00", "4.350383"], ["84225.50", "5.256712"], ["84234.00", "4.169117"], ["84242.50", "3.987851"], ["84251.00", "5.528611"], ["84259.50", "4.259750"], ["84268.00", "4.531649"], ["84276.50", "4.712914"], ["84285.00", "5.619244"], ["84293.50", "4.803547"], ["84302.00", "5.347345"], ["84310.50", "5.075446"], ["84527.47", "0"]], "bids": [["84030.80", "0.103417"], ["84028.80", "0.272148"], ["84026.80", "0.716179"], ["84024.80", "1.884682"], ["84022.80", "4.959950"], ["84021.90", "0.456660"], ["84021.00", "0.000032"], ["84019.30", "0.076440"], ["84002.00", "0.000032"], ["84001.00", "0.000032"], ["84000.00", "0.003139"], ["83999.00", "0.000032"], ["83998.00", "0.000032"], ["83997.00", "0.000032"], ["83996.00", "0.000032"], ["83995.00", "0.000032"], ["83994.00", "0.000032"], ["83980.80", "3.987851"], ["83972.30", "4.350383"], ["83963.80", "4.622282"], ["83955.30", "4.169117"], ["83946.80", "5.528611"], ["83929.80", "4.803547"], ["83921.30", "4.078484"], ["83912.80", "5.166079"], ["83904.30", "5.437978"], ["83895.80", "4.531649"], ["83887.30", "5.347345"], ["83878.80", "4.712914"], ["83870.30", "4.984813"], ["83861.80", "5.075446"], ["83853.30", "4.259750"], ["83844.80", "5.256712"], ["83836.30", "3.897218"], ["83827.80", "5.619244"], ["83819.30", "4.894180"]], "checksum": -1411482703, "ts": "1742555194378"}], "ts": 1742555194381, "record_time": 1742555194.43517, "EXCHANGE": "BITGET"}
{"action": "update", "arg": {"instType": "SPOT", "channel": "books", "instId": "BTCUSDT"}, "data": [{"asks": [["84043.37", "0.086745"], ["84043.38", "0"], ["84077.18", "0.123373"], ["84086.63", "0.010000"], ["84107.00", "9.064078"], ["84108.70", "0"], ["84109.40", "0.071880"], ["84115.10", "0.006870"], ["84116.90", "0.228000"], ["84117.00", "3.135090"], ["84145.49", "0"], ["84149.00", "3.987851"], ["84157.50", "5.075446"], ["84166.00", "4.712914"], ["84174.50", "4.441016"], ["84183.00", "4.259750"], ["84191.50", "5.437978"], ["84200.00", "5.347345"], ["84208.50", "5.528611"], ["84217.00", "5.256712"], ["84225.50", "4.803547"], ["84242.50", "4.622282"], ["84251.00", "5.166079"], ["84259.50", "4.894180"], ["84268.00", "4.350383"], ["84276.50", "5.619244"], ["84285.00", "4.531649"], ["84293.50", "3.897218"], ["84302.00", "4.984813"], ["84310.50", "4.078484"], ["84525.00", "0"], ["84525.82", "0"]], "bids": [["84036.80", "0.005555"], ["84034.80", "0.014617"], ["84032.80", "0.038465"], ["84030.80", "0.101224"], ["84028.80", "0.266379"], ["84026.80", "0.700999"], ["84024.80", "1.844734"], ["84022.80", "4.854563"], ["83980.80", "5.528611"], ["83972.30", "3.987851"], ["83963.80", "4.803547"], ["83955.30", "4.259750"], ["83946.80", "4.350383"], ["83938.30", "4.712914"], ["83929.80", "5.437978"], ["83921.30", "5.166079"], ["83912.80", "4.169117"], ["83904.30", "4.622282"], ["83895.80", "4.078484"], ["83887.30", "5.619244"], ["83878.80", "4.894180"], ["83870.30", "4.441016"], ["83853.30", "4.531649"], ["83844.80", "4.984813"], ["83827.80", "5.256712"], ["83819.30", "5.347345"]], "checksum": 1157191711, "ts": "1742555194578"}], "ts": 1742555194582, "record_time": 1742555194.604378, "EXCHANGE": "BITGET"}
{"action": "update", "arg": {"instType": "SPOT", "channel": "books", "instId": "BTCUSDT"}, "data": [{"asks": [["84089.00", "0.001545"], ["84091.00", "0.004065"], ["84093.00", "0.010699"], ["84095.00", "0.028154"], ["84097.00", "0.074091"], ["84099.00", "0.194976"], ["84101.00", "0.513094"], ["84103.00", "1.350247"], ["84105.00", "3.553281"], ["84107.00", "9.350741"], ["84108.10", "0.069480"], ["84149.00", "4.622282"], ["84157.50", "3.897218"], ["84166.00", "5.528611"], ["84174.50", "4.169117"], ["84183.00", "5.166079"], ["84191.50", "4.803547"], ["84200.00", "5.619244"], ["84208.50", "4.078484"], ["84217.00", "4.712914"], ["84225.50", "5.256712"], ["84234.00", "5.075446"], ["84242.50", "5.437978"], ["84251.00", "4.259750"], ["84259.50", "5.347345"], ["84268.00", "4.894180"], ["84276.50", "4.984813"], ["84285.00", "3.987851"], ["84293.50", "4.350383"], ["84302.00", "4.531649"], ["84310.50", "4.441016"]], "bids": [["84042.26", "0"], ["84031.41", "0"], ["84026.80", "0.700754"], ["84024.80", "1.844091"], ["84022.80", "4.852870"], ["84018.50", "0.015000"], ["83992.00", "0.000017"], ["83980.80", "4.259750"], ["83972.30", "5.256712"], ["83963.80", "4.169117"], ["83955.30", "5.619244"], ["83946.80", "5.166079"], ["83938.30", "5.347345"], ["83929.80", "5.075446"], ["83921.30", "4.622282"], ["83912.80", "4.984813"], ["83904.30", "4.350383"], ["83895.80", "5.437978"], ["83887.30", "4.441016"], ["83878.80", "3.897218"], ["83870.30", "4.803547"], ["83861.80", "4.894180"], ["83853.30", "5.528611"], ["83844.80", "4.078484"], ["83836.30", "4.531649"], ["83827.80", "3.987851"], ["83819.30", "4.712914"]], "checksum": 1724984384, "ts": "1742555194787"}], "ts": 1742555194791, "record_time": 1742555194.813225, "EXCHANGE": "BITGET"}
{"action": "update", "arg": {"instType": "SPOT", "channel": "books", "instId": "BTCUSDT"}, "data": [{"asks": [["84043.37", "0"], ["84093.00", "0.010703"], ["84095.00", "0.028166"], ["84097.00", "0.074122"], ["84099.00", "0.195056"], ["84101.00", "0.513306"], ["84103.00", "1.350806"], ["84105.00", "3.554751"], ["84107.00", "9.354610"], ["84108.10", "0.068430"], ["84109.40", "0"], ["84109.80", "0.527040"], ["84115.40", "0.009000"], ["84149.00", "4.441016"], ["84157.50", "4.259750"], ["84159.88", "0.125644"], ["84171.24", "0"], ["84174.50", "5.347345"], ["84183.00", "4.531649"], ["84191.50", "4.984813"], ["84200.00", "4.622282"], ["84208.50", "5.075446"], ["84217.00", "5.619244"], ["84225.50", "3.897218"], ["84234.00", "4.894180"], ["84242.50", "3.987851"], ["84251.00", "5.256712"], ["84259.50", "4.169117"], ["84268.00", "4.350383"], ["84276.50", "5.437978"], ["84285.00", "4.803547"], ["84293.50", "4.078484"], ["84302.00", "4.712914"], ["84310.50", "5.166079"], ["84525.00", "0.003689"], ["84525.82", "0.000099"]], "bids": [["84036.80", "0.005943"], ["84034.80", "0.015639"], ["84032.80", "0.041156"], ["84031.41", "0.101351"], ["84030.80", "0.108304"], ["84028.80", "0.285010"], ["84026.80", "0.750026"], ["84024.80", "1.973753"], ["84022.80", "5.194087"], ["84021.00", "0.074520"], ["84019.40", "0.045540"], ["84011.70", "0"], ["83980.80", "4.350383"], ["83972.30", "4.259750"], ["83963.80", "3.897218"], ["83955.30", "5.347345"], ["83946.80", "4.441016"], ["83938.30", "5.437978"], ["83929.80", "4.894180"], ["83921.30", "4.078484"], ["83912.80", "4.622282"], ["83904.30", "5.619244"], ["83895.80", "5.528611"], ["83887.30", "4.169117"], ["83878.80", "4.712914"], ["83870.30", "5.075446"], ["83861.80", "5.166079"], ["83853.30", "4.803547"], ["83844.80", "3.987851"], ["83836.30", "4.984813"], ["83827.80", "5.256712"], ["83819.30", "4.531649"]], "checksum": 1526217169, "ts": "1742555194996"}], "ts": 1742555194998, "record_time": 1742555195.021551, "EXCHANGE": "BITGET"}
{"action": "update", "arg": {"instType": "SPOT", "channel": "books", "instId": "BTCUSDT"}, "data": [{"asks": [["84043.02", "0.020701"], ["84043.35", "0.086745"], ["84089.00", "0.001403"], ["84091.00", "0.003692"], ["84093.00", "0.009715"], ["84095.00", "0.025566"], ["84097.00", "0.067280"], ["84099.00", "0.177053"], ["84101.00", "0.465929"], ["84102.99", "0.092920"], ["84103.00", "1.226129"], ["84105.00", "3.226655"], ["84107.00", "8.491198"], ["84108.70", "0.053640"], ["84109.80", "0.526830"], ["84115.40", "1.359000"], ["84149.00", "3.897218"], ["84157.50", "4.350383"], ["84166.00", "4.622282"], ["84174.50", "5.075446"], ["84183.00", "4.441016"], ["84200.00", "5.619244"], ["84208.50", "5.528611"], ["84217.00", "5.166079"], ["84225.50", "4.894180"], ["84234.00", "5.347345"], ["84242.50", "4.712914"], ["84259.50", "4.531649"], ["84268.00", "5.437978"], ["84276.50", "4.078484"], ["84285.00", "4.259750"], ["84293.50", "4.803547"], ["84302.00", "4.169117"], ["84310.50", "3.987851"], ["84525.00", "0"], ["84525.82", "0"]], "bids": [["84042.44", "0.027856"], ["84037.54", "0"], ["83980.80", "5.619244"], ["83972.30", "4.803547"], ["83963.80", "4.078484"], ["83955.30", "5.256712"], ["83946.80", "4.894180"], ["83938.30", "4.350383"], ["83929.80", "4.622282"], ["83921.30", "3.987851"], ["83912.80", "5.347345"], ["83904.30", "4.259750"], ["83895.80", "4.984813"], ["83887.30", "5.075446"], ["83878.80", "5.437978"], ["83870.30", "4.169117"], ["83861.80", "3.897218"], ["83853.30", "5.528611"], ["83844.80", "4.712914"], ["83836.30", "4.531649"], ["83827.80", "4.441016"], ["83819.30", "5.166079"]], "checksum": 539550839, "ts": "1742555195205"}], "ts": 1742555195210, "record_time": 1742555195.293263, "EXCHANGE": "BITGET"}
{"action": "update", "arg": {"instType": "SPOT", "channel": "books", "instId": "BTCUSDT"}, "data": [{"asks": [["84043.01", "2.238504"], ["84043.02", "0.046208"], ["84097.74", "0"], ["84097.88", "0.001598"], ["84099.39", "0"], ["84099.71", "0.001597"], ["84108.70", "0"], ["84109.80", "0.527040"], ["84149.00", "5.075446"], ["84157.50", "5.437978"], ["84166.00", "4.894180"], ["84174.50", "4.259750"], ["84183.00", "5.528611"], ["84191.50", "5.619244"], ["84200.00", "4.441016"], ["84208.50", "4.803547"], ["84217.00", "5.347345"], ["84225.50", "3.987851"], ["84234.00", "4.984813"], ["84242.50", "4.169117"], ["84251.00", "4.350383"], ["84259.50", "4.622282"], ["84268.00", "4.078484"], ["84276.50", "3.897218"], ["84285.00", "4.531649"], ["84293.50", "5.166079"], ["84302.00", "5.256712"], ["84310.50", "4.712914"], ["84525.00", "0.003689"]], "bids": [["84004.00", "0.000032"], ["83993.00", "0.000015"], ["83987.61", "0.001176"], ["83987.48", "0"], ["83985.58", "0.001173"], ["83985.26", "0"], ["83980.80", "4.169117"], ["83972.30", "5.619244"], ["83955.30", "4.622282"], ["83946.80", "5.528611"], ["83938.30", "4.531649"], ["83929.80", "4.803547"], ["83912.80", "5.075446"], ["83904.30", "3.897218"], ["83895.80", "5.437978"], ["83887.30", "4.350383"], ["83878.80", "4.712914"], ["83870.30", "5.256712"], ["83861.80", "4.984813"], ["83853.30", "4.441016"], ["83844.80", "5.166079"], ["83836.30", "4.259750"], ["83827.80", "5.347345"], ["83819.30", "4.894180"]], "checksum": -1991697650, "ts": "1742555195415"}], "ts": 1742555195421, "record_time": 1742555195.482467, "EXCHANGE": "BITGET"}
{"action": "update", "arg": {"instType": "SPOT", "channel": "books", "instId": "BTCUSDT"}, "data": [{"asks": [["84043.35", "0"], ["84063.55", "0.054377"], ["84089.00", "0.001564"], ["84091.00", "0.004114"], ["84093.00", "0.010828"], ["84095.00", "0.028493"], ["84097.00", "0.074982"], ["84099.00", "0.197321"], ["84101.00", "0.519266"], ["84103.00", "1.366491"], ["84105.00", "3.596029"], ["84107.00", "9.463234"], ["84109.70", "0.478770"], ["84109.80", "0.526830"], ["84117.00", "0"], ["84126.21", "0"], ["84136.10", "0"], ["84149.00", "3.897218"], ["84157.50", "4.894180"], ["84166.00", "4.531649"], ["84174.50", "4.622282"], ["84183.00", "5.619244"], ["84191.50", "4.712914"], ["84200.00", "5.256712"], ["84208.50", "5.166079"], ["84217.00", "3.987851"], ["84225.50", "5.437978"], ["84234.00", "5.347345"], ["84242.50", "4.350383"], ["84251.00", "4.169117"], ["84259.50", "4.984813"], ["84276.50", "4.803547"], ["84285.00", "5.528611"], ["84293.50", "4.441016"], ["84302.00", "4.259750"], ["84310.50", "5.075446"], ["84525.82", "0.000099"], ["84527.47", "0.000608"]], "bids": [["84026.80", "0.749868"], ["84024.80", "1.973336"], ["84022.80", "5.192990"], ["83980.80", "4.984813"], ["83972.30", "4.894180"], ["83963.80", "5.619244"], ["83955.30", "5.347345"], ["83946.80", "3.987851"], ["83938.30", "4.259750"], ["83921.30", "4.441016"], ["83912.80", "4.350383"], ["83904.30", "5.075446"], ["83887.30", "4.622282"], ["83878.80", "5.256712"], ["83870.30", "3.897218"], ["83861.80", "5.166079"], ["83853.30", "4.531649"], ["83844.80", "4.169117"], ["83836.30", "4.078484"], ["83827.80", "4.712914"], ["83819.30", "5.528611"]], "checksum": -675939830, "ts": "1742555195619"}], "ts": 1742555195622, "record_time": 1742555195.649287, "EXCHANGE": "BITGET"}
{"action": "update", "arg": {"instType": "SPOT", "channel": "books", "instId": "BTCUSDT"}, "data": [{"asks": [["84043.02", "0.020701"], ["84043.34", "0.086745"], ["84088.99", "0.002303"], ["84091.00", "0.004320"], ["84093.00", "0.011369"], ["84095.00", "0.029917"], ["84097.00", "0.078729"], ["84099.00", "0.207184"], ["84101.00", "0.545220"], ["84103.00", "1.434789"], ["84105.00", "3.775931"], ["84107.00", "9.936659"], ["84149.00", "4.350383"], ["84157.50", "4.259750"], ["84174.50", "3.987851"], ["84191.50", "4.078484"], ["84200.00", "3.897218"], ["84208.50", "4.803547"], ["84217.00", "4.984813"], ["84225.50", "4.441016"], ["84242.50", "4.169117"], ["84251.00", "5.166079"], ["84259.50", "5.256712"], ["84268.00", "5.437978"], ["84276.50", "5.528611"], ["84285.00", "5.075446"], ["84293.50", "4.894180"], ["84302.00", "4.622282"], ["84310.50", "4.712914"], ["84525.82", "0"], ["84527.47", "0"]], "bids": [["84036.80", "0.005586"], ["84034.80", "0.014699"], ["84032.80", "0.038442"], ["84030.80", "0.101164"], ["84028.80", "0.266219"], ["84026.80", "0.700577"], ["84024.80", "1.843624"], ["84022.80", "4.851643"], ["84021.00", "0.000032"], ["84020.90", "0.074130"], ["83980.80", "4.622282"], ["83972.30", "5.166079"], ["83963.80", "4.803547"], ["83946.80", "5.437978"], ["83938.30", "4.531649"], ["83929.80", "4.894180"], ["83921.30", "3.897218"], ["83912.80", "5.256712"], ["83904.30", "5.619244"], ["83895.80", "4.169117"], ["83887.30", "4.984813"], ["83878.80", "5.075446"], ["83870.30", "3.987851"], ["83861.80", "4.441016"], ["83853.30", "4.350383"], ["83844.80", "4.712914"], ["83836.30", "4.259750"], ["83827.80", "4.078484"], ["83659.61", "0"]], "checksum": -248185879, "ts": "1742555195849"}], "ts": 1742555195853, "record_time": 1742555195.876448, "EXCHANGE": "BITGET"}
{"action": "update", "arg": {"instType": "SPOT", "channel": "books", "instId": "BTCUSDT"}, "data": [{"asks": [["84043.02", "0.046208"], ["84109.40", "0.071580"], ["84109.70", "0.478560"], ["84116.90", "0"], ["84149.00", "4.803547"], ["84157.50", "4.169117"], ["84166.00", "4.622282"], ["84174.50", "4.259750"], ["84183.00", "5.166079"], ["84191.50", "5.619244"], ["84200.00", "4.350383"], ["84208.50", "4.894180"], ["84217.00", "5.256712"], ["84225.50", "5.075446"], ["84234.00", "5.437978"], ["84242.50", "3.897218"], ["84251.00", "4.712914"], ["84259.50", "5.347345"], ["84268.00", "4.441016"], ["84276.50", "4.531649"], ["84285.00", "3.987851"], ["84293.50", "4.984813"], ["84302.00", "5.528611"], ["84310.50", "4.078484"]], "bids": [["83991.00", "0.000017"], ["83980.80", "4.531649"], ["83972.30", "5.075446"], ["83963.80", "4.894180"], ["83955.30", "5.619244"], ["83946.80", "3.897218"], ["83938.30", "4.169117"], ["83929.80", "4.984813"], ["83921.30", "3.987851"], ["83912.80", "4.078484"], ["83904.30", "5.256712"], ["83895.80", "4.803547"], ["83887.30", "5.437978"], ["83878.80", "4.350383"], ["83870.30", "4.622282"], ["83861.80", "5.166079"], ["83853.30", "5.528611"], ["83844.80", "4.441016"], ["83827.80", "4.712914"], ["83819.30", "5.347345"], ["83660.00", "0"]], "checksum": 984045169, "ts": "1742555196052"}], "ts": 1742555196054, "record_time": 1742555196.11101, "EXCHANGE": "BITGET"}
{"action": "update", "arg": {"instType": "SPOT", "channel": "books", "instId": "BTCUSDT"}, "data": [{"asks": [["84043.33", "0.086745"], ["84043.34", "0"], ["84095.00", "0.030071"], ["84097.00", "0.079135"], ["84099.00", "0.208249"], ["84101.00", "0.548024"], ["84103.00", "1.442170"], ["84105.00", "3.795184"], ["84107.00", "9.987326"], ["84149.00", "4.078484"], ["84157.50", "5.256712"], ["84166.00", "4.894180"], ["84174.50", "3.897218"], ["84183.00", "4.622282"], ["84191.50", "4.169117"], ["84200.00", "5.437978"], ["84208.50", "4.712914"], ["84217.00", "5.075446"], ["84225.50", "5.619244"], ["84234.00", "4.984813"], ["84242.50", "4.259750"], ["84251.00", "4.350383"], ["84259.50", "4.441016"], ["84268.00", "5.347345"], ["84276.50", "4.803547"], ["84285.00", "4.531649"], ["84293.50", "5.528611"], ["84302.00", "5.166079"], ["84310.50", "3.987851"]], "bids": [["84042.44", "0"], ["84022.80", "4.851382"], ["84018.50", "0.030000"], ["83980.80", "5.528611"], ["83972.30", "3.987851"], ["83963.80", "4.259750"], ["83955.30", "5.166079"], ["83946.80", "4.622282"], ["83938.30", "4.350383"], ["83929.80", "5.075446"], ["83921.30", "4.169117"], ["83912.80", "4.984813"], ["83895.80", "5.347345"], ["83887.30", "4.894180"], ["83878.80", "4.441016"], ["83870.30", "5.619244"], ["83861.80", "4.712914"], ["83853.30", "4.803547"], ["83844.80", "4.078484"], ["83836.30", "4.531649"], ["83827.80", "3.897218"], ["83819.30", "5.437978"], ["83660.00", "0.001273"]], "checksum": 1082631607, "ts": "1742555196273"}], "ts": 1742555196276, "record_time": 1742555196.366589, "EXCHANGE": "BITGET"}
{"action": "update", "arg": {"instType": "SPOT", "channel": "books", "instId": "BTCUSDT"}, "data": [{"asks": [["84149.00", "3.897218"], ["84157.50", "4.259750"], ["84174.50", "5.619244"], ["84183.00", "5.075446"], ["84208.50", "4.531649"], ["84217.00", "4.078484"], ["84225.50", "4.350383"], ["84234.00", "5.256712"], ["84242.50", "5.166079"], ["84251.00", "5.528611"], ["84259.50", "4.622282"], ["84268.00", "4.984813"], ["84276.50", "4.712914"], ["84285.00", "3.987851"], ["84293.50", "5.347345"], ["84302.00", "4.803547"], ["84310.50", "4.441016"]], "bids": [["84043.00", "0.265448"], ["84041.77", "0.027859"], ["84034.80", "0.014940"], ["84032.80", "0.039317"], ["84030.80", "0.103466"], ["84028.80", "0.272278"], ["84026.80", "0.716520"], ["84024.80", "1.885580"], ["84022.80", "4.962052"], ["83992.00", "0.000032"], ["83980.80", "3.987851"], ["83972.30", "5.528611"], ["83963.80", "3.897218"], ["83955.30", "4.169117"], ["83946.80", "4.984813"], ["83938.30", "5.619244"], ["83929.80", "4.441016"], ["83921.30", "5.075446"], ["83912.80", "4.078484"], ["83904.30", "4.894180"], ["83895.80", "4.803547"], ["83887.30", "4.712914"], ["83878.80", "5.347345"], ["83870.30", "4.531649"], ["83861.80", "4.622282"], ["83853.30", "4.259750"], ["83844.80", "5.437978"], ["83836.30", "5.256712"], ["83827.80", "5.166079"], ["83819.30", "4.350383"], ["83660.00", "0"]], "checksum": 786926266, "ts": "1742555196481"}], "ts": 1742555196487, "record_time": 1742555196.53063, "EXCHANGE": "BITGET"}
{"action": "update", "arg": {"instType": "SPOT", "channel": "books", "instId": "BTCUSDT"}, "data": [{"asks": [["84043.01", "2.238738"], ["84043.32", "0.086817"], ["84043.33", "0"], ["84049.00", "0.110662"], ["84063.32", "0.035952"], ["84063.47", "0"], ["84064.92", "0.035961"], ["84064.93", "0"], ["84065.36", "0.006356"], ["84065.37", "0"], ["84065.52", "0.006356"], ["84065.53", "0"], ["84065.85", "0.006356"], ["84065.86", "0"], ["84067.03", "0.010984"], ["84067.23", "0"], ["84067.97", "0.006356"], ["84068.17", "0"], ["84068.36", "0.006356"], ["84068.37", "0"], ["84068.46", "0.006356"], ["84068.60", "0"], ["84068.72", "0.119883"], ["84068.73", "0"], ["84068.79", "0.016429"], ["84068.91", "0.006356"], ["84068.93", "0"], ["84068.94", "0"], ["84070.33", "0"], ["84070.38", "0.010985"], ["84071.29", "0.009990"], ["84071.50", "0"], ["84073.67", "0.015895"], ["84073.82", "0"], ["84077.56", "0.015892"], ["84077.68", "0"], ["84078.46", "0.010988"], ["84078.60", "0"], ["84084.14", "0.385668"], ["84086.63", "0"], ["84087.00", "0.001129"], ["84089.00", "0.001841"], ["84091.00", "0.004845"], ["84093.00", "0.012750"], ["84095.00", "0.033554"], ["84097.00", "0.088300"], ["84099.00", "0.232368"], ["84101.00", "0.611495"], ["84103.00", "1.609197"], ["84105.00", "4.234728"], ["84107.00", "11.144023"], ["84107.80", "0.001031"], ["84109.70", "0"], ["84110.20", "0.535260"], ["84110.60", "0.022710"], ["84114.60", "0.269760"], ["84115.10", "0.021870"], ["84149.00", "4.078484"], ["84166.00", "5.347345"], ["84174.50", "5.166079"], ["84183.00", "4.169117"], ["84191.50", "3.897218"], ["84200.00", "4.803547"], ["84208.50", "5.075446"], ["84217.00", "4.531649"], ["84225.50", "4.984813"], ["84234.00", "3.987851"], ["84242.50", "5.528611"], ["84251.00", "4.350383"], ["84259.50", "5.437978"], ["84268.00", "4.712914"], ["84276.50", "4.622282"], ["84285.00", "4.894180"], ["84293.50", "5.619244"], ["84302.00", "4.441016"], ["84310.50", "5.256712"]], "bids": [["84043.00", "0.260522"], ["84041.77", "0"], ["84039.21", "0.027859"], ["84038.80", "0.001566"], ["84036.80", "0.004380"], ["84034.80", "0.011528"], ["84033.93", "0"], ["84032.80", "0.030337"], ["84031.41", "0"], ["84030.80", "0.079832"], ["84028.80", "0.210085"], ["84026.80", "0.552856"], ["84025.29", "0.028180"], ["84024.80", "1.454884"], ["84023.13", "0"], ["84022.98", "0.089506"], ["84022.80", "3.828643"], ["84022.50", "0.019920"], ["84021.90", "0.307260"], ["84020.90", "0"], ["84020.83", "0"], ["84020.82", "0.017821"], ["84020.73", "0"], ["84020.62", "0.004018"], ["84020.31", "0"], ["84020.30", "0.005948"], ["84019.50", "0"], ["84019.40", "0.045750"], ["84019.29", "0.055669"], ["84018.70", "0.991920"], ["84018.59", "0"], ["84018.50", "0.015000"], ["84018.38", "0.007341"], ["84018.01", "0"], ["84017.86", "0.007945"], ["84017.78", "0"], ["84017.77", "0.008996"], ["84017.67", "0"], ["84017.53", "0.025190"], ["84017.50", "0.009000"], ["84017.46", "0"], ["84017.45", "0.224937"], ["84016.10", "2.356620"], ["84015.76", "0.064634"], ["84015.70", "0"], ["84015.19", "0"], ["84014.98", "0.018521"], ["84013.01", "0"], ["84013.00", "0.222755"], ["84012.80", "0"], ["84012.65", "0.076131"], ["84011.70", "0.120000"], ["84011.50", "0.120000"], ["84008.76", "0"], ["84008.65", "0.073233"], ["84008.01", "0"], ["84007.86", "0.056381"], ["84006.35", "0"], ["84006.20", "0.000877"], ["83992.00", "0.000015"], ["83987.85", "0"], ["83987.70", "0.003598"], ["83980.80", "5.166079"], ["83972.30", "4.169117"], ["83963.80", "4.531649"], ["83955.30", "4.894180"], ["83946.80", "5.347345"], ["83938.30", "4.622282"], ["83929.80", "3.897218"], ["83912.80", "5.619244"], ["83904.30", "4.441016"], ["83895.80", "4.078484"], ["83887.30", "3.987851"], ["83878.80", "5.528611"], ["83870.30", "4.350383"], ["83861.80", "4.984813"], ["83853.30", "4.712914"], ["83844.80", "4.259750"], ["83827.80", "4.803547"], ["83819.30", "5.437978"], ["83660.00", "0.001273"], ["83659.61", "0.000454"]], "checksum": 1802729749, "ts": "1742555196682"}], "ts": 1742555196686, "record_time": 1742555196.713255, "EXCHANGE": "BITGET"}
{"action": "update", "arg": {"instType": "SPOT", "channel": "books", "instId": "BTCUSDT"}, "data": [{"asks": [["84077.19", "0"], ["84087.00", "0.001015"], ["84089.00", "0.001536"], ["84091.00", "0.004042"], ["84093.00", "0.010639"], ["84094.28", "0"], ["84095.00", "0.027997"], ["84097.00", "0.073676"], ["84099.00", "0.193883"], ["84101.00", "0.510218"], ["84102.99", "0.017353"], ["84103.00", "1.342681"], ["84105.00", "3.533371"], ["84107.00", "9.298345"], ["84109.40", "0"], ["84109.80", "0.527040"], ["84110.20", "0.178290"], ["84111.20", "0.356970"], ["84114.60", "0"], ["84115.40", "0.009000"], ["84116.90", "0.228000"], ["84117.00", "3.135090"], ["84149.00", "5.347345"], ["84157.50", "4.078484"], ["84166.00", "5.256712"], ["84174.50", "4.531649"], ["84183.00", "3.897218"], ["84191.50", "4.894180"], ["84200.00", "5.528611"], ["84208.50", "4.441016"], ["84217.00", "4.350383"], ["84225.50", "5.075446"], ["84234.00", "5.166079"], ["84242.50", "4.712914"], ["84251.00", "4.622282"], ["84259.50", "3.987851"], ["84268.00", "5.437978"], ["84276.50", "5.619244"], ["84285.00", "4.259750"], ["84293.50", "4.803547"], ["84302.00", "4.169117"], ["84310.50", "4.984813"], ["84525.82", "0.000099"]], "bids": [["84043.00", "0.279422"], ["84042.64", "0.027859"], ["84039.21", "0"], ["84038.80", "0.002665"], ["84036.80", "0.007013"], ["84034.80", "0.018457"], ["84032.80", "0.048571"], ["84030.80", "0.127819"], ["84028.81", "0.264929"], ["84028.80", "0.336366"], ["84026.80", "0.885172"], ["84024.80", "2.329401"], ["84022.80", "6.130002"], ["84022.50", "0.001009"], ["84021.90", "0.456480"], ["84019.40", "0.045540"], ["84017.40", "0.070440"], ["84011.50", "0"], ["83980.80", "4.078484"], ["83972.30", "4.259750"], ["83963.80", "3.897218"], ["83955.30", "5.075446"], ["83946.80", "5.166079"], ["83938.30", "4.984813"], ["83929.80", "4.894180"], ["83921.30", "4.622282"], ["83912.80", "4.169117"], ["83904.30", "3.987851"], ["83895.80", "5.619244"], ["83887.30", "4.441016"], ["83878.80", "5.256712"], ["83870.30", "5.347345"], ["83861.80", "4.712914"], ["83853.30", "4.350383"], ["83844.80", "5.528611"], ["83836.30", "4.531649"], ["83827.80", "5.437978"], ["83819.30", "4.803547"]], "checksum": 735565165, "ts": "1742555196885"}], "ts": 1742555196888, "record_time": 1742555196.915438, "EXCHANGE": "BITGET"}
{"action": "update", "arg": {"instType": "SPOT", "channel": "books", "instId": "BTCUSDT"}, "data": [{"asks": [["84043.01", "2.233361"], ["84077.18", "0"], ["84089.00", "0.001411"], ["84091.00", "0.003711"], ["84093.00", "0.009823"], ["84095.00", "0.025852"], ["84097.00", "0.068031"], ["84099.00", "0.179028"], ["84101.00", "0.471126"], ["84103.00", "1.239665"], ["84105.00", "3.262278"], ["84107.00", "8.584942"], ["84107.80", "0"], ["84108.70", "0.054030"], ["84109.40", "0.070800"], ["84109.80", "0.526830"], ["84109.89", "0.059095"], ["84110.20", "0"], ["84115.40", "1.359000"], ["84117.00", "0"], ["84149.00", "4.350383"], ["84157.50", "4.531649"], ["84166.00", "4.712914"], ["84174.50", "5.528611"], ["84183.00", "5.437978"], ["84191.50", "4.169117"], ["84200.00", "3.987851"], ["84208.50", "4.803547"], ["84217.00", "5.166079"], ["84225.50", "4.441016"], ["84234.00", "4.622282"], ["84242.50", "5.619244"], ["84251.00", "3.897218"], ["84259.50", "5.256712"], ["84268.00", "4.984813"], ["84276.50", "4.078484"], ["84285.00", "5.075446"], ["84293.50", "5.347345"], ["84302.00", "4.259750"], ["84310.50", "4.894180"], ["84527.47", "0.000608"]], "bids": [["84038.80", "0.002372"], ["84036.80", "0.006242"], ["84034.80", "0.016251"], ["84032.80", "0.042766"], ["84031.41", "0.109330"], ["84030.80", "0.112542"], ["84028.80", "0.295933"], ["84026.80", "0.778770"], ["84024.80", "2.049395"], ["84022.80", "5.393144"], ["84020.90", "0.072150"], ["84019.90", "0.071550"], ["84018.10", "2.356560"], ["84016.10", "0"], ["83993.00", "0"], ["83980.80", "4.350383"], ["83972.30", "4.441016"], ["83963.80", "5.166079"], ["83955.30", "5.437978"], ["83946.80", "5.075446"], ["83921.30", "4.803547"], ["83912.80", "4.259750"], ["83904.30", "4.078484"], ["83895.80", "5.347345"], ["83887.30", "4.622282"], ["83878.80", "3.987851"], ["83870.30", "4.169117"], ["83861.80", "5.619244"], ["83853.30", "4.531649"], ["83836.30", "3.897218"], ["83827.80", "5.256712"], ["83819.30", "4.712914"], ["83659.61", "0"]], "checksum": -29240375, "ts": "1742555197095"}], "ts": 1742555197100, "record_time": 1742555197.121868, "EXCHANGE": "BITGET"}
{"action": "update", "arg": {"instType": "SPOT", "channel": "books", "instId": "BTCUSDT"}, "data": [{"asks": [["84043.30", "0.086817"], ["84043.32", "0"], ["84091.00", "0.003603"], ["84093.00", "0.009482"], ["84095.00", "0.024954"], ["84097.00", "0.065669"], ["84099.00", "0.172813"], ["84101.00", "0.454769"], ["84103.00", "1.196762"], ["84105.00", "3.149374"], ["84107.00", "8.287825"], ["84149.00", "4.531649"], ["84157.50", "5.528611"], ["84166.00", "4.259750"], ["84174.50", "5.619244"], ["84183.00", "4.984813"], ["84191.50", "5.075446"], ["84200.00", "5.437978"], ["84208.50", "4.712914"], ["84217.00", "5.347345"], ["84225.50", "4.078484"], ["84234.00", "4.350383"], ["84242.50", "5.256712"], ["84259.50", "4.894180"], ["84268.00", "5.166079"], ["84276.50", "4.169117"], ["84285.00", "3.987851"], ["84293.50", "4.803547"], ["84302.00", "4.622282"], ["84310.50", "4.441016"]], "bids": [["84041.57", "0.010000"], ["84019.89", "0.298084"], ["83993.00", "0.000017"], ["83980.80", "5.619244"], ["83972.30", "4.350383"], ["83963.80", "5.347345"], ["83955.30", "5.166079"], ["83946.80", "4.441016"], ["83938.30", "4.894180"], ["83929.80", "5.256712"], ["83921.30", "4.169117"], ["83912.80", "4.712914"], ["83904.30", "4.803547"], ["83895.80", "4.984813"], ["83887.30", "5.437978"], ["83878.80", "3.897218"], ["83870.30", "4.622282"], ["83861.80", "5.528611"], ["83853.30", "4.259750"], ["83844.80", "4.078484"], ["83836.30", "5.075446"], ["83827.80", "4.531649"], ["83819.30", "3.987851"], ["83660.14", "0"], ["83660.00", "0"]], "checksum": -1715065736, "ts": "1742555197306"}], "ts": 1742555197309, "record_time": 1742555197.389985, "EXCHANGE": "BITGET"}
{"action": "update", "arg": {"instType": "SPOT", "channel": "books", "instId": "BTCUSDT"}, "data": [{"asks": [["84077.21", "0.183668"], ["84097.00", "0.065504"], ["84099.00", "0.172496"], ["84101.00", "0.453937"], ["84103.00", "1.194570"], ["84105.00", "3.143606"], ["84107.00", "8.272648"], ["84108.80", "0.022620"], ["84109.40", "0"], ["84110.60", "0"], ["84117.00", "0.904980"], ["84149.00", "4.803547"], ["84157.50", "4.531649"], ["84166.00", "4.984813"], ["84174.50", "4.078484"], ["84183.00", "5.528611"], ["84191.50", "5.347345"], ["84200.00", "5.619244"], ["84208.50", "4.622282"], ["84217.00", "4.712914"], ["84225.50", "5.437978"], ["84242.50", "4.259750"], ["84251.00", "5.256712"], ["84268.00", "3.987851"], ["84276.50", "3.897218"], ["84285.00", "5.166079"], ["84293.50", "4.441016"], ["84302.00", "5.075446"], ["84310.50", "4.169117"], ["84527.47", "0"]], "bids": [["84034.80", "0.016639"], ["84032.80", "0.043788"], ["84030.80", "0.115230"], ["84028.80", "0.303237"], ["84026.80", "0.797993"], ["84024.80", "2.099980"], ["84022.80", "5.526265"], ["84018.10", "0"], ["84017.90", "0.075030"], ["84016.40", "2.356620"], ["84012.20", "0.084150"], ["83980.80", "4.350383"], ["83972.30", "5.437978"], ["83963.80", "4.803547"], ["83955.30", "4.712914"], ["83946.80", "4.622282"], ["83938.30", "5.619244"], ["83929.80", "5.075446"], ["83921.30", "4.078484"], ["83912.80", "3.897218"], ["83904.30", "4.531649"], ["83887.30", "4.441016"], ["83878.80", "3.987851"], ["83870.30", "4.894180"], ["83861.80", "5.166079"], ["83844.80", "5.347345"], ["83836.30", "4.169117"], ["83827.80", "5.528611"], ["83819.30", "5.256712"], ["83660.71", "0"]], "checksum": -2109027220, "ts": "1742555197510"}], "ts": 1742555197512, "record_time": 1742555197.586507, "EXCHANGE": "BITGET"}
{"action": "update", "arg": {"instType": "SPOT", "channel": "books", "instId": "BTCUSDT"}, "data": [{"asks": [["84043.30", "0"], ["84077.20", "0.125924"], ["84093.00", "0.009683"], ["84095.00", "0.025482"], ["84097.00", "0.067057"], ["84099.00", "0.176466"], ["84101.00", "0.464385"], ["84103.00", "1.222065"], ["84105.00", "3.215961"], ["84107.00", "8.463056"], ["84109.89", "0"], ["84149.00", "4.350383"], ["84154.73", "0"], ["84157.50", "5.256712"], ["84163.14", "0"], ["84166.00", "4.259750"], ["84174.50", "4.622282"], ["84183.00", "4.531649"], ["84191.50", "4.169117"], ["84200.00", "5.347345"], ["84208.50", "4.078484"], ["84225.50", "3.987851"], ["84234.00", "3.897218"], ["84242.50", "4.894180"], ["84251.00", "5.166079"], ["84259.50", "4.984813"], ["84268.00", "4.441016"], ["84276.50", "5.075446"], ["84285.00", "5.437978"], ["84293.50", "4.803547"], ["84302.00", "5.619244"], ["84310.50", "5.528611"], ["84527.47", "0.000608"], ["84528.57", "0.000008"], ["84530.00", "0.000031"]], "bids": [["84043.00", "0.277063"], ["83991.00", "0.000032"], ["83980.80", "4.984813"], ["83972.30", "4.531649"], ["83964.63", "0"], ["83963.80", "3.987851"], ["83956.23", "0"], ["83955.30", "5.528611"], ["83946.80", "4.350383"], ["83938.30", "5.437978"], ["83929.80", "5.166079"], ["83921.30", "5.256712"], ["83912.80", "5.619244"], ["83904.30", "4.712914"], ["83895.80", "4.078484"], ["83887.30", "3.897218"], ["83878.80", "4.441016"], ["83870.30", "4.169117"], ["83861.80", "4.894180"], ["83853.30", "4.803547"], ["83844.80", "4.622282"], ["83836.30", "5.075446"], ["83827.80", "5.347345"], ["83819.30", "4.259750"], ["83660.71", "0.000309"], ["83660.14", "0.000016"]], "checksum": -563752184, "ts": "1742555197714"}], "ts": 1742555197718, "record_time": 1742555197.742668, "EXCHANGE": "BITGET"}
{"action": "update", "arg": {"instType": "SPOT", "channel": "books", "instId": "BTCUSDT"}, "data": [{"asks": [["84043.02", "0.020701"], ["84043.29", "0.086851"], ["84091.00", "0.003715"], ["84093.00", "0.009737"], ["84095.00", "0.025624"], ["84097.00", "0.067432"], ["84099.00", "0.177452"], ["84101.00", "0.466979"], ["84103.00", "1.228893"], ["84105.00", "3.233928"], ["84107.00", "8.510337"], ["84110.20", "0.178290"], ["84117.00", "0"], ["84149.00", "3.897218"], ["84157.50", "5.347345"], ["84166.00", "4.441016"], ["84174.50", "5.075446"], ["84183.00", "4.803547"], ["84191.50", "5.437978"], ["84200.00", "4.078484"], ["84208.50", "4.531649"], ["84217.00", "5.528611"], ["84225.50", "4.259750"], ["84234.00", "4.984813"], ["84242.50", "5.166079"], ["84251.00", "4.169117"], ["84259.50", "5.619244"], ["84268.00", "4.712914"], ["84276.50", "4.350383"], ["84285.00", "3.987851"], ["84293.50", "5.256712"], ["84302.00", "4.894180"], ["84310.50", "4.622282"], ["84530.00", "0"]], "bids": [["84042.64", "0"], ["84038.80", "0.002402"], ["84036.80", "0.006320"], ["84034.80", "0.016633"], ["84032.80", "0.043770"], ["84030.80", "0.115184"], ["84028.80", "0.303117"], ["84026.80", "0.797676"], ["84024.80", "2.099146"], ["84022.80", "5.524070"], ["84012.20", "0"], ["83980.80", "5.166079"], ["83972.30", "3.987851"], ["83963.80", "4.078484"], ["83955.30", "5.075446"], ["83946.80", "4.984813"], ["83938.30", "4.894180"], ["83929.80", "3.897218"], ["83921.30", "5.347345"], ["83912.80", "4.531649"], ["83895.80", "4.169117"], ["83887.30", "4.803547"], ["83870.30", "4.350383"], ["83861.80", "4.622282"], ["83853.30", "5.256712"], ["83844.80", "5.619244"], ["83836.30", "5.437978"], ["83827.80", "5.528611"], ["83660.00", "0.001273"], ["83659.61", "0.000454"]], "checksum": -1142560616, "ts": "1742555197936"}], "ts": 1742555197939, "record_time": 1742555197.963943, "EXCHANGE": "BITGET"}
{"action": "update", "arg": {"instType": "SPOT", "channel": "books", "instId": "BTCUSDT"}, "data": [{"asks": [["84043.02", "0.046240"], ["84093.00", "0.009724"], ["84095.00", "0.025591"], ["84097.00", "0.067343"], ["84099.00", "0.177218"], ["84101.00", "0.466365"], ["84103.00", "1.227276"], ["84105.00", "3.229673"], ["84107.00", "8.499140"], ["84108.50", "0.074760"], ["84108.70", "0.053670"], ["84148.72", "0.001810"], ["84149.00", "5.166079"], ["84157.13", "0.003620"], ["84157.50", "5.437978"], ["84166.00", "5.256712"], ["84183.00", "4.894180"], ["84191.50", "4.622282"], ["84200.00", "4.441016"], ["84208.50", "4.984813"], ["84217.00", "4.169117"], ["84225.50", "4.531649"], ["84234.00", "5.619244"], ["84242.50", "3.897218"], ["84251.00", "4.350383"], ["84259.50", "4.259750"], ["84268.00", "4.803547"], ["84276.50", "5.347345"], ["84285.00", "4.078484"], ["84293.50", "3.987851"], ["84302.00", "4.712914"], ["84310.50", "5.528611"], ["84527.47", "0"], ["84528.57", "0"]], "bids": [["84041.97", "0.027859"], ["84038.80", "0.002549"], ["84036.80", "0.006504"], ["84034.80", "0.017117"], ["84032.80", "0.045044"], ["84030.80", "0.118537"], ["84028.80", "0.311940"], ["84026.80", "0.820895"], ["84024.80", "2.160249"], ["84022.80", "5.684867"], ["83991.00", "0.000015"], ["83980.80", "5.256712"], ["83972.30", "5.075446"], ["83963.80", "4.712914"], ["83955.30", "4.531649"], ["83951.77", "0.001810"], ["83946.80", "4.350383"], ["83943.37", "0.003620"], ["83938.30", "5.437978"], ["83929.80", "4.259750"], ["83912.80", "4.984813"], ["83904.30", "4.441016"], ["83895.80", "3.987851"], ["83887.30", "4.622282"], ["83878.80", "3.897218"], ["83870.30", "4.169117"], ["83861.80", "4.078484"], ["83853.30", "5.528611"], ["83844.80", "4.894180"], ["83836.30", "4.803547"], ["83827.80", "5.619244"], ["83819.30", "5.166079"], ["83660.14", "0"], ["83660.00", "0"], ["83659.61", "0"]], "checksum": -916117118, "ts": "1742555198146"}], "ts": 1742555198149, "record_time": 1742555198.170896, "EXCHANGE": "BITGET"}
{"action": "update", "arg": {"instType": "SPOT", "channel": "books", "instId": "BTCUSDT"}, "data": [{"asks": [["84043.28", "0.086851"], ["84043.29", "0"], ["84108.50", "0.001023"], ["84108.70", "0"], ["84109.80", "0.527040"], ["84109.90", "0.405780"], ["84115.10", "0.006870"], ["84117.00", "0.904980"], ["84117.50", "0.713880"], ["84149.00", "5.256712"], ["84157.50", "4.712914"], ["84166.00", "4.078484"], ["84174.50", "4.259750"], ["84183.00", "5.075446"], ["84191.50", "4.803547"], ["84200.00", "4.350383"], ["84208.50", "3.897218"], ["84217.00", "5.619244"], ["84225.50", "5.347345"], ["84234.00", "3.987851"], ["84242.50", "4.531649"], ["84251.00", "4.622282"], ["84259.50", "5.166079"], ["84268.00", "4.441016"], ["84276.50", "4.894180"], ["84285.00", "4.984813"], ["84293.50", "5.528611"], ["84302.00", "5.437978"], ["84310.50", "4.169117"], ["84525.82", "0"]], "bids": [["83980.80", "4.622282"], ["83972.30", "4.078484"], ["83963.80", "4.350383"], ["83955.30", "5.166079"], ["83946.80", "5.075446"], ["83938.30", "4.169117"], ["83929.80", "4.531649"], ["83921.30", "4.803547"], ["83912.80", "5.619244"], ["83904.30", "3.987851"], ["83895.80", "4.712914"], ["83887.30", "5.256712"], ["83878.80", "5.528611"], ["83870.30", "4.259750"], ["83861.80", "4.894180"], ["83853.30", "4.441016"], ["83844.80", "3.897218"], ["83836.30", "5.347345"], ["83827.80", "4.984813"], ["83819.30", "5.437978"]], "checksum": -1421807068, "ts": "1742555198413"}], "ts": 1742555198417, "record_time": 1742555198.449915, "EXCHANGE": "BITGET"}
{"action": "update", "arg": {"instType": "SPOT", "channel": "books", "instId": "BTCUSDT"}, "data": [{"asks": [["84086.21", "0.010000"], ["84095.00", "0.025781"], ["84097.00", "0.067847"], ["84099.00", "0.178545"], ["84101.00", "0.470059"], ["84103.00", "1.236996"], ["84105.00", "3.255252"], ["84107.00", "8.566453"], ["84115.10", "0.021870"], ["84149.00", "4.259750"], ["84157.50", "5.075446"], ["84166.00", "4.803547"], ["84174.50", "5.347345"], ["84183.00", "3.987851"], ["84191.50", "4.441016"], ["84200.00", "4.078484"], ["84208.50", "4.169117"], ["84217.00", "4.531649"], ["84225.50", "4.350383"], ["84234.00", "5.619244"], ["84242.50", "5.528611"], ["84251.00", "3.897218"], ["84259.50", "4.894180"], ["84268.00", "5.256712"], ["84276.50", "5.166079"], ["84285.00", "4.622282"], ["84293.50", "4.712914"], ["84310.50", "4.984813"], ["84525.00", "0"]], "bids": [["84036.80", "0.006631"], ["84034.80", "0.017450"], ["84032.80", "0.045921"], ["84030.80", "0.120845"], ["84028.80", "0.318013"], ["84026.80", "0.836875"], ["84024.80", "2.202304"], ["84022.80", "5.795537"], ["83992.00", "0"], ["83980.80", "4.984813"], ["83972.30", "4.803547"], ["83963.80", "5.075446"], ["83955.30", "4.712914"], ["83946.80", "4.078484"], ["83938.30", "5.347345"], ["83929.80", "5.437978"], ["83921.30", "4.259750"], ["83912.80", "3.987851"], ["83904.30", "4.894180"], ["83895.80", "5.166079"], ["83887.30", "3.897218"], ["83878.80", "5.619244"], ["83870.30", "4.350383"], ["83861.80", "4.169117"], ["83853.30", "4.531649"], ["83844.80", "4.441016"], ["83836.30", "5.256712"], ["83827.80", "4.622282"], ["83819.30", "5.528611"], ["83660.14", "0.000016"]], "checksum": 1513129698, "ts": "1742555198639"}], "ts": 1742555198642, "record_time": 1742555198.665149, "EXCHANGE": "BITGET"}
