{"event": "subscribe", "arg": {"instType": "SPOT", "channel": "books", "instId": "BTCUSDT"}, "record_time": 1742576770.298868, "EXCHANGE": "BITGET"}
{"action": "snapshot", "arg": {"instType": "SPOT", "channel": "books", "instId": "BTCUSDT"}, "data": [{"asks": [["83896.83", "0.000001"], ["83896.84", "0.000100"], ["83896.85", "0.000100"], ["83909.74", "0.091201"], ["83910.00", "0.002000"], ["83914.01", "0.114615"], ["83919.41", "3.188123"], ["83919.53", "0.209200"], ["83921.23", "0.004587"], ["83924.50", "0.175218"], ["83925.31", "0.314756"], ["83926.53", "0.119905"], ["83927.94", "0.035972"], ["83928.14", "0.035971"], ["83930.76", "0.006357"], ["83931.01", "0.006357"], ["83931.55", "0.006357"], ["83931.65", "0.013500"], ["83931.66", "0.006356"], ["83931.78", "0.006357"], ["83931.81", "0.006357"], ["83932.13", "0.010995"], ["83932.45", "0.017484"], ["83932.84", "0.006357"], ["83933.01", "0.006357"], ["83933.21", "0.006357"], ["83933.29", "0.010993"], ["83933.83", "0.006357"], ["83934.00", "0.066056"], ["83934.01", "0.209200"], ["83934.04", "0.006357"], ["83934.06", "0.006357"], ["83934.32", "0.116400"], ["83934.58", "0.006357"], ["83934.76", "0.006357"], ["83934.86", "0.016429"], ["83934.96", "0.006357"], ["83935.03", "0.016429"], ["83935.36", "0.006357"], ["83935.43", "0.119901"], ["83935.96", "0.119905"], ["83937.47", "0.119850"], ["83938.27", "0.009990"], ["83938.50", "0.119858"], ["83940.00", "0.002000"], ["83940.04", "0.015895"], ["83940.56", "0.009989"], ["83941.41", "0.010988"], ["83941.97", "0.006356"], ["83942.31", "0.116400"], ["83942.61", "0.209200"], ["83944.60", "0.015896"], ["83947.81", "0.464387"], ["83947.82", "3.719477"], ["83949.69", "0.001376"], ["83951.00", "0.209200"], ["83954.89", "0.184408"], ["83956.00", "0.001009"], ["83958.00", "0.001008"], ["83960.00", "0.001040"], ["83960.41", "0.714622"], ["83962.00", "0.001025"], ["83963.00", "0.000976"], ["83964.00", "0.002026"], ["83964.68", "0.001598"], ["83966.00", "0.005330"], ["83966.48", "0.001598"], ["83966.55", "0.010000"], ["83966.71", "0.209200"], ["83968.00", "0.014028"], ["83970.00", "0.036915"], ["83972.00", "0.097144"], ["83974.00", "0.255643"], ["83976.00", "0.672743"], ["83976.10", "0.001004"], ["83976.30", "0.001019"], ["83976.70", "0.001001"], ["83976.75", "1.786208"], ["83976.80", "0.001007"], ["83977.00", "0.001050"], ["83977.20", "0.888910"], ["83978.00", "0.007770"], ["83978.20", "0.009000"], ["83978.50", "0.940380"], ["83978.70", "1.042170"], ["83979.60", "0.215370"], ["83981.70", "0.146400"], ["83981.90", "0.068130"], ["83982.00", "0.209200"], ["83982.10", "0.414870"], ["83983.00", "0.012240"], ["83983.30", "0.859050"], ["83983.70", "0.066420"], ["83985.80", "1.430250"], ["83986.30", "0.060000"], ["83986.40", "0.470790"], ["83986.70", "0.030000"], ["83986.90", "0.515400"], ["83987.00", "0.288000"], ["83992.00", "0.196628"], ["83993.00", "0.000087"], ["83993.01", "0.209200"], ["83996.44", "0.010010"], ["83996.62", "0.000179"], ["83999.00", "0.000315"], ["84000.00", "0.002000"], ["84001.40", "0.209200"], ["84003.55", "0.001810"], ["84012.84", "0.003620"], ["84015.01", "0.209200"], ["84016.34", "0.057335"], ["84017.90", "5.628008"], ["84018.24", "0.125912"], ["84025.82", "0.209200"], ["84026.30", "3.994070"], ["84030.00", "0.073668"], ["84034.42", "0.209200"], ["84034.70", "5.174136"], ["84036.67", "0.071678"], ["84042.82", "0.209200"], ["84043.10", "3.903296"], ["84050.00", "0.000100"], ["84051.50", "4.901813"], ["84052.01", "0.209200"], ["84059.90", "4.538716"], ["84060.00", "0.002000"], ["84063.21", "0.209200"], ["84068.30", "4.357167"], ["84070.00", "0.001279"], ["84072.80", "0.209200"], ["84076.70", "5.083362"], ["84081.19", "0.209200"], ["84081.60", "0.000027"], ["84082.46", "0.027677"], ["84085.10", "5.446459"], ["84090.00", "0.002000"], ["84092.11", "0.209200"], ["84093.50", "5.264910"], ["84101.11", "0.209200"], ["84101.90", "5.355685"], ["84102.97", "0.001720"], ["84110.30", "4.175619"], ["84114.71", "0.203800"], ["84117.07", "0.163907"], ["84118.70", "4.629490"], ["84120.00", "0.002000"], ["84120.31", "0.000018"], ["84120.42", "0.000008"], ["84121.21", "0.000010"], ["84121.90", "0.000124"], ["84121.93", "0.000069"], ["84122.10", "0.000042"], ["84122.11", "0.000023"], ["84123.60", "0.001450"], ["84124.00", "0.000175"], ["84124.14", "0.000135"], ["84124.65", "0.000066"], ["84125.00", "0.007748"], ["84125.55", "0.209200"], ["84126.51", "0.000008"], ["84126.70", "0.296078"], ["84127.10", "4.811039"], ["84127.27", "0.000010"], ["84128.44", "0.000072"], ["84129.03", "0.000008"], ["84129.07", "0.000020"], ["84130.00", "0.060049"], ["84130.43", "0.003446"], ["84132.13", "0.000176"], ["84132.80", "0.000008"], ["84132.97", "0.000104"], ["84133.33", "0.002817"], ["84133.94", "0.209200"], ["84135.50", "4.084844"], ["84136.28", "0.000011"], ["84137.93", "0.000024"], ["84138.74", "0.000024"], ["84139.90", "0.000023"], ["84140.00", "0.000630"], ["84140.96", "0.000013"], ["84141.97", "0.000423"], ["84142.33", "0.209200"], ["84142.86", "0.042208"], ["84143.90", "4.720265"], ["84144.14", "0.000061"], ["84144.15", "0.000053"], ["84144.74", "0.000093"], ["84148.30", "0.000060"], ["84148.94", "0.000137"], ["84148.96", "0.000039"], ["84150.00", "0.002747"], ["84150.08", "0.000019"], ["84150.33", "0.000008"], ["84150.72", "0.209200"], ["84151.59", "0.000020"], ["84151.79", "0.000036"], ["84152.17", "0.000010"], ["84152.30", "5.537233"], ["84153.84", "0.000008"], ["84153.85", "0.000023"], ["84155.83", "0.000019"], ["84156.01", "0.000019"], ["84157.89", "0.000183"], ["84159.01", "0.000149"], ["84159.09", "0.000042"], ["84159.11", "0.209200"], ["84159.59", "0.000036"], ["84159.60", "0.300112"], ["84159.62", "0.000099"], ["84160.00", "0.001138"], ["84160.70", "4.992587"], ["84160.71", "0.000016"], ["84162.16", "0.000009"], ["84162.50", "0.000031"], ["84163.18", "0.000050"], ["84163.64", "0.000008"], ["84163.92", "0.000010"], ["84164.43", "0.011010"], ["84165.59", "0.000054"], ["84166.55", "0.000008"], ["84166.67", "0.000699"], ["84166.69", "0.000010"], ["84166.71", "0.000008"], ["84167.50", "0.209200"], ["84168.50", "0.000008"], ["84169.10", "4.447942"], ["84169.49", "0.001213"], ["84170.00", "0.000725"], ["84170.25", "0.000143"], ["84170.47", "0.000013"], ["84170.56", "0.000009"], ["84171.43", "0.000016"], ["84173.62", "0.000024"], ["84173.91", "0.000020"], ["84174.51", "0.000388"], ["84174.57", "0.000010"], ["84174.61", "0.000043"], ["84175.73", "0.000010"], ["84175.89", "0.209200"], ["84176.47", "0.000040"], ["84177.00", "0.001450"], ["84177.20", "0.000064"], ["84177.50", "4.266393"], ["84179.10", "0.000008"], ["84180.00", "0.002639"], ["84180.09", "0.000033"], ["84181.09", "0.000030"], ["84181.81", "0.001547"], ["84181.82", "0.000060"], ["84182.16", "0.000048"], ["84182.69", "0.000067"], ["84183.27", "0.000009"], ["84183.50", "0.000113"], ["84183.67", "0.000010"], ["84184.17", "0.000009"], ["84188.89", "0.000025"], ["84189.33", "0.000133"], ["84189.45", "0.000023"], ["84190.00", "0.000670"], ["84191.18", "0.000041"], ["84192.12", "0.000288"], ["84192.98", "0.000033"], ["84193.22", "0.000023"], ["84193.77", "0.000012"], ["84193.99", "0.000209"], ["84194.12", "0.000071"], ["84195.96", "0.000038"], ["84196.77", "0.000020"], ["84197.27", "0.000016"], ["84198.00", "0.001012"], ["84198.35", "0.000057"], ["84198.45", "0.000008"], ["84200.00", "0.028168"], ["84200.01", "0.000246"], ["84203.00", "0.000008"], ["84203.59", "0.000061"], ["84204.08", "0.000184"], ["84205.61", "0.000034"], ["84205.79", "0.000135"], ["84205.88", "0.000080"], ["84206.90", "0.000008"], ["84207.14", "0.000128"], ["84207.69", "0.000009"], ["84208.00", "0.000012"], ["84209.48", "0.000013"], ["84209.68", "0.000019"], ["84209.82", "0.000047"], ["84210.00", "0.002618"], ["84210.53", "0.000009"], ["84212.00", "0.000012"], ["84212.47", "0.000009"], ["84212.50", "0.006969"], ["84214.29", "0.000033"], ["84214.88", "0.000161"], ["84215.69", "0.000008"], ["84216.22", "0.000008"], ["84216.67", "0.000970"], ["84216.87", "0.000008"], ["84217.48", "0.000095"], ["84217.86", "0.000273"], ["84219.35", "0.000008"], ["84219.55", "0.000349"], ["84220.00", "0.000618"], ["84220.69", "0.000135"], ["84222.00", "0.000081"], ["84222.03", "0.000013"], ["84222.22", "0.000907"], ["84223.05", "0.000039"], ["84223.65", "0.000178"], ["84223.89", "0.000008"], ["84224.11", "0.000277"], ["84224.14", "0.000016"], ["84224.62", "0.000022"], ["84225.00", "0.000107"], ["84225.86", "0.007944"], ["84225.88", "0.000024"], ["84226.09", "0.000013"], ["84226.42", "0.000096"], ["84228.57", "0.000013"], ["84228.72", "0.000188"], ["84229.07", "0.000010"], ["84229.39", "0.000020"], ["84230.00", "0.000640"], ["84230.76", "0.000008"], ["84230.77", "0.000111"], ["84232.69", "0.000066"], ["84233.16", "0.000023"], ["84233.34", "0.000119"], ["84233.38", "0.001273"], ["84233.43", "0.000015"], ["84233.87", "0.000039"], ["84234.04", "0.000137"], ["84234.07", "0.000039"], ["84234.23", "0.000698"], ["84235.10", "0.001444"], ["84235.23", "0.000051"], ["84235.29", "0.042045"], ["84235.93", "0.000046"], ["84238.10", "0.000024"], ["84238.53", "0.000072"], ["84238.89", "0.000134"], ["84239.00", "0.000240"], ["84239.11", "0.000011"], ["84239.13", "0.000010"], ["84240.00", "0.003183"], ["84242.34", "0.000423"], ["84242.60", "0.000537"], ["84244.60", "0.301368"], ["84244.90", "0.000085"], ["84246.15", "0.000015"], ["84249.42", "0.000030"], ["84250.00", "0.067266"], ["84251.44", "0.000011"], ["84252.44", "0.000143"], ["84252.50", "0.000025"], ["84254.39", "0.000022"], ["84254.55", "0.000009"], ["84255.35", "0.000143"], ["84256.00", "0.000022"], ["84256.79", "0.000314"], ["84257.14", "0.000145"], ["84258.91", "0.000036"], ["84259.12", "0.000009"], ["84259.87", "0.000093"], ["84259.99", "0.000017"], ["84260.00", "0.000676"], ["84260.87", "0.000008"], ["84263.15", "0.000019"], ["84263.16", "0.000183"], ["84264.58", "1.645384"], ["84264.71", "0.000009"], ["84266.08", "0.000016"], ["84266.67", "0.002976"], ["84267.78", "0.000010"], ["84268.56", "0.000013"], ["84269.24", "0.000032"], ["84270.00", "0.002641"], ["84270.27", "0.000009"], ["84270.80", "0.000018"], ["84270.96", "0.000055"], ["84270.98", "0.000052"], ["84271.10", "0.000019"], ["84271.34", "0.000026"], ["84272.72", "0.000105"], ["84272.73", "0.000492"], ["84273.33", "0.000013"], ["84276.28", "0.000009"], ["84277.78", "0.000011"], ["84278.24", "0.000050"], ["84278.38", "0.000199"], ["84279.36", "0.000009"], ["84279.98", "0.000239"], ["84280.00", "0.001334"], ["84280.70", "0.000033"], ["84280.74", "0.000047"], ["84281.69", "0.000099"], ["84282.35", "0.000071"], ["84282.39", "0.000135"], ["84282.82", "0.000012"], ["84283.33", "0.000010"], ["84283.87", "0.000020"], ["84285.00", "0.000031"], ["84285.68", "0.000178"], ["84285.71", "0.000347"], ["84285.95", "0.000028"], ["84286.00", "0.000119"], ["84286.67", "0.000009"], ["84286.73", "0.000057"], ["84286.79", "0.000016"], ["84287.50", "0.000076"], ["84288.00", "0.003000"], ["84288.89", "0.000361"], ["84289.58", "0.000008"], ["84290.00", "0.000617"], ["84293.56", "0.000063"], ["84294.12", "0.000080"], ["84294.20", "0.000128"], ["84294.68", "0.000019"], ["84296.87", "0.000014"], ["84297.06", "0.000035"], ["84298.07", "0.000811"], ["84298.31", "0.000023"], ["84298.41", "0.000009"], ["84298.64", "0.000088"], ["84300.00", "0.023174"], ["84301.40", "0.000023"], ["84301.47", "0.000041"], ["84302.88", "0.000067"], ["84303.00", "0.296549"], ["84306.66", "0.000145"], ["84307.00", "0.000113"], ["84307.23", "0.000008"], ["84309.09", "0.000010"], ["84309.60", "0.002450"], ["84309.68", "0.000062"], ["84309.96", "0.000011"], ["84310.34", "0.000331"], ["84310.35", "0.000146"], ["84311.11", "0.000025"], ["84311.16", "0.000008"], ["84311.31", "0.002260"], ["84311.72", "0.000013"], ["84312.50", "0.000125"], ["84313.03", "0.000024"], ["84314.97", "0.000008"], ["84315.74", "0.000051"], ["84316.67", "0.000322"], ["84317.24", "0.000135"], ["84317.40", "0.000010"], ["84318.18", "0.000012"], ["84318.59", "0.000027"], ["84319.15", "0.000137"], ["84319.18", "0.000039"], ["84320.00", "0.000019"], ["84321.87", "0.000919"], ["84322.11", "0.000008"], ["84324.32", "0.000069"], ["84325.00", "0.000128"], ["84325.07", "0.000161"], ["84326.09", "0.000010"], ["84326.42", "0.000023"], ["84327.14", "0.000039"], ["84327.73", "0.041940"], ["84328.95", "0.000174"], ["84329.64", "0.000026"], ["84330.00", "0.002000"], ["84332.00", "0.511323"], ["84332.56", "0.000009"], ["84333.32", "0.000047"], ["84333.33", "0.003953"], ["84333.36", "0.000010"], ["84333.38", "0.000008"], ["84334.48", "0.000096"], ["84334.77", "0.000022"], ["84336.00", "0.000133"], ["84336.23", "0.000013"], ["84336.29", "0.000010"], ["84336.34", "0.000176"], ["84337.25", "0.000067"], ["84337.35", "0.000008"], ["84337.50", "0.000010"], ["84338.26", "0.000023"], ["84338.46", "0.000015"], ["84339.21", "0.000010"], ["84339.29", "0.000029"], ["84339.50", "0.000323"], ["84339.62", "0.000051"], ["84340.00", "0.018287"], ["84340.46", "0.000143"], ["84340.72", "0.000066"], ["84341.00", "0.002997"], ["84341.01", "0.000008"], ["84342.11", "0.000051"], ["84342.63", "0.000009"], ["84342.70", "0.000423"], ["84343.02", "0.000338"], ["84343.07", "0.000014"], ["84343.70", "0.000075"], ["84343.97", "0.000188"], ["84344.77", "0.000361"]], "bids": [["83896.82", "1.463761"], ["83896.81", "0.359318"], ["83895.90", "1.446343"], ["83893.91", "2.389762"], ["83893.90", "3.806168"], ["83893.66", "0.008282"], ["83893.05", "0.204856"], ["83893.04", "0.256880"], ["83893.00", "0.000015"], ["83892.64", "0.764775"], ["83892.01", "0.008076"], ["83892.00", "0.000032"], ["83891.90", "10.016230"], ["83891.89", "0.015220"], ["83891.84", "0.009807"], ["83891.79", "0.009570"], ["83891.77", "0.007781"], ["83891.76", "0.008265"], ["83891.75", "0.006979"], ["83891.61", "0.009328"], ["83891.60", "0.001044"], ["83891.40", "0.191880"], ["83891.25", "0.007205"], ["83891.15", "0.008483"], ["83891.14", "0.014211"], ["83891.11", "0.006318"], ["83891.09", "0.005948"], ["83891.08", "0.023163"], ["83891.07", "0.010065"], ["83891.03", "0.009425"], ["83891.02", "0.009264"], ["83891.00", "0.000032"], ["83890.92", "0.001952"], ["83890.00", "0.000017"], ["83889.30", "0.128550"], ["83889.20", "0.179100"], ["83889.10", "0.420180"], ["83889.00", "1.010400"], ["83888.50", "0.022830"], ["83888.00", "0.000017"], ["83887.86", "0.089696"], ["83887.00", "0.000017"], ["83886.97", "0.018277"], ["83886.80", "2.849910"], ["83886.69", "0.015754"], ["83886.50", "0.006060"], ["83886.28", "0.017831"], ["83886.20", "0.917100"], ["83886.00", "0.074970"], ["83885.54", "0.005951"], ["83885.42", "0.247617"], ["83885.36", "0.028882"], ["83885.33", "0.007142"], ["83885.07", "0.016437"], ["83885.00", "0.000017"], ["83884.90", "0.171060"], ["83884.65", "0.008319"], ["83884.64", "0.008111"], ["83884.63", "0.005063"], ["83884.61", "0.005613"], ["83884.58", "0.005182"], ["83884.53", "0.005129"], ["83884.50", "0.004862"], ["83884.48", "0.008558"], ["83884.47", "0.055651"], ["83884.32", "0.006573"], ["83884.31", "0.083662"], ["83884.30", "0.015000"], ["83884.25", "0.225105"], ["83884.24", "0.007958"], ["83884.23", "0.017128"], ["83884.06", "0.019377"], ["83884.00", "0.000017"], ["83883.96", "0.008936"], ["83883.90", "0.015000"], ["83883.85", "0.025205"], ["83883.77", "0.008780"], ["83883.71", "0.007349"], ["83883.70", "0.193680"], ["83883.40", "0.030000"], ["83883.17", "0.017119"], ["83883.00", "0.000017"], ["83882.90", "0.030000"], ["83882.85", "0.051859"], ["83882.54", "0.017381"], ["83882.52", "0.008203"], ["83882.40", "0.447510"], ["83882.05", "0.018554"], ["83882.00", "0.000017"], ["83881.60", "2.501190"], ["83881.43", "0.008292"], ["83881.40", "0.017520"], ["83881.10", "0.314756"], ["83881.04", "0.047600"], ["83881.03", "0.209200"], ["83881.00", "0.000017"], ["83880.82", "0.012677"], ["83880.80", "0.168630"], ["83880.60", "1.079040"], ["83880.40", "0.120000"], ["83880.00", "0.000017"], ["83879.90", "2.681760"], ["83879.50", "0.120000"], ["83879.49", "0.017250"], ["83879.40", "0.268909"], ["83879.30", "0.021172"], ["83879.12", "0.076263"], ["83879.10", "0.480000"], ["83879.00", "0.000017"], ["83878.70", "0.240000"], ["83878.60", "4.839660"], ["83878.42", "0.223111"], ["83878.00", "0.000017"], ["83877.01", "0.101342"], ["83877.00", "0.000017"], ["83876.69", "0.012463"], ["83876.00", "0.000017"], ["83875.79", "0.073205"], ["83875.55", "0.259289"], ["83875.00", "0.000017"], ["83874.00", "0.000017"], ["83873.00", "0.000017"], ["83872.28", "0.209200"], ["83872.00", "0.000017"], ["83871.00", "0.000017"], ["83870.93", "0.056482"], ["83870.00", "0.000017"], ["83869.18", "0.000879"], ["83869.00", "0.000017"], ["83868.93", "0.007450"], ["83868.00", "0.000017"], ["83867.01", "0.017484"], ["83867.00", "0.000017"], ["83866.10", "0.207210"], ["83866.07", "0.008589"], ["83866.00", "0.000017"], ["83865.00", "0.000017"], ["83864.00", "0.000017"], ["83863.45", "0.209200"], ["83863.27", "0.715450"], ["83863.00", "0.000017"], ["83862.60", "0.007667"], ["83862.58", "0.007352"], ["83862.55", "0.007262"], ["83862.00", "0.000017"], ["83861.47", "0.006216"], ["83861.00", "0.000017"], ["83860.00", "0.000017"], ["83859.00", "0.000017"], ["83858.70", "0.000061"], ["83858.00", "0.000032"], ["83857.00", "0.000032"], ["83856.00", "0.000032"], ["83855.00", "0.000032"], ["83854.60", "0.001177"], ["83854.03", "0.000200"], ["83854.00", "0.000032"], ["83853.97", "0.003604"], ["83853.00", "0.000032"], ["83852.53", "0.001174"], ["83852.00", "0.000032"], ["83851.68", "0.209200"], ["83851.00", "0.000032"], ["83850.00", "3.994070"], ["83849.00", "0.000032"], ["83848.00", "0.000032"], ["83847.00", "0.000032"], ["83844.43", "0.000100"], ["83843.00", "0.000017"], ["83841.60", "5.264910"], ["83841.00", "0.000015"], ["83840.79", "0.071668"], ["83840.26", "0.209200"], ["83837.42", "0.071678"], ["83833.30", "0.000971"], ["83833.20", "5.446459"], ["83831.87", "0.209200"], ["83826.13", "0.000172"], ["83824.80", "5.628008"], ["83823.46", "0.209200"], ["83820.00", "0.007600"], ["83816.40", "4.266393"], ["83815.37", "0.000022"], ["83815.06", "0.209200"], ["83814.35", "0.001810"], ["83810.00", "0.000270"], ["83808.00", "4.992587"], ["83806.66", "0.209200"], ["83805.97", "0.003620"], ["83803.64", "0.057335"], ["83802.81", "0.000022"], ["83800.00", "0.000387"], ["83799.60", "4.084844"], ["83798.26", "0.209200"], ["83791.20", "4.357167"], ["83790.00", "0.002270"], ["83789.87", "0.209200"], ["83782.80", "5.537233"], ["83781.46", "0.209200"], ["83780.00", "0.000270"], ["83779.93", "0.000028"], ["83774.40", "4.538716"], ["83773.82", "0.125878"], ["83773.31", "0.000154"], ["83770.00", "0.000270"], ["83767.90", "0.001457"], ["83766.00", "4.629490"], ["83762.50", "0.000076"], ["83760.00", "0.002281"], ["83757.60", "4.447942"], ["83754.70", "0.000013"], ["83751.34", "0.000487"], ["83750.67", "0.000146"], ["83750.00", "0.000270"], ["83749.66", "0.000016"], ["83749.50", "0.000069"], ["83749.20", "5.174136"], ["83747.02", "0.012368"], ["83745.37", "0.012371"], ["83745.16", "0.000389"], ["83740.80", "4.175619"], ["83740.00", "0.000322"], ["83737.00", "0.000009"], ["83734.30", "0.304409"], ["83732.40", "3.903296"], ["83730.00", "0.002270"], ["83729.32", "0.000035"], ["83728.57", "0.000017"], ["83728.37", "0.001273"], ["83727.27", "0.000066"], ["83726.20", "0.000016"], ["83724.00", "4.901813"], ["83723.40", "0.000068"], ["83720.00", "0.002671"], ["83717.48", "0.005970"], ["83715.60", "5.355685"], ["83713.71", "0.000323"], ["83712.30", "0.011010"], ["83710.00", "0.000293"], ["83707.34", "0.001720"], ["83707.20", "4.720265"], ["83705.85", "0.000019"], ["83703.70", "0.000425"], ["83702.50", "0.000033"], ["83701.28", "0.000248"], ["83700.80", "0.311180"], ["83700.00", "0.004213"], ["83698.80", "5.083362"], ["83695.89", "0.027677"], ["83690.84", "0.000162"], ["83690.40", "4.811039"], ["83690.00", "0.000270"], ["83689.50", "0.000113"], ["83687.50", "0.006969"], ["83687.00", "0.000008"], ["83686.11", "0.000096"], ["83686.07", "0.005970"], ["83680.00", "0.001552"], ["83677.37", "0.000008"], ["83676.47", "0.000080"], ["83675.68", "0.000008"], ["83675.00", "0.000076"], ["83674.19", "0.000020"], ["83673.87", "0.000022"], ["83672.50", "0.000031"], ["83670.05", "0.000033"], ["83670.00", "0.002270"], ["83669.66", "0.000010"], ["83669.09", "0.000135"], ["83668.70", "0.001434"], ["83667.23", "0.012503"], ["83666.67", "0.000146"], ["83664.71", "0.000071"], ["83663.91", "0.000161"], ["83662.97", "0.000149"], ["83660.14", "0.000016"], ["83660.00", "0.000270"], ["83659.60", "0.000143"], ["83659.49", "0.000012"], ["83654.23", "0.000009"], ["83650.00", "0.000353"], ["83648.40", "0.001485"], ["83646.67", "0.000018"], ["83642.10", "0.305869"], ["83640.35", "0.000022"], ["83640.00", "0.003066"], ["83639.71", "0.000041"], ["83639.15", "0.000009"], ["83638.32", "0.000039"], ["83638.30", "0.000137"], ["83637.17", "0.000027"], ["83636.36", "0.041598"], ["83633.33", "0.000970"], ["83631.53", "0.000009"], ["83630.43", "0.000010"], ["83630.00", "0.000619"], ["83629.03", "0.000039"], ["83629.02", "0.000078"], ["83625.00", "0.000356"], ["83623.43", "0.000010"], ["83621.62", "0.000009"], ["83620.70", "0.000146"], ["83620.69", "0.000016"], ["83620.00", "0.000667"], ["83619.21", "0.000051"], ["83618.18", "0.000008"], ["83617.90", "0.000364"], ["83616.67", "0.000322"], ["83615.85", "0.000024"], ["83611.93", "0.000028"], ["83610.00", "0.002619"], ["83608.30", "0.493274"], ["83607.60", "0.000014"], ["83603.60", "0.000061"], ["83603.26", "0.000010"], ["83602.67", "0.000133"], ["83600.00", "0.015433"], ["83598.51", "0.000039"], ["83596.01", "0.000013"], ["83594.44", "0.000134"], ["83593.33", "0.000013"], ["83593.13", "1.672615"], ["83590.00", "0.000619"], ["83588.24", "0.042020"], ["83587.50", "0.000076"], ["83587.10", "0.000028"], ["83586.96", "0.002633"], ["83586.29", "0.000008"], ["83584.53", "0.000314"], ["83584.34", "0.000008"], ["83584.00", "0.000022"], ["83583.85", "0.000052"], ["83583.33", "0.000010"], ["83581.82", "0.000010"], ["83581.73", "0.000067"], ["83581.30", "0.001130"], ["83580.64", "0.004656"], ["83580.56", "0.000019"], ["83580.31", "0.000023"], ["83580.00", "0.002642"], ["83578.95", "0.000033"], ["83578.04", "0.000096"], ["83577.78", "0.000025"], ["83576.47", "0.000071"], ["83574.50", "0.000143"], ["83571.43", "0.000104"], ["83571.42", "0.000008"], ["83570.62", "0.000016"], ["83570.45", "0.000012"], ["83570.00", "0.000678"], ["83569.08", "0.000093"], ["83568.28", "0.000010"], ["83567.57", "0.000008"], ["83566.00", "0.000113"], ["83565.22", "0.000021"], ["83563.71", "0.000022"], ["83562.71", "0.000023"], ["83562.50", "0.000761"], ["83560.71", "0.001273"], ["83560.00", "0.000950"], ["83558.43", "0.000019"], ["83558.00", "0.000008"], ["83557.47", "0.001539"], ["83556.15", "0.000024"], ["83555.56", "0.000105"], ["83555.38", "0.000013"], ["83553.72", "0.000161"], ["83553.21", "0.000039"], ["83553.19", "0.000137"], ["83552.63", "0.000051"], ["83551.42", "0.000017"], ["83550.58", "0.000009"], ["83550.00", "0.002749"], ["83546.24", "0.000016"], ["83545.82", "0.000009"], ["83545.45", "0.000113"], ["83544.88", "0.011010"], ["83544.83", "0.000135"], ["83544.33", "0.000008"], ["83543.48", "0.000010"], ["83542.86", "0.000013"], ["83540.93", "0.000035"], ["83540.15", "0.000014"], ["83540.00", "0.000631"], ["83539.78", "0.000423"], ["83539.45", "0.000033"], ["83539.43", "0.000009"], ["83537.50", "0.000016"], ["83537.23", "0.000188"], ["83535.71", "0.000016"], ["83534.48", "0.000016"], ["83533.68", "0.000144"], ["83533.33", "0.000151"], ["83532.05", "0.000364"], ["83532.00", "0.002409"], ["83531.38", "0.000010"], ["83531.31", "0.000390"], ["83530.61", "0.000085"], ["83530.39", "0.000043"], ["83530.00", "0.000654"], ["83529.41", "0.000085"], ["83528.71", "0.000024"], ["83528.11", "0.000179"], ["83527.05", "0.000008"], ["83526.32", "0.000183"], ["83523.81", "0.000009"], ["83523.06", "0.000022"], ["83521.43", "0.000273"], ["83521.12", "0.000022"], ["83520.00", "0.003225"], ["83519.52", "0.000176"], ["83516.67", "0.000970"], ["83514.80", "0.000537"], ["83514.29", "0.000009"], ["83513.51", "0.000070"], ["83512.50", "0.006969"], ["83511.11", "0.000009"], ["83510.71", "0.000128"], ["83510.49", "0.000019"], ["83510.00", "0.000619"], ["83509.09", "0.000008"], ["83508.29", "0.000015"], ["83508.06", "0.000039"], ["83507.69", "0.000015"], ["83507.21", "0.000297"], ["83506.49", "0.000088"], ["83505.74", "0.000315"], ["83502.04", "0.000016"], ["83500.72", "0.000033"], ["83500.04", "0.000008"], ["83500.02", "0.000010"], ["83500.01", "0.000119"], ["83500.00", "0.016168"], ["83499.14", "0.000051"], ["83498.85", "0.000030"], ["83498.52", "0.000013"], ["83497.26", "0.000010"], ["83496.77", "0.000008"], ["83496.48", "0.000008"], ["83495.80", "0.041940"], ["83495.20", "0.000008"], ["83494.42", "0.000039"], ["83493.98", "0.000008"], ["83493.77", "0.000013"], ["83491.92", "0.000009"], ["83491.23", "0.000033"], ["83490.00", "0.002000"], ["83489.39", "0.000143"], ["83488.85", "0.000459"], ["83488.30", "0.000065"], ["83488.24", "0.000071"], ["83487.05", "0.000023"], ["83486.67", "0.000008"], ["83486.37", "0.000008"], ["83485.71", "0.000016"], ["83485.00", "0.000012"], ["83483.48", "0.000424"], ["83482.76", "0.000008"], ["83482.35", "0.000105"], ["83481.47", "0.000219"], ["83481.40", "0.000012"], ["83481.09", "0.000016"], ["83480.00", "0.000021"], ["83478.26", "0.016818"], ["83477.27", "0.000042"], ["83476.45", "0.000067"], ["83476.19", "0.000024"], ["83474.95", "0.000026"], ["83474.17", "0.000460"], ["83473.68", "0.000242"], ["83472.80", "0.000050"], ["83472.51", "0.000063"], ["83472.00", "0.000012"], ["83470.00", "0.000052"], ["83469.98", "0.000096"], ["83468.61", "0.000061"], ["83468.10", "0.000039"], ["83468.09", "0.000137"], ["83467.89", "0.000072"], ["83466.67", "0.002827"], ["83465.47", "0.000019"], ["83464.91", "0.000022"], ["83464.65", "0.000135"], ["83464.29", "0.000036"], ["83463.89", "0.000026"], ["83462.50", "0.000025"], ["83462.01", "0.000009"], ["83461.54", "0.000178"], ["83461.53", "0.000008"], ["83460.43", "0.000010"], ["83460.00", "0.002021"], ["83459.46", "0.000008"], ["83458.33", "0.000218"], ["83458.15", "0.000010"], ["83458.10", "0.000011"], ["83457.63", "0.000023"], ["83456.52", "0.000010"], ["83456.00", "0.000133"], ["83455.56", "0.000025"], ["83455.07", "0.000013"]], "checksum": 0, "ts": "1742576769994"}], "ts": 1742576770102, "record_time": 1742576770.351047, "EXCHANGE": "BITGET"}
{"action": "update", "arg": {"instType": "SPOT", "channel": "books", "instId": "BTCUSDT"}, "data": [{"asks": [["83896.83", "0.519501"], ["83925.78", "0.116400"], ["83929.30", "0.013838"], ["83958.00", "0.001262"], ["83960.00", "0.003321"], ["83962.00", "0.008741"], ["83964.00", "0.023002"], ["83966.00", "0.060531"], ["83968.00", "0.159294"], ["83970.00", "0.419194"], ["83972.00", "1.103142"], ["83974.00", "2.903004"], ["83976.00", "7.639485"], ["83976.30", "0.528120"], ["83976.40", "0.826170"], ["83976.70", "0"], ["83976.80", "0"], ["83977.00", "0"], ["83978.00", "0.050280"], ["83978.50", "0"], ["83978.70", "0"], ["83979.60", "0.215160"], ["83980.00", "0.042300"], ["83981.70", "0"], ["83982.70", "0.035400"], ["83983.30", "0.876900"], ["83983.70", "0"], ["83986.40", "0"], ["83986.70", "0.933030"], ["83987.10", "0.072840"], ["84017.90", "4.720265"], ["84026.30", "4.357167"], ["84034.70", "3.994070"], ["84043.10", "5.628008"], ["84051.50", "4.538716"], ["84059.90", "5.264910"], ["84068.30", "5.083362"], ["84076.70", "5.355685"], ["84085.10", "4.629490"], ["84093.50", "3.903296"], ["84101.90", "5.537233"], ["84110.30", "4.811039"], ["84118.70", "4.992587"], ["84127.10", "4.447942"], ["84135.50", "4.901813"], ["84143.90", "4.084844"], ["84152.30", "5.446459"], ["84160.70", "5.174136"], ["84169.10", "4.266393"], ["84177.50", "4.175619"], ["84345.79", "0.000034"], ["84346.43", "0.000128"]], "bids": [["83896.82", "1.413920"], ["83895.90", "0.441214"], ["83893.90", "1.161089"], ["83891.90", "3.055496"], ["83891.60", "0.216060"], ["83891.40", "0.162090"], ["83889.30", "0.128370"], ["83889.20", "0"], ["83889.00", "1.993770"], ["83886.80", "0.070920"], ["83886.20", "0.438330"], ["83886.18", "0.024893"], ["83885.50", "0.495600"], ["83883.90", "0"], ["83883.80", "0.516000"], ["83883.70", "0.015000"], ["83880.60", "0.004038"], ["83878.60", "0.120000"], ["83876.13", "0.024948"], ["83850.00", "5.446459"], ["83841.60", "5.355685"], ["83841.00", "0.000032"], ["83833.20", "4.811039"], ["83824.80", "5.537233"], ["83816.40", "4.992587"], ["83808.00", "3.994070"], ["83799.60", "4.357167"], ["83791.20", "5.174136"], ["83782.80", "4.720265"], ["83774.40", "4.901813"], ["83757.60", "4.266393"], ["83749.20", "4.084844"], ["83740.80", "5.628008"], ["83732.40", "5.264910"], ["83724.00", "4.447942"], ["83715.60", "5.083362"], ["83707.20", "3.903296"], ["83698.80", "4.175619"], ["83690.40", "4.538716"], ["83455.56", "0"], ["83455.07", "0"]], "checksum": 598367723, "ts": "1742576770196"}], "ts": 1742576770203, "record_time": 1742576770.413772, "EXCHANGE": "BITGET"}
{"action": "update", "arg": {"instType": "SPOT", "channel": "books", "instId": "BTCUSDT"}, "data": [{"asks": [["83896.83", "0"], ["83914.00", "0.034385"], ["83929.30", "0"], ["83938.41", "0.013838"], ["83954.89", "0"], ["83958.00", "0.001491"], ["83960.00", "0.003925"], ["83962.00", "0.010328"], ["83964.00", "0.027178"], ["83966.00", "0.071522"], ["83968.00", "0.188216"], ["83970.00", "0.495304"], ["83972.00", "1.303433"], ["83974.00", "3.430086"], ["83976.00", "9.026543"], ["83976.30", "0.298050"], ["83979.60", "1.257510"], ["83980.40", "1.430250"], ["83982.70", "0.035730"], ["83982.90", "2.359920"], ["83985.80", "0"], ["83986.90", "0"], ["84017.90", "5.264910"], ["84026.30", "5.537233"], ["84034.70", "4.266393"], ["84043.10", "3.994070"], ["84051.50", "5.174136"], ["84059.90", "4.811039"], ["84068.30", "4.992587"], ["84076.70", "3.903296"], ["84085.10", "4.720265"], ["84093.50", "4.175619"], ["84101.90", "4.084844"], ["84110.30", "4.447942"], ["84118.70", "5.446459"], ["84127.10", "5.628008"], ["84143.90", "4.538716"], ["84152.30", "4.357167"], ["84160.70", "5.355685"], ["84169.10", "4.629490"], ["84177.50", "5.083362"], ["84346.94", "0.000085"]], "bids": [["83896.82", "1.734588"], ["83895.90", "0.512480"], ["83893.90", "1.348631"], ["83891.90", "3.549029"], ["83891.80", "0.001032"], ["83891.60", "0.001032"], ["83891.40", "0"], ["83889.10", "0.420390"], ["83889.00", "0.829230"], ["83888.10", "0.066030"], ["83887.90", "0.161070"], ["83886.80", "0.053430"], ["83886.20", "0.239280"], ["83885.50", "0"], ["83883.80", "0"], ["83883.50", "0.009000"], ["83881.60", "1.104570"], ["83881.40", "0"], ["83878.60", "0"], ["83877.01", "0"], ["83850.00", "3.994070"], ["83841.60", "4.084844"], ["83833.20", "5.628008"], ["83824.80", "4.720265"], ["83816.40", "4.266393"], ["83808.00", "4.175619"], ["83791.20", "4.629490"], ["83782.80", "3.903296"], ["83774.40", "5.174136"], ["83766.00", "5.537233"], ["83757.60", "4.811039"], ["83749.20", "4.992587"], ["83740.80", "5.083362"], ["83732.40", "5.446459"], ["83724.00", "5.355685"], ["83715.60", "4.901813"], ["83707.20", "5.264910"], ["83698.80", "4.538716"], ["83690.40", "4.447942"], ["83455.56", "0.000025"], ["83455.07", "0.000013"]], "checksum": 813177350, "ts": "1742576770396"}], "ts": 1742576770400, "record_time": 1742576770.598173, "EXCHANGE": "BITGET"}
{"action": "update", "arg": {"instType": "SPOT", "channel": "books", "instId": "BTCUSDT"}, "data": [{"asks": [["83909.28", "0.091202"], ["83909.74", "0"], ["83919.40", "1.019197"], ["83921.22", "0.001376"], ["83954.89", "0.185125"], ["83982.70", "0"], ["83983.30", "0.426300"], ["83987.70", "0.261480"], ["84017.90", "4.084844"], ["84018.24", "0"], ["84026.30", "4.357167"], ["84034.70", "5.174136"], ["84041.48", "0.125872"], ["84043.10", "5.628008"], ["84051.50", "4.266393"], ["84059.90", "5.355685"], ["84068.30", "4.175619"], ["84076.70", "4.629490"], ["84085.10", "4.992587"], ["84093.50", "4.901813"], ["84101.90", "3.994070"], ["84110.30", "5.264910"], ["84118.70", "4.538716"], ["84127.10", "5.083362"], ["84135.50", "3.903296"], ["84143.90", "4.811039"], ["84152.30", "4.447942"], ["84160.70", "4.720265"], ["84169.10", "5.446459"], ["84177.50", "5.537233"], ["84345.79", "0"], ["84346.43", "0"], ["84346.94", "0"]], "bids": [["83896.83", "1.380348"], ["83896.82", "0.759560"], ["83896.81", "0.150118"], ["83895.91", "1.428758"], ["83893.91", "0"], ["83891.90", "3.549233"], ["83889.30", "0"], ["83888.10", "0.066240"], ["83886.80", "0.053100"], ["83881.60", "1.600170"], ["83878.60", "0.132540"], ["83850.00", "5.264910"], ["83833.20", "4.992587"], ["83824.80", "4.901813"], ["83816.40", "4.175619"], ["83808.00", "4.266393"], ["83799.60", "5.174136"], ["83791.20", "5.628008"], ["83782.80", "4.447942"], ["83774.40", "5.355685"], ["83766.00", "3.903296"], ["83757.60", "4.357167"], ["83749.20", "4.811039"], ["83740.80", "5.446459"], ["83732.40", "5.537233"], ["83724.00", "3.994070"], ["83715.60", "4.720265"], ["83707.20", "4.538716"], ["83698.80", "4.629490"], ["83690.40", "5.083362"], ["83455.07", "0"]], "checksum": 1271037844, "ts": "1742576770619"}], "ts": 1742576770622, "record_time": 1742576770.819511, "EXCHANGE": "BITGET"}
{"event": "subscribe", "arg": {"instType": "SPOT", "channel": "books", "instId": "BTCUSDT"}, "record_time": 1742576907.726983, "EXCHANGE": "BITGET"}
{"action": "snapshot", "arg": {"instType": "SPOT", "channel": "books", "instId": "BTCUSDT"}, "data": [{"asks": [["83919.34", "0.551763"], ["83919.35", "0.000100"], ["83919.36", "0.000100"], ["83919.37", "0.000100"], ["83919.89", "0.091662"], ["83925.42", "0.114350"], ["83927.33", "0.004587"], ["83929.78", "0.687075"], ["83929.79", "3.187517"], ["83931.52", "0.013830"], ["83934.00", "0.078797"], ["83934.01", "0.209200"], ["83940.00", "0.002000"], ["83940.27", "0.057591"], ["83940.87", "0.120500"], ["83940.88", "0.016429"], ["83941.07", "0.035971"], ["83941.29", "0.151918"], ["83941.59", "0.239806"], ["83942.61", "0.209200"], ["83942.76", "0.035972"], ["83944.19", "0.009990"], ["83944.70", "0.006357"], ["83944.72", "0.010995"], ["83944.80", "0.006357"], ["83944.85", "0.006357"], ["83945.16", "0.006357"], ["83945.28", "0.006357"], ["83945.81", "0.140489"], ["83945.82", "0.314612"], ["83945.85", "0.006357"], ["83946.34", "0.006357"], ["83946.62", "0.006356"], ["83946.75", "0.009989"], ["83947.02", "0.006357"], ["83947.20", "0.006357"], ["83947.30", "0.006357"], ["83947.31", "0.006357"], ["83947.82", "0.006357"], ["83948.06", "0.016429"], ["83948.20", "0.006357"], ["83948.78", "0.017480"], ["83948.87", "0.006357"], ["83949.39", "0.006357"], ["83949.73", "0.010993"], ["83950.56", "0.015896"], ["83950.88", "0.013838"], ["83951.00", "0.209200"], ["83951.14", "0.119905"], ["83951.39", "0.015895"], ["83951.41", "0.010988"], ["83951.49", "0.119850"], ["83952.49", "0.119858"], ["83954.89", "0.006356"], ["83957.32", "1.024710"], ["83957.33", "3.718770"], ["83963.00", "0.000976"], ["83966.71", "0.209200"], ["83967.70", "0.001045"], ["83969.70", "0.001042"], ["83970.00", "0.002000"], ["83971.70", "0.001162"], ["83972.48", "0.714519"], ["83973.70", "0.003058"], ["83975.70", "0.008047"], ["83977.70", "0.021176"], ["83979.70", "0.055726"], ["83979.85", "0.889478"], ["83980.71", "0.001598"], ["83981.70", "0.146647"], ["83982.00", "0.209200"], ["83982.55", "0.001598"], ["83983.70", "0.385915"], ["83985.70", "1.015566"], ["83987.70", "2.672690"], ["83988.70", "0.001002"], ["83989.20", "0.001027"], ["83989.70", "0.001028"], ["83990.00", "0.043200"], ["83990.30", "0.478110"], ["83991.00", "0.015000"], ["83991.20", "0.681570"], ["83991.50", "0.069150"], ["83991.60", "1.324230"], ["83992.00", "0.196628"], ["83992.20", "0.015180"], ["83992.50", "0.268650"], ["83993.00", "0.000087"], ["83993.01", "0.209200"], ["83993.60", "0.021600"], ["83993.70", "0.012240"], ["83993.90", "0.066420"], ["83994.20", "0.945510"], ["83994.50", "1.430250"], ["83994.80", "1.787820"], ["83995.70", "0.009000"], ["83996.10", "2.537310"], ["83996.40", "0.493590"], ["83996.44", "0.010010"], ["83996.50", "0.120000"], ["83996.80", "0.072600"], ["83996.90", "1.430250"], ["83997.00", "0.288000"], ["83997.90", "0.090000"], ["83998.20", "0.536970"], ["83998.36", "1.785749"], ["83999.00", "0.000315"], ["84000.00", "0.002000"], ["84001.40", "0.209200"], ["84007.39", "0.000179"], ["84009.92", "0.001810"], ["84018.98", "0.003620"], ["84025.82", "0.209200"], ["84029.60", "5.354940"], ["84030.00", "0.002000"], ["84034.42", "0.209200"], ["84036.49", "0.125846"], ["84038.00", "4.538084"], ["84042.62", "0.057335"], ["84042.82", "0.209200"], ["84046.40", "5.445701"], ["84048.35", "0.071668"], ["84050.00", "0.000694"], ["84050.16", "0.071678"], ["84052.01", "0.209200"], ["84054.80", "4.175038"], ["84060.00", "0.002000"], ["84063.20", "5.173416"], ["84063.21", "0.209200"], ["84070.00", "0.001279"], ["84070.10", "0.001450"], ["84071.60", "5.536463"], ["84072.80", "0.209200"], ["84073.70", "0.296078"], ["84080.00", "4.084276"], ["84081.19", "0.209200"], ["84081.60", "0.000027"], ["84082.46", "0.027677"], ["84088.40", "4.991893"], ["84090.00", "0.002000"], ["84092.11", "0.209200"], ["84096.80", "5.264178"], ["84100.00", "0.014914"], ["84100.40", "0.001450"], ["84101.11", "0.209200"], ["84105.20", "5.627225"], ["84113.60", "4.356561"], ["84114.71", "0.203800"], ["84120.00", "0.002000"], ["84120.31", "0.000018"], ["84120.42", "0.000008"], ["84121.21", "0.000010"], ["84121.90", "0.000124"], ["84121.93", "0.000069"], ["84122.00", "4.810369"], ["84122.10", "0.000042"], ["84122.11", "0.000023"], ["84124.00", "0.000175"], ["84124.14", "0.000135"], ["84124.65", "0.000066"], ["84124.67", "0.163879"], ["84125.00", "0.007748"], ["84125.55", "0.209200"], ["84126.51", "0.000008"], ["84127.27", "0.000010"], ["84128.44", "0.000072"], ["84129.03", "0.000008"], ["84129.07", "0.000020"], ["84130.00", "0.060049"], ["84130.40", "3.993514"], ["84130.43", "0.003446"], ["84132.13", "0.000176"], ["84132.80", "0.000008"], ["84132.97", "0.000104"], ["84133.33", "0.002817"], ["84133.94", "0.209200"], ["84136.28", "0.000011"], ["84137.93", "0.000024"], ["84138.74", "0.000024"], ["84138.80", "3.902753"], ["84139.60", "0.001444"], ["84139.90", "0.000023"], ["84140.00", "0.000630"], ["84140.96", "0.000013"], ["84141.97", "0.000423"], ["84142.33", "0.209200"], ["84142.86", "0.042208"], ["84144.14", "0.000061"], ["84144.15", "0.000053"], ["84144.74", "0.000093"], ["84147.20", "4.628846"], ["84148.30", "0.000060"], ["84148.94", "0.000137"], ["84148.96", "0.000039"], ["84149.00", "0.301368"], ["84150.00", "0.002747"], ["84150.08", "0.000019"], ["84150.33", "0.000008"], ["84150.72", "0.209200"], ["84151.59", "0.000020"], ["84151.79", "0.000036"], ["84152.17", "0.000010"], ["84153.84", "0.000008"], ["84153.85", "0.000023"], ["84155.60", "4.719608"], ["84155.83", "0.000019"], ["84156.01", "0.000019"], ["84157.89", "0.000183"], ["84159.01", "0.000149"], ["84159.09", "0.000042"], ["84159.11", "0.209200"], ["84159.59", "0.000036"], ["84159.60", "0.300112"], ["84159.62", "0.000099"], ["84160.00", "0.001138"], ["84160.59", "0.001720"], ["84160.71", "0.000016"], ["84162.16", "0.000009"], ["84162.50", "0.000031"], ["84163.18", "0.000050"], ["84163.64", "0.000008"], ["84163.92", "0.000010"], ["84164.00", "4.901131"], ["84164.43", "0.011010"], ["84165.59", "0.000054"], ["84166.55", "0.000008"], ["84166.67", "0.000699"], ["84166.69", "0.000010"], ["84166.71", "0.000008"], ["84167.50", "0.209200"], ["84168.50", "0.000008"], ["84169.49", "0.001213"], ["84170.00", "0.000725"], ["84170.25", "0.000143"], ["84170.47", "0.000013"], ["84170.56", "0.000009"], ["84171.43", "0.000016"], ["84172.40", "4.447323"], ["84173.62", "0.000024"], ["84173.91", "0.000020"], ["84174.51", "0.000388"], ["84174.57", "0.000010"], ["84174.61", "0.000043"], ["84175.73", "0.000010"], ["84175.89", "0.209200"], ["84176.47", "0.000040"], ["84177.20", "0.000064"], ["84179.10", "0.000008"], ["84180.00", "0.002639"], ["84180.09", "0.000033"], ["84180.80", "5.082654"], ["84181.09", "0.000030"], ["84181.81", "0.001547"], ["84181.82", "0.000060"], ["84182.16", "0.000048"], ["84182.69", "0.000067"], ["84183.27", "0.000009"], ["84183.50", "0.000113"], ["84183.67", "0.000010"], ["84184.17", "0.000009"], ["84184.29", "0.209200"], ["84188.89", "0.000025"], ["84189.20", "4.265799"], ["84189.33", "0.000133"], ["84189.45", "0.000023"], ["84190.00", "0.000670"], ["84191.18", "0.000041"], ["84192.12", "0.000288"], ["84192.69", "0.209200"], ["84192.98", "0.000033"], ["84193.22", "0.000023"], ["84193.77", "0.000012"], ["84193.99", "0.000209"], ["84194.12", "0.000071"], ["84195.96", "0.000038"], ["84196.77", "0.000020"], ["84197.27", "0.000016"], ["84198.00", "0.001012"], ["84198.35", "0.000057"], ["84198.45", "0.000008"], ["84200.00", "0.013254"], ["84200.01", "0.000246"], ["84203.00", "0.000008"], ["84203.59", "0.000061"], ["84204.08", "0.000184"], ["84205.61", "0.000034"], ["84205.79", "0.000135"], ["84205.88", "0.000080"], ["84206.90", "0.000008"], ["84207.14", "0.000128"], ["84207.69", "0.000009"], ["84208.00", "0.000012"], ["84209.48", "0.000013"], ["84209.68", "0.000019"], ["84209.82", "0.000047"], ["84210.00", "0.002618"], ["84210.53", "0.000009"], ["84212.00", "0.000012"], ["84212.47", "0.000009"], ["84212.50", "0.006969"], ["84214.29", "0.000033"], ["84214.88", "0.000161"], ["84215.69", "0.000008"], ["84216.22", "0.000008"], ["84216.67", "0.000970"], ["84216.87", "0.000008"], ["84217.48", "0.000095"], ["84217.86", "0.000273"], ["84219.35", "0.000008"], ["84219.55", "0.000349"], ["84220.00", "0.000618"], ["84220.69", "0.000135"], ["84222.00", "0.000081"], ["84222.03", "0.000013"], ["84222.22", "0.000907"], ["84223.05", "0.000039"], ["84223.65", "0.000178"], ["84223.89", "0.000008"], ["84224.11", "0.000277"], ["84224.14", "0.000016"], ["84224.62", "0.000022"], ["84225.00", "0.000107"], ["84225.86", "0.007944"], ["84225.88", "0.000024"], ["84226.09", "0.000013"], ["84226.42", "0.000096"], ["84228.57", "0.000013"], ["84228.72", "0.000188"], ["84229.07", "0.000010"], ["84229.39", "0.000020"], ["84230.00", "0.000640"], ["84230.76", "0.000008"], ["84230.77", "0.000111"], ["84232.69", "0.000066"], ["84233.16", "0.000023"], ["84233.34", "0.000119"], ["84233.38", "0.001273"], ["84233.43", "0.000015"], ["84233.87", "0.000039"], ["84234.04", "0.000137"], ["84234.07", "0.000039"], ["84234.23", "0.000698"], ["84235.23", "0.000051"], ["84235.29", "0.042045"], ["84235.93", "0.000046"], ["84238.10", "0.000024"], ["84238.53", "0.000072"], ["84238.89", "0.000134"], ["84239.00", "0.000240"], ["84239.11", "0.000011"], ["84239.13", "0.000010"], ["84240.00", "0.003183"], ["84242.34", "0.000423"], ["84242.60", "0.000537"], ["84244.90", "0.000085"], ["84246.15", "0.000015"], ["84249.42", "0.000030"], ["84250.00", "0.067266"], ["84251.44", "0.000011"], ["84252.44", "0.000143"], ["84252.50", "0.000025"], ["84254.39", "0.000022"], ["84254.55", "0.000009"], ["84255.35", "0.000143"], ["84256.00", "0.000022"], ["84256.79", "0.000314"], ["84257.14", "0.000145"], ["84258.91", "0.000036"], ["84259.12", "0.000009"], ["84259.87", "0.000093"], ["84259.99", "0.000017"], ["84260.00", "0.000676"], ["84260.87", "0.000008"], ["84263.15", "0.000019"], ["84263.16", "0.000183"], ["84264.71", "0.000009"], ["84266.08", "0.000016"], ["84266.67", "0.002976"], ["84267.78", "0.000010"], ["84268.56", "0.000013"], ["84269.24", "0.000032"], ["84270.00", "0.002641"], ["84270.27", "0.000009"], ["84270.80", "0.000018"], ["84270.96", "0.000055"], ["84270.98", "0.000052"], ["84271.10", "0.000019"], ["84271.34", "0.000026"], ["84272.72", "0.000105"], ["84272.73", "0.000492"], ["84273.33", "0.000013"], ["84276.28", "0.000009"], ["84277.78", "0.000011"], ["84278.24", "0.000050"], ["84278.38", "0.000199"], ["84279.36", "0.000009"], ["84279.98", "0.000239"], ["84280.00", "0.001334"], ["84280.70", "0.000033"], ["84280.74", "0.000047"], ["84281.43", "1.665360"], ["84281.69", "0.000099"], ["84282.35", "0.000071"], ["84282.39", "0.000135"], ["84282.82", "0.000012"], ["84283.33", "0.000010"], ["84283.87", "0.000020"], ["84285.00", "0.000031"], ["84285.68", "0.000178"], ["84285.71", "0.000347"], ["84285.95", "0.000028"], ["84286.00", "0.000119"], ["84286.67", "0.000009"], ["84286.73", "0.000057"], ["84286.79", "0.000016"], ["84287.50", "0.000076"], ["84288.00", "0.003000"], ["84288.89", "0.000361"], ["84289.58", "0.000008"], ["84290.00", "0.000617"], ["84293.56", "0.000063"], ["84294.12", "0.000080"], ["84294.20", "0.000128"], ["84294.68", "0.000019"], ["84296.87", "0.000014"], ["84297.06", "0.000035"], ["84298.07", "0.000811"], ["84298.31", "0.000023"], ["84298.41", "0.000009"], ["84298.64", "0.000088"], ["84300.00", "0.023791"], ["84301.40", "0.000023"], ["84301.47", "0.000041"], ["84302.88", "0.000067"], ["84303.00", "0.296549"], ["84306.66", "0.000145"], ["84307.00", "0.000113"], ["84307.23", "0.000008"], ["84309.09", "0.000010"], ["84309.60", "0.002450"], ["84309.68", "0.000062"], ["84309.96", "0.000011"], ["84310.00", "0.000348"], ["84310.34", "0.000331"], ["84310.35", "0.000146"], ["84311.11", "0.000025"], ["84311.16", "0.000008"], ["84311.31", "0.002260"], ["84311.72", "0.000013"], ["84312.50", "0.000125"], ["84313.03", "0.000024"], ["84314.97", "0.000008"], ["84315.74", "0.000051"], ["84316.67", "0.000322"], ["84317.24", "0.000135"], ["84317.40", "0.000010"], ["84318.18", "0.000012"], ["84318.59", "0.000027"], ["84319.15", "0.000137"], ["84319.18", "0.000039"], ["84320.00", "0.000019"], ["84321.87", "0.000919"], ["84322.11", "0.000008"], ["84324.32", "0.000069"], ["84325.00", "0.000128"], ["84325.07", "0.000161"], ["84326.09", "0.000010"], ["84326.42", "0.000023"], ["84327.14", "0.000039"], ["84327.73", "0.041940"], ["84328.95", "0.000174"], ["84329.64", "0.000026"], ["84330.00", "0.002000"], ["84332.00", "0.511323"], ["84332.56", "0.000009"], ["84333.32", "0.000047"], ["84333.33", "0.003953"], ["84333.36", "0.000010"], ["84333.38", "0.000008"], ["84334.48", "0.000096"], ["84334.77", "0.000022"], ["84336.00", "0.000133"], ["84336.23", "0.000013"], ["84336.29", "0.000010"], ["84336.34", "0.000176"], ["84337.25", "0.000067"], ["84337.35", "0.000008"], ["84337.50", "0.000010"], ["84338.26", "0.000023"], ["84338.46", "0.000015"], ["84339.21", "0.000010"], ["84339.29", "0.000029"], ["84339.50", "0.000323"], ["84339.62", "0.000051"], ["84340.00", "0.018287"], ["84340.46", "0.000143"], ["84340.72", "0.000066"], ["84341.00", "0.002997"], ["84341.01", "0.000008"], ["84342.11", "0.000051"]], "bids": [["83919.33", "1.330684"], ["83917.62", "0.043978"], ["83917.61", "0.114348"], ["83917.60", "0.010808"], ["83916.74", "0.007599"], ["83915.60", "0.028609"], ["83913.60", "0.075287"], ["83911.94", "0.146364"], ["83911.93", "0.209200"], ["83911.92", "0.014564"], ["83911.90", "0.215477"], ["83911.86", "0.009906"], ["83911.60", "0.198125"], ["83910.00", "0.000017"], ["83909.61", "0.528590"], ["83909.60", "0.521381"], ["83909.00", "0.000017"], ["83908.90", "0.204856"], ["83908.00", "0.000017"], ["83907.60", "1.372056"], ["83907.00", "0.000017"], ["83906.00", "0.000017"], ["83905.61", "1.141074"], ["83905.60", "3.610674"], ["83905.43", "0.764670"], ["83905.00", "0.000017"], ["83904.00", "0.000017"], ["83903.83", "0.000385"], ["83903.60", "9.501773"], ["83903.50", "0.001013"], ["83903.20", "0.001033"], ["83903.00", "0.000032"], ["83902.80", "0.754830"], ["83902.70", "2.586480"], ["83902.51", "0.024948"], ["83902.30", "0.006060"], ["83902.20", "0.030210"], ["83902.00", "0.042300"], ["83901.80", "0.030000"], ["83901.70", "0.180000"], ["83901.10", "0.099180"], ["83901.00", "0.071130"], ["83900.79", "0.089680"], ["83900.47", "0.247561"], ["83900.30", "0.022680"], ["83900.22", "0.017828"], ["83900.03", "0.018274"], ["83900.00", "0.042300"], ["83899.80", "0.074040"], ["83899.67", "0.008280"], ["83899.31", "0.005950"], ["83899.12", "0.083643"], ["83899.10", "1.107960"], ["83899.00", "0.015783"], ["83898.78", "0.016434"], ["83898.76", "0.314632"], ["83898.45", "0.017125"], ["83898.35", "0.006572"], ["83898.01", "0.008074"], ["83898.00", "0.042480"], ["83897.84", "0.007141"], ["83897.68", "0.007347"], ["83897.50", "0.120000"], ["83897.17", "0.017116"], ["83897.05", "0.055641"], ["83897.00", "0.000032"], ["83896.87", "0.025198"], ["83896.83", "0.209200"], ["83896.79", "0.007956"], ["83896.78", "0.009011"], ["83896.68", "0.008201"], ["83896.30", "0.120000"], ["83896.29", "0.017378"], ["83896.20", "0.269760"], ["83896.17", "0.007830"], ["83896.09", "0.017830"], ["83896.08", "0.009805"], ["83896.04", "0.007389"], ["83896.01", "0.007781"], ["83896.00", "0.042300"], ["83895.95", "0.006978"], ["83895.94", "0.009326"], ["83895.80", "0.120000"], ["83895.47", "0.006219"], ["83895.33", "0.008290"], ["83895.21", "0.017250"], ["83895.20", "0.525300"], ["83895.18", "0.051846"], ["83895.00", "0.240000"], ["83894.90", "3.637410"], ["83894.84", "0.012675"], ["83894.50", "0.545760"], ["83894.00", "0.144600"], ["83893.90", "0.120000"], ["83893.83", "0.007203"], ["83893.82", "0.008605"], ["83893.76", "0.008483"], ["83893.74", "0.012263"], ["83893.73", "0.017291"], ["83893.72", "0.001952"], ["83893.70", "0.008530"], ["83893.67", "0.006599"], ["83893.66", "0.005601"], ["83893.65", "0.009424"], ["83893.64", "0.010064"], ["83893.41", "0.268840"], ["83893.20", "1.225394"], ["83893.10", "0.240390"], ["83893.00", "0.000032"], ["83892.90", "2.574630"], ["83892.40", "0.223054"], ["83892.00", "0.000032"], ["83891.37", "0.028877"], ["83891.00", "0.000032"], ["83890.72", "0.259231"], ["83890.46", "0.076250"], ["83890.40", "0.225065"], ["83890.31", "0.004037"], ["83890.00", "0.000032"], ["83889.60", "0.012460"], ["83889.53", "0.024893"], ["83889.00", "0.000032"], ["83888.92", "0.008316"], ["83888.91", "0.008556"], ["83888.90", "0.008109"], ["83888.89", "0.005129"], ["83888.86", "0.005612"], ["83888.83", "0.010042"], ["83888.81", "0.005062"], ["83888.00", "0.000032"], ["83887.96", "0.018550"], ["83887.00", "0.000032"], ["83886.64", "0.008934"], ["83886.62", "0.010362"], ["83886.55", "0.008778"], ["83886.00", "0.000032"], ["83885.78", "0.715258"], ["83885.49", "0.021168"], ["83885.00", "0.000032"], ["83884.00", "0.000032"], ["83883.32", "0.017480"], ["83883.00", "0.000032"], ["83882.00", "0.000032"], ["83881.74", "0.073191"], ["83881.03", "0.209200"], ["83881.00", "0.000032"], ["83880.92", "0.056469"], ["83880.00", "0.002032"], ["83879.27", "0.000200"], ["83879.00", "0.000032"], ["83878.00", "0.000032"], ["83877.00", "0.000032"], ["83876.84", "0.000879"], ["83876.00", "0.000032"], ["83875.00", "0.000032"], ["83874.00", "0.000032"], ["83873.22", "0.007448"], ["83873.00", "0.000032"], ["83872.28", "0.209200"], ["83872.00", "0.000032"], ["83871.00", "0.000032"], ["83870.60", "0.001177"], ["83870.25", "0.008588"], ["83870.00", "0.000032"], ["83869.00", "0.000032"], ["83868.58", "0.001174"], ["83868.00", "0.000032"], ["83867.00", "0.000032"], ["83866.00", "0.000032"], ["83865.24", "0.007666"], ["83865.17", "0.007261"], ["83865.00", "0.000032"], ["83864.00", "0.000032"], ["83863.73", "0.007350"], ["83863.45", "0.209200"], ["83863.00", "0.000032"], ["83862.00", "0.000032"], ["83861.70", "4.084276"], ["83861.00", "0.000032"], ["83860.00", "0.000017"], ["83859.00", "0.000015"], ["83858.70", "0.000061"], ["83858.30", "0.003603"], ["83853.30", "4.810369"], ["83852.04", "0.071668"], ["83851.68", "0.209200"], ["83850.00", "0.002000"], ["83844.90", "4.265799"], ["83844.43", "0.000100"], ["83844.00", "0.000971"], ["83843.28", "0.209200"], ["83839.90", "0.071678"], ["83837.90", "0.000172"], ["83836.50", "5.173416"], ["83835.14", "0.057335"], ["83831.87", "0.209200"], ["83828.10", "4.991893"], ["83823.74", "0.001810"], ["83823.46", "0.209200"], ["83820.00", "0.007600"], ["83819.70", "3.993514"], ["83815.37", "0.000022"], ["83815.36", "0.003620"], ["83815.06", "0.209200"], ["83811.30", "4.447323"], ["83810.00", "0.000270"], ["83806.66", "0.209200"], ["83802.90", "4.175038"], ["83802.81", "0.000022"], ["83801.90", "0.304409"], ["83800.00", "0.000387"], ["83799.69", "0.012389"], ["83798.26", "0.209200"], ["83797.94", "0.012393"], ["83797.31", "0.125846"], ["83794.50", "3.902753"], ["83790.00", "0.002270"], ["83789.86", "0.209200"], ["83786.10", "4.628846"], ["83780.00", "0.000270"], ["83779.93", "0.000028"], ["83777.70", "5.082654"], ["83773.31", "0.000154"], ["83770.00", "0.000270"], ["83769.30", "4.901131"], ["83767.90", "0.001457"], ["83762.50", "0.000076"], ["83760.90", "5.536463"], ["83760.00", "0.002281"], ["83754.70", "0.000013"], ["83752.50", "4.719608"], ["83751.34", "0.000487"], ["83750.67", "0.000146"], ["83750.00", "0.000270"], ["83749.66", "0.000016"], ["83749.50", "0.000069"], ["83745.16", "0.000389"], ["83744.10", "5.264178"], ["83744.00", "0.001184"], ["83740.00", "0.000322"], ["83737.00", "0.000009"], ["83735.70", "4.538084"], ["83730.00", "0.002270"], ["83729.32", "0.000035"], ["83728.57", "0.000017"], ["83728.37", "0.001273"], ["83727.30", "4.356561"], ["83727.27", "0.000066"], ["83726.20", "0.000016"], ["83723.40", "0.000068"], ["83720.00", "0.002671"], ["83718.90", "5.354940"], ["83717.48", "0.005970"], ["83713.71", "0.000323"], ["83712.30", "0.011010"], ["83710.50", "5.627225"], ["83710.27", "0.001720"], ["83710.00", "0.000293"], ["83705.85", "0.000019"], ["83703.70", "0.000425"], ["83702.50", "0.000033"], ["83702.10", "5.445701"], ["83701.28", "0.000248"], ["83700.80", "0.311180"], ["83700.00", "0.004213"], ["83695.89", "0.027677"], ["83690.84", "0.000162"], ["83690.00", "0.000270"], ["83689.50", "0.000113"], ["83687.50", "0.006969"], ["83687.00", "0.000008"], ["83686.11", "0.000096"], ["83686.07", "0.005970"], ["83680.00", "0.000368"], ["83677.37", "0.000008"], ["83676.47", "0.000080"], ["83675.68", "0.000008"], ["83675.00", "0.000076"], ["83674.19", "0.000020"], ["83673.87", "0.000022"], ["83672.50", "0.000031"], ["83670.05", "0.000033"], ["83670.00", "0.002270"], ["83669.66", "0.000010"], ["83669.09", "0.000135"], ["83668.70", "0.001434"], ["83667.23", "0.012503"], ["83666.67", "0.000146"], ["83664.71", "0.000071"], ["83663.91", "0.000161"], ["83662.97", "0.000149"], ["83660.14", "0.000016"], ["83660.00", "0.000270"], ["83659.60", "0.000143"], ["83659.49", "0.000012"], ["83654.23", "0.000009"], ["83650.00", "0.000353"], ["83648.40", "0.001485"], ["83646.67", "0.000018"], ["83642.10", "0.305869"], ["83640.35", "0.000022"], ["83640.00", "0.003066"], ["83639.71", "0.000041"], ["83639.15", "0.000009"], ["83638.32", "0.000039"], ["83638.30", "0.000137"], ["83637.17", "0.000027"], ["83636.36", "0.041598"], ["83633.33", "0.000970"], ["83631.53", "0.000009"], ["83630.43", "0.000010"], ["83630.00", "0.000619"], ["83629.03", "0.000039"], ["83629.02", "0.000078"], ["83625.00", "0.000356"], ["83623.43", "0.000010"], ["83621.62", "0.000009"], ["83620.70", "0.000146"], ["83620.69", "0.000016"], ["83620.00", "0.000667"], ["83619.21", "0.000051"], ["83618.18", "0.000008"], ["83617.90", "0.000364"], ["83616.67", "0.000322"], ["83615.85", "0.000024"], ["83611.93", "0.000028"], ["83610.00", "0.002619"], ["83609.86", "1.652639"], ["83608.30", "0.493274"], ["83607.60", "0.000014"], ["83603.60", "0.000061"], ["83603.26", "0.000010"], ["83602.67", "0.000133"], ["83600.00", "0.015433"], ["83598.51", "0.000039"], ["83596.01", "0.000013"], ["83594.44", "0.000134"], ["83593.33", "0.000013"], ["83590.00", "0.000619"], ["83588.24", "0.042020"], ["83587.50", "0.000076"], ["83587.10", "0.000028"], ["83586.96", "0.002633"], ["83586.29", "0.000008"], ["83584.53", "0.000314"], ["83584.34", "0.000008"], ["83584.00", "0.000022"], ["83583.85", "0.000052"], ["83583.33", "0.000010"], ["83581.82", "0.000010"], ["83581.73", "0.000067"], ["83581.30", "0.001130"], ["83580.56", "0.000019"], ["83580.35", "0.004656"], ["83580.31", "0.000023"], ["83580.00", "0.002642"], ["83578.95", "0.000033"], ["83578.04", "0.000096"], ["83577.78", "0.000025"], ["83576.47", "0.000071"], ["83576.25", "0.001539"], ["83574.50", "0.000143"], ["83571.43", "0.000104"], ["83571.42", "0.000008"], ["83570.62", "0.000016"], ["83570.45", "0.000012"], ["83570.00", "0.000678"], ["83569.08", "0.000093"], ["83568.28", "0.000010"], ["83567.57", "0.000008"], ["83566.00", "0.000113"], ["83565.22", "0.000021"], ["83563.71", "0.000022"], ["83562.71", "0.000023"], ["83562.50", "0.000761"], ["83560.71", "0.001273"], ["83560.00", "0.000950"], ["83558.43", "0.000019"], ["83558.00", "0.000008"], ["83556.15", "0.000024"], ["83555.56", "0.000105"], ["83555.38", "0.000013"], ["83553.72", "0.000161"], ["83553.21", "0.000039"], ["83553.19", "0.000137"], ["83552.63", "0.000051"], ["83551.42", "0.000017"], ["83550.58", "0.000009"], ["83550.00", "0.002749"], ["83546.24", "0.000016"], ["83545.82", "0.000009"], ["83545.45", "0.000113"], ["83544.88", "0.011010"], ["83544.83", "0.000135"], ["83544.33", "0.000008"], ["83543.48", "0.000010"], ["83542.86", "0.000013"], ["83540.93", "0.000035"], ["83540.15", "0.000014"], ["83540.00", "0.000631"], ["83539.78", "0.000423"], ["83539.45", "0.000033"], ["83539.43", "0.000009"], ["83537.50", "0.000016"], ["83537.23", "0.000188"], ["83535.71", "0.000016"], ["83534.48", "0.000016"], ["83533.68", "0.000144"], ["83533.33", "0.000151"], ["83532.05", "0.000364"], ["83532.00", "0.002409"], ["83531.38", "0.000010"], ["83531.31", "0.000390"], ["83530.61", "0.000085"], ["83530.39", "0.000043"], ["83530.00", "0.000654"], ["83529.41", "0.000085"], ["83528.71", "0.000024"], ["83528.11", "0.000179"], ["83527.05", "0.000008"], ["83526.32", "0.000183"], ["83523.81", "0.000009"], ["83523.06", "0.000022"], ["83521.43", "0.000273"], ["83521.12", "0.000022"], ["83520.00", "0.003225"], ["83519.52", "0.000176"], ["83516.67", "0.000970"], ["83514.80", "0.000537"], ["83514.29", "0.000009"], ["83513.51", "0.000070"], ["83512.50", "0.006969"], ["83511.11", "0.000009"], ["83510.71", "0.000128"], ["83510.49", "0.000019"], ["83509.09", "0.000008"], ["83508.29", "0.000015"], ["83508.06", "0.000039"], ["83507.69", "0.000015"], ["83507.21", "0.000297"], ["83506.49", "0.000088"], ["83505.74", "0.000315"], ["83502.04", "0.000016"], ["83500.72", "0.000033"], ["83500.04", "0.000008"], ["83500.02", "0.000010"], ["83500.01", "0.000119"], ["83500.00", "0.015549"], ["83499.14", "0.000051"], ["83498.85", "0.000030"], ["83498.52", "0.000013"], ["83497.26", "0.000010"], ["83496.77", "0.000008"], ["83496.48", "0.000008"], ["83495.80", "0.041940"], ["83495.20", "0.000008"], ["83494.42", "0.000039"], ["83493.98", "0.000008"], ["83493.77", "0.000013"], ["83491.92", "0.000009"], ["83491.23", "0.000033"], ["83490.00", "0.002000"], ["83489.39", "0.000143"], ["83488.85", "0.000459"], ["83488.30", "0.000065"], ["83488.24", "0.000071"], ["83487.05", "0.000023"], ["83486.67", "0.000008"], ["83486.37", "0.000008"], ["83485.71", "0.000016"], ["83485.00", "0.000012"], ["83483.48", "0.000424"], ["83482.76", "0.000008"], ["83482.35", "0.000105"], ["83481.47", "0.000219"], ["83481.40", "0.000012"], ["83481.09", "0.000016"], ["83480.00", "0.000021"], ["83478.26", "0.016818"], ["83477.27", "0.000042"], ["83476.45", "0.000067"], ["83476.19", "0.000024"], ["83474.95", "0.000026"], ["83474.17", "0.000460"], ["83473.68", "0.000242"], ["83472.80", "0.000050"], ["83472.51", "0.000063"], ["83472.00", "0.000012"], ["83470.00", "0.000052"], ["83469.98", "0.000096"], ["83468.61", "0.000061"], ["83468.10", "0.000039"], ["83468.09", "0.000137"], ["83467.89", "0.000072"], ["83466.67", "0.002827"], ["83465.47", "0.000019"], ["83464.91", "0.000022"], ["83464.65", "0.000135"], ["83464.29", "0.000036"], ["83463.89", "0.000026"]], "checksum": 0, "ts": "1742576907326"}], "ts": 1742576907532, "record_time": 1742576907.776086, "EXCHANGE": "BITGET"}
{"action": "update", "arg": {"instType": "SPOT", "channel": "books", "instId": "BTCUSDT"}, "data": [{"asks": [["83919.89", "0"], ["83971.70", "0.001005"], ["83973.70", "0.002448"], ["83975.48", "0.010000"], ["83975.70", "0.006444"], ["83977.70", "0.016957"], ["83979.70", "0.044625"], ["83981.70", "0.117432"], ["83983.70", "0.308839"], ["83985.70", "0.812735"], ["83987.70", "2.138777"], ["83990.30", "0.478320"], ["83991.00", "0"], ["83991.80", "0.015000"], ["84029.60", "5.445701"], ["84038.00", "4.991893"], ["84046.40", "4.447323"], ["84054.79", "0.044747"], ["84054.80", "4.356561"], ["84071.60", "5.264178"], ["84088.40", "4.719608"], ["84096.80", "5.536463"], ["84100.00", "0"], ["84105.20", "4.810369"], ["84113.60", "4.175038"], ["84122.00", "5.354940"], ["84130.40", "4.538084"], ["84138.80", "5.627225"], ["84147.20", "5.082654"], ["84155.60", "3.902753"], ["84164.00", "4.265799"], ["84172.40", "3.993514"], ["84180.80", "4.901131"], ["84189.20", "4.628846"]], "bids": [["83917.60", "0.010193"], ["83915.60", "0.026824"], ["83913.60", "0.070589"], ["83911.60", "0.185761"], ["83909.60", "0.488844"], ["83907.60", "1.286431"], ["83905.60", "3.385346"], ["83903.60", "8.908805"], ["83902.00", "0.042480"], ["83893.20", "1.430250"], ["83861.70", "4.810369"], ["83853.30", "5.536463"], ["83844.90", "5.354940"], ["83836.50", "4.175038"], ["83828.10", "4.538084"], ["83819.70", "4.084276"], ["83811.30", "4.991893"], ["83802.90", "4.628846"], ["83794.50", "4.356561"], ["83786.10", "4.901131"], ["83777.70", "5.627225"], ["83769.30", "4.265799"], ["83760.90", "4.719608"], ["83752.50", "5.264178"], ["83744.10", "5.173416"], ["83735.70", "5.082654"], ["83727.30", "3.902753"], ["83718.90", "4.447323"], ["83710.50", "3.993514"]], "checksum": -1697193227, "ts": "1742576907539"}], "ts": 1742576907541, "record_time": 1742576907.778087, "EXCHANGE": "BITGET"}
{"action": "update", "arg": {"instType": "SPOT", "channel": "books", "instId": "BTCUSDT"}, "data": [{"asks": [["83919.34", "0.551411"], ["83919.87", "0.091662"], ["83958.99", "0.183063"], ["83987.70", "2.138907"], ["83989.30", "0.424410"], ["83989.70", "0"], ["83990.00", "0.042990"], ["83990.30", "0.778230"], ["83991.60", "1.324050"], ["83998.20", "0"], ["84029.60", "4.265799"], ["84038.00", "4.175038"], ["84046.40", "4.810369"], ["84054.80", "5.264178"], ["84063.20", "5.082654"], ["84071.60", "4.901131"], ["84080.00", "4.719608"], ["84088.40", "3.902753"], ["84096.80", "4.628846"], ["84104.00", "0.001184"], ["84105.20", "5.173416"], ["84113.60", "4.538084"], ["84122.00", "5.627225"], ["84130.40", "5.536463"], ["84138.80", "3.993514"], ["84147.20", "5.354940"], ["84155.60", "5.445701"], ["84164.00", "4.084276"], ["84172.40", "4.991893"], ["84180.80", "4.447323"], ["84189.20", "4.356561"], ["84341.01", "0"], ["84342.11", "0"]], "bids": [["83919.33", "1.350517"], ["83917.60", "0.008188"], ["83915.60", "0.021549"], ["83913.60", "0.056706"], ["83911.60", "0.149227"], ["83909.60", "0.392704"], ["83907.60", "1.033431"], ["83905.60", "2.719554"], ["83903.60", "7.156722"], ["83861.70", "3.902753"], ["83861.00", "0.000015"], ["83859.00", "0"], ["83853.30", "5.627225"], ["83844.90", "5.082654"], ["83836.50", "5.173416"], ["83828.10", "4.447323"], ["83819.70", "5.264178"], ["83811.30", "4.538084"], ["83802.90", "4.719608"], ["83794.50", "5.354940"], ["83786.10", "4.810369"], ["83777.70", "5.445701"], ["83760.90", "4.901131"], ["83752.50", "4.991893"], ["83744.10", "4.628846"], ["83735.70", "4.175038"], ["83727.30", "4.084276"], ["83718.90", "4.356561"], ["83702.10", "5.536463"], ["83462.50", "0.000025"]], "checksum": -122109119, "ts": "1742576907739"}], "ts": 1742576907743, "record_time": 1742576907.938527, "EXCHANGE": "BITGET"}
{"action": "update", "arg": {"instType": "SPOT", "channel": "books", "instId": "BTCUSDT"}, "data": [{"asks": [["83940.88", "0"], ["83941.59", "0.119905"], ["83944.19", "0"], ["83946.24", "0.016429"], ["83946.75", "0"], ["83946.97", "0.119901"], ["83949.55", "0.009990"], ["83950.56", "0"], ["83951.41", "0"], ["83952.11", "0.009989"], ["83955.91", "0.015896"], ["83957.14", "0.010988"], ["83996.10", "1.187310"], ["83998.20", "0.536970"], ["84029.60", "4.991893"], ["84038.00", "5.082654"], ["84046.40", "4.538084"], ["84054.80", "4.356561"], ["84063.20", "5.445701"], ["84071.60", "4.175038"], ["84080.00", "5.354940"], ["84096.80", "5.264178"], ["84105.20", "4.901131"], ["84113.60", "3.993514"], ["84130.40", "4.447323"], ["84138.80", "4.810369"], ["84147.20", "4.084276"], ["84155.60", "4.719608"], ["84164.00", "5.173416"], ["84172.40", "4.265799"], ["84180.80", "4.628846"], ["84189.20", "5.536463"], ["84340.72", "0"], ["84341.00", "0"]], "bids": [["83919.33", "1.379102"], ["83917.60", "0.008514"], ["83915.60", "0.022407"], ["83913.60", "0.058966"], ["83911.60", "0.155172"], ["83909.60", "0.408349"], ["83907.60", "1.074602"], ["83905.60", "2.827900"], ["83903.60", "7.441841"], ["83897.98", "0.004036"], ["83896.73", "0.028874"], ["83895.78", "0.225045"], ["83893.32", "0.018549"], ["83891.37", "0"], ["83890.85", "0.021166"], ["83890.40", "0"], ["83890.31", "0"], ["83887.96", "0"], ["83887.09", "0.073185"], ["83886.64", "0.065398"], ["83885.49", "0"], ["83884.92", "0.000878"], ["83881.74", "0"], ["83880.92", "0"], ["83876.84", "0"], ["83861.70", "4.356561"], ["83853.30", "5.173416"], ["83844.90", "5.445701"], ["83836.50", "4.175038"], ["83828.10", "3.902753"], ["83819.70", "4.901131"], ["83811.30", "4.447323"], ["83794.50", "5.082654"], ["83786.10", "5.354940"], ["83777.70", "5.536463"], ["83769.30", "4.991893"], ["83760.90", "3.993514"], ["83752.50", "5.627225"], ["83744.10", "4.084276"], ["83735.70", "4.265799"], ["83727.30", "4.538084"], ["83718.90", "5.264178"], ["83710.50", "4.810369"], ["83702.10", "4.628846"], ["83462.01", "0.000009"]], "checksum": -1427898424, "ts": "1742576907946"}], "ts": 1742576907951, "record_time": 1742576908.146889, "EXCHANGE": "BITGET"}
{"action": "update", "arg": {"instType": "SPOT", "channel": "books", "instId": "BTCUSDT"}, "data": [{"asks": [["83919.86", "0.091662"], ["83919.87", "0"], ["83989.30", "1.426470"], ["83990.00", "0.042810"], ["83990.30", "0"], ["83991.80", "0.030000"], ["83996.10", "2.537310"], ["83998.20", "0"], ["84029.60", "4.810369"], ["84038.00", "4.356561"], ["84046.40", "4.447323"], ["84054.80", "3.993514"], ["84063.20", "4.901131"], ["84071.60", "4.265799"], ["84080.00", "4.175038"], ["84088.40", "5.082654"], ["84096.80", "5.173416"], ["84105.20", "5.354940"], ["84113.60", "4.719608"], ["84122.00", "4.991893"], ["84130.40", "4.084276"], ["84138.80", "5.536463"], ["84147.20", "4.538084"], ["84155.60", "5.627225"], ["84164.00", "5.264178"], ["84172.40", "5.445701"], ["84189.20", "3.902753"], ["84340.72", "0.000066"], ["84341.00", "0.002997"]], "bids": [["83866.03", "0.003603"], ["83861.70", "4.447323"], ["83858.30", "0"], ["83853.30", "3.993514"], ["83844.90", "4.719608"], ["83836.50", "4.901131"], ["83828.10", "4.538084"], ["83819.70", "4.628846"], ["83811.30", "5.173416"], ["83802.90", "3.902753"], ["83794.50", "4.084276"], ["83760.90", "5.082654"], ["83752.50", "5.445701"], ["83744.10", "4.175038"], ["83727.30", "4.356561"], ["83702.10", "5.627225"]], "checksum": -863952471, "ts": "1742576908151"}], "ts": 1742576908155, "record_time": 1742576908.352092, "EXCHANGE": "BITGET"}
{"action": "update", "arg": {"instType": "SPOT", "channel": "books", "instId": "BTCUSDT"}, "data": [{"asks": [["83919.35", "0.001236"], ["83950.99", "0.178409"], ["83973.70", "0.002785"], ["83975.70", "0.007328"], ["83977.70", "0.019286"], ["83979.70", "0.050751"], ["83981.70", "0.133555"], ["83983.70", "0.351461"], ["83985.70", "0.924897"], ["83987.70", "2.433940"], ["83988.10", "0.001004"], ["83988.20", "0.438840"], ["83988.30", "1.076400"], ["83988.70", "0"], ["83989.20", "0"], ["83989.30", "0"], ["84029.60", "4.265799"], ["84038.00", "4.538084"], ["84046.40", "3.993514"], ["84054.79", "0"], ["84054.80", "5.082654"], ["84063.20", "4.447323"], ["84071.60", "5.354940"], ["84080.00", "5.445701"], ["84088.40", "3.902753"], ["84096.80", "5.627225"], ["84105.20", "5.173416"], ["84113.60", "4.084276"], ["84122.00", "4.356561"], ["84130.40", "4.810369"], ["84147.20", "4.991893"], ["84155.60", "4.628846"], ["84164.00", "4.175038"], ["84172.40", "4.719608"], ["84180.80", "5.264178"], ["84189.20", "4.901131"]], "bids": [["83917.60", "0.007638"], ["83915.60", "0.020099"], ["83913.60", "0.052892"], ["83911.60", "0.139190"], ["83909.60", "0.366290"], ["83907.60", "0.963921"], ["83905.60", "2.536635"], ["83903.60", "6.675354"], ["83861.70", "5.173416"], ["83859.00", "0.000017"], ["83853.30", "4.901131"], ["83844.90", "3.993514"], ["83836.50", "5.536463"], ["83828.10", "5.082654"], ["83819.70", "4.175038"], ["83811.30", "5.354940"], ["83802.90", "4.991893"], ["83794.50", "3.902753"], ["83786.10", "5.264178"], ["83777.70", "4.084276"], ["83769.30", "4.810369"], ["83760.90", "4.356561"], ["83752.50", "5.627225"], ["83744.10", "4.538084"], ["83727.30", "4.628846"], ["83718.90", "4.719608"], ["83710.50", "4.447323"], ["83702.10", "5.445701"], ["83462.01", "0"]], "checksum": 1743976869, "ts": "1742576908364"}], "ts": 1742576908367, "record_time": 1742576908.563096, "EXCHANGE": "BITGET"}
{"action": "update", "arg": {"instType": "SPOT", "channel": "books", "instId": "BTCUSDT"}, "data": [{"asks": [["83919.86", "0"], ["83957.32", "0.727367"], ["83973.70", "0.001874"], ["83975.70", "0.004933"], ["83977.70", "0.012980"], ["83979.70", "0.034160"], ["83979.84", "0.163681"], ["83981.70", "0.089893"], ["83983.70", "0.236803"], ["83985.70", "0.623164"], ["83987.70", "1.639906"], ["83988.10", "0.001260"], ["83991.80", "0.015000"], ["83996.10", "3.501720"], ["83998.20", "0.536970"], ["84029.60", "5.445701"], ["84038.00", "4.265799"], ["84046.40", "4.175038"], ["84054.80", "4.901131"], ["84063.20", "5.173416"], ["84071.60", "4.084276"], ["84080.00", "3.902753"], ["84088.40", "5.264178"], ["84096.80", "4.719608"], ["84105.20", "4.356561"], ["84113.60", "4.991893"], ["84122.00", "4.628846"], ["84130.40", "5.082654"], ["84138.80", "4.810369"], ["84147.20", "5.536463"], ["84155.60", "4.538084"], ["84164.00", "3.993514"], ["84172.40", "5.627225"], ["84180.80", "4.447323"], ["84189.20", "5.354940"], ["84341.00", "0"]], "bids": [["83902.70", "2.524710"], ["83896.20", "0"], ["83892.70", "0.009000"], ["83861.70", "4.991893"], ["83853.30", "3.902753"], ["83836.50", "5.173416"], ["83828.10", "4.628846"], ["83819.70", "4.901131"], ["83811.30", "4.810369"], ["83802.90", "5.082654"], ["83794.50", "5.445701"], ["83777.70", "4.265799"], ["83769.30", "5.536463"], ["83760.90", "5.354940"], ["83752.50", "4.084276"], ["83744.10", "4.175038"], ["83735.70", "4.356561"], ["83727.30", "4.719608"], ["83718.90", "5.627225"], ["83710.50", "4.538084"], ["83702.10", "4.447323"]], "checksum": -1840474991, "ts": "1742576908565"}], "ts": 1742576908570, "record_time": 1742576908.766376, "EXCHANGE": "BITGET"}
{"action": "update", "arg": {"instType": "SPOT", "channel": "books", "instId": "BTCUSDT"}, "data": [{"asks": [["83919.34", "0.760611"], ["83919.84", "0.091662"], ["84029.60", "4.538084"], ["84038.00", "4.356561"], ["84046.40", "4.265799"], ["84054.80", "4.991893"], ["84063.20", "5.354940"], ["84071.60", "4.810369"], ["84080.00", "3.993514"], ["84088.40", "4.901131"], ["84096.80", "3.902753"], ["84105.20", "5.627225"], ["84113.60", "5.264178"], ["84122.00", "5.082654"], ["84130.40", "4.628846"], ["84138.80", "4.447323"], ["84147.20", "4.084276"], ["84155.60", "5.536463"], ["84164.00", "5.173416"], ["84172.40", "4.719608"], ["84180.80", "4.175038"], ["84189.20", "5.445701"], ["84340.72", "0"]], "bids": [["83915.60", "0.020214"], ["83913.60", "0.053197"], ["83911.60", "0.139991"], ["83909.60", "0.368398"], ["83907.60", "0.969467"], ["83905.60", "2.551230"], ["83903.60", "6.713763"], ["83861.70", "4.538084"], ["83853.30", "5.627225"], ["83844.90", "4.447323"], ["83836.50", "3.993514"], ["83819.70", "4.084276"], ["83811.30", "5.445701"], ["83802.90", "5.536463"], ["83794.50", "4.991893"], ["83786.10", "4.265799"], ["83777.70", "3.902753"], ["83769.30", "5.082654"], ["83760.90", "4.719608"], ["83752.50", "4.901131"], ["83744.10", "4.356561"], ["83735.70", "5.264178"], ["83727.30", "4.810369"], ["83718.90", "5.354940"], ["83710.50", "5.173416"], ["83702.10", "4.175038"]], "checksum": 1079835866, "ts": "1742576908785"}], "ts": 1742576908790, "record_time": 1742576908.991128, "EXCHANGE": "BITGET"}
{"action": "update", "arg": {"instType": "SPOT", "channel": "books", "instId": "BTCUSDT"}, "data": [{"asks": [["83919.34", "0.552379"], ["83941.07", "0"], ["83941.59", "0"], ["83941.62", "0.035971"], ["83942.04", "0.119905"], ["83942.76", "0"], ["83943.60", "0.035972"], ["83944.72", "0"], ["83945.63", "0.010995"], ["83951.14", "0"], ["83951.39", "0"], ["83951.69", "0.119905"], ["83951.93", "0.015895"], ["83971.70", "0.002141"], ["83973.70", "0.005848"], ["83975.70", "0.015390"], ["83977.70", "0.040501"], ["83979.70", "0.106816"], ["83981.70", "0.281095"], ["83983.70", "0.739723"], ["83985.70", "1.946640"], ["83987.70", "5.122738"], ["83992.50", "0.098730"], ["83993.90", "0"], ["83996.50", "2.479530"], ["84029.60", "5.264178"], ["84036.49", "0"], ["84038.00", "5.082654"], ["84046.40", "5.173416"], ["84054.80", "5.445701"], ["84057.52", "0.125841"], ["84063.20", "4.991893"], ["84071.60", "4.538084"], ["84080.00", "4.901131"], ["84088.40", "4.810369"], ["84096.80", "4.265799"], ["84105.20", "3.993514"], ["84113.60", "5.354940"], ["84122.00", "5.627225"], ["84130.40", "4.175038"], ["84138.80", "4.719608"], ["84147.20", "3.902753"], ["84155.60", "4.628846"], ["84164.00", "4.447323"], ["84172.40", "4.356561"], ["84180.80", "5.536463"], ["84189.20", "4.084276"], ["84340.72", "0.000066"]], "bids": [["83919.33", "1.359269"], ["83917.60", "0.006215"], ["83915.60", "0.016356"], ["83913.60", "0.043041"], ["83911.60", "0.113266"], ["83911.00", "0.000015"], ["83910.00", "0.000032"], ["83909.60", "0.298069"], ["83909.00", "0.000032"], ["83908.00", "0.000032"], ["83907.60", "0.784392"], ["83907.00", "0.000032"], ["83906.00", "0.000032"], ["83905.60", "2.064188"], ["83905.00", "0.000032"], ["83904.00", "0.000032"], ["83903.60", "5.432074"], ["83901.33", "0.089672"], ["83901.10", "0"], ["83900.91", "0.247539"], ["83900.79", "0"], ["83900.47", "0"], ["83899.96", "0.083636"], ["83899.12", "0"], ["83897.96", "0.055636"], ["83897.05", "0"], ["83895.30", "0.168570"], ["83892.90", "0"], ["83891.27", "0.259208"], ["83891.01", "0.076243"], ["83890.72", "0"], ["83890.46", "0"], ["83861.70", "4.265799"], ["83860.00", "0.000032"], ["83853.30", "4.084276"], ["83844.90", "5.445701"], ["83836.50", "5.354940"], ["83828.10", "3.993514"], ["83819.70", "4.175038"], ["83811.30", "4.447323"], ["83802.90", "4.356561"], ["83786.10", "5.173416"], ["83777.70", "4.719608"], ["83760.90", "4.538084"], ["83752.50", "5.627225"], ["83744.10", "5.264178"], ["83735.70", "4.810369"], ["83727.30", "4.901131"], ["83718.90", "4.628846"], ["83710.50", "5.536463"], ["83702.10", "3.902753"]], "checksum": 1846796681, "ts": "1742576908994"}], "ts": 1742576908997, "record_time": 1742576909.193095, "EXCHANGE": "BITGET"}
{"action": "update", "arg": {"instType": "SPOT", "channel": "books", "instId": "BTCUSDT"}, "data": [{"asks": [["83919.34", "0.558279"], ["83919.35", "0.000100"], ["83919.82", "0.091662"], ["83919.84", "0"], ["83925.41", "0.035681"], ["83940.27", "0"], ["83950.88", "0"], ["83953.74", "0.013838"], ["83977.70", "0.040604"], ["84038.00", "4.175038"], ["84046.40", "4.538084"], ["84054.80", "4.356561"], ["84063.20", "5.082654"], ["84071.60", "5.445701"], ["84088.40", "4.447323"], ["84096.80", "5.627225"], ["84105.20", "5.354940"], ["84113.60", "4.084276"], ["84122.00", "3.902753"], ["84130.40", "4.719608"], ["84138.80", "4.265799"], ["84147.20", "4.991893"], ["84155.60", "5.536463"], ["84164.00", "4.810369"], ["84172.40", "5.173416"], ["84180.80", "4.628846"], ["84189.20", "3.993514"]], "bids": [["83913.60", "0.043147"], ["83911.60", "0.113545"], ["83909.61", "0"], ["83909.60", "0.298803"], ["83907.60", "0.786322"], ["83905.60", "2.069270"], ["83903.60", "5.445448"], ["83902.00", "0.042300"], ["83898.20", "0.459870"], ["83894.90", "3.625380"], ["83869.00", "0.000015"], ["83868.00", "0.000015"], ["83867.00", "0.000015"], ["83866.00", "0.000015"], ["83865.00", "0.000015"], ["83864.00", "0.000015"], ["83863.00", "0.000015"], ["83862.00", "0.000015"], ["83861.70", "3.902753"], ["83860.00", "0.000015"], ["83844.90", "5.536463"], ["83836.50", "3.993514"], ["83828.10", "5.264178"], ["83819.70", "4.901131"], ["83811.30", "4.175038"], ["83802.90", "4.628846"], ["83794.50", "5.627225"], ["83786.10", "4.991893"], ["83777.70", "5.082654"], ["83769.30", "4.265799"], ["83760.90", "4.810369"], ["83752.50", "5.173416"], ["83744.10", "4.719608"], ["83735.70", "5.354940"], ["83727.30", "4.447323"], ["83718.90", "4.538084"], ["83710.50", "4.356561"], ["83702.10", "5.445701"]], "checksum": 1406163811, "ts": "1742576909201"}], "ts": 1742576909204, "record_time": 1742576909.399638, "EXCHANGE": "BITGET"}
{"action": "update", "arg": {"instType": "SPOT", "channel": "books", "instId": "BTCUSDT"}, "data": [{"asks": [["83919.34", "0.827353"], ["83919.81", "0.027499"], ["83925.42", "0"], ["83940.86", "0.036150"], ["83969.70", "0.001460"], ["83971.70", "0.004104"], ["83973.70", "0.010802"], ["83975.48", "0"], ["83975.70", "0.028425"], ["83977.70", "0.074803"], ["83979.70", "0.196851"], ["83981.70", "0.518027"], ["83983.70", "1.363231"], ["83985.70", "3.587448"], ["83987.70", "9.440653"], ["83988.20", "0.438660"], ["83988.30", "0.001043"], ["83990.00", "0.042990"], ["83991.20", "0.951330"], ["83991.60", "1.921770"], ["83991.90", "0.120000"], ["83992.10", "2.359650"], ["83992.50", "0.116580"], ["83994.40", "0.035730"], ["83996.10", "2.537310"], ["83996.40", "0"], ["83996.50", "0.120000"], ["83998.20", "0"], ["84029.60", "4.175038"], ["84038.00", "4.265799"], ["84046.40", "4.356561"], ["84054.80", "3.993514"], ["84063.20", "4.628846"], ["84071.60", "3.902753"], ["84080.00", "4.084276"], ["84096.80", "5.173416"], ["84105.20", "4.810369"], ["84113.60", "5.082654"], ["84122.00", "4.719608"], ["84130.40", "4.538084"], ["84138.80", "4.991893"], ["84147.20", "5.445701"], ["84155.60", "5.354940"], ["84164.00", "5.536463"], ["84172.40", "4.901131"], ["84180.80", "5.627225"], ["84189.20", "5.264178"], ["84340.72", "0"]], "bids": [["83919.33", "1.297480"], ["83917.60", "0.001435"], ["83915.60", "0.003660"], ["83913.60", "0.009631"], ["83911.92", "0"], ["83911.60", "0.025346"], ["83909.61", "0.387014"], ["83909.60", "0.066698"], ["83907.60", "0.175522"], ["83905.60", "0.461901"], ["83903.60", "1.215529"], ["83903.20", "0"], ["83902.80", "0"], ["83902.70", "2.464710"], ["83902.51", "0"], ["83902.20", "0"], ["83902.00", "0.042690"], ["83901.80", "0"], ["83901.70", "0"], ["83901.00", "0.071520"], ["83900.00", "0.042480"], ["83899.10", "0"], ["83898.90", "0.129690"], ["83898.20", "0.066420"], ["83897.50", "0.409650"], ["83896.90", "0.015000"], ["83896.50", "0.015000"], ["83895.60", "0.150000"], ["83895.20", "0.090000"], ["83894.90", "1.464450"], ["83894.50", "0.425760"], ["83893.95", "0.024948"], ["83861.70", "5.445701"], ["83853.30", "4.991893"], ["83844.90", "5.264178"], ["83836.50", "4.901131"], ["83828.10", "4.084276"], ["83819.70", "4.356561"], ["83811.30", "4.447323"], ["83802.90", "5.173416"], ["83794.50", "4.810369"], ["83786.10", "4.538084"], ["83777.70", "3.993514"], ["83769.30", "5.536463"], ["83760.90", "4.719608"], ["83752.50", "5.082654"], ["83744.10", "4.628846"], ["83735.70", "5.627225"], ["83727.30", "4.265799"], ["83718.90", "4.175038"], ["83710.50", "5.354940"], ["83702.10", "3.902753"], ["83462.01", "0.000009"], ["83461.54", "0.000178"]], "checksum": -1574971485, "ts": "1742576909407"}], "ts": 1742576909410, "record_time": 1742576909.605327, "EXCHANGE": "BITGET"}
{"action": "update", "arg": {"instType": "SPOT", "channel": "books", "instId": "BTCUSDT"}, "data": [{"asks": [["83919.82", "0"], ["83924.06", "0.114336"], ["83925.41", "0.001376"], ["83957.32", "0.828890"], ["83958.99", "0"], ["83969.70", "0.001623"], ["83971.70", "0.004480"], ["83973.70", "0.011791"], ["83975.70", "0.031029"], ["83977.70", "0.081653"], ["83979.70", "0.214878"], ["83979.84", "0"], ["83981.70", "0.565468"], ["83983.70", "1.488074"], ["83985.70", "3.915983"], ["83987.70", "10.305218"], ["83987.90", "0.120420"], ["83990.00", "0.042780"], ["83991.20", "0.681570"], ["83991.80", "0.030000"], ["83992.10", "0"], ["83993.80", "2.359620"], ["84029.60", "5.264178"], ["84038.00", "4.810369"], ["84046.40", "4.084276"], ["84054.80", "4.901131"], ["84063.20", "3.993514"], ["84071.60", "5.173416"], ["84080.00", "4.175038"], ["84088.40", "4.628846"], ["84096.80", "5.536463"], ["84105.20", "4.265799"], ["84122.00", "5.445701"], ["84130.40", "5.354940"], ["84138.80", "4.719608"], ["84147.20", "5.627225"], ["84155.60", "4.538084"], ["84164.00", "4.991893"], ["84172.40", "4.356561"], ["84180.80", "4.447323"], ["84189.20", "3.902753"], ["84340.72", "0.000066"]], "bids": [["83919.33", "1.059796"], ["83917.60", "0.001803"], ["83915.60", "0.004744"], ["83913.60", "0.012486"], ["83911.60", "0.032857"], ["83910.52", "0.013838"], ["83909.61", "0.134142"], ["83909.60", "0.086466"], ["83907.60", "0.227542"], ["83905.61", "0.044996"], ["83905.60", "0.598794"], ["83904.01", "0.013755"], ["83903.60", "1.575773"], ["83899.80", "0.074220"], ["83897.10", "0.160890"], ["83861.70", "4.810369"], ["83853.30", "5.627225"], ["83844.90", "5.445701"], ["83836.50", "3.902753"], ["83828.10", "4.991893"], ["83819.70", "5.264178"], ["83811.30", "4.175038"], ["83802.90", "4.538084"], ["83794.50", "4.356561"], ["83786.10", "5.354940"], ["83777.70", "5.082654"], ["83760.90", "3.993514"], ["83752.50", "4.719608"], ["83744.10", "5.173416"], ["83735.70", "4.084276"], ["83718.90", "4.901131"], ["83710.50", "4.628846"], ["83702.10", "4.447323"], ["83462.50", "0"], ["83462.01", "0"], ["83461.54", "0"]], "checksum": 741074184, "ts": "1742576909613"}], "ts": 1742576909616, "record_time": 1742576909.814591, "EXCHANGE": "BITGET"}
{"action": "update", "arg": {"instType": "SPOT", "channel": "books", "instId": "BTCUSDT"}, "data": [{"asks": [["83919.34", "0.558279"], ["83919.80", "0.091662"], ["83919.81", "0"], ["83924.05", "0.034301"], ["83954.43", "0.175763"], ["83969.70", "0.001465"], ["83971.70", "0.003856"], ["83973.70", "0.010146"], ["83975.70", "0.026700"], ["83977.70", "0.070264"], ["83979.70", "0.184904"], ["83979.84", "0.034305"], ["83981.70", "0.486590"], ["83983.70", "1.280501"], ["83985.70", "3.369740"], ["83987.70", "8.867736"], ["83992.50", "0.098730"], ["83994.40", "0.017850"], ["84018.97", "0.001086"], ["84029.60", "4.084276"], ["84038.00", "4.991893"], ["84046.40", "4.628846"], ["84054.80", "4.356561"], ["84063.20", "5.264178"], ["84071.60", "5.082654"], ["84080.00", "5.173416"], ["84088.40", "4.447323"], ["84096.80", "4.538084"], ["84105.20", "3.902753"], ["84113.60", "4.175038"], ["84130.40", "3.993514"], ["84138.80", "4.901131"], ["84147.20", "4.719608"], ["84155.60", "4.810369"], ["84164.00", "5.627225"], ["84172.40", "5.536463"], ["84180.80", "5.354940"], ["84189.20", "4.265799"], ["84339.62", "0"], ["84340.00", "0"], ["84340.46", "0"], ["84340.72", "0"]], "bids": [["83917.60", "0.002680"], ["83915.60", "0.007051"], ["83913.60", "0.018556"], ["83911.60", "0.048832"], ["83909.60", "0.128504"], ["83907.60", "0.338168"], ["83905.61", "0.880712"], ["83905.60", "0.889918"], ["83903.60", "2.341889"], ["83902.71", "0.892135"], ["83898.20", "0"], ["83897.50", "0.120000"], ["83896.30", "0.930750"], ["83895.30", "0.705540"], ["83895.20", "1.440000"], ["83861.70", "5.082654"], ["83853.30", "5.536463"], ["83844.90", "4.991893"], ["83836.50", "5.627225"], ["83828.10", "4.265799"], ["83819.70", "4.084276"], ["83811.30", "5.354940"], ["83802.90", "4.628846"], ["83794.50", "3.902753"], ["83786.10", "4.901131"], ["83777.70", "5.445701"], ["83769.30", "5.173416"], ["83760.90", "4.810369"], ["83752.50", "4.175038"], ["83744.10", "4.719608"], ["83735.70", "5.264178"], ["83727.30", "4.447323"], ["83718.90", "4.356561"], ["83710.50", "4.538084"], ["83702.10", "3.993514"]], "checksum": 1698731672, "ts": "1742576909813"}], "ts": 1742576909817, "record_time": 1742576910.013321, "EXCHANGE": "BITGET"}
{"action": "update", "arg": {"instType": "SPOT", "channel": "books", "instId": "BTCUSDT"}, "data": [{"asks": [["83997.00", "0.492000"], ["83997.80", "0.192000"], ["83997.90", "0"], ["84029.60", "4.628846"], ["84038.00", "4.265799"], ["84042.61", "0.013241"], ["84046.40", "4.175038"], ["84054.80", "5.082654"], ["84063.20", "4.538084"], ["84071.60", "4.810369"], ["84080.00", "5.536463"], ["84088.40", "4.356561"], ["84096.80", "5.445701"], ["84105.20", "5.627225"], ["84113.60", "4.719608"], ["84122.00", "5.173416"], ["84138.80", "4.991893"], ["84147.20", "4.084276"], ["84155.60", "5.264178"], ["84164.00", "4.447323"], ["84172.40", "4.901131"], ["84189.20", "3.902753"], ["84339.50", "0"]], "bids": [["83917.60", "0.001803"], ["83915.60", "0.004744"], ["83913.60", "0.012486"], ["83911.60", "0.032857"], ["83909.61", "0.184710"], ["83909.60", "0.086466"], ["83907.60", "0.227542"], ["83905.60", "0.598794"], ["83903.60", "1.575773"], ["83900.26", "0.006218"], ["83895.47", "0"], ["83861.70", "4.447323"], ["83861.00", "0.000032"], ["83853.30", "4.175038"], ["83844.90", "5.082654"], ["83836.50", "5.536463"], ["83828.10", "4.991893"], ["83819.70", "5.445701"], ["83811.30", "3.993514"], ["83797.94", "0"], ["83794.50", "5.354940"], ["83786.10", "4.719608"], ["83777.70", "5.264178"], ["83769.30", "4.810369"], ["83760.90", "4.356561"], ["83752.50", "5.173416"], ["83744.10", "5.627225"], ["83735.70", "4.538084"], ["83727.30", "4.084276"], ["83718.90", "3.902753"], ["83710.50", "4.265799"], ["83702.10", "4.901131"], ["83462.50", "0.000025"]], "checksum": 22246917, "ts": "1742576910013"}], "ts": 1742576910015, "record_time": 1742576910.210682, "EXCHANGE": "BITGET"}
{"action": "update", "arg": {"instType": "SPOT", "channel": "books", "instId": "BTCUSDT"}, "data": [{"asks": [["83919.34", "0.806224"], ["83919.78", "0.091662"], ["83919.80", "0"], ["83973.70", "0.010381"], ["83975.70", "0.027318"], ["83977.70", "0.071891"], ["83979.70", "0.189187"], ["83981.70", "0.497859"], ["83983.70", "1.310155"], ["83985.70", "3.447777"], ["83987.70", "9.073099"], ["84029.60", "4.991893"], ["84038.00", "5.627225"], ["84046.40", "4.628846"], ["84054.80", "4.810369"], ["84063.20", "4.175038"], ["84071.60", "5.536463"], ["84080.00", "4.719608"], ["84088.40", "4.538084"], ["84096.80", "5.173416"], ["84105.20", "5.264178"], ["84113.60", "3.902753"], ["84122.00", "5.354940"], ["84130.40", "4.901131"], ["84138.80", "4.356561"], ["84147.20", "5.445701"], ["84155.60", "4.084276"], ["84164.00", "5.082654"], ["84172.40", "4.447323"], ["84180.80", "3.993514"], ["84189.20", "4.265799"]], "bids": [["83917.60", "0.002109"], ["83915.60", "0.005550"], ["83913.60", "0.014607"], ["83911.60", "0.038439"], ["83909.60", "0.101155"], ["83907.60", "0.266196"], ["83905.60", "0.700516"], ["83903.60", "1.843465"], ["83903.40", "0.008700"], ["83899.80", "0.074040"], ["83898.90", "0"], ["83894.70", "0.459870"], ["83892.70", "0"], ["83889.53", "0"], ["83881.00", "0.024925"], ["83861.70", "5.264178"], ["83853.30", "5.354940"], ["83844.90", "4.628846"], ["83836.50", "4.538084"], ["83828.10", "5.536463"], ["83819.70", "3.902753"], ["83811.30", "5.082654"], ["83802.90", "4.356561"], ["83794.50", "4.084276"], ["83786.10", "4.810369"], ["83777.70", "4.991893"], ["83769.30", "4.719608"], ["83760.90", "5.627225"], ["83752.50", "4.901131"], ["83744.10", "4.265799"], ["83735.70", "3.993514"], ["83727.30", "5.173416"], ["83718.90", "4.175038"], ["83710.50", "5.445701"], ["83702.10", "4.447323"], ["83462.01", "0.000009"]], "checksum": -2016241746, "ts": "1742576910213"}], "ts": 1742576910216, "record_time": 1742576910.422241, "EXCHANGE": "BITGET"}
{"action": "update", "arg": {"instType": "SPOT", "channel": "books", "instId": "BTCUSDT"}, "data": [{"asks": [["83919.34", "0.833930"], ["83919.77", "0.061799"], ["83924.05", "0"], ["83969.70", "0.001645"], ["83971.70", "0.004330"], ["83973.70", "0.011394"], ["83975.70", "0.029986"], ["83977.70", "0.078910"], ["83979.70", "0.207658"], ["83981.70", "0.546468"], ["83983.70", "1.438074"], ["83985.70", "3.784405"], ["83987.70", "9.958961"], ["83994.40", "0.053580"], ["83997.80", "0"], ["84029.60", "4.538084"], ["84038.00", "5.536463"], ["84046.40", "5.082654"], ["84054.80", "3.902753"], ["84063.20", "5.264178"], ["84071.60", "4.175038"], ["84088.40", "4.356561"], ["84096.80", "4.991893"], ["84105.20", "4.265799"], ["84113.60", "4.810369"], ["84122.00", "5.173416"], ["84138.80", "4.084276"], ["84147.20", "4.447323"], ["84155.60", "5.627225"], ["84164.00", "5.354940"], ["84172.40", "3.993514"], ["84180.80", "5.445701"], ["84189.20", "4.628846"], ["84315.00", "0.000404"]], "bids": [["83917.60", "0.001665"], ["83915.60", "0.004381"], ["83913.60", "0.011530"], ["83911.60", "0.030208"], ["83909.60", "0.079495"], ["83907.60", "0.209197"], ["83905.60", "0.550520"], ["83903.60", "1.448735"], ["83903.40", "0.246360"], ["83901.20", "0.066600"], ["83901.00", "0.071130"], ["83900.00", "0.042300"], ["83896.30", "0.525780"], ["83895.20", "0.090000"], ["83895.00", "0.240180"], ["83893.10", "0"], ["83869.00", "0"], ["83868.00", "0"], ["83867.00", "0"], ["83866.00", "0"], ["83865.00", "0"], ["83864.00", "0"], ["83863.00", "0"], ["83862.00", "0"], ["83861.70", "3.993514"], ["83861.00", "0.000017"], ["83853.30", "4.084276"], ["83844.90", "4.447323"], ["83836.50", "4.628846"], ["83828.10", "4.356561"], ["83819.70", "4.719608"], ["83811.30", "5.627225"], ["83802.90", "4.265799"], ["83794.50", "3.902753"], ["83786.10", "4.991893"], ["83777.70", "4.538084"], ["83769.30", "5.354940"], ["83760.90", "4.175038"], ["83752.50", "5.445701"], ["83744.10", "5.536463"], ["83735.70", "5.173416"], ["83727.30", "4.810369"], ["83718.90", "5.082654"], ["83710.50", "4.901131"], ["83702.10", "5.264178"], ["83461.54", "0.000178"], ["83461.53", "0.000008"], ["83460.43", "0.000010"], ["83460.00", "0.002021"], ["83459.46", "0.000008"], ["83458.33", "0.000218"], ["83458.15", "0.000010"], ["83458.10", "0.000011"]], "checksum": -671208498, "ts": "1742576910414"}], "ts": 1742576910417, "record_time": 1742576910.62969, "EXCHANGE": "BITGET"}
{"action": "update", "arg": {"instType": "SPOT", "channel": "books", "instId": "BTCUSDT"}, "data": [{"asks": [["83966.70", "0.021134"], ["83969.70", "0.001846"], ["83971.70", "0.004858"], ["83973.70", "0.012784"], ["83975.70", "0.033642"], ["83977.70", "0.088530"], ["83979.70", "0.232976"], ["83981.70", "0.613094"], ["83983.70", "1.613406"], ["83985.70", "4.245804"], ["83987.70", "11.173169"], ["83989.30", "0.011940"], ["83991.90", "0"], ["83992.10", "2.359650"], ["83993.80", "0"], ["84029.60", "5.082654"], ["84038.00", "4.265799"], ["84046.40", "3.902753"], ["84054.80", "4.810369"], ["84063.20", "4.538084"], ["84071.60", "5.445701"], ["84080.00", "5.173416"], ["84088.40", "4.991893"], ["84096.80", "5.627225"], ["84105.20", "4.084276"], ["84113.60", "4.901131"], ["84122.00", "5.536463"], ["84130.40", "4.175038"], ["84138.80", "3.993514"], ["84147.20", "4.628846"], ["84155.60", "5.354940"], ["84164.00", "4.719608"], ["84172.40", "4.447323"], ["84180.80", "5.264178"], ["84189.20", "4.356561"], ["84339.29", "0"]], "bids": [["83917.60", "0.001040"], ["83915.60", "0.002403"], ["83913.60", "0.006324"], ["83911.60", "0.016642"], ["83909.60", "0.043796"], ["83907.60", "0.115252"], ["83905.60", "0.303295"], ["83903.60", "0.798145"], ["83903.40", "0"], ["83901.20", "0.188400"], ["83901.00", "0.071310"], ["83900.00", "0.042480"], ["83899.80", "0.140460"], ["83893.10", "0.240390"], ["83892.70", "0.009000"], ["83861.70", "4.084276"], ["83859.00", "0"], ["83853.30", "4.810369"], ["83844.90", "4.356561"], ["83836.50", "4.447323"], ["83828.10", "4.175038"], ["83819.70", "5.627225"], ["83811.30", "4.991893"], ["83802.90", "4.901131"], ["83786.10", "5.354940"], ["83777.70", "5.264178"], ["83769.30", "3.993514"], ["83760.90", "4.628846"], ["83752.50", "4.265799"], ["83744.10", "4.719608"], ["83735.70", "4.538084"], ["83727.30", "5.536463"], ["83718.90", "5.445701"], ["83710.50", "5.173416"], ["83702.10", "5.082654"]], "checksum": -18415040, "ts": "1742576910615"}], "ts": 1742576910617, "record_time": 1742576910.812841, "EXCHANGE": "BITGET"}
{"action": "update", "arg": {"instType": "SPOT", "channel": "books", "instId": "BTCUSDT"}, "data": [{"asks": [["83919.34", "0.841635"], ["83919.77", "0.153461"], ["83919.78", "0"], ["83967.70", "0.001146"], ["83969.70", "0.001723"], ["83971.70", "0.004535"], ["83973.70", "0.011934"], ["83975.70", "0.031404"], ["83977.70", "0.082642"], ["83979.70", "0.217481"], ["83981.70", "0.572316"], ["83983.70", "1.506095"], ["83985.70", "3.963410"], ["83987.70", "10.430024"], ["83989.30", "0.011580"], ["84029.60", "5.536463"], ["84038.00", "4.538084"], ["84046.40", "5.173416"], ["84054.80", "4.175038"], ["84063.20", "4.356561"], ["84071.60", "3.993514"], ["84080.00", "4.628846"], ["84088.40", "4.719608"], ["84096.80", "4.991893"], ["84105.20", "5.354940"], ["84113.60", "5.445701"], ["84122.00", "4.810369"], ["84130.40", "4.084276"], ["84138.80", "4.265799"], ["84147.20", "5.082654"], ["84155.60", "5.264178"], ["84164.00", "3.902753"], ["84172.40", "4.901131"], ["84180.80", "4.447323"], ["84189.20", "5.627225"], ["84339.29", "0.000029"]], "bids": [["83909.61", "0.134142"], ["83905.61", "0"], ["83861.70", "5.536463"], ["83853.30", "3.902753"], ["83844.90", "5.445701"], ["83836.50", "4.084276"], ["83828.10", "4.810369"], ["83811.30", "4.719608"], ["83802.90", "4.265799"], ["83794.50", "4.901131"], ["83786.10", "5.173416"], ["83777.70", "4.538084"], ["83769.30", "5.082654"], ["83760.90", "4.356561"], ["83752.50", "4.447323"], ["83744.10", "4.628846"], ["83735.70", "5.354940"], ["83727.30", "4.991893"], ["83718.90", "4.175038"], ["83710.50", "5.264178"], ["83702.10", "3.993514"], ["83457.63", "0.000023"]], "checksum": -663046389, "ts": "1742576910841"}], "ts": 1742576910845, "record_time": 1742576911.041348, "EXCHANGE": "BITGET"}
{"action": "update", "arg": {"instType": "SPOT", "channel": "books", "instId": "BTCUSDT"}, "data": [{"asks": [["83919.34", "0.841285"], ["83919.76", "0.061799"], ["83919.77", "0.091662"], ["83989.30", "0"], ["83997.80", "0.192000"], ["84029.60", "5.445701"], ["84046.40", "4.628846"], ["84054.80", "5.264178"], ["84071.60", "4.901131"], ["84080.00", "5.082654"], ["84088.40", "5.536463"], ["84096.80", "5.173416"], ["84105.20", "4.991893"], ["84113.60", "4.810369"], ["84122.00", "4.084276"], ["84130.40", "4.175038"], ["84138.80", "5.627225"], ["84147.20", "4.265799"], ["84155.60", "3.902753"], ["84164.00", "5.354940"], ["84172.40", "3.993514"], ["84180.80", "4.719608"], ["84189.20", "4.447323"], ["84339.29", "0"]], "bids": [["83915.60", "0.002854"], ["83913.60", "0.007511"], ["83911.60", "0.019764"], ["83909.60", "0.052012"], ["83907.60", "0.136873"], ["83905.60", "0.360192"], ["83905.44", "0.473410"], ["83903.60", "0.947875"], ["83902.60", "0.757440"], ["83901.20", "0.188190"], ["83901.00", "0.071100"], ["83900.00", "0.042300"], ["83897.11", "0.407302"], ["83892.70", "0"], ["83861.70", "4.719608"], ["83853.30", "4.628846"], ["83844.90", "4.265799"], ["83836.50", "4.810369"], ["83828.10", "5.264178"], ["83819.70", "5.173416"], ["83811.30", "5.445701"], ["83802.90", "4.901131"], ["83794.50", "5.536463"], ["83786.10", "4.175038"], ["83777.70", "5.627225"], ["83769.30", "4.991893"], ["83760.90", "3.902753"], ["83752.50", "5.082654"], ["83744.10", "4.356561"], ["83735.70", "3.993514"], ["83727.30", "4.084276"], ["83718.90", "5.354940"], ["83710.50", "4.447323"], ["83702.10", "4.538084"], ["83458.10", "0"], ["83457.63", "0"]], "checksum": -1354026720, "ts": "1742576911052"}], "ts": 1742576911055, "record_time": 1742576911.250671, "EXCHANGE": "BITGET"}
{"action": "update", "arg": {"instType": "SPOT", "channel": "books", "instId": "BTCUSDT"}, "data": [{"asks": [["83919.34", "0.836733"], ["83919.35", "0.001236"], ["83919.75", "0.091662"], ["83919.77", "0"], ["83969.70", "0.001870"], ["83971.70", "0.004920"], ["83973.70", "0.012948"], ["83975.70", "0.034074"], ["83977.70", "0.089669"], ["83979.70", "0.235970"], ["83981.70", "0.620975"], ["83983.70", "1.634143"], ["83985.70", "4.300376"], ["83987.70", "11.316779"], ["84029.60", "4.628846"], ["84038.00", "4.810369"], ["84046.40", "5.536463"], ["84054.80", "5.445701"], ["84063.20", "5.082654"], ["84080.00", "5.354940"], ["84088.40", "4.719608"], ["84096.80", "3.902753"], ["84105.20", "4.265799"], ["84113.60", "3.993514"], ["84122.00", "4.991893"], ["84130.40", "4.356561"], ["84138.80", "4.084276"], ["84147.20", "5.627225"], ["84155.60", "5.173416"], ["84164.00", "5.264178"], ["84172.40", "4.538084"], ["84180.80", "4.447323"], ["84189.20", "4.175038"]], "bids": [["83901.00", "0.070920"], ["83893.10", "0"], ["83869.00", "0.000017"], ["83861.70", "4.901131"], ["83853.30", "5.354940"], ["83844.90", "4.538084"], ["83836.50", "3.902753"], ["83828.10", "4.810369"], ["83819.70", "4.084276"], ["83811.30", "4.175038"], ["83802.90", "5.536463"], ["83794.50", "4.991893"], ["83786.10", "4.628846"], ["83777.70", "5.264178"], ["83769.30", "4.265799"], ["83760.90", "5.445701"], ["83752.50", "4.719608"], ["83744.10", "3.993514"], ["83735.70", "4.447323"], ["83727.30", "4.356561"], ["83718.90", "5.627225"], ["83710.50", "5.173416"], ["83702.10", "5.082654"], ["83580.34", "0.004656"], ["83458.15", "0"]], "checksum": -944925615, "ts": "1742576911264"}], "ts": 1742576911268, "record_time": 1742576911.466286, "EXCHANGE": "BITGET"}
{"action": "update", "arg": {"instType": "SPOT", "channel": "books", "instId": "BTCUSDT"}, "data": [{"asks": [["83919.34", "0.839480"], ["83919.76", "0"], ["83941.56", "0.006357"], ["83941.77", "0.006357"], ["83942.09", "0.006357"], ["83942.37", "0.006357"], ["83942.58", "0.006357"], ["83942.95", "0.006357"], ["83943.45", "0.006356"], ["83943.47", "0.006357"], ["83944.12", "0.012714"], ["83944.52", "0.006357"], ["83944.61", "0.006357"], ["83944.70", "0"], ["83944.80", "0"], ["83944.85", "0"], ["83945.11", "0.006357"], ["83945.12", "0.006357"], ["83945.16", "0"], ["83945.28", "0"], ["83945.85", "0"], ["83945.97", "0.006357"], ["83946.34", "0"], ["83946.62", "0"], ["83946.64", "0.006357"], ["83947.02", "0"], ["83947.20", "0"], ["83947.30", "0"], ["83947.31", "0"], ["83947.82", "0"], ["83948.20", "0"], ["83948.87", "0"], ["83949.39", "0"], ["83967.70", "0.001032"], ["83968.43", "0.010000"], ["83969.70", "0.001815"], ["83971.70", "0.004778"], ["83973.70", "0.012574"], ["83975.70", "0.033088"], ["83977.70", "0.087074"], ["83979.70", "0.229143"], ["83981.70", "0.603006"], ["83983.70", "1.586859"], ["83985.70", "4.175944"], ["83987.70", "10.989326"], ["84029.60", "4.901131"], ["84046.40", "4.447323"], ["84054.80", "4.175038"], ["84063.20", "4.265799"], ["84071.60", "5.082654"], ["84080.00", "5.627225"], ["84088.40", "5.264178"], ["84096.80", "5.173416"], ["84105.20", "5.354940"], ["84113.60", "4.991893"], ["84122.00", "5.445701"], ["84130.40", "4.628846"], ["84138.80", "5.536463"], ["84147.20", "3.902753"], ["84155.60", "3.993514"], ["84164.00", "4.719608"], ["84172.40", "4.084276"], ["84180.80", "4.538084"], ["84189.20", "4.356561"], ["84339.29", "0.000029"]], "bids": [["83901.00", "0.071100"], ["83900.30", "0"], ["83900.22", "0"], ["83900.03", "0"], ["83899.31", "0"], ["83899.00", "0.000032"], ["83898.78", "0"], ["83898.45", "0"], ["83898.35", "0"], ["83897.84", "0"], ["83897.70", "0.022770"], ["83897.68", "0"], ["83897.17", "0"], ["83897.09", "0.017826"], ["83896.95", "0.018272"], ["83896.79", "0"], ["83896.78", "0"], ["83896.68", "0"], ["83896.60", "0.005949"], ["83896.29", "0"], ["83896.22", "0.015750"], ["83896.09", "0.034262"], ["83895.45", "0.006572"], ["83895.33", "0"], ["83895.28", "0.017123"], ["83894.96", "0.007140"], ["83894.84", "0"], ["83894.60", "0.007347"], ["83894.27", "0.017114"], ["83894.09", "0.007955"], ["83893.60", "0.008200"], ["83893.58", "0.017376"], ["83893.20", "0"], ["83892.43", "0.008290"], ["83892.10", "0.012674"], ["83861.70", "4.538084"], ["83859.00", "0.000015"], ["83853.30", "5.082654"], ["83844.90", "4.447323"], ["83836.50", "4.356561"], ["83828.10", "5.445701"], ["83819.70", "4.175038"], ["83811.30", "4.265799"], ["83802.90", "4.084276"], ["83794.50", "4.628846"], ["83786.10", "5.264178"], ["83777.70", "3.902753"], ["83769.30", "5.536463"], ["83760.90", "5.627225"], ["83752.50", "4.991893"], ["83744.10", "4.901131"], ["83735.70", "5.173416"], ["83727.30", "4.719608"], ["83718.90", "5.354940"], ["83710.50", "4.810369"], ["83702.10", "3.993514"], ["83458.15", "0.000010"]], "checksum": 1513138548, "ts": "1742576911467"}], "ts": 1742576911471, "record_time": 1742576911.666578, "EXCHANGE": "BITGET"}
{"action": "update", "arg": {"instType": "SPOT", "channel": "books", "instId": "BTCUSDT"}, "data": [{"asks": [["83919.74", "0.061799"], ["83945.06", "0.016429"], ["83946.63", "0.010993"], ["83948.06", "0"], ["83948.40", "0.119850"], ["83949.36", "0.119858"], ["83949.73", "0"], ["83951.49", "0"], ["83952.49", "0"], ["83969.70", "0.001669"], ["83971.70", "0.004393"], ["83972.47", "0.061799"], ["83973.70", "0.011559"], ["83975.70", "0.030418"], ["83977.70", "0.080048"], ["83979.70", "0.210652"], ["83981.70", "0.554348"], ["83983.70", "1.458812"], ["83985.70", "3.838977"], ["83987.70", "10.102571"], ["83991.60", "1.860690"], ["83992.10", "0"], ["83992.50", "0"], ["83993.10", "2.359650"], ["83994.50", "0"], ["83997.80", "0.396000"], ["83997.90", "0.204000"], ["84029.60", "4.628846"], ["84038.00", "4.991893"], ["84046.40", "5.264178"], ["84054.80", "4.084276"], ["84071.60", "4.901131"], ["84080.00", "4.810369"], ["84088.40", "4.719608"], ["84105.20", "4.538084"], ["84113.60", "5.536463"], ["84130.40", "3.993514"], ["84138.80", "3.902753"], ["84147.20", "4.356561"], ["84155.60", "4.447323"], ["84164.00", "5.082654"], ["84172.40", "5.627225"], ["84180.80", "4.175038"], ["84189.20", "5.354940"], ["84339.29", "0"]], "bids": [["83917.60", "0.001636"], ["83915.60", "0.004431"], ["83913.60", "0.011660"], ["83911.60", "0.030684"], ["83909.60", "0.080748"], ["83907.60", "0.212496"], ["83905.60", "0.559199"], ["83903.60", "1.471576"], ["83902.70", "2.464530"], ["83902.60", "0"], ["83901.20", "0.188400"], ["83896.87", "0"], ["83896.30", "0.405780"], ["83895.18", "0"], ["83893.90", "0"], ["83893.87", "0.025198"], ["83893.41", "0"], ["83893.20", "1.430250"], ["83893.10", "0.240390"], ["83892.40", "0"], ["83892.09", "0.051845"], ["83890.32", "0.268837"], ["83889.60", "0"], ["83889.28", "0.223051"], ["83886.85", "0.012460"], ["83861.70", "4.175038"], ["83853.30", "5.445701"], ["83844.90", "4.810369"], ["83836.50", "5.536463"], ["83828.10", "3.993514"], ["83819.70", "4.719608"], ["83811.30", "4.991893"], ["83802.90", "5.354940"], ["83794.50", "5.264178"], ["83786.10", "4.538084"], ["83777.70", "5.082654"], ["83769.30", "4.084276"], ["83760.90", "4.447323"], ["83752.50", "4.901131"], ["83744.10", "4.265799"], ["83735.70", "3.902753"], ["83727.30", "4.356561"], ["83718.90", "4.628846"], ["83710.50", "5.627225"], ["83702.10", "5.173416"]], "checksum": 522051761, "ts": "1742576911679"}], "ts": 1742576911682, "record_time": 1742576911.878348, "EXCHANGE": "BITGET"}
{"action": "update", "arg": {"instType": "SPOT", "channel": "books", "instId": "BTCUSDT"}, "data": [{"asks": [["83919.74", "0.153461"], ["83919.75", "0"], ["83945.81", "0.204987"], ["83950.99", "0"], ["83969.70", "0.001815"], ["83971.70", "0.004778"], ["83973.70", "0.012574"], ["83975.70", "0.033088"], ["83977.70", "0.087074"], ["83979.70", "0.229143"], ["83981.70", "0.603006"], ["83983.70", "1.586859"], ["83985.70", "4.175944"], ["83987.70", "10.989326"], ["84029.60", "3.993514"], ["84038.00", "4.265799"], ["84054.80", "4.901131"], ["84063.20", "4.628846"], ["84071.60", "3.902753"], ["84080.00", "5.445701"], ["84088.40", "4.810369"], ["84096.80", "4.991893"], ["84105.20", "4.356561"], ["84113.60", "4.447323"], ["84122.00", "5.536463"], ["84130.40", "4.175038"], ["84138.80", "5.173416"], ["84147.20", "4.084276"], ["84155.60", "4.719608"], ["84164.00", "5.354940"], ["84180.80", "5.082654"], ["84189.20", "4.538084"], ["84339.29", "0.000029"], ["84339.50", "0.000323"]], "bids": [["83915.60", "0.004307"], ["83913.60", "0.011333"], ["83911.60", "0.029823"], ["83909.60", "0.078483"], ["83907.60", "0.206533"], ["83905.60", "0.543508"], ["83903.60", "1.430284"], ["83861.70", "4.810369"], ["83853.30", "4.991893"], ["83844.90", "4.356561"], ["83836.50", "4.719608"], ["83828.10", "5.173416"], ["83819.70", "4.175038"], ["83811.30", "5.445701"], ["83802.90", "5.082654"], ["83794.50", "3.902753"], ["83786.10", "5.264178"], ["83777.70", "5.354940"], ["83760.90", "3.993514"], ["83752.50", "4.538084"], ["83744.10", "5.627225"], ["83735.70", "4.447323"], ["83727.30", "4.901131"], ["83718.90", "4.265799"], ["83710.50", "4.628846"], ["83702.10", "5.536463"]], "checksum": -1702063917, "ts": "1742576911883"}], "ts": 1742576911886, "record_time": 1742576912.081642, "EXCHANGE": "BITGET"}
{"action": "update", "arg": {"instType": "SPOT", "channel": "books", "instId": "BTCUSDT"}, "data": [{"asks": [["83919.34", "0.848100"], ["83919.73", "0.043260"], ["83919.74", "0.091662"], ["84038.00", "5.536463"], ["84046.40", "4.810369"], ["84054.80", "4.628846"], ["84063.20", "3.902753"], ["84071.60", "4.538084"], ["84080.00", "5.082654"], ["84088.40", "4.447323"], ["84105.20", "4.719608"], ["84113.60", "4.356561"], ["84122.00", "4.901131"], ["84130.40", "5.264178"], ["84138.80", "4.265799"], ["84147.20", "5.445701"], ["84155.60", "5.354940"], ["84164.00", "5.173416"], ["84180.80", "4.175038"], ["84189.20", "4.084276"], ["84339.50", "0"]], "bids": [["83915.60", "0.004431"], ["83913.60", "0.011660"], ["83911.60", "0.030684"], ["83909.60", "0.080748"], ["83907.60", "0.212496"], ["83905.60", "0.559199"], ["83903.60", "1.471576"], ["83861.70", "5.627225"], ["83853.30", "4.265799"], ["83844.90", "4.991893"], ["83836.50", "4.628846"], ["83828.10", "5.536463"], ["83819.70", "4.901131"], ["83811.30", "4.538084"], ["83794.50", "4.719608"], ["83786.10", "4.810369"], ["83777.70", "3.993514"], ["83769.30", "5.445701"], ["83760.90", "4.356561"], ["83752.50", "5.354940"], ["83744.10", "5.264178"], ["83735.70", "3.902753"], ["83727.30", "5.173416"], ["83718.90", "4.084276"], ["83710.50", "4.175038"], ["83702.10", "4.447323"]], "checksum": 1113486490, "ts": "1742576912083"}], "ts": 1742576912087, "record_time": 1742576912.281762, "EXCHANGE": "BITGET"}
{"action": "update", "arg": {"instType": "SPOT", "channel": "books", "instId": "BTCUSDT"}, "data": [{"asks": [["83919.34", "1.061420"], ["83952.24", "0.006356"], ["83954.89", "0"], ["83974.47", "0.001598"], ["83976.37", "0.001598"], ["83980.71", "0"], ["83982.55", "0"], ["83993.10", "0"], ["83995.30", "2.359560"], ["83996.09", "0.027726"], ["84029.60", "5.354940"], ["84038.00", "4.628846"], ["84046.40", "3.902753"], ["84054.80", "4.719608"], ["84063.20", "4.265799"], ["84071.60", "5.536463"], ["84080.00", "4.356561"], ["84088.40", "4.084276"], ["84096.80", "3.993514"], ["84105.20", "4.901131"], ["84113.60", "4.175038"], ["84122.00", "5.627225"], ["84130.40", "4.538084"], ["84138.80", "5.264178"], ["84147.20", "4.447323"], ["84155.60", "4.810369"], ["84164.00", "5.082654"], ["84172.40", "4.991893"], ["84180.80", "5.173416"], ["84189.20", "5.445701"], ["84339.29", "0"]], "bids": [["83911.60", "0.030459"], ["83909.60", "0.080154"], ["83907.60", "0.210933"], ["83905.60", "0.555085"], ["83903.60", "1.460751"], ["83870.60", "0"], ["83868.58", "0"], ["83864.37", "0.001177"], ["83862.41", "0.001174"], ["83861.70", "4.810369"], ["83853.30", "4.901131"], ["83844.90", "5.082654"], ["83836.50", "4.265799"], ["83828.10", "4.356561"], ["83819.70", "5.173416"], ["83811.30", "4.175038"], ["83802.90", "5.627225"], ["83794.50", "5.264178"], ["83786.10", "5.354940"], ["83777.70", "5.445701"], ["83769.30", "3.993514"], ["83760.90", "3.902753"], ["83752.50", "4.538084"], ["83744.10", "4.447323"], ["83735.70", "4.991893"], ["83727.30", "4.719608"], ["83718.90", "5.536463"], ["83710.50", "4.628846"], ["83702.10", "4.084276"]], "checksum": 1199688846, "ts": "1742576912290"}], "ts": 1742576912293, "record_time": 1742576912.503687, "EXCHANGE": "BITGET"}
{"action": "update", "arg": {"instType": "SPOT", "channel": "books", "instId": "BTCUSDT"}, "data": [{"asks": [["83919.72", "0.091662"], ["83919.74", "0"], ["83967.70", "0.001236"], ["83969.70", "0.002016"], ["83971.70", "0.005306"], ["83973.70", "0.013963"], ["83975.70", "0.036744"], ["83977.70", "0.096695"], ["83979.70", "0.254460"], ["83981.70", "0.669632"], ["83983.70", "1.762191"], ["83985.70", "4.637343"], ["83987.70", "12.203534"], ["83987.90", "0.126480"], ["83988.30", "0"], ["83997.90", "0"], ["84009.92", "0"], ["84018.98", "0"], ["84029.60", "5.627225"], ["84038.00", "4.991893"], ["84046.40", "5.082654"], ["84054.80", "3.902753"], ["84063.20", "4.538084"], ["84071.60", "4.810369"], ["84080.00", "4.447323"], ["84088.40", "3.993514"], ["84096.80", "4.265799"], ["84105.20", "4.356561"], ["84113.60", "4.628846"], ["84122.00", "5.173416"], ["84124.67", "0"], ["84130.40", "5.445701"], ["84138.80", "5.354940"], ["84147.20", "4.175038"], ["84155.60", "5.264178"], ["84164.00", "4.084276"], ["84172.40", "4.901131"], ["84180.80", "5.536463"], ["84189.20", "4.719608"], ["84339.29", "0.000029"], ["84339.50", "0.000323"], ["84339.62", "0.000051"], ["84340.00", "0.018287"], ["84340.46", "0.000143"]], "bids": [["83917.60", "0.001023"], ["83915.60", "0.001097"], ["83913.60", "0.002652"], ["83911.60", "0.006981"], ["83909.60", "0.018370"], ["83907.60", "0.048343"], ["83905.60", "0.127217"], ["83903.60", "0.334781"], ["83902.30", "0"], ["83892.70", "0.009000"], ["83861.70", "4.991893"], ["83860.00", "0"], ["83853.30", "4.810369"], ["83844.90", "5.173416"], ["83836.50", "4.628846"], ["83828.10", "4.175038"], ["83823.74", "0"], ["83819.70", "4.538084"], ["83815.36", "0"], ["83811.30", "5.354940"], ["83802.90", "5.445701"], ["83794.50", "4.356561"], ["83786.10", "3.902753"], ["83777.70", "4.447323"], ["83769.30", "5.536463"], ["83760.90", "4.265799"], ["83752.50", "4.719608"], ["83744.10", "4.084276"], ["83735.70", "3.993514"], ["83727.30", "5.627225"], ["83718.90", "5.082654"], ["83710.50", "5.264178"], ["83702.10", "4.901131"], ["83458.10", "0.000011"], ["83457.63", "0.000023"], ["83456.52", "0.000010"]], "checksum": -1006953648, "ts": "1742576912495"}], "ts": 1742576912499, "record_time": 1742576912.703283, "EXCHANGE": "BITGET"}
{"action": "update", "arg": {"instType": "SPOT", "channel": "books", "instId": "BTCUSDT"}, "data": [{"asks": [["83919.35", "0.000100"], ["83950.99", "0.112555"], ["83987.90", "0.126690"], ["83996.09", "0"], ["83997.90", "0.204000"], ["84018.97", "0"], ["84029.60", "5.536463"], ["84038.00", "4.538084"], ["84046.40", "3.902753"], ["84054.80", "4.810369"], ["84063.20", "4.175038"], ["84071.60", "4.991893"], ["84080.00", "4.265799"], ["84088.40", "5.173416"], ["84096.80", "4.356561"], ["84105.20", "4.084276"], ["84113.60", "5.445701"], ["84122.00", "5.627225"], ["84130.40", "4.628846"], ["84138.80", "5.082654"], ["84147.20", "5.354940"], ["84155.60", "4.447323"], ["84164.00", "4.901131"], ["84172.40", "4.719608"], ["84180.80", "3.993514"], ["84189.20", "5.264178"]], "bids": [["83915.60", "0.001680"], ["83913.60", "0.004657"], ["83911.60", "0.012257"], ["83909.61", "0.081490"], ["83909.60", "0.032255"], ["83907.60", "0.084880"], ["83905.60", "0.223370"], ["83905.44", "0"], ["83903.60", "0.587816"], ["83903.20", "0.006060"], ["83901.00", "0.070920"], ["83900.00", "0.967170"], ["83893.10", "0"], ["83892.70", "0"], ["83861.70", "4.356561"], ["83861.00", "0"], ["83853.30", "5.445701"], ["83844.90", "4.084276"], ["83836.50", "4.175038"], ["83828.10", "5.354940"], ["83819.70", "4.901131"], ["83811.30", "4.265799"], ["83802.90", "5.627225"], ["83794.50", "5.264178"], ["83786.10", "4.991893"], ["83769.30", "5.082654"], ["83760.90", "4.810369"], ["83752.50", "5.536463"], ["83744.10", "4.719608"], ["83727.30", "4.538084"], ["83718.90", "4.628846"], ["83710.50", "5.173416"], ["83702.10", "3.902753"], ["83456.00", "0.000133"], ["83455.56", "0.000025"], ["83455.07", "0.000013"]], "checksum": 462575449, "ts": "1742576912694"}], "ts": 1742576912698, "record_time": 1742576912.893214, "EXCHANGE": "BITGET"}
{"action": "update", "arg": {"instType": "SPOT", "channel": "books", "instId": "BTCUSDT"}, "data": [{"asks": [["83919.72", "0"], ["83975.70", "0.036927"], ["83977.70", "0.097178"], ["83979.70", "0.255731"], ["83981.70", "0.672977"], ["83983.70", "1.770992"], ["83985.70", "4.660505"], ["83987.70", "12.264487"], ["83997.90", "0"], ["84014.63", "0.001810"], ["84023.68", "0.003620"], ["84029.60", "4.628846"], ["84038.00", "4.175038"], ["84046.40", "5.264178"], ["84054.80", "5.445701"], ["84063.20", "3.902753"], ["84080.00", "5.627225"], ["84088.40", "3.993514"], ["84096.80", "5.536463"], ["84105.20", "4.538084"], ["84113.60", "4.084276"], ["84116.02", "0.164017"], ["84122.00", "4.901131"], ["84130.40", "4.356561"], ["84138.80", "5.173416"], ["84147.20", "4.719608"], ["84164.00", "4.810369"], ["84172.40", "4.265799"], ["84180.80", "5.082654"], ["84189.20", "5.354940"], ["84340.46", "0"]], "bids": [["83919.33", "1.059446"], ["83915.60", "0.001681"], ["83913.60", "0.004659"], ["83911.60", "0.012261"], ["83909.60", "0.032267"], ["83908.90", "0"], ["83907.60", "0.084913"], ["83905.60", "0.223455"], ["83905.44", "0.410311"], ["83903.60", "0.588039"], ["83861.70", "4.175038"], ["83853.30", "3.993514"], ["83844.90", "5.536463"], ["83836.50", "5.082654"], ["83829.33", "0.001810"], ["83828.10", "4.447323"], ["83820.95", "0.003620"], ["83819.70", "3.902753"], ["83811.30", "5.173416"], ["83802.90", "4.901131"], ["83794.50", "4.810369"], ["83786.10", "4.538084"], ["83777.70", "4.084276"], ["83769.30", "4.991893"], ["83760.90", "4.628846"], ["83752.50", "5.445701"], ["83744.10", "5.627225"], ["83735.70", "4.719608"], ["83727.30", "5.354940"], ["83718.90", "5.264178"], ["83710.50", "4.265799"], ["83702.10", "4.356561"], ["83455.56", "0"], ["83455.07", "0"]], "checksum": 1926949026, "ts": "1742576912894"}], "ts": 1742576912896, "record_time": 1742576913.092257, "EXCHANGE": "BITGET"}
{"action": "update", "arg": {"instType": "SPOT", "channel": "books", "instId": "BTCUSDT"}, "data": [{"asks": [["83919.71", "0.091662"], ["83944.32", "0.016429"], ["83945.19", "0.119901"], ["83946.24", "0"], ["83946.97", "0"], ["83947.66", "0.009990"], ["83949.55", "0"], ["83950.20", "0.009989"], ["83952.11", "0"], ["83953.97", "0.015896"], ["83955.91", "0"], ["83981.70", "0.672726"], ["83983.70", "1.770331"], ["83985.70", "4.658766"], ["83987.70", "12.259911"], ["83991.80", "0.015000"], ["84029.60", "4.356561"], ["84038.00", "5.627225"], ["84046.40", "5.354940"], ["84054.80", "4.628846"], ["84063.20", "5.082654"], ["84071.60", "5.445701"], ["84080.00", "4.084276"], ["84088.40", "4.447323"], ["84096.80", "4.810369"], ["84105.20", "3.902753"], ["84113.60", "5.173416"], ["84122.00", "5.264178"], ["84130.40", "4.538084"], ["84138.80", "4.901131"], ["84147.20", "4.265799"], ["84155.60", "3.993514"], ["84164.00", "4.991893"], ["84172.40", "4.175038"], ["84180.80", "5.536463"], ["84189.20", "4.719608"], ["84340.00", "0"]], "bids": [["83917.61", "0"], ["83916.14", "0.114328"], ["83909.61", "0.035173"], ["83907.60", "0.084757"], ["83905.60", "0.223045"], ["83903.60", "0.586960"], ["83902.30", "0.204856"], ["83897.98", "0"], ["83896.73", "0"], ["83895.78", "0"], ["83895.40", "0.004036"], ["83894.81", "0.028874"], ["83894.00", "0.234087"], ["83893.32", "0"], ["83891.43", "0.018549"], ["83890.85", "0"], ["83888.94", "0.021166"], ["83887.09", "0"], ["83885.16", "0.073185"], ["83884.92", "0"], ["83882.79", "0.000878"], ["83872.90", "0.207210"], ["83861.70", "5.354940"], ["83853.30", "4.084276"], ["83844.90", "3.993514"], ["83836.50", "5.445701"], ["83828.10", "4.901131"], ["83819.70", "4.356561"], ["83811.30", "3.902753"], ["83802.90", "5.082654"], ["83794.50", "5.536463"], ["83786.10", "5.173416"], ["83777.70", "4.628846"], ["83769.30", "5.264178"], ["83760.90", "4.991893"], ["83752.50", "4.175038"], ["83744.10", "4.810369"], ["83735.70", "4.447323"], ["83727.30", "4.538084"], ["83718.90", "4.719608"], ["83710.50", "5.627225"], ["83702.10", "4.265799"], ["83456.00", "0"]], "checksum": 1067364610, "ts": "1742576913100"}], "ts": 1742576913103, "record_time": 1742576913.298569, "EXCHANGE": "BITGET"}
{"action": "update", "arg": {"instType": "SPOT", "channel": "books", "instId": "BTCUSDT"}, "data": [{"asks": [["83919.34", "0.630280"], ["83919.35", "0.001068"], ["83919.73", "0"], ["83967.70", "0.001112"], ["83969.70", "0.001815"], ["83971.70", "0.004776"], ["83973.70", "0.012568"], ["83975.70", "0.033075"], ["83977.70", "0.087038"], ["83979.70", "0.229047"], ["83981.70", "0.602755"], ["83983.70", "1.586198"], ["83985.70", "4.174205"], ["83987.70", "10.984751"], ["83991.60", "0.814140"], ["83994.40", "0.028980"], ["83994.90", "2.359590"], ["83995.30", "0"], ["83996.10", "3.433080"], ["83997.90", "0.204000"], ["84007.20", "0.000179"], ["84007.39", "0"], ["84038.00", "4.175038"], ["84046.40", "4.991893"], ["84054.80", "3.993514"], ["84063.20", "4.447323"], ["84071.60", "5.627225"], ["84080.00", "4.810369"], ["84088.40", "5.264178"], ["84096.80", "5.173416"], ["84105.20", "5.445701"], ["84113.60", "4.084276"], ["84122.00", "4.628846"], ["84130.40", "4.719608"], ["84138.80", "4.265799"], ["84147.20", "5.536463"], ["84155.60", "4.901131"], ["84164.00", "4.538084"], ["84172.40", "3.902753"], ["84180.80", "5.354940"], ["84189.20", "5.082654"]], "bids": [["83915.60", "0.002527"], ["83913.60", "0.006651"], ["83911.60", "0.017502"], ["83909.60", "0.046057"], ["83907.60", "0.121204"], ["83905.60", "0.318958"], ["83903.60", "0.839362"], ["83902.71", "1.242794"], ["83902.50", "0.813750"], ["83901.20", "0.188190"], ["83900.00", "0.042300"], ["83897.11", "0"], ["83869.00", "0.000032"], ["83868.00", "0.000017"], ["83861.70", "4.719608"], ["83853.30", "4.538084"], ["83844.90", "4.447323"], ["83837.90", "0"], ["83837.72", "0.000172"], ["83836.50", "4.084276"], ["83828.10", "5.082654"], ["83811.30", "4.628846"], ["83802.90", "4.265799"], ["83786.10", "4.991893"], ["83777.70", "5.173416"], ["83769.30", "5.445701"], ["83760.90", "5.627225"], ["83752.50", "3.902753"], ["83744.10", "5.264178"], ["83735.70", "5.354940"], ["83727.30", "4.901131"], ["83718.90", "4.810369"], ["83710.50", "3.993514"], ["83702.10", "4.175038"], ["83456.52", "0"]], "checksum": -1247763619, "ts": "1742576913300"}], "ts": 1742576913302, "record_time": 1742576913.523231, "EXCHANGE": "BITGET"}
{"action": "update", "arg": {"instType": "SPOT", "channel": "books", "instId": "BTCUSDT"}, "data": [{"asks": [["83919.70", "0.091662"], ["83919.71", "0"], ["83954.97", "0.010988"], ["83957.14", "0"], ["83967.70", "0.001000"], ["83969.70", "0.001505"], ["83971.70", "0.003962"], ["83973.70", "0.010426"], ["83975.69", "0.001356"], ["83975.70", "0.027436"], ["83977.70", "0.072200"], ["83979.70", "0.190000"], ["83981.70", "0.500000"], ["83983.70", "1.315791"], ["83985.70", "3.462606"], ["83987.70", "9.112121"], ["83994.40", "0.017850"], ["83994.90", "0"], ["83996.60", "2.359530"], ["83997.90", "0.294000"], ["84029.60", "3.993514"], ["84038.00", "4.810369"], ["84046.40", "4.447323"], ["84054.80", "5.536463"], ["84063.20", "4.538084"], ["84071.60", "5.445701"], ["84080.00", "4.175038"], ["84088.40", "5.173416"], ["84096.80", "5.627225"], ["84105.20", "4.719608"], ["84113.60", "4.356561"], ["84122.00", "4.991893"], ["84130.40", "4.084276"], ["84138.80", "5.354940"], ["84147.20", "4.901131"], ["84155.60", "3.902753"], ["84164.00", "4.265799"], ["84172.40", "4.628846"], ["84180.80", "5.264178"], ["84339.62", "0"]], "bids": [["83919.33", "1.073284"], ["83917.60", "0.003202"], ["83915.60", "0.008428"], ["83913.60", "0.022177"], ["83911.60", "0.058362"], ["83910.52", "0"], ["83909.60", "0.153584"], ["83907.60", "0.404168"], ["83905.60", "1.063599"], ["83903.60", "2.798947"], ["83902.50", "0"], ["83901.20", "0.372960"], ["83897.11", "0.218711"], ["83896.30", "0.724080"], ["83895.20", "1.440000"], ["83894.71", "0.024893"], ["83886.64", "0.008934"], ["83884.48", "0.056464"], ["83881.00", "0.000032"], ["83866.03", "0"], ["83864.16", "0.003603"], ["83861.70", "5.445701"], ["83853.30", "4.901131"], ["83844.90", "4.175038"], ["83828.10", "4.991893"], ["83819.70", "5.536463"], ["83811.30", "5.264178"], ["83802.90", "3.993514"], ["83794.50", "4.538084"], ["83786.10", "4.265799"], ["83777.70", "4.447323"], ["83769.30", "5.627225"], ["83760.90", "5.354940"], ["83752.50", "5.173416"], ["83744.10", "4.719608"], ["83735.70", "4.810369"], ["83727.30", "3.902753"], ["83718.90", "4.356561"], ["83710.50", "5.082654"], ["83702.10", "4.628846"], ["83457.63", "0"]], "checksum": 2037331660, "ts": "1742576913515"}], "ts": 1742576913517, "record_time": 1742576913.713807, "EXCHANGE": "BITGET"}
{"action": "update", "arg": {"instType": "SPOT", "channel": "books", "instId": "BTCUSDT"}, "data": [{"asks": [["83919.34", "0.016821"], ["83919.70", "0"], ["83924.06", "0"], ["83925.41", "0"], ["83929.78", "0"], ["83929.79", "0"], ["83934.00", "0"], ["83934.01", "0"], ["83940.86", "0"], ["83940.87", "0"], ["83941.29", "0"], ["83941.56", "0"], ["83942.09", "0"], ["83942.37", "0"], ["83942.58", "0"], ["83942.61", "0"], ["83942.95", "0"], ["83943.47", "0"], ["83944.12", "0"], ["83944.52", "0"], ["83944.61", "0"], ["83945.06", "0"], ["83945.11", "0"], ["83945.81", "0"], ["83945.82", "0"], ["83945.97", "0"], ["83946.64", "0"], ["83948.40", "0"], ["83950.99", "0"], ["83953.74", "0"], ["83954.43", "0"], ["83957.32", "0"], ["83957.33", "0"], ["83966.70", "0.064596"], ["83969.70", "0.001395"], ["83971.70", "0.003670"], ["83972.48", "0"], ["83973.70", "0.009658"], ["83975.70", "0.025418"], ["83977.70", "0.066889"], ["83979.70", "0.176022"], ["83979.85", "0"], ["83981.70", "0.463216"], ["83983.70", "1.218990"], ["83985.70", "3.207868"], ["83987.70", "8.441759"], ["83993.20", "0.545400"], ["83997.90", "0.204000"], ["84038.00", "4.084276"], ["84046.40", "4.991893"], ["84054.80", "3.902753"], ["84063.20", "4.175038"], ["84071.60", "4.447323"], ["84080.00", "4.265799"], ["84082.46", "0"], ["84088.40", "4.901131"], ["84096.80", "5.173416"], ["84105.20", "4.356561"], ["84113.60", "5.627225"], ["84122.00", "4.719608"], ["84130.40", "5.354940"], ["84138.80", "4.628846"], ["84147.20", "5.264178"], ["84155.60", "5.536463"], ["84164.00", "5.445701"], ["84172.40", "5.082654"], ["84180.80", "4.538084"], ["84189.20", "4.810369"], ["84339.62", "0.000051"], ["84340.00", "0.018287"], ["84340.46", "0.000143"], ["84340.72", "0.000066"], ["84341.00", "0.002997"], ["84341.01", "0.000008"], ["84342.11", "0.000051"], ["84342.63", "0.000009"], ["84342.70", "0.000423"], ["84343.02", "0.000338"], ["84343.07", "0.000014"], ["84343.70", "0.000075"], ["84343.97", "0.000188"], ["84344.77", "0.000361"], ["84345.79", "0.000034"], ["84346.43", "0.000128"], ["84346.94", "0.000085"], ["84346.97", "0.000030"], ["84347.55", "0.000095"], ["84347.69", "0.000009"], ["84347.83", "0.016818"], ["84348.21", "0.000036"], ["84348.27", "0.012402"], ["84348.62", "0.000072"], ["84350.00", "0.000041"], ["84350.79", "0.000033"], ["84351.64", "0.000102"], ["84354.58", "0.000115"], ["84354.64", "0.000018"], ["84354.82", "0.000078"], ["84354.84", "0.000194"], ["84355.00", "0.000297"], ["84356.98", "0.000048"], ["84357.14", "0.000342"]], "bids": [["83917.60", "0.002143"], ["83915.60", "0.005641"], ["83913.60", "0.014845"], ["83911.60", "0.039065"], ["83909.61", "0.162948"], ["83909.60", "0.102802"], ["83908.58", "0.314594"], ["83907.60", "0.270531"], ["83905.60", "0.711924"], ["83903.60", "1.873485"], ["83902.30", "0"], ["83901.20", "0.372750"], ["83900.20", "0.160890"], ["83899.80", "0.074040"], ["83898.76", "0"], ["83897.11", "0"], ["83897.10", "0"], ["83897.09", "0"], ["83896.60", "0"], ["83896.22", "0"], ["83896.09", "0.017830"], ["83895.45", "0"], ["83894.96", "0"], ["83894.71", "0"], ["83894.60", "0"], ["83894.27", "0"], ["83894.09", "0"], ["83894.00", "0.225077"], ["83893.95", "0"], ["83893.87", "0"], ["83893.58", "0"], ["83892.43", "0"], ["83892.10", "0"], ["83890.32", "0"], ["83861.70", "5.354940"], ["83853.30", "5.082654"], ["83844.90", "4.991893"], ["83836.50", "5.445701"], ["83828.10", "4.356561"], ["83819.70", "4.810369"], ["83811.30", "4.447323"], ["83802.90", "4.265799"], ["83794.50", "5.627225"], ["83786.10", "4.538084"], ["83777.70", "5.264178"], ["83769.30", "5.173416"], ["83760.90", "4.175038"], ["83752.50", "4.628846"], ["83744.10", "3.902753"], ["83735.70", "4.719608"], ["83727.30", "4.901131"], ["83718.90", "5.536463"], ["83710.50", "4.084276"], ["83702.10", "3.993514"], ["83457.63", "0.000023"], ["83456.52", "0.000010"], ["83456.00", "0.000133"], ["83455.56", "0.000025"], ["83455.07", "0.000013"], ["83454.55", "0.000027"], ["83454.54", "0.001547"], ["83454.53", "0.000057"], ["83453.95", "0.000093"], ["83453.56", "0.000022"], ["83452.83", "0.000008"], ["83451.33", "0.000010"], ["83450.00", "0.005575"], ["83448.28", "0.000151"], ["83448.14", "0.000070"], ["83448.00", "0.000012"], ["83447.32", "0.000009"]], "checksum": -2102692003, "ts": "1742576913726"}], "ts": 1742576913732, "record_time": 1742576913.929943, "EXCHANGE": "BITGET"}
{"action": "update", "arg": {"instType": "SPOT", "channel": "books", "instId": "BTCUSDT"}, "data": [{"asks": [["83919.34", "0"], ["83919.35", "0"], ["83919.36", "0"], ["83919.37", "0"], ["83927.33", "0"], ["83931.52", "0"], ["83940.00", "0.484128"], ["83940.15", "0.004587"], ["83941.62", "0"], ["83941.77", "0"], ["83942.04", "0"], ["83943.45", "0"], ["83943.60", "0"], ["83944.32", "0"], ["83945.12", "0"], ["83945.19", "0"], ["83945.63", "0"], ["83946.63", "0"], ["83947.66", "0"], ["83948.78", "0"], ["83949.36", "0"], ["83950.20", "0"], ["83950.91", "0.035971"], ["83951.38", "0.119905"], ["83951.69", "0"], ["83951.93", "0"], ["83952.24", "0"], ["83952.58", "0.006357"], ["83952.79", "0.006357"], ["83952.82", "0.035972"], ["83953.30", "0.006357"], ["83953.38", "0.006357"], ["83953.51", "0.006357"], ["83953.67", "0.006357"], ["83953.97", "0"], ["83954.09", "0.006357"], ["83954.10", "0.006357"], ["83954.20", "0.006357"], ["83954.38", "0.006357"], ["83954.82", "0.010995"], ["83954.83", "0.006357"], ["83954.97", "0.006357"], ["83955.67", "0.006356"], ["83956.46", "0.119901"], ["83956.59", "0.016429"], ["83956.74", "0.006357"], ["83957.49", "0.006357"], ["83958.20", "0.010993"], ["83958.29", "0.006357"], ["83958.62", "0.016429"], ["83958.86", "0.119850"], ["83958.97", "0.009990"], ["83960.46", "0.117600"], ["83960.96", "0.119858"], ["83961.37", "0.015895"], ["83961.49", "0.009989"], ["83962.09", "0.119905"], ["83965.06", "0.017477"], ["83966.39", "0.010988"], ["83966.64", "0.006356"], ["83967.70", "0"], ["83968.27", "0.015896"], ["83968.43", "0"], ["83969.70", "0"], ["83971.70", "0"], ["83972.47", "0.003377"], ["83973.70", "0"], ["83975.70", "0"], ["83977.70", "0"], ["83979.70", "0"], ["83980.30", "0.001012"], ["83981.44", "0.314594"], ["83981.70", "0"], ["83982.30", "0.001037"], ["83983.70", "0"], ["83984.30", "0.001999"], ["83985.70", "0"], ["83986.30", "0.005261"], ["83987.61", "0.714391"], ["83987.70", "0"], ["83987.90", "0"], ["83988.10", "0"], ["83988.20", "0"], ["83988.30", "0.013844"], ["83990.00", "0"], ["83990.30", "0.036432"], ["83991.20", "0"], ["83991.50", "0"], ["83991.60", "0"], ["83991.80", "0"], ["83992.20", "0"], ["83992.30", "0.095873"], ["83993.20", "0"], ["83993.60", "0"], ["83993.70", "0"], ["83994.20", "0"], ["83994.30", "0.252297"], ["83994.40", "0"], ["83994.80", "0"], ["83995.70", "0"], ["83996.10", "0"], ["83996.30", "0.663939"], ["83996.50", "0"], ["83996.60", "0"], ["83996.80", "0"], ["83996.90", "0"], ["83997.00", "0"], ["83997.80", "0"], ["83997.90", "0"], ["83998.30", "1.747210"], ["84000.30", "4.597920"], ["84000.40", "0.001036"], ["84000.60", "0.011790"], ["84002.00", "0.077940"], ["84003.90", "0.158850"], ["84004.00", "0.042300"], ["84004.40", "0.012240"], ["84005.00", "0.592110"], ["84006.00", "0.048600"], ["84006.60", "0.009000"], ["84007.40", "0.090000"], ["84008.70", "1.350000"], ["84010.00", "0.006300"], ["84012.00", "0.009000"], ["84012.80", "0.035700"], ["84013.70", "0.070620"], ["84014.00", "0.006300"], ["84016.00", "0.244770"], ["84016.80", "0.035730"], ["84017.00", "2.016210"], ["84017.10", "1.350000"], ["84017.60", "0.478110"], ["84029.60", "0"], ["84038.00", "0"], ["84042.30", "5.535633"], ["84046.40", "0"], ["84048.35", "0"], ["84050.16", "0"], ["84050.70", "4.718901"], ["84054.80", "0"], ["84059.10", "4.083664"], ["84063.20", "0"], ["84067.50", "3.992916"], ["84071.60", "0"], ["84075.90", "4.628153"], ["84076.89", "0.071668"], ["84080.00", "0"], ["84084.30", "3.902168"], ["84088.40", "0"], ["84088.60", "0.071678"], ["84092.70", "4.446656"], ["84096.80", "0"], ["84101.10", "4.809649"], ["84104.00", "0"], ["84105.20", "0"], ["84109.50", "4.174412"], ["84113.60", "0"], ["84117.90", "4.355908"], ["84122.00", "0"], ["84126.30", "5.081893"], ["84130.40", "0"], ["84134.70", "4.991145"], ["84138.80", "0"], ["84143.10", "5.626381"], ["84147.20", "0"], ["84151.50", "4.265160"], ["84155.60", "0"], ["84157.75", "0.027677"], ["84159.90", "5.263389"], ["84164.00", "0"], ["84168.30", "5.354137"], ["84172.40", "0"], ["84176.70", "4.537404"], ["84180.80", "0"], ["84185.10", "4.900397"], ["84189.20", "0"], ["84193.50", "5.172641"], ["84201.90", "5.444885"], ["84285.09", "0.209200"], ["84310.29", "0.209200"], ["84348.62", "0"], ["84350.00", "0"], ["84350.79", "0"], ["84351.64", "0"], ["84354.58", "0"], ["84354.64", "0"], ["84354.82", "0"], ["84354.84", "0"], ["84355.00", "0"], ["84356.98", "0"], ["84357.14", "0"]], "bids": [["83939.99", "0.400117"], ["83938.76", "0.209200"], ["83936.20", "0.001095"], ["83934.20", "0.001223"], ["83932.20", "0.003217"], ["83931.51", "0.038719"], ["83930.20", "0.008466"], ["83929.78", "0.240300"], ["83929.00", "0.007599"], ["83928.20", "0.022279"], ["83927.72", "0.209200"], ["83926.20", "0.058629"], ["83924.75", "0.009904"], ["83924.20", "0.154288"], ["83923.53", "0.245840"], ["83922.20", "0.406021"], ["83920.20", "1.068475"], ["83919.34", "0.053815"], ["83919.33", "0.278980"], ["83918.20", "2.811778"], ["83917.60", "0"], ["83916.74", "0"], ["83916.20", "7.399415"], ["83916.14", "0"], ["83916.00", "1.872270"], ["83915.70", "0.161490"], ["83915.60", "0"], ["83915.30", "0.142680"], ["83914.31", "0.018590"], ["83914.00", "0.042480"], ["83913.60", "2.681940"], ["83912.32", "0.008279"], ["83912.00", "0.042480"], ["83911.93", "0"], ["83911.86", "0"], ["83911.60", "0"], ["83911.00", "2.320590"], ["83910.90", "2.681940"], ["83910.66", "0.008074"], ["83910.62", "0.089672"], ["83910.60", "0.240000"], ["83910.35", "0.017826"], ["83910.26", "0.247539"], ["83910.10", "0.607890"], ["83910.00", "0.042300"], ["83909.90", "0.204856"], ["83909.70", "2.681760"], ["83909.60", "0.437100"], ["83909.17", "0.083636"], ["83909.10", "0.028874"], ["83908.70", "0.493980"], ["83908.62", "0.007828"], ["83908.56", "0.018272"], ["83908.53", "0.007389"], ["83908.52", "0.009567"], ["83908.49", "0.018068"], ["83908.45", "0.011816"], ["83908.44", "0.009326"], ["83908.00", "0.042300"], ["83907.60", "1.430250"], ["83907.49", "0.017123"], ["83907.17", "0.016432"], ["83907.15", "0.055636"], ["83907.09", "0.005949"], ["83907.00", "0.071460"], ["83906.70", "0.120000"], ["83906.58", "0.022322"], ["83906.40", "0.209160"], ["83906.00", "0.057300"], ["83905.96", "0.006978"], ["83905.91", "0.007202"], ["83905.90", "0.008605"], ["83905.85", "0.008530"], ["83905.84", "0.019484"], ["83905.83", "0.022827"], ["83905.82", "0.014151"], ["83905.80", "0.005946"], ["83905.79", "0.009262"], ["83905.60", "0.015000"], ["83905.44", "0.744723"], ["83905.43", "0"], ["83905.39", "0.025198"], ["83905.21", "0.233245"], ["83904.70", "0.120000"], ["83904.60", "0.324300"], ["83904.56", "0.007347"], ["83904.00", "0.072300"], ["83903.97", "0.007140"], ["83903.94", "0.008290"], ["83903.87", "0.009010"], ["83903.86", "0.007955"], ["83903.80", "0.178650"], ["83903.73", "0.012674"], ["83903.70", "1.066050"], ["83903.69", "0.051845"], ["83903.60", "7.892310"], ["83903.50", "0"], ["83903.46", "0.017114"], ["83903.40", "0.178770"], ["83902.90", "4.508880"], ["83902.74", "0.018549"], ["83902.71", "0.892135"], ["83902.70", "0"], ["83902.52", "0.017376"], ["83902.00", "0.000032"], ["83901.66", "0.259208"], ["83901.34", "0.020567"], ["83901.33", "0"], ["83901.32", "0.013444"], ["83901.31", "0.013618"], ["83901.26", "0.005612"], ["83901.24", "0.004861"], ["83901.22", "0.005181"], ["83901.20", "0"], ["83901.00", "0.000032"], ["83900.91", "0"], ["83900.86", "0.223051"], ["83900.78", "0.268837"], ["83900.44", "0.076243"], ["83900.26", "0"], ["83900.22", "0.021166"], ["83900.20", "0"], ["83900.00", "0.000032"], ["83899.96", "0"], ["83899.80", "0"], ["83899.67", "0"], ["83899.59", "0.017477"], ["83899.44", "0.073185"], ["83898.73", "0.008934"], ["83898.71", "0.010362"], ["83898.70", "0.008778"], ["83898.01", "0"], ["83898.00", "0.000032"], ["83897.96", "0"], ["83897.95", "0.715154"], ["83897.70", "0"], ["83897.50", "0"], ["83897.07", "0.000878"], ["83896.95", "0"], ["83896.90", "0"], ["83896.50", "0"], ["83896.30", "0"], ["83896.17", "0"], ["83896.09", "0"], ["83896.08", "0"], ["83896.04", "0"], ["83896.01", "0"], ["83896.00", "0.000032"], ["83895.95", "0"], ["83895.94", "0"], ["83895.89", "0.056464"], ["83895.80", "0"], ["83895.60", "0"], ["83895.40", "0"], ["83895.30", "0"], ["83895.28", "0"], ["83895.21", "0"], ["83895.20", "0"], ["83895.00", "0.000032"], ["83894.90", "0"], ["83894.81", "0"], ["83894.70", "0"], ["83894.50", "0"], ["83894.00", "0.000032"], ["83893.83", "0"], ["83893.82", "0"], ["83893.76", "0"], ["83893.74", "0"], ["83893.73", "0"], ["83893.72", "0"], ["83893.70", "0"], ["83893.67", "0"], ["83893.66", "0"], ["83893.65", "0"], ["83893.64", "0"], ["83893.60", "0"], ["83893.20", "0"], ["83892.09", "0"], ["83891.43", "0"], ["83891.27", "0"], ["83891.01", "0"], ["83889.28", "0"], ["83888.94", "0"], ["83888.92", "0"], ["83888.91", "0"], ["83888.90", "0"], ["83888.89", "0"], ["83888.86", "0"], ["83888.83", "0"], ["83888.81", "0"], ["83886.85", "0"], ["83886.77", "0.071668"], ["83886.64", "0"], ["83886.62", "0"], ["83886.55", "0"], ["83885.78", "0"], ["83885.65", "0.007448"], ["83885.16", "0"], ["83884.48", "0"], ["83883.32", "0"], ["83882.79", "0"], ["83882.75", "0.008588"], ["83878.63", "0.071678"], ["83877.33", "0.007350"], ["83877.26", "0.007260"], ["83877.20", "0.007665"], ["83874.20", "4.991145"], ["83873.22", "0"], ["83872.90", "0"], ["83870.25", "0"], ["83865.80", "4.718901"], ["83865.24", "0"], ["83865.17", "0"], ["83863.73", "0"], ["83861.70", "0"], ["83857.40", "4.446656"], ["83853.30", "0"], ["83852.04", "0"], ["83849.00", "4.265160"], ["83844.90", "0"], ["83844.00", "0"], ["83840.60", "3.902168"], ["83839.90", "0"], ["83836.50", "0"], ["83832.20", "5.535633"], ["83828.10", "0"], ["83823.80", "4.900397"], ["83819.70", "0"], ["83815.40", "5.626381"], ["83811.30", "0"], ["83807.00", "5.172641"], ["83802.90", "0"], ["83798.60", "4.809649"], ["83798.26", "0"], ["83794.50", "0"], ["83790.20", "5.263389"], ["83789.86", "0"], ["83786.10", "0"], ["83781.80", "4.174412"], ["83777.70", "0"], ["83773.40", "4.537404"], ["83769.30", "0"], ["83765.00", "5.081893"], ["83760.90", "0"], ["83756.60", "4.083664"], ["83752.50", "0"], ["83748.20", "4.628153"], ["83744.30", "0.001434"], ["83744.10", "0"], ["83739.80", "3.992916"], ["83735.70", "0"], ["83731.40", "4.355908"], ["83727.30", "0"], ["83723.00", "5.354137"], ["83718.90", "0"], ["83714.60", "5.444885"], ["83710.50", "0"], ["83702.10", "0"], ["83668.70", "0"], ["83576.25", "0"], ["83456.00", "0"], ["83455.56", "0"], ["83455.07", "0"], ["83454.55", "0"], ["83454.54", "0"], ["83454.53", "0"], ["83453.95", "0"], ["83453.56", "0"], ["83452.83", "0"], ["83451.33", "0"], ["83450.00", "0"], ["83448.28", "0"], ["83448.14", "0"], ["83448.00", "0"], ["83447.32", "0"]], "checksum": -2004453816, "ts": "1742576913926"}], "ts": 1742576913935, "record_time": 1742576914.134823, "EXCHANGE": "BITGET"}
{"action": "update", "arg": {"instType": "SPOT", "channel": "books", "instId": "BTCUSDT"}, "data": [{"asks": [["83940.00", "1.101563"], ["83949.98", "0.114324"], ["83950.99", "0.135195"], ["83954.58", "0.002383"], ["83954.82", "0.061429"], ["83963.00", "0"], ["83972.47", "0"], ["83975.69", "0"], ["83984.30", "0.001954"], ["83986.00", "0.000976"], ["83986.30", "0.005142"], ["83987.13", "0.191553"], ["83988.30", "0.013532"], ["83990.30", "0.035609"], ["83991.54", "0.010000"], ["83992.30", "0.093709"], ["83994.30", "0.246602"], ["83996.30", "0.648953"], ["83998.30", "1.707770"], ["84000.30", "4.494132"], ["84000.40", "0.472500"], ["84000.60", "0.011580"], ["84001.60", "0.310800"], ["84004.00", "0.111060"], ["84004.40", "0.027240"], ["84005.00", "0.591690"], ["84008.60", "0.409830"], ["84012.80", "0.024240"], ["84013.40", "0.384000"], ["84013.70", "0"], ["84014.10", "0.070080"], ["84014.30", "0.180000"], ["84014.60", "2.852910"], ["84016.00", "0"], ["84016.80", "0"], ["84017.00", "0"], ["84017.10", "0"], ["84017.60", "0"], ["84042.30", "5.626381"], ["84050.70", "4.446656"], ["84059.10", "4.265160"], ["84067.50", "4.809649"], ["84075.90", "3.992916"], ["84084.30", "5.444885"], ["84092.70", "5.535633"], ["84101.10", "4.537404"], ["84109.50", "4.355908"], ["84117.90", "4.991145"], ["84126.30", "4.718901"], ["84134.70", "5.172641"], ["84143.10", "4.083664"], ["84151.50", "5.081893"], ["84159.90", "4.174412"], ["84168.30", "4.900397"], ["84176.70", "5.263389"], ["84185.10", "5.354137"], ["84193.50", "4.628153"], ["84201.90", "3.902168"], ["84347.83", "0"], ["84348.21", "0"], ["84348.27", "0"]], "bids": [["83939.99", "1.008000"], ["83938.77", "0.062760"], ["83934.20", "0.001061"], ["83933.71", "0.114324"], ["83932.20", "0.002792"], ["83930.20", "0.007348"], ["83929.79", "0.074370"], ["83928.20", "0.019337"], ["83927.73", "0.083320"], ["83927.22", "0.314594"], ["83926.20", "0.050886"], ["83924.20", "0.133909"], ["83923.53", "0"], ["83922.20", "0.352393"], ["83920.20", "0.927351"], ["83919.33", "0.107256"], ["83918.20", "2.440397"], ["83916.20", "6.422096"], ["83916.00", "1.065840"], ["83915.70", "0.161280"], ["83915.30", "0"], ["83914.00", "0.042690"], ["83912.40", "0.074640"], ["83912.20", "0.357480"], ["83911.94", "0"], ["83911.70", "0.017850"], ["83911.00", "2.302740"], ["83909.10", "0.120000"], ["83908.58", "0"], ["83908.50", "0.357300"], ["83908.30", "0.240000"], ["83908.20", "0.071460"], ["83907.50", "0.071460"], ["83907.40", "0.120000"], ["83907.00", "0.000032"], ["83906.40", "0"], ["83904.60", "2.053590"], ["83904.10", "0.120000"], ["83904.01", "0"], ["83903.60", "0"], ["83903.40", "0"], ["83903.20", "0"], ["83902.90", "0"], ["83902.71", "0"], ["83886.77", "0"], ["83874.20", "3.902168"], ["83865.80", "4.991145"], ["83860.00", "0.000971"], ["83859.58", "0.071668"], ["83857.40", "5.354137"], ["83849.00", "3.992916"], ["83840.60", "4.809649"], ["83832.20", "4.628153"], ["83823.80", "4.718901"], ["83807.00", "4.083664"], ["83798.60", "4.265160"], ["83790.20", "4.537404"], ["83781.80", "5.172641"], ["83773.40", "5.263389"], ["83765.00", "4.174412"], ["83756.60", "4.355908"], ["83748.20", "5.081893"], ["83739.80", "5.444885"], ["83731.40", "5.535633"], ["83723.00", "4.446656"], ["83714.60", "4.900397"], ["83583.65", "0.001538"], ["83458.33", "0"], ["83458.15", "0"], ["83458.10", "0"], ["83457.63", "0"], ["83456.52", "0"]], "checksum": -641409937, "ts": "1742576914132"}], "ts": 1742576914136, "record_time": 1742576914.332294, "EXCHANGE": "BITGET"}
{"action": "update", "arg": {"instType": "SPOT", "channel": "books", "instId": "BTCUSDT"}, "data": [{"asks": [["83940.00", "1.125040"], ["83944.57", "0.114324"], ["83949.98", "0"], ["83950.48", "3.186767"], ["83953.51", "0"], ["83958.85", "0.153926"], ["83959.11", "0.006357"], ["83965.05", "0.008540"], ["83978.46", "3.717895"], ["83979.84", "0.153465"], ["83992.00", "0"], ["83998.29", "1.048750"], ["84000.29", "1.634110"], ["84000.30", "4.494318"], ["84000.40", "0.724890"], ["84000.60", "0.010740"], ["84001.60", "0"], ["84007.85", "0.891848"], ["84011.70", "0.252000"], ["84012.80", "0.015750"], ["84014.63", "0"], ["84014.90", "0.196628"], ["84023.68", "0"], ["84042.30", "4.083664"], ["84042.61", "0"], ["84050.70", "4.174412"], ["84059.10", "3.992916"], ["84067.50", "5.172641"], ["84075.90", "4.355908"], ["84084.30", "4.809649"], ["84092.70", "5.081893"], ["84101.10", "4.718901"], ["84109.50", "4.991145"], ["84117.90", "5.626381"], ["84126.30", "4.446656"], ["84134.70", "5.354137"], ["84143.10", "4.537404"], ["84151.50", "5.263389"], ["84159.90", "4.265160"], ["84168.30", "5.444885"], ["84176.70", "4.900397"], ["84185.10", "5.535633"], ["84193.50", "3.902168"], ["84201.90", "4.628153"], ["84346.94", "0"], ["84346.97", "0"], ["84347.55", "0"], ["84347.69", "0"]], "bids": [["83939.99", "1.016769"], ["83934.20", "0.001276"], ["83933.72", "0.034297"], ["83932.20", "0.003127"], ["83931.51", "0"], ["83930.20", "0.008229"], ["83928.20", "0.021655"], ["83927.73", "0.164960"], ["83926.20", "0.056987"], ["83924.21", "0.014137"], ["83924.20", "0.149966"], ["83922.21", "0.383923"], ["83922.20", "0.394649"], ["83920.58", "0.764504"], ["83920.20", "1.038550"], ["83918.30", "0.204856"], ["83918.20", "2.733026"], ["83917.62", "1.160689"], ["83916.20", "7.192174"], ["83910.00", "0.162300"], ["83909.90", "0"], ["83909.61", "0.035173"], ["83908.20", "0.191460"], ["83905.80", "0.120000"], ["83905.44", "0"], ["83904.90", "0.120000"], ["83904.10", "0"], ["83904.00", "0.000032"], ["83903.80", "0"], ["83903.70", "0"], ["83897.95", "0"], ["83888.90", "0.207210"], ["83874.20", "3.992916"], ["83869.00", "0.000015"], ["83865.80", "4.174412"], ["83857.40", "4.537404"], ["83849.00", "4.809649"], ["83840.60", "5.626381"], ["83832.20", "4.718901"], ["83829.33", "0"], ["83823.80", "4.446656"], ["83820.95", "0"], ["83815.40", "5.081893"], ["83807.00", "5.263389"], ["83798.60", "5.172641"], ["83790.20", "4.991145"], ["83781.80", "5.444885"], ["83773.40", "4.083664"], ["83765.00", "4.900397"], ["83756.60", "4.628153"], ["83748.20", "4.355908"], ["83739.80", "4.265160"], ["83723.00", "3.902168"], ["83714.60", "5.354137"], ["83458.33", "0.000218"], ["83458.15", "0.000010"]], "checksum": -1127302877, "ts": "1742576914332"}], "ts": 1742576914340, "record_time": 1742576914.569978, "EXCHANGE": "BITGET"}
{"action": "update", "arg": {"instType": "SPOT", "channel": "books", "instId": "BTCUSDT"}, "data": [{"asks": [["83940.00", "1.217060"], ["83944.56", "0.034297"], ["83950.47", "1.126439"], ["83950.99", "0.014229"], ["83984.30", "0.001358"], ["83986.30", "0.003574"], ["83987.13", "0"], ["83988.30", "0.009406"], ["83990.30", "0.024754"], ["83992.30", "0.065142"], ["83994.30", "0.171425"], ["83996.30", "0.451119"], ["83998.29", "0.044970"], ["83998.30", "1.187156"], ["84000.29", "0.402429"], ["84000.30", "3.124093"], ["84000.40", "0.260820"], ["84000.60", "0"], ["84002.00", "0.078150"], ["84003.90", "0.159060"], ["84004.00", "0.111270"], ["84005.00", "0.592110"], ["84012.80", "0"], ["84013.80", "0.070710"], ["84014.10", "0"], ["84042.30", "4.900397"], ["84050.70", "4.718901"], ["84059.10", "5.354137"], ["84067.50", "5.263389"], ["84075.90", "4.446656"], ["84084.30", "5.081893"], ["84092.70", "5.535633"], ["84101.10", "4.628153"], ["84109.50", "4.174412"], ["84117.90", "4.991145"], ["84126.30", "5.444885"], ["84134.70", "4.265160"], ["84151.50", "5.172641"], ["84159.90", "4.083664"], ["84168.30", "3.902168"], ["84176.70", "5.626381"], ["84185.10", "3.992916"], ["84193.50", "4.355908"], ["84201.90", "4.809649"], ["84346.94", "0.000085"]], "bids": [["83939.99", "1.022790"], ["83934.20", "0.001520"], ["83932.44", "0.038711"], ["83932.20", "0.003998"], ["83930.20", "0.010521"], ["83928.20", "0.027688"], ["83926.20", "0.072864"], ["83924.20", "0.191746"], ["83922.21", "0.611321"], ["83922.20", "0.504594"], ["83920.20", "1.327879"], ["83918.20", "3.494419"], ["83917.62", "0.167746"], ["83916.20", "9.195840"], ["83906.43", "0.715082"], ["83874.20", "4.446656"], ["83865.80", "5.081893"], ["83857.40", "4.083664"], ["83849.00", "4.355908"], ["83840.60", "4.174412"], ["83832.20", "4.537404"], ["83823.80", "5.535633"], ["83815.40", "5.626381"], ["83807.00", "5.172641"], ["83798.60", "5.444885"], ["83790.20", "5.354137"], ["83781.80", "3.902168"], ["83773.40", "5.263389"], ["83765.00", "4.628153"], ["83756.60", "4.809649"], ["83748.20", "4.718901"], ["83739.80", "3.992916"], ["83731.40", "4.265160"], ["83723.00", "4.900397"], ["83714.60", "4.991145"], ["83458.33", "0"], ["83458.15", "0"]], "checksum": -363913080, "ts": "1742576914554"}], "ts": 1742576914561, "record_time": 1742576914.757324, "EXCHANGE": "BITGET"}
{"action": "update", "arg": {"instType": "SPOT", "channel": "books", "instId": "BTCUSDT"}, "data": [{"asks": [["83940.00", "1.217160"], ["83940.01", "0.000100"], ["83940.02", "0.000100"], ["83940.03", "0.000100"], ["83978.45", "0.747805"], ["83979.84", "0.034305"], ["83979.89", "0.198999"], ["83998.29", "0"], ["84000.29", "0"], ["84000.40", "0.117210"], ["84008.60", "0.110730"], ["84008.70", "0"], ["84010.70", "0.101010"], ["84014.60", "0.708330"], ["84042.30", "4.628153"], ["84050.70", "5.354137"], ["84059.10", "5.081893"], ["84067.50", "4.991145"], ["84075.90", "4.265160"], ["84084.30", "4.355908"], ["84092.70", "5.626381"], ["84101.10", "5.444885"], ["84109.50", "4.718901"], ["84117.90", "4.809649"], ["84126.30", "4.083664"], ["84134.70", "4.446656"], ["84143.10", "3.992916"], ["84151.50", "4.537404"], ["84159.90", "4.174412"], ["84168.30", "5.535633"], ["84176.70", "3.902168"], ["84185.10", "5.263389"], ["84193.50", "5.172641"], ["84201.90", "4.900397"], ["84345.79", "0"], ["84346.43", "0"], ["84346.94", "0"]], "bids": [["83939.99", "1.039234"], ["83926.20", "0.072617"], ["83924.20", "0.191097"], ["83922.20", "0.502886"], ["83920.20", "1.323386"], ["83918.20", "3.482595"], ["83917.62", "0.927067"], ["83916.20", "9.164722"], ["83907.80", "0.009000"], ["83874.20", "4.991145"], ["83865.80", "4.355908"], ["83857.40", "4.265160"], ["83849.00", "3.992916"], ["83840.60", "5.172641"], ["83832.20", "4.446656"], ["83823.80", "5.081893"], ["83815.40", "4.809649"], ["83807.00", "5.535633"], ["83790.20", "4.083664"], ["83781.80", "4.174412"], ["83773.40", "5.626381"], ["83765.00", "4.900397"], ["83756.60", "3.902168"], ["83748.20", "5.354137"], ["83739.80", "4.718901"], ["83731.40", "4.628153"], ["83723.00", "4.537404"], ["83714.60", "5.263389"], ["83459.46", "0"]], "checksum": -704431223, "ts": "1742576914754"}], "ts": 1742576914758, "record_time": 1742576914.953507, "EXCHANGE": "BITGET"}
{"action": "update", "arg": {"instType": "SPOT", "channel": "books", "instId": "BTCUSDT"}, "data": [{"asks": [["83940.01", "0.004414"], ["83965.06", "0.332071"], ["83981.44", "0"], ["83984.30", "0.001043"], ["83986.30", "0.001009"], ["83988.30", "0.001006"], ["83990.30", "0.001443"], ["83992.30", "0.003796"], ["83994.30", "0.009991"], ["83996.30", "0.026292"], ["83998.30", "0.069189"], ["84000.30", "0.182075"], ["84000.40", "0.009450"], ["84002.00", "0.281520"], ["84003.90", "0.508350"], ["84005.00", "1.853040"], ["84008.60", "0.080430"], ["84010.10", "0.066390"], ["84010.70", "0"], ["84011.20", "0.066360"], ["84013.80", "0"], ["84014.60", "2.852910"], ["84042.30", "4.355908"], ["84050.70", "4.265160"], ["84059.10", "5.354137"], ["84067.50", "3.992916"], ["84075.90", "4.900397"], ["84084.30", "4.991145"], ["84092.70", "5.535633"], ["84109.50", "4.174412"], ["84112.00", "0.001184"], ["84117.90", "4.718901"], ["84126.30", "4.537404"], ["84134.70", "3.902168"], ["84143.10", "4.628153"], ["84151.50", "4.083664"], ["84159.90", "5.263389"], ["84168.30", "4.809649"], ["84176.70", "5.081893"], ["84185.10", "5.172641"], ["84193.50", "4.446656"], ["84201.90", "5.626381"]], "bids": [["83939.99", "1.090500"], ["83934.20", "0.001703"], ["83932.70", "0.038711"], ["83932.44", "0"], ["83932.20", "0.004483"], ["83930.20", "0.011797"], ["83928.20", "0.031045"], ["83926.20", "0.081696"], ["83924.20", "0.214990"], ["83922.20", "0.565764"], ["83920.20", "1.488853"], ["83918.20", "3.918033"], ["83916.20", "10.310612"], ["83908.92", "0.017110"], ["83908.90", "0.269760"], ["83907.80", "2.591100"], ["83906.00", "0.486060"], ["83905.50", "0.071460"], ["83904.90", "0"], ["83904.70", "0"], ["83904.60", "0"], ["83903.46", "0"], ["83874.20", "4.446656"], ["83867.00", "0.000017"], ["83865.80", "5.444885"], ["83857.40", "4.628153"], ["83849.00", "5.081893"], ["83840.60", "4.718901"], ["83832.20", "4.900397"], ["83823.80", "4.537404"], ["83815.40", "5.263389"], ["83807.00", "5.172641"], ["83798.60", "3.902168"], ["83790.20", "4.355908"], ["83781.80", "5.535633"], ["83773.40", "4.265160"], ["83765.00", "4.809649"], ["83756.60", "4.991145"], ["83748.20", "5.626381"], ["83739.80", "4.083664"], ["83731.40", "3.992916"], ["83723.00", "4.174412"], ["83714.60", "5.354137"]], "checksum": -1699797155, "ts": "1742576914971"}], "ts": 1742576914973, "record_time": 1742576915.16927, "EXCHANGE": "BITGET"}
{"action": "update", "arg": {"instType": "SPOT", "channel": "books", "instId": "BTCUSDT"}, "data": [{"asks": [["83965.05", "0.101850"], ["83979.84", "0"], ["84014.60", "1.458330"], ["84042.30", "5.444885"], ["84050.70", "4.446656"], ["84059.10", "5.172641"], ["84067.50", "3.902168"], ["84075.90", "5.081893"], ["84084.30", "4.809649"], ["84092.70", "5.354137"], ["84101.10", "4.355908"], ["84109.50", "4.718901"], ["84117.90", "5.263389"], ["84126.30", "3.992916"], ["84134.70", "4.174412"], ["84143.10", "4.991145"], ["84159.90", "5.535633"], ["84168.30", "4.628153"], ["84176.70", "4.265160"], ["84185.10", "4.900397"], ["84193.50", "4.537404"], ["84345.79", "0.000034"]], "bids": [["83939.99", "1.144551"], ["83928.20", "0.031159"], ["83926.20", "0.081997"], ["83924.20", "0.215943"], ["83922.20", "0.568270"], ["83920.20", "1.495449"], ["83918.20", "3.935392"], ["83916.20", "10.356294"], ["83916.10", "0.061050"], ["83916.00", "1.065420"], ["83915.70", "0.161070"], ["83914.00", "0.042480"], ["83910.90", "2.681760"], ["83909.61", "0"], ["83909.51", "0.007139"], ["83908.05", "0.017372"], ["83907.80", "2.412450"], ["83904.90", "0.120000"], ["83903.97", "0"], ["83902.52", "0"], ["83874.20", "4.265160"], ["83865.80", "4.446656"], ["83859.00", "0"], ["83857.40", "3.902168"], ["83849.00", "4.809649"], ["83840.60", "4.174412"], ["83832.20", "4.718901"], ["83823.80", "4.628153"], ["83815.40", "4.991145"], ["83807.00", "5.535633"], ["83798.60", "3.992916"], ["83790.20", "5.263389"], ["83781.80", "4.537404"], ["83773.40", "4.355908"], ["83765.00", "4.900397"], ["83756.60", "4.083664"], ["83748.20", "5.354137"], ["83739.80", "5.444885"], ["83731.40", "5.081893"], ["83723.00", "5.172641"], ["83714.60", "5.626381"]], "checksum": -649794393, "ts": "1742576915173"}], "ts": 1742576915180, "record_time": 1742576915.375855, "EXCHANGE": "BITGET"}
{"action": "update", "arg": {"instType": "SPOT", "channel": "books", "instId": "BTCUSDT"}, "data": [{"asks": [["83940.00", "1.223060"], ["83974.47", "0"], ["83976.37", "0"], ["83991.32", "0.001598"], ["83993.23", "0.001598"], ["84000.30", "0.181852"], ["84042.30", "4.083664"], ["84050.70", "4.809649"], ["84059.10", "5.626381"], ["84067.50", "4.991145"], ["84075.90", "4.718901"], ["84084.30", "4.265160"], ["84092.70", "5.444885"], ["84101.10", "5.081893"], ["84109.50", "4.174412"], ["84117.90", "3.902168"], ["84126.30", "4.355908"], ["84134.70", "5.172641"], ["84143.10", "5.263389"], ["84151.50", "4.446656"], ["84159.90", "4.900397"], ["84168.30", "5.535633"], ["84176.70", "3.992916"], ["84185.10", "4.628153"], ["84193.50", "5.354137"], ["84201.90", "4.537404"]], "bids": [["83932.70", "0"], ["83930.20", "0.011556"], ["83928.20", "0.030536"], ["83926.20", "0.080359"], ["83924.20", "0.211470"], ["83922.20", "0.556501"], ["83920.20", "1.464476"], ["83918.20", "3.853714"], ["83916.20", "10.141352"], ["83910.03", "0.007345"], ["83909.41", "0.009008"], ["83904.56", "0"], ["83903.87", "0"], ["83881.20", "0.001177"], ["83879.24", "0.001173"], ["83874.20", "5.172641"], ["83865.80", "4.991145"], ["83864.37", "0"], ["83862.41", "0"], ["83857.40", "4.537404"], ["83849.00", "5.444885"], ["83840.60", "5.081893"], ["83832.20", "5.626381"], ["83823.80", "4.900397"], ["83815.40", "4.355908"], ["83807.00", "4.446656"], ["83798.60", "4.718901"], ["83790.20", "4.174412"], ["83781.80", "3.992916"], ["83773.40", "4.809649"], ["83765.00", "5.354137"], ["83748.20", "4.265160"], ["83739.80", "3.902168"], ["83731.40", "5.263389"], ["83723.00", "5.535633"], ["83714.60", "4.628153"], ["83459.46", "0.000008"]], "checksum": 1441509960, "ts": "1742576915383"}], "ts": 1742576915386, "record_time": 1742576915.610331, "EXCHANGE": "BITGET"}
{"action": "update", "arg": {"instType": "SPOT", "channel": "books", "instId": "BTCUSDT"}, "data": [{"asks": [["83954.20", "0"], ["83959.80", "0.006357"], ["84008.60", "0.515190"], ["84008.70", "1.350000"], ["84014.60", "0.250620"], ["84042.30", "4.446656"], ["84050.70", "5.626381"], ["84059.10", "4.537404"], ["84067.50", "4.628153"], ["84075.90", "5.081893"], ["84084.30", "5.535633"], ["84092.70", "3.902168"], ["84101.10", "4.355908"], ["84109.50", "4.809649"], ["84117.90", "4.900397"], ["84126.30", "5.172641"], ["84134.70", "5.263389"], ["84143.10", "4.265160"], ["84151.50", "4.991145"], ["84159.90", "4.718901"], ["84168.30", "5.354137"], ["84176.70", "5.444885"], ["84185.10", "3.992916"], ["84193.50", "4.174412"], ["84201.90", "4.083664"], ["84345.79", "0"]], "bids": [["83932.94", "0.038711"], ["83922.20", "0.556360"], ["83920.20", "1.464269"], ["83918.20", "3.853339"], ["83916.20", "10.140367"], ["83907.60", "0"], ["83904.70", "0.120000"], ["83874.20", "4.628153"], ["83865.80", "5.354137"], ["83857.40", "3.902168"], ["83840.60", "4.265160"], ["83832.20", "4.900397"], ["83823.80", "4.537404"], ["83815.40", "5.172641"], ["83807.00", "4.083664"], ["83790.20", "5.626381"], ["83781.80", "5.535633"], ["83773.40", "4.446656"], ["83765.00", "5.263389"], ["83756.60", "5.081893"], ["83748.20", "4.174412"], ["83739.80", "4.355908"], ["83731.40", "3.992916"], ["83723.00", "4.991145"], ["83714.60", "4.809649"], ["83459.46", "0"]], "checksum": -1456681664, "ts": "1742576915589"}], "ts": 1742576915593, "record_time": 1742576915.788857, "EXCHANGE": "BITGET"}
{"action": "update", "arg": {"instType": "SPOT", "channel": "books", "instId": "BTCUSDT"}, "data": [{"asks": [["83940.00", "1.438160"], ["83980.49", "0.013838"], ["83986.30", "0.002086"], ["83988.30", "0.005491"], ["83990.30", "0.014448"], ["83992.30", "0.038023"], ["83994.30", "0.100059"], ["83996.30", "0.263315"], ["83998.30", "0.692932"], ["84000.30", "1.823507"], ["84001.20", "0.442080"], ["84002.00", "0.281340"], ["84003.60", "0.868560"], ["84003.90", "0"], ["84004.00", "0.110880"], ["84005.00", "0.943830"], ["84012.80", "0.011640"], ["84014.30", "0"], ["84014.60", "0"], ["84042.30", "5.172641"], ["84050.70", "4.446656"], ["84059.10", "5.354137"], ["84067.50", "5.444885"], ["84075.90", "4.991145"], ["84084.30", "5.263389"], ["84088.60", "0"], ["84092.70", "4.718901"], ["84101.10", "4.083664"], ["84117.90", "5.535633"], ["84126.30", "4.174412"], ["84134.70", "4.537404"], ["84143.10", "4.355908"], ["84151.50", "4.900397"], ["84159.90", "3.992916"], ["84168.30", "4.628153"], ["84176.70", "3.902168"], ["84185.10", "4.265160"], ["84193.50", "5.081893"], ["84201.90", "5.626381"]], "bids": [["83939.99", "0.524378"], ["83938.77", "0"], ["83938.76", "0"], ["83933.71", "0"], ["83929.78", "0"], ["83919.33", "0.055953"], ["83916.20", "10.140590"], ["83916.10", "0.061230"], ["83910.90", "2.681940"], ["83909.97", "0.026355"], ["83878.63", "0"], ["83874.20", "4.083664"], ["83865.80", "4.446656"], ["83857.40", "3.992916"], ["83849.00", "4.355908"], ["83840.60", "3.902168"], ["83832.20", "5.626381"], ["83823.80", "5.172641"], ["83815.40", "4.537404"], ["83807.00", "5.444885"], ["83798.60", "4.174412"], ["83790.20", "4.991145"], ["83781.80", "4.265160"], ["83773.40", "4.718901"], ["83756.60", "4.628153"], ["83748.20", "5.354137"], ["83739.80", "4.809649"], ["83731.40", "5.081893"], ["83723.00", "5.535633"], ["83714.60", "4.900397"], ["83459.46", "0.000008"], ["83458.33", "0.000218"], ["83458.15", "0.000010"], ["83458.10", "0.000011"]], "checksum": -81473431, "ts": "1742576915791"}], "ts": 1742576915794, "record_time": 1742576915.990901, "EXCHANGE": "BITGET"}
{"action": "update", "arg": {"instType": "SPOT", "channel": "books", "instId": "BTCUSDT"}, "data": [{"asks": [["83941.33", "0.114321"], ["83944.57", "0"], ["83950.99", "0"], ["83982.30", "0.001377"], ["83984.30", "0.003623"], ["83986.30", "0.009534"], ["83988.30", "0.025090"], ["83990.30", "0.066027"], ["83991.54", "0"], ["83992.30", "0.173755"], ["83994.30", "0.457251"], ["83996.30", "1.203291"], ["83998.30", "3.166726"], ["84000.30", "8.333488"], ["84001.20", "0"], ["84002.00", "0.166470"], ["84003.60", "0"], ["84004.00", "0.111300"], ["84005.00", "0.999510"], ["84007.80", "1.430250"], ["84008.60", "1.225470"], ["84009.40", "2.144580"], ["84010.10", "0"], ["84011.00", "0.493590"], ["84011.20", "0"], ["84012.10", "0.536970"], ["84012.80", "0.035700"], ["84013.40", "0"], ["84014.00", "0"], ["84042.30", "4.355908"], ["84050.70", "4.809649"], ["84055.84", "0.071678"], ["84059.10", "4.537404"], ["84067.50", "4.083664"], ["84075.90", "5.081893"], ["84084.30", "4.446656"], ["84092.70", "3.902168"], ["84101.10", "5.535633"], ["84109.50", "3.992916"], ["84117.90", "4.628153"], ["84126.30", "5.263389"], ["84134.70", "4.174412"], ["84143.10", "4.265160"], ["84151.50", "5.626381"], ["84159.90", "4.991145"], ["84168.30", "4.718901"], ["84176.70", "5.354137"], ["84185.10", "5.444885"], ["84193.50", "5.172641"], ["84201.90", "4.900397"], ["84345.79", "0.000034"], ["84346.43", "0.000128"], ["84346.94", "0.000085"]], "bids": [["83934.55", "0.114321"], ["83934.20", "0.001037"], ["83933.72", "0.011613"], ["83933.22", "0.038711"], ["83932.94", "0"], ["83932.20", "0.002014"], ["83930.20", "0.005114"], ["83929.79", "0"], ["83928.20", "0.013458"], ["83926.20", "0.035416"], ["83924.20", "0.093198"], ["83922.20", "0.245259"], ["83920.20", "0.645418"], ["83918.20", "1.698575"], ["83916.20", "4.469933"], ["83916.10", "0.061050"], ["83916.00", "0.043110"], ["83915.70", "0"], ["83914.00", "0.042690"], ["83913.60", "3.629100"], ["83912.40", "0.074460"], ["83912.20", "0"], ["83912.00", "0.042300"], ["83911.70", "0"], ["83911.00", "2.302560"], ["83910.90", "2.681760"], ["83910.70", "0.160890"], ["83910.60", "0.790530"], ["83910.10", "0.070920"], ["83908.90", "0"], ["83908.50", "0"], ["83907.90", "0.324300"], ["83907.50", "0"], ["83906.00", "0.057300"], ["83905.90", "1.430250"], ["83905.50", "0"], ["83904.70", "0"], ["83903.00", "0.024980"], ["83874.20", "5.354137"], ["83865.80", "5.172641"], ["83857.40", "4.718901"], ["83849.00", "4.083664"], ["83846.40", "0.071678"], ["83840.60", "4.991145"], ["83832.20", "3.902168"], ["83823.80", "4.537404"], ["83815.40", "4.900397"], ["83807.00", "5.263389"], ["83798.60", "5.081893"], ["83790.20", "4.628153"], ["83781.80", "4.446656"], ["83773.40", "4.809649"], ["83765.00", "5.444885"], ["83756.60", "5.626381"], ["83748.20", "4.174412"], ["83739.80", "4.355908"], ["83731.40", "5.535633"], ["83723.00", "3.992916"], ["83714.60", "4.265160"], ["83457.63", "0.000023"], ["83456.52", "0.000010"], ["83456.00", "0.000133"], ["83455.56", "0.000025"], ["83455.07", "0.000013"]], "checksum": 2112371092, "ts": "1742576916000"}], "ts": 1742576916004, "record_time": 1742576916.199502, "EXCHANGE": "BITGET"}
{"action": "update", "arg": {"instType": "SPOT", "channel": "books", "instId": "BTCUSDT"}, "data": [{"asks": [["83940.00", "1.452041"], ["83940.01", "0.000100"], ["83941.32", "0.034296"], ["83944.56", "0"], ["83986.30", "0.009281"], ["83988.30", "0.024424"], ["83990.30", "0.064274"], ["83992.30", "0.169142"], ["83994.30", "0.445112"], ["83996.30", "1.171346"], ["83998.30", "3.082489"], ["84000.30", "8.111813"], ["84002.00", "0.135600"], ["84004.40", "0.012240"], ["84013.40", "0.384000"], ["84042.30", "5.354137"], ["84050.70", "4.355908"], ["84059.10", "4.265160"], ["84067.50", "4.174412"], ["84075.90", "5.535633"], ["84084.30", "5.081893"], ["84101.10", "5.626381"], ["84109.50", "4.628153"], ["84117.90", "4.991145"], ["84126.30", "4.446656"], ["84134.70", "5.263389"], ["84143.10", "3.992916"], ["84151.50", "5.172641"], ["84159.90", "4.537404"], ["84168.30", "4.809649"], ["84176.70", "4.083664"], ["84193.50", "4.900397"], ["84201.90", "4.718901"], ["84281.43", "0"], ["84294.06", "1.676796"], ["84346.94", "0"]], "bids": [["83939.99", "0.552614"], ["83934.56", "0.046221"], ["83933.72", "0"], ["83914.00", "0.203580"], ["83910.70", "0"], ["83889.00", "0.000015"], ["83888.00", "0.000015"], ["83887.00", "0.000015"], ["83886.00", "0.000015"], ["83885.00", "0.000015"], ["83884.00", "0.000015"], ["83883.00", "0.000015"], ["83882.00", "0.000015"], ["83881.00", "0.000015"], ["83880.00", "0.002015"], ["83879.00", "0.000015"], ["83878.00", "0.000015"], ["83877.00", "0.000015"], ["83876.00", "0.000015"], ["83875.00", "0.000015"], ["83874.20", "3.902168"], ["83874.00", "0.000015"], ["83873.00", "0.000015"], ["83872.00", "0.000015"], ["83871.00", "0.000015"], ["83870.00", "0.000015"], ["83868.00", "0"], ["83865.80", "4.991145"], ["83857.40", "5.354137"], ["83849.00", "4.809649"], ["83840.60", "4.718901"], ["83832.20", "5.081893"], ["83823.80", "4.174412"], ["83815.40", "5.172641"], ["83798.60", "4.265160"], ["83790.20", "5.535633"], ["83781.80", "5.444885"], ["83773.40", "4.446656"], ["83765.00", "4.628153"], ["83756.60", "4.355908"], ["83748.20", "4.537404"], ["83739.80", "3.992916"], ["83731.40", "5.626381"], ["83723.00", "4.083664"], ["83714.60", "4.900397"], ["83622.39", "1.641203"], ["83609.86", "0"], ["83454.55", "0.000027"], ["83454.54", "0.001547"]], "checksum": 1293672659, "ts": "1742576916204"}], "ts": 1742576916208, "record_time": 1742576916.404134, "EXCHANGE": "BITGET"}
{"action": "update", "arg": {"instType": "SPOT", "channel": "books", "instId": "BTCUSDT"}, "data": [{"asks": [["83984.30", "0.003858"], ["83986.30", "0.010154"], ["83988.30", "0.026720"], ["83990.30", "0.070317"], ["83992.30", "0.185043"], ["83994.30", "0.486957"], ["83996.30", "1.281466"], ["83998.30", "3.372150"], ["84000.30", "8.874079"], ["84007.00", "0.035700"], ["84013.40", "0"], ["84042.30", "4.446656"], ["84050.70", "4.174412"], ["84059.10", "4.900397"], ["84067.50", "4.628153"], ["84084.30", "4.537404"], ["84092.70", "5.263389"], ["84109.50", "5.081893"], ["84117.90", "4.083664"], ["84126.30", "5.354137"], ["84134.70", "4.718901"], ["84143.10", "5.172641"], ["84151.50", "4.355908"], ["84159.90", "3.902168"], ["84168.30", "5.444885"], ["84176.70", "4.265160"], ["84185.10", "3.992916"], ["84193.50", "4.991145"], ["84201.90", "4.809649"]], "bids": [["83930.21", "0.003814"], ["83916.10", "0.064830"], ["83916.00", "0.042720"], ["83912.30", "0.022620"], ["83904.90", "0"], ["83874.20", "5.626381"], ["83865.80", "4.900397"], ["83857.40", "4.083664"], ["83849.00", "3.992916"], ["83832.20", "4.174412"], ["83823.80", "4.537404"], ["83815.40", "4.628153"], ["83807.00", "5.081893"], ["83798.60", "5.535633"], ["83790.20", "5.444885"], ["83781.80", "5.172641"], ["83773.40", "5.354137"], ["83765.00", "4.991145"], ["83756.60", "4.809649"], ["83748.20", "4.265160"], ["83739.80", "4.446656"], ["83731.40", "5.263389"], ["83723.00", "4.355908"], ["83714.60", "3.902168"], ["83454.54", "0"]], "checksum": 802161771, "ts": "1742576916405"}], "ts": 1742576916407, "record_time": 1742576916.628871, "EXCHANGE": "BITGET"}
{"action": "update", "arg": {"instType": "SPOT", "channel": "books", "instId": "BTCUSDT"}, "data": [{"asks": [["83940.00", "1.437039"], ["83996.30", "1.281261"], ["83998.30", "3.371740"], ["84000.30", "8.873000"], ["84004.90", "0.099630"], ["84007.00", "0"], ["84042.30", "5.263389"], ["84050.70", "5.626381"], ["84059.10", "4.628153"], ["84067.50", "3.902168"], ["84075.90", "5.354137"], ["84084.30", "4.174412"], ["84092.70", "4.900397"], ["84101.10", "4.083664"], ["84109.50", "4.446656"], ["84117.90", "4.718901"], ["84126.30", "4.355908"], ["84134.70", "5.535633"], ["84143.10", "4.991145"], ["84151.50", "5.444885"], ["84159.90", "4.265160"], ["84168.30", "5.172641"], ["84176.70", "4.809649"], ["84185.10", "5.081893"], ["84193.50", "4.537404"], ["84201.90", "3.992916"]], "bids": [["83933.45", "0.038711"], ["83933.22", "0"], ["83920.20", "0.645209"], ["83918.20", "1.697917"], ["83916.20", "4.468204"], ["83916.10", "0.061260"], ["83913.61", "0.343948"], ["83913.60", "4.165860"], ["83905.60", "0"], ["83874.20", "4.174412"], ["83865.80", "5.535633"], ["83857.40", "4.809649"], ["83849.00", "4.628153"], ["83840.60", "4.265160"], ["83832.20", "5.444885"], ["83823.80", "4.083664"], ["83815.40", "3.992916"], ["83807.00", "4.900397"], ["83798.60", "4.718901"], ["83790.20", "5.263389"], ["83781.80", "4.537404"], ["83773.40", "3.902168"], ["83765.00", "5.172641"], ["83756.60", "5.081893"], ["83748.20", "4.355908"], ["83731.40", "5.354137"], ["83723.00", "5.626381"], ["83714.60", "4.991145"]], "checksum": 1016089022, "ts": "1742576916609"}], "ts": 1742576916614, "record_time": 1742576916.810015, "EXCHANGE": "BITGET"}
{"action": "update", "arg": {"instType": "SPOT", "channel": "books", "instId": "BTCUSDT"}, "data": [{"asks": [["83984.30", "0.003526"], ["83986.30", "0.009280"], ["83988.30", "0.024420"], ["83990.30", "0.064263"], ["83992.30", "0.169112"], ["83994.30", "0.445034"], ["83996.30", "1.171142"], ["83998.30", "3.081952"], ["84000.30", "8.110400"], ["84042.30", "4.265160"], ["84050.70", "4.355908"], ["84059.10", "5.444885"], ["84067.50", "5.263389"], ["84075.90", "4.718901"], ["84084.30", "4.809649"], ["84092.70", "4.537404"], ["84101.10", "5.081893"], ["84109.50", "3.992916"], ["84117.90", "4.900397"], ["84126.30", "4.628153"], ["84134.70", "4.083664"], ["84143.10", "5.626381"], ["84151.50", "4.446656"], ["84159.90", "5.354137"], ["84168.30", "4.991145"], ["84176.70", "3.902168"], ["84185.10", "5.172641"], ["84193.50", "4.174412"], ["84201.90", "5.535633"]], "bids": [["83932.20", "0.001893"], ["83930.20", "0.004983"], ["83928.20", "0.013113"], ["83926.20", "0.034509"], ["83924.20", "0.090811"], ["83922.20", "0.238977"], ["83920.20", "0.628887"], ["83918.20", "1.654965"], ["83916.20", "4.355171"], ["83874.20", "4.809649"], ["83869.00", "0.000032"], ["83865.80", "3.902168"], ["83857.40", "5.354137"], ["83849.00", "4.900397"], ["83840.60", "5.081893"], ["83823.80", "4.991145"], ["83815.40", "4.174412"], ["83807.00", "5.535633"], ["83798.60", "4.083664"], ["83773.40", "4.446656"], ["83765.00", "4.718901"], ["83756.60", "5.172641"], ["83748.20", "5.626381"], ["83739.80", "4.628153"], ["83731.40", "4.265160"], ["83723.00", "4.355908"], ["83714.60", "3.992916"]], "checksum": 1571120303, "ts": "1742576916811"}], "ts": 1742576916815, "record_time": 1742576917.010637, "EXCHANGE": "BITGET"}
{"action": "update", "arg": {"instType": "SPOT", "channel": "books", "instId": "BTCUSDT"}, "data": [{"asks": [["83940.00", "1.452041"], ["83984.30", "0.003858"], ["83986.30", "0.010152"], ["83988.30", "0.026716"], ["83990.30", "0.070306"], ["83992.30", "0.185014"], ["83994.30", "0.486879"], ["83996.30", "1.281261"], ["83998.30", "3.371740"], ["84000.30", "8.873000"], ["84004.90", "0"], ["84007.00", "0.014010"], ["84042.30", "4.355908"], ["84050.70", "4.446656"], ["84059.10", "5.172641"], ["84067.50", "5.354137"], ["84075.90", "3.902168"], ["84084.30", "4.900397"], ["84092.70", "5.626381"], ["84101.10", "5.535633"], ["84109.50", "4.718901"], ["84117.90", "5.081893"], ["84126.30", "4.265160"], ["84134.70", "4.537404"], ["84143.10", "4.991145"], ["84151.50", "3.992916"], ["84159.90", "4.628153"], ["84168.30", "4.809649"], ["84176.70", "5.444885"], ["84185.10", "4.083664"], ["84193.50", "5.263389"], ["84201.90", "4.174412"]], "bids": [["83933.70", "0.038711"], ["83933.45", "0"], ["83918.20", "1.654718"], ["83916.20", "4.354520"], ["83908.20", "0.120000"], ["83905.60", "0.015000"], ["83874.20", "5.626381"], ["83865.80", "4.083664"], ["83857.40", "4.265160"], ["83840.60", "4.809649"], ["83832.20", "4.446656"], ["83823.80", "3.902168"], ["83815.40", "5.172641"], ["83807.00", "4.537404"], ["83798.60", "4.628153"], ["83790.20", "3.992916"], ["83781.80", "4.174412"], ["83773.40", "5.535633"], ["83756.60", "5.081893"], ["83748.20", "5.444885"], ["83739.80", "4.355908"], ["83731.40", "5.354137"], ["83723.00", "4.991145"], ["83714.60", "5.263389"], ["83454.55", "0"]], "checksum": 790474649, "ts": "1742576917030"}], "ts": 1742576917038, "record_time": 1742576917.234955, "EXCHANGE": "BITGET"}
{"action": "update", "arg": {"instType": "SPOT", "channel": "books", "instId": "BTCUSDT"}, "data": [{"asks": [["83953.30", "0"], ["83954.10", "0"], ["83954.97", "0"], ["83958.99", "0.006357"], ["83959.75", "0.006357"], ["83960.64", "0.006357"], ["83979.89", "0"], ["83996.30", "1.281100"], ["83998.30", "3.371316"], ["84000.30", "8.871884"], ["84004.90", "0.100500"], ["84012.80", "0"], ["84042.30", "5.172641"], ["84050.70", "5.081893"], ["84059.10", "3.992916"], ["84067.50", "4.718901"], ["84075.90", "5.263389"], ["84084.30", "5.354137"], ["84092.70", "4.537404"], ["84101.10", "4.628153"], ["84109.50", "4.265160"], ["84117.90", "3.902168"], ["84126.30", "4.174412"], ["84134.70", "4.900397"], ["84143.10", "4.355908"], ["84151.50", "4.446656"], ["84159.90", "5.535633"], ["84168.30", "4.083664"], ["84176.70", "5.626381"], ["84185.10", "5.444885"], ["84193.50", "4.809649"], ["84201.90", "4.991145"], ["84346.94", "0.000085"]], "bids": [["83874.20", "5.444885"], ["83865.80", "5.081893"], ["83857.40", "4.991145"], ["83849.00", "5.172641"], ["83840.60", "3.902168"], ["83832.20", "5.354137"], ["83823.80", "4.265160"], ["83815.40", "3.992916"], ["83807.00", "5.626381"], ["83798.60", "5.263389"], ["83790.20", "4.537404"], ["83781.80", "4.718901"], ["83773.40", "4.628153"], ["83765.00", "4.174412"], ["83756.60", "4.083664"], ["83748.20", "4.355908"], ["83739.80", "4.900397"], ["83731.40", "4.446656"], ["83723.00", "5.535633"], ["83714.60", "4.809649"]], "checksum": -186799789, "ts": "1742576917233"}], "ts": 1742576917237, "record_time": 1742576917.431824, "EXCHANGE": "BITGET"}
{"action": "update", "arg": {"instType": "SPOT", "channel": "books", "instId": "BTCUSDT"}, "data": [{"asks": [["83978.70", "0.195048"], ["83990.30", "0.070179"], ["83992.30", "0.184681"], ["83994.30", "0.486004"], ["83996.30", "1.278956"], ["83998.30", "3.365676"], ["84000.30", "8.857041"], ["84042.30", "4.718901"], ["84050.70", "5.626381"], ["84059.10", "4.900397"], ["84067.50", "3.992916"], ["84075.90", "4.446656"], ["84084.30", "5.444885"], ["84092.70", "4.083664"], ["84101.10", "4.537404"], ["84109.50", "4.809649"], ["84117.90", "4.628153"], ["84126.30", "4.355908"], ["84134.70", "4.991145"], ["84143.10", "3.902168"], ["84151.50", "5.172641"], ["84159.90", "5.263389"], ["84168.30", "4.174412"], ["84176.70", "5.535633"], ["84185.10", "5.081893"], ["84193.50", "4.265160"], ["84201.90", "5.354137"], ["84346.94", "0"]], "bids": [["83932.20", "0.001769"], ["83930.20", "0.004656"], ["83928.20", "0.012253"], ["83926.20", "0.032244"], ["83924.20", "0.084853"], ["83922.20", "0.223297"], ["83920.20", "0.587624"], ["83918.20", "1.546379"], ["83916.20", "4.069420"], ["83911.00", "2.781090"], ["83905.60", "0"], ["83874.20", "5.626381"], ["83867.00", "0"], ["83857.40", "4.628153"], ["83849.00", "4.083664"], ["83840.60", "5.263389"], ["83832.20", "5.444885"], ["83823.80", "4.537404"], ["83815.40", "4.991145"], ["83807.00", "4.718901"], ["83798.60", "4.174412"], ["83790.20", "5.535633"], ["83781.80", "4.265160"], ["83773.40", "5.172641"], ["83765.00", "4.809649"], ["83756.60", "4.355908"], ["83748.20", "5.354137"], ["83739.80", "4.446656"], ["83731.40", "3.902168"], ["83723.00", "3.992916"], ["83714.60", "4.900397"], ["83454.55", "0.000027"], ["83454.54", "0.001547"]], "checksum": 504314166, "ts": "1742576917434"}], "ts": 1742576917438, "record_time": 1742576917.66561, "EXCHANGE": "BITGET"}
{"action": "update", "arg": {"instType": "SPOT", "channel": "books", "instId": "BTCUSDT"}, "data": [{"asks": [["83941.33", "0"], ["84042.30", "4.809649"], ["84059.10", "4.446656"], ["84067.50", "5.081893"], ["84075.90", "4.537404"], ["84084.30", "4.900397"], ["84092.70", "4.265160"], ["84101.10", "4.355908"], ["84109.50", "5.263389"], ["84117.90", "5.444885"], ["84126.30", "4.083664"], ["84143.10", "4.628153"], ["84151.50", "3.902168"], ["84159.90", "5.535633"], ["84176.70", "5.354137"], ["84185.10", "3.992916"], ["84193.50", "5.172641"], ["84201.90", "4.718901"], ["84346.94", "0.000085"]], "bids": [["83933.90", "0.038711"], ["83933.70", "0"], ["83874.20", "4.628153"], ["83865.80", "4.991145"], ["83857.40", "5.535633"], ["83849.00", "4.174412"], ["83840.60", "4.265160"], ["83832.20", "3.992916"], ["83823.80", "4.809649"], ["83815.40", "3.902168"], ["83807.00", "4.083664"], ["83798.60", "5.081893"], ["83790.20", "4.718901"], ["83781.80", "5.354137"], ["83773.40", "5.444885"], ["83765.00", "5.172641"], ["83756.60", "4.446656"], ["83748.20", "5.263389"], ["83739.80", "5.626381"], ["83731.40", "4.900397"], ["83723.00", "4.537404"], ["83714.60", "4.355908"]], "checksum": 575803382, "ts": "1742576917661"}], "ts": 1742576917665, "record_time": 1742576917.861087, "EXCHANGE": "BITGET"}
{"action": "update", "arg": {"instType": "SPOT", "channel": "books", "instId": "BTCUSDT"}, "data": [{"asks": [["83940.00", "1.451692"], ["83940.14", "0.001376"], ["83940.55", "0.114310"], ["83941.32", "0"], ["84000.30", "8.856836"], ["84042.30", "3.992916"], ["84050.70", "5.354137"], ["84059.10", "4.355908"], ["84067.50", "4.628153"], ["84084.30", "5.444885"], ["84092.70", "4.991145"], ["84101.10", "4.265160"], ["84109.50", "4.900397"], ["84117.90", "5.172641"], ["84126.30", "3.902168"], ["84134.70", "4.809649"], ["84143.10", "5.626381"], ["84151.50", "5.263389"], ["84159.90", "4.718901"], ["84168.30", "5.535633"], ["84176.70", "4.174412"], ["84185.10", "5.081893"], ["84193.50", "4.446656"], ["84201.90", "4.083664"], ["84346.94", "0"]], "bids": [["83920.20", "0.587469"], ["83918.20", "1.545969"], ["83916.20", "4.068341"], ["83909.97", "0"], ["83901.48", "0.026355"], ["83874.20", "5.444885"], ["83865.80", "4.446656"], ["83857.40", "4.628153"], ["83849.00", "5.172641"], ["83840.60", "5.081893"], ["83832.20", "4.083664"], ["83823.80", "3.902168"], ["83815.40", "4.355908"], ["83807.00", "5.626381"], ["83798.60", "4.991145"], ["83790.20", "4.537404"], ["83781.80", "4.265160"], ["83773.40", "5.535633"], ["83765.00", "4.809649"], ["83756.60", "5.354137"], ["83748.20", "3.992916"], ["83739.80", "4.174412"], ["83731.40", "4.718901"], ["83723.00", "4.900397"], ["83714.60", "5.263389"]], "checksum": 1568646250, "ts": "1742576917877"}], "ts": 1742576917881, "record_time": 1742576918.076644, "EXCHANGE": "BITGET"}
{"action": "update", "arg": {"instType": "SPOT", "channel": "books", "instId": "BTCUSDT"}, "data": [{"asks": [["83940.00", "1.456006"], ["83940.14", "0.035497"], ["83952.79", "0"], ["83952.82", "0"], ["83953.67", "0"], ["83954.38", "0"], ["83957.88", "0.035972"], ["83958.40", "0.006357"], ["83958.86", "0"], ["83959.31", "0.006357"], ["83960.34", "0.006357"], ["83965.10", "0.119850"], ["83983.98", "0.010000"], ["83984.30", "0.003519"], ["83986.30", "0.009261"], ["83988.30", "0.024372"], ["83990.30", "0.064136"], ["83992.30", "0.168779"], ["83994.30", "0.444154"], ["83996.30", "1.168826"], ["83998.30", "3.075859"], ["84000.30", "8.094367"], ["84004.40", "0.027240"], ["84004.90", "0"], ["84005.90", "0.098610"], ["84007.00", "0"], ["84012.80", "0.035700"], ["84042.30", "5.626381"], ["84050.70", "4.083664"], ["84059.10", "4.900397"], ["84067.50", "5.081893"], ["84075.90", "5.444885"], ["84084.30", "5.535633"], ["84092.70", "5.172641"], ["84101.10", "4.446656"], ["84109.50", "4.809649"], ["84117.90", "4.174412"], ["84134.70", "5.263389"], ["84143.10", "4.355908"], ["84151.50", "4.991145"], ["84159.90", "4.265160"], ["84168.30", "4.628153"], ["84176.70", "4.537404"], ["84185.10", "4.718901"], ["84193.50", "3.992916"], ["84201.90", "5.354137"], ["84346.43", "0"]], "bids": [["83939.99", "0.542614"], ["83934.11", "0.038711"], ["83933.90", "0"], ["83930.20", "0.004788"], ["83928.20", "0.012601"], ["83926.20", "0.033159"], ["83924.20", "0.087263"], ["83922.20", "0.229637"], ["83920.20", "0.604308"], ["83918.20", "1.590286"], ["83916.20", "4.184963"], ["83914.23", "0.083615"], ["83912.81", "0.016428"], ["83912.24", "0.015746"], ["83909.81", "0.007953"], ["83909.17", "0"], ["83907.17", "0"], ["83907.01", "0.268771"], ["83906.58", "0.006572"], ["83903.86", "0"], ["83900.78", "0"], ["83889.00", "0.000032"], ["83874.20", "4.809649"], ["83865.80", "4.991145"], ["83849.00", "4.265160"], ["83840.60", "4.355908"], ["83832.20", "4.900397"], ["83823.80", "5.172641"], ["83815.40", "4.718901"], ["83807.00", "3.902168"], ["83798.60", "4.083664"], ["83790.20", "5.081893"], ["83781.80", "4.537404"], ["83773.40", "4.446656"], ["83765.00", "5.444885"], ["83756.60", "5.263389"], ["83739.80", "5.626381"], ["83731.40", "4.174412"], ["83723.00", "5.354137"], ["83714.60", "5.535633"], ["83454.54", "0"]], "checksum": 136969090, "ts": "1742576918108"}], "ts": 1742576918112, "record_time": 1742576918.307346, "EXCHANGE": "BITGET"}
{"action": "update", "arg": {"instType": "SPOT", "channel": "books", "instId": "BTCUSDT"}, "data": [{"asks": [["83940.01", "0.002399"], ["83952.58", "0"], ["83958.11", "0.006357"], ["84042.30", "4.991145"], ["84050.70", "4.537404"], ["84059.10", "5.081893"], ["84067.50", "5.263389"], ["84075.90", "4.355908"], ["84084.30", "5.626381"], ["84092.70", "3.902168"], ["84101.10", "3.992916"], ["84109.50", "5.354137"], ["84117.90", "4.446656"], ["84126.30", "4.174412"], ["84134.70", "4.900397"], ["84143.10", "5.172641"], ["84151.50", "4.628153"], ["84159.90", "4.809649"], ["84168.30", "4.265160"], ["84176.70", "5.444885"], ["84193.50", "4.083664"], ["84201.90", "5.535633"]], "bids": [["83923.00", "0.000015"], ["83919.00", "0.000015"], ["83918.00", "0.000015"], ["83917.00", "0.000015"], ["83916.00", "0.042735"], ["83915.00", "0.000015"], ["83914.00", "0.203595"], ["83913.00", "0.000015"], ["83912.62", "0.005948"], ["83912.00", "0.042315"], ["83907.09", "0"], ["83874.20", "4.355908"], ["83868.00", "0.000015"], ["83865.80", "5.444885"], ["83857.40", "5.172641"], ["83849.00", "4.446656"], ["83840.60", "3.902168"], ["83832.20", "4.718901"], ["83823.80", "4.083664"], ["83815.40", "5.535633"], ["83807.00", "4.537404"], ["83798.60", "5.354137"], ["83790.20", "4.265160"], ["83781.80", "5.626381"], ["83773.40", "4.809649"], ["83765.00", "5.263389"], ["83756.60", "4.991145"], ["83748.20", "4.900397"], ["83739.80", "4.174412"], ["83731.40", "3.992916"], ["83723.00", "4.628153"], ["83714.60", "5.081893"], ["83458.10", "0"], ["83457.63", "0"], ["83456.52", "0"], ["83456.00", "0"], ["83455.56", "0"], ["83455.07", "0"], ["83454.55", "0"]], "checksum": 578547882, "ts": "1742576918331"}], "ts": 1742576918334, "record_time": 1742576918.529373, "EXCHANGE": "BITGET"}
{"action": "update", "arg": {"instType": "SPOT", "channel": "books", "instId": "BTCUSDT"}, "data": [{"asks": [["84042.30", "4.083664"], ["84050.70", "4.718901"], ["84059.10", "5.263389"], ["84067.50", "5.535633"], ["84075.90", "4.991145"], ["84084.30", "5.081893"], ["84092.70", "4.355908"], ["84101.10", "4.628153"], ["84109.50", "4.900397"], ["84117.90", "4.809649"], ["84126.30", "3.902168"], ["84134.70", "5.444885"], ["84143.10", "4.265160"], ["84151.50", "4.446656"], ["84159.90", "5.172641"], ["84168.30", "3.992916"], ["84176.70", "4.174412"], ["84185.10", "4.537404"], ["84193.50", "5.626381"], ["84201.90", "5.354137"]], "bids": [["83934.11", "0"], ["83874.20", "3.992916"], ["83865.80", "4.537404"], ["83857.40", "5.354137"], ["83849.00", "5.263389"], ["83840.60", "4.991145"], ["83832.20", "4.174412"], ["83815.40", "4.355908"], ["83807.00", "5.081893"], ["83798.60", "5.444885"], ["83790.20", "4.900397"], ["83781.80", "4.446656"], ["83765.00", "3.902168"], ["83756.60", "5.626381"], ["83748.20", "5.172641"], ["83739.80", "4.265160"], ["83731.40", "4.718901"], ["83714.60", "5.535633"], ["83458.10", "0.000011"]], "checksum": -84677423, "ts": "1742576918532"}], "ts": 1742576918535, "record_time": 1742576918.731365, "EXCHANGE": "BITGET"}
{"action": "update", "arg": {"instType": "SPOT", "channel": "books", "instId": "BTCUSDT"}, "data": [{"asks": [["84000.30", "8.094106"], ["84042.30", "4.174412"], ["84050.70", "4.083664"], ["84059.10", "5.444885"], ["84067.50", "3.902168"], ["84075.90", "5.081893"], ["84084.30", "5.354137"], ["84092.70", "4.446656"], ["84101.10", "5.535633"], ["84109.50", "4.628153"], ["84117.90", "5.263389"], ["84126.30", "5.626381"], ["84134.70", "5.172641"], ["84143.10", "3.992916"], ["84151.50", "4.718901"], ["84159.90", "4.355908"], ["84168.30", "4.265160"], ["84176.70", "4.537404"], ["84185.10", "4.809649"], ["84193.50", "4.900397"], ["84201.90", "4.991145"]], "bids": [["83934.56", "0.034607"], ["83934.33", "0.038711"], ["83922.20", "0.229411"], ["83920.20", "0.603712"], ["83918.20", "1.588717"], ["83916.20", "4.180834"], ["83874.20", "4.628153"], ["83865.80", "4.991145"], ["83857.40", "4.174412"], ["83849.00", "5.172641"], ["83840.60", "5.263389"], ["83832.20", "4.809649"], ["83823.80", "5.444885"], ["83815.40", "4.718901"], ["83807.00", "4.446656"], ["83798.60", "4.900397"], ["83790.20", "4.537404"], ["83781.80", "4.265160"], ["83773.40", "5.354137"], ["83765.00", "4.083664"], ["83756.60", "3.992916"], ["83748.20", "4.355908"], ["83739.80", "5.081893"], ["83731.40", "5.626381"], ["83723.00", "5.535633"], ["83714.60", "3.902168"], ["83458.10", "0"]], "checksum": 1299604650, "ts": "1742576918732"}], "ts": 1742576918736, "record_time": 1742576918.93248, "EXCHANGE": "BITGET"}
{"action": "update", "arg": {"instType": "SPOT", "channel": "books", "instId": "BTCUSDT"}, "data": [{"asks": [["83940.00", "1.451692"], ["84042.30", "4.537404"], ["84050.70", "5.172641"], ["84075.90", "4.446656"], ["84084.30", "5.263389"], ["84092.70", "5.626381"], ["84101.10", "4.628153"], ["84109.50", "4.718901"], ["84117.90", "4.991145"], ["84126.30", "3.992916"], ["84134.70", "5.354137"], ["84143.10", "4.083664"], ["84151.50", "4.809649"], ["84159.90", "4.900397"], ["84168.30", "4.174412"], ["84176.70", "5.081893"], ["84185.10", "4.355908"], ["84193.50", "4.265160"], ["84201.90", "5.535633"]], "bids": [["83932.20", "0.001817"], ["83930.20", "0.004782"], ["83928.20", "0.012585"], ["83926.20", "0.033119"], ["83924.20", "0.087155"], ["83922.20", "0.229355"], ["83920.20", "0.603564"], ["83918.20", "1.588328"], ["83916.20", "4.179811"], ["83913.61", "0.354563"], ["83874.20", "5.626381"], ["83869.00", "0.000015"], ["83865.80", "4.718901"], ["83857.40", "4.083664"], ["83849.00", "4.809649"], ["83840.60", "4.265160"], ["83832.20", "5.444885"], ["83823.80", "3.902168"], ["83815.40", "4.991145"], ["83807.00", "4.628153"], ["83798.60", "5.354137"], ["83790.20", "4.174412"], ["83781.80", "3.992916"], ["83773.40", "4.900397"], ["83765.00", "5.535633"], ["83756.60", "5.172641"], ["83748.20", "5.263389"], ["83731.40", "4.446656"], ["83723.00", "4.537404"], ["83714.60", "4.355908"]], "checksum": -860528174, "ts": "1742576918943"}], "ts": 1742576918948, "record_time": 1742576919.143946, "EXCHANGE": "BITGET"}
{"action": "update", "arg": {"instType": "SPOT", "channel": "books", "instId": "BTCUSDT"}, "data": [{"asks": [["83940.00", "1.451668"], ["83950.91", "0"], ["83951.38", "0"], ["83953.38", "0"], ["83954.09", "0"], ["83954.82", "0.050434"], ["83954.83", "0"], ["83955.67", "0"], ["83956.46", "0"], ["83956.57", "0.035971"], ["83956.59", "0"], ["83956.74", "0"], ["83957.00", "0.119905"], ["83957.49", "0"], ["83958.20", "0"], ["83958.29", "0"], ["83958.62", "0"], ["83958.93", "0.006357"], ["83958.97", "0"], ["83959.11", "0.012714"], ["83960.24", "0.006357"], ["83960.38", "0.010995"], ["83960.64", "0.012713"], ["83960.96", "0"], ["83961.37", "0"], ["83961.40", "0.016429"], ["83961.49", "0"], ["83962.03", "0.119901"], ["83962.09", "0"], ["83962.29", "0.016429"], ["83962.46", "0.006357"], ["83963.20", "0.006357"], ["83963.83", "0.006357"], ["83963.98", "0.010993"], ["83964.74", "0.009990"], ["83966.39", "0"], ["83966.64", "0"], ["83966.67", "0.119905"], ["83966.73", "0.119858"], ["83966.90", "0.015895"], ["83967.27", "0.009989"], ["83968.27", "0"], ["83969.20", "0.006356"], ["83971.05", "0.015896"], ["83971.80", "0.010988"], ["83982.30", "0.001500"], ["83984.30", "0.003851"], ["83986.30", "0.010133"], ["83988.30", "0.026667"], ["83990.30", "0.070177"], ["83992.30", "0.184674"], ["83994.30", "0.485985"], ["83996.30", "1.278909"], ["83998.30", "3.365548"], ["84000.30", "8.856706"], ["84004.40", "0.012240"], ["84012.70", "2.359080"], ["84012.80", "0"], ["84042.30", "4.446656"], ["84050.70", "5.354137"], ["84059.10", "4.628153"], ["84067.50", "5.626381"], ["84075.90", "4.718901"], ["84084.30", "4.083664"], ["84092.70", "4.900397"], ["84101.10", "3.992916"], ["84109.50", "5.444885"], ["84117.90", "5.081893"], ["84126.30", "4.809649"], ["84134.70", "4.265160"], ["84143.10", "5.263389"], ["84151.50", "4.174412"], ["84159.90", "4.355908"], ["84168.30", "5.535633"], ["84176.70", "3.902168"], ["84185.10", "4.537404"], ["84193.50", "4.991145"], ["84201.90", "5.172641"], ["84346.43", "0.000128"]], "bids": [["83934.55", "0.153031"], ["83934.33", "0"], ["83930.20", "0.004651"], ["83928.20", "0.012240"], ["83926.20", "0.032211"], ["83924.20", "0.084765"], ["83922.20", "0.223067"], ["83920.20", "0.587017"], ["83919.34", "0.047600"], ["83918.20", "1.544676"], ["83916.28", "0.089650"], ["83916.20", "4.064937"], ["83916.10", "0.076680"], ["83915.87", "0.247478"], ["83914.46", "0.004035"], ["83914.45", "0.017822"], ["83914.28", "0.018268"], ["83913.30", "0.012000"], ["83912.74", "0.006570"], ["83912.70", "0.055622"], ["83912.46", "0.017119"], ["83911.87", "0.028867"], ["83911.09", "0.025192"], ["83910.93", "0.008198"], ["83910.83", "0.224990"], ["83910.62", "0"], ["83910.35", "0"], ["83910.26", "0"], ["83909.65", "0.008288"], ["83909.42", "0.051833"], ["83909.27", "0.012671"], ["83908.56", "0"], ["83908.51", "0.018544"], ["83908.45", "0.007780"], ["83907.49", "0"], ["83907.15", "0"], ["83906.63", "0.222996"], ["83906.58", "0"], ["83906.23", "0.259144"], ["83905.96", "0.083202"], ["83905.39", "0"], ["83905.21", "0"], ["83903.94", "0"], ["83903.89", "0.012457"], ["83903.73", "0"], ["83903.69", "0"], ["83902.74", "0"], ["83902.22", "0.073167"], ["83901.66", "0"], ["83901.34", "0.008107"], ["83901.29", "0.056450"], ["83900.86", "0"], ["83900.44", "0"], ["83900.22", "0"], ["83899.64", "0.000878"], ["83899.44", "0"], ["83897.07", "0"], ["83895.89", "0"], ["83881.14", "0.003602"], ["83874.20", "4.900397"], ["83865.80", "4.537404"], ["83864.16", "0"], ["83857.40", "5.354137"], ["83840.60", "4.718901"], ["83832.20", "3.992916"], ["83823.80", "4.991145"], ["83815.40", "5.535633"], ["83807.00", "4.355908"], ["83798.60", "4.174412"], ["83790.20", "4.083664"], ["83781.80", "3.902168"], ["83773.40", "4.446656"], ["83765.00", "5.081893"], ["83756.60", "5.626381"], ["83748.20", "4.628153"], ["83739.80", "4.265160"], ["83731.40", "5.263389"], ["83723.00", "5.172641"], ["83714.60", "5.444885"], ["83458.33", "0"], ["83458.15", "0"]], "checksum": -606183351, "ts": "1742576919144"}], "ts": 1742576919146, "record_time": 1742576919.342999, "EXCHANGE": "BITGET"}
{"action": "update", "arg": {"instType": "SPOT", "channel": "books", "instId": "BTCUSDT"}, "data": [{"asks": [["83940.01", "0.000100"], ["83958.85", "0.100455"], ["83986.30", "0.010389"], ["83988.30", "0.027340"], ["83990.30", "0.071945"], ["83992.30", "0.189330"], ["83994.30", "0.498237"], ["83996.30", "1.311149"], ["83998.30", "3.450392"], ["84000.30", "9.079981"], ["84042.30", "5.444885"], ["84059.10", "4.537404"], ["84067.50", "4.355908"], ["84075.90", "5.535633"], ["84084.30", "4.265160"], ["84092.70", "4.991145"], ["84109.50", "4.174412"], ["84117.90", "4.083664"], ["84126.30", "4.628153"], ["84134.70", "5.626381"], ["84143.10", "3.902168"], ["84151.50", "5.172641"], ["84159.90", "4.900397"], ["84168.30", "4.718901"], ["84176.70", "5.081893"], ["84185.10", "4.809649"], ["84193.50", "5.263389"], ["84201.90", "4.446656"]], "bids": [["83939.99", "0.542265"], ["83916.10", "0.061260"], ["83889.00", "0.000017"], ["83888.00", "0.000017"], ["83887.00", "0"], ["83886.00", "0"], ["83885.00", "0"], ["83884.00", "0"], ["83883.00", "0"], ["83882.00", "0"], ["83881.00", "0"], ["83880.00", "0.002000"], ["83879.00", "0"], ["83878.00", "0"], ["83877.00", "0"], ["83876.00", "0"], ["83875.00", "0"], ["83874.20", "5.263389"], ["83874.00", "0"], ["83873.00", "0"], ["83872.00", "0"], ["83871.00", "0"], ["83870.00", "0"], ["83869.00", "0"], ["83865.80", "5.354137"], ["83857.40", "4.174412"], ["83849.00", "4.446656"], ["83840.60", "4.628153"], ["83832.20", "4.083664"], ["83823.80", "4.265160"], ["83815.40", "5.081893"], ["83807.00", "5.444885"], ["83798.60", "4.991145"], ["83790.20", "4.718901"], ["83781.80", "4.537404"], ["83773.40", "5.626381"], ["83765.00", "3.992916"], ["83756.60", "4.809649"], ["83748.20", "5.172641"], ["83739.80", "5.535633"], ["83731.40", "4.355908"], ["83723.00", "3.902168"], ["83714.60", "4.900397"], ["83458.33", "0.000218"], ["83458.15", "0.000010"], ["83458.10", "0.000011"], ["83457.63", "0.000023"], ["83456.52", "0.000010"], ["83456.00", "0.000133"], ["83455.56", "0.000025"], ["83455.07", "0.000013"], ["83454.55", "0.000027"], ["83454.54", "0.001547"], ["83454.53", "0.000057"], ["83453.95", "0.000093"], ["83453.56", "0.000022"], ["83452.83", "0.000008"], ["83451.33", "0.000010"], ["83450.00", "0.005575"], ["83448.28", "0.000151"], ["83448.14", "0.000070"]], "checksum": -2016032696, "ts": "1742576919345"}], "ts": 1742576919347, "record_time": 1742576919.543144, "EXCHANGE": "BITGET"}
{"action": "update", "arg": {"instType": "SPOT", "channel": "books", "instId": "BTCUSDT"}, "data": [{"asks": [["83959.11", "0.006357"], ["83961.59", "0.006357"], ["83966.70", "0.100915"], ["83986.30", "0.010133"], ["83988.30", "0.026667"], ["83990.30", "0.070177"], ["83992.30", "0.184674"], ["83994.30", "0.485985"], ["83996.30", "1.278909"], ["83998.30", "3.365548"], ["84000.30", "8.856706"], ["84042.30", "5.354137"], ["84050.70", "4.265160"], ["84059.10", "5.263389"], ["84075.90", "4.900397"], ["84084.30", "4.537404"], ["84092.70", "4.628153"], ["84101.10", "5.535633"], ["84109.50", "4.446656"], ["84126.30", "5.626381"], ["84134.70", "4.174412"], ["84143.10", "5.444885"], ["84151.50", "3.902168"], ["84159.90", "4.991145"], ["84168.30", "5.172641"], ["84176.70", "3.992916"], ["84193.50", "5.081893"], ["84201.90", "4.718901"], ["84346.43", "0"]], "bids": [["83926.20", "0.031981"], ["83924.20", "0.084161"], ["83922.20", "0.221475"], ["83920.20", "0.582830"], ["83918.20", "1.533763"], ["83916.20", "4.036460"], ["83874.20", "4.083664"], ["83865.80", "4.991145"], ["83857.40", "4.628153"], ["83849.00", "5.081893"], ["83840.60", "4.174412"], ["83832.20", "4.537404"], ["83823.80", "5.172641"], ["83815.40", "3.902168"], ["83807.00", "4.718901"], ["83798.60", "4.900397"], ["83790.20", "4.809649"], ["83781.80", "5.626381"], ["83773.40", "4.446656"], ["83765.00", "5.263389"], ["83756.60", "5.444885"], ["83748.20", "5.535633"], ["83739.80", "3.992916"], ["83731.40", "4.265160"], ["83723.00", "4.355908"], ["83714.60", "5.354137"]], "checksum": -734591781, "ts": "1742576919557"}], "ts": 1742576919559, "record_time": 1742576919.754529, "EXCHANGE": "BITGET"}
{"action": "update", "arg": {"instType": "SPOT", "channel": "books", "instId": "BTCUSDT"}, "data": [{"asks": [["83978.70", "0"], ["84042.30", "4.174412"], ["84059.10", "4.991145"], ["84075.90", "3.902168"], ["84084.30", "4.083664"], ["84092.70", "5.535633"], ["84101.10", "5.263389"], ["84109.50", "5.354137"], ["84117.90", "5.444885"], ["84126.30", "4.809649"], ["84134.70", "5.172641"], ["84143.10", "4.718901"], ["84151.50", "4.446656"], ["84159.90", "4.628153"], ["84168.30", "3.992916"], ["84176.70", "5.626381"], ["84185.10", "4.537404"], ["84201.90", "4.900397"], ["84346.43", "0.000128"]], "bids": [["83934.73", "0.038710"], ["83934.55", "0"], ["83932.37", "0.114301"], ["83932.20", "0.002237"], ["83930.20", "0.005887"], ["83928.20", "0.015491"], ["83926.20", "0.040767"], ["83924.20", "0.107281"], ["83922.20", "0.282318"], ["83920.20", "0.742944"], ["83918.20", "1.955115"], ["83916.20", "5.145039"], ["83874.20", "4.355908"], ["83865.80", "4.900397"], ["83857.40", "4.083664"], ["83849.00", "4.446656"], ["83840.60", "5.626381"], ["83823.80", "3.992916"], ["83815.40", "5.172641"], ["83807.00", "5.081893"], ["83798.60", "4.628153"], ["83790.20", "4.265160"], ["83781.80", "5.444885"], ["83773.40", "4.809649"], ["83756.60", "4.991145"], ["83748.20", "4.174412"], ["83739.80", "5.535633"], ["83731.40", "3.902168"], ["83723.00", "5.354137"], ["83714.60", "4.718901"], ["83448.14", "0"]], "checksum": 1553885756, "ts": "1742576919758"}], "ts": 1742576919761, "record_time": 1742576919.971509, "EXCHANGE": "BITGET"}
{"action": "update", "arg": {"instType": "SPOT", "channel": "books", "instId": "BTCUSDT"}, "data": [{"asks": [["83978.83", "0.191152"], ["83986.30", "0.010154"], ["83988.30", "0.026720"], ["83990.30", "0.070316"], ["83992.30", "0.185043"], ["83994.30", "0.486955"], ["83996.30", "1.281460"], ["83998.30", "3.372263"], ["84000.30", "8.874376"], ["84007.00", "0.018510"], ["84042.30", "4.355908"], ["84050.70", "5.263389"], ["84059.10", "5.444885"], ["84067.50", "5.535633"], ["84075.90", "4.174412"], ["84092.70", "4.537404"], ["84101.10", "4.628153"], ["84109.50", "5.172641"], ["84117.90", "5.626381"], ["84126.30", "4.446656"], ["84134.70", "3.992916"], ["84143.10", "4.265160"], ["84151.50", "4.991145"], ["84159.90", "3.902168"], ["84168.30", "4.718901"], ["84176.70", "5.081893"], ["84185.10", "4.900397"], ["84193.50", "4.809649"], ["84201.90", "5.354137"], ["84345.79", "0"], ["84346.43", "0"]], "bids": [["83934.74", "0.011924"], ["83934.56", "0"], ["83932.20", "0.001754"], ["83930.20", "0.004616"], ["83928.20", "0.012148"], ["83926.20", "0.032198"], ["83924.20", "0.084732"], ["83922.20", "0.222981"], ["83920.20", "0.586792"], ["83918.20", "1.544188"], ["83916.20", "4.063654"], ["83916.10", "0.066210"], ["83916.00", "0.042510"], ["83913.60", "4.165680"], ["83874.20", "5.354137"], ["83865.80", "4.628153"], ["83857.40", "5.444885"], ["83849.00", "5.263389"], ["83840.60", "4.174412"], ["83832.20", "4.991145"], ["83823.80", "4.083664"], ["83815.40", "5.535633"], ["83807.00", "3.902168"], ["83798.60", "4.537404"], ["83790.20", "4.718901"], ["83781.80", "4.809649"], ["83773.40", "4.900397"], ["83765.00", "4.265160"], ["83756.60", "4.446656"], ["83748.20", "5.172641"], ["83739.80", "3.992916"], ["83731.40", "5.626381"], ["83723.00", "4.355908"], ["83714.60", "5.081893"]], "checksum": 1933250021, "ts": "1742576919981"}], "ts": 1742576919986, "record_time": 1742576920.181872, "EXCHANGE": "BITGET"}
{"action": "update", "arg": {"instType": "SPOT", "channel": "books", "instId": "BTCUSDT"}, "data": [{"asks": [["83983.98", "0"], ["83990.30", "0.070169"], ["83992.30", "0.184655"], ["83994.30", "0.485934"], ["83996.30", "1.278774"], ["83998.30", "3.365195"], ["84000.30", "8.855776"], ["84004.40", "0.027240"], ["84012.70", "0"], ["84042.30", "5.354137"], ["84050.70", "4.537404"], ["84059.10", "5.626381"], ["84067.50", "4.809649"], ["84075.90", "4.355908"], ["84084.30", "4.718901"], ["84092.70", "5.444885"], ["84101.10", "5.172641"], ["84109.50", "4.900397"], ["84117.90", "4.265160"], ["84126.30", "4.083664"], ["84143.10", "4.174412"], ["84151.50", "4.628153"], ["84159.90", "5.263389"], ["84168.30", "5.081893"], ["84176.70", "4.446656"], ["84185.10", "5.535633"], ["84193.50", "4.991145"], ["84201.90", "3.902168"], ["84345.79", "0.000034"], ["84346.43", "0.000128"]], "bids": [["83934.93", "0.038710"], ["83934.73", "0"], ["83932.38", "0.038481"], ["83930.21", "0"], ["83916.10", "0.061470"], ["83913.30", "0"], ["83889.00", "0"], ["83874.20", "4.991145"], ["83867.00", "0.000015"], ["83865.80", "3.902168"], ["83857.40", "5.081893"], ["83849.00", "4.900397"], ["83832.20", "4.265160"], ["83823.80", "4.809649"], ["83815.40", "5.444885"], ["83807.00", "5.535633"], ["83798.60", "5.263389"], ["83781.80", "5.354137"], ["83773.40", "4.355908"], ["83765.00", "4.628153"], ["83756.60", "4.083664"], ["83748.20", "3.992916"], ["83739.80", "5.626381"], ["83731.40", "5.172641"], ["83723.00", "4.446656"], ["83714.60", "4.537404"], ["83448.14", "0.000070"]], "checksum": -1267604158, "ts": "1742576920182"}], "ts": 1742576920186, "record_time": 1742576920.384061, "EXCHANGE": "BITGET"}
{"action": "update", "arg": {"instType": "SPOT", "channel": "books", "instId": "BTCUSDT"}, "data": [{"asks": [["83996.30", "1.278661"], ["83998.30", "3.364898"], ["84000.30", "8.854995"], ["84042.30", "5.263389"], ["84050.70", "5.172641"], ["84059.10", "4.174412"], ["84067.50", "5.444885"], ["84075.90", "5.626381"], ["84084.30", "4.809649"], ["84092.70", "4.991145"], ["84101.10", "5.535633"], ["84109.50", "4.355908"], ["84117.90", "4.446656"], ["84126.30", "4.537404"], ["84134.70", "3.902168"], ["84143.10", "4.083664"], ["84151.50", "4.718901"], ["84159.90", "4.265160"], ["84168.30", "3.992916"], ["84176.70", "5.081893"], ["84185.10", "4.628153"], ["84193.50", "4.900397"], ["84201.90", "5.354137"]], "bids": [["83936.46", "0.010000"], ["83934.94", "0.011924"], ["83934.74", "0"], ["83920.20", "0.586904"], ["83918.20", "1.544422"], ["83916.20", "4.064435"], ["83874.20", "4.809649"], ["83865.80", "5.354137"], ["83857.40", "4.991145"], ["83849.00", "4.628153"], ["83840.60", "5.535633"], ["83832.20", "4.083664"], ["83823.80", "4.718901"], ["83807.00", "4.174412"], ["83798.60", "3.992916"], ["83797.31", "0"], ["83790.20", "5.626381"], ["83781.80", "4.446656"], ["83773.40", "4.537404"], ["83765.00", "4.355908"], ["83756.60", "4.265160"], ["83748.20", "5.263389"], ["83739.80", "4.900397"], ["83731.40", "3.902168"], ["83723.00", "5.081893"], ["83714.60", "5.172641"]], "checksum": -321493127, "ts": "1742576920427"}], "ts": 1742576920430, "record_time": 1742576920.626299, "EXCHANGE": "BITGET"}
{"action": "update", "arg": {"instType": "SPOT", "channel": "books", "instId": "BTCUSDT"}, "data": [{"asks": [["83940.01", "0.004414"], ["83971.04", "0.008065"], ["83991.32", "0"], ["83992.90", "0.001598"], ["83993.23", "0"], ["83994.82", "0.001598"], ["84007.00", "0.035700"], ["84042.30", "4.991145"], ["84050.70", "4.174412"], ["84059.10", "5.172641"], ["84067.50", "4.537404"], ["84075.90", "4.355908"], ["84084.30", "3.992916"], ["84092.70", "4.718901"], ["84101.10", "4.809649"], ["84109.50", "3.902168"], ["84117.90", "5.626381"], ["84126.30", "4.083664"], ["84134.70", "5.081893"], ["84143.10", "5.354137"], ["84151.50", "4.265160"], ["84159.90", "5.263389"], ["84168.30", "5.444885"], ["84176.70", "4.628153"], ["84185.10", "4.446656"], ["84201.90", "5.535633"], ["84346.43", "0"]], "bids": [["83934.93", "0"], ["83926.20", "0.032028"], ["83924.20", "0.084283"], ["83922.20", "0.221799"], ["83920.20", "0.583681"], ["83918.20", "1.536004"], ["83916.20", "4.042115"], ["83916.10", "0.066990"], ["83914.00", "0.467640"], ["83913.60", "0.536970"], ["83910.90", "0"], ["83887.00", "0.000017"], ["83882.77", "0.001177"], ["83881.20", "0"], ["83880.83", "0.001173"], ["83879.24", "0"], ["83865.80", "5.626381"], ["83857.40", "3.902168"], ["83849.00", "5.535633"], ["83840.60", "5.444885"], ["83832.20", "4.900397"], ["83823.80", "4.537404"], ["83817.47", "0.125823"], ["83815.40", "5.354137"], ["83807.00", "5.263389"], ["83798.60", "5.081893"], ["83790.20", "4.446656"], ["83781.80", "4.174412"], ["83773.40", "4.265160"], ["83756.60", "4.628153"], ["83748.20", "3.992916"], ["83739.80", "4.991145"], ["83731.40", "5.172641"], ["83723.00", "4.718901"], ["83714.60", "4.083664"], ["83530.00", "0.000575"]], "checksum": 923422603, "ts": "1742576920632"}], "ts": 1742576920635, "record_time": 1742576920.830633, "EXCHANGE": "BITGET"}
