{"action": "update", "arg": {"instType": "SPOT", "channel": "books", "instId": "BTCUSDT"}, "data": [{"asks": [["84065.30", "4.808330"], ["84073.70", "4.989777"], ["84082.10", "4.354714"], ["84090.50", "5.443393"], ["84098.90", "4.173268"], ["84107.30", "5.352670"], ["84115.70", "5.534116"], ["84124.10", "4.082545"], ["84132.50", "4.445437"], ["84140.90", "3.901098"], ["84149.30", "4.899054"], ["84157.70", "4.626884"], ["84166.10", "4.536161"], ["84174.50", "4.717607"], ["84182.90", "3.991821"], ["84191.30", "5.171223"], ["84199.70", "5.624839"], ["84208.10", "5.080500"], ["84216.50", "5.261946"]], "bids": [["83957.88", "0.038690"], ["83897.20", "4.354714"], ["83888.80", "4.989777"], ["83880.40", "4.536161"], ["83872.00", "4.082545"], ["83863.60", "5.352670"], ["83855.20", "5.443393"], ["83846.80", "3.991821"], ["83838.40", "5.171223"], ["83830.00", "4.173268"], ["83821.60", "4.808330"], ["83813.20", "4.445437"], ["83804.80", "4.626884"], ["83796.40", "4.263991"], ["83788.00", "5.534116"], ["83771.20", "4.717607"], ["83762.80", "5.261946"], ["83754.40", "4.899054"], ["83746.00", "5.080500"], ["83737.60", "3.901098"], ["83439.42", "0"]], "checksum": -659196788, "ts": "1742577055587"}], "ts": 1742577055590, "record_time": 1742577055.783276, "EXCHANGE": "BITGET"}
{"action": "update", "arg": {"instType": "SPOT", "channel": "books", "instId": "BTCUSDT"}, "data": [{"asks": [["84003.30", "0.001354"], ["84005.30", "0.002208"], ["84007.30", "0.005627"], ["84009.30", "0.014807"], ["84011.30", "0.038966"], ["84013.30", "0.102542"], ["84015.30", "0.269848"], ["84017.30", "0.710128"], ["84019.30", "1.868756"], ["84021.30", "4.917780"], ["84023.30", "12.941527"], ["84028.70", "0"], ["84030.60", "1.607880"], ["84030.70", "2.358570"], ["84065.30", "4.354714"], ["84073.70", "5.534116"], ["84082.10", "4.899054"], ["84090.50", "4.082545"], ["84098.90", "5.352670"], ["84107.30", "4.536161"], ["84115.70", "4.173268"], ["84124.10", "5.261946"], ["84132.50", "3.991821"], ["84140.90", "4.445437"], ["84149.30", "5.171223"], ["84157.70", "5.443393"], ["84166.10", "4.626884"], ["84174.50", "5.080500"], ["84182.90", "3.901098"], ["84191.30", "4.717607"], ["84199.70", "4.808330"], ["84208.10", "4.989777"], ["84216.50", "4.263991"], ["84224.90", "5.624839"]], "bids": [["83953.20", "0.003491"], ["83951.20", "0.009187"], ["83949.20", "0.024175"], ["83947.20", "0.063618"], ["83945.20", "0.167416"], ["83943.20", "0.440569"], ["83941.20", "1.159393"], ["83939.20", "3.051032"], ["83939.00", "0.971790"], ["83936.30", "0.387570"], ["83936.20", "0.361620"], ["83935.00", "0.075000"], ["83931.20", "1.449240"], ["83897.20", "5.080500"], ["83888.80", "5.352670"], ["83880.40", "3.901098"], ["83863.60", "4.626884"], ["83855.20", "5.624839"], ["83846.80", "4.445437"], ["83838.40", "4.263991"], ["83830.00", "5.261946"], ["83821.60", "4.536161"], ["83813.20", "4.808330"], ["83804.80", "5.171223"], ["83796.40", "5.534116"], ["83788.00", "4.899054"], ["83779.60", "3.991821"], ["83771.20", "5.443393"], ["83762.80", "4.354714"], ["83754.40", "4.989777"], ["83746.00", "4.173268"], ["83737.60", "4.717607"], ["83441.56", "0"], ["83440.00", "0"]], "checksum": -1273473342, "ts": "1742577055808"}], "ts": 1742577055812, "record_time": 1742577056.035621, "EXCHANGE": "BITGET"}
{"action": "update", "arg": {"instType": "SPOT", "channel": "books", "instId": "BTCUSDT"}, "data": [{"asks": [["84065.30", "5.261946"], ["84082.10", "5.624839"], ["84090.50", "4.899054"], ["84098.90", "4.082545"], ["84107.30", "5.352670"], ["84124.10", "4.989777"], ["84140.90", "5.443393"], ["84149.30", "4.626884"], ["84157.70", "4.536161"], ["84166.10", "5.080500"], ["84174.50", "4.263991"], ["84182.90", "4.354714"], ["84191.30", "4.808330"], ["84199.70", "4.717607"], ["84208.10", "5.171223"], ["84216.50", "4.445437"], ["84224.90", "3.901098"]], "bids": [["83958.02", "0.038690"], ["83957.88", "0"], ["83951.92", "0"], ["83939.20", "3.051293"], ["83938.40", "0.099630"], ["83937.90", "0.538980"], ["83936.40", "0.089280"], ["83936.30", "0"], ["83931.20", "1.146600"], ["83928.60", "0.012630"], ["83897.20", "4.536161"], ["83888.80", "5.080500"], ["83886.00", "0"], ["83880.40", "4.263991"], ["83879.20", "0.000971"], ["83872.00", "4.989777"], ["83863.60", "4.899054"], ["83855.20", "5.171223"], ["83846.80", "3.991821"], ["83838.40", "5.261946"], ["83830.00", "4.626884"], ["83821.60", "5.443393"], ["83813.20", "5.534116"], ["83804.80", "4.082545"], ["83796.40", "4.173268"], ["83788.00", "3.901098"], ["83779.60", "4.808330"], ["83771.20", "5.624839"], ["83762.80", "4.445437"], ["83754.40", "4.354714"], ["83746.00", "4.717607"], ["83737.60", "5.352670"]], "checksum": 759318620, "ts": "1742577056024"}], "ts": 1742577056028, "record_time": 1742577056.221836, "EXCHANGE": "BITGET"}
{"action": "update", "arg": {"instType": "SPOT", "channel": "books", "instId": "BTCUSDT"}, "data": [{"asks": [["83983.94", "0.314422"], ["83996.86", "0"], ["84011.30", "0.038742"], ["84013.30", "0.101953"], ["84015.30", "0.268297"], ["84017.30", "0.706045"], ["84019.30", "1.858013"], ["84021.30", "4.889508"], ["84023.30", "12.867127"], ["84065.30", "4.173268"], ["84073.70", "3.901098"], ["84082.10", "5.261946"], ["84090.50", "3.991821"], ["84098.90", "4.808330"], ["84107.30", "4.717607"], ["84115.70", "5.080500"], ["84124.10", "5.624839"], ["84132.50", "5.534116"], ["84140.90", "4.354714"], ["84149.30", "4.263991"], ["84157.70", "4.989777"], ["84166.10", "4.082545"], ["84174.50", "4.899054"], ["84182.90", "4.445437"], ["84191.30", "5.171223"], ["84199.70", "4.536161"], ["84208.10", "5.443393"], ["84216.50", "5.352670"], ["84224.90", "4.626884"]], "bids": [["83953.20", "0.003236"], ["83951.20", "0.008515"], ["83949.20", "0.022408"], ["83947.20", "0.058968"], ["83945.20", "0.155179"], ["83943.20", "0.408366"], ["83941.20", "1.074647"], ["83939.20", "2.828018"], ["83939.00", "0"], ["83938.40", "0"], ["83937.90", "0"], ["83936.40", "0.089490"], ["83936.20", "0.361830"], ["83928.60", "0.057630"], ["83910.00", "0.002121"], ["83897.20", "5.624839"], ["83888.80", "4.536161"], ["83880.40", "5.080500"], ["83872.00", "4.263991"], ["83863.60", "5.534116"], ["83855.20", "4.899054"], ["83846.80", "4.717607"], ["83838.40", "3.991821"], ["83830.00", "5.171223"], ["83821.60", "4.445437"], ["83813.20", "4.354714"], ["83804.80", "3.901098"], ["83788.00", "5.352670"], ["83779.60", "5.443393"], ["83771.20", "4.808330"], ["83762.80", "4.626884"], ["83754.40", "4.989777"], ["83746.00", "5.261946"], ["83737.60", "4.082545"], ["83441.56", "0.000024"], ["83440.00", "0.000460"], ["83439.42", "0.000423"]], "checksum": 1248507977, "ts": "1742577056226"}], "ts": 1742577056229, "record_time": 1742577056.422929, "EXCHANGE": "BITGET"}
{"action": "update", "arg": {"instType": "SPOT", "channel": "books", "instId": "BTCUSDT"}, "data": [{"asks": [["83996.73", "0"], ["84021.29", "0.081518"], ["84021.30", "4.889388"], ["84023.30", "12.866810"], ["84065.30", "5.443393"], ["84073.70", "4.263991"], ["84082.10", "5.534116"], ["84098.90", "5.261946"], ["84107.30", "4.808330"], ["84115.70", "4.899054"], ["84124.10", "4.717607"], ["84132.50", "5.624839"], ["84140.90", "5.352670"], ["84149.30", "4.173268"], ["84157.70", "5.080500"], ["84166.10", "4.536161"], ["84174.50", "4.445437"], ["84182.90", "4.626884"], ["84191.30", "4.082545"], ["84199.70", "3.901098"], ["84208.10", "4.354714"], ["84216.50", "4.989777"], ["84224.90", "5.171223"]], "bids": [["83958.02", "0"], ["83951.57", "0"], ["83943.20", "0.408253"], ["83941.20", "1.074350"], ["83939.20", "2.827237"], ["83928.60", "0.012630"], ["83897.20", "4.717607"], ["83888.80", "5.352670"], ["83872.00", "4.536161"], ["83863.60", "5.171223"], ["83855.20", "4.173268"], ["83846.80", "4.899054"], ["83838.40", "5.624839"], ["83830.00", "3.991821"], ["83821.60", "5.261946"], ["83813.20", "5.534116"], ["83804.80", "4.263991"], ["83796.40", "4.082545"], ["83788.00", "4.808330"], ["83779.60", "4.354714"], ["83771.20", "4.989777"], ["83762.80", "5.443393"], ["83754.40", "4.445437"], ["83746.00", "3.901098"], ["83737.60", "4.626884"], ["83439.33", "0.000010"], ["83437.50", "0.000009"]], "checksum": 465922145, "ts": "1742577056428"}], "ts": 1742577056432, "record_time": 1742577056.625986, "EXCHANGE": "BITGET"}
{"action": "update", "arg": {"instType": "SPOT", "channel": "books", "instId": "BTCUSDT"}, "data": [{"asks": [["84001.56", "0.010000"], ["84007.30", "0.005780"], ["84009.30", "0.015210"], ["84011.30", "0.040026"], ["84013.30", "0.105332"], ["84015.30", "0.277190"], ["84017.30", "0.729447"], ["84019.30", "1.919597"], ["84021.30", "5.051570"], ["84023.30", "13.293606"], ["84028.80", "2.358630"], ["84030.60", "1.018470"], ["84030.70", "0"], ["84065.30", "4.354714"], ["84073.70", "4.536161"], ["84082.10", "4.445437"], ["84090.50", "3.901098"], ["84098.90", "4.173268"], ["84107.30", "4.263991"], ["84115.70", "3.991821"], ["84124.10", "5.261946"], ["84132.50", "5.443393"], ["84140.90", "4.808330"], ["84149.30", "4.626884"], ["84166.10", "4.082545"], ["84174.50", "4.717607"], ["84182.90", "5.534116"], ["84191.30", "5.624839"], ["84199.70", "5.352670"], ["84208.10", "5.171223"], ["84224.90", "4.899054"], ["84340.00", "0"]], "bids": [["83958.18", "0.038690"], ["83952.59", "0.006794"], ["83951.10", "0.114057"], ["83943.20", "0.408530"], ["83941.20", "1.075078"], ["83939.20", "2.829153"], ["83938.00", "0.004290"], ["83935.70", "0.120210"], ["83934.90", "0"], ["83934.80", "0.878550"], ["83934.70", "0.456630"], ["83934.60", "0.072780"], ["83933.70", "0.136800"], ["83929.90", "0"], ["83928.60", "0"], ["83897.20", "5.624839"], ["83888.80", "4.536161"], ["83880.40", "4.989777"], ["83872.00", "3.991821"], ["83863.60", "4.899054"], ["83855.20", "4.445437"], ["83846.80", "4.263991"], ["83838.40", "4.173268"], ["83830.00", "5.080500"], ["83821.60", "5.171223"], ["83813.20", "4.626884"], ["83804.80", "3.901098"], ["83796.40", "5.534116"], ["83788.00", "4.082545"], ["83779.60", "5.443393"], ["83771.20", "4.717607"], ["83762.80", "4.354714"], ["83754.40", "5.261946"], ["83746.00", "4.808330"], ["83737.60", "5.352670"], ["83439.42", "0"], ["83439.33", "0"], ["83437.50", "0"]], "checksum": -1688745851, "ts": "1742577056643"}], "ts": 1742577056645, "record_time": 1742577056.8393, "EXCHANGE": "BITGET"}
{"action": "update", "arg": {"instType": "SPOT", "channel": "books", "instId": "BTCUSDT"}, "data": [{"asks": [["83996.74", "0"], ["84003.30", "0.001470"], ["84005.30", "0.002398"], ["84007.30", "0.006310"], ["84009.30", "0.016606"], ["84011.30", "0.043700"], ["84013.30", "0.115000"], ["84015.30", "0.302632"], ["84017.30", "0.796399"], ["84019.30", "2.095788"], ["84021.30", "5.515231"], ["84023.30", "14.513766"], ["84065.30", "4.263991"], ["84073.70", "4.717607"], ["84082.10", "3.991821"], ["84090.50", "4.808330"], ["84098.90", "5.534116"], ["84107.30", "5.352670"], ["84115.70", "4.354714"], ["84132.50", "5.171223"], ["84140.90", "4.082545"], ["84149.30", "4.899054"], ["84157.70", "4.173268"], ["84166.10", "4.445437"], ["84174.50", "4.536161"], ["84182.90", "4.626884"], ["84199.70", "5.080500"], ["84208.10", "3.901098"], ["84216.50", "5.443393"], ["84224.90", "4.989777"], ["84340.00", "0.019520"]], "bids": [["83952.59", "0.040162"], ["83936.30", "1.005840"], ["83935.70", "0.120000"], ["83935.60", "0.720150"], ["83934.80", "0"], ["83934.70", "0"], ["83929.90", "0.120000"], ["83912.00", "0.000281"], ["83897.20", "4.808330"], ["83888.80", "4.082545"], ["83880.40", "5.534116"], ["83872.00", "4.263991"], ["83863.60", "4.536161"], ["83855.20", "4.989777"], ["83846.80", "3.901098"], ["83838.40", "4.445437"], ["83830.00", "4.173268"], ["83821.60", "4.354714"], ["83813.20", "5.261946"], ["83804.80", "4.626884"], ["83796.40", "5.352670"], ["83788.00", "5.443393"], ["83779.60", "5.080500"], ["83771.20", "4.899054"], ["83762.80", "5.171223"], ["83754.40", "5.624839"], ["83746.00", "3.991821"], ["83737.60", "4.717607"]], "checksum": 733411117, "ts": "1742577056845"}], "ts": 1742577056847, "record_time": 1742577057.067165, "EXCHANGE": "BITGET"}
{"action": "update", "arg": {"instType": "SPOT", "channel": "books", "instId": "BTCUSDT"}, "data": [{"asks": [["83983.93", "0.168102"], ["83984.04", "0"], ["84021.29", "0"], ["84065.30", "4.989777"], ["84073.70", "4.808330"], ["84090.50", "4.445437"], ["84098.90", "4.626884"], ["84107.30", "5.261946"], ["84115.70", "4.536161"], ["84124.10", "4.263991"], ["84132.50", "4.173268"], ["84140.90", "4.717607"], ["84149.30", "3.901098"], ["84157.70", "4.899054"], ["84166.10", "5.534116"], ["84174.50", "5.352670"], ["84182.90", "4.354714"], ["84191.30", "5.443393"], ["84199.70", "5.171223"], ["84208.10", "4.082545"], ["84216.50", "5.080500"], ["84224.90", "5.624839"], ["84340.46", "0.000143"]], "bids": [["83958.28", "0.038690"], ["83958.18", "0"], ["83936.44", "0.272716"], ["83897.20", "5.534116"], ["83888.80", "4.626884"], ["83880.40", "4.899054"], ["83872.00", "5.624839"], ["83863.60", "4.717607"], ["83846.80", "3.991821"], ["83838.40", "4.173268"], ["83830.00", "5.443393"], ["83821.60", "5.171223"], ["83804.80", "5.080500"], ["83796.40", "4.445437"], ["83788.00", "4.808330"], ["83779.60", "4.263991"], ["83771.20", "4.082545"], ["83762.80", "4.354714"], ["83754.40", "3.901098"], ["83746.00", "5.352670"], ["83737.60", "4.536161"]], "checksum": -568258922, "ts": "1742577057069"}], "ts": 1742577057073, "record_time": 1742577057.266196, "EXCHANGE": "BITGET"}
{"action": "update", "arg": {"instType": "SPOT", "channel": "books", "instId": "BTCUSDT"}, "data": [{"asks": [["83962.01", "1.086045"], ["83994.21", "0.180634"], ["84013.54", "0.001598"], ["84015.47", "0.001598"], ["84015.81", "0"], ["84017.71", "0"], ["84065.30", "4.173268"], ["84073.70", "4.263991"], ["84082.10", "4.354714"], ["84090.50", "5.171223"], ["84098.90", "5.534116"], ["84107.30", "4.989777"], ["84124.10", "3.991821"], ["84132.50", "4.717607"], ["84140.90", "4.445437"], ["84149.30", "4.899054"], ["84157.70", "4.626884"], ["84166.10", "5.443393"], ["84174.50", "3.901098"], ["84182.90", "5.624839"], ["84191.30", "5.352670"], ["84199.70", "4.808330"], ["84208.10", "5.080500"], ["84216.50", "4.082545"], ["84224.90", "5.261946"], ["84340.46", "0"]], "bids": [["83962.00", "0.561168"], ["83952.59", "0"], ["83941.20", "1.074937"], ["83939.20", "2.828781"], ["83936.30", "0"], ["83935.70", "0.120210"], ["83928.60", "0.012630"], ["83905.66", "0"], ["83903.69", "0"], ["83903.39", "0.001177"], ["83901.46", "0.001173"], ["83897.20", "4.263991"], ["83888.80", "4.173268"], ["83880.40", "5.080500"], ["83872.00", "4.989777"], ["83863.60", "5.443393"], ["83855.20", "4.808330"], ["83846.80", "4.536161"], ["83838.40", "4.717607"], ["83830.00", "3.901098"], ["83821.60", "5.624839"], ["83804.80", "4.082545"], ["83796.40", "3.991821"], ["83788.00", "5.171223"], ["83779.60", "4.354714"], ["83771.20", "5.534116"], ["83762.80", "4.899054"], ["83754.40", "4.626884"], ["83737.60", "4.445437"], ["83439.42", "0.000423"]], "checksum": 1200690779, "ts": "1742577057276"}], "ts": 1742577057278, "record_time": 1742577057.472456, "EXCHANGE": "BITGET"}
{"action": "update", "arg": {"instType": "SPOT", "channel": "books", "instId": "BTCUSDT"}, "data": [{"asks": [["83962.01", "1.078341"], ["84065.30", "4.626884"], ["84073.70", "4.354714"], ["84082.10", "4.899054"], ["84090.50", "5.261946"], ["84098.90", "5.443393"], ["84107.30", "4.717607"], ["84115.70", "5.624839"], ["84124.10", "4.173268"], ["84132.50", "3.991821"], ["84140.90", "4.082545"], ["84149.30", "4.989777"], ["84157.70", "4.445437"], ["84166.10", "4.808330"], ["84174.50", "4.536161"], ["84182.90", "5.080500"], ["84191.30", "4.263991"], ["84199.70", "5.171223"], ["84208.10", "3.901098"], ["84216.50", "5.352670"], ["84224.90", "5.534116"]], "bids": [["83958.28", "0"], ["83951.11", "0.038457"], ["83943.20", "0.408218"], ["83941.20", "1.074259"], ["83939.20", "2.826995"], ["83939.02", "0"], ["83938.66", "0.004034"], ["83936.44", "0"], ["83936.20", "0"], ["83935.60", "0.720360"], ["83935.00", "0.060000"], ["83934.40", "1.304580"], ["83928.60", "0.057630"], ["83909.00", "0"], ["83897.20", "5.080500"], ["83888.80", "4.536161"], ["83880.40", "4.717607"], ["83872.00", "4.808330"], ["83863.60", "5.352670"], ["83855.20", "5.624839"], ["83846.80", "4.354714"], ["83838.40", "5.171223"], ["83830.00", "4.263991"], ["83821.60", "5.261946"], ["83813.20", "4.626884"], ["83804.80", "5.443393"], ["83788.00", "5.534116"], ["83779.60", "4.899054"], ["83771.20", "4.445437"], ["83762.80", "3.901098"], ["83754.40", "4.082545"], ["83746.00", "4.173268"], ["83737.60", "4.989777"], ["83439.33", "0.000010"], ["83437.50", "0.000009"], ["83437.10", "0.000095"]], "checksum": -2144085034, "ts": "1742577057476"}], "ts": 1742577057480, "record_time": 1742577057.675119, "EXCHANGE": "BITGET"}
{"action": "update", "arg": {"instType": "SPOT", "channel": "books", "instId": "BTCUSDT"}, "data": [{"asks": [["83994.79", "0.010988"], ["83994.80", "0"], ["84065.30", "5.171223"], ["84073.70", "3.901098"], ["84082.10", "5.624839"], ["84090.50", "4.717607"], ["84098.90", "5.534116"], ["84107.30", "4.989777"], ["84115.70", "5.080500"], ["84124.10", "4.626884"], ["84132.50", "5.352670"], ["84140.90", "4.899054"], ["84149.30", "4.263991"], ["84157.70", "4.354714"], ["84166.10", "4.173268"], ["84174.50", "5.261946"], ["84182.90", "4.445437"], ["84191.30", "5.443393"], ["84199.70", "4.082545"], ["84208.10", "4.808330"], ["84216.50", "4.536161"], ["84224.90", "3.991821"]], "bids": [["83958.44", "0.038740"], ["83943.20", "0.408524"], ["83941.20", "1.075064"], ["83939.20", "2.829246"], ["83938.00", "0.004710"], ["83937.90", "0.230340"], ["83936.44", "0.274421"], ["83936.30", "0.807180"], ["83935.70", "0.120000"], ["83935.60", "0.720150"], ["83934.40", "0.444660"], ["83932.90", "0"], ["83897.20", "4.173268"], ["83888.80", "4.445437"], ["83880.40", "5.261946"], ["83872.00", "5.080500"], ["83863.60", "5.171223"], ["83855.20", "5.443393"], ["83846.80", "3.901098"], ["83838.40", "4.989777"], ["83830.00", "5.352670"], ["83821.60", "4.899054"], ["83813.20", "4.354714"], ["83804.80", "3.991821"], ["83796.40", "5.624839"], ["83788.00", "4.263991"], ["83779.60", "4.082545"], ["83771.20", "5.534116"], ["83762.80", "4.626884"], ["83754.40", "4.536161"], ["83746.00", "4.717607"], ["83737.60", "4.808330"], ["83439.33", "0"], ["83437.50", "0"], ["83437.10", "0"]], "checksum": 1341248764, "ts": "1742577057695"}], "ts": 1742577057699, "record_time": 1742577057.892171, "EXCHANGE": "BITGET"}
{"action": "update", "arg": {"instType": "SPOT", "channel": "books", "instId": "BTCUSDT"}, "data": [{"asks": [["84065.30", "4.173268"], ["84073.70", "5.080500"], ["84082.10", "5.171223"], ["84090.50", "4.899054"], ["84098.90", "3.901098"], ["84107.30", "3.991821"], ["84115.70", "5.261946"], ["84124.10", "5.352670"], ["84132.50", "5.624839"], ["84140.90", "4.808330"], ["84149.30", "4.445437"], ["84157.70", "4.082545"], ["84166.10", "5.534116"], ["84174.50", "4.626884"], ["84182.90", "5.443393"], ["84191.30", "4.717607"], ["84199.70", "4.263991"], ["84208.10", "4.536161"], ["84216.50", "4.989777"], ["84224.90", "4.354714"]], "bids": [["83910.00", "0.002281"], ["83897.20", "4.082545"], ["83888.80", "5.352670"], ["83880.40", "4.173268"], ["83872.00", "3.991821"], ["83863.60", "5.534116"], ["83855.20", "4.717607"], ["83846.80", "4.626884"], ["83838.40", "4.263991"], ["83830.00", "4.808330"], ["83813.20", "5.443393"], ["83804.80", "3.901098"], ["83796.40", "4.354714"], ["83788.00", "5.624839"], ["83779.60", "5.171223"], ["83771.20", "4.445437"], ["83762.80", "4.989777"], ["83754.40", "5.080500"], ["83746.00", "5.261946"], ["83737.60", "4.536161"]], "checksum": 1341248764, "ts": "1742577057909"}], "ts": 1742577057911, "record_time": 1742577058.10507, "EXCHANGE": "BITGET"}
{"action": "update", "arg": {"instType": "SPOT", "channel": "books", "instId": "BTCUSDT"}, "data": [{"asks": [["83994.20", "0.120247"], ["83995.13", "0"], ["84005.12", "0.012864"], ["84065.30", "4.989777"], ["84073.70", "4.445437"], ["84082.10", "4.899054"], ["84090.50", "5.080500"], ["84098.90", "4.536161"], ["84107.30", "5.534116"], ["84115.70", "3.991821"], ["84124.10", "4.717607"], ["84132.50", "4.173268"], ["84140.90", "5.624839"], ["84149.30", "3.901098"], ["84157.70", "5.352670"], ["84166.10", "5.261946"], ["84174.50", "5.443393"], ["84182.90", "4.808330"], ["84191.30", "5.171223"], ["84199.70", "4.082545"], ["84208.10", "4.354714"], ["84216.50", "4.626884"], ["84224.90", "4.263991"]], "bids": [["83958.58", "0.038740"], ["83958.44", "0"], ["83951.34", "0.010000"], ["83934.80", "0.412410"], ["83897.20", "4.536161"], ["83888.80", "3.991821"], ["83880.40", "3.901098"], ["83872.00", "4.717607"], ["83863.60", "4.173268"], ["83855.20", "5.624839"], ["83846.80", "5.443393"], ["83838.40", "4.445437"], ["83830.00", "4.354714"], ["83821.60", "5.352670"], ["83813.20", "5.171223"], ["83804.80", "4.989777"], ["83796.40", "5.534116"], ["83788.00", "4.082545"], ["83779.60", "4.626884"], ["83771.20", "5.080500"], ["83762.80", "4.808330"], ["83754.40", "4.899054"], ["83746.00", "4.263991"], ["83737.60", "5.261946"], ["83440.00", "0"], ["83439.42", "0"]], "checksum": 1850520208, "ts": "1742577058111"}], "ts": 1742577058115, "record_time": 1742577058.311856, "EXCHANGE": "BITGET"}
{"action": "update", "arg": {"instType": "SPOT", "channel": "books", "instId": "BTCUSDT"}, "data": [{"asks": [["83971.96", "0.092943"], ["84017.29", "0.301569"], ["84065.30", "4.263991"], ["84073.70", "3.901098"], ["84082.10", "5.624839"], ["84090.50", "5.352670"], ["84098.90", "4.354714"], ["84107.30", "4.989777"], ["84115.70", "4.808330"], ["84124.10", "5.534116"], ["84132.50", "4.899054"], ["84140.90", "4.717607"], ["84149.30", "4.082545"], ["84157.70", "4.445437"], ["84166.10", "4.173268"], ["84174.50", "3.991821"], ["84182.90", "5.261946"], ["84191.30", "4.536161"], ["84199.70", "4.626884"], ["84208.10", "5.443393"], ["84216.50", "5.080500"], ["84224.90", "5.171223"], ["84340.00", "0"]], "bids": [["83939.20", "2.829376"], ["83937.40", "0.101700"], ["83936.30", "0.806970"], ["83934.60", "0"], ["83897.20", "4.263991"], ["83880.40", "4.899054"], ["83872.00", "3.901098"], ["83863.60", "5.080500"], ["83855.20", "4.536161"], ["83846.80", "4.173268"], ["83838.40", "5.261946"], ["83830.00", "4.808330"], ["83821.60", "4.717607"], ["83813.20", "5.352670"], ["83804.80", "4.354714"], ["83796.40", "5.624839"], ["83788.00", "5.171223"], ["83779.60", "5.534116"], ["83771.20", "5.443393"], ["83762.80", "4.445437"], ["83754.40", "4.082545"], ["83746.00", "4.626884"], ["83737.60", "4.989777"]], "checksum": -86314333, "ts": "1742577058316"}], "ts": 1742577058322, "record_time": 1742577058.514813, "EXCHANGE": "BITGET"}
{"action": "update", "arg": {"instType": "SPOT", "channel": "books", "instId": "BTCUSDT"}, "data": [{"asks": [["84032.50", "0.100920"], ["84033.90", "0"], ["84065.30", "4.808330"], ["84073.70", "5.261946"], ["84082.10", "4.989777"], ["84090.50", "4.626884"], ["84098.90", "5.080500"], ["84107.30", "4.536161"], ["84115.70", "4.082545"], ["84124.10", "4.445437"], ["84132.50", "5.624839"], ["84140.90", "4.354714"], ["84149.30", "5.352670"], ["84157.70", "5.443393"], ["84166.10", "3.901098"], ["84174.50", "5.171223"], ["84182.90", "4.717607"], ["84191.30", "3.991821"], ["84199.70", "4.263991"], ["84208.10", "5.534116"], ["84216.50", "4.173268"], ["84224.90", "4.899054"], ["84340.00", "0.019520"]], "bids": [["83951.20", "0.008679"], ["83949.20", "0.022839"], ["83947.20", "0.060102"], ["83945.20", "0.158163"], ["83944.30", "0"], ["83943.20", "0.416219"], ["83941.20", "1.095314"], ["83939.20", "2.882405"], ["83937.50", "0.204856"], ["83929.90", "0.130710"], ["83928.60", "0"], ["83908.10", "0.207210"], ["83897.20", "4.717607"], ["83888.80", "5.443393"], ["83880.40", "4.445437"], ["83872.00", "4.173268"], ["83855.20", "5.624839"], ["83846.80", "5.261946"], ["83838.40", "4.808330"], ["83830.00", "5.352670"], ["83821.60", "5.534116"], ["83813.20", "4.082545"], ["83804.80", "5.171223"], ["83796.40", "4.354714"], ["83788.00", "4.263991"], ["83779.60", "4.626884"], ["83771.20", "3.991821"], ["83762.80", "4.536161"], ["83754.40", "4.989777"], ["83746.00", "3.901098"], ["83737.60", "4.899054"]], "checksum": -1307167926, "ts": "1742577058520"}], "ts": 1742577058522, "record_time": 1742577058.715818, "EXCHANGE": "BITGET"}
{"action": "update", "arg": {"instType": "SPOT", "channel": "books", "instId": "BTCUSDT"}, "data": [{"asks": [["84001.56", "0"], ["84065.30", "3.901098"], ["84073.70", "4.808330"], ["84082.10", "5.352670"], ["84090.50", "5.080500"], ["84098.90", "4.899054"], ["84107.30", "5.171223"], ["84115.70", "5.261946"], ["84124.10", "4.263991"], ["84132.50", "5.443393"], ["84140.90", "3.991821"], ["84149.30", "4.445437"], ["84157.70", "4.536161"], ["84166.10", "4.626884"], ["84174.50", "4.989777"], ["84182.90", "5.624839"], ["84191.30", "4.082545"], ["84199.70", "4.173268"], ["84208.10", "4.717607"], ["84216.50", "4.354714"], ["84224.90", "5.534116"], ["84340.46", "0.000143"]], "bids": [["83958.70", "0.038740"], ["83958.58", "0"], ["83953.20", "0.003553"], ["83951.20", "0.009351"], ["83949.20", "0.024608"], ["83947.20", "0.064758"], ["83945.20", "0.170415"], ["83943.20", "0.448460"], ["83941.20", "1.180158"], ["83939.20", "3.105679"], ["83912.00", "0.000121"], ["83897.20", "5.352670"], ["83880.40", "5.080500"], ["83872.00", "4.717607"], ["83863.60", "5.624839"], ["83855.20", "4.173268"], ["83846.80", "4.263991"], ["83830.00", "4.082545"], ["83821.60", "4.899054"], ["83813.20", "5.171223"], ["83804.80", "3.901098"], ["83788.00", "3.991821"], ["83779.60", "4.536161"], ["83771.20", "4.626884"], ["83762.80", "4.445437"], ["83754.40", "5.261946"], ["83746.00", "5.534116"], ["83737.60", "4.989777"]], "checksum": -246861271, "ts": "1742577058726"}], "ts": 1742577058730, "record_time": 1742577058.925123, "EXCHANGE": "BITGET"}
{"action": "update", "arg": {"instType": "SPOT", "channel": "books", "instId": "BTCUSDT"}, "data": [{"asks": [["83994.21", "0"], ["84019.30", "2.095661"], ["84021.30", "5.514899"], ["84023.30", "14.512892"], ["84065.30", "4.626884"], ["84073.70", "4.989777"], ["84082.10", "5.261946"], ["84090.50", "4.717607"], ["84098.90", "5.443393"], ["84107.30", "4.445437"], ["84115.70", "3.901098"], ["84124.10", "4.808330"], ["84132.50", "4.173268"], ["84140.90", "5.624839"], ["84149.30", "5.171223"], ["84166.10", "3.991821"], ["84174.50", "4.354714"], ["84182.90", "4.263991"], ["84191.30", "5.080500"], ["84199.70", "4.899054"], ["84208.10", "4.082545"], ["84216.50", "5.534116"], ["84224.90", "5.352670"], ["84340.72", "0.000066"]], "bids": [["83953.20", "0.003298"], ["83951.20", "0.008679"], ["83949.20", "0.022683"], ["83947.20", "0.059691"], ["83945.20", "0.157083"], ["83943.20", "0.413375"], ["83941.20", "1.087829"], ["83939.20", "2.862707"], ["83937.40", "0"], ["83936.30", "0.098220"], ["83928.60", "0.045000"], ["83897.20", "4.173268"], ["83888.80", "5.624839"], ["83872.00", "3.991821"], ["83863.60", "4.536161"], ["83855.20", "5.261946"], ["83846.80", "4.082545"], ["83838.40", "3.901098"], ["83830.00", "5.352670"], ["83821.60", "4.626884"], ["83813.20", "4.717607"], ["83804.80", "4.354714"], ["83796.40", "4.263991"], ["83788.00", "4.989777"], ["83779.60", "5.534116"], ["83771.20", "4.808330"], ["83762.80", "5.443393"], ["83754.40", "4.899054"], ["83746.00", "4.445437"], ["83737.60", "5.171223"]], "checksum": -667380892, "ts": "1742577058948"}], "ts": 1742577058949, "record_time": 1742577059.144372, "EXCHANGE": "BITGET"}
{"action": "update", "arg": {"instType": "SPOT", "channel": "books", "instId": "BTCUSDT"}, "data": [{"asks": [["83993.84", "0.183712"], ["83994.20", "0.066056"], ["84017.30", "0.796206"], ["84019.30", "2.095280"], ["84021.30", "5.513895"], ["84023.30", "14.510251"], ["84028.80", "0"], ["84030.40", "2.358600"], ["84065.30", "4.808330"], ["84073.70", "5.352670"], ["84082.10", "4.173268"], ["84090.50", "4.626884"], ["84098.90", "5.080500"], ["84107.30", "4.354714"], ["84115.70", "4.899054"], ["84124.10", "4.082545"], ["84132.50", "4.989777"], ["84140.90", "4.445437"], ["84149.30", "3.991821"], ["84166.10", "4.263991"], ["84174.50", "4.717607"], ["84182.90", "5.443393"], ["84191.30", "5.534116"], ["84199.70", "3.901098"], ["84208.10", "5.261946"], ["84216.50", "5.171223"], ["84224.90", "5.624839"], ["84340.72", "0"]], "bids": [["83958.82", "0.038740"], ["83958.70", "0"], ["83941.78", "0"], ["83939.20", "2.862819"], ["83937.10", "0.495090"], ["83936.50", "0.894840"], ["83936.30", "0.098010"], ["83935.60", "0.240390"], ["83935.00", "0.075000"], ["83934.60", "0.070830"], ["83928.60", "0"], ["83897.20", "5.624839"], ["83888.80", "4.717607"], ["83880.40", "4.263991"], ["83872.00", "4.536161"], ["83863.60", "4.989777"], ["83855.20", "4.626884"], ["83846.80", "5.534116"], ["83838.40", "4.082545"], ["83830.00", "5.261946"], ["83821.60", "5.080500"], ["83813.20", "3.901098"], ["83804.80", "5.171223"], ["83796.40", "4.445437"], ["83788.00", "4.354714"], ["83779.60", "4.173268"], ["83771.20", "5.443393"], ["83762.80", "5.352670"], ["83746.00", "3.991821"], ["83737.60", "4.808330"], ["83441.56", "0"]], "checksum": 1390133533, "ts": "1742577059148"}], "ts": 1742577059150, "record_time": 1742577059.343392, "EXCHANGE": "BITGET"}
{"action": "update", "arg": {"instType": "SPOT", "channel": "books", "instId": "BTCUSDT"}, "data": [{"asks": [["84007.30", "0.006123"], ["84009.30", "0.016114"], ["84011.30", "0.042404"], ["84013.30", "0.111591"], ["84015.30", "0.293659"], ["84017.30", "0.772787"], ["84019.30", "2.033651"], ["84021.30", "5.351713"], ["84023.30", "14.083455"], ["84030.40", "4.014630"], ["84030.60", "0.073230"], ["84044.01", "0.036715"], ["84065.30", "4.626884"], ["84073.70", "5.080500"], ["84082.10", "5.261946"], ["84090.50", "4.536161"], ["84098.90", "4.082545"], ["84107.30", "4.173268"], ["84115.70", "4.989777"], ["84124.10", "3.991821"], ["84132.50", "4.263991"], ["84140.90", "4.808330"], ["84149.30", "5.624839"], ["84157.70", "5.443393"], ["84166.10", "4.717607"], ["84174.50", "5.534116"], ["84182.90", "4.445437"], ["84191.30", "5.352670"], ["84199.70", "4.354714"], ["84208.10", "3.901098"], ["84224.90", "4.899054"], ["84340.46", "0"]], "bids": [["83936.50", "0.895050"], ["83936.40", "0.089280"], ["83934.60", "0"], ["83909.00", "0.000160"], ["83897.20", "4.354714"], ["83888.80", "4.536161"], ["83880.40", "4.717607"], ["83872.00", "4.899054"], ["83863.60", "5.171223"], ["83855.20", "5.261946"], ["83846.80", "5.624839"], ["83838.40", "4.173268"], ["83830.00", "5.080500"], ["83821.60", "3.991821"], ["83813.20", "5.352670"], ["83804.80", "4.445437"], ["83796.40", "4.808330"], ["83788.00", "5.534116"], ["83779.60", "5.443393"], ["83771.20", "3.901098"], ["83762.80", "4.263991"], ["83754.40", "4.989777"], ["83746.00", "4.626884"], ["83737.60", "4.082545"]], "checksum": 1390133533, "ts": "1742577059402"}], "ts": 1742577059406, "record_time": 1742577059.599121, "EXCHANGE": "BITGET"}
{"action": "update", "arg": {"instType": "SPOT", "channel": "books", "instId": "BTCUSDT"}, "data": [{"asks": [["84023.30", "14.083585"], ["84073.70", "4.808330"], ["84082.10", "5.352670"], ["84090.50", "4.717607"], ["84098.90", "5.261946"], ["84107.30", "5.080500"], ["84115.70", "4.173268"], ["84124.10", "4.354714"], ["84140.90", "5.443393"], ["84157.70", "4.445437"], ["84166.10", "4.989777"], ["84174.50", "5.171223"], ["84182.90", "5.534116"], ["84191.30", "3.901098"], ["84199.70", "3.991821"], ["84208.10", "4.899054"], ["84216.50", "4.536161"], ["84224.90", "4.082545"]], "bids": [["83958.82", "0"], ["83955.20", "0.001025"], ["83953.20", "0.001805"], ["83951.20", "0.004749"], ["83949.20", "0.012498"], ["83947.20", "0.032890"], ["83945.20", "0.086551"], ["83943.20", "0.227768"], ["83941.20", "0.599387"], ["83939.20", "1.577522"], ["83897.20", "5.624839"], ["83888.80", "4.626884"], ["83880.40", "5.171223"], ["83872.00", "4.173268"], ["83863.60", "5.534116"], ["83855.20", "4.808330"], ["83846.80", "4.354714"], ["83838.40", "3.991821"], ["83830.00", "4.263991"], ["83821.60", "4.445437"], ["83813.20", "4.717607"], ["83804.80", "5.443393"], ["83796.40", "4.899054"], ["83788.00", "5.261946"], ["83779.60", "5.352670"], ["83771.20", "4.082545"], ["83762.80", "5.080500"], ["83746.00", "4.536161"], ["83737.60", "3.901098"], ["83441.56", "0.000024"]], "checksum": 1323027233, "ts": "1742577059620"}], "ts": 1742577059624, "record_time": 1742577059.817652, "EXCHANGE": "BITGET"}
{"action": "update", "arg": {"instType": "SPOT", "channel": "books", "instId": "BTCUSDT"}, "data": [{"asks": [["84019.30", "2.033431"], ["84021.30", "5.351133"], ["84023.30", "14.081930"], ["84065.30", "3.991821"], ["84082.10", "4.899054"], ["84090.50", "5.624839"], ["84098.90", "4.626884"], ["84107.30", "5.534116"], ["84132.50", "3.901098"], ["84140.90", "5.261946"], ["84149.30", "4.717607"], ["84157.70", "4.082545"], ["84166.10", "4.536161"], ["84174.50", "4.263991"], ["84182.90", "5.171223"], ["84191.30", "4.445437"], ["84199.70", "5.080500"], ["84208.10", "5.443393"], ["84216.50", "5.352670"], ["84224.90", "4.989777"]], "bids": [["83958.93", "0.038740"], ["83945.20", "0.086352"], ["83943.21", "0.252298"], ["83943.20", "0.227241"], ["83941.20", "0.598002"], ["83939.20", "1.573690"], ["83897.20", "4.717607"], ["83888.80", "5.443393"], ["83880.40", "4.082545"], ["83872.00", "4.808330"], ["83863.60", "5.624839"], ["83855.20", "4.536161"], ["83846.80", "4.173268"], ["83838.40", "5.534116"], ["83821.60", "5.171223"], ["83813.20", "4.354714"], ["83804.80", "4.899054"], ["83796.40", "5.352670"], ["83788.00", "5.080500"], ["83779.60", "4.989777"], ["83771.20", "4.445437"], ["83762.80", "3.991821"], ["83754.40", "5.261946"], ["83746.00", "4.626884"], ["83441.56", "0"]], "checksum": 1046600914, "ts": "1742577059832"}], "ts": 1742577059834, "record_time": 1742577060.026994, "EXCHANGE": "BITGET"}
{"action": "update", "arg": {"instType": "SPOT", "channel": "books", "instId": "BTCUSDT"}, "data": [{"asks": [["84023.30", "14.081725"], ["84073.70", "5.443393"], ["84082.10", "5.080500"], ["84098.90", "4.354714"], ["84107.30", "4.717607"], ["84115.70", "5.352670"], ["84124.10", "4.082545"], ["84132.50", "4.808330"], ["84140.90", "4.989777"], ["84149.30", "5.534116"], ["84157.70", "4.536161"], ["84166.10", "5.261946"], ["84174.50", "5.171223"], ["84182.90", "4.173268"], ["84191.30", "4.626884"], ["84199.70", "4.899054"], ["84208.10", "3.901098"], ["84216.50", "4.263991"], ["84224.90", "4.445437"]], "bids": [["83941.20", "0.597868"], ["83939.20", "1.573337"], ["83936.44", "0.460007"], ["83910.00", "0.002121"], ["83897.20", "4.626884"], ["83888.80", "5.261946"], ["83880.40", "5.352670"], ["83872.00", "4.989777"], ["83863.60", "4.899054"], ["83855.20", "5.624839"], ["83846.80", "4.354714"], ["83838.40", "4.082545"], ["83830.00", "4.173268"], ["83821.60", "4.445437"], ["83813.20", "4.808330"], ["83804.80", "5.171223"], ["83796.40", "4.717607"], ["83788.00", "4.536161"], ["83779.60", "3.901098"], ["83771.20", "3.991821"], ["83762.80", "5.534116"], ["83754.40", "5.080500"], ["83746.00", "5.443393"], ["83737.60", "4.263991"]], "checksum": 766345474, "ts": "1742577060034"}], "ts": 1742577060036, "record_time": 1742577060.229581, "EXCHANGE": "BITGET"}
{"action": "update", "arg": {"instType": "SPOT", "channel": "books", "instId": "BTCUSDT"}, "data": [{"asks": [["83993.83", "0.125939"], ["83994.20", "0"], ["84017.30", "0.772678"], ["84021.30", "5.350957"], ["84023.30", "14.081595"], ["84065.30", "4.354714"], ["84073.70", "5.534116"], ["84082.10", "4.082545"], ["84090.50", "4.899054"], ["84098.90", "5.443393"], ["84107.30", "3.991821"], ["84115.70", "5.624839"], ["84124.10", "4.717607"], ["84132.50", "4.445437"], ["84140.90", "4.536161"], ["84149.30", "5.261946"], ["84157.70", "3.901098"], ["84166.10", "4.808330"], ["84174.50", "4.989777"], ["84191.30", "4.263991"], ["84199.70", "5.171223"], ["84208.10", "5.080500"], ["84216.50", "5.352670"], ["84224.90", "4.626884"]], "bids": [["83959.04", "0.038739"], ["83958.93", "0"], ["83951.34", "0"], ["83939.20", "1.573225"], ["83934.10", "0.071910"], ["83897.20", "4.082545"], ["83888.80", "4.173268"], ["83880.40", "3.991821"], ["83872.00", "5.534116"], ["83863.60", "4.808330"], ["83855.20", "4.445437"], ["83846.80", "4.989777"], ["83838.40", "4.354714"], ["83830.00", "5.624839"], ["83821.60", "4.626884"], ["83813.20", "5.171223"], ["83804.80", "5.080500"], ["83796.40", "3.901098"], ["83788.00", "5.352670"], ["83779.60", "5.443393"], ["83771.20", "5.261946"], ["83762.80", "4.263991"], ["83754.40", "4.717607"], ["83746.00", "4.899054"], ["83737.60", "4.536161"]], "checksum": -1791482033, "ts": "1742577060236"}], "ts": 1742577060241, "record_time": 1742577060.434328, "EXCHANGE": "BITGET"}
{"action": "update", "arg": {"instType": "SPOT", "channel": "books", "instId": "BTCUSDT"}, "data": [{"asks": [["84065.30", "4.263991"], ["84073.70", "4.626884"], ["84082.10", "4.717607"], ["84090.50", "5.171223"], ["84098.90", "4.445437"], ["84107.30", "5.534116"], ["84115.70", "4.989777"], ["84124.10", "3.991821"], ["84132.50", "4.899054"], ["84140.90", "4.354714"], ["84149.30", "5.443393"], ["84157.70", "5.261946"], ["84166.10", "5.352670"], ["84174.50", "3.901098"], ["84182.90", "4.808330"], ["84191.30", "5.624839"], ["84199.70", "4.536161"], ["84216.50", "4.082545"], ["84224.90", "4.173268"]], "bids": [["83962.00", "0.291668"], ["83897.20", "4.354714"], ["83888.80", "4.626884"], ["83880.40", "5.534116"], ["83872.00", "4.536161"], ["83855.20", "4.082545"], ["83846.80", "3.991821"], ["83838.40", "4.717607"], ["83830.00", "5.443393"], ["83821.60", "4.263991"], ["83813.20", "5.261946"], ["83804.80", "5.171223"], ["83796.40", "4.445437"], ["83788.00", "5.624839"], ["83779.60", "5.080500"], ["83771.20", "4.899054"], ["83762.80", "4.173268"], ["83754.40", "5.352670"], ["83746.00", "4.989777"], ["83737.60", "3.901098"]], "checksum": 1244902646, "ts": "1742577060437"}], "ts": 1742577060442, "record_time": 1742577060.636769, "EXCHANGE": "BITGET"}
{"action": "update", "arg": {"instType": "SPOT", "channel": "books", "instId": "BTCUSDT"}, "data": [{"asks": [["83959.46", "0.497000"], ["83960.06", "0.158391"], ["83962.00", "0.026960"], ["83962.01", "0.993690"], ["83970.01", "0"], ["83971.16", "0.006357"], ["83971.97", "0.221109"], ["83972.01", "0.006357"], ["83972.19", "0.006357"], ["83972.24", "0.002383"], ["83972.94", "0.006357"], ["83973.65", "0.006357"], ["83973.73", "0.016429"], ["83973.74", "0.006357"], ["83973.93", "0.010995"], ["83974.19", "0.006357"], ["83974.21", "0.006357"], ["83975.73", "0.006357"], ["83975.97", "0.017475"], ["83976.18", "0.035971"], ["83976.52", "0"], ["83977.14", "0.119905"], ["83978.28", "0"], ["83978.32", "0.119850"], ["83978.45", "0.006357"], ["83979.04", "0.119858"], ["83979.48", "0.015895"], ["83979.93", "0"], ["83980.11", "0"], ["83980.14", "0.006356"], ["83981.19", "0.035972"], ["83981.51", "0"], ["83981.61", "0.006356"], ["83981.98", "0"], ["83982.14", "0"], ["83982.39", "0.006357"], ["83982.54", "0"], ["83982.57", "0"], ["83983.01", "0"], ["83983.32", "0.010993"], ["83983.51", "0"], ["83983.61", "0"], ["83983.68", "0"], ["83983.74", "0"], ["83984.23", "0"], ["83984.49", "0"], ["83984.52", "0"], ["83984.82", "0"], ["83984.97", "0.119901"], ["83985.00", "0"], ["83985.06", "0"], ["83985.17", "0"], ["83985.38", "0"], ["83985.50", "0"], ["83985.55", "0"], ["83985.95", "0"], ["83986.41", "0"], ["83986.67", "0.009989"], ["83987.07", "0"], ["83987.08", "0"], ["83987.51", "0.009990"], ["83987.76", "0"], ["83988.67", "0"], ["83989.56", "0.119905"], ["83989.84", "0"], ["83989.96", "0"], ["83990.06", "0"], ["83990.37", "0"], ["83992.27", "0"], ["83992.70", "0.001018"], ["83993.77", "0.015896"], ["83994.19", "0"], ["83994.70", "0.001019"], ["83994.79", "0"], ["83994.84", "0.010000"], ["83996.70", "0.001008"], ["83998.70", "0.001001"], ["84000.06", "0.714285"], ["84000.70", "0.001479"], ["84002.70", "0.003892"], ["84003.30", "0"], ["84004.70", "0.010242"], ["84005.13", "0"], ["84005.30", "0"], ["84006.70", "0.026953"], ["84007.30", "0"], ["84008.70", "0.070927"], ["84009.30", "0"], ["84010.57", "0.022837"], ["84010.64", "0"], ["84010.70", "0.186652"], ["84011.30", "0"], ["84011.43", "0.023109"], ["84012.70", "0.491189"], ["84012.90", "2.315460"], ["84013.30", "0"], ["84013.80", "10.050690"], ["84014.00", "17.387940"], ["84014.10", "1.079040"], ["84014.40", "7.142100"], ["84014.90", "15.281940"], ["84015.30", "0"], ["84016.00", "0.042510"], ["84016.90", "0.035700"], ["84017.29", "0.116137"], ["84017.30", "0"], ["84017.80", "11.921760"], ["84018.00", "0.042480"], ["84018.50", "2.859150"], ["84019.00", "1.079220"], ["84019.30", "0"], ["84019.80", "1.968000"], ["84020.00", "0.042300"], ["84020.50", "0.603090"], ["84021.30", "0"], ["84022.00", "6.297360"], ["84022.60", "0.250620"], ["84022.90", "0.090000"], ["84023.20", "1.350000"], ["84023.30", "1.924050"], ["84023.40", "0"], ["84023.70", "0.323640"], ["84024.00", "0.042300"], ["84024.30", "0.069510"], ["84025.00", "0"], ["84025.70", "0"], ["84026.00", "0"], ["84026.30", "0"], ["84026.50", "0"], ["84027.10", "0"], ["84028.00", "0"], ["84028.90", "0"], ["84029.80", "0"], ["84030.00", "0.002000"], ["84030.30", "0"], ["84030.40", "0"], ["84030.60", "0"], ["84031.00", "0"], ["84031.10", "0"], ["84031.70", "0"], ["84032.00", "0"], ["84032.10", "0"], ["84032.50", "0"], ["84033.08", "1.785011"], ["84033.10", "0"], ["84033.20", "0"], ["84034.00", "0"], ["84034.50", "0"], ["84034.80", "0"], ["84034.90", "0"], ["84044.02", "0"], ["84049.41", "0"], ["84050.32", "0"], ["84054.70", "3.901590"], ["84063.10", "5.534813"], ["84065.30", "0"], ["84071.50", "4.718201"], ["84073.70", "0"], ["84079.90", "5.262609"], ["84082.10", "0"], ["84088.30", "4.445998"], ["84090.50", "0"], ["84096.70", "4.899671"], ["84098.90", "0"], ["84105.10", "5.625548"], ["84107.30", "0"], ["84113.50", "4.536732"], ["84115.70", "0"], ["84121.90", "5.081140"], ["84124.10", "0"], ["84130.30", "4.083059"], ["84132.50", "0"], ["84138.70", "4.627467"], ["84140.90", "0"], ["84147.10", "5.444079"], ["84149.30", "0"], ["84155.50", "4.990405"], ["84155.80", "0"], ["84157.70", "0"], ["84163.90", "3.992324"], ["84166.10", "0"], ["84172.30", "5.353344"], ["84174.50", "0"], ["84180.70", "5.171875"], ["84182.90", "0"], ["84189.10", "4.808936"], ["84191.30", "0"], ["84197.50", "4.355263"], ["84199.70", "0"], ["84205.90", "4.173794"], ["84208.10", "0"], ["84214.30", "4.264528"], ["84216.50", "0"], ["84224.90", "0"], ["84340.46", "0.000143"], ["84340.72", "0.000066"], ["84341.00", "0.002997"], ["84341.01", "0.000008"], ["84342.11", "0.000051"], ["84342.63", "0.000009"], ["84342.70", "0.000423"], ["84343.02", "0.000338"], ["84343.07", "0.000014"], ["84343.70", "0.000075"], ["84343.97", "0.000188"], ["84344.77", "0.000361"]], "bids": [["83962.00", "0"], ["83959.45", "0"], ["83959.20", "0"], ["83959.04", "0"], ["83957.20", "0"], ["83955.20", "0"], ["83953.20", "0"], ["83951.20", "0"], ["83951.11", "0"], ["83951.10", "0"], ["83950.84", "0"], ["83949.67", "0"], ["83949.20", "0"], ["83948.60", "0.001006"], ["83948.40", "0"], ["83948.39", "0"], ["83947.58", "0"], ["83947.20", "0"], ["83946.60", "0.001000"], ["83945.20", "0"], ["83944.60", "0.001047"], ["83943.21", "0"], ["83943.20", "0"], ["83942.60", "0.001039"], ["83941.60", "0.007594"], ["83941.37", "0"], ["83941.20", "0"], ["83940.74", "0.006540"], ["83940.60", "0.001038"], ["83940.14", "0"], ["83939.63", "0"], ["83939.20", "0"], ["83939.10", "0"], ["83938.97", "0"], ["83938.60", "0.001007"], ["83938.00", "0"], ["83937.90", "0"], ["83937.85", "0"], ["83937.53", "0.083593"], ["83937.50", "0"], ["83937.48", "0"], ["83937.31", "0"], ["83937.10", "0"], ["83937.03", "0"], ["83936.60", "0.001025"], ["83936.50", "0"], ["83936.49", "0"], ["83936.43", "0"], ["83936.40", "0"], ["83936.39", "0"], ["83936.30", "0"], ["83935.99", "0"], ["83935.93", "0"], ["83935.88", "0.089626"], ["83935.80", "0.006188"], ["83935.70", "0"], ["83935.61", "0"], ["83935.60", "0"], ["83935.49", "0"], ["83935.45", "0.247414"], ["83935.30", "0"], ["83935.21", "0"], ["83935.00", "0"], ["83934.96", "0"], ["83934.80", "0"], ["83934.69", "0"], ["83934.65", "0"], ["83934.60", "0.001014"], ["83934.57", "0"], ["83934.52", "0"], ["83934.45", "0"], ["83934.40", "0"], ["83934.16", "0"], ["83934.10", "0"], ["83934.00", "0"], ["83933.96", "0"], ["83933.95", "0"], ["83933.76", "0.224931"], ["83933.70", "0"], ["83933.61", "0.018263"], ["83932.87", "0"], ["83932.85", "0"], ["83932.60", "0.001049"], ["83932.50", "0"], ["83932.27", "0"], ["83932.13", "0"], ["83932.11", "0"], ["83931.95", "0.017115"], ["83931.70", "0"], ["83931.60", "0"], ["83931.51", "0"], ["83931.26", "0.018539"], ["83931.20", "0"], ["83931.10", "0"], ["83931.00", "0.204856"], ["83930.80", "0"], ["83930.70", "0"], ["83930.60", "0.001040"], ["83930.57", "0"], ["83930.02", "0"], ["83930.00", "0"], ["83929.90", "0"], ["83929.73", "0"], ["83929.54", "0"], ["83929.52", "0"], ["83929.51", "0"], ["83929.49", "0"], ["83929.48", "0"], ["83929.46", "0"], ["83929.11", "0.259076"], ["83929.10", "0"], ["83929.08", "0"], ["83928.75", "0.051819"], ["83928.60", "0.001004"], ["83928.50", "0.001014"], ["83928.26", "0.008196"], ["83928.20", "0.002850"], ["83928.10", "0.001021"], ["83928.00", "0.012390"], ["83927.72", "0"], ["83927.70", "0"], ["83927.69", "0"], ["83927.63", "0"], ["83927.62", "0"], ["83927.60", "0"], ["83927.59", "0"], ["83927.53", "0"], ["83927.51", "0"], ["83927.00", "0.009000"], ["83926.95", "0"], ["83926.67", "0.017817"], ["83926.25", "0.055608"], ["83926.00", "0.420000"], ["83925.83", "0.015742"], ["83925.69", "0.016424"], ["83925.38", "0.021155"], ["83925.35", "0"], ["83925.03", "0"], ["83925.01", "0"], ["83924.92", "0.073148"], ["83924.89", "0"], ["83924.52", "0.008275"], ["83924.42", "0.007137"], ["83924.27", "0"], ["83924.21", "0.007343"], ["83924.20", "0.028860"], ["83923.94", "0.008069"], ["83923.80", "0.826560"], ["83923.67", "0.009005"], ["83923.66", "0.007951"], ["83923.01", "0"], ["83922.95", "0"], ["83922.90", "0.120210"], ["83922.83", "0.008285"], ["83922.80", "0.536970"], ["83922.39", "0"], ["83922.35", "0"], ["83922.34", "0"], ["83922.32", "0"], ["83922.31", "0"], ["83922.30", "0.160920"], ["83921.90", "0.017220"], ["83921.70", "0.058020"], ["83921.40", "0.070470"], ["83920.90", "0.010770"], ["83920.80", "0.621360"], ["83920.51", "0"], ["83920.46", "0"], ["83920.45", "0"], ["83920.42", "0.009562"], ["83920.41", "0.006973"], ["83920.39", "0.009800"], ["83920.37", "0.009321"], ["83920.23", "0.268701"], ["83920.00", "0.485160"], ["83919.70", "0.946830"], ["83919.60", "0.045000"], ["83919.50", "0.480000"], ["83919.12", "0.009257"], ["83919.11", "0.000878"], ["83919.03", "0.010058"], ["83918.93", "0.222938"], ["83918.90", "0.045000"], ["83918.80", "0.015090"], ["83918.53", "0.076204"], ["83918.50", "0.535650"], ["83918.00", "0.216520"], ["83916.80", "0.009000"], ["83916.29", "0.012454"], ["83915.80", "0.014280"], ["83913.32", "0.005179"], ["83913.27", "0.008551"], ["83912.14", "0.005058"], ["83912.00", "0.000281"], ["83910.78", "0.008773"], ["83910.49", "0.017475"], ["83908.10", "0"], ["83906.67", "0"], ["83904.22", "0"], ["83903.76", "0"], ["83901.49", "0"], ["83900.65", "0.003601"], ["83899.12", "0"], ["83898.93", "0"], ["83897.20", "0"], ["83888.80", "0"], ["83886.60", "3.901590"], ["83885.36", "0"], ["83883.63", "0"], ["83880.51", "0"], ["83880.40", "0"], ["83879.20", "0"], ["83878.20", "4.536732"], ["83872.00", "0"], ["83869.80", "4.899671"], ["83863.60", "0"], ["83861.40", "5.262609"], ["83855.20", "0"], ["83854.41", "0.071678"], ["83853.76", "0.071668"], ["83853.00", "5.353344"], ["83846.80", "0"], ["83844.60", "3.992324"], ["83838.40", "0"], ["83836.20", "4.808936"], ["83830.27", "0.209200"], ["83830.00", "0"], ["83827.80", "4.718201"], ["83821.60", "0"], ["83819.40", "4.173794"], ["83813.20", "0"], ["83811.00", "4.355263"], ["83804.80", "0"], ["83802.60", "4.445998"], ["83796.40", "0"], ["83794.20", "5.081140"], ["83788.00", "0"], ["83785.80", "5.444079"], ["83784.00", "0"], ["83779.60", "0"], ["83777.40", "4.990405"], ["83771.20", "0"], ["83769.00", "5.171875"], ["83762.80", "0"], ["83760.60", "4.083059"], ["83754.40", "0"], ["83752.20", "5.534813"], ["83746.00", "0"], ["83743.80", "5.625548"], ["83737.60", "0"], ["83735.40", "4.264528"], ["83727.00", "4.627467"], ["83441.56", "0.000024"], ["83440.00", "0.000460"], ["83439.42", "0.000423"], ["83439.33", "0.000010"], ["83437.50", "0.000009"], ["83437.10", "0.000095"], ["83433.33", "0.000134"], ["83433.12", "0.000544"], ["83433.00", "0.000075"], ["83432.57", "0.000155"], ["83431.37", "0.000008"], ["83430.00", "0.002012"], ["83429.00", "0.000008"], ["83428.57", "0.000212"], ["83427.23", "0.000099"], ["83425.93", "0.000011"], ["83425.00", "0.006969"], ["83423.73", "0.001213"], ["83423.42", "0.000061"], ["83421.99", "0.000188"], ["83421.05", "0.000260"], ["83420.00", "0.018057"], ["83419.12", "0.000041"], ["83417.42", "0.000176"], ["83417.32", "0.000018"], ["83417.31", "0.000314"], ["83416.00", "0.000022"], ["83415.96", "0.000146"], ["83415.38", "0.000015"], ["83415.25", "0.000013"], ["83414.20", "0.003950"], ["83413.40", "0.000013"], ["83412.50", "0.000076"], ["83411.76", "0.000071"], ["83411.75", "0.000008"], ["83410.00", "0.000118"], ["83409.09", "0.000012"], ["83408.03", "0.000008"], ["83406.45", "0.000008"], ["83405.41", "0.000009"], ["83404.28", "0.000143"], ["83404.11", "0.000008"], ["83403.61", "0.000008"], ["83403.51", "0.000033"], ["83403.36", "0.041940"]], "checksum": -754670975, "ts": "1742577060641"}], "ts": 1742577060669, "record_time": 1742577060.867543, "EXCHANGE": "BITGET"}
{"action": "update", "arg": {"instType": "SPOT", "channel": "books", "instId": "BTCUSDT"}, "data": [{"asks": [["83948.21", "0.995674"], ["83948.33", "0.123194"], ["83948.60", "0.062779"], ["83948.61", "0.380582"], ["83955.26", "0.270420"], ["83959.45", "0.175493"], ["83959.46", "0.819738"], ["83960.06", "0"], ["83962.00", "0"], ["83962.01", "0.320427"], ["83963.25", "0.002383"], ["83964.48", "0"], ["83966.33", "0.035971"], ["83968.12", "0.119905"], ["83969.53", "0.035972"], ["83970.00", "0"], ["83970.30", "0.006357"], ["83971.03", "0.006356"], ["83971.49", "0.006357"], ["83972.24", "0"], ["83972.36", "0.006357"], ["83972.50", "0.006357"], ["83973.08", "0.119901"], ["83974.31", "0.016429"], ["83974.50", "0.006357"], ["83974.66", "0.010993"], ["83975.62", "0.009990"], ["83975.99", "0.006357"], ["83976.18", "0"], ["83976.51", "0.073834"], ["83977.14", "0"], ["83977.78", "0.119905"], ["83978.45", "0"], ["83978.62", "0.009989"], ["83980.10", "0"], ["83980.14", "0"], ["83981.19", "0"], ["83981.98", "0.015896"], ["83982.39", "0"], ["83983.32", "0"], ["83983.94", "0.325410"], ["83984.97", "0"], ["83986.67", "0"], ["83987.51", "0"], ["83988.49", "0"], ["83989.56", "0"], ["83992.30", "0.001434"], ["83992.70", "0"], ["83993.77", "0"], ["83994.30", "0.002339"], ["83994.70", "0"], ["83994.84", "0"], ["83996.30", "0.006310"], ["83996.70", "0"], ["83998.30", "0.016606"], ["83998.70", "0"], ["84000.30", "0.043701"], ["84000.70", "0"], ["84002.30", "0.115003"], ["84002.70", "0"], ["84004.30", "0.302639"], ["84004.70", "0"], ["84006.30", "0.796419"], ["84006.70", "0"], ["84008.30", "2.095839"], ["84008.70", "0"], ["84010.30", "5.515366"], ["84010.57", "0"], ["84010.70", "0"], ["84012.30", "14.514119"], ["84012.32", "0.019632"], ["84012.60", "9.198510"], ["84012.70", "2.988180"], ["84012.90", "0.006060"], ["84013.80", "1.026120"], ["84014.00", "1.722960"], ["84014.10", "1.079220"], ["84014.40", "1.350000"], ["84014.90", "0"], ["84016.00", "0.042300"], ["84016.10", "0.069510"], ["84016.90", "0.022650"], ["84017.80", "0.347760"], ["84018.00", "0.042300"], ["84018.50", "1.072110"], ["84018.80", "0.432000"], ["84019.00", "1.079040"], ["84019.80", "0"], ["84020.30", "0.017850"], ["84020.50", "0.291660"], ["84021.10", "0.178680"], ["84022.00", "2.153670"], ["84022.10", "0.180000"], ["84022.90", "0.144000"], ["84023.20", "1.360890"], ["84023.30", "0.547920"], ["84023.90", "0.908610"], ["84024.20", "2.680320"], ["84024.30", "0"], ["84026.19", "0"], ["84032.46", "0.000179"], ["84044.01", "0"], ["84054.30", "3.992343"], ["84054.70", "0"], ["84062.70", "4.627488"], ["84063.10", "0"], ["84071.10", "4.899694"], ["84071.49", "1.131944"], ["84071.50", "0"], ["84079.50", "5.444104"], ["84079.90", "0"], ["84087.90", "5.081164"], ["84088.30", "0"], ["84096.30", "5.353369"], ["84096.70", "0"], ["84104.70", "5.171899"], ["84105.10", "0"], ["84113.10", "3.901608"], ["84113.50", "0"], ["84121.50", "4.173813"], ["84121.90", "0.000124"], ["84129.90", "4.446018"], ["84130.30", "0"], ["84138.30", "4.355283"], ["84138.70", "0"], ["84146.70", "4.990429"], ["84147.10", "0"], ["84155.10", "4.536753"], ["84155.50", "0"], ["84155.79", "0.164585"], ["84163.50", "4.718223"], ["84163.90", "0"], ["84171.90", "5.625574"], ["84172.30", "0"], ["84180.30", "4.264548"], ["84180.70", "0"], ["84188.70", "4.083078"], ["84189.10", "0"], ["84197.10", "4.808958"], ["84197.50", "0"], ["84205.50", "5.262634"], ["84205.90", "0"], ["84213.90", "5.534839"], ["84214.30", "0"], ["84217.89", "0"], ["84340.72", "0"], ["84341.00", "0"], ["84341.01", "0"], ["84342.11", "0"], ["84342.63", "0"], ["84342.70", "0"], ["84343.02", "0"], ["84343.07", "0"], ["84343.70", "0"], ["84343.97", "0"], ["84344.77", "0"]], "bids": [["83948.60", "0"], ["83948.20", "0.001042"], ["83946.60", "0"], ["83946.20", "0.001012"], ["83944.60", "0"], ["83944.20", "0.001032"], ["83942.60", "0"], ["83942.20", "0.001028"], ["83940.60", "0"], ["83940.20", "0.001050"], ["83939.21", "0"], ["83938.66", "0"], ["83938.60", "0"], ["83938.20", "0.001701"], ["83937.53", "0"], ["83936.81", "0.114055"], ["83936.60", "0"], ["83936.44", "0.185586"], ["83936.20", "0.004476"], ["83935.88", "0"], ["83935.45", "0"], ["83934.60", "0"], ["83934.20", "0.011780"], ["83933.76", "0"], ["83933.61", "0"], ["83933.11", "0.314430"], ["83932.60", "0"], ["83932.20", "0.031000"], ["83931.95", "0"], ["83931.26", "0"], ["83931.01", "0.218099"], ["83930.60", "0"], ["83930.20", "0.081579"], ["83929.11", "0"], ["83929.10", "0.013838"], ["83928.75", "0"], ["83928.60", "0"], ["83928.50", "0"], ["83928.26", "0"], ["83928.20", "0.214681"], ["83928.10", "0.002280"], ["83928.00", "0.001023"], ["83927.70", "0.001031"], ["83927.10", "0.001031"], ["83927.00", "0.009780"], ["83926.99", "0.247437"], ["83926.73", "0.004035"], ["83926.03", "0.089635"], ["83926.00", "0"], ["83925.99", "0.005946"], ["83925.88", "0.083601"], ["83925.47", "0.018265"], ["83925.38", "0"], ["83924.98", "0.006568"], ["83924.92", "0"], ["83924.53", "0.013901"], ["83924.50", "0.073800"], ["83923.80", "0"], ["83923.78", "0.017106"], ["83923.10", "0.025185"], ["83922.96", "0.017367"], ["83922.90", "0"], ["83922.84", "0.017116"], ["83922.80", "0"], ["83922.30", "0"], ["83921.90", "0"], ["83921.88", "0.224952"], ["83921.70", "0.058410"], ["83921.42", "0.012668"], ["83921.40", "0.070680"], ["83920.90", "0"], ["83920.82", "0.008197"], ["83920.80", "0"], ["83920.60", "0.010710"], ["83920.10", "0.051824"], ["83920.00", "0"], ["83919.70", "0"], ["83919.60", "0.066600"], ["83919.50", "0"], ["83919.38", "0.018541"], ["83919.36", "0.007823"], ["83919.35", "0.007384"], ["83919.25", "0.008258"], ["83918.91", "0.018590"], ["83918.90", "0"], ["83918.80", "0"], ["83918.70", "0.060000"], ["83918.60", "0.120000"], ["83918.50", "0"], ["83918.00", "0.240000"], ["83917.94", "0.008601"], ["83917.90", "0.120000"], ["83917.88", "0.006312"], ["83917.81", "0.008525"], ["83917.40", "0.005599"], ["83917.34", "0.021157"], ["83917.10", "0.120000"], ["83916.88", "0.259101"], ["83915.80", "0"], ["83915.50", "0.491970"], ["83914.00", "0.009000"], ["83913.50", "0.015000"], ["83913.43", "0.056435"], ["83913.28", "0.008104"], ["83912.69", "0.073155"], ["83912.17", "0.008312"], ["83912.14", "0.010183"], ["83911.96", "0.005608"], ["83911.78", "0.004859"], ["83910.50", "0.008929"], ["83896.11", "0.007444"], ["83889.40", "0.007258"], ["83889.24", "0.007661"], ["83886.60", "0"], ["83886.20", "4.990429"], ["83878.20", "0"], ["83877.80", "5.444104"], ["83869.80", "0"], ["83869.40", "4.718223"], ["83863.60", "0.000172"], ["83861.40", "0"], ["83861.00", "4.264548"], ["83853.00", "0"], ["83852.60", "5.171899"], ["83844.60", "0"], ["83844.20", "4.083078"], ["83836.20", "0"], ["83835.80", "3.901608"], ["83827.80", "0"], ["83827.40", "5.262634"], ["83819.40", "0"], ["83819.00", "3.992343"], ["83811.00", "0"], ["83810.60", "4.536753"], ["83802.60", "0"], ["83802.20", "4.446018"], ["83794.20", "0"], ["83793.80", "5.534839"], ["83785.80", "0"], ["83785.40", "4.899694"], ["83777.40", "0"], ["83777.00", "5.625574"], ["83769.00", "0"], ["83768.60", "4.627488"], ["83760.60", "0"], ["83760.20", "5.353369"], ["83752.20", "0"], ["83751.80", "5.081164"], ["83743.80", "0"], ["83743.40", "4.173813"], ["83735.40", "0"], ["83735.00", "4.808958"], ["83727.00", "0"], ["83726.60", "4.355283"], ["83417.32", "0"], ["83417.31", "0"], ["83416.00", "0"], ["83415.96", "0"], ["83415.38", "0"], ["83415.25", "0"], ["83414.20", "0"], ["83413.40", "0"], ["83412.50", "0"], ["83411.76", "0"], ["83411.75", "0"], ["83410.00", "0"], ["83409.09", "0"], ["83408.03", "0"], ["83406.45", "0"], ["83405.41", "0"], ["83404.28", "0"], ["83404.11", "0"], ["83403.61", "0"], ["83403.51", "0"], ["83403.36", "0"]], "checksum": 1405809973, "ts": "1742577060852"}], "ts": 1742577060854, "record_time": 1742577061.048465, "EXCHANGE": "BITGET"}
{"action": "update", "arg": {"instType": "SPOT", "channel": "books", "instId": "BTCUSDT"}, "data": [{"asks": [["83948.21", "1.109729"], ["83948.32", "0.014519"], ["83948.60", "0.106327"], ["83948.61", "0.244700"], ["83955.25", "0.081126"], ["83955.26", "0"], ["83959.45", "0.345394"], ["83959.46", "0.559001"], ["83961.26", "0.002382"], ["83962.01", "0.320327"], ["83962.02", "0"], ["83962.03", "0"], ["83962.04", "0"], ["83963.25", "0"], ["83964.47", "0"], ["83966.32", "0.010791"], ["83968.15", "0.010995"], ["83971.35", "0.013838"], ["83971.97", "0.209200"], ["83973.93", "0"], ["83976.08", "0.010000"], ["83983.93", "0"], ["83983.94", "0.010988"], ["83988.30", "0.001226"], ["83990.30", "0.002000"], ["83992.30", "0.005264"], ["83993.84", "0"], ["83994.30", "0.013851"], ["83996.30", "0.036450"], ["83998.30", "0.095922"], ["84000.30", "0.252427"], ["84002.30", "0.664281"], ["84004.30", "1.748109"], ["84006.30", "4.600285"], ["84008.30", "12.106015"], ["84008.50", "0.001025"], ["84008.60", "0.001038"], ["84009.30", "0.538620"], ["84010.00", "0.042900"], ["84010.30", "0"], ["84012.00", "0.042900"], ["84012.10", "0.069960"], ["84012.20", "1.230390"], ["84012.30", "18.852000"], ["84012.60", "0"], ["84012.70", "1.438410"], ["84013.80", "1.588020"], ["84014.00", "1.722600"], ["84014.10", "1.079040"], ["84016.10", "0"], ["84017.80", "0.891690"], ["84018.50", "0.000976"], ["84018.80", "0.624000"], ["84020.70", "0.009000"], ["84020.90", "0.192000"], ["84022.60", "0.406620"], ["84022.70", "0.216000"], ["84023.20", "1.350000"], ["84023.30", "0"], ["84023.70", "0"], ["84023.90", "0"], ["84024.00", "0"], ["84024.20", "0"], ["84050.30", "4.809188"], ["84054.30", "0"], ["84058.70", "3.992533"], ["84062.70", "0"], ["84067.10", "4.174012"], ["84071.10", "0"], ["84071.49", "0"], ["84075.50", "5.625842"], ["84079.50", "0"], ["84083.90", "4.627709"], ["84087.90", "0"], ["84092.30", "5.081406"], ["84096.30", "0"], ["84100.70", "4.083273"], ["84104.70", "0"], ["84109.10", "5.262884"], ["84113.10", "0"], ["84117.50", "5.535103"], ["84121.50", "0"], ["84125.90", "4.899927"], ["84129.90", "0"], ["84134.30", "5.444363"], ["84138.30", "0"], ["84142.70", "4.446230"], ["84146.70", "0"], ["84151.10", "4.990666"], ["84155.10", "0"], ["84159.50", "4.718448"], ["84163.50", "0"], ["84167.90", "4.355491"], ["84171.90", "0"], ["84176.30", "4.264751"], ["84180.30", "0"], ["84184.70", "5.172145"], ["84188.70", "0"], ["84193.10", "4.536969"], ["84197.10", "0"], ["84201.50", "5.353624"], ["84205.50", "0"], ["84209.90", "3.901794"], ["84213.90", "0"], ["84340.46", "0"]], "bids": [["83948.20", "0.270420"], ["83946.20", "0"], ["83941.60", "0"], ["83940.74", "0"], ["83938.20", "0.001013"], ["83936.81", "0"], ["83936.44", "0.101062"], ["83936.20", "0.001311"], ["83936.12", "0.007594"], ["83935.88", "0.009899"], ["83935.27", "0.006540"], ["83934.20", "0.003450"], ["83932.20", "0.009081"], ["83932.10", "0"], ["83931.01", "0.152842"], ["83930.20", "0.023895"], ["83928.21", "0.268205"], ["83928.20", "0.062884"], ["83928.10", "0"], ["83928.00", "0"], ["83927.70", "0"], ["83927.10", "0"], ["83927.00", "0"], ["83926.25", "0"], ["83926.20", "0.165483"], ["83924.52", "0"], ["83924.50", "0"], ["83924.20", "0.435482"], ["83923.94", "0"], ["83922.70", "0.099450"], ["83922.30", "2.364180"], ["83921.89", "0.207614"], ["83921.70", "0.001008"], ["83921.40", "0.001028"], ["83921.30", "0.417210"], ["83920.47", "0.055617"], ["83920.42", "0"], ["83920.41", "0"], ["83920.40", "0.073140"], ["83920.39", "0"], ["83920.37", "0"], ["83919.36", "0"], ["83919.35", "0"], ["83919.25", "0"], ["83919.12", "0"], ["83919.11", "0"], ["83919.03", "0"], ["83918.47", "0.008069"], ["83918.10", "0.066390"], ["83917.94", "0"], ["83917.90", "0"], ["83917.88", "0"], ["83917.81", "0"], ["83917.52", "0.009418"], ["83917.40", "0"], ["83917.10", "0"], ["83915.50", "0.329790"], ["83915.03", "0.007823"], ["83914.99", "0.007384"], ["83914.96", "0.007775"], ["83914.95", "0.009562"], ["83914.93", "0.006973"], ["83914.92", "0.018058"], ["83914.90", "0.009321"], ["83913.70", "0.005942"], ["83913.68", "0.009257"], ["83913.67", "0.008024"], ["83913.66", "0.007199"], ["83913.62", "0.008478"], ["83913.61", "0.008601"], ["83913.59", "0.016653"], ["83913.58", "0.006312"], ["83913.48", "0.008525"], ["83913.40", "0.005599"], ["83913.32", "0"], ["83913.28", "0"], ["83913.27", "0"], ["83913.20", "0.030000"], ["83912.90", "0.497490"], ["83912.80", "0.015000"], ["83912.50", "0.030000"], ["83912.40", "0.120000"], ["83912.17", "0"], ["83912.14", "0"], ["83912.10", "0.360000"], ["83911.96", "0"], ["83911.78", "0"], ["83910.78", "0"], ["83910.50", "0"], ["83907.85", "0.005179"], ["83907.83", "0.008312"], ["83907.81", "0.005125"], ["83907.80", "0.016655"], ["83907.78", "0.009917"], ["83907.70", "0.005608"], ["83907.36", "0.000878"], ["83906.51", "0.008929"], ["83906.45", "0.008773"], ["83896.11", "0"], ["83892.13", "0.007444"], ["83889.40", "0"], ["83889.24", "0"], ["83889.22", "0.008582"], ["83886.20", "0"], ["83885.10", "0.007258"], ["83885.01", "0.007661"], ["83884.95", "0.007346"], ["83882.20", "4.446230"], ["83877.80", "0"], ["83873.80", "4.174012"], ["83869.40", "0"], ["83865.40", "4.355491"], ["83861.00", "0"], ["83857.00", "4.083273"], ["83852.60", "0"], ["83848.60", "5.172145"], ["83844.20", "0"], ["83840.20", "4.809188"], ["83835.80", "0"], ["83831.80", "5.625842"], ["83827.40", "0"], ["83823.40", "3.901794"], ["83819.00", "0"], ["83815.00", "4.899927"], ["83810.60", "0"], ["83806.60", "3.992533"], ["83802.20", "0"], ["83798.20", "4.536969"], ["83793.80", "0"], ["83789.80", "5.262884"], ["83785.40", "0"], ["83781.40", "4.990666"], ["83777.00", "0"], ["83773.00", "4.264751"], ["83768.60", "0"], ["83764.60", "4.627709"], ["83760.20", "0"], ["83756.20", "4.718448"], ["83751.80", "0"], ["83747.80", "5.444363"], ["83743.40", "0"], ["83739.40", "5.535103"], ["83735.00", "0"], ["83731.00", "5.353624"], ["83726.60", "0"], ["83722.60", "5.081406"], ["83425.93", "0"], ["83425.00", "0"], ["83423.73", "0"], ["83423.42", "0"], ["83421.99", "0"], ["83421.05", "0"], ["83420.00", "0"], ["83419.12", "0"], ["83417.42", "0"]], "checksum": 1274898684, "ts": "1742577061057"}], "ts": 1742577061062, "record_time": 1742577061.256129, "EXCHANGE": "BITGET"}
{"action": "update", "arg": {"instType": "SPOT", "channel": "books", "instId": "BTCUSDT"}, "data": [{"asks": [["83948.21", "1.484839"], ["83948.32", "0.124887"], ["83948.60", "0"], ["83955.25", "0"], ["83959.45", "0.047600"], ["83959.46", "0.467456"], ["83962.73", "3.186492"], ["83966.53", "0.314430"], ["83968.11", "0.048670"], ["83981.15", "0.177530"], ["83988.30", "0.001491"], ["83990.29", "3.717574"], ["83990.30", "0.002434"], ["83991.07", "0"], ["83992.30", "0.006403"], ["83993.83", "0"], ["83994.30", "0.016850"], ["83995.67", "0.714322"], ["83996.30", "0.044342"], ["83998.30", "0.116691"], ["84000.06", "0"], ["84000.30", "0.307081"], ["84002.30", "0.808108"], ["84004.30", "2.126600"], ["84006.30", "5.596315"], ["84008.30", "14.726941"], ["84009.30", "0.538410"], ["84010.00", "0.078630"], ["84010.20", "0.022800"], ["84012.00", "0.042690"], ["84012.20", "2.260530"], ["84012.30", "6.775590"], ["84012.70", "0"], ["84013.80", "1.587840"], ["84014.00", "1.722420"], ["84014.10", "0"], ["84014.30", "2.359050"], ["84016.70", "0.276000"], ["84016.90", "0"], ["84017.50", "0.204000"], ["84019.68", "0.892444"], ["84022.00", "2.825370"], ["84022.10", "0.207660"], ["84022.60", "0.156000"], ["84022.70", "0"], ["84022.90", "0"], ["84023.20", "0"], ["84050.30", "4.446230"], ["84058.70", "4.809188"], ["84059.90", "0"], ["84067.10", "5.444363"], ["84068.30", "0"], ["84075.50", "4.264751"], ["84083.90", "4.536969"], ["84100.70", "4.718448"], ["84109.10", "3.992533"], ["84117.50", "5.172145"], ["84125.90", "4.174012"], ["84134.30", "3.901794"], ["84142.70", "5.535103"], ["84151.10", "4.899927"], ["84159.50", "4.355491"], ["84167.90", "4.627709"], ["84176.30", "4.083273"], ["84184.70", "5.262884"], ["84193.10", "5.625842"], ["84201.50", "4.990666"], ["84209.90", "5.353624"], ["84340.46", "0.000143"], ["84340.72", "0.000066"]], "bids": [["83944.35", "0.038753"], ["83936.20", "0.002797"], ["83934.20", "0.007362"], ["83933.41", "0.114054"], ["83932.20", "0.019373"], ["83930.20", "0.050983"], ["83928.20", "0.134166"], ["83926.20", "0.353068"], ["83925.44", "0.764438"], ["83924.20", "0.929126"], ["83924.00", "2.362560"], ["83923.50", "0.001030"], ["83922.70", "0.099240"], ["83922.40", "0.515190"], ["83922.30", "0"], ["83921.89", "0"], ["83921.70", "0"], ["83921.40", "0"], ["83921.30", "0"], ["83920.40", "0.073350"], ["83920.19", "0.008275"], ["83919.90", "0.070920"], ["83919.60", "0"], ["83918.94", "0.392713"], ["83918.10", "0.156510"], ["83917.00", "0.066390"], ["83916.80", "0.169920"], ["83915.80", "0.026640"], ["83914.63", "0.715012"], ["83912.40", "0"], ["83912.10", "0"], ["83909.00", "0"], ["83906.53", "0.010357"], ["83882.20", "4.174012"], ["83874.87", "0"], ["83873.80", "4.809188"], ["83866.48", "0"], ["83857.00", "4.446230"], ["83848.60", "5.081406"], ["83840.20", "4.899927"], ["83823.40", "5.262884"], ["83815.00", "4.990666"], ["83806.60", "5.172145"], ["83798.20", "5.535103"], ["83789.80", "4.627709"], ["83781.40", "4.264751"], ["83773.00", "3.901794"], ["83764.60", "4.536969"], ["83756.20", "3.992533"], ["83747.80", "4.083273"], ["83739.40", "4.718448"], ["83722.60", "5.444363"], ["83427.23", "0"]], "checksum": -1691942282, "ts": "1742577061257"}], "ts": 1742577061259, "record_time": 1742577061.454514, "EXCHANGE": "BITGET"}
{"action": "update", "arg": {"instType": "SPOT", "channel": "books", "instId": "BTCUSDT"}, "data": [{"asks": [["83948.21", "1.620721"], ["83959.45", "0.240304"], ["83962.72", "0.966739"], ["83966.32", "0"], ["83981.15", "0"], ["84010.00", "0.042900"], ["84010.20", "0"], ["84012.10", "0.070350"], ["84012.20", "2.717910"], ["84012.60", "0.022770"], ["84013.80", "1.588020"], ["84014.00", "1.722600"], ["84022.60", "0.406620"], ["84022.70", "0.216000"], ["84047.16", "0.001810"], ["84050.30", "5.444363"], ["84055.56", "0.003620"], ["84058.70", "4.083273"], ["84067.10", "4.990666"], ["84075.50", "5.625842"], ["84083.90", "4.627709"], ["84092.30", "5.172145"], ["84100.70", "3.992533"], ["84109.10", "5.353624"], ["84117.50", "4.355491"], ["84125.90", "5.081406"], ["84134.30", "5.262884"], ["84142.70", "3.901794"], ["84159.50", "4.536969"], ["84167.90", "4.264751"], ["84176.30", "5.535103"], ["84184.70", "4.446230"], ["84193.10", "4.174012"], ["84201.50", "4.809188"], ["84209.90", "4.718448"], ["84302.14", "1.585680"], ["84317.17", "0"], ["84340.46", "0"], ["84340.72", "0"]], "bids": [["83936.20", "0.001985"], ["83934.20", "0.005224"], ["83932.20", "0.013747"], ["83930.20", "0.036178"], ["83928.21", "0.499928"], ["83928.20", "0.095205"], ["83926.20", "0.250540"], ["83924.21", "1.344666"], ["83924.20", "0.659314"], ["83924.00", "2.363040"], ["83922.70", "0.099660"], ["83922.40", "0.514980"], ["83918.94", "0"], ["83915.80", "0"], ["83882.20", "3.992533"], ["83873.80", "5.353624"], ["83870.36", "0.001810"], ["83865.40", "4.809188"], ["83861.96", "0.003620"], ["83857.00", "3.901794"], ["83848.60", "4.264751"], ["83840.20", "5.262884"], ["83831.80", "4.083273"], ["83823.40", "4.627709"], ["83815.00", "4.536969"], ["83806.60", "4.174012"], ["83798.20", "4.899927"], ["83789.80", "5.625842"], ["83781.40", "4.718448"], ["83773.00", "4.355491"], ["83764.60", "5.535103"], ["83756.20", "4.990666"], ["83747.80", "4.446230"], ["83739.40", "5.081406"], ["83731.00", "5.172145"], ["83645.32", "0"], ["83630.40", "1.732319"]], "checksum": -319122429, "ts": "1742577061475"}], "ts": 1742577061477, "record_time": 1742577061.671108, "EXCHANGE": "BITGET"}
{"action": "update", "arg": {"instType": "SPOT", "channel": "books", "instId": "BTCUSDT"}, "data": [{"asks": [["83966.52", "0.146298"], ["83968.11", "0"], ["83978.77", "0.181003"], ["83990.30", "0.002583"], ["83992.30", "0.006797"], ["83994.30", "0.017888"], ["83996.30", "0.047074"], ["83998.30", "0.123877"], ["84000.30", "0.325993"], ["84002.30", "0.857875"], ["84004.30", "2.257465"], ["84006.30", "5.940696"], ["84008.30", "15.633412"], ["84010.00", "0.078990"], ["84012.10", "0.070140"], ["84012.30", "6.741780"], ["84012.50", "0.100170"], ["84014.00", "1.722420"], ["84015.00", "0.035700"], ["84020.90", "0.227700"], ["84022.60", "0.156000"], ["84022.70", "0"], ["84050.30", "4.446230"], ["84058.70", "5.444363"], ["84067.10", "4.264751"], ["84075.50", "5.262884"], ["84083.90", "3.992533"], ["84092.30", "5.625842"], ["84100.70", "5.353624"], ["84109.10", "4.718448"], ["84117.50", "4.809188"], ["84125.90", "4.083273"], ["84134.30", "4.899927"], ["84142.70", "4.355491"], ["84151.10", "4.174012"], ["84159.50", "5.172145"], ["84167.90", "5.081406"], ["84176.30", "3.901794"], ["84184.70", "5.535103"], ["84193.10", "4.990666"], ["84201.50", "4.627709"], ["84209.90", "4.536969"], ["84339.62", "0"], ["84340.00", "0"]], "bids": [["83944.35", "0"], ["83936.20", "0.002715"], ["83934.20", "0.007146"], ["83932.20", "0.018804"], ["83931.00", "0"], ["83930.20", "0.049484"], ["83928.20", "0.130220"], ["83926.20", "0.342685"], ["83924.20", "0.901802"], ["83924.00", "2.365590"], ["83892.40", "0.207210"], ["83882.20", "5.262884"], ["83873.80", "5.625842"], ["83865.40", "4.627709"], ["83857.00", "4.446230"], ["83848.60", "4.083273"], ["83840.20", "4.899927"], ["83831.80", "4.174012"], ["83823.40", "4.809188"], ["83815.00", "4.990666"], ["83806.60", "4.718448"], ["83798.20", "5.172145"], ["83789.80", "3.992533"], ["83781.40", "4.355491"], ["83773.00", "3.901794"], ["83764.60", "4.536969"], ["83756.20", "5.081406"], ["83747.80", "4.264751"], ["83739.40", "5.353624"], ["83731.00", "5.535103"], ["83427.23", "0.000099"]], "checksum": -901058416, "ts": "1742577061684"}], "ts": 1742577061687, "record_time": 1742577061.880745, "EXCHANGE": "BITGET"}
{"action": "update", "arg": {"instType": "SPOT", "channel": "books", "instId": "BTCUSDT"}, "data": [{"asks": [["83948.32", "0.072758"], ["84006.30", "5.940548"], ["84008.30", "15.633021"], ["84011.90", "0.073230"], ["84012.00", "0.042480"], ["84013.80", "1.587840"], ["84020.50", "0.171660"], ["84022.60", "0"], ["84050.30", "4.990666"], ["84058.70", "4.083273"], ["84067.10", "5.081406"], ["84075.50", "4.718448"], ["84083.90", "5.444363"], ["84092.30", "5.535103"], ["84100.70", "4.899927"], ["84109.10", "5.262884"], ["84117.50", "3.901794"], ["84125.90", "4.174012"], ["84134.30", "3.992533"], ["84151.10", "4.627709"], ["84159.50", "4.446230"], ["84167.90", "5.172145"], ["84176.30", "5.353624"], ["84184.70", "5.625842"], ["84193.10", "4.536969"], ["84201.50", "4.809188"], ["84209.90", "4.264751"]], "bids": [["83944.49", "0.038753"], ["83938.20", "0.001222"], ["83936.20", "0.003216"], ["83934.20", "0.008463"], ["83932.20", "0.022271"], ["83931.01", "0.081757"], ["83930.20", "0.058608"], ["83928.20", "0.154232"], ["83926.20", "0.405873"], ["83924.20", "1.068086"], ["83921.80", "0.204856"], ["83910.00", "0.002281"], ["83908.00", "0.000160"], ["83907.00", "0.000160"], ["83906.00", "0.000160"], ["83905.00", "0.000160"], ["83904.00", "0.000160"], ["83903.00", "0.000160"], ["83902.00", "0.000160"], ["83901.00", "0.000160"], ["83900.00", "0.000160"], ["83899.00", "0.000160"], ["83882.20", "5.081406"], ["83873.80", "4.264751"], ["83865.40", "3.901794"], ["83857.00", "5.353624"], ["83848.60", "4.990666"], ["83840.20", "3.992533"], ["83831.80", "5.535103"], ["83823.40", "4.083273"], ["83815.00", "4.809188"], ["83806.60", "5.262884"], ["83798.20", "4.627709"], ["83789.80", "5.444363"], ["83781.40", "5.172145"], ["83773.00", "4.536969"], ["83768.00", "0.001184"], ["83764.60", "4.446230"], ["83756.20", "5.625842"], ["83747.80", "4.899927"], ["83739.40", "4.174012"], ["83731.00", "4.718448"], ["83722.60", "4.355491"], ["83439.42", "0"], ["83439.33", "0"], ["83437.50", "0"], ["83437.10", "0"], ["83433.33", "0"], ["83433.12", "0"], ["83433.00", "0"], ["83432.57", "0"], ["83431.37", "0"], ["83430.00", "0"], ["83429.00", "0"], ["83428.57", "0"], ["83427.23", "0"]], "checksum": 1840178806, "ts": "1742577061890"}], "ts": 1742577061892, "record_time": 1742577062.085163, "EXCHANGE": "BITGET"}
{"action": "update", "arg": {"instType": "SPOT", "channel": "books", "instId": "BTCUSDT"}, "data": [{"asks": [["83948.21", "1.632521"], ["83948.32", "0.117607"], ["84011.90", "0"], ["84012.00", "0.042690"], ["84012.50", "0.100350"], ["84013.30", "0.439920"], ["84017.80", "0.665520"], ["84020.50", "0.486510"], ["84022.10", "0.180000"], ["84050.30", "5.172145"], ["84058.70", "4.718448"], ["84067.10", "4.899927"], ["84075.50", "4.174012"], ["84083.90", "5.262884"], ["84092.30", "4.627709"], ["84100.70", "5.081406"], ["84109.10", "3.901794"], ["84117.50", "5.535103"], ["84125.90", "4.446230"], ["84134.30", "4.264751"], ["84142.70", "4.536969"], ["84151.10", "4.083273"], ["84159.50", "4.809188"], ["84167.90", "3.992533"], ["84184.70", "4.990666"], ["84193.10", "4.355491"], ["84201.50", "5.444363"], ["84209.90", "5.625842"]], "bids": [["83938.20", "0.001042"], ["83936.20", "0.001030"], ["83934.20", "0.001681"], ["83932.20", "0.004424"], ["83930.20", "0.011755"], ["83928.20", "0.030936"], ["83926.20", "0.081409"], ["83924.20", "0.214384"], ["83924.00", "2.365410"], ["83922.70", "0.001001"], ["83922.40", "0"], ["83920.40", "0.073170"], ["83919.90", "0"], ["83918.94", "0.071085"], ["83918.70", "0.060210"], ["83918.60", "0.120210"], ["83918.40", "0.614340"], ["83916.80", "0.160920"], ["83916.60", "0.448980"], ["83882.20", "4.174012"], ["83873.80", "5.444363"], ["83865.40", "5.353624"], ["83857.00", "3.992533"], ["83848.60", "4.627709"], ["83840.20", "4.355491"], ["83831.80", "4.083273"], ["83823.40", "4.264751"], ["83806.60", "5.625842"], ["83798.20", "4.899927"], ["83789.80", "5.535103"], ["83781.40", "4.536969"], ["83773.00", "5.262884"], ["83764.60", "3.901794"], ["83756.20", "5.081406"], ["83747.80", "5.172145"], ["83739.40", "4.718448"], ["83731.00", "4.446230"], ["83722.60", "4.990666"], ["83440.00", "0"]], "checksum": 1286265196, "ts": "1742577062107"}], "ts": 1742577062111, "record_time": 1742577062.305184, "EXCHANGE": "BITGET"}
{"action": "update", "arg": {"instType": "SPOT", "channel": "books", "instId": "BTCUSDT"}, "data": [{"asks": [["83962.00", "0.000083"], ["83990.28", "0.447867"], ["83998.30", "0.123754"], ["84000.30", "0.325667"], ["84002.30", "0.857019"], ["84004.30", "2.255313"], ["84006.30", "5.935035"], ["84008.30", "15.618513"], ["84013.30", "0.440100"], ["84017.29", "0"], ["84050.30", "4.446230"], ["84058.70", "4.264751"], ["84067.10", "3.992533"], ["84075.50", "4.083273"], ["84083.90", "5.625842"], ["84092.30", "4.355491"], ["84100.70", "5.353624"], ["84109.10", "4.627709"], ["84117.50", "4.990666"], ["84125.90", "4.174012"], ["84134.30", "4.718448"], ["84142.70", "5.172145"], ["84151.10", "4.536969"], ["84167.90", "5.081406"], ["84176.30", "5.444363"], ["84184.70", "5.262884"], ["84193.10", "4.899927"], ["84201.50", "3.901794"], ["84209.90", "5.535103"], ["84339.50", "0"]], "bids": [["83944.60", "0.038753"], ["83944.49", "0"], ["83940.00", "0.002000"], ["83936.44", "0"], ["83924.00", "2.365590"], ["83920.40", "0.073350"], ["83919.50", "0.433170"], ["83918.60", "0.120000"], ["83882.20", "4.264751"], ["83873.80", "3.901794"], ["83865.40", "5.444363"], ["83857.00", "4.355491"], ["83848.60", "4.809188"], ["83840.20", "4.446230"], ["83831.80", "5.262884"], ["83823.40", "3.992533"], ["83815.00", "5.172145"], ["83806.60", "4.718448"], ["83798.20", "5.353624"], ["83789.80", "4.627709"], ["83781.40", "5.081406"], ["83773.00", "4.899927"], ["83764.60", "5.535103"], ["83756.20", "4.174012"], ["83747.80", "4.990666"], ["83739.40", "4.536969"], ["83731.00", "4.083273"], ["83722.60", "5.625842"]], "checksum": -1009555558, "ts": "1742577062308"}], "ts": 1742577062311, "record_time": 1742577062.504614, "EXCHANGE": "BITGET"}
{"action": "update", "arg": {"instType": "SPOT", "channel": "books", "instId": "BTCUSDT"}, "data": [{"asks": [["83998.66", "0.001598"], ["84000.59", "0.001598"], ["84002.30", "0.857138"], ["84004.30", "2.255624"], ["84006.30", "5.935855"], ["84008.30", "15.620671"], ["84011.90", "0.071670"], ["84012.00", "0.042480"], ["84012.40", "2.359080"], ["84012.50", "0.100170"], ["84013.30", "0.439920"], ["84013.54", "0"], ["84013.80", "1.028940"], ["84014.30", "0"], ["84015.47", "0"], ["84019.00", "1.257720"], ["84022.10", "0"], ["84050.30", "3.992533"], ["84058.70", "4.446230"], ["84067.10", "4.083273"], ["84075.50", "4.990666"], ["84092.30", "4.536969"], ["84100.70", "4.627709"], ["84109.10", "4.899927"], ["84117.50", "4.355491"], ["84125.90", "5.535103"], ["84134.30", "4.264751"], ["84142.70", "4.809188"], ["84151.10", "5.081406"], ["84159.50", "5.444363"], ["84167.90", "5.353624"], ["84176.30", "4.174012"], ["84193.10", "4.718448"], ["84209.90", "5.172145"]], "bids": [["83939.91", "0"], ["83933.42", "0.128545"], ["83926.20", "0.081289"], ["83924.20", "0.213919"], ["83924.00", "0.002220"], ["83922.80", "0.001006"], ["83922.30", "0.102570"], ["83920.40", "0.548130"], ["83919.80", "2.359320"], ["83919.50", "0"], ["83919.30", "0.069840"], ["83918.70", "0.060000"], ["83915.70", "0.026520"], ["83915.50", "0"], ["83913.50", "0"], ["83913.20", "0"], ["83912.90", "0"], ["83912.80", "0"], ["83912.50", "0"], ["83903.39", "0"], ["83901.46", "0"], ["83888.53", "0.001177"], ["83886.60", "0.001173"], ["83882.20", "5.262884"], ["83873.80", "4.083273"], ["83865.40", "4.809188"], ["83857.00", "4.627709"], ["83848.60", "3.901794"], ["83840.20", "5.081406"], ["83831.80", "5.625842"], ["83823.40", "5.172145"], ["83815.00", "3.992533"], ["83806.60", "5.535103"], ["83789.80", "4.446230"], ["83781.40", "4.899927"], ["83773.00", "4.264751"], ["83764.60", "4.174012"], ["83756.20", "4.355491"], ["83747.80", "4.718448"], ["83739.40", "5.444363"], ["83731.00", "4.990666"], ["83722.60", "4.536969"], ["83440.00", "0.000460"], ["83439.42", "0.000423"]], "checksum": 1046531965, "ts": "1742577062510"}], "ts": 1742577062512, "record_time": 1742577062.705674, "EXCHANGE": "BITGET"}
{"action": "update", "arg": {"instType": "SPOT", "channel": "books", "instId": "BTCUSDT"}, "data": [{"asks": [["83948.21", "1.606796"], ["83948.32", "0.014519"], ["83962.01", "0.253514"], ["83963.28", "0.119905"], ["83964.87", "0.006357"], ["83965.04", "0.006357"], ["83965.33", "0.006357"], ["83965.76", "0.006357"], ["83966.39", "0.006357"], ["83966.82", "0.006357"], ["83967.51", "0.006357"], ["83967.67", "0.006357"], ["83967.91", "0.006357"], ["83968.12", "0"], ["83968.39", "0.006357"], ["83968.61", "0.006357"], ["83969.58", "0.006357"], ["83969.94", "0.006357"], ["83971.16", "0"], ["83971.49", "0"], ["83972.01", "0"], ["83972.19", "0"], ["83972.50", "0"], ["83972.73", "0.119858"], ["83972.94", "0"], ["83973.65", "0"], ["83973.74", "0"], ["83974.19", "0"], ["83974.21", "0"], ["83974.50", "0"], ["83975.73", "0"], ["83975.99", "0"], ["83978.32", "0"], ["83979.04", "0"], ["83986.50", "0.000976"], ["83988.30", "0.001737"], ["83990.30", "0.002834"], ["83992.30", "0.007458"], ["83994.30", "0.019627"], ["83996.30", "0.051650"], ["83998.30", "0.135920"], ["84000.30", "0.357685"], ["84002.30", "0.941275"], ["84004.30", "2.477040"], ["84006.30", "6.518527"], ["84008.30", "17.154017"], ["84010.00", "0.123750"], ["84010.70", "0.071430"], ["84011.00", "0.323820"], ["84011.80", "0.269940"], ["84011.90", "0.071460"], ["84012.20", "2.032590"], ["84012.30", "6.651780"], ["84012.40", "0"], ["84013.50", "0.178620"], ["84014.30", "0.228000"], ["84014.40", "1.542000"], ["84017.70", "0.180000"], ["84018.20", "0.216000"], ["84018.50", "0"], ["84018.80", "0.396000"], ["84019.10", "0.180000"], ["84020.50", "0"], ["84020.70", "0"], ["84020.90", "0"], ["84021.10", "0"], ["84022.00", "0"], ["84050.30", "5.081406"], ["84058.70", "4.083273"], ["84067.10", "4.718448"], ["84075.50", "5.625842"], ["84083.90", "4.990666"], ["84092.30", "4.264751"], ["84100.70", "5.172145"], ["84109.10", "4.355491"], ["84117.50", "4.536969"], ["84125.90", "5.262884"], ["84134.30", "4.899927"], ["84151.10", "5.535103"], ["84159.50", "3.992533"], ["84167.90", "4.446230"], ["84184.70", "4.627709"], ["84193.10", "5.444363"], ["84201.50", "5.353624"], ["84209.90", "3.901794"], ["84339.29", "0"]], "bids": [["83948.20", "0"], ["83935.80", "0"], ["83933.42", "0"], ["83933.41", "0"], ["83926.99", "0"], ["83926.67", "0"], ["83925.99", "0"], ["83925.83", "0"], ["83925.69", "0"], ["83925.02", "0.006185"], ["83924.98", "0"], ["83924.42", "0"], ["83924.21", "0.466416"], ["83924.20", "0.213714"], ["83923.78", "0"], ["83923.67", "0"], ["83923.66", "0"], ["83922.96", "0"], ["83922.83", "0"], ["83922.80", "0"], ["83922.70", "0"], ["83922.30", "0.001470"], ["83922.15", "0.247454"], ["83921.80", "0"], ["83921.42", "0"], ["83920.40", "0.072960"], ["83920.23", "0"], ["83919.83", "0.017820"], ["83919.80", "0"], ["83919.55", "0.005947"], ["83919.31", "0.006569"], ["83919.30", "0"], ["83918.94", "0.739720"], ["83918.93", "0"], ["83918.83", "0.016427"], ["83918.70", "0"], ["83918.60", "0"], ["83918.00", "0.209321"], ["83917.98", "0.007344"], ["83917.87", "0.007138"], ["83917.86", "0.009007"], ["83917.81", "0.017108"], ["83917.37", "0.007953"], ["83917.07", "0.017370"], ["83916.80", "0"], ["83916.02", "0.008287"], ["83915.70", "0"], ["83915.38", "0.012670"], ["83914.80", "0.060000"], ["83914.70", "0.120000"], ["83913.92", "0.268745"], ["83913.90", "0.240000"], ["83913.60", "0.160920"], ["83912.90", "0.012330"], ["83912.63", "0.222975"], ["83912.40", "0.120000"], ["83909.00", "0.000160"], ["83898.00", "0.000160"], ["83892.40", "0"], ["83889.30", "0.207210"], ["83882.20", "4.899927"], ["83873.80", "5.353624"], ["83865.40", "5.081406"], ["83860.40", "0.000971"], ["83857.00", "3.901794"], ["83848.60", "4.536969"], ["83840.20", "4.174012"], ["83831.80", "5.172145"], ["83823.40", "5.625842"], ["83821.87", "0.209200"], ["83815.00", "5.444363"], ["83806.60", "4.083273"], ["83798.20", "4.446230"], ["83789.80", "4.718448"], ["83781.40", "3.992533"], ["83773.00", "4.990666"], ["83764.60", "5.535103"], ["83756.20", "4.627709"], ["83747.80", "4.809188"], ["83739.40", "4.264751"], ["83731.00", "4.355491"], ["83722.60", "5.262884"], ["83439.33", "0.000010"], ["83437.50", "0.000009"]], "checksum": 1924073895, "ts": "1742577062726"}], "ts": 1742577062728, "record_time": 1742577062.922457, "EXCHANGE": "BITGET"}
{"action": "update", "arg": {"instType": "SPOT", "channel": "books", "instId": "BTCUSDT"}, "data": [{"asks": [["83944.21", "0.800015"], ["83944.34", "0.136409"], ["83944.60", "0.664917"], ["83944.61", "0.262927"], ["83948.21", "0.420481"], ["83948.32", "0"], ["83948.33", "0"], ["83948.61", "0.209200"], ["83959.46", "0.258256"], ["83962.01", "0.253157"], ["83964.13", "0.035972"], ["83964.56", "0.017477"], ["83966.33", "0"], ["83967.15", "0.016429"], ["83967.69", "0.016429"], ["83969.53", "0"], ["83970.30", "0"], ["83971.03", "0"], ["83972.00", "0.119850"], ["83972.36", "0"], ["83972.89", "0.015895"], ["83973.08", "0"], ["83973.73", "0"], ["83974.31", "0"], ["83974.66", "0"], ["83975.05", "0.006356"], ["83975.62", "0"], ["83975.97", "0"], ["83976.08", "0"], ["83978.62", "0"], ["83979.48", "0"], ["83981.61", "0"], ["83983.94", "0"], ["83988.30", "0.001915"], ["83990.28", "0"], ["83990.30", "0.003125"], ["83992.30", "0.008224"], ["83994.30", "0.021642"], ["83995.67", "0"], ["83996.30", "0.056952"], ["83998.30", "0.149874"], ["84000.30", "0.394406"], ["84002.30", "1.037909"], ["84004.30", "2.731341"], ["84006.30", "7.187739"], ["84008.30", "18.915103"], ["84009.20", "0.072450"], ["84009.30", "0.538200"], ["84009.70", "0.071430"], ["84010.00", "0.078180"], ["84010.70", "0.071610"], ["84011.43", "0"], ["84011.50", "0.178800"], ["84011.80", "0.448560"], ["84012.10", "0.069960"], ["84012.20", "2.032410"], ["84012.30", "6.651420"], ["84013.10", "0.204000"], ["84013.30", "0.511350"], ["84013.79", "0.254263"], ["84014.00", "1.926420"], ["84015.70", "0.178620"], ["84016.30", "0.178620"], ["84016.50", "0.192000"], ["84017.40", "0.178620"], ["84017.80", "0"], ["84018.00", "0"], ["84018.20", "0"], ["84018.80", "0"], ["84019.00", "0"], ["84019.10", "0"], ["84020.00", "0"], ["84020.30", "0"], ["84050.30", "4.174012"], ["84067.10", "4.264751"], ["84075.50", "4.899927"], ["84083.90", "3.992533"], ["84092.30", "5.444363"], ["84100.70", "4.355491"], ["84109.10", "5.535103"], ["84117.50", "5.172145"], ["84125.90", "4.718448"], ["84134.30", "4.990666"], ["84142.70", "4.627709"], ["84151.10", "5.262884"], ["84159.50", "5.353624"], ["84167.90", "4.536969"], ["84176.30", "3.901794"], ["84184.70", "4.446230"], ["84193.10", "5.625842"], ["84201.50", "4.809188"], ["84209.90", "5.081406"], ["84339.29", "0.000029"], ["84339.50", "0.000323"], ["84339.62", "0.000051"], ["84340.00", "0.019520"], ["84340.46", "0.000143"], ["84340.72", "0.000066"], ["84341.00", "0.002997"], ["84341.01", "0.000008"], ["84342.11", "0.000051"]], "bids": [["83944.60", "0"], ["83935.88", "0"], ["83931.09", "0.010000"], ["83928.21", "0.268205"], ["83926.03", "0"], ["83925.88", "0"], ["83925.47", "0"], ["83924.21", "0"], ["83923.10", "0"], ["83922.84", "0"], ["83921.88", "0"], ["83920.82", "0"], ["83920.48", "0.083609"], ["83920.40", "0.073140"], ["83920.10", "0.015000"], ["83919.59", "0.015744"], ["83919.38", "0"], ["83918.53", "0"], ["83918.40", "0"], ["83918.30", "2.359380"], ["83917.63", "0.028865"], ["83917.52", "0"], ["83917.34", "0"], ["83916.49", "0.025190"], ["83916.29", "0"], ["83913.43", "0"], ["83912.90", "0"], ["83912.40", "0"], ["83911.95", "0.076218"], ["83911.70", "0.850830"], ["83910.49", "0"], ["83909.74", "0.012456"], ["83899.09", "0.017477"], ["83882.20", "5.262884"], ["83873.80", "4.899927"], ["83865.40", "4.627709"], ["83860.40", "0"], ["83858.90", "0.000971"], ["83857.00", "3.992533"], ["83848.60", "4.083273"], ["83840.20", "4.446230"], ["83831.80", "5.353624"], ["83823.40", "4.809188"], ["83806.60", "4.990666"], ["83798.20", "4.718448"], ["83789.80", "5.172145"], ["83781.40", "5.081406"], ["83773.00", "4.174012"], ["83768.00", "0"], ["83764.60", "4.536969"], ["83756.20", "4.264751"], ["83747.80", "5.625842"], ["83739.40", "3.901794"], ["83722.60", "5.535103"], ["83437.10", "0.000095"], ["83433.33", "0.000134"], ["83433.12", "0.000544"], ["83433.00", "0.000075"], ["83432.57", "0.000155"], ["83431.37", "0.000008"], ["83430.00", "0.002012"], ["83429.00", "0.000008"], ["83428.57", "0.000212"], ["83427.23", "0.000099"], ["83425.93", "0.000011"]], "checksum": -1024085687, "ts": "1742577062927"}], "ts": 1742577062931, "record_time": 1742577063.124348, "EXCHANGE": "BITGET"}
{"action": "update", "arg": {"instType": "SPOT", "channel": "books", "instId": "BTCUSDT"}, "data": [{"asks": [["83940.01", "0.244700"], ["83940.50", "0.529500"], ["83940.51", "0.509312"], ["83944.21", "0.832849"], ["83944.33", "0.013663"], ["83944.60", "0"], ["83944.61", "0.091902"], ["83948.20", "0.134208"], ["83948.21", "0"], ["83951.38", "0.002382"], ["83958.14", "0.119905"], ["83960.63", "0.035971"], ["83961.26", "0"], ["83961.45", "0.010995"], ["83962.01", "0.235292"], ["83962.73", "0"], ["83963.19", "0.006357"], ["83963.28", "0"], ["83964.64", "0.006356"], ["83965.94", "0.119901"], ["83966.63", "0.006357"], ["83967.48", "0.010993"], ["83967.79", "0.119905"], ["83968.15", "0"], ["83968.64", "0.009990"], ["83971.33", "0.009989"], ["83971.96", "0.144579"], ["83971.99", "0.015896"], ["83972.08", "0.010000"], ["83975.45", "0.010988"], ["83977.78", "0"], ["83981.20", "0.001552"], ["83981.98", "0"], ["83983.20", "0.002532"], ["83985.20", "0.006796"], ["83987.20", "0.017883"], ["83988.30", "0"], ["83988.51", "0.714383"], ["83989.20", "0.047060"], ["83990.29", "0"], ["83990.30", "0"], ["83991.20", "0.123843"], ["83992.30", "0"], ["83993.20", "0.325904"], ["83994.30", "0"], ["83995.20", "0.857640"], ["83996.30", "0"], ["83997.20", "2.256949"], ["83998.30", "0"], ["83999.20", "5.939340"], ["84000.30", "0"], ["84001.20", "15.629840"], ["84001.70", "0.001026"], ["84002.00", "0.044460"], ["84002.20", "0.270150"], ["84002.30", "0"], ["84002.80", "0.035730"], ["84004.00", "0.042480"], ["84004.10", "9.001500"], ["84004.30", "1.429680"], ["84004.50", "5.262180"], ["84004.70", "1.726650"], ["84004.80", "2.359290"], ["84005.40", "0.052770"], ["84006.00", "0.042300"], ["84006.20", "0.456660"], ["84006.30", "0"], ["84006.40", "0.167400"], ["84007.60", "1.186440"], ["84008.00", "0.042300"], ["84008.30", "4.056900"], ["84008.50", "0"], ["84008.60", "0"], ["84009.20", "0.071430"], ["84009.30", "1.366170"], ["84010.00", "0.042300"], ["84010.20", "0.069960"], ["84010.70", "0.071430"], ["84011.00", "0.323640"], ["84011.50", "0.178620"], ["84011.80", "0.178620"], ["84011.90", "0.071280"], ["84012.00", "0.042300"], ["84012.10", "0"], ["84012.20", "0"], ["84012.30", "0.276000"], ["84012.32", "0"], ["84012.50", "0"], ["84012.60", "0"], ["84012.90", "0"], ["84013.10", "0"], ["84013.30", "0"], ["84013.50", "0"], ["84013.70", "1.785423"], ["84013.79", "0"], ["84013.80", "0"], ["84014.00", "0"], ["84014.30", "0"], ["84014.40", "0"], ["84015.00", "0"], ["84015.70", "0"], ["84016.00", "0"], ["84016.30", "0"], ["84016.50", "0"], ["84016.70", "0"], ["84017.40", "0"], ["84017.50", "0"], ["84017.70", "0"], ["84033.08", "0"], ["84043.20", "4.265114"], ["84050.30", "0"], ["84051.60", "5.444827"], ["84058.70", "0"], ["84060.00", "4.809597"], ["84067.10", "0"], ["84068.40", "3.992873"], ["84075.50", "0"], ["84076.80", "5.626321"], ["84083.90", "0"], ["84085.20", "4.718850"], ["84092.30", "0"], ["84093.60", "4.900344"], ["84100.70", "0"], ["84102.00", "4.628103"], ["84109.10", "0"], ["84110.40", "3.902126"], ["84117.50", "0"], ["84118.80", "4.083620"], ["84125.90", "0"], ["84127.20", "4.991091"], ["84134.30", "0"], ["84135.60", "5.263333"], ["84142.70", "0"], ["84144.00", "5.354080"], ["84151.10", "0"], ["84152.40", "4.537356"], ["84159.50", "0"], ["84160.80", "4.355862"], ["84167.90", "0"], ["84169.20", "5.081838"], ["84176.30", "0"], ["84177.60", "5.172586"], ["84184.70", "0"], ["84186.00", "4.174367"], ["84193.10", "0"], ["84194.40", "5.535574"], ["84201.50", "0"], ["84202.80", "4.446609"], ["84209.90", "0"], ["84340.72", "0"], ["84341.00", "0"], ["84341.01", "0"], ["84342.11", "0"]], "bids": [["83944.20", "0"], ["83942.20", "0"], ["83940.20", "0"], ["83938.20", "0"], ["83937.10", "0.001038"], ["83936.20", "0"], ["83936.12", "0"], ["83935.27", "0"], ["83935.10", "0.001038"], ["83934.20", "0"], ["83933.10", "0.001014"], ["83932.20", "0"], ["83931.10", "0.001009"], ["83931.01", "0"], ["83930.20", "0"], ["83929.10", "0.001005"], ["83929.02", "0.007594"], ["83928.22", "0.006541"], ["83928.20", "0"], ["83928.15", "0.009902"], ["83927.10", "0.001849"], ["83926.73", "0"], ["83926.20", "0"], ["83925.10", "0.004866"], ["83924.53", "0"], ["83924.21", "0.207311"], ["83924.20", "0"], ["83924.00", "0"], ["83923.67", "0.013838"], ["83923.50", "0"], ["83923.10", "0.012806"], ["83922.30", "0"], ["83922.15", "0"], ["83921.10", "0.033699"], ["83920.60", "0"], ["83920.47", "0"], ["83920.40", "0"], ["83920.33", "0.089643"], ["83920.19", "0"], ["83920.10", "0"], ["83919.10", "0.088816"], ["83918.91", "0"], ["83918.47", "0"], ["83918.36", "0.018266"], ["83918.30", "0"], ["83918.10", "0"], ["83917.17", "0.004035"], ["83917.10", "0.233728"], ["83917.01", "0.247466"], ["83917.00", "0.000281"], ["83916.88", "0"], ["83916.70", "0.002370"], ["83916.60", "0.001048"], ["83916.50", "0.001028"], ["83916.46", "0.017118"], ["83916.00", "0.001008"], ["83915.30", "0.001009"], ["83915.09", "0.008198"], ["83915.03", "0"], ["83914.99", "0"], ["83914.96", "0"], ["83914.95", "0"], ["83914.93", "0"], ["83914.92", "0"], ["83914.90", "0"], ["83914.80", "2.359650"], ["83914.73", "0.224972"], ["83914.70", "0"], ["83914.64", "0.555353"], ["83913.90", "0"], ["83913.77", "0.055619"], ["83913.70", "0"], ["83913.68", "0"], ["83913.67", "0"], ["83913.66", "0"], ["83913.62", "0"], ["83913.61", "0"], ["83913.60", "0"], ["83913.59", "0"], ["83913.58", "0"], ["83913.48", "0"], ["83913.40", "0"], ["83913.12", "0.008276"], ["83912.92", "0.051829"], ["83912.90", "0.066570"], ["83912.69", "0"], ["83912.50", "0.072480"], ["83912.40", "0.018543"], ["83912.30", "0.420000"], ["83911.70", "0.536970"], ["83911.43", "0.008069"], ["83910.49", "0.018590"], ["83910.05", "0.021159"], ["83910.00", "0.066390"], ["83909.92", "0.009418"], ["83909.50", "0.463200"], ["83908.00", "0.035730"], ["83907.96", "0.007823"], ["83907.91", "0.007384"], ["83907.89", "0.007775"], ["83907.88", "0.009562"], ["83907.87", "0.006973"], ["83907.86", "0.018058"], ["83907.85", "0"], ["83907.84", "0.009321"], ["83907.83", "0"], ["83907.81", "0"], ["83907.80", "0"], ["83907.78", "0"], ["83907.70", "0"], ["83907.60", "0.240000"], ["83907.50", "0.120000"], ["83907.40", "1.135410"], ["83907.35", "0.259131"], ["83907.30", "0.485160"], ["83906.70", "0.009257"], ["83906.65", "0.007199"], ["83906.64", "0.008478"], ["83906.62", "0.006595"], ["83906.61", "0.016370"], ["83906.60", "0.008603"], ["83906.53", "0"], ["83906.51", "0"], ["83906.45", "0"], ["83906.43", "0.005599"], ["83906.00", "0.205920"], ["83905.90", "0.480000"], ["83904.94", "0.056446"], ["83903.16", "0.073163"], ["83900.78", "0.005179"], ["83900.77", "0.008312"], ["83900.74", "0.016655"], ["83900.73", "0.005125"], ["83900.71", "0.009917"], ["83900.64", "0.005609"], ["83899.53", "0.008929"], ["83899.52", "0.010357"], ["83899.47", "0.008773"], ["83892.13", "0"], ["83889.22", "0"], ["83885.10", "0"], ["83885.07", "0.007444"], ["83885.01", "0"], ["83884.95", "0"], ["83882.20", "0"], ["83882.16", "0.008582"], ["83878.13", "0.007258"], ["83878.04", "0.007661"], ["83877.98", "0.007346"], ["83875.10", "4.083620"], ["83874.86", "0"], ["83873.80", "0"], ["83866.70", "5.626321"], ["83865.40", "0"], ["83858.30", "5.444827"], ["83857.00", "0"], ["83849.90", "5.081838"], ["83848.60", "0"], ["83848.55", "0.057335"], ["83841.50", "4.537356"], ["83840.20", "0"], ["83833.10", "4.809597"], ["83831.80", "0"], ["83824.70", "4.265114"], ["83823.40", "0"], ["83816.30", "4.718850"], ["83815.00", "0"], ["83807.90", "3.992873"], ["83806.60", "0"], ["83799.50", "3.902126"], ["83798.20", "0"], ["83791.10", "4.446609"], ["83789.80", "0"], ["83782.70", "4.991091"], ["83781.40", "0"], ["83774.30", "4.355862"], ["83773.00", "0"], ["83765.90", "4.174367"], ["83764.60", "0"], ["83757.50", "5.354080"], ["83756.20", "0"], ["83749.10", "4.628103"], ["83747.80", "0"], ["83740.70", "5.263333"], ["83739.40", "0"], ["83732.30", "4.900344"], ["83731.00", "0"], ["83723.90", "5.535574"], ["83722.60", "0"], ["83715.50", "5.172586"], ["83433.12", "0"], ["83433.00", "0"], ["83432.57", "0"], ["83431.37", "0"], ["83430.00", "0"], ["83429.00", "0"], ["83428.57", "0"], ["83427.23", "0"], ["83425.93", "0"]], "checksum": 909777684, "ts": "1742577063131"}], "ts": 1742577063135, "record_time": 1742577063.330054, "EXCHANGE": "BITGET"}
{"action": "update", "arg": {"instType": "SPOT", "channel": "books", "instId": "BTCUSDT"}, "data": [{"asks": [["83940.01", "1.780580"], ["83940.49", "0.634091"], ["83940.50", "0"], ["83940.51", "0.035500"], ["83944.21", "0.312495"], ["83944.61", "0.000357"], ["83948.20", "0"], ["83948.60", "0.062760"], ["83962.72", "0"], ["83976.51", "0"], ["83981.20", "0.001680"], ["83983.20", "0.002741"], ["83985.20", "0.007321"], ["83987.20", "0.019267"], ["83989.20", "0.050701"], ["83991.20", "0.133423"], ["83993.20", "0.351115"], ["83995.20", "0.923986"], ["83997.20", "2.431542"], ["83999.20", "6.398795"], ["84001.20", "16.838933"], ["84002.20", "0.001034"], ["84004.10", "5.943690"], ["84004.50", "2.667720"], ["84004.80", "0"], ["84004.90", "0.069960"], ["84007.10", "2.359230"], ["84008.30", "2.787720"], ["84010.00", "0.462300"], ["84010.20", "0"], ["84030.99", "0"], ["84043.20", "4.991091"], ["84051.60", "4.446609"], ["84060.00", "5.535574"], ["84068.40", "4.355862"], ["84076.80", "3.992873"], ["84085.20", "4.265114"], ["84102.00", "4.083620"], ["84110.40", "5.172586"], ["84118.80", "5.081838"], ["84127.20", "5.626321"], ["84135.60", "4.537356"], ["84144.00", "5.263333"], ["84152.40", "4.174367"], ["84160.80", "4.809597"], ["84169.20", "5.354080"], ["84177.60", "3.902126"], ["84186.00", "5.444827"], ["84194.40", "4.718850"], ["84202.80", "4.628103"], ["84209.49", "0"], ["84340.72", "0.000066"], ["84341.00", "0.002997"], ["84341.01", "0.000008"], ["84342.11", "0.000051"]], "bids": [["83940.00", "0.159898"], ["83937.69", "0.038760"], ["83929.12", "0.114052"], ["83928.21", "0"], ["83927.10", "0.001858"], ["83925.45", "0.232647"], ["83925.10", "0.004889"], ["83924.21", "0.070700"], ["83923.67", "0"], ["83923.10", "0.012866"], ["83921.10", "0.033858"], ["83919.10", "0.089099"], ["83918.94", "0.071085"], ["83917.10", "0.234472"], ["83917.00", "2.363730"], ["83916.70", "0.001011"], ["83916.03", "0.014016"], ["83916.00", "0.000281"], ["83915.30", "0"], ["83914.80", "0"], ["83914.70", "0.528870"], ["83913.90", "0.463800"], ["83913.70", "0.099120"], ["83913.30", "0.072990"], ["83912.90", "0.149280"], ["83912.50", "0"], ["83911.70", "0"], ["83907.60", "0"], ["83907.50", "0"], ["83907.30", "0"], ["83906.75", "0.005942"], ["83906.73", "0.008026"], ["83906.54", "0.008525"], ["83866.70", "4.991091"], ["83853.76", "0"], ["83849.90", "4.537356"], ["83841.50", "5.626321"], ["83833.10", "3.992873"], ["83824.70", "4.628103"], ["83816.30", "4.355862"], ["83807.90", "5.081838"], ["83799.50", "5.263333"], ["83791.10", "4.265114"], ["83782.70", "5.535574"], ["83774.30", "4.174367"], ["83765.90", "5.172586"], ["83757.50", "3.902126"], ["83749.10", "4.809597"], ["83740.70", "5.354080"], ["83732.30", "4.446609"], ["83723.90", "4.900344"], ["83715.50", "4.718850"], ["83433.33", "0"]], "checksum": 1466359751, "ts": "1742577063333"}], "ts": 1742577063336, "record_time": 1742577063.530192, "EXCHANGE": "BITGET"}
{"action": "update", "arg": {"instType": "SPOT", "channel": "books", "instId": "BTCUSDT"}, "data": [{"asks": [["83940.01", "1.732980"], ["83940.49", "0.149527"], ["83951.58", "3.186753"], ["83964.55", "0.052656"], ["83972.08", "0"], ["83978.76", "0.054301"], ["83979.95", "3.717879"], ["83981.20", "0.001503"], ["83983.20", "0.002452"], ["83985.20", "0.006454"], ["83987.20", "0.016984"], ["83989.20", "0.044695"], ["83991.20", "0.117618"], ["83993.20", "0.309521"], ["83995.20", "0.814529"], ["83997.20", "2.143496"], ["83999.20", "5.640780"], ["84001.20", "14.844158"], ["84002.00", "0.044670"], ["84002.80", "0"], ["84004.00", "0.042690"], ["84004.10", "5.841270"], ["84004.70", "0.376650"], ["84006.40", "0.060000"], ["84007.10", "0"], ["84007.60", "0"], ["84008.30", "2.995170"], ["84012.30", "0.743700"], ["84012.50", "0.100170"], ["84043.20", "5.354080"], ["84051.60", "4.265114"], ["84060.00", "4.537356"], ["84068.40", "3.902126"], ["84076.80", "4.083620"], ["84085.20", "4.628103"], ["84093.60", "5.626321"], ["84102.00", "4.991091"], ["84110.40", "4.355862"], ["84118.80", "4.900344"], ["84127.20", "5.444827"], ["84135.60", "4.718850"], ["84144.00", "4.809597"], ["84152.40", "4.446609"], ["84160.80", "4.174367"], ["84169.20", "3.992873"], ["84177.60", "5.535574"], ["84186.00", "5.263333"], ["84194.40", "5.081838"], ["84202.80", "5.172586"], ["84342.11", "0"]], "bids": [["83931.10", "0.002727"], ["83929.12", "0"], ["83929.10", "0.007177"], ["83927.10", "0.018886"], ["83927.03", "0.114051"], ["83925.10", "0.049701"], ["83923.10", "0.130792"], ["83921.10", "0.344191"], ["83919.10", "0.905764"], ["83918.94", "0.945042"], ["83917.10", "2.383590"], ["83917.00", "2.365050"], ["83916.90", "0.520980"], ["83916.50", "0"], ["83914.90", "0.066600"], ["83914.70", "0"], ["83913.90", "0"], ["83913.70", "0.099150"], ["83911.30", "0.083100"], ["83910.00", "0.002281"], ["83909.51", "0.169796"], ["83908.70", "1.510920"], ["83908.20", "0.026190"], ["83907.40", "0"], ["83906.00", "0.045000"], ["83905.90", "0.858360"], ["83875.10", "4.355862"], ["83866.70", "4.537356"], ["83858.30", "3.902126"], ["83849.90", "4.991091"], ["83841.50", "5.263333"], ["83833.10", "4.900344"], ["83824.70", "3.992873"], ["83816.30", "5.444827"], ["83807.90", "5.535574"], ["83799.50", "4.446609"], ["83791.10", "5.354080"], ["83782.70", "4.628103"], ["83774.30", "4.718850"], ["83765.90", "5.081838"], ["83757.50", "4.265114"], ["83749.10", "4.083620"], ["83740.70", "4.809597"], ["83732.30", "5.172586"], ["83723.90", "5.626321"], ["83715.50", "4.174367"], ["83437.50", "0"], ["83437.10", "0"]], "checksum": 697744483, "ts": "1742577063539"}], "ts": 1742577063543, "record_time": 1742577063.736537, "EXCHANGE": "BITGET"}
{"action": "update", "arg": {"instType": "SPOT", "channel": "books", "instId": "BTCUSDT"}, "data": [{"asks": [["83951.57", "0.956026"], ["83981.20", "0.001353"], ["83983.20", "0.002290"], ["83985.20", "0.006142"], ["83987.20", "0.016163"], ["83989.20", "0.042534"], ["83991.20", "0.111932"], ["83993.20", "0.294556"], ["83995.20", "0.775148"], ["83997.20", "2.039863"], ["83999.20", "5.368061"], ["84001.20", "14.126477"], ["84004.10", "3.568380"], ["84004.30", "3.282840"], ["84004.50", "0"], ["84006.80", "0.651750"], ["84009.20", "0"], ["84010.70", "0"], ["84011.50", "0"], ["84012.20", "0.012570"], ["84013.10", "0.204000"], ["84043.20", "4.718850"], ["84051.60", "4.083620"], ["84060.00", "5.535574"], ["84068.40", "3.992873"], ["84076.80", "5.354080"], ["84085.20", "5.263333"], ["84093.60", "4.900344"], ["84102.00", "3.902126"], ["84110.40", "4.809597"], ["84118.80", "4.265114"], ["84127.20", "4.628103"], ["84135.60", "4.174367"], ["84144.00", "4.537356"], ["84152.40", "5.626321"], ["84160.80", "4.991091"], ["84169.20", "5.081838"], ["84177.60", "5.444827"], ["84186.00", "4.355862"], ["84194.40", "4.446609"]], "bids": [["83940.00", "0.693409"], ["83933.12", "0.094633"], ["83933.10", "0.001277"], ["83931.10", "0.003362"], ["83929.10", "0.008847"], ["83927.10", "0.023282"], ["83925.10", "0.061268"], ["83923.10", "0.161230"], ["83921.10", "0.424290"], ["83919.10", "1.116553"], ["83917.10", "2.938428"], ["83917.00", "2.369610"], ["83916.60", "0"], ["83914.90", "0"], ["83913.30", "0.073200"], ["83912.90", "0.030000"], ["83912.00", "0.042300"], ["83911.40", "0.160920"], ["83909.50", "1.074540"], ["83908.70", "1.350000"], ["83906.00", "0.165000"], ["83905.90", "0.933360"], ["83897.00", "0.000160"], ["83896.00", "0.000160"], ["83895.00", "0.000160"], ["83890.79", "0.024948"], ["83866.87", "0.071668"], ["83866.70", "3.992873"], ["83858.30", "4.991091"], ["83849.90", "5.626321"], ["83833.10", "4.265114"], ["83824.70", "4.537356"], ["83816.30", "4.718850"], ["83807.90", "4.446609"], ["83799.50", "5.535574"], ["83791.10", "4.174367"], ["83782.70", "4.083620"], ["83774.30", "3.902126"], ["83765.90", "4.628103"], ["83757.50", "4.809597"], ["83749.10", "5.172586"], ["83740.70", "5.444827"], ["83732.30", "4.900344"], ["83723.90", "5.081838"], ["83715.50", "5.354080"], ["83442.50", "0"], ["83441.56", "0"], ["83440.00", "0"], ["83439.42", "0"], ["83439.33", "0"]], "checksum": 1149086344, "ts": "1742577063746"}], "ts": 1742577063748, "record_time": 1742577063.941942, "EXCHANGE": "BITGET"}
{"action": "update", "arg": {"instType": "SPOT", "channel": "books", "instId": "BTCUSDT"}, "data": [{"asks": [["83979.94", "0.313960"], ["83981.20", "0.001543"], ["83983.20", "0.002517"], ["83985.20", "0.006623"], ["83987.20", "0.017431"], ["83989.20", "0.045869"], ["83991.20", "0.120710"], ["83993.20", "0.317816"], ["83995.20", "0.836360"], ["83997.20", "2.200947"], ["83999.20", "5.791964"], ["84001.20", "15.242012"], ["84004.70", "0.869880"], ["84012.20", "0"], ["84013.30", "0.180000"], ["84043.20", "4.628103"], ["84051.60", "5.444827"], ["84060.00", "5.263333"], ["84068.40", "5.354080"], ["84076.80", "4.900344"], ["84085.20", "5.081838"], ["84093.60", "4.355862"], ["84102.00", "4.265114"], ["84110.40", "5.626321"], ["84118.80", "3.992873"], ["84127.20", "5.172586"], ["84135.60", "4.991091"], ["84144.00", "4.174367"], ["84152.40", "5.535574"], ["84160.80", "3.902126"], ["84169.20", "4.809597"], ["84177.60", "4.083620"], ["84186.00", "4.446609"], ["84194.40", "4.537356"], ["84202.80", "4.718850"], ["84341.01", "0"]], "bids": [["83937.77", "0.038760"], ["83937.69", "0"], ["83933.12", "0"], ["83930.10", "0.067692"], ["83908.80", "0.485160"], ["83905.90", "0"], ["83875.10", "5.172586"], ["83866.70", "4.446609"], ["83858.30", "4.809597"], ["83849.90", "4.355862"], ["83841.50", "4.900344"], ["83833.10", "4.718850"], ["83824.70", "4.083620"], ["83816.30", "3.992873"], ["83807.90", "5.263333"], ["83799.50", "4.991091"], ["83791.10", "5.444827"], ["83782.70", "5.354080"], ["83774.30", "5.081838"], ["83765.90", "4.265114"], ["83757.50", "5.626321"], ["83749.10", "4.537356"], ["83740.70", "4.628103"], ["83732.30", "5.535574"], ["83723.90", "3.902126"], ["83715.50", "4.174367"]], "checksum": -57710514, "ts": "1742577063977"}], "ts": 1742577063981, "record_time": 1742577064.174831, "EXCHANGE": "BITGET"}
{"action": "update", "arg": {"instType": "SPOT", "channel": "books", "instId": "BTCUSDT"}, "data": [{"asks": [["83940.49", "0.045129"], ["83981.20", "0.001651"], ["83983.20", "0.002695"], ["83985.20", "0.007092"], ["83987.20", "0.018927"], ["83989.20", "0.049808"], ["83991.20", "0.131072"], ["83993.20", "0.344928"], ["83995.20", "0.907704"], ["83997.20", "2.388694"], ["83999.20", "6.286039"], ["84001.20", "16.542208"], ["84002.80", "0.032190"], ["84004.10", "3.568170"], ["84004.70", "0.376650"], ["84006.80", "0"], ["84009.00", "3.826560"], ["84009.30", "0.536970"], ["84012.50", "0"], ["84013.30", "0"], ["84043.20", "4.446609"], ["84051.60", "5.172586"], ["84060.00", "5.535574"], ["84068.40", "3.992873"], ["84076.80", "5.263333"], ["84085.20", "5.444827"], ["84093.60", "5.354080"], ["84102.00", "4.355862"], ["84118.80", "4.174367"], ["84127.20", "4.537356"], ["84135.60", "4.809597"], ["84144.00", "4.628103"], ["84152.40", "5.081838"], ["84169.20", "4.265114"], ["84177.60", "4.900344"], ["84186.00", "4.991091"], ["84194.40", "4.083620"], ["84341.01", "0.000008"]], "bids": [["83933.10", "0.001163"], ["83931.10", "0.003061"], ["83929.10", "0.007926"], ["83927.10", "0.020859"], ["83925.10", "0.054892"], ["83924.21", "0.219416"], ["83923.10", "0.144452"], ["83921.10", "0.380138"], ["83919.10", "1.000363"], ["83917.10", "2.632532"], ["83917.00", "2.365470"], ["83915.10", "0.234570"], ["83914.30", "0.066630"], ["83913.70", "0.098940"], ["83913.30", "0.072990"], ["83909.50", "0.766800"], ["83908.70", "0"], ["83906.00", "0.000160"], ["83875.10", "5.263333"], ["83866.70", "5.626321"], ["83858.30", "4.718850"], ["83849.90", "4.446609"], ["83841.50", "4.537356"], ["83833.10", "3.992873"], ["83824.70", "5.354080"], ["83816.30", "4.083620"], ["83807.90", "4.174367"], ["83799.50", "3.902126"], ["83791.10", "4.809597"], ["83782.70", "5.172586"], ["83774.30", "4.265114"], ["83765.90", "4.628103"], ["83757.50", "5.535574"], ["83749.10", "5.081838"], ["83740.70", "4.355862"], ["83732.30", "4.991091"], ["83723.90", "5.444827"], ["83715.50", "4.900344"], ["83443.53", "0"]], "checksum": -970810297, "ts": "1742577064179"}], "ts": 1742577064183, "record_time": 1742577064.378086, "EXCHANGE": "BITGET"}
{"action": "update", "arg": {"instType": "SPOT", "channel": "books", "instId": "BTCUSDT"}, "data": [{"asks": [["83940.01", "1.744780"], ["83940.49", "0.143886"], ["84001.70", "0"], ["84001.80", "0.001038"], ["84002.00", "0.044460"], ["84002.20", "0"], ["84002.80", "0.001024"], ["84004.10", "3.568380"], ["84009.00", "1.467360"], ["84011.40", "2.359110"], ["84013.30", "0.180000"], ["84043.20", "5.444827"], ["84051.60", "3.902126"], ["84060.00", "4.809597"], ["84068.40", "4.991091"], ["84076.80", "4.900344"], ["84085.20", "4.628103"], ["84093.60", "5.626321"], ["84102.00", "4.446609"], ["84110.40", "4.083620"], ["84118.80", "4.537356"], ["84127.20", "4.718850"], ["84135.60", "5.535574"], ["84144.00", "4.174367"], ["84152.40", "5.263333"], ["84160.80", "5.172586"], ["84169.20", "5.354080"], ["84177.60", "5.081838"], ["84186.00", "4.265114"], ["84194.40", "3.992873"], ["84202.80", "4.355862"], ["84341.01", "0"]], "bids": [["83937.84", "0.038760"], ["83937.77", "0"], ["83925.10", "0.054696"], ["83923.10", "0.143938"], ["83921.10", "0.378784"], ["83919.10", "0.996800"], ["83918.94", "1.571400"], ["83917.10", "2.623158"], ["83914.64", "0"], ["83909.51", "0"], ["83908.70", "1.350000"], ["83875.10", "4.446609"], ["83866.70", "4.174367"], ["83858.30", "4.991091"], ["83849.90", "4.628103"], ["83841.50", "4.355862"], ["83833.10", "5.535574"], ["83824.70", "4.537356"], ["83816.30", "5.172586"], ["83807.90", "5.081838"], ["83799.50", "3.992873"], ["83791.10", "4.718850"], ["83782.70", "4.900344"], ["83774.30", "4.809597"], ["83765.90", "4.083620"], ["83760.00", "0.003465"], ["83757.50", "5.626321"], ["83749.10", "4.265114"], ["83740.70", "5.444827"], ["83732.30", "5.263333"], ["83723.90", "3.902126"], ["83715.50", "5.354080"], ["83443.53", "0.000161"]], "checksum": -938793222, "ts": "1742577064378"}], "ts": 1742577064381, "record_time": 1742577064.57843, "EXCHANGE": "BITGET"}
{"action": "update", "arg": {"instType": "SPOT", "channel": "books", "instId": "BTCUSDT"}, "data": [{"asks": [["83979.94", "0.319601"], ["84008.30", "2.680320"], ["84013.80", "0.718530"], ["84043.20", "5.172586"], ["84051.60", "4.900344"], ["84060.00", "5.354080"], ["84068.40", "4.537356"], ["84076.80", "4.809597"], ["84085.20", "4.174367"], ["84093.60", "5.263333"], ["84102.00", "5.444827"], ["84110.40", "5.626321"], ["84118.80", "4.083620"], ["84135.60", "5.081838"], ["84144.00", "4.265114"], ["84152.40", "4.991091"], ["84160.80", "3.992873"], ["84169.20", "4.628103"], ["84177.60", "3.902126"], ["84186.00", "4.446609"], ["84194.40", "4.355862"], ["84202.80", "5.535574"], ["84294.97", "1.653488"], ["84302.14", "0"], ["84341.00", "0"]], "bids": [["83933.12", "0.094678"], ["83910.00", "0.002160"], ["83894.00", "0.000160"], ["83893.00", "0.000160"], ["83892.00", "0.000160"], ["83891.00", "0.000160"], ["83875.10", "4.900344"], ["83858.30", "4.537356"], ["83849.90", "4.991091"], ["83841.50", "5.444827"], ["83833.10", "4.265114"], ["83824.70", "4.809597"], ["83816.30", "4.083620"], ["83807.90", "4.355862"], ["83799.50", "5.081838"], ["83791.10", "3.902126"], ["83782.70", "4.446609"], ["83774.30", "3.992873"], ["83765.90", "4.628103"], ["83757.50", "5.263333"], ["83749.10", "5.626321"], ["83740.70", "5.354080"], ["83732.30", "5.535574"], ["83723.90", "5.172586"], ["83715.50", "4.718850"], ["83630.40", "0"], ["83623.28", "1.664511"], ["83445.16", "0"], ["83444.44", "0"], ["83444.38", "0"], ["83444.27", "0"], ["83443.53", "0"]], "checksum": 1481579512, "ts": "1742577064585"}], "ts": 1742577064587, "record_time": 1742577064.780864, "EXCHANGE": "BITGET"}
{"action": "update", "arg": {"instType": "SPOT", "channel": "books", "instId": "BTCUSDT"}, "data": [{"asks": [["83983.20", "0.002550"], ["83985.20", "0.006711"], ["83987.20", "0.017659"], ["83989.20", "0.046471"], ["83991.20", "0.122294"], ["83993.20", "0.321825"], ["83995.20", "0.846909"], ["83997.20", "2.228707"], ["83999.20", "5.865020"], ["84001.20", "15.434261"], ["84004.10", "2.230500"], ["84011.40", "2.359830"], ["84011.80", "0"], ["84013.90", "0.010890"], ["84043.20", "4.083620"], ["84051.60", "3.902126"], ["84060.00", "4.537356"], ["84068.40", "5.172586"], ["84076.80", "3.992873"], ["84085.20", "4.446609"], ["84093.60", "5.081838"], ["84102.00", "4.174367"], ["84110.40", "5.444827"], ["84118.80", "5.535574"], ["84127.20", "4.991091"], ["84135.60", "4.809597"], ["84144.00", "5.626321"], ["84152.40", "4.265114"], ["84160.80", "4.718850"], ["84177.60", "5.354080"], ["84186.00", "5.263333"], ["84202.80", "4.900344"]], "bids": [["83937.84", "0"], ["83908.70", "0"], ["83875.10", "4.355862"], ["83866.70", "5.626321"], ["83858.30", "3.902126"], ["83849.90", "4.900344"], ["83841.50", "4.718850"], ["83833.10", "5.354080"], ["83824.70", "3.992873"], ["83816.30", "4.537356"], ["83807.90", "5.444827"], ["83799.50", "4.809597"], ["83791.10", "4.265114"], ["83782.70", "4.174367"], ["83774.30", "4.083620"], ["83765.90", "4.446609"], ["83757.50", "5.172586"], ["83749.10", "4.628103"], ["83740.70", "5.263333"], ["83723.90", "4.991091"], ["83715.50", "5.081838"], ["83636.07", "0"], ["83445.16", "0.000054"], ["83444.44", "0.000105"], ["83444.38", "0.000025"]], "checksum": 810296081, "ts": "1742577064796"}], "ts": 1742577064800, "record_time": 1742577064.993988, "EXCHANGE": "BITGET"}
{"event": "subscribe", "arg": {"instType": "SPOT", "channel": "books", "instId": "BTCUSDT"}, "record_time": 1742577141.979347, "EXCHANGE": "BITGET"}
{"action": "snapshot", "arg": {"instType": "SPOT", "channel": "books", "instId": "BTCUSDT"}, "data": [{"asks": [["83918.03", "0.644316"], ["83918.07", "0.092739"], ["83918.91", "0.062760"], ["83924.41", "0.355310"], ["83924.42", "0.727090"], ["83924.43", "0.155339"], ["83925.83", "0.013887"], ["83928.39", "0.209200"], ["83934.77", "0.035971"], ["83935.12", "0.056636"], ["83935.13", "0.119905"], ["83935.87", "0.035972"], ["83936.15", "0.006357"], ["83936.37", "0.006357"], ["83936.68", "0.006357"], ["83937.24", "0.010995"], ["83937.42", "0.006357"], ["83937.56", "1.024057"], ["83937.57", "3.187357"], ["83937.71", "0.006357"], ["83937.95", "0.006356"], ["83938.37", "0.006357"], ["83938.63", "0.017482"], ["83938.86", "0.006357"], ["83939.08", "0.006357"], ["83939.20", "0.006357"], ["83939.23", "0.016429"], ["83939.25", "0.119901"], ["83939.33", "0.006357"], ["83939.39", "0.006357"], ["83939.61", "0.006357"], ["83939.99", "0.000119"], ["83940.00", "0.002000"], ["83940.01", "0.209200"], ["83940.20", "0.006357"], ["83940.33", "0.006357"], ["83941.54", "0.009990"], ["83941.56", "0.010993"], ["83941.67", "0.006357"], ["83941.92", "0.150844"], ["83941.93", "0.314701"], ["83943.01", "0.119850"], ["83943.95", "0.119905"], ["83944.04", "0.015895"], ["83944.43", "0.119858"], ["83944.44", "0.009989"], ["83945.21", "0.016429"], ["83946.22", "0.006356"], ["83946.98", "0.105865"], ["83946.99", "0.116800"], ["83948.61", "0.209200"], ["83948.89", "0.015896"], ["83949.60", "0.010988"], ["83958.63", "0.175050"], ["83959.30", "0.001310"], ["83959.45", "0.047600"], ["83961.30", "0.002138"], ["83962.01", "0.209200"], ["83962.11", "3.718712"], ["83963.30", "0.005626"], ["83965.30", "0.014805"], ["83966.69", "0.714569"], ["83967.30", "0.038961"], ["83968.30", "0.000976"], ["83969.30", "0.102528"], ["83970.00", "0.002000"], ["83971.30", "0.269810"], ["83971.97", "0.209200"], ["83973.30", "0.710026"], ["83975.30", "1.868490"], ["83977.22", "0.001598"], ["83977.30", "4.917081"], ["83979.30", "12.939685"], ["83979.40", "6.648000"], ["83980.00", "0.042480"], ["83980.07", "0.001598"], ["83980.37", "0.209200"], ["83981.30", "0.001024"], ["83982.00", "0.042480"], ["83983.10", "0.071730"], ["83983.30", "0.288000"], ["83984.00", "0.042480"], ["83984.20", "0.204000"], ["83984.30", "5.997330"], ["83984.80", "0.522360"], ["83985.00", "0.432000"], ["83985.10", "0.192000"], ["83985.20", "0.449520"], ["83985.50", "0.323640"], ["83986.00", "0.071220"], ["83986.90", "0.060000"], ["83987.00", "2.141970"], ["83987.10", "3.924450"], ["83987.35", "1.785983"], ["83987.60", "0.291390"], ["83987.70", "0.625710"], ["83987.80", "1.072110"], ["83988.00", "0.042300"], ["83988.40", "0.180000"], ["83989.10", "0.072990"], ["83989.20", "0.300000"], ["83989.30", "0.216000"], ["83991.30", "0.015000"], ["83991.48", "0.890330"], ["83991.55", "0.001810"], ["83995.14", "0.209200"], ["83996.28", "0.000179"], ["84000.00", "0.002000"], ["84002.10", "0.196628"], ["84006.31", "0.209200"], ["84006.40", "0.003620"], ["84021.30", "4.538535"], ["84025.82", "0.209200"], ["84029.70", "4.447765"], ["84030.00", "0.002000"], ["84031.83", "0.057335"], ["84034.22", "0.209200"], ["84038.10", "5.173930"], ["84042.82", "0.209200"], ["84045.89", "0.010010"], ["84046.50", "4.266223"], ["84048.59", "0.071668"], ["84049.36", "0.071678"], ["84050.00", "0.002144"], ["84052.01", "0.209200"], ["84052.14", "0.125880"], ["84054.20", "0.296078"], ["84054.90", "5.083159"], ["84060.00", "0.002000"], ["84063.21", "0.209200"], ["84063.30", "4.356994"], ["84066.80", "0.001450"], ["84070.00", "0.001279"], ["84071.61", "0.209200"], ["84071.70", "4.175453"], ["84080.10", "5.264701"], ["84081.19", "0.209200"], ["84081.60", "0.000027"], ["84083.80", "0.300112"], ["84088.50", "5.537013"], ["84089.59", "0.209200"], ["84090.00", "0.002000"], ["84096.00", "0.001184"], ["84096.90", "4.992389"], ["84101.11", "0.209200"], ["84105.30", "4.084682"], ["84108.80", "0.001444"], ["84113.70", "5.627784"], ["84113.80", "0.301368"], ["84114.71", "0.203800"], ["84117.23", "0.001720"], ["84118.31", "0.168704"], ["84120.00", "0.002000"], ["84120.31", "0.000018"], ["84120.42", "0.000008"], ["84121.21", "0.000010"], ["84121.90", "0.000124"], ["84121.93", "0.000069"], ["84122.10", "5.355472"], ["84122.11", "0.000023"], ["84124.00", "0.000175"], ["84124.14", "0.000135"], ["84124.65", "0.000066"], ["84125.00", "0.007748"], ["84125.55", "0.209200"], ["84126.51", "0.000008"], ["84127.27", "0.000010"], ["84128.44", "0.000072"], ["84129.03", "0.000008"], ["84129.07", "0.000020"], ["84130.00", "0.060049"], ["84130.43", "0.003446"], ["84130.50", "4.720077"], ["84132.13", "0.000176"], ["84132.80", "0.000008"], ["84132.97", "0.000104"], ["84133.33", "0.002817"], ["84133.94", "0.209200"], ["84136.28", "0.000011"], ["84137.93", "0.000024"], ["84138.74", "0.000024"], ["84138.90", "4.629306"], ["84139.90", "0.000023"], ["84140.00", "0.000630"], ["84140.96", "0.000013"], ["84141.97", "0.000423"], ["84142.33", "0.209200"], ["84142.86", "0.042208"], ["84144.14", "0.000061"], ["84144.15", "0.000053"], ["84144.74", "0.000093"], ["84147.30", "4.810847"], ["84148.30", "0.000060"], ["84148.94", "0.000137"], ["84148.96", "0.000039"], ["84150.00", "0.002747"], ["84150.08", "0.000019"], ["84150.33", "0.000008"], ["84150.72", "0.209200"], ["84151.59", "0.000020"], ["84151.79", "0.000036"], ["84152.17", "0.000010"], ["84153.84", "0.000008"], ["84153.85", "0.000023"], ["84155.70", "3.903140"], ["84155.83", "0.000019"], ["84156.01", "0.000019"], ["84157.75", "0.027677"], ["84157.89", "0.000183"], ["84159.01", "0.000149"], ["84159.09", "0.000042"], ["84159.11", "0.209200"], ["84159.59", "0.000036"], ["84159.62", "0.000099"], ["84160.00", "0.001138"], ["84160.71", "0.000016"], ["84162.16", "0.000009"], ["84162.50", "0.000031"], ["84163.18", "0.000050"], ["84163.64", "0.000008"], ["84163.92", "0.000010"], ["84164.10", "5.446242"], ["84165.59", "0.000054"], ["84166.55", "0.000008"], ["84166.67", "0.000699"], ["84166.69", "0.000010"], ["84166.71", "0.000008"], ["84167.51", "0.209200"], ["84168.50", "0.000008"], ["84169.49", "0.001213"], ["84170.00", "0.000725"], ["84170.25", "0.000143"], ["84170.47", "0.000013"], ["84170.56", "0.000009"], ["84171.43", "0.000016"], ["84172.50", "4.901618"], ["84173.62", "0.000024"], ["84173.91", "0.000020"], ["84174.51", "0.000388"], ["84174.57", "0.000010"], ["84174.61", "0.000043"], ["84175.73", "0.000010"], ["84176.47", "0.000040"], ["84177.20", "0.000064"], ["84179.10", "0.000008"], ["84180.00", "0.002639"], ["84180.09", "0.000033"], ["84180.90", "3.993911"], ["84181.09", "0.000030"], ["84181.81", "0.001547"], ["84181.82", "0.000060"], ["84182.16", "0.000048"], ["84182.69", "0.000067"], ["84183.27", "0.000009"], ["84183.50", "0.000113"], ["84183.67", "0.000010"], ["84184.17", "0.000009"], ["84188.89", "0.000025"], ["84189.33", "0.000133"], ["84189.45", "0.000023"], ["84190.00", "0.000670"], ["84191.18", "0.000041"], ["84192.12", "0.000288"], ["84192.98", "0.000033"], ["84193.22", "0.000023"], ["84193.77", "0.000012"], ["84193.99", "0.000209"], ["84194.12", "0.000071"], ["84195.96", "0.000038"], ["84196.77", "0.000020"], ["84197.27", "0.000016"], ["84198.00", "0.001012"], ["84198.35", "0.000057"], ["84198.45", "0.000008"], ["84200.00", "0.013254"], ["84200.01", "0.000246"], ["84203.00", "0.000008"], ["84203.59", "0.000061"], ["84204.08", "0.000184"], ["84205.61", "0.000034"], ["84205.79", "0.000135"], ["84205.88", "0.000080"], ["84206.90", "0.000008"], ["84207.14", "0.000128"], ["84207.69", "0.000009"], ["84208.00", "0.000012"], ["84209.48", "0.000013"], ["84209.68", "0.000019"], ["84209.82", "0.000047"], ["84210.00", "0.002618"], ["84210.53", "0.000009"], ["84212.00", "0.000012"], ["84212.47", "0.000009"], ["84212.50", "0.006969"], ["84213.98", "0.011010"], ["84214.29", "0.000033"], ["84214.88", "0.000161"], ["84215.69", "0.000008"], ["84216.22", "0.000008"], ["84216.67", "0.000970"], ["84216.87", "0.000008"], ["84217.48", "0.000095"], ["84217.86", "0.000273"], ["84219.35", "0.000008"], ["84219.55", "0.000349"], ["84220.00", "0.000618"], ["84220.69", "0.000135"], ["84222.00", "0.000081"], ["84222.03", "0.000013"], ["84222.22", "0.000907"], ["84223.05", "0.000039"], ["84223.65", "0.000178"], ["84223.89", "0.000008"], ["84224.11", "0.000277"], ["84224.14", "0.000016"], ["84224.62", "0.000022"], ["84225.00", "0.000107"], ["84225.86", "0.007944"], ["84225.88", "0.000024"], ["84226.09", "0.000013"], ["84226.42", "0.000096"], ["84228.57", "0.000013"], ["84228.72", "0.000188"], ["84229.07", "0.000010"], ["84229.39", "0.000020"], ["84230.00", "0.000640"], ["84230.76", "0.000008"], ["84230.77", "0.000111"], ["84232.69", "0.000066"], ["84233.16", "0.000023"], ["84233.34", "0.000119"], ["84233.38", "0.001273"], ["84233.43", "0.000015"], ["84233.87", "0.000039"], ["84234.04", "0.000137"], ["84234.07", "0.000039"], ["84234.23", "0.000698"], ["84235.23", "0.000051"], ["84235.29", "0.042045"], ["84235.93", "0.000046"], ["84238.10", "0.000024"], ["84238.53", "0.000072"], ["84238.89", "0.000134"], ["84239.00", "0.000240"], ["84239.11", "0.000011"], ["84239.13", "0.000010"], ["84240.00", "0.003183"], ["84242.34", "0.000423"], ["84242.60", "0.000537"], ["84243.01", "0.209200"], ["84244.90", "0.000085"], ["84246.15", "0.000015"], ["84249.42", "0.000030"], ["84250.00", "0.067266"], ["84251.44", "0.000011"], ["84252.44", "0.000143"], ["84252.50", "0.000025"], ["84254.39", "0.000022"], ["84254.55", "0.000009"], ["84255.35", "0.000143"], ["84256.00", "0.000022"], ["84256.79", "0.000314"], ["84257.14", "0.000145"], ["84258.91", "0.000036"], ["84259.12", "0.000009"], ["84259.81", "0.209200"], ["84259.87", "0.000093"], ["84259.99", "0.000017"], ["84260.00", "0.000676"], ["84260.87", "0.000008"], ["84263.15", "0.000019"], ["84263.16", "0.000183"], ["84264.71", "0.000009"], ["84266.08", "0.000016"], ["84266.67", "0.002976"], ["84267.78", "0.000010"], ["84268.56", "0.000013"], ["84269.24", "0.000032"], ["84270.00", "0.002641"], ["84270.27", "0.000009"], ["84270.80", "0.000018"], ["84270.96", "0.000055"], ["84270.98", "0.000052"], ["84271.10", "0.000019"], ["84271.34", "0.000026"], ["84272.72", "0.000105"], ["84272.73", "0.000492"], ["84273.33", "0.000013"], ["84276.28", "0.000009"], ["84277.78", "0.000011"], ["84278.24", "0.000050"], ["84278.38", "0.000199"], ["84279.36", "0.000009"], ["84279.98", "0.000239"], ["84280.00", "0.001334"], ["84280.70", "0.000033"], ["84280.74", "0.000047"], ["84280.90", "1.718877"], ["84281.69", "0.000099"], ["84282.35", "0.000071"], ["84282.39", "0.000135"], ["84282.82", "0.000012"], ["84283.33", "0.000010"], ["84283.87", "0.000020"], ["84285.00", "0.000031"], ["84285.68", "0.000178"], ["84285.71", "0.000347"], ["84285.95", "0.000028"], ["84286.00", "0.000119"], ["84286.67", "0.000009"], ["84286.73", "0.000057"], ["84286.79", "0.000016"], ["84287.50", "0.000076"], ["84288.00", "0.003000"], ["84288.89", "0.000361"], ["84289.58", "0.000008"], ["84290.00", "0.000617"], ["84293.56", "0.000063"], ["84294.12", "0.000080"], ["84294.20", "0.000128"], ["84294.68", "0.000019"], ["84296.87", "0.000014"], ["84297.06", "0.000035"], ["84298.07", "0.000811"], ["84298.31", "0.000023"], ["84298.41", "0.000009"], ["84298.64", "0.000088"], ["84300.00", "0.023791"], ["84301.40", "0.000023"], ["84301.47", "0.000041"], ["84302.88", "0.000067"], ["84303.00", "0.296549"], ["84306.66", "0.000145"], ["84307.00", "0.000113"], ["84307.23", "0.000008"], ["84309.09", "0.000010"], ["84309.60", "0.002450"], ["84309.68", "0.000062"], ["84309.96", "0.000011"], ["84310.34", "0.000331"], ["84310.35", "0.000146"], ["84311.11", "0.000025"], ["84311.16", "0.000008"], ["84311.31", "0.002260"], ["84311.72", "0.000013"], ["84312.50", "0.000125"], ["84313.03", "0.000024"], ["84314.97", "0.000008"], ["84315.74", "0.000051"], ["84316.67", "0.000322"], ["84317.24", "0.000135"], ["84317.40", "0.000010"], ["84318.18", "0.000012"], ["84318.59", "0.000027"], ["84319.15", "0.000137"], ["84319.18", "0.000039"], ["84320.00", "0.000019"], ["84321.87", "0.000919"], ["84322.11", "0.000008"], ["84324.32", "0.000069"], ["84325.00", "0.000128"], ["84325.07", "0.000161"], ["84326.09", "0.000010"], ["84326.42", "0.000023"], ["84327.14", "0.000039"], ["84327.73", "0.041940"], ["84328.95", "0.000174"], ["84329.64", "0.000026"], ["84330.00", "0.002000"], ["84332.00", "0.511323"], ["84332.56", "0.000009"], ["84333.32", "0.000047"], ["84333.33", "0.003953"], ["84333.36", "0.000010"], ["84333.38", "0.000008"], ["84334.48", "0.000096"], ["84334.77", "0.000022"], ["84336.00", "0.000133"], ["84336.23", "0.000013"], ["84336.29", "0.000010"], ["84336.34", "0.000176"], ["84337.25", "0.000067"], ["84337.35", "0.000008"], ["84337.50", "0.000010"], ["84338.26", "0.000023"], ["84338.46", "0.000015"], ["84339.21", "0.000010"], ["84339.29", "0.000029"], ["84339.50", "0.000323"], ["84339.62", "0.000051"], ["84340.00", "0.018287"], ["84340.46", "0.000143"], ["84340.72", "0.000066"], ["84341.00", "0.002997"], ["84341.01", "0.000008"], ["84342.11", "0.000051"], ["84342.63", "0.000009"], ["84342.70", "0.000423"], ["84343.02", "0.000338"], ["84343.07", "0.000014"]], "bids": [["83918.02", "0.517896"], ["83915.30", "0.001047"], ["83914.72", "0.157464"], ["83914.71", "0.209200"], ["83913.30", "0.001002"], ["83912.50", "0.314679"], ["83911.30", "0.001818"], ["83911.00", "0.004766"], ["83910.99", "0.006543"], ["83910.18", "0.007599"], ["83909.30", "0.004785"], ["83907.30", "0.012593"], ["83906.00", "0.009907"], ["83905.77", "0.225289"], ["83905.76", "0.270613"], ["83905.73", "0.059590"], ["83905.72", "0.214764"], ["83905.37", "0.204856"], ["83905.30", "0.033139"], ["83904.93", "0.010000"], ["83904.58", "0.114033"], ["83904.00", "0.000121"], ["83903.30", "0.087209"], ["83903.12", "0.062723"], ["83901.30", "0.229495"], ["83899.30", "0.603935"], ["83897.30", "1.589304"], ["83896.23", "0.557900"], ["83896.22", "0.764679"], ["83895.82", "0.008279"], ["83895.81", "0.013838"], ["83895.70", "0.028879"], ["83895.30", "4.182377"], ["83895.20", "0.001022"], ["83895.10", "0.001025"], ["83895.00", "0.001017"], ["83894.60", "2.361090"], ["83894.49", "0.089666"], ["83894.17", "0.008076"], ["83894.01", "0.247524"], ["83893.90", "0.128340"], ["83892.71", "0.250158"], ["83892.65", "0.008029"], ["83892.62", "0.006317"], ["83892.60", "0.010890"], ["83892.58", "0.012547"], ["83892.56", "0.009262"], ["83892.54", "0.015735"], ["83892.51", "0.008483"], ["83892.49", "0.005601"], ["83892.48", "0.009425"], ["83892.47", "0.010065"], ["83892.38", "0.008608"], ["83892.23", "0.083631"], ["83892.21", "0.017825"], ["83892.00", "0.000121"], ["83891.66", "0.024669"], ["83891.60", "0.071610"], ["83891.56", "0.018271"], ["83891.27", "0.015749"], ["83891.22", "0.016431"], ["83891.20", "0.017593"], ["83891.19", "0.007830"], ["83891.17", "0.006978"], ["83891.13", "0.007781"], ["83891.11", "0.009803"], ["83891.07", "0.009567"], ["83891.03", "0.007389"], ["83890.88", "0.006571"], ["83890.86", "0.715214"], ["83890.67", "0.005950"], ["83890.60", "0.262440"], ["83890.36", "0.007140"], ["83890.00", "0.042300"], ["83889.82", "0.007346"], ["83889.78", "0.017124"], ["83889.58", "0.055632"], ["83889.55", "0.017113"], ["83889.39", "0.209200"], ["83889.30", "0.180000"], ["83889.10", "0.886470"], ["83889.00", "0.070560"], ["83888.81", "0.008200"], ["83888.68", "0.004036"], ["83888.56", "0.009009"], ["83888.06", "0.225049"], ["83888.04", "0.025199"], ["83888.00", "0.042300"], ["83887.80", "0.442410"], ["83887.68", "0.017376"], ["83887.12", "0.012673"], ["83887.07", "0.051842"], ["83887.03", "0.024948"], ["83886.90", "1.350000"], ["83886.66", "0.008290"], ["83886.00", "0.042300"], ["83885.60", "0.015000"], ["83885.48", "0.010364"], ["83885.47", "0.008934"], ["83885.46", "0.008782"], ["83885.32", "0.018549"], ["83885.20", "0.030000"], ["83885.00", "0.015000"], ["83884.94", "0.268821"], ["83884.50", "0.030000"], ["83884.34", "0.223038"], ["83884.30", "0.217140"], ["83884.24", "0.018589"], ["83884.10", "0.460080"], ["83884.07", "0.008558"], ["83884.04", "0.005128"], ["83884.02", "0.005063"], ["83884.01", "0.004862"], ["83884.00", "0.042300"], ["83883.99", "0.005181"], ["83883.97", "0.008109"], ["83883.93", "0.008316"], ["83883.85", "0.005612"], ["83883.60", "0.026910"], ["83883.53", "0.259192"], ["83883.18", "0.021166"], ["83883.12", "0.076244"], ["83883.10", "0.007800"], ["83881.00", "0.217466"], ["83880.94", "0.012460"], ["83880.08", "0.073180"], ["83880.00", "0.002281"], ["83879.69", "0.000879"], ["83879.11", "0.056461"], ["83879.00", "0.000281"], ["83878.00", "0.000281"], ["83877.00", "0.000281"], ["83876.23", "0.006183"], ["83876.10", "0.207210"], ["83876.00", "0.000281"], ["83875.28", "0.000200"], ["83875.00", "0.000281"], ["83874.00", "0.000121"], ["83873.18", "0.017482"], ["83873.00", "0.000121"], ["83872.28", "0.209200"], ["83872.00", "0.000121"], ["83871.00", "0.000121"], ["83870.00", "0.000121"], ["83869.00", "0.000121"], ["83868.26", "0.007449"], ["83868.00", "0.000121"], ["83867.12", "0.001177"], ["83867.00", "0.000121"], ["83866.10", "0.001174"], ["83866.00", "0.000121"], ["83865.43", "0.008589"], ["83865.00", "0.000121"], ["83864.10", "0.007262"], ["83864.00", "0.000121"], ["83863.99", "0.007666"], ["83863.89", "0.007351"], ["83863.87", "0.209200"], ["83863.00", "0.000121"], ["83862.00", "0.000121"], ["83861.00", "0.000121"], ["83860.00", "0.000121"], ["83859.00", "0.000121"], ["83858.70", "0.000061"], ["83858.03", "0.003603"], ["83858.00", "0.000121"], ["83857.00", "0.000121"], ["83856.00", "0.000121"], ["83855.47", "0.209200"], ["83855.00", "0.000121"], ["83853.30", "5.173930"], ["83853.00", "0.000281"], ["83850.00", "0.002000"], ["83847.20", "0.000971"], ["83847.07", "0.209200"], ["83844.90", "5.446242"], ["83844.43", "0.000100"], ["83839.49", "0.071678"], ["83838.67", "0.209200"], ["83836.50", "3.903140"], ["83830.27", "0.209200"], ["83828.10", "5.355472"], ["83827.83", "0.000172"], ["83822.00", "0.057335"], ["83821.87", "0.209200"], ["83820.00", "0.007600"], ["83819.70", "4.810847"], ["83816.41", "0.071668"], ["83815.37", "0.000022"], ["83815.05", "0.001810"], ["83813.47", "0.209200"], ["83811.30", "4.720077"], ["83810.00", "0.000270"], ["83808.45", "0.001720"], ["83806.67", "0.003620"], ["83805.07", "0.209200"], ["83802.90", "5.083159"], ["83802.81", "0.000022"], ["83800.00", "0.000387"], ["83794.50", "3.993911"], ["83790.00", "0.002270"], ["83786.10", "5.537013"], ["83783.92", "0.125887"], ["83780.00", "0.000270"], ["83779.93", "0.000028"], ["83777.70", "4.629306"], ["83773.31", "0.000154"], ["83770.00", "0.000270"], ["83769.30", "4.084682"], ["83767.90", "0.001457"], ["83767.54", "0.027677"], ["83767.45", "0.012430"], ["83765.90", "0.304409"], ["83765.63", "0.012430"], ["83762.50", "0.000076"], ["83760.90", "5.627784"], ["83760.00", "0.002281"], ["83754.70", "0.000013"], ["83752.50", "4.992389"], ["83751.34", "0.000487"], ["83750.67", "0.000146"], ["83750.00", "0.000270"], ["83749.66", "0.000016"], ["83749.50", "0.000069"], ["83745.16", "0.000389"], ["83744.10", "4.901618"], ["83740.00", "0.000322"], ["83737.00", "0.000009"], ["83735.70", "4.266223"], ["83732.61", "0.005970"], ["83730.00", "0.002270"], ["83729.32", "0.000035"], ["83728.57", "0.000017"], ["83728.37", "0.001273"], ["83727.30", "4.447765"], ["83727.27", "0.000066"], ["83726.20", "0.000016"], ["83723.40", "0.000068"], ["83720.92", "0.011010"], ["83720.00", "0.002671"], ["83718.90", "4.356994"], ["83717.48", "0.005970"], ["83713.71", "0.000323"], ["83710.50", "4.175453"], ["83710.00", "0.000293"], ["83705.85", "0.000019"], ["83703.70", "0.000425"], ["83702.50", "0.000033"], ["83702.10", "4.538535"], ["83701.28", "0.000248"], ["83700.80", "0.311180"], ["83700.00", "0.004213"], ["83693.70", "5.264701"], ["83693.00", "0.001434"], ["83690.84", "0.000162"], ["83690.00", "0.000270"], ["83689.50", "0.000113"], ["83688.00", "0.001184"], ["83687.50", "0.006969"], ["83687.00", "0.000008"], ["83686.11", "0.000096"], ["83680.00", "0.000368"], ["83677.37", "0.000008"], ["83676.47", "0.000080"], ["83675.68", "0.000008"], ["83675.00", "0.000076"], ["83674.19", "0.000020"], ["83673.87", "0.000022"], ["83672.50", "0.000031"], ["83670.05", "0.000033"], ["83670.00", "0.002270"], ["83669.66", "0.000010"], ["83669.09", "0.000135"], ["83667.23", "0.012503"], ["83666.67", "0.000146"], ["83664.71", "0.000071"], ["83663.91", "0.000161"], ["83662.97", "0.000149"], ["83660.14", "0.000016"], ["83660.00", "0.000270"], ["83659.60", "0.000143"], ["83659.49", "0.000012"], ["83654.23", "0.000009"], ["83650.00", "0.000353"], ["83648.40", "0.001485"], ["83646.67", "0.000018"], ["83642.10", "0.305869"], ["83640.35", "0.000022"], ["83640.00", "0.003066"], ["83639.71", "0.000041"], ["83639.15", "0.000009"], ["83638.32", "0.000039"], ["83638.30", "0.000137"], ["83637.17", "0.000027"], ["83636.36", "0.041598"], ["83633.33", "0.000970"], ["83631.53", "0.000009"], ["83630.43", "0.000010"], ["83630.00", "0.000619"], ["83629.03", "0.000039"], ["83629.02", "0.000078"], ["83625.00", "0.000356"], ["83623.43", "0.000010"], ["83621.62", "0.000009"], ["83620.70", "0.000146"], ["83620.69", "0.000016"], ["83620.00", "0.000667"], ["83619.21", "0.000051"], ["83618.18", "0.000008"], ["83617.90", "0.000364"], ["83616.67", "0.000322"], ["83615.85", "0.000024"], ["83611.93", "0.000028"], ["83610.00", "0.002619"], ["83609.33", "1.599122"], ["83608.30", "0.493274"], ["83607.60", "0.000014"], ["83603.60", "0.000061"], ["83603.26", "0.000010"], ["83602.67", "0.000133"], ["83600.00", "0.015433"], ["83598.51", "0.000039"], ["83596.01", "0.000013"], ["83594.44", "0.000134"], ["83593.33", "0.000013"], ["83590.00", "0.000619"], ["83588.24", "0.042020"], ["83587.50", "0.000076"], ["83587.10", "0.000028"], ["83586.96", "0.002633"], ["83586.29", "0.000008"], ["83584.53", "0.000314"], ["83584.34", "0.000008"], ["83584.00", "0.000022"], ["83583.85", "0.000052"], ["83583.33", "0.000010"], ["83581.82", "0.000010"], ["83581.79", "0.007500"], ["83581.73", "0.000067"], ["83581.30", "0.001130"], ["83580.62", "0.007500"], ["83580.56", "0.000019"], ["83580.31", "0.000023"], ["83580.00", "0.002642"], ["83578.95", "0.000033"], ["83578.04", "0.000096"], ["83577.78", "0.000025"], ["83576.47", "0.000071"], ["83574.50", "0.000143"], ["83571.43", "0.000104"], ["83571.42", "0.000008"], ["83570.62", "0.000016"], ["83570.45", "0.000012"], ["83570.00", "0.000678"], ["83569.08", "0.000093"], ["83568.28", "0.000010"], ["83567.57", "0.000008"], ["83566.00", "0.000113"], ["83565.22", "0.000021"], ["83563.71", "0.000022"], ["83562.71", "0.000023"], ["83562.50", "0.000761"], ["83560.71", "0.001273"], ["83560.00", "0.000950"], ["83558.43", "0.000019"], ["83558.00", "0.000008"], ["83556.15", "0.000024"], ["83555.56", "0.000105"], ["83555.38", "0.000013"], ["83553.72", "0.000161"], ["83553.48", "0.011010"], ["83553.21", "0.000039"], ["83553.19", "0.000137"], ["83552.63", "0.000051"], ["83551.42", "0.000017"], ["83550.58", "0.000009"], ["83550.00", "0.002749"], ["83546.24", "0.000016"], ["83545.82", "0.000009"], ["83545.47", "0.001539"], ["83545.45", "0.000113"], ["83544.83", "0.000135"], ["83544.33", "0.000008"], ["83543.48", "0.000010"], ["83542.86", "0.000013"], ["83540.93", "0.000035"], ["83540.15", "0.000014"], ["83540.00", "0.000631"], ["83539.78", "0.000423"], ["83539.45", "0.000033"], ["83539.43", "0.000009"], ["83537.50", "0.000016"], ["83537.23", "0.000188"], ["83535.71", "0.000016"], ["83534.48", "0.000016"], ["83533.68", "0.000144"], ["83533.33", "0.000151"], ["83532.05", "0.000364"], ["83532.00", "0.002409"], ["83531.38", "0.000010"], ["83531.31", "0.000390"], ["83530.61", "0.000085"], ["83530.39", "0.000043"], ["83530.00", "0.000654"], ["83529.41", "0.000085"], ["83528.71", "0.000024"], ["83528.11", "0.000179"], ["83527.05", "0.000008"], ["83526.32", "0.000183"], ["83523.81", "0.000009"], ["83523.06", "0.000022"], ["83521.43", "0.000273"], ["83521.12", "0.000022"], ["83520.00", "0.003225"], ["83519.52", "0.000176"], ["83516.67", "0.000970"], ["83514.80", "0.000537"], ["83514.29", "0.000009"], ["83513.51", "0.000070"], ["83512.50", "0.006969"], ["83511.11", "0.000009"], ["83510.71", "0.000128"], ["83510.49", "0.000019"], ["83510.00", "0.000621"], ["83509.09", "0.000008"], ["83508.29", "0.000015"], ["83508.06", "0.000039"], ["83507.69", "0.000015"], ["83507.21", "0.000297"], ["83506.49", "0.000088"], ["83505.74", "0.000315"], ["83502.04", "0.000016"], ["83500.72", "0.000033"], ["83500.04", "0.000008"], ["83500.02", "0.000010"], ["83500.01", "0.000119"], ["83500.00", "0.015549"], ["83499.14", "0.000051"], ["83498.85", "0.000030"], ["83498.52", "0.000013"], ["83497.26", "0.000010"], ["83496.77", "0.000008"], ["83496.48", "0.000008"], ["83495.80", "0.041940"], ["83495.20", "0.000008"], ["83494.42", "0.000039"], ["83493.98", "0.000008"], ["83493.77", "0.000013"], ["83491.92", "0.000009"], ["83491.23", "0.000033"], ["83490.00", "0.002000"], ["83489.39", "0.000143"], ["83488.85", "0.000459"], ["83488.30", "0.000065"], ["83488.24", "0.000071"], ["83487.05", "0.000023"], ["83486.67", "0.000008"], ["83486.37", "0.000008"], ["83485.71", "0.000016"], ["83485.00", "0.000012"], ["83483.48", "0.000424"], ["83482.76", "0.000008"], ["83482.35", "0.000105"], ["83481.47", "0.000219"], ["83481.40", "0.000012"], ["83481.09", "0.000016"], ["83480.00", "0.000021"], ["83478.26", "0.016818"], ["83477.27", "0.000042"], ["83476.45", "0.000067"], ["83476.19", "0.000024"], ["83474.95", "0.000026"], ["83474.17", "0.000460"], ["83473.68", "0.000242"], ["83472.80", "0.000050"], ["83472.51", "0.000063"], ["83472.00", "0.000012"], ["83470.00", "0.000052"], ["83469.98", "0.000096"], ["83468.61", "0.000061"], ["83468.10", "0.000039"], ["83468.09", "0.000137"], ["83467.89", "0.000072"], ["83466.67", "0.002827"], ["83465.47", "0.000019"], ["83464.91", "0.000022"], ["83464.65", "0.000135"], ["83464.29", "0.000036"], ["83463.89", "0.000026"], ["83462.50", "0.000025"], ["83462.01", "0.000009"], ["83461.54", "0.000178"], ["83461.53", "0.000008"], ["83460.43", "0.000010"], ["83460.00", "0.002021"], ["83459.46", "0.000008"], ["83458.33", "0.000218"], ["83458.15", "0.000010"], ["83458.10", "0.000011"], ["83457.63", "0.000023"]], "checksum": 0, "ts": "1742577141735"}], "ts": 1742577141787, "record_time": 1742577142.029195, "EXCHANGE": "BITGET"}
{"action": "update", "arg": {"instType": "SPOT", "channel": "books", "instId": "BTCUSDT"}, "data": [{"asks": [["83918.03", "0.955611"], ["83918.06", "0.027822"], ["83918.91", "0"], ["83924.42", "0"], ["83941.34", "0.013838"], ["83959.30", "0.001012"], ["83961.30", "0.001529"], ["83963.30", "0.004023"], ["83965.30", "0.010587"], ["83967.30", "0.027862"], ["83969.30", "0.073320"], ["83971.30", "0.192947"], ["83973.30", "0.507756"], ["83975.30", "1.336200"], ["83977.30", "3.516316"], ["83979.30", "9.253463"], ["83979.40", "5.724270"], ["83981.30", "0"], ["83984.50", "0.465870"], ["83986.00", "0.092580"], ["83987.00", "0"], ["83987.70", "0.861540"], ["83991.30", "0"], ["84021.30", "5.627784"], ["84029.70", "5.083159"], ["84038.10", "5.355472"], ["84046.50", "5.173930"], ["84054.90", "5.264701"], ["84063.30", "4.538535"], ["84071.70", "4.629306"], ["84080.10", "4.266223"], ["84088.50", "4.901618"], ["84096.90", "5.537013"], ["84105.30", "3.993911"], ["84113.70", "4.356994"], ["84122.10", "4.175453"], ["84130.50", "4.992389"], ["84138.90", "4.720077"], ["84147.30", "4.447765"], ["84164.10", "4.810847"], ["84172.50", "4.084682"], ["84180.90", "5.446242"], ["84200.00", "0.011138"], ["84343.70", "0.000075"], ["84343.97", "0.000188"]], "bids": [["83918.02", "0.531734"], ["83911.30", "0.001122"], ["83909.30", "0.002951"], ["83907.30", "0.007766"], ["83905.30", "0.020436"], ["83904.93", "0"], ["83903.30", "0.053779"], ["83903.12", "0.242189"], ["83901.30", "0.141524"], ["83899.30", "0.372432"], ["83897.30", "0.980084"], ["83895.81", "0"], ["83895.30", "2.579169"], ["83888.00", "0.203220"], ["83884.30", "0.056220"], ["83884.10", "0.323760"], ["83879.69", "0"], ["83877.21", "0.000878"], ["83853.30", "5.264701"], ["83828.10", "4.629306"], ["83819.70", "4.266223"], ["83811.30", "4.901618"], ["83802.90", "4.992389"], ["83794.50", "4.810847"], ["83786.10", "5.083159"], ["83777.70", "4.084682"], ["83769.30", "5.627784"], ["83760.90", "5.355472"], ["83752.50", "4.538535"], ["83744.10", "4.356994"], ["83735.70", "5.173930"], ["83727.30", "4.720077"], ["83718.90", "3.993911"], ["83710.50", "4.447765"], ["83702.10", "4.175453"], ["83693.70", "5.537013"], ["83456.52", "0.000010"], ["83456.00", "0.000133"]], "checksum": 675565556, "ts": "1742577141944"}], "ts": 1742577141949, "record_time": 1742577142.14189, "EXCHANGE": "BITGET"}
{"action": "update", "arg": {"instType": "SPOT", "channel": "books", "instId": "BTCUSDT"}, "data": [{"asks": [["83924.41", "0.113528"], ["83963.60", "0.010000"], ["83981.20", "0.120000"], ["83983.50", "0.015000"], ["83985.10", "0.848100"], ["83986.00", "0.056850"], ["83988.30", "2.359770"], ["84021.30", "4.992389"], ["84029.70", "4.720077"], ["84038.10", "5.264701"], ["84046.50", "4.447765"], ["84054.90", "5.627784"], ["84063.30", "5.173930"], ["84071.70", "4.901618"], ["84080.10", "4.356994"], ["84088.50", "4.629306"], ["84096.90", "5.355472"], ["84105.30", "4.538535"], ["84113.70", "5.446242"], ["84122.10", "5.537013"], ["84130.50", "3.993911"], ["84138.90", "4.810847"], ["84147.30", "4.266223"], ["84155.70", "5.083159"], ["84164.10", "4.084682"], ["84172.50", "3.903140"], ["84180.90", "4.175453"], ["84343.02", "0"], ["84343.07", "0"], ["84343.70", "0"], ["84343.97", "0"]], "bids": [["83911.30", "0.001824"], ["83909.30", "0.004800"], ["83907.30", "0.012632"], ["83905.30", "0.033242"], ["83903.30", "0.087480"], ["83903.12", "0.146346"], ["83901.30", "0.230208"], ["83899.30", "0.605813"], ["83897.30", "1.594244"], ["83895.30", "4.195379"], ["83895.20", "0.285810"], ["83894.60", "2.360250"], ["83893.90", "0"], ["83891.30", "0.161130"], ["83890.60", "0.262230"], ["83888.50", "0.478530"], ["83888.00", "0.042300"], ["83882.50", "0.480000"], ["83853.30", "4.356994"], ["83844.90", "3.903140"], ["83836.50", "4.084682"], ["83828.10", "5.537013"], ["83819.70", "4.447765"], ["83811.30", "4.175453"], ["83802.90", "3.993911"], ["83794.50", "5.355472"], ["83786.10", "4.538535"], ["83777.70", "4.810847"], ["83769.30", "4.720077"], ["83760.90", "5.627784"], ["83752.50", "4.992389"], ["83744.10", "5.264701"], ["83735.70", "4.266223"], ["83727.30", "4.901618"], ["83718.90", "5.173930"], ["83710.50", "5.083159"], ["83702.10", "5.446242"], ["83693.70", "4.629306"], ["83456.52", "0"], ["83456.00", "0"]], "checksum": 42664604, "ts": "1742577142145"}], "ts": 1742577142149, "record_time": 1742577142.349656, "EXCHANGE": "BITGET"}
{"action": "update", "arg": {"instType": "SPOT", "channel": "books", "instId": "BTCUSDT"}, "data": [{"asks": [["83963.30", "0.004225"], ["83965.30", "0.011117"], ["83967.30", "0.029257"], ["83969.30", "0.076990"], ["83971.30", "0.202606"], ["83973.30", "0.533173"], ["83975.29", "0.420354"], ["83975.30", "1.403089"], ["83977.30", "3.692337"], ["83979.30", "9.716677"], ["83985.80", "2.359830"], ["83986.00", "0.084240"], ["83987.70", "0.258690"], ["83988.30", "0"], ["84021.30", "4.266223"], ["84029.70", "5.446242"], ["84038.10", "4.175453"], ["84046.50", "5.083159"], ["84054.90", "3.903140"], ["84063.30", "4.629306"], ["84071.70", "5.173930"], ["84080.10", "5.355472"], ["84088.50", "4.992389"], ["84096.90", "5.627784"], ["84105.30", "4.356994"], ["84113.70", "4.901618"], ["84122.10", "5.264701"], ["84130.50", "4.447765"], ["84147.30", "3.993911"], ["84155.70", "4.084682"], ["84164.10", "5.537013"], ["84172.50", "4.720077"], ["84180.90", "4.538535"], ["84273.06", "1.629741"], ["84280.90", "0"], ["84342.70", "0"]], "bids": [["83918.02", "0.517896"], ["83911.30", "0.001122"], ["83909.30", "0.002951"], ["83907.30", "0.007529"], ["83905.37", "0"], ["83905.30", "0.019813"], ["83903.30", "0.052141"], ["83903.12", "0.232513"], ["83901.30", "0.137213"], ["83899.30", "0.361087"], ["83897.30", "0.950229"], ["83895.30", "2.500603"], ["83893.00", "0.204856"], ["83876.10", "0"], ["83874.00", "0"], ["83873.00", "0"], ["83872.00", "0"], ["83871.00", "0"], ["83870.00", "0"], ["83869.00", "0"], ["83868.00", "0"], ["83867.00", "0"], ["83866.00", "0"], ["83865.00", "0"], ["83864.00", "0"], ["83863.00", "0"], ["83862.00", "0"], ["83861.00", "0"], ["83860.00", "0"], ["83859.00", "0"], ["83858.00", "0"], ["83857.00", "0"], ["83856.00", "0"], ["83855.00", "0.000281"], ["83853.30", "4.629306"], ["83853.00", "0.000160"], ["83844.90", "3.993911"], ["83836.50", "4.538535"], ["83828.10", "5.355472"], ["83819.70", "5.173930"], ["83811.30", "4.266223"], ["83802.90", "4.356994"], ["83794.50", "5.627784"], ["83786.10", "4.901618"], ["83769.30", "5.083159"], ["83760.90", "4.720077"], ["83752.50", "4.084682"], ["83744.10", "3.903140"], ["83735.70", "5.446242"], ["83727.30", "4.992389"], ["83718.90", "4.447765"], ["83710.50", "5.264701"], ["83702.10", "4.175453"], ["83693.70", "5.537013"], ["83609.33", "0"], ["83601.55", "1.688258"], ["83456.52", "0.000010"], ["83456.00", "0.000133"], ["83455.56", "0.000025"], ["83455.07", "0.000013"], ["83454.55", "0.000027"], ["83454.54", "0.001547"], ["83454.53", "0.000057"], ["83453.95", "0.000093"], ["83453.56", "0.000022"], ["83452.83", "0.000008"], ["83451.33", "0.000010"], ["83450.00", "0.005575"], ["83448.28", "0.000151"], ["83448.14", "0.000070"], ["83448.00", "0.000012"], ["83447.32", "0.000009"], ["83447.31", "0.000008"], ["83447.17", "0.000008"], ["83446.43", "0.000016"], ["83445.30", "0.000011"]], "checksum": -942299911, "ts": "1742577142367"}], "ts": 1742577142371, "record_time": 1742577142.565169, "EXCHANGE": "BITGET"}
{"action": "update", "arg": {"instType": "SPOT", "channel": "books", "instId": "BTCUSDT"}, "data": [{"asks": [["83918.03", "0.926011"], ["83958.63", "0"], ["83975.30", "1.403343"], ["83977.30", "3.693009"], ["83979.30", "9.718444"], ["83983.50", "0.030000"], ["83987.70", "0.907320"], ["84021.30", "5.537013"], ["84029.70", "5.264701"], ["84038.10", "4.720077"], ["84046.50", "5.355472"], ["84054.90", "4.901618"], ["84063.30", "5.627784"], ["84071.70", "3.903140"], ["84080.10", "4.538535"], ["84088.50", "4.266223"], ["84096.90", "4.356994"], ["84105.30", "4.629306"], ["84113.70", "4.175453"], ["84122.10", "4.447765"], ["84130.50", "5.173930"], ["84138.90", "4.992389"], ["84147.30", "4.810847"], ["84155.70", "5.083159"], ["84164.10", "4.084682"], ["84172.50", "3.993911"], ["84180.90", "5.446242"], ["84342.70", "0.000423"]], "bids": [["83906.18", "0.013838"], ["83903.12", "0.146346"], ["83896.23", "1.007350"], ["83853.30", "5.627784"], ["83844.90", "4.810847"], ["83828.10", "5.264701"], ["83819.70", "5.083159"], ["83811.30", "5.173930"], ["83802.90", "4.447765"], ["83794.50", "4.175453"], ["83786.10", "4.084682"], ["83777.70", "5.446242"], ["83769.30", "3.903140"], ["83760.90", "4.356994"], ["83752.50", "4.720077"], ["83744.10", "4.629306"], ["83735.70", "4.901618"], ["83727.30", "5.537013"], ["83718.90", "4.266223"], ["83710.50", "3.993911"], ["83702.10", "4.992389"], ["83693.70", "5.355472"], ["83445.30", "0"]], "checksum": 394315690, "ts": "1742577142568"}], "ts": 1742577142571, "record_time": 1742577142.767155, "EXCHANGE": "BITGET"}
{"action": "update", "arg": {"instType": "SPOT", "channel": "books", "instId": "BTCUSDT"}, "data": [{"asks": [["83918.03", "0.276320"], ["83918.06", "0"], ["83924.43", "0.036103"], ["83925.83", "0"], ["83937.24", "0"], ["83941.34", "0"], ["83942.92", "0.010995"], ["83944.98", "0.016429"], ["83945.21", "0"], ["83953.27", "0.013838"], ["83961.30", "0.001011"], ["83963.30", "0.001033"], ["83965.30", "0.001283"], ["83967.30", "0.003375"], ["83969.30", "0.008883"], ["83971.30", "0.023375"], ["83973.30", "0.061515"], ["83975.30", "0.161881"], ["83977.30", "0.426003"], ["83979.30", "1.121059"], ["83979.40", "1.977000"], ["83979.78", "0.001598"], ["83980.00", "0"], ["83980.07", "0"], ["83981.20", "0.066090"], ["83981.70", "0.001019"], ["83983.30", "0"], ["83983.80", "0.120180"], ["83984.20", "0"], ["83984.30", "1.197180"], ["83984.50", "0"], ["83984.80", "0"], ["83985.00", "0"], ["83985.10", "0"], ["83985.20", "0.449700"], ["83985.50", "0"], ["83985.80", "0"], ["83986.00", "0.056850"], ["83986.90", "0"], ["83987.10", "2.037480"], ["83987.60", "0"], ["83987.70", "0.703860"], ["83988.40", "0"], ["83989.10", "0"], ["83989.20", "0"], ["83989.30", "0"], ["83990.40", "0.012570"], ["83991.10", "0.090000"], ["83991.55", "0"], ["83991.90", "0.035730"], ["83992.00", "0.082350"], ["83992.10", "2.293440"], ["83992.30", "0.009000"], ["83992.40", "0.465870"], ["83993.50", "0.025170"], ["83995.10", "0.010710"], ["83995.40", "2.680320"], ["83995.50", "1.350000"], ["83995.60", "1.429500"], ["83995.80", "3.029820"], ["83995.90", "2.398620"], ["84006.40", "0"], ["84021.30", "4.084682"], ["84029.70", "4.720077"], ["84038.10", "5.537013"], ["84046.50", "5.446242"], ["84054.90", "4.538535"], ["84063.30", "3.903140"], ["84071.70", "4.266223"], ["84080.10", "5.627784"], ["84088.50", "4.629306"], ["84096.90", "5.083159"], ["84105.30", "4.992389"], ["84113.70", "4.901618"], ["84122.10", "4.356994"], ["84138.90", "3.993911"], ["84147.30", "5.264701"], ["84155.70", "5.355472"], ["84164.10", "4.175453"], ["84172.50", "4.810847"], ["84180.90", "4.447765"], ["84343.02", "0.000338"], ["84343.07", "0.000014"], ["84343.70", "0.000075"]], "bids": [["83918.02", "0.551734"], ["83913.30", "0.001234"], ["83911.30", "0.003247"], ["83911.24", "0.024669"], ["83909.30", "0.008544"], ["83907.30", "0.022485"], ["83906.34", "0.024948"], ["83906.18", "0"], ["83905.30", "0.059171"], ["83904.58", "0"], ["83903.30", "0.155712"], ["83901.30", "0.409769"], ["83899.30", "1.078341"], ["83897.30", "2.837738"], ["83896.22", "0"], ["83895.70", "0"], ["83895.47", "0.028875"], ["83895.30", "7.467733"], ["83895.25", "0.055637"], ["83895.20", "0.285990"], ["83894.60", "3.142650"], ["83894.40", "0.161310"], ["83894.00", "0.357600"], ["83893.40", "0.045000"], ["83891.66", "0"], ["83891.60", "0.071400"], ["83891.40", "0.357360"], ["83891.30", "0"], ["83890.60", "0"], ["83889.58", "0"], ["83889.30", "0"], ["83889.11", "0.372631"], ["83889.10", "0.646260"], ["83888.70", "0.269760"], ["83888.50", "0"], ["83888.30", "0.178680"], ["83887.03", "0"], ["83886.00", "0.098520"], ["83885.80", "0.089310"], ["83885.60", "0"], ["83885.20", "0"], ["83885.00", "0"], ["83884.50", "0"], ["83883.80", "0.071460"], ["83882.50", "0"], ["83866.10", "0"], ["83865.81", "0.001174"], ["83853.30", "5.355472"], ["83849.46", "0.071668"], ["83844.90", "4.175453"], ["83836.50", "4.810847"], ["83828.10", "4.356994"], ["83819.70", "4.538535"], ["83816.41", "0"], ["83815.05", "0"], ["83811.30", "4.084682"], ["83806.67", "0"], ["83802.90", "5.537013"], ["83794.50", "4.720077"], ["83786.10", "5.173930"], ["83777.70", "3.903140"], ["83769.30", "4.629306"], ["83760.90", "3.993911"], ["83752.50", "5.264701"], ["83744.10", "4.447765"], ["83735.70", "5.446242"], ["83727.30", "5.083159"], ["83718.90", "4.901618"], ["83710.50", "4.992389"], ["83702.10", "4.266223"], ["83693.70", "5.627784"], ["83445.30", "0.000011"], ["83445.16", "0.000054"], ["83444.44", "0.000105"], ["83444.38", "0.000025"], ["83444.27", "0.000028"]], "checksum": -235701507, "ts": "1742577142770"}], "ts": 1742577142775, "record_time": 1742577142.968721, "EXCHANGE": "BITGET"}
{"action": "update", "arg": {"instType": "SPOT", "channel": "books", "instId": "BTCUSDT"}, "data": [{"asks": [["83918.03", "0.276420"], ["83918.04", "0.000100"], ["83918.05", "0.000100"], ["83918.06", "0.000100"], ["83918.85", "0.114021"], ["83924.41", "0.073591"], ["83934.77", "0"], ["83935.13", "0"], ["83935.86", "0.013887"], ["83935.87", "0"], ["83936.15", "0"], ["83936.37", "0"], ["83937.95", "0"], ["83938.37", "0"], ["83939.08", "0"], ["83939.20", "0"], ["83939.33", "0"], ["83940.20", "0"], ["83940.41", "0.035971"], ["83940.45", "0.119905"], ["83941.51", "0.035972"], ["83942.08", "0.006357"], ["83942.26", "0.006357"], ["83943.79", "0.006356"], ["83944.00", "0.006357"], ["83944.93", "0.006357"], ["83945.01", "0.006357"], ["83945.31", "0.006357"], ["83946.31", "0.006357"], ["83955.25", "0.180495"], ["83965.30", "0.002321"], ["83967.30", "0.006108"], ["83969.30", "0.016074"], ["83971.30", "0.042300"], ["83973.30", "0.111317"], ["83975.29", "0"], ["83975.30", "0.292939"], ["83977.22", "0"], ["83977.30", "0.770893"], ["83978.36", "0.001598"], ["83979.30", "2.028665"], ["83979.40", "2.983830"], ["83979.50", "0.006060"], ["83979.70", "1.046100"], ["83979.90", "0.508710"], ["83980.80", "0.001029"], ["83981.20", "0"], ["83981.70", "0"], ["83982.60", "0.228420"], ["83983.60", "0.066600"], ["83984.00", "0.057600"], ["83984.30", "0.759180"], ["83986.00", "0.042480"], ["83987.70", "1.077060"], ["83988.90", "1.429500"], ["83990.00", "0.323610"], ["83993.00", "0.288000"], ["83993.10", "0.656100"], ["83993.80", "0.204000"], ["83995.10", "0"], ["83995.40", "0"], ["83995.50", "0"], ["83995.60", "0"], ["83995.80", "0"], ["83995.90", "0"], ["84021.30", "5.537013"], ["84022.12", "0.001810"], ["84029.70", "4.175453"], ["84030.52", "0.003620"], ["84038.10", "4.538535"], ["84046.50", "3.993911"], ["84054.90", "4.356994"], ["84063.30", "4.447765"], ["84071.70", "5.264701"], ["84080.10", "4.084682"], ["84088.50", "4.992389"], ["84096.90", "4.629306"], ["84105.30", "5.627784"], ["84113.70", "5.355472"], ["84122.10", "5.173930"], ["84130.50", "4.266223"], ["84138.90", "4.720077"], ["84147.30", "4.810847"], ["84155.70", "3.903140"], ["84164.10", "5.446242"], ["84172.50", "4.901618"], ["84180.90", "5.083159"], ["84340.46", "0"], ["84340.72", "0"], ["84341.00", "0"], ["84341.01", "0"], ["84342.11", "0"], ["84342.63", "0"], ["84342.70", "0"], ["84343.02", "0"], ["84343.07", "0"], ["84343.70", "0"]], "bids": [["83913.30", "0.001357"], ["83911.46", "0.114021"], ["83911.30", "0.003571"], ["83911.25", "0.014207"], ["83911.24", "0"], ["83911.00", "0"], ["83909.30", "0.009397"], ["83907.30", "0.024730"], ["83906.34", "0"], ["83905.73", "0.824226"], ["83905.30", "0.065080"], ["83903.30", "0.171261"], ["83901.30", "0.450687"], ["83900.13", "0.089673"], ["83899.33", "0.247543"], ["83899.30", "1.186018"], ["83898.11", "0.024669"], ["83897.87", "0.083637"], ["83897.30", "3.121102"], ["83897.26", "0.018273"], ["83896.77", "0.005950"], ["83896.50", "0.006572"], ["83895.94", "0.024948"], ["83895.62", "0.017124"], ["83895.49", "0.007347"], ["83895.30", "8.213425"], ["83894.90", "0.006060"], ["83894.70", "0.928980"], ["83894.60", "2.360430"], ["83894.49", "0"], ["83894.41", "0.009010"], ["83894.01", "0"], ["83894.00", "0.087660"], ["83893.78", "0.017376"], ["83892.77", "0.008290"], ["83892.23", "0"], ["83891.56", "0"], ["83890.88", "0"], ["83890.67", "0"], ["83890.30", "0.017850"], ["83889.90", "2.695440"], ["83889.82", "0"], ["83889.78", "0"], ["83889.10", "0.007955"], ["83888.90", "0.357390"], ["83888.56", "0"], ["83888.10", "0.120000"], ["83887.68", "0"], ["83887.10", "0.451380"], ["83886.70", "0.071460"], ["83886.66", "0"], ["83885.60", "0.120000"], ["83884.30", "0"], ["83884.10", "0"], ["83884.00", "0"], ["83883.80", "0"], ["83883.60", "0"], ["83883.10", "0"], ["83868.25", "0.001177"], ["83867.12", "0"], ["83854.00", "0.000121"], ["83853.30", "5.537013"], ["83853.00", "0"], ["83847.20", "0"], ["83844.90", "3.903140"], ["83844.20", "0.000971"], ["83836.50", "5.173930"], ["83834.03", "0.001810"], ["83828.10", "4.720077"], ["83825.64", "0.003620"], ["83819.70", "4.629306"], ["83811.30", "4.992389"], ["83802.90", "4.266223"], ["83794.50", "5.264701"], ["83786.10", "4.356994"], ["83777.70", "5.083159"], ["83769.30", "4.901618"], ["83760.90", "5.355472"], ["83752.50", "3.993911"], ["83744.10", "4.810847"], ["83735.70", "4.538535"], ["83727.30", "4.175453"], ["83718.90", "5.627784"], ["83710.50", "4.447765"], ["83702.10", "4.084682"], ["83693.70", "5.446242"], ["83446.43", "0"], ["83445.30", "0"], ["83445.16", "0"], ["83444.44", "0"], ["83444.38", "0"], ["83444.27", "0"]], "checksum": 582590647, "ts": "1742577142971"}], "ts": 1742577142977, "record_time": 1742577143.171858, "EXCHANGE": "BITGET"}
{"action": "update", "arg": {"instType": "SPOT", "channel": "books", "instId": "BTCUSDT"}, "data": [{"asks": [["83918.03", "0.541120"], ["83935.12", "0.006073"], ["83939.61", "0"], ["83945.12", "0.006357"], ["83965.30", "0.001017"], ["83967.30", "0.001449"], ["83969.30", "0.003813"], ["83971.30", "0.010033"], ["83973.30", "0.026403"], ["83975.30", "0.069483"], ["83977.30", "0.182849"], ["83979.30", "0.481182"], ["83979.40", "1.977270"], ["83979.70", "1.045920"], ["83980.80", "0"], ["83983.50", "0.015000"], ["83985.20", "0.449520"], ["83985.80", "0.098070"], ["83986.00", "0.042300"], ["83993.80", "0"], ["84021.30", "5.355472"], ["84029.70", "4.447765"], ["84038.10", "5.446242"], ["84046.50", "5.264701"], ["84054.90", "3.903140"], ["84063.30", "5.083159"], ["84071.70", "5.173930"], ["84080.10", "4.720077"], ["84088.50", "5.537013"], ["84096.90", "4.356994"], ["84105.30", "4.538535"], ["84113.70", "5.627784"], ["84122.10", "4.810847"], ["84130.50", "4.992389"], ["84138.90", "4.175453"], ["84147.30", "3.993911"], ["84155.70", "4.901618"], ["84164.10", "4.084682"], ["84172.50", "4.629306"], ["84180.90", "4.266223"], ["84340.46", "0.000143"]], "bids": [["83911.47", "0.042339"], ["83911.25", "0"], ["83903.30", "0.171416"], ["83901.30", "0.451095"], ["83899.30", "1.187093"], ["83897.30", "3.123929"], ["83895.30", "8.220865"], ["83889.90", "3.232410"], ["83889.80", "0.120000"], ["83889.10", "0"], ["83889.00", "0.190560"], ["83888.10", "0.360000"], ["83886.10", "0.536040"], ["83886.00", "0.056220"], ["83885.80", "0"], ["83885.60", "0"], ["83853.30", "4.538535"], ["83844.90", "5.627784"], ["83836.50", "4.175453"], ["83828.10", "3.903140"], ["83819.70", "4.810847"], ["83811.30", "5.083159"], ["83802.90", "5.173930"], ["83798.16", "0.125860"], ["83794.50", "5.537013"], ["83786.10", "5.446242"], ["83783.92", "0"], ["83777.70", "3.993911"], ["83769.30", "4.084682"], ["83760.90", "4.629306"], ["83752.50", "4.447765"], ["83744.10", "5.264701"], ["83735.70", "5.355472"], ["83727.30", "4.266223"], ["83718.90", "4.901618"], ["83710.50", "4.720077"], ["83702.10", "4.356994"], ["83693.70", "4.992389"], ["83446.43", "0.000016"]], "checksum": -297967575, "ts": "1742577143178"}], "ts": 1742577143181, "record_time": 1742577143.374577, "EXCHANGE": "BITGET"}
{"action": "update", "arg": {"instType": "SPOT", "channel": "books", "instId": "BTCUSDT"}, "data": [{"asks": [["83938.86", "0"], ["83939.39", "0"], ["83940.33", "0"], ["83943.01", "0"], ["83944.44", "0"], ["83944.63", "0.006357"], ["83945.23", "0.006357"], ["83946.13", "0.006357"], ["83949.18", "0.119850"], ["83950.79", "0.009989"], ["83962.10", "0.763039"], ["83967.30", "0.001102"], ["83969.30", "0.002901"], ["83971.30", "0.007634"], ["83973.30", "0.020090"], ["83975.30", "0.052868"], ["83977.30", "0.139127"], ["83979.30", "0.366122"], ["83979.40", "1.977870"], ["83979.70", "0"], ["83979.90", "0"], ["83980.00", "0.001048"], ["83980.80", "0.001019"], ["83981.20", "0.001029"], ["83983.50", "0.037800"], ["83985.80", "0"], ["83993.80", "0.204000"], ["84029.70", "3.903140"], ["84038.10", "3.993911"], ["84046.50", "5.083159"], ["84054.90", "4.992389"], ["84063.30", "4.901618"], ["84071.70", "4.810847"], ["84080.10", "4.629306"], ["84088.50", "5.173930"], ["84096.90", "4.266223"], ["84105.30", "5.627784"], ["84113.70", "4.175453"], ["84122.10", "5.264701"], ["84130.50", "4.538535"], ["84138.90", "5.537013"], ["84147.30", "4.447765"], ["84155.70", "4.720077"], ["84164.10", "5.446242"], ["84172.50", "4.084682"], ["84180.90", "4.356994"], ["84340.00", "0"], ["84340.46", "0"]], "bids": [["83913.30", "0.001566"], ["83911.30", "0.004121"], ["83909.30", "0.010845"], ["83907.30", "0.028539"], ["83905.77", "0.384280"], ["83905.30", "0.075347"], ["83903.30", "0.198283"], ["83901.30", "0.521798"], ["83899.30", "1.373152"], ["83897.30", "3.613557"], ["83896.12", "0.007141"], ["83895.39", "0.017114"], ["83895.30", "9.509362"], ["83891.11", "0.278644"], ["83890.36", "0"], ["83889.55", "0"], ["83889.53", "0.021166"], ["83889.11", "0"], ["83888.81", "0"], ["83886.10", "1.160880"], ["83886.00", "0"], ["83884.94", "0"], ["83884.24", "0"], ["83883.18", "0"], ["83853.30", "4.810847"], ["83844.90", "3.903140"], ["83836.50", "4.447765"], ["83828.10", "4.992389"], ["83819.70", "5.083159"], ["83811.30", "5.173930"], ["83802.90", "4.720077"], ["83794.50", "5.264701"], ["83786.10", "4.538535"], ["83777.70", "4.901618"], ["83769.30", "3.993911"], ["83760.90", "4.084682"], ["83752.50", "4.175453"], ["83744.10", "5.446242"], ["83718.90", "5.627784"], ["83710.50", "4.629306"], ["83702.10", "5.537013"], ["83693.70", "4.356994"], ["83580.62", "0"], ["83445.30", "0.000011"], ["83445.16", "0.000054"], ["83444.44", "0.000105"], ["83444.38", "0.000025"], ["83444.27", "0.000028"], ["83443.53", "0.000161"]], "checksum": 533226403, "ts": "1742577143377"}], "ts": 1742577143381, "record_time": 1742577143.57435, "EXCHANGE": "BITGET"}
{"action": "update", "arg": {"instType": "SPOT", "channel": "books", "instId": "BTCUSDT"}, "data": [{"asks": [["83918.03", "0.547020"], ["83918.07", "0"], ["83918.18", "0.092744"], ["83959.30", "0"], ["83959.40", "0.001007"], ["83961.30", "0"], ["83961.40", "0.001004"], ["83963.30", "0"], ["83963.40", "0.001012"], ["83965.30", "0"], ["83965.40", "0.001403"], ["83967.30", "0"], ["83967.40", "0.003692"], ["83969.30", "0"], ["83969.40", "0.009715"], ["83971.30", "0"], ["83971.40", "0.025566"], ["83973.30", "0"], ["83973.40", "0.067279"], ["83975.30", "0"], ["83975.40", "0.177050"], ["83977.30", "0"], ["83977.40", "0.465923"], ["83979.30", "0"], ["83979.40", "1.226112"], ["83979.50", "0"], ["83979.60", "0.006060"], ["83980.80", "0"], ["83982.00", "0"], ["83982.60", "0.319500"], ["83984.30", "0.222900"], ["83985.20", "1.430520"], ["83986.00", "0.042480"], ["83987.10", "0.250800"], ["83987.70", "1.077240"], ["83989.00", "0.001443"], ["83994.60", "0.432000"], ["83994.70", "0.192180"], ["83995.10", "0.010710"], ["83995.40", "2.680320"], ["84021.30", "0"], ["84021.40", "4.901611"], ["84029.70", "0"], ["84029.80", "4.356988"], ["84038.10", "0"], ["84038.20", "5.537005"], ["84046.50", "0"], ["84046.60", "4.084676"], ["84054.90", "0"], ["84055.00", "5.083152"], ["84063.30", "0"], ["84063.40", "4.447758"], ["84071.70", "0"], ["84071.80", "4.175447"], ["84080.10", "0"], ["84080.20", "4.810841"], ["84088.50", "0"], ["84088.60", "4.720070"], ["84096.90", "0"], ["84097.00", "3.993905"], ["84105.30", "0"], ["84105.40", "5.264693"], ["84113.70", "0"], ["84113.80", "4.992382"], ["84122.10", "0.000042"], ["84122.20", "4.538529"], ["84130.50", "0"], ["84130.60", "5.627776"], ["84138.90", "0"], ["84139.00", "5.355464"], ["84147.30", "0"], ["84147.40", "5.173923"], ["84155.70", "0"], ["84155.80", "4.629299"], ["84164.10", "0"], ["84164.20", "4.266217"], ["84172.50", "0"], ["84172.60", "3.903135"], ["84180.90", "0"], ["84181.00", "5.446234"], ["84339.50", "0"], ["84339.62", "0"]], "bids": [["83918.02", "0.551388"], ["83915.40", "0.001311"], ["83915.30", "0"], ["83913.40", "0.002140"], ["83913.30", "0"], ["83911.40", "0.005631"], ["83911.30", "0"], ["83909.40", "0.014818"], ["83909.30", "0"], ["83907.40", "0.038996"], ["83907.30", "0"], ["83905.40", "0.102619"], ["83905.30", "0"], ["83903.40", "0.270050"], ["83903.30", "0"], ["83903.12", "0.651357"], ["83901.40", "0.710659"], ["83901.30", "0"], ["83899.40", "1.870156"], ["83899.30", "0"], ["83897.40", "4.921463"], ["83897.30", "0"], ["83896.83", "0.018589"], ["83895.40", "12.951217"], ["83895.30", "14.710620"], ["83895.20", "0.285360"], ["83895.10", "0"], ["83895.00", "0.006270"], ["83894.90", "0"], ["83894.70", "0"], ["83894.40", "0.161100"], ["83893.40", "0.045180"], ["83892.71", "0"], ["83889.90", "1.802910"], ["83887.40", "0.017850"], ["83886.00", "0.098520"], ["83885.80", "0.089310"], ["83874.00", "0.000160"], ["83873.00", "0.000160"], ["83872.00", "0.000160"], ["83871.00", "0.000160"], ["83870.00", "0.000160"], ["83869.00", "0.000160"], ["83853.40", "5.264693"], ["83853.30", "0"], ["83845.00", "5.446234"], ["83844.90", "0"], ["83836.60", "5.627776"], ["83836.50", "0"], ["83828.20", "4.901611"], ["83828.10", "0"], ["83819.80", "4.992382"], ["83819.70", "0"], ["83811.40", "4.084676"], ["83811.30", "0"], ["83803.00", "5.355464"], ["83802.90", "0"], ["83794.60", "4.175447"], ["83794.50", "0"], ["83786.20", "4.720070"], ["83786.10", "0"], ["83777.80", "5.173923"], ["83777.70", "0"], ["83769.40", "4.629299"], ["83769.30", "0"], ["83761.00", "3.993905"], ["83760.90", "0"], ["83752.60", "3.903135"], ["83752.50", "0"], ["83744.20", "4.266217"], ["83744.10", "0"], ["83735.80", "5.537005"], ["83735.70", "0"], ["83727.40", "4.356988"], ["83727.30", "0"], ["83719.00", "5.083152"], ["83718.90", "0"], ["83710.60", "4.810841"], ["83710.50", "0"], ["83702.20", "4.538529"], ["83702.10", "0"], ["83693.80", "4.447758"], ["83693.70", "0"], ["83446.43", "0"], ["83445.30", "0"], ["83445.16", "0"], ["83444.44", "0"], ["83444.38", "0"], ["83444.27", "0"], ["83443.53", "0"]], "checksum": -1600444507, "ts": "1742577143581"}], "ts": 1742577143583, "record_time": 1742577143.777327, "EXCHANGE": "BITGET"}
{"action": "update", "arg": {"instType": "SPOT", "channel": "books", "instId": "BTCUSDT"}, "data": [{"asks": [["83918.85", "0"], ["83922.62", "0.114020"], ["83936.68", "0"], ["83937.42", "0"], ["83937.71", "0"], ["83939.23", "0"], ["83939.25", "0"], ["83941.54", "0"], ["83941.67", "0"], ["83942.70", "0.006357"], ["83943.34", "0.006357"], ["83943.70", "0.006357"], ["83944.04", "0"], ["83944.43", "0"], ["83945.90", "0.119901"], ["83946.09", "0.016429"], ["83946.22", "0"], ["83947.72", "0.006357"], ["83948.24", "0.009990"], ["83950.54", "0.119858"], ["83950.69", "0.015895"], ["83952.87", "0.006356"], ["83979.40", "1.226298"], ["83979.50", "0.001170"], ["83984.00", "0.484200"], ["83984.10", "0.015180"], ["83984.30", "0.489480"], ["83985.20", "1.430340"], ["83986.00", "0.042300"], ["83987.10", "0.250620"], ["83987.70", "1.077060"], ["83994.70", "0"], ["83995.10", "0"], ["83995.40", "0"], ["84029.80", "5.173923"], ["84038.20", "4.720070"], ["84046.60", "5.355464"], ["84055.00", "4.084676"], ["84063.40", "3.903135"], ["84071.80", "4.810841"], ["84080.20", "4.175447"], ["84088.60", "5.537005"], ["84097.00", "4.356988"], ["84105.40", "3.993905"], ["84113.80", "5.446234"], ["84130.60", "4.992382"], ["84139.00", "5.264693"], ["84147.40", "4.447758"], ["84155.80", "5.083152"], ["84172.60", "5.627776"], ["84181.00", "4.629299"], ["84339.50", "0.000323"]], "bids": [["83915.67", "0.114020"], ["83915.40", "0.001442"], ["83913.40", "0.002353"], ["83911.46", "0"], ["83911.40", "0.006191"], ["83909.40", "0.016294"], ["83907.40", "0.042877"], ["83905.40", "0.112836"], ["83903.40", "0.296937"], ["83901.40", "0.781411"], ["83899.40", "2.056346"], ["83898.22", "0.017826"], ["83897.40", "5.411438"], ["83897.21", "0.016433"], ["83897.19", "0.015750"], ["83895.40", "14.240625"], ["83895.30", "9.385710"], ["83895.20", "0.285150"], ["83895.00", "0.006060"], ["83894.90", "0.025199"], ["83894.71", "0.225049"], ["83893.17", "0.012674"], ["83892.21", "0"], ["83892.01", "0.018549"], ["83891.27", "0"], ["83891.22", "0"], ["83890.45", "0.223055"], ["83888.06", "0"], ["83888.04", "0"], ["83887.70", "0.553890"], ["83887.60", "0.071460"], ["83887.58", "0.012460"], ["83887.12", "0"], ["83886.40", "0.375210"], ["83886.10", "0"], ["83886.00", "0"], ["83885.80", "0"], ["83885.32", "0"], ["83884.34", "0"], ["83883.12", "0"], ["83880.94", "0"], ["83853.40", "4.084676"], ["83845.00", "4.447758"], ["83836.60", "5.173923"], ["83828.20", "4.720070"], ["83811.40", "4.266217"], ["83803.00", "5.083152"], ["83794.60", "5.355464"], ["83786.20", "5.264693"], ["83777.80", "5.537005"], ["83769.40", "4.538529"], ["83761.00", "4.175447"], ["83744.20", "5.446234"], ["83735.80", "5.627776"], ["83727.40", "3.993905"], ["83719.00", "4.810841"], ["83710.60", "4.629299"], ["83702.20", "4.356988"], ["83693.80", "4.901611"], ["83446.43", "0.000016"]], "checksum": -1886184610, "ts": "1742577143786"}], "ts": 1742577143790, "record_time": 1742577143.983446, "EXCHANGE": "BITGET"}
{"action": "update", "arg": {"instType": "SPOT", "channel": "books", "instId": "BTCUSDT"}, "data": [{"asks": [["83935.12", "0.004166"], ["83987.70", "1.513770"], ["83987.80", "0"], ["83990.70", "2.359710"], ["83991.90", "0"], ["83992.00", "0.098670"], ["84021.40", "3.993905"], ["84029.80", "5.627776"], ["84038.20", "4.447758"], ["84046.60", "4.901611"], ["84055.00", "4.175447"], ["84063.40", "4.810841"], ["84071.80", "5.173923"], ["84080.20", "5.446234"], ["84088.60", "5.264693"], ["84105.40", "4.720070"], ["84113.80", "4.538529"], ["84122.20", "5.355464"], ["84130.60", "4.266217"], ["84139.00", "5.083152"], ["84147.40", "4.084676"], ["84155.80", "5.537005"], ["84164.20", "3.903135"], ["84172.60", "4.629299"], ["84181.00", "4.992382"], ["84339.62", "0.000051"]], "bids": [["83918.02", "0.561388"], ["83911.47", "0.010988"], ["83911.40", "0.006320"], ["83909.40", "0.016633"], ["83907.40", "0.043771"], ["83905.40", "0.115187"], ["83903.40", "0.303123"], ["83901.40", "0.797691"], ["83899.40", "2.099188"], ["83897.40", "5.524179"], ["83895.40", "14.537314"], ["83895.30", "6.344670"], ["83853.40", "5.446234"], ["83845.00", "3.993905"], ["83836.60", "4.175447"], ["83828.20", "4.084676"], ["83819.80", "4.629299"], ["83811.40", "4.901611"], ["83803.00", "3.903135"], ["83786.20", "4.538529"], ["83777.80", "4.356988"], ["83769.40", "4.447758"], ["83761.00", "5.627776"], ["83752.60", "5.537005"], ["83744.20", "5.264693"], ["83735.80", "4.720070"], ["83727.40", "4.810841"], ["83719.00", "4.266217"], ["83710.60", "5.083152"], ["83702.20", "4.992382"], ["83693.80", "5.173923"]], "checksum": -1111727947, "ts": "1742577143993"}], "ts": 1742577143996, "record_time": 1742577144.18903, "EXCHANGE": "BITGET"}
{"action": "update", "arg": {"instType": "SPOT", "channel": "books", "instId": "BTCUSDT"}, "data": [{"asks": [["83941.56", "0"], ["83948.31", "0.010993"], ["83963.60", "0"], ["83967.40", "0.003691"], ["83969.40", "0.009714"], ["83971.40", "0.025564"], ["83973.40", "0.067273"], ["83975.40", "0.177035"], ["83977.40", "0.465880"], ["83979.40", "1.226000"], ["83979.60", "0.006300"], ["83980.00", "0"], ["83982.00", "0.726390"], ["83982.60", "0.228420"], ["83983.60", "0.066420"], ["83983.80", "0"], ["83984.00", "0.706080"], ["83984.20", "0.970530"], ["83984.29", "0.002501"], ["83984.30", "0"], ["83985.20", "0.449520"], ["83988.50", "2.359770"], ["83990.00", "0.425040"], ["83990.70", "0"], ["83992.00", "0.108300"], ["83992.60", "0.073230"], ["83993.80", "0"], ["83994.60", "0"], ["84021.40", "4.901611"], ["84029.80", "4.992382"], ["84038.20", "4.356988"], ["84046.60", "4.266217"], ["84055.00", "4.084676"], ["84063.40", "3.903135"], ["84071.80", "4.810841"], ["84080.20", "5.627776"], ["84088.60", "5.355464"], ["84097.00", "5.083152"], ["84105.40", "3.993905"], ["84113.80", "5.537005"], ["84122.20", "5.264693"], ["84130.60", "5.446234"], ["84139.00", "4.175447"], ["84147.40", "4.720070"], ["84155.80", "4.447758"], ["84164.20", "4.629299"], ["84172.60", "4.538529"], ["84181.00", "5.173923"], ["84340.00", "0.018287"], ["84340.46", "0.000143"]], "bids": [["83907.40", "0.043899"], ["83905.40", "0.115594"], ["83903.40", "0.304196"], ["83901.40", "0.800515"], ["83899.40", "2.106617"], ["83897.40", "5.543729"], ["83895.40", "14.588761"], ["83895.30", "6.282810"], ["83895.20", "0.001024"], ["83894.40", "0.161310"], ["83893.76", "0.051846"], ["83890.33", "0.076244"], ["83887.07", "0"], ["83855.00", "0"], ["83853.40", "5.083152"], ["83845.00", "3.903135"], ["83836.60", "4.356988"], ["83828.20", "4.992382"], ["83819.80", "5.537005"], ["83811.40", "5.264693"], ["83803.00", "4.629299"], ["83794.60", "4.720070"], ["83786.20", "4.266217"], ["83777.80", "4.084676"], ["83769.40", "4.810841"], ["83761.00", "4.175447"], ["83752.60", "5.446234"], ["83744.20", "4.447758"], ["83735.80", "5.627776"], ["83727.40", "4.901611"], ["83719.00", "4.538529"], ["83710.60", "3.993905"], ["83702.20", "5.173923"], ["83693.80", "5.355464"]], "checksum": 1407935221, "ts": "1742577144194"}], "ts": 1742577144197, "record_time": 1742577144.390039, "EXCHANGE": "BITGET"}
{"action": "update", "arg": {"instType": "SPOT", "channel": "books", "instId": "BTCUSDT"}, "data": [{"asks": [["83922.61", "0.034206"], ["83971.40", "0.025759"], ["83973.40", "0.067788"], ["83975.40", "0.178388"], ["83977.40", "0.469442"], ["83979.40", "1.235375"], ["83980.00", "0.001008"], ["83983.50", "0.015000"], ["83986.60", "0.022770"], ["83993.50", "0"], ["84021.40", "4.084676"], ["84029.80", "5.537005"], ["84038.20", "5.264693"], ["84055.00", "4.538529"], ["84063.40", "4.810841"], ["84071.80", "4.175447"], ["84080.20", "4.356988"], ["84088.60", "4.447758"], ["84105.40", "4.720070"], ["84113.80", "5.355464"], ["84122.20", "4.901611"], ["84130.60", "4.629299"], ["84139.00", "4.992382"], ["84147.40", "3.903135"], ["84155.80", "5.627776"], ["84164.20", "5.173923"], ["84172.60", "3.993905"], ["84181.00", "5.446234"], ["84340.00", "0"], ["84340.46", "0"]], "bids": [["83903.40", "0.304401"], ["83901.40", "0.801056"], ["83899.40", "2.108041"], ["83897.40", "5.547475"], ["83895.40", "14.598619"], ["83853.40", "5.627776"], ["83845.00", "5.264693"], ["83836.60", "4.084676"], ["83828.20", "4.901611"], ["83819.80", "5.446234"], ["83811.40", "3.993905"], ["83803.00", "4.266217"], ["83794.60", "3.903135"], ["83786.20", "4.629299"], ["83777.80", "5.355464"], ["83769.40", "4.175447"], ["83761.00", "4.356988"], ["83752.60", "4.810841"], ["83744.20", "4.992382"], ["83735.80", "5.173923"], ["83727.40", "5.083152"], ["83710.60", "4.720070"], ["83702.20", "5.537005"], ["83693.80", "4.447758"]], "checksum": 1274099610, "ts": "1742577144394"}], "ts": 1742577144396, "record_time": 1742577144.589686, "EXCHANGE": "BITGET"}
{"action": "update", "arg": {"instType": "SPOT", "channel": "books", "instId": "BTCUSDT"}, "data": [{"asks": [["83918.17", "0.092744"], ["83918.18", "0"], ["83922.61", "0"], ["83955.24", "0.054149"], ["83979.60", "0.006060"], ["83982.00", "0"], ["83982.60", "0.319500"], ["83983.50", "0"], ["83984.00", "0.289110"], ["83984.20", "0"], ["83988.50", "0"], ["83990.00", "0.323610"], ["83990.50", "2.359710"], ["83992.00", "0.082350"], ["83992.60", "0"], ["83993.50", "0.025170"], ["83993.80", "0.204000"], ["83994.60", "0.432000"], ["83994.70", "0.192180"], ["83995.00", "1.072110"], ["84021.40", "4.447758"], ["84029.80", "5.264693"], ["84038.20", "4.720070"], ["84046.60", "4.356988"], ["84055.00", "4.810841"], ["84063.40", "4.992382"], ["84071.80", "5.083152"], ["84080.20", "5.173923"], ["84088.60", "5.537005"], ["84097.00", "4.175447"], ["84105.40", "5.627776"], ["84113.80", "3.993905"], ["84122.20", "4.629299"], ["84130.60", "4.538529"], ["84139.00", "5.446234"], ["84147.40", "4.084676"], ["84155.80", "4.901611"], ["84164.20", "5.355464"], ["84172.60", "4.266217"], ["84181.00", "3.903135"], ["84339.62", "0"]], "bids": [["83909.40", "0.016746"], ["83907.40", "0.044235"], ["83905.40", "0.116406"], ["83903.40", "0.306331"], ["83901.40", "0.806136"], ["83899.40", "2.121411"], ["83897.40", "5.582660"], ["83895.40", "14.691210"], ["83888.00", "0.057300"], ["83853.40", "4.356988"], ["83845.00", "4.538529"], ["83836.60", "4.992382"], ["83828.20", "3.903135"], ["83819.80", "5.264693"], ["83811.40", "4.175447"], ["83803.00", "4.084676"], ["83794.60", "5.083152"], ["83786.20", "3.993905"], ["83777.80", "4.901611"], ["83769.40", "4.266217"], ["83761.00", "5.627776"], ["83752.60", "5.537005"], ["83744.20", "4.447758"], ["83735.80", "4.810841"], ["83727.40", "5.355464"], ["83719.00", "4.720070"], ["83710.60", "5.173923"], ["83702.20", "5.446234"], ["83693.80", "4.629299"]], "checksum": -1711773789, "ts": "1742577144596"}], "ts": 1742577144598, "record_time": 1742577144.791402, "EXCHANGE": "BITGET"}
{"action": "update", "arg": {"instType": "SPOT", "channel": "books", "instId": "BTCUSDT"}, "data": [{"asks": [["83922.52", "0.114014"], ["83922.62", "0"], ["83924.41", "0"], ["83977.40", "0.469513"], ["83979.40", "1.235561"], ["83982.60", "0.229020"], ["83983.10", "0.072150"], ["83984.00", "0.042300"], ["83985.70", "0.480990"], ["83990.00", "0"], ["83992.10", "2.396400"], ["84021.40", "4.629299"], ["84029.80", "4.266217"], ["84038.20", "4.992382"], ["84046.60", "5.537005"], ["84055.00", "5.083152"], ["84063.40", "4.901611"], ["84071.80", "4.810841"], ["84080.20", "4.175447"], ["84088.60", "4.356988"], ["84097.00", "3.903135"], ["84113.80", "5.264693"], ["84122.20", "5.355464"], ["84130.60", "4.084676"], ["84139.00", "4.720070"], ["84147.40", "3.993905"], ["84155.80", "4.447758"], ["84164.20", "4.538529"], ["84172.60", "5.446234"], ["84181.00", "5.173923"], ["84339.62", "0.000051"]], "bids": [["83903.40", "0.306526"], ["83903.12", "0.635367"], ["83901.40", "0.806646"], ["83899.40", "2.122754"], ["83897.40", "5.586194"], ["83896.23", "0.557900"], ["83895.40", "14.700640"], ["83893.90", "0.127710"], ["83893.40", "0.045000"], ["83886.40", "0"], ["83868.00", "0.000160"], ["83853.40", "5.537005"], ["83845.00", "4.175447"], ["83836.60", "4.629299"], ["83819.80", "5.355464"], ["83811.40", "4.538529"], ["83803.00", "4.901611"], ["83794.60", "4.266217"], ["83786.20", "4.447758"], ["83777.80", "5.264693"], ["83769.40", "5.627776"], ["83761.00", "3.993905"], ["83752.60", "4.356988"], ["83744.20", "5.083152"], ["83735.80", "5.173923"], ["83727.40", "4.720070"], ["83719.00", "4.084676"], ["83710.60", "4.810841"], ["83693.80", "4.992382"], ["83446.43", "0"]], "checksum": -1200340324, "ts": "1742577144805"}], "ts": 1742577144809, "record_time": 1742577145.001878, "EXCHANGE": "BITGET"}
{"action": "update", "arg": {"instType": "SPOT", "channel": "books", "instId": "BTCUSDT"}, "data": [{"asks": [["83928.38", "0.062760"], ["83955.25", "0"], ["83982.60", "0.319620"], ["83983.10", "0.071730"], ["83983.80", "0.851460"], ["83985.70", "0"], ["83986.00", "0.832920"], ["83988.10", "2.359770"], ["83988.90", "0"], ["83990.50", "0"], ["83992.00", "1.512240"], ["83994.00", "0.323580"], ["83994.70", "0"], ["83995.00", "0"], ["84029.80", "4.720070"], ["84038.20", "5.264693"], ["84046.60", "4.447758"], ["84055.00", "4.992382"], ["84063.40", "5.173923"], ["84071.80", "5.446234"], ["84080.20", "3.993905"], ["84088.60", "4.538529"], ["84097.00", "4.356988"], ["84105.40", "4.901611"], ["84113.80", "5.083152"], ["84122.20", "4.084676"], ["84130.60", "5.627776"], ["84139.00", "5.537005"], ["84147.40", "3.903135"], ["84155.80", "4.810841"], ["84164.20", "5.355464"], ["84172.60", "4.175447"], ["84181.00", "4.266217"], ["84340.00", "0.018287"], ["84340.46", "0.000143"]], "bids": [["83903.12", "0.900564"], ["83874.00", "0.000281"], ["83873.00", "0.000281"], ["83872.00", "0.000281"], ["83871.00", "0.000281"], ["83870.00", "0.000281"], ["83869.00", "0.000281"], ["83853.40", "4.720070"], ["83845.00", "4.992382"], ["83836.60", "3.903135"], ["83828.20", "5.627776"], ["83819.80", "4.901611"], ["83811.40", "4.810841"], ["83803.00", "4.629299"], ["83794.60", "5.355464"], ["83786.20", "4.266217"], ["83769.40", "4.084676"], ["83752.60", "5.537005"], ["83735.80", "4.175447"], ["83727.40", "4.356988"], ["83719.00", "4.447758"], ["83710.60", "5.173923"], ["83693.80", "4.538529"]], "checksum": -1521729923, "ts": "1742577145015"}], "ts": 1742577145019, "record_time": 1742577145.216727, "EXCHANGE": "BITGET"}
{"action": "update", "arg": {"instType": "SPOT", "channel": "books", "instId": "BTCUSDT"}, "data": [{"asks": [["83955.24", "0"], ["83958.66", "0.179640"], ["83979.39", "0.013332"], ["83983.80", "1.118250"], ["83987.70", "1.090140"], ["83992.00", "1.521780"], ["83994.70", "0.192180"], ["84021.40", "4.084676"], ["84029.80", "4.992382"], ["84038.20", "4.447758"], ["84046.60", "4.720070"], ["84055.00", "5.537005"], ["84063.40", "5.264693"], ["84071.80", "4.266217"], ["84080.20", "4.538529"], ["84088.60", "4.356988"], ["84097.00", "4.629299"], ["84113.80", "5.355464"], ["84122.20", "3.993905"], ["84130.60", "4.175447"], ["84139.00", "4.810841"], ["84147.40", "5.446234"], ["84155.80", "3.903135"], ["84164.20", "5.173923"], ["84172.60", "5.627776"], ["84181.00", "5.083152"], ["84340.00", "0"], ["84340.46", "0"]], "bids": [["83896.23", "0.710115"], ["83853.40", "5.446234"], ["83845.00", "4.266217"], ["83836.60", "5.264693"], ["83828.20", "4.356988"], ["83819.80", "5.627776"], ["83811.40", "4.629299"], ["83803.00", "4.810841"], ["83794.60", "5.173923"], ["83786.20", "5.083152"], ["83777.80", "4.175447"], ["83769.40", "4.538529"], ["83761.00", "4.901611"], ["83752.60", "4.084676"], ["83744.20", "4.720070"], ["83735.80", "5.537005"], ["83727.40", "4.447758"], ["83719.00", "3.993905"], ["83710.60", "5.355464"], ["83702.20", "3.903135"], ["83693.80", "4.992382"]], "checksum": -1521729923, "ts": "1742577145220"}], "ts": 1742577145222, "record_time": 1742577145.42094, "EXCHANGE": "BITGET"}
{"action": "update", "arg": {"instType": "SPOT", "channel": "books", "instId": "BTCUSDT"}, "data": [{"asks": [["83975.40", "0.178238"], ["83977.40", "0.469047"], ["83979.40", "1.234333"], ["83992.00", "1.512240"], ["83995.00", "1.072110"], ["84021.40", "3.903135"], ["84029.80", "5.264693"], ["84038.20", "5.355464"], ["84046.60", "4.175447"], ["84055.00", "5.446234"], ["84063.40", "4.084676"], ["84071.80", "4.356988"], ["84080.20", "4.992382"], ["84088.60", "4.629299"], ["84097.00", "4.538529"], ["84105.40", "4.720070"], ["84113.80", "5.083152"], ["84122.20", "4.266217"], ["84130.60", "3.993905"], ["84139.00", "5.173923"], ["84147.40", "4.810841"], ["84155.80", "5.627776"], ["84164.20", "4.447758"], ["84172.60", "5.537005"], ["84181.00", "4.901611"], ["84339.62", "0"]], "bids": [["83893.90", "0"], ["83891.90", "0.217080"], ["83853.40", "5.537005"], ["83845.00", "4.447758"], ["83836.60", "3.903135"], ["83828.20", "5.355464"], ["83819.80", "4.538529"], ["83811.40", "5.083152"], ["83803.00", "4.720070"], ["83794.60", "4.266217"], ["83786.20", "4.175447"], ["83777.80", "5.264693"], ["83769.40", "5.446234"], ["83761.00", "5.173923"], ["83752.60", "5.627776"], ["83744.20", "4.810841"], ["83735.80", "4.629299"], ["83727.40", "4.084676"], ["83719.00", "4.356988"], ["83710.60", "3.993905"], ["83702.20", "4.901611"]], "checksum": -1521729923, "ts": "1742577145421"}], "ts": 1742577145425, "record_time": 1742577145.617739, "EXCHANGE": "BITGET"}
{"action": "update", "arg": {"instType": "SPOT", "channel": "books", "instId": "BTCUSDT"}, "data": [{"asks": [["83918.16", "0.092744"], ["83918.17", "0"], ["83950.53", "0.049781"], ["83988.10", "0"], ["83990.00", "2.359710"], ["83992.10", "2.293440"], ["83995.10", "0.010710"], ["84021.40", "4.447758"], ["84029.80", "5.173923"], ["84038.20", "4.992382"], ["84046.60", "4.901611"], ["84055.00", "3.993905"], ["84063.40", "4.175447"], ["84071.80", "5.355464"], ["84080.20", "5.627776"], ["84088.60", "3.903135"], ["84097.00", "4.629299"], ["84105.40", "5.537005"], ["84113.80", "4.356988"], ["84122.20", "4.538529"], ["84130.60", "5.083152"], ["84139.00", "4.810841"], ["84147.40", "4.720070"], ["84155.80", "5.446234"], ["84164.20", "4.266217"], ["84172.60", "5.264693"], ["84181.00", "4.084676"], ["84339.29", "0"], ["84339.50", "0"]], "bids": [["83867.00", "0.000160"], ["83853.40", "4.720070"], ["83836.60", "3.993905"], ["83828.20", "4.266217"], ["83819.80", "4.175447"], ["83811.40", "5.627776"], ["83803.00", "4.901611"], ["83794.60", "4.629299"], ["83786.20", "5.264693"], ["83777.80", "4.538529"], ["83769.40", "4.356988"], ["83761.00", "4.810841"], ["83752.60", "5.537005"], ["83744.20", "5.355464"], ["83735.80", "4.992382"], ["83727.40", "5.173923"], ["83719.00", "4.084676"], ["83710.60", "3.903135"], ["83702.20", "5.083152"], ["83693.80", "5.446234"], ["83447.17", "0"]], "checksum": -1020338148, "ts": "1742577145623"}], "ts": 1742577145629, "record_time": 1742577145.822552, "EXCHANGE": "BITGET"}
{"action": "update", "arg": {"instType": "SPOT", "channel": "books", "instId": "BTCUSDT"}, "data": [{"asks": [["83992.10", "2.395080"], ["83995.10", "0"], ["84021.40", "5.083152"], ["84029.80", "4.084676"], ["84038.20", "4.810841"], ["84046.60", "4.266217"], ["84055.00", "4.175447"], ["84063.40", "4.447758"], ["84071.80", "5.264693"], ["84080.20", "5.355464"], ["84088.60", "5.627776"], ["84097.00", "4.992382"], ["84105.40", "5.446234"], ["84113.80", "4.901611"], ["84118.31", "0"], ["84122.20", "4.720070"], ["84130.60", "4.356988"], ["84139.00", "4.629299"], ["84147.40", "5.537005"], ["84155.80", "3.903135"], ["84164.20", "4.538529"], ["84172.60", "5.173923"], ["84181.00", "3.993905"], ["84273.06", "0"], ["84273.18", "1.604030"], ["84339.29", "0.000029"], ["84339.50", "0.000323"]], "bids": [["83854.00", "0"], ["83853.40", "5.537005"], ["83845.00", "5.264693"], ["83836.60", "4.992382"], ["83828.20", "4.810841"], ["83819.80", "4.720070"], ["83811.40", "4.356988"], ["83803.00", "5.627776"], ["83794.60", "5.173923"], ["83786.20", "4.084676"], ["83777.80", "3.993905"], ["83769.40", "5.446234"], ["83761.00", "4.175447"], ["83752.60", "4.538529"], ["83735.80", "4.629299"], ["83727.40", "4.266217"], ["83719.00", "4.901611"], ["83693.80", "4.447758"], ["83601.67", "1.713969"], ["83601.55", "0"], ["83447.17", "0.000008"]], "checksum": -1020338148, "ts": "1742577145837"}], "ts": 1742577145843, "record_time": 1742577146.035786, "EXCHANGE": "BITGET"}
{"action": "update", "arg": {"instType": "SPOT", "channel": "books", "instId": "BTCUSDT"}, "data": [{"asks": [["83918.03", "0.546674"], ["83982.60", "0.229020"], ["83983.10", "0.072150"], ["83986.00", "0.042300"], ["83992.10", "2.293440"], ["83995.10", "0.010710"], ["83995.40", "2.680320"], ["84021.40", "4.720070"], ["84029.80", "4.629299"], ["84038.20", "5.355464"], ["84046.60", "4.538529"], ["84055.00", "4.447758"], ["84063.40", "5.537005"], ["84071.80", "4.084676"], ["84080.20", "5.264693"], ["84088.60", "4.175447"], ["84097.00", "4.356988"], ["84105.40", "5.173923"], ["84113.80", "5.446234"], ["84120.85", "0.163881"], ["84122.20", "3.993905"], ["84130.60", "4.266217"], ["84139.00", "4.810841"], ["84147.40", "4.901611"], ["84155.80", "5.627776"], ["84164.20", "3.903135"], ["84172.60", "4.992382"], ["84181.00", "5.083152"], ["84339.21", "0"], ["84339.29", "0"], ["84339.50", "0"]], "bids": [["83905.40", "0.116543"], ["83903.40", "0.306694"], ["83901.40", "0.807087"], ["83899.40", "2.123914"], ["83897.40", "5.589247"], ["83895.40", "14.708545"], ["83853.40", "5.627776"], ["83845.00", "4.175447"], ["83836.60", "4.720070"], ["83828.20", "4.356988"], ["83819.80", "4.266217"], ["83811.40", "5.537005"], ["83803.00", "4.992382"], ["83794.60", "5.264693"], ["83786.20", "3.993905"], ["83777.80", "4.538529"], ["83769.40", "4.084676"], ["83761.00", "5.446234"], ["83752.60", "5.173923"], ["83744.20", "3.903135"], ["83735.80", "5.083152"], ["83727.40", "4.901611"], ["83719.00", "4.810841"], ["83710.60", "5.355464"], ["83702.20", "4.629299"]], "checksum": -678768986, "ts": "1742577146048"}], "ts": 1742577146052, "record_time": 1742577146.246908, "EXCHANGE": "BITGET"}
{"action": "update", "arg": {"instType": "SPOT", "channel": "books", "instId": "BTCUSDT"}, "data": [{"asks": [["83918.03", "0.281974"], ["83918.16", "0"], ["83922.52", "0"], ["83924.43", "0.024188"], ["83928.39", "0"], ["83938.63", "0"], ["83943.95", "0"], ["83948.89", "0"], ["83949.60", "0"], ["83950.87", "0.119905"], ["83953.27", "0"], ["83955.07", "0.015896"], ["83955.86", "0.010988"], ["83958.66", "0"], ["83965.40", "0.001029"], ["83967.40", "0.001008"], ["83969.40", "0.001033"], ["83971.40", "0.001031"], ["83973.40", "0.001002"], ["83975.40", "0.001558"], ["83977.40", "0.004099"], ["83979.40", "0.010788"], ["83979.70", "0.001041"], ["83982.60", "0.229050"], ["83983.10", "0.071730"], ["83983.60", "0.081810"], ["83983.80", "0.739830"], ["83984.00", "0.042480"], ["83985.20", "0.449700"], ["83988.70", "0.967200"], ["83992.50", "0.099510"], ["83994.60", "0"], ["83994.70", "0"], ["83995.00", "0"], ["83995.10", "0"], ["83995.40", "0"], ["84021.40", "4.175447"], ["84038.20", "4.266217"], ["84046.60", "5.083152"], ["84055.00", "4.538529"], ["84063.40", "4.810841"], ["84071.80", "5.173923"], ["84080.20", "4.720070"], ["84088.60", "4.901611"], ["84097.00", "5.264693"], ["84105.40", "4.447758"], ["84113.80", "4.084676"], ["84122.20", "3.903135"], ["84130.60", "5.446234"], ["84139.00", "3.993905"], ["84147.40", "5.627776"], ["84155.80", "5.537005"], ["84164.20", "4.356988"], ["84172.60", "5.355464"], ["84181.00", "4.992382"], ["84339.21", "0.000010"], ["84339.29", "0.000029"], ["84339.50", "0.000323"], ["84339.62", "0.000051"], ["84340.00", "0.018287"], ["84340.46", "0.000143"], ["84340.72", "0.000066"], ["84341.00", "0.002997"]], "bids": [["83910.99", "0"], ["83910.18", "0"], ["83906.00", "0"], ["83898.11", "0"], ["83895.94", "0"], ["83895.82", "0"], ["83895.40", "14.708657"], ["83895.30", "6.282990"], ["83894.17", "0"], ["83893.40", "0.045180"], ["83892.65", "0"], ["83892.62", "0"], ["83892.58", "0"], ["83892.56", "0"], ["83892.54", "0"], ["83892.49", "0"], ["83892.48", "0"], ["83892.47", "0"], ["83892.38", "0"], ["83891.40", "0.485070"], ["83891.20", "0"], ["83891.19", "0"], ["83891.17", "0"], ["83891.11", "0.268841"], ["83891.07", "0"], ["83891.03", "0"], ["83890.45", "0.482267"], ["83888.68", "0"], ["83886.70", "0"], ["83886.25", "0.073186"], ["83885.48", "0"], ["83885.46", "0"], ["83885.37", "0.056465"], ["83884.07", "0"], ["83884.04", "0"], ["83884.02", "0"], ["83884.01", "0"], ["83883.99", "0"], ["83883.97", "0"], ["83883.85", "0"], ["83883.53", "0"], ["83880.08", "0"], ["83879.11", "0"], ["83873.18", "0"], ["83868.26", "0"], ["83868.00", "0"], ["83865.43", "0"], ["83865.18", "0.003603"], ["83864.10", "0"], ["83863.89", "0"], ["83858.03", "0"], ["83853.40", "5.355464"], ["83846.80", "0.000971"], ["83845.00", "4.992382"], ["83844.20", "0"], ["83836.60", "5.627776"], ["83828.20", "5.173923"], ["83811.40", "5.264693"], ["83803.00", "5.446234"], ["83794.60", "4.538529"], ["83786.20", "4.356988"], ["83777.80", "5.537005"], ["83769.40", "4.629299"], ["83761.00", "3.903135"], ["83752.60", "4.810841"], ["83744.20", "4.720070"], ["83735.80", "3.993905"], ["83727.40", "4.084676"], ["83719.00", "4.175447"], ["83710.60", "4.901611"], ["83702.20", "4.447758"], ["83693.80", "5.083152"], ["83446.43", "0.000016"], ["83445.30", "0.000011"], ["83445.16", "0.000054"], ["83444.44", "0.000105"], ["83444.38", "0.000025"], ["83444.27", "0.000028"], ["83443.53", "0.000161"], ["83442.50", "0.000113"], ["83441.56", "0.000024"], ["83440.00", "0.000460"], ["83439.42", "0.000423"], ["83439.33", "0.000010"], ["83437.50", "0.000009"], ["83437.10", "0.000095"], ["83433.33", "0.000134"], ["83433.12", "0.000544"], ["83433.00", "0.000075"], ["83432.57", "0.000155"], ["83431.37", "0.000008"], ["83430.00", "0.002012"], ["83429.00", "0.000008"], ["83428.57", "0.000212"], ["83427.23", "0.000099"], ["83425.93", "0.000011"], ["83425.00", "0.006969"], ["83423.73", "0.001213"], ["83423.42", "0.000061"], ["83421.99", "0.000188"], ["83421.05", "0.000260"], ["83420.00", "0.018057"], ["83419.12", "0.000041"], ["83417.42", "0.000176"], ["83417.32", "0.000018"], ["83417.31", "0.000314"], ["83416.00", "0.000022"], ["83415.96", "0.000146"], ["83415.38", "0.000015"], ["83415.25", "0.000013"], ["83414.20", "0.003950"]], "checksum": -1215647347, "ts": "1742577146259"}], "ts": 1742577146262, "record_time": 1742577146.457712, "EXCHANGE": "BITGET"}
