{"action": "snapshot", "arg": {"instType": "SPOT", "channel": "books", "instId": "BTCUSDT"}, "data": [{"asks": [["83531.86", "3.659823"], ["83531.87", "0.000100"], ["83531.88", "0.000100"], ["83531.89", "0.000100"], ["83537.64", "0.134644"], ["83537.65", "0.239612"], ["83540.42", "0.209200"], ["83541.81", "0.144647"], ["83541.82", "0.330304"], ["83542.91", "0.035952"], ["83543.28", "0.001387"], ["83543.85", "0.119843"], ["83544.80", "0.035960"], ["83546.72", "0.010377"], ["83546.73", "0.010994"], ["83546.80", "0.017240"], ["83548.53", "0.006357"], ["83550.00", "0.113811"], ["83550.01", "0.209200"], ["83550.44", "0.006357"], ["83550.48", "0.006357"], ["83550.77", "0.006356"], ["83551.30", "0.006356"], ["83551.48", "0.006356"], ["83551.85", "0.006356"], ["83552.24", "0.006357"], ["83552.45", "0.006357"], ["83552.99", "0.016429"], ["83553.00", "0.006357"], ["83553.04", "0.006357"], ["83553.54", "0.006357"], ["83553.59", "0.006357"], ["83553.69", "0.119885"], ["83554.09", "0.006357"], ["83554.36", "3.701776"], ["83554.45", "0.016429"], ["83555.00", "0.001009"], ["83555.03", "0.275853"], ["83555.09", "0.006357"], ["83555.20", "0.013175"], ["83555.42", "0.010985"], ["83555.59", "0.006357"], ["83556.33", "0.009990"], ["83557.00", "0.001205"], ["83557.18", "0.119908"], ["83557.52", "0.718068"], ["83558.18", "0.119881"], ["83558.37", "0.119900"], ["83558.67", "0.015896"], ["83558.76", "0.009989"], ["83559.00", "0.003172"], ["83560.79", "0.114900"], ["83560.84", "0.006357"], ["83561.00", "0.008348"], ["83562.69", "0.015895"], ["83563.00", "0.021968"], ["83563.32", "0.010984"], ["83564.56", "0.183911"], ["83565.00", "0.057811"], ["83565.01", "0.209200"], ["83567.00", "0.152134"], ["83567.89", "0.001277"], ["83569.00", "0.400351"], ["83570.00", "0.000073"], ["83570.62", "0.000016"], ["83570.99", "1.210776"], ["83571.00", "1.053555"], ["83571.42", "0.000298"], ["83571.43", "0.000230"], ["83572.00", "0.000014"], ["83573.00", "2.772515"], ["83573.37", "0.209200"], ["83574.19", "0.000109"], ["83575.00", "7.296092"], ["83575.20", "0.001017"], ["83575.22", "0.000031"], ["83575.30", "0.978570"], ["83575.40", "0.001050"], ["83575.89", "0.055674"], ["83576.00", "0.001026"], ["83576.10", "0.001048"], ["83576.30", "0.143880"], ["83576.40", "0.022620"], ["83576.90", "0.022740"], ["83577.02", "0.005982"], ["83577.73", "0.000200"], ["83577.78", "0.000025"], ["83577.98", "0.000072"], ["83578.04", "0.000096"], ["83578.50", "0.075060"], ["83578.70", "0.666150"], ["83578.95", "0.000025"], ["83579.95", "0.023344"], ["83580.00", "0.004875"], ["83580.31", "0.000023"], ["83580.56", "0.000019"], ["83581.38", "0.000059"], ["83581.70", "0.843990"], ["83581.73", "0.000067"], ["83581.84", "0.026749"], ["83582.09", "0.000008"], ["83583.22", "0.000492"], ["83583.30", "0.143700"], ["83583.33", "0.000010"], ["83583.40", "0.009000"], ["83583.80", "0.213600"], ["83583.85", "0.000052"], ["83584.00", "0.000022"], ["83584.18", "0.000347"], ["83584.49", "0.000066"], ["83584.53", "0.000314"], ["83584.69", "0.952889"], ["83584.94", "0.001598"], ["83585.60", "0.040350"], ["83585.80", "0.213600"], ["83586.00", "0.603240"], ["83586.40", "0.043020"], ["83586.45", "0.209200"], ["83586.51", "0.000095"], ["83586.80", "0.169020"], ["83586.93", "0.002167"], ["83586.96", "0.002633"], ["83587.10", "0.010000"], ["83587.30", "1.798740"], ["83587.50", "0.000783"], ["83587.70", "2.861580"], ["83587.80", "0.213600"], ["83587.87", "0.000050"], ["83587.90", "1.370670"], ["83588.00", "0.179640"], ["83588.20", "0.299850"], ["83588.30", "1.350000"], ["83588.90", "0.276000"], ["83589.00", "0.000024"], ["83589.25", "0.000054"], ["83589.60", "0.179640"], ["83589.70", "0.216000"], ["83589.80", "0.213600"], ["83590.20", "0.457320"], ["83590.30", "0.143700"], ["83592.00", "0.000097"], ["83593.33", "0.000013"], ["83593.39", "0.000014"], ["83593.75", "0.000173"], ["83594.44", "0.000134"], ["83594.79", "0.209200"], ["83595.00", "0.000121"], ["83595.05", "0.004883"], ["83595.93", "1.794345"], ["83596.39", "0.000015"], ["83598.44", "0.000052"], ["83598.51", "0.000039"], ["83598.56", "0.000383"], ["83600.00", "0.017919"], ["83600.35", "0.000674"], ["83600.78", "0.002491"], ["83601.40", "0.201269"], ["83602.67", "0.000133"], ["83602.86", "0.000081"], ["83603.14", "0.209200"], ["83603.60", "0.000051"], ["83606.00", "0.000014"], ["83607.00", "0.000014"], ["83607.60", "0.000014"], ["83608.00", "0.000014"], ["83608.70", "0.000035"], ["83609.00", "0.000014"], ["83610.00", "0.002000"], ["83610.34", "0.000008"], ["83611.49", "0.209200"], ["83611.93", "0.000010"], ["83612.01", "0.000009"], ["83614.90", "0.000040"], ["83614.97", "0.000008"], ["83615.71", "0.000009"], ["83615.85", "0.000024"], ["83616.00", "0.001191"], ["83616.67", "0.000345"], ["83616.80", "4.469282"], ["83617.02", "0.000032"], ["83618.18", "0.000008"], ["83619.21", "0.000051"], ["83619.83", "0.209200"], ["83620.00", "0.001306"], ["83620.07", "0.000020"], ["83620.60", "0.001258"], ["83620.61", "0.000149"], ["83620.70", "0.000146"], ["83620.88", "0.000269"], ["83621.62", "0.000185"], ["83621.89", "0.000325"], ["83622.28", "0.000025"], ["83622.57", "0.000012"], ["83623.43", "0.000010"], ["83623.62", "0.000011"], ["83624.16", "0.000149"], ["83625.00", "0.005055"], ["83625.20", "4.651702"], ["83626.68", "0.000126"], ["83626.90", "0.297882"], ["83626.92", "0.000009"], ["83627.45", "0.000016"], ["83627.68", "0.000361"], ["83628.00", "0.000097"], ["83628.17", "0.209200"], ["83628.57", "0.000008"], ["83629.02", "0.000078"], ["83629.03", "0.000039"], ["83630.43", "0.000010"], ["83630.71", "0.000758"], ["83631.57", "0.000019"], ["83631.58", "0.000183"], ["83632.65", "0.000085"], ["83633.60", "5.290171"], ["83633.63", "0.000502"], ["83633.88", "0.000071"], ["83634.85", "0.000642"], ["83635.64", "0.000030"], ["83636.36", "0.000179"], ["83636.37", "0.000039"], ["83636.52", "0.209200"], ["83637.17", "0.000027"], ["83637.76", "0.000102"], ["83638.30", "0.000157"], ["83638.32", "0.000039"], ["83639.15", "0.000009"], ["83639.71", "0.000041"], ["83639.87", "0.002772"], ["83640.00", "0.005428"], ["83640.15", "0.000423"], ["83640.35", "0.000022"], ["83641.00", "0.000020"], ["83641.62", "0.002925"], ["83642.00", "5.381380"], ["83644.33", "0.000013"], ["83644.44", "0.000008"], ["83644.48", "0.000012"], ["83644.86", "0.000034"], ["83644.87", "0.209200"], ["83645.83", "0.000014"], ["83646.67", "0.000018"], ["83647.06", "0.000457"], ["83647.46", "0.000222"], ["83648.96", "0.000030"], ["83649.00", "0.001047"], ["83649.43", "0.132121"], ["83649.50", "0.000020"], ["83650.00", "0.001877"], ["83650.01", "0.000612"], ["83650.40", "3.922023"], ["83650.64", "0.058036"], ["83651.16", "0.000896"], ["83651.65", "0.000018"], ["83652.00", "0.000097"], ["83652.17", "0.000008"], ["83652.48", "0.000188"], ["83653.22", "0.209200"], ["83653.31", "0.000015"], ["83653.35", "0.072173"], ["83654.23", "0.000009"], ["83655.00", "0.000166"], ["83655.07", "0.072538"], ["83655.89", "0.000512"], ["83658.54", "0.000036"], ["83658.67", "0.008431"], ["83658.80", "4.560492"], ["83659.09", "0.000008"], ["83660.00", "0.001835"], ["83660.14", "0.000016"], ["83660.71", "0.000273"], ["83661.08", "0.000331"], ["83661.57", "0.209200"], ["83661.60", "0.000042"], ["83661.97", "0.000052"], ["83662.55", "0.000122"], ["83663.72", "0.000031"], ["83663.91", "0.000161"], ["83663.95", "0.000022"], ["83663.98", "0.000008"], ["83664.19", "0.000073"], ["83664.42", "0.000504"], ["83666.00", "0.006075"], ["83666.25", "0.000180"], ["83666.65", "0.000122"], ["83666.66", "0.000220"], ["83666.67", "0.009185"], ["83667.20", "5.655010"], ["83667.23", "0.012503"], ["83667.36", "0.001810"], ["83667.80", "0.000023"], ["83669.09", "0.000135"], ["83669.66", "0.000010"], ["83669.92", "0.209200"], ["83670.00", "0.002822"], ["83670.05", "0.000033"], ["83670.16", "0.000235"], ["83670.59", "0.000105"], ["83671.36", "0.000099"], ["83672.00", "0.000035"], ["83672.25", "0.004043"], ["83673.58", "0.000023"], ["83673.83", "0.000017"], ["83673.87", "0.000022"], ["83674.42", "0.000010"], ["83675.00", "0.002631"], ["83675.20", "0.000018"], ["83675.36", "0.000013"], ["83675.60", "4.013233"], ["83675.62", "0.000011"], ["83675.93", "0.003620"], ["83676.00", "0.000097"], ["83676.47", "0.000009"], ["83677.59", "0.000009"], ["83678.08", "0.000145"], ["83678.27", "0.209200"], ["83678.41", "0.000010"], ["83679.11", "0.000027"], ["83680.00", "0.002205"], ["83680.14", "0.000009"], ["83681.16", "0.000611"], ["83681.82", "0.000175"], ["83682.00", "0.000120"], ["83683.67", "0.000184"], ["83683.91", "0.001247"], ["83684.00", "4.286863"], ["83684.21", "0.000115"], ["83685.00", "0.000121"], ["83685.02", "0.000183"], ["83686.11", "0.000096"], ["83686.62", "0.209200"], ["83687.67", "0.002422"], ["83688.00", "0.005550"], ["83688.07", "0.000072"], ["83688.89", "0.000009"], ["83689.50", "0.000113"], ["83689.87", "0.000098"], ["83690.00", "0.000121"], ["83690.09", "0.000082"], ["83690.48", "0.000248"], ["83690.84", "0.000162"], ["83691.74", "0.000659"], ["83692.31", "0.000016"], ["83692.38", "0.000007"], ["83692.40", "5.107751"], ["83692.52", "0.000066"], ["83693.69", "0.000051"], ["83694.97", "0.209200"], ["83695.38", "0.000010"], ["83695.63", "0.000011"], ["83695.65", "0.003570"], ["83697.23", "0.000095"], ["83697.83", "0.000059"], ["83699.88", "0.000008"], ["83700.00", "0.030886"], ["83700.80", "4.834122"], ["83701.28", "0.000248"], ["83701.92", "0.000067"], ["83702.48", "0.000057"], ["83702.50", "0.000033"], ["83702.60", "0.000039"], ["83702.93", "0.000050"], ["83703.00", "0.000024"], ["83703.22", "0.026350"], ["83703.32", "0.209200"], ["83703.70", "0.000030"], ["83705.15", "0.000646"], ["83705.18", "0.000009"], ["83705.32", "0.000023"], ["83705.42", "0.000015"], ["83705.85", "0.000019"], ["83706.28", "0.000046"], ["83706.67", "0.000013"], ["83707.07", "0.000067"], ["83708.26", "0.005970"], ["83709.05", "0.000061"], ["83709.20", "4.925331"], ["83709.30", "0.000028"], ["83709.31", "0.000058"], ["83709.34", "0.001953"], ["83710.00", "0.000023"], ["83711.68", "0.209200"], ["83712.00", "0.000097"], ["83712.12", "0.000012"], ["83713.40", "0.298651"], ["83713.80", "0.000024"], ["83714.28", "0.000836"], ["83714.29", "0.010141"], ["83714.89", "0.005076"], ["83715.00", "0.000121"], ["83715.48", "0.000010"], ["83716.08", "0.000010"], ["83716.50", "0.000480"], ["83717.39", "0.000010"], ["83717.45", "0.000244"], ["83717.46", "0.000009"], ["83717.60", "5.198961"], ["83717.93", "0.000065"], ["83718.33", "0.165490"], ["83718.75", "0.000012"], ["83718.87", "0.000028"], ["83719.46", "0.000053"], ["83720.00", "0.003694"], ["83720.04", "0.209200"], ["83723.40", "0.000225"], ["83723.43", "0.000039"], ["83723.72", "0.000176"], ["83725.00", "0.001852"], ["83726.00", "5.016541"], ["83727.27", "0.000016"], ["83727.71", "0.000009"], ["83728.07", "0.000022"], ["83728.37", "0.001273"], ["83728.40", "0.209200"], ["83728.57", "0.000017"], ["83729.32", "0.000035"], ["83729.39", "0.000008"], ["83729.73", "0.000009"], ["83730.00", "0.002261"], ["83731.48", "0.000124"], ["83732.10", "0.000009"], ["83733.33", "0.000419"], ["83734.40", "4.104443"], ["83734.69", "0.000085"], ["83735.29", "0.000417"], ["83735.30", "0.296098"], ["83736.00", "0.000097"], ["83736.75", "0.209200"], ["83736.84", "0.000183"], ["83736.94", "0.000103"], ["83737.00", "0.000026"], ["83737.14", "0.000024"], ["83737.37", "0.000012"], ["83739.13", "0.000008"], ["83739.28", "0.000051"], ["83739.60", "0.000048"], ["83740.00", "0.001886"], ["83740.51", "0.000423"], ["83741.00", "0.298539"], ["83742.80", "4.378072"], ["83743.32", "0.000013"], ["83745.00", "0.000121"], ["83745.11", "0.209200"], ["83745.16", "0.000390"], ["83745.97", "0.000017"], ["83745.98", "0.091148"], ["83747.10", "0.000298"], ["83748.00", "0.000097"], ["83748.39", "0.012050"], ["83749.19", "0.000010"], ["83749.33", "0.000133"], ["83749.66", "0.000016"], ["83749.95", "0.000010"], ["83750.00", "0.012325"], ["83750.46", "0.001499"], ["83750.76", "0.000073"], ["83751.20", "5.472590"], ["83752.00", "0.000034"], ["83752.09", "0.000314"], ["83752.21", "0.000031"], ["83753.10", "0.000008"], ["83753.33", "0.000011"], ["83753.47", "0.209200"], ["83754.39", "0.000025"], ["83754.70", "0.000013"], ["83754.88", "0.000098"], ["83755.56", "0.000134"], ["83756.08", "0.000099"], ["83756.52", "0.000018"], ["83757.25", "0.003950"], ["83757.40", "0.000537"], ["83757.61", "0.000009"], ["83759.60", "4.195653"], ["83759.85", "0.000026"], ["83760.00", "0.003419"], ["83761.83", "0.209200"], ["83761.90", "0.000024"], ["83762.50", "0.000783"], ["83766.23", "0.000178"], ["83766.67", "0.000008"], ["83766.84", "0.002395"], ["83766.95", "0.000274"], ["83767.73", "0.000188"], ["83768.00", "4.742912"], ["83769.19", "0.000335"], ["83769.23", "0.000101"], ["83770.74", "0.000729"], ["83771.43", "0.000084"], ["83771.61", "0.001720"], ["83772.00", "0.000096"], ["83772.50", "0.000008"], ["83772.56", "0.000614"], ["83772.68", "0.000087"], ["83772.73", "0.000008"], ["83772.88", "0.000023"], ["83772.92", "0.000293"], ["83773.00", "0.000106"], ["83773.14", "0.000275"], ["83773.31", "0.000154"], ["83773.58", "0.000008"], ["83773.68", "0.000119"]], "bids": [["83531.85", "0.080513"], ["83531.83", "0.000100"], ["83529.16", "0.346623"], ["83524.33", "0.239455"], ["83522.07", "0.013175"], ["83521.80", "0.209200"], ["83518.86", "0.112531"], ["83518.74", "0.055266"], ["83518.68", "0.000369"], ["83518.13", "0.045997"], ["83514.87", "0.022300"], ["83513.33", "0.221174"], ["83513.00", "0.000015"], ["83512.00", "0.000032"], ["83511.40", "0.001540"], ["83511.00", "0.000032"], ["83510.00", "0.000032"], ["83509.53", "0.330356"], ["83509.40", "0.002615"], ["83509.00", "0.000032"], ["83508.21", "0.014105"], ["83508.00", "0.000032"], ["83507.84", "2.544414"], ["83507.40", "0.006881"], ["83507.27", "0.020000"], ["83507.00", "0.000032"], ["83506.39", "0.004092"], ["83506.21", "0.017968"], ["83506.00", "0.000032"], ["83505.83", "0.018393"], ["83505.49", "0.005979"], ["83505.40", "0.018106"], ["83505.36", "0.015857"], ["83505.21", "0.016544"], ["83505.00", "0.000032"], ["83504.57", "0.006612"], ["83504.30", "0.017198"], ["83504.17", "0.007184"], ["83504.00", "0.000032"], ["83503.71", "0.036374"], ["83503.49", "0.025214"], ["83503.42", "0.017179"], ["83503.40", "0.047648"], ["83503.30", "0.007988"], ["83503.27", "0.209200"], ["83503.25", "0.009048"], ["83503.15", "0.008534"], ["83503.13", "0.009777"], ["83503.12", "0.008263"], ["83503.09", "0.008102"], ["83503.08", "0.005605"], ["83503.07", "0.012469"], ["83503.06", "0.004771"], ["83503.00", "0.000032"], ["83502.92", "0.247058"], ["83502.82", "0.090631"], ["83502.80", "0.008233"], ["83502.74", "0.227328"], ["83502.00", "0.000032"], ["83501.80", "0.008334"], ["83501.40", "0.125582"], ["83501.36", "0.084435"], ["83501.30", "0.012734"], ["83501.12", "0.052245"], ["83501.00", "0.000032"], ["83500.37", "0.018629"], ["83500.00", "0.000032"], ["83499.40", "0.330479"], ["83499.38", "0.270542"], ["83499.29", "0.056175"], ["83499.00", "0.000032"], ["83498.92", "0.010000"], ["83498.37", "0.222932"], ["83498.23", "0.262436"], ["83498.03", "0.076567"], ["83498.00", "0.000032"], ["83497.78", "0.021255"], ["83497.40", "0.869682"], ["83497.25", "0.017470"], ["83497.00", "0.000032"], ["83496.00", "0.130374"], ["83495.86", "0.012518"], ["83495.40", "2.288636"], ["83495.00", "0.000032"], ["83494.20", "0.073682"], ["83494.00", "0.000032"], ["83493.95", "0.007462"], ["83493.40", "6.022897"], ["83493.15", "0.056696"], ["83493.00", "0.000032"], ["83492.70", "0.008220"], ["83492.00", "0.000032"], ["83491.40", "15.849730"], ["83491.30", "0.002430"], ["83491.20", "0.320910"], ["83491.04", "0.022236"], ["83491.00", "0.000032"], ["83490.80", "0.336480"], ["83490.65", "0.023933"], ["83490.60", "0.430920"], ["83490.50", "0.215460"], ["83490.20", "0.027000"], ["83490.10", "0.120000"], ["83490.00", "0.120180"], ["83489.95", "0.022252"], ["83489.93", "0.037436"], ["83489.90", "0.538860"], ["83489.89", "0.209200"], ["83489.81", "0.020197"], ["83489.79", "0.005927"], ["83489.78", "0.008409"], ["83489.40", "0.215460"], ["83489.21", "0.007722"], ["83489.20", "0.159870"], ["83489.19", "0.014314"], ["83489.18", "0.007351"], ["83489.12", "0.009498"], ["83489.11", "0.008329"], ["83489.10", "0.215460"], ["83489.08", "0.009757"], ["83489.00", "0.000032"], ["83488.40", "0.120000"], ["83488.29", "0.024138"], ["83488.20", "0.213930"], ["83488.00", "0.000032"], ["83487.80", "0.077880"], ["83487.55", "0.012493"], ["83487.50", "0.120000"], ["83487.46", "0.718670"], ["83487.00", "0.000032"], ["83486.60", "0.630660"], ["83486.20", "0.213600"], ["83486.00", "0.000032"], ["83485.90", "0.648600"], ["83485.80", "0.360000"], ["83485.70", "0.160890"], ["83485.20", "0.010530"], ["83485.00", "0.000032"], ["83484.40", "0.035910"], ["83484.20", "0.005370"], ["83484.00", "0.000032"], ["83483.00", "0.000032"], ["83482.95", "0.008787"], ["83482.84", "0.008928"], ["83482.81", "0.000325"], ["83482.07", "0.005046"], ["83482.02", "0.005212"], ["83482.00", "0.000032"], ["83481.99", "0.005116"], ["83481.65", "0.017240"], ["83481.56", "0.001040"], ["83481.00", "0.000032"], ["83480.00", "0.000015"], ["83479.83", "0.209200"], ["83479.00", "0.000017"], ["83472.22", "0.001810"], ["83471.51", "0.001182"], ["83468.61", "0.209200"], ["83466.70", "0.207716"], ["83463.87", "0.003620"], ["83463.60", "0.008530"], ["83461.53", "0.008078"], ["83460.00", "0.002000"], ["83455.73", "0.072173"], ["83455.35", "0.072538"], ["83455.00", "0.208967"], ["83450.00", "0.000180"], ["83449.60", "3.922023"], ["83443.30", "0.209200"], ["83441.76", "0.058036"], ["83441.20", "5.290171"], ["83432.80", "4.013233"], ["83431.65", "0.209200"], ["83430.00", "0.002000"], ["83424.40", "5.198961"], ["83423.00", "0.209200"], ["83416.50", "0.000008"], ["83416.00", "4.925331"], ["83415.30", "0.000750"], ["83414.65", "0.209200"], ["83407.60", "4.104443"], ["83400.73", "0.132121"], ["83400.30", "0.209200"], ["83400.00", "0.002420"], ["83399.20", "5.563800"], ["83398.67", "0.000023"], ["83397.78", "0.000600"], ["83396.60", "0.303213"], ["83391.30", "0.209200"], ["83390.80", "5.381380"], ["83382.40", "5.016541"], ["83382.22", "0.005990"], ["83377.00", "0.209200"], ["83374.00", "4.834122"], ["83373.34", "0.000052"], ["83370.00", "0.002000"], ["83368.36", "0.000023"], ["83367.93", "0.000265"], ["83365.60", "4.742912"], ["83365.00", "0.209200"], ["83357.20", "4.651702"], ["83355.91", "0.026350"], ["83350.00", "0.000180"], ["83349.64", "0.209200"], ["83348.80", "5.472590"], ["83344.00", "0.001215"], ["83340.95", "0.209200"], ["83340.40", "4.378072"], ["83340.00", "0.002000"], ["83336.08", "0.005990"], ["83333.00", "0.000008"], ["83332.00", "5.655010"], ["83329.44", "0.001335"], ["83325.63", "0.209200"], ["83323.60", "5.107751"], ["83320.61", "0.001720"], ["83319.87", "0.000024"], ["83318.01", "0.000391"], ["83315.37", "0.000104"], ["83315.20", "4.469282"], ["83315.01", "0.000024"], ["83315.00", "0.209033"], ["83310.00", "0.002000"], ["83306.80", "4.286863"], ["83303.30", "0.209200"], ["83302.29", "0.000139"], ["83300.00", "0.006458"], ["83298.40", "4.560492"], ["83294.96", "0.209200"], ["83291.20", "0.298470"], ["83290.70", "0.305281"], ["83290.00", "4.195653"], ["83288.96", "0.007500"], ["83288.82", "0.000013"], ["83283.01", "0.001388"], ["83283.00", "0.209200"], ["83280.00", "0.002000"], ["83277.90", "0.000033"], ["83270.03", "0.209200"], ["83261.70", "0.209200"], ["83259.73", "0.000019"], ["83259.25", "0.000024"], ["83255.00", "0.000060"], ["83253.34", "0.209200"], ["83250.00", "0.002180"], ["83249.50", "0.000008"], ["83242.23", "0.000183"], ["83242.12", "0.000567"], ["83241.41", "0.000750"], ["83239.43", "0.000022"], ["83230.76", "0.000022"], ["83226.38", "0.001273"], ["83220.00", "0.002000"], ["83215.34", "0.000010"], ["83211.85", "1.583085"], ["83208.27", "0.000043"], ["83205.45", "0.000013"], ["83204.69", "0.000024"], ["83200.86", "0.000292"], ["83200.00", "0.000949"], ["83197.14", "0.000017"], ["83195.50", "0.000113"], ["83193.28", "0.000009"], ["83190.00", "0.002000"], ["83182.50", "0.000180"], ["83181.82", "0.000010"], ["83181.81", "0.000105"], ["83179.71", "0.000366"], ["83176.60", "0.000145"], ["83174.56", "0.000033"], ["83172.98", "0.000690"], ["83172.30", "0.494693"], ["83166.00", "0.000008"], ["83165.41", "0.000035"], ["83164.56", "0.000658"], ["83163.33", "0.000011"], ["83163.09", "0.000033"], ["83160.00", "0.002000"], ["83158.01", "0.000011"], ["83157.89", "0.000020"], ["83156.19", "0.000024"], ["83155.08", "0.000024"], ["83150.00", "0.001231"], ["83142.86", "0.000033"], ["83140.97", "0.002189"], ["83138.69", "0.000014"], ["83134.94", "0.000120"], ["83133.34", "0.000119"], ["83130.00", "0.002000"], ["83127.68", "0.000039"], ["83127.66", "0.000157"], ["83125.00", "0.000741"], ["83123.11", "0.000022"], ["83123.01", "0.000016"], ["83122.08", "0.000013"], ["83121.14", "0.000019"], ["83120.69", "0.000008"], ["83117.65", "0.000417"], ["83115.00", "0.000120"], ["83114.39", "0.000022"], ["83114.29", "0.000008"], ["83114.04", "0.000022"], ["83113.27", "0.000070"], ["83112.95", "0.000161"], ["83111.11", "0.000105"], ["83111.10", "0.000219"], ["83110.95", "0.000013"], ["83110.37", "0.000024"], ["83110.00", "0.000052"], ["83109.95", "0.000010"], ["83108.70", "0.000010"], ["83108.55", "0.000093"], ["83107.74", "0.000009"], ["83105.25", "0.000392"], ["83103.44", "0.000315"], ["83100.78", "0.000087"], ["83100.00", "0.003766"], ["83096.28", "0.000366"], ["83093.75", "0.000012"], ["83093.22", "0.000155"], ["83092.97", "0.000024"], ["83090.91", "0.000068"], ["83090.90", "0.000505"], ["83088.24", "0.000056"], ["83086.96", "0.000035"], ["83086.75", "0.000011"], ["83085.00", "0.000120"], ["83082.50", "0.000008"], ["83081.08", "0.000009"], ["83080.00", "0.000279"], ["83077.66", "0.000008"], ["83077.17", "0.000013"], ["83076.92", "0.000167"], ["83072.73", "0.000008"], ["83072.00", "0.000113"], ["83071.43", "0.000082"], ["83071.13", "0.000010"], ["83070.00", "0.000121"], ["83069.28", "0.000043"], ["83067.73", "0.000009"], ["83067.46", "0.000055"], ["83066.67", "0.000018"], ["83064.94", "0.000088"], ["83063.06", "0.000051"], ["83062.50", "0.000803"], ["83060.00", "0.000156"], ["83059.73", "0.001273"], ["83055.79", "0.000135"], ["83055.00", "0.000121"], ["83053.94", "0.000068"], ["83052.63", "0.000025"], ["83050.00", "0.000296"], ["83049.62", "0.000013"], ["83047.97", "0.000024"], ["83045.53", "0.000010"], ["83044.25", "0.000031"], ["83044.24", "0.000766"], ["83043.48", "0.016817"], ["83042.57", "0.000039"], ["83042.55", "0.000157"], ["83040.00", "0.000532"], ["83038.71", "0.000013"], ["83037.96", "0.000423"], ["83037.74", "0.000096"], ["83037.38", "0.000099"], ["83037.29", "0.000023"], ["83034.69", "0.000049"], ["83033.79", "0.000322"], ["83033.49", "0.000016"], ["83033.33", "0.000322"], ["83031.03", "0.000058"], ["83030.30", "0.000009"], ["83030.00", "0.000345"], ["83029.60", "0.000537"], ["83029.41", "0.000417"], ["83029.03", "0.000065"], ["83028.57", "0.000024"], ["83028.00", "0.000012"], ["83026.67", "0.000013"], ["83026.56", "0.000010"], ["83026.32", "0.000031"], ["83025.00", "0.000121"], ["83024.39", "0.000248"], ["83024.19", "0.000039"], ["83021.74", "0.000010"], ["83020.94", "0.000162"], ["83020.73", "0.000023"], ["83020.41", "0.000085"], ["83020.00", "0.000070"], ["83019.17", "0.000009"], ["83018.87", "0.000051"], ["83017.62", "0.000010"], ["83017.08", "0.000024"], ["83017.00", "0.000009"], ["83016.00", "0.000133"], ["83014.49", "0.000013"], ["83012.96", "0.000022"], ["83012.85", "0.000366"], ["83010.00", "0.002121"], ["83009.01", "0.000176"], ["83008.85", "0.000010"], ["83008.00", "0.000249"], ["83005.82", "0.000024"], ["83005.12", "0.000019"], ["83005.08", "0.000024"], ["83002.75", "0.000161"], ["83002.00", "0.000024"], ["83001.82", "0.000016"], ["83001.00", "0.252737"], ["83000.00", "0.041131"], ["82999.99", "0.000057"], ["82999.00", "0.000008"], ["82998.09", "0.000013"], ["82995.98", "0.000008"], ["82995.00", "0.000121"], ["82994.79", "0.000033"], ["82993.42", "0.000093"], ["82992.00", "0.000012"], ["82991.99", "0.000108"], ["82991.69", "0.012605"], ["82990.00", "0.000011"], ["82988.15", "0.010000"], ["82986.66", "0.000033"], ["82984.85", "0.000008"], ["82984.67", "0.000019"], ["82984.64", "0.000011"], ["82984.42", "0.000008"], ["82982.32", "0.000020"], ["82980.77", "0.000067"], ["82980.76", "0.000014"], ["82980.00", "0.002121"], ["82979.08", "0.000010"], ["82979.06", "0.000235"], ["82978.28", "0.000035"], ["82977.94", "0.000041"], ["82977.78", "0.000009"], ["82977.27", "0.000008"], ["82975.00", "0.000783"], ["82974.76", "0.000063"], ["82973.98", "0.000039"], ["82972.97", "0.000060"], ["82970.00", "0.000121"], ["82966.97", "0.001147"], ["82966.67", "0.000036"], ["82965.00", "0.000121"], ["82964.91", "0.000025"], ["82964.29", "0.000273"], ["82963.64", "0.000008"], ["82962.00", "0.000035"], ["82961.03", "0.000019"], ["82960.99", "0.000188"], ["82960.00", "0.018650"], ["82957.74", "0.000022"], ["82957.46", "0.000039"], ["82957.45", "0.000157"], ["82956.52", "0.000008"], ["82955.76", "0.000027"], ["82955.75", "0.000031"], ["82955.33", "0.000013"], ["82953.57", "0.000128"], ["82953.19", "0.000051"], ["82950.00", "0.002648"], ["82949.40", "0.000060"], ["82948.66", "0.000018"], ["82948.50", "0.000113"], ["82947.77", "0.007149"], ["82947.37", "0.000068"], ["82945.77", "0.000008"], ["82945.44", "0.000422"], ["82943.96", "0.000016"], ["82943.30", "0.000010"], ["82943.20", "0.000009"], ["82942.86", "0.000017"], ["82942.68", "0.000024"], ["82942.22", "0.000015"], ["82941.18", "0.000446"], ["82940.00", "0.002472"], ["82938.97", "0.000099"], ["82938.60", "0.000022"], ["82938.45", "0.000022"], ["82937.59", "0.000423"], ["82937.50", "0.000012"], ["82936.29", "0.000067"], ["82935.00", "0.000121"], ["82934.78", "0.000010"], ["82933.33", "0.000019"], ["82932.20", "0.000023"], ["82931.04", "0.000146"], ["82930.60", "0.000009"], ["82930.00", "0.000076"], ["82929.67", "0.000096"], ["82928.18", "0.000015"], ["82927.46", "0.000023"], ["82927.15", "0.000019"], ["82922.22", "0.000008"], ["82922.10", "0.000008"], ["82921.48", "0.000297"], ["82920.59", "0.000008"], ["82920.00", "0.002447"], ["82918.68", "0.000024"]], "checksum": 0, "ts": "1742377117225"}], "ts": 1742377117347, "record_time": 1742377118.282914}
{"action": "update", "arg": {"instType": "SPOT", "channel": "books", "instId": "BTCUSDT"}, "data": [{"asks": [["83557.00", "0.001359"], ["83559.00", "0.003576"], ["83561.00", "0.009410"], ["83563.00", "0.024764"], ["83565.00", "0.065169"], ["83567.00", "0.171496"], ["83569.00", "0.451305"], ["83571.00", "1.187646"], ["83573.00", "3.125385"], ["83575.00", "8.224697"], ["83578.70", "0"], ["83579.80", "0.143700"], ["83585.40", "2.369970"], ["83590.30", "0"], ["83595.92", "0.543826"], ["83616.80", "5.472590"], ["83625.20", "4.195653"], ["83633.60", "4.469282"], ["83642.00", "4.651702"], ["83650.40", "4.560492"], ["83658.80", "5.290171"], ["83667.20", "3.922023"], ["83667.36", "0"], ["83675.60", "4.925331"], ["83675.93", "0"], ["83684.00", "4.104443"], ["83692.40", "5.655010"], ["83700.80", "4.378072"], ["83709.20", "4.013233"], ["83717.60", "4.834122"], ["83718.33", "0"], ["83726.00", "4.286863"], ["83734.40", "5.563800"], ["83742.80", "5.016541"], ["83751.20", "5.198961"], ["83759.60", "5.381380"], ["83774.01", "0.005960"], ["83774.10", "0.000161"]], "bids": [["83531.85", "0.000100"], ["83503.40", "0.047451"], ["83501.40", "0.124870"], ["83499.40", "0.328607"], ["83497.40", "0.864756"], ["83495.40", "2.275672"], ["83493.40", "5.988610"], ["83491.40", "15.759501"], ["83489.20", "0.016170"], ["83488.20", "0"], ["83487.20", "0.015000"], ["83486.20", "0"], ["83484.20", "0.025350"], ["83479.00", "0"], ["83472.22", "0"], ["83463.87", "0"], ["83449.60", "5.472590"], ["83441.20", "4.834122"], ["83432.80", "4.286863"], ["83424.40", "4.104443"], ["83416.00", "5.381380"], ["83407.60", "4.560492"], ["83399.20", "4.013233"], ["83390.80", "4.195653"], ["83382.40", "4.378072"], ["83374.00", "4.651702"], ["83365.60", "5.016541"], ["83357.20", "5.655010"], ["83348.80", "4.925331"], ["83340.40", "5.107751"], ["83332.00", "5.563800"], ["83323.60", "4.469282"], ["83315.20", "5.290171"], ["83306.80", "3.922023"], ["83298.40", "5.198961"], ["83290.00", "4.742912"], ["82918.37", "0.000085"], ["82917.65", "0.000105"], ["82917.64", "0.000314"], ["82917.50", "0.000015"]], "checksum": -1424425996, "ts": "1742377117427"}], "ts": 1742377117434, "record_time": 1742377118.314991}
{"action": "update", "arg": {"instType": "SPOT", "channel": "books", "instId": "BTCUSDT"}, "data": [{"asks": [["83531.86", "3.332613"], ["83546.09", "0.006357"], ["83546.11", "0.006357"], ["83546.42", "0.006356"], ["83546.81", "0.006356"], ["83546.98", "0.006356"], ["83547.44", "0.006356"], ["83547.80", "0.006357"], ["83548.01", "0.006357"], ["83548.46", "0.006357"], ["83548.62", "0.006357"], ["83548.93", "0.016429"], ["83549.00", "0.006357"], ["83549.13", "0.006357"], ["83549.29", "0.119885"], ["83549.50", "0.006357"], ["83550.44", "0"], ["83550.48", "0"], ["83550.50", "0.006357"], ["83550.77", "0"], ["83550.97", "0.010985"], ["83551.00", "0.006357"], ["83551.30", "0"], ["83551.48", "0"], ["83551.80", "0.009990"], ["83551.85", "0"], ["83552.24", "0"], ["83552.45", "0"], ["83552.73", "0.119908"], ["83552.99", "0"], ["83553.00", "0"], ["83553.04", "0"], ["83553.54", "0"], ["83553.59", "0"], ["83553.69", "0"], ["83553.73", "0.119881"], ["83553.97", "0.119900"], ["83554.09", "0"], ["83554.17", "0.015896"], ["83554.31", "0.009989"], ["83555.09", "0"], ["83555.42", "0"], ["83555.59", "0"], ["83556.31", "0.006357"], ["83556.33", "0"], ["83557.18", "0"], ["83558.11", "0.015895"], ["83558.18", "0"], ["83558.37", "0"], ["83558.67", "0"], ["83558.76", "0"], ["83558.89", "0.010984"], ["83560.84", "0"], ["83562.69", "0"], ["83563.32", "0"], ["83571.00", "1.187410"], ["83573.00", "3.124763"], ["83575.00", "8.223060"], ["83575.30", "0.948510"], ["83577.60", "0.666150"], ["83578.50", "0.074880"], ["83585.40", "3.760770"], ["83586.00", "0.000386"], ["83590.20", "0.228000"], ["83616.80", "5.655010"], ["83625.19", "0.857540"], ["83625.20", "4.560492"], ["83633.60", "5.016541"], ["83642.00", "5.381380"], ["83650.38", "0.001810"], ["83650.40", "4.286863"], ["83658.74", "0.003620"], ["83658.80", "4.925331"], ["83667.20", "5.563800"], ["83675.60", "5.472590"], ["83684.00", "4.834122"], ["83692.40", "5.198961"], ["83700.80", "4.651702"], ["83717.60", "4.742912"], ["83726.00", "5.107751"], ["83734.40", "4.469282"], ["83742.80", "4.104443"], ["83751.20", "3.922023"], ["83759.60", "4.195653"], ["83768.00", "4.378072"], ["83773.58", "0"], ["83773.68", "0"], ["83774.01", "0"], ["83774.10", "0"]], "bids": [["83531.85", "0"], ["83531.81", "0.000100"], ["83521.96", "0.050695"], ["83518.74", "0"], ["83518.13", "0"], ["83509.53", "0"], ["83506.21", "0"], ["83505.83", "0"], ["83505.49", "0"], ["83505.36", "0"], ["83505.21", "0"], ["83504.57", "0"], ["83504.30", "0"], ["83504.17", "0"], ["83503.71", "0"], ["83503.42", "0"], ["83503.30", "0"], ["83503.25", "0"], ["83502.80", "0"], ["83502.74", "0"], ["83501.84", "0.017968"], ["83501.80", "0"], ["83501.49", "0.018393"], ["83501.30", "0"], ["83501.15", "0.005979"], ["83501.12", "0"], ["83500.87", "0.015857"], ["83500.71", "0.016544"], ["83500.37", "0"], ["83500.17", "0.006612"], ["83499.86", "0.017198"], ["83499.73", "0.007184"], ["83499.65", "0.029001"], ["83499.38", "0"], ["83499.19", "0.007373"], ["83499.01", "0.017179"], ["83498.85", "0.009048"], ["83498.72", "0.007988"], ["83498.37", "0"], ["83498.34", "0.227328"], ["83498.23", "0"], ["83498.22", "0.008233"], ["83498.03", "0"], ["83497.78", "0"], ["83497.22", "0.008334"], ["83496.71", "0.012734"], ["83496.68", "0.052245"], ["83495.86", "0"], ["83495.84", "0.018629"], ["83494.93", "0.270542"], ["83494.20", "0"], ["83493.93", "0.222932"], ["83493.83", "0.262436"], ["83493.53", "0.076567"], ["83493.40", "5.988498"], ["83493.34", "0.021255"], ["83493.15", "0"], ["83491.40", "15.759203"], ["83491.33", "0.012518"], ["83490.65", "0"], ["83489.90", "0.120000"], ["83489.62", "0.073682"], ["83488.73", "0.056696"], ["83488.29", "0"], ["83486.23", "0.023933"], ["83483.77", "0.024138"], ["83483.60", "0.017940"], ["83481.00", "0.000017"], ["83468.81", "0.001810"], ["83459.21", "0.003620"], ["83449.60", "4.195653"], ["83441.20", "4.286863"], ["83432.80", "4.834122"], ["83424.40", "3.922023"], ["83416.00", "5.290171"], ["83407.60", "5.198961"], ["83399.20", "4.378072"], ["83390.80", "4.013233"], ["83382.40", "4.560492"], ["83374.00", "5.563800"], ["83365.60", "5.655010"], ["83357.20", "5.381380"], ["83348.80", "5.016541"], ["83340.40", "4.651702"], ["83332.00", "4.742912"], ["83315.20", "4.104443"], ["83306.80", "5.107751"], ["83298.40", "5.472590"], ["83290.00", "4.925331"], ["82917.64", "0"], ["82917.50", "0"]], "checksum": 1365818017, "ts": "1742377117632"}], "ts": 1742377117635, "record_time": 1742377118.517546}
{"action": "update", "arg": {"instType": "SPOT", "channel": "books", "instId": "BTCUSDT"}, "data": [{"asks": [["83531.84", "2.876767"], ["83531.85", "0.991195"], ["83531.86", "0.570978"], ["83546.72", "0.069044"], ["83569.00", "0.451193"], ["83573.00", "3.124607"], ["83575.00", "8.222651"], ["83616.80", "4.925331"], ["83625.20", "5.472590"], ["83633.60", "4.742912"], ["83642.00", "4.651702"], ["83650.40", "5.290171"], ["83658.80", "3.922023"], ["83667.20", "5.198961"], ["83675.60", "5.381380"], ["83684.00", "5.655010"], ["83692.40", "4.104443"], ["83700.80", "5.016541"], ["83709.20", "4.195653"], ["83715.27", "0.170729"], ["83717.60", "4.286863"], ["83726.00", "4.834122"], ["83734.40", "5.563800"], ["83742.80", "4.560492"], ["83751.20", "4.378072"], ["83759.60", "4.469282"], ["83768.00", "5.107751"], ["83773.00", "0"], ["83773.14", "0"], ["83773.31", "0"]], "bids": [["83531.83", "0.000200"], ["83531.80", "0.000100"], ["83518.60", "0.045996"], ["83505.12", "0.330305"], ["83503.28", "0.115926"], ["83480.00", "0.000032"], ["83449.60", "3.922023"], ["83441.20", "4.651702"], ["83432.80", "4.013233"], ["83424.40", "5.198961"], ["83416.00", "5.381380"], ["83407.60", "5.563800"], ["83399.20", "4.195653"], ["83390.80", "5.472590"], ["83382.40", "4.834122"], ["83374.00", "4.378072"], ["83365.60", "4.925331"], ["83357.20", "5.655010"], ["83348.80", "5.290171"], ["83340.40", "4.742912"], ["83332.00", "5.107751"], ["83315.20", "5.016541"], ["83306.80", "4.560492"], ["83298.40", "4.104443"], ["83290.00", "4.286863"], ["82920.00", "0"], ["82918.68", "0"], ["82918.37", "0"], ["82917.65", "0"]], "checksum": -1609149641, "ts": "1742377117834"}], "ts": 1742377117838, "record_time": 1742377118.720458}
{"action": "update", "arg": {"instType": "SPOT", "channel": "books", "instId": "BTCUSDT"}, "data": [{"asks": [["83531.84", "2.877574"], ["83531.85", "0.162705"], ["83531.86", "0.552830"], ["83543.36", "0.479763"], ["83589.60", "0"], ["83590.20", "0.432000"], ["83616.80", "5.381380"], ["83625.19", "0"], ["83625.20", "5.290171"], ["83633.60", "4.013233"], ["83642.00", "4.286863"], ["83650.40", "4.560492"], ["83658.80", "4.742912"], ["83667.20", "4.104443"], ["83675.60", "4.195653"], ["83684.00", "5.472590"], ["83692.40", "5.563800"], ["83700.80", "4.925331"], ["83709.20", "4.378072"], ["83717.60", "4.834122"], ["83726.00", "4.651702"], ["83734.40", "5.107751"], ["83742.80", "3.922023"], ["83751.20", "5.655010"], ["83759.60", "5.016541"], ["83768.00", "5.198961"], ["83773.00", "0.000106"]], "bids": [["83499.40", "0.328601"], ["83497.40", "0.864739"], ["83495.40", "2.275629"], ["83449.60", "5.472590"], ["83441.20", "4.286863"], ["83432.80", "5.563800"], ["83424.40", "5.107751"], ["83416.00", "4.013233"], ["83407.60", "4.378072"], ["83399.20", "4.651702"], ["83390.80", "4.104443"], ["83382.40", "5.655010"], ["83374.00", "4.469282"], ["83365.60", "5.290171"], ["83357.20", "5.016541"], ["83348.80", "4.195653"], ["83340.40", "4.834122"], ["83332.00", "5.198961"], ["83323.60", "3.922023"], ["83315.20", "4.925331"], ["83306.80", "5.381380"], ["83298.40", "4.742912"], ["83290.00", "4.560492"]], "checksum": -1908929064, "ts": "1742377118046"}], "ts": 1742377118050, "record_time": 1742377118.933512}
{"action": "update", "arg": {"instType": "SPOT", "channel": "books", "instId": "BTCUSDT"}, "data": [{"asks": [["83531.84", "4.438858"], ["83531.86", "0.553100"], ["83541.81", "0.282882"], ["83616.80", "4.378072"], ["83625.20", "4.469282"], ["83633.60", "4.560492"], ["83642.00", "4.651702"], ["83650.40", "3.922023"], ["83658.80", "4.013233"], ["83667.20", "5.655010"], ["83675.60", "4.104443"], ["83684.00", "5.290171"], ["83692.40", "4.925331"], ["83700.80", "5.107751"], ["83709.20", "5.563800"], ["83717.60", "4.286863"], ["83726.00", "4.195653"], ["83734.40", "5.198961"], ["83742.80", "5.016541"], ["83751.20", "4.834122"], ["83759.60", "4.742912"], ["83768.00", "5.381380"]], "bids": [["83519.14", "0.045996"], ["83518.60", "0"], ["83506.39", "0"], ["83503.56", "0.004092"], ["83499.40", "0.328725"], ["83497.40", "0.865064"], ["83495.40", "2.276486"], ["83493.40", "5.990752"], ["83491.40", "15.765137"], ["83486.70", "0.027360"], ["83485.10", "0.015000"], ["83484.20", "0"], ["83483.60", "0"], ["83479.00", "0.000015"], ["83449.60", "5.381380"], ["83441.20", "4.925331"], ["83432.80", "4.286863"], ["83424.40", "5.016541"], ["83416.00", "5.472590"], ["83407.60", "4.651702"], ["83399.20", "5.563800"], ["83382.40", "4.378072"], ["83374.00", "5.655010"], ["83365.60", "4.834122"], ["83357.20", "5.107751"], ["83348.80", "5.290171"], ["83340.40", "4.742912"], ["83323.60", "4.469282"], ["83315.20", "4.560492"], ["83306.80", "4.013233"], ["83298.40", "3.922023"], ["83290.00", "4.195653"], ["82920.59", "0"]], "checksum": -66191703, "ts": "1742377118247"}], "ts": 1742377118251, "record_time": 1742377119.13144}
{"action": "update", "arg": {"instType": "SPOT", "channel": "books", "instId": "BTCUSDT"}, "data": [{"asks": [["83531.84", "4.766068"], ["83550.00", "0.168797"], ["83563.00", "0.024592"], ["83565.00", "0.064716"], ["83567.00", "0.170304"], ["83569.00", "0.448169"], ["83571.00", "1.179393"], ["83573.00", "3.103665"], ["83575.00", "8.167539"], ["83576.40", "0"], ["83576.90", "0"], ["83581.10", "0.022740"], ["83581.50", "0.022620"], ["83616.80", "5.198961"], ["83625.20", "4.651702"], ["83633.60", "5.290171"], ["83642.00", "5.655010"], ["83650.40", "4.560492"], ["83658.80", "4.834122"], ["83667.20", "4.013233"], ["83675.60", "5.472590"], ["83684.00", "5.381380"], ["83692.40", "4.104443"], ["83700.80", "5.563800"], ["83709.20", "4.469282"], ["83717.60", "4.195653"], ["83726.00", "5.107751"], ["83734.40", "4.742912"], ["83742.80", "3.922023"], ["83751.20", "4.925331"], ["83759.60", "4.286863"], ["83768.00", "4.378072"]], "bids": [["83499.40", "0.328601"], ["83497.40", "0.864739"], ["83495.40", "2.275629"], ["83493.40", "5.988498"], ["83491.40", "15.759203"], ["83449.60", "4.834122"], ["83441.20", "4.013233"], ["83432.80", "5.563800"], ["83424.40", "4.195653"], ["83407.60", "5.016541"], ["83399.20", "5.381380"], ["83390.80", "5.290171"], ["83374.00", "5.107751"], ["83365.60", "3.922023"], ["83357.20", "4.742912"], ["83348.80", "4.651702"], ["83340.40", "4.286863"], ["83332.00", "5.655010"], ["83323.60", "4.560492"], ["83315.20", "4.925331"], ["83306.80", "5.198961"], ["83298.40", "4.104443"], ["83290.00", "4.469282"]], "checksum": -479104528, "ts": "1742377118450"}], "ts": 1742377118453, "record_time": 1742377119.334008}
{"action": "update", "arg": {"instType": "SPOT", "channel": "books", "instId": "BTCUSDT"}, "data": [{"asks": [["83531.86", "0.547648"], ["83554.35", "1.342220"], ["83555.03", "0"], ["83581.69", "0.261392"], ["83595.92", "0"], ["83597.47", "0.000750"], ["83616.80", "4.469282"], ["83633.60", "4.560492"], ["83650.40", "5.472590"], ["83658.80", "4.195653"], ["83667.20", "5.290171"], ["83675.60", "5.198961"], ["83684.00", "4.834122"], ["83692.40", "4.925331"], ["83700.80", "4.013233"], ["83709.20", "5.107751"], ["83717.60", "5.381380"], ["83726.00", "3.922023"], ["83734.40", "4.104443"], ["83742.80", "4.286863"], ["83751.20", "4.742912"], ["83759.60", "5.016541"], ["83768.00", "5.563800"], ["83773.00", "0"]], "bids": [["83521.96", "0"], ["83519.14", "0"], ["83481.00", "0"], ["83449.60", "4.651702"], ["83441.20", "4.469282"], ["83432.80", "5.198961"], ["83424.40", "4.013233"], ["83416.00", "4.286863"], ["83407.60", "4.195653"], ["83399.20", "5.472590"], ["83390.80", "3.922023"], ["83382.40", "5.655010"], ["83374.00", "4.742912"], ["83365.60", "4.925331"], ["83357.20", "4.560492"], ["83348.80", "5.290171"], ["83340.40", "5.563800"], ["83332.00", "5.381380"], ["83323.60", "4.834122"], ["83315.20", "4.104443"], ["83306.80", "5.016541"], ["83298.40", "4.378072"], ["83290.00", "5.107751"], ["82920.59", "0.000008"], ["82920.00", "0.002447"], ["82918.68", "0.000024"]], "checksum": -764100494, "ts": "1742377118654"}], "ts": 1742377118658, "record_time": 1742377119.538782}
{"action": "update", "arg": {"instType": "SPOT", "channel": "books", "instId": "BTCUSDT"}, "data": [{"asks": [["83561.00", "0.009270"], ["83563.00", "0.024396"], ["83565.00", "0.064200"], ["83567.00", "0.168947"], ["83569.00", "0.444597"], ["83571.00", "1.169992"], ["83573.00", "3.078927"], ["83575.00", "8.102439"], ["83584.69", "0"], ["83611.48", "0.062766"], ["83616.80", "4.104443"], ["83625.20", "5.472590"], ["83633.60", "4.925331"], ["83642.00", "4.742912"], ["83650.40", "5.381380"], ["83658.80", "4.651702"], ["83667.20", "5.016541"], ["83675.60", "5.563800"], ["83684.00", "5.290171"], ["83692.40", "5.107751"], ["83700.80", "4.378072"], ["83709.20", "4.469282"], ["83717.60", "4.560492"], ["83726.00", "4.013233"], ["83734.40", "5.198961"], ["83742.80", "3.922023"], ["83751.20", "4.834122"], ["83759.60", "4.195653"], ["83768.00", "4.286863"]], "bids": [["83524.38", "0.055266"], ["83519.61", "0.045996"], ["83501.40", "0.124972"], ["83499.40", "0.328872"], ["83497.40", "0.865452"], ["83495.40", "2.277506"], ["83493.40", "5.993438"], ["83491.40", "15.772205"], ["83484.40", "0.017970"], ["83449.60", "5.290171"], ["83441.20", "5.107751"], ["83424.40", "4.834122"], ["83416.00", "4.742912"], ["83407.60", "5.472590"], ["83399.20", "4.651702"], ["83397.96", "0.000600"], ["83390.80", "4.013233"], ["83382.40", "4.925331"], ["83374.00", "4.104443"], ["83365.60", "4.195653"], ["83357.20", "5.016541"], ["83348.80", "4.469282"], ["83340.40", "5.655010"], ["83332.00", "4.286863"], ["83323.60", "3.922023"], ["83315.20", "4.560492"], ["83306.80", "5.563800"], ["83290.00", "5.381380"], ["83211.85", "0"], ["83199.05", "1.731881"], ["82920.59", "0"], ["82920.00", "0"], ["82918.68", "0"]], "checksum": 601078729, "ts": "1742377118876"}], "ts": 1742377118879, "record_time": 1742377119.759368}
{"action": "update", "arg": {"instType": "SPOT", "channel": "books", "instId": "BTCUSDT"}, "data": [{"asks": [["83531.86", "0.547378"], ["83616.80", "4.834122"], ["83625.20", "5.381380"], ["83633.59", "0.549137"], ["83633.60", "4.651702"], ["83642.00", "4.469282"], ["83650.40", "4.560492"], ["83658.80", "3.922023"], ["83667.20", "4.104443"], ["83675.60", "5.016541"], ["83684.00", "4.742912"], ["83692.40", "5.563800"], ["83700.80", "5.290171"], ["83709.20", "5.107751"], ["83717.60", "4.286863"], ["83726.00", "5.198961"], ["83734.40", "5.472590"], ["83742.80", "4.195653"], ["83751.20", "4.013233"], ["83759.60", "5.655010"], ["83768.00", "4.925331"], ["83772.92", "0"]], "bids": [["83480.00", "0.000017"], ["83449.60", "4.195653"], ["83441.20", "4.286863"], ["83424.40", "4.742912"], ["83416.00", "5.563800"], ["83407.60", "4.834122"], ["83390.80", "5.290171"], ["83382.40", "5.016541"], ["83374.00", "5.381380"], ["83365.60", "4.104443"], ["83357.20", "5.107751"], ["83348.80", "3.922023"], ["83340.40", "4.560492"], ["83332.00", "4.378072"], ["83323.60", "4.013233"], ["83315.20", "5.472590"], ["83306.80", "4.469282"], ["83298.40", "4.925331"], ["83290.00", "5.655010"]], "checksum": -2026382245, "ts": "1742377119093"}], "ts": 1742377119097, "record_time": 1742377119.983602}
{"action": "update", "arg": {"instType": "SPOT", "channel": "books", "instId": "BTCUSDT"}, "data": [{"asks": [["83531.84", "4.442358"], ["83564.56", "0"], ["83616.80", "4.925331"], ["83625.20", "5.655010"], ["83633.60", "4.013233"], ["83642.00", "5.472590"], ["83650.40", "4.742912"], ["83658.80", "4.834122"], ["83667.20", "4.469282"], ["83675.60", "4.286863"], ["83684.00", "4.104443"], ["83692.40", "5.107751"], ["83700.80", "5.381380"], ["83709.20", "5.016541"], ["83717.60", "3.922023"], ["83726.00", "4.651702"], ["83734.40", "5.198961"], ["83742.80", "4.560492"], ["83751.20", "5.563800"], ["83759.60", "4.195653"], ["83768.00", "4.378072"], ["83772.92", "0.000293"]], "bids": [["83519.99", "0.045996"], ["83519.61", "0"], ["83493.40", "5.993551"], ["83491.40", "15.772502"], ["83479.00", "0.000032"], ["83449.60", "5.381380"], ["83441.20", "5.107751"], ["83432.80", "5.472590"], ["83424.40", "5.655010"], ["83416.00", "4.104443"], ["83407.60", "5.198961"], ["83399.20", "4.834122"], ["83390.80", "4.013233"], ["83382.40", "3.922023"], ["83374.00", "4.469282"], ["83365.60", "4.378072"], ["83357.20", "5.290171"], ["83348.80", "4.742912"], ["83340.40", "4.925331"], ["83332.00", "5.016541"], ["83323.60", "5.563800"], ["83315.20", "4.195653"], ["83306.80", "4.286863"], ["83298.40", "4.651702"], ["83290.00", "4.560492"]], "checksum": 598349440, "ts": "1742377119298"}], "ts": 1742377119302, "record_time": 1742377120.182837}
{"action": "update", "arg": {"instType": "SPOT", "channel": "books", "instId": "BTCUSDT"}, "data": [{"asks": [["83531.84", "4.769568"], ["83554.95", "0.179480"], ["83616.80", "4.195653"], ["83625.20", "4.378072"], ["83633.60", "4.286863"], ["83642.00", "5.107751"], ["83650.40", "5.472590"], ["83658.80", "4.742912"], ["83667.20", "5.290171"], ["83675.60", "4.104443"], ["83684.00", "5.563800"], ["83692.40", "5.016541"], ["83709.20", "4.469282"], ["83717.60", "5.655010"], ["83726.00", "3.922023"], ["83734.40", "4.925331"], ["83751.20", "4.651702"], ["83759.60", "4.834122"], ["83768.00", "4.013233"], ["83772.92", "0"]], "bids": [["83524.38", "0"], ["83499.40", "0.328661"], ["83497.40", "0.864898"], ["83495.40", "2.276048"], ["83493.40", "5.989600"], ["83491.40", "15.762105"], ["83449.60", "4.469282"], ["83441.20", "4.834122"], ["83432.80", "4.195653"], ["83416.00", "5.016541"], ["83407.60", "4.013233"], ["83399.20", "4.742912"], ["83390.80", "4.560492"], ["83382.40", "4.651702"], ["83374.00", "3.922023"], ["83365.60", "4.104443"], ["83357.20", "4.378072"], ["83348.80", "5.290171"], ["83340.40", "5.563800"], ["83332.00", "5.107751"], ["83323.60", "5.381380"], ["83315.20", "4.286863"], ["83306.80", "5.198961"], ["83298.40", "4.925331"], ["83290.00", "5.472590"], ["82920.59", "0.000008"]], "checksum": 193940226, "ts": "1742377119500"}], "ts": 1742377119505, "record_time": 1742377120.460317}
{"action": "update", "arg": {"instType": "SPOT", "channel": "books", "instId": "BTCUSDT"}, "data": [{"asks": [["83567.89", "0.133246"], ["83573.00", "3.079075"], ["83575.00", "8.102830"], ["83616.80", "4.286863"], ["83625.20", "5.107751"], ["83633.59", "0"], ["83633.60", "4.378072"], ["83642.00", "4.013233"], ["83650.40", "4.195653"], ["83658.80", "4.925331"], ["83667.20", "4.560492"], ["83684.00", "4.834122"], ["83700.80", "4.651702"], ["83709.20", "5.472590"], ["83726.00", "4.469282"], ["83734.40", "4.742912"], ["83742.80", "5.198961"], ["83751.20", "3.922023"], ["83759.60", "5.563800"], ["83768.00", "5.381380"], ["83772.92", "0.000293"]], "bids": [["83526.20", "0.050696"], ["83481.00", "0.000015"], ["83449.60", "5.381380"], ["83441.20", "5.016541"], ["83424.40", "5.107751"], ["83416.00", "4.469282"], ["83407.60", "5.198961"], ["83399.20", "4.104443"], ["83390.80", "4.013233"], ["83382.40", "5.563800"], ["83374.00", "4.560492"], ["83365.60", "5.655010"], ["83357.20", "4.925331"], ["83348.80", "3.922023"], ["83340.40", "5.290171"], ["83332.00", "4.742912"], ["83323.60", "4.286863"], ["83315.20", "4.834122"], ["83306.80", "4.378072"], ["83298.40", "5.472590"], ["83290.00", "4.651702"], ["82921.48", "0"], ["82920.59", "0"]], "checksum": 1131216390, "ts": "1742377119702"}], "ts": 1742377119707, "record_time": 1742377120.589462}
{"action": "update", "arg": {"instType": "SPOT", "channel": "books", "instId": "BTCUSDT"}, "data": [{"asks": [["83616.80", "5.381380"], ["83625.20", "4.195653"], ["83633.60", "5.290171"], ["83642.00", "5.472590"], ["83650.40", "5.016541"], ["83658.79", "0.417168"], ["83658.80", "3.922023"], ["83667.20", "4.651702"], ["83675.60", "4.469282"], ["83684.00", "5.107751"], ["83692.40", "5.655010"], ["83700.80", "4.013233"], ["83709.20", "5.198961"], ["83717.60", "4.104443"], ["83726.00", "5.563800"], ["83734.40", "4.925331"], ["83742.80", "4.286863"], ["83751.20", "4.378072"], ["83759.60", "4.834122"], ["83768.00", "4.742912"], ["83772.92", "0"]], "bids": [["83520.46", "0.045995"], ["83519.99", "0"], ["83501.40", "0.124856"], ["83497.40", "0.864653"], ["83495.40", "2.275403"], ["83493.40", "5.987904"], ["83491.40", "15.757641"], ["83480.00", "0"], ["83449.60", "4.742912"], ["83441.20", "5.472590"], ["83432.80", "5.655010"], ["83424.40", "4.925331"], ["83416.00", "4.651702"], ["83407.60", "4.378072"], ["83399.20", "5.563800"], ["83382.40", "5.381380"], ["83374.00", "3.922023"], ["83365.60", "5.198961"], ["83357.20", "4.195653"], ["83348.80", "4.560492"], ["83340.40", "5.107751"], ["83332.00", "4.104443"], ["83315.20", "5.290171"], ["83306.80", "4.469282"], ["83298.40", "4.834122"], ["83290.00", "5.016541"], ["82921.48", "0.000297"]], "checksum": 941326433, "ts": "1742377119905"}], "ts": 1742377119908, "record_time": 1742377120.788659}
{"action": "update", "arg": {"instType": "SPOT", "channel": "books", "instId": "BTCUSDT"}, "data": [{"asks": [["83531.84", "4.442358"], ["83616.80", "4.013233"], ["83625.20", "5.655010"], ["83633.60", "4.651702"], ["83650.40", "4.742912"], ["83658.80", "4.834122"], ["83667.20", "5.198961"], ["83675.60", "4.378072"], ["83684.00", "5.381380"], ["83692.40", "5.563800"], ["83700.80", "4.560492"], ["83709.20", "4.925331"], ["83717.60", "5.290171"], ["83726.00", "4.469282"], ["83734.40", "5.107751"], ["83751.20", "4.195653"], ["83759.60", "5.016541"], ["83768.00", "4.104443"]], "bids": [["83526.20", "0"], ["83499.40", "0.328429"], ["83497.40", "0.864287"], ["83495.40", "2.274439"], ["83493.40", "5.985366"], ["83491.40", "15.750964"], ["83486.70", "0"], ["83484.40", "0.035910"], ["83449.60", "4.834122"], ["83432.80", "4.742912"], ["83424.40", "4.286863"], ["83416.00", "5.016541"], ["83407.60", "5.563800"], ["83399.20", "4.104443"], ["83390.80", "5.107751"], ["83382.40", "4.469282"], ["83365.60", "5.290171"], ["83348.80", "4.925331"], ["83340.40", "4.560492"], ["83332.00", "4.651702"], ["83323.60", "5.655010"], ["83315.20", "5.381380"], ["83306.80", "4.378072"], ["83298.40", "4.013233"], ["83290.00", "5.198961"], ["82920.59", "0.000008"], ["82920.00", "0.002447"]], "checksum": -1113517201, "ts": "1742377120108"}], "ts": 1742377120112, "record_time": 1742377120.99245}
{"action": "update", "arg": {"instType": "SPOT", "channel": "books", "instId": "BTCUSDT"}, "data": [{"asks": [["83531.84", "4.769568"], ["83616.80", "4.104443"], ["83625.20", "5.290171"], ["83633.60", "4.013233"], ["83642.00", "4.925331"], ["83650.40", "4.651702"], ["83658.80", "5.381380"], ["83667.20", "4.834122"], ["83675.60", "5.016541"], ["83684.00", "4.469282"], ["83692.40", "5.107751"], ["83700.80", "3.922023"], ["83709.20", "4.560492"], ["83717.60", "5.655010"], ["83726.00", "4.742912"], ["83734.40", "5.563800"], ["83742.80", "4.378072"], ["83751.20", "5.198961"], ["83759.60", "5.472590"], ["83768.00", "4.195653"]], "bids": [["83526.87", "0.050696"], ["83520.46", "0"], ["83449.60", "5.472590"], ["83441.20", "4.195653"], ["83432.80", "5.655010"], ["83424.40", "5.198961"], ["83416.00", "5.381380"], ["83407.60", "4.834122"], ["83399.20", "5.563800"], ["83390.80", "4.469282"], ["83382.40", "4.104443"], ["83374.00", "4.286863"], ["83365.60", "3.922023"], ["83357.20", "4.560492"], ["83348.80", "5.016541"], ["83340.40", "4.742912"], ["83332.00", "5.107751"], ["83323.60", "5.290171"], ["83315.20", "4.378072"], ["83306.80", "4.651702"], ["83290.00", "4.925331"]], "checksum": -624591375, "ts": "1742377120312"}], "ts": 1742377120316, "record_time": 1742377121.19891}
{"action": "update", "arg": {"instType": "SPOT", "channel": "books", "instId": "BTCUSDT"}, "data": [{"asks": [["83531.85", "0.168157"], ["83551.66", "0.016429"], ["83554.45", "0"], ["83565.00", "0.064314"], ["83567.00", "0.169248"], ["83569.00", "0.445390"], ["83571.00", "1.172079"], ["83573.00", "3.084419"], ["83575.00", "8.116891"], ["83616.80", "5.563800"], ["83625.20", "4.742912"], ["83642.00", "5.016541"], ["83658.80", "5.198961"], ["83667.20", "5.107751"], ["83675.60", "4.195653"], ["83692.40", "5.381380"], ["83700.80", "4.286863"], ["83709.20", "5.290171"], ["83717.60", "5.472590"], ["83726.00", "4.925331"], ["83734.40", "4.378072"], ["83742.80", "4.560492"], ["83751.20", "4.104443"], ["83759.60", "4.834122"], ["83768.00", "5.655010"]], "bids": [["83520.85", "0.045995"], ["83503.49", "0"], ["83500.71", "0.041758"], ["83493.40", "5.985550"], ["83491.40", "15.751447"], ["83481.00", "0.000032"], ["83479.00", "0.000017"], ["83449.60", "5.381380"], ["83441.20", "5.290171"], ["83432.80", "4.286863"], ["83424.40", "3.922023"], ["83416.00", "5.655010"], ["83407.60", "4.469282"], ["83399.20", "5.016541"], ["83390.80", "5.472590"], ["83382.40", "4.742912"], ["83374.00", "4.560492"], ["83365.60", "4.651702"], ["83357.20", "4.925331"], ["83348.80", "5.107751"], ["83340.40", "5.198961"], ["83332.00", "5.563800"], ["83323.60", "4.013233"], ["83315.20", "4.834122"], ["83306.80", "4.195653"], ["83298.40", "4.104443"], ["83290.00", "4.378072"]], "checksum": -2005730771, "ts": "1742377120515"}], "ts": 1742377120519, "record_time": 1742377121.401068}
{"action": "update", "arg": {"instType": "SPOT", "channel": "books", "instId": "BTCUSDT"}, "data": [{"asks": [["83564.99", "0.082054"], ["83575.00", "8.117003"], ["83575.30", "0.948870"], ["83576.30", "0.143700"], ["83577.60", "0"], ["83578.50", "0.075060"], ["83579.80", "0.673410"], ["83581.70", "0.649140"], ["83585.50", "0.035910"], ["83590.20", "0.457320"], ["83625.20", "4.104443"], ["83633.60", "4.469282"], ["83642.00", "5.655010"], ["83650.40", "4.378072"], ["83658.80", "4.286863"], ["83675.60", "3.922023"], ["83684.00", "5.198961"], ["83692.40", "4.651702"], ["83700.80", "5.472590"], ["83709.20", "5.016541"], ["83717.60", "4.195653"], ["83726.00", "5.290171"], ["83734.40", "4.013233"], ["83742.80", "4.834122"], ["83751.20", "4.742912"], ["83759.60", "5.381380"], ["83768.00", "4.560492"], ["83772.88", "0"]], "bids": [["83526.87", "0"], ["83524.33", "0"], ["83522.07", "0"], ["83521.80", "0"], ["83518.86", "0"], ["83518.17", "0.013175"], ["83517.62", "0.112437"], ["83509.40", "0.002492"], ["83507.84", "0"], ["83507.40", "0.006558"], ["83505.40", "0.017258"], ["83503.40", "0.045415"], ["83501.40", "0.119513"], ["83499.40", "0.314316"], ["83497.40", "0.827148"], ["83495.40", "2.176707"], ["83493.40", "5.728176"], ["83491.40", "15.074147"], ["83490.80", "0.336660"], ["83490.60", "0.431280"], ["83490.50", "0.215640"], ["83484.80", "0.026490"], ["83484.40", "0"], ["83455.73", "0"], ["83455.35", "0"], ["83449.60", "4.286863"], ["83441.20", "5.563800"], ["83432.80", "4.378072"], ["83429.27", "0.072538"], ["83428.31", "0.072173"], ["83424.40", "4.195653"], ["83416.00", "5.016541"], ["83407.60", "4.104443"], ["83399.20", "4.469282"], ["83390.80", "4.560492"], ["83382.40", "5.655010"], ["83374.00", "4.834122"], ["83365.60", "4.742912"], ["83357.20", "4.651702"], ["83348.80", "3.922023"], ["83340.40", "5.381380"], ["83332.00", "5.472590"], ["83323.60", "5.290171"], ["83315.20", "4.925331"], ["83306.80", "5.198961"], ["83298.40", "5.107751"], ["83290.00", "4.013233"], ["83194.82", "0.209200"], ["82918.68", "0.000024"], ["82918.37", "0.000085"], ["82917.65", "0.000105"]], "checksum": -35095940, "ts": "1742377120717"}], "ts": 1742377120720, "record_time": 1742377121.610838}
{"action": "update", "arg": {"instType": "SPOT", "channel": "books", "instId": "BTCUSDT"}, "data": [{"asks": [["83531.84", "4.442358"], ["83557.00", "0.001528"], ["83559.00", "0.004021"], ["83561.00", "0.010581"], ["83563.00", "0.027845"], ["83565.00", "0.073277"], ["83567.00", "0.192833"], ["83569.00", "0.507456"], ["83571.00", "1.335411"], ["83573.00", "3.514238"], ["83575.00", "9.247994"], ["83575.30", "0.778980"], ["83585.30", "1.401300"], ["83585.40", "2.369970"], ["83587.69", "0.397880"], ["83587.90", "1.368150"], ["83590.20", "0.228000"], ["83616.80", "4.013233"], ["83625.20", "4.560492"], ["83633.60", "4.378072"], ["83642.00", "4.742912"], ["83650.40", "4.195653"], ["83658.79", "0"], ["83667.20", "4.104443"], ["83675.60", "4.651702"], ["83684.00", "4.834122"], ["83692.40", "5.655010"], ["83700.80", "5.016541"], ["83709.20", "4.469282"], ["83717.60", "5.290171"], ["83726.00", "4.925331"], ["83734.40", "3.922023"], ["83742.80", "5.381380"], ["83751.20", "5.107751"], ["83759.60", "5.198961"], ["83768.00", "5.472590"], ["83772.73", "0"]], "bids": [["83527.18", "0.050696"], ["83521.29", "0.045995"], ["83520.85", "0"], ["83515.40", "0.239724"], ["83501.40", "0.119380"], ["83499.40", "0.314158"], ["83498.70", "2.544502"], ["83497.40", "0.826731"], ["83495.40", "2.175710"], ["83493.40", "5.725554"], ["83491.40", "15.067246"], ["83486.60", "0.498930"], ["83449.60", "3.922023"], ["83441.20", "5.198961"], ["83432.80", "4.469282"], ["83416.00", "5.655010"], ["83399.20", "5.107751"], ["83390.80", "5.381380"], ["83382.40", "4.013233"], ["83365.60", "5.290171"], ["83357.20", "5.472590"], ["83348.80", "4.651702"], ["83340.40", "5.563800"], ["83332.00", "4.378072"], ["83323.60", "4.742912"], ["83315.20", "4.560492"], ["83306.80", "4.286863"], ["83298.40", "5.016541"], ["83290.00", "4.925331"], ["82918.68", "0"], ["82918.37", "0"], ["82917.65", "0"]], "checksum": -165269432, "ts": "1742377120930"}], "ts": 1742377120934, "record_time": 1742377121.814968}
{"action": "update", "arg": {"instType": "SPOT", "channel": "books", "instId": "BTCUSDT"}, "data": [{"asks": [["83531.84", "4.769568"], ["83531.85", "0.162975"], ["83616.80", "4.104443"], ["83625.20", "5.655010"], ["83633.60", "3.922023"], ["83642.00", "4.651702"], ["83650.40", "4.560492"], ["83658.80", "4.013233"], ["83667.20", "4.469282"], ["83675.60", "5.290171"], ["83684.00", "5.563800"], ["83692.40", "5.472590"], ["83700.80", "5.198961"], ["83709.20", "4.378072"], ["83717.60", "4.286863"], ["83726.00", "5.107751"], ["83734.40", "4.195653"], ["83742.80", "4.742912"], ["83751.20", "5.381380"], ["83759.60", "4.834122"], ["83768.00", "5.016541"]], "bids": [["83496.00", "0.000032"], ["83493.20", "0.130342"], ["83491.40", "15.067023"], ["83480.00", "0.000015"], ["83479.00", "0"], ["83466.70", "0"], ["83463.90", "0.207716"], ["83449.60", "5.472590"], ["83441.20", "5.016541"], ["83432.80", "4.013233"], ["83424.40", "5.655010"], ["83416.00", "4.286863"], ["83407.60", "4.560492"], ["83399.20", "4.104443"], ["83382.40", "5.107751"], ["83374.00", "4.651702"], ["83365.60", "5.198961"], ["83357.20", "4.742912"], ["83348.80", "5.563800"], ["83340.40", "4.925331"], ["83332.00", "4.195653"], ["83323.60", "4.469282"], ["83315.20", "4.834122"], ["83306.80", "3.922023"], ["83298.40", "5.290171"], ["83290.00", "4.378072"], ["82920.00", "0"]], "checksum": -1926358216, "ts": "1742377121149"}], "ts": 1742377121153, "record_time": 1742377122.036692}
{"action": "update", "arg": {"instType": "SPOT", "channel": "books", "instId": "BTCUSDT"}, "data": [{"asks": [["83531.84", "4.797218"], ["83616.80", "5.563800"], ["83625.20", "4.469282"], ["83633.60", "5.472590"], ["83642.00", "4.834122"], ["83650.40", "4.742912"], ["83658.80", "4.925331"], ["83667.20", "4.378072"], ["83675.60", "4.286863"], ["83684.00", "5.107751"], ["83692.40", "5.290171"], ["83700.80", "4.651702"], ["83709.20", "3.922023"], ["83717.60", "5.381380"], ["83726.00", "5.655010"], ["83734.40", "5.016541"], ["83742.80", "5.198961"], ["83751.20", "4.013233"], ["83759.60", "4.195653"], ["83768.00", "4.560492"]], "bids": [["83521.29", "0"], ["83495.40", "2.175468"], ["83493.40", "5.724918"], ["83491.40", "15.065572"], ["83449.60", "4.834122"], ["83441.20", "4.742912"], ["83432.80", "4.651702"], ["83424.40", "4.286863"], ["83416.00", "5.472590"], ["83407.60", "4.104443"], ["83399.20", "5.107751"], ["83382.40", "4.560492"], ["83374.00", "5.563800"], ["83365.60", "4.925331"], ["83357.20", "4.469282"], ["83348.80", "4.013233"], ["83340.40", "5.198961"], ["83332.00", "5.290171"], ["83323.60", "3.922023"], ["83315.20", "5.016541"], ["83306.80", "4.195653"], ["83298.40", "4.378072"], ["83290.00", "5.655010"], ["82920.00", "0.002447"]], "checksum": -1585025907, "ts": "1742377121348"}], "ts": 1742377121375, "record_time": 1742377122.257428}
{"action": "update", "arg": {"instType": "SPOT", "channel": "books", "instId": "BTCUSDT"}, "data": [{"asks": [["83531.84", "4.803921"], ["83571.00", "1.335655"], ["83573.00", "3.514881"], ["83575.00", "9.249687"], ["83581.10", "0.123510"], ["83587.70", "3.504180"], ["83589.60", "0.179640"], ["83590.20", "0"], ["83616.80", "4.560492"], ["83625.20", "5.563800"], ["83633.60", "4.104443"], ["83642.00", "5.198961"], ["83650.40", "4.651702"], ["83658.80", "4.286863"], ["83667.20", "4.195653"], ["83675.60", "5.472590"], ["83684.00", "5.655010"], ["83692.40", "5.016541"], ["83700.80", "4.469282"], ["83709.20", "4.013233"], ["83717.60", "5.290171"], ["83726.00", "5.107751"], ["83734.40", "4.378072"], ["83742.80", "3.922023"], ["83751.20", "4.742912"], ["83759.60", "5.381380"], ["83768.00", "4.834122"]], "bids": [["83527.18", "0"], ["83521.66", "0.045995"], ["83505.40", "0.017141"], ["83503.40", "0.045107"], ["83501.40", "0.118704"], ["83499.40", "0.312379"], ["83497.40", "0.822049"], ["83495.40", "2.163289"], ["83493.40", "5.692864"], ["83491.40", "14.981221"], ["83449.60", "5.655010"], ["83441.20", "4.286863"], ["83432.80", "5.198961"], ["83424.40", "4.651702"], ["83416.00", "4.104443"], ["83407.60", "5.472590"], ["83399.20", "4.195653"], ["83390.80", "5.016541"], ["83382.40", "4.742912"], ["83374.00", "4.013233"], ["83357.20", "3.922023"], ["83348.80", "5.381380"], ["83340.40", "5.107751"], ["83332.00", "4.469282"], ["83323.60", "4.560492"], ["83315.20", "4.834122"], ["83306.80", "5.290171"], ["83290.00", "5.563800"]], "checksum": 1728460283, "ts": "1742377121561"}], "ts": 1742377121565, "record_time": 1742377122.446015}
{"action": "update", "arg": {"instType": "SPOT", "channel": "books", "instId": "BTCUSDT"}, "data": [{"asks": [["83541.88", "0.001387"], ["83542.91", "0"], ["83543.28", "0"], ["83543.85", "0"], ["83544.80", "0"], ["83546.18", "0.035952"], ["83546.54", "0.119843"], ["83546.73", "0"], ["83547.70", "0.035960"], ["83548.53", "0"], ["83549.90", "0.010994"], ["83551.79", "0.006357"], ["83554.95", "0"], ["83566.99", "0.210113"], ["83567.00", "0.192868"], ["83567.89", "0"], ["83569.00", "0.507549"], ["83581.10", "0.022740"], ["83585.10", "0.012450"], ["83587.90", "1.355850"], ["83611.48", "0"], ["83616.80", "5.290171"], ["83625.20", "4.925331"], ["83633.60", "5.563800"], ["83642.00", "5.655010"], ["83650.40", "4.013233"], ["83658.80", "5.107751"], ["83667.20", "5.381380"], ["83675.60", "5.016541"], ["83684.00", "4.195653"], ["83692.40", "4.560492"], ["83700.80", "4.651702"], ["83709.20", "4.834122"], ["83717.60", "5.198961"], ["83726.00", "4.742912"], ["83734.40", "3.922023"], ["83742.80", "5.472590"], ["83751.20", "4.104443"], ["83759.60", "4.378072"], ["83768.00", "4.469282"], ["83772.73", "0.000008"]], "bids": [["83506.09", "0.090631"], ["83505.61", "0.247058"], ["83504.26", "0.084435"], ["83502.92", "0"], ["83502.82", "0"], ["83502.46", "0.056175"], ["83501.36", "0"], ["83500.50", "0.017470"], ["83499.40", "0.312163"], ["83499.29", "0"], ["83497.40", "0.821482"], ["83497.25", "0"], ["83495.40", "2.161795"], ["83493.40", "5.688934"], ["83491.40", "14.970880"], ["83486.60", "0.309750"], ["83485.90", "0"], ["83484.20", "0.005370"], ["83480.00", "0.000032"], ["83449.60", "4.469282"], ["83441.20", "5.016541"], ["83432.80", "5.563800"], ["83424.40", "5.381380"], ["83416.00", "5.472590"], ["83407.60", "4.013233"], ["83399.20", "3.922023"], ["83390.80", "4.378072"], ["83382.40", "5.290171"], ["83374.00", "5.198961"], ["83365.60", "4.834122"], ["83357.20", "5.107751"], ["83348.80", "4.651702"], ["83340.40", "5.655010"], ["83332.00", "4.104443"], ["83323.60", "4.742912"], ["83315.20", "4.286863"], ["83306.80", "4.560492"], ["83298.40", "4.925331"], ["83290.00", "4.195653"]], "checksum": 1166481695, "ts": "1742377121767"}], "ts": 1742377121770, "record_time": 1742377122.652114}
{"action": "update", "arg": {"instType": "SPOT", "channel": "books", "instId": "BTCUSDT"}, "data": [{"asks": [["83546.53", "0.111877"], ["83546.72", "0"], ["83553.87", "0.185583"], ["83571.00", "1.335411"], ["83573.00", "3.514238"], ["83575.00", "9.247994"], ["83587.69", "0"], ["83587.70", "3.506070"], ["83616.80", "5.655010"], ["83625.20", "4.378072"], ["83633.60", "5.290171"], ["83642.00", "5.563800"], ["83650.40", "5.016541"], ["83658.80", "4.469282"], ["83667.20", "3.922023"], ["83675.60", "4.286863"], ["83684.00", "5.381380"], ["83692.40", "4.651702"], ["83700.80", "4.195653"], ["83709.20", "4.925331"], ["83717.60", "4.742912"], ["83726.00", "4.834122"], ["83734.40", "5.107751"], ["83742.80", "4.104443"], ["83751.20", "4.560492"], ["83759.60", "5.472590"], ["83768.00", "4.013233"]], "bids": [["83526.78", "0.050696"], ["83522.00", "0.045995"], ["83521.66", "0"], ["83495.40", "2.162037"], ["83493.40", "5.689570"], ["83491.40", "14.972554"], ["83449.60", "4.195653"], ["83441.20", "5.381380"], ["83432.80", "4.286863"], ["83424.40", "4.651702"], ["83416.00", "4.013233"], ["83407.60", "4.469282"], ["83399.20", "5.563800"], ["83390.80", "5.655010"], ["83382.40", "4.378072"], ["83374.00", "3.922023"], ["83365.60", "4.104443"], ["83357.20", "4.742912"], ["83348.80", "4.834122"], ["83340.40", "5.290171"], ["83332.00", "4.560492"], ["83323.60", "5.107751"], ["83315.20", "5.016541"], ["83306.80", "5.472590"], ["83290.00", "5.198961"], ["82920.00", "0"]], "checksum": 1598182319, "ts": "1742377121973"}], "ts": 1742377121977, "record_time": 1742377122.878245}
{"action": "update", "arg": {"instType": "SPOT", "channel": "books", "instId": "BTCUSDT"}, "data": [{"asks": [["83531.85", "0.162705"], ["83571.00", "1.335652"], ["83573.00", "3.514874"], ["83575.00", "9.249668"], ["83579.80", "0.459810"], ["83583.40", "0.798900"], ["83583.90", "0.102090"], ["83585.30", "0"], ["83585.40", "0"], ["83616.79", "0.278179"], ["83616.80", "4.104443"], ["83625.20", "4.925331"], ["83633.60", "4.195653"], ["83642.00", "5.472590"], ["83650.40", "5.381380"], ["83658.80", "4.834122"], ["83667.20", "5.655010"], ["83684.00", "4.742912"], ["83700.80", "5.198961"], ["83709.20", "5.290171"], ["83717.60", "4.560492"], ["83726.00", "5.016541"], ["83734.40", "4.378072"], ["83742.80", "5.107751"], ["83751.20", "5.563800"], ["83759.60", "4.013233"], ["83768.00", "4.469282"]], "bids": [["83523.47", "0.209200"], ["83507.40", "0.006779"], ["83505.62", "0.115927"], ["83505.40", "0.017841"], ["83503.40", "0.046949"], ["83501.40", "0.123551"], ["83499.40", "0.325133"], ["83497.40", "0.855614"], ["83495.40", "2.251615"], ["83493.40", "5.925302"], ["83491.40", "15.592901"], ["83481.00", "0.000017"], ["83449.60", "5.016541"], ["83441.20", "4.286863"], ["83432.80", "4.925331"], ["83424.40", "4.195653"], ["83416.00", "4.560492"], ["83407.60", "5.655010"], ["83390.80", "4.651702"], ["83382.40", "3.922023"], ["83374.00", "5.381380"], ["83365.60", "4.834122"], ["83357.20", "4.013233"], ["83348.80", "5.198961"], ["83340.40", "4.742912"], ["83332.00", "5.472590"], ["83323.60", "4.104443"], ["83315.20", "4.378072"], ["83306.80", "5.290171"], ["83298.40", "4.469282"], ["83290.00", "5.107751"], ["82921.48", "0"], ["82920.59", "0"]], "checksum": -226586824, "ts": "1742377122205"}], "ts": 1742377122208, "record_time": 1742377123.090159}
{"action": "update", "arg": {"instType": "SPOT", "channel": "books", "instId": "BTCUSDT"}, "data": [{"asks": [["83557.00", "0.001409"], ["83559.00", "0.003529"], ["83561.00", "0.009286"], ["83563.00", "0.024439"], ["83565.00", "0.064311"], ["83567.00", "0.169241"], ["83569.00", "0.445371"], ["83571.00", "1.172028"], ["83573.00", "3.084284"], ["83575.00", "8.116538"], ["83579.20", "0.015000"], ["83583.90", "0"], ["83625.20", "5.563800"], ["83633.60", "5.381380"], ["83642.00", "5.655010"], ["83650.40", "4.925331"], ["83658.80", "5.198961"], ["83667.20", "5.016541"], ["83675.60", "4.651702"], ["83684.00", "5.472590"], ["83692.40", "4.286863"], ["83700.80", "3.922023"], ["83709.20", "4.378072"], ["83717.60", "4.742912"], ["83726.00", "5.107751"], ["83734.40", "4.013233"], ["83742.80", "4.834122"], ["83751.20", "4.469282"], ["83759.60", "5.290171"], ["83768.00", "4.560492"]], "bids": [["83528.22", "0.036897"], ["83526.78", "0"], ["83522.00", "0"], ["83503.40", "0.046972"], ["83501.40", "0.123613"], ["83499.40", "0.325295"], ["83497.40", "0.856040"], ["83495.40", "2.252738"], ["83493.40", "5.928256"], ["83491.40", "15.600676"], ["83488.50", "0.071820"], ["83486.60", "0.610470"], ["83485.10", "0"], ["83484.90", "0.179550"], ["83484.20", "0"], ["83481.00", "0"], ["83449.60", "5.563800"], ["83441.20", "4.651702"], ["83432.80", "5.016541"], ["83416.00", "4.104443"], ["83407.60", "4.013233"], ["83400.73", "0"], ["83399.20", "4.469282"], ["83390.80", "3.922023"], ["83382.40", "4.925331"], ["83374.00", "4.834122"], ["83365.60", "4.560492"], ["83357.20", "5.381380"], ["83348.80", "5.107751"], ["83340.40", "5.655010"], ["83332.00", "5.290171"], ["83323.60", "4.378072"], ["83315.20", "4.742912"], ["83306.80", "4.286863"], ["83298.40", "5.198961"], ["83290.00", "5.472590"], ["82921.48", "0.000297"], ["82920.59", "0.000008"], ["82920.00", "0.002447"]], "checksum": 1374664637, "ts": "1742377122405"}], "ts": 1742377122410, "record_time": 1742377123.297386}
{"action": "update", "arg": {"instType": "SPOT", "channel": "books", "instId": "BTCUSDT"}, "data": [{"asks": [["83579.30", "0.666150"], ["83584.21", "0.001598"], ["83584.94", "0"], ["83589.80", "0"], ["83616.80", "5.198961"], ["83625.20", "5.655010"], ["83633.60", "4.560492"], ["83642.00", "4.742912"], ["83650.40", "5.290171"], ["83658.80", "4.834122"], ["83667.20", "4.378072"], ["83675.60", "4.469282"], ["83684.00", "4.286863"], ["83692.40", "3.922023"], ["83700.80", "5.016541"], ["83709.20", "4.104443"], ["83717.60", "5.472590"], ["83726.00", "4.651702"], ["83734.40", "5.563800"], ["83742.80", "4.195653"], ["83751.20", "4.925331"], ["83759.60", "5.107751"], ["83768.00", "4.013233"]], "bids": [["83522.37", "0.045994"], ["83490.80", "1.005090"], ["83471.51", "0"], ["83470.78", "0.001182"], ["83449.60", "5.472590"], ["83441.20", "5.655010"], ["83432.80", "4.651702"], ["83416.00", "4.742912"], ["83407.60", "5.016541"], ["83399.20", "5.198961"], ["83396.15", "0.132126"], ["83390.80", "4.560492"], ["83382.40", "5.381380"], ["83374.00", "4.925331"], ["83365.60", "4.013233"], ["83357.20", "4.104443"], ["83348.80", "5.290171"], ["83340.40", "5.107751"], ["83332.00", "3.922023"], ["83323.60", "4.286863"], ["83315.20", "4.834122"], ["83306.80", "5.563800"], ["83298.40", "4.378072"], ["83290.00", "4.469282"], ["82920.59", "0"], ["82920.00", "0"]], "checksum": -110908317, "ts": "1742377122606"}], "ts": 1742377122610, "record_time": 1742377123.49211}
{"action": "update", "arg": {"instType": "SPOT", "channel": "books", "instId": "BTCUSDT"}, "data": [{"asks": [["83560.78", "0.037256"], ["83616.80", "5.107751"], ["83625.20", "4.742912"], ["83633.60", "4.925331"], ["83642.00", "5.290171"], ["83650.40", "5.563800"], ["83658.80", "4.286863"], ["83667.20", "5.472590"], ["83675.60", "4.104443"], ["83684.00", "3.922023"], ["83692.40", "4.651702"], ["83700.80", "4.834122"], ["83709.20", "5.016541"], ["83717.60", "5.198961"], ["83726.00", "4.469282"], ["83734.40", "4.560492"], ["83742.80", "5.655010"], ["83751.20", "4.013233"], ["83759.60", "5.381380"], ["83768.00", "4.195653"], ["83772.73", "0"]], "bids": [["83499.40", "0.325451"], ["83497.40", "0.856449"], ["83495.40", "2.253815"], ["83493.40", "5.931091"], ["83491.40", "15.608134"], ["83479.00", "0.000015"], ["83449.60", "4.104443"], ["83441.20", "5.198961"], ["83432.80", "5.472590"], ["83424.40", "4.013233"], ["83416.00", "4.651702"], ["83407.60", "4.834122"], ["83399.20", "5.563800"], ["83390.80", "5.381380"], ["83382.40", "4.195653"], ["83374.00", "4.286863"], ["83365.60", "3.922023"], ["83357.20", "4.560492"], ["83348.80", "4.925331"], ["83340.40", "4.469282"], ["83332.00", "5.290171"], ["83323.60", "5.655010"], ["83315.20", "5.107751"], ["83306.80", "4.742912"], ["83290.00", "5.016541"], ["82921.48", "0"]], "checksum": -110908317, "ts": "1742377122809"}], "ts": 1742377122811, "record_time": 1742377123.692631}
{"action": "update", "arg": {"instType": "SPOT", "channel": "books", "instId": "BTCUSDT"}, "data": [{"asks": [["83531.84", "4.476711"], ["83531.85", "0.168157"], ["83579.20", "0"], ["83583.39", "0.240923"], ["83589.60", "0"], ["83589.80", "0.213600"], ["83616.79", "0"], ["83616.80", "5.563800"], ["83625.20", "4.013233"], ["83633.60", "5.107751"], ["83642.00", "4.742912"], ["83650.40", "4.925331"], ["83658.80", "4.651702"], ["83667.20", "5.290171"], ["83675.60", "3.922023"], ["83684.00", "4.469282"], ["83692.40", "5.381380"], ["83700.80", "5.016541"], ["83709.20", "5.655010"], ["83717.60", "4.286863"], ["83726.00", "4.834122"], ["83742.80", "4.195653"], ["83751.20", "5.198961"], ["83759.60", "4.378072"], ["83768.00", "5.472590"], ["83772.73", "0.000008"]], "bids": [["83528.22", "0"], ["83522.69", "0.045994"], ["83522.37", "0"], ["83509.40", "0.002602"], ["83505.40", "0.017858"], ["83503.40", "0.046995"], ["83501.40", "0.123673"], ["83499.40", "0.325454"], ["83497.40", "0.856457"], ["83495.40", "2.253836"], ["83493.40", "5.931148"], ["83491.40", "15.608283"], ["83479.00", "0.000032"], ["83449.60", "5.107751"], ["83441.20", "5.290171"], ["83432.80", "4.104443"], ["83424.40", "4.925331"], ["83416.00", "4.560492"], ["83407.60", "4.013233"], ["83399.20", "4.469282"], ["83390.80", "3.922023"], ["83382.40", "5.016541"], ["83374.00", "4.834122"], ["83365.60", "4.195653"], ["83357.20", "5.563800"], ["83348.80", "5.655010"], ["83340.40", "4.378072"], ["83332.00", "4.651702"], ["83323.60", "5.381380"], ["83315.20", "4.742912"], ["83306.80", "4.286863"], ["83298.40", "5.472590"], ["83290.00", "5.198961"], ["82921.48", "0.000297"]], "checksum": 630087969, "ts": "1742377123008"}], "ts": 1742377123013, "record_time": 1742377123.897863}
{"action": "update", "arg": {"instType": "SPOT", "channel": "books", "instId": "BTCUSDT"}, "data": [{"asks": [["83531.84", "4.803921"], ["83546.09", "0"], ["83546.11", "0"], ["83546.42", "0"], ["83546.81", "0"], ["83546.98", "0"], ["83547.44", "0"], ["83547.80", "0"], ["83548.01", "0"], ["83548.46", "0"], ["83548.62", "0"], ["83548.66", "0.006357"], ["83548.78", "0.006357"], ["83548.93", "0"], ["83549.00", "0"], ["83549.11", "0.006356"], ["83549.13", "0"], ["83549.29", "0"], ["83549.50", "0.006356"], ["83550.13", "0.006356"], ["83550.48", "0.006357"], ["83550.50", "0"], ["83550.65", "0.006357"], ["83550.97", "0"], ["83551.00", "0"], ["83551.26", "0.016429"], ["83551.27", "0.006357"], ["83551.31", "0.006357"], ["83551.68", "0.006357"], ["83551.69", "0.006357"], ["83551.80", "0"], ["83551.98", "0.119885"], ["83552.19", "0.006357"], ["83552.73", "0"], ["83553.37", "0.006357"], ["83553.66", "0.010985"], ["83553.73", "0"], ["83553.97", "0"], ["83554.17", "0"], ["83554.31", "0"], ["83554.64", "0.009990"], ["83555.42", "0.119908"], ["83556.31", "0"], ["83556.42", "0.119881"], ["83556.59", "0.119900"], ["83556.85", "0.015896"], ["83557.00", "0.009989"], ["83558.11", "0"], ["83558.89", "0"], ["83559.15", "0.006357"], ["83560.79", "0.130795"], ["83561.58", "0.010984"], ["83616.80", "4.560492"], ["83625.20", "5.563800"], ["83633.60", "4.104443"], ["83642.00", "4.925331"], ["83650.40", "4.469282"], ["83658.80", "5.655010"], ["83667.20", "5.381380"], ["83675.60", "4.195653"], ["83684.00", "5.290171"], ["83692.40", "4.013233"], ["83700.80", "4.286863"], ["83709.20", "4.742912"], ["83717.60", "4.378072"], ["83726.00", "5.107751"], ["83734.40", "3.922023"], ["83742.80", "5.198961"], ["83751.20", "5.016541"], ["83759.60", "4.834122"], ["83772.88", "0.000023"], ["83772.92", "0.000293"], ["83773.00", "0.000106"], ["83773.14", "0.000275"]], "bids": [["83529.08", "0.036897"], ["83505.40", "0.018012"], ["83504.39", "0.017968"], ["83504.18", "0.018393"], ["83503.84", "0.005979"], ["83503.56", "0.019949"], ["83503.40", "0.047399"], ["83502.85", "0.006612"], ["83502.54", "0.017198"], ["83502.38", "0.007184"], ["83501.99", "0.007373"], ["83501.98", "0.029001"], ["83501.84", "0"], ["83501.69", "0.017179"], ["83501.49", "0"], ["83501.40", "0.124733"], ["83501.39", "0.009048"], ["83501.15", "0"], ["83501.02", "0.227328"], ["83500.90", "0.008233"], ["83500.87", "0"], ["83500.71", "0.025214"], ["83500.17", "0"], ["83500.08", "0.008334"], ["83499.86", "0"], ["83499.73", "0"], ["83499.65", "0"], ["83499.40", "0.328247"], ["83499.37", "0.052245"], ["83499.19", "0"], ["83499.01", "0"], ["83498.85", "0"], ["83498.72", "0"], ["83498.68", "0.018629"], ["83498.34", "0"], ["83498.22", "0"], ["83497.62", "0.270542"], ["83497.40", "0.863806"], ["83497.22", "0"], ["83496.71", "0"], ["83496.68", "0"], ["83496.61", "0.222932"], ["83496.45", "0.262436"], ["83496.21", "0.076567"], ["83496.03", "0.021255"], ["83495.84", "0"], ["83495.40", "2.273174"], ["83494.93", "0"], ["83494.17", "0.012518"], ["83493.93", "0"], ["83493.83", "0"], ["83493.53", "0"], ["83493.40", "5.982037"], ["83493.34", "0"], ["83492.30", "0.073682"], ["83491.42", "0.056696"], ["83491.40", "15.742203"], ["83491.33", "0"], ["83489.62", "0"], ["83488.92", "0.023933"], ["83488.73", "0"], ["83486.45", "0.024139"], ["83486.23", "0"], ["83483.77", "0"], ["83441.20", "4.742912"], ["83432.80", "5.563800"], ["83424.40", "5.016541"], ["83416.00", "4.286863"], ["83407.60", "5.655010"], ["83399.20", "5.381380"], ["83382.40", "4.195653"], ["83374.00", "4.925331"], ["83365.60", "4.834122"], ["83357.20", "4.104443"], ["83348.80", "5.290171"], ["83340.40", "5.472590"], ["83332.00", "4.013233"], ["83323.60", "5.198961"], ["83315.20", "4.469282"], ["83306.80", "4.651702"], ["83298.40", "4.378072"], ["83290.00", "4.560492"], ["82920.59", "0.000008"], ["82920.00", "0.002447"]], "checksum": -1442147866, "ts": "1742377123223"}], "ts": 1742377123228, "record_time": 1742377124.111898}
{"action": "update", "arg": {"instType": "SPOT", "channel": "books", "instId": "BTCUSDT"}, "data": [{"asks": [["83546.53", "0.059541"], ["83582.20", "0.015000"], ["83583.90", "0.103110"], ["83587.80", "2.583480"], ["83589.70", "0"], ["83589.80", "0"], ["83616.80", "4.742912"], ["83625.20", "4.286863"], ["83633.60", "4.469282"], ["83642.00", "5.381380"], ["83650.40", "4.104443"], ["83658.80", "4.925331"], ["83667.20", "5.655010"], ["83675.60", "4.013233"], ["83684.00", "4.834122"], ["83692.40", "4.560492"], ["83700.80", "5.016541"], ["83709.20", "4.651702"], ["83717.60", "5.107751"], ["83726.00", "5.290171"], ["83734.40", "5.198961"], ["83742.80", "3.922023"], ["83751.20", "5.563800"], ["83759.60", "4.378072"], ["83768.00", "4.195653"]], "bids": [["83522.69", "0"], ["83506.39", "0.004092"], ["83503.56", "0.015857"], ["83487.20", "0"], ["83449.60", "4.104443"], ["83441.20", "5.290171"], ["83432.80", "5.655010"], ["83416.00", "4.469282"], ["83407.60", "5.472590"], ["83399.20", "4.378072"], ["83390.80", "4.560492"], ["83382.40", "5.107751"], ["83374.00", "4.195653"], ["83365.60", "5.381380"], ["83357.20", "4.286863"], ["83348.80", "4.651702"], ["83340.40", "4.013233"], ["83332.00", "5.563800"], ["83323.60", "4.834122"], ["83315.20", "4.742912"], ["83306.80", "5.198961"], ["83298.40", "3.922023"], ["83290.00", "4.925331"], ["82918.68", "0.000024"]], "checksum": -2008320801, "ts": "1742377123436"}], "ts": 1742377123439, "record_time": 1742377124.320839}
{"action": "update", "arg": {"instType": "SPOT", "channel": "books", "instId": "BTCUSDT"}, "data": [{"asks": [["83531.85", "0.162705"], ["83549.85", "0.006356"], ["83553.88", "0.006357"], ["83575.00", "8.116649"], ["83611.48", "0.052336"], ["83616.80", "5.107751"], ["83625.20", "4.469282"], ["83633.60", "4.104443"], ["83642.00", "4.560492"], ["83650.40", "5.472590"], ["83658.80", "5.198961"], ["83667.20", "5.563800"], ["83675.60", "5.655010"], ["83684.00", "5.290171"], ["83692.40", "3.922023"], ["83700.80", "5.381380"], ["83717.60", "4.834122"], ["83726.00", "4.742912"], ["83734.40", "4.013233"], ["83742.80", "4.286863"], ["83751.20", "4.925331"], ["83759.60", "4.195653"], ["83768.00", "4.378072"], ["83772.92", "0"], ["83773.00", "0"], ["83773.14", "0"]], "bids": [["83523.04", "0.045994"], ["83503.58", "0.016544"], ["83484.90", "0"], ["83484.20", "0.005370"], ["83480.00", "0"], ["83449.60", "5.198961"], ["83441.20", "5.655010"], ["83432.80", "4.651702"], ["83416.00", "4.195653"], ["83407.60", "3.922023"], ["83399.20", "5.107751"], ["83390.80", "4.286863"], ["83382.40", "4.378072"], ["83374.00", "5.563800"], ["83365.60", "4.925331"], ["83357.20", "4.469282"], ["83348.80", "5.381380"], ["83340.40", "4.834122"], ["83332.00", "4.742912"], ["83323.60", "4.013233"], ["83315.20", "5.472590"], ["83306.80", "4.560492"], ["83298.40", "4.104443"], ["83290.00", "5.290171"], ["82918.68", "0"]], "checksum": 2081169259, "ts": "1742377123637"}], "ts": 1742377123640, "record_time": 1742377124.521092}
{"action": "update", "arg": {"instType": "SPOT", "channel": "books", "instId": "BTCUSDT"}, "data": [{"asks": [["83531.84", "4.476711"], ["83574.99", "0.554651"], ["83575.89", "0"], ["83611.48", "0"], ["83616.80", "3.922023"], ["83625.20", "4.742912"], ["83633.60", "4.013233"], ["83642.00", "4.925331"], ["83650.40", "4.560492"], ["83658.80", "5.107751"], ["83667.20", "5.472590"], ["83684.00", "5.016541"], ["83692.40", "4.195653"], ["83700.80", "4.378072"], ["83709.20", "4.469282"], ["83717.60", "5.198961"], ["83726.00", "4.651702"], ["83734.40", "4.104443"], ["83742.80", "5.290171"], ["83751.20", "5.381380"], ["83759.60", "5.563800"], ["83768.00", "4.834122"], ["83772.92", "0.000293"]], "bids": [["83505.40", "0.017858"], ["83503.40", "0.046997"], ["83501.40", "0.123675"], ["83499.40", "0.325462"], ["83497.40", "0.856477"], ["83495.40", "2.253887"], ["83493.40", "5.931048"], ["83491.40", "15.608023"], ["83449.60", "4.378072"], ["83441.20", "4.651702"], ["83432.80", "5.198961"], ["83424.40", "5.563800"], ["83416.00", "5.472590"], ["83407.60", "4.925331"], ["83399.20", "4.195653"], ["83390.80", "4.469282"], ["83382.40", "5.655010"], ["83374.00", "4.286863"], ["83365.60", "4.104443"], ["83357.20", "4.742912"], ["83348.80", "4.834122"], ["83340.40", "5.016541"], ["83332.00", "3.922023"], ["83323.60", "5.107751"], ["83315.20", "5.290171"], ["83298.40", "4.013233"], ["83290.00", "5.381380"]], "checksum": 295668369, "ts": "1742377123840"}], "ts": 1742377123844, "record_time": 1742377124.726361}
{"action": "update", "arg": {"instType": "SPOT", "channel": "books", "instId": "BTCUSDT"}, "data": [{"asks": [["83531.84", "4.803790"], ["83553.87", "0"], ["83581.69", "0"], ["83583.39", "0"], ["83616.79", "0.055674"], ["83616.80", "4.742912"], ["83625.20", "4.195653"], ["83633.60", "4.286863"], ["83642.00", "4.104443"], ["83650.40", "4.834122"], ["83658.80", "4.925331"], ["83667.20", "4.378072"], ["83675.60", "5.198961"], ["83684.00", "3.922023"], ["83692.40", "4.651702"], ["83700.80", "4.560492"], ["83709.20", "5.107751"], ["83717.60", "5.290171"], ["83726.00", "5.016541"], ["83734.40", "4.013233"], ["83742.80", "5.563800"], ["83751.20", "5.472590"], ["83759.60", "5.381380"], ["83768.00", "4.469282"], ["83773.00", "0.000106"], ["83773.14", "0.000275"]], "bids": [["83523.33", "0.045994"], ["83523.04", "0"], ["83495.40", "2.254073"], ["83493.40", "5.931769"], ["83491.40", "15.609920"], ["83449.60", "5.472590"], ["83441.20", "4.013233"], ["83432.80", "5.381380"], ["83424.40", "5.107751"], ["83416.00", "4.286863"], ["83407.60", "3.922023"], ["83399.20", "4.742912"], ["83390.80", "5.016541"], ["83382.40", "5.563800"], ["83374.00", "4.925331"], ["83365.60", "4.195653"], ["83357.20", "5.655010"], ["83348.80", "4.651702"], ["83340.40", "4.834122"], ["83332.00", "5.290171"], ["83323.60", "5.198961"], ["83315.20", "4.378072"], ["83306.80", "4.469282"], ["83298.40", "4.560492"], ["83290.00", "4.104443"]], "checksum": -1275699697, "ts": "1742377124040"}], "ts": 1742377124045, "record_time": 1742377124.930401}
{"action": "update", "arg": {"instType": "SPOT", "channel": "books", "instId": "BTCUSDT"}, "data": [{"asks": [["83531.84", "4.804191"], ["83553.95", "0.177159"], ["83616.80", "5.290171"], ["83625.20", "4.742912"], ["83633.60", "5.563800"], ["83642.00", "4.925331"], ["83650.40", "4.104443"], ["83658.80", "5.016541"], ["83667.20", "4.469282"], ["83675.60", "5.655010"], ["83684.00", "4.013233"], ["83692.40", "4.834122"], ["83700.80", "5.198961"], ["83709.20", "4.286863"], ["83717.60", "3.922023"], ["83726.00", "4.560492"], ["83734.40", "5.472590"], ["83742.80", "5.381380"], ["83751.20", "4.195653"], ["83759.60", "4.651702"], ["83768.00", "5.107751"], ["83773.14", "0"]], "bids": [["83505.40", "0.018012"], ["83503.40", "0.047401"], ["83501.40", "0.124740"], ["83499.40", "0.328263"], ["83497.40", "0.863849"], ["83495.40", "2.273287"], ["83493.40", "5.982334"], ["83491.40", "15.742984"], ["83481.00", "0.000032"], ["83449.60", "4.925331"], ["83441.20", "5.381380"], ["83432.80", "4.834122"], ["83416.00", "4.651702"], ["83407.60", "5.655010"], ["83399.20", "4.286863"], ["83390.80", "4.013233"], ["83382.40", "5.472590"], ["83374.00", "5.563800"], ["83365.60", "4.104443"], ["83357.20", "3.922023"], ["83348.80", "4.469282"], ["83340.40", "4.378072"], ["83332.00", "4.560492"], ["83323.60", "5.290171"], ["83315.20", "4.742912"], ["83306.80", "4.195653"], ["83298.40", "5.016541"], ["83290.00", "5.198961"], ["82920.00", "0"]], "checksum": 961907636, "ts": "1742377124241"}], "ts": 1742377124245, "record_time": 1742377125.12791}
{"action": "update", "arg": {"instType": "SPOT", "channel": "books", "instId": "BTCUSDT"}, "data": [{"asks": [["83573.00", "3.084136"], ["83575.00", "8.116147"], ["83616.80", "4.651702"], ["83625.20", "4.195653"], ["83633.60", "4.560492"], ["83642.00", "5.655010"], ["83650.40", "4.469282"], ["83658.80", "4.013233"], ["83667.20", "5.107751"], ["83675.60", "5.198961"], ["83684.00", "5.472590"], ["83692.40", "5.016541"], ["83700.80", "5.563800"], ["83709.20", "4.925331"], ["83717.60", "4.742912"], ["83726.00", "4.286863"], ["83734.40", "5.290171"], ["83742.80", "3.922023"], ["83751.20", "4.378072"], ["83759.60", "4.834122"], ["83768.00", "5.381380"]], "bids": [["83523.33", "0"], ["83505.40", "0.017860"], ["83503.40", "0.047199"], ["83501.40", "0.124210"], ["83499.40", "0.326866"], ["83497.40", "0.860175"], ["83495.40", "2.263618"], ["83493.40", "5.956889"], ["83491.40", "15.676024"], ["83485.10", "0.015000"], ["83484.20", "0"], ["83449.60", "3.922023"], ["83441.20", "5.290171"], ["83424.40", "4.378072"], ["83416.00", "4.469282"], ["83407.60", "4.560492"], ["83382.40", "4.195653"], ["83374.00", "5.381380"], ["83365.60", "5.655010"], ["83357.20", "5.563800"], ["83348.80", "5.107751"], ["83340.40", "5.016541"], ["83332.00", "5.472590"], ["83323.60", "4.742912"], ["83315.20", "4.925331"], ["83306.80", "5.198961"], ["83298.40", "4.651702"], ["83290.00", "4.104443"], ["82920.00", "0.002447"]], "checksum": -1976452723, "ts": "1742377124441"}], "ts": 1742377124444, "record_time": 1742377125.327853}
{"action": "update", "arg": {"instType": "SPOT", "channel": "books", "instId": "BTCUSDT"}, "data": [{"asks": [["83528.79", "0.209200"], ["83529.17", "1.908610"], ["83531.84", "1.218849"], ["83531.85", "0"], ["83531.86", "0.338178"], ["83551.20", "0.718122"], ["83557.52", "0"], ["83559.00", "0.003861"], ["83561.00", "0.010161"], ["83563.00", "0.026738"], ["83565.00", "0.070364"], ["83567.00", "0.185169"], ["83569.00", "0.487287"], ["83571.00", "1.282333"], ["83573.00", "3.374560"], ["83575.00", "8.880421"], ["83587.26", "1.794531"], ["83587.70", "2.276070"], ["83587.80", "0.213600"], ["83588.80", "0.179550"], ["83589.70", "0.216000"], ["83595.93", "0"], ["83616.80", "4.742912"], ["83625.20", "5.472590"], ["83633.60", "5.563800"], ["83642.00", "4.925331"], ["83650.40", "5.381380"], ["83658.80", "5.107751"], ["83667.20", "4.560492"], ["83675.60", "4.378072"], ["83684.00", "5.290171"], ["83692.40", "4.013233"], ["83700.80", "5.016541"], ["83709.20", "4.469282"], ["83717.60", "4.104443"], ["83726.00", "5.198961"], ["83734.40", "4.834122"], ["83742.80", "4.286863"], ["83751.20", "4.195653"], ["83759.60", "4.651702"], ["83768.00", "5.655010"], ["83772.88", "0"], ["83772.92", "0"], ["83773.00", "0"]], "bids": [["83531.83", "0"], ["83531.81", "0"], ["83531.80", "0"], ["83529.16", "0"], ["83529.08", "0"], ["83528.78", "0.055266"], ["83523.66", "0.045994"], ["83523.47", "0"], ["83505.40", "0.017741"], ["83503.40", "0.046685"], ["83501.40", "0.122857"], ["83499.40", "0.323307"], ["83497.40", "0.850809"], ["83495.40", "2.238970"], ["83493.40", "5.892026"], ["83491.40", "15.505332"], ["83490.80", "0.336660"], ["83488.50", "0"], ["83486.60", "0.120000"], ["83485.80", "0.803280"], ["83482.96", "0.024770"], ["83449.60", "5.016541"], ["83441.20", "4.469282"], ["83432.80", "5.381380"], ["83424.40", "4.651702"], ["83416.00", "5.563800"], ["83407.60", "4.286863"], ["83399.20", "4.378072"], ["83397.78", "0"], ["83390.80", "4.560492"], ["83382.40", "4.742912"], ["83374.00", "4.834122"], ["83357.20", "4.104443"], ["83348.80", "5.472590"], ["83340.40", "5.198961"], ["83332.00", "4.925331"], ["83323.60", "5.290171"], ["83315.20", "4.013233"], ["83306.80", "4.195653"], ["83298.40", "3.922023"], ["83290.00", "5.107751"], ["82918.68", "0.000024"], ["82918.37", "0.000085"], ["82917.65", "0.000105"], ["82917.64", "0.000314"], ["82917.50", "0.000015"]], "checksum": -144919525, "ts": "1742377124641"}], "ts": 1742377124645, "record_time": 1742377125.525543}
{"action": "update", "arg": {"instType": "SPOT", "channel": "books", "instId": "BTCUSDT"}, "data": [{"asks": [["83528.79", "1.307680"], ["83529.12", "0.252504"], ["83529.16", "1.039781"], ["83529.17", "0.054700"], ["83531.84", "0.257348"], ["83531.86", "0.225656"], ["83531.87", "0"], ["83531.88", "0"], ["83531.89", "0"], ["83550.00", "0.382591"], ["83559.00", "0.004215"], ["83561.00", "0.011093"], ["83563.00", "0.029191"], ["83565.00", "0.076819"], ["83567.00", "0.202157"], ["83569.00", "0.531990"], ["83570.99", "0"], ["83571.00", "1.399976"], ["83573.00", "3.684145"], ["83575.00", "9.695120"], ["83576.30", "0.143880"], ["83578.50", "0.074880"], ["83579.30", "0"], ["83585.10", "0.012300"], ["83589.80", "0.213600"], ["83616.80", "4.378072"], ["83625.20", "4.742912"], ["83633.60", "5.381380"], ["83650.40", "4.560492"], ["83658.80", "4.651702"], ["83667.20", "5.107751"], ["83675.60", "4.104443"], ["83684.00", "5.198961"], ["83700.80", "5.655010"], ["83709.20", "3.922023"], ["83717.60", "5.563800"], ["83726.00", "4.469282"], ["83734.40", "5.472590"], ["83742.80", "4.834122"], ["83751.20", "5.016541"], ["83759.60", "4.286863"], ["83768.00", "5.290171"], ["83772.88", "0.000023"], ["83772.92", "0.000293"]], "bids": [["83528.78", "0.055466"], ["83528.77", "0.000100"], ["83528.76", "0.000100"], ["83528.75", "0.000100"], ["83495.40", "2.239131"], ["83493.40", "5.892450"], ["83491.40", "15.506448"], ["83490.80", "0.216480"], ["83490.10", "0.120180"], ["83490.00", "0.002032"], ["83489.90", "0"], ["83487.50", "0"], ["83486.60", "0"], ["83486.20", "0.120000"], ["83485.80", "0.073320"], ["83484.20", "0.025350"], ["83482.90", "0.120000"], ["83479.00", "0.000015"], ["83449.60", "4.104443"], ["83441.20", "3.922023"], ["83432.80", "4.378072"], ["83424.40", "4.013233"], ["83416.00", "5.472590"], ["83407.60", "4.925331"], ["83399.20", "5.381380"], ["83390.80", "5.290171"], ["83374.00", "5.563800"], ["83365.60", "4.195653"], ["83357.20", "4.560492"], ["83348.80", "5.655010"], ["83340.40", "4.469282"], ["83332.00", "5.198961"], ["83323.60", "4.286863"], ["83315.20", "4.834122"], ["83306.80", "5.016541"], ["83298.40", "5.107751"], ["83290.00", "4.651702"], ["82917.65", "0"], ["82917.64", "0"], ["82917.50", "0"]], "checksum": -387090045, "ts": "1742377124842"}], "ts": 1742377124846, "record_time": 1742377125.736181}
{"action": "update", "arg": {"instType": "SPOT", "channel": "books", "instId": "BTCUSDT"}, "data": [{"asks": [["83528.79", "3.164707"], ["83529.16", "0.161311"], ["83531.84", "0.257078"], ["83559.00", "0.004395"], ["83561.00", "0.011565"], ["83563.00", "0.030435"], ["83565.00", "0.080092"], ["83567.00", "0.210768"], ["83569.00", "0.554653"], ["83571.00", "1.459615"], ["83573.00", "3.841090"], ["83574.99", "0.729831"], ["83575.00", "10.108133"], ["83585.10", "0"], ["83585.20", "0.012360"], ["83586.30", "0.204000"], ["83588.80", "0"], ["83616.80", "4.742912"], ["83625.20", "5.198961"], ["83633.60", "4.834122"], ["83642.00", "3.922023"], ["83650.40", "5.472590"], ["83658.80", "5.563800"], ["83667.20", "4.469282"], ["83675.60", "5.290171"], ["83684.00", "4.560492"], ["83692.40", "5.016541"], ["83709.20", "5.381380"], ["83717.60", "4.925331"], ["83726.00", "4.378072"], ["83734.40", "5.107751"], ["83742.80", "4.651702"], ["83751.20", "4.104443"], ["83768.00", "4.195653"]], "bids": [["83523.85", "0.045995"], ["83523.66", "0"], ["83485.80", "0.136170"], ["83485.40", "0.240000"], ["83482.90", "0"], ["83479.00", "0"], ["83449.60", "5.198961"], ["83432.80", "4.925331"], ["83424.40", "4.469282"], ["83416.00", "5.290171"], ["83407.60", "4.104443"], ["83399.20", "5.563800"], ["83390.80", "5.472590"], ["83382.40", "4.834122"], ["83374.00", "4.651702"], ["83365.60", "5.381380"], ["83357.20", "4.013233"], ["83348.80", "4.286863"], ["83340.40", "4.560492"], ["83332.00", "5.016541"], ["83323.60", "5.655010"], ["83315.20", "4.742912"], ["83306.80", "5.107751"], ["83298.40", "4.378072"], ["83290.00", "4.195653"], ["82917.65", "0.000105"]], "checksum": -2117459958, "ts": "1742377125044"}], "ts": 1742377125048, "record_time": 1742377125.929553}
{"action": "snapshot", "arg": {"instType": "SPOT", "channel": "books", "instId": "BTCUSDT"}, "data": [{"asks": [["83445.01", "1.174244"], ["83445.02", "0.000100"], ["83445.03", "0.000100"], ["83445.04", "0.000100"], ["83445.92", "0.051206"], ["83445.93", "0.111708"], ["83446.10", "0.058980"], ["83448.62", "0.005117"], ["83449.58", "0.004855"], ["83449.59", "0.010050"], ["83449.63", "0.006134"], ["83454.52", "0.565742"], ["83454.53", "1.857027"], ["83455.80", "0.330633"], ["83456.97", "0.004120"], ["83457.00", "0.003357"], ["83459.91", "0.062760"], ["83461.01", "0.209200"], ["83463.08", "0.035952"], ["83463.50", "0.119843"], ["83463.54", "0.245961"], ["83463.55", "0.479763"], ["83464.49", "0.013175"], ["83464.76", "0.035960"], ["83464.88", "0.000359"], ["83465.15", "0.006357"], ["83465.16", "0.241573"], ["83465.31", "0.006357"], ["83465.64", "0.017257"], ["83465.65", "0.006356"], ["83465.97", "0.006356"], ["83466.11", "0.006356"], ["83466.65", "0.006356"], ["83466.73", "0.010994"], ["83466.98", "0.006357"], ["83467.15", "0.006357"], ["83467.65", "0.022786"], ["83467.80", "0.006357"], ["83468.14", "0.006357"], ["83468.15", "0.006357"], ["83468.43", "0.016429"], ["83468.52", "0.119885"], ["83468.65", "0.006357"], ["83468.67", "0.006357"], ["83468.94", "0.260196"], ["83468.95", "0.718830"], ["83469.60", "0.006357"], ["83470.19", "0.010985"], ["83470.32", "0.006357"], ["83470.99", "0.009990"], ["83471.65", "0.204278"], ["83471.94", "0.119908"], ["83471.98", "0.175721"], ["83472.71", "0.119900"], ["83472.90", "0.119881"], ["83473.23", "0.209200"], ["83473.36", "0.015896"], ["83473.48", "0.009989"], ["83474.01", "0.094100"], ["83475.44", "0.006357"], ["83477.17", "0.008064"], ["83477.18", "0.015895"], ["83477.71", "0.010984"], ["83480.40", "1.225949"], ["83481.10", "0.001812"], ["83481.85", "3.699815"], ["83483.10", "0.002957"], ["83485.10", "0.007646"], ["83487.00", "0.068796"], ["83487.01", "0.209200"], ["83487.10", "0.019891"], ["83489.10", "0.052389"], ["83490.00", "0.002000"], ["83491.10", "0.137752"], ["83493.10", "0.362505"], ["83494.81", "0.029608"], ["83495.07", "0.023624"], ["83495.10", "0.953962"], ["83495.43", "0.209200"], ["83495.51", "0.001598"], ["83497.10", "2.510213"], ["83498.41", "0.001598"], ["83499.10", "6.605823"], ["83499.99", "0.000497"], ["83501.10", "17.383746"], ["83501.20", "0.001260"], ["83501.30", "0.202770"], ["83501.90", "0.120000"], ["83502.00", "0.102270"], ["83502.80", "0.143700"], ["83503.10", "0.269760"], ["83503.78", "0.209200"], ["83503.80", "0.213600"], ["83504.60", "0.077850"], ["83504.80", "2.372250"], ["83505.10", "6.970200"], ["83505.42", "1.796290"], ["83505.70", "0.201250"], ["83505.80", "0.213600"], ["83506.30", "0.143700"], ["83507.70", "0.035940"], ["83507.80", "0.213600"], ["83508.40", "0.358230"], ["83508.70", "3.418740"], ["83509.00", "0.103470"], ["83509.10", "0.269760"], ["83509.20", "0.331530"], ["83509.40", "0.008130"], ["83509.80", "0.357300"], ["83510.40", "1.798740"], ["83520.00", "0.002000"], ["83541.39", "0.209200"], ["83542.79", "0.755082"], ["83542.80", "4.016787"], ["83550.00", "0.183269"], ["83550.01", "0.209200"], ["83551.20", "4.838403"], ["83559.60", "5.386146"], ["83565.01", "0.209200"], ["83568.00", "3.925496"], ["83568.23", "0.001810"], ["83568.97", "0.132260"], ["83570.00", "0.000073"], ["83570.62", "0.000016"], ["83571.42", "0.000298"], ["83571.43", "0.000230"], ["83572.00", "0.000014"], ["83573.37", "0.209200"], ["83574.19", "0.000109"], ["83575.00", "0.001598"], ["83575.22", "0.000031"], ["83575.63", "0.058036"], ["83576.40", "4.655821"], ["83576.59", "0.003620"], ["83577.02", "0.005982"], ["83577.73", "0.000200"], ["83577.78", "0.000025"], ["83577.98", "0.000072"], ["83578.04", "0.000096"], ["83578.95", "0.000025"], ["83580.00", "0.004875"], ["83580.31", "0.000023"], ["83580.56", "0.000019"], ["83581.38", "0.000059"], ["83581.73", "0.000067"], ["83582.09", "0.000008"], ["83583.22", "0.000492"], ["83583.33", "0.000010"], ["83583.85", "0.000052"], ["83584.00", "0.000022"], ["83584.18", "0.000347"], ["83584.49", "0.000066"], ["83584.53", "0.000314"], ["83584.80", "5.568727"], ["83586.00", "0.000386"], ["83586.45", "0.209200"], ["83586.51", "0.000095"], ["83586.93", "0.002167"], ["83586.96", "0.002633"], ["83587.25", "0.010000"], ["83587.50", "0.000783"], ["83587.87", "0.000050"], ["83589.00", "0.000024"], ["83589.25", "0.000054"], ["83592.00", "0.000097"], ["83593.20", "4.290659"], ["83593.33", "0.000013"], ["83593.39", "0.000014"], ["83593.75", "0.000173"], ["83594.44", "0.000134"], ["83594.79", "0.209200"], ["83595.00", "0.000121"], ["83595.05", "0.004883"], ["83596.39", "0.000015"], ["83597.11", "0.005980"], ["83597.76", "0.072538"], ["83597.96", "0.072173"], ["83598.44", "0.000052"], ["83598.51", "0.000039"], ["83598.56", "0.000383"], ["83600.00", "0.017919"], ["83600.35", "0.000674"], ["83600.78", "0.002491"], ["83601.40", "0.000019"], ["83601.60", "5.020984"], ["83602.67", "0.000133"], ["83602.86", "0.000081"], ["83603.14", "0.209200"], ["83603.60", "0.000051"], ["83606.00", "0.000014"], ["83607.00", "0.000014"], ["83607.60", "0.000014"], ["83608.00", "0.000014"], ["83608.70", "0.000035"], ["83609.00", "0.000014"], ["83610.00", "4.747112"], ["83610.34", "0.000008"], ["83611.49", "0.209200"], ["83611.93", "0.000010"], ["83612.01", "0.000009"], ["83614.30", "0.297882"], ["83614.90", "0.000040"], ["83614.97", "0.000008"], ["83615.71", "0.000009"], ["83615.85", "0.000024"], ["83616.00", "0.001191"], ["83616.67", "0.000345"], ["83617.02", "0.000032"], ["83618.18", "0.000008"], ["83618.40", "4.564531"], ["83619.21", "0.000051"], ["83619.83", "0.209200"], ["83620.00", "0.001306"], ["83620.07", "0.000020"], ["83620.60", "0.001258"], ["83620.61", "0.000149"], ["83620.70", "0.000146"], ["83620.88", "0.000269"], ["83621.62", "0.000185"], ["83621.89", "0.000325"], ["83622.28", "0.000025"], ["83622.57", "0.000012"], ["83623.43", "0.000010"], ["83623.62", "0.000011"], ["83624.16", "0.000149"], ["83625.00", "0.005055"], ["83626.68", "0.000126"], ["83626.80", "5.660018"], ["83626.92", "0.000009"], ["83627.45", "0.000016"], ["83627.68", "0.000361"], ["83628.00", "0.000097"], ["83628.17", "0.209200"], ["83628.57", "0.000008"], ["83629.02", "0.000078"], ["83629.03", "0.000039"], ["83630.43", "0.000010"], ["83630.71", "0.000758"], ["83631.57", "0.000019"], ["83631.58", "0.000183"], ["83632.65", "0.000085"], ["83633.63", "0.000502"], ["83633.88", "0.000071"], ["83634.85", "0.000642"], ["83635.20", "4.473240"], ["83635.64", "0.000030"], ["83636.36", "0.000179"], ["83636.37", "0.000039"], ["83636.52", "0.209200"], ["83637.17", "0.000027"], ["83637.76", "0.000102"], ["83638.15", "0.163719"], ["83638.30", "0.000157"], ["83638.32", "0.000039"], ["83639.15", "0.000009"], ["83639.71", "0.000041"], ["83639.87", "0.002772"], ["83640.00", "0.005428"], ["83640.15", "0.000423"], ["83640.35", "0.000022"], ["83641.00", "0.000020"], ["83641.62", "0.002925"], ["83643.60", "4.108078"], ["83644.33", "0.000013"], ["83644.44", "0.000008"], ["83644.48", "0.000012"], ["83644.86", "0.000034"], ["83644.87", "0.209200"], ["83645.83", "0.000014"], ["83646.67", "0.000018"], ["83647.06", "0.000457"], ["83647.46", "0.000222"], ["83648.96", "0.000030"], ["83649.00", "0.001047"], ["83649.50", "0.000020"], ["83650.00", "0.001877"], ["83650.01", "0.000612"], ["83651.16", "0.000896"], ["83651.65", "0.000018"], ["83652.00", "4.381949"], ["83652.17", "0.000008"], ["83652.48", "0.000188"], ["83653.22", "0.209200"], ["83653.31", "0.000015"], ["83654.23", "0.000009"], ["83655.00", "0.000166"], ["83655.89", "0.000512"], ["83658.54", "0.000036"], ["83658.67", "0.008431"], ["83659.09", "0.000008"], ["83660.00", "0.001835"], ["83660.14", "0.000016"], ["83660.40", "5.477437"], ["83660.71", "0.000273"], ["83661.08", "0.000331"], ["83661.57", "0.209200"], ["83661.60", "0.000042"], ["83661.97", "0.000052"], ["83662.55", "0.000122"], ["83663.72", "0.000031"], ["83663.91", "0.000161"], ["83663.95", "0.000022"], ["83663.98", "0.000008"], ["83664.19", "0.000073"], ["83664.42", "0.000504"], ["83666.00", "0.006075"], ["83666.25", "0.000180"], ["83666.65", "0.000122"], ["83666.66", "0.000220"], ["83666.67", "0.009185"], ["83667.23", "0.012503"], ["83667.80", "0.000023"], ["83668.80", "5.203565"], ["83669.09", "0.000135"], ["83669.66", "0.000010"], ["83669.92", "0.209200"], ["83670.00", "0.002822"], ["83670.05", "0.000033"], ["83670.16", "0.000235"], ["83670.59", "0.000105"], ["83671.36", "0.000099"], ["83672.00", "0.000035"], ["83672.25", "0.004043"], ["83673.58", "0.000023"], ["83673.83", "0.000017"], ["83673.87", "0.000022"], ["83674.42", "0.000010"], ["83675.00", "0.002631"], ["83675.20", "0.000018"], ["83675.36", "0.000013"], ["83675.62", "0.000011"], ["83676.00", "0.000097"], ["83676.47", "0.000009"], ["83677.20", "5.294856"], ["83677.59", "0.000009"], ["83678.08", "0.000145"], ["83678.27", "0.209200"], ["83678.41", "0.000010"], ["83679.11", "0.000027"], ["83680.00", "0.002205"], ["83680.14", "0.000009"], ["83681.16", "0.000611"], ["83681.82", "0.000175"], ["83682.00", "0.000120"], ["83683.67", "0.000184"], ["83683.91", "0.001247"], ["83684.21", "0.000115"], ["83684.62", "0.001720"], ["83685.00", "0.000121"], ["83685.02", "0.000183"], ["83685.60", "4.199368"], ["83686.11", "0.000096"], ["83686.62", "0.209200"], ["83687.67", "0.002422"], ["83688.00", "0.005550"], ["83688.07", "0.000072"], ["83688.89", "0.000009"], ["83689.50", "0.000113"], ["83689.87", "0.000098"], ["83690.00", "0.000121"], ["83690.09", "0.000082"], ["83690.48", "0.000248"], ["83690.84", "0.000162"], ["83691.74", "0.000659"], ["83692.31", "0.000016"], ["83692.38", "0.000007"], ["83692.52", "0.000066"], ["83693.69", "0.000051"], ["83694.00", "5.112274"], ["83694.97", "0.209200"], ["83695.38", "0.000010"], ["83695.63", "0.000011"], ["83695.65", "0.003570"], ["83697.23", "0.000095"], ["83697.83", "0.000059"], ["83699.88", "0.000008"], ["83700.00", "0.030886"], ["83701.28", "0.000248"], ["83701.92", "0.000067"], ["83702.40", "4.929693"], ["83702.48", "0.000057"], ["83702.50", "0.000033"], ["83702.60", "0.000039"], ["83702.93", "0.000050"], ["83703.00", "0.000024"], ["83703.32", "0.209200"], ["83703.70", "0.000030"], ["83705.15", "0.000646"], ["83705.18", "0.000009"], ["83705.32", "0.000023"], ["83705.42", "0.000015"], ["83705.85", "0.000019"], ["83706.28", "0.000046"], ["83706.67", "0.000013"], ["83707.07", "0.000067"], ["83708.26", "0.005970"], ["83709.05", "0.000061"], ["83709.30", "0.000028"], ["83709.31", "0.000058"], ["83709.34", "0.001953"], ["83710.00", "0.000023"], ["83711.68", "0.209200"], ["83712.00", "0.000097"], ["83712.12", "0.000012"], ["83713.40", "0.298651"], ["83713.80", "0.000024"], ["83714.28", "0.000836"], ["83714.29", "0.010141"], ["83714.89", "0.005076"], ["83715.00", "0.000121"], ["83715.48", "0.000010"], ["83716.08", "0.000010"], ["83716.50", "0.000480"], ["83717.39", "0.000010"], ["83717.45", "0.000244"], ["83717.46", "0.000009"], ["83717.93", "0.000065"], ["83718.75", "0.000012"], ["83718.87", "0.000028"], ["83719.46", "0.000053"], ["83720.00", "0.003694"], ["83720.04", "0.209200"], ["83723.40", "0.000225"], ["83723.43", "0.000039"], ["83723.72", "0.000176"], ["83725.00", "0.001852"], ["83726.43", "0.026350"], ["83727.27", "0.000016"], ["83727.71", "0.000009"], ["83728.07", "0.000022"], ["83728.37", "0.001273"], ["83728.57", "0.000017"], ["83729.32", "0.000035"], ["83729.39", "0.000008"], ["83729.73", "0.000009"], ["83730.00", "0.002261"], ["83731.48", "0.000124"], ["83732.10", "0.000009"], ["83733.33", "0.000419"], ["83734.69", "0.000085"], ["83735.29", "0.000417"], ["83735.30", "0.296098"], ["83736.00", "0.000097"], ["83736.84", "0.000183"], ["83736.94", "0.000103"], ["83737.00", "0.000026"], ["83737.14", "0.000024"], ["83737.37", "0.000012"], ["83739.13", "0.000008"], ["83739.28", "0.000051"], ["83739.60", "0.000048"], ["83740.00", "0.001886"], ["83740.51", "0.000423"], ["83741.00", "0.298539"], ["83743.32", "0.000013"], ["83745.00", "0.000121"], ["83745.16", "0.000390"], ["83745.97", "0.000017"], ["83745.98", "0.091148"], ["83747.10", "0.000298"], ["83748.00", "0.000097"], ["83748.39", "0.012050"], ["83749.19", "0.000010"], ["83749.33", "0.000133"], ["83749.66", "0.000016"], ["83749.95", "0.000010"], ["83750.00", "0.012325"], ["83750.46", "0.001499"], ["83750.76", "0.000073"], ["83752.00", "0.000034"], ["83752.09", "0.000314"], ["83752.21", "0.000031"], ["83753.10", "0.000008"], ["83753.33", "0.000011"], ["83754.39", "0.000025"], ["83754.70", "0.000013"], ["83754.88", "0.000098"], ["83755.56", "0.000134"], ["83756.08", "0.000099"], ["83756.52", "0.000018"], ["83757.25", "0.003950"], ["83757.40", "0.000537"], ["83757.61", "0.000009"], ["83759.85", "0.000026"], ["83760.00", "0.003419"], ["83761.90", "0.000024"], ["83762.50", "0.000783"], ["83766.23", "0.000178"], ["83766.67", "0.000008"], ["83766.84", "0.002395"], ["83766.95", "0.000274"], ["83767.73", "0.000188"], ["83768.00", "0.000012"], ["83769.19", "0.000335"], ["83769.23", "0.000101"], ["83770.74", "0.000729"], ["83771.43", "0.000084"], ["83772.00", "0.000096"], ["83772.50", "0.000008"], ["83772.56", "0.000614"]], "bids": [["83445.00", "0.589963"], ["83444.99", "0.000100"], ["83444.98", "0.000100"], ["83444.97", "0.000100"], ["83444.00", "0.000122"], ["83443.97", "0.045560"], ["83443.00", "0.000122"], ["83442.67", "0.004151"], ["83442.00", "0.000122"], ["83441.00", "0.000122"], ["83440.00", "0.000122"], ["83439.00", "0.000122"], ["83438.66", "0.001387"], ["83438.00", "0.000122"], ["83437.50", "0.001025"], ["83437.00", "0.000122"], ["83436.00", "0.000122"], ["83435.50", "0.001006"], ["83435.26", "0.000366"], ["83435.00", "0.000122"], ["83434.00", "0.000122"], ["83433.50", "0.001027"], ["83433.11", "0.111706"], ["83433.00", "0.000122"], ["83432.21", "0.241665"], ["83432.00", "0.000122"], ["83431.95", "0.009788"], ["83431.94", "0.013320"], ["83431.93", "0.008274"], ["83431.90", "0.013722"], ["83431.65", "0.209200"], ["83431.50", "0.002713"], ["83431.00", "0.000122"], ["83430.00", "0.002122"], ["83429.50", "0.007022"], ["83429.00", "0.000122"], ["83428.00", "0.000122"], ["83427.57", "0.140849"], ["83427.51", "0.014654"], ["83427.50", "0.018593"], ["83427.00", "0.000122"], ["83426.24", "0.006220"], ["83426.16", "0.008229"], ["83426.12", "0.330651"], ["83426.00", "0.000122"], ["83425.74", "0.009429"], ["83425.72", "0.006582"], ["83425.71", "0.005934"], ["83425.70", "0.014185"], ["83425.68", "0.008036"], ["83425.67", "0.008418"], ["83425.61", "0.018711"], ["83425.50", "0.048708"], ["83425.00", "0.000122"], ["83424.54", "0.007685"], ["83424.53", "0.007234"], ["83424.52", "0.007338"], ["83424.02", "0.014193"], ["83424.00", "0.000122"], ["83423.97", "0.015833"], ["83423.96", "0.009238"], ["83423.94", "0.009508"], ["83423.93", "0.015663"], ["83423.50", "0.128179"], ["83423.03", "0.090725"], ["83423.01", "0.212118"], ["83423.00", "0.209322"], ["83422.71", "0.007470"], ["83422.61", "0.247315"], ["83422.00", "0.000283"], ["83421.60", "0.001000"], ["83421.54", "0.006265"], ["83421.52", "0.006529"], ["83421.51", "0.009231"], ["83421.50", "0.337312"], ["83421.37", "0.084523"], ["83421.00", "0.000283"], ["83420.92", "0.017987"], ["83420.75", "0.018412"], ["83420.42", "0.005985"], ["83420.08", "0.015873"], ["83420.00", "0.000283"], ["83419.88", "0.016562"], ["83419.86", "0.009767"], ["83419.51", "0.283883"], ["83419.50", "0.887663"], ["83419.43", "0.004096"], ["83419.42", "0.006619"], ["83419.34", "0.056234"], ["83419.09", "0.017216"], ["83419.00", "0.000283"], ["83418.92", "0.007191"], ["83418.60", "0.008938"], ["83418.42", "0.036412"], ["83418.23", "0.017196"], ["83418.00", "0.000283"], ["83417.91", "0.017054"], ["83417.79", "0.012495"], ["83417.62", "0.227565"], ["83417.53", "0.025240"], ["83417.50", "2.335955"], ["83417.44", "0.017488"], ["83417.41", "0.008242"], ["83417.30", "0.001013"], ["83417.00", "0.000283"], ["83416.88", "0.005218"], ["83416.85", "0.005051"], ["83416.80", "0.001044"], ["83416.50", "0.000008"], ["83416.36", "0.008343"], ["83416.10", "0.434010"], ["83416.09", "0.012748"], ["83416.00", "0.000283"], ["83415.95", "0.052300"], ["83415.90", "0.110610"], ["83415.52", "2.545139"], ["83415.30", "0.000750"], ["83415.08", "0.018649"], ["83415.00", "0.000283"], ["83414.65", "0.209200"], ["83414.43", "0.009124"], ["83414.20", "0.270824"], ["83414.00", "0.000283"], ["83413.90", "0.066360"], ["83413.30", "0.015000"], ["83413.22", "0.015066"], ["83413.15", "0.223164"], ["83413.10", "0.008340"], ["83413.00", "0.000283"], ["83412.80", "0.013830"], ["83412.78", "0.076646"], ["83412.63", "0.262709"], ["83412.57", "0.021277"], ["83412.20", "0.143700"], ["83412.00", "0.000283"], ["83411.50", "0.096450"], ["83411.40", "0.022740"], ["83411.30", "0.022590"], ["83411.00", "0.000283"], ["83410.52", "0.012531"], ["83410.00", "0.000283"], ["83409.50", "0.130342"], ["83409.00", "0.000283"], ["83408.90", "0.120000"], ["83408.80", "0.255300"], ["83408.75", "0.073759"], ["83408.70", "0.143700"], ["83408.40", "0.600000"], ["83408.20", "0.026850"], ["83408.00", "0.000283"], ["83407.70", "0.021600"], ["83407.62", "0.056755"], ["83407.40", "0.107850"], ["83407.00", "0.000283"], ["83406.20", "0.007050"], ["83406.00", "0.000283"], ["83405.70", "0.918150"], ["83405.20", "0.143700"], ["83405.00", "0.000283"], ["83404.90", "0.012690"], ["83404.70", "0.009000"], ["83404.30", "0.120000"], ["83404.20", "0.009000"], ["83404.00", "0.000283"], ["83403.34", "0.023958"], ["83403.00", "0.000283"], ["83402.21", "0.719405"], ["83402.00", "0.000283"], ["83401.00", "0.000283"], ["83400.78", "0.024164"], ["83400.56", "0.017257"], ["83400.30", "0.209200"], ["83400.00", "0.002703"], ["83399.00", "0.000283"], ["83398.67", "0.000023"], ["83398.46", "0.008539"], ["83398.00", "0.000283"], ["83397.00", "0.000283"], ["83396.25", "0.000600"], ["83396.00", "0.000283"], ["83395.79", "0.020924"], ["83395.00", "0.000161"], ["83394.00", "0.000122"], ["83393.22", "0.008085"], ["83393.00", "0.000122"], ["83391.30", "0.209200"], ["83386.04", "0.001186"], ["83385.10", "0.001183"], ["83382.25", "0.001810"], ["83382.22", "0.005990"], ["83382.09", "0.072538"], ["83377.00", "0.209200"], ["83376.66", "0.012500"], ["83375.80", "4.564531"], ["83373.34", "0.000052"], ["83373.23", "0.003620"], ["83370.00", "0.002000"], ["83368.36", "0.000023"], ["83367.93", "0.000265"], ["83367.40", "3.925496"], ["83365.00", "0.209200"], ["83362.42", "0.072173"], ["83359.00", "4.747112"], ["83353.81", "0.058036"], ["83350.60", "4.199368"], ["83350.00", "0.000180"], ["83349.64", "0.209200"], ["83342.20", "4.929693"], ["83340.95", "0.209200"], ["83340.00", "0.002000"], ["83336.08", "0.005990"], ["83335.71", "0.026350"], ["83333.80", "5.112274"], ["83333.00", "0.000008"], ["83329.44", "0.001335"], ["83325.70", "0.303213"], ["83325.63", "0.209200"], ["83325.40", "4.838403"], ["83319.87", "0.000024"], ["83318.01", "0.000391"], ["83317.00", "5.020984"], ["83315.37", "0.000104"], ["83315.01", "0.000024"], ["83315.00", "0.209033"], ["83313.24", "0.132250"], ["83310.00", "0.002000"], ["83308.60", "5.203565"], ["83303.30", "0.209200"], ["83302.29", "0.000139"], ["83300.20", "4.108078"], ["83300.00", "0.006458"], ["83294.96", "0.209200"], ["83291.80", "5.386146"], ["83290.70", "0.305281"], ["83288.82", "0.000013"], ["83288.81", "0.007500"], ["83283.40", "4.473240"], ["83283.01", "0.001388"], ["83283.00", "0.209200"], ["83280.00", "0.002000"], ["83277.90", "0.000033"], ["83275.00", "5.477437"], ["83272.00", "0.001215"], ["83270.03", "0.209200"], ["83266.60", "5.294856"], ["83265.00", "0.179105"], ["83261.70", "0.209200"], ["83259.73", "0.000019"], ["83259.25", "0.000024"], ["83258.20", "4.290659"], ["83255.00", "0.000060"], ["83253.34", "0.209200"], ["83250.00", "0.002180"], ["83249.80", "5.568727"], ["83249.50", "0.000008"], ["83244.99", "0.209200"], ["83242.23", "0.000183"], ["83242.12", "0.000567"], ["83241.63", "0.000331"], ["83241.41", "0.000750"], ["83241.40", "4.655821"], ["83239.43", "0.000022"], ["83236.64", "0.209200"], ["83233.00", "4.016787"], ["83232.34", "0.001720"], ["83230.76", "0.000022"], ["83228.40", "0.298470"], ["83228.29", "0.209200"], ["83226.38", "0.001273"], ["83224.60", "4.381949"], ["83220.00", "0.002000"], ["83219.94", "0.209200"], ["83216.20", "5.660018"], ["83215.34", "0.000010"], ["83211.59", "0.209200"], ["83208.27", "0.000043"], ["83205.45", "0.000013"], ["83204.69", "0.000024"], ["83203.18", "0.209200"], ["83200.86", "0.000292"], ["83200.00", "0.000949"], ["83197.14", "0.000017"], ["83195.50", "0.000113"], ["83193.28", "0.000009"], ["83190.00", "0.002000"], ["83182.50", "0.000180"], ["83181.82", "0.000010"], ["83181.81", "0.000105"], ["83179.71", "0.000366"], ["83176.60", "0.000145"], ["83174.56", "0.000033"], ["83172.98", "0.000690"], ["83172.30", "0.494693"], ["83169.74", "0.209200"], ["83166.00", "0.000008"], ["83165.41", "0.000035"], ["83164.56", "0.000658"], ["83163.33", "0.000011"], ["83163.09", "0.000033"], ["83161.01", "0.000408"], ["83160.00", "0.002000"], ["83158.01", "0.000011"], ["83157.89", "0.000020"], ["83156.19", "0.000024"], ["83155.08", "0.000024"], ["83153.04", "0.209200"], ["83150.00", "0.001231"], ["83142.86", "0.000033"], ["83140.97", "0.002189"], ["83138.69", "0.000014"], ["83134.94", "0.000120"], ["83133.34", "0.000119"], ["83130.00", "0.002000"], ["83127.68", "0.000039"], ["83127.66", "0.000157"], ["83125.43", "1.714554"], ["83125.00", "0.000741"], ["83123.11", "0.000022"], ["83123.01", "0.000016"], ["83122.08", "0.000013"], ["83121.14", "0.000019"], ["83120.69", "0.000008"], ["83117.65", "0.000417"], ["83115.00", "0.000120"], ["83114.39", "0.000022"], ["83114.29", "0.000008"], ["83114.04", "0.000022"], ["83113.27", "0.000070"], ["83112.95", "0.000161"], ["83111.11", "0.000105"], ["83111.10", "0.000219"], ["83110.95", "0.000013"], ["83110.37", "0.000024"], ["83110.00", "0.000052"], ["83109.95", "0.000010"], ["83108.70", "0.000010"], ["83108.55", "0.000093"], ["83107.74", "0.000009"], ["83105.25", "0.000392"], ["83103.44", "0.000315"], ["83100.78", "0.000087"], ["83100.00", "0.003766"], ["83096.28", "0.000366"], ["83093.75", "0.000012"], ["83093.22", "0.000155"], ["83092.97", "0.000024"], ["83090.91", "0.000068"], ["83090.90", "0.000505"], ["83088.24", "0.000056"], ["83086.96", "0.000035"], ["83086.75", "0.000011"], ["83085.00", "0.000120"], ["83082.50", "0.000008"], ["83081.08", "0.000009"], ["83080.00", "0.000279"], ["83077.66", "0.000008"], ["83077.17", "0.000013"], ["83076.92", "0.000167"], ["83072.73", "0.000008"], ["83072.00", "0.000113"], ["83071.43", "0.000082"], ["83071.13", "0.000010"], ["83070.00", "0.000121"], ["83069.28", "0.000043"], ["83067.73", "0.000009"], ["83067.46", "0.000055"], ["83066.67", "0.000018"], ["83064.94", "0.000088"], ["83063.06", "0.000051"], ["83062.50", "0.000803"], ["83060.00", "0.000156"], ["83059.73", "0.001273"], ["83055.79", "0.000135"], ["83055.00", "0.000121"], ["83053.94", "0.000068"], ["83052.63", "0.000025"], ["83050.00", "0.000296"], ["83049.62", "0.000013"], ["83047.97", "0.000024"], ["83045.53", "0.000010"], ["83044.25", "0.000031"], ["83044.24", "0.000766"], ["83043.48", "0.016817"], ["83042.57", "0.000039"], ["83042.55", "0.000157"], ["83040.00", "0.000532"], ["83038.71", "0.000013"], ["83037.96", "0.000423"], ["83037.74", "0.000096"], ["83037.38", "0.000099"], ["83037.29", "0.000023"], ["83034.69", "0.000049"], ["83033.79", "0.000322"], ["83033.49", "0.000016"], ["83033.33", "0.000322"], ["83031.03", "0.000058"], ["83030.30", "0.000009"], ["83030.00", "0.000345"], ["83029.60", "0.000537"], ["83029.41", "0.000417"], ["83029.03", "0.000065"], ["83028.57", "0.000024"], ["83028.00", "0.000012"], ["83026.67", "0.000013"], ["83026.56", "0.000010"], ["83026.32", "0.000031"], ["83025.00", "0.000121"], ["83024.39", "0.000248"], ["83024.19", "0.000039"], ["83021.74", "0.000010"], ["83020.94", "0.000162"], ["83020.73", "0.000023"], ["83020.41", "0.000085"], ["83020.00", "0.000070"], ["83019.17", "0.000009"], ["83018.87", "0.000051"], ["83017.62", "0.000010"], ["83017.08", "0.000024"], ["83017.00", "0.000009"], ["83016.00", "0.000133"], ["83014.49", "0.000013"], ["83012.96", "0.000022"], ["83012.85", "0.000366"], ["83010.00", "0.002121"], ["83009.01", "0.000176"], ["83008.85", "0.000010"], ["83005.82", "0.000024"], ["83005.12", "0.000019"], ["83005.08", "0.000024"], ["83002.75", "0.000161"], ["83002.00", "0.000024"], ["83001.82", "0.000016"], ["83001.00", "0.252737"], ["83000.00", "0.041131"], ["82999.99", "0.000057"], ["82999.00", "0.000008"], ["82998.09", "0.000013"], ["82995.98", "0.000008"], ["82995.00", "0.000121"], ["82994.79", "0.000033"], ["82993.42", "0.000093"], ["82992.00", "0.000012"], ["82991.99", "0.000108"], ["82991.69", "0.012605"], ["82990.00", "0.000011"], ["82988.15", "0.010000"], ["82986.66", "0.000033"], ["82984.85", "0.000008"], ["82984.67", "0.000019"], ["82984.64", "0.000011"], ["82984.42", "0.000008"], ["82982.32", "0.000020"], ["82980.77", "0.000067"], ["82980.76", "0.000014"], ["82980.00", "0.002121"], ["82979.08", "0.000010"], ["82979.06", "0.000235"], ["82978.28", "0.000035"], ["82977.94", "0.000041"], ["82977.78", "0.000009"], ["82977.27", "0.000008"], ["82975.00", "0.000783"], ["82974.76", "0.000063"], ["82973.98", "0.000039"], ["82972.97", "0.000060"], ["82970.00", "0.000121"], ["82966.97", "0.001147"], ["82966.67", "0.000036"], ["82965.00", "0.000121"], ["82964.91", "0.000025"], ["82964.29", "0.000273"], ["82963.64", "0.000008"], ["82962.00", "0.000035"], ["82961.03", "0.000019"], ["82960.99", "0.000188"], ["82960.00", "0.018650"], ["82957.74", "0.000022"], ["82957.46", "0.000039"], ["82957.45", "0.000157"], ["82956.52", "0.000008"], ["82955.76", "0.000027"], ["82955.75", "0.000031"], ["82955.33", "0.000013"], ["82953.57", "0.000128"], ["82953.19", "0.000051"], ["82950.00", "0.002648"], ["82949.40", "0.000060"], ["82948.66", "0.000018"], ["82948.50", "0.000113"], ["82947.77", "0.007149"], ["82947.37", "0.000068"], ["82945.77", "0.000008"], ["82945.44", "0.000422"], ["82943.96", "0.000016"], ["82943.30", "0.000010"], ["82943.20", "0.000009"], ["82942.86", "0.000017"], ["82942.68", "0.000024"], ["82942.22", "0.000015"], ["82941.18", "0.000446"]], "checksum": 0, "ts": "1742377412306"}], "ts": 1742377412454, "record_time": 1742377413.393968}
{"action": "update", "arg": {"instType": "SPOT", "channel": "books", "instId": "BTCUSDT"}, "data": [{"asks": [["83471.98", "0"], ["83497.09", "0.755082"], ["83502.00", "0"], ["83511.20", "0.072570"], ["83542.79", "0"], ["83542.80", "4.290659"], ["83551.20", "4.108078"], ["83559.60", "5.568727"], ["83568.00", "5.203565"], ["83576.40", "5.294856"], ["83584.80", "4.199368"], ["83593.20", "4.747112"], ["83601.60", "4.929693"], ["83610.00", "5.386146"], ["83618.40", "4.473240"], ["83626.80", "5.112274"], ["83635.20", "4.564531"], ["83643.60", "4.655821"], ["83652.00", "5.020984"], ["83660.40", "4.838403"], ["83668.80", "5.477437"], ["83677.20", "3.925496"], ["83685.60", "5.660018"], ["83694.00", "4.016787"], ["83702.40", "4.381949"], ["83772.68", "0.000087"]], "bids": [["83442.67", "0"], ["83440.99", "0.004151"], ["83427.50", "0.018377"], ["83425.50", "0.048362"], ["83423.50", "0.127267"], ["83421.50", "0.334913"], ["83419.50", "0.881351"], ["83417.50", "2.319234"], ["83375.80", "4.929693"], ["83367.40", "5.477437"], ["83359.00", "4.016787"], ["83350.60", "4.655821"], ["83342.20", "4.381949"], ["83333.80", "4.108078"], ["83325.40", "5.568727"], ["83317.00", "5.386146"], ["83308.60", "5.112274"], ["83300.20", "5.294856"], ["83291.80", "4.199368"], ["83275.00", "4.564531"], ["83266.60", "5.660018"], ["83258.20", "4.838403"], ["83249.80", "3.925496"], ["83241.40", "5.020984"], ["83233.00", "4.290659"], ["83224.60", "4.747112"], ["83216.20", "5.203565"]], "checksum": -1427881413, "ts": "1742377412506"}], "ts": 1742377412511, "record_time": 1742377413.409066}
{"action": "update", "arg": {"instType": "SPOT", "channel": "books", "instId": "BTCUSDT"}, "data": [{"asks": [["83542.80", "5.112274"], ["83551.20", "5.386146"], ["83559.60", "4.564531"], ["83568.00", "4.108078"], ["83576.40", "4.929693"], ["83584.80", "4.747112"], ["83593.20", "5.294856"], ["83601.60", "4.381949"], ["83610.00", "4.016787"], ["83626.80", "5.020984"], ["83635.20", "4.838403"], ["83643.60", "5.660018"], ["83652.00", "4.290659"], ["83660.40", "4.199368"], ["83668.80", "5.568727"], ["83677.20", "5.477437"], ["83685.60", "4.655821"], ["83694.00", "3.925496"], ["83702.40", "5.203565"]], "bids": [["83445.00", "0.589856"], ["83444.01", "0.045560"], ["83443.97", "0"], ["83394.00", "0"], ["83375.80", "5.660018"], ["83367.40", "5.294856"], ["83359.00", "4.381949"], ["83350.60", "5.020984"], ["83342.20", "3.925496"], ["83333.80", "4.199368"], ["83325.40", "4.290659"], ["83317.00", "5.477437"], ["83308.60", "4.108078"], ["83300.20", "4.564531"], ["83291.80", "5.203565"], ["83283.40", "5.386146"], ["83275.00", "5.568727"], ["83266.60", "4.016787"], ["83249.80", "4.747112"], ["83241.40", "4.929693"], ["83233.00", "4.655821"], ["83224.60", "5.112274"], ["83216.20", "4.473240"], ["82940.00", "0.002472"]], "checksum": -1438654856, "ts": "1742377412706"}], "ts": 1742377412711, "record_time": 1742377413.600694}
{"action": "update", "arg": {"instType": "SPOT", "channel": "books", "instId": "BTCUSDT"}, "data": [{"asks": [["83471.96", "0.179209"], ["83542.80", "3.925496"], ["83551.20", "4.199368"], ["83559.60", "5.568727"], ["83568.00", "4.929693"], ["83576.40", "5.660018"], ["83584.80", "5.294856"], ["83593.20", "4.473240"], ["83601.60", "5.020984"], ["83610.00", "4.838403"], ["83618.40", "4.108078"], ["83626.80", "5.386146"], ["83635.20", "5.477437"], ["83643.60", "4.655821"], ["83652.00", "4.564531"], ["83660.40", "4.016787"], ["83668.80", "5.112274"], ["83677.20", "4.747112"], ["83685.60", "5.203565"], ["83694.00", "4.290659"], ["83702.40", "4.381949"], ["83772.68", "0"]], "bids": [["83444.10", "0.004151"], ["83440.99", "0"], ["83429.50", "0.006917"], ["83427.50", "0.018203"], ["83425.74", "0"], ["83425.72", "0"], ["83425.71", "0"], ["83425.70", "0.005582"], ["83425.50", "0.047901"], ["83423.50", "0.126057"], ["83421.50", "0.331728"], ["83419.50", "0.872969"], ["83418.60", "0"], ["83417.50", "2.297286"], ["83405.90", "0.023958"], ["83403.47", "0.024164"], ["83403.34", "0"], ["83400.78", "0"], ["83394.00", "0.000161"], ["83375.80", "4.290659"], ["83367.40", "5.112274"], ["83359.00", "5.660018"], ["83350.60", "5.386146"], ["83342.20", "4.381949"], ["83333.80", "4.108078"], ["83325.40", "5.294856"], ["83308.60", "4.655821"], ["83300.20", "5.020984"], ["83291.80", "4.199368"], ["83283.40", "5.568727"], ["83275.00", "4.564531"], ["83266.60", "5.203565"], ["83258.20", "4.473240"], ["83249.80", "4.838403"], ["83241.40", "4.016787"], ["83233.00", "4.929693"], ["83224.60", "3.925496"], ["83216.20", "4.747112"], ["83161.01", "0"], ["82938.97", "0.000099"], ["82938.60", "0.000022"], ["82938.45", "0.000022"], ["82937.59", "0.000423"]], "checksum": 359672239, "ts": "1742377412920"}], "ts": 1742377412922, "record_time": 1742377413.818412}
{"action": "update", "arg": {"instType": "SPOT", "channel": "books", "instId": "BTCUSDT"}, "data": [{"asks": [["83495.51", "0"], ["83497.23", "0.001598"], ["83505.20", "0.015000"], ["83511.20", "0"], ["83542.80", "4.381949"], ["83551.20", "5.294856"], ["83559.60", "4.564531"], ["83568.00", "5.020984"], ["83576.40", "4.199368"], ["83584.80", "4.290659"], ["83593.20", "4.838403"], ["83601.60", "4.747112"], ["83610.00", "5.660018"], ["83618.40", "3.925496"], ["83626.80", "5.203565"], ["83635.20", "4.108078"], ["83643.60", "4.016787"], ["83652.00", "5.386146"], ["83660.40", "5.112274"], ["83668.80", "5.568727"], ["83677.20", "4.929693"], ["83685.60", "5.477437"], ["83694.00", "4.655821"], ["83702.40", "4.473240"]], "bids": [["83444.01", "0"], ["83427.50", "0.018377"], ["83425.50", "0.048359"], ["83423.50", "0.127261"], ["83421.56", "0.009429"], ["83421.54", "0.012847"], ["83421.53", "0.005934"], ["83421.52", "0.015132"], ["83421.50", "0.334897"], ["83419.50", "0.881309"], ["83417.95", "0.012499"], ["83417.79", "0"], ["83417.50", "2.319234"], ["83414.42", "0.008938"], ["83404.70", "0"], ["83387.76", "0.001186"], ["83386.04", "0"], ["83375.80", "5.294856"], ["83367.40", "4.564531"], ["83359.00", "4.199368"], ["83350.60", "5.660018"], ["83342.20", "4.747112"], ["83333.80", "4.929693"], ["83325.40", "4.838403"], ["83317.00", "5.020984"], ["83308.60", "4.473240"], ["83300.20", "5.477437"], ["83291.80", "5.386146"], ["83283.40", "3.925496"], ["83275.00", "4.655821"], ["83266.60", "4.108078"], ["83258.20", "4.381949"], ["83249.80", "5.112274"], ["83241.40", "5.203565"], ["83233.00", "4.016787"], ["83224.60", "5.568727"], ["83216.20", "4.290659"], ["82937.59", "0"]], "checksum": -1225829559, "ts": "1742377413124"}], "ts": 1742377413126, "record_time": 1742377414.041667}
{"action": "update", "arg": {"instType": "SPOT", "channel": "books", "instId": "BTCUSDT"}, "data": [{"asks": [["83542.80", "5.477437"], ["83551.20", "4.655821"], ["83559.60", "4.108078"], ["83568.00", "5.294856"], ["83576.40", "5.020984"], ["83584.80", "4.473240"], ["83593.20", "4.381949"], ["83601.60", "4.564531"], ["83610.00", "4.747112"], ["83618.40", "4.929693"], ["83626.80", "4.016787"], ["83635.20", "5.203565"], ["83643.60", "4.199368"], ["83652.00", "5.660018"], ["83677.20", "3.925496"], ["83685.60", "5.386146"], ["83694.00", "4.838403"], ["83702.40", "4.290659"]], "bids": [["83444.05", "0.045560"], ["83427.50", "0.018203"], ["83425.50", "0.047901"], ["83423.50", "0.126057"], ["83421.50", "0.331728"], ["83419.50", "0.872969"], ["83417.50", "2.297286"], ["83395.00", "0.000283"], ["83375.80", "4.655821"], ["83367.40", "5.568727"], ["83359.00", "5.020984"], ["83350.60", "3.925496"], ["83342.20", "4.929693"], ["83333.80", "4.290659"], ["83325.40", "5.203565"], ["83317.00", "4.016787"], ["83308.60", "4.564531"], ["83300.20", "4.838403"], ["83283.40", "4.199368"], ["83275.00", "5.112274"], ["83266.60", "4.473240"], ["83258.20", "4.747112"], ["83249.80", "4.381949"], ["83241.40", "4.108078"], ["83233.00", "5.660018"], ["83224.60", "5.294856"], ["83216.20", "5.477437"], ["82938.45", "0"]], "checksum": -351640329, "ts": "1742377413333"}], "ts": 1742377413337, "record_time": 1742377414.234657}
{"action": "update", "arg": {"instType": "SPOT", "channel": "books", "instId": "BTCUSDT"}, "data": [{"asks": [["83493.09", "0.473670"], ["83542.80", "4.108078"], ["83551.20", "4.838403"], ["83559.60", "4.381949"], ["83568.00", "4.290659"], ["83576.40", "5.112274"], ["83584.80", "4.564531"], ["83593.20", "4.747112"], ["83601.60", "5.477437"], ["83610.00", "3.925496"], ["83618.40", "4.473240"], ["83626.80", "5.203565"], ["83635.20", "5.020984"], ["83643.60", "5.386146"], ["83652.00", "4.929693"], ["83660.40", "5.294856"], ["83668.80", "4.016787"], ["83677.20", "5.660018"], ["83685.60", "4.655821"], ["83694.00", "5.568727"], ["83702.40", "4.199368"], ["83772.56", "0"]], "bids": [["83444.10", "0"], ["83407.40", "0"], ["83407.30", "0.107850"], ["83395.00", "0.000122"], ["83375.80", "4.016787"], ["83367.40", "4.381949"], ["83359.00", "5.203565"], ["83350.60", "5.660018"], ["83342.20", "5.112274"], ["83333.80", "5.386146"], ["83325.40", "4.838403"], ["83317.00", "4.564531"], ["83308.60", "4.473240"], ["83300.20", "4.290659"], ["83291.80", "5.477437"], ["83283.40", "3.925496"], ["83275.00", "5.020984"], ["83266.60", "4.747112"], ["83258.20", "5.294856"], ["83249.80", "5.568727"], ["83241.40", "4.929693"], ["83233.00", "4.199368"], ["83224.60", "4.655821"], ["83216.20", "4.108078"], ["82938.45", "0.000022"]], "checksum": 560122011, "ts": "1742377413538"}], "ts": 1742377413544, "record_time": 1742377414.434337}
{"action": "update", "arg": {"instType": "SPOT", "channel": "books", "instId": "BTCUSDT"}, "data": [{"asks": [["83497.09", "0"], ["83508.70", "4.246350"], ["83542.80", "5.112274"], ["83551.20", "4.016787"], ["83559.60", "4.929693"], ["83568.00", "4.655821"], ["83576.40", "5.020984"], ["83584.80", "5.294856"], ["83593.20", "5.660018"], ["83601.60", "4.564531"], ["83610.00", "5.477437"], ["83618.40", "4.108078"], ["83635.20", "4.473240"], ["83643.60", "4.381949"], ["83652.00", "4.290659"], ["83660.40", "4.838403"], ["83668.80", "3.925496"], ["83677.20", "5.568727"], ["83685.60", "4.199368"], ["83694.00", "5.386146"], ["83702.40", "4.747112"], ["83772.56", "0.000614"]], "bids": [["83444.08", "0.045560"], ["83444.05", "0"], ["83443.71", "0.004151"], ["83416.10", "0"], ["83412.20", "0"], ["83375.80", "4.473240"], ["83367.40", "4.290659"], ["83359.00", "5.477437"], ["83350.60", "5.020984"], ["83342.20", "5.386146"], ["83333.80", "4.108078"], ["83325.40", "5.203565"], ["83317.00", "5.568727"], ["83308.60", "5.112274"], ["83300.20", "4.655821"], ["83291.80", "4.381949"], ["83283.40", "5.660018"], ["83275.00", "3.925496"], ["83266.60", "5.294856"], ["83258.20", "4.564531"], ["83249.80", "4.016787"], ["83241.40", "4.838403"], ["83233.00", "4.747112"], ["83224.60", "4.199368"], ["83216.20", "4.929693"], ["82937.59", "0.000423"]], "checksum": 1589808970, "ts": "1742377413748"}], "ts": 1742377413751, "record_time": 1742377414.648462}
{"action": "update", "arg": {"instType": "SPOT", "channel": "books", "instId": "BTCUSDT"}, "data": [{"asks": [["83445.93", "0"], ["83483.10", "0.002840"], ["83485.10", "0.007472"], ["83487.10", "0.019664"], ["83489.10", "0.051746"], ["83491.10", "0.136175"], ["83493.10", "0.358355"], ["83495.10", "0.943040"], ["83497.10", "2.481684"], ["83498.41", "0"], ["83499.10", "6.530747"], ["83499.37", "0.001598"], ["83501.10", "17.186177"], ["83542.80", "5.294856"], ["83551.20", "5.477437"], ["83559.60", "5.568727"], ["83567.99", "0.281412"], ["83568.00", "3.925496"], ["83576.40", "4.381949"], ["83584.80", "5.112274"], ["83593.20", "5.203565"], ["83601.60", "4.108078"], ["83610.00", "4.290659"], ["83618.40", "4.016787"], ["83626.80", "4.564531"], ["83643.60", "4.655821"], ["83652.00", "4.199368"], ["83660.40", "5.660018"], ["83668.80", "4.747112"], ["83677.20", "5.386146"], ["83685.60", "4.838403"], ["83694.00", "4.929693"], ["83702.40", "5.020984"]], "bids": [["83445.00", "0.380656"], ["83443.71", "0"], ["83442.32", "0.004151"], ["83431.50", "0.002293"], ["83429.50", "0.006035"], ["83427.50", "0.015881"], ["83425.50", "0.041792"], ["83423.50", "0.109980"], ["83421.50", "0.289421"], ["83419.50", "0.761633"], ["83417.50", "2.004299"], ["83413.50", "0.507810"], ["83393.00", "0.000283"], ["83386.06", "0.001183"], ["83385.10", "0"], ["83375.80", "3.925496"], ["83367.40", "4.747112"], ["83359.00", "4.108078"], ["83350.60", "4.473240"], ["83333.80", "5.112274"], ["83325.40", "4.564531"], ["83317.00", "4.381949"], ["83308.60", "5.477437"], ["83300.20", "5.294856"], ["83291.80", "5.660018"], ["83283.40", "4.838403"], ["83275.00", "5.568727"], ["83266.60", "4.290659"], ["83258.20", "4.199368"], ["83249.80", "4.655821"], ["83241.40", "4.016787"], ["83233.00", "5.020984"], ["83224.60", "4.929693"], ["83216.20", "5.203565"], ["82937.59", "0"]], "checksum": 1019791673, "ts": "1742377413961"}], "ts": 1742377413965, "record_time": 1742377414.878581}
{"action": "update", "arg": {"instType": "SPOT", "channel": "books", "instId": "BTCUSDT"}, "data": [{"asks": [["83445.01", "1.285952"], ["83445.92", "0.019229"], ["83472.71", "0"], ["83473.72", "0.119900"], ["83477.18", "0"], ["83477.71", "0"], ["83477.89", "0.015895"], ["83478.72", "0.010984"], ["83487.10", "0.019890"], ["83489.10", "0.052340"], ["83491.10", "0.137738"], ["83493.10", "0.362468"], ["83495.10", "0.953864"], ["83497.10", "2.510167"], ["83499.10", "6.605703"], ["83501.10", "17.383430"], ["83501.30", "0.911760"], ["83502.80", "2.516010"], ["83504.80", "0"], ["83510.60", "1.500000"], ["83511.20", "0.072570"], ["83511.40", "1.012440"], ["83542.80", "5.660018"], ["83551.20", "4.381949"], ["83559.60", "4.473240"], ["83568.00", "5.294856"], ["83576.40", "5.568727"], ["83584.80", "4.564531"], ["83593.20", "4.108078"], ["83601.60", "5.386146"], ["83610.00", "4.747112"], ["83618.40", "5.203565"], ["83626.80", "5.020984"], ["83635.20", "4.929693"], ["83643.60", "4.199368"], ["83652.00", "5.112274"], ["83660.40", "4.290659"], ["83668.80", "5.477437"], ["83677.20", "3.925496"], ["83694.00", "4.016787"], ["83702.40", "4.655821"], ["83772.50", "0"], ["83772.56", "0"]], "bids": [["83445.00", "0.589856"], ["83431.50", "0.002605"], ["83429.50", "0.006853"], ["83427.50", "0.018036"], ["83425.70", "0"], ["83425.68", "0"], ["83425.61", "0.008724"], ["83425.50", "0.047462"], ["83423.50", "0.124900"], ["83421.50", "0.328685"], ["83419.50", "0.864961"], ["83417.50", "2.276212"], ["83413.64", "0.262709"], ["83413.30", "0"], ["83412.63", "0"], ["83409.46", "0.073759"], ["83408.75", "0"], ["83408.63", "0.056755"], ["83407.62", "0"], ["83393.00", "0.000161"], ["83375.80", "4.016787"], ["83367.40", "4.564531"], ["83359.00", "4.290659"], ["83350.60", "5.020984"], ["83342.20", "5.477437"], ["83333.80", "5.386146"], ["83325.40", "5.112274"], ["83317.00", "4.108078"], ["83308.60", "4.747112"], ["83300.20", "4.199368"], ["83291.80", "5.203565"], ["83283.40", "4.655821"], ["83266.60", "4.381949"], ["83258.20", "3.925496"], ["83249.80", "4.473240"], ["83241.40", "4.929693"], ["83233.00", "5.660018"], ["83224.60", "4.838403"], ["83216.20", "5.294856"], ["82937.59", "0.000423"], ["82937.50", "0.000012"], ["82936.29", "0.000067"]], "checksum": -470158050, "ts": "1742377414167"}], "ts": 1742377414173, "record_time": 1742377415.070014}
{"action": "update", "arg": {"instType": "SPOT", "channel": "books", "instId": "BTCUSDT"}, "data": [{"asks": [["83493.10", "0.362342"], ["83495.10", "0.953532"], ["83497.10", "2.509294"], ["83499.10", "6.603597"], ["83501.10", "17.377887"], ["83501.20", "0.001050"], ["83501.30", "0.356550"], ["83502.80", "0.143700"], ["83504.70", "2.372250"], ["83511.20", "0"], ["83511.40", "0"], ["83542.80", "4.199368"], ["83551.20", "5.568727"], ["83559.60", "4.838403"], ["83568.00", "5.203565"], ["83576.40", "4.381949"], ["83584.80", "3.925496"], ["83593.19", "0.031977"], ["83593.20", "5.020984"], ["83601.60", "4.564531"], ["83610.00", "5.477437"], ["83618.40", "4.473240"], ["83626.80", "4.108078"], ["83635.20", "4.747112"], ["83643.60", "4.929693"], ["83652.00", "4.016787"], ["83660.40", "5.660018"], ["83668.80", "5.112274"], ["83677.20", "4.290659"], ["83685.60", "5.294856"], ["83694.00", "4.655821"], ["83702.40", "5.386146"]], "bids": [["83444.11", "0.045560"], ["83444.08", "0"], ["83442.32", "0"], ["83435.26", "0"], ["83434.91", "0.000366"], ["83421.52", "0.020714"], ["83421.43", "0.009987"], ["83375.80", "4.381949"], ["83367.40", "4.929693"], ["83350.60", "4.655821"], ["83342.20", "5.386146"], ["83333.80", "4.473240"], ["83325.40", "4.016787"], ["83317.00", "5.112274"], ["83308.60", "5.660018"], ["83300.20", "5.020984"], ["83291.80", "5.294856"], ["83283.40", "4.838403"], ["83275.00", "5.203565"], ["83266.60", "3.925496"], ["83258.20", "4.108078"], ["83249.80", "5.568727"], ["83241.40", "4.747112"], ["83233.00", "5.477437"], ["83224.60", "4.564531"], ["83216.20", "4.199368"]], "checksum": -752138779, "ts": "1742377414368"}], "ts": 1742377414371, "record_time": 1742377415.261796}
{"action": "update", "arg": {"instType": "SPOT", "channel": "books", "instId": "BTCUSDT"}, "data": [{"asks": [["83445.01", "1.285845"], ["83497.09", "0.313389"], ["83499.10", "6.603427"], ["83501.10", "17.377441"], ["83501.30", "0.225540"], ["83542.80", "4.108078"], ["83551.20", "4.473240"], ["83567.99", "0"], ["83568.00", "4.747112"], ["83576.40", "5.203565"], ["83584.80", "4.381949"], ["83593.20", "4.929693"], ["83601.60", "4.199368"], ["83610.00", "5.294856"], ["83618.40", "4.290659"], ["83626.80", "4.564531"], ["83635.20", "5.112274"], ["83643.60", "5.020984"], ["83652.00", "5.568727"], ["83668.80", "4.655821"], ["83677.20", "3.925496"], ["83685.60", "5.386146"], ["83694.00", "5.477437"], ["83702.40", "4.016787"]], "bids": [["83441.83", "0.004151"], ["83427.50", "0.018209"], ["83425.50", "0.047920"], ["83423.50", "0.126105"], ["83421.50", "0.331854"], ["83419.50", "0.873301"], ["83417.50", "2.298160"], ["83394.00", "0"], ["83375.80", "4.929693"], ["83367.40", "4.838403"], ["83359.00", "4.108078"], ["83350.60", "4.016787"], ["83342.20", "4.473240"], ["83333.80", "4.199368"], ["83325.40", "4.747112"], ["83317.00", "4.655821"], ["83308.60", "4.290659"], ["83300.20", "5.294856"], ["83291.80", "5.477437"], ["83283.40", "5.660018"], ["83275.00", "5.568727"], ["83266.60", "5.203565"], ["83258.20", "5.386146"], ["83249.80", "3.925496"], ["83241.40", "5.020984"], ["83233.00", "4.564531"], ["83224.60", "5.112274"], ["83216.20", "4.381949"]], "checksum": -784697038, "ts": "1742377414572"}], "ts": 1742377414574, "record_time": 1742377415.464941}
{"action": "update", "arg": {"instType": "SPOT", "channel": "books", "instId": "BTCUSDT"}, "data": [{"asks": [["83463.08", "0"], ["83463.50", "0"], ["83463.80", "0.035952"], ["83464.21", "0.119843"], ["83464.76", "0"], ["83465.15", "0"], ["83465.31", "0"], ["83465.47", "0.035960"], ["83465.65", "0"], ["83465.87", "0.006357"], ["83465.97", "0"], ["83466.04", "0.006357"], ["83466.11", "0"], ["83466.37", "0.006356"], ["83466.65", "0"], ["83466.73", "0"], ["83466.77", "0.006356"], ["83466.90", "0.006356"], ["83466.98", "0"], ["83467.15", "0"], ["83467.37", "0.006356"], ["83467.45", "0.010994"], ["83467.65", "0"], ["83467.70", "0.006357"], ["83467.80", "0"], ["83467.87", "0.006357"], ["83468.14", "0"], ["83468.15", "0"], ["83468.37", "0.016429"], ["83468.43", "0"], ["83468.45", "0.006357"], ["83468.52", "0.006357"], ["83468.65", "0"], ["83468.67", "0"], ["83468.87", "0.012714"], ["83469.20", "0.119885"], ["83469.25", "0.016429"], ["83469.37", "0.006357"], ["83469.39", "0.006357"], ["83469.60", "0"], ["83470.19", "0"], ["83470.42", "0.006357"], ["83470.87", "0.010985"], ["83470.99", "0"], ["83471.71", "0.009990"], ["83471.94", "0"], ["83471.96", "0"], ["83472.62", "0.119908"], ["83472.90", "0"], ["83473.36", "0"], ["83473.48", "0"], ["83473.69", "0.119881"], ["83474.12", "0.015896"], ["83474.28", "0.009989"], ["83475.44", "0"], ["83476.26", "0.006357"], ["83542.80", "5.203565"], ["83551.20", "5.660018"], ["83559.60", "5.568727"], ["83568.00", "4.473240"], ["83576.40", "4.747112"], ["83584.80", "5.294856"], ["83593.20", "4.199368"], ["83601.60", "3.925496"], ["83610.00", "4.290659"], ["83618.40", "5.386146"], ["83626.80", "4.016787"], ["83635.20", "4.655821"], ["83643.60", "5.112274"], ["83652.00", "4.838403"], ["83660.40", "4.564531"], ["83668.80", "5.020984"], ["83677.20", "4.381949"], ["83685.60", "4.108078"], ["83694.00", "4.929693"], ["83702.40", "5.477437"], ["83772.50", "0.000008"]], "bids": [["83444.14", "0.045560"], ["83444.11", "0"], ["83441.83", "0"], ["83427.50", "0.018036"], ["83425.67", "0"], ["83425.50", "0.047462"], ["83423.75", "0.090725"], ["83423.50", "0.124900"], ["83423.33", "0.247315"], ["83423.03", "0"], ["83422.61", "0"], ["83422.08", "0.084523"], ["83421.71", "0.004096"], ["83421.64", "0.017987"], ["83421.50", "0.328685"], ["83421.48", "0.018412"], ["83421.37", "0"], ["83421.14", "0.005985"], ["83420.92", "0"], ["83420.88", "0.015873"], ["83420.75", "0"], ["83420.68", "0.016562"], ["83420.42", "0"], ["83420.14", "0.006619"], ["83420.08", "0"], ["83420.05", "0.056234"], ["83419.88", "0"], ["83419.81", "0.017216"], ["83419.64", "0.007191"], ["83419.50", "0.864961"], ["83419.43", "0"], ["83419.42", "0"], ["83419.34", "0"], ["83419.22", "0.007380"], ["83419.14", "0.029032"], ["83419.09", "0"], ["83418.95", "0.017196"], ["83418.92", "0"], ["83418.64", "0.017054"], ["83418.42", "0"], ["83418.35", "0.025240"], ["83418.30", "0.227565"], ["83418.23", "0"], ["83418.15", "0.017488"], ["83418.14", "0.008242"], ["83417.91", "0"], ["83417.62", "0"], ["83417.53", "0"], ["83417.50", "2.276212"], ["83417.44", "0"], ["83417.41", "0"], ["83417.18", "0.008343"], ["83416.36", "0"], ["83415.95", "0"], ["83415.80", "0.018649"], ["83415.08", "0"], ["83414.88", "0.270824"], ["83414.20", "0"], ["83413.95", "0.223164"], ["83413.54", "0.076646"], ["83413.36", "0.021277"], ["83413.15", "0"], ["83412.78", "0"], ["83412.57", "0"], ["83411.34", "0.012531"], ["83410.52", "0"], ["83375.80", "4.199368"], ["83367.40", "3.925496"], ["83359.00", "5.203565"], ["83350.60", "4.290659"], ["83342.20", "4.108078"], ["83333.80", "4.016787"], ["83325.40", "4.929693"], ["83317.00", "5.386146"], ["83308.60", "4.564531"], ["83300.20", "5.568727"], ["83291.80", "5.294856"], ["83283.40", "5.020984"], ["83275.00", "4.381949"], ["83266.60", "4.838403"], ["83258.20", "5.112274"], ["83249.80", "5.660018"], ["83241.40", "5.477437"], ["83233.00", "4.473240"], ["83224.60", "4.747112"], ["83216.20", "4.655821"], ["82935.00", "0.000121"], ["82934.78", "0.000010"]], "checksum": 996338700, "ts": "1742377414774"}], "ts": 1742377414776, "record_time": 1742377415.667886}
{"action": "update", "arg": {"instType": "SPOT", "channel": "books", "instId": "BTCUSDT"}, "data": [{"asks": [["83495.10", "0.953293"], ["83497.10", "2.508666"], ["83499.10", "6.601753"], ["83501.10", "17.373032"], ["83508.70", "4.256400"], ["83542.80", "4.016787"], ["83551.20", "5.477437"], ["83559.60", "4.381949"], ["83568.00", "5.386146"], ["83576.40", "5.112274"], ["83584.80", "5.020984"], ["83593.20", "5.660018"], ["83601.60", "4.108078"], ["83610.00", "4.564531"], ["83618.40", "5.203565"], ["83626.80", "4.929693"], ["83635.20", "4.473240"], ["83643.60", "4.199368"], ["83652.00", "5.568727"], ["83660.40", "4.655821"], ["83668.80", "5.294856"], ["83677.20", "3.925496"], ["83685.60", "4.290659"], ["83694.00", "4.747112"], ["83702.40", "4.838403"]], "bids": [["83444.20", "0.004151"], ["83421.49", "0.008418"], ["83394.00", "0.000122"], ["83380.30", "0.207716"], ["83375.80", "4.838403"], ["83367.40", "5.386146"], ["83359.00", "4.290659"], ["83350.60", "4.108078"], ["83342.20", "5.477437"], ["83317.00", "3.925496"], ["83300.20", "5.660018"], ["83291.80", "4.199368"], ["83275.00", "4.655821"], ["83266.60", "4.473240"], ["83258.20", "4.747112"], ["83249.80", "5.203565"], ["83241.40", "5.112274"], ["83233.00", "4.381949"], ["83224.60", "5.568727"], ["83216.20", "5.294856"], ["82937.50", "0"], ["82936.29", "0"], ["82935.00", "0"], ["82934.78", "0"]], "checksum": -733263608, "ts": "1742377414997"}], "ts": 1742377415001, "record_time": 1742377415.891922}
{"action": "update", "arg": {"instType": "SPOT", "channel": "books", "instId": "BTCUSDT"}, "data": [{"asks": [["83468.76", "0.179030"], ["83505.20", "0"], ["83511.20", "0.072570"], ["83542.80", "4.381949"], ["83551.20", "4.290659"], ["83559.60", "5.660018"], ["83568.00", "5.568727"], ["83576.40", "5.294856"], ["83593.20", "4.108078"], ["83601.60", "4.016787"], ["83610.00", "5.203565"], ["83618.40", "5.386146"], ["83626.80", "4.199368"], ["83635.20", "4.655821"], ["83643.60", "5.477437"], ["83652.00", "4.473240"], ["83660.40", "4.747112"], ["83668.80", "4.929693"], ["83677.20", "4.564531"], ["83685.60", "3.925496"], ["83694.00", "4.838403"], ["83702.40", "5.112274"], ["83772.50", "0"]], "bids": [["83444.20", "0"], ["83395.00", "0.000283"], ["83375.80", "4.929693"], ["83367.40", "4.108078"], ["83359.00", "4.199368"], ["83350.60", "4.016787"], ["83342.20", "5.568727"], ["83333.80", "4.564531"], ["83325.40", "5.112274"], ["83317.00", "5.020984"], ["83308.60", "4.473240"], ["83300.20", "5.386146"], ["83291.80", "4.747112"], ["83283.40", "4.381949"], ["83275.00", "5.477437"], ["83266.60", "5.294856"], ["83258.20", "5.203565"], ["83249.80", "3.925496"], ["83241.40", "4.838403"], ["83233.00", "5.660018"], ["83224.60", "4.290659"], ["83216.20", "4.655821"], ["82937.50", "0.000012"]], "checksum": 996338700, "ts": "1742377415211"}], "ts": 1742377415215, "record_time": 1742377416.115267}
{"action": "update", "arg": {"instType": "SPOT", "channel": "books", "instId": "BTCUSDT"}, "data": [{"asks": [["83485.10", "0.007581"], ["83489.10", "0.052497"], ["83491.10", "0.138150"], ["83493.10", "0.363554"], ["83495.10", "0.956720"], ["83497.10", "2.517685"], ["83499.10", "6.625487"], ["83501.10", "17.435603"], ["83501.30", "0.225720"], ["83501.90", "0.120180"], ["83502.80", "0.143880"], ["83503.10", "0.269940"], ["83503.80", "0.213780"], ["83511.40", "1.012440"], ["83542.80", "4.747112"], ["83551.20", "5.660018"], ["83559.60", "5.112274"], ["83568.00", "5.386146"], ["83576.40", "4.929693"], ["83584.80", "5.477437"], ["83593.20", "4.655821"], ["83601.60", "4.838403"], ["83610.00", "5.568727"], ["83618.40", "4.290659"], ["83626.80", "5.203565"], ["83635.20", "4.473240"], ["83638.15", "0"], ["83643.60", "4.016787"], ["83652.00", "4.108078"], ["83660.40", "4.381949"], ["83668.80", "5.020984"], ["83677.20", "4.199368"], ["83694.00", "4.564531"], ["83702.40", "5.294856"]], "bids": [["83445.00", "0.380656"], ["83444.18", "0.045559"], ["83444.14", "0"], ["83441.75", "0.004151"], ["83431.50", "0.002293"], ["83429.50", "0.006035"], ["83427.50", "0.015881"], ["83425.50", "0.041792"], ["83423.50", "0.109980"], ["83421.50", "0.289421"], ["83419.50", "0.761633"], ["83417.50", "2.004299"], ["83415.90", "0.110790"], ["83413.90", "0.066540"], ["83413.50", "0.507990"], ["83403.50", "0.009000"], ["83375.80", "5.568727"], ["83367.40", "4.747112"], ["83359.00", "4.838403"], ["83350.60", "5.203565"], ["83342.20", "4.290659"], ["83325.40", "5.294856"], ["83317.00", "4.016787"], ["83308.60", "5.660018"], ["83300.20", "5.477437"], ["83291.80", "4.108078"], ["83283.40", "4.473240"], ["83275.00", "5.112274"], ["83266.60", "5.020984"], ["83258.20", "5.386146"], ["83249.80", "4.199368"], ["83241.40", "4.655821"], ["83233.00", "4.929693"], ["83224.60", "4.381949"], ["83216.20", "3.925496"], ["82937.59", "0"], ["82937.50", "0"]], "checksum": 2015919445, "ts": "1742377415411"}], "ts": 1742377415415, "record_time": 1742377416.30667}
{"action": "update", "arg": {"instType": "SPOT", "channel": "books", "instId": "BTCUSDT"}, "data": [{"asks": [["83463.55", "0"], ["83470.32", "0"], ["83471.03", "0.006357"], ["83481.10", "0.001925"], ["83483.10", "0.003140"], ["83485.10", "0.008265"], ["83487.10", "0.021749"], ["83489.09", "0.057794"], ["83489.10", "0.057235"], ["83491.10", "0.150618"], ["83493.10", "0.396364"], ["83495.10", "1.043061"], ["83497.10", "2.744899"], ["83499.10", "7.223419"], ["83501.10", "19.008995"], ["83542.80", "4.929693"], ["83551.20", "4.199368"], ["83559.60", "4.290659"], ["83568.00", "4.838403"], ["83576.40", "5.660018"], ["83584.80", "4.564531"], ["83601.60", "5.386146"], ["83610.00", "5.294856"], ["83618.40", "4.747112"], ["83626.80", "5.477437"], ["83635.20", "4.108078"], ["83643.60", "5.112274"], ["83652.00", "5.203565"], ["83660.40", "4.473240"], ["83668.80", "5.568727"], ["83677.20", "5.020984"], ["83694.00", "4.016787"], ["83702.40", "4.381949"]], "bids": [["83427.57", "0"], ["83423.51", "0.331522"], ["83423.01", "0"], ["83416.79", "0.065048"], ["83416.09", "0"], ["83395.00", "0.000161"], ["83367.40", "5.386146"], ["83359.00", "4.747112"], ["83342.20", "4.655821"], ["83333.80", "3.925496"], ["83325.40", "4.838403"], ["83317.00", "5.660018"], ["83308.60", "4.381949"], ["83300.20", "4.108078"], ["83291.80", "5.294856"], ["83275.00", "4.016787"], ["83266.60", "4.929693"], ["83258.20", "5.112274"], ["83249.80", "4.290659"], ["83241.40", "4.199368"], ["83233.00", "4.564531"], ["83224.60", "5.020984"], ["83216.20", "5.477437"], ["82937.59", "0.000423"]], "checksum": -1688306613, "ts": "1742377415619"}], "ts": 1742377415621, "record_time": 1742377416.520737}
{"action": "update", "arg": {"instType": "SPOT", "channel": "books", "instId": "BTCUSDT"}, "data": [{"asks": [["83459.95", "0.479763"], ["83463.54", "0.143050"], ["83481.10", "0.001765"], ["83483.10", "0.002880"], ["83485.10", "0.007579"], ["83487.10", "0.019945"], ["83489.10", "0.052485"], ["83491.10", "0.138121"], ["83493.10", "0.363475"], ["83495.10", "0.956513"], ["83497.10", "2.517140"], ["83499.10", "6.624052"], ["83501.10", "17.431715"], ["83542.80", "4.838403"], ["83551.20", "5.294856"], ["83568.00", "5.020984"], ["83568.97", "0"], ["83576.40", "4.655821"], ["83584.80", "3.925496"], ["83593.20", "4.747112"], ["83601.60", "5.477437"], ["83610.00", "4.108078"], ["83618.40", "4.929693"], ["83626.80", "5.660018"], ["83635.20", "4.473240"], ["83643.60", "4.381949"], ["83660.40", "4.199368"], ["83668.80", "4.016787"], ["83677.20", "5.568727"], ["83685.60", "5.386146"], ["83694.00", "4.564531"], ["83702.40", "5.112274"]], "bids": [["83444.21", "0.045559"], ["83444.18", "0"], ["83429.50", "0.006274"], ["83427.50", "0.016509"], ["83425.50", "0.043446"], ["83423.50", "0.114332"], ["83421.50", "0.300873"], ["83419.51", "0.305328"], ["83419.50", "0.791772"], ["83417.50", "2.083609"], ["83393.00", "0"], ["83375.80", "5.112274"], ["83367.40", "5.568727"], ["83359.00", "4.838403"], ["83350.60", "4.199368"], ["83342.20", "4.108078"], ["83325.40", "5.203565"], ["83317.00", "4.290659"], ["83308.60", "4.564531"], ["83300.20", "4.473240"], ["83291.80", "4.381949"], ["83283.40", "4.929693"], ["83275.00", "5.294856"], ["83266.60", "4.655821"], ["83258.20", "5.020984"], ["83249.80", "5.477437"], ["83241.40", "4.016787"], ["83233.00", "4.747112"], ["83224.60", "5.660018"], ["83216.20", "5.386146"], ["82937.50", "0.000012"]], "checksum": 296330278, "ts": "1742377415827"}], "ts": 1742377415830, "record_time": 1742377416.719845}
{"action": "update", "arg": {"instType": "SPOT", "channel": "books", "instId": "BTCUSDT"}, "data": [{"asks": [["83459.91", "0.198844"], ["83508.70", "4.258500"], ["83542.80", "4.290659"], ["83551.20", "5.020984"], ["83559.60", "5.294856"], ["83563.35", "0.132255"], ["83568.00", "5.568727"], ["83576.40", "5.203565"], ["83593.19", "0"], ["83593.20", "4.108078"], ["83601.60", "4.747112"], ["83610.00", "5.477437"], ["83618.40", "4.199368"], ["83626.80", "5.112274"], ["83630.57", "0.167488"], ["83635.20", "4.655821"], ["83643.60", "4.838403"], ["83652.00", "4.929693"], ["83660.40", "4.381949"], ["83677.20", "5.386146"], ["83685.60", "5.660018"], ["83694.00", "4.473240"], ["83702.40", "4.564531"], ["83772.00", "0"]], "bids": [["83375.80", "4.199368"], ["83367.40", "4.838403"], ["83359.00", "5.294856"], ["83350.60", "4.747112"], ["83342.20", "4.564531"], ["83333.80", "4.473240"], ["83325.40", "4.108078"], ["83317.00", "5.112274"], ["83308.60", "4.016787"], ["83300.20", "4.655821"], ["83291.80", "4.929693"], ["83283.40", "5.020984"], ["83275.00", "5.660018"], ["83266.60", "4.381949"], ["83258.20", "4.290659"], ["83241.40", "5.203565"], ["83233.00", "5.568727"], ["83224.60", "3.925496"]], "checksum": 776948247, "ts": "1742377416034"}], "ts": 1742377416039, "record_time": 1742377416.94197}
{"action": "update", "arg": {"instType": "SPOT", "channel": "books", "instId": "BTCUSDT"}, "data": [{"asks": [["83464.49", "0"], ["83489.10", "0.052352"], ["83491.10", "0.137767"], ["83493.10", "0.362546"], ["83495.10", "0.954068"], ["83497.10", "2.510704"], ["83499.10", "6.607117"], ["83501.10", "17.387150"], ["83502.40", "0.073560"], ["83503.80", "0.213600"], ["83511.40", "0"], ["83542.80", "4.199368"], ["83551.20", "5.294856"], ["83559.60", "5.203565"], ["83568.00", "4.381949"], ["83576.40", "4.108078"], ["83593.20", "5.568727"], ["83601.60", "5.020984"], ["83610.00", "4.929693"], ["83618.40", "5.386146"], ["83626.80", "4.747112"], ["83635.20", "5.112274"], ["83643.60", "4.564531"], ["83652.00", "4.655821"], ["83660.40", "4.473240"], ["83668.80", "4.838403"], ["83677.20", "5.660018"], ["83685.60", "4.016787"], ["83694.00", "4.290659"], ["83702.40", "5.477437"], ["83772.00", "0.000096"]], "bids": [["83445.00", "0.380549"], ["83375.80", "5.020984"], ["83367.40", "4.016787"], ["83359.00", "5.203565"], ["83350.60", "5.294856"], ["83342.20", "4.381949"], ["83333.80", "4.199368"], ["83325.40", "4.564531"], ["83317.00", "3.925496"], ["83308.60", "5.477437"], ["83300.20", "4.747112"], ["83291.80", "5.568727"], ["83283.40", "4.108078"], ["83266.60", "4.929693"], ["83258.20", "4.473240"], ["83249.80", "4.290659"], ["83241.40", "4.655821"], ["83233.00", "4.838403"], ["83224.60", "5.386146"], ["83216.20", "5.112274"]], "checksum": -1056492624, "ts": "1742377416240"}], "ts": 1742377416243, "record_time": 1742377417.136947}
{"action": "update", "arg": {"instType": "SPOT", "channel": "books", "instId": "BTCUSDT"}, "data": [{"asks": [["83469.38", "0.013175"], ["83497.10", "2.510860"], ["83499.10", "6.607266"], ["83501.10", "17.387540"], ["83511.20", "0"], ["83542.80", "5.477437"], ["83551.20", "4.290659"], ["83559.60", "5.568727"], ["83568.00", "4.655821"], ["83576.40", "5.386146"], ["83593.20", "5.294856"], ["83601.60", "4.473240"], ["83610.00", "5.112274"], ["83618.40", "5.660018"], ["83635.20", "4.381949"], ["83643.60", "4.108078"], ["83652.00", "5.020984"], ["83660.40", "4.838403"], ["83668.80", "4.016787"], ["83677.20", "5.203565"], ["83685.60", "4.564531"], ["83694.00", "4.199368"], ["83702.40", "4.929693"]], "bids": [["83444.23", "0.045559"], ["83444.21", "0"], ["83427.50", "0.016332"], ["83425.50", "0.042978"], ["83423.50", "0.113102"], ["83421.50", "0.297637"], ["83419.50", "0.783255"], ["83417.50", "2.061196"], ["83394.00", "0.000283"], ["83393.00", "0.000122"], ["83375.80", "4.655821"], ["83367.40", "4.199368"], ["83350.60", "4.108078"], ["83342.20", "4.838403"], ["83333.80", "3.925496"], ["83325.40", "5.477437"], ["83317.00", "4.290659"], ["83308.60", "4.929693"], ["83300.20", "4.473240"], ["83291.80", "5.660018"], ["83283.40", "5.386146"], ["83275.00", "5.020984"], ["83266.60", "4.016787"], ["83258.20", "4.564531"], ["83249.80", "5.568727"], ["83241.40", "4.747112"], ["83233.00", "5.112274"], ["83224.60", "4.381949"], ["83216.20", "5.294856"], ["82937.50", "0"]], "checksum": 251667158, "ts": "1742377416448"}], "ts": 1742377416451, "record_time": 1742377417.347972}
{"action": "update", "arg": {"instType": "SPOT", "channel": "books", "instId": "BTCUSDT"}, "data": [{"asks": [["83481.10", "0.001921"], ["83483.10", "0.003133"], ["83485.10", "0.008245"], ["83487.10", "0.021699"], ["83489.10", "0.057102"], ["83491.10", "0.150268"], ["83493.10", "0.395442"], ["83495.07", "0"], ["83495.10", "1.040638"], ["83497.10", "2.738520"], ["83499.10", "7.206632"], ["83501.10", "18.964820"], ["83501.30", "0.931500"], ["83502.40", "2.446230"], ["83504.70", "0"], ["83511.20", "0.072570"], ["83511.40", "1.012440"], ["83542.80", "5.660018"], ["83551.20", "4.929693"], ["83559.60", "4.381949"], ["83568.00", "5.386146"], ["83575.63", "0"], ["83576.40", "4.199368"], ["83584.80", "4.473240"], ["83593.20", "4.016787"], ["83601.60", "4.838403"], ["83610.00", "3.925496"], ["83618.40", "5.112274"], ["83626.80", "5.294856"], ["83635.20", "5.020984"], ["83643.60", "4.290659"], ["83652.00", "5.477437"], ["83660.40", "5.203565"], ["83668.80", "4.747112"], ["83677.20", "4.564531"], ["83685.60", "4.655821"], ["83694.00", "5.568727"], ["83702.40", "4.108078"], ["83772.50", "0.000008"]], "bids": [["83413.50", "0"], ["83413.22", "0"], ["83403.50", "0"], ["83375.80", "5.203565"], ["83367.40", "4.473240"], ["83359.00", "5.112274"], ["83353.81", "0"], ["83350.60", "4.199368"], ["83342.20", "4.564531"], ["83333.80", "5.020984"], ["83325.40", "4.381949"], ["83317.00", "4.016787"], ["83308.60", "3.925496"], ["83300.20", "5.477437"], ["83291.80", "5.568727"], ["83283.40", "4.655821"], ["83275.00", "4.929693"], ["83266.60", "5.660018"], ["83258.20", "4.838403"], ["83249.80", "4.290659"], ["83241.40", "5.294856"], ["83233.00", "5.386146"], ["83224.60", "4.108078"], ["83216.20", "4.747112"], ["82937.50", "0.000012"], ["82936.29", "0.000067"], ["82935.00", "0.000121"], ["82934.78", "0.000010"]], "checksum": 251667158, "ts": "1742377416682"}], "ts": 1742377416685, "record_time": 1742377417.577043}
{"action": "update", "arg": {"instType": "SPOT", "channel": "books", "instId": "BTCUSDT"}, "data": [{"asks": [["83501.10", "18.964560"], ["83542.80", "4.108078"], ["83551.20", "5.477437"], ["83559.60", "5.203565"], ["83568.00", "4.747112"], ["83576.40", "4.473240"], ["83584.80", "4.199368"], ["83593.20", "5.112274"], ["83601.60", "4.381949"], ["83610.00", "4.655821"], ["83618.40", "5.386146"], ["83626.80", "5.020984"], ["83635.20", "4.016787"], ["83643.60", "3.925496"], ["83652.00", "5.568727"], ["83660.40", "5.660018"], ["83668.80", "4.564531"], ["83677.20", "4.929693"], ["83685.60", "4.838403"], ["83694.00", "4.290659"], ["83702.40", "5.294856"]], "bids": [["83444.26", "0.045559"], ["83444.23", "0"], ["83417.50", "2.061438"], ["83375.80", "5.112274"], ["83367.40", "5.294856"], ["83359.00", "4.838403"], ["83350.60", "4.016787"], ["83342.20", "4.381949"], ["83333.80", "4.473240"], ["83325.40", "3.925496"], ["83317.00", "4.199368"], ["83308.60", "4.290659"], ["83300.20", "5.386146"], ["83291.80", "5.203565"], ["83283.40", "5.477437"], ["83275.00", "4.108078"], ["83266.60", "4.655821"], ["83258.20", "5.568727"], ["83249.80", "4.929693"], ["83241.40", "4.564531"], ["83233.00", "5.660018"], ["83224.60", "4.747112"], ["83216.20", "5.020984"]], "checksum": 796692200, "ts": "1742377416892"}], "ts": 1742377416896, "record_time": 1742377417.792157}
{"action": "update", "arg": {"instType": "SPOT", "channel": "books", "instId": "BTCUSDT"}, "data": [{"asks": [["83505.20", "0.015000"], ["83542.80", "4.747112"], ["83551.20", "4.108078"], ["83559.60", "5.020984"], ["83568.00", "5.660018"], ["83576.40", "4.838403"], ["83584.80", "5.568727"], ["83593.20", "5.386146"], ["83601.60", "4.290659"], ["83610.00", "5.203565"], ["83618.40", "5.294856"], ["83626.80", "4.564531"], ["83635.20", "4.199368"], ["83643.60", "4.929693"], ["83652.00", "3.925496"], ["83660.40", "5.112274"], ["83668.80", "4.016787"], ["83677.20", "5.477437"], ["83685.60", "4.381949"], ["83694.00", "4.655821"], ["83702.40", "4.473240"], ["83772.50", "0"]], "bids": [["83423.50", "0.113117"], ["83421.50", "0.297677"], ["83419.50", "0.783361"], ["83417.50", "2.061475"], ["83409.00", "0.407970"], ["83395.00", "0"], ["83394.00", "0.000161"], ["83375.80", "4.381949"], ["83367.40", "5.203565"], ["83359.00", "4.929693"], ["83350.60", "5.477437"], ["83342.20", "5.660018"], ["83333.80", "5.386146"], ["83325.40", "4.108078"], ["83317.00", "3.925496"], ["83308.60", "4.016787"], ["83300.20", "4.747112"], ["83291.80", "4.290659"], ["83283.40", "4.655821"], ["83275.00", "5.020984"], ["83266.60", "5.112274"], ["83258.20", "4.838403"], ["83249.80", "4.473240"], ["83241.40", "5.294856"], ["83233.00", "4.564531"], ["83224.60", "4.199368"], ["83216.20", "5.568727"], ["82933.33", "0.000019"]], "checksum": 796692200, "ts": "1742377417099"}], "ts": 1742377417101, "record_time": 1742377417.991671}
{"action": "update", "arg": {"instType": "SPOT", "channel": "books", "instId": "BTCUSDT"}, "data": [{"asks": [["83542.80", "5.660018"], ["83551.20", "4.381949"], ["83559.60", "4.655821"], ["83568.00", "4.016787"], ["83576.40", "4.290659"], ["83584.80", "4.108078"], ["83593.20", "4.199368"], ["83601.60", "4.564531"], ["83610.00", "4.929693"], ["83618.40", "5.568727"], ["83626.80", "3.925496"], ["83635.20", "4.747112"], ["83643.60", "5.386146"], ["83652.00", "5.020984"], ["83660.40", "5.477437"], ["83668.80", "5.112274"], ["83677.20", "5.294856"], ["83685.60", "4.473240"], ["83694.00", "5.203565"], ["83702.40", "4.838403"]], "bids": [["83375.80", "5.660018"], ["83367.40", "4.473240"], ["83359.00", "5.112274"], ["83350.60", "5.020984"], ["83342.20", "4.290659"], ["83333.80", "5.203565"], ["83325.40", "4.838403"], ["83317.00", "5.294856"], ["83308.60", "4.108078"], ["83300.20", "4.199368"], ["83291.80", "4.747112"], ["83283.40", "3.925496"], ["83275.00", "4.929693"], ["83266.60", "5.386146"], ["83258.20", "5.568727"], ["83249.80", "4.381949"], ["83241.40", "5.477437"], ["83233.00", "4.655821"], ["83224.60", "4.564531"], ["83216.20", "4.016787"]], "checksum": 796692200, "ts": "1742377417308"}], "ts": 1742377417315, "record_time": 1742377418.217572}
{"action": "update", "arg": {"instType": "SPOT", "channel": "books", "instId": "BTCUSDT"}, "data": [{"asks": [["83497.10", "2.738407"], ["83499.10", "7.206335"], ["83501.10", "18.964039"], ["83542.80", "5.294856"], ["83551.20", "4.655821"], ["83559.60", "4.838403"], ["83568.00", "5.568727"], ["83576.40", "4.564531"], ["83584.80", "4.929693"], ["83593.20", "4.290659"], ["83601.60", "4.108078"], ["83610.00", "4.016787"], ["83618.40", "4.473240"], ["83626.80", "5.386146"], ["83643.60", "5.477437"], ["83652.00", "5.203565"], ["83660.40", "5.020984"], ["83668.80", "3.925496"], ["83677.20", "5.112274"], ["83685.60", "4.199368"], ["83694.00", "4.381949"], ["83702.40", "5.660018"]], "bids": [["83444.29", "0.045559"], ["83444.26", "0"], ["83441.75", "0"], ["83375.80", "4.838403"], ["83367.40", "4.016787"], ["83359.00", "5.294856"], ["83350.60", "5.477437"], ["83342.20", "5.203565"], ["83333.80", "5.020984"], ["83325.40", "5.568727"], ["83317.00", "4.747112"], ["83308.60", "4.199368"], ["83300.20", "5.386146"], ["83291.80", "5.660018"], ["83275.00", "4.655821"], ["83266.60", "4.929693"], ["83258.20", "4.108078"], ["83249.80", "4.290659"], ["83241.40", "4.381949"], ["83233.00", "5.112274"], ["83216.20", "4.473240"], ["82932.20", "0.000023"]], "checksum": 724872130, "ts": "1742377417518"}], "ts": 1742377417523, "record_time": 1742377418.425765}
{"action": "update", "arg": {"instType": "SPOT", "channel": "books", "instId": "BTCUSDT"}, "data": [{"asks": [["83493.10", "0.395225"], ["83495.10", "1.040066"], ["83497.10", "2.737016"], ["83499.10", "7.202674"], ["83501.10", "18.954404"], ["83542.80", "4.747112"], ["83551.20", "5.568727"], ["83559.60", "3.925496"], ["83568.00", "4.016787"], ["83576.40", "4.108078"], ["83584.80", "5.112274"], ["83587.23", "0.010000"], ["83593.20", "5.660018"], ["83601.60", "4.381949"], ["83610.00", "4.473240"], ["83618.40", "4.929693"], ["83635.20", "4.290659"], ["83643.60", "4.199368"], ["83660.40", "5.477437"], ["83668.80", "5.020984"], ["83677.20", "4.838403"], ["83685.60", "5.294856"], ["83694.00", "4.655821"], ["83702.40", "4.564531"], ["83772.00", "0"]], "bids": [["83439.67", "0.004151"], ["83429.50", "0.006126"], ["83427.50", "0.016119"], ["83425.50", "0.042419"], ["83423.50", "0.111629"], ["83421.50", "0.293761"], ["83419.50", "0.773056"], ["83417.50", "2.034356"], ["83408.40", "0.360000"], ["83395.79", "0"], ["83395.00", "0.000122"], ["83393.00", "0.000283"], ["83375.80", "4.929693"], ["83367.40", "4.381949"], ["83350.60", "4.838403"], ["83342.20", "5.660018"], ["83333.80", "4.199368"], ["83325.40", "5.203565"], ["83317.00", "5.568727"], ["83308.60", "5.112274"], ["83300.20", "4.290659"], ["83291.80", "3.925496"], ["83288.83", "0.007500"], ["83283.40", "4.473240"], ["83275.00", "4.564531"], ["83266.60", "4.108078"], ["83258.20", "5.386146"], ["83249.80", "4.747112"], ["83241.40", "5.477437"], ["83233.00", "4.655821"], ["83224.60", "4.016787"], ["83216.20", "5.020984"], ["82933.33", "0"], ["82932.20", "0"]], "checksum": 111631657, "ts": "1742377417733"}], "ts": 1742377417735, "record_time": 1742377418.64427}
{"action": "update", "arg": {"instType": "SPOT", "channel": "books", "instId": "BTCUSDT"}, "data": [{"asks": [["83499.10", "7.202886"], ["83501.10", "18.954962"], ["83542.80", "4.108078"], ["83551.20", "5.477437"], ["83559.60", "5.660018"], ["83568.00", "4.290659"], ["83576.40", "5.386146"], ["83584.80", "4.473240"], ["83593.20", "4.199368"], ["83601.60", "4.016787"], ["83610.00", "5.112274"], ["83618.40", "4.838403"], ["83626.80", "3.925496"], ["83635.20", "5.020984"], ["83643.60", "4.564531"], ["83652.00", "4.929693"], ["83660.40", "4.655821"], ["83668.80", "5.568727"], ["83677.20", "5.203565"], ["83685.60", "4.747112"], ["83694.00", "4.381949"], ["83702.40", "5.294856"]], "bids": [["83444.31", "0.045559"], ["83444.29", "0"], ["83433.11", "0"], ["83427.50", "0.015885"], ["83425.50", "0.041804"], ["83423.50", "0.110008"], ["83421.50", "0.289496"], ["83419.50", "0.761831"], ["83417.50", "2.004820"], ["83408.40", "0.240000"], ["83407.30", "0.347850"], ["83375.80", "4.655821"], ["83367.40", "5.568727"], ["83359.00", "4.564531"], ["83350.60", "4.108078"], ["83342.20", "5.477437"], ["83333.80", "4.290659"], ["83325.40", "5.020984"], ["83317.00", "3.925496"], ["83308.60", "4.747112"], ["83300.20", "4.199368"], ["83291.80", "5.386146"], ["83283.40", "4.929693"], ["83275.00", "5.294856"], ["83266.60", "5.112274"], ["83258.20", "4.016787"], ["83249.80", "4.381949"], ["83241.40", "4.838403"], ["83233.00", "4.473240"], ["83224.60", "5.203565"], ["83216.20", "5.660018"], ["82933.33", "0.000019"]], "checksum": 1097904478, "ts": "1742377417939"}], "ts": 1742377417946, "record_time": 1742377418.843454}
{"action": "update", "arg": {"instType": "SPOT", "channel": "books", "instId": "BTCUSDT"}, "data": [{"asks": [["83503.80", "0.213780"], ["83505.20", "0"], ["83508.40", "0.598230"], ["83510.50", "0.056610"], ["83551.20", "4.016787"], ["83559.60", "4.747112"], ["83568.00", "5.020984"], ["83576.40", "5.477437"], ["83584.80", "3.925496"], ["83593.20", "4.473240"], ["83601.60", "5.660018"], ["83610.00", "4.199368"], ["83618.40", "5.294856"], ["83626.80", "5.112274"], ["83635.20", "5.203565"], ["83643.60", "4.838403"], ["83652.00", "4.655821"], ["83660.40", "4.564531"], ["83668.80", "4.929693"], ["83677.20", "5.386146"], ["83685.60", "4.290659"], ["83702.40", "5.568727"]], "bids": [["83431.60", "0.111708"], ["83429.50", "0.005918"], ["83427.50", "0.015574"], ["83425.50", "0.040828"], ["83423.50", "0.107442"], ["83421.50", "0.282744"], ["83419.50", "0.744063"], ["83417.50", "1.958320"], ["83415.90", "0.007380"], ["83414.40", "0.102480"], ["83408.40", "0"], ["83407.30", "0.480000"], ["83406.90", "0.107850"], ["83375.80", "4.747112"], ["83367.40", "4.655821"], ["83359.00", "5.477437"], ["83350.60", "3.925496"], ["83342.20", "4.564531"], ["83333.80", "4.016787"], ["83325.40", "4.929693"], ["83317.00", "5.568727"], ["83308.60", "5.020984"], ["83300.20", "5.386146"], ["83291.80", "5.112274"], ["83283.40", "5.660018"], ["83275.00", "4.838403"], ["83266.60", "4.290659"], ["83258.20", "4.473240"], ["83249.80", "4.199368"], ["83241.40", "4.108078"], ["83233.00", "4.381949"], ["83224.60", "5.294856"], ["83216.20", "5.203565"], ["82934.78", "0"], ["82933.33", "0"]], "checksum": 1097904478, "ts": "1742377418153"}], "ts": 1742377418156, "record_time": 1742377419.046336}
{"action": "update", "arg": {"instType": "SPOT", "channel": "books", "instId": "BTCUSDT"}, "data": [{"asks": [["83448.62", "0"], ["83449.59", "0"], ["83449.63", "0"], ["83454.53", "0"], ["83456.50", "0.479763"], ["83459.95", "0"], ["83465.16", "0"], ["83475.10", "0.001237"], ["83477.10", "0.002018"], ["83479.10", "0.005312"], ["83481.10", "0.013978"], ["83481.85", "0"], ["83483.10", "0.036784"], ["83485.10", "0.096801"], ["83487.10", "0.254738"], ["83489.10", "0.670364"], ["83491.10", "1.764116"], ["83493.10", "4.642411"], ["83495.10", "12.216871"], ["83495.80", "0.215040"], ["83496.19", "0.001598"], ["83496.30", "0.001025"], ["83496.70", "6.484620"], ["83496.80", "0.001030"], ["83497.10", "0"], ["83497.23", "0"], ["83497.40", "0.014820"], ["83497.50", "4.277100"], ["83497.80", "0.213780"], ["83498.10", "1.079220"], ["83499.10", "0.179730"], ["83499.30", "0.143880"], ["83499.80", "0.213780"], ["83500.30", "3.840450"], ["83500.40", "2.142750"], ["83500.80", "0.011130"], ["83501.00", "0.004320"], ["83501.10", "4.298220"], ["83501.20", "0"], ["83501.30", "0"], ["83501.80", "0.213930"], ["83501.90", "0"], ["83502.40", "0.151410"], ["83502.80", "0.143700"], ["83503.00", "0.008340"], ["83503.10", "0.269760"], ["83503.80", "0.213600"], ["83504.60", "0"], ["83505.10", "0.320880"], ["83507.50", "0.180000"], ["83508.40", "0.240000"], ["83508.70", "5.700090"], ["83509.00", "0"], ["83509.10", "0"], ["83509.20", "0"], ["83509.40", "0"], ["83509.80", "0"], ["83510.40", "0"], ["83510.50", "0"], ["83510.60", "0"], ["83511.20", "0"], ["83511.40", "0"], ["83536.80", "4.930048"], ["83542.80", "0"], ["83545.20", "4.199670"], ["83551.20", "0"], ["83553.60", "4.382265"], ["83559.60", "0"], ["83562.00", "4.564859"], ["83566.51", "0.072173"], ["83568.00", "0"], ["83570.40", "5.295236"], ["83576.40", "0"], ["83578.80", "4.747453"], ["83584.80", "0"], ["83587.20", "4.108373"], ["83593.20", "0"], ["83595.60", "4.290967"], ["83597.96", "0"], ["83601.60", "0"], ["83604.00", "4.017076"], ["83610.00", "0.002000"], ["83612.40", "5.021345"], ["83618.40", "0"], ["83620.80", "3.925779"], ["83626.80", "0"], ["83629.20", "5.203939"], ["83635.20", "0"], ["83637.60", "4.656156"], ["83643.60", "0"], ["83646.00", "4.473562"], ["83652.00", "0.000097"], ["83654.40", "4.838750"], ["83660.40", "0"], ["83662.80", "5.386533"], ["83668.80", "0"], ["83671.20", "5.660425"], ["83677.20", "0"], ["83679.60", "5.112642"], ["83685.60", "0"], ["83688.00", "5.569128"], ["83694.00", "0"], ["83696.40", "5.477831"], ["83702.40", "0"]], "bids": [["83445.00", "0.043126"], ["83444.31", "0"], ["83437.50", "0"], ["83435.50", "0"], ["83433.50", "0"], ["83431.95", "0"], ["83431.94", "0"], ["83431.93", "0"], ["83431.90", "0"], ["83431.50", "0.001035"], ["83429.50", "0.001002"], ["83427.50", "0.001022"], ["83426.24", "0"], ["83426.16", "0"], ["83425.97", "0.009788"], ["83425.96", "0.013320"], ["83425.95", "0.008274"], ["83425.93", "0.013722"], ["83425.61", "0"], ["83425.50", "0.001009"], ["83424.54", "0"], ["83424.53", "0"], ["83424.52", "0"], ["83424.02", "0"], ["83423.97", "0"], ["83423.96", "0"], ["83423.94", "0"], ["83423.93", "0"], ["83423.50", "0.001032"], ["83422.71", "0"], ["83421.60", "0"], ["83421.56", "0"], ["83421.54", "0"], ["83421.53", "0"], ["83421.52", "0"], ["83421.51", "0"], ["83421.50", "0.002714"], ["83421.49", "0"], ["83421.43", "0"], ["83419.86", "0"], ["83419.50", "0.007142"], ["83417.95", "0"], ["83417.50", "0.018796"], ["83417.30", "0"], ["83416.88", "0"], ["83416.85", "0"], ["83416.80", "0"], ["83416.74", "0.007470"], ["83416.03", "0.008229"], ["83415.90", "0"], ["83415.60", "0.009429"], ["83415.55", "0.001000"], ["83415.53", "0.006582"], ["83415.52", "2.551073"], ["83415.51", "0.020714"], ["83415.50", "0.057498"], ["83415.49", "0.014683"], ["83415.47", "0.017955"], ["83415.43", "0.009987"], ["83414.43", "0"], ["83414.42", "0.007234"], ["83414.41", "0.007338"], ["83414.40", "0.007685"], ["83413.95", "0.245695"], ["83413.92", "0.007495"], ["83413.91", "0.009508"], ["83413.90", "0"], ["83413.88", "0.007934"], ["83413.50", "0.130164"], ["83413.10", "0"], ["83412.80", "0"], ["83411.50", "0.342538"], ["83411.40", "0.026070"], ["83411.30", "0.023640"], ["83410.90", "0.012498"], ["83410.10", "0.001019"], ["83409.80", "0.001026"], ["83409.00", "0.408150"], ["83408.90", "0.120180"], ["83408.80", "0.255480"], ["83408.70", "0"], ["83408.41", "0.008938"], ["83408.39", "0.008797"], ["83408.38", "0.000327"], ["83407.30", "0"], ["83406.90", "0"], ["83406.85", "0.005051"], ["83406.70", "0.008130"], ["83406.30", "0.840000"], ["83405.90", "0"], ["83404.20", "0.036060"], ["83403.50", "0.009000"], ["83403.47", "0"], ["83403.40", "0.120000"], ["83402.73", "0.023958"], ["83402.60", "1.186320"], ["83402.50", "0.120000"], ["83402.20", "0.007050"], ["83401.70", "0.143700"], ["83401.60", "0.301170"], ["83400.45", "0.024164"], ["83398.46", "0"], ["83394.00", "0"], ["83393.22", "0"], ["83388.41", "0.008539"], ["83387.76", "0"], ["83387.17", "0.008085"], ["83386.71", "0.001186"], ["83375.80", "0"], ["83369.80", "5.295236"], ["83367.40", "0"], ["83361.40", "5.021345"], ["83359.00", "0"], ["83353.00", "5.569128"], ["83350.60", "0"], ["83344.60", "4.290967"], ["83342.20", "0"], ["83336.20", "4.747453"], ["83333.80", "0"], ["83327.80", "4.838750"], ["83325.40", "0"], ["83319.40", "4.930048"], ["83317.00", "0"], ["83311.00", "5.112642"], ["83308.60", "0"], ["83302.60", "5.660425"], ["83300.20", "0"], ["83294.20", "4.382265"], ["83291.80", "0"], ["83285.80", "5.386533"], ["83283.40", "0"], ["83277.40", "4.564859"], ["83275.00", "0"], ["83269.00", "3.925779"], ["83266.60", "0"], ["83260.60", "5.203939"], ["83258.20", "0"], ["83252.20", "4.656156"], ["83249.80", "0"], ["83243.80", "5.477831"], ["83241.63", "0"], ["83241.40", "0"], ["83235.40", "4.199670"], ["83233.00", "0"], ["83227.00", "4.017076"], ["83224.60", "0"], ["83218.60", "4.473562"], ["83216.20", "0"], ["83210.20", "4.108373"], ["83176.24", "0.000419"], ["82934.78", "0.000010"], ["82933.33", "0.000019"], ["82932.20", "0.000023"], ["82931.04", "0.000146"], ["82930.60", "0.000009"], ["82930.00", "0.000076"], ["82929.67", "0.000096"], ["82928.18", "0.000015"]], "checksum": 339046016, "ts": "1742377418364"}], "ts": 1742377418368, "record_time": 1742377419.258973}
{"action": "update", "arg": {"instType": "SPOT", "channel": "books", "instId": "BTCUSDT"}, "data": [{"asks": [["83445.01", "1.286005"], ["83449.58", "0"], ["83454.52", "0.245362"], ["83459.91", "0.062760"], ["83463.54", "0"], ["83475.10", "0.001519"], ["83477.10", "0.002479"], ["83479.10", "0.006381"], ["83480.40", "0"], ["83481.10", "0.016791"], ["83483.10", "0.044189"], ["83485.10", "0.116287"], ["83487.10", "0.306017"], ["83489.10", "0.805308"], ["83491.10", "2.119233"], ["83493.10", "5.576928"], ["83495.10", "14.676125"], ["83495.80", "0.214860"], ["83496.70", "3.899550"], ["83496.80", "0"], ["83497.50", "1.728120"], ["83498.60", "0.077850"], ["83499.20", "0.179550"], ["83499.30", "0.143700"], ["83499.80", "0.213600"], ["83500.30", "1.817340"], ["83500.40", "2.142570"], ["83501.10", "2.727840"], ["83501.90", "0.360000"], ["83502.40", "0.073560"], ["83502.80", "0.431700"], ["83503.60", "0.552000"], ["83503.70", "0.276000"], ["83505.10", "0.553560"], ["83506.30", "0"], ["83507.50", "0"], ["83507.70", "0"], ["83507.80", "0"], ["83508.40", "0"], ["83508.70", "0"], ["83536.80", "5.477831"], ["83545.20", "4.017076"], ["83553.60", "5.386533"], ["83562.00", "4.108373"], ["83570.40", "4.747453"], ["83578.80", "4.382265"], ["83587.20", "4.199670"], ["83595.60", "5.295236"], ["83604.00", "5.569128"], ["83612.40", "5.203939"], ["83620.80", "5.021345"], ["83629.20", "4.838750"], ["83646.00", "4.564859"], ["83654.40", "4.473562"], ["83662.80", "4.290967"], ["83679.60", "4.930048"], ["83688.00", "5.112642"], ["83696.40", "3.925779"], ["83772.00", "0.000096"], ["83772.50", "0.000008"], ["83772.56", "0.000614"], ["83772.68", "0.000087"], ["83772.73", "0.000008"]], "bids": [["83445.00", "0.207566"], ["83438.41", "0.045563"], ["83425.50", "0.002386"], ["83423.51", "0"], ["83423.50", "0.006280"], ["83421.50", "0.016525"], ["83420.45", "0.006222"], ["83419.51", "0.134375"], ["83419.50", "0.043488"], ["83417.50", "0.114442"], ["83415.50", "0.301163"], ["83413.94", "0.009238"], ["83413.93", "0.009767"], ["83413.90", "0.007729"], ["83413.50", "0.792535"], ["83411.50", "2.085618"], ["83411.30", "0.023430"], ["83410.70", "0.001041"], ["83410.10", "0"], ["83409.80", "0"], ["83408.80", "0.255300"], ["83407.90", "0.066360"], ["83404.20", "0.062040"], ["83404.10", "0.107850"], ["83393.00", "0.000161"], ["83369.80", "5.660425"], ["83361.40", "4.199670"], ["83353.00", "4.108373"], ["83344.60", "4.930048"], ["83336.20", "4.290967"], ["83327.80", "5.021345"], ["83319.40", "5.295236"], ["83311.00", "4.473562"], ["83302.60", "4.838750"], ["83294.20", "5.203939"], ["83285.80", "4.656156"], ["83277.40", "4.747453"], ["83269.00", "5.477831"], ["83260.60", "4.382265"], ["83252.20", "5.569128"], ["83243.80", "5.112642"], ["83235.40", "4.564859"], ["83227.00", "3.925779"], ["83218.60", "4.017076"], ["83210.20", "5.386533"], ["83176.24", "0"], ["83125.43", "0"], ["83119.46", "1.662640"], ["82930.60", "0"], ["82930.00", "0"], ["82929.67", "0"], ["82928.18", "0"]], "checksum": -96430997, "ts": "1742377418565"}], "ts": 1742377418568, "record_time": 1742377419.492963}
{"action": "update", "arg": {"instType": "SPOT", "channel": "books", "instId": "BTCUSDT"}, "data": [{"asks": [["83445.77", "1.857027"], ["83456.48", "0.241774"], ["83456.50", "0"], ["83464.20", "0.055840"], ["83473.17", "3.699614"], ["83496.70", "3.899760"], ["83499.10", "0.179550"], ["83503.40", "0.009000"], ["83505.80", "0"], ["83536.80", "4.930048"], ["83545.20", "5.203939"], ["83553.60", "4.838750"], ["83562.00", "5.295236"], ["83570.40", "4.108373"], ["83578.80", "5.660425"], ["83587.20", "4.017076"], ["83595.60", "4.290967"], ["83604.00", "5.386533"], ["83612.40", "4.199670"], ["83620.80", "4.747453"], ["83629.20", "4.473562"], ["83637.60", "5.569128"], ["83646.00", "5.021345"], ["83654.40", "4.382265"], ["83662.80", "4.656156"], ["83671.20", "5.112642"], ["83679.60", "5.477831"], ["83688.00", "3.925779"], ["83696.40", "4.564859"], ["83772.56", "0"], ["83772.68", "0"], ["83772.73", "0"]], "bids": [["83445.00", "0.416766"], ["83415.53", "0.509057"], ["83406.86", "0.005218"], ["83369.80", "4.838750"], ["83361.40", "4.656156"], ["83344.60", "4.473562"], ["83336.20", "5.477831"], ["83327.80", "5.386533"], ["83319.40", "5.569128"], ["83311.00", "5.203939"], ["83302.60", "4.199670"], ["83294.20", "5.660425"], ["83285.80", "5.021345"], ["83277.40", "5.295236"], ["83269.00", "4.930048"], ["83252.20", "4.747453"], ["83235.40", "3.925779"], ["83227.00", "4.017076"], ["83218.60", "4.290967"], ["83210.20", "4.564859"], ["83157.14", "0.000428"], ["82932.20", "0"], ["82931.04", "0"]], "checksum": -1324496583, "ts": "1742377418780"}], "ts": 1742377418784, "record_time": 1742377419.674204}
{"action": "update", "arg": {"instType": "SPOT", "channel": "books", "instId": "BTCUSDT"}, "data": [{"asks": [["83445.76", "0.574802"], ["83445.92", "0"], ["83454.52", "0"], ["83462.27", "0.479763"], ["83475.10", "0.001358"], ["83477.10", "0.002217"], ["83479.10", "0.005832"], ["83481.10", "0.015349"], ["83483.10", "0.040391"], ["83485.10", "0.106292"], ["83487.10", "0.279716"], ["83489.10", "0.736095"], ["83491.10", "1.937093"], ["83493.10", "5.097611"], ["83494.81", "0"], ["83495.10", "13.414766"], ["83495.80", "0.001047"], ["83495.90", "0.001015"], ["83496.70", "1.165050"], ["83497.50", "1.727940"], ["83497.80", "0"], ["83498.10", "0"], ["83499.20", "0.179760"], ["83499.80", "0"], ["83500.40", "1.603890"], ["83501.10", "2.626200"], ["83502.40", "0"], ["83503.10", "0"], ["83505.80", "0.213600"], ["83506.10", "0.252000"], ["83506.30", "0.143700"], ["83506.90", "0.312000"], ["83536.80", "5.660425"], ["83545.20", "5.295236"], ["83553.60", "4.656156"], ["83562.00", "4.290967"], ["83578.80", "5.112642"], ["83587.20", "5.021345"], ["83595.60", "4.199670"], ["83604.00", "5.569128"], ["83612.40", "4.930048"], ["83620.80", "5.386533"], ["83629.20", "5.477831"], ["83637.60", "3.925779"], ["83646.00", "5.203939"], ["83662.80", "4.564859"], ["83671.20", "4.747453"], ["83679.60", "4.838750"], ["83688.00", "4.473562"], ["83696.40", "4.017076"], ["83772.56", "0.000614"]], "bids": [["83438.61", "0.045563"], ["83438.41", "0"], ["83427.50", "0.001319"], ["83426.13", "0.113516"], ["83425.50", "0.003470"], ["83423.50", "0.009131"], ["83421.50", "0.024029"], ["83419.50", "0.063234"], ["83417.50", "0.166407"], ["83415.50", "0.437913"], ["83415.20", "0.020924"], ["83413.50", "1.152402"], ["83411.50", "3.032637"], ["83410.90", "0.498210"], ["83410.70", "0"], ["83409.20", "0.108330"], ["83409.00", "0.000283"], ["83408.70", "0.143700"], ["83407.85", "0.018506"], ["83406.20", "0.220650"], ["83404.20", "0.009000"], ["83403.10", "1.350000"], ["83395.00", "0.000283"], ["83369.80", "4.473562"], ["83361.40", "5.295236"], ["83353.00", "5.569128"], ["83344.60", "4.656156"], ["83336.20", "4.199670"], ["83327.80", "4.838750"], ["83319.40", "5.203939"], ["83311.00", "5.021345"], ["83302.60", "4.290967"], ["83294.20", "4.382265"], ["83285.80", "5.660425"], ["83277.40", "4.747453"], ["83269.00", "5.477831"], ["83260.60", "4.108373"], ["83252.20", "3.925779"], ["83235.40", "4.564859"], ["83218.60", "4.930048"], ["83210.20", "5.386533"], ["82937.50", "0"], ["82936.29", "0"], ["82935.00", "0"], ["82934.78", "0"], ["82933.33", "0"]], "checksum": 2114253482, "ts": "1742377418990"}], "ts": 1742377418992, "record_time": 1742377419.882717}
{"action": "update", "arg": {"instType": "SPOT", "channel": "books", "instId": "BTCUSDT"}, "data": [{"asks": [["83445.01", "1.174297"], ["83455.79", "0.173965"], ["83495.10", "13.414915"], ["83498.47", "0.001598"], ["83499.37", "0"], ["83500.40", "0.253890"], ["83536.80", "4.290967"], ["83545.20", "4.017076"], ["83553.60", "4.747453"], ["83562.00", "4.930048"], ["83570.40", "5.569128"], ["83578.80", "5.203939"], ["83587.20", "4.199670"], ["83595.60", "5.021345"], ["83604.00", "4.382265"], ["83612.40", "3.925779"], ["83620.80", "4.564859"], ["83629.20", "4.473562"], ["83637.60", "4.108373"], ["83646.00", "4.838750"], ["83654.40", "5.386533"], ["83662.80", "5.477831"], ["83671.20", "5.660425"], ["83679.60", "5.112642"], ["83688.00", "4.656156"], ["83696.40", "5.295236"], ["83772.56", "0"]], "bids": [["83423.34", "0.195268"], ["83417.50", "0.166508"], ["83415.53", "0.006582"], ["83415.50", "0.438157"], ["83413.50", "1.153045"], ["83411.50", "3.034478"], ["83407.30", "0.015000"], ["83394.00", "0.000122"], ["83386.06", "0"], ["83385.16", "0.001183"], ["83369.80", "4.564859"], ["83361.40", "3.925779"], ["83353.00", "5.477831"], ["83344.60", "5.203939"], ["83336.20", "4.017076"], ["83327.80", "5.295236"], ["83319.40", "4.108373"], ["83302.60", "5.569128"], ["83294.20", "4.199670"], ["83285.80", "4.290967"], ["83277.40", "4.930048"], ["83269.00", "4.656156"], ["83260.60", "5.386533"], ["83252.20", "4.838750"], ["83243.80", "4.747453"], ["83235.40", "5.112642"], ["83227.00", "4.382265"], ["83218.60", "4.473562"], ["83210.20", "5.660425"], ["82938.60", "0"], ["82938.45", "0"], ["82937.59", "0"]], "checksum": -939624784, "ts": "1742377419191"}], "ts": 1742377419197, "record_time": 1742377420.089973}
{"action": "update", "arg": {"instType": "SPOT", "channel": "books", "instId": "BTCUSDT"}, "data": [{"asks": [["83445.01", "1.286006"], ["83462.26", "0.210554"], ["83464.20", "0"], ["83470.80", "0.119900"], ["83473.72", "0"], ["83474.98", "0.015895"], ["83475.81", "0.010984"], ["83477.89", "0"], ["83478.72", "0"], ["83498.30", "0.318510"], ["83501.10", "2.307690"], ["83536.80", "5.386533"], ["83545.20", "5.203939"], ["83553.60", "4.838750"], ["83562.00", "4.290967"], ["83570.40", "4.108373"], ["83578.80", "5.112642"], ["83587.20", "4.747453"], ["83595.60", "5.569128"], ["83604.00", "4.656156"], ["83612.40", "4.199670"], ["83620.80", "4.930048"], ["83637.60", "5.295236"], ["83646.00", "5.021345"], ["83654.40", "5.660425"], ["83662.80", "4.564859"], ["83671.20", "5.477831"], ["83679.60", "3.925779"], ["83688.00", "4.017076"], ["83696.40", "4.382265"], ["83772.50", "0"]], "bids": [["83438.66", "0"], ["83435.57", "0.001387"], ["83415.53", "0.200273"], ["83415.20", "0"], ["83413.64", "0"], ["83411.50", "3.034590"], ["83411.40", "0.002910"], ["83411.30", "0.001041"], ["83410.72", "0.262709"], ["83409.46", "0"], ["83408.63", "0"], ["83407.85", "0"], ["83406.56", "0.073759"], ["83405.72", "0.056755"], ["83405.60", "0.022620"], ["83405.20", "0.166440"], ["83401.70", "0"], ["83401.60", "0"], ["83399.47", "0.018506"], ["83369.80", "5.477831"], ["83361.40", "5.112642"], ["83353.00", "5.386533"], ["83344.60", "5.295236"], ["83336.20", "4.838750"], ["83327.80", "4.108373"], ["83319.40", "5.660425"], ["83302.60", "4.656156"], ["83294.20", "4.017076"], ["83285.80", "4.930048"], ["83277.40", "4.382265"], ["83269.00", "4.473562"], ["83260.60", "4.290967"], ["83252.20", "4.747453"], ["83243.80", "5.203939"], ["83235.40", "4.564859"], ["83227.00", "5.569128"], ["83218.60", "3.925779"], ["83210.20", "4.199670"], ["82938.60", "0.000022"], ["82938.45", "0.000022"]], "checksum": 1849409691, "ts": "1742377419395"}], "ts": 1742377419398, "record_time": 1742377420.290024}
{"action": "update", "arg": {"instType": "SPOT", "channel": "books", "instId": "BTCUSDT"}, "data": [{"asks": [["83471.65", "1.258039"], ["83477.10", "0.002106"], ["83477.17", "0"], ["83479.10", "0.005542"], ["83481.10", "0.014585"], ["83483.10", "0.038380"], ["83485.10", "0.101001"], ["83487.10", "0.265792"], ["83489.10", "0.699453"], ["83491.10", "1.840665"], ["83493.10", "4.843856"], ["83495.10", "12.746989"], ["83536.80", "4.290967"], ["83545.20", "5.386533"], ["83553.60", "4.382265"], ["83562.00", "4.930048"], ["83570.40", "4.564859"], ["83578.80", "4.838750"], ["83587.20", "5.295236"], ["83595.60", "5.660425"], ["83604.00", "4.747453"], ["83612.40", "5.112642"], ["83620.80", "5.203939"], ["83629.20", "4.108373"], ["83637.60", "3.925779"], ["83646.00", "4.017076"], ["83654.40", "4.473562"], ["83662.80", "5.477831"], ["83671.20", "5.021345"], ["83679.60", "5.569128"], ["83688.00", "4.199670"], ["83696.40", "4.656156"], ["83772.50", "0.000008"]], "bids": [["83438.87", "0.045562"], ["83438.61", "0"], ["83406.00", "0.021207"], ["83393.00", "0"], ["83369.80", "4.838750"], ["83361.40", "3.925779"], ["83353.00", "4.747453"], ["83344.60", "4.290967"], ["83336.20", "5.021345"], ["83327.80", "5.569128"], ["83319.40", "5.112642"], ["83311.00", "5.477831"], ["83294.20", "5.386533"], ["83285.80", "4.473562"], ["83277.40", "5.660425"], ["83269.00", "5.295236"], ["83260.60", "4.199670"], ["83252.20", "4.564859"], ["83235.40", "4.108373"], ["83227.00", "4.930048"], ["83218.60", "4.382265"], ["83210.20", "4.017076"], ["82937.59", "0.000423"]], "checksum": 1824002195, "ts": "1742377419609"}], "ts": 1742377419613, "record_time": 1742377420.504522}
{"action": "update", "arg": {"instType": "SPOT", "channel": "books", "instId": "BTCUSDT"}, "data": [{"asks": [["83462.27", "0"], ["83468.76", "0"], ["83489.10", "0.699217"], ["83491.10", "1.840045"], ["83493.10", "4.842223"], ["83495.10", "12.742693"], ["83536.80", "4.656156"], ["83545.20", "5.477831"], ["83553.60", "4.473562"], ["83562.00", "4.747453"], ["83570.40", "4.290967"], ["83578.80", "5.386533"], ["83587.20", "3.925779"], ["83595.60", "4.838750"], ["83604.00", "5.112642"], ["83612.40", "4.199670"], ["83620.80", "4.382265"], ["83629.20", "5.021345"], ["83637.60", "5.660425"], ["83654.40", "5.203939"], ["83662.80", "4.108373"], ["83671.20", "5.295236"], ["83688.00", "4.930048"], ["83696.40", "4.564859"], ["83772.56", "0.000614"], ["83772.68", "0.000087"]], "bids": [["83439.67", "0"], ["83411.50", "3.034404"], ["83369.80", "4.747453"], ["83361.40", "4.290967"], ["83353.00", "5.021345"], ["83344.60", "5.295236"], ["83336.20", "5.203939"], ["83327.80", "5.660425"], ["83319.40", "4.656156"], ["83311.00", "4.473562"], ["83302.60", "4.564859"], ["83285.80", "4.382265"], ["83277.40", "4.930048"], ["83269.00", "4.017076"], ["83260.60", "5.569128"], ["83252.20", "4.199670"], ["83243.80", "4.838750"], ["83235.40", "5.112642"], ["83227.00", "3.925779"], ["83218.60", "5.477831"], ["83210.20", "4.108373"], ["82937.50", "0.000012"]], "checksum": -1380123113, "ts": "1742377419818"}], "ts": 1742377419821, "record_time": 1742377420.729766}
{"action": "update", "arg": {"instType": "SPOT", "channel": "books", "instId": "BTCUSDT"}, "data": [{"asks": [["83445.01", "1.011732"], ["83453.73", "0.051217"], ["83462.26", "0.066626"], ["83468.91", "0.181233"], ["83469.15", "0.479763"], ["83469.38", "0"], ["83472.57", "0.013175"], ["83475.10", "0.001027"], ["83477.10", "0.001032"], ["83479.10", "0.001006"], ["83481.10", "0.002172"], ["83483.10", "0.005716"], ["83485.10", "0.015043"], ["83487.10", "0.039431"], ["83489.10", "0.103764"], ["83491.10", "0.273064"], ["83493.10", "0.718589"], ["83495.10", "1.891025"], ["83495.20", "0.088050"], ["83496.30", "0"], ["83496.70", "0.163230"], ["83497.40", "0"], ["83497.50", "0"], ["83499.10", "0"], ["83499.20", "0"], ["83501.10", "1.349640"], ["83501.80", "0"], ["83502.00", "0.927930"], ["83503.40", "1.086300"], ["83503.80", "0"], ["83505.50", "0.012630"], ["83505.80", "0"], ["83536.80", "4.382265"], ["83545.20", "4.108373"], ["83553.60", "5.295236"], ["83570.40", "5.386533"], ["83578.80", "4.290967"], ["83587.20", "5.660425"], ["83595.60", "3.925779"], ["83604.00", "4.199670"], ["83612.40", "4.656156"], ["83620.80", "5.569128"], ["83629.20", "4.838750"], ["83637.60", "4.017076"], ["83646.00", "5.112642"], ["83654.40", "5.477831"], ["83662.80", "4.473562"], ["83671.20", "5.021345"], ["83679.60", "4.564859"], ["83696.40", "5.203939"], ["83772.73", "0.000008"], ["83772.88", "0.000023"]], "bids": [["83445.00", "1.030717"], ["83438.87", "0"], ["83432.22", "0.170129"], ["83429.50", "0.001405"], ["83427.50", "0.003698"], ["83426.23", "0.020924"], ["83425.50", "0.009730"], ["83423.50", "0.025605"], ["83421.50", "0.067382"], ["83419.50", "0.177322"], ["83417.50", "0.466636"], ["83415.53", "0.006582"], ["83415.50", "1.227991"], ["83413.71", "0.018506"], ["83413.50", "3.231553"], ["83411.50", "8.504087"], ["83409.20", "0.212580"], ["83406.60", "2.015550"], ["83406.00", "0.000283"], ["83404.90", "0"], ["83403.20", "0.971640"], ["83402.60", "0.240000"], ["83399.47", "0"], ["83395.00", "0.000161"], ["83369.80", "4.382265"], ["83361.40", "4.199670"], ["83353.00", "5.386533"], ["83344.60", "4.747453"], ["83336.20", "4.930048"], ["83327.80", "5.112642"], ["83319.40", "4.473562"], ["83311.00", "5.295236"], ["83302.60", "4.108373"], ["83294.20", "5.203939"], ["83285.80", "4.838750"], ["83277.40", "3.925779"], ["83269.00", "4.290967"], ["83260.60", "4.017076"], ["83252.20", "5.021345"], ["83243.80", "5.569128"], ["83235.40", "5.477831"], ["83227.00", "4.564859"], ["83218.60", "4.656156"], ["83210.20", "5.660425"], ["82937.59", "0"], ["82937.50", "0"]], "checksum": 1595330302, "ts": "1742377420020"}], "ts": 1742377420024, "record_time": 1742377420.925787}
{"action": "update", "arg": {"instType": "SPOT", "channel": "books", "instId": "BTCUSDT"}, "data": [{"asks": [["83445.01", "1.011709"], ["83453.48", "0.051217"], ["83453.73", "0"], ["83459.90", "0.013824"], ["83462.14", "0.035952"], ["83462.56", "0.119843"], ["83463.80", "0"], ["83463.82", "0.035960"], ["83464.21", "0.006357"], ["83464.42", "0.006357"], ["83464.75", "0.006356"], ["83464.93", "0.006356"], ["83465.10", "0.006356"], ["83465.47", "0"], ["83465.73", "0.006356"], ["83465.81", "0.010994"], ["83465.87", "0"], ["83466.04", "0"], ["83466.07", "0.006357"], ["83466.21", "0.006357"], ["83466.37", "0"], ["83466.61", "0.006357"], ["83466.73", "0.016429"], ["83466.77", "0"], ["83466.90", "0"], ["83466.92", "0.006357"], ["83467.23", "0.006357"], ["83467.27", "0.006357"], ["83467.37", "0"], ["83467.44", "0.136314"], ["83467.45", "0"], ["83467.70", "0"], ["83467.73", "0.006357"], ["83467.77", "0.006357"], ["83467.87", "0"], ["83468.37", "0"], ["83468.45", "0"], ["83468.52", "0"], ["83468.74", "0.006357"], ["83468.87", "0"], ["83469.18", "0.010985"], ["83469.20", "0"], ["83469.25", "0"], ["83469.37", "0"], ["83469.39", "0"], ["83470.11", "0.009990"], ["83470.42", "0"], ["83470.86", "0.119908"], ["83470.87", "0"], ["83471.71", "0"], ["83471.86", "0.119881"], ["83472.28", "0.015896"], ["83472.44", "0.009989"], ["83472.62", "0"], ["83473.69", "0"], ["83474.12", "0"], ["83474.28", "0"], ["83474.45", "0.006357"], ["83476.26", "0"], ["83495.10", "1.891285"], ["83495.60", "0.303630"], ["83495.70", "0.463920"], ["83495.80", "0"], ["83495.90", "0"], ["83496.70", "0"], ["83497.09", "0"], ["83498.90", "0.014820"], ["83500.29", "0.456241"], ["83505.10", "0.774990"], ["83506.70", "0.958050"], ["83507.70", "0.035940"], ["83536.80", "5.386533"], ["83545.20", "5.569128"], ["83553.60", "5.660425"], ["83562.00", "3.925779"], ["83570.40", "4.656156"], ["83578.80", "4.199670"], ["83587.20", "4.017076"], ["83595.60", "5.112642"], ["83604.00", "4.108373"], ["83612.40", "5.295236"], ["83620.80", "4.930048"], ["83629.20", "4.747453"], ["83637.60", "4.290967"], ["83646.00", "4.473562"], ["83654.40", "5.203939"], ["83662.80", "4.838750"], ["83671.20", "5.477831"], ["83688.00", "5.021345"], ["83696.40", "4.382265"], ["83772.68", "0"], ["83772.73", "0"], ["83772.88", "0"]], "bids": [["83439.10", "0.045562"], ["83429.50", "0.001257"], ["83427.50", "0.003308"], ["83425.50", "0.008705"], ["83423.75", "0"], ["83423.50", "0.023111"], ["83423.33", "0"], ["83422.09", "0.090725"], ["83422.08", "0"], ["83421.71", "0"], ["83421.67", "0.247315"], ["83421.64", "0"], ["83421.50", "0.060817"], ["83421.48", "0"], ["83421.14", "0"], ["83420.88", "0"], ["83420.68", "0"], ["83420.61", "0.004096"], ["83420.43", "0.084523"], ["83420.14", "0"], ["83420.05", "0"], ["83419.98", "0.017987"], ["83419.86", "0.018412"], ["83419.81", "0"], ["83419.64", "0"], ["83419.53", "0.005985"], ["83419.50", "0.160044"], ["83419.22", "0"], ["83419.14", "0"], ["83419.04", "0.015873"], ["83418.95", "0"], ["83418.87", "0.016562"], ["83418.64", "0"], ["83418.50", "0.006619"], ["83418.42", "0.056234"], ["83418.35", "0"], ["83418.30", "0"], ["83418.17", "0.017216"], ["83418.15", "0"], ["83418.14", "0"], ["83417.98", "0.007191"], ["83417.50", "0.421168"], ["83417.38", "0.007380"], ["83417.36", "0.017196"], ["83417.18", "0"], ["83417.04", "0.007996"], ["83417.00", "0.009341"], ["83416.54", "0.261047"], ["83416.50", "0.017496"], ["83415.80", "0"], ["83415.50", "1.108339"], ["83414.88", "0"], ["83414.20", "0.018649"], ["83413.95", "0.022531"], ["83413.54", "0"], ["83413.50", "2.916681"], ["83413.36", "0"], ["83413.12", "0.270824"], ["83412.11", "0.223164"], ["83411.70", "0.076646"], ["83411.53", "0.021277"], ["83411.50", "7.675476"], ["83411.34", "0"], ["83411.10", "0.946530"], ["83410.90", "0.497580"], ["83409.53", "0.012531"], ["83394.00", "0.000283"], ["83382.10", "0.023562"], ["83361.40", "4.108373"], ["83353.00", "4.656156"], ["83344.60", "5.295236"], ["83336.20", "4.017076"], ["83327.80", "4.290967"], ["83319.40", "5.203939"], ["83311.00", "5.386533"], ["83302.60", "5.021345"], ["83294.20", "5.477831"], ["83285.80", "4.747453"], ["83277.40", "5.660425"], ["83269.00", "3.925779"], ["83260.60", "5.112642"], ["83252.20", "4.838750"], ["83243.80", "4.473562"], ["83235.40", "4.930048"], ["83218.60", "5.569128"], ["83210.20", "4.199670"], ["82937.59", "0.000423"]], "checksum": 275357714, "ts": "1742377420240"}], "ts": 1742377420244, "record_time": 1742377421.136387}
{"action": "update", "arg": {"instType": "SPOT", "channel": "books", "instId": "BTCUSDT"}, "data": [{"asks": [["83453.47", "0.015365"], ["83493.10", "0.718738"], ["83495.10", "1.891174"], ["83495.60", "0.303840"], ["83501.80", "0.102000"], ["83536.80", "4.838750"], ["83545.20", "5.112642"], ["83553.60", "4.290967"], ["83570.40", "4.108373"], ["83578.80", "5.295236"], ["83587.20", "4.382265"], ["83595.60", "4.473562"], ["83604.00", "4.017076"], ["83612.40", "5.477831"], ["83620.80", "4.199670"], ["83629.20", "4.930048"], ["83637.60", "5.569128"], ["83646.00", "5.021345"], ["83654.40", "5.386533"], ["83662.80", "5.203939"], ["83671.20", "5.660425"], ["83688.00", "4.656156"], ["83696.40", "4.747453"], ["83772.50", "0"], ["83772.56", "0"]], "bids": [["83423.50", "0.023094"], ["83421.50", "0.060774"], ["83419.51", "0.157937"], ["83419.50", "0.159933"], ["83417.50", "0.420876"], ["83415.50", "1.107568"], ["83413.50", "2.914652"], ["83411.50", "7.670138"], ["83369.80", "4.564859"], ["83361.40", "4.838750"], ["83353.00", "5.477831"], ["83344.60", "4.199670"], ["83327.80", "4.656156"], ["83319.40", "4.290967"], ["83311.00", "4.473562"], ["83302.60", "4.747453"], ["83294.20", "5.386533"], ["83285.80", "5.112642"], ["83277.40", "4.930048"], ["83269.00", "5.203939"], ["83260.60", "5.021345"], ["83252.20", "4.108373"], ["83243.80", "5.569128"], ["83235.40", "5.660425"], ["83227.00", "4.382265"], ["83218.60", "3.925779"], ["83210.20", "5.295236"]], "checksum": -901083671, "ts": "1742377420464"}], "ts": 1742377420468, "record_time": 1742377421.360034}
{"action": "update", "arg": {"instType": "SPOT", "channel": "books", "instId": "BTCUSDT"}, "data": [{"asks": [["83468.90", "0.420240"], ["83468.94", "0"], ["83500.29", "0"], ["83536.80", "5.112642"], ["83545.20", "4.017076"], ["83553.60", "4.199670"], ["83562.00", "5.021345"], ["83570.40", "5.569128"], ["83578.80", "4.290967"], ["83587.20", "4.838750"], ["83595.60", "4.564859"], ["83604.00", "4.747453"], ["83612.40", "5.660425"], ["83620.80", "5.477831"], ["83629.20", "4.656156"], ["83637.60", "4.473562"], ["83646.00", "4.382265"], ["83654.40", "4.108373"], ["83671.20", "4.930048"], ["83679.60", "3.925779"], ["83688.00", "5.295236"], ["83696.40", "5.386533"], ["83772.50", "0.000008"]], "bids": [["83445.00", "1.017691"], ["83439.32", "0.045562"], ["83439.10", "0"], ["83426.12", "0"], ["83418.60", "0.330639"], ["83393.00", "0.000122"], ["83369.80", "5.477831"], ["83361.40", "5.386533"], ["83353.00", "5.021345"], ["83344.60", "4.382265"], ["83336.20", "4.199670"], ["83327.80", "4.838750"], ["83319.40", "4.656156"], ["83311.00", "4.290967"], ["83302.60", "5.295236"], ["83294.20", "5.112642"], ["83285.80", "4.017076"], ["83277.40", "3.925779"], ["83269.00", "4.564859"], ["83260.60", "4.747453"], ["83252.20", "5.569128"], ["83243.80", "4.473562"], ["83235.40", "5.203939"], ["83227.00", "4.108373"], ["83218.60", "4.930048"], ["83210.20", "5.660425"], ["82937.59", "0"]], "checksum": -424046595, "ts": "1742377420667"}], "ts": 1742377420672, "record_time": 1742377421.561569}
