{"action": "snapshot", "arg": {"instType": "SPOT", "channel": "books", "instId": "BTCUSDT"}, "data": [{"asks": [["83873.01", "1.230984"], ["83873.02", "0.000100"], ["83873.03", "0.000100"], ["83873.04", "0.000100"], ["83875.48", "0.004300"], ["83876.50", "0.001048"], ["83876.93", "0.035953"], ["83877.44", "0.026942"], ["83878.50", "0.001278"], ["83879.78", "0.006357"], ["83879.88", "0.314866"], ["83880.00", "0.002000"], ["83880.04", "0.006357"], ["83880.05", "0.014703"], ["83880.50", "0.003474"], ["83880.55", "0.006357"], ["83880.72", "0.035972"], ["83880.79", "0.119869"], ["83880.88", "0.006357"], ["83881.24", "0.006357"], ["83881.54", "0.016429"], ["83882.39", "0.006357"], ["83882.43", "0.006356"], ["83882.48", "0.006357"], ["83882.50", "0.009143"], ["83882.59", "0.010995"], ["83882.71", "0.006357"], ["83883.06", "0.006357"], ["83883.13", "0.022786"], ["83883.39", "0.000701"], ["83883.69", "0.006357"], ["83884.05", "0.006357"], ["83884.50", "0.024060"], ["83884.78", "0.010994"], ["83885.38", "0.006357"], ["83885.51", "0.006357"], ["83885.61", "0.119883"], ["83885.84", "0.006357"], ["83886.05", "0.119850"], ["83886.50", "0.063316"], ["83886.59", "2.745911"], ["83886.82", "0.119858"], ["83888.22", "0.009990"], ["83888.50", "0.166621"], ["83890.27", "0.119867"], ["83890.50", "0.438475"], ["83890.60", "0.009989"], ["83890.79", "0.015895"], ["83892.19", "0.023107"], ["83892.28", "0.006356"], ["83892.50", "1.153883"], ["83893.26", "0.015892"], ["83894.07", "0.010988"], ["83894.50", "3.036533"], ["83895.14", "0.209200"], ["83896.50", "7.990876"], ["83897.06", "0.017174"], ["83897.10", "0.001002"], ["83898.00", "0.232200"], ["83898.20", "0.001047"], ["83899.90", "0.028350"], ["83900.00", "0.023837"], ["83900.40", "0.143310"], ["83900.70", "2.549970"], ["83900.80", "0.687900"], ["83901.40", "0.006060"], ["83902.20", "0.120000"], ["83902.30", "1.350000"], ["83902.70", "0.497550"], ["83903.60", "0.537480"], ["83904.24", "0.070700"], ["83905.01", "0.209200"], ["83905.90", "1.569750"], ["83906.40", "0.716850"], ["83906.80", "0.143100"], ["83907.11", "0.715076"], ["83908.10", "0.372000"], ["83909.10", "0.420000"], ["83909.30", "0.071520"], ["83909.90", "2.490240"], ["83910.00", "0.528000"], ["83910.50", "0.269760"], ["83911.30", "1.386000"], ["83912.00", "1.013130"], ["83912.20", "0.232650"], ["83912.50", "0.179010"], ["83913.10", "0.480000"], ["83913.20", "0.143100"], ["83913.40", "0.209200"], ["83917.43", "0.001598"], ["83919.74", "0.001597"], ["83923.01", "0.209200"], ["83923.70", "1.787337"], ["83938.16", "0.209200"], ["83938.50", "4.179573"], ["83940.00", "0.002000"], ["83946.55", "0.209200"], ["83946.90", "5.179036"], ["83955.30", "4.815595"], ["83957.40", "0.209200"], ["83960.61", "0.071253"], ["83960.72", "0.001810"], ["83963.70", "4.270433"], ["83966.41", "0.209200"], ["83970.00", "0.002000"], ["83970.06", "0.003620"], ["83970.60", "0.071045"], ["83972.10", "3.906992"], ["83974.80", "0.209200"], ["83976.76", "0.000508"], ["83980.50", "5.088176"], ["83983.13", "0.057001"], ["83987.87", "0.179631"], ["83988.90", "5.360757"], ["83996.26", "0.209200"], ["83997.30", "4.724735"], ["84000.00", "0.002392"], ["84005.70", "4.543014"], ["84009.01", "0.209200"], ["84010.13", "0.125950"], ["84014.10", "4.361294"], ["84016.00", "0.001184"], ["84017.40", "0.209200"], ["84022.50", "4.997315"], ["84025.99", "0.209200"], ["84030.00", "0.002000"], ["84030.07", "0.026416"], ["84030.90", "4.088713"], ["84034.37", "0.209200"], ["84039.30", "4.906455"], ["84047.70", "4.452154"], ["84051.13", "0.209200"], ["84056.10", "4.633874"], ["84056.13", "0.000041"], ["84059.51", "0.209200"], ["84060.00", "0.002000"], ["84064.50", "5.269896"], ["84072.90", "3.997852"], ["84074.10", "0.000958"], ["84075.80", "0.200966"], ["84076.27", "0.209200"], ["84081.30", "5.451617"], ["84084.50", "0.000022"], ["84084.66", "0.209200"], ["84086.72", "0.000146"], ["84089.70", "5.633337"], ["84090.00", "0.002000"], ["84093.05", "0.209200"], ["84095.53", "0.000013"], ["84095.63", "0.001720"], ["84098.10", "5.542477"], ["84100.00", "0.000656"], ["84101.44", "0.209200"], ["84107.68", "0.000022"], ["84112.50", "0.000076"], ["84115.44", "0.000153"], ["84116.94", "0.000028"], ["84120.00", "0.002011"], ["84121.21", "0.000010"], ["84121.93", "0.000069"], ["84125.00", "0.007104"], ["84126.22", "0.000053"], ["84126.55", "0.209200"], ["84127.27", "0.000010"], ["84140.96", "0.000013"], ["84142.86", "0.000081"], ["84146.34", "0.000016"], ["84150.00", "0.002031"], ["84151.72", "0.209200"], ["84155.83", "0.000019"], ["84160.00", "0.000025"], ["84160.11", "0.209200"], ["84161.91", "0.010000"], ["84162.50", "0.000031"], ["84163.92", "0.000010"], ["84166.67", "0.000362"], ["84169.49", "0.001213"], ["84170.00", "0.000107"], ["84174.51", "0.000388"], ["84174.61", "0.000043"], ["84176.89", "0.209200"], ["84180.00", "0.002000"], ["84180.09", "0.000033"], ["84181.81", "0.001547"], ["84183.50", "0.000113"], ["84185.28", "0.209200"], ["84188.46", "0.001182"], ["84190.00", "0.000052"], ["84191.18", "0.000041"], ["84192.98", "0.000033"], ["84194.12", "0.000071"], ["84195.65", "0.000046"], ["84196.77", "0.000020"], ["84197.27", "0.000016"], ["84199.87", "1.584735"], ["84200.00", "0.003412"], ["84203.00", "0.000008"], ["84205.79", "0.000011"], ["84205.88", "0.000071"], ["84206.90", "0.000008"], ["84208.00", "0.000012"], ["84210.00", "0.002000"], ["84212.00", "0.000012"], ["84212.50", "0.006969"], ["84214.29", "0.000033"], ["84214.88", "0.000161"], ["84216.22", "0.000008"], ["84216.67", "0.000970"], ["84216.87", "0.000008"], ["84222.03", "0.000013"], ["84222.22", "0.000898"], ["84223.65", "0.000178"], ["84224.14", "0.000016"], ["84224.62", "0.000022"], ["84225.88", "0.000024"], ["84226.42", "0.000096"], ["84230.00", "0.000023"], ["84230.76", "0.000008"], ["84230.77", "0.000103"], ["84233.16", "0.000023"], ["84233.33", "0.000090"], ["84233.34", "0.000119"], ["84233.38", "0.001273"], ["84233.87", "0.000039"], ["84234.04", "0.000137"], ["84234.07", "0.000039"], ["84234.23", "0.000051"], ["84235.22", "0.000099"], ["84235.23", "0.000051"], ["84235.29", "0.041940"], ["84235.71", "0.000074"], ["84238.10", "0.000024"], ["84238.89", "0.000134"], ["84239.13", "0.000010"], ["84240.00", "0.002472"], ["84242.60", "0.000537"], ["84246.15", "0.000015"], ["84250.00", "0.002629"], ["84252.44", "0.000143"], ["84254.39", "0.000022"], ["84254.55", "0.000009"], ["84256.00", "0.000022"], ["84256.79", "0.000314"], ["84259.12", "0.000009"], ["84259.87", "0.000093"], ["84259.99", "0.000017"], ["84260.00", "0.000012"], ["84266.08", "0.000016"], ["84266.67", "0.002899"], ["84267.78", "0.000010"], ["84269.24", "0.000032"], ["84270.00", "0.002000"], ["84270.27", "0.000009"], ["84270.98", "0.000052"], ["84271.10", "0.000019"], ["84272.72", "0.000105"], ["84272.73", "0.000016"], ["84273.33", "0.000013"], ["84275.00", "0.001542"], ["84276.28", "0.000009"], ["84277.78", "0.000011"], ["84280.00", "0.000364"], ["84280.70", "0.000033"], ["84281.56", "0.017891"], ["84282.35", "0.000071"], ["84282.39", "0.000135"], ["84282.61", "0.000046"], ["84282.82", "0.000012"], ["84283.33", "0.000010"], ["84283.87", "0.000020"], ["84285.00", "0.000031"], ["84285.71", "0.000080"], ["84285.95", "0.000028"], ["84286.67", "0.000009"], ["84286.79", "0.000016"], ["84287.50", "0.000076"], ["84288.89", "0.000361"], ["84289.58", "0.000008"], ["84292.40", "0.300132"], ["84294.12", "0.000071"], ["84294.68", "0.000019"], ["84297.06", "0.000035"], ["84298.31", "0.000023"], ["84300.00", "0.012243"], ["84301.47", "0.000041"], ["84302.88", "0.000067"], ["84307.00", "0.000113"], ["84307.23", "0.000008"], ["84309.09", "0.000010"], ["84310.34", "0.000331"], ["84310.35", "0.000146"], ["84311.11", "0.000025"], ["84312.50", "0.000125"], ["84313.03", "0.000024"], ["84315.00", "0.001428"], ["84316.67", "0.000322"], ["84317.24", "0.000135"], ["84317.40", "0.000010"], ["84318.59", "0.000027"], ["84319.15", "0.000137"], ["84319.18", "0.000039"], ["84320.00", "0.000019"], ["84321.70", "0.313004"], ["84322.11", "0.000008"], ["84324.32", "0.000059"], ["84324.70", "0.001469"], ["84325.00", "0.001624"], ["84325.07", "0.000161"], ["84326.09", "0.000010"], ["84326.42", "0.000023"], ["84327.14", "0.000039"], ["84327.73", "0.041940"], ["84328.40", "0.001403"], ["84328.95", "0.000174"], ["84329.64", "0.000026"], ["84330.00", "0.002000"], ["84332.00", "0.000008"], ["84333.33", "0.002262"], ["84333.36", "0.000010"], ["84333.38", "0.000008"], ["84334.48", "0.000096"], ["84334.77", "0.000022"], ["84336.00", "0.000133"], ["84336.23", "0.000013"], ["84336.29", "0.000010"], ["84336.34", "0.000176"], ["84337.25", "0.000067"], ["84337.35", "0.000008"], ["84338.46", "0.000015"], ["84339.21", "0.000010"], ["84339.29", "0.000029"], ["84339.62", "0.000051"], ["84340.00", "0.018045"], ["84340.72", "0.000066"], ["84341.01", "0.000008"], ["84342.11", "0.000051"], ["84342.63", "0.000009"], ["84342.70", "0.000423"], ["84343.07", "0.000014"], ["84343.70", "0.000075"], ["84343.75", "0.000012"], ["84343.97", "0.000188"], ["84344.00", "0.298916"], ["84346.43", "0.000128"], ["84346.94", "0.000085"], ["84347.69", "0.000009"], ["84347.83", "0.016818"], ["84348.21", "0.000036"], ["84348.27", "0.012402"], ["84348.62", "0.000072"], ["84350.00", "0.001583"], ["84350.79", "0.000033"], ["84354.58", "0.000115"], ["84354.64", "0.000018"], ["84354.82", "0.000078"], ["84354.84", "0.000194"], ["84357.14", "0.000273"], ["84358.29", "0.000024"], ["84359.83", "0.000010"], ["84360.00", "0.002661"], ["84363.63", "0.000057"], ["84363.64", "0.000078"], ["84366.14", "0.000162"], ["84366.15", "0.000061"], ["84366.19", "0.000022"], ["84366.60", "0.000011"], ["84366.96", "0.000018"], ["84367.10", "0.000014"], ["84367.82", "0.000476"], ["84368.38", "0.000009"], ["84368.42", "0.000284"], ["84369.57", "0.000046"], ["84370.00", "0.000052"], ["84370.59", "0.000071"], ["84370.97", "0.000020"], ["84371.86", "0.000012"], ["84375.00", "0.003336"], ["84376.31", "0.000016"], ["84378.11", "0.000008"], ["84378.38", "0.000009"], ["84378.45", "0.000015"], ["84380.00", "0.020277"], ["84381.82", "0.000008"], ["84382.00", "0.000035"], ["84382.35", "0.000071"], ["84383.41", "0.000053"], ["84383.69", "0.000248"], ["84384.38", "0.000424"], ["84384.61", "0.000008"], ["84386.19", "0.000019"], ["84386.67", "0.000013"], ["84387.50", "0.006969"], ["84387.76", "0.000024"], ["84389.61", "0.000088"], ["84390.00", "0.002000"], ["84390.01", "0.000387"], ["84391.30", "0.000018"], ["84393.31", "0.000050"], ["84396.55", "0.000016"], ["84396.98", "0.007500"], ["84397.59", "0.000008"], ["84397.69", "0.000275"], ["84398.26", "0.000068"], ["84399.54", "0.000030"], ["84399.91", "0.000018"], ["84399.99", "0.000022"], ["84400.00", "0.059194"], ["84400.18", "0.000024"], ["84402.40", "0.001273"], ["84403.39", "0.000023"], ["84403.76", "0.000099"], ["84403.98", "0.007500"], ["84404.26", "0.000137"], ["84404.28", "0.000039"], ["84406.83", "0.000064"], ["84407.50", "0.000031"], ["84410.00", "0.000059"], ["84410.04", "0.000025"], ["84411.11", "0.000361"], ["84411.43", "0.000008"], ["84411.76", "0.000101"], ["84411.77", "0.000020"], ["84412.50", "0.000049"], ["84413.04", "0.000010"], ["84413.33", "0.000073"], ["84413.79", "0.000135"], ["84414.29", "0.000074"], ["84414.41", "0.000051"], ["84415.09", "0.000008"], ["84416.67", "0.000355"], ["84418.34", "0.000046"], ["84419.69", "0.000023"], ["84420.00", "0.003442"], ["84420.17", "0.041940"], ["84422.71", "0.000010"], ["84423.08", "0.000067"], ["84423.53", "0.000105"], ["84424.00", "0.000022"], ["84424.12", "0.000146"], ["84425.00", "0.001535"], ["84425.69", "0.000314"], ["84426.68", "0.000101"], ["84427.08", "0.000014"], ["84427.92", "0.000323"], ["84428.57", "0.000057"], ["84429.82", "0.000022"], ["84430.50", "0.000113"], ["84430.74", "0.000010"], ["84430.77", "0.000015"], ["84431.23", "0.000039"], ["84432.43", "0.000008"], ["84433.33", "0.000347"], ["84434.78", "0.000008"], ["84435.26", "0.000161"], ["84436.26", "0.000009"], ["84437.14", "0.000017"], ["84437.50", "0.000725"], ["84437.75", "0.000013"], ["84438.44", "0.000176"], ["84440.00", "0.000008"], ["84442.54", "0.000096"], ["84443.07", "0.000423"], ["84444.25", "0.000013"], ["84444.41", "0.000371"], ["84444.44", "0.000574"], ["84444.92", "0.000022"], ["84446.04", "0.000016"], ["84446.38", "0.000013"], ["84446.43", "0.000036"], ["84447.80", "0.000718"], ["84448.75", "0.000066"], ["84448.98", "0.000085"], ["84449.11", "0.000028"], ["84449.34", "0.000010"], ["84450.00", "0.009386"], ["84451.88", "0.000010"], ["84452.66", "0.000009"], ["84453.76", "0.000054"], ["84454.43", "0.000061"], ["84454.53", "0.000019"], ["84454.55", "0.000083"], ["84454.60", "0.000093"], ["84455.31", "0.000028"], ["84456.14", "0.000033"], ["84456.52", "0.002679"], ["84457.00", "0.000009"], ["84458.06", "0.000020"], ["84458.72", "0.000072"], ["84458.82", "0.000071"], ["84458.97", "0.000153"], ["84459.08", "0.000008"], ["84459.22", "0.000188"], ["84459.69", "0.000051"], ["84460.00", "0.000086"], ["84460.23", "0.000010"], ["84460.49", "0.000009"], ["84460.87", "0.000069"], ["84460.91", "0.000012"], ["84461.00", "0.000008"], ["84462.50", "0.000076"]], "bids": [["83873.00", "0.001371"], ["83868.38", "0.013875"], ["83867.02", "0.037396"], ["83862.60", "0.114875"], ["83862.01", "0.000228"], ["83858.00", "0.000015"], ["83857.00", "0.000032"], ["83856.00", "0.000032"], ["83855.00", "0.000032"], ["83854.00", "0.000032"], ["83853.00", "0.000032"], ["83852.00", "0.000032"], ["83851.12", "0.007314"], ["83851.00", "0.000032"], ["83850.41", "0.007187"], ["83850.34", "0.008028"], ["83850.00", "0.193596"], ["83849.99", "0.209200"], ["83849.00", "0.000032"], ["83848.00", "0.000032"], ["83847.55", "0.001299"], ["83847.49", "0.002121"], ["83847.17", "0.314866"], ["83847.16", "0.055103"], ["83847.00", "0.000032"], ["83846.21", "0.010359"], ["83846.12", "0.008737"], ["83846.00", "0.000032"], ["83845.00", "0.000032"], ["83844.00", "0.000032"], ["83843.00", "0.000032"], ["83842.00", "0.000032"], ["83841.68", "0.002993"], ["83841.63", "0.008111"], ["83841.55", "0.001478"], ["83841.00", "0.000032"], ["83840.01", "0.014277"], ["83840.00", "0.089777"], ["83839.00", "0.000032"], ["83838.49", "0.209200"], ["83838.30", "0.248333"], ["83838.00", "0.000032"], ["83837.26", "0.005961"], ["83837.11", "0.084169"], ["83837.00", "0.000032"], ["83836.94", "0.015765"], ["83836.36", "0.055786"], ["83836.11", "0.017858"], ["83836.00", "0.000032"], ["83835.03", "0.007961"], ["83835.02", "0.006577"], ["83835.00", "0.018329"], ["83834.89", "0.017143"], ["83834.60", "0.225393"], ["83834.11", "0.004026"], ["83834.00", "0.000032"], ["83833.58", "0.016449"], ["83833.00", "0.000032"], ["83832.95", "0.007358"], ["83832.77", "0.007149"], ["83832.60", "0.001010"], ["83832.58", "0.017129"], ["83832.06", "0.028930"], ["83832.04", "0.018559"], ["83832.00", "0.000032"], ["83831.97", "0.025239"], ["83831.95", "0.008204"], ["83831.64", "0.017391"], ["83831.57", "0.009015"], ["83831.00", "0.000032"], ["83830.60", "0.001024"], ["83830.27", "0.052073"], ["83830.19", "0.008295"], ["83830.10", "0.209200"], ["83830.00", "0.000032"], ["83829.91", "0.076285"], ["83829.89", "0.260385"], ["83829.54", "0.012684"], ["83829.50", "0.000878"], ["83829.38", "0.021175"], ["83829.00", "0.000032"], ["83828.60", "0.001046"], ["83828.21", "0.010000"], ["83828.02", "0.268986"], ["83828.00", "0.000032"], ["83827.04", "0.012467"], ["83827.00", "0.000032"], ["83826.78", "0.223175"], ["83826.60", "0.001024"], ["83826.11", "0.013208"], ["83826.00", "0.000032"], ["83825.96", "0.007453"], ["83825.21", "0.715775"], ["83825.00", "0.000032"], ["83824.60", "0.001446"], ["83824.50", "0.073381"], ["83824.00", "0.000032"], ["83823.62", "0.056495"], ["83823.13", "0.008591"], ["83823.00", "0.000017"], ["83822.60", "0.003806"], ["83822.00", "0.000015"], ["83821.80", "0.003986"], ["83820.60", "0.010016"], ["83820.00", "0.002000"], ["83819.99", "0.205629"], ["83818.99", "0.007265"], ["83818.94", "0.015023"], ["83818.87", "0.017174"], ["83818.60", "0.026357"], ["83816.60", "0.069362"], ["83816.08", "0.000200"], ["83814.60", "0.182531"], ["83812.60", "0.480345"], ["83811.30", "0.001025"], ["83811.00", "0.006840"], ["83810.90", "0.001017"], ["83810.10", "0.001050"], ["83810.00", "0.228480"], ["83809.70", "0.601740"], ["83808.40", "0.068280"], ["83808.10", "0.038610"], ["83808.00", "0.031470"], ["83807.70", "0.009000"], ["83807.50", "3.187860"], ["83807.40", "0.038400"], ["83806.90", "0.022080"], ["83805.85", "0.001176"], ["83805.70", "0.070500"], ["83805.20", "0.483810"], ["83804.86", "0.209200"], ["83804.78", "0.003605"], ["83804.40", "0.015060"], ["83804.10", "1.006170"], ["83803.60", "0.143100"], ["83802.40", "0.036330"], ["83801.60", "0.145020"], ["83801.50", "0.325650"], ["83800.50", "2.686830"], ["83800.00", "0.000012"], ["83799.90", "2.317380"], ["83799.50", "2.685150"], ["83799.20", "1.910100"], ["83798.00", "0.000353"], ["83794.98", "0.209200"], ["83790.00", "0.002000"], ["83786.59", "0.209200"], ["83782.52", "0.101079"], ["83774.99", "0.209200"], ["83770.60", "4.543014"], ["83762.72", "0.001810"], ["83762.20", "5.633337"], ["83761.87", "0.209200"], ["83760.00", "0.002000"], ["83754.34", "0.003620"], ["83753.80", "4.997315"], ["83753.12", "0.057001"], ["83750.35", "0.125964"], ["83750.00", "0.209200"], ["83749.95", "0.000010"], ["83749.66", "0.000016"], ["83749.50", "0.000069"], ["83749.33", "0.000133"], ["83749.19", "0.000010"], ["83749.00", "0.000250"], ["83748.54", "0.000012"], ["83746.09", "0.000010"], ["83745.40", "4.906455"], ["83745.16", "0.000389"], ["83744.52", "0.000159"], ["83743.57", "0.071045"], ["83741.82", "0.071253"], ["83741.00", "0.100000"], ["83740.80", "0.209200"], ["83740.51", "0.000423"], ["83740.00", "0.000064"], ["83739.60", "0.000048"], ["83739.28", "0.000051"], ["83739.13", "0.000008"], ["83737.93", "0.000135"], ["83737.37", "0.000012"], ["83737.00", "3.997852"], ["83736.94", "0.000104"], ["83736.84", "0.000183"], ["83736.33", "0.000025"], ["83734.69", "0.000085"], ["83733.33", "0.003222"], ["83732.41", "0.209200"], ["83732.10", "0.000009"], ["83731.48", "0.000124"], ["83730.00", "0.002000"], ["83729.73", "0.000009"], ["83729.39", "0.000008"], ["83729.32", "0.000035"], ["83728.60", "4.452154"], ["83728.57", "0.000017"], ["83728.37", "0.001273"], ["83728.07", "0.000022"], ["83727.71", "0.000009"], ["83727.27", "0.000082"], ["83726.20", "0.000016"], ["83725.00", "0.001829"], ["83724.02", "0.209200"], ["83723.72", "0.000176"], ["83723.64", "0.000009"], ["83723.61", "0.000883"], ["83723.43", "0.000039"], ["83723.40", "0.000205"], ["83721.56", "0.000015"], ["83720.20", "4.815595"], ["83720.00", "0.002437"], ["83719.46", "0.000053"], ["83718.75", "0.000012"], ["83717.93", "0.000065"], ["83717.46", "0.000009"], ["83717.45", "0.000040"], ["83717.39", "0.000010"], ["83716.34", "0.000613"], ["83715.63", "0.209200"], ["83715.48", "0.000010"], ["83714.29", "0.009987"], ["83714.28", "0.000836"], ["83713.80", "0.000024"], ["83713.71", "0.000323"], ["83713.40", "0.000161"], ["83711.93", "0.000018"], ["83711.80", "5.179036"], ["83710.00", "0.000023"], ["83709.88", "0.000107"], ["83707.24", "0.209200"], ["83707.07", "0.000067"], ["83707.00", "0.000597"], ["83706.90", "0.000016"], ["83706.67", "0.000013"], ["83705.85", "0.000019"], ["83705.32", "0.000065"], ["83705.18", "0.000009"], ["83703.70", "0.000499"], ["83703.40", "4.270433"], ["83703.00", "0.000024"], ["83702.93", "0.000050"], ["83702.60", "0.000039"], ["83702.50", "0.000033"], ["83702.48", "0.000057"], ["83701.92", "0.000067"], ["83701.28", "0.000248"], ["83700.00", "0.008889"], ["83699.88", "0.000008"], ["83698.85", "0.209200"], ["83697.34", "0.000972"], ["83697.23", "0.000095"], ["83695.65", "0.003535"], ["83695.63", "0.000011"], ["83695.00", "5.269896"], ["83693.69", "0.000051"], ["83692.52", "0.000066"], ["83692.38", "0.000007"], ["83692.31", "0.000031"], ["83691.74", "0.000653"], ["83690.84", "0.000162"], ["83690.48", "0.000248"], ["83689.78", "0.001684"], ["83689.50", "0.000113"], ["83688.89", "0.000009"], ["83688.18", "0.001236"], ["83688.07", "0.000072"], ["83687.50", "0.006969"], ["83687.00", "0.000008"], ["83686.60", "4.088713"], ["83686.11", "0.000096"], ["83684.21", "0.000102"], ["83683.67", "0.000184"], ["83681.82", "0.000175"], ["83680.67", "0.041940"], ["83680.00", "0.000482"], ["83679.44", "0.000361"], ["83678.41", "0.000010"], ["83678.20", "5.451617"], ["83678.08", "0.000145"], ["83676.47", "0.000080"], ["83675.68", "0.000008"], ["83675.62", "0.000011"], ["83675.36", "0.000013"], ["83675.20", "0.000018"], ["83675.00", "0.001901"], ["83674.70", "0.000008"], ["83674.19", "0.000020"], ["83674.00", "0.001195"], ["83673.91", "0.000046"], ["83673.87", "0.000022"], ["83673.58", "0.000023"], ["83672.96", "0.002168"], ["83672.50", "0.000031"], ["83672.25", "0.004023"], ["83672.00", "0.000035"], ["83671.36", "0.000099"], ["83670.59", "0.000105"], ["83670.05", "0.000033"], ["83670.00", "0.003500"], ["83669.80", "5.088176"], ["83669.66", "0.000010"], ["83669.58", "0.000251"], ["83669.09", "0.000135"], ["83667.80", "0.000023"], ["83667.23", "0.012503"], ["83666.67", "0.001986"], ["83666.66", "0.000513"], ["83666.65", "0.000122"], ["83666.00", "0.270427"], ["83664.71", "0.000071"], ["83664.19", "0.000073"], ["83663.98", "0.000008"], ["83663.95", "0.000022"], ["83663.91", "0.000161"], ["83662.50", "0.000077"], ["83661.97", "0.000052"], ["83661.60", "0.000042"], ["83661.40", "4.724735"], ["83661.08", "0.004152"], ["83660.71", "0.000309"], ["83660.14", "0.000016"], ["83660.00", "0.000037"], ["83659.61", "0.000454"], ["83659.49", "0.000012"], ["83658.54", "0.000036"], ["83656.60", "0.000607"], ["83654.23", "0.000009"], ["83653.94", "0.000133"], ["83653.67", "0.001695"], ["83653.31", "0.000015"], ["83653.00", "4.179573"], ["83652.80", "0.000119"], ["83652.48", "0.000188"], ["83651.65", "0.000018"], ["83651.38", "0.000046"], ["83651.16", "0.000896"], ["83650.84", "0.003326"], ["83650.00", "0.031580"], ["83649.37", "0.001720"], ["83648.96", "0.000030"], ["83647.46", "0.000224"], ["83647.06", "0.000040"], ["83646.67", "0.000018"], ["83645.83", "0.000014"], ["83644.86", "0.000034"], ["83644.60", "5.542477"], ["83644.33", "0.000013"], ["83643.79", "0.026416"], ["83643.18", "0.000052"], ["83643.00", "1.020000"], ["83641.86", "0.000379"], ["83641.62", "0.002925"], ["83641.38", "0.000135"], ["83641.00", "0.000082"], ["83640.35", "0.000022"], ["83640.15", "0.000423"], ["83640.00", "0.000575"], ["83639.71", "0.000041"], ["83639.70", "0.000010"], ["83639.15", "0.000009"], ["83638.32", "0.000039"], ["83638.30", "0.000137"], ["83637.17", "0.000027"], ["83636.36", "0.000179"], ["83636.20", "5.360757"], ["83635.64", "0.000030"], ["83634.09", "0.000124"], ["83634.05", "0.000008"], ["83633.88", "0.000071"], ["83633.63", "0.000521"], ["83633.61", "0.000059"], ["83633.40", "0.000076"], ["83633.33", "0.000970"], ["83633.19", "0.007264"], ["83632.65", "0.000085"], ["83632.10", "0.000012"], ["83632.02", "0.000459"], ["83631.58", "0.000330"], ["83631.57", "0.000019"], ["83631.53", "0.000009"], ["83631.09", "0.002040"], ["83630.43", "0.000010"], ["83629.43", "0.000025"], ["83629.36", "0.000121"], ["83629.03", "0.000039"], ["83629.02", "0.000078"], ["83628.94", "0.000988"], ["83628.50", "0.000989"], ["83627.80", "3.906992"], ["83627.68", "0.000364"], ["83627.45", "0.000016"], ["83626.68", "0.000126"], ["83625.00", "0.002507"], ["83624.16", "0.000149"], ["83623.62", "0.000011"], ["83623.43", "0.000010"], ["83621.62", "0.000185"], ["83620.88", "0.000269"], ["83620.70", "0.000146"], ["83620.69", "0.000016"], ["83620.61", "0.000149"], ["83620.60", "0.001218"], ["83620.07", "0.000020"], ["83620.00", "0.000071"], ["83619.97", "0.000090"], ["83619.40", "4.633874"], ["83619.21", "0.000051"], ["83618.76", "0.000111"], ["83618.18", "0.000008"], ["83617.80", "0.000948"], ["83617.02", "0.000032"], ["83616.67", "0.000345"], ["83615.85", "0.000024"], ["83614.97", "0.000008"], ["83614.90", "0.000040"], ["83613.60", "0.000010"], ["83612.01", "0.000009"], ["83611.93", "0.000028"], ["83611.54", "0.000018"], ["83611.00", "4.361294"], ["83610.22", "0.000012"], ["83610.00", "0.001150"], ["83607.60", "0.000014"], ["83606.42", "0.000525"], ["83605.99", "0.000012"], ["83605.66", "0.000276"], ["83603.60", "0.000051"], ["83603.26", "0.000010"], ["83602.67", "0.000133"], ["83601.85", "0.005980"], ["83601.40", "0.000019"], ["83600.36", "0.000209"], ["83600.01", "0.000086"], ["83600.00", "0.047709"], ["83599.92", "0.000080"], ["83599.69", "0.001041"], ["83598.80", "0.005980"], ["83598.51", "0.000039"], ["83598.44", "0.000052"], ["83597.99", "0.000065"], ["83597.89", "0.000036"], ["83597.77", "0.000013"], ["83597.71", "0.006133"], ["83594.92", "0.000755"], ["83594.44", "0.000134"], ["83593.75", "0.000173"], ["83593.39", "0.000014"], ["83593.33", "0.000013"], ["83590.91", "0.000009"], ["83589.25", "0.000054"], ["83589.05", "0.000069"], ["83589.00", "0.000024"], ["83588.42", "0.000172"], ["83588.24", "0.042011"], ["83588.15", "0.000294"], ["83587.87", "0.000050"], ["83587.50", "0.000076"], ["83587.10", "0.000020"], ["83586.96", "0.002679"], ["83586.51", "0.000096"], ["83586.00", "0.000386"], ["83585.60", "0.000042"], ["83584.53", "0.000314"], ["83584.49", "0.000066"], ["83584.37", "0.000290"], ["83584.34", "0.000008"], ["83584.18", "0.000338"], ["83584.00", "0.000022"], ["83583.85", "0.000052"], ["83583.33", "0.000010"], ["83582.09", "0.000008"], ["83581.82", "0.000010"], ["83581.73", "0.000067"], ["83581.38", "0.000059"], ["83580.56", "0.000019"], ["83580.31", "0.000023"], ["83580.00", "0.000294"], ["83578.95", "0.000033"], ["83578.11", "0.000023"], ["83578.04", "0.000096"], ["83577.98", "0.000072"], ["83577.78", "0.000025"], ["83577.76", "0.000483"], ["83577.73", "0.000200"], ["83577.41", "0.000034"], ["83576.47", "0.000071"], ["83575.00", "0.001544"], ["83574.19", "0.000109"], ["83571.79", "0.000098"], ["83571.43", "0.000330"], ["83571.42", "0.000008"], ["83571.39", "0.000178"], ["83570.62", "0.000016"], ["83570.45", "0.000012"], ["83570.00", "0.000059"], ["83569.08", "0.000093"], ["83568.75", "0.000025"], ["83568.28", "0.000010"], ["83568.00", "0.000050"], ["83567.59", "0.000047"]], "checksum": 0, "ts": "1742543252790"}], "ts": 1742543252952, "record_time": 1742543252.976917}
{"action": "update", "arg": {"instType": "SPOT", "channel": "books", "instId": "BTCUSDT"}, "data": [{"asks": [["83873.01", "1.165250"], ["83873.02", "0.000355"], ["83876.92", "0.019252"], ["83878.50", "0.001468"], ["83879.87", "0.179941"], ["83880.05", "0"], ["83880.50", "0.003862"], ["83882.50", "0.010162"], ["83884.50", "0.026744"], ["83886.50", "0.070377"], ["83888.50", "0.185205"], ["83890.50", "0.487380"], ["83892.50", "1.282580"], ["83894.50", "3.375211"], ["83896.50", "8.882132"], ["83899.90", "0.028560"], ["83900.40", "0.143100"], ["83900.80", "0.702900"], ["83906.40", "0.667680"], ["83909.90", "3.845040"], ["83912.90", "4.065480"], ["83913.20", "0"], ["83938.50", "5.542477"], ["83946.90", "5.269896"], ["83955.30", "3.997852"], ["83963.70", "4.815595"], ["83972.10", "4.997315"], ["83980.50", "4.088713"], ["83988.90", "5.179036"], ["83997.30", "4.633874"], ["84005.70", "5.088176"], ["84014.10", "3.906992"], ["84022.50", "4.724735"], ["84030.90", "4.543014"], ["84031.72", "0.161739"], ["84039.30", "5.633337"], ["84047.70", "4.361294"], ["84056.10", "4.906455"], ["84064.50", "4.179573"], ["84072.90", "4.270433"], ["84081.30", "4.452154"], ["84089.70", "5.451617"], ["84098.10", "5.360757"], ["84461.00", "0"], ["84462.50", "0"]], "bids": [["83862.60", "0"], ["83826.60", "0.001007"], ["83824.60", "0.001429"], ["83822.60", "0.003760"], ["83822.00", "0.000032"], ["83820.60", "0.009895"], ["83818.60", "0.026040"], ["83816.60", "0.068527"], ["83814.60", "0.180333"], ["83812.60", "0.474560"], ["83810.00", "0"], ["83809.80", "0.202350"], ["83807.50", "3.188070"], ["83801.50", "0"], ["83770.60", "4.815595"], ["83762.20", "4.088713"], ["83753.80", "5.633337"], ["83745.40", "5.542477"], ["83737.00", "4.361294"], ["83720.20", "4.270433"], ["83711.80", "4.633874"], ["83703.40", "5.360757"], ["83695.00", "5.451617"], ["83686.60", "3.906992"], ["83678.20", "5.088176"], ["83669.80", "4.724735"], ["83661.40", "4.906455"], ["83653.00", "4.543014"], ["83644.60", "4.997315"], ["83636.20", "3.997852"], ["83627.80", "4.179573"], ["83619.40", "5.179036"], ["83611.00", "5.269896"], ["83567.57", "0.000008"], ["83567.40", "0.000046"]], "checksum": 1535645947, "ts": "1742543252992"}], "ts": 1742543252998, "record_time": 1742543252.979189}
{"action": "update", "arg": {"instType": "SPOT", "channel": "books", "instId": "BTCUSDT"}, "data": [{"asks": [["83873.01", "0.973939"], ["83877.44", "0"], ["83878.50", "0.001318"], ["83880.50", "0.003467"], ["83881.57", "0.028238"], ["83882.50", "0.009125"], ["83884.50", "0.024012"], ["83886.10", "0.026942"], ["83886.50", "0.063190"], ["83886.58", "0.211703"], ["83888.50", "0.166290"], ["83890.50", "0.437605"], ["83892.50", "1.151592"], ["83894.50", "3.030504"], ["83896.50", "7.975010"], ["83898.00", "0.052110"], ["83900.80", "0.376800"], ["83901.50", "0.145020"], ["83902.30", "0"], ["83909.90", "2.239740"], ["83910.50", "0"], ["83912.90", "0"], ["83913.20", "0.143100"], ["83913.40", "0.537480"], ["83914.10", "0.540000"], ["83914.20", "0.480000"], ["83938.50", "3.997852"], ["83955.30", "5.088176"], ["83963.70", "5.451617"], ["83972.10", "4.361294"], ["83980.50", "5.542477"], ["83988.90", "4.633874"], ["83997.30", "4.815595"], ["84005.70", "4.997315"], ["84014.10", "4.270433"], ["84022.50", "4.906455"], ["84030.90", "4.179573"], ["84039.30", "4.724735"], ["84047.70", "5.633337"], ["84056.10", "3.906992"], ["84064.50", "5.360757"], ["84072.90", "5.179036"], ["84081.30", "4.088713"], ["84089.70", "4.452154"], ["84098.10", "4.543014"], ["84460.49", "0"], ["84460.87", "0"], ["84460.91", "0"]], "bids": [["83873.00", "0.328581"], ["83862.09", "1.534643"], ["83860.50", "0.114962"], ["83857.94", "0.044428"], ["83855.06", "0.055103"], ["83847.16", "0"], ["83834.22", "3.578959"], ["83828.60", "0.001341"], ["83826.60", "0.003530"], ["83824.60", "0.009288"], ["83822.60", "0.024444"], ["83820.60", "0.064326"], ["83818.60", "0.169279"], ["83816.60", "0.445471"], ["83814.60", "1.172292"], ["83812.60", "3.084977"], ["83812.40", "0.103740"], ["83810.10", "0"], ["83810.00", "3.562080"], ["83809.80", "0"], ["83809.70", "0.601530"], ["83808.40", "0.068070"], ["83808.10", "0.076830"], ["83808.00", "0.116070"], ["83807.50", "0.825150"], ["83807.40", "0.001178"], ["83805.00", "0.145020"], ["83804.87", "0.711921"], ["83804.20", "1.350000"], ["83801.60", "0"], ["83799.70", "0.325830"], ["83770.60", "5.088176"], ["83762.20", "4.361294"], ["83753.80", "4.815595"], ["83745.40", "4.452154"], ["83737.00", "3.997852"], ["83728.60", "3.906992"], ["83720.20", "4.906455"], ["83711.80", "5.269896"], ["83703.40", "4.724735"], ["83695.00", "4.179573"], ["83686.60", "4.543014"], ["83678.20", "4.633874"], ["83669.80", "4.270433"], ["83661.40", "5.179036"], ["83653.00", "5.451617"], ["83636.20", "4.088713"], ["83627.80", "5.633337"], ["83619.40", "5.542477"], ["83611.00", "5.360757"], ["83569.08", "0"], ["83568.75", "0"], ["83568.28", "0"], ["83568.00", "0"], ["83567.59", "0"], ["83567.57", "0"], ["83567.40", "0"]], "checksum": -932169505, "ts": "1742543253194"}], "ts": 1742543253196, "record_time": 1742543253.189971}
{"action": "update", "arg": {"instType": "SPOT", "channel": "books", "instId": "BTCUSDT"}, "data": [{"asks": [["83873.01", "1.153129"], ["83876.92", "0.011181"], ["83884.50", "0.024163"], ["83886.50", "0.063588"], ["83888.50", "0.167337"], ["83890.50", "0.440361"], ["83892.50", "1.158843"], ["83894.50", "3.049588"], ["83896.50", "8.025230"], ["83900.10", "0.022710"], ["83906.30", "0.006810"], ["83912.00", "1.006320"], ["83913.40", "0.209200"], ["83914.10", "0"], ["83914.20", "0"], ["83938.50", "5.542477"], ["83946.90", "4.088713"], ["83963.70", "4.543014"], ["83972.10", "4.724735"], ["83980.50", "4.633874"], ["83988.90", "4.270433"], ["83997.30", "4.997315"], ["84005.70", "4.452154"], ["84014.10", "5.179036"], ["84022.50", "5.451617"], ["84030.90", "4.815595"], ["84039.30", "5.269896"], ["84047.70", "4.906455"], ["84056.10", "3.997852"], ["84064.50", "3.906992"], ["84072.90", "5.360757"], ["84081.30", "4.179573"], ["84089.70", "4.361294"], ["84098.10", "5.633337"]], "bids": [["83873.00", "0.001371"], ["83862.10", "0.494950"], ["83828.60", "0.001031"], ["83826.60", "0.002435"], ["83824.60", "0.006406"], ["83822.60", "0.017036"], ["83820.60", "0.044833"], ["83818.60", "0.117982"], ["83816.60", "0.310477"], ["83814.60", "0.817047"], ["83812.60", "2.150253"], ["83807.50", "0.221100"], ["83804.20", "0"], ["83770.60", "4.724735"], ["83762.20", "4.088713"], ["83753.80", "5.179036"], ["83745.40", "5.088176"], ["83737.00", "4.452154"], ["83728.60", "4.361294"], ["83720.20", "4.543014"], ["83711.80", "5.451617"], ["83703.40", "4.997315"], ["83695.00", "5.633337"], ["83686.60", "4.815595"], ["83678.20", "3.906992"], ["83669.80", "5.269896"], ["83661.40", "4.179573"], ["83653.00", "4.633874"], ["83644.60", "5.360757"], ["83636.20", "3.997852"], ["83627.80", "5.542477"], ["83619.40", "4.270433"], ["83611.00", "4.906455"]], "checksum": -116398084, "ts": "1742543253420"}], "ts": 1742543253422, "record_time": 1742543253.395834}
{"action": "update", "arg": {"instType": "SPOT", "channel": "books", "instId": "BTCUSDT"}, "data": [{"asks": [["83886.58", "0.219774"], ["83890.50", "0.440162"], ["83892.50", "1.158319"], ["83894.50", "3.048210"], ["83896.50", "8.021492"], ["83911.30", "1.562760"], ["83913.20", "0"], ["83938.50", "5.633337"], ["83946.90", "4.543014"], ["83955.30", "5.360757"], ["83963.70", "4.997315"], ["83972.10", "4.088713"], ["83980.50", "5.088176"], ["83988.90", "4.633874"], ["83997.30", "4.906455"], ["84005.70", "4.179573"], ["84014.10", "4.270433"], ["84022.50", "5.542477"], ["84030.90", "5.179036"], ["84039.30", "4.452154"], ["84047.70", "5.269896"], ["84056.10", "4.724735"], ["84064.50", "4.361294"], ["84072.90", "5.451617"], ["84081.30", "3.997852"], ["84089.70", "4.815595"], ["84098.10", "3.906992"], ["84460.49", "0.000009"]], "bids": [["83862.10", "0"], ["83858.54", "0.044428"], ["83857.94", "0"], ["83855.46", "0.055103"], ["83855.06", "0"], ["83821.00", "0.000015"], ["83805.70", "0"], ["83798.80", "0.465690"], ["83770.60", "5.360757"], ["83762.20", "3.997852"], ["83753.80", "4.997315"], ["83745.40", "4.179573"], ["83737.00", "4.906455"], ["83720.20", "5.633337"], ["83711.80", "4.815595"], ["83703.40", "5.179036"], ["83695.00", "5.451617"], ["83686.60", "4.543014"], ["83678.20", "4.633874"], ["83669.80", "5.542477"], ["83661.40", "4.452154"], ["83653.00", "5.088176"], ["83644.60", "4.270433"], ["83636.20", "3.906992"], ["83627.80", "4.088713"], ["83619.40", "4.724735"], ["83611.00", "5.269896"]], "checksum": 1656594267, "ts": "1742543253624"}], "ts": 1742543253627, "record_time": 1742543253.600498}
{"action": "update", "arg": {"instType": "SPOT", "channel": "books", "instId": "BTCUSDT"}, "data": [{"asks": [["83873.01", "0.942579"], ["83873.02", "0.000100"], ["83902.20", "0"], ["83904.90", "0.009000"], ["83909.50", "0.026940"], ["83909.90", "2.490240"], ["83912.50", "0"], ["83913.10", "0"], ["83938.50", "4.997315"], ["83946.90", "4.361294"], ["83955.30", "4.179573"], ["83963.70", "5.179036"], ["83972.10", "3.906992"], ["83980.50", "4.633874"], ["83988.90", "5.269896"], ["83997.30", "5.088176"], ["84005.70", "4.724735"], ["84014.10", "5.360757"], ["84030.90", "5.633337"], ["84039.30", "4.088713"], ["84047.70", "4.270433"], ["84056.10", "4.906455"], ["84064.50", "4.815595"], ["84072.90", "3.997852"], ["84081.30", "5.451617"], ["84089.70", "4.543014"], ["84098.10", "4.452154"], ["84460.87", "0.000069"]], "bids": [["83823.00", "0"], ["83822.60", "0.016601"], ["83820.60", "0.043688"], ["83818.60", "0.114968"], ["83816.60", "0.302546"], ["83814.60", "0.796175"], ["83812.60", "2.095197"], ["83810.00", "3.358500"], ["83770.60", "4.452154"], ["83762.20", "5.451617"], ["83753.80", "5.360757"], ["83745.40", "4.724735"], ["83737.00", "4.633874"], ["83728.60", "5.269896"], ["83720.20", "5.179036"], ["83711.80", "4.179573"], ["83703.40", "4.361294"], ["83695.00", "4.997315"], ["83686.60", "4.815595"], ["83678.20", "4.088713"], ["83669.80", "4.543014"], ["83661.40", "5.542477"], ["83653.00", "5.633337"], ["83648.00", "0.001184"], ["83644.60", "3.997852"], ["83627.80", "4.270433"], ["83619.40", "4.906455"], ["83611.00", "5.088176"]], "checksum": -824683757, "ts": "1742543253825"}], "ts": 1742543253829, "record_time": 1742543253.802258}
{"action": "update", "arg": {"instType": "SPOT", "channel": "books", "instId": "BTCUSDT"}, "data": [{"asks": [["83873.01", "1.269789"], ["83892.50", "1.158215"], ["83894.50", "3.047934"], ["83896.50", "8.020878"], ["83907.40", "0.015000"], ["83938.50", "5.451617"], ["83955.30", "5.179036"], ["83963.70", "5.633337"], ["83972.10", "4.270433"], ["83980.50", "5.088176"], ["83988.90", "4.997315"], ["83997.30", "4.633874"], ["84014.10", "4.906455"], ["84022.50", "5.360757"], ["84030.90", "4.088713"], ["84039.30", "3.997852"], ["84047.70", "3.906992"], ["84056.10", "4.179573"], ["84064.50", "5.269896"], ["84072.90", "4.452154"], ["84081.30", "5.542477"], ["84098.10", "4.815595"], ["84460.87", "0"]], "bids": [["83860.50", "0"], ["83826.60", "0.001846"], ["83824.60", "0.004860"], ["83822.60", "0.012788"], ["83820.60", "0.033652"], ["83818.60", "0.088558"], ["83816.60", "0.233047"], ["83814.60", "0.613284"], ["83812.60", "1.613903"], ["83799.70", "0"], ["83798.70", "0.009870"], ["83770.60", "3.906992"], ["83762.20", "3.997852"], ["83753.80", "5.088176"], ["83745.40", "4.088713"], ["83737.00", "5.542477"], ["83728.60", "4.997315"], ["83720.20", "4.452154"], ["83703.40", "4.815595"], ["83695.00", "5.451617"], ["83686.60", "5.633337"], ["83678.20", "5.269896"], ["83669.80", "4.633874"], ["83661.40", "5.360757"], ["83653.00", "4.724735"], ["83644.60", "4.543014"], ["83636.20", "4.270433"], ["83627.80", "5.179036"], ["83611.00", "4.361294"], ["83569.08", "0.000093"]], "checksum": 1567739371, "ts": "1742543254027"}], "ts": 1742543254031, "record_time": 1742543254.0061}
{"action": "update", "arg": {"instType": "SPOT", "channel": "books", "instId": "BTCUSDT"}, "data": [{"asks": [["83873.01", "1.060718"], ["83910.60", "0.326580"], ["83912.20", "0.214770"], ["83938.50", "5.179036"], ["83946.90", "4.906455"], ["83955.30", "4.543014"], ["83963.70", "4.724735"], ["83972.10", "5.542477"], ["83980.50", "4.815595"], ["83988.90", "5.269896"], ["83997.30", "3.906992"], ["84005.70", "4.997315"], ["84014.10", "4.633874"], ["84022.50", "4.361294"], ["84030.90", "5.088176"], ["84039.30", "5.451617"], ["84047.70", "4.270433"], ["84064.50", "5.360757"], ["84072.90", "5.633337"], ["84081.30", "4.088713"], ["84089.70", "4.452154"], ["84098.10", "3.997852"], ["84460.49", "0"]], "bids": [["83859.69", "0.115278"], ["83859.04", "0.044428"], ["83858.54", "0"], ["83821.00", "0.000032"], ["83816.60", "0.232938"], ["83814.60", "0.612993"], ["83812.60", "1.613141"], ["83812.40", "0.001031"], ["83809.70", "0.601740"], ["83808.50", "0.077130"], ["83808.00", "0.116400"], ["83799.00", "0.326580"], ["83798.80", "0"], ["83798.70", "0"], ["83770.60", "5.633337"], ["83762.20", "5.269896"], ["83753.80", "4.270433"], ["83745.40", "5.179036"], ["83737.00", "5.451617"], ["83728.60", "4.088713"], ["83720.20", "5.088176"], ["83711.80", "4.997315"], ["83703.40", "3.997852"], ["83695.00", "4.452154"], ["83686.60", "5.542477"], ["83678.20", "4.179573"], ["83669.80", "4.815595"], ["83644.60", "4.361294"], ["83636.20", "3.906992"], ["83627.80", "4.633874"], ["83611.00", "4.543014"], ["83569.08", "0"]], "checksum": 1397240718, "ts": "1742543254230"}], "ts": 1742543254232, "record_time": 1742543254.255576}
{"action": "update", "arg": {"instType": "SPOT", "channel": "books", "instId": "BTCUSDT"}, "data": [{"asks": [["83884.50", "0.024269"], ["83886.50", "0.063865"], ["83888.50", "0.168066"], ["83890.50", "0.442036"], ["83892.50", "1.163253"], ["83894.50", "3.061193"], ["83896.50", "8.055772"], ["83938.50", "4.906455"], ["83946.90", "3.906992"], ["83955.30", "5.542477"], ["83963.70", "5.633337"], ["83972.10", "3.997852"], ["83980.50", "4.270433"], ["83988.90", "4.633874"], ["83997.30", "4.088713"], ["84005.70", "4.452154"], ["84014.10", "5.360757"], ["84022.50", "5.451617"], ["84030.90", "4.543014"], ["84039.30", "4.724735"], ["84047.70", "5.269896"], ["84056.10", "5.088176"], ["84064.50", "4.361294"], ["84072.90", "4.179573"], ["84081.30", "4.815595"], ["84089.70", "4.997315"], ["84098.10", "5.179036"]], "bids": [["83873.00", "0.328581"], ["83828.21", "0"], ["83822.00", "0.000017"], ["83814.60", "0.612753"], ["83812.60", "1.612508"], ["83770.60", "4.543014"], ["83762.20", "5.451617"], ["83753.80", "5.542477"], ["83745.40", "3.997852"], ["83737.00", "4.361294"], ["83728.60", "4.633874"], ["83720.20", "4.815595"], ["83711.80", "4.270433"], ["83703.40", "4.997315"], ["83695.00", "4.088713"], ["83686.60", "4.179573"], ["83678.20", "5.360757"], ["83669.80", "5.179036"], ["83661.40", "5.269896"], ["83653.00", "5.088176"], ["83644.60", "5.633337"], ["83636.20", "4.906455"], ["83627.80", "4.452154"], ["83619.40", "3.906992"], ["83611.00", "4.724735"], ["83569.08", "0.000093"]], "checksum": 1571233619, "ts": "1742543254429"}], "ts": 1742543254432, "record_time": 1742543254.417584}
{"action": "update", "arg": {"instType": "SPOT", "channel": "books", "instId": "BTCUSDT"}, "data": [{"asks": [["83873.01", "1.282729"], ["83888.50", "0.167894"], ["83890.50", "0.441825"], ["83892.50", "1.162698"], ["83894.50", "3.059730"], ["83896.50", "8.051921"], ["83898.20", "0.028350"], ["83899.90", "0.001020"], ["83938.50", "4.543014"], ["83946.90", "4.633874"], ["83955.30", "4.361294"], ["83963.70", "4.997315"], ["83972.10", "5.088176"], ["83980.50", "5.633337"], ["83988.90", "4.179573"], ["83997.30", "5.269896"], ["84005.70", "3.906992"], ["84014.10", "4.815595"], ["84022.50", "5.360757"], ["84030.90", "4.724735"], ["84039.30", "4.270433"], ["84047.70", "4.906455"], ["84056.10", "5.451617"], ["84064.50", "5.179036"], ["84072.90", "5.542477"], ["84081.30", "3.997852"], ["84089.70", "4.452154"], ["84098.10", "4.088713"]], "bids": [["83862.10", "0.508373"], ["83859.52", "0.044427"], ["83859.04", "0"], ["83770.60", "5.360757"], ["83762.20", "5.179036"], ["83753.80", "4.997315"], ["83745.40", "4.088713"], ["83728.60", "5.451617"], ["83720.20", "5.269896"], ["83703.40", "3.997852"], ["83695.00", "4.179573"], ["83686.60", "4.633874"], ["83678.20", "5.088176"], ["83669.80", "4.543014"], ["83661.40", "4.724735"], ["83653.00", "4.452154"], ["83644.60", "3.906992"], ["83636.20", "4.815595"], ["83627.80", "4.906455"], ["83619.40", "5.633337"], ["83611.00", "5.542477"], ["83569.08", "0"]], "checksum": -847510922, "ts": "1742543254651"}], "ts": 1742543254655, "record_time": 1742543254.628137}
{"action": "update", "arg": {"instType": "SPOT", "channel": "books", "instId": "BTCUSDT"}, "data": [{"asks": [["83911.30", "1.386000"], ["83912.20", "0.232650"], ["83938.50", "5.542477"], ["83946.90", "4.543014"], ["83955.30", "4.633874"], ["83963.70", "3.906992"], ["83972.10", "5.633337"], ["83980.50", "4.815595"], ["83988.90", "4.270433"], ["83997.30", "5.451617"], ["84005.70", "4.361294"], ["84014.10", "5.088176"], ["84022.50", "4.088713"], ["84039.30", "4.452154"], ["84047.70", "5.360757"], ["84056.10", "5.269896"], ["84072.90", "3.997852"], ["84081.30", "4.997315"], ["84089.70", "4.906455"], ["84098.10", "4.179573"], ["84189.98", "1.693841"], ["84199.87", "0"]], "bids": [["83855.47", "0.016541"], ["83816.60", "0.232825"], ["83812.60", "1.612360"], ["83770.60", "4.906455"], ["83762.20", "4.088713"], ["83753.80", "4.361294"], ["83745.40", "5.269896"], ["83737.00", "5.451617"], ["83728.60", "4.452154"], ["83720.20", "4.179573"], ["83703.40", "5.088176"], ["83695.00", "4.815595"], ["83686.60", "5.542477"], ["83678.20", "3.997852"], ["83669.80", "4.724735"], ["83661.40", "5.179036"], ["83653.00", "5.360757"], ["83644.60", "4.997315"], ["83636.20", "5.633337"], ["83627.80", "4.633874"], ["83619.40", "3.906992"], ["83611.00", "4.543014"], ["83570.00", "0"]], "checksum": -2109673195, "ts": "1742543254856"}], "ts": 1742543254859, "record_time": 1742543254.844235}
{"action": "update", "arg": {"instType": "SPOT", "channel": "books", "instId": "BTCUSDT"}, "data": [{"asks": [["83873.02", "0.000310"], ["83882.50", "0.009283"], ["83884.50", "0.024428"], ["83886.50", "0.064284"], ["83888.50", "0.169168"], ["83890.50", "0.445180"], ["83892.50", "1.171526"], ["83894.50", "3.082962"], ["83896.50", "8.113060"], ["83900.80", "0.361800"], ["83938.50", "5.088176"], ["83946.90", "4.452154"], ["83955.30", "5.633337"], ["83963.70", "5.269896"], ["83972.10", "4.815595"], ["83980.50", "4.543014"], ["83988.90", "5.542477"], ["83997.30", "4.179573"], ["84005.70", "5.360757"], ["84014.10", "4.633874"], ["84022.50", "4.361294"], ["84030.90", "4.088713"], ["84039.30", "3.997852"], ["84047.70", "3.906992"], ["84056.10", "5.179036"], ["84064.50", "4.724735"], ["84072.90", "4.997315"], ["84081.30", "5.451617"], ["84089.70", "4.270433"], ["84098.10", "4.906455"]], "bids": [["83873.00", "0.001371"], ["83862.10", "0"], ["83851.13", "0.006768"], ["83823.00", "0.000015"], ["83822.00", "0"], ["83805.90", "0.015000"], ["83770.60", "5.269896"], ["83762.20", "5.451617"], ["83753.80", "3.906992"], ["83745.40", "5.179036"], ["83737.00", "4.633874"], ["83728.60", "4.997315"], ["83720.20", "4.543014"], ["83711.80", "4.724735"], ["83703.40", "4.361294"], ["83695.00", "5.088176"], ["83686.60", "5.633337"], ["83678.20", "5.542477"], ["83669.80", "4.906455"], ["83661.40", "4.452154"], ["83653.00", "4.815595"], ["83644.60", "4.088713"], ["83636.20", "4.270433"], ["83627.80", "4.179573"], ["83619.40", "3.997852"], ["83611.00", "5.360757"], ["83570.45", "0"]], "checksum": -2129641768, "ts": "1742543255057"}], "ts": 1742543255061, "record_time": 1742543255.035778}
{"action": "update", "arg": {"instType": "SPOT", "channel": "books", "instId": "BTCUSDT"}, "data": [{"asks": [["83868.39", "0.150906"], ["83868.81", "0.327210"], ["83869.05", "0.008055"], ["83869.07", "0.004300"], ["83873.01", "0.886319"], ["83873.70", "0.001017"], ["83874.88", "2.745911"], ["83875.48", "0"], ["83875.70", "0.001199"], ["83876.50", "0"], ["83877.70", "0.003280"], ["83878.50", "0"], ["83879.70", "0.008633"], ["83880.50", "0"], ["83881.57", "0"], ["83881.70", "0.022717"], ["83882.50", "0"], ["83883.70", "0.059782"], ["83883.82", "0.017177"], ["83884.50", "0"], ["83885.70", "0.157323"], ["83886.10", "0"], ["83886.50", "0"], ["83886.59", "0"], ["83887.70", "0.414007"], ["83888.50", "0"], ["83889.70", "1.089492"], ["83890.50", "0"], ["83891.70", "2.867085"], ["83892.50", "0"], ["83893.70", "7.544960"], ["83893.80", "2.684820"], ["83894.00", "4.840470"], ["83894.20", "0.006030"], ["83894.50", "0"], ["83896.00", "0.084600"], ["83896.50", "3.938220"], ["83897.06", "0"], ["83897.10", "0"], ["83897.30", "0.045000"], ["83898.00", "0.022800"], ["83898.10", "0.075210"], ["83898.20", "0"], ["83899.90", "0"], ["83900.10", "0"], ["83900.50", "0.006810"], ["83900.70", "0.306300"], ["83900.80", "0"], ["83901.40", "0.137340"], ["83901.50", "0.269760"], ["83901.94", "0.715120"], ["83902.70", "0"], ["83903.60", "0.909480"], ["83904.10", "0.017250"], ["83904.60", "0.420000"], ["83904.80", "0.070080"], ["83905.50", "0.516000"], ["83905.90", "1.973850"], ["83906.30", "0"], ["83906.40", "0.672000"], ["83907.11", "0"], ["83908.00", "0.528000"], ["83908.20", "0.920760"], ["83908.30", "0.026400"], ["83909.10", "0"], ["83909.30", "0"], ["83909.50", "0"], ["83909.90", "0"], ["83910.00", "0.002000"], ["83910.60", "0"], ["83911.30", "0"], ["83912.00", "0"], ["83912.20", "0"], ["83935.60", "4.997484"], ["83938.50", "0"], ["83944.00", "4.452304"], ["83946.90", "0"], ["83952.40", "4.179714"], ["83955.30", "0"], ["83960.80", "5.179211"], ["83963.70", "0"], ["83969.20", "3.907124"], ["83972.10", "0"], ["83977.60", "4.361441"], ["83980.50", "0"], ["83986.00", "4.634031"], ["83988.90", "0"], ["83994.40", "5.451801"], ["83997.30", "0"], ["84002.80", "5.270074"], ["84005.70", "0"], ["84011.20", "4.815757"], ["84014.10", "0"], ["84019.60", "5.088347"], ["84022.50", "0"], ["84028.00", "5.542664"], ["84030.90", "0"], ["84036.40", "5.633527"], ["84039.30", "0"], ["84044.80", "4.906621"], ["84047.70", "0"], ["84053.20", "4.724894"], ["84056.10", "0"], ["84061.60", "4.270577"], ["84064.50", "0"], ["84070.00", "4.543167"], ["84072.90", "0"], ["84078.40", "3.997987"], ["84081.30", "0"], ["84086.80", "5.360937"], ["84089.70", "0"], ["84095.20", "4.088851"], ["84098.10", "0"], ["84460.23", "0"]], "bids": [["83873.00", "0"], ["83868.38", "0.008946"], ["83862.01", "0"], ["83859.69", "0"], ["83859.52", "0"], ["83857.22", "0.044429"], ["83855.47", "0"], ["83855.46", "0"], ["83853.22", "0.000228"], ["83849.97", "0.055103"], ["83847.17", "0"], ["83840.01", "0.178489"], ["83834.63", "0.314881"], ["83832.60", "0"], ["83830.60", "0"], ["83829.70", "0.001041"], ["83828.60", "0"], ["83827.70", "0.001003"], ["83826.60", "0"], ["83826.11", "0"], ["83825.70", "0.001012"], ["83824.60", "0"], ["83823.70", "0.001032"], ["83822.60", "0"], ["83821.70", "0.001145"], ["83821.25", "0.010000"], ["83820.60", "0"], ["83819.70", "0.003013"], ["83818.87", "0"], ["83818.60", "0"], ["83817.70", "0.007929"], ["83816.60", "0"], ["83815.70", "0.021079"], ["83814.60", "0"], ["83813.70", "0.055471"], ["83812.60", "0"], ["83812.40", "0"], ["83811.70", "0.145975"], ["83811.30", "0"], ["83811.00", "0"], ["83810.90", "0"], ["83810.00", "0"], ["83809.70", "0.384146"], ["83809.20", "0.001029"], ["83808.50", "0.001023"], ["83808.40", "0.001001"], ["83808.10", "0"], ["83808.00", "0.032010"], ["83807.50", "0"], ["83805.90", "0.083280"], ["83805.20", "0.006630"], ["83805.00", "0"], ["83804.40", "0"], ["83804.26", "0.017177"], ["83804.10", "0"], ["83803.70", "0.038610"], ["83803.60", "0"], ["83801.80", "0.038610"], ["83801.50", "0.015060"], ["83800.50", "0"], ["83799.90", "0.697410"], ["83799.60", "0.461700"], ["83799.50", "0"], ["83799.20", "0.120000"], ["83799.00", "0"], ["83798.70", "0.009870"], ["83798.20", "2.482770"], ["83797.60", "0.206670"], ["83797.40", "0.240000"], ["83770.60", "0"], ["83767.80", "3.997987"], ["83762.20", "0"], ["83759.40", "4.543167"], ["83753.80", "0"], ["83751.00", "5.542664"], ["83745.40", "0"], ["83742.60", "5.451801"], ["83737.00", "0.000009"], ["83734.20", "5.088347"], ["83728.60", "0"], ["83725.80", "4.997484"], ["83720.20", "0"], ["83717.40", "5.360937"], ["83711.80", "0"], ["83709.00", "4.088851"], ["83703.40", "0"], ["83700.60", "4.724894"], ["83695.00", "0"], ["83692.20", "4.815757"], ["83686.60", "0"], ["83683.80", "4.452304"], ["83678.20", "0"], ["83675.40", "5.270074"], ["83669.80", "0"], ["83667.00", "5.633527"], ["83661.40", "0"], ["83658.60", "4.634031"], ["83653.00", "0"], ["83650.20", "4.179714"], ["83644.60", "0"], ["83641.80", "5.179211"], ["83636.20", "0"], ["83633.40", "4.270577"], ["83627.80", "0"], ["83625.00", "4.361441"], ["83620.90", "0.198453"], ["83619.40", "0"], ["83617.80", "0"], ["83616.60", "4.906621"], ["83611.60", "0.000948"], ["83611.00", "0.000059"], ["83608.20", "3.907124"], ["83570.45", "0.000012"], ["83570.00", "0.000059"], ["83569.08", "0.000093"], ["83568.75", "0.000025"], ["83568.28", "0.000010"], ["83568.00", "0.000050"], ["83567.59", "0.000047"], ["83567.57", "0.000008"]], "checksum": 1796939407, "ts": "1742543255259"}], "ts": 1742543255263, "record_time": 1742543255.281246}
{"action": "update", "arg": {"instType": "SPOT", "channel": "books", "instId": "BTCUSDT"}, "data": [{"asks": [["83868.39", "0.882805"], ["83868.80", "0.101870"], ["83868.81", "0"], ["83873.01", "0.741883"], ["83873.02", "0.000210"], ["83873.03", "0"], ["83873.04", "0"], ["83875.70", "0.001474"], ["83877.70", "0.003998"], ["83879.70", "0.010520"], ["83881.70", "0.027685"], ["83883.70", "0.072992"], ["83885.70", "0.192085"], ["83886.58", "0.211703"], ["83887.70", "0.505486"], ["83889.70", "1.330227"], ["83891.70", "3.500597"], ["83893.70", "9.212096"], ["83893.80", "0.913500"], ["83896.50", "2.773230"], ["83896.80", "0.468360"], ["83897.64", "0.069700"], ["83899.80", "0.465240"], ["83900.70", "0.872190"], ["83901.70", "0.010830"], ["83903.80", "0.456000"], ["83903.90", "0.528000"], ["83908.00", "0"], ["83908.10", "0"], ["83908.20", "0"], ["83908.30", "0"], ["83935.60", "4.179714"], ["83944.00", "3.997987"], ["83952.40", "4.088851"], ["83960.80", "4.270577"], ["83969.20", "5.088347"], ["83977.60", "4.634031"], ["83986.00", "4.815757"], ["83994.40", "5.270074"], ["84002.80", "4.724894"], ["84011.20", "5.633527"], ["84019.60", "4.361441"], ["84036.40", "5.360937"], ["84044.80", "5.451801"], ["84053.20", "4.906621"], ["84061.60", "4.997484"], ["84078.40", "5.179211"], ["84086.80", "3.907124"], ["84095.20", "4.452304"]], "bids": [["83854.59", "0.115245"], ["83850.00", "0.083230"], ["83826.60", "0.013208"], ["83821.70", "0.001020"], ["83821.25", "0"], ["83819.70", "0.002252"], ["83817.70", "0.005928"], ["83815.70", "0.015599"], ["83813.70", "0.041050"], ["83811.70", "0.108028"], ["83809.70", "0.284282"], ["83802.50", "0.485610"], ["83801.80", "0.038400"], ["83801.70", "0.166560"], ["83799.90", "1.104780"], ["83799.20", "0"], ["83798.20", "2.362770"], ["83797.40", "0.179010"], ["83797.20", "0.143100"], ["83767.80", "4.634031"], ["83759.40", "3.907124"], ["83751.00", "5.451801"], ["83742.60", "4.724894"], ["83734.20", "5.542664"], ["83725.80", "4.088851"], ["83717.40", "4.543167"], ["83709.00", "5.179211"], ["83700.60", "4.270577"], ["83692.20", "4.452304"], ["83683.80", "5.360937"], ["83667.00", "4.179714"], ["83658.60", "4.815757"], ["83650.20", "4.906621"], ["83641.80", "5.088347"], ["83633.40", "3.997987"], ["83625.00", "5.633527"], ["83616.60", "4.361441"], ["83608.20", "4.997484"], ["83568.00", "0"], ["83567.59", "0"], ["83567.57", "0"]], "checksum": -1181643485, "ts": "1742543255465"}], "ts": 1742543255467, "record_time": 1742543255.443766}
{"action": "update", "arg": {"instType": "SPOT", "channel": "books", "instId": "BTCUSDT"}, "data": [{"asks": [["83868.80", "0.003707"], ["83873.02", "0.000465"], ["83886.58", "0"], ["83887.70", "0.505595"], ["83889.70", "1.330514"], ["83891.70", "3.501353"], ["83893.70", "9.214087"], ["83893.80", "1.365750"], ["83896.50", "2.692230"], ["83897.60", "0.045000"], ["83899.10", "0.107310"], ["83905.70", "0.268290"], ["83906.80", "0"], ["83907.40", "0"], ["83935.60", "4.543167"], ["83944.00", "4.724894"], ["83952.40", "5.179211"], ["83960.80", "3.997987"], ["83969.20", "5.360937"], ["83977.60", "4.815757"], ["83986.00", "4.179714"], ["83994.40", "4.088851"], ["84002.80", "4.997484"], ["84011.20", "5.542664"], ["84019.60", "4.634031"], ["84028.00", "4.270577"], ["84036.40", "5.451801"], ["84044.80", "5.270074"], ["84053.20", "5.633527"], ["84061.60", "4.361441"], ["84070.00", "3.907124"], ["84078.40", "4.906621"], ["84086.80", "5.088347"]], "bids": [["83857.64", "0.044431"], ["83857.22", "0"], ["83823.00", "0.000032"], ["83811.70", "0.108176"], ["83809.70", "0.284673"], ["83809.40", "0.001027"], ["83806.90", "0.031290"], ["83805.90", "0.068280"], ["83804.80", "0.045210"], ["83804.60", "0.428340"], ["83803.70", "0.038400"], ["83802.50", "0"], ["83801.70", "0"], ["83800.40", "2.362680"], ["83798.20", "0"], ["83796.90", "0.009000"], ["83767.80", "5.270074"], ["83759.40", "4.452304"], ["83751.00", "4.997484"], ["83742.60", "4.088851"], ["83734.20", "3.907124"], ["83725.80", "4.815757"], ["83717.40", "4.634031"], ["83709.00", "3.997987"], ["83700.60", "4.179714"], ["83692.20", "5.451801"], ["83683.80", "5.088347"], ["83675.40", "4.543167"], ["83667.00", "5.179211"], ["83658.60", "4.724894"], ["83650.20", "5.360937"], ["83641.80", "5.633527"], ["83633.40", "5.542664"], ["83625.00", "4.270577"], ["83608.20", "4.906621"], ["83568.75", "0"], ["83568.28", "0"]], "checksum": -1801533855, "ts": "1742543255668"}], "ts": 1742543255670, "record_time": 1742543255.647972}
{"action": "update", "arg": {"instType": "SPOT", "channel": "books", "instId": "BTCUSDT"}, "data": [{"asks": [["83873.00", "0.407189"], ["83873.02", "0.000255"], ["83879.87", "0"], ["83881.70", "0.027862"], ["83883.70", "0.073321"], ["83885.70", "0.192949"], ["83887.70", "0.507760"], ["83889.70", "1.336211"], ["83891.70", "3.516344"], ["83893.70", "9.253537"], ["83935.60", "5.542664"], ["83944.00", "4.997484"], ["83952.40", "5.088347"], ["83960.80", "5.360937"], ["83969.20", "4.815757"], ["83977.60", "5.179211"], ["83986.00", "4.452304"], ["83994.40", "4.724894"], ["84002.80", "5.451801"], ["84011.20", "5.270074"], ["84019.60", "4.179714"], ["84028.00", "4.088851"], ["84036.40", "4.270577"], ["84044.80", "4.634031"], ["84053.20", "4.543167"], ["84070.00", "4.906621"], ["84078.40", "3.907124"], ["84086.80", "3.997987"], ["84095.20", "5.633527"]], "bids": [["83821.00", "0.000017"], ["83800.50", "0.708810"], ["83799.90", "0.304800"], ["83767.80", "4.361441"], ["83742.60", "4.724894"], ["83734.20", "5.270074"], ["83725.80", "4.270577"], ["83717.40", "4.815757"], ["83709.00", "5.179211"], ["83700.60", "4.906621"], ["83692.20", "5.633527"], ["83683.80", "5.360937"], ["83667.00", "3.997987"], ["83658.60", "4.088851"], ["83650.20", "5.451801"], ["83641.80", "4.179714"], ["83633.40", "3.907124"], ["83625.00", "4.634031"], ["83616.60", "5.088347"], ["83608.20", "5.542664"], ["83569.08", "0"]], "checksum": -1525755537, "ts": "1742543255876"}], "ts": 1742543255878, "record_time": 1742543255.856469}
{"action": "update", "arg": {"instType": "SPOT", "channel": "books", "instId": "BTCUSDT"}, "data": [{"asks": [["83868.39", "0.555595"], ["83887.70", "0.507869"], ["83889.70", "1.336498"], ["83891.70", "3.517101"], ["83893.70", "9.255527"], ["83896.20", "0.468360"], ["83896.50", "2.689020"], ["83896.80", "0"], ["83898.60", "0.030000"], ["83898.70", "0.536580"], ["83904.24", "0"], ["83906.40", "0"], ["83935.60", "5.088347"], ["83944.00", "4.361441"], ["83952.40", "5.542664"], ["83960.80", "4.088851"], ["83969.20", "5.633527"], ["83977.60", "4.906621"], ["83986.00", "3.997987"], ["83994.40", "4.815757"], ["84011.20", "4.452304"], ["84019.60", "4.724894"], ["84028.00", "4.543167"], ["84036.40", "3.907124"], ["84044.80", "5.179211"], ["84053.20", "5.360937"], ["84061.60", "4.634031"], ["84070.00", "4.997484"], ["84078.40", "5.270074"], ["84086.80", "4.179714"], ["84095.20", "4.270577"]], "bids": [["83868.38", "0.336156"], ["83849.97", "0"], ["83821.70", "0.001170"], ["83819.70", "0.003080"], ["83817.70", "0.008103"], ["83815.70", "0.021326"], ["83813.70", "0.056121"], ["83811.70", "0.147686"], ["83809.70", "0.388647"], ["83809.30", "0.001020"], ["83808.40", "0"], ["83806.50", "0.426420"], ["83804.60", "0"], ["83767.80", "4.815757"], ["83759.40", "4.361441"], ["83751.00", "4.270577"], ["83742.60", "5.451801"], ["83734.20", "4.452304"], ["83725.80", "3.997987"], ["83717.40", "5.542664"], ["83709.00", "5.270074"], ["83700.60", "4.724894"], ["83692.20", "4.634031"], ["83683.80", "4.543167"], ["83675.40", "4.997484"], ["83667.00", "4.906621"], ["83658.60", "5.088347"], ["83650.20", "3.907124"], ["83641.80", "4.088851"], ["83633.40", "4.179714"], ["83625.00", "5.179211"], ["83616.60", "5.360937"], ["83608.20", "5.633527"], ["83569.08", "0.000093"]], "checksum": -1288118670, "ts": "1742543256079"}], "ts": 1742543256084, "record_time": 1742543256.056782}
{"action": "update", "arg": {"instType": "SPOT", "channel": "books", "instId": "BTCUSDT"}, "data": [{"asks": [["83868.39", "0.882805"], ["83873.01", "0.714941"], ["83873.02", "0"], ["83881.64", "0.026942"], ["83896.50", "2.770020"], ["83901.50", "0"], ["83913.68", "0.001598"], ["83915.72", "0.001597"], ["83917.43", "0"], ["83919.74", "0"], ["83935.60", "4.724894"], ["83944.00", "4.270577"], ["83952.40", "4.543167"], ["83969.20", "5.088347"], ["83977.60", "5.270074"], ["83986.00", "4.815757"], ["83994.40", "5.360937"], ["84002.80", "3.907124"], ["84011.20", "4.997484"], ["84019.60", "4.906621"], ["84028.00", "5.542664"], ["84036.40", "4.634031"], ["84044.80", "4.452304"], ["84053.20", "4.179714"], ["84061.60", "5.179211"], ["84070.00", "4.361441"], ["84078.40", "5.633527"], ["84086.80", "3.997987"], ["84095.20", "5.451801"], ["84460.23", "0.000010"]], "bids": [["83868.38", "0.335561"], ["83858.00", "0.044445"], ["83857.64", "0"], ["83854.73", "0.055103"], ["83834.23", "1.079840"], ["83829.50", "0"], ["83822.94", "0.000878"], ["83821.70", "0.002589"], ["83821.00", "0"], ["83819.70", "0.006812"], ["83817.70", "0.017925"], ["83815.70", "0.047172"], ["83813.70", "0.124137"], ["83811.70", "0.326676"], ["83809.70", "0.859673"], ["83808.30", "0.457800"], ["83807.50", "0.381570"], ["83807.40", "0"], ["83806.50", "0"], ["83805.85", "0"], ["83804.80", "0.045000"], ["83803.66", "0.001178"], ["83801.84", "0.001176"], ["83800.50", "0.709230"], ["83767.80", "5.451801"], ["83759.40", "5.542664"], ["83751.00", "4.543167"], ["83742.60", "4.634031"], ["83734.20", "5.633527"], ["83725.80", "4.906621"], ["83717.40", "4.452304"], ["83709.00", "4.361441"], ["83700.60", "3.997987"], ["83692.20", "5.360937"], ["83683.80", "4.270577"], ["83675.40", "4.815757"], ["83667.00", "4.724894"], ["83658.60", "3.907124"], ["83650.20", "4.997484"], ["83641.80", "5.270074"], ["83633.40", "4.088851"], ["83625.00", "4.179714"], ["83616.60", "5.179211"], ["83608.20", "5.088347"], ["83569.08", "0"]], "checksum": -1074672365, "ts": "1742543256281"}], "ts": 1742543256286, "record_time": 1742543256.358676}
{"action": "update", "arg": {"instType": "SPOT", "channel": "books", "instId": "BTCUSDT"}, "data": [{"asks": [["83891.70", "3.516917"], ["83893.70", "9.255044"], ["83935.60", "4.906621"], ["83944.00", "4.815757"], ["83952.40", "5.451801"], ["83960.80", "5.270074"], ["83969.20", "3.907124"], ["83977.60", "5.633527"], ["83986.00", "4.634031"], ["83994.40", "4.724894"], ["84002.80", "4.543167"], ["84011.20", "5.542664"], ["84019.60", "5.179211"], ["84028.00", "5.088347"], ["84036.40", "4.997484"], ["84044.80", "4.270577"], ["84053.20", "4.452304"], ["84061.60", "4.088851"], ["84070.00", "3.997987"], ["84078.40", "5.360937"], ["84086.80", "4.179714"], ["84095.20", "4.361441"]], "bids": [["83859.99", "0.209200"], ["83828.03", "0.372953"], ["83823.70", "0.002856"], ["83821.70", "0.007517"], ["83819.70", "0.019780"], ["83819.15", "0.010000"], ["83817.70", "0.052054"], ["83815.70", "0.136985"], ["83813.70", "0.360485"], ["83811.70", "0.948646"], ["83809.70", "2.496436"], ["83808.30", "0"], ["83807.50", "0"], ["83806.10", "0.077160"], ["83805.90", "0.068070"], ["83803.70", "0.077910"], ["83803.60", "0.143100"], ["83802.80", "3.087510"], ["83801.80", "0"], ["83801.40", "1.350000"], ["83800.50", "0"], ["83800.40", "0"], ["83797.90", "0.145020"], ["83767.80", "5.088347"], ["83759.40", "4.906621"], ["83751.00", "4.452304"], ["83742.60", "5.451801"], ["83734.20", "4.361441"], ["83725.80", "5.542664"], ["83717.40", "3.997987"], ["83709.00", "5.179211"], ["83700.60", "4.815757"], ["83692.20", "4.724894"], ["83683.80", "4.543167"], ["83675.40", "5.633527"], ["83667.00", "4.088851"], ["83658.60", "4.270577"], ["83650.20", "3.907124"], ["83641.80", "4.634031"], ["83633.40", "5.360937"], ["83625.00", "4.997484"], ["83616.60", "5.270074"], ["83608.20", "4.179714"], ["83570.62", "0"], ["83570.45", "0"], ["83570.00", "0"]], "checksum": 106232094, "ts": "1742543256482"}], "ts": 1742543256484, "record_time": 1742543256.463427}
{"action": "update", "arg": {"instType": "SPOT", "channel": "books", "instId": "BTCUSDT"}, "data": [{"asks": [["83868.39", "0.847305"], ["83873.01", "0.492930"], ["83881.70", "0.027614"], ["83883.70", "0.072666"], ["83885.70", "0.191228"], ["83887.70", "0.503121"], ["83889.70", "1.324004"], ["83891.70", "3.484220"], ["83893.70", "9.169000"], ["83896.50", "2.706600"], ["83897.10", "0.145020"], ["83898.70", "0"], ["83899.10", "0"], ["83906.40", "0.004320"], ["83935.60", "5.633527"], ["83944.00", "4.543167"], ["83952.40", "4.361441"], ["83960.80", "4.906621"], ["83969.20", "5.451801"], ["83977.60", "4.452304"], ["83986.00", "3.997987"], ["83994.40", "4.634031"], ["84002.80", "4.088851"], ["84011.20", "4.179714"], ["84019.60", "4.724894"], ["84028.00", "5.179211"], ["84036.40", "3.907124"], ["84044.80", "5.088347"], ["84053.20", "5.360937"], ["84061.60", "4.270577"], ["84070.00", "5.542664"], ["84078.40", "5.270074"], ["84086.80", "4.815757"], ["84095.20", "4.997484"]], "bids": [["83859.99", "0"], ["83858.00", "0.000015"], ["83822.00", "0.000015"], ["83820.00", "0.002015"], ["83819.00", "0.000015"], ["83802.81", "1.347026"], ["83801.40", "0"], ["83800.90", "0.145020"], ["83797.90", "0"], ["83767.80", "4.452304"], ["83759.40", "4.361441"], ["83751.00", "4.270577"], ["83742.60", "3.907124"], ["83734.20", "5.088347"], ["83725.80", "5.360937"], ["83717.40", "4.179714"], ["83709.00", "3.997987"], ["83700.60", "4.997484"], ["83692.20", "4.543167"], ["83683.80", "5.633527"], ["83675.40", "5.451801"], ["83667.00", "4.724894"], ["83658.60", "4.634031"], ["83650.20", "5.270074"], ["83641.80", "5.179211"], ["83633.40", "4.815757"], ["83625.00", "5.542664"], ["83616.60", "4.906621"], ["83608.20", "4.088851"], ["83571.39", "0"]], "checksum": 1505955137, "ts": "1742543256683"}], "ts": 1742543256686, "record_time": 1742543256.659248}
{"action": "update", "arg": {"instType": "SPOT", "channel": "books", "instId": "BTCUSDT"}, "data": [{"asks": [["83868.39", "1.055319"], ["83879.70", "0.010363"], ["83881.70", "0.027167"], ["83883.70", "0.071492"], ["83885.70", "0.188136"], ["83887.70", "0.495094"], ["83889.70", "1.302880"], ["83891.70", "3.428630"], ["83893.70", "9.022711"], ["83899.10", "0.107310"], ["83899.40", "0.536580"], ["83905.90", "1.013850"], ["83906.40", "0"], ["83944.00", "4.088851"], ["83952.40", "4.724894"], ["83960.80", "5.542664"], ["83969.20", "4.543167"], ["83977.60", "4.270577"], ["83986.00", "4.179714"], ["83994.40", "4.906621"], ["84002.80", "4.815757"], ["84011.20", "5.179211"], ["84019.60", "5.088347"], ["84028.00", "3.907124"], ["84036.40", "4.634031"], ["84044.80", "4.997484"], ["84053.20", "4.361441"], ["84061.60", "4.452304"], ["84070.00", "5.360937"], ["84078.40", "5.451801"], ["84086.80", "3.997987"], ["84095.20", "5.270074"], ["84460.23", "0"]], "bids": [["83858.36", "0.044430"], ["83854.74", "0.051104"], ["83823.70", "0.002489"], ["83822.00", "0.000032"], ["83821.70", "0.006552"], ["83820.00", "0.002032"], ["83819.70", "0.017240"], ["83819.00", "0.000032"], ["83817.70", "0.045370"], ["83815.70", "0.119394"], ["83813.70", "0.314195"], ["83811.70", "0.826829"], ["83809.70", "2.175865"], ["83804.80", "0.090000"], ["83802.81", "0"], ["83797.50", "0.250230"], ["83767.80", "4.997484"], ["83759.40", "3.907124"], ["83751.00", "4.452304"], ["83742.60", "5.179211"], ["83734.20", "5.633527"], ["83725.80", "4.724894"], ["83717.40", "4.815757"], ["83709.00", "5.542664"], ["83700.60", "4.543167"], ["83692.20", "4.361441"], ["83683.80", "4.270577"], ["83675.40", "5.360937"], ["83667.00", "4.179714"], ["83658.60", "4.088851"], ["83650.20", "3.997987"], ["83641.80", "5.451801"], ["83633.40", "4.906621"], ["83625.00", "5.270074"], ["83616.60", "5.088347"], ["83608.20", "4.634031"], ["83571.43", "0"], ["83571.42", "0"]], "checksum": 1347768934, "ts": "1742543256893"}], "ts": 1742543256896, "record_time": 1742543256.870709}
{"action": "update", "arg": {"instType": "SPOT", "channel": "books", "instId": "BTCUSDT"}, "data": [{"asks": [["83896.50", "2.975520"], ["83935.60", "4.543167"], ["83944.00", "4.634031"], ["83952.40", "4.270577"], ["83960.80", "5.633527"], ["83969.20", "3.997987"], ["83977.60", "4.815757"], ["83986.00", "4.906621"], ["83994.40", "4.361441"], ["84002.80", "3.907124"], ["84011.20", "5.360937"], ["84019.60", "4.179714"], ["84028.00", "5.179211"], ["84036.40", "5.088347"], ["84044.80", "5.542664"], ["84053.20", "4.724894"], ["84061.60", "4.997484"], ["84070.00", "5.451801"], ["84078.40", "4.088851"], ["84086.80", "4.452304"]], "bids": [["83857.90", "0.055103"], ["83854.73", "0"], ["83806.90", "0.022080"], ["83805.90", "0.068280"], ["83805.50", "0.015000"], ["83796.90", "0"], ["83775.00", "0.062760"], ["83767.80", "3.907124"], ["83759.40", "5.451801"], ["83751.00", "4.997484"], ["83742.60", "4.724894"], ["83725.80", "4.361441"], ["83717.40", "5.360937"], ["83709.00", "3.997987"], ["83700.60", "5.270074"], ["83692.20", "4.270577"], ["83683.80", "4.906621"], ["83675.40", "4.815757"], ["83667.00", "4.634031"], ["83658.60", "4.543167"], ["83650.20", "5.542664"], ["83641.80", "5.088347"], ["83633.40", "5.179211"], ["83625.00", "4.452304"], ["83616.60", "4.179714"], ["83608.20", "4.088851"], ["83571.79", "0"]], "checksum": 926044694, "ts": "1742543257099"}], "ts": 1742543257102, "record_time": 1742543257.082097}
{"action": "update", "arg": {"instType": "SPOT", "channel": "books", "instId": "BTCUSDT"}, "data": [{"asks": [["83873.01", "0.482930"], ["83893.70", "9.022562"], ["83935.60", "3.907124"], ["83944.00", "4.543167"], ["83952.40", "4.634031"], ["83960.80", "4.179714"], ["83969.20", "4.906621"], ["83977.60", "5.270074"], ["83986.00", "4.361441"], ["83994.40", "3.997987"], ["84002.80", "5.451801"], ["84011.20", "4.088851"], ["84019.60", "5.088347"], ["84028.00", "4.270577"], ["84036.40", "4.997484"], ["84044.80", "5.179211"], ["84053.20", "4.815757"], ["84061.60", "5.633527"], ["84070.00", "4.452304"], ["84078.40", "4.724894"], ["84086.80", "5.360937"], ["84095.20", "5.542664"]], "bids": [["83859.99", "0.209200"], ["83858.76", "0.044430"], ["83858.36", "0"], ["83854.74", "0.034574"], ["83767.80", "4.997484"], ["83759.40", "4.634031"], ["83751.00", "4.088851"], ["83742.60", "5.179211"], ["83734.20", "5.542664"], ["83725.80", "5.360937"], ["83717.40", "4.815757"], ["83700.60", "4.270577"], ["83692.20", "5.451801"], ["83683.80", "4.452304"], ["83675.40", "5.633527"], ["83667.00", "5.270074"], ["83658.60", "4.179714"], ["83650.20", "3.907124"], ["83641.80", "4.906621"], ["83633.40", "4.724894"], ["83625.00", "4.361441"], ["83616.60", "5.088347"], ["83608.20", "4.543167"], ["83574.19", "0"]], "checksum": 1272093643, "ts": "1742543257311"}], "ts": 1742543257315, "record_time": 1742543257.369362}
{"action": "update", "arg": {"instType": "SPOT", "channel": "books", "instId": "BTCUSDT"}, "data": [{"asks": [["83868.39", "1.055469"], ["83873.01", "0.472930"], ["83894.00", "4.697370"], ["83896.50", "1.115640"], ["83899.10", "0"], ["83899.40", "0"], ["83902.10", "1.350000"], ["83905.90", "1.973850"], ["83906.40", "0.004320"], ["83935.60", "5.451801"], ["83944.00", "5.270074"], ["83952.40", "5.633527"], ["83960.80", "5.179211"], ["83969.20", "4.724894"], ["83977.60", "4.361441"], ["83986.00", "4.452304"], ["83994.40", "5.542664"], ["84002.80", "4.634031"], ["84011.20", "3.907124"], ["84019.60", "4.997484"], ["84028.00", "4.815757"], ["84036.40", "4.179714"], ["84044.80", "4.543167"], ["84053.20", "4.270577"], ["84061.60", "4.088851"], ["84070.00", "4.906621"], ["84078.40", "5.088347"], ["84095.20", "3.997987"]], "bids": [["83868.38", "0.334854"], ["83830.28", "0.192351"], ["83821.00", "0.000015"], ["83818.00", "0.000015"], ["83809.70", "2.176014"], ["83804.00", "0.084600"], ["83802.80", "3.445440"], ["83801.40", "1.350000"], ["83767.80", "3.997987"], ["83759.40", "4.270577"], ["83742.60", "4.179714"], ["83734.20", "4.815757"], ["83725.80", "4.361441"], ["83717.40", "4.997484"], ["83709.00", "5.542664"], ["83700.60", "4.906621"], ["83675.40", "5.179211"], ["83667.00", "3.907124"], ["83658.60", "5.088347"], ["83650.20", "5.633527"], ["83641.80", "5.270074"], ["83633.40", "4.634031"], ["83625.00", "4.724894"], ["83616.60", "4.543167"], ["83608.20", "5.360937"], ["83577.76", "0"], ["83577.73", "0"], ["83577.41", "0"], ["83576.47", "0"], ["83575.00", "0"]], "checksum": -1728541354, "ts": "1742543257512"}], "ts": 1742543257515, "record_time": 1742543257.492409}
{"action": "update", "arg": {"instType": "SPOT", "channel": "books", "instId": "BTCUSDT"}, "data": [{"asks": [["83868.39", "1.055639"], ["83880.55", "0"], ["83880.72", "0"], ["83880.79", "0"], ["83881.15", "0.119869"], ["83882.47", "0.035972"], ["83882.48", "0"], ["83882.59", "0"], ["83882.71", "0"], ["83882.91", "0.006357"], ["83883.06", "0"], ["83883.53", "0.006357"], ["83883.89", "0.006357"], ["83884.54", "0.006357"], ["83884.63", "0.010995"], ["83885.38", "0"], ["83885.51", "0"], ["83885.61", "0"], ["83885.84", "0"], ["83886.09", "0.006357"], ["83886.12", "0.006357"], ["83886.39", "0.119883"], ["83886.56", "0.006357"], ["83888.22", "0"], ["83888.89", "0.009990"], ["83890.27", "0"], ["83890.60", "0"], ["83890.79", "0"], ["83891.00", "0.119867"], ["83891.38", "0.015895"], ["83891.41", "0.009989"], ["83892.28", "0"], ["83893.26", "0"], ["83893.31", "0.006356"], ["83894.07", "0"], ["83895.26", "0.015892"], ["83895.83", "0.010988"], ["83896.50", "1.292400"], ["83906.40", "0"], ["83935.60", "4.361441"], ["83944.00", "5.088347"], ["83952.40", "4.815757"], ["83960.80", "4.997484"], ["83969.20", "4.634031"], ["83977.60", "3.907124"], ["83986.00", "5.360937"], ["83994.40", "5.270074"], ["84002.80", "4.543167"], ["84011.20", "3.997987"], ["84019.60", "4.724894"], ["84028.00", "4.179714"], ["84036.40", "4.452304"], ["84044.80", "5.633527"], ["84053.20", "5.542664"], ["84061.60", "4.270577"], ["84070.00", "4.088851"], ["84078.40", "5.451801"], ["84086.80", "4.906621"], ["84095.20", "5.179211"], ["84460.23", "0.000010"]], "bids": [["83840.74", "0.089750"], ["83840.06", "0.248347"], ["83840.00", "0.000032"], ["83838.86", "0.084173"], ["83838.58", "0.004026"], ["83838.46", "0.017859"], ["83838.30", "0"], ["83838.08", "0.005961"], ["83837.77", "0.015766"], ["83837.26", "0"], ["83837.11", "0"], ["83837.08", "0.006577"], ["83837.00", "0.055821"], ["83836.94", "0"], ["83836.81", "0.017144"], ["83836.36", "0"], ["83836.11", "0"], ["83835.60", "0.007962"], ["83835.24", "0.225405"], ["83835.03", "0"], ["83835.02", "0"], ["83834.89", "0"], ["83834.60", "0"], ["83834.11", "0"], ["83832.70", "0.018560"], ["83832.04", "0"], ["83830.62", "0.260400"], ["83830.50", "0.076289"], ["83830.19", "0.029471"], ["83829.91", "0"], ["83829.89", "0"], ["83829.38", "0"], ["83828.06", "0.012467"], ["83827.04", "0"], ["83826.49", "0.073385"], ["83825.38", "0.056498"], ["83824.50", "0"], ["83823.62", "0"], ["83821.00", "0.000032"], ["83818.00", "0.000032"], ["83817.70", "0.045187"], ["83815.70", "0.118913"], ["83813.70", "0.312930"], ["83811.70", "0.823500"], ["83809.70", "2.167365"], ["83805.46", "0.003605"], ["83804.88", "0.309571"], ["83804.78", "0"], ["83802.80", "3.087510"], ["83801.40", "0"], ["83767.80", "4.361441"], ["83759.40", "3.907124"], ["83751.00", "3.997987"], ["83742.60", "4.088851"], ["83734.20", "5.451801"], ["83725.80", "4.179714"], ["83717.40", "4.724894"], ["83709.00", "5.270074"], ["83700.60", "4.452304"], ["83692.20", "5.088347"], ["83683.80", "5.179211"], ["83675.40", "4.997484"], ["83667.00", "4.634031"], ["83658.60", "5.360937"], ["83650.20", "4.906621"], ["83641.80", "4.270577"], ["83633.40", "5.542664"], ["83625.00", "4.815757"], ["83608.20", "5.633527"], ["83577.76", "0.000483"]], "checksum": -1760007542, "ts": "1742543257713"}], "ts": 1742543257715, "record_time": 1742543257.689536}
{"action": "update", "arg": {"instType": "SPOT", "channel": "books", "instId": "BTCUSDT"}, "data": [{"asks": [["83876.93", "0"], ["83879.78", "0"], ["83880.04", "0"], ["83880.88", "0"], ["83881.24", "0"], ["83881.26", "0.035953"], ["83881.54", "0"], ["83882.39", "0"], ["83882.43", "0"], ["83883.13", "0"], ["83883.19", "0.006357"], ["83883.69", "0"], ["83884.05", "0"], ["83884.36", "0.006357"], ["83884.78", "0"], ["83884.92", "0.006357"], ["83885.20", "0.006357"], ["83885.71", "0.006357"], ["83885.81", "0.006356"], ["83885.85", "0.016429"], ["83886.05", "0"], ["83886.44", "0.016429"], ["83886.54", "0.006357"], ["83886.82", "0"], ["83887.92", "0.006357"], ["83888.11", "0.010994"], ["83888.36", "0.006357"], ["83889.71", "0.119850"], ["83890.89", "0.119858"], ["83893.70", "9.022748"], ["83935.60", "4.543167"], ["83944.00", "3.907124"], ["83952.40", "4.270577"], ["83960.72", "0"], ["83969.20", "4.088851"], ["83970.06", "0"], ["83977.60", "5.542664"], ["83986.00", "4.179714"], ["83994.40", "4.815757"], ["84002.80", "3.997987"], ["84011.20", "5.179211"], ["84019.60", "5.451801"], ["84028.00", "4.452304"], ["84036.40", "5.360937"], ["84044.80", "4.724894"], ["84053.20", "4.634031"], ["84061.60", "5.633527"], ["84070.00", "5.270074"], ["84078.40", "4.906621"], ["84086.80", "4.361441"], ["84095.20", "5.088347"], ["84187.14", "1.726669"], ["84189.98", "0"], ["84460.49", "0.000009"]], "bids": [["83859.11", "0.044430"], ["83858.76", "0"], ["83840.07", "0.179912"], ["83840.01", "0.014277"], ["83838.41", "0.018298"], ["83837.90", "0.016450"], ["83836.45", "0.007149"], ["83836.37", "0.028932"], ["83836.34", "0.007359"], ["83835.90", "0.017130"], ["83835.89", "0.009016"], ["83835.33", "0.008205"], ["83835.28", "0.025240"], ["83835.05", "0.017392"], ["83835.00", "0.000032"], ["83834.42", "0.008296"], ["83833.85", "0.012685"], ["83833.60", "0.052076"], ["83833.58", "0"], ["83832.95", "0"], ["83832.77", "0"], ["83832.58", "0"], ["83832.06", "0"], ["83831.97", "0"], ["83831.95", "0"], ["83831.68", "0.269000"], ["83831.64", "0"], ["83831.57", "0"], ["83830.85", "0.223187"], ["83830.28", "0"], ["83830.27", "0"], ["83830.19", "0.021176"], ["83829.54", "0"], ["83828.02", "0"], ["83826.78", "0"], ["83811.70", "0.823393"], ["83809.70", "2.166826"], ["83767.80", "4.815757"], ["83762.72", "0"], ["83759.40", "4.088851"], ["83754.34", "0"], ["83751.00", "5.179211"], ["83742.60", "4.906621"], ["83734.20", "4.361441"], ["83725.80", "4.724894"], ["83717.40", "3.997987"], ["83709.00", "5.633527"], ["83692.20", "5.451801"], ["83683.80", "5.088347"], ["83675.40", "5.270074"], ["83667.00", "4.543167"], ["83658.60", "4.997484"], ["83650.20", "4.179714"], ["83641.80", "3.907124"], ["83633.40", "4.270577"], ["83625.00", "5.360937"], ["83616.60", "5.542664"], ["83608.20", "4.634031"]], "checksum": 38282081, "ts": "1742543257916"}], "ts": 1742543257921, "record_time": 1742543257.895596}
{"action": "update", "arg": {"instType": "SPOT", "channel": "books", "instId": "BTCUSDT"}, "data": [{"asks": [["83876.92", "0"], ["83881.70", "0.027387"], ["83883.70", "0.072070"], ["83885.70", "0.189657"], ["83887.70", "0.499099"], ["83889.70", "1.313419"], ["83891.70", "3.456365"], ["83893.70", "9.095698"], ["83896.50", "1.294080"], ["83935.60", "5.633527"], ["83944.00", "4.088851"], ["83952.40", "5.270074"], ["83960.80", "4.452304"], ["83969.20", "5.542664"], ["83977.60", "4.634031"], ["83986.00", "5.451801"], ["83994.40", "5.088347"], ["84002.80", "4.724894"], ["84011.20", "3.997987"], ["84019.60", "4.270577"], ["84028.00", "4.179714"], ["84036.40", "3.907124"], ["84044.80", "4.361441"], ["84053.20", "4.815757"], ["84061.60", "5.360937"], ["84070.00", "5.179211"], ["84078.40", "4.543167"], ["84086.80", "4.997484"], ["84095.20", "4.906621"], ["84460.87", "0.000069"]], "bids": [["83828.03", "0"], ["83809.70", "2.166956"], ["83805.50", "0.030000"], ["83767.80", "4.906621"], ["83759.40", "4.634031"], ["83751.01", "0.085140"], ["83751.00", "5.360937"], ["83742.60", "4.815757"], ["83734.20", "4.179714"], ["83725.80", "4.270577"], ["83717.40", "5.451801"], ["83709.00", "4.543167"], ["83700.60", "5.088347"], ["83692.20", "4.997484"], ["83683.80", "4.452304"], ["83675.40", "5.542664"], ["83667.00", "3.907124"], ["83658.60", "4.361441"], ["83650.20", "4.088851"], ["83641.80", "5.633527"], ["83633.40", "4.724894"], ["83625.00", "3.997987"], ["83616.60", "5.270074"], ["83608.20", "5.179211"]], "checksum": -175216147, "ts": "1742543258128"}], "ts": 1742543258130, "record_time": 1742543258.107129}
{"action": "update", "arg": {"instType": "SPOT", "channel": "books", "instId": "BTCUSDT"}, "data": [{"asks": [["83885.70", "0.189417"], ["83887.70", "0.498465"], ["83889.70", "1.311751"], ["83891.70", "3.451976"], ["83893.70", "9.084147"], ["83894.00", "4.840470"], ["83935.60", "4.906621"], ["83938.29", "0.001810"], ["83944.00", "4.634031"], ["83946.68", "0.003620"], ["83952.40", "4.452304"], ["83960.80", "3.907124"], ["83969.20", "4.815757"], ["83977.38", "0.125961"], ["83977.60", "5.179211"], ["83986.00", "5.360937"], ["83994.40", "4.543167"], ["84010.13", "0"], ["84011.20", "4.179714"], ["84019.60", "5.451801"], ["84028.00", "4.270577"], ["84036.40", "5.088347"], ["84044.80", "3.997987"], ["84053.20", "5.633527"], ["84061.60", "5.542664"], ["84070.00", "4.361441"], ["84078.40", "4.088851"], ["84095.20", "5.270074"], ["84460.49", "0"], ["84460.87", "0"]], "bids": [["83859.11", "0"], ["83809.70", "2.166826"], ["83767.80", "4.634031"], ["83759.40", "5.451801"], ["83751.00", "4.361441"], ["83745.18", "0.001810"], ["83742.60", "4.179714"], ["83735.49", "0.003620"], ["83734.20", "4.906621"], ["83717.41", "1.635727"], ["83717.40", "4.088851"], ["83709.00", "5.179211"], ["83700.60", "4.543167"], ["83692.20", "5.542664"], ["83683.80", "5.360937"], ["83675.40", "5.633527"], ["83667.00", "5.088347"], ["83658.60", "4.815757"], ["83650.20", "5.270074"], ["83641.80", "3.997987"], ["83633.40", "3.907124"], ["83625.00", "4.724894"], ["83616.60", "4.452304"], ["83608.20", "4.997484"], ["83577.78", "0"], ["83577.76", "0"]], "checksum": -630844249, "ts": "1742543258330"}], "ts": 1742543258334, "record_time": 1742543258.307895}
{"action": "update", "arg": {"instType": "SPOT", "channel": "books", "instId": "BTCUSDT"}, "data": [{"asks": [["83868.39", "1.055319"], ["83889.70", "1.311632"], ["83891.70", "3.451665"], ["83893.70", "9.083329"], ["83935.60", "4.088851"], ["83944.00", "4.997484"], ["83952.40", "4.543167"], ["83960.80", "5.360937"], ["83969.20", "4.270577"], ["83977.60", "4.361441"], ["83986.00", "3.997987"], ["83994.40", "5.179211"], ["84011.20", "4.452304"], ["84019.60", "5.088347"], ["84028.00", "5.633527"], ["84036.40", "5.451801"], ["84044.80", "4.634031"], ["84053.20", "5.542664"], ["84061.60", "4.179714"], ["84070.00", "4.815757"], ["84078.40", "4.906621"], ["84086.80", "5.270074"], ["84095.20", "3.907124"]], "bids": [["83868.38", "0.333483"], ["83859.41", "0.044430"], ["83831.69", "0.318107"], ["83767.80", "4.815757"], ["83759.40", "4.361441"], ["83751.00", "4.543167"], ["83742.60", "3.907124"], ["83734.20", "4.270577"], ["83725.80", "5.088347"], ["83717.40", "4.724894"], ["83700.60", "5.360937"], ["83692.20", "5.270074"], ["83683.80", "5.633527"], ["83675.40", "4.906621"], ["83667.00", "4.997484"], ["83658.60", "3.997987"], ["83650.20", "5.542664"], ["83641.80", "5.451801"], ["83633.40", "4.179714"], ["83625.00", "4.088851"], ["83608.20", "4.634031"], ["83578.04", "0"], ["83577.98", "0"]], "checksum": -19540526, "ts": "1742543258538"}], "ts": 1742543258541, "record_time": 1742543258.513998}
{"action": "update", "arg": {"instType": "SPOT", "channel": "books", "instId": "BTCUSDT"}, "data": [{"asks": [["83900.70", "1.196400"], ["83935.60", "4.361441"], ["83944.00", "4.452304"], ["83952.40", "4.634031"], ["83960.80", "4.088851"], ["83969.20", "5.542664"], ["83977.60", "4.906621"], ["83986.00", "4.815757"], ["83994.40", "3.907124"], ["84002.80", "5.360937"], ["84011.20", "5.633527"], ["84019.60", "4.997484"], ["84028.00", "5.179211"], ["84036.40", "5.088347"], ["84044.80", "5.451801"], ["84053.20", "4.270577"], ["84070.00", "5.270074"], ["84078.40", "4.543167"], ["84086.80", "3.997987"], ["84095.20", "4.724894"]], "bids": [["83857.90", "0"], ["83819.15", "0"], ["83802.81", "0.985532"], ["83767.80", "3.907124"], ["83759.40", "4.543167"], ["83751.00", "4.997484"], ["83742.60", "4.724894"], ["83734.20", "3.997987"], ["83725.80", "5.360937"], ["83717.41", "0.097853"], ["83717.40", "5.451801"], ["83709.00", "4.452304"], ["83700.60", "5.270074"], ["83692.20", "4.179714"], ["83683.80", "4.270577"], ["83675.40", "4.361441"], ["83667.00", "4.088851"], ["83658.60", "4.815757"], ["83650.20", "4.906621"], ["83641.80", "5.542664"], ["83633.40", "5.088347"], ["83625.00", "5.179211"], ["83616.60", "4.634031"], ["83608.20", "5.633527"], ["83578.04", "0.000096"]], "checksum": 736963155, "ts": "1742543258737"}], "ts": 1742543258741, "record_time": 1742543258.714953}
{"action": "update", "arg": {"instType": "SPOT", "channel": "books", "instId": "BTCUSDT"}, "data": [{"asks": [["83868.39", "1.065319"], ["83896.50", "1.117320"], ["83906.40", "0.004320"], ["83935.60", "5.360937"], ["83944.00", "4.270577"], ["83952.40", "3.997987"], ["83960.80", "4.906621"], ["83969.20", "5.633527"], ["83977.60", "4.452304"], ["83986.00", "4.361441"], ["83994.40", "4.815757"], ["84002.80", "5.270074"], ["84011.20", "4.724894"], ["84019.60", "3.907124"], ["84028.00", "4.179714"], ["84036.40", "5.542664"], ["84044.80", "4.088851"], ["84053.20", "5.451801"], ["84061.60", "4.997484"], ["84070.00", "5.088347"], ["84086.80", "4.634031"], ["84095.20", "5.179211"], ["84460.23", "0"]], "bids": [["83860.62", "0.055103"], ["83859.99", "0"], ["83859.77", "0.044429"], ["83859.41", "0"], ["83825.70", "0.001000"], ["83823.70", "0.002479"], ["83821.70", "0.006524"], ["83819.70", "0.017168"], ["83817.70", "0.044990"], ["83815.70", "0.118395"], ["83813.70", "0.311566"], ["83811.70", "0.819909"], ["83809.70", "2.157656"], ["83808.50", "0"], ["83767.81", "0.822579"], ["83767.80", "5.451801"], ["83759.40", "5.270074"], ["83751.00", "5.088347"], ["83742.60", "3.997987"], ["83734.20", "4.997484"], ["83725.80", "4.634031"], ["83717.41", "0"], ["83717.40", "5.542664"], ["83709.00", "4.543167"], ["83700.60", "4.361441"], ["83683.80", "4.452304"], ["83675.40", "3.907124"], ["83667.00", "5.360937"], ["83658.60", "5.633527"], ["83650.20", "4.724894"], ["83641.80", "4.270577"], ["83633.40", "5.179211"], ["83625.00", "4.906621"], ["83616.60", "4.815757"], ["83608.20", "4.088851"], ["83577.98", "0.000072"]], "checksum": 230696440, "ts": "1742543258959"}], "ts": 1742543258962, "record_time": 1742543258.948029}
{"action": "update", "arg": {"instType": "SPOT", "channel": "books", "instId": "BTCUSDT"}, "data": [{"asks": [["83868.39", "0.857305"], ["83900.30", "0.015000"], ["83906.40", "0"], ["83935.60", "4.361441"], ["83944.00", "4.543167"], ["83952.40", "4.088851"], ["83960.80", "3.907124"], ["83969.20", "4.452304"], ["83977.60", "4.815757"], ["83986.00", "4.634031"], ["83994.40", "5.270074"], ["84002.80", "5.542664"], ["84011.20", "4.270577"], ["84019.60", "4.906621"], ["84028.00", "5.179211"], ["84036.40", "4.179714"], ["84044.80", "5.633527"], ["84053.20", "3.997987"], ["84061.60", "5.360937"], ["84070.00", "4.997484"], ["84078.40", "5.088347"], ["84086.80", "5.451801"], ["84095.20", "4.724894"]], "bids": [["83859.99", "0.209200"], ["83817.00", "0.000032"], ["83809.70", "2.157786"], ["83805.50", "0.015000"], ["83767.80", "5.179211"], ["83759.40", "4.815757"], ["83751.00", "4.906621"], ["83742.60", "4.724894"], ["83734.20", "4.543167"], ["83725.80", "5.542664"], ["83717.40", "4.452304"], ["83709.00", "3.907124"], ["83700.60", "5.451801"], ["83692.20", "4.634031"], ["83683.80", "3.997987"], ["83675.40", "5.633527"], ["83667.00", "4.361441"], ["83658.60", "5.088347"], ["83650.20", "5.270074"], ["83641.80", "5.360937"], ["83633.40", "4.088851"], ["83625.00", "4.270577"], ["83616.60", "4.179714"], ["83608.20", "4.997484"], ["83578.04", "0"], ["83577.98", "0"]], "checksum": -653508237, "ts": "1742543259167"}], "ts": 1742543259169, "record_time": 1742543259.146062}
{"action": "update", "arg": {"instType": "SPOT", "channel": "books", "instId": "BTCUSDT"}, "data": [{"asks": [["83881.64", "0"], ["83881.70", "0.027235"], ["83883.70", "0.071670"], ["83885.70", "0.188605"], ["83887.70", "0.496329"], ["83889.70", "1.306129"], ["83891.70", "3.437183"], ["83893.70", "9.045217"], ["83903.10", "0.107370"], ["83905.90", "1.013850"], ["83935.60", "4.906621"], ["83944.00", "3.907124"], ["83952.40", "5.360937"], ["83960.80", "5.633527"], ["83969.20", "4.179714"], ["83977.60", "5.179211"], ["83986.00", "4.088851"], ["83994.40", "4.997484"], ["84019.60", "5.088347"], ["84028.00", "5.270074"], ["84036.40", "4.724894"], ["84044.80", "4.815757"], ["84061.60", "4.543167"], ["84070.00", "4.452304"], ["84078.40", "5.451801"], ["84086.80", "4.361441"], ["84095.20", "4.634031"]], "bids": [["83859.77", "0"], ["83825.70", "0.001104"], ["83823.70", "0.002906"], ["83821.70", "0.007647"], ["83819.70", "0.020123"], ["83817.70", "0.052957"], ["83815.70", "0.139361"], ["83813.70", "0.366738"], ["83811.70", "0.965100"], ["83809.70", "2.539737"], ["83767.80", "4.815757"], ["83759.40", "5.088347"], ["83751.00", "4.452304"], ["83742.60", "5.451801"], ["83734.20", "4.361441"], ["83725.80", "4.634031"], ["83717.40", "5.179211"], ["83709.00", "5.633527"], ["83700.60", "3.997987"], ["83692.20", "4.179714"], ["83683.80", "4.088851"], ["83675.40", "5.360937"], ["83667.00", "4.543167"], ["83658.60", "4.270577"], ["83650.20", "4.906621"], ["83641.80", "5.542664"], ["83633.40", "4.724894"], ["83625.00", "4.997484"], ["83616.60", "3.907124"], ["83608.20", "5.270074"], ["83578.04", "0.000096"]], "checksum": 1324251053, "ts": "1742543259378"}], "ts": 1742543259382, "record_time": 1742543259.357406}
{"action": "update", "arg": {"instType": "SPOT", "channel": "books", "instId": "BTCUSDT"}, "data": [{"asks": [["83868.39", "1.086667"], ["83889.70", "1.305995"], ["83890.04", "0.026942"], ["83891.70", "3.436829"], ["83893.70", "9.044287"], ["83894.00", "4.697370"], ["83903.10", "0"], ["83905.90", "1.973850"], ["83935.60", "5.451801"], ["83944.00", "5.542664"], ["83952.40", "4.724894"], ["83960.80", "5.270074"], ["83969.20", "3.997987"], ["83994.40", "4.179714"], ["84002.80", "4.543167"], ["84011.20", "4.906621"], ["84019.60", "5.360937"], ["84028.00", "4.452304"], ["84036.40", "4.270577"], ["84044.80", "5.633527"], ["84053.20", "5.088347"], ["84061.60", "4.815757"], ["84070.00", "4.361441"], ["84078.40", "3.907124"], ["84086.80", "4.997484"]], "bids": [["83868.38", "0.602983"], ["83860.07", "0.044429"], ["83825.70", "0.001458"], ["83825.22", "0.214733"], ["83823.70", "0.003836"], ["83821.70", "0.010094"], ["83819.70", "0.026564"], ["83817.70", "0.069906"], ["83815.70", "0.183961"], ["83813.70", "0.484109"], ["83811.70", "1.273972"], ["83809.70", "3.352557"], ["83802.80", "3.445440"], ["83801.40", "1.350000"], ["83767.81", "0"], ["83767.80", "4.270577"], ["83759.40", "5.451801"], ["83751.00", "4.543167"], ["83742.60", "3.907124"], ["83734.20", "4.179714"], ["83725.80", "4.906621"], ["83717.40", "5.088347"], ["83709.00", "5.542664"], ["83700.60", "4.634031"], ["83692.20", "4.724894"], ["83683.80", "4.997484"], ["83675.40", "5.633527"], ["83667.00", "5.179211"], ["83658.60", "3.997987"], ["83650.20", "4.361441"], ["83641.80", "4.815757"], ["83633.40", "5.360937"], ["83625.00", "4.088851"], ["83616.60", "5.270074"], ["83608.20", "4.452304"], ["83578.11", "0"], ["83578.04", "0"]], "checksum": -1284921095, "ts": "1742543259601"}], "ts": 1742543259605, "record_time": 1742543259.590032}
{"action": "update", "arg": {"instType": "SPOT", "channel": "books", "instId": "BTCUSDT"}, "data": [{"asks": [["83893.70", "9.044101"], ["83903.10", "0.107340"], ["83905.90", "1.013850"], ["83935.60", "3.997987"], ["83944.00", "4.088851"], ["83952.40", "4.997484"], ["83960.80", "5.179211"], ["83969.20", "4.270577"], ["83977.60", "5.360937"], ["83986.00", "4.543167"], ["83994.40", "4.815757"], ["84002.80", "4.906621"], ["84011.20", "4.361441"], ["84019.60", "5.088347"], ["84028.00", "4.724894"], ["84036.40", "5.451801"], ["84044.80", "5.542664"], ["84053.20", "4.634031"], ["84061.60", "4.179714"], ["84070.00", "3.907124"], ["84078.40", "5.633527"], ["84086.80", "5.270074"], ["84095.20", "4.452304"], ["84460.00", "0"]], "bids": [["83819.70", "0.026775"], ["83818.00", "0.000015"], ["83817.70", "0.070461"], ["83815.70", "0.185422"], ["83813.70", "0.487952"], ["83811.70", "1.284086"], ["83809.70", "3.379174"], ["83802.80", "3.087510"], ["83801.40", "0"], ["83767.80", "5.179211"], ["83759.40", "4.088851"], ["83751.01", "0.607846"], ["83751.00", "5.542664"], ["83742.60", "5.088347"], ["83734.20", "5.451801"], ["83725.80", "4.543167"], ["83717.40", "4.361441"], ["83709.00", "3.997987"], ["83700.60", "5.270074"], ["83692.20", "4.270577"], ["83683.80", "4.724894"], ["83675.40", "4.179714"], ["83667.00", "4.997484"], ["83658.60", "4.634031"], ["83650.20", "4.906621"], ["83641.80", "4.452304"], ["83633.40", "3.907124"], ["83625.00", "5.633527"], ["83616.60", "4.815757"], ["83608.20", "5.360937"], ["83578.11", "0.000023"]], "checksum": -1284921095, "ts": "1742543259803"}], "ts": 1742543259806, "record_time": 1742543259.780437}
{"action": "update", "arg": {"instType": "SPOT", "channel": "books", "instId": "BTCUSDT"}, "data": [{"asks": [["83935.60", "5.451801"], ["83944.00", "4.634031"], ["83960.80", "4.906621"], ["83969.20", "3.997987"], ["83977.60", "5.633527"], ["83986.00", "3.907124"], ["83994.40", "4.088851"], ["84002.80", "5.179211"], ["84019.60", "4.179714"], ["84028.00", "4.543167"], ["84036.40", "4.724894"], ["84044.80", "5.088347"], ["84053.20", "4.815757"], ["84061.60", "5.270074"], ["84070.00", "5.360937"], ["84078.40", "4.270577"], ["84086.80", "4.452304"], ["84095.20", "5.542664"]], "bids": [["83860.35", "0.044429"], ["83860.07", "0"], ["83819.70", "0.026565"], ["83818.00", "0"], ["83817.70", "0.069793"], ["83815.70", "0.183664"], ["83813.70", "0.483328"], ["83811.70", "1.271915"], ["83809.70", "3.347144"], ["83805.50", "0"], ["83767.80", "4.088851"], ["83759.40", "3.997987"], ["83751.00", "5.360937"], ["83742.60", "3.907124"], ["83734.20", "4.724894"], ["83725.80", "5.270074"], ["83717.40", "4.543167"], ["83709.00", "5.451801"], ["83700.60", "4.997484"], ["83692.20", "5.088347"], ["83683.80", "4.270577"], ["83675.40", "4.361441"], ["83667.00", "4.452304"], ["83650.20", "4.815757"], ["83641.80", "5.542664"], ["83633.40", "4.179714"], ["83625.00", "4.906621"], ["83616.60", "5.179211"], ["83608.20", "5.633527"], ["83578.04", "0.000096"], ["83577.98", "0.000072"]], "checksum": -1954636963, "ts": "1742543260003"}], "ts": 1742543260005, "record_time": 1742543260.005004}
{"action": "update", "arg": {"instType": "SPOT", "channel": "books", "instId": "BTCUSDT"}, "data": [{"asks": [["83868.39", "1.068967"], ["83887.70", "0.496091"], ["83889.70", "1.305504"], ["83891.70", "3.435536"], ["83893.70", "9.040883"], ["83903.10", "0"], ["83905.90", "1.973850"], ["83935.60", "4.634031"], ["83944.00", "5.360937"], ["83952.40", "4.724894"], ["83960.80", "4.179714"], ["83969.20", "5.270074"], ["83977.60", "4.270577"], ["83986.00", "4.906621"], ["83994.40", "5.633527"], ["84002.80", "5.542664"], ["84011.20", "5.088347"], ["84019.60", "3.907124"], ["84028.00", "4.088851"], ["84036.40", "4.543167"], ["84044.80", "4.997484"], ["84061.60", "3.997987"], ["84070.00", "5.179211"], ["84078.40", "5.451801"], ["84086.80", "4.361441"], ["84095.20", "4.452304"], ["84460.00", "0.000086"]], "bids": [["83823.70", "0.004049"], ["83821.70", "0.010654"], ["83819.70", "0.028038"], ["83817.70", "0.073783"], ["83815.70", "0.194167"], ["83813.70", "0.510965"], ["83811.70", "1.344645"], ["83809.70", "3.538538"], ["83767.80", "4.270577"], ["83759.40", "5.451801"], ["83751.00", "4.815757"], ["83742.60", "5.270074"], ["83734.20", "5.542664"], ["83725.80", "4.361441"], ["83717.40", "4.179714"], ["83709.00", "4.088851"], ["83700.60", "3.997987"], ["83692.20", "5.360937"], ["83683.80", "5.179211"], ["83675.40", "4.906621"], ["83667.00", "4.997484"], ["83658.60", "5.088347"], ["83650.20", "4.724894"], ["83641.80", "4.452304"], ["83633.40", "4.543167"], ["83625.00", "4.634031"], ["83620.90", "0"], ["83616.60", "3.907124"], ["83614.90", "0.198493"], ["83577.78", "0.000025"]], "checksum": 743113907, "ts": "1742543260208"}], "ts": 1742543260212, "record_time": 1742543260.187063}
{"action": "update", "arg": {"instType": "SPOT", "channel": "books", "instId": "BTCUSDT"}, "data": [{"asks": [["83868.39", "1.069137"], ["83881.70", "0.027222"], ["83883.70", "0.071636"], ["83885.70", "0.188517"], ["83887.70", "0.496095"], ["83889.70", "1.305514"], ["83891.70", "3.435564"], ["83893.70", "9.040958"], ["83935.60", "4.906621"], ["83944.00", "3.997987"], ["83952.40", "4.270577"], ["83960.80", "4.997484"], ["83969.20", "5.088347"], ["83977.60", "4.088851"], ["83986.00", "4.179714"], ["83994.40", "5.360937"], ["84002.80", "5.451801"], ["84011.20", "4.452304"], ["84019.60", "4.815757"], ["84028.00", "4.361441"], ["84036.40", "5.179211"], ["84044.80", "3.907124"], ["84053.20", "4.543167"], ["84061.60", "4.634031"], ["84070.00", "4.724894"], ["84078.40", "5.542664"], ["84086.80", "5.270074"], ["84095.20", "5.633527"]], "bids": [["83860.62", "0"], ["83860.35", "0"], ["83823.70", "0.004018"], ["83821.70", "0.010572"], ["83819.70", "0.027823"], ["83817.70", "0.073216"], ["83816.00", "0.000017"], ["83815.70", "0.192676"], ["83813.70", "0.507041"], ["83811.70", "1.334318"], ["83809.70", "3.511364"], ["83805.90", "0.068070"], ["83767.80", "4.906621"], ["83759.40", "3.907124"], ["83751.00", "4.270577"], ["83742.60", "5.542664"], ["83734.20", "5.270074"], ["83717.40", "4.815757"], ["83709.00", "4.634031"], ["83700.60", "4.452304"], ["83692.20", "4.179714"], ["83683.80", "4.088851"], ["83675.40", "4.543167"], ["83667.00", "5.633527"], ["83658.60", "5.360937"], ["83650.20", "5.451801"], ["83641.80", "3.997987"], ["83633.40", "4.724894"], ["83625.00", "5.088347"], ["83616.60", "5.179211"], ["83608.20", "4.997484"], ["83577.76", "0.000483"]], "checksum": -503954, "ts": "1742543260410"}], "ts": 1742543260414, "record_time": 1742543260.395563}
{"action": "update", "arg": {"instType": "SPOT", "channel": "books", "instId": "BTCUSDT"}, "data": [{"asks": [["83868.39", "1.068943"], ["83868.40", "0.000150"], ["83868.80", "0"], ["83873.01", "0.444692"], ["83875.70", "0.001040"], ["83877.70", "0.001652"], ["83879.70", "0.004348"], ["83881.70", "0.011441"], ["83883.70", "0.030109"], ["83885.70", "0.079234"], ["83887.70", "0.208510"], ["83889.70", "0.548712"], ["83890.04", "0"], ["83891.59", "0.028238"], ["83891.70", "1.443978"], ["83893.70", "3.799943"], ["83893.80", "1.366380"], ["83893.90", "0.001009"], ["83894.00", "0.001026"], ["83896.20", "0"], ["83896.50", "0.693990"], ["83897.10", "0"], ["83899.80", "0"], ["83900.30", "0.026942"], ["83904.90", "0.154020"], ["83905.70", "0"], ["83906.40", "0.672000"], ["83906.80", "0.143100"], ["83935.60", "4.361441"], ["83944.00", "5.633527"], ["83952.40", "4.815757"], ["83960.80", "4.270577"], ["83969.20", "4.634031"], ["83977.60", "4.179714"], ["83986.00", "4.724894"], ["83994.40", "5.270074"], ["84002.80", "5.088347"], ["84011.20", "4.997484"], ["84019.60", "4.088851"], ["84028.00", "5.542664"], ["84036.40", "4.543167"], ["84053.20", "4.906621"], ["84061.60", "5.451801"], ["84070.00", "5.179211"], ["84078.40", "4.452304"], ["84086.80", "5.360937"], ["84095.20", "3.997987"], ["84460.23", "0.000010"]], "bids": [["83868.38", "0.658086"], ["83867.03", "0.011219"], ["83825.70", "0.002373"], ["83825.21", "0"], ["83823.70", "0.006243"], ["83823.14", "0.007237"], ["83822.38", "0.715799"], ["83821.70", "0.016431"], ["83819.70", "0.043239"], ["83817.70", "0.113786"], ["83816.00", "0.000032"], ["83815.70", "0.299438"], ["83813.70", "0.787993"], ["83811.70", "2.073666"], ["83809.70", "5.457017"], ["83809.40", "0.186900"], ["83809.20", "0"], ["83808.00", "0.116610"], ["83806.90", "0.167100"], ["83806.10", "0"], ["83803.70", "0"], ["83802.80", "0.724470"], ["83801.40", "1.350000"], ["83800.90", "0"], ["83800.00", "0.071550"], ["83799.60", "0"], ["83799.20", "2.149350"], ["83797.50", "0.500730"], ["83797.10", "0.269760"], ["83767.80", "4.270577"], ["83751.00", "5.179211"], ["83742.60", "4.361441"], ["83734.20", "4.452304"], ["83725.80", "4.906621"], ["83717.40", "5.270074"], ["83709.00", "4.543167"], ["83700.60", "3.997987"], ["83698.85", "0"], ["83683.80", "4.815757"], ["83675.40", "5.542664"], ["83667.00", "5.088347"], ["83658.60", "4.997484"], ["83641.80", "5.360937"], ["83633.40", "4.088851"], ["83625.00", "4.634031"], ["83616.60", "5.633527"], ["83608.20", "4.724894"], ["83577.73", "0.000200"]], "checksum": -1088699005, "ts": "1742543260611"}], "ts": 1742543260615, "record_time": 1742543260.594129}
{"action": "update", "arg": {"instType": "SPOT", "channel": "books", "instId": "BTCUSDT"}, "data": [{"asks": [["83868.39", "1.058943"], ["83873.00", "0.410672"], ["83873.01", "0.430681"], ["83893.80", "0.001034"], ["83894.00", "0"], ["83894.20", "0.006240"], ["83894.80", "0.683430"], ["83896.50", "0.257220"], ["83904.30", "0.468360"], ["83905.20", "0.326070"], ["83906.40", "0.004320"], ["83906.80", "0"], ["83935.60", "5.088347"], ["83944.00", "5.179211"], ["83952.40", "4.088851"], ["83960.80", "4.997484"], ["83969.20", "5.542664"], ["83977.60", "4.634031"], ["83986.00", "4.815757"], ["83994.40", "4.906621"], ["84002.80", "4.452304"], ["84011.20", "4.179714"], ["84019.60", "5.270074"], ["84028.00", "4.543167"], ["84036.40", "4.361441"], ["84044.80", "5.360937"], ["84053.20", "5.451801"], ["84061.60", "3.997987"], ["84070.00", "5.633527"], ["84078.40", "4.270577"], ["84086.80", "3.907124"], ["84095.20", "4.724894"], ["84460.23", "0"]], "bids": [["83862.10", "0.523153"], ["83825.70", "0.002707"], ["83825.22", "0"], ["83823.70", "0.007124"], ["83821.70", "0.018748"], ["83819.70", "0.049335"], ["83817.70", "0.129829"], ["83815.70", "0.341657"], ["83813.70", "0.899095"], ["83811.70", "2.366042"], ["83809.70", "6.226424"], ["83807.40", "2.362500"], ["83802.81", "0.846967"], ["83802.80", "0.442140"], ["83799.90", "1.001460"], ["83798.00", "0.120000"], ["83797.50", "1.038210"], ["83767.80", "4.906621"], ["83751.01", "0.085140"], ["83751.00", "5.270074"], ["83742.60", "5.542664"], ["83725.80", "4.997484"], ["83717.40", "4.361441"], ["83709.00", "5.088347"], ["83700.60", "4.634031"], ["83692.20", "3.997987"], ["83683.80", "5.633527"], ["83675.40", "4.270577"], ["83667.00", "5.451801"], ["83658.60", "4.088851"], ["83650.20", "5.360937"], ["83641.80", "4.724894"], ["83633.40", "4.815757"], ["83625.00", "4.179714"], ["83616.60", "5.179211"], ["83611.60", "0"], ["83611.10", "0.000948"], ["83608.20", "4.543167"], ["83577.73", "0"]], "checksum": 1826091895, "ts": "1742543260813"}], "ts": 1742543260819, "record_time": 1742543260.801003}
{"action": "update", "arg": {"instType": "SPOT", "channel": "books", "instId": "BTCUSDT"}, "data": [{"asks": [["83868.39", "1.072468"], ["83906.40", "0"], ["83935.60", "5.542664"], ["83944.00", "4.088851"], ["83952.40", "4.179714"], ["83960.80", "4.906621"], ["83969.20", "5.179211"], ["83977.60", "5.360937"], ["83986.00", "4.361441"], ["83994.40", "4.815757"], ["84002.80", "3.907124"], ["84011.20", "4.634031"], ["84019.60", "4.997484"], ["84028.00", "4.452304"], ["84036.40", "3.997987"], ["84044.80", "5.633527"], ["84053.20", "4.270577"], ["84061.60", "5.088347"], ["84070.00", "5.451801"], ["84078.40", "4.724894"], ["84086.80", "4.543167"], ["84095.20", "5.270074"], ["84460.23", "0.000010"]], "bids": [["83860.92", "0.044429"], ["83817.00", "0.000015"], ["83802.81", "0"], ["83799.21", "0.290148"], ["83797.40", "0.299010"], ["83797.10", "0"], ["83767.80", "4.361441"], ["83759.40", "5.179211"], ["83751.00", "4.543167"], ["83742.60", "4.270577"], ["83734.20", "3.997987"], ["83725.80", "5.270074"], ["83717.40", "4.997484"], ["83709.00", "4.452304"], ["83700.60", "5.451801"], ["83692.20", "4.634031"], ["83683.80", "5.542664"], ["83675.40", "3.907124"], ["83667.00", "4.088851"], ["83658.60", "4.906621"], ["83650.20", "4.815757"], ["83641.80", "5.633527"], ["83633.40", "4.724894"], ["83625.00", "5.360937"], ["83616.60", "4.179714"], ["83608.20", "5.088347"]], "checksum": -1693445164, "ts": "1742543261018"}], "ts": 1742543261022, "record_time": 1742543261.044246}
{"action": "update", "arg": {"instType": "SPOT", "channel": "books", "instId": "BTCUSDT"}, "data": [{"asks": [["83883.39", "0"], ["83893.80", "0.005610"], ["83894.20", "0.006030"], ["83902.00", "0.145020"], ["83903.70", "0.107370"], ["83904.90", "0.009000"], ["83905.90", "0"], ["83935.60", "5.179211"], ["83944.00", "4.724894"], ["83960.80", "5.633527"], ["83969.20", "4.997484"], ["83977.60", "4.815757"], ["83986.00", "4.270577"], ["83994.40", "4.452304"], ["84002.80", "5.270074"], ["84011.20", "3.907124"], ["84019.60", "4.088851"], ["84028.00", "4.361441"], ["84036.40", "5.360937"], ["84044.80", "5.451801"], ["84053.20", "4.634031"], ["84061.60", "4.543167"], ["84070.00", "3.997987"], ["84078.40", "5.088347"], ["84086.80", "4.906621"], ["84095.20", "5.542664"]], "bids": [["83825.70", "0.002829"], ["83823.70", "0.007446"], ["83821.70", "0.019594"], ["83819.70", "0.051564"], ["83817.70", "0.135693"], ["83815.70", "0.357087"], ["83813.70", "0.939703"], ["83811.70", "2.472902"], ["83809.70", "6.507638"], ["83803.40", "0.069930"], ["83797.20", "0"], ["83767.81", "0.976354"], ["83767.80", "4.088851"], ["83759.40", "5.360937"], ["83742.60", "5.179211"], ["83734.20", "5.633527"], ["83725.80", "4.815757"], ["83717.40", "5.270074"], ["83709.00", "4.361441"], ["83700.60", "4.724894"], ["83692.20", "4.179714"], ["83675.40", "4.997484"], ["83667.00", "5.088347"], ["83658.60", "3.907124"], ["83650.20", "4.270577"], ["83641.80", "4.634031"], ["83633.40", "4.452304"], ["83625.00", "5.451801"], ["83616.60", "3.997987"], ["83608.20", "4.906621"], ["83577.76", "0"]], "checksum": -158529902, "ts": "1742543261217"}], "ts": 1742543261221, "record_time": 1742543261.246428}
{"action": "update", "arg": {"instType": "SPOT", "channel": "books", "instId": "BTCUSDT"}, "data": [{"asks": [["83868.39", "1.071750"], ["83868.40", "0"], ["83877.70", "0.001489"], ["83879.70", "0.003920"], ["83881.70", "0.010316"], ["83883.70", "0.027145"], ["83885.70", "0.071435"], ["83887.70", "0.187987"], ["83889.70", "0.494702"], ["83891.70", "1.301848"], ["83893.70", "3.425915"], ["83893.80", "0.013170"], ["83896.00", "0.112530"], ["83897.30", "0"], ["83897.60", "0"], ["83898.60", "0"], ["83900.00", "0.030000"], ["83900.20", "0.015000"], ["83900.30", "0.045000"], ["83900.50", "0.021810"], ["83905.50", "0"], ["83913.68", "0"], ["83915.72", "0"], ["83935.60", "4.270577"], ["83944.00", "5.451801"], ["83952.40", "5.088347"], ["83960.80", "5.270074"], ["83969.20", "4.634031"], ["83977.60", "3.997987"], ["83986.00", "4.452304"], ["83994.40", "5.360937"], ["84002.80", "3.907124"], ["84011.20", "4.997484"], ["84019.60", "4.815757"], ["84028.00", "4.543167"], ["84036.40", "4.906621"], ["84044.80", "4.088851"], ["84053.20", "5.542664"], ["84061.60", "5.633527"], ["84070.00", "5.179211"], ["84078.40", "4.361441"], ["84086.80", "4.724894"], ["84095.20", "4.179714"], ["84460.49", "0.000009"], ["84460.87", "0.000069"], ["84460.91", "0.000012"], ["84461.00", "0.000008"], ["84462.50", "0.000076"], ["84464.28", "0.000008"]], "bids": [["83860.92", "0"], ["83825.69", "0.010000"], ["83822.94", "0"], ["83817.00", "0"], ["83809.50", "2.363490"], ["83809.40", "0.186690"], ["83809.30", "0"], ["83808.00", "0.116400"], ["83807.40", "0"], ["83803.66", "0"], ["83801.84", "0"], ["83767.80", "4.452304"], ["83759.40", "5.633527"], ["83751.00", "5.088347"], ["83742.60", "4.179714"], ["83734.20", "4.724894"], ["83725.80", "5.360937"], ["83717.40", "3.907124"], ["83709.00", "3.997987"], ["83700.60", "5.179211"], ["83692.20", "4.361441"], ["83683.80", "4.634031"], ["83675.40", "5.542664"], ["83667.00", "4.997484"], ["83658.60", "4.270577"], ["83650.20", "4.088851"], ["83641.80", "4.543167"], ["83633.40", "5.270074"], ["83616.60", "4.815757"], ["83577.76", "0.000483"], ["83577.73", "0.000200"], ["83577.41", "0.000034"], ["83576.47", "0.000071"], ["83575.00", "0.001544"]], "checksum": 1707049165, "ts": "1742543261417"}], "ts": 1742543261421, "record_time": 1742543261.395155}
{"action": "update", "arg": {"instType": "SPOT", "channel": "books", "instId": "BTCUSDT"}, "data": [{"asks": [["83868.39", "0.653188"], ["83873.00", "0"], ["83877.70", "0.001025"], ["83879.70", "0.001768"], ["83881.70", "0.004654"], ["83883.70", "0.012247"], ["83885.70", "0.032228"], ["83887.70", "0.084810"], ["83889.70", "0.223185"], ["83891.70", "0.587330"], ["83893.70", "1.545604"], ["83893.80", "0.030090"], ["83894.80", "0.505830"], ["83900.30", "0.030000"], ["83900.40", "0"], ["83902.10", "0"], ["83903.70", "0"], ["83905.50", "0.516000"], ["83905.90", "1.973850"], ["83906.40", "0.004320"], ["83919.98", "0.001598"], ["83921.85", "0.001597"], ["83935.60", "5.451801"], ["83944.00", "5.088347"], ["83952.40", "5.360937"], ["83960.80", "4.361441"], ["83969.20", "4.270577"], ["83977.60", "4.815757"], ["83994.40", "5.179211"], ["84002.80", "5.542664"], ["84011.20", "3.997987"], ["84019.60", "4.543167"], ["84028.00", "5.633527"], ["84036.40", "4.724894"], ["84044.80", "4.179714"], ["84053.20", "5.270074"], ["84061.60", "3.907124"], ["84070.00", "4.997484"], ["84078.40", "4.088851"], ["84086.80", "4.634031"], ["84095.20", "4.906621"], ["84464.28", "0"]], "bids": [["83868.38", "0.867286"], ["83861.19", "0.044434"], ["83827.70", "0.001130"], ["83827.23", "0.000878"], ["83826.50", "0.045059"], ["83825.70", "0.003031"], ["83823.70", "0.007974"], ["83821.70", "0.020985"], ["83819.70", "0.055225"], ["83818.00", "0.000017"], ["83817.70", "0.145328"], ["83815.70", "0.382443"], ["83813.70", "1.006427"], ["83811.70", "2.648492"], ["83809.95", "0.001178"], ["83809.70", "6.969718"], ["83807.96", "0.001176"], ["83807.80", "0.102330"], ["83797.40", "0"], ["83767.80", "5.360937"], ["83759.40", "4.543167"], ["83751.01", "0"], ["83751.00", "4.724894"], ["83742.60", "5.270074"], ["83734.20", "5.088347"], ["83725.80", "4.452304"], ["83717.40", "4.634031"], ["83709.00", "4.997484"], ["83700.60", "5.542664"], ["83692.20", "4.270577"], ["83683.80", "4.361441"], ["83675.40", "5.451801"], ["83667.00", "5.179211"], ["83658.60", "4.088851"], ["83650.20", "3.907124"], ["83641.80", "4.906621"], ["83633.40", "4.179714"], ["83625.00", "5.633527"], ["83608.20", "3.997987"], ["83577.76", "0"], ["83577.73", "0"], ["83577.41", "0"], ["83576.47", "0"], ["83575.00", "0"]], "checksum": 1118106260, "ts": "1742543261617"}], "ts": 1742543261619, "record_time": 1742543261.596888}
{"action": "update", "arg": {"instType": "SPOT", "channel": "books", "instId": "BTCUSDT"}, "data": [{"asks": [["83868.39", "0.177719"], ["83869.05", "0"], ["83869.07", "0"], ["83873.01", "0.209558"], ["83873.70", "0"], ["83873.83", "0.008055"], ["83873.91", "0.004300"], ["83874.88", "0"], ["83875.70", "0"], ["83876.36", "0.010000"], ["83877.60", "0.001007"], ["83877.70", "0"], ["83879.60", "0.001033"], ["83879.70", "0"], ["83881.15", "0"], ["83881.26", "0"], ["83881.60", "0.001020"], ["83881.70", "0"], ["83882.47", "0"], ["83882.91", "0"], ["83883.19", "0"], ["83883.53", "0"], ["83883.60", "0.001000"], ["83883.70", "0"], ["83883.82", "0"], ["83883.89", "0"], ["83884.36", "0"], ["83884.54", "0"], ["83884.63", "0"], ["83884.92", "0"], ["83885.20", "0"], ["83885.60", "0.001033"], ["83885.70", "0"], ["83885.71", "0"], ["83885.81", "0"], ["83885.85", "0"], ["83886.09", "0"], ["83886.12", "0"], ["83886.39", "0"], ["83886.44", "0"], ["83886.54", "0"], ["83886.56", "0"], ["83887.60", "0.001013"], ["83887.70", "0"], ["83887.92", "0"], ["83888.11", "0"], ["83888.36", "0"], ["83888.39", "0.119869"], ["83888.89", "0"], ["83889.60", "0.001040"], ["83889.66", "0.035972"], ["83889.70", "0"], ["83889.71", "0"], ["83890.19", "0.006357"], ["83890.51", "0.006357"], ["83890.89", "0"], ["83891.00", "0"], ["83891.38", "0"], ["83891.41", "0"], ["83891.52", "0.006357"], ["83891.59", "0"], ["83891.60", "0.001016"], ["83891.70", "0"], ["83891.92", "0.006357"], ["83893.13", "0.006357"], ["83893.31", "0"], ["83893.55", "0.006357"], ["83893.60", "0.001040"], ["83893.65", "0.006357"], ["83893.70", "0"], ["83893.80", "0"], ["83893.90", "0"], ["83894.20", "0"], ["83894.80", "0"], ["83895.15", "0.006357"], ["83895.26", "0"], ["83895.60", "0.001016"], ["83895.83", "0"], ["83896.00", "0"], ["83896.50", "0"], ["83897.60", "0.001711"], ["83897.78", "0.017174"], ["83898.00", "0.001021"], ["83898.10", "0"], ["83898.60", "0.060210"], ["83899.40", "0.001033"], ["83900.00", "0.023837"], ["83900.20", "0"], ["83900.30", "0"], ["83900.40", "0.120000"], ["83900.50", "0.006810"], ["83900.70", "0"], ["83900.90", "0.480000"], ["83901.50", "0.022620"], ["83901.70", "0.049230"], ["83901.92", "0.028238"], ["83902.00", "0"], ["83902.70", "0.038160"], ["83903.60", "0"], ["83903.80", "0"], ["83903.90", "0"], ["83904.10", "0"], ["83904.30", "0"], ["83904.60", "0"], ["83904.70", "0.012510"], ["83904.80", "0"], ["83905.20", "0.045000"], ["83905.50", "0.045000"], ["83905.90", "0.293280"], ["83906.40", "0.101130"], ["83907.40", "0.015000"], ["83907.50", "0.480000"], ["83908.90", "0.081000"], ["83909.00", "0.070440"], ["83909.10", "0.420000"], ["83909.30", "0.071520"], ["83909.50", "0.026940"], ["83909.60", "1.372290"], ["83910.50", "0.516000"], ["83910.90", "0.326190"], ["83911.30", "1.442970"], ["83935.60", "0"], ["83939.50", "4.542959"], ["83944.00", "0"], ["83947.90", "5.360691"], ["83952.40", "0"], ["83956.30", "5.633269"], ["83960.80", "0"], ["83964.70", "4.452100"], ["83969.20", "0"], ["83973.10", "5.542410"], ["83977.60", "0"], ["83981.50", "5.178973"], ["83986.00", "0"], ["83989.90", "4.633818"], ["83994.40", "0"], ["83998.30", "4.906395"], ["84002.80", "0"], ["84006.70", "4.997255"], ["84011.20", "0"], ["84015.10", "4.179522"], ["84019.60", "0"], ["84023.50", "5.269832"], ["84028.00", "0"], ["84031.90", "3.906945"], ["84036.40", "0"], ["84040.30", "4.815536"], ["84044.80", "0"], ["84048.70", "4.724677"], ["84053.20", "0"], ["84057.10", "4.361240"], ["84061.60", "0"], ["84065.50", "4.270381"], ["84070.00", "0"], ["84073.90", "5.088114"], ["84078.40", "0"], ["84082.30", "4.088663"], ["84086.80", "0"], ["84090.70", "3.997804"], ["84095.20", "0"], ["84099.10", "5.451550"], ["84464.28", "0.000008"], ["84465.83", "0.000016"], ["84466.67", "0.000157"], ["84470.34", "0.000017"], ["84470.59", "0.000071"], ["84473.14", "0.000126"], ["84473.68", "0.000192"], ["84474.78", "0.000099"], ["84475.00", "0.007068"], ["84475.81", "0.000039"], ["84476.97", "0.000063"], ["84477.61", "0.000095"], ["84477.67", "0.000008"], ["84478.74", "0.000036"], ["84479.37", "0.000090"], ["84480.00", "0.004066"], ["84481.00", "0.000069"], ["84481.77", "0.000011"], ["84482.67", "0.000133"], ["84482.76", "0.000016"], ["84485.20", "0.000537"], ["84485.39", "0.000020"], ["84485.71", "0.000128"]], "bids": [["83868.38", "1.076486"], ["83859.54", "0.115110"], ["83854.59", "0"], ["83850.41", "0"], ["83850.34", "0"], ["83847.55", "0"], ["83847.49", "0"], ["83847.29", "0.248347"], ["83846.21", "0"], ["83846.12", "0"], ["83846.05", "0.084173"], ["83845.41", "0.018298"], ["83845.05", "0.005961"], ["83844.05", "0.006577"], ["83843.45", "0.007149"], ["83842.64", "0.007962"], ["83842.16", "0.008205"], ["83842.05", "0.017392"], ["83841.68", "0"], ["83841.63", "0"], ["83841.55", "0"], ["83840.74", "0"], ["83840.63", "0.012685"], ["83840.06", "0"], ["83838.86", "0"], ["83838.46", "0"], ["83838.41", "0"], ["83838.08", "0"], ["83837.90", "0"], ["83837.77", "0"], ["83837.08", "0"], ["83837.00", "0.000032"], ["83836.81", "0"], ["83836.45", "0"], ["83836.37", "0"], ["83836.34", "0"], ["83835.90", "0"], ["83835.89", "0"], ["83835.60", "0"], ["83835.33", "0"], ["83835.28", "0"], ["83835.24", "0"], ["83835.05", "0"], ["83834.42", "0"], ["83833.85", "0"], ["83833.60", "0.001049"], ["83832.70", "0"], ["83831.68", "0"], ["83831.60", "0.001266"], ["83830.85", "0"], ["83830.62", "0"], ["83830.50", "0"], ["83830.19", "0"], ["83829.70", "0"], ["83829.60", "0.003332"], ["83828.06", "0"], ["83827.70", "0"], ["83827.60", "0.008767"], ["83826.49", "0"], ["83825.96", "0"], ["83825.70", "0"], ["83825.69", "0"], ["83825.60", "0.023072"], ["83825.38", "0"], ["83823.70", "0"], ["83823.60", "0.060717"], ["83823.13", "0"], ["83822.38", "0"], ["83821.80", "0"], ["83821.70", "0"], ["83821.60", "0.159780"], ["83819.70", "0"], ["83819.60", "0.420475"], ["83819.04", "0.017174"], ["83818.99", "0"], ["83818.94", "0"], ["83817.70", "0"], ["83817.60", "1.106512"], ["83815.70", "0"], ["83815.60", "2.911875"], ["83813.70", "0"], ["83813.60", "7.662828"], ["83813.50", "0.001002"], ["83812.60", "0.001025"], ["83812.40", "1.231050"], ["83812.30", "9.402270"], ["83812.00", "0.084810"], ["83811.90", "1.079040"], ["83811.70", "0"], ["83811.00", "0.145020"], ["83810.80", "0.107280"], ["83810.00", "0.227700"], ["83809.80", "5.647230"], ["83809.70", "1.059390"], ["83809.50", "0"], ["83809.40", "0"], ["83808.10", "0.337830"], ["83808.00", "0.987660"], ["83807.80", "0.107400"], ["83806.90", "0.022080"], ["83805.90", "0"], ["83805.30", "0.473550"], ["83804.70", "2.149350"], ["83804.26", "0"], ["83802.81", "0.574524"], ["83802.80", "1.245930"], ["83800.30", "0.012570"], ["83800.00", "0.000012"], ["83799.90", "0"], ["83799.20", "0"], ["83798.70", "0"], ["83798.00", "0.000353"], ["83797.60", "0"], ["83797.50", "0"], ["83771.70", "4.906395"], ["83767.81", "0.031711"], ["83767.80", "0"], ["83763.30", "4.088663"], ["83759.40", "0"], ["83754.90", "5.451550"], ["83751.00", "0"], ["83746.50", "3.906945"], ["83742.60", "0"], ["83738.10", "5.360691"], ["83734.20", "0"], ["83729.70", "4.452100"], ["83725.80", "0"], ["83721.30", "4.815536"], ["83717.40", "0"], ["83712.90", "5.633269"], ["83709.00", "0"], ["83704.50", "4.179522"], ["83700.60", "0"], ["83696.10", "5.542410"], ["83692.20", "0"], ["83687.70", "5.178973"], ["83683.80", "0"], ["83679.30", "5.088114"], ["83675.40", "0"], ["83670.90", "5.269832"], ["83667.00", "0"], ["83662.50", "4.542959"], ["83658.60", "0"], ["83654.10", "4.270381"], ["83650.20", "0"], ["83645.70", "4.997255"], ["83641.80", "0"], ["83637.30", "4.633818"], ["83633.40", "0.000076"], ["83628.90", "4.361240"], ["83625.00", "0.002507"], ["83620.50", "3.997804"], ["83616.60", "0"], ["83612.10", "4.724677"], ["83608.20", "0"], ["83577.76", "0.000483"], ["83577.73", "0.000200"], ["83577.41", "0.000034"], ["83576.47", "0.000071"], ["83575.00", "0.001544"], ["83574.19", "0.000109"], ["83571.79", "0.000098"], ["83571.43", "0.000330"], ["83571.42", "0.000008"], ["83571.39", "0.000178"], ["83570.62", "0.000016"], ["83570.45", "0.000012"], ["83570.00", "0.000059"], ["83569.08", "0.000093"], ["83568.75", "0.000025"], ["83568.28", "0.000010"], ["83568.00", "0.000050"], ["83567.59", "0.000047"], ["83567.57", "0.000008"], ["83567.40", "0.000046"], ["83567.37", "0.000019"], ["83567.16", "0.000095"], ["83566.29", "0.000894"], ["83566.01", "0.000025"], ["83566.00", "0.000113"], ["83565.96", "0.000058"], ["83565.90", "0.000342"], ["83565.22", "0.000389"], ["83564.59", "0.000013"]], "checksum": 1484413942, "ts": "1742543261820"}], "ts": 1742543261826, "record_time": 1742543261.807105}
{"action": "update", "arg": {"instType": "SPOT", "channel": "books", "instId": "BTCUSDT"}, "data": [{"asks": [["83868.39", "0.164124"], ["83868.40", "0.000100"], ["83868.41", "0.000100"], ["83868.42", "0.000100"], ["83869.77", "0.115184"], ["83869.82", "0.176673"], ["83876.36", "0"], ["83877.60", "0"], ["83879.40", "0.001002"], ["83879.60", "0"], ["83881.40", "0.001009"], ["83881.60", "0"], ["83881.83", "0.013208"], ["83883.40", "0.001041"], ["83883.60", "0"], ["83885.40", "0.001034"], ["83885.60", "0"], ["83886.44", "2.745911"], ["83887.40", "0.001042"], ["83887.60", "0"], ["83888.38", "0.054998"], ["83889.40", "0.001018"], ["83889.60", "0"], ["83891.40", "0.001036"], ["83891.60", "0"], ["83891.90", "0.035953"], ["83892.19", "0"], ["83893.40", "0.001004"], ["83893.60", "0"], ["83893.91", "0.006357"], ["83894.89", "0.006357"], ["83895.00", "0.006357"], ["83895.40", "0.001027"], ["83895.60", "0"], ["83895.61", "0.010995"], ["83895.81", "0.006357"], ["83896.64", "0.006356"], ["83896.68", "0.016429"], ["83896.69", "0.006357"], ["83897.07", "0.006357"], ["83897.37", "0.119883"], ["83897.40", "0.016429"], ["83897.60", "0"], ["83898.00", "0"], ["83898.53", "0.006357"], ["83898.60", "0"], ["83899.08", "0.010994"], ["83899.50", "0.001740"], ["83899.60", "0.001006"], ["83899.86", "0.009990"], ["83899.90", "0.001010"], ["83900.30", "0.001033"], ["83900.40", "0"], ["83900.71", "0.119850"], ["83900.90", "0"], ["83901.05", "0.023107"], ["83901.50", "0"], ["83901.70", "0"], ["83901.71", "0.119858"], ["83901.99", "0.119867"], ["83902.00", "0.570690"], ["83902.10", "0.015895"], ["83902.30", "0.360000"], ["83902.39", "0.009989"], ["83902.60", "0.519960"], ["83903.40", "0.022710"], ["83903.50", "0.075210"], ["83904.17", "0.006356"], ["83904.70", "0.040440"], ["83904.80", "0.038370"], ["83905.20", "0"], ["83905.50", "0"], ["83906.17", "0.015892"], ["83907.06", "0.010988"], ["83907.50", "0"], ["83908.90", "0.960000"], ["83909.00", "0"], ["83909.10", "0"], ["83909.30", "0"], ["83909.50", "0"], ["83909.60", "0.567150"], ["83909.70", "0.045000"], ["83910.00", "0.045000"], ["83910.10", "0.372000"], ["83910.16", "0.026942"], ["83910.50", "0"], ["83910.90", "0"], ["83911.30", "0.092970"], ["83912.00", "1.006320"], ["83912.20", "0.179010"], ["83939.50", "0"], ["83941.40", "4.815428"], ["83947.90", "0"], ["83949.80", "4.179428"], ["83956.30", "0"], ["83958.20", "5.633142"], ["83964.70", "0"], ["83966.60", "4.633714"], ["83973.10", "0"], ["83975.00", "3.906857"], ["83981.50", "0"], ["83983.40", "5.542285"], ["83989.90", "0"], ["83991.80", "4.542856"], ["83998.30", "0"], ["84000.20", "5.178856"], ["84006.70", "0"], ["84008.60", "4.088571"], ["84015.10", "0"], ["84017.00", "4.906285"], ["84023.50", "0"], ["84025.40", "4.270285"], ["84031.90", "0"], ["84033.80", "4.724571"], ["84040.30", "0"], ["84042.20", "5.087999"], ["84048.70", "0"], ["84050.60", "3.997714"], ["84057.10", "0"], ["84059.00", "4.451999"], ["84065.50", "0"], ["84067.40", "5.360570"], ["84073.90", "0"], ["84075.80", "5.451428"], ["84082.30", "0"], ["84084.20", "4.997142"], ["84090.70", "0"], ["84092.60", "5.269713"], ["84099.10", "0"], ["84101.00", "4.361142"], ["84460.87", "0"], ["84460.91", "0"], ["84461.00", "0"], ["84462.50", "0"], ["84464.28", "0"], ["84465.83", "0"], ["84466.67", "0"], ["84470.34", "0"], ["84470.59", "0"], ["84473.14", "0"], ["84473.68", "0"], ["84474.78", "0"], ["84475.00", "0"], ["84475.81", "0"], ["84476.97", "0"], ["84477.61", "0"], ["84477.67", "0"], ["84478.74", "0"], ["84479.37", "0"], ["84480.00", "0"], ["84481.00", "0"], ["84481.77", "0"], ["84482.67", "0"], ["84482.76", "0"], ["84485.20", "0"], ["84485.39", "0"], ["84485.71", "0"]], "bids": [["83868.38", "1.178791"], ["83867.10", "0.044431"], ["83861.19", "0"], ["83854.85", "0.007188"], ["83854.80", "0.008028"], ["83854.74", "0"], ["83853.06", "0.002121"], ["83852.96", "0.001299"], ["83851.98", "0.004026"], ["83851.64", "0.089750"], ["83851.13", "0.002204"], ["83850.66", "0.010359"], ["83850.58", "0.008737"], ["83849.46", "0.017859"], ["83848.76", "0.015766"], ["83848.54", "0.016450"], ["83847.97", "0.055789"], ["83847.67", "0.017144"], ["83847.19", "0.028932"], ["83847.16", "0.007359"], ["83846.87", "0.017130"], ["83846.58", "0.009016"], ["83846.24", "0.025240"], ["83846.21", "0.225405"], ["83846.06", "0.008111"], ["83845.98", "0.004471"], ["83845.02", "0.008296"], ["83844.56", "0.052076"], ["83843.67", "0.018560"], ["83842.67", "0.269000"], ["83841.66", "0.223187"], ["83841.60", "0.260400"], ["83841.21", "0.076289"], ["83841.16", "0.021176"], ["83840.07", "0"], ["83838.92", "0.012467"], ["83838.58", "0"], ["83837.40", "0.073385"], ["83836.61", "0.056498"], ["83835.50", "0.001050"], ["83833.60", "0"], ["83833.50", "0.001154"], ["83831.69", "0"], ["83831.60", "0"], ["83831.50", "0.003165"], ["83830.33", "0.007453"], ["83829.60", "0"], ["83829.50", "0.008554"], ["83828.12", "0.715750"], ["83827.60", "0"], ["83827.55", "0.008593"], ["83827.50", "0.022508"], ["83827.33", "0.003986"], ["83826.50", "0"], ["83825.60", "0"], ["83825.50", "0.059233"], ["83824.47", "0.015023"], ["83824.41", "0.007265"], ["83823.60", "0"], ["83823.50", "0.155875"], ["83821.60", "0"], ["83821.50", "0.410198"], ["83819.60", "0"], ["83819.50", "1.079468"], ["83817.60", "0"], ["83817.50", "2.840707"], ["83815.60", "0"], ["83815.50", "7.475545"], ["83815.30", "3.025800"], ["83815.10", "1.079460"], ["83814.80", "0.001047"], ["83814.70", "2.362500"], ["83814.00", "0.084600"], ["83813.60", "0.464040"], ["83813.50", "0"], ["83813.40", "0.071730"], ["83812.60", "0"], ["83812.40", "0"], ["83812.30", "4.547310"], ["83812.00", "0.084600"], ["83811.40", "0.068040"], ["83811.00", "0"], ["83809.80", "3.857130"], ["83809.70", "0.236130"], ["83808.10", "0"], ["83808.00", "1.988790"], ["83806.00", "0.537480"], ["83804.80", "2.685150"], ["83804.60", "1.034220"], ["83803.50", "4.330800"], ["83803.20", "0.179010"], ["83802.80", "0"], ["83802.40", "0.015570"], ["83801.50", "0"], ["83801.40", "0"], ["83800.30", "0"], ["83799.21", "0"], ["83773.50", "4.815428"], ["83771.70", "0"], ["83767.81", "0"], ["83765.10", "5.269713"], ["83763.30", "0"], ["83756.70", "5.542285"], ["83754.90", "0"], ["83748.30", "5.087999"], ["83746.50", "0"], ["83739.90", "5.633142"], ["83738.10", "0"], ["83731.50", "3.906857"], ["83729.70", "0"], ["83723.10", "4.270285"], ["83721.30", "0"], ["83714.70", "5.360570"], ["83712.90", "0"], ["83706.30", "4.724571"], ["83704.50", "0"], ["83697.90", "4.179428"], ["83696.10", "0"], ["83689.50", "4.088571"], ["83687.70", "0"], ["83681.10", "3.997714"], ["83679.30", "0"], ["83672.70", "5.178856"], ["83670.90", "0"], ["83664.30", "4.451999"], ["83662.50", "0.000077"], ["83655.90", "4.542856"], ["83654.10", "0"], ["83647.50", "4.633714"], ["83645.70", "0"], ["83639.10", "5.451428"], ["83637.30", "0"], ["83630.70", "4.361142"], ["83628.90", "0"], ["83622.30", "4.906285"], ["83620.50", "0"], ["83613.90", "4.997142"], ["83612.10", "0"], ["83578.95", "0"], ["83578.11", "0"], ["83578.04", "0"], ["83577.98", "0"], ["83577.78", "0"], ["83577.76", "0"], ["83577.73", "0"], ["83577.41", "0"], ["83576.47", "0"], ["83575.00", "0"], ["83574.19", "0"], ["83571.79", "0"], ["83571.43", "0"], ["83571.42", "0"], ["83571.39", "0"], ["83570.62", "0"], ["83570.45", "0"], ["83570.00", "0"], ["83569.08", "0"], ["83568.75", "0"], ["83568.28", "0"], ["83568.00", "0"], ["83567.59", "0"], ["83567.57", "0"], ["83567.40", "0"], ["83567.37", "0"], ["83567.16", "0"], ["83566.29", "0"], ["83566.01", "0"], ["83566.00", "0"], ["83565.96", "0"], ["83565.90", "0"], ["83565.22", "0"], ["83564.59", "0"]], "checksum": 577152778, "ts": "1742543262022"}], "ts": 1742543262041, "record_time": 1742543262.086597}
{"action": "update", "arg": {"instType": "SPOT", "channel": "books", "instId": "BTCUSDT"}, "data": [{"asks": [["83868.39", "0.084836"], ["83868.75", "0.079994"], ["83869.04", "0.008433"], ["83869.05", "0.016104"], ["83869.07", "0.024848"], ["83869.08", "0.017532"], ["83869.11", "0.006612"], ["83869.12", "0.016091"], ["83869.13", "0.009221"], ["83869.14", "0.013995"], ["83869.17", "0.005060"], ["83869.18", "0.008249"], ["83869.20", "0.009594"], ["83879.39", "0.013695"], ["83879.40", "0"], ["83881.10", "0.001003"], ["83881.40", "0"], ["83883.10", "0.001009"], ["83883.40", "0"], ["83885.10", "0.001043"], ["83885.40", "0"], ["83886.43", "0.410672"], ["83887.10", "0.001007"], ["83887.40", "0"], ["83889.10", "0.001190"], ["83889.40", "0"], ["83891.10", "0.003132"], ["83891.40", "0"], ["83893.10", "0.008242"], ["83893.40", "0"], ["83895.10", "0.021688"], ["83895.40", "0"], ["83897.10", "0.057074"], ["83899.10", "0.150195"], ["83899.40", "0"], ["83899.50", "0"], ["83899.60", "0"], ["83899.90", "0"], ["83900.30", "0"], ["83900.50", "0"], ["83901.10", "0.395250"], ["83901.40", "0.002670"], ["83902.00", "0.486060"], ["83902.30", "0.360630"], ["83902.60", "0"], ["83902.70", "0.078930"], ["83903.50", "0"], ["83905.10", "0.075180"], ["83906.30", "0.006630"], ["83907.20", "0.110850"], ["83907.50", "2.362050"], ["83909.50", "1.350000"], ["83913.20", "0.143100"], ["83913.40", "0.537480"], ["83913.60", "2.449980"], ["83941.40", "0"], ["83943.00", "5.542177"], ["83949.80", "0"], ["83951.40", "4.633623"], ["83958.20", "0"], ["83959.80", "5.360466"], ["83966.60", "0"], ["83968.20", "5.087900"], ["83975.00", "0"], ["83976.60", "3.997636"], ["83983.40", "0"], ["83985.00", "4.724479"], ["83991.80", "0"], ["83993.40", "5.451322"], ["84000.20", "0"], ["84001.80", "3.906781"], ["84008.60", "0"], ["84010.20", "4.815334"], ["84017.00", "0"], ["84018.60", "4.361057"], ["84025.40", "0"], ["84027.00", "4.088491"], ["84033.80", "0"], ["84035.40", "4.542768"], ["84042.20", "0"], ["84043.80", "4.906190"], ["84050.60", "0"], ["84052.20", "4.451913"], ["84059.00", "0"], ["84060.60", "5.269611"], ["84067.40", "0"], ["84069.00", "4.270202"], ["84075.80", "0.200966"], ["84077.40", "5.633032"], ["84084.20", "0"], ["84085.80", "5.178756"], ["84092.60", "0"], ["84094.20", "4.179347"], ["84101.00", "0"], ["84102.60", "4.997045"], ["84454.55", "0"], ["84454.60", "0"], ["84455.31", "0"], ["84456.14", "0"], ["84456.52", "0"], ["84457.00", "0"], ["84458.06", "0"], ["84458.72", "0"], ["84458.82", "0"], ["84458.97", "0"], ["84459.08", "0"], ["84459.22", "0"], ["84459.69", "0"], ["84460.00", "0"], ["84460.23", "0"], ["84460.49", "0"]], "bids": [["83867.11", "0.024548"], ["83867.03", "0"], ["83851.12", "0"], ["83837.10", "0.001016"], ["83835.50", "0"], ["83835.10", "0.001356"], ["83833.50", "0"], ["83833.10", "0.003567"], ["83831.50", "0"], ["83831.10", "0.009387"], ["83829.50", "0"], ["83829.10", "0.024703"], ["83827.50", "0"], ["83827.10", "0.065009"], ["83825.50", "0"], ["83825.10", "0.171077"], ["83823.50", "0"], ["83823.10", "0.450201"], ["83821.50", "0"], ["83821.10", "1.184740"], ["83819.50", "0"], ["83819.10", "3.117737"], ["83818.00", "0.000032"], ["83817.50", "0"], ["83817.10", "8.204572"], ["83816.80", "0.001046"], ["83816.60", "0.001039"], ["83816.50", "0.001011"], ["83816.40", "0.143520"], ["83816.10", "0.001018"], ["83816.00", "0.084810"], ["83815.60", "1.230210"], ["83815.50", "11.307660"], ["83815.30", "0.145020"], ["83815.10", "0"], ["83814.80", "0"], ["83814.70", "0"], ["83813.10", "0.068040"], ["83811.40", "0"], ["83811.00", "0.006810"], ["83806.60", "0.123570"], ["83805.60", "0.120000"], ["83805.20", "0"], ["83804.90", "0.120000"], ["83804.70", "2.161980"], ["83803.60", "0"], ["83803.50", "0"], ["83803.40", "0"], ["83803.20", "0"], ["83802.81", "0.007577"], ["83802.40", "0"], ["83775.20", "4.270202"], ["83773.50", "0"], ["83766.80", "3.997636"], ["83765.10", "0"], ["83758.40", "5.269611"], ["83756.70", "0"], ["83750.00", "4.633623"], ["83748.30", "0"], ["83741.60", "4.542768"], ["83739.90", "0"], ["83733.20", "5.542177"], ["83731.50", "0"], ["83724.80", "4.724479"], ["83723.10", "0"], ["83716.40", "5.087900"], ["83714.70", "0"], ["83708.00", "4.815334"], ["83706.30", "0"], ["83699.60", "5.360466"], ["83697.90", "0"], ["83691.20", "4.451913"], ["83689.50", "0.000113"], ["83682.80", "4.906190"], ["83681.10", "0"], ["83674.40", "3.906781"], ["83672.70", "0"], ["83666.00", "5.451322"], ["83664.30", "0"], ["83657.60", "4.088491"], ["83655.90", "0"], ["83649.20", "5.178756"], ["83647.50", "0"], ["83640.80", "5.633032"], ["83639.10", "0"], ["83632.40", "4.179347"], ["83630.70", "0"], ["83624.00", "4.361057"], ["83622.30", "0"], ["83615.60", "4.997045"], ["83613.90", "0"]], "checksum": -1743447337, "ts": "1742543262222"}], "ts": 1742543262227, "record_time": 1742543262.284168}
{"action": "update", "arg": {"instType": "SPOT", "channel": "books", "instId": "BTCUSDT"}, "data": [{"asks": [["83869.01", "0.008907"], ["83869.06", "0.008603"], ["83869.08", "0.024022"], ["83869.12", "0.023867"], ["83869.13", "0.011409"], ["83869.14", "0.021458"], ["83869.17", "0.014789"], ["83869.20", "0.014722"], ["83869.21", "0.008555"], ["83869.22", "0.004837"], ["83888.39", "0"], ["83889.10", "0.001010"], ["83891.10", "0.001016"], ["83893.06", "0.119869"], ["83893.10", "0.001954"], ["83895.10", "0.005143"], ["83897.10", "0.013534"], ["83899.10", "0.035616"], ["83901.10", "0.093725"], ["83901.60", "0.006240"], ["83902.30", "0.360000"], ["83903.40", "0"], ["83905.00", "0.022680"], ["83905.90", "1.031340"], ["83909.50", "2.322210"], ["83909.60", "0"], ["83911.90", "0.145020"], ["83913.40", "0.209200"], ["83913.60", "0"], ["83943.00", "4.088491"], ["83951.40", "5.542177"], ["83959.80", "5.178756"], ["83968.20", "3.906781"], ["83976.60", "4.270202"], ["83985.00", "5.451322"], ["83993.40", "4.179347"], ["84001.80", "3.997636"], ["84010.20", "4.361057"], ["84018.60", "5.087900"], ["84027.00", "5.269611"], ["84035.40", "5.360466"], ["84043.80", "4.724479"], ["84052.20", "4.633623"], ["84060.60", "5.633032"], ["84069.00", "4.542768"], ["84077.40", "4.997045"], ["84085.80", "4.451913"], ["84094.20", "4.815334"], ["84102.60", "4.906190"], ["84452.66", "0"], ["84453.76", "0"], ["84454.43", "0"], ["84454.53", "0"]], "bids": [["83856.59", "0.007316"], ["83854.86", "0.004565"], ["83851.96", "0.248347"], ["83847.29", "0"], ["83835.10", "0.001673"], ["83833.10", "0.004404"], ["83831.10", "0.011589"], ["83829.10", "0.030498"], ["83827.10", "0.080257"], ["83825.10", "0.211405"], ["83823.10", "0.556329"], ["83821.10", "1.464025"], ["83819.10", "3.852696"], ["83817.10", "10.138674"], ["83816.10", "0"], ["83816.00", "0.084793"], ["83815.60", "0"], ["83815.50", "8.749470"], ["83809.70", "0.187140"], ["83803.60", "0.143100"], ["83802.81", "0"], ["83775.20", "5.178756"], ["83766.80", "5.360466"], ["83758.40", "5.087900"], ["83750.00", "5.633032"], ["83733.20", "5.269611"], ["83724.80", "3.997636"], ["83716.40", "4.997045"], ["83708.00", "4.451913"], ["83699.60", "5.451322"], ["83691.20", "4.633623"], ["83682.80", "3.906781"], ["83674.40", "4.724479"], ["83666.00", "4.815334"], ["83657.60", "4.906190"], ["83649.20", "5.542177"], ["83640.80", "4.270202"], ["83632.40", "4.088491"], ["83624.00", "4.179347"], ["83615.60", "4.361057"]], "checksum": 296051086, "ts": "1742543262426"}], "ts": 1742543262430, "record_time": 1742543262.408081}
{"action": "update", "arg": {"instType": "SPOT", "channel": "books", "instId": "BTCUSDT"}, "data": [{"asks": [["83868.75", "0"], ["83881.10", "0"], ["83881.40", "0.001043"], ["83883.10", "0"], ["83883.40", "0.001012"], ["83885.10", "0"], ["83885.40", "0.001011"], ["83887.10", "0"], ["83887.40", "0.001015"], ["83888.38", "0"], ["83889.10", "0"], ["83889.40", "0.001025"], ["83891.10", "0"], ["83891.40", "0.001019"], ["83893.10", "0"], ["83893.40", "0.002130"], ["83895.10", "0"], ["83895.40", "0.005605"], ["83897.10", "0"], ["83899.10", "0"], ["83899.40", "0.038818"], ["83901.10", "0"], ["83901.40", "0.102151"], ["83901.60", "0.001019"], ["83902.00", "0.388950"], ["83902.30", "0.240630"], ["83903.30", "0.070440"], ["83903.90", "0.480000"], ["83904.50", "0.471870"], ["83904.70", "0.012510"], ["83908.90", "0"], ["83909.50", "0.972210"], ["83910.50", "0.480000"], ["83913.20", "0"], ["83943.00", "0"], ["83943.30", "5.269592"], ["83951.40", "0"], ["83951.70", "4.451897"], ["83959.80", "0"], ["83960.10", "5.360447"], ["83968.20", "0"], ["83968.50", "4.270187"], ["83976.60", "0"], ["83976.90", "4.542752"], ["83985.00", "0"], ["83985.30", "4.179332"], ["83993.40", "0"], ["83993.70", "5.633012"], ["84001.80", "0"], ["84002.10", "5.451302"], ["84010.20", "0"], ["84010.50", "4.997027"], ["84018.60", "0"], ["84018.90", "4.088477"], ["84027.00", "0"], ["84027.30", "4.361042"], ["84035.40", "0"], ["84035.70", "3.906767"], ["84043.80", "0"], ["84044.10", "3.997622"], ["84052.20", "0"], ["84052.50", "4.633607"], ["84060.60", "0"], ["84060.90", "4.724462"], ["84069.00", "0"], ["84069.30", "5.087882"], ["84077.40", "0"], ["84077.70", "4.906172"], ["84085.80", "0"], ["84086.10", "5.178737"], ["84094.20", "0"], ["84094.50", "5.542157"], ["84102.60", "0"], ["84102.90", "4.815317"], ["84452.66", "0.000009"], ["84453.76", "0.000054"]], "bids": [["83868.38", "1.223221"], ["83867.10", "0"], ["83851.97", "0.107168"], ["83851.13", "0"], ["83837.52", "0.010000"], ["83837.10", "0"], ["83835.40", "0.001043"], ["83835.10", "0"], ["83833.40", "0.002514"], ["83833.10", "0"], ["83831.40", "0.006617"], ["83831.10", "0"], ["83829.40", "0.017411"], ["83829.10", "0"], ["83827.40", "0.045820"], ["83827.10", "0"], ["83825.40", "0.120578"], ["83825.10", "0"], ["83823.40", "0.317312"], ["83823.10", "0"], ["83821.40", "0.835030"], ["83821.10", "0"], ["83819.40", "2.197448"], ["83819.10", "0"], ["83817.40", "5.782759"], ["83817.30", "1.230420"], ["83817.10", "6.753750"], ["83816.60", "0"], ["83816.50", "0"], ["83816.40", "0.143310"], ["83816.00", "0.084600"], ["83815.50", "2.539350"], ["83809.70", "0.186690"], ["83806.60", "0.120000"], ["83803.60", "0"], ["83775.50", "4.542752"], ["83775.20", "0"], ["83767.10", "4.088477"], ["83766.80", "0"], ["83758.70", "4.815317"], ["83758.40", "0"], ["83750.30", "3.906767"], ["83750.00", "0.209200"], ["83741.90", "5.087882"], ["83741.60", "0"], ["83733.50", "5.360447"], ["83733.20", "0"], ["83725.10", "4.997027"], ["83724.80", "0"], ["83716.70", "3.997622"], ["83716.40", "0"], ["83708.30", "4.724462"], ["83708.00", "0"], ["83699.90", "4.179332"], ["83699.60", "0"], ["83691.50", "4.361042"], ["83691.20", "0"], ["83683.10", "4.906172"], ["83682.80", "0"], ["83674.70", "5.542157"], ["83674.40", "0"], ["83666.30", "5.633012"], ["83666.00", "0.270427"], ["83657.90", "5.269592"], ["83657.60", "0"], ["83649.50", "5.451302"], ["83649.20", "0"], ["83641.10", "4.633607"], ["83640.80", "0"], ["83632.70", "4.451897"], ["83632.40", "0"], ["83624.30", "4.270187"], ["83624.00", "0"], ["83615.90", "5.178737"], ["83615.60", "0"], ["83578.95", "0.000033"]], "checksum": -596352976, "ts": "1742543262656"}], "ts": 1742543262660, "record_time": 1742543262.634348}
{"action": "update", "arg": {"instType": "SPOT", "channel": "books", "instId": "BTCUSDT"}, "data": [{"asks": [["83868.39", "0.134576"], ["83869.04", "0.088426"], ["83887.40", "0.001939"], ["83889.40", "0.005102"], ["83891.40", "0.013427"], ["83893.40", "0.035334"], ["83895.40", "0.092985"], ["83897.40", "0.244696"], ["83899.40", "0.643937"], ["83901.40", "1.694572"], ["83901.90", "0.006240"], ["83902.00", "0.551190"], ["83902.30", "0.240000"], ["83903.30", "0"], ["83903.60", "0.507090"], ["83904.50", "0.565410"], ["83909.80", "1.350000"], ["83943.30", "3.997622"], ["83951.70", "4.633607"], ["83960.10", "4.179332"], ["83968.50", "3.906767"], ["83985.30", "4.997027"], ["83993.70", "5.451302"], ["84002.10", "4.451897"], ["84010.50", "4.361042"], ["84018.90", "5.087882"], ["84027.30", "4.270187"], ["84035.70", "4.815317"], ["84044.10", "5.360447"], ["84052.50", "4.088477"], ["84060.90", "5.633012"], ["84069.30", "5.542157"], ["84077.70", "5.178737"], ["84086.10", "4.906172"], ["84094.50", "5.269592"], ["84102.90", "4.724462"], ["84452.66", "0"], ["84453.76", "0"]], "bids": [["83867.11", "0.011219"], ["83850.00", "0.183248"], ["83833.40", "0.002654"], ["83831.40", "0.006873"], ["83829.40", "0.018087"], ["83827.40", "0.047599"], ["83825.40", "0.125260"], ["83823.40", "0.329446"], ["83821.40", "0.866965"], ["83819.40", "2.281487"], ["83817.40", "6.003913"], ["83817.30", "1.231050"], ["83817.20", "0.001010"], ["83817.10", "5.735490"], ["83817.08", "0.003605"], ["83816.80", "0"], ["83816.40", "0.143100"], ["83816.00", "0.084585"], ["83815.50", "0.390000"], ["83813.60", "0.362850"], ["83813.40", "0"], ["83812.30", "1.666560"], ["83811.90", "0"], ["83805.46", "0"], ["83775.50", "5.087882"], ["83758.70", "4.542752"], ["83750.30", "3.997622"], ["83741.90", "5.178737"], ["83733.50", "4.724462"], ["83725.10", "4.361042"], ["83716.70", "3.906767"], ["83708.30", "4.906172"], ["83699.90", "4.815317"], ["83691.50", "4.997027"], ["83683.10", "5.542157"], ["83674.70", "5.633012"], ["83666.30", "4.179332"], ["83657.90", "5.451302"], ["83649.50", "4.270187"], ["83641.10", "5.269592"], ["83632.70", "4.633607"], ["83624.30", "5.360447"], ["83615.90", "4.451897"], ["83578.11", "0.000023"], ["83578.04", "0.000096"]], "checksum": 644347530, "ts": "1742543262860"}], "ts": 1742543262864, "record_time": 1742543262.921963}
{"action": "update", "arg": {"instType": "SPOT", "channel": "books", "instId": "BTCUSDT"}, "data": [{"asks": [["83868.39", "0.134746"], ["83887.40", "0.001009"], ["83889.40", "0.002656"], ["83891.40", "0.006990"], ["83893.40", "0.018395"], ["83895.40", "0.048408"], ["83897.40", "0.127390"], ["83899.40", "0.335235"], ["83901.40", "0.882198"], ["83902.30", "0.706590"], ["83903.60", "0"], ["83905.40", "3.142440"], ["83905.90", "0"], ["83907.50", "0"], ["83911.40", "0.107370"], ["83943.30", "5.360447"], ["83951.70", "5.451302"], ["83960.10", "4.361042"], ["83968.50", "5.633012"], ["83976.90", "4.633607"], ["83985.30", "5.087882"], ["83993.70", "5.542157"], ["84002.10", "4.724462"], ["84010.50", "3.997622"], ["84018.90", "4.815317"], ["84027.30", "4.542752"], ["84035.70", "4.997027"], ["84044.10", "4.088477"], ["84052.50", "4.451897"], ["84060.90", "5.178737"], ["84069.30", "5.269592"], ["84077.70", "4.906172"], ["84086.10", "3.906767"], ["84094.50", "4.179332"], ["84102.90", "4.270187"], ["84452.66", "0.000009"]], "bids": [["83828.13", "0.272673"], ["83819.40", "2.281656"], ["83817.40", "6.004359"], ["83817.30", "3.067980"], ["83817.20", "0.001028"], ["83817.10", "2.753940"], ["83817.00", "0.000017"], ["83805.90", "0.015000"], ["83804.60", "0"], ["83804.00", "0"], ["83794.99", "0.062760"], ["83775.50", "4.270187"], ["83767.10", "4.815317"], ["83758.70", "5.360447"], ["83750.35", "0"], ["83750.30", "4.997027"], ["83741.90", "5.633012"], ["83733.89", "0.125969"], ["83733.50", "4.451897"], ["83725.10", "4.906172"], ["83708.30", "5.178737"], ["83699.90", "4.361042"], ["83691.50", "4.542752"], ["83683.10", "5.087882"], ["83674.70", "4.633607"], ["83666.30", "5.451302"], ["83657.90", "5.542157"], ["83649.50", "4.179332"], ["83632.70", "3.997622"], ["83624.30", "4.088477"], ["83615.90", "4.724462"], ["83578.11", "0"], ["83578.04", "0"]], "checksum": 417394524, "ts": "1742543263060"}], "ts": 1742543263064, "record_time": 1742543263.037354}
{"action": "update", "arg": {"instType": "SPOT", "channel": "books", "instId": "BTCUSDT"}, "data": [{"asks": [["83868.39", "0.147954"], ["83869.02", "0.079993"], ["83869.04", "0.008433"], ["83881.83", "0"], ["83887.40", "0.001340"], ["83889.40", "0.003527"], ["83891.40", "0.009282"], ["83893.40", "0.024427"], ["83895.40", "0.064282"], ["83897.40", "0.169162"], ["83899.40", "0.445164"], ["83901.40", "1.171670"], ["83905.00", "0"], ["83905.40", "3.142020"], ["83909.20", "0.022680"], ["83911.40", "0"], ["83943.30", "5.633012"], ["83951.70", "4.906172"], ["83960.10", "4.542752"], ["83968.50", "5.451302"], ["83976.90", "4.997027"], ["83985.30", "4.724462"], ["83993.70", "4.815317"], ["84002.10", "4.088477"], ["84010.50", "5.542157"], ["84018.90", "3.997622"], ["84027.30", "5.178737"], ["84035.70", "5.087882"], ["84044.10", "4.633607"], ["84052.50", "5.269592"], ["84060.90", "4.451897"], ["84069.30", "3.906767"], ["84077.70", "4.361042"], ["84086.10", "5.360447"], ["84453.76", "0.000054"]], "bids": [["83833.40", "0.002942"], ["83831.40", "0.007741"], ["83829.40", "0.020372"], ["83827.40", "0.053611"], ["83825.40", "0.141082"], ["83823.40", "0.371268"], ["83821.40", "0.977020"], ["83819.40", "2.571105"], ["83817.40", "6.766066"], ["83817.30", "1.290540"], ["83817.10", "2.753730"], ["83816.40", "0.143310"], ["83813.20", "0.098160"], ["83804.70", "0"], ["83775.50", "4.633607"], ["83767.11", "1.258679"], ["83767.10", "4.088477"], ["83758.70", "4.906172"], ["83750.30", "4.361042"], ["83741.90", "5.360447"], ["83733.50", "4.179332"], ["83725.10", "3.906767"], ["83716.70", "5.451302"], ["83708.30", "5.542157"], ["83699.90", "5.087882"], ["83691.50", "4.815317"], ["83683.10", "4.724462"], ["83674.70", "4.542752"], ["83666.30", "4.270187"], ["83657.90", "5.633012"], ["83649.50", "4.997027"], ["83641.10", "3.997622"], ["83632.70", "5.269592"], ["83627.00", "0.198453"], ["83624.30", "4.451897"], ["83615.90", "5.178737"], ["83614.90", "0.000040"], ["83580.00", "0"], ["83578.95", "0"]], "checksum": -231549612, "ts": "1742543263268"}], "ts": 1742543263271, "record_time": 1742543263.245864}
{"action": "update", "arg": {"instType": "SPOT", "channel": "books", "instId": "BTCUSDT"}, "data": [{"asks": [["83868.40", "0.000250"], ["83869.02", "0"], ["83873.83", "0"], ["83873.91", "0"], ["83878.37", "0.008055"], ["83878.45", "0.004300"], ["83881.40", "0"], ["83882.00", "0.001023"], ["83883.40", "0"], ["83884.00", "0.001011"], ["83885.40", "0"], ["83886.00", "0.001011"], ["83887.40", "0"], ["83888.00", "0.001405"], ["83889.40", "0"], ["83890.00", "0.003698"], ["83891.40", "0"], ["83892.00", "0.009730"], ["83893.40", "0"], ["83894.00", "0.025605"], ["83895.40", "0"], ["83896.00", "0.067382"], ["83897.40", "0.016429"], ["83898.00", "0.177322"], ["83899.40", "0"], ["83900.00", "0.466636"], ["83901.40", "0"], ["83901.60", "0"], ["83901.90", "0"], ["83902.00", "1.227991"], ["83902.30", "1.273200"], ["83902.70", "0.079140"], ["83904.70", "0"], ["83904.80", "0.050880"], ["83905.10", "0"], ["83906.10", "0.075180"], ["83909.80", "0"], ["83910.40", "1.350000"], ["83913.20", "0.143100"], ["83913.40", "0.537480"], ["83913.60", "1.647600"], ["83943.30", "0"], ["83943.90", "3.997592"], ["83951.70", "0"], ["83952.30", "4.179300"], ["83960.10", "0"], ["83960.70", "4.270155"], ["83968.50", "0"], ["83969.10", "5.451261"], ["83976.90", "0"], ["83977.50", "4.633572"], ["83985.30", "0"], ["83985.90", "3.906737"], ["83993.70", "0"], ["83994.30", "4.451863"], ["84002.10", "0"], ["84002.70", "4.542718"], ["84010.50", "0"], ["84011.10", "4.815281"], ["84018.90", "0"], ["84019.50", "4.361009"], ["84027.30", "0"], ["84027.90", "5.087844"], ["84035.70", "0"], ["84036.30", "5.269552"], ["84044.10", "0"], ["84044.70", "5.632970"], ["84052.50", "0"], ["84053.10", "5.178698"], ["84060.90", "0"], ["84061.50", "4.996989"], ["84069.30", "0"], ["84069.90", "4.088446"], ["84077.70", "0"], ["84078.30", "4.724426"], ["84086.10", "0"], ["84086.70", "4.906135"], ["84094.50", "0"], ["84095.10", "5.360407"], ["84102.90", "0"], ["84103.50", "5.542116"], ["84454.43", "0.000061"], ["84454.53", "0.000019"], ["84454.55", "0.000083"]], "bids": [["83838.00", "0.001023"], ["83836.00", "0.001650"], ["83835.40", "0"], ["83834.00", "0.004343"], ["83833.40", "0"], ["83832.00", "0.011428"], ["83831.40", "0"], ["83830.00", "0.030075"], ["83829.40", "0"], ["83828.00", "0.079145"], ["83827.40", "0"], ["83826.00", "0.208276"], ["83825.40", "0"], ["83824.00", "0.548095"], ["83823.40", "0"], ["83822.00", "1.442355"], ["83821.40", "0"], ["83820.00", "3.795672"], ["83819.40", "0"], ["83818.00", "9.988609"], ["83817.70", "0.001025"], ["83817.60", "1.230420"], ["83817.40", "4.009560"], ["83817.30", "0.006030"], ["83817.20", "0"], ["83817.10", "2.362440"], ["83817.00", "0.000032"], ["83816.40", "0.143100"], ["83814.00", "0.152640"], ["83813.60", "0"], ["83813.20", "0"], ["83813.10", "0.098160"], ["83811.00", "0"], ["83810.90", "0.006810"], ["83809.80", "1.457280"], ["83809.70", "2.586540"], ["83804.90", "0"], ["83804.80", "0"], ["83776.10", "4.633572"], ["83775.50", "0"], ["83767.70", "5.542116"], ["83767.10", "0"], ["83759.30", "5.360407"], ["83758.70", "0"], ["83750.90", "4.996989"], ["83750.30", "0"], ["83742.50", "3.906737"], ["83741.90", "0"], ["83734.10", "5.269552"], ["83733.50", "0"], ["83725.70", "4.542718"], ["83725.10", "0"], ["83717.30", "4.451863"], ["83716.70", "0"], ["83708.90", "4.088446"], ["83708.30", "0"], ["83700.50", "4.270155"], ["83699.90", "0"], ["83692.10", "4.815281"], ["83691.50", "0"], ["83683.70", "5.178698"], ["83683.10", "0"], ["83675.30", "5.087844"], ["83674.70", "0.000008"], ["83666.90", "4.906135"], ["83666.30", "0"], ["83658.50", "5.632970"], ["83657.90", "0"], ["83650.10", "5.451261"], ["83649.50", "0"], ["83641.70", "4.179300"], ["83641.10", "0"], ["83633.30", "4.724426"], ["83632.70", "0"], ["83624.90", "3.997592"], ["83624.30", "0"], ["83616.50", "4.361009"], ["83615.90", "0"], ["83580.00", "0.000294"], ["83578.95", "0.000033"], ["83578.11", "0.000023"], ["83578.04", "0.000096"], ["83577.98", "0.000072"], ["83577.78", "0.000025"], ["83577.76", "0.000483"], ["83577.73", "0.000200"], ["83577.41", "0.000034"], ["83576.47", "0.000071"], ["83575.00", "0.001544"]], "checksum": 1144916867, "ts": "1742543263477"}], "ts": 1742543263480, "record_time": 1742543263.45676}
{"action": "update", "arg": {"instType": "SPOT", "channel": "books", "instId": "BTCUSDT"}, "data": [{"asks": [["83888.00", "0.001525"], ["83890.00", "0.004011"], ["83892.00", "0.010556"], ["83894.00", "0.027778"], ["83896.00", "0.073100"], ["83898.00", "0.192371"], ["83900.00", "0.506239"], ["83902.00", "1.332206"], ["83911.60", "0.107370"], ["83943.90", "5.178698"], ["83952.30", "4.815281"], ["83960.70", "4.179300"], ["83977.50", "3.997592"], ["83985.90", "4.996989"], ["83994.30", "4.633572"], ["84002.70", "5.360407"], ["84011.10", "5.632970"], ["84019.50", "3.906737"], ["84027.90", "4.088446"], ["84036.30", "4.906135"], ["84044.70", "5.087844"], ["84053.10", "4.361009"], ["84061.50", "5.542116"], ["84069.90", "4.542718"], ["84078.30", "4.270155"], ["84086.70", "4.724426"], ["84095.10", "4.451863"], ["84103.50", "5.269552"], ["84454.55", "0"]], "bids": [["83836.00", "0.001466"], ["83834.00", "0.003856"], ["83832.00", "0.010148"], ["83830.00", "0.026707"], ["83828.00", "0.070281"], ["83826.00", "0.184949"], ["83824.00", "0.486707"], ["83822.00", "1.280810"], ["83820.00", "3.370553"], ["83818.00", "8.869875"], ["83817.60", "1.231050"], ["83817.50", "0.001024"], ["83817.40", "2.838390"], ["83776.10", "5.178698"], ["83767.70", "4.179300"], ["83767.11", "0.214073"], ["83759.30", "3.906737"], ["83750.90", "4.270155"], ["83742.50", "4.906135"], ["83734.10", "4.451863"], ["83725.70", "5.451261"], ["83717.30", "4.088446"], ["83708.90", "4.361009"], ["83700.50", "4.724426"], ["83692.10", "5.542116"], ["83683.70", "5.360407"], ["83675.30", "4.815281"], ["83666.90", "3.997592"], ["83658.50", "4.996989"], ["83650.10", "5.269552"], ["83641.70", "5.087844"], ["83633.30", "4.542718"], ["83624.90", "5.632970"], ["83616.50", "4.633572"], ["83575.00", "0"]], "checksum": 1144916867, "ts": "1742543263677"}], "ts": 1742543263679, "record_time": 1742543263.663842}
{"action": "update", "arg": {"instType": "SPOT", "channel": "books", "instId": "BTCUSDT"}, "data": [{"asks": [["83869.61", "0.079993"], ["83888.00", "0.001915"], ["83890.00", "0.005040"], ["83892.00", "0.013262"], ["83894.00", "0.034901"], ["83896.00", "0.091846"], ["83898.00", "0.241699"], ["83900.00", "0.636049"], ["83902.00", "1.673814"], ["83904.90", "0.021000"], ["83907.40", "0"], ["83943.90", "5.632970"], ["83952.30", "3.997592"], ["83960.70", "4.906135"], ["83969.10", "4.088446"], ["83977.50", "4.542718"], ["83985.90", "4.361009"], ["83994.30", "4.451863"], ["84002.70", "4.633572"], ["84011.10", "4.179300"], ["84019.50", "5.087844"], ["84027.90", "4.996989"], ["84036.30", "5.451261"], ["84044.70", "5.178698"], ["84053.10", "5.542116"], ["84061.50", "5.360407"], ["84069.90", "5.269552"], ["84078.30", "3.906737"], ["84086.70", "4.270155"], ["84095.10", "4.724426"], ["84103.50", "4.815281"]], "bids": [["83859.54", "0"], ["83822.00", "1.280918"], ["83820.00", "3.370835"], ["83818.00", "8.870619"], ["83817.40", "2.795460"], ["83776.10", "4.361009"], ["83767.70", "5.360407"], ["83767.11", "0"], ["83759.30", "5.542116"], ["83750.90", "5.178698"], ["83742.50", "5.269552"], ["83734.10", "4.724426"], ["83725.70", "3.906737"], ["83717.30", "4.906135"], ["83708.91", "1.258679"], ["83708.90", "5.632970"], ["83700.50", "4.270155"], ["83692.10", "3.997592"], ["83683.70", "4.451863"], ["83675.30", "4.179300"], ["83666.90", "4.542718"], ["83658.50", "5.087844"], ["83650.10", "4.996989"], ["83641.70", "5.451261"], ["83633.30", "4.815281"], ["83624.90", "4.088446"], ["83575.00", "0.001544"]], "checksum": 1937924221, "ts": "1742543263880"}], "ts": 1742543263882, "record_time": 1742543263.85778}
{"action": "update", "arg": {"instType": "SPOT", "channel": "books", "instId": "BTCUSDT"}, "data": [{"asks": [["83869.77", "0"], ["83904.90", "0.009000"], ["83907.40", "0.015000"], ["83943.90", "4.724426"], ["83952.30", "4.179300"], ["83969.10", "3.997592"], ["83977.50", "3.906737"], ["83985.90", "5.451261"], ["83994.30", "5.087844"], ["84002.70", "4.270155"], ["84011.10", "4.542718"], ["84019.50", "4.815281"], ["84027.90", "4.361009"], ["84031.72", "0"], ["84036.30", "5.178698"], ["84044.70", "4.633572"], ["84053.10", "4.451863"], ["84061.50", "5.269552"], ["84069.90", "4.088446"], ["84078.30", "4.996989"], ["84086.70", "5.360407"], ["84095.10", "5.632970"], ["84103.50", "5.542116"], ["84187.14", "0"], ["84195.47", "1.728621"], ["84454.55", "0.000083"]], "bids": [["83868.38", "1.222626"], ["83865.12", "0.115155"], ["83841.67", "0.249240"], ["83830.00", "0.026813"], ["83828.00", "0.070561"], ["83826.00", "0.185686"], ["83824.00", "0.488648"], ["83822.00", "1.285915"], ["83820.00", "3.383989"], ["83818.00", "8.905234"], ["83817.40", "2.792610"], ["83776.10", "4.451863"], ["83767.70", "5.632970"], ["83759.30", "5.451261"], ["83750.90", "3.997592"], ["83742.50", "4.361009"], ["83734.10", "4.088446"], ["83725.70", "4.633572"], ["83717.30", "4.270155"], ["83708.91", "0.136702"], ["83708.90", "4.996989"], ["83700.50", "3.906737"], ["83692.10", "5.360407"], ["83683.70", "4.179300"], ["83675.30", "5.542116"], ["83666.90", "5.178698"], ["83658.50", "4.906135"], ["83650.10", "5.269552"], ["83641.70", "4.724426"], ["83633.30", "5.087844"], ["83624.90", "4.815281"], ["83616.50", "4.542718"], ["83576.47", "0"], ["83575.00", "0"]], "checksum": 520765670, "ts": "1742543264088"}], "ts": 1742543264093, "record_time": 1742543264.188655}
{"action": "update", "arg": {"instType": "SPOT", "channel": "books", "instId": "BTCUSDT"}, "data": [{"asks": [["83868.39", "0.134746"], ["83868.40", "0.000100"], ["83869.61", "0"], ["83869.82", "0"], ["83871.09", "0.115151"], ["83883.99", "0.010000"], ["83905.40", "0.779910"], ["83907.80", "2.362020"], ["83943.90", "4.179300"], ["83952.30", "4.633572"], ["83960.70", "4.996989"], ["83969.10", "5.451261"], ["83977.50", "4.361009"], ["83985.90", "4.815281"], ["83994.30", "5.360407"], ["84002.70", "4.906135"], ["84011.10", "3.997592"], ["84019.50", "4.451863"], ["84027.90", "5.632970"], ["84036.30", "3.906737"], ["84038.00", "0.161045"], ["84044.70", "5.178698"], ["84053.10", "5.542116"], ["84069.90", "4.542718"], ["84078.30", "4.088446"], ["84086.70", "4.270155"], ["84095.10", "4.724426"], ["84103.50", "5.087844"], ["84454.53", "0"], ["84454.55", "0"]], "bids": [["83867.11", "0.044363"], ["83828.00", "0.070772"], ["83826.00", "0.186241"], ["83824.00", "0.490109"], ["83822.00", "1.289759"], ["83820.00", "3.394103"], ["83818.00", "8.931850"], ["83816.00", "0.084602"], ["83767.70", "4.996989"], ["83759.30", "5.269552"], ["83750.90", "4.270155"], ["83742.50", "5.360407"], ["83734.10", "4.906135"], ["83725.70", "5.178698"], ["83717.30", "4.179300"], ["83708.90", "4.724426"], ["83700.50", "4.633572"], ["83692.10", "4.088446"], ["83683.70", "5.087844"], ["83675.30", "3.906737"], ["83666.90", "3.997592"], ["83658.50", "5.542116"], ["83650.10", "4.815281"], ["83641.70", "5.632970"], ["83633.30", "4.542718"], ["83624.90", "5.451261"], ["83616.50", "4.361009"]], "checksum": -1192103768, "ts": "1742543264289"}], "ts": 1742543264292, "record_time": 1742543264.266337}
{"action": "update", "arg": {"instType": "SPOT", "channel": "books", "instId": "BTCUSDT"}, "data": [{"asks": [["83869.56", "0.079993"], ["83873.58", "0.179971"], ["83886.00", "0.001350"], ["83887.55", "0.028238"], ["83888.00", "0.003554"], ["83890.00", "0.009352"], ["83892.00", "0.024612"], ["83894.00", "0.064768"], ["83896.00", "0.170441"], ["83898.00", "0.448530"], ["83900.00", "1.180342"], ["83901.92", "0"], ["83902.00", "3.106163"], ["83903.30", "0.072510"], ["83904.50", "0.537480"], ["83905.00", "0.028140"], ["83907.20", "0.133590"], ["83908.00", "0.084600"], ["83909.20", "0"], ["83910.10", "0"], ["83911.90", "0"], ["83943.90", "3.906737"], ["83952.30", "5.451261"], ["83960.70", "5.542116"], ["83969.10", "4.633572"], ["83977.50", "4.451863"], ["83985.90", "5.178698"], ["83994.30", "4.996989"], ["84002.70", "4.815281"], ["84011.10", "5.087844"], ["84019.50", "4.542718"], ["84027.90", "4.361009"], ["84036.30", "5.632970"], ["84044.70", "5.360407"], ["84053.10", "4.724426"], ["84061.50", "4.906135"], ["84069.90", "5.269552"], ["84078.30", "4.270155"], ["84086.70", "4.088446"], ["84095.10", "3.997592"], ["84103.50", "4.179300"], ["84453.76", "0"], ["84454.43", "0"]], "bids": [["83836.00", "0.001601"], ["83834.00", "0.003952"], ["83832.00", "0.010400"], ["83830.00", "0.027368"], ["83828.00", "0.072022"], ["83826.00", "0.189530"], ["83824.00", "0.498764"], ["83822.00", "1.312538"], ["83820.00", "3.454047"], ["83818.00", "9.089597"], ["83817.60", "0.001044"], ["83817.40", "2.792190"], ["83816.40", "0.143310"], ["83812.31", "1.411386"], ["83810.80", "0"], ["83809.80", "1.350000"], ["83809.70", "2.436630"], ["83805.30", "0"], ["83794.99", "0"], ["83776.10", "4.361009"], ["83775.00", "0"], ["83767.70", "5.269552"], ["83759.30", "4.270155"], ["83750.90", "5.087844"], ["83742.50", "4.906135"], ["83734.10", "4.996989"], ["83725.70", "4.542718"], ["83717.30", "3.997592"], ["83708.91", "0"], ["83708.90", "3.906737"], ["83700.50", "5.632970"], ["83692.10", "5.178698"], ["83683.70", "4.088446"], ["83675.30", "4.179300"], ["83666.90", "5.360407"], ["83658.50", "4.724426"], ["83650.10", "5.542116"], ["83641.70", "5.451261"], ["83633.30", "4.815281"], ["83624.90", "4.633572"], ["83616.50", "4.451863"], ["83576.47", "0.000071"], ["83575.00", "0.001544"], ["83574.19", "0.000109"], ["83571.79", "0.000098"]], "checksum": 1078593069, "ts": "1742543264493"}], "ts": 1742543264494, "record_time": 1742543264.467136}
{"action": "update", "arg": {"instType": "SPOT", "channel": "books", "instId": "BTCUSDT"}, "data": [{"asks": [["83878.36", "0.007815"], ["83886.00", "0.001030"], ["83888.00", "0.002711"], ["83890.00", "0.007134"], ["83892.00", "0.018775"], ["83894.00", "0.049407"], ["83894.25", "0.026942"], ["83896.00", "0.130019"], ["83898.00", "0.342154"], ["83900.00", "0.900407"], ["83902.00", "2.369491"], ["83902.30", "1.272780"], ["83902.70", "0"], ["83904.80", "0"], ["83905.60", "2.362080"], ["83906.80", "0.143100"], ["83907.80", "0"], ["83908.40", "0.145020"], ["83910.16", "0"], ["83911.40", "0.071520"], ["83943.90", "4.724426"], ["83952.30", "5.542116"], ["83960.70", "5.632970"], ["83969.10", "3.906737"], ["83977.50", "5.178698"], ["83985.90", "4.542718"], ["83994.30", "4.179300"], ["84002.70", "4.451863"], ["84011.10", "5.269552"], ["84019.50", "4.996989"], ["84027.90", "5.360407"], ["84036.30", "5.451261"], ["84044.70", "3.997592"], ["84053.10", "4.088446"], ["84061.50", "4.815281"], ["84069.90", "4.270155"], ["84078.30", "4.361009"], ["84086.70", "4.633572"], ["84095.10", "5.087844"], ["84103.50", "4.906135"], ["84451.88", "0"], ["84452.66", "0"]], "bids": [["83837.52", "0"], ["83836.00", "0.001303"], ["83834.00", "0.003430"], ["83832.00", "0.009027"], ["83830.00", "0.023650"], ["83828.00", "0.062237"], ["83826.00", "0.163781"], ["83824.00", "0.431002"], ["83822.00", "1.134217"], ["83820.00", "2.984781"], ["83818.00", "7.854687"], ["83817.40", "0.993360"], ["83816.00", "0.084810"], ["83813.10", "0.101820"], ["83812.30", "1.233750"], ["83811.70", "0.120000"], ["83810.70", "0.120000"], ["83809.90", "0.240000"], ["83809.80", "0"], ["83806.70", "0.120000"], ["83806.60", "0"], ["83805.90", "0"], ["83805.60", "0"], ["83804.88", "0"], ["83776.10", "3.997592"], ["83767.70", "5.178698"], ["83759.30", "5.542116"], ["83750.90", "5.451261"], ["83742.50", "5.087844"], ["83734.10", "4.542718"], ["83725.70", "3.906737"], ["83717.30", "4.088446"], ["83708.90", "5.360407"], ["83700.50", "4.724426"], ["83692.10", "4.361009"], ["83683.70", "4.906135"], ["83675.30", "5.269552"], ["83666.90", "4.451863"], ["83658.50", "4.815281"], ["83650.10", "4.179300"], ["83641.70", "5.632970"], ["83633.30", "4.633572"], ["83624.90", "4.996989"], ["83616.50", "4.270155"], ["83571.43", "0.000330"], ["83571.42", "0.000008"]], "checksum": -1780121277, "ts": "1742543264697"}], "ts": 1742543264699, "record_time": 1742543264.725814}
{"action": "update", "arg": {"instType": "SPOT", "channel": "books", "instId": "BTCUSDT"}, "data": [{"asks": [["83868.39", "0.084746"], ["83869.52", "0.079993"], ["83869.56", "0"], ["83878.36", "0"], ["83879.39", "0"], ["83886.00", "0.001048"], ["83888.00", "0.001123"], ["83890.00", "0.002955"], ["83892.00", "0.007776"], ["83894.00", "0.020464"], ["83894.25", "0"], ["83896.00", "0.053852"], ["83898.00", "0.141716"], ["83900.00", "0.372936"], ["83902.00", "0.981410"], ["83902.10", "0.091320"], ["83902.30", "0.466800"], ["83903.90", "0.518400"], ["83904.00", "0.360000"], ["83905.00", "0"], ["83905.40", "0"], ["83905.60", "0"], ["83906.80", "0"], ["83909.70", "2.361990"], ["83910.00", "0.002000"], ["83911.40", "0.045000"], ["83911.70", "0.045000"], ["83913.60", "0"], ["83943.90", "4.906135"], ["83952.30", "4.361009"], ["83960.70", "4.542718"], ["83969.10", "4.088446"], ["83977.50", "4.633572"], ["83985.90", "4.815281"], ["83994.30", "4.996989"], ["84002.70", "5.178698"], ["84011.10", "4.179300"], ["84019.50", "5.360407"], ["84027.90", "4.270155"], ["84036.30", "5.632970"], ["84053.10", "5.087844"], ["84061.50", "3.906737"], ["84069.90", "4.724426"], ["84078.30", "5.542116"], ["84086.70", "5.269552"], ["84095.10", "4.451863"], ["84103.50", "5.451261"], ["84451.88", "0.000010"], ["84452.66", "0.000009"], ["84453.76", "0.000054"], ["84454.43", "0.000061"], ["84454.53", "0.000019"], ["84454.55", "0.000083"]], "bids": [["83853.22", "0"], ["83832.00", "0.009258"], ["83830.00", "0.024365"], ["83828.00", "0.064119"], ["83826.00", "0.168732"], ["83824.00", "0.444033"], ["83822.00", "1.168507"], ["83820.00", "3.075018"], ["83818.00", "8.092153"], ["83817.00", "0.000015"], ["83815.50", "0.300000"], ["83815.30", "0"], ["83811.80", "0.145020"], ["83809.80", "0.120000"], ["83807.40", "0.120000"], ["83806.70", "0"], ["83806.00", "0"], ["83767.70", "4.451863"], ["83759.30", "4.270155"], ["83750.90", "4.906135"], ["83742.50", "5.269552"], ["83734.10", "4.088446"], ["83725.70", "4.996989"], ["83717.30", "5.632970"], ["83708.90", "4.361009"], ["83700.50", "5.178698"], ["83692.10", "5.542116"], ["83683.70", "5.360407"], ["83675.30", "3.906737"], ["83666.90", "4.724426"], ["83658.50", "5.451261"], ["83641.70", "4.633572"], ["83633.30", "4.815281"], ["83624.90", "4.542718"], ["83616.50", "5.087844"], ["83571.39", "0.000178"]], "checksum": 2017997588, "ts": "1742543264910"}], "ts": 1742543264914, "record_time": 1742543264.887915}
{"action": "update", "arg": {"instType": "SPOT", "channel": "books", "instId": "BTCUSDT"}, "data": [{"asks": [["83868.39", "0.097954"], ["83878.36", "0.014965"], ["83879.87", "0.095367"], ["83887.55", "0"], ["83888.00", "0.002239"], ["83889.66", "0"], ["83890.00", "0.005893"], ["83892.00", "0.015507"], ["83894.00", "0.040648"], ["83894.77", "0.035972"], ["83896.00", "0.106969"], ["83896.21", "0.028238"], ["83898.00", "0.281497"], ["83900.00", "0.740783"], ["83902.00", "1.949429"], ["83902.10", "0.091530"], ["83902.30", "1.054440"], ["83906.20", "0.015000"], ["83906.40", "0.246120"], ["83906.84", "0.026942"], ["83909.50", "1.623840"], ["83913.40", "0.209200"], ["83943.90", "5.542116"], ["83952.30", "4.906135"], ["83960.70", "3.906737"], ["83969.10", "5.269552"], ["83977.50", "4.451863"], ["83985.90", "4.179300"], ["84002.70", "4.724426"], ["84011.10", "4.361009"], ["84019.50", "3.997592"], ["84027.90", "5.451261"], ["84044.70", "4.542718"], ["84053.10", "4.815281"], ["84061.50", "4.088446"], ["84069.90", "5.087844"], ["84078.30", "4.270155"], ["84086.70", "4.633572"], ["84095.10", "5.360407"], ["84103.50", "5.178698"], ["84453.76", "0"], ["84454.43", "0"], ["84454.53", "0"], ["84454.55", "0"]], "bids": [["83862.11", "0.000228"], ["83851.15", "0.084173"], ["83846.05", "0"], ["83845.42", "0.125881"], ["83834.00", "0.003667"], ["83832.00", "0.009652"], ["83830.00", "0.025399"], ["83828.00", "0.066838"], ["83826.00", "0.175891"], ["83824.00", "0.462872"], ["83822.00", "1.218082"], ["83820.01", "1.285505"], ["83820.00", "3.205479"], ["83818.00", "8.435472"], ["83816.00", "0.084825"], ["83815.20", "0.145020"], ["83813.40", "0.070020"], ["83812.31", "0.891071"], ["83811.80", "0"], ["83808.50", "0.269760"], ["83767.70", "4.996989"], ["83759.30", "4.906135"], ["83750.90", "4.542718"], ["83742.50", "4.451863"], ["83734.10", "5.087844"], ["83725.70", "5.360407"], ["83717.30", "5.451261"], ["83708.90", "4.724426"], ["83700.50", "5.632970"], ["83692.10", "4.361009"], ["83683.70", "5.542116"], ["83675.30", "5.178698"], ["83666.90", "4.815281"], ["83658.50", "4.088446"], ["83650.10", "5.269552"], ["83641.70", "4.179300"], ["83633.30", "3.906737"], ["83624.90", "4.633572"], ["83616.50", "4.270155"], ["83574.19", "0"], ["83571.79", "0"], ["83571.43", "0"], ["83571.42", "0"], ["83571.39", "0"]], "checksum": 457008774, "ts": "1742543265118"}], "ts": 1742543265121, "record_time": 1742543265.435831}
{"action": "update", "arg": {"instType": "SPOT", "channel": "books", "instId": "BTCUSDT"}, "data": [{"asks": [["83868.39", "0.084201"], ["83869.52", "0"], ["83871.65", "0.013208"], ["83896.00", "0.106726"], ["83898.00", "0.280858"], ["83900.00", "0.739101"], ["83902.00", "1.945002"], ["83903.30", "0"], ["83906.10", "0.103110"], ["83906.40", "0.202620"], ["83908.40", "0"], ["83912.20", "0.324030"], ["83913.40", "0.537480"], ["83913.50", "0.012360"], ["83943.90", "4.815281"], ["83960.70", "4.451863"], ["83969.10", "4.088446"], ["83977.50", "4.633572"], ["83985.90", "4.996989"], ["83994.30", "5.087844"], ["84002.70", "5.178698"], ["84019.50", "4.724426"], ["84027.90", "5.269552"], ["84036.30", "5.542116"], ["84044.70", "3.997592"], ["84053.10", "5.451261"], ["84061.50", "4.270155"], ["84069.90", "4.542718"], ["84078.30", "5.632970"], ["84086.70", "5.360407"], ["84095.10", "3.906737"], ["84103.50", "4.179300"], ["84453.76", "0.000054"]], "bids": [["83813.40", "0"], ["83812.31", "0"], ["83776.10", "5.360407"], ["83767.70", "4.906135"], ["83759.30", "4.633572"], ["83750.90", "5.087844"], ["83742.50", "3.906737"], ["83734.10", "4.270155"], ["83725.70", "4.451863"], ["83708.90", "3.997592"], ["83700.50", "4.542718"], ["83692.10", "5.542116"], ["83683.70", "4.996989"], ["83675.30", "4.088446"], ["83666.90", "4.724426"], ["83658.50", "5.632970"], ["83650.10", "5.178698"], ["83641.70", "5.269552"], ["83633.30", "4.815281"], ["83624.90", "4.361009"], ["83616.50", "4.179300"], ["83574.19", "0.000109"], ["83571.79", "0.000098"]], "checksum": 1718419955, "ts": "1742543265323"}], "ts": 1742543265325, "record_time": 1742543265.439183}
{"action": "update", "arg": {"instType": "SPOT", "channel": "books", "instId": "BTCUSDT"}, "data": [{"asks": [["83868.39", "0.097409"], ["83869.48", "0.079993"], ["83871.65", "0"], ["83892.00", "0.015393"], ["83894.00", "0.040510"], ["83896.00", "0.106483"], ["83898.00", "0.279977"], ["83900.00", "0.736783"], ["83902.00", "1.938901"], ["83943.90", "4.361009"], ["83952.30", "5.451261"], ["83960.70", "5.360407"], ["83969.10", "5.178698"], ["83977.50", "4.815281"], ["83985.90", "4.542718"], ["84002.70", "4.088446"], ["84011.10", "5.632970"], ["84019.50", "4.451863"], ["84027.90", "3.997592"], ["84036.30", "5.269552"], ["84044.70", "4.270155"], ["84053.10", "5.542116"], ["84061.50", "3.906737"], ["84069.90", "4.996989"], ["84078.30", "4.633572"], ["84086.70", "4.179300"], ["84095.10", "4.906135"], ["84103.50", "4.724426"]], "bids": [["83820.00", "3.205282"], ["83818.00", "8.434951"], ["83813.10", "0"], ["83806.70", "0.120000"], ["83776.10", "4.542718"], ["83767.70", "5.269552"], ["83759.30", "4.179300"], ["83750.90", "4.724426"], ["83742.50", "5.178698"], ["83734.10", "3.997592"], ["83725.70", "5.087844"], ["83717.30", "4.361009"], ["83708.90", "5.451261"], ["83700.50", "4.996989"], ["83692.10", "3.906737"], ["83683.70", "4.451863"], ["83675.30", "5.360407"], ["83666.90", "4.088446"], ["83658.50", "4.633572"], ["83650.10", "4.906135"], ["83641.70", "4.270155"], ["83633.30", "5.632970"], ["83624.90", "4.815281"], ["83616.50", "5.542116"]], "checksum": -1296188191, "ts": "1742543265553"}], "ts": 1742543265555, "record_time": 1742543265.528474}
