{"event": "subscribe", "arg": {"instType": "SPOT", "channel": "books", "instId": "BTCUSDT"}, "record_time": 1742142203.495162}
{"action": "snapshot", "arg": {"instType": "SPOT", "channel": "books", "instId": "BTCUSDT"}, "data": [{"asks": [["84277.52", "0.000100"], ["84277.53", "0.000100"], ["84277.54", "0.000100"], ["84277.55", "0.000100"], ["84291.54", "0.313401"], ["84291.96", "0.140146"], ["84294.66", "0.002907"], ["84294.70", "0.003017"], ["84295.85", "0.001827"], ["84297.11", "0.011836"], ["84300.00", "0.002000"], ["84301.95", "0.001205"], ["84304.05", "0.119869"], ["84305.35", "0.053993"], ["84305.51", "0.017798"], ["84306.53", "0.006356"], ["84306.91", "0.006356"], ["84307.05", "0.010985"], ["84307.12", "0.209200"], ["84307.15", "0.006356"], ["84307.45", "0.006356"], ["84308.02", "0.012680"], ["84308.18", "0.006356"], ["84308.32", "0.016427"], ["84308.38", "0.006356"], ["84308.81", "0.016428"], ["84308.83", "0.119843"], ["84309.45", "0.006356"], ["84309.59", "0.010984"], ["84309.95", "0.006356"], ["84310.11", "0.006357"], ["84311.38", "0.006356"], ["84312.13", "0.015892"], ["84312.17", "0.006356"], ["84312.28", "0.010000"], ["84312.34", "0.009989"], ["84312.95", "0.009989"], ["84313.33", "0.119895"], ["84314.37", "0.006356"], ["84314.56", "0.119879"], ["84315.32", "0.072304"], ["84315.55", "0.209200"], ["84318.10", "0.001015"], ["84320.10", "0.001026"], ["84322.10", "0.001027"], ["84324.10", "0.001013"], ["84324.72", "0.209200"], ["84326.10", "0.001018"], ["84328.10", "0.001031"], ["84330.00", "0.002000"], ["84330.10", "0.001029"], ["84332.10", "0.001404"], ["84334.10", "0.003696"], ["84334.17", "0.001597"], ["84336.10", "0.009725"], ["84336.60", "0.197885"], ["84338.10", "0.025798"], ["84339.10", "0.001008"], ["84340.10", "0.002040"], ["84340.20", "0.001030"], ["84341.56", "0.209200"], ["84341.97", "0.001597"], ["84342.00", "0.000094"], ["84345.30", "0.406740"], ["84345.50", "0.015060"], ["84346.90", "3.694380"], ["84347.00", "0.021600"], ["84347.10", "0.015120"], ["84347.30", "0.265950"], ["84347.50", "0.490740"], ["84347.80", "0.489570"], ["84348.60", "0.142500"], ["84349.30", "0.177780"], ["84349.40", "0.032910"], ["84349.98", "0.209200"], ["84350.20", "0.007050"], ["84350.60", "0.936510"], ["84351.20", "2.348670"], ["84351.50", "0.015210"], ["84351.80", "2.669430"], ["84352.70", "6.215520"], ["84354.20", "0.007050"], ["84358.40", "0.209200"], ["84360.00", "0.002000"], ["84366.83", "0.209200"], ["84375.26", "0.209200"], ["84376.97", "0.057629"], ["84380.20", "5.603845"], ["84383.69", "0.209200"], ["84385.55", "0.072042"], ["84386.40", "0.304146"], ["84388.70", "5.151922"], ["84390.00", "0.002000"], ["84390.01", "0.000387"], ["84392.12", "0.209200"], ["84393.46", "0.000860"], ["84397.20", "4.519230"], ["84397.71", "0.000860"], ["84400.55", "0.209200"], ["84405.70", "5.242306"], ["84408.98", "0.209200"], ["84414.20", "4.428845"], ["84417.41", "0.209200"], ["84420.00", "0.002000"], ["84422.70", "5.513460"], ["84425.84", "0.209200"], ["84431.20", "4.609614"], ["84432.82", "0.125360"], ["84439.70", "4.157691"], ["84448.20", "5.423076"], ["84456.70", "4.880768"], ["84459.31", "0.025290"], ["84462.74", "0.000092"], ["84465.20", "4.248076"], ["84473.70", "4.067307"], ["84474.20", "0.308747"], ["84482.20", "4.790383"], ["84488.00", "0.000532"], ["84490.11", "0.000582"], ["84490.70", "3.976922"], ["84496.73", "0.000043"], ["84498.20", "0.295145"], ["84499.20", "4.338461"], ["84500.00", "0.010935"], ["84507.70", "4.971153"], ["84508.46", "0.000658"], ["84516.20", "3.886538"], ["84521.85", "0.000033"], ["84524.70", "5.061537"], ["84525.00", "0.000021"], ["84533.20", "4.699999"], ["84541.70", "5.332691"], ["84545.45", "0.000557"], ["84549.53", "0.015814"], ["84550.00", "0.000342"], ["84551.02", "0.000008"], ["84555.35", "0.000016"], ["84568.97", "0.000008"], ["84570.00", "0.002000"], ["84571.43", "0.000033"], ["84573.57", "0.000158"], ["84573.59", "0.000177"], ["84579.71", "0.000129"], ["84582.14", "0.000011"], ["84590.00", "0.000121"], ["84591.34", "0.000021"], ["84592.59", "0.000219"], ["84600.00", "0.020825"], ["84606.06", "0.000395"], ["84608.70", "0.000924"], ["84612.50", "0.000021"], ["84613.40", "0.000009"], ["84614.14", "0.000142"], ["84615.38", "0.000066"], ["84616.67", "0.000052"], ["84617.50", "0.495362"], ["84617.65", "0.000417"], ["84619.05", "0.000009"], ["84620.00", "0.000082"], ["84621.00", "0.000238"], ["84621.16", "1.657450"], ["84622.22", "0.000008"], ["84625.00", "0.000091"], ["84627.06", "0.000048"], ["84628.57", "0.000016"], ["84629.33", "0.000133"], ["84630.00", "0.000296"], ["84631.58", "0.000025"], ["84632.35", "0.000041"], ["84633.22", "0.000008"], ["84634.13", "0.000032"], ["84635.71", "0.000273"], ["84635.97", "0.000024"], ["84635.98", "0.000010"], ["84635.99", "0.000007"], ["84636.35", "0.000008"], ["84636.36", "0.000018"], ["84636.47", "0.000064"], ["84637.50", "0.000150"], ["84639.41", "0.000039"], ["84639.46", "0.000008"], ["84640.00", "0.024752"], ["84640.88", "0.000573"], ["84642.64", "0.000176"], ["84642.85", "0.000298"], ["84642.86", "0.000248"], ["84643.80", "0.000423"], ["84644.87", "0.000016"], ["84645.83", "0.000020"], ["84647.50", "0.000025"], ["84647.88", "0.000022"], ["84647.89", "0.000099"], ["84650.00", "0.000280"], ["84651.43", "0.000009"], ["84652.17", "0.000035"], ["84652.50", "0.000031"], ["84653.06", "0.000085"], ["84655.18", "0.000146"], ["84655.56", "0.000008"], ["84655.65", "0.000161"], ["84656.00", "0.000012"], ["84656.25", "0.000012"], ["84657.14", "0.000069"], ["84658.66", "0.000096"], ["84659.30", "0.000027"], ["84659.57", "0.000137"], ["84659.60", "0.000039"], ["84660.00", "0.002000"], ["84660.44", "0.000134"], ["84660.71", "0.000008"], ["84661.35", "0.000009"], ["84661.62", "0.000024"], ["84662.58", "0.000051"], ["84663.46", "0.000067"], ["84664.82", "0.000066"], ["84665.23", "0.000022"], ["84666.00", "0.000035"], ["84666.21", "0.000008"], ["84666.47", "0.000013"], ["84666.66", "0.000010"], ["84666.67", "0.012581"], ["84666.70", "0.000017"], ["84668.51", "0.000015"], ["84669.60", "0.000010"], ["84670.00", "0.000023"], ["84670.83", "0.000008"], ["84673.20", "0.000008"], ["84675.00", "0.000016"], ["84675.12", "0.000008"], ["84676.07", "0.000008"], ["84677.69", "0.000035"], ["84677.78", "0.000025"], ["84677.97", "0.000013"], ["84678.90", "0.000072"], ["84679.87", "0.000120"], ["84680.00", "0.000548"], ["84682.34", "0.000008"], ["84683.33", "0.000053"], ["84684.21", "0.000425"], ["84684.68", "0.000506"], ["84685.71", "0.000009"], ["84687.31", "0.000432"], ["84687.50", "0.000148"], ["84689.00", "0.000118"], ["84689.53", "0.000019"], ["84689.72", "0.000188"], ["84690.00", "0.002000"], ["84691.26", "0.000135"], ["84692.29", "0.000022"], ["84692.31", "0.000014"], ["84692.84", "0.000009"], ["84692.98", "0.000022"], ["84693.24", "0.000033"], ["84693.33", "0.000036"], ["84694.21", "0.000057"], ["84695.65", "0.000932"], ["84697.28", "0.000149"], ["84699.48", "0.000023"], ["84699.77", "0.000030"], ["84699.83", "0.000051"], ["84700.00", "0.004686"], ["84700.32", "0.000175"], ["84701.97", "0.000009"], ["84702.70", "0.000009"], ["84703.70", "0.000019"], ["84704.83", "0.000014"], ["84705.84", "0.000162"], ["84705.88", "0.000426"], ["84706.20", "0.000155"], ["84706.81", "0.000235"], ["84708.25", "0.000049"], ["84709.09", "0.000008"], ["84711.11", "0.000008"], ["84712.09", "0.000011"], ["84712.64", "0.000315"], ["84714.29", "0.000072"], ["84714.35", "0.000099"], ["84716.00", "0.000010"], ["84717.74", "0.000039"], ["84718.64", "0.000023"], ["84719.24", "0.001232"], ["84719.30", "0.000025"], ["84720.00", "0.002816"], ["84720.39", "0.000093"], ["84721.50", "0.000474"], ["84722.45", "0.000016"], ["84722.89", "0.000564"], ["84724.49", "0.000184"], ["84725.00", "0.000204"], ["84726.01", "0.000011"], ["84726.53", "0.000030"], ["84726.67", "0.000013"], ["84726.98", "0.000248"], ["84727.07", "0.000056"], ["84727.26", "0.000008"], ["84727.27", "0.000018"], ["84727.80", "0.000537"], ["84727.89", "0.000008"], ["84728.03", "0.000010"], ["84729.28", "0.000573"], ["84730.00", "0.000051"], ["84730.84", "0.000007"], ["84731.46", "0.000019"], ["84731.60", "0.000098"], ["84731.96", "0.000039"], ["84732.79", "0.000018"], ["84734.05", "0.000041"], ["84734.40", "0.000016"], ["84734.84", "0.000234"], ["84735.85", "0.000008"], ["84736.67", "0.000011"], ["84736.84", "0.000029"], ["84737.37", "0.000067"], ["84737.73", "0.000068"], ["84737.74", "0.000095"], ["84737.78", "0.000009"], ["84738.49", "0.000050"], ["84739.13", "0.000035"], ["84739.94", "0.000008"], ["84740.00", "0.000119"], ["84740.46", "0.000193"], ["84741.94", "0.000054"], ["84742.65", "0.000041"], ["84742.83", "0.000063"], ["84742.86", "0.000085"], ["84743.49", "0.000039"], ["84744.16", "0.000423"], ["84744.53", "0.000014"], ["84744.68", "0.000137"], ["84744.71", "0.000039"], ["84744.74", "0.000176"], ["84745.57", "0.000012"], ["84746.76", "0.000009"], ["84746.84", "0.000014"], ["84748.76", "0.000024"], ["84750.00", "0.003897"], ["84750.55", "0.000054"], ["84753.24", "0.000019"], ["84753.89", "0.000008"], ["84754.23", "0.000060"], ["84755.10", "0.000085"], ["84755.56", "0.000009"], ["84759.36", "0.000024"], ["84760.00", "0.024666"], ["84762.50", "0.000010"], ["84764.29", "0.000128"], ["84764.52", "0.000314"], ["84765.84", "0.000161"], ["84766.36", "0.000034"], ["84766.72", "0.000096"], ["84767.53", "0.000011"], ["84768.00", "0.000175"], ["84768.36", "0.000146"], ["84769.95", "0.000099"], ["84770.00", "0.000121"], ["84770.02", "0.000193"], ["84770.72", "0.000013"], ["84772.73", "0.000012"], ["84772.85", "0.000066"], ["84774.77", "0.000041"], ["84775.00", "0.000410"], ["84775.38", "0.000022"], ["84776.00", "0.000133"], ["84776.12", "0.000008"], ["84776.81", "0.000013"], ["84776.93", "0.000007"], ["84777.00", "0.000084"], ["84777.78", "0.000105"], ["84778.76", "0.000010"], ["84779.74", "0.000010"], ["84780.70", "0.000022"], ["84781.36", "0.000013"], ["84782.05", "0.000014"], ["84782.59", "0.000011"], ["84782.61", "0.017749"], ["84782.72", "0.000008"], ["84783.33", "0.000322"], ["84783.65", "0.000074"], ["84785.71", "0.000104"], ["84786.67", "0.000036"], ["84788.78", "0.000008"], ["84788.99", "0.000072"], ["84789.47", "0.000183"], ["84790.53", "0.000009"], ["84790.54", "0.000032"], ["84791.67", "0.000023"], ["84792.75", "0.000023"], ["84792.86", "0.000008"], ["84794.12", "0.000417"], ["84795.03", "0.000010"], ["84795.92", "0.000034"], ["84796.04", "0.000008"], ["84797.89", "0.000036"], ["84799.10", "0.000008"], ["84799.44", "0.000017"], ["84800.00", "0.034813"], ["84802.77", "0.000075"], ["84803.90", "0.000152"], ["84803.92", "0.000008"], ["84804.00", "0.000012"], ["84804.96", "0.000188"], ["84807.02", "0.000025"], ["84808.00", "0.000035"], ["84809.52", "0.000024"], ["84811.54", "0.000009"], ["84812.50", "0.000312"], ["84812.93", "0.000009"], ["84813.54", "0.000015"], ["84814.78", "0.000414"], ["84816.33", "0.000008"], ["84817.00", "0.000009"], ["84817.28", "0.000133"], ["84817.68", "0.000573"], ["84817.71", "0.000014"], ["84818.17", "0.000065"], ["84818.18", "0.000026"], ["84818.84", "0.000043"], ["84819.28", "0.000564"], ["84819.90", "0.000051"], ["84820.00", "0.004085"], ["84820.08", "0.000010"], ["84820.72", "0.000009"], ["84821.42", "0.000008"], ["84821.99", "0.000235"], ["84822.00", "0.000474"], ["84822.66", "0.000385"], ["84823.30", "0.000018"], ["84823.73", "0.000023"], ["84823.92", "0.000016"], ["84824.88", "0.000181"], ["84825.16", "0.000027"], ["84826.09", "0.000035"], ["84827.26", "0.000011"], ["84827.59", "0.000008"], ["84828.57", "0.000069"], ["84829.79", "0.000137"], ["84829.82", "0.000039"], ["84830.00", "0.000059"], ["84830.38", "0.000104"], ["84831.17", "0.000088"], ["84833.33", "0.000051"], ["84833.45", "0.000066"], ["84834.25", "0.000009"], ["84834.83", "0.000502"], ["84835.36", "0.000152"], ["84835.53", "0.000093"], ["84835.91", "0.000024"], ["84837.38", "0.000008"], ["84838.70", "0.000078"], ["84838.71", "0.000214"], ["84839.83", "0.000098"], ["84840.00", "0.000436"], ["84841.58", "0.000008"], ["84842.11", "0.000068"], ["84844.53", "0.000423"], ["84845.00", "0.000025"], ["84845.94", "0.000008"], ["84846.15", "0.004277"], ["84846.55", "0.000019"], ["84846.85", "0.000176"], ["84847.58", "0.000039"], ["84847.82", "0.000671"], ["84849.88", "0.000030"], ["84850.00", "0.000031"], ["84851.66", "0.000029"], ["84852.81", "0.000115"], ["84852.94", "0.000065"], ["84853.56", "0.000050"], ["84857.14", "0.000347"], ["84858.75", "0.000285"], ["84859.29", "0.000036"], ["84860.00", "0.000169"], ["84862.90", "0.000169"], ["84864.69", "0.000052"], ["84864.86", "0.000041"], ["84864.99", "0.000033"], ["84866.10", "0.000064"], ["84866.40", "0.000018"], ["84867.80", "0.000095"], ["84868.42", "0.000031"], ["84868.52", "0.000013"], ["84868.65", "0.000035"], ["84869.57", "0.000932"], ["84871.66", "0.000078"], ["84871.79", "0.000014"], ["84873.84", "0.000057"], ["84874.79", "0.000096"], ["84875.00", "0.000959"], ["84875.78", "0.000038"], ["84876.03", "0.000161"], ["84879.10", "0.000009"], ["84879.37", "0.000009"], ["84879.59", "0.000173"], ["84880.00", "0.025078"], ["84880.89", "0.000065"], ["84882.35", "0.000417"], ["84883.31", "0.001088"], ["84883.65", "0.000008"], ["84883.72", "0.000010"], ["84883.84", "0.000040"]], "bids": [["84277.51", "3.572999"], ["84275.79", "0.176984"], ["84275.78", "0.473554"], ["84273.70", "0.001024"], ["84272.63", "0.163095"], ["84272.62", "0.088256"], ["84271.70", "0.001693"], ["84271.68", "0.189990"], ["84271.05", "0.001228"], ["84269.70", "0.004455"], ["84269.57", "0.014271"], ["84269.56", "0.000164"], ["84269.55", "0.022223"], ["84268.92", "0.043563"], ["84267.70", "0.011725"], ["84267.64", "2.546755"], ["84265.70", "0.030856"], ["84264.51", "0.102484"], ["84263.70", "0.081199"], ["84263.23", "0.313315"], ["84262.75", "0.248017"], ["84262.24", "0.017837"], ["84261.70", "0.213682"], ["84261.52", "0.018262"], ["84261.43", "0.008989"], ["84261.27", "0.005938"], ["84260.76", "0.016461"], ["84260.01", "0.017081"], ["84259.70", "0.562320"], ["84259.32", "0.913061"], ["84259.31", "0.209200"], ["84259.18", "0.056358"], ["84259.09", "0.028809"], ["84258.96", "0.025086"], ["84258.71", "0.007934"], ["84258.45", "0.007317"], ["84258.37", "0.017333"], ["84258.20", "0.008165"], ["84257.70", "1.479791"], ["84257.42", "0.227687"], ["84256.59", "0.012650"], ["84256.34", "0.008284"], ["84255.87", "0.018521"], ["84255.70", "3.894185"], ["84255.12", "0.271918"], ["84254.80", "0.052114"], ["84254.21", "0.222746"], ["84253.70", "10.247856"], ["84253.60", "0.178170"], ["84253.50", "0.001260"], ["84253.47", "0.021110"], ["84252.30", "0.001024"], ["84252.20", "0.001016"], ["84251.80", "0.069600"], ["84251.60", "0.405420"], ["84251.40", "0.142500"], ["84251.15", "0.012440"], ["84250.95", "0.003523"], ["84250.94", "0.076025"], ["84250.88", "0.209200"], ["84250.20", "2.607630"], ["84249.80", "0.988410"], ["84248.90", "1.350000"], ["84247.80", "0.069600"], ["84246.10", "0.197876"], ["84245.80", "1.195200"], ["84245.00", "0.142500"], ["84244.43", "0.023742"], ["84243.80", "0.069600"], ["84242.97", "0.023941"], ["84242.30", "0.038460"], ["84242.00", "0.196680"], ["84241.80", "0.095730"], ["84241.30", "0.090000"], ["84240.10", "0.009000"], ["84239.97", "0.209200"], ["84239.80", "0.069600"], ["84239.40", "0.090000"], ["84239.30", "0.177960"], ["84238.60", "0.142500"], ["84238.50", "0.090000"], ["84237.80", "0.069600"], ["84230.84", "0.209200"], ["84227.51", "0.001180"], ["84224.26", "0.017798"], ["84223.59", "0.001189"], ["84213.98", "0.209200"], ["84211.60", "4.609614"], ["84210.00", "0.002000"], ["84203.10", "4.880768"], ["84201.56", "0.209200"], ["84200.00", "0.000059"], ["84194.60", "3.886538"], ["84189.99", "0.209200"], ["84186.10", "4.157691"], ["84180.00", "0.000593"], ["84179.68", "0.072042"], ["84178.41", "0.209200"], ["84177.60", "5.513460"], ["84169.98", "0.209200"], ["84169.10", "4.971153"], ["84169.00", "0.012838"], ["84167.00", "0.000121"], ["84166.67", "0.000022"], ["84164.00", "0.000159"], ["84163.64", "0.000008"], ["84162.50", "0.000031"], ["84161.56", "0.209200"], ["84160.60", "4.699999"], ["84160.00", "0.024386"], ["84156.01", "0.000019"], ["84155.83", "0.000019"], ["84153.85", "0.000022"], ["84153.84", "0.000008"], ["84153.14", "0.209200"], ["84152.10", "3.976922"], ["84150.00", "0.002236"], ["84149.98", "0.005940"], ["84148.96", "0.000039"], ["84148.94", "0.000137"], ["84146.67", "0.000011"], ["84144.74", "0.000093"], ["84144.58", "0.000564"], ["84144.32", "0.125360"], ["84144.22", "0.209200"], ["84144.15", "0.000053"], ["84144.14", "0.000041"], ["84143.60", "5.423076"], ["84142.86", "0.000102"], ["84142.85", "0.000229"], ["84140.96", "0.000013"], ["84140.11", "0.000008"], ["84140.00", "0.000133"], ["84139.90", "0.000023"], ["84138.74", "0.000024"], ["84137.47", "0.000057"], ["84137.40", "0.000118"], ["84135.78", "0.209200"], ["84135.10", "4.248076"], ["84133.33", "0.000046"], ["84130.43", "0.003511"], ["84127.34", "0.209200"], ["84126.60", "5.151922"], ["84125.00", "0.000100"], ["84122.96", "0.000707"], ["84122.11", "0.000023"], ["84120.42", "0.000008"], ["84120.31", "0.000018"], ["84120.00", "0.000302"], ["84119.54", "0.000509"], ["84118.90", "0.209200"], ["84118.35", "0.000096"], ["84118.10", "4.067307"], ["84116.94", "0.000010"], ["84115.44", "0.000153"], ["84114.47", "0.000022"], ["84112.90", "0.000039"], ["84112.89", "0.000078"], ["84112.50", "0.000151"], ["84111.11", "0.000105"], ["84111.01", "0.000009"], ["84110.50", "0.000573"], ["84110.46", "0.209200"], ["84110.00", "0.002401"], ["84109.60", "4.338461"], ["84108.84", "0.000008"], ["84107.74", "0.000016"], ["84107.68", "0.000022"], ["84107.39", "0.000035"], ["84105.26", "0.000025"], ["84104.68", "0.000161"], ["84104.50", "0.310308"], ["84102.02", "0.209200"], ["84101.10", "5.332691"], ["84100.54", "0.000126"], ["84100.00", "0.002717"], ["84099.49", "0.000051"], ["84097.95", "0.000019"], ["84097.00", "0.000009"], ["84095.53", "0.000013"], ["84093.58", "0.209200"], ["84092.60", "4.428845"], ["84090.91", "0.000008"], ["84090.90", "0.000034"], ["84088.89", "0.000008"], ["84088.24", "0.000417"], ["84088.22", "0.000314"], ["84088.14", "0.000023"], ["84088.00", "0.000022"], ["84087.50", "0.000021"], ["84086.96", "0.000932"], ["84085.45", "0.000010"], ["84085.14", "0.209200"], ["84084.50", "0.000022"], ["84084.10", "5.242306"], ["84083.68", "0.000010"], ["84083.33", "0.000348"], ["84082.25", "0.000098"], ["84081.99", "0.000041"], ["84080.88", "0.000041"], ["84080.00", "0.000068"], ["84078.95", "0.000031"], ["84077.96", "0.000135"], ["84077.78", "0.000008"], ["84076.70", "0.209200"], ["84075.60", "5.603845"], ["84071.43", "0.000035"], ["84069.69", "0.000008"], ["84068.26", "0.209200"], ["84067.86", "0.000128"], ["84067.10", "5.061537"], ["84066.67", "0.000025"], ["84065.22", "0.000010"], ["84064.10", "0.000014"], ["84064.00", "0.000012"], ["84063.85", "0.000039"], ["84063.83", "0.000137"], ["84062.50", "0.000276"], ["84060.16", "0.000068"], ["84060.00", "0.000025"], ["84059.82", "0.209200"], ["84058.60", "4.790383"], ["84057.14", "0.000128"], ["84054.55", "0.000008"], ["84054.05", "0.000041"], ["84053.01", "0.000048"], ["84052.63", "0.000183"], ["84052.42", "0.000008"], ["84051.59", "0.000024"], ["84051.39", "0.209200"], ["84050.10", "4.519230"], ["84050.00", "0.000162"], ["84048.19", "0.000564"], ["84048.12", "0.000050"], ["84047.64", "0.000008"], ["84047.62", "0.000024"], ["84047.06", "0.000105"], ["84046.67", "0.000013"], ["84046.63", "0.000023"], ["84044.79", "0.000008"], ["84044.74", "0.000026"], ["84044.44", "0.000009"], ["84043.48", "0.000035"], ["84042.96", "0.209200"], ["84042.67", "0.000133"], ["84041.79", "0.000248"], ["84041.61", "0.002143"], ["84041.44", "0.000008"], ["84040.92", "0.000019"], ["84040.82", "0.000085"], ["84040.54", "0.186931"], ["84040.00", "0.024725"], ["84035.88", "0.000007"], ["84034.53", "0.209200"], ["84033.98", "0.000009"], ["84032.00", "0.000165"], ["84031.25", "0.000012"], ["84030.03", "0.000176"], ["84029.61", "0.000093"], ["84028.08", "0.000012"], ["84028.00", "0.000010"], ["84027.81", "0.000162"], ["84025.00", "0.000160"], ["84023.90", "0.000009"], ["84022.10", "0.000573"], ["84021.67", "0.000017"], ["84021.51", "0.000054"], ["84021.11", "0.000011"], ["84020.41", "0.000008"], ["84020.00", "0.000012"], ["84019.61", "0.000008"], ["84018.35", "0.000072"], ["84018.22", "0.000016"], ["84018.00", "0.022769"], ["84017.54", "0.000025"], ["84016.62", "0.000066"], ["84015.71", "0.000235"], ["84014.87", "0.000039"], ["84011.00", "0.000008"], ["84010.29", "0.000096"], ["84010.00", "0.000290"], ["84009.73", "0.000033"], ["84009.56", "0.005950"], ["84008.81", "0.000010"], ["84005.80", "0.000013"], ["84004.32", "0.000022"], ["84001.97", "0.000013"], ["84000.96", "0.000016"], ["84000.00", "0.024694"], ["83999.99", "0.000016"], ["83999.82", "0.000013"], ["83998.23", "0.000188"], ["83996.30", "0.305402"], ["83995.65", "0.000099"], ["83995.57", "0.000363"], ["83994.60", "0.025290"], ["83994.49", "0.000161"], ["83993.42", "0.000009"], ["83992.38", "0.209200"], ["83991.94", "0.000039"], ["83991.63", "0.000010"], ["83991.23", "0.000022"], ["83990.00", "0.000059"], ["83987.35", "0.000014"], ["83985.48", "0.000008"], ["83984.62", "0.000155"], ["83983.05", "0.000023"], ["83981.48", "0.000008"], ["83980.10", "0.000008"], ["83980.00", "0.000107"], ["83979.59", "0.000024"], ["83979.42", "0.000051"], ["83978.75", "0.000039"], ["83978.72", "0.000137"], ["83978.26", "0.000010"], ["83978.16", "0.000039"], ["83977.88", "0.000027"], ["83976.74", "0.000010"], ["83975.52", "0.000100"], ["83974.51", "0.000018"], ["83974.36", "0.000014"], ["83974.03", "0.000098"], ["83973.72", "0.000202"], ["83973.00", "0.000018"], ["83972.29", "0.000009"], ["83971.43", "0.000069"], ["83970.59", "0.000065"], ["83970.00", "0.002023"], ["83966.67", "0.000322"], ["83966.01", "0.000119"], ["83965.52", "0.000146"], ["83964.74", "0.000008"], ["83964.44", "0.000024"], ["83963.96", "0.000041"], ["83963.90", "0.000025"], ["83962.16", "0.000061"], ["83960.79", "0.000009"], ["83960.00", "0.000129"], ["83959.56", "0.000388"], ["83958.72", "0.000036"], ["83958.67", "0.000010"], ["83957.36", "0.000095"], ["83957.22", "0.000024"], ["83956.52", "0.000035"], ["83956.44", "0.000013"], ["83956.04", "0.000024"], ["83956.00", "0.000035"], ["83955.93", "0.000024"], ["83955.34", "0.000020"], ["83955.00", "0.001146"], ["83954.20", "0.305504"], ["83953.37", "0.000023"], ["83953.17", "0.000117"], ["83952.38", "0.000063"], ["83951.81", "0.000564"], ["83951.60", "0.000008"], ["83950.00", "0.000161"], ["83949.37", "0.000107"], ["83949.19", "0.000030"], ["83948.87", "0.000346"], ["83948.26", "0.000010"], ["83948.05", "0.000088"], ["83947.57", "0.000064"], ["83947.37", "0.000212"], ["83946.87", "1.660549"], ["83946.67", "0.000036"], ["83945.45", "0.000008"], ["83944.44", "0.000025"], ["83943.37", "0.000015"], ["83942.86", "0.000016"], ["83942.31", "0.000067"], ["83942.30", "0.000014"], ["83942.01", "0.000011"], ["83941.61", "0.000014"], ["83941.24", "0.000423"], ["83940.00", "0.002019"], ["83939.29", "0.000273"], ["83938.78", "0.000085"], ["83937.50", "0.000276"], ["83936.69", "0.000235"], ["83934.80", "0.000199"], ["83933.93", "0.000502"], ["83933.70", "0.000573"], ["83933.33", "0.000021"], ["83933.18", "0.000071"], ["83933.05", "0.000050"], ["83932.12", "0.002248"], ["83931.97", "0.000008"], ["83930.79", "0.000033"], ["83930.01", "0.000499"], ["83930.00", "0.000047"], ["83929.82", "0.000025"], ["83928.86", "0.000384"], ["83928.70", "0.000016"], ["83928.59", "0.000743"], ["83928.57", "0.000495"], ["83927.93", "0.000176"], ["83926.71", "0.000052"], ["83925.83", "0.000019"], ["83925.30", "0.000046"], ["83925.23", "0.000034"], ["83925.00", "0.000015"], ["83923.08", "0.000017"], ["83920.00", "0.025082"], ["83919.99", "0.000314"], ["83918.52", "0.000016"], ["83918.14", "0.000035"], ["83917.50", "0.000031"], ["83916.78", "0.000152"], ["83916.00", "0.000012"], ["83915.49", "0.000099"], ["83915.06", "0.000021"], ["83914.47", "0.000093"], ["83914.10", "0.000363"], ["83913.04", "0.017741"], ["83912.57", "0.000440"], ["83912.50", "0.000010"], ["83911.76", "0.000417"], ["83911.55", "0.000017"], ["83911.40", "0.000064"], ["83911.30", "0.000269"], ["83911.11", "0.000009"], ["83910.78", "0.000039"], ["83910.68", "0.000009"], ["83910.53", "0.000048"], ["83910.00", "0.002000"], ["83909.15", "0.000093"], ["83909.09", "0.000018"], ["83909.08", "0.000065"], ["83908.59", "0.000066"], ["83908.26", "0.000072"], ["83908.04", "0.000315"], ["83907.22", "0.000012"], ["83906.25", "0.000014"], ["83905.95", "0.000011"], ["83904.85", "0.000009"], ["83904.78", "0.000054"], ["83904.35", "0.000042"], ["83904.34", "0.000131"], ["83903.51", "0.000022"], ["83902.23", "0.000096"], ["83901.67", "0.000019"], ["83901.14", "0.000008"], ["83900.60", "0.000013"], ["83900.52", "0.000235"], ["83900.00", "0.002977"], ["83899.58", "0.000010"], ["83898.68", "0.000010"], ["83896.11", "0.000094"], ["83896.00", "0.000133"], ["83895.65", "0.000013"], ["83895.00", "0.006121"], ["83894.74", "0.000068"], ["83894.17", "0.000022"], ["83893.81", "0.000010"], ["83893.64", "0.000039"], ["83893.62", "0.000137"], ["83892.29", "0.000143"], ["83891.43", "0.000455"], ["83891.30", "0.000010"], ["83888.89", "0.000163"], ["83888.86", "0.000371"], ["83887.29", "0.000586"], ["83887.11", "0.000075"], ["83886.91", "0.000145"], ["83885.98", "0.000018"], ["83885.71", "0.000069"], ["83884.62", "0.000014"], ["83884.55", "0.000048"], ["83884.30", "0.000161"], ["83882.98", "0.000188"], ["83882.92", "0.002384"], ["83881.99", "0.000038"], ["83880.00", "0.020454"], ["83877.97", "0.000023"], ["83877.55", "0.000010"], ["83877.42", "0.000054"], ["83877.29", "0.000024"], ["83877.05", "0.000008"], ["83876.25", "0.000028"], ["83876.12", "0.000681"], ["83875.99", "0.000299"], ["83875.49", "0.000723"], ["83875.16", "0.000179"], ["83875.00", "0.000145"], ["83874.55", "0.000145"], ["83874.15", "0.000150"], ["83873.87", "0.000041"], ["83873.52", "0.000135"], ["83870.97", "0.000194"], ["83870.95", "0.000078"], ["83870.78", "0.000019"], ["83870.00", "0.000121"], ["83869.57", "0.000035"], ["83868.82", "0.000017"], ["83866.67", "0.000138"], ["83865.80", "0.000098"], ["83865.10", "0.000134"], ["83864.54", "0.000009"], ["83863.64", "0.000012"]], "checksum": 0, "ts": "1742142204264"}], "ts": 1742142204392, "record_time": 1742142203.549068}
{"action": "update", "arg": {"instType": "SPOT", "channel": "books", "instId": "BTCUSDT"}, "data": [{"asks": [["84277.52", "0.745649"], ["84289.72", "0.140144"], ["84289.95", "0.004595"], ["84290.05", "0.005541"], ["84290.06", "0.010074"], ["84290.08", "0.001066"], ["84290.10", "0.001475"], ["84290.14", "0.008962"], ["84290.19", "0.006307"], ["84290.86", "0.007955"], ["84290.88", "0.018101"], ["84290.89", "0.015378"], ["84290.91", "0.007385"], ["84290.92", "0.000078"], ["84290.97", "0.014986"], ["84291.53", "0.014953"], ["84291.96", "0"], ["84292.19", "0.080382"], ["84294.38", "0.209200"], ["84301.24", "0.035952"], ["84302.81", "0.006356"], ["84303.92", "0.006356"], ["84304.37", "0.006356"], ["84304.48", "0.006356"], ["84305.96", "0.006356"], ["84312.11", "0.001807"], ["84312.17", "0"], ["84312.28", "0"], ["84313.68", "0.015891"], ["84315.23", "0.075500"], ["84315.43", "0.010986"], ["84317.90", "0.119881"], ["84318.10", "0"], ["84319.30", "0.001019"], ["84320.10", "0"], ["84321.30", "0.001016"], ["84322.10", "0"], ["84323.30", "0.002621"], ["84324.10", "0"], ["84325.30", "0.006898"], ["84326.10", "0"], ["84327.30", "0.018152"], ["84327.32", "0.026414"], ["84328.10", "0"], ["84329.30", "0.047770"], ["84330.10", "0"], ["84331.30", "0.125709"], ["84332.10", "0"], ["84333.30", "0.330814"], ["84334.10", "0"], ["84335.30", "0.870564"], ["84336.10", "0"], ["84337.30", "2.290958"], ["84338.10", "0"], ["84339.10", "0"], ["84339.30", "6.028837"], ["84340.10", "0"], ["84340.20", "1.156560"], ["84340.90", "0.001004"], ["84341.00", "0.035790"], ["84341.10", "0.001008"], ["84341.20", "0.177900"], ["84342.20", "0.973560"], ["84343.40", "0.410370"], ["84344.00", "0.052650"], ["84344.20", "0.122250"], ["84344.60", "0.052650"], ["84344.90", "0.071190"], ["84345.10", "0.052830"], ["84345.30", "6.777600"], ["84345.50", "0"], ["84346.00", "0.035580"], ["84346.20", "0.069600"], ["84346.40", "0.269760"], ["84347.10", "0"], ["84347.30", "0"], ["84347.50", "1.613520"], ["84347.80", "0"], ["84347.90", "0.936510"], ["84348.10", "0.180000"], ["84348.80", "0.015420"], ["84348.90", "0.015060"], ["84349.20", "0.015060"], ["84349.30", "0"], ["84349.40", "0"], ["84350.20", "0.076650"], ["84350.60", "0"], ["84351.10", "3.559050"], ["84351.20", "0"], ["84351.50", "0"], ["84351.90", "0.035580"], ["84352.70", "2.657010"], ["84354.20", "0"], ["84380.20", "0"], ["84381.40", "4.428781"], ["84388.70", "0"], ["84389.90", "4.248014"], ["84397.20", "0"], ["84398.40", "5.513380"], ["84405.70", "0"], ["84406.90", "4.971080"], ["84414.20", "0"], ["84415.40", "5.422996"], ["84422.70", "0"], ["84423.90", "4.338397"], ["84431.20", "0"], ["84432.40", "3.886481"], ["84439.70", "0"], ["84440.90", "4.067247"], ["84448.20", "0"], ["84449.40", "5.242230"], ["84456.70", "0"], ["84457.90", "4.699930"], ["84465.20", "0"], ["84466.40", "4.880697"], ["84473.70", "0"], ["84474.90", "4.790314"], ["84482.20", "0"], ["84483.40", "3.976864"], ["84490.70", "0"], ["84491.90", "5.603763"], ["84499.20", "0"], ["84500.40", "4.157631"], ["84507.70", "0"], ["84508.90", "4.609547"], ["84516.20", "0"], ["84517.40", "4.519164"], ["84524.70", "0"], ["84525.90", "5.151847"], ["84533.20", "0"], ["84534.40", "5.061463"], ["84541.70", "0"], ["84542.90", "5.332613"], ["84852.81", "0"], ["84852.94", "0"], ["84853.56", "0"], ["84857.14", "0"], ["84858.75", "0"], ["84859.29", "0"], ["84860.00", "0"], ["84862.90", "0"], ["84864.69", "0"], ["84864.86", "0"], ["84864.99", "0"], ["84866.10", "0"], ["84866.40", "0"], ["84867.80", "0"], ["84868.42", "0"], ["84868.52", "0"], ["84868.65", "0"], ["84869.57", "0"], ["84871.66", "0"], ["84871.79", "0"], ["84873.84", "0"], ["84874.79", "0"], ["84875.00", "0"], ["84875.78", "0"], ["84876.03", "0"], ["84879.10", "0"], ["84879.37", "0"], ["84879.59", "0"], ["84880.00", "0"], ["84880.89", "0"], ["84882.35", "0"], ["84883.31", "0"], ["84883.65", "0"], ["84883.72", "0"], ["84883.84", "0"]], "bids": [["84277.51", "2.951457"], ["84275.79", "0.142373"], ["84275.78", "0"], ["84274.90", "0.001016"], ["84273.70", "0"], ["84272.90", "0.001044"], ["84272.63", "0"], ["84271.70", "0"], ["84271.68", "0"], ["84271.05", "0"], ["84270.90", "0.001019"], ["84269.70", "0"], ["84269.57", "0"], ["84269.55", "0.012223"], ["84269.22", "0.000070"], ["84269.08", "0.209200"], ["84268.92", "0.771355"], ["84268.90", "0.001007"], ["84267.70", "0"], ["84267.64", "0"], ["84266.90", "0.001360"], ["84265.70", "0"], ["84265.18", "0.000213"], ["84265.08", "0.001228"], ["84265.05", "0.007646"], ["84265.04", "0.008537"], ["84265.02", "0.006529"], ["84264.90", "0.003581"], ["84263.76", "0.007440"], ["84263.74", "0.008554"], ["84263.72", "0.012749"], ["84263.70", "0.008988"], ["84263.66", "0.007346"], ["84263.44", "0.001199"], ["84262.90", "0.009422"], ["84262.23", "0.008146"], ["84262.17", "0.007875"], ["84261.70", "0"], ["84261.43", "0"], ["84260.90", "0.024567"], ["84260.65", "0.007475"], ["84259.70", "0"], ["84259.32", "0.066845"], ["84258.90", "0.064651"], ["84258.00", "0.005550"], ["84257.91", "0.000875"], ["84257.90", "0.005089"], ["84257.86", "0.008156"], ["84257.83", "0.009633"], ["84257.70", "0"], ["84257.41", "0.084444"], ["84256.90", "0.170134"], ["84256.54", "0.008674"], ["84256.46", "0.010237"], ["84256.41", "0.015772"], ["84256.21", "0.107469"], ["84255.70", "0"], ["84254.90", "0.447721"], ["84254.31", "0.017062"], ["84254.08", "0.263346"], ["84253.74", "0.008989"], ["84253.70", "0.019470"], ["84253.60", "0"], ["84253.50", "0.001025"], ["84252.30", "0"], ["84252.20", "0"], ["84252.00", "0.053310"], ["84251.80", "0"], ["84251.60", "0"], ["84251.40", "0"], ["84250.20", "0"], ["84249.80", "0"], ["84248.90", "0"], ["84247.80", "0"], ["84245.80", "0"], ["84244.63", "0.056642"], ["84244.57", "0.073510"], ["84243.80", "0"], ["84242.00", "0"], ["84241.80", "2.703570"], ["84241.60", "1.061130"], ["84241.50", "0.918810"], ["84241.30", "0"], ["84240.50", "0.383790"], ["84239.40", "0"], ["84239.30", "0"], ["84239.26", "0.008209"], ["84238.50", "0"], ["84237.80", "0"], ["84237.00", "1.759920"], ["84235.90", "0.177960"], ["84235.60", "2.669430"], ["84235.50", "0.012000"], ["84235.20", "0.030000"], ["84235.01", "0.007585"], ["84234.94", "0.007187"], ["84212.80", "5.603763"], ["84211.60", "0"], ["84204.30", "4.699930"], ["84203.10", "0"], ["84195.80", "4.338397"], ["84194.60", "0"], ["84187.30", "5.422996"], ["84186.10", "0"], ["84178.80", "5.513380"], ["84177.60", "0"], ["84170.30", "4.248014"], ["84169.10", "0"], ["84161.80", "5.332613"], ["84160.60", "0"], ["84153.30", "4.971080"], ["84152.10", "0"], ["84144.80", "4.428781"], ["84143.60", "0"], ["84136.30", "4.609547"], ["84135.10", "0"], ["84127.80", "4.790314"], ["84126.60", "0"], ["84119.30", "4.519164"], ["84118.10", "0"], ["84110.80", "3.976864"], ["84109.60", "0"], ["84102.30", "4.880697"], ["84101.10", "0"], ["84093.80", "4.067247"], ["84092.60", "0"], ["84085.30", "5.151847"], ["84084.10", "0"], ["84076.80", "5.242230"], ["84075.60", "0"], ["84068.30", "5.061463"], ["84067.10", "0"], ["84059.80", "4.157631"], ["84058.60", "0"], ["84051.30", "3.886481"], ["84050.10", "0"], ["84036.61", "0.027250"], ["83876.12", "0"], ["83875.99", "0"], ["83875.49", "0"], ["83875.16", "0"], ["83875.00", "0"], ["83874.55", "0"], ["83874.15", "0"], ["83873.87", "0"], ["83873.52", "0"], ["83870.97", "0"], ["83870.95", "0"], ["83870.78", "0"], ["83870.00", "0"], ["83869.57", "0"], ["83868.82", "0"], ["83866.67", "0"], ["83865.80", "0"], ["83865.10", "0"], ["83864.54", "0"], ["83863.64", "0"]], "checksum": -1993456665, "ts": "1742142204468"}], "ts": 1742142204473, "record_time": 1742142203.582066}
{"action": "update", "arg": {"instType": "SPOT", "channel": "books", "instId": "BTCUSDT"}, "data": [{"asks": [["84283.49", "0.063814"], ["84289.71", "0.053449"], ["84290.03", "0.004974"], ["84290.92", "0.004817"], ["84291.53", "0.151017"], ["84295.49", "0.000292"], ["84298.66", "0.119869"], ["84300.80", "0.006356"], ["84300.83", "0.006356"], ["84301.63", "0.010985"], ["84301.83", "0.006356"], ["84301.95", "0"], ["84302.31", "0.006356"], ["84303.66", "0.006356"], ["84303.91", "0.006356"], ["84304.05", "0"], ["84305.65", "0.006356"], ["84306.53", "0"], ["84306.91", "0"], ["84307.05", "0"], ["84307.15", "0"], ["84307.45", "0"], ["84308.38", "0"], ["84308.58", "1.924536"], ["84309.45", "0"], ["84310.02", "0.119881"], ["84311.38", "0"], ["84312.79", "0.148098"], ["84313.33", "0"], ["84314.56", "0"], ["84317.90", "0"], ["84323.30", "0.002882"], ["84325.12", "0.031812"], ["84325.30", "0.007584"], ["84325.44", "2.202526"], ["84327.30", "0.019957"], ["84329.30", "0.052518"], ["84331.30", "0.138205"], ["84331.80", "0.001597"], ["84333.30", "0.363699"], ["84334.17", "0"], ["84335.30", "0.957101"], ["84337.30", "2.518689"], ["84339.30", "6.628129"], ["84340.20", "0.943980"], ["84341.00", "0.024810"], ["84344.00", "0"], ["84344.20", "0.069600"], ["84344.60", "0"], ["84345.10", "0"], ["84345.30", "6.408180"], ["84350.70", "0.032910"], ["84351.50", "0.288000"], ["84352.70", "1.945950"], ["84353.70", "0.360270"], ["84354.20", "0.007050"], ["84381.40", "4.157631"], ["84389.90", "4.067247"], ["84398.40", "5.603763"], ["84406.90", "4.790314"], ["84415.40", "4.248014"], ["84423.90", "4.971080"], ["84425.84", "0"], ["84432.40", "4.609547"], ["84440.90", "3.976864"], ["84449.40", "5.332613"], ["84457.90", "4.428781"], ["84466.40", "4.338397"], ["84474.90", "4.880697"], ["84483.40", "5.242230"], ["84491.90", "5.061463"], ["84500.40", "5.422996"], ["84508.90", "5.513380"], ["84517.40", "4.699930"], ["84534.40", "3.886481"], ["84542.90", "4.519164"], ["84621.16", "0"], ["84847.82", "0"], ["84849.88", "0"], ["84850.00", "0"], ["84851.66", "0"]], "bids": [["84277.51", "2.774491"], ["84275.79", "0"], ["84272.64", "0.026853"], ["84269.22", "0"], ["84268.92", "0"], ["84266.90", "0.001002"], ["84265.09", "0.007515"], ["84264.90", "0.001032"], ["84262.90", "0.001027"], ["84262.75", "0"], ["84262.49", "0.002062"], ["84262.24", "0"], ["84261.52", "0"], ["84261.27", "0"], ["84260.90", "0.001700"], ["84260.76", "0"], ["84260.57", "0.007955"], ["84260.01", "0"], ["84259.33", "0.014825"], ["84259.18", "0"], ["84258.90", "0.004475"], ["84258.71", "0"], ["84258.37", "0"], ["84258.23", "2.546842"], ["84257.89", "0.004937"], ["84257.36", "0.248017"], ["84256.90", "0.011775"], ["84256.59", "0"], ["84256.13", "0.017837"], ["84255.83", "0.018262"], ["84255.20", "0.007120"], ["84255.14", "0.016461"], ["84255.12", "0"], ["84254.90", "0.030988"], ["84254.30", "0.001037"], ["84254.21", "0"], ["84254.00", "0.001004"], ["84253.93", "0.017080"], ["84253.76", "0.056358"], ["84253.70", "0.018420"], ["84253.50", "0"], ["84252.93", "0.007934"], ["84252.27", "0.017333"], ["84252.00", "0.096210"], ["84250.87", "0.012650"], ["84249.82", "0.002950"], ["84246.50", "0.052380"], ["84246.10", "0"], ["84245.00", "0.197430"], ["84242.30", "0.216420"], ["84241.80", "5.668200"], ["84239.30", "0.177960"], ["84239.10", "2.349450"], ["84239.00", "0.451110"], ["84238.60", "0"], ["84237.00", "0"], ["84235.90", "0"], ["84235.60", "0"], ["84235.50", "0"], ["84235.20", "0"], ["84223.59", "0"], ["84221.23", "0.001189"], ["84216.10", "0.207047"], ["84212.80", "4.157631"], ["84204.30", "5.061463"], ["84195.80", "4.699930"], ["84187.30", "4.248014"], ["84178.80", "5.603763"], ["84170.30", "4.067247"], ["84166.00", "0.000159"], ["84161.80", "3.886481"], ["84144.80", "4.880697"], ["84136.30", "3.976864"], ["84127.80", "4.338397"], ["84119.30", "5.513380"], ["84110.80", "5.242230"], ["84102.30", "4.519164"], ["84093.80", "5.422996"], ["84085.30", "4.428781"], ["84076.80", "5.151847"], ["84068.30", "5.332613"], ["84059.80", "4.790314"], ["84051.30", "4.609547"], ["83946.87", "0"], ["83877.05", "0"], ["83876.25", "0"]], "checksum": 48471874, "ts": "1742142204669"}], "ts": 1742142204679, "record_time": 1742142203.787448}
{"action": "update", "arg": {"instType": "SPOT", "channel": "books", "instId": "BTCUSDT"}, "data": [{"asks": [["84283.48", "0.019144"], ["84285.95", "0.209200"], ["84289.72", "0"], ["84295.49", "0"], ["84296.42", "0.001205"], ["84301.31", "0.006356"], ["84304.20", "0.006356"], ["84307.28", "0.119895"], ["84308.37", "0.119879"], ["84308.58", "0"], ["84309.95", "0"], ["84316.40", "0.001003"], ["84318.40", "0.001745"], ["84319.30", "0"], ["84320.40", "0.004593"], ["84321.30", "0"], ["84322.40", "0.012088"], ["84323.30", "0"], ["84324.40", "0.031810"], ["84325.12", "0"], ["84325.30", "0"], ["84325.44", "0"], ["84326.40", "0.083710"], ["84327.30", "0"], ["84328.40", "0.220290"], ["84329.30", "0"], ["84330.40", "0.579709"], ["84331.30", "0"], ["84332.40", "1.525552"], ["84333.30", "0"], ["84334.40", "4.014610"], ["84335.30", "0"], ["84336.40", "10.564763"], ["84336.70", "0.001013"], ["84337.00", "2.369910"], ["84337.30", "0.001041"], ["84337.80", "0.001046"], ["84338.20", "0.069600"], ["84339.30", "0.617040"], ["84340.20", "0.069600"], ["84340.90", "0"], ["84341.00", "0"], ["84341.10", "0"], ["84341.20", "0.177690"], ["84342.20", "0.973260"], ["84342.80", "0.936510"], ["84343.10", "0.035580"], ["84344.40", "0.423750"], ["84345.90", "0.015060"], ["84346.00", "0"], ["84346.10", "0.015090"], ["84346.40", "0.015150"], ["84346.90", "3.694770"], ["84347.90", "0"], ["84348.60", "0.319770"], ["84348.80", "0"], ["84348.90", "0"], ["84349.20", "0.117000"], ["84350.00", "0.180000"], ["84350.10", "0.135000"], ["84351.50", "0"], ["84351.80", "0"], ["84351.90", "0"], ["84352.70", "0"], ["84353.70", "0"], ["84354.20", "0"], ["84370.73", "0.072042"], ["84378.50", "5.332797"], ["84381.40", "0"], ["84387.00", "4.880865"], ["84389.90", "0"], ["84395.50", "4.428933"], ["84398.40", "0"], ["84404.00", "4.609706"], ["84406.90", "0"], ["84412.50", "4.790478"], ["84415.40", "0"], ["84421.00", "5.152024"], ["84423.90", "0"], ["84429.50", "3.977001"], ["84432.40", "0"], ["84438.00", "4.248160"], ["84440.90", "0"], ["84446.50", "4.700092"], ["84449.40", "0"], ["84455.00", "4.971251"], ["84457.90", "0"], ["84463.50", "5.061638"], ["84466.40", "0"], ["84472.00", "5.423183"], ["84474.90", "0"], ["84480.50", "3.886615"], ["84483.40", "0"], ["84489.00", "5.603956"], ["84491.90", "0"], ["84497.50", "5.242410"], ["84500.40", "0"], ["84506.00", "4.338547"], ["84508.90", "0"], ["84514.50", "4.157774"], ["84517.40", "0"], ["84523.00", "5.513569"], ["84525.90", "0"], ["84531.50", "4.067387"], ["84534.40", "0"], ["84540.00", "4.519319"], ["84542.90", "0"], ["84631.39", "1.656316"], ["84846.55", "0"], ["84846.85", "0"], ["84847.58", "0"]], "bids": [["84277.51", "2.688611"], ["84274.90", "0"], ["84273.78", "0.012680"], ["84272.90", "0"], ["84272.00", "0.001033"], ["84270.90", "0"], ["84270.00", "0.001013"], ["84269.09", "0.072863"], ["84268.90", "0"], ["84268.79", "0.000070"], ["84268.00", "0.001050"], ["84266.90", "0"], ["84266.00", "0.001021"], ["84264.90", "0"], ["84264.00", "0.001025"], ["84262.90", "0"], ["84262.00", "0.001018"], ["84260.90", "0"], ["84260.00", "0.002189"], ["84259.32", "0.058578"], ["84258.90", "0"], ["84258.60", "0.003069"], ["84258.20", "0"], ["84258.00", "0.005760"], ["84256.90", "0"], ["84256.00", "0.015159"], ["84255.68", "0.005938"], ["84254.90", "0"], ["84254.30", "0"], ["84254.00", "0.040082"], ["84253.70", "0"], ["84252.46", "0.008165"], ["84252.00", "0.105481"], ["84251.40", "0.001230"], ["84251.38", "0.194852"], ["84250.90", "0.001024"], ["84250.70", "0.418080"], ["84250.30", "0.001037"], ["84248.96", "0.271918"], ["84248.60", "0.414720"], ["84248.03", "0.222746"], ["84247.50", "0.627390"], ["84246.50", "0.052560"], ["84245.00", "0.229950"], ["84242.30", "0.038460"], ["84241.80", "2.161200"], ["84241.60", "0"], ["84239.30", "0"], ["84238.60", "0.142500"], ["84237.00", "0.425160"], ["84236.60", "0.177960"], ["84235.50", "0.012000"], ["84234.30", "0.090000"], ["84234.00", "1.151130"], ["84212.80", "0"], ["84209.90", "5.242410"], ["84204.30", "0"], ["84201.40", "5.513569"], ["84195.80", "0"], ["84192.90", "4.428933"], ["84187.30", "0"], ["84184.40", "4.338547"], ["84178.80", "0"], ["84175.90", "5.152024"], ["84170.30", "0"], ["84169.00", "0.012717"], ["84167.40", "5.603956"], ["84161.80", "0"], ["84158.90", "4.157774"], ["84153.30", "0"], ["84150.40", "5.061638"], ["84144.80", "0"], ["84141.90", "3.977001"], ["84136.30", "0"], ["84133.40", "4.790478"], ["84127.80", "0"], ["84124.90", "3.886615"], ["84119.30", "0"], ["84116.40", "4.067387"], ["84110.80", "0"], ["84107.90", "4.971251"], ["84102.30", "0"], ["84099.40", "4.880865"], ["84093.80", "0"], ["84090.90", "4.700092"], ["84085.30", "0"], ["84082.40", "4.248160"], ["84076.80", "0"], ["84073.90", "4.609706"], ["84068.30", "0"], ["84065.40", "5.332797"], ["84059.80", "0"], ["84056.90", "4.519319"], ["84051.30", "0"], ["84048.40", "5.423183"], ["83957.03", "1.661683"], ["83885.98", "0"], ["83885.71", "0"], ["83884.62", "0"], ["83884.55", "0"], ["83884.30", "0"], ["83882.98", "0"], ["83882.92", "0"], ["83881.99", "0"], ["83880.00", "0"], ["83877.97", "0"], ["83877.55", "0"], ["83877.42", "0"], ["83877.29", "0"]], "checksum": 825958288, "ts": "1742142204871"}], "ts": 1742142204876, "record_time": 1742142203.984018}
{"action": "update", "arg": {"instType": "SPOT", "channel": "books", "instId": "BTCUSDT"}, "data": [{"asks": [["84277.52", "1.036591"], ["84279.17", "0.063817"], ["84283.48", "0.079511"], ["84283.49", "0"], ["84285.59", "0.140142"], ["84285.65", "0.004595"], ["84285.79", "0.005541"], ["84285.80", "0.001066"], ["84285.81", "0.015048"], ["84285.82", "0.000245"], ["84285.85", "0.008962"], ["84285.89", "0.006307"], ["84286.62", "0.009117"], ["84286.63", "0.011557"], ["84286.65", "0.020799"], ["84286.67", "0.007385"], ["84286.69", "0.004739"], ["84286.70", "0.014986"], ["84289.71", "0"], ["84289.95", "0"], ["84290.02", "0.011520"], ["84290.03", "0"], ["84290.05", "0"], ["84290.06", "0"], ["84290.08", "0"], ["84290.10", "0"], ["84290.14", "0"], ["84290.19", "0"], ["84290.86", "0"], ["84290.88", "0"], ["84290.89", "0"], ["84290.91", "0"], ["84290.92", "0"], ["84290.97", "0"], ["84302.23", "0.006356"], ["84302.27", "0.016428"], ["84304.00", "0.006357"], ["84305.58", "0.009989"], ["84308.18", "0"], ["84308.81", "0"], ["84310.11", "0"], ["84312.34", "0"], ["84312.92", "0.031812"], ["84315.10", "0.001012"], ["84316.40", "0"], ["84317.10", "0.001199"], ["84318.40", "0"], ["84319.10", "0.003328"], ["84320.40", "0"], ["84321.10", "0.008759"], ["84322.40", "0"], ["84323.10", "0.023050"], ["84324.40", "0"], ["84325.10", "0.060657"], ["84326.40", "0"], ["84327.10", "0.159624"], ["84328.40", "0"], ["84329.10", "0.420064"], ["84330.40", "0"], ["84331.10", "1.105430"], ["84332.40", "0"], ["84333.10", "2.909026"], ["84334.40", "0"], ["84335.10", "7.655332"], ["84335.30", "0.001041"], ["84335.40", "0.001042"], ["84335.80", "0.248640"], ["84336.20", "0.069810"], ["84336.40", "15.710760"], ["84336.70", "0"], ["84337.00", "0"], ["84337.30", "0"], ["84337.80", "0"], ["84339.20", "0.009000"], ["84339.30", "0.835020"], ["84341.20", "0"], ["84344.70", "0.015150"], ["84345.10", "0.015120"], ["84345.90", "0"], ["84346.40", "0"], ["84349.00", "0.035580"], ["84350.00", "0"], ["84350.10", "0"], ["84350.20", "0"], ["84350.70", "0"], ["84351.10", "0"], ["84377.20", "4.971327"], ["84378.50", "0"], ["84385.70", "4.609776"], ["84387.00", "0"], ["84394.20", "5.423266"], ["84395.50", "0"], ["84402.70", "4.157837"], ["84404.00", "0"], ["84411.20", "4.338613"], ["84412.50", "0"], ["84419.70", "3.977062"], ["84421.00", "0"], ["84428.20", "4.790552"], ["84429.50", "0"], ["84436.70", "5.152103"], ["84438.00", "0"], ["84445.20", "4.248225"], ["84446.50", "0"], ["84453.70", "5.332878"], ["84455.00", "0"], ["84462.20", "5.061715"], ["84463.50", "0"], ["84470.70", "3.886674"], ["84472.00", "0"], ["84479.20", "5.604042"], ["84480.50", "0"], ["84487.70", "4.880939"], ["84489.00", "0"], ["84496.20", "4.067450"], ["84497.50", "0"], ["84504.70", "5.242490"], ["84506.00", "0"], ["84513.20", "4.519388"], ["84514.50", "0"], ["84521.70", "4.700164"], ["84523.00", "0"], ["84530.20", "4.429001"], ["84531.50", "0"], ["84538.70", "5.513654"], ["84540.00", "0"], ["84846.55", "0.000019"], ["84846.85", "0.000176"]], "bids": [["84272.64", "0"], ["84272.00", "0"], ["84270.70", "0.001004"], ["84270.00", "0"], ["84268.79", "0"], ["84268.70", "0.001012"], ["84268.00", "0"], ["84267.02", "0.003007"], ["84266.70", "0.001026"], ["84266.00", "0"], ["84265.95", "0.000070"], ["84265.18", "0"], ["84265.09", "0"], ["84265.08", "0"], ["84265.05", "0"], ["84265.04", "0"], ["84265.02", "0"], ["84264.70", "0.001028"], ["84264.00", "0"], ["84263.76", "0"], ["84263.74", "0"], ["84263.72", "0"], ["84263.70", "0"], ["84263.66", "0"], ["84263.60", "0.010000"], ["84263.44", "0"], ["84262.70", "0.001009"], ["84262.49", "0"], ["84262.23", "0"], ["84262.17", "0"], ["84262.00", "0"], ["84260.86", "0.000213"], ["84260.80", "0.007515"], ["84260.77", "0.001228"], ["84260.73", "0.022671"], ["84260.70", "0.002018"], ["84260.65", "0"], ["84260.57", "0"], ["84260.00", "0"], ["84259.43", "0.008554"], ["84259.39", "0.007440"], ["84259.36", "0.008988"], ["84259.34", "0.012749"], ["84259.32", "1.009164"], ["84259.09", "0"], ["84259.07", "0.001199"], ["84258.96", "0"], ["84258.70", "0.005312"], ["84258.45", "0"], ["84258.27", "0.002062"], ["84258.00", "0"], ["84257.97", "0.008146"], ["84257.91", "0"], ["84257.90", "0"], ["84257.89", "0"], ["84257.86", "0.007875"], ["84257.83", "0"], ["84256.70", "0.013979"], ["84256.54", "0"], ["84256.46", "0"], ["84256.37", "0.007475"], ["84256.34", "0"], ["84256.21", "0.171413"], ["84256.00", "0"], ["84255.87", "0"], ["84254.70", "0.036785"], ["84254.00", "0"], ["84253.71", "0.005550"], ["84253.65", "0.000875"], ["84253.64", "0.004937"], ["84253.60", "0.008151"], ["84253.59", "0.005089"], ["84253.52", "0.009633"], ["84253.47", "0"], ["84252.70", "0.096803"], ["84252.54", "0.028809"], ["84252.51", "0.007317"], ["84252.24", "0.008674"], ["84252.15", "0.025086"], ["84252.08", "0.010237"], ["84252.00", "0"], ["84251.40", "0"], ["84251.15", "0"], ["84250.90", "0"], ["84250.70", "0.254987"], ["84250.30", "0"], ["84250.23", "0.008284"], ["84249.12", "0.018521"], ["84249.00", "0.002160"], ["84248.60", "0"], ["84248.50", "0.001010"], ["84247.60", "0.053580"], ["84247.50", "0"], ["84247.10", "0.001015"], ["84247.07", "0.021110"], ["84247.00", "0.032070"], ["84246.50", "0"], ["84245.00", "0"], ["84244.19", "0.012440"], ["84242.30", "0"], ["84241.80", "0.808890"], ["84241.50", "0"], ["84239.80", "0"], ["84239.40", "0.177960"], ["84239.30", "0.216420"], ["84239.26", "0"], ["84239.10", "0"], ["84237.00", "0.778470"], ["84236.60", "0"], ["84235.50", "0"], ["84235.01", "0"], ["84234.97", "0.008209"], ["84234.94", "0"], ["84234.50", "0.918810"], ["84233.90", "1.527960"], ["84233.40", "2.223270"], ["84233.10", "0.090000"], ["84232.30", "2.759430"], ["84232.20", "0.142500"], ["84232.10", "0.090000"], ["84232.00", "2.684520"], ["84230.64", "0.007187"], ["84230.63", "0.007585"], ["84209.90", "0"], ["84208.60", "3.977062"], ["84201.40", "0"], ["84200.10", "4.338613"], ["84192.90", "0"], ["84191.60", "4.429001"], ["84184.40", "0"], ["84183.10", "5.152103"], ["84175.90", "0"], ["84174.60", "5.332878"], ["84167.40", "0"], ["84166.10", "4.067450"], ["84158.90", "0"], ["84157.60", "5.604042"], ["84150.40", "0"], ["84149.10", "5.061715"], ["84141.90", "0"], ["84140.60", "4.157837"], ["84133.40", "0"], ["84132.10", "5.242490"], ["84124.90", "0"], ["84123.60", "5.423266"], ["84116.40", "0"], ["84115.10", "4.609776"], ["84107.90", "0"], ["84106.60", "4.971327"], ["84099.40", "0"], ["84098.10", "4.700164"], ["84090.90", "0.000034"], ["84089.60", "4.790552"], ["84082.40", "0"], ["84081.10", "3.886674"], ["84073.90", "0"], ["84072.60", "4.519388"], ["84065.40", "0"], ["84064.10", "4.880939"], ["84056.90", "0"], ["84055.60", "5.513654"], ["84048.40", "0"], ["84047.10", "4.248225"], ["83885.98", "0.000018"]], "checksum": -765107925, "ts": "1742142205073"}], "ts": 1742142205080, "record_time": 1742142204.189084}
{"action": "update", "arg": {"instType": "SPOT", "channel": "books", "instId": "BTCUSDT"}, "data": [{"asks": [["84277.52", "0.745649"], ["84279.16", "0.019145"], ["84285.84", "0.001230"], ["84286.62", "0.026957"], ["84286.67", "0.007463"], ["84288.30", "0.000292"], ["84290.02", "0"], ["84301.39", "1.924586"], ["84312.92", "0"], ["84317.10", "0.001330"], ["84318.25", "2.202476"], ["84319.10", "0.003632"], ["84321.10", "0.009557"], ["84322.50", "0.031812"], ["84323.10", "0.025151"], ["84325.10", "0.066187"], ["84327.10", "0.174175"], ["84329.10", "0.458357"], ["84331.10", "1.206203"], ["84333.10", "3.174218"], ["84335.10", "8.353204"], ["84335.80", "0.143340"], ["84336.40", "12.116730"], ["84336.80", "0.035580"], ["84337.70", "0.410370"], ["84343.40", "0"], ["84345.30", "5.652540"], ["84346.50", "0.032910"], ["84349.20", "0"], ["84377.20", "5.061715"], ["84385.70", "4.880939"], ["84394.20", "3.886674"], ["84402.70", "5.513654"], ["84411.20", "3.977062"], ["84419.70", "5.332878"], ["84428.20", "5.242490"], ["84436.70", "4.338613"], ["84445.20", "4.429001"], ["84453.70", "4.790552"], ["84462.20", "4.157837"], ["84470.70", "5.152103"], ["84479.20", "5.423266"], ["84487.70", "4.971327"], ["84496.20", "5.604042"], ["84504.70", "4.248225"], ["84513.20", "4.067450"], ["84521.70", "4.519388"], ["84530.20", "4.609776"], ["84538.70", "4.700164"], ["84845.00", "0"], ["84845.94", "0"], ["84846.15", "0"], ["84846.55", "0"], ["84846.85", "0"]], "bids": [["84272.63", "0.030445"], ["84265.95", "0"], ["84262.70", "0.001903"], ["84260.70", "0.005008"], ["84258.70", "0.013181"], ["84256.70", "0.034687"], ["84256.34", "0.007955"], ["84254.70", "0.091281"], ["84252.70", "0.240213"], ["84250.70", "0.632140"], ["84250.20", "0.002430"], ["84250.10", "0.001003"], ["84249.00", "0.001950"], ["84248.80", "0.339780"], ["84248.50", "0"], ["84247.60", "0.052560"], ["84247.10", "0"], ["84247.00", "0.059220"], ["84245.10", "0.627300"], ["84241.80", "0.404100"], ["84239.40", "0"], ["84234.30", "0"], ["84232.10", "0"], ["84232.00", "0"], ["84230.85", "0.067546"], ["84208.60", "5.242490"], ["84200.10", "5.513654"], ["84191.60", "5.423266"], ["84183.10", "4.971327"], ["84174.60", "5.604042"], ["84166.10", "4.338613"], ["84157.60", "4.790552"], ["84149.10", "4.429001"], ["84140.60", "4.609776"], ["84132.10", "4.880939"], ["84123.60", "4.519388"], ["84115.10", "4.700164"], ["84106.60", "5.061715"], ["84098.10", "5.332878"], ["84089.60", "4.067450"], ["84081.10", "4.157837"], ["84072.60", "3.977062"], ["84064.10", "5.152103"], ["84055.60", "3.886674"]], "checksum": 1595979700, "ts": "1742142205275"}], "ts": 1742142205280, "record_time": 1742142204.389312}
{"action": "update", "arg": {"instType": "SPOT", "channel": "books", "instId": "BTCUSDT"}, "data": [{"asks": [["84277.52", "0.744459"], ["84285.95", "0"], ["84298.65", "0.035961"], ["84319.10", "0.003268"], ["84321.10", "0.008599"], ["84322.50", "0"], ["84323.10", "0.022631"], ["84325.10", "0.059555"], ["84327.10", "0.156723"], ["84329.10", "0.412429"], ["84331.10", "1.085340"], ["84333.10", "2.856158"], ["84335.10", "7.516465"], ["84335.80", "0.143970"], ["84336.20", "0.069600"], ["84336.40", "8.337690"], ["84344.70", "0"], ["84345.10", "0"], ["84346.70", "0.106800"], ["84347.60", "0.015210"], ["84348.00", "0.015120"], ["84348.60", "0.177270"], ["84349.00", "0"], ["84349.98", "0"], ["84370.73", "0"], ["84377.20", "5.513654"], ["84385.70", "4.609776"], ["84393.46", "0"], ["84394.20", "5.242490"], ["84397.71", "0"], ["84402.70", "4.700164"], ["84411.20", "5.332878"], ["84419.70", "4.971327"], ["84428.20", "4.248225"], ["84436.70", "4.429001"], ["84445.20", "4.157837"], ["84453.70", "4.880939"], ["84462.20", "5.061715"], ["84479.20", "4.338613"], ["84487.70", "5.604042"], ["84496.20", "4.067450"], ["84504.70", "3.977062"], ["84513.20", "5.423266"], ["84521.70", "4.790552"], ["84530.20", "3.886674"], ["84538.70", "4.519388"], ["84845.00", "0.000025"], ["84845.94", "0.000008"], ["84846.15", "0.004277"], ["84846.55", "0.000019"], ["84846.85", "0.000176"]], "bids": [["84273.79", "0.003804"], ["84264.70", "0.001630"], ["84262.70", "0.004289"], ["84260.70", "0.011287"], ["84258.70", "0.029702"], ["84256.70", "0.078163"], ["84256.21", "0.255515"], ["84254.70", "0.205692"], ["84252.70", "0.541296"], ["84250.70", "1.424462"], ["84249.70", "0.001041"], ["84249.00", "0.001740"], ["84248.80", "0.001019"], ["84247.00", "0.059040"], ["84245.10", "0"], ["84245.00", "0.239430"], ["84242.30", "0.177960"], ["84241.80", "1.059060"], ["84240.00", "2.349690"], ["84237.70", "1.080180"], ["84237.00", "0"], ["84233.90", "1.350000"], ["84232.30", "0.090000"], ["84232.20", "0"], ["84208.60", "4.429001"], ["84200.10", "4.790552"], ["84191.60", "3.886674"], ["84183.10", "5.152103"], ["84174.60", "5.242490"], ["84166.10", "4.609776"], ["84164.00", "0"], ["84157.60", "3.977062"], ["84149.10", "4.248225"], ["84140.60", "5.332878"], ["84132.10", "4.067450"], ["84123.60", "5.604042"], ["84115.10", "4.157837"], ["84106.60", "5.423266"], ["84098.10", "4.971327"], ["84089.60", "4.700164"], ["84081.10", "4.880939"], ["84072.60", "5.061715"], ["84064.10", "4.519388"], ["84055.60", "5.513654"], ["84047.10", "4.338613"], ["83886.91", "0"], ["83885.98", "0"]], "checksum": 606785653, "ts": "1742142205476"}], "ts": 1742142205482, "record_time": 1742142204.590656}
{"action": "update", "arg": {"instType": "SPOT", "channel": "books", "instId": "BTCUSDT"}, "data": [{"asks": [["84279.11", "0.063817"], ["84279.16", "0"], ["84279.17", "0"], ["84283.48", "0.052548"], ["84317.10", "0.001204"], ["84321.10", "0.008338"], ["84323.10", "0.021942"], ["84325.10", "0.057743"], ["84327.10", "0.151956"], ["84329.10", "0.399885"], ["84331.10", "1.052328"], ["84333.10", "2.769285"], ["84335.10", "7.287592"], ["84335.80", "0.001050"], ["84336.20", "0"], ["84336.80", "0"], ["84337.70", "0.824610"], ["84338.20", "0"], ["84340.20", "0"], ["84344.40", "0"], ["84348.60", "0.319770"], ["84377.20", "3.977062"], ["84385.70", "4.519388"], ["84394.20", "4.338613"], ["84402.70", "4.248225"], ["84411.20", "4.157837"], ["84419.70", "5.423266"], ["84425.84", "0.209200"], ["84428.20", "5.152103"], ["84436.70", "4.609776"], ["84445.20", "4.880939"], ["84453.70", "4.429001"], ["84462.20", "4.067450"], ["84470.70", "4.971327"], ["84479.20", "5.604042"], ["84487.70", "4.700164"], ["84496.20", "5.242490"], ["84504.70", "3.886674"], ["84513.20", "5.513654"], ["84520.51", "0.001720"], ["84521.70", "5.061715"], ["84530.20", "4.790552"], ["84538.70", "5.332878"], ["84847.58", "0.000039"], ["84847.82", "0.000671"], ["84849.88", "0.000030"], ["84850.00", "0.000031"]], "bids": [["84264.70", "0.001528"], ["84262.70", "0.004022"], ["84260.70", "0.010585"], ["84258.70", "0.027854"], ["84257.74", "0.003036"], ["84256.70", "0.073300"], ["84254.70", "0.192894"], ["84252.70", "0.507617"], ["84250.70", "1.335833"], ["84240.50", "0.803160"], ["84232.30", "0"], ["84208.60", "3.886674"], ["84200.10", "4.700164"], ["84191.60", "4.429001"], ["84183.10", "4.971327"], ["84174.60", "5.152103"], ["84168.00", "0.000121"], ["84166.10", "4.880939"], ["84149.10", "5.604042"], ["84140.60", "4.609776"], ["84132.10", "5.423266"], ["84123.60", "4.067450"], ["84115.10", "5.061715"], ["84106.60", "4.157837"], ["84098.10", "5.332878"], ["84089.60", "4.338613"], ["84081.10", "4.790552"], ["84072.60", "4.519388"], ["84064.10", "5.242490"], ["84055.60", "4.248225"], ["84047.10", "5.513654"], ["83887.11", "0"]], "checksum": -1296110616, "ts": "1742142205683"}], "ts": 1742142205687, "record_time": 1742142204.794215}
{"action": "update", "arg": {"instType": "SPOT", "channel": "books", "instId": "BTCUSDT"}, "data": [{"asks": [["84277.52", "0.953659"], ["84285.59", "0"], ["84285.95", "0.209200"], ["84317.10", "0.001404"], ["84318.24", "0.661723"], ["84319.10", "0.003696"], ["84321.10", "0.009725"], ["84323.10", "0.025769"], ["84325.10", "0.067814"], ["84327.10", "0.178457"], ["84329.10", "0.469625"], ["84331.10", "1.235855"], ["84333.10", "3.252248"], ["84335.10", "8.558548"], ["84335.80", "0.143550"], ["84336.80", "0.035580"], ["84339.30", "0.834300"], ["84341.30", "0.071160"], ["84346.50", "0.204660"], ["84346.70", "0"], ["84370.71", "0.072042"], ["84377.20", "4.880939"], ["84385.70", "5.513654"], ["84394.20", "5.332878"], ["84402.70", "4.519388"], ["84411.20", "5.604042"], ["84419.70", "4.700164"], ["84436.70", "4.971327"], ["84445.20", "3.886674"], ["84453.70", "5.423266"], ["84462.20", "4.790552"], ["84470.70", "5.242490"], ["84479.20", "4.067450"], ["84487.70", "5.061715"], ["84496.20", "4.429001"], ["84504.70", "4.338613"], ["84513.20", "4.248225"], ["84521.70", "4.609776"], ["84530.20", "3.977062"], ["84538.70", "4.157837"], ["84847.82", "0"], ["84849.88", "0"], ["84850.00", "0"]], "bids": [["84274.22", "0.010000"], ["84273.79", "0"], ["84273.78", "0"], ["84265.39", "0.000070"], ["84264.70", "0.001034"], ["84263.60", "0"], ["84262.70", "0.001048"], ["84260.70", "0.001010"], ["84259.29", "0.012680"], ["84258.70", "0.001035"], ["84256.70", "0.001009"], ["84254.70", "0.002052"], ["84252.70", "0.005400"], ["84250.70", "0.014210"], ["84247.00", "0.059220"], ["84245.00", "0"], ["84242.30", "0"], ["84241.80", "0.404100"], ["84240.00", "0"], ["84239.40", "0.177960"], ["84237.70", "0.621780"], ["84233.90", "0"], ["84233.10", "0"], ["84232.30", "2.349630"], ["84208.60", "4.157837"], ["84200.10", "4.519388"], ["84191.60", "4.338613"], ["84183.10", "4.248225"], ["84174.60", "4.429001"], ["84166.10", "3.886674"], ["84157.60", "4.971327"], ["84149.10", "4.609776"], ["84140.60", "5.242490"], ["84132.10", "3.977062"], ["84115.10", "4.790552"], ["84106.60", "4.700164"], ["84098.10", "5.513654"], ["84089.60", "5.604042"], ["84081.10", "5.423266"], ["84072.60", "5.061715"], ["84064.10", "5.332878"], ["84055.60", "4.880939"], ["84047.10", "5.152103"], ["83887.11", "0.000075"], ["83886.91", "0.000145"], ["83885.98", "0.000018"]], "checksum": 1180220441, "ts": "1742142205888"}], "ts": 1742142205891, "record_time": 1742142205.005684}
{"action": "update", "arg": {"instType": "SPOT", "channel": "books", "instId": "BTCUSDT"}, "data": [{"asks": [["84277.52", "0.808278"], ["84279.10", "0.019145"], ["84279.11", "0"], ["84282.43", "0.140138"], ["84323.88", "0.031812"], ["84337.50", "0.936510"], ["84341.30", "0"], ["84342.80", "0"], ["84346.50", "0.032910"], ["84349.00", "0.035580"], ["84377.20", "5.604042"], ["84385.70", "4.157837"], ["84394.20", "5.513654"], ["84402.70", "5.332878"], ["84411.20", "4.519388"], ["84419.70", "4.429001"], ["84428.20", "4.880939"], ["84436.70", "4.248225"], ["84445.20", "5.061715"], ["84453.70", "3.886674"], ["84462.20", "3.977062"], ["84470.70", "5.152103"], ["84479.20", "4.609776"], ["84487.70", "5.423266"], ["84496.20", "5.242490"], ["84504.70", "4.790552"], ["84513.20", "4.067450"], ["84521.70", "4.700164"], ["84530.20", "4.338613"], ["84538.70", "4.971327"], ["84846.85", "0"], ["84847.58", "0"]], "bids": [["84277.51", "2.633459"], ["84274.23", "0.003000"], ["84262.70", "0.001011"], ["84260.70", "0.001021"], ["84258.70", "0.001001"], ["84256.70", "0.001008"], ["84256.21", "0.006565"], ["84249.30", "0.001019"], ["84249.10", "0.302430"], ["84249.00", "0"], ["84248.80", "0"], ["84245.60", "0.645450"], ["84245.00", "0.185670"], ["84239.00", "0"], ["84237.70", "1.626930"], ["84235.50", "2.349540"], ["84234.00", "1.061130"], ["84233.90", "1.350000"], ["84232.30", "2.669430"], ["84232.20", "0.142500"], ["84208.60", "5.242490"], ["84200.11", "0.221024"], ["84200.10", "5.513654"], ["84191.60", "4.157837"], ["84183.10", "4.338613"], ["84174.60", "4.519388"], ["84166.10", "4.067450"], ["84165.00", "0.000159"], ["84157.60", "4.700164"], ["84149.10", "5.423266"], ["84140.60", "5.604042"], ["84132.10", "3.886674"], ["84123.60", "4.790552"], ["84115.10", "5.061715"], ["84106.60", "4.971327"], ["84098.10", "4.609776"], ["84089.60", "3.977062"], ["84081.10", "4.248225"], ["84072.60", "5.152103"], ["84064.10", "4.880939"], ["84055.60", "5.332878"], ["84047.10", "4.429001"], ["83891.30", "0"], ["83888.89", "0"], ["83888.86", "0"], ["83887.29", "0"], ["83887.11", "0"], ["83886.91", "0"], ["83885.98", "0"]], "checksum": -1875862875, "ts": "1742142206087"}], "ts": 1742142206092, "record_time": 1742142205.199738}
{"action": "update", "arg": {"instType": "SPOT", "channel": "books", "instId": "BTCUSDT"}, "data": [{"asks": [["84277.52", "1.003152"], ["84279.10", "0"], ["84282.42", "0.117700"], ["84283.48", "0"], ["84301.86", "0.119843"], ["84308.83", "0"], ["84313.50", "0.001132"], ["84315.10", "0"], ["84315.50", "0.001964"], ["84317.10", "0"], ["84317.50", "0.005168"], ["84319.10", "0"], ["84319.50", "0.013601"], ["84321.10", "0"], ["84321.50", "0.035793"], ["84323.10", "0"], ["84323.50", "0.094191"], ["84323.88", "0"], ["84325.10", "0"], ["84325.50", "0.247870"], ["84327.10", "0"], ["84327.50", "0.652403"], ["84327.51", "0.031812"], ["84329.10", "0"], ["84329.50", "1.716851"], ["84331.10", "0"], ["84331.50", "4.518028"], ["84333.10", "0"], ["84333.50", "11.889548"], ["84333.70", "0.001010"], ["84334.50", "0.001018"], ["84334.60", "0.001048"], ["84335.10", "4.757880"], ["84335.30", "0"], ["84335.40", "0"], ["84335.80", "0.142500"], ["84336.40", "3.943260"], ["84339.30", "0.373440"], ["84340.20", "0.035580"], ["84341.20", "0.015120"], ["84341.60", "0.015120"], ["84342.80", "0.015090"], ["84343.10", "0"], ["84344.20", "0.186600"], ["84345.00", "0.180000"], ["84345.70", "0.198000"], ["84345.80", "0.090000"], ["84346.10", "0.035580"], ["84347.60", "0"], ["84348.00", "0"], ["84348.60", "0"], ["84349.00", "0"], ["84375.60", "4.609864"], ["84377.20", "0"], ["84384.10", "4.429085"], ["84385.70", "0"], ["84392.60", "5.423369"], ["84394.20", "0"], ["84401.10", "5.152201"], ["84402.70", "0"], ["84409.60", "4.338695"], ["84411.20", "0"], ["84418.10", "3.977137"], ["84419.70", "0"], ["84426.60", "5.061811"], ["84428.20", "0"], ["84435.10", "4.881032"], ["84436.70", "0"], ["84443.60", "5.513758"], ["84445.20", "0"], ["84452.10", "4.067527"], ["84453.70", "0"], ["84460.60", "5.242590"], ["84462.20", "0"], ["84469.10", "4.157916"], ["84470.70", "0"], ["84477.60", "4.971422"], ["84479.20", "0"], ["84486.10", "5.332979"], ["84487.70", "0"], ["84494.60", "4.519474"], ["84496.20", "0"], ["84503.10", "3.886748"], ["84504.70", "0"], ["84511.60", "5.604148"], ["84513.20", "0"], ["84520.10", "4.790643"], ["84521.70", "0"], ["84528.60", "4.700253"], ["84530.20", "0"], ["84537.10", "4.248306"], ["84538.70", "0"], ["84845.94", "0"], ["84846.15", "0"], ["84846.55", "0"]], "bids": [["84277.45", "0.055152"], ["84270.70", "0"], ["84269.10", "0.001049"], ["84268.70", "0"], ["84268.65", "0.000070"], ["84267.10", "0.001032"], ["84266.70", "0"], ["84265.39", "0"], ["84265.10", "0.001008"], ["84264.70", "0"], ["84263.10", "0.001038"], ["84262.70", "0"], ["84261.10", "0.001966"], ["84260.70", "0"], ["84259.10", "0.005173"], ["84258.70", "0"], ["84257.42", "0"], ["84257.10", "0.013615"], ["84256.70", "0"], ["84255.10", "0.035828"], ["84254.70", "0"], ["84254.08", "0"], ["84253.10", "0.094284"], ["84252.70", "0"], ["84251.10", "0.248115"], ["84250.70", "0"], ["84250.45", "0.227687"], ["84250.20", "0"], ["84250.10", "0"], ["84249.70", "0"], ["84249.30", "0"], ["84249.10", "0.652934"], ["84249.00", "0.002160"], ["84248.50", "0.001034"], ["84247.60", "0.053580"], ["84247.00", "0.059850"], ["84246.50", "1.062660"], ["84246.41", "0.263346"], ["84245.70", "0.077550"], ["84245.60", "0"], ["84245.00", "0.142680"], ["84241.80", "0.392010"], ["84233.90", "0"], ["84232.00", "2.669430"], ["84231.20", "0.177600"], ["84231.00", "0.030000"], ["84230.40", "0.451110"], ["84208.60", "0"], ["84207.00", "4.700253"], ["84200.10", "0"], ["84198.50", "4.248306"], ["84191.60", "0"], ["84190.00", "5.332979"], ["84183.10", "0"], ["84181.50", "3.886748"], ["84174.60", "0"], ["84173.00", "5.242590"], ["84166.10", "0"], ["84164.50", "4.157916"], ["84157.60", "0"], ["84156.00", "5.152201"], ["84149.10", "0"], ["84147.50", "5.513758"], ["84140.60", "0"], ["84139.00", "4.338695"], ["84132.10", "0"], ["84130.50", "4.429085"], ["84123.60", "0"], ["84122.00", "3.977137"], ["84115.10", "0"], ["84113.50", "4.790643"], ["84106.60", "0"], ["84105.00", "5.061811"], ["84098.10", "0"], ["84096.50", "5.423369"], ["84089.60", "0"], ["84088.00", "4.881032"], ["84081.10", "0"], ["84079.50", "4.519474"], ["84072.60", "0"], ["84071.00", "4.067527"], ["84064.10", "0.000014"], ["84062.50", "5.604148"], ["84055.60", "0"], ["84054.00", "4.971422"], ["84047.10", "0"], ["84045.50", "4.609864"], ["83891.43", "0"]], "checksum": -1903938940, "ts": "1742142206301"}], "ts": 1742142206305, "record_time": 1742142205.413701}
{"action": "update", "arg": {"instType": "SPOT", "channel": "books", "instId": "BTCUSDT"}, "data": [{"asks": [["84277.52", "0.808278"], ["84305.50", "0.010000"], ["84315.50", "0.001688"], ["84317.50", "0.004442"], ["84319.50", "0.011691"], ["84321.50", "0.030764"], ["84323.50", "0.080960"], ["84325.50", "0.213051"], ["84327.50", "0.560661"], ["84329.50", "1.475423"], ["84331.50", "3.882693"], ["84333.50", "10.217612"], ["84335.10", "3.780180"], ["84342.19", "0.344889"], ["84384.10", "5.423369"], ["84392.60", "5.604148"], ["84401.10", "3.977137"], ["84409.60", "4.248306"], ["84418.10", "4.338695"], ["84426.60", "4.790643"], ["84435.10", "5.061811"], ["84443.60", "4.429085"], ["84460.60", "4.881032"], ["84469.10", "5.332979"], ["84477.60", "5.513758"], ["84486.10", "5.242590"], ["84503.10", "4.971422"], ["84511.60", "3.886748"], ["84520.10", "5.152201"], ["84528.60", "4.157916"], ["84537.10", "4.700253"], ["84844.53", "0"], ["84845.00", "0"]], "bids": [["84277.46", "0.019546"], ["84274.23", "0"], ["84268.65", "0"], ["84250.95", "0.289093"], ["84247.50", "0.592080"], ["84247.00", "0.059220"], ["84246.50", "0.245880"], ["84245.70", "0.066270"], ["84243.80", "0.069600"], ["84239.00", "0.265440"], ["84238.00", "2.349480"], ["84235.50", "0"], ["84232.10", "0.030390"], ["84231.00", "0"], ["84230.40", "0"], ["84207.00", "4.609864"], ["84200.11", "0"], ["84198.50", "4.881032"], ["84190.00", "5.242590"], ["84181.50", "5.423369"], ["84173.00", "4.519474"], ["84167.00", "0"], ["84164.50", "3.886748"], ["84156.00", "4.429085"], ["84147.50", "4.700253"], ["84139.00", "5.513758"], ["84130.50", "4.971422"], ["84122.00", "4.157916"], ["84113.50", "5.604148"], ["84096.50", "4.248306"], ["84088.00", "5.332979"], ["84079.50", "5.152201"], ["84071.00", "4.790643"], ["84062.50", "4.067527"], ["84054.00", "4.338695"], ["84045.50", "3.977137"], ["83891.43", "0.000455"]], "checksum": 394209688, "ts": "1742142206508"}], "ts": 1742142206511, "record_time": 1742142205.619308}
{"action": "update", "arg": {"instType": "SPOT", "channel": "books", "instId": "BTCUSDT"}, "data": [{"asks": [["84313.50", "0.001017"], ["84319.50", "0.011494"], ["84321.50", "0.030246"], ["84323.50", "0.079595"], ["84325.50", "0.209461"], ["84327.50", "0.551213"], ["84327.51", "0"], ["84329.50", "1.450297"], ["84331.50", "3.816572"], ["84333.50", "10.043609"], ["84333.80", "0.267210"], ["84334.70", "0.269760"], ["84335.10", "1.941540"], ["84336.40", "3.943680"], ["84336.80", "0"], ["84337.50", "0"], ["84337.70", "0.414240"], ["84343.00", "0.410370"], ["84343.70", "0.936510"], ["84346.20", "0.081930"], ["84347.50", "0"], ["84348.10", "0"], ["84370.71", "0"], ["84375.60", "5.061811"], ["84384.10", "4.429085"], ["84392.60", "3.886748"], ["84401.10", "4.609864"], ["84409.60", "4.157916"], ["84418.10", "5.513758"], ["84426.60", "3.977137"], ["84435.10", "5.604148"], ["84443.60", "4.790643"], ["84452.10", "4.248306"], ["84460.60", "4.700253"], ["84469.10", "4.519474"], ["84477.60", "5.332979"], ["84486.10", "4.338695"], ["84494.60", "4.067527"], ["84511.60", "5.152201"], ["84520.10", "4.881032"], ["84528.60", "5.242590"], ["84537.10", "5.423369"], ["84844.53", "0.000423"], ["84845.00", "0.000025"]], "bids": [["84272.14", "0.000070"], ["84263.10", "0.002001"], ["84261.10", "0.005266"], ["84259.10", "0.013859"], ["84257.10", "0.036472"], ["84255.10", "0.095978"], ["84253.10", "0.252574"], ["84251.10", "0.664668"], ["84249.10", "1.749125"], ["84249.00", "0.001048"], ["84247.60", "0.053370"], ["84247.50", "0"], ["84247.00", "0.059040"], ["84246.50", "0"], ["84245.70", "0.043080"], ["84245.00", "0.142500"], ["84243.80", "0"], ["84241.80", "1.170480"], ["84240.70", "0.265440"], ["84240.60", "2.349420"], ["84239.00", "0"], ["84238.00", "0"], ["84237.70", "0.621780"], ["84233.70", "0.030000"], ["84232.10", "0"], ["84231.20", "0"], ["84207.00", "3.977137"], ["84198.50", "5.152201"], ["84190.00", "5.423369"], ["84181.50", "4.700253"], ["84173.00", "4.971422"], ["84164.50", "4.790643"], ["84156.00", "5.332979"], ["84147.50", "5.513758"], ["84139.00", "5.242590"], ["84130.50", "4.338695"], ["84122.00", "4.067527"], ["84113.50", "4.609864"], ["84105.00", "4.157916"], ["84096.50", "4.881032"], ["84088.00", "5.061811"], ["84079.50", "5.604148"], ["84071.00", "3.886748"], ["84062.50", "4.248306"], ["84054.00", "4.519474"], ["84045.50", "4.429085"], ["83891.30", "0.000010"], ["83888.89", "0.000163"], ["83888.86", "0.000371"]], "checksum": 205474398, "ts": "1742142206710"}], "ts": 1742142206713, "record_time": 1742142205.820676}
{"action": "update", "arg": {"instType": "SPOT", "channel": "books", "instId": "BTCUSDT"}, "data": [{"asks": [["84301.38", "0.629180"], ["84315.50", "0.001797"], ["84317.50", "0.004731"], ["84319.50", "0.012449"], ["84321.50", "0.032761"], ["84323.50", "0.086213"], ["84325.50", "0.226875"], ["84327.50", "0.597041"], ["84329.50", "1.571160"], ["84331.50", "4.134632"], ["84333.50", "10.880609"], ["84335.10", "1.350660"], ["84346.20", "0.069600"], ["84347.50", "1.613520"], ["84374.96", "0.072042"], ["84375.60", "4.609864"], ["84384.10", "5.604148"], ["84392.60", "4.248306"], ["84401.10", "4.790643"], ["84409.60", "4.971422"], ["84418.10", "4.429085"], ["84426.60", "3.886748"], ["84435.10", "5.423369"], ["84443.60", "3.977137"], ["84452.10", "4.700253"], ["84460.60", "5.152201"], ["84469.10", "4.157916"], ["84477.60", "4.519474"], ["84486.10", "5.242590"], ["84494.60", "5.513758"], ["84503.10", "5.061811"], ["84511.60", "5.332979"], ["84528.60", "4.338695"], ["84537.10", "4.067527"], ["84842.11", "0"], ["84844.53", "0"], ["84845.00", "0"]], "bids": [["84263.10", "0.001013"], ["84261.10", "0.001967"], ["84259.10", "0.005177"], ["84257.10", "0.013625"], ["84255.10", "0.035855"], ["84253.10", "0.094353"], ["84251.10", "0.248299"], ["84249.10", "0.653418"], ["84232.50", "0.090000"], ["84232.00", "0"], ["84207.00", "4.338695"], ["84198.50", "4.790643"], ["84190.00", "4.157916"], ["84181.50", "4.609864"], ["84173.00", "5.423369"], ["84166.00", "0"], ["84164.50", "4.881032"], ["84147.50", "5.604148"], ["84139.00", "5.061811"], ["84130.50", "4.700253"], ["84122.00", "3.886748"], ["84113.50", "4.248306"], ["84105.00", "5.513758"], ["84096.50", "4.519474"], ["84088.00", "3.977137"], ["84079.50", "4.067527"], ["84071.00", "5.152201"], ["84062.50", "4.429085"], ["84054.00", "4.971422"], ["84045.50", "5.242590"], ["83887.29", "0.000586"]], "checksum": 1300699076, "ts": "1742142206915"}], "ts": 1742142206918, "record_time": 1742142206.025452}
{"action": "update", "arg": {"instType": "SPOT", "channel": "books", "instId": "BTCUSDT"}, "data": [{"asks": [["84313.50", "0.001119"], ["84319.50", "0.012647"], ["84321.50", "0.033281"], ["84323.50", "0.087581"], ["84325.50", "0.230478"], ["84327.50", "0.606360"], ["84329.49", "1.108314"], ["84329.50", "1.595685"], ["84331.50", "4.199169"], ["84333.50", "11.050446"], ["84333.80", "0.001008"], ["84335.20", "0.011400"], ["84342.19", "0"], ["84347.50", "0"], ["84375.60", "4.338695"], ["84392.60", "5.061811"], ["84401.10", "4.429085"], ["84409.60", "5.513758"], ["84418.10", "5.152201"], ["84426.60", "5.242590"], ["84435.10", "4.700253"], ["84452.10", "4.248306"], ["84460.60", "5.423369"], ["84469.10", "4.067527"], ["84477.60", "4.881032"], ["84486.10", "4.609864"], ["84494.60", "4.157916"], ["84503.10", "4.790643"], ["84511.60", "4.971422"], ["84520.10", "4.519474"], ["84528.60", "3.886748"], ["84537.10", "5.332979"]], "bids": [["84273.45", "0.000070"], ["84272.14", "0"], ["84251.10", "0.248157"], ["84249.10", "0.653046"], ["84247.30", "0.655920"], ["84246.00", "0.273420"], ["84245.70", "0"], ["84234.50", "0.948810"], ["84233.70", "0"], ["84198.50", "4.429085"], ["84190.00", "5.513758"], ["84181.50", "5.152201"], ["84173.00", "4.609864"], ["84169.00", "0.012838"], ["84164.50", "3.886748"], ["84156.00", "4.248306"], ["84147.50", "4.700253"], ["84139.00", "5.332979"], ["84130.50", "4.971422"], ["84122.00", "4.790643"], ["84113.50", "4.157916"], ["84105.00", "5.061811"], ["84096.50", "4.067527"], ["84088.00", "5.604148"], ["84079.50", "5.242590"], ["84071.00", "4.519474"], ["84062.50", "5.423369"], ["84054.00", "4.881032"], ["84045.50", "3.977137"]], "checksum": -266284105, "ts": "1742142207126"}], "ts": 1742142207130, "record_time": 1742142206.23802}
{"action": "update", "arg": {"instType": "SPOT", "channel": "books", "instId": "BTCUSDT"}, "data": [{"asks": [["84277.52", "0.807799"], ["84282.42", "0"], ["84282.43", "0"], ["84285.95", "0"], ["84286.62", "0.009117"], ["84294.38", "0"], ["84305.50", "0"], ["84315.50", "0.001015"], ["84317.50", "0.001026"], ["84319.50", "0.001096"], ["84321.50", "0.001025"], ["84323.50", "0.001931"], ["84325.50", "0.005082"], ["84327.50", "0.013372"], ["84329.50", "0.035190"], ["84331.50", "0.092605"], ["84333.50", "0.243697"], ["84333.60", "0.001024"], ["84334.60", "0"], ["84334.70", "0"], ["84335.10", "0"], ["84335.20", "0"], ["84335.80", "0"], ["84336.40", "0"], ["84337.70", "0.618840"], ["84338.20", "2.349030"], ["84338.70", "0.265950"], ["84339.30", "0.056520"], ["84340.20", "0"], ["84342.20", "0.142500"], ["84343.00", "0"], ["84343.70", "0"], ["84343.80", "0.489570"], ["84344.20", "0"], ["84345.00", "0"], ["84345.20", "1.779300"], ["84345.30", "3.139350"], ["84345.70", "0"], ["84345.80", "0"], ["84346.20", "0"], ["84347.50", "1.613520"], ["84348.60", "0.319770"], ["84350.10", "0.135000"], ["84350.20", "0.076650"], ["84350.80", "0.012540"], ["84374.96", "0"], ["84375.60", "5.423369"], ["84384.10", "5.061811"], ["84392.60", "4.971422"], ["84409.60", "4.881032"], ["84418.10", "4.338695"], ["84426.60", "4.157916"], ["84434.27", "0.209200"], ["84435.10", "3.886748"], ["84443.60", "4.519474"], ["84452.10", "4.609864"], ["84460.60", "5.332979"], ["84477.60", "4.248306"], ["84486.10", "5.513758"], ["84494.60", "5.604148"], ["84511.60", "5.152201"], ["84520.10", "4.700253"], ["84528.60", "3.977137"], ["84537.10", "5.242590"], ["84842.11", "0.000068"], ["84844.53", "0.000423"], ["84845.00", "0.000025"], ["84845.94", "0.000008"], ["84846.15", "0.004277"], ["84846.55", "0.000019"], ["84846.85", "0.000176"], ["84847.58", "0.000039"], ["84847.82", "0.000671"]], "bids": [["84277.51", "2.715265"], ["84276.14", "0.140120"], ["84274.22", "0"], ["84273.45", "0"], ["84265.10", "0.001282"], ["84263.10", "0.003374"], ["84261.10", "0.008878"], ["84259.29", "0"], ["84259.10", "0.023364"], ["84257.10", "0.061485"], ["84255.10", "0.161802"], ["84253.10", "0.425794"], ["84251.10", "1.120511"], ["84249.10", "2.948714"], ["84248.90", "0.343560"], ["84248.80", "0.645990"], ["84248.70", "2.349180"], ["84248.50", "0"], ["84247.80", "0.069600"], ["84247.60", "0.265440"], ["84247.30", "0"], ["84247.00", "0.197880"], ["84246.00", "0.334260"], ["84243.80", "0.069600"], ["84242.70", "0.918810"], ["84241.80", "0.791010"], ["84240.70", "1.350000"], ["84240.60", "0"], ["84237.70", "0.451830"], ["84234.50", "0"], ["84234.40", "0.030000"], ["84233.90", "0.410370"], ["84232.30", "0.248880"], ["84232.20", "0"], ["84207.00", "4.971422"], ["84198.50", "3.977137"], ["84190.00", "5.423369"], ["84181.50", "4.338695"], ["84164.50", "4.067527"], ["84156.00", "5.061811"], ["84147.50", "5.604148"], ["84139.00", "4.248306"], ["84130.50", "5.513758"], ["84122.00", "5.152201"], ["84113.50", "4.790643"], ["84105.00", "3.886748"], ["84096.50", "4.700253"], ["84088.00", "4.157916"], ["84079.50", "5.332979"], ["84071.00", "4.881032"], ["84062.50", "4.519474"], ["84054.00", "4.429085"], ["84045.50", "5.242590"], ["83887.29", "0"]], "checksum": -497431090, "ts": "1742142207327"}], "ts": 1742142207332, "record_time": 1742142206.44083}
{"action": "update", "arg": {"instType": "SPOT", "channel": "books", "instId": "BTCUSDT"}, "data": [{"asks": [["84307.27", "0.119924"], ["84313.50", "0.001013"], ["84323.50", "0.001568"], ["84325.50", "0.004125"], ["84327.50", "0.010856"], ["84329.49", "0.092037"], ["84329.50", "0.028570"], ["84331.50", "0.075182"], ["84333.50", "0.197848"], ["84334.00", "0.004110"], ["84337.70", "0.414240"], ["84338.20", "0"], ["84338.70", "0"], ["84338.90", "0.599430"], ["84339.30", "0.811500"], ["84340.10", "0.333360"], ["84342.20", "0"], ["84343.00", "2.348910"], ["84345.20", "0"], ["84345.30", "1.540470"], ["84345.60", "0.265950"], ["84346.10", "0"], ["84349.40", "0.936510"], ["84350.80", "0"], ["84375.60", "4.157916"], ["84384.10", "4.700253"], ["84401.10", "4.248306"], ["84409.60", "4.609864"], ["84418.10", "4.790643"], ["84426.60", "4.338695"], ["84435.10", "4.519474"], ["84443.60", "5.152201"], ["84452.10", "5.423369"], ["84460.60", "4.881032"], ["84469.10", "3.977137"], ["84477.60", "5.513758"], ["84486.10", "3.886748"], ["84503.10", "5.061811"], ["84511.60", "4.429085"], ["84520.10", "5.242590"], ["84528.60", "5.332979"], ["84537.10", "4.067527"], ["84847.82", "0"]], "bids": [["84277.46", "0.056138"], ["84265.10", "0.002738"], ["84263.10", "0.007204"], ["84261.10", "0.018958"], ["84259.10", "0.049891"], ["84257.10", "0.131292"], ["84255.10", "0.345505"], ["84253.10", "0.909224"], ["84251.10", "2.392695"], ["84249.10", "6.296565"], ["84248.90", "1.016640"], ["84247.60", "0"], ["84246.00", "0.042990"], ["84242.70", "0"], ["84240.20", "0.410370"], ["84240.00", "0.025350"], ["84237.70", "0.090810"], ["84237.60", "0.090000"], ["84237.30", "0.030000"], ["84236.60", "0.090000"], ["84234.40", "0"], ["84234.30", "0.090000"], ["84234.00", "0"], ["84233.90", "0"], ["84232.50", "0"], ["84232.30", "0"], ["84230.85", "0"], ["84222.42", "0.000595"], ["84207.00", "4.700253"], ["84198.50", "4.881032"], ["84190.00", "4.157916"], ["84181.50", "4.248306"], ["84173.00", "5.423369"], ["84164.50", "5.152201"], ["84156.00", "4.971422"], ["84147.50", "4.338695"], ["84139.00", "4.067527"], ["84130.50", "5.061811"], ["84122.00", "5.242590"], ["84113.50", "5.513758"], ["84105.00", "5.604148"], ["84096.50", "4.429085"], ["84088.00", "5.332979"], ["84079.50", "3.886748"], ["84071.00", "4.790643"], ["84062.50", "4.609864"], ["84054.00", "3.977137"], ["84045.50", "4.519474"], ["83887.29", "0.000586"]], "checksum": -506489436, "ts": "1742142207529"}], "ts": 1742142207532, "record_time": 1742142206.640719}
{"action": "update", "arg": {"instType": "SPOT", "channel": "books", "instId": "BTCUSDT"}, "data": [{"asks": [["84289.02", "0.140119"], ["84329.49", "0"], ["84333.50", "0.197718"], ["84333.80", "0.009300"], ["84334.00", "0.001014"], ["84334.50", "0"], ["84350.10", "0"], ["84375.60", "5.332979"], ["84384.10", "5.152201"], ["84392.60", "4.429085"], ["84401.10", "3.977137"], ["84409.60", "5.604148"], ["84426.60", "4.971422"], ["84435.10", "4.881032"], ["84443.60", "5.513758"], ["84452.10", "4.248306"], ["84460.60", "5.423369"], ["84469.10", "5.061811"], ["84477.60", "4.519474"], ["84486.10", "4.338695"], ["84494.60", "3.886748"], ["84503.10", "4.067527"], ["84511.60", "4.609864"], ["84520.10", "4.700253"], ["84528.60", "4.157916"], ["84537.10", "5.242590"], ["84847.82", "0.000671"], ["84849.88", "0.000030"]], "bids": [["84277.51", "2.715425"], ["84255.11", "0.235955"], ["84238.50", "0.090000"], ["84238.20", "0.030000"], ["84237.70", "0.133470"], ["84237.30", "0"], ["84236.90", "0.090000"], ["84236.70", "0.090000"], ["84234.30", "0"], ["84233.40", "0"], ["84207.00", "5.152201"], ["84198.50", "4.338695"], ["84190.00", "5.242590"], ["84181.50", "5.604148"], ["84173.00", "3.886748"], ["84164.50", "5.332979"], ["84164.00", "0.000159"], ["84156.00", "4.429085"], ["84147.50", "5.423369"], ["84139.00", "4.790643"], ["84130.50", "3.977137"], ["84122.00", "4.700253"], ["84113.50", "4.248306"], ["84105.00", "5.513758"], ["84096.50", "4.881032"], ["84088.00", "5.061811"], ["84079.50", "4.971422"], ["84071.00", "4.609864"], ["84062.50", "4.157916"], ["84054.00", "4.067527"], ["83888.89", "0"], ["83888.86", "0"], ["83887.29", "0"]], "checksum": -1987959906, "ts": "1742142207731"}], "ts": 1742142207734, "record_time": 1742142206.842463}
{"action": "update", "arg": {"instType": "SPOT", "channel": "books", "instId": "BTCUSDT"}, "data": [{"asks": [["84294.38", "0.209200"], ["84312.78", "0.143414"], ["84315.32", "0"], ["84321.50", "0.002999"], ["84323.50", "0.007893"], ["84325.50", "0.020769"], ["84327.50", "0.054655"], ["84329.50", "0.143829"], ["84331.50", "0.378498"], ["84333.50", "0.996049"], ["84333.80", "0.016920"], ["84334.90", "0.312690"], ["84337.70", "0.539010"], ["84338.90", "0"], ["84340.10", "0"], ["84341.90", "1.350000"], ["84342.20", "0.142500"], ["84343.00", "0"], ["84344.50", "0.265950"], ["84345.60", "0"], ["84346.10", "0.035580"], ["84375.60", "4.157916"], ["84384.10", "4.790643"], ["84392.60", "5.332979"], ["84401.10", "5.423369"], ["84409.00", "0.125315"], ["84409.60", "3.977137"], ["84418.10", "3.886748"], ["84426.60", "5.604148"], ["84432.82", "0"], ["84435.10", "4.609864"], ["84443.60", "4.519474"], ["84452.10", "4.881032"], ["84460.60", "5.242590"], ["84469.10", "4.338695"], ["84477.60", "5.061811"], ["84486.10", "4.067527"], ["84494.60", "4.429085"], ["84503.10", "4.971422"], ["84511.60", "5.152201"], ["84520.10", "4.248306"], ["84528.60", "4.700253"], ["84537.10", "5.513758"], ["84628.49", "1.631305"], ["84631.39", "0"], ["84847.82", "0"], ["84849.88", "0"]], "bids": [["84277.51", "2.506155"], ["84277.45", "0"], ["84276.19", "0.000070"], ["84265.10", "0.002008"], ["84263.10", "0.005283"], ["84261.10", "0.013902"], ["84259.10", "0.036585"], ["84257.10", "0.096510"], ["84255.10", "0.253974"], ["84253.10", "0.668353"], ["84251.38", "0"], ["84251.10", "1.758822"], ["84250.95", "0.003523"], ["84249.10", "4.628480"], ["84248.70", "0"], ["84246.40", "2.349240"], ["84240.00", "0"], ["84236.50", "0.025350"], ["84207.00", "5.604148"], ["84198.50", "5.242590"], ["84190.00", "5.423369"], ["84181.50", "3.886748"], ["84173.00", "5.152201"], ["84168.00", "0"], ["84156.00", "4.609864"], ["84147.50", "4.157916"], ["84139.00", "4.248306"], ["84130.50", "4.881032"], ["84122.00", "4.338695"], ["84113.50", "4.067527"], ["84105.00", "4.790643"], ["84096.50", "4.971422"], ["84088.00", "5.513758"], ["84079.50", "5.061811"], ["84071.00", "4.429085"], ["84062.50", "4.519474"], ["84054.00", "4.700253"], ["84045.50", "3.977137"], ["83957.03", "0"], ["83954.15", "1.686694"], ["83888.89", "0.000163"], ["83888.86", "0.000371"]], "checksum": -235946923, "ts": "1742142207932"}], "ts": 1742142207935, "record_time": 1742142207.044052}
{"action": "update", "arg": {"instType": "SPOT", "channel": "books", "instId": "BTCUSDT"}, "data": [{"asks": [["84319.50", "0.001814"], ["84321.50", "0.004773"], ["84323.50", "0.012561"], ["84325.50", "0.033055"], ["84327.50", "0.086987"], ["84329.50", "0.228911"], ["84331.50", "0.602399"], ["84333.50", "1.585259"], ["84333.80", "0.032880"], ["84334.00", "0"], ["84334.50", "0.001040"], ["84334.90", "0.531330"], ["84337.70", "0.414240"], ["84339.30", "0.454530"], ["84342.30", "0.265950"], ["84344.50", "0"], ["84345.30", "1.135470"], ["84346.90", "3.943650"], ["84350.80", "0.410370"], ["84375.60", "4.519474"], ["84384.10", "4.157916"], ["84392.60", "5.152201"], ["84401.10", "5.332979"], ["84409.60", "5.604148"], ["84418.10", "4.429085"], ["84426.60", "4.067527"], ["84435.10", "4.700253"], ["84443.60", "4.971422"], ["84452.10", "3.977137"], ["84460.60", "4.338695"], ["84469.10", "4.790643"], ["84477.60", "5.242590"], ["84486.10", "5.513758"], ["84494.60", "4.881032"], ["84503.10", "5.423369"], ["84511.60", "3.886748"], ["84520.10", "5.061811"], ["84528.60", "4.248306"], ["84537.10", "4.609864"], ["84847.58", "0"]], "bids": [["84277.51", "2.715355"], ["84277.46", "0.094766"], ["84263.10", "0.005108"], ["84261.10", "0.013440"], ["84259.10", "0.035370"], ["84257.10", "0.093079"], ["84255.10", "0.244943"], ["84253.10", "0.644588"], ["84251.10", "1.696285"], ["84249.10", "4.463907"], ["84248.60", "0.265440"], ["84238.60", "0.172500"], ["84238.20", "0"], ["84207.00", "4.790643"], ["84198.50", "5.061811"], ["84190.00", "4.971422"], ["84181.50", "4.338695"], ["84173.00", "4.248306"], ["84164.50", "5.513758"], ["84156.00", "5.332979"], ["84139.00", "4.700253"], ["84130.50", "5.242590"], ["84122.00", "3.886748"], ["84113.50", "3.977137"], ["84105.00", "4.519474"], ["84096.50", "5.152201"], ["84088.00", "5.423369"], ["84079.50", "4.881032"], ["84071.00", "4.067527"], ["84062.50", "4.429085"], ["84054.00", "5.604148"], ["84045.50", "4.609864"]], "checksum": -1668154110, "ts": "1742142208131"}], "ts": 1742142208135, "record_time": 1742142207.243156}
{"action": "update", "arg": {"instType": "SPOT", "channel": "books", "instId": "BTCUSDT"}, "data": [{"asks": [["84319.50", "0.001031"], ["84321.50", "0.001965"], ["84323.50", "0.005172"], ["84325.50", "0.013611"], ["84327.50", "0.035817"], ["84329.50", "0.094257"], ["84331.50", "0.248045"], ["84333.50", "0.652748"], ["84334.90", "0.312690"], ["84342.10", "0.265950"], ["84342.30", "0"], ["84366.83", "0"], ["84375.60", "4.700253"], ["84384.10", "4.338695"], ["84392.60", "4.971422"], ["84401.10", "5.152201"], ["84409.60", "4.519474"], ["84418.10", "5.332979"], ["84426.60", "5.513758"], ["84435.10", "4.881032"], ["84443.60", "4.609864"], ["84452.10", "5.061811"], ["84460.60", "5.604148"], ["84469.10", "5.423369"], ["84477.60", "3.977137"], ["84486.10", "4.248306"], ["84494.60", "5.242590"], ["84503.10", "4.157916"], ["84520.10", "4.429085"], ["84528.60", "4.067527"], ["84537.10", "4.790643"], ["84847.58", "0.000039"]], "bids": [["84276.35", "0.000070"], ["84276.19", "0"], ["84268.78", "0.189435"], ["84248.70", "0.265440"], ["84248.60", "0"], ["84230.85", "0.013001"], ["84207.00", "3.977137"], ["84198.50", "4.881032"], ["84190.00", "5.152201"], ["84181.50", "5.061811"], ["84173.00", "5.242590"], ["84165.00", "0"], ["84164.50", "4.609864"], ["84156.00", "4.248306"], ["84147.50", "4.338695"], ["84139.00", "4.157916"], ["84130.50", "4.429085"], ["84122.00", "5.604148"], ["84113.50", "3.886748"], ["84105.00", "5.332979"], ["84096.50", "5.513758"], ["84088.00", "4.700253"], ["84079.50", "4.067527"], ["84071.00", "4.971422"], ["84062.50", "5.423369"], ["84054.00", "4.519474"], ["84045.50", "4.790643"], ["83888.86", "0"]], "checksum": -356923878, "ts": "1742142208332"}], "ts": 1742142208339, "record_time": 1742142207.454488}
{"action": "update", "arg": {"instType": "SPOT", "channel": "books", "instId": "BTCUSDT"}, "data": [{"asks": [["84321.50", "0.001013"], ["84323.50", "0.001026"], ["84325.50", "0.002016"], ["84327.50", "0.005304"], ["84329.50", "0.013958"], ["84331.50", "0.036733"], ["84333.50", "0.096404"], ["84333.80", "0.001021"], ["84334.00", "0.007740"], ["84334.90", "0"], ["84337.70", "0.539010"], ["84339.30", "0.093630"], ["84341.89", "0.700797"], ["84341.90", "0"], ["84342.20", "0"], ["84345.20", "1.743900"], ["84345.30", "0"], ["84346.10", "0.013980"], ["84375.60", "4.067527"], ["84392.60", "4.429085"], ["84401.10", "5.332979"], ["84409.60", "4.248306"], ["84418.10", "5.604148"], ["84426.60", "4.700253"], ["84435.10", "5.423369"], ["84442.70", "0.209200"], ["84443.60", "3.977137"], ["84460.60", "4.971422"], ["84469.10", "4.157916"], ["84477.60", "4.609864"], ["84486.10", "5.513758"], ["84494.60", "4.881032"], ["84503.10", "5.152201"], ["84511.60", "5.242590"], ["84520.10", "3.886748"], ["84528.60", "4.790643"], ["84537.10", "4.519474"]], "bids": [["84269.09", "0.112297"], ["84265.10", "0.002372"], ["84263.10", "0.006240"], ["84261.10", "0.016422"], ["84259.10", "0.043215"], ["84257.10", "0.113725"], ["84255.10", "0.299275"], ["84253.10", "0.787566"], ["84251.10", "2.072543"], ["84249.10", "5.454059"], ["84248.80", "2.995170"], ["84248.70", "0"], ["84246.40", "0"], ["84239.10", "0.030000"], ["84238.60", "0.142500"], ["84207.00", "4.790643"], ["84190.00", "4.609864"], ["84181.50", "4.971422"], ["84173.00", "4.338695"], ["84164.50", "4.248306"], ["84156.00", "5.152201"], ["84147.50", "3.886748"], ["84139.00", "4.700253"], ["84130.50", "5.332979"], ["84122.00", "5.513758"], ["84113.50", "4.157916"], ["84105.00", "4.067527"], ["84096.50", "5.061811"], ["84088.00", "4.429085"], ["84079.50", "3.977137"], ["84071.00", "5.242590"], ["84062.50", "4.519474"], ["84054.00", "5.604148"], ["84045.50", "5.423369"], ["83888.86", "0.000371"]], "checksum": 1062382842, "ts": "1742142208535"}], "ts": 1742142208538, "record_time": 1742142207.645963}
{"action": "update", "arg": {"instType": "SPOT", "channel": "books", "instId": "BTCUSDT"}, "data": [{"asks": [["84286.66", "0.050280"], ["84321.50", "0.001787"], ["84323.50", "0.004702"], ["84325.50", "0.012373"], ["84327.50", "0.032561"], ["84329.50", "0.085533"], ["84331.50", "0.225087"], ["84333.50", "0.592336"], ["84333.60", "0.626790"], ["84334.00", "0"], ["84334.20", "0.382320"], ["84334.30", "0.010650"], ["84334.50", "0"], ["84337.70", "1.348230"], ["84337.80", "2.349060"], ["84341.89", "0"], ["84341.90", "1.350000"], ["84342.20", "0.142500"], ["84345.20", "1.209390"], ["84346.10", "0.033120"], ["84350.20", "0"], ["84350.80", "0"], ["84375.60", "4.609864"], ["84392.60", "5.061811"], ["84401.10", "4.157916"], ["84409.60", "4.700253"], ["84418.10", "4.067527"], ["84426.60", "4.790643"], ["84435.10", "5.152201"], ["84443.60", "5.513758"], ["84452.10", "3.977137"], ["84460.60", "3.886748"], ["84469.10", "5.332979"], ["84477.60", "5.242590"], ["84486.10", "5.423369"], ["84494.60", "5.604148"], ["84503.10", "4.429085"], ["84511.60", "4.971422"], ["84520.10", "4.519474"], ["84528.60", "4.881032"], ["84537.10", "4.248306"], ["84847.58", "0"]], "bids": [["84276.35", "0"], ["84276.33", "0.000070"], ["84265.10", "0.001727"], ["84263.10", "0.004545"], ["84261.10", "0.011959"], ["84259.10", "0.031471"], ["84257.10", "0.082820"], ["84255.10", "0.217946"], ["84253.10", "0.573542"], ["84251.10", "1.509322"], ["84249.10", "3.971900"], ["84248.90", "1.016220"], ["84248.80", "0.645990"], ["84246.60", "2.349240"], ["84241.70", "1.061130"], ["84207.00", "5.332979"], ["84198.50", "3.977137"], ["84190.00", "5.061811"], ["84181.50", "3.886748"], ["84173.00", "4.790643"], ["84167.00", "0.000121"], ["84164.50", "4.519474"], ["84156.00", "4.067527"], ["84147.50", "4.881032"], ["84130.50", "5.604148"], ["84122.00", "5.423369"], ["84105.00", "5.242590"], ["84096.50", "4.609864"], ["84088.00", "5.152201"], ["84079.50", "4.338695"], ["84071.00", "4.248306"], ["84062.50", "5.513758"], ["84054.00", "4.971422"], ["84045.50", "4.429085"], ["83891.30", "0"], ["83888.89", "0"], ["83888.86", "0"]], "checksum": -853521300, "ts": "1742142208735"}], "ts": 1742142208738, "record_time": 1742142207.846821}
{"action": "update", "arg": {"instType": "SPOT", "channel": "books", "instId": "BTCUSDT"}, "data": [{"asks": [["84277.52", "0.808278"], ["84285.78", "0.011520"], ["84321.50", "0.001784"], ["84323.50", "0.004693"], ["84325.50", "0.012351"], ["84327.50", "0.032503"], ["84334.20", "1.572510"], ["84335.60", "2.349120"], ["84337.70", "0.414240"], ["84337.80", "0"], ["84339.30", "0.529590"], ["84340.60", "0.265950"], ["84342.10", "0"], ["84375.60", "5.152201"], ["84384.10", "5.604148"], ["84392.60", "3.977137"], ["84401.10", "4.790643"], ["84409.60", "5.332979"], ["84418.10", "5.061811"], ["84426.60", "4.067527"], ["84435.10", "4.609864"], ["84443.60", "4.519474"], ["84452.10", "4.157916"], ["84460.60", "4.700253"], ["84469.10", "4.338695"], ["84477.60", "5.513758"], ["84486.10", "4.248306"], ["84494.60", "5.423369"], ["84503.10", "4.971422"], ["84511.60", "3.886748"], ["84520.10", "4.881032"], ["84528.60", "4.429085"], ["84537.10", "5.242590"], ["84846.85", "0"]], "bids": [["84265.10", "0.001534"], ["84263.10", "0.004036"], ["84261.10", "0.010622"], ["84259.10", "0.027951"], ["84257.10", "0.073556"], ["84255.10", "0.193568"], ["84253.10", "0.509391"], ["84251.10", "1.340503"], ["84249.10", "3.527639"], ["84247.10", "0.265440"], ["84246.00", "0.194400"], ["84242.80", "0.451110"], ["84241.80", "1.217790"], ["84240.10", "0.039000"], ["84239.10", "0"], ["84236.50", "0"], ["84207.00", "4.157916"], ["84198.50", "4.700253"], ["84190.00", "3.886748"], ["84181.50", "4.429085"], ["84173.00", "4.338695"], ["84164.50", "5.332979"], ["84156.00", "5.152201"], ["84147.50", "5.423369"], ["84139.00", "3.977137"], ["84130.50", "5.242590"], ["84122.00", "4.881032"], ["84113.50", "4.248306"], ["84105.00", "4.609864"], ["84096.50", "5.061811"], ["84088.00", "4.519474"], ["84079.50", "5.604148"], ["84071.00", "4.067527"], ["84062.50", "4.971422"], ["84054.00", "5.513758"], ["84045.50", "4.790643"]], "checksum": 1223830979, "ts": "1742142208935"}], "ts": 1742142208941, "record_time": 1742142208.065517}
{"action": "update", "arg": {"instType": "SPOT", "channel": "books", "instId": "BTCUSDT"}, "data": [{"asks": [["84293.05", "0.003017"], ["84293.62", "0.002907"], ["84294.27", "0.001827"], ["84294.66", "0"], ["84294.70", "0"], ["84295.85", "0"], ["84305.80", "0.016427"], ["84307.21", "0.010984"], ["84308.32", "0"], ["84309.59", "0"], ["84309.92", "0.015892"], ["84310.75", "0.009989"], ["84312.13", "0"], ["84312.15", "0.006356"], ["84312.95", "0"], ["84314.37", "0"], ["84324.71", "0.084140"], ["84338.81", "0.001597"], ["84341.97", "0"], ["84375.60", "4.067527"], ["84384.10", "4.881032"], ["84392.60", "4.519474"], ["84401.10", "4.700253"], ["84409.60", "4.248306"], ["84418.10", "5.152201"], ["84426.60", "5.332979"], ["84443.60", "4.971422"], ["84460.60", "5.061811"], ["84469.10", "5.423369"], ["84486.10", "5.604148"], ["84494.60", "3.886748"], ["84503.10", "4.429085"], ["84511.60", "3.977137"], ["84520.10", "4.338695"], ["84528.60", "4.790643"], ["84846.55", "0"]], "bids": [["84268.78", "0"], ["84259.10", "0.027788"], ["84257.10", "0.073127"], ["84255.10", "0.192438"], ["84254.80", "0"], ["84253.10", "0.506415"], ["84252.43", "0.052111"], ["84251.10", "1.332671"], ["84250.94", "0"], ["84249.10", "3.507030"], ["84248.73", "0.076018"], ["84244.43", "0"], ["84241.95", "0.023741"], ["84227.51", "0"], ["84224.35", "0.001180"], ["84207.00", "3.886748"], ["84198.50", "5.513758"], ["84190.00", "4.067527"], ["84181.50", "5.332979"], ["84173.00", "4.881032"], ["84166.00", "0.000159"], ["84164.50", "3.977137"], ["84156.00", "4.609864"], ["84147.50", "4.971422"], ["84139.00", "5.423369"], ["84130.50", "4.157916"], ["84122.00", "4.429085"], ["84113.50", "5.061811"], ["84105.00", "4.248306"], ["84096.50", "5.604148"], ["84088.00", "5.242590"], ["84079.50", "4.700253"], ["84071.00", "4.519474"], ["84062.50", "4.790643"], ["84054.00", "5.152201"], ["84045.50", "4.338695"]], "checksum": -1273654021, "ts": "1742142209136"}], "ts": 1742142209139, "record_time": 1742142208.24771}
{"action": "update", "arg": {"instType": "SPOT", "channel": "books", "instId": "BTCUSDT"}, "data": [{"asks": [["84285.78", "0"], ["84321.50", "0.001402"], ["84323.50", "0.003690"], ["84325.50", "0.009710"], ["84327.50", "0.025552"], ["84329.50", "0.067243"], ["84331.50", "0.176954"], ["84333.50", "0.465670"], ["84341.20", "0"], ["84341.60", "0"], ["84344.20", "0.015120"], ["84344.60", "0.015180"], ["84375.60", "4.429085"], ["84384.10", "4.248306"], ["84392.60", "3.977137"], ["84401.10", "5.332979"], ["84409.60", "4.067527"], ["84418.10", "5.604148"], ["84426.60", "5.061811"], ["84435.10", "4.338695"], ["84443.60", "4.881032"], ["84452.10", "4.519474"], ["84460.60", "3.886748"], ["84469.10", "5.513758"], ["84477.60", "5.152201"], ["84486.10", "4.157916"], ["84494.60", "5.242590"], ["84503.10", "5.423369"], ["84511.60", "4.790643"], ["84520.10", "4.609864"], ["84528.60", "4.971422"], ["84537.10", "4.700253"], ["84846.55", "0.000019"]], "bids": [["84277.51", "2.675355"], ["84270.29", "0.197268"], ["84269.09", "0.072863"], ["84265.10", "0.002414"], ["84263.10", "0.006353"], ["84261.10", "0.016720"], ["84259.10", "0.043999"], ["84257.10", "0.115787"], ["84255.10", "0.304701"], ["84253.10", "0.801847"], ["84252.20", "0.197876"], ["84251.10", "2.110286"], ["84250.95", "0.016524"], ["84249.10", "5.553383"], ["84248.90", "0.001016"], ["84247.40", "0.265440"], ["84247.10", "0"], ["84241.00", "0.030000"], ["84240.10", "0.009000"], ["84236.50", "0.025350"], ["84216.10", "0"], ["84207.00", "4.248306"], ["84198.50", "4.881032"], ["84190.00", "4.790643"], ["84181.50", "4.429085"], ["84173.00", "5.604148"], ["84164.50", "5.242590"], ["84156.00", "4.971422"], ["84147.50", "4.338695"], ["84139.00", "5.513758"], ["84130.50", "5.152201"], ["84122.00", "5.332979"], ["84105.00", "3.886748"], ["84096.50", "4.067527"], ["84088.00", "4.519474"], ["84079.50", "4.609864"], ["84071.00", "4.157916"], ["84062.50", "3.977137"], ["84054.00", "5.423369"], ["84045.50", "4.700253"], ["83893.62", "0"], ["83892.29", "0"], ["83891.43", "0"]], "checksum": 1513744214, "ts": "1742142209336"}], "ts": 1742142209341, "record_time": 1742142208.448864}
{"action": "update", "arg": {"instType": "SPOT", "channel": "books", "instId": "BTCUSDT"}, "data": [{"asks": [["84285.78", "0.011520"], ["84292.19", "0"], ["84292.47", "0.080382"], ["84301.24", "0"], ["84301.66", "0.035952"], ["84302.80", "0.006356"], ["84302.81", "0"], ["84304.48", "0"], ["84304.91", "0.006356"], ["84305.94", "0.006356"], ["84305.96", "0"], ["84312.11", "0"], ["84313.68", "0"], ["84313.78", "0.001807"], ["84314.15", "0.015891"], ["84315.41", "0.010986"], ["84315.43", "0"], ["84321.50", "0.001042"], ["84323.50", "0.001037"], ["84325.50", "0.001982"], ["84327.50", "0.005215"], ["84329.50", "0.013725"], ["84331.50", "0.036117"], ["84333.50", "0.095046"], ["84333.60", "0.001890"], ["84334.20", "1.332720"], ["84334.30", "0.019590"], ["84339.30", "0.093630"], ["84375.60", "4.790643"], ["84384.10", "4.338695"], ["84392.60", "5.332979"], ["84401.10", "4.157916"], ["84409.60", "5.423369"], ["84418.10", "5.242590"], ["84426.60", "5.513758"], ["84435.10", "5.061811"], ["84442.70", "0"], ["84443.60", "4.971422"], ["84452.10", "4.609864"], ["84460.60", "4.248306"], ["84469.10", "4.429085"], ["84477.60", "4.519474"], ["84486.10", "3.977137"], ["84494.60", "5.152201"], ["84503.10", "3.886748"], ["84511.60", "4.067527"], ["84520.10", "4.700253"], ["84528.60", "5.604148"], ["84537.10", "4.881032"]], "bids": [["84277.51", "2.476155"], ["84276.33", "0"], ["84272.63", "0.085568"], ["84265.10", "0.001885"], ["84263.10", "0.004961"], ["84261.10", "0.013054"], ["84259.10", "0.034352"], ["84257.84", "0.084444"], ["84257.41", "0"], ["84257.10", "0.090400"], ["84256.41", "0"], ["84256.40", "0.015772"], ["84256.21", "0"], ["84256.19", "0.006565"], ["84255.10", "0.237896"], ["84254.18", "0.008989"], ["84253.74", "0"], ["84253.10", "0.626043"], ["84251.10", "1.647480"], ["84249.82", "0"], ["84249.10", "4.335474"], ["84247.50", "0.265440"], ["84247.40", "0"], ["84245.05", "0.073510"], ["84244.63", "0"], ["84244.62", "0.056642"], ["84244.57", "0"], ["84242.97", "0"], ["84241.30", "0.030000"], ["84241.00", "0"], ["84240.20", "0"], ["84239.31", "0.023941"], ["84237.70", "0.249840"], ["84198.50", "5.332979"], ["84190.00", "4.609864"], ["84181.50", "4.700253"], ["84173.00", "4.790643"], ["84169.00", "0.012717"], ["84164.50", "4.971422"], ["84156.00", "5.513758"], ["84139.00", "5.604148"], ["84130.50", "4.881032"], ["84122.00", "4.157916"], ["84113.50", "3.886748"], ["84105.00", "3.977137"], ["84096.50", "4.519474"], ["84088.00", "4.067527"], ["84079.50", "5.152201"], ["84071.00", "5.242590"], ["84062.50", "5.061811"], ["84054.00", "4.429085"], ["84045.50", "5.423369"], ["83893.62", "0.000137"], ["83892.29", "0.000143"], ["83891.43", "0.000455"]], "checksum": -546188047, "ts": "1742142209539"}], "ts": 1742142209543, "record_time": 1742142208.651188}
{"action": "update", "arg": {"instType": "SPOT", "channel": "books", "instId": "BTCUSDT"}, "data": [{"asks": [["84277.52", "0.815346"], ["84303.90", "0.006356"], ["84303.91", "0"], ["84304.37", "0"], ["84304.78", "0.006356"], ["84310.02", "0"], ["84310.31", "0.119881"], ["84316.37", "0.010000"], ["84319.50", "0.002787"], ["84321.50", "0.007334"], ["84323.50", "0.019301"], ["84325.50", "0.050792"], ["84327.50", "0.133661"], ["84329.50", "0.351740"], ["84331.50", "0.925632"], ["84331.80", "0"], ["84333.50", "2.435875"], ["84333.60", "0.001470"], ["84333.80", "0"], ["84334.00", "0.024060"], ["84334.20", "0.949980"], ["84334.30", "0"], ["84334.40", "2.349150"], ["84335.60", "0"], ["84337.00", "0.001597"], ["84339.30", "0.521820"], ["84340.00", "0.265950"], ["84340.20", "0.006960"], ["84340.60", "0"], ["84346.10", "0.035580"], ["84375.60", "4.519474"], ["84384.10", "5.061811"], ["84392.60", "4.881032"], ["84401.10", "3.977137"], ["84409.60", "5.152201"], ["84418.10", "5.332979"], ["84435.10", "4.429085"], ["84443.60", "4.248306"], ["84452.10", "4.338695"], ["84460.60", "4.790643"], ["84469.10", "5.242590"], ["84477.60", "5.604148"], ["84486.10", "5.423369"], ["84494.60", "4.609864"], ["84503.10", "4.700253"], ["84511.60", "4.157916"], ["84520.10", "4.067527"], ["84528.60", "3.886748"], ["84537.10", "4.971422"], ["84846.55", "0"]], "bids": [["84277.51", "2.474965"], ["84276.48", "0.000070"], ["84265.10", "0.001277"], ["84263.10", "0.003621"], ["84261.10", "0.009530"], ["84259.10", "0.025080"], ["84258.60", "0"], ["84257.10", "0.065998"], ["84255.21", "0.007120"], ["84255.20", "0"], ["84255.10", "0.173680"], ["84254.71", "0.017062"], ["84254.31", "0"], ["84253.10", "0.457052"], ["84251.10", "1.202768"], ["84250.16", "0.002950"], ["84249.10", "3.165181"], ["84248.90", "0"], ["84247.80", "0"], ["84246.60", "0"], ["84246.00", "0"], ["84245.00", "0.341700"], ["84242.00", "0.030000"], ["84241.30", "0"], ["84240.50", "0.981090"], ["84236.50", "0"], ["84226.42", "0.001189"], ["84221.23", "0"], ["84207.00", "5.604148"], ["84198.50", "4.429085"], ["84190.00", "3.977137"], ["84181.50", "4.790643"], ["84173.00", "3.886748"], ["84156.00", "4.700253"], ["84147.50", "4.609864"], ["84139.00", "4.067527"], ["84113.50", "5.242590"], ["84105.00", "5.152201"], ["84096.50", "5.423369"], ["84088.00", "4.338695"], ["84079.50", "4.519474"], ["84071.00", "5.061811"], ["84062.50", "5.513758"], ["84054.00", "4.248306"], ["84045.50", "5.332979"], ["83891.30", "0.000010"], ["83888.89", "0.000163"], ["83888.86", "0.000371"], ["83887.29", "0.000586"]], "checksum": -85881975, "ts": "1742142209740"}], "ts": 1742142209743, "record_time": 1742142208.853868}
{"action": "update", "arg": {"instType": "SPOT", "channel": "books", "instId": "BTCUSDT"}, "data": [{"asks": [["84289.02", "0"], ["84296.42", "0"], ["84298.27", "0.001205"], ["84298.66", "0"], ["84300.36", "0.119869"], ["84300.80", "0"], ["84300.83", "0"], ["84301.31", "0"], ["84301.63", "0"], ["84301.83", "0"], ["84302.31", "0"], ["84302.44", "0.006356"], ["84302.50", "0.006356"], ["84302.74", "0.006356"], ["84303.25", "0.006356"], ["84303.46", "0.010985"], ["84303.66", "0"], ["84304.17", "0.006356"], ["84304.20", "0"], ["84305.02", "0.006356"], ["84305.65", "0"], ["84305.81", "0.006356"], ["84307.01", "0.006356"], ["84307.28", "0"], ["84308.37", "0"], ["84309.18", "0.119895"], ["84310.28", "0.119879"], ["84317.50", "0.001143"], ["84319.50", "0.002215"], ["84321.50", "0.005828"], ["84323.50", "0.015336"], ["84325.50", "0.040358"], ["84327.50", "0.106205"], ["84329.50", "0.279489"], ["84331.50", "0.735496"], ["84333.50", "1.935516"], ["84339.00", "0.265950"], ["84339.20", "0"], ["84340.00", "0"], ["84340.20", "0"], ["84349.70", "0.106800"], ["84384.10", "4.881032"], ["84392.60", "5.152201"], ["84401.10", "4.971422"], ["84409.60", "5.423369"], ["84418.10", "5.513758"], ["84426.60", "4.700253"], ["84435.10", "5.332979"], ["84443.60", "3.886748"], ["84452.10", "4.429085"], ["84460.60", "5.242590"], ["84469.10", "3.977137"], ["84477.60", "4.790643"], ["84486.10", "4.609864"], ["84494.60", "5.061811"], ["84503.10", "4.248306"], ["84528.60", "4.338695"], ["84537.10", "5.604148"], ["84846.55", "0.000019"], ["84846.85", "0.000176"]], "bids": [["84277.51", "2.493893"], ["84276.48", "0"], ["84267.02", "0"], ["84265.10", "0.001114"], ["84263.10", "0.002689"], ["84261.10", "0.007075"], ["84259.10", "0.018620"], ["84259.06", "0.248017"], ["84257.83", "0.017837"], ["84257.43", "0.018262"], ["84257.36", "0"], ["84257.10", "0.048999"], ["84256.56", "0.016461"], ["84256.13", "0"], ["84255.83", "0"], ["84255.80", "0.017080"], ["84255.68", "0"], ["84255.59", "0.056358"], ["84255.14", "0"], ["84255.10", "0.128946"], ["84254.28", "0.007934"], ["84254.14", "0.017333"], ["84254.06", "0.008165"], ["84253.93", "0"], ["84253.76", "0"], ["84253.10", "0.339332"], ["84252.93", "0"], ["84252.46", "0"], ["84252.27", "0"], ["84252.23", "0.012650"], ["84251.10", "0.892978"], ["84250.87", "0"], ["84250.86", "0.271918"], ["84249.93", "0.222746"], ["84249.10", "2.349943"], ["84248.96", "0"], ["84248.03", "0"], ["84245.80", "0.069600"], ["84245.00", "1.306380"], ["84244.90", "2.349300"], ["84242.90", "0.918810"], ["84236.70", "0"], ["84236.60", "0"], ["84207.00", "4.519474"], ["84198.50", "5.242590"], ["84190.00", "4.157916"], ["84181.50", "4.881032"], ["84173.00", "5.332979"], ["84164.50", "5.604148"], ["84164.00", "0"], ["84156.00", "4.429085"], ["84147.50", "5.061811"], ["84139.00", "3.977137"], ["84130.50", "4.067527"], ["84122.00", "4.700253"], ["84113.50", "5.513758"], ["84105.00", "3.886748"], ["84088.00", "5.152201"], ["84079.50", "4.338695"], ["84071.00", "4.609864"], ["84062.50", "4.790643"], ["84045.50", "4.971422"], ["83887.11", "0.000075"], ["83886.91", "0.000145"], ["83885.98", "0.000018"]], "checksum": 38090272, "ts": "1742142209942"}], "ts": 1742142209945, "record_time": 1742142209.053605}
{"action": "update", "arg": {"instType": "SPOT", "channel": "books", "instId": "BTCUSDT"}, "data": [{"asks": [["84286.62", "0.027068"], ["84286.66", "0"], ["84290.09", "0.140096"], ["84298.65", "0"], ["84302.23", "0"], ["84302.27", "0"], ["84304.00", "0"], ["84304.49", "0.006356"], ["84304.58", "0.016428"], ["84305.58", "0"], ["84306.35", "0.006357"], ["84308.14", "0.009989"], ["84317.50", "0.001004"], ["84331.50", "0.735680"], ["84333.50", "1.936000"], ["84345.10", "0.178140"], ["84349.70", "0"], ["84375.60", "5.061811"], ["84384.10", "5.152201"], ["84392.60", "5.332979"], ["84401.10", "4.700253"], ["84409.60", "4.971422"], ["84418.10", "4.157916"], ["84426.60", "4.248306"], ["84435.10", "5.604148"], ["84443.60", "5.423369"], ["84452.10", "3.977137"], ["84460.60", "3.886748"], ["84469.10", "4.519474"], ["84477.60", "5.242590"], ["84486.10", "5.513758"], ["84494.60", "4.790643"], ["84503.10", "4.609864"], ["84511.60", "4.338695"], ["84528.60", "4.429085"], ["84537.10", "4.881032"], ["84847.58", "0.000039"]], "bids": [["84257.10", "0.048827"], ["84255.10", "0.128493"], ["84254.85", "0.028809"], ["84254.76", "0.007317"], ["84254.47", "0.025086"], ["84253.10", "0.338139"], ["84252.58", "0.008284"], ["84252.54", "0"], ["84252.51", "0"], ["84252.15", "0"], ["84251.67", "0.018521"], ["84251.10", "0.889840"], ["84250.23", "0"], ["84249.31", "0.021110"], ["84249.12", "0"], ["84249.10", "2.341684"], ["84247.07", "0"], ["84246.77", "0.012440"], ["84244.19", "0"], ["84242.70", "0.030000"], ["84242.00", "0"], ["84222.70", "0.207047"], ["84207.00", "4.609864"], ["84198.50", "4.157916"], ["84190.00", "3.977137"], ["84181.50", "5.604148"], ["84173.00", "5.513758"], ["84164.50", "4.429085"], ["84156.00", "4.519474"], ["84147.50", "4.790643"], ["84139.00", "3.886748"], ["84130.50", "5.061811"], ["84113.50", "5.332979"], ["84105.00", "5.423369"], ["84096.50", "4.971422"], ["84088.00", "4.067527"], ["84079.50", "5.242590"], ["84071.00", "5.152201"], ["84062.50", "4.881032"], ["84054.00", "4.338695"], ["84045.50", "4.248306"], ["83885.98", "0"]], "checksum": -474183110, "ts": "1742142210143"}], "ts": 1742142210147, "record_time": 1742142209.254651}
{"action": "update", "arg": {"instType": "SPOT", "channel": "books", "instId": "BTCUSDT"}, "data": [{"asks": [["84285.78", "0"], ["84286.62", "0.009117"], ["84319.50", "0.001044"], ["84321.50", "0.001019"], ["84323.50", "0.001026"], ["84325.50", "0.001998"], ["84327.50", "0.005256"], ["84329.50", "0.013832"], ["84331.50", "0.036400"], ["84333.50", "0.095790"], ["84334.20", "0"], ["84334.40", "0"], ["84336.60", "2.349090"], ["84339.30", "0.056610"], ["84341.60", "0.015180"], ["84341.90", "0"], ["84342.00", "0.015120"], ["84344.20", "0"], ["84344.60", "0"], ["84349.70", "0.106800"], ["84375.60", "4.519474"], ["84384.10", "5.423369"], ["84392.60", "4.790643"], ["84409.60", "3.886748"], ["84418.10", "5.061811"], ["84426.60", "4.067527"], ["84435.10", "5.242590"], ["84443.60", "4.609864"], ["84452.10", "5.604148"], ["84460.60", "5.513758"], ["84469.10", "5.152201"], ["84477.60", "4.338695"], ["84486.10", "4.157916"], ["84494.60", "4.429085"], ["84503.10", "5.332979"], ["84511.60", "4.881032"], ["84520.10", "4.248306"], ["84528.60", "4.971422"], ["84537.10", "3.977137"], ["84847.82", "0.000671"], ["84849.88", "0.000030"], ["84850.00", "0.000031"], ["84851.66", "0.000029"]], "bids": [["84277.51", "2.703093"], ["84265.10", "0.001622"], ["84263.10", "0.004267"], ["84261.10", "0.011230"], ["84260.46", "0.003069"], ["84259.10", "0.029552"], ["84257.10", "0.077770"], ["84255.10", "0.204656"], ["84253.10", "0.538570"], ["84251.10", "1.417290"], ["84249.10", "3.729709"], ["84248.80", "2.157990"], ["84247.80", "0.069600"], ["84247.60", "0.265440"], ["84247.50", "0"], ["84247.20", "2.349210"], ["84245.00", "0.601440"], ["84244.90", "0"], ["84207.00", "5.423369"], ["84198.50", "4.790643"], ["84181.50", "5.061811"], ["84173.00", "4.700253"], ["84168.00", "0.000121"], ["84164.50", "4.609864"], ["84156.00", "4.248306"], ["84147.50", "5.513758"], ["84139.00", "5.604148"], ["84130.50", "5.242590"], ["84122.00", "5.332979"], ["84113.50", "4.519474"], ["84105.00", "4.338695"], ["84096.50", "3.886748"], ["84088.00", "4.971422"], ["84079.50", "4.881032"], ["84062.50", "4.157916"], ["84054.00", "4.067527"], ["84045.50", "4.429085"], ["83887.29", "0"], ["83887.11", "0"], ["83886.91", "0"]], "checksum": -40693751, "ts": "1742142210345"}], "ts": 1742142210349, "record_time": 1742142209.4576}
{"action": "update", "arg": {"instType": "SPOT", "channel": "books", "instId": "BTCUSDT"}, "data": [{"asks": [["84277.52", "0.547878"], ["84281.63", "0.063815"], ["84291.53", "0.014953"], ["84294.38", "0"], ["84301.86", "0"], ["84308.45", "0.119843"], ["84316.37", "0"], ["84327.50", "0.005458"], ["84329.50", "0.014364"], ["84331.50", "0.037800"], ["84333.50", "0.099473"], ["84333.60", "0.001650"], ["84334.00", "0.001027"], ["84334.50", "0.010530"], ["84336.60", "0.197885"], ["84338.40", "0.361260"], ["84339.00", "0"], ["84339.30", "0"], ["84342.20", "0.969360"], ["84343.20", "2.348910"], ["84349.40", "0"], ["84349.70", "0"], ["84375.60", "5.423369"], ["84384.10", "3.886748"], ["84392.60", "5.332979"], ["84401.10", "4.609864"], ["84409.60", "4.881032"], ["84418.10", "5.604148"], ["84426.60", "4.338695"], ["84435.10", "4.157916"], ["84442.70", "0.209200"], ["84443.60", "4.248306"], ["84452.10", "4.519474"], ["84460.60", "4.790643"], ["84469.10", "4.067527"], ["84477.60", "5.152201"], ["84486.10", "3.977137"], ["84494.60", "4.700253"], ["84503.10", "4.971422"], ["84511.60", "5.242590"], ["84520.10", "4.429085"], ["84528.60", "5.061811"], ["84537.10", "5.513758"], ["84852.81", "0.000115"]], "bids": [["84277.51", "2.758710"], ["84277.46", "0.039614"], ["84272.35", "0.003007"], ["84265.10", "0.002465"], ["84263.10", "0.006486"], ["84261.10", "0.017069"], ["84259.10", "0.044917"], ["84258.23", "0"], ["84257.74", "0"], ["84257.10", "0.118204"], ["84257.03", "0.227687"], ["84255.10", "0.311062"], ["84253.10", "0.818585"], ["84251.10", "2.154171"], ["84250.45", "0"], ["84249.10", "5.668871"], ["84248.50", "0.918810"], ["84247.60", "0"], ["84245.00", "0.215370"], ["84242.90", "0.030000"], ["84242.80", "0"], ["84242.70", "0"], ["84241.80", "0.791010"], ["84241.70", "0"], ["84236.70", "0.090000"], ["84236.60", "0.090000"], ["84207.00", "4.790643"], ["84198.50", "4.519474"], ["84190.00", "4.157916"], ["84181.50", "5.604148"], ["84173.00", "4.338695"], ["84165.00", "0.000159"], ["84164.50", "5.242590"], ["84156.00", "3.886748"], ["84147.50", "5.152201"], ["84139.00", "3.977137"], ["84130.50", "4.067527"], ["84122.00", "4.429085"], ["84113.50", "4.248306"], ["84105.00", "4.700253"], ["84096.50", "4.609864"], ["84088.00", "5.423369"], ["84071.00", "5.513758"], ["84062.50", "5.061811"], ["84054.00", "5.332979"], ["84045.50", "4.971422"], ["83887.29", "0.000586"]], "checksum": -1791805203, "ts": "1742142210546"}], "ts": 1742142210550, "record_time": 1742142209.658454}
{"action": "update", "arg": {"instType": "SPOT", "channel": "books", "instId": "BTCUSDT"}, "data": [{"asks": [["84277.52", "0.210238"], ["84290.09", "0"], ["84313.50", "0"], ["84315.50", "0"], ["84317.50", "0"], ["84317.70", "0.001038"], ["84319.50", "0"], ["84319.70", "0.001020"], ["84321.50", "0"], ["84321.70", "0.001013"], ["84323.50", "0"], ["84323.70", "0.001340"], ["84325.50", "0"], ["84325.70", "0.003527"], ["84327.50", "0"], ["84327.70", "0.009281"], ["84329.50", "0"], ["84329.70", "0.024426"], ["84331.50", "0"], ["84331.70", "0.064279"], ["84333.50", "0"], ["84333.60", "0"], ["84333.70", "0.169154"], ["84334.00", "0"], ["84334.50", "0"], ["84335.70", "0.445143"], ["84336.60", "0"], ["84337.70", "1.171428"], ["84337.80", "0.001024"], ["84338.10", "0.001020"], ["84338.40", "0.048360"], ["84338.50", "0.140070"], ["84338.70", "0.001021"], ["84338.90", "2.349030"], ["84341.60", "0"], ["84342.00", "0.000094"], ["84342.20", "0"], ["84343.20", "0"], ["84343.70", "0.015090"], ["84343.80", "0"], ["84344.90", "0"], ["84345.10", "0.015150"], ["84345.20", "0"], ["84345.60", "0.265950"], ["84346.10", "2.945130"], ["84346.50", "0"], ["84348.70", "0.032910"], ["84348.90", "0.489570"], ["84349.40", "0.936510"], ["84350.20", "0.007050"], ["84350.30", "0.035580"], ["84350.80", "0.422910"], ["84351.10", "3.559050"], ["84351.80", "3.025230"], ["84356.00", "0.197885"], ["84375.60", "0"], ["84379.80", "4.700021"], ["84384.10", "0"], ["84388.30", "4.157711"], ["84392.60", "0"], ["84396.80", "4.880791"], ["84401.10", "0"], ["84405.30", "4.790406"], ["84409.60", "0"], ["84413.80", "5.242331"], ["84418.10", "0"], ["84422.30", "4.067326"], ["84426.60", "0"], ["84430.80", "3.976941"], ["84435.10", "0"], ["84439.30", "4.609636"], ["84443.60", "0"], ["84447.80", "5.423101"], ["84452.10", "0"], ["84456.30", "5.603871"], ["84460.60", "0"], ["84464.80", "5.513486"], ["84469.10", "0"], ["84473.30", "4.428866"], ["84477.60", "0"], ["84481.80", "3.886556"], ["84486.10", "0"], ["84490.30", "4.519251"], ["84494.60", "0"], ["84498.80", "4.338481"], ["84503.10", "0"], ["84507.30", "4.971176"], ["84511.60", "0"], ["84515.80", "5.061561"], ["84520.10", "0"], ["84524.30", "5.332716"], ["84528.60", "0"], ["84532.80", "4.248096"], ["84537.10", "0"], ["84541.30", "5.151946"], ["84851.66", "0"], ["84852.81", "0"]], "bids": [["84277.51", "2.758780"], ["84273.30", "0.001031"], ["84271.30", "0.001036"], ["84269.30", "0.002052"], ["84269.10", "0"], ["84267.30", "0.005583"], ["84267.10", "0"], ["84266.72", "2.549757"], ["84265.30", "0.014693"], ["84265.10", "0"], ["84264.97", "0.003036"], ["84263.30", "0.038665"], ["84263.10", "0"], ["84261.30", "0.101749"], ["84261.10", "0"], ["84259.32", "0.209434"], ["84259.30", "0.267761"], ["84259.10", "0"], ["84257.30", "0.704636"], ["84257.10", "0.005938"], ["84255.30", "1.854304"], ["84255.10", "0"], ["84253.30", "4.879747"], ["84253.10", "0"], ["84252.90", "0.564840"], ["84252.60", "0.001010"], ["84252.20", "0"], ["84251.90", "0.001043"], ["84251.80", "0.069600"], ["84251.40", "0.142500"], ["84251.10", "0"], ["84250.90", "1.512000"], ["84250.16", "0"], ["84250.10", "2.174010"], ["84249.80", "0.069600"], ["84249.10", "1.296810"], ["84249.00", "0"], ["84248.80", "0"], ["84247.00", "0"], ["84243.00", "0.030000"], ["84242.90", "0"], ["84242.20", "0.038460"], ["84240.40", "0.410370"], ["84239.40", "0"], ["84239.30", "0.177960"], ["84238.60", "0"], ["84238.50", "0"], ["84237.70", "0"], ["84237.60", "0"], ["84236.90", "0"], ["84236.70", "0"], ["84236.60", "0"], ["84222.71", "0.062293"], ["84222.70", "0"], ["84211.20", "5.423101"], ["84207.00", "0"], ["84202.70", "5.332716"], ["84198.50", "0"], ["84194.20", "4.428866"], ["84190.00", "0"], ["84185.70", "4.248096"], ["84181.50", "0"], ["84177.20", "4.157711"], ["84173.00", "0"], ["84168.70", "4.880791"], ["84164.50", "0"], ["84160.20", "4.519251"], ["84156.00", "0"], ["84151.70", "3.886556"], ["84147.50", "0"], ["84143.20", "4.067326"], ["84139.00", "0"], ["84134.70", "5.061561"], ["84130.50", "0"], ["84126.20", "4.609636"], ["84122.00", "0"], ["84117.70", "4.971176"], ["84113.50", "0"], ["84109.20", "4.700021"], ["84105.00", "0"], ["84100.70", "5.603871"], ["84096.50", "0"], ["84092.20", "5.151946"], ["84088.00", "0.000022"], ["84083.70", "4.790406"], ["84079.50", "0"], ["84075.20", "4.338481"], ["84071.00", "0"], ["84066.70", "3.976941"], ["84062.50", "0.000276"], ["84058.20", "5.242331"], ["84054.00", "0"], ["84049.70", "5.513486"], ["84045.50", "0"], ["83888.89", "0"], ["83888.86", "0"], ["83887.29", "0"]], "checksum": -826182719, "ts": "1742142210748"}], "ts": 1742142210753, "record_time": 1742142209.861983}
{"action": "update", "arg": {"instType": "SPOT", "channel": "books", "instId": "BTCUSDT"}, "data": [{"asks": [["84277.52", "0"], ["84277.53", "0"], ["84277.54", "0"], ["84277.55", "0"], ["84281.63", "0"], ["84285.65", "0"], ["84285.79", "0"], ["84285.80", "0"], ["84285.81", "0"], ["84285.82", "0"], ["84285.84", "0"], ["84285.85", "0"], ["84285.89", "0"], ["84286.62", "0"], ["84286.63", "0"], ["84286.65", "0"], ["84286.67", "0"], ["84286.69", "0"], ["84286.70", "0"], ["84288.30", "0"], ["84291.53", "0"], ["84291.54", "0"], ["84292.47", "0"], ["84293.05", "0"], ["84293.18", "0.010074"], ["84293.20", "0.001066"], ["84293.22", "0.005541"], ["84293.27", "0.001230"], ["84293.32", "0.006307"], ["84293.62", "0"], ["84294.09", "0.001923"], ["84294.11", "0.007955"], ["84294.12", "0.001162"], ["84294.14", "0.013689"], ["84294.15", "0.007110"], ["84294.17", "0.004739"], ["84294.19", "0.007359"], ["84294.27", "0"], ["84296.50", "0.004974"], ["84296.55", "0.008962"], ["84296.59", "0.000245"], ["84297.40", "0.009191"], ["84297.42", "0.007385"], ["84297.43", "0.000521"], ["84298.27", "0"], ["84300.36", "0"], ["84301.39", "0"], ["84301.66", "0"], ["84302.44", "0"], ["84302.50", "0"], ["84302.51", "0.080382"], ["84302.74", "0"], ["84302.80", "0"], ["84303.25", "0"], ["84303.46", "0"], ["84303.69", "0.003017"], ["84303.90", "0"], ["84303.92", "0"], ["84304.17", "0"], ["84304.49", "0"], ["84304.57", "0.002907"], ["84304.58", "0"], ["84304.70", "0.001827"], ["84304.78", "0"], ["84304.91", "0"], ["84305.02", "0"], ["84305.51", "0"], ["84305.80", "0"], ["84305.81", "0"], ["84305.94", "0"], ["84306.35", "0"], ["84307.01", "0"], ["84307.12", "0"], ["84307.21", "0"], ["84307.26", "0.001205"], ["84308.02", "0"], ["84308.14", "0"], ["84308.21", "0.313262"], ["84308.45", "0"], ["84309.16", "0.119869"], ["84309.18", "0"], ["84309.92", "0"], ["84310.27", "0.012680"], ["84310.28", "0"], ["84310.31", "0"], ["84310.75", "0"], ["84311.84", "0.006356"], ["84312.06", "0.035952"], ["84312.15", "0"], ["84312.24", "0.010985"], ["84312.68", "0.006356"], ["84312.77", "0.006356"], ["84312.78", "0.149770"], ["84312.80", "0.006356"], ["84313.78", "0"], ["84313.87", "0.006356"], ["84313.92", "0.006356"], ["84314.15", "0"], ["84314.26", "0.006356"], ["84314.52", "0.006356"], ["84314.80", "0.006356"], ["84315.06", "0.006356"], ["84315.09", "0.016428"], ["84315.14", "0.006356"], ["84315.22", "0.006357"], ["84315.26", "0.006356"], ["84315.41", "0"], ["84315.60", "0.126199"], ["84315.96", "0.016427"], ["84316.05", "0.010984"], ["84316.06", "0.006356"], ["84316.73", "0.009989"], ["84317.70", "0"], ["84318.09", "0.017795"], ["84318.25", "0"], ["84318.87", "0.119881"], ["84318.93", "0.119879"], ["84319.26", "0.119895"], ["84319.45", "0.009989"], ["84319.70", "0"], ["84319.95", "0.015892"], ["84321.70", "0"], ["84322.27", "0.001807"], ["84322.65", "0.006356"], ["84323.70", "0"], ["84324.53", "0.015891"], ["84325.65", "0.010986"], ["84325.70", "0"], ["84326.10", "0.001038"], ["84327.32", "0"], ["84327.70", "0"], ["84328.10", "0.001044"], ["84329.70", "0"], ["84330.10", "0.001050"], ["84331.46", "0.010000"], ["84331.70", "0"], ["84332.10", "0.002049"], ["84333.70", "0"], ["84334.10", "0.005393"], ["84335.70", "0"], ["84336.10", "0.014191"], ["84337.70", "0"], ["84337.80", "0"], ["84338.10", "0.037345"], ["84338.40", "0"], ["84338.50", "0"], ["84338.70", "0"], ["84338.90", "0"], ["84340.10", "0.098276"], ["84342.10", "0.258622"], ["84342.80", "0"], ["84343.70", "0"], ["84344.10", "0.680585"], ["84345.10", "0"], ["84345.60", "0"], ["84346.10", "1.791013"], ["84346.90", "0.002700"], ["84347.00", "0.021810"], ["84347.10", "0.001015"], ["84347.50", "0.001030"], ["84348.60", "0"], ["84348.70", "0"], ["84348.90", "0"], ["84349.40", "0"], ["84350.30", "0"], ["84350.80", "0.012540"], ["84350.90", "0.015210"], ["84351.10", "0"], ["84351.30", "0.704610"], ["84351.80", "1.401960"], ["84352.80", "0.281040"], ["84354.20", "0.007050"], ["84354.50", "1.350000"], ["84354.90", "0.441870"], ["84355.00", "0.142500"], ["84355.40", "3.694380"], ["84356.00", "0.616470"], ["84357.80", "0.489570"], ["84358.20", "0.007050"], ["84358.30", "0.035580"], ["84359.70", "0.025350"], ["84360.00", "0.936510"], ["84360.40", "0.204870"], ["84360.80", "0.189480"], ["84361.40", "0.142500"], ["84379.80", "0"], ["84388.30", "5.512936"], ["84396.80", "5.061056"], ["84405.30", "4.699552"], ["84413.80", "5.241808"], ["84422.30", "4.157296"], ["84430.80", "4.247672"], ["84439.30", "4.970680"], ["84447.80", "3.886168"], ["84451.13", "0.209200"], ["84456.30", "4.518800"], ["84464.80", "5.422560"], ["84473.30", "4.789928"], ["84481.80", "3.976544"], ["84490.30", "5.603312"], ["84498.80", "4.428424"], ["84507.30", "5.151432"], ["84515.80", "4.880304"], ["84524.30", "5.332184"], ["84532.80", "4.066920"], ["84541.30", "4.609176"], ["84549.80", "4.338048"], ["84628.49", "0"], ["84632.66", "1.638157"], ["84851.66", "0.000029"], ["84852.81", "0.000115"], ["84852.94", "0.000065"], ["84853.56", "0.000050"], ["84857.14", "0.000347"], ["84858.75", "0.000285"], ["84859.29", "0.000036"], ["84860.00", "0.000169"]], "bids": [["84291.53", "1.133800"], ["84291.52", "0.035518"], ["84285.94", "0.209200"], ["84281.73", "0.209200"], ["84281.70", "0.001004"], ["84281.62", "0.250670"], ["84279.70", "0.001003"], ["84277.70", "0.002143"], ["84277.52", "0.132932"], ["84277.51", "2.590673"], ["84277.46", "0"], ["84275.70", "0.005640"], ["84273.70", "0.014843"], ["84273.30", "0"], ["84272.62", "0"], ["84272.35", "0"], ["84271.70", "0.039059"], ["84271.41", "0.007515"], ["84271.38", "0.001228"], ["84271.34", "0.016178"], ["84271.33", "0.006488"], ["84271.30", "0"], ["84269.90", "0.008555"], ["84269.85", "0.008988"], ["84269.81", "0.006213"], ["84269.70", "0.102788"], ["84269.56", "0"], ["84269.30", "0"], ["84269.09", "0.825573"], ["84268.65", "0.008142"], ["84268.38", "0.007870"], ["84268.11", "0.017837"], ["84268.03", "0.084444"], ["84267.85", "0.248017"], ["84267.70", "0.270495"], ["84267.32", "0.005938"], ["84267.30", "0"], ["84266.72", "0"], ["84266.65", "0.007437"], ["84266.53", "0.007346"], ["84266.51", "0.006536"], ["84266.21", "0.015772"], ["84266.08", "0.017080"], ["84265.81", "0.056358"], ["84265.70", "0.711828"], ["84265.59", "0.002062"], ["84265.36", "0.028809"], ["84265.35", "0.007120"], ["84265.30", "0"], ["84265.14", "0.016461"], ["84265.06", "0.007317"], ["84264.99", "0.017062"], ["84264.97", "0"], ["84264.77", "0.006565"], ["84264.75", "0.025086"], ["84264.60", "0.008989"], ["84264.32", "0.005552"], ["84264.31", "0.007934"], ["84264.30", "0.008165"], ["84264.26", "0.004937"], ["84264.24", "0.000875"], ["84264.19", "0.227687"], ["84264.18", "0.005089"], ["84264.11", "0.009630"], ["84263.79", "0.007950"], ["84263.76", "0.007475"], ["84263.70", "1.873232"], ["84263.30", "0"], ["84262.76", "0.017333"], ["84262.37", "0.002949"], ["84262.26", "0.012650"], ["84261.70", "4.929558"], ["84261.60", "0.001012"], ["84261.44", "0.008284"], ["84261.30", "0"], ["84261.27", "0.052111"], ["84260.97", "0.008151"], ["84260.93", "0.271918"], ["84260.90", "0.372330"], ["84260.86", "0"], ["84260.80", "0.266280"], ["84260.77", "0"], ["84260.73", "0"], ["84260.46", "0"], ["84260.25", "0.018521"], ["84260.00", "0.035580"], ["84259.80", "0.069600"], ["84259.52", "0.008672"], ["84259.43", "0"], ["84259.39", "0"], ["84259.37", "0.021110"], ["84259.36", "0.010237"], ["84259.34", "0"], ["84259.32", "0.202088"], ["84259.30", "0.918810"], ["84259.07", "0"], ["84259.06", "0"], ["84258.76", "0.076018"], ["84258.58", "0.222746"], ["84258.40", "2.442360"], ["84258.27", "0"], ["84258.18", "0.263346"], ["84257.97", "0"], ["84257.86", "0"], ["84257.84", "0"], ["84257.83", "0"], ["84257.80", "0.212100"], ["84257.43", "0"], ["84257.30", "0"], ["84257.10", "0"], ["84257.07", "0.012440"], ["84257.03", "0"], ["84257.00", "0.451110"], ["84256.56", "0"], ["84256.50", "0.424920"], ["84256.40", "0"], ["84256.37", "0"], ["84256.34", "0"], ["84256.19", "0"], ["84255.80", "0.069600"], ["84255.59", "0"], ["84255.41", "0.073510"], ["84255.30", "0"], ["84255.21", "0"], ["84254.90", "0.013140"], ["84254.85", "0"], ["84254.84", "0.056642"], ["84254.76", "0"], ["84254.71", "0"], ["84254.50", "0.065280"], ["84254.47", "0"], ["84254.28", "0"], ["84254.18", "0"], ["84254.14", "0"], ["84254.06", "0"], ["84253.80", "0.069600"], ["84253.71", "0"], ["84253.70", "2.831010"], ["84253.65", "0"], ["84253.64", "0"], ["84253.60", "0.177960"], ["84253.59", "0"], ["84253.52", "0"], ["84253.30", "0.028950"], ["84252.90", "0"], ["84252.60", "0"], ["84252.58", "0"], ["84252.43", "0"], ["84252.24", "0"], ["84252.23", "0"], ["84252.08", "0"], ["84251.90", "0"], ["84251.67", "0"], ["84250.86", "0"], ["84250.10", "0.414210"], ["84249.93", "0"], ["84249.31", "0"], ["84249.10", "0.018060"], ["84248.73", "0"], ["84248.50", "0"], ["84247.20", "0"], ["84246.77", "0"], ["84246.41", "0"], ["84246.10", "0.638880"], ["84245.05", "0"], ["84245.00", "0.142500"], ["84244.70", "0.420000"], ["84244.62", "0"], ["84243.80", "0"], ["84243.00", "0"], ["84242.35", "0.008209"], ["84242.20", "0"], ["84241.80", "0"], ["84241.11", "0.007182"], ["84240.70", "0"], ["84240.50", "0"], ["84240.40", "0"], ["84240.10", "0"], ["84239.30", "0"], ["84237.90", "0.007585"], ["84236.39", "0.017796"], ["84234.97", "0"], ["84230.64", "0"], ["84230.63", "0"], ["84224.26", "0"], ["84222.71", "0"], ["84219.50", "5.061056"], ["84211.20", "0"], ["84211.00", "5.422560"], ["84202.70", "0"], ["84202.50", "5.512936"], ["84194.20", "0"], ["84194.00", "3.886168"], ["84185.70", "0"], ["84185.50", "4.247672"], ["84177.20", "0"], ["84177.00", "4.518800"], ["84168.70", "0"], ["84168.50", "4.880304"], ["84160.20", "0"], ["84160.00", "5.332184"], ["84151.70", "0"], ["84151.50", "4.157296"], ["84143.20", "0"], ["84143.00", "4.066920"], ["84134.70", "0"], ["84134.50", "4.789928"], ["84126.20", "0"], ["84126.00", "4.699552"], ["84117.70", "0"], ["84117.50", "4.428424"], ["84109.20", "0"], ["84109.00", "5.151432"], ["84100.70", "0"], ["84100.50", "4.338048"], ["84092.20", "0"], ["84092.00", "5.603312"], ["84083.70", "0"], ["84083.50", "4.609176"], ["84075.20", "0"], ["84075.00", "4.970680"], ["84066.70", "0"], ["84066.50", "5.241808"], ["84058.20", "0"], ["84058.00", "3.976544"], ["84049.70", "0"], ["83992.38", "0"], ["83958.29", "1.679842"], ["83954.15", "0"], ["83891.43", "0"], ["83891.30", "0"]], "checksum": 631941880, "ts": "1742142210952"}], "ts": 1742142210957, "record_time": 1742142210.06997}
{"action": "update", "arg": {"instType": "SPOT", "channel": "books", "instId": "BTCUSDT"}, "data": [{"asks": [["84293.16", "1.086300"], ["84296.34", "0.004595"], ["84297.45", "0.007627"], ["84298.86", "0.140092"], ["84301.38", "0.024115"], ["84303.68", "0.002325"], ["84305.35", "0"], ["84308.21", "0"], ["84310.00", "0.313262"], ["84318.24", "0"], ["84331.46", "0"], ["84332.10", "0.001466"], ["84334.10", "0.003859"], ["84336.10", "0.010154"], ["84338.10", "0.026722"], ["84338.43", "0.026414"], ["84340.10", "0.070320"], ["84342.10", "0.185055"], ["84344.10", "0.486985"], ["84346.10", "1.281540"], ["84347.80", "3.267930"], ["84350.80", "0"], ["84350.90", "0"], ["84351.30", "0"], ["84352.40", "0.015120"], ["84356.00", "0.450210"], ["84357.20", "0.032910"], ["84360.80", "0.175650"], ["84361.40", "0"], ["84388.30", "4.970680"], ["84396.80", "5.332184"], ["84405.30", "5.422560"], ["84430.80", "4.609176"], ["84439.30", "5.061056"], ["84447.80", "4.518800"], ["84456.30", "4.247672"], ["84464.80", "4.880304"], ["84473.30", "3.976544"], ["84481.80", "5.603312"], ["84490.30", "4.699552"], ["84498.80", "5.151432"], ["84507.30", "4.338048"], ["84515.80", "4.789928"], ["84524.30", "4.066920"], ["84532.80", "5.512936"], ["84541.30", "4.428424"], ["84549.80", "3.886168"], ["84859.29", "0"], ["84860.00", "0"]], "bids": [["84291.55", "1.086300"], ["84291.54", "0.012680"], ["84291.53", "0.000160"], ["84291.52", "0"], ["84291.15", "0.140092"], ["84290.69", "0.055142"], ["84285.95", "0.062760"], ["84281.74", "0.139206"], ["84281.62", "0.047500"], ["84277.51", "2.492681"], ["84276.14", "0"], ["84271.45", "0.000213"], ["84269.70", "0.102914"], ["84269.57", "0.001199"], ["84269.37", "0.018259"], ["84269.09", "0.072863"], ["84267.70", "0.270827"], ["84265.70", "0.712701"], ["84264.51", "0.001843"], ["84263.70", "1.875416"], ["84261.70", "4.935305"], ["84260.90", "0.371700"], ["84259.32", "0"], ["84256.10", "2.348970"], ["84255.11", "0"], ["84254.50", "0.062640"], ["84253.70", "2.325840"], ["84253.30", "0.020370"], ["84250.60", "0.038460"], ["84250.10", "0.095580"], ["84247.90", "0.090390"], ["84246.90", "0.090000"], ["84246.10", "0.740040"], ["84245.80", "0"], ["84245.00", "0"], ["84244.70", "0"], ["84219.50", "5.241808"], ["84211.00", "4.066920"], ["84202.50", "3.886168"], ["84194.00", "4.789928"], ["84185.50", "4.518800"], ["84177.00", "5.512936"], ["84168.50", "5.151432"], ["84167.00", "0"], ["84160.00", "3.976544"], ["84151.50", "5.422560"], ["84143.00", "4.157296"], ["84134.50", "4.609176"], ["84126.00", "4.970680"], ["84117.50", "5.603312"], ["84109.00", "4.699552"], ["84092.00", "4.880304"], ["84083.50", "5.061056"], ["84075.00", "4.247672"], ["84066.50", "4.428424"], ["84058.00", "5.332184"], ["83894.17", "0"], ["83893.81", "0"], ["83893.64", "0"], ["83893.62", "0"], ["83892.29", "0"]], "checksum": 696142718, "ts": "1742142211155"}], "ts": 1742142211159, "record_time": 1742142210.266524}
{"action": "update", "arg": {"instType": "SPOT", "channel": "books", "instId": "BTCUSDT"}, "data": [{"asks": [["84293.15", "0.599900"], ["84293.16", "0"], ["84293.18", "0"], ["84293.20", "0"], ["84293.22", "0"], ["84293.27", "0"], ["84293.32", "0"], ["84294.09", "0"], ["84294.11", "0"], ["84294.12", "0"], ["84294.14", "0"], ["84294.15", "0"], ["84294.17", "0"], ["84294.19", "0"], ["84296.34", "0"], ["84296.50", "0"], ["84296.55", "0"], ["84296.59", "0"], ["84297.11", "0"], ["84297.40", "0"], ["84297.42", "0"], ["84297.43", "0"], ["84297.45", "0"], ["84298.86", "0"], ["84299.58", "0.030015"], ["84299.83", "0.006307"], ["84300.64", "0.007955"], ["84300.67", "0.009033"], ["84300.70", "0.004739"], ["84301.31", "0.140090"], ["84301.38", "0"], ["84301.51", "0.008506"], ["84301.56", "0.007359"], ["84302.04", "0.004595"], ["84302.19", "0.015048"], ["84302.22", "0.001066"], ["84302.23", "0.000245"], ["84302.24", "0.008962"], ["84302.51", "0"], ["84303.08", "0.000443"], ["84303.11", "0.009191"], ["84303.13", "0.007385"], ["84303.14", "0.000078"], ["84303.16", "0.007627"], ["84303.68", "0"], ["84307.26", "0"], ["84308.80", "0.080382"], ["84309.15", "0.014770"], ["84309.16", "0"], ["84310.00", "0"], ["84310.27", "0"], ["84311.84", "0"], ["84312.24", "0"], ["84312.50", "0.313262"], ["84312.67", "1.894541"], ["84312.79", "0"], ["84313.92", "0"], ["84314.52", "0"], ["84315.15", "0.012680"], ["84315.22", "0"], ["84315.60", "0.119843"], ["84316.05", "0"], ["84316.06", "0"], ["84316.20", "0.119869"], ["84316.73", "0"], ["84318.86", "0.110893"], ["84318.93", "0"], ["84319.28", "0.010985"], ["84319.45", "0"], ["84319.51", "0.006356"], ["84319.94", "0.007217"], ["84319.95", "0"], ["84320.15", "0.006356"], ["84322.15", "0.006356"], ["84322.19", "0.006356"], ["84322.26", "0.006357"], ["84323.10", "0.006356"], ["84323.73", "0.010984"], ["84324.34", "0.009989"], ["84326.10", "0"], ["84326.60", "0.119879"], ["84327.18", "0.009989"], ["84328.10", "0"], ["84329.53", "2.229549"], ["84330.10", "0"], ["84331.80", "0.001025"], ["84332.10", "0"], ["84333.80", "0.001020"], ["84334.10", "0"], ["84335.80", "0.001039"], ["84336.10", "0"], ["84337.80", "0.001083"], ["84338.10", "0"], ["84339.80", "0.002850"], ["84340.10", "0"], ["84341.80", "0.007501"], ["84342.10", "0"], ["84343.80", "0.019740"], ["84344.10", "0"], ["84345.80", "0.051947"], ["84346.10", "0"], ["84346.90", "0"], ["84347.00", "0"], ["84347.10", "0"], ["84347.50", "0"], ["84347.80", "0.136701"], ["84349.80", "0.359740"], ["84350.20", "0"], ["84351.80", "0.946684"], ["84352.10", "0.001033"], ["84352.30", "0.001410"], ["84352.40", "0.015540"], ["84352.80", "0.015300"], ["84353.10", "0.001041"], ["84353.50", "0.001044"], ["84354.50", "0"], ["84354.90", "0"], ["84355.00", "0"], ["84355.40", "7.151670"], ["84356.80", "0.265950"], ["84357.20", "0"], ["84358.30", "0"], ["84359.70", "0"], ["84360.80", "0.257430"], ["84361.40", "0.142500"], ["84361.80", "0.410370"], ["84362.20", "0.078210"], ["84364.30", "11.224110"], ["84364.40", "1.467000"], ["84364.70", "0.025350"], ["84376.97", "0"], ["84388.30", "0"], ["84394.00", "5.151083"], ["84396.80", "0"], ["84402.50", "5.060713"], ["84403.37", "0.057629"], ["84405.30", "0"], ["84411.00", "4.970343"], ["84413.80", "0"], ["84419.50", "4.247384"], ["84422.30", "0"], ["84428.00", "5.512562"], ["84430.80", "0"], ["84436.50", "5.241453"], ["84439.30", "0"], ["84445.00", "4.518494"], ["84447.80", "0"], ["84453.50", "5.422192"], ["84456.30", "0"], ["84462.00", "3.885905"], ["84464.80", "0"], ["84470.50", "5.602932"], ["84473.30", "0"], ["84479.00", "4.789603"], ["84481.80", "0"], ["84487.50", "4.699233"], ["84490.30", "0"], ["84496.00", "4.428124"], ["84498.80", "0"], ["84504.50", "4.157014"], ["84507.30", "0"], ["84513.00", "4.608864"], ["84515.80", "0"], ["84521.50", "4.066644"], ["84524.30", "0"], ["84530.00", "4.337754"], ["84532.80", "0"], ["84538.50", "4.879973"], ["84541.30", "0"], ["84547.00", "5.331823"], ["84549.80", "0"], ["84555.50", "3.976275"], ["84859.29", "0.000036"], ["84860.00", "0.000169"], ["84862.90", "0.000169"], ["84864.69", "0.000052"], ["84864.86", "0.000041"]], "bids": [["84293.14", "0.209200"], ["84292.08", "1.894541"], ["84291.60", "0.209200"], ["84291.56", "0.754124"], ["84291.55", "0.000516"], ["84291.54", "0.000164"], ["84291.53", "0"], ["84287.40", "0.001013"], ["84285.40", "0.001003"], ["84283.40", "0.002046"], ["84281.74", "0"], ["84281.73", "0"], ["84281.70", "0"], ["84281.40", "0.005383"], ["84279.70", "0"], ["84279.40", "0.014166"], ["84277.70", "0"], ["84277.52", "0.958315"], ["84277.51", "0.035598"], ["84277.40", "0.037281"], ["84277.15", "0.000213"], ["84277.08", "0.001228"], ["84277.01", "0.006488"], ["84275.70", "0"], ["84275.57", "0.008555"], ["84275.53", "0.006213"], ["84275.40", "0.098107"], ["84275.22", "2.549465"], ["84274.89", "0.247973"], ["84273.99", "0.007870"], ["84273.70", "0"], ["84273.40", "0.258176"], ["84273.10", "0.013882"], ["84272.81", "0.016458"], ["84272.79", "0.003069"], ["84272.43", "0.006564"], ["84272.02", "0.002062"], ["84271.70", "0"], ["84271.45", "0"], ["84271.41", "0"], ["84271.40", "0.735758"], ["84271.38", "0"], ["84271.34", "0"], ["84271.33", "0"], ["84270.43", "0.017330"], ["84270.39", "0.008164"], ["84270.34", "0.007475"], ["84270.28", "0.007950"], ["84269.94", "0.004937"], ["84269.90", "0"], ["84269.88", "0.005089"], ["84269.85", "0"], ["84269.81", "0"], ["84269.80", "0.009630"], ["84269.70", "0"], ["84269.57", "0"], ["84269.55", "0"], ["84269.40", "1.787921"], ["84268.93", "0.052102"], ["84268.65", "0"], ["84268.48", "0.008282"], ["84268.38", "0"], ["84267.86", "0.018518"], ["84267.85", "0"], ["84267.70", "0"], ["84267.48", "0.008151"], ["84267.40", "4.705056"], ["84267.30", "0.001035"], ["84267.11", "0.197876"], ["84266.79", "0.002949"], ["84266.70", "0.001025"], ["84266.65", "0"], ["84266.53", "0"], ["84266.51", "0"], ["84266.25", "0.222707"], ["84266.10", "0.001015"], ["84266.00", "0.001048"], ["84265.82", "0.010237"], ["84265.81", "0"], ["84265.80", "2.766210"], ["84265.70", "0"], ["84265.59", "0"], ["84265.14", "0"], ["84265.12", "0.076005"], ["84265.00", "2.172300"], ["84264.90", "1.675890"], ["84264.77", "0"], ["84264.32", "0"], ["84264.30", "0"], ["84264.26", "0"], ["84264.24", "0"], ["84264.20", "0.142500"], ["84264.18", "0"], ["84264.11", "0"], ["84263.80", "0.069600"], ["84263.79", "0"], ["84263.76", "0"], ["84263.70", "0"], ["84263.10", "0.265440"], ["84262.76", "0"], ["84262.37", "0"], ["84262.26", "0"], ["84261.80", "0.069600"], ["84261.70", "1.191480"], ["84261.60", "0"], ["84261.44", "0"], ["84261.27", "0"], ["84260.97", "0"], ["84260.90", "0"], ["84260.80", "0"], ["84260.25", "0"], ["84260.00", "0"], ["84259.80", "0.366120"], ["84259.52", "0"], ["84259.36", "0"], ["84258.76", "0"], ["84258.58", "0"], ["84258.40", "1.718430"], ["84256.50", "0"], ["84256.10", "0"], ["84255.63", "0.023737"], ["84255.30", "0.383610"], ["84255.09", "0.023936"], ["84254.90", "0"], ["84250.10", "0.220140"], ["84249.10", "0"], ["84248.85", "0.008209"], ["84248.80", "0.090000"], ["84248.70", "0.177960"], ["84247.90", "0"], ["84247.80", "0"], ["84246.90", "0"], ["84246.83", "0.007182"], ["84246.10", "0"], ["84244.38", "0.007585"], ["84242.35", "0"], ["84241.95", "0"], ["84241.11", "0"], ["84239.31", "0"], ["84238.00", "0.207047"], ["84237.90", "0"], ["84225.20", "4.699233"], ["84219.50", "0"], ["84216.70", "4.247384"], ["84211.00", "0"], ["84208.20", "5.331823"], ["84202.50", "0"], ["84199.70", "3.976275"], ["84194.00", "0"], ["84191.20", "5.151083"], ["84185.50", "0"], ["84182.70", "4.337754"], ["84180.00", "0"], ["84177.00", "0"], ["84174.20", "4.970343"], ["84168.50", "0"], ["84166.00", "0"], ["84165.70", "5.512562"], ["84160.00", "0.024386"], ["84157.20", "5.602932"], ["84151.50", "0"], ["84148.70", "4.879973"], ["84143.00", "0"], ["84140.20", "5.241453"], ["84134.50", "0"], ["84131.70", "4.428124"], ["84126.00", "0"], ["84123.20", "4.608864"], ["84117.50", "0"], ["84114.70", "3.885905"], ["84109.00", "0"], ["84106.20", "4.518494"], ["84100.50", "0"], ["84097.70", "5.060713"], ["84092.00", "0"], ["84089.20", "5.422192"], ["84083.50", "0"], ["84080.70", "4.066644"], ["84075.00", "0"], ["84072.20", "4.789603"], ["84066.50", "0"], ["84063.70", "4.157014"], ["84058.00", "0"], ["83894.17", "0.000022"], ["83893.81", "0.000010"], ["83893.64", "0.000039"], ["83893.62", "0.000137"], ["83892.29", "0.000143"], ["83891.43", "0.000455"]], "checksum": -100181035, "ts": "1742142211358"}], "ts": 1742142211362, "record_time": 1742142210.471211}
{"action": "update", "arg": {"instType": "SPOT", "channel": "books", "instId": "BTCUSDT"}, "data": [{"asks": [["84293.15", "0.758396"], ["84295.60", "0.063807"], ["84302.14", "0.005541"], ["84302.21", "0.001230"], ["84303.08", "0.001605"], ["84303.10", "0.014793"], ["84307.27", "0"], ["84312.06", "0"], ["84312.68", "0"], ["84312.77", "0"], ["84312.78", "0.143414"], ["84312.80", "0"], ["84313.87", "0"], ["84314.26", "0"], ["84314.80", "0"], ["84315.07", "0.001205"], ["84315.14", "0"], ["84315.26", "0"], ["84315.98", "0.148098"], ["84317.46", "0.035952"], ["84318.58", "0.006356"], ["84318.75", "0.006356"], ["84318.84", "0.006356"], ["84318.86", "0"], ["84318.87", "0"], ["84319.02", "0.006356"], ["84319.88", "0.006356"], ["84320.39", "0.006356"], ["84320.41", "0.006356"], ["84320.48", "0.006356"], ["84321.12", "0.006356"], ["84322.27", "0"], ["84325.96", "0.015892"], ["84326.60", "0.239760"], ["84326.62", "0.001807"], ["84335.80", "0.001000"], ["84337.80", "0.001854"], ["84339.80", "0.004879"], ["84341.80", "0.012839"], ["84343.80", "0.033786"], ["84345.80", "0.088910"], ["84347.80", "0.233974"], ["84349.80", "0.615722"], ["84351.80", "1.620320"], ["84352.40", "0.001045"], ["84353.00", "4.165860"], ["84353.10", "0"], ["84353.50", "0"], ["84355.40", "3.694380"], ["84357.30", "0.015150"], ["84358.50", "0.035580"], ["84360.00", "0.002000"], ["84362.90", "0.032910"], ["84364.50", "0.035550"], ["84364.70", "0"], ["84394.00", "4.699233"], ["84402.50", "4.518494"], ["84411.00", "3.885905"], ["84419.50", "4.066644"], ["84428.00", "5.331823"], ["84436.50", "4.337754"], ["84445.00", "4.608864"], ["84453.50", "4.157014"], ["84462.00", "4.247384"], ["84470.50", "5.060713"], ["84479.00", "3.976275"], ["84487.50", "5.602932"], ["84496.00", "5.241453"], ["84504.50", "5.512562"], ["84513.00", "4.970343"], ["84521.50", "4.879973"], ["84530.00", "5.151083"], ["84538.50", "4.789603"], ["84547.00", "5.422192"], ["84555.50", "4.428124"], ["84857.14", "0"], ["84858.75", "0"], ["84859.29", "0"], ["84860.00", "0"], ["84862.90", "0"], ["84864.69", "0"], ["84864.86", "0"]], "bids": [["84293.14", "1.071020"], ["84292.09", "0.916134"], ["84291.56", "0.353132"], ["84291.55", "0.000356"], ["84290.69", "0"], ["84283.40", "0.002371"], ["84281.40", "0.006240"], ["84279.40", "0.016420"], ["84277.52", "0.649837"], ["84277.40", "0.043210"], ["84277.11", "0.007515"], ["84277.03", "0.007643"], ["84277.02", "0.008535"], ["84275.57", "0.017543"], ["84275.53", "0.013650"], ["84275.40", "0.113711"], ["84275.24", "0.001199"], ["84274.34", "0.008142"], ["84274.16", "0.017833"], ["84273.62", "0.084428"], ["84273.40", "0.298990"], ["84273.33", "0.005937"], ["84272.22", "0.015769"], ["84272.10", "0.017076"], ["84271.40", "0.786817"], ["84271.16", "0.007118"], ["84270.65", "0.007315"], ["84270.38", "0.007932"], ["84270.00", "0.005552"], ["84269.94", "0.005812"], ["84269.40", "2.070571"], ["84269.09", "0"], ["84268.39", "0.008672"], ["84268.31", "0.012647"], ["84268.11", "0"], ["84268.03", "0"], ["84267.40", "5.448870"], ["84267.32", "0"], ["84266.21", "0"], ["84266.08", "0"], ["84265.90", "0.263297"], ["84265.80", "1.244520"], ["84265.35", "0"], ["84265.06", "0"], ["84265.00", "0.014970"], ["84264.90", "0.165090"], ["84264.60", "0.265440"], ["84264.31", "0"], ["84263.10", "0"], ["84261.70", "0.020550"], ["84260.70", "3.350460"], ["84259.80", "0.069600"], ["84258.18", "0"], ["84256.30", "0.038460"], ["84253.30", "0"], ["84252.10", "0.410370"], ["84250.60", "0"], ["84248.70", "0"], ["84225.20", "5.422192"], ["84216.70", "4.970343"], ["84208.20", "3.976275"], ["84199.70", "4.879973"], ["84191.20", "4.337754"], ["84182.70", "4.789603"], ["84174.20", "4.066644"], ["84165.70", "4.699233"], ["84157.20", "4.247384"], ["84148.70", "4.518494"], ["84140.20", "5.060713"], ["84131.70", "5.602932"], ["84123.20", "5.241453"], ["84114.70", "5.151083"], ["84106.20", "3.885905"], ["84097.70", "4.428124"], ["84089.20", "5.512562"], ["84080.70", "5.331823"], ["84072.20", "4.608864"], ["83894.17", "0"], ["83893.81", "0"], ["83893.64", "0"], ["83893.62", "0"], ["83892.29", "0"], ["83891.43", "0"]], "checksum": -1908719551, "ts": "1742142211560"}], "ts": 1742142211566, "record_time": 1742142210.675521}
{"action": "update", "arg": {"instType": "SPOT", "channel": "books", "instId": "BTCUSDT"}, "data": [{"asks": [["84308.79", "0.028546"], ["84319.26", "0"], ["84325.25", "0.119895"], ["84347.80", "0.233754"], ["84349.80", "0.615142"], ["84351.80", "1.618795"], ["84356.00", "0.245820"], ["84394.00", "4.879973"], ["84402.50", "5.060713"], ["84411.00", "4.789603"], ["84419.50", "5.602932"], ["84428.00", "3.976275"], ["84436.50", "3.885905"], ["84445.00", "5.331823"], ["84453.50", "5.422192"], ["84462.00", "4.337754"], ["84470.50", "5.241453"], ["84479.00", "4.518494"], ["84487.50", "4.247384"], ["84496.00", "5.512562"], ["84504.50", "4.157014"], ["84513.00", "4.066644"], ["84521.50", "4.428124"], ["84538.50", "4.608864"], ["84547.00", "4.970343"], ["84555.50", "4.699233"], ["84853.56", "0"]], "bids": [["84285.70", "0.003006"], ["84281.63", "0.021048"], ["84277.52", "0.516905"], ["84277.40", "0.043433"], ["84275.40", "0.114298"], ["84273.40", "0.300612"], ["84271.40", "0.791085"], ["84269.40", "2.081802"], ["84267.40", "5.478425"], ["84266.91", "0.271868"], ["84265.80", "0.445440"], ["84265.00", "0.015390"], ["84264.70", "0.265440"], ["84264.60", "0.008989"], ["84260.93", "0"], ["84254.60", "0.071310"], ["84250.95", "0.003523"], ["84249.80", "0"], ["84248.80", "0"], ["84242.69", "0.018226"], ["84230.85", "0"], ["84225.20", "4.337754"], ["84208.20", "5.241453"], ["84199.70", "5.060713"], ["84191.20", "4.428124"], ["84169.00", "0.012838"], ["84165.70", "5.512562"], ["84157.20", "5.331823"], ["84148.70", "4.608864"], ["84140.20", "3.976275"], ["84131.70", "4.879973"], ["84123.20", "5.422192"], ["84106.20", "4.157014"], ["84097.70", "4.518494"], ["84089.20", "4.699233"], ["84080.70", "3.885905"], ["84072.20", "4.247384"], ["84063.70", "5.602932"], ["84040.54", "0"], ["83894.74", "0"]], "checksum": -2079639548, "ts": "1742142211761"}], "ts": 1742142211764, "record_time": 1742142210.872068}
{"action": "update", "arg": {"instType": "SPOT", "channel": "books", "instId": "BTCUSDT"}, "data": [{"asks": [["84301.31", "0"], ["84303.46", "0.140087"], ["84312.66", "0.700726"], ["84312.78", "0"], ["84337.80", "0.001721"], ["84339.80", "0.004527"], ["84341.80", "0.011915"], ["84343.80", "0.031353"], ["84345.80", "0.082509"], ["84347.80", "0.217129"], ["84349.80", "0.571391"], ["84351.80", "1.503661"], ["84394.00", "3.885905"], ["84402.50", "4.789603"], ["84411.00", "4.879973"], ["84419.50", "4.157014"], ["84428.00", "4.608864"], ["84436.50", "5.422192"], ["84445.00", "5.512562"], ["84453.50", "5.060713"], ["84462.00", "4.518494"], ["84470.50", "5.151083"], ["84479.00", "5.602932"], ["84487.50", "4.066644"], ["84496.00", "5.241453"], ["84504.50", "3.976275"], ["84513.00", "4.337754"], ["84521.50", "4.970343"], ["84530.00", "5.331823"], ["84538.50", "4.247384"], ["84547.00", "4.699233"], ["84555.50", "4.428124"]], "bids": [["84293.14", "0.814250"], ["84291.60", "0"], ["84279.40", "0.016654"], ["84277.40", "0.043825"], ["84277.00", "0.003036"], ["84275.40", "0.115330"], ["84273.40", "0.303499"], ["84271.40", "0.798683"], ["84270.29", "0"], ["84269.40", "2.101797"], ["84267.40", "5.531045"], ["84265.80", "0.299730"], ["84265.70", "0.035580"], ["84260.70", "3.363150"], ["84259.70", "0.286770"], ["84259.00", "0.009000"], ["84251.80", "0"], ["84251.40", "0"], ["84250.90", "0"], ["84250.10", "0"], ["84225.20", "3.885905"], ["84216.70", "4.066644"], ["84208.20", "4.608864"], ["84199.70", "4.970343"], ["84191.20", "5.060713"], ["84182.70", "4.699233"], ["84174.20", "4.337754"], ["84165.70", "4.247384"], ["84164.00", "0.000159"], ["84148.70", "5.512562"], ["84140.20", "5.422192"], ["84123.20", "4.518494"], ["84114.70", "3.976275"], ["84106.20", "5.602932"], ["84097.70", "4.428124"], ["84089.20", "4.157014"], ["84080.70", "5.151083"], ["84072.20", "4.789603"], ["84063.70", "5.241453"], ["83894.74", "0.000068"]], "checksum": 258685252, "ts": "1742142211970"}], "ts": 1742142212000, "record_time": 1742142211.108995}
{"action": "update", "arg": {"instType": "SPOT", "channel": "books", "instId": "BTCUSDT"}, "data": [{"asks": [["84295.51", "0.063807"], ["84295.60", "0"], ["84303.10", "0.055617"], ["84334.62", "0.031812"], ["84335.80", "0.001337"], ["84337.80", "0.003520"], ["84339.80", "0.009263"], ["84341.80", "0.024375"], ["84343.80", "0.064145"], ["84345.80", "0.168803"], ["84347.80", "0.444219"], ["84349.80", "1.168998"], ["84351.80", "3.076310"], ["84355.00", "0.142500"], ["84360.80", "0.379050"], ["84363.40", "0.441870"], ["84394.00", "4.970343"], ["84402.50", "5.241453"], ["84419.50", "4.337754"], ["84428.00", "4.247384"], ["84453.50", "4.066644"], ["84462.00", "4.789603"], ["84470.50", "4.518494"], ["84479.00", "5.151083"], ["84487.50", "5.331823"], ["84496.00", "5.060713"], ["84513.00", "4.157014"], ["84521.50", "5.602932"], ["84530.00", "4.428124"], ["84538.50", "4.699233"], ["84547.00", "3.885905"], ["84555.50", "4.608864"], ["84851.66", "0"], ["84852.81", "0"], ["84852.94", "0"]], "bids": [["84285.57", "0.000070"], ["84283.40", "0.001831"], ["84281.40", "0.004819"], ["84279.40", "0.012681"], ["84278.41", "0.195839"], ["84277.40", "0.033372"], ["84275.40", "0.087819"], ["84273.40", "0.231103"], ["84271.40", "0.608165"], ["84269.40", "1.600330"], ["84267.40", "4.211393"], ["84265.80", "0.291210"], ["84265.50", "0.424920"], ["84265.00", "0.012570"], ["84263.80", "0"], ["84261.80", "0"], ["84260.70", "0.422010"], ["84258.60", "3.718950"], ["84258.40", "1.061130"], ["84254.60", "0"], ["84253.60", "0"], ["84251.80", "0.069600"], ["84251.40", "0.142500"], ["84242.69", "0"], ["84208.20", "4.518494"], ["84199.70", "4.337754"], ["84191.20", "5.241453"], ["84182.70", "5.151083"], ["84174.20", "4.789603"], ["84165.70", "5.602932"], ["84157.20", "5.060713"], ["84148.70", "5.422192"], ["84140.20", "4.608864"], ["84131.70", "5.512562"], ["84123.20", "5.331823"], ["84114.70", "4.247384"], ["84106.20", "4.699233"], ["84100.39", "0.172590"], ["84097.70", "3.976275"], ["84089.20", "4.428124"], ["84080.70", "4.879973"], ["84072.20", "4.157014"], ["84063.70", "4.970343"], ["83895.00", "0"], ["83894.74", "0"]], "checksum": 1037230256, "ts": "1742142212171"}], "ts": 1742142212175, "record_time": 1742142211.283235}
{"action": "update", "arg": {"instType": "SPOT", "channel": "books", "instId": "BTCUSDT"}, "data": [{"asks": [["84315.97", "0.109344"], ["84334.62", "0"], ["84351.80", "3.076459"], ["84352.80", "0.001020"], ["84354.60", "0.265950"], ["84356.00", "0.197885"], ["84356.80", "0"], ["84357.30", "0"], ["84359.20", "0.015090"], ["84359.60", "0.015090"], ["84394.00", "3.976275"], ["84402.50", "4.066644"], ["84411.00", "4.699233"], ["84419.50", "5.422192"], ["84428.00", "5.060713"], ["84436.50", "3.885905"], ["84445.00", "4.428124"], ["84453.50", "4.247384"], ["84462.00", "4.608864"], ["84470.50", "4.337754"], ["84479.00", "5.241453"], ["84487.50", "5.602932"], ["84496.00", "4.879973"], ["84504.50", "4.518494"], ["84513.00", "5.151083"], ["84521.50", "5.512562"], ["84530.00", "4.970343"], ["84538.50", "5.331823"], ["84547.00", "4.789603"], ["84555.50", "4.157014"], ["84850.00", "0"]], "bids": [["84281.63", "0.075621"], ["84275.40", "0.088043"], ["84273.40", "0.231693"], ["84272.63", "0.030445"], ["84271.40", "0.609718"], ["84269.40", "1.604521"], ["84267.40", "4.222423"], ["84265.00", "0.012150"], ["84264.70", "0"], ["84261.70", "0"], ["84261.20", "0.265440"], ["84253.60", "0.177960"], ["84251.40", "0"], ["84225.20", "4.157014"], ["84216.70", "4.699233"], ["84208.20", "4.066644"], ["84199.70", "5.512562"], ["84191.20", "5.602932"], ["84182.70", "4.518494"], ["84174.20", "4.970343"], ["84165.70", "5.422192"], ["84157.20", "5.331823"], ["84148.70", "5.151083"], ["84140.20", "5.060713"], ["84131.70", "5.241453"], ["84123.20", "4.247384"], ["84114.70", "3.976275"], ["84106.20", "4.608864"], ["84097.70", "4.789603"], ["84089.20", "4.337754"], ["84080.70", "4.428124"], ["84072.20", "3.885905"], ["84063.70", "4.879973"], ["83895.00", "0.006121"]], "checksum": -499210505, "ts": "1742142212391"}], "ts": 1742142212395, "record_time": 1742142211.502715}
{"action": "update", "arg": {"instType": "SPOT", "channel": "books", "instId": "BTCUSDT"}, "data": [{"asks": [["84295.43", "0.063807"], ["84295.51", "0"], ["84299.57", "0.033780"], ["84310.44", "0.148098"], ["84315.98", "0"], ["84335.80", "0.001811"], ["84337.80", "0.004766"], ["84338.08", "0.031812"], ["84339.80", "0.012542"], ["84341.80", "0.033006"], ["84343.80", "0.086856"], ["84345.80", "0.228570"], ["84347.80", "0.601671"], ["84349.80", "1.583345"], ["84351.80", "4.166698"], ["84353.50", "0.024930"], ["84354.10", "0.265950"], ["84354.60", "0"], ["84356.20", "0.069600"], ["84394.00", "5.241453"], ["84402.50", "4.247384"], ["84411.00", "5.422192"], ["84419.50", "4.428124"], ["84428.00", "4.157014"], ["84436.50", "4.879973"], ["84445.00", "4.970343"], ["84453.50", "5.151083"], ["84462.00", "5.060713"], ["84470.50", "3.885905"], ["84479.00", "5.602932"], ["84487.50", "4.518494"], ["84496.00", "4.608864"], ["84504.50", "4.337754"], ["84513.00", "5.512562"], ["84521.50", "5.331823"], ["84530.00", "4.699233"], ["84538.50", "3.976275"], ["84555.50", "4.066644"], ["84846.85", "0"], ["84847.58", "0"], ["84847.82", "0"], ["84849.88", "0"]], "bids": [["84293.14", "1.167382"], ["84292.10", "0.885386"], ["84292.09", "0"], ["84291.56", "0"], ["84283.40", "0.001730"], ["84281.40", "0.004553"], ["84279.40", "0.011980"], ["84277.40", "0.031527"], ["84275.40", "0.082966"], ["84273.40", "0.218332"], ["84271.40", "0.574558"], ["84269.40", "1.511993"], ["84267.40", "3.978931"], ["84265.70", "0"], ["84260.70", "0.421650"], ["84258.60", "1.370040"], ["84254.80", "0.013140"], ["84254.10", "0.072570"], ["84225.20", "4.699233"], ["84216.70", "4.608864"], ["84199.70", "3.885905"], ["84191.20", "5.151083"], ["84182.70", "4.789603"], ["84174.20", "4.428124"], ["84168.00", "0"], ["84165.70", "4.518494"], ["84157.20", "5.241453"], ["84148.70", "5.602932"], ["84140.20", "5.331823"], ["84131.70", "5.422192"], ["84123.20", "5.060713"], ["84106.20", "4.247384"], ["84097.70", "4.157014"], ["84080.70", "4.879973"], ["84072.20", "4.970343"], ["84063.70", "5.512562"], ["83894.74", "0.000068"]], "checksum": -1002379815, "ts": "1742142212594"}], "ts": 1742142212598, "record_time": 1742142211.70609}
{"action": "update", "arg": {"instType": "SPOT", "channel": "books", "instId": "BTCUSDT"}, "data": [{"asks": [["84315.97", "0"], ["84335.80", "0.001448"], ["84337.80", "0.003809"], ["84338.08", "0"], ["84339.80", "0.010024"], ["84341.80", "0.026379"], ["84343.80", "0.069420"], ["84345.80", "0.182684"], ["84347.80", "0.480747"], ["84349.80", "1.265122"], ["84351.80", "3.329270"], ["84353.20", "0.265950"], ["84353.50", "0"], ["84354.10", "0"], ["84356.20", "0"], ["84360.60", "0.936510"], ["84394.00", "5.151083"], ["84402.50", "4.699233"], ["84411.00", "4.789603"], ["84419.50", "5.602932"], ["84428.00", "3.976275"], ["84436.50", "4.518494"], ["84445.00", "4.066644"], ["84453.50", "5.331823"], ["84462.00", "5.422192"], ["84470.50", "4.247384"], ["84479.00", "4.879973"], ["84487.50", "4.970343"], ["84496.00", "5.060713"], ["84504.50", "4.608864"], ["84521.50", "4.428124"], ["84530.00", "3.885905"], ["84538.50", "4.337754"], ["84547.00", "5.241453"], ["84555.50", "4.157014"], ["84846.85", "0.000176"], ["84847.58", "0.000039"], ["84847.82", "0.000671"]], "bids": [["84293.14", "1.307466"], ["84292.10", "0"], ["84292.09", "0.610546"], ["84291.15", "0"], ["84286.58", "0.000070"], ["84285.57", "0"], ["84271.40", "0.574673"], ["84269.40", "1.512298"], ["84267.40", "3.979730"], ["84265.80", "0.001027"], ["84265.50", "0.649230"], ["84265.00", "0.012570"], ["84258.60", "1.175220"], ["84258.30", "2.348910"], ["84257.90", "0.383550"], ["84255.30", "0"], ["84251.80", "0"], ["84225.20", "5.512562"], ["84216.70", "5.060713"], ["84208.20", "3.885905"], ["84199.70", "4.518494"], ["84191.20", "5.331823"], ["84182.70", "4.428124"], ["84174.20", "4.970343"], ["84165.70", "4.699233"], ["84157.20", "4.157014"], ["84148.70", "4.337754"], ["84140.20", "5.422192"], ["84131.70", "4.247384"], ["84123.20", "4.608864"], ["84114.70", "5.602932"], ["84106.20", "5.241453"], ["84097.70", "4.789603"], ["84089.20", "3.976275"], ["84072.20", "5.151083"], ["84063.70", "4.066644"], ["83894.17", "0.000022"]], "checksum": 1683474915, "ts": "1742142212809"}], "ts": 1742142212812, "record_time": 1742142211.919865}
{"action": "update", "arg": {"instType": "SPOT", "channel": "books", "instId": "BTCUSDT"}, "data": [{"asks": [["84293.15", "0.758875"], ["84308.79", "0.069407"], ["84341.80", "0.026492"], ["84343.41", "0.031812"], ["84343.80", "0.069715"], ["84345.80", "0.183460"], ["84347.80", "0.482790"], ["84349.80", "1.270502"], ["84351.80", "3.343424"], ["84360.60", "1.613130"], ["84360.80", "0.013830"], ["84381.30", "0.072042"], ["84394.00", "5.512562"], ["84402.50", "4.247384"], ["84411.00", "4.428124"], ["84419.50", "5.331823"], ["84428.00", "5.422192"], ["84436.50", "4.699233"], ["84445.00", "3.976275"], ["84453.50", "4.608864"], ["84462.00", "4.066644"], ["84470.50", "4.789603"], ["84479.00", "4.518494"], ["84487.50", "5.241453"], ["84496.00", "5.151083"], ["84504.50", "3.885905"], ["84513.00", "5.602932"], ["84521.50", "4.970343"], ["84530.00", "4.879973"], ["84538.50", "5.060713"], ["84547.00", "4.157014"], ["84555.50", "4.337754"], ["84847.58", "0"], ["84847.82", "0"]], "bids": [["84277.52", "0.750776"], ["84269.40", "1.512545"], ["84267.40", "3.980381"], ["84225.20", "5.602932"], ["84216.70", "4.337754"], ["84208.20", "4.879973"], ["84191.20", "5.060713"], ["84174.20", "4.066644"], ["84165.70", "4.789603"], ["84165.00", "0"], ["84157.20", "5.331823"], ["84148.70", "4.157014"], ["84140.20", "4.247384"], ["84131.70", "3.885905"], ["84123.20", "5.512562"], ["84114.70", "5.151083"], ["84106.20", "5.422192"], ["84097.70", "5.241453"], ["84089.20", "4.608864"], ["84080.70", "4.970343"], ["84072.20", "3.976275"], ["84063.70", "4.699233"], ["83893.81", "0.000010"]], "checksum": 40645662, "ts": "1742142213010"}], "ts": 1742142213014, "record_time": 1742142212.121831}
{"action": "update", "arg": {"instType": "SPOT", "channel": "books", "instId": "BTCUSDT"}, "data": [{"asks": [["84295.34", "0.063807"], ["84295.43", "0"], ["84299.57", "0"], ["84314.68", "0.012680"], ["84315.15", "0"], ["84316.19", "0.064914"], ["84326.78", "0.010000"], ["84335.80", "0.001972"], ["84337.80", "0.005189"], ["84339.80", "0.013654"], ["84341.80", "0.035932"], ["84343.41", "0"], ["84343.80", "0.094557"], ["84345.80", "0.248835"], ["84347.80", "0.654829"], ["84349.80", "1.723235"], ["84351.80", "4.534829"], ["84352.10", "0.380340"], ["84353.00", "4.431810"], ["84353.20", "0"], ["84353.50", "0.010980"], ["84356.20", "0.069600"], ["84364.30", "10.936950"], ["84364.40", "0.117000"], ["84364.50", "0"], ["84394.00", "5.602932"], ["84402.50", "4.428124"], ["84411.00", "5.422192"], ["84419.50", "3.976275"], ["84428.00", "4.157014"], ["84436.50", "4.066644"], ["84445.00", "4.608864"], ["84453.50", "5.060713"], ["84462.00", "3.885905"], ["84470.50", "4.970343"], ["84479.00", "5.241453"], ["84487.50", "5.151083"], ["84496.00", "4.247384"], ["84504.50", "5.512562"], ["84513.00", "4.337754"], ["84521.50", "4.789603"], ["84530.00", "4.518494"], ["84538.50", "4.879973"], ["84547.00", "5.331823"], ["84555.50", "4.699233"]], "bids": [["84289.97", "0.000070"], ["84286.82", "0.010000"], ["84286.58", "0"], ["84283.40", "0.001036"], ["84281.40", "0.002332"], ["84279.40", "0.006139"], ["84277.40", "0.016153"], ["84275.40", "0.042510"], ["84273.40", "0.111868"], ["84271.40", "0.294390"], ["84269.40", "0.774709"], ["84267.40", "2.038709"], ["84264.20", "0"], ["84260.70", "1.078020"], ["84259.80", "0"], ["84258.60", "0.669300"], ["84258.30", "0"], ["84257.50", "2.348940"], ["84254.80", "0"], ["84253.70", "0.975840"], ["84251.80", "0.069600"], ["84225.20", "5.060713"], ["84216.70", "4.789603"], ["84208.20", "5.512562"], ["84199.70", "5.151083"], ["84191.20", "3.976275"], ["84182.70", "4.608864"], ["84174.20", "5.331823"], ["84165.70", "4.428124"], ["84157.20", "4.247384"], ["84140.20", "4.970343"], ["84131.70", "5.602932"], ["84123.20", "4.879973"], ["84114.70", "5.422192"], ["84106.20", "4.337754"], ["84097.70", "4.066644"], ["84089.20", "5.241453"], ["84080.70", "3.885905"], ["84072.20", "4.518494"], ["83893.64", "0.000039"]], "checksum": 131800950, "ts": "1742142213216"}], "ts": 1742142213219, "record_time": 1742142212.326899}
{"action": "update", "arg": {"instType": "SPOT", "channel": "books", "instId": "BTCUSDT"}, "data": [{"asks": [["84335.80", "0.001120"], ["84337.80", "0.002949"], ["84339.80", "0.007760"], ["84341.80", "0.020422"], ["84343.80", "0.053900"], ["84345.80", "0.141842"], ["84347.80", "0.373270"], ["84349.80", "0.982290"], ["84351.80", "2.584972"], ["84353.50", "0"], ["84356.20", "0"], ["84357.10", "0.015150"], ["84357.50", "0.015150"], ["84359.20", "0"], ["84359.60", "0"], ["84364.40", "1.467000"], ["84364.50", "0.035550"], ["84394.00", "4.879973"], ["84402.50", "5.241453"], ["84411.00", "4.247384"], ["84419.50", "5.060713"], ["84428.00", "5.331823"], ["84436.50", "5.422192"], ["84445.00", "4.428124"], ["84453.50", "5.602932"], ["84462.00", "4.970343"], ["84470.50", "3.976275"], ["84479.00", "4.518494"], ["84487.50", "5.512562"], ["84496.00", "4.608864"], ["84504.50", "4.066644"], ["84513.00", "4.699233"], ["84521.50", "4.157014"], ["84530.00", "4.337754"], ["84538.50", "5.151083"], ["84547.00", "4.789603"], ["84555.50", "3.885905"], ["84847.58", "0.000039"]], "bids": [["84290.18", "0.000070"], ["84289.97", "0"], ["84286.83", "0.003000"], ["84281.40", "0.001982"], ["84279.40", "0.005215"], ["84277.40", "0.013724"], ["84275.40", "0.036114"], ["84273.40", "0.095037"], ["84271.40", "0.250097"], ["84269.40", "0.658151"], ["84267.40", "1.731976"], ["84264.20", "0.142500"], ["84263.80", "0.069600"], ["84261.80", "0.069600"], ["84260.70", "0.757350"], ["84259.00", "1.359000"], ["84258.60", "1.286370"], ["84251.80", "0"], ["84225.20", "4.970343"], ["84216.70", "5.151083"], ["84208.20", "4.608864"], ["84199.70", "3.976275"], ["84191.20", "4.789603"], ["84182.70", "4.066644"], ["84174.20", "4.699233"], ["84167.00", "0.000121"], ["84165.70", "4.157014"], ["84157.20", "5.060713"], ["84148.70", "4.518494"], ["84140.20", "5.241453"], ["84131.70", "4.879973"], ["84123.20", "5.331823"], ["84114.70", "4.247384"], ["84106.20", "5.512562"], ["84097.70", "4.337754"], ["84089.20", "3.885905"], ["84080.70", "4.428124"], ["84072.20", "5.422192"], ["84063.70", "5.602932"], ["83894.74", "0"], ["83894.17", "0"], ["83893.81", "0"], ["83893.64", "0"]], "checksum": 249219792, "ts": "1742142213425"}], "ts": 1742142213428, "record_time": 1742142212.537244}
{"action": "update", "arg": {"instType": "SPOT", "channel": "books", "instId": "BTCUSDT"}, "data": [{"asks": [["84293.15", "0.757815"], ["84295.34", "0"], ["84343.80", "0.053741"], ["84345.80", "0.141424"], ["84347.80", "0.372169"], ["84349.80", "0.979392"], ["84351.80", "2.577346"], ["84353.50", "0.007800"], ["84356.20", "0.069600"], ["84364.40", "0.117000"], ["84364.50", "0"], ["84381.30", "0"], ["84394.00", "4.789603"], ["84402.50", "4.970343"], ["84411.00", "4.337754"], ["84419.50", "4.699233"], ["84428.00", "5.241453"], ["84436.50", "4.608864"], ["84445.00", "5.331823"], ["84453.50", "4.428124"], ["84462.00", "4.157014"], ["84470.50", "5.602932"], ["84479.00", "5.512562"], ["84487.50", "5.151083"], ["84496.00", "5.422192"], ["84504.50", "4.247384"], ["84513.00", "5.060713"], ["84521.50", "3.885905"], ["84530.00", "4.879973"], ["84538.50", "4.066644"], ["84547.00", "4.518494"], ["84555.50", "3.976275"], ["84847.82", "0.000671"]], "bids": [["84290.18", "0"], ["84281.40", "0.002339"], ["84279.40", "0.006157"], ["84277.40", "0.016201"], ["84275.40", "0.042635"], ["84273.40", "0.112196"], ["84271.40", "0.295255"], ["84269.40", "0.776985"], ["84267.40", "2.044698"], ["84263.80", "0"], ["84261.80", "0"], ["84259.60", "2.348880"], ["84259.00", "0.009000"], ["84258.60", "0.669300"], ["84257.50", "0"], ["84254.80", "0.013140"], ["84225.20", "4.066644"], ["84216.70", "5.331823"], ["84208.20", "5.151083"], ["84199.70", "5.512562"], ["84191.20", "4.699233"], ["84182.70", "4.428124"], ["84174.20", "5.241453"], ["84166.00", "0.000159"], ["84165.70", "3.885905"], ["84157.20", "4.247384"], ["84148.70", "4.608864"], ["84140.20", "5.602932"], ["84131.70", "5.060713"], ["84123.20", "5.422192"], ["84114.70", "3.976275"], ["84106.20", "4.518494"], ["84089.20", "4.970343"], ["84080.70", "4.157014"], ["84072.20", "4.879973"], ["84063.70", "4.789603"], ["83894.74", "0.000068"]], "checksum": -69505283, "ts": "1742142213633"}], "ts": 1742142213638, "record_time": 1742142212.745625}
{"action": "update", "arg": {"instType": "SPOT", "channel": "books", "instId": "BTCUSDT"}, "data": [{"asks": [["84295.26", "0.063807"], ["84310.44", "0"], ["84343.80", "0.053746"], ["84345.80", "0.141436"], ["84347.80", "0.372201"], ["84349.80", "0.979477"], ["84351.80", "2.577569"], ["84353.50", "0"], ["84356.20", "0"], ["84364.40", "1.467000"], ["84364.50", "0.035550"], ["84394.00", "3.976275"], ["84395.97", "0.002935"], ["84402.50", "5.060713"], ["84411.00", "4.247384"], ["84419.50", "5.422192"], ["84428.00", "4.789603"], ["84436.50", "5.602932"], ["84445.00", "4.157014"], ["84453.50", "5.151083"], ["84462.00", "4.518494"], ["84470.50", "4.699233"], ["84479.00", "4.970343"], ["84487.50", "4.337754"], ["84496.00", "4.879973"], ["84504.50", "5.241453"], ["84513.00", "5.331823"], ["84521.50", "4.428124"], ["84530.00", "3.885905"], ["84538.50", "4.608864"], ["84547.00", "4.066644"], ["84555.50", "5.512562"]], "bids": [["84277.40", "0.016020"], ["84275.40", "0.042157"], ["84273.40", "0.110939"], ["84271.40", "0.291946"], ["84269.40", "0.768277"], ["84267.40", "2.021783"], ["84265.70", "0.004560"], ["84261.80", "0.069600"], ["84260.70", "1.419870"], ["84259.00", "1.359000"], ["84254.50", "0.071640"], ["84253.60", "0"], ["84252.10", "0"], ["84225.20", "4.247384"], ["84223.01", "0.002935"], ["84216.70", "4.518494"], ["84208.20", "4.337754"], ["84199.70", "5.331823"], ["84191.20", "5.241453"], ["84182.70", "4.789603"], ["84174.20", "4.066644"], ["84165.70", "4.608864"], ["84157.20", "5.602932"], ["84148.70", "3.885905"], ["84140.20", "5.060713"], ["84131.70", "5.422192"], ["84123.20", "4.879973"], ["84114.70", "4.970343"], ["84106.20", "5.512562"], ["84097.70", "4.699233"], ["84089.20", "3.976275"], ["84080.70", "5.151083"], ["84072.20", "4.428124"], ["84063.70", "4.157014"], ["83894.74", "0"]], "checksum": -1014206097, "ts": "1742142213845"}], "ts": 1742142213849, "record_time": 1742142212.956472}
{"action": "update", "arg": {"instType": "SPOT", "channel": "books", "instId": "BTCUSDT"}, "data": [{"asks": [["84301.58", "0.209200"], ["84308.79", "0.028546"], ["84314.68", "0.160778"], ["84329.52", "0.669772"], ["84335.80", "0.001009"], ["84337.80", "0.002140"], ["84339.80", "0.005631"], ["84341.80", "0.014818"], ["84343.80", "0.038994"], ["84345.80", "0.102616"], ["84347.80", "0.270042"], ["84349.80", "0.710638"], ["84351.80", "1.870100"], ["84352.10", "0.381180"], ["84353.00", "4.431600"], ["84364.40", "0.117000"], ["84364.50", "0"], ["84385.61", "0.072042"], ["84394.00", "4.337754"], ["84411.00", "4.789603"], ["84428.00", "4.879973"], ["84436.50", "5.512562"], ["84445.00", "3.885905"], ["84453.50", "3.976275"], ["84462.00", "4.157014"], ["84470.50", "5.151083"], ["84487.50", "4.247384"], ["84496.00", "4.428124"], ["84504.50", "5.331823"], ["84513.00", "5.241453"], ["84521.50", "4.608864"], ["84530.00", "5.602932"], ["84538.50", "4.518494"], ["84547.00", "4.699233"], ["84555.50", "4.066644"], ["84632.66", "0"], ["84646.85", "1.618308"], ["84847.58", "0"], ["84847.82", "0"]], "bids": [["84281.40", "0.002664"], ["84279.40", "0.007012"], ["84278.41", "0"], ["84277.40", "0.018451"], ["84275.40", "0.048557"], ["84273.40", "0.127781"], ["84271.40", "0.336264"], ["84269.40", "0.884907"], ["84267.40", "2.328701"], ["84261.30", "0.265440"], ["84261.20", "0"], ["84260.70", "1.391490"], ["84254.80", "0"], ["84253.60", "0.177960"], ["84225.20", "4.428124"], ["84216.70", "5.602932"], ["84208.20", "4.970343"], ["84199.70", "3.885905"], ["84191.20", "5.331823"], ["84182.70", "5.060713"], ["84174.20", "3.976275"], ["84165.70", "4.879973"], ["84157.20", "4.789603"], ["84148.70", "4.247384"], ["84140.20", "4.518494"], ["84131.70", "4.699233"], ["84123.20", "5.241453"], ["84114.70", "4.608864"], ["84106.20", "5.151083"], ["84097.70", "4.337754"], ["84089.20", "4.066644"], ["84080.70", "5.512562"], ["84072.20", "4.157014"], ["84063.70", "5.422192"], ["83972.36", "1.699691"], ["83958.29", "0"], ["83894.74", "0.000068"]], "checksum": 170267768, "ts": "1742142214045"}], "ts": 1742142214048, "record_time": 1742142213.156339}
{"action": "update", "arg": {"instType": "SPOT", "channel": "books", "instId": "BTCUSDT"}, "data": [{"asks": [["84295.19", "0.063807"], ["84295.26", "0"], ["84301.50", "0.078526"], ["84301.58", "0"], ["84335.80", "0.001055"], ["84337.80", "0.002778"], ["84339.80", "0.007310"], ["84341.80", "0.019236"], ["84343.80", "0.050622"], ["84345.80", "0.133214"], ["84347.80", "0.350564"], ["84349.80", "0.922536"], ["84351.80", "2.427728"], ["84353.50", "0.035580"], ["84364.40", "0"], ["84394.00", "5.241453"], ["84402.50", "3.976275"], ["84411.00", "5.422192"], ["84419.50", "5.151083"], ["84428.00", "5.512562"], ["84436.50", "3.885905"], ["84445.00", "4.970343"], ["84453.50", "4.428124"], ["84462.00", "4.518494"], ["84470.50", "4.699233"], ["84479.00", "5.331823"], ["84496.00", "4.066644"], ["84504.50", "4.337754"], ["84513.00", "4.608864"], ["84521.50", "4.157014"], ["84530.00", "5.060713"], ["84538.50", "4.879973"], ["84547.00", "5.602932"], ["84555.50", "4.789603"]], "bids": [["84285.51", "0.000070"], ["84281.63", "0.021048"], ["84281.40", "0.001896"], ["84279.40", "0.004989"], ["84277.40", "0.013129"], ["84275.40", "0.034550"], ["84273.40", "0.090921"], ["84272.63", "0.051573"], ["84271.40", "0.239265"], ["84269.40", "0.629646"], ["84267.40", "1.656962"], ["84265.70", "0"], ["84265.50", "0.606360"], ["84262.00", "0.265440"], ["84261.30", "0"], ["84260.70", "0.400020"], ["84259.60", "0"], ["84259.00", "0.009000"], ["84258.60", "1.287270"], ["84257.30", "2.348940"], ["84254.80", "0.013140"], ["84253.60", "0"], ["84225.20", "4.066644"], ["84216.70", "5.241453"], ["84208.20", "4.518494"], ["84199.70", "4.247384"], ["84191.20", "4.970343"], ["84182.70", "5.422192"], ["84174.20", "5.331823"], ["84169.00", "0.012717"], ["84157.20", "3.976275"], ["84148.70", "5.602932"], ["84140.20", "5.060713"], ["84131.70", "5.512562"], ["84123.20", "3.885905"], ["84114.70", "4.157014"], ["84106.20", "4.428124"], ["84097.70", "4.789603"], ["84089.20", "4.608864"], ["84080.70", "4.337754"], ["84072.20", "5.151083"], ["84063.70", "4.699233"]], "checksum": 158627405, "ts": "1742142214247"}], "ts": 1742142214250, "record_time": 1742142213.357853}
{"action": "update", "arg": {"instType": "SPOT", "channel": "books", "instId": "BTCUSDT"}, "data": [{"asks": [["84299.57", "0.033780"], ["84301.50", "0"], ["84338.81", "0"], ["84352.11", "0.001597"], ["84394.00", "4.518494"], ["84402.50", "4.789603"], ["84419.50", "4.699233"], ["84436.50", "4.247384"], ["84445.00", "5.602932"], ["84453.50", "4.337754"], ["84462.00", "4.157014"], ["84470.50", "4.066644"], ["84479.00", "4.970343"], ["84487.50", "3.976275"], ["84496.00", "4.608864"], ["84504.50", "5.060713"], ["84513.00", "3.885905"], ["84521.50", "5.151083"], ["84530.00", "5.241453"], ["84547.00", "4.428124"], ["84555.50", "5.331823"]], "bids": [["84281.74", "0.195462"], ["84281.40", "0.002100"], ["84279.40", "0.005527"], ["84277.40", "0.014545"], ["84275.40", "0.038276"], ["84273.40", "0.100726"], ["84271.40", "0.265068"], ["84269.40", "0.697548"], ["84267.40", "1.835653"], ["84266.70", "1.291230"], ["84266.00", "0"], ["84265.80", "0"], ["84265.50", "0.424920"], ["84265.00", "0.012150"], ["84259.00", "1.359000"], ["84254.50", "0.062640"], ["84253.60", "0.177960"], ["84252.60", "0.207960"], ["84237.64", "0.001180"], ["84225.20", "4.337754"], ["84224.35", "0"], ["84208.20", "5.512562"], ["84199.70", "4.699233"], ["84191.20", "4.789603"], ["84182.70", "4.428124"], ["84174.20", "4.066644"], ["84165.70", "4.157014"], ["84164.00", "0"], ["84157.20", "5.151083"], ["84148.70", "4.518494"], ["84131.70", "5.422192"], ["84123.20", "3.976275"], ["84114.70", "4.879973"], ["84106.20", "5.331823"], ["84097.70", "3.885905"], ["84080.70", "4.247384"], ["84072.20", "4.970343"], ["84063.70", "5.602932"]], "checksum": -2077811366, "ts": "1742142214447"}], "ts": 1742142214450, "record_time": 1742142213.557966}
{"action": "update", "arg": {"instType": "SPOT", "channel": "books", "instId": "BTCUSDT"}, "data": [{"asks": [["84295.12", "0.063807"], ["84295.19", "0"], ["84299.57", "0"], ["84339.80", "0.007204"], ["84341.80", "0.018958"], ["84343.80", "0.049888"], ["84345.80", "0.131285"], ["84347.80", "0.345488"], ["84349.80", "0.909178"], ["84351.80", "2.392574"], ["84353.50", "0"], ["84364.20", "0.012660"], ["84394.00", "4.066644"], ["84402.50", "5.512562"], ["84411.00", "4.608864"], ["84419.50", "4.157014"], ["84428.00", "4.789603"], ["84436.50", "4.337754"], ["84445.00", "4.247384"], ["84453.50", "4.518494"], ["84462.00", "4.970343"], ["84470.50", "5.060713"], ["84479.00", "5.331823"], ["84487.50", "5.151083"], ["84496.00", "5.241453"], ["84504.50", "4.428124"], ["84513.00", "5.602932"], ["84521.50", "5.422192"], ["84530.00", "3.885905"], ["84538.50", "4.699233"], ["84547.00", "4.879973"], ["84555.50", "3.976275"], ["84847.58", "0.000039"]], "bids": [["84293.14", "1.516666"], ["84281.75", "0.075177"], ["84281.63", "0"], ["84267.40", "1.835467"], ["84265.70", "0.009870"], ["84254.80", "0"], ["84253.30", "0.030000"], ["84252.60", "0"], ["84225.20", "4.247384"], ["84216.70", "4.608864"], ["84208.20", "3.976275"], ["84199.70", "5.241453"], ["84191.20", "4.879973"], ["84182.70", "4.970343"], ["84174.20", "5.151083"], ["84165.70", "5.331823"], ["84157.20", "4.518494"], ["84148.70", "5.602932"], ["84140.20", "4.066644"], ["84131.70", "4.789603"], ["84123.20", "5.422192"], ["84114.70", "5.060713"], ["84106.20", "4.337754"], ["84097.70", "4.699233"], ["84089.20", "4.428124"], ["84080.70", "4.157014"], ["84072.20", "5.512562"], ["84063.70", "3.885905"]], "checksum": -1383379790, "ts": "1742142214661"}], "ts": 1742142214665, "record_time": 1742142213.773483}
{"action": "update", "arg": {"instType": "SPOT", "channel": "books", "instId": "BTCUSDT"}, "data": [{"asks": [["84337.00", "0"], ["84339.80", "0.007101"], ["84341.80", "0.018793"], ["84343.80", "0.049455"], ["84345.80", "0.130144"], ["84347.80", "0.342485"], ["84349.80", "0.901276"], ["84350.26", "0.001597"], ["84351.80", "2.371779"], ["84355.39", "1.228091"], ["84394.00", "4.428124"], ["84402.50", "4.699233"], ["84411.00", "5.512562"], ["84419.50", "3.885905"], ["84428.00", "4.518494"], ["84436.50", "4.066644"], ["84453.50", "5.422192"], ["84462.00", "5.602932"], ["84470.50", "4.970343"], ["84479.00", "4.789603"], ["84487.50", "5.241453"], ["84496.00", "3.976275"], ["84504.50", "4.157014"], ["84513.00", "5.060713"], ["84521.50", "4.337754"], ["84530.00", "5.331823"], ["84538.50", "4.879973"], ["84547.00", "4.608864"], ["84555.50", "5.151083"], ["84847.58", "0"]], "bids": [["84293.14", "1.307466"], ["84279.40", "0.005529"], ["84277.40", "0.014550"], ["84275.40", "0.038289"], ["84273.40", "0.100761"], ["84271.40", "0.265160"], ["84267.40", "1.835653"], ["84267.11", "0"], ["84265.70", "0.035580"], ["84260.70", "0.736920"], ["84253.60", "0.207960"], ["84253.30", "0"], ["84252.60", "0.177960"], ["84239.67", "0.001189"], ["84226.42", "0"], ["84225.20", "3.885905"], ["84216.70", "5.151083"], ["84208.20", "4.428124"], ["84199.70", "4.157014"], ["84191.20", "4.608864"], ["84182.70", "5.512562"], ["84174.20", "5.060713"], ["84165.70", "4.518494"], ["84157.20", "5.331823"], ["84148.70", "4.247384"], ["84140.20", "4.789603"], ["84131.70", "4.879973"], ["84123.20", "5.241453"], ["84114.70", "3.976275"], ["84089.20", "4.066644"], ["84080.70", "5.602932"], ["84072.20", "4.970343"], ["84063.70", "5.422192"], ["83894.17", "0.000022"]], "checksum": -1887679095, "ts": "1742142214870"}], "ts": 1742142214875, "record_time": 1742142213.983219}
{"action": "update", "arg": {"instType": "SPOT", "channel": "books", "instId": "BTCUSDT"}, "data": [{"asks": [["84301.58", "0.209200"], ["84314.15", "0.148098"], ["84314.68", "0.012680"], ["84324.71", "0.174741"], ["84326.78", "0"], ["84335.80", "0.001673"], ["84337.80", "0.004403"], ["84339.80", "0.011588"], ["84341.80", "0.030495"], ["84343.80", "0.080250"], ["84345.80", "0.211184"], ["84347.80", "0.555746"], ["84349.80", "1.462489"], ["84351.80", "3.848656"], ["84352.30", "0.001200"], ["84353.00", "4.430970"], ["84353.50", "0.024780"], ["84356.20", "0.069600"], ["84364.30", "3.433830"], ["84394.00", "4.157014"], ["84402.50", "4.608864"], ["84411.00", "5.422192"], ["84419.50", "4.970343"], ["84428.00", "5.512562"], ["84436.50", "5.060713"], ["84445.00", "5.151083"], ["84453.50", "3.976275"], ["84470.50", "5.331823"], ["84479.00", "4.337754"], ["84487.50", "4.428124"], ["84496.00", "4.247384"], ["84504.50", "4.699233"], ["84513.00", "4.789603"], ["84521.50", "4.066644"], ["84530.00", "4.518494"], ["84538.50", "3.885905"], ["84547.00", "5.241453"], ["84555.50", "4.879973"], ["84846.15", "0"], ["84846.55", "0"], ["84846.85", "0"]], "bids": [["84286.82", "0"], ["84285.51", "0"], ["84281.40", "0.001949"], ["84279.40", "0.005130"], ["84277.40", "0.013501"], ["84275.40", "0.035528"], ["84273.40", "0.093494"], ["84271.40", "0.246036"], ["84269.40", "0.647464"], ["84267.40", "1.703853"], ["84266.70", "1.291440"], ["84265.70", "0"], ["84261.80", "0"], ["84260.70", "0.400020"], ["84259.00", "0.009000"], ["84254.80", "0.013140"], ["84253.70", "1.005840"], ["84253.60", "0.177960"], ["84252.60", "0"], ["84252.10", "0.410370"], ["84225.20", "5.151083"], ["84216.70", "4.066644"], ["84208.20", "5.331823"], ["84199.70", "4.337754"], ["84191.20", "4.789603"], ["84182.70", "4.699233"], ["84174.20", "5.512562"], ["84168.00", "0.000121"], ["84165.70", "4.157014"], ["84165.00", "0.000159"], ["84157.20", "4.428124"], ["84148.70", "5.602932"], ["84140.20", "4.608864"], ["84131.70", "3.976275"], ["84123.20", "3.885905"], ["84114.70", "5.060713"], ["84106.20", "5.422192"], ["84097.70", "4.970343"], ["84089.20", "4.879973"], ["84080.70", "5.241453"], ["84072.20", "4.247384"], ["84063.70", "4.518494"], ["83893.81", "0.000010"]], "checksum": -115744480, "ts": "1742142215078"}], "ts": 1742142215081, "record_time": 1742142214.194875}
{"action": "update", "arg": {"instType": "SPOT", "channel": "books", "instId": "BTCUSDT"}, "data": [{"asks": [["84295.05", "0.063807"], ["84295.12", "0"], ["84301.50", "0.078526"], ["84301.58", "0"], ["84335.80", "0.001017"], ["84337.80", "0.002497"], ["84339.80", "0.006571"], ["84341.80", "0.017292"], ["84343.80", "0.045507"], ["84345.80", "0.119754"], ["84347.80", "0.315143"], ["84349.80", "0.829324"], ["84351.80", "2.182431"], ["84355.39", "0"], ["84356.20", "0"], ["84364.20", "0"], ["84364.30", "7.377090"], ["84394.00", "4.518494"], ["84402.50", "4.337754"], ["84428.00", "3.885905"], ["84436.50", "4.428124"], ["84445.00", "4.699233"], ["84453.50", "4.789603"], ["84462.00", "5.241453"], ["84470.50", "4.247384"], ["84479.00", "5.060713"], ["84487.50", "5.602932"], ["84496.00", "4.608864"], ["84504.50", "4.157014"], ["84513.00", "5.331823"], ["84521.50", "4.879973"], ["84530.00", "5.512562"], ["84538.50", "3.976275"], ["84547.00", "5.151083"], ["84555.50", "4.066644"], ["84846.15", "0.004277"], ["84846.55", "0.000019"], ["84846.85", "0.000176"]], "bids": [["84293.14", "1.306471"], ["84292.08", "0"], ["84286.83", "0"], ["84284.93", "0.000070"], ["84281.40", "0.002017"], ["84279.40", "0.005309"], ["84277.40", "0.013972"], ["84275.40", "0.036767"], ["84273.40", "0.096756"], ["84271.40", "0.254620"], ["84269.40", "0.670053"], ["84267.40", "1.763299"], ["84261.80", "0.069600"], ["84259.00", "1.359000"], ["84252.10", "0"], ["84225.20", "3.976275"], ["84216.70", "4.247384"], ["84208.20", "4.337754"], ["84199.70", "5.602932"], ["84191.20", "4.970343"], ["84182.70", "5.060713"], ["84174.20", "5.422192"], ["84165.70", "5.512562"], ["84157.20", "4.879973"], ["84148.70", "3.885905"], ["84140.20", "4.157014"], ["84131.70", "4.428124"], ["84123.20", "4.699233"], ["84114.70", "5.241453"], ["84106.20", "5.151083"], ["84097.70", "5.331823"], ["84089.20", "4.608864"], ["84080.70", "4.518494"], ["84072.20", "4.789603"], ["84063.70", "4.066644"], ["83893.64", "0.000039"]], "checksum": -926756120, "ts": "1742142215283"}], "ts": 1742142215287, "record_time": 1742142214.394924}
{"action": "update", "arg": {"instType": "SPOT", "channel": "books", "instId": "BTCUSDT"}, "data": [{"asks": [["84299.57", "0.033780"], ["84301.50", "0"], ["84301.58", "0.209200"], ["84341.80", "0.017185"], ["84343.80", "0.045222"], ["84345.80", "0.119007"], ["84347.80", "0.313174"], ["84349.80", "0.824143"], ["84351.80", "2.168797"], ["84364.20", "0.012300"], ["84364.30", "7.128210"], ["84394.00", "5.060713"], ["84402.50", "4.789603"], ["84411.00", "4.157014"], ["84419.50", "5.512562"], ["84428.00", "5.331823"], ["84436.50", "4.247384"], ["84445.00", "4.879973"], ["84453.50", "3.976275"], ["84462.00", "4.608864"], ["84470.50", "4.518494"], ["84479.00", "4.970343"], ["84487.50", "5.241453"], ["84496.00", "4.699233"], ["84504.50", "4.428124"], ["84513.00", "5.151083"], ["84521.50", "3.885905"], ["84530.00", "5.602932"], ["84538.50", "5.422192"], ["84547.00", "4.337754"], ["84846.55", "0"], ["84846.85", "0"]], "bids": [["84293.14", "3.201011"], ["84292.09", "0"], ["84271.40", "0.254457"], ["84269.40", "0.669622"], ["84267.40", "1.762164"], ["84259.00", "0.009000"], ["84254.30", "0.030000"], ["84253.70", "0.975840"], ["84225.20", "4.337754"], ["84216.70", "5.241453"], ["84208.20", "5.602932"], ["84199.70", "5.060713"], ["84191.20", "5.422192"], ["84182.70", "5.512562"], ["84174.20", "5.331823"], ["84165.70", "4.247384"], ["84157.20", "4.428124"], ["84140.20", "4.699233"], ["84131.70", "3.976275"], ["84123.20", "4.066644"], ["84114.70", "5.151083"], ["84106.20", "4.157014"], ["84097.70", "4.608864"], ["84089.20", "4.518494"], ["84080.70", "4.879973"], ["84072.20", "4.970343"], ["84063.70", "4.789603"]], "checksum": 682349569, "ts": "1742142215502"}], "ts": 1742142215506, "record_time": 1742142214.614341}
{"action": "update", "arg": {"instType": "SPOT", "channel": "books", "instId": "BTCUSDT"}, "data": [{"asks": [["84295.05", "0"], ["84299.57", "0"], ["84301.58", "0"], ["84335.80", "0.001044"], ["84337.80", "0.001801"], ["84339.80", "0.004739"], ["84341.80", "0.012472"], ["84343.80", "0.032820"], ["84345.80", "0.086370"], ["84347.80", "0.227289"], ["84349.80", "0.598130"], ["84351.80", "1.574025"], ["84353.50", "0"], ["84358.90", "0.269760"], ["84363.40", "0.619890"], ["84364.20", "0"], ["84394.00", "4.066644"], ["84402.50", "5.602932"], ["84411.00", "5.422192"], ["84419.50", "5.331823"], ["84428.00", "5.151083"], ["84436.50", "5.241453"], ["84445.00", "4.789603"], ["84453.50", "3.885905"], ["84462.00", "4.879973"], ["84470.50", "4.608864"], ["84479.00", "4.518494"], ["84487.50", "4.428124"], ["84496.00", "4.247384"], ["84504.50", "5.512562"], ["84513.00", "4.699233"], ["84521.50", "3.976275"], ["84530.00", "4.337754"], ["84538.50", "4.157014"], ["84547.00", "4.970343"], ["84555.50", "5.060713"], ["84846.55", "0.000019"], ["84846.85", "0.000176"], ["84847.58", "0.000039"], ["84847.82", "0.000671"]], "bids": [["84284.93", "0"], ["84281.40", "0.002125"], ["84279.40", "0.005592"], ["84277.40", "0.014714"], ["84275.40", "0.038722"], ["84273.40", "0.101901"], ["84271.40", "0.268160"], ["84269.40", "0.705683"], ["84267.40", "1.857061"], ["84266.70", "1.291230"], ["84266.10", "0"], ["84265.70", "0.035580"], ["84263.80", "0.069600"], ["84260.70", "1.441590"], ["84259.40", "2.348880"], ["84259.00", "1.359000"], ["84258.60", "0.669300"], ["84257.30", "0"], ["84254.80", "0"], ["84238.01", "0.067807"], ["84225.20", "3.885905"], ["84216.70", "4.247384"], ["84208.20", "4.337754"], ["84199.70", "5.512562"], ["84191.20", "4.428124"], ["84182.70", "4.699233"], ["84165.70", "4.066644"], ["84157.20", "4.518494"], ["84148.70", "5.060713"], ["84140.20", "4.157014"], ["84131.70", "5.602932"], ["84123.20", "4.789603"], ["84114.70", "5.422192"], ["84106.20", "4.879973"], ["84097.70", "4.970343"], ["84089.20", "5.151083"], ["84080.70", "3.976275"], ["84072.20", "5.241453"], ["84063.70", "4.608864"]], "checksum": -646267702, "ts": "1742142215704"}], "ts": 1742142215708, "record_time": 1742142214.815777}
{"action": "update", "arg": {"instType": "SPOT", "channel": "books", "instId": "BTCUSDT"}, "data": [{"asks": [["84294.98", "0.063807"], ["84303.69", "0"], ["84304.57", "0"], ["84304.70", "0"], ["84337.80", "0.001993"], ["84339.80", "0.005354"], ["84341.80", "0.014089"], ["84343.80", "0.037075"], ["84345.80", "0.097567"], ["84347.80", "0.256756"], ["84349.80", "0.675672"], ["84351.79", "1.137490"], ["84351.80", "1.778086"], ["84358.90", "0"], ["84364.30", "7.377090"], ["84402.50", "5.241453"], ["84411.00", "4.518494"], ["84419.50", "4.428124"], ["84428.00", "4.337754"], ["84436.50", "4.970343"], ["84445.00", "4.699233"], ["84453.50", "5.602932"], ["84470.50", "5.512562"], ["84479.00", "4.789603"], ["84487.50", "5.151083"], ["84496.00", "4.608864"], ["84504.50", "5.060713"], ["84513.00", "3.885905"], ["84521.50", "5.331823"], ["84530.00", "3.976275"], ["84547.00", "5.422192"], ["84555.50", "4.247384"], ["84849.88", "0.000030"], ["84850.00", "0.000031"]], "bids": [["84287.88", "0.000070"], ["84281.40", "0.001987"], ["84279.40", "0.005228"], ["84277.40", "0.013564"], ["84275.40", "0.035697"], ["84273.40", "0.093937"], ["84271.40", "0.247205"], ["84269.40", "0.650539"], ["84267.40", "1.711944"], ["84263.80", "0"], ["84254.70", "0.030000"], ["84254.30", "0"], ["84252.30", "0.178680"], ["84225.20", "5.602932"], ["84216.70", "4.518494"], ["84213.99", "0.062760"], ["84208.20", "5.422192"], ["84199.70", "4.699233"], ["84191.20", "4.970343"], ["84182.70", "4.066644"], ["84174.20", "4.428124"], ["84166.00", "0"], ["84165.70", "4.157014"], ["84157.20", "5.331823"], ["84148.70", "4.608864"], ["84140.20", "4.247384"], ["84131.70", "4.789603"], ["84123.20", "5.060713"], ["84114.70", "3.885905"], ["84106.20", "3.976275"], ["84097.70", "4.337754"], ["84089.20", "5.241453"], ["84080.70", "5.151083"], ["84072.20", "5.512562"], ["84063.70", "4.879973"], ["83893.64", "0"]], "checksum": 1912876195, "ts": "1742142215910"}], "ts": 1742142215918, "record_time": 1742142215.025496}
{"action": "update", "arg": {"instType": "SPOT", "channel": "books", "instId": "BTCUSDT"}, "data": [{"asks": [["84293.15", "1.276786"], ["84299.83", "0"], ["84300.64", "0"], ["84300.67", "0"], ["84300.70", "0"], ["84301.51", "0"], ["84301.56", "0"], ["84301.58", "0.209200"], ["84302.04", "0"], ["84302.14", "0"], ["84302.19", "0"], ["84302.21", "0"], ["84302.22", "0"], ["84302.23", "0"], ["84302.24", "0"], ["84303.08", "0"], ["84303.10", "0.050434"], ["84303.11", "0"], ["84303.13", "0"], ["84303.14", "0"], ["84303.16", "0"], ["84303.46", "0"], ["84304.94", "0.031812"], ["84308.80", "0"], ["84309.35", "0.002907"], ["84309.66", "0.003017"], ["84310.58", "0.001827"], ["84312.61", "0.016427"], ["84314.15", "0"], ["84314.68", "0"], ["84315.02", "0.012680"], ["84315.06", "0"], ["84315.07", "0"], ["84315.09", "0"], ["84315.60", "0"], ["84315.96", "0"], ["84316.20", "0"], ["84317.46", "0"], ["84318.58", "0"], ["84318.75", "0"], ["84318.84", "0"], ["84319.02", "0"], ["84319.28", "0"], ["84319.51", "0"], ["84319.88", "0"], ["84319.94", "0.021461"], ["84320.15", "0"], ["84320.39", "0"], ["84320.41", "0"], ["84320.48", "0"], ["84321.12", "0"], ["84322.15", "0"], ["84322.19", "0"], ["84322.26", "0"], ["84322.65", "0"], ["84323.10", "0"], ["84323.73", "0"], ["84324.34", "0"], ["84324.53", "0"], ["84325.25", "0"], ["84325.65", "0"], ["84325.96", "0"], ["84326.60", "0"], ["84326.62", "0"], ["84327.18", "0"], ["84335.80", "0.002022"], ["84337.80", "0.005321"], ["84339.80", "0.014005"], ["84341.80", "0.036853"], ["84343.80", "0.096984"], ["84345.80", "0.255220"], ["84347.80", "0.671632"], ["84349.80", "1.767453"], ["84351.80", "4.651190"], ["84352.10", "0.381390"], ["84352.20", "0.069600"], ["84352.40", "0.269760"], ["84352.80", "0"], ["84353.00", "4.165020"], ["84353.50", "0.007170"], ["84356.20", "0.069600"], ["84357.70", "0.269760"], ["84357.80", "0"], ["84363.00", "0.705450"], ["84363.40", "0.441870"], ["84364.30", "3.433830"], ["84394.00", "4.428124"], ["84402.50", "5.331823"], ["84411.00", "5.512562"], ["84419.50", "3.885905"], ["84428.00", "5.602932"], ["84436.50", "4.247384"], ["84445.00", "5.060713"], ["84451.13", "0"], ["84453.50", "4.789603"], ["84462.00", "4.608864"], ["84470.50", "4.699233"], ["84479.00", "4.066644"], ["84487.50", "4.970343"], ["84496.00", "4.337754"], ["84504.50", "4.879973"], ["84513.00", "5.241453"], ["84521.50", "3.976275"], ["84530.00", "4.157014"], ["84538.50", "5.151083"], ["84547.00", "4.518494"], ["84555.50", "5.422192"], ["84851.66", "0.000029"], ["84852.81", "0.000115"], ["84852.94", "0.000065"], ["84853.56", "0.000050"], ["84857.14", "0.000347"], ["84858.75", "0.000285"], ["84859.29", "0.000036"], ["84860.00", "0.000169"], ["84862.90", "0.000169"], ["84864.69", "0.000052"], ["84864.86", "0.000041"], ["84864.99", "0.000033"], ["84866.10", "0.000064"], ["84866.40", "0.000018"], ["84867.80", "0.000095"], ["84868.42", "0.000031"], ["84868.52", "0.000013"], ["84868.65", "0.000035"], ["84869.57", "0.000932"], ["84871.66", "0.000078"], ["84871.79", "0.000014"], ["84873.84", "0.000057"], ["84874.79", "0.000096"], ["84875.00", "0.000959"], ["84875.78", "0.000038"], ["84876.03", "0.000161"], ["84879.10", "0.000009"], ["84879.37", "0.000009"], ["84879.59", "0.000173"], ["84880.00", "0.025078"], ["84880.89", "0.000065"], ["84882.35", "0.000417"], ["84883.65", "0.000008"], ["84883.72", "0.000010"], ["84883.84", "0.000040"], ["84885.24", "0.000112"], ["84885.53", "0.000022"], ["84886.01", "0.000023"], ["84886.02", "0.000054"], ["84886.96", "0.000013"], ["84887.65", "0.000019"], ["84888.00", "0.000010"], ["84888.68", "0.000013"], ["84888.89", "0.000113"], ["84889.87", "0.000010"], ["84890.00", "0.000118"]], "bids": [["84293.14", "2.097710"], ["84291.55", "0"], ["84287.88", "0"], ["84285.94", "0"], ["84285.70", "0"], ["84281.40", "0.001295"], ["84279.40", "0.003407"], ["84277.40", "0.008966"], ["84277.15", "0"], ["84277.08", "0"], ["84277.03", "0"], ["84277.02", "0"], ["84277.01", "0"], ["84277.00", "0"], ["84275.57", "0"], ["84275.53", "0"], ["84275.40", "0.023594"], ["84274.89", "0"], ["84274.34", "0"], ["84274.16", "0"], ["84273.99", "0"], ["84273.62", "0"], ["84273.40", "0.062089"], ["84273.33", "0"], ["84273.10", "0"], ["84272.81", "0"], ["84272.43", "0"], ["84272.22", "0"], ["84272.10", "0"], ["84272.02", "0"], ["84271.40", "0.163393"], ["84271.16", "0"], ["84270.65", "0"], ["84270.43", "0"], ["84270.39", "0"], ["84270.38", "0"], ["84270.34", "0"], ["84270.28", "0"], ["84270.00", "0"], ["84269.94", "0"], ["84269.88", "0"], ["84269.80", "0"], ["84269.40", "0.429982"], ["84269.37", "0"], ["84268.93", "0"], ["84268.48", "0"], ["84268.39", "0"], ["84268.31", "0"], ["84267.86", "0"], ["84267.48", "0"], ["84267.40", "1.131531"], ["84266.91", "0"], ["84266.80", "0.001047"], ["84266.79", "0"], ["84266.70", "0.524430"], ["84266.25", "0"], ["84265.90", "0"], ["84265.82", "0"], ["84265.70", "0.013620"], ["84265.36", "0"], ["84265.12", "0"], ["84264.99", "0"], ["84264.75", "0"], ["84264.60", "0"], ["84264.20", "0"], ["84264.19", "0"], ["84262.00", "0"], ["84261.80", "0"], ["84261.19", "0.025081"], ["84260.70", "1.456200"], ["84259.40", "0"], ["84259.37", "0"], ["84259.00", "0.009000"], ["84258.40", "1.326570"], ["84257.80", "0.142500"], ["84257.07", "0"], ["84255.80", "0"], ["84255.41", "0"], ["84254.84", "0"], ["84254.70", "0"], ["84254.50", "0.092640"], ["84254.40", "0.012000"], ["84253.70", "0.701700"], ["84248.85", "0"], ["84246.83", "0"], ["84244.38", "0"], ["84225.20", "4.518494"], ["84216.70", "4.789603"], ["84208.20", "5.060713"], ["84199.70", "5.602932"], ["84191.20", "5.241453"], ["84182.71", "0.422724"], ["84182.70", "4.428124"], ["84174.20", "4.066644"], ["84169.62", "0.125282"], ["84167.00", "0"], ["84165.70", "4.699233"], ["84157.20", "4.157014"], ["84144.32", "0"], ["84140.20", "3.885905"], ["84131.70", "4.247384"], ["84123.20", "5.331823"], ["84114.70", "4.337754"], ["84106.20", "4.970343"], ["84097.70", "5.512562"], ["84089.20", "4.879973"], ["84080.70", "5.422192"], ["84072.20", "3.976275"], ["84063.70", "5.151083"], ["83893.64", "0.000039"], ["83893.62", "0.000137"], ["83892.29", "0.000143"], ["83891.43", "0.000455"], ["83891.30", "0.000010"], ["83888.89", "0.000163"], ["83888.86", "0.000371"], ["83887.29", "0.000586"], ["83887.11", "0.000075"], ["83886.91", "0.000145"], ["83885.98", "0.000018"], ["83885.71", "0.000069"], ["83884.62", "0.000014"], ["83884.55", "0.000048"], ["83884.30", "0.000161"], ["83882.98", "0.000188"], ["83882.92", "0.002384"], ["83881.99", "0.000038"], ["83880.00", "0.020454"], ["83877.97", "0.000023"], ["83877.55", "0.000010"], ["83877.42", "0.000054"], ["83877.29", "0.000024"], ["83877.05", "0.000008"], ["83876.25", "0.000028"], ["83876.12", "0.000681"], ["83875.99", "0.000299"], ["83875.49", "0.000723"], ["83875.16", "0.000179"], ["83875.00", "0.000145"], ["83874.55", "0.000145"], ["83874.15", "0.000150"], ["83873.87", "0.000041"], ["83873.52", "0.000135"], ["83870.97", "0.000194"], ["83870.95", "0.000078"], ["83870.78", "0.000019"], ["83870.00", "0.000121"], ["83869.57", "0.000035"], ["83868.82", "0.000017"], ["83866.67", "0.000138"], ["83865.80", "0.000098"], ["83865.10", "0.000134"], ["83864.54", "0.000009"], ["83863.64", "0.000012"], ["83863.52", "0.000510"], ["83860.29", "0.000041"], ["83860.10", "0.000023"], ["83860.00", "0.000024"], ["83859.94", "0.000058"], ["83859.35", "0.000051"], ["83859.25", "0.000115"], ["83858.82", "0.000105"], ["83857.50", "0.000025"], ["83857.14", "0.000431"], ["83857.13", "0.000019"], ["83856.00", "0.000010"], ["83855.78", "0.000009"], ["83855.44", "0.000008"], ["83855.42", "0.000564"], ["83854.95", "0.000462"], ["83854.17", "0.000039"], ["83854.00", "0.500470"]], "checksum": -1299936645, "ts": "1742142216118"}], "ts": 1742142216126, "record_time": 1742142215.234142}
