{"action": "snapshot", "arg": {"instType": "SPOT", "channel": "books", "instId": "BTCUSDT"}, "data": [{"asks": [["84073.01", "1.705762"], ["84073.02", "0.000100"], ["84073.03", "0.000100"], ["84073.04", "0.000100"], ["84075.61", "0.000222"], ["84075.62", "0.196307"], ["84075.63", "0.654357"], ["84078.64", "0.009407"], ["84078.71", "0.005575"], ["84078.72", "0.006307"], ["84078.74", "0.006601"], ["84078.79", "0.007162"], ["84078.82", "0.000865"], ["84081.41", "0.088794"], ["84081.42", "0.209200"], ["84082.94", "0.112930"], ["84087.64", "0.035961"], ["84087.65", "0.119870"], ["84088.26", "0.035952"], ["84088.66", "0.026893"], ["84089.27", "0.035961"], ["84089.32", "0.006356"], ["84089.52", "0.006356"], ["84089.85", "0.006356"], ["84091.20", "0.006356"], ["84091.37", "0.006356"], ["84092.02", "0.010984"], ["84092.21", "0.006356"], ["84092.36", "0.006356"], ["84092.51", "0.006356"], ["84092.84", "0.006356"], ["84092.89", "0.006356"], ["84093.32", "0.016429"], ["84094.16", "0.140284"], ["84094.17", "0.119883"], ["84094.37", "0.006357"], ["84094.50", "0.016429"], ["84095.74", "0.313959"], ["84096.19", "0.010985"], ["84097.01", "0.009990"], ["84097.93", "0.554320"], ["84097.95", "0.119850"], ["84098.41", "0.209200"], ["84098.81", "0.119858"], ["84099.14", "0.119867"], ["84099.21", "0.009989"], ["84099.26", "1.531031"], ["84099.31", "0.015895"], ["84102.63", "0.010988"], ["84102.82", "0.222300"], ["84102.99", "0.015892"], ["84105.37", "0.017446"], ["84113.40", "0.064018"], ["84113.41", "0.209200"], ["84115.01", "0.012472"], ["84116.17", "0.184426"], ["84120.00", "0.002000"], ["84125.31", "0.001598"], ["84126.21", "0.706776"], ["84126.22", "0.209200"], ["84126.70", "0.001631"], ["84126.85", "3.569077"], ["84127.22", "0.001597"], ["84128.70", "0.002688"], ["84130.70", "0.007142"], ["84132.20", "0.000958"], ["84132.70", "0.018793"], ["84134.05", "0.713147"], ["84134.70", "0.049456"], ["84136.70", "0.129923"], ["84137.08", "0.063339"], ["84137.09", "0.209200"], ["84138.70", "0.341949"], ["84140.70", "0.899864"], ["84141.80", "0.207473"], ["84142.70", "2.368065"], ["84144.70", "6.231750"], ["84146.70", "16.399341"], ["84147.30", "0.001740"], ["84147.80", "0.003480"], ["84148.10", "0.067980"], ["84148.90", "0.071880"], ["84149.00", "0.001047"], ["84149.60", "0.001200"], ["84150.00", "0.002064"], ["84150.10", "1.123680"], ["84150.30", "0.072060"], ["84150.80", "0.297720"], ["84151.40", "1.350000"], ["84152.00", "0.006060"], ["84152.20", "0.356820"], ["84153.00", "0.356820"], ["84153.40", "0.071310"], ["84153.90", "0.356820"], ["84154.10", "1.146840"], ["84154.40", "1.069320"], ["84154.70", "0.891480"], ["84155.20", "0.009000"], ["84155.50", "0.423000"], ["84155.60", "0.120000"], ["84156.10", "1.101900"], ["84156.50", "0.131280"], ["84157.30", "0.300000"], ["84157.40", "0.156000"], ["84158.02", "0.404946"], ["84158.10", "1.462680"], ["84159.00", "0.024930"], ["84159.29", "1.782334"], ["84159.70", "0.249990"], ["84159.90", "0.228000"], ["84161.58", "0.209200"], ["84174.51", "0.000388"], ["84178.41", "0.209200"], ["84180.00", "0.002000"], ["84186.81", "0.209200"], ["84188.00", "0.000202"], ["84188.80", "4.348327"], ["84190.00", "0.001000"], ["84195.21", "0.209200"], ["84197.30", "4.438917"], ["84200.77", "0.001810"], ["84203.61", "0.209200"], ["84205.80", "4.076556"], ["84209.19", "0.003620"], ["84209.47", "0.071253"], ["84210.00", "0.002000"], ["84211.43", "0.125580"], ["84212.01", "0.209200"], ["84213.46", "0.000163"], ["84214.30", "5.525998"], ["84217.51", "0.071045"], ["84220.41", "0.209200"], ["84220.57", "0.057001"], ["84222.80", "4.710687"], ["84224.20", "0.010000"], ["84224.32", "0.010000"], ["84225.80", "0.301470"], ["84228.81", "0.209200"], ["84231.30", "5.073048"], ["84232.06", "0.011010"], ["84233.38", "0.001273"], ["84234.12", "0.000044"], ["84237.21", "0.209200"], ["84239.80", "4.982457"], ["84240.00", "0.002000"], ["84245.00", "0.000149"], ["84248.30", "5.435408"], ["84250.00", "0.000684"], ["84252.44", "0.000143"], ["84253.92", "0.209200"], ["84256.80", "5.344818"], ["84258.20", "0.296868"], ["84259.99", "0.000017"], ["84264.00", "0.001184"], ["84265.30", "4.620097"], ["84266.08", "0.000016"], ["84266.67", "0.000078"], ["84269.24", "0.000032"], ["84270.00", "0.002692"], ["84270.70", "0.209200"], ["84270.98", "0.000052"], ["84272.72", "0.000105"], ["84273.80", "5.163638"], ["84275.00", "0.000671"], ["84279.10", "0.209200"], ["84280.00", "0.000077"], ["84282.30", "3.895376"], ["84285.00", "0.000031"], ["84285.71", "0.000010"], ["84285.95", "0.000028"], ["84286.79", "0.000016"], ["84286.96", "0.024945"], ["84287.50", "0.209276"], ["84288.16", "0.168022"], ["84288.30", "0.001469"], ["84288.89", "0.000361"], ["84290.80", "4.801277"], ["84294.68", "0.000019"], ["84295.90", "0.209200"], ["84297.06", "0.000035"], ["84299.30", "4.167146"], ["84300.00", "0.023631"], ["84304.31", "0.209200"], ["84307.00", "0.000113"], ["84307.23", "0.000008"], ["84307.80", "4.891867"], ["84309.09", "0.000010"], ["84310.34", "0.000331"], ["84310.35", "0.000146"], ["84311.11", "0.000025"], ["84312.50", "0.000125"], ["84312.72", "0.209200"], ["84313.03", "0.000024"], ["84314.97", "0.000008"], ["84316.30", "4.529507"], ["84316.67", "0.000322"], ["84317.24", "0.000135"], ["84317.40", "0.000010"], ["84317.97", "0.001720"], ["84318.59", "0.000027"], ["84319.15", "0.000137"], ["84319.18", "0.000039"], ["84320.00", "0.000019"], ["84321.13", "0.209200"], ["84322.11", "0.000008"], ["84324.32", "0.000059"], ["84324.80", "5.616588"], ["84325.00", "0.002294"], ["84325.07", "0.000161"], ["84326.09", "0.000010"], ["84326.42", "0.000023"], ["84327.14", "0.000039"], ["84327.73", "0.041940"], ["84328.95", "0.000174"], ["84329.54", "0.209200"], ["84329.64", "0.000026"], ["84330.00", "0.002000"], ["84332.00", "0.000008"], ["84333.30", "5.254228"], ["84333.33", "0.002262"], ["84333.36", "0.000010"], ["84333.38", "0.000008"], ["84334.48", "0.000096"], ["84334.77", "0.000022"], ["84335.90", "0.300375"], ["84336.00", "0.000133"], ["84336.23", "0.000013"], ["84336.29", "0.000010"], ["84336.34", "0.000176"], ["84337.25", "0.000067"], ["84337.35", "0.000008"], ["84337.95", "0.209200"], ["84338.46", "0.000015"], ["84339.21", "0.000010"], ["84339.29", "0.000029"], ["84339.62", "0.000051"], ["84340.00", "0.018287"], ["84340.72", "0.000066"], ["84341.01", "0.000008"], ["84341.80", "4.257736"], ["84342.11", "0.000051"], ["84342.63", "0.000009"], ["84342.70", "0.000423"], ["84343.07", "0.000014"], ["84343.70", "0.000075"], ["84343.75", "0.000012"], ["84343.97", "0.000188"], ["84346.36", "0.209200"], ["84346.43", "0.000128"], ["84346.94", "0.000085"], ["84347.69", "0.000009"], ["84347.83", "0.016818"], ["84348.21", "0.000036"], ["84348.27", "0.012402"], ["84348.62", "0.000072"], ["84350.00", "0.002253"], ["84350.30", "3.985966"], ["84350.79", "0.000033"], ["84354.58", "0.000115"], ["84354.64", "0.000018"], ["84354.77", "0.209200"], ["84354.82", "0.000078"], ["84354.84", "0.000194"], ["84356.98", "0.000048"], ["84357.14", "0.000273"], ["84358.10", "0.001403"], ["84358.29", "0.000024"], ["84359.83", "0.000010"], ["84360.00", "0.002661"], ["84363.18", "0.209200"], ["84363.63", "0.000057"], ["84363.64", "0.000078"], ["84366.14", "0.000162"], ["84366.15", "0.000061"], ["84366.19", "0.000022"], ["84366.60", "0.000011"], ["84366.96", "0.000018"], ["84367.10", "0.000014"], ["84367.82", "0.000476"], ["84368.38", "0.000009"], ["84368.42", "0.000284"], ["84370.00", "0.000052"], ["84370.59", "0.000071"], ["84370.97", "0.000020"], ["84371.86", "0.000012"], ["84375.00", "0.004006"], ["84376.31", "0.000016"], ["84378.11", "0.000008"], ["84378.38", "0.000009"], ["84378.45", "0.000015"], ["84380.00", "0.032216"], ["84381.82", "0.000008"], ["84382.00", "0.000035"], ["84382.35", "0.000071"], ["84383.41", "0.000053"], ["84383.69", "0.000248"], ["84384.38", "0.000424"], ["84384.61", "0.000008"], ["84386.19", "0.000019"], ["84386.67", "0.000013"], ["84387.50", "0.006969"], ["84387.76", "0.000024"], ["84389.61", "0.000088"], ["84389.90", "0.000012"], ["84390.00", "0.002000"], ["84390.01", "0.000387"], ["84391.30", "0.000018"], ["84393.31", "0.000050"], ["84396.55", "0.000016"], ["84396.98", "0.007500"], ["84397.59", "0.000008"], ["84397.69", "0.000275"], ["84398.26", "0.000068"], ["84399.54", "0.000030"], ["84399.91", "0.000018"], ["84399.99", "0.000022"], ["84400.00", "0.060615"], ["84400.18", "0.000024"], ["84402.40", "0.001273"], ["84403.39", "0.000023"], ["84403.76", "0.000099"], ["84403.98", "0.007500"], ["84404.26", "0.000137"], ["84404.28", "0.000039"], ["84405.00", "0.000402"], ["84406.06", "0.000008"], ["84406.83", "0.000064"], ["84407.50", "0.000031"], ["84410.00", "0.000059"], ["84410.04", "0.000025"], ["84411.11", "0.000361"], ["84411.43", "0.000008"], ["84411.76", "0.000101"], ["84411.77", "0.000020"], ["84412.50", "0.000049"], ["84413.04", "0.000010"], ["84413.33", "0.000073"], ["84413.79", "0.000135"], ["84414.29", "0.000074"], ["84414.41", "0.000051"], ["84415.09", "0.000008"], ["84416.67", "0.000355"], ["84418.34", "0.000046"], ["84419.69", "0.000023"], ["84420.00", "0.002640"], ["84420.17", "0.041940"], ["84422.71", "0.000010"], ["84423.08", "0.000067"], ["84423.53", "0.000105"], ["84424.00", "0.000022"], ["84424.12", "0.000146"], ["84425.00", "0.002205"], ["84425.69", "0.000314"], ["84426.68", "0.000101"], ["84427.08", "0.000014"], ["84427.92", "0.000323"], ["84428.57", "0.000057"], ["84429.82", "0.000022"], ["84430.50", "0.000113"], ["84430.74", "0.000010"], ["84430.77", "0.000015"], ["84431.23", "0.000039"], ["84432.43", "0.000008"], ["84433.33", "0.000347"], ["84434.78", "0.000008"], ["84435.26", "0.000161"], ["84436.26", "0.000009"], ["84437.14", "0.000017"], ["84437.50", "0.000725"], ["84437.75", "0.000013"], ["84438.44", "0.000176"], ["84440.00", "0.000544"], ["84441.04", "1.590219"], ["84442.54", "0.000096"], ["84443.07", "0.000423"], ["84444.25", "0.000013"], ["84444.41", "0.000371"], ["84444.44", "0.000574"], ["84444.92", "0.000022"], ["84446.04", "0.000016"], ["84446.38", "0.000013"], ["84446.43", "0.000036"], ["84447.80", "0.000718"], ["84448.75", "0.000066"], ["84448.98", "0.000085"], ["84449.11", "0.000028"], ["84449.34", "0.000010"], ["84450.00", "0.010457"], ["84451.88", "0.000010"], ["84452.66", "0.000009"], ["84453.76", "0.000054"], ["84454.43", "0.000061"], ["84454.53", "0.000019"], ["84454.55", "0.000083"], ["84454.60", "0.000093"], ["84455.31", "0.000028"], ["84456.14", "0.000033"], ["84456.52", "0.002633"], ["84457.00", "0.000009"], ["84457.40", "0.002343"], ["84458.06", "0.000020"], ["84458.72", "0.000072"], ["84458.82", "0.000071"], ["84458.97", "0.000153"], ["84459.08", "0.000008"], ["84459.22", "0.000188"], ["84459.69", "0.000051"], ["84460.00", "0.000622"], ["84460.23", "0.000010"], ["84460.49", "0.000009"], ["84460.87", "0.000069"], ["84460.91", "0.000012"], ["84461.00", "0.000008"], ["84462.50", "0.000076"], ["84464.28", "0.000008"], ["84465.83", "0.000016"], ["84466.67", "0.000157"], ["84470.34", "0.000017"], ["84470.59", "0.000071"], ["84471.30", "0.510950"], ["84473.14", "0.000126"], ["84473.68", "0.000192"], ["84474.78", "0.000099"], ["84475.00", "0.009271"], ["84475.81", "0.000039"], ["84476.97", "0.000063"], ["84477.61", "0.000095"], ["84477.67", "0.000008"], ["84478.74", "0.000036"], ["84479.37", "0.000090"], ["84480.00", "0.003246"], ["84481.00", "0.000069"], ["84481.77", "0.000011"], ["84482.67", "0.000133"], ["84482.76", "0.000016"], ["84485.20", "0.000537"], ["84485.39", "0.000020"], ["84485.71", "0.000128"], ["84485.98", "0.000034"], ["84486.49", "0.000009"], ["84486.82", "0.000135"], ["84487.00", "0.000119"], ["84487.16", "0.000035"], ["84487.32", "0.000024"], ["84487.95", "0.000008"], ["84488.88", "0.000025"], ["84489.36", "0.000137"], ["84489.39", "0.000039"], ["84489.80", "0.000010"], ["84490.00", "0.007510"], ["84490.13", "0.000093"], ["84490.91", "0.000018"], ["84491.26", "0.000008"], ["84491.87", "0.000019"], ["84492.06", "0.000009"], ["84496.43", "0.000273"], ["84496.66", "0.004837"], ["84496.73", "0.000043"], ["84497.14", "0.000008"], ["84497.26", "0.000010"], ["84500.00", "0.124015"], ["84500.03", "0.000010"], ["84500.04", "0.000008"], ["84500.11", "0.000012"], ["84501.24", "0.000010"], ["84501.28", "0.000019"], ["84501.32", "0.000326"], ["84501.99", "0.000009"], ["84503.33", "0.010000"], ["84503.57", "0.000074"], ["84504.50", "0.000051"], ["84504.74", "0.000013"], ["84506.54", "0.000008"], ["84508.00", "0.001210"], ["84508.37", "0.000050"], ["84508.46", "0.000013"], ["84508.47", "0.000023"], ["84510.00", "0.000402"], ["84510.34", "0.000135"], ["84512.00", "0.000012"], ["84512.19", "0.000016"], ["84512.61", "0.041940"], ["84512.95", "0.000023"], ["84514.29", "0.000059"], ["84516.67", "0.000010"], ["84517.54", "0.000022"], ["84517.86", "0.000016"], ["84518.98", "0.000029"], ["84520.00", "0.000318"], ["84520.50", "0.000238"], ["84520.67", "0.002384"], ["84521.85", "0.000033"], ["84522.06", "0.000041"], ["84523.08", "0.000015"], ["84523.48", "0.000015"], ["84523.81", "0.000024"], ["84524.00", "0.000035"], ["84524.83", "0.000009"], ["84525.00", "0.003286"], ["84525.82", "0.000099"]], "bids": [["84073.00", "0.950618"], ["84072.99", "0.000100"], ["84072.98", "0.000100"], ["84072.97", "0.000100"], ["84072.50", "0.018043"], ["84072.00", "0.000032"], ["84071.00", "0.000032"], ["84070.51", "0.075610"], ["84070.50", "0.047480"], ["84070.00", "0.000032"], ["84069.19", "0.007750"], ["84069.00", "0.000032"], ["84068.50", "0.124947"], ["84068.35", "0.010000"], ["84068.32", "0.005920"], ["84068.27", "0.008501"], ["84068.00", "0.000032"], ["84067.53", "0.041077"], ["84067.07", "0.019301"], ["84067.03", "0.007467"], ["84067.02", "0.008237"], ["84067.00", "0.000032"], ["84066.96", "0.007795"], ["84066.51", "0.371582"], ["84066.50", "0.328808"], ["84066.00", "0.000032"], ["84065.00", "0.000032"], ["84064.50", "0.865031"], ["84064.45", "0.021425"], ["84064.00", "0.000032"], ["84063.00", "0.000032"], ["84062.94", "0.009863"], ["84062.93", "0.005169"], ["84062.92", "0.005581"], ["84062.90", "0.006107"], ["84062.88", "0.008535"], ["84062.84", "0.005117"], ["84062.81", "0.004827"], ["84062.51", "1.439574"], ["84062.50", "2.276398"], ["84062.20", "0.001016"], ["84062.00", "0.008744"], ["84061.93", "0.010334"], ["84061.90", "1.382700"], ["84061.86", "0.008896"], ["84061.70", "0.001018"], ["84061.57", "0.314001"], ["84061.50", "0.071280"], ["84061.00", "0.000032"], ["84060.50", "0.286500"], ["84060.00", "0.185751"], ["84059.90", "0.111450"], ["84059.00", "0.070770"], ["84058.80", "0.069690"], ["84058.37", "0.028180"], ["84058.20", "0.009180"], ["84058.00", "0.000032"], ["84057.90", "0.067980"], ["84057.78", "0.445604"], ["84057.77", "3.051796"], ["84057.70", "0.028440"], ["84057.20", "0.045540"], ["84057.00", "0.000032"], ["84056.70", "0.540600"], ["84056.60", "0.880560"], ["84056.50", "0.270000"], ["84056.30", "0.012630"], ["84056.00", "0.000032"], ["84055.90", "0.067800"], ["84055.70", "0.294300"], ["84055.60", "0.030000"], ["84055.40", "0.022650"], ["84055.10", "0.153580"], ["84055.00", "0.000032"], ["84054.70", "0.120000"], ["84054.00", "0.000032"], ["84053.96", "0.027453"], ["84053.91", "0.020944"], ["84053.90", "0.120000"], ["84053.70", "0.015000"], ["84053.20", "0.000700"], ["84053.10", "0.131100"], ["84053.00", "0.000032"], ["84052.90", "0.120000"], ["84052.50", "2.879130"], ["84052.20", "0.120930"], ["84052.00", "0.000032"], ["84051.59", "0.209200"], ["84051.06", "0.008268"], ["84051.00", "0.000032"], ["84050.00", "0.000032"], ["84049.27", "0.008059"], ["84049.00", "0.000032"], ["84048.87", "0.014231"], ["84048.00", "0.000032"], ["84047.91", "0.089474"], ["84047.00", "0.000032"], ["84046.45", "0.247559"], ["84046.00", "0.000032"], ["84045.81", "0.004017"], ["84045.55", "0.083930"], ["84045.00", "0.000956"], ["84044.77", "0.017815"], ["84044.62", "0.018253"], ["84044.29", "0.005945"], ["84044.27", "0.055649"], ["84044.00", "0.000032"], ["84043.72", "0.028861"], ["84043.22", "0.025182"], ["84043.00", "0.000032"], ["84042.94", "0.017101"], ["84042.89", "0.224857"], ["84042.78", "0.007131"], ["84042.61", "0.007339"], ["84042.00", "0.000032"], ["84041.90", "0.007942"], ["84041.75", "0.008993"], ["84041.54", "0.051957"], ["84041.27", "0.017349"], ["84041.23", "0.008184"], ["84041.20", "0.000396"], ["84041.00", "0.000032"], ["84040.93", "0.009210"], ["84040.87", "0.006905"], ["84040.73", "0.007304"], ["84040.68", "0.018515"], ["84040.00", "0.001261"], ["84039.99", "0.209200"], ["84039.78", "0.285792"], ["84039.73", "0.012654"], ["84039.38", "0.713951"], ["84039.31", "0.008319"], ["84039.20", "0.008012"], ["84039.15", "0.008426"], ["84039.12", "0.008596"], ["84039.05", "0.006471"], ["84039.00", "0.000032"], ["84038.61", "0.482410"], ["84038.28", "0.076104"], ["84038.00", "0.000032"], ["84037.84", "0.021127"], ["84037.00", "0.000032"], ["84036.00", "0.000032"], ["84035.14", "0.010000"], ["84035.00", "0.000032"], ["84034.05", "0.073206"], ["84034.00", "0.000032"], ["84033.86", "0.010000"], ["84033.72", "0.008092"], ["84033.68", "0.008265"], ["84033.67", "0.005051"], ["84033.00", "0.000032"], ["84032.02", "0.056361"], ["84032.00", "0.000032"], ["84031.40", "0.209200"], ["84031.00", "0.000032"], ["84030.11", "0.000876"], ["84030.00", "0.002956"], ["84029.00", "0.000032"], ["84028.00", "0.000032"], ["84027.00", "0.000032"], ["84026.00", "0.000032"], ["84025.60", "0.200459"], ["84025.00", "0.000032"], ["84024.00", "0.000032"], ["84023.00", "0.000017"], ["84022.00", "0.000015"], ["84021.58", "0.209200"], ["84021.00", "0.000032"], ["84020.40", "5.254228"], ["84020.00", "0.001231"], ["84017.90", "0.007435"], ["84015.01", "0.001176"], ["84015.00", "0.009496"], ["84013.17", "0.209200"], ["84013.15", "0.003596"], ["84013.06", "0.001173"], ["84011.90", "4.710687"], ["84011.80", "0.000948"], ["84010.79", "0.000957"], ["84010.59", "0.007651"], ["84010.52", "0.007337"], ["84010.46", "0.007247"], ["84007.26", "0.001810"], ["84007.22", "0.071045"], ["84004.76", "0.209200"], ["84004.26", "0.003975"], ["84003.40", "5.344818"], ["84000.00", "0.003107"], ["83999.88", "0.057001"], ["83998.86", "0.003620"], ["83995.80", "0.209200"], ["83994.90", "4.982457"], ["83988.41", "0.071253"], ["83986.40", "4.801277"], ["83985.00", "0.000924"], ["83980.00", "0.001231"], ["83978.64", "0.012367"], ["83977.90", "4.620097"], ["83975.60", "0.209200"], ["83970.00", "0.004067"], ["83969.40", "5.525998"], ["83968.50", "0.303578"], ["83968.10", "0.024945"], ["83964.20", "0.209200"], ["83960.90", "5.163638"], ["83960.00", "0.001231"], ["83959.22", "0.125581"], ["83955.00", "0.000924"], ["83952.40", "5.616588"], ["83951.10", "0.209200"], ["83950.44", "0.005950"], ["83946.24", "0.010010"], ["83943.90", "4.438917"], ["83940.00", "0.003231"], ["83938.51", "0.209200"], ["83935.40", "4.167146"], ["83932.20", "0.001459"], ["83929.10", "0.300943"], ["83926.90", "3.985966"], ["83925.07", "0.209200"], ["83922.80", "0.001475"], ["83920.00", "0.001231"], ["83918.40", "4.891867"], ["83915.77", "0.209200"], ["83910.00", "0.002924"], ["83909.90", "4.076556"], ["83907.35", "0.209200"], ["83901.40", "4.348327"], ["83901.30", "0.308119"], ["83900.21", "0.005950"], ["83898.93", "0.209200"], ["83896.00", "0.001184"], ["83895.00", "0.000924"], ["83892.90", "3.895376"], ["83890.51", "0.209200"], ["83884.40", "5.435408"], ["83882.09", "0.209200"], ["83880.00", "0.003231"], ["83877.01", "0.000023"], ["83875.90", "4.257736"], ["83875.16", "0.000179"], ["83875.00", "0.000704"], ["83874.93", "0.001720"], ["83873.68", "0.209200"], ["83873.52", "0.000135"], ["83868.70", "0.001444"], ["83868.39", "0.002014"], ["83867.40", "4.529507"], ["83866.67", "0.002945"], ["83865.27", "0.209200"], ["83865.00", "0.000924"], ["83862.50", "0.006969"], ["83860.29", "0.000041"], ["83860.00", "0.001234"], ["83859.54", "0.000008"], ["83858.90", "5.073048"], ["83857.14", "0.000079"], ["83857.13", "0.000019"], ["83856.11", "0.010000"], ["83854.55", "0.000009"], ["83854.17", "0.000020"], ["83852.94", "0.000071"], ["83852.50", "0.000043"], ["83851.85", "0.000011"], ["83851.84", "0.000219"], ["83850.00", "0.003028"], ["83848.39", "0.000020"], ["83846.15", "0.000111"], ["83844.83", "0.000008"], ["83842.11", "0.000033"], ["83841.18", "0.000071"], ["83840.00", "0.001282"], ["83839.72", "0.000033"], ["83839.18", "0.000016"], ["83837.84", "0.000009"], ["83837.59", "0.000012"], ["83836.36", "0.000008"], ["83835.56", "0.000009"], ["83835.00", "0.000926"], ["83831.11", "0.000011"], ["83830.59", "0.000010"], ["83830.00", "0.000063"], ["83828.57", "0.000016"], ["83826.67", "0.000073"], ["83825.00", "0.000672"], ["83822.12", "0.000067"], ["83820.00", "0.003247"], ["83818.18", "0.001526"], ["83818.17", "0.000029"], ["83816.67", "0.000010"], ["83816.28", "0.000009"], ["83816.00", "0.000008"], ["83815.79", "0.000022"], ["83815.75", "0.000009"], ["83815.37", "0.000022"], ["83813.00", "0.000113"], ["83810.74", "0.000019"], ["83810.41", "0.000264"], ["83808.53", "0.000039"], ["83808.51", "0.000137"], ["83807.88", "0.000051"], ["83807.53", "0.000010"], ["83805.00", "0.000926"], ["83804.35", "0.000010"], ["83803.57", "0.000016"], ["83802.81", "0.000022"], ["83800.91", "0.000012"], ["83800.00", "0.039884"], ["83799.34", "0.000093"], ["83796.61", "0.001213"], ["83795.00", "0.000031"], ["83794.17", "0.000096"], ["83793.10", "0.000016"], ["83791.03", "0.000996"], ["83791.02", "0.000632"], ["83790.15", "0.000024"], ["83790.00", "0.003033"], ["83789.60", "0.000363"], ["83789.29", "0.000074"], ["83787.88", "0.000010"], ["83785.71", "0.000081"], ["83784.62", "0.000015"], ["83784.36", "0.000069"], ["83784.02", "0.000022"], ["83783.78", "0.000059"], ["83783.12", "0.000008"], ["83780.48", "0.000016"], ["83780.00", "0.001547"], ["83779.93", "0.000028"], ["83778.35", "0.011010"], ["83777.78", "0.000679"], ["83777.60", "0.000013"], ["83777.18", "0.000013"], ["83775.00", "0.009183"], ["83774.10", "0.000161"], ["83773.31", "0.000154"], ["83773.11", "0.041940"], ["83772.88", "0.000023"], ["83769.28", "0.000972"], ["83768.46", "0.000008"], ["83768.19", "1.727780"], ["83768.00", "0.000012"], ["83766.84", "0.000023"], ["83765.06", "0.000008"], ["83764.71", "0.000071"], ["83763.64", "0.000010"], ["83762.50", "0.000076"], ["83761.90", "0.000024"], ["83761.29", "0.000020"], ["83760.00", "0.001718"], ["83758.93", "0.000036"], ["83758.00", "0.000353"], ["83757.40", "0.000537"], ["83756.08", "0.000099"], ["83755.56", "0.000134"], ["83754.70", "0.000013"], ["83754.39", "0.000033"], ["83752.94", "0.000071"], ["83752.37", "0.000119"], ["83752.09", "0.000314"], ["83752.00", "0.000034"], ["83750.67", "0.000146"], ["83750.00", "0.041680"], ["83749.66", "0.000016"], ["83749.50", "0.000069"], ["83749.33", "0.000133"], ["83748.54", "0.000012"], ["83746.09", "0.000010"], ["83745.16", "0.000389"], ["83745.00", "0.000926"], ["83743.29", "0.001451"], ["83743.20", "0.506997"], ["83740.51", "0.000423"], ["83740.00", "0.001311"], ["83739.60", "0.000048"], ["83739.28", "0.000051"], ["83739.13", "0.000008"], ["83737.93", "0.000135"], ["83737.37", "0.000012"], ["83737.00", "0.000009"], ["83736.94", "0.000104"], ["83736.84", "0.000183"], ["83736.70", "0.001536"], ["83736.33", "0.000025"], ["83735.70", "0.002419"], ["83734.69", "0.000085"], ["83733.33", "0.003222"], ["83732.10", "0.000009"], ["83731.48", "0.000124"], ["83730.00", "0.002926"], ["83729.73", "0.000009"], ["83729.39", "0.000008"], ["83729.32", "0.000035"], ["83728.57", "0.000017"], ["83728.37", "0.001273"], ["83728.07", "0.000022"], ["83727.71", "0.000009"], ["83727.27", "0.000082"], ["83726.20", "0.000016"], ["83725.00", "0.002501"], ["83723.72", "0.000176"], ["83723.64", "0.000009"], ["83723.61", "0.000883"], ["83723.43", "0.000039"], ["83723.40", "0.000205"], ["83721.56", "0.000015"], ["83720.00", "0.003671"], ["83719.46", "0.000053"], ["83718.75", "0.000012"], ["83717.93", "0.000065"], ["83717.46", "0.000009"], ["83717.45", "0.000040"], ["83717.39", "0.000010"], ["83715.48", "0.000010"], ["83715.00", "0.000926"], ["83714.29", "0.009987"], ["83714.28", "0.000836"], ["83713.80", "0.000024"], ["83713.71", "0.000323"], ["83713.40", "0.000161"], ["83711.93", "0.000018"], ["83710.00", "0.000023"], ["83709.88", "0.000107"], ["83707.07", "0.000067"], ["83706.90", "0.000016"], ["83706.67", "0.000013"], ["83705.85", "0.000019"], ["83705.32", "0.000065"], ["83705.18", "0.000009"], ["83703.75", "0.000364"], ["83703.70", "0.000499"], ["83703.00", "0.000024"], ["83702.93", "0.000050"], ["83702.60", "0.000039"], ["83702.50", "0.000033"], ["83702.48", "0.000057"], ["83701.92", "0.000067"], ["83701.28", "0.000248"], ["83700.00", "0.007170"], ["83699.88", "0.000008"], ["83697.23", "0.000095"], ["83695.65", "0.003535"], ["83695.63", "0.000011"], ["83693.69", "0.000051"], ["83692.52", "0.000066"], ["83692.38", "0.000007"], ["83692.31", "0.000031"], ["83691.74", "0.000653"], ["83690.84", "0.000162"], ["83690.48", "0.000248"], ["83689.78", "0.001684"], ["83689.50", "0.000113"], ["83688.89", "0.000009"], ["83688.07", "0.000072"], ["83687.50", "0.006969"], ["83687.00", "0.000008"], ["83686.11", "0.000096"], ["83685.00", "0.000926"], ["83684.21", "0.000102"], ["83683.67", "0.000184"], ["83681.82", "0.000175"], ["83680.67", "0.041940"], ["83680.00", "0.001718"], ["83679.44", "0.000361"], ["83678.41", "0.000010"], ["83678.08", "0.000145"], ["83677.37", "0.000008"], ["83676.47", "0.000080"], ["83675.68", "0.000008"], ["83675.62", "0.000011"], ["83675.36", "0.000013"], ["83675.20", "0.000018"], ["83675.00", "0.002674"], ["83674.70", "0.000008"], ["83674.19", "0.000020"], ["83674.00", "0.001195"], ["83673.87", "0.000022"], ["83673.58", "0.000023"], ["83672.96", "0.002168"], ["83672.50", "0.000031"], ["83672.25", "0.004023"], ["83672.00", "0.000035"], ["83671.36", "0.000099"], ["83670.59", "0.000105"], ["83670.05", "0.000033"], ["83670.00", "0.004426"], ["83669.66", "0.000010"], ["83669.58", "0.000251"], ["83669.09", "0.000135"], ["83667.80", "0.000023"], ["83667.23", "0.012503"], ["83666.67", "0.052199"], ["83666.66", "0.000513"], ["83666.65", "0.000122"], ["83666.00", "0.271427"], ["83664.71", "0.000071"], ["83664.19", "0.000073"], ["83663.98", "0.000008"], ["83663.95", "0.000022"]], "checksum": 0, "ts": "1742555025092"}], "ts": 1742555025258, "record_time": 1742555025.33227, "EXCHANGE": "BITGET"}
{"action": "update", "arg": {"instType": "SPOT", "channel": "books", "instId": "BTCUSDT"}, "data": [{"asks": [["84116.17", "0"], ["84126.21", "0.829113"], ["84188.80", "4.438917"], ["84197.30", "4.982457"], ["84205.80", "5.073048"], ["84214.30", "5.616588"], ["84222.80", "5.254228"], ["84231.30", "4.257736"], ["84239.80", "5.525998"], ["84248.30", "4.891867"], ["84256.80", "4.348327"], ["84265.30", "4.529507"], ["84273.80", "3.895376"], ["84282.30", "4.710687"], ["84290.80", "4.076556"], ["84299.30", "3.985966"], ["84307.80", "5.344818"], ["84316.30", "4.167146"], ["84324.80", "5.163638"], ["84333.30", "4.620097"], ["84341.80", "5.435408"], ["84350.30", "4.801277"], ["84527.47", "0.000608"]], "bids": [["84072.50", "0.017524"], ["84070.50", "0.046116"], ["84068.50", "0.121359"], ["84066.50", "0.319365"], ["84064.50", "0.840435"], ["84062.50", "2.211670"], ["84020.40", "4.620097"], ["84011.90", "5.073048"], ["84003.40", "5.616588"], ["83994.90", "5.525998"], ["83986.40", "4.710687"], ["83977.90", "5.435408"], ["83969.40", "4.891867"], ["83960.90", "5.344818"], ["83952.40", "4.801277"], ["83943.90", "4.529507"], ["83935.40", "3.895376"], ["83926.90", "5.254228"], ["83918.40", "3.985966"], ["83909.90", "4.348327"], ["83901.40", "4.167146"], ["83892.90", "4.982457"], ["83884.40", "4.438917"], ["83867.40", "5.163638"], ["83858.90", "4.076556"]], "checksum": -753282278, "ts": "1742555025294"}], "ts": 1742555025299, "record_time": 1742555025.33928, "EXCHANGE": "BITGET"}
{"action": "update", "arg": {"instType": "SPOT", "channel": "books", "instId": "BTCUSDT"}, "data": [{"asks": [["84119.62", "0.181306"], ["84159.90", "0"], ["84188.80", "3.895376"], ["84197.30", "4.348327"], ["84205.80", "3.985966"], ["84214.30", "5.073048"], ["84222.80", "4.620097"], ["84231.30", "5.163638"], ["84239.80", "5.616588"], ["84248.30", "4.257736"], ["84256.80", "4.167146"], ["84265.30", "5.344818"], ["84273.80", "4.076556"], ["84282.30", "4.891867"], ["84290.80", "4.801277"], ["84299.30", "4.710687"], ["84307.80", "4.529507"], ["84316.30", "5.435408"], ["84324.80", "4.438917"], ["84333.30", "5.525998"], ["84341.80", "4.982457"], ["84350.30", "5.254228"]], "bids": [["84072.50", "0.017736"], ["84070.50", "0.046673"], ["84068.50", "0.122823"], ["84067.74", "0.041077"], ["84067.53", "0"], ["84066.50", "0.323220"], ["84064.50", "0.850372"], ["84062.50", "2.237822"], ["84020.40", "5.344818"], ["84011.90", "3.985966"], ["84003.40", "5.254228"], ["83994.90", "3.895376"], ["83986.40", "4.801277"], ["83977.90", "4.982457"], ["83969.40", "4.076556"], ["83960.90", "4.438917"], ["83952.40", "5.163638"], ["83943.90", "4.257736"], ["83935.40", "4.891867"], ["83926.90", "5.525998"], ["83918.40", "5.616588"], ["83909.90", "4.620097"], ["83901.40", "4.529507"], ["83892.90", "4.167146"], ["83884.40", "4.348327"], ["83875.90", "4.710687"], ["83867.40", "5.073048"], ["83858.90", "5.435408"]], "checksum": 121601955, "ts": "1742555025501"}], "ts": 1742555025504, "record_time": 1742555025.527076, "EXCHANGE": "BITGET"}
{"action": "update", "arg": {"instType": "SPOT", "channel": "books", "instId": "BTCUSDT"}, "data": [{"asks": [["84188.80", "5.344818"], ["84197.30", "4.710687"], ["84205.80", "5.073048"], ["84214.30", "4.982457"], ["84222.80", "4.529507"], ["84231.30", "4.076556"], ["84239.80", "4.167146"], ["84248.30", "4.801277"], ["84256.80", "5.525998"], ["84265.30", "4.438917"], ["84273.80", "3.985966"], ["84282.30", "4.257736"], ["84290.80", "5.163638"], ["84299.30", "4.620097"], ["84307.80", "3.895376"], ["84316.30", "5.616588"], ["84324.80", "5.435408"], ["84333.30", "4.891867"], ["84341.80", "4.348327"]], "bids": [["84020.40", "5.525998"], ["84011.90", "5.435408"], ["84003.40", "3.895376"], ["83994.90", "5.073048"], ["83986.40", "4.438917"], ["83977.90", "5.163638"], ["83969.40", "3.985966"], ["83960.90", "4.620097"], ["83952.40", "4.257736"], ["83943.90", "5.616588"], ["83935.40", "4.529507"], ["83926.90", "4.167146"], ["83918.40", "4.076556"], ["83909.90", "4.348327"], ["83901.40", "5.254228"], ["83892.90", "4.710687"], ["83884.40", "4.801277"], ["83875.90", "4.891867"], ["83867.40", "5.344818"], ["83858.90", "4.982457"]], "checksum": 121601955, "ts": "1742555025715"}], "ts": 1742555025718, "record_time": 1742555025.750686, "EXCHANGE": "BITGET"}
{"action": "update", "arg": {"instType": "SPOT", "channel": "books", "instId": "BTCUSDT"}, "data": [{"asks": [["84188.80", "3.985966"], ["84197.30", "3.895376"], ["84205.80", "5.254228"], ["84214.30", "4.257736"], ["84222.80", "5.616588"], ["84231.30", "4.982457"], ["84239.80", "4.438917"], ["84248.30", "5.163638"], ["84256.80", "4.710687"], ["84265.30", "4.076556"], ["84273.80", "4.348327"], ["84282.30", "5.344818"], ["84290.80", "4.801277"], ["84299.30", "5.435408"], ["84307.80", "5.525998"], ["84316.30", "4.167146"], ["84324.80", "4.891867"], ["84333.30", "5.073048"], ["84341.80", "4.620097"], ["84350.30", "4.529507"]], "bids": [["84020.40", "3.985966"], ["84011.90", "5.073048"], ["84003.40", "4.620097"], ["83994.90", "4.438917"], ["83986.40", "4.167146"], ["83977.90", "4.076556"], ["83969.40", "3.895376"], ["83960.90", "4.801277"], ["83952.40", "5.344818"], ["83935.40", "4.257736"], ["83926.90", "5.525998"], ["83918.40", "5.254228"], ["83909.90", "5.163638"], ["83901.40", "4.710687"], ["83892.90", "4.348327"], ["83884.40", "4.529507"], ["83875.90", "5.435408"], ["83867.40", "4.982457"], ["83858.90", "4.891867"]], "checksum": 121601955, "ts": "1742555025924"}], "ts": 1742555025927, "record_time": 1742555025.955939, "EXCHANGE": "BITGET"}
{"action": "update", "arg": {"instType": "SPOT", "channel": "books", "instId": "BTCUSDT"}, "data": [{"asks": [["84102.81", "0.071458"], ["84137.08", "0.000039"], ["84188.80", "4.348327"], ["84197.30", "4.076556"], ["84205.80", "4.167146"], ["84214.30", "3.895376"], ["84222.80", "4.438917"], ["84231.30", "5.073048"], ["84239.80", "5.344818"], ["84248.30", "4.801277"], ["84256.80", "4.891867"], ["84265.30", "5.435408"], ["84273.80", "5.254228"], ["84282.30", "4.257736"], ["84290.80", "4.710687"], ["84299.30", "4.620097"], ["84307.80", "4.982457"], ["84316.30", "5.525998"], ["84324.80", "3.985966"], ["84333.30", "5.616588"], ["84341.80", "5.163638"], ["84527.47", "0"]], "bids": [["84067.93", "0.041077"], ["84067.74", "0"], ["84062.50", "2.237971"], ["84057.70", "0.015180"], ["84052.60", "2.355600"], ["84052.20", "0"], ["84020.40", "4.891867"], ["84011.90", "4.710687"], ["84003.40", "4.167146"], ["83994.90", "4.348327"], ["83986.40", "5.616588"], ["83977.90", "5.163638"], ["83969.40", "5.344818"], ["83960.90", "5.435408"], ["83952.40", "4.982457"], ["83943.90", "5.525998"], ["83935.40", "4.529507"], ["83926.90", "4.620097"], ["83918.40", "5.073048"], ["83909.90", "4.076556"], ["83901.40", "5.254228"], ["83892.90", "4.801277"], ["83884.40", "3.895376"], ["83875.90", "4.438917"], ["83867.40", "4.257736"], ["83858.90", "3.985966"]], "checksum": 1908532961, "ts": "1742555026137"}], "ts": 1742555026140, "record_time": 1742555026.161796, "EXCHANGE": "BITGET"}
{"action": "update", "arg": {"instType": "SPOT", "channel": "books", "instId": "BTCUSDT"}, "data": [{"asks": [["84080.01", "0.112929"], ["84082.94", "0"], ["84121.60", "0.010000"], ["84156.80", "0.320940"], ["84159.70", "0.178200"], ["84188.80", "4.891867"], ["84197.30", "4.710687"], ["84205.80", "4.438917"], ["84214.30", "4.076556"], ["84222.80", "5.073048"], ["84231.30", "4.801277"], ["84239.80", "4.348327"], ["84248.30", "5.163638"], ["84256.80", "4.167146"], ["84265.30", "3.985966"], ["84273.80", "3.895376"], ["84282.30", "5.344818"], ["84290.80", "4.257736"], ["84299.30", "5.525998"], ["84307.80", "5.254228"], ["84316.30", "5.435408"], ["84324.80", "4.620097"], ["84333.30", "4.982457"], ["84341.80", "4.529507"], ["84350.30", "5.616588"], ["84525.00", "0"], ["84525.82", "0"]], "bids": [["84073.00", "0.944501"], ["84056.90", "0.022620"], ["84055.40", "0"], ["84020.40", "4.076556"], ["84011.90", "4.529507"], ["84003.40", "5.525998"], ["83994.90", "5.163638"], ["83986.40", "4.257736"], ["83977.90", "5.073048"], ["83969.40", "3.895376"], ["83952.40", "4.348327"], ["83943.90", "4.891867"], ["83935.40", "4.620097"], ["83926.90", "4.982457"], ["83918.40", "4.801277"], ["83909.90", "5.254228"], ["83901.40", "5.344818"], ["83892.90", "3.985966"], ["83884.40", "4.710687"], ["83867.40", "5.616588"], ["83858.90", "4.167146"]], "checksum": 1526371759, "ts": "1742555026343"}], "ts": 1742555026346, "record_time": 1742555026.384085, "EXCHANGE": "BITGET"}
{"action": "update", "arg": {"instType": "SPOT", "channel": "books", "instId": "BTCUSDT"}, "data": [{"asks": [["84080.00", "0.096639"], ["84081.41", "0"], ["84188.80", "5.254228"], ["84197.30", "4.257736"], ["84205.80", "5.344818"], ["84214.30", "5.616588"], ["84222.80", "4.167146"], ["84231.30", "3.895376"], ["84239.80", "5.073048"], ["84248.30", "5.435408"], ["84256.80", "4.438917"], ["84273.80", "4.076556"], ["84282.30", "4.891867"], ["84290.80", "5.163638"], ["84299.30", "4.620097"], ["84307.80", "4.801277"], ["84316.30", "4.982457"], ["84324.80", "4.529507"], ["84333.30", "4.710687"], ["84341.80", "5.525998"], ["84350.30", "4.348327"]], "bids": [["84068.10", "0.041077"], ["84067.93", "0"], ["84066.50", "0.323214"], ["84064.50", "0.850563"], ["84062.50", "2.238324"], ["84020.40", "5.525998"], ["84011.90", "4.438917"], ["84003.40", "4.076556"], ["83994.90", "5.435408"], ["83986.40", "4.167146"], ["83977.90", "3.985966"], ["83969.40", "4.710687"], ["83960.90", "5.344818"], ["83952.40", "4.620097"], ["83943.90", "4.257736"], ["83935.40", "4.348327"], ["83926.90", "3.895376"], ["83918.40", "4.982457"], ["83909.90", "4.529507"], ["83901.40", "4.891867"], ["83892.90", "5.254228"], ["83884.40", "5.163638"], ["83875.90", "5.073048"], ["83867.40", "4.801277"], ["83858.90", "5.616588"]], "checksum": 1396699506, "ts": "1742555026546"}], "ts": 1742555026550, "record_time": 1742555026.575592, "EXCHANGE": "BITGET"}
{"action": "update", "arg": {"instType": "SPOT", "channel": "books", "instId": "BTCUSDT"}, "data": [{"asks": [["84144.70", "6.231544"], ["84146.70", "16.398802"], ["84150.90", "0.015000"], ["84159.70", "0"], ["84188.80", "4.620097"], ["84197.30", "4.438917"], ["84205.80", "4.891867"], ["84214.30", "5.163638"], ["84222.80", "5.254228"], ["84231.30", "5.525998"], ["84239.80", "4.982457"], ["84248.30", "3.895376"], ["84256.80", "4.167146"], ["84265.30", "5.073048"], ["84273.80", "4.529507"], ["84282.30", "5.616588"], ["84290.80", "4.710687"], ["84299.30", "3.985966"], ["84316.30", "4.076556"], ["84324.80", "4.257736"], ["84333.30", "4.348327"], ["84341.80", "5.435408"], ["84350.30", "5.344818"]], "bids": [["84068.32", "0.020024"], ["84057.70", "0.014430"], ["84055.30", "2.355540"], ["84053.70", "0"], ["84052.60", "0"], ["84052.20", "0.120930"], ["84020.40", "4.438917"], ["84011.90", "3.895376"], ["84003.40", "4.891867"], ["83994.90", "4.348327"], ["83986.40", "4.801277"], ["83977.90", "4.167146"], ["83969.40", "5.073048"], ["83960.90", "4.529507"], ["83952.40", "4.710687"], ["83943.90", "5.344818"], ["83935.40", "5.435408"], ["83926.90", "4.620097"], ["83909.90", "5.163638"], ["83901.40", "5.254228"], ["83892.90", "4.257736"], ["83884.40", "5.616588"], ["83875.90", "4.076556"], ["83867.40", "3.985966"], ["83858.90", "5.525998"]], "checksum": -1772203117, "ts": "1742555026754"}], "ts": 1742555026758, "record_time": 1742555026.780244, "EXCHANGE": "BITGET"}
{"action": "update", "arg": {"instType": "SPOT", "channel": "books", "instId": "BTCUSDT"}, "data": [{"asks": [["84146.70", "16.398653"], ["84155.30", "0.037560"], ["84188.80", "4.257736"], ["84197.30", "4.891867"], ["84205.80", "4.076556"], ["84214.30", "4.982457"], ["84222.80", "5.073048"], ["84231.30", "5.616588"], ["84239.80", "5.525998"], ["84248.30", "5.344818"], ["84256.80", "3.985966"], ["84265.30", "4.167146"], ["84273.80", "4.438917"], ["84282.30", "3.895376"], ["84290.80", "4.348327"], ["84299.30", "5.435408"], ["84307.80", "4.620097"], ["84316.30", "5.254228"], ["84324.80", "4.801277"], ["84333.30", "4.529507"], ["84341.80", "4.710687"], ["84350.30", "5.163638"], ["84524.83", "0"]], "bids": [["84068.50", "0.122935"], ["84066.50", "0.323515"], ["84064.50", "0.851355"], ["84062.50", "2.240407"], ["84056.70", "1.254570"], ["84055.30", "0"], ["84052.20", "0.589140"], ["84020.40", "3.985966"], ["84011.90", "5.616588"], ["84003.40", "4.167146"], ["83994.90", "4.891867"], ["83986.40", "4.982457"], ["83977.90", "5.435408"], ["83969.40", "4.801277"], ["83952.40", "5.344818"], ["83943.90", "5.163638"], ["83935.40", "3.895376"], ["83926.90", "4.348327"], ["83918.40", "4.076556"], ["83909.90", "5.525998"], ["83901.40", "4.438917"], ["83892.90", "4.620097"], ["83884.40", "4.257736"], ["83875.90", "5.254228"], ["83867.40", "4.710687"], ["83858.90", "5.073048"], ["83663.91", "0.000161"]], "checksum": 1904085494, "ts": "1742555026965"}], "ts": 1742555026968, "record_time": 1742555027.006537, "EXCHANGE": "BITGET"}
{"action": "update", "arg": {"instType": "SPOT", "channel": "books", "instId": "BTCUSDT"}, "data": [{"asks": [["84105.36", "0.005234"], ["84188.80", "5.163638"], ["84197.30", "4.529507"], ["84205.80", "4.348327"], ["84214.30", "5.525998"], ["84222.80", "4.620097"], ["84231.30", "5.254228"], ["84239.80", "5.344818"], ["84248.30", "5.073048"], ["84256.80", "4.257736"], ["84265.30", "5.435408"], ["84273.80", "4.710687"], ["84282.30", "5.616588"], ["84290.80", "4.438917"], ["84299.30", "3.985966"], ["84307.80", "4.076556"], ["84316.30", "3.895376"], ["84324.80", "4.891867"], ["84333.30", "4.167146"], ["84341.80", "4.982457"], ["84350.30", "4.801277"], ["84524.00", "0"]], "bids": [["84068.30", "0.041077"], ["84068.10", "0"], ["84055.10", "0"], ["84052.90", "2.475600"], ["84052.20", "0.120930"], ["84051.40", "0.153580"], ["84025.60", "0"], ["84021.90", "0.200459"], ["84020.40", "5.163638"], ["84003.40", "4.620097"], ["83994.90", "5.344818"], ["83986.40", "3.895376"], ["83977.90", "4.891867"], ["83969.40", "4.167146"], ["83960.90", "4.257736"], ["83952.40", "5.254228"], ["83943.90", "4.982457"], ["83935.40", "3.985966"], ["83918.40", "5.073048"], ["83909.90", "4.438917"], ["83901.40", "4.801277"], ["83892.90", "4.710687"], ["83884.40", "5.525998"], ["83875.90", "4.076556"], ["83867.40", "5.435408"], ["83858.90", "4.529507"]], "checksum": -2114763391, "ts": "1742555027170"}], "ts": 1742555027179, "record_time": 1742555027.206303, "EXCHANGE": "BITGET"}
{"action": "update", "arg": {"instType": "SPOT", "channel": "books", "instId": "BTCUSDT"}, "data": [{"asks": [["84188.80", "5.344818"], ["84205.80", "5.254228"], ["84214.30", "4.257736"], ["84222.80", "5.073048"], ["84231.30", "4.620097"], ["84239.80", "3.895376"], ["84248.30", "4.348327"], ["84256.80", "4.801277"], ["84265.30", "5.616588"], ["84273.80", "4.076556"], ["84282.30", "5.525998"], ["84290.80", "5.163638"], ["84299.30", "4.710687"], ["84307.80", "4.167146"], ["84316.30", "3.985966"], ["84324.80", "5.435408"], ["84333.30", "4.891867"], ["84341.80", "4.438917"], ["84350.30", "4.982457"]], "bids": [["84020.40", "5.254228"], ["84011.90", "4.891867"], ["83994.90", "4.982457"], ["83986.40", "4.801277"], ["83977.90", "5.525998"], ["83969.40", "4.710687"], ["83960.90", "4.438917"], ["83952.40", "5.344818"], ["83943.90", "4.348327"], ["83935.40", "4.257736"], ["83926.90", "3.895376"], ["83918.40", "4.529507"], ["83909.90", "3.985966"], ["83901.40", "4.076556"], ["83892.90", "5.073048"], ["83884.40", "5.616588"], ["83875.90", "4.167146"], ["83858.90", "5.163638"]], "checksum": -2114763391, "ts": "1742555027379"}], "ts": 1742555027382, "record_time": 1742555027.403588, "EXCHANGE": "BITGET"}
{"action": "update", "arg": {"instType": "SPOT", "channel": "books", "instId": "BTCUSDT"}, "data": [{"asks": [["84119.62", "0"], ["84132.70", "0.018648"], ["84134.70", "0.049075"], ["84136.70", "0.129144"], ["84138.70", "0.339853"], ["84140.70", "0.894351"], ["84142.70", "2.353553"], ["84144.70", "6.193561"], ["84146.70", "16.298845"], ["84148.10", "0.146010"], ["84149.40", "0.120000"], ["84149.60", "0"], ["84158.10", "1.394880"], ["84159.00", "0"], ["84188.80", "4.891867"], ["84205.80", "4.348327"], ["84214.30", "5.616588"], ["84222.80", "5.344818"], ["84231.30", "5.435408"], ["84248.30", "4.982457"], ["84256.80", "5.073048"], ["84265.30", "4.620097"], ["84273.80", "5.525998"], ["84282.30", "4.076556"], ["84290.80", "3.985966"], ["84299.30", "4.438917"], ["84307.80", "5.254228"], ["84316.30", "4.801277"], ["84324.80", "5.163638"], ["84333.30", "4.710687"], ["84341.80", "4.167146"], ["84350.30", "4.257736"], ["84524.00", "0.000035"], ["84524.83", "0.000009"]], "bids": [["84068.46", "0.041077"], ["84068.30", "0"], ["84059.90", "0.177600"], ["84056.20", "2.355510"], ["84055.70", "0.030000"], ["84052.90", "0.120000"], ["84011.90", "4.076556"], ["84003.40", "5.525998"], ["83994.90", "4.438917"], ["83986.40", "5.163638"], ["83977.90", "4.257736"], ["83969.40", "4.348327"], ["83960.90", "4.710687"], ["83952.40", "4.620097"], ["83943.90", "5.435408"], ["83935.40", "4.982457"], ["83926.90", "4.167146"], ["83918.40", "5.344818"], ["83909.90", "5.073048"], ["83901.40", "4.529507"], ["83892.90", "4.891867"], ["83884.40", "3.895376"], ["83875.90", "4.801277"], ["83867.40", "3.985966"], ["83858.90", "5.616588"], ["83663.91", "0"]], "checksum": 353763442, "ts": "1742555027597"}], "ts": 1742555027603, "record_time": 1742555027.626064, "EXCHANGE": "BITGET"}
{"action": "update", "arg": {"instType": "SPOT", "channel": "books", "instId": "BTCUSDT"}, "data": [{"asks": [["84073.01", "1.704257"], ["84126.70", "0.001417"], ["84128.70", "0.002312"], ["84130.70", "0.006084"], ["84132.70", "0.016011"], ["84134.70", "0.042133"], ["84136.70", "0.110877"], ["84138.70", "0.291782"], ["84140.70", "0.767846"], ["84142.70", "2.020649"], ["84144.70", "5.317497"], ["84146.70", "13.993412"], ["84150.10", "0.909630"], ["84150.30", "0.071880"], ["84151.40", "0"], ["84158.10", "1.462680"], ["84188.80", "4.438917"], ["84197.30", "5.344818"], ["84205.80", "4.982457"], ["84214.30", "4.620097"], ["84222.80", "5.525998"], ["84231.30", "4.167146"], ["84239.80", "5.616588"], ["84248.30", "4.710687"], ["84256.80", "4.529507"], ["84265.30", "5.435408"], ["84273.80", "4.348327"], ["84282.30", "5.163638"], ["84290.80", "5.073048"], ["84299.30", "5.254228"], ["84307.80", "4.257736"], ["84316.30", "4.076556"], ["84324.80", "4.891867"], ["84333.30", "4.801277"], ["84341.80", "3.895376"], ["84350.30", "3.985966"], ["84525.00", "0.003286"]], "bids": [["84072.50", "0.024461"], ["84070.50", "0.064371"], ["84068.50", "0.169396"], ["84066.50", "0.445780"], ["84064.50", "1.173104"], ["84062.50", "3.087116"], ["84056.70", "1.175250"], ["84056.20", "0"], ["84052.20", "0.589140"], ["84020.40", "4.529507"], ["84011.90", "4.801277"], ["84003.40", "4.438917"], ["83994.90", "3.895376"], ["83986.40", "5.073048"], ["83977.90", "5.435408"], ["83969.40", "4.982457"], ["83960.90", "5.525998"], ["83952.40", "5.344818"], ["83943.90", "5.163638"], ["83935.40", "4.076556"], ["83926.90", "4.257736"], ["83918.40", "3.985966"], ["83909.90", "4.620097"], ["83901.40", "4.167146"], ["83892.90", "4.348327"], ["83884.40", "5.616588"], ["83875.90", "4.710687"], ["83867.40", "4.891867"], ["83858.90", "5.254228"], ["83663.91", "0.000161"]], "checksum": 713851410, "ts": "1742555027805"}], "ts": 1742555027809, "record_time": 1742555027.830123, "EXCHANGE": "BITGET"}
{"action": "update", "arg": {"instType": "SPOT", "channel": "books", "instId": "BTCUSDT"}, "data": [{"asks": [["84087.65", "0"], ["84088.26", "0"], ["84089.27", "0"], ["84089.32", "0"], ["84089.52", "0"], ["84089.85", "0"], ["84090.92", "0.035952"], ["84091.20", "0"], ["84091.37", "0"], ["84091.38", "0.119870"], ["84092.02", "0"], ["84092.21", "0"], ["84092.36", "0"], ["84092.51", "0"], ["84092.65", "0.035961"], ["84092.84", "0"], ["84092.89", "0"], ["84093.04", "0.006356"], ["84093.21", "0.006356"], ["84093.54", "0.006356"], ["84094.37", "0"], ["84094.67", "0.010984"], ["84094.79", "0.006356"], ["84094.96", "0.006356"], ["84095.59", "0.006356"], ["84096.01", "0.006356"], ["84096.08", "0.006356"], ["84096.48", "0.006356"], ["84096.56", "0.006356"], ["84098.10", "0.006357"], ["84102.63", "0"], ["84106.06", "0.010988"], ["84119.17", "0.176813"], ["84188.80", "4.710687"], ["84197.30", "4.348327"], ["84205.80", "5.073048"], ["84214.30", "4.257736"], ["84222.80", "5.344818"], ["84231.30", "3.895376"], ["84248.30", "4.529507"], ["84256.80", "4.982457"], ["84265.30", "4.167146"], ["84273.80", "5.525998"], ["84282.30", "5.435408"], ["84290.80", "4.076556"], ["84307.80", "3.985966"], ["84316.30", "4.620097"], ["84333.30", "5.163638"], ["84341.80", "4.801277"], ["84350.30", "4.438917"], ["84525.00", "0"]], "bids": [["84072.50", "0.017798"], ["84070.50", "0.046838"], ["84068.50", "0.123257"], ["84066.50", "0.324361"], ["84064.50", "0.853581"], ["84062.50", "2.246266"], ["84056.70", "0.540600"], ["84050.56", "0.089474"], ["84050.19", "0.247559"], ["84048.93", "0.083930"], ["84048.48", "0.017815"], ["84048.31", "0.018253"], ["84047.98", "0.005945"], ["84047.91", "0"], ["84046.92", "0.055649"], ["84046.53", "0.017101"], ["84046.45", "0"], ["84046.36", "0.007131"], ["84045.99", "0.007339"], ["84045.55", "0"], ["84045.47", "0.008993"], ["84045.40", "0.007942"], ["84044.94", "0.008184"], ["84044.86", "0.017349"], ["84044.77", "0"], ["84044.62", "0"], ["84044.29", "0"], ["84044.27", "0"], ["84043.45", "0.012654"], ["84042.94", "0"], ["84042.78", "0"], ["84042.61", "0"], ["84041.90", "0"], ["84041.75", "0"], ["84041.27", "0"], ["84041.23", "0"], ["84039.73", "0"], ["84035.44", "0.056361"], ["84033.79", "0.000876"], ["84032.02", "0"], ["84030.11", "0"], ["84020.40", "3.895376"], ["84011.90", "4.982457"], ["84003.40", "5.344818"], ["83994.90", "4.529507"], ["83986.40", "4.348327"], ["83977.90", "4.801277"], ["83969.40", "4.710687"], ["83960.90", "5.163638"], ["83952.40", "4.167146"], ["83943.90", "5.073048"], ["83935.40", "4.257736"], ["83926.90", "4.891867"], ["83918.40", "5.525998"], ["83909.90", "4.438917"], ["83901.40", "4.076556"], ["83892.90", "5.254228"], ["83884.40", "5.435408"], ["83875.90", "4.620097"], ["83867.40", "5.616588"], ["83858.90", "3.985966"]], "checksum": -1812121412, "ts": "1742555028017"}], "ts": 1742555028022, "record_time": 1742555028.051672, "EXCHANGE": "BITGET"}
{"action": "update", "arg": {"instType": "SPOT", "channel": "books", "instId": "BTCUSDT"}, "data": [{"asks": [["84087.64", "0"], ["84088.66", "0.043385"], ["84188.80", "5.344818"], ["84197.30", "5.163638"], ["84205.80", "4.801277"], ["84214.30", "5.616588"], ["84222.80", "4.257736"], ["84231.30", "4.891867"], ["84239.80", "5.254228"], ["84248.30", "3.895376"], ["84256.80", "4.438917"], ["84273.80", "4.620097"], ["84282.30", "5.073048"], ["84290.80", "3.985966"], ["84299.30", "4.348327"], ["84307.80", "4.529507"], ["84316.30", "5.525998"], ["84324.80", "4.076556"], ["84333.30", "5.435408"], ["84341.80", "4.982457"], ["84350.30", "4.710687"], ["84525.00", "0.003286"]], "bids": [["84068.62", "0.041077"], ["84068.46", "0"], ["84058.30", "0.015000"], ["84052.20", "0.120930"], ["84020.40", "4.891867"], ["84011.90", "5.344818"], ["84003.40", "4.801277"], ["83994.90", "5.435408"], ["83986.40", "4.982457"], ["83977.90", "4.076556"], ["83969.40", "5.073048"], ["83960.90", "4.348327"], ["83952.40", "4.710687"], ["83943.90", "4.529507"], ["83935.40", "4.167146"], ["83926.90", "4.257736"], ["83909.90", "5.616588"], ["83901.40", "3.895376"], ["83892.90", "4.438917"], ["83884.40", "5.163638"], ["83875.90", "3.985966"], ["83867.40", "4.620097"], ["83858.90", "5.254228"], ["83663.91", "0"]], "checksum": 1334874038, "ts": "1742555028261"}], "ts": 1742555028264, "record_time": 1742555028.289017, "EXCHANGE": "BITGET"}
{"action": "update", "arg": {"instType": "SPOT", "channel": "books", "instId": "BTCUSDT"}, "data": [{"asks": [["84105.36", "0.007876"], ["84121.60", "0"], ["84188.80", "3.895376"], ["84197.30", "4.438917"], ["84205.80", "4.982457"], ["84214.30", "3.985966"], ["84222.80", "4.891867"], ["84231.30", "4.167146"], ["84239.80", "5.525998"], ["84248.30", "4.076556"], ["84256.80", "4.348327"], ["84265.30", "4.620097"], ["84273.80", "4.529507"], ["84282.30", "4.710687"], ["84290.80", "5.254228"], ["84299.30", "5.163638"], ["84307.80", "5.435408"], ["84316.30", "5.073048"], ["84324.80", "4.257736"], ["84333.30", "5.616588"], ["84341.80", "5.344818"], ["84350.30", "4.801277"], ["84525.82", "0.000099"]], "bids": [["84073.00", "0.934501"], ["84068.32", "0.005920"], ["84020.40", "3.985966"], ["84011.90", "5.525998"], ["84003.40", "4.438917"], ["83994.90", "4.801277"], ["83986.40", "5.435408"], ["83977.90", "3.895376"], ["83969.40", "4.257736"], ["83960.90", "4.167146"], ["83952.40", "5.344818"], ["83943.90", "4.620097"], ["83935.40", "5.616588"], ["83926.90", "4.529507"], ["83918.40", "4.076556"], ["83909.90", "4.710687"], ["83901.40", "5.163638"], ["83892.90", "5.073048"], ["83884.40", "4.982457"], ["83875.90", "4.891867"], ["83867.40", "5.254228"], ["83858.90", "4.348327"]], "checksum": 1876557317, "ts": "1742555028487"}], "ts": 1742555028491, "record_time": 1742555028.57658, "EXCHANGE": "BITGET"}
{"action": "update", "arg": {"instType": "SPOT", "channel": "books", "instId": "BTCUSDT"}, "data": [{"asks": [["84188.80", "5.163638"], ["84197.30", "4.982457"], ["84205.80", "5.435408"], ["84214.30", "4.529507"], ["84222.80", "4.710687"], ["84231.30", "4.891867"], ["84239.80", "5.073048"], ["84248.30", "4.348327"], ["84256.80", "4.076556"], ["84265.30", "5.344818"], ["84273.80", "4.801277"], ["84282.30", "4.438917"], ["84299.30", "3.985966"], ["84307.80", "5.616588"], ["84316.30", "5.525998"], ["84324.80", "4.167146"], ["84333.30", "3.895376"], ["84341.80", "4.257736"], ["84350.30", "4.620097"]], "bids": [["84069.44", "0.014104"], ["84068.76", "0.041077"], ["84068.62", "0"], ["84020.40", "5.344818"], ["84011.90", "4.257736"], ["84003.40", "5.254228"], ["83986.40", "5.163638"], ["83977.90", "4.529507"], ["83969.40", "3.985966"], ["83960.90", "4.076556"], ["83952.40", "4.620097"], ["83943.90", "4.982457"], ["83935.40", "5.525998"], ["83926.90", "4.710687"], ["83918.40", "5.435408"], ["83909.90", "4.438917"], ["83901.40", "4.167146"], ["83892.90", "4.891867"], ["83884.40", "4.348327"], ["83875.90", "3.895376"], ["83867.40", "5.616588"], ["83858.90", "5.073048"], ["83663.95", "0"]], "checksum": -1703916276, "ts": "1742555028717"}], "ts": 1742555028720, "record_time": 1742555028.772097, "EXCHANGE": "BITGET"}
{"action": "update", "arg": {"instType": "SPOT", "channel": "books", "instId": "BTCUSDT"}, "data": [{"asks": [["84188.80", "4.529507"], ["84197.30", "4.438917"], ["84205.80", "4.167146"], ["84214.30", "5.163638"], ["84222.80", "4.257736"], ["84231.30", "5.073048"], ["84239.80", "4.348327"], ["84248.30", "3.895376"], ["84256.80", "5.616588"], ["84265.30", "5.254228"], ["84273.80", "5.435408"], ["84282.30", "4.076556"], ["84290.80", "4.710687"], ["84299.30", "4.982457"], ["84307.80", "4.620097"], ["84316.30", "3.985966"], ["84324.80", "5.344818"], ["84333.30", "4.801277"], ["84341.80", "5.525998"], ["84350.30", "4.891867"]], "bids": [["84020.40", "4.348327"], ["84011.90", "4.167146"], ["84003.40", "4.801277"], ["83994.90", "5.254228"], ["83986.40", "3.895376"], ["83977.90", "4.438917"], ["83969.40", "4.529507"], ["83960.90", "4.710687"], ["83952.40", "4.076556"], ["83943.90", "5.344818"], ["83935.40", "5.616588"], ["83926.90", "5.435408"], ["83918.40", "4.620097"], ["83909.90", "3.985966"], ["83901.40", "4.891867"], ["83892.90", "5.073048"], ["83884.40", "5.525998"], ["83875.90", "5.163638"], ["83867.40", "4.982457"], ["83858.90", "4.257736"]], "checksum": -1703916276, "ts": "1742555028921"}], "ts": 1742555028924, "record_time": 1742555028.945318, "EXCHANGE": "BITGET"}
{"action": "update", "arg": {"instType": "SPOT", "channel": "books", "instId": "BTCUSDT"}, "data": [{"asks": [["84188.80", "5.525998"], ["84197.30", "4.167146"], ["84205.80", "4.891867"], ["84214.30", "4.620097"], ["84222.80", "4.801277"], ["84231.30", "5.435408"], ["84248.30", "4.076556"], ["84256.80", "4.438917"], ["84265.30", "4.710687"], ["84273.80", "3.985966"], ["84282.30", "5.344818"], ["84290.80", "5.073048"], ["84299.30", "5.616588"], ["84307.80", "4.257736"], ["84316.30", "5.254228"], ["84324.80", "4.982457"], ["84333.30", "4.529507"], ["84341.80", "5.163638"], ["84350.30", "3.895376"]], "bids": [["84072.50", "0.024430"], ["84070.50", "0.064290"], ["84068.76", "0"], ["84068.50", "0.169185"], ["84066.50", "0.445224"], ["84064.50", "1.171641"], ["84062.50", "3.083266"], ["84020.40", "4.620097"], ["84011.90", "3.985966"], ["84003.40", "4.891867"], ["83994.90", "5.525998"], ["83986.40", "4.257736"], ["83977.90", "4.348327"], ["83969.40", "5.616588"], ["83960.90", "5.344818"], ["83952.40", "5.163638"], ["83943.90", "4.529507"], ["83935.40", "4.982457"], ["83926.90", "4.438917"], ["83918.40", "4.167146"], ["83909.90", "5.073048"], ["83901.40", "5.435408"], ["83892.90", "4.801277"], ["83884.40", "4.710687"], ["83875.90", "5.254228"], ["83867.40", "4.076556"], ["83858.90", "3.895376"], ["83663.95", "0.000022"]], "checksum": -1209383248, "ts": "1742555029137"}], "ts": 1742555029142, "record_time": 1742555029.164519, "EXCHANGE": "BITGET"}
{"action": "update", "arg": {"instType": "SPOT", "channel": "books", "instId": "BTCUSDT"}, "data": [{"asks": [["84073.01", "1.495057"], ["84119.16", "0.053644"], ["84128.70", "0.002174"], ["84130.70", "0.005720"], ["84132.70", "0.015052"], ["84134.70", "0.039612"], ["84136.70", "0.104241"], ["84138.70", "0.274320"], ["84140.70", "0.721894"], ["84142.70", "1.899722"], ["84144.70", "4.999267"], ["84146.70", "13.155966"], ["84188.80", "5.435408"], ["84197.30", "4.348327"], ["84205.80", "4.982457"], ["84214.30", "5.616588"], ["84222.80", "4.710687"], ["84231.30", "4.620097"], ["84239.80", "5.344818"], ["84248.30", "5.254228"], ["84256.80", "3.895376"], ["84265.30", "4.076556"], ["84273.80", "4.438917"], ["84282.30", "5.525998"], ["84290.80", "4.891867"], ["84299.30", "5.163638"], ["84307.80", "4.801277"], ["84316.30", "4.167146"], ["84324.80", "4.529507"], ["84333.30", "3.985966"], ["84341.80", "4.257736"], ["84350.30", "5.073048"], ["84525.82", "0"]], "bids": [["84073.00", "1.250250"], ["84072.50", "0.037442"], ["84070.50", "0.098531"], ["84068.91", "0.041076"], ["84068.50", "0.259293"], ["84066.50", "0.682348"], ["84064.50", "1.795654"], ["84062.50", "4.725404"], ["84053.91", "0"], ["84020.40", "4.076556"], ["84011.90", "4.529507"], ["84003.40", "3.985966"], ["83994.90", "4.710687"], ["83986.40", "5.344818"], ["83977.90", "4.801277"], ["83969.40", "4.167146"], ["83960.90", "4.982457"], ["83952.40", "3.895376"], ["83943.90", "5.254228"], ["83935.40", "4.891867"], ["83926.90", "5.525998"], ["83918.40", "5.073048"], ["83909.90", "5.435408"], ["83901.40", "4.348327"], ["83892.90", "4.438917"], ["83884.40", "5.163638"], ["83875.90", "5.616588"], ["83867.40", "4.620097"], ["83858.90", "4.257736"]], "checksum": 353034631, "ts": "1742555029339"}], "ts": 1742555029342, "record_time": 1742555029.364384, "EXCHANGE": "BITGET"}
{"action": "update", "arg": {"instType": "SPOT", "channel": "books", "instId": "BTCUSDT"}, "data": [{"asks": [["84093.32", "0"], ["84094.17", "0"], ["84094.50", "0"], ["84095.76", "0.016429"], ["84096.19", "0"], ["84096.61", "0.119883"], ["84096.71", "0.016429"], ["84097.01", "0"], ["84097.95", "0"], ["84098.39", "0.010985"], ["84098.81", "0"], ["84099.14", "0"], ["84099.21", "0"], ["84099.23", "0.009990"], ["84099.31", "0"], ["84100.16", "0.119850"], ["84101.12", "0.119858"], ["84101.31", "0.119867"], ["84101.57", "0.015895"], ["84101.65", "0.009989"], ["84102.99", "0"], ["84105.43", "0.015892"], ["84125.31", "0"], ["84126.21", "0.706776"], ["84126.70", "0.001026"], ["84127.05", "0.001598"], ["84127.22", "0"], ["84128.70", "0.001674"], ["84128.94", "0.001597"], ["84130.70", "0.004404"], ["84132.70", "0.011590"], ["84134.70", "0.030501"], ["84136.70", "0.080266"], ["84138.70", "0.210978"], ["84140.70", "0.555204"], ["84142.70", "1.461065"], ["84144.70", "3.844907"], ["84146.70", "10.118177"], ["84188.80", "4.076556"], ["84197.30", "4.257736"], ["84205.80", "5.616588"], ["84214.30", "3.985966"], ["84222.80", "5.344818"], ["84239.80", "4.801277"], ["84248.30", "5.163638"], ["84256.80", "4.529507"], ["84265.30", "5.435408"], ["84273.80", "4.982457"], ["84282.30", "4.167146"], ["84290.80", "4.710687"], ["84299.30", "5.525998"], ["84307.80", "4.348327"], ["84316.30", "5.073048"], ["84324.80", "4.438917"], ["84333.30", "4.891867"], ["84341.80", "5.254228"], ["84350.30", "3.895376"]], "bids": [["84073.00", "1.245808"], ["84072.50", "0.040812"], ["84070.51", "0.124130"], ["84070.50", "0.107400"], ["84068.50", "0.282629"], ["84066.51", "0.322994"], ["84066.50", "0.743763"], ["84064.50", "1.957271"], ["84062.50", "5.150712"], ["84057.78", "0.043750"], ["84048.90", "0.004017"], ["84046.16", "0.028861"], ["84045.81", "0"], ["84045.43", "0.025182"], ["84045.33", "0.224857"], ["84043.74", "0.051957"], ["84043.72", "0"], ["84043.22", "0"], ["84042.90", "0.018515"], ["84042.89", "0"], ["84041.98", "0.268346"], ["84041.54", "0"], ["84040.93", "0.231854"], ["84040.78", "0.259766"], ["84040.68", "0"], ["84040.53", "0.076104"], ["84040.28", "0.021127"], ["84039.78", "0.017446"], ["84038.61", "0"], ["84038.28", "0"], ["84037.84", "0"], ["84036.49", "0.073206"], ["84034.05", "0"], ["84020.40", "5.073048"], ["84016.74", "0.001176"], ["84015.01", "0"], ["84014.78", "0.001173"], ["84013.06", "0"], ["84011.90", "4.710687"], ["84003.40", "5.525998"], ["83994.90", "5.344818"], ["83986.40", "5.435408"], ["83977.90", "4.348327"], ["83969.40", "4.801277"], ["83960.90", "4.891867"], ["83952.40", "4.076556"], ["83943.90", "4.438917"], ["83935.40", "3.985966"], ["83926.90", "4.529507"], ["83918.40", "3.895376"], ["83909.90", "5.254228"], ["83901.40", "4.620097"], ["83892.90", "5.616588"], ["83884.40", "4.167146"], ["83875.90", "4.982457"], ["83867.40", "5.163638"], ["83663.95", "0"]], "checksum": 1709451598, "ts": "1742555029540"}], "ts": 1742555029543, "record_time": 1742555029.631318, "EXCHANGE": "BITGET"}
{"action": "update", "arg": {"instType": "SPOT", "channel": "books", "instId": "BTCUSDT"}, "data": [{"asks": [["84075.62", "0"], ["84080.00", "0"], ["84128.70", "0.001812"], ["84130.70", "0.004768"], ["84132.70", "0.012549"], ["84134.70", "0.032921"], ["84136.70", "0.086633"], ["84138.70", "0.227982"], ["84140.70", "0.599954"], ["84142.70", "1.578825"], ["84144.70", "4.155016"], ["84146.70", "10.934252"], ["84156.10", "1.102440"], ["84188.80", "4.529507"], ["84197.30", "4.167146"], ["84205.80", "3.985966"], ["84214.30", "4.348327"], ["84222.80", "5.163638"], ["84231.30", "5.254228"], ["84239.80", "5.344818"], ["84248.30", "4.620097"], ["84256.80", "5.525998"], ["84273.80", "4.891867"], ["84282.30", "4.710687"], ["84290.80", "4.982457"], ["84299.30", "4.438917"], ["84307.80", "5.073048"], ["84316.30", "4.076556"], ["84324.80", "4.257736"], ["84333.30", "4.801277"], ["84341.80", "5.616588"], ["84525.82", "0.000099"], ["84527.47", "0.000608"]], "bids": [["84072.50", "0.043518"], ["84070.50", "0.114522"], ["84069.08", "0.041076"], ["84068.91", "0"], ["84068.50", "0.301375"], ["84066.51", "0.703419"], ["84066.50", "0.793091"], ["84064.50", "2.087081"], ["84062.50", "5.492320"], ["84054.60", "2.355540"], ["84052.20", "0"], ["84020.40", "4.710687"], ["84015.60", "0.003596"], ["84013.15", "0"], ["84011.90", "4.167146"], ["84003.40", "4.257736"], ["83994.90", "4.438917"], ["83986.40", "4.982457"], ["83977.90", "5.254228"], ["83969.40", "5.435408"], ["83960.90", "4.620097"], ["83959.22", "0"], ["83952.40", "4.891867"], ["83951.62", "0.125585"], ["83943.90", "4.529507"], ["83935.40", "5.163638"], ["83926.90", "3.895376"], ["83918.40", "5.073048"], ["83909.90", "5.616588"], ["83901.40", "4.348327"], ["83892.90", "4.076556"], ["83884.40", "3.985966"], ["83875.90", "5.344818"], ["83867.40", "5.525998"], ["83858.90", "4.801277"]], "checksum": -1197411836, "ts": "1742555029765"}], "ts": 1742555029769, "record_time": 1742555029.815862, "EXCHANGE": "BITGET"}
{"action": "update", "arg": {"instType": "SPOT", "channel": "books", "instId": "BTCUSDT"}, "data": [{"asks": [["84075.62", "0.207082"], ["84123.62", "0.010000"], ["84128.70", "0.001380"], ["84130.70", "0.003631"], ["84132.70", "0.009555"], ["84134.70", "0.024979"], ["84136.70", "0.065732"], ["84138.70", "0.173143"], ["84140.70", "0.455639"], ["84142.70", "1.199050"], ["84144.70", "3.155396"], ["84146.70", "8.303672"], ["84147.80", "0.001740"], ["84148.10", "0.124260"], ["84148.90", "0.001023"], ["84149.00", "0"], ["84150.10", "0.863820"], ["84150.90", "0"], ["84151.60", "0.045540"], ["84153.40", "0"], ["84159.00", "0.024930"], ["84188.80", "4.438917"], ["84197.30", "4.710687"], ["84205.80", "5.435408"], ["84214.30", "4.529507"], ["84222.80", "5.525998"], ["84231.30", "3.895376"], ["84239.80", "5.616588"], ["84248.30", "3.985966"], ["84256.80", "5.254228"], ["84265.30", "4.620097"], ["84273.80", "5.163638"], ["84282.30", "5.344818"], ["84290.80", "4.348327"], ["84299.30", "4.982457"], ["84307.80", "4.257736"], ["84316.30", "4.801277"], ["84324.80", "4.076556"], ["84333.30", "5.073048"], ["84341.80", "4.891867"], ["84350.30", "4.167146"], ["84527.47", "0"]], "bids": [["84072.50", "0.051632"], ["84070.50", "0.135716"], ["84068.50", "0.357146"], ["84066.50", "0.939859"], ["84064.50", "2.473312"], ["84062.50", "6.508717"], ["84061.90", "1.382430"], ["84059.90", "0.111450"], ["84059.60", "0.057540"], ["84057.20", "0"], ["84056.70", "1.171470"], ["84056.50", "2.625480"], ["84056.30", "0"], ["84054.60", "0"], ["84052.20", "0.589140"], ["84020.40", "4.529507"], ["84011.90", "5.073048"], ["84003.40", "4.620097"], ["83994.90", "4.076556"], ["83986.40", "4.167146"], ["83977.90", "5.525998"], ["83969.40", "3.985966"], ["83960.90", "5.435408"], ["83952.40", "5.344818"], ["83943.90", "4.710687"], ["83935.40", "5.616588"], ["83926.90", "4.891867"], ["83918.40", "3.895376"], ["83909.90", "4.348327"], ["83901.40", "4.801277"], ["83892.90", "5.254228"], ["83884.40", "4.982457"], ["83875.90", "5.163638"], ["83867.40", "4.257736"], ["83858.90", "4.438917"], ["83663.95", "0.000022"]], "checksum": -411002751, "ts": "1742555029969"}], "ts": 1742555029972, "record_time": 1742555029.994766, "EXCHANGE": "BITGET"}
{"action": "update", "arg": {"instType": "SPOT", "channel": "books", "instId": "BTCUSDT"}, "data": [{"asks": [["84073.01", "1.498557"], ["84080.00", "0.096639"], ["84128.70", "0.001636"], ["84130.70", "0.004305"], ["84132.70", "0.011329"], ["84134.70", "0.029814"], ["84136.70", "0.078457"], ["84138.70", "0.206466"], ["84140.70", "0.543332"], ["84142.70", "1.429820"], ["84144.70", "3.762685"], ["84146.70", "9.901803"], ["84188.80", "4.710687"], ["84197.30", "3.985966"], ["84214.30", "4.348327"], ["84222.80", "4.257736"], ["84231.30", "4.438917"], ["84239.80", "5.525998"], ["84248.30", "5.344818"], ["84256.80", "4.167146"], ["84265.30", "5.073048"], ["84282.30", "4.801277"], ["84290.80", "5.616588"], ["84299.30", "4.620097"], ["84307.80", "4.891867"], ["84316.30", "5.254228"], ["84324.80", "4.529507"], ["84333.30", "3.895376"], ["84341.80", "4.076556"], ["84350.30", "4.982457"], ["84525.82", "0"]], "bids": [["84069.08", "0"], ["84058.30", "0"], ["84052.00", "0.012630"], ["84020.40", "3.895376"], ["84011.90", "4.529507"], ["84003.40", "3.985966"], ["83994.90", "4.801277"], ["83986.40", "4.438917"], ["83977.90", "5.163638"], ["83969.40", "4.348327"], ["83960.90", "4.620097"], ["83943.90", "4.167146"], ["83935.40", "4.076556"], ["83926.90", "5.073048"], ["83918.40", "4.257736"], ["83909.90", "5.254228"], ["83901.40", "4.710687"], ["83892.90", "4.982457"], ["83884.40", "4.891867"], ["83875.90", "5.435408"], ["83867.40", "5.525998"], ["83858.90", "5.616588"], ["83663.91", "0.000161"], ["83662.50", "0.000077"]], "checksum": 866990974, "ts": "1742555030177"}], "ts": 1742555030183, "record_time": 1742555030.205044, "EXCHANGE": "BITGET"}
{"action": "update", "arg": {"instType": "SPOT", "channel": "books", "instId": "BTCUSDT"}, "data": [{"asks": [["84146.70", "9.902045"], ["84188.80", "4.348327"], ["84197.30", "5.163638"], ["84205.80", "3.895376"], ["84214.30", "4.167146"], ["84222.80", "4.891867"], ["84231.30", "4.529507"], ["84239.80", "4.801277"], ["84248.30", "4.257736"], ["84256.80", "5.525998"], ["84265.30", "3.985966"], ["84273.80", "5.616588"], ["84282.30", "5.435408"], ["84290.80", "4.710687"], ["84299.30", "5.073048"], ["84307.80", "4.438917"], ["84316.30", "4.620097"], ["84324.80", "4.076556"], ["84333.30", "4.982457"], ["84341.80", "5.254228"], ["84350.30", "5.344818"]], "bids": [["84069.44", "0"], ["84069.21", "0.041076"], ["84066.50", "0.939652"], ["84064.50", "2.472768"], ["84062.50", "6.507284"], ["84062.40", "0.319260"], ["84062.20", "0.003480"], ["84062.10", "0.001013"], ["84061.90", "1.381110"], ["84061.70", "0"], ["84060.50", "0"], ["84056.50", "0.270000"], ["84052.20", "0.120930"], ["84052.00", "0.000032"], ["84020.40", "5.525998"], ["84011.90", "3.985966"], ["84003.40", "3.895376"], ["83994.90", "4.438917"], ["83986.40", "5.254228"], ["83969.40", "4.801277"], ["83960.90", "5.435408"], ["83952.40", "4.167146"], ["83943.90", "4.076556"], ["83935.40", "5.344818"], ["83926.90", "4.529507"], ["83909.90", "4.348327"], ["83892.90", "5.616588"], ["83884.40", "4.982457"], ["83875.90", "4.620097"], ["83867.40", "4.891867"], ["83858.90", "5.073048"]], "checksum": 1632723509, "ts": "1742555030387"}], "ts": 1742555030392, "record_time": 1742555030.42814, "EXCHANGE": "BITGET"}
{"action": "update", "arg": {"instType": "SPOT", "channel": "books", "instId": "BTCUSDT"}, "data": [{"asks": [["84101.11", "0.146373"], ["84102.81", "0"], ["84197.30", "4.529507"], ["84205.80", "5.344818"], ["84214.30", "5.073048"], ["84222.80", "4.620097"], ["84231.30", "3.985966"], ["84239.80", "4.891867"], ["84248.30", "5.163638"], ["84256.80", "4.982457"], ["84265.30", "3.895376"], ["84273.80", "5.254228"], ["84282.30", "4.167146"], ["84290.80", "4.257736"], ["84299.30", "4.710687"], ["84307.80", "5.525998"], ["84316.30", "4.076556"], ["84324.80", "4.801277"], ["84333.30", "4.438917"], ["84341.80", "5.435408"], ["84350.30", "5.616588"]], "bids": [["84070.32", "0.014104"], ["84062.20", "0.008880"], ["84056.70", "0.540600"], ["84020.40", "4.982457"], ["84011.90", "5.435408"], ["84003.40", "5.073048"], ["83994.90", "5.163638"], ["83986.40", "4.167146"], ["83977.90", "4.529507"], ["83969.40", "3.985966"], ["83960.90", "4.438917"], ["83952.40", "4.620097"], ["83943.90", "5.344818"], ["83935.40", "4.710687"], ["83926.90", "4.257736"], ["83918.40", "3.895376"], ["83909.90", "4.891867"], ["83901.40", "4.801277"], ["83892.90", "5.525998"], ["83884.40", "5.254228"], ["83875.90", "4.348327"], ["83867.40", "4.076556"], ["83858.90", "5.616588"], ["83662.50", "0"]], "checksum": -583717154, "ts": "1742555030601"}], "ts": 1742555030604, "record_time": 1742555030.674994, "EXCHANGE": "BITGET"}
{"action": "update", "arg": {"instType": "SPOT", "channel": "books", "instId": "BTCUSDT"}, "data": [{"asks": [["84073.01", "1.497052"], ["84144.70", "3.762791"], ["84148.20", "0.069810"], ["84150.90", "0.015000"], ["84158.10", "1.394880"], ["84159.00", "0"], ["84188.80", "4.891867"], ["84197.30", "5.073048"], ["84205.80", "5.525998"], ["84214.30", "4.620097"], ["84222.80", "4.348327"], ["84231.30", "4.710687"], ["84239.80", "4.801277"], ["84248.30", "4.076556"], ["84256.80", "5.254228"], ["84265.30", "5.435408"], ["84273.80", "4.167146"], ["84282.30", "4.982457"], ["84290.80", "4.529507"], ["84299.30", "5.163638"], ["84307.80", "5.344818"], ["84316.30", "5.616588"], ["84324.80", "4.438917"], ["84333.30", "3.985966"], ["84341.80", "4.257736"], ["84350.30", "3.895376"], ["84525.00", "0"]], "bids": [["84072.50", "0.048337"], ["84070.50", "0.127203"], ["84069.35", "0.041076"], ["84069.21", "0"], ["84068.50", "0.334745"], ["84066.50", "0.880644"], ["84064.50", "2.317484"], ["84062.50", "6.098642"], ["84062.20", "0.001028"], ["84062.10", "0.005610"], ["84059.90", "0.111270"], ["84059.60", "0.045540"], ["84020.40", "5.435408"], ["84011.90", "4.801277"], ["84003.40", "4.529507"], ["83994.90", "4.438917"], ["83986.40", "4.891867"], ["83977.90", "5.525998"], ["83969.40", "4.982457"], ["83960.90", "4.257736"], ["83952.40", "5.254228"], ["83943.90", "4.167146"], ["83935.40", "5.616588"], ["83926.90", "5.073048"], ["83918.40", "4.348327"], ["83909.90", "3.895376"], ["83901.40", "5.163638"], ["83892.90", "4.620097"], ["83884.40", "4.710687"], ["83875.90", "4.076556"], ["83867.40", "3.985966"], ["83858.90", "5.344818"]], "checksum": -1653163005, "ts": "1742555030807"}], "ts": 1742555030810, "record_time": 1742555030.865048, "EXCHANGE": "BITGET"}
{"action": "update", "arg": {"instType": "SPOT", "channel": "books", "instId": "BTCUSDT"}, "data": [{"asks": [["84123.62", "0"], ["84140.70", "0.543196"], ["84142.70", "1.429463"], ["84144.70", "3.761745"], ["84146.70", "9.899329"], ["84188.80", "5.073048"], ["84197.30", "4.891867"], ["84205.80", "4.620097"], ["84214.30", "3.985966"], ["84222.80", "5.525998"], ["84231.30", "5.163638"], ["84239.80", "5.344818"], ["84248.30", "5.616588"], ["84256.80", "4.167146"], ["84265.30", "4.076556"], ["84273.80", "4.438917"], ["84282.30", "4.529507"], ["84290.80", "4.710687"], ["84299.30", "5.435408"], ["84307.80", "3.895376"], ["84316.30", "4.801277"], ["84324.80", "4.982457"], ["84333.30", "5.254228"], ["84341.80", "4.348327"], ["84350.30", "4.257736"], ["84525.00", "0.003286"]], "bids": [["84073.00", "0.928554"], ["84072.50", "0.041688"], ["84070.50", "0.109706"], ["84068.50", "0.288699"], ["84066.50", "0.759736"], ["84064.50", "1.999304"], ["84062.50", "5.261326"], ["84062.10", "0"], ["84061.90", "1.382010"], ["84052.20", "0.589140"], ["84052.00", "0.012630"], ["84020.40", "5.344818"], ["84011.90", "5.616588"], ["84003.40", "4.076556"], ["83994.90", "4.710687"], ["83986.40", "4.348327"], ["83977.90", "5.073048"], ["83969.40", "4.891867"], ["83960.90", "5.254228"], ["83952.40", "4.620097"], ["83943.90", "3.985966"], ["83935.40", "4.167146"], ["83926.90", "4.529507"], ["83918.40", "5.435408"], ["83909.90", "4.801277"], ["83901.40", "5.525998"], ["83892.90", "4.982457"], ["83884.40", "4.257736"], ["83875.90", "5.163638"], ["83867.40", "4.438917"], ["83858.90", "3.895376"], ["83662.50", "0.000077"]], "checksum": 1151358035, "ts": "1742555031012"}], "ts": 1742555031017, "record_time": 1742555031.037499, "EXCHANGE": "BITGET"}
{"action": "update", "arg": {"instType": "SPOT", "channel": "books", "instId": "BTCUSDT"}, "data": [{"asks": [["84073.01", "1.706252"], ["84130.70", "0.004506"], ["84132.70", "0.011859"], ["84134.70", "0.031206"], ["84136.70", "0.082122"], ["84138.70", "0.216110"], ["84140.70", "0.568712"], ["84142.70", "1.496609"], ["84144.70", "3.938445"], ["84146.70", "10.364106"], ["84154.10", "2.096640"], ["84156.80", "2.890080"], ["84158.10", "0"], ["84188.80", "4.529507"], ["84197.30", "5.254228"], ["84205.80", "4.982457"], ["84214.30", "4.891867"], ["84222.80", "4.620097"], ["84231.30", "4.348327"], ["84239.80", "3.985966"], ["84248.30", "3.895376"], ["84256.80", "5.616588"], ["84265.30", "4.438917"], ["84273.80", "5.435408"], ["84282.30", "5.344818"], ["84290.80", "5.525998"], ["84299.30", "5.163638"], ["84307.80", "4.710687"], ["84316.30", "4.167146"], ["84324.80", "4.076556"], ["84333.30", "4.257736"], ["84341.80", "4.801277"], ["84350.30", "5.073048"], ["84525.82", "0.000099"]], "bids": [["84073.00", "0.916660"], ["84072.50", "0.024321"], ["84070.50", "0.064002"], ["84069.35", "0"], ["84068.50", "0.168425"], ["84066.50", "0.443226"], ["84064.50", "1.166382"], ["84062.51", "0"], ["84062.50", "3.069428"], ["84062.40", "0.001018"], ["84061.50", "0.363270"], ["84059.60", "0.066150"], ["84058.80", "0"], ["84057.10", "0.045540"], ["84052.50", "1.737360"], ["84052.30", "2.355600"], ["84052.00", "0.000032"], ["84020.40", "5.163638"], ["84011.90", "4.167146"], ["84003.40", "4.438917"], ["83986.40", "4.891867"], ["83977.90", "4.620097"], ["83969.40", "5.254228"], ["83960.90", "4.348327"], ["83952.40", "4.257736"], ["83943.90", "5.525998"], ["83935.40", "4.076556"], ["83926.90", "4.801277"], ["83918.40", "4.529507"], ["83909.90", "4.982457"], ["83901.40", "5.435408"], ["83892.90", "5.616588"], ["83884.40", "3.895376"], ["83875.90", "5.073048"], ["83867.40", "5.344818"], ["83858.90", "3.985966"], ["83661.97", "0.000052"]], "checksum": 1677250873, "ts": "1742555031219"}], "ts": 1742555031222, "record_time": 1742555031.249397, "EXCHANGE": "BITGET"}
{"action": "update", "arg": {"instType": "SPOT", "channel": "books", "instId": "BTCUSDT"}, "data": [{"asks": [["84188.80", "5.163638"], ["84197.30", "3.985966"], ["84205.80", "5.344818"], ["84214.30", "4.167146"], ["84222.80", "4.710687"], ["84231.30", "4.438917"], ["84239.80", "5.435408"], ["84248.30", "5.254228"], ["84256.80", "4.982457"], ["84265.30", "5.616588"], ["84273.80", "4.257736"], ["84282.30", "5.073048"], ["84290.80", "4.620097"], ["84299.30", "4.076556"], ["84307.80", "4.348327"], ["84316.30", "4.801277"], ["84324.80", "5.525998"], ["84333.30", "3.895376"], ["84341.80", "4.891867"], ["84350.30", "4.529507"]], "bids": [["84070.51", "0.075610"], ["84070.32", "0"], ["84069.49", "0.041076"], ["84069.17", "0.014104"], ["84066.51", "0.489348"], ["84020.40", "4.710687"], ["84011.90", "4.982457"], ["84003.40", "3.985966"], ["83994.90", "3.895376"], ["83986.40", "5.344818"], ["83977.90", "4.257736"], ["83952.40", "5.163638"], ["83943.90", "4.529507"], ["83935.40", "4.620097"], ["83926.90", "5.073048"], ["83918.40", "4.438917"], ["83909.90", "4.801277"], ["83884.40", "4.167146"], ["83875.90", "4.891867"], ["83867.40", "4.076556"], ["83858.90", "5.525998"], ["83661.97", "0"]], "checksum": 658431462, "ts": "1742555031420"}], "ts": 1742555031424, "record_time": 1742555031.47758, "EXCHANGE": "BITGET"}
{"action": "update", "arg": {"instType": "SPOT", "channel": "books", "instId": "BTCUSDT"}, "data": [{"asks": [["84105.36", "0.012313"], ["84156.80", "0.320940"], ["84158.10", "1.394880"], ["84188.80", "5.254228"], ["84197.30", "5.344818"], ["84205.80", "4.257736"], ["84214.30", "5.525998"], ["84231.30", "4.076556"], ["84239.80", "4.801277"], ["84248.30", "5.073048"], ["84256.80", "4.620097"], ["84265.30", "3.985966"], ["84273.80", "4.167146"], ["84282.30", "4.982457"], ["84290.80", "5.616588"], ["84299.30", "5.435408"], ["84316.30", "4.529507"], ["84324.80", "3.895376"], ["84333.30", "4.891867"], ["84341.80", "4.438917"], ["84350.30", "5.163638"], ["84525.82", "0"]], "bids": [["84072.50", "0.032373"], ["84070.50", "0.085192"], ["84068.50", "0.224189"], ["84066.50", "0.589972"], ["84064.50", "1.552557"], ["84062.51", "1.677811"], ["84062.50", "4.085676"], ["84052.30", "0"], ["84052.00", "0.012630"], ["84020.40", "5.073048"], ["84003.40", "5.435408"], ["83994.90", "4.076556"], ["83986.40", "5.254228"], ["83977.90", "4.710687"], ["83969.40", "4.801277"], ["83960.90", "5.163638"], ["83952.40", "4.620097"], ["83943.90", "4.257736"], ["83935.40", "5.525998"], ["83926.90", "3.985966"], ["83909.90", "4.348327"], ["83901.40", "3.895376"], ["83892.90", "4.891867"], ["83884.40", "4.529507"], ["83875.90", "5.344818"], ["83867.40", "5.616588"], ["83858.90", "4.167146"]], "checksum": -604575758, "ts": "1742555031659"}], "ts": 1742555031664, "record_time": 1742555031.724177, "EXCHANGE": "BITGET"}
{"action": "update", "arg": {"instType": "SPOT", "channel": "books", "instId": "BTCUSDT"}, "data": [{"asks": [["84154.10", "1.146840"], ["84188.80", "5.525998"], ["84197.30", "4.348327"], ["84205.80", "5.163638"], ["84214.30", "5.344818"], ["84222.80", "4.438917"], ["84231.30", "4.710687"], ["84239.80", "4.891867"], ["84248.30", "5.616588"], ["84265.30", "5.254228"], ["84273.80", "4.801277"], ["84282.30", "4.257736"], ["84290.80", "3.985966"], ["84299.30", "4.076556"], ["84307.80", "3.895376"], ["84316.30", "4.982457"], ["84324.80", "5.073048"], ["84333.30", "4.529507"], ["84341.80", "5.435408"], ["84350.30", "4.167146"]], "bids": [["84072.50", "0.033050"], ["84070.81", "0.014104"], ["84070.51", "0.109597"], ["84070.50", "0.086974"], ["84069.61", "0.041076"], ["84069.49", "0"], ["84069.17", "0"], ["84068.50", "0.228880"], ["84066.50", "0.602316"], ["84064.50", "1.585041"], ["84062.50", "4.171162"], ["84020.40", "3.985966"], ["84011.90", "4.529507"], ["84003.40", "4.620097"], ["83994.90", "5.525998"], ["83986.40", "4.891867"], ["83977.90", "3.895376"], ["83969.40", "4.710687"], ["83960.90", "4.982457"], ["83952.40", "4.167146"], ["83943.90", "4.438917"], ["83935.40", "5.616588"], ["83926.90", "4.348327"], ["83918.40", "4.801277"], ["83909.90", "4.076556"], ["83901.40", "5.435408"], ["83892.90", "5.163638"], ["83884.40", "4.257736"], ["83867.40", "5.073048"], ["83858.90", "5.254228"]], "checksum": -294566151, "ts": "1742555031861"}], "ts": 1742555031864, "record_time": 1742555031.913803, "EXCHANGE": "BITGET"}
{"action": "update", "arg": {"instType": "SPOT", "channel": "books", "instId": "BTCUSDT"}, "data": [{"asks": [["84188.80", "5.344818"], ["84197.30", "4.710687"], ["84205.80", "5.435408"], ["84214.30", "5.254228"], ["84222.80", "5.525998"], ["84231.30", "3.895376"], ["84239.80", "5.073048"], ["84248.30", "4.348327"], ["84256.80", "3.985966"], ["84265.30", "4.891867"], ["84273.80", "4.620097"], ["84282.30", "4.982457"], ["84290.80", "4.438917"], ["84299.30", "5.163638"], ["84307.80", "4.167146"], ["84316.30", "5.616588"], ["84324.80", "4.529507"], ["84333.30", "4.257736"], ["84341.80", "4.076556"], ["84350.30", "4.801277"]], "bids": [["84066.50", "0.602213"], ["84064.50", "1.584773"], ["84062.50", "4.170455"], ["84059.60", "0"], ["84057.78", "0.007878"], ["84051.50", "1.350000"], ["84020.40", "5.435408"], ["84011.90", "4.167146"], ["84003.40", "5.525998"], ["83994.90", "4.348327"], ["83986.40", "3.895376"], ["83977.90", "4.891867"], ["83969.40", "4.257736"], ["83960.90", "4.076556"], ["83952.40", "3.985966"], ["83943.90", "4.982457"], ["83935.40", "5.254228"], ["83926.90", "5.163638"], ["83918.40", "4.710687"], ["83909.90", "5.073048"], ["83901.40", "4.801277"], ["83892.90", "4.438917"], ["83884.40", "4.620097"], ["83875.90", "4.529507"], ["83867.40", "5.616588"], ["83858.90", "5.344818"]], "checksum": -294566151, "ts": "1742555032064"}], "ts": 1742555032067, "record_time": 1742555032.095023, "EXCHANGE": "BITGET"}
{"action": "update", "arg": {"instType": "SPOT", "channel": "books", "instId": "BTCUSDT"}, "data": [{"asks": [["84144.70", "3.938275"], ["84146.70", "10.363883"], ["84188.80", "4.529507"], ["84197.30", "4.167146"], ["84205.80", "5.073048"], ["84214.30", "3.895376"], ["84222.80", "5.254228"], ["84231.30", "4.620097"], ["84239.80", "5.163638"], ["84248.30", "5.435408"], ["84256.80", "5.344818"], ["84265.30", "4.257736"], ["84273.80", "4.348327"], ["84282.30", "5.525998"], ["84290.80", "4.982457"], ["84299.30", "3.985966"], ["84307.80", "5.616588"], ["84316.30", "4.438917"], ["84324.80", "4.801277"], ["84333.30", "4.076556"], ["84341.80", "4.710687"], ["84350.30", "4.891867"]], "bids": [["84073.00", "1.058678"], ["84069.61", "0"], ["84066.50", "0.602458"], ["84064.50", "1.585543"], ["84062.50", "4.172482"], ["84058.30", "0.015000"], ["84051.50", "0"], ["84020.40", "4.167146"], ["84011.90", "4.076556"], ["84003.40", "4.529507"], ["83994.90", "5.616588"], ["83986.40", "4.982457"], ["83977.90", "5.344818"], ["83969.40", "4.801277"], ["83960.90", "5.163638"], ["83952.40", "3.895376"], ["83943.90", "4.438917"], ["83935.40", "4.891867"], ["83926.90", "5.525998"], ["83918.40", "5.435408"], ["83909.90", "3.985966"], ["83901.40", "4.348327"], ["83892.90", "4.710687"], ["83884.40", "5.254228"], ["83875.90", "4.620097"], ["83867.40", "4.257736"], ["83858.90", "5.073048"], ["83661.97", "0.000052"]], "checksum": 1032265387, "ts": "1742555032264"}], "ts": 1742555032274, "record_time": 1742555032.296084, "EXCHANGE": "BITGET"}
{"action": "update", "arg": {"instType": "SPOT", "channel": "books", "instId": "BTCUSDT"}, "data": [{"asks": [["84188.80", "5.073048"], ["84197.30", "4.348327"], ["84205.80", "4.620097"], ["84214.30", "4.167146"], ["84222.80", "4.529507"], ["84231.30", "4.438917"], ["84239.80", "5.254228"], ["84248.30", "5.163638"], ["84256.80", "4.076556"], ["84265.30", "5.616588"], ["84273.80", "5.435408"], ["84290.80", "4.891867"], ["84299.30", "4.257736"], ["84307.80", "4.982457"], ["84316.30", "3.985966"], ["84324.80", "3.895376"], ["84333.30", "4.801277"], ["84350.30", "5.344818"]], "bids": [["84072.50", "0.032851"], ["84070.50", "0.086448"], ["84069.72", "0.041076"], ["84068.50", "0.227496"], ["84066.50", "0.598674"], ["84064.50", "1.575457"], ["84062.50", "4.145940"], ["84058.70", "0.070560"], ["84052.20", "0.120930"], ["84052.00", "0.000032"], ["84011.90", "5.254228"], ["84003.40", "4.620097"], ["83994.90", "5.525998"], ["83986.40", "5.435408"], ["83977.90", "4.891867"], ["83960.90", "3.985966"], ["83952.40", "5.616588"], ["83943.90", "4.529507"], ["83935.40", "4.710687"], ["83926.90", "4.257736"], ["83918.40", "5.163638"], ["83909.90", "4.076556"], ["83901.40", "4.438917"], ["83892.90", "4.982457"], ["83884.40", "5.073048"], ["83875.90", "5.344818"], ["83867.40", "4.348327"], ["83858.90", "3.895376"], ["83662.50", "0"], ["83661.97", "0"]], "checksum": -205463237, "ts": "1742555032482"}], "ts": 1742555032486, "record_time": 1742555032.519765, "EXCHANGE": "BITGET"}
{"action": "update", "arg": {"instType": "SPOT", "channel": "books", "instId": "BTCUSDT"}, "data": [{"asks": [["84140.70", "0.568594"], ["84142.70", "1.496301"], ["84144.70", "3.937753"], ["84146.70", "10.362506"], ["84197.30", "5.525998"], ["84205.80", "5.163638"], ["84214.30", "3.895376"], ["84222.80", "4.891867"], ["84231.30", "3.985966"], ["84239.80", "4.167146"], ["84248.30", "5.344818"], ["84256.80", "5.254228"], ["84265.30", "4.982457"], ["84273.80", "4.620097"], ["84282.30", "4.257736"], ["84290.80", "5.616588"], ["84299.30", "4.348327"], ["84307.80", "5.435408"], ["84316.30", "4.438917"], ["84324.80", "4.801277"], ["84333.30", "4.076556"], ["84350.30", "4.529507"]], "bids": [["84068.50", "0.227371"], ["84066.50", "0.598346"], ["84064.50", "1.574595"], ["84062.50", "4.143671"], ["84020.40", "4.620097"], ["84011.90", "5.525998"], ["84003.40", "4.167146"], ["83994.90", "5.163638"], ["83986.40", "4.438917"], ["83977.90", "4.076556"], ["83969.40", "4.529507"], ["83960.90", "5.344818"], ["83952.40", "5.073048"], ["83943.90", "3.895376"], ["83935.40", "4.982457"], ["83926.90", "4.348327"], ["83918.40", "5.254228"], ["83909.90", "4.891867"], ["83901.40", "4.801277"], ["83892.90", "5.616588"], ["83884.40", "4.710687"], ["83875.90", "3.985966"], ["83867.40", "5.435408"], ["83858.90", "4.257736"]], "checksum": -1728528359, "ts": "1742555032694"}], "ts": 1742555032697, "record_time": 1742555032.779055, "EXCHANGE": "BITGET"}
{"action": "update", "arg": {"instType": "SPOT", "channel": "books", "instId": "BTCUSDT"}, "data": [{"asks": [["84144.70", "3.937562"], ["84146.70", "10.362004"], ["84188.80", "5.344818"], ["84197.30", "5.254228"], ["84205.80", "3.895376"], ["84214.30", "4.620097"], ["84222.80", "4.982457"], ["84231.30", "5.073048"], ["84239.80", "5.525998"], ["84248.30", "4.891867"], ["84256.80", "5.616588"], ["84265.30", "4.257736"], ["84273.80", "5.435408"], ["84282.30", "3.985966"], ["84290.80", "4.529507"], ["84299.30", "4.710687"], ["84307.80", "4.076556"], ["84316.30", "4.348327"], ["84333.30", "4.167146"], ["84341.80", "4.438917"], ["84350.30", "5.163638"]], "bids": [["84073.00", "1.057173"], ["84072.50", "0.032992"], ["84070.50", "0.086822"], ["84069.84", "0.041076"], ["84069.72", "0"], ["84068.50", "0.228479"], ["84066.50", "0.601260"], ["84064.50", "1.582264"], ["84062.50", "4.163852"], ["84062.20", "0.456300"], ["84061.90", "1.381110"], ["84061.50", "0.071280"], ["84052.20", "0"], ["84020.40", "4.257736"], ["84011.90", "4.982457"], ["84003.40", "5.163638"], ["83994.90", "4.801277"], ["83986.40", "4.076556"], ["83977.90", "4.438917"], ["83969.40", "3.985966"], ["83960.90", "5.073048"], ["83952.40", "5.344818"], ["83943.90", "5.254228"], ["83935.40", "4.348327"], ["83926.90", "5.435408"], ["83918.40", "5.616588"], ["83909.90", "4.529507"], ["83901.40", "4.710687"], ["83892.90", "4.891867"], ["83884.40", "5.525998"], ["83875.90", "4.620097"], ["83867.40", "4.167146"], ["83858.90", "3.895376"], ["83662.50", "0.000077"]], "checksum": -794190613, "ts": "1742555032897"}], "ts": 1742555032900, "record_time": 1742555032.972959, "EXCHANGE": "BITGET"}
{"action": "update", "arg": {"instType": "SPOT", "channel": "books", "instId": "BTCUSDT"}, "data": [{"asks": [["84073.01", "1.497052"], ["84090.92", "0"], ["84091.38", "0"], ["84091.79", "0.035952"], ["84092.23", "0.119870"], ["84092.65", "0"], ["84093.04", "0"], ["84093.21", "0"], ["84093.50", "0.035961"], ["84093.54", "0"], ["84093.88", "0.006356"], ["84094.05", "0.006356"], ["84094.39", "0.006356"], ["84094.67", "0"], ["84094.79", "0"], ["84094.96", "0"], ["84095.52", "0.010984"], ["84095.59", "0"], ["84095.73", "0.006356"], ["84095.90", "0.006356"], ["84096.01", "0"], ["84096.08", "0"], ["84096.44", "0.006356"], ["84096.48", "0"], ["84096.56", "0"], ["84096.88", "0.006356"], ["84096.93", "0.006356"], ["84097.41", "0.006356"], ["84097.42", "0.006356"], ["84098.10", "0"], ["84098.95", "0.006357"], ["84106.06", "0"], ["84106.93", "0.010988"], ["84123.29", "0.010000"], ["84128.70", "0.001639"], ["84130.70", "0.004313"], ["84132.70", "0.011350"], ["84134.70", "0.029869"], ["84136.70", "0.078601"], ["84138.70", "0.206845"], ["84140.70", "0.544329"], ["84142.70", "1.432444"], ["84144.70", "3.769591"], ["84146.70", "9.919975"], ["84148.20", "0"], ["84158.10", "1.462680"], ["84188.80", "3.895376"], ["84197.30", "4.982457"], ["84205.80", "4.076556"], ["84214.30", "4.801277"], ["84222.80", "4.710687"], ["84231.30", "4.620097"], ["84239.80", "4.257736"], ["84248.30", "3.985966"], ["84256.80", "4.348327"], ["84265.30", "5.073048"], ["84273.80", "5.163638"], ["84282.30", "5.254228"], ["84290.80", "5.525998"], ["84299.30", "4.529507"], ["84307.80", "5.435408"], ["84316.30", "4.438917"], ["84324.80", "4.891867"], ["84341.80", "5.344818"], ["84350.30", "5.616588"]], "bids": [["84073.00", "1.266373"], ["84072.50", "0.035733"], ["84070.50", "0.094035"], ["84068.50", "0.247459"], ["84066.50", "0.651209"], ["84064.50", "1.713707"], ["84062.50", "4.509756"], ["84056.70", "1.172340"], ["84056.40", "2.355510"], ["84052.50", "0"], ["84051.43", "0.089474"], ["84051.04", "0.247559"], ["84050.56", "0"], ["84050.19", "0"], ["84049.78", "0.083930"], ["84049.33", "0.017815"], ["84049.16", "0.018253"], ["84048.93", "0"], ["84048.82", "0.005945"], ["84048.48", "0"], ["84048.31", "0"], ["84047.98", "0"], ["84047.77", "0.055649"], ["84047.48", "0.017101"], ["84047.31", "0.007131"], ["84046.92", "0"], ["84046.84", "0.007339"], ["84046.53", "0"], ["84046.36", "0"], ["84046.32", "0.008993"], ["84046.27", "0.007942"], ["84045.99", "0"], ["84045.80", "0.017349"], ["84045.79", "0.008184"], ["84045.47", "0"], ["84045.40", "0"], ["84044.94", "0"], ["84044.86", "0"], ["84044.30", "0.012654"], ["84043.45", "0"], ["84036.31", "0.056361"], ["84035.44", "0"], ["84034.64", "0.000876"], ["84033.79", "0"], ["84020.40", "5.254228"], ["84011.90", "5.616588"], ["84003.40", "5.073048"], ["83994.90", "5.525998"], ["83986.40", "4.348327"], ["83977.90", "4.801277"], ["83969.40", "5.435408"], ["83960.90", "4.891867"], ["83943.90", "4.620097"], ["83935.40", "4.167146"], ["83926.90", "4.438917"], ["83918.40", "3.895376"], ["83909.90", "4.710687"], ["83901.40", "4.076556"], ["83892.90", "3.985966"], ["83884.40", "5.163638"], ["83875.90", "4.529507"], ["83867.40", "4.257736"], ["83858.90", "4.982457"]], "checksum": 1617347822, "ts": "1742555033099"}], "ts": 1742555033105, "record_time": 1742555033.127536, "EXCHANGE": "BITGET"}
{"action": "update", "arg": {"instType": "SPOT", "channel": "books", "instId": "BTCUSDT"}, "data": [{"asks": [["84123.28", "0.003000"], ["84128.70", "0.001501"], ["84130.70", "0.003949"], ["84132.70", "0.010392"], ["84134.70", "0.027349"], ["84136.70", "0.071971"], ["84138.70", "0.189398"], ["84140.70", "0.498414"], ["84142.70", "1.311617"], ["84144.70", "3.451622"], ["84146.70", "9.083217"], ["84155.30", "0"], ["84159.00", "0.024930"], ["84188.80", "5.163638"], ["84197.30", "3.895376"], ["84200.77", "0"], ["84205.80", "5.616588"], ["84209.19", "0"], ["84214.30", "5.344818"], ["84231.30", "3.985966"], ["84239.80", "4.438917"], ["84248.30", "4.891867"], ["84256.80", "4.167146"], ["84273.80", "4.801277"], ["84282.30", "5.435408"], ["84290.80", "4.982457"], ["84299.30", "5.525998"], ["84307.80", "4.076556"], ["84316.30", "4.257736"], ["84324.80", "4.529507"], ["84333.30", "4.620097"], ["84341.80", "5.254228"], ["84350.30", "4.348327"], ["84525.82", "0.000099"]], "bids": [["84073.00", "1.146273"], ["84072.50", "0.033449"], ["84070.50", "0.088025"], ["84069.84", "0"], ["84068.50", "0.231643"], ["84066.50", "0.609586"], ["84064.50", "1.604174"], ["84062.50", "4.221512"], ["84058.60", "0.022830"], ["84057.78", "0.029710"], ["84056.90", "0"], ["84020.40", "4.620097"], ["84011.90", "4.167146"], ["84007.26", "0"], ["84003.40", "5.163638"], ["83998.86", "0"], ["83994.90", "4.438917"], ["83986.40", "4.076556"], ["83977.90", "4.529507"], ["83969.40", "4.348327"], ["83960.90", "5.435408"], ["83952.40", "5.616588"], ["83943.90", "5.073048"], ["83935.40", "4.982457"], ["83926.90", "5.525998"], ["83918.40", "5.344818"], ["83909.90", "5.254228"], ["83901.40", "4.257736"], ["83892.90", "4.710687"], ["83884.40", "3.985966"], ["83875.90", "3.895376"], ["83867.40", "4.891867"], ["83858.90", "4.801277"], ["83661.97", "0.000052"], ["83661.60", "0.000042"], ["83661.08", "0.004152"]], "checksum": -1016182711, "ts": "1742555033306"}], "ts": 1742555033310, "record_time": 1742555033.331506, "EXCHANGE": "BITGET"}
{"action": "update", "arg": {"instType": "SPOT", "channel": "books", "instId": "BTCUSDT"}, "data": [{"asks": [["84130.70", "0.003810"], ["84132.70", "0.010027"], ["84134.70", "0.026387"], ["84136.70", "0.069438"], ["84138.70", "0.182733"], ["84140.70", "0.480876"], ["84142.70", "1.265463"], ["84144.70", "3.330166"], ["84146.70", "8.763595"], ["84148.60", "0.071160"], ["84159.00", "0"], ["84188.80", "5.073048"], ["84193.56", "0.001810"], ["84197.30", "4.891867"], ["84201.98", "0.003620"], ["84205.80", "4.076556"], ["84214.30", "3.985966"], ["84222.80", "5.435408"], ["84231.30", "4.529507"], ["84239.80", "5.525998"], ["84248.30", "4.982457"], ["84256.80", "4.257736"], ["84265.30", "4.801277"], ["84273.80", "5.344818"], ["84282.30", "5.616588"], ["84290.80", "4.710687"], ["84299.30", "3.895376"], ["84307.80", "5.254228"], ["84316.30", "4.438917"], ["84324.80", "4.348327"], ["84333.30", "4.167146"], ["84341.80", "4.620097"], ["84350.30", "5.163638"], ["84525.00", "0"], ["84525.82", "0"]], "bids": [["84072.50", "0.034614"], ["84070.50", "0.091089"], ["84069.96", "0.041076"], ["84068.50", "0.239709"], ["84066.50", "0.630812"], ["84064.50", "1.660033"], ["84062.50", "4.368508"], ["84056.70", "3.527820"], ["84056.40", "0"], ["84020.40", "4.710687"], ["84011.90", "5.163638"], ["84003.40", "5.525998"], ["83994.90", "4.620097"], ["83994.33", "0.001810"], ["83985.93", "0.003620"], ["83977.90", "4.438917"], ["83969.40", "3.985966"], ["83960.90", "5.344818"], ["83952.40", "3.895376"], ["83943.90", "5.616588"], ["83935.40", "4.257736"], ["83926.90", "4.348327"], ["83918.40", "4.801277"], ["83909.90", "5.435408"], ["83901.40", "4.167146"], ["83892.90", "4.529507"], ["83884.40", "4.982457"], ["83875.90", "5.254228"], ["83867.40", "5.073048"], ["83858.90", "4.891867"], ["83661.60", "0"], ["83661.08", "0"]], "checksum": 821168251, "ts": "1742555033506"}], "ts": 1742555033510, "record_time": 1742555033.531636, "EXCHANGE": "BITGET"}
{"action": "update", "arg": {"instType": "SPOT", "channel": "books", "instId": "BTCUSDT"}, "data": [{"asks": [["84128.70", "0.001641"], ["84130.70", "0.004318"], ["84132.70", "0.011362"], ["84134.70", "0.029900"], ["84136.70", "0.078685"], ["84138.70", "0.207066"], ["84140.70", "0.544911"], ["84142.70", "1.433976"], ["84144.70", "3.773619"], ["84146.70", "9.930577"], ["84148.60", "0"], ["84149.00", "0.001027"], ["84157.20", "2.569140"], ["84188.80", "3.985966"], ["84197.30", "4.801277"], ["84205.80", "5.525998"], ["84214.30", "4.257736"], ["84222.80", "3.895376"], ["84231.30", "4.348327"], ["84239.80", "4.982457"], ["84248.30", "5.435408"], ["84256.80", "5.254228"], ["84265.30", "4.438917"], ["84273.80", "5.073048"], ["84282.30", "4.710687"], ["84290.80", "4.620097"], ["84299.30", "4.891867"], ["84307.80", "4.529507"], ["84316.30", "5.616588"], ["84324.80", "5.344818"], ["84341.80", "4.076556"], ["84524.83", "0"]], "bids": [["84056.70", "1.172340"], ["84052.70", "2.355600"], ["84020.40", "4.620097"], ["84011.90", "5.254228"], ["83994.90", "4.348327"], ["83986.40", "4.801277"], ["83977.90", "5.163638"], ["83969.40", "4.710687"], ["83960.90", "4.891867"], ["83952.40", "4.982457"], ["83943.90", "4.257736"], ["83935.40", "4.076556"], ["83926.90", "4.438917"], ["83918.40", "5.344818"], ["83909.90", "4.167146"], ["83901.40", "5.073048"], ["83892.90", "5.435408"], ["83884.40", "4.529507"], ["83875.90", "3.985966"], ["83867.40", "5.616588"], ["83858.90", "3.895376"], ["83661.97", "0"]], "checksum": 821168251, "ts": "1742555033715"}], "ts": 1742555033718, "record_time": 1742555033.822884, "EXCHANGE": "BITGET"}
{"action": "update", "arg": {"instType": "SPOT", "channel": "books", "instId": "BTCUSDT"}, "data": [{"asks": [["84144.70", "3.773853"], ["84146.70", "9.931191"], ["84149.00", "0"], ["84154.10", "2.085360"], ["84157.20", "0"], ["84159.00", "0.024930"], ["84188.80", "4.348327"], ["84197.30", "4.529507"], ["84214.30", "5.616588"], ["84222.80", "4.982457"], ["84231.30", "3.895376"], ["84239.80", "4.710687"], ["84248.30", "3.985966"], ["84256.80", "5.344818"], ["84265.30", "5.073048"], ["84273.80", "5.163638"], ["84282.30", "4.438917"], ["84290.80", "5.435408"], ["84299.30", "4.620097"], ["84307.80", "4.257736"], ["84316.30", "4.891867"], ["84324.80", "5.254228"], ["84350.30", "4.801277"], ["84524.83", "0.000009"]], "bids": [["84072.50", "0.031908"], ["84070.50", "0.083969"], ["84069.96", "0"], ["84068.50", "0.220971"], ["84066.50", "0.581503"], ["84064.50", "1.530272"], ["84062.50", "4.027030"], ["84060.90", "0.063000"], ["84055.90", "2.423310"], ["84052.70", "0"], ["84020.40", "5.435408"], ["84011.90", "4.348327"], ["84003.40", "4.891867"], ["83994.90", "5.073048"], ["83986.40", "4.620097"], ["83977.90", "3.895376"], ["83969.40", "4.982457"], ["83960.90", "4.529507"], ["83952.40", "5.525998"], ["83943.90", "4.438917"], ["83935.40", "3.985966"], ["83926.90", "5.344818"], ["83918.40", "4.801277"], ["83909.90", "5.163638"], ["83901.40", "4.257736"], ["83892.90", "5.616588"], ["83884.40", "4.710687"], ["83875.90", "4.076556"], ["83867.40", "5.254228"], ["83858.90", "4.167146"], ["83661.97", "0.000052"]], "checksum": -1900150404, "ts": "1742555033920"}], "ts": 1742555033924, "record_time": 1742555034.015591, "EXCHANGE": "BITGET"}
{"action": "update", "arg": {"instType": "SPOT", "channel": "books", "instId": "BTCUSDT"}, "data": [{"asks": [["84128.70", "0.001503"], ["84130.70", "0.003955"], ["84132.70", "0.010407"], ["84134.70", "0.027389"], ["84136.70", "0.072076"], ["84138.70", "0.189673"], ["84140.70", "0.499139"], ["84142.70", "1.313523"], ["84144.70", "3.456641"], ["84146.70", "9.096423"], ["84147.50", "0.071430"], ["84150.30", "0.143250"], ["84154.10", "1.146840"], ["84159.00", "0"], ["84188.80", "4.891867"], ["84197.30", "4.257736"], ["84205.80", "4.982457"], ["84214.30", "5.525998"], ["84222.80", "4.529507"], ["84231.30", "5.435408"], ["84239.80", "4.801277"], ["84248.30", "4.710687"], ["84256.80", "5.254228"], ["84265.30", "3.985966"], ["84273.80", "5.344818"], ["84282.30", "4.167146"], ["84290.80", "5.616588"], ["84299.30", "5.073048"], ["84307.80", "4.076556"], ["84316.30", "4.348327"], ["84324.80", "4.438917"], ["84333.30", "5.163638"], ["84341.80", "4.620097"], ["84350.30", "3.895376"]], "bids": [["84070.07", "0.041076"], ["84055.90", "0.067800"], ["84054.00", "2.355570"], ["84020.40", "4.529507"], ["84011.90", "4.257736"], ["84003.40", "5.254228"], ["83986.40", "4.167146"], ["83977.90", "3.985966"], ["83969.40", "5.435408"], ["83960.90", "4.982457"], ["83952.40", "5.163638"], ["83935.40", "5.616588"], ["83926.90", "4.801277"], ["83918.40", "4.076556"], ["83909.90", "4.891867"], ["83901.40", "4.710687"], ["83892.90", "4.620097"], ["83884.40", "3.895376"], ["83875.90", "5.525998"], ["83867.40", "5.344818"], ["83858.90", "4.348327"], ["83661.97", "0"]], "checksum": 1469665207, "ts": "1742555034124"}], "ts": 1742555034127, "record_time": 1742555034.161323, "EXCHANGE": "BITGET"}
{"action": "update", "arg": {"instType": "SPOT", "channel": "books", "instId": "BTCUSDT"}, "data": [{"asks": [["84130.70", "0.003957"], ["84132.70", "0.010412"], ["84134.70", "0.027400"], ["84136.70", "0.072107"], ["84138.70", "0.189754"], ["84140.70", "0.499353"], ["84142.70", "1.314088"], ["84144.70", "3.458125"], ["84146.70", "9.100329"], ["84188.80", "4.982457"], ["84197.30", "3.895376"], ["84205.80", "4.620097"], ["84214.30", "4.076556"], ["84222.80", "4.257736"], ["84231.30", "3.985966"], ["84239.80", "5.254228"], ["84248.30", "5.344818"], ["84256.80", "4.891867"], ["84265.30", "4.710687"], ["84273.80", "5.616588"], ["84282.30", "4.529507"], ["84290.80", "4.438917"], ["84299.30", "4.167146"], ["84307.80", "4.801277"], ["84316.30", "5.163638"], ["84324.80", "5.073048"], ["84333.30", "5.435408"], ["84341.80", "4.348327"], ["84350.30", "5.525998"]], "bids": [["84073.00", "1.160296"], ["84072.50", "0.034615"], ["84070.50", "0.091092"], ["84068.50", "0.239587"], ["84066.50", "0.630490"], ["84064.50", "1.659184"], ["84062.50", "4.366276"], ["84062.30", "0.361140"], ["84062.20", "0.001040"], ["84062.10", "0.016140"], ["84060.90", "0"], ["84057.70", "0"], ["84056.70", "0.540600"], ["84055.70", "2.385510"], ["84054.00", "0.000032"], ["84020.40", "3.895376"], ["84011.90", "3.985966"], ["84003.40", "4.438917"], ["83994.90", "4.076556"], ["83986.40", "4.891867"], ["83977.90", "4.348327"], ["83969.40", "4.710687"], ["83960.90", "5.344818"], ["83943.90", "5.525998"], ["83926.90", "4.167146"], ["83918.40", "4.257736"], ["83909.90", "4.982457"], ["83901.40", "5.254228"], ["83892.90", "5.073048"], ["83884.40", "4.620097"], ["83875.90", "4.529507"], ["83867.40", "5.435408"], ["83858.90", "4.801277"]], "checksum": -2053551521, "ts": "1742555034324"}], "ts": 1742555034327, "record_time": 1742555034.348086, "EXCHANGE": "BITGET"}
{"action": "update", "arg": {"instType": "SPOT", "channel": "books", "instId": "BTCUSDT"}, "data": [{"asks": [["84073.01", "1.495547"], ["84130.70", "0.003811"], ["84132.70", "0.010028"], ["84134.70", "0.026388"], ["84136.70", "0.069443"], ["84138.70", "0.182746"], ["84140.70", "0.480910"], ["84142.70", "1.265552"], ["84144.70", "3.330399"], ["84146.70", "8.764208"], ["84188.80", "4.620097"], ["84197.30", "4.076556"], ["84203.88", "0.125588"], ["84205.80", "5.163638"], ["84211.43", "0"], ["84214.30", "4.257736"], ["84222.80", "5.073048"], ["84231.30", "5.616588"], ["84239.80", "4.801277"], ["84248.30", "5.254228"], ["84256.80", "4.348327"], ["84265.30", "4.982457"], ["84273.80", "5.435408"], ["84282.30", "5.525998"], ["84290.80", "3.985966"], ["84299.30", "3.895376"], ["84307.80", "4.438917"], ["84316.30", "4.891867"], ["84324.80", "4.710687"], ["84333.30", "5.344818"], ["84341.80", "4.529507"], ["84350.30", "4.167146"]], "bids": [["84072.50", "0.034578"], ["84070.50", "0.090994"], ["84070.18", "0.041076"], ["84070.07", "0"], ["84068.50", "0.239459"], ["84066.50", "0.630154"], ["84064.50", "1.658301"], ["84062.50", "4.363951"], ["84062.30", "0.361350"], ["84062.10", "0"], ["84056.70", "1.172340"], ["84052.50", "1.737360"], ["84052.20", "0.120930"], ["84021.00", "0.000015"], ["84020.40", "5.525998"], ["84011.90", "4.801277"], ["84003.40", "4.710687"], ["83977.90", "3.985966"], ["83969.40", "4.438917"], ["83960.90", "5.254228"], ["83952.40", "5.073048"], ["83943.90", "4.167146"], ["83935.40", "5.163638"], ["83926.90", "4.529507"], ["83918.40", "5.616588"], ["83901.40", "4.257736"], ["83892.90", "5.344818"], ["83875.90", "5.435408"], ["83867.40", "3.895376"], ["83858.90", "4.348327"], ["83662.50", "0"]], "checksum": 993606535, "ts": "1742555034537"}], "ts": 1742555034540, "record_time": 1742555034.562587, "EXCHANGE": "BITGET"}
{"event": "subscribe", "arg": {"instType": "SPOT", "channel": "books", "instId": "BTCUSDT"}, "record_time": 1742555170.130956, "EXCHANGE": "BITGET"}
{"action": "snapshot", "arg": {"instType": "SPOT", "channel": "books", "instId": "BTCUSDT"}, "data": [{"asks": [["84054.01", "1.532143"], ["84054.74", "0.095134"], ["84054.75", "0.204076"], ["84054.92", "0.113037"], ["84059.00", "0.126169"], ["84059.01", "0.224949"], ["84059.89", "0.014359"], ["84059.91", "0.209200"], ["84063.01", "0.000357"], ["84065.85", "0.005236"], ["84065.86", "0.017454"], ["84068.21", "0.160991"], ["84068.22", "0.314035"], ["84069.01", "0.222600"], ["84073.48", "0.119870"], ["84074.68", "0.035952"], ["84075.11", "0.459309"], ["84075.12", "1.531031"], ["84076.34", "0.035961"], ["84076.89", "0.006356"], ["84077.12", "0.006356"], ["84077.53", "0.006356"], ["84078.42", "0.010984"], ["84078.76", "0.006356"], ["84079.10", "0.006356"], ["84079.35", "0.006356"], ["84079.67", "0.062760"], ["84079.68", "0.209200"], ["84079.76", "0.016429"], ["84079.84", "0.006356"], ["84079.99", "0.006356"], ["84080.18", "0.016429"], ["84080.27", "0.006356"], ["84080.28", "0.006356"], ["84080.44", "0.193700"], ["84080.45", "0.119883"], ["84081.82", "0.010985"], ["84082.13", "0.006357"], ["84082.62", "0.009990"], ["84082.70", "0.207000"], ["84083.49", "0.119867"], ["84083.61", "0.119850"], ["84084.56", "0.044138"], ["84084.57", "0.119858"], ["84085.05", "0.015895"], ["84085.16", "0.009989"], ["84087.16", "0.015892"], ["84088.25", "0.010988"], ["84088.47", "0.056736"], ["84088.48", "0.176649"], ["84088.61", "0.012472"], ["84093.18", "0.010000"], ["84095.06", "0.062760"], ["84095.07", "0.209200"], ["84098.19", "0.001212"], ["84098.20", "0.001535"], ["84100.20", "0.002504"], ["84102.20", "0.006851"], ["84103.48", "0.209200"], ["84103.84", "0.488184"], ["84103.85", "3.570413"], ["84104.20", "0.018029"], ["84105.51", "0.713389"], ["84106.20", "0.047445"], ["84107.10", "0.001598"], ["84108.20", "0.124856"], ["84109.18", "0.001597"], ["84110.20", "0.328568"], ["84112.20", "0.864651"], ["84113.41", "0.209200"], ["84114.20", "2.275398"], ["84116.20", "5.987889"], ["84118.20", "15.757604"], ["84118.80", "0.122370"], ["84118.89", "0.014887"], ["84118.90", "0.001008"], ["84119.40", "0.001002"], ["84119.80", "0.036300"], ["84119.90", "0.405960"], ["84120.00", "0.002000"], ["84120.10", "0.068190"], ["84121.30", "0.292440"], ["84121.70", "0.072720"], ["84122.50", "0.551520"], ["84123.40", "0.320670"], ["84124.00", "1.366770"], ["84124.10", "4.823970"], ["84124.20", "0.120000"], ["84124.50", "1.922700"], ["84125.00", "0.007080"], ["84125.80", "0.035670"], ["84126.10", "0.067980"], ["84126.22", "0.209200"], ["84126.50", "0.178410"], ["84126.60", "0.009000"], ["84126.90", "0.113280"], ["84127.09", "0.012765"], ["84127.40", "0.006030"], ["84127.50", "0.150210"], ["84127.60", "0.073110"], ["84127.80", "0.035670"], ["84128.10", "0.067800"], ["84128.60", "0.356880"], ["84129.10", "0.341100"], ["84136.10", "0.000044"], ["84137.08", "0.000039"], ["84137.09", "0.209200"], ["84139.46", "1.782754"], ["84141.96", "0.404270"], ["84145.50", "0.209200"], ["84150.00", "0.002064"], ["84160.20", "4.440423"], ["84161.64", "0.001810"], ["84165.70", "0.000958"], ["84168.70", "4.349802"], ["84169.99", "0.209200"], ["84170.05", "0.003620"], ["84174.51", "0.000388"], ["84176.90", "0.207473"], ["84177.20", "4.259181"], ["84178.41", "0.209200"], ["84178.87", "0.057001"], ["84180.00", "0.002000"], ["84180.79", "0.125604"], ["84185.70", "4.077939"], ["84186.81", "0.209200"], ["84188.00", "0.000202"], ["84190.00", "0.001000"], ["84194.20", "4.168560"], ["84195.21", "0.209200"], ["84202.70", "3.987319"], ["84202.75", "0.071045"], ["84202.86", "0.071253"], ["84203.61", "0.209200"], ["84210.00", "0.002000"], ["84211.20", "4.984148"], ["84212.01", "0.209200"], ["84213.46", "0.000163"], ["84219.70", "5.074769"], ["84220.41", "0.209200"], ["84228.20", "4.531044"], ["84228.81", "0.209200"], ["84232.06", "0.011010"], ["84233.38", "0.001273"], ["84234.12", "0.000044"], ["84236.70", "4.712286"], ["84237.21", "0.209200"], ["84240.00", "0.002000"], ["84245.00", "0.000149"], ["84245.20", "5.437252"], ["84250.00", "0.000684"], ["84252.44", "0.000143"], ["84253.70", "3.896698"], ["84253.92", "0.209200"], ["84259.99", "0.000017"], ["84262.20", "4.893527"], ["84266.08", "0.000016"], ["84266.67", "0.000078"], ["84269.24", "0.000032"], ["84270.00", "0.002692"], ["84270.70", "5.618494"], ["84270.98", "0.000052"], ["84272.72", "0.000105"], ["84275.00", "0.000671"], ["84279.10", "0.209200"], ["84279.20", "5.256011"], ["84280.00", "0.001261"], ["84285.00", "0.000031"], ["84285.71", "0.000010"], ["84285.78", "0.166943"], ["84285.95", "0.000028"], ["84286.79", "0.000016"], ["84286.96", "0.024945"], ["84287.50", "0.209276"], ["84287.70", "5.346632"], ["84288.89", "0.000361"], ["84294.68", "0.000019"], ["84295.90", "0.209200"], ["84296.20", "5.165390"], ["84297.06", "0.000035"], ["84300.00", "0.023631"], ["84304.31", "0.209200"], ["84304.70", "4.802906"], ["84307.00", "0.000113"], ["84307.23", "0.000008"], ["84309.09", "0.000010"], ["84310.34", "0.000331"], ["84310.35", "0.000146"], ["84311.11", "0.000025"], ["84312.50", "0.000125"], ["84312.72", "0.209200"], ["84313.03", "0.000024"], ["84313.20", "5.527873"], ["84314.97", "0.000008"], ["84315.70", "0.296868"], ["84316.67", "0.000322"], ["84317.24", "0.000135"], ["84317.40", "0.000010"], ["84318.59", "0.000027"], ["84319.15", "0.000137"], ["84319.18", "0.000039"], ["84320.00", "0.301489"], ["84320.10", "0.001428"], ["84321.13", "0.209200"], ["84321.70", "4.621665"], ["84322.11", "0.000008"], ["84324.32", "0.000059"], ["84325.00", "0.002294"], ["84325.07", "0.000161"], ["84326.09", "0.000010"], ["84326.42", "0.000023"], ["84327.14", "0.000039"], ["84327.73", "0.041940"], ["84328.95", "0.000174"], ["84329.54", "0.209200"], ["84329.64", "0.000026"], ["84330.00", "0.002000"], ["84332.00", "0.000008"], ["84333.33", "0.002262"], ["84333.36", "0.000010"], ["84333.38", "0.000008"], ["84334.48", "0.000096"], ["84334.77", "0.000022"], ["84335.90", "0.300375"], ["84336.00", "0.000133"], ["84336.23", "0.000013"], ["84336.29", "0.000010"], ["84336.34", "0.000176"], ["84337.25", "0.000067"], ["84337.35", "0.000008"], ["84337.95", "0.209200"], ["84338.46", "0.000015"], ["84339.10", "0.001469"], ["84339.21", "0.000010"], ["84339.29", "0.000029"], ["84339.62", "0.000051"], ["84340.00", "0.018287"], ["84340.72", "0.000066"], ["84341.01", "0.000008"], ["84342.11", "0.000051"], ["84342.63", "0.000009"], ["84342.70", "0.000423"], ["84343.07", "0.000014"], ["84343.70", "0.000075"], ["84343.75", "0.000012"], ["84343.97", "0.000188"], ["84346.43", "0.000128"], ["84346.94", "0.000085"], ["84347.20", "0.001720"], ["84347.69", "0.000009"], ["84347.83", "0.016818"], ["84348.21", "0.000036"], ["84348.27", "0.012402"], ["84348.62", "0.000072"], ["84350.00", "0.002253"], ["84350.79", "0.000033"], ["84354.58", "0.000115"], ["84354.64", "0.000018"], ["84354.82", "0.000078"], ["84354.84", "0.000194"], ["84356.98", "0.000048"], ["84357.14", "0.000273"], ["84358.10", "0.001403"], ["84358.29", "0.000024"], ["84359.83", "0.000010"], ["84360.00", "0.002661"], ["84363.63", "0.000057"], ["84363.64", "0.000078"], ["84366.14", "0.000162"], ["84366.15", "0.000061"], ["84366.19", "0.000022"], ["84366.60", "0.000011"], ["84366.96", "0.000018"], ["84367.10", "0.000014"], ["84367.82", "0.000476"], ["84368.38", "0.000009"], ["84368.42", "0.000284"], ["84370.00", "0.000052"], ["84370.59", "0.000071"], ["84370.97", "0.000020"], ["84371.86", "0.000012"], ["84375.00", "0.004006"], ["84376.31", "0.000016"], ["84378.11", "0.000008"], ["84378.38", "0.000009"], ["84378.45", "0.000015"], ["84380.00", "0.032216"], ["84381.82", "0.000008"], ["84382.00", "0.000035"], ["84382.35", "0.000071"], ["84383.41", "0.000053"], ["84383.69", "0.000248"], ["84384.38", "0.000424"], ["84384.61", "0.000008"], ["84386.19", "0.000019"], ["84386.67", "0.000013"], ["84387.50", "0.006969"], ["84387.76", "0.000024"], ["84389.61", "0.000088"], ["84389.90", "0.000012"], ["84390.00", "0.002000"], ["84390.01", "0.000387"], ["84391.30", "0.000018"], ["84393.31", "0.000050"], ["84396.55", "0.000016"], ["84396.98", "0.007500"], ["84397.59", "0.000008"], ["84397.69", "0.000275"], ["84398.26", "0.000068"], ["84399.54", "0.000030"], ["84399.91", "0.000018"], ["84399.99", "0.000022"], ["84400.00", "0.060615"], ["84400.18", "0.000024"], ["84402.40", "0.001273"], ["84403.39", "0.000023"], ["84403.76", "0.000099"], ["84403.98", "0.007500"], ["84404.26", "0.000137"], ["84404.28", "0.000039"], ["84405.00", "0.000402"], ["84406.06", "0.000008"], ["84406.83", "0.000064"], ["84407.50", "0.000031"], ["84410.00", "0.000059"], ["84410.04", "0.000025"], ["84411.11", "0.000361"], ["84411.43", "0.000008"], ["84411.76", "0.000101"], ["84411.77", "0.000020"], ["84412.39", "1.592259"], ["84412.50", "0.000049"], ["84413.04", "0.000010"], ["84413.33", "0.000073"], ["84413.79", "0.000135"], ["84414.29", "0.000074"], ["84414.41", "0.000051"], ["84415.09", "0.000008"], ["84416.67", "0.000355"], ["84418.34", "0.000046"], ["84419.69", "0.000023"], ["84420.00", "0.002640"], ["84420.17", "0.041940"], ["84422.71", "0.000010"], ["84423.08", "0.000067"], ["84423.53", "0.000105"], ["84424.00", "0.000022"], ["84424.12", "0.000146"], ["84425.00", "0.002205"], ["84425.69", "0.000314"], ["84426.68", "0.000101"], ["84427.08", "0.000014"], ["84427.92", "0.000323"], ["84428.57", "0.000057"], ["84429.82", "0.000022"], ["84430.50", "0.000113"], ["84430.74", "0.000010"], ["84430.77", "0.000015"], ["84431.23", "0.000039"], ["84432.43", "0.000008"], ["84433.33", "0.000347"], ["84434.78", "0.000008"], ["84435.26", "0.000161"], ["84436.26", "0.000009"], ["84437.14", "0.000017"], ["84437.50", "0.000725"], ["84437.75", "0.000013"], ["84438.44", "0.000176"], ["84440.00", "0.000544"], ["84442.54", "0.000096"], ["84443.07", "0.000423"], ["84444.25", "0.000013"], ["84444.41", "0.000371"], ["84444.44", "0.000574"], ["84444.92", "0.000022"], ["84446.04", "0.000016"], ["84446.38", "0.000013"], ["84446.43", "0.000036"], ["84447.80", "0.000718"], ["84448.75", "0.000066"], ["84448.98", "0.000085"], ["84449.11", "0.000028"], ["84449.34", "0.000010"], ["84450.00", "0.010457"], ["84451.88", "0.000010"], ["84452.66", "0.000009"], ["84453.76", "0.000054"], ["84454.43", "0.000061"], ["84454.53", "0.000019"], ["84454.55", "0.000083"], ["84454.60", "0.000093"], ["84455.31", "0.000028"], ["84456.14", "0.000033"], ["84456.52", "0.002633"], ["84457.00", "0.000009"], ["84458.06", "0.000020"], ["84458.72", "0.000072"], ["84458.82", "0.000071"], ["84458.97", "0.000153"], ["84459.08", "0.000008"], ["84459.22", "0.000188"], ["84459.69", "0.000051"], ["84460.00", "0.000622"], ["84460.23", "0.000010"], ["84460.49", "0.000009"], ["84460.87", "0.000069"], ["84460.91", "0.000012"], ["84461.00", "0.000008"], ["84462.50", "0.000076"], ["84464.28", "0.000008"], ["84465.83", "0.000016"], ["84466.67", "0.000157"], ["84470.34", "0.000017"], ["84470.59", "0.000071"], ["84473.14", "0.000126"], ["84473.68", "0.000192"], ["84474.78", "0.000099"], ["84475.00", "0.009271"], ["84475.81", "0.000039"], ["84476.97", "0.000063"], ["84477.61", "0.000095"], ["84477.67", "0.000008"], ["84478.74", "0.000036"], ["84479.37", "0.000090"], ["84480.00", "0.003246"], ["84481.00", "0.000069"], ["84481.77", "0.000011"], ["84482.67", "0.000133"], ["84482.76", "0.000016"], ["84485.20", "0.000537"], ["84485.39", "0.000020"], ["84485.71", "0.000128"], ["84485.98", "0.000034"], ["84486.49", "0.000009"], ["84486.82", "0.000135"], ["84487.00", "0.000119"], ["84487.16", "0.000035"], ["84487.32", "0.000024"], ["84487.95", "0.000008"], ["84488.88", "0.000025"], ["84489.36", "0.000137"], ["84489.39", "0.000039"], ["84489.80", "0.000010"], ["84490.00", "0.007510"], ["84490.13", "0.000093"], ["84490.91", "0.000018"], ["84491.26", "0.000008"], ["84491.87", "0.000019"], ["84492.06", "0.000009"], ["84496.43", "0.000273"], ["84496.66", "0.004837"], ["84496.73", "0.000043"], ["84497.14", "0.000008"], ["84497.26", "0.000010"], ["84500.00", "0.124015"], ["84500.03", "0.000010"], ["84500.04", "0.000008"], ["84500.11", "0.000012"], ["84501.24", "0.000010"], ["84501.28", "0.000019"], ["84501.32", "0.000326"], ["84501.99", "0.000009"], ["84503.33", "0.010000"], ["84503.57", "0.000074"], ["84504.50", "0.000051"], ["84504.74", "0.000013"], ["84506.54", "0.000008"], ["84508.00", "0.001210"], ["84508.37", "0.000050"], ["84508.46", "0.000013"], ["84508.47", "0.000023"], ["84510.00", "0.000402"], ["84510.34", "0.000135"], ["84512.00", "0.000012"], ["84512.19", "0.000016"], ["84512.61", "0.041940"], ["84512.95", "0.000023"], ["84514.29", "0.000059"], ["84516.67", "0.000010"], ["84517.54", "0.000022"], ["84517.86", "0.000016"], ["84518.98", "0.000029"], ["84520.00", "0.000318"], ["84520.50", "0.000238"], ["84520.67", "0.002384"], ["84521.85", "0.000033"], ["84522.06", "0.000041"], ["84523.08", "0.000015"], ["84523.48", "0.000015"], ["84523.81", "0.000024"], ["84524.00", "0.000035"], ["84524.83", "0.000009"], ["84525.00", "0.003286"], ["84525.82", "0.000099"], ["84527.47", "0.000608"], ["84528.57", "0.000008"], ["84530.00", "0.000031"], ["84533.01", "0.000591"], ["84533.33", "0.003186"], ["84534.53", "0.000461"]], "bids": [["84054.00", "0.055632"], ["84053.99", "0.000100"], ["84053.98", "0.000100"], ["84053.97", "0.000100"], ["84053.90", "0.010000"], ["84053.74", "0.041107"], ["84053.20", "0.000700"], ["84053.00", "0.000032"], ["84052.86", "0.027845"], ["84052.00", "0.001032"], ["84051.00", "0.000032"], ["84050.00", "0.001091"], ["84049.00", "0.000032"], ["84048.00", "0.002146"], ["84047.00", "0.000032"], ["84046.94", "0.010000"], ["84046.00", "0.005618"], ["84045.51", "0.021425"], ["84045.00", "0.000956"], ["84044.00", "0.014784"], ["84043.00", "0.000032"], ["84042.39", "0.112803"], ["84042.00", "0.038906"], ["84041.04", "0.014844"], ["84041.00", "0.000032"], ["84040.67", "0.028180"], ["84040.16", "0.008502"], ["84040.10", "0.005920"], ["84040.01", "0.193805"], ["84040.00", "0.102384"], ["84039.99", "0.209200"], ["84039.60", "0.017952"], ["84039.58", "0.007468"], ["84039.55", "0.009588"], ["84039.53", "0.007795"], ["84039.51", "0.007751"], ["84039.00", "0.000032"], ["84038.33", "0.012472"], ["84038.00", "0.269430"], ["84037.00", "0.000032"], ["84036.31", "1.093198"], ["84036.07", "0.008897"], ["84036.00", "0.709026"], ["84035.93", "0.010334"], ["84035.88", "0.008713"], ["84035.43", "0.009863"], ["84035.40", "0.005582"], ["84035.39", "0.005169"], ["84035.38", "0.008536"], ["84035.37", "0.005118"], ["84035.33", "0.004828"], ["84035.00", "0.000032"], ["84034.34", "0.089484"], ["84034.00", "1.866045"], ["84033.90", "0.006810"], ["84033.70", "0.001031"], ["84033.60", "0.001030"], ["84033.41", "0.899223"], ["84033.40", "0.230970"], ["84033.00", "0.000032"], ["84032.90", "1.004820"], ["84032.66", "0.006147"], ["84032.63", "0.083939"], ["84032.57", "0.017817"], ["84032.40", "0.289710"], ["84032.29", "0.247585"], ["84032.00", "0.018286"], ["84031.97", "0.005946"], ["84031.78", "0.004017"], ["84031.40", "0.209200"], ["84031.00", "0.000032"], ["84030.86", "0.017103"], ["84030.80", "0.755970"], ["84030.68", "0.055655"], ["84030.40", "0.069990"], ["84030.18", "0.007131"], ["84030.16", "0.028864"], ["84030.00", "0.002956"], ["84029.90", "0.006600"], ["84029.80", "0.015000"], ["84029.76", "0.007339"], ["84029.50", "0.006000"], ["84029.39", "0.008994"], ["84029.24", "0.007943"], ["84029.18", "0.224881"], ["84029.10", "0.072990"], ["84029.00", "0.006870"], ["84028.91", "0.025184"], ["84028.67", "0.085428"], ["84028.66", "0.017351"], ["84028.62", "0.314035"], ["84028.00", "0.000032"], ["84027.50", "0.120000"], ["84027.20", "3.481110"], ["84027.19", "0.051963"], ["84027.00", "0.000032"], ["84026.70", "0.120000"], ["84026.31", "0.018517"], ["84026.00", "0.000032"], ["84025.90", "0.006600"], ["84025.44", "0.268374"], ["84025.00", "0.000032"], ["84024.94", "0.008269"], ["84024.80", "0.085560"], ["84024.50", "0.144510"], ["84024.39", "0.222668"], ["84024.03", "0.076112"], ["84024.00", "0.000032"], ["84023.80", "0.021129"], ["84023.67", "0.027453"], ["84023.30", "0.008061"], ["84023.00", "0.000032"], ["84022.97", "0.259798"], ["84022.85", "0.000200"], ["84022.00", "0.000032"], ["84021.68", "3.053102"], ["84021.58", "0.209200"], ["84021.31", "0.714104"], ["84021.00", "0.000032"], ["84020.00", "0.001263"], ["84019.00", "0.000032"], ["84018.24", "0.073216"], ["84018.00", "0.000032"], ["84017.64", "0.056368"], ["84017.00", "0.000032"], ["84016.36", "0.000876"], ["84016.00", "0.000032"], ["84015.05", "0.008319"], ["84015.03", "0.008015"], ["84015.00", "0.000956"], ["84014.96", "0.008428"], ["84014.95", "0.006473"], ["84014.81", "0.008596"], ["84014.11", "0.009210"], ["84014.05", "0.006906"], ["84014.00", "0.000032"], ["84013.97", "0.007305"], ["84013.17", "0.209200"], ["84013.00", "0.000032"], ["84012.00", "0.000017"], ["84011.00", "0.000032"], ["84010.79", "0.000957"], ["84010.00", "0.000032"], ["84009.00", "0.000032"], ["84008.00", "0.000032"], ["84007.04", "0.008265"], ["84007.01", "0.005053"], ["84007.00", "0.000032"], ["84006.90", "0.008092"], ["84006.00", "0.000032"], ["84005.00", "0.000032"], ["84004.76", "0.209200"], ["84004.26", "0.003975"], ["84004.00", "0.000017"], ["84000.31", "0.017454"], ["84000.00", "0.003107"], ["83998.02", "0.003597"], ["83996.83", "0.001176"], ["83995.80", "0.209200"], ["83995.03", "0.001173"], ["83992.00", "4.440423"], ["83991.23", "0.007435"], ["83988.28", "0.008572"], ["83986.45", "0.007337"], ["83986.42", "0.007651"], ["83986.40", "0.209200"], ["83986.38", "0.007247"], ["83985.00", "0.000924"], ["83983.60", "0.071045"], ["83983.50", "4.531044"], ["83980.00", "0.001231"], ["83977.82", "0.057001"], ["83975.60", "0.209200"], ["83975.00", "3.896698"], ["83974.24", "0.001810"], ["83970.00", "0.004067"], ["83966.50", "5.437252"], ["83965.83", "0.003620"], ["83965.54", "0.071253"], ["83964.20", "0.209200"], ["83960.46", "0.012357"], ["83960.00", "0.001231"], ["83958.00", "4.984148"], ["83955.00", "0.000924"], ["83951.10", "0.209200"], ["83950.44", "0.005950"], ["83949.50", "5.165390"], ["83946.24", "0.010010"], ["83941.00", "5.256011"], ["83940.00", "0.003231"], ["83938.51", "0.209200"], ["83933.56", "0.125597"], ["83932.50", "5.074769"], ["83928.50", "0.000948"], ["83925.07", "0.209200"], ["83924.00", "5.527873"], ["83920.00", "0.001231"], ["83915.77", "0.209200"], ["83915.50", "4.168560"], ["83910.00", "0.002924"], ["83907.35", "0.209200"], ["83907.00", "4.077939"], ["83903.24", "0.024945"], ["83898.93", "0.209200"], ["83898.50", "5.618494"], ["83895.52", "0.001720"], ["83895.00", "0.000924"], ["83890.51", "0.209200"], ["83890.00", "3.987319"], ["83882.09", "0.209200"], ["83881.50", "4.349802"], ["83880.00", "0.003231"], ["83877.01", "0.000023"], ["83875.16", "0.000179"], ["83875.00", "0.000704"], ["83873.68", "0.209200"], ["83873.52", "0.000135"], ["83873.00", "4.712286"], ["83872.00", "0.001184"], ["83868.70", "0.001444"], ["83868.39", "0.002014"], ["83866.67", "0.002945"], ["83865.27", "0.209200"], ["83865.00", "0.000924"], ["83864.50", "4.259181"], ["83862.50", "0.006969"], ["83862.00", "0.305037"], ["83860.29", "0.000041"], ["83860.00", "0.001234"], ["83859.54", "0.000008"], ["83857.14", "0.000079"], ["83857.13", "0.000019"], ["83856.86", "0.209200"], ["83856.11", "0.010000"], ["83856.00", "5.346632"], ["83854.55", "0.000009"], ["83854.17", "0.000020"], ["83852.94", "0.000071"], ["83852.50", "0.000043"], ["83851.85", "0.000011"], ["83851.84", "0.000219"], ["83850.00", "0.003028"], ["83848.39", "0.000020"], ["83847.50", "4.802906"], ["83846.15", "0.000111"], ["83844.83", "0.000008"], ["83844.10", "0.153580"], ["83843.10", "0.302418"], ["83842.11", "0.000033"], ["83841.18", "0.000071"], ["83840.00", "0.001282"], ["83839.72", "0.000033"], ["83839.18", "0.000016"], ["83839.00", "4.621665"], ["83837.84", "0.000009"], ["83837.59", "0.000012"], ["83836.36", "0.000008"], ["83835.56", "0.000009"], ["83835.00", "0.309045"], ["83831.11", "0.000011"], ["83830.59", "0.000010"], ["83830.50", "4.893527"], ["83830.00", "0.000063"], ["83829.70", "0.000396"], ["83828.57", "0.000016"], ["83826.67", "0.000073"], ["83825.00", "0.000672"], ["83822.12", "0.000067"], ["83820.00", "0.003247"], ["83818.18", "0.001526"], ["83818.17", "0.000029"], ["83816.67", "0.000010"], ["83816.28", "0.000009"], ["83816.00", "0.000008"], ["83815.79", "0.000022"], ["83815.75", "0.000009"], ["83815.37", "0.000022"], ["83813.00", "0.000113"], ["83810.74", "0.000019"], ["83810.41", "0.000264"], ["83808.53", "0.000039"], ["83808.51", "0.000137"], ["83807.88", "0.000051"], ["83807.53", "0.000010"], ["83805.00", "0.000926"], ["83804.35", "0.000010"], ["83803.57", "0.000016"], ["83802.81", "0.000022"], ["83800.91", "0.000012"], ["83800.00", "0.039884"], ["83799.34", "0.000093"], ["83796.61", "0.001213"], ["83795.00", "0.000031"], ["83794.17", "0.000096"], ["83793.10", "0.000016"], ["83791.03", "0.000996"], ["83791.02", "0.000632"], ["83790.15", "0.000024"], ["83790.00", "0.003033"], ["83789.60", "0.000363"], ["83789.29", "0.000074"], ["83787.88", "0.000010"], ["83785.71", "0.000081"], ["83784.62", "0.000015"], ["83784.36", "0.000069"], ["83784.02", "0.000022"], ["83783.78", "0.000059"], ["83783.12", "0.000008"], ["83780.48", "0.000016"], ["83780.00", "0.001547"], ["83779.93", "0.000028"], ["83778.35", "0.011010"], ["83777.78", "0.000679"], ["83777.60", "0.000013"], ["83777.18", "0.000013"], ["83775.00", "0.009183"], ["83774.10", "0.000161"], ["83773.31", "0.000154"], ["83773.11", "0.041940"], ["83772.88", "0.000023"], ["83769.28", "0.000972"], ["83768.46", "0.000008"], ["83768.00", "0.000012"], ["83766.84", "0.000023"], ["83765.06", "0.000008"], ["83764.71", "0.000071"], ["83763.64", "0.000010"], ["83762.50", "0.000076"], ["83761.90", "0.000024"], ["83761.29", "0.000020"], ["83760.00", "0.001718"], ["83758.93", "0.000036"], ["83758.00", "0.000353"], ["83757.40", "0.000537"], ["83756.08", "0.000099"], ["83755.56", "0.000134"], ["83754.70", "0.000013"], ["83754.39", "0.000033"], ["83752.94", "0.000071"], ["83752.37", "0.000119"], ["83752.09", "0.000314"], ["83752.00", "0.000034"], ["83750.67", "0.000146"], ["83750.00", "0.041680"], ["83749.66", "0.000016"], ["83749.50", "0.000069"], ["83749.33", "0.000133"], ["83748.54", "0.000012"], ["83746.09", "0.000010"], ["83745.16", "0.000389"], ["83745.00", "0.000926"], ["83743.29", "0.001451"], ["83740.51", "0.000423"], ["83740.00", "0.001311"], ["83739.78", "1.725740"], ["83739.60", "0.000048"], ["83739.28", "0.000051"], ["83739.13", "0.000008"], ["83737.93", "0.000135"], ["83737.37", "0.000012"], ["83737.00", "0.000009"], ["83736.94", "0.000104"], ["83736.84", "0.000183"], ["83736.33", "0.000025"], ["83734.69", "0.000085"], ["83733.33", "0.003222"], ["83732.10", "0.000009"], ["83731.48", "0.000124"], ["83730.63", "0.001536"], ["83730.00", "0.002926"], ["83729.73", "0.000009"], ["83729.39", "0.000008"], ["83729.32", "0.000035"], ["83728.57", "0.000017"], ["83728.37", "0.001273"], ["83728.07", "0.000022"], ["83727.71", "0.000009"], ["83727.27", "0.000082"], ["83726.20", "0.000016"], ["83725.00", "0.002501"], ["83723.72", "0.000176"], ["83723.64", "0.000009"], ["83723.61", "0.000883"], ["83723.43", "0.000039"], ["83723.40", "0.000205"], ["83721.56", "0.000015"], ["83720.00", "0.003671"], ["83719.46", "0.000053"], ["83718.75", "0.000012"], ["83717.93", "0.000065"], ["83717.46", "0.000009"], ["83717.45", "0.000040"], ["83717.39", "0.000010"], ["83715.48", "0.000010"], ["83715.00", "0.000926"], ["83714.29", "0.009987"], ["83714.28", "0.000836"], ["83713.80", "0.000024"], ["83713.71", "0.000323"], ["83713.40", "0.000161"], ["83711.93", "0.000018"], ["83710.00", "0.000023"], ["83709.88", "0.000107"], ["83707.07", "0.000067"], ["83706.90", "0.000016"], ["83706.67", "0.000013"], ["83705.85", "0.000019"], ["83705.32", "0.000065"], ["83705.18", "0.000009"], ["83703.75", "0.000364"], ["83703.70", "0.000499"], ["83703.00", "0.000024"], ["83702.93", "0.000050"], ["83702.60", "0.000039"], ["83702.50", "0.000033"], ["83702.48", "0.000057"], ["83701.92", "0.000067"], ["83701.28", "0.000248"], ["83700.00", "0.007170"], ["83699.88", "0.000008"], ["83697.23", "0.000095"], ["83695.65", "0.003535"], ["83695.63", "0.000011"], ["83693.69", "0.000051"], ["83692.52", "0.000066"], ["83692.38", "0.000007"], ["83692.31", "0.000031"], ["83691.74", "0.000653"], ["83690.84", "0.000162"], ["83690.48", "0.000248"], ["83689.78", "0.001684"], ["83689.50", "0.000113"], ["83688.89", "0.000009"], ["83688.07", "0.000072"], ["83687.50", "0.006969"], ["83687.00", "0.000008"], ["83686.11", "0.000096"], ["83685.00", "0.000926"], ["83684.21", "0.000102"], ["83683.67", "0.000184"], ["83681.82", "0.000175"], ["83680.67", "0.041940"], ["83680.00", "0.001718"], ["83679.44", "0.000361"], ["83678.41", "0.000010"], ["83678.08", "0.000145"], ["83677.37", "0.000008"], ["83676.47", "0.000080"], ["83675.68", "0.000008"], ["83675.62", "0.000011"], ["83675.36", "0.000013"], ["83675.20", "0.000018"], ["83675.00", "0.002674"], ["83674.70", "0.000008"], ["83674.19", "0.000020"], ["83674.00", "0.001195"], ["83673.87", "0.000022"], ["83673.58", "0.000023"], ["83672.96", "0.002168"], ["83672.50", "0.000031"], ["83672.25", "0.004023"], ["83672.00", "0.000035"], ["83671.36", "0.000099"], ["83670.59", "0.000105"], ["83670.05", "0.000033"], ["83670.00", "0.004426"], ["83669.66", "0.000010"], ["83669.58", "0.000251"], ["83669.09", "0.000135"], ["83667.80", "0.000023"], ["83667.23", "0.012503"], ["83666.67", "0.052199"], ["83666.66", "0.000513"], ["83666.65", "0.000122"], ["83666.00", "0.271427"], ["83664.71", "0.000071"], ["83664.19", "0.000073"], ["83663.98", "0.000008"], ["83663.95", "0.000022"], ["83663.91", "0.000161"], ["83662.50", "0.000077"], ["83661.97", "0.000052"], ["83661.60", "0.000042"], ["83661.08", "0.004152"], ["83660.71", "0.000309"], ["83660.14", "0.000016"], ["83660.00", "0.001273"], ["83659.61", "0.000454"], ["83659.49", "0.000012"], ["83659.44", "0.000613"], ["83658.54", "0.000036"], ["83656.60", "0.000607"], ["83655.00", "0.000926"], ["83654.23", "0.000009"], ["83653.94", "0.000133"], ["83653.67", "0.001695"], ["83653.31", "0.000015"], ["83652.80", "0.000119"], ["83652.48", "0.000188"], ["83651.65", "0.000018"]], "checksum": 0, "ts": "1742555169969"}], "ts": 1742555170108, "record_time": 1742555170.184388, "EXCHANGE": "BITGET"}
{"action": "update", "arg": {"instType": "SPOT", "channel": "books", "instId": "BTCUSDT"}, "data": [{"asks": [["84160.20", "3.987319"], ["84177.20", "4.168560"], ["84185.70", "5.074769"], ["84194.20", "4.984148"], ["84202.70", "4.077939"], ["84211.20", "4.621665"], ["84219.70", "5.527873"], ["84228.20", "3.896698"], ["84236.70", "5.165390"], ["84245.20", "5.346632"], ["84253.70", "4.802906"], ["84262.20", "4.440423"], ["84270.70", "4.893527"], ["84279.20", "4.531044"], ["84287.70", "5.437252"], ["84296.20", "5.256011"], ["84304.70", "5.618494"], ["84313.20", "4.259181"], ["84321.70", "4.712286"]], "bids": [["84052.86", "0"], ["84048.00", "0.002009"], ["84046.00", "0.005289"], ["84044.00", "0.013917"], ["84042.00", "0.036623"], ["84040.01", "0"], ["84040.00", "0.096378"], ["84038.00", "0.253627"], ["84036.00", "0.667438"], ["84034.00", "1.756417"], ["84028.67", "0.279233"], ["84003.00", "0.000017"], ["83992.00", "5.074769"], ["83983.50", "4.621665"], ["83975.00", "4.440423"], ["83966.50", "4.531044"], ["83958.00", "5.346632"], ["83949.50", "4.802906"], ["83941.00", "4.893527"], ["83932.50", "5.618494"], ["83924.00", "4.984148"], ["83915.50", "3.896698"], ["83907.00", "4.168560"], ["83898.50", "4.712286"], ["83890.00", "4.077939"], ["83881.50", "3.987319"], ["83873.00", "5.165390"], ["83864.50", "4.349802"], ["83856.00", "5.256011"], ["83847.50", "5.437252"], ["83839.00", "4.259181"], ["83830.50", "5.527873"], ["83651.16", "0.000896"]], "checksum": -1662924922, "ts": "1742555170175"}], "ts": 1742555170177, "record_time": 1742555170.229542, "EXCHANGE": "BITGET"}
{"action": "update", "arg": {"instType": "SPOT", "channel": "books", "instId": "BTCUSDT"}, "data": [{"asks": [["84110.20", "0.328448"], ["84112.20", "0.864338"], ["84114.20", "2.274574"], ["84116.20", "5.985719"], ["84118.20", "15.751894"], ["84123.30", "0.356880"], ["84128.60", "0"], ["84160.20", "5.346632"], ["84168.70", "4.259181"], ["84177.20", "5.618494"], ["84185.70", "5.256011"], ["84194.20", "4.621665"], ["84202.70", "5.527873"], ["84211.20", "4.893527"], ["84219.70", "5.437252"], ["84228.20", "4.531044"], ["84236.70", "4.712286"], ["84245.20", "4.440423"], ["84253.70", "5.165390"], ["84262.20", "4.802906"], ["84270.70", "4.984148"], ["84279.20", "4.077939"], ["84287.70", "4.168560"], ["84296.20", "5.074769"], ["84304.70", "4.349802"], ["84313.20", "3.987319"], ["84321.70", "3.896698"]], "bids": [["84053.74", "0"], ["84053.41", "0.027845"], ["84044.00", "0.013918"], ["84042.39", "0"], ["84042.00", "0.036627"], ["84040.09", "0.112804"], ["84040.00", "0.096385"], ["84038.00", "0.253645"], ["84036.31", "0.719684"], ["84036.00", "0.667488"], ["84032.40", "0"], ["84030.80", "0.974850"], ["84030.20", "0.066600"], ["84029.80", "0.030000"], ["84012.00", "0.000032"], ["84004.00", "0.000032"], ["83992.00", "4.077939"], ["83983.50", "3.896698"], ["83975.00", "4.893527"], ["83966.50", "5.074769"], ["83958.00", "4.168560"], ["83949.50", "5.346632"], ["83941.00", "4.712286"], ["83932.50", "4.621665"], ["83924.00", "4.531044"], ["83915.50", "4.349802"], ["83907.00", "5.437252"], ["83898.50", "3.987319"], ["83890.00", "4.440423"], ["83881.50", "4.259181"], ["83873.00", "4.984148"], ["83864.50", "5.527873"], ["83847.50", "4.802906"], ["83839.00", "5.165390"], ["83830.50", "5.618494"]], "checksum": -217033264, "ts": "1742555170375"}], "ts": 1742555170381, "record_time": 1742555170.403123, "EXCHANGE": "BITGET"}
{"action": "update", "arg": {"instType": "SPOT", "channel": "books", "instId": "BTCUSDT"}, "data": [{"asks": [["84054.01", "1.092143"], ["84116.20", "5.985592"], ["84118.20", "15.751559"], ["84127.50", "0.450210"], ["84127.60", "0.229110"], ["84160.20", "3.987319"], ["84168.70", "5.165390"], ["84185.70", "4.259181"], ["84194.20", "5.527873"], ["84202.70", "5.256011"], ["84211.20", "5.074769"], ["84219.70", "4.077939"], ["84228.20", "4.984148"], ["84245.20", "4.802906"], ["84253.70", "4.440423"], ["84262.20", "4.349802"], ["84270.70", "3.896698"], ["84279.20", "5.346632"], ["84287.70", "5.437252"], ["84296.20", "4.168560"], ["84304.70", "4.531044"], ["84313.20", "4.893527"], ["84321.70", "4.621665"]], "bids": [["84053.75", "0.041107"], ["84040.00", "0.096281"], ["84038.00", "0.253371"], ["84036.00", "0.666767"], ["84034.00", "1.754650"], ["84028.67", "0.008185"], ["83992.00", "4.349802"], ["83983.50", "4.621665"], ["83975.00", "5.437252"], ["83966.50", "3.896698"], ["83958.00", "4.712286"], ["83949.50", "4.168560"], ["83941.00", "4.440423"], ["83932.50", "4.259181"], ["83924.00", "5.527873"], ["83915.50", "3.987319"], ["83907.00", "5.165390"], ["83898.50", "4.077939"], ["83890.00", "5.074769"], ["83881.50", "4.984148"], ["83873.00", "5.346632"], ["83864.50", "4.531044"], ["83847.50", "4.893527"], ["83839.00", "4.802906"], ["83651.16", "0"]], "checksum": 1116712370, "ts": "1742555170581"}], "ts": 1742555170585, "record_time": 1742555170.60954, "EXCHANGE": "BITGET"}
{"action": "update", "arg": {"instType": "SPOT", "channel": "books", "instId": "BTCUSDT"}, "data": [{"asks": [["84054.01", "1.532143"], ["84112.20", "0.864201"], ["84114.20", "2.274213"], ["84116.20", "5.984773"], ["84118.20", "15.749401"], ["84125.90", "0.120000"], ["84126.70", "0.121740"], ["84129.10", "0.071340"], ["84160.20", "4.440423"], ["84168.70", "5.618494"], ["84177.20", "4.168560"], ["84185.70", "4.621665"], ["84194.20", "4.531044"], ["84202.70", "4.259181"], ["84211.20", "5.527873"], ["84219.70", "4.802906"], ["84228.20", "5.074769"], ["84236.70", "4.077939"], ["84245.20", "5.346632"], ["84253.70", "4.349802"], ["84262.20", "4.712286"], ["84264.10", "0.001428"], ["84270.70", "4.984148"], ["84279.20", "4.893527"], ["84296.20", "3.987319"], ["84304.70", "3.896698"], ["84313.20", "5.165390"], ["84320.10", "0"], ["84321.70", "5.256011"], ["84533.33", "0"], ["84534.53", "0"]], "bids": [["84027.21", "0.644562"], ["84004.00", "0.000015"], ["83992.00", "4.802906"], ["83983.50", "4.259181"], ["83975.00", "5.256011"], ["83958.00", "4.531044"], ["83949.50", "5.346632"], ["83941.00", "5.527873"], ["83933.56", "0"], ["83932.50", "4.893527"], ["83924.00", "5.074769"], ["83915.50", "4.077939"], ["83907.00", "5.437252"], ["83898.50", "4.168560"], ["83890.00", "4.440423"], ["83881.50", "3.987319"], ["83873.00", "4.984148"], ["83864.50", "5.165390"], ["83856.00", "5.618494"], ["83847.50", "4.621665"], ["83839.00", "4.712286"], ["83830.50", "4.349802"]], "checksum": 1809399887, "ts": "1742555170791"}], "ts": 1742555170794, "record_time": 1742555170.816476, "EXCHANGE": "BITGET"}
{"action": "update", "arg": {"instType": "SPOT", "channel": "books", "instId": "BTCUSDT"}, "data": [{"asks": [["84126.10", "0.094290"], ["84129.10", "0"], ["84160.20", "4.712286"], ["84168.70", "5.527873"], ["84177.20", "5.437252"], ["84185.70", "4.984148"], ["84194.20", "5.346632"], ["84202.70", "5.618494"], ["84211.20", "4.440423"], ["84228.20", "4.077939"], ["84236.70", "4.259181"], ["84245.20", "5.165390"], ["84253.70", "4.893527"], ["84262.20", "4.621665"], ["84270.70", "5.256011"], ["84279.20", "4.349802"], ["84287.70", "3.987319"], ["84296.20", "4.168560"], ["84304.70", "5.074769"], ["84313.20", "4.531044"], ["84321.70", "3.896698"], ["84533.33", "0.003186"]], "bids": [["84053.76", "0.041107"], ["84053.75", "0"], ["84048.00", "0.002127"], ["84046.00", "0.005720"], ["84044.00", "0.015051"], ["84042.00", "0.039608"], ["84040.00", "0.104232"], ["84038.00", "0.274294"], ["84036.00", "0.721826"], ["84034.00", "1.899544"], ["84032.40", "0.525270"], ["84030.80", "0.525840"], ["84027.30", "0.018210"], ["84026.40", "0.070590"], ["84025.60", "1.350000"], ["84024.50", "0"], ["83992.00", "4.077939"], ["83983.50", "5.256011"], ["83975.00", "5.527873"], ["83966.50", "5.437252"], ["83958.00", "4.802906"], ["83949.50", "4.531044"], ["83941.00", "5.346632"], ["83932.50", "4.349802"], ["83924.00", "5.165390"], ["83919.35", "0.125619"], ["83915.50", "5.618494"], ["83907.00", "4.984148"], ["83898.50", "4.893527"], ["83890.00", "4.621665"], ["83881.50", "3.896698"], ["83873.00", "3.987319"], ["83864.50", "4.712286"], ["83856.00", "4.168560"], ["83847.50", "4.440423"], ["83839.00", "5.074769"], ["83830.50", "4.259181"], ["83653.31", "0"], ["83652.80", "0"], ["83652.48", "0"], ["83651.65", "0"]], "checksum": 398580490, "ts": "1742555170993"}], "ts": 1742555170995, "record_time": 1742555171.017569, "EXCHANGE": "BITGET"}
{"action": "update", "arg": {"instType": "SPOT", "channel": "books", "instId": "BTCUSDT"}, "data": [{"asks": [["84118.20", "15.749531"], ["84121.30", "0.022680"], ["84129.10", "0.071340"], ["84160.20", "5.165390"], ["84168.70", "4.621665"], ["84177.20", "4.712286"], ["84185.70", "3.987319"], ["84194.20", "5.527873"], ["84202.70", "4.802906"], ["84211.20", "5.256011"], ["84219.70", "4.168560"], ["84228.20", "4.259181"], ["84236.70", "5.074769"], ["84245.20", "4.077939"], ["84253.70", "4.349802"], ["84262.20", "4.440423"], ["84270.70", "4.984148"], ["84279.20", "4.531044"], ["84287.70", "3.896698"], ["84296.20", "5.437252"], ["84304.70", "4.893527"], ["84313.20", "5.346632"], ["84321.70", "5.618494"], ["84533.33", "0"]], "bids": [["84040.10", "0.234996"], ["84038.00", "0.274530"], ["84036.00", "0.722449"], ["84034.00", "1.901180"], ["84027.21", "0"], ["84002.00", "0.000017"], ["83992.00", "4.259181"], ["83983.50", "5.165390"], ["83975.00", "4.712286"], ["83966.50", "4.893527"], ["83941.00", "4.168560"], ["83932.50", "5.256011"], ["83924.00", "3.987319"], ["83907.00", "4.440423"], ["83898.50", "5.074769"], ["83890.00", "3.896698"], ["83881.50", "4.621665"], ["83873.00", "5.527873"], ["83864.50", "5.346632"], ["83856.00", "5.437252"], ["83847.50", "4.077939"], ["83839.00", "4.984148"], ["83830.50", "4.349802"]], "checksum": 398580490, "ts": "1742555171212"}], "ts": 1742555171215, "record_time": 1742555171.237474, "EXCHANGE": "BITGET"}
{"action": "update", "arg": {"instType": "SPOT", "channel": "books", "instId": "BTCUSDT"}, "data": [{"asks": [["84160.20", "3.987319"], ["84168.70", "3.896698"], ["84177.20", "4.893527"], ["84185.70", "4.621665"], ["84194.20", "4.077939"], ["84202.70", "5.256011"], ["84211.20", "5.165390"], ["84219.70", "5.437252"], ["84228.20", "5.618494"], ["84236.70", "4.531044"], ["84245.20", "5.346632"], ["84253.70", "4.984148"], ["84262.20", "4.259181"], ["84270.70", "5.074769"], ["84279.20", "5.527873"], ["84287.70", "4.712286"], ["84296.20", "4.168560"], ["84304.70", "4.349802"], ["84313.20", "4.440423"], ["84321.70", "4.802906"]], "bids": [["84046.00", "0.005601"], ["84044.00", "0.014740"], ["84042.00", "0.038789"], ["84040.00", "0.102076"], ["84038.00", "0.268622"], ["84036.00", "0.706899"], ["84034.00", "1.860260"], ["84032.90", "1.464600"], ["84030.80", "0.525630"], ["84027.21", "0.416075"], ["84024.80", "0"], ["84003.00", "0.000032"], ["83992.00", "5.165390"], ["83983.50", "4.077939"], ["83975.00", "5.437252"], ["83966.50", "4.349802"], ["83958.00", "5.346632"], ["83949.50", "4.984148"], ["83941.00", "5.527873"], ["83932.50", "4.712286"], ["83924.00", "5.256011"], ["83915.50", "5.074769"], ["83907.00", "4.802906"], ["83898.50", "4.531044"], ["83890.00", "4.168560"], ["83881.50", "3.987319"], ["83873.00", "4.893527"], ["83864.50", "4.259181"], ["83856.00", "3.896698"], ["83847.50", "5.618494"], ["83839.00", "4.440423"], ["83830.50", "4.621665"]], "checksum": 611575577, "ts": "1742555171414"}], "ts": 1742555171417, "record_time": 1742555171.44135, "EXCHANGE": "BITGET"}
{"action": "update", "arg": {"instType": "SPOT", "channel": "books", "instId": "BTCUSDT"}, "data": [{"asks": [["84054.01", "1.092143"], ["84118.20", "15.749383"], ["84160.20", "4.802906"], ["84168.70", "4.621665"], ["84177.20", "5.437252"], ["84185.70", "4.077939"], ["84194.20", "4.168560"], ["84202.70", "5.618494"], ["84211.20", "5.527873"], ["84219.70", "4.259181"], ["84228.20", "4.984148"], ["84236.70", "4.440423"], ["84245.20", "4.349802"], ["84253.70", "5.346632"], ["84262.20", "5.256011"], ["84270.70", "5.165390"], ["84279.20", "3.987319"], ["84287.70", "3.896698"], ["84296.20", "4.531044"], ["84304.70", "4.712286"], ["84313.20", "4.893527"], ["84321.70", "5.074769"]], "bids": [["84053.77", "0.041107"], ["84053.76", "0"], ["84046.94", "0"], ["83992.00", "4.984148"], ["83983.50", "4.349802"], ["83975.00", "4.168560"], ["83966.50", "4.621665"], ["83958.00", "5.437252"], ["83949.50", "4.802906"], ["83941.00", "4.440423"], ["83932.50", "4.077939"], ["83924.00", "4.712286"], ["83907.00", "4.259181"], ["83898.50", "5.165390"], ["83890.00", "5.256011"], ["83881.50", "4.531044"], ["83864.50", "5.618494"], ["83856.00", "3.987319"], ["83847.50", "5.527873"], ["83839.00", "3.896698"], ["83830.50", "5.346632"], ["83653.31", "0.000015"]], "checksum": 35631322, "ts": "1742555171624"}], "ts": 1742555171626, "record_time": 1742555171.649892, "EXCHANGE": "BITGET"}
{"action": "update", "arg": {"instType": "SPOT", "channel": "books", "instId": "BTCUSDT"}, "data": [{"asks": [["84160.20", "4.349802"], ["84168.70", "5.527873"], ["84177.20", "3.987319"], ["84185.70", "4.168560"], ["84194.20", "4.712286"], ["84202.70", "5.346632"], ["84211.20", "4.259181"], ["84219.70", "5.074769"], ["84228.20", "5.618494"], ["84236.70", "4.802906"], ["84245.20", "3.896698"], ["84253.70", "4.531044"], ["84262.20", "4.893527"], ["84270.70", "5.437252"], ["84279.20", "4.621665"], ["84287.70", "4.077939"], ["84296.20", "5.256011"], ["84304.70", "4.440423"], ["84313.20", "4.984148"], ["84321.70", "5.165390"]], "bids": [["84003.00", "0.000015"], ["83992.00", "4.802906"], ["83983.50", "4.440423"], ["83975.00", "5.346632"], ["83958.00", "4.984148"], ["83949.50", "4.077939"], ["83941.00", "5.256011"], ["83932.50", "5.618494"], ["83924.00", "4.259181"], ["83915.50", "3.896698"], ["83907.00", "4.349802"], ["83898.50", "4.531044"], ["83890.00", "3.987319"], ["83881.50", "5.074769"], ["83873.00", "5.527873"], ["83864.50", "4.712286"], ["83856.00", "4.168560"], ["83847.50", "4.893527"], ["83839.00", "5.437252"], ["83830.50", "5.165390"]], "checksum": 35631322, "ts": "1742555171832"}], "ts": 1742555171835, "record_time": 1742555171.85737, "EXCHANGE": "BITGET"}
{"action": "update", "arg": {"instType": "SPOT", "channel": "books", "instId": "BTCUSDT"}, "data": [{"asks": [["84054.01", "1.551209"], ["84093.18", "0"], ["84123.20", "0.356940"], ["84126.10", "0.094110"], ["84129.10", "0"], ["84160.20", "5.256011"], ["84168.70", "4.259181"], ["84177.20", "4.440423"], ["84185.70", "5.618494"], ["84194.20", "3.896698"], ["84202.70", "5.437252"], ["84211.20", "5.527873"], ["84219.70", "4.621665"], ["84228.20", "5.346632"], ["84236.70", "4.531044"], ["84245.20", "4.712286"], ["84253.70", "3.987319"], ["84262.20", "4.168560"], ["84264.10", "0.302898"], ["84270.70", "4.802906"], ["84279.20", "4.893527"], ["84296.20", "5.074769"], ["84304.70", "5.165390"], ["84313.20", "4.349802"], ["84320.00", "0.000019"], ["84321.70", "4.984148"], ["84533.33", "0.003186"]], "bids": [["84054.00", "0.055600"], ["84053.78", "0.041107"], ["84053.77", "0"], ["84025.60", "0"], ["84024.80", "0.085560"], ["83992.00", "4.349802"], ["83983.50", "4.802906"], ["83975.00", "3.896698"], ["83966.50", "5.346632"], ["83958.00", "5.256011"], ["83949.50", "4.893527"], ["83941.00", "5.165390"], ["83939.60", "0.200459"], ["83932.50", "4.077939"], ["83915.50", "4.712286"], ["83907.00", "4.984148"], ["83898.50", "4.168560"], ["83890.00", "4.621665"], ["83873.00", "4.440423"], ["83864.50", "5.618494"], ["83856.00", "3.987319"], ["83847.50", "5.437252"], ["83844.10", "0"], ["83840.90", "0.153580"], ["83839.00", "5.527873"], ["83830.50", "4.531044"], ["83653.31", "0"]], "checksum": -1463272470, "ts": "1742555172040"}], "ts": 1742555172044, "record_time": 1742555172.067573, "EXCHANGE": "BITGET"}
{"action": "update", "arg": {"instType": "SPOT", "channel": "books", "instId": "BTCUSDT"}, "data": [{"asks": [["84054.01", "1.552143"], ["84102.20", "0.006725"], ["84104.20", "0.017593"], ["84106.20", "0.046299"], ["84108.20", "0.121837"], ["84110.20", "0.320626"], ["84112.20", "0.843751"], ["84114.20", "2.220397"], ["84116.20", "5.843151"], ["84118.20", "15.376713"], ["84120.80", "0.144510"], ["84126.10", "0.094290"], ["84160.20", "5.165390"], ["84168.70", "3.896698"], ["84177.20", "4.712286"], ["84185.70", "3.987319"], ["84194.20", "4.802906"], ["84202.70", "5.074769"], ["84211.20", "4.077939"], ["84219.70", "4.984148"], ["84228.20", "4.259181"], ["84236.70", "5.437252"], ["84245.20", "5.256011"], ["84253.70", "4.168560"], ["84262.20", "5.346632"], ["84270.70", "4.621665"], ["84279.20", "4.440423"], ["84287.70", "4.531044"], ["84296.20", "4.349802"], ["84304.70", "5.618494"], ["84313.20", "4.893527"], ["84321.70", "5.527873"], ["84533.33", "0"]], "bids": [["84053.41", "0"], ["84048.00", "0.001996"], ["84046.00", "0.005254"], ["84044.00", "0.013827"], ["84042.00", "0.036387"], ["84040.09", "0"], ["84040.00", "0.095753"], ["84038.00", "0.251983"], ["84036.00", "0.663113"], ["84034.00", "1.745164"], ["84032.90", "0"], ["84030.80", "0.525840"], ["84027.30", "0.008010"], ["84004.00", "0"], ["83992.00", "4.802906"], ["83983.50", "4.259181"], ["83975.00", "3.987319"], ["83966.50", "5.165390"], ["83958.00", "4.712286"], ["83949.50", "4.531044"], ["83941.00", "5.074769"], ["83932.50", "5.256011"], ["83924.00", "4.893527"], ["83915.50", "3.896698"], ["83907.00", "5.527873"], ["83898.50", "4.077939"], ["83890.00", "4.984148"], ["83881.50", "4.349802"], ["83864.50", "4.168560"], ["83856.00", "5.437252"], ["83847.50", "5.346632"], ["83839.00", "5.618494"], ["83830.50", "4.621665"], ["83653.31", "0.000015"], ["83652.80", "0.000119"], ["83652.48", "0.000188"], ["83651.65", "0.000018"]], "checksum": 631110155, "ts": "1742555172243"}], "ts": 1742555172248, "record_time": 1742555172.280348, "EXCHANGE": "BITGET"}
{"action": "update", "arg": {"instType": "SPOT", "channel": "books", "instId": "BTCUSDT"}, "data": [{"asks": [["84073.94", "0.035952"], ["84074.68", "0"], ["84075.49", "0.035961"], ["84076.01", "0.006356"], ["84076.17", "0.006356"], ["84076.34", "0"], ["84076.49", "0.006356"], ["84076.89", "0"], ["84077.12", "0"], ["84077.53", "0.010984"], ["84078.42", "0"], ["84078.45", "0.006356"], ["84078.99", "0.006356"], ["84079.10", "0.012712"], ["84079.33", "0.119883"], ["84079.35", "0"], ["84079.44", "0.016429"], ["84079.55", "0.006356"], ["84079.84", "0"], ["84079.99", "0"], ["84080.18", "0"], ["84080.27", "0"], ["84080.28", "0"], ["84080.45", "0"], ["84080.76", "0.006357"], ["84080.96", "0.010985"], ["84081.79", "0.009990"], ["84081.82", "0"], ["84082.13", "0"], ["84082.62", "0"], ["84083.91", "0.119858"], ["84084.31", "0.015895"], ["84084.50", "0.009989"], ["84084.57", "0"], ["84085.05", "0"], ["84085.16", "0"], ["84104.20", "0.017792"], ["84106.20", "0.046821"], ["84108.20", "0.123211"], ["84110.20", "0.324240"], ["84112.20", "0.853264"], ["84114.20", "2.245432"], ["84116.20", "5.909032"], ["84118.20", "15.550084"], ["84128.10", "0"], ["84160.20", "4.984148"], ["84168.70", "3.987319"], ["84177.20", "4.349802"], ["84185.70", "5.256011"], ["84194.20", "4.893527"], ["84202.70", "5.618494"], ["84211.20", "4.168560"], ["84219.70", "4.531044"], ["84228.20", "5.346632"], ["84236.70", "4.440423"], ["84245.20", "5.527873"], ["84253.70", "5.165390"], ["84262.20", "5.074769"], ["84270.70", "4.802906"], ["84279.20", "4.712286"], ["84287.70", "4.621665"], ["84296.20", "4.259181"], ["84304.70", "4.077939"], ["84313.20", "5.437252"], ["84321.70", "3.896698"], ["84533.33", "0.003186"], ["84534.53", "0.000461"], ["84535.32", "0.000039"]], "bids": [["84046.00", "0.005124"], ["84044.00", "0.013485"], ["84042.00", "0.035486"], ["84040.08", "0.112805"], ["84040.00", "0.093384"], ["84038.00", "0.245749"], ["84036.00", "0.646708"], ["84034.34", "0"], ["84034.00", "1.701993"], ["84033.60", "0.089495"], ["84033.41", "0.533538"], ["84032.63", "0"], ["84032.57", "0"], ["84032.40", "0"], ["84032.00", "0.000032"], ["84031.97", "0"], ["84031.78", "0.087966"], ["84031.46", "0.017819"], ["84031.28", "0.018257"], ["84030.93", "0.005947"], ["84030.80", "0.526050"], ["84030.68", "0"], ["84030.40", "0.070200"], ["84029.79", "0.055662"], ["84029.76", "0"], ["84029.39", "0"], ["84029.24", "0"], ["84029.18", "0"], ["84028.91", "0"], ["84028.86", "0.007340"], ["84028.67", "0"], ["84028.66", "0"], ["84028.50", "0.007944"], ["84028.39", "0.008995"], ["84028.17", "0.025187"], ["84028.06", "0.224907"], ["84028.01", "0.017353"], ["84027.94", "0.008186"], ["84027.60", "0.764250"], ["84027.30", "0"], ["84027.21", "0.781760"], ["84027.19", "0"], ["84026.33", "0.051969"], ["84026.31", "0"], ["84026.12", "0.012657"], ["84025.48", "0.018519"], ["84024.50", "0.144510"], ["84024.39", "0"], ["84024.03", "0"], ["84023.80", "0"], ["84023.73", "0.222694"], ["84023.29", "0.076121"], ["84023.15", "0.021132"], ["84004.00", "0.000017"], ["83992.00", "5.256011"], ["83983.50", "4.893527"], ["83975.00", "5.165390"], ["83966.50", "4.168560"], ["83958.00", "5.437252"], ["83949.50", "3.987319"], ["83941.00", "4.621665"], ["83932.50", "3.896698"], ["83924.00", "5.527873"], ["83915.50", "5.346632"], ["83907.00", "4.802906"], ["83898.50", "5.074769"], ["83890.00", "4.349802"], ["83881.50", "4.984148"], ["83873.00", "4.077939"], ["83864.50", "5.618494"], ["83856.00", "4.712286"], ["83847.50", "4.259181"], ["83839.00", "4.440423"], ["83830.50", "4.531044"], ["83652.48", "0"], ["83651.65", "0"]], "checksum": -642400685, "ts": "1742555172445"}], "ts": 1742555172449, "record_time": 1742555172.474116, "EXCHANGE": "BITGET"}
{"action": "update", "arg": {"instType": "SPOT", "channel": "books", "instId": "BTCUSDT"}, "data": [{"asks": [["84079.32", "0.110489"], ["84079.67", "0"], ["84084.56", "0"], ["84110.20", "0.324010"], ["84112.20", "0.852657"], ["84114.20", "2.243834"], ["84116.20", "5.904826"], ["84118.20", "15.539017"], ["84160.20", "4.893527"], ["84168.70", "4.531044"], ["84177.20", "5.618494"], ["84185.70", "4.440423"], ["84194.20", "5.346632"], ["84202.70", "4.621665"], ["84211.20", "4.259181"], ["84219.70", "5.527873"], ["84228.20", "4.802906"], ["84236.70", "5.256011"], ["84245.20", "5.074769"], ["84253.70", "5.437252"], ["84262.20", "4.712286"], ["84270.70", "4.984148"], ["84279.20", "3.987319"], ["84287.70", "4.077939"], ["84296.20", "4.349802"], ["84304.70", "3.896698"], ["84313.20", "5.165390"], ["84321.70", "4.168560"], ["84536.36", "0.000053"]], "bids": [["84053.79", "0.041107"], ["84053.78", "0"], ["84053.38", "0.027856"], ["84040.00", "0.093280"], ["84038.00", "0.245475"], ["84036.00", "0.645987"], ["84034.00", "1.699966"], ["84030.80", "0.685560"], ["83992.00", "4.259181"], ["83983.50", "4.984148"], ["83975.00", "4.168560"], ["83966.50", "5.165390"], ["83958.00", "5.618494"], ["83949.50", "3.896698"], ["83941.00", "4.349802"], ["83932.50", "5.527873"], ["83924.00", "4.531044"], ["83915.50", "5.256011"], ["83907.00", "4.440423"], ["83898.50", "4.893527"], ["83890.00", "4.712286"], ["83881.50", "4.077939"], ["83873.00", "5.346632"], ["83864.50", "5.437252"], ["83856.00", "3.987319"], ["83847.50", "4.621665"], ["83839.00", "5.074769"], ["83830.50", "4.802906"], ["83652.80", "0"]], "checksum": -360284498, "ts": "1742555172650"}], "ts": 1742555172654, "record_time": 1742555172.676758, "EXCHANGE": "BITGET"}
{"action": "update", "arg": {"instType": "SPOT", "channel": "books", "instId": "BTCUSDT"}, "data": [{"asks": [["84104.20", "0.017581"], ["84106.20", "0.046265"], ["84108.20", "0.121750"], ["84110.20", "0.320394"], ["84112.20", "0.843144"], ["84114.20", "2.218800"], ["84116.20", "5.838945"], ["84118.20", "15.365646"], ["84126.90", "0.079500"], ["84160.20", "4.802906"], ["84168.70", "4.440423"], ["84177.20", "5.346632"], ["84185.70", "5.074769"], ["84194.20", "5.527873"], ["84202.70", "5.165390"], ["84211.20", "3.987319"], ["84219.70", "4.168560"], ["84228.20", "4.893527"], ["84236.70", "4.077939"], ["84245.20", "4.712286"], ["84253.70", "5.256011"], ["84262.20", "5.618494"], ["84270.70", "4.621665"], ["84279.20", "4.531044"], ["84287.70", "4.349802"], ["84296.20", "3.896698"], ["84304.70", "4.984148"], ["84313.20", "5.437252"], ["84321.70", "4.259181"]], "bids": [["84042.00", "0.035687"], ["84040.00", "0.093915"], ["84038.00", "0.247143"], ["84036.00", "0.650376"], ["84034.00", "1.711516"], ["84030.40", "0.591870"], ["84024.50", "0"], ["83992.00", "3.896698"], ["83983.50", "4.168560"], ["83975.00", "3.987319"], ["83966.50", "5.437252"], ["83958.00", "4.531044"], ["83949.50", "5.527873"], ["83941.00", "4.712286"], ["83932.50", "5.165390"], ["83924.00", "5.256011"], ["83915.50", "4.893527"], ["83907.00", "4.259181"], ["83898.50", "5.346632"], ["83890.00", "4.621665"], ["83881.50", "5.618494"], ["83873.00", "4.077939"], ["83864.50", "4.440423"], ["83856.00", "4.349802"], ["83847.50", "4.984148"], ["83652.80", "0.000119"]], "checksum": 836888640, "ts": "1742555172856"}], "ts": 1742555172857, "record_time": 1742555172.887184, "EXCHANGE": "BITGET"}
{"action": "update", "arg": {"instType": "SPOT", "channel": "books", "instId": "BTCUSDT"}, "data": [{"asks": [["84108.20", "0.121916"], ["84110.20", "0.320831"], ["84112.20", "0.844293"], ["84114.20", "2.221823"], ["84116.20", "5.846904"], ["84118.20", "15.386590"], ["84160.20", "4.984148"], ["84168.70", "5.165390"], ["84177.20", "4.531044"], ["84185.70", "5.256011"], ["84194.20", "5.346632"], ["84202.70", "4.349802"], ["84211.20", "5.618494"], ["84219.70", "4.712286"], ["84228.20", "4.259181"], ["84236.70", "4.893527"], ["84245.20", "3.987319"], ["84253.70", "4.621665"], ["84262.20", "4.077939"], ["84270.70", "5.527873"], ["84279.20", "4.440423"], ["84287.70", "4.802906"], ["84296.20", "4.168560"], ["84304.70", "5.074769"], ["84321.70", "3.896698"]], "bids": [["84048.00", "0.002169"], ["84046.00", "0.005707"], ["84044.00", "0.015018"], ["84042.00", "0.039522"], ["84040.10", "0.005920"], ["84040.00", "0.104005"], ["84038.00", "0.273915"], ["84036.00", "0.720830"], ["84034.00", "1.896921"], ["84030.80", "0.905970"], ["84029.00", "1.050990"], ["84027.60", "0"], ["84024.50", "0.144510"], ["84002.00", "0.000015"], ["83992.00", "4.259181"], ["83966.50", "4.349802"], ["83958.00", "5.618494"], ["83949.50", "5.256011"], ["83941.00", "4.621665"], ["83932.50", "5.527873"], ["83924.00", "4.440423"], ["83915.50", "4.712286"], ["83907.00", "4.531044"], ["83898.50", "5.437252"], ["83890.00", "5.346632"], ["83881.50", "4.893527"], ["83873.00", "3.896698"], ["83864.50", "4.802906"], ["83856.00", "5.074769"], ["83839.00", "5.165390"], ["83830.50", "4.077939"]], "checksum": -1314261607, "ts": "1742555173064"}], "ts": 1742555173066, "record_time": 1742555173.089328, "EXCHANGE": "BITGET"}
{"action": "update", "arg": {"instType": "SPOT", "channel": "books", "instId": "BTCUSDT"}, "data": [{"asks": [["84054.01", "1.574956"], ["84116.20", "5.847032"], ["84118.20", "15.386924"], ["84118.30", "0.144720"], ["84119.80", "0.035880"], ["84120.10", "0.067980"], ["84120.80", "0"], ["84121.10", "0.269760"], ["84122.50", "0.551340"], ["84123.20", "0"], ["84123.70", "0.356940"], ["84126.10", "0.166440"], ["84127.70", "0.178410"], ["84160.20", "5.437252"], ["84168.70", "4.531044"], ["84177.20", "5.256011"], ["84185.70", "4.077939"], ["84194.20", "4.259181"], ["84202.70", "5.346632"], ["84211.20", "4.168560"], ["84219.70", "4.621665"], ["84228.20", "4.984148"], ["84236.70", "4.440423"], ["84245.20", "3.896698"], ["84253.70", "4.349802"], ["84262.20", "4.893527"], ["84270.70", "3.987319"], ["84279.20", "5.165390"], ["84287.70", "5.527873"], ["84296.20", "4.802906"], ["84304.70", "4.712286"], ["84313.20", "5.618494"], ["84321.70", "5.074769"], ["84535.32", "0"], ["84536.36", "0"]], "bids": [["84054.00", "0.020100"], ["84053.80", "0.041107"], ["84053.79", "0"], ["84053.38", "0"], ["84048.00", "0.001006"], ["84046.00", "0.002646"], ["84045.51", "0"], ["84044.00", "0.006964"], ["84042.00", "0.018327"], ["84040.00", "0.048229"], ["84038.00", "0.126916"], ["84036.90", "0.021425"], ["84036.00", "0.333992"], ["84034.00", "0.879110"], ["84033.90", "0.007260"], ["84033.40", "0.228330"], ["84030.80", "0"], ["84030.40", "0.070200"], ["84030.20", "0"], ["84029.80", "0.030210"], ["84029.10", "0"], ["84029.00", "0.006870"], ["84027.50", "0.120210"], ["84027.21", "0"], ["84027.20", "1.124790"], ["84026.40", "0"], ["84025.40", "2.604960"], ["84025.10", "0.067710"], ["84023.40", "0.949170"], ["83992.00", "5.346632"], ["83983.50", "5.437252"], ["83975.00", "5.527873"], ["83966.50", "5.165390"], ["83958.00", "4.349802"], ["83949.50", "4.531044"], ["83941.00", "4.984148"], ["83932.50", "3.987319"], ["83924.00", "3.896698"], ["83915.50", "4.440423"], ["83907.00", "5.256011"], ["83898.50", "5.618494"], ["83890.00", "4.077939"], ["83881.50", "4.259181"], ["83873.00", "5.074769"], ["83864.50", "4.621665"], ["83856.00", "4.893527"], ["83847.50", "4.712286"], ["83839.00", "4.168560"], ["83830.50", "4.802906"], ["83652.48", "0.000188"], ["83651.65", "0.000018"], ["83651.16", "0.000896"]], "checksum": -177646480, "ts": "1742555173275"}], "ts": 1742555173277, "record_time": 1742555173.302306, "EXCHANGE": "BITGET"}
{"action": "update", "arg": {"instType": "SPOT", "channel": "books", "instId": "BTCUSDT"}, "data": [{"asks": [["84054.01", "1.114956"], ["84073.48", "0"], ["84074.12", "0.119870"], ["84077.68", "0.006356"], ["84077.84", "0.006356"], ["84078.34", "0.016429"], ["84078.76", "0"], ["84079.10", "0.006356"], ["84079.35", "0.006356"], ["84079.76", "0"], ["84082.66", "0.119850"], ["84083.49", "0"], ["84083.61", "0"], ["84083.78", "0.119867"], ["84087.16", "0"], ["84087.95", "0.015892"], ["84088.25", "0"], ["84088.90", "0.010988"], ["84104.20", "0.017929"], ["84106.20", "0.047182"], ["84107.10", "0"], ["84108.02", "0.001598"], ["84108.20", "0.124164"], ["84110.20", "0.326747"], ["84112.20", "0.859859"], ["84114.20", "2.262788"], ["84116.20", "5.954705"], ["84118.20", "15.670277"], ["84122.40", "0.120000"], ["84124.50", "2.190990"], ["84125.80", "0.263670"], ["84126.70", "0"], ["84127.50", "0.642210"], ["84127.70", "0"], ["84127.80", "0"], ["84160.20", "5.256011"], ["84168.70", "4.621665"], ["84177.20", "5.527873"], ["84185.70", "5.346632"], ["84194.20", "5.437252"], ["84202.70", "4.168560"], ["84211.20", "5.165390"], ["84219.70", "4.077939"], ["84228.20", "3.896698"], ["84236.70", "4.712286"], ["84245.20", "5.618494"], ["84262.20", "4.440423"], ["84270.70", "4.802906"], ["84279.20", "4.984148"], ["84287.70", "4.531044"], ["84296.20", "4.259181"], ["84304.70", "3.987319"], ["84313.20", "4.893527"]], "bids": [["84054.00", "0.001035"], ["84050.58", "0.027856"], ["84038.00", "0.126726"], ["84036.31", "0.413388"], ["84036.00", "0.333489"], ["84034.00", "0.877604"], ["84033.41", "0"], ["84032.94", "0.247615"], ["84032.29", "0"], ["84031.78", "0.083949"], ["84031.73", "0.004018"], ["84030.86", "0"], ["84030.18", "0"], ["84030.16", "0"], ["84029.43", "0.017105"], ["84029.25", "0.007132"], ["84028.75", "0.028868"], ["84027.00", "2.356320"], ["84026.80", "0.386160"], ["84025.44", "0"], ["84025.40", "0.248580"], ["84024.49", "0.268406"], ["84023.26", "0.259825"], ["84022.97", "0"], ["84019.03", "0.073223"], ["84018.29", "0.056373"], ["84018.24", "0"], ["84017.64", "0"], ["83997.74", "0.001176"], ["83996.83", "0"], ["83983.50", "4.621665"], ["83975.00", "4.168560"], ["83966.50", "4.984148"], ["83958.00", "3.896698"], ["83949.50", "5.256011"], ["83941.00", "5.527873"], ["83932.50", "5.437252"], ["83924.00", "4.802906"], ["83915.50", "4.349802"], ["83907.00", "3.987319"], ["83898.50", "4.893527"], ["83890.00", "4.440423"], ["83881.50", "5.074769"], ["83873.00", "4.259181"], ["83864.50", "4.531044"], ["83856.00", "5.618494"], ["83847.50", "5.165390"], ["83839.00", "4.077939"], ["83830.50", "4.712286"], ["83651.65", "0"], ["83651.16", "0"]], "checksum": 2051810202, "ts": "1742555173480"}], "ts": 1742555173482, "record_time": 1742555173.508443, "EXCHANGE": "BITGET"}
{"action": "update", "arg": {"instType": "SPOT", "channel": "books", "instId": "BTCUSDT"}, "data": [{"asks": [["84054.01", "1.552143"], ["84109.18", "0"], ["84110.04", "0.001597"], ["84116.20", "5.954543"], ["84118.20", "15.669849"], ["84121.60", "0.120000"], ["84122.30", "0.356940"], ["84122.50", "2.647080"], ["84123.30", "0.812880"], ["84123.70", "0"], ["84124.00", "0"], ["84126.70", "0.216000"], ["84127.50", "0.150210"], ["84127.60", "0"], ["84160.20", "4.259181"], ["84168.70", "5.618494"], ["84177.20", "5.165390"], ["84185.70", "4.349802"], ["84194.20", "4.984148"], ["84202.70", "3.987319"], ["84211.20", "4.712286"], ["84219.70", "5.346632"], ["84228.20", "5.074769"], ["84236.70", "4.621665"], ["84245.20", "4.168560"], ["84253.70", "4.893527"], ["84262.20", "4.077939"], ["84270.70", "5.527873"], ["84279.20", "3.896698"], ["84287.70", "5.437252"], ["84296.20", "4.440423"], ["84304.70", "4.802906"], ["84313.20", "4.531044"], ["84321.70", "5.256011"]], "bids": [["84042.82", "0.010000"], ["84034.00", "0.877381"], ["84033.41", "0.313822"], ["84027.21", "1.297688"], ["84025.80", "0.787650"], ["84003.00", "0.000017"], ["83995.89", "0.001173"], ["83995.03", "0"], ["83992.00", "4.531044"], ["83983.50", "5.527873"], ["83975.00", "4.077939"], ["83958.00", "4.349802"], ["83949.50", "5.437252"], ["83941.00", "4.259181"], ["83932.50", "4.893527"], ["83924.00", "5.074769"], ["83915.50", "5.618494"], ["83907.00", "4.168560"], ["83898.50", "4.712286"], ["83890.00", "4.621665"], ["83881.50", "5.346632"], ["83873.00", "4.440423"], ["83864.50", "5.165390"], ["83856.00", "5.256011"], ["83847.50", "3.896698"], ["83839.00", "3.987319"], ["83830.50", "4.802906"], ["83653.67", "0"], ["83653.31", "0"], ["83652.80", "0"], ["83652.48", "0"]], "checksum": 260740513, "ts": "1742555173681"}], "ts": 1742555173685, "record_time": 1742555173.713134, "EXCHANGE": "BITGET"}
{"action": "update", "arg": {"instType": "SPOT", "channel": "books", "instId": "BTCUSDT"}, "data": [{"asks": [["84084.30", "0.012533"], ["84125.80", "0.319740"], ["84125.90", "0"], ["84160.20", "4.984148"], ["84168.70", "5.256011"], ["84177.20", "4.802906"], ["84185.70", "3.987319"], ["84194.20", "5.437252"], ["84202.70", "4.077939"], ["84211.20", "5.527873"], ["84219.70", "4.259181"], ["84228.20", "4.349802"], ["84236.70", "3.896698"], ["84245.20", "5.074769"], ["84253.70", "4.621665"], ["84262.20", "4.893527"], ["84270.70", "5.165390"], ["84279.20", "4.712286"], ["84287.70", "5.618494"], ["84304.70", "5.346632"], ["84313.20", "4.168560"], ["84321.70", "4.531044"]], "bids": [["84050.58", "0"], ["84034.00", "0.877641"], ["84027.70", "0.686190"], ["84027.50", "0.120000"], ["84026.80", "0"], ["84023.41", "0.239160"], ["84016.61", "0.000876"], ["84016.36", "0"], ["83998.15", "0.003597"], ["83998.02", "0"], ["83992.00", "5.165390"], ["83983.50", "3.987319"], ["83975.00", "4.440423"], ["83966.50", "5.618494"], ["83958.00", "4.077939"], ["83949.50", "5.074769"], ["83941.00", "5.527873"], ["83924.00", "4.168560"], ["83915.50", "4.349802"], ["83907.00", "5.346632"], ["83898.50", "4.802906"], ["83890.00", "4.984148"], ["83881.50", "5.256011"], ["83873.00", "4.531044"], ["83864.50", "4.621665"], ["83856.00", "4.259181"], ["83839.00", "4.712286"], ["83830.50", "5.437252"]], "checksum": -441828205, "ts": "1742555173883"}], "ts": 1742555173885, "record_time": 1742555173.912353, "EXCHANGE": "BITGET"}
{"action": "update", "arg": {"instType": "SPOT", "channel": "books", "instId": "BTCUSDT"}, "data": [{"asks": [["84090.49", "0.010000"], ["84102.20", "0.006827"], ["84108.20", "0.124020"], ["84110.20", "0.326369"], ["84112.20", "0.858866"], ["84114.20", "2.260172"], ["84116.20", "5.947821"], ["84118.20", "15.652160"], ["84118.30", "0.145140"], ["84119.40", "0"], ["84127.50", "0"], ["84160.20", "5.074769"], ["84168.70", "5.165390"], ["84177.20", "4.259181"], ["84185.70", "4.984148"], ["84194.20", "4.168560"], ["84202.70", "5.346632"], ["84211.20", "4.621665"], ["84219.70", "4.802906"], ["84228.20", "3.896698"], ["84236.70", "3.987319"], ["84245.20", "4.531044"], ["84253.70", "4.077939"], ["84262.20", "5.618494"], ["84270.70", "4.440423"], ["84279.20", "5.527873"], ["84287.70", "5.437252"], ["84296.20", "4.349802"], ["84304.70", "5.256011"], ["84313.20", "4.712286"], ["84321.70", "4.893527"], ["84535.32", "0.000039"]], "bids": [["84053.81", "0.041107"], ["84053.80", "0"], ["84038.00", "0.126890"], ["84036.00", "0.333921"], ["84034.00", "0.878738"], ["84029.90", "0.278220"], ["84027.70", "0.685980"], ["84026.70", "1.071750"], ["84025.80", "0"], ["84025.10", "0"], ["83983.50", "4.621665"], ["83975.00", "4.259181"], ["83966.50", "3.896698"], ["83958.00", "5.527873"], ["83949.50", "4.077939"], ["83941.00", "4.893527"], ["83932.50", "5.256011"], ["83924.00", "4.531044"], ["83915.50", "3.987319"], ["83907.00", "4.349802"], ["83898.50", "5.618494"], ["83890.00", "5.437252"], ["83881.50", "4.984148"], ["83873.00", "4.712286"], ["83864.50", "5.074769"], ["83856.00", "4.802906"], ["83847.50", "5.346632"], ["83839.00", "4.168560"], ["83830.50", "4.440423"], ["83653.67", "0.001695"], ["83653.31", "0.000015"]], "checksum": -634081339, "ts": "1742555174084"}], "ts": 1742555174087, "record_time": 1742555174.110555, "EXCHANGE": "BITGET"}
{"action": "update", "arg": {"instType": "SPOT", "channel": "books", "instId": "BTCUSDT"}, "data": [{"asks": [["84118.30", "0"], ["84119.40", "0.001038"], ["84119.80", "0.036300"], ["84120.10", "0.068190"], ["84121.10", "0"], ["84121.20", "0.144510"], ["84123.10", "0.356940"], ["84127.09", "0"], ["84160.20", "5.437252"], ["84168.70", "5.256011"], ["84177.20", "4.621665"], ["84185.70", "4.349802"], ["84194.20", "4.259181"], ["84202.70", "5.074769"], ["84211.20", "4.531044"], ["84228.20", "3.987319"], ["84236.70", "5.346632"], ["84245.20", "4.893527"], ["84253.70", "4.440423"], ["84270.70", "4.168560"], ["84279.20", "4.984148"], ["84287.70", "5.527873"], ["84296.20", "5.165390"], ["84304.70", "3.896698"], ["84321.70", "4.077939"]], "bids": [["84054.00", "0.035577"], ["84053.64", "0.027856"], ["84048.00", "0.002170"], ["84046.00", "0.005710"], ["84044.00", "0.015026"], ["84042.00", "0.039544"], ["84040.00", "0.104061"], ["84038.00", "0.273846"], ["84036.00", "0.720646"], ["84034.00", "1.896437"], ["84032.00", "0.475620"], ["84030.10", "1.349250"], ["84029.90", "0.278010"], ["84029.80", "0.030000"], ["84027.70", "0"], ["84026.70", "0.120000"], ["84004.00", "0"], ["83992.00", "4.531044"], ["83983.50", "4.168560"], ["83975.00", "4.077939"], ["83966.50", "3.987319"], ["83949.50", "5.437252"], ["83941.00", "3.896698"], ["83932.50", "5.165390"], ["83924.00", "4.712286"], ["83915.50", "5.346632"], ["83907.00", "4.984148"], ["83898.50", "4.621665"], ["83890.00", "4.802906"], ["83881.50", "5.256011"], ["83873.00", "4.259181"], ["83864.50", "4.349802"], ["83856.00", "4.440423"], ["83847.50", "5.618494"], ["83839.00", "4.893527"], ["83830.50", "5.074769"]], "checksum": 278384183, "ts": "1742555174307"}], "ts": 1742555174309, "record_time": 1742555174.331773, "EXCHANGE": "BITGET"}
{"action": "update", "arg": {"instType": "SPOT", "channel": "books", "instId": "BTCUSDT"}, "data": [{"asks": [["84114.20", "2.260062"], ["84116.20", "5.947531"], ["84118.20", "15.651528"], ["84120.40", "0.269760"], ["84127.40", "0"], ["84160.20", "4.440423"], ["84168.70", "4.168560"], ["84177.20", "4.712286"], ["84185.70", "5.527873"], ["84194.20", "4.621665"], ["84202.70", "3.987319"], ["84211.20", "4.349802"], ["84219.70", "4.259181"], ["84228.20", "4.531044"], ["84236.70", "5.256011"], ["84245.20", "5.346632"], ["84253.70", "4.802906"], ["84262.20", "4.984148"], ["84270.70", "4.077939"], ["84279.20", "5.437252"], ["84287.70", "3.896698"], ["84296.20", "4.893527"], ["84304.70", "5.074769"], ["84313.20", "5.165390"], ["84321.70", "5.618494"]], "bids": [["84053.64", "0"], ["84052.22", "0.027856"], ["84038.00", "0.273649"], ["84036.31", "0.782909"], ["84036.00", "0.720130"], ["84034.00", "1.895080"], ["84032.00", "0.000032"], ["84030.10", "0.935220"], ["84029.90", "0.278220"], ["84029.80", "0.015000"], ["84027.21", "0.206997"], ["84004.00", "0.000015"], ["83992.00", "4.259181"], ["83983.50", "5.165390"], ["83975.00", "5.618494"], ["83966.50", "4.802906"], ["83949.50", "4.893527"], ["83941.00", "4.440423"], ["83932.50", "5.437252"], ["83924.00", "3.987319"], ["83915.50", "4.077939"], ["83907.00", "4.531044"], ["83898.50", "4.168560"], ["83890.00", "5.346632"], ["83873.00", "4.349802"], ["83864.50", "5.074769"], ["83856.00", "4.621665"], ["83847.50", "4.712286"], ["83839.00", "3.896698"], ["83830.50", "4.984148"], ["83653.31", "0"]], "checksum": 251652985, "ts": "1742555174507"}], "ts": 1742555174509, "record_time": 1742555174.534409, "EXCHANGE": "BITGET"}
{"action": "update", "arg": {"instType": "SPOT", "channel": "books", "instId": "BTCUSDT"}, "data": [{"asks": [["84124.50", "3.038880"], ["84160.20", "5.437252"], ["84168.70", "5.618494"], ["84177.20", "5.256011"], ["84185.70", "5.165390"], ["84194.20", "5.346632"], ["84202.70", "4.259181"], ["84219.70", "4.440423"], ["84228.20", "4.621665"], ["84236.70", "4.712286"], ["84245.20", "3.987319"], ["84253.70", "4.893527"], ["84262.20", "5.074769"], ["84270.70", "5.527873"], ["84279.20", "3.896698"], ["84287.70", "4.077939"], ["84296.20", "4.984148"], ["84304.70", "4.802906"], ["84313.20", "4.168560"], ["84321.70", "4.531044"]], "bids": [["84053.82", "0.041107"], ["84053.81", "0"], ["84048.00", "0.002168"], ["84046.00", "0.005706"], ["84044.00", "0.015016"], ["84042.00", "0.039515"], ["84040.00", "0.103987"], ["84033.41", "0.621295"], ["84030.10", "0"], ["84029.90", "0.401550"], ["84029.80", "0"], ["84022.80", "1.518360"], ["83992.00", "5.165390"], ["83983.50", "4.712286"], ["83975.00", "4.440423"], ["83966.50", "5.437252"], ["83958.00", "4.893527"], ["83949.50", "4.259181"], ["83941.00", "4.349802"], ["83932.50", "3.896698"], ["83924.00", "5.346632"], ["83915.50", "5.256011"], ["83907.00", "4.077939"], ["83898.50", "3.987319"], ["83890.00", "4.621665"], ["83881.50", "4.802906"], ["83873.00", "5.618494"], ["83864.50", "4.168560"], ["83856.00", "4.531044"], ["83847.50", "5.074769"], ["83839.00", "4.984148"], ["83830.50", "5.527873"], ["83653.31", "0.000015"]], "checksum": 2032747233, "ts": "1742555174709"}], "ts": 1742555174714, "record_time": 1742555174.737154, "EXCHANGE": "BITGET"}
{"action": "update", "arg": {"instType": "SPOT", "channel": "books", "instId": "BTCUSDT"}, "data": [{"asks": [["84160.20", "5.256011"], ["84168.70", "4.168560"], ["84177.20", "4.440423"], ["84185.70", "4.712286"], ["84194.20", "4.259181"], ["84202.70", "4.531044"], ["84211.20", "5.437252"], ["84219.70", "4.349802"], ["84226.33", "0.024945"], ["84228.20", "4.893527"], ["84236.70", "4.621665"], ["84245.20", "5.346632"], ["84253.70", "3.987319"], ["84262.20", "5.618494"], ["84270.70", "3.896698"], ["84279.20", "5.527873"], ["84286.96", "0"], ["84287.70", "4.984148"], ["84296.20", "5.165390"], ["84304.70", "4.077939"], ["84313.20", "5.074769"], ["84321.70", "4.802906"]], "bids": [["84044.00", "0.015231"], ["84042.00", "0.040081"], ["84040.00", "0.105476"], ["84038.00", "0.277568"], ["84036.00", "0.730442"], ["84034.00", "1.922217"], ["84033.41", "0.313822"], ["84023.41", "0"], ["84022.70", "0.120000"], ["84002.00", "0.000032"], ["83992.00", "5.074769"], ["83983.50", "3.896698"], ["83975.00", "4.893527"], ["83966.50", "5.618494"], ["83958.00", "4.531044"], ["83949.50", "4.984148"], ["83941.00", "5.256011"], ["83932.50", "5.346632"], ["83924.00", "4.621665"], ["83915.50", "4.802906"], ["83907.00", "4.712286"], ["83898.50", "4.440423"], ["83890.00", "4.077939"], ["83881.50", "5.437252"], ["83873.00", "5.527873"], ["83864.50", "4.259181"], ["83856.00", "4.168560"], ["83847.50", "3.987319"], ["83839.00", "4.349802"], ["83830.50", "5.165390"]], "checksum": -1426643801, "ts": "1742555174924"}], "ts": 1742555174927, "record_time": 1742555174.949346, "EXCHANGE": "BITGET"}
{"action": "update", "arg": {"instType": "SPOT", "channel": "books", "instId": "BTCUSDT"}, "data": [{"asks": [["84108.20", "0.124243"], ["84110.20", "0.326955"], ["84112.20", "0.860407"], ["84114.20", "2.264230"], ["84116.20", "5.958501"], ["84118.20", "15.680265"], ["84160.20", "5.165390"], ["84177.20", "4.712286"], ["84185.70", "5.074769"], ["84202.70", "4.349802"], ["84211.20", "4.077939"], ["84219.70", "5.527873"], ["84228.20", "5.437252"], ["84236.70", "5.618494"], ["84245.20", "4.802906"], ["84253.70", "4.893527"], ["84262.20", "4.531044"], ["84270.70", "3.987319"], ["84279.20", "4.621665"], ["84296.20", "4.440423"], ["84304.70", "5.346632"], ["84313.20", "5.256011"], ["84321.70", "3.896698"]], "bids": [["84029.90", "0.786840"], ["84029.70", "0.514650"], ["84027.70", "0.820560"], ["84027.21", "1.155965"], ["84022.80", "0"], ["84022.70", "0"], ["84002.00", "0.000017"], ["83992.00", "4.259181"], ["83983.50", "4.531044"], ["83975.00", "4.712286"], ["83966.50", "4.621665"], ["83958.00", "5.256011"], ["83949.50", "4.440423"], ["83941.00", "5.346632"], ["83932.50", "5.527873"], ["83924.00", "4.893527"], ["83915.50", "3.987319"], ["83907.00", "3.896698"], ["83898.50", "5.074769"], ["83890.00", "4.984148"], ["83881.50", "4.802906"], ["83873.00", "5.437252"], ["83864.50", "4.077939"], ["83856.00", "4.349802"], ["83847.50", "5.165390"], ["83839.00", "4.168560"], ["83830.50", "5.618494"]], "checksum": -1426643801, "ts": "1742555175130"}], "ts": 1742555175135, "record_time": 1742555175.157201, "EXCHANGE": "BITGET"}
{"action": "update", "arg": {"instType": "SPOT", "channel": "books", "instId": "BTCUSDT"}, "data": [{"asks": [["84160.20", "4.802906"], ["84168.70", "3.987319"], ["84177.20", "4.984148"], ["84185.70", "3.896698"], ["84194.20", "4.440423"], ["84202.70", "4.712286"], ["84211.20", "5.346632"], ["84219.70", "5.618494"], ["84228.20", "5.074769"], ["84236.70", "4.349802"], ["84245.20", "4.893527"], ["84253.70", "4.077939"], ["84262.20", "5.165390"], ["84270.70", "5.437252"], ["84279.20", "5.256011"], ["84287.70", "4.168560"], ["84296.20", "4.259181"], ["84304.70", "4.621665"], ["84313.20", "5.527873"], ["84321.70", "4.531044"]], "bids": [["84033.41", "0.643210"], ["84029.90", "0.786420"], ["84027.21", "0.206997"], ["84022.80", "1.518360"], ["83992.00", "4.893527"], ["83983.50", "5.346632"], ["83975.00", "5.437252"], ["83966.50", "4.531044"], ["83958.00", "4.621665"], ["83941.00", "4.077939"], ["83932.50", "4.259181"], ["83924.00", "4.168560"], ["83915.50", "4.802906"], ["83907.00", "5.618494"], ["83898.50", "3.987319"], ["83890.00", "5.165390"], ["83881.50", "5.256011"], ["83873.00", "4.712286"], ["83864.50", "4.349802"], ["83856.00", "5.074769"], ["83847.50", "4.984148"], ["83839.00", "3.896698"], ["83830.50", "5.527873"], ["83653.31", "0"]], "checksum": -1426643801, "ts": "1742555175333"}], "ts": 1742555175336, "record_time": 1742555175.35826, "EXCHANGE": "BITGET"}
{"action": "update", "arg": {"instType": "SPOT", "channel": "books", "instId": "BTCUSDT"}, "data": [{"asks": [["84054.01", "1.092143"], ["84098.20", "0.001656"], ["84100.20", "0.002701"], ["84102.20", "0.007108"], ["84104.20", "0.018705"], ["84106.20", "0.049226"], ["84108.20", "0.129540"], ["84110.20", "0.340895"], ["84112.20", "0.897093"], ["84114.20", "2.360770"], ["84116.20", "6.212553"], ["84118.20", "16.348823"], ["84124.10", "3.754080"], ["84160.20", "3.896698"], ["84168.70", "5.527873"], ["84177.20", "5.346632"], ["84185.70", "4.440423"], ["84194.20", "4.349802"], ["84202.70", "5.618494"], ["84211.20", "4.712286"], ["84219.70", "4.077939"], ["84228.20", "4.531044"], ["84236.70", "5.256011"], ["84245.20", "5.165390"], ["84253.70", "4.893527"], ["84262.20", "4.168560"], ["84270.70", "4.984148"], ["84279.20", "5.074769"], ["84287.70", "4.802906"], ["84296.20", "5.437252"], ["84304.70", "4.259181"], ["84313.20", "3.987319"], ["84321.70", "4.621665"]], "bids": [["84053.83", "0.041107"], ["84053.82", "0"], ["84052.22", "0"], ["84027.21", "0.837939"], ["84025.40", "0.319860"], ["84022.80", "0"], ["84003.00", "0"], ["83992.00", "4.802906"], ["83983.50", "4.077939"], ["83975.00", "5.256011"], ["83966.50", "4.712286"], ["83960.46", "0"], ["83958.00", "5.527873"], ["83949.50", "4.531044"], ["83941.00", "5.074769"], ["83932.50", "5.437252"], ["83924.00", "3.896698"], ["83915.50", "4.349802"], ["83890.00", "4.168560"], ["83881.50", "5.165390"], ["83873.00", "4.984148"], ["83864.50", "4.893527"], ["83856.00", "4.259181"], ["83847.50", "5.346632"], ["83839.00", "4.621665"], ["83830.50", "4.440423"], ["83653.31", "0.000015"], ["83652.80", "0.000119"], ["83652.48", "0.000188"], ["83651.65", "0.000018"]], "checksum": 832838880, "ts": "1742555175536"}], "ts": 1742555175540, "record_time": 1742555175.56643, "EXCHANGE": "BITGET"}
{"action": "update", "arg": {"instType": "SPOT", "channel": "books", "instId": "BTCUSDT"}, "data": [{"asks": [["84054.01", "1.552143"], ["84102.20", "0.007109"], ["84104.20", "0.018707"], ["84106.20", "0.049230"], ["84108.20", "0.129551"], ["84110.20", "0.340924"], ["84112.20", "0.897169"], ["84114.20", "2.360972"], ["84116.20", "6.213083"], ["84118.20", "16.350218"], ["84160.20", "4.349802"], ["84168.70", "5.074769"], ["84171.24", "0.125626"], ["84177.20", "5.618494"], ["84180.79", "0"], ["84185.70", "5.165390"], ["84194.20", "4.531044"], ["84202.70", "4.893527"], ["84211.20", "4.077939"], ["84219.70", "4.984148"], ["84228.20", "4.259181"], ["84236.70", "4.802906"], ["84245.20", "4.621665"], ["84253.70", "5.527873"], ["84262.20", "5.346632"], ["84270.70", "3.896698"], ["84279.20", "4.440423"], ["84287.70", "4.712286"], ["84296.20", "5.256011"], ["84304.70", "5.437252"], ["84321.70", "4.168560"]], "bids": [["84050.00", "0.027888"], ["84042.82", "0"], ["84029.90", "0.278220"], ["84029.70", "0.978570"], ["84028.10", "0.074610"], ["84025.40", "0.248580"], ["83992.00", "3.987319"], ["83983.50", "5.618494"], ["83975.00", "4.893527"], ["83966.50", "4.077939"], ["83958.00", "5.437252"], ["83950.26", "0.012357"], ["83949.50", "5.346632"], ["83941.00", "4.349802"], ["83932.50", "4.802906"], ["83924.00", "5.165390"], ["83915.50", "5.256011"], ["83907.00", "4.440423"], ["83898.50", "4.621665"], ["83890.00", "4.712286"], ["83881.50", "4.531044"], ["83873.00", "4.168560"], ["83864.50", "3.896698"], ["83847.50", "4.984148"], ["83839.00", "5.074769"], ["83830.50", "5.527873"], ["83651.65", "0"]], "checksum": 2047772147, "ts": "1742555175745"}], "ts": 1742555175749, "record_time": 1742555175.786874, "EXCHANGE": "BITGET"}
{"action": "update", "arg": {"instType": "SPOT", "channel": "books", "instId": "BTCUSDT"}, "data": [{"asks": [["84112.20", "0.897272"], ["84114.20", "2.361243"], ["84116.20", "6.213797"], ["84118.20", "16.352097"], ["84120.90", "0.462270"], ["84126.90", "0"], ["84160.20", "5.256011"], ["84168.70", "4.531044"], ["84177.20", "4.621665"], ["84185.70", "4.259181"], ["84194.20", "4.984148"], ["84202.70", "4.712286"], ["84211.20", "5.074769"], ["84219.70", "4.802906"], ["84228.20", "5.437252"], ["84236.70", "5.527873"], ["84245.20", "3.987319"], ["84253.70", "5.346632"], ["84262.20", "5.165390"], ["84270.70", "4.077939"], ["84279.20", "4.893527"], ["84287.70", "4.168560"], ["84296.20", "4.440423"], ["84304.70", "4.349802"], ["84313.20", "3.896698"], ["84321.70", "5.618494"]], "bids": [["84044.00", "0.015016"], ["84042.00", "0.039515"], ["84040.00", "0.103987"], ["84038.00", "0.273649"], ["84036.00", "0.720130"], ["84034.00", "1.895080"], ["84029.80", "0.015000"], ["84023.40", "0"], ["84003.00", "0.000015"], ["83992.00", "4.531044"], ["83983.50", "4.621665"], ["83975.00", "5.256011"], ["83966.50", "3.987319"], ["83958.00", "4.893527"], ["83949.50", "3.896698"], ["83932.50", "5.527873"], ["83924.00", "4.259181"], ["83915.50", "5.618494"], ["83907.00", "4.984148"], ["83898.50", "5.074769"], ["83890.00", "5.165390"], ["83881.50", "4.440423"], ["83873.00", "4.802906"], ["83864.50", "4.168560"], ["83856.00", "5.437252"], ["83847.50", "5.346632"], ["83839.00", "4.077939"], ["83830.50", "4.712286"], ["83652.48", "0"]], "checksum": 582447918, "ts": "1742555175945"}], "ts": 1742555175948, "record_time": 1742555175.973571, "EXCHANGE": "BITGET"}
{"action": "update", "arg": {"instType": "SPOT", "channel": "books", "instId": "BTCUSDT"}, "data": [{"asks": [["84090.49", "0"], ["84102.20", "0.006985"], ["84104.20", "0.018382"], ["84106.20", "0.048372"], ["84108.20", "0.127297"], ["84110.20", "0.334991"], ["84112.20", "0.881556"], ["84114.20", "2.319884"], ["84116.20", "6.104956"], ["84118.20", "16.065676"], ["84160.20", "5.165390"], ["84168.70", "4.440423"], ["84177.20", "4.984148"], ["84194.20", "5.618494"], ["84202.70", "4.893527"], ["84211.20", "4.168560"], ["84219.70", "3.896698"], ["84228.20", "4.531044"], ["84236.70", "4.349802"], ["84245.20", "4.712286"], ["84253.70", "5.437252"], ["84262.20", "3.987319"], ["84270.70", "4.802906"], ["84279.20", "4.077939"], ["84287.70", "5.256011"], ["84296.20", "4.621665"], ["84304.70", "5.346632"], ["84313.20", "5.527873"], ["84321.70", "5.074769"], ["84536.36", "0.000053"]], "bids": [["84054.00", "0.000077"], ["84040.00", "0.103849"], ["84038.00", "0.273287"], ["84036.00", "0.719176"], ["84034.00", "1.892569"], ["84029.70", "0.514860"], ["84023.40", "0.949170"], ["84004.00", "0.000032"], ["83992.00", "4.802906"], ["83983.50", "5.618494"], ["83975.00", "4.621665"], ["83966.50", "4.712286"], ["83958.00", "4.531044"], ["83949.50", "5.437252"], ["83941.00", "4.893527"], ["83932.50", "4.259181"], ["83924.00", "5.165390"], ["83915.50", "4.984148"], ["83907.00", "3.896698"], ["83898.50", "5.256011"], ["83890.00", "3.987319"], ["83881.50", "4.349802"], ["83873.00", "5.346632"], ["83864.50", "4.077939"], ["83856.00", "4.440423"], ["83847.50", "4.168560"], ["83839.00", "5.527873"], ["83830.50", "5.074769"], ["83652.80", "0"]], "checksum": -792917882, "ts": "1742555176145"}], "ts": 1742555176148, "record_time": 1742555176.184499, "EXCHANGE": "BITGET"}
{"action": "update", "arg": {"instType": "SPOT", "channel": "books", "instId": "BTCUSDT"}, "data": [{"asks": [["84054.01", "0.846303"], ["84054.74", "0"], ["84102.20", "0.006971"], ["84103.84", "0.305356"], ["84104.20", "0.018343"], ["84106.20", "0.048273"], ["84124.50", "2.373000"], ["84160.20", "4.802906"], ["84168.70", "4.984148"], ["84177.20", "4.077939"], ["84185.70", "4.531044"], ["84194.20", "4.621665"], ["84202.70", "5.527873"], ["84211.20", "5.074769"], ["84219.70", "5.256011"], ["84228.20", "4.440423"], ["84245.20", "4.259181"], ["84253.70", "5.618494"], ["84270.70", "3.896698"], ["84279.20", "4.712286"], ["84287.70", "5.437252"], ["84296.20", "5.165390"], ["84313.20", "4.893527"], ["84321.70", "4.168560"], ["84537.04", "0.000958"]], "bids": [["84054.00", "0.001033"], ["84053.84", "0.041107"], ["84053.83", "0"], ["84050.58", "0.027856"], ["84050.00", "0.001037"], ["84042.00", "0.039408"], ["84040.00", "0.103525"], ["84038.00", "0.272433"], ["84036.00", "0.716928"], ["84034.00", "1.886654"], ["84029.80", "0.030210"], ["84029.70", "0.978300"], ["84023.40", "0"], ["83992.00", "5.527873"], ["83983.50", "3.987319"], ["83975.00", "4.440423"], ["83958.00", "5.437252"], ["83949.50", "4.349802"], ["83941.00", "4.077939"], ["83932.50", "5.074769"], ["83924.00", "5.256011"], ["83915.50", "4.168560"], ["83907.00", "4.259181"], ["83898.50", "4.984148"], ["83890.00", "5.618494"], ["83881.50", "5.346632"], ["83873.00", "5.165390"], ["83864.50", "4.531044"], ["83856.00", "4.802906"], ["83847.50", "3.896698"], ["83839.00", "4.893527"], ["83830.50", "4.621665"]], "checksum": -1394276826, "ts": "1742555176347"}], "ts": 1742555176352, "record_time": 1742555176.376601, "EXCHANGE": "BITGET"}
{"action": "update", "arg": {"instType": "SPOT", "channel": "books", "instId": "BTCUSDT"}, "data": [{"asks": [["84054.01", "1.195207"], ["84102.20", "0.007114"], ["84104.20", "0.018721"], ["84106.20", "0.049266"], ["84108.20", "0.129648"], ["84110.20", "0.341178"], ["84112.20", "0.897837"], ["84114.20", "2.362728"], ["84116.20", "6.217705"], ["84118.20", "16.362383"], ["84126.09", "0.233715"], ["84160.20", "5.618494"], ["84168.70", "5.256011"], ["84177.20", "3.896698"], ["84185.70", "4.259181"], ["84194.20", "5.527873"], ["84202.70", "3.987319"], ["84211.20", "4.802906"], ["84219.70", "4.531044"], ["84228.20", "4.349802"], ["84236.70", "4.712286"], ["84245.20", "5.165390"], ["84253.70", "4.440423"], ["84262.20", "4.077939"], ["84270.70", "4.893527"], ["84279.20", "5.346632"], ["84287.70", "4.621665"], ["84296.20", "5.437252"], ["84304.70", "4.168560"], ["84313.20", "4.984148"], ["84321.70", "5.074769"], ["84537.04", "0"]], "bids": [["84044.00", "0.015119"], ["84042.00", "0.039787"], ["84040.00", "0.104703"], ["84038.00", "0.275532"], ["84036.00", "0.725085"], ["84034.00", "1.908118"], ["83992.00", "4.893527"], ["83983.50", "5.437252"], ["83975.00", "5.527873"], ["83966.50", "5.165390"], ["83958.00", "4.168560"], ["83949.50", "5.256011"], ["83941.00", "4.440423"], ["83932.50", "3.987319"], ["83924.00", "5.618494"], ["83915.50", "4.712286"], ["83907.00", "5.346632"], ["83890.00", "4.621665"], ["83881.50", "4.077939"], ["83873.00", "4.259181"], ["83856.00", "5.074769"], ["83839.00", "4.349802"], ["83830.50", "4.802906"]], "checksum": 1836971235, "ts": "1742555176550"}], "ts": 1742555176554, "record_time": 1742555176.576168, "EXCHANGE": "BITGET"}
{"action": "update", "arg": {"instType": "SPOT", "channel": "books", "instId": "BTCUSDT"}, "data": [{"asks": [["84054.01", "1.441047"], ["84100.20", "0.002593"], ["84102.20", "0.006825"], ["84104.20", "0.017961"], ["84106.20", "0.047264"], ["84108.20", "0.124381"], ["84110.20", "0.327317"], ["84112.20", "0.861362"], ["84114.20", "2.266742"], ["84116.20", "5.965109"], ["84118.20", "15.697656"], ["84126.00", "1.069890"], ["84160.19", "0.162531"], ["84160.20", "5.256011"], ["84168.70", "3.987319"], ["84177.20", "5.165390"], ["84185.70", "4.893527"], ["84202.70", "4.259181"], ["84211.20", "4.440423"], ["84219.70", "4.984148"], ["84228.20", "5.074769"], ["84236.70", "4.802906"], ["84245.20", "4.077939"], ["84253.70", "4.712286"], ["84262.20", "5.437252"], ["84270.70", "5.346632"], ["84279.20", "3.896698"], ["84287.70", "5.618494"], ["84296.20", "4.168560"], ["84304.70", "4.531044"], ["84313.20", "4.621665"], ["84321.70", "4.349802"], ["84535.32", "0"], ["84536.36", "0"]], "bids": [["84004.00", "0.000017"], ["84002.00", "0"], ["83992.00", "4.802906"], ["83983.50", "4.893527"], ["83975.00", "4.531044"], ["83966.50", "4.259181"], ["83958.00", "4.349802"], ["83949.50", "5.346632"], ["83941.00", "5.437252"], ["83932.50", "4.168560"], ["83924.00", "4.440423"], ["83915.50", "5.165390"], ["83907.00", "4.712286"], ["83898.50", "5.527873"], ["83890.00", "5.074769"], ["83881.50", "4.621665"], ["83873.00", "5.618494"], ["83864.50", "3.987319"], ["83856.00", "4.077939"], ["83847.50", "5.256011"], ["83839.00", "4.984148"], ["83830.50", "3.896698"], ["83652.80", "0.000119"]], "checksum": 474960504, "ts": "1742555176757"}], "ts": 1742555176759, "record_time": 1742555176.783178, "EXCHANGE": "BITGET"}
{"action": "update", "arg": {"instType": "SPOT", "channel": "books", "instId": "BTCUSDT"}, "data": [{"asks": [["84059.01", "0.209200"], ["84114.20", "2.266940"], ["84116.20", "5.965633"], ["84118.20", "15.699032"], ["84160.20", "4.984148"], ["84168.70", "4.077939"], ["84177.20", "3.987319"], ["84185.70", "4.802906"], ["84194.20", "4.259181"], ["84202.70", "4.893527"], ["84211.20", "5.074769"], ["84219.70", "5.256011"], ["84228.20", "4.168560"], ["84236.70", "4.349802"], ["84245.20", "5.346632"], ["84262.20", "5.165390"], ["84270.70", "4.531044"], ["84279.20", "5.527873"], ["84280.00", "0.000077"], ["84287.70", "4.621665"], ["84296.20", "3.896698"], ["84304.70", "5.437252"], ["84313.20", "5.618494"], ["84321.70", "4.440423"]], "bids": [["84029.70", "0.978660"], ["84023.40", "0.949170"], ["83992.00", "5.165390"], ["83983.50", "3.896698"], ["83975.00", "4.984148"], ["83966.50", "3.987319"], ["83958.00", "4.168560"], ["83949.50", "4.077939"], ["83941.00", "5.256011"], ["83932.50", "4.349802"], ["83924.00", "4.712286"], ["83915.50", "4.440423"], ["83907.00", "5.346632"], ["83898.50", "4.259181"], ["83890.00", "5.437252"], ["83881.50", "5.527873"], ["83873.00", "4.621665"], ["83864.50", "4.802906"], ["83856.00", "4.531044"], ["83847.50", "5.074769"], ["83839.00", "5.618494"], ["83830.50", "4.893527"], ["83652.80", "0"]], "checksum": -1379941443, "ts": "1742555176970"}], "ts": 1742555176978, "record_time": 1742555177.003239, "EXCHANGE": "BITGET"}
{"action": "update", "arg": {"instType": "SPOT", "channel": "books", "instId": "BTCUSDT"}, "data": [{"asks": [["84054.01", "1.454305"], ["84108.20", "0.124595"], ["84110.20", "0.327881"], ["84112.20", "0.862847"], ["84114.20", "2.270650"], ["84116.20", "5.975393"], ["84118.20", "15.724719"], ["84121.20", "0"], ["84160.20", "4.259181"], ["84168.70", "4.802906"], ["84177.20", "4.168560"], ["84185.70", "4.349802"], ["84194.20", "4.893527"], ["84202.70", "5.527873"], ["84211.20", "4.440423"], ["84219.70", "3.987319"], ["84228.20", "4.531044"], ["84236.70", "3.896698"], ["84245.20", "4.621665"], ["84253.70", "5.256011"], ["84270.70", "5.618494"], ["84279.20", "5.074769"], ["84287.70", "5.437252"], ["84296.20", "4.712286"], ["84304.70", "4.077939"], ["84313.20", "4.984148"], ["84321.70", "5.346632"], ["84535.32", "0.000039"]], "bids": [["84050.58", "0"], ["84048.56", "0.027856"], ["84042.00", "0.039889"], ["84040.00", "0.104972"], ["84038.00", "0.276241"], ["84036.00", "0.726951"], ["84034.00", "1.913029"], ["84029.80", "0.096420"], ["84029.70", "0.978240"], ["84026.00", "0.045540"], ["84025.40", "0.071070"], ["84024.50", "0"], ["84023.40", "0"], ["83992.00", "5.074769"], ["83983.50", "3.987319"], ["83975.00", "4.077939"], ["83966.50", "5.256011"], ["83958.00", "4.712286"], ["83949.50", "4.621665"], ["83941.00", "3.896698"], ["83924.00", "5.618494"], ["83915.50", "4.259181"], ["83907.00", "4.984148"], ["83898.50", "5.165390"], ["83890.00", "5.346632"], ["83881.50", "5.437252"], ["83873.00", "4.440423"], ["83864.50", "4.893527"], ["83856.00", "4.168560"], ["83847.50", "5.527873"], ["83839.00", "4.531044"], ["83830.50", "4.802906"], ["83652.80", "0.000119"], ["83652.48", "0.000188"]], "checksum": 410415444, "ts": "1742555177173"}], "ts": 1742555177175, "record_time": 1742555177.202606, "EXCHANGE": "BITGET"}
{"action": "update", "arg": {"instType": "SPOT", "channel": "books", "instId": "BTCUSDT"}, "data": [{"asks": [["84054.01", "1.433048"], ["84090.00", "0.002000"], ["84102.20", "0.006708"], ["84104.20", "0.017652"], ["84106.20", "0.046453"], ["84108.20", "0.122244"], ["84110.20", "0.321695"], ["84112.20", "0.846566"], ["84114.20", "2.227805"], ["84116.20", "5.862644"], ["84118.20", "15.428012"], ["84160.20", "4.893527"], ["84168.70", "4.168560"], ["84177.20", "5.618494"], ["84185.70", "4.712286"], ["84194.20", "3.987319"], ["84202.70", "4.440423"], ["84211.20", "4.259181"], ["84219.70", "4.621665"], ["84228.20", "5.074769"], ["84236.70", "5.165390"], ["84245.20", "4.077939"], ["84253.70", "3.896698"], ["84262.20", "4.349802"], ["84270.70", "5.437252"], ["84279.20", "4.531044"], ["84285.78", "0"], ["84287.70", "4.802906"], ["84296.20", "5.256011"], ["84304.70", "5.346632"], ["84321.70", "5.527873"]], "bids": [["84053.85", "0.041107"], ["84053.84", "0"], ["84038.00", "0.276102"], ["84036.00", "0.726584"], ["84034.00", "1.912061"], ["84029.30", "0.823200"], ["84027.70", "0"], ["84003.00", "0.000032"], ["84002.00", "0.000015"], ["83992.00", "3.896698"], ["83983.50", "5.346632"], ["83975.00", "4.802906"], ["83966.50", "4.440423"], ["83958.00", "5.165390"], ["83949.50", "5.256011"], ["83941.00", "4.168560"], ["83932.50", "4.893527"], ["83924.00", "5.527873"], ["83915.50", "4.531044"], ["83907.00", "4.621665"], ["83898.50", "3.987319"], ["83890.00", "5.074769"], ["83881.50", "4.984148"], ["83873.00", "4.259181"], ["83864.50", "4.349802"], ["83856.00", "4.077939"], ["83847.50", "4.712286"], ["83839.00", "5.437252"], ["83830.50", "5.618494"], ["83652.48", "0"]], "checksum": 600288821, "ts": "1742555177377"}], "ts": 1742555177381, "record_time": 1742555177.404029, "EXCHANGE": "BITGET"}
{"action": "update", "arg": {"instType": "SPOT", "channel": "books", "instId": "BTCUSDT"}, "data": [{"asks": [["84054.01", "1.456321"], ["84073.94", "0"], ["84074.01", "0.035952"], ["84075.49", "0"], ["84075.64", "0.035961"], ["84076.01", "0"], ["84076.16", "0.006356"], ["84076.17", "0"], ["84076.28", "0.006356"], ["84076.49", "0"], ["84076.65", "0.006356"], ["84077.53", "0"], ["84077.68", "0.017340"], ["84078.45", "0"], ["84078.61", "0.006356"], ["84078.99", "0"], ["84079.10", "0"], ["84079.15", "0.012712"], ["84079.33", "0"], ["84079.44", "0"], ["84079.49", "0.016429"], ["84079.52", "0.119883"], ["84079.55", "0"], ["84079.66", "0.006356"], ["84080.76", "0"], ["84080.96", "0"], ["84081.11", "0.006357"], ["84081.12", "0.010985"], ["84081.79", "0"], ["84081.95", "0.009990"], ["84083.91", "0"], ["84083.97", "0.119858"], ["84084.31", "0"], ["84084.36", "0.015895"], ["84084.50", "0"], ["84084.56", "0.009989"], ["84098.20", "0.001533"], ["84102.20", "0.006581"], ["84104.20", "0.017320"], ["84106.20", "0.045579"], ["84108.20", "0.119944"], ["84110.20", "0.315643"], ["84112.20", "0.830638"], ["84114.20", "2.185890"], ["84116.20", "5.752341"], ["84118.20", "15.137740"], ["84160.20", "4.349802"], ["84168.70", "5.074769"], ["84177.20", "4.440423"], ["84185.70", "4.531044"], ["84194.20", "4.168560"], ["84202.70", "5.346632"], ["84211.20", "4.893527"], ["84219.70", "4.802906"], ["84228.20", "4.621665"], ["84245.20", "3.987319"], ["84248.21", "0.168090"], ["84253.70", "5.256011"], ["84262.20", "3.896698"], ["84270.70", "5.527873"], ["84279.20", "4.712286"], ["84287.70", "5.437252"], ["84296.20", "5.618494"], ["84304.70", "4.984148"], ["84313.20", "4.259181"], ["84321.70", "4.077939"], ["84536.36", "0.000053"]], "bids": [["84040.00", "0.104859"], ["84038.00", "0.275943"], ["84036.00", "0.726166"], ["84034.00", "1.910964"], ["84033.66", "0.089495"], ["84033.60", "0.001006"], ["84031.93", "0.083949"], ["84031.78", "0"], ["84031.61", "0.017819"], ["84031.46", "0"], ["84031.39", "0.018257"], ["84031.28", "0"], ["84031.09", "0.005947"], ["84030.93", "0"], ["84029.94", "0.055662"], ["84029.79", "0"], ["84029.01", "0.007340"], ["84028.86", "0"], ["84028.55", "0.016939"], ["84028.50", "0"], ["84028.39", "0"], ["84028.25", "0.224907"], ["84028.22", "0.025187"], ["84028.17", "0"], ["84028.07", "0.017353"], ["84028.06", "0"], ["84028.05", "0.008186"], ["84028.01", "0"], ["84027.94", "0"], ["84026.48", "0.064626"], ["84026.33", "0"], ["84026.12", "0"], ["84025.63", "0.018519"], ["84025.48", "0"], ["84023.79", "0.222694"], ["84023.73", "0"], ["84023.34", "0.076121"], ["84023.29", "0"], ["84023.20", "0.021132"], ["84023.15", "0"], ["83992.00", "5.618494"], ["83983.50", "4.893527"], ["83975.00", "5.437252"], ["83966.50", "4.621665"], ["83958.00", "4.984148"], ["83949.50", "4.259181"], ["83941.00", "4.077939"], ["83932.50", "5.527873"], ["83924.00", "3.987319"], ["83915.50", "5.165390"], ["83907.00", "4.168560"], ["83898.50", "5.346632"], ["83890.00", "4.531044"], ["83881.50", "4.349802"], ["83873.00", "4.440423"], ["83864.50", "4.712286"], ["83856.00", "4.802906"], ["83847.50", "3.896698"], ["83839.00", "5.256011"], ["83830.50", "5.074769"], ["83652.48", "0.000188"]], "checksum": -1285880985, "ts": "1742555177582"}], "ts": 1742555177585, "record_time": 1742555177.613583, "EXCHANGE": "BITGET"}
{"action": "update", "arg": {"instType": "SPOT", "channel": "books", "instId": "BTCUSDT"}, "data": [{"asks": [["84054.01", "0.710956"], ["84102.20", "0.006708"], ["84104.20", "0.017651"], ["84106.20", "0.046451"], ["84108.20", "0.122239"], ["84110.20", "0.321681"], ["84112.20", "0.846530"], ["84114.20", "2.227711"], ["84116.20", "5.862397"], ["84118.20", "15.427361"], ["84160.20", "4.531044"], ["84168.70", "4.259181"], ["84177.20", "5.527873"], ["84185.70", "4.712286"], ["84194.20", "5.256011"], ["84202.70", "5.165390"], ["84211.20", "4.621665"], ["84219.70", "5.618494"], ["84228.20", "5.437252"], ["84236.70", "4.893527"], ["84245.20", "4.168560"], ["84253.70", "4.440423"], ["84262.20", "5.074769"], ["84270.70", "3.896698"], ["84279.20", "5.346632"], ["84287.70", "4.802906"], ["84296.20", "3.987319"], ["84304.70", "4.077939"], ["84313.20", "4.349802"], ["84321.70", "4.984148"]], "bids": [["83992.00", "4.984148"], ["83983.50", "5.074769"], ["83975.00", "5.346632"], ["83966.50", "4.077939"], ["83958.00", "4.531044"], ["83949.50", "5.256011"], ["83941.00", "5.437252"], ["83932.50", "4.802906"], ["83924.00", "4.168560"], ["83915.50", "4.259181"], ["83907.00", "4.440423"], ["83898.50", "4.712286"], ["83890.00", "3.987319"], ["83873.00", "5.618494"], ["83864.50", "5.165390"], ["83856.00", "4.893527"], ["83847.50", "4.621665"], ["83839.00", "3.896698"], ["83830.50", "5.527873"]], "checksum": -769881407, "ts": "1742555177809"}], "ts": 1742555177812, "record_time": 1742555177.840811, "EXCHANGE": "BITGET"}
{"action": "update", "arg": {"instType": "SPOT", "channel": "books", "instId": "BTCUSDT"}, "data": [{"asks": [["84054.01", "0.861896"], ["84054.74", "0.095134"], ["84054.92", "0.112803"], ["84088.48", "0"], ["84102.20", "0.006581"], ["84103.84", "0.716489"], ["84104.20", "0.017320"], ["84106.20", "0.045579"], ["84108.20", "0.119944"], ["84110.20", "0.315643"], ["84112.20", "0.830638"], ["84114.20", "2.185890"], ["84116.20", "5.752341"], ["84118.20", "15.137740"], ["84126.09", "0"], ["84160.19", "0"], ["84160.20", "4.349802"], ["84168.70", "4.077939"], ["84177.20", "5.618494"], ["84185.70", "3.987319"], ["84194.20", "4.531044"], ["84202.70", "5.437252"], ["84211.20", "5.074769"], ["84216.00", "0.001184"], ["84219.70", "4.440423"], ["84228.20", "5.346632"], ["84245.20", "4.802906"], ["84253.70", "4.712286"], ["84262.20", "5.527873"], ["84270.70", "5.256011"], ["84279.20", "3.896698"], ["84287.70", "4.168560"], ["84296.20", "4.259181"], ["84304.70", "5.165390"], ["84313.20", "4.984148"], ["84321.70", "4.621665"], ["84537.04", "0.000958"]], "bids": [["84054.00", "0.020000"], ["84045.85", "0.010000"], ["84044.00", "0.014958"], ["84042.00", "0.039362"], ["84040.00", "0.103585"], ["84038.00", "0.272591"], ["84036.00", "0.717346"], ["84034.00", "1.887751"], ["84029.80", "0.081420"], ["84004.00", "0"], ["83992.00", "5.618494"], ["83983.50", "4.168560"], ["83975.00", "5.256011"], ["83966.50", "4.349802"], ["83958.00", "4.893527"], ["83949.50", "5.074769"], ["83941.00", "4.077939"], ["83932.50", "5.527873"], ["83924.00", "4.621665"], ["83907.00", "5.437252"], ["83898.50", "4.802906"], ["83890.00", "4.712286"], ["83881.50", "5.346632"], ["83873.00", "5.165390"], ["83864.50", "3.987319"], ["83856.00", "4.440423"], ["83847.50", "4.531044"], ["83830.50", "4.984148"]], "checksum": -976796806, "ts": "1742555178010"}], "ts": 1742555178017, "record_time": 1742555178.041468, "EXCHANGE": "BITGET"}
