{"action": "update", "arg": {"instType": "SPOT", "channel": "books", "instId": "BTCUSDT"}, "data": [{"asks": [["84324.85", "0"], ["84330.00", "0"], ["84331.04", "0"], ["84331.32", "0"], ["84331.37", "0"], ["84331.38", "0"], ["84331.42", "0"], ["84331.43", "0"], ["84332.43", "0"], ["84332.44", "0"], ["84332.45", "0"], ["84332.46", "0"], ["84332.48", "0"], ["84332.49", "0"], ["84332.51", "0"], ["84334.11", "0"], ["84334.28", "0"], ["84335.74", "0"], ["84336.73", "0"], ["84338.10", "0"], ["84338.91", "0"], ["84339.09", "0"], ["84339.46", "0"], ["84339.58", "0"], ["84340.35", "0"], ["84341.55", "0"], ["84341.67", "0"], ["84341.78", "0"], ["84341.81", "0"], ["84341.88", "0"], ["84342.00", "0"], ["84342.04", "0"], ["84342.14", "0"], ["84342.45", "0"], ["84342.86", "0"], ["84343.05", "0"], ["84343.13", "0"], ["84343.41", "0"], ["84343.60", "0"], ["84343.69", "0"], ["84343.79", "0"], ["84344.64", "0"], ["84344.75", "0"], ["84345.76", "0"], ["84346.62", "0.004595"], ["84346.63", "0.009639"], ["84346.81", "0"], ["84346.83", "0"], ["84346.84", "0.008962"], ["84346.88", "0.004974"], ["84346.89", "0.001230"], ["84346.94", "0.006307"], ["84346.95", "0.001066"], ["84347.83", "0.005183"], ["84347.86", "0"], ["84348.01", "0.016476"], ["84348.27", "0"], ["84348.93", "0"], ["84349.20", "0"], ["84350.47", "0"], ["84350.91", "0"], ["84351.59", "0"], ["84352.21", "0.080082"], ["84352.61", "0"], ["84352.73", "0"], ["84353.87", "0"], ["84354.25", "0.002807"], ["84354.64", "0"], ["84355.51", "0"], ["84355.98", "0"], ["84358.40", "0"], ["84359.85", "0.209200"], ["84360.18", "0.119869"], ["84360.37", "0.001205"], ["84361.95", "0.006356"], ["84362.20", "0"], ["84362.30", "0.035952"], ["84362.49", "0.006356"], ["84362.77", "0.006356"], ["84363.17", "0.006356"], ["84363.40", "0.006356"], ["84363.44", "0.006356"], ["84364.01", "0.006356"], ["84364.20", "0"], ["84364.29", "0.006356"], ["84364.57", "0"], ["84364.58", "0.010985"], ["84364.63", "0.006356"], ["84364.86", "0.006356"], ["84365.23", "0.016427"], ["84365.27", "0.016428"], ["84365.37", "0.012712"], ["84365.57", "0.012712"], ["84365.87", "0.119843"], ["84366.20", "0"], ["84366.48", "0"], ["84366.55", "0.010984"], ["84366.67", "0.006357"], ["84368.20", "0"], ["84368.21", "0.009989"], ["84368.29", "0"], ["84368.35", "0.006356"], ["84368.76", "0.119895"], ["84370.20", "0"], ["84370.25", "0.017784"], ["84370.62", "0.015892"], ["84370.64", "0.009989"], ["84370.68", "0.119879"], ["84371.09", "0.119881"], ["84372.20", "0"], ["84372.70", "0.006356"], ["84374.20", "0"], ["84375.82", "0.010986"], ["84376.20", "0"], ["84377.80", "0.001001"], ["84378.20", "0"], ["84379.80", "0.001029"], ["84380.20", "0"], ["84381.80", "0.002386"], ["84382.20", "0"], ["84382.30", "0"], ["84383.10", "0"], ["84383.40", "0"], ["84383.80", "0.006281"], ["84385.80", "0.016528"], ["84386.20", "0"], ["84386.70", "0"], ["84387.80", "0.043494"], ["84387.90", "0"], ["84388.20", "0"], ["84389.70", "0"], ["84389.80", "0.114458"], ["84390.20", "0"], ["84391.30", "0"], ["84391.80", "0.301368"], ["84392.10", "0"], ["84392.20", "0"], ["84393.00", "0"], ["84393.20", "0"], ["84393.30", "0"], ["84393.40", "0"], ["84393.80", "0.793072"], ["84393.90", "0"], ["84394.20", "0"], ["84395.80", "2.087032"], ["84397.52", "0.001597"], ["84397.80", "5.492189"], ["84398.00", "0.001042"], ["84398.20", "0.007470"], ["84398.60", "0.014160"], ["84398.70", "0.001012"], ["84399.10", "0.177660"], ["84399.48", "0.001597"], ["84400.10", "0.015180"], ["84402.10", "0.010530"], ["84402.20", "0.078420"], ["84403.00", "0.004470"], ["84403.50", "0.064230"], ["84405.90", "0.303690"], ["84406.20", "0.007050"], ["84406.50", "0.015120"], ["84406.60", "0.102600"], ["84407.50", "0.009000"], ["84409.20", "0.981300"], ["84409.50", "0.197885"], ["84410.20", "0.007050"], ["84411.40", "3.732000"], ["84412.70", "0.135000"], ["84424.40", "0"], ["84427.05", "0"], ["84427.20", "0"], ["84427.41", "0"], ["84431.42", "0"], ["84432.90", "0"], ["84440.00", "5.238598"], ["84441.40", "0"], ["84448.50", "5.419239"], ["84449.90", "0"], ["84453.76", "0.072042"], ["84457.00", "4.967636"], ["84457.83", "0.057629"], ["84458.40", "0"], ["84459.31", "0"], ["84464.30", "0.304146"], ["84465.50", "5.328918"], ["84466.90", "0"], ["84474.00", "3.883788"], ["84475.40", "0"], ["84480.72", "0.072042"], ["84482.50", "4.245071"], ["84483.90", "0"], ["84491.00", "4.064429"], ["84492.40", "0"], ["84493.30", "0.209200"], ["84498.20", "0"], ["84499.50", "4.786994"], ["84500.90", "0"], ["84501.74", "0.209200"], ["84508.00", "4.154750"], ["84509.40", "0"], ["84516.50", "5.509559"], ["84517.90", "0"], ["84525.00", "5.599880"], ["84526.40", "0"], ["84533.50", "4.425712"], ["84534.90", "0"], ["84541.96", "0.025360"], ["84542.00", "4.696674"], ["84543.40", "0"], ["84550.50", "4.335391"], ["84551.90", "0"], ["84559.00", "5.148277"], ["84560.40", "0"], ["84567.50", "4.516032"], ["84568.90", "0"], ["84576.00", "3.974109"], ["84577.40", "0"], ["84584.50", "4.877315"], ["84585.90", "0"], ["84593.00", "4.606353"], ["84601.50", "5.057956"], ["84871.66", "0.000078"], ["84871.79", "0.000014"], ["84873.84", "0.000057"], ["84874.79", "0.000096"], ["84875.00", "0.000959"], ["84875.78", "0.000038"], ["84876.03", "0.000161"], ["84879.10", "0.000009"], ["84879.37", "0.000009"], ["84879.59", "0.000173"], ["84880.00", "0.025078"], ["84880.89", "0.000065"], ["84882.35", "0.000417"], ["84883.65", "0.000008"], ["84883.72", "0.000010"], ["84883.84", "0.000040"], ["84885.24", "0.000112"], ["84885.53", "0.000022"], ["84886.01", "0.000023"]], "bids": [["84344.71", "0.047500"], ["84333.30", "0.001044"], ["84331.30", "0.001045"], ["84329.30", "0.002176"], ["84329.05", "0.209200"], ["84327.38", "0.034691"], ["84327.30", "0.005724"], ["84325.30", "0.015065"], ["84324.85", "0.130300"], ["84324.84", "0.473523"], ["84323.30", "0.039643"], ["84321.30", "0.104325"], ["84321.14", "0.000213"], ["84319.41", "0.007345"], ["84319.31", "0.006213"], ["84319.30", "0.274540"], ["84319.27", "0.008549"], ["84319.03", "0.006535"], ["84319.02", "0.008576"], ["84318.91", "0.822241"], ["84318.90", "0.660829"], ["84318.89", "0.003018"], ["84318.67", "0"], ["84318.29", "0.084399"], ["84318.05", "0.017827"], ["84317.80", "0"], ["84317.76", "0.007870"], ["84317.30", "0.722472"], ["84317.05", "0.015764"], ["84316.91", "0"], ["84316.68", "0.016453"], ["84316.67", "0.056328"], ["84316.56", "0.018252"], ["84316.43", "0.005935"], ["84315.80", "0"], ["84315.60", "0.017071"], ["84315.53", "0.007116"], ["84315.51", "0.028794"], ["84315.43", "0.006562"], ["84315.30", "1.901242"], ["84315.15", "0.197876"], ["84314.80", "0.007929"], ["84314.76", "0.017053"], ["84314.60", "0.008984"], ["84314.53", "0.007313"], ["84314.42", "0.227568"], ["84314.38", "0.008161"], ["84314.06", "0.005548"], ["84314.03", "0.004935"], ["84313.98", "0.005088"], ["84313.97", "0.009627"], ["84313.80", "0"], ["84313.78", "0.025072"], ["84313.53", "0.012643"], ["84313.43", "0.017324"], ["84313.30", "5.003270"], ["84313.20", "0.001041"], ["84313.10", "1.351440"], ["84312.83", "0.002948"], ["84312.50", "0.001021"], ["84311.99", "0.010234"], ["84311.98", "0.008667"], ["84311.90", "0.025350"], ["84311.81", "0.018511"], ["84311.80", "0.275190"], ["84311.73", "0.052084"], ["84310.50", "3.694380"], ["84310.39", "0.271775"], ["84310.37", "0.263207"], ["84310.30", "0.003600"], ["84310.29", "0.222629"], ["84309.80", "0"], ["84309.39", "0.075978"], ["84309.07", "0.021099"], ["84309.00", "0.142500"], ["84308.80", "1.507200"], ["84308.40", "0.005610"], ["84307.80", "1.576800"], ["84307.20", "0.410370"], ["84307.10", "0.011220"], ["84307.08", "0.012434"], ["84306.10", "0.450030"], ["84305.97", "0.073472"], ["84305.80", "0.069600"], ["84305.71", "0"], ["84305.63", "0"], ["84305.60", "1.840680"], ["84305.30", "0.121500"], ["84304.98", "0.056613"], ["84304.70", "0"], ["84304.00", "0.916620"], ["84303.92", "0"], ["84303.85", "0"], ["84303.83", "0"], ["84303.82", "0"], ["84303.80", "0.069600"], ["84303.78", "0"], ["84303.76", "0"], ["84303.75", "0"], ["84303.51", "0"], ["84303.40", "5.398650"], ["84302.60", "0.142500"], ["84302.34", "0.023728"], ["84302.27", "0"], ["84302.20", "0.120000"], ["84301.84", "0"], ["84301.80", "0.069600"], ["84301.51", "0"], ["84300.70", "0.120000"], ["84300.60", "2.669430"], ["84300.35", "0.017783"], ["84300.30", "2.669430"], ["84299.80", "0.069600"], ["84299.42", "0"], ["84299.40", "0.028290"], ["84298.56", "0"], ["84298.52", "0"], ["84298.48", "0"], ["84298.46", "0"], ["84298.41", "0"], ["84298.40", "0.023928"], ["84298.30", "3.710430"], ["84297.81", "0"], ["84297.80", "2.427840"], ["84297.70", "0"], ["84297.60", "0"], ["84297.40", "0"], ["84297.08", "0"], ["84296.71", "0"], ["84296.62", "0"], ["84296.20", "0"], ["84296.10", "0"], ["84296.00", "0"], ["84295.90", "0"], ["84295.80", "0"], ["84295.62", "0"], ["84295.51", "0"], ["84295.42", "0.008206"], ["84295.41", "0"], ["84295.30", "0"], ["84295.25", "0"], ["84295.16", "0"], ["84295.09", "0"], ["84295.00", "0"], ["84294.83", "0"], ["84294.45", "0.018018"], ["84294.24", "0"], ["84294.13", "0"], ["84293.80", "0"], ["84293.73", "0"], ["84293.62", "0"], ["84293.03", "0"], ["84292.50", "0"], ["84292.40", "0"], ["84292.36", "0"], ["84292.30", "0"], ["84292.29", "0"], ["84292.12", "0"], ["84292.10", "0"], ["84292.00", "0"], ["84291.69", "0"], ["84291.51", "0"], ["84291.30", "0"], ["84291.22", "0"], ["84291.10", "0"], ["84291.00", "0"], ["84290.95", "0"], ["84290.84", "0"], ["84290.71", "0"], ["84290.67", "0"], ["84290.20", "0"], ["84290.12", "0"], ["84289.80", "0"], ["84289.10", "0"], ["84287.90", "0"], ["84287.15", "0"], ["84286.87", "0.001189"], ["84286.72", "0"], ["84286.70", "0"], ["84285.80", "0"], ["84285.40", "0"], ["84285.31", "0"], ["84284.10", "0"], ["84283.52", "0"], ["84283.40", "0"], ["84283.05", "0"], ["84283.00", "0"], ["84282.85", "0"], ["84282.50", "0"], ["84282.11", "0.020085"], ["84281.90", "0"], ["84280.90", "0"], ["84280.50", "0"], ["84280.30", "0"], ["84279.91", "0"], ["84279.90", "0"], ["84279.80", "0"], ["84275.09", "0"], ["84275.06", "0"], ["84274.16", "0"], ["84272.36", "0.016216"], ["84271.10", "4.064429"], ["84270.77", "0"], ["84262.80", "0"], ["84262.60", "4.696674"], ["84258.82", "0.072042"], ["84255.60", "0"], ["84254.10", "5.509559"], ["84253.95", "0"], ["84253.05", "0"], ["84251.99", "0"], ["84247.10", "0"], ["84245.60", "5.148277"], ["84238.60", "0"], ["84237.10", "4.245071"], ["84230.10", "0"], ["84228.60", "5.238598"], ["84221.60", "0"], ["84220.10", "5.599880"], ["84219.68", "0"], ["84213.10", "0"], ["84211.60", "4.877315"], ["84204.60", "0"], ["84204.01", "0"], ["84203.10", "4.967636"], ["84196.10", "0"], ["84194.60", "5.419239"], ["84187.60", "0"], ["84186.10", "4.425712"], ["84179.10", "0"], ["84177.60", "4.154750"], ["84170.60", "0"], ["84169.10", "5.057956"], ["84168.00", "0.000121"], ["84162.10", "0"], ["84160.60", "3.974109"], ["84153.60", "0"], ["84152.10", "5.328918"], ["84145.10", "0"], ["84143.60", "4.516032"], ["84136.60", "0"], ["84135.10", "4.606353"], ["84128.10", "0"], ["84126.60", "4.335391"], ["84119.60", "0"], ["84118.10", "3.883788"], ["84111.10", "0"], ["84109.60", "4.786994"], ["84102.60", "0"], ["84094.10", "0"], ["84082.92", "0.055209"], ["83992.30", "0"], ["83988.50", "0"], ["83893.62", "0.000137"], ["83892.29", "0.000143"], ["83891.43", "0.000455"], ["83891.30", "0.000010"], ["83888.89", "0.000163"], ["83888.86", "0.000371"], ["83887.29", "0.000586"], ["83887.11", "0.000075"], ["83886.91", "0.000145"], ["83885.98", "0.000018"], ["83885.71", "0.000069"]], "checksum": 733740805, "ts": "1742142244151"}], "ts": 1742142244156, "record_time": 1742142243.265907}
{"action": "update", "arg": {"instType": "SPOT", "channel": "books", "instId": "BTCUSDT"}, "data": [{"asks": [["84346.62", "0.340251"], ["84346.92", "0.000245"], ["84347.96", "0.007627"], ["84348.00", "0.008506"], ["84348.01", "0.023586"], ["84348.02", "0.009191"], ["84348.06", "0.004739"], ["84352.20", "0.024025"], ["84357.49", "0.139860"], ["84359.84", "0.101589"], ["84360.00", "0.013836"], ["84368.29", "0.209200"], ["84371.65", "0.313161"], ["84371.72", "0.010000"], ["84374.39", "0.015891"], ["84378.91", "0.001807"], ["84383.80", "0.006507"], ["84384.73", "0.075400"], ["84385.80", "0.017123"], ["84387.80", "0.045062"], ["84389.80", "0.118582"], ["84391.80", "0.312060"], ["84393.27", "0.031812"], ["84393.80", "0.821209"], ["84395.80", "2.161076"], ["84397.80", "5.687043"], ["84398.20", "0.007260"], ["84398.60", "0.013980"], ["84398.70", "0"], ["84399.10", "0"], ["84400.10", "0"], ["84400.40", "0.770160"], ["84402.10", "0"], ["84402.20", "0.078600"], ["84403.00", "0.171420"], ["84403.50", "0"], ["84406.20", "0.149550"], ["84406.50", "0.133770"], ["84408.20", "0.015150"], ["84409.20", "0"], ["84410.40", "0.035550"], ["84411.40", "0.343320"], ["84412.60", "0.142500"], ["84412.70", "0"], ["84413.20", "0.013860"], ["84414.20", "0.007440"], ["84440.00", "5.419239"], ["84448.50", "3.883788"], ["84457.00", "4.877315"], ["84465.50", "4.516032"], ["84474.00", "4.786994"], ["84482.50", "5.238598"], ["84491.00", "4.245071"], ["84499.50", "4.154750"], ["84501.74", "0"], ["84508.00", "5.328918"], ["84516.50", "5.057956"], ["84533.50", "4.335391"], ["84542.00", "5.148277"], ["84550.50", "5.509559"], ["84559.00", "4.064429"], ["84561.70", "0.295145"], ["84566.67", "0"], ["84567.50", "4.425712"], ["84576.00", "4.606353"], ["84584.50", "4.696674"], ["84593.00", "4.967636"], ["84601.50", "3.974109"], ["84620.19", "0.028128"], ["84672.06", "0"], ["84692.98", "1.603195"], ["84876.03", "0"], ["84879.10", "0"], ["84879.37", "0"], ["84879.59", "0"], ["84880.00", "0"], ["84880.89", "0"], ["84882.35", "0"], ["84883.65", "0"], ["84883.72", "0"], ["84883.84", "0"], ["84885.24", "0"], ["84885.53", "0"], ["84886.01", "0"]], "bids": [["84346.61", "0.766590"], ["84346.21", "0.025081"], ["84344.72", "0.014414"], ["84344.71", "0.000160"], ["84343.09", "0.139860"], ["84342.79", "1.893495"], ["84339.73", "0.209200"], ["84335.34", "0.006929"], ["84335.32", "0.007591"], ["84334.68", "0.010000"], ["84334.04", "0.003004"], ["84333.96", "0.005548"], ["84331.31", "0.047500"], ["84329.30", "0.002407"], ["84329.06", "0.062760"], ["84327.38", "0"], ["84327.30", "0.006333"], ["84325.92", "2.548096"], ["84325.30", "0.016667"], ["84324.86", "0.181147"], ["84324.85", "0"], ["84323.30", "0.043861"], ["84321.30", "0.115423"], ["84321.22", "0.008532"], ["84321.21", "0.001228"], ["84319.36", "0.008986"], ["84319.31", "0.013649"], ["84319.30", "0.303744"], ["84319.01", "0.001199"], ["84318.91", "0.313161"], ["84318.90", "0.307181"], ["84318.89", "0.006076"], ["84318.47", "0"], ["84317.79", "0.002062"], ["84317.36", "0.007475"], ["84317.30", "0.799328"], ["84315.30", "2.103493"], ["84315.15", "0"], ["84313.92", "0.008151"], ["84313.30", "5.535509"], ["84313.10", "1.670730"], ["84312.86", "0.008279"], ["84312.50", "0"], ["84312.10", "0.917010"], ["84311.90", "0"], ["84311.80", "0"], ["84311.60", "0.035550"], ["84310.50", "0"], ["84310.40", "2.347650"], ["84310.30", "0.012090"], ["84309.00", "0.229920"], ["84308.80", "0"], ["84308.40", "0"], ["84307.80", "0"], ["84307.20", "0"], ["84307.15", "0.018018"], ["84306.60", "0.035550"], ["84306.40", "0.015180"], ["84306.37", "0"], ["84306.10", "0"], ["84305.60", "0.015120"], ["84305.30", "0"], ["84304.70", "0.177960"], ["84304.00", "0"], ["84303.70", "0.025350"], ["84303.40", "6.143370"], ["84302.40", "0.177960"], ["84302.20", "0"], ["84300.80", "0.099000"], ["84300.70", "0.035550"], ["84300.60", "6.662100"], ["84299.60", "0.120000"], ["84298.70", "0.060000"], ["84298.30", "0"], ["84297.80", "0.069600"], ["84297.40", "7.500300"], ["84294.45", "0"], ["84290.57", "0.007181"], ["84290.54", "0.007582"], ["84290.50", "0.207047"], ["84289.51", "0"], ["84284.89", "0.001180"], ["84282.11", "0"], ["84272.36", "0"], ["84271.10", "3.883788"], ["84262.60", "4.335391"], ["84254.10", "4.064429"], ["84245.60", "4.516032"], ["84243.92", "0.057629"], ["84237.10", "4.425712"], ["84228.60", "4.245071"], ["84211.60", "4.967636"], ["84203.10", "4.877315"], ["84194.60", "4.786994"], ["84186.10", "5.057956"], ["84177.60", "5.328918"], ["84169.10", "5.509559"], ["84160.60", "5.148277"], ["84152.10", "4.696674"], ["84143.60", "4.154750"], ["84126.60", "5.419239"], ["84118.10", "5.238598"], ["84109.60", "3.974109"], ["84018.13", "1.714826"], ["83997.37", "0"], ["83896.11", "0"], ["83896.00", "0"], ["83895.65", "0"], ["83895.00", "0"], ["83894.74", "0"], ["83894.17", "0"], ["83893.81", "0"], ["83893.64", "0"], ["83893.62", "0"], ["83892.29", "0"], ["83891.43", "0"], ["83891.30", "0"], ["83888.89", "0"], ["83888.86", "0"], ["83887.29", "0"], ["83887.11", "0"], ["83886.91", "0"], ["83885.98", "0"], ["83885.71", "0"]], "checksum": 34479915, "ts": "1742142244359"}], "ts": 1742142244365, "record_time": 1742142243.473485}
{"action": "update", "arg": {"instType": "SPOT", "channel": "books", "instId": "BTCUSDT"}, "data": [{"asks": [["84346.62", "0.260871"], ["84346.63", "0"], ["84346.84", "0"], ["84346.88", "0"], ["84346.89", "0"], ["84346.92", "0"], ["84346.94", "0"], ["84346.95", "0"], ["84347.83", "0"], ["84347.96", "0"], ["84348.00", "0"], ["84348.01", "0"], ["84348.06", "0"], ["84352.20", "0"], ["84352.21", "0"], ["84357.49", "0"], ["84359.83", "0.014226"], ["84359.84", "0"], ["84359.85", "0"], ["84360.18", "0"], ["84360.37", "0"], ["84361.95", "0"], ["84362.30", "0"], ["84362.49", "0"], ["84362.77", "0"], ["84363.17", "0"], ["84363.39", "0.068173"], ["84363.40", "0"], ["84363.44", "0"], ["84364.01", "0"], ["84364.58", "0"], ["84364.63", "0"], ["84364.86", "0"], ["84365.23", "0"], ["84365.27", "0"], ["84365.37", "0"], ["84365.57", "0"], ["84365.87", "0"], ["84366.55", "0"], ["84366.67", "0"], ["84368.21", "0"], ["84368.29", "0"], ["84368.35", "0"], ["84368.76", "0"], ["84370.62", "0"], ["84370.64", "0"], ["84370.68", "0"], ["84371.72", "0"], ["84372.70", "0"], ["84375.82", "0"], ["84381.80", "0.002449"], ["84383.80", "0.006446"], ["84385.80", "0.016962"], ["84387.80", "0.044637"], ["84389.80", "0.117466"], ["84391.80", "0.309121"], ["84393.27", "0"], ["84393.80", "0.813477"], ["84395.80", "2.140727"], ["84397.80", "5.633494"], ["84398.20", "0.007860"], ["84398.60", "0.013560"], ["84400.40", "0"], ["84402.70", "0.835080"], ["84403.00", "0.004470"], ["84405.50", "2.347170"], ["84406.50", "0.062070"], ["84409.10", "0.032790"], ["84413.20", "0"], ["84414.20", "0"], ["84425.84", "0"], ["84440.00", "5.328918"], ["84448.50", "5.509559"], ["84457.00", "4.516032"], ["84465.50", "5.057956"], ["84482.50", "4.696674"], ["84491.00", "4.335391"], ["84499.50", "4.425712"], ["84508.00", "5.599880"], ["84516.50", "3.974109"], ["84525.00", "4.245071"], ["84533.50", "4.967636"], ["84542.00", "4.606353"], ["84550.50", "4.064429"], ["84559.00", "5.238598"], ["84567.50", "5.419239"], ["84576.00", "4.154750"], ["84584.50", "4.877315"], ["84593.00", "5.148277"], ["84601.50", "3.883788"], ["84876.03", "0.000161"], ["84879.10", "0.000009"], ["84879.37", "0.000009"], ["84879.59", "0.000173"], ["84880.00", "0.025078"], ["84880.89", "0.000065"], ["84882.35", "0.000417"], ["84883.65", "0.000008"], ["84883.72", "0.000010"], ["84883.84", "0.000040"], ["84885.24", "0.000112"], ["84885.53", "0.000022"], ["84886.01", "0.000023"], ["84886.02", "0.000054"], ["84886.96", "0.000013"], ["84887.65", "0.000019"], ["84888.00", "0.000010"], ["84888.68", "0.000013"], ["84888.89", "0.000113"], ["84889.87", "0.000010"], ["84890.00", "0.000118"], ["84892.02", "0.000099"], ["84892.76", "0.000096"], ["84892.78", "0.000013"], ["84894.73", "0.000019"], ["84894.74", "0.000208"], ["84895.69", "0.000135"], ["84895.83", "0.000019"], ["84897.50", "0.000031"], ["84899.08", "0.000072"], ["84899.44", "0.000026"], ["84900.00", "0.005252"], ["84901.15", "0.000019"], ["84903.27", "0.000007"], ["84903.57", "0.000128"], ["84903.79", "0.000016"], ["84903.84", "0.000014"], ["84903.85", "0.000067"], ["84904.06", "0.000077"], ["84904.76", "0.000032"], ["84905.66", "0.000023"], ["84906.08", "0.000573"], ["84906.54", "0.000034"], ["84909.08", "0.000008"], ["84909.09", "0.000575"], ["84909.66", "0.000049"], ["84910.00", "0.000062"]], "bids": [["84346.61", "0.988630"], ["84344.72", "0.000164"], ["84344.71", "0"], ["84342.80", "0.568049"], ["84342.79", "0"], ["84333.96", "0"], ["84329.30", "0.002303"], ["84327.30", "0.006061"], ["84325.30", "0.015951"], ["84324.84", "0.209200"], ["84323.30", "0.041976"], ["84321.30", "0.110462"], ["84321.22", "0"], ["84321.21", "0"], ["84321.14", "0"], ["84319.41", "0"], ["84319.36", "0"], ["84319.31", "0.006213"], ["84319.30", "0.290689"], ["84318.90", "0.011859"], ["84318.89", "0"], ["84318.29", "0"], ["84318.05", "0"], ["84317.76", "0"], ["84317.30", "0.764973"], ["84317.05", "0"], ["84316.68", "0"], ["84316.67", "0"], ["84316.56", "0"], ["84316.43", "0"], ["84315.60", "0"], ["84315.53", "0"], ["84315.51", "0"], ["84315.43", "0"], ["84315.30", "2.013087"], ["84315.14", "0.611345"], ["84314.80", "0"], ["84314.76", "0"], ["84314.60", "0"], ["84314.42", "0"], ["84314.38", "0"], ["84314.06", "0"], ["84314.03", "0"], ["84313.98", "0"], ["84313.92", "0"], ["84313.78", "0"], ["84313.53", "0"], ["84313.43", "0"], ["84313.30", "5.297596"], ["84313.10", "0.787860"], ["84312.86", "0"], ["84312.83", "0"], ["84312.30", "2.347410"], ["84312.10", "0.916800"], ["84311.99", "0"], ["84311.98", "0"], ["84311.81", "0"], ["84311.79", "0.188966"], ["84311.73", "0"], ["84310.40", "0"], ["84310.39", "0"], ["84310.29", "0"], ["84309.39", "0"], ["84309.07", "0"], ["84309.00", "0.456990"], ["84307.20", "0.410370"], ["84307.08", "0"], ["84306.51", "0"], ["84306.00", "0.383070"], ["84304.98", "0"], ["84304.20", "0.090000"], ["84303.70", "0"], ["84303.20", "0.090000"], ["84302.40", "0.267960"], ["84302.00", "0.038550"], ["84301.52", "0"], ["84300.90", "0.090000"], ["84300.40", "0.177960"], ["84300.00", "0"], ["84299.40", "0"], ["84298.70", "0"], ["84297.80", "0"], ["84297.40", "0"], ["84295.42", "0"], ["84290.57", "0"], ["84290.54", "0"], ["84290.50", "0"], ["84271.10", "4.154750"], ["84262.60", "4.606353"], ["84254.10", "4.967636"], ["84245.60", "4.877315"], ["84237.10", "5.599880"], ["84228.60", "5.238598"], ["84220.10", "5.419239"], ["84211.60", "4.245071"], ["84203.10", "4.516032"], ["84194.60", "3.883788"], ["84186.10", "5.328918"], ["84177.60", "4.425712"], ["84169.10", "4.786994"], ["84166.00", "0.000159"], ["84160.60", "5.509559"], ["84152.10", "3.974109"], ["84143.60", "5.148277"], ["84135.10", "4.064429"], ["84126.60", "4.696674"], ["84118.10", "5.057956"], ["84109.60", "4.335391"], ["83896.11", "0.000094"], ["83896.00", "0.000133"], ["83895.65", "0.000013"], ["83895.00", "0.006121"], ["83894.74", "0.000068"], ["83894.17", "0.000022"], ["83893.81", "0.000010"], ["83893.64", "0.000039"], ["83893.62", "0.000137"], ["83892.29", "0.000143"], ["83891.43", "0.000455"], ["83891.30", "0.000010"], ["83888.89", "0.000163"], ["83888.86", "0.000371"], ["83887.29", "0.000586"], ["83887.11", "0.000075"], ["83886.91", "0.000145"], ["83885.98", "0.000018"], ["83885.71", "0.000069"], ["83884.62", "0.000014"], ["83884.55", "0.000048"], ["83884.30", "0.000161"], ["83882.98", "0.000188"], ["83882.92", "0.002384"], ["83881.99", "0.000038"], ["83880.00", "0.020454"], ["83877.97", "0.000023"], ["83877.55", "0.000010"], ["83877.42", "0.000054"], ["83877.29", "0.000024"], ["83877.05", "0.000008"], ["83876.25", "0.000028"], ["83876.12", "0.000681"], ["83875.99", "0.000299"], ["83875.49", "0.000723"], ["83875.16", "0.000179"], ["83875.00", "0.000145"], ["83874.55", "0.000145"], ["83874.15", "0.000150"], ["83873.87", "0.000041"], ["83873.52", "0.000135"], ["83870.97", "0.000194"], ["83870.95", "0.000078"], ["83870.78", "0.000019"], ["83870.00", "0.000121"], ["83869.57", "0.000035"], ["83868.82", "0.000017"]], "checksum": -1014151156, "ts": "1742142244559"}], "ts": 1742142244563, "record_time": 1742142243.674296}
{"action": "update", "arg": {"instType": "SPOT", "channel": "books", "instId": "BTCUSDT"}, "data": [{"asks": [["84346.62", "0.223590"], ["84346.63", "0.000100"], ["84346.64", "0.000100"], ["84346.65", "0.000100"], ["84348.02", "0"], ["84353.77", "0.030015"], ["84354.25", "0"], ["84354.95", "0.001882"], ["84354.96", "0.009639"], ["84354.97", "0.004974"], ["84354.99", "0.001230"], ["84355.05", "0.001066"], ["84356.03", "0.007627"], ["84356.08", "0.008506"], ["84356.09", "0.016301"], ["84356.10", "0.007955"], ["84356.12", "0.005183"], ["84356.14", "0.004739"], ["84359.69", "0.080082"], ["84361.08", "0.139858"], ["84363.39", "0"], ["84363.50", "0.209200"], ["84364.14", "0.002807"], ["84364.29", "0"], ["84366.77", "1.893203"], ["84367.35", "0.119869"], ["84368.90", "0.001205"], ["84369.70", "0.035952"], ["84370.25", "0"], ["84370.31", "0.006356"], ["84370.89", "0.006356"], ["84371.51", "0.006356"], ["84371.93", "0.006356"], ["84372.17", "0.006356"], ["84372.24", "0.010985"], ["84372.41", "0.006356"], ["84372.66", "0.006356"], ["84373.00", "0.006356"], ["84373.12", "0.006356"], ["84373.49", "0.006356"], ["84373.72", "0.119843"], ["84373.95", "0.006356"], ["84374.06", "0.006356"], ["84374.08", "0.006356"], ["84374.39", "0"], ["84374.54", "0.016428"], ["84374.79", "0.016427"], ["84375.06", "0.006357"], ["84375.25", "0.010984"], ["84375.37", "0.006356"], ["84376.40", "0.006356"], ["84377.11", "0.119895"], ["84377.16", "0.009989"], ["84377.80", "0"], ["84378.91", "0"], ["84378.98", "0.009989"], ["84379.25", "0.119879"], ["84379.80", "0"], ["84380.31", "0.015892"], ["84381.19", "0.006356"], ["84381.80", "0"], ["84382.32", "0.017782"], ["84383.64", "2.230887"], ["84383.68", "0.015891"], ["84383.80", "0"], ["84385.08", "0.010000"], ["84385.44", "0.010986"], ["84385.80", "0"], ["84385.90", "0.001020"], ["84385.96", "0.001807"], ["84387.80", "0"], ["84387.90", "0.001011"], ["84389.80", "0"], ["84389.90", "0.001007"], ["84391.80", "0"], ["84391.90", "0.002516"], ["84393.80", "0"], ["84393.90", "0.006622"], ["84395.80", "0"], ["84395.90", "0.017424"], ["84397.80", "0"], ["84397.90", "0.045855"], ["84398.00", "0"], ["84398.20", "0"], ["84398.60", "0"], ["84399.90", "0.120671"], ["84401.90", "0.317555"], ["84402.20", "0"], ["84402.70", "0"], ["84403.00", "0"], ["84403.90", "0.835671"], ["84405.50", "0"], ["84405.90", "2.199134"], ["84406.20", "0.007470"], ["84406.50", "0"], ["84406.60", "0.141060"], ["84407.50", "0.010380"], ["84408.20", "0"], ["84409.10", "0"], ["84410.40", "0"], ["84411.40", "0"], ["84413.20", "0.013860"], ["84414.20", "0.007440"], ["84414.50", "0.629400"], ["84415.10", "0.512760"], ["84416.20", "0.015120"], ["84418.00", "0.981300"], ["84418.20", "0.007050"], ["84418.50", "0.035550"], ["84419.00", "0.142500"], ["84419.10", "1.574640"], ["84419.90", "2.346780"], ["84421.00", "0.012330"], ["84421.20", "6.226470"], ["84440.00", "0"], ["84448.10", "4.064040"], ["84448.50", "0"], ["84456.60", "5.238096"], ["84457.00", "0"], ["84465.10", "3.883416"], ["84465.50", "0"], ["84473.60", "4.244664"], ["84474.00", "0"], ["84474.20", "0"], ["84482.10", "4.334976"], ["84482.50", "0"], ["84490.60", "4.967160"], ["84491.00", "0"], ["84499.10", "4.696224"], ["84499.50", "0"], ["84501.74", "0.209200"], ["84507.60", "5.328408"], ["84508.00", "0"], ["84510.18", "0.209200"], ["84516.10", "4.876848"], ["84516.50", "0"], ["84524.60", "5.599344"], ["84525.00", "0.000021"], ["84526.40", "0.308747"], ["84533.10", "4.605912"], ["84533.50", "0"], ["84541.60", "3.973728"], ["84542.00", "0"], ["84550.10", "5.509032"], ["84550.50", "0"], ["84558.60", "4.786536"], ["84559.00", "0"], ["84567.10", "5.418720"], ["84567.50", "0"], ["84575.60", "4.515600"], ["84576.00", "0"], ["84584.10", "5.147784"], ["84584.50", "0"], ["84592.60", "5.057472"], ["84593.00", "0"], ["84601.10", "4.154352"], ["84601.50", "0"], ["84609.60", "4.425288"], ["84871.79", "0"], ["84873.84", "0"], ["84874.79", "0"], ["84875.00", "0"], ["84875.78", "0"], ["84876.03", "0"], ["84879.10", "0"], ["84879.37", "0"], ["84879.59", "0"], ["84880.00", "0"], ["84880.89", "0"], ["84882.35", "0"], ["84883.65", "0"], ["84883.72", "0"], ["84883.84", "0"], ["84885.24", "0"], ["84885.53", "0"], ["84886.01", "0"], ["84886.02", "0"], ["84886.96", "0"], ["84887.65", "0"], ["84888.00", "0"], ["84888.68", "0"], ["84888.89", "0"], ["84889.87", "0"], ["84890.00", "0"], ["84892.02", "0"], ["84892.76", "0"], ["84892.78", "0"], ["84894.73", "0"], ["84894.74", "0"], ["84895.69", "0"], ["84895.83", "0"], ["84897.50", "0"], ["84899.08", "0"], ["84899.44", "0"], ["84900.00", "0"], ["84901.15", "0"], ["84903.27", "0"], ["84903.57", "0"], ["84903.79", "0"], ["84903.84", "0"], ["84903.85", "0"], ["84904.06", "0"], ["84904.76", "0"], ["84905.66", "0"], ["84906.08", "0"], ["84906.54", "0"], ["84909.08", "0"], ["84909.09", "0"], ["84909.66", "0"], ["84910.00", "0"]], "bids": [["84346.61", "2.688508"], ["84343.42", "0.006929"], ["84343.40", "0.009564"], ["84343.38", "0.007591"], ["84343.10", "0.041958"], ["84342.80", "0"], ["84341.40", "0.001021"], ["84340.47", "0.055110"], ["84339.40", "0.001265"], ["84339.17", "0.008261"], ["84337.70", "2.547714"], ["84337.40", "0.003329"], ["84336.28", "0.313161"], ["84335.40", "0.008761"], ["84335.34", "0"], ["84335.32", "0"], ["84334.68", "0"], ["84334.04", "0"], ["84333.40", "0.023055"], ["84333.30", "0"], ["84332.40", "0.003058"], ["84331.40", "0.060670"], ["84331.32", "0.014417"], ["84331.30", "0"], ["84329.40", "0.159658"], ["84329.30", "0"], ["84329.28", "0.003017"], ["84329.27", "0.001228"], ["84329.21", "0.000213"], ["84327.54", "0.007345"], ["84327.45", "0.006209"], ["84327.43", "0.007436"], ["84327.40", "0.420152"], ["84327.37", "0.000437"], ["84327.36", "0.009748"], ["84327.34", "0.006535"], ["84327.30", "0"], ["84327.10", "0.008139"], ["84326.81", "0.017822"], ["84326.62", "0.007114"], ["84326.02", "0.247814"], ["84325.92", "0"], ["84325.64", "0.084375"], ["84325.54", "0.015759"], ["84325.52", "0.007870"], ["84325.45", "0.002062"], ["84325.44", "0.016448"], ["84325.43", "0.007475"], ["84325.40", "1.105664"], ["84325.38", "0.006560"], ["84325.30", "0"], ["84325.27", "0.018247"], ["84325.17", "0.005933"], ["84324.86", "0"], ["84324.77", "0.028786"], ["84324.33", "0.056312"], ["84324.19", "0.008158"], ["84324.00", "0.017066"], ["84323.40", "2.909641"], ["84323.34", "0.025065"], ["84323.30", "0"], ["84323.28", "0.007927"], ["84322.91", "0.008981"], ["84322.89", "0.024359"], ["84322.27", "0.227501"], ["84322.17", "0.017319"], ["84322.14", "0.005548"], ["84322.08", "0.005088"], ["84322.06", "0.009627"], ["84322.01", "0.008151"], ["84321.54", "0.002947"], ["84321.40", "7.656950"], ["84321.30", "0.001036"], ["84321.25", "0.008277"], ["84321.23", "0.012639"], ["84321.00", "0.001680"], ["84320.80", "0.001001"], ["84320.70", "0.001005"], ["84320.65", "0.018506"], ["84320.43", "0.052069"], ["84320.33", "0.008667"], ["84319.70", "0.035550"], ["84319.31", "0"], ["84319.30", "0"], ["84319.27", "0"], ["84319.03", "0"], ["84319.02", "0"], ["84319.01", "0"], ["84318.91", "0"], ["84318.90", "0.197876"], ["84318.88", "0.075956"], ["84318.85", "0.222563"], ["84318.74", "0.271695"], ["84318.50", "1.709100"], ["84318.30", "0.410370"], ["84317.79", "0"], ["84317.40", "0.021092"], ["84317.36", "0"], ["84317.30", "0"], ["84315.57", "0.012430"], ["84315.40", "0.142500"], ["84315.30", "0"], ["84314.61", "0.073450"], ["84314.60", "0.035550"], ["84314.59", "0.056596"], ["84314.53", "0"], ["84314.20", "0.672930"], ["84313.97", "0"], ["84313.80", "0.069600"], ["84313.30", "4.364670"], ["84313.20", "0"], ["84313.10", "0.434670"], ["84312.90", "1.350000"], ["84312.30", "0"], ["84312.10", "0.916620"], ["84311.80", "0.069600"], ["84311.79", "0"], ["84311.70", "2.669430"], ["84311.60", "0"], ["84311.20", "0.090000"], ["84310.30", "0"], ["84310.00", "0.360000"], ["84309.70", "0.450030"], ["84309.00", "0.743520"], ["84308.90", "0.090000"], ["84307.30", "0.060000"], ["84307.10", "0"], ["84306.60", "0"], ["84306.40", "0"], ["84305.97", "0"], ["84305.60", "0"], ["84303.90", "0.177960"], ["84303.70", "4.373910"], ["84303.50", "0.008206"], ["84303.40", "0"], ["84303.20", "0"], ["84302.60", "0"], ["84302.40", "0"], ["84302.00", "0"], ["84301.80", "0"], ["84300.90", "0"], ["84300.80", "0"], ["84300.70", "0"], ["84300.60", "0"], ["84300.40", "0"], ["84300.30", "0"], ["84299.80", "0"], ["84299.60", "0"], ["84298.70", "0.007181"], ["84298.68", "0.007582"], ["84297.10", "0.207047"], ["84279.20", "4.515600"], ["84271.10", "0"], ["84270.70", "4.244664"], ["84262.60", "0"], ["84262.20", "4.334976"], ["84254.10", "0"], ["84253.70", "4.064040"], ["84245.60", "0"], ["84245.20", "5.238096"], ["84237.10", "0"], ["84236.70", "4.967160"], ["84228.60", "0"], ["84228.20", "5.057472"], ["84220.10", "0"], ["84219.70", "4.696224"], ["84211.60", "0"], ["84211.20", "4.786536"], ["84203.10", "0"], ["84202.70", "3.883416"], ["84194.60", "0"], ["84194.20", "4.425288"], ["84186.10", "0"], ["84185.70", "4.876848"], ["84177.60", "0"], ["84177.20", "5.509032"], ["84169.10", "0"], ["84168.70", "5.418720"], ["84160.60", "0"], ["84160.20", "3.973728"], ["84152.10", "0"], ["84151.70", "5.328408"], ["84143.60", "0"], ["84143.20", "5.599344"], ["84135.10", "0"], ["84134.70", "4.154352"], ["84126.60", "0"], ["84126.20", "4.605912"], ["84118.10", "0"], ["84117.70", "5.147784"], ["84109.60", "0"], ["83895.00", "0"], ["83894.74", "0"], ["83894.17", "0"], ["83893.81", "0"], ["83893.64", "0"], ["83893.62", "0"], ["83892.29", "0"], ["83891.43", "0"], ["83891.30", "0"], ["83888.89", "0"], ["83888.86", "0"], ["83887.29", "0"], ["83887.11", "0"], ["83886.91", "0"], ["83885.98", "0"], ["83885.71", "0"], ["83884.62", "0"], ["83884.55", "0"], ["83884.30", "0"], ["83882.98", "0"], ["83882.92", "0"], ["83881.99", "0"], ["83880.00", "0"], ["83877.97", "0"], ["83877.55", "0"], ["83877.42", "0"], ["83877.29", "0"], ["83877.05", "0"], ["83876.25", "0"], ["83876.12", "0"], ["83875.99", "0"], ["83875.49", "0"], ["83875.16", "0"], ["83875.00", "0"], ["83874.55", "0"], ["83874.15", "0"], ["83873.87", "0"], ["83873.52", "0"], ["83870.97", "0"], ["83870.95", "0"], ["83870.78", "0"], ["83870.00", "0"], ["83869.57", "0"], ["83868.82", "0"]], "checksum": -48706920, "ts": "1742142244766"}], "ts": 1742142244772, "record_time": 1742142243.882045}
{"action": "update", "arg": {"instType": "SPOT", "channel": "books", "instId": "BTCUSDT"}, "data": [{"asks": [["84346.62", "0.766690"], ["84348.51", "0.063766"], ["84354.93", "0.008962"], ["84354.99", "0.001475"], ["84355.01", "0.006307"], ["84355.06", "0.209200"], ["84356.08", "0.017027"], ["84359.68", "0.074401"], ["84361.08", "0"], ["84371.09", "0"], ["84371.94", "0.209200"], ["84379.65", "0.119881"], ["84385.08", "0"], ["84389.90", "0.001579"], ["84391.90", "0.004153"], ["84393.90", "0.010931"], ["84395.42", "0.031812"], ["84395.90", "0.028764"], ["84397.90", "0.075695"], ["84399.90", "0.199199"], ["84401.90", "0.524206"], ["84403.90", "1.379490"], ["84405.90", "3.630236"], ["84406.20", "0.150150"], ["84406.30", "1.097400"], ["84406.60", "0.103620"], ["84407.50", "0.009000"], ["84410.20", "0.076830"], ["84410.50", "2.347020"], ["84412.60", "0.178050"], ["84414.30", "6.379620"], ["84414.50", "0"], ["84415.10", "0.070590"], ["84417.20", "0.032790"], ["84418.00", "0"], ["84419.10", "7.440360"], ["84419.90", "0"], ["84421.20", "0"], ["84448.10", "5.599344"], ["84456.60", "4.515600"], ["84465.10", "5.509032"], ["84473.60", "5.147784"], ["84482.10", "5.057472"], ["84490.60", "4.334976"], ["84499.10", "4.064040"], ["84501.74", "0"], ["84510.18", "0"], ["84516.10", "4.605912"], ["84524.60", "4.876848"], ["84533.10", "4.967160"], ["84541.60", "3.883416"], ["84550.10", "4.786536"], ["84558.60", "3.973728"], ["84567.10", "4.244664"], ["84575.60", "4.154352"], ["84584.10", "4.696224"], ["84592.60", "5.238096"], ["84601.10", "5.418720"], ["84868.65", "0"], ["84869.57", "0"], ["84871.66", "0"]], "bids": [["84346.61", "2.477682"], ["84342.27", "0.005548"], ["84339.40", "0.001001"], ["84337.71", "0.765313"], ["84337.40", "0.001037"], ["84335.40", "0.001657"], ["84333.40", "0.004361"], ["84332.68", "0.003066"], ["84331.40", "0.011477"], ["84329.40", "0.030203"], ["84329.28", "0.011549"], ["84329.16", "0.003034"], ["84327.43", "0.016422"], ["84327.40", "0.079481"], ["84325.47", "0.007950"], ["84325.40", "0.209159"], ["84323.40", "0.550421"], ["84322.06", "0.014560"], ["84321.40", "1.448475"], ["84321.00", "0.001050"], ["84320.60", "0.274770"], ["84320.09", "0.010234"], ["84318.92", "0.263130"], ["84318.50", "1.106610"], ["84318.30", "0"], ["84315.40", "0.142680"], ["84314.70", "2.347350"], ["84314.20", "0.222810"], ["84314.10", "0.450030"], ["84313.80", "0"], ["84313.30", "1.888650"], ["84312.90", "0"], ["84310.37", "0"], ["84310.00", "0.038520"], ["84309.70", "0"], ["84309.00", "0.456810"], ["84308.70", "0.035550"], ["84307.30", "0"], ["84307.20", "0"], ["84303.70", "3.314130"], ["84279.20", "4.876848"], ["84270.70", "3.973728"], ["84262.20", "4.605912"], ["84253.70", "4.967160"], ["84245.20", "5.057472"], ["84236.70", "4.334976"], ["84228.20", "5.147784"], ["84219.70", "4.244664"], ["84211.20", "5.599344"], ["84202.70", "5.418720"], ["84194.20", "4.154352"], ["84185.70", "4.696224"], ["84177.20", "3.883416"], ["84168.70", "5.509032"], ["84160.20", "5.328408"], ["84151.70", "4.786536"], ["84143.20", "4.515600"], ["84134.70", "5.238096"], ["84126.20", "4.425288"], ["84117.70", "4.064040"], ["83898.68", "0"], ["83896.11", "0"], ["83896.00", "0"], ["83895.65", "0"]], "checksum": 400188092, "ts": "1742142244969"}], "ts": 1742142244973, "record_time": 1742142244.080762}
{"action": "update", "arg": {"instType": "SPOT", "channel": "books", "instId": "BTCUSDT"}, "data": [{"asks": [["84355.06", "0"], ["84358.93", "0.139856"], ["84359.68", "0"], ["84363.50", "0"], ["84389.90", "0.001016"], ["84391.90", "0.002534"], ["84393.90", "0.006667"], ["84395.90", "0.017546"], ["84397.90", "0.046174"], ["84399.90", "0.121509"], ["84401.90", "0.319763"], ["84403.90", "0.841481"], ["84405.90", "2.214423"], ["84406.20", "0.007470"], ["84406.30", "0.001830"], ["84406.60", "0.102780"], ["84407.50", "0"], ["84410.20", "0.007050"], ["84410.50", "0"], ["84412.60", "0.142500"], ["84414.10", "0.177210"], ["84414.30", "4.624620"], ["84415.10", "0.324150"], ["84416.70", "2.346840"], ["84418.00", "0.410370"], ["84418.20", "0.471300"], ["84448.10", "4.696224"], ["84456.60", "3.973728"], ["84465.10", "4.064040"], ["84473.60", "4.515600"], ["84482.10", "4.334976"], ["84490.60", "4.786536"], ["84499.10", "5.509032"], ["84507.60", "4.967160"], ["84516.10", "5.328408"], ["84524.60", "5.057472"], ["84533.10", "4.605912"], ["84541.60", "5.238096"], ["84550.10", "4.876848"], ["84558.60", "4.244664"], ["84567.10", "5.147784"], ["84575.60", "3.883416"], ["84584.10", "4.425288"], ["84592.60", "5.599344"], ["84601.10", "4.154352"], ["84609.60", "5.418720"], ["84868.65", "0.000035"]], "bids": [["84346.61", "2.742382"], ["84344.72", "0"], ["84344.42", "0.010000"], ["84340.47", "0"], ["84337.40", "0.001977"], ["84336.29", "0.096674"], ["84335.40", "0.005202"], ["84333.40", "0.013689"], ["84331.40", "0.036023"], ["84330.11", "0.189501"], ["84329.40", "0.094799"], ["84327.40", "0.249470"], ["84325.40", "0.656500"], ["84323.40", "1.727631"], ["84321.40", "4.546398"], ["84321.30", "0.001260"], ["84320.90", "2.347170"], ["84320.80", "0"], ["84320.70", "0"], ["84320.60", "0"], ["84319.70", "0.080850"], ["84318.90", "0"], ["84318.50", "0"], ["84318.48", "0.003049"], ["84318.40", "0.197876"], ["84315.80", "0.144870"], ["84314.70", "0"], ["84314.20", "0"], ["84314.10", "0"], ["84313.30", "0.731340"], ["84313.10", "0"], ["84312.90", "1.359000"], ["84311.80", "0"], ["84311.70", "0"], ["84311.20", "0"], ["84309.94", "0"], ["84309.00", "1.692690"], ["84308.90", "0"], ["84308.80", "0.072180"], ["84307.60", "0.099000"], ["84307.15", "0"], ["84306.00", "4.326330"], ["84305.50", "0.590370"], ["84304.50", "0.009000"], ["84303.90", "0"], ["84303.80", "0"], ["84303.70", "0"], ["84298.71", "0.018018"], ["84297.10", "0"], ["84279.20", "4.334976"], ["84270.70", "4.244664"], ["84262.20", "4.425288"], ["84253.70", "4.064040"], ["84245.20", "5.147784"], ["84236.70", "5.238096"], ["84228.20", "4.605912"], ["84219.70", "4.696224"], ["84211.20", "4.876848"], ["84194.20", "4.967160"], ["84185.70", "5.057472"], ["84177.20", "4.515600"], ["84168.70", "4.786536"], ["84167.00", "0"], ["84164.00", "0"], ["84160.20", "3.883416"], ["84151.70", "5.509032"], ["84143.20", "5.328408"], ["84134.70", "4.154352"], ["84126.20", "5.599344"], ["84117.70", "3.973728"], ["83898.68", "0.000010"], ["83896.11", "0.000094"], ["83896.00", "0.000133"], ["83895.65", "0.000013"], ["83895.00", "0.006121"], ["83894.74", "0.000068"], ["83894.17", "0.000022"], ["83893.81", "0.000010"], ["83893.64", "0.000039"], ["83893.62", "0.000137"], ["83892.29", "0.000143"]], "checksum": 1654251001, "ts": "1742142245171"}], "ts": 1742142245174, "record_time": 1742142244.282743}
{"action": "update", "arg": {"instType": "SPOT", "channel": "books", "instId": "BTCUSDT"}, "data": [{"asks": [["84358.59", "0.139853"], ["84358.92", "0.074400"], ["84358.93", "0"], ["84363.50", "0.209200"], ["84376.27", "0.148098"], ["84389.90", "0.001171"], ["84391.90", "0.003223"], ["84393.90", "0.008482"], ["84395.90", "0.022319"], ["84397.90", "0.058735"], ["84399.90", "0.154567"], ["84401.90", "0.406755"], ["84403.90", "1.070406"], ["84405.90", "2.816858"], ["84406.20", "0.229470"], ["84406.30", "0.001620"], ["84406.60", "0.102600"], ["84412.60", "0.178050"], ["84413.60", "4.580910"], ["84414.30", "4.907040"], ["84416.70", "0"], ["84419.10", "3.745980"], ["84421.00", "0"], ["84448.10", "4.515600"], ["84456.60", "5.328408"], ["84465.10", "5.509032"], ["84473.60", "4.244664"], ["84482.10", "3.973728"], ["84490.60", "4.334976"], ["84499.10", "4.605912"], ["84501.74", "0.209200"], ["84507.60", "5.147784"], ["84516.10", "5.238096"], ["84524.60", "4.786536"], ["84533.10", "4.064040"], ["84541.60", "5.418720"], ["84550.10", "5.599344"], ["84558.60", "4.876848"], ["84567.10", "4.696224"], ["84575.60", "5.057472"], ["84584.10", "4.154352"], ["84592.60", "3.883416"], ["84601.10", "4.967160"], ["84609.60", "4.425288"], ["84868.42", "0"], ["84868.52", "0"], ["84868.65", "0"]], "bids": [["84346.61", "3.095514"], ["84337.40", "0.001762"], ["84335.40", "0.004638"], ["84333.40", "0.012205"], ["84331.40", "0.031903"], ["84330.12", "0.152857"], ["84329.40", "0.083955"], ["84329.06", "0"], ["84327.40", "0.220936"], ["84325.40", "0.581409"], ["84323.40", "1.530024"], ["84321.40", "4.026379"], ["84320.90", "0.729360"], ["84319.70", "0.035550"], ["84317.80", "2.347260"], ["84315.80", "0.053460"], ["84315.40", "0.142500"], ["84315.14", "0.001972"], ["84313.30", "0.713640"], ["84310.90", "0.410370"], ["84308.60", "0.090000"], ["84304.20", "0"], ["84303.90", "0.177960"], ["84303.80", "0.069600"], ["84279.20", "3.973728"], ["84270.70", "5.418720"], ["84262.20", "5.509032"], ["84253.70", "4.244664"], ["84245.20", "5.599344"], ["84236.70", "4.515600"], ["84228.20", "5.328408"], ["84219.70", "4.876848"], ["84211.20", "5.147784"], ["84202.70", "3.883416"], ["84194.20", "4.696224"], ["84177.20", "4.786536"], ["84169.99", "0.001017"], ["84168.70", "4.154352"], ["84160.20", "4.605912"], ["84151.70", "4.967160"], ["84143.20", "4.334976"], ["84134.70", "4.064040"], ["84126.20", "5.238096"], ["84117.70", "4.425288"], ["83894.17", "0"], ["83893.81", "0"], ["83893.64", "0"], ["83893.62", "0"], ["83892.29", "0"]], "checksum": -247342594, "ts": "1742142245384"}], "ts": 1742142245387, "record_time": 1742142244.494528}
{"action": "update", "arg": {"instType": "SPOT", "channel": "books", "instId": "BTCUSDT"}, "data": [{"asks": [["84348.44", "0.063766"], ["84348.51", "0"], ["84358.08", "0.139852"], ["84358.59", "0"], ["84358.92", "0"], ["84389.90", "0.001334"], ["84391.90", "0.003510"], ["84393.90", "0.009238"], ["84395.90", "0.024311"], ["84397.90", "0.063858"], ["84399.90", "0.168046"], ["84401.90", "0.442226"], ["84403.90", "1.163753"], ["84405.90", "3.062509"], ["84406.20", "0.944280"], ["84406.30", "0.001230"], ["84410.20", "0.076650"], ["84410.60", "2.347020"], ["84413.60", "1.529910"], ["84415.10", "0.209880"], ["84418.00", "0"], ["84448.10", "3.883416"], ["84456.60", "5.418720"], ["84465.10", "4.967160"], ["84473.60", "5.147784"], ["84482.10", "4.605912"], ["84490.60", "5.057472"], ["84499.10", "4.244664"], ["84507.60", "5.328408"], ["84516.10", "4.154352"], ["84524.60", "5.599344"], ["84533.10", "4.876848"], ["84541.60", "3.973728"], ["84550.10", "4.786536"], ["84558.60", "4.064040"], ["84567.10", "5.238096"], ["84575.60", "5.509032"], ["84584.10", "4.515600"], ["84592.60", "4.425288"], ["84601.10", "4.696224"], ["84609.60", "4.334976"], ["84868.42", "0.000031"]], "bids": [["84343.09", "0"], ["84339.05", "0.003004"], ["84335.40", "0.004471"], ["84333.40", "0.011768"], ["84331.40", "0.031170"], ["84329.40", "0.082025"], ["84327.40", "0.215855"], ["84326.03", "0.391307"], ["84325.40", "0.568042"], ["84323.40", "1.494847"], ["84321.40", "3.933807"], ["84321.00", "0.276060"], ["84320.90", "0.728520"], ["84303.90", "0"], ["84303.80", "0"], ["84279.20", "4.786536"], ["84270.70", "5.509032"], ["84262.20", "5.328408"], ["84253.70", "4.515600"], ["84245.20", "5.057472"], ["84236.70", "4.967160"], ["84228.20", "4.425288"], ["84219.70", "4.696224"], ["84211.20", "3.973728"], ["84202.70", "5.238096"], ["84194.20", "4.605912"], ["84185.70", "4.154352"], ["84177.20", "4.334976"], ["84168.70", "4.064040"], ["84160.20", "3.883416"], ["84151.70", "4.876848"], ["84143.20", "5.418720"], ["84134.70", "5.599344"], ["84126.20", "5.147784"], ["84117.70", "4.244664"], ["83894.17", "0.000022"]], "checksum": -604848407, "ts": "1742142245583"}], "ts": 1742142245587, "record_time": 1742142244.694672}
{"action": "update", "arg": {"instType": "SPOT", "channel": "books", "instId": "BTCUSDT"}, "data": [{"asks": [["84355.72", "0.139851"], ["84358.08", "0"], ["84363.49", "0.063602"], ["84363.50", "0"], ["84389.90", "0.001018"], ["84391.90", "0.001044"], ["84393.90", "0.001474"], ["84395.42", "0"], ["84395.90", "0.003879"], ["84397.90", "0.010320"], ["84399.90", "0.027158"], ["84401.90", "0.071467"], ["84403.90", "0.188073"], ["84405.90", "0.494927"], ["84406.20", "0.008640"], ["84406.30", "0"], ["84410.20", "0.007050"], ["84410.60", "0"], ["84412.60", "0.142500"], ["84413.60", "0"], ["84414.30", "0"], ["84418.70", "2.346810"], ["84420.00", "0.117000"], ["84448.10", "4.876848"], ["84456.60", "4.696224"], ["84465.10", "4.154352"], ["84473.60", "4.244664"], ["84482.10", "5.057472"], ["84490.60", "3.883416"], ["84499.10", "3.973728"], ["84507.60", "4.425288"], ["84516.10", "5.599344"], ["84524.60", "4.605912"], ["84533.10", "4.515600"], ["84541.60", "4.334976"], ["84550.10", "5.509032"], ["84558.60", "5.147784"], ["84567.10", "4.064040"], ["84575.60", "4.967160"], ["84584.10", "5.238096"], ["84592.60", "4.786536"], ["84601.10", "5.328408"], ["84609.60", "5.418720"], ["84868.52", "0.000013"], ["84868.65", "0.000035"], ["84869.57", "0.000932"], ["84871.66", "0.000078"]], "bids": [["84346.61", "3.255365"], ["84346.22", "0.019720"], ["84346.00", "0.000121"], ["84343.10", "0"], ["84337.40", "0.002606"], ["84335.40", "0.006859"], ["84333.40", "0.018050"], ["84331.40", "0.047500"], ["84329.40", "0.125001"], ["84327.40", "0.328948"], ["84325.40", "0.865544"], ["84323.40", "2.277748"], ["84321.40", "5.994073"], ["84321.00", "0.001050"], ["84320.90", "0"], ["84320.40", "2.347170"], ["84317.80", "0"], ["84317.60", "0.260940"], ["84315.80", "0.069600"], ["84309.50", "0.383040"], ["84308.80", "0"], ["84308.70", "0.105000"], ["84306.00", "3.943260"], ["84303.80", "0.069600"], ["84279.20", "5.238096"], ["84270.70", "4.154352"], ["84262.20", "4.064040"], ["84253.70", "5.509032"], ["84245.20", "3.883416"], ["84236.70", "4.425288"], ["84228.20", "5.418720"], ["84219.70", "4.515600"], ["84211.20", "4.786536"], ["84202.70", "4.605912"], ["84194.20", "5.057472"], ["84185.70", "5.599344"], ["84177.20", "5.328408"], ["84168.70", "4.334976"], ["84160.20", "3.973728"], ["84151.70", "5.147784"], ["84143.20", "4.244664"], ["84134.70", "4.967160"], ["84126.20", "4.696224"], ["84117.70", "4.876848"], ["83894.74", "0"], ["83894.17", "0"]], "checksum": 1270561556, "ts": "1742142245788"}], "ts": 1742142245794, "record_time": 1742142244.90198}
{"action": "update", "arg": {"instType": "SPOT", "channel": "books", "instId": "BTCUSDT"}, "data": [{"asks": [["84346.62", "0.300000"], ["84348.44", "0"], ["84355.72", "0"], ["84363.49", "0"], ["84371.94", "0"], ["84376.27", "0"], ["84391.90", "0.001033"], ["84393.90", "0.002402"], ["84395.90", "0.006321"], ["84397.90", "0.016633"], ["84399.90", "0.043771"], ["84401.90", "0.115188"], ["84403.90", "0.303125"], ["84405.90", "0.797698"], ["84406.10", "0.726330"], ["84406.20", "0.008220"], ["84412.60", "0.194220"], ["84413.30", "2.346960"], ["84414.10", "0"], ["84415.10", "0.887700"], ["84418.70", "0"], ["84419.10", "6.131430"], ["84448.10", "4.605912"], ["84456.60", "5.599344"], ["84465.10", "3.883416"], ["84473.60", "5.418720"], ["84482.10", "5.328408"], ["84490.60", "4.515600"], ["84499.10", "5.147784"], ["84507.60", "5.238096"], ["84516.10", "4.064040"], ["84524.60", "4.244664"], ["84533.10", "4.425288"], ["84541.60", "4.786536"], ["84550.10", "4.876848"], ["84558.60", "4.696224"], ["84567.10", "3.973728"], ["84575.60", "4.154352"], ["84584.10", "5.057472"], ["84592.60", "4.334976"], ["84601.10", "5.509032"], ["84609.60", "4.967160"], ["84871.79", "0.000014"], ["84873.84", "0.000057"], ["84874.79", "0.000096"], ["84875.00", "0.000959"], ["84875.78", "0.000038"]], "bids": [["84346.61", "3.254305"], ["84343.00", "0.000159"], ["84337.40", "0.002242"], ["84335.40", "0.005901"], ["84333.40", "0.015528"], ["84331.40", "0.040864"], ["84329.40", "0.107537"], ["84327.40", "0.282991"], ["84325.40", "0.744714"], ["84323.41", "0.068395"], ["84323.40", "1.959773"], ["84323.00", "0.000159"], ["84321.40", "5.157296"], ["84320.40", "3.062940"], ["84317.70", "0.304740"], ["84317.60", "0"], ["84317.40", "0.916620"], ["84312.42", "0.018018"], ["84312.10", "0"], ["84304.50", "0"], ["84303.80", "0"], ["84298.71", "0"], ["84279.20", "4.154352"], ["84270.70", "5.328408"], ["84262.20", "3.973728"], ["84253.70", "4.334976"], ["84245.20", "4.515600"], ["84236.70", "3.883416"], ["84228.20", "4.876848"], ["84219.70", "4.696224"], ["84211.20", "5.238096"], ["84202.70", "5.418720"], ["84194.20", "4.967160"], ["84185.70", "4.064040"], ["84177.20", "4.425288"], ["84168.70", "5.509032"], ["84165.00", "0.000159"], ["84160.20", "5.057472"], ["84143.20", "5.599344"], ["84134.70", "4.605912"], ["84126.20", "4.244664"], ["84117.70", "4.786536"], ["83895.00", "0"]], "checksum": -490635734, "ts": "1742142245992"}], "ts": 1742142245997, "record_time": 1742142245.103857}
{"action": "update", "arg": {"instType": "SPOT", "channel": "books", "instId": "BTCUSDT"}, "data": [{"asks": [["84346.62", "0.000100"], ["84359.83", "0"], ["84366.71", "0.139848"], ["84383.63", "0.763557"], ["84385.90", "0"], ["84386.70", "0.148098"], ["84387.90", "0"], ["84388.20", "0.010000"], ["84388.60", "0.001025"], ["84389.90", "0"], ["84390.60", "0.001021"], ["84391.90", "0"], ["84392.60", "0.001013"], ["84393.90", "0"], ["84394.60", "0.001009"], ["84395.90", "0"], ["84396.60", "0.001009"], ["84397.90", "0"], ["84398.60", "0.001004"], ["84399.90", "0"], ["84400.60", "0.001114"], ["84401.90", "0"], ["84402.60", "0.002931"], ["84403.90", "0"], ["84404.60", "0.007842"], ["84405.90", "0"], ["84406.10", "0"], ["84406.20", "0"], ["84406.60", "0.020844"], ["84408.60", "0.054851"], ["84409.10", "0.001020"], ["84410.00", "0.001031"], ["84410.20", "0.007260"], ["84411.20", "0.001038"], ["84412.60", "0"], ["84413.30", "0"], ["84414.70", "0.357570"], ["84415.10", "0"], ["84416.20", "0"], ["84417.20", "0"], ["84418.20", "0.007050"], ["84418.50", "0"], ["84419.10", "0"], ["84419.80", "0.032790"], ["84420.00", "0.002000"], ["84421.00", "0.015120"], ["84422.20", "0.078150"], ["84422.60", "0.258030"], ["84423.00", "0.045600"], ["84423.90", "0.493710"], ["84425.40", "0.142500"], ["84425.50", "1.350000"], ["84426.20", "0.007050"], ["84448.10", "0"], ["84450.80", "3.883291"], ["84453.76", "0"], ["84456.60", "0"], ["84459.30", "4.967000"], ["84465.10", "0"], ["84467.80", "5.057309"], ["84473.60", "0"], ["84476.30", "4.696073"], ["84480.51", "0.072042"], ["84482.10", "0"], ["84484.80", "4.876691"], ["84490.60", "0"], ["84493.30", "5.237928"], ["84499.10", "0"], ["84501.80", "5.418546"], ["84507.60", "0"], ["84510.18", "0.209200"], ["84510.30", "5.508855"], ["84516.10", "0"], ["84518.80", "4.605764"], ["84524.60", "0"], ["84527.30", "5.328237"], ["84533.10", "0"], ["84535.80", "4.244528"], ["84541.60", "0"], ["84544.30", "5.147618"], ["84550.10", "0"], ["84552.80", "4.425146"], ["84558.60", "0"], ["84561.30", "5.599164"], ["84567.10", "0"], ["84569.80", "4.515455"], ["84575.60", "0"], ["84578.30", "4.154219"], ["84584.10", "0"], ["84586.80", "4.786382"], ["84592.60", "0"], ["84595.30", "4.334837"], ["84601.10", "0"], ["84603.80", "3.973600"], ["84609.60", "0"], ["84612.30", "4.063909"], ["84871.66", "0"], ["84871.79", "0"], ["84873.84", "0"], ["84874.79", "0"], ["84875.00", "0"], ["84875.78", "0"]], "bids": [["84346.61", "3.254661"], ["84344.42", "0"], ["84344.10", "0.001004"], ["84342.10", "0.001417"], ["84341.40", "0"], ["84340.10", "0.003729"], ["84339.40", "0"], ["84339.05", "0"], ["84338.10", "0.009971"], ["84337.40", "0"], ["84336.10", "0.026240"], ["84335.40", "0"], ["84334.10", "0.069051"], ["84333.40", "0"], ["84332.10", "0.181715"], ["84331.40", "0"], ["84330.11", "0"], ["84330.10", "0.478197"], ["84329.40", "0"], ["84329.16", "0"], ["84328.10", "1.258413"], ["84327.40", "0"], ["84326.10", "3.311612"], ["84326.03", "0"], ["84325.40", "0"], ["84324.10", "8.714770"], ["84323.90", "0.411810"], ["84323.80", "0.069990"], ["84323.40", "0"], ["84323.10", "0.001014"], ["84323.00", "0.405750"], ["84322.80", "2.119800"], ["84322.70", "0.916620"], ["84322.40", "0.035550"], ["84322.10", "5.207100"], ["84321.80", "0.243720"], ["84321.40", "3.994440"], ["84321.30", "0"], ["84321.00", "2.669430"], ["84320.60", "0.704430"], ["84320.40", "3.694380"], ["84319.80", "0.069600"], ["84319.70", "0"], ["84318.50", "0.012000"], ["84317.70", "0.563610"], ["84317.40", "0.035550"], ["84316.90", "0.090000"], ["84316.60", "0.015150"], ["84316.10", "0.015180"], ["84315.90", "0.090000"], ["84315.70", "0.177960"], ["84314.60", "0"], ["84313.60", "0.090000"], ["84313.30", "0.674250"], ["84312.80", "0.038520"], ["84311.80", "0.269760"], ["84311.50", "0.035550"], ["84310.90", "0"], ["84310.00", "0"], ["84309.50", "0"], ["84309.00", "0"], ["84308.70", "0"], ["84308.60", "0"], ["84307.60", "0"], ["84306.00", "0"], ["84305.80", "0"], ["84305.50", "0"], ["84304.70", "0"], ["84300.35", "0"], ["84281.90", "5.508855"], ["84279.20", "0"], ["84273.40", "5.418546"], ["84270.70", "0"], ["84264.90", "5.599164"], ["84262.20", "0"], ["84256.40", "4.244528"], ["84253.70", "0"], ["84247.90", "4.334837"], ["84245.20", "0"], ["84239.40", "4.425146"], ["84236.70", "0"], ["84230.90", "4.063909"], ["84228.20", "0"], ["84222.40", "4.786382"], ["84219.70", "0"], ["84213.90", "3.973600"], ["84211.20", "0"], ["84205.40", "4.876691"], ["84202.70", "0"], ["84196.90", "5.147618"], ["84194.20", "0"], ["84188.40", "5.237928"], ["84185.70", "0"], ["84179.90", "4.605764"], ["84177.20", "0"], ["84171.40", "5.057309"], ["84168.70", "0"], ["84162.90", "4.515455"], ["84160.20", "0"], ["84154.40", "4.967000"], ["84151.70", "0"], ["84145.90", "5.328237"], ["84143.20", "0"], ["84137.40", "4.696073"], ["84134.70", "0"], ["84128.90", "4.154219"], ["84126.20", "0"], ["84120.40", "3.883291"], ["84117.70", "0"]], "checksum": -1962797201, "ts": "1742142246196"}], "ts": 1742142246203, "record_time": 1742142245.312689}
{"action": "update", "arg": {"instType": "SPOT", "channel": "books", "instId": "BTCUSDT"}, "data": [{"asks": [["84346.62", "0"], ["84346.66", "0.000100"], ["84353.77", "0"], ["84354.93", "0"], ["84354.95", "0"], ["84354.96", "0"], ["84354.97", "0"], ["84354.99", "0"], ["84355.01", "0"], ["84355.05", "0"], ["84356.03", "0"], ["84356.08", "0"], ["84356.09", "0"], ["84356.10", "0"], ["84356.12", "0"], ["84356.14", "0"], ["84359.69", "0"], ["84360.00", "0.002000"], ["84363.59", "0.001882"], ["84363.61", "0.008962"], ["84363.65", "0.001230"], ["84363.71", "0.001311"], ["84363.73", "0.006307"], ["84364.75", "0.007627"], ["84364.78", "0.008506"], ["84364.80", "0.014469"], ["84364.84", "0.001162"], ["84364.86", "0.009922"], ["84365.38", "0.139847"], ["84366.71", "0"], ["84366.76", "0.616976"], ["84366.77", "0"], ["84367.35", "0"], ["84368.23", "0.080082"], ["84368.90", "0"], ["84369.70", "0"], ["84370.31", "0"], ["84370.89", "0"], ["84371.50", "0.014226"], ["84371.51", "0"], ["84371.93", "0"], ["84371.94", "0.209200"], ["84372.17", "0"], ["84372.24", "0"], ["84372.41", "0"], ["84372.66", "0"], ["84373.00", "0"], ["84373.12", "0"], ["84373.49", "0"], ["84373.72", "0"], ["84373.95", "0"], ["84374.06", "0"], ["84374.08", "0"], ["84374.54", "0"], ["84374.79", "0"], ["84375.06", "0"], ["84375.25", "0"], ["84375.37", "0"], ["84376.15", "0.119869"], ["84376.40", "0"], ["84376.54", "0.001205"], ["84377.11", "0"], ["84377.16", "0"], ["84377.37", "0.035952"], ["84378.65", "0.006356"], ["84378.84", "0.006356"], ["84378.98", "0"], ["84379.25", "0"], ["84379.30", "0.006356"], ["84380.31", "0"], ["84380.33", "0.012712"], ["84380.44", "0.006356"], ["84380.55", "0.006356"], ["84380.59", "0.006356"], ["84380.83", "0.006356"], ["84380.92", "0.010985"], ["84381.19", "0"], ["84381.20", "0.006356"], ["84381.46", "0.119843"], ["84381.63", "0.006356"], ["84381.90", "0.016428"], ["84381.93", "0.016427"], ["84382.21", "0.006356"], ["84382.24", "0.006356"], ["84382.51", "0.006356"], ["84382.81", "0.006357"], ["84383.60", "0.010984"], ["84383.64", "0"], ["84384.56", "0.006356"], ["84385.47", "0.119895"], ["84385.57", "0.009989"], ["84385.96", "0"], ["84386.34", "0.009989"], ["84386.60", "0.119879"], ["84387.59", "0.015892"], ["84388.60", "0"], ["84389.72", "0.006356"], ["84390.60", "0"], ["84392.60", "0"], ["84393.55", "0.001807"], ["84394.60", "0"], ["84394.70", "0.001013"], ["84396.60", "0"], ["84396.70", "0.001026"], ["84398.60", "0"], ["84398.70", "0.001007"], ["84400.60", "0"], ["84400.70", "0.001037"], ["84402.60", "0"], ["84402.70", "0.001533"], ["84404.60", "0"], ["84404.70", "0.004036"], ["84406.60", "0"], ["84406.70", "0.010619"], ["84408.60", "0"], ["84408.70", "0.027945"], ["84409.10", "0"], ["84410.00", "0"], ["84410.20", "0"], ["84410.70", "0.073334"], ["84411.20", "0"], ["84412.70", "0.192985"], ["84413.20", "0"], ["84414.20", "0"], ["84414.70", "0.507854"], ["84414.80", "0.391200"], ["84415.40", "0.005850"], ["84415.90", "0.833580"], ["84419.80", "0"], ["84421.00", "0"], ["84421.20", "0.141690"], ["84422.60", "0"], ["84423.80", "2.228970"], ["84423.90", "5.904180"], ["84425.50", "0"], ["84426.50", "0.258030"], ["84426.70", "0.015120"], ["84427.70", "0.152550"], ["84429.20", "0.464250"], ["84429.80", "6.177660"], ["84430.20", "0.007050"], ["84430.50", "3.650730"], ["84430.70", "0.013830"], ["84450.80", "0"], ["84456.90", "3.883009"], ["84459.30", "0"], ["84465.40", "4.244219"], ["84467.80", "0"], ["84473.90", "5.418151"], ["84476.30", "0"], ["84482.40", "4.063614"], ["84484.80", "0"], ["84490.90", "5.147244"], ["84493.30", "0.209200"], ["84499.40", "4.153916"], ["84501.80", "0"], ["84507.90", "5.598756"], ["84510.30", "0"], ["84516.40", "4.695731"], ["84518.80", "0"], ["84524.90", "5.056941"], ["84527.30", "0"], ["84533.40", "5.327849"], ["84535.80", "0"], ["84541.90", "4.334521"], ["84544.30", "0"], ["84550.40", "5.237546"], ["84552.80", "0"], ["84558.90", "4.515126"], ["84561.30", "0"], ["84567.40", "4.605429"], ["84569.80", "0"], ["84575.90", "3.973311"], ["84578.30", "0"], ["84584.40", "4.876336"], ["84586.80", "0"], ["84592.90", "4.786034"], ["84595.30", "0"], ["84601.40", "4.966639"], ["84603.80", "0"], ["84609.90", "5.508454"], ["84612.30", "0"], ["84618.40", "4.424824"], ["84871.66", "0.000078"]], "bids": [["84346.62", "1.037406"], ["84346.61", "2.899730"], ["84346.20", "0.002078"], ["84344.20", "0.005470"], ["84344.10", "0"], ["84343.42", "0"], ["84343.40", "0"], ["84343.38", "0"], ["84342.27", "0"], ["84342.20", "0.014393"], ["84342.10", "0"], ["84340.20", "0.037877"], ["84340.10", "0"], ["84339.17", "0"], ["84338.20", "0.099676"], ["84338.10", "0"], ["84337.98", "0.001228"], ["84337.90", "0.008532"], ["84337.89", "0.000213"], ["84336.91", "0.003017"], ["84336.20", "0.262305"], ["84336.10", "0"], ["84336.05", "0.007345"], ["84335.96", "0.018671"], ["84335.95", "0.007436"], ["84335.94", "0.008986"], ["84335.83", "0.006535"], ["84335.76", "0.008139"], ["84334.82", "0.247814"], ["84334.37", "0.007870"], ["84334.20", "0.690277"], ["84334.10", "0"], ["84334.09", "0.007469"], ["84334.05", "0.015759"], ["84333.94", "0.017822"], ["84333.85", "0.016448"], ["84333.80", "0.018247"], ["84333.58", "0.005933"], ["84333.50", "0.084375"], ["84333.01", "0.056312"], ["84332.88", "0.007114"], ["84332.59", "0.006560"], ["84332.41", "0.017066"], ["84332.40", "0"], ["84332.20", "1.816518"], ["84332.13", "0.028786"], ["84332.10", "0"], ["84331.73", "0.007927"], ["84330.72", "0.005548"], ["84330.70", "0.004933"], ["84330.66", "0.005088"], ["84330.56", "0.007311"], ["84330.47", "0.025065"], ["84330.45", "0.017048"], ["84330.44", "0.008158"], ["84330.42", "0.008981"], ["84330.41", "0.017319"], ["84330.20", "4.780312"], ["84330.10", "0"], ["84330.00", "0.227501"], ["84329.80", "0.001049"], ["84329.73", "0.012639"], ["84329.28", "0"], ["84329.27", "0"], ["84329.21", "0"], ["84329.20", "0.197876"], ["84329.05", "0.018506"], ["84328.99", "0.008277"], ["84328.90", "0.002947"], ["84328.81", "0.008667"], ["84328.77", "0.052069"], ["84328.61", "0.010227"], ["84328.60", "0.035730"], ["84328.30", "0.105750"], ["84328.20", "0.142680"], ["84328.10", "0"], ["84327.60", "2.346990"], ["84327.54", "0"], ["84327.45", "0"], ["84327.43", "0"], ["84327.37", "0"], ["84327.36", "0"], ["84327.34", "0"], ["84327.10", "0"], ["84327.09", "0.271695"], ["84326.81", "0"], ["84326.62", "0"], ["84326.34", "0.075956"], ["84326.20", "0.222563"], ["84326.11", "0.459702"], ["84326.10", "0"], ["84326.02", "0"], ["84325.80", "0.247500"], ["84325.64", "0"], ["84325.54", "0"], ["84325.52", "0"], ["84325.50", "1.350000"], ["84325.47", "0"], ["84325.45", "0"], ["84325.44", "0"], ["84325.43", "0"], ["84325.38", "0"], ["84325.27", "0"], ["84325.17", "0"], ["84324.77", "0"], ["84324.76", "0.021092"], ["84324.33", "0"], ["84324.19", "0"], ["84324.10", "5.546550"], ["84324.09", "0.012430"], ["84324.00", "0"], ["84323.90", "0.410370"], ["84323.80", "0.069600"], ["84323.34", "0"], ["84323.28", "0"], ["84323.10", "0"], ["84323.00", "0.000159"], ["84322.91", "0"], ["84322.89", "0"], ["84322.80", "0"], ["84322.27", "0"], ["84322.17", "0"], ["84322.14", "0"], ["84322.10", "0"], ["84322.08", "0"], ["84322.06", "0"], ["84322.01", "0"], ["84321.54", "0"], ["84321.40", "2.963940"], ["84321.25", "0"], ["84321.23", "0"], ["84320.65", "0"], ["84320.60", "0"], ["84320.43", "0"], ["84320.33", "0"], ["84320.09", "0"], ["84318.88", "0"], ["84318.85", "0"], ["84318.80", "0.015090"], ["84318.74", "0"], ["84318.50", "0.027120"], ["84318.40", "0"], ["84318.30", "0.015090"], ["84318.21", "0.023721"], ["84317.70", "0.255210"], ["84317.60", "0.099000"], ["84317.40", "0.125550"], ["84316.60", "0"], ["84316.10", "0"], ["84315.70", "0"], ["84315.57", "0"], ["84314.88", "0.023921"], ["84313.60", "0"], ["84313.30", "0"], ["84313.26", "0.017780"], ["84312.90", "0"], ["84312.80", "0"], ["84312.18", "0.008206"], ["84311.80", "0"], ["84311.50", "0"], ["84307.30", "0.007582"], ["84307.18", "0.007181"], ["84303.50", "0"], ["84302.34", "0"], ["84299.60", "0.207047"], ["84298.70", "0"], ["84298.68", "0"], ["84298.40", "0"], ["84288.00", "5.508454"], ["84281.90", "0"], ["84279.50", "4.244219"], ["84273.40", "0"], ["84271.00", "4.786034"], ["84264.90", "0"], ["84262.50", "4.605429"], ["84256.40", "0"], ["84254.00", "5.598756"], ["84247.90", "0"], ["84245.50", "5.327849"], ["84240.00", "0.002000"], ["84239.40", "0"], ["84237.00", "5.147244"], ["84230.90", "0"], ["84228.50", "5.237546"], ["84222.40", "0"], ["84220.00", "5.056941"], ["84213.90", "0"], ["84211.50", "4.153916"], ["84205.40", "0"], ["84203.00", "4.334521"], ["84196.90", "0"], ["84194.50", "4.876336"], ["84188.40", "0"], ["84186.00", "4.515126"], ["84179.90", "0"], ["84177.50", "3.973311"], ["84171.40", "0"], ["84169.00", "4.063614"], ["84162.90", "0"], ["84160.50", "4.695731"], ["84154.40", "0"], ["84152.00", "4.424824"], ["84145.90", "0"], ["84143.50", "4.966639"], ["84137.40", "0.000118"], ["84135.00", "3.883009"], ["84128.90", "0"], ["84126.50", "5.418151"], ["84120.40", "0"], ["83895.00", "0.006121"], ["83894.74", "0.000068"], ["83894.17", "0.000022"], ["83893.81", "0.000010"], ["83893.64", "0.000039"], ["83893.62", "0.000137"], ["83892.29", "0.000143"]], "checksum": 1943561473, "ts": "1742142246397"}], "ts": 1742142246401, "record_time": 1742142245.509746}
{"action": "update", "arg": {"instType": "SPOT", "channel": "books", "instId": "BTCUSDT"}, "data": [{"asks": [["84346.63", "0"], ["84346.64", "0"], ["84346.65", "0"], ["84346.66", "0"], ["84360.00", "0"], ["84363.59", "0.584312"], ["84363.60", "0.009639"], ["84364.79", "0.009191"], ["84364.80", "0.022424"], ["84366.76", "0"], ["84371.94", "0"], ["84383.63", "0"], ["84402.70", "0.001040"], ["84404.70", "0.001025"], ["84406.70", "0.001049"], ["84408.70", "0.002398"], ["84410.70", "0.006312"], ["84412.70", "0.016610"], ["84414.70", "0.043710"], ["84414.80", "0.396390"], ["84415.40", "0.001710"], ["84415.90", "0.237690"], ["84419.00", "0.142680"], ["84421.20", "0.738210"], ["84421.30", "2.347080"], ["84423.80", "1.204770"], ["84423.90", "3.557520"], ["84425.30", "0.258030"], ["84426.00", "0.032790"], ["84426.50", "0"], ["84430.70", "0"], ["84456.90", "4.424824"], ["84465.40", "4.695731"], ["84473.90", "4.786034"], ["84482.40", "5.147244"], ["84490.90", "3.883009"], ["84499.40", "4.244219"], ["84507.90", "3.973311"], ["84516.40", "4.876336"], ["84541.90", "5.418151"], ["84550.40", "4.515126"], ["84558.90", "5.598756"], ["84567.40", "4.063614"], ["84575.90", "5.237546"], ["84584.40", "5.508454"], ["84592.90", "4.605429"], ["84609.90", "4.153916"], ["84618.40", "4.334521"], ["84871.79", "0.000014"], ["84873.84", "0.000057"], ["84874.79", "0.000096"], ["84875.00", "0.000959"], ["84875.78", "0.000038"]], "bids": [["84363.58", "0.080618"], ["84357.53", "0.033994"], ["84356.32", "0.209200"], ["84352.12", "0.006929"], ["84352.10", "0.226350"], ["84350.91", "0.005548"], ["84350.84", "0.223490"], ["84350.20", "0.001029"], ["84348.20", "0.001016"], ["84347.90", "0.047500"], ["84347.89", "0.008261"], ["84346.63", "1.350363"], ["84346.62", "1.112678"], ["84346.61", "2.100998"], ["84346.22", "0"], ["84346.21", "0"], ["84346.20", "0.002329"], ["84344.20", "0.006129"], ["84342.20", "0.016129"], ["84340.20", "0.042445"], ["84338.20", "0.111699"], ["84336.20", "0.293943"], ["84335.86", "0.000436"], ["84334.20", "0.773536"], ["84334.12", "0.007950"], ["84334.05", "0.017821"], ["84332.20", "2.035619"], ["84331.32", "0"], ["84331.31", "0"], ["84330.60", "0.008151"], ["84330.20", "5.356893"], ["84327.60", "2.347170"], ["84326.00", "0.178140"], ["84325.80", "0.247680"], ["84325.50", "2.185110"], ["84325.00", "0.450210"], ["84324.20", "0.695790"], ["84324.10", "1.011660"], ["84319.20", "0.090000"], ["84319.00", "0.038520"], ["84315.80", "0"], ["84315.40", "0"], ["84288.00", "3.883009"], ["84279.50", "4.063614"], ["84262.50", "5.327849"], ["84254.00", "5.418151"], ["84245.50", "4.244219"], ["84237.00", "3.973311"], ["84228.50", "4.424824"], ["84220.00", "5.508454"], ["84211.50", "5.598756"], ["84203.00", "4.153916"], ["84186.00", "5.056941"], ["84177.50", "4.515126"], ["84169.00", "4.605429"], ["84168.00", "0"], ["84166.00", "0"], ["84160.50", "5.237546"], ["84152.00", "5.147244"], ["84143.50", "4.334521"], ["84135.00", "4.695731"], ["84126.50", "4.966639"], ["84068.26", "0"], ["83898.68", "0"], ["83896.11", "0"], ["83896.00", "0"], ["83895.65", "0"], ["83895.00", "0"], ["83894.74", "0"], ["83894.17", "0"], ["83893.81", "0"], ["83893.64", "0"], ["83893.62", "0"], ["83892.29", "0"]], "checksum": -789967342, "ts": "1742142246602"}], "ts": 1742142246608, "record_time": 1742142245.715948}
{"action": "update", "arg": {"instType": "SPOT", "channel": "books", "instId": "BTCUSDT"}, "data": [{"asks": [["84363.59", "0.523390"], ["84363.60", "0"], ["84363.61", "0"], ["84363.65", "0"], ["84363.71", "0"], ["84363.73", "0"], ["84364.14", "0"], ["84364.75", "0"], ["84364.78", "0"], ["84364.79", "0"], ["84364.80", "0"], ["84364.84", "0"], ["84364.86", "0"], ["84365.38", "0"], ["84365.54", "0.030015"], ["84368.23", "0"], ["84370.13", "0.000245"], ["84371.09", "0.004974"], ["84371.10", "0.008962"], ["84371.12", "0.001230"], ["84371.20", "0.001066"], ["84371.27", "0.008506"], ["84371.29", "0.017712"], ["84371.31", "0.005183"], ["84371.34", "0.004739"], ["84372.29", "0.007110"], ["84372.31", "0.007955"], ["84374.80", "0.080082"], ["84376.15", "0"], ["84376.54", "0"], ["84376.61", "0.002807"], ["84377.37", "0"], ["84378.54", "1.893058"], ["84378.65", "0"], ["84378.84", "0"], ["84379.30", "0"], ["84379.65", "0"], ["84380.33", "0"], ["84380.44", "0"], ["84380.55", "0"], ["84380.59", "0"], ["84380.83", "0"], ["84380.92", "0"], ["84381.20", "0"], ["84381.63", "0"], ["84381.93", "0"], ["84382.21", "0"], ["84382.24", "0"], ["84382.32", "0"], ["84382.51", "0"], ["84382.81", "0"], ["84383.03", "0.119869"], ["84383.04", "0.001205"], ["84383.68", "0"], ["84383.69", "0"], ["84384.25", "0.035952"], ["84384.56", "0"], ["84384.73", "0"], ["84385.16", "0.006356"], ["84385.35", "0.006356"], ["84385.44", "0"], ["84385.47", "0"], ["84385.79", "0.006356"], ["84386.53", "0.006356"], ["84386.60", "0"], ["84386.68", "0.006356"], ["84386.70", "0"], ["84387.01", "0.010985"], ["84387.12", "0.006356"], ["84387.21", "0.006356"], ["84387.27", "0.006356"], ["84387.31", "0.006356"], ["84387.32", "0.006356"], ["84387.72", "0.006356"], ["84388.20", "0"], ["84388.44", "0.016427"], ["84388.60", "0.006356"], ["84388.69", "0.006356"], ["84388.74", "0.006356"], ["84388.88", "0.006357"], ["84390.65", "0.006356"], ["84391.95", "0.119895"], ["84392.50", "0.119881"], ["84393.08", "0.119879"], ["84394.70", "0"], ["84395.42", "2.231032"], ["84396.38", "0.015891"], ["84396.70", "0"], ["84397.52", "0"], ["84398.70", "0"], ["84398.75", "0.010986"], ["84399.48", "0"], ["84400.04", "0.148098"], ["84400.70", "0"], ["84401.20", "0.001013"], ["84402.70", "0"], ["84403.20", "0.001010"], ["84404.70", "0"], ["84405.20", "0.001044"], ["84406.70", "0"], ["84407.20", "0.001005"], ["84408.70", "0"], ["84409.20", "0.001010"], ["84410.70", "0"], ["84411.20", "0.001012"], ["84412.70", "0"], ["84413.20", "0.001044"], ["84414.70", "0"], ["84414.80", "0"], ["84415.20", "0.001011"], ["84415.40", "0"], ["84415.90", "0"], ["84417.20", "0.001006"], ["84418.20", "0"], ["84419.00", "0"], ["84419.20", "0.001562"], ["84420.71", "0.001597"], ["84421.20", "0.004111"], ["84421.30", "0.001050"], ["84422.20", "0.079710"], ["84422.60", "0.001045"], ["84422.70", "0.003090"], ["84423.00", "0.045780"], ["84423.80", "1.204950"], ["84423.90", "0"], ["84425.20", "0.258030"], ["84425.30", "0"], ["84425.40", "0"], ["84426.00", "0"], ["84427.70", "0"], ["84429.80", "2.620620"], ["84430.50", "0.981300"], ["84430.70", "0.013830"], ["84431.80", "0.781320"], ["84432.00", "0.180000"], ["84432.70", "0.198000"], ["84432.80", "0.090000"], ["84433.00", "0.135000"], ["84433.90", "0.035520"], ["84434.10", "0.117000"], ["84434.20", "0.007050"], ["84434.80", "0.062940"], ["84435.40", "0.117000"], ["84456.90", "0"], ["84457.83", "0"], ["84463.40", "3.973005"], ["84465.40", "0"], ["84471.90", "3.882709"], ["84473.90", "0"], ["84480.40", "5.327438"], ["84482.40", "0"], ["84488.90", "5.056551"], ["84490.90", "0"], ["84497.40", "4.605073"], ["84499.40", "0"], ["84505.90", "4.063300"], ["84507.90", "0"], ["84514.40", "4.424482"], ["84516.40", "0"], ["84522.90", "5.146847"], ["84524.90", "0"], ["84531.40", "4.334187"], ["84533.40", "0"], ["84539.90", "4.785665"], ["84541.90", "0"], ["84548.40", "5.598325"], ["84550.40", "0"], ["84556.90", "5.237142"], ["84558.90", "0"], ["84565.40", "4.875960"], ["84567.40", "0"], ["84573.90", "4.695369"], ["84575.90", "0"], ["84582.40", "4.966256"], ["84584.40", "0"], ["84590.90", "5.417733"], ["84592.90", "0"], ["84599.40", "4.243891"], ["84601.40", "0"], ["84607.90", "4.153596"], ["84609.90", "0"], ["84616.40", "4.514778"], ["84618.40", "0"], ["84624.90", "5.508029"]], "bids": [["84363.58", "1.079318"], ["84359.64", "0.006929"], ["84359.59", "0.009564"], ["84358.14", "0.139845"], ["84357.54", "0.000164"], ["84357.42", "0.005548"], ["84356.80", "0.001006"], ["84356.33", "0.062760"], ["84355.37", "0.008261"], ["84354.80", "0.001337"], ["84353.83", "0.003004"], ["84352.80", "0.003519"], ["84352.12", "0"], ["84352.11", "0.136925"], ["84352.10", "0.209200"], ["84350.91", "0"], ["84350.84", "0"], ["84350.80", "0.009260"], ["84350.20", "0"], ["84348.80", "0.024368"], ["84348.20", "0"], ["84347.89", "0"], ["84346.80", "0.064126"], ["84346.63", "0.867963"], ["84346.62", "0.617687"], ["84346.61", "0.047780"], ["84346.20", "0"], ["84344.80", "0.168752"], ["84344.39", "0.001228"], ["84344.38", "0.008532"], ["84344.29", "0.000213"], ["84344.20", "0"], ["84343.41", "0.003017"], ["84343.01", "0.014417"], ["84342.80", "0.444086"], ["84342.53", "0.007345"], ["84342.43", "0.007436"], ["84342.40", "0.008986"], ["84342.35", "0.000436"], ["84342.31", "0.018997"], ["84342.25", "0.008139"], ["84342.20", "0"], ["84341.69", "0.247764"], ["84341.62", "0.007950"], ["84340.80", "1.168647"], ["84340.63", "0.007870"], ["84340.50", "0.002062"], ["84340.44", "0.017818"], ["84340.38", "0.084358"], ["84340.30", "0.018243"], ["84340.20", "0"], ["84340.13", "0.015756"], ["84340.06", "0.005932"], ["84339.94", "0.016445"], ["84339.57", "0.006558"], ["84339.09", "0.056300"], ["84338.96", "0.007112"], ["84338.89", "0.017062"], ["84338.80", "3.075386"], ["84338.20", "0"], ["84337.98", "0"], ["84337.90", "0"], ["84337.89", "0"], ["84337.82", "0.007925"], ["84337.71", "0"], ["84337.70", "0"], ["84337.44", "0.007309"], ["84337.19", "0.005548"], ["84337.18", "0.004933"], ["84337.01", "0.017045"], ["84336.98", "0.025060"], ["84336.95", "0.008157"], ["84336.91", "0"], ["84336.89", "0.017315"], ["84336.80", "8.093120"], ["84336.48", "0.008980"], ["84336.20", "0.001040"], ["84336.05", "0"], ["84335.96", "0"], ["84335.95", "0"], ["84335.94", "0"], ["84335.86", "0"], ["84335.85", "0.002947"], ["84335.83", "0"], ["84335.82", "0.012637"], ["84335.80", "0.071040"], ["84335.76", "0"], ["84335.28", "0.008667"], ["84335.10", "0.036390"], ["84335.05", "0.008275"], ["84334.82", "0"], ["84334.60", "0.143520"], ["84334.37", "0"], ["84334.20", "0"], ["84334.12", "0"], ["84334.09", "0"], ["84334.05", "0"], ["84333.94", "0"], ["84333.85", "0"], ["84333.80", "0.255090"], ["84333.58", "0"], ["84333.57", "0.271641"], ["84333.50", "0"], ["84333.01", "0"], ["84332.88", "0"], ["84332.68", "0.222519"], ["84332.59", "0"], ["84332.41", "0"], ["84332.20", "0"], ["84331.76", "0.263077"], ["84331.73", "0"], ["84330.72", "0"], ["84330.70", "0"], ["84330.66", "0"], ["84330.60", "0"], ["84330.56", "0"], ["84330.47", "0"], ["84330.45", "0"], ["84330.44", "0"], ["84330.42", "0"], ["84330.41", "0"], ["84330.40", "0.520890"], ["84330.30", "7.336740"], ["84330.20", "1.153830"], ["84329.80", "0"], ["84329.73", "0"], ["84328.99", "0"], ["84328.90", "0.015210"], ["84328.81", "0"], ["84328.61", "0"], ["84328.60", "0.035550"], ["84328.30", "0"], ["84328.20", "0.142500"], ["84327.88", "0.056585"], ["84327.60", "0"], ["84327.20", "0.073435"], ["84327.09", "0"], ["84326.20", "0"], ["84326.11", "0"], ["84326.00", "0.177960"], ["84325.80", "0.247320"], ["84325.50", "1.377660"], ["84325.43", "0.018018"], ["84325.00", "0"], ["84324.20", "0"], ["84324.10", "1.002600"], ["84319.90", "0.420000"], ["84318.92", "0"], ["84318.58", "0.008201"], ["84318.30", "0"], ["84317.40", "0"], ["84316.90", "0"], ["84315.90", "0"], ["84314.61", "0"], ["84314.59", "0"], ["84313.67", "0.007576"], ["84313.63", "0.007181"], ["84312.42", "0"], ["84312.18", "0"], ["84308.12", "0.001188"], ["84307.30", "0"], ["84307.18", "0"], ["84294.60", "4.605073"], ["84288.00", "0"], ["84286.87", "0"], ["84286.10", "4.334187"], ["84284.89", "0"], ["84279.50", "0"], ["84277.60", "4.063300"], ["84276.19", "0.057629"], ["84271.00", "0"], ["84270.00", "0.002000"], ["84269.10", "5.237142"], ["84262.50", "0"], ["84260.60", "5.417733"], ["84254.00", "0"], ["84252.10", "5.508029"], ["84245.50", "0"], ["84243.92", "0"], ["84243.60", "5.146847"], ["84237.00", "0"], ["84235.10", "4.424482"], ["84228.50", "0"], ["84226.60", "4.785665"], ["84220.00", "0"], ["84218.10", "4.514778"], ["84211.50", "0"], ["84209.60", "4.695369"], ["84203.00", "0"], ["84201.10", "4.875960"], ["84194.50", "0"], ["84192.60", "4.153596"], ["84186.00", "0"], ["84184.10", "5.598325"], ["84177.50", "0"], ["84175.60", "5.327438"], ["84169.99", "0"], ["84169.00", "0.012717"], ["84167.10", "3.973005"], ["84160.50", "0"], ["84158.60", "3.882709"], ["84152.00", "0"], ["84150.10", "4.966256"], ["84143.50", "0"], ["84141.60", "5.056551"], ["84135.00", "0"], ["84133.10", "4.243891"], ["84126.50", "0"], ["84106.44", "0"], ["83898.68", "0.000010"], ["83896.11", "0.000094"]], "checksum": -1042890126, "ts": "1742142246807"}], "ts": 1742142246815, "record_time": 1742142245.925574}
{"action": "update", "arg": {"instType": "SPOT", "channel": "books", "instId": "BTCUSDT"}, "data": [{"asks": [["84363.59", "0.223590"], ["84363.60", "0.000100"], ["84363.61", "0.000100"], ["84363.62", "0.000100"], ["84364.56", "0.063756"], ["84371.05", "0.000381"], ["84371.08", "0.009639"], ["84371.13", "0.006307"], ["84371.65", "0"], ["84372.24", "0.007627"], ["84374.69", "0.139814"], ["84378.53", "0.567917"], ["84380.47", "0.209200"], ["84381.46", "0"], ["84381.90", "0"], ["84383.60", "0"], ["84385.57", "0"], ["84386.34", "0"], ["84387.59", "0"], ["84389.72", "0"], ["84389.87", "0.119843"], ["84390.34", "0.016428"], ["84392.38", "0.010984"], ["84393.55", "0"], ["84394.01", "0.009989"], ["84394.67", "0.017779"], ["84395.26", "0.009989"], ["84396.03", "0.015892"], ["84396.16", "0.075400"], ["84398.16", "0.006356"], ["84401.20", "0"], ["84401.51", "0.001807"], ["84402.20", "0.001028"], ["84402.82", "0.010000"], ["84403.20", "0"], ["84404.20", "0.001036"], ["84405.20", "0"], ["84406.20", "0.001045"], ["84407.20", "0"], ["84408.20", "0.001030"], ["84409.20", "0"], ["84410.20", "0.002711"], ["84411.20", "0"], ["84412.20", "0.007134"], ["84413.20", "0"], ["84414.07", "0.031812"], ["84414.20", "0.018772"], ["84415.20", "0"], ["84416.20", "0.049401"], ["84417.20", "0"], ["84418.20", "0.130003"], ["84418.80", "0.001597"], ["84419.20", "0"], ["84420.20", "0.342112"], ["84421.20", "0"], ["84421.30", "0"], ["84422.20", "0.900296"], ["84422.30", "0.001007"], ["84422.70", "0.002880"], ["84423.00", "0.047250"], ["84423.80", "0"], ["84425.20", "0"], ["84425.40", "0.142680"], ["84426.70", "0"], ["84429.10", "0.667170"], ["84429.20", "0"], ["84429.80", "0"], ["84430.30", "2.346480"], ["84430.50", "0"], ["84431.80", "0.278610"], ["84432.00", "0"], ["84432.70", "0"], ["84432.80", "0"], ["84433.00", "0"], ["84433.50", "0.032790"], ["84433.90", "0"], ["84434.10", "0"], ["84434.70", "0.015210"], ["84434.80", "0"], ["84434.90", "0.279900"], ["84435.40", "0"], ["84435.50", "0.006360"], ["84436.50", "2.383050"], ["84436.60", "4.684410"], ["84437.80", "0.012660"], ["84438.00", "0.981300"], ["84438.20", "0.149550"], ["84449.20", "0.002935"], ["84457.72", "0"], ["84463.40", "0"], ["84464.40", "4.605019"], ["84471.90", "0"], ["84472.90", "4.875902"], ["84480.40", "0"], ["84481.40", "5.327375"], ["84487.71", "0.057629"], ["84488.90", "0"], ["84489.90", "4.243841"], ["84497.40", "0"], ["84498.40", "3.972958"], ["84500.90", "0.125238"], ["84505.90", "0"], ["84506.90", "4.695313"], ["84514.40", "0"], ["84515.40", "5.598258"], ["84518.62", "0.209200"], ["84522.90", "0"], ["84523.90", "5.507964"], ["84531.40", "0"], ["84532.40", "3.882663"], ["84539.90", "0"], ["84540.90", "4.785608"], ["84548.40", "0"], ["84549.40", "4.334135"], ["84556.90", "0"], ["84557.90", "4.966197"], ["84565.40", "0"], ["84566.40", "4.514724"], ["84573.90", "0"], ["84574.90", "4.153546"], ["84582.40", "0"], ["84583.40", "5.237080"], ["84590.90", "0"], ["84591.90", "5.417669"], ["84599.40", "0"], ["84600.40", "5.056491"], ["84607.90", "0"], ["84608.90", "4.424430"], ["84616.40", "0"], ["84617.40", "5.146786"], ["84624.90", "0"], ["84625.90", "4.063252"], ["84864.86", "0"], ["84864.99", "0"], ["84866.10", "0"], ["84866.40", "0"], ["84867.80", "0"], ["84868.42", "0"], ["84868.52", "0"], ["84868.65", "0"], ["84869.57", "0"], ["84871.66", "0"], ["84871.79", "0"], ["84873.84", "0"], ["84874.79", "0"], ["84875.00", "0"], ["84875.78", "0"]], "bids": [["84363.58", "2.968593"], ["84359.59", "0.017150"], ["84358.15", "0.041954"], ["84358.14", "0"], ["84357.80", "0.001043"], ["84357.54", "0"], ["84356.80", "0"], ["84355.80", "0.001005"], ["84354.80", "0"], ["84353.80", "0.002401"], ["84353.16", "0.313096"], ["84352.80", "0"], ["84352.11", "0"], ["84351.80", "0.006317"], ["84350.80", "0"], ["84349.80", "0.016625"], ["84349.31", "2.547369"], ["84348.80", "0"], ["84347.80", "0.043748"], ["84347.56", "0.003057"], ["84346.80", "0"], ["84346.63", "0.117103"], ["84346.62", "0.562581"], ["84345.80", "0.115127"], ["84344.80", "0"], ["84343.80", "0.302966"], ["84343.41", "0.009226"], ["84342.80", "0"], ["84341.80", "0.797278"], ["84341.55", "0.007469"], ["84340.80", "0"], ["84340.57", "0.028780"], ["84339.80", "2.098100"], ["84338.80", "0"], ["84338.41", "0.227455"], ["84338.12", "0.005083"], ["84338.11", "0.009627"], ["84338.07", "0.008151"], ["84337.80", "5.521317"], ["84337.70", "0.258750"], ["84337.54", "0.052058"], ["84337.49", "0.018502"], ["84336.80", "4.039500"], ["84336.28", "0"], ["84336.20", "0"], ["84336.06", "0.010227"], ["84335.80", "0"], ["84335.10", "0.035550"], ["84334.78", "0.075940"], ["84334.60", "0.196320"], ["84333.80", "0"], ["84333.67", "0.021088"], ["84332.53", "0.012427"], ["84332.13", "0"], ["84331.00", "0.035550"], ["84330.40", "1.448730"], ["84330.30", "1.365180"], ["84330.20", "0.017700"], ["84330.10", "0.916620"], ["84330.00", "0"], ["84329.90", "0.015120"], ["84329.70", "0.410370"], ["84329.30", "0.009000"], ["84329.05", "0"], ["84328.77", "0"], ["84328.60", "2.669430"], ["84326.50", "0.038520"], ["84326.34", "0"], ["84325.80", "0.069600"], ["84325.50", "2.035350"], ["84325.10", "0.213510"], ["84325.00", "0.090000"], ["84324.80", "0.382950"], ["84324.76", "0"], ["84324.70", "2.669430"], ["84324.10", "0.987180"], ["84324.09", "0"], ["84324.00", "0.090000"], ["84323.90", "0"], ["84323.30", "2.669430"], ["84322.70", "0.099000"], ["84322.40", "0"], ["84321.40", "2.747700"], ["84321.00", "0"], ["84320.40", "0"], ["84319.90", "0"], ["84319.80", "0"], ["84319.20", "0"], ["84319.00", "0"], ["84318.80", "0"], ["84318.50", "0"], ["84317.70", "0"], ["84317.60", "0"], ["84306.14", "0.001179"], ["84295.60", "5.417669"], ["84295.47", "0.002935"], ["84294.60", "0"], ["84287.10", "5.146786"], ["84286.10", "0"], ["84278.60", "4.424430"], ["84277.60", "0"], ["84270.10", "4.153546"], ["84269.10", "0"], ["84261.60", "4.605019"], ["84260.60", "0"], ["84253.10", "4.695313"], ["84252.10", "0"], ["84244.60", "3.972958"], ["84243.60", "0"], ["84236.10", "4.063252"], ["84235.10", "0"], ["84227.60", "4.514724"], ["84226.60", "0"], ["84219.10", "5.507964"], ["84218.10", "0"], ["84210.60", "4.785608"], ["84209.60", "0"], ["84202.10", "4.966197"], ["84201.10", "0"], ["84193.60", "5.237080"], ["84192.60", "0"], ["84185.10", "5.327375"], ["84184.10", "0"], ["84176.60", "5.598258"], ["84175.60", "0"], ["84168.10", "3.882663"], ["84167.10", "0"], ["84159.60", "4.243841"], ["84158.60", "0"], ["84152.17", "0.000860"], ["84151.10", "4.334135"], ["84150.10", "0"], ["84142.60", "5.056491"], ["84141.60", "0"], ["84134.10", "4.875902"], ["84133.10", "0"], ["83901.14", "0"], ["83900.60", "0"], ["83900.52", "0"], ["83900.00", "0"], ["83899.58", "0"], ["83898.68", "0"], ["83896.11", "0"]], "checksum": -1736543238, "ts": "1742142247011"}], "ts": 1742142247016, "record_time": 1742142246.126564}
{"action": "update", "arg": {"instType": "SPOT", "channel": "books", "instId": "BTCUSDT"}, "data": [{"asks": [["84380.46", "0.099082"], ["84392.06", "0.313096"], ["84410.20", "0.001007"], ["84412.20", "0.001026"], ["84414.20", "0.001002"], ["84416.20", "0.002505"], ["84418.20", "0.006594"], ["84420.20", "0.017352"], ["84422.20", "0.045663"], ["84422.30", "0.001440"], ["84422.70", "0.003090"], ["84423.00", "0.047280"], ["84425.40", "0"], ["84429.10", "0.059400"], ["84430.30", "0"], ["84433.70", "0.244380"], ["84434.90", "0.035520"], ["84436.30", "2.346300"], ["84449.20", "0"], ["84464.40", "4.966197"], ["84472.90", "3.882663"], ["84481.40", "4.424430"], ["84489.90", "5.327375"], ["84498.40", "4.514724"], ["84506.90", "4.605019"], ["84515.40", "4.334135"], ["84532.40", "4.153546"], ["84540.90", "4.243841"], ["84549.40", "3.972958"], ["84557.90", "4.695313"], ["84566.40", "5.146786"], ["84574.90", "5.237080"], ["84583.40", "5.598258"], ["84591.90", "5.056491"], ["84600.40", "4.875902"], ["84608.90", "4.063252"], ["84617.40", "5.417669"], ["84625.90", "4.785608"], ["84864.69", "0"]], "bids": [["84363.58", "3.177793"], ["84359.65", "0.007537"], ["84358.15", "0"], ["84355.80", "0.001192"], ["84353.80", "0.003138"], ["84351.80", "0.008257"], ["84349.80", "0.021729"], ["84348.01", "0.003066"], ["84347.90", "0.050533"], ["84347.80", "0.057181"], ["84345.80", "0.150478"], ["84343.80", "0.395994"], ["84341.80", "1.042090"], ["84339.80", "2.742342"], ["84337.80", "7.216688"], ["84337.70", "0.258540"], ["84336.80", "4.406280"], ["84335.20", "0.705900"], ["84334.60", "1.258770"], ["84331.30", "0.064110"], ["84330.40", "7.371000"], ["84330.10", "1.006620"], ["84329.10", "0.090000"], ["84328.40", "0.099000"], ["84328.20", "0.232500"], ["84325.90", "0.090000"], ["84324.10", "0.090000"], ["84324.00", "0"], ["84323.80", "0"], ["84323.30", "0"], ["84322.70", "0"], ["84321.80", "0"], ["84321.40", "0"], ["84295.47", "0"], ["84287.10", "4.334135"], ["84278.60", "4.243841"], ["84270.10", "4.966197"], ["84261.60", "4.875902"], ["84253.10", "4.424430"], ["84244.60", "4.695313"], ["84236.10", "4.785608"], ["84227.60", "5.507964"], ["84219.10", "4.063252"], ["84210.60", "5.237080"], ["84202.10", "4.153546"], ["84193.60", "5.327375"], ["84185.10", "5.146786"], ["84176.60", "4.514724"], ["84168.10", "5.598258"], ["84159.60", "4.605019"], ["84151.10", "3.972958"], ["84134.10", "3.882663"], ["83901.14", "0.000008"]], "checksum": 152851074, "ts": "1742142247211"}], "ts": 1742142247219, "record_time": 1742142246.326754}
{"action": "update", "arg": {"instType": "SPOT", "channel": "books", "instId": "BTCUSDT"}, "data": [{"asks": [["84380.47", "0"], ["84384.24", "0.033149"], ["84423.50", "0.349140"], ["84429.10", "0.224490"], ["84431.80", "0.198240"], ["84433.70", "0"], ["84434.70", "0"], ["84434.90", "0.028260"], ["84435.50", "0"], ["84436.30", "0"], ["84436.80", "0.015060"], ["84436.90", "0.244380"], ["84472.90", "5.237080"], ["84481.40", "5.146786"], ["84489.90", "4.424430"], ["84498.40", "5.417669"], ["84506.90", "4.695313"], ["84515.40", "4.063252"], ["84532.40", "4.605019"], ["84540.90", "3.882663"], ["84549.40", "4.785608"], ["84557.90", "3.972958"], ["84566.40", "4.334135"], ["84574.90", "5.056491"], ["84583.40", "4.153546"], ["84591.90", "5.327375"], ["84600.40", "4.514724"], ["84608.90", "4.875902"], ["84617.40", "4.243841"], ["84625.90", "5.598258"], ["84692.98", "0.000022"], ["84717.52", "1.730930"]], "bids": [["84363.58", "3.177723"], ["84362.00", "0.000121"], ["84361.00", "0.000121"], ["84360.00", "0.000121"], ["84359.00", "0.000121"], ["84358.00", "0.000121"], ["84357.00", "0.000121"], ["84356.00", "0.000121"], ["84355.00", "0.000121"], ["84354.00", "0.000121"], ["84353.17", "0.165685"], ["84353.00", "0.000121"], ["84352.00", "0.000121"], ["84351.00", "0.000121"], ["84350.00", "0.000121"], ["84349.00", "0.000121"], ["84348.00", "0.000121"], ["84347.80", "0.057078"], ["84347.00", "0.000121"], ["84345.80", "0.150207"], ["84345.00", "0.000121"], ["84344.00", "0.000121"], ["84343.80", "0.395050"], ["84342.00", "0.000121"], ["84341.80", "1.039605"], ["84339.80", "2.735804"], ["84337.80", "7.199483"], ["84337.70", "0.259350"], ["84330.40", "6.192840"], ["84330.20", "0"], ["84324.10", "0"], ["84323.41", "0"], ["84295.60", "4.875902"], ["84278.60", "3.882663"], ["84270.10", "5.146786"], ["84261.60", "5.598258"], ["84258.82", "0"], ["84253.10", "4.153546"], ["84244.60", "4.514724"], ["84227.60", "5.327375"], ["84219.10", "3.972958"], ["84210.60", "4.243841"], ["84202.10", "5.507964"], ["84193.60", "5.056491"], ["84185.10", "4.605019"], ["84176.60", "5.237080"], ["84169.00", "0.012838"], ["84168.10", "4.966197"], ["84164.00", "0.000159"], ["84159.60", "5.417669"], ["84151.10", "4.424430"], ["84142.60", "4.695313"], ["84134.10", "4.063252"], ["84042.47", "1.587069"], ["84018.13", "0"], ["83909.15", "0"], ["83909.09", "0"], ["83909.08", "0"], ["83908.59", "0"], ["83908.26", "0"], ["83908.04", "0"], ["83907.22", "0"], ["83906.25", "0"], ["83905.95", "0"], ["83904.85", "0"], ["83904.78", "0"], ["83904.35", "0"], ["83904.34", "0"], ["83903.51", "0"], ["83902.23", "0"], ["83901.67", "0"], ["83901.14", "0"]], "checksum": 1567954421, "ts": "1742142247415"}], "ts": 1742142247422, "record_time": 1742142246.529385}
{"action": "update", "arg": {"instType": "SPOT", "channel": "books", "instId": "BTCUSDT"}, "data": [{"asks": [["84364.53", "0.063756"], ["84364.56", "0"], ["84365.54", "0"], ["84371.50", "0"], ["84378.54", "0"], ["84380.46", "0.036322"], ["84395.42", "0"], ["84409.50", "0"], ["84422.20", "0.045496"], ["84429.10", "0.057780"], ["84434.90", "0"], ["84438.50", "0.291660"], ["84439.80", "0.197885"], ["84464.40", "3.882663"], ["84472.90", "5.417669"], ["84481.40", "4.966197"], ["84489.90", "4.514724"], ["84498.40", "5.146786"], ["84506.90", "5.327375"], ["84515.40", "3.972958"], ["84523.90", "4.875902"], ["84532.40", "4.334135"], ["84540.90", "4.243841"], ["84549.40", "4.063252"], ["84557.90", "4.695313"], ["84566.40", "5.237080"], ["84574.90", "5.507964"], ["84583.40", "4.605019"], ["84591.90", "5.056491"], ["84600.40", "4.153546"], ["84608.90", "4.424430"], ["84617.40", "5.598258"], ["84625.90", "4.785608"], ["84864.69", "0.000052"], ["84864.86", "0.000041"], ["84864.99", "0.000033"], ["84866.10", "0.000064"]], "bids": [["84363.58", "3.177793"], ["84349.32", "1.061777"], ["84346.63", "0"], ["84345.80", "0.150348"], ["84343.80", "0.395652"], ["84341.80", "1.041190"], ["84339.80", "2.739974"], ["84337.80", "7.210457"], ["84337.70", "0.284910"], ["84336.80", "4.406910"], ["84336.70", "0.690810"], ["84335.20", "0"], ["84334.60", "0.196320"], ["84330.10", "0.090000"], ["84329.20", "0.178290"], ["84324.10", "0.090000"], ["84299.60", "0"], ["84295.60", "5.417669"], ["84287.10", "5.327375"], ["84278.60", "4.243841"], ["84270.10", "5.507964"], ["84261.60", "3.972958"], ["84244.60", "5.056491"], ["84236.10", "4.605019"], ["84227.60", "5.598258"], ["84219.10", "4.424430"], ["84210.60", "4.063252"], ["84202.10", "4.785608"], ["84193.60", "4.334135"], ["84185.10", "4.966197"], ["84176.60", "3.882663"], ["84168.10", "5.146786"], ["84159.60", "4.695313"], ["84151.10", "4.875902"], ["84142.60", "5.237080"], ["84134.10", "4.514724"]], "checksum": -2120068687, "ts": "1742142247615"}], "ts": 1742142247619, "record_time": 1742142246.727048}
{"action": "update", "arg": {"instType": "SPOT", "channel": "books", "instId": "BTCUSDT"}, "data": [{"asks": [["84364.53", "0"], ["84374.69", "0"], ["84374.80", "0"], ["84378.53", "0"], ["84380.00", "0.080082"], ["84380.46", "0"], ["84383.03", "0"], ["84383.04", "0"], ["84384.25", "0"], ["84385.79", "0"], ["84387.01", "0"], ["84387.31", "0"], ["84387.71", "0.014257"], ["84388.45", "0.119869"], ["84388.73", "0.047318"], ["84388.82", "0.001205"], ["84389.65", "0.035952"], ["84391.39", "0.006356"], ["84392.54", "0.010985"], ["84392.88", "0.006356"], ["84402.20", "0"], ["84404.20", "0"], ["84404.60", "0.001044"], ["84406.20", "0"], ["84406.60", "0.001011"], ["84408.20", "0"], ["84408.60", "0.001040"], ["84410.20", "0"], ["84410.60", "0.001002"], ["84412.20", "0"], ["84412.60", "0.001039"], ["84414.20", "0"], ["84414.60", "0.002805"], ["84416.20", "0"], ["84416.60", "0.007381"], ["84418.20", "0"], ["84418.60", "0.019423"], ["84420.20", "0"], ["84420.60", "0.051114"], ["84422.20", "0"], ["84422.30", "0"], ["84422.60", "0.134511"], ["84422.70", "0"], ["84423.00", "0"], ["84423.50", "0"], ["84424.60", "0.354125"], ["84424.70", "0.001037"], ["84425.20", "0.003840"], ["84426.20", "0.007260"], ["84426.90", "0.001043"], ["84429.10", "0"], ["84431.80", "0"], ["84433.50", "0"], ["84435.80", "0.032790"], ["84436.50", "0.490260"], ["84436.60", "1.127370"], ["84436.70", "0.027240"], ["84436.80", "0"], ["84436.90", "0"], ["84438.00", "0"], ["84439.10", "0.009000"], ["84439.20", "0.015180"], ["84440.30", "0.464250"], ["84441.20", "2.896920"], ["84441.50", "0.244380"], ["84441.70", "0.382950"], ["84441.80", "3.557040"], ["84442.20", "0.145080"], ["84443.70", "0.009120"], ["84464.40", "0"], ["84466.80", "4.875767"], ["84472.90", "0"], ["84475.30", "5.598102"], ["84481.40", "0"], ["84483.80", "4.334015"], ["84489.90", "0"], ["84492.30", "5.507810"], ["84498.40", "0"], ["84500.80", "4.153431"], ["84506.90", "0"], ["84509.30", "5.146642"], ["84515.40", "0"], ["84517.80", "5.236934"], ["84523.90", "0"], ["84526.30", "4.785475"], ["84532.40", "0"], ["84534.80", "4.695183"], ["84540.90", "0"], ["84543.30", "4.966059"], ["84549.40", "0"], ["84551.80", "4.424307"], ["84557.90", "0"], ["84560.30", "3.882555"], ["84566.40", "0"], ["84568.80", "4.243723"], ["84574.90", "0"], ["84577.30", "4.514599"], ["84583.40", "0"], ["84585.80", "5.056350"], ["84591.90", "0"], ["84594.30", "3.972847"], ["84600.40", "0"], ["84602.80", "5.327226"], ["84608.90", "0"], ["84611.30", "5.417518"], ["84617.40", "0"], ["84619.80", "4.604891"], ["84625.90", "0"], ["84628.30", "4.063139"], ["84866.10", "0"]], "bids": [["84363.58", "3.531281"], ["84360.10", "0.001042"], ["84358.10", "0.001136"], ["84357.80", "0"], ["84356.10", "0.002990"], ["84355.80", "0"], ["84354.10", "0.007867"], ["84353.83", "0"], ["84353.80", "0"], ["84351.80", "0"], ["84350.10", "0.054481"], ["84349.80", "0"], ["84349.31", "0"], ["84348.10", "0.143370"], ["84347.80", "0"], ["84347.11", "0.247764"], ["84346.62", "0.209449"], ["84346.61", "0.047424"], ["84346.10", "0.377289"], ["84346.00", "0.197997"], ["84345.80", "0"], ["84345.77", "0.084358"], ["84345.66", "0.005932"], ["84344.62", "0.056300"], ["84344.45", "0.017062"], ["84344.10", "0.992867"], ["84343.81", "0.192539"], ["84343.80", "0"], ["84342.10", "2.612806"], ["84341.80", "0"], ["84341.69", "0"], ["84341.06", "0.002947"], ["84340.38", "0"], ["84340.10", "6.875806"], ["84340.06", "0"], ["84339.80", "0.071040"], ["84339.10", "6.920790"], ["84339.09", "0"], ["84338.89", "0"], ["84338.50", "0.444030"], ["84338.40", "0.035550"], ["84337.80", "0"], ["84337.70", "1.708830"], ["84336.80", "0"], ["84336.70", "1.403220"], ["84335.85", "0"], ["84335.10", "0"], ["84334.80", "0.410370"], ["84334.60", "0.345720"], ["84333.50", "0.025350"], ["84333.40", "0.035550"], ["84332.70", "0.193680"], ["84331.80", "0.015180"], ["84331.30", "0"], ["84331.20", "0.063930"], ["84331.00", "0"], ["84330.40", "6.264510"], ["84330.30", "1.350000"], ["84330.12", "0"], ["84329.90", "0"], ["84329.80", "0.015120"], ["84329.70", "0"], ["84329.60", "0.410370"], ["84329.20", "0"], ["84329.10", "0.268290"], ["84328.90", "0.038520"], ["84328.70", "0.180000"], ["84328.60", "0"], ["84328.50", "2.669430"], ["84328.20", "0.142500"], ["84328.10", "0.090000"], ["84327.40", "0.035550"], ["84326.50", "0"], ["84326.40", "0.269760"], ["84325.90", "0"], ["84325.80", "0.159600"], ["84325.50", "0"], ["84325.10", "0"], ["84325.00", "0"], ["84324.80", "0"], ["84324.70", "0"], ["84324.10", "0"], ["84316.40", "0.207047"], ["84297.90", "4.514599"], ["84295.60", "0"], ["84289.40", "4.966059"], ["84287.10", "0"], ["84280.90", "4.063139"], ["84278.60", "0"], ["84272.40", "4.153431"], ["84270.10", "0"], ["84263.90", "5.236934"], ["84261.60", "0"], ["84255.40", "4.875767"], ["84253.10", "0"], ["84246.90", "5.327226"], ["84244.60", "0"], ["84238.40", "4.785475"], ["84236.10", "0"], ["84229.90", "4.334015"], ["84227.60", "0"], ["84221.40", "5.598102"], ["84219.10", "0"], ["84212.90", "4.695183"], ["84210.60", "0"], ["84204.40", "5.056350"], ["84202.10", "0"], ["84195.90", "5.507810"], ["84193.60", "0"], ["84187.40", "4.243723"], ["84185.10", "0"], ["84178.90", "3.972847"], ["84176.60", "0"], ["84170.40", "5.146642"], ["84168.10", "0"], ["84161.90", "4.424307"], ["84159.60", "0"], ["84154.51", "0.000860"], ["84153.40", "4.604891"], ["84151.10", "0"], ["84144.90", "5.417518"], ["84142.60", "0"], ["84136.40", "3.882555"], ["84134.10", "0"], ["84107.01", "0"], ["83909.15", "0.000093"]], "checksum": -1619996257, "ts": "1742142247818"}], "ts": 1742142247822, "record_time": 1742142246.931064}
{"action": "update", "arg": {"instType": "SPOT", "channel": "books", "instId": "BTCUSDT"}, "data": [{"asks": [["84363.59", "0"], ["84363.60", "0"], ["84363.61", "0"], ["84363.62", "0"], ["84370.13", "0"], ["84371.05", "0"], ["84371.08", "0"], ["84371.09", "0"], ["84371.10", "0"], ["84371.12", "0"], ["84371.13", "0"], ["84371.20", "0"], ["84371.27", "0"], ["84371.29", "0"], ["84371.31", "0"], ["84371.34", "0"], ["84372.24", "0"], ["84372.29", "0"], ["84372.31", "0"], ["84376.61", "0"], ["84380.00", "0.079992"], ["84384.24", "0"], ["84385.16", "0"], ["84385.35", "0"], ["84386.53", "0"], ["84386.68", "0"], ["84387.12", "0"], ["84387.21", "0"], ["84387.27", "0"], ["84387.32", "0"], ["84387.72", "0"], ["84388.44", "0"], ["84388.60", "0"], ["84388.69", "0"], ["84388.74", "0"], ["84388.88", "0"], ["84390.34", "0"], ["84390.65", "0"], ["84391.03", "0.006356"], ["84391.30", "0.006356"], ["84391.95", "0"], ["84392.12", "0"], ["84392.50", "0"], ["84392.53", "0.006356"], ["84392.71", "0.006356"], ["84392.74", "0.006356"], ["84393.01", "0.006356"], ["84393.08", "0"], ["84393.13", "0.006356"], ["84393.19", "0.006356"], ["84393.72", "0.006356"], ["84394.58", "0.006356"], ["84394.67", "0"], ["84394.68", "0.006356"], ["84394.71", "0.006356"], ["84394.80", "0.006357"], ["84396.38", "0"], ["84396.73", "0.006356"], ["84398.75", "0"], ["84401.51", "0"], ["84402.20", "0.119895"], ["84403.09", "0.119879"], ["84404.60", "0"], ["84406.40", "0.001807"], ["84406.60", "0"], ["84408.60", "0"], ["84408.85", "0.010986"], ["84409.20", "0.001035"], ["84410.60", "0"], ["84411.20", "0.001023"], ["84412.60", "0"], ["84413.20", "0.001031"], ["84414.07", "0"], ["84414.60", "0"], ["84415.20", "0.001034"], ["84416.60", "0"], ["84417.20", "0.001044"], ["84418.60", "0"], ["84419.20", "0.001048"], ["84420.60", "0"], ["84421.20", "0.001040"], ["84422.60", "0"], ["84423.20", "0.001038"], ["84424.60", "0"], ["84424.70", "0"], ["84425.20", "0.001034"], ["84426.20", "0"], ["84426.90", "0"], ["84427.20", "0.001011"], ["84429.20", "0.001916"], ["84430.50", "0.001020"], ["84430.70", "0.014040"], ["84430.80", "0.001029"], ["84431.30", "0.001049"], ["84431.80", "0.001014"], ["84432.60", "0.001022"], ["84433.70", "0.297420"], ["84436.50", "0.431040"], ["84437.80", "0"], ["84438.20", "0.007050"], ["84441.70", "0"], ["84444.30", "3.694380"], ["84444.60", "0.142500"], ["84445.20", "1.986840"], ["84445.40", "0.065190"], ["84466.80", "0"], ["84471.40", "5.597800"], ["84475.30", "0"], ["84479.90", "5.326939"], ["84483.80", "0"], ["84488.40", "3.972632"], ["84492.30", "0"], ["84496.90", "4.875503"], ["84500.80", "0"], ["84505.40", "4.694929"], ["84509.30", "0"], ["84513.90", "4.424068"], ["84517.80", "0"], ["84522.40", "4.062919"], ["84526.30", "0"], ["84530.90", "4.604642"], ["84534.80", "0"], ["84539.40", "5.146364"], ["84543.30", "0"], ["84547.90", "5.507513"], ["84551.80", "0"], ["84556.40", "4.965790"], ["84560.30", "0"], ["84564.90", "5.056077"], ["84568.80", "0"], ["84573.40", "5.236651"], ["84577.30", "0"], ["84581.90", "5.417226"], ["84585.80", "0"], ["84590.40", "4.785216"], ["84594.30", "0"], ["84598.90", "3.882345"], ["84602.80", "0"], ["84607.40", "4.514355"], ["84611.30", "0"], ["84615.90", "4.333781"], ["84619.80", "0"], ["84624.40", "4.153206"], ["84628.30", "0"], ["84632.90", "4.243493"], ["84866.10", "0.000064"], ["84866.40", "0.000018"], ["84867.80", "0.000095"], ["84868.42", "0.000031"], ["84868.52", "0.000013"], ["84868.65", "0.000035"], ["84869.57", "0.000932"], ["84871.66", "0.000078"], ["84871.79", "0.000014"], ["84873.84", "0.000057"], ["84874.79", "0.000096"], ["84875.00", "0.000959"], ["84875.78", "0.000038"], ["84876.03", "0.000161"], ["84879.10", "0.000009"], ["84879.37", "0.000009"], ["84879.59", "0.000173"], ["84880.00", "0.025078"], ["84880.89", "0.000065"], ["84882.35", "0.000417"], ["84883.65", "0.000008"], ["84883.72", "0.000010"], ["84883.84", "0.000040"], ["84885.24", "0.000112"]], "bids": [["84363.58", "3.307256"], ["84362.70", "0.001031"], ["84360.70", "0.001017"], ["84360.10", "0"], ["84359.96", "0.003003"], ["84359.64", "0"], ["84359.59", "0"], ["84358.70", "0.001277"], ["84358.10", "0"], ["84357.42", "0"], ["84356.70", "0.003359"], ["84356.10", "0"], ["84355.37", "0"], ["84354.70", "0.008840"], ["84354.10", "0"], ["84353.16", "0.313309"], ["84352.70", "0.023264"], ["84350.70", "0.061221"], ["84350.10", "0"], ["84349.32", "0"], ["84348.70", "0.161108"], ["84348.10", "0"], ["84348.01", "0"], ["84347.90", "0.047500"], ["84347.56", "0"], ["84346.70", "0.423967"], ["84346.62", "0"], ["84346.61", "0.011856"], ["84346.32", "0.017818"], ["84346.25", "0.018243"], ["84346.12", "0.015756"], ["84346.10", "0"], ["84346.00", "0.214442"], ["84344.95", "0.013670"], ["84344.70", "1.115702"], ["84344.39", "0"], ["84344.38", "0"], ["84344.29", "0"], ["84344.10", "0"], ["84343.89", "0.007925"], ["84343.62", "0.271641"], ["84343.41", "0"], ["84343.36", "0.007309"], ["84343.20", "0.462900"], ["84342.91", "0.008157"], ["84342.89", "0.017045"], ["84342.78", "0.017315"], ["84342.68", "0.222519"], ["84342.53", "0"], ["84342.43", "0"], ["84342.40", "0.538814"], ["84342.35", "0"], ["84342.31", "0"], ["84342.25", "0"], ["84342.10", "0"], ["84341.89", "0.012637"], ["84341.70", "0.848490"], ["84341.62", "0"], ["84341.55", "0"], ["84341.06", "0"], ["84340.97", "0.008275"], ["84340.70", "7.270410"], ["84340.63", "0"], ["84340.57", "0"], ["84340.50", "0"], ["84340.44", "0"], ["84340.30", "0"], ["84340.20", "0.706620"], ["84340.13", "0"], ["84340.10", "16.468440"], ["84339.94", "0"], ["84339.80", "0.070200"], ["84339.57", "0"], ["84339.10", "3.697020"], ["84338.96", "0"], ["84338.50", "0.444210"], ["84338.12", "0"], ["84338.11", "0"], ["84338.07", "0"], ["84337.98", "0.056585"], ["84337.82", "0"], ["84337.70", "0.017700"], ["84337.44", "0"], ["84337.19", "0"], ["84337.18", "0"], ["84337.01", "0"], ["84336.98", "0"], ["84336.95", "0"], ["84336.89", "0"], ["84336.48", "0"], ["84336.06", "0"], ["84335.82", "0"], ["84335.28", "0"], ["84335.05", "0"], ["84334.74", "0.023717"], ["84333.57", "0"], ["84332.68", "0"], ["84331.76", "0"], ["84331.70", "0.023916"], ["84328.40", "0"], ["84328.20", "0"], ["84328.10", "0"], ["84327.88", "0"], ["84327.40", "0"], ["84327.20", "0"], ["84326.40", "0"], ["84326.00", "0.017777"], ["84325.80", "0"], ["84318.58", "0"], ["84318.21", "0"], ["84314.88", "0"], ["84313.67", "0"], ["84313.63", "0"], ["84313.26", "0"], ["84302.50", "4.062919"], ["84297.90", "0"], ["84294.00", "3.972632"], ["84289.40", "0"], ["84285.50", "4.333781"], ["84280.90", "0"], ["84277.00", "5.146364"], ["84272.40", "0"], ["84268.50", "4.875503"], ["84263.90", "0"], ["84260.00", "5.507513"], ["84255.40", "0"], ["84251.50", "4.243493"], ["84246.90", "0"], ["84243.00", "5.326939"], ["84238.40", "0"], ["84234.50", "4.604642"], ["84229.90", "0"], ["84226.00", "4.785216"], ["84221.40", "0"], ["84217.50", "4.424068"], ["84212.90", "0"], ["84209.00", "5.056077"], ["84204.40", "0"], ["84200.50", "5.236651"], ["84195.90", "0"], ["84192.00", "5.417226"], ["84187.40", "0"], ["84183.50", "5.597800"], ["84178.90", "0"], ["84175.00", "4.694929"], ["84170.40", "0"], ["84166.50", "4.153206"], ["84161.90", "0"], ["84158.00", "4.965790"], ["84153.40", "0"], ["84149.50", "3.882345"], ["84144.90", "0"], ["84141.00", "4.514355"], ["84136.40", "0"], ["83909.09", "0.000018"], ["83909.08", "0.000065"], ["83908.59", "0.000066"], ["83908.26", "0.000072"], ["83908.04", "0.000315"], ["83907.22", "0.000012"], ["83906.25", "0.000014"], ["83905.95", "0.000011"], ["83904.85", "0.000009"], ["83904.78", "0.000054"], ["83904.35", "0.000042"], ["83904.34", "0.000131"], ["83903.51", "0.000022"], ["83902.23", "0.000096"], ["83901.67", "0.000019"], ["83901.14", "0.000008"], ["83900.60", "0.000013"], ["83900.52", "0.000235"], ["83900.00", "0.002977"], ["83899.58", "0.000010"], ["83898.68", "0.000010"], ["83896.11", "0.000094"], ["83896.00", "0.000133"], ["83895.65", "0.000013"], ["83895.00", "0.006121"], ["83894.74", "0.000068"], ["83894.17", "0.000022"], ["83893.81", "0.000010"], ["83893.64", "0.000039"], ["83893.62", "0.000137"], ["83892.29", "0.000143"], ["83891.43", "0.000455"], ["83891.30", "0.000010"], ["83888.89", "0.000163"], ["83888.86", "0.000371"], ["83887.29", "0.000586"], ["83887.11", "0.000075"], ["83886.91", "0.000145"], ["83885.98", "0.000018"], ["83885.71", "0.000069"]], "checksum": -497141683, "ts": "1742142248019"}], "ts": 1742142248025, "record_time": 1742142247.133655}
{"action": "update", "arg": {"instType": "SPOT", "channel": "books", "instId": "BTCUSDT"}, "data": [{"asks": [["84372.37", "0.053802"], ["84374.76", "0.030015"], ["84378.94", "0.000381"], ["84378.95", "0.009639"], ["84379.00", "0.004974"], ["84379.01", "0.008962"], ["84379.05", "0.001475"], ["84379.99", "0.101439"], ["84380.00", "0"], ["84380.13", "0.007627"], ["84380.20", "0.008506"], ["84380.21", "0.007110"], ["84380.22", "0.016550"], ["84380.23", "0.001162"], ["84380.24", "0.013138"], ["84380.28", "0.004739"], ["84380.29", "0.139808"], ["84385.27", "0.079902"], ["84387.00", "0.002807"], ["84387.77", "1.892732"], ["84388.44", "0.089497"], ["84388.45", "0"], ["84388.73", "0"], ["84388.82", "0"], ["84389.65", "0"], ["84389.87", "0"], ["84392.38", "0"], ["84392.54", "0"], ["84393.77", "0.119869"], ["84394.01", "0"], ["84394.14", "0.001205"], ["84394.72", "0.035952"], ["84395.26", "0"], ["84396.03", "0"], ["84396.88", "0.209200"], ["84397.48", "0.010985"], ["84397.93", "0.119843"], ["84398.16", "0"], ["84398.54", "0.016428"], ["84398.92", "0.016427"], ["84400.55", "0.010984"], ["84402.23", "0.009989"], ["84402.82", "0"], ["84402.97", "0.119881"], ["84403.63", "0.009989"], ["84404.00", "0.015892"], ["84404.64", "2.231358"], ["84406.14", "0.006356"], ["84406.74", "0.015891"], ["84407.47", "0.017777"], ["84409.20", "0"], ["84410.20", "0.001046"], ["84411.20", "0"], ["84412.20", "0.001043"], ["84413.20", "0"], ["84414.20", "0.001040"], ["84415.20", "0"], ["84416.20", "0.001012"], ["84416.23", "0.012680"], ["84417.20", "0"], ["84418.20", "0.001009"], ["84419.20", "0"], ["84420.20", "0.001192"], ["84421.20", "0"], ["84422.20", "0.003135"], ["84423.20", "0"], ["84424.20", "0.008251"], ["84425.20", "0"], ["84426.20", "0.021847"], ["84427.20", "0"], ["84428.20", "0.057491"], ["84429.20", "0"], ["84429.42", "0.031812"], ["84430.20", "0.151292"], ["84430.30", "0.528990"], ["84430.70", "0.013830"], ["84430.80", "0.004020"], ["84431.80", "0"], ["84432.60", "0"], ["84433.70", "0"], ["84435.80", "0"], ["84436.50", "0.063390"], ["84436.60", "0"], ["84436.70", "0"], ["84439.20", "0"], ["84440.30", "0"], ["84441.20", "0.044670"], ["84441.40", "0.032790"], ["84441.50", "0"], ["84441.80", "0"], ["84443.70", "0"], ["84444.30", "0"], ["84444.60", "2.488590"], ["84445.20", "2.787870"], ["84445.30", "0.015090"], ["84445.40", "0"], ["84445.50", "0.244380"], ["84446.20", "0.007050"], ["84446.30", "0.981300"], ["84471.40", "0"], ["84472.40", "4.604582"], ["84479.90", "0"], ["84480.90", "4.243439"], ["84488.40", "0"], ["84489.40", "5.326870"], ["84496.90", "0"], ["84497.90", "4.875440"], ["84505.40", "0"], ["84506.40", "4.694868"], ["84513.90", "0"], ["84514.90", "5.146298"], ["84522.40", "0"], ["84523.40", "4.153153"], ["84527.06", "0.209200"], ["84530.90", "0"], ["84531.90", "3.882295"], ["84539.40", "0"], ["84540.40", "4.333725"], ["84547.90", "0"], ["84548.90", "5.417156"], ["84556.40", "0"], ["84557.40", "4.785154"], ["84564.90", "0"], ["84565.90", "4.424010"], ["84573.40", "0"], ["84574.40", "5.597727"], ["84581.90", "0"], ["84582.90", "3.972581"], ["84590.40", "0"], ["84591.40", "4.965726"], ["84598.90", "0"], ["84599.90", "4.062867"], ["84607.40", "0"], ["84608.40", "5.056012"], ["84615.90", "0"], ["84616.90", "4.514296"], ["84624.40", "0"], ["84625.40", "5.507442"], ["84632.90", "0"], ["84633.90", "5.236584"], ["84868.65", "0"], ["84869.57", "0"], ["84871.66", "0"], ["84871.79", "0"], ["84873.84", "0"], ["84874.79", "0"], ["84875.00", "0"], ["84875.78", "0"], ["84876.03", "0"], ["84879.10", "0"], ["84879.37", "0"], ["84879.59", "0"], ["84880.00", "0"], ["84880.89", "0"], ["84882.35", "0"], ["84883.65", "0"], ["84883.72", "0"], ["84883.84", "0"], ["84885.24", "0"]], "bids": [["84372.36", "2.449402"], ["84372.02", "0.092970"], ["84372.01", "0.209200"], ["84367.80", "0.223490"], ["84367.79", "0.209200"], ["84367.53", "0.006929"], ["84367.52", "0.009564"], ["84367.48", "0.007586"], ["84365.70", "0.001013"], ["84363.70", "0.001431"], ["84363.59", "0.032680"], ["84363.58", "0.525479"], ["84363.26", "0.008261"], ["84362.70", "0"], ["84361.70", "0.003894"], ["84360.71", "0.001698"], ["84360.70", "0"], ["84359.70", "0.010249"], ["84359.65", "0"], ["84358.70", "0"], ["84358.48", "2.547097"], ["84357.70", "0.026969"], ["84356.70", "0"], ["84356.30", "0.003033"], ["84355.88", "0.003057"], ["84355.70", "0.070971"], ["84354.70", "0"], ["84354.10", "0.003017"], ["84353.70", "0.186767"], ["84353.21", "0.008532"], ["84353.19", "0.001228"], ["84352.70", "0"], ["84352.43", "0.247740"], ["84352.10", "0"], ["84351.70", "0.491491"], ["84351.28", "0.006209"], ["84351.19", "0.000436"], ["84351.17", "0.021827"], ["84351.15", "0.006529"], ["84351.10", "0.008139"], ["84350.85", "0.084350"], ["84350.70", "0"], ["84350.06", "0.008549"], ["84349.70", "1.293399"], ["84349.56", "0.056295"], ["84349.42", "0.007469"], ["84349.34", "0.007870"], ["84349.19", "0.002062"], ["84348.76", "0.028780"], ["84348.70", "0"], ["84347.70", "3.403680"], ["84347.45", "0.025060"], ["84347.11", "0"], ["84346.70", "0"], ["84346.46", "0.227433"], ["84346.11", "0.002946"], ["84346.06", "0.010481"], ["84346.02", "0.005083"], ["84346.01", "0.009627"], ["84345.97", "0.008151"], ["84345.77", "0"], ["84345.71", "0.052053"], ["84345.70", "8.957053"], ["84345.00", "0.001032"], ["84344.70", "5.113290"], ["84344.62", "0"], ["84344.60", "0.001021"], ["84344.12", "0.008667"], ["84344.10", "0.035550"], ["84343.93", "0.010227"], ["84343.80", "0.069780"], ["84343.50", "0.916800"], ["84343.20", "0"], ["84342.74", "0.075933"], ["84342.40", "3.107490"], ["84342.22", "0.263077"], ["84342.04", "0.021086"], ["84341.80", "0.069780"], ["84341.70", "0.120180"], ["84341.00", "0.142680"], ["84340.70", "0.120180"], ["84340.50", "0.410550"], ["84340.20", "0"], ["84340.10", "3.428970"], ["84339.80", "0.069600"], ["84339.10", "1.350000"], ["84338.50", "0"], ["84338.41", "0"], ["84337.90", "0.015060"], ["84337.80", "0.133440"], ["84337.55", "0.073435"], ["84337.54", "0"], ["84337.50", "0.015060"], ["84337.49", "0"], ["84337.40", "0.015150"], ["84336.70", "0"], ["84335.20", "0.177960"], ["84334.80", "0"], ["84334.78", "0"], ["84334.50", "0.038520"], ["84333.67", "0"], ["84332.70", "0.178530"], ["84332.53", "0"], ["84331.80", "0"], ["84329.80", "0"], ["84329.30", "0"], ["84329.10", "0"], ["84328.90", "0"], ["84328.70", "0"], ["84328.50", "0"], ["84327.45", "0.008201"], ["84322.47", "0.007181"], ["84315.14", "0"], ["84303.50", "4.604582"], ["84302.50", "0"], ["84301.76", "0"], ["84295.00", "5.417156"], ["84294.00", "0"], ["84286.50", "5.146298"], ["84285.50", "0"], ["84278.00", "4.875440"], ["84277.00", "0"], ["84269.50", "4.965726"], ["84268.50", "0"], ["84261.00", "4.243439"], ["84260.00", "0"], ["84252.50", "5.507442"], ["84251.50", "0"], ["84244.00", "5.056012"], ["84243.00", "0"], ["84235.50", "4.694868"], ["84234.50", "0"], ["84227.00", "4.424010"], ["84226.00", "0"], ["84218.50", "5.326870"], ["84217.50", "0"], ["84210.00", "4.062867"], ["84209.00", "0"], ["84201.50", "4.785154"], ["84200.50", "0"], ["84193.00", "4.514296"], ["84192.00", "0"], ["84184.50", "4.333725"], ["84183.50", "0"], ["84176.00", "3.972581"], ["84175.00", "0"], ["84167.50", "4.153153"], ["84166.50", "0"], ["84165.00", "0"], ["84159.00", "5.597727"], ["84158.00", "0"], ["84150.50", "5.236584"], ["84149.50", "0"], ["84142.00", "3.882295"], ["84141.00", "0"], ["84076.70", "0"], ["83904.85", "0"], ["83904.78", "0"], ["83904.35", "0"], ["83904.34", "0"], ["83903.51", "0"], ["83902.23", "0"], ["83901.67", "0"], ["83901.14", "0"], ["83900.60", "0"], ["83900.52", "0"], ["83900.00", "0"], ["83899.58", "0"], ["83898.68", "0"], ["83896.11", "0"], ["83896.00", "0"], ["83895.65", "0"], ["83895.00", "0"], ["83894.74", "0"], ["83894.17", "0"], ["83893.81", "0"], ["83893.64", "0"], ["83893.62", "0"], ["83892.29", "0"], ["83891.43", "0"], ["83891.30", "0"], ["83888.89", "0"], ["83888.86", "0"], ["83887.29", "0"], ["83887.11", "0"], ["83886.91", "0"], ["83885.98", "0"], ["83885.71", "0"]], "checksum": 1851018297, "ts": "1742142248221"}], "ts": 1742142248224, "record_time": 1742142247.33294}
{"action": "update", "arg": {"instType": "SPOT", "channel": "books", "instId": "BTCUSDT"}, "data": [{"asks": [["84372.37", "0"], ["84374.76", "0"], ["84378.94", "0"], ["84378.95", "0"], ["84379.00", "0"], ["84379.01", "0"], ["84379.05", "0"], ["84379.99", "0"], ["84380.13", "0"], ["84380.20", "0"], ["84380.21", "0"], ["84380.22", "0"], ["84380.23", "0"], ["84380.24", "0"], ["84380.28", "0"], ["84380.29", "0"], ["84384.22", "0.009639"], ["84384.26", "0.001230"], ["84384.32", "0.001066"], ["84385.27", "0"], ["84385.43", "0.008506"], ["84385.45", "0.016550"], ["84385.47", "0.005183"], ["84385.51", "0.004739"], ["84387.17", "0.008962"], ["84387.21", "0.006552"], ["84387.71", "0"], ["84387.77", "0"], ["84388.35", "0.007627"], ["84388.40", "0.007110"], ["84388.42", "0.007955"], ["84388.44", "0"], ["84391.03", "0"], ["84391.30", "0"], ["84391.39", "0"], ["84391.87", "0.079992"], ["84392.06", "0"], ["84392.53", "0"], ["84392.71", "0"], ["84392.74", "0"], ["84392.88", "0"], ["84393.01", "0"], ["84393.13", "0"], ["84393.19", "0"], ["84393.72", "0"], ["84393.77", "0"], ["84394.14", "0"], ["84394.58", "0"], ["84394.68", "0"], ["84394.71", "0"], ["84394.72", "0"], ["84394.80", "0"], ["84396.16", "0"], ["84396.73", "0"], ["84396.87", "0.111865"], ["84396.88", "0"], ["84397.48", "0"], ["84397.93", "0"], ["84398.54", "0"], ["84398.92", "0"], ["84400.03", "0.166382"], ["84400.04", "0"], ["84400.13", "0.119869"], ["84400.65", "0.006356"], ["84400.66", "0.001205"], ["84400.95", "0.006356"], ["84401.32", "0.035952"], ["84401.86", "0.006356"], ["84402.00", "0.006356"], ["84402.05", "0.006356"], ["84402.20", "0"], ["84402.23", "0"], ["84402.24", "0.006356"], ["84402.48", "0.006356"], ["84402.97", "0"], ["84403.09", "0"], ["84403.56", "0.006356"], ["84403.62", "0.006357"], ["84403.63", "0"], ["84403.69", "0.006356"], ["84404.00", "0.006356"], ["84404.25", "0.010985"], ["84404.31", "0.006356"], ["84404.49", "0.006356"], ["84404.64", "0"], ["84405.46", "0.006356"], ["84405.87", "0.006356"], ["84406.14", "0"], ["84406.40", "0"], ["84406.74", "0"], ["84407.47", "0.006356"], ["84408.14", "0.075500"], ["84408.63", "0.119895"], ["84408.85", "0"], ["84410.20", "0"], ["84410.94", "0.148098"], ["84412.20", "0"], ["84414.01", "0.313096"], ["84414.20", "0"], ["84416.20", "0"], ["84416.23", "0"], ["84418.20", "0"], ["84418.50", "0.001049"], ["84418.80", "0"], ["84419.09", "0.001807"], ["84420.20", "0"], ["84420.50", "0.001015"], ["84420.71", "0"], ["84422.20", "0"], ["84422.50", "0.001026"], ["84423.64", "0.017774"], ["84424.20", "0"], ["84424.50", "0.001025"], ["84426.20", "0"], ["84426.50", "0.001033"], ["84428.20", "0"], ["84428.50", "0.001451"], ["84429.42", "0"], ["84430.20", "0"], ["84430.30", "0"], ["84430.50", "0.003819"], ["84430.70", "0"], ["84430.80", "0"], ["84431.30", "0"], ["84432.50", "0.010051"], ["84434.20", "0"], ["84434.50", "0.026450"], ["84435.89", "0.001597"], ["84436.50", "0.069606"], ["84438.20", "0"], ["84438.50", "0.183173"], ["84438.70", "0.003990"], ["84441.20", "0"], ["84441.40", "0.001470"], ["84442.20", "0.146340"], ["84444.60", "0"], ["84445.20", "0"], ["84445.30", "0"], ["84445.50", "0"], ["84446.30", "0"], ["84447.60", "0.009000"], ["84447.90", "0.244380"], ["84448.10", "0.013830"], ["84448.20", "0.021600"], ["84449.00", "1.285320"], ["84449.70", "0.464250"], ["84449.90", "0.009000"], ["84450.20", "0.010080"], ["84451.10", "0.025590"], ["84451.50", "0.020760"], ["84453.30", "2.906910"], ["84454.00", "0.009240"], ["84454.20", "0.007050"], ["84454.70", "0.009060"], ["84464.30", "0"], ["84472.40", "0"], ["84480.70", "4.423579"], ["84480.72", "0"], ["84480.90", "0"], ["84489.20", "4.152748"], ["84489.40", "0"], ["84497.70", "5.326350"], ["84497.90", "0"], ["84503.00", "0.304146"], ["84506.20", "3.881916"], ["84506.40", "0"], ["84507.94", "0.072042"], ["84514.70", "4.694410"], ["84514.90", "0"], ["84523.20", "4.333302"], ["84523.40", "0"], ["84531.70", "4.874965"], ["84531.90", "0"], ["84540.20", "4.784688"], ["84540.40", "0"], ["84548.70", "4.965242"], ["84548.90", "0"], ["84557.20", "5.145796"], ["84557.40", "0"], ["84565.70", "5.055519"], ["84565.90", "0"], ["84574.20", "5.416627"], ["84574.40", "0"], ["84582.70", "5.506904"], ["84582.90", "0"], ["84591.20", "5.236073"], ["84591.40", "0"], ["84599.70", "4.513856"], ["84599.90", "0"], ["84608.20", "3.972194"], ["84608.40", "0"], ["84616.70", "4.243025"], ["84616.90", "0"], ["84617.50", "0"], ["84625.20", "4.062471"], ["84625.40", "0"], ["84633.70", "4.604133"], ["84633.90", "0"], ["84642.20", "5.597182"], ["84722.40", "0.495362"], ["84868.65", "0.000035"], ["84869.57", "0.000932"], ["84871.66", "0.000078"], ["84871.79", "0.000014"], ["84873.84", "0.000057"], ["84874.79", "0.000096"], ["84875.00", "0.000959"], ["84875.78", "0.000038"], ["84876.03", "0.000161"], ["84879.10", "0.000009"], ["84879.37", "0.000009"], ["84879.59", "0.000173"], ["84880.00", "0.025078"], ["84880.89", "0.000065"], ["84882.35", "0.000417"], ["84883.65", "0.000008"], ["84883.72", "0.000010"], ["84883.84", "0.000040"], ["84885.24", "0.000112"], ["84885.53", "0.000022"], ["84886.01", "0.000023"]], "bids": [["84384.21", "0.035500"], ["84384.13", "0.209200"], ["84379.91", "0.209200"], ["84375.75", "0.006929"], ["84375.71", "1.133800"], ["84375.70", "0.017150"], ["84374.75", "0.223490"], ["84374.00", "0.001030"], ["84372.37", "0.255850"], ["84372.36", "0.163274"], ["84372.02", "0"], ["84372.00", "0.001390"], ["84371.54", "0.005548"], ["84371.48", "0.313096"], ["84370.00", "0.003657"], ["84368.53", "0.008261"], ["84368.00", "0.009625"], ["84367.80", "0"], ["84367.79", "0"], ["84367.53", "0"], ["84367.52", "0"], ["84367.48", "0"], ["84366.13", "0.195074"], ["84366.00", "0.025329"], ["84365.70", "0"], ["84364.00", "0.066654"], ["84363.70", "0"], ["84363.59", "0.160122"], ["84363.58", "0.365341"], ["84363.26", "0"], ["84362.00", "0.175407"], ["84361.70", "0"], ["84360.71", "0.768001"], ["84360.66", "0.003016"], ["84360.00", "0.461596"], ["84359.96", "0"], ["84359.70", "0"], ["84359.39", "0.006209"], ["84359.38", "0.008979"], ["84359.31", "0.008139"], ["84359.26", "0.006529"], ["84358.78", "0.247738"], ["84358.48", "0"], ["84358.45", "0.001228"], ["84358.36", "0.000213"], ["84358.00", "1.214728"], ["84357.70", "0"], ["84357.68", "0.007950"], ["84357.63", "0.007469"], ["84357.52", "0.017817"], ["84357.45", "0.084349"], ["84357.42", "0.018241"], ["84356.95", "0.016443"], ["84356.53", "0.007338"], ["84356.43", "0.007436"], ["84356.36", "0.000436"], ["84356.33", "0.135077"], ["84356.32", "0.265494"], ["84356.31", "0.008549"], ["84356.30", "0"], ["84356.24", "0.006558"], ["84356.00", "3.196651"], ["84355.88", "0"], ["84355.72", "0.007112"], ["84355.70", "0"], ["84354.92", "0.005931"], ["84354.62", "0.007870"], ["84354.55", "0.015754"], ["84354.53", "0.007308"], ["84354.21", "0.005548"], ["84354.17", "0.005083"], ["84354.10", "0"], ["84354.06", "0.017313"], ["84354.00", "8.412241"], ["84353.84", "0.197876"], ["84353.80", "0.212520"], ["84353.70", "0.001000"], ["84353.57", "0.017060"], ["84353.50", "0.405990"], ["84353.21", "0"], ["84353.19", "0"], ["84353.16", "0"], ["84352.82", "0.002946"], ["84352.63", "0.012635"], ["84352.43", "0"], ["84352.23", "0.008667"], ["84352.00", "0.021060"], ["84351.80", "0.069600"], ["84351.75", "0.008156"], ["84351.74", "0.017043"], ["84351.70", "0"], ["84351.28", "0"], ["84351.26", "0.008979"], ["84351.25", "0.004933"], ["84351.21", "0.009627"], ["84351.19", "0"], ["84351.17", "0.008151"], ["84351.15", "0"], ["84351.10", "0"], ["84351.00", "4.270920"], ["84350.85", "0"], ["84350.60", "1.508400"], ["84350.24", "0.271612"], ["84350.06", "0"], ["84349.80", "0.069600"], ["84349.79", "0.008274"], ["84349.70", "0"], ["84349.56", "0"], ["84349.42", "0"], ["84349.34", "0"], ["84349.19", "0"], ["84349.10", "0.254910"], ["84348.80", "1.350000"], ["84348.76", "0"], ["84348.60", "0.005640"], ["84348.20", "0.410370"], ["84347.80", "0.069600"], ["84347.70", "0"], ["84347.45", "0"], ["84347.40", "0.142500"], ["84346.61", "0"], ["84346.46", "0"], ["84346.32", "0"], ["84346.25", "0"], ["84346.12", "0"], ["84346.11", "0"], ["84346.06", "0"], ["84346.02", "0"], ["84346.01", "0"], ["84346.00", "0.000121"], ["84345.97", "0"], ["84345.80", "10.730820"], ["84345.70", "3.357760"], ["84345.66", "0"], ["84345.60", "0.015180"], ["84345.50", "0.450030"], ["84345.00", "0.000121"], ["84344.95", "0"], ["84344.70", "0"], ["84344.60", "0"], ["84344.45", "0"], ["84344.12", "0"], ["84344.10", "0"], ["84343.93", "0"], ["84343.89", "0"], ["84343.81", "0"], ["84343.80", "0.069600"], ["84343.70", "0.120000"], ["84343.62", "0"], ["84343.50", "0"], ["84343.36", "0"], ["84342.91", "0"], ["84342.89", "0"], ["84342.78", "0"], ["84342.74", "0"], ["84342.68", "0"], ["84342.40", "1.589730"], ["84342.22", "0"], ["84342.04", "0"], ["84342.00", "0.382920"], ["84341.89", "0"], ["84341.80", "0.069600"], ["84341.70", "0.120000"], ["84341.00", "0.142500"], ["84340.97", "0"], ["84340.80", "0.269760"], ["84340.70", "0.120000"], ["84340.50", "0"], ["84340.10", "0.123030"], ["84338.84", "0.017775"], ["84338.80", "0.084540"], ["84338.40", "0"], ["84338.24", "0.018018"], ["84337.98", "0"], ["84337.90", "0"], ["84337.80", "0"], ["84337.70", "0"], ["84337.55", "0"], ["84337.50", "0"], ["84337.40", "0"], ["84336.29", "0"], ["84335.20", "0"], ["84334.60", "0"], ["84334.50", "0"], ["84333.50", "0"], ["84333.40", "0"], ["84332.70", "0"], ["84332.64", "0.008201"], ["84331.20", "0"], ["84330.40", "0"], ["84330.30", "0"], ["84330.10", "0"], ["84329.60", "0"], ["84327.63", "0.007181"], ["84327.45", "0"], ["84326.00", "0"], ["84325.43", "0"], ["84325.40", "0.207047"], ["84325.18", "0.001188"], ["84322.47", "0"], ["84316.40", "0"], ["84311.80", "4.152748"], ["84308.12", "0"], ["84306.14", "0"], ["84303.50", "0"], ["84303.30", "5.506904"], ["84295.00", "0"], ["84294.80", "4.874965"], ["84294.50", "0.072042"], ["84286.50", "0"], ["84286.30", "5.416627"], ["84278.00", "0"], ["84277.80", "4.784688"], ["84269.50", "0"], ["84269.30", "4.423579"], ["84261.00", "0"], ["84260.80", "3.972194"], ["84252.50", "0"], ["84252.30", "5.326350"], ["84244.00", "0"], ["84243.80", "5.597182"], ["84235.50", "0"], ["84235.30", "4.243025"], ["84227.00", "0"], ["84226.80", "4.333302"], ["84218.50", "0"], ["84218.30", "4.513856"], ["84210.00", "0.002000"], ["84209.80", "4.965242"], ["84201.50", "0"], ["84201.30", "5.145796"], ["84193.00", "0"], ["84192.80", "4.604133"], ["84184.50", "0"], ["84184.30", "4.062471"], ["84176.00", "0.000165"], ["84175.80", "5.055519"], ["84167.50", "0"], ["84167.30", "5.236073"], ["84159.00", "0"], ["84158.80", "3.881916"], ["84150.50", "0"], ["84150.30", "4.694410"], ["84142.00", "0"], ["84085.14", "0"], ["83904.85", "0.000009"], ["83904.78", "0.000054"], ["83904.35", "0.000042"], ["83904.34", "0.000131"], ["83903.51", "0.000022"], ["83902.23", "0.000096"], ["83901.67", "0.000019"], ["83901.14", "0.000008"], ["83900.60", "0.000013"], ["83900.52", "0.000235"], ["83900.00", "0.002977"], ["83899.58", "0.000010"], ["83898.68", "0.000010"], ["83896.11", "0.000094"], ["83896.00", "0.000133"]], "checksum": -1501600645, "ts": "1742142248425"}], "ts": 1742142248448, "record_time": 1742142247.561062}
{"action": "update", "arg": {"instType": "SPOT", "channel": "books", "instId": "BTCUSDT"}, "data": [{"asks": [["84384.22", "0.296766"], ["84387.00", "0"], ["84387.14", "0.005355"], ["84388.40", "0.008272"], ["84391.87", "0"], ["84393.23", "0.139806"], ["84396.87", "0"], ["84398.54", "0.079992"], ["84400.03", "0"], ["84400.13", "0"], ["84400.55", "0.002807"], ["84400.65", "0"], ["84400.66", "0"], ["84400.95", "0"], ["84401.31", "0.014257"], ["84401.32", "0"], ["84401.86", "0"], ["84402.00", "0"], ["84402.05", "0"], ["84402.24", "0"], ["84402.48", "0"], ["84403.56", "0"], ["84403.62", "0"], ["84404.00", "0"], ["84404.25", "0"], ["84404.31", "0"], ["84404.49", "0"], ["84405.46", "0"], ["84406.56", "0.016428"], ["84406.80", "0.119869"], ["84407.37", "0.016427"], ["84407.47", "0"], ["84407.50", "0.119843"], ["84407.51", "0.001205"], ["84408.00", "0.035952"], ["84408.48", "0.006356"], ["84408.63", "0"], ["84409.14", "0.006356"], ["84409.16", "0.006356"], ["84409.26", "0.006356"], ["84409.80", "0.006356"], ["84409.91", "0.009989"], ["84410.16", "0.006356"], ["84410.36", "0.006356"], ["84410.42", "0.006356"], ["84410.88", "0.010985"], ["84410.99", "0.006356"], ["84411.35", "0.119881"], ["84411.40", "0.006356"], ["84411.76", "0.009989"], ["84411.86", "0.006356"], ["84412.21", "0.006356"], ["84412.63", "0.006357"], ["84412.75", "0.010984"], ["84412.76", "0.119879"], ["84413.41", "0.015892"], ["84414.11", "0.006356"], ["84414.38", "0.006356"], ["84415.30", "0.119895"], ["84416.36", "0.015891"], ["84417.04", "0.010986"], ["84434.50", "0.026600"], ["84436.50", "0.070002"], ["84438.50", "0.184307"], ["84438.70", "0.001680"], ["84439.80", "0"], ["84440.50", "0.003000"], ["84441.50", "0.296760"], ["84442.20", "0.145080"], ["84443.30", "0.001597"], ["84447.90", "0"], ["84449.00", "0"], ["84449.70", "0"], ["84450.20", "0.007050"], ["84451.00", "0.188130"], ["84451.10", "0"], ["84451.50", "0.008190"], ["84453.30", "0"], ["84453.50", "0.015150"], ["84454.70", "0"], ["84457.10", "0.876810"], ["84457.20", "0.244380"], ["84457.40", "0.142500"], ["84461.90", "0.197885"], ["84480.70", "4.513856"], ["84489.20", "4.965242"], ["84497.70", "5.145796"], ["84506.20", "4.874965"], ["84514.70", "5.506904"], ["84523.20", "5.416627"], ["84531.70", "4.604133"], ["84540.20", "5.597182"], ["84548.70", "5.326350"], ["84557.20", "5.236073"], ["84574.20", "4.423579"], ["84582.70", "3.881916"], ["84591.20", "4.694410"], ["84599.70", "3.972194"], ["84608.20", "4.152748"], ["84616.70", "4.062471"], ["84620.19", "0"], ["84625.20", "4.333302"], ["84633.70", "4.243025"], ["84642.20", "4.784688"], ["84876.03", "0"], ["84879.10", "0"], ["84879.37", "0"], ["84879.59", "0"], ["84880.00", "0"], ["84880.89", "0"], ["84882.35", "0"], ["84883.65", "0"], ["84883.72", "0"], ["84883.84", "0"], ["84885.24", "0"], ["84885.53", "0"], ["84886.01", "0"]], "bids": [["84384.21", "1.092258"], ["84382.30", "0.139805"], ["84380.54", "0.055172"], ["84375.71", "0"], ["84374.75", "0"], ["84372.37", "0.046650"], ["84372.36", "0"], ["84372.00", "0.001628"], ["84370.00", "0.004472"], ["84368.00", "0.011768"], ["84367.51", "0.003016"], ["84366.00", "0.030969"], ["84365.45", "0.247703"], ["84364.19", "0.017814"], ["84364.12", "0.084337"], ["84364.10", "0.018239"], ["84364.00", "0.081497"], ["84363.59", "0"], ["84362.94", "0.056287"], ["84362.85", "0.015752"], ["84362.74", "0.005931"], ["84362.66", "0.006557"], ["84362.63", "0.007111"], ["84362.00", "0.214466"], ["84361.40", "0.016456"], ["84361.36", "0.017058"], ["84361.20", "0.007307"], ["84360.66", "0"], ["84360.05", "0.008155"], ["84360.04", "0.017041"], ["84360.00", "0.564384"], ["84359.68", "0.002946"], ["84359.56", "0.008977"], ["84359.26", "0.011941"], ["84358.79", "0.008273"], ["84358.78", "0"], ["84358.00", "1.485221"], ["84357.90", "0.052045"], ["84357.52", "0"], ["84357.45", "0"], ["84357.42", "0"], ["84357.28", "0.002061"], ["84356.91", "0.271574"], ["84356.77", "0.028773"], ["84356.32", "0.209200"], ["84356.24", "0"], ["84356.03", "0.227431"], ["84356.00", "3.908477"], ["84355.90", "0.025054"], ["84355.72", "0"], ["84354.92", "0"], ["84354.55", "0"], ["84354.53", "0"], ["84354.00", "10.285465"], ["84353.90", "0.354510"], ["84353.84", "0"], ["84353.80", "0.212700"], ["84353.70", "0"], ["84353.57", "0"], ["84353.50", "0.406170"], ["84353.37", "0.018500"], ["84353.30", "0.410550"], ["84352.82", "0"], ["84352.63", "0"], ["84352.34", "0.222464"], ["84352.15", "0.075922"], ["84352.02", "0.010227"], ["84352.00", "0.000121"], ["84351.80", "0.069780"], ["84351.75", "0"], ["84351.74", "0"], ["84351.26", "0"], ["84351.00", "4.162950"], ["84350.60", "1.508580"], ["84350.40", "3.586410"], ["84350.24", "0"], ["84350.16", "0.021086"], ["84349.79", "0"], ["84349.10", "0"], ["84348.73", "0.012424"], ["84348.50", "0.180000"], ["84348.20", "0"], ["84347.80", "0.159600"], ["84346.16", "0.056571"], ["84345.99", "0.073417"], ["84345.80", "5.614140"], ["84345.71", "0"], ["84345.70", "1.852830"], ["84345.50", "0"], ["84345.17", "0.023910"], ["84343.70", "0"], ["84343.01", "0"], ["84342.40", "1.064910"], ["84342.00", "0.502920"], ["84341.90", "0.090000"], ["84341.00", "0.320250"], ["84340.80", "0"], ["84340.70", "0"], ["84340.10", "0"], ["84339.80", "0"], ["84339.10", "0"], ["84338.80", "0"], ["84331.70", "0"], ["84330.59", "0.007576"], ["84330.50", "0.207047"], ["84328.70", "0.001179"], ["84325.40", "0"], ["84318.48", "0"], ["84311.80", "4.423579"], ["84303.30", "4.694410"], ["84294.80", "4.965242"], ["84294.50", "0"], ["84286.30", "4.333302"], ["84277.80", "4.243025"], ["84269.30", "5.416627"], ["84265.39", "0.125210"], ["84260.80", "5.145796"], ["84252.30", "4.062471"], ["84243.80", "4.152748"], ["84235.30", "4.513856"], ["84226.80", "4.874965"], ["84218.30", "5.236073"], ["84209.80", "3.881916"], ["84201.30", "5.326350"], ["84192.80", "5.506904"], ["84184.30", "5.597182"], ["84168.00", "0.000121"], ["84167.30", "3.972194"], ["84165.91", "0"], ["84158.80", "4.784688"], ["84150.30", "4.604133"], ["83899.58", "0"], ["83898.68", "0"], ["83896.11", "0"], ["83896.00", "0"]], "checksum": -2084105291, "ts": "1742142248626"}], "ts": 1742142248632, "record_time": 1742142247.743037}
{"action": "update", "arg": {"instType": "SPOT", "channel": "books", "instId": "BTCUSDT"}, "data": [{"asks": [["84384.22", "0.596666"], ["84393.23", "0"], ["84395.78", "0.030015"], ["84397.16", "0.139772"], ["84398.53", "0.023998"], ["84401.30", "0.006184"], ["84406.79", "0.110639"], ["84408.79", "1.892379"], ["84425.67", "2.231711"], ["84426.27", "0.012680"], ["84428.50", "0.001387"], ["84430.50", "0.003650"], ["84432.50", "0.009605"], ["84434.36", "0.031812"], ["84434.50", "0.025276"], ["84436.50", "0.066517"], ["84438.50", "0.175045"], ["84439.30", "0.002700"], ["84439.40", "0.342570"], ["84440.50", "0"], ["84441.50", "0"], ["84442.70", "0.705690"], ["84451.00", "0.142500"], ["84451.10", "0.270030"], ["84451.80", "0.032790"], ["84454.00", "0.253620"], ["84455.30", "1.422840"], ["84455.40", "1.351770"], ["84457.10", "0"], ["84457.20", "0"], ["84457.40", "0"], ["84480.70", "5.236073"], ["84489.20", "4.513856"], ["84497.70", "5.326350"], ["84506.20", "4.243025"], ["84514.70", "5.416627"], ["84523.20", "4.694410"], ["84531.70", "3.881916"], ["84540.20", "5.506904"], ["84548.70", "4.604133"], ["84557.20", "4.874965"], ["84565.70", "4.784688"], ["84574.20", "5.055519"], ["84582.70", "4.152748"], ["84591.20", "5.597182"], ["84599.70", "4.333302"], ["84608.20", "3.972194"], ["84616.70", "4.423579"], ["84625.20", "4.965242"], ["84633.70", "4.062471"], ["84642.20", "5.145796"], ["84868.52", "0"], ["84868.65", "0"], ["84869.57", "0"], ["84871.66", "0"], ["84871.79", "0"], ["84873.84", "0"], ["84874.79", "0"], ["84875.00", "0"], ["84875.78", "0"]], "bids": [["84384.21", "1.275626"], ["84384.14", "0.125520"], ["84384.13", "0"], ["84384.04", "1.892379"], ["84379.91", "0"], ["84375.76", "0.007224"], ["84372.86", "0.000070"], ["84372.37", "0.153010"], ["84372.00", "0.001787"], ["84371.55", "0.014089"], ["84370.00", "0.004139"], ["84368.54", "0.006914"], ["84368.00", "0.010890"], ["84367.16", "2.546637"], ["84366.13", "0"], ["84366.00", "0.028659"], ["84364.00", "0.075417"], ["84363.58", "0.012209"], ["84362.00", "0.198467"], ["84360.00", "0.522281"], ["84359.26", "0.024575"], ["84358.00", "1.374263"], ["84356.00", "3.616484"], ["84354.00", "9.517062"], ["84353.50", "0.405990"], ["84353.30", "0"], ["84353.20", "0.213450"], ["84352.30", "0.035520"], ["84351.30", "0.099000"], ["84351.10", "0.090000"], ["84351.00", "4.162770"], ["84350.60", "0.263013"], ["84350.40", "3.262980"], ["84348.50", "0"], ["84348.10", "0.410370"], ["84347.60", "0.177960"], ["84347.20", "0.035520"], ["84347.00", "0.090000"], ["84346.90", "0.090000"], ["84345.90", "0.090000"], ["84345.80", "5.436300"], ["84345.70", "0.222930"], ["84345.30", "0.120000"], ["84345.20", "0.090000"], ["84344.20", "0.090000"], ["84343.70", "2.669430"], ["84343.60", "0.090000"], ["84342.40", "0"], ["84342.00", "0.000121"], ["84341.90", "0"], ["84341.80", "0"], ["84341.70", "0"], ["84341.00", "0"], ["84303.30", "5.145796"], ["84286.30", "4.604133"], ["84269.30", "4.694410"], ["84260.80", "3.972194"], ["84252.30", "4.513856"], ["84243.80", "5.597182"], ["84235.30", "5.326350"], ["84226.80", "5.506904"], ["84218.30", "4.062471"], ["84209.80", "4.152748"], ["84201.30", "5.055519"], ["84192.80", "4.874965"], ["84184.30", "4.784688"], ["84175.80", "3.881916"], ["84167.30", "5.236073"], ["84158.80", "4.333302"], ["84150.30", "5.416627"], ["84100.81", "0"], ["83904.78", "0"], ["83904.35", "0"], ["83904.34", "0"], ["83903.51", "0"], ["83902.23", "0"], ["83901.67", "0"], ["83901.14", "0"], ["83900.60", "0"], ["83900.52", "0"], ["83900.00", "0"]], "checksum": -1170212787, "ts": "1742142248839"}], "ts": 1742142248843, "record_time": 1742142247.956584}
{"action": "update", "arg": {"instType": "SPOT", "channel": "books", "instId": "BTCUSDT"}, "data": [{"asks": [["84384.22", "0.596631"], ["84395.77", "0.009005"], ["84397.15", "0.065929"], ["84398.53", "0"], ["84408.78", "0.743038"], ["84428.50", "0.001610"], ["84430.50", "0.004238"], ["84432.50", "0.011151"], ["84434.50", "0.029345"], ["84436.50", "0.077225"], ["84438.50", "0.203224"], ["84439.10", "0.001049"], ["84439.30", "0.003150"], ["84439.40", "0.342780"], ["84440.20", "0.615720"], ["84441.40", "0"], ["84442.70", "0.209200"], ["84446.10", "3.065460"], ["84451.00", "0.272820"], ["84451.10", "0.035520"], ["84451.70", "0.244380"], ["84454.00", "0.009240"], ["84454.20", "0"], ["84455.30", "0"], ["84455.40", "0"], ["84480.70", "5.145796"], ["84489.20", "4.062471"], ["84497.70", "4.243025"], ["84506.20", "5.416627"], ["84514.70", "3.881916"], ["84523.20", "4.333302"], ["84531.70", "3.972194"], ["84540.20", "4.784688"], ["84548.70", "5.236073"], ["84557.20", "4.965242"], ["84565.70", "4.513856"], ["84582.70", "4.604133"], ["84591.20", "5.506904"], ["84599.70", "4.694410"], ["84608.20", "4.152748"], ["84616.70", "5.326350"], ["84625.20", "4.423579"], ["84633.70", "5.597182"], ["84642.20", "4.874965"], ["84868.42", "0"]], "bids": [["84384.21", "1.304011"], ["84384.14", "0.610517"], ["84378.85", "0.194885"], ["84373.76", "0.000070"], ["84372.86", "0"], ["84372.00", "0.001363"], ["84370.00", "0.003587"], ["84368.00", "0.009440"], ["84366.00", "0.024840"], ["84364.00", "0.065368"], ["84362.00", "0.172021"], ["84361.10", "0.197876"], ["84360.71", "0.001698"], ["84360.00", "0.452689"], ["84358.00", "1.191285"], ["84356.33", "0"], ["84356.00", "3.134962"], ["84354.00", "8.249900"], ["84353.90", "0.896460"], ["84353.50", "0.405960"], ["84353.20", "0"], ["84353.17", "0"], ["84353.10", "2.346270"], ["84351.30", "0.099180"], ["84351.10", "0.090180"], ["84351.00", "3.339600"], ["84350.40", "0.916620"], ["84345.80", "6.076260"], ["84345.50", "0.009000"], ["84345.30", "0"], ["84344.80", "0.060000"], ["84344.30", "0.120000"], ["84343.60", "0"], ["84330.50", "0"], ["84311.80", "5.326350"], ["84303.30", "5.055519"], ["84294.80", "4.604133"], ["84286.30", "4.333302"], ["84277.80", "5.506904"], ["84269.30", "5.145796"], ["84260.80", "4.062471"], ["84243.80", "4.874965"], ["84235.30", "4.243025"], ["84226.80", "5.236073"], ["84218.30", "4.423579"], ["84201.30", "4.694410"], ["84200.59", "0.176594"], ["84192.80", "4.784688"], ["84184.30", "3.881916"], ["84175.80", "5.597182"], ["84167.30", "5.416627"], ["84158.80", "3.972194"], ["84150.30", "4.965242"], ["83904.85", "0"]], "checksum": -1117528258, "ts": "1742142249041"}], "ts": 1742142249045, "record_time": 1742142248.152068}
{"action": "update", "arg": {"instType": "SPOT", "channel": "books", "instId": "BTCUSDT"}, "data": [{"asks": [["84412.75", "0.190194"], ["84425.66", "0.674110"], ["84428.50", "0.001397"], ["84430.50", "0.003675"], ["84432.50", "0.009673"], ["84434.50", "0.025453"], ["84436.50", "0.066849"], ["84438.50", "0.176142"], ["84439.30", "0.002910"], ["84439.40", "0.001015"], ["84440.20", "0"], ["84446.10", "0.063390"], ["84448.80", "0.887400"], ["84449.10", "2.345940"], ["84451.00", "0.142500"], ["84451.10", "0.017640"], ["84480.70", "4.243025"], ["84489.20", "4.604133"], ["84497.70", "3.881916"], ["84506.20", "5.597182"], ["84514.70", "5.416627"], ["84523.20", "4.062471"], ["84531.70", "4.874965"], ["84540.20", "5.326350"], ["84548.70", "4.152748"], ["84557.20", "5.236073"], ["84565.70", "3.972194"], ["84582.70", "4.694410"], ["84591.20", "5.145796"], ["84599.70", "4.423579"], ["84608.20", "5.506904"], ["84616.70", "4.784688"], ["84625.20", "4.513856"], ["84633.70", "4.965242"], ["84642.20", "4.333302"], ["84866.40", "0"], ["84867.80", "0"]], "bids": [["84384.21", "1.527340"], ["84380.67", "0.055172"], ["84380.54", "0"], ["84378.86", "0.065689"], ["84378.85", "0"], ["84375.76", "0"], ["84373.80", "0.003003"], ["84372.00", "0.001512"], ["84370.00", "0.003980"], ["84368.00", "0.010474"], ["84366.00", "0.027561"], ["84365.80", "0.003065"], ["84364.00", "0.072531"], ["84362.00", "0.190870"], ["84360.00", "0.502291"], ["84358.00", "1.321817"], ["84356.00", "3.478467"], ["84354.00", "9.153860"], ["84353.40", "0.680820"], ["84352.90", "0.420300"], ["84343.70", "0"], ["84331.50", "0.207047"], ["84311.80", "5.055519"], ["84303.30", "5.506904"], ["84294.80", "5.416627"], ["84277.80", "4.604133"], ["84260.80", "4.243025"], ["84252.30", "3.972194"], ["84235.30", "4.694410"], ["84226.80", "4.152748"], ["84218.30", "4.965242"], ["84209.80", "4.513856"], ["84201.30", "4.784688"], ["84192.80", "4.062471"], ["84184.30", "5.236073"], ["84175.80", "5.326350"], ["84167.30", "4.423579"], ["84158.80", "3.881916"], ["84150.30", "5.597182"], ["83907.22", "0"], ["83906.25", "0"], ["83905.95", "0"]], "checksum": -129588196, "ts": "1742142249246"}], "ts": 1742142249249, "record_time": 1742142248.356839}
{"action": "update", "arg": {"instType": "SPOT", "channel": "books", "instId": "BTCUSDT"}, "data": [{"asks": [["84417.40", "0.064521"], ["84434.26", "0.100473"], ["84436.50", "0.067026"], ["84438.50", "0.176495"], ["84441.50", "0.375000"], ["84446.10", "0.246990"], ["84446.60", "0.818580"], ["84451.10", "0.020880"], ["84453.50", "0"], ["84454.20", "0.007050"], ["84480.70", "4.694410"], ["84489.20", "4.062471"], ["84497.70", "5.506904"], ["84506.20", "5.416627"], ["84514.70", "4.152748"], ["84523.20", "4.874965"], ["84531.70", "5.236073"], ["84540.20", "4.243025"], ["84548.70", "5.597182"], ["84557.20", "5.055519"], ["84565.70", "4.423579"], ["84574.20", "5.145796"], ["84582.70", "4.604133"], ["84591.20", "3.881916"], ["84599.70", "4.333302"], ["84608.20", "4.513856"], ["84625.20", "3.972194"], ["84642.20", "5.326350"], ["84864.69", "0"], ["84864.86", "0"], ["84864.99", "0"], ["84866.10", "0"]], "bids": [["84384.21", "1.342553"], ["84378.86", "0"], ["84375.76", "0.007224"], ["84365.68", "0.003032"], ["84365.52", "0.003056"], ["84362.00", "0.191021"], ["84360.00", "0.502685"], ["84358.00", "1.322857"], ["84356.00", "3.481202"], ["84354.00", "9.161225"], ["84353.40", "0.681000"], ["84353.10", "2.346450"], ["84352.90", "0.420480"], ["84311.80", "4.152748"], ["84294.80", "5.236073"], ["84286.30", "4.874965"], ["84277.80", "4.694410"], ["84269.30", "5.326350"], ["84260.80", "4.604133"], ["84252.30", "4.423579"], ["84243.80", "4.062471"], ["84235.30", "4.243025"], ["84226.80", "4.333302"], ["84218.30", "4.784688"], ["84209.80", "3.881916"], ["84201.30", "3.972194"], ["84200.00", "0"], ["84192.80", "4.513856"], ["84184.30", "5.416627"], ["84175.80", "5.055519"], ["84169.00", "0.012717"], ["84167.30", "5.145796"], ["84158.80", "5.597182"], ["84150.30", "4.965242"], ["83908.04", "0"]], "checksum": 1063040658, "ts": "1742142249447"}], "ts": 1742142249452, "record_time": 1742142248.559792}
{"action": "update", "arg": {"instType": "SPOT", "channel": "books", "instId": "BTCUSDT"}, "data": [{"asks": [["84423.63", "0.005640"], ["84430.49", "0.004004"], ["84438.50", "0.176607"], ["84446.10", "0"], ["84446.60", "0"], ["84451.10", "0"], ["84451.70", "0"], ["84480.70", "4.965242"], ["84489.20", "4.694410"], ["84506.20", "4.062471"], ["84514.70", "4.513856"], ["84523.20", "5.236073"], ["84531.70", "5.326350"], ["84540.20", "3.881916"], ["84548.70", "4.784688"], ["84557.20", "3.972194"], ["84565.70", "4.604133"], ["84574.20", "5.055519"], ["84582.70", "4.874965"], ["84591.20", "5.145796"], ["84608.20", "4.243025"], ["84616.70", "4.423579"], ["84625.20", "4.152748"], ["84633.70", "5.597182"], ["84642.20", "5.416627"], ["84864.69", "0.000052"], ["84864.86", "0.000041"]], "bids": [["84384.21", "1.318140"], ["84380.79", "0.055172"], ["84380.67", "0"], ["84376.28", "0.196971"], ["84373.76", "0"], ["84373.51", "0.000070"], ["84368.54", "0.611677"], ["84365.46", "0.024413"], ["84364.00", "0.072750"], ["84362.00", "0.191449"], ["84360.00", "0.503813"], ["84358.00", "1.325822"], ["84356.00", "3.489005"], ["84354.00", "9.181592"], ["84311.80", "4.333302"], ["84303.30", "4.243025"], ["84294.80", "3.972194"], ["84286.30", "4.784688"], ["84277.80", "4.513856"], ["84269.30", "3.881916"], ["84260.80", "4.874965"], ["84252.30", "4.604133"], ["84243.80", "4.423579"], ["84235.30", "5.416627"], ["84226.80", "4.152748"], ["84218.30", "5.236073"], ["84209.80", "5.055519"], ["84201.30", "5.326350"], ["84192.80", "5.597182"], ["84184.30", "5.145796"], ["84175.80", "4.965242"], ["84167.30", "4.062471"], ["84164.00", "0"], ["84158.80", "5.506904"], ["84150.30", "4.694410"], ["83908.26", "0"]], "checksum": -1806934928, "ts": "1742142249649"}], "ts": 1742142249659, "record_time": 1742142248.767082}
{"action": "update", "arg": {"instType": "SPOT", "channel": "books", "instId": "BTCUSDT"}, "data": [{"asks": [["84438.50", "0.176123"], ["84441.50", "0"], ["84446.90", "0.063690"], ["84448.79", "0.873142"], ["84449.10", "0"], ["84451.80", "2.378670"], ["84454.70", "0.244380"], ["84480.70", "4.062471"], ["84489.20", "4.784688"], ["84497.70", "5.597182"], ["84506.20", "3.972194"], ["84514.70", "4.333302"], ["84523.20", "4.965242"], ["84531.70", "3.881916"], ["84540.20", "5.236073"], ["84548.70", "5.326350"], ["84557.20", "5.145796"], ["84565.70", "4.152748"], ["84574.20", "4.243025"], ["84591.20", "4.423579"], ["84599.70", "4.604133"], ["84608.20", "5.506904"], ["84616.70", "4.513856"], ["84625.20", "5.055519"], ["84633.70", "4.694410"], ["84864.86", "0"]], "bids": [["84384.21", "1.426717"], ["84376.29", "0.066315"], ["84375.76", "0"], ["84365.46", "0"], ["84345.70", "0.150150"], ["84343.70", "2.669430"], ["84311.80", "4.152748"], ["84294.80", "4.513856"], ["84286.30", "5.055519"], ["84277.80", "4.333302"], ["84269.30", "5.145796"], ["84260.80", "4.784688"], ["84252.30", "4.965242"], ["84243.80", "3.881916"], ["84235.30", "5.236073"], ["84226.80", "4.604133"], ["84218.30", "3.972194"], ["84209.80", "4.423579"], ["84201.30", "4.694410"], ["84192.80", "5.506904"], ["84184.30", "4.874965"], ["84175.80", "5.416627"], ["84167.30", "5.597182"], ["84158.80", "4.062471"], ["84150.30", "5.326350"]], "checksum": 1272141787, "ts": "1742142249852"}], "ts": 1742142249857, "record_time": 1742142248.964157}
{"action": "update", "arg": {"instType": "SPOT", "channel": "books", "instId": "BTCUSDT"}, "data": [{"asks": [["84394.16", "0.139765"], ["84397.16", "0"], ["84428.50", "0.001395"], ["84430.50", "0.003672"], ["84432.50", "0.009661"], ["84434.50", "0.025424"], ["84436.50", "0.066905"], ["84438.50", "0.176068"], ["84439.60", "0.326370"], ["84443.60", "0.627360"], ["84444.60", "0.201000"], ["84446.90", "0"], ["84448.79", "0"], ["84448.80", "0.062220"], ["84449.60", "0.032790"], ["84451.79", "0.791802"], ["84451.80", "0"], ["84454.20", "0"], ["84454.70", "0"], ["84480.70", "5.326350"], ["84489.20", "5.506904"], ["84497.70", "4.604133"], ["84514.70", "4.694410"], ["84523.20", "4.423579"], ["84531.70", "5.236073"], ["84540.20", "4.513856"], ["84548.70", "5.145796"], ["84557.20", "5.416627"], ["84582.70", "4.333302"], ["84591.20", "4.965242"], ["84599.70", "5.055519"], ["84608.20", "4.874965"], ["84616.70", "3.881916"], ["84625.20", "4.062471"], ["84633.70", "5.597182"], ["84642.20", "4.784688"]], "bids": [["84384.21", "1.375367"], ["84372.00", "0.001357"], ["84370.00", "0.003570"], ["84368.54", "0.519772"], ["84368.00", "0.009394"], ["84366.00", "0.024723"], ["84364.00", "0.065059"], ["84362.00", "0.171207"], ["84360.00", "0.450545"], ["84358.00", "1.185645"], ["84356.00", "3.120119"], ["84354.00", "8.210840"], ["84311.80", "5.055519"], ["84303.30", "4.423579"], ["84294.80", "5.416627"], ["84286.30", "5.145796"], ["84277.80", "3.881916"], ["84269.30", "4.784688"], ["84260.80", "4.965242"], ["84252.30", "5.236073"], ["84243.80", "5.506904"], ["84235.30", "5.326350"], ["84226.80", "4.513856"], ["84218.30", "4.062471"], ["84209.80", "4.874965"], ["84201.30", "4.604133"], ["84192.80", "4.243025"], ["84184.30", "4.333302"], ["84175.80", "4.152748"], ["84158.80", "3.972194"], ["84150.30", "4.694410"], ["84150.00", "0.002177"], ["83962.29", "0.000122"], ["83908.59", "0"]], "checksum": 1348450498, "ts": "1742142250054"}], "ts": 1742142250058, "record_time": 1742142249.165535}
{"action": "update", "arg": {"instType": "SPOT", "channel": "books", "instId": "BTCUSDT"}, "data": [{"asks": [["84384.22", "0.597270"], ["84392.66", "0.209200"], ["84394.15", "0.050934"], ["84395.77", "0"], ["84395.78", "0"], ["84397.15", "0"], ["84405.62", "0.010985"], ["84408.79", "0"], ["84410.88", "0"], ["84420.14", "0.031812"], ["84422.50", "0.001138"], ["84424.50", "0.002996"], ["84425.67", "0"], ["84426.50", "0.007884"], ["84428.50", "0.020748"], ["84430.50", "0.054598"], ["84432.50", "0.143679"], ["84434.36", "0"], ["84434.50", "0.378105"], ["84436.50", "0.995012"], ["84438.50", "2.618452"], ["84439.20", "0.719520"], ["84439.40", "0"], ["84443.60", "0"], ["84444.20", "0.069600"], ["84444.60", "0.606000"], ["84446.90", "1.350000"], ["84451.10", "0.035520"], ["84451.79", "0.013403"], ["84454.00", "0"], ["84480.70", "5.145796"], ["84489.20", "4.513856"], ["84497.70", "4.874965"], ["84506.20", "4.423579"], ["84523.20", "4.604133"], ["84531.70", "4.784688"], ["84540.20", "3.972194"], ["84548.70", "5.236073"], ["84557.20", "5.597182"], ["84565.70", "4.965242"], ["84574.20", "3.881916"], ["84582.70", "4.062471"], ["84591.20", "5.506904"], ["84599.70", "5.326350"], ["84608.20", "4.333302"], ["84616.70", "4.152748"], ["84625.20", "4.243025"], ["84633.70", "5.416627"], ["84642.20", "5.055519"], ["84864.86", "0.000041"], ["84864.99", "0.000033"]], "bids": [["84384.21", "1.235140"], ["84384.00", "0.000121"], ["84380.92", "0.055172"], ["84380.79", "0"], ["84373.51", "0"], ["84372.00", "0.001058"], ["84370.00", "0.002783"], ["84368.00", "0.007324"], ["84366.00", "0.019274"], ["84365.46", "0.057227"], ["84364.00", "0.050722"], ["84362.94", "0"], ["84362.00", "0.133478"], ["84360.00", "0.351257"], ["84359.68", "0"], ["84358.00", "0.924361"], ["84357.69", "0.056287"], ["84356.00", "2.432530"], ["84354.44", "0.002946"], ["84354.00", "6.401395"], ["84353.90", "0.438600"], ["84353.80", "0.142920"], ["84353.50", "0.405750"], ["84353.40", "0"], ["84353.10", "0"], ["84351.80", "0"], ["84351.30", "0"], ["84351.10", "0"], ["84351.00", "1.059420"], ["84350.80", "0.697350"], ["84349.80", "0"], ["84348.80", "0"], ["84348.60", "0"], ["84347.00", "0.000121"], ["84345.80", "0.769560"], ["84345.70", "0.030150"], ["84344.90", "0.987180"], ["84344.80", "0"], ["84344.30", "0"], ["84343.60", "0.090000"], ["84342.70", "0.038520"], ["84342.40", "1.528020"], ["84342.00", "0.382920"], ["84341.90", "0.090000"], ["84341.80", "0.069600"], ["84311.80", "4.694410"], ["84303.30", "4.604133"], ["84294.80", "4.784688"], ["84286.30", "4.965242"], ["84269.30", "4.423579"], ["84260.80", "5.506904"], ["84252.30", "4.874965"], ["84243.80", "5.236073"], ["84235.30", "3.972194"], ["84218.30", "5.416627"], ["84209.80", "4.243025"], ["84201.30", "5.145796"], ["84192.80", "4.152748"], ["84184.30", "5.326350"], ["84175.80", "4.062471"], ["84167.30", "4.333302"], ["84158.80", "5.597182"], ["84150.30", "5.055519"], ["83962.29", "0"], ["83908.59", "0.000066"], ["83908.26", "0.000072"], ["83908.04", "0.000315"]], "checksum": -2062085373, "ts": "1742142250255"}], "ts": 1742142250264, "record_time": 1742142249.372946}
{"action": "update", "arg": {"instType": "SPOT", "channel": "books", "instId": "BTCUSDT"}, "data": [{"asks": [["84384.22", "0.834875"], ["84388.34", "0.007872"], ["84394.16", "0"], ["84402.21", "0.001205"], ["84407.51", "0"], ["84408.78", "0"], ["84422.50", "0.001021"], ["84424.50", "0.002011"], ["84425.66", "0"], ["84426.50", "0.005294"], ["84428.50", "0.013930"], ["84430.50", "0.036659"], ["84432.50", "0.096470"], ["84434.50", "0.253868"], ["84436.50", "0.668074"], ["84438.50", "1.758091"], ["84439.20", "0.972210"], ["84439.30", "2.346240"], ["84439.60", "0.326190"], ["84445.20", "0.029130"], ["84445.70", "0.244380"], ["84448.80", "0.348480"], ["84451.50", "0"], ["84451.79", "0"], ["84480.70", "4.062471"], ["84489.20", "5.416627"], ["84497.70", "4.152748"], ["84506.20", "3.881916"], ["84514.70", "4.965242"], ["84527.06", "0"], ["84531.70", "5.326350"], ["84540.20", "4.784688"], ["84557.20", "3.972194"], ["84565.70", "4.423579"], ["84574.20", "4.694410"], ["84582.70", "4.874965"], ["84591.20", "5.597182"], ["84599.70", "4.243025"], ["84608.20", "5.506904"], ["84616.70", "4.513856"], ["84625.20", "4.333302"], ["84633.70", "5.145796"], ["84717.52", "0"], ["84733.81", "1.705138"], ["84763.94", "0.000786"], ["84866.10", "0.000064"], ["84866.40", "0.000018"]], "bids": [["84384.21", "0.853130"], ["84384.14", "0"], ["84382.30", "0"], ["84382.00", "0.000159"], ["84381.00", "0.000159"], ["84380.00", "0.000159"], ["84379.00", "0.000159"], ["84378.00", "0.000159"], ["84377.00", "0.000159"], ["84376.00", "0.000159"], ["84375.00", "0.000159"], ["84374.48", "0.000070"], ["84374.00", "0.001044"], ["84373.00", "0.000159"], ["84370.00", "0.002563"], ["84368.00", "0.006745"], ["84366.00", "0.017749"], ["84365.46", "0.085612"], ["84364.00", "0.046709"], ["84362.00", "0.122919"], ["84360.00", "0.323471"], ["84358.00", "0.851240"], ["84356.00", "2.240103"], ["84354.00", "5.895010"], ["84353.90", "0.304170"], ["84353.80", "0.001022"], ["84353.30", "0.254910"], ["84351.00", "1.731990"], ["84350.80", "0"], ["84350.40", "0"], ["84349.80", "0.177960"], ["84347.80", "0.090000"], ["84345.80", "1.250280"], ["84345.20", "0"], ["84344.90", "1.086180"], ["84344.60", "0.090000"], ["84344.20", "0"], ["84343.70", "3.586050"], ["84341.80", "0"], ["84311.80", "3.881916"], ["84303.30", "5.055519"], ["84294.80", "5.236073"], ["84286.30", "4.062471"], ["84277.80", "4.423579"], ["84269.30", "4.784688"], ["84260.80", "4.965242"], ["84252.30", "4.152748"], ["84243.80", "4.513856"], ["84235.30", "4.333302"], ["84226.80", "4.694410"], ["84218.30", "3.972194"], ["84209.80", "5.416627"], ["84201.30", "5.506904"], ["84192.80", "4.243025"], ["84184.30", "4.874965"], ["84175.80", "5.597182"], ["84167.30", "5.326350"], ["84166.00", "0.000159"], ["84158.80", "4.604133"], ["84150.30", "5.145796"], ["84058.64", "1.612861"], ["84042.47", "0"], ["83910.00", "0"], ["83909.15", "0"], ["83909.09", "0"], ["83909.08", "0"], ["83908.59", "0"], ["83908.26", "0"], ["83908.04", "0"]], "checksum": 672591801, "ts": "1742142250457"}], "ts": 1742142250462, "record_time": 1742142249.570075}
{"action": "update", "arg": {"instType": "SPOT", "channel": "books", "instId": "BTCUSDT"}, "data": [{"asks": [["84384.04", "0.599900"], ["84384.05", "0.053200"], ["84384.22", "1.009851"], ["84384.26", "0"], ["84384.32", "0"], ["84384.95", "0.079992"], ["84385.43", "0"], ["84385.45", "0"], ["84385.51", "0"], ["84385.70", "0.002807"], ["84387.14", "0"], ["84387.17", "0"], ["84387.21", "0"], ["84388.35", "0"], ["84388.40", "0"], ["84388.42", "0"], ["84392.77", "0.001205"], ["84394.15", "0"], ["84395.59", "0.006356"], ["84395.93", "0.006356"], ["84396.47", "1.892616"], ["84396.81", "0.010985"], ["84397.11", "0.016428"], ["84397.37", "0.006356"], ["84397.99", "0.119843"], ["84398.01", "0.006356"], ["84398.15", "0.016427"], ["84398.54", "0"], ["84398.99", "0.017778"], ["84399.48", "0.010984"], ["84400.55", "0"], ["84400.59", "0.009989"], ["84402.21", "0"], ["84402.39", "0.119879"], ["84403.16", "0.009989"], ["84403.69", "0"], ["84403.76", "0.015892"], ["84404.68", "0.006356"], ["84405.61", "0.031812"], ["84405.62", "0"], ["84405.87", "0"], ["84406.01", "0.006356"], ["84406.46", "0.015891"], ["84406.56", "0"], ["84406.57", "0.006356"], ["84406.80", "0"], ["84407.37", "0"], ["84407.50", "0"], ["84407.92", "0.001807"], ["84408.00", "0"], ["84408.48", "0"], ["84409.14", "0"], ["84409.16", "0"], ["84409.26", "0"], ["84409.80", "0"], ["84409.91", "0"], ["84410.16", "0"], ["84410.36", "0"], ["84410.42", "0"], ["84410.94", "0"], ["84410.99", "0"], ["84411.35", "0"], ["84411.40", "0"], ["84411.76", "0"], ["84411.86", "0"], ["84412.21", "0"], ["84412.50", "0.001032"], ["84412.63", "0"], ["84412.75", "0.179210"], ["84412.76", "0"], ["84413.34", "2.231474"], ["84413.41", "0"], ["84414.11", "0"], ["84414.38", "0"], ["84414.50", "0.001038"], ["84415.30", "0"], ["84416.36", "0"], ["84416.50", "0.002363"], ["84418.50", "0.006218"], ["84419.09", "0"], ["84420.14", "0"], ["84420.50", "0.016363"], ["84421.88", "0.027943"], ["84422.50", "0.043061"], ["84423.64", "0"], ["84424.50", "0.113319"], ["84426.27", "0"], ["84426.50", "0.298208"], ["84428.50", "0.784757"], ["84430.50", "2.065149"], ["84432.50", "5.434604"], ["84432.60", "0.001003"], ["84433.10", "0.001004"], ["84433.30", "13.911180"], ["84434.00", "2.346750"], ["84434.10", "0.001048"], ["84434.20", "0.372570"], ["84434.30", "0.052830"], ["84434.50", "0"], ["84434.70", "0.120180"], ["84435.00", "0.052830"], ["84435.40", "0.244380"], ["84435.50", "0.105660"], ["84435.60", "1.079220"], ["84436.20", "0.069780"], ["84436.50", "0"], ["84437.60", "0.410370"], ["84438.20", "0.212100"], ["84438.50", "3.533280"], ["84438.70", "0"], ["84439.10", "0"], ["84439.20", "0"], ["84439.30", "0"], ["84439.90", "3.557040"], ["84440.20", "0.069600"], ["84442.20", "0.483870"], ["84442.40", "0.269760"], ["84443.50", "0.464250"], ["84444.50", "0.417030"], ["84444.60", "1.650240"], ["84444.90", "0.981300"], ["84445.20", "0"], ["84445.40", "3.557040"], ["84445.70", "0"], ["84446.20", "0"], ["84446.90", "0"], ["84447.60", "0"], ["84448.10", "0"], ["84448.20", "0"], ["84448.80", "0"], ["84449.60", "0"], ["84449.90", "0"], ["84450.20", "0"], ["84451.00", "0"], ["84451.10", "0"], ["84474.70", "4.785026"], ["84475.01", "0.072042"], ["84480.70", "0"], ["84483.20", "3.972474"], ["84489.20", "0"], ["84491.70", "4.153041"], ["84497.70", "0"], ["84500.20", "5.326727"], ["84506.20", "0"], ["84507.94", "0"], ["84508.70", "4.514175"], ["84514.70", "0"], ["84517.20", "3.882191"], ["84523.20", "0"], ["84525.70", "4.604459"], ["84531.70", "0"], ["84534.20", "5.597577"], ["84540.20", "0"], ["84542.70", "5.146160"], ["84548.70", "0"], ["84551.20", "5.417010"], ["84557.20", "0"], ["84559.70", "4.694742"], ["84565.70", "0"], ["84568.20", "4.965593"], ["84574.20", "0"], ["84576.70", "4.875309"], ["84582.70", "0"], ["84585.20", "4.243325"], ["84591.20", "0"], ["84593.70", "5.236443"], ["84599.70", "0"], ["84602.20", "5.055876"], ["84608.20", "0"], ["84610.70", "4.423892"], ["84616.70", "0"], ["84619.20", "4.062758"], ["84625.20", "0"], ["84627.70", "5.507294"], ["84633.70", "0"], ["84636.20", "4.333608"], ["84642.20", "0"], ["84659.24", "0.015814"], ["84867.80", "0.000095"], ["84868.42", "0.000031"], ["84868.52", "0.000013"], ["84868.65", "0.000035"], ["84869.57", "0.000932"], ["84871.66", "0.000078"], ["84871.79", "0.000014"], ["84873.84", "0.000057"], ["84874.79", "0.000096"], ["84875.00", "0.000959"], ["84875.78", "0.000038"], ["84876.03", "0.000161"], ["84879.10", "0.000009"], ["84879.37", "0.000009"], ["84879.59", "0.000173"]], "bids": [["84384.21", "0"], ["84384.04", "0"], ["84384.00", "0"], ["84382.00", "0"], ["84381.00", "0"], ["84380.92", "0"], ["84380.00", "0"], ["84379.00", "0"], ["84378.00", "0"], ["84377.21", "0.009880"], ["84376.29", "0"], ["84376.28", "0"], ["84375.75", "0"], ["84375.70", "0"], ["84375.41", "1.892616"], ["84374.48", "0"], ["84374.00", "0.000159"], ["84373.80", "0"], ["84373.30", "0.353132"], ["84372.37", "0"], ["84372.01", "0"], ["84372.00", "0.000159"], ["84371.55", "0"], ["84371.54", "0"], ["84370.00", "0"], ["84369.76", "0.006921"], ["84368.54", "0"], ["84368.00", "0.001029"], ["84367.51", "0"], ["84367.16", "0"], ["84366.00", "0.001037"], ["84365.80", "0"], ["84365.68", "0"], ["84365.52", "0"], ["84365.46", "0"], ["84365.45", "0"], ["84364.19", "0"], ["84364.12", "0"], ["84364.10", "0"], ["84364.00", "0.001043"], ["84362.85", "0"], ["84362.74", "0"], ["84362.66", "0"], ["84362.63", "0"], ["84362.00", "0.001031"], ["84361.40", "0"], ["84361.36", "0"], ["84361.20", "0"], ["84361.10", "0"], ["84360.71", "0"], ["84360.05", "0"], ["84360.04", "0"], ["84360.00", "0.001020"], ["84359.56", "0"], ["84359.39", "0"], ["84359.38", "0"], ["84359.31", "0"], ["84359.26", "0"], ["84358.79", "0"], ["84358.53", "2.546945"], ["84358.45", "0"], ["84358.36", "0"], ["84358.00", "0.002103"], ["84357.90", "0"], ["84357.69", "0"], ["84357.68", "0"], ["84357.63", "0"], ["84357.28", "0"], ["84356.95", "0"], ["84356.91", "0"], ["84356.77", "0"], ["84356.53", "0"], ["84356.43", "0"], ["84356.36", "0"], ["84356.31", "0"], ["84356.03", "0"], ["84356.00", "0.000121"], ["84355.90", "0"], ["84354.62", "0"], ["84354.44", "0"], ["84354.21", "0"], ["84354.17", "0"], ["84354.06", "0"], ["84354.00", "0.014564"], ["84353.90", "0"], ["84353.88", "0.007924"], ["84353.80", "0"], ["84353.50", "0"], ["84353.49", "0.006209"], ["84353.42", "0.005412"], ["84353.41", "0.008549"], ["84353.40", "0.000436"], ["84353.37", "0"], ["84353.30", "0"], ["84352.90", "0"], ["84352.34", "0"], ["84352.30", "0"], ["84352.23", "0"], ["84352.15", "0"], ["84352.02", "0"], ["84352.00", "0.038327"], ["84351.73", "0.007469"], ["84351.72", "0.012634"], ["84351.25", "0"], ["84351.21", "0"], ["84351.17", "0"], ["84351.00", "0.000121"], ["84350.60", "0"], ["84350.16", "0"], ["84350.00", "0.100860"], ["84349.80", "0"], ["84348.87", "0.056287"], ["84348.73", "0"], ["84348.18", "0.006557"], ["84348.17", "0.009627"], ["84348.10", "0"], ["84348.00", "0.265422"], ["84347.87", "0.008667"], ["84347.80", "0"], ["84347.70", "0.010227"], ["84347.60", "0"], ["84347.53", "0.025054"], ["84347.40", "0"], ["84347.33", "0.028773"], ["84347.25", "0.017041"], ["84347.20", "0"], ["84346.90", "0"], ["84346.53", "0.227399"], ["84346.21", "0.017311"], ["84345.99", "0"], ["84345.90", "0"], ["84345.80", "0.017100"], ["84345.70", "0.015090"], ["84345.60", "0"], ["84345.40", "0.001039"], ["84345.17", "0"], ["84344.90", "0.451380"], ["84344.62", "0.052045"], ["84344.60", "0"], ["84344.06", "0.018497"], ["84343.80", "0"], ["84343.70", "0"], ["84343.60", "0"], ["84342.70", "0"], ["84342.51", "0.075922"], ["84342.40", "0"], ["84342.00", "0.000121"], ["84341.98", "0.222464"], ["84341.90", "0"], ["84341.70", "0.015210"], ["84341.57", "0.021083"], ["84341.30", "0.035550"], ["84340.37", "0.012424"], ["84338.84", "0"], ["84338.30", "0.015060"], ["84338.24", "0"], ["84337.30", "0.916620"], ["84337.17", "0.073417"], ["84337.10", "0.009000"], ["84336.30", "0.012510"], ["84336.10", "0.987180"], ["84335.40", "0.035550"], ["84334.60", "0.142500"], ["84333.90", "0.357180"], ["84332.64", "0"], ["84331.50", "0"], ["84330.59", "0"], ["84330.40", "1.627170"], ["84330.30", "1.380000"], ["84329.60", "0.500370"], ["84329.30", "0.009000"], ["84329.10", "0.178290"], ["84329.00", "0.014010"], ["84328.80", "0.060000"], ["84328.70", "0.267960"], ["84328.50", "2.669430"], ["84327.63", "0"], ["84324.75", "0.007576"], ["84324.71", "0.007174"], ["84316.40", "0.207047"], ["84313.69", "0.017779"], ["84311.80", "0"], ["84305.80", "3.882191"], ["84303.30", "0"], ["84297.30", "4.153041"], ["84294.80", "0"], ["84288.80", "5.417010"], ["84286.30", "0"], ["84280.30", "4.243325"], ["84277.80", "0"], ["84271.80", "5.326727"], ["84271.29", "0.209200"], ["84269.30", "0"], ["84263.30", "4.423892"], ["84260.80", "0"], ["84254.80", "4.965593"], ["84252.30", "0"], ["84246.30", "4.694742"], ["84243.80", "0"], ["84237.80", "4.514175"], ["84235.30", "0"], ["84229.30", "4.875309"], ["84226.80", "0"], ["84220.80", "5.146160"], ["84218.30", "0"], ["84212.30", "5.597577"], ["84209.80", "0"], ["84203.80", "4.333608"], ["84201.30", "0"], ["84195.30", "5.507294"], ["84192.80", "0"], ["84186.80", "5.236443"], ["84184.30", "0"], ["84178.30", "4.604459"], ["84175.80", "0"], ["84169.80", "4.785026"], ["84167.30", "0"], ["84161.30", "3.972474"], ["84158.80", "0"], ["84152.80", "5.055876"], ["84150.30", "0"], ["84144.30", "4.062758"], ["83910.00", "0.002000"], ["83909.15", "0.000093"], ["83909.09", "0.000018"], ["83909.08", "0.000065"], ["83908.59", "0.000066"], ["83908.26", "0.000072"], ["83908.04", "0.000315"], ["83907.22", "0.000012"], ["83906.25", "0.000014"], ["83905.95", "0.000011"], ["83904.85", "0.000009"], ["83904.78", "0.000054"], ["83904.35", "0.000042"], ["83904.34", "0.000131"], ["83903.51", "0.000022"], ["83902.23", "0.000096"], ["83901.67", "0.000019"], ["83901.14", "0.000008"], ["83900.60", "0.000013"], ["83900.52", "0.000235"], ["83900.00", "0.002977"], ["83899.58", "0.000010"], ["83898.68", "0.000010"], ["83896.11", "0.000094"], ["83896.00", "0.000133"], ["83895.65", "0.000013"], ["83895.00", "0.006121"], ["83894.74", "0.000068"], ["83894.17", "0.000022"], ["83893.81", "0.000010"], ["83893.64", "0.000039"], ["83893.62", "0.000137"], ["83892.29", "0.000143"], ["83891.43", "0.000455"], ["83891.30", "0.000010"], ["83888.89", "0.000163"], ["83888.86", "0.000371"], ["83887.29", "0.000586"], ["83887.11", "0.000075"], ["83886.91", "0.000145"], ["83885.98", "0.000018"], ["83885.71", "0.000069"], ["83884.62", "0.000014"], ["83884.55", "0.000048"], ["83884.30", "0.000161"], ["83882.98", "0.000188"], ["83882.92", "0.002384"], ["83881.99", "0.000038"], ["83880.00", "0.020454"], ["83877.97", "0.000023"], ["83877.55", "0.000010"], ["83877.42", "0.000054"], ["83877.29", "0.000024"], ["83877.05", "0.000008"], ["83876.25", "0.000028"], ["83876.12", "0.000681"], ["83875.99", "0.000299"]], "checksum": -831952103, "ts": "1742142250660"}], "ts": 1742142250664, "record_time": 1742142249.77412}
{"action": "update", "arg": {"instType": "SPOT", "channel": "books", "instId": "BTCUSDT"}, "data": [{"asks": [["84377.01", "1.289689"], ["84377.22", "0.368674"], ["84379.17", "0.079992"], ["84379.82", "0.223490"], ["84380.48", "0.013476"], ["84384.01", "0.209200"], ["84384.04", "0.000639"], ["84384.05", "0.018456"], ["84384.22", "0.396817"], ["84384.95", "0"], ["84385.47", "0"], ["84385.90", "0.001205"], ["84387.76", "0.119869"], ["84388.29", "0.006356"], ["84388.34", "0"], ["84388.72", "0.006356"], ["84388.88", "0.006356"], ["84389.08", "0.035952"], ["84389.75", "0.006356"], ["84390.07", "0.010985"], ["84390.27", "0.006356"], ["84390.97", "0.006356"], ["84391.12", "0.006356"], ["84391.34", "0.006356"], ["84391.37", "0.006356"], ["84391.64", "0.006356"], ["84392.00", "0.006356"], ["84392.65", "0.065028"], ["84392.77", "0"], ["84393.01", "0.006356"], ["84393.32", "0.006357"], ["84393.80", "0.313026"], ["84394.31", "0.119895"], ["84395.38", "0.012680"], ["84395.67", "0.119879"], ["84396.77", "0.010000"], ["84396.81", "0"], ["84396.91", "0.148098"], ["84397.35", "0.119881"], ["84397.37", "0"], ["84398.53", "0.001807"], ["84400.80", "0.010986"], ["84401.31", "0"], ["84402.39", "0"], ["84404.68", "0"], ["84406.20", "0.001030"], ["84406.57", "0"], ["84406.79", "0"], ["84407.92", "0"], ["84408.20", "0.001410"], ["84410.20", "0.003711"], ["84412.20", "0.009765"], ["84412.50", "0"], ["84414.01", "0"], ["84414.20", "0.025698"], ["84414.50", "0"], ["84416.20", "0.067626"], ["84416.50", "0"], ["84417.04", "0"], ["84417.27", "0.001597"], ["84418.20", "0.177963"], ["84418.50", "0"], ["84420.20", "0.468323"], ["84420.21", "0.001597"], ["84420.50", "0"], ["84422.20", "1.232430"], ["84422.50", "0"], ["84424.20", "3.243237"], ["84424.50", "0"], ["84426.20", "8.534833"], ["84426.50", "0"], ["84426.60", "0.001027"], ["84426.90", "2.514240"], ["84427.00", "2.752920"], ["84428.30", "2.700000"], ["84428.50", "0"], ["84430.20", "0.191100"], ["84430.30", "1.079610"], ["84430.50", "0"], ["84431.80", "0.142680"], ["84432.20", "0.069600"], ["84432.50", "4.474740"], ["84432.60", "0"], ["84432.63", "0.020400"], ["84433.10", "0"], ["84433.30", "0.248880"], ["84434.00", "0.981300"], ["84434.10", "0"], ["84434.20", "0.069600"], ["84434.30", "0.071070"], ["84434.70", "0"], ["84434.80", "3.555180"], ["84435.00", "0"], ["84435.40", "0"], ["84435.50", "0"], ["84435.60", "0"], ["84435.89", "0"], ["84436.20", "0.069600"], ["84436.90", "0.071070"], ["84437.60", "0.588090"], ["84438.00", "0.554250"], ["84438.20", "0.390600"], ["84438.40", "3.694380"], ["84438.50", "4.151400"], ["84439.00", "0.177720"], ["84439.60", "0"], ["84442.20", "0.606180"], ["84442.40", "0"], ["84443.30", "0"], ["84443.50", "0"], ["84444.20", "0"], ["84444.50", "0"], ["84444.60", "0"], ["84444.90", "0"], ["84445.40", "0"], ["84468.40", "5.056256"], ["84474.70", "0"], ["84476.90", "3.972773"], ["84483.20", "0"], ["84485.40", "4.424224"], ["84491.70", "0"], ["84493.90", "5.146547"], ["84500.20", "0"], ["84502.40", "4.965966"], ["84508.70", "0"], ["84510.90", "3.882483"], ["84517.20", "0"], ["84519.40", "5.597998"], ["84525.70", "0"], ["84527.90", "5.327127"], ["84534.20", "0"], ["84536.40", "4.333934"], ["84542.70", "0"], ["84544.90", "4.063063"], ["84551.20", "0"], ["84553.40", "4.514515"], ["84559.70", "0"], ["84561.90", "5.417418"], ["84568.20", "0"], ["84570.40", "4.785386"], ["84576.70", "0"], ["84578.90", "4.695095"], ["84585.20", "0"], ["84587.40", "5.236837"], ["84593.70", "0"], ["84595.90", "5.507708"], ["84602.20", "0"], ["84604.40", "4.153354"], ["84610.70", "0"], ["84612.90", "4.243644"], ["84619.20", "0"], ["84621.40", "4.604805"], ["84627.70", "0"], ["84629.90", "4.875676"], ["84636.20", "0"], ["84864.99", "0"], ["84866.10", "0"], ["84866.40", "0"], ["84867.80", "0"], ["84868.42", "0"], ["84868.52", "0"], ["84868.65", "0"], ["84869.57", "0"], ["84871.66", "0"], ["84871.79", "0"], ["84873.84", "0"], ["84874.79", "0"], ["84875.00", "0"], ["84875.78", "0"], ["84876.03", "0"], ["84879.10", "0"], ["84879.37", "0"], ["84879.59", "0"]], "bids": [["84377.21", "0"], ["84375.41", "0"], ["84371.48", "0"], ["84369.76", "0"], ["84368.53", "0"], ["84368.00", "0"], ["84366.00", "0"], ["84364.00", "0"], ["84363.59", "0.003663"], ["84363.43", "0.006921"], ["84363.41", "0.009555"], ["84363.39", "0.007586"], ["84363.05", "0.012680"], ["84362.42", "0.139761"], ["84362.24", "0.005546"], ["84362.00", "0.000121"], ["84361.70", "0.001016"], ["84360.00", "0.000121"], ["84359.70", "0.001045"], ["84359.17", "0.008256"], ["84358.53", "0"], ["84358.00", "0.000121"], ["84357.70", "0.001016"], ["84357.53", "0"], ["84355.70", "0.001015"], ["84354.00", "0.000121"], ["84353.88", "0"], ["84353.70", "0.001043"], ["84353.50", "0.313026"], ["84353.49", "0"], ["84353.42", "0"], ["84353.41", "0"], ["84353.40", "0"], ["84352.00", "0.000121"], ["84351.73", "0"], ["84351.72", "0"], ["84351.70", "0.001018"], ["84350.00", "0.000121"], ["84349.70", "0.001030"], ["84349.11", "0.001228"], ["84348.87", "0"], ["84348.85", "0.016440"], ["84348.17", "0"], ["84348.00", "0.000121"], ["84347.87", "0"], ["84347.70", "0.001012"], ["84347.34", "0.007338"], ["84347.25", "0"], ["84347.23", "0.006209"], ["84347.22", "0.007436"], ["84347.14", "0.008979"], ["84347.08", "0.005412"], ["84347.07", "0.008139"], ["84346.42", "0.247714"], ["84346.16", "0"], ["84345.80", "0"], ["84345.70", "0.001727"], ["84345.50", "0"], ["84345.44", "0.007939"], ["84345.40", "0"], ["84345.39", "0.007469"], ["84345.23", "0.007859"], ["84345.21", "0.084341"], ["84344.90", "0"], ["84344.71", "0.003017"], ["84344.63", "0.014936"], ["84344.01", "0.017815"], ["84343.83", "0.018239"], ["84343.70", "0.004545"], ["84343.35", "0.015753"], ["84342.57", "0.005931"], ["84342.23", "0.007308"], ["84342.21", "0.007111"], ["84342.15", "0.056289"], ["84341.98", "0"], ["84341.93", "0.005548"], ["84341.90", "0.010016"], ["84341.85", "0.025201"], ["84341.70", "0.011960"], ["84341.30", "0"], ["84341.23", "0.017041"], ["84340.99", "0.008978"], ["84340.58", "0.007924"], ["84340.03", "0.008667"], ["84339.85", "0.010227"], ["84339.84", "0.008155"], ["84339.60", "0.001046"], ["84339.49", "0.008273"], ["84339.20", "0.070470"], ["84338.70", "0.001022"], ["84338.30", "0"], ["84338.20", "0.002100"], ["84338.17", "0.012634"], ["84337.30", "0"], ["84337.12", "0.002947"], ["84336.60", "0.263024"], ["84336.30", "0"], ["84336.18", "0.271586"], ["84336.10", "0"], ["84335.40", "0"], ["84335.30", "0.321060"], ["84335.26", "0.222474"], ["84334.60", "0"], ["84333.90", "0.177210"], ["84333.20", "0.015060"], ["84330.40", "0.578520"], ["84330.30", "0"], ["84329.93", "0.056573"], ["84329.60", "0"], ["84329.00", "0.049560"], ["84328.80", "0"], ["84328.70", "0"], ["84328.60", "0.015210"], ["84328.50", "0"], ["84328.20", "0.142500"], ["84328.10", "0.382800"], ["84326.90", "0.177960"], ["84326.50", "0.450030"], ["84325.81", "0.023911"], ["84325.70", "0.090000"], ["84325.50", "0.178110"], ["84325.18", "0"], ["84324.75", "0"], ["84324.71", "0"], ["84324.70", "2.015940"], ["84323.40", "0.090000"], ["84323.32", "0.008201"], ["84323.30", "2.669430"], ["84322.90", "1.127130"], ["84322.60", "0.111540"], ["84322.50", "0.090000"], ["84318.42", "0.007576"], ["84318.38", "0.007174"], ["84306.59", "0.001188"], ["84305.80", "0"], ["84305.65", "0.001179"], ["84299.50", "4.785386"], ["84297.30", "0"], ["84291.00", "4.153354"], ["84288.80", "0"], ["84282.50", "5.597998"], ["84280.30", "0"], ["84274.00", "5.236837"], ["84271.80", "0"], ["84265.50", "4.604805"], ["84263.30", "0"], ["84257.00", "5.417418"], ["84254.80", "0"], ["84248.50", "4.063063"], ["84246.30", "0"], ["84240.00", "4.965966"], ["84237.80", "0"], ["84231.50", "5.056256"], ["84229.30", "0"], ["84223.00", "4.695095"], ["84220.80", "0"], ["84214.50", "5.327127"], ["84212.30", "0"], ["84206.00", "4.333934"], ["84203.80", "0"], ["84197.50", "4.243644"], ["84195.30", "0"], ["84189.00", "3.972773"], ["84186.80", "0"], ["84180.50", "4.424224"], ["84178.30", "0"], ["84172.00", "4.514515"], ["84169.80", "0"], ["84163.50", "5.507708"], ["84161.30", "0"], ["84155.00", "3.882483"], ["84152.80", "0"], ["84146.50", "4.875676"], ["84144.30", "0"], ["84138.00", "5.146547"], ["83900.00", "0"], ["83899.58", "0"], ["83898.68", "0"], ["83896.11", "0"], ["83896.00", "0"], ["83895.65", "0"], ["83895.00", "0"], ["83894.74", "0"], ["83894.17", "0"], ["83893.81", "0"], ["83893.64", "0"], ["83893.62", "0"], ["83892.29", "0"], ["83891.43", "0"], ["83891.30", "0"], ["83888.89", "0"], ["83888.86", "0"], ["83887.29", "0"], ["83887.11", "0"], ["83886.91", "0"], ["83885.98", "0"], ["83885.71", "0"], ["83884.62", "0"], ["83884.55", "0"], ["83884.30", "0"], ["83882.98", "0"], ["83882.92", "0"], ["83881.99", "0"], ["83880.00", "0"], ["83877.97", "0"], ["83877.55", "0"], ["83877.42", "0"], ["83877.29", "0"], ["83877.05", "0"], ["83876.25", "0"], ["83876.12", "0"], ["83875.99", "0"]], "checksum": 850529971, "ts": "1742142250867"}], "ts": 1742142250871, "record_time": 1742142249.980074}
{"action": "update", "arg": {"instType": "SPOT", "channel": "books", "instId": "BTCUSDT"}, "data": [{"asks": [["84376.01", "2.099453"], ["84376.06", "0.007627"], ["84376.10", "0.015616"], ["84376.11", "0.017712"], ["84376.12", "0.007955"], ["84376.14", "0.005183"], ["84376.17", "0.004739"], ["84377.00", "0.497509"], ["84377.01", "0.594411"], ["84377.21", "0.014268"], ["84377.22", "0.063642"], ["84379.16", "0.095087"], ["84379.82", "0"], ["84384.00", "0.183200"], ["84384.01", "0"], ["84384.03", "0.012842"], ["84384.04", "0"], ["84384.22", "0.256894"], ["84388.18", "0.006356"], ["84388.70", "0.006356"], ["84389.09", "0.016428"], ["84389.97", "0.119843"], ["84390.67", "0.006356"], ["84390.78", "0.016427"], ["84392.12", "0.010984"], ["84392.47", "0.009989"], ["84394.79", "0.015892"], ["84395.38", "0"], ["84395.59", "0"], ["84395.74", "0.009989"], ["84395.93", "0"], ["84396.46", "0.629332"], ["84396.77", "0"], ["84397.04", "0.006356"], ["84397.11", "0"], ["84397.99", "0"], ["84398.01", "0"], ["84398.15", "0"], ["84399.48", "0"], ["84400.59", "0"], ["84403.16", "0"], ["84403.76", "0"], ["84406.01", "0"], ["84408.20", "0.001544"], ["84410.20", "0.004062"], ["84412.20", "0.010690"], ["84414.20", "0.028133"], ["84416.20", "0.074033"], ["84418.20", "0.194823"], ["84420.20", "0.512694"], ["84422.20", "1.349194"], ["84424.20", "3.550511"], ["84426.20", "9.343450"], ["84426.50", "0.001023"], ["84426.60", "0"], ["84426.90", "1.653120"], ["84427.00", "2.752710"], ["84427.80", "0.035550"], ["84428.30", "2.700180"], ["84430.20", "0.191280"], ["84430.30", "1.079220"], ["84432.20", "0.069780"], ["84432.40", "0.410550"], ["84432.50", "1.478970"], ["84432.90", "0.035520"], ["84433.10", "0.180000"], ["84434.20", "0.204600"], ["84436.30", "0.117000"], ["84437.90", "0.198000"], ["84438.00", "0.090000"], ["84438.20", "0.507600"], ["84438.40", "6.595050"], ["84438.50", "2.238930"], ["84438.80", "0.035520"], ["84440.20", "0"], ["84442.20", "0"], ["84468.40", "5.146547"], ["84476.90", "5.056256"], ["84485.40", "4.153354"], ["84493.90", "4.604805"], ["84502.40", "4.333934"], ["84510.90", "4.063063"], ["84519.40", "3.882483"], ["84527.90", "4.785386"], ["84536.40", "4.875676"], ["84544.90", "5.417418"], ["84553.40", "5.327127"], ["84561.90", "4.695095"], ["84570.40", "4.424224"], ["84578.90", "3.972773"], ["84595.90", "4.965966"], ["84604.40", "4.514515"], ["84612.90", "5.507708"], ["84621.40", "5.597998"], ["84629.90", "4.243644"], ["84849.88", "0"], ["84850.00", "0"], ["84851.66", "0"], ["84852.81", "0"], ["84852.94", "0"], ["84853.56", "0"], ["84857.14", "0"], ["84858.75", "0"], ["84859.29", "0"], ["84860.00", "0"], ["84862.90", "0"], ["84864.69", "0"], ["84864.86", "0"]], "bids": [["84377.00", "0"], ["84359.71", "0.002863"], ["84356.33", "0.069579"], ["84355.71", "0.000070"], ["84353.51", "0.094667"], ["84352.22", "0.197600"], ["84349.13", "0.008532"], ["84349.04", "0.000213"], ["84348.85", "0"], ["84348.18", "0"], ["84347.53", "0"], ["84347.33", "0"], ["84347.17", "0.000470"], ["84347.14", "0.015508"], ["84347.12", "0.008549"], ["84346.53", "0"], ["84346.21", "0"], ["84345.70", "0.001561"], ["84345.18", "0.002061"], ["84344.62", "0"], ["84344.06", "0"], ["84343.70", "0.004106"], ["84342.51", "0"], ["84341.88", "0.009627"], ["84341.70", "0.010807"], ["84341.60", "0.001022"], ["84341.57", "0"], ["84341.44", "0.016442"], ["84340.95", "0.006557"], ["84340.37", "0"], ["84339.32", "0.025056"], ["84339.31", "0.028775"], ["84339.20", "0.071640"], ["84338.87", "0.017313"], ["84338.51", "0.227419"], ["84338.20", "0.002310"], ["84337.28", "0.052050"], ["84335.94", "0.018499"], ["84335.30", "0.321240"], ["84334.15", "0.021085"], ["84334.00", "0.029340"], ["84333.90", "0.425790"], ["84333.60", "0.648870"], ["84333.54", "0.075928"], ["84331.40", "0.012425"], ["84330.40", "0.421950"], ["84325.70", "0"], ["84325.50", "0"], ["84324.30", "0.916620"], ["84324.00", "0.090000"], ["84323.40", "0"], ["84322.90", "0"], ["84322.60", "0"], ["84322.50", "0"], ["84299.50", "4.243644"], ["84291.00", "5.327127"], ["84282.50", "4.333934"], ["84274.00", "4.785386"], ["84265.50", "4.153354"], ["84257.00", "4.875676"], ["84248.50", "5.417418"], ["84240.00", "4.063063"], ["84231.50", "4.514515"], ["84223.00", "5.146547"], ["84214.50", "3.972773"], ["84206.00", "4.604805"], ["84197.50", "5.597998"], ["84189.00", "5.056256"], ["84180.50", "4.695095"], ["84172.00", "4.424224"], ["84168.00", "0"], ["84146.50", "4.965966"], ["84138.00", "5.236837"], ["83904.35", "0"], ["83904.34", "0"], ["83903.51", "0"], ["83902.23", "0"], ["83901.67", "0"], ["83901.14", "0"], ["83900.60", "0"], ["83900.52", "0"]], "checksum": -1805896151, "ts": "1742142251072"}], "ts": 1742142251075, "record_time": 1742142250.183235}
{"action": "update", "arg": {"instType": "SPOT", "channel": "books", "instId": "BTCUSDT"}, "data": [{"asks": [["84376.01", "0.287132"], ["84376.06", "0"], ["84376.10", "0"], ["84376.11", "0"], ["84376.12", "0"], ["84376.14", "0"], ["84376.17", "0"], ["84376.45", "0.002807"], ["84377.00", "0"], ["84377.01", "0"], ["84377.21", "0"], ["84377.22", "0"], ["84379.16", "0"], ["84379.17", "0"], ["84381.75", "0.000245"], ["84381.91", "0.004974"], ["84381.92", "0.009604"], ["84381.93", "0.008962"], ["84381.97", "0.007537"], ["84382.02", "0.001066"], ["84382.81", "0.007627"], ["84382.85", "0.024807"], ["84382.86", "0.001162"], ["84383.46", "0.030015"], ["84384.00", "0"], ["84384.03", "0.000162"], ["84384.22", "0.047694"], ["84385.70", "0"], ["84385.90", "0"], ["84387.76", "0"], ["84388.18", "0"], ["84388.29", "0"], ["84388.70", "0"], ["84388.72", "0"], ["84388.88", "0"], ["84389.08", "0"], ["84389.09", "0"], ["84389.50", "0.079992"], ["84389.75", "0"], ["84389.97", "0"], ["84390.07", "0"], ["84390.27", "0"], ["84390.67", "0"], ["84390.78", "0"], ["84390.97", "0"], ["84391.12", "0"], ["84391.34", "0"], ["84391.37", "0"], ["84391.64", "0"], ["84392.00", "0"], ["84392.12", "0"], ["84392.47", "0"], ["84392.66", "0"], ["84393.01", "0"], ["84393.32", "0"], ["84394.31", "0"], ["84394.79", "0"], ["84395.67", "0"], ["84395.74", "0"], ["84395.92", "0.010000"], ["84396.91", "0"], ["84397.04", "0"], ["84397.35", "0"], ["84397.89", "0.119869"], ["84398.53", "0"], ["84399.10", "0.006356"], ["84399.21", "0.035952"], ["84399.61", "0.006356"], ["84399.74", "0.006356"], ["84400.12", "0.006356"], ["84400.44", "0.006356"], ["84400.80", "0"], ["84400.89", "0.010985"], ["84400.96", "0.006356"], ["84401.30", "0"], ["84401.51", "0.006356"], ["84401.90", "0.006356"], ["84402.01", "0.006356"], ["84402.10", "0.006356"], ["84402.13", "0.006356"], ["84402.14", "0.119843"], ["84402.20", "0.016427"], ["84402.41", "0.006356"], ["84403.54", "0.010984"], ["84404.51", "0.009989"], ["84405.36", "0.119895"], ["84405.61", "0"], ["84406.20", "0"], ["84406.46", "0"], ["84406.47", "0.119879"], ["84407.04", "0.119881"], ["84407.30", "0.009989"], ["84408.20", "0"], ["84409.26", "0.006356"], ["84410.20", "0"], ["84411.06", "0.015891"], ["84411.69", "0.010986"], ["84412.20", "0"], ["84412.90", "0.001040"], ["84414.20", "0"], ["84414.90", "0.001008"], ["84416.20", "0"], ["84416.90", "0.001046"], ["84418.20", "0"], ["84418.90", "0.001049"], ["84420.20", "0"], ["84420.90", "0.001049"], ["84421.88", "0"], ["84422.20", "0"], ["84422.90", "0.001041"], ["84424.20", "0"], ["84424.90", "0.001038"], ["84426.20", "0"], ["84426.50", "0"], ["84426.90", "0.001003"], ["84427.00", "0"], ["84427.80", "0"], ["84428.30", "0"], ["84428.90", "0.001033"], ["84430.20", "0"], ["84430.30", "0"], ["84430.90", "0.001013"], ["84431.80", "0"], ["84432.20", "0"], ["84432.40", "0"], ["84432.50", "0"], ["84432.63", "0"], ["84432.90", "0.001026"], ["84433.10", "0.043800"], ["84433.30", "0.043980"], ["84433.80", "0.001049"], ["84434.00", "0"], ["84434.20", "0.003000"], ["84434.30", "0.001033"], ["84434.60", "0.017760"], ["84434.80", "0"], ["84435.10", "0.065160"], ["84436.20", "0"], ["84436.30", "0"], ["84436.90", "0.071250"], ["84437.60", "0"], ["84437.70", "0.244560"], ["84437.90", "0"], ["84438.00", "0"], ["84438.20", "0.178680"], ["84438.40", "0"], ["84438.50", "0.889290"], ["84438.80", "0"], ["84439.00", "0.177900"], ["84439.90", "0"], ["84441.70", "0.071070"], ["84442.20", "0.244770"], ["84443.20", "0.015210"], ["84443.70", "0.177720"], ["84444.20", "0.981300"], ["84444.60", "1.482390"], ["84445.50", "0.120000"], ["84445.70", "2.346060"], ["84446.20", "0.007050"], ["84446.40", "0.177720"], ["84447.60", "0.009000"], ["84468.40", "0"], ["84475.01", "0"], ["84475.10", "5.507268"], ["84476.90", "0"], ["84480.51", "0"], ["84483.60", "5.416985"], ["84485.40", "0"], ["84492.10", "4.785003"], ["84493.90", "0"], ["84500.60", "4.153022"], ["84502.40", "0"], ["84509.10", "5.326702"], ["84509.24", "0.072042"], ["84509.68", "0.072042"], ["84510.90", "0"], ["84517.60", "5.236419"], ["84519.40", "0"], ["84526.10", "4.604437"], ["84527.90", "0"], ["84534.60", "4.965569"], ["84536.40", "0"], ["84543.10", "4.514154"], ["84544.90", "0"], ["84551.60", "4.875286"], ["84553.40", "0"], ["84560.10", "4.694720"], ["84561.90", "0"], ["84568.60", "4.333588"], ["84570.40", "0"], ["84577.10", "5.146136"], ["84578.90", "0"], ["84585.60", "4.062739"], ["84587.40", "0"], ["84594.10", "3.972456"], ["84595.90", "0"], ["84602.60", "5.055853"], ["84604.40", "0"], ["84611.10", "4.423871"], ["84612.90", "0"], ["84619.60", "5.597551"], ["84621.40", "0"], ["84628.10", "4.243305"], ["84629.90", "0"], ["84636.60", "3.882173"], ["84849.88", "0.000030"], ["84850.00", "0.000031"], ["84851.66", "0.000029"], ["84852.81", "0.000115"], ["84852.94", "0.000065"], ["84853.56", "0.000050"], ["84857.14", "0.000347"], ["84858.75", "0.000285"], ["84859.29", "0.000036"], ["84860.00", "0.000169"], ["84862.90", "0.000169"], ["84864.69", "0.000052"], ["84864.86", "0.000041"], ["84864.99", "0.000033"], ["84866.10", "0.000064"], ["84866.40", "0.000018"], ["84867.80", "0.000095"], ["84868.42", "0.000031"], ["84868.52", "0.000013"], ["84868.65", "0.000035"], ["84869.57", "0.000932"], ["84871.66", "0.000078"]], "bids": [["84376.00", "1.026069"], ["84373.31", "0.106035"], ["84369.08", "0.055181"], ["84369.04", "0.005546"], ["84368.40", "0.001043"], ["84367.56", "0.209200"], ["84366.40", "0.001007"], ["84364.40", "0.001248"], ["84363.43", "0"], ["84363.41", "0"], ["84363.39", "0"], ["84363.05", "0"], ["84362.42", "0"], ["84362.40", "0.003285"], ["84362.24", "0"], ["84361.70", "0"], ["84360.40", "0.008645"], ["84359.70", "0"], ["84359.17", "0"], ["84358.40", "0.022748"], ["84357.70", "0"], ["84356.54", "0.247727"], ["84356.40", "0.059865"], ["84355.97", "0.003016"], ["84355.71", "0"], ["84355.70", "0"], ["84355.33", "0.084345"], ["84354.40", "0.157539"], ["84353.94", "0.018240"], ["84353.70", "0"], ["84353.51", "0.142114"], ["84353.37", "0.005931"], ["84353.33", "0.015754"], ["84352.96", "0.056292"], ["84352.40", "0.414575"], ["84352.37", "0.006558"], ["84352.35", "0.007308"], ["84352.19", "0.007111"], ["84352.00", "0.017181"], ["84351.70", "0"], ["84351.10", "0.008978"], ["84350.73", "0.025056"], ["84350.67", "0.227422"], ["84350.61", "0.008156"], ["84350.40", "1.090988"], ["84350.29", "0.017313"], ["84349.70", "0"], ["84349.61", "0.008274"], ["84349.13", "0"], ["84349.11", "0"], ["84349.04", "0"], ["84348.69", "0.052050"], ["84348.60", "0.008142"], ["84348.40", "2.871022"], ["84348.20", "0.001027"], ["84348.10", "0.001026"], ["84348.00", "0.001045"], ["84347.97", "0.018499"], ["84347.70", "0"], ["84347.40", "1.540890"], ["84347.34", "0"], ["84347.30", "1.398750"], ["84347.23", "0"], ["84347.22", "0"], ["84347.17", "0"], ["84347.14", "0"], ["84347.12", "0"], ["84347.08", "0"], ["84347.07", "0"], ["84346.97", "0.271601"], ["84346.42", "0"], ["84346.28", "0.263039"], ["84346.06", "0.222486"], ["84345.80", "0.070020"], ["84345.72", "0.075929"], ["84345.71", "0.021085"], ["84345.70", "0.001027"], ["84345.44", "0"], ["84345.40", "5.877990"], ["84345.39", "0"], ["84345.23", "0"], ["84345.21", "0"], ["84345.18", "0"], ["84344.71", "0"], ["84344.01", "0"], ["84343.83", "0"], ["84343.80", "0.609600"], ["84343.70", "0"], ["84343.61", "0.012426"], ["84343.35", "0"], ["84342.57", "0"], ["84342.50", "0.087450"], ["84342.40", "2.857380"], ["84342.23", "0"], ["84342.21", "0"], ["84342.15", "0"], ["84341.93", "0"], ["84341.90", "0"], ["84341.88", "0"], ["84341.85", "0"], ["84341.80", "0.069780"], ["84341.70", "6.809760"], ["84341.60", "0"], ["84341.44", "0"], ["84341.23", "0"], ["84341.00", "0.142500"], ["84340.99", "0"], ["84340.95", "0"], ["84340.81", "0.056576"], ["84340.80", "0.385080"], ["84340.58", "0"], ["84340.10", "0.689940"], ["84340.03", "0"], ["84339.85", "0"], ["84339.84", "0"], ["84339.80", "0.069600"], ["84339.60", "0"], ["84339.49", "0"], ["84339.32", "0"], ["84339.31", "0"], ["84339.20", "0.109830"], ["84338.87", "0"], ["84338.70", "0"], ["84338.51", "0"], ["84338.20", "0"], ["84338.17", "0"], ["84337.80", "0.069600"], ["84337.28", "0"], ["84337.17", "0"], ["84337.12", "0"], ["84336.60", "0"], ["84336.18", "0"], ["84335.94", "0"], ["84335.80", "0.069600"], ["84335.30", "0.015090"], ["84335.26", "0"], ["84334.90", "0.916620"], ["84334.60", "0.283440"], ["84334.15", "0"], ["84334.00", "0"], ["84333.90", "0.177210"], ["84333.60", "0"], ["84333.54", "0"], ["84333.20", "0"], ["84331.40", "0"], ["84330.40", "0"], ["84329.93", "0"], ["84329.30", "0"], ["84329.10", "0"], ["84329.00", "0"], ["84328.60", "0"], ["84328.20", "0"], ["84328.10", "0"], ["84326.90", "0"], ["84326.50", "0"], ["84324.70", "0"], ["84324.30", "0"], ["84324.00", "0"], ["84323.32", "0"], ["84323.30", "0"], ["84323.00", "0"], ["84318.42", "0"], ["84318.38", "0"], ["84316.40", "0"], ["84306.20", "4.694720"], ["84299.50", "0"], ["84298.66", "0.072042"], ["84297.70", "4.153022"], ["84291.00", "0"], ["84289.20", "5.507268"], ["84282.50", "0"], ["84280.70", "5.326702"], ["84274.00", "0"], ["84272.20", "5.055853"], ["84265.50", "0"], ["84263.70", "4.965569"], ["84257.00", "0"], ["84255.20", "4.785003"], ["84248.50", "0"], ["84246.70", "4.333588"], ["84240.00", "0.002000"], ["84238.20", "5.236419"], ["84231.50", "0"], ["84229.70", "5.597551"], ["84223.00", "0"], ["84221.20", "4.243305"], ["84214.50", "0"], ["84212.70", "4.604437"], ["84206.00", "0"], ["84204.20", "5.416985"], ["84200.59", "0"], ["84197.50", "0"], ["84195.70", "5.146136"], ["84189.00", "0"], ["84187.20", "4.062739"], ["84180.50", "0"], ["84178.70", "4.875286"], ["84172.00", "0"], ["84170.20", "3.882173"], ["84163.50", "0"], ["84161.70", "4.514154"], ["84155.00", "0"], ["84153.20", "3.972456"], ["84146.50", "0"], ["84144.70", "4.423871"], ["84138.00", "0"], ["84093.58", "0"], ["83904.35", "0.000042"], ["83904.34", "0.000131"], ["83903.51", "0.000022"], ["83902.23", "0.000096"], ["83901.67", "0.000019"], ["83901.14", "0.000008"], ["83900.60", "0.000013"], ["83900.52", "0.000235"], ["83900.00", "0.002977"], ["83899.58", "0.000010"], ["83898.68", "0.000010"], ["83896.11", "0.000094"], ["83896.00", "0.000133"], ["83895.65", "0.000013"], ["83895.00", "0.006121"], ["83894.74", "0.000068"], ["83894.17", "0.000022"], ["83893.81", "0.000010"], ["83893.64", "0.000039"], ["83893.62", "0.000137"], ["83892.29", "0.000143"], ["83891.43", "0.000455"], ["83891.30", "0.000010"], ["83888.89", "0.000163"], ["83888.86", "0.000371"], ["83887.29", "0.000586"], ["83887.11", "0.000075"], ["83886.91", "0.000145"], ["83885.98", "0.000018"], ["83885.71", "0.000069"], ["83884.62", "0.000014"], ["83884.55", "0.000048"], ["83884.30", "0.000161"], ["83882.98", "0.000188"], ["83882.92", "0.002384"], ["83881.99", "0.000038"], ["83880.00", "0.020454"]], "checksum": -1045429034, "ts": "1742142251278"}], "ts": 1742142251284, "record_time": 1742142250.39311}
{"action": "update", "arg": {"instType": "SPOT", "channel": "books", "instId": "BTCUSDT"}, "data": [{"asks": [["84376.01", "0.287232"], ["84376.02", "0.000100"], ["84376.03", "0.000100"], ["84376.04", "0.000100"], ["84381.93", "0.009343"], ["84382.86", "0.008521"], ["84382.87", "0.007955"], ["84382.89", "0.005183"], ["84382.92", "0.004739"], ["84384.70", "0.139757"], ["84389.49", "0.024714"], ["84392.89", "0.209200"], ["84393.79", "0.014268"], ["84395.92", "0"], ["84396.17", "0.001205"], ["84398.85", "0.006356"], ["84399.00", "0.006356"], ["84401.30", "0.016428"], ["84401.54", "0.148098"], ["84403.44", "0.006357"], ["84403.89", "0.006356"], ["84406.98", "0.015892"], ["84410.30", "0.001807"], ["84416.90", "0.001300"], ["84418.06", "0.012680"], ["84418.90", "0.003650"], ["84420.90", "0.009606"], ["84422.90", "0.025277"], ["84423.63", "0"], ["84424.90", "0.066519"], ["84426.90", "0.175051"], ["84428.90", "0.460659"], ["84430.90", "1.212261"], ["84432.90", "3.190160"], ["84433.10", "0.301230"], ["84433.30", "0.004410"], ["84433.70", "0.001020"], ["84433.80", "0"], ["84434.20", "0"], ["84434.30", "0"], ["84434.60", "0"], ["84435.10", "0"], ["84435.60", "0.423570"], ["84436.10", "0.761250"], ["84436.90", "0"], ["84437.70", "0"], ["84438.20", "0"], ["84438.50", "1.555110"], ["84439.00", "0"], ["84439.20", "2.346420"], ["84441.00", "0.015090"], ["84441.30", "2.361780"], ["84441.70", "0"], ["84443.20", "0"], ["84443.70", "0"], ["84444.20", "0"], ["84444.60", "0.383880"], ["84445.50", "0"], ["84445.60", "0.026790"], ["84445.70", "0"], ["84446.40", "0"], ["84446.60", "0.464250"], ["84448.10", "0.013830"], ["84448.20", "0.021600"], ["84448.50", "0.117000"], ["84448.80", "3.463110"], ["84449.90", "0.009000"], ["84450.00", "3.694380"], ["84475.10", "4.423871"], ["84483.60", "4.875286"], ["84492.10", "4.153022"], ["84500.60", "5.507268"], ["84509.10", "3.882173"], ["84517.60", "4.785003"], ["84526.10", "5.055853"], ["84534.60", "5.416985"], ["84543.10", "4.965569"], ["84551.60", "5.326702"], ["84560.10", "5.146136"], ["84568.60", "4.062739"], ["84577.10", "4.243305"], ["84585.60", "3.972456"], ["84594.10", "5.236419"], ["84602.60", "4.514154"], ["84611.10", "4.694720"], ["84619.60", "4.333588"], ["84628.10", "5.597551"], ["84636.60", "4.604437"], ["84858.75", "0"], ["84859.29", "0"], ["84860.00", "0"], ["84862.90", "0"], ["84864.69", "0"], ["84864.86", "0"], ["84864.99", "0"], ["84866.10", "0"], ["84866.40", "0"], ["84867.80", "0"], ["84868.42", "0"], ["84868.52", "0"], ["84868.65", "0"], ["84869.57", "0"], ["84871.66", "0"]], "bids": [["84376.00", "2.957429"], ["84370.56", "0.139757"], ["84370.20", "0.006921"], ["84370.16", "0.017141"], ["84369.09", "0.081593"], ["84366.24", "0.003003"], ["84365.94", "0.008256"], ["84364.40", "0.001818"], ["84362.54", "2.546912"], ["84362.40", "0.004786"], ["84360.40", "0.012594"], ["84358.40", "0.033143"], ["84358.21", "0.003066"], ["84356.40", "0.087218"], ["84355.88", "0.008532"], ["84355.86", "0.001228"], ["84355.79", "0.000213"], ["84354.40", "0.229521"], ["84354.13", "0.017816"], ["84354.11", "0.007338"], ["84354.00", "0.006330"], ["84353.99", "0.016415"], ["84353.97", "0.005412"], ["84353.96", "0.000470"], ["84353.91", "0.006529"], ["84353.87", "0.008139"], ["84352.86", "0.016442"], ["84352.40", "0.604003"], ["84352.23", "0.007939"], ["84352.19", "0.014580"], ["84352.01", "0.007859"], ["84351.89", "0.002061"], ["84351.52", "0.028776"], ["84351.39", "0.017042"], ["84351.21", "0.007924"], ["84350.40", "1.589480"], ["84349.05", "0.012635"], ["84348.67", "0.005548"], ["84348.65", "0.005083"], ["84348.40", "4.182842"], ["84348.39", "0.002946"], ["84348.00", "0.248820"], ["84347.40", "0.143310"], ["84347.30", "0"], ["84346.88", "0.008667"], ["84346.69", "0.010227"], ["84346.40", "0.130470"], ["84345.80", "0"], ["84345.70", "0"], ["84345.40", "0"], ["84343.80", "0"], ["84343.60", "0.736980"], ["84343.30", "0.450030"], ["84343.00", "0.916800"], ["84342.80", "4.161270"], ["84342.40", "0"], ["84341.87", "0.073424"], ["84341.80", "0.069600"], ["84341.70", "2.161140"], ["84340.40", "0.015090"], ["84340.10", "0"], ["84339.90", "0.015180"], ["84339.80", "0.134670"], ["84339.20", "0"], ["84338.30", "0.159570"], ["84336.40", "0.025350"], ["84335.40", "0.099000"], ["84335.30", "0"], ["84334.90", "0"], ["84334.60", "0.765060"], ["84333.90", "0.597210"], ["84333.70", "0.015120"], ["84333.20", "1.350000"], ["84330.07", "0.008201"], ["84328.24", "0.020085"], ["84328.11", "0.017776"], ["84327.47", "0.016216"], ["84326.01", "0.018018"], ["84325.21", "0.007174"], ["84321.80", "0.207047"], ["84313.69", "0"], ["84297.70", "4.514154"], ["84289.20", "4.785003"], ["84280.70", "5.416985"], ["84263.70", "5.597551"], ["84255.20", "3.882173"], ["84246.70", "4.604437"], ["84238.20", "5.326702"], ["84229.70", "4.965569"], ["84221.20", "4.423871"], ["84212.70", "5.507268"], ["84204.20", "3.972456"], ["84195.70", "5.236419"], ["84187.20", "4.243305"], ["84170.20", "5.146136"], ["84161.70", "4.153022"], ["84153.20", "4.333588"], ["84144.70", "4.062739"], ["83904.85", "0"], ["83904.78", "0"], ["83904.35", "0"], ["83904.34", "0"], ["83903.51", "0"], ["83902.23", "0"], ["83901.67", "0"], ["83901.14", "0"], ["83900.60", "0"], ["83900.52", "0"], ["83900.00", "0"], ["83899.58", "0"], ["83898.68", "0"], ["83896.11", "0"], ["83896.00", "0"], ["83895.65", "0"], ["83895.00", "0"], ["83894.74", "0"], ["83894.17", "0"], ["83893.81", "0"], ["83893.64", "0"], ["83893.62", "0"], ["83892.29", "0"], ["83891.43", "0"], ["83891.30", "0"], ["83888.89", "0"], ["83888.86", "0"], ["83887.29", "0"], ["83887.11", "0"], ["83886.91", "0"], ["83885.98", "0"], ["83885.71", "0"], ["83884.62", "0"], ["83884.55", "0"], ["83884.30", "0"], ["83882.98", "0"], ["83882.92", "0"], ["83881.99", "0"], ["83880.00", "0"]], "checksum": 1561083507, "ts": "1742142251478"}], "ts": 1742142251483, "record_time": 1742142250.592725}
{"action": "update", "arg": {"instType": "SPOT", "channel": "books", "instId": "BTCUSDT"}, "data": [{"asks": [["84376.01", "0.223577"], ["84389.49", "0"], ["84392.89", "0"], ["84398.99", "0"], ["84401.54", "0"], ["84408.71", "0.148098"], ["84412.35", "0.017776"], ["84412.90", "0"], ["84413.10", "0.001015"], ["84414.90", "0"], ["84415.10", "0.001028"], ["84416.90", "0"], ["84417.10", "0.001020"], ["84417.27", "0"], ["84418.90", "0"], ["84419.10", "0.001008"], ["84420.21", "0"], ["84420.90", "0"], ["84421.10", "0.001026"], ["84422.90", "0"], ["84423.10", "0.001492"], ["84424.90", "0"], ["84425.10", "0.003926"], ["84426.90", "0"], ["84427.10", "0.010334"], ["84428.90", "0"], ["84429.10", "0.027194"], ["84430.90", "0"], ["84431.10", "0.071564"], ["84432.90", "0"], ["84433.10", "0.188455"], ["84433.30", "0.002490"], ["84434.20", "0.001005"], ["84435.00", "0.001017"], ["84436.10", "0"], ["84438.50", "1.170240"], ["84439.20", "0"], ["84441.30", "0.189150"], ["84444.10", "0.032790"], ["84445.60", "0"], ["84446.60", "0.708630"], ["84448.50", "0"], ["84450.00", "7.249560"], ["84450.10", "0.248880"], ["84475.10", "0"], ["84475.30", "4.694708"], ["84483.60", "0"], ["84483.80", "4.604425"], ["84492.10", "0"], ["84492.30", "5.326688"], ["84500.60", "0"], ["84500.80", "4.784991"], ["84509.10", "0"], ["84509.30", "5.416971"], ["84517.60", "0"], ["84517.80", "4.965557"], ["84526.10", "0"], ["84526.30", "4.423860"], ["84527.06", "0.209200"], ["84534.60", "0"], ["84534.80", "4.333577"], ["84543.10", "0"], ["84543.30", "5.507254"], ["84551.60", "0"], ["84551.80", "5.055839"], ["84560.10", "0"], ["84560.30", "4.243294"], ["84568.60", "0"], ["84568.80", "4.153011"], ["84577.10", "0"], ["84577.30", "5.597536"], ["84585.60", "0"], ["84585.80", "5.146122"], ["84594.10", "0"], ["84594.30", "4.062728"], ["84602.60", "0"], ["84602.80", "3.972445"], ["84611.10", "0"], ["84611.30", "3.882162"], ["84619.60", "0"], ["84619.80", "4.514142"], ["84628.10", "0"], ["84628.30", "4.875274"], ["84636.60", "0"], ["84636.80", "5.236405"], ["84858.75", "0.000285"], ["84859.29", "0.000036"], ["84860.00", "0.000169"], ["84862.90", "0.000169"]], "bids": [["84376.00", "2.958014"], ["84375.23", "0.139755"], ["84373.30", "0"], ["84370.56", "0"], ["84369.08", "0"], ["84368.60", "0.001005"], ["84368.40", "0"], ["84366.60", "0.001026"], ["84366.40", "0"], ["84364.60", "0.002668"], ["84364.40", "0"], ["84363.59", "0.768714"], ["84362.60", "0.007023"], ["84362.40", "0"], ["84360.60", "0.018482"], ["84360.40", "0"], ["84358.60", "0.048635"], ["84358.40", "0"], ["84358.04", "0.003033"], ["84357.97", "0.003057"], ["84356.60", "0.127988"], ["84356.40", "0"], ["84354.60", "0.336809"], ["84354.40", "0"], ["84353.93", "0.008549"], ["84352.60", "0.886341"], ["84352.40", "0"], ["84350.60", "2.332475"], ["84350.40", "0"], ["84348.66", "0.004933"], ["84348.61", "0.009627"], ["84348.60", "6.138093"], ["84348.40", "7.421130"], ["84348.00", "0.000121"], ["84347.40", "0.142680"], ["84346.70", "0.035520"], ["84343.80", "0.069780"], ["84343.30", "0.178110"], ["84343.00", "2.281530"], ["84342.80", "0"], ["84342.50", "0"], ["84341.80", "0.069780"], ["84341.70", "1.385550"], ["84340.80", "0"], ["84339.44", "0.018018"], ["84339.10", "0.090000"], ["84338.30", "0.082800"], ["84338.20", "0.090000"], ["84337.30", "0.038520"], ["84337.20", "0.090000"], ["84335.80", "0.105150"], ["84335.20", "0.090000"], ["84334.90", "0.090000"], ["84334.60", "2.026020"], ["84333.20", "1.440000"], ["84333.00", "0.090000"], ["84328.24", "0"], ["84326.01", "0"], ["84325.24", "0.007576"], ["84306.59", "0"], ["84306.40", "4.784991"], ["84306.20", "0"], ["84305.65", "0"], ["84297.90", "5.236405"], ["84297.70", "0"], ["84289.40", "4.243294"], ["84289.20", "0"], ["84280.90", "3.972445"], ["84280.70", "0"], ["84272.40", "4.604425"], ["84272.20", "0"], ["84263.90", "4.694708"], ["84263.70", "0"], ["84255.40", "4.333577"], ["84255.20", "0"], ["84246.90", "4.514142"], ["84246.70", "0"], ["84238.40", "4.875274"], ["84238.20", "0"], ["84229.90", "5.055839"], ["84229.70", "0"], ["84221.40", "3.882162"], ["84221.20", "0"], ["84212.90", "5.146122"], ["84212.70", "0"], ["84204.40", "5.326688"], ["84204.20", "0"], ["84195.90", "4.153011"], ["84195.70", "0"], ["84187.40", "5.416971"], ["84187.20", "0"], ["84182.32", "0.173436"], ["84178.90", "4.965557"], ["84178.70", "0"], ["84170.40", "5.597536"], ["84170.20", "0"], ["84161.90", "4.423860"], ["84161.70", "0"], ["84153.40", "4.062728"], ["84153.20", "0"], ["84144.90", "5.507254"], ["84144.70", "0"], ["83909.09", "0"], ["83909.08", "0"], ["83908.59", "0"], ["83908.26", "0"], ["83908.04", "0"], ["83907.22", "0"], ["83906.25", "0"], ["83905.95", "0"]], "checksum": -21052943, "ts": "1742142251679"}], "ts": 1742142251688, "record_time": 1742142250.796784}
