{"action": "update", "arg": {"instType": "SPOT", "channel": "books", "instId": "BTCUSDT"}, "data": [{"asks": [["84284.97", "0"], ["84288.97", "0"], ["84293.24", "0"], ["84293.79", "0"], ["84295.58", "0"], ["84296.72", "0"], ["84297.18", "0"], ["84298.40", "0"], ["84298.85", "0"], ["84301.10", "0.001311"], ["84301.22", "0"], ["84303.10", "0.003452"], ["84303.57", "0"], ["84304.07", "0"], ["84305.10", "0.009084"], ["84305.83", "0"], ["84307.10", "0.023903"], ["84309.10", "0.062904"], ["84311.10", "0.165536"], ["84313.10", "0.435623"], ["84315.10", "1.146376"], ["84317.10", "3.017025"], ["84319.10", "7.939540"], ["84319.60", "0"], ["84320.70", "0.248670"], ["84322.70", "0.469260"], ["84324.30", "0.407340"], ["84334.20", "0.069600"], ["84361.20", "5.333893"], ["84369.70", "4.068224"], ["84378.20", "4.429844"], ["84386.70", "3.977819"], ["84395.20", "5.243488"], ["84403.70", "4.158629"], ["84412.20", "5.514703"], ["84420.70", "5.153083"], ["84429.20", "4.520249"], ["84437.70", "4.972273"], ["84454.70", "5.062678"], ["84463.20", "3.887414"], ["84471.70", "5.605108"], ["84480.20", "4.339439"], ["84488.70", "5.424298"], ["84497.20", "4.249034"], ["84505.70", "4.701058"], ["84514.20", "4.610654"], ["84522.70", "4.791463"], ["84866.10", "0.000064"], ["84866.40", "0.000018"], ["84867.80", "0.000095"], ["84868.42", "0.000031"], ["84868.52", "0.000013"], ["84868.65", "0.000035"], ["84869.57", "0.000932"], ["84871.66", "0.000078"], ["84871.79", "0.000014"], ["84873.84", "0.000057"], ["84874.79", "0.000096"], ["84875.00", "0.000959"], ["84875.78", "0.000038"]], "bids": [["84274.13", "0.000100"], ["84264.72", "0"], ["84263.51", "0"], ["84262.87", "0"], ["84262.07", "0"], ["84256.50", "0"], ["84252.67", "0"], ["84248.70", "0.001422"], ["84247.86", "0"], ["84246.70", "0.003741"], ["84244.70", "0.009846"], ["84243.53", "0"], ["84242.70", "0.025909"], ["84242.38", "0"], ["84241.15", "0"], ["84240.81", "0"], ["84240.70", "0.068181"], ["84238.70", "0.179425"], ["84238.41", "0"], ["84237.73", "0"], ["84237.67", "0"], ["84236.85", "0"], ["84236.70", "0.472171"], ["84235.67", "0"], ["84235.66", "0"], ["84234.70", "1.242554"], ["84234.47", "0"], ["84234.20", "0.001770"], ["84234.10", "0.402090"], ["84233.29", "0"], ["84233.20", "0"], ["84233.00", "0"], ["84232.60", "0.001620"], ["84232.50", "1.065840"], ["84229.00", "0.440970"], ["84228.40", "0.383670"], ["84227.10", "0"], ["84226.30", "0"], ["84225.80", "0.172500"], ["84225.00", "0.460890"], ["84223.30", "0.048210"], ["84222.10", "0.013140"], ["84220.70", "1.170330"], ["84220.50", "2.349960"], ["84220.40", "0.180000"], ["84219.60", "0.090000"], ["84207.20", "0"], ["84192.60", "4.068224"], ["84184.10", "5.243488"], ["84175.60", "3.977819"], ["84167.10", "4.972273"], ["84167.00", "0"], ["84158.60", "4.881868"], ["84150.10", "5.605108"], ["84141.60", "4.791463"], ["84133.10", "4.249034"], ["84124.60", "5.514703"], ["84116.10", "4.158629"], ["84107.60", "5.333893"], ["84099.10", "4.520249"], ["84090.60", "4.701058"], ["84082.10", "4.339439"], ["84073.60", "4.610654"], ["84065.10", "3.887414"], ["84056.60", "4.429844"], ["84048.10", "5.153083"], ["84039.60", "5.424298"], ["84031.10", "5.062678"], ["83895.65", "0.000013"], ["83895.00", "0.006121"], ["83894.74", "0.000068"], ["83894.17", "0.000022"], ["83893.81", "0.000010"], ["83893.64", "0.000039"], ["83893.62", "0.000137"], ["83892.29", "0.000143"], ["83891.43", "0.000455"], ["83891.30", "0.000010"], ["83888.89", "0.000163"], ["83888.86", "0.000371"], ["83887.29", "0.000586"], ["83887.11", "0.000075"], ["83886.91", "0.000145"], ["83885.98", "0.000018"], ["83885.71", "0.000069"], ["83884.62", "0.000014"], ["83884.55", "0.000048"], ["83884.30", "0.000161"]], "checksum": 437711588, "ts": "1742142225470"}], "ts": 1742142225477, "record_time": 1742142224.588923}
{"action": "update", "arg": {"instType": "SPOT", "channel": "books", "instId": "BTCUSDT"}, "data": [{"asks": [["84254.34", "0.529711"], ["84255.29", "0.004595"], ["84255.38", "0.005541"], ["84255.40", "0.308533"], ["84256.21", "0.007385"], ["84256.25", "0.000443"], ["84258.01", "0.209200"], ["84262.22", "0.047711"], ["84264.17", "0.079782"], ["84266.08", "0.017806"], ["84269.92", "0.203170"], ["84271.08", "0.001205"], ["84271.83", "1.895407"], ["84274.13", "1.188441"], ["84274.14", "0.219918"], ["84274.67", "0"], ["84274.69", "0"], ["84275.09", "0.119869"], ["84275.23", "0"], ["84276.17", "0.006356"], ["84276.29", "0.006356"], ["84276.57", "0.006356"], ["84277.05", "0.006356"], ["84277.35", "0.006356"], ["84277.46", "0.010985"], ["84277.64", "0.006356"], ["84277.75", "0.035952"], ["84277.79", "0.006356"], ["84278.17", "0.006356"], ["84278.56", "0.313257"], ["84279.23", "0.006356"], ["84279.27", "0.006356"], ["84279.39", "0.006356"], ["84279.42", "0.006356"], ["84279.56", "0.006356"], ["84280.34", "0.006356"], ["84280.36", "0.119843"], ["84280.66", "0.006357"], ["84281.02", "0.016428"], ["84281.74", "0.009989"], ["84282.77", "0"], ["84283.06", "0"], ["84284.00", "0.010984"], ["84285.05", "0"], ["84285.09", "0"], ["84285.10", "0.001182"], ["84285.15", "0"], ["84285.63", "0"], ["84286.12", "0"], ["84286.26", "0"], ["84286.41", "0"], ["84286.44", "0.119881"], ["84286.48", "0.015892"], ["84286.59", "0"], ["84286.85", "0"], ["84286.93", "0.009989"], ["84287.10", "0.001928"], ["84287.12", "0"], ["84287.24", "0.053755"], ["84287.25", "0"], ["84287.27", "0"], ["84288.16", "0"], ["84288.24", "0"], ["84288.31", "0"], ["84288.69", "2.228683"], ["84288.78", "0"], ["84288.96", "0"], ["84289.10", "0.005073"], ["84289.26", "0"], ["84289.34", "0.006356"], ["84289.89", "0.029802"], ["84290.26", "0"], ["84290.51", "0"], ["84291.10", "0.013352"], ["84291.34", "0"], ["84291.72", "0.010986"], ["84291.94", "0.015891"], ["84293.10", "0.035136"], ["84293.46", "0.026414"], ["84295.10", "0.092463"], ["84295.46", "0"], ["84295.47", "0"], ["84296.01", "0"], ["84297.10", "0.243323"], ["84297.58", "0"], ["84298.80", "0"], ["84299.10", "0.640324"], ["84301.10", "1.685064"], ["84302.59", "0"], ["84303.10", "4.434378"], ["84305.10", "11.669417"], ["84305.82", "0"], ["84306.00", "0.258210"], ["84306.20", "0.069780"], ["84307.10", "0"], ["84307.40", "0.052830"], ["84307.80", "0.550620"], ["84308.20", "0.069780"], ["84308.50", "2.184900"], ["84308.70", "1.350180"], ["84309.00", "0.062970"], ["84309.10", "0"], ["84309.16", "0"], ["84310.20", "0.212280"], ["84310.30", "0.469260"], ["84310.80", "4.569360"], ["84310.87", "0.001597"], ["84311.10", "0"], ["84312.20", "0.069600"], ["84313.00", "0.410370"], ["84313.10", "0"], ["84313.60", "0.725010"], ["84314.20", "0.069600"], ["84314.90", "1.779300"], ["84315.00", "0.529980"], ["84315.10", "0"], ["84316.00", "0.015090"], ["84316.20", "0.069600"], ["84316.60", "0.142500"], ["84316.90", "0.291750"], ["84317.10", "0.985470"], ["84317.20", "1.350000"], ["84318.20", "0.069600"], ["84319.00", "1.753530"], ["84319.10", "1.321950"], ["84320.00", "1.779300"], ["84320.10", "0.070950"], ["84320.20", "0.069600"], ["84320.50", "0.015180"], ["84320.60", "3.694380"], ["84320.70", "0"], ["84322.30", "0"], ["84322.70", "0"], ["84323.00", "0"], ["84324.30", "0"], ["84325.40", "0"], ["84325.80", "0"], ["84326.85", "0"], ["84327.40", "0"], ["84328.14", "0"], ["84328.40", "0"], ["84328.50", "0"], ["84328.80", "0"], ["84329.40", "0"], ["84329.70", "0"], ["84330.10", "0"], ["84330.20", "0"], ["84330.70", "0"], ["84331.60", "0"], ["84331.70", "0"], ["84332.20", "0"], ["84332.30", "0"], ["84332.90", "0"], ["84333.60", "0"], ["84334.20", "0"], ["84343.70", "0.072042"], ["84345.76", "0.072042"], ["84347.20", "4.792259"], ["84355.70", "5.606039"], ["84361.20", "0"], ["84364.20", "4.973099"], ["84369.70", "0"], ["84372.70", "4.520999"], ["84378.20", "0"], ["84379.96", "0"], ["84380.39", "0"], ["84381.20", "3.888059"], ["84386.70", "0"], ["84389.70", "4.249737"], ["84395.20", "0"], ["84398.20", "4.882679"], ["84403.70", "0"], ["84406.70", "5.153939"], ["84412.20", "0"], ["84415.20", "4.701839"], ["84417.41", "0"], ["84420.70", "0"], ["84423.70", "4.068899"], ["84429.20", "0"], ["84432.20", "5.334779"], ["84437.70", "0"], ["84440.70", "4.159319"], ["84446.20", "0"], ["84449.20", "5.244359"], ["84454.70", "0"], ["84457.70", "4.340157"], ["84463.20", "0"], ["84466.20", "3.978479"], ["84471.70", "0"], ["84474.70", "4.430576"], ["84480.20", "0"], ["84483.20", "4.611419"], ["84488.70", "0"], ["84491.70", "5.063519"], ["84497.20", "0"], ["84500.20", "5.425199"], ["84505.70", "0"], ["84508.70", "5.515619"], ["84514.20", "0"], ["84522.70", "0"], ["84859.29", "0"], ["84860.00", "0"], ["84862.90", "0"], ["84864.69", "0"], ["84864.86", "0"], ["84864.99", "0"], ["84866.10", "0"], ["84866.40", "0"], ["84867.80", "0"], ["84868.42", "0"], ["84868.52", "0"], ["84868.65", "0"], ["84869.57", "0"], ["84871.66", "0"], ["84871.79", "0"], ["84873.84", "0"], ["84874.79", "0"], ["84875.00", "0"], ["84875.78", "0"]], "bids": [["84274.13", "0"], ["84274.12", "0"], ["84274.11", "0"], ["84274.10", "0"], ["84265.31", "0"], ["84262.06", "0"], ["84255.39", "0"], ["84254.70", "0"], ["84254.33", "0.010000"], ["84253.75", "0"], ["84253.61", "0"], ["84252.70", "0"], ["84252.68", "0"], ["84252.12", "0"], ["84251.65", "0"], ["84250.70", "0"], ["84248.70", "0"], ["84247.87", "0"], ["84247.83", "0"], ["84246.70", "0"], ["84244.93", "0"], ["84244.88", "0"], ["84244.70", "0"], ["84244.26", "0"], ["84243.58", "0"], ["84243.55", "0"], ["84243.54", "0"], ["84243.50", "0"], ["84242.70", "0"], ["84241.85", "0"], ["84241.81", "0"], ["84241.78", "0"], ["84241.77", "0"], ["84241.75", "0"], ["84241.72", "0"], ["84241.71", "0"], ["84241.66", "0"], ["84241.64", "0"], ["84240.98", "0"], ["84240.70", "0.001007"], ["84240.43", "0"], ["84240.26", "0"], ["84240.03", "0"], ["84239.97", "0"], ["84239.58", "0"], ["84239.51", "0"], ["84239.42", "0"], ["84239.41", "0"], ["84239.38", "2.550600"], ["84239.29", "0"], ["84238.73", "0"], ["84238.70", "0.001040"], ["84238.43", "0"], ["84238.15", "0"], ["84238.04", "0"], ["84237.52", "0"], ["84237.51", "0"], ["84237.41", "0"], ["84237.29", "0"], ["84237.20", "0"], ["84236.91", "0"], ["84236.70", "0.001024"], ["84236.54", "0"], ["84236.49", "0"], ["84236.47", "0"], ["84236.42", "0"], ["84236.39", "0"], ["84236.35", "0"], ["84236.34", "0"], ["84236.32", "0"], ["84235.49", "0"], ["84235.02", "0"], ["84234.79", "0.313257"], ["84234.71", "0"], ["84234.70", "0.001008"], ["84234.66", "0"], ["84234.50", "0"], ["84234.35", "0"], ["84234.20", "0"], ["84234.10", "0"], ["84234.05", "0"], ["84233.94", "0.084447"], ["84233.81", "0.248027"], ["84232.80", "0"], ["84232.70", "0.001010"], ["84232.60", "0"], ["84232.50", "0"], ["84231.52", "0.017837"], ["84231.50", "0.016462"], ["84231.31", "0.028810"], ["84230.70", "0.001020"], ["84230.62", "0.005938"], ["84230.60", "0"], ["84230.23", "0.015773"], ["84230.02", "0.008538"], ["84230.01", "0.007515"], ["84229.67", "0.006565"], ["84229.62", "0.007934"], ["84229.61", "0.056360"], ["84229.52", "0.007317"], ["84229.38", "0.017063"], ["84229.28", "0.017080"], ["84229.23", "0.052113"], ["84229.22", "0.018262"], ["84229.09", "0.007120"], ["84229.00", "0"], ["84228.97", "0.227697"], ["84228.70", "0.001043"], ["84228.68", "0.007346"], ["84228.62", "0.008988"], ["84228.58", "0.006535"], ["84228.54", "0.008989"], ["84228.52", "0.006213"], ["84228.51", "0.007442"], ["84228.41", "0.001199"], ["84228.40", "0"], ["84228.20", "0"], ["84228.00", "0"], ["84227.83", "0.008165"], ["84227.66", "0.017334"], ["84227.25", "0.007871"], ["84227.17", "0.002062"], ["84226.90", "0.008284"], ["84226.70", "0.001001"], ["84226.40", "0"], ["84225.95", "0.007475"], ["84225.80", "0"], ["84225.78", "0.263357"], ["84225.42", "0.021111"], ["84225.31", "0.076021"], ["84225.29", "0.018522"], ["84225.00", "0"], ["84224.70", "0.001043"], ["84224.40", "0"], ["84224.10", "0"], ["84223.90", "0"], ["84223.79", "0.012441"], ["84223.70", "0"], ["84223.60", "0"], ["84223.40", "0"], ["84223.30", "0"], ["84223.20", "0"], ["84223.10", "0"], ["84222.92", "0.005554"], ["84222.89", "0.005089"], ["84222.85", "0.073513"], ["84222.70", "0.001002"], ["84222.42", "0"], ["84222.10", "0"], ["84221.50", "0.008674"], ["84221.30", "0"], ["84220.94", "0.056645"], ["84220.70", "0.001021"], ["84220.50", "0"], ["84220.40", "0"], ["84220.10", "0.001045"], ["84219.60", "0"], ["84218.80", "0.001012"], ["84218.20", "0.001014"], ["84218.10", "0.023742"], ["84218.00", "0.001050"], ["84217.78", "0"], ["84217.57", "0"], ["84217.20", "0.001028"], ["84215.40", "0.023941"], ["84214.90", "0.274770"], ["84214.50", "0.915540"], ["84213.90", "0.126750"], ["84213.15", "0"], ["84213.09", "0"], ["84212.50", "0.284430"], ["84212.41", "0"], ["84212.30", "0.009000"], ["84212.00", "0.021600"], ["84211.20", "0.383430"], ["84210.71", "0"], ["84210.50", "1.334880"], ["84210.00", "0.090180"], ["84209.40", "0.009000"], ["84208.60", "0.462600"], ["84208.10", "1.105260"], ["84207.90", "2.669430"], ["84207.80", "0.035610"], ["84207.00", "0.013860"], ["84206.60", "0.142500"], ["84205.80", "0.987180"], ["84205.50", "0.071310"], ["84204.80", "0.177180"], ["84204.40", "0.090000"], ["84204.20", "0.090000"], ["84203.80", "0.097260"], ["84203.40", "0.090000"], ["84200.33", "0.001189"], ["84196.60", "0.017804"], ["84194.30", "0.207047"], ["84192.60", "0"], ["84184.10", "0"], ["84178.60", "5.244359"], ["84175.60", "0"], ["84170.10", "5.063519"], ["84167.10", "0"], ["84161.60", "3.978479"], ["84158.60", "0"], ["84153.10", "5.425196"], ["84150.10", "0"], ["84144.60", "4.792259"], ["84141.60", "0"], ["84136.10", "5.334779"], ["84133.10", "0"], ["84127.60", "4.973099"], ["84124.60", "0"], ["84119.10", "5.606039"], ["84116.10", "0"], ["84110.60", "4.520999"], ["84107.60", "0"], ["84102.10", "4.701839"], ["84099.10", "0"], ["84093.60", "4.159319"], ["84090.60", "0"], ["84085.10", "4.249739"], ["84082.10", "0"], ["84076.60", "4.068899"], ["84073.60", "0"], ["84068.10", "4.882679"], ["84065.10", "0"], ["84059.60", "4.611419"], ["84056.60", "0"], ["84051.10", "3.888059"], ["84048.10", "0"], ["84042.60", "4.430579"], ["84039.60", "0"], ["84034.10", "4.340159"], ["84031.10", "0"], ["84026.10", "0.209200"], ["84025.60", "5.515619"], ["84017.10", "5.153939"], ["83950.23", "0.209200"], ["83882.98", "0.000188"], ["83882.92", "0.002384"], ["83881.99", "0.000038"], ["83880.00", "0.020454"], ["83877.97", "0.000023"], ["83877.55", "0.000010"], ["83877.42", "0.000054"], ["83877.29", "0.000024"], ["83877.05", "0.000008"], ["83876.25", "0.000028"], ["83876.12", "0.000681"], ["83875.99", "0.000299"], ["83875.49", "0.000723"], ["83875.16", "0.000179"], ["83875.00", "0.000145"], ["83874.55", "0.000145"], ["83874.15", "0.000150"], ["83873.87", "0.000041"], ["83873.52", "0.000135"], ["83870.97", "0.000194"], ["83870.95", "0.000078"], ["83870.78", "0.000019"]], "checksum": -1752325260, "ts": "1742142225675"}], "ts": 1742142225680, "record_time": 1742142224.789469}
{"action": "update", "arg": {"instType": "SPOT", "channel": "books", "instId": "BTCUSDT"}, "data": [{"asks": [["84247.04", "1.133800"], ["84247.05", "0.209200"], ["84247.14", "0.030015"], ["84247.24", "0.006307"], ["84250.12", "0.203170"], ["84250.43", "0.004595"], ["84250.46", "0.001230"], ["84250.49", "0.005541"], ["84251.21", "0.010074"], ["84251.26", "0.005219"], ["84251.29", "0.007955"], ["84251.30", "0.007385"], ["84251.32", "0.019315"], ["84251.36", "0.001066"], ["84251.39", "0.004739"], ["84252.09", "0.005183"], ["84252.10", "0.000078"], ["84252.14", "0.007359"], ["84254.33", "0.256862"], ["84254.34", "0.353415"], ["84255.29", "0"], ["84255.38", "0.011836"], ["84255.40", "0.273033"], ["84256.21", "0"], ["84256.25", "0"], ["84256.34", "0.002907"], ["84256.85", "0.003017"], ["84258.00", "0.062760"], ["84258.01", "0"], ["84259.00", "0.080082"], ["84261.33", "0.001205"], ["84262.17", "0.006620"], ["84262.21", "0.038248"], ["84263.83", "0.209200"], ["84264.17", "0"], ["84265.60", "0.006356"], ["84266.45", "0.006356"], ["84266.75", "0.119869"], ["84267.50", "0.016428"], ["84267.96", "0.006356"], ["84268.06", "0.035952"], ["84268.29", "0.006356"], ["84268.42", "0.006356"], ["84269.03", "0.006356"], ["84269.14", "0.017341"], ["84269.31", "0.006356"], ["84269.46", "0.006356"], ["84269.92", "0"], ["84270.68", "0.006356"], ["84270.90", "0.006356"], ["84271.07", "0.006356"], ["84271.08", "0"], ["84271.27", "0.006356"], ["84271.83", "0"], ["84272.04", "0.119843"], ["84272.33", "0.006357"], ["84272.73", "0.006356"], ["84273.39", "0.010984"], ["84273.42", "0.009989"], ["84274.13", "0.256700"], ["84274.14", "0.054595"], ["84275.09", "0"], ["84275.64", "0.006356"], ["84275.65", "0.119895"], ["84275.68", "0.015892"], ["84276.17", "0"], ["84276.29", "0"], ["84276.57", "0"], ["84276.89", "0.239760"], ["84276.94", "0.001807"], ["84277.05", "0"], ["84277.35", "0"], ["84277.43", "0"], ["84277.44", "0.009989"], ["84277.46", "0"], ["84277.64", "0"], ["84277.75", "0"], ["84277.79", "0"], ["84278.17", "0"], ["84278.24", "0.015891"], ["84278.92", "0"], ["84279.23", "0"], ["84279.27", "0"], ["84279.39", "0"], ["84279.42", "0"], ["84279.56", "0"], ["84279.80", "0.001005"], ["84280.34", "0"], ["84280.36", "0"], ["84280.66", "0.010986"], ["84281.02", "0"], ["84281.74", "0"], ["84281.80", "0.001231"], ["84282.08", "0"], ["84282.41", "0"], ["84283.80", "0.003239"], ["84284.00", "0"], ["84285.10", "0"], ["84285.80", "0.008524"], ["84286.44", "0"], ["84286.48", "0"], ["84286.93", "0"], ["84287.10", "0"], ["84287.80", "0.022431"], ["84288.41", "0"], ["84288.69", "0"], ["84289.10", "0"], ["84289.34", "0"], ["84289.80", "0.059030"], ["84291.10", "0"], ["84291.72", "0"], ["84291.80", "0.155341"], ["84291.94", "0"], ["84293.10", "0"], ["84293.80", "0.408791"], ["84295.10", "0"], ["84295.80", "1.075768"], ["84297.10", "0"], ["84297.80", "2.830967"], ["84299.10", "0"], ["84299.80", "7.449914"], ["84300.20", "15.577500"], ["84301.00", "0.406020"], ["84301.10", "0"], ["84301.20", "0.163080"], ["84302.20", "0.069780"], ["84302.40", "5.015460"], ["84303.10", "0"], ["84303.30", "1.079220"], ["84303.80", "0.142680"], ["84303.82", "0.001597"], ["84305.10", "0"], ["84305.40", "0.985650"], ["84305.70", "1.608000"], ["84306.00", "0"], ["84306.20", "0.069600"], ["84307.40", "0"], ["84307.80", "0"], ["84308.20", "0.069600"], ["84308.50", "1.506810"], ["84308.70", "1.350000"], ["84309.50", "1.779300"], ["84310.20", "0.212100"], ["84310.30", "0.157980"], ["84310.50", "0.015120"], ["84310.80", "0"], ["84310.90", "0.015090"], ["84312.60", "0.015210"], ["84313.60", "0"], ["84314.80", "1.390320"], ["84315.00", "0.025350"], ["84316.00", "0"], ["84317.10", "0"], ["84317.20", "0"], ["84318.20", "0"], ["84319.00", "0"], ["84319.10", "0"], ["84320.00", "0"], ["84320.10", "0"], ["84320.20", "0"], ["84320.50", "0"], ["84320.60", "0"], ["84341.90", "3.888303"], ["84347.20", "0"], ["84350.40", "5.154262"], ["84355.70", "0"], ["84358.90", "4.792560"], ["84364.20", "0"], ["84367.40", "5.425539"], ["84372.70", "0"], ["84375.90", "4.702134"], ["84381.20", "0"], ["84384.40", "4.430857"], ["84389.70", "0"], ["84392.90", "4.521283"], ["84398.20", "0"], ["84400.55", "0"], ["84401.40", "5.063837"], ["84406.70", "0"], ["84408.98", "0"], ["84409.90", "5.515965"], ["84415.20", "0"], ["84418.40", "4.250006"], ["84423.70", "0"], ["84426.90", "4.340432"], ["84432.20", "0"], ["84435.40", "4.159580"], ["84440.70", "0"], ["84443.90", "4.882985"], ["84449.20", "0"], ["84452.40", "3.978729"], ["84457.70", "0"], ["84460.90", "4.973411"], ["84466.20", "0"], ["84469.40", "5.244688"], ["84474.70", "0"], ["84477.90", "4.611709"], ["84483.20", "0"], ["84486.40", "4.069155"], ["84491.70", "0"], ["84494.90", "5.606391"], ["84500.20", "0"], ["84503.40", "5.335114"], ["84508.70", "0"], ["84846.85", "0"], ["84847.58", "0"], ["84847.82", "0"], ["84849.88", "0"], ["84850.00", "0"], ["84851.66", "0"], ["84852.81", "0"], ["84852.94", "0"], ["84853.56", "0"], ["84857.14", "0"], ["84858.75", "0"]], "bids": [["84254.33", "0"], ["84243.43", "1.895673"], ["84242.28", "0.486400"], ["84242.27", "0.599900"], ["84240.71", "0.000164"], ["84240.70", "0"], ["84239.39", "0.353132"], ["84239.38", "0"], ["84238.70", "0"], ["84238.42", "0"], ["84236.70", "0"], ["84235.40", "0.001010"], ["84234.80", "0.213257"], ["84234.70", "0"], ["84233.94", "0"], ["84233.81", "0"], ["84233.40", "0.001040"], ["84233.02", "0.012680"], ["84232.70", "0"], ["84231.52", "0"], ["84231.50", "0"], ["84231.40", "0.001033"], ["84231.31", "0"], ["84230.85", "0.224605"], ["84230.70", "0"], ["84230.62", "0"], ["84230.23", "0"], ["84230.02", "0"], ["84230.01", "0"], ["84229.67", "0"], ["84229.62", "0"], ["84229.61", "0"], ["84229.52", "0"], ["84229.40", "0.001044"], ["84229.38", "0"], ["84229.28", "0"], ["84229.23", "0"], ["84229.22", "0"], ["84229.09", "0"], ["84228.97", "0"], ["84228.70", "0"], ["84228.68", "0"], ["84228.62", "0"], ["84228.58", "0"], ["84228.54", "0"], ["84228.52", "0"], ["84228.51", "0"], ["84228.41", "0"], ["84227.83", "0"], ["84227.66", "0"], ["84227.40", "0.001018"], ["84227.25", "0"], ["84227.17", "0"], ["84226.90", "0"], ["84226.70", "0"], ["84226.58", "2.550948"], ["84225.95", "0"], ["84225.78", "0"], ["84225.47", "0.248085"], ["84225.42", "0"], ["84225.40", "0.001047"], ["84225.31", "0"], ["84225.29", "0"], ["84225.12", "0.007515"], ["84224.70", "0"], ["84224.25", "0.084467"], ["84223.86", "0.007346"], ["84223.79", "0"], ["84223.76", "0.008988"], ["84223.70", "0.006213"], ["84223.68", "0.007442"], ["84223.65", "0.007734"], ["84223.40", "0.001045"], ["84223.39", "0.008147"], ["84223.26", "0.008556"], ["84222.92", "0"], ["84222.89", "0"], ["84222.85", "0"], ["84222.70", "0"], ["84222.66", "0.025087"], ["84222.32", "0.007871"], ["84222.30", "0.005940"], ["84222.28", "0.002062"], ["84221.80", "0.017841"], ["84221.75", "0.016466"], ["84221.51", "0.018267"], ["84221.50", "0"], ["84221.40", "0.001027"], ["84221.34", "0.006567"], ["84221.23", "0.017067"], ["84221.20", "0.007319"], ["84221.19", "0.056373"], ["84221.03", "0.007475"], ["84221.00", "0.008167"], ["84220.96", "0.017084"], ["84220.94", "0"], ["84220.77", "0.007122"], ["84220.70", "0"], ["84220.65", "0.227750"], ["84220.10", "0"], ["84219.97", "0.007936"], ["84219.40", "0.001040"], ["84219.38", "0.012650"], ["84219.34", "0.017338"], ["84219.26", "0.015776"], ["84218.81", "0.013582"], ["84218.80", "0"], ["84218.63", "0.052126"], ["84218.58", "0.008286"], ["84218.20", "0"], ["84218.03", "0.005554"], ["84218.00", "0.005089"], ["84217.80", "0.028817"], ["84217.75", "0.007950"], ["84217.58", "0.008991"], ["84217.40", "0.001022"], ["84217.35", "0.271929"], ["84217.20", "0"], ["84216.97", "0.018526"], ["84216.68", "0.008674"], ["84216.57", "0.222807"], ["84216.39", "0.010235"], ["84216.23", "0.263418"], ["84215.94", "0.021116"], ["84215.85", "0.002951"], ["84214.90", "0"], ["84214.75", "0.004937"], ["84214.60", "0.001014"], ["84214.52", "0.076039"], ["84214.50", "0"], ["84213.90", "0"], ["84213.40", "0.001001"], ["84213.00", "0.001230"], ["84212.70", "0.198919"], ["84212.50", "0.287520"], ["84211.20", "0.383610"], ["84210.50", "0"], ["84210.10", "0.012444"], ["84210.00", "0.002000"], ["84209.90", "0.056658"], ["84209.16", "0.073530"], ["84209.10", "0.100680"], ["84208.60", "0"], ["84208.10", "0.243510"], ["84207.90", "0"], ["84206.70", "0.274590"], ["84205.80", "0"], ["84204.20", "0"], ["84203.70", "0.009000"], ["84202.80", "1.428540"], ["84202.60", "0.090000"], ["84202.50", "0.090000"], ["84200.60", "0.462600"], ["84200.20", "0.142500"], ["84200.16", "0.008208"], ["84199.80", "0.071220"], ["84199.10", "1.030980"], ["84196.60", "0"], ["84194.30", "0"], ["84191.69", "0.007585"], ["84189.41", "0.001180"], ["84184.20", "0.017807"], ["84178.60", "0"], ["84173.30", "4.702134"], ["84170.10", "0"], ["84166.00", "0"], ["84164.80", "3.888303"], ["84161.60", "0"], ["84156.30", "5.335114"], ["84153.10", "0"], ["84147.80", "5.515965"], ["84144.60", "0"], ["84139.30", "5.425539"], ["84136.10", "0"], ["84130.80", "4.430857"], ["84127.60", "0"], ["84122.30", "5.063837"], ["84119.10", "0"], ["84113.80", "4.069155"], ["84110.60", "0"], ["84105.30", "4.159580"], ["84102.10", "0"], ["84096.80", "5.244688"], ["84093.60", "0"], ["84088.30", "4.792560"], ["84085.10", "0"], ["84079.80", "5.606391"], ["84076.60", "0"], ["84071.30", "4.611709"], ["84068.10", "0"], ["84062.80", "4.882985"], ["84059.60", "0"], ["84054.30", "3.978729"], ["84051.10", "0"], ["84045.80", "4.340432"], ["84042.60", "0"], ["84037.30", "4.973411"], ["84034.10", "0"], ["84028.80", "4.521283"], ["84025.60", "0"], ["84020.30", "5.154262"], ["84017.10", "0"], ["84011.80", "4.250006"], ["83877.42", "0"], ["83877.29", "0"], ["83877.05", "0"], ["83876.25", "0"], ["83876.12", "0"], ["83875.99", "0"], ["83875.49", "0"], ["83875.16", "0"], ["83875.00", "0"], ["83874.55", "0"], ["83874.15", "0"], ["83873.87", "0"], ["83873.52", "0"], ["83870.97", "0"], ["83870.95", "0"], ["83870.78", "0"]], "checksum": 1999717300, "ts": "1742142225880"}], "ts": 1742142225886, "record_time": 1742142224.995633}
{"action": "update", "arg": {"instType": "SPOT", "channel": "books", "instId": "BTCUSDT"}, "data": [{"asks": [["84243.44", "0.202102"], ["84247.01", "0.209200"], ["84247.02", "0.047500"], ["84247.03", "0.634784"], ["84247.04", "0.000479"], ["84247.98", "0.001923"], ["84248.01", "0.008506"], ["84248.03", "0.014737"], ["84248.04", "0.000443"], ["84250.12", "0"], ["84254.33", "0.192357"], ["84254.34", "0.034919"], ["84255.40", "0.209200"], ["84255.78", "0.001827"], ["84258.00", "0"], ["84258.99", "0.024025"], ["84260.84", "0.012680"], ["84261.33", "0.314462"], ["84261.42", "1.895673"], ["84266.07", "0.005342"], ["84276.90", "0.001010"], ["84278.27", "2.228417"], ["84278.56", "0"], ["84278.90", "0.001270"], ["84279.57", "0.075100"], ["84279.80", "0"], ["84280.80", "0"], ["84280.90", "0.003342"], ["84281.80", "0"], ["84282.90", "0.008795"], ["84283.80", "0"], ["84284.90", "0.023146"], ["84285.80", "0"], ["84286.90", "0.060909"], ["84287.24", "0"], ["84287.80", "0"], ["84288.90", "0.160287"], ["84289.80", "0"], ["84290.90", "0.421808"], ["84291.80", "0"], ["84292.90", "1.110281"], ["84293.80", "0"], ["84294.90", "2.921791"], ["84295.80", "0"], ["84296.90", "7.688924"], ["84297.40", "0.143310"], ["84297.80", "0"], ["84298.20", "0.069600"], ["84298.90", "1.243080"], ["84299.00", "1.508610"], ["84299.80", "0"], ["84300.20", "1.099830"], ["84300.60", "0.701220"], ["84301.00", "0.405750"], ["84301.20", "0"], ["84302.30", "1.600230"], ["84302.40", "4.099950"], ["84303.30", "1.079040"], ["84303.80", "0.142500"], ["84305.40", "0.985470"], ["84305.70", "1.607640"], ["84306.20", "0.084690"], ["84307.80", "0.015120"], ["84308.10", "0.032910"], ["84308.40", "0.015090"], ["84308.50", "0.427770"], ["84308.60", "0.009000"], ["84309.00", "0"], ["84310.00", "0.012630"], ["84310.50", "0"], ["84310.90", "0"], ["84311.60", "0.177960"], ["84312.50", "0.117000"], ["84312.60", "0"], ["84314.20", "0"], ["84314.80", "0"], ["84314.90", "0"], ["84315.00", "0"], ["84316.20", "0"], ["84316.60", "0"], ["84316.90", "0"], ["84317.09", "0"], ["84339.00", "5.064010"], ["84341.90", "0"], ["84347.50", "3.888436"], ["84350.40", "0"], ["84356.00", "3.978865"], ["84358.90", "0"], ["84364.50", "4.159722"], ["84367.40", "0"], ["84373.00", "4.250151"], ["84375.90", "0"], ["84381.50", "5.606582"], ["84384.40", "0"], ["84390.00", "4.431009"], ["84392.90", "0"], ["84398.50", "4.069294"], ["84401.40", "0"], ["84407.00", "5.154439"], ["84409.90", "0"], ["84415.50", "4.702295"], ["84418.40", "0"], ["84424.00", "4.973581"], ["84426.90", "0"], ["84432.50", "5.516154"], ["84435.40", "0"], ["84441.00", "4.792724"], ["84443.90", "0"], ["84449.50", "5.425725"], ["84452.40", "0"], ["84458.00", "4.340580"], ["84460.90", "0"], ["84466.50", "5.244867"], ["84469.40", "0"], ["84475.00", "4.521437"], ["84477.90", "0"], ["84483.50", "4.883152"], ["84486.40", "0"], ["84492.00", "4.611866"], ["84494.90", "0"], ["84500.50", "5.335296"], ["84503.40", "0"], ["84839.83", "0"], ["84840.00", "0"], ["84841.58", "0"], ["84842.11", "0"], ["84844.53", "0"], ["84845.00", "0"], ["84845.94", "0"], ["84846.15", "0"], ["84846.55", "0"]], "bids": [["84242.28", "0"], ["84242.27", "0"], ["84236.36", "0.140012"], ["84235.40", "0"], ["84234.80", "0.098403"], ["84234.67", "0.189981"], ["84233.40", "0"], ["84232.50", "0.001001"], ["84231.40", "0"], ["84230.85", "0.063379"], ["84230.50", "0.001017"], ["84229.40", "0"], ["84228.50", "0.001013"], ["84227.40", "0"], ["84226.59", "0.884260"], ["84226.50", "0.001011"], ["84225.40", "0"], ["84225.16", "0.008538"], ["84224.50", "0.001526"], ["84223.40", "0"], ["84222.50", "0.004196"], ["84222.42", "0.083279"], ["84221.88", "0.006487"], ["84221.87", "0.001443"], ["84221.79", "0.007641"], ["84221.40", "0"], ["84220.50", "0.011040"], ["84219.60", "0.010000"], ["84219.40", "0"], ["84218.50", "0.029053"], ["84218.10", "0"], ["84217.40", "0"], ["84216.50", "0.076600"], ["84214.66", "0.000875"], ["84214.63", "0.009635"], ["84214.61", "0.008149"], ["84214.60", "0"], ["84214.50", "0.201579"], ["84213.40", "0"], ["84213.00", "0"], ["84212.70", "0.197876"], ["84212.50", "0.530472"], ["84212.30", "0"], ["84212.20", "0.001048"], ["84212.10", "0.001018"], ["84211.80", "0.607920"], ["84211.70", "0.396750"], ["84211.20", "0"], ["84209.10", "0.100860"], ["84208.10", "0.160680"], ["84206.70", "0"], ["84205.35", "0.023750"], ["84204.10", "2.586990"], ["84202.90", "0.274590"], ["84202.80", "0.915360"], ["84201.30", "0.038490"], ["84200.00", "0.090000"], ["84199.20", "0.027240"], ["84199.10", "1.957380"], ["84199.00", "0.009000"], ["84191.83", "0.007181"], ["84173.30", "0"], ["84170.40", "5.335296"], ["84164.80", "0"], ["84161.90", "4.069294"], ["84156.30", "0"], ["84153.40", "4.431009"], ["84147.80", "0"], ["84144.90", "5.516154"], ["84139.30", "0"], ["84136.40", "4.792724"], ["84130.80", "0"], ["84127.90", "4.250151"], ["84122.30", "0"], ["84119.40", "3.978865"], ["84113.80", "0"], ["84110.90", "4.159722"], ["84105.30", "0"], ["84102.40", "4.973581"], ["84096.80", "0"], ["84093.90", "4.883152"], ["84088.30", "0"], ["84085.40", "4.521437"], ["84079.80", "0"], ["84076.90", "4.611866"], ["84071.30", "0"], ["84068.40", "5.154439"], ["84062.80", "0"], ["84059.90", "5.606582"], ["84054.30", "0"], ["84051.40", "5.244867"], ["84045.80", "0"], ["84042.90", "4.702295"], ["84037.30", "0"], ["84034.40", "3.888436"], ["84028.80", "0"], ["84025.90", "5.064010"], ["84020.30", "0"], ["84017.40", "5.425725"], ["84011.80", "0"], ["84008.90", "4.340580"], ["83887.29", "0"], ["83887.11", "0"], ["83886.91", "0"], ["83885.98", "0"], ["83885.71", "0"], ["83884.62", "0"], ["83884.55", "0"], ["83884.30", "0"], ["83882.98", "0"], ["83882.92", "0"], ["83881.99", "0"], ["83880.00", "0"], ["83877.97", "0"], ["83877.55", "0"]], "checksum": 1313004212, "ts": "1742142226082"}], "ts": 1742142226089, "record_time": 1742142225.196396}
{"action": "update", "arg": {"instType": "SPOT", "channel": "books", "instId": "BTCUSDT"}, "data": [{"asks": [["84243.44", "1.441609"], ["84247.01", "0.495368"], ["84247.02", "0.102585"], ["84247.03", "0.154086"], ["84247.04", "0"], ["84247.05", "0"], ["84254.09", "0.080082"], ["84254.33", "0"], ["84259.00", "0"], ["84265.71", "0.148098"], ["84278.90", "0.001409"], ["84280.79", "0"], ["84280.90", "0.003707"], ["84282.90", "0.009756"], ["84284.90", "0.025672"], ["84286.90", "0.067558"], ["84288.90", "0.177785"], ["84290.90", "0.467856"], ["84292.90", "1.231200"], ["84294.90", "3.240000"], ["84296.90", "8.526314"], ["84297.40", "0.143940"], ["84298.20", "0.069990"], ["84298.90", "1.029720"], ["84299.00", "1.508790"], ["84299.20", "0.417630"], ["84300.60", "0"], ["84302.40", "4.100130"], ["84306.60", "0.015180"], ["84308.40", "0"], ["84309.40", "0.180000"], ["84310.30", "0.267150"], ["84310.87", "0"], ["84313.09", "0"], ["84339.00", "3.888436"], ["84347.50", "4.431009"], ["84356.00", "4.702295"], ["84364.50", "5.516154"], ["84373.00", "5.064010"], ["84381.50", "4.973581"], ["84390.00", "4.250151"], ["84398.50", "5.244867"], ["84407.00", "4.069294"], ["84415.50", "4.340580"], ["84424.00", "4.521437"], ["84432.50", "5.154439"], ["84441.00", "5.606582"], ["84458.00", "5.335296"], ["84466.50", "4.159722"], ["84475.00", "4.792724"], ["84483.50", "3.978865"], ["84500.50", "4.883152"], ["84591.74", "1.705193"], ["84613.99", "0"], ["84839.83", "0.000098"], ["84840.00", "0.000436"], ["84841.58", "0.000008"], ["84842.11", "0.000068"]], "bids": [["84243.43", "2.098843"], ["84240.71", "0"], ["84236.36", "0"], ["84234.80", "0.142775"], ["84224.50", "0.001012"], ["84222.50", "0.001486"], ["84221.84", "0.003071"], ["84220.50", "0.003911"], ["84218.50", "0.010292"], ["84216.50", "0.027084"], ["84215.85", "0"], ["84214.50", "0.071274"], ["84212.70", "0"], ["84212.50", "0.187562"], ["84212.00", "0.022020"], ["84211.80", "0.001260"], ["84211.70", "0.001230"], ["84208.10", "0.160500"], ["84206.60", "0"], ["84204.40", "0"], ["84204.10", "1.236990"], ["84203.40", "0"], ["84202.60", "0"], ["84202.50", "0"], ["84200.33", "0"], ["84200.00", "0.000059"], ["84199.20", "0"], ["84198.60", "0.012540"], ["84198.40", "0.177960"], ["84197.80", "2.669430"], ["84177.30", "0.207047"], ["84170.40", "3.978865"], ["84169.00", "0.012838"], ["84161.90", "4.702295"], ["84153.40", "4.973581"], ["84144.90", "5.244867"], ["84136.40", "4.521437"], ["84119.40", "4.431009"], ["84110.90", "3.888436"], ["84102.40", "4.883152"], ["84093.90", "5.425725"], ["84085.40", "5.064010"], ["84076.90", "4.069294"], ["84068.40", "4.159722"], ["84059.90", "5.516154"], ["84051.40", "5.606582"], ["84042.90", "5.154439"], ["84034.40", "4.340580"], ["84025.90", "4.792724"], ["84017.40", "5.335296"], ["84008.90", "4.611866"], ["83939.76", "0"], ["83917.69", "1.612806"], ["83887.29", "0.000586"], ["83887.11", "0.000075"], ["83886.91", "0.000145"], ["83885.98", "0.000018"], ["83885.71", "0.000069"], ["83884.62", "0.000014"]], "checksum": 1256427635, "ts": "1742142226284"}], "ts": 1742142226287, "record_time": 1742142225.395573}
{"action": "update", "arg": {"instType": "SPOT", "channel": "books", "instId": "BTCUSDT"}, "data": [{"asks": [["84243.44", "1.232409"], ["84247.00", "0.158341"], ["84247.01", "0.209200"], ["84251.20", "0.020512"], ["84255.89", "0.001205"], ["84258.99", "0"], ["84261.33", "0.313257"], ["84261.90", "0.119869"], ["84264.29", "0.010985"], ["84266.75", "0"], ["84267.49", "0.016427"], ["84268.90", "0.006356"], ["84269.14", "0.006356"], ["84274.14", "0.031812"], ["84278.90", "0.001308"], ["84280.90", "0.003442"], ["84282.90", "0.009058"], ["84284.90", "0.023838"], ["84286.90", "0.062731"], ["84288.90", "0.165081"], ["84290.90", "0.434425"], ["84292.80", "0.001597"], ["84292.90", "1.143222"], ["84294.90", "3.008480"], ["84296.90", "7.917053"], ["84297.00", "0"], ["84298.60", "0.035790"], ["84298.90", "1.029510"], ["84302.30", "2.208180"], ["84303.60", "0.035580"], ["84303.70", "2.669430"], ["84305.70", "2.320320"], ["84307.40", "2.669430"], ["84308.50", "0.248880"], ["84309.50", "1.814880"], ["84310.00", "0"], ["84310.30", "1.095150"], ["84310.70", "0.064680"], ["84310.90", "0.071460"], ["84311.60", "0"], ["84312.20", "0"], ["84312.50", "0"], ["84313.00", "0"], ["84339.00", "4.973581"], ["84347.50", "4.883152"], ["84356.00", "4.250151"], ["84364.50", "5.335296"], ["84373.00", "4.340580"], ["84381.50", "5.606582"], ["84390.00", "4.069294"], ["84398.50", "4.611866"], ["84407.00", "4.702295"], ["84415.50", "5.154439"], ["84424.00", "5.244867"], ["84432.50", "3.888436"], ["84441.00", "3.978865"], ["84458.00", "5.516154"], ["84466.50", "5.064010"], ["84475.00", "4.521437"], ["84483.50", "4.431009"], ["84492.00", "4.159722"], ["84500.50", "4.792724"], ["84838.70", "0"], ["84838.71", "0"], ["84839.83", "0"], ["84840.00", "0"], ["84841.58", "0"], ["84842.11", "0"]], "bids": [["84242.18", "0.055179"], ["84238.51", "0.000070"], ["84236.37", "0.000164"], ["84234.41", "0.140010"], ["84225.47", "0"], ["84224.50", "0.001607"], ["84222.66", "0"], ["84222.50", "0.004229"], ["84222.42", "0.227436"], ["84221.19", "0"], ["84220.63", "0.248117"], ["84220.50", "0.011130"], ["84219.38", "0"], ["84218.50", "0.029145"], ["84217.36", "0.182018"], ["84216.50", "0.076696"], ["84216.44", "0.056381"], ["84216.10", "0.025096"], ["84215.40", "0"], ["84214.50", "0.201834"], ["84214.15", "0.012655"], ["84212.50", "0.531142"], ["84211.90", "0.001019"], ["84211.80", "0.001013"], ["84211.70", "0"], ["84211.10", "0.383850"], ["84209.50", "0.683400"], ["84209.10", "0"], ["84208.86", "0.002951"], ["84208.10", "0.090510"], ["84206.80", "0.197876"], ["84205.80", "0.035580"], ["84204.90", "0.086460"], ["84204.10", "0.582540"], ["84203.70", "0"], ["84202.90", "0"], ["84200.89", "0.023950"], ["84199.90", "0.013170"], ["84199.60", "0.274590"], ["84199.10", "1.030980"], ["84198.60", "0"], ["84198.40", "0"], ["84197.80", "0"], ["84182.29", "0.001190"], ["84170.40", "5.516154"], ["84164.00", "0.000159"], ["84161.90", "4.069294"], ["84153.40", "5.425725"], ["84144.90", "5.154439"], ["84136.40", "4.883152"], ["84127.90", "4.792724"], ["84119.40", "4.250151"], ["84110.90", "5.335296"], ["84102.40", "5.064010"], ["84093.90", "4.611866"], ["84085.40", "5.606582"], ["84076.90", "4.973581"], ["84068.40", "4.702295"], ["84059.90", "4.521437"], ["84051.40", "4.431009"], ["84042.90", "4.159722"], ["84034.40", "3.978865"], ["84025.90", "5.244867"], ["84017.40", "3.888436"], ["84008.90", "4.340580"], ["83891.30", "0"], ["83888.89", "0"], ["83888.86", "0"], ["83887.29", "0"], ["83887.11", "0"], ["83886.91", "0"], ["83885.98", "0"], ["83885.71", "0"], ["83884.62", "0"]], "checksum": -428075055, "ts": "1742142226485"}], "ts": 1742142226489, "record_time": 1742142225.597656}
{"action": "update", "arg": {"instType": "SPOT", "channel": "books", "instId": "BTCUSDT"}, "data": [{"asks": [["84254.08", "0.102593"], ["84278.90", "0.001420"], ["84280.90", "0.003737"], ["84282.90", "0.009834"], ["84284.90", "0.025880"], ["84286.90", "0.068106"], ["84288.90", "0.179065"], ["84290.90", "0.471225"], ["84292.90", "1.240066"], ["84294.90", "3.263331"], ["84296.90", "8.587713"], ["84300.20", "0.143850"], ["84301.00", "0"], ["84302.40", "3.694380"], ["84310.10", "0.012510"], ["84311.60", "0.177960"], ["84315.55", "0"], ["84339.00", "4.159722"], ["84347.50", "4.250151"], ["84356.00", "5.244867"], ["84364.50", "4.069294"], ["84373.00", "3.978865"], ["84381.50", "5.154439"], ["84390.00", "5.335296"], ["84398.50", "4.340580"], ["84407.00", "5.064010"], ["84415.50", "5.516154"], ["84424.00", "3.888436"], ["84432.50", "4.521437"], ["84441.00", "4.883152"], ["84449.50", "5.606582"], ["84458.00", "4.792724"], ["84466.50", "4.973581"], ["84475.00", "4.431009"], ["84483.50", "4.702295"], ["84492.00", "4.611866"], ["84500.50", "5.425725"], ["84837.38", "0"]], "bids": [["84238.51", "0"], ["84234.67", "0"], ["84227.88", "0.003008"], ["84224.50", "0.001787"], ["84222.50", "0.004705"], ["84220.50", "0.012381"], ["84218.73", "0.003038"], ["84218.50", "0.032580"], ["84216.50", "0.085737"], ["84214.50", "0.225625"], ["84212.50", "0.593749"], ["84211.00", "0.683220"], ["84209.50", "0"], ["84208.10", "0.158610"], ["84206.60", "0.142500"], ["84200.10", "0.274590"], ["84199.60", "0"], ["84199.10", "1.978350"], ["84198.60", "0.012540"], ["84170.40", "4.250151"], ["84161.90", "5.064010"], ["84153.40", "4.069294"], ["84144.90", "4.521437"], ["84136.40", "3.888436"], ["84127.90", "5.154439"], ["84119.40", "5.335296"], ["84110.90", "3.978865"], ["84102.40", "5.425725"], ["84093.90", "4.159722"], ["84085.40", "4.611866"], ["84076.90", "5.244867"], ["84068.40", "5.516154"], ["84059.90", "4.792724"], ["84051.40", "4.702295"], ["84042.90", "4.431009"], ["84034.40", "4.340580"], ["84025.90", "5.606582"], ["84017.40", "4.883152"], ["84008.90", "4.973581"], ["83892.29", "0"], ["83891.43", "0"]], "checksum": -1897499175, "ts": "1742142226686"}], "ts": 1742142226692, "record_time": 1742142225.80275}
{"action": "update", "arg": {"instType": "SPOT", "channel": "books", "instId": "BTCUSDT"}, "data": [{"asks": [["84243.44", "0.808572"], ["84247.01", "0"], ["84255.40", "0"], ["84261.41", "0.687017"], ["84262.21", "0"], ["84274.14", "0"], ["84280.90", "0.003615"], ["84282.90", "0.009514"], ["84284.90", "0.025036"], ["84286.90", "0.065886"], ["84288.90", "0.173383"], ["84290.90", "0.456272"], ["84292.90", "1.200716"], ["84294.90", "3.159778"], ["84296.90", "8.315204"], ["84297.40", "0.143760"], ["84298.20", "0.001023"], ["84298.60", "0.001035"], ["84298.90", "0.622380"], ["84299.00", "0.429750"], ["84300.20", "0.074250"], ["84302.20", "0"], ["84310.01", "0.209200"], ["84310.10", "0.012300"], ["84310.90", "0"], ["84311.60", "0"], ["84312.20", "0.069600"], ["84339.00", "4.883152"], ["84347.50", "4.159722"], ["84356.00", "3.888436"], ["84364.50", "5.425725"], ["84373.00", "4.702295"], ["84381.50", "4.611866"], ["84390.00", "5.244867"], ["84398.50", "3.978865"], ["84407.00", "4.250151"], ["84424.00", "5.064010"], ["84432.50", "4.973581"], ["84441.00", "5.154439"], ["84449.50", "4.340580"], ["84458.00", "4.521437"], ["84466.50", "4.431009"], ["84475.00", "4.069294"], ["84483.50", "5.606582"], ["84492.00", "5.335296"], ["84500.50", "4.792724"], ["84837.38", "0.000008"], ["84838.70", "0.000078"], ["84838.71", "0.000214"], ["84839.83", "0.000098"]], "bids": [["84243.43", "2.111523"], ["84242.18", "0"], ["84233.02", "0"], ["84226.50", "0.001886"], ["84225.19", "0.184564"], ["84224.50", "0.004963"], ["84222.50", "0.013062"], ["84220.50", "0.034373"], ["84218.50", "0.090456"], ["84216.50", "0.238040"], ["84214.50", "0.626423"], ["84212.50", "1.648481"], ["84211.10", "0.383670"], ["84211.00", "0"], ["84210.90", "0.010920"], ["84207.80", "0.105210"], ["84205.80", "0"], ["84204.10", "1.932960"], ["84200.80", "0.274590"], ["84200.10", "0"], ["84199.90", "0"], ["84170.40", "5.064010"], ["84161.90", "5.335296"], ["84144.90", "4.792724"], ["84127.90", "5.425725"], ["84119.40", "3.978865"], ["84110.90", "4.159722"], ["84102.40", "4.521437"], ["84093.90", "5.516154"], ["84085.40", "4.340580"], ["84068.40", "4.702295"], ["84059.90", "4.973581"], ["84051.40", "4.431009"], ["84042.90", "4.883152"], ["84034.40", "4.250151"], ["84017.40", "4.611866"], ["84008.90", "5.154439"], ["83892.29", "0.000143"], ["83891.43", "0.000455"], ["83891.30", "0.000010"]], "checksum": 1135757631, "ts": "1742142226889"}], "ts": 1742142226894, "record_time": 1742142226.002613}
{"action": "update", "arg": {"instType": "SPOT", "channel": "books", "instId": "BTCUSDT"}, "data": [{"asks": [["84243.44", "0.808093"], ["84247.00", "0.095581"], ["84254.08", "0"], ["84274.19", "0.010000"], ["84278.90", "0.001036"], ["84280.90", "0.002220"], ["84282.59", "0.031812"], ["84282.90", "0.005840"], ["84284.90", "0.015369"], ["84286.90", "0.040573"], ["84288.90", "0.106773"], ["84289.89", "0"], ["84290.90", "0.280982"], ["84292.90", "0.739183"], ["84294.90", "1.945220"], ["84296.90", "5.118999"], ["84297.40", "1.146870"], ["84298.10", "0.001006"], ["84298.60", "0"], ["84298.90", "0"], ["84299.00", "0.309750"], ["84302.30", "1.172760"], ["84302.40", "0"], ["84303.30", "0"], ["84303.60", "0"], ["84305.30", "1.350000"], ["84305.70", "1.197270"], ["84306.20", "0.015090"], ["84308.60", "0"], ["84308.70", "0"], ["84309.40", "0"], ["84309.50", "0.035580"], ["84310.30", "2.154090"], ["84311.40", "0.250050"], ["84312.10", "3.694380"], ["84312.50", "0.117000"], ["84312.60", "2.669430"], ["84313.00", "0.410370"], ["84347.50", "4.973581"], ["84356.00", "5.606582"], ["84364.50", "5.516154"], ["84373.00", "4.431009"], ["84381.50", "4.702295"], ["84390.00", "3.978865"], ["84398.50", "5.335296"], ["84400.55", "0.209200"], ["84407.00", "4.611866"], ["84415.50", "5.244867"], ["84424.00", "4.159722"], ["84432.50", "4.250151"], ["84441.00", "5.064010"], ["84449.50", "5.425725"], ["84458.00", "4.069294"], ["84466.50", "4.340580"], ["84475.00", "4.521437"], ["84483.50", "3.888436"], ["84492.00", "5.154439"]], "bids": [["84243.43", "2.111593"], ["84242.23", "0.055179"], ["84239.40", "0.105989"], ["84228.50", "0.001153"], ["84226.50", "0.003033"], ["84224.50", "0.007981"], ["84222.50", "0.021003"], ["84220.50", "0.055384"], ["84219.60", "0"], ["84218.50", "0.145748"], ["84216.50", "0.383546"], ["84214.50", "1.009331"], ["84212.50", "2.656136"], ["84211.10", "0.506460"], ["84209.80", "0.069600"], ["84208.10", "0.501270"], ["84205.10", "0.274590"], ["84204.90", "0.156180"], ["84204.10", "2.843460"], ["84203.10", "2.350440"], ["84200.80", "0"], ["84199.10", "1.420500"], ["84199.00", "0"], ["84198.50", "0.410370"], ["84198.40", "0.177960"], ["84197.80", "2.669430"], ["84170.40", "4.973581"], ["84168.00", "0"], ["84161.90", "4.611866"], ["84153.40", "4.159722"], ["84144.90", "4.521437"], ["84136.40", "5.425725"], ["84127.90", "5.244867"], ["84119.40", "5.064010"], ["84110.90", "5.516154"], ["84102.40", "3.888436"], ["84093.90", "5.606582"], ["84085.40", "4.250151"], ["84076.90", "4.702295"], ["84068.40", "5.154439"], ["84059.90", "4.431009"], ["84051.40", "3.978865"], ["84042.90", "4.069294"], ["84034.40", "4.792724"], ["84025.90", "4.340580"], ["84017.40", "5.335296"], ["84008.90", "4.883152"], ["83893.62", "0"], ["83892.29", "0"], ["83891.43", "0"], ["83891.30", "0"]], "checksum": -505673624, "ts": "1742142227090"}], "ts": 1742142227097, "record_time": 1742142226.209064}
{"action": "update", "arg": {"instType": "SPOT", "channel": "books", "instId": "BTCUSDT"}, "data": [{"asks": [["84243.44", "1.366498"], ["84247.00", "0.089411"], ["84247.03", "0.014074"], ["84251.87", "0.209200"], ["84269.84", "0.031812"], ["84274.19", "0"], ["84278.90", "0.001149"], ["84280.47", "0.029802"], ["84280.90", "0.003026"], ["84282.59", "0"], ["84282.90", "0.007963"], ["84284.90", "0.020955"], ["84286.90", "0.055144"], ["84288.90", "0.145115"], ["84290.90", "0.381882"], ["84292.90", "1.004953"], ["84294.90", "2.644612"], ["84296.90", "6.959506"], ["84297.30", "0.001042"], ["84297.40", "0.721740"], ["84298.10", "0"], ["84298.20", "0"], ["84298.60", "0.035580"], ["84298.90", "0.269940"], ["84300.20", "0.074430"], ["84301.50", "0.071190"], ["84302.30", "1.172940"], ["84302.40", "0.065550"], ["84302.90", "0.410370"], ["84309.50", "1.814880"], ["84310.10", "0"], ["84310.40", "0.269760"], ["84311.50", "2.563410"], ["84311.60", "0.177960"], ["84312.10", "0"], ["84312.20", "0"], ["84312.50", "0"], ["84312.60", "0"], ["84313.00", "0"], ["84339.00", "4.340580"], ["84347.50", "4.792724"], ["84364.50", "4.883152"], ["84373.00", "3.888436"], ["84381.50", "4.521437"], ["84390.00", "5.335296"], ["84398.50", "5.425725"], ["84400.55", "0"], ["84407.00", "5.244867"], ["84415.50", "4.250151"], ["84424.00", "4.431009"], ["84432.50", "4.973581"], ["84449.50", "5.154439"], ["84466.50", "3.978865"], ["84475.00", "4.702295"], ["84483.50", "4.159722"], ["84492.00", "4.611866"], ["84500.50", "5.516154"], ["84839.83", "0"]], "bids": [["84243.43", "2.098843"], ["84239.40", "0"], ["84235.01", "0.010000"], ["84230.84", "0"], ["84228.95", "0.012680"], ["84228.50", "0.001028"], ["84226.50", "0.001033"], ["84224.50", "0.001011"], ["84222.50", "0.001105"], ["84220.50", "0.002910"], ["84218.50", "0.007658"], ["84216.50", "0.020152"], ["84214.50", "0.053031"], ["84212.50", "0.139556"], ["84212.10", "0.001470"], ["84212.00", "0.021810"], ["84211.10", "0"], ["84210.90", "0"], ["84209.80", "0"], ["84208.10", "0"], ["84207.80", "0.035610"], ["84206.60", "0"], ["84205.50", "0.193680"], ["84205.10", "0"], ["84204.90", "0"], ["84204.10", "0.770610"], ["84203.50", "0.027930"], ["84203.40", "0.274590"], ["84203.10", "0"], ["84198.60", "0"], ["84198.50", "0"], ["84197.00", "0.987180"], ["84196.90", "0.383430"], ["84170.40", "3.888436"], ["84165.00", "0"], ["84161.90", "5.064010"], ["84153.40", "5.244867"], ["84144.90", "4.702295"], ["84136.40", "5.335296"], ["84127.90", "4.250151"], ["84119.40", "4.431009"], ["84110.90", "5.606582"], ["84102.40", "5.425725"], ["84093.90", "4.340580"], ["84085.40", "5.154439"], ["84076.90", "4.792724"], ["84068.40", "4.069294"], ["84059.90", "3.978865"], ["84051.40", "4.611866"], ["84042.90", "4.521437"], ["84034.40", "4.883152"], ["84025.90", "5.516154"], ["84017.67", "0.209200"], ["84017.40", "4.159722"], ["84008.90", "4.973581"], ["83893.62", "0.000137"], ["83892.29", "0.000143"], ["83891.43", "0.000455"], ["83891.30", "0.000010"], ["83888.89", "0.000163"], ["83888.86", "0.000371"]], "checksum": -1464084214, "ts": "1742142227295"}], "ts": 1742142227299, "record_time": 1742142226.406512}
{"action": "update", "arg": {"instType": "SPOT", "channel": "books", "instId": "BTCUSDT"}, "data": [{"asks": [["84243.44", "0.948577"], ["84247.00", "0.049355"], ["84251.20", "0.080708"], ["84278.90", "0.001013"], ["84280.47", "0"], ["84280.90", "0.002665"], ["84282.90", "0.007014"], ["84284.90", "0.018458"], ["84286.90", "0.048574"], ["84288.90", "0.127663"], ["84289.31", "0.029802"], ["84290.90", "0.335954"], ["84292.90", "0.884090"], ["84294.90", "2.326552"], ["84296.90", "6.122506"], ["84297.40", "0.519630"], ["84298.60", "0.010890"], ["84300.20", "0.074250"], ["84301.50", "0"], ["84302.30", "1.172760"], ["84303.60", "0.035580"], ["84311.50", "0"], ["84339.00", "5.244867"], ["84347.50", "4.431009"], ["84356.00", "5.154439"], ["84364.50", "4.159722"], ["84373.00", "5.064010"], ["84381.50", "5.516154"], ["84390.00", "4.792724"], ["84398.50", "4.340580"], ["84407.00", "4.069294"], ["84415.50", "4.883152"], ["84424.00", "4.973581"], ["84432.50", "4.250151"], ["84441.00", "4.611866"], ["84449.50", "3.888436"], ["84458.00", "5.425725"], ["84475.00", "4.521437"], ["84483.50", "5.606582"], ["84492.00", "5.335296"], ["84500.50", "4.702295"], ["84839.83", "0.000098"]], "bids": [["84243.43", "2.111523"], ["84242.27", "0.055179"], ["84242.23", "0"], ["84239.24", "0.000070"], ["84235.00", "0.209200"], ["84230.85", "0.005320"], ["84228.95", "0"], ["84224.50", "0.002436"], ["84222.50", "0.006410"], ["84220.50", "0.016869"], ["84218.50", "0.044393"], ["84216.50", "0.116824"], ["84214.50", "0.307429"], ["84212.50", "0.809026"], ["84211.40", "0.647250"], ["84206.60", "0.396360"], ["84205.80", "0.035580"], ["84205.50", "0.071310"], ["84204.10", "0.338910"], ["84203.50", "0.112830"], ["84203.40", "0"], ["84202.80", "0"], ["84201.30", "0.313080"], ["84199.90", "0.013170"], ["84197.00", "1.902540"], ["84196.40", "0.429960"], ["84195.90", "0.090000"], ["84170.40", "3.978865"], ["84161.90", "4.973581"], ["84153.40", "4.069294"], ["84144.90", "4.521437"], ["84136.40", "4.792724"], ["84127.90", "5.154439"], ["84119.40", "5.516154"], ["84110.90", "5.425725"], ["84102.40", "4.883152"], ["84093.90", "4.611866"], ["84085.40", "5.244867"], ["84076.90", "5.606582"], ["84068.40", "4.340580"], ["84059.90", "4.431009"], ["84051.40", "3.888436"], ["84042.90", "5.064010"], ["84034.40", "5.335296"], ["84025.90", "4.159722"], ["84017.40", "4.250151"], ["84008.90", "4.702295"], ["83892.29", "0"], ["83891.43", "0"], ["83891.30", "0"], ["83888.89", "0"], ["83888.86", "0"]], "checksum": 474101123, "ts": "1742142227496"}], "ts": 1742142227499, "record_time": 1742142226.614558}
{"action": "update", "arg": {"instType": "SPOT", "channel": "books", "instId": "BTCUSDT"}, "data": [{"asks": [["84243.44", "1.157777"], ["84254.08", "0.039833"], ["84280.90", "0.002850"], ["84282.90", "0.007501"], ["84284.90", "0.019738"], ["84286.90", "0.051944"], ["84288.90", "0.136693"], ["84290.90", "0.359718"], ["84292.90", "0.946398"], ["84294.90", "2.490523"], ["84296.90", "6.554008"], ["84298.60", "0"], ["84310.60", "0.012630"], ["84311.60", "0"], ["84339.00", "4.883152"], ["84347.50", "5.335296"], ["84356.00", "5.244867"], ["84364.50", "4.702295"], ["84381.50", "5.154439"], ["84390.00", "4.250151"], ["84398.50", "4.069294"], ["84407.00", "3.978865"], ["84415.50", "4.340580"], ["84424.00", "4.159722"], ["84432.50", "4.792724"], ["84441.00", "5.425725"], ["84449.50", "5.606582"], ["84458.00", "4.611866"], ["84466.50", "4.973581"], ["84475.00", "5.516154"], ["84483.50", "4.521437"], ["84492.00", "3.888436"], ["84500.50", "4.431009"]], "bids": [["84235.00", "0"], ["84230.85", "0.001516"], ["84226.50", "0.002447"], ["84224.50", "0.006440"], ["84222.50", "0.016946"], ["84220.50", "0.044597"], ["84218.50", "0.117359"], ["84216.50", "0.308839"], ["84214.50", "0.812735"], ["84212.50", "2.138777"], ["84211.40", "0"], ["84210.90", "0.003630"], ["84206.60", "0.396780"], ["84202.10", "0.274590"], ["84201.30", "0.038490"], ["84199.90", "0"], ["84196.90", "0"], ["84196.40", "0"], ["84195.90", "0"], ["84170.40", "5.335296"], ["84161.90", "4.431009"], ["84153.40", "3.978865"], ["84136.40", "5.606582"], ["84127.90", "4.973581"], ["84119.40", "5.425725"], ["84110.90", "4.702295"], ["84102.40", "5.244867"], ["84093.90", "4.159722"], ["84085.40", "4.340580"], ["84076.90", "4.792724"], ["84068.40", "5.064010"], ["84059.90", "3.888436"], ["84051.40", "4.250151"], ["84042.90", "5.516154"], ["84034.40", "4.069294"], ["84025.90", "4.611866"], ["84017.40", "4.883152"], ["84008.90", "5.154439"], ["83892.29", "0.000143"], ["83891.43", "0.000455"], ["83891.30", "0.000010"], ["83888.89", "0.000163"]], "checksum": 2140867968, "ts": "1742142227697"}], "ts": 1742142227702, "record_time": 1742142226.81002}
{"action": "update", "arg": {"instType": "SPOT", "channel": "books", "instId": "BTCUSDT"}, "data": [{"asks": [["84278.26", "0.695510"], ["84278.90", "0.001221"], ["84280.90", "0.003214"], ["84282.90", "0.008459"], ["84284.90", "0.022259"], ["84286.90", "0.058578"], ["84288.90", "0.154305"], ["84290.90", "0.406065"], ["84292.90", "1.068594"], ["84294.90", "2.812089"], ["84296.90", "7.400233"], ["84298.60", "0.035580"], ["84303.70", "8.143110"], ["84310.60", "0"], ["84311.40", "0.180000"], ["84339.00", "4.159722"], ["84356.00", "3.888436"], ["84364.50", "5.606582"], ["84373.00", "5.244867"], ["84381.50", "5.516154"], ["84390.00", "4.973581"], ["84398.50", "4.792724"], ["84407.00", "4.521437"], ["84415.50", "5.425725"], ["84424.00", "5.154439"], ["84432.50", "4.431009"], ["84441.00", "5.064010"], ["84449.50", "4.069294"], ["84458.00", "4.702295"], ["84466.50", "4.883152"], ["84475.00", "4.611866"], ["84483.50", "3.978865"], ["84492.00", "4.340580"], ["84500.50", "4.250151"], ["84839.83", "0"]], "bids": [["84234.80", "0"], ["84226.50", "0.001048"], ["84224.50", "0.001020"], ["84222.50", "0.001104"], ["84220.50", "0.002906"], ["84218.50", "0.007648"], ["84217.36", "0.243881"], ["84216.50", "0.020125"], ["84214.50", "0.052960"], ["84212.50", "0.139370"], ["84212.10", "0.001650"], ["84210.90", "0"], ["84207.80", "0.035850"], ["84206.60", "0"], ["84204.10", "0"], ["84199.90", "0.022710"], ["84170.40", "4.792724"], ["84167.00", "0.000121"], ["84161.90", "3.978865"], ["84153.40", "3.888436"], ["84144.90", "5.516154"], ["84136.40", "4.611866"], ["84127.90", "5.244867"], ["84119.40", "4.973581"], ["84110.90", "4.521437"], ["84102.40", "4.250151"], ["84093.90", "5.064010"], ["84085.40", "4.702295"], ["84076.90", "5.425725"], ["84068.40", "4.159722"], ["84059.90", "4.340580"], ["84051.40", "5.335296"], ["84042.90", "5.606582"], ["84034.40", "4.883152"], ["84025.90", "4.069294"], ["84017.40", "5.154439"], ["84008.90", "4.431009"], ["83888.86", "0.000371"], ["83887.29", "0.000586"]], "checksum": -2093482054, "ts": "1742142227899"}], "ts": 1742142227902, "record_time": 1742142227.01001}
{"action": "update", "arg": {"instType": "SPOT", "channel": "books", "instId": "BTCUSDT"}, "data": [{"asks": [["84243.44", "0.948577"], ["84274.12", "0.195423"], ["84276.94", "0"], ["84278.90", "0.001084"], ["84280.90", "0.002854"], ["84282.90", "0.007509"], ["84284.90", "0.019582"], ["84286.90", "0.051531"], ["84288.90", "0.135609"], ["84290.90", "0.356866"], ["84292.90", "0.939120"], ["84294.90", "2.471368"], ["84296.90", "6.503602"], ["84297.40", "0.519450"], ["84298.60", "0"], ["84298.90", "0"], ["84302.30", "2.898570"], ["84303.60", "1.814880"], ["84303.70", "6.363810"], ["84309.90", "0.012660"], ["84311.40", "0"], ["84339.00", "4.250151"], ["84347.50", "5.154439"], ["84356.00", "4.973581"], ["84364.50", "4.883152"], ["84373.00", "4.792724"], ["84381.50", "5.335296"], ["84390.00", "4.340580"], ["84398.50", "3.888436"], ["84407.00", "4.611866"], ["84415.50", "5.244867"], ["84424.00", "5.425725"], ["84432.50", "4.069294"], ["84441.00", "4.702295"], ["84449.50", "3.978865"], ["84458.00", "5.064010"], ["84466.50", "4.159722"], ["84475.00", "4.431009"], ["84483.50", "5.606582"], ["84492.00", "4.521437"], ["84500.50", "5.516154"], ["84839.83", "0.000098"], ["84840.00", "0.000436"]], "bids": [["84242.31", "0.055179"], ["84242.27", "0"], ["84239.24", "0"], ["84235.00", "0.209200"], ["84234.80", "0.136280"], ["84226.50", "0.001362"], ["84224.50", "0.003585"], ["84222.50", "0.009434"], ["84220.50", "0.024825"], ["84218.50", "0.065330"], ["84216.50", "0.171920"], ["84214.50", "0.452423"], ["84212.50", "1.190586"], ["84212.10", "0.001033"], ["84209.60", "0.012000"], ["84206.60", "0.265740"], ["84205.80", "0.015900"], ["84202.30", "0.274590"], ["84202.10", "0.946500"], ["84201.00", "2.350500"], ["84199.90", "0"], ["84199.10", "2.224680"], ["84198.40", "0"], ["84197.80", "0"], ["84197.00", "0"], ["84170.40", "4.340580"], ["84166.00", "0.000159"], ["84161.90", "4.792724"], ["84153.40", "4.883152"], ["84144.90", "5.244867"], ["84136.40", "3.888436"], ["84127.90", "5.606582"], ["84119.40", "5.516154"], ["84110.90", "4.431009"], ["84102.40", "4.702295"], ["84093.90", "4.069294"], ["84085.40", "3.978865"], ["84076.90", "4.250151"], ["84059.90", "5.335296"], ["84051.40", "4.611866"], ["84042.90", "4.973581"], ["84034.40", "4.521437"], ["84025.90", "5.425725"], ["84017.40", "5.064010"], ["84008.90", "5.154439"], ["83888.86", "0"], ["83887.29", "0"]], "checksum": -1267175772, "ts": "1742142228102"}], "ts": 1742142228105, "record_time": 1742142227.213344}
{"action": "update", "arg": {"instType": "SPOT", "channel": "books", "instId": "BTCUSDT"}, "data": [{"asks": [["84243.44", "1.366977"], ["84265.70", "0.083761"], ["84266.07", "0"], ["84271.77", "0.001807"], ["84278.90", "0.001213"], ["84280.90", "0.003192"], ["84282.90", "0.008399"], ["84284.90", "0.022102"], ["84286.90", "0.058163"], ["84288.90", "0.153061"], ["84290.90", "0.402794"], ["84292.90", "1.059983"], ["84294.90", "2.789428"], ["84296.90", "7.340602"], ["84297.10", "0.270180"], ["84297.40", "0.519030"], ["84298.60", "0.035580"], ["84302.20", "0.269760"], ["84302.50", "0.071310"], ["84309.90", "0"], ["84339.00", "4.702295"], ["84347.50", "4.250151"], ["84356.00", "4.521437"], ["84364.50", "5.154439"], ["84373.00", "4.611866"], ["84381.50", "4.973581"], ["84390.00", "3.888436"], ["84398.50", "4.340580"], ["84407.00", "4.792724"], ["84415.50", "5.516154"], ["84424.00", "5.064010"], ["84432.50", "4.159722"], ["84441.00", "5.425725"], ["84449.50", "5.335296"], ["84458.00", "4.431009"], ["84466.50", "5.244867"], ["84475.00", "4.883152"], ["84483.50", "3.978865"], ["84492.00", "4.069294"], ["84500.50", "5.606582"], ["84838.70", "0"], ["84838.71", "0"], ["84839.83", "0"], ["84840.00", "0"]], "bids": [["84235.00", "0"], ["84234.80", "0"], ["84226.50", "0.001029"], ["84224.50", "0.001050"], ["84222.50", "0.001009"], ["84220.50", "0.001940"], ["84218.50", "0.005105"], ["84217.36", "0.250376"], ["84216.50", "0.013435"], ["84214.50", "0.035354"], ["84212.50", "0.093037"], ["84206.60", "0"], ["84205.80", "0"], ["84202.10", "0.193380"], ["84201.00", "0"], ["84199.90", "0.035610"], ["84198.40", "0.177960"], ["84197.80", "2.669430"], ["84197.00", "0.987180"], ["84170.40", "3.978865"], ["84161.90", "5.606582"], ["84153.40", "4.250151"], ["84144.90", "4.159722"], ["84136.40", "4.069294"], ["84127.90", "4.521437"], ["84119.40", "5.064010"], ["84110.90", "4.973581"], ["84102.40", "4.340580"], ["84093.90", "4.883152"], ["84085.40", "5.335296"], ["84076.90", "4.431009"], ["84068.40", "5.516154"], ["84059.90", "5.425725"], ["84042.90", "4.792724"], ["84034.40", "3.888436"], ["84025.90", "5.244867"], ["84017.40", "5.154439"], ["84008.90", "4.702295"], ["83888.86", "0.000371"]], "checksum": 1981191315, "ts": "1742142228302"}], "ts": 1742142228308, "record_time": 1742142227.41555}
{"action": "update", "arg": {"instType": "SPOT", "channel": "books", "instId": "BTCUSDT"}, "data": [{"asks": [["84276.57", "0.029802"], ["84282.56", "0.071910"], ["84284.90", "0.022215"], ["84286.90", "0.058459"], ["84288.90", "0.153840"], ["84289.31", "0"], ["84290.90", "0.404842"], ["84292.90", "1.065373"], ["84294.90", "2.803614"], ["84296.90", "7.377932"], ["84297.40", "0.686610"], ["84298.20", "0.069600"], ["84299.70", "0.985470"], ["84303.40", "0.071190"], ["84305.40", "0"], ["84310.70", "0"], ["84311.40", "0.250050"], ["84339.00", "4.792724"], ["84347.50", "4.159722"], ["84356.00", "5.154439"], ["84364.50", "4.340580"], ["84373.00", "4.069294"], ["84381.50", "3.888436"], ["84390.00", "4.611866"], ["84398.50", "4.973581"], ["84407.00", "4.702295"], ["84415.50", "3.978865"], ["84424.00", "4.431009"], ["84432.50", "5.516154"], ["84441.00", "4.883152"], ["84449.50", "4.521437"], ["84458.00", "5.335296"], ["84466.50", "5.064010"], ["84475.00", "5.606582"], ["84483.50", "5.425725"], ["84492.00", "5.244867"], ["84500.50", "4.250151"], ["84835.53", "0"], ["84835.91", "0"], ["84837.38", "0"]], "bids": [["84242.35", "0.055179"], ["84242.31", "0"], ["84235.81", "0.000070"], ["84235.01", "0"], ["84234.80", "0.136280"], ["84220.50", "0.001115"], ["84218.50", "0.002934"], ["84216.50", "0.007835"], ["84214.50", "0.020448"], ["84212.50", "0.053810"], ["84212.40", "0.065580"], ["84211.90", "0"], ["84211.80", "0"], ["84206.80", "0.332010"], ["84203.80", "1.048320"], ["84202.30", "0"], ["84202.10", "0"], ["84200.60", "0"], ["84198.90", "0.274590"], ["84170.40", "4.250151"], ["84153.40", "5.244867"], ["84144.90", "4.521437"], ["84136.40", "5.154439"], ["84127.90", "5.335296"], ["84119.40", "4.159722"], ["84110.90", "5.516154"], ["84102.40", "4.702295"], ["84093.90", "4.069294"], ["84085.40", "4.792724"], ["84076.90", "4.973581"], ["84068.40", "4.883152"], ["84051.40", "4.431009"], ["84042.90", "3.888436"], ["84034.40", "4.340580"], ["84025.90", "3.978865"], ["84017.40", "4.611866"], ["84008.90", "5.064010"], ["83887.29", "0.000586"], ["83887.11", "0.000075"]], "checksum": -609906141, "ts": "1742142228502"}], "ts": 1742142228506, "record_time": 1742142227.614021}
{"action": "update", "arg": {"instType": "SPOT", "channel": "books", "instId": "BTCUSDT"}, "data": [{"asks": [["84269.83", "0.060775"], ["84292.90", "1.065140"], ["84294.90", "2.802999"], ["84296.90", "7.376314"], ["84297.10", "0.270360"], ["84297.40", "0.686970"], ["84298.20", "0.069780"], ["84299.20", "0.417810"], ["84299.70", "0.985650"], ["84300.20", "0.074430"], ["84302.20", "0.269940"], ["84339.00", "4.069294"], ["84347.50", "5.244867"], ["84356.00", "4.702295"], ["84364.50", "4.611866"], ["84373.00", "4.521437"], ["84381.50", "4.159722"], ["84390.00", "5.425725"], ["84398.50", "5.064010"], ["84407.00", "5.335296"], ["84415.50", "5.154439"], ["84424.00", "5.516154"], ["84432.50", "4.883152"], ["84441.00", "4.250151"], ["84449.50", "5.606582"], ["84458.00", "4.973581"], ["84466.50", "3.888436"], ["84475.00", "4.431009"], ["84483.50", "4.792724"], ["84492.00", "3.978865"], ["84500.50", "4.340580"], ["84835.36", "0"]], "bids": [["84212.50", "0.053921"], ["84212.40", "0.066240"], ["84209.00", "0.341100"], ["84206.80", "0.197876"], ["84205.10", "0.780810"], ["84203.80", "0.316170"], ["84170.40", "4.973581"], ["84169.00", "0.012717"], ["84164.00", "0"], ["84161.90", "3.888436"], ["84136.40", "4.340580"], ["84127.90", "5.516154"], ["84119.40", "5.425725"], ["84110.90", "5.064010"], ["84102.40", "5.154439"], ["84093.90", "4.883152"], ["84085.40", "5.606582"], ["84076.90", "4.250151"], ["84068.40", "4.702295"], ["84059.90", "3.978865"], ["84042.90", "5.335296"], ["84034.40", "4.159722"], ["84025.90", "4.069294"], ["84008.90", "4.792724"], ["83887.11", "0"]], "checksum": -609906141, "ts": "1742142228705"}], "ts": 1742142228708, "record_time": 1742142227.815517}
{"action": "update", "arg": {"instType": "SPOT", "channel": "books", "instId": "BTCUSDT"}, "data": [{"asks": [["84243.44", "1.182282"], ["84247.24", "0"], ["84248.01", "0"], ["84248.03", "0.007110"], ["84250.43", "0"], ["84250.46", "0"], ["84250.49", "0"], ["84251.21", "0"], ["84251.26", "0"], ["84251.29", "0"], ["84251.30", "0"], ["84251.32", "0"], ["84251.36", "0"], ["84251.39", "0"], ["84252.09", "0"], ["84252.10", "0"], ["84252.14", "0"], ["84254.34", "0"], ["84255.78", "0"], ["84256.34", "0"], ["84256.85", "0"], ["84260.84", "0"], ["84262.17", "0"], ["84262.22", "0"], ["84265.71", "0"], ["84267.96", "0"], ["84268.06", "0"], ["84269.14", "0"], ["84270.90", "0"], ["84271.07", "0"], ["84272.73", "0"], ["84273.42", "0"], ["84276.89", "0"], ["84284.90", "0.022092"], ["84286.90", "0.058139"], ["84288.90", "0.152996"], ["84290.90", "0.402776"], ["84292.90", "1.059937"], ["84294.89", "0.790666"], ["84294.90", "2.789309"], ["84296.90", "7.340285"], ["84297.40", "0.686790"], ["84299.20", "0.417630"], ["84302.50", "0"], ["84309.09", "0"], ["84309.70", "5.979510"], ["84310.30", "0"], ["84339.00", "5.516154"], ["84347.50", "4.159722"], ["84356.00", "4.973581"], ["84364.50", "5.064010"], ["84373.00", "5.244867"], ["84381.50", "4.069294"], ["84390.00", "4.431009"], ["84398.50", "3.978865"], ["84407.00", "4.250151"], ["84415.50", "5.606582"], ["84424.00", "4.611866"], ["84432.50", "3.888436"], ["84441.00", "5.154439"], ["84449.50", "5.425725"], ["84458.00", "4.340580"], ["84466.50", "4.702295"], ["84475.00", "4.521437"], ["84483.50", "5.335296"], ["84492.00", "4.883152"], ["84500.50", "4.792724"], ["84835.36", "0.000152"], ["84835.53", "0.000093"], ["84835.91", "0.000024"], ["84837.38", "0.000008"], ["84838.70", "0.000078"], ["84838.71", "0.000214"], ["84839.83", "0.000098"], ["84840.00", "0.000436"], ["84841.58", "0.000008"], ["84842.11", "0.000068"], ["84844.53", "0.000423"], ["84845.00", "0.000025"], ["84845.94", "0.000008"], ["84846.15", "0.004277"], ["84846.55", "0.000019"], ["84846.85", "0.000176"], ["84847.58", "0.000039"], ["84847.82", "0.000671"], ["84849.88", "0.000030"], ["84850.00", "0.000031"], ["84851.66", "0.000029"], ["84852.81", "0.000115"], ["84852.94", "0.000065"], ["84853.56", "0.000050"], ["84857.14", "0.000347"], ["84858.75", "0.000285"], ["84859.29", "0.000036"], ["84860.00", "0.000169"], ["84862.90", "0.000169"], ["84864.69", "0.000052"], ["84864.86", "0.000041"], ["84864.99", "0.000033"]], "bids": [["84243.43", "0.000160"], ["84242.35", "0"], ["84239.39", "0"], ["84236.37", "0"], ["84235.81", "0"], ["84234.80", "0"], ["84234.79", "0"], ["84234.41", "0"], ["84226.58", "0"], ["84225.16", "0"], ["84224.25", "0"], ["84223.86", "0"], ["84223.76", "0"], ["84223.70", "0"], ["84223.68", "0"], ["84223.65", "0"], ["84223.39", "0"], ["84223.26", "0"], ["84222.32", "0"], ["84222.30", "0"], ["84222.28", "0"], ["84221.88", "0"], ["84221.87", "0"], ["84221.84", "0"], ["84221.79", "0"], ["84221.51", "0"], ["84221.20", "0"], ["84221.03", "0"], ["84221.00", "0"], ["84219.34", "0"], ["84218.73", "0"], ["84218.50", "0.002757"], ["84218.03", "0"], ["84218.00", "0"], ["84217.75", "0"], ["84216.97", "0"], ["84216.68", "0"], ["84216.57", "0"], ["84216.50", "0.007255"], ["84216.39", "0"], ["84216.23", "0"], ["84214.75", "0"], ["84214.63", "0"], ["84214.61", "0"], ["84214.50", "0.019090"], ["84212.50", "0.050239"], ["84212.40", "0.001020"], ["84208.86", "0"], ["84205.50", "0.147210"], ["84205.10", "0"], ["84203.80", "0.215010"], ["84200.16", "0"], ["84199.10", "1.664490"], ["84191.83", "0"], ["84191.69", "0"], ["84170.40", "5.335296"], ["84161.90", "4.340580"], ["84153.40", "4.069294"], ["84144.90", "5.244867"], ["84136.40", "4.973581"], ["84127.90", "3.888436"], ["84119.40", "3.978865"], ["84110.90", "5.154439"], ["84102.40", "4.431009"], ["84093.90", "5.516154"], ["84085.40", "5.425725"], ["84076.90", "4.159722"], ["84068.40", "4.883152"], ["84059.90", "4.611866"], ["84051.40", "4.250151"], ["84042.90", "4.702295"], ["84034.40", "5.064010"], ["84025.90", "4.521437"], ["84017.40", "5.606582"], ["83887.11", "0.000075"], ["83886.91", "0.000145"], ["83885.98", "0.000018"], ["83885.71", "0.000069"], ["83884.62", "0.000014"], ["83884.55", "0.000048"], ["83884.30", "0.000161"], ["83882.98", "0.000188"], ["83882.92", "0.002384"], ["83881.99", "0.000038"], ["83880.00", "0.020454"], ["83877.97", "0.000023"], ["83877.55", "0.000010"], ["83877.42", "0.000054"], ["83877.29", "0.000024"], ["83877.05", "0.000008"], ["83876.25", "0.000028"], ["83876.12", "0.000681"], ["83875.99", "0.000299"], ["83875.49", "0.000723"], ["83875.16", "0.000179"], ["83875.00", "0.000145"], ["83874.55", "0.000145"], ["83874.15", "0.000150"], ["83873.87", "0.000041"], ["83873.52", "0.000135"], ["83870.97", "0.000194"], ["83870.95", "0.000078"], ["83870.78", "0.000019"], ["83870.00", "0.000121"], ["83869.57", "0.000035"], ["83868.82", "0.000017"], ["83866.67", "0.000138"], ["83865.80", "0.000098"], ["83865.10", "0.000134"], ["83864.54", "0.000009"], ["83863.64", "0.000012"], ["83863.52", "0.000510"], ["83860.29", "0.000041"], ["83860.10", "0.000023"], ["83860.00", "0.000024"], ["83859.94", "0.000058"], ["83859.35", "0.000051"], ["83859.25", "0.000115"], ["83858.82", "0.000105"], ["83857.50", "0.000025"]], "checksum": 2130470276, "ts": "1742142228907"}], "ts": 1742142228911, "record_time": 1742142228.020193}
{"action": "update", "arg": {"instType": "SPOT", "channel": "books", "instId": "BTCUSDT"}, "data": [{"asks": [["84227.85", "0.035500"], ["84232.24", "0.330847"], ["84232.45", "0.209200"], ["84232.46", "0.209200"], ["84232.49", "0.047500"], ["84232.50", "1.133800"], ["84234.44", "0.010074"], ["84235.29", "0.015582"], ["84235.96", "0.025625"], ["84240.94", "0.209200"], ["84243.44", "0.605170"], ["84244.23", "0.002907"], ["84244.98", "0.003017"], ["84246.46", "0.001827"], ["84247.02", "0"], ["84247.14", "0"], ["84247.95", "0.080082"], ["84247.98", "0"], ["84248.03", "0"], ["84248.04", "0"], ["84249.23", "0.001205"], ["84253.61", "0.017809"], ["84254.08", "0.027937"], ["84254.09", "0"], ["84255.76", "0.119869"], ["84255.89", "0"], ["84256.84", "0.031812"], ["84257.31", "0.016427"], ["84257.84", "0.006356"], ["84257.85", "0.006356"], ["84258.41", "0.006356"], ["84258.47", "0.006356"], ["84258.88", "0.006356"], ["84258.89", "0.010985"], ["84259.18", "0.006356"], ["84259.66", "0.006356"], ["84259.89", "0.016428"], ["84259.91", "0.006356"], ["84260.28", "0.006356"], ["84260.44", "0.006356"], ["84260.56", "0.006356"], ["84260.89", "0.006356"], ["84261.06", "0.119843"], ["84261.42", "0"], ["84261.53", "0.148098"], ["84261.81", "0.010000"], ["84261.84", "0.006357"], ["84261.90", "0"], ["84262.29", "0.010984"], ["84262.59", "0.006356"], ["84263.38", "0.009989"], ["84263.64", "0.001807"], ["84264.20", "0.001017"], ["84264.29", "0"], ["84264.88", "0.119895"], ["84265.02", "0.075100"], ["84265.60", "0"], ["84265.70", "0.119881"], ["84265.94", "0.015892"], ["84266.08", "0"], ["84266.19", "0.009989"], ["84266.20", "0.001066"], ["84266.45", "0"], ["84267.34", "0.119879"], ["84267.49", "0"], ["84267.50", "0"], ["84268.20", "0.002807"], ["84268.26", "0.006356"], ["84268.29", "0"], ["84268.42", "0"], ["84268.90", "0"], ["84269.03", "0"], ["84269.31", "0"], ["84269.46", "0"], ["84269.84", "0"], ["84269.91", "0.015891"], ["84270.20", "0.007385"], ["84270.49", "0.010986"], ["84270.68", "0"], ["84271.27", "0"], ["84271.77", "0"], ["84272.04", "0"], ["84272.20", "0.019435"], ["84272.33", "0"], ["84273.39", "0"], ["84274.12", "0"], ["84274.20", "0.051145"], ["84275.64", "0"], ["84275.65", "0"], ["84275.68", "0"], ["84276.20", "0.134592"], ["84276.90", "0"], ["84277.44", "0"], ["84278.20", "0.354191"], ["84278.24", "0"], ["84278.27", "0"], ["84278.90", "0"], ["84280.20", "0.932081"], ["84280.66", "0"], ["84280.68", "0.026414"], ["84280.90", "0"], ["84282.20", "2.452843"], ["84282.90", "0"], ["84284.20", "6.454851"], ["84284.60", "0.549480"], ["84284.90", "0"], ["84285.10", "0.001030"], ["84285.40", "0.001042"], ["84285.70", "0.001027"], ["84285.90", "0.035610"], ["84286.20", "0.069990"], ["84286.90", "0"], ["84287.10", "3.732090"], ["84287.70", "0.249060"], ["84287.80", "0.350370"], ["84287.90", "2.978430"], ["84288.20", "0.069780"], ["84288.90", "0"], ["84289.50", "0.035580"], ["84290.20", "0.069780"], ["84290.90", "0"], ["84291.30", "2.193270"], ["84292.20", "3.755370"], ["84292.90", "0"], ["84293.20", "0.064260"], ["84293.46", "0"], ["84294.00", "6.186780"], ["84294.20", "0.069600"], ["84294.90", "0"], ["84295.20", "0.410370"], ["84295.60", "1.779300"], ["84296.20", "0.069600"], ["84296.50", "0.025350"], ["84296.80", "0.035580"], ["84296.90", "2.666370"], ["84297.10", "0.461730"], ["84297.30", "0"], ["84297.40", "0.142500"], ["84298.00", "0.015090"], ["84298.20", "0.069600"], ["84298.50", "1.075560"], ["84298.60", "0"], ["84299.00", "0.309570"], ["84299.20", "0"], ["84299.70", "0"], ["84300.20", "0.015180"], ["84301.40", "0.240000"], ["84302.20", "0"], ["84302.30", "0"], ["84302.40", "0"], ["84302.90", "0"], ["84303.40", "0"], ["84303.60", "0"], ["84303.70", "0"], ["84303.80", "0"], ["84305.30", "0"], ["84305.70", "0"], ["84306.20", "0"], ["84306.60", "0"], ["84307.40", "0"], ["84307.80", "0"], ["84308.10", "0"], ["84308.20", "0"], ["84308.50", "0"], ["84309.50", "0"], ["84309.70", "0"], ["84310.20", "0"], ["84310.40", "0"], ["84311.40", "0"], ["84326.30", "4.522120"], ["84334.80", "5.516986"], ["84339.00", "0"], ["84343.30", "4.341235"], ["84347.50", "0"], ["84351.80", "4.160350"], ["84356.00", "0"], ["84360.30", "4.974332"], ["84364.50", "0"], ["84368.80", "4.069908"], ["84373.00", "0"], ["84377.30", "5.155216"], ["84381.50", "0"], ["84385.80", "5.245659"], ["84390.00", "0.002000"], ["84392.12", "0"], ["84394.30", "4.431677"], ["84398.50", "0"], ["84402.80", "3.979465"], ["84407.00", "0"], ["84411.30", "4.883889"], ["84415.50", "0"], ["84419.80", "4.250792"], ["84424.00", "0"], ["84428.30", "4.703004"], ["84432.50", "0"], ["84436.80", "5.064774"], ["84441.00", "0"], ["84445.30", "5.426543"], ["84449.50", "0"], ["84453.80", "5.607428"], ["84458.00", "0"], ["84462.30", "4.612562"], ["84466.50", "0"], ["84470.80", "3.889023"], ["84475.00", "0"], ["84479.30", "4.793447"], ["84483.50", "0"], ["84487.80", "5.336101"], ["84492.00", "0"], ["84500.50", "0"], ["84520.51", "0"], ["84850.00", "0"], ["84851.66", "0"], ["84852.81", "0"], ["84852.94", "0"], ["84853.56", "0"], ["84857.14", "0"], ["84858.75", "0"], ["84859.29", "0"], ["84860.00", "0"], ["84862.90", "0"], ["84864.69", "0"], ["84864.86", "0"], ["84864.99", "0"]], "bids": [["84243.43", "0"], ["84232.50", "0"], ["84230.85", "0"], ["84230.50", "0"], ["84228.50", "0"], ["84227.88", "0"], ["84227.84", "0.000164"], ["84226.60", "0.353132"], ["84226.59", "0"], ["84226.50", "0"], ["84226.49", "1.895866"], ["84225.19", "0"], ["84225.12", "0"], ["84224.50", "0"], ["84224.42", "0.012680"], ["84222.50", "0"], ["84222.41", "0"], ["84221.80", "0"], ["84221.75", "0"], ["84221.34", "0"], ["84221.23", "0"], ["84220.96", "0"], ["84220.77", "0"], ["84220.65", "0"], ["84220.63", "0"], ["84220.50", "0"], ["84219.97", "0"], ["84219.80", "0.001029"], ["84219.26", "0"], ["84219.00", "0.010000"], ["84218.81", "0"], ["84218.63", "0"], ["84218.58", "0"], ["84218.50", "0"], ["84217.80", "0.001032"], ["84217.58", "0"], ["84217.36", "0"], ["84217.35", "0"], ["84216.50", "0"], ["84216.44", "0"], ["84216.10", "0"], ["84215.94", "0"], ["84215.80", "0.001014"], ["84214.66", "0"], ["84214.52", "0"], ["84214.50", "0"], ["84214.49", "0.248117"], ["84214.15", "0"], ["84213.80", "0.001007"], ["84213.20", "0.017844"], ["84212.84", "0.018269"], ["84212.50", "0"], ["84212.40", "0"], ["84212.20", "0"], ["84212.19", "0.005940"], ["84212.14", "0.015778"], ["84212.10", "0"], ["84212.00", "0"], ["84211.80", "0.001012"], ["84211.74", "0.016468"], ["84211.20", "0.006568"], ["84211.04", "0.056381"], ["84210.97", "0.007123"], ["84210.83", "0.017087"], ["84210.25", "0.017069"], ["84210.22", "0.007320"], ["84210.19", "0.028821"], ["84210.10", "0"], ["84209.90", "0"], ["84209.85", "0.007937"], ["84209.80", "0.001027"], ["84209.73", "0.008992"], ["84209.68", "0.227779"], ["84209.64", "2.551201"], ["84209.60", "0"], ["84209.40", "0"], ["84209.19", "0.313279"], ["84209.17", "0.017340"], ["84209.16", "0"], ["84209.08", "0.007515"], ["84209.07", "0.007646"], ["84209.00", "0"], ["84208.10", "0.008287"], ["84207.84", "0.012655"], ["84207.80", "0.001029"], ["84207.54", "0.052132"], ["84207.02", "0.222836"], ["84207.00", "0"], ["84206.94", "0.018528"], ["84206.59", "0.272028"], ["84206.23", "0.002064"], ["84205.93", "0.025096"], ["84205.80", "0.002560"], ["84205.50", "0"], ["84205.05", "0.263453"], ["84204.80", "0"], ["84204.78", "0.076049"], ["84204.70", "0.021118"], ["84203.80", "0.006736"], ["84203.50", "0"], ["84202.72", "0.012445"], ["84202.13", "0.002951"], ["84201.99", "0.005554"], ["84201.91", "0.009635"], ["84201.80", "0.017726"], ["84201.30", "0"], ["84200.84", "0.073540"], ["84200.20", "0"], ["84199.90", "0"], ["84199.80", "0.046649"], ["84199.74", "0.056665"], ["84199.20", "0.001014"], ["84199.10", "0.001680"], ["84198.90", "0"], ["84198.60", "0.001033"], ["84198.40", "0.001026"], ["84197.80", "0"], ["84197.00", "0"], ["84196.40", "0.039420"], ["84195.70", "0.058290"], ["84195.50", "0.109200"], ["84193.80", "0.142500"], ["84193.10", "0.035610"], ["84191.40", "0.843630"], ["84191.30", "0.015180"], ["84190.90", "0.089760"], ["84190.50", "0.009000"], ["84190.00", "0.915360"], ["84189.50", "0.013860"], ["84189.00", "0.090000"], ["84188.20", "0.431790"], ["84188.00", "0.987180"], ["84187.40", "0.142500"], ["84187.30", "0.099270"], ["84187.10", "1.061640"], ["84186.40", "0.090000"], ["84186.20", "0.462600"], ["84184.20", "0"], ["84178.99", "0.007585"], ["84170.40", "0"], ["84161.90", "0"], ["84157.70", "4.250792"], ["84153.40", "0"], ["84149.20", "4.431677"], ["84144.90", "0"], ["84140.70", "4.612562"], ["84136.40", "0"], ["84132.20", "3.889023"], ["84127.90", "0"], ["84123.70", "5.336101"], ["84119.40", "0"], ["84115.20", "5.064774"], ["84110.90", "0"], ["84106.70", "4.883889"], ["84102.40", "0"], ["84098.20", "5.155216"], ["84093.90", "0"], ["84089.70", "5.607428"], ["84085.40", "0"], ["84081.20", "4.703004"], ["84076.90", "0"], ["84072.70", "4.974332"], ["84068.40", "0"], ["84064.20", "3.979465"], ["84059.90", "0"], ["84055.70", "4.069908"], ["84051.40", "0"], ["84047.20", "5.245659"], ["84042.90", "0"], ["84038.70", "4.522120"], ["84036.61", "0"], ["84034.40", "0"], ["84030.20", "5.426543"], ["84025.90", "0"], ["84021.70", "5.516986"], ["84017.40", "0"], ["84013.20", "4.793447"], ["84008.90", "0"], ["84004.70", "4.341235"], ["83996.20", "4.160350"], ["83988.50", "0.027265"], ["83863.64", "0"], ["83863.52", "0"], ["83860.29", "0"], ["83860.10", "0"], ["83860.00", "0"], ["83859.94", "0"], ["83859.35", "0"], ["83859.25", "0"], ["83858.82", "0"], ["83857.50", "0"]], "checksum": 1081059816, "ts": "1742142229114"}], "ts": 1742142229117, "record_time": 1742142228.22652}
{"action": "update", "arg": {"instType": "SPOT", "channel": "books", "instId": "BTCUSDT"}, "data": [{"asks": [["84227.85", "1.085606"], ["84232.24", "0.063847"], ["84232.34", "0.140003"], ["84232.44", "0.487607"], ["84232.45", "0"], ["84232.46", "0"], ["84232.49", "0"], ["84232.50", "0"], ["84234.43", "0.004595"], ["84234.45", "0.001230"], ["84234.47", "0.004974"], ["84234.48", "0.005541"], ["84234.50", "0.000245"], ["84234.51", "0.015269"], ["84234.58", "0.001066"], ["84235.27", "0.017892"], ["84235.29", "0.020765"], ["84235.30", "0.007553"], ["84235.31", "0.017712"], ["84235.38", "0.004739"], ["84235.95", "0.007688"], ["84240.93", "0.244311"], ["84243.44", "0.263533"], ["84247.00", "0"], ["84250.41", "0.012680"], ["84253.51", "0.035952"], ["84253.82", "0.006356"], ["84257.42", "0.006356"], ["84261.41", "0"], ["84261.81", "0"], ["84266.20", "0.001013"], ["84268.20", "0.002635"], ["84269.83", "0"], ["84270.20", "0.006933"], ["84272.20", "0.018245"], ["84274.20", "0.048015"], ["84276.20", "0.126354"], ["84278.20", "0.332510"], ["84278.26", "0"], ["84280.20", "0.875028"], ["84282.20", "2.302705"], ["84284.20", "6.059750"], ["84284.60", "0.407430"], ["84285.10", "0"], ["84285.40", "0"], ["84285.70", "0"], ["84285.90", "0"], ["84286.20", "0"], ["84286.30", "0.001028"], ["84287.10", "0.663300"], ["84287.90", "1.628250"], ["84288.20", "0"], ["84288.70", "0.410370"], ["84290.20", "0.069600"], ["84291.30", "0.429900"], ["84292.20", "2.447250"], ["84292.60", "0.015090"], ["84293.20", "0"], ["84293.80", "0.015180"], ["84294.50", "0.064080"], ["84295.20", "0"], ["84295.50", "0.117000"], ["84296.50", "0"], ["84296.90", "2.266980"], ["84297.40", "0.154950"], ["84298.00", "0"], ["84300.20", "0"], ["84301.40", "0"], ["84310.01", "0"], ["84326.30", "4.883889"], ["84334.80", "4.431677"], ["84343.30", "5.607428"], ["84351.80", "5.336101"], ["84360.30", "4.160350"], ["84368.80", "5.516986"], ["84377.30", "3.889023"], ["84385.80", "4.522120"], ["84392.12", "0.209200"], ["84394.30", "4.250792"], ["84411.30", "5.426543"], ["84419.80", "5.245659"], ["84428.30", "5.064774"], ["84436.80", "4.703004"], ["84445.30", "4.612562"], ["84453.80", "4.069908"], ["84462.30", "4.793447"], ["84469.46", "0.001720"], ["84470.80", "4.341235"], ["84479.30", "5.155216"], ["84487.80", "4.974332"], ["84578.98", "1.712819"], ["84591.74", "0"], ["84846.55", "0"], ["84846.85", "0"], ["84847.58", "0"], ["84847.82", "0"], ["84849.88", "0"]], "bids": [["84227.84", "0.446370"], ["84226.61", "0.000164"], ["84226.50", "0.572564"], ["84226.20", "0.185492"], ["84223.78", "0.140004"], ["84222.42", "0.003309"], ["84219.00", "0"], ["84214.50", "0.074435"], ["84213.99", "0.127766"], ["84213.80", "0.002701"], ["84211.80", "0.007108"], ["84209.80", "0.018704"], ["84209.71", "0.084478"], ["84209.15", "0.008538"], ["84209.12", "0.007720"], ["84209.11", "0.000213"], ["84207.90", "0.007346"], ["84207.80", "0.049222"], ["84207.76", "0.008988"], ["84207.74", "0.006213"], ["84207.69", "0.007442"], ["84207.67", "0.008556"], ["84207.66", "0.006540"], ["84207.65", "0.001199"], ["84206.64", "0.008147"], ["84206.03", "0.007873"], ["84205.94", "0.014097"], ["84205.80", "0.129532"], ["84205.70", "0.008168"], ["84205.03", "0.007475"], ["84203.80", "0.340874"], ["84202.00", "0.004937"], ["84201.96", "0.005089"], ["84201.91", "0.010510"], ["84201.86", "0.008156"], ["84201.80", "0.897035"], ["84200.67", "0.008674"], ["84199.80", "2.360619"], ["84198.40", "0"], ["84198.20", "0.035610"], ["84196.40", "0"], ["84195.70", "0"], ["84195.50", "0.181500"], ["84193.10", "0"], ["84191.50", "0.177960"], ["84191.40", "1.378140"], ["84191.30", "0"], ["84189.00", "0"], ["84187.30", "2.359890"], ["84186.40", "0"], ["84185.60", "0.383430"], ["84185.50", "0.012600"], ["84183.35", "0.008208"], ["84179.12", "0.007186"], ["84170.26", "0.017810"], ["84157.70", "5.516986"], ["84149.20", "4.250792"], ["84140.70", "4.522120"], ["84132.20", "5.155216"], ["84123.70", "4.703004"], ["84115.20", "3.979465"], ["84098.20", "3.889023"], ["84089.70", "4.793447"], ["84081.20", "4.341235"], ["84072.70", "5.064774"], ["84064.20", "4.069908"], ["84055.70", "5.245659"], ["84047.20", "5.607428"], ["84038.70", "4.431677"], ["84030.20", "4.974332"], ["84021.70", "4.160350"], ["84013.20", "5.426543"], ["84009.24", "0.209200"], ["84004.70", "5.336101"], ["83996.20", "4.612562"], ["83917.69", "0"], ["83905.03", "1.605180"], ["83880.00", "0"], ["83877.97", "0"], ["83877.55", "0"], ["83877.42", "0"], ["83877.29", "0"], ["83877.05", "0"], ["83876.25", "0"], ["83876.12", "0"], ["83875.99", "0"], ["83875.49", "0"], ["83875.16", "0"], ["83875.00", "0"], ["83874.55", "0"], ["83874.15", "0"], ["83873.87", "0"], ["83873.52", "0"], ["83870.97", "0"], ["83870.95", "0"], ["83870.78", "0"], ["83870.00", "0"], ["83869.57", "0"], ["83868.82", "0"], ["83866.67", "0"], ["83865.80", "0"], ["83865.10", "0"], ["83864.54", "0"]], "checksum": 843756425, "ts": "1742142229314"}], "ts": 1742142229317, "record_time": 1742142228.426278}
{"action": "update", "arg": {"instType": "SPOT", "channel": "books", "instId": "BTCUSDT"}, "data": [{"asks": [["84227.85", "0.000479"], ["84232.24", "0"], ["84232.34", "0"], ["84232.44", "0"], ["84234.43", "0"], ["84234.45", "0"], ["84234.47", "0"], ["84234.48", "0"], ["84234.50", "0"], ["84234.51", "0"], ["84234.58", "0"], ["84235.27", "0.009386"], ["84235.29", "0"], ["84235.31", "0"], ["84235.38", "0"], ["84235.95", "0"], ["84238.10", "0.030015"], ["84240.93", "0"], ["84240.94", "0"], ["84243.44", "0.054333"], ["84247.02", "0.028247"], ["84250.41", "0"], ["84251.87", "0"], ["84252.38", "1.895970"], ["84253.51", "0"], ["84253.82", "0"], ["84256.84", "0"], ["84257.31", "0"], ["84257.42", "0"], ["84262.64", "0.010000"], ["84267.34", "0"], ["84268.20", "0.001035"], ["84269.23", "2.228120"], ["84270.20", "0.001148"], ["84272.20", "0.003023"], ["84274.20", "0.007953"], ["84276.20", "0.020929"], ["84276.57", "0"], ["84278.20", "0.055078"], ["84279.57", "0"], ["84280.20", "0.144941"], ["84282.20", "0.381425"], ["84284.20", "1.003749"], ["84284.60", "0.001260"], ["84285.20", "0.707250"], ["84286.30", "0"], ["84286.40", "0.831090"], ["84286.50", "2.418300"], ["84287.10", "0"], ["84287.70", "0"], ["84287.80", "0.350190"], ["84287.90", "0"], ["84288.70", "0"], ["84289.50", "0"], ["84290.20", "0"], ["84292.20", "1.242090"], ["84293.10", "0.469080"], ["84294.00", "0.953130"], ["84294.20", "0.410370"], ["84295.30", "0.032940"], ["84295.60", "0"], ["84296.30", "0.180000"], ["84297.20", "0.090000"], ["84297.40", "0.289950"], ["84326.30", "5.426543"], ["84334.80", "5.245659"], ["84343.30", "4.160350"], ["84351.80", "4.612562"], ["84360.30", "4.522120"], ["84368.80", "5.155216"], ["84377.30", "4.883889"], ["84385.80", "4.069908"], ["84394.30", "4.341235"], ["84400.55", "0.209200"], ["84402.80", "4.974332"], ["84411.30", "5.607428"], ["84419.80", "3.979465"], ["84428.30", "4.793447"], ["84436.80", "5.336101"], ["84445.30", "4.431677"], ["84453.80", "4.250792"], ["84462.30", "4.703004"], ["84470.80", "5.516986"], ["84479.30", "3.889023"], ["84487.80", "5.064774"], ["84846.55", "0.000019"], ["84846.85", "0.000176"], ["84847.58", "0.000039"], ["84847.82", "0.000671"], ["84849.88", "0.000030"], ["84850.00", "0.000031"], ["84851.66", "0.000029"], ["84852.81", "0.000115"], ["84852.94", "0.000065"], ["84853.56", "0.000050"], ["84857.14", "0.000347"], ["84858.75", "0.000285"], ["84859.29", "0.000036"], ["84860.00", "0.000169"], ["84862.90", "0.000169"], ["84864.69", "0.000052"], ["84864.86", "0.000041"], ["84864.99", "0.000033"], ["84866.10", "0.000064"], ["84866.40", "0.000018"], ["84867.80", "0.000095"]], "bids": [["84227.84", "0.932640"], ["84224.42", "0"], ["84222.42", "0"], ["84220.76", "0.010000"], ["84215.80", "0.001673"], ["84213.80", "0.004404"], ["84211.80", "0.011590"], ["84209.80", "0.030500"], ["84209.71", "0"], ["84209.65", "0.725103"], ["84208.43", "0.003071"], ["84207.80", "0.080261"], ["84207.74", "0"], ["84207.02", "0"], ["84205.93", "0"], ["84205.80", "0.211214"], ["84205.70", "0"], ["84205.35", "0"], ["84205.03", "0"], ["84203.80", "0.555826"], ["84202.00", "0"], ["84201.99", "0"], ["84201.91", "0.000875"], ["84201.86", "0"], ["84201.80", "1.462702"], ["84199.80", "3.849214"], ["84199.70", "0.001003"], ["84199.10", "0.001470"], ["84198.20", "0.089130"], ["84197.80", "0.069600"], ["84195.80", "0.069600"], ["84195.50", "0.478590"], ["84192.48", "0.023755"], ["84191.60", "0.063480"], ["84191.40", "2.728140"], ["84188.70", "0.038490"], ["84187.30", "0.009000"], ["84186.20", "0"], ["84185.60", "0"], ["84185.50", "0"], ["84183.35", "0"], ["84178.99", "0"], ["84165.00", "0.000159"], ["84149.20", "3.889023"], ["84140.70", "5.336101"], ["84123.70", "4.069908"], ["84115.20", "4.974332"], ["84106.70", "4.522120"], ["84098.20", "4.883889"], ["84089.70", "4.250792"], ["84081.20", "5.426543"], ["84072.70", "4.793447"], ["84064.20", "4.703004"], ["84055.70", "4.341235"], ["84047.20", "4.612562"], ["84038.70", "5.607428"], ["84030.20", "5.064774"], ["84021.70", "3.979465"], ["84013.20", "4.431677"], ["84004.70", "4.160350"], ["83996.20", "5.245659"], ["83880.00", "0.020454"], ["83877.97", "0.000023"], ["83877.55", "0.000010"], ["83877.42", "0.000054"], ["83877.29", "0.000024"], ["83877.05", "0.000008"], ["83876.25", "0.000028"]], "checksum": -1798417069, "ts": "1742142229517"}], "ts": 1742142229521, "record_time": 1742142228.630967}
{"action": "update", "arg": {"instType": "SPOT", "channel": "books", "instId": "BTCUSDT"}, "data": [{"asks": [["84227.85", "0"], ["84234.44", "0"], ["84235.27", "0"], ["84235.30", "0"], ["84235.96", "0"], ["84237.64", "0.063843"], ["84239.83", "0.140001"], ["84242.40", "0.004595"], ["84242.41", "0.010074"], ["84242.43", "0.004974"], ["84242.48", "0.008962"], ["84242.49", "0.006307"], ["84243.24", "0.009386"], ["84243.25", "0.008506"], ["84243.26", "0.007627"], ["84243.27", "0.014912"], ["84243.28", "0.001162"], ["84243.34", "0.004739"], ["84247.02", "0"], ["84247.95", "0"], ["84251.20", "0"], ["84253.14", "0.209200"], ["84253.61", "0"], ["84253.83", "0.080082"], ["84255.76", "0"], ["84260.94", "0.119869"], ["84262.06", "0.042308"], ["84262.64", "0"], ["84263.64", "0"], ["84264.20", "0"], ["84264.51", "0.012680"], ["84265.54", "0.016427"], ["84265.65", "0.006356"], ["84265.68", "0.017806"], ["84266.20", "0"], ["84268.20", "0"], ["84269.97", "0.119879"], ["84270.20", "0"], ["84270.64", "0.001807"], ["84272.20", "0.001005"], ["84274.20", "0.001013"], ["84276.20", "0.001031"], ["84278.20", "0.001238"], ["84280.20", "0.003258"], ["84282.20", "0.008573"], ["84284.20", "0.022561"], ["84284.60", "0"], ["84285.20", "0"], ["84286.20", "0.059371"], ["84286.40", "0"], ["84286.50", "0"], ["84287.80", "0"], ["84288.20", "0.156241"], ["84290.20", "0.411160"], ["84291.30", "0"], ["84292.20", "1.081999"], ["84292.30", "0.001033"], ["84292.60", "0.001023"], ["84293.10", "0.411120"], ["84293.70", "0.091110"], ["84293.80", "0"], ["84294.00", "0"], ["84294.20", "0"], ["84294.40", "2.350260"], ["84294.50", "0.479970"], ["84295.30", "0"], ["84295.50", "0"], ["84296.20", "0"], ["84296.30", "0"], ["84296.80", "0"], ["84296.90", "0.659760"], ["84297.10", "0"], ["84297.20", "0"], ["84297.40", "0.142500"], ["84298.20", "0"], ["84298.50", "0"], ["84299.00", "0"], ["84300.20", "0.015150"], ["84300.60", "1.350000"], ["84300.80", "0.015180"], ["84302.00", "1.469670"], ["84302.30", "1.978590"], ["84302.40", "0.065550"], ["84302.50", "0.070950"], ["84303.70", "6.363810"], ["84303.80", "0.142500"], ["84305.10", "0.135000"], ["84305.50", "2.292000"], ["84306.60", "0.117000"], ["84307.40", "0.180000"], ["84326.30", "0"], ["84334.30", "3.979088"], ["84334.80", "0"], ["84342.80", "4.702558"], ["84343.30", "0"], ["84351.30", "5.064294"], ["84351.80", "0"], ["84359.80", "5.426029"], ["84360.30", "0"], ["84368.30", "4.340823"], ["84368.80", "0"], ["84376.80", "5.335595"], ["84377.30", "0"], ["84385.30", "4.792992"], ["84385.80", "0"], ["84393.80", "5.516463"], ["84394.30", "0"], ["84402.30", "4.159956"], ["84402.80", "0"], ["84408.98", "0.209200"], ["84410.80", "3.888654"], ["84411.30", "0"], ["84419.30", "4.431257"], ["84419.80", "0"], ["84427.80", "5.245161"], ["84428.30", "0"], ["84436.30", "4.521691"], ["84436.80", "0"], ["84444.80", "4.883426"], ["84445.30", "0"], ["84453.30", "4.250389"], ["84453.80", "0"], ["84461.80", "4.612125"], ["84462.30", "0"], ["84470.30", "4.069522"], ["84470.80", "0"], ["84478.80", "5.606896"], ["84479.30", "0"], ["84487.30", "5.154727"], ["84487.80", "0"], ["84495.80", "4.973860"], ["84860.00", "0"], ["84862.90", "0"], ["84864.69", "0"], ["84864.86", "0"], ["84864.99", "0"], ["84866.10", "0"], ["84866.40", "0"], ["84867.80", "0"]], "bids": [["84237.63", "0.181895"], ["84235.79", "1.895864"], ["84234.44", "1.133800"], ["84232.06", "0.203170"], ["84227.84", "0.639289"], ["84227.80", "0.001022"], ["84226.61", "0"], ["84226.49", "0"], ["84225.80", "0.001050"], ["84223.80", "0.001329"], ["84223.78", "0"], ["84221.80", "0.003499"], ["84220.77", "0.003309"], ["84220.76", "0"], ["84219.80", "0.009207"], ["84219.66", "0.248163"], ["84218.94", "2.551197"], ["84218.25", "0.084494"], ["84217.80", "0.024230"], ["84217.10", "0.008539"], ["84217.08", "0.001230"], ["84217.07", "0.006703"], ["84217.04", "0.007515"], ["84217.02", "0.007646"], ["84215.80", "0.063763"], ["84215.69", "0.006213"], ["84215.61", "0.015096"], ["84215.60", "0.001199"], ["84214.60", "0.008147"], ["84214.49", "0"], ["84214.16", "0.025100"], ["84214.08", "0.002064"], ["84214.07", "0.007873"], ["84213.93", "0.008170"], ["84213.80", "0.167797"], ["84212.99", "0.007475"], ["84211.80", "0.441571"], ["84209.95", "0.005554"], ["84209.91", "0.005089"], ["84209.87", "0.000875"], ["84209.86", "0.009635"], ["84209.80", "1.162029"], ["84209.65", "0.226186"], ["84209.64", "0"], ["84209.15", "0"], ["84209.12", "0"], ["84209.11", "0"], ["84209.08", "0"], ["84209.07", "0"], ["84208.62", "0.008674"], ["84208.43", "0"], ["84208.41", "0.010235"], ["84207.90", "0"], ["84207.80", "3.057970"], ["84207.76", "0"], ["84207.70", "0.404100"], ["84207.69", "0"], ["84207.67", "0"], ["84207.66", "0"], ["84207.65", "0"], ["84207.54", "0.055083"], ["84207.00", "0.001001"], ["84206.90", "0.001036"], ["84206.64", "0"], ["84206.60", "0.142680"], ["84206.23", "0"], ["84206.03", "0"], ["84205.80", "0.069780"], ["84204.80", "1.746570"], ["84203.80", "0.069780"], ["84203.40", "2.731050"], ["84202.13", "0"], ["84201.96", "0"], ["84201.91", "0"], ["84201.80", "0.069780"], ["84201.20", "0.701940"], ["84200.67", "0"], ["84200.20", "0.142680"], ["84199.80", "7.228080"], ["84199.70", "0"], ["84199.20", "0"], ["84199.10", "0"], ["84198.60", "0"], ["84198.40", "0.177960"], ["84198.20", "0"], ["84198.00", "1.093380"], ["84196.90", "0.003900"], ["84195.60", "0.410370"], ["84195.50", "0.160320"], ["84194.70", "0.177540"], ["84191.60", "0.064860"], ["84191.40", "2.193630"], ["84191.30", "0.008208"], ["84190.50", "0"], ["84190.00", "0.000071"], ["84189.50", "0"], ["84188.70", "0"], ["84188.20", "0"], ["84188.00", "0"], ["84187.40", "0"], ["84187.30", "0"], ["84187.10", "0"], ["84187.07", "0.007186"], ["84186.94", "0.007585"], ["84182.02", "0.017808"], ["84179.12", "0"], ["84170.26", "0"], ["84168.00", "0.000121"], ["84165.70", "4.069522"], ["84157.70", "0"], ["84157.20", "5.335595"], ["84149.20", "0"], ["84148.70", "5.064294"], ["84140.70", "0"], ["84140.20", "4.250389"], ["84132.20", "0"], ["84131.70", "4.431257"], ["84123.70", "0"], ["84123.20", "3.979088"], ["84115.20", "0"], ["84114.70", "4.883426"], ["84106.70", "0"], ["84106.20", "4.973860"], ["84098.20", "0"], ["84097.70", "5.154727"], ["84089.70", "0"], ["84089.20", "4.792992"], ["84081.20", "0"], ["84080.70", "4.340823"], ["84072.70", "0"], ["84072.20", "5.606896"], ["84064.20", "0"], ["84063.70", "4.521691"], ["84055.70", "0"], ["84055.20", "3.888654"], ["84047.20", "0"], ["84046.70", "5.426029"], ["84038.70", "0"], ["84038.20", "5.516463"], ["84030.20", "0"], ["84029.70", "4.612125"], ["84021.70", "0"], ["84021.20", "4.702558"], ["84013.20", "0"], ["84012.70", "5.245161"], ["84004.70", "0"], ["84004.20", "4.159956"], ["83996.20", "0"], ["83950.23", "0"], ["83882.92", "0"], ["83881.99", "0"], ["83880.00", "0"], ["83877.97", "0"], ["83877.55", "0"], ["83877.42", "0"], ["83877.29", "0"], ["83877.05", "0"], ["83876.25", "0"]], "checksum": -1334803442, "ts": "1742142229720"}], "ts": 1742142229726, "record_time": 1742142228.833865}
{"action": "update", "arg": {"instType": "SPOT", "channel": "books", "instId": "BTCUSDT"}, "data": [{"asks": [["84237.64", "0.333914"], ["84242.42", "0.001230"], ["84242.44", "0.005541"], ["84242.46", "0.000245"], ["84242.54", "0.001066"], ["84243.25", "0.016461"], ["84243.26", "0.012810"], ["84243.28", "0.010353"], ["84244.97", "0.005675"], ["84249.23", "0"], ["84254.08", "0"], ["84254.68", "0.001205"], ["84258.89", "0"], ["84264.02", "0.010985"], ["84275.92", "0.031812"], ["84276.20", "0.001057"], ["84278.20", "0.002781"], ["84280.20", "0.007319"], ["84282.20", "0.019260"], ["84284.20", "0.050684"], ["84286.20", "0.133381"], ["84286.33", "0.029802"], ["84288.20", "0.351002"], ["84290.20", "0.923688"], ["84292.20", "2.430760"], ["84294.30", "1.049700"], ["84294.50", "0.479790"], ["84294.89", "0"], ["84300.60", "1.759560"], ["84302.00", "0.484200"], ["84303.60", "1.779300"], ["84305.10", "0"], ["84305.50", "1.346010"], ["84307.20", "0.410370"], ["84307.40", "2.849670"], ["84334.30", "4.792992"], ["84351.30", "3.888654"], ["84359.80", "4.521691"], ["84368.30", "4.883426"], ["84376.80", "4.069522"], ["84385.30", "3.979088"], ["84393.80", "4.973860"], ["84402.30", "4.340823"], ["84410.80", "5.516463"], ["84419.30", "4.250389"], ["84427.80", "5.426029"], ["84436.30", "4.431257"], ["84444.80", "4.159956"], ["84453.30", "5.064294"], ["84461.80", "5.335595"], ["84470.30", "5.245161"], ["84478.80", "4.612125"], ["84495.80", "5.606896"], ["84851.66", "0"], ["84852.81", "0"], ["84852.94", "0"], ["84853.56", "0"], ["84857.14", "0"], ["84858.75", "0"], ["84859.29", "0"]], "bids": [["84237.63", "1.417139"], ["84235.80", "0.568759"], ["84234.45", "0.401091"], ["84234.44", "0.209200"], ["84232.06", "0"], ["84227.84", "0.417085"], ["84226.50", "0"], ["84223.80", "0.001328"], ["84221.80", "0.003496"], ["84219.80", "0.009199"], ["84217.80", "0.024208"], ["84216.18", "0.056384"], ["84215.84", "0.007346"], ["84215.80", "0.063706"], ["84215.71", "0.008988"], ["84215.63", "0.007442"], ["84214.50", "0"], ["84213.80", "0.167646"], ["84213.00", "0.007953"], ["84211.80", "0.441173"], ["84211.04", "0"], ["84209.95", "0.010491"], ["84209.81", "0.008156"], ["84209.80", "1.160983"], ["84207.80", "3.055217"], ["84207.70", "0.710880"], ["84206.90", "0"], ["84205.80", "0"], ["84204.80", "0.405570"], ["84204.40", "0.915360"], ["84203.80", "0"], ["84203.40", "0"], ["84202.50", "0.462600"], ["84201.80", "0.069600"], ["84201.20", "0"], ["84200.20", "0.142500"], ["84199.80", "4.879800"], ["84198.00", "0.178020"], ["84196.90", "0"], ["84196.60", "0.090000"], ["84196.40", "0.090000"], ["84195.60", "0.670080"], ["84195.50", "0.014010"], ["84193.10", "0.090000"], ["84192.30", "0.090000"], ["84192.10", "0.090000"], ["84191.40", "2.675220"], ["84190.90", "0"], ["84165.70", "5.606896"], ["84157.20", "4.069522"], ["84148.70", "5.516463"], ["84140.20", "4.702558"], ["84131.70", "4.792992"], ["84123.20", "4.431257"], ["84114.70", "4.250389"], ["84106.20", "5.064294"], ["84097.70", "4.340823"], ["84089.20", "5.426029"], ["84080.70", "4.521691"], ["84072.20", "4.612125"], ["84063.70", "5.335595"], ["84046.70", "5.154727"], ["84038.20", "4.159956"], ["84029.70", "5.245161"], ["84021.20", "4.973860"], ["84012.70", "3.979088"], ["84004.20", "4.883426"], ["83884.62", "0"], ["83884.55", "0"], ["83884.30", "0"], ["83882.98", "0"]], "checksum": 1887799911, "ts": "1742142229922"}], "ts": 1742142229925, "record_time": 1742142229.03385}
{"action": "update", "arg": {"instType": "SPOT", "channel": "books", "instId": "BTCUSDT"}, "data": [{"asks": [["84237.64", "0.203270"], ["84237.65", "0.000100"], ["84237.66", "0.000100"], ["84237.67", "0.000100"], ["84238.10", "0"], ["84244.23", "0"], ["84244.97", "0"], ["84244.98", "0"], ["84246.46", "0"], ["84252.37", "0.659126"], ["84252.38", "0"], ["84253.14", "0"], ["84257.84", "0"], ["84257.85", "0"], ["84258.40", "0.022090"], ["84258.41", "0"], ["84258.47", "0"], ["84258.88", "0"], ["84259.18", "0"], ["84259.66", "0"], ["84259.89", "0"], ["84259.91", "0"], ["84260.28", "0"], ["84260.44", "0"], ["84260.56", "0"], ["84260.89", "0"], ["84261.06", "0"], ["84261.84", "0"], ["84262.29", "0"], ["84262.59", "0"], ["84263.38", "0"], ["84263.86", "0.006356"], ["84264.88", "0"], ["84264.90", "0.006356"], ["84265.36", "0.006356"], ["84265.66", "0.006356"], ["84265.70", "0"], ["84265.94", "0"], ["84266.14", "0.006356"], ["84266.19", "0"], ["84266.36", "0.006356"], ["84266.91", "0.006356"], ["84267.05", "0.006356"], ["84267.38", "0.006356"], ["84268.26", "0"], ["84269.23", "0"], ["84269.86", "0.009989"], ["84269.91", "0"], ["84270.49", "0"], ["84272.20", "0"], ["84272.42", "0.015892"], ["84272.96", "0.009989"], ["84274.20", "0"], ["84274.30", "0.001035"], ["84274.74", "0.006356"], ["84275.92", "0"], ["84276.20", "0"], ["84276.30", "0.001034"], ["84278.20", "0"], ["84278.30", "0.001006"], ["84280.20", "0"], ["84280.30", "0.001036"], ["84282.20", "0"], ["84282.30", "0.001040"], ["84284.20", "0"], ["84284.30", "0.001034"], ["84286.20", "0"], ["84286.30", "0.002721"], ["84286.33", "0"], ["84288.20", "0"], ["84288.30", "0.007162"], ["84290.20", "0"], ["84290.30", "0.018847"], ["84292.20", "0"], ["84292.30", "0.049596"], ["84292.60", "0"], ["84293.10", "0"], ["84293.70", "0"], ["84294.30", "0.130516"], ["84294.40", "0.001470"], ["84294.50", "0.419070"], ["84294.80", "0.001011"], ["84295.40", "0.098580"], ["84296.40", "0.001047"], ["84296.90", "0"], ["84297.40", "0.052410"], ["84300.20", "0"], ["84300.60", "0"], ["84300.90", "0.258030"], ["84302.00", "0.469080"], ["84302.50", "0.086130"], ["84303.60", "0"], ["84303.70", "0"], ["84304.10", "0.015180"], ["84306.60", "0"], ["84307.00", "0.035580"], ["84307.20", "0"], ["84307.40", "0"], ["84308.20", "1.127790"], ["84308.40", "0.985470"], ["84308.50", "0.262920"], ["84309.00", "0.009000"], ["84309.70", "7.015800"], ["84334.30", "0"], ["84336.50", "4.521574"], ["84342.80", "0"], ["84345.00", "5.245026"], ["84351.30", "0"], ["84353.50", "4.250280"], ["84359.80", "0"], ["84362.00", "3.888554"], ["84368.30", "0"], ["84370.50", "4.431143"], ["84376.80", "0"], ["84379.00", "4.883300"], ["84385.30", "0"], ["84387.50", "5.335458"], ["84393.80", "0"], ["84396.00", "4.159848"], ["84402.30", "0"], ["84404.50", "5.425889"], ["84410.80", "0"], ["84413.00", "4.069417"], ["84419.30", "0"], ["84421.50", "4.612006"], ["84427.80", "0"], ["84430.00", "5.064163"], ["84436.30", "0"], ["84438.50", "5.516321"], ["84444.80", "0"], ["84447.00", "4.973732"], ["84453.30", "0"], ["84455.50", "4.340711"], ["84461.80", "0"], ["84464.00", "4.792869"], ["84470.30", "0"], ["84472.50", "3.978985"], ["84478.80", "0"], ["84481.00", "5.606752"], ["84487.30", "0"], ["84489.50", "4.702437"], ["84495.80", "0"], ["84498.00", "5.154595"], ["84851.66", "0.000029"], ["84852.81", "0.000115"], ["84852.94", "0.000065"], ["84853.56", "0.000050"], ["84857.14", "0.000347"], ["84858.75", "0.000285"], ["84859.29", "0.000036"], ["84860.00", "0.000169"], ["84862.90", "0.000169"], ["84864.69", "0.000052"], ["84864.86", "0.000041"], ["84864.99", "0.000033"], ["84866.10", "0.000064"], ["84866.40", "0.000018"], ["84867.80", "0.000095"], ["84868.42", "0.000031"], ["84868.52", "0.000013"], ["84868.65", "0.000035"], ["84869.57", "0.000932"]], "bids": [["84237.63", "1.403734"], ["84237.57", "0.055182"], ["84234.45", "0.062760"], ["84233.96", "0.139998"], ["84230.00", "0.001046"], ["84228.00", "0.001037"], ["84227.84", "0.221429"], ["84227.80", "0"], ["84226.60", "0.356140"], ["84226.00", "0.001738"], ["84225.80", "0"], ["84224.00", "0.004573"], ["84223.80", "0"], ["84222.00", "0.012034"], ["84221.80", "0"], ["84220.00", "0.031669"], ["84219.80", "0"], ["84219.21", "0.017845"], ["84218.85", "0.018270"], ["84218.23", "0.016469"], ["84218.00", "0.083340"], ["84217.80", "0"], ["84217.68", "0.006568"], ["84217.45", "0.007123"], ["84217.31", "0.017088"], ["84217.14", "0.003038"], ["84216.67", "0.012656"], ["84216.66", "0.007320"], ["84216.33", "0.007937"], ["84216.20", "0.008993"], ["84216.00", "0.219316"], ["84215.80", "0"], ["84215.65", "0.017341"], ["84214.77", "0.008288"], ["84214.00", "0.577147"], ["84213.80", "0"], ["84213.42", "0.018530"], ["84213.20", "0"], ["84212.84", "0"], ["84212.19", "0"], ["84212.14", "0"], ["84212.00", "1.518807"], ["84211.80", "0"], ["84211.74", "0"], ["84211.46", "0.021120"], ["84211.26", "0.076054"], ["84211.20", "0"], ["84210.97", "0"], ["84210.83", "0"], ["84210.25", "0"], ["84210.22", "0"], ["84210.19", "0"], ["84210.00", "3.996861"], ["84209.85", "0"], ["84209.80", "0.070200"], ["84209.73", "0"], ["84209.68", "0"], ["84209.40", "0.001002"], ["84209.30", "2.350890"], ["84209.20", "0.012446"], ["84209.17", "0"], ["84208.80", "0.001007"], ["84208.70", "0.001030"], ["84208.30", "0.035580"], ["84208.10", "0"], ["84207.84", "0"], ["84207.80", "7.332570"], ["84207.70", "0.402840"], ["84207.54", "0.002951"], ["84207.20", "0.274770"], ["84207.00", "0"], ["84206.94", "0"], ["84206.59", "0"], ["84205.80", "0.069780"], ["84205.05", "0"], ["84204.80", "0"], ["84204.78", "0"], ["84204.70", "0"], ["84204.40", "0.915540"], ["84203.50", "0.202470"], ["84203.30", "0.013170"], ["84202.72", "0"], ["84201.50", "0.064470"], ["84200.84", "0"], ["84199.80", "0.406710"], ["84199.74", "0"], ["84199.40", "0.009000"], ["84198.20", "0.090000"], ["84197.30", "0.090000"], ["84196.70", "0.038490"], ["84196.30", "0.090000"], ["84195.60", "0.885660"], ["84194.70", "0"], ["84193.80", "0"], ["84193.10", "0"], ["84192.48", "0"], ["84192.30", "0"], ["84192.10", "0"], ["84191.60", "0"], ["84191.50", "0"], ["84191.40", "0"], ["84167.80", "4.250280"], ["84165.70", "0"], ["84159.30", "5.335458"], ["84157.20", "0"], ["84150.80", "4.431143"], ["84148.70", "0"], ["84142.30", "5.064163"], ["84140.20", "0"], ["84133.80", "5.516321"], ["84131.70", "0"], ["84125.30", "4.521574"], ["84123.20", "0"], ["84116.80", "5.154595"], ["84114.70", "0"], ["84108.30", "4.792869"], ["84106.20", "0"], ["84099.80", "3.978985"], ["84097.70", "0"], ["84091.30", "4.159848"], ["84089.20", "0"], ["84082.80", "4.702437"], ["84080.70", "0"], ["84074.30", "4.883300"], ["84072.20", "0"], ["84065.80", "5.606752"], ["84063.70", "0"], ["84057.30", "5.245026"], ["84055.20", "0"], ["84048.80", "4.973732"], ["84046.70", "0"], ["84040.30", "5.425889"], ["84038.20", "0"], ["84031.80", "4.612006"], ["84029.70", "0"], ["84023.30", "4.069417"], ["84021.20", "0"], ["84014.80", "3.888554"], ["84012.70", "0"], ["84006.30", "4.340711"], ["84004.20", "0"], ["83884.62", "0.000014"]], "checksum": 1236608610, "ts": "1742142230124"}], "ts": 1742142230129, "record_time": 1742142229.239123}
{"action": "update", "arg": {"instType": "SPOT", "channel": "books", "instId": "BTCUSDT"}, "data": [{"asks": [["84239.83", "0"], ["84252.37", "0"], ["84253.90", "0.002907"], ["84254.58", "0.003017"], ["84255.80", "0.001827"], ["84258.40", "0"], ["84261.53", "0"], ["84266.80", "0.006356"], ["84267.43", "0.006356"], ["84268.51", "0.006357"], ["84268.77", "0.016428"], ["84269.04", "0.006356"], ["84269.91", "0.119843"], ["84270.64", "0"], ["84270.78", "0.010984"], ["84270.89", "0.148098"], ["84271.42", "0.006356"], ["84273.37", "0.119895"], ["84274.30", "0"], ["84274.46", "0.119881"], ["84274.50", "0.001044"], ["84276.30", "0"], ["84276.50", "0.001000"], ["84278.30", "0"], ["84278.50", "0.001046"], ["84278.77", "0.015891"], ["84279.45", "0.010986"], ["84280.30", "0"], ["84280.50", "0.001035"], ["84280.68", "0"], ["84282.30", "0"], ["84282.50", "0.001033"], ["84284.30", "0"], ["84284.50", "0.002061"], ["84286.30", "0"], ["84286.50", "0.005424"], ["84288.30", "0"], ["84288.50", "0.014272"], ["84290.30", "0"], ["84290.50", "0.037559"], ["84292.30", "0"], ["84292.50", "0.098839"], ["84294.30", "0"], ["84294.40", "0"], ["84294.50", "0.260270"], ["84295.40", "0.001050"], ["84295.60", "0.001045"], ["84296.40", "0"], ["84296.50", "0.001110"], ["84297.40", "0"], ["84298.40", "0.007890"], ["84300.60", "0.359610"], ["84300.80", "0"], ["84300.90", "0"], ["84301.50", "0.662640"], ["84302.00", "0"], ["84302.30", "0"], ["84302.40", "0"], ["84302.50", "2.365200"], ["84303.10", "0.015090"], ["84303.80", "0"], ["84305.10", "0.258030"], ["84305.50", "0"], ["84307.00", "0"], ["84308.20", "1.768680"], ["84308.50", "0.014040"], ["84309.70", "3.279510"], ["84310.20", "0.430500"], ["84310.40", "0.135000"], ["84312.10", "3.694380"], ["84312.30", "0.117000"], ["84336.50", "0"], ["84336.60", "5.154585"], ["84345.00", "0"], ["84345.10", "4.792860"], ["84353.50", "0"], ["84353.60", "4.431135"], ["84362.00", "0"], ["84362.10", "5.516311"], ["84370.50", "0"], ["84370.60", "4.159841"], ["84379.00", "0"], ["84379.10", "4.973723"], ["84387.50", "0"], ["84387.60", "4.521566"], ["84396.00", "0"], ["84396.10", "4.883292"], ["84404.50", "0"], ["84404.60", "3.888547"], ["84413.00", "0"], ["84413.10", "5.606742"], ["84421.50", "0"], ["84421.60", "4.250272"], ["84430.00", "0"], ["84430.10", "4.611998"], ["84438.50", "0"], ["84438.60", "4.069410"], ["84447.00", "0"], ["84447.10", "5.335448"], ["84455.50", "0"], ["84455.60", "3.978978"], ["84464.00", "0"], ["84464.10", "5.064154"], ["84472.50", "0"], ["84472.60", "5.245017"], ["84481.00", "0"], ["84481.10", "5.425879"], ["84489.50", "0"], ["84489.60", "4.702429"], ["84498.00", "0"], ["84498.10", "4.340704"], ["84864.86", "0"], ["84864.99", "0"], ["84866.10", "0"], ["84866.40", "0"], ["84867.80", "0"], ["84868.42", "0"], ["84868.52", "0"], ["84868.65", "0"], ["84869.57", "0"]], "bids": [["84237.63", "1.434730"], ["84234.45", "0.096914"], ["84230.10", "0.001045"], ["84230.00", "0"], ["84228.10", "0.001236"], ["84228.00", "0"], ["84226.10", "0.003254"], ["84226.00", "0"], ["84224.10", "0.008563"], ["84224.00", "0"], ["84222.10", "0.022533"], ["84222.00", "0"], ["84221.14", "0.005941"], ["84221.10", "0.015780"], ["84220.10", "0.059299"], ["84220.00", "0"], ["84219.07", "0.028823"], ["84219.00", "0.017070"], ["84218.52", "0.227795"], ["84218.10", "0.156050"], ["84218.00", "0"], ["84216.10", "0.410658"], ["84216.02", "0.052136"], ["84216.00", "0"], ["84215.07", "0.272047"], ["84214.10", "1.080677"], ["84214.00", "0"], ["84213.80", "0.263471"], ["84212.10", "2.843887"], ["84212.00", "0"], ["84210.10", "7.483915"], ["84210.00", "3.293130"], ["84209.80", "0.069990"], ["84209.70", "0.915750"], ["84209.69", "0.073545"], ["84209.40", "0"], ["84209.30", "2.350470"], ["84208.80", "0"], ["84208.70", "0"], ["84208.69", "0.056669"], ["84207.80", "1.483800"], ["84207.20", "0"], ["84205.80", "0.069600"], ["84205.20", "0.023752"], ["84205.00", "0.071640"], ["84204.80", "0.006840"], ["84204.40", "0"], ["84202.50", "0.177900"], ["84201.40", "0.410370"], ["84198.00", "0.418020"], ["84195.80", "0"], ["84195.60", "0"], ["84195.50", "0"], ["84168.00", "5.516311"], ["84167.80", "0"], ["84166.00", "0"], ["84159.50", "4.883292"], ["84159.30", "0"], ["84153.83", "0.072042"], ["84151.00", "4.702429"], ["84150.80", "0"], ["84142.50", "4.431135"], ["84142.30", "0"], ["84134.00", "3.888547"], ["84133.80", "0"], ["84125.50", "5.335448"], ["84125.30", "0"], ["84117.00", "4.973723"], ["84116.80", "0"], ["84108.50", "4.521566"], ["84108.30", "0"], ["84100.00", "4.250272"], ["84099.80", "0"], ["84091.50", "5.064154"], ["84091.30", "0"], ["84083.00", "4.792860"], ["84082.80", "0"], ["84074.50", "5.425879"], ["84074.30", "0"], ["84066.00", "4.611998"], ["84065.80", "0"], ["84057.50", "4.159841"], ["84057.30", "0"], ["84049.00", "5.245017"], ["84048.80", "0"], ["84040.50", "3.978978"], ["84040.30", "0"], ["84032.00", "4.069410"], ["84031.80", "0"], ["84023.50", "4.340704"], ["84023.30", "0"], ["84015.00", "5.606742"], ["84014.80", "0"], ["84006.50", "5.154585"], ["84006.30", "0"], ["83887.11", "0"], ["83886.91", "0"], ["83885.98", "0"], ["83885.71", "0"], ["83884.62", "0"]], "checksum": -1029885498, "ts": "1742142230331"}], "ts": 1742142230353, "record_time": 1742142229.469364}
{"action": "update", "arg": {"instType": "SPOT", "channel": "books", "instId": "BTCUSDT"}, "data": [{"asks": [["84237.64", "0"], ["84242.40", "0"], ["84242.41", "0"], ["84242.42", "0"], ["84242.43", "0"], ["84242.44", "0"], ["84242.46", "0"], ["84242.48", "0"], ["84242.49", "0"], ["84242.54", "0"], ["84243.24", "0"], ["84243.25", "0"], ["84243.26", "0"], ["84243.27", "0"], ["84243.28", "0"], ["84243.34", "0"], ["84243.44", "0"], ["84247.03", "0"], ["84250.84", "0.004595"], ["84250.85", "0.010074"], ["84250.87", "0.004974"], ["84250.88", "0.030015"], ["84250.89", "0.005541"], ["84250.91", "0.000245"], ["84250.92", "0.008962"], ["84250.98", "0.139996"], ["84250.99", "0.001066"], ["84251.68", "0.009308"], ["84251.69", "0.008584"], ["84251.70", "0.021208"], ["84251.71", "0.014469"], ["84251.78", "0.004739"], ["84253.82", "0.030262"], ["84253.83", "0"], ["84254.68", "0"], ["84260.94", "0"], ["84262.06", "0"], ["84262.33", "0.080082"], ["84263.86", "0"], ["84264.02", "0"], ["84264.41", "0.001205"], ["84264.51", "0"], ["84264.90", "0"], ["84265.02", "0"], ["84265.16", "1.895584"], ["84265.36", "0"], ["84265.54", "0"], ["84265.65", "0"], ["84265.66", "0"], ["84266.14", "0"], ["84266.36", "0"], ["84266.91", "0"], ["84267.05", "0"], ["84267.38", "0"], ["84268.51", "0"], ["84269.86", "0"], ["84269.97", "0"], ["84270.30", "0.119869"], ["84270.89", "0"], ["84271.45", "0.006356"], ["84271.47", "0.006356"], ["84271.61", "0.035952"], ["84272.42", "0"], ["84272.51", "0.006356"], ["84272.96", "0"], ["84272.98", "0.006356"], ["84273.28", "0.006356"], ["84273.49", "0.006356"], ["84274.46", "0.126237"], ["84274.50", "0.006356"], ["84274.62", "0.075100"], ["84274.74", "0"], ["84274.94", "0.016427"], ["84274.99", "0.006356"], ["84275.01", "0.006356"], ["84276.29", "0.001807"], ["84276.50", "0"], ["84276.61", "0.006357"], ["84277.48", "0.009989"], ["84278.50", "0"], ["84279.26", "0.119879"], ["84280.50", "0"], ["84280.52", "0.015892"], ["84280.58", "0.009989"], ["84280.60", "0.001002"], ["84281.41", "0.148098"], ["84282.01", "2.228506"], ["84282.50", "0"], ["84282.60", "0.001008"], ["84282.84", "0.006356"], ["84284.50", "0"], ["84284.60", "0.001018"], ["84286.50", "0"], ["84286.60", "0.001484"], ["84287.87", "0.031812"], ["84288.50", "0"], ["84288.60", "0.003906"], ["84290.50", "0"], ["84290.60", "0.010279"], ["84292.50", "0"], ["84292.60", "0.027051"], ["84294.50", "0"], ["84294.60", "0.071186"], ["84294.80", "0"], ["84295.40", "0"], ["84295.60", "0"], ["84296.50", "0"], ["84296.60", "0.187332"], ["84298.40", "0"], ["84298.60", "0.492979"], ["84300.60", "1.297313"], ["84300.70", "0.001018"], ["84301.50", "0.001026"], ["84302.20", "3.353490"], ["84302.50", "0.001022"], ["84303.10", "0"], ["84303.80", "0.142680"], ["84304.10", "0"], ["84304.60", "0.049080"], ["84305.10", "0"], ["84307.40", "0.430860"], ["84308.20", "1.669830"], ["84308.40", "0"], ["84308.80", "0.015120"], ["84309.70", "1.684980"], ["84310.01", "0.209200"], ["84310.20", "0.142500"], ["84310.40", "0.015120"], ["84311.70", "0.032910"], ["84312.10", "0"], ["84312.30", "0"], ["84312.60", "2.669430"], ["84313.20", "0.025350"], ["84313.30", "0.035580"], ["84313.70", "0.012660"], ["84313.80", "0.985470"], ["84314.80", "3.169620"], ["84315.20", "2.669430"], ["84316.50", "0.090000"], ["84316.60", "0.142500"], ["84316.70", "0.383400"], ["84317.00", "0.009000"], ["84336.60", "0"], ["84342.80", "4.521237"], ["84343.70", "0"], ["84345.10", "0"], ["84351.30", "5.244635"], ["84353.60", "0"], ["84359.80", "4.882936"], ["84362.10", "0"], ["84368.30", "4.973360"], ["84370.36", "0.072042"], ["84370.60", "0"], ["84376.80", "4.792511"], ["84379.10", "0"], ["84385.30", "5.606333"], ["84387.60", "0"], ["84393.80", "5.063785"], ["84396.10", "0"], ["84402.30", "5.425484"], ["84404.60", "0"], ["84408.98", "0"], ["84410.80", "3.888264"], ["84413.10", "0"], ["84419.30", "3.978688"], ["84421.60", "0"], ["84427.80", "5.154210"], ["84430.10", "0"], ["84436.30", "4.069113"], ["84438.60", "0"], ["84444.80", "5.515909"], ["84447.10", "0"], ["84453.30", "4.249963"], ["84455.60", "0"], ["84461.80", "4.430812"], ["84464.10", "0"], ["84470.30", "4.340387"], ["84472.60", "0"], ["84478.80", "4.611661"], ["84481.10", "0"], ["84487.30", "5.335059"], ["84489.60", "0"], ["84495.80", "4.159538"], ["84498.10", "0"], ["84504.30", "4.702086"], ["84859.29", "0"], ["84860.00", "0"], ["84862.90", "0"], ["84864.69", "0"]], "bids": [["84237.64", "1.566173"], ["84237.63", "1.465078"], ["84237.57", "0"], ["84236.30", "0.001050"], ["84235.80", "0"], ["84235.79", "0"], ["84234.44", "0"], ["84234.30", "0.001026"], ["84233.96", "0"], ["84232.30", "0.001255"], ["84230.30", "0.003303"], ["84230.10", "0"], ["84229.02", "0.248134"], ["84228.30", "0.008692"], ["84228.10", "0"], ["84227.85", "0.066429"], ["84227.80", "0.084484"], ["84227.70", "0.313279"], ["84226.82", "0.017845"], ["84226.60", "0"], ["84226.46", "0.018270"], ["84226.30", "0.022874"], ["84226.10", "0"], ["84225.84", "0.016469"], ["84225.50", "0.001230"], ["84225.49", "0.006703"], ["84225.46", "0.007515"], ["84225.45", "0.007646"], ["84225.29", "0.006568"], ["84224.92", "0.017088"], ["84224.79", "0.007123"], ["84224.75", "0.007320"], ["84224.30", "0.060194"], ["84224.29", "0.008993"], ["84224.27", "0.007346"], ["84224.13", "0.008988"], ["84224.11", "0.006213"], ["84224.10", "0"], ["84224.04", "0.006540"], ["84224.02", "0.001199"], ["84223.79", "0.007937"], ["84223.55", "0.025097"], ["84223.32", "0.008169"], ["84223.26", "0.017341"], ["84223.04", "0.008147"], ["84222.86", "0.008288"], ["84222.49", "0.002064"], ["84222.30", "0.158405"], ["84222.10", "0"], ["84221.44", "0.007953"], ["84221.43", "0.007475"], ["84221.03", "0.018530"], ["84220.30", "0.416856"], ["84220.10", "0"], ["84219.66", "0"], ["84219.35", "0.076054"], ["84219.21", "0"], ["84219.08", "0.021120"], ["84218.94", "0.222851"], ["84218.85", "0"], ["84218.37", "0.005554"], ["84218.34", "0.005089"], ["84218.30", "1.096989"], ["84218.29", "0.010510"], ["84218.25", "0"], ["84218.23", "0"], ["84218.10", "0"], ["84217.68", "0"], ["84217.45", "0"], ["84217.31", "0"], ["84217.29", "0.012446"], ["84217.25", "0.002951"], ["84217.14", "0"], ["84217.10", "0"], ["84217.08", "0"], ["84217.07", "0"], ["84217.04", "0.008674"], ["84217.02", "0"], ["84216.84", "0.010235"], ["84216.66", "0"], ["84216.33", "0"], ["84216.30", "2.886813"], ["84216.20", "0"], ["84216.18", "0"], ["84216.10", "0.454500"], ["84215.84", "0"], ["84215.80", "0.070830"], ["84215.71", "0"], ["84215.69", "0"], ["84215.65", "0"], ["84215.63", "0"], ["84215.61", "0"], ["84215.60", "0"], ["84214.77", "0"], ["84214.60", "0.035790"], ["84214.30", "0.001013"], ["84214.16", "0"], ["84214.10", "0"], ["84214.08", "0"], ["84214.07", "0"], ["84213.93", "0"], ["84213.42", "0"], ["84213.00", "0.142680"], ["84212.99", "0"], ["84212.10", "0"], ["84211.80", "0.069780"], ["84211.46", "0"], ["84211.26", "0"], ["84211.10", "2.261190"], ["84210.10", "2.575650"], ["84210.00", "0.002000"], ["84209.95", "0"], ["84209.91", "0"], ["84209.87", "0"], ["84209.86", "0"], ["84209.81", "0"], ["84209.80", "0.069600"], ["84209.70", "0.915360"], ["84209.65", "0.003309"], ["84209.50", "0.013140"], ["84209.30", "0"], ["84209.20", "0"], ["84209.19", "0"], ["84208.62", "0"], ["84208.41", "0"], ["84208.30", "0"], ["84207.80", "2.115540"], ["84207.70", "0"], ["84207.54", "0"], ["84206.60", "0.142500"], ["84205.94", "0"], ["84205.20", "0.038490"], ["84204.50", "0.383400"], ["84203.60", "0.090000"], ["84203.50", "0.288420"], ["84203.40", "0.090000"], ["84203.30", "0"], ["84200.10", "0.090000"], ["84199.80", "1.342800"], ["84199.40", "0"], ["84198.40", "0"], ["84198.20", "0"], ["84198.00", "0"], ["84197.80", "0"], ["84197.30", "0"], ["84196.70", "0"], ["84196.60", "0"], ["84196.40", "0"], ["84196.30", "0"], ["84194.80", "0.017805"], ["84191.30", "0"], ["84187.07", "0"], ["84186.94", "0"], ["84182.02", "0"], ["84174.10", "5.425484"], ["84168.00", "0.000121"], ["84167.00", "0"], ["84165.60", "4.069113"], ["84159.50", "0"], ["84157.10", "5.063785"], ["84153.83", "0"], ["84151.00", "0"], ["84148.60", "4.611661"], ["84142.50", "0"], ["84140.10", "4.159538"], ["84134.00", "0"], ["84131.60", "5.515909"], ["84125.50", "0"], ["84123.10", "5.244635"], ["84117.00", "0"], ["84114.60", "5.606333"], ["84108.50", "0"], ["84106.10", "4.973360"], ["84100.00", "0.002717"], ["84097.60", "5.335059"], ["84091.50", "0"], ["84089.10", "4.792511"], ["84083.00", "0"], ["84080.60", "3.888264"], ["84074.50", "0"], ["84072.10", "4.430812"], ["84066.00", "0"], ["84063.60", "4.521237"], ["84057.50", "0"], ["84055.10", "3.978688"], ["84049.00", "0"], ["84046.60", "4.340387"], ["84040.50", "0"], ["84038.10", "4.702086"], ["84032.00", "0.000165"], ["84029.60", "5.154210"], ["84023.50", "0"], ["84021.10", "4.882936"], ["84015.00", "0"], ["84012.60", "4.249963"], ["84006.50", "0"], ["83887.11", "0.000075"], ["83886.91", "0.000145"], ["83885.98", "0.000018"], ["83885.71", "0.000069"], ["83884.62", "0.000014"], ["83884.55", "0.000048"], ["83884.30", "0.000161"], ["83882.98", "0.000188"], ["83882.92", "0.002384"], ["83881.99", "0.000038"], ["83880.00", "0.020454"], ["83877.97", "0.000023"], ["83877.55", "0.000010"], ["83877.42", "0.000054"], ["83877.29", "0.000024"]], "checksum": -215610124, "ts": "1742142230537"}], "ts": 1742142230541, "record_time": 1742142229.650086}
{"action": "update", "arg": {"instType": "SPOT", "channel": "books", "instId": "BTCUSDT"}, "data": [{"asks": [["84237.65", "0.203270"], ["84245.86", "0.063838"], ["84250.82", "0.001230"], ["84250.88", "0.100557"], ["84250.98", "0"], ["84251.69", "0.017775"], ["84251.70", "0.022370"], ["84253.82", "0"], ["84254.57", "0.005004"], ["84261.32", "0.195055"], ["84262.61", "0.012680"], ["84269.79", "0.010985"], ["84271.70", "0.006356"], ["84284.60", "0.001348"], ["84286.60", "0.003547"], ["84288.60", "0.009333"], ["84290.60", "0.024561"], ["84292.60", "0.064635"], ["84294.60", "0.170091"], ["84296.60", "0.447608"], ["84298.60", "1.177918"], ["84300.60", "3.099783"], ["84300.70", "0"], ["84301.00", "0.001023"], ["84301.10", "0.001019"], ["84301.50", "0"], ["84301.60", "0.259260"], ["84302.20", "3.623640"], ["84302.50", "0"], ["84304.60", "0.212910"], ["84305.00", "0.469260"], ["84305.40", "0.985470"], ["84307.40", "0.466440"], ["84308.20", "7.169370"], ["84309.00", "0.419370"], ["84309.20", "0.015180"], ["84309.70", "0.957870"], ["84313.20", "0"], ["84313.80", "0"], ["84314.80", "3.927240"], ["84316.50", "0"], ["84316.60", "0"], ["84316.70", "0"], ["84317.00", "0"], ["84342.80", "4.882936"], ["84351.30", "5.063785"], ["84359.80", "5.515909"], ["84368.30", "5.606333"], ["84376.80", "5.154210"], ["84385.30", "4.611661"], ["84393.80", "4.430812"], ["84402.30", "3.978688"], ["84410.80", "4.249963"], ["84419.30", "4.792511"], ["84427.80", "3.888264"], ["84436.30", "5.425484"], ["84444.80", "4.521237"], ["84453.30", "4.340387"], ["84461.80", "4.702086"], ["84470.30", "5.335059"], ["84478.80", "4.973360"], ["84487.30", "4.069113"], ["84495.80", "5.244635"], ["84504.30", "4.159538"], ["84857.14", "0"], ["84858.75", "0"]], "bids": [["84237.64", "2.046871"], ["84237.63", "0.702562"], ["84234.97", "1.895650"], ["84234.45", "0"], ["84232.30", "0.001156"], ["84230.30", "0.003041"], ["84228.30", "0.008003"], ["84227.85", "0.177454"], ["84226.83", "0.014097"], ["84226.61", "0.166035"], ["84226.30", "0.021326"], ["84226.20", "0"], ["84225.48", "0.008539"], ["84224.51", "0.003070"], ["84224.30", "0.056119"], ["84223.98", "0.007442"], ["84223.96", "0.008556"], ["84222.30", "0.147683"], ["84222.26", "0.007873"], ["84221.94", "0.056384"], ["84220.77", "0.234419"], ["84220.30", "0.388638"], ["84218.33", "0.004937"], ["84218.31", "0.540876"], ["84218.30", "1.022733"], ["84218.19", "0.008156"], ["84218.12", "2.550918"], ["84216.30", "2.691401"], ["84216.10", "0.001050"], ["84215.80", "0.001023"], ["84214.60", "0.064830"], ["84214.30", "0"], ["84213.00", "0.142500"], ["84211.80", "0.069600"], ["84211.40", "1.319010"], ["84211.10", "0.405570"], ["84210.10", "0.026790"], ["84209.80", "0"], ["84209.70", "0"], ["84209.50", "0.020340"], ["84208.40", "0.274590"], ["84207.90", "0.987990"], ["84207.80", "1.482960"], ["84204.20", "0.462600"], ["84203.60", "0"], ["84203.50", "0.525300"], ["84203.40", "0"], ["84202.60", "0.915360"], ["84202.30", "0.090000"], ["84201.40", "0"], ["84200.20", "0"], ["84200.10", "0"], ["84199.80", "0"], ["84199.68", "0.008208"], ["84195.41", "0.007186"], ["84195.28", "0.007585"], ["84174.10", "4.249963"], ["84165.60", "5.425484"], ["84157.10", "4.159538"], ["84148.60", "5.063785"], ["84140.10", "5.335059"], ["84131.60", "4.340387"], ["84123.10", "4.973360"], ["84114.60", "4.069113"], ["84106.10", "5.606333"], ["84097.60", "3.888264"], ["84089.10", "4.611661"], ["84080.60", "4.702086"], ["84063.60", "5.515909"], ["84055.10", "4.521237"], ["84046.60", "4.882936"], ["84038.10", "3.978688"], ["84021.10", "5.244635"], ["84012.60", "4.792511"], ["83884.62", "0"], ["83884.55", "0"], ["83884.30", "0"], ["83882.98", "0"], ["83882.92", "0"], ["83881.99", "0"], ["83880.00", "0"], ["83877.97", "0"], ["83877.55", "0"], ["83877.42", "0"], ["83877.29", "0"]], "checksum": 1060478052, "ts": "1742142230738"}], "ts": 1742142230741, "record_time": 1742142229.849579}
{"action": "update", "arg": {"instType": "SPOT", "channel": "books", "instId": "BTCUSDT"}, "data": [{"asks": [["84248.73", "0.140006"], ["84250.88", "0.036322"], ["84265.15", "0.584666"], ["84284.60", "0.001044"], ["84286.60", "0.001691"], ["84288.60", "0.004451"], ["84290.60", "0.011713"], ["84292.60", "0.030719"], ["84294.60", "0.080840"], ["84296.60", "0.212738"], ["84298.60", "0.559835"], ["84300.60", "1.473250"], ["84300.90", "0.001046"], ["84301.60", "0.001029"], ["84301.80", "0.001044"], ["84302.20", "1.002420"], ["84302.30", "0.078630"], ["84303.11", "0.001597"], ["84303.80", "0"], ["84303.82", "0"], ["84304.60", "2.350170"], ["84305.40", "0"], ["84305.80", "0.258030"], ["84307.40", "0.430860"], ["84308.20", "6.285720"], ["84309.00", "0.009000"], ["84313.30", "1.021050"], ["84314.70", "0.065550"], ["84315.20", "0"], ["84342.80", "4.611661"], ["84351.30", "4.069113"], ["84359.80", "4.882936"], ["84368.30", "4.430812"], ["84376.80", "4.340387"], ["84385.30", "4.702086"], ["84393.80", "5.154210"], ["84410.80", "5.515909"], ["84419.30", "4.159538"], ["84427.80", "5.335059"], ["84436.30", "3.888264"], ["84453.30", "4.792511"], ["84461.80", "4.249963"], ["84470.30", "4.973360"], ["84478.80", "5.244635"], ["84487.30", "5.606333"], ["84495.80", "5.063785"], ["84504.30", "5.425484"], ["84851.66", "0"], ["84852.81", "0"], ["84852.94", "0"], ["84853.56", "0"]], "bids": [["84234.98", "0.569350"], ["84232.30", "0.001564"], ["84230.78", "0.190982"], ["84230.30", "0.004115"], ["84228.30", "0.010828"], ["84226.61", "0"], ["84226.30", "0.028496"], ["84224.30", "0.074989"], ["84222.30", "0.197340"], ["84220.30", "0.519315"], ["84218.31", "0"], ["84218.30", "1.366619"], ["84216.30", "3.596366"], ["84214.60", "0.186570"], ["84213.80", "1.579200"], ["84213.50", "0.274590"], ["84213.00", "0.142680"], ["84211.80", "0.069780"], ["84211.40", "1.318950"], ["84210.50", "0.915360"], ["84208.40", "0"], ["84207.80", "1.491960"], ["84203.50", "0.245460"], ["84203.20", "0.090000"], ["84202.60", "0"], ["84201.60", "0.090000"], ["84201.50", "0"], ["84189.41", "0"], ["84188.70", "0.001181"], ["84174.10", "5.606333"], ["84165.60", "4.249963"], ["84164.00", "0.000159"], ["84157.10", "4.069113"], ["84148.60", "4.430812"], ["84140.10", "4.973360"], ["84131.60", "3.978688"], ["84123.10", "4.702086"], ["84114.60", "4.521237"], ["84106.10", "5.425484"], ["84097.60", "5.063785"], ["84089.10", "3.888264"], ["84080.60", "4.159538"], ["84072.10", "4.340387"], ["84063.60", "5.335059"], ["84055.10", "4.792511"], ["84038.10", "4.611661"], ["84029.60", "5.244635"], ["84021.10", "5.154210"], ["84012.60", "5.515909"], ["83885.98", "0"], ["83885.71", "0"]], "checksum": 614402514, "ts": "1742142230938"}], "ts": 1742142230941, "record_time": 1742142230.048888}
{"action": "update", "arg": {"instType": "SPOT", "channel": "books", "instId": "BTCUSDT"}, "data": [{"asks": [["84237.65", "0.000100"], ["84245.86", "0"], ["84248.73", "0"], ["84250.82", "0"], ["84250.84", "0"], ["84250.85", "0"], ["84250.87", "0"], ["84250.88", "0"], ["84250.89", "0"], ["84250.91", "0"], ["84250.92", "0"], ["84250.99", "0"], ["84251.68", "0.007385"], ["84251.69", "0.000078"], ["84251.70", "0"], ["84251.71", "0.007110"], ["84251.78", "0"], ["84254.57", "0"], ["84255.38", "0"], ["84262.61", "0"], ["84263.83", "0"], ["84265.16", "0"], ["84266.80", "0"], ["84267.43", "0"], ["84268.77", "0"], ["84269.04", "0"], ["84269.79", "0"], ["84269.90", "0.135311"], ["84269.91", "0"], ["84270.78", "0"], ["84271.42", "0"], ["84273.37", "0"], ["84282.01", "0"], ["84286.60", "0.001012"], ["84287.87", "0"], ["84288.60", "0.001210"], ["84290.60", "0.003184"], ["84292.60", "0.008379"], ["84294.60", "0.022050"], ["84296.60", "0.058028"], ["84298.60", "0.152704"], ["84300.60", "0.401853"], ["84301.50", "0.001008"], ["84301.80", "0"], ["84302.20", "0"], ["84303.00", "0.709410"], ["84304.60", "3.196620"], ["84305.00", "0"], ["84308.20", "1.483020"], ["84314.80", "1.779300"], ["84342.80", "5.244635"], ["84345.76", "0"], ["84351.30", "3.888264"], ["84359.80", "4.611661"], ["84368.30", "4.882936"], ["84373.09", "0.072042"], ["84376.80", "4.521237"], ["84385.30", "4.069113"], ["84393.80", "4.702086"], ["84410.80", "5.606333"], ["84419.30", "4.430812"], ["84427.80", "4.249963"], ["84436.30", "4.792511"], ["84444.80", "4.973360"], ["84453.30", "5.154210"], ["84461.80", "5.425484"], ["84470.30", "4.340387"], ["84478.80", "5.515909"], ["84487.30", "5.335059"], ["84495.80", "4.159538"], ["84504.30", "5.063785"], ["84851.66", "0.000029"], ["84852.81", "0.000115"], ["84852.94", "0.000065"], ["84853.56", "0.000050"], ["84857.14", "0.000347"], ["84858.75", "0.000285"], ["84859.29", "0.000036"], ["84860.00", "0.000169"], ["84862.90", "0.000169"], ["84864.69", "0.000052"], ["84864.86", "0.000041"], ["84864.99", "0.000033"], ["84866.10", "0.000064"], ["84866.40", "0.000018"], ["84867.80", "0.000095"], ["84868.42", "0.000031"], ["84868.52", "0.000013"], ["84868.65", "0.000035"], ["84869.57", "0.000932"], ["84871.66", "0.000078"], ["84871.79", "0.000014"], ["84873.84", "0.000057"], ["84874.79", "0.000096"], ["84875.00", "0.000959"], ["84875.78", "0.000038"], ["84876.03", "0.000161"], ["84879.10", "0.000009"], ["84879.37", "0.000009"], ["84879.59", "0.000173"]], "bids": [["84237.64", "2.046941"], ["84237.63", "0.702492"], ["84234.97", "0"], ["84232.30", "0.002292"], ["84230.30", "0.006031"], ["84228.30", "0.015870"], ["84227.84", "0.221073"], ["84226.31", "0.096904"], ["84226.30", "0.041763"], ["84225.50", "0"], ["84225.49", "0.006490"], ["84225.48", "0"], ["84224.30", "0.109904"], ["84224.27", "0"], ["84224.13", "0"], ["84224.11", "0"], ["84224.04", "0"], ["84224.02", "0"], ["84223.96", "0"], ["84222.49", "0"], ["84222.30", "0.289221"], ["84222.26", "0"], ["84221.94", "0"], ["84221.44", "0"], ["84221.14", "0"], ["84221.10", "0"], ["84220.30", "0.761108"], ["84219.07", "0"], ["84219.00", "0"], ["84218.52", "0"], ["84218.34", "0"], ["84218.33", "0"], ["84218.30", "2.002916"], ["84218.29", "0"], ["84218.19", "0"], ["84218.12", "0"], ["84217.04", "0"], ["84216.84", "0"], ["84216.67", "0"], ["84216.30", "5.270831"], ["84216.02", "0"], ["84215.07", "0"], ["84214.60", "0.914070"], ["84214.10", "0.444660"], ["84213.80", "1.579560"], ["84213.50", "0"], ["84204.60", "0.025350"], ["84202.50", "0"], ["84199.68", "0"], ["84195.41", "0"], ["84195.28", "0"], ["84174.10", "5.244635"], ["84165.60", "4.340387"], ["84157.10", "4.882936"], ["84148.60", "5.515909"], ["84140.10", "4.792511"], ["84131.60", "4.430812"], ["84123.10", "3.888264"], ["84114.60", "5.606333"], ["84106.10", "4.973360"], ["84097.60", "4.159538"], ["84089.10", "4.069113"], ["84080.60", "4.611661"], ["84072.10", "5.425484"], ["84063.60", "3.978688"], ["84055.10", "5.154210"], ["84046.60", "4.702086"], ["84038.10", "5.063785"], ["84029.60", "4.249963"], ["84021.10", "5.335059"], ["84012.60", "4.521237"], ["83885.98", "0.000018"], ["83885.71", "0.000069"], ["83884.62", "0.000014"], ["83884.55", "0.000048"], ["83884.30", "0.000161"], ["83882.98", "0.000188"], ["83882.92", "0.002384"], ["83881.99", "0.000038"], ["83880.00", "0.020454"], ["83877.97", "0.000023"], ["83877.55", "0.000010"], ["83877.42", "0.000054"], ["83877.29", "0.000024"], ["83877.05", "0.000008"], ["83876.25", "0.000028"], ["83876.12", "0.000681"], ["83875.99", "0.000299"], ["83875.49", "0.000723"], ["83875.16", "0.000179"], ["83875.00", "0.000145"], ["83874.55", "0.000145"], ["83874.15", "0.000150"], ["83873.87", "0.000041"], ["83873.52", "0.000135"], ["83870.97", "0.000194"], ["83870.95", "0.000078"], ["83870.78", "0.000019"], ["83870.00", "0.000121"], ["83869.57", "0.000035"], ["83868.82", "0.000017"]], "checksum": -1531591194, "ts": "1742142231138"}], "ts": 1742142231142, "record_time": 1742142230.251017}
{"action": "update", "arg": {"instType": "SPOT", "channel": "books", "instId": "BTCUSDT"}, "data": [{"asks": [["84237.65", "0"], ["84237.68", "0.000100"], ["84237.69", "0.000100"], ["84251.68", "0"], ["84251.69", "0"], ["84251.71", "0"], ["84252.29", "0.063833"], ["84257.45", "0.004595"], ["84257.46", "0.010074"], ["84257.47", "0.001230"], ["84257.48", "0.004974"], ["84257.49", "0.005541"], ["84257.51", "0.000245"], ["84257.52", "0.008962"], ["84257.57", "0.006307"], ["84257.59", "0.001066"], ["84257.61", "0.030015"], ["84258.33", "0.009308"], ["84258.34", "0.008584"], ["84258.35", "0.007955"], ["84258.36", "0.020169"], ["84258.38", "0.001605"], ["84258.39", "0.007110"], ["84258.43", "0.004739"], ["84261.32", "0.013932"], ["84262.94", "0.209200"], ["84265.15", "0"], ["84265.68", "0"], ["84269.90", "0"], ["84271.60", "0.012680"], ["84271.89", "1.895587"], ["84274.08", "0.006356"], ["84274.36", "0.006356"], ["84275.09", "0.010985"], ["84275.85", "0.006356"], ["84276.08", "0.016428"], ["84276.29", "0"], ["84277.08", "0.119843"], ["84277.53", "0.017804"], ["84278.07", "0.010984"], ["84278.49", "0.006356"], ["84280.00", "0.119895"], ["84280.60", "0"], ["84282.24", "0.001807"], ["84282.60", "0"], ["84283.81", "0.010000"], ["84284.60", "0"], ["84286.60", "0"], ["84287.40", "0.001026"], ["84287.48", "0.031812"], ["84288.60", "0"], ["84288.74", "2.228503"], ["84289.40", "0.001038"], ["84290.60", "0"], ["84291.40", "0.001700"], ["84292.60", "0"], ["84293.40", "0.004474"], ["84294.60", "0"], ["84295.40", "0.011774"], ["84296.60", "0"], ["84297.40", "0.030985"], ["84298.60", "0"], ["84299.40", "0.081538"], ["84300.60", "0"], ["84300.90", "0"], ["84301.00", "0"], ["84301.10", "0"], ["84301.40", "0.214574"], ["84301.50", "0"], ["84301.60", "0"], ["84302.30", "0"], ["84303.00", "0"], ["84303.40", "0.564668"], ["84304.60", "0"], ["84305.40", "1.485970"], ["84305.80", "0"], ["84307.40", "3.910445"], ["84308.10", "0.001046"], ["84308.20", "2.328360"], ["84308.80", "0"], ["84308.90", "2.350050"], ["84309.20", "0"], ["84309.50", "0.258030"], ["84309.70", "0.273270"], ["84310.20", "0.142680"], ["84310.40", "0"], ["84311.70", "0"], ["84312.20", "0.069600"], ["84312.60", "0"], ["84313.30", "0"], ["84313.70", "0.481740"], ["84314.00", "0.406110"], ["84314.10", "0.035430"], ["84314.70", "0"], ["84314.80", "0.581310"], ["84315.30", "0.064890"], ["84315.70", "0.015210"], ["84315.80", "1.350000"], ["84316.10", "0.015090"], ["84316.60", "0.142500"], ["84317.10", "0.009000"], ["84317.30", "0.015120"], ["84317.40", "0.117000"], ["84318.00", "0.410370"], ["84318.10", "8.288550"], ["84342.80", "0"], ["84349.50", "4.520875"], ["84351.30", "0"], ["84358.00", "5.515468"], ["84359.80", "0"], ["84366.50", "4.972963"], ["84368.30", "0"], ["84375.00", "3.887953"], ["84376.80", "0"], ["84383.50", "4.340040"], ["84385.30", "0"], ["84392.00", "4.701710"], ["84393.80", "0"], ["84400.50", "5.063380"], ["84402.30", "0"], ["84408.98", "0.209200"], ["84409.00", "4.882545"], ["84410.80", "0"], ["84417.50", "5.153798"], ["84419.30", "0"], ["84426.00", "5.244215"], ["84427.80", "0"], ["84434.50", "4.430458"], ["84436.30", "0"], ["84443.00", "4.792128"], ["84444.80", "0"], ["84451.50", "4.249623"], ["84453.30", "0"], ["84460.00", "5.334633"], ["84461.80", "0"], ["84468.50", "4.611293"], ["84470.30", "0"], ["84477.00", "3.978370"], ["84478.80", "0"], ["84485.50", "4.159205"], ["84487.30", "0"], ["84494.00", "4.068788"], ["84495.80", "0"], ["84502.50", "5.605885"], ["84504.30", "0"], ["84511.00", "5.425050"], ["84852.81", "0"], ["84852.94", "0"], ["84853.56", "0"], ["84857.14", "0"], ["84858.75", "0"], ["84859.29", "0"], ["84860.00", "0"], ["84862.90", "0"], ["84864.69", "0"], ["84864.86", "0"], ["84864.99", "0"], ["84866.10", "0"], ["84866.40", "0"], ["84867.80", "0"], ["84868.42", "0"], ["84868.52", "0"], ["84868.65", "0"], ["84869.57", "0"], ["84871.66", "0"], ["84871.79", "0"], ["84873.84", "0"], ["84874.79", "0"], ["84875.00", "0"], ["84875.78", "0"], ["84876.03", "0"], ["84879.10", "0"], ["84879.37", "0"], ["84879.59", "0"]], "bids": [["84237.65", "1.916083"], ["84237.64", "0.905958"], ["84237.00", "0.005152"], ["84236.30", "0"], ["84235.50", "0.003008"], ["84235.00", "0.013559"], ["84234.99", "0.171800"], ["84234.98", "0"], ["84234.30", "0"], ["84233.00", "0.035680"], ["84232.30", "0"], ["84232.14", "0.001230"], ["84232.13", "0.006490"], ["84232.12", "0.008539"], ["84232.08", "0.000213"], ["84232.05", "0.007515"], ["84232.04", "0.007646"], ["84231.00", "0.093896"], ["84230.78", "0.198328"], ["84230.64", "0.008988"], ["84230.62", "0.006213"], ["84230.57", "0.007443"], ["84230.55", "0.015096"], ["84230.53", "0.001199"], ["84230.30", "0"], ["84229.64", "0.008147"], ["84229.00", "0.247094"], ["84228.98", "0.002064"], ["84228.91", "0.007873"], ["84228.41", "0.005941"], ["84228.30", "0"], ["84228.05", "0.007953"], ["84228.03", "0.007475"], ["84228.02", "0.015780"], ["84227.23", "0.056384"], ["84227.01", "2.550835"], ["84227.00", "0.650247"], ["84226.83", "0"], ["84226.37", "0.028823"], ["84226.30", "0"], ["84226.02", "0.003037"], ["84225.81", "0.017070"], ["84225.68", "0.227795"], ["84225.49", "0"], ["84225.46", "0"], ["84225.45", "0"], ["84225.00", "1.711177"], ["84224.97", "0.004937"], ["84224.96", "0.005554"], ["84224.93", "0.005089"], ["84224.88", "0.010510"], ["84224.83", "0.008156"], ["84224.30", "0"], ["84223.98", "0"], ["84223.73", "0.012656"], ["84223.55", "0.033773"], ["84223.35", "0.010235"], ["84223.31", "0.052136"], ["84223.04", "0"], ["84223.00", "4.503097"], ["84222.90", "0.246690"], ["84222.30", "0"], ["84222.20", "0.001017"], ["84221.80", "0.001017"], ["84221.70", "0.272047"], ["84221.43", "0"], ["84221.40", "0.001042"], ["84221.30", "0.035580"], ["84220.50", "0.405570"], ["84220.30", "0"], ["84219.80", "0.791490"], ["84219.40", "0.542520"], ["84218.37", "0"], ["84218.30", "0"], ["84217.60", "0.915360"], ["84216.30", "1.957140"], ["84216.20", "0.689700"], ["84216.10", "0"], ["84215.80", "0.344190"], ["84215.50", "0.462600"], ["84215.20", "2.350110"], ["84214.60", "0"], ["84214.10", "0"], ["84213.80", "0.263471"], ["84213.00", "0.142500"], ["84212.00", "0.040470"], ["84211.90", "0.038460"], ["84211.80", "0.069600"], ["84211.40", "0"], ["84211.10", "0"], ["84210.50", "0"], ["84209.50", "0"], ["84207.90", "0"], ["84207.80", "2.479950"], ["84207.00", "0.178890"], ["84206.31", "0.008208"], ["84206.20", "0.090000"], ["84206.10", "0.177960"], ["84205.80", "0"], ["84205.20", "0.023752"], ["84205.00", "0"], ["84204.80", "0"], ["84204.60", "0"], ["84204.50", "0"], ["84204.20", "0"], ["84203.50", "0"], ["84203.20", "0"], ["84202.30", "0"], ["84201.99", "0.007186"], ["84201.87", "0.007585"], ["84201.80", "0"], ["84201.60", "0"], ["84180.90", "4.430458"], ["84174.10", "0"], ["84172.40", "5.063380"], ["84169.00", "0.012838"], ["84165.60", "0"], ["84163.90", "4.972963"], ["84157.10", "0"], ["84155.40", "5.244215"], ["84148.60", "0"], ["84146.90", "4.882545"], ["84140.10", "0"], ["84138.40", "4.340040"], ["84131.60", "0"], ["84129.90", "4.520875"], ["84123.10", "0"], ["84122.97", "0.001017"], ["84121.40", "4.611293"], ["84114.60", "0"], ["84112.90", "5.153798"], ["84106.10", "0"], ["84104.40", "5.425050"], ["84097.60", "0"], ["84095.90", "5.515468"], ["84089.10", "0"], ["84087.40", "4.159205"], ["84080.60", "0"], ["84078.90", "3.887953"], ["84072.10", "0"], ["84070.40", "5.605885"], ["84063.60", "0"], ["84061.90", "4.701710"], ["84055.10", "0"], ["84053.40", "3.978370"], ["84046.60", "0"], ["84044.90", "4.249623"], ["84038.10", "0"], ["84036.40", "4.792128"], ["84029.60", "0"], ["84027.90", "5.334633"], ["84021.10", "0"], ["84019.40", "4.068788"], ["84012.60", "0"], ["83884.30", "0"], ["83882.98", "0"], ["83882.92", "0"], ["83881.99", "0"], ["83880.00", "0"], ["83877.97", "0"], ["83877.55", "0"], ["83877.42", "0"], ["83877.29", "0"], ["83877.05", "0"], ["83876.25", "0"], ["83876.12", "0"], ["83875.99", "0"], ["83875.49", "0"], ["83875.16", "0"], ["83875.00", "0"], ["83874.55", "0"], ["83874.15", "0"], ["83873.87", "0"], ["83873.52", "0"], ["83870.97", "0"], ["83870.95", "0"], ["83870.78", "0"], ["83870.00", "0"], ["83869.57", "0"], ["83868.82", "0"]], "checksum": -841717591, "ts": "1742142231341"}], "ts": 1742142231344, "record_time": 1742142230.453522}
{"action": "update", "arg": {"instType": "SPOT", "channel": "books", "instId": "BTCUSDT"}, "data": [{"asks": [["84253.89", "0.002325"], ["84255.18", "0.140002"], ["84257.50", "0.031820"], ["84258.33", "0.018499"], ["84291.40", "0.001944"], ["84292.80", "0"], ["84293.40", "0.005117"], ["84295.40", "0.013465"], ["84297.40", "0.035435"], ["84299.40", "0.093249"], ["84301.40", "0.245392"], ["84303.40", "0.645770"], ["84305.40", "1.699395"], ["84305.45", "0.001597"], ["84307.40", "4.472091"], ["84308.20", "1.199790"], ["84310.20", "0.142500"], ["84314.10", "0.035580"], ["84317.40", "0"], ["84318.40", "0.032910"], ["84349.50", "4.430458"], ["84358.00", "3.978370"], ["84366.50", "5.605885"], ["84375.00", "4.792128"], ["84383.50", "4.159205"], ["84392.00", "5.334633"], ["84400.50", "5.153798"], ["84409.00", "5.244215"], ["84417.50", "3.887953"], ["84426.00", "5.063380"], ["84434.50", "4.701710"], ["84443.00", "4.520875"], ["84460.00", "5.515468"], ["84468.50", "4.882545"], ["84477.00", "4.340040"], ["84485.50", "4.611293"], ["84494.00", "4.972963"], ["84502.50", "5.425050"], ["84511.00", "4.068788"], ["84849.88", "0"], ["84850.00", "0"], ["84851.66", "0"]], "bids": [["84237.65", "4.415374"], ["84237.64", "0.355444"], ["84237.63", "0.349360"], ["84237.00", "0.004219"], ["84235.00", "0.011104"], ["84234.99", "0"], ["84233.01", "0.020194"], ["84233.00", "0.029220"], ["84231.00", "0.076896"], ["84229.00", "0.202356"], ["84227.00", "0.532516"], ["84225.00", "1.401521"], ["84223.00", "3.688008"], ["84222.50", "0.715800"], ["84222.31", "0.418908"], ["84221.40", "0"], ["84220.77", "0"], ["84220.70", "5.054160"], ["84219.80", "0"], ["84219.40", "0.153090"], ["84216.30", "1.964430"], ["84216.10", "0.274590"], ["84215.80", "0.069600"], ["84210.49", "0.023952"], ["84210.10", "0.009180"], ["84207.80", "2.569950"], ["84206.90", "0.090000"], ["84200.89", "0"], ["84194.92", "0.001190"], ["84182.29", "0"], ["84180.90", "4.068788"], ["84172.40", "4.520875"], ["84155.40", "3.887953"], ["84146.90", "4.340040"], ["84138.40", "5.515468"], ["84129.90", "4.249623"], ["84121.40", "5.334633"], ["84112.90", "4.701710"], ["84095.90", "4.611293"], ["84087.40", "3.978370"], ["84078.90", "4.430458"], ["84070.40", "4.882545"], ["84061.90", "5.153798"], ["84053.40", "5.244215"], ["84044.90", "4.159205"], ["84036.40", "5.605885"], ["84027.90", "5.063380"], ["84019.40", "4.792128"], ["83884.62", "0"], ["83884.55", "0"]], "checksum": -1318920063, "ts": "1742142231542"}], "ts": 1742142231547, "record_time": 1742142230.654565}
{"action": "update", "arg": {"instType": "SPOT", "channel": "books", "instId": "BTCUSDT"}, "data": [{"asks": [["84251.78", "0.063833"], ["84252.29", "0"], ["84271.60", "0"], ["84272.88", "0.012680"], ["84293.40", "0.005300"], ["84295.40", "0.013947"], ["84297.40", "0.036702"], ["84299.40", "0.096585"], ["84301.40", "0.254171"], ["84303.40", "0.668871"], ["84305.40", "1.760186"], ["84307.40", "4.632070"], ["84309.50", "0"], ["84313.70", "0.012660"], ["84315.30", "0"], ["84318.10", "8.218680"], ["84319.00", "0.248880"], ["84320.00", "0.035580"], ["84349.50", "4.340040"], ["84358.00", "4.249623"], ["84366.50", "5.515468"], ["84375.00", "4.430458"], ["84383.50", "5.153798"], ["84392.00", "5.605885"], ["84400.50", "4.520875"], ["84400.55", "0"], ["84409.00", "4.068788"], ["84417.50", "5.244215"], ["84426.00", "4.701710"], ["84434.50", "4.159205"], ["84443.00", "3.887953"], ["84451.50", "4.882545"], ["84460.00", "3.978370"], ["84468.50", "5.334633"], ["84477.00", "5.063380"], ["84485.50", "4.792128"], ["84494.00", "4.611293"], ["84502.50", "4.972963"], ["84511.00", "5.425050"], ["84849.88", "0.000030"]], "bids": [["84237.64", "0.312758"], ["84227.85", "0"], ["84225.00", "1.401372"], ["84223.00", "3.687822"], ["84222.90", "0.001037"], ["84222.31", "0"], ["84220.50", "0.446070"], ["84219.40", "0.142500"], ["84217.60", "0"], ["84215.50", "0"], ["84206.10", "0.267960"], ["84180.90", "3.978370"], ["84172.40", "5.515468"], ["84163.90", "3.887953"], ["84155.40", "4.068788"], ["84146.90", "4.430458"], ["84138.40", "4.792128"], ["84129.90", "4.340040"], ["84121.40", "5.425050"], ["84112.90", "4.520875"], ["84104.40", "5.244215"], ["84095.90", "4.701710"], ["84087.40", "5.605885"], ["84078.90", "5.063380"], ["84070.40", "5.334633"], ["84061.90", "4.972963"], ["84053.40", "4.249623"], ["84036.40", "4.882545"], ["84027.90", "4.611293"], ["84019.40", "5.153798"], ["83884.62", "0.000014"], ["83884.55", "0.000048"], ["83884.30", "0.000161"], ["83882.98", "0.000188"]], "checksum": 723676347, "ts": "1742142231743"}], "ts": 1742142231749, "record_time": 1742142230.857025}
{"action": "update", "arg": {"instType": "SPOT", "channel": "books", "instId": "BTCUSDT"}, "data": [{"asks": [["84237.66", "0"], ["84237.67", "0"], ["84237.68", "0"], ["84237.69", "0"], ["84251.78", "0"], ["84253.89", "0"], ["84253.90", "0"], ["84254.58", "0"], ["84255.18", "0"], ["84255.80", "0"], ["84255.87", "0.139999"], ["84257.50", "0"], ["84262.94", "0"], ["84272.88", "0"], ["84274.46", "0.006356"], ["84274.62", "0"], ["84278.77", "0"], ["84283.81", "0"], ["84287.48", "0"], ["84291.40", "0.001005"], ["84293.40", "0.001644"], ["84295.40", "0.004325"], ["84297.40", "0.011381"], ["84299.40", "0.029952"], ["84301.40", "0.078821"], ["84303.40", "0.207422"], ["84305.40", "0.545847"], ["84307.40", "1.436441"], ["84308.20", "0.852270"], ["84309.00", "0"], ["84309.20", "0.258030"], ["84309.70", "0.047250"], ["84310.20", "0"], ["84312.20", "0"], ["84314.00", "0.885900"], ["84314.10", "0"], ["84314.40", "0.985470"], ["84314.80", "0"], ["84315.80", "0"], ["84318.10", "7.303680"], ["84320.40", "0.714690"], ["84321.90", "0.180000"], ["84349.50", "4.430458"], ["84358.00", "3.887953"], ["84375.00", "4.882545"], ["84383.50", "5.425050"], ["84392.00", "4.159205"], ["84400.50", "5.334633"], ["84409.00", "5.063380"], ["84417.41", "0.209200"], ["84417.50", "4.701710"], ["84426.00", "5.244215"], ["84434.50", "4.340040"], ["84443.00", "4.068788"], ["84451.50", "5.153798"], ["84460.00", "4.792128"], ["84468.50", "4.972963"], ["84477.00", "4.520875"], ["84485.50", "3.978370"], ["84494.00", "5.605885"], ["84502.50", "4.611293"], ["84511.00", "4.249623"], ["84850.00", "0.000031"], ["84851.66", "0.000029"], ["84852.81", "0.000115"], ["84852.94", "0.000065"], ["84853.56", "0.000050"], ["84857.14", "0.000347"], ["84858.75", "0.000285"], ["84859.29", "0.000036"], ["84860.00", "0.000169"], ["84862.90", "0.000169"], ["84864.69", "0.000052"], ["84864.86", "0.000041"], ["84864.99", "0.000033"], ["84866.10", "0.000064"], ["84866.40", "0.000018"], ["84867.80", "0.000095"], ["84868.42", "0.000031"]], "bids": [["84237.65", "4.211739"], ["84237.64", "0.416980"], ["84227.01", "0"], ["84226.02", "0"], ["84225.00", "1.401535"], ["84224.51", "0"], ["84223.00", "3.688250"], ["84220.70", "5.226090"], ["84220.50", "0.649830"], ["84219.80", "0.010590"], ["84217.80", "2.419650"], ["84217.25", "0"], ["84216.60", "1.184160"], ["84216.30", "0.418710"], ["84216.20", "0"], ["84215.20", "0"], ["84214.60", "0.009000"], ["84213.80", "0.069600"], ["84212.00", "0.304800"], ["84211.50", "0.915360"], ["84209.70", "0.462600"], ["84209.69", "0"], ["84206.80", "0"], ["84206.60", "0"], ["84206.20", "0"], ["84206.10", "0"], ["84180.90", "5.605885"], ["84177.30", "0"], ["84172.40", "5.153798"], ["84167.35", "0.072042"], ["84163.90", "4.249623"], ["84155.40", "5.063380"], ["84146.90", "4.611293"], ["84138.40", "4.340040"], ["84129.90", "4.792128"], ["84121.40", "4.159205"], ["84112.90", "3.887953"], ["84104.40", "4.520875"], ["84095.90", "3.978370"], ["84087.40", "5.425050"], ["84078.90", "5.244215"], ["84070.40", "4.701710"], ["84061.90", "5.334633"], ["84053.40", "4.430458"], ["84044.90", "4.068788"], ["84036.40", "4.972963"], ["84027.90", "5.515468"], ["84019.40", "4.882545"], ["83882.92", "0.002384"], ["83881.99", "0.000038"], ["83880.00", "0.020454"], ["83877.97", "0.000023"], ["83877.55", "0.000010"]], "checksum": -75535904, "ts": "1742142231948"}], "ts": 1742142231953, "record_time": 1742142231.062187}
{"action": "update", "arg": {"instType": "SPOT", "channel": "books", "instId": "BTCUSDT"}, "data": [{"asks": [["84255.87", "0"], ["84257.45", "0.040451"], ["84259.51", "0.139998"], ["84262.33", "0"], ["84264.41", "0"], ["84266.65", "0.002907"], ["84266.71", "0.003017"], ["84267.58", "0.080082"], ["84268.98", "0.001827"], ["84270.30", "0"], ["84271.61", "0"], ["84271.88", "0.574397"], ["84271.96", "0.001205"], ["84272.26", "0.012680"], ["84275.01", "0"], ["84275.76", "0.119869"], ["84276.61", "0"], ["84277.00", "0.035952"], ["84279.45", "0"], ["84280.59", "0.006356"], ["84281.40", "0.006357"], ["84282.24", "0"], ["84285.33", "0.119881"], ["84287.40", "0"], ["84288.20", "0.001021"], ["84288.28", "0.001807"], ["84288.38", "0.075200"], ["84289.40", "0"], ["84289.50", "0.015891"], ["84289.87", "0.010986"], ["84290.20", "0.001021"], ["84291.40", "0"], ["84292.20", "0.001007"], ["84293.40", "0"], ["84294.20", "0.001049"], ["84295.40", "0"], ["84296.20", "0.001512"], ["84297.40", "0"], ["84298.20", "0.003979"], ["84299.40", "0"], ["84300.20", "0.010470"], ["84301.40", "0"], ["84302.20", "0.027553"], ["84303.03", "0.031812"], ["84303.40", "0"], ["84304.20", "0.072507"], ["84305.40", "0"], ["84305.96", "0.026414"], ["84306.20", "0.190807"], ["84306.42", "0.029802"], ["84307.40", "0"], ["84308.10", "0"], ["84308.20", "0.502367"], ["84308.30", "0.001015"], ["84308.50", "0.014910"], ["84308.90", "0.001020"], ["84309.20", "0"], ["84309.70", "0"], ["84310.40", "0.080280"], ["84311.30", "2.349780"], ["84312.06", "0.010000"], ["84313.60", "0.037890"], ["84313.70", "0"], ["84314.00", "0.729270"], ["84314.40", "0"], ["84316.90", "0.469080"], ["84317.30", "0.273150"], ["84318.00", "0"], ["84318.10", "0.353010"], ["84319.00", "0"], ["84320.00", "0"], ["84320.40", "0"], ["84320.80", "0.014490"], ["84321.00", "0.985470"], ["84321.90", "0"], ["84322.30", "0.024510"], ["84322.80", "0.604740"], ["84323.00", "0.142500"], ["84349.50", "0"], ["84349.87", "0.002935"], ["84350.30", "4.792084"], ["84358.00", "0"], ["84358.80", "3.978334"], ["84366.50", "0"], ["84367.30", "4.430417"], ["84375.00", "0"], ["84375.80", "4.249584"], ["84383.50", "0"], ["84384.30", "5.244167"], ["84392.00", "0"], ["84392.80", "5.605834"], ["84400.50", "0"], ["84401.30", "3.887917"], ["84409.00", "0.125315"], ["84409.80", "5.063334"], ["84417.50", "0"], ["84418.30", "5.334584"], ["84426.00", "0"], ["84426.80", "4.611250"], ["84434.50", "0"], ["84435.30", "4.520834"], ["84443.00", "0"], ["84443.80", "5.425000"], ["84451.50", "0"], ["84452.30", "4.159167"], ["84460.00", "0"], ["84460.80", "5.153750"], ["84468.50", "0"], ["84469.30", "5.515417"], ["84477.00", "0"], ["84477.80", "4.340000"], ["84485.50", "0"], ["84486.30", "4.701667"], ["84494.00", "0"], ["84494.80", "4.972917"], ["84502.50", "0"], ["84503.30", "4.882500"], ["84511.00", "0"], ["84511.80", "4.068750"], ["84523.39", "0.031835"], ["84549.53", "0"], ["84853.56", "0"], ["84857.14", "0"], ["84858.75", "0"], ["84859.29", "0"], ["84860.00", "0"], ["84862.90", "0"], ["84864.69", "0"], ["84864.86", "0"], ["84864.99", "0"], ["84866.10", "0"], ["84866.40", "0"], ["84867.80", "0"], ["84868.42", "0"]], "bids": [["84257.44", "0.458795"], ["84256.32", "0.209200"], ["84255.86", "0.209200"], ["84253.64", "0.036210"], ["84246.07", "0.209200"], ["84243.80", "0.001025"], ["84241.87", "0.203170"], ["84241.80", "0.001021"], ["84239.80", "0.002293"], ["84237.80", "0.006034"], ["84237.66", "0.060180"], ["84237.65", "0.879953"], ["84237.64", "0.154510"], ["84237.63", "0.349196"], ["84237.00", "0"], ["84235.80", "0.015880"], ["84235.00", "0"], ["84234.89", "2.550709"], ["84234.47", "0.248107"], ["84233.80", "0.041789"], ["84233.18", "0.084475"], ["84233.00", "0"], ["84231.80", "0.109973"], ["84231.00", "0"], ["84229.87", "0.008992"], ["84229.80", "0.289402"], ["84229.03", "0.511594"], ["84229.02", "0"], ["84229.00", "0"], ["84227.80", "0.761712"], ["84227.65", "0.008287"], ["84227.00", "0"], ["84225.80", "2.004506"], ["84225.00", "0"], ["84224.71", "0.002951"], ["84224.67", "0.263442"], ["84224.29", "0"], ["84223.90", "0.197876"], ["84223.80", "5.275016"], ["84223.70", "0.275010"], ["84223.10", "2.005410"], ["84223.00", "4.024110"], ["84222.90", "0"], ["84222.86", "0"], ["84222.50", "0.714750"], ["84222.20", "0"], ["84221.80", "0.069780"], ["84220.91", "0.073545"], ["84220.90", "0.442800"], ["84220.70", "5.375670"], ["84220.50", "0.449280"], ["84219.80", "0"], ["84219.10", "0.056663"], ["84218.20", "0.915360"], ["84217.80", "0.069600"], ["84216.60", "0.091860"], ["84216.30", "0.013140"], ["84216.10", "0"], ["84213.20", "0.090000"], ["84212.30", "0.090000"], ["84212.10", "0.018870"], ["84211.50", "0.090000"], ["84211.30", "0.090000"], ["84210.20", "0.587550"], ["84209.00", "0.090000"], ["84208.69", "0"], ["84207.80", "0"], ["84207.00", "0"], ["84206.90", "0"], ["84194.40", "0.207047"], ["84188.72", "0.012005"], ["84183.13", "0.002935"], ["84181.70", "4.882500"], ["84180.90", "0"], ["84173.20", "3.978334"], ["84172.40", "0"], ["84168.00", "0"], ["84167.35", "0"], ["84164.70", "4.792084"], ["84163.90", "0"], ["84156.20", "4.340000"], ["84155.40", "0"], ["84147.70", "5.063334"], ["84146.90", "0"], ["84139.20", "4.611250"], ["84138.40", "0"], ["84130.70", "5.153750"], ["84129.90", "0"], ["84122.20", "5.425000"], ["84121.40", "0"], ["84113.70", "4.430417"], ["84112.90", "0.000039"], ["84105.20", "5.605834"], ["84104.40", "0"], ["84096.70", "4.972917"], ["84095.90", "0"], ["84088.20", "4.159167"], ["84087.40", "0"], ["84079.70", "3.887917"], ["84078.90", "0"], ["84071.20", "4.249584"], ["84070.40", "0"], ["84062.70", "5.334584"], ["84061.90", "0"], ["84054.20", "4.520834"], ["84053.40", "0"], ["84045.70", "5.515417"], ["84044.90", "0"], ["84037.20", "4.701667"], ["84036.40", "0"], ["84028.70", "5.244167"], ["84027.90", "0"], ["84020.20", "4.068750"], ["84019.40", "0"], ["84009.24", "0"], ["83992.38", "0"], ["83893.62", "0"], ["83892.29", "0"], ["83891.43", "0"], ["83891.30", "0"], ["83888.89", "0"], ["83888.86", "0"], ["83887.29", "0"], ["83887.11", "0"], ["83886.91", "0"], ["83885.98", "0"], ["83885.71", "0"], ["83884.62", "0"], ["83884.55", "0"], ["83884.30", "0"], ["83882.98", "0"], ["83882.92", "0"], ["83881.99", "0"], ["83880.00", "0"], ["83877.97", "0"], ["83877.55", "0"]], "checksum": -1391253778, "ts": "1742142232148"}], "ts": 1742142232151, "record_time": 1742142231.259896}
{"action": "update", "arg": {"instType": "SPOT", "channel": "books", "instId": "BTCUSDT"}, "data": [{"asks": [["84257.45", "0"], ["84257.46", "0"], ["84257.47", "0"], ["84257.48", "0"], ["84257.49", "0"], ["84257.51", "0"], ["84257.52", "0"], ["84257.57", "0"], ["84257.59", "0"], ["84257.61", "0"], ["84258.33", "0"], ["84258.34", "0"], ["84258.35", "0"], ["84258.36", "0"], ["84258.38", "0"], ["84258.39", "0"], ["84258.43", "0"], ["84259.51", "0"], ["84261.32", "0"], ["84261.33", "0"], ["84267.58", "0"], ["84268.80", "0.004595"], ["84270.03", "0.030015"], ["84270.14", "0.000078"], ["84270.89", "0.001230"], ["84270.90", "0.004974"], ["84271.01", "0.001066"], ["84271.45", "0"], ["84271.47", "0"], ["84271.70", "0"], ["84271.86", "0.005183"], ["84271.88", "0.009191"], ["84271.89", "0"], ["84271.96", "0"], ["84272.26", "0"], ["84272.51", "0"], ["84272.98", "0"], ["84273.28", "0"], ["84273.49", "0"], ["84274.08", "0"], ["84274.13", "0"], ["84274.36", "0"], ["84274.46", "0"], ["84274.50", "0"], ["84274.94", "0"], ["84274.99", "0"], ["84275.09", "0"], ["84275.76", "0"], ["84275.85", "0.080082"], ["84276.08", "0"], ["84277.00", "0"], ["84277.08", "0"], ["84277.48", "0"], ["84277.53", "0"], ["84278.07", "0"], ["84278.49", "0"], ["84279.26", "0"], ["84280.00", "0"], ["84280.52", "0"], ["84280.58", "0"], ["84280.59", "0"], ["84281.40", "0"], ["84281.41", "0"], ["84282.57", "0"], ["84282.84", "0"], ["84282.90", "0.001205"], ["84284.03", "0.119869"], ["84284.31", "1.895168"], ["84285.27", "0.035952"], ["84285.33", "0"], ["84285.95", "0.006356"], ["84286.04", "0.016427"], ["84286.06", "0.006356"], ["84286.29", "0.313304"], ["84286.67", "0.010985"], ["84287.67", "0.016428"], ["84288.20", "0"], ["84288.28", "0"], ["84288.56", "0.006356"], ["84288.68", "0.006356"], ["84288.73", "0.676920"], ["84288.74", "0"], ["84289.10", "0.119843"], ["84289.24", "0.006356"], ["84289.50", "0"], ["84289.56", "0.006356"], ["84289.62", "0.006356"], ["84289.78", "0.012680"], ["84289.87", "0"], ["84289.89", "0.017801"], ["84289.98", "0.010984"], ["84290.09", "0.006357"], ["84290.20", "0"], ["84290.42", "0.006356"], ["84291.27", "0.006356"], ["84292.00", "0.119895"], ["84292.20", "0"], ["84293.92", "0.009989"], ["84294.20", "0"], ["84295.66", "0.015892"], ["84295.74", "0.006356"], ["84296.20", "0"], ["84298.20", "0"], ["84300.20", "0"], ["84300.22", "0.015891"], ["84300.81", "0.010986"], ["84301.00", "0.001016"], ["84301.17", "2.228922"], ["84302.20", "0"], ["84303.00", "0.001040"], ["84303.03", "0"], ["84304.20", "0"], ["84305.00", "0.001046"], ["84305.45", "0"], ["84305.96", "0"], ["84306.20", "0"], ["84306.42", "0"], ["84307.00", "0.001050"], ["84308.20", "0"], ["84308.30", "0"], ["84308.50", "0"], ["84308.90", "0"], ["84309.00", "0.001058"], ["84310.00", "0.791778"], ["84310.40", "0"], ["84311.00", "0.002783"], ["84311.30", "0"], ["84312.06", "0"], ["84313.00", "0.007323"], ["84313.60", "0"], ["84314.00", "0"], ["84315.00", "0.019271"], ["84315.70", "0"], ["84316.10", "0"], ["84316.60", "0"], ["84316.90", "0"], ["84317.00", "0.050714"], ["84317.10", "0"], ["84317.30", "0"], ["84318.10", "0"], ["84318.40", "0"], ["84319.00", "0.133458"], ["84320.80", "0"], ["84321.00", "0.351205"], ["84322.30", "0.025350"], ["84322.80", "0.346800"], ["84322.90", "0.002940"], ["84323.00", "0"], ["84324.50", "0.177960"], ["84324.70", "0.273330"], ["84325.40", "0.469080"], ["84325.90", "0.013860"], ["84326.40", "2.655420"], ["84327.60", "0.012660"], ["84327.80", "0.985470"], ["84329.00", "3.694380"], ["84330.90", "3.727620"], ["84332.40", "0.178950"], ["84332.70", "0.009000"], ["84333.60", "1.127880"], ["84334.10", "0.198000"], ["84334.50", "0.065250"], ["84334.70", "2.669430"], ["84334.80", "0.410370"], ["84334.90", "3.470700"], ["84335.80", "0.241500"], ["84350.30", "0"], ["84358.80", "0"], ["84363.10", "4.610546"], ["84367.30", "0"], ["84371.60", "4.429741"], ["84375.80", "0"], ["84380.10", "4.068129"], ["84384.30", "0"], ["84388.60", "4.700949"], ["84392.80", "0"], ["84397.10", "4.881755"], ["84400.55", "0.209200"], ["84401.30", "0"], ["84405.60", "3.977726"], ["84409.80", "0"], ["84414.10", "4.248935"], ["84418.30", "0"], ["84422.60", "5.424172"], ["84425.84", "0.209200"], ["84426.80", "0"], ["84431.10", "4.339338"], ["84435.30", "0"], ["84439.60", "4.158532"], ["84443.80", "0"], ["84448.10", "5.062561"], ["84452.30", "0"], ["84456.60", "5.604978"], ["84460.80", "0"], ["84465.10", "4.520143"], ["84469.30", "0"], ["84473.60", "5.514575"], ["84477.80", "0"], ["84482.10", "3.887323"], ["84486.30", "0"], ["84490.60", "4.972158"], ["84494.80", "0"], ["84499.10", "5.333769"], ["84503.30", "0"], ["84507.60", "5.243366"], ["84511.80", "0"], ["84516.10", "4.791352"], ["84524.60", "5.152963"], ["84578.98", "0"], ["84603.14", "1.669295"], ["84853.56", "0.000050"], ["84857.14", "0.000347"], ["84858.75", "0.000285"], ["84859.29", "0.000036"], ["84860.00", "0.000169"], ["84862.90", "0.000169"], ["84864.69", "0.000052"], ["84864.86", "0.000041"], ["84864.99", "0.000033"], ["84866.10", "0.000064"], ["84866.40", "0.000018"], ["84867.80", "0.000095"], ["84868.42", "0.000031"], ["84868.52", "0.000013"], ["84868.65", "0.000035"], ["84869.57", "0.000932"], ["84871.66", "0.000078"], ["84871.79", "0.000014"], ["84873.84", "0.000057"], ["84874.79", "0.000096"], ["84875.00", "0.000959"], ["84875.78", "0.000038"], ["84876.03", "0.000161"], ["84879.10", "0.000009"], ["84879.37", "0.000009"]], "bids": [["84266.64", "0.104839"], ["84261.32", "2.343038"], ["84257.45", "0.647400"], ["84257.44", "0.420033"], ["84256.60", "0.001032"], ["84256.33", "0.073623"], ["84256.32", "0"], ["84254.60", "0.001030"], ["84253.64", "0"], ["84253.48", "0.010000"], ["84252.60", "0.001370"], ["84250.60", "0.003606"], ["84248.60", "0.009488"], ["84248.08", "2.550287"], ["84246.60", "0.024970"], ["84246.08", "0.062760"], ["84245.48", "0.000213"], ["84244.60", "0.065710"], ["84243.80", "0.001199"], ["84242.74", "0.248076"], ["84242.60", "0.172920"], ["84242.21", "0.007873"], ["84241.88", "0.061945"], ["84241.87", "0"], ["84241.80", "0"], ["84241.54", "0.006567"], ["84241.45", "0.084464"], ["84241.20", "0.017084"], ["84240.60", "0.455054"], ["84240.28", "0.005939"], ["84239.87", "0.007935"], ["84239.80", "0"], ["84239.71", "0.015776"], ["84239.53", "0.017337"], ["84238.81", "0.056371"], ["84238.62", "0.017066"], ["84238.60", "1.197510"], ["84238.23", "0.008156"], ["84237.95", "0.028816"], ["84237.83", "0.008991"], ["84237.80", "0"], ["84237.70", "0.227742"], ["84237.66", "0.047500"], ["84237.65", "0.849629"], ["84237.64", "0.118897"], ["84237.63", "0.209200"], ["84236.60", "3.151342"], ["84236.50", "0.291030"], ["84236.33", "0.008286"], ["84236.07", "0.263409"], ["84235.80", "0.091650"], ["84235.60", "0.291030"], ["84235.55", "0.002950"], ["84235.50", "0"], ["84235.49", "0.012653"], ["84235.40", "0.981911"], ["84235.20", "0.052124"], ["84235.00", "4.695780"], ["84234.89", "0"], ["84234.64", "0.025092"], ["84234.48", "0.076036"], ["84234.47", "0"], ["84234.10", "0.080160"], ["84233.80", "0.069780"], ["84233.70", "0.282780"], ["84233.69", "0.271983"], ["84233.18", "0"], ["84232.41", "0.021115"], ["84232.20", "0.142680"], ["84232.14", "0"], ["84232.13", "0"], ["84232.12", "0"], ["84232.10", "0.035580"], ["84232.08", "0"], ["84232.05", "0"], ["84232.04", "0"], ["84231.80", "0.069780"], ["84231.12", "0.073528"], ["84231.10", "0.274770"], ["84230.78", "0"], ["84230.64", "0"], ["84230.62", "0"], ["84230.57", "0"], ["84230.55", "0"], ["84230.53", "0"], ["84230.18", "0.012443"], ["84230.03", "0.056656"], ["84229.87", "0"], ["84229.80", "0.069780"], ["84229.64", "0"], ["84229.20", "10.447740"], ["84228.98", "0"], ["84228.91", "0"], ["84228.41", "0"], ["84228.05", "0"], ["84228.03", "0"], ["84228.02", "0"], ["84227.84", "0.209200"], ["84227.80", "0.069600"], ["84227.70", "0"], ["84227.65", "0"], ["84227.23", "0"], ["84226.82", "0"], ["84226.70", "1.148430"], ["84226.46", "0"], ["84226.37", "0"], ["84225.84", "0"], ["84225.81", "0"], ["84225.80", "0.212100"], ["84225.68", "0"], ["84225.60", "0.987180"], ["84225.29", "0"], ["84225.00", "0.915360"], ["84224.97", "0"], ["84224.96", "0"], ["84224.93", "0"], ["84224.92", "0"], ["84224.88", "0"], ["84224.83", "0"], ["84224.79", "0"], ["84224.75", "0"], ["84224.71", "0"], ["84224.67", "0"], ["84224.30", "0.462600"], ["84224.12", "0.023747"], ["84223.90", "0"], ["84223.80", "4.452060"], ["84223.79", "0"], ["84223.73", "0"], ["84223.70", "0"], ["84223.55", "0"], ["84223.35", "0"], ["84223.32", "0"], ["84223.31", "0"], ["84223.26", "0"], ["84223.20", "0.410370"], ["84223.10", "0"], ["84223.00", "0.018060"], ["84222.50", "0"], ["84221.80", "0.069600"], ["84221.70", "0"], ["84221.30", "0"], ["84221.03", "0"], ["84220.91", "0"], ["84220.90", "0"], ["84220.70", "1.984200"], ["84220.50", "0"], ["84219.40", "0"], ["84219.35", "0"], ["84219.10", "0"], ["84219.08", "0"], ["84218.94", "0"], ["84218.20", "0"], ["84217.80", "0"], ["84217.29", "0"], ["84216.60", "0"], ["84216.30", "0"], ["84215.80", "0"], ["84215.13", "0.007585"], ["84214.60", "0"], ["84213.99", "0"], ["84213.80", "0"], ["84213.20", "0"], ["84213.00", "0"], ["84212.30", "0"], ["84212.10", "0"], ["84212.00", "0"], ["84211.90", "0"], ["84211.80", "0"], ["84211.50", "0"], ["84211.30", "0"], ["84210.49", "0.017802"], ["84210.20", "0"], ["84210.10", "0"], ["84209.70", "0"], ["84209.00", "0"], ["84206.31", "0"], ["84205.20", "0"], ["84201.99", "0"], ["84201.87", "0"], ["84200.00", "0.207106"], ["84194.92", "0"], ["84194.80", "0"], ["84194.50", "5.604978"], ["84194.40", "0"], ["84188.72", "0"], ["84186.00", "5.424172"], ["84181.70", "0"], ["84177.50", "4.339338"], ["84174.46", "0.072042"], ["84173.20", "0"], ["84172.21", "0.057629"], ["84169.00", "4.610546"], ["84164.70", "0"], ["84160.50", "4.791352"], ["84156.20", "0"], ["84152.00", "5.333769"], ["84147.70", "0"], ["84143.50", "4.248935"], ["84139.20", "0"], ["84135.00", "4.429741"], ["84130.70", "0"], ["84126.50", "4.700949"], ["84122.20", "0"], ["84118.00", "3.977726"], ["84113.70", "0"], ["84109.50", "4.972158"], ["84105.20", "0"], ["84101.00", "4.068129"], ["84096.70", "0"], ["84092.50", "4.158532"], ["84088.20", "0"], ["84084.00", "5.152963"], ["84079.70", "0"], ["84075.50", "4.520143"], ["84071.20", "0"], ["84067.00", "5.243366"], ["84062.70", "0"], ["84058.50", "4.881755"], ["84054.20", "0"], ["84050.00", "3.887323"], ["84045.70", "0"], ["84041.50", "5.514575"], ["84037.20", "0"], ["84033.00", "5.062561"], ["84028.70", "0"], ["84020.20", "0"], ["84017.67", "0"], ["83929.00", "1.648704"], ["83905.03", "0"], ["83893.62", "0.000137"], ["83892.29", "0.000143"], ["83891.43", "0.000455"], ["83891.30", "0.000010"], ["83888.89", "0.000163"], ["83888.86", "0.000371"], ["83887.29", "0.000586"], ["83887.11", "0.000075"], ["83886.91", "0.000145"], ["83885.98", "0.000018"], ["83885.71", "0.000069"], ["83884.62", "0.000014"], ["83884.55", "0.000048"], ["83884.30", "0.000161"], ["83882.98", "0.000188"], ["83882.92", "0.002384"], ["83881.99", "0.000038"], ["83880.00", "0.020454"], ["83877.97", "0.000023"], ["83877.55", "0.000010"], ["83877.42", "0.000054"], ["83877.29", "0.000024"], ["83877.05", "0.000008"], ["83876.25", "0.000028"], ["83876.12", "0.000681"], ["83875.99", "0.000299"], ["83875.49", "0.000723"], ["83875.16", "0.000179"], ["83875.00", "0.000145"], ["83874.55", "0.000145"], ["83874.15", "0.000150"], ["83873.87", "0.000041"], ["83873.52", "0.000135"], ["83870.97", "0.000194"], ["83870.95", "0.000078"], ["83870.78", "0.000019"], ["83870.00", "0.000121"], ["83869.57", "0.000035"], ["83868.82", "0.000017"]], "checksum": 495451120, "ts": "1742142232352"}], "ts": 1742142232356, "record_time": 1742142231.471022}
{"action": "update", "arg": {"instType": "SPOT", "channel": "books", "instId": "BTCUSDT"}, "data": [{"asks": [["84266.65", "0"], ["84266.71", "0"], ["84268.98", "0"], ["84270.03", "0"], ["84270.14", "0"], ["84270.89", "0"], ["84270.90", "0"], ["84271.01", "0"], ["84271.86", "0"], ["84271.88", "0"], ["84272.64", "0.010074"], ["84273.61", "0.008506"], ["84273.62", "0.007955"], ["84273.63", "0.007627"], ["84273.65", "0.000443"], ["84273.72", "0.004739"], ["84275.85", "0"], ["84279.74", "0.002907"], ["84280.90", "0.003017"], ["84282.55", "0.014791"], ["84282.56", "0"], ["84284.03", "0"], ["84284.31", "0"], ["84285.27", "0"], ["84285.95", "0"], ["84286.04", "0"], ["84286.06", "0"], ["84286.29", "0"], ["84286.67", "0"], ["84287.67", "0"], ["84288.38", "0"], ["84288.56", "0"], ["84288.68", "0"], ["84288.73", "0"], ["84289.10", "0"], ["84289.24", "0"], ["84289.56", "0"], ["84289.62", "0"], ["84289.78", "0"], ["84289.98", "0"], ["84290.09", "0"], ["84290.42", "0"], ["84290.99", "0"], ["84291.00", "0"], ["84291.27", "0"], ["84292.00", "0"], ["84292.89", "0.006356"], ["84293.92", "0"], ["84295.66", "0"], ["84295.74", "0"], ["84296.74", "0.119881"], ["84296.97", "0.119879"], ["84300.22", "0"], ["84300.81", "0"], ["84301.00", "0"], ["84301.70", "0.001807"], ["84302.80", "0.001038"], ["84303.00", "0"], ["84303.11", "0"], ["84304.80", "0.001042"], ["84305.00", "0"], ["84306.80", "0.001013"], ["84307.00", "0"], ["84308.80", "0.001778"], ["84309.00", "0"], ["84310.00", "0"], ["84310.80", "0.004680"], ["84311.00", "0"], ["84312.80", "0.012315"], ["84313.00", "0"], ["84314.80", "0.032407"], ["84315.00", "0"], ["84316.80", "0.085283"], ["84317.00", "0"], ["84318.80", "0.224429"], ["84319.00", "0"], ["84320.80", "0.590602"], ["84321.00", "0"], ["84322.30", "0"], ["84322.80", "1.554216"], ["84322.90", "0.001027"], ["84323.00", "2.351100"], ["84323.10", "0.698880"], ["84324.08", "0.001597"], ["84324.50", "0"], ["84324.70", "0"], ["84325.40", "0"], ["84326.02", "0.001597"], ["84326.40", "0"], ["84326.90", "0.258210"], ["84327.60", "0"], ["84327.80", "0"], ["84328.90", "0.188880"], ["84329.00", "0"], ["84329.40", "0.142500"], ["84330.40", "0.469080"], ["84330.90", "0.736530"], ["84331.30", "1.350000"], ["84332.90", "0.015180"], ["84334.10", "0"], ["84334.20", "0.015210"], ["84334.40", "0.985470"], ["84334.50", "0"], ["84334.70", "0"], ["84334.80", "0"], ["84334.90", "1.175400"], ["84335.80", "0.142500"], ["84336.60", "3.694380"], ["84338.70", "0.135390"], ["84339.10", "2.138520"], ["84339.90", "0.435720"], ["84349.87", "0"], ["84363.10", "0"], ["84364.90", "4.248845"], ["84371.60", "0"], ["84373.40", "4.520047"], ["84380.10", "0"], ["84381.90", "5.333656"], ["84388.60", "0"], ["84390.40", "4.972052"], ["84397.10", "0"], ["84398.90", "5.514458"], ["84405.60", "0"], ["84407.40", "4.068043"], ["84414.10", "0"], ["84415.90", "5.152854"], ["84422.60", "0"], ["84424.40", "4.610448"], ["84431.10", "0"], ["84432.90", "4.700849"], ["84439.60", "0"], ["84441.40", "4.881651"], ["84448.10", "0"], ["84449.90", "5.062453"], ["84456.60", "0"], ["84458.40", "5.604859"], ["84465.10", "0"], ["84466.90", "5.243255"], ["84473.60", "0"], ["84475.40", "5.424057"], ["84482.10", "0"], ["84483.90", "3.887241"], ["84490.60", "0"], ["84492.40", "4.429647"], ["84499.10", "0"], ["84500.90", "3.977642"], ["84507.60", "0"], ["84509.40", "4.791250"], ["84516.10", "0"], ["84517.90", "4.339246"], ["84524.60", "0"], ["84526.40", "4.158444"], ["84879.59", "0.000173"], ["84880.00", "0.025078"], ["84880.89", "0.000065"], ["84882.35", "0.000417"], ["84883.65", "0.000008"], ["84883.72", "0.000010"], ["84883.84", "0.000040"], ["84885.24", "0.000112"], ["84885.53", "0.000022"], ["84886.01", "0.000023"], ["84886.02", "0.000054"], ["84886.96", "0.000013"], ["84887.65", "0.000019"], ["84888.00", "0.000010"], ["84888.68", "0.000013"], ["84888.89", "0.000113"], ["84889.87", "0.000010"], ["84890.00", "0.000118"], ["84892.02", "0.000099"], ["84892.76", "0.000096"], ["84892.78", "0.000013"], ["84894.73", "0.000019"], ["84894.74", "0.000208"], ["84895.69", "0.000135"], ["84895.83", "0.000019"], ["84897.50", "0.000031"], ["84899.08", "0.000072"], ["84899.44", "0.000026"], ["84900.00", "0.005252"]], "bids": [["84266.64", "1.079174"], ["84265.86", "0.209200"], ["84265.07", "0.059821"], ["84263.51", "0.139996"], ["84261.33", "0.702911"], ["84261.32", "0.209200"], ["84258.40", "0.001045"], ["84257.45", "0"], ["84257.44", "0.011868"], ["84256.60", "0"], ["84256.40", "0.001052"], ["84256.33", "0"], ["84254.60", "0"], ["84254.40", "0.002590"], ["84253.48", "0"], ["84252.60", "0"], ["84252.40", "0.006817"], ["84250.60", "0"], ["84250.50", "0.189706"], ["84250.40", "0.017940"], ["84248.60", "0"], ["84248.40", "0.047211"], ["84248.08", "0"], ["84247.39", "0.313304"], ["84247.28", "0.001230"], ["84247.20", "0.007515"], ["84246.60", "0"], ["84246.40", "0.124237"], ["84245.77", "0.007346"], ["84245.64", "0.008988"], ["84245.62", "0.006213"], ["84245.57", "0.007443"], ["84245.55", "0.015096"], ["84244.85", "0.008147"], ["84244.60", "0"], ["84244.40", "0.326941"], ["84243.68", "0.002064"], ["84243.21", "0.007475"], ["84242.74", "0"], ["84242.60", "0"], ["84242.40", "0.860167"], ["84242.21", "0"], ["84241.54", "0"], ["84241.45", "0"], ["84241.20", "0"], ["84240.60", "0"], ["84240.40", "2.263598"], ["84240.28", "0"], ["84240.10", "0.005554"], ["84240.09", "0.005089"], ["84240.03", "0.000875"], ["84239.87", "0"], ["84239.71", "0"], ["84239.53", "0"], ["84238.81", "0"], ["84238.62", "0"], ["84238.60", "0"], ["84238.55", "0.008676"], ["84238.40", "5.956836"], ["84238.30", "0.001017"], ["84238.23", "0"], ["84237.95", "0"], ["84237.83", "0"], ["84237.70", "0"], ["84237.66", "0.421911"], ["84237.65", "0.496497"], ["84237.64", "0"], ["84237.40", "0.001016"], ["84237.20", "1.132890"], ["84236.63", "0.222799"], ["84236.60", "0.017790"], ["84236.50", "0"], ["84236.33", "0"], ["84235.80", "0"], ["84235.60", "0"], ["84235.55", "0"], ["84235.49", "0"], ["84235.40", "0"], ["84235.20", "0"], ["84235.00", "0"], ["84234.64", "0"], ["84234.48", "0"], ["84234.10", "0.079950"], ["84233.80", "0"], ["84233.70", "0"], ["84233.69", "0"], ["84233.20", "0.274770"], ["84232.70", "0.337260"], ["84232.41", "0"], ["84232.10", "0"], ["84231.80", "0.069600"], ["84231.30", "0.915360"], ["84231.12", "0"], ["84231.10", "0"], ["84230.18", "0"], ["84230.03", "0"], ["84229.80", "0.069600"], ["84229.20", "2.340660"], ["84229.03", "0"], ["84227.36", "0.023946"], ["84226.70", "0"], ["84226.31", "0"], ["84225.00", "0.304080"], ["84223.80", "0.262620"], ["84223.00", "0"], ["84221.46", "0.008208"], ["84220.70", "7.403490"], ["84220.30", "0.009060"], ["84219.70", "2.669430"], ["84219.40", "0.142500"], ["84219.30", "0.383400"], ["84216.99", "0.007186"], ["84215.13", "0"], ["84213.52", "0.001190"], ["84211.59", "0.001180"], ["84209.65", "0"], ["84200.00", "0.000059"], ["84196.30", "5.604859"], ["84194.50", "0"], ["84188.70", "0"], ["84187.80", "4.248845"], ["84186.00", "0"], ["84183.13", "0"], ["84179.30", "4.158444"], ["84177.50", "0"], ["84174.46", "0"], ["84170.80", "4.881651"], ["84169.00", "0.012838"], ["84162.30", "4.791250"], ["84160.50", "0"], ["84153.80", "4.339246"], ["84152.00", "0"], ["84145.30", "4.700849"], ["84143.50", "0"], ["84136.80", "5.424057"], ["84135.00", "0"], ["84128.30", "3.887241"], ["84126.50", "0"], ["84119.80", "5.514458"], ["84118.00", "0"], ["84111.30", "4.972052"], ["84109.50", "0"], ["84102.80", "4.429647"], ["84101.00", "0"], ["84094.30", "3.977642"], ["84092.50", "0"], ["84085.80", "4.068043"], ["84084.00", "0"], ["84077.30", "5.243255"], ["84075.50", "0"], ["84068.80", "4.520047"], ["84067.00", "0"], ["84060.30", "5.062453"], ["84058.50", "0"], ["84051.80", "4.610448"], ["84050.00", "0.000162"], ["84043.30", "5.152854"], ["84041.50", "0"], ["84034.80", "5.333656"], ["84033.00", "0"], ["83866.67", "0.000138"], ["83865.80", "0.000098"], ["83865.10", "0.000134"], ["83864.54", "0.000009"], ["83863.64", "0.000012"], ["83863.52", "0.000510"], ["83860.29", "0.000041"], ["83860.10", "0.000023"], ["83860.00", "0.000024"], ["83859.94", "0.000058"]], "checksum": -1656790786, "ts": "1742142232561"}], "ts": 1742142232565, "record_time": 1742142231.674112}
{"action": "update", "arg": {"instType": "SPOT", "channel": "books", "instId": "BTCUSDT"}, "data": [{"asks": [["84268.80", "0"], ["84272.64", "0"], ["84273.61", "0"], ["84273.62", "0"], ["84273.63", "0"], ["84273.65", "0"], ["84273.72", "0"], ["84282.05", "0.001827"], ["84282.55", "0"], ["84282.90", "0"], ["84289.89", "0"], ["84291.21", "0.139994"], ["84292.89", "0"], ["84296.74", "0"], ["84296.97", "0"], ["84301.16", "0.732290"], ["84301.17", "0"], ["84301.57", "0"], ["84301.70", "0"], ["84302.59", "0.006356"], ["84302.80", "0"], ["84303.16", "0.119869"], ["84304.80", "0"], ["84305.73", "0.119881"], ["84306.53", "0.006356"], ["84306.80", "0"], ["84307.63", "0.017798"], ["84307.74", "0.313304"], ["84308.80", "0"], ["84309.26", "0.075200"], ["84309.59", "0.006357"], ["84310.42", "0.119895"], ["84310.80", "0"], ["84312.40", "0.001049"], ["84312.80", "0"], ["84314.40", "0.001031"], ["84314.80", "0"], ["84316.40", "0.001005"], ["84316.80", "0"], ["84318.40", "0.001035"], ["84318.80", "0"], ["84320.11", "0.010000"], ["84320.40", "0.001009"], ["84320.80", "0"], ["84322.40", "0.001047"], ["84322.80", "0"], ["84322.90", "0"], ["84323.00", "0"], ["84323.10", "0"], ["84324.40", "0.001018"], ["84325.90", "0"], ["84326.40", "0.001026"], ["84326.90", "0"], ["84328.40", "0.001002"], ["84328.90", "0"], ["84329.40", "0"], ["84330.40", "0.001632"], ["84330.90", "0"], ["84331.30", "0"], ["84332.40", "0.004297"], ["84332.50", "0.001048"], ["84332.70", "0.015360"], ["84332.90", "0.001001"], ["84333.20", "0.001008"], ["84333.60", "0"], ["84334.20", "0"], ["84334.40", "0"], ["84334.90", "0"], ["84335.40", "0.002760"], ["84335.80", "0"], ["84336.60", "0"], ["84338.70", "0"], ["84339.10", "0"], ["84339.90", "0"], ["84341.50", "0.012450"], ["84343.40", "0.013860"], ["84343.50", "0.032910"], ["84343.80", "0.015060"], ["84344.10", "0.284280"], ["84346.70", "0.180000"], ["84347.00", "0.021600"], ["84347.80", "0.135000"], ["84348.20", "0.236190"], ["84348.60", "0.142500"], ["84349.90", "0.015150"], ["84350.20", "0.117000"], ["84350.50", "0.010560"], ["84351.80", "3.807060"], ["84352.20", "2.669430"], ["84352.60", "0.420000"], ["84364.90", "0"], ["84370.12", "0"], ["84370.36", "0"], ["84373.09", "0"], ["84373.40", "0"], ["84374.50", "4.429143"], ["84381.90", "0"], ["84383.00", "5.604221"], ["84390.40", "0"], ["84391.50", "4.338752"], ["84398.90", "0"], ["84399.16", "0.072042"], ["84399.47", "0.057629"], ["84400.00", "3.977189"], ["84400.46", "0.072042"], ["84407.40", "0"], ["84408.50", "4.067580"], ["84415.90", "0"], ["84417.00", "4.881096"], ["84424.40", "0"], ["84425.50", "5.242658"], ["84432.90", "0"], ["84434.00", "4.248361"], ["84434.27", "0.209200"], ["84441.40", "0"], ["84442.50", "4.971486"], ["84449.90", "0"], ["84451.00", "4.609924"], ["84458.40", "0"], ["84459.50", "4.157971"], ["84466.90", "0"], ["84468.00", "3.886799"], ["84475.40", "0"], ["84476.50", "4.519533"], ["84483.90", "0"], ["84485.00", "4.700314"], ["84492.40", "0"], ["84493.50", "5.423440"], ["84500.90", "0"], ["84502.00", "5.333049"], ["84509.40", "0"], ["84510.50", "5.152268"], ["84517.90", "0"], ["84519.00", "5.513830"], ["84526.40", "0"], ["84527.50", "4.790705"], ["84536.00", "5.061877"], ["84603.14", "0"], ["84635.91", "1.669295"], ["84901.15", "0.000019"], ["84903.27", "0.000007"], ["84903.57", "0.000128"]], "bids": [["84279.73", "0.460535"], ["84277.79", "0.209200"], ["84273.58", "0.035598"], ["84268.79", "0.203635"], ["84268.00", "0.001006"], ["84266.65", "0.437139"], ["84266.64", "0.353812"], ["84266.00", "0.001020"], ["84265.07", "0"], ["84264.00", "0.001935"], ["84263.86", "0.313304"], ["84262.00", "0.005250"], ["84261.86", "0.248046"], ["84261.34", "0.273633"], ["84261.33", "0"], ["84261.32", "0"], ["84260.00", "0.013817"], ["84258.40", "0"], ["84258.33", "0.056364"], ["84258.15", "0.017082"], ["84258.00", "0.036360"], ["84257.45", "0.003560"], ["84256.80", "0.006490"], ["84256.40", "0"], ["84256.00", "0.095683"], ["84254.41", "0.002822"], ["84254.40", "0"], ["84254.00", "0.251798"], ["84252.40", "0"], ["84252.10", "0.271950"], ["84252.00", "0.662626"], ["84250.40", "0"], ["84250.00", "1.743753"], ["84248.40", "0"], ["84248.00", "4.588825"], ["84247.90", "4.205910"], ["84247.80", "0.069990"], ["84247.40", "2.349810"], ["84247.39", "0"], ["84247.28", "0"], ["84247.20", "0"], ["84246.70", "1.755750"], ["84246.40", "0"], ["84246.20", "0.405750"], ["84246.10", "0.269940"], ["84245.80", "0.069780"], ["84245.77", "0"], ["84245.64", "0"], ["84245.62", "0"], ["84245.57", "0"], ["84245.55", "0"], ["84245.48", "0"], ["84245.05", "0.263377"], ["84245.00", "0.142680"], ["84244.85", "0"], ["84244.40", "0"], ["84243.80", "0"], ["84243.68", "0"], ["84243.21", "0"], ["84243.00", "0.280200"], ["84242.40", "0"], ["84242.00", "5.618430"], ["84241.80", "0.069600"], ["84241.50", "5.473680"], ["84241.30", "0.274590"], ["84240.70", "0.410370"], ["84240.40", "0"], ["84240.10", "0"], ["84240.09", "0"], ["84240.03", "0"], ["84239.67", "0.023744"], ["84239.50", "0.915360"], ["84239.30", "0.177960"], ["84238.60", "0.142500"], ["84238.55", "0"], ["84238.40", "1.440900"], ["84238.30", "0"], ["84238.20", "0.025350"], ["84238.10", "0.447690"], ["84237.80", "0.069600"], ["84237.65", "0.482400"], ["84237.64", "0.197876"], ["84237.40", "0"], ["84237.20", "2.417130"], ["84236.90", "0.038460"], ["84236.80", "2.669430"], ["84236.63", "0"], ["84236.07", "0"], ["84235.70", "0.177960"], ["84234.70", "4.448730"], ["84234.50", "0.383400"], ["84234.10", "0"], ["84233.30", "5.415690"], ["84233.20", "2.669430"], ["84232.70", "0"], ["84232.20", "0.142500"], ["84231.80", "0"], ["84231.30", "0"], ["84229.80", "0"], ["84229.20", "0"], ["84227.80", "0"], ["84227.36", "0"], ["84225.80", "0"], ["84225.60", "0"], ["84225.00", "0"], ["84224.73", "0.013678"], ["84224.30", "0"], ["84224.12", "0"], ["84223.80", "0"], ["84223.20", "0"], ["84222.69", "0.017799"], ["84221.80", "0"], ["84221.46", "0"], ["84220.70", "0"], ["84220.30", "0"], ["84219.70", "0"], ["84219.40", "0"], ["84219.30", "0"], ["84216.99", "0"], ["84213.50", "0.207047"], ["84210.49", "0"], ["84205.90", "3.886799"], ["84197.40", "5.242658"], ["84196.30", "0"], ["84188.90", "4.971486"], ["84187.80", "0"], ["84180.40", "4.067580"], ["84179.30", "0"], ["84171.90", "4.429143"], ["84170.98", "0.072042"], ["84170.80", "0"], ["84167.00", "0.000121"], ["84163.40", "4.881096"], ["84162.30", "0"], ["84154.90", "5.152268"], ["84153.80", "0"], ["84146.40", "5.423440"], ["84145.30", "0"], ["84137.90", "4.700314"], ["84136.80", "0"], ["84129.40", "4.338752"], ["84128.30", "0"], ["84122.97", "0"], ["84120.90", "4.519533"], ["84119.80", "0"], ["84112.40", "5.513830"], ["84111.30", "0"], ["84103.90", "3.977189"], ["84102.80", "0"], ["84095.40", "5.604221"], ["84094.30", "0"], ["84086.90", "4.157971"], ["84085.80", "0"], ["84078.40", "4.609924"], ["84077.30", "0"], ["84069.90", "5.333049"], ["84068.80", "0"], ["84061.40", "5.061877"], ["84060.30", "0"], ["84052.90", "4.790705"], ["84051.80", "0"], ["84044.40", "4.248361"], ["84043.30", "0"], ["84034.80", "0"], ["84026.10", "0"], ["83961.52", "1.648704"], ["83929.00", "0"], ["83859.35", "0.000051"]], "checksum": 339828621, "ts": "1742142232764"}], "ts": 1742142232768, "record_time": 1742142231.876678}
{"action": "update", "arg": {"instType": "SPOT", "channel": "books", "instId": "BTCUSDT"}, "data": [{"asks": [["84279.74", "0.206077"], ["84280.90", "0"], ["84290.66", "0.004595"], ["84290.70", "0.005541"], ["84290.71", "0.010074"], ["84290.72", "0.001475"], ["84290.73", "0.013936"], ["84290.78", "0.006307"], ["84290.81", "0.001066"], ["84291.14", "0.030015"], ["84291.65", "0.001923"], ["84291.66", "0.000078"], ["84291.67", "0.007955"], ["84291.68", "0.024680"], ["84291.70", "0.012985"], ["84291.71", "0.007110"], ["84291.72", "0.009191"], ["84291.75", "0.004739"], ["84294.99", "0.080082"], ["84300.54", "0.001205"], ["84301.15", "0.014791"], ["84301.16", "0.064667"], ["84303.15", "0.073832"], ["84303.74", "1.894765"], ["84303.80", "0.006356"], ["84304.23", "0.006356"], ["84304.40", "0.035952"], ["84305.65", "0.006356"], ["84306.20", "0.010985"], ["84306.24", "0.006356"], ["84307.22", "0.016428"], ["84307.33", "0.006356"], ["84307.35", "0.006356"], ["84308.07", "0.006356"], ["84308.34", "0.010984"], ["84308.59", "0.119843"], ["84309.42", "0.006356"], ["84311.59", "0.119879"], ["84312.40", "0"], ["84313.00", "0.015892"], ["84313.06", "0.009989"], ["84314.40", "0"], ["84315.29", "0.006356"], ["84316.00", "0.001807"], ["84316.40", "0"], ["84317.46", "0.015891"], ["84317.78", "0.010986"], ["84318.40", "0"], ["84320.11", "0"], ["84320.40", "0"], ["84320.60", "2.229325"], ["84320.90", "0.001033"], ["84322.40", "0"], ["84322.90", "0.001027"], ["84324.40", "0"], ["84324.90", "0.001037"], ["84326.40", "0"], ["84326.90", "0.001007"], ["84328.40", "0"], ["84328.90", "0.002837"], ["84330.40", "0"], ["84330.90", "0.007465"], ["84332.40", "0"], ["84332.50", "0"], ["84332.70", "0"], ["84332.90", "0.019646"], ["84333.20", "0"], ["84334.90", "0.051699"], ["84335.40", "0"], ["84336.90", "0.136051"], ["84338.90", "0.358030"], ["84340.90", "0.942183"], ["84341.50", "0.004980"], ["84341.80", "0.001026"], ["84342.10", "0.001049"], ["84342.20", "0.001046"], ["84342.80", "0.001320"], ["84342.90", "3.054420"], ["84343.50", "0"], ["84343.60", "0.428880"], ["84343.80", "0"], ["84346.70", "0"], ["84347.80", "0"], ["84348.20", "0.411330"], ["84349.60", "0.469080"], ["84349.90", "0"], ["84350.20", "0"], ["84350.50", "0"], ["84351.50", "0.015150"], ["84351.70", "2.792490"], ["84351.80", "5.044380"], ["84351.90", "0.985470"], ["84352.20", "0"], ["84352.30", "0.015120"], ["84353.30", "0.117000"], ["84353.50", "0.035580"], ["84354.10", "2.669430"], ["84354.20", "0.007050"], ["84374.50", "0"], ["84383.00", "5.603656"], ["84391.50", "4.067170"], ["84400.00", "4.519077"], ["84408.50", "4.970985"], ["84417.00", "5.061367"], ["84425.50", "4.428696"], ["84434.00", "4.247933"], ["84442.50", "4.609459"], ["84451.00", "5.332511"], ["84459.50", "4.338314"], ["84468.00", "4.790222"], ["84476.50", "5.151748"], ["84485.00", "5.422893"], ["84493.50", "4.157551"], ["84502.00", "3.886407"], ["84510.50", "3.976788"], ["84519.00", "5.513274"], ["84527.50", "4.880604"], ["84536.00", "5.242130"], ["84544.50", "4.699841"], ["84869.57", "0"], ["84871.66", "0"], ["84871.79", "0"], ["84873.84", "0"], ["84874.79", "0"], ["84875.00", "0"], ["84875.78", "0"], ["84876.03", "0"], ["84879.10", "0"], ["84879.37", "0"], ["84879.59", "0"], ["84880.00", "0"], ["84880.89", "0"], ["84882.35", "0"], ["84883.65", "0"], ["84883.72", "0"], ["84883.84", "0"], ["84885.24", "0"], ["84885.53", "0"], ["84886.01", "0"], ["84886.02", "0"], ["84886.96", "0"], ["84887.65", "0"], ["84888.00", "0"], ["84888.68", "0"], ["84888.89", "0"], ["84889.87", "0"], ["84890.00", "0"], ["84892.02", "0"], ["84892.76", "0"], ["84892.78", "0"], ["84894.73", "0"], ["84894.74", "0"], ["84895.69", "0"], ["84895.83", "0"], ["84897.50", "0"], ["84899.08", "0"], ["84899.44", "0"], ["84900.00", "0"], ["84901.15", "0"], ["84903.27", "0"], ["84903.57", "0"]], "bids": [["84279.73", "1.486415"], ["84279.51", "1.894765"], ["84277.80", "0.073439"], ["84277.19", "0.139994"], ["84276.50", "0.001036"], ["84274.50", "0.001042"], ["84272.50", "0.001281"], ["84270.50", "0.003372"], ["84268.80", "0.014369"], ["84268.79", "0.000465"], ["84268.50", "0.008872"], ["84268.00", "0"], ["84266.66", "0.300351"], ["84266.65", "0"], ["84266.64", "0.353488"], ["84266.50", "0.023348"], ["84266.00", "0"], ["84265.31", "0.001230"], ["84265.30", "0.008539"], ["84265.26", "0.006703"], ["84265.22", "0.007515"], ["84265.20", "0.007646"], ["84264.50", "0.061443"], ["84264.00", "0"], ["84263.79", "0.007346"], ["84263.68", "0.006213"], ["84263.63", "0.016431"], ["84263.61", "0.015096"], ["84263.53", "0.001199"], ["84263.51", "0"], ["84263.22", "0.003069"], ["84262.86", "0.008147"], ["84262.65", "2.549760"], ["84262.50", "0.161692"], ["84262.00", "0"], ["84261.60", "0.002064"], ["84261.58", "0.007873"], ["84261.34", "0"], ["84261.25", "0.007953"], ["84261.23", "0.007475"], ["84260.57", "0.084454"], ["84260.50", "0.425504"], ["84260.00", "0"], ["84259.49", "0.005939"], ["84259.40", "0.017839"], ["84259.30", "0.015774"], ["84258.99", "0.016463"], ["84258.54", "0.006566"], ["84258.50", "1.119748"], ["84258.16", "0.005552"], ["84258.14", "0.004937"], ["84258.13", "0.007121"], ["84258.09", "0.005964"], ["84258.01", "0.008156"], ["84258.00", "0.009635"], ["84257.61", "0.007317"], ["84257.49", "0.028813"], ["84257.44", "0"], ["84257.33", "0.008989"], ["84257.28", "0.017064"], ["84257.18", "0.227714"], ["84256.80", "0"], ["84256.76", "0.007934"], ["84256.60", "0.008676"], ["84256.53", "0.017335"], ["84256.50", "2.946947"], ["84256.41", "0.010235"], ["84256.10", "0.001004"], ["84256.00", "0"], ["84255.82", "0.008283"], ["84255.71", "0.025088"], ["84255.43", "0.008166"], ["84255.40", "0.001035"], ["84254.64", "0.012651"], ["84254.06", "0.018523"], ["84254.00", "0.001011"], ["84253.90", "0.430410"], ["84253.60", "0.178560"], ["84253.56", "0.052117"], ["84253.24", "0.002950"], ["84252.00", "0"], ["84251.90", "0.274770"], ["84251.81", "0.076027"], ["84251.80", "0.069780"], ["84251.53", "0.021112"], ["84251.40", "0.142680"], ["84250.50", "0"], ["84250.00", "0"], ["84249.72", "0.012442"], ["84249.40", "0.701610"], ["84248.35", "0.073519"], ["84248.10", "0.009000"], ["84248.00", "4.826400"], ["84247.90", "1.779300"], ["84247.80", "0.069600"], ["84247.50", "0.915360"], ["84247.40", "0"], ["84246.98", "0.056649"], ["84246.70", "1.755570"], ["84246.20", "0.722070"], ["84246.10", "0"], ["84245.80", "0.479970"], ["84245.00", "0.142500"], ["84243.00", "0"], ["84242.00", "3.160020"], ["84241.98", "0.023943"], ["84241.88", "0.535170"], ["84241.30", "0.177960"], ["84241.20", "0.090000"], ["84240.70", "0"], ["84239.70", "0.009000"], ["84239.52", "0.008208"], ["84239.50", "0.177960"], ["84238.40", "0.370020"], ["84238.10", "0"], ["84237.20", "0.248880"], ["84236.90", "0"], ["84236.80", "0"], ["84236.60", "0"], ["84235.70", "0"], ["84234.97", "0.007186"], ["84234.92", "0.007585"], ["84234.70", "0"], ["84234.50", "0"], ["84233.30", "0"], ["84233.20", "0"], ["84232.20", "0"], ["84214.40", "4.609459"], ["84205.90", "3.886407"], ["84197.40", "4.338314"], ["84188.90", "4.157551"], ["84180.40", "4.699841"], ["84171.90", "4.880604"], ["84163.40", "4.067170"], ["84154.90", "5.513274"], ["84146.40", "3.976788"], ["84137.90", "5.422893"], ["84129.40", "4.428696"], ["84120.90", "5.151748"], ["84112.40", "5.603656"], ["84103.90", "5.061367"], ["84095.40", "4.790222"], ["84086.90", "4.519077"], ["84078.40", "4.247933"], ["84069.90", "5.332511"], ["84061.40", "4.970985"], ["84052.90", "5.242130"], ["84044.40", "0"], ["83894.17", "0"], ["83893.81", "0"], ["83893.64", "0"], ["83893.62", "0"], ["83892.29", "0"], ["83891.43", "0"], ["83891.30", "0"], ["83888.89", "0"], ["83888.86", "0"], ["83887.29", "0"], ["83887.11", "0"], ["83886.91", "0"], ["83885.98", "0"], ["83885.71", "0"], ["83884.62", "0"], ["83884.55", "0"], ["83884.30", "0"], ["83882.98", "0"], ["83882.92", "0"], ["83881.99", "0"], ["83880.00", "0"], ["83877.97", "0"], ["83877.55", "0"], ["83877.42", "0"], ["83877.29", "0"], ["83877.05", "0"], ["83876.25", "0"], ["83876.12", "0"], ["83875.99", "0"], ["83875.49", "0"], ["83875.16", "0"], ["83875.00", "0"], ["83874.55", "0"], ["83874.15", "0"], ["83873.87", "0"], ["83873.52", "0"], ["83870.97", "0"], ["83870.95", "0"], ["83870.78", "0"], ["83870.00", "0"], ["83869.57", "0"], ["83868.82", "0"], ["83866.67", "0"], ["83865.80", "0"], ["83865.10", "0"], ["83864.54", "0"], ["83863.64", "0"], ["83863.52", "0"], ["83860.29", "0"], ["83860.10", "0"], ["83860.00", "0"], ["83859.94", "0"], ["83859.35", "0"]], "checksum": -973619315, "ts": "1742142232969"}], "ts": 1742142232972, "record_time": 1742142232.081876}
{"action": "update", "arg": {"instType": "SPOT", "channel": "books", "instId": "BTCUSDT"}, "data": [{"asks": [["84279.74", "0"], ["84282.05", "0"], ["84294.99", "0"], ["84296.10", "0.003017"], ["84298.94", "0.002907"], ["84300.54", "0"], ["84300.57", "0.080082"], ["84301.58", "0"], ["84302.59", "0"], ["84302.89", "0.001827"], ["84303.15", "0.654741"], ["84303.16", "0"], ["84303.80", "0"], ["84304.23", "0"], ["84304.40", "0"], ["84305.73", "0"], ["84306.13", "0.001205"], ["84306.20", "0"], ["84307.13", "0.016427"], ["84307.33", "0"], ["84307.35", "0"], ["84308.19", "0.119869"], ["84309.38", "0.006356"], ["84309.42", "0.042308"], ["84309.65", "0.006356"], ["84309.82", "0.006356"], ["84310.17", "0.009989"], ["84310.92", "0.006356"], ["84311.50", "0.010985"], ["84312.13", "0.006356"], ["84312.36", "0.006356"], ["84312.77", "0.006356"], ["84312.79", "0.006356"], ["84312.93", "0.012712"], ["84316.00", "0"], ["84318.32", "0.119881"], ["84320.90", "0"], ["84322.90", "0"], ["84324.08", "0"], ["84324.10", "0.001044"], ["84324.83", "0.010000"], ["84324.90", "0"], ["84326.02", "0"], ["84326.10", "0.001012"], ["84326.50", "0"], ["84326.90", "0"], ["84328.10", "0.001049"], ["84328.90", "0"], ["84330.10", "0.001034"], ["84330.90", "0"], ["84332.10", "0.001040"], ["84332.90", "0"], ["84334.10", "0.001401"], ["84334.90", "0"], ["84336.10", "0.003688"], ["84336.90", "0"], ["84338.10", "0.009704"], ["84338.90", "0"], ["84340.10", "0.025537"], ["84340.90", "0"], ["84341.50", "0"], ["84341.80", "0"], ["84342.10", "0.067202"], ["84342.20", "0"], ["84342.80", "0"], ["84342.90", "0"], ["84343.40", "0"], ["84343.60", "0"], ["84343.91", "0.001597"], ["84344.10", "0.176849"], ["84345.00", "0.002880"], ["84345.10", "0.001890"], ["84345.85", "0.001597"], ["84346.90", "0.001004"], ["84347.10", "0.001006"], ["84348.20", "0.233010"], ["84348.30", "0.179100"], ["84348.60", "0"], ["84349.30", "0.258210"], ["84351.70", "0"], ["84351.80", "0"], ["84351.90", "0"], ["84352.30", "0"], ["84352.60", "0"], ["84353.30", "0.209100"], ["84353.50", "0"], ["84354.00", "0.015180"], ["84354.10", "0"], ["84355.50", "0.180000"], ["84356.10", "0.682230"], ["84356.40", "0.198000"], ["84356.60", "0.135000"], ["84357.10", "0.197885"], ["84357.20", "0.500370"], ["84357.50", "0.117000"], ["84357.60", "0.985470"], ["84358.20", "0.007050"], ["84383.00", "0"], ["84386.30", "4.247773"], ["84391.50", "0"], ["84394.80", "4.157395"], ["84400.00", "0"], ["84403.30", "5.603445"], ["84408.50", "0"], ["84411.80", "3.976639"], ["84417.00", "0"], ["84420.30", "4.699664"], ["84425.50", "0"], ["84428.80", "5.241933"], ["84434.00", "0"], ["84437.30", "4.880420"], ["84442.50", "0"], ["84442.70", "0.209200"], ["84445.80", "5.332311"], ["84451.00", "0"], ["84454.30", "3.886261"], ["84459.50", "0"], ["84462.80", "4.790042"], ["84468.00", "0"], ["84471.30", "4.428529"], ["84476.50", "0"], ["84479.80", "5.151555"], ["84485.00", "0"], ["84488.30", "4.067017"], ["84493.50", "0"], ["84496.80", "4.609286"], ["84502.00", "0"], ["84505.30", "4.338151"], ["84510.50", "0"], ["84513.80", "5.422689"], ["84519.00", "0"], ["84522.30", "5.061176"], ["84527.50", "0"], ["84530.80", "5.513067"], ["84536.00", "0"], ["84539.30", "4.518908"], ["84544.50", "0"], ["84547.80", "4.970798"], ["84867.80", "0"], ["84868.42", "0"], ["84868.52", "0"], ["84868.65", "0"]], "bids": [["84290.65", "0.414453"], ["84289.71", "1.894663"], ["84283.94", "0.209200"], ["84279.74", "1.133800"], ["84279.73", "1.662464"], ["84279.70", "0.001041"], ["84279.51", "0"], ["84277.80", "0"], ["84277.79", "0"], ["84277.70", "0.001048"], ["84276.50", "0"], ["84275.70", "0.002425"], ["84274.50", "0"], ["84273.70", "0.006380"], ["84272.85", "2.549626"], ["84272.51", "0.001396"], ["84272.50", "0"], ["84271.70", "0.016790"], ["84270.50", "0"], ["84269.70", "0.044185"], ["84268.79", "0"], ["84268.50", "0"], ["84267.70", "0.116275"], ["84266.66", "0"], ["84266.64", "0.353132"], ["84266.50", "0"], ["84265.70", "0.305987"], ["84265.59", "0.084442"], ["84264.98", "0.017836"], ["84264.50", "0"], ["84264.37", "0.018261"], ["84263.70", "0.805231"], ["84263.63", "0.072787"], ["84262.87", "0.017062"], ["84262.65", "0"], ["84262.50", "0"], ["84261.86", "0"], ["84261.70", "2.119029"], ["84261.02", "0.008165"], ["84260.57", "0"], ["84260.50", "0"], ["84259.80", "0.197876"], ["84259.70", "5.576392"], ["84259.40", "0"], ["84259.20", "0.406170"], ["84258.90", "0.001044"], ["84258.80", "2.351859"], ["84258.50", "0"], ["84258.33", "0"], ["84257.80", "0.212280"], ["84257.63", "0.263339"], ["84257.61", "0"], ["84257.28", "0"], ["84256.50", "9.612330"], ["84256.10", "0"], ["84255.80", "0.069780"], ["84255.60", "0.274770"], ["84255.43", "0"], ["84255.40", "0"], ["84254.30", "1.206180"], ["84254.00", "0"], ["84253.90", "0"], ["84253.60", "0.178140"], ["84253.24", "0"], ["84253.20", "0.915360"], ["84251.90", "0"], ["84251.80", "0.069600"], ["84251.40", "0.142500"], ["84251.24", "0.222740"], ["84249.40", "0"], ["84248.00", "2.387220"], ["84247.90", "0"], ["84247.50", "0"], ["84246.70", "0"], ["84246.20", "0.315600"], ["84245.05", "0"], ["84243.50", "0.090000"], ["84242.90", "0.420000"], ["84240.30", "0.090000"], ["84239.70", "0"], ["84239.60", "0.009000"], ["84239.50", "0"], ["84239.30", "0.090000"], ["84239.20", "0.177960"], ["84237.66", "0.047500"], ["84237.64", "0"], ["84237.20", "0"], ["84234.49", "0.017796"], ["84233.32", "0.001189"], ["84233.01", "0"], ["84231.39", "0.001180"], ["84230.30", "0.207047"], ["84222.69", "0"], ["84217.50", "4.880420"], ["84214.40", "0"], ["84213.52", "0"], ["84213.50", "0"], ["84211.59", "0"], ["84209.00", "4.970798"], ["84205.90", "0"], ["84200.50", "4.699664"], ["84197.40", "0"], ["84192.00", "5.151555"], ["84188.90", "0"], ["84183.50", "3.976639"], ["84180.40", "0"], ["84175.00", "4.609286"], ["84171.90", "0"], ["84166.50", "4.338151"], ["84163.40", "0"], ["84158.00", "4.157395"], ["84154.90", "0"], ["84149.50", "5.513067"], ["84146.40", "0"], ["84141.00", "4.790042"], ["84137.90", "0"], ["84132.50", "4.518908"], ["84129.40", "0"], ["84124.00", "5.422689"], ["84120.90", "0"], ["84115.50", "4.428529"], ["84112.40", "0"], ["84107.00", "5.332311"], ["84103.90", "0"], ["84098.50", "3.886261"], ["84095.40", "0"], ["84090.00", "5.061176"], ["84086.90", "0"], ["84081.50", "5.241933"], ["84078.40", "0"], ["84073.00", "4.247773"], ["84069.90", "0"], ["84064.50", "5.603445"], ["84061.40", "0"], ["84056.00", "4.067017"], ["84052.90", "0"], ["83894.17", "0.000022"]], "checksum": 1200215672, "ts": "1742142233170"}], "ts": 1742142233178, "record_time": 1742142232.286947}
