{"action": "update", "arg": {"instType": "SPOT", "channel": "books", "instId": "BTCUSDT"}, "data": [{"asks": [["83453.48", "0"], ["83469.40", "0.006357"], ["83471.03", "0"], ["83483.10", "0.005468"], ["83485.10", "0.014390"], ["83487.10", "0.037867"], ["83489.10", "0.099650"], ["83491.10", "0.262238"], ["83493.09", "0.754502"], ["83493.10", "0.690098"], ["83495.10", "1.816048"], ["83506.70", "0.958770"], ["83507.70", "0"], ["83536.80", "5.569128"], ["83545.20", "4.108373"], ["83553.60", "5.477831"], ["83562.00", "4.930048"], ["83570.40", "4.017076"], ["83578.80", "4.199670"], ["83587.20", "4.382265"], ["83595.60", "4.290967"], ["83604.00", "5.021345"], ["83612.40", "4.473562"], ["83620.80", "4.656156"], ["83629.20", "4.838750"], ["83637.60", "5.295236"], ["83646.00", "5.112642"], ["83654.40", "4.564859"], ["83662.80", "5.386533"], ["83671.20", "5.660425"], ["83679.60", "5.203939"], ["83688.00", "3.925779"], ["83696.40", "4.747453"], ["83772.56", "0.000614"], ["83772.68", "0.000087"]], "bids": [["83426.13", "0.016216"], ["83419.50", "0.160035"], ["83417.50", "0.421144"], ["83416.79", "0"], ["83415.50", "1.108274"], ["83415.17", "0.012748"], ["83415.07", "0.052300"], ["83413.50", "2.916511"], ["83411.50", "7.675030"], ["83395.00", "0"], ["83369.80", "5.203939"], ["83361.40", "5.295236"], ["83353.00", "4.564859"], ["83344.60", "4.747453"], ["83336.20", "5.386533"], ["83327.80", "5.112642"], ["83319.40", "4.017076"], ["83311.00", "4.473562"], ["83302.60", "4.199670"], ["83294.20", "5.569128"], ["83285.80", "3.925779"], ["83277.40", "4.108373"], ["83269.00", "5.660425"], ["83260.60", "4.656156"], ["83252.20", "5.021345"], ["83243.80", "4.382265"], ["83235.40", "4.930048"], ["83227.00", "5.477831"], ["83218.60", "4.290967"], ["83210.20", "4.838750"]], "checksum": 1896905087, "ts": "1742377420871"}], "ts": 1742377420874, "record_time": 1742377421.765974}
{"action": "update", "arg": {"instType": "SPOT", "channel": "books", "instId": "BTCUSDT"}, "data": [{"asks": [["83451.11", "0.032684"], ["83453.47", "0"], ["83536.79", "0.015365"], ["83545.20", "5.660425"], ["83553.60", "4.747453"], ["83562.00", "4.199670"], ["83570.40", "4.290967"], ["83578.80", "4.017076"], ["83595.60", "4.930048"], ["83604.00", "3.925779"], ["83612.40", "5.021345"], ["83629.20", "5.295236"], ["83637.60", "5.386533"], ["83646.00", "5.203939"], ["83654.40", "5.112642"], ["83662.80", "4.838750"], ["83671.20", "4.473562"], ["83679.60", "5.477831"], ["83688.00", "4.564859"], ["83696.40", "4.108373"], ["83772.68", "0"]], "bids": [["83445.00", "1.030866"], ["83439.32", "0"], ["83391.31", "0.062760"], ["83369.80", "4.382265"], ["83361.40", "5.203939"], ["83353.00", "4.290967"], ["83344.60", "4.017076"], ["83336.20", "5.112642"], ["83327.80", "4.564859"], ["83319.40", "4.930048"], ["83311.00", "5.295236"], ["83302.60", "4.473562"], ["83294.20", "4.108373"], ["83277.40", "4.199670"], ["83269.00", "5.021345"], ["83260.60", "4.838750"], ["83252.20", "4.656156"], ["83243.80", "5.386533"], ["83235.40", "5.477831"], ["83227.00", "5.660425"], ["83218.60", "4.747453"], ["83210.20", "5.569128"]], "checksum": 619365145, "ts": "1742377421078"}], "ts": 1742377421082, "record_time": 1742377421.98059}
{"action": "update", "arg": {"instType": "SPOT", "channel": "books", "instId": "BTCUSDT"}, "data": [{"asks": [["83445.01", "1.220909"], ["83451.10", "0.009805"], ["83451.11", "0"], ["83483.10", "0.005584"], ["83485.10", "0.014695"], ["83487.10", "0.038670"], ["83489.10", "0.101763"], ["83491.10", "0.267797"], ["83493.10", "0.704729"], ["83495.10", "1.854550"], ["83536.80", "4.838750"], ["83545.20", "4.930048"], ["83553.60", "5.112642"], ["83562.00", "5.386533"], ["83570.40", "3.925779"], ["83578.80", "5.295236"], ["83587.20", "5.569128"], ["83595.60", "4.747453"], ["83604.00", "4.656156"], ["83612.40", "5.203939"], ["83620.80", "4.290967"], ["83629.20", "4.382265"], ["83630.57", "0"], ["83637.60", "4.017076"], ["83646.00", "4.199670"], ["83654.40", "5.477831"], ["83662.80", "4.108373"], ["83671.20", "5.660425"], ["83679.60", "4.564859"], ["83688.00", "4.473562"], ["83696.40", "5.021345"], ["83772.68", "0.000087"]], "bids": [["83445.00", "1.030262"], ["83439.52", "0.045562"], ["83426.23", "0"], ["83425.50", "0.008859"], ["83423.50", "0.023111"], ["83421.50", "0.060816"], ["83419.50", "0.160042"], ["83417.50", "0.421165"], ["83416.95", "0.020924"], ["83415.50", "1.108328"], ["83413.71", "0"], ["83413.50", "2.916652"], ["83411.50", "7.675402"], ["83411.40", "0.002700"], ["83411.10", "0.946320"], ["83402.03", "0.018506"], ["83394.00", "0.000161"], ["83369.80", "4.108373"], ["83361.40", "4.930048"], ["83353.00", "5.203939"], ["83344.60", "3.925779"], ["83336.20", "5.477831"], ["83327.80", "5.386533"], ["83319.40", "4.564859"], ["83311.00", "4.017076"], ["83302.60", "4.838750"], ["83294.20", "5.112642"], ["83285.80", "5.569128"], ["83277.40", "4.747453"], ["83269.00", "4.199670"], ["83260.60", "4.382265"], ["83252.20", "4.473562"], ["83243.80", "4.656156"], ["83235.40", "4.290967"], ["83218.60", "5.295236"], ["83210.20", "5.021345"], ["82938.45", "0"]], "checksum": -763934869, "ts": "1742377421278"}], "ts": 1742377421283, "record_time": 1742377422.173576}
{"action": "update", "arg": {"instType": "SPOT", "channel": "books", "instId": "BTCUSDT"}, "data": [{"asks": [["83451.10", "0"], ["83481.10", "0.001537"], ["83483.10", "0.003918"], ["83485.10", "0.010311"], ["83487.10", "0.027132"], ["83489.10", "0.071402"], ["83491.10", "0.187899"], ["83493.10", "0.494470"], ["83495.10", "1.301237"], ["83501.80", "0"], ["83507.70", "0.035940"], ["83536.80", "5.112642"], ["83545.20", "4.017076"], ["83553.60", "4.382265"], ["83562.00", "4.747453"], ["83570.40", "4.199670"], ["83578.80", "4.838750"], ["83587.20", "4.473562"], ["83595.60", "4.656156"], ["83604.00", "5.386533"], ["83620.80", "5.021345"], ["83629.20", "3.925779"], ["83637.60", "5.477831"], ["83646.00", "5.295236"], ["83654.40", "5.569128"], ["83662.80", "4.564859"], ["83671.20", "4.290967"], ["83679.60", "4.108373"], ["83688.00", "5.660425"], ["83696.40", "4.930048"], ["83772.73", "0.000008"]], "bids": [["83429.50", "0.001015"], ["83427.50", "0.001430"], ["83425.50", "0.003764"], ["83423.50", "0.009906"], ["83421.50", "0.026068"], ["83419.51", "0.255237"], ["83419.50", "0.068599"], ["83417.50", "0.180524"], ["83416.95", "0"], ["83415.50", "0.475063"], ["83413.50", "1.250167"], ["83411.50", "3.289912"], ["83409.10", "0.022770"], ["83408.70", "0.166350"], ["83407.98", "0.020924"], ["83406.60", "0.991200"], ["83405.60", "0"], ["83405.20", "0.143700"], ["83403.20", "0"], ["83393.00", "0.000283"], ["83369.80", "5.295236"], ["83361.40", "5.112642"], ["83353.00", "4.199670"], ["83344.60", "4.838750"], ["83336.20", "4.564859"], ["83327.80", "4.473562"], ["83319.40", "5.021345"], ["83311.00", "3.925779"], ["83302.60", "4.017076"], ["83294.20", "5.386533"], ["83285.80", "4.108373"], ["83277.40", "4.930048"], ["83269.00", "5.203939"], ["83260.60", "5.660425"], ["83252.20", "5.569128"], ["83243.80", "4.747453"], ["83227.00", "5.477831"], ["83218.60", "4.382265"], ["83210.20", "4.656156"], ["82938.45", "0.000022"]], "checksum": -1562688703, "ts": "1742377421485"}], "ts": 1742377421487, "record_time": 1742377422.386041}
{"action": "update", "arg": {"instType": "SPOT", "channel": "books", "instId": "BTCUSDT"}, "data": [{"asks": [["83445.01", "1.272126"], ["83474.97", "0.008681"], ["83481.10", "0.002450"], ["83483.10", "0.006447"], ["83485.10", "0.016966"], ["83487.10", "0.044648"], ["83489.10", "0.117495"], ["83491.10", "0.309196"], ["83493.10", "0.813675"], ["83495.10", "2.141251"], ["83495.60", "0.922200"], ["83498.30", "2.312910"], ["83498.60", "0.092670"], ["83498.90", "0"], ["83499.10", "0.179550"], ["83505.50", "0"], ["83507.70", "0"], ["83536.80", "4.747453"], ["83545.20", "5.021345"], ["83553.60", "5.477831"], ["83562.00", "4.564859"], ["83570.40", "4.290967"], ["83578.80", "4.930048"], ["83587.20", "4.017076"], ["83604.00", "3.925779"], ["83612.40", "5.660425"], ["83620.80", "4.473562"], ["83629.20", "5.386533"], ["83633.51", "0.161395"], ["83637.60", "5.295236"], ["83646.00", "4.199670"], ["83654.40", "5.203939"], ["83662.80", "4.838750"], ["83671.20", "4.382265"], ["83679.60", "5.112642"], ["83688.00", "4.108373"], ["83696.40", "5.569128"]], "bids": [["83439.72", "0.045562"], ["83439.52", "0"], ["83423.50", "0.009907"], ["83421.50", "0.026071"], ["83419.50", "0.068609"], ["83417.50", "0.180550"], ["83415.50", "0.475131"], ["83413.50", "1.250343"], ["83411.50", "3.290377"], ["83411.10", "0"], ["83406.60", "0"], ["83403.20", "0.971640"], ["83369.80", "4.017076"], ["83361.40", "5.021345"], ["83353.00", "5.386533"], ["83327.80", "5.112642"], ["83319.40", "4.382265"], ["83311.00", "4.290967"], ["83302.60", "3.925779"], ["83294.20", "5.295236"], ["83285.80", "4.930048"], ["83277.40", "5.477831"], ["83269.00", "5.569128"], ["83260.60", "4.108373"], ["83252.20", "4.656156"], ["83243.80", "4.199670"], ["83235.40", "4.747453"], ["83227.00", "5.203939"], ["83218.60", "4.473562"], ["83210.20", "5.660425"], ["82937.59", "0.000423"]], "checksum": 23587153, "ts": "1742377421688"}], "ts": 1742377421692, "record_time": 1742377422.59039}
{"action": "update", "arg": {"instType": "SPOT", "channel": "books", "instId": "BTCUSDT"}, "data": [{"asks": [["83479.10", "0.002400"], ["83481.10", "0.006316"], ["83483.10", "0.016620"], ["83485.10", "0.043738"], ["83487.10", "0.115100"], ["83489.10", "0.302894"], ["83491.10", "0.797090"], ["83493.10", "2.097606"], ["83495.10", "5.519848"], ["83500.29", "0.006684"], ["83500.60", "0.269760"], ["83536.80", "4.564859"], ["83545.20", "5.112642"], ["83562.00", "4.017076"], ["83570.40", "4.199670"], ["83578.80", "5.660425"], ["83587.20", "4.382265"], ["83612.40", "4.473562"], ["83620.80", "4.747453"], ["83629.20", "5.021345"], ["83637.60", "4.290967"], ["83646.00", "4.930048"], ["83654.40", "4.838750"], ["83662.80", "5.295236"], ["83671.20", "5.386533"], ["83679.60", "5.203939"], ["83688.00", "5.569128"], ["83696.40", "4.108373"], ["83772.68", "0"], ["83772.73", "0"]], "bids": [["83445.00", "1.020866"], ["83423.50", "0.009810"], ["83421.50", "0.025815"], ["83419.50", "0.067934"], ["83417.50", "0.178774"], ["83415.50", "0.470457"], ["83413.50", "1.238045"], ["83411.50", "3.258013"], ["83405.50", "0.946320"], ["83369.80", "4.930048"], ["83353.00", "4.199670"], ["83344.60", "4.108373"], ["83336.20", "4.382265"], ["83327.80", "5.477831"], ["83319.40", "4.564859"], ["83302.60", "5.295236"], ["83294.20", "5.569128"], ["83285.80", "4.017076"], ["83277.40", "4.473562"], ["83269.00", "5.203939"], ["83260.60", "4.656156"], ["83252.20", "4.838750"], ["83243.80", "4.747453"], ["83235.40", "5.112642"], ["83227.00", "3.925779"], ["83218.60", "5.386533"], ["82937.59", "0"]], "checksum": -1531369187, "ts": "1742377421893"}], "ts": 1742377421895, "record_time": 1742377422.786819}
{"action": "update", "arg": {"instType": "SPOT", "channel": "books", "instId": "BTCUSDT"}, "data": [{"asks": [["83468.91", "0"], ["83479.10", "0.002690"], ["83481.10", "0.007080"], ["83483.10", "0.018631"], ["83485.10", "0.049029"], ["83487.10", "0.129023"], ["83489.10", "0.339536"], ["83491.10", "0.893514"], ["83493.10", "2.351354"], ["83495.10", "6.187774"], ["83536.80", "4.382265"], ["83553.60", "3.925779"], ["83562.00", "4.656156"], ["83570.40", "5.021345"], ["83578.80", "5.203939"], ["83587.20", "5.295236"], ["83595.60", "4.199670"], ["83604.00", "5.386533"], ["83612.40", "4.108373"], ["83620.80", "4.473562"], ["83629.20", "4.747453"], ["83637.60", "4.564859"], ["83646.00", "5.477831"], ["83654.40", "5.569128"], ["83662.80", "4.930048"], ["83671.20", "4.290967"], ["83679.60", "4.838750"], ["83688.00", "5.660425"], ["83696.40", "4.017076"], ["83772.68", "0.000087"]], "bids": [["83425.50", "0.003651"], ["83423.50", "0.009608"], ["83421.50", "0.025284"], ["83419.50", "0.066538"], ["83417.50", "0.175100"], ["83415.50", "0.460788"], ["83413.50", "1.212600"], ["83411.50", "3.191053"], ["83395.00", "0.000122"], ["83394.00", "0"], ["83369.80", "5.477831"], ["83361.40", "4.108373"], ["83353.00", "5.295236"], ["83344.60", "4.564859"], ["83336.20", "4.656156"], ["83327.80", "5.021345"], ["83319.40", "4.930048"], ["83302.60", "4.199670"], ["83294.20", "3.925779"], ["83285.80", "5.569128"], ["83277.40", "4.382265"], ["83269.00", "4.838750"], ["83260.60", "4.747453"], ["83252.20", "4.017076"], ["83243.80", "4.473562"], ["83235.40", "5.386533"], ["83227.00", "5.660425"], ["83218.60", "5.203939"], ["83210.20", "5.112642"]], "checksum": -1531369187, "ts": "1742377422107"}], "ts": 1742377422111, "record_time": 1742377423.001068}
{"action": "update", "arg": {"instType": "SPOT", "channel": "books", "instId": "BTCUSDT"}, "data": [{"asks": [["83483.10", "0.018884"], ["83485.10", "0.049694"], ["83487.10", "0.130775"], ["83489.10", "0.344143"], ["83491.10", "0.905641"], ["83493.10", "2.383266"], ["83495.10", "6.271753"], ["83495.60", "0.303840"], ["83498.30", "0.318510"], ["83503.00", "0"], ["83503.20", "0.008640"], ["83507.70", "0.035940"], ["83536.80", "5.021345"], ["83545.20", "4.382265"], ["83553.60", "5.386533"], ["83562.00", "5.477831"], ["83570.40", "5.569128"], ["83578.80", "3.925779"], ["83587.20", "4.017076"], ["83604.00", "4.930048"], ["83612.40", "4.290967"], ["83620.80", "5.203939"], ["83629.20", "5.660425"], ["83637.60", "5.112642"], ["83646.00", "5.295236"], ["83654.40", "4.656156"], ["83662.80", "4.564859"], ["83671.20", "4.473562"], ["83679.60", "4.108373"], ["83688.00", "4.747453"], ["83696.40", "4.838750"], ["83772.68", "0"]], "bids": [["83439.93", "0.045562"], ["83439.72", "0"], ["83423.50", "0.009810"], ["83421.50", "0.025816"], ["83419.50", "0.067938"], ["83417.50", "0.178784"], ["83415.50", "0.470484"], ["83413.50", "1.238116"], ["83411.50", "3.258199"], ["83406.70", "0"], ["83406.50", "0.008460"], ["83369.80", "4.108373"], ["83361.40", "4.199670"], ["83353.00", "4.838750"], ["83344.60", "4.473562"], ["83319.40", "5.386533"], ["83311.00", "5.660425"], ["83302.60", "5.203939"], ["83294.20", "5.569128"], ["83285.80", "4.930048"], ["83277.40", "5.295236"], ["83269.00", "4.017076"], ["83260.60", "4.564859"], ["83252.20", "5.477831"], ["83243.80", "5.112642"], ["83235.40", "3.925779"], ["83227.00", "4.382265"], ["83218.60", "4.290967"], ["83210.20", "4.747453"]], "checksum": 599558649, "ts": "1742377422313"}], "ts": 1742377422318, "record_time": 1742377423.208263}
{"action": "update", "arg": {"instType": "SPOT", "channel": "books", "instId": "BTCUSDT"}, "data": [{"asks": [["83471.69", "0.180306"], ["83536.80", "4.564859"], ["83545.20", "5.021345"], ["83553.60", "4.108373"], ["83562.00", "4.199670"], ["83570.40", "3.925779"], ["83578.80", "4.382265"], ["83595.60", "4.290967"], ["83604.00", "5.112642"], ["83612.40", "4.473562"], ["83620.80", "5.569128"], ["83629.20", "5.477831"], ["83637.60", "4.747453"], ["83654.40", "4.930048"], ["83662.80", "4.838750"], ["83671.20", "5.203939"], ["83679.60", "5.660425"], ["83688.00", "5.386533"], ["83696.40", "4.656156"], ["83772.56", "0"]], "bids": [["83423.50", "0.009609"], ["83421.50", "0.025285"], ["83419.50", "0.066542"], ["83417.50", "0.175110"], ["83415.50", "0.460815"], ["83413.50", "1.212671"], ["83411.50", "3.191239"], ["83395.00", "0.000283"], ["83369.80", "3.925779"], ["83361.40", "5.021345"], ["83353.00", "4.199670"], ["83344.60", "5.203939"], ["83336.20", "5.386533"], ["83327.80", "4.656156"], ["83319.40", "5.569128"], ["83311.00", "4.747453"], ["83302.60", "4.017076"], ["83294.20", "4.564859"], ["83285.80", "4.108373"], ["83277.40", "4.290967"], ["83269.00", "4.382265"], ["83260.60", "4.473562"], ["83252.20", "5.112642"], ["83243.80", "5.477831"], ["83235.40", "4.930048"], ["83227.00", "4.838750"], ["83218.60", "5.295236"], ["83210.20", "5.660425"]], "checksum": 599558649, "ts": "1742377422528"}], "ts": 1742377422531, "record_time": 1742377423.420951}
{"action": "update", "arg": {"instType": "SPOT", "channel": "books", "instId": "BTCUSDT"}, "data": [{"asks": [["83479.09", "0.002931"], ["83485.04", "0.023624"], ["83536.80", "5.203939"], ["83545.20", "4.108373"], ["83553.60", "4.930048"], ["83560.75", "0.058036"], ["83562.00", "5.295236"], ["83570.40", "4.564859"], ["83578.80", "5.112642"], ["83587.20", "5.477831"], ["83595.60", "4.838750"], ["83604.00", "4.656156"], ["83612.40", "4.290967"], ["83629.20", "5.386533"], ["83637.60", "4.473562"], ["83646.00", "4.199670"], ["83654.40", "4.747453"], ["83662.80", "3.925779"], ["83671.20", "5.021345"], ["83688.00", "4.017076"], ["83696.40", "4.382265"], ["83771.43", "0"], ["83772.00", "0"], ["83772.50", "0"]], "bids": [["83439.93", "0"], ["83404.74", "0.015066"], ["83369.80", "4.199670"], ["83361.40", "4.108373"], ["83353.00", "4.838750"], ["83352.10", "0.058036"], ["83336.20", "4.656156"], ["83327.80", "5.477831"], ["83319.40", "4.564859"], ["83311.00", "5.021345"], ["83294.20", "4.930048"], ["83285.80", "5.569128"], ["83277.40", "4.473562"], ["83269.00", "5.295236"], ["83260.60", "5.660425"], ["83252.20", "4.290967"], ["83243.80", "4.382265"], ["83235.40", "5.112642"], ["83227.00", "3.925779"], ["83218.60", "4.747453"], ["83210.20", "5.386533"], ["82938.45", "0"]], "checksum": -1965643832, "ts": "1742377422727"}], "ts": 1742377422729, "record_time": 1742377423.621442}
{"action": "update", "arg": {"instType": "SPOT", "channel": "books", "instId": "BTCUSDT"}, "data": [{"asks": [["83497.60", "0.927930"], ["83498.30", "0.333330"], ["83498.60", "0.077850"], ["83499.80", "0.958050"], ["83501.80", "0.101550"], ["83502.00", "0"], ["83505.10", "0.552720"], ["83506.70", "0"], ["83507.70", "0"], ["83536.80", "4.473562"], ["83545.20", "5.295236"], ["83553.60", "4.656156"], ["83562.00", "4.747453"], ["83578.80", "5.477831"], ["83587.20", "4.290967"], ["83595.60", "4.017076"], ["83604.00", "5.386533"], ["83612.40", "5.660425"], ["83620.80", "4.382265"], ["83629.20", "5.112642"], ["83637.60", "5.021345"], ["83646.00", "4.838750"], ["83654.40", "5.569128"], ["83662.80", "4.108373"], ["83671.20", "4.930048"], ["83679.60", "4.199670"], ["83688.00", "5.203939"], ["83696.40", "3.925779"]], "bids": [["83440.10", "0.045562"], ["83425.50", "0.003946"], ["83423.50", "0.010384"], ["83421.50", "0.027325"], ["83419.50", "0.071908"], ["83417.50", "0.189233"], ["83415.50", "0.497982"], ["83413.50", "1.310478"], ["83411.50", "3.448626"], ["83393.00", "0.000161"], ["83369.80", "5.112642"], ["83361.40", "4.747453"], ["83353.00", "4.930048"], ["83344.60", "4.564859"], ["83336.20", "3.925779"], ["83327.80", "4.382265"], ["83319.40", "5.569128"], ["83311.00", "4.838750"], ["83302.60", "4.656156"], ["83294.20", "5.203939"], ["83285.80", "4.199670"], ["83277.40", "5.295236"], ["83269.00", "5.386533"], ["83260.60", "4.290967"], ["83252.20", "4.108373"], ["83243.80", "5.021345"], ["83235.40", "4.017076"], ["83227.00", "4.473562"], ["83218.60", "5.660425"], ["83210.20", "5.477831"], ["82938.60", "0"]], "checksum": 1356184490, "ts": "1742377422928"}], "ts": 1742377422932, "record_time": 1742377423.821816}
{"action": "update", "arg": {"instType": "SPOT", "channel": "books", "instId": "BTCUSDT"}, "data": [{"asks": [["83479.10", "0.002657"], ["83481.10", "0.006993"], ["83483.10", "0.018402"], ["83485.10", "0.048428"], ["83487.10", "0.127440"], ["83489.10", "0.335369"], ["83491.10", "0.882551"], ["83493.10", "2.322503"], ["83495.10", "6.111848"], ["83495.60", "0.889680"], ["83500.60", "0"], ["83504.80", "0.015000"], ["83506.90", "0.312750"], ["83507.70", "0.035940"], ["83536.80", "4.564859"], ["83545.20", "5.203939"], ["83553.60", "4.473562"], ["83562.00", "4.290967"], ["83570.40", "4.382265"], ["83578.80", "5.295236"], ["83587.20", "4.930048"], ["83595.60", "5.569128"], ["83612.40", "4.747453"], ["83620.80", "4.017076"], ["83629.20", "5.477831"], ["83637.60", "4.199670"], ["83646.00", "4.656156"], ["83654.40", "4.838750"], ["83662.80", "3.925779"], ["83671.20", "5.112642"], ["83679.60", "4.108373"], ["83688.00", "5.021345"], ["83696.40", "5.660425"], ["83770.74", "0"]], "bids": [["83407.30", "0"], ["83404.10", "1.137210"], ["83369.80", "4.838750"], ["83361.40", "4.382265"], ["83353.00", "5.203939"], ["83344.60", "4.290967"], ["83327.80", "4.017076"], ["83319.40", "5.660425"], ["83311.00", "5.569128"], ["83302.60", "4.473562"], ["83294.20", "4.564859"], ["83277.40", "4.747453"], ["83269.00", "5.295236"], ["83260.60", "4.930048"], ["83252.20", "5.112642"], ["83243.80", "4.656156"], ["83235.40", "5.386533"], ["83227.00", "4.108373"], ["83218.60", "5.477831"], ["83210.20", "5.021345"], ["82938.60", "0.000022"]], "checksum": 1356184490, "ts": "1742377423128"}], "ts": 1742377423133, "record_time": 1742377424.024975}
{"action": "update", "arg": {"instType": "SPOT", "channel": "books", "instId": "BTCUSDT"}, "data": [{"asks": [["83493.10", "2.322340"], ["83495.10", "6.111421"], ["83495.60", "0.890130"], ["83495.70", "0.463710"], ["83500.30", "1.057530"], ["83503.40", "0.009000"], ["83504.50", "2.372250"], ["83507.70", "0"], ["83536.80", "4.656156"], ["83545.20", "4.473562"], ["83553.60", "4.108373"], ["83562.00", "5.112642"], ["83570.40", "5.203939"], ["83578.80", "4.199670"], ["83587.20", "3.925779"], ["83595.60", "5.386533"], ["83604.00", "4.930048"], ["83612.40", "4.290967"], ["83620.80", "5.660425"], ["83629.20", "4.838750"], ["83637.60", "4.382265"], ["83646.00", "5.477831"], ["83654.40", "4.017076"], ["83662.80", "5.569128"], ["83671.20", "5.295236"], ["83679.60", "4.747453"], ["83696.40", "4.564859"]], "bids": [["83440.29", "0.045562"], ["83440.10", "0"], ["83427.50", "0.001533"], ["83423.50", "0.010414"], ["83421.50", "0.027405"], ["83419.50", "0.072117"], ["83417.50", "0.189782"], ["83415.50", "0.499427"], ["83413.50", "1.314280"], ["83411.50", "3.458633"], ["83409.10", "0"], ["83408.70", "0.143700"], ["83407.40", "0.022800"], ["83406.90", "0.022680"], ["83393.00", "0"], ["83369.80", "5.203939"], ["83361.40", "5.021345"], ["83353.00", "5.112642"], ["83344.60", "4.564859"], ["83336.20", "5.569128"], ["83327.80", "4.199670"], ["83319.40", "4.382265"], ["83311.00", "5.477831"], ["83302.60", "5.386533"], ["83294.20", "4.473562"], ["83285.80", "5.660425"], ["83277.40", "4.290967"], ["83260.60", "4.838750"], ["83252.20", "4.017076"], ["83243.80", "4.930048"], ["83235.40", "3.925779"], ["83227.00", "4.747453"], ["83218.60", "4.656156"], ["83210.20", "4.108373"]], "checksum": -1990955484, "ts": "1742377423328"}], "ts": 1742377423332, "record_time": 1742377424.224998}
{"action": "update", "arg": {"instType": "SPOT", "channel": "books", "instId": "BTCUSDT"}, "data": [{"asks": [["83504.50", "3.637560"], ["83505.10", "0.003810"], ["83536.80", "5.386533"], ["83545.20", "4.930048"], ["83553.60", "4.017076"], ["83570.40", "4.564859"], ["83578.80", "4.838750"], ["83587.20", "5.477831"], ["83595.60", "4.290967"], ["83604.00", "5.569128"], ["83612.40", "4.382265"], ["83620.80", "4.199670"], ["83629.20", "5.295236"], ["83637.60", "4.656156"], ["83646.00", "4.747453"], ["83654.40", "4.108373"], ["83662.80", "4.473562"], ["83671.20", "5.203939"], ["83679.60", "5.660425"], ["83696.40", "3.925779"]], "bids": [["83417.50", "0.189921"], ["83415.50", "0.499792"], ["83413.50", "1.315242"], ["83411.50", "3.461162"], ["83394.00", "0.000122"], ["83369.80", "5.386533"], ["83361.40", "4.930048"], ["83353.00", "5.569128"], ["83344.60", "4.838750"], ["83336.20", "4.017076"], ["83327.80", "5.660425"], ["83319.40", "4.290967"], ["83311.00", "5.112642"], ["83302.60", "5.021345"], ["83294.20", "4.199670"], ["83285.80", "4.108373"], ["83277.40", "5.295236"], ["83269.00", "4.656156"], ["83260.60", "5.477831"], ["83252.20", "4.747453"], ["83243.80", "4.382265"], ["83235.40", "4.473562"], ["83227.00", "3.925779"], ["83218.60", "5.203939"], ["83210.20", "4.564859"], ["82938.60", "0"]], "checksum": -1990955484, "ts": "1742377423552"}], "ts": 1742377423555, "record_time": 1742377424.445473}
{"action": "update", "arg": {"instType": "SPOT", "channel": "books", "instId": "BTCUSDT"}, "data": [{"asks": [["83485.09", "0.115520"], ["83487.00", "0"], ["83536.80", "4.930048"], ["83545.20", "5.477831"], ["83553.60", "4.290967"], ["83562.00", "5.569128"], ["83570.40", "5.386533"], ["83578.80", "5.203939"], ["83587.20", "4.747453"], ["83595.60", "5.660425"], ["83604.00", "4.199670"], ["83612.40", "4.656156"], ["83620.80", "4.838750"], ["83629.20", "5.021345"], ["83637.60", "4.108373"], ["83646.00", "4.382265"], ["83654.40", "5.112642"], ["83662.80", "4.017076"], ["83671.20", "5.295236"], ["83679.60", "3.925779"], ["83688.00", "4.473562"], ["83696.40", "4.564859"]], "bids": [["83440.29", "0"], ["83427.50", "0.002265"], ["83425.50", "0.005962"], ["83423.50", "0.015690"], ["83421.50", "0.041289"], ["83419.50", "0.108654"], ["83417.50", "0.285933"], ["83415.50", "0.752454"], ["83413.50", "1.980142"], ["83411.50", "5.210902"], ["83394.00", "0.000283"], ["83369.80", "5.477831"], ["83361.40", "5.112642"], ["83353.00", "4.930048"], ["83344.60", "4.473562"], ["83336.20", "4.108373"], ["83327.80", "4.564859"], ["83319.40", "5.203939"], ["83311.00", "5.660425"], ["83294.20", "3.925779"], ["83285.80", "4.747453"], ["83277.40", "4.017076"], ["83269.00", "5.295236"], ["83260.60", "4.656156"], ["83252.20", "5.569128"], ["83243.80", "4.290967"], ["83235.40", "4.382265"], ["83227.00", "5.386533"], ["83218.60", "4.838750"], ["83210.20", "4.199670"], ["82938.60", "0.000022"]], "checksum": -1965643832, "ts": "1742377423753"}], "ts": 1742377423758, "record_time": 1742377424.655399}
{"action": "update", "arg": {"instType": "SPOT", "channel": "books", "instId": "BTCUSDT"}, "data": [{"asks": [["83536.80", "3.925779"], ["83545.20", "5.112642"], ["83553.60", "5.203939"], ["83562.00", "5.386533"], ["83570.40", "4.656156"], ["83578.80", "4.564859"], ["83587.20", "4.017076"], ["83595.60", "5.569128"], ["83604.00", "4.838750"], ["83612.40", "4.290967"], ["83620.80", "5.295236"], ["83629.20", "5.477831"], ["83637.60", "4.382265"], ["83646.00", "4.930048"], ["83654.40", "4.199670"], ["83662.80", "4.473562"], ["83671.20", "4.747453"], ["83679.60", "4.108373"], ["83688.00", "5.021345"], ["83696.40", "5.660425"]], "bids": [["83445.00", "1.030262"], ["83440.46", "0.045562"], ["83427.50", "0.001505"], ["83425.50", "0.003960"], ["83423.50", "0.010422"], ["83421.50", "0.027424"], ["83419.50", "0.072170"], ["83417.50", "0.189921"], ["83415.50", "0.499792"], ["83413.50", "1.315242"], ["83411.50", "3.461162"], ["83407.98", "0"], ["83397.30", "0.020924"], ["83369.80", "5.660425"], ["83361.40", "4.930048"], ["83353.00", "4.838750"], ["83344.60", "5.477831"], ["83336.20", "3.925779"], ["83327.80", "4.382265"], ["83319.40", "4.017076"], ["83311.00", "4.656156"], ["83302.60", "4.747453"], ["83294.20", "4.199670"], ["83285.80", "5.203939"], ["83277.40", "5.569128"], ["83269.00", "4.108373"], ["83260.60", "5.386533"], ["83252.20", "4.473562"], ["83235.40", "5.021345"], ["83227.00", "5.295236"], ["83218.60", "4.564859"], ["83210.20", "5.112642"], ["82938.60", "0"]], "checksum": -1552958801, "ts": "1742377423965"}], "ts": 1742377423969, "record_time": 1742377424.872031}
{"action": "update", "arg": {"instType": "SPOT", "channel": "books", "instId": "BTCUSDT"}, "data": [{"asks": [["83496.19", "0"], ["83498.71", "0.001598"], ["83504.80", "0"], ["83507.70", "0.035940"], ["83536.80", "4.930048"], ["83545.20", "4.108373"], ["83553.60", "4.838750"], ["83562.00", "5.295236"], ["83570.40", "5.386533"], ["83578.80", "5.203939"], ["83587.20", "4.656156"], ["83595.60", "4.564859"], ["83604.00", "5.477831"], ["83612.40", "5.021345"], ["83620.80", "5.112642"], ["83629.20", "4.473562"], ["83637.60", "4.747453"], ["83646.00", "4.382265"], ["83654.40", "3.925779"], ["83662.80", "4.017076"], ["83671.20", "4.199670"], ["83679.60", "5.569128"], ["83688.00", "5.660425"], ["83696.40", "4.290967"]], "bids": [["83431.60", "0"], ["83431.06", "0.111710"], ["83405.29", "0.023958"], ["83402.85", "0.024164"], ["83402.73", "0"], ["83400.45", "0"], ["83389.23", "0.001186"], ["83386.71", "0"], ["83369.80", "5.112642"], ["83353.00", "4.564859"], ["83344.60", "5.021345"], ["83336.20", "4.656156"], ["83327.80", "3.925779"], ["83319.40", "5.477831"], ["83311.00", "5.660425"], ["83302.60", "4.108373"], ["83294.20", "4.382265"], ["83285.80", "4.199670"], ["83277.40", "5.203939"], ["83269.00", "4.838750"], ["83260.60", "5.569128"], ["83243.80", "5.386533"], ["83235.40", "4.290967"], ["83218.60", "4.017076"], ["83210.20", "4.747453"]], "checksum": -535466680, "ts": "1742377424166"}], "ts": 1742377424170, "record_time": 1742377425.060311}
{"action": "update", "arg": {"instType": "SPOT", "channel": "books", "instId": "BTCUSDT"}, "data": [{"asks": [["83536.80", "5.112642"], ["83545.20", "4.382265"], ["83553.60", "4.473562"], ["83570.40", "5.477831"], ["83578.80", "4.017076"], ["83587.20", "4.108373"], ["83595.60", "4.747453"], ["83604.00", "5.386533"], ["83620.80", "4.290967"], ["83629.20", "5.569128"], ["83637.60", "3.925779"], ["83646.00", "5.660425"], ["83654.40", "5.203939"], ["83662.80", "4.656156"], ["83671.20", "4.930048"], ["83679.60", "4.838750"], ["83688.00", "4.199670"], ["83696.40", "4.564859"]], "bids": [["83440.62", "0.045561"], ["83440.46", "0"], ["83427.50", "0.002269"], ["83425.50", "0.005970"], ["83423.50", "0.015710"], ["83421.50", "0.041342"], ["83419.50", "0.108795"], ["83417.50", "0.286302"], ["83415.50", "0.753426"], ["83413.50", "1.982701"], ["83411.50", "5.217635"], ["83395.00", "0.000161"], ["83369.80", "5.386533"], ["83361.40", "5.021345"], ["83353.00", "4.382265"], ["83344.60", "4.017076"], ["83336.20", "5.477831"], ["83327.80", "4.930048"], ["83319.40", "5.569128"], ["83311.00", "4.838750"], ["83302.60", "4.199670"], ["83294.20", "4.108373"], ["83285.80", "5.660425"], ["83277.40", "5.112642"], ["83269.00", "4.564859"], ["83260.60", "4.656156"], ["83252.20", "3.925779"], ["83243.80", "5.203939"], ["83218.60", "4.473562"]], "checksum": -1222999408, "ts": "1742377424369"}], "ts": 1742377424373, "record_time": 1742377425.265775}
{"action": "update", "arg": {"instType": "SPOT", "channel": "books", "instId": "BTCUSDT"}, "data": [{"asks": [["83495.10", "6.111179"], ["83545.20", "5.660425"], ["83553.60", "5.477831"], ["83562.00", "5.021345"], ["83570.40", "4.838750"], ["83578.80", "4.290967"], ["83587.20", "4.473562"], ["83595.60", "4.017076"], ["83604.00", "4.930048"], ["83612.40", "5.203939"], ["83620.80", "4.199670"], ["83629.20", "5.295236"], ["83637.60", "4.747453"], ["83646.00", "4.564859"], ["83654.40", "4.108373"], ["83671.20", "3.925779"], ["83679.60", "5.386533"], ["83688.00", "4.382265"], ["83696.40", "5.569128"]], "bids": [["83445.00", "1.029562"], ["83435.03", "0.000366"], ["83434.91", "0"], ["83395.00", "0"], ["83369.80", "5.112642"], ["83361.40", "5.203939"], ["83344.60", "4.747453"], ["83336.20", "4.564859"], ["83327.80", "4.290967"], ["83319.40", "5.477831"], ["83311.00", "4.473562"], ["83302.60", "4.656156"], ["83285.80", "4.017076"], ["83277.40", "5.660425"], ["83269.00", "4.199670"], ["83260.60", "3.925779"], ["83252.20", "4.930048"], ["83243.80", "5.569128"], ["83235.40", "5.295236"], ["83227.00", "5.386533"], ["83218.60", "4.838750"], ["83210.20", "5.021345"], ["82938.60", "0.000022"]], "checksum": -1093311341, "ts": "1742377424570"}], "ts": 1742377424573, "record_time": 1742377425.464204}
{"action": "update", "arg": {"instType": "SPOT", "channel": "books", "instId": "BTCUSDT"}, "data": [{"asks": [["83470.80", "0"], ["83471.69", "0"], ["83472.87", "0.119900"], ["83474.98", "0"], ["83475.81", "0"], ["83477.05", "0.015895"], ["83477.87", "0.010984"], ["83479.10", "0.001385"], ["83481.10", "0.003537"], ["83483.10", "0.009308"], ["83485.10", "0.024494"], ["83487.10", "0.064459"], ["83489.09", "0.358752"], ["83489.10", "0.169628"], ["83491.10", "0.446389"], ["83493.10", "1.174708"], ["83495.10", "3.091339"], ["83498.47", "0"], ["83500.55", "0.001598"], ["83507.70", "0"], ["83536.79", "0"], ["83536.80", "4.656156"], ["83545.20", "5.477831"], ["83553.60", "4.564859"], ["83562.00", "5.569128"], ["83570.40", "5.386533"], ["83595.60", "4.199670"], ["83612.40", "5.112642"], ["83620.80", "4.017076"], ["83629.20", "5.021345"], ["83646.00", "4.838750"], ["83654.40", "4.382265"], ["83662.80", "3.925779"], ["83671.20", "5.295236"], ["83679.60", "5.660425"], ["83688.00", "5.203939"], ["83696.40", "4.108373"], ["83770.74", "0.000729"], ["83771.43", "0.000084"], ["83772.00", "0.000096"]], "bids": [["83436.62", "0.001387"], ["83435.57", "0"], ["83427.50", "0.002644"], ["83425.50", "0.006960"], ["83423.50", "0.018315"], ["83421.50", "0.048198"], ["83419.50", "0.126997"], ["83417.50", "0.334203"], ["83415.50", "0.879481"], ["83413.50", "2.314423"], ["83412.79", "0.262709"], ["83411.50", "6.090589"], ["83410.72", "0"], ["83410.46", "0.020924"], ["83408.63", "0.073759"], ["83407.78", "0.056755"], ["83406.56", "0"], ["83405.72", "0"], ["83397.30", "0"], ["83387.23", "0.001183"], ["83385.16", "0"], ["83369.80", "5.386533"], ["83361.40", "4.564859"], ["83353.00", "5.021345"], ["83336.20", "5.203939"], ["83327.80", "4.108373"], ["83319.40", "5.569128"], ["83311.00", "5.477831"], ["83302.60", "5.112642"], ["83294.20", "4.930048"], ["83285.80", "4.473562"], ["83277.40", "4.017076"], ["83269.00", "4.382265"], ["83252.20", "4.838750"], ["83243.80", "5.295236"], ["83235.40", "4.290967"], ["83227.00", "5.660425"], ["83218.60", "4.199670"], ["83210.20", "4.656156"]], "checksum": -63619770, "ts": "1742377424771"}], "ts": 1742377424774, "record_time": 1742377425.664444}
{"action": "update", "arg": {"instType": "SPOT", "channel": "books", "instId": "BTCUSDT"}, "data": [{"asks": [["83471.67", "0.180783"], ["83479.09", "0"], ["83489.09", "0.057794"], ["83536.80", "4.382265"], ["83545.20", "5.569128"], ["83553.60", "4.017076"], ["83562.00", "5.112642"], ["83570.40", "4.838750"], ["83578.80", "4.656156"], ["83587.20", "3.925779"], ["83595.60", "5.203939"], ["83604.00", "4.564859"], ["83612.40", "4.290967"], ["83620.80", "5.386533"], ["83629.20", "4.747453"], ["83637.60", "4.108373"], ["83646.00", "5.021345"], ["83654.40", "5.477831"], ["83662.80", "5.295236"], ["83671.20", "5.660425"], ["83679.60", "4.473562"], ["83688.00", "4.199670"], ["83696.40", "4.930048"]], "bids": [["83440.78", "0.045561"], ["83440.62", "0"], ["83417.50", "0.334316"], ["83415.50", "0.879779"], ["83413.50", "2.315208"], ["83411.50", "6.092653"], ["83408.80", "0.254340"], ["83393.00", "0.000161"], ["83369.80", "5.112642"], ["83361.40", "4.382265"], ["83353.00", "4.564859"], ["83344.60", "5.477831"], ["83327.80", "5.386533"], ["83319.40", "4.108373"], ["83311.00", "4.747453"], ["83302.60", "3.925779"], ["83294.20", "4.473562"], ["83285.80", "5.295236"], ["83277.40", "5.021345"], ["83269.00", "5.660425"], ["83260.60", "4.290967"], ["83252.20", "4.199670"], ["83243.80", "4.930048"], ["83235.40", "4.838750"], ["83227.00", "4.656156"], ["83218.60", "5.569128"], ["83210.20", "4.017076"], ["82938.60", "0"]], "checksum": -342668847, "ts": "1742377424970"}], "ts": 1742377424973, "record_time": 1742377425.86407}
{"action": "update", "arg": {"instType": "SPOT", "channel": "books", "instId": "BTCUSDT"}, "data": [{"asks": [["83536.80", "5.477831"], ["83545.20", "4.290967"], ["83553.60", "4.564859"], ["83562.00", "4.473562"], ["83570.40", "5.295236"], ["83578.80", "4.382265"], ["83587.20", "4.108373"], ["83595.60", "5.021345"], ["83604.00", "3.925779"], ["83612.40", "4.199670"], ["83629.20", "4.656156"], ["83637.60", "5.203939"], ["83646.00", "4.747453"], ["83654.40", "5.569128"], ["83662.80", "5.660425"], ["83671.20", "4.838750"], ["83679.60", "4.017076"], ["83688.00", "4.930048"], ["83696.40", "5.112642"]], "bids": [["83393.00", "0.000283"], ["83369.80", "5.203939"], ["83361.40", "4.838750"], ["83353.00", "4.473562"], ["83344.60", "4.747453"], ["83336.20", "5.295236"], ["83327.80", "4.108373"], ["83319.40", "5.112642"], ["83311.00", "4.199670"], ["83302.60", "4.290967"], ["83294.20", "4.930048"], ["83285.80", "4.017076"], ["83277.40", "4.656156"], ["83269.00", "4.564859"], ["83260.60", "5.386533"], ["83252.20", "3.925779"], ["83243.80", "5.660425"], ["83235.40", "5.569128"], ["83227.00", "5.021345"], ["83218.60", "4.382265"], ["83210.20", "5.477831"]], "checksum": -342668847, "ts": "1742377425171"}], "ts": 1742377425175, "record_time": 1742377426.066195}
{"action": "update", "arg": {"instType": "SPOT", "channel": "books", "instId": "BTCUSDT"}, "data": [{"asks": [["83485.10", "0.024383"], ["83487.10", "0.064165"], ["83489.10", "0.168856"], ["83491.10", "0.444356"], ["83493.10", "1.169358"], ["83495.10", "3.077258"], ["83504.80", "0.015000"], ["83536.80", "4.473562"], ["83545.20", "4.838750"], ["83553.60", "4.290967"], ["83562.00", "4.656156"], ["83570.40", "5.660425"], ["83578.80", "4.747453"], ["83587.20", "4.017076"], ["83595.60", "4.108373"], ["83604.00", "4.382265"], ["83612.40", "5.295236"], ["83620.80", "3.925779"], ["83629.20", "5.386533"], ["83637.60", "5.569128"], ["83646.00", "4.930048"], ["83654.40", "5.021345"], ["83662.80", "4.199670"], ["83671.20", "4.564859"], ["83679.60", "5.477831"], ["83688.00", "5.112642"], ["83696.40", "5.203939"], ["83772.00", "0"]], "bids": [["83440.78", "0"], ["83427.50", "0.002273"], ["83425.50", "0.005981"], ["83423.50", "0.015975"], ["83421.50", "0.042039"], ["83419.50", "0.110630"], ["83417.50", "0.291132"], ["83415.50", "0.766136"], ["83413.50", "2.016147"], ["83411.50", "5.305650"], ["83410.46", "0"], ["83401.94", "0.020924"], ["83369.80", "4.108373"], ["83361.40", "4.290967"], ["83344.60", "5.203939"], ["83336.20", "4.564859"], ["83327.80", "4.747453"], ["83319.40", "5.386533"], ["83311.00", "4.930048"], ["83302.60", "5.021345"], ["83294.20", "4.382265"], ["83285.80", "4.199670"], ["83277.40", "5.477831"], ["83269.00", "5.112642"], ["83260.60", "4.017076"], ["83252.20", "5.660425"], ["83243.80", "4.838750"], ["83235.40", "5.295236"], ["83227.00", "4.656156"], ["83218.60", "3.925779"], ["83210.20", "5.569128"], ["82938.60", "0.000022"]], "checksum": 63963347, "ts": "1742377425382"}], "ts": 1742377425390, "record_time": 1742377426.280302}
{"action": "update", "arg": {"instType": "SPOT", "channel": "books", "instId": "BTCUSDT"}, "data": [{"asks": [["83536.80", "4.747453"], ["83545.20", "4.564859"], ["83553.60", "4.930048"], ["83562.00", "5.386533"], ["83570.40", "4.473562"], ["83578.80", "5.660425"], ["83587.20", "5.112642"], ["83595.60", "5.477831"], ["83604.00", "4.108373"], ["83620.80", "4.656156"], ["83629.20", "5.203939"], ["83646.00", "4.290967"], ["83654.40", "4.838750"], ["83662.80", "4.382265"], ["83671.20", "5.021345"], ["83679.60", "4.017076"], ["83688.00", "4.199670"], ["83696.40", "3.925779"]], "bids": [["83440.93", "0.045561"], ["83423.50", "0.015775"], ["83421.50", "0.041513"], ["83419.50", "0.109246"], ["83417.50", "0.287490"], ["83415.50", "0.756553"], ["83413.50", "1.990929"], ["83411.50", "5.239285"], ["83394.00", "0.000122"], ["83369.80", "4.017076"], ["83361.40", "4.108373"], ["83353.00", "3.925779"], ["83344.60", "5.386533"], ["83336.20", "4.199670"], ["83327.80", "4.838750"], ["83319.40", "4.564859"], ["83313.24", "0"], ["83311.00", "5.660425"], ["83310.50", "0.132259"], ["83302.60", "4.656156"], ["83285.80", "5.477831"], ["83277.40", "5.295236"], ["83269.00", "5.203939"], ["83260.60", "4.747453"], ["83252.20", "5.569128"], ["83243.80", "4.473562"], ["83235.40", "5.112642"], ["83227.00", "4.930048"], ["83218.60", "5.021345"], ["83210.20", "4.290967"], ["82938.60", "0"]], "checksum": 1542121963, "ts": "1742377425602"}], "ts": 1742377425606, "record_time": 1742377426.496298}
{"action": "update", "arg": {"instType": "SPOT", "channel": "books", "instId": "BTCUSDT"}, "data": [{"asks": [["83479.09", "0.001477"], ["83493.10", "1.169394"], ["83495.10", "3.077351"], ["83536.80", "4.930048"], ["83545.20", "5.660425"], ["83553.60", "4.290967"], ["83562.00", "5.021345"], ["83570.40", "4.564859"], ["83578.80", "4.747453"], ["83587.20", "5.569128"], ["83595.60", "5.295236"], ["83604.00", "3.925779"], ["83612.40", "4.017076"], ["83620.80", "4.382265"], ["83629.20", "4.838750"], ["83637.60", "4.473562"], ["83646.00", "4.108373"], ["83654.40", "5.112642"], ["83662.80", "5.203939"], ["83671.20", "5.386533"], ["83679.60", "5.477831"], ["83688.00", "4.656156"], ["83696.40", "4.199670"], ["83771.43", "0"]], "bids": [["83421.50", "0.041740"], ["83419.50", "0.109844"], ["83417.50", "0.289062"], ["83415.50", "0.760689"], ["83413.50", "2.002025"], ["83411.50", "5.268487"], ["83394.00", "0"], ["83369.80", "5.203939"], ["83361.40", "4.564859"], ["83344.60", "4.382265"], ["83327.80", "5.660425"], ["83319.40", "4.290967"], ["83311.00", "5.021345"], ["83302.60", "4.930048"], ["83294.20", "4.108373"], ["83285.80", "4.838750"], ["83277.40", "5.112642"], ["83269.00", "5.569128"], ["83260.60", "4.017076"], ["83252.20", "4.747453"], ["83243.80", "5.295236"], ["83235.40", "4.656156"], ["83227.00", "5.477831"], ["83218.60", "4.473562"], ["83210.20", "5.386533"], ["82938.60", "0.000022"]], "checksum": 1542121963, "ts": "1742377425803"}], "ts": 1742377425805, "record_time": 1742377426.710516}
{"action": "update", "arg": {"instType": "SPOT", "channel": "books", "instId": "BTCUSDT"}, "data": [{"asks": [["83466.92", "0"], ["83469.40", "0"], ["83501.80", "0"], ["83536.80", "4.838750"], ["83545.20", "4.290967"], ["83553.60", "4.930048"], ["83562.00", "5.295236"], ["83570.40", "5.021345"], ["83578.80", "4.199670"], ["83587.20", "4.108373"], ["83595.60", "5.477831"], ["83604.00", "5.203939"], ["83612.40", "5.386533"], ["83620.80", "3.925779"], ["83629.20", "4.656156"], ["83637.60", "4.564859"], ["83646.00", "4.473562"], ["83654.40", "4.747453"], ["83662.80", "5.660425"], ["83671.20", "4.382265"], ["83679.60", "4.017076"], ["83688.00", "5.569128"], ["83696.40", "5.112642"], ["83771.43", "0.000084"], ["83772.00", "0.000096"], ["83772.50", "0.000008"]], "bids": [["83441.07", "0.045561"], ["83440.93", "0"], ["83417.36", "0"], ["83415.17", "0"], ["83369.80", "5.295236"], ["83361.40", "5.660425"], ["83353.00", "4.930048"], ["83344.60", "5.203939"], ["83327.80", "4.656156"], ["83319.40", "4.017076"], ["83311.00", "4.747453"], ["83302.60", "3.925779"], ["83294.20", "4.290967"], ["83285.80", "4.382265"], ["83269.00", "4.473562"], ["83260.60", "4.838750"], ["83252.20", "5.477831"], ["83243.80", "4.564859"], ["83235.40", "5.386533"], ["83227.00", "5.021345"], ["83218.60", "5.569128"], ["83210.20", "4.108373"], ["82938.45", "0.000022"], ["82937.59", "0.000423"]], "checksum": 1061038350, "ts": "1742377426003"}], "ts": 1742377426007, "record_time": 1742377426.897136}
{"action": "update", "arg": {"instType": "SPOT", "channel": "books", "instId": "BTCUSDT"}, "data": [{"asks": [["83485.10", "0.024600"], ["83487.10", "0.064736"], ["83489.10", "0.170357"], ["83491.10", "0.448310"], ["83493.10", "1.179762"], ["83495.10", "3.104638"], ["83536.80", "4.656156"], ["83545.20", "4.838750"], ["83553.60", "5.569128"], ["83562.00", "3.925779"], ["83578.80", "5.295236"], ["83587.20", "5.386533"], ["83595.60", "4.930048"], ["83604.00", "4.564859"], ["83612.40", "4.290967"], ["83620.80", "5.660425"], ["83629.20", "4.382265"], ["83637.60", "4.747453"], ["83646.00", "4.017076"], ["83654.40", "4.108373"], ["83662.80", "4.199670"], ["83671.20", "5.477831"], ["83679.60", "5.112642"], ["83688.00", "5.203939"], ["83696.40", "4.473562"]], "bids": [["83445.00", "1.020262"], ["83421.50", "0.041751"], ["83419.50", "0.109871"], ["83417.50", "0.289133"], ["83415.50", "0.760877"], ["83413.50", "2.002308"], ["83411.50", "5.269231"], ["83408.80", "0.238020"], ["83395.00", "0.000161"], ["83369.80", "4.199670"], ["83361.40", "5.203939"], ["83353.00", "5.660425"], ["83344.60", "4.473562"], ["83336.20", "4.382265"], ["83327.80", "4.017076"], ["83319.40", "5.295236"], ["83311.00", "5.021345"], ["83302.60", "5.112642"], ["83294.20", "5.386533"], ["83285.80", "5.569128"], ["83277.40", "5.477831"], ["83269.00", "3.925779"], ["83260.60", "4.930048"], ["83252.20", "4.656156"], ["83235.40", "4.747453"], ["83227.00", "4.290967"], ["83218.60", "4.108373"], ["83210.20", "4.838750"], ["82937.59", "0"]], "checksum": 412882576, "ts": "1742377426230"}], "ts": 1742377426234, "record_time": 1742377427.125053}
{"action": "update", "arg": {"instType": "SPOT", "channel": "books", "instId": "BTCUSDT"}, "data": [{"asks": [["83462.14", "0"], ["83462.56", "0"], ["83462.93", "0.035952"], ["83463.35", "0.119843"], ["83463.82", "0"], ["83464.21", "0"], ["83464.42", "0"], ["83464.61", "0.035960"], ["83464.75", "0"], ["83464.93", "0"], ["83465.01", "0.006357"], ["83465.10", "0"], ["83465.20", "0.006357"], ["83465.53", "0.006356"], ["83465.73", "0"], ["83465.81", "0"], ["83465.85", "0.006356"], ["83466.01", "0.006356"], ["83466.07", "0"], ["83466.21", "0"], ["83466.52", "0.006356"], ["83466.60", "0.010994"], ["83466.61", "0"], ["83466.73", "0"], ["83466.86", "0.006357"], ["83467.02", "0.006357"], ["83467.23", "0"], ["83467.27", "0"], ["83467.44", "0"], ["83467.52", "0.016429"], ["83467.53", "0.006357"], ["83467.73", "0"], ["83467.77", "0"], ["83468.02", "0.006357"], ["83468.05", "0.006357"], ["83468.36", "0.136314"], ["83468.52", "0.006357"], ["83468.55", "0.006357"], ["83468.74", "0"], ["83469.18", "0"], ["83469.53", "0.006357"], ["83470.05", "0.010985"], ["83470.11", "0"], ["83470.86", "0"], ["83470.89", "0.009990"], ["83471.78", "0.119908"], ["83471.86", "0"], ["83472.28", "0"], ["83472.44", "0"], ["83472.77", "0.119881"], ["83473.20", "0.015896"], ["83473.36", "0.009989"], ["83474.45", "0"], ["83475.37", "0.006357"], ["83536.80", "3.925779"], ["83545.20", "4.747453"], ["83553.60", "5.021345"], ["83562.00", "5.203939"], ["83570.40", "4.108373"], ["83578.80", "5.569128"], ["83587.20", "5.660425"], ["83595.60", "4.017076"], ["83604.00", "4.199670"], ["83612.40", "5.386533"], ["83620.80", "4.564859"], ["83629.20", "4.838750"], ["83637.60", "4.930048"], ["83646.00", "5.477831"], ["83654.40", "4.290967"], ["83662.80", "4.656156"], ["83671.20", "5.112642"], ["83679.60", "4.473562"], ["83688.00", "4.382265"], ["83696.40", "5.295236"]], "bids": [["83441.22", "0.045561"], ["83441.07", "0"], ["83422.88", "0.090725"], ["83422.46", "0.247315"], ["83422.09", "0.004096"], ["83421.67", "0"], ["83421.22", "0.084523"], ["83420.79", "0.017987"], ["83420.64", "0.018412"], ["83420.61", "0"], ["83420.43", "0"], ["83420.30", "0.005985"], ["83419.98", "0"], ["83419.95", "0.015873"], ["83419.86", "0"], ["83419.79", "0.016562"], ["83419.53", "0"], ["83419.29", "0.006619"], ["83419.21", "0.056234"], ["83419.04", "0"], ["83418.96", "0.017216"], ["83418.87", "0"], ["83418.50", "0"], ["83418.42", "0"], ["83418.30", "0.007380"], ["83418.29", "0.029032"], ["83418.17", "0"], ["83417.98", "0"], ["83417.82", "0.007996"], ["83417.79", "0.009058"], ["83417.50", "0.289085"], ["83417.46", "0.252805"], ["83417.38", "0"], ["83417.32", "0.008242"], ["83417.29", "0.017488"], ["83417.04", "0"], ["83417.00", "0.000283"], ["83416.54", "0"], ["83416.50", "0.000008"], ["83416.29", "0.008343"], ["83415.81", "0.052300"], ["83415.50", "0.760751"], ["83415.07", "0"], ["83414.98", "0.018649"], ["83414.20", "0"], ["83414.04", "0.270824"], ["83413.50", "2.001976"], ["83413.12", "0"], ["83413.03", "0.223164"], ["83412.62", "0.076646"], ["83412.44", "0.021277"], ["83412.11", "0"], ["83411.70", "0"], ["83411.53", "0"], ["83411.50", "5.268357"], ["83410.45", "0.012531"], ["83409.53", "0"], ["83369.80", "4.656156"], ["83361.40", "5.386533"], ["83353.00", "5.112642"], ["83344.60", "4.290967"], ["83336.20", "5.203939"], ["83327.80", "5.021345"], ["83319.40", "5.660425"], ["83311.00", "4.108373"], ["83302.60", "4.382265"], ["83294.20", "5.569128"], ["83285.80", "4.017076"], ["83277.40", "4.747453"], ["83269.00", "4.564859"], ["83260.60", "5.477831"], ["83252.20", "4.199670"], ["83243.80", "4.473562"], ["83235.40", "4.838750"], ["83227.00", "3.925779"], ["83218.60", "4.930048"], ["83210.20", "5.295236"], ["82940.00", "0"], ["82938.97", "0"], ["82938.60", "0"], ["82938.45", "0"]], "checksum": -1347583939, "ts": "1742377426431"}], "ts": 1742377426434, "record_time": 1742377427.329147}
{"action": "update", "arg": {"instType": "SPOT", "channel": "books", "instId": "BTCUSDT"}, "data": [{"asks": [["83495.10", "3.104507"], ["83497.60", "0.942750"], ["83498.30", "0.318510"], ["83536.80", "5.477831"], ["83545.20", "4.564859"], ["83553.60", "4.382265"], ["83570.40", "5.295236"], ["83578.80", "5.660425"], ["83587.20", "5.112642"], ["83595.60", "4.473562"], ["83604.00", "4.108373"], ["83612.40", "5.569128"], ["83620.80", "5.386533"], ["83646.00", "5.021345"], ["83654.40", "4.747453"], ["83662.80", "4.199670"], ["83671.20", "3.925779"], ["83679.60", "4.017076"], ["83688.00", "4.290967"], ["83696.40", "4.656156"]], "bids": [["83425.50", "0.006105"], ["83423.50", "0.016064"], ["83421.50", "0.042275"], ["83419.50", "0.111248"], ["83417.50", "0.292758"], ["83415.50", "0.770417"], ["83413.50", "2.027414"], ["83411.50", "5.335298"], ["83395.00", "0.000283"], ["83369.80", "4.108373"], ["83361.40", "4.017076"], ["83353.00", "5.660425"], ["83344.60", "5.203939"], ["83336.20", "4.930048"], ["83327.80", "5.477831"], ["83319.40", "4.838750"], ["83311.00", "3.925779"], ["83302.60", "5.021345"], ["83294.20", "4.382265"], ["83285.80", "5.569128"], ["83269.00", "4.473562"], ["83260.60", "5.386533"], ["83252.20", "5.295236"], ["83243.80", "4.656156"], ["83235.40", "4.564859"], ["83227.00", "4.290967"], ["83218.60", "5.112642"], ["83210.20", "4.199670"]], "checksum": -1347583939, "ts": "1742377426644"}], "ts": 1742377426648, "record_time": 1742377427.545446}
{"action": "update", "arg": {"instType": "SPOT", "channel": "books", "instId": "BTCUSDT"}, "data": [{"asks": [["83489.09", "0.178976"], ["83536.80", "5.569128"], ["83545.20", "5.112642"], ["83553.60", "4.017076"], ["83562.00", "4.473562"], ["83570.40", "5.021345"], ["83578.80", "4.838750"], ["83587.20", "4.382265"], ["83595.60", "5.295236"], ["83604.00", "4.656156"], ["83612.40", "5.477831"], ["83620.80", "5.660425"], ["83629.20", "5.386533"], ["83637.60", "4.564859"], ["83646.00", "5.203939"], ["83654.40", "4.199670"], ["83662.80", "3.925779"], ["83671.20", "4.108373"], ["83679.60", "4.290967"], ["83688.00", "4.930048"], ["83696.40", "4.747453"]], "bids": [["83423.50", "0.015863"], ["83421.50", "0.041744"], ["83419.50", "0.109852"], ["83417.50", "0.289084"], ["83415.50", "0.760748"], ["83413.50", "2.001969"], ["83411.50", "5.268338"], ["83393.00", "0.000122"], ["83369.80", "4.473562"], ["83361.40", "5.660425"], ["83353.00", "4.017076"], ["83344.60", "4.382265"], ["83336.20", "3.925779"], ["83327.80", "5.112642"], ["83319.40", "5.021345"], ["83311.00", "5.386533"], ["83302.60", "5.203939"], ["83294.20", "4.747453"], ["83285.80", "4.108373"], ["83277.40", "4.838750"], ["83269.00", "4.656156"], ["83260.60", "5.295236"], ["83252.20", "5.569128"], ["83243.80", "4.930048"], ["83235.40", "4.290967"], ["83227.00", "4.564859"], ["83218.60", "5.477831"]], "checksum": -1347583939, "ts": "1742377426851"}], "ts": 1742377426853, "record_time": 1742377427.74985}
{"action": "update", "arg": {"instType": "SPOT", "channel": "books", "instId": "BTCUSDT"}, "data": [{"asks": [["83493.09", "0.473670"], ["83536.79", "0.111449"], ["83536.80", "3.925779"], ["83545.20", "5.386533"], ["83553.60", "5.569128"], ["83562.00", "5.021345"], ["83570.40", "4.290967"], ["83578.80", "4.473562"], ["83587.20", "5.477831"], ["83595.60", "4.930048"], ["83604.00", "4.108373"], ["83612.40", "5.295236"], ["83620.80", "4.838750"], ["83629.20", "5.203939"], ["83646.00", "4.017076"], ["83654.40", "5.112642"], ["83662.80", "5.660425"], ["83671.20", "4.382265"], ["83679.60", "4.199670"], ["83688.00", "4.747453"], ["83696.40", "4.656156"], ["83772.50", "0"]], "bids": [["83441.28", "0.045561"], ["83441.22", "0"], ["83369.80", "4.564859"], ["83361.40", "4.473562"], ["83353.00", "4.656156"], ["83344.60", "5.660425"], ["83336.20", "4.108373"], ["83327.80", "5.295236"], ["83319.40", "5.203939"], ["83311.00", "5.021345"], ["83302.60", "4.382265"], ["83285.80", "5.112642"], ["83277.40", "4.930048"], ["83269.00", "4.199670"], ["83260.60", "5.569128"], ["83252.20", "5.386533"], ["83243.80", "3.925779"], ["83235.40", "4.838750"], ["83227.00", "4.290967"], ["83210.20", "4.017076"]], "checksum": 819904220, "ts": "1742377427067"}], "ts": 1742377427069, "record_time": 1742377427.980859}
{"action": "update", "arg": {"instType": "SPOT", "channel": "books", "instId": "BTCUSDT"}, "data": [{"asks": [["83445.01", "1.270069"], ["83471.67", "0"], ["83479.10", "0.001710"], ["83481.10", "0.004500"], ["83483.10", "0.011587"], ["83485.10", "0.030492"], ["83487.10", "0.080240"], ["83489.10", "0.211159"], ["83491.10", "0.555681"], ["83493.10", "1.462320"], ["83495.10", "3.848210"], ["83507.70", "0.035940"], ["83536.80", "5.477831"], ["83545.20", "5.569128"], ["83553.60", "4.382265"], ["83562.00", "4.656156"], ["83568.23", "0"], ["83576.59", "0"], ["83578.80", "5.660425"], ["83587.20", "4.838750"], ["83595.60", "5.386533"], ["83604.00", "4.747453"], ["83612.40", "4.564859"], ["83620.80", "3.925779"], ["83629.20", "4.199670"], ["83637.60", "4.930048"], ["83646.00", "5.295236"], ["83654.40", "5.203939"], ["83662.80", "4.017076"], ["83671.20", "4.108373"], ["83679.60", "5.112642"], ["83688.00", "5.021345"], ["83696.40", "4.473562"], ["83772.50", "0.000008"], ["83772.56", "0.000614"]], "bids": [["83423.50", "0.016085"], ["83421.50", "0.042329"], ["83419.50", "0.111392"], ["83417.50", "0.293136"], ["83415.50", "0.771411"], ["83413.50", "2.030029"], ["83411.50", "5.342180"], ["83382.25", "0"], ["83376.66", "0"], ["83373.23", "0"], ["83361.40", "4.017076"], ["83344.60", "5.569128"], ["83336.20", "5.477831"], ["83327.80", "4.290967"], ["83319.40", "3.925779"], ["83311.00", "5.112642"], ["83302.60", "5.660425"], ["83294.20", "4.382265"], ["83285.80", "4.473562"], ["83277.40", "4.747453"], ["83269.00", "5.386533"], ["83260.60", "4.930048"], ["83252.20", "5.203939"], ["83243.80", "4.199670"], ["83235.40", "4.108373"], ["83227.00", "4.838750"], ["83218.60", "5.021345"], ["83210.20", "5.295236"], ["82940.00", "0.002472"], ["82938.97", "0.000099"], ["82938.60", "0.000022"]], "checksum": 154126435, "ts": "1742377427280"}], "ts": 1742377427285, "record_time": 1742377428.187323}
{"action": "update", "arg": {"instType": "SPOT", "channel": "books", "instId": "BTCUSDT"}, "data": [{"asks": [["83466.96", "0.718847"], ["83468.95", "0"], ["83471.66", "0.175120"], ["83503.42", "1.796333"], ["83505.42", "0"], ["83536.80", "4.290967"], ["83545.20", "4.747453"], ["83553.60", "4.838750"], ["83562.00", "5.386533"], ["83567.43", "0.001810"], ["83570.40", "4.017076"], ["83575.78", "0.003620"], ["83578.80", "4.656156"], ["83587.20", "5.477831"], ["83595.60", "5.569128"], ["83604.00", "4.930048"], ["83612.40", "5.112642"], ["83629.20", "4.382265"], ["83637.60", "5.660425"], ["83662.80", "4.199670"], ["83679.60", "4.473562"], ["83696.40", "4.564859"], ["83772.00", "0"], ["83772.50", "0"], ["83772.56", "0"]], "bids": [["83441.28", "0"], ["83423.50", "0.016149"], ["83421.50", "0.042499"], ["83419.50", "0.111838"], ["83418.84", "0.007191"], ["83417.50", "0.294311"], ["83415.50", "0.774502"], ["83413.50", "2.038164"], ["83411.50", "5.363589"], ["83402.21", "0"], ["83400.21", "0.719422"], ["83394.00", "0.000161"], ["83393.00", "0"], ["83376.74", "0.001810"], ["83373.45", "0.012498"], ["83369.80", "4.747453"], ["83366.83", "0.003620"], ["83361.40", "5.569128"], ["83353.00", "3.925779"], ["83344.60", "4.199670"], ["83336.20", "5.386533"], ["83327.80", "5.112642"], ["83319.40", "4.564859"], ["83311.00", "4.290967"], ["83302.60", "4.838750"], ["83294.20", "5.203939"], ["83285.80", "5.477831"], ["83277.40", "4.017076"], ["83272.00", "0"], ["83269.00", "4.656156"], ["83260.60", "5.660425"], ["83252.20", "4.930048"], ["83243.80", "4.473562"], ["83235.40", "5.295236"], ["83227.00", "5.021345"], ["83218.60", "4.382265"], ["83210.20", "4.108373"], ["82938.97", "0"], ["82938.60", "0"]], "checksum": 1579999882, "ts": "1742377427482"}], "ts": 1742377427485, "record_time": 1742377428.376829}
{"action": "update", "arg": {"instType": "SPOT", "channel": "books", "instId": "BTCUSDT"}, "data": [{"asks": [["83468.90", "0"], ["83479.10", "0.001313"], ["83481.10", "0.003455"], ["83483.10", "0.009092"], ["83485.10", "0.023926"], ["83487.10", "0.062962"], ["83489.10", "0.165691"], ["83491.10", "0.436027"], ["83493.10", "1.147313"], ["83495.10", "3.019245"], ["83536.80", "3.925779"], ["83545.20", "5.477831"], ["83553.60", "4.656156"], ["83561.99", "0.420240"], ["83562.00", "5.021345"], ["83570.40", "5.660425"], ["83578.80", "4.199670"], ["83587.20", "5.386533"], ["83595.60", "4.382265"], ["83604.00", "5.569128"], ["83612.40", "5.203939"], ["83620.80", "4.473562"], ["83629.20", "4.017076"], ["83637.60", "4.564859"], ["83646.00", "5.112642"], ["83654.40", "4.290967"], ["83662.80", "4.108373"], ["83671.20", "4.838750"], ["83679.60", "4.747453"], ["83688.00", "4.930048"], ["83696.40", "5.295236"]], "bids": [["83441.48", "0.045561"], ["83427.50", "0.002303"], ["83425.50", "0.006060"], ["83423.50", "0.015948"], ["83421.50", "0.041968"], ["83419.50", "0.110442"], ["83417.50", "0.290637"], ["83415.50", "0.764833"], ["83413.50", "2.012719"], ["83411.50", "5.296629"], ["83369.80", "4.290967"], ["83361.40", "4.564859"], ["83353.00", "4.930048"], ["83344.60", "5.386533"], ["83336.20", "4.382265"], ["83327.80", "5.295236"], ["83319.40", "3.925779"], ["83311.00", "5.203939"], ["83302.60", "5.021345"], ["83294.20", "4.838750"], ["83285.80", "5.660425"], ["83277.40", "4.747453"], ["83269.00", "4.017076"], ["83260.60", "5.112642"], ["83252.20", "4.108373"], ["83235.40", "5.569128"], ["83227.00", "4.656156"], ["83218.60", "4.199670"], ["83210.20", "5.477831"], ["82940.00", "0"]], "checksum": -225531156, "ts": "1742377427690"}], "ts": 1742377427692, "record_time": 1742377428.582964}
{"action": "update", "arg": {"instType": "SPOT", "channel": "books", "instId": "BTCUSDT"}, "data": [{"asks": [["83466.95", "0.422051"], ["83501.90", "0.462750"], ["83507.70", "0"], ["83545.20", "4.473562"], ["83553.60", "4.747453"], ["83561.99", "0"], ["83562.00", "4.930048"], ["83570.40", "4.382265"], ["83578.80", "5.295236"], ["83587.20", "5.112642"], ["83595.60", "5.569128"], ["83604.00", "4.564859"], ["83612.40", "5.477831"], ["83620.80", "5.203939"], ["83629.20", "4.656156"], ["83637.60", "5.660425"], ["83646.00", "4.290967"], ["83654.40", "4.838750"], ["83662.80", "5.386533"], ["83671.20", "5.021345"], ["83679.60", "4.199670"], ["83688.00", "4.108373"], ["83696.40", "4.017076"], ["83772.00", "0.000096"]], "bids": [["83423.50", "0.015790"], ["83421.50", "0.041552"], ["83419.50", "0.109347"], ["83417.50", "0.287756"], ["83415.50", "0.757251"], ["83413.50", "1.992766"], ["83411.50", "5.244121"], ["83369.80", "5.021345"], ["83361.40", "5.477831"], ["83353.00", "5.660425"], ["83344.60", "4.656156"], ["83336.20", "4.473562"], ["83327.80", "5.386533"], ["83319.40", "4.199670"], ["83311.00", "4.930048"], ["83302.60", "5.203939"], ["83294.20", "4.290967"], ["83285.80", "4.747453"], ["83277.40", "5.295236"], ["83269.00", "5.112642"], ["83260.60", "4.017076"], ["83243.80", "4.564859"], ["83227.00", "4.838750"], ["83218.60", "4.382265"], ["83210.20", "3.925779"]], "checksum": -225531156, "ts": "1742377427902"}], "ts": 1742377427904, "record_time": 1742377428.794706}
{"action": "update", "arg": {"instType": "SPOT", "channel": "books", "instId": "BTCUSDT"}, "data": [{"asks": [["83493.09", "0.589992"], ["83536.79", "0"], ["83536.80", "4.199670"], ["83545.20", "5.386533"], ["83553.60", "5.660425"], ["83562.00", "4.564859"], ["83570.40", "4.930048"], ["83578.80", "4.656156"], ["83587.20", "5.295236"], ["83595.60", "4.017076"], ["83604.00", "5.112642"], ["83612.40", "4.290967"], ["83620.80", "4.473562"], ["83629.20", "4.382265"], ["83637.60", "5.021345"], ["83646.00", "4.747453"], ["83654.40", "4.108373"], ["83662.80", "5.477831"], ["83671.20", "5.569128"], ["83679.60", "4.838750"], ["83688.00", "5.203939"], ["83696.40", "3.925779"], ["83772.50", "0.000008"]], "bids": [["83441.61", "0.045561"], ["83441.48", "0"], ["83423.50", "0.015791"], ["83421.50", "0.041554"], ["83419.50", "0.109354"], ["83417.50", "0.287773"], ["83415.50", "0.757297"], ["83413.50", "1.992886"], ["83411.50", "5.244437"], ["83395.00", "0.000122"], ["83394.00", "0.000283"], ["83369.80", "5.295236"], ["83361.40", "4.747453"], ["83353.00", "3.925779"], ["83344.60", "4.290967"], ["83336.20", "5.660425"], ["83327.80", "5.477831"], ["83319.40", "4.108373"], ["83302.60", "4.017076"], ["83294.20", "4.473562"], ["83285.80", "5.203939"], ["83277.40", "4.838750"], ["83269.00", "5.386533"], ["83260.60", "4.656156"], ["83252.20", "4.199670"], ["83243.80", "5.021345"], ["83235.40", "4.382265"], ["83227.00", "5.569128"], ["83218.60", "4.564859"], ["83210.20", "5.112642"]], "checksum": -330480761, "ts": "1742377428118"}], "ts": 1742377428121, "record_time": 1742377429.011715}
{"action": "update", "arg": {"instType": "SPOT", "channel": "books", "instId": "BTCUSDT"}, "data": [{"asks": [["83536.80", "5.203939"], ["83545.20", "4.108373"], ["83553.60", "4.838750"], ["83562.00", "5.386533"], ["83570.40", "4.747453"], ["83578.80", "4.930048"], ["83587.20", "5.660425"], ["83595.60", "4.564859"], ["83604.00", "4.473562"], ["83612.40", "4.382265"], ["83620.80", "4.290967"], ["83629.20", "5.295236"], ["83637.60", "3.925779"], ["83646.00", "5.112642"], ["83654.40", "5.477831"], ["83662.80", "5.569128"], ["83671.20", "4.656156"], ["83679.60", "4.199670"], ["83688.00", "4.017076"], ["83696.40", "5.021345"]], "bids": [["83445.00", "1.029562"], ["83407.30", "0.015000"], ["83402.20", "0"], ["83369.80", "4.108373"], ["83361.40", "4.017076"], ["83353.00", "5.021345"], ["83344.60", "4.747453"], ["83336.20", "5.295236"], ["83327.80", "4.656156"], ["83319.40", "5.112642"], ["83311.00", "4.564859"], ["83302.60", "4.838750"], ["83294.20", "5.477831"], ["83285.80", "5.386533"], ["83277.40", "5.660425"], ["83269.00", "4.473562"], ["83260.60", "5.569128"], ["83252.20", "4.290967"], ["83243.80", "4.199670"], ["83235.40", "3.925779"], ["83227.00", "4.382265"], ["83218.60", "5.203939"], ["83210.20", "4.930048"]], "checksum": -873497575, "ts": "1742377428318"}], "ts": 1742377428323, "record_time": 1742377429.216062}
{"action": "update", "arg": {"instType": "SPOT", "channel": "books", "instId": "BTCUSDT"}, "data": [{"asks": [["83445.01", "1.268489"], ["83479.10", "0.001145"], ["83481.10", "0.003011"], ["83483.10", "0.007925"], ["83485.10", "0.020856"], ["83487.10", "0.054883"], ["83489.10", "0.144430"], ["83491.10", "0.380079"], ["83493.10", "1.000207"], ["83495.10", "2.632123"], ["83536.80", "3.925779"], ["83545.20", "5.569128"], ["83553.60", "5.477831"], ["83562.00", "5.295236"], ["83570.40", "4.838750"], ["83578.80", "5.386533"], ["83587.20", "5.203939"], ["83595.60", "5.021345"], ["83604.00", "4.564859"], ["83612.40", "4.747453"], ["83620.80", "4.382265"], ["83629.20", "4.108373"], ["83637.60", "5.660425"], ["83654.40", "4.017076"], ["83662.80", "4.199670"], ["83671.20", "4.290967"], ["83679.60", "4.930048"], ["83688.00", "4.656156"], ["83696.40", "4.473562"]], "bids": [["83441.61", "0"], ["83427.50", "0.001886"], ["83425.50", "0.004964"], ["83423.50", "0.013062"], ["83421.50", "0.034373"], ["83419.50", "0.090457"], ["83417.50", "0.238043"], ["83415.50", "0.626429"], ["83413.50", "1.648498"], ["83411.50", "4.338152"], ["83407.30", "0"], ["83402.20", "0.007050"], ["83369.80", "4.838750"], ["83361.40", "5.660425"], ["83353.00", "4.473562"], ["83344.60", "4.656156"], ["83336.20", "4.290967"], ["83327.80", "4.382265"], ["83319.40", "4.199670"], ["83311.00", "5.386533"], ["83302.60", "3.925779"], ["83294.20", "5.295236"], ["83285.80", "5.203939"], ["83277.40", "5.021345"], ["83269.00", "5.569128"], ["83260.60", "4.747453"], ["83252.20", "4.108373"], ["83243.80", "5.477831"], ["83235.40", "5.112642"], ["83227.00", "4.017076"], ["83218.60", "4.564859"], ["82940.00", "0.002472"]], "checksum": 949880542, "ts": "1742377428520"}], "ts": 1742377428524, "record_time": 1742377429.415998}
{"action": "update", "arg": {"instType": "SPOT", "channel": "books", "instId": "BTCUSDT"}, "data": [{"asks": [["83479.10", "0.001603"], ["83481.10", "0.004218"], ["83483.10", "0.011100"], ["83485.09", "0"], ["83485.10", "0.029209"], ["83487.10", "0.076868"], ["83489.10", "0.202282"], ["83491.10", "0.532323"], ["83493.10", "1.400849"], ["83495.10", "3.686446"], ["83536.80", "5.203939"], ["83545.20", "4.564859"], ["83553.60", "4.656156"], ["83562.00", "5.021345"], ["83570.40", "5.386533"], ["83578.80", "4.747453"], ["83587.19", "0.108836"], ["83587.20", "4.382265"], ["83595.60", "5.569128"], ["83604.00", "4.838750"], ["83612.40", "4.290967"], ["83620.80", "5.477831"], ["83629.20", "4.930048"], ["83637.60", "4.108373"], ["83646.00", "5.295236"], ["83654.40", "4.199670"], ["83662.80", "5.660425"], ["83671.20", "4.017076"], ["83679.60", "4.473562"], ["83688.00", "3.925779"], ["83696.40", "5.112642"]], "bids": [["83441.74", "0.045561"], ["83421.50", "0.034495"], ["83419.50", "0.090777"], ["83417.50", "0.238886"], ["83415.50", "0.628648"], ["83413.50", "1.654336"], ["83411.50", "4.353516"], ["83395.00", "0"], ["83393.00", "0.000161"], ["83369.80", "4.656156"], ["83361.40", "4.564859"], ["83353.00", "4.930048"], ["83344.60", "3.925779"], ["83336.20", "5.295236"], ["83327.80", "4.838750"], ["83319.40", "5.477831"], ["83311.00", "5.660425"], ["83302.60", "4.382265"], ["83294.20", "5.203939"], ["83285.80", "4.747453"], ["83277.40", "5.112642"], ["83269.00", "4.473562"], ["83260.60", "4.290967"], ["83252.20", "5.021345"], ["83243.80", "5.569128"], ["83235.40", "4.199670"], ["83218.60", "5.386533"], ["83210.20", "4.108373"], ["82940.00", "0"]], "checksum": -301356959, "ts": "1742377428742"}], "ts": 1742377428768, "record_time": 1742377429.658975}
{"action": "update", "arg": {"instType": "SPOT", "channel": "books", "instId": "BTCUSDT"}, "data": [{"asks": [["83479.10", "0.001136"], ["83481.10", "0.002990"], ["83483.10", "0.007868"], ["83485.10", "0.020707"], ["83487.00", "0.085820"], ["83487.10", "0.054329"], ["83489.10", "0.142973"], ["83491.10", "0.376243"], ["83493.10", "0.990114"], ["83495.10", "2.605562"], ["83495.60", "0.303630"], ["83497.60", "0"], ["83498.10", "0.015060"], ["83499.80", "0"], ["83500.70", "0.915510"], ["83501.90", "0.360000"], ["83504.50", "1.196070"], ["83507.70", "0.035940"], ["83507.80", "0.777600"], ["83536.80", "4.564859"], ["83545.20", "4.838750"], ["83553.60", "4.747453"], ["83570.40", "4.656156"], ["83578.80", "4.199670"], ["83587.20", "3.925779"], ["83595.60", "4.290967"], ["83604.00", "4.108373"], ["83612.40", "5.203939"], ["83620.80", "4.382265"], ["83629.20", "5.569128"], ["83637.60", "5.112642"], ["83646.00", "5.386533"], ["83654.40", "4.017076"], ["83671.20", "4.930048"], ["83688.00", "5.477831"], ["83696.40", "5.295236"], ["83771.43", "0"], ["83772.00", "0"], ["83772.50", "0"]], "bids": [["83429.50", "0.001273"], ["83427.50", "0.003351"], ["83425.50", "0.008818"], ["83423.50", "0.023010"], ["83421.50", "0.060554"], ["83419.50", "0.159351"], ["83417.50", "0.419346"], ["83415.50", "1.103542"], ["83414.87", "0.020924"], ["83413.50", "2.904058"], ["83411.50", "7.642256"], ["83406.30", "1.833030"], ["83402.20", "0"], ["83401.94", "0"], ["83369.80", "5.112642"], ["83361.40", "4.382265"], ["83344.60", "4.564859"], ["83336.20", "4.473562"], ["83327.80", "5.477831"], ["83319.40", "5.569128"], ["83311.00", "4.017076"], ["83302.60", "4.199670"], ["83294.20", "5.660425"], ["83285.80", "5.386533"], ["83277.40", "3.925779"], ["83269.00", "4.838750"], ["83260.60", "5.203939"], ["83252.20", "4.108373"], ["83243.80", "4.747453"], ["83235.40", "4.290967"], ["83227.00", "5.295236"], ["83218.60", "4.656156"], ["83210.20", "5.021345"], ["82940.00", "0.002472"]], "checksum": -301356959, "ts": "1742377428946"}], "ts": 1742377428950, "record_time": 1742377429.840755}
{"action": "update", "arg": {"instType": "SPOT", "channel": "books", "instId": "BTCUSDT"}, "data": [{"asks": [["83445.01", "1.266909"], ["83483.10", "0.007673"], ["83485.10", "0.020192"], ["83487.10", "0.053136"], ["83489.10", "0.139833"], ["83491.10", "0.367982"], ["83493.10", "0.968372"], ["83495.10", "2.548349"], ["83495.60", "0.222810"], ["83495.70", "0"], ["83498.10", "0"], ["83503.50", "0.946440"], ["83504.50", "0.553650"], ["83504.90", "0.012660"], ["83507.70", "0"], ["83507.80", "0"], ["83536.79", "0.023016"], ["83536.80", "4.930048"], ["83545.20", "5.477831"], ["83553.60", "4.199670"], ["83562.00", "4.838750"], ["83570.40", "5.112642"], ["83578.80", "4.017076"], ["83587.20", "4.473562"], ["83595.60", "5.386533"], ["83604.00", "3.925779"], ["83620.80", "4.747453"], ["83629.20", "4.382265"], ["83637.60", "5.569128"], ["83646.00", "4.656156"], ["83654.40", "5.021345"], ["83662.80", "4.564859"], ["83671.20", "5.295236"], ["83679.60", "4.108373"], ["83688.00", "5.660425"], ["83696.40", "4.290967"], ["83771.43", "0.000084"]], "bids": [["83441.74", "0"], ["83429.50", "0.001263"], ["83427.50", "0.003323"], ["83425.50", "0.008746"], ["83423.50", "0.023015"], ["83421.50", "0.060567"], ["83419.50", "0.159387"], ["83417.50", "0.419439"], ["83415.50", "1.103786"], ["83413.50", "2.904701"], ["83411.50", "7.643949"], ["83369.80", "5.021345"], ["83361.40", "4.747453"], ["83353.00", "5.112642"], ["83344.60", "4.382265"], ["83327.80", "4.656156"], ["83319.40", "4.017076"], ["83311.00", "5.295236"], ["83302.60", "4.930048"], ["83294.20", "5.477831"], ["83277.40", "4.108373"], ["83269.00", "4.199670"], ["83252.20", "4.838750"], ["83243.80", "4.290967"], ["83235.40", "5.660425"], ["83227.00", "5.569128"], ["83218.60", "4.564859"], ["83210.20", "3.925779"], ["82938.97", "0.000099"]], "checksum": 562608043, "ts": "1742377429150"}], "ts": 1742377429154, "record_time": 1742377430.04484}
{"action": "update", "arg": {"instType": "SPOT", "channel": "books", "instId": "BTCUSDT"}, "data": [{"asks": [["83498.30", "0.333330"], ["83498.61", "0.001598"], ["83498.71", "0"], ["83504.50", "1.195380"], ["83504.80", "0"], ["83506.90", "0"], ["83536.80", "4.017076"], ["83545.20", "4.290967"], ["83553.60", "4.930048"], ["83562.00", "4.382265"], ["83570.40", "4.838750"], ["83578.80", "4.564859"], ["83587.20", "3.925779"], ["83595.60", "5.477831"], ["83604.00", "4.656156"], ["83612.40", "4.473562"], ["83620.80", "5.203939"], ["83629.20", "5.569128"], ["83637.60", "4.747453"], ["83646.00", "5.021345"], ["83654.40", "5.660425"], ["83662.80", "5.112642"], ["83671.20", "4.199670"], ["83688.00", "5.295236"], ["83696.40", "5.386533"], ["83772.00", "0.000096"], ["83772.50", "0.000008"]], "bids": [["83441.86", "0.045561"], ["83423.50", "0.023217"], ["83421.50", "0.061097"], ["83419.50", "0.160783"], ["83417.50", "0.423113"], ["83415.50", "1.113456"], ["83413.50", "2.930145"], ["83411.50", "7.710909"], ["83407.30", "0.015000"], ["83405.61", "0.023958"], ["83405.29", "0"], ["83403.12", "0.024164"], ["83402.85", "0"], ["83402.50", "0"], ["83394.00", "0.000122"], ["83389.23", "0"], ["83389.13", "0.001186"], ["83369.80", "5.660425"], ["83361.40", "5.112642"], ["83353.00", "5.386533"], ["83344.60", "4.108373"], ["83336.20", "4.199670"], ["83327.80", "4.747453"], ["83302.60", "4.838750"], ["83294.20", "5.203939"], ["83285.80", "4.930048"], ["83277.40", "5.477831"], ["83269.00", "4.656156"], ["83260.60", "4.290967"], ["83252.20", "4.564859"], ["83243.80", "5.569128"], ["83235.40", "3.925779"], ["83227.00", "5.021345"], ["83218.60", "4.382265"], ["83210.20", "4.473562"], ["82938.97", "0"]], "checksum": 1738624537, "ts": "1742377429354"}], "ts": 1742377429357, "record_time": 1742377430.247799}
{"action": "update", "arg": {"instType": "SPOT", "channel": "books", "instId": "BTCUSDT"}, "data": [{"asks": [["83479.10", "0.001010"], ["83481.10", "0.001387"], ["83483.10", "0.003651"], ["83485.10", "0.009608"], ["83487.10", "0.025282"], ["83489.10", "0.066532"], ["83491.10", "0.175084"], ["83493.10", "0.460749"], ["83495.10", "1.212497"], ["83495.60", "0.350340"], ["83496.80", "0.517230"], ["83500.30", "1.729380"], ["83502.20", "1.077300"], ["83506.10", "0"], ["83506.30", "0"], ["83536.80", "4.930048"], ["83545.20", "4.838750"], ["83553.60", "4.473562"], ["83570.40", "4.564859"], ["83578.80", "4.747453"], ["83587.20", "4.017076"], ["83595.60", "5.386533"], ["83604.00", "5.203939"], ["83612.40", "5.112642"], ["83620.80", "5.569128"], ["83629.20", "4.290967"], ["83637.60", "5.295236"], ["83646.00", "5.477831"], ["83654.40", "5.021345"], ["83662.80", "4.199670"], ["83671.20", "4.656156"], ["83679.60", "5.660425"], ["83688.00", "3.925779"], ["83696.40", "4.108373"]], "bids": [["83423.50", "0.022910"], ["83421.50", "0.060288"], ["83419.50", "0.158653"], ["83417.50", "0.417508"], ["83415.50", "1.098704"], ["83413.50", "2.891328"], ["83411.50", "7.608758"], ["83402.03", "0"], ["83393.00", "0.000283"], ["83369.80", "4.382265"], ["83361.40", "5.295236"], ["83353.00", "4.747453"], ["83344.60", "4.930048"], ["83336.20", "5.569128"], ["83327.80", "4.199670"], ["83319.40", "3.925779"], ["83311.00", "5.112642"], ["83302.60", "4.290967"], ["83294.20", "5.386533"], ["83285.80", "4.656156"], ["83277.40", "4.017076"], ["83269.00", "4.838750"], ["83260.60", "5.203939"], ["83243.80", "4.473562"], ["83235.40", "5.660425"], ["83218.60", "4.108373"], ["83210.20", "5.477831"], ["82938.97", "0.000099"]], "checksum": 1738624537, "ts": "1742377429559"}], "ts": 1742377429563, "record_time": 1742377430.453531}
{"action": "update", "arg": {"instType": "SPOT", "channel": "books", "instId": "BTCUSDT"}, "data": [{"asks": [["83445.01", "1.267009"], ["83479.09", "0"], ["83489.09", "0.057794"], ["83498.30", "0.318510"], ["83536.80", "3.925779"], ["83553.60", "5.569128"], ["83561.99", "0.122659"], ["83570.40", "4.108373"], ["83578.80", "4.199670"], ["83587.20", "5.386533"], ["83595.60", "5.477831"], ["83604.00", "4.564859"], ["83612.40", "4.473562"], ["83620.80", "4.290967"], ["83629.20", "5.203939"], ["83637.60", "4.017076"], ["83646.00", "4.930048"], ["83654.40", "5.112642"], ["83662.80", "4.747453"], ["83688.00", "5.021345"], ["83696.40", "5.295236"]], "bids": [["83441.98", "0.045561"], ["83441.86", "0"], ["83423.50", "0.022913"], ["83421.50", "0.060297"], ["83419.50", "0.158820"], ["83417.50", "0.417949"], ["83415.50", "1.099865"], ["83414.72", "0.018506"], ["83413.50", "2.894381"], ["83411.50", "7.616793"], ["83403.20", "0"], ["83403.10", "0"], ["83402.60", "0"], ["83369.80", "5.386533"], ["83361.40", "4.473562"], ["83353.00", "4.017076"], ["83344.60", "5.295236"], ["83327.80", "5.203939"], ["83319.40", "4.199670"], ["83311.00", "4.564859"], ["83302.60", "4.747453"], ["83294.20", "4.290967"], ["83285.80", "4.838750"], ["83277.40", "5.477831"], ["83269.00", "3.925779"], ["83260.60", "4.930048"], ["83252.20", "4.382265"], ["83243.80", "4.656156"], ["83235.40", "4.108373"], ["83218.60", "5.112642"], ["83210.20", "5.660425"], ["82938.60", "0.000022"], ["82938.45", "0.000022"]], "checksum": -858196313, "ts": "1742377429778"}], "ts": 1742377429780, "record_time": 1742377430.677767}
{"action": "update", "arg": {"instType": "SPOT", "channel": "books", "instId": "BTCUSDT"}, "data": [{"asks": [["83472.87", "0"], ["83473.26", "0.119900"], ["83477.05", "0"], ["83477.43", "0.015895"], ["83477.87", "0"], ["83478.26", "0.010984"], ["83493.10", "0.460607"], ["83495.10", "1.212125"], ["83495.59", "0.152359"], ["83497.90", "0.014820"], ["83500.55", "0"], ["83500.56", "0.001598"], ["83536.80", "5.112642"], ["83545.20", "4.108373"], ["83553.60", "4.838750"], ["83561.99", "0"], ["83562.00", "4.747453"], ["83570.40", "5.203939"], ["83578.80", "4.290967"], ["83587.19", "0"], ["83587.20", "4.656156"], ["83595.60", "5.295236"], ["83612.40", "5.021345"], ["83620.80", "3.925779"], ["83629.20", "4.473562"], ["83637.60", "4.930048"], ["83646.00", "5.386533"], ["83654.40", "4.017076"], ["83662.80", "4.199670"], ["83671.20", "4.382265"], ["83688.00", "5.569128"], ["83696.40", "5.477831"]], "bids": [["83436.64", "0.001387"], ["83436.62", "0"], ["83415.50", "1.100053"], ["83413.50", "2.894876"], ["83413.18", "0.262709"], ["83412.79", "0"], ["83411.50", "7.618095"], ["83409.01", "0.073759"], ["83408.63", "0"], ["83408.17", "0.056755"], ["83407.78", "0"], ["83395.00", "0.000161"], ["83387.24", "0.001183"], ["83387.23", "0"], ["83361.40", "4.017076"], ["83353.00", "4.656156"], ["83344.60", "5.477831"], ["83336.20", "4.838750"], ["83327.80", "5.569128"], ["83319.40", "5.021345"], ["83311.00", "4.290967"], ["83302.60", "4.108373"], ["83294.20", "3.925779"], ["83285.80", "4.382265"], ["83277.40", "4.473562"], ["83269.00", "5.112642"], ["83260.60", "4.747453"], ["83252.20", "5.295236"], ["83243.80", "5.660425"], ["83235.40", "4.199670"], ["83227.00", "4.564859"], ["83218.60", "5.203939"], ["83210.20", "4.930048"], ["82938.45", "0"]], "checksum": -1247843328, "ts": "1742377429988"}], "ts": 1742377429992, "record_time": 1742377430.883318}
{"action": "update", "arg": {"instType": "SPOT", "channel": "books", "instId": "BTCUSDT"}, "data": [{"asks": [["83536.80", "4.838750"], ["83545.20", "4.656156"], ["83553.60", "5.477831"], ["83562.00", "4.382265"], ["83570.40", "4.564859"], ["83578.80", "5.386533"], ["83587.20", "5.295236"], ["83595.60", "4.930048"], ["83604.00", "4.747453"], ["83612.40", "3.925779"], ["83620.80", "5.021345"], ["83629.20", "5.660425"], ["83637.60", "5.203939"], ["83646.00", "4.290967"], ["83654.40", "4.108373"], ["83671.20", "4.473562"], ["83679.60", "4.017076"], ["83696.40", "5.112642"]], "bids": [["83442.08", "0.045561"], ["83441.98", "0"], ["83423.50", "0.022975"], ["83421.50", "0.060460"], ["83419.50", "0.159106"], ["83417.50", "0.418700"], ["83415.50", "1.101842"], ["83413.50", "2.899583"], ["83411.50", "7.630483"], ["83407.30", "0"], ["83369.80", "4.656156"], ["83361.40", "3.925779"], ["83353.00", "4.930048"], ["83344.60", "5.660425"], ["83336.20", "4.199670"], ["83327.80", "5.021345"], ["83319.40", "5.477831"], ["83311.00", "4.108373"], ["83302.60", "5.386533"], ["83294.20", "5.112642"], ["83285.80", "5.203939"], ["83277.40", "4.838750"], ["83269.00", "4.382265"], ["83260.60", "4.017076"], ["83252.20", "4.564859"], ["83243.80", "5.569128"], ["83235.40", "4.290967"], ["83227.00", "4.473562"], ["83218.60", "5.295236"], ["83210.20", "4.747453"], ["82938.45", "0.000022"]], "checksum": 681510885, "ts": "1742377430188"}], "ts": 1742377430192, "record_time": 1742377431.081667}
{"action": "update", "arg": {"instType": "SPOT", "channel": "books", "instId": "BTCUSDT"}, "data": [{"asks": [["83497.90", "0"], ["83498.30", "0.333330"], ["83504.50", "0.553650"], ["83536.80", "4.382265"], ["83545.20", "4.930048"], ["83553.60", "4.199670"], ["83562.00", "4.017076"], ["83570.40", "5.112642"], ["83578.80", "5.569128"], ["83587.20", "4.747453"], ["83595.60", "5.386533"], ["83604.00", "4.290967"], ["83612.40", "5.477831"], ["83620.80", "4.108373"], ["83629.20", "4.564859"], ["83637.60", "4.473562"], ["83646.00", "4.838750"], ["83654.40", "5.660425"], ["83662.80", "3.925779"], ["83671.20", "5.021345"], ["83679.60", "4.656156"], ["83688.00", "5.295236"], ["83696.40", "5.203939"], ["83772.56", "0.000614"]], "bids": [["83409.10", "0.022590"], ["83408.70", "0.166290"], ["83407.40", "0"], ["83406.90", "0"], ["83394.00", "0"], ["83369.80", "4.290967"], ["83361.40", "4.473562"], ["83353.00", "5.112642"], ["83336.20", "4.747453"], ["83327.80", "5.295236"], ["83319.40", "4.656156"], ["83311.99", "0.132260"], ["83311.00", "4.930048"], ["83310.50", "0"], ["83302.60", "4.382265"], ["83294.20", "4.838750"], ["83285.80", "4.199670"], ["83277.40", "4.108373"], ["83269.00", "4.017076"], ["83260.60", "5.477831"], ["83243.80", "5.386533"], ["83235.40", "5.569128"], ["83227.00", "5.203939"], ["83218.60", "3.925779"], ["83210.20", "5.021345"], ["82937.59", "0.000423"], ["82937.50", "0.000012"]], "checksum": 681510885, "ts": "1742377430403"}], "ts": 1742377430407, "record_time": 1742377431.2976}
{"action": "update", "arg": {"instType": "SPOT", "channel": "books", "instId": "BTCUSDT"}, "data": [{"asks": [["83461.00", "0.000495"], ["83498.30", "0.318510"], ["83536.80", "4.108373"], ["83545.20", "4.656156"], ["83553.60", "5.112642"], ["83562.00", "4.930048"], ["83570.40", "5.203939"], ["83578.80", "4.290967"], ["83595.60", "4.199670"], ["83604.00", "5.569128"], ["83612.40", "4.017076"], ["83620.80", "5.295236"], ["83629.20", "3.925779"], ["83637.60", "5.660425"], ["83646.00", "5.021345"], ["83654.40", "4.564859"], ["83662.80", "4.473562"], ["83671.20", "4.382265"], ["83679.60", "5.386533"], ["83688.00", "4.838750"], ["83696.40", "5.477831"], ["83772.56", "0"]], "bids": [["83429.50", "0.001399"], ["83427.50", "0.003681"], ["83425.50", "0.009688"], ["83423.50", "0.025494"], ["83421.50", "0.067089"], ["83419.50", "0.176551"], ["83417.50", "0.464606"], ["83415.50", "1.222648"], ["83413.50", "3.217495"], ["83411.50", "8.467092"], ["83393.00", "0.000122"], ["83369.80", "5.112642"], ["83353.00", "4.930048"], ["83336.20", "5.021345"], ["83327.80", "4.199670"], ["83319.40", "5.569128"], ["83311.00", "3.925779"], ["83302.60", "5.203939"], ["83294.20", "5.477831"], ["83285.80", "4.564859"], ["83277.40", "4.290967"], ["83269.00", "4.747453"], ["83260.60", "4.838750"], ["83252.20", "4.017076"], ["83235.40", "5.295236"], ["83227.00", "4.108373"], ["83218.60", "4.656156"], ["83210.20", "4.382265"]], "checksum": 1201590667, "ts": "1742377430605"}], "ts": 1742377430610, "record_time": 1742377431.510838}
{"action": "update", "arg": {"instType": "SPOT", "channel": "books", "instId": "BTCUSDT"}, "data": [{"asks": [["83498.30", "0.333330"], ["83536.80", "5.660425"], ["83553.60", "5.203939"], ["83562.00", "5.112642"], ["83570.40", "4.290967"], ["83578.80", "4.747453"], ["83587.20", "5.477831"], ["83595.60", "5.386533"], ["83604.00", "4.382265"], ["83612.40", "5.569128"], ["83620.80", "4.838750"], ["83629.20", "5.295236"], ["83637.60", "4.108373"], ["83671.20", "4.930048"], ["83679.60", "3.925779"], ["83688.00", "4.199670"], ["83696.40", "4.017076"]], "bids": [["83442.19", "0.045561"], ["83442.08", "0"], ["83429.50", "0.001388"], ["83427.50", "0.003652"], ["83425.50", "0.009610"], ["83423.50", "0.025290"], ["83421.50", "0.066552"], ["83419.50", "0.175136"], ["83417.50", "0.460885"], ["83415.50", "1.212856"], ["83413.50", "3.191725"], ["83411.50", "8.399276"], ["83361.40", "4.290967"], ["83353.00", "3.925779"], ["83344.60", "4.473562"], ["83336.20", "4.564859"], ["83327.80", "4.382265"], ["83319.40", "4.838750"], ["83311.00", "4.017076"], ["83302.60", "5.477831"], ["83294.20", "4.747453"], ["83285.80", "4.108373"], ["83277.40", "4.199670"], ["83269.00", "5.295236"], ["83260.60", "4.930048"], ["83252.20", "5.386533"], ["83243.80", "5.569128"], ["83235.40", "5.660425"], ["83227.00", "4.656156"], ["83218.60", "5.021345"], ["83210.20", "5.203939"]], "checksum": -86031088, "ts": "1742377430813"}], "ts": 1742377430817, "record_time": 1742377431.706905}
{"action": "update", "arg": {"instType": "SPOT", "channel": "books", "instId": "BTCUSDT"}, "data": [{"asks": [["83497.50", "0.015060"], ["83498.30", "0.318510"], ["83536.80", "5.477831"], ["83545.20", "4.564859"], ["83553.60", "5.569128"], ["83562.00", "4.290967"], ["83570.40", "4.747453"], ["83578.80", "5.021345"], ["83587.20", "4.108373"], ["83595.60", "4.473562"], ["83604.00", "3.925779"], ["83612.40", "4.930048"], ["83620.80", "4.656156"], ["83629.20", "5.386533"], ["83637.60", "5.112642"], ["83646.00", "4.838750"], ["83654.40", "5.295236"], ["83662.80", "5.203939"], ["83671.20", "4.199670"], ["83679.60", "4.017076"], ["83688.00", "5.660425"], ["83696.40", "4.382265"], ["83772.50", "0"]], "bids": [["83429.50", "0.001249"], ["83427.50", "0.003288"], ["83425.50", "0.008652"], ["83423.50", "0.022770"], ["83421.50", "0.059920"], ["83419.50", "0.157684"], ["83417.50", "0.414957"], ["83415.50", "1.091993"], ["83413.50", "2.873665"], ["83411.50", "7.562276"], ["83395.00", "0.000283"], ["83394.00", "0.000161"], ["83369.80", "5.569128"], ["83361.40", "4.473562"], ["83353.00", "5.477831"], ["83344.60", "5.021345"], ["83336.20", "3.925779"], ["83327.80", "4.199670"], ["83319.40", "4.930048"], ["83311.00", "4.564859"], ["83302.60", "4.017076"], ["83294.20", "4.290967"], ["83285.80", "5.295236"], ["83277.40", "4.747453"], ["83269.00", "4.656156"], ["83260.60", "4.382265"], ["83252.20", "5.660425"], ["83243.80", "5.112642"], ["83235.40", "5.203939"], ["83227.00", "4.108373"], ["83218.60", "5.386533"], ["83210.20", "4.838750"], ["82937.50", "0"]], "checksum": -86031088, "ts": "1742377431014"}], "ts": 1742377431016, "record_time": 1742377431.909525}
{"action": "update", "arg": {"instType": "SPOT", "channel": "books", "instId": "BTCUSDT"}, "data": [{"asks": [["83483.10", "0.003766"], ["83485.10", "0.009911"], ["83487.10", "0.026081"], ["83489.10", "0.068635"], ["83491.10", "0.180617"], ["83493.10", "0.475309"], ["83495.10", "1.250813"], ["83497.50", "0"], ["83504.80", "0.015000"], ["83536.80", "4.930048"], ["83545.20", "5.660425"], ["83553.60", "4.290967"], ["83562.00", "5.295236"], ["83570.40", "4.199670"], ["83578.80", "4.656156"], ["83587.20", "5.112642"], ["83595.60", "5.569128"], ["83604.00", "4.747453"], ["83612.40", "5.386533"], ["83620.80", "4.473562"], ["83629.20", "5.021345"], ["83637.60", "5.477831"], ["83654.40", "4.564859"], ["83662.80", "4.017076"], ["83671.20", "3.925779"], ["83679.60", "4.382265"], ["83688.00", "4.108373"], ["83696.40", "5.203939"]], "bids": [["83442.19", "0"], ["83411.50", "7.562425"], ["83369.80", "5.386533"], ["83361.40", "5.203939"], ["83353.00", "4.017076"], ["83344.60", "4.930048"], ["83336.20", "5.112642"], ["83327.80", "4.290967"], ["83319.40", "4.656156"], ["83311.00", "4.838750"], ["83302.60", "5.569128"], ["83294.20", "4.564859"], ["83285.80", "5.021345"], ["83277.40", "4.199670"], ["83269.00", "5.660425"], ["83260.60", "5.295236"], ["83252.20", "4.108373"], ["83243.80", "4.747453"], ["83235.40", "4.382265"], ["83227.00", "5.477831"], ["83218.60", "4.473562"], ["83210.20", "3.925779"], ["82937.50", "0.000012"]], "checksum": 1193440923, "ts": "1742377431225"}], "ts": 1742377431229, "record_time": 1742377432.120825}
{"action": "update", "arg": {"instType": "SPOT", "channel": "books", "instId": "BTCUSDT"}, "data": [{"asks": [["83483.10", "0.003649"], ["83485.10", "0.009603"], ["83487.10", "0.025271"], ["83489.10", "0.066501"], ["83491.10", "0.175004"], ["83493.10", "0.460537"], ["83495.10", "1.212069"], ["83496.90", "0.014820"], ["83499.10", "0"], ["83536.80", "4.656156"], ["83545.20", "4.564859"], ["83553.60", "5.660425"], ["83570.40", "5.569128"], ["83578.80", "5.112642"], ["83587.20", "5.477831"], ["83595.60", "4.930048"], ["83604.00", "4.838750"], ["83612.40", "4.108373"], ["83620.80", "4.199670"], ["83629.20", "4.017076"], ["83637.60", "5.021345"], ["83646.00", "3.925779"], ["83654.40", "4.473562"], ["83662.80", "5.203939"], ["83671.20", "4.290967"], ["83679.60", "4.747453"], ["83688.00", "5.386533"], ["83696.40", "4.382265"]], "bids": [["83442.29", "0.045561"], ["83421.50", "0.059922"], ["83419.50", "0.157689"], ["83417.50", "0.414970"], ["83415.50", "1.092028"], ["83413.50", "2.873757"], ["83411.50", "7.562518"], ["83410.00", "0.022680"], ["83409.10", "0"], ["83408.80", "0.236340"], ["83369.80", "4.108373"], ["83361.40", "4.382265"], ["83353.00", "4.199670"], ["83344.60", "4.656156"], ["83327.80", "4.017076"], ["83319.40", "3.925779"], ["83311.00", "5.386533"], ["83302.60", "4.747453"], ["83294.20", "5.569128"], ["83285.80", "5.660425"], ["83277.40", "4.290967"], ["83269.00", "5.477831"], ["83252.20", "4.838750"], ["83243.80", "5.021345"], ["83235.40", "5.203939"], ["83227.00", "4.473562"], ["83218.60", "4.564859"], ["83210.20", "4.930048"]], "checksum": -1681318110, "ts": "1742377431426"}], "ts": 1742377431428, "record_time": 1742377432.325533}
{"action": "update", "arg": {"instType": "SPOT", "channel": "books", "instId": "BTCUSDT"}, "data": [{"asks": [["83499.10", "0.179550"], ["83504.50", "1.199880"], ["83536.80", "4.930048"], ["83545.20", "4.199670"], ["83553.60", "5.569128"], ["83562.00", "3.925779"], ["83570.40", "5.203939"], ["83578.80", "4.382265"], ["83587.20", "4.656156"], ["83595.60", "5.386533"], ["83604.00", "4.108373"], ["83612.40", "5.021345"], ["83620.80", "5.295236"], ["83629.20", "4.838750"], ["83637.60", "5.660425"], ["83646.00", "4.017076"], ["83654.40", "5.112642"], ["83662.80", "5.477831"], ["83671.20", "4.473562"], ["83688.00", "4.290967"], ["83696.40", "4.564859"], ["83772.00", "0"]], "bids": [["83429.50", "0.001388"], ["83427.50", "0.003652"], ["83425.50", "0.009612"], ["83423.50", "0.025295"], ["83421.50", "0.066566"], ["83419.50", "0.175173"], ["83417.50", "0.460982"], ["83415.50", "1.213111"], ["83413.50", "3.192397"], ["83411.50", "8.401043"], ["83393.00", "0"], ["83369.80", "4.747453"], ["83361.40", "4.108373"], ["83353.00", "4.017076"], ["83344.60", "4.290967"], ["83336.20", "5.386533"], ["83327.80", "5.477831"], ["83319.40", "4.473562"], ["83311.00", "4.564859"], ["83302.60", "4.930048"], ["83294.20", "5.203939"], ["83285.80", "5.569128"], ["83277.40", "4.382265"], ["83269.00", "4.199670"], ["83260.60", "5.660425"], ["83252.20", "5.112642"], ["83243.80", "4.838750"], ["83235.40", "4.656156"], ["83227.00", "3.925779"], ["83218.60", "5.021345"], ["83210.20", "5.295236"], ["82936.29", "0.000067"]], "checksum": -1681318110, "ts": "1742377431641"}], "ts": 1742377431644, "record_time": 1742377432.536692}
{"action": "update", "arg": {"instType": "SPOT", "channel": "books", "instId": "BTCUSDT"}, "data": [{"asks": [["83481.10", "0.001729"], ["83483.10", "0.004551"], ["83485.10", "0.011977"], ["83487.10", "0.031516"], ["83489.10", "0.082939"], ["83491.10", "0.218259"], ["83493.10", "0.574367"], ["83495.10", "1.511492"], ["83495.60", "0.222810"], ["83496.80", "0"], ["83504.50", "1.199910"], ["83536.80", "4.656156"], ["83545.20", "5.386533"], ["83553.60", "5.477831"], ["83562.00", "5.569128"], ["83570.40", "5.021345"], ["83578.80", "4.108373"], ["83587.20", "4.838750"], ["83595.60", "4.382265"], ["83604.00", "4.290967"], ["83612.40", "4.199670"], ["83620.80", "5.660425"], ["83629.20", "4.017076"], ["83637.60", "5.295236"], ["83646.00", "3.925779"], ["83662.80", "4.747453"], ["83671.20", "5.203939"], ["83679.60", "4.473562"], ["83688.00", "4.564859"], ["83696.40", "4.930048"], ["83772.00", "0.000096"]], "bids": [["83442.39", "0.045560"], ["83442.29", "0"], ["83429.50", "0.001250"], ["83427.50", "0.003288"], ["83425.50", "0.008655"], ["83423.50", "0.022774"], ["83421.50", "0.059934"], ["83419.50", "0.157721"], ["83417.50", "0.415054"], ["83415.50", "1.092248"], ["83414.72", "0"], ["83413.50", "2.874337"], ["83411.50", "7.564043"], ["83406.16", "0.018506"], ["83395.00", "0.000122"], ["83369.80", "4.838750"], ["83361.40", "5.569128"], ["83353.00", "4.564859"], ["83344.60", "5.386533"], ["83336.20", "5.295236"], ["83327.80", "4.382265"], ["83311.00", "4.108373"], ["83302.60", "5.112642"], ["83294.20", "4.290967"], ["83285.80", "4.930048"], ["83277.40", "5.477831"], ["83269.00", "4.747453"], ["83260.60", "4.199670"], ["83252.20", "4.017076"], ["83243.80", "4.656156"], ["83235.40", "5.021345"], ["83227.00", "5.203939"], ["83218.60", "3.925779"], ["83210.20", "5.660425"]], "checksum": 1422258673, "ts": "1742377431841"}], "ts": 1742377431845, "record_time": 1742377432.736095}
{"action": "update", "arg": {"instType": "SPOT", "channel": "books", "instId": "BTCUSDT"}, "data": [{"asks": [["83489.09", "0.083735"], ["83493.10", "0.574198"], ["83495.10", "1.511045"], ["83536.80", "5.295236"], ["83545.20", "5.112642"], ["83553.60", "4.199670"], ["83570.40", "4.017076"], ["83578.80", "4.564859"], ["83587.20", "4.382265"], ["83595.60", "3.925779"], ["83604.00", "5.660425"], ["83612.40", "5.477831"], ["83620.80", "4.473562"], ["83629.20", "4.747453"], ["83637.60", "4.930048"], ["83646.00", "4.108373"], ["83654.40", "4.290967"], ["83662.80", "5.386533"], ["83671.20", "5.021345"], ["83679.60", "5.203939"], ["83688.00", "4.656156"], ["83696.40", "4.838750"]], "bids": [["83425.50", "0.008790"], ["83423.50", "0.023133"], ["83421.50", "0.060877"], ["83419.50", "0.160202"], ["83417.50", "0.421583"], ["83415.50", "1.109429"], ["83413.50", "2.919550"], ["83411.50", "7.683028"], ["83369.80", "5.477831"], ["83361.40", "3.925779"], ["83353.00", "5.021345"], ["83344.60", "4.747453"], ["83336.20", "4.656156"], ["83327.80", "5.203939"], ["83319.40", "4.290967"], ["83311.00", "4.017076"], ["83302.60", "5.569128"], ["83294.20", "4.930048"], ["83285.80", "4.382265"], ["83277.40", "5.386533"], ["83269.00", "4.199670"], ["83260.60", "4.473562"], ["83252.20", "5.112642"], ["83243.80", "5.660425"], ["83235.40", "4.838750"], ["83227.00", "5.295236"], ["83218.60", "4.564859"], ["83210.20", "4.108373"]], "checksum": 1422258673, "ts": "1742377432054"}], "ts": 1742377432057, "record_time": 1742377432.950116}
{"action": "update", "arg": {"instType": "SPOT", "channel": "books", "instId": "BTCUSDT"}, "data": [{"asks": [["83491.10", "0.218063"], ["83493.10", "0.573851"], ["83495.10", "1.510134"], ["83536.80", "5.112642"], ["83545.20", "4.473562"], ["83553.60", "4.930048"], ["83562.00", "5.295236"], ["83570.40", "5.203939"], ["83578.80", "4.017076"], ["83587.20", "5.477831"], ["83595.60", "4.656156"], ["83604.00", "4.382265"], ["83612.40", "5.569128"], ["83620.80", "4.199670"], ["83629.20", "5.021345"], ["83637.60", "4.747453"], ["83646.00", "3.925779"], ["83654.40", "4.564859"], ["83671.20", "5.660425"], ["83679.60", "4.290967"], ["83688.00", "4.108373"]], "bids": [["83442.39", "0"], ["83407.30", "0.015000"], ["83393.00", "0.000161"], ["83369.80", "5.112642"], ["83361.40", "4.564859"], ["83353.00", "4.473562"], ["83344.60", "4.108373"], ["83336.20", "5.386533"], ["83327.80", "4.199670"], ["83319.40", "4.382265"], ["83311.00", "5.569128"], ["83302.60", "5.477831"], ["83285.80", "4.656156"], ["83277.40", "5.203939"], ["83269.00", "3.925779"], ["83260.60", "4.838750"], ["83252.20", "5.295236"], ["83243.80", "5.021345"], ["83235.40", "4.747453"], ["83227.00", "5.660425"], ["83218.60", "4.017076"], ["83210.20", "4.290967"], ["82936.29", "0"]], "checksum": 1193440923, "ts": "1742377432255"}], "ts": 1742377432257, "record_time": 1742377433.154835}
{"action": "update", "arg": {"instType": "SPOT", "channel": "books", "instId": "BTCUSDT"}, "data": [{"asks": [["83536.80", "4.564859"], ["83545.20", "5.112642"], ["83553.60", "4.382265"], ["83562.00", "4.838750"], ["83570.40", "5.569128"], ["83578.80", "4.290967"], ["83587.20", "5.660425"], ["83595.60", "5.295236"], ["83604.00", "4.930048"], ["83612.40", "5.021345"], ["83629.20", "4.017076"], ["83633.51", "0"], ["83637.60", "5.477831"], ["83646.00", "4.108373"], ["83654.40", "3.925779"], ["83662.80", "4.473562"], ["83671.20", "4.747453"], ["83679.60", "4.656156"], ["83688.00", "5.386533"], ["83696.40", "5.203939"], ["83772.50", "0.000008"]], "bids": [["83442.48", "0.045560"], ["83394.00", "0.000283"], ["83369.80", "4.290967"], ["83361.40", "4.747453"], ["83353.00", "5.021345"], ["83344.60", "3.925779"], ["83336.20", "5.295236"], ["83327.80", "4.473562"], ["83319.40", "4.838750"], ["83311.00", "5.477831"], ["83302.60", "4.108373"], ["83294.20", "5.112642"], ["83285.80", "4.930048"], ["83277.40", "4.199670"], ["83269.00", "5.203939"], ["83260.60", "5.660425"], ["83252.20", "4.564859"], ["83243.80", "5.569128"], ["83235.40", "4.017076"], ["83227.00", "4.656156"], ["83218.60", "4.382265"], ["83210.20", "5.386533"], ["82937.50", "0"]], "checksum": 732483854, "ts": "1742377432456"}], "ts": 1742377432459, "record_time": 1742377433.351273}
{"action": "update", "arg": {"instType": "SPOT", "channel": "books", "instId": "BTCUSDT"}, "data": [{"asks": [["83545.20", "4.930048"], ["83553.60", "4.108373"], ["83562.00", "3.925779"], ["83570.40", "4.199670"], ["83578.80", "5.660425"], ["83587.20", "5.477831"], ["83595.60", "4.747453"], ["83604.00", "5.112642"], ["83612.40", "4.656156"], ["83620.80", "4.290967"], ["83629.20", "5.203939"], ["83633.49", "0.160102"], ["83637.60", "5.569128"], ["83646.00", "5.021345"], ["83654.40", "5.386533"], ["83662.80", "4.017076"], ["83671.20", "4.382265"], ["83679.60", "4.838750"], ["83688.00", "5.295236"], ["83696.40", "4.473562"], ["83772.50", "0"]], "bids": [["83419.50", "0.160001"], ["83417.50", "0.421056"], ["83415.50", "1.108040"], ["83413.50", "2.915897"], ["83411.50", "7.673411"], ["83403.40", "0"], ["83361.40", "5.021345"], ["83353.00", "4.838750"], ["83344.60", "5.295236"], ["83336.20", "4.382265"], ["83327.80", "4.747453"], ["83319.40", "5.569128"], ["83311.00", "4.473562"], ["83302.60", "5.660425"], ["83294.20", "4.108373"], ["83285.80", "4.017076"], ["83277.40", "3.925779"], ["83269.00", "5.112642"], ["83260.60", "4.199670"], ["83252.20", "4.930048"], ["83243.80", "5.477831"], ["83235.40", "5.203939"], ["83227.00", "5.386533"], ["83218.60", "4.656156"], ["83210.20", "4.564859"], ["82937.50", "0.000012"]], "checksum": 732483854, "ts": "1742377432666"}], "ts": 1742377432670, "record_time": 1742377433.562823}
{"action": "update", "arg": {"instType": "SPOT", "channel": "books", "instId": "BTCUSDT"}, "data": [{"asks": [["83536.80", "5.021345"], ["83545.20", "4.017076"], ["83553.60", "4.656156"], ["83562.00", "4.564859"], ["83570.40", "4.290967"], ["83578.80", "5.295236"], ["83587.20", "4.747453"], ["83595.60", "3.925779"], ["83604.00", "5.569128"], ["83612.40", "5.386533"], ["83620.80", "5.660425"], ["83637.60", "4.473562"], ["83646.00", "4.838750"], ["83654.40", "4.108373"], ["83662.80", "4.930048"], ["83679.60", "5.477831"], ["83688.00", "4.199670"], ["83696.40", "5.112642"]], "bids": [["83442.55", "0.045560"], ["83442.48", "0"], ["83421.50", "0.060771"], ["83415.50", "1.108044"], ["83413.50", "2.915903"], ["83411.50", "7.673430"], ["83369.80", "4.199670"], ["83361.40", "5.477831"], ["83353.00", "5.386533"], ["83344.60", "5.021345"], ["83336.20", "5.112642"], ["83327.80", "4.564859"], ["83319.40", "5.295236"], ["83311.00", "4.290967"], ["83302.60", "4.108373"], ["83294.20", "4.473562"], ["83285.80", "4.930048"], ["83277.40", "5.569128"], ["83269.00", "4.838750"], ["83260.60", "4.382265"], ["83252.20", "4.017076"], ["83243.80", "3.925779"], ["83235.40", "4.656156"], ["83227.00", "5.203939"], ["83218.60", "5.660425"], ["83210.20", "4.747453"]], "checksum": -1156594516, "ts": "1742377432871"}], "ts": 1742377432873, "record_time": 1742377433.765392}
{"action": "update", "arg": {"instType": "SPOT", "channel": "books", "instId": "BTCUSDT"}, "data": [{"asks": [["83483.10", "0.004442"], ["83485.10", "0.011689"], ["83487.10", "0.030762"], ["83489.10", "0.080952"], ["83491.10", "0.213033"], ["83493.10", "0.560613"], ["83495.10", "1.475296"], ["83536.80", "5.203939"], ["83545.20", "5.660425"], ["83553.60", "5.112642"], ["83562.00", "5.477831"], ["83570.40", "5.569128"], ["83578.80", "4.747453"], ["83587.20", "4.564859"], ["83595.60", "4.656156"], ["83604.00", "5.386533"], ["83612.40", "4.838750"], ["83620.80", "4.473562"], ["83629.20", "4.199670"], ["83637.60", "4.108373"], ["83646.00", "4.290967"], ["83654.40", "3.925779"], ["83662.80", "5.021345"], ["83679.60", "4.930048"], ["83688.00", "4.017076"], ["83696.40", "5.295236"]], "bids": [["83395.00", "0"], ["83394.00", "0.000122"], ["83369.80", "4.930048"], ["83361.40", "5.112642"], ["83353.00", "4.838750"], ["83344.60", "5.477831"], ["83336.20", "3.925779"], ["83327.80", "4.017076"], ["83319.40", "5.660425"], ["83311.00", "4.747453"], ["83302.60", "4.199670"], ["83294.20", "5.203939"], ["83285.80", "4.290967"], ["83277.40", "4.564859"], ["83269.00", "4.473562"], ["83260.60", "4.108373"], ["83252.20", "5.386533"], ["83243.80", "4.382265"], ["83235.40", "5.295236"], ["83227.00", "4.656156"], ["83218.60", "5.021345"], ["83210.20", "5.569128"], ["82936.29", "0.000067"]], "checksum": -1156594516, "ts": "1742377433072"}], "ts": 1742377433074, "record_time": 1742377433.964678}
{"action": "update", "arg": {"instType": "SPOT", "channel": "books", "instId": "BTCUSDT"}, "data": [{"asks": [["83495.10", "1.475147"], ["83499.10", "0"], ["83504.80", "0"], ["83536.80", "4.108373"], ["83545.20", "4.564859"], ["83553.60", "4.017076"], ["83562.00", "4.290967"], ["83570.40", "4.473562"], ["83578.80", "5.203939"], ["83587.20", "5.660425"], ["83595.60", "5.295236"], ["83604.00", "4.382265"], ["83612.40", "5.386533"], ["83620.80", "3.925779"], ["83629.20", "4.838750"], ["83637.60", "4.747453"], ["83646.00", "5.112642"], ["83654.40", "5.477831"], ["83671.20", "5.569128"], ["83679.60", "4.656156"], ["83688.00", "4.199670"], ["83696.40", "4.930048"], ["83772.50", "0.000008"], ["83772.56", "0.000614"]], "bids": [["83429.50", "0.001406"], ["83427.50", "0.003700"], ["83425.50", "0.009737"], ["83423.50", "0.025625"], ["83421.50", "0.067432"], ["83419.50", "0.177454"], ["83417.50", "0.466985"], ["83415.50", "1.228906"], ["83413.50", "3.233963"], ["83411.50", "8.510430"], ["83407.30", "0.030000"], ["83369.80", "5.660425"], ["83361.40", "4.290967"], ["83353.00", "5.295236"], ["83344.60", "4.199670"], ["83336.20", "5.569128"], ["83319.40", "5.112642"], ["83311.00", "5.477831"], ["83302.60", "4.930048"], ["83285.80", "4.838750"], ["83277.40", "3.925779"], ["83269.00", "4.564859"], ["83260.60", "4.382265"], ["83243.80", "4.108373"], ["83235.40", "5.021345"], ["83227.00", "4.747453"], ["83218.60", "4.656156"], ["83210.20", "4.473562"]], "checksum": -1156594516, "ts": "1742377433275"}], "ts": 1742377433277, "record_time": 1742377434.167111}
{"action": "update", "arg": {"instType": "SPOT", "channel": "books", "instId": "BTCUSDT"}, "data": [{"asks": [["83481.10", "0.001006"], ["83483.10", "0.001059"], ["83485.10", "0.002479"], ["83487.10", "0.006523"], ["83489.10", "0.017167"], ["83491.10", "0.045176"], ["83493.10", "0.118884"], ["83495.10", "0.312852"], ["83504.50", "0.553650"], ["83506.10", "0.252000"], ["83536.80", "5.112642"], ["83545.20", "4.108373"], ["83553.60", "5.295236"], ["83562.00", "4.017076"], ["83570.40", "4.656156"], ["83578.80", "4.473562"], ["83587.20", "4.930048"], ["83595.60", "5.386533"], ["83604.00", "3.925779"], ["83612.40", "4.199670"], ["83620.80", "5.660425"], ["83629.20", "4.747453"], ["83637.60", "5.477831"], ["83646.00", "4.564859"], ["83654.40", "4.382265"], ["83662.80", "4.290967"], ["83671.20", "5.203939"], ["83679.60", "4.838750"], ["83688.00", "5.569128"], ["83696.40", "5.021345"], ["83772.56", "0"]], "bids": [["83442.66", "0.045560"], ["83442.55", "0"], ["83406.00", "0.912060"], ["83403.50", "0"], ["83395.00", "0.000161"], ["83369.80", "5.477831"], ["83361.40", "4.473562"], ["83353.00", "4.290967"], ["83344.60", "4.838750"], ["83336.20", "4.564859"], ["83327.80", "4.382265"], ["83319.40", "5.295236"], ["83311.00", "4.656156"], ["83302.60", "5.021345"], ["83294.20", "5.660425"], ["83285.80", "4.747453"], ["83277.40", "5.569128"], ["83269.00", "4.017076"], ["83260.60", "5.203939"], ["83252.20", "3.925779"], ["83243.80", "4.930048"], ["83235.40", "4.199670"], ["83227.00", "5.386533"], ["83218.60", "5.112642"], ["83210.20", "4.108373"]], "checksum": -1480818880, "ts": "1742377433477"}], "ts": 1742377433480, "record_time": 1742377434.371326}
{"action": "update", "arg": {"instType": "SPOT", "channel": "books", "instId": "BTCUSDT"}, "data": [{"asks": [["83489.09", "0"], ["83493.09", "0.116322"], ["83496.90", "0"], ["83497.60", "0.014820"], ["83500.29", "0.531464"], ["83536.80", "4.930048"], ["83545.20", "5.660425"], ["83553.60", "5.569128"], ["83562.00", "5.386533"], ["83570.40", "4.199670"], ["83578.80", "4.747453"], ["83587.20", "4.473562"], ["83595.60", "4.017076"], ["83604.00", "5.021345"], ["83612.40", "5.295236"], ["83620.80", "4.838750"], ["83629.20", "4.290967"], ["83637.60", "5.112642"], ["83654.40", "4.108373"], ["83662.80", "5.203939"], ["83671.20", "4.656156"], ["83679.60", "3.925779"], ["83688.00", "5.477831"], ["83696.40", "4.382265"], ["83772.56", "0.000614"]], "bids": [["83429.50", "0.001268"], ["83427.50", "0.003336"], ["83425.50", "0.008780"], ["83423.50", "0.023104"], ["83421.50", "0.060802"], ["83419.50", "0.160003"], ["83417.50", "0.421061"], ["83415.50", "1.108057"], ["83413.50", "2.915939"], ["83411.50", "7.673523"], ["83369.80", "5.295236"], ["83361.40", "4.382265"], ["83353.00", "5.569128"], ["83344.60", "5.021345"], ["83336.20", "4.017076"], ["83327.80", "5.112642"], ["83319.40", "4.108373"], ["83311.00", "3.925779"], ["83302.60", "5.660425"], ["83294.20", "4.199670"], ["83285.80", "4.564859"], ["83277.40", "4.930048"], ["83269.00", "5.386533"], ["83252.20", "4.838750"], ["83243.80", "4.747453"], ["83235.40", "4.290967"], ["83227.00", "4.656156"], ["83218.60", "5.477831"], ["83210.20", "4.473562"]], "checksum": -1480818880, "ts": "1742377433680"}], "ts": 1742377433684, "record_time": 1742377434.584584}
{"action": "update", "arg": {"instType": "SPOT", "channel": "books", "instId": "BTCUSDT"}, "data": [{"asks": [["83536.80", "5.569128"], ["83545.20", "4.108373"], ["83553.60", "4.747453"], ["83562.00", "4.382265"], ["83578.80", "5.660425"], ["83595.60", "4.290967"], ["83604.00", "5.295236"], ["83612.40", "4.838750"], ["83620.80", "5.203939"], ["83629.20", "5.112642"], ["83637.60", "5.386533"], ["83654.40", "5.477831"], ["83662.80", "4.930048"], ["83671.20", "5.021345"], ["83679.60", "4.017076"], ["83688.00", "4.656156"], ["83696.40", "3.925779"]], "bids": [["83442.66", "0"], ["83393.00", "0.000283"], ["83369.80", "3.925779"], ["83361.40", "5.112642"], ["83353.00", "5.386533"], ["83344.60", "5.477831"], ["83336.20", "5.021345"], ["83327.80", "5.295236"], ["83319.40", "4.656156"], ["83311.00", "4.564859"], ["83302.60", "4.290967"], ["83294.20", "4.473562"], ["83285.80", "5.569128"], ["83277.40", "5.660425"], ["83269.00", "4.382265"], ["83260.60", "4.199670"], ["83252.20", "5.203939"], ["83243.80", "4.838750"], ["83235.40", "4.108373"], ["83227.00", "4.747453"], ["83218.60", "4.930048"], ["83210.20", "4.017076"], ["82935.00", "0.000121"]], "checksum": 1193440923, "ts": "1742377433889"}], "ts": 1742377433892, "record_time": 1742377434.806902}
{"action": "update", "arg": {"instType": "SPOT", "channel": "books", "instId": "BTCUSDT"}, "data": [{"asks": [["83536.80", "4.017076"], ["83545.20", "3.925779"], ["83553.60", "5.386533"], ["83562.00", "4.473562"], ["83570.40", "4.290967"], ["83578.80", "5.112642"], ["83587.20", "5.021345"], ["83595.60", "4.108373"], ["83604.00", "4.930048"], ["83612.40", "4.747453"], ["83620.80", "4.838750"], ["83629.20", "4.382265"], ["83637.60", "5.295236"], ["83646.00", "5.477831"], ["83654.40", "5.569128"], ["83662.80", "4.564859"], ["83671.20", "5.660425"], ["83679.60", "4.656156"], ["83688.00", "4.199670"], ["83696.40", "5.203939"]], "bids": [["83442.74", "0.045560"], ["83415.50", "1.107903"], ["83413.50", "2.915536"], ["83411.50", "7.672463"], ["83369.80", "5.477831"], ["83361.40", "4.930048"], ["83353.00", "5.295236"], ["83344.60", "5.569128"], ["83327.80", "4.838750"], ["83311.00", "4.017076"], ["83294.20", "4.108373"], ["83285.80", "5.112642"], ["83277.40", "3.925779"], ["83269.00", "4.747453"], ["83260.60", "4.473562"], ["83243.80", "4.382265"], ["83235.40", "4.199670"], ["83227.00", "5.660425"], ["83218.60", "5.386533"], ["83210.20", "4.564859"], ["82935.00", "0"]], "checksum": 1733822981, "ts": "1742377434092"}], "ts": 1742377434094, "record_time": 1742377434.984163}
{"action": "update", "arg": {"instType": "SPOT", "channel": "books", "instId": "BTCUSDT"}, "data": [{"asks": [["83445.01", "1.266986"], ["83536.80", "5.660425"], ["83545.20", "4.473562"], ["83553.60", "5.477831"], ["83562.00", "4.108373"], ["83570.40", "5.569128"], ["83578.80", "5.295236"], ["83587.20", "4.930048"], ["83595.60", "5.386533"], ["83604.00", "4.656156"], ["83612.40", "4.838750"], ["83620.80", "3.925779"], ["83629.20", "4.017076"], ["83637.60", "4.290967"], ["83646.00", "5.021345"], ["83654.40", "4.382265"], ["83662.80", "5.112642"], ["83671.20", "4.564859"], ["83679.60", "4.199670"], ["83688.00", "4.747453"]], "bids": [["83433.64", "0.111711"], ["83431.06", "0"], ["83419.50", "0.160189"], ["83417.50", "0.421550"], ["83415.50", "1.109343"], ["83413.50", "2.919325"], ["83411.50", "7.682432"], ["83407.30", "0.015000"], ["83393.00", "0.000122"], ["83369.80", "4.838750"], ["83361.40", "5.477831"], ["83353.00", "3.925779"], ["83344.60", "4.930048"], ["83327.80", "4.290967"], ["83319.40", "5.203939"], ["83311.00", "4.564859"], ["83302.60", "5.112642"], ["83294.20", "5.295236"], ["83285.80", "4.473562"], ["83280.00", "0.003215"], ["83277.40", "4.017076"], ["83269.00", "5.569128"], ["83260.60", "4.656156"], ["83252.20", "4.747453"], ["83243.80", "4.108373"], ["83235.40", "5.386533"], ["83218.60", "4.382265"], ["83210.20", "4.199670"]], "checksum": -1988778625, "ts": "1742377434295"}], "ts": 1742377434299, "record_time": 1742377435.19936}
{"action": "update", "arg": {"instType": "SPOT", "channel": "books", "instId": "BTCUSDT"}, "data": [{"asks": [["83462.93", "0"], ["83463.35", "0"], ["83463.62", "0.035952"], ["83464.03", "0.119843"], ["83464.61", "0"], ["83465.01", "0"], ["83465.20", "0"], ["83465.29", "0.035960"], ["83465.53", "0"], ["83465.71", "0.006357"], ["83465.85", "0"], ["83465.89", "0.006357"], ["83466.01", "0"], ["83466.22", "0.006356"], ["83466.52", "0"], ["83466.54", "0.006356"], ["83466.60", "0"], ["83466.70", "0.006356"], ["83466.86", "0"], ["83467.02", "0"], ["83467.21", "0.006356"], ["83467.29", "0.010994"], ["83467.52", "0"], ["83467.53", "0"], ["83467.54", "0.006357"], ["83467.71", "0.006357"], ["83468.02", "0"], ["83468.05", "0"], ["83468.21", "0.016429"], ["83468.22", "0.006357"], ["83468.36", "0"], ["83468.38", "0.006357"], ["83468.52", "0"], ["83468.55", "0"], ["83468.71", "0.006357"], ["83468.72", "0.006357"], ["83469.05", "0.136314"], ["83469.21", "0.006357"], ["83469.22", "0.006357"], ["83469.53", "0"], ["83470.05", "0"], ["83470.21", "0.006357"], ["83470.72", "0.017342"], ["83470.89", "0"], ["83471.66", "0"], ["83471.78", "0"], ["83472.47", "0.119908"], ["83472.77", "0"], ["83473.20", "0"], ["83473.36", "0"], ["83473.46", "0.119881"], ["83473.89", "0.015896"], ["83474.05", "0.009989"], ["83475.37", "0"], ["83476.06", "0.006357"], ["83536.80", "5.386533"], ["83545.20", "4.290967"], ["83553.60", "4.108373"], ["83562.00", "4.747453"], ["83570.40", "4.017076"], ["83578.80", "5.569128"], ["83587.20", "4.564859"], ["83587.25", "0"], ["83595.60", "5.477831"], ["83604.00", "5.112642"], ["83620.80", "5.021345"], ["83629.20", "4.382265"], ["83637.60", "4.473562"], ["83646.00", "3.925779"], ["83654.40", "5.203939"], ["83662.80", "4.656156"], ["83671.20", "4.199670"], ["83679.60", "4.930048"], ["83688.00", "5.660425"], ["83696.40", "5.295236"], ["83772.68", "0.000087"], ["83772.73", "0.000008"]], "bids": [["83442.83", "0.045560"], ["83442.74", "0"], ["83433.65", "0.033550"], ["83423.56", "0.090725"], ["83423.14", "0.247315"], ["83422.88", "0"], ["83422.67", "0.004096"], ["83422.46", "0"], ["83422.09", "0"], ["83421.90", "0.084523"], ["83421.48", "0.017987"], ["83421.33", "0.018412"], ["83421.22", "0"], ["83420.99", "0.005985"], ["83420.79", "0"], ["83420.64", "0.015873"], ["83420.48", "0.016562"], ["83420.30", "0"], ["83419.99", "0.006619"], ["83419.95", "0"], ["83419.89", "0.056234"], ["83419.79", "0"], ["83419.65", "0.017216"], ["83419.48", "0.007191"], ["83419.29", "0"], ["83419.21", "0"], ["83418.98", "0.007380"], ["83418.97", "0.029032"], ["83418.96", "0"], ["83418.84", "0"], ["83418.82", "0.017196"], ["83418.49", "0.007996"], ["83418.47", "0.009058"], ["83418.30", "0"], ["83418.29", "0"], ["83418.15", "0.252805"], ["83417.98", "0.008242"], ["83417.97", "0.017488"], ["83417.82", "0"], ["83417.79", "0"], ["83417.50", "0.421286"], ["83417.46", "0"], ["83417.32", "0"], ["83417.29", "0"], ["83416.98", "0.008343"], ["83416.48", "0.065048"], ["83416.29", "0"], ["83415.81", "0"], ["83415.66", "0.018649"], ["83415.50", "1.108647"], ["83414.98", "0"], ["83414.73", "0.270824"], ["83414.04", "0"], ["83413.72", "0.223164"], ["83413.50", "2.917494"], ["83413.31", "0.076646"], ["83413.13", "0.021277"], ["83413.03", "0"], ["83412.62", "0"], ["83412.44", "0"], ["83411.50", "7.677615"], ["83411.14", "0.012531"], ["83410.45", "0"], ["83406.04", "0.023958"], ["83405.61", "0"], ["83403.55", "0.024164"], ["83403.12", "0"], ["83394.00", "0"], ["83382.10", "0"], ["83369.80", "4.199670"], ["83353.00", "4.930048"], ["83344.60", "4.564859"], ["83336.20", "5.295236"], ["83327.80", "4.382265"], ["83319.40", "5.112642"], ["83311.00", "4.747453"], ["83302.60", "5.660425"], ["83294.20", "4.838750"], ["83285.80", "4.656156"], ["83277.40", "5.021345"], ["83269.00", "4.017076"], ["83260.60", "5.203939"], ["83252.20", "5.569128"], ["83227.00", "3.925779"], ["83218.60", "4.473562"], ["83210.20", "4.290967"]], "checksum": -1300497844, "ts": "1742377434499"}], "ts": 1742377434502, "record_time": 1742377435.393086}
{"action": "update", "arg": {"instType": "SPOT", "channel": "books", "instId": "BTCUSDT"}, "data": [{"asks": [["83445.01", "1.155277"], ["83473.96", "0.177084"], ["83495.60", "0.073410"], ["83498.30", "0"], ["83500.80", "0"], ["83536.80", "5.112642"], ["83545.20", "4.930048"], ["83553.60", "3.925779"], ["83562.00", "5.021345"], ["83570.40", "5.386533"], ["83578.80", "5.295236"], ["83587.20", "5.660425"], ["83595.60", "4.838750"], ["83604.00", "4.747453"], ["83612.40", "4.199670"], ["83620.80", "4.017076"], ["83629.20", "5.569128"], ["83637.60", "4.564859"], ["83646.00", "5.477831"], ["83654.40", "4.290967"], ["83662.80", "4.473562"], ["83671.20", "4.382265"], ["83679.60", "5.203939"], ["83688.00", "4.656156"], ["83696.40", "4.108373"], ["83772.88", "0.000023"]], "bids": [["83435.13", "0.000366"], ["83435.03", "0"], ["83394.00", "0.000161"], ["83369.80", "4.747453"], ["83361.40", "4.473562"], ["83353.00", "4.564859"], ["83344.60", "5.112642"], ["83336.20", "4.290967"], ["83327.80", "5.386533"], ["83319.40", "5.660425"], ["83311.00", "5.569128"], ["83302.60", "5.021345"], ["83294.20", "4.382265"], ["83288.81", "0"], ["83285.80", "4.930048"], ["83277.40", "5.295236"], ["83269.00", "5.477831"], ["83260.60", "3.925779"], ["83252.20", "4.108373"], ["83243.80", "4.017076"], ["83235.40", "4.199670"], ["83227.00", "4.656156"], ["83218.60", "4.838750"], ["83210.20", "5.203939"]], "checksum": -687776711, "ts": "1742377434708"}], "ts": 1742377434711, "record_time": 1742377435.601371}
{"action": "update", "arg": {"instType": "SPOT", "channel": "books", "instId": "BTCUSDT"}, "data": [{"asks": [["83445.01", "1.266988"], ["83471.56", "0.009990"], ["83491.10", "0.044950"], ["83493.10", "0.118290"], ["83495.10", "0.311290"], ["83495.59", "0"], ["83498.61", "0"], ["83498.78", "0.001598"], ["83501.40", "0.318540"], ["83506.10", "0"], ["83536.79", "0.152359"], ["83536.80", "4.108373"], ["83545.20", "5.386533"], ["83553.60", "5.477831"], ["83562.00", "5.112642"], ["83570.40", "5.295236"], ["83578.80", "4.747453"], ["83587.20", "3.925779"], ["83595.60", "4.017076"], ["83604.00", "5.569128"], ["83612.40", "4.290967"], ["83620.80", "4.382265"], ["83629.20", "4.930048"], ["83637.60", "4.199670"], ["83646.00", "4.473562"], ["83654.40", "5.660425"], ["83662.80", "4.838750"], ["83671.20", "4.564859"], ["83688.00", "5.021345"], ["83696.40", "4.656156"]], "bids": [["83442.83", "0"], ["83404.10", "0"], ["83389.30", "0.001186"], ["83389.13", "0"], ["83369.80", "5.386533"], ["83361.40", "5.477831"], ["83353.00", "5.112642"], ["83344.60", "5.660425"], ["83336.20", "4.108373"], ["83327.80", "4.382265"], ["83319.40", "4.656156"], ["83311.00", "4.199670"], ["83302.60", "4.747453"], ["83294.20", "5.021345"], ["83285.80", "4.838750"], ["83277.40", "4.290967"], ["83269.00", "4.930048"], ["83260.60", "4.564859"], ["83252.20", "4.017076"], ["83243.80", "4.473562"], ["83235.40", "5.295236"], ["83227.00", "5.569128"], ["83218.60", "3.925779"], ["82935.00", "0.000121"], ["82934.78", "0.000010"]], "checksum": -1898863618, "ts": "1742377434915"}], "ts": 1742377434918, "record_time": 1742377435.821717}
{"action": "update", "arg": {"instType": "SPOT", "channel": "books", "instId": "BTCUSDT"}, "data": [{"asks": [["83473.26", "0"], ["83473.64", "0.119900"], ["83477.43", "0"], ["83477.82", "0.015895"], ["83478.26", "0"], ["83478.64", "0.010984"], ["83500.29", "0.683823"], ["83500.56", "0"], ["83536.79", "0.023016"], ["83536.80", "4.747453"], ["83545.20", "4.199670"], ["83553.60", "5.021345"], ["83562.00", "5.386533"], ["83570.40", "4.108373"], ["83578.80", "4.382265"], ["83587.20", "5.295236"], ["83595.60", "5.569128"], ["83604.00", "3.925779"], ["83612.40", "4.838750"], ["83620.80", "4.290967"], ["83629.20", "5.477831"], ["83637.60", "4.930048"], ["83646.00", "4.564859"], ["83654.40", "4.473562"], ["83662.80", "4.656156"], ["83671.20", "4.017076"], ["83679.60", "5.112642"], ["83688.00", "5.660425"], ["83696.40", "5.203939"], ["83772.92", "0.000293"]], "bids": [["83442.90", "0.045560"], ["83429.50", "0.001407"], ["83427.50", "0.003702"], ["83425.50", "0.009742"], ["83423.50", "0.025637"], ["83421.50", "0.067466"], ["83420.69", "0.330653"], ["83419.50", "0.177541"], ["83418.60", "0"], ["83417.50", "0.467214"], ["83415.50", "1.229510"], ["83413.56", "0.262709"], ["83413.50", "3.235554"], ["83413.18", "0"], ["83411.50", "8.514615"], ["83409.39", "0.073759"], ["83409.01", "0"], ["83408.55", "0.056755"], ["83408.17", "0"], ["83387.38", "0.001183"], ["83387.24", "0"], ["83369.80", "5.477831"], ["83361.40", "5.569128"], ["83353.00", "5.021345"], ["83344.60", "3.925779"], ["83336.20", "4.473562"], ["83327.80", "4.108373"], ["83319.40", "4.838750"], ["83311.00", "5.112642"], ["83302.60", "4.656156"], ["83294.20", "4.930048"], ["83285.80", "5.386533"], ["83277.40", "4.747453"], ["83269.00", "4.564859"], ["83260.60", "4.199670"], ["83243.80", "5.203939"], ["83235.40", "5.660425"], ["83227.00", "5.295236"], ["83218.60", "4.382265"], ["83210.20", "4.290967"], ["82934.78", "0"]], "checksum": -1434112983, "ts": "1742377435115"}], "ts": 1742377435124, "record_time": 1742377436.022494}
{"action": "update", "arg": {"instType": "SPOT", "channel": "books", "instId": "BTCUSDT"}, "data": [{"asks": [["83481.10", "0.001794"], ["83483.10", "0.004723"], ["83485.10", "0.012429"], ["83487.10", "0.032959"], ["83489.10", "0.086733"], ["83491.10", "0.228246"], ["83493.10", "0.600645"], ["83495.10", "1.580647"], ["83500.30", "2.268270"], ["83504.50", "1.199880"], ["83504.80", "0.015000"], ["83536.80", "5.203939"], ["83545.20", "4.838750"], ["83553.60", "4.930048"], ["83562.00", "5.295236"], ["83578.80", "5.569128"], ["83587.20", "4.656156"], ["83595.60", "4.473562"], ["83604.00", "4.564859"], ["83612.40", "3.925779"], ["83620.80", "5.477831"], ["83629.20", "5.112642"], ["83637.60", "4.382265"], ["83646.00", "4.290967"], ["83654.40", "5.021345"], ["83662.80", "4.017076"], ["83671.20", "4.747453"], ["83679.60", "5.660425"], ["83688.00", "5.386533"], ["83696.40", "4.199670"], ["83772.92", "0"]], "bids": [["83429.50", "0.001264"], ["83427.50", "0.003328"], ["83425.50", "0.008758"], ["83423.50", "0.023047"], ["83423.34", "0.283086"], ["83421.50", "0.060648"], ["83419.51", "0"], ["83419.50", "0.159462"], ["83417.50", "0.419638"], ["83415.50", "1.104310"], ["83413.50", "2.906079"], ["83411.50", "7.647576"], ["83407.30", "0"], ["83404.10", "0.107850"], ["83395.00", "0.000283"], ["83369.80", "4.108373"], ["83361.40", "3.925779"], ["83353.00", "5.386533"], ["83344.60", "5.477831"], ["83327.80", "5.021345"], ["83319.40", "5.112642"], ["83311.00", "4.017076"], ["83302.60", "4.747453"], ["83294.20", "4.382265"], ["83285.80", "5.295236"], ["83277.40", "4.930048"], ["83269.00", "4.199670"], ["83260.60", "5.203939"], ["83252.20", "4.838750"], ["83243.80", "4.656156"], ["83235.40", "4.290967"], ["83227.00", "5.660425"], ["83218.60", "5.569128"], ["83210.20", "4.564859"], ["82934.78", "0.000010"]], "checksum": -1434112983, "ts": "1742377435316"}], "ts": 1742377435320, "record_time": 1742377436.21053}
{"action": "update", "arg": {"instType": "SPOT", "channel": "books", "instId": "BTCUSDT"}, "data": [{"asks": [["83485.10", "0.012216"], ["83487.10", "0.032148"], ["83489.10", "0.084600"], ["83491.10", "0.222632"], ["83493.10", "0.585873"], ["83495.10", "1.541773"], ["83495.60", "0.769290"], ["83497.50", "2.349600"], ["83500.30", "2.268060"], ["83536.80", "5.112642"], ["83545.20", "5.295236"], ["83553.60", "3.925779"], ["83562.00", "5.569128"], ["83570.40", "5.386533"], ["83578.80", "4.564859"], ["83587.20", "5.021345"], ["83595.60", "4.017076"], ["83604.00", "4.199670"], ["83612.40", "4.838750"], ["83620.80", "4.747453"], ["83629.20", "4.108373"], ["83637.60", "4.473562"], ["83654.40", "5.203939"], ["83662.80", "4.382265"], ["83671.20", "4.656156"], ["83688.00", "4.930048"], ["83696.40", "5.477831"], ["83772.88", "0"]], "bids": [["83442.98", "0.045560"], ["83442.90", "0"], ["83427.50", "0.003213"], ["83425.50", "0.008456"], ["83423.50", "0.022252"], ["83421.50", "0.058558"], ["83419.51", "0.133869"], ["83419.50", "0.154099"], ["83417.50", "0.405525"], ["83415.50", "1.067170"], ["83413.50", "2.808343"], ["83411.50", "7.390375"], ["83395.00", "0.000122"], ["83369.80", "5.477831"], ["83361.40", "4.199670"], ["83353.00", "4.656156"], ["83344.60", "4.747453"], ["83336.20", "4.838750"], ["83327.80", "4.017076"], ["83319.40", "5.660425"], ["83311.00", "5.569128"], ["83302.60", "4.108373"], ["83294.20", "4.564859"], ["83285.80", "4.473562"], ["83277.40", "5.386533"], ["83269.00", "4.290967"], ["83260.60", "4.930048"], ["83252.20", "4.382265"], ["83243.80", "5.021345"], ["83235.40", "5.112642"], ["83227.00", "5.203939"], ["83218.60", "3.925779"], ["83210.20", "5.295236"], ["82934.78", "0"]], "checksum": 720293944, "ts": "1742377435525"}], "ts": 1742377435528, "record_time": 1742377436.41872}
{"action": "update", "arg": {"instType": "SPOT", "channel": "books", "instId": "BTCUSDT"}, "data": [{"asks": [["83485.10", "0.012524"], ["83487.10", "0.032959"], ["83489.10", "0.086733"], ["83491.10", "0.228246"], ["83493.10", "0.600645"], ["83495.10", "1.580647"], ["83496.90", "0.014820"], ["83497.60", "0"], ["83536.80", "4.930048"], ["83545.20", "4.473562"], ["83553.60", "5.477831"], ["83562.00", "3.925779"], ["83570.40", "4.656156"], ["83578.80", "4.108373"], ["83587.20", "4.290967"], ["83595.60", "5.569128"], ["83604.00", "4.838750"], ["83612.40", "5.660425"], ["83620.80", "4.382265"], ["83629.20", "5.295236"], ["83637.60", "5.112642"], ["83646.00", "4.199670"], ["83654.40", "5.021345"], ["83662.80", "4.564859"], ["83671.20", "4.017076"], ["83679.60", "5.386533"], ["83688.00", "5.203939"], ["83696.40", "4.747453"]], "bids": [["83445.00", "1.016387"], ["83442.70", "0.013175"], ["83429.50", "0.001138"], ["83427.50", "0.002993"], ["83425.50", "0.007877"], ["83423.50", "0.020730"], ["83421.50", "0.054553"], ["83419.50", "0.143559"], ["83417.50", "0.377787"], ["83415.50", "0.994177"], ["83413.50", "2.616256"], ["83411.50", "6.884883"], ["83406.16", "0"], ["83397.55", "0.018506"], ["83369.80", "4.747453"], ["83361.40", "5.112642"], ["83353.00", "4.930048"], ["83344.60", "5.386533"], ["83336.20", "4.564859"], ["83327.80", "5.477831"], ["83319.40", "4.382265"], ["83311.00", "5.295236"], ["83302.60", "4.017076"], ["83294.20", "3.925779"], ["83285.80", "5.569128"], ["83277.40", "5.660425"], ["83269.00", "5.021345"], ["83260.60", "4.290967"], ["83252.20", "4.199670"], ["83243.80", "4.108373"], ["83235.40", "4.838750"], ["83227.00", "4.656156"], ["83218.60", "4.473562"], ["83210.20", "5.203939"], ["82935.00", "0"]], "checksum": -353361142, "ts": "1742377435743"}], "ts": 1742377435746, "record_time": 1742377436.636412}
{"action": "update", "arg": {"instType": "SPOT", "channel": "books", "instId": "BTCUSDT"}, "data": [{"asks": [["83479.10", "0.001324"], ["83481.10", "0.003485"], ["83483.10", "0.009172"], ["83485.10", "0.024136"], ["83487.10", "0.063516"], ["83489.10", "0.167148"], ["83491.10", "0.439863"], ["83493.10", "1.157533"], ["83495.10", "3.046141"], ["83495.60", "0.769530"], ["83496.90", "0"], ["83504.90", "0"], ["83506.10", "0.252000"], ["83506.30", "0.144510"], ["83536.80", "4.017076"], ["83545.20", "4.930048"], ["83553.60", "3.925779"], ["83562.00", "4.838750"], ["83570.40", "4.199670"], ["83578.80", "4.656156"], ["83587.20", "5.660425"], ["83595.60", "4.564859"], ["83604.00", "4.382265"], ["83612.40", "5.295236"], ["83620.80", "4.290967"], ["83629.20", "5.203939"], ["83646.00", "4.747453"], ["83654.40", "5.477831"], ["83662.80", "4.108373"], ["83671.20", "5.021345"], ["83688.00", "4.473562"], ["83696.40", "5.569128"]], "bids": [["83445.00", "1.029562"], ["83442.70", "0"], ["83429.50", "0.001033"], ["83427.50", "0.002494"], ["83425.50", "0.006563"], ["83423.50", "0.017272"], ["83421.50", "0.045453"], ["83419.50", "0.119614"], ["83417.50", "0.314772"], ["83415.50", "0.828348"], ["83413.50", "2.179863"], ["83411.50", "5.736482"], ["83406.00", "0.000283"], ["83404.10", "1.137210"], ["83393.00", "0"], ["83369.80", "5.660425"], ["83361.40", "4.382265"], ["83353.00", "5.295236"], ["83344.60", "4.017076"], ["83336.20", "4.199670"], ["83327.80", "3.925779"], ["83319.40", "4.930048"], ["83311.00", "4.290967"], ["83302.60", "5.569128"], ["83294.20", "5.477831"], ["83285.80", "4.473562"], ["83277.40", "5.112642"], ["83269.00", "4.564859"], ["83260.60", "4.108373"], ["83252.20", "5.386533"], ["83243.80", "4.656156"], ["83235.40", "5.203939"], ["83227.00", "4.747453"], ["83218.60", "4.838750"], ["83210.20", "5.021345"], ["82935.00", "0.000121"], ["82934.78", "0.000010"]], "checksum": 720293944, "ts": "1742377435946"}], "ts": 1742377435948, "record_time": 1742377436.838848}
{"action": "update", "arg": {"instType": "SPOT", "channel": "books", "instId": "BTCUSDT"}, "data": [{"asks": [["83445.01", "1.266828"], ["83479.09", "0.001443"], ["83479.10", "0.001208"], ["83481.10", "0.003179"], ["83483.10", "0.008366"], ["83485.10", "0.022016"], ["83487.10", "0.057937"], ["83489.10", "0.152466"], ["83491.10", "0.401227"], ["83493.10", "1.055860"], ["83495.10", "2.778580"], ["83497.50", "2.579220"], ["83504.80", "0"], ["83506.30", "0.143700"], ["83506.90", "0.312840"], ["83536.80", "4.656156"], ["83545.20", "4.473562"], ["83553.60", "4.382265"], ["83562.00", "5.295236"], ["83570.40", "5.569128"], ["83578.80", "4.290967"], ["83587.20", "4.564859"], ["83595.60", "4.747453"], ["83604.00", "4.108373"], ["83612.40", "4.017076"], ["83620.80", "5.203939"], ["83629.20", "5.386533"], ["83637.60", "4.930048"], ["83646.00", "5.477831"], ["83654.40", "5.112642"], ["83662.80", "4.838750"], ["83671.20", "3.925779"], ["83679.60", "4.199670"], ["83688.00", "5.021345"], ["83696.40", "5.660425"], ["83772.73", "0"]], "bids": [["83445.00", "0.983262"], ["83443.05", "0.045560"], ["83442.98", "0"], ["83427.50", "0.001497"], ["83425.50", "0.003938"], ["83423.50", "0.010364"], ["83421.50", "0.027274"], ["83419.50", "0.071774"], ["83417.50", "0.188879"], ["83415.50", "0.497050"], ["83413.50", "1.308025"], ["83411.50", "3.442172"], ["83393.00", "0.000161"], ["83369.80", "4.017076"], ["83361.40", "4.930048"], ["83353.00", "4.290967"], ["83344.60", "4.473562"], ["83336.20", "4.656156"], ["83327.80", "4.108373"], ["83319.40", "4.564859"], ["83311.00", "4.382265"], ["83302.60", "5.660425"], ["83294.20", "5.112642"], ["83285.80", "5.477831"], ["83277.40", "4.838750"], ["83269.00", "5.295236"], ["83260.60", "3.925779"], ["83252.20", "4.747453"], ["83243.80", "5.203939"], ["83235.40", "5.569128"], ["83227.00", "5.021345"], ["83218.60", "5.386533"], ["83210.20", "4.199670"], ["82934.78", "0"]], "checksum": -306741165, "ts": "1742377436150"}], "ts": 1742377436152, "record_time": 1742377437.044664}
{"action": "update", "arg": {"instType": "SPOT", "channel": "books", "instId": "BTCUSDT"}, "data": [{"asks": [["83445.01", "1.267088"], ["83487.10", "0.057921"], ["83489.10", "0.152423"], ["83491.10", "0.401114"], ["83493.10", "1.055564"], ["83495.10", "2.777798"], ["83499.10", "0.179550"], ["83505.40", "2.372220"], ["83506.30", "0"], ["83506.90", "0"], ["83536.80", "4.564859"], ["83545.20", "4.930048"], ["83553.60", "3.925779"], ["83562.00", "4.290967"], ["83570.40", "4.656156"], ["83578.80", "4.473562"], ["83587.20", "5.295236"], ["83595.60", "5.021345"], ["83604.00", "5.203939"], ["83612.40", "5.660425"], ["83620.80", "4.017076"], ["83637.60", "4.199670"], ["83646.00", "4.838750"], ["83654.40", "4.108373"], ["83662.80", "5.477831"], ["83671.20", "4.382265"], ["83679.60", "4.747453"], ["83688.00", "5.569128"], ["83696.40", "5.112642"]], "bids": [["83423.50", "0.010170"], ["83421.50", "0.026764"], ["83419.50", "0.070433"], ["83417.50", "0.185348"], ["83415.50", "0.487760"], ["83413.50", "1.283577"], ["83411.50", "3.377834"], ["83369.80", "5.386533"], ["83361.40", "4.656156"], ["83353.00", "5.112642"], ["83344.60", "5.569128"], ["83336.20", "4.473562"], ["83319.40", "5.203939"], ["83311.00", "3.925779"], ["83302.60", "5.295236"], ["83294.20", "4.290967"], ["83285.80", "4.564859"], ["83277.40", "4.017076"], ["83269.00", "4.930048"], ["83260.60", "4.838750"], ["83252.20", "5.660425"], ["83243.80", "4.382265"], ["83235.40", "4.747453"], ["83227.00", "5.477831"], ["83218.60", "4.199670"], ["83210.20", "5.021345"]], "checksum": -2107103053, "ts": "1742377436353"}], "ts": 1742377436357, "record_time": 1742377437.255235}
{"action": "update", "arg": {"instType": "SPOT", "channel": "books", "instId": "BTCUSDT"}, "data": [{"asks": [["83489.10", "0.152320"], ["83491.10", "0.400843"], ["83493.10", "1.054849"], ["83495.10", "2.775920"], ["83536.80", "5.112642"], ["83545.20", "5.021345"], ["83553.60", "4.473562"], ["83562.00", "4.017076"], ["83570.40", "4.382265"], ["83578.80", "4.199670"], ["83587.20", "3.925779"], ["83595.60", "5.477831"], ["83604.00", "4.108373"], ["83612.40", "4.930048"], ["83620.80", "4.838750"], ["83629.20", "5.295236"], ["83637.60", "4.656156"], ["83646.00", "5.569128"], ["83654.40", "4.747453"], ["83662.80", "5.386533"], ["83671.20", "4.564859"], ["83679.60", "5.203939"], ["83688.00", "4.290967"], ["83696.40", "5.660425"]], "bids": [["83443.12", "0.045560"], ["83443.05", "0"], ["83394.00", "0.000283"], ["83369.80", "4.017076"], ["83361.40", "4.930048"], ["83353.00", "4.656156"], ["83344.60", "5.477831"], ["83336.20", "4.290967"], ["83327.80", "4.382265"], ["83319.40", "5.112642"], ["83311.00", "5.569128"], ["83302.60", "4.473562"], ["83294.20", "4.838750"], ["83285.80", "5.295236"], ["83277.40", "4.564859"], ["83269.00", "5.021345"], ["83260.60", "4.199670"], ["83252.20", "5.386533"], ["83243.80", "4.108373"], ["83235.40", "5.203939"], ["83227.00", "4.747453"], ["83218.60", "3.925779"], ["83210.20", "5.660425"]], "checksum": -1098466749, "ts": "1742377436557"}], "ts": 1742377436560, "record_time": 1742377437.450732}
{"action": "update", "arg": {"instType": "SPOT", "channel": "books", "instId": "BTCUSDT"}, "data": [{"asks": [["83487.10", "0.057777"], ["83489.10", "0.152044"], ["83491.10", "0.400115"], ["83493.10", "1.052934"], ["83495.10", "2.770879"], ["83536.80", "4.747453"], ["83545.20", "3.925779"], ["83553.60", "4.108373"], ["83562.00", "4.656156"], ["83570.40", "4.290967"], ["83578.80", "4.382265"], ["83587.20", "4.564859"], ["83595.60", "5.660425"], ["83604.00", "4.017076"], ["83612.40", "5.112642"], ["83620.80", "4.930048"], ["83629.20", "5.203939"], ["83637.60", "4.838750"], ["83646.00", "5.477831"], ["83654.40", "4.199670"], ["83662.80", "5.295236"], ["83671.20", "5.569128"], ["83679.60", "5.386533"], ["83688.00", "4.473562"], ["83696.40", "5.021345"]], "bids": [["83445.00", "0.981459"], ["83423.50", "0.010367"], ["83421.50", "0.027281"], ["83419.50", "0.071794"], ["83417.50", "0.188931"], ["83415.50", "0.497187"], ["83413.50", "1.308386"], ["83411.50", "3.443120"], ["83394.00", "0.000122"], ["83369.80", "4.473562"], ["83361.40", "4.838750"], ["83353.00", "4.747453"], ["83344.60", "5.295236"], ["83336.20", "5.386533"], ["83327.80", "4.017076"], ["83319.40", "5.021345"], ["83311.00", "4.108373"], ["83302.60", "5.477831"], ["83294.20", "5.203939"], ["83285.80", "3.925779"], ["83277.40", "5.569128"], ["83269.00", "5.660425"], ["83260.60", "5.112642"], ["83252.20", "4.930048"], ["83243.80", "4.382265"], ["83235.40", "4.199670"], ["83227.00", "4.290967"], ["83218.60", "4.564859"], ["83210.20", "4.656156"]], "checksum": -2013676355, "ts": "1742377436784"}], "ts": 1742377436787, "record_time": 1742377437.686972}
{"action": "update", "arg": {"instType": "SPOT", "channel": "books", "instId": "BTCUSDT"}, "data": [{"asks": [["83445.01", "1.387583"], ["83477.10", "0.001474"], ["83479.10", "0.003879"], ["83481.10", "0.010208"], ["83483.10", "0.026863"], ["83485.10", "0.070693"], ["83487.10", "0.186035"], ["83489.10", "0.489566"], ["83491.10", "1.288330"], ["83493.10", "3.390343"], ["83495.10", "8.921955"], ["83495.20", "0.173580"], ["83496.40", "0.284580"], ["83497.50", "2.564400"], ["83500.29", "0"], ["83504.50", "1.469640"], ["83506.10", "0"], ["83536.80", "5.386533"], ["83545.20", "4.382265"], ["83553.60", "5.569128"], ["83562.00", "5.477831"], ["83570.40", "4.473562"], ["83578.80", "4.747453"], ["83587.20", "3.925779"], ["83595.60", "4.838750"], ["83604.00", "4.930048"], ["83612.40", "5.660425"], ["83620.80", "4.656156"], ["83629.20", "5.021345"], ["83637.60", "5.295236"], ["83646.00", "4.564859"], ["83654.40", "5.112642"], ["83662.80", "5.203939"], ["83671.20", "4.199670"], ["83679.60", "4.290967"], ["83688.00", "4.017076"], ["83696.40", "4.108373"], ["83772.73", "0.000008"]], "bids": [["83445.00", "0.981559"], ["83433.65", "0"], ["83425.50", "0.003832"], ["83423.50", "0.010136"], ["83421.50", "0.026534"], ["83419.50", "0.069825"], ["83417.50", "0.183750"], ["83415.50", "0.483554"], ["83414.87", "0"], ["83413.50", "1.272508"], ["83411.50", "3.348707"], ["83406.30", "0.840000"], ["83405.28", "0.020924"], ["83403.50", "0.009000"], ["83403.40", "0.120000"], ["83369.80", "4.382265"], ["83361.40", "5.477831"], ["83353.00", "4.199670"], ["83344.60", "5.569128"], ["83336.20", "5.112642"], ["83327.80", "4.473562"], ["83319.40", "3.925779"], ["83311.00", "4.656156"], ["83302.60", "4.017076"], ["83294.20", "4.564859"], ["83285.80", "5.203939"], ["83277.40", "5.295236"], ["83269.00", "5.021345"], ["83260.60", "4.930048"], ["83252.20", "4.838750"], ["83243.80", "4.290967"], ["83235.40", "4.108373"], ["83227.00", "4.747453"], ["83218.60", "5.386533"], ["83210.20", "5.660425"], ["82935.00", "0"]], "checksum": -622847875, "ts": "1742377436986"}], "ts": 1742377436989, "record_time": 1742377437.884016}
{"action": "update", "arg": {"instType": "SPOT", "channel": "books", "instId": "BTCUSDT"}, "data": [{"asks": [["83473.96", "0"], ["83485.09", "0.139778"], ["83487.00", "0"], ["83536.79", "0.507927"], ["83536.80", "5.477831"], ["83545.20", "4.838750"], ["83553.60", "5.660425"], ["83562.00", "4.108373"], ["83570.40", "4.564859"], ["83578.80", "5.295236"], ["83587.20", "4.199670"], ["83595.60", "5.021345"], ["83612.40", "5.569128"], ["83620.80", "4.017076"], ["83629.20", "4.473562"], ["83637.60", "4.382265"], ["83646.00", "4.656156"], ["83654.40", "3.925779"], ["83662.80", "4.747453"], ["83671.20", "4.290967"], ["83679.60", "5.112642"], ["83688.00", "5.203939"], ["83696.40", "5.386533"], ["83772.88", "0.000023"]], "bids": [["83443.19", "0.045560"], ["83443.12", "0"], ["83419.51", "0.167419"], ["83406.20", "0.007050"], ["83405.28", "0"], ["83403.20", "1.924110"], ["83403.10", "1.350000"], ["83396.87", "0.020924"], ["83369.80", "5.569128"], ["83361.40", "5.386533"], ["83353.00", "4.747453"], ["83344.60", "4.290967"], ["83336.20", "5.295236"], ["83327.80", "4.017076"], ["83319.40", "4.199670"], ["83311.00", "4.108373"], ["83302.60", "4.564859"], ["83294.20", "5.021345"], ["83285.80", "4.473562"], ["83277.40", "5.660425"], ["83269.00", "5.477831"], ["83260.60", "4.838750"], ["83252.20", "4.656156"], ["83243.80", "4.382265"], ["83235.40", "5.203939"], ["83227.00", "4.930048"], ["83218.60", "5.112642"], ["83210.20", "3.925779"], ["82937.50", "0"], ["82936.29", "0"]], "checksum": -1111084682, "ts": "1742377437187"}], "ts": 1742377437189, "record_time": 1742377438.086307}
{"action": "update", "arg": {"instType": "SPOT", "channel": "books", "instId": "BTCUSDT"}, "data": [{"asks": [["83471.66", "0.182524"], ["83477.10", "0.001678"], ["83479.10", "0.004416"], ["83481.10", "0.011622"], ["83483.10", "0.030583"], ["83485.10", "0.080483"], ["83487.10", "0.211798"], ["83489.10", "0.557362"], ["83491.10", "1.466743"], ["83493.10", "3.859849"], ["83495.10", "10.157497"], ["83495.60", "1.039290"], ["83496.40", "0"], ["83496.70", "0.014820"], ["83497.50", "0"], ["83499.20", "0.179760"], ["83500.70", "0.001598"], ["83503.60", "0.651150"], ["83504.80", "0.015000"], ["83536.80", "5.295236"], ["83545.20", "5.021345"], ["83553.60", "3.925779"], ["83562.00", "5.386533"], ["83570.40", "5.203939"], ["83578.80", "4.017076"], ["83587.20", "5.112642"], ["83595.60", "4.382265"], ["83604.00", "5.477831"], ["83612.40", "4.564859"], ["83620.80", "4.473562"], ["83629.20", "4.199670"], ["83637.60", "4.930048"], ["83646.00", "5.660425"], ["83654.40", "4.108373"], ["83671.20", "4.838750"], ["83679.60", "5.569128"], ["83688.00", "4.656156"], ["83696.40", "4.290967"], ["83772.73", "0"], ["83772.88", "0"]], "bids": [["83445.00", "0.772359"], ["83432.22", "0"], ["83423.50", "0.010284"], ["83421.50", "0.027062"], ["83419.50", "0.071216"], ["83417.50", "0.187411"], ["83415.50", "0.493187"], ["83413.50", "1.297862"], ["83411.50", "3.415425"], ["83395.00", "0.000161"], ["83369.80", "5.295236"], ["83361.40", "5.660425"], ["83353.00", "4.108373"], ["83344.60", "4.656156"], ["83336.20", "5.477831"], ["83327.80", "5.112642"], ["83319.40", "3.925779"], ["83311.00", "4.199670"], ["83302.60", "5.569128"], ["83294.20", "5.386533"], ["83285.80", "4.838750"], ["83277.40", "4.017076"], ["83269.00", "4.930048"], ["83260.60", "4.382265"], ["83252.20", "4.473562"], ["83243.80", "4.290967"], ["83235.40", "4.747453"], ["83227.00", "5.021345"], ["83218.60", "5.203939"], ["83210.20", "4.564859"], ["82937.50", "0.000012"]], "checksum": -1963254340, "ts": "1742377437394"}], "ts": 1742377437397, "record_time": 1742377438.28979}
{"action": "update", "arg": {"instType": "SPOT", "channel": "books", "instId": "BTCUSDT"}, "data": [{"asks": [["83495.60", "0.451470"], ["83503.60", "3.023430"], ["83504.50", "0.823410"], ["83505.40", "0"], ["83506.10", "0.252000"], ["83545.20", "5.203939"], ["83553.60", "4.108373"], ["83562.00", "4.473562"], ["83570.40", "3.925779"], ["83578.80", "5.477831"], ["83587.20", "4.382265"], ["83595.60", "4.290967"], ["83604.00", "4.656156"], ["83620.80", "5.021345"], ["83629.20", "4.838750"], ["83637.60", "4.199670"], ["83646.00", "4.017076"], ["83654.40", "5.569128"], ["83662.80", "4.930048"], ["83671.20", "5.112642"], ["83679.60", "5.660425"], ["83688.00", "5.386533"], ["83696.40", "4.747453"]], "bids": [["83443.19", "0"], ["83423.50", "0.010082"], ["83421.50", "0.026532"], ["83419.50", "0.069820"], ["83417.50", "0.183737"], ["83415.53", "0.176711"], ["83415.50", "0.483518"], ["83413.50", "1.272417"], ["83411.50", "3.348465"], ["83403.20", "0"], ["83403.10", "0"], ["83369.80", "5.112642"], ["83361.40", "4.838750"], ["83353.00", "4.199670"], ["83344.60", "4.382265"], ["83336.20", "3.925779"], ["83327.80", "4.930048"], ["83319.40", "5.569128"], ["83311.00", "4.473562"], ["83302.60", "5.295236"], ["83294.20", "5.477831"], ["83285.80", "4.290967"], ["83277.40", "5.203939"], ["83269.00", "5.021345"], ["83260.60", "4.564859"], ["83252.20", "4.017076"], ["83243.80", "4.656156"], ["83227.00", "5.660425"], ["83218.60", "4.108373"], ["83210.20", "5.386533"], ["82936.29", "0.000067"], ["82935.00", "0.000121"], ["82934.78", "0.000010"]], "checksum": -53104577, "ts": "1742377437607"}], "ts": 1742377437610, "record_time": 1742377438.51333}
{"action": "update", "arg": {"instType": "SPOT", "channel": "books", "instId": "BTCUSDT"}, "data": [{"asks": [["83493.10", "3.860096"], ["83495.10", "10.158148"], ["83502.70", "0.070620"], ["83506.10", "0"], ["83536.80", "5.203939"], ["83545.20", "4.199670"], ["83553.60", "5.569128"], ["83562.00", "4.017076"], ["83570.40", "5.477831"], ["83578.80", "4.564859"], ["83587.20", "5.112642"], ["83595.60", "5.660425"], ["83604.00", "5.386533"], ["83612.40", "5.295236"], ["83620.80", "4.382265"], ["83629.20", "3.925779"], ["83637.60", "4.930048"], ["83646.00", "4.747453"], ["83654.40", "4.290967"], ["83662.80", "4.473562"], ["83671.20", "5.021345"], ["83679.60", "4.838750"], ["83688.00", "4.108373"], ["83696.40", "4.656156"]], "bids": [["83443.25", "0.045560"], ["83415.50", "0.483304"], ["83413.50", "1.271851"], ["83411.50", "3.346977"], ["83369.80", "4.199670"], ["83361.40", "3.925779"], ["83353.00", "5.295236"], ["83344.60", "4.473562"], ["83336.20", "5.569128"], ["83327.80", "5.021345"], ["83319.40", "5.386533"], ["83311.00", "4.656156"], ["83302.60", "4.747453"], ["83294.20", "4.930048"], ["83285.80", "4.382265"], ["83277.40", "4.290967"], ["83269.00", "5.477831"], ["83260.60", "4.108373"], ["83252.20", "5.203939"], ["83243.80", "4.564859"], ["83235.40", "4.838750"], ["83218.60", "5.112642"], ["83210.20", "4.017076"], ["82934.78", "0"]], "checksum": 237794466, "ts": "1742377437827"}], "ts": 1742377437830, "record_time": 1742377439.776827}
{"action": "update", "arg": {"instType": "SPOT", "channel": "books", "instId": "BTCUSDT"}, "data": [{"asks": [["83489.10", "0.557179"], ["83491.10", "1.466262"], ["83493.10", "3.858584"], ["83495.10", "10.154168"], ["83495.60", "0.181290"], ["83500.30", "2.268270"], ["83545.20", "4.473562"], ["83553.60", "4.747453"], ["83562.00", "4.838750"], ["83570.40", "5.660425"], ["83578.80", "4.199670"], ["83587.20", "5.569128"], ["83595.60", "4.108373"], ["83612.40", "4.382265"], ["83620.80", "4.290967"], ["83629.20", "4.564859"], ["83637.60", "4.656156"], ["83646.00", "5.021345"], ["83654.40", "5.295236"], ["83662.80", "5.112642"], ["83671.20", "4.930048"], ["83679.60", "3.925779"], ["83688.00", "4.017076"], ["83696.40", "5.477831"]], "bids": [["83403.10", "1.350000"], ["83402.60", "0.240000"], ["83393.00", "0.000122"], ["83369.80", "5.569128"], ["83361.40", "4.747453"], ["83353.00", "4.473562"], ["83344.60", "4.290967"], ["83336.20", "4.199670"], ["83327.80", "4.838750"], ["83319.40", "5.203939"], ["83311.00", "5.295236"], ["83302.60", "5.112642"], ["83285.80", "4.656156"], ["83277.40", "4.017076"], ["83269.00", "5.660425"], ["83260.60", "4.564859"], ["83252.20", "5.477831"], ["83243.80", "4.382265"], ["83235.40", "4.108373"], ["83227.00", "3.925779"], ["83218.60", "5.021345"], ["83210.20", "5.386533"], ["82936.29", "0"], ["82935.00", "0"]], "checksum": 237794466, "ts": "1742377438027"}], "ts": 1742377438029, "record_time": 1742377439.778833}
{"action": "update", "arg": {"instType": "SPOT", "channel": "books", "instId": "BTCUSDT"}, "data": [{"asks": [["83479.09", "0.004631"], ["83502.70", "0"], ["83504.50", "0.553650"], ["83506.10", "0.252000"], ["83536.80", "5.477831"], ["83545.20", "5.112642"], ["83553.60", "5.386533"], ["83562.00", "5.203939"], ["83570.40", "4.930048"], ["83587.20", "4.108373"], ["83595.60", "5.295236"], ["83604.00", "4.838750"], ["83612.40", "4.017076"], ["83620.80", "4.382265"], ["83629.20", "4.290967"], ["83637.60", "4.747453"], ["83646.00", "4.564859"], ["83654.40", "5.021345"], ["83662.80", "5.569128"], ["83671.20", "3.925779"], ["83679.60", "5.660425"], ["83688.00", "4.473562"], ["83696.40", "4.656156"]], "bids": [["83445.00", "0.981559"], ["83443.31", "0.045560"], ["83443.25", "0"], ["83433.64", "0"], ["83410.00", "0.000283"], ["83408.00", "0.022650"], ["83407.30", "0.015000"], ["83402.50", "0.120000"], ["83361.40", "4.930048"], ["83353.00", "5.386533"], ["83344.60", "4.747453"], ["83336.20", "3.925779"], ["83327.80", "4.564859"], ["83319.40", "4.017076"], ["83311.00", "4.838750"], ["83302.60", "4.290967"], ["83294.20", "4.199670"], ["83285.80", "4.108373"], ["83277.40", "4.382265"], ["83269.00", "4.473562"], ["83260.60", "5.112642"], ["83243.80", "5.295236"], ["83235.40", "5.021345"], ["83227.00", "5.203939"], ["83218.60", "5.660425"], ["83210.20", "4.656156"], ["82937.50", "0"]], "checksum": -1172219334, "ts": "1742377438243"}], "ts": 1742377438247, "record_time": 1742377439.780152}
{"action": "update", "arg": {"instType": "SPOT", "channel": "books", "instId": "BTCUSDT"}, "data": [{"asks": [["83504.49", "0.307713"], ["83536.79", "0.023016"], ["83536.80", "3.925779"], ["83545.20", "4.838750"], ["83553.60", "4.564859"], ["83562.00", "4.473562"], ["83570.40", "5.112642"], ["83578.80", "4.017076"], ["83587.20", "5.203939"], ["83595.60", "4.290967"], ["83604.00", "4.747453"], ["83612.40", "4.930048"], ["83620.80", "4.656156"], ["83629.20", "5.660425"], ["83637.60", "4.199670"], ["83646.00", "5.386533"], ["83654.40", "4.382265"], ["83662.80", "5.021345"], ["83671.20", "5.569128"], ["83679.60", "5.295236"], ["83688.00", "4.108373"], ["83696.40", "5.477831"], ["83772.68", "0"]], "bids": [["83431.20", "0.111711"], ["83422.13", "0.006216"], ["83420.45", "0"], ["83369.80", "5.203939"], ["83361.40", "4.564859"], ["83353.00", "5.569128"], ["83344.60", "4.473562"], ["83336.20", "5.477831"], ["83327.80", "5.112642"], ["83319.40", "5.660425"], ["83311.00", "4.656156"], ["83302.60", "5.295236"], ["83294.20", "4.017076"], ["83285.80", "5.386533"], ["83277.40", "4.747453"], ["83269.00", "4.930048"], ["83260.60", "4.290967"], ["83252.20", "4.838750"], ["83243.80", "4.382265"], ["83235.40", "4.108373"], ["83227.00", "5.021345"], ["83218.60", "3.925779"], ["83210.20", "4.199670"], ["82937.59", "0"]], "checksum": -1171369958, "ts": "1742377438445"}], "ts": 1742377438448, "record_time": 1742377439.781655}
{"action": "update", "arg": {"instType": "SPOT", "channel": "books", "instId": "BTCUSDT"}, "data": [{"asks": [["83489.10", "0.557317"], ["83491.10", "1.466624"], ["83493.10", "3.859538"], ["83495.10", "10.156549"], ["83536.80", "4.108373"], ["83545.20", "5.660425"], ["83553.60", "5.477831"], ["83561.99", "0.174010"], ["83562.00", "4.564859"], ["83570.40", "4.747453"], ["83578.80", "4.199670"], ["83587.20", "4.017076"], ["83595.60", "5.112642"], ["83604.00", "4.838750"], ["83612.40", "5.021345"], ["83620.80", "3.925779"], ["83629.20", "5.569128"], ["83637.60", "4.382265"], ["83646.00", "4.930048"], ["83654.40", "4.290967"], ["83662.80", "4.473562"], ["83671.20", "5.386533"], ["83679.60", "4.656156"], ["83688.00", "5.295236"], ["83696.40", "5.203939"], ["83772.56", "0"]], "bids": [["83443.31", "0"], ["83394.00", "0.000283"], ["83369.80", "5.477831"], ["83361.40", "5.295236"], ["83353.00", "4.473562"], ["83344.60", "4.564859"], ["83336.20", "4.656156"], ["83327.80", "4.838750"], ["83319.40", "3.925779"], ["83311.00", "4.382265"], ["83302.60", "5.569128"], ["83294.20", "5.021345"], ["83285.80", "4.108373"], ["83277.40", "5.660425"], ["83269.00", "4.199670"], ["83260.60", "5.112642"], ["83252.20", "5.203939"], ["83243.80", "4.930048"], ["83235.40", "4.017076"], ["83227.00", "4.290967"], ["83218.60", "4.747453"], ["83210.20", "5.386533"], ["82937.59", "0.000423"]], "checksum": -463909859, "ts": "1742377438650"}], "ts": 1742377438653, "record_time": 1742377439.78316}
{"action": "update", "arg": {"instType": "SPOT", "channel": "books", "instId": "BTCUSDT"}, "data": [{"asks": [["83536.80", "3.925779"], ["83545.20", "5.203939"], ["83553.60", "5.295236"], ["83562.00", "4.199670"], ["83570.40", "5.112642"], ["83578.80", "5.021345"], ["83587.20", "4.108373"], ["83595.60", "4.656156"], ["83604.00", "4.747453"], ["83612.40", "5.477831"], ["83620.80", "5.660425"], ["83629.20", "4.838750"], ["83637.60", "5.569128"], ["83646.00", "5.386533"], ["83654.40", "4.564859"], ["83662.80", "4.930048"], ["83671.20", "4.290967"], ["83679.60", "4.382265"], ["83688.00", "4.017076"], ["83696.40", "4.473562"]], "bids": [["83443.38", "0.045560"], ["83423.50", "0.010279"], ["83421.50", "0.027051"], ["83419.50", "0.071185"], ["83417.50", "0.187329"], ["83415.50", "0.492973"], ["83413.50", "1.297296"], ["83411.50", "3.413937"], ["83394.00", "0.000161"], ["83369.80", "4.017076"], ["83361.40", "4.290967"], ["83353.00", "5.203939"], ["83344.60", "4.930048"], ["83336.20", "3.925779"], ["83327.80", "5.021345"], ["83319.40", "4.564859"], ["83311.00", "5.295236"], ["83302.60", "4.838750"], ["83294.20", "4.108373"], ["83285.80", "5.386533"], ["83277.40", "5.112642"], ["83260.60", "4.747453"], ["83252.20", "5.569128"], ["83243.80", "4.656156"], ["83235.40", "5.477831"], ["83227.00", "4.382265"], ["83218.60", "5.660425"], ["83210.20", "4.473562"], ["82937.59", "0"]], "checksum": -1573560387, "ts": "1742377438855"}], "ts": 1742377438858, "record_time": 1742377439.784589}
