{"action": "update", "arg": {"instType": "SPOT", "channel": "books", "instId": "BTCUSDT"}, "data": [{"asks": [["83918.03", "0.011900"], ["83924.43", "0.000357"], ["83927.29", "0.114012"], ["83928.38", "0"], ["83935.86", "0"], ["83940.41", "0"], ["83940.45", "0"], ["83941.51", "0"], ["83942.08", "0"], ["83942.26", "0"], ["83942.70", "0"], ["83942.92", "0"], ["83943.34", "0"], ["83943.70", "0"], ["83943.79", "0"], ["83944.00", "0"], ["83944.63", "0"], ["83944.93", "0"], ["83944.98", "0"], ["83945.01", "0"], ["83945.12", "0"], ["83945.23", "0"], ["83945.31", "0"], ["83945.90", "0"], ["83946.09", "0"], ["83946.13", "0"], ["83946.31", "0"], ["83947.15", "0.035971"], ["83947.26", "0.119905"], ["83947.72", "0"], ["83948.24", "0"], ["83948.31", "0"], ["83948.87", "0.035972"], ["83949.07", "0.017480"], ["83949.18", "0"], ["83949.31", "0.006357"], ["83949.41", "0.006357"], ["83949.72", "0.006357"], ["83950.54", "0"], ["83950.69", "0.006356"], ["83950.74", "0.006357"], ["83950.79", "0"], ["83950.81", "0.010995"], ["83950.97", "0.006357"], ["83951.08", "0.006357"], ["83951.68", "0.006357"], ["83951.70", "0.006357"], ["83951.74", "0.006357"], ["83952.27", "0.006357"], ["83952.28", "0.006357"], ["83952.47", "0.006357"], ["83952.75", "0.006357"], ["83952.87", "0"], ["83953.11", "0.016429"], ["83953.59", "0.119901"], ["83953.76", "0.006357"], ["83954.04", "0.016429"], ["83954.33", "0.006357"], ["83955.68", "0.010993"], ["83955.85", "0.009990"], ["83956.05", "0.119850"], ["83958.42", "0.015895"], ["83958.46", "0.013838"], ["83958.49", "0.119858"], ["83959.07", "0.009989"], ["83959.40", "0"], ["83960.54", "0.006356"], ["83961.40", "0"], ["83963.40", "0"], ["83965.40", "0"], ["83967.40", "0"], ["83967.70", "0.001020"], ["83969.40", "0"], ["83969.70", "0.001046"], ["83971.40", "0"], ["83971.57", "0.010000"], ["83971.70", "0.001042"], ["83973.40", "0"], ["83973.70", "0.001043"], ["83975.40", "0"], ["83975.70", "0.001004"], ["83977.40", "0"], ["83977.70", "0.001102"], ["83979.40", "0"], ["83979.50", "0"], ["83979.60", "0"], ["83979.70", "0.002900"], ["83980.00", "0"], ["83981.20", "0"], ["83981.70", "0.007632"], ["83982.60", "0"], ["83983.10", "0"], ["83983.60", "0"], ["83983.70", "0.020085"], ["83983.80", "0"], ["83984.00", "0"], ["83984.10", "0"], ["83984.29", "0.012979"], ["83985.20", "0"], ["83985.70", "0.052854"], ["83986.00", "0"], ["83986.60", "0"], ["83987.10", "0"], ["83987.70", "0.139091"], ["83988.00", "0"], ["83988.40", "0.001046"], ["83988.60", "0.001018"], ["83988.70", "0"], ["83989.60", "0.002250"], ["83989.70", "0.447630"], ["83990.00", "0"], ["83990.40", "0"], ["83991.10", "0"], ["83992.00", "0.082350"], ["83992.10", "0"], ["83992.30", "0"], ["83992.40", "0.009000"], ["83992.50", "0"], ["83992.70", "0.196350"], ["83993.00", "0"], ["83993.10", "0"], ["83993.50", "0"], ["83993.60", "0.021600"], ["83993.80", "0"], ["83994.00", "0"], ["83994.80", "0.066030"], ["83995.10", "0.010710"], ["83995.60", "1.528530"], ["83995.80", "0.887280"], ["83995.90", "1.688280"], ["83996.10", "0.009000"], ["83996.28", "0"], ["83996.60", "0.007770"], ["83997.60", "2.680320"], ["83998.10", "0.090000"], ["83998.70", "2.085600"], ["83998.80", "0.536220"], ["83999.20", "0.035730"], ["83999.90", "0.178680"], ["84000.10", "1.374930"], ["84001.10", "0.204000"], ["84002.00", "0.072180"], ["84013.80", "0.000179"], ["84021.40", "0"], ["84029.60", "3.993514"], ["84029.80", "0"], ["84038.00", "4.084276"], ["84038.20", "0"], ["84046.40", "5.173416"], ["84046.60", "0"], ["84054.80", "4.265799"], ["84055.00", "0"], ["84063.20", "5.445701"], ["84063.40", "0"], ["84071.60", "4.901131"], ["84071.80", "0"], ["84080.00", "5.354939"], ["84080.20", "0"], ["84088.40", "4.719607"], ["84088.60", "0"], ["84096.00", "0"], ["84096.80", "4.447322"], ["84097.00", "0"], ["84105.20", "5.627224"], ["84105.40", "0"], ["84113.60", "4.175037"], ["84113.80", "0.301368"], ["84122.00", "4.991892"], ["84122.20", "0"], ["84130.40", "4.628846"], ["84130.60", "0"], ["84138.80", "5.536462"], ["84139.00", "0"], ["84147.20", "5.082654"], ["84147.40", "0"], ["84155.60", "4.356561"], ["84155.80", "0"], ["84164.00", "5.264177"], ["84164.20", "0"], ["84172.40", "4.538084"], ["84172.60", "0"], ["84175.91", "0.209200"], ["84180.80", "4.810369"], ["84181.00", "0"], ["84189.20", "3.902752"], ["84341.01", "0.000008"], ["84342.11", "0.000051"], ["84342.63", "0.000009"], ["84342.70", "0.000423"]], "bids": [["83918.02", "0.625995"], ["83917.60", "0.011679"], ["83915.66", "0.006543"], ["83915.60", "0.030733"], ["83915.40", "0"], ["83913.60", "0.080877"], ["83913.40", "0"], ["83913.06", "0.764602"], ["83911.60", "0.212835"], ["83911.47", "0.006920"], ["83911.40", "0"], ["83909.60", "0.560091"], ["83909.40", "0"], ["83907.60", "1.473924"], ["83907.40", "0"], ["83906.86", "0.089673"], ["83906.14", "0.247543"], ["83905.73", "0.059590"], ["83905.60", "3.878749"], ["83905.40", "0"], ["83905.23", "0.083637"], ["83905.20", "0.016433"], ["83904.83", "0.017826"], ["83904.81", "0.015750"], ["83904.60", "0.018273"], ["83904.23", "0.005950"], ["83903.60", "10.207234"], ["83903.59", "0.028875"], ["83903.50", "0.001014"], ["83903.40", "0"], ["83903.23", "0.006572"], ["83903.14", "0.055637"], ["83903.00", "0.541050"], ["83902.84", "0.025199"], ["83902.60", "8.304420"], ["83902.57", "0.007141"], ["83902.51", "0.017124"], ["83902.39", "0.225049"], ["83902.23", "0.007347"], ["83902.00", "0.042690"], ["83901.83", "0.017114"], ["83901.76", "0.007956"], ["83901.74", "0.009010"], ["83901.40", "0"], ["83901.22", "0.017376"], ["83901.12", "0.051846"], ["83901.10", "0.537150"], ["83900.93", "0.008200"], ["83900.51", "0.008279"], ["83900.50", "0.071370"], ["83900.21", "0.008290"], ["83900.13", "0"], ["83900.09", "0.004036"], ["83900.00", "2.328480"], ["83899.78", "0.012674"], ["83899.77", "0.008029"], ["83899.67", "0.008532"], ["83899.64", "0.005601"], ["83899.63", "0.008482"], ["83899.62", "0.018549"], ["83899.60", "0.050880"], ["83899.40", "0"], ["83899.33", "0"], ["83898.85", "0.008074"], ["83898.60", "1.099230"], ["83898.40", "0.223055"], ["83898.22", "0"], ["83898.00", "0.042480"], ["83897.97", "0.268841"], ["83897.87", "0"], ["83897.80", "0.021166"], ["83897.48", "0.076244"], ["83897.40", "0"], ["83897.26", "0"], ["83897.22", "0.006316"], ["83897.21", "0.006599"], ["83897.20", "0.005946"], ["83897.19", "0"], ["83897.18", "0.009262"], ["83897.17", "0.009422"], ["83897.07", "0.010062"], ["83897.02", "0.008608"], ["83896.77", "0"], ["83896.50", "0"], ["83896.30", "0.150000"], ["83896.12", "0"], ["83896.00", "0.042300"], ["83895.92", "0.007828"], ["83895.91", "0.008263"], ["83895.90", "0.009326"], ["83895.88", "0.006978"], ["83895.82", "0.009803"], ["83895.74", "0.007389"], ["83895.62", "0"], ["83895.49", "0"], ["83895.47", "0"], ["83895.40", "1.414020"], ["83895.39", "0"], ["83895.30", "2.006310"], ["83895.25", "0"], ["83895.24", "0.012460"], ["83895.20", "0"], ["83894.90", "0"], ["83894.71", "0"], ["83894.60", "0.579090"], ["83894.41", "0"], ["83894.40", "0"], ["83894.00", "0.087300"], ["83893.78", "0"], ["83893.76", "0"], ["83893.50", "0.071400"], ["83893.40", "0.045000"], ["83893.17", "0"], ["83892.77", "0"], ["83892.59", "0.010362"], ["83892.58", "0.008933"], ["83892.51", "0"], ["83892.50", "0.445290"], ["83892.01", "0"], ["83891.60", "0"], ["83891.40", "0.306390"], ["83891.29", "0.008556"], ["83891.24", "0.005181"], ["83891.18", "0.008316"], ["83891.13", "0"], ["83891.11", "0"], ["83890.45", "0.259212"], ["83890.33", "0"], ["83890.08", "0.008778"], ["83890.00", "2.141970"], ["83889.90", "0"], ["83889.80", "0"], ["83889.66", "0.000878"], ["83889.53", "0"], ["83889.00", "0"], ["83888.90", "0"], ["83888.75", "0.005062"], ["83888.74", "0.004861"], ["83888.71", "0.008109"], ["83888.70", "0"], ["83888.56", "0.005612"], ["83888.30", "0"], ["83888.10", "0"], ["83888.00", "0"], ["83887.80", "0"], ["83887.70", "0"], ["83887.60", "0"], ["83887.58", "0"], ["83887.40", "0"], ["83887.10", "0"], ["83886.90", "0"], ["83885.47", "0"], ["83883.93", "0"], ["83883.61", "0.017480"], ["83877.21", "0"], ["83873.02", "0.007448"], ["83872.65", "0.008589"], ["83871.22", "0.007260"], ["83871.14", "0.007665"], ["83871.01", "0.007351"], ["83863.99", "0"], ["83861.70", "4.175037"], ["83853.40", "0"], ["83853.30", "4.265799"], ["83845.65", "0.000172"], ["83845.00", "0"], ["83844.90", "4.084276"], ["83836.60", "0"], ["83836.50", "4.810369"], ["83828.20", "0"], ["83828.10", "4.628846"], ["83827.83", "0"], ["83819.80", "0"], ["83819.70", "5.354939"], ["83811.40", "0"], ["83811.30", "4.901131"], ["83803.00", "0"], ["83802.90", "3.993514"], ["83794.60", "0"], ["83794.50", "4.719607"], ["83786.20", "0"], ["83786.10", "5.536462"], ["83777.80", "0"], ["83777.70", "4.447322"], ["83769.40", "0"], ["83769.30", "5.445701"], ["83761.00", "0"], ["83760.90", "5.627224"], ["83752.60", "0"], ["83752.50", "5.082654"], ["83744.20", "0"], ["83744.10", "5.173416"], ["83735.80", "0"], ["83735.70", "5.264177"], ["83727.40", "0"], ["83727.30", "4.991892"], ["83719.00", "0"], ["83718.90", "4.538084"], ["83710.60", "0"], ["83710.50", "4.356561"], ["83702.20", "0"], ["83702.10", "3.902752"], ["83693.80", "0"], ["83510.00", "0.000542"], ["83441.56", "0"], ["83440.00", "0"], ["83439.42", "0"], ["83439.33", "0"], ["83437.50", "0"], ["83437.10", "0"], ["83433.33", "0"], ["83433.12", "0"], ["83433.00", "0"], ["83432.57", "0"], ["83431.37", "0"], ["83430.00", "0"], ["83429.00", "0"], ["83428.57", "0"], ["83427.23", "0"], ["83425.93", "0"], ["83425.00", "0"], ["83423.73", "0"], ["83423.42", "0"], ["83421.99", "0"], ["83421.05", "0"], ["83420.00", "0"], ["83419.12", "0"], ["83417.42", "0"], ["83417.32", "0"], ["83417.31", "0"], ["83416.00", "0"], ["83415.96", "0"], ["83415.38", "0"], ["83415.25", "0"], ["83414.20", "0"]], "checksum": -333867194, "ts": "1742577146465"}], "ts": 1742577146470, "record_time": 1742577146.669148, "EXCHANGE": "BITGET"}
{"action": "update", "arg": {"instType": "SPOT", "channel": "books", "instId": "BTCUSDT"}, "data": [{"asks": [["83935.12", "0"], ["83941.92", "0.094410"], ["83946.97", "0.014348"], ["83961.80", "0.174659"], ["83985.70", "0.053116"], ["83987.70", "0.139779"], ["83989.70", "0.447870"], ["83991.30", "0.071730"], ["83991.90", "0.015000"], ["83992.00", "0.082530"], ["83992.30", "0.469380"], ["83993.20", "0.869550"], ["83994.40", "0.863820"], ["83995.60", "1.429500"], ["83995.90", "0.981270"], ["83997.60", "0"], ["83998.80", "0.859800"], ["84000.10", "0"], ["84001.10", "0"], ["84002.00", "0"], ["84038.00", "5.264177"], ["84046.40", "5.354939"], ["84054.80", "3.902752"], ["84063.20", "4.901131"], ["84071.60", "4.538084"], ["84080.00", "4.265799"], ["84088.40", "5.627224"], ["84096.80", "4.810369"], ["84105.20", "5.173416"], ["84113.60", "4.719607"], ["84122.00", "5.536462"], ["84130.40", "4.991892"], ["84138.80", "4.356561"], ["84147.20", "4.084276"], ["84155.60", "5.082654"], ["84164.00", "4.447322"], ["84172.40", "5.445701"], ["84180.80", "4.175037"], ["84189.20", "4.628846"], ["84342.63", "0"], ["84342.70", "0"]], "bids": [["83917.60", "0.013230"], ["83915.60", "0.034814"], ["83914.72", "0.391124"], ["83914.33", "0.009907"], ["83913.60", "0.091616"], ["83911.60", "0.241094"], ["83909.60", "0.634460"], ["83907.60", "1.669631"], ["83905.60", "4.393766"], ["83903.60", "11.562541"], ["83903.00", "0.540870"], ["83902.60", "5.664720"], ["83900.76", "0.007202"], ["83900.50", "0.071550"], ["83900.10", "0.451380"], ["83900.00", "2.381760"], ["83899.45", "0.007780"], ["83899.35", "0.009567"], ["83898.60", "0.692760"], ["83896.23", "0.557900"], ["83896.10", "0.120000"], ["83896.00", "0.162300"], ["83895.40", "1.396860"], ["83895.30", "0.523050"], ["83894.60", "0.410460"], ["83894.40", "0.240000"], ["83894.30", "0.240000"], ["83894.20", "0.120000"], ["83893.50", "0"], ["83892.33", "0.005128"], ["83890.30", "0"], ["83890.00", "0"], ["83861.70", "5.082654"], ["83853.30", "5.354939"], ["83836.50", "3.902752"], ["83828.10", "5.445701"], ["83819.70", "4.810369"], ["83811.30", "5.627224"], ["83802.90", "4.628846"], ["83794.50", "3.993514"], ["83786.10", "4.356561"], ["83777.70", "4.991892"], ["83769.30", "5.173416"], ["83760.90", "5.264177"], ["83752.50", "4.901131"], ["83744.10", "4.719607"], ["83735.70", "4.447322"], ["83727.30", "5.536462"], ["83718.90", "4.175037"], ["83710.50", "4.538084"], ["83702.10", "4.265799"], ["83445.30", "0"], ["83445.16", "0"], ["83444.44", "0"], ["83444.38", "0"], ["83444.27", "0"], ["83443.53", "0"], ["83442.50", "0"]], "checksum": 919387529, "ts": "1742577146668"}], "ts": 1742577146674, "record_time": 1742577146.867224, "EXCHANGE": "BITGET"}
{"action": "update", "arg": {"instType": "SPOT", "channel": "books", "instId": "BTCUSDT"}, "data": [{"asks": [["83918.03", "0.004180"], ["83926.16", "0.092735"], ["83985.70", "0.052975"], ["83987.70", "0.139407"], ["83992.30", "0.469200"], ["83992.70", "0"], ["83999.20", "0"], ["84000.10", "1.498590"], ["84029.60", "5.627224"], ["84038.00", "4.538084"], ["84046.40", "4.628846"], ["84054.80", "5.082654"], ["84063.20", "5.173416"], ["84071.60", "4.447322"], ["84080.00", "4.901131"], ["84088.40", "4.991892"], ["84096.80", "4.356561"], ["84105.20", "3.902752"], ["84113.60", "4.265799"], ["84122.00", "5.445701"], ["84130.40", "3.993514"], ["84138.80", "5.264177"], ["84147.20", "4.810369"], ["84155.60", "4.175037"], ["84164.00", "5.536462"], ["84172.40", "4.084276"], ["84180.80", "4.719607"], ["84189.20", "5.354939"], ["84310.00", "0.000079"], ["84342.11", "0"]], "bids": [["83918.02", "0.625075"], ["83911.47", "0.690362"], ["83905.60", "4.393624"], ["83903.60", "11.562169"], ["83903.12", "0.635367"], ["83903.00", "0.541050"], ["83902.60", "5.664900"], ["83900.30", "0.120180"], ["83900.10", "0.451560"], ["83900.00", "2.381580"], ["83899.50", "0.120000"], ["83898.70", "0.120000"], ["83898.60", "0.932760"], ["83896.23", "0"], ["83896.00", "0.042300"], ["83895.30", "0.643050"], ["83894.50", "0.120000"], ["83894.40", "1.114020"], ["83894.30", "0.120000"], ["83891.90", "0"], ["83891.40", "0"], ["83868.00", "0.000121"], ["83866.00", "0.000160"], ["83861.70", "4.991892"], ["83853.30", "4.265799"], ["83844.90", "4.175037"], ["83836.50", "5.264177"], ["83828.10", "4.628846"], ["83819.70", "4.447322"], ["83811.30", "5.445701"], ["83802.90", "5.627224"], ["83794.50", "4.084276"], ["83786.10", "5.173416"], ["83777.70", "4.538084"], ["83769.30", "5.536462"], ["83760.90", "4.901131"], ["83752.50", "3.993514"], ["83744.10", "4.810369"], ["83735.70", "4.356561"], ["83727.30", "5.082654"], ["83718.90", "4.719607"], ["83710.50", "5.354939"], ["83702.10", "3.902752"], ["83447.31", "0"], ["83447.17", "0"], ["83446.43", "0"]], "checksum": -171489496, "ts": "1742577146875"}], "ts": 1742577146877, "record_time": 1742577147.070739, "EXCHANGE": "BITGET"}
{"action": "update", "arg": {"instType": "SPOT", "channel": "books", "instId": "BTCUSDT"}, "data": [{"asks": [["83987.70", "0.139184"], ["83996.10", "0"], ["84000.30", "0.288000"], ["84029.60", "3.993514"], ["84038.00", "4.719607"], ["84046.40", "5.536462"], ["84054.80", "4.901131"], ["84063.20", "5.082654"], ["84071.60", "5.627224"], ["84080.00", "4.991892"], ["84088.40", "4.265799"], ["84096.80", "5.173416"], ["84105.20", "4.356561"], ["84113.60", "4.628846"], ["84122.00", "3.902752"], ["84130.40", "5.264177"], ["84138.80", "4.175037"], ["84147.20", "5.354939"], ["84155.60", "4.810369"], ["84164.00", "4.447322"], ["84172.40", "5.445701"], ["84180.80", "4.084276"], ["84189.20", "4.538084"]], "bids": [["83918.02", "1.207795"], ["83915.60", "0.034940"], ["83913.60", "0.091863"], ["83911.60", "0.241967"], ["83909.60", "0.636754"], ["83907.60", "1.675668"], ["83905.77", "0.537820"], ["83905.60", "4.409655"], ["83903.60", "11.604354"], ["83903.12", "0"], ["83899.60", "0"], ["83895.20", "0.009000"], ["83894.60", "0.693810"], ["83894.30", "0"], ["83894.20", "0"], ["83891.90", "0.217080"], ["83861.70", "4.175037"], ["83853.30", "4.628846"], ["83844.90", "4.719607"], ["83836.50", "5.627224"], ["83828.10", "5.445701"], ["83811.30", "4.538084"], ["83802.90", "5.536462"], ["83794.50", "5.264177"], ["83786.10", "3.902752"], ["83777.70", "5.354939"], ["83769.30", "4.901131"], ["83760.90", "4.991892"], ["83744.10", "5.082654"], ["83735.70", "4.084276"], ["83727.30", "5.173416"], ["83718.90", "4.356561"], ["83710.50", "4.810369"], ["83702.10", "4.265799"], ["83447.31", "0.000008"], ["83447.17", "0.000008"]], "checksum": 1969766112, "ts": "1742577147082"}], "ts": 1742577147086, "record_time": 1742577147.278863, "EXCHANGE": "BITGET"}
{"action": "update", "arg": {"instType": "SPOT", "channel": "books", "instId": "BTCUSDT"}, "data": [{"asks": [["83925.87", "0.092735"], ["83926.16", "0"], ["84000.30", "0.006570"], ["84029.60", "4.719607"], ["84038.00", "5.354939"], ["84046.40", "3.902752"], ["84054.80", "4.084276"], ["84063.20", "4.991892"], ["84071.60", "4.538084"], ["84080.00", "4.901131"], ["84088.40", "3.993514"], ["84096.80", "5.445701"], ["84113.60", "5.536462"], ["84122.00", "4.265799"], ["84130.40", "5.627224"], ["84138.80", "5.264177"], ["84147.20", "5.173416"], ["84155.60", "5.082654"], ["84172.40", "4.175037"], ["84180.80", "4.810369"], ["84189.20", "4.628846"]], "bids": [["83905.77", "1.081925"], ["83895.40", "1.377840"], ["83891.90", "0"], ["83861.70", "5.264177"], ["83853.30", "5.082654"], ["83844.90", "3.993514"], ["83836.50", "5.173416"], ["83828.10", "4.175037"], ["83819.70", "3.902752"], ["83811.30", "4.356561"], ["83802.90", "5.445701"], ["83794.50", "5.354939"], ["83786.10", "5.536462"], ["83777.70", "4.447322"], ["83769.30", "4.265799"], ["83752.50", "4.901131"], ["83744.10", "5.627224"], ["83735.70", "4.628846"], ["83727.30", "4.719607"], ["83718.90", "4.538084"], ["83702.10", "4.084276"], ["83446.43", "0.000016"]], "checksum": -1805873816, "ts": "1742577147296"}], "ts": 1742577147300, "record_time": 1742577147.492509, "EXCHANGE": "BITGET"}
{"action": "update", "arg": {"instType": "SPOT", "channel": "books", "instId": "BTCUSDT"}, "data": [{"asks": [["83987.70", "0.139500"], ["83993.20", "0"], ["83994.40", "1.661010"], ["83994.70", "0.175980"], ["83994.80", "0.175830"], ["84000.30", "0.005100"], ["84038.00", "3.902752"], ["84046.40", "4.084276"], ["84054.80", "5.627224"], ["84063.20", "5.173416"], ["84071.60", "5.354939"], ["84080.00", "5.264177"], ["84088.40", "4.628846"], ["84096.80", "5.082654"], ["84105.20", "5.536462"], ["84113.60", "4.265799"], ["84122.00", "4.810369"], ["84130.40", "4.447322"], ["84138.80", "5.445701"], ["84147.20", "4.991892"], ["84155.60", "4.175037"], ["84164.00", "4.538084"], ["84172.40", "4.356561"], ["84180.80", "4.901131"], ["84189.20", "3.993514"]], "bids": [["83918.02", "1.206155"], ["83917.60", "0.015692"], ["83915.60", "0.041296"], ["83913.60", "0.108673"], ["83911.60", "0.285982"], ["83909.60", "0.752584"], ["83907.60", "1.980485"], ["83905.60", "5.211802"], ["83903.60", "13.715268"], ["83902.60", "4.235400"], ["83900.30", "0.247890"], ["83892.50", "0"], ["83867.00", "0"], ["83853.30", "5.173416"], ["83844.90", "4.719607"], ["83836.50", "4.175037"], ["83828.10", "4.265799"], ["83819.70", "5.082654"], ["83802.90", "4.628846"], ["83794.50", "4.447322"], ["83786.10", "5.627224"], ["83777.70", "4.538084"], ["83769.30", "4.084276"], ["83760.90", "3.902752"], ["83752.50", "5.536462"], ["83744.10", "4.901131"], ["83735.70", "4.810369"], ["83727.30", "5.445701"], ["83718.90", "5.354939"], ["83710.50", "4.991892"], ["83702.10", "3.993514"], ["83445.30", "0.000011"], ["83445.16", "0.000054"]], "checksum": 585502746, "ts": "1742577147500"}], "ts": 1742577147504, "record_time": 1742577147.697664, "EXCHANGE": "BITGET"}
{"action": "update", "arg": {"instType": "SPOT", "channel": "books", "instId": "BTCUSDT"}, "data": [{"asks": [["83961.80", "0"], ["83985.70", "0.052657"], ["83987.70", "0.138570"], ["83991.90", "0"], ["84029.60", "4.175037"], ["84046.40", "5.445701"], ["84054.80", "4.991892"], ["84063.20", "4.084276"], ["84071.60", "3.993514"], ["84080.00", "5.627224"], ["84088.40", "4.356561"], ["84096.80", "4.265799"], ["84104.00", "0.001184"], ["84113.60", "4.538084"], ["84122.00", "4.628846"], ["84130.40", "4.901131"], ["84138.80", "5.173416"], ["84147.20", "5.354939"], ["84155.60", "4.447322"], ["84164.00", "4.719607"], ["84172.40", "5.082654"], ["84180.80", "4.810369"], ["84189.20", "5.264177"], ["84342.11", "0.000051"]], "bids": [["83918.02", "0.935735"], ["83900.00", "2.381400"], ["83867.00", "0.000121"], ["83861.70", "4.810369"], ["83853.30", "4.719607"], ["83844.90", "5.627224"], ["83836.50", "4.991892"], ["83828.10", "5.445701"], ["83819.70", "5.173416"], ["83811.30", "4.538084"], ["83786.10", "4.901131"], ["83777.70", "4.356561"], ["83769.30", "4.265799"], ["83760.90", "5.536462"], ["83752.50", "4.084276"], ["83744.10", "3.993514"], ["83735.70", "5.264177"], ["83727.30", "5.082654"], ["83710.50", "3.902752"], ["83702.10", "4.175037"], ["83445.16", "0"]], "checksum": -448691440, "ts": "1742577147713"}], "ts": 1742577147717, "record_time": 1742577147.909588, "EXCHANGE": "BITGET"}
{"action": "update", "arg": {"instType": "SPOT", "channel": "books", "instId": "BTCUSDT"}, "data": [{"asks": [["83925.54", "0.092761"], ["83925.87", "0"], ["83941.93", "0"], ["83955.86", "0"], ["83966.14", "0.182470"], ["83978.36", "0"], ["83979.78", "0"], ["83984.59", "0.001598"], ["83998.80", "0.393930"], ["84000.30", "0.293100"], ["84029.60", "4.084276"], ["84038.00", "5.173416"], ["84046.40", "5.264177"], ["84054.80", "4.265799"], ["84063.20", "4.810369"], ["84071.60", "4.991892"], ["84080.00", "4.628846"], ["84088.40", "5.536462"], ["84096.80", "4.538084"], ["84105.20", "3.902752"], ["84113.60", "4.447322"], ["84122.00", "4.356561"], ["84130.40", "5.354939"], ["84138.80", "5.082654"], ["84147.20", "3.993514"], ["84155.60", "4.901131"], ["84164.00", "5.627224"], ["84172.40", "4.175037"], ["84180.80", "4.719607"], ["84189.20", "5.445701"], ["84342.63", "0.000009"], ["84342.70", "0.000423"]], "bids": [["83918.02", "1.206155"], ["83917.60", "0.016124"], ["83915.60", "0.042430"], ["83913.60", "0.111660"], ["83913.40", "0.204856"], ["83911.60", "0.293841"], ["83909.60", "0.773266"], ["83907.60", "2.034911"], ["83905.60", "5.355028"], ["83903.60", "14.092178"], ["83893.00", "0"], ["83885.37", "0"], ["83884.00", "0.207210"], ["83870.62", "0.001174"], ["83868.25", "0"], ["83865.81", "0"], ["83861.70", "5.536462"], ["83853.30", "5.082654"], ["83844.90", "4.991892"], ["83836.50", "4.719607"], ["83828.10", "5.354939"], ["83819.70", "5.445701"], ["83811.30", "5.627224"], ["83802.90", "3.993514"], ["83794.50", "4.265799"], ["83786.10", "4.084276"], ["83777.70", "4.628846"], ["83769.30", "5.264177"], ["83760.90", "4.901131"], ["83752.50", "3.902752"], ["83744.10", "4.447322"], ["83735.70", "4.810369"], ["83727.30", "4.175037"], ["83718.90", "4.538084"], ["83710.50", "5.173416"], ["83702.10", "4.356561"], ["83445.16", "0.000054"]], "checksum": 677207733, "ts": "1742577147916"}], "ts": 1742577147920, "record_time": 1742577148.125689, "EXCHANGE": "BITGET"}
{"action": "update", "arg": {"instType": "SPOT", "channel": "books", "instId": "BTCUSDT"}, "data": [{"asks": [["83927.29", "0"], ["83931.44", "0.114005"], ["83941.92", "0"], ["83952.09", "0.314626"], ["83963.50", "0.010988"], ["83986.35", "0.001598"], ["83992.30", "0.469380"], ["83992.50", "1.050270"], ["83994.40", "0.797190"], ["83995.90", "0.605340"], ["83998.10", "0"], ["83998.70", "1.429500"], ["84000.30", "0.323730"], ["84000.60", "0.099600"], ["84029.60", "5.354939"], ["84038.00", "4.175037"], ["84046.40", "4.628846"], ["84054.80", "4.356561"], ["84063.20", "4.447322"], ["84071.60", "4.084276"], ["84080.00", "3.902752"], ["84088.40", "4.810369"], ["84096.80", "4.901131"], ["84105.20", "5.173416"], ["84113.60", "5.627224"], ["84122.00", "4.719607"], ["84130.40", "5.445701"], ["84138.80", "3.993514"], ["84147.20", "5.536462"], ["84155.60", "4.538084"], ["84164.00", "4.991892"], ["84172.40", "5.082654"], ["84180.80", "5.264177"], ["84189.20", "4.265799"], ["84342.11", "0"], ["84342.63", "0"], ["84342.70", "0"]], "bids": [["83918.02", "0.935390"], ["83917.60", "0.016314"], ["83915.60", "0.042932"], ["83913.60", "0.112980"], ["83911.60", "0.297314"], ["83909.60", "0.782407"], ["83907.60", "2.058965"], ["83905.60", "5.418329"], ["83903.60", "14.258574"], ["83902.70", "0.481230"], ["83902.60", "4.234560"], ["83902.00", "0.042480"], ["83900.30", "0.248070"], ["83900.00", "2.381040"], ["83894.60", "0.690240"], ["83894.00", "0.042300"], ["83893.90", "0.003600"], ["83893.40", "0"], ["83893.00", "0.056465"], ["83892.60", "0"], ["83876.23", "0.007360"], ["83868.00", "0.000281"], ["83861.70", "4.810369"], ["83853.30", "5.627224"], ["83844.90", "4.084276"], ["83836.50", "4.356561"], ["83828.10", "4.175037"], ["83819.70", "5.354939"], ["83811.30", "5.082654"], ["83794.50", "4.628846"], ["83786.10", "5.264177"], ["83777.70", "3.902752"], ["83769.30", "4.265799"], ["83752.50", "5.445701"], ["83744.10", "4.719607"], ["83735.70", "5.173416"], ["83727.30", "4.538084"], ["83718.90", "4.447322"], ["83710.50", "4.991892"], ["83702.10", "5.536462"], ["83445.16", "0"]], "checksum": 1088435126, "ts": "1742577148116"}], "ts": 1742577148118, "record_time": 1742577148.311255, "EXCHANGE": "BITGET"}
{"action": "update", "arg": {"instType": "SPOT", "channel": "books", "instId": "BTCUSDT"}, "data": [{"asks": [["83918.03", "0.010080"], ["83925.54", "0"], ["83971.57", "0"], ["83990.70", "0.470820"], ["83991.20", "0.876960"], ["83991.90", "0.015000"], ["83992.00", "0.082350"], ["83992.30", "0"], ["83992.50", "0"], ["83994.40", "0.538050"], ["84000.70", "2.359410"], ["84029.60", "5.173416"], ["84038.00", "3.902752"], ["84046.40", "5.445701"], ["84063.20", "4.719607"], ["84071.60", "5.536462"], ["84080.00", "5.354939"], ["84088.40", "5.627224"], ["84096.80", "3.993514"], ["84105.20", "4.084276"], ["84113.60", "5.264177"], ["84122.00", "4.901131"], ["84130.40", "4.810369"], ["84138.80", "4.628846"], ["84147.20", "4.538084"], ["84155.60", "4.447322"], ["84164.00", "5.082654"], ["84172.40", "4.175037"], ["84180.80", "4.991892"]], "bids": [["83918.02", "1.156193"], ["83911.60", "0.297557"], ["83909.60", "0.783044"], ["83909.40", "0.024669"], ["83907.60", "2.060641"], ["83905.60", "5.422739"], ["83903.60", "14.270366"], ["83861.70", "5.354939"], ["83853.30", "4.084276"], ["83844.90", "4.810369"], ["83836.50", "4.265799"], ["83828.10", "3.993514"], ["83819.70", "3.902752"], ["83811.30", "5.627224"], ["83802.90", "4.447322"], ["83794.50", "5.264177"], ["83786.10", "4.991892"], ["83777.70", "4.901131"], ["83769.30", "5.173416"], ["83760.90", "5.082654"], ["83752.50", "4.356561"], ["83744.10", "4.538084"], ["83735.70", "4.719607"], ["83727.30", "4.175037"], ["83718.90", "4.628846"], ["83710.50", "5.536462"], ["83702.10", "5.445701"], ["83445.30", "0"]], "checksum": 2045992264, "ts": "1742577148324"}], "ts": 1742577148328, "record_time": 1742577148.527785, "EXCHANGE": "BITGET"}
{"action": "update", "arg": {"instType": "SPOT", "channel": "books", "instId": "BTCUSDT"}, "data": [{"asks": [["83918.03", "0.280500"], ["83925.27", "0.092767"], ["83973.70", "0.002507"], ["83975.70", "0.006597"], ["83977.70", "0.017361"], ["83979.70", "0.045685"], ["83981.70", "0.120225"], ["83983.70", "0.316381"], ["83985.70", "0.832582"], ["83987.70", "2.191006"], ["83988.40", "0"], ["83989.10", "0.939870"], ["83989.50", "0.275610"], ["83989.60", "0.001035"], ["83989.70", "1.008030"], ["83990.70", "0"], ["83991.20", "0"], ["83994.40", "0.563910"], ["83994.70", "0"], ["83994.80", "0"], ["83995.50", "2.359560"], ["83995.90", "0.934650"], ["83996.10", "1.350000"], ["84000.60", "0"], ["84000.70", "0"], ["84029.60", "4.991892"], ["84038.00", "5.445701"], ["84046.40", "4.901131"], ["84054.80", "4.538084"], ["84063.20", "4.447322"], ["84071.60", "4.175037"], ["84080.00", "4.628846"], ["84088.40", "4.265799"], ["84096.80", "5.082654"], ["84105.20", "3.993514"], ["84122.00", "5.173416"], ["84130.40", "4.356561"], ["84138.80", "5.354939"], ["84147.20", "4.719607"], ["84155.60", "5.536462"], ["84164.00", "3.902752"], ["84172.40", "4.810369"], ["84180.80", "5.627224"], ["84189.20", "4.084276"], ["84342.11", "0.000051"], ["84342.63", "0.000009"]], "bids": [["83917.60", "0.006248"], ["83915.60", "0.016443"], ["83913.60", "0.043271"], ["83911.60", "0.113871"], ["83909.60", "0.299661"], ["83909.40", "0"], ["83907.60", "0.788582"], ["83905.60", "2.075214"], ["83903.60", "5.461090"], ["83903.40", "0.001014"], ["83903.00", "0.001017"], ["83902.70", "0.480390"], ["83902.60", "0.913830"], ["83901.10", "0"], ["83900.30", "0.247890"], ["83900.10", "0.451380"], ["83900.00", "0.830430"], ["83898.70", "0.298680"], ["83898.26", "0.024669"], ["83897.40", "0.612210"], ["83897.22", "0.031264"], ["83896.30", "0"], ["83895.40", "1.365180"], ["83895.30", "0.222210"], ["83894.00", "0"], ["83893.90", "0"], ["83868.00", "0.000160"], ["83861.70", "4.265799"], ["83853.30", "4.991892"], ["83844.90", "5.627224"], ["83836.50", "4.901131"], ["83828.10", "5.536462"], ["83819.70", "5.354939"], ["83811.30", "5.173416"], ["83802.90", "3.993514"], ["83786.10", "4.538084"], ["83777.70", "4.084276"], ["83769.30", "4.356561"], ["83760.90", "3.902752"], ["83752.50", "4.719607"], ["83744.10", "4.175037"], ["83735.70", "5.445701"], ["83727.30", "4.810369"], ["83710.50", "4.447322"], ["83702.10", "5.082654"], ["83445.30", "0.000011"], ["83445.16", "0.000054"]], "checksum": 658688941, "ts": "1742577148540"}], "ts": 1742577148544, "record_time": 1742577148.738752, "EXCHANGE": "BITGET"}
{"action": "update", "arg": {"instType": "SPOT", "channel": "books", "instId": "BTCUSDT"}, "data": [{"asks": [["83925.26", "0.027830"], ["83926.43", "0.209200"], ["83967.96", "0.010000"], ["83971.70", "0.001176"], ["83973.70", "0.003095"], ["83975.70", "0.008145"], ["83977.70", "0.021435"], ["83979.70", "0.056408"], ["83981.70", "0.148441"], ["83983.70", "0.390862"], ["83985.70", "1.028585"], ["83987.70", "2.706802"], ["83989.10", "0.324930"], ["83989.40", "0.001021"], ["83989.50", "0.558390"], ["83989.60", "0"], ["83989.70", "0.447210"], ["83991.90", "0.030000"], ["83994.40", "1.098960"], ["83995.40", "0.250620"], ["83996.40", "0.465870"], ["84000.10", "0.837900"], ["84000.30", "0.035730"], ["84029.60", "4.901131"], ["84038.00", "4.810369"], ["84046.40", "4.084276"], ["84054.80", "5.536462"], ["84063.20", "3.902752"], ["84071.60", "4.447322"], ["84080.00", "5.082654"], ["84088.40", "4.538084"], ["84096.80", "5.627224"], ["84113.60", "5.173416"], ["84122.00", "4.628846"], ["84130.40", "5.445701"], ["84155.60", "4.356561"], ["84164.00", "5.264177"], ["84172.40", "4.265799"], ["84180.80", "4.991892"], ["84189.20", "4.175037"], ["84340.72", "0"], ["84341.00", "0"], ["84341.01", "0"], ["84342.11", "0"], ["84342.63", "0"]], "bids": [["83917.60", "0.006049"], ["83915.60", "0.015919"], ["83913.60", "0.041892"], ["83911.60", "0.110241"], ["83911.47", "0"], ["83909.60", "0.290107"], ["83907.60", "0.763278"], ["83905.60", "2.008626"], ["83903.60", "5.285860"], ["83902.60", "0.717090"], ["83902.10", "0.266880"], ["83901.10", "0.029280"], ["83900.30", "0.120000"], ["83900.10", "0"], ["83897.22", "0.006316"], ["83866.00", "0"], ["83861.70", "4.628846"], ["83853.30", "5.082654"], ["83844.90", "4.991892"], ["83836.50", "4.810369"], ["83828.10", "5.627224"], ["83819.70", "4.538084"], ["83811.30", "4.175037"], ["83802.90", "5.445701"], ["83794.50", "4.719607"], ["83786.10", "4.356561"], ["83777.70", "5.536462"], ["83769.30", "3.993514"], ["83760.90", "4.084276"], ["83752.50", "3.902752"], ["83744.10", "4.447322"], ["83735.70", "5.264177"], ["83727.30", "5.173416"], ["83718.90", "4.265799"], ["83710.50", "4.901131"], ["83702.10", "5.354939"], ["83444.44", "0.000105"]], "checksum": -1543929724, "ts": "1742577148749"}], "ts": 1742577148756, "record_time": 1742577148.950095, "EXCHANGE": "BITGET"}
{"action": "update", "arg": {"instType": "SPOT", "channel": "books", "instId": "BTCUSDT"}, "data": [{"asks": [["83918.03", "0.814700"], ["83925.01", "0.092767"], ["83925.26", "0.087111"], ["83925.27", "0"], ["83937.53", "0.013838"], ["83958.46", "0"], ["83969.70", "0.001404"], ["83971.70", "0.003694"], ["83973.70", "0.009722"], ["83975.70", "0.025583"], ["83977.70", "0.067325"], ["83979.70", "0.177170"], ["83981.70", "0.466427"], ["83983.70", "1.227439"], ["83985.70", "3.230105"], ["83987.70", "8.500274"], ["83989.40", "0.033240"], ["83994.40", "0.563910"], ["83995.20", "0.492360"], ["83995.40", "0.791160"], ["83995.50", "0"], ["83996.40", "0"], ["84000.10", "1.492020"], ["84000.30", "0.323730"], ["84029.60", "5.627224"], ["84038.00", "5.445701"], ["84046.40", "5.264177"], ["84054.80", "4.538084"], ["84063.20", "4.991892"], ["84071.60", "5.173416"], ["84080.00", "3.993514"], ["84088.40", "5.354939"], ["84096.80", "4.356561"], ["84105.20", "5.536462"], ["84113.60", "4.628846"], ["84122.00", "4.719607"], ["84130.40", "4.810369"], ["84138.80", "4.901131"], ["84147.20", "4.175037"], ["84155.60", "5.082654"], ["84164.00", "4.084276"], ["84172.40", "3.902752"], ["84180.80", "4.265799"], ["84189.20", "4.447322"], ["84273.18", "0"], ["84281.44", "1.611332"], ["84340.72", "0.000066"]], "bids": [["83918.02", "1.142355"], ["83917.60", "0.002308"], ["83915.60", "0.006072"], ["83913.60", "0.015981"], ["83911.60", "0.041826"], ["83910.51", "0.013838"], ["83909.61", "0.316016"], ["83909.60", "0.110070"], ["83907.60", "0.289657"], ["83905.60", "0.762255"], ["83903.60", "2.005936"], ["83902.70", "0"], ["83902.60", "0.005460"], ["83902.10", "0"], ["83902.00", "0.042510"], ["83901.10", "0"], ["83901.00", "0.028290"], ["83900.50", "0.132150"], ["83900.40", "0.120210"], ["83900.10", "0.240000"], ["83900.00", "0.593130"], ["83899.70", "0.160920"], ["83899.20", "0.159150"], ["83898.70", "0.120000"], ["83898.60", "1.403610"], ["83898.26", "0"], ["83898.10", "0.081420"], ["83898.00", "0.162480"], ["83897.40", "0"], ["83896.90", "0.030000"], ["83896.80", "0.478530"], ["83896.30", "0.030000"], ["83895.60", "1.429500"], ["83895.30", "0.120000"], ["83895.20", "0"], ["83895.00", "0"], ["83894.60", "0"], ["83894.50", "0"], ["83894.40", "0"], ["83885.18", "0.024669"], ["83878.53", "0.024948"], ["83861.70", "4.810369"], ["83853.30", "4.084276"], ["83844.90", "5.264177"], ["83836.50", "5.354939"], ["83828.10", "4.991892"], ["83819.70", "5.536462"], ["83811.30", "4.538084"], ["83802.90", "4.719607"], ["83794.50", "4.356561"], ["83786.10", "4.265799"], ["83777.70", "5.445701"], ["83769.30", "3.902752"], ["83760.90", "5.627224"], ["83752.50", "5.173416"], ["83744.10", "5.082654"], ["83735.70", "4.628846"], ["83727.30", "4.175037"], ["83718.90", "4.447322"], ["83702.10", "3.993514"], ["83609.87", "1.706667"], ["83601.67", "0"], ["83446.43", "0"], ["83445.30", "0"], ["83445.16", "0"], ["83444.44", "0"]], "checksum": 399111570, "ts": "1742577148955"}], "ts": 1742577148958, "record_time": 1742577149.155929, "EXCHANGE": "BITGET"}
{"action": "update", "arg": {"instType": "SPOT", "channel": "books", "instId": "BTCUSDT"}, "data": [{"asks": [["83925.26", "0.027830"], ["83927.45", "0.114004"], ["83931.44", "0"], ["83937.53", "0"], ["83939.49", "0.013838"], ["83946.97", "0"], ["83979.70", "0.177278"], ["83983.70", "1.227684"], ["83985.70", "3.230747"], ["83987.70", "8.501967"], ["83988.90", "0.001048"], ["83989.00", "2.359740"], ["83989.10", "1.000890"], ["83989.40", "0.035730"], ["83989.70", "0.447030"], ["83991.70", "0.070620"], ["83991.90", "0.015000"], ["83994.40", "0.776160"], ["83998.30", "0.012450"], ["84000.30", "0"], ["84029.60", "4.356561"], ["84038.00", "4.175037"], ["84046.40", "5.173416"], ["84054.80", "5.264177"], ["84063.20", "5.536462"], ["84071.60", "3.993514"], ["84080.00", "5.354939"], ["84088.40", "5.082654"], ["84096.80", "5.627224"], ["84105.20", "4.538084"], ["84113.60", "4.991892"], ["84122.00", "4.628846"], ["84130.40", "4.084276"], ["84138.80", "3.902752"], ["84147.20", "4.447322"], ["84155.60", "5.445701"], ["84164.00", "4.265799"], ["84172.40", "4.901131"], ["84180.80", "4.719607"], ["84189.20", "4.810369"], ["84340.72", "0"]], "bids": [["83917.60", "0.002285"], ["83915.67", "0"], ["83915.60", "0.006013"], ["83913.60", "0.015824"], ["83911.60", "0.041642"], ["83909.61", "0.119918"], ["83909.60", "0.109585"], ["83907.60", "0.288139"], ["83905.60", "0.758262"], ["83903.60", "1.995427"], ["83902.00", "0.042690"], ["83901.00", "0"], ["83900.30", "0"], ["83899.50", "0"], ["83898.70", "0"], ["83898.60", "0.015000"], ["83896.10", "0"], ["83895.60", "2.303190"], ["83895.40", "0.015180"], ["83895.30", "0.102210"], ["83895.20", "0.009000"], ["83895.00", "0.006060"], ["83894.60", "0.963660"], ["83894.40", "0.874020"], ["83894.20", "0.120000"], ["83891.13", "0.024948"], ["83878.53", "0"], ["83861.70", "4.447322"], ["83853.30", "3.993514"], ["83844.90", "4.901131"], ["83836.50", "4.265799"], ["83828.10", "5.082654"], ["83819.70", "4.538084"], ["83811.30", "5.445701"], ["83794.50", "4.175037"], ["83786.10", "5.536462"], ["83777.70", "4.991892"], ["83769.30", "5.627224"], ["83760.90", "4.084276"], ["83752.50", "4.810369"], ["83744.10", "5.354939"], ["83735.70", "5.264177"], ["83727.30", "4.628846"], ["83718.90", "4.356561"], ["83710.50", "5.173416"], ["83702.10", "3.902752"], ["83446.43", "0.000016"]], "checksum": -824901370, "ts": "1742577149158"}], "ts": 1742577149160, "record_time": 1742577149.353148, "EXCHANGE": "BITGET"}
{"action": "update", "arg": {"instType": "SPOT", "channel": "books", "instId": "BTCUSDT"}, "data": [{"asks": [["83925.01", "0"], ["83925.26", "0.093482"], ["83937.55", "0.013566"], ["83939.49", "0"], ["83950.53", "0.191219"], ["83951.49", "0.013838"], ["83975.70", "0.025739"], ["83977.70", "0.067733"], ["83979.70", "0.178244"], ["83981.70", "0.469063"], ["83983.70", "1.234377"], ["83985.70", "3.248361"], ["83987.70", "8.548318"], ["83988.90", "1.043760"], ["83989.10", "0.001029"], ["83997.70", "0.027660"], ["83998.30", "0"], ["83998.40", "0.012660"], ["84000.10", "0"], ["84029.60", "3.993514"], ["84038.00", "5.536462"], ["84046.40", "4.265799"], ["84054.80", "4.901131"], ["84063.20", "5.354939"], ["84071.60", "4.719607"], ["84080.00", "4.175037"], ["84088.40", "5.264177"], ["84096.80", "4.810369"], ["84105.20", "5.627224"], ["84113.60", "4.628846"], ["84122.00", "5.445701"], ["84130.40", "5.082654"], ["84147.20", "4.538084"], ["84155.60", "4.084276"], ["84164.00", "4.447322"], ["84172.40", "4.356561"], ["84180.80", "4.991892"], ["84189.20", "5.173416"]], "bids": [["83918.02", "1.270197"], ["83917.60", "0.002406"], ["83915.60", "0.006332"], ["83913.60", "0.016664"], ["83911.60", "0.043851"], ["83910.51", "0"], ["83909.60", "0.115398"], ["83907.60", "0.303680"], ["83905.60", "0.799158"], ["83903.60", "2.103046"], ["83901.84", "0.487225"], ["83900.00", "0.113670"], ["83899.80", "0.022620"], ["83898.00", "0.042480"], ["83897.49", "0.083219"], ["83895.60", "1.934190"], ["83895.00", "0.126060"], ["83894.10", "0.168630"], ["83867.00", "0.000281"], ["83866.00", "0.000121"], ["83861.70", "5.082654"], ["83853.30", "4.447322"], ["83844.90", "5.445701"], ["83836.50", "4.719607"], ["83828.10", "4.265799"], ["83819.70", "5.536462"], ["83811.30", "4.901131"], ["83802.90", "5.627224"], ["83794.50", "5.354939"], ["83786.10", "3.902752"], ["83777.70", "5.264177"], ["83769.30", "4.175037"], ["83760.90", "3.993514"], ["83752.50", "4.356561"], ["83744.10", "4.628846"], ["83735.70", "4.810369"], ["83727.30", "4.084276"], ["83718.90", "5.173416"], ["83710.50", "4.991892"], ["83702.10", "4.538084"], ["83447.32", "0"], ["83447.31", "0"], ["83447.17", "0"], ["83446.43", "0"]], "checksum": -1712008620, "ts": "1742577149375"}], "ts": 1742577149380, "record_time": 1742577149.597441, "EXCHANGE": "BITGET"}
{"action": "update", "arg": {"instType": "SPOT", "channel": "books", "instId": "BTCUSDT"}, "data": [{"asks": [["83924.76", "0.092767"], ["83969.70", "0.001215"], ["83971.70", "0.003199"], ["83973.70", "0.008418"], ["83975.70", "0.022152"], ["83977.70", "0.058295"], ["83979.70", "0.153407"], ["83981.70", "0.403703"], ["83983.70", "1.062376"], ["83985.70", "2.795726"], ["83987.70", "7.357174"], ["83988.90", "1.043340"], ["83989.00", "0.001443"], ["83989.40", "0"], ["83989.60", "0.001019"], ["83990.20", "0.120000"], ["83991.30", "0.071550"], ["83991.70", "0"], ["84000.10", "1.492020"], ["84029.60", "5.445701"], ["84038.00", "3.902752"], ["84046.40", "4.628846"], ["84054.80", "5.082654"], ["84063.20", "4.447322"], ["84071.60", "5.536462"], ["84080.00", "5.354939"], ["84088.40", "3.993514"], ["84096.80", "4.265799"], ["84105.20", "4.991892"], ["84113.60", "4.719607"], ["84122.00", "4.356561"], ["84130.40", "4.084276"], ["84138.80", "4.810369"], ["84147.20", "4.175037"], ["84155.60", "4.538084"], ["84164.00", "4.901131"], ["84172.40", "5.264177"], ["84180.80", "5.627224"], ["84340.00", "0"], ["84340.46", "0"]], "bids": [["83917.60", "0.003753"], ["83915.60", "0.009877"], ["83913.60", "0.025994"], ["83911.60", "0.068403"], ["83909.60", "0.180010"], ["83907.60", "0.473710"], ["83905.60", "1.246604"], ["83903.60", "3.280538"], ["83901.84", "0.350173"], ["83900.40", "0.366270"], ["83898.24", "0.024669"], ["83898.10", "0.015000"], ["83897.49", "0.220271"], ["83885.18", "0"], ["83861.70", "4.538084"], ["83853.30", "4.628846"], ["83844.90", "4.356561"], ["83836.50", "4.265799"], ["83828.10", "4.810369"], ["83819.70", "4.719607"], ["83811.30", "5.264177"], ["83802.90", "5.173416"], ["83794.50", "3.902752"], ["83786.10", "5.445701"], ["83777.70", "3.993514"], ["83769.30", "5.627224"], ["83760.90", "4.991892"], ["83752.50", "5.354939"], ["83744.10", "4.901131"], ["83735.70", "4.447322"], ["83727.30", "4.175037"], ["83718.90", "4.084276"], ["83710.50", "5.082654"], ["83702.10", "5.536462"]], "checksum": 769774750, "ts": "1742577149582"}], "ts": 1742577149586, "record_time": 1742577149.77823, "EXCHANGE": "BITGET"}
{"action": "update", "arg": {"instType": "SPOT", "channel": "books", "instId": "BTCUSDT"}, "data": [{"asks": [["83971.70", "0.003021"], ["83973.70", "0.007950"], ["83975.70", "0.020922"], ["83977.70", "0.055057"], ["83979.70", "0.144888"], ["83981.70", "0.381284"], ["83983.70", "1.003379"], ["83985.70", "2.640470"], ["83987.70", "6.948607"], ["83988.90", "0.360660"], ["83989.40", "0.001045"], ["83989.60", "0"], ["83992.50", "0.465870"], ["83993.40", "0.656100"], ["83994.40", "1.457490"], ["83995.10", "2.370300"], ["83999.90", "0"], ["84000.10", "0"], ["84029.60", "4.810369"], ["84038.00", "4.538084"], ["84046.40", "4.991892"], ["84054.80", "4.901131"], ["84063.20", "4.175037"], ["84071.60", "4.265799"], ["84080.00", "5.082654"], ["84088.40", "4.356561"], ["84096.80", "4.447322"], ["84105.20", "5.354939"], ["84113.60", "5.264177"], ["84122.00", "5.627224"], ["84130.40", "3.902752"], ["84138.80", "5.445701"], ["84147.20", "4.084276"], ["84155.60", "4.628846"], ["84164.00", "3.993514"], ["84172.40", "5.536462"], ["84180.80", "4.719607"]], "bids": [["83911.60", "0.068592"], ["83909.61", "0.181126"], ["83909.60", "0.180505"], ["83907.60", "0.475012"], ["83905.60", "1.250032"], ["83903.60", "3.289559"], ["83894.10", "0"], ["83861.70", "5.264177"], ["83844.90", "4.447322"], ["83836.50", "4.356561"], ["83828.10", "5.627224"], ["83819.70", "4.901131"], ["83811.30", "5.354939"], ["83802.90", "4.538084"], ["83794.50", "5.536462"], ["83777.70", "4.265799"], ["83769.30", "4.991892"], ["83760.90", "4.810369"], ["83752.50", "3.993514"], ["83744.10", "5.082654"], ["83735.70", "4.175037"], ["83727.30", "3.902752"], ["83710.50", "5.173416"], ["83702.10", "4.719607"], ["83447.32", "0.000009"]], "checksum": 374625602, "ts": "1742577149784"}], "ts": 1742577149786, "record_time": 1742577149.986204, "EXCHANGE": "BITGET"}
{"action": "update", "arg": {"instType": "SPOT", "channel": "books", "instId": "BTCUSDT"}, "data": [{"asks": [["83924.52", "0.092768"], ["83924.76", "0"], ["83971.70", "0.003385"], ["83973.70", "0.008908"], ["83975.70", "0.023442"], ["83977.70", "0.061689"], ["83979.70", "0.162340"], ["83981.70", "0.427212"], ["83983.70", "1.124242"], ["83985.70", "2.958530"], ["83987.70", "7.785607"], ["83989.40", "0.026310"], ["83992.20", "0.069810"], ["83993.40", "4.956750"], ["83994.40", "0.025860"], ["83995.10", "0.010710"], ["83998.70", "0"], ["83998.80", "0"], ["84029.60", "5.173416"], ["84038.00", "4.447322"], ["84046.40", "4.628846"], ["84054.80", "3.993514"], ["84063.20", "5.536462"], ["84071.60", "4.175037"], ["84080.00", "5.445701"], ["84096.80", "3.902752"], ["84105.20", "4.810369"], ["84122.00", "5.354939"], ["84130.40", "4.538084"], ["84138.80", "4.265799"], ["84147.20", "4.719607"], ["84155.60", "4.991892"], ["84164.00", "5.627224"], ["84172.40", "5.082654"], ["84180.80", "4.901131"], ["84189.20", "4.084276"], ["84340.00", "0.018287"]], "bids": [["83917.60", "0.003469"], ["83915.60", "0.009130"], ["83913.60", "0.024025"], ["83911.60", "0.063225"], ["83909.60", "0.166380"], ["83907.60", "0.437843"], ["83905.60", "1.152219"], ["83903.60", "3.032153"], ["83861.70", "5.445701"], ["83853.30", "4.810369"], ["83844.90", "4.265799"], ["83836.50", "4.991892"], ["83828.10", "4.538084"], ["83819.70", "4.719607"], ["83811.30", "5.173416"], ["83802.90", "4.628846"], ["83794.50", "5.354939"], ["83786.10", "3.902752"], ["83777.70", "5.536462"], ["83769.30", "4.447322"], ["83760.90", "3.993514"], ["83752.50", "5.627224"], ["83744.10", "4.175037"], ["83735.70", "4.901131"], ["83727.30", "4.084276"], ["83718.90", "5.264177"], ["83710.50", "5.082654"], ["83702.10", "4.356561"]], "checksum": -1559120038, "ts": "1742577149989"}], "ts": 1742577149991, "record_time": 1742577150.184147, "EXCHANGE": "BITGET"}
{"action": "update", "arg": {"instType": "SPOT", "channel": "books", "instId": "BTCUSDT"}, "data": [{"asks": [["83918.03", "0.814355"], ["83975.70", "0.023634"], ["83977.70", "0.062195"], ["83979.70", "0.163670"], ["83981.70", "0.430710"], ["83983.70", "1.133449"], ["83985.70", "2.982760"], ["83987.70", "7.849367"], ["83989.40", "0.001003"], ["83991.90", "0.030000"], ["83998.70", "1.429500"], ["83998.80", "0.070350"], ["84029.60", "5.264177"], ["84038.00", "4.991892"], ["84046.40", "4.538084"], ["84054.80", "4.628846"], ["84063.20", "3.902752"], ["84071.60", "5.445701"], ["84080.00", "4.810369"], ["84096.80", "4.447322"], ["84105.20", "5.627224"], ["84113.60", "5.082654"], ["84130.40", "4.175037"], ["84138.80", "4.901131"], ["84147.20", "3.993514"], ["84155.60", "4.265799"], ["84164.00", "5.536462"], ["84172.40", "4.084276"], ["84180.80", "4.719607"], ["84189.20", "5.173416"], ["84339.62", "0"], ["84340.00", "0"]], "bids": [["83913.60", "0.024289"], ["83911.60", "0.063917"], ["83909.60", "0.168203"], ["83907.60", "0.442640"], ["83905.60", "1.164842"], ["83903.60", "3.065373"], ["83903.20", "0.001012"], ["83868.00", "0"], ["83867.00", "0.000160"], ["83861.70", "4.810369"], ["83853.30", "4.538084"], ["83844.90", "5.173416"], ["83836.50", "5.536462"], ["83828.10", "3.993514"], ["83819.70", "4.991892"], ["83811.30", "3.902752"], ["83802.90", "4.175037"], ["83786.10", "4.265799"], ["83777.70", "5.264177"], ["83769.30", "4.719607"], ["83760.90", "4.447322"], ["83744.10", "4.356561"], ["83718.90", "4.628846"], ["83702.10", "5.445701"]], "checksum": -433484366, "ts": "1742577150195"}], "ts": 1742577150199, "record_time": 1742577150.391869, "EXCHANGE": "BITGET"}
{"action": "update", "arg": {"instType": "SPOT", "channel": "books", "instId": "BTCUSDT"}, "data": [{"asks": [["83926.43", "0"], ["83945.57", "0.006357"], ["83946.08", "0.010995"], ["83950.81", "0"], ["83951.70", "0"], ["83952.36", "0.119858"], ["83958.49", "0"], ["83966.14", "0"], ["83969.70", "0.001019"], ["83971.70", "0.002544"], ["83973.70", "0.006695"], ["83975.70", "0.017618"], ["83977.70", "0.046363"], ["83979.70", "0.122008"], ["83981.70", "0.321074"], ["83983.70", "0.844930"], ["83985.70", "2.223501"], ["83987.70", "5.851318"], ["83993.40", "2.597130"], ["83995.10", "2.370300"], ["83998.80", "0.092970"], ["84029.60", "5.627224"], ["84038.00", "4.356561"], ["84046.40", "4.810369"], ["84054.80", "5.264177"], ["84063.20", "4.265799"], ["84071.60", "5.082654"], ["84080.00", "3.993514"], ["84088.40", "5.445701"], ["84096.80", "4.084276"], ["84105.20", "5.354939"], ["84113.60", "4.719607"], ["84122.00", "4.175037"], ["84130.40", "4.628846"], ["84138.80", "5.173416"], ["84147.20", "3.902752"], ["84155.60", "4.991892"], ["84172.40", "4.538084"], ["84180.80", "4.901131"], ["84189.20", "4.447322"], ["84339.62", "0.000051"], ["84340.00", "0.018287"]], "bids": [["83917.60", "0.003763"], ["83915.60", "0.009902"], ["83913.60", "0.026057"], ["83911.60", "0.068573"], ["83909.60", "0.180455"], ["83907.60", "0.474881"], ["83905.60", "1.249686"], ["83905.20", "0"], ["83903.60", "3.288647"], ["83903.14", "0"], ["83899.80", "0"], ["83899.08", "0.016433"], ["83898.41", "0.055637"], ["83898.40", "0"], ["83896.60", "0.022710"], ["83892.27", "0.223055"], ["83861.70", "5.082654"], ["83853.30", "4.628846"], ["83836.50", "5.354939"], ["83819.70", "5.627224"], ["83811.30", "4.084276"], ["83802.90", "4.991892"], ["83794.50", "4.901131"], ["83786.10", "4.810369"], ["83777.70", "4.356561"], ["83769.30", "4.265799"], ["83760.90", "3.902752"], ["83752.50", "5.445701"], ["83744.10", "4.719607"], ["83735.70", "4.538084"], ["83727.30", "5.264177"], ["83718.90", "5.536462"], ["83710.50", "4.175037"], ["83702.10", "4.447322"], ["83510.00", "0.000271"]], "checksum": -290956448, "ts": "1742577150400"}], "ts": 1742577150402, "record_time": 1742577150.599685, "EXCHANGE": "BITGET"}
{"action": "update", "arg": {"instType": "SPOT", "channel": "books", "instId": "BTCUSDT"}, "data": [{"asks": [["83924.28", "0.092768"], ["83924.51", "0.062032"], ["83924.52", "0"], ["83925.26", "0"], ["83939.99", "0"], ["83959.87", "0.184405"], ["83992.20", "0"], ["84029.60", "4.265799"], ["84038.00", "4.901131"], ["84046.40", "3.993514"], ["84054.80", "3.902752"], ["84063.20", "4.719607"], ["84071.60", "5.536462"], ["84080.00", "4.175037"], ["84088.40", "4.356561"], ["84096.80", "4.538084"], ["84105.20", "4.447322"], ["84113.60", "5.082654"], ["84122.00", "5.264177"], ["84130.40", "5.445701"], ["84138.80", "5.354939"], ["84147.20", "4.810369"], ["84155.60", "4.084276"], ["84164.00", "5.627224"], ["84172.40", "5.173416"], ["84180.80", "4.628846"], ["84189.20", "4.991892"], ["84340.46", "0.000143"]], "bids": [["83917.60", "0.004526"], ["83915.60", "0.011911"], ["83913.60", "0.031344"], ["83911.60", "0.082485"], ["83909.60", "0.217064"], ["83907.60", "0.571222"], ["83905.60", "1.503215"], ["83903.60", "3.955829"], ["83861.70", "4.991892"], ["83853.30", "4.265799"], ["83844.90", "4.356561"], ["83836.50", "4.810369"], ["83828.10", "5.354939"], ["83819.70", "4.084276"], ["83811.30", "3.902752"], ["83802.90", "5.536462"], ["83794.50", "3.993514"], ["83786.10", "4.175037"], ["83777.70", "5.264177"], ["83769.30", "5.082654"], ["83760.90", "5.627224"], ["83752.50", "4.901131"], ["83744.10", "4.447322"], ["83735.70", "4.719607"], ["83727.30", "4.628846"], ["83718.90", "5.445701"], ["83710.50", "4.538084"], ["83702.10", "5.173416"]], "checksum": 1838021230, "ts": "1742577150602"}], "ts": 1742577150605, "record_time": 1742577150.804033, "EXCHANGE": "BITGET"}
{"action": "update", "arg": {"instType": "SPOT", "channel": "books", "instId": "BTCUSDT"}, "data": [{"asks": [["83924.27", "0.027830"], ["83924.51", "0"], ["83926.43", "0.209200"], ["83941.00", "0.000119"], ["84029.60", "3.993514"], ["84038.00", "5.082654"], ["84046.40", "4.538084"], ["84054.80", "5.445701"], ["84063.20", "5.536462"], ["84071.60", "4.991892"], ["84080.00", "4.719607"], ["84088.40", "4.175037"], ["84096.80", "5.173416"], ["84105.20", "5.354939"], ["84113.60", "4.084276"], ["84122.00", "4.447322"], ["84130.40", "4.628846"], ["84138.80", "4.901131"], ["84147.20", "4.356561"], ["84155.60", "4.810369"], ["84164.00", "3.902752"], ["84172.40", "5.627224"], ["84180.80", "5.264177"], ["84189.20", "4.265799"], ["84310.00", "0.000348"], ["84340.00", "0"], ["84340.46", "0"]], "bids": [["83917.60", "0.005175"], ["83915.60", "0.013617"], ["83913.60", "0.035834"], ["83911.60", "0.094300"], ["83909.60", "0.248157"], ["83907.60", "0.653046"], ["83905.77", "1.591161"], ["83905.60", "1.718542"], ["83903.60", "4.522478"], ["83902.70", "0.168840"], ["83901.84", "0"], ["83900.40", "0.366060"], ["83897.49", "0.083219"], ["83881.00", "0.211274"], ["83868.00", "0.000121"], ["83866.00", "0.000281"], ["83861.70", "4.719607"], ["83853.30", "5.536462"], ["83844.90", "3.993514"], ["83836.50", "5.173416"], ["83828.10", "4.447322"], ["83819.70", "4.175037"], ["83811.30", "5.354939"], ["83802.90", "5.264177"], ["83794.50", "5.082654"], ["83786.10", "4.356561"], ["83777.70", "4.538084"], ["83769.30", "4.628846"], ["83760.90", "4.265799"], ["83752.50", "4.991892"], ["83744.10", "4.084276"], ["83735.70", "5.627224"], ["83727.30", "3.902752"], ["83718.90", "4.810369"], ["83710.50", "5.445701"], ["83702.10", "4.901131"], ["83447.32", "0"]], "checksum": -1490124130, "ts": "1742577150806"}], "ts": 1742577150810, "record_time": 1742577151.002831, "EXCHANGE": "BITGET"}
{"action": "update", "arg": {"instType": "SPOT", "channel": "books", "instId": "BTCUSDT"}, "data": [{"asks": [["83924.06", "0.092768"], ["83924.28", "0"], ["83926.42", "0.096961"], ["83967.96", "0"], ["83969.70", "0.001295"], ["83971.70", "0.003407"], ["83973.70", "0.008965"], ["83975.70", "0.023592"], ["83977.70", "0.062085"], ["83979.70", "0.163382"], ["83981.70", "0.429951"], ["83983.70", "1.131706"], ["83985.70", "2.978172"], ["83987.70", "7.837296"], ["83989.40", "0.036150"], ["83993.40", "1.684830"], ["83993.60", "2.381220"], ["83995.10", "0.010710"], ["84029.60", "3.902752"], ["84038.00", "4.084276"], ["84046.40", "5.173416"], ["84054.80", "4.810369"], ["84071.60", "3.993514"], ["84080.00", "4.991892"], ["84096.80", "4.719607"], ["84105.20", "4.901131"], ["84113.60", "5.627224"], ["84122.00", "5.264177"], ["84130.40", "5.082654"], ["84138.80", "4.538084"], ["84155.60", "5.445701"], ["84164.00", "4.265799"], ["84172.40", "5.354939"], ["84180.80", "4.447322"], ["84189.20", "4.628846"], ["84315.00", "0.000404"], ["84339.62", "0"]], "bids": [["83917.60", "0.002837"], ["83915.60", "0.007465"], ["83913.60", "0.019646"], ["83911.60", "0.051700"], ["83909.60", "0.136053"], ["83907.60", "0.358033"], ["83905.60", "0.942193"], ["83903.60", "2.479454"], ["83900.40", "0.120000"], ["83898.00", "0.108900"], ["83894.20", "0"], ["83861.70", "5.173416"], ["83853.30", "4.538084"], ["83836.50", "4.175037"], ["83828.10", "4.901131"], ["83819.70", "4.447322"], ["83811.30", "4.719607"], ["83802.90", "4.356561"], ["83794.50", "5.264177"], ["83786.10", "5.536462"], ["83777.70", "5.445701"], ["83769.30", "5.354939"], ["83760.90", "5.082654"], ["83752.50", "3.902752"], ["83744.10", "4.810369"], ["83735.70", "4.265799"], ["83727.30", "5.627224"], ["83718.90", "4.628846"], ["83710.50", "4.084276"], ["83702.10", "4.991892"], ["83447.32", "0.000009"]], "checksum": 32902285, "ts": "1742577151023"}], "ts": 1742577151026, "record_time": 1742577151.230688, "EXCHANGE": "BITGET"}
{"action": "update", "arg": {"instType": "SPOT", "channel": "books", "instId": "BTCUSDT"}, "data": [{"asks": [["83924.05", "0.027830"], ["83924.27", "0"], ["83977.70", "0.062198"], ["83979.70", "0.163678"], ["83981.70", "0.430733"], ["83983.70", "1.133508"], ["83985.70", "2.982915"], ["83987.70", "7.849777"], ["83993.40", "2.264130"], ["84029.60", "3.993514"], ["84038.00", "5.445701"], ["84046.40", "4.175037"], ["84054.80", "4.991892"], ["84063.20", "4.719607"], ["84071.60", "5.354939"], ["84080.00", "5.173416"], ["84088.40", "3.902752"], ["84096.80", "4.901131"], ["84105.20", "4.356561"], ["84113.60", "4.538084"], ["84120.85", "0"], ["84130.40", "4.628846"], ["84138.80", "5.536462"], ["84147.20", "4.265799"], ["84155.60", "5.082654"], ["84164.00", "5.627224"], ["84172.40", "4.084276"], ["84189.20", "4.810369"], ["84339.62", "0.000051"]], "bids": [["83917.60", "0.002584"], ["83915.60", "0.006798"], ["83913.60", "0.017890"], ["83911.60", "0.047078"], ["83909.60", "0.123890"], ["83907.60", "0.326026"], ["83905.60", "0.857963"], ["83903.60", "2.257798"], ["83861.70", "5.264177"], ["83853.30", "5.445701"], ["83844.90", "4.538084"], ["83836.50", "4.265799"], ["83828.10", "4.084276"], ["83819.70", "3.993514"], ["83811.30", "4.810369"], ["83802.90", "4.901131"], ["83794.50", "5.627224"], ["83786.10", "4.719607"], ["83777.70", "5.173416"], ["83769.30", "4.447322"], ["83752.50", "4.356561"], ["83744.10", "4.175037"], ["83735.70", "4.991892"], ["83727.30", "5.354939"], ["83718.90", "3.902752"], ["83710.50", "5.536462"], ["83702.10", "4.628846"]], "checksum": 1135122967, "ts": "1742577151236"}], "ts": 1742577151240, "record_time": 1742577151.432961, "EXCHANGE": "BITGET"}
{"action": "update", "arg": {"instType": "SPOT", "channel": "books", "instId": "BTCUSDT"}, "data": [{"asks": [["83955.06", "0.047019"], ["83975.70", "0.023815"], ["83977.70", "0.062671"], ["83979.39", "0"], ["83979.70", "0.164924"], ["83981.70", "0.434009"], ["83983.70", "1.142129"], ["83984.29", "0"], ["83985.70", "3.005603"], ["83987.70", "7.909483"], ["84029.60", "5.264177"], ["84038.00", "4.810369"], ["84054.80", "5.536462"], ["84063.20", "4.356561"], ["84071.60", "5.445701"], ["84080.00", "5.354939"], ["84088.40", "4.447322"], ["84096.80", "5.082654"], ["84105.20", "4.991892"], ["84113.60", "3.902752"], ["84121.72", "0.161442"], ["84122.00", "5.627224"], ["84130.40", "4.084276"], ["84138.80", "4.901131"], ["84147.20", "5.173416"], ["84155.60", "3.993514"], ["84164.00", "4.265799"], ["84172.40", "4.628846"], ["84180.80", "4.719607"], ["84189.20", "4.538084"]], "bids": [["83909.61", "0.119918"], ["83905.77", "1.479010"], ["83902.70", "1.086330"], ["83902.40", "0.173359"], ["83900.50", "0.131940"], ["83867.00", "0"], ["83861.70", "3.993514"], ["83853.30", "5.627224"], ["83844.90", "4.628846"], ["83836.50", "4.447322"], ["83828.10", "5.445701"], ["83819.70", "4.901131"], ["83811.30", "4.084276"], ["83808.45", "0"], ["83802.90", "5.354939"], ["83794.50", "5.082654"], ["83786.10", "4.265799"], ["83777.70", "4.991892"], ["83769.30", "5.264177"], ["83760.90", "4.810369"], ["83752.50", "4.538084"], ["83744.10", "3.902752"], ["83735.70", "4.175037"], ["83727.30", "5.536462"], ["83718.90", "4.356561"], ["83710.50", "4.719607"], ["83702.10", "5.173416"], ["83447.31", "0.000008"]], "checksum": 1240010601, "ts": "1742577151437"}], "ts": 1742577151439, "record_time": 1742577151.636094, "EXCHANGE": "BITGET"}
{"action": "update", "arg": {"instType": "SPOT", "channel": "books", "instId": "BTCUSDT"}, "data": [{"asks": [["83923.83", "0.092769"], ["83924.06", "0"], ["83962.10", "0"], ["83979.69", "0.242440"], ["83987.70", "7.909669"], ["83988.60", "0.072750"], ["83989.40", "0.026100"], ["83998.70", "0"], ["83998.80", "0"], ["84029.60", "4.356561"], ["84038.00", "5.354939"], ["84046.40", "5.536462"], ["84054.80", "5.082654"], ["84063.20", "4.901131"], ["84071.60", "4.175037"], ["84080.00", "4.447322"], ["84088.40", "4.084276"], ["84096.80", "4.719607"], ["84105.20", "5.627224"], ["84113.60", "5.264177"], ["84122.00", "4.538084"], ["84130.40", "4.810369"], ["84138.80", "4.991892"], ["84147.20", "3.993514"], ["84155.60", "3.902752"], ["84164.00", "4.628846"], ["84172.40", "5.445701"], ["84180.80", "5.173416"], ["84189.20", "4.265799"], ["84340.00", "0.018287"], ["84340.46", "0.000143"]], "bids": [["83917.60", "0.003604"], ["83915.60", "0.009485"], ["83913.60", "0.024959"], ["83911.60", "0.065570"], ["83909.60", "0.172552"], ["83907.60", "0.454084"], ["83905.60", "1.194958"], ["83903.60", "3.144628"], ["83903.00", "0"], ["83902.70", "0.169050"], ["83894.20", "0.120000"], ["83894.00", "0.042300"], ["83893.40", "0.240000"], ["83893.30", "0.120000"], ["83866.00", "0.000160"], ["83861.70", "5.536462"], ["83853.30", "5.082654"], ["83844.90", "4.538084"], ["83836.50", "5.445701"], ["83828.10", "4.265799"], ["83819.70", "4.628846"], ["83802.90", "4.901131"], ["83794.50", "5.264177"], ["83786.10", "3.993514"], ["83777.70", "4.175037"], ["83769.30", "3.902752"], ["83752.50", "4.719607"], ["83744.10", "4.991892"], ["83735.70", "4.447322"], ["83727.30", "5.173416"], ["83719.00", "0.001720"], ["83710.50", "5.627224"], ["83702.10", "5.354939"], ["83448.14", "0"], ["83448.00", "0"], ["83447.32", "0"], ["83447.31", "0"]], "checksum": 2078346849, "ts": "1742577151638"}], "ts": 1742577151641, "record_time": 1742577151.839545, "EXCHANGE": "BITGET"}
{"action": "update", "arg": {"instType": "SPOT", "channel": "books", "instId": "BTCUSDT"}, "data": [{"asks": [["83923.82", "0.027831"], ["83924.05", "0"], ["83969.70", "0.001296"], ["83971.70", "0.003411"], ["83973.70", "0.008975"], ["83975.70", "0.023618"], ["83977.70", "0.062154"], ["83979.70", "0.163562"], ["83981.70", "0.430427"], ["83983.70", "1.132702"], ["83985.70", "2.980794"], ["83987.70", "7.844197"], ["83988.60", "0.001026"], ["83989.40", "0.001015"], ["83998.70", "1.429500"], ["84029.60", "4.991892"], ["84038.00", "4.719607"], ["84046.40", "5.264177"], ["84054.80", "4.175037"], ["84063.20", "5.627224"], ["84071.60", "4.538084"], ["84080.00", "3.993514"], ["84088.40", "4.356561"], ["84096.80", "3.902752"], ["84105.20", "4.628846"], ["84113.60", "4.265799"], ["84122.00", "5.082654"], ["84130.40", "4.901131"], ["84138.80", "5.354939"], ["84147.20", "5.536462"], ["84155.60", "4.084276"], ["84164.00", "5.173416"], ["84172.40", "4.447322"], ["84180.80", "4.810369"], ["84189.20", "5.445701"], ["84340.46", "0"]], "bids": [["83917.60", "0.003853"], ["83915.60", "0.010141"], ["83913.60", "0.026685"], ["83911.60", "0.070226"], ["83909.61", "0.173001"], ["83909.60", "0.184557"], ["83907.60", "0.485678"], ["83905.60", "1.278100"], ["83903.60", "3.363419"], ["83898.24", "0"], ["83897.49", "0"], ["83861.70", "4.991892"], ["83853.30", "4.265799"], ["83844.90", "5.536462"], ["83836.50", "4.538084"], ["83828.10", "5.445701"], ["83819.70", "5.354939"], ["83811.30", "4.175037"], ["83802.90", "4.447322"], ["83794.50", "4.810369"], ["83786.10", "5.082654"], ["83777.70", "3.993514"], ["83769.30", "4.719607"], ["83760.90", "4.356561"], ["83752.50", "5.627224"], ["83744.10", "4.084276"], ["83735.70", "4.901131"], ["83727.30", "5.264177"], ["83718.90", "4.628846"], ["83710.50", "5.173416"], ["83702.10", "3.902752"], ["83448.14", "0.000070"], ["83448.00", "0.000012"]], "checksum": 1782434909, "ts": "1742577151840"}], "ts": 1742577151844, "record_time": 1742577152.036363, "EXCHANGE": "BITGET"}
{"action": "update", "arg": {"instType": "SPOT", "channel": "books", "instId": "BTCUSDT"}, "data": [{"asks": [["83923.83", "0"], ["83971.70", "0.003589"], ["83973.70", "0.009444"], ["83975.70", "0.024853"], ["83977.70", "0.065404"], ["83979.70", "0.172116"], ["83981.70", "0.452937"], ["83983.70", "1.191938"], ["83985.70", "3.136679"], ["83987.70", "8.254420"], ["83989.40", "0.012660"], ["83991.30", "0.143760"], ["83992.50", "0"], ["83993.40", "1.608030"], ["83993.50", "1.429500"], ["83995.90", "0.605340"], ["83998.70", "0"], ["83998.80", "0.416550"], ["84006.30", "0.062760"], ["84029.60", "3.902752"], ["84038.00", "3.993514"], ["84046.40", "5.627224"], ["84054.80", "5.445701"], ["84063.20", "5.264177"], ["84080.00", "4.265799"], ["84088.40", "5.173416"], ["84096.80", "4.447322"], ["84113.60", "5.536462"], ["84122.00", "5.354939"], ["84138.80", "4.175037"], ["84147.20", "4.719607"], ["84155.60", "5.082654"], ["84164.00", "4.810369"], ["84172.40", "4.084276"], ["84180.80", "4.356561"], ["84189.20", "4.991892"]], "bids": [["83918.02", "1.269852"], ["83917.60", "0.003628"], ["83915.60", "0.009548"], ["83913.60", "0.025126"], ["83911.60", "0.066121"], ["83909.60", "0.174002"], ["83907.60", "0.457901"], ["83905.60", "1.205002"], ["83903.60", "3.171058"], ["83899.90", "0.120000"], ["83893.30", "0"], ["83889.34", "0.024669"], ["83868.00", "0.000281"], ["83861.70", "4.538084"], ["83853.30", "5.264177"], ["83847.90", "0.000971"], ["83846.80", "0"], ["83844.90", "5.082654"], ["83836.50", "5.445701"], ["83828.10", "4.265799"], ["83819.70", "3.902752"], ["83811.30", "4.901131"], ["83802.90", "4.991892"], ["83794.50", "4.719607"], ["83786.10", "4.447322"], ["83777.70", "4.356561"], ["83769.30", "5.536462"], ["83760.90", "4.084276"], ["83744.10", "4.810369"], ["83735.70", "5.354939"], ["83727.30", "5.173416"], ["83718.90", "3.993514"], ["83710.50", "4.628846"], ["83702.10", "4.175037"], ["83448.00", "0"]], "checksum": -1923477043, "ts": "1742577152041"}], "ts": 1742577152045, "record_time": 1742577152.238773, "EXCHANGE": "BITGET"}
{"action": "update", "arg": {"instType": "SPOT", "channel": "books", "instId": "BTCUSDT"}, "data": [{"asks": [["83923.63", "0.092769"], ["83923.82", "0"], ["83941.86", "0.035971"], ["83942.17", "0.119905"], ["83943.41", "0.035972"], ["83943.76", "0.006357"], ["83943.97", "0.006357"], ["83944.26", "0.006357"], ["83944.69", "0.006357"], ["83945.47", "0.006357"], ["83945.62", "0.006356"], ["83945.85", "0.006357"], ["83946.46", "0.016429"], ["83946.47", "0.006357"], ["83946.49", "0.006357"], ["83946.78", "0.006357"], ["83946.82", "0.006357"], ["83947.13", "0.016429"], ["83947.14", "0.119901"], ["83947.15", "0"], ["83947.21", "0.006357"], ["83947.26", "0"], ["83947.37", "0.006357"], ["83948.30", "0.006357"], ["83948.79", "0.017350"], ["83948.87", "0"], ["83949.31", "0"], ["83949.41", "0"], ["83949.64", "0.009990"], ["83949.72", "0"], ["83950.60", "0.119850"], ["83950.69", "0"], ["83950.74", "0"], ["83950.87", "0"], ["83950.97", "0"], ["83951.08", "0"], ["83951.68", "0"], ["83951.74", "0"], ["83951.75", "0.119905"], ["83952.09", "0.330521"], ["83952.23", "0.009989"], ["83952.27", "0"], ["83952.28", "0"], ["83952.47", "0"], ["83952.75", "0"], ["83953.11", "0"], ["83953.59", "0"], ["83953.76", "0"], ["83954.04", "0"], ["83954.26", "0.006356"], ["83954.33", "0"], ["83955.07", "0"], ["83955.68", "0"], ["83955.85", "0"], ["83955.95", "0.015896"], ["83956.05", "0"], ["83958.42", "0"], ["83959.07", "0"], ["83960.54", "0"], ["83963.26", "0.010000"], ["83969.70", "0.001412"], ["83971.70", "0.003714"], ["83973.70", "0.009775"], ["83975.70", "0.025724"], ["83977.70", "0.067693"], ["83979.70", "0.178142"], ["83981.70", "0.468794"], ["83983.70", "1.233668"], ["83985.70", "3.246495"], ["83987.70", "8.543408"], ["83989.40", "0.036150"], ["83991.90", "0.015000"], ["84029.59", "0.353742"], ["84029.60", "5.173416"], ["84038.00", "4.084276"], ["84046.40", "3.993514"], ["84054.80", "3.902752"], ["84063.20", "4.628846"], ["84071.60", "4.175037"], ["84080.00", "4.538084"], ["84088.40", "4.810369"], ["84096.80", "4.265799"], ["84105.20", "5.354939"], ["84113.60", "5.627224"], ["84122.00", "4.991892"], ["84130.40", "5.264177"], ["84138.80", "4.356561"], ["84155.60", "5.536462"], ["84164.00", "5.082654"], ["84172.40", "5.445701"], ["84180.80", "4.901131"], ["84189.20", "4.447322"]], "bids": [["83917.60", "0.002760"], ["83915.60", "0.007265"], ["83913.60", "0.019117"], ["83911.60", "0.050309"], ["83909.60", "0.132392"], ["83907.60", "0.348399"], ["83906.86", "0"], ["83906.14", "0"], ["83905.60", "0.916840"], ["83905.23", "0"], ["83904.83", "0"], ["83904.81", "0"], ["83904.60", "0"], ["83904.23", "0"], ["83903.60", "2.412736"], ["83903.59", "0"], ["83903.23", "0"], ["83902.84", "0"], ["83902.57", "0"], ["83902.51", "0"], ["83902.39", "0"], ["83902.23", "0"], ["83901.83", "0"], ["83901.76", "0"], ["83901.74", "0"], ["83901.58", "0.089673"], ["83901.22", "0"], ["83901.12", "0"], ["83901.05", "0.247543"], ["83900.93", "0"], ["83900.21", "0"], ["83900.09", "0"], ["83899.78", "0"], ["83899.77", "0.091666"], ["83899.62", "0"], ["83899.29", "0.017826"], ["83899.16", "0.018273"], ["83898.78", "0.005950"], ["83898.53", "0.015750"], ["83897.97", "0.006572"], ["83897.80", "0"], ["83897.48", "0"], ["83897.45", "0.017124"], ["83897.34", "0.007141"], ["83896.96", "0.007347"], ["83896.95", "0.028875"], ["83896.88", "0.004036"], ["83896.64", "0.017114"], ["83896.26", "0.007956"], ["83895.94", "0.250248"], ["83895.84", "0.008200"], ["83895.68", "0.017376"], ["83895.24", "0"], ["83894.76", "0.008290"], ["83894.24", "0.064520"], ["83893.41", "0.018549"], ["83893.30", "0.120000"], ["83892.53", "0.268841"], ["83891.32", "0.259212"], ["83891.17", "0.076244"], ["83890.96", "0.021166"], ["83890.45", "0"], ["83889.66", "0"], ["83888.96", "0.012460"], ["83887.14", "0.073186"], ["83886.25", "0"], ["83884.69", "0.000878"], ["83866.16", "0.003603"], ["83865.18", "0"], ["83861.70", "4.084276"], ["83853.30", "4.538084"], ["83844.90", "4.447322"], ["83836.50", "5.536462"], ["83828.10", "5.354939"], ["83819.70", "4.175037"], ["83811.30", "4.628846"], ["83802.90", "4.356561"], ["83794.50", "4.265799"], ["83786.10", "3.902752"], ["83777.70", "4.810369"], ["83769.30", "5.082654"], ["83760.90", "5.173416"], ["83752.50", "5.264177"], ["83744.10", "4.719607"], ["83735.70", "4.991892"], ["83727.30", "3.993514"], ["83718.90", "5.445701"], ["83710.50", "5.627224"], ["83702.10", "4.901131"], ["83510.00", "0"], ["83448.00", "0.000012"], ["83447.32", "0.000009"], ["83447.31", "0.000008"], ["83447.17", "0.000008"]], "checksum": 2093401132, "ts": "1742577152246"}], "ts": 1742577152249, "record_time": 1742577152.461246, "EXCHANGE": "BITGET"}
{"action": "update", "arg": {"instType": "SPOT", "channel": "books", "instId": "BTCUSDT"}, "data": [{"asks": [["83923.62", "0.027831"], ["83955.06", "0"], ["83975.70", "0.025922"], ["83977.70", "0.068216"], ["83979.70", "0.179517"], ["83981.70", "0.472412"], ["83983.70", "1.243189"], ["83985.70", "3.271551"], ["83987.70", "8.609345"], ["83987.90", "0.006030"], ["83989.40", "0.035730"], ["83993.60", "0.021600"], ["83993.80", "2.359620"], ["83998.40", "0.012600"], ["83998.80", "0.092970"], ["84029.60", "4.084276"], ["84038.00", "3.902752"], ["84046.40", "4.810369"], ["84054.80", "5.627224"], ["84063.20", "5.445701"], ["84071.60", "4.991892"], ["84080.00", "4.356561"], ["84088.40", "5.536462"], ["84105.20", "4.175037"], ["84113.60", "5.354939"], ["84122.00", "4.447322"], ["84138.80", "5.173416"], ["84147.20", "4.901131"], ["84155.60", "5.082654"], ["84164.00", "4.628846"], ["84172.40", "4.719607"], ["84180.80", "4.538084"], ["84189.20", "3.993514"], ["84339.62", "0"], ["84340.00", "0"]], "bids": [["83917.60", "0.001531"], ["83915.60", "0.004030"], ["83913.60", "0.010605"], ["83911.60", "0.028030"], ["83909.60", "0.073762"], ["83907.60", "0.194111"], ["83905.60", "0.510819"], ["83903.60", "1.344259"], ["83903.20", "0.006720"], ["83902.70", "0.168840"], ["83902.60", "0"], ["83900.50", "0.132150"], ["83899.90", "0"], ["83899.70", "0"], ["83898.20", "0.120000"], ["83897.10", "0.160920"], ["83895.40", "0"], ["83895.00", "0.120000"], ["83894.40", "0.889020"], ["83894.00", "0"], ["83893.40", "0"], ["83893.30", "0"], ["83867.00", "0.000121"], ["83861.70", "4.810369"], ["83853.30", "5.536462"], ["83844.90", "4.719607"], ["83836.50", "4.447322"], ["83828.10", "5.264177"], ["83819.70", "4.538084"], ["83811.30", "5.354939"], ["83802.90", "5.082654"], ["83794.50", "4.901131"], ["83786.10", "5.445701"], ["83777.70", "5.173416"], ["83769.30", "4.991892"], ["83760.90", "4.628846"], ["83752.50", "4.265799"], ["83744.10", "4.175037"], ["83735.70", "3.993514"], ["83727.30", "4.356561"], ["83718.90", "5.627224"], ["83710.50", "3.902752"], ["83702.10", "4.084276"], ["83446.43", "0.000016"], ["83445.30", "0.000011"], ["83445.16", "0.000054"], ["83444.44", "0.000105"]], "checksum": 827438323, "ts": "1742577152450"}], "ts": 1742577152453, "record_time": 1742577152.645517, "EXCHANGE": "BITGET"}
{"action": "update", "arg": {"instType": "SPOT", "channel": "books", "instId": "BTCUSDT"}, "data": [{"asks": [["83923.43", "0.092774"], ["83923.63", "0"], ["83962.10", "0.678130"], ["83979.69", "0"], ["83983.70", "1.242945"], ["83985.70", "3.270908"], ["83987.70", "8.607652"], ["83989.40", "0.001001"], ["84029.59", "0"], ["84029.60", "5.264177"], ["84038.00", "4.810369"], ["84046.40", "4.538084"], ["84054.80", "4.991892"], ["84063.20", "4.265799"], ["84071.60", "4.628846"], ["84080.00", "5.354939"], ["84088.40", "3.993514"], ["84096.80", "4.356561"], ["84105.20", "5.082654"], ["84113.60", "5.627224"], ["84122.00", "5.445701"], ["84130.40", "4.901131"], ["84138.80", "4.175037"], ["84147.20", "4.447322"], ["84155.60", "3.902752"], ["84164.00", "5.173416"], ["84172.40", "4.084276"], ["84180.80", "5.536462"], ["84189.20", "4.719607"], ["84339.62", "0.000051"]], "bids": [["83917.60", "0.003501"], ["83915.60", "0.009212"], ["83913.60", "0.024243"], ["83911.60", "0.063797"], ["83909.61", "0.073727"], ["83909.60", "0.168073"], ["83907.60", "0.442299"], ["83905.77", "0.397085"], ["83905.60", "1.163944"], ["83903.60", "3.063011"], ["83903.20", "0.006060"], ["83900.50", "0.131940"], ["83894.00", "0.042300"], ["83893.40", "0.240000"], ["83861.70", "4.719607"], ["83853.30", "4.175037"], ["83844.90", "5.627224"], ["83836.50", "5.354939"], ["83828.10", "4.356561"], ["83819.70", "5.264177"], ["83811.30", "5.082654"], ["83802.90", "4.628846"], ["83794.50", "4.991892"], ["83786.10", "3.902752"], ["83777.70", "4.538084"], ["83769.30", "4.084276"], ["83760.90", "5.536462"], ["83752.50", "3.993514"], ["83744.10", "5.173416"], ["83735.70", "4.901131"], ["83727.30", "4.447322"], ["83718.90", "4.265799"], ["83710.50", "5.445701"], ["83702.10", "4.810369"], ["83445.16", "0"], ["83444.44", "0"]], "checksum": -473779124, "ts": "1742577152653"}], "ts": 1742577152657, "record_time": 1742577152.853761, "EXCHANGE": "BITGET"}
{"action": "update", "arg": {"instType": "SPOT", "channel": "books", "instId": "BTCUSDT"}, "data": [{"asks": [["83923.42", "0.027832"], ["83923.62", "0"], ["83959.87", "0"], ["83989.40", "0.035730"], ["83998.40", "0"], ["84029.60", "5.173416"], ["84038.00", "4.901131"], ["84046.40", "4.447322"], ["84054.80", "5.082654"], ["84063.20", "5.536462"], ["84071.60", "5.445701"], ["84080.00", "3.993514"], ["84088.40", "4.356561"], ["84096.80", "5.627224"], ["84105.20", "5.264177"], ["84113.60", "4.810369"], ["84122.00", "4.991892"], ["84130.40", "5.354939"], ["84138.80", "3.902752"], ["84147.20", "4.628846"], ["84155.60", "4.084276"], ["84164.00", "4.175037"], ["84172.40", "4.265799"], ["84180.80", "4.538084"], ["84340.00", "0.018287"], ["84340.46", "0.000143"]], "bids": [["83909.61", "0.173896"], ["83866.00", "0"], ["83861.70", "4.175037"], ["83853.30", "4.356561"], ["83844.90", "5.445701"], ["83836.50", "5.536462"], ["83828.10", "4.265799"], ["83819.70", "5.627224"], ["83811.30", "4.084276"], ["83807.65", "0.125844"], ["83802.90", "5.264177"], ["83798.16", "0"], ["83794.50", "5.354939"], ["83786.10", "3.993514"], ["83769.30", "4.810369"], ["83760.90", "3.902752"], ["83752.50", "4.901131"], ["83744.10", "4.991892"], ["83735.70", "4.628846"], ["83718.90", "5.082654"], ["83710.50", "4.719607"], ["83702.10", "5.173416"], ["83445.16", "0.000054"]], "checksum": 965317051, "ts": "1742577152878"}], "ts": 1742577152881, "record_time": 1742577153.075051, "EXCHANGE": "BITGET"}
{"action": "update", "arg": {"instType": "SPOT", "channel": "books", "instId": "BTCUSDT"}, "data": [{"asks": [["83923.43", "0"], ["83927.45", "0"], ["83978.29", "0.001598"], ["83984.59", "0"], ["83998.80", "0.416550"], ["84029.60", "4.901131"], ["84038.00", "4.719607"], ["84046.40", "5.354939"], ["84054.80", "3.902752"], ["84063.20", "4.356561"], ["84071.60", "5.082654"], ["84080.00", "4.447322"], ["84088.40", "4.538084"], ["84096.80", "5.536462"], ["84105.20", "4.628846"], ["84113.60", "5.627224"], ["84122.00", "5.445701"], ["84130.40", "4.084276"], ["84138.80", "4.175037"], ["84147.20", "5.173416"], ["84155.60", "4.810369"], ["84164.00", "4.265799"], ["84172.40", "5.264177"], ["84180.80", "4.991892"], ["84189.20", "3.993514"], ["84340.72", "0.000066"], ["84341.00", "0.002997"]], "bids": [["83917.60", "0.003251"], ["83915.60", "0.008554"], ["83913.60", "0.022512"], ["83911.60", "0.059240"], ["83909.60", "0.155897"], ["83907.60", "0.410254"], ["83905.77", "1.382586"], ["83905.60", "1.079616"], ["83903.60", "2.841094"], ["83893.40", "0"], ["83870.62", "0"], ["83864.32", "0.001174"], ["83861.70", "5.264177"], ["83853.30", "4.628846"], ["83844.90", "5.082654"], ["83836.50", "5.354939"], ["83828.10", "4.719607"], ["83811.30", "4.175037"], ["83802.90", "4.901131"], ["83794.50", "4.265799"], ["83786.10", "5.445701"], ["83769.30", "4.991892"], ["83760.90", "3.993514"], ["83752.50", "5.536462"], ["83744.10", "4.084276"], ["83735.70", "3.902752"], ["83727.30", "5.173416"], ["83718.90", "4.447322"], ["83710.50", "4.356561"], ["83702.10", "4.810369"], ["83444.44", "0.000105"]], "checksum": -1821650641, "ts": "1742577153084"}], "ts": 1742577153086, "record_time": 1742577153.278308, "EXCHANGE": "BITGET"}
{"action": "update", "arg": {"instType": "SPOT", "channel": "books", "instId": "BTCUSDT"}, "data": [{"asks": [["83923.24", "0.092775"], ["83923.42", "0"], ["83923.71", "0.113994"], ["83926.42", "0.062760"], ["83961.02", "0.178187"], ["83976.52", "0.001598"], ["83983.70", "1.243184"], ["83985.70", "3.271537"], ["83986.35", "0"], ["83987.70", "8.609308"], ["84029.60", "4.719607"], ["84038.00", "3.993514"], ["84046.40", "5.082654"], ["84054.80", "4.356561"], ["84063.20", "4.810369"], ["84071.60", "5.264177"], ["84080.00", "5.354939"], ["84088.40", "5.536462"], ["84096.80", "4.628846"], ["84105.20", "5.445701"], ["84113.60", "5.173416"], ["84122.00", "4.991892"], ["84130.40", "5.627224"], ["84138.80", "4.084276"], ["84147.20", "4.538084"], ["84155.60", "4.901131"], ["84164.00", "4.447322"], ["84172.40", "4.265799"], ["84180.80", "3.902752"], ["84189.20", "4.175037"], ["84340.72", "0"], ["84341.00", "0"]], "bids": [["83917.60", "0.003504"], ["83915.60", "0.009222"], ["83913.60", "0.024268"], ["83911.60", "0.063863"], ["83909.60", "0.168060"], ["83907.60", "0.442264"], ["83905.60", "1.163852"], ["83903.60", "3.062769"], ["83902.40", "0.215805"], ["83876.23", "0.006183"], ["83868.00", "0.000160"], ["83866.42", "0.001177"], ["83861.70", "4.265799"], ["83853.30", "4.991892"], ["83844.90", "4.901131"], ["83828.10", "4.538084"], ["83819.70", "5.536462"], ["83811.30", "5.627224"], ["83802.90", "5.082654"], ["83794.50", "4.175037"], ["83777.70", "3.902752"], ["83769.30", "3.993514"], ["83760.90", "4.447322"], ["83752.50", "5.173416"], ["83744.10", "4.356561"], ["83735.70", "4.628846"], ["83727.30", "4.719607"], ["83718.90", "4.084276"], ["83710.50", "4.810369"], ["83702.10", "5.264177"], ["83444.44", "0"]], "checksum": -897820247, "ts": "1742577153284"}], "ts": 1742577153287, "record_time": 1742577153.486049, "EXCHANGE": "BITGET"}
{"action": "update", "arg": {"instType": "SPOT", "channel": "books", "instId": "BTCUSDT"}, "data": [{"asks": [["83923.23", "0.062031"], ["83989.40", "0.001045"], ["84029.60", "4.538084"], ["84038.00", "4.628846"], ["84046.40", "5.173416"], ["84054.80", "4.265799"], ["84063.20", "4.356561"], ["84071.60", "4.810369"], ["84080.00", "5.445701"], ["84088.40", "5.354939"], ["84096.80", "5.627224"], ["84105.20", "4.084276"], ["84113.60", "4.991892"], ["84122.00", "4.901131"], ["84130.40", "3.902752"], ["84138.80", "4.175037"], ["84147.20", "4.447322"], ["84155.60", "3.993514"], ["84164.00", "5.264177"], ["84172.40", "4.719607"], ["84180.80", "5.536462"], ["84189.20", "5.082654"], ["84340.46", "0"]], "bids": [["83907.60", "0.442506"], ["83905.60", "1.164488"], ["83903.60", "3.064443"], ["83898.10", "0.040050"], ["83896.60", "0"], ["83893.40", "0.240000"], ["83867.00", "0.000281"], ["83861.70", "5.536462"], ["83853.30", "5.082654"], ["83844.90", "4.265799"], ["83836.50", "4.810369"], ["83828.10", "4.175037"], ["83819.70", "5.627224"], ["83811.30", "4.356561"], ["83802.90", "4.719607"], ["83794.50", "4.538084"], ["83786.10", "4.628846"], ["83769.30", "4.901131"], ["83760.90", "5.445701"], ["83752.50", "4.084276"], ["83744.10", "5.173416"], ["83735.70", "5.354939"], ["83727.30", "5.264177"], ["83718.90", "4.447322"], ["83710.50", "3.993514"], ["83702.10", "4.991892"]], "checksum": 1095081637, "ts": "1742577153486"}], "ts": 1742577153489, "record_time": 1742577153.684939, "EXCHANGE": "BITGET"}
{"action": "update", "arg": {"instType": "SPOT", "channel": "books", "instId": "BTCUSDT"}, "data": [{"asks": [["83923.05", "0.092775"], ["83923.24", "0"], ["83942.16", "0.054392"], ["83975.70", "0.025729"], ["83977.70", "0.067707"], ["83979.70", "0.178177"], ["83981.70", "0.468887"], ["83983.70", "1.233913"], ["83985.70", "3.247138"], ["83987.70", "8.545100"], ["83989.40", "0.027450"], ["83993.80", "0"], ["83995.80", "4.553670"], ["83995.90", "0"], ["84006.30", "0"], ["84029.60", "4.810369"], ["84038.00", "4.901131"], ["84046.40", "4.538084"], ["84054.80", "5.445701"], ["84063.20", "4.719607"], ["84071.60", "5.627224"], ["84080.00", "4.084276"], ["84088.40", "3.993514"], ["84096.80", "5.264177"], ["84105.20", "4.175037"], ["84113.60", "4.628846"], ["84122.00", "4.265799"], ["84130.40", "5.082654"], ["84138.80", "4.991892"], ["84147.20", "4.356561"], ["84155.60", "5.536462"], ["84164.00", "5.354939"], ["84172.40", "4.447322"], ["84180.80", "5.173416"], ["84189.20", "3.902752"], ["84340.46", "0.000143"], ["84340.72", "0.000066"]], "bids": [["83913.40", "0"], ["83884.00", "0"], ["83876.80", "0.207210"], ["83861.70", "5.082654"], ["83853.30", "5.536462"], ["83844.90", "3.902752"], ["83836.50", "4.538084"], ["83828.10", "4.628846"], ["83819.70", "4.901131"], ["83811.30", "5.445701"], ["83802.90", "4.356561"], ["83794.50", "4.175037"], ["83786.10", "3.993514"], ["83777.70", "4.265799"], ["83769.30", "5.173416"], ["83760.90", "5.264177"], ["83752.50", "5.627224"], ["83744.10", "4.084276"], ["83727.30", "4.447322"], ["83718.90", "4.719607"], ["83710.50", "4.991892"], ["83702.10", "4.810369"], ["83444.44", "0.000105"]], "checksum": -1376642656, "ts": "1742577153686"}], "ts": 1742577153690, "record_time": 1742577153.882826, "EXCHANGE": "BITGET"}
{"action": "update", "arg": {"instType": "SPOT", "channel": "books", "instId": "BTCUSDT"}, "data": [{"asks": [["83923.04", "0.062031"], ["83923.23", "0"], ["83983.70", "1.234154"], ["83985.70", "3.247775"], ["83987.70", "8.546774"], ["83989.40", "0.016260"], ["83991.30", "0.071550"], ["83991.90", "0"], ["83999.40", "0.012510"], ["84029.60", "4.265799"], ["84038.00", "5.173416"], ["84046.40", "5.264177"], ["84054.80", "5.627224"], ["84063.20", "4.810369"], ["84071.60", "4.991892"], ["84080.00", "5.536462"], ["84088.40", "4.084276"], ["84096.80", "4.175037"], ["84105.20", "3.902752"], ["84113.60", "3.993514"], ["84122.00", "4.447322"], ["84130.40", "4.356561"], ["84138.80", "4.719607"], ["84147.20", "5.082654"], ["84155.60", "4.628846"], ["84164.00", "4.901131"], ["84172.40", "5.354939"], ["84180.80", "4.538084"], ["84189.20", "5.445701"]], "bids": [["83909.60", "0.168173"], ["83905.60", "1.164637"], ["83903.60", "3.064834"], ["83899.80", "0.160920"], ["83897.10", "0"], ["83861.70", "5.264177"], ["83853.30", "3.993514"], ["83844.90", "5.445701"], ["83836.50", "5.082654"], ["83828.10", "5.627224"], ["83819.70", "4.538084"], ["83811.30", "5.354939"], ["83802.90", "5.536462"], ["83794.50", "4.265799"], ["83786.10", "5.173416"], ["83777.70", "4.356561"], ["83769.30", "3.902752"], ["83760.90", "4.901131"], ["83752.50", "4.719607"], ["83735.70", "4.447322"], ["83727.30", "4.628846"], ["83718.90", "4.175037"], ["83710.50", "4.810369"], ["83702.10", "4.991892"]], "checksum": 2032741255, "ts": "1742577153894"}], "ts": 1742577153898, "record_time": 1742577154.099165, "EXCHANGE": "BITGET"}
{"action": "update", "arg": {"instType": "SPOT", "channel": "books", "instId": "BTCUSDT"}, "data": [{"asks": [["83918.03", "0.814011"], ["83988.30", "0.100380"], ["83989.10", "0"], ["83989.40", "0"], ["84029.60", "5.082654"], ["84038.00", "4.538084"], ["84046.40", "5.445701"], ["84054.80", "3.902752"], ["84063.20", "4.447322"], ["84080.00", "5.354939"], ["84088.40", "4.719607"], ["84096.80", "4.901131"], ["84105.20", "5.627224"], ["84113.60", "4.084276"], ["84122.00", "4.265799"], ["84138.80", "5.536462"], ["84147.20", "5.264177"], ["84155.60", "3.993514"], ["84164.00", "4.810369"], ["84172.40", "4.628846"], ["84180.80", "5.173416"], ["84189.20", "4.175037"], ["84341.00", "0.002997"]], "bids": [["83907.60", "0.442387"], ["83905.60", "1.164177"], ["83903.60", "3.063625"], ["83868.00", "0"], ["83866.00", "0.000121"], ["83861.70", "5.536462"], ["83853.30", "5.627224"], ["83844.90", "5.264177"], ["83836.50", "4.538084"], ["83828.10", "4.265799"], ["83819.70", "3.902752"], ["83811.30", "4.810369"], ["83802.90", "3.993514"], ["83794.50", "5.354939"], ["83786.10", "4.901131"], ["83769.30", "5.173416"], ["83760.90", "4.719607"], ["83752.50", "4.447322"], ["83735.70", "4.628846"], ["83727.30", "5.082654"], ["83718.90", "5.445701"], ["83710.50", "4.991892"], ["83702.10", "4.175037"]], "checksum": -1869109024, "ts": "1742577154095"}], "ts": 1742577154098, "record_time": 1742577154.291666, "EXCHANGE": "BITGET"}
{"action": "update", "arg": {"instType": "SPOT", "channel": "books", "instId": "BTCUSDT"}, "data": [{"asks": [["83922.86", "0.092775"], ["83923.05", "0"], ["83957.12", "0.010988"], ["83963.26", "0"], ["83963.50", "0"], ["83988.30", "0"], ["83989.10", "0.001020"], ["83989.40", "0.001026"], ["83999.90", "0.178680"], ["84029.60", "5.627224"], ["84038.00", "5.264177"], ["84046.40", "4.810369"], ["84054.80", "3.993514"], ["84063.20", "4.265799"], ["84071.60", "5.173416"], ["84080.00", "4.719607"], ["84088.40", "4.991892"], ["84096.80", "4.538084"], ["84105.20", "4.084276"], ["84113.60", "5.082654"], ["84122.00", "5.445701"], ["84130.40", "5.354939"], ["84138.80", "4.175037"], ["84147.20", "5.536462"], ["84155.60", "4.901131"], ["84164.00", "3.902752"], ["84180.80", "4.356561"], ["84189.20", "4.447322"], ["84341.00", "0"]], "bids": [["83917.60", "0.002922"], ["83915.60", "0.007689"], ["83913.60", "0.020236"], ["83911.60", "0.053252"], ["83909.60", "0.140137"], ["83907.60", "0.368782"], ["83905.60", "0.970479"], ["83903.60", "2.553892"], ["83900.50", "0.132150"], ["83894.20", "0"], ["83894.00", "0"], ["83893.40", "0"], ["83893.00", "0"], ["83886.63", "0.056465"], ["83861.70", "4.175037"], ["83853.30", "4.810369"], ["83844.90", "5.627224"], ["83836.50", "5.173416"], ["83828.10", "4.447322"], ["83819.70", "4.991892"], ["83811.30", "3.993514"], ["83802.90", "4.084276"], ["83794.50", "4.265799"], ["83786.10", "4.628846"], ["83777.70", "4.719607"], ["83769.30", "5.082654"], ["83760.90", "4.538084"], ["83752.50", "3.902752"], ["83744.10", "4.901131"], ["83735.70", "5.264177"], ["83727.30", "5.354939"], ["83718.90", "5.536462"], ["83710.50", "5.445701"], ["83702.10", "4.356561"], ["83444.38", "0.000025"], ["83444.27", "0.000028"], ["83443.53", "0.000161"]], "checksum": -2034030074, "ts": "1742577154295"}], "ts": 1742577154299, "record_time": 1742577154.492631, "EXCHANGE": "BITGET"}
{"action": "update", "arg": {"instType": "SPOT", "channel": "books", "instId": "BTCUSDT"}, "data": [{"asks": [["83922.85", "0.062031"], ["83923.04", "0"], ["83983.70", "1.233835"], ["83985.70", "3.246933"], ["83987.70", "8.544561"], ["83992.00", "0.155040"], ["84029.60", "4.265799"], ["84038.00", "4.538084"], ["84046.40", "5.082654"], ["84054.80", "5.354939"], ["84063.20", "4.991892"], ["84071.60", "4.447322"], ["84088.40", "3.902752"], ["84096.80", "5.173416"], ["84105.20", "5.627224"], ["84113.60", "4.084276"], ["84122.00", "5.536462"], ["84130.40", "4.628846"], ["84138.80", "5.445701"], ["84147.20", "4.175037"], ["84155.60", "4.356561"], ["84164.00", "5.264177"], ["84172.40", "4.901131"], ["84180.80", "3.993514"], ["84189.20", "4.810369"]], "bids": [["83918.02", "1.155848"], ["83917.90", "0.113988"], ["83917.60", "0.002068"], ["83915.60", "0.005443"], ["83913.60", "0.014324"], ["83911.60", "0.037695"], ["83909.60", "0.099196"], ["83907.60", "0.261042"], ["83905.60", "0.686953"], ["83903.60", "1.807771"], ["83902.90", "0.845700"], ["83902.70", "0"], ["83894.20", "0.120000"], ["83894.00", "0.042300"], ["83893.40", "0.240000"], ["83861.70", "4.447322"], ["83853.30", "4.356561"], ["83844.90", "4.628846"], ["83836.50", "5.445701"], ["83828.10", "5.173416"], ["83819.70", "5.082654"], ["83802.90", "4.265799"], ["83794.50", "3.902752"], ["83786.10", "4.719607"], ["83777.70", "4.084276"], ["83769.30", "4.810369"], ["83752.50", "5.264177"], ["83744.10", "4.991892"], ["83735.70", "4.175037"], ["83727.30", "5.536462"], ["83718.90", "5.354939"], ["83710.50", "4.901131"], ["83702.10", "5.627224"], ["83444.44", "0"], ["83444.38", "0"], ["83444.27", "0"], ["83443.53", "0"]], "checksum": -2064208995, "ts": "1742577154497"}], "ts": 1742577154501, "record_time": 1742577154.700359, "EXCHANGE": "BITGET"}
{"action": "update", "arg": {"instType": "SPOT", "channel": "books", "instId": "BTCUSDT"}, "data": [{"asks": [["83922.86", "0"], ["83955.94", "0.008065"], ["83989.10", "0.098610"], ["83989.40", "0.027300"], ["83991.90", "0.015000"], ["83999.40", "0"], ["83999.90", "0"], ["84029.60", "4.628846"], ["84038.00", "5.082654"], ["84046.40", "4.175037"], ["84054.80", "4.991892"], ["84063.20", "5.536462"], ["84071.60", "3.993514"], ["84080.00", "4.265799"], ["84088.40", "5.173416"], ["84096.80", "5.264177"], ["84113.60", "4.719607"], ["84122.00", "4.901131"], ["84130.40", "5.354939"], ["84138.80", "3.902752"], ["84147.20", "4.447322"], ["84155.60", "4.538084"], ["84164.00", "4.356561"], ["84172.40", "4.810369"], ["84180.80", "4.084276"], ["84189.20", "5.445701"], ["84341.00", "0.002997"]], "bids": [["83911.60", "0.037593"], ["83909.61", "0.073727"], ["83909.60", "0.098930"], ["83907.60", "0.260341"], ["83905.77", "0"], ["83905.60", "0.685108"], ["83903.60", "1.802917"], ["83866.00", "0.000281"], ["83861.70", "5.627224"], ["83853.30", "4.175037"], ["83844.90", "4.538084"], ["83836.50", "5.354939"], ["83828.10", "5.082654"], ["83819.70", "5.264177"], ["83811.30", "4.991892"], ["83786.10", "4.810369"], ["83777.70", "3.993514"], ["83769.30", "4.084276"], ["83760.90", "4.628846"], ["83752.50", "5.445701"], ["83744.10", "5.173416"], ["83735.70", "4.356561"], ["83727.30", "4.719607"], ["83718.90", "4.447322"], ["83710.50", "5.536462"], ["83702.10", "4.901131"], ["83444.44", "0.000105"]], "checksum": 1741552091, "ts": "1742577154707"}], "ts": 1742577154710, "record_time": 1742577154.903363, "EXCHANGE": "BITGET"}
{"action": "update", "arg": {"instType": "SPOT", "channel": "books", "instId": "BTCUSDT"}, "data": [{"asks": [["83922.69", "0.092775"], ["83922.85", "0.034198"], ["83989.40", "0.003720"], ["83991.30", "0.073440"], ["83997.90", "0.192000"], ["83998.80", "0.092970"], ["84029.60", "4.447322"], ["84038.00", "5.354939"], ["84054.80", "5.082654"], ["84063.20", "5.627224"], ["84080.00", "5.173416"], ["84088.40", "4.356561"], ["84096.80", "3.902752"], ["84105.20", "4.628846"], ["84113.60", "4.991892"], ["84122.00", "4.810369"], ["84130.40", "4.265799"], ["84138.80", "4.084276"], ["84147.20", "4.538084"], ["84155.60", "5.445701"], ["84164.00", "5.536462"], ["84172.40", "5.264177"], ["84180.80", "4.901131"], ["84189.20", "4.719607"], ["84340.72", "0"], ["84341.00", "0"]], "bids": [["83917.60", "0.001771"], ["83915.60", "0.004661"], ["83913.60", "0.012500"], ["83911.60", "0.032895"], ["83909.60", "0.086565"], ["83907.60", "0.227802"], ["83905.61", "0.747052"], ["83905.60", "0.599479"], ["83903.60", "1.577578"], ["83867.00", "0.000160"], ["83861.70", "3.993514"], ["83853.30", "4.084276"], ["83844.90", "4.810369"], ["83836.50", "5.173416"], ["83828.10", "4.628846"], ["83819.70", "4.447322"], ["83802.90", "4.719607"], ["83794.50", "4.265799"], ["83791.71", "0.012426"], ["83789.89", "0.012426"], ["83786.10", "3.902752"], ["83777.70", "4.538084"], ["83769.30", "4.356561"], ["83767.45", "0"], ["83765.63", "0"], ["83760.90", "5.445701"], ["83752.50", "5.536462"], ["83744.10", "5.354939"], ["83735.70", "5.082654"], ["83727.30", "5.264177"], ["83718.90", "4.175037"], ["83710.50", "5.627224"], ["83444.44", "0"]], "checksum": 1245295345, "ts": "1742577154923"}], "ts": 1742577154927, "record_time": 1742577155.124794, "EXCHANGE": "BITGET"}
{"action": "update", "arg": {"instType": "SPOT", "channel": "books", "instId": "BTCUSDT"}, "data": [{"asks": [["83922.68", "0.062031"], ["83922.69", "0"], ["83922.85", "0"], ["83981.70", "0.468765"], ["83983.70", "1.233593"], ["83985.70", "3.246297"], ["83987.70", "8.542887"], ["83989.40", "0"], ["83996.90", "0.204000"], ["83998.80", "0"], ["84029.60", "5.445701"], ["84038.00", "4.356561"], ["84046.40", "5.354939"], ["84054.80", "4.538084"], ["84063.20", "5.082654"], ["84071.60", "4.991892"], ["84080.00", "3.902752"], ["84088.40", "4.447322"], ["84096.80", "5.264177"], ["84105.20", "4.084276"], ["84113.60", "5.173416"], ["84122.00", "4.175037"], ["84130.40", "4.719607"], ["84138.80", "4.628846"], ["84147.20", "4.265799"], ["84155.60", "3.993514"], ["84164.00", "5.627224"], ["84172.40", "5.536462"], ["84180.80", "4.810369"], ["84189.20", "4.901131"], ["84340.72", "0.000066"], ["84341.00", "0.002997"]], "bids": [["83917.60", "0.002684"], ["83915.60", "0.007062"], ["83913.60", "0.018586"], ["83911.60", "0.048909"], ["83909.60", "0.128871"], ["83907.60", "0.339375"], ["83905.60", "0.893091"], ["83903.60", "2.350240"], ["83902.40", "0"], ["83894.40", "0.874020"], ["83893.30", "0.120000"], ["83853.30", "3.902752"], ["83844.90", "5.082654"], ["83836.50", "4.265799"], ["83828.10", "5.627224"], ["83819.70", "5.264177"], ["83811.30", "4.447322"], ["83802.90", "4.628846"], ["83794.50", "4.810369"], ["83786.10", "4.084276"], ["83777.70", "4.719607"], ["83769.30", "5.536462"], ["83760.90", "4.175037"], ["83752.50", "4.356561"], ["83744.10", "5.445701"], ["83735.70", "5.354939"], ["83727.30", "4.538084"], ["83718.90", "4.991892"], ["83710.50", "5.173416"]], "checksum": -1623928076, "ts": "1742577155144"}], "ts": 1742577155147, "record_time": 1742577155.340893, "EXCHANGE": "BITGET"}
{"action": "update", "arg": {"instType": "SPOT", "channel": "books", "instId": "BTCUSDT"}, "data": [{"asks": [["83922.53", "0.092775"], ["83922.68", "0.034198"], ["83996.10", "1.638000"], ["83997.80", "0.432000"], ["84029.60", "5.354939"], ["84038.00", "4.628846"], ["84046.40", "4.810369"], ["84054.80", "5.627224"], ["84063.20", "4.991892"], ["84071.60", "4.175037"], ["84080.00", "4.719607"], ["84088.40", "5.445701"], ["84096.80", "3.902752"], ["84105.20", "4.447322"], ["84113.60", "4.538084"], ["84122.00", "5.536462"], ["84130.40", "4.901131"], ["84138.80", "5.264177"], ["84147.20", "4.084276"], ["84155.60", "4.356561"], ["84164.00", "5.082654"], ["84172.40", "5.173416"], ["84180.80", "4.265799"], ["84189.20", "3.993514"], ["84340.72", "0"], ["84341.00", "0"]], "bids": [["83917.60", "0.002943"], ["83915.60", "0.007744"], ["83913.60", "0.020379"], ["83911.60", "0.053628"], ["83909.61", "0.131258"], ["83909.60", "0.141126"], ["83907.60", "0.371384"], ["83905.60", "0.977328"], ["83903.60", "2.571915"], ["83893.00", "0.012360"], ["83867.00", "0"], ["83861.70", "5.173416"], ["83853.30", "4.628846"], ["83836.50", "4.356561"], ["83828.10", "4.175037"], ["83819.70", "5.627224"], ["83811.30", "4.265799"], ["83802.90", "4.447322"], ["83794.50", "3.902752"], ["83786.10", "5.536462"], ["83777.70", "4.084276"], ["83769.30", "4.719607"], ["83760.90", "5.445701"], ["83752.50", "3.993514"], ["83744.10", "5.354939"], ["83735.70", "4.901131"], ["83718.90", "5.264177"], ["83710.50", "4.991892"], ["83702.10", "4.810369"], ["83545.47", "0"], ["83444.44", "0.000105"]], "checksum": 1204664723, "ts": "1742577155355"}], "ts": 1742577155358, "record_time": 1742577155.553818, "EXCHANGE": "BITGET"}
{"action": "update", "arg": {"instType": "SPOT", "channel": "books", "instId": "BTCUSDT"}, "data": [{"asks": [["83922.52", "0.062031"], ["83922.68", "0"], ["83973.70", "0.009519"], ["83975.70", "0.025050"], ["83977.70", "0.065921"], ["83979.70", "0.173475"], ["83981.70", "0.456513"], ["83983.70", "1.201352"], ["83985.70", "3.161453"], ["83987.70", "8.319613"], ["83989.10", "0.001023"], ["83989.40", "0.001039"], ["83992.00", "0.082350"], ["83998.80", "0.092970"], ["84029.60", "4.084276"], ["84038.00", "3.993514"], ["84046.40", "5.354939"], ["84054.80", "4.538084"], ["84063.20", "5.445701"], ["84080.00", "5.264177"], ["84088.40", "4.901131"], ["84096.80", "5.082654"], ["84105.20", "4.265799"], ["84113.60", "5.627224"], ["84122.00", "4.447322"], ["84130.40", "4.810369"], ["84138.80", "5.173416"], ["84147.20", "4.991892"], ["84155.60", "4.628846"], ["84164.00", "3.902752"], ["84172.40", "4.719607"], ["84180.80", "4.356561"], ["84189.20", "5.536462"], ["84340.00", "0"], ["84340.46", "0"]], "bids": [["83917.60", "0.002944"], ["83915.60", "0.007748"], ["83913.60", "0.020387"], ["83911.60", "0.053652"], ["83909.60", "0.141188"], ["83907.60", "0.371548"], ["83905.60", "0.977759"], ["83903.60", "2.573050"], ["83902.91", "0.694929"], ["83868.00", "0.000121"], ["83853.30", "4.719607"], ["83844.90", "5.264177"], ["83836.50", "5.354939"], ["83828.10", "4.991892"], ["83819.70", "5.082654"], ["83811.30", "4.810369"], ["83802.90", "3.993514"], ["83794.50", "5.536462"], ["83786.10", "5.627224"], ["83777.70", "4.356561"], ["83769.30", "4.447322"], ["83760.90", "4.538084"], ["83752.50", "3.902752"], ["83744.10", "4.265799"], ["83735.70", "4.628846"], ["83727.30", "4.084276"], ["83718.90", "4.175037"], ["83710.50", "4.901131"], ["83702.10", "5.445701"], ["83582.34", "0.001538"], ["83445.30", "0"], ["83445.16", "0"], ["83444.44", "0"]], "checksum": 290339144, "ts": "1742577155558"}], "ts": 1742577155563, "record_time": 1742577155.755744, "EXCHANGE": "BITGET"}
{"action": "update", "arg": {"instType": "SPOT", "channel": "books", "instId": "BTCUSDT"}, "data": [{"asks": [["83922.36", "0.092781"], ["83922.53", "0"], ["83971.70", "0.003491"], ["83973.70", "0.009187"], ["83975.70", "0.024175"], ["83977.70", "0.063618"], ["83979.70", "0.167416"], ["83981.70", "0.440569"], ["83983.70", "1.159391"], ["83985.70", "3.051029"], ["83987.70", "8.029025"], ["83998.80", "0"], ["84029.60", "4.447322"], ["84038.00", "4.628846"], ["84046.40", "4.991892"], ["84054.80", "4.719607"], ["84063.20", "4.538084"], ["84080.00", "4.901131"], ["84088.40", "4.356561"], ["84096.80", "3.993514"], ["84113.60", "5.173416"], ["84122.00", "5.536462"], ["84138.80", "5.082654"], ["84147.20", "5.445701"], ["84155.60", "5.627224"], ["84164.00", "4.084276"], ["84172.40", "5.264177"], ["84180.80", "3.902752"], ["84189.20", "5.354939"], ["84340.00", "0.018287"]], "bids": [["83918.02", "1.155504"], ["83917.60", "0.004285"], ["83915.60", "0.011278"], ["83913.60", "0.029679"], ["83911.60", "0.078103"], ["83909.60", "0.205533"], ["83907.60", "0.540877"], ["83905.60", "1.423361"], ["83903.60", "3.745687"], ["83896.81", "0.199048"], ["83893.00", "0.492360"], ["83861.70", "4.356561"], ["83853.30", "4.084276"], ["83844.90", "4.991892"], ["83836.50", "5.536462"], ["83828.10", "5.445701"], ["83819.70", "4.810369"], ["83811.30", "4.719607"], ["83802.90", "4.538084"], ["83794.50", "4.447322"], ["83786.10", "3.902752"], ["83777.70", "5.354939"], ["83769.30", "4.265799"], ["83760.90", "5.264177"], ["83752.50", "4.628846"], ["83744.10", "5.173416"], ["83735.70", "5.627224"], ["83727.30", "3.993514"], ["83702.10", "5.082654"], ["83446.43", "0"]], "checksum": -889374659, "ts": "1742577155767"}], "ts": 1742577155769, "record_time": 1742577155.966952, "EXCHANGE": "BITGET"}
{"action": "update", "arg": {"instType": "SPOT", "channel": "books", "instId": "BTCUSDT"}, "data": [{"asks": [["83922.35", "0.062033"], ["83922.52", "0"], ["83944.67", "0.006357"], ["83945.17", "0.010995"], ["83945.57", "0"], ["83946.08", "0"], ["83951.46", "0.119858"], ["83952.36", "0"], ["83969.70", "0.001326"], ["83971.70", "0.003488"], ["83973.70", "0.009436"], ["83975.70", "0.024830"], ["83977.70", "0.065343"], ["83979.70", "0.171955"], ["83981.70", "0.452514"], ["83983.70", "1.190827"], ["83985.70", "3.133753"], ["83987.70", "8.246719"], ["83992.40", "0.474870"], ["84029.60", "5.536462"], ["84046.40", "4.538084"], ["84054.80", "5.173416"], ["84063.20", "4.901131"], ["84071.60", "3.902752"], ["84080.00", "4.265799"], ["84088.40", "4.991892"], ["84096.80", "5.354939"], ["84105.20", "4.447322"], ["84113.60", "4.719607"], ["84122.00", "5.627224"], ["84130.40", "4.356561"], ["84138.80", "5.264177"], ["84147.20", "4.084276"], ["84155.60", "5.445701"], ["84164.00", "3.993514"], ["84172.40", "4.810369"], ["84180.80", "4.175037"], ["84189.20", "5.082654"]], "bids": [["83917.60", "0.002068"], ["83915.60", "0.005442"], ["83913.60", "0.014322"], ["83911.60", "0.037690"], ["83909.61", "0.207516"], ["83909.60", "0.099185"], ["83907.60", "0.261013"], ["83905.60", "0.686875"], ["83903.60", "1.807567"], ["83899.08", "0"], ["83898.41", "0"], ["83898.18", "0.016433"], ["83897.50", "0.055637"], ["83892.27", "0"], ["83891.37", "0.223055"], ["83868.00", "0.000281"], ["83861.70", "5.536462"], ["83853.30", "5.627224"], ["83844.90", "4.084276"], ["83836.50", "4.901131"], ["83828.10", "4.356561"], ["83819.70", "5.354939"], ["83811.30", "3.993514"], ["83802.90", "4.175037"], ["83794.50", "4.538084"], ["83786.10", "4.810369"], ["83777.70", "4.447322"], ["83769.30", "3.902752"], ["83760.90", "4.628846"], ["83752.50", "4.265799"], ["83744.10", "5.264177"], ["83735.70", "5.445701"], ["83727.30", "5.173416"], ["83718.90", "5.082654"], ["83710.50", "4.991892"], ["83702.10", "4.719607"]], "checksum": 1785779145, "ts": "1742577155969"}], "ts": 1742577155972, "record_time": 1742577156.174706, "EXCHANGE": "BITGET"}
{"action": "update", "arg": {"instType": "SPOT", "channel": "books", "instId": "BTCUSDT"}, "data": [{"asks": [["83973.70", "0.009299"], ["83975.70", "0.024472"], ["83977.70", "0.064399"], ["83979.70", "0.169471"], ["83981.70", "0.445978"], ["83983.70", "1.173626"], ["83985.70", "3.088490"], ["83987.70", "8.127605"], ["83989.10", "0.099630"], ["83989.40", "0"], ["84029.60", "3.902752"], ["84038.00", "4.447322"], ["84046.40", "5.627224"], ["84054.80", "4.175037"], ["84063.20", "4.628846"], ["84071.60", "3.993514"], ["84080.00", "4.084276"], ["84088.40", "5.082654"], ["84096.80", "4.991892"], ["84105.20", "4.538084"], ["84113.60", "4.901131"], ["84122.00", "4.356561"], ["84130.40", "5.445701"], ["84138.80", "4.265799"], ["84147.20", "5.354939"], ["84155.60", "4.810369"], ["84164.00", "5.264177"], ["84172.40", "5.536462"], ["84180.80", "5.173416"], ["84189.20", "4.719607"], ["84340.46", "0.000143"]], "bids": [["83909.61", "0.108059"], ["83907.60", "0.261008"], ["83905.60", "0.686861"], ["83903.60", "1.807529"], ["83898.00", "0.109080"], ["83866.00", "0.000160"], ["83861.70", "5.627224"], ["83853.30", "4.265799"], ["83844.90", "4.810369"], ["83828.10", "5.173416"], ["83819.70", "4.447322"], ["83811.30", "4.356561"], ["83802.90", "5.082654"], ["83794.50", "4.991892"], ["83786.10", "5.536462"], ["83777.70", "4.084276"], ["83760.90", "4.175037"], ["83752.50", "4.538084"], ["83744.10", "4.719607"], ["83735.70", "5.264177"], ["83727.30", "5.354939"], ["83718.90", "4.628846"], ["83710.50", "5.445701"], ["83702.10", "3.993514"]], "checksum": 837330261, "ts": "1742577156172"}], "ts": 1742577156177, "record_time": 1742577156.372114, "EXCHANGE": "BITGET"}
{"action": "update", "arg": {"instType": "SPOT", "channel": "books", "instId": "BTCUSDT"}, "data": [{"asks": [["83922.20", "0.092781"], ["83922.36", "0"], ["83989.10", "0.001030"], ["83989.40", "0.001022"], ["83991.90", "0.030000"], ["83992.20", "0.072870"], ["84029.60", "4.356561"], ["84038.00", "4.538084"], ["84046.40", "4.901131"], ["84054.80", "4.447322"], ["84063.20", "5.082654"], ["84071.60", "5.354939"], ["84080.00", "4.991892"], ["84088.40", "4.719607"], ["84096.80", "4.265799"], ["84105.20", "4.628846"], ["84113.60", "5.627224"], ["84122.00", "3.993514"], ["84130.40", "4.810369"], ["84138.80", "3.902752"], ["84147.20", "5.445701"], ["84155.60", "5.264177"], ["84164.00", "4.175037"], ["84172.40", "5.173416"], ["84180.80", "4.084276"], ["84189.20", "5.536462"], ["84340.00", "0"], ["84340.46", "0"]], "bids": [["83896.81", "0.222247"], ["83853.30", "3.993514"], ["83844.90", "4.538084"], ["83836.50", "5.536462"], ["83828.10", "4.356561"], ["83819.70", "4.719607"], ["83811.30", "4.810369"], ["83794.50", "4.265799"], ["83786.10", "5.445701"], ["83777.70", "4.991892"], ["83769.30", "5.354939"], ["83752.50", "5.173416"], ["83744.10", "5.264177"], ["83735.70", "4.084276"], ["83727.30", "4.901131"], ["83718.90", "4.447322"], ["83710.50", "3.902752"], ["83702.10", "4.628846"]], "checksum": 907044784, "ts": "1742577156375"}], "ts": 1742577156380, "record_time": 1742577156.573805, "EXCHANGE": "BITGET"}
{"action": "update", "arg": {"instType": "SPOT", "channel": "books", "instId": "BTCUSDT"}, "data": [{"asks": [["83922.19", "0.062033"], ["83922.35", "0"], ["84011.83", "0.000179"], ["84013.80", "0"], ["84029.60", "5.354939"], ["84038.00", "5.082654"], ["84046.40", "4.538084"], ["84054.80", "5.627224"], ["84063.20", "5.173416"], ["84071.60", "5.536462"], ["84080.00", "4.265799"], ["84088.40", "4.810369"], ["84096.80", "3.902752"], ["84105.20", "5.264177"], ["84113.60", "4.901131"], ["84122.00", "4.356561"], ["84130.40", "4.719607"], ["84138.80", "4.084276"], ["84147.20", "4.628846"], ["84155.60", "4.447322"], ["84164.00", "3.993514"], ["84172.40", "4.991892"], ["84180.80", "5.445701"], ["84189.20", "4.175037"]], "bids": [["83918.02", "1.153802"], ["83917.60", "0.002982"], ["83915.60", "0.007849"], ["83913.60", "0.020654"], ["83911.60", "0.054354"], ["83909.60", "0.143036"], ["83907.60", "0.376409"], ["83905.60", "0.990552"], ["83903.60", "2.606716"], ["83861.70", "4.447322"], ["83853.30", "5.264177"], ["83845.65", "0"], ["83844.90", "5.536462"], ["83843.68", "0.000172"], ["83836.50", "5.082654"], ["83828.10", "4.991892"], ["83819.70", "4.538084"], ["83811.30", "4.719607"], ["83802.90", "4.356561"], ["83794.50", "5.445701"], ["83786.10", "5.627224"], ["83777.70", "3.993514"], ["83769.30", "4.265799"], ["83760.90", "4.810369"], ["83744.10", "4.628846"], ["83735.70", "4.175037"], ["83718.90", "4.084276"], ["83710.50", "5.354939"], ["83702.10", "3.902752"]], "checksum": -629029324, "ts": "1742577156600"}], "ts": 1742577156603, "record_time": 1742577156.796785, "EXCHANGE": "BITGET"}
{"action": "update", "arg": {"instType": "SPOT", "channel": "books", "instId": "BTCUSDT"}, "data": [{"asks": [["83922.19", "0"], ["83922.20", "0"], ["83992.20", "0"], ["84029.60", "5.082654"], ["84038.00", "5.627224"], ["84046.40", "4.447322"], ["84054.80", "4.538084"], ["84063.20", "4.356561"], ["84071.60", "4.810369"], ["84080.00", "3.993514"], ["84088.40", "4.901131"], ["84105.20", "5.445701"], ["84113.60", "4.175037"], ["84122.00", "5.264177"], ["84130.40", "5.173416"], ["84138.80", "4.719607"], ["84147.20", "4.991892"], ["84155.60", "5.354939"], ["84164.00", "4.265799"], ["84172.40", "4.628846"], ["84180.80", "5.536462"], ["84189.20", "4.084276"], ["84340.00", "0.018287"], ["84340.46", "0.000143"], ["84340.72", "0.000066"]], "bids": [["83866.00", "0"], ["83861.70", "5.445701"], ["83853.30", "4.538084"], ["83844.90", "3.902752"], ["83836.50", "4.991892"], ["83828.10", "4.719607"], ["83819.70", "4.901131"], ["83811.30", "5.354939"], ["83802.90", "5.536462"], ["83794.50", "4.356561"], ["83786.10", "5.173416"], ["83777.70", "5.082654"], ["83769.30", "5.627224"], ["83760.90", "4.084276"], ["83752.50", "4.447322"], ["83744.10", "4.810369"], ["83735.70", "5.264177"], ["83727.30", "4.265799"], ["83718.90", "4.175037"], ["83710.50", "3.993514"], ["83702.10", "4.628846"], ["83446.43", "0.000016"]], "checksum": 447884368, "ts": "1742577156814"}], "ts": 1742577156817, "record_time": 1742577157.0143, "EXCHANGE": "BITGET"}
{"action": "update", "arg": {"instType": "SPOT", "channel": "books", "instId": "BTCUSDT"}, "data": [{"asks": [["83918.03", "0.796155"], ["83922.06", "0.092781"], ["83923.70", "0.034198"], ["83969.81", "0.010000"], ["83973.70", "0.009041"], ["83975.70", "0.023794"], ["83977.70", "0.062614"], ["83979.70", "0.164775"], ["83981.70", "0.433618"], ["83983.70", "1.141101"], ["83985.70", "3.002896"], ["83987.70", "7.902359"], ["84029.60", "4.991892"], ["84038.00", "5.354939"], ["84046.40", "5.264177"], ["84054.80", "4.901131"], ["84063.20", "4.538084"], ["84071.60", "5.536462"], ["84088.40", "5.445701"], ["84096.80", "5.173416"], ["84105.20", "4.810369"], ["84122.00", "4.719607"], ["84130.40", "4.265799"], ["84138.80", "5.082654"], ["84147.20", "4.084276"], ["84155.60", "3.902752"], ["84164.00", "4.447322"], ["84172.40", "5.627224"], ["84180.80", "4.356561"], ["84189.20", "4.628846"], ["84340.00", "0"], ["84340.46", "0"], ["84340.72", "0"]], "bids": [["83917.60", "0.004065"], ["83915.60", "0.010698"], ["83913.60", "0.028153"], ["83911.60", "0.074086"], ["83909.60", "0.194965"], ["83907.60", "0.513065"], ["83905.60", "1.350172"], ["83903.60", "3.553084"], ["83867.00", "0.000121"], ["83861.70", "3.902752"], ["83853.30", "5.627224"], ["83844.90", "4.447322"], ["83836.50", "4.175037"], ["83828.10", "4.265799"], ["83819.70", "5.264177"], ["83811.30", "4.628846"], ["83802.90", "4.901131"], ["83794.50", "3.993514"], ["83786.10", "4.719607"], ["83777.70", "5.536462"], ["83769.30", "4.810369"], ["83760.90", "5.082654"], ["83752.50", "5.445701"], ["83744.10", "4.991892"], ["83735.70", "4.538084"], ["83727.30", "5.354939"], ["83718.90", "4.084276"], ["83710.50", "4.356561"], ["83702.10", "5.173416"], ["83446.43", "0"]], "checksum": 1469967862, "ts": "1742577157027"}], "ts": 1742577157037, "record_time": 1742577157.231295, "EXCHANGE": "BITGET"}
{"action": "update", "arg": {"instType": "SPOT", "channel": "books", "instId": "BTCUSDT"}, "data": [{"asks": [["83922.05", "0.062033"], ["83923.70", "0"], ["83971.70", "0.003356"], ["83973.70", "0.008831"], ["83975.70", "0.023241"], ["83977.70", "0.061161"], ["83979.70", "0.160948"], ["83981.70", "0.423549"], ["83983.70", "1.114860"], ["83985.70", "2.933842"], ["83987.70", "7.720637"], ["83989.40", "0.101520"], ["83993.20", "0.688830"], ["84029.60", "3.902752"], ["84038.00", "4.175037"], ["84046.40", "5.536462"], ["84054.80", "5.173416"], ["84063.20", "5.082654"], ["84071.60", "4.538084"], ["84080.00", "4.991892"], ["84088.40", "4.447322"], ["84096.80", "4.356561"], ["84105.20", "5.354939"], ["84113.60", "4.810369"], ["84122.00", "5.627224"], ["84138.80", "4.719607"], ["84147.20", "4.628846"], ["84155.60", "4.901131"], ["84164.00", "3.993514"], ["84172.40", "5.264177"], ["84180.80", "5.445701"], ["84189.20", "4.084276"], ["84339.62", "0"]], "bids": [["83917.60", "0.002983"], ["83915.60", "0.007850"], ["83913.60", "0.020658"], ["83911.60", "0.054363"], ["83909.61", "0.198902"], ["83909.60", "0.143059"], ["83907.60", "0.376471"], ["83905.60", "0.990715"], ["83903.60", "2.607143"], ["83861.70", "4.175037"], ["83853.30", "4.084276"], ["83844.90", "4.265799"], ["83836.50", "4.901131"], ["83828.10", "5.627224"], ["83819.70", "4.356561"], ["83802.90", "4.810369"], ["83794.50", "5.445701"], ["83786.10", "5.264177"], ["83777.70", "3.902752"], ["83769.30", "3.993514"], ["83760.90", "4.991892"], ["83752.50", "5.173416"], ["83744.10", "5.354939"], ["83735.70", "4.447322"], ["83727.30", "4.538084"], ["83718.90", "5.082654"], ["83710.50", "4.719607"], ["83702.10", "5.536462"]], "checksum": 161252663, "ts": "1742577157230"}], "ts": 1742577157232, "record_time": 1742577157.424717, "EXCHANGE": "BITGET"}
{"action": "update", "arg": {"instType": "SPOT", "channel": "books", "instId": "BTCUSDT"}, "data": [{"asks": [["83921.91", "0.092781"], ["83922.06", "0"], ["83946.82", "0"], ["83949.64", "0"], ["83981.70", "0.423738"], ["83983.70", "1.115102"], ["83985.70", "2.934478"], ["83987.70", "7.722311"], ["83994.00", "2.359620"], ["83995.80", "1.821570"], ["84029.60", "5.536462"], ["84038.00", "5.264177"], ["84046.40", "5.082654"], ["84054.80", "4.447322"], ["84063.20", "4.901131"], ["84071.60", "5.173416"], ["84080.00", "4.538084"], ["84088.40", "4.084276"], ["84096.80", "4.175037"], ["84105.20", "4.991892"], ["84113.60", "4.265799"], ["84130.40", "5.354939"], ["84138.80", "4.810369"], ["84147.20", "3.902752"], ["84155.60", "4.628846"], ["84164.00", "4.356561"], ["84172.40", "5.445701"], ["84180.80", "3.993514"], ["84189.20", "4.719607"], ["84339.62", "0.000051"]], "bids": [["83918.02", "0.884302"], ["83917.60", "0.002107"], ["83915.60", "0.005437"], ["83913.60", "0.014308"], ["83911.60", "0.037652"], ["83909.60", "0.099085"], ["83907.60", "0.260492"], ["83905.60", "0.685504"], ["83903.60", "1.803958"], ["83896.30", "0.020990"], ["83893.41", "0"], ["83893.00", "0.012360"], ["83867.00", "0.000281"], ["83861.70", "4.628846"], ["83853.30", "5.627224"], ["83844.90", "4.810369"], ["83836.50", "4.447322"], ["83828.10", "4.175037"], ["83819.70", "3.902752"], ["83811.30", "4.265799"], ["83802.90", "5.445701"], ["83794.50", "5.264177"], ["83786.10", "4.084276"], ["83777.70", "5.173416"], ["83769.30", "4.538084"], ["83760.90", "5.536462"], ["83752.50", "5.354939"], ["83744.10", "4.719607"], ["83735.70", "5.082654"], ["83727.30", "4.901131"], ["83718.90", "3.993514"], ["83710.50", "4.991892"], ["83702.10", "4.356561"], ["83446.43", "0.000016"]], "checksum": 1386685112, "ts": "1742577157437"}], "ts": 1742577157440, "record_time": 1742577157.642756, "EXCHANGE": "BITGET"}
{"action": "update", "arg": {"instType": "SPOT", "channel": "books", "instId": "BTCUSDT"}, "data": [{"asks": [["83918.03", "1.414338"], ["83919.52", "0.113982"], ["83922.05", "0"], ["83923.71", "0"], ["83936.30", "0.035971"], ["83936.65", "0.119905"], ["83938.01", "0.035972"], ["83938.46", "0.006357"], ["83938.59", "0.006357"], ["83938.72", "0.006357"], ["83939.12", "0.006357"], ["83939.79", "0.010995"], ["83939.91", "0.006357"], ["83940.12", "0.006356"], ["83940.36", "0.006357"], ["83940.91", "0.022786"], ["83941.01", "0.006357"], ["83941.45", "0.006357"], ["83941.46", "0.006357"], ["83941.64", "0.119901"], ["83941.81", "0.022786"], ["83941.85", "0.006357"], ["83941.86", "0"], ["83942.17", "0"], ["83942.76", "0.006357"], ["83943.41", "0"], ["83943.47", "0.010993"], ["83943.49", "0.006357"], ["83943.76", "0"], ["83943.97", "0"], ["83944.10", "0.009990"], ["83944.26", "0"], ["83944.69", "0"], ["83945.17", "0"], ["83945.22", "0.119850"], ["83945.47", "0"], ["83945.62", "0"], ["83945.85", "0"], ["83946.26", "0.119905"], ["83946.46", "0"], ["83946.47", "0"], ["83946.49", "0"], ["83946.53", "0.015895"], ["83946.78", "0"], ["83946.83", "0.009989"], ["83947.13", "0"], ["83947.14", "0"], ["83947.21", "0"], ["83947.37", "0"], ["83948.30", "0"], ["83948.69", "0.006356"], ["83948.79", "0"], ["83950.47", "0.015896"], ["83950.60", "0"], ["83951.75", "0"], ["83952.09", "0.314626"], ["83952.23", "0"], ["83954.26", "0"], ["83955.95", "0"], ["83962.10", "0"], ["83964.40", "0.001039"], ["83966.40", "0.001588"], ["83967.70", "0"], ["83968.40", "0.004302"], ["83969.70", "0"], ["83970.40", "0.011322"], ["83971.70", "0"], ["83972.40", "0.029793"], ["83973.70", "0"], ["83974.40", "0.078405"], ["83975.70", "0"], ["83976.40", "0.206328"], ["83977.70", "0"], ["83978.40", "0.542967"], ["83979.70", "0"], ["83980.40", "1.428861"], ["83981.70", "0"], ["83982.40", "3.760162"], ["83983.70", "0"], ["83984.40", "9.895163"], ["83984.50", "0.001021"], ["83984.60", "0.654900"], ["83985.70", "0"], ["83986.00", "0.042300"], ["83986.10", "0.035730"], ["83987.00", "0.250980"], ["83987.30", "1.977780"], ["83987.60", "1.350000"], ["83987.70", "4.194090"], ["83988.00", "0.042480"], ["83988.10", "0.071550"], ["83988.40", "0.269760"], ["83988.50", "1.429500"], ["83988.60", "0"], ["83988.90", "0"], ["83989.10", "0"], ["83989.50", "0"], ["83990.20", "0"], ["83991.10", "0.035730"], ["83991.30", "0"], ["83992.20", "0.072900"], ["83992.40", "0.009000"], ["83992.80", "0.090000"], ["83993.20", "0"], ["83993.40", "1.028730"], ["83993.50", "0"], ["83994.00", "0"], ["83994.40", "0"], ["83995.00", "0.022740"], ["83995.40", "0.787590"], ["83995.50", "1.072110"], ["83995.60", "0"], ["83995.80", "0"], ["83996.10", "0"], ["83996.60", "0"], ["83996.90", "0"], ["83997.70", "0"], ["83997.80", "0"], ["83997.90", "0"], ["84026.40", "5.355147"], ["84029.60", "0"], ["84034.80", "5.627442"], ["84038.00", "0"], ["84043.20", "4.447495"], ["84046.40", "0"], ["84051.60", "3.902904"], ["84052.14", "0"], ["84054.80", "0"], ["84056.57", "0.125836"], ["84060.00", "3.993669"], ["84063.20", "0"], ["84068.40", "5.536677"], ["84071.60", "0"], ["84076.80", "5.445912"], ["84080.00", "0"], ["84085.20", "4.901321"], ["84088.40", "0"], ["84093.60", "4.719791"], ["84096.80", "0"], ["84102.00", "4.356730"], ["84105.20", "0"], ["84110.40", "5.264382"], ["84113.60", "0"], ["84118.80", "4.992086"], ["84122.00", "0"], ["84127.20", "4.175199"], ["84130.40", "0"], ["84135.60", "4.629025"], ["84138.80", "0"], ["84144.00", "5.082851"], ["84147.20", "0"], ["84152.40", "4.810556"], ["84155.60", "0"], ["84160.80", "5.173616"], ["84164.00", "0"], ["84169.20", "4.265965"], ["84172.40", "0"], ["84177.60", "4.084434"], ["84180.80", "0"], ["84186.00", "4.538260"], ["84189.20", "0"], ["84340.00", "0.018287"], ["84340.46", "0.000143"]], "bids": [["83918.02", "0.619602"], ["83917.90", "0"], ["83917.60", "0"], ["83916.40", "0.001050"], ["83915.60", "0"], ["83914.83", "0.007599"], ["83914.72", "0.284775"], ["83914.40", "0.001042"], ["83913.60", "0"], ["83913.18", "0.113982"], ["83913.06", "0"], ["83912.40", "0.002696"], ["83911.60", "0"], ["83910.40", "0.007095"], ["83909.61", "0.108059"], ["83909.60", "0"], ["83908.40", "0.018670"], ["83907.60", "0"], ["83906.40", "0.049133"], ["83905.60", "0"], ["83904.40", "0.129296"], ["83904.26", "0.764642"], ["83903.60", "0"], ["83903.50", "0"], ["83903.40", "0"], ["83903.20", "0"], ["83902.90", "0"], ["83902.40", "0.340254"], ["83902.00", "0"], ["83901.58", "0"], ["83901.05", "0"], ["83900.76", "0"], ["83900.50", "0"], ["83900.40", "0.895404"], ["83900.10", "0.001016"], ["83900.00", "0.003660"], ["83899.80", "0"], ["83899.77", "0.008029"], ["83899.45", "0"], ["83899.35", "0"], ["83899.29", "0"], ["83899.20", "0"], ["83899.16", "0"], ["83898.78", "0"], ["83898.60", "0"], ["83898.53", "0"], ["83898.20", "0.120390"], ["83898.10", "0"], ["83898.00", "0"], ["83897.97", "0"], ["83897.50", "0"], ["83897.45", "0"], ["83897.34", "0"], ["83896.96", "0"], ["83896.95", "0"], ["83896.90", "0.173070"], ["83896.88", "0"], ["83896.80", "0"], ["83896.70", "0.071760"], ["83896.64", "0"], ["83896.31", "0.007202"], ["83896.30", "0.060210"], ["83896.26", "0"], ["83896.02", "0.089673"], ["83896.00", "0.360000"], ["83895.94", "0"], ["83895.84", "0"], ["83895.68", "0"], ["83895.60", "0"], ["83895.53", "0.247543"], ["83895.44", "0.009567"], ["83895.30", "0.105900"], ["83895.00", "0"], ["83894.76", "0"], ["83894.60", "0"], ["83894.50", "0.022650"], ["83894.40", "0"], ["83894.38", "0.083637"], ["83894.24", "0"], ["83894.20", "0"], ["83894.00", "0"], ["83893.99", "0.017826"], ["83893.78", "0.018273"], ["83893.40", "0"], ["83893.30", "0"], ["83893.24", "0.005950"], ["83893.10", "0.045000"], ["83892.97", "0.015750"], ["83892.90", "0.160920"], ["83892.60", "0.010890"], ["83892.53", "0"], ["83892.50", "0.490290"], ["83892.41", "0.006572"], ["83892.33", "0"], ["83892.12", "0.055637"], ["83892.00", "0.133350"], ["83891.96", "0.017124"], ["83891.90", "0.217080"], ["83891.86", "0.007141"], ["83891.40", "0.007347"], ["83891.39", "0.028875"], ["83891.32", "0"], ["83891.29", "0.012592"], ["83891.17", "0"], ["83891.16", "0.017114"], ["83890.96", "0"], ["83890.94", "0.007956"], ["83890.93", "0.009010"], ["83890.62", "0.025199"], ["83890.45", "0.225049"], ["83890.33", "0.008200"], ["83890.28", "0.017376"], ["83890.10", "0.656970"], ["83890.00", "1.471800"], ["83889.90", "2.343300"], ["83889.80", "0.487590"], ["83889.34", "0"], ["83889.22", "0.008290"], ["83888.96", "0"], ["83888.94", "0.012674"], ["83888.93", "0.051846"], ["83888.41", "0.005129"], ["83887.87", "0.018549"], ["83887.15", "0.268841"], ["83887.14", "0"], ["83885.84", "0.259212"], ["83885.60", "0.076244"], ["83885.57", "0.021166"], ["83884.69", "0"], ["83883.40", "0.012460"], ["83881.66", "0.073186"], ["83880.94", "0.024669"], ["83879.15", "0.000878"], ["83872.65", "0"], ["83869.77", "0.008588"], ["83866.16", "0"], ["83861.70", "0"], ["83860.63", "0.003603"], ["83858.40", "5.173616"], ["83853.30", "0"], ["83850.00", "4.629025"], ["83844.90", "0"], ["83841.60", "4.901321"], ["83836.50", "0"], ["83833.20", "5.264382"], ["83828.10", "0"], ["83824.80", "5.355147"], ["83819.70", "0"], ["83816.40", "4.265965"], ["83811.30", "0"], ["83808.00", "4.538260"], ["83802.90", "0"], ["83799.60", "5.082851"], ["83794.50", "0"], ["83791.20", "4.810556"], ["83786.10", "0"], ["83782.80", "4.447495"], ["83777.70", "0"], ["83774.40", "5.445912"], ["83769.30", "0"], ["83766.00", "5.627442"], ["83760.90", "0"], ["83757.60", "4.356730"], ["83752.50", "0"], ["83749.20", "4.719791"], ["83744.10", "0"], ["83740.80", "5.536677"], ["83735.70", "0"], ["83732.40", "4.175199"], ["83727.30", "0"], ["83724.00", "4.084434"], ["83718.90", "0"], ["83715.60", "3.902904"], ["83710.50", "0"], ["83707.20", "4.992086"], ["83702.10", "0"], ["83698.80", "3.993669"], ["83445.30", "0.000011"], ["83445.16", "0.000054"], ["83444.44", "0.000105"], ["83444.38", "0.000025"], ["83444.27", "0.000028"], ["83443.53", "0.000161"]], "checksum": -993545875, "ts": "1742577157643"}], "ts": 1742577157647, "record_time": 1742577157.841928, "EXCHANGE": "BITGET"}
{"action": "update", "arg": {"instType": "SPOT", "channel": "books", "instId": "BTCUSDT"}, "data": [{"asks": [["83919.51", "0.034195"], ["83921.90", "0.027834"], ["83921.91", "0"], ["83950.53", "0.049781"], ["83955.94", "0"], ["83966.40", "0.001768"], ["83968.40", "0.004654"], ["83970.40", "0.012246"], ["83972.40", "0.032227"], ["83974.40", "0.084686"], ["83976.40", "0.222860"], ["83978.40", "0.586473"], ["83980.40", "1.543351"], ["83982.40", "4.061450"], ["83984.40", "10.688025"], ["83984.50", "0.146400"], ["83984.60", "0.001038"], ["83986.00", "0.042900"], ["83987.00", "0.250800"], ["83987.30", "0"], ["83987.60", "2.560080"], ["83987.70", "0.027930"], ["83988.40", "0"], ["83991.10", "0.037650"], ["83995.60", "1.429500"], ["84022.12", "0"], ["84026.40", "5.536677"], ["84030.52", "0"], ["84034.80", "4.447495"], ["84043.20", "5.082851"], ["84051.60", "3.993669"], ["84060.00", "5.264382"], ["84068.40", "4.175199"], ["84076.80", "4.992086"], ["84085.20", "5.627442"], ["84093.60", "5.445912"], ["84102.00", "5.173616"], ["84110.40", "4.538260"], ["84118.80", "4.629025"], ["84127.20", "4.901321"], ["84135.60", "4.810556"], ["84144.00", "4.265965"], ["84152.40", "4.084434"], ["84160.80", "4.719791"], ["84169.20", "5.355147"], ["84177.60", "3.902904"], ["84186.00", "4.356730"], ["84340.72", "0.000066"], ["84341.00", "0.002997"], ["84341.01", "0.000008"]], "bids": [["83918.02", "0.609602"], ["83914.72", "0"], ["83914.40", "0.001020"], ["83912.40", "0.001898"], ["83910.41", "0.007730"], ["83910.40", "0.004996"], ["83909.61", "0"], ["83908.40", "0.013148"], ["83906.40", "0.034599"], ["83905.61", "0"], ["83904.40", "0.091050"], ["83902.91", "0"], ["83902.40", "0.239605"], ["83900.40", "0.630540"], ["83900.10", "0.001380"], ["83900.00", "0.003690"], ["83898.20", "0.120210"], ["83896.90", "0"], ["83896.00", "0.360210"], ["83895.50", "0.007780"], ["83892.70", "0.066420"], ["83890.10", "0.120000"], ["83889.90", "2.880270"], ["83868.00", "0.000160"], ["83858.40", "4.175199"], ["83850.00", "4.719791"], ["83841.60", "5.445912"], ["83834.03", "0"], ["83833.20", "4.538260"], ["83825.64", "0"], ["83824.80", "4.992086"], ["83816.40", "5.627442"], ["83808.00", "5.173616"], ["83799.60", "5.355147"], ["83791.20", "4.356730"], ["83782.80", "5.264382"], ["83774.40", "4.447495"], ["83766.00", "3.902904"], ["83757.60", "5.082851"], ["83749.20", "3.993669"], ["83732.40", "4.084434"], ["83724.00", "4.901321"], ["83715.60", "4.629025"], ["83707.20", "4.265965"], ["83698.80", "4.810556"], ["83442.50", "0.000113"], ["83441.56", "0.000024"], ["83440.00", "0.000460"], ["83439.42", "0.000423"]], "checksum": -701028625, "ts": "1742577157847"}], "ts": 1742577157851, "record_time": 1742577158.051731, "EXCHANGE": "BITGET"}
{"action": "update", "arg": {"instType": "SPOT", "channel": "books", "instId": "BTCUSDT"}, "data": [{"asks": [["83918.03", "0.863575"], ["83918.60", "0.092785"], ["83919.51", "0"], ["83921.90", "0"], ["83936.29", "0.046763"], ["83968.40", "0.004551"], ["83970.40", "0.011975"], ["83972.40", "0.031515"], ["83974.40", "0.082932"], ["83976.40", "0.218243"], ["83978.40", "0.574324"], ["83980.40", "1.511378"], ["83982.40", "3.977312"], ["83984.40", "10.466611"], ["83984.50", "0.088890"], ["83986.10", "0"], ["83991.10", "0.035730"], ["83991.90", "4.336620"], ["83993.40", "0"], ["83995.60", "0"], ["84026.40", "5.445912"], ["84034.80", "4.810556"], ["84043.20", "4.356730"], ["84051.60", "5.536677"], ["84060.00", "5.173616"], ["84068.40", "4.265965"], ["84076.80", "4.447495"], ["84085.20", "4.084434"], ["84093.60", "4.901321"], ["84102.00", "5.355147"], ["84110.40", "4.719791"], ["84118.80", "4.538260"], ["84127.20", "5.264382"], ["84135.60", "5.627442"], ["84144.00", "5.082851"], ["84152.40", "3.902904"], ["84160.80", "3.993669"], ["84169.20", "4.175199"], ["84177.60", "4.992086"], ["84186.00", "4.629025"], ["84342.11", "0.000051"], ["84342.63", "0.000009"], ["84342.70", "0.000423"]], "bids": [["83914.72", "0.195206"], ["83914.40", "0.002741"], ["83912.40", "0.007212"], ["83910.41", "0"], ["83910.40", "0.018981"], ["83908.40", "0.049948"], ["83906.40", "0.131581"], ["83904.40", "0.346266"], ["83902.40", "0.911228"], ["83900.40", "2.397968"], ["83900.10", "0.001170"], ["83898.30", "0.070770"], ["83897.00", "0.176010"], ["83896.70", "0.071580"], ["83896.30", "0.060000"], ["83896.00", "0.360000"], ["83892.70", "0.133230"], ["83892.50", "1.095240"], ["83892.00", "1.350000"], ["83890.00", "0"], ["83889.90", "0"], ["83889.80", "0"], ["83880.94", "0"], ["83868.00", "0"], ["83858.40", "5.627442"], ["83850.00", "4.629025"], ["83847.90", "0"], ["83841.80", "0.000971"], ["83841.60", "5.264382"], ["83833.20", "4.901321"], ["83824.80", "4.265965"], ["83816.40", "5.445912"], ["83808.00", "4.992086"], ["83799.60", "4.719791"], ["83791.20", "4.538260"], ["83782.80", "4.175199"], ["83774.40", "5.355147"], ["83766.00", "4.356730"], ["83757.60", "5.173616"], ["83749.20", "5.082851"], ["83740.80", "4.084434"], ["83732.40", "3.993669"], ["83724.00", "5.536677"], ["83715.60", "4.447495"], ["83707.20", "3.902904"], ["83439.33", "0.000010"], ["83437.50", "0.000009"], ["83437.10", "0.000095"]], "checksum": 1026103211, "ts": "1742577158048"}], "ts": 1742577158052, "record_time": 1742577158.24608, "EXCHANGE": "BITGET"}
{"action": "update", "arg": {"instType": "SPOT", "channel": "books", "instId": "BTCUSDT"}, "data": [{"asks": [["83962.10", "0.780445"], ["83966.40", "0.001047"], ["83968.40", "0.002757"], ["83970.40", "0.007255"], ["83971.59", "0.001598"], ["83972.40", "0.019090"], ["83974.40", "0.050238"], ["83976.40", "0.132204"], ["83978.29", "0"], ["83978.40", "0.347907"], ["83980.40", "0.915543"], ["83982.40", "2.409326"], ["83984.40", "6.340331"], ["83987.00", "0.250620"], ["83987.60", "0.638430"], ["83989.40", "0"], ["83990.40", "0.450600"], ["83991.10", "0"], ["83991.50", "0.688830"], ["83991.90", "1.247190"], ["83992.20", "0"], ["83993.90", "2.359620"], ["83995.60", "1.429500"], ["83995.70", "0.012480"], ["84023.74", "0.001810"], ["84026.40", "4.175199"], ["84032.14", "0.003620"], ["84034.80", "5.264382"], ["84051.60", "4.447495"], ["84060.00", "5.536677"], ["84068.40", "4.810556"], ["84076.80", "5.445912"], ["84085.20", "5.355147"], ["84093.60", "4.084434"], ["84102.00", "3.902904"], ["84118.80", "4.629025"], ["84127.20", "4.538260"], ["84135.60", "4.992086"], ["84144.00", "5.627442"], ["84152.40", "5.082851"], ["84160.80", "4.901321"], ["84169.20", "4.265965"], ["84177.60", "3.993669"], ["84186.00", "5.173616"], ["84278.17", "1.590137"], ["84281.44", "0"], ["84341.00", "0"], ["84341.01", "0"], ["84342.11", "0"], ["84342.63", "0"], ["84342.70", "0"]], "bids": [["83918.02", "0.619602"], ["83916.40", "0.001750"], ["83914.40", "0.004606"], ["83912.40", "0.012120"], ["83910.41", "0.020679"], ["83910.40", "0.031895"], ["83908.40", "0.083935"], ["83906.85", "0.024669"], ["83906.40", "0.220881"], ["83904.40", "0.581509"], ["83904.05", "0.024948"], ["83902.40", "1.530286"], ["83900.40", "4.027067"], ["83899.20", "0.161130"], ["83898.20", "0.498630"], ["83897.00", "0.175800"], ["83896.70", "0.071370"], ["83896.00", "0.402300"], ["83893.00", "0"], ["83892.90", "0"], ["83892.70", "0"], ["83892.50", "1.059480"], ["83891.13", "0"], ["83890.00", "1.471800"], ["83864.32", "0"], ["83858.40", "5.355147"], ["83857.63", "0.001174"], ["83850.00", "5.264382"], ["83841.60", "4.356730"], ["83837.82", "0.001810"], ["83833.20", "4.810556"], ["83829.43", "0.003620"], ["83824.80", "3.902904"], ["83816.40", "4.447495"], ["83808.00", "4.719791"], ["83799.60", "4.901321"], ["83791.20", "4.992086"], ["83782.80", "4.265965"], ["83774.40", "5.536677"], ["83766.00", "5.627442"], ["83749.20", "4.629025"], ["83740.80", "5.445912"], ["83732.40", "4.175199"], ["83724.00", "4.084434"], ["83715.60", "3.993669"], ["83707.20", "5.082851"], ["83698.80", "4.538260"], ["83609.87", "0"], ["83606.62", "1.727862"], ["83439.33", "0"], ["83437.50", "0"], ["83437.10", "0"]], "checksum": -268106528, "ts": "1742577158256"}], "ts": 1742577158262, "record_time": 1742577158.455307, "EXCHANGE": "BITGET"}
{"action": "update", "arg": {"instType": "SPOT", "channel": "books", "instId": "BTCUSDT"}, "data": [{"asks": [["83918.58", "0.092785"], ["83918.60", "0"], ["83969.90", "0.001598"], ["83976.52", "0"], ["83988.60", "0.015000"], ["83991.90", "1.792800"], ["84026.40", "5.445912"], ["84034.80", "4.356730"], ["84043.20", "4.629025"], ["84051.60", "4.719791"], ["84060.00", "3.993669"], ["84068.40", "5.536677"], ["84076.80", "5.082851"], ["84085.20", "4.447495"], ["84093.60", "5.264382"], ["84102.00", "4.901321"], ["84110.40", "4.265965"], ["84118.80", "4.175199"], ["84127.20", "4.084434"], ["84135.60", "4.810556"], ["84152.40", "4.538260"], ["84160.80", "5.173616"], ["84169.20", "4.992086"], ["84177.60", "5.355147"], ["84186.00", "3.902904"], ["84340.72", "0"]], "bids": [["83910.41", "0.032164"], ["83866.42", "0"], ["83866.00", "0.000121"], ["83859.81", "0.001177"], ["83858.40", "4.992086"], ["83850.00", "4.175199"], ["83841.60", "5.627442"], ["83833.20", "4.629025"], ["83824.80", "5.173616"], ["83816.40", "3.902904"], ["83808.00", "5.264382"], ["83799.60", "3.993669"], ["83791.20", "5.445912"], ["83782.80", "4.356730"], ["83774.40", "4.901321"], ["83766.00", "5.082851"], ["83757.60", "4.265965"], ["83749.20", "4.447495"], ["83740.80", "4.719791"], ["83732.40", "4.810556"], ["83715.60", "4.538260"], ["83707.20", "5.536677"], ["83698.80", "5.355147"], ["83439.42", "0"]], "checksum": 807026358, "ts": "1742577158459"}], "ts": 1742577158461, "record_time": 1742577158.655583, "EXCHANGE": "BITGET"}
{"action": "update", "arg": {"instType": "SPOT", "channel": "books", "instId": "BTCUSDT"}, "data": [{"asks": [["83966.40", "0.001223"], ["83968.40", "0.003218"], ["83970.40", "0.008212"], ["83972.40", "0.021610"], ["83974.40", "0.056870"], ["83976.40", "0.149657"], ["83978.40", "0.393835"], ["83980.40", "1.036406"], ["83982.40", "2.727386"], ["83984.40", "7.177331"], ["83987.60", "0.911580"], ["83989.40", "0.099360"], ["83990.40", "0.452520"], ["83991.10", "0.022140"], ["83995.70", "0"], ["84026.40", "5.173616"], ["84034.80", "3.902904"], ["84043.20", "4.719791"], ["84051.60", "4.810556"], ["84060.00", "4.992086"], ["84076.80", "5.264382"], ["84085.20", "4.538260"], ["84093.60", "4.901321"], ["84102.00", "4.447495"], ["84118.80", "5.627442"], ["84127.20", "3.993669"], ["84135.60", "5.082851"], ["84144.00", "4.356730"], ["84152.40", "5.445912"], ["84160.80", "4.629025"], ["84169.20", "4.175199"], ["84186.00", "4.084434"], ["84340.46", "0"]], "bids": [["83905.77", "0.574856"], ["83904.40", "0.581143"], ["83902.40", "1.529324"], ["83900.40", "4.024538"], ["83899.60", "0.340650"], ["83898.20", "0.498420"], ["83895.10", "0.487590"], ["83890.00", "0"], ["83866.00", "0.000281"], ["83858.40", "5.082851"], ["83850.00", "4.810556"], ["83841.60", "5.536677"], ["83833.20", "5.264382"], ["83824.80", "5.355147"], ["83816.40", "4.992086"], ["83808.00", "4.629025"], ["83799.60", "4.084434"], ["83791.20", "4.356730"], ["83782.80", "4.901321"], ["83774.40", "4.538260"], ["83766.00", "4.175199"], ["83757.60", "5.173616"], ["83740.80", "5.627442"], ["83732.40", "4.265965"], ["83724.00", "3.993669"], ["83715.60", "3.902904"], ["83707.20", "4.719791"], ["83698.80", "5.445912"], ["83441.56", "0"], ["83440.00", "0"]], "checksum": 1574105111, "ts": "1742577158674"}], "ts": 1742577158679, "record_time": 1742577158.872618, "EXCHANGE": "BITGET"}
{"action": "update", "arg": {"instType": "SPOT", "channel": "books", "instId": "BTCUSDT"}, "data": [{"asks": [["83918.03", "1.072775"], ["83988.60", "0.030000"], ["83989.40", "0"], ["83991.10", "0.009870"], ["83991.90", "1.777800"], ["83995.70", "0.012480"], ["84026.40", "4.810556"], ["84034.80", "5.082851"], ["84043.20", "5.627442"], ["84051.60", "5.264382"], ["84060.00", "3.993669"], ["84068.40", "4.356730"], ["84076.80", "4.992086"], ["84085.20", "5.445912"], ["84093.60", "3.902904"], ["84102.00", "4.901321"], ["84110.40", "5.355147"], ["84118.80", "4.084434"], ["84127.20", "4.719791"], ["84135.60", "4.447495"], ["84144.00", "4.538260"], ["84152.40", "4.265965"], ["84160.80", "5.536677"], ["84169.20", "4.629025"], ["84177.60", "5.173616"], ["84186.00", "4.175199"]], "bids": [["83902.41", "1.361185"], ["83896.81", "0.023199"], ["83858.40", "4.084434"], ["83850.00", "5.536677"], ["83841.60", "5.264382"], ["83833.20", "4.356730"], ["83824.80", "4.175199"], ["83816.40", "5.173616"], ["83808.00", "3.902904"], ["83799.60", "4.265965"], ["83791.20", "4.992086"], ["83782.80", "4.719791"], ["83774.40", "5.355147"], ["83766.00", "4.538260"], ["83757.60", "4.447495"], ["83749.20", "5.627442"], ["83740.80", "4.810556"], ["83732.40", "4.629025"], ["83724.00", "5.445912"], ["83715.60", "5.082851"], ["83707.20", "4.901321"], ["83698.80", "3.993669"], ["83442.50", "0"]], "checksum": 1402617458, "ts": "1742577158876"}], "ts": 1742577158879, "record_time": 1742577159.072856, "EXCHANGE": "BITGET"}
{"action": "update", "arg": {"instType": "SPOT", "channel": "books", "instId": "BTCUSDT"}, "data": [{"asks": [["83918.56", "0.092785"], ["83918.58", "0"], ["83969.81", "0"], ["83989.40", "0.102180"], ["83991.10", "0.021660"], ["83992.20", "0.071670"], ["83995.70", "0"], ["84026.40", "5.173616"], ["84034.80", "5.627442"], ["84043.20", "5.264382"], ["84051.60", "4.629025"], ["84060.00", "5.355147"], ["84068.40", "4.992086"], ["84076.80", "5.536677"], ["84085.20", "4.901321"], ["84093.60", "4.265965"], ["84102.00", "4.538260"], ["84110.40", "4.084434"], ["84118.80", "5.082851"], ["84135.60", "4.356730"], ["84144.00", "3.902904"], ["84152.40", "5.445912"], ["84160.80", "4.447495"], ["84169.20", "3.993669"], ["84177.60", "4.175199"], ["84186.00", "4.810556"]], "bids": [["83906.85", "0"], ["83904.40", "0.581326"], ["83902.40", "1.529805"], ["83900.40", "4.025803"], ["83900.10", "0.206026"], ["83876.80", "0"], ["83858.40", "3.993669"], ["83850.00", "5.082851"], ["83841.60", "4.447495"], ["83833.20", "5.264382"], ["83824.80", "4.265965"], ["83816.40", "4.356730"], ["83808.00", "4.810556"], ["83799.60", "5.173616"], ["83791.20", "3.902904"], ["83782.80", "5.627442"], ["83774.40", "4.992086"], ["83766.00", "4.719791"], ["83757.60", "5.445912"], ["83749.20", "4.538260"], ["83740.80", "4.084434"], ["83724.00", "4.901321"], ["83715.60", "4.175199"], ["83707.20", "5.536677"], ["83698.80", "5.355147"], ["83442.50", "0.000113"], ["83441.56", "0.000024"]], "checksum": -700162523, "ts": "1742577159080"}], "ts": 1742577159083, "record_time": 1742577159.276542, "EXCHANGE": "BITGET"}
{"action": "update", "arg": {"instType": "SPOT", "channel": "books", "instId": "BTCUSDT"}, "data": [{"asks": [["83918.03", "1.072431"], ["83918.55", "0.062030"], ["83966.40", "0.001621"], ["83968.40", "0.004266"], ["83970.40", "0.011228"], ["83972.40", "0.029546"], ["83974.40", "0.077754"], ["83976.40", "0.204616"], ["83978.40", "0.538461"], ["83980.40", "1.417003"], ["83982.40", "3.728957"], ["83984.40", "9.813044"], ["83986.10", "0.015510"], ["83990.00", "2.402010"], ["83990.40", "0"], ["83991.10", "0.035730"], ["83991.50", "0"], ["83991.80", "1.941090"], ["83991.90", "0"], ["83993.90", "0"], ["84026.40", "5.264382"], ["84034.80", "5.536677"], ["84043.20", "5.445912"], ["84051.60", "4.265965"], ["84060.00", "4.810556"], ["84068.40", "3.902904"], ["84076.80", "4.992086"], ["84085.20", "5.082851"], ["84093.60", "4.356730"], ["84118.80", "4.175199"], ["84127.20", "4.447495"], ["84135.60", "3.993669"], ["84144.00", "4.719791"], ["84152.40", "5.173616"], ["84160.80", "4.629025"], ["84169.20", "5.627442"], ["84177.60", "5.355147"], ["84186.00", "4.901321"]], "bids": [["83916.40", "0.001028"], ["83914.40", "0.001828"], ["83912.40", "0.004809"], ["83910.40", "0.012656"], ["83908.40", "0.033074"], ["83906.40", "0.087036"], ["83904.40", "0.229043"], ["83904.05", "0"], ["83902.40", "0.602745"], ["83900.40", "1.586171"], ["83900.10", "0.204856"], ["83899.60", "0"], ["83899.20", "0"], ["83898.20", "0.120210"], ["83897.00", "0.176010"], ["83896.70", "0.071580"], ["83896.30", "0.220920"], ["83896.00", "0.402510"], ["83895.30", "0.172320"], ["83895.10", "0"], ["83894.13", "0.024948"], ["83892.50", "0.690240"], ["83892.00", "0.000121"], ["83890.00", "1.471800"], ["83889.90", "2.880270"], ["83883.40", "0.037129"], ["83870.70", "0.207210"], ["83867.00", "0.000160"], ["83858.40", "5.264382"], ["83850.00", "4.175199"], ["83841.60", "3.993669"], ["83833.20", "4.992086"], ["83824.80", "5.627442"], ["83816.40", "5.355147"], ["83808.00", "4.629025"], ["83799.60", "4.810556"], ["83791.20", "4.265965"], ["83782.80", "5.082851"], ["83774.40", "3.902904"], ["83766.00", "4.901321"], ["83749.20", "4.719791"], ["83732.40", "5.173616"], ["83724.00", "4.538260"], ["83715.60", "4.356730"], ["83698.80", "4.447495"]], "checksum": 1589384135, "ts": "1742577159283"}], "ts": 1742577159287, "record_time": 1742577159.479629, "EXCHANGE": "BITGET"}
{"action": "update", "arg": {"instType": "SPOT", "channel": "books", "instId": "BTCUSDT"}, "data": [{"asks": [["83918.03", "1.078331"], ["83918.54", "0.092785"], ["83918.56", "0"], ["83941.63", "0.092684"], ["83942.16", "0"], ["83951.81", "0.010988"], ["83957.12", "0"], ["83968.40", "0.004392"], ["83970.40", "0.011557"], ["83972.40", "0.030414"], ["83974.40", "0.080037"], ["83976.40", "0.210624"], ["83978.40", "0.554274"], ["83980.40", "1.458615"], ["83982.40", "3.838461"], ["83984.40", "10.101214"], ["83986.10", "0"], ["83987.60", "1.265490"], ["83991.80", "1.228650"], ["83995.80", "2.474670"], ["84026.40", "5.445912"], ["84034.80", "3.902904"], ["84043.20", "5.264382"], ["84051.60", "4.810556"], ["84060.00", "5.173616"], ["84068.40", "5.355147"], ["84076.80", "4.356730"], ["84085.20", "4.901321"], ["84093.60", "4.084434"], ["84102.00", "4.629025"], ["84110.40", "5.082851"], ["84118.80", "4.265965"], ["84135.60", "4.175199"], ["84144.00", "5.627442"], ["84152.40", "3.993669"], ["84160.80", "4.538260"], ["84169.20", "5.536677"], ["84177.60", "4.992086"], ["84186.00", "4.719791"]], "bids": [["83914.40", "0.001934"], ["83912.40", "0.005089"], ["83910.41", "0.011485"], ["83910.40", "0.013392"], ["83908.40", "0.035242"], ["83906.40", "0.092741"], ["83904.40", "0.243875"], ["83902.41", "0"], ["83902.40", "0.641774"], ["83900.40", "1.688880"], ["83890.40", "0.487590"], ["83889.90", "0"], ["83886.63", "0"], ["83881.32", "0.056465"], ["83867.00", "0"], ["83858.40", "5.627442"], ["83850.00", "5.082851"], ["83841.60", "4.810556"], ["83833.20", "4.719791"], ["83824.80", "4.447495"], ["83816.40", "4.175199"], ["83808.00", "3.902904"], ["83799.60", "5.264382"], ["83782.80", "5.536677"], ["83774.40", "4.901321"], ["83766.00", "4.356730"], ["83757.60", "4.084434"], ["83749.20", "4.629025"], ["83740.80", "5.355147"], ["83732.40", "5.445912"], ["83724.00", "4.992086"], ["83715.60", "3.993669"], ["83707.20", "5.173616"], ["83698.80", "4.538260"], ["83440.00", "0.000460"], ["83439.42", "0.000423"]], "checksum": 1598607239, "ts": "1742577159490"}], "ts": 1742577159495, "record_time": 1742577159.68789, "EXCHANGE": "BITGET"}
{"action": "update", "arg": {"instType": "SPOT", "channel": "books", "instId": "BTCUSDT"}, "data": [{"asks": [["83918.03", "1.084231"], ["83918.53", "0.062030"], ["83918.55", "0"], ["83990.00", "0.042300"], ["83991.10", "0.037650"], ["83992.20", "2.431320"], ["84026.40", "5.264382"], ["84034.80", "3.993669"], ["84043.20", "5.627442"], ["84051.60", "4.265965"], ["84060.00", "4.629025"], ["84068.40", "5.536677"], ["84076.80", "4.992086"], ["84085.20", "5.082851"], ["84093.60", "4.810556"], ["84102.00", "4.084434"], ["84110.40", "4.175199"], ["84118.80", "4.901321"], ["84127.20", "4.538260"], ["84135.60", "5.355147"], ["84144.00", "5.445912"], ["84152.40", "4.356730"], ["84160.80", "4.447495"], ["84169.20", "3.902904"], ["84177.60", "4.719791"], ["84186.00", "5.173616"]], "bids": [["83916.40", "0.001164"], ["83914.40", "0.003062"], ["83912.40", "0.008059"], ["83910.40", "0.021207"], ["83908.40", "0.055809"], ["83906.40", "0.146865"], ["83904.40", "0.386487"], ["83902.41", "0.773437"], ["83902.40", "1.017071"], ["83900.40", "2.676503"], ["83889.90", "0.536970"], ["83858.40", "4.901321"], ["83850.00", "4.175199"], ["83841.60", "5.355147"], ["83824.80", "4.084434"], ["83816.40", "4.356730"], ["83808.00", "4.810556"], ["83799.60", "5.627442"], ["83791.20", "4.447495"], ["83782.80", "3.993669"], ["83774.40", "4.629025"], ["83766.00", "5.264382"], ["83757.60", "3.902904"], ["83749.20", "5.082851"], ["83740.80", "5.445912"], ["83732.40", "4.538260"], ["83724.00", "5.536677"], ["83715.60", "5.173616"], ["83707.20", "4.992086"], ["83698.80", "4.265965"], ["83440.00", "0"], ["83439.42", "0"]], "checksum": -458616021, "ts": "1742577159712"}], "ts": 1742577159716, "record_time": 1742577159.910083, "EXCHANGE": "BITGET"}
{"action": "update", "arg": {"instType": "SPOT", "channel": "books", "instId": "BTCUSDT"}, "data": [{"asks": [["83976.40", "0.210464"], ["83978.40", "0.553852"], ["83980.40", "1.457506"], ["83982.40", "3.835542"], ["83984.40", "10.093532"], ["83987.30", "0.012000"], ["83987.60", "0.671550"], ["83988.60", "0.015000"], ["83989.40", "0.104100"], ["83991.10", "0.035730"], ["83991.80", "1.782960"], ["83995.30", "0.012450"], ["83995.80", "0"], ["84026.40", "5.536677"], ["84034.80", "4.356730"], ["84043.20", "5.264382"], ["84060.00", "4.810556"], ["84068.40", "5.445912"], ["84076.80", "4.719791"], ["84093.60", "4.992086"], ["84102.00", "4.447495"], ["84110.40", "5.173616"], ["84118.80", "3.902904"], ["84127.20", "5.627442"], ["84135.60", "3.993669"], ["84144.00", "4.629025"], ["84152.40", "4.084434"], ["84160.80", "5.355147"], ["84169.20", "4.175199"], ["84177.60", "4.538260"], ["84186.00", "4.901321"], ["84340.00", "0"]], "bids": [["83910.41", "0.021669"], ["83906.40", "0.146988"], ["83904.40", "0.386812"], ["83902.40", "1.017927"], ["83900.40", "2.678753"], ["83868.00", "0.000160"], ["83858.40", "3.993669"], ["83850.00", "5.355147"], ["83841.60", "4.084434"], ["83833.20", "4.810556"], ["83824.80", "4.901321"], ["83808.00", "4.629025"], ["83799.60", "5.264382"], ["83791.20", "4.538260"], ["83782.80", "5.536677"], ["83774.40", "5.173616"], ["83766.00", "5.082851"], ["83749.20", "5.445912"], ["83740.80", "4.175199"], ["83732.40", "4.992086"], ["83724.00", "4.719791"], ["83715.60", "4.447495"], ["83707.20", "4.265965"], ["83698.80", "5.627442"], ["83441.56", "0"]], "checksum": -393460245, "ts": "1742577159914"}], "ts": 1742577159919, "record_time": 1742577160.110986, "EXCHANGE": "BITGET"}
{"action": "update", "arg": {"instType": "SPOT", "channel": "books", "instId": "BTCUSDT"}, "data": [{"asks": [["83918.52", "0.092785"], ["83918.54", "0"], ["83968.40", "0.004003"], ["83970.40", "0.010534"], ["83972.40", "0.027722"], ["83974.40", "0.072954"], ["83976.40", "0.191984"], ["83978.40", "0.505219"], ["83980.40", "1.329362"], ["83982.40", "3.498321"], ["83984.40", "9.206107"], ["84026.40", "5.627442"], ["84034.80", "4.447495"], ["84043.20", "5.173616"], ["84051.60", "5.082851"], ["84068.40", "4.356730"], ["84076.80", "4.992086"], ["84085.20", "4.901321"], ["84093.60", "4.084434"], ["84102.00", "5.264382"], ["84110.40", "5.355147"], ["84118.80", "4.719791"], ["84127.20", "4.265965"], ["84135.60", "4.538260"], ["84144.00", "4.175199"], ["84152.40", "4.629025"], ["84160.80", "3.993669"], ["84169.20", "5.445912"], ["84177.60", "5.536677"], ["84186.00", "3.902904"]], "bids": [["83904.40", "0.386672"], ["83902.41", "1.086565"], ["83902.40", "1.017559"], ["83900.40", "2.677786"], ["83868.00", "0.000281"], ["83858.40", "5.082851"], ["83850.00", "4.538260"], ["83841.60", "4.629025"], ["83833.20", "4.175199"], ["83824.80", "4.265965"], ["83816.40", "4.447495"], ["83808.00", "4.810556"], ["83799.60", "4.719791"], ["83791.20", "3.993669"], ["83774.40", "4.356730"], ["83766.00", "5.627442"], ["83757.60", "4.084434"], ["83740.80", "4.992086"], ["83732.40", "4.901321"], ["83724.00", "3.902904"], ["83715.60", "5.173616"], ["83707.20", "5.355147"], ["83698.80", "5.264382"]], "checksum": -599667125, "ts": "1742577160140"}], "ts": 1742577160144, "record_time": 1742577160.337094, "EXCHANGE": "BITGET"}
{"action": "update", "arg": {"instType": "SPOT", "channel": "books", "instId": "BTCUSDT"}, "data": [{"asks": [["83918.51", "0.062030"], ["83918.53", "0"], ["84026.40", "5.264382"], ["84034.80", "4.265965"], ["84043.20", "5.355147"], ["84051.60", "4.447495"], ["84060.00", "4.629025"], ["84068.40", "4.992086"], ["84076.80", "4.719791"], ["84085.20", "5.536677"], ["84093.60", "4.356730"], ["84102.00", "5.445912"], ["84110.40", "4.810556"], ["84118.80", "4.901321"], ["84127.20", "5.082851"], ["84135.60", "5.627442"], ["84144.00", "5.173616"], ["84152.40", "4.538260"], ["84169.20", "4.175199"], ["84177.60", "4.084434"]], "bids": [["83910.40", "0.021376"], ["83908.40", "0.056253"], ["83906.40", "0.148034"], ["83904.40", "0.389562"], ["83902.40", "1.025164"], ["83900.40", "2.697800"], ["83896.81", "0.285115"], ["83858.40", "4.447495"], ["83850.00", "5.445912"], ["83841.60", "4.175199"], ["83833.20", "4.810556"], ["83824.80", "4.719791"], ["83816.40", "5.627442"], ["83808.00", "4.629025"], ["83799.60", "3.902904"], ["83791.20", "5.264382"], ["83782.80", "4.084434"], ["83766.00", "5.082851"], ["83757.60", "4.538260"], ["83749.20", "4.901321"], ["83732.40", "5.355147"], ["83724.00", "5.536677"], ["83715.60", "3.993669"], ["83707.20", "4.265965"], ["83698.80", "5.173616"]], "checksum": 409114182, "ts": "1742577160345"}], "ts": 1742577160349, "record_time": 1742577160.541603, "EXCHANGE": "BITGET"}
{"action": "update", "arg": {"instType": "SPOT", "channel": "books", "instId": "BTCUSDT"}, "data": [{"asks": [["83918.52", "0"], ["83950.53", "0.131570"], ["83962.10", "0"], ["83984.40", "9.205884"], ["84026.40", "4.810556"], ["84034.80", "5.445912"], ["84043.20", "3.993669"], ["84060.00", "5.627442"], ["84068.40", "4.901321"], ["84076.80", "4.265965"], ["84085.20", "4.084434"], ["84093.60", "5.536677"], ["84102.00", "5.264382"], ["84110.40", "4.175199"], ["84118.80", "5.082851"], ["84127.20", "4.719791"], ["84135.60", "4.538260"], ["84144.00", "3.902904"], ["84152.40", "5.355147"], ["84160.80", "4.992086"], ["84169.20", "4.356730"], ["84177.60", "4.629025"], ["84186.00", "5.173616"], ["84340.00", "0.018287"], ["84340.46", "0.000143"]], "bids": [["83914.40", "0.002833"], ["83912.40", "0.007557"], ["83910.40", "0.019888"], ["83908.40", "0.052337"], ["83906.40", "0.137727"], ["83904.40", "0.362441"], ["83902.40", "0.953791"], ["83900.40", "2.509977"], ["83858.40", "5.173616"], ["83841.60", "4.901321"], ["83833.20", "5.264382"], ["83824.80", "4.265965"], ["83816.40", "4.810556"], ["83808.00", "5.627442"], ["83799.60", "4.084434"], ["83791.20", "3.902904"], ["83782.80", "3.993669"], ["83774.40", "4.175199"], ["83766.00", "5.536677"], ["83757.60", "4.992086"], ["83749.20", "5.082851"], ["83740.80", "4.356730"], ["83732.40", "4.629025"], ["83724.00", "4.447495"], ["83715.60", "4.538260"], ["83707.20", "5.355147"], ["83698.80", "4.719791"]], "checksum": -331475363, "ts": "1742577160555"}], "ts": 1742577160557, "record_time": 1742577160.750643, "EXCHANGE": "BITGET"}
{"action": "update", "arg": {"instType": "SPOT", "channel": "books", "instId": "BTCUSDT"}, "data": [{"asks": [["83918.50", "0.092785"], ["83918.51", "0.034195"], ["83987.30", "0"], ["83988.60", "0.030000"], ["84026.40", "5.173616"], ["84034.80", "4.901321"], ["84043.20", "5.445912"], ["84051.60", "4.992086"], ["84060.00", "4.084434"], ["84068.40", "4.265965"], ["84076.80", "4.810556"], ["84085.20", "5.536677"], ["84093.60", "4.356730"], ["84102.00", "4.175199"], ["84110.40", "3.993669"], ["84118.80", "3.902904"], ["84135.60", "4.447495"], ["84144.00", "5.264382"], ["84160.80", "4.629025"], ["84169.20", "4.538260"], ["84177.60", "5.627442"], ["84186.00", "5.082851"]], "bids": [["83866.00", "0.000121"], ["83858.40", "4.356730"], ["83850.00", "5.355147"], ["83841.60", "3.993669"], ["83833.20", "3.902904"], ["83824.80", "5.264382"], ["83808.00", "4.992086"], ["83799.60", "5.445912"], ["83791.20", "4.629025"], ["83782.80", "5.536677"], ["83774.40", "5.082851"], ["83766.00", "4.265965"], ["83757.60", "4.538260"], ["83749.20", "4.719791"], ["83740.80", "4.175199"], ["83732.40", "4.447495"], ["83724.00", "5.173616"], ["83715.60", "4.901321"], ["83707.20", "5.627442"], ["83698.80", "4.084434"]], "checksum": -1721333543, "ts": "1742577160768"}], "ts": 1742577160772, "record_time": 1742577160.965185, "EXCHANGE": "BITGET"}
{"action": "update", "arg": {"instType": "SPOT", "channel": "books", "instId": "BTCUSDT"}, "data": [{"asks": [["83918.49", "0.062030"], ["83918.51", "0"], ["83964.44", "0.010000"], ["84026.40", "4.356730"], ["84034.80", "4.447495"], ["84043.20", "4.084434"], ["84051.60", "4.719791"], ["84060.00", "3.902904"], ["84068.40", "4.992086"], ["84076.80", "5.173616"], ["84085.20", "4.901321"], ["84093.60", "5.264382"], ["84110.40", "4.810556"], ["84118.80", "5.355147"], ["84127.20", "5.536677"], ["84135.60", "4.538260"], ["84144.00", "3.993669"], ["84152.40", "5.627442"], ["84169.20", "5.445912"], ["84177.60", "5.082851"], ["84186.00", "4.265965"], ["84340.46", "0"]], "bids": [["83866.00", "0"], ["83858.40", "4.629025"], ["83850.00", "4.175199"], ["83841.60", "4.992086"], ["83833.20", "3.993669"], ["83824.80", "5.445912"], ["83816.40", "5.264382"], ["83808.00", "4.810556"], ["83799.60", "5.355147"], ["83791.20", "4.265965"], ["83782.80", "4.356730"], ["83774.40", "4.901321"], ["83766.00", "4.538260"], ["83757.60", "5.173616"], ["83749.20", "4.447495"], ["83740.80", "5.536677"], ["83732.40", "5.627442"], ["83724.00", "3.902904"], ["83715.60", "4.084434"], ["83707.20", "4.719791"], ["83698.80", "5.082851"], ["83441.56", "0.000024"]], "checksum": -818860931, "ts": "1742577160975"}], "ts": 1742577160978, "record_time": 1742577161.171975, "EXCHANGE": "BITGET"}
{"action": "update", "arg": {"instType": "SPOT", "channel": "books", "instId": "BTCUSDT"}, "data": [{"asks": [["83918.49", "0.154815"], ["83918.50", "0"], ["83976.39", "0.209161"], ["83988.60", "0.015000"], ["84026.40", "4.992086"], ["84034.80", "4.538260"], ["84043.20", "5.445912"], ["84051.60", "4.447495"], ["84060.00", "4.356730"], ["84068.40", "5.355147"], ["84076.80", "4.629025"], ["84085.20", "4.265965"], ["84093.60", "3.993669"], ["84102.00", "5.173616"], ["84110.40", "5.082851"], ["84118.80", "4.901321"], ["84135.60", "3.902904"], ["84144.00", "5.264382"], ["84152.40", "4.810556"], ["84160.80", "4.084434"], ["84169.20", "4.175199"], ["84177.60", "4.719791"], ["84186.00", "5.627442"]], "bids": [["83914.40", "0.003125"], ["83912.40", "0.008225"], ["83910.40", "0.021644"], ["83908.40", "0.056959"], ["83906.40", "0.149891"], ["83904.40", "0.394450"], ["83902.40", "1.038028"], ["83900.40", "2.731652"], ["83892.50", "0.804240"], ["83867.00", "0.000160"], ["83858.40", "4.538260"], ["83850.00", "4.265965"], ["83841.60", "5.627442"], ["83833.20", "4.810556"], ["83824.80", "4.901321"], ["83816.40", "4.447495"], ["83808.00", "4.992086"], ["83799.60", "4.175199"], ["83791.20", "5.536677"], ["83782.80", "5.173616"], ["83774.40", "4.356730"], ["83766.00", "5.445912"], ["83757.60", "5.082851"], ["83749.20", "4.084434"], ["83740.80", "3.902904"], ["83732.40", "5.264382"], ["83724.00", "4.629025"], ["83715.60", "5.355147"], ["83698.80", "3.993669"], ["83441.56", "0"]], "checksum": 1996059156, "ts": "1742577161190"}], "ts": 1742577161193, "record_time": 1742577161.385096, "EXCHANGE": "BITGET"}
{"action": "update", "arg": {"instType": "SPOT", "channel": "books", "instId": "BTCUSDT"}, "data": [{"asks": [["83918.48", "0.062030"], ["83918.49", "0.092785"], ["83978.40", "0.505115"], ["83980.40", "1.329249"], ["83982.40", "3.498024"], ["83984.40", "9.205326"], ["83986.10", "0.034110"], ["83995.60", "0"], ["84026.40", "4.447495"], ["84034.80", "5.355147"], ["84043.20", "4.084434"], ["84051.60", "5.536677"], ["84060.00", "5.173616"], ["84068.40", "5.264382"], ["84076.80", "5.627442"], ["84085.20", "4.719791"], ["84093.60", "3.902904"], ["84102.00", "5.445912"], ["84110.40", "4.629025"], ["84127.20", "4.175199"], ["84135.60", "4.992086"], ["84144.00", "5.082851"], ["84160.80", "4.538260"], ["84169.20", "4.356730"], ["84177.60", "4.265965"], ["84186.00", "3.993669"], ["84340.00", "0"]], "bids": [["83916.40", "0.001019"], ["83914.40", "0.001461"], ["83912.40", "0.003846"], ["83910.40", "0.010121"], ["83908.40", "0.026634"], ["83906.40", "0.070090"], ["83904.40", "0.184448"], ["83902.40", "0.485388"], ["83900.40", "1.277336"], ["83898.30", "0"], ["83896.30", "0.221130"], ["83896.00", "0.402720"], ["83892.50", "0.685770"], ["83889.90", "2.880270"], ["83876.23", "0"], ["83858.40", "4.356730"], ["83850.00", "4.810556"], ["83841.60", "4.175199"], ["83833.20", "5.082851"], ["83824.80", "5.355147"], ["83816.40", "5.173616"], ["83808.00", "5.627442"], ["83799.60", "4.447495"], ["83791.20", "4.265965"], ["83782.80", "5.264382"], ["83774.40", "3.993669"], ["83766.00", "3.902904"], ["83757.60", "4.719791"], ["83740.80", "4.992086"], ["83732.40", "5.445912"], ["83715.60", "5.536677"], ["83707.20", "4.901321"], ["83698.80", "4.538260"], ["83441.56", "0.000024"], ["83440.00", "0.000460"]], "checksum": 1359928311, "ts": "1742577161392"}], "ts": 1742577161396, "record_time": 1742577161.589363, "EXCHANGE": "BITGET"}
{"action": "update", "arg": {"instType": "SPOT", "channel": "books", "instId": "BTCUSDT"}, "data": [{"asks": [["83918.03", "1.293431"], ["83918.49", "0"], ["83962.10", "0.598334"], ["83976.40", "0.192107"], ["83978.40", "0.505544"], ["83980.40", "1.330380"], ["83982.40", "3.500999"], ["83984.40", "9.213157"], ["83987.60", "1.290990"], ["83990.40", "2.359710"], ["83991.80", "1.228650"], ["83992.20", "0.071670"], ["83995.30", "0"], ["83995.60", "1.429500"], ["84026.40", "4.175199"], ["84034.80", "5.445912"], ["84043.20", "4.810556"], ["84051.60", "4.992086"], ["84060.00", "4.538260"], ["84068.40", "5.173616"], ["84076.80", "5.536677"], ["84093.60", "5.355147"], ["84102.00", "5.627442"], ["84110.40", "4.084434"], ["84118.80", "5.082851"], ["84127.20", "4.629025"], ["84135.60", "4.447495"], ["84144.00", "3.993669"], ["84152.40", "4.901321"], ["84160.80", "5.264382"], ["84177.60", "3.902904"], ["84186.00", "4.265965"], ["84339.62", "0"]], "bids": [["83918.02", "0.619259"], ["83914.40", "0.001510"], ["83912.40", "0.003975"], ["83910.41", "0.011485"], ["83910.40", "0.010459"], ["83908.40", "0.027526"], ["83906.40", "0.072435"], ["83904.40", "0.190620"], ["83902.41", "0.773437"], ["83902.40", "0.501630"], ["83900.40", "1.320079"], ["83892.51", "0.323312"], ["83888.47", "0.006153"], ["83867.00", "0.000281"], ["83858.40", "4.084434"], ["83850.00", "4.901321"], ["83841.60", "5.627442"], ["83833.20", "3.902904"], ["83824.80", "4.992086"], ["83816.40", "5.445912"], ["83808.00", "4.719791"], ["83799.60", "5.355147"], ["83791.20", "4.538260"], ["83782.80", "3.993669"], ["83774.40", "4.810556"], ["83766.00", "4.356730"], ["83757.60", "5.082851"], ["83749.20", "5.264382"], ["83740.80", "4.447495"], ["83732.40", "4.629025"], ["83724.00", "5.173616"], ["83715.60", "4.265965"], ["83707.20", "5.536677"], ["83698.80", "4.175199"], ["83441.56", "0"], ["83440.00", "0"]], "checksum": 1765839692, "ts": "1742577161601"}], "ts": 1742577161606, "record_time": 1742577161.79849, "EXCHANGE": "BITGET"}
{"action": "update", "arg": {"instType": "SPOT", "channel": "books", "instId": "BTCUSDT"}, "data": [{"asks": [["83918.47", "0.092791"], ["83918.48", "0.034195"], ["83940.40", "0.006357"], ["83944.67", "0"], ["83947.19", "0.119858"], ["83951.46", "0"], ["83976.39", "0"], ["83986.10", "0.035730"], ["84026.40", "5.264382"], ["84043.20", "4.447495"], ["84051.60", "4.265965"], ["84060.00", "4.901321"], ["84068.40", "4.175199"], ["84076.80", "5.355147"], ["84085.20", "4.629025"], ["84093.60", "4.538260"], ["84102.00", "5.173616"], ["84110.40", "5.627442"], ["84127.20", "4.992086"], ["84135.60", "3.902904"], ["84144.00", "4.084434"], ["84152.40", "3.993669"], ["84160.80", "5.536677"], ["84169.20", "4.810556"], ["84177.60", "4.719791"], ["84186.00", "4.356730"]], "bids": [["83914.40", "0.001578"], ["83912.40", "0.004153"], ["83910.40", "0.010928"], ["83908.40", "0.028758"], ["83906.40", "0.075679"], ["83904.40", "0.199274"], ["83902.40", "0.524403"], ["83900.40", "1.380008"], ["83900.30", "0.102720"], ["83900.00", "0"], ["83898.18", "0"], ["83897.70", "0.479730"], ["83897.60", "0.069930"], ["83897.00", "0"], ["83896.70", "0.071370"], ["83896.30", "0.220920"], ["83896.00", "0.402300"], ["83895.30", "0.257460"], ["83894.70", "0.066420"], ["83893.91", "0.016433"], ["83891.37", "0"], ["83889.90", "0"], ["83887.11", "0.223055"], ["83858.40", "4.810556"], ["83850.00", "5.445912"], ["83841.60", "5.536677"], ["83833.20", "4.175199"], ["83824.80", "5.264382"], ["83816.40", "4.992086"], ["83808.00", "5.173616"], ["83799.60", "4.629025"], ["83791.20", "4.719791"], ["83782.80", "4.265965"], ["83774.40", "4.356730"], ["83766.00", "4.901321"], ["83757.60", "5.627442"], ["83749.20", "5.082851"], ["83732.40", "5.355147"], ["83724.00", "4.084434"], ["83715.60", "3.902904"], ["83707.20", "3.993669"], ["83698.80", "4.538260"], ["83442.50", "0"]], "checksum": 586555473, "ts": "1742577161813"}], "ts": 1742577161816, "record_time": 1742577162.009165, "EXCHANGE": "BITGET"}
{"action": "update", "arg": {"instType": "SPOT", "channel": "books", "instId": "BTCUSDT"}, "data": [{"asks": [["83918.46", "0.062032"], ["83918.48", "0"], ["84026.40", "4.447495"], ["84034.80", "4.629025"], ["84043.20", "5.627442"], ["84051.60", "4.538260"], ["84060.00", "4.810556"], ["84068.40", "5.536677"], ["84076.80", "3.902904"], ["84085.20", "4.901321"], ["84093.60", "3.993669"], ["84102.00", "5.082851"], ["84110.40", "5.355147"], ["84118.80", "5.264382"], ["84135.60", "4.356730"], ["84144.00", "5.445912"], ["84152.40", "5.173616"], ["84160.80", "4.175199"], ["84169.20", "4.265965"], ["84186.00", "4.084434"]], "bids": [["83914.40", "0.001458"], ["83912.40", "0.003835"], ["83910.40", "0.010093"], ["83908.40", "0.026561"], ["83906.40", "0.069896"], ["83904.40", "0.183937"], ["83902.40", "0.484045"], ["83900.40", "1.273802"], ["83868.00", "0.000121"], ["83858.40", "4.992086"], ["83850.00", "5.264382"], ["83841.60", "5.355147"], ["83824.80", "3.902904"], ["83816.40", "5.082851"], ["83808.00", "4.356730"], ["83799.60", "5.173616"], ["83791.20", "4.538260"], ["83782.80", "4.447495"], ["83774.40", "4.629025"], ["83766.00", "4.719791"], ["83757.60", "5.536677"], ["83749.20", "4.901321"], ["83740.80", "4.084434"], ["83732.40", "5.445912"], ["83724.00", "4.810556"], ["83715.60", "4.265965"], ["83698.80", "5.627442"]], "checksum": 486159598, "ts": "1742577162017"}], "ts": 1742577162020, "record_time": 1742577162.214083, "EXCHANGE": "BITGET"}
{"action": "update", "arg": {"instType": "SPOT", "channel": "books", "instId": "BTCUSDT"}, "data": [{"asks": [["83918.45", "0.092791"], ["83918.47", "0"], ["84026.40", "5.536677"], ["84034.80", "4.810556"], ["84043.20", "4.265965"], ["84051.60", "5.355147"], ["84060.00", "4.719791"], ["84068.40", "5.082851"], ["84076.80", "5.173616"], ["84085.20", "4.175199"], ["84093.60", "4.447495"], ["84102.00", "5.627442"], ["84110.40", "4.356730"], ["84118.80", "4.538260"], ["84127.20", "4.901321"], ["84135.60", "5.264382"], ["84144.00", "3.993669"], ["84152.40", "5.445912"], ["84160.80", "4.629025"], ["84169.20", "4.084434"], ["84177.60", "3.902904"], ["84186.00", "4.992086"]], "bids": [["83914.40", "0.001833"], ["83912.40", "0.004823"], ["83910.40", "0.012692"], ["83908.40", "0.033399"], ["83906.40", "0.087892"], ["83904.40", "0.231297"], ["83902.40", "0.608675"], ["83900.40", "1.601776"], ["83858.40", "4.447495"], ["83850.00", "5.173616"], ["83841.60", "4.538260"], ["83833.20", "3.993669"], ["83816.40", "4.265965"], ["83808.00", "4.175199"], ["83799.60", "5.445912"], ["83791.20", "4.629025"], ["83782.80", "5.264382"], ["83774.40", "4.084434"], ["83766.00", "5.536677"], ["83757.60", "4.356730"], ["83749.20", "5.355147"], ["83740.80", "4.719791"], ["83732.40", "5.627442"], ["83715.60", "5.082851"], ["83707.20", "4.992086"], ["83698.80", "4.901321"]], "checksum": 939885546, "ts": "1742577162225"}], "ts": 1742577162229, "record_time": 1742577162.422422, "EXCHANGE": "BITGET"}
{"action": "update", "arg": {"instType": "SPOT", "channel": "books", "instId": "BTCUSDT"}, "data": [{"asks": [["83918.03", "1.084231"], ["83918.44", "0.062032"], ["83918.46", "0"], ["83945.08", "0.314588"], ["83952.09", "0"], ["83966.40", "0.001515"], ["83972.40", "0.027613"], ["83974.40", "0.072666"], ["83976.40", "0.191226"], ["83978.40", "0.503225"], ["83980.40", "1.324278"], ["83982.40", "3.484941"], ["83984.40", "9.170897"], ["83986.10", "0"], ["83988.60", "0.030000"], ["83990.40", "0"], ["83992.10", "2.359650"], ["83995.20", "0.504840"], ["84026.40", "5.445912"], ["84034.80", "4.356730"], ["84043.20", "3.993669"], ["84051.60", "5.627442"], ["84060.00", "3.902904"], ["84068.40", "4.538260"], ["84076.80", "4.447495"], ["84085.20", "4.992086"], ["84093.60", "5.264382"], ["84102.00", "4.719791"], ["84110.40", "4.629025"], ["84118.80", "4.901321"], ["84127.20", "4.175199"], ["84135.60", "5.082851"], ["84144.00", "4.265965"], ["84152.40", "5.355147"], ["84160.80", "5.173616"], ["84169.20", "4.810556"], ["84177.60", "5.536677"], ["84186.00", "4.084434"], ["84339.62", "0.000051"]], "bids": [["83918.02", "0.609259"], ["83914.40", "0.002709"], ["83912.40", "0.007131"], ["83910.40", "0.018764"], ["83908.40", "0.049381"], ["83906.40", "0.129842"], ["83904.40", "0.341690"], ["83902.40", "0.899184"], ["83901.42", "0.024669"], ["83900.40", "2.366273"], ["83899.80", "0.420210"], ["83897.70", "0"], ["83895.30", "0.253770"], ["83892.00", "1.350000"], ["83883.40", "0.012460"], ["83868.00", "0"], ["83858.40", "4.629025"], ["83850.00", "5.355147"], ["83841.60", "4.992086"], ["83833.20", "4.356730"], ["83824.80", "4.447495"], ["83816.40", "5.082851"], ["83808.00", "4.265965"], ["83799.60", "5.627442"], ["83791.20", "4.810556"], ["83782.80", "4.175199"], ["83774.40", "5.264382"], ["83766.00", "3.993669"], ["83757.60", "4.084434"], ["83749.20", "5.536677"], ["83740.80", "3.902904"], ["83732.40", "4.538260"], ["83724.00", "5.445912"], ["83715.60", "4.719791"], ["83707.20", "4.901321"], ["83698.80", "5.173616"]], "checksum": 396672073, "ts": "1742577162424"}], "ts": 1742577162428, "record_time": 1742577162.621469, "EXCHANGE": "BITGET"}
{"action": "update", "arg": {"instType": "SPOT", "channel": "books", "instId": "BTCUSDT"}, "data": [{"asks": [["83918.45", "0"], ["83941.45", "0"], ["83941.63", "0.173568"], ["83942.57", "0.006357"], ["83950.53", "0"], ["83987.60", "0.671550"], ["83991.80", "1.786680"], ["84026.40", "4.810556"], ["84034.80", "5.264382"], ["84051.60", "5.445912"], ["84060.00", "5.082851"], ["84068.40", "4.992086"], ["84076.80", "5.355147"], ["84085.20", "4.356730"], ["84093.60", "4.538260"], ["84102.00", "4.265965"], ["84118.80", "3.902904"], ["84121.72", "0"], ["84127.20", "5.173616"], ["84135.60", "4.084434"], ["84144.00", "4.901321"], ["84152.40", "5.627442"], ["84160.80", "4.447495"], ["84169.20", "5.536677"], ["84177.60", "4.719791"], ["84186.00", "4.175199"], ["84340.00", "0.018287"], ["84340.46", "0.000143"], ["84340.72", "0.000066"]], "bids": [["83914.40", "0.001833"], ["83912.40", "0.004823"], ["83910.41", "0.019008"], ["83910.40", "0.012693"], ["83908.40", "0.033402"], ["83906.40", "0.088038"], ["83904.40", "0.231678"], ["83902.40", "0.609679"], ["83901.42", "0"], ["83900.40", "1.604417"], ["83892.55", "0.024669"], ["83892.50", "0.784860"], ["83892.05", "0.009010"], ["83892.00", "0.000121"], ["83890.93", "0"], ["83889.90", "0.536970"], ["83866.00", "0.000160"], ["83858.40", "5.355147"], ["83850.00", "5.264382"], ["83841.60", "4.538260"], ["83833.20", "4.629025"], ["83824.80", "4.901321"], ["83816.40", "4.992086"], ["83808.00", "3.902904"], ["83799.60", "5.445912"], ["83791.20", "4.719791"], ["83782.80", "4.265965"], ["83774.40", "4.810556"], ["83766.00", "4.356730"], ["83757.60", "3.993669"], ["83749.20", "5.173616"], ["83740.80", "5.627442"], ["83732.40", "5.536677"], ["83724.00", "4.447495"], ["83715.60", "4.084434"], ["83707.20", "5.082851"], ["83698.80", "4.175199"], ["83444.27", "0"], ["83443.53", "0"]], "checksum": 1172597275, "ts": "1742577162644"}], "ts": 1742577162646, "record_time": 1742577162.839169, "EXCHANGE": "BITGET"}
{"action": "update", "arg": {"instType": "SPOT", "channel": "books", "instId": "BTCUSDT"}, "data": [{"asks": [["83918.44", "0.126986"], ["83988.60", "0.015000"], ["83990.00", "2.402010"], ["83992.10", "0"], ["84026.40", "5.264382"], ["84034.80", "4.810556"], ["84048.59", "0"], ["84051.60", "5.627442"], ["84060.00", "5.173616"], ["84068.40", "4.447495"], ["84076.80", "3.902904"], ["84085.20", "5.445912"], ["84093.60", "5.082851"], ["84110.40", "4.356730"], ["84118.40", "0.162031"], ["84118.80", "4.901321"], ["84127.20", "4.084434"], ["84135.60", "5.355147"], ["84144.00", "5.536677"], ["84152.40", "4.629025"], ["84160.80", "4.992086"], ["84169.20", "4.719791"], ["84177.60", "4.175199"], ["84186.00", "4.538260"], ["84341.00", "0.002997"]], "bids": [["83914.40", "0.001983"], ["83912.40", "0.005218"], ["83910.41", "0.011485"], ["83910.40", "0.013732"], ["83908.40", "0.036137"], ["83906.40", "0.095097"], ["83904.40", "0.250256"], ["83902.40", "0.658568"], ["83900.40", "1.733074"], ["83892.55", "0"], ["83892.50", "0.749100"], ["83858.40", "4.084434"], ["83850.00", "4.992086"], ["83849.46", "0"], ["83841.60", "3.993669"], ["83833.20", "5.355147"], ["83824.80", "5.173616"], ["83816.40", "4.175199"], ["83808.00", "4.629025"], ["83799.60", "4.810556"], ["83791.20", "5.536677"], ["83774.40", "5.445912"], ["83766.00", "5.082851"], ["83757.60", "5.264382"], ["83749.20", "4.538260"], ["83740.80", "4.447495"], ["83732.40", "4.901321"], ["83724.00", "4.719791"], ["83715.60", "3.902904"], ["83707.20", "5.627442"], ["83698.80", "4.356730"], ["83444.27", "0.000028"], ["83443.53", "0.000161"]], "checksum": -609228386, "ts": "1742577162849"}], "ts": 1742577162853, "record_time": 1742577163.045804, "EXCHANGE": "BITGET"}
{"action": "update", "arg": {"instType": "SPOT", "channel": "books", "instId": "BTCUSDT"}, "data": [{"asks": [["83918.03", "1.293431"], ["83918.43", "0.053681"], ["83918.44", "0.092791"], ["83976.40", "0.191387"], ["83978.40", "0.503651"], ["83980.40", "1.325398"], ["83982.40", "3.487888"], ["83984.40", "9.178654"], ["83986.10", "0.035730"], ["83987.60", "1.290990"], ["83991.80", "1.228650"], ["83995.20", "0.492360"], ["84026.40", "4.084434"], ["84034.80", "4.356730"], ["84043.20", "3.902904"], ["84051.60", "3.993669"], ["84060.00", "5.355147"], ["84068.40", "4.901321"], ["84076.80", "4.810556"], ["84085.20", "4.992086"], ["84102.00", "4.629025"], ["84110.40", "5.173616"], ["84118.80", "4.538260"], ["84127.20", "5.445912"], ["84135.60", "5.627442"], ["84152.40", "5.264382"], ["84160.80", "4.265965"], ["84169.20", "4.175199"], ["84177.60", "4.719791"], ["84186.00", "4.447495"], ["84340.72", "0"], ["84341.00", "0"]], "bids": [["83904.40", "0.249998"], ["83902.40", "0.657889"], ["83900.40", "1.731288"], ["83889.90", "0"], ["83866.00", "0.000281"], ["83858.40", "5.536677"], ["83850.00", "3.993669"], ["83841.60", "5.264382"], ["83833.20", "4.084434"], ["83824.80", "5.627442"], ["83816.40", "4.447495"], ["83808.00", "4.992086"], ["83791.20", "4.265965"], ["83782.80", "4.175199"], ["83774.40", "3.902904"], ["83757.60", "5.445912"], ["83749.20", "4.356730"], ["83740.80", "4.719791"], ["83732.40", "4.629025"], ["83724.00", "5.173616"], ["83715.60", "4.901321"], ["83707.20", "4.538260"], ["83698.80", "5.355147"], ["83442.50", "0.000113"]], "checksum": 2005807278, "ts": "1742577163051"}], "ts": 1742577163054, "record_time": 1742577163.255376, "EXCHANGE": "BITGET"}
{"action": "update", "arg": {"instType": "SPOT", "channel": "books", "instId": "BTCUSDT"}, "data": [{"asks": [["83918.42", "0.092791"], ["83918.44", "0"], ["83936.65", "0"], ["83937.89", "0.119905"], ["83938.01", "0"], ["83938.46", "0"], ["83938.59", "0"], ["83938.72", "0"], ["83939.12", "0"], ["83939.17", "0.035972"], ["83939.67", "0.006357"], ["83939.75", "0.006357"], ["83939.79", "0"], ["83939.91", "0"], ["83940.01", "0.215557"], ["83940.12", "0"], ["83940.36", "0"], ["83940.39", "0.006357"], ["83940.91", "0"], ["83941.01", "0"], ["83941.10", "0.010995"], ["83941.11", "0.006357"], ["83941.38", "0.006356"], ["83941.46", "0"], ["83941.58", "0.006357"], ["83941.64", "0"], ["83941.81", "0"], ["83941.85", "0"], ["83942.11", "0.016429"], ["83942.12", "0.006357"], ["83942.23", "0.006357"], ["83942.67", "0.006357"], ["83942.76", "0"], ["83942.89", "0.119901"], ["83943.01", "0.016429"], ["83943.06", "0.006357"], ["83943.10", "0.006357"], ["83943.47", "0"], ["83943.49", "0"], ["83944.05", "0.006357"], ["83944.10", "0"], ["83944.68", "0.010993"], ["83944.69", "0.006357"], ["83945.22", "0"], ["83945.39", "0.009990"], ["83946.26", "0"], ["83946.38", "0.119850"], ["83946.53", "0"], ["83946.83", "0"], ["83947.50", "0.119905"], ["83947.78", "0.015895"], ["83947.98", "0.009989"], ["83948.69", "0"], ["83949.96", "0.006356"], ["83950.47", "0"], ["83951.70", "0.015896"], ["83966.68", "0.059035"], ["83974.40", "0.072774"], ["83976.40", "0.191511"], ["83978.40", "0.503978"], ["83980.40", "1.326257"], ["83982.40", "3.490150"], ["83984.40", "9.184606"], ["84026.40", "4.810556"], ["84034.80", "5.627442"], ["84043.20", "4.265965"], ["84051.60", "4.175199"], ["84060.00", "5.264382"], ["84068.40", "4.992086"], ["84076.80", "4.447495"], ["84085.20", "5.082851"], ["84093.60", "5.355147"], ["84102.00", "5.536677"], ["84110.40", "3.902904"], ["84118.80", "5.445912"], ["84127.20", "4.538260"], ["84135.60", "4.084434"], ["84144.00", "4.901321"], ["84152.40", "3.993669"], ["84160.80", "4.629025"], ["84169.20", "4.719791"], ["84177.60", "5.173616"], ["84186.00", "4.356730"], ["84340.00", "0"], ["84340.46", "0"]], "bids": [["83914.40", "0.001727"], ["83912.40", "0.004545"], ["83910.40", "0.011962"], ["83908.40", "0.031477"], ["83906.40", "0.082836"], ["83904.40", "0.217988"], ["83902.40", "0.573653"], ["83900.40", "1.509613"], ["83896.77", "0.247543"], ["83895.53", "0.083637"], ["83895.19", "0.017826"], ["83894.94", "0.018273"], ["83894.53", "0.005950"], ["83894.38", "0"], ["83894.24", "0.015750"], ["83893.99", "0"], ["83893.85", "0.004036"], ["83893.78", "0"], ["83893.61", "0.006572"], ["83893.43", "0.055637"], ["83893.24", "0"], ["83893.21", "0.017124"], ["83893.08", "0.007141"], ["83892.97", "0"], ["83892.60", "0.036222"], ["83892.41", "0"], ["83892.39", "0.017114"], ["83892.15", "0.007956"], ["83892.12", "0"], ["83891.96", "0"], ["83891.86", "0"], ["83891.82", "0.025199"], ["83891.70", "0.225049"], ["83891.57", "0.008200"], ["83891.53", "0.017376"], ["83891.40", "0"], ["83891.39", "0"], ["83891.29", "0.008556"], ["83891.16", "0"], ["83890.94", "0"], ["83890.62", "0"], ["83890.51", "0.008290"], ["83890.45", "0"], ["83890.33", "0"], ["83890.28", "0"], ["83890.15", "0.012674"], ["83890.13", "0.051846"], ["83889.22", "0"], ["83889.17", "0.018549"], ["83888.94", "0"], ["83888.93", "0"], ["83888.31", "0.268841"], ["83887.87", "0"], ["83887.15", "0"], ["83887.08", "0.259212"], ["83886.86", "0.076244"], ["83886.72", "0.021166"], ["83885.84", "0"], ["83885.60", "0"], ["83885.57", "0"], ["83884.67", "0.012460"], ["83883.40", "0"], ["83882.89", "0.073186"], ["83881.66", "0"], ["83880.38", "0.000878"], ["83879.15", "0"], ["83867.00", "0.000121"], ["83861.91", "0.003603"], ["83860.63", "0"], ["83858.40", "4.629025"], ["83841.60", "4.538260"], ["83833.20", "4.901321"], ["83824.80", "4.265965"], ["83816.40", "4.356730"], ["83799.60", "5.445912"], ["83791.20", "4.084434"], ["83782.80", "5.264382"], ["83774.40", "4.719791"], ["83766.00", "4.175199"], ["83757.60", "5.355147"], ["83749.20", "5.082851"], ["83740.80", "5.627442"], ["83732.40", "5.536677"], ["83724.00", "3.902904"], ["83715.60", "5.173616"], ["83707.20", "4.810556"], ["83698.80", "4.447495"], ["83441.56", "0.000024"]], "checksum": 536001577, "ts": "1742577163280"}], "ts": 1742577163284, "record_time": 1742577163.477335, "EXCHANGE": "BITGET"}
{"action": "update", "arg": {"instType": "SPOT", "channel": "books", "instId": "BTCUSDT"}, "data": [{"asks": [["83918.41", "0.062032"], ["83918.43", "0"], ["83936.29", "0"], ["83971.59", "0"], ["83973.60", "0.001598"], ["84026.40", "5.445912"], ["84034.80", "4.719791"], ["84043.20", "3.993669"], ["84051.60", "4.084434"], ["84068.40", "4.356730"], ["84076.80", "4.810556"], ["84085.20", "5.173616"], ["84093.60", "3.902904"], ["84102.00", "5.627442"], ["84110.40", "4.992086"], ["84118.80", "4.901321"], ["84127.20", "4.447495"], ["84135.60", "4.175199"], ["84144.00", "4.538260"], ["84152.40", "5.536677"], ["84169.20", "5.082851"], ["84177.60", "4.265965"], ["84186.00", "5.355147"], ["84340.00", "0.018287"]], "bids": [["83912.40", "0.004765"], ["83910.40", "0.012541"], ["83908.40", "0.033003"], ["83906.40", "0.086850"], ["83904.40", "0.228552"], ["83902.40", "0.601451"], ["83900.40", "1.582767"], ["83896.81", "0"], ["83892.51", "0"], ["83859.64", "0.001174"], ["83858.40", "4.084434"], ["83857.63", "0"], ["83850.00", "4.629025"], ["83841.60", "4.901321"], ["83833.20", "4.538260"], ["83824.80", "4.992086"], ["83816.40", "5.173616"], ["83808.00", "5.355147"], ["83799.60", "5.082851"], ["83791.20", "4.719791"], ["83782.80", "5.627442"], ["83774.40", "4.356730"], ["83766.00", "4.810556"], ["83757.60", "4.175199"], ["83749.20", "5.264382"], ["83740.80", "3.902904"], ["83732.40", "4.265965"], ["83724.00", "3.993669"], ["83715.60", "5.445912"], ["83707.20", "4.447495"], ["83698.80", "5.536677"], ["83440.00", "0.000460"], ["83439.42", "0.000423"]], "checksum": -947544854, "ts": "1742577163483"}], "ts": 1742577163487, "record_time": 1742577163.68215, "EXCHANGE": "BITGET"}
{"action": "update", "arg": {"instType": "SPOT", "channel": "books", "instId": "BTCUSDT"}, "data": [{"asks": [["83918.03", "0.875031"], ["83918.42", "0"], ["83936.29", "0.010791"], ["83964.44", "0"], ["83969.90", "0"], ["83971.72", "0.001598"], ["83986.10", "0"], ["83987.60", "0.671550"], ["83989.40", "0"], ["83990.00", "0.042300"], ["83991.80", "1.761450"], ["83992.10", "2.359650"], ["83992.20", "0"], ["83995.80", "2.474670"], ["83996.10", "1.638000"], ["84026.40", "4.538260"], ["84034.80", "4.810556"], ["84043.20", "5.536677"], ["84051.60", "5.082851"], ["84060.00", "3.993669"], ["84068.40", "4.629025"], ["84076.80", "5.355147"], ["84085.20", "4.447495"], ["84093.60", "4.901321"], ["84102.00", "4.992086"], ["84110.40", "4.175199"], ["84118.80", "5.173616"], ["84127.20", "5.445912"], ["84135.60", "4.084434"], ["84144.00", "5.264382"], ["84152.40", "4.719791"], ["84160.80", "3.902904"], ["84169.20", "4.356730"], ["84186.00", "5.627442"], ["84340.46", "0.000143"]], "bids": [["83914.40", "0.002687"], ["83912.40", "0.007072"], ["83910.40", "0.018611"], ["83908.40", "0.048974"], ["83906.40", "0.128879"], ["83904.40", "0.339157"], ["83902.40", "0.892519"], ["83900.40", "2.348734"], ["83896.78", "0.441053"], ["83892.50", "1.062870"], ["83892.00", "1.350000"], ["83861.62", "0.001177"], ["83859.81", "0"], ["83858.40", "3.902904"], ["83850.00", "4.447495"], ["83841.60", "5.445912"], ["83833.20", "4.810556"], ["83824.80", "5.355147"], ["83816.40", "5.627442"], ["83808.00", "3.993669"], ["83799.60", "4.356730"], ["83791.20", "5.264382"], ["83782.80", "4.901321"], ["83774.40", "4.084434"], ["83766.00", "5.536677"], ["83757.60", "4.719791"], ["83749.20", "4.175199"], ["83740.80", "4.629025"], ["83732.40", "5.173616"], ["83724.00", "4.992086"], ["83715.60", "4.538260"], ["83707.20", "5.082851"], ["83698.80", "4.265965"], ["83439.42", "0"]], "checksum": -1689178790, "ts": "1742577163703"}], "ts": 1742577163706, "record_time": 1742577163.916487, "EXCHANGE": "BITGET"}
{"action": "update", "arg": {"instType": "SPOT", "channel": "books", "instId": "BTCUSDT"}, "data": [{"asks": [["83918.41", "0.126986"], ["83936.30", "0"], ["83937.55", "0.049537"], ["83966.40", "0.001353"], ["83968.40", "0.003561"], ["83970.40", "0.009372"], ["83972.40", "0.024662"], ["83974.40", "0.064902"], ["83976.40", "0.170793"], ["83978.40", "0.449455"], ["83980.40", "1.182776"], ["83982.40", "3.112571"], ["83984.40", "8.190975"], ["83994.80", "0.012480"], ["84026.40", "4.629025"], ["84034.80", "5.445912"], ["84043.20", "4.901321"], ["84051.60", "5.173616"], ["84060.00", "4.538260"], ["84068.40", "4.084434"], ["84076.80", "4.447495"], ["84085.20", "4.356730"], ["84093.60", "5.536677"], ["84102.00", "3.902904"], ["84110.40", "5.082851"], ["84118.80", "4.992086"], ["84127.20", "4.265965"], ["84135.60", "4.175199"], ["84144.00", "3.993669"], ["84152.40", "5.355147"], ["84160.80", "5.627442"], ["84169.20", "5.264382"], ["84177.60", "4.719791"], ["84186.00", "4.810556"]], "bids": [["83914.40", "0.002943"], ["83912.40", "0.007744"], ["83910.41", "0.018840"], ["83910.40", "0.020381"], ["83908.40", "0.053634"], ["83906.40", "0.141141"], ["83904.40", "0.371666"], ["83902.40", "0.978070"], ["83900.40", "2.573868"], ["83897.27", "0.089673"], ["83896.02", "0"], ["83889.90", "0.536970"], ["83868.00", "0.000160"], ["83867.00", "0"], ["83858.40", "5.627442"], ["83850.00", "4.538260"], ["83841.60", "5.173616"], ["83833.20", "4.175199"], ["83824.80", "3.993669"], ["83816.40", "5.536677"], ["83808.00", "4.810556"], ["83799.60", "5.445912"], ["83791.20", "4.629025"], ["83782.80", "5.082851"], ["83774.40", "4.719791"], ["83766.00", "4.265965"], ["83757.60", "4.356730"], ["83749.20", "4.084434"], ["83740.80", "4.901321"], ["83732.40", "5.355147"], ["83724.00", "3.902904"], ["83715.60", "4.447495"], ["83707.20", "5.264382"], ["83698.80", "4.992086"], ["83440.00", "0"]], "checksum": -1123539992, "ts": "1742577163931"}], "ts": 1742577163934, "record_time": 1742577164.126478, "EXCHANGE": "BITGET"}
{"action": "update", "arg": {"instType": "SPOT", "channel": "books", "instId": "BTCUSDT"}, "data": [{"asks": [["83918.03", "1.084231"], ["83918.40", "0.053681"], ["83918.41", "0.092791"], ["83936.29", "0"], ["83962.10", "0.723618"], ["83966.40", "0.001479"], ["83968.40", "0.003893"], ["83970.40", "0.010500"], ["83972.40", "0.027631"], ["83974.40", "0.072713"], ["83976.40", "0.191350"], ["83978.40", "0.503552"], ["83980.40", "1.325137"], ["83982.40", "3.487203"], ["83984.40", "9.176849"], ["83989.80", "0.100890"], ["83996.10", "0"], ["84026.40", "5.082851"], ["84034.80", "3.902904"], ["84043.20", "5.173616"], ["84051.60", "4.356730"], ["84060.00", "5.355147"], ["84068.40", "5.264382"], ["84076.80", "4.629025"], ["84085.20", "4.992086"], ["84093.60", "4.175199"], ["84102.00", "4.447495"], ["84110.40", "5.627442"], ["84118.80", "5.536677"], ["84127.20", "4.719791"], ["84135.60", "4.084434"], ["84144.00", "4.265965"], ["84152.40", "4.810556"], ["84160.80", "4.538260"], ["84169.20", "3.993669"], ["84177.60", "5.445912"], ["84186.00", "4.901321"]], "bids": [["83914.40", "0.002068"], ["83912.40", "0.005443"], ["83910.40", "0.014323"], ["83908.40", "0.037692"], ["83906.40", "0.099191"], ["83904.40", "0.261029"], ["83902.41", "1.198914"], ["83902.40", "0.686918"], ["83900.40", "1.807678"], ["83899.60", "0.268470"], ["83897.60", "0.069720"], ["83896.78", "0"], ["83894.70", "0"], ["83892.00", "0.000121"], ["83858.40", "5.355147"], ["83850.00", "4.992086"], ["83841.60", "4.629025"], ["83824.80", "4.538260"], ["83808.00", "5.173616"], ["83791.20", "4.719791"], ["83782.80", "3.993669"], ["83774.40", "5.264382"], ["83766.00", "5.627442"], ["83757.60", "5.082851"], ["83749.20", "3.902904"], ["83740.80", "4.810556"], ["83732.40", "4.265965"], ["83724.00", "4.447495"], ["83715.60", "4.084434"], ["83707.20", "4.901321"], ["83698.80", "4.356730"], ["83440.00", "0.000460"]], "checksum": 1547304711, "ts": "1742577164132"}], "ts": 1742577164135, "record_time": 1742577164.327213, "EXCHANGE": "BITGET"}
{"action": "update", "arg": {"instType": "SPOT", "channel": "books", "instId": "BTCUSDT"}, "data": [{"asks": [["83918.39", "0.092791"], ["83918.41", "0"], ["83976.40", "0.191511"], ["83978.40", "0.503976"], ["83980.40", "1.326053"], ["83982.40", "3.489613"], ["83984.40", "9.183192"], ["83986.10", "0.006300"], ["83988.60", "0"], ["83990.30", "2.359710"], ["83992.10", "0"], ["83992.20", "0.072390"], ["83994.80", "0"], ["84026.40", "4.719791"], ["84034.80", "4.175199"], ["84043.20", "4.901321"], ["84051.60", "4.084434"], ["84060.00", "4.629025"], ["84068.40", "4.447495"], ["84076.80", "3.902904"], ["84085.20", "5.445912"], ["84093.60", "5.627442"], ["84102.00", "5.082851"], ["84110.40", "3.993669"], ["84118.80", "5.264382"], ["84127.20", "4.538260"], ["84135.60", "5.536677"], ["84144.00", "4.356730"], ["84152.40", "5.173616"], ["84160.80", "4.265965"], ["84169.20", "4.992086"], ["84177.60", "5.355147"], ["84186.00", "4.810556"]], "bids": [["83906.40", "0.098981"], ["83904.40", "0.260476"], ["83902.40", "0.685461"], ["83900.40", "1.803716"], ["83899.60", "0"], ["83897.60", "0.069930"], ["83896.84", "0.175595"], ["83895.80", "0.193560"], ["83892.50", "0.749100"], ["83889.90", "0"], ["83858.40", "3.993669"], ["83850.00", "4.356730"], ["83841.60", "4.447495"], ["83833.20", "5.355147"], ["83824.80", "4.901321"], ["83816.40", "5.173616"], ["83808.00", "4.538260"], ["83799.60", "4.084434"], ["83782.80", "5.627442"], ["83774.40", "3.902904"], ["83766.00", "4.265965"], ["83757.60", "4.175199"], ["83749.20", "4.992086"], ["83740.80", "4.629025"], ["83732.40", "5.264382"], ["83724.00", "5.445912"], ["83715.60", "5.082851"], ["83707.20", "4.810556"], ["83698.80", "5.536677"]], "checksum": -1178301546, "ts": "1742577164336"}], "ts": 1742577164340, "record_time": 1742577164.533316, "EXCHANGE": "BITGET"}
{"action": "update", "arg": {"instType": "SPOT", "channel": "books", "instId": "BTCUSDT"}, "data": [{"asks": [["83918.38", "0.062032"], ["83918.40", "0"], ["83986.10", "0.009330"], ["83987.60", "1.290690"], ["83988.60", "0.015000"], ["83991.80", "1.228650"], ["83995.80", "0"], ["84026.40", "5.082851"], ["84034.80", "4.719791"], ["84043.20", "5.536677"], ["84051.60", "4.265965"], ["84060.00", "4.810556"], ["84068.40", "4.084434"], ["84076.80", "4.538260"], ["84085.20", "5.264382"], ["84093.60", "4.992086"], ["84102.00", "4.356730"], ["84110.40", "4.901321"], ["84118.80", "4.629025"], ["84127.20", "4.175199"], ["84135.60", "5.445912"], ["84144.00", "5.627442"], ["84152.40", "3.993669"], ["84160.80", "4.447495"], ["84169.20", "3.902904"], ["84186.00", "5.173616"]], "bids": [["83918.02", "0.619259"], ["83912.40", "0.005210"], ["83910.40", "0.013713"], ["83908.40", "0.036085"], ["83906.40", "0.094960"], ["83904.40", "0.249896"], ["83902.40", "0.657621"], ["83900.40", "1.730711"], ["83868.00", "0.000281"], ["83866.00", "0.000121"], ["83858.40", "4.538260"], ["83841.60", "3.902904"], ["83833.20", "4.265965"], ["83824.80", "5.536677"], ["83816.40", "5.355147"], ["83808.00", "4.992086"], ["83799.60", "4.810556"], ["83791.20", "5.445912"], ["83782.80", "4.719791"], ["83774.40", "4.084434"], ["83766.00", "5.173616"], ["83757.60", "5.264382"], ["83749.20", "5.627442"], ["83740.80", "4.901321"], ["83732.40", "4.629025"], ["83724.00", "4.447495"], ["83707.20", "4.175199"], ["83698.80", "3.993669"]], "checksum": 310598842, "ts": "1742577164544"}], "ts": 1742577164548, "record_time": 1742577164.740847, "EXCHANGE": "BITGET"}
{"action": "update", "arg": {"instType": "SPOT", "channel": "books", "instId": "BTCUSDT"}, "data": [{"asks": [["83918.38", "0.154823"], ["83918.39", "0"], ["83951.81", "0"], ["83952.73", "0.010988"], ["83966.40", "0.001663"], ["83968.40", "0.004378"], ["83970.40", "0.011521"], ["83972.40", "0.030319"], ["83974.40", "0.079786"], ["83976.40", "0.209962"], ["83978.40", "0.552533"], ["83980.40", "1.454033"], ["83982.40", "3.826403"], ["83984.40", "10.069482"], ["83986.10", "0"], ["83995.80", "2.474670"], ["84026.40", "4.992086"], ["84034.80", "4.538260"], ["84043.20", "4.356730"], ["84051.60", "5.355147"], ["84060.00", "5.445912"], ["84068.40", "4.447495"], ["84076.80", "4.084434"], ["84085.20", "4.629025"], ["84093.60", "5.264382"], ["84102.00", "5.082851"], ["84110.40", "4.265965"], ["84118.80", "5.536677"], ["84135.60", "4.810556"], ["84144.00", "3.993669"], ["84152.40", "4.719791"], ["84160.80", "5.627442"], ["84169.20", "4.901321"], ["84177.60", "5.173616"], ["84186.00", "3.902904"], ["84340.72", "0.000066"]], "bids": [["83912.40", "0.005323"], ["83910.40", "0.014008"], ["83908.40", "0.036864"], ["83906.40", "0.097011"], ["83904.40", "0.255292"], ["83902.40", "0.671820"], ["83900.40", "1.767949"], ["83882.24", "0.056465"], ["83881.32", "0"], ["83858.40", "4.719791"], ["83850.00", "5.355147"], ["83833.20", "5.082851"], ["83824.80", "4.629025"], ["83816.40", "4.538260"], ["83808.00", "4.356730"], ["83799.60", "4.175199"], ["83791.20", "4.810556"], ["83782.80", "5.264382"], ["83774.40", "4.447495"], ["83766.00", "5.627442"], ["83757.60", "4.901321"], ["83749.20", "4.265965"], ["83740.80", "5.536677"], ["83732.40", "5.445912"], ["83724.00", "5.173616"], ["83715.60", "3.993669"], ["83707.20", "4.992086"], ["83698.80", "4.084434"]], "checksum": -1461573490, "ts": "1742577164758"}], "ts": 1742577164761, "record_time": 1742577164.954164, "EXCHANGE": "BITGET"}
{"action": "update", "arg": {"instType": "SPOT", "channel": "books", "instId": "BTCUSDT"}, "data": [{"asks": [["83918.37", "0.062032"], ["83918.38", "0.092791"], ["83987.90", "0.008010"], ["84026.40", "3.902904"], ["84034.80", "4.629025"], ["84043.20", "4.175199"], ["84051.60", "5.627442"], ["84068.40", "4.084434"], ["84076.80", "3.993669"], ["84085.20", "5.082851"], ["84093.60", "4.538260"], ["84102.00", "5.536677"], ["84110.40", "4.356730"], ["84118.80", "5.355147"], ["84127.20", "4.447495"], ["84135.60", "4.265965"], ["84144.00", "5.173616"], ["84160.80", "5.264382"], ["84169.20", "4.810556"], ["84177.60", "4.992086"], ["84186.00", "4.901321"], ["84340.72", "0"]], "bids": [["83912.40", "0.005541"], ["83910.40", "0.014582"], ["83908.40", "0.038373"], ["83906.40", "0.100982"], ["83904.40", "0.265743"], ["83902.40", "0.699322"], ["83900.40", "1.840321"], ["83858.40", "4.538260"], ["83850.00", "4.084434"], ["83841.60", "5.355147"], ["83824.80", "5.536677"], ["83816.40", "5.173616"], ["83808.00", "4.447495"], ["83799.60", "3.993669"], ["83791.20", "4.265965"], ["83782.80", "3.902904"], ["83774.40", "5.627442"], ["83766.00", "4.175199"], ["83757.60", "4.356730"], ["83749.20", "5.264382"], ["83740.80", "5.445912"], ["83732.40", "4.629025"], ["83724.00", "4.992086"], ["83715.60", "4.719791"], ["83707.20", "4.810556"], ["83698.80", "4.901321"]], "checksum": -1600235268, "ts": "1742577164962"}], "ts": 1742577164966, "record_time": 1742577165.158948, "EXCHANGE": "BITGET"}
{"action": "update", "arg": {"instType": "SPOT", "channel": "books", "instId": "BTCUSDT"}, "data": [{"asks": [["83918.37", "0"], ["83946.98", "0.169505"], ["83966.40", "0.001517"], ["83966.68", "0"], ["83968.40", "0.003993"], ["83970.40", "0.010507"], ["83972.40", "0.027650"], ["83974.40", "0.072763"], ["83976.40", "0.191483"], ["83978.40", "0.503903"], ["83980.40", "1.326058"], ["83982.40", "3.489627"], ["83984.40", "9.183229"], ["83987.60", "0.671550"], ["83988.50", "0"], ["83993.20", "1.429500"], ["84026.40", "4.084434"], ["84034.80", "4.356730"], ["84051.60", "5.445912"], ["84060.00", "4.265965"], ["84068.40", "4.538260"], ["84076.80", "4.447495"], ["84085.20", "4.810556"], ["84093.60", "5.173616"], ["84102.00", "4.629025"], ["84110.40", "3.902904"], ["84118.80", "4.901321"], ["84127.20", "4.719791"], ["84135.60", "3.993669"], ["84144.00", "5.264382"], ["84152.40", "5.082851"], ["84160.80", "5.536677"], ["84169.20", "4.992086"], ["84177.60", "5.355147"], ["84186.00", "5.627442"], ["84340.72", "0.000066"], ["84341.00", "0.002997"]], "bids": [["83914.40", "0.001071"], ["83913.18", "0"], ["83912.78", "0.113972"], ["83912.40", "0.002151"], ["83910.40", "0.005660"], ["83908.40", "0.014895"], ["83906.40", "0.039198"], ["83904.40", "0.103153"], ["83902.40", "0.271453"], ["83900.40", "0.714352"], ["83900.30", "0.001020"], ["83897.60", "0"], ["83896.70", "0.071580"], ["83896.30", "0.221130"], ["83895.80", "0"], ["83894.00", "1.429500"], ["83893.80", "0.066420"], ["83890.00", "0.042300"], ["83889.90", "0.536970"], ["83867.00", "0.000160"], ["83858.40", "5.536677"], ["83841.60", "4.356730"], ["83833.20", "4.901321"], ["83824.80", "4.629025"], ["83816.40", "5.264382"], ["83808.00", "5.445912"], ["83799.60", "4.175199"], ["83791.20", "3.993669"], ["83782.80", "5.082851"], ["83774.40", "5.173616"], ["83766.00", "5.627442"], ["83757.60", "4.719791"], ["83749.20", "4.992086"], ["83740.80", "4.538260"], ["83732.40", "3.902904"], ["83724.00", "5.355147"], ["83715.60", "4.810556"], ["83707.20", "4.265965"], ["83698.80", "4.447495"], ["83441.56", "0"], ["83440.00", "0"]], "checksum": -485158644, "ts": "1742577165183"}], "ts": 1742577165187, "record_time": 1742577165.381654, "EXCHANGE": "BITGET"}
{"action": "update", "arg": {"instType": "SPOT", "channel": "books", "instId": "BTCUSDT"}, "data": [{"asks": [["83918.03", "1.293431"], ["83918.37", "0.154823"], ["83918.38", "0"], ["83966.40", "0.001664"], ["83968.40", "0.004378"], ["83970.40", "0.011523"], ["83972.40", "0.030324"], ["83974.40", "0.079800"], ["83976.40", "0.209999"], ["83978.40", "0.552628"], ["83980.40", "1.454286"], ["83982.40", "3.827068"], ["83984.40", "10.071230"], ["83986.10", "0.035730"], ["83995.80", "0"], ["84026.40", "4.992086"], ["84034.80", "4.901321"], ["84043.20", "5.082851"], ["84051.60", "4.447495"], ["84060.00", "4.175199"], ["84068.40", "4.265965"], ["84076.80", "5.264382"], ["84085.20", "5.445912"], ["84093.60", "4.356730"], ["84102.00", "3.993669"], ["84110.40", "5.173616"], ["84118.80", "4.629025"], ["84135.60", "3.902904"], ["84144.00", "5.627442"], ["84152.40", "5.536677"], ["84160.80", "4.810556"], ["84169.20", "4.084434"], ["84186.00", "4.538260"]], "bids": [["83912.40", "0.001940"], ["83910.41", "0.007355"], ["83910.40", "0.005106"], ["83908.40", "0.013436"], ["83906.40", "0.035359"], ["83905.77", "0"], ["83904.40", "0.093048"], ["83902.41", "0.425477"], ["83902.40", "0.244864"], ["83900.40", "0.644378"], ["83899.80", "0"], ["83896.30", "0.221340"], ["83896.00", "0.402720"], ["83895.50", "0.942150"], ["83895.30", "0.257460"], ["83889.90", "0"], ["83858.40", "5.627442"], ["83850.00", "4.265965"], ["83841.60", "5.536677"], ["83833.20", "5.355147"], ["83824.80", "4.447495"], ["83816.40", "3.993669"], ["83808.00", "4.810556"], ["83791.20", "5.173616"], ["83782.80", "3.902904"], ["83774.40", "5.264382"], ["83766.00", "4.538260"], ["83757.60", "4.992086"], ["83749.20", "5.082851"], ["83740.80", "4.084434"], ["83732.40", "4.719791"], ["83724.00", "5.445912"], ["83715.60", "4.356730"], ["83707.20", "4.901321"], ["83698.80", "4.629025"], ["83441.56", "0.000024"], ["83440.00", "0.000460"], ["83439.42", "0.000423"]], "checksum": -214120281, "ts": "1742577165383"}], "ts": 1742577165387, "record_time": 1742577165.579428, "EXCHANGE": "BITGET"}
{"action": "update", "arg": {"instType": "SPOT", "channel": "books", "instId": "BTCUSDT"}, "data": [{"asks": [["83918.36", "0.080642"], ["83918.37", "0.092791"], ["83937.55", "0.035971"], ["83972.40", "0.030515"], ["83974.40", "0.080301"], ["83976.40", "0.211320"], ["83978.40", "0.556104"], ["83980.40", "1.463431"], ["83982.40", "3.851134"], ["83984.40", "10.134563"], ["84034.80", "5.082851"], ["84043.20", "4.719791"], ["84051.60", "5.445912"], ["84060.00", "4.084434"], ["84068.40", "4.629025"], ["84076.80", "4.810556"], ["84085.20", "4.901321"], ["84093.60", "5.355147"], ["84102.00", "4.538260"], ["84110.40", "3.902904"], ["84118.80", "4.265965"], ["84127.20", "4.447495"], ["84135.60", "5.173616"], ["84144.00", "4.356730"], ["84152.40", "4.175199"], ["84160.80", "5.536677"], ["84169.20", "3.993669"], ["84177.60", "5.264382"], ["84186.00", "5.627442"], ["84341.00", "0"]], "bids": [["83918.02", "0.410059"], ["83912.40", "0.002755"], ["83910.40", "0.007251"], ["83908.40", "0.019082"], ["83906.40", "0.050216"], ["83905.77", "0.420833"], ["83904.40", "0.132146"], ["83902.40", "0.347752"], ["83900.40", "0.915269"], ["83898.30", "0.487680"], ["83897.90", "0.986370"], ["83896.30", "0.220920"], ["83896.00", "0.402300"], ["83895.50", "0.007780"], ["83895.30", "0.105900"], ["83892.80", "0.066420"], ["83866.00", "0"], ["83858.40", "4.538260"], ["83850.00", "4.084434"], ["83841.60", "4.719791"], ["83833.20", "5.627442"], ["83824.80", "5.082851"], ["83816.40", "5.355147"], ["83808.00", "4.901321"], ["83799.60", "3.902904"], ["83791.20", "4.629025"], ["83782.80", "5.173616"], ["83774.40", "4.265965"], ["83766.00", "4.175199"], ["83757.60", "3.993669"], ["83749.20", "4.810556"], ["83740.80", "4.992086"], ["83732.40", "5.445912"], ["83724.00", "5.536677"], ["83715.60", "4.447495"], ["83707.20", "4.356730"], ["83698.80", "5.264382"], ["83441.56", "0"], ["83440.00", "0"], ["83439.42", "0"]], "checksum": 650230052, "ts": "1742577165586"}], "ts": 1742577165589, "record_time": 1742577165.782025, "EXCHANGE": "BITGET"}
{"action": "update", "arg": {"instType": "SPOT", "channel": "books", "instId": "BTCUSDT"}, "data": [{"asks": [["83918.03", "1.307417"], ["83918.37", "0"], ["83961.75", "0.010000"], ["84026.40", "3.902904"], ["84034.80", "4.719791"], ["84043.20", "4.084434"], ["84051.60", "4.447495"], ["84060.00", "5.445912"], ["84068.40", "4.901321"], ["84085.20", "5.082851"], ["84102.00", "4.629025"], ["84110.40", "5.264382"], ["84118.80", "5.536677"], ["84127.20", "5.627442"], ["84135.60", "4.175199"], ["84144.00", "4.265965"], ["84152.40", "4.992086"], ["84160.80", "5.173616"], ["84177.60", "4.356730"], ["84186.00", "4.538260"]], "bids": [["83918.02", "0.619259"], ["83912.40", "0.001944"], ["83910.40", "0.005114"], ["83908.40", "0.013459"], ["83906.40", "0.035419"], ["83904.40", "0.093206"], ["83902.40", "0.245281"], ["83900.40", "0.645476"], ["83898.21", "0.751170"], ["83896.84", "0"], ["83889.90", "0.536970"], ["83868.00", "0.000121"], ["83858.40", "5.355147"], ["83850.00", "3.993669"], ["83841.60", "4.992086"], ["83833.20", "4.356730"], ["83824.80", "4.810556"], ["83816.40", "5.173616"], ["83808.00", "4.538260"], ["83799.60", "5.536677"], ["83791.20", "4.719791"], ["83782.80", "4.901321"], ["83774.40", "4.175199"], ["83766.00", "4.629025"], ["83757.60", "5.264382"], ["83749.20", "4.447495"], ["83740.80", "4.084434"], ["83724.00", "4.265965"], ["83715.60", "3.902904"], ["83707.20", "5.627442"], ["83698.80", "5.082851"], ["83442.50", "0"]], "checksum": -1405016331, "ts": "1742577165788"}], "ts": 1742577165790, "record_time": 1742577165.982625, "EXCHANGE": "BITGET"}
{"action": "update", "arg": {"instType": "SPOT", "channel": "books", "instId": "BTCUSDT"}, "data": [{"asks": [["83918.03", "1.342093"], ["83918.36", "0.126986"], ["83988.00", "2.402070"], ["83990.30", "0"], ["84026.40", "3.993669"], ["84034.80", "4.901321"], ["84043.20", "4.356730"], ["84051.60", "5.264382"], ["84060.00", "4.719791"], ["84068.40", "4.629025"], ["84076.80", "4.447495"], ["84085.20", "5.445912"], ["84093.60", "4.084434"], ["84102.00", "5.536677"], ["84110.40", "4.175199"], ["84118.80", "5.173616"], ["84127.20", "4.265965"], ["84135.60", "4.538260"], ["84144.00", "3.902904"], ["84152.40", "5.355147"], ["84160.80", "4.992086"], ["84169.20", "5.082851"], ["84177.60", "5.627442"], ["84186.00", "4.810556"], ["84341.00", "0.002997"]], "bids": [["83918.02", "0.399051"], ["83914.72", "0"], ["83912.40", "0.002135"], ["83910.40", "0.005618"], ["83908.40", "0.014786"], ["83906.40", "0.038909"], ["83905.76", "0.256800"], ["83904.40", "0.102392"], ["83902.40", "0.269453"], ["83900.40", "0.709088"], ["83898.30", "0"], ["83897.90", "0"], ["83896.30", "0.060210"], ["83896.00", "0.162930"], ["83895.30", "0.003690"], ["83894.01", "0.363370"], ["83893.70", "0.240000"], ["83893.20", "0.160920"], ["83889.90", "0"], ["83858.40", "4.084434"], ["83850.00", "3.902904"], ["83841.60", "4.719791"], ["83833.20", "5.264382"], ["83824.80", "4.992086"], ["83816.40", "4.901321"], ["83808.00", "5.355147"], ["83799.60", "4.810556"], ["83791.20", "5.445912"], ["83782.80", "4.447495"], ["83774.40", "4.629025"], ["83766.00", "3.993669"], ["83757.60", "5.536677"], ["83749.20", "4.175199"], ["83740.80", "5.173616"], ["83732.40", "5.627442"], ["83724.00", "4.356730"], ["83715.60", "4.265965"], ["83707.20", "5.082851"], ["83698.80", "4.538260"], ["83442.50", "0.000113"]], "checksum": -1481742500, "ts": "1742577165993"}], "ts": 1742577165996, "record_time": 1742577166.188429, "EXCHANGE": "BITGET"}
{"action": "update", "arg": {"instType": "SPOT", "channel": "books", "instId": "BTCUSDT"}, "data": [{"asks": [["83951.48", "0.012217"], ["83964.40", "0.001252"], ["83966.40", "0.002043"], ["83968.40", "0.005375"], ["83970.40", "0.014147"], ["83972.40", "0.037229"], ["83974.40", "0.097970"], ["83976.40", "0.257816"], ["83978.40", "0.678463"], ["83980.40", "1.785428"], ["83982.40", "4.698495"], ["83984.40", "12.364462"], ["83984.50", "0.124770"], ["83987.00", "0.250800"], ["83987.40", "0.120180"], ["83987.60", "0.942870"], ["83988.00", "2.402430"], ["83989.30", "0.269760"], ["83993.20", "0"], ["83995.60", "0"], ["84026.40", "5.355147"], ["84034.80", "4.447495"], ["84043.20", "4.538260"], ["84051.60", "5.536677"], ["84060.00", "4.629025"], ["84068.40", "4.265965"], ["84076.80", "4.810556"], ["84085.20", "4.356730"], ["84093.60", "4.992086"], ["84102.00", "4.175199"], ["84110.40", "5.627442"], ["84118.80", "3.993669"], ["84127.20", "5.264382"], ["84135.60", "5.445912"], ["84144.00", "4.084434"], ["84152.40", "3.902904"], ["84160.80", "5.082851"], ["84169.20", "4.901321"], ["84177.60", "5.173616"], ["84186.00", "4.719791"], ["84341.00", "0"]], "bids": [["83912.78", "0"], ["83902.40", "0.269651"], ["83900.40", "0.709739"], ["83898.21", "0"], ["83898.20", "0.120390"], ["83897.28", "0.014507"], ["83896.70", "0.071760"], ["83896.30", "0"], ["83896.00", "0.042510"], ["83895.40", "0.101970"], ["83895.20", "0.431610"], ["83894.13", "0"], ["83894.00", "0"], ["83893.80", "0.146790"], ["83893.70", "0.420000"], ["83893.10", "0"], ["83892.50", "0.445290"], ["83891.60", "0.757740"], ["83890.40", "0"], ["83890.10", "0.165000"], ["83890.00", "1.471800"], ["83889.90", "0.536970"], ["83889.60", "0.045000"], ["83885.72", "0.024948"], ["83858.40", "4.356730"], ["83850.00", "5.082851"], ["83841.60", "4.901321"], ["83833.20", "5.445912"], ["83824.80", "4.629025"], ["83816.40", "3.902904"], ["83808.00", "4.447495"], ["83799.60", "4.719791"], ["83791.20", "4.538260"], ["83782.80", "5.173616"], ["83774.40", "4.810556"], ["83766.00", "5.264382"], ["83757.60", "5.627442"], ["83749.20", "5.355147"], ["83740.80", "4.084434"], ["83732.40", "4.175199"], ["83724.00", "5.536677"], ["83707.20", "4.992086"], ["83698.80", "3.993669"], ["83441.56", "0.000024"]], "checksum": 689930823, "ts": "1742577166194"}], "ts": 1742577166196, "record_time": 1742577166.401409, "EXCHANGE": "BITGET"}
