{"action": "update", "arg": {"instType": "SPOT", "channel": "books", "instId": "BTCUSDT"}, "data": [{"asks": [["84043.27", "0.086851"], ["84043.28", "0"], ["84108.80", "0.076980"], ["84109.90", "0.405570"], ["84117.50", "0"], ["84157.50", "5.437978"], ["84166.00", "5.256712"], ["84174.50", "3.897218"], ["84183.00", "5.347345"], ["84191.50", "4.894180"], ["84200.00", "3.987851"], ["84208.50", "5.075446"], ["84217.00", "4.441016"], ["84225.50", "5.528611"], ["84234.00", "4.169117"], ["84242.50", "4.712914"], ["84251.00", "4.531649"], ["84259.50", "5.166079"], ["84268.00", "4.803547"], ["84276.50", "4.078484"], ["84285.00", "5.619244"], ["84293.50", "4.350383"], ["84302.00", "4.984813"], ["84310.50", "4.622282"], ["84525.00", "0.003689"]], "bids": [["84043.00", "0.276889"], ["84028.81", "0.370484"], ["84018.50", "0"], ["83992.00", "0.000017"], ["83980.80", "5.619244"], ["83972.30", "4.712914"], ["83963.80", "4.259750"], ["83955.30", "5.347345"], ["83946.80", "4.169117"], ["83938.30", "4.441016"], ["83929.80", "5.528611"], ["83921.30", "5.437978"], ["83912.80", "4.531649"], ["83904.30", "4.622282"], ["83895.80", "4.984813"], ["83887.30", "4.803547"], ["83878.80", "3.897218"], ["83870.30", "4.078484"], ["83861.80", "4.350383"], ["83853.30", "5.166079"], ["83844.80", "5.075446"], ["83836.30", "4.894180"], ["83827.80", "3.987851"], ["83819.30", "5.256712"]], "checksum": -9519364, "ts": "1742555198843"}], "ts": 1742555198848, "record_time": 1742555198.96775, "EXCHANGE": "BITGET"}
{"action": "update", "arg": {"instType": "SPOT", "channel": "books", "instId": "BTCUSDT"}, "data": [{"asks": [["84063.56", "0"], ["84063.69", "0.119870"], ["84067.11", "0"], ["84067.19", "0.006356"], ["84067.28", "0"], ["84067.36", "0.006356"], ["84067.78", "0"], ["84067.86", "0.016429"], ["84068.80", "0"], ["84068.87", "0.006356"], ["84072.16", "0"], ["84072.25", "0.119850"], ["84093.00", "0.009918"], ["84095.00", "0.026100"], ["84097.00", "0.068684"], ["84099.00", "0.180747"], ["84101.00", "0.475650"], ["84103.00", "1.251711"], ["84105.00", "3.293978"], ["84107.00", "8.668363"], ["84108.50", "0.074790"], ["84108.80", "0.077190"], ["84109.80", "0.526830"], ["84117.00", "0"], ["84157.50", "5.528611"], ["84166.00", "4.350383"], ["84174.50", "4.803547"], ["84183.00", "4.984813"], ["84191.50", "5.347345"], ["84200.00", "5.437978"], ["84208.50", "4.169117"], ["84225.50", "4.712914"], ["84234.00", "4.531649"], ["84242.50", "5.075446"], ["84251.00", "4.622282"], ["84259.50", "5.256712"], ["84268.00", "5.166079"], ["84276.50", "3.897218"], ["84293.50", "4.078484"], ["84302.00", "4.894180"], ["84310.50", "3.987851"], ["84525.82", "0.000099"]], "bids": [["84042.79", "0.027859"], ["84041.97", "0"], ["84022.51", "0.247647"], ["84022.38", "0"], ["84018.94", "0.017107"], ["84018.87", "0"], ["84018.78", "0.007133"], ["84018.71", "0"], ["84018.27", "0.028872"], ["84018.20", "0"], ["84014.10", "0.268442"], ["84014.00", "0.000032"], ["83980.80", "4.441016"], ["83972.30", "4.894180"], ["83963.80", "4.712914"], ["83955.30", "4.803547"], ["83946.80", "4.350383"], ["83938.30", "3.897218"], ["83929.80", "5.437978"], ["83921.30", "4.259750"], ["83912.80", "5.256712"], ["83904.30", "4.984813"], ["83895.80", "4.531649"], ["83887.30", "4.169117"], ["83878.80", "3.987851"], ["83870.30", "5.347345"], ["83861.80", "4.078484"], ["83853.30", "5.528611"], ["83844.80", "5.619244"], ["83836.30", "5.166079"], ["83827.80", "5.075446"], ["83819.30", "4.622282"], ["83660.14", "0"]], "checksum": 502313121, "ts": "1742555199043"}], "ts": 1742555199046, "record_time": 1742555199.152215, "EXCHANGE": "BITGET"}
{"action": "update", "arg": {"instType": "SPOT", "channel": "books", "instId": "BTCUSDT"}, "data": [{"asks": [["84093.00", "0.009724"], ["84095.00", "0.025590"], ["84097.00", "0.067343"], ["84099.00", "0.177218"], ["84101.00", "0.466363"], ["84103.00", "1.227270"], ["84105.00", "3.229659"], ["84107.00", "8.499103"], ["84108.80", "0.022620"], ["84149.00", "4.078484"], ["84157.50", "4.622282"], ["84166.00", "5.619244"], ["84174.50", "4.350383"], ["84183.00", "4.712914"], ["84191.50", "3.897218"], ["84200.00", "3.987851"], ["84208.50", "5.528611"], ["84217.00", "4.531649"], ["84225.50", "5.166079"], ["84234.00", "4.984813"], ["84242.50", "5.437978"], ["84251.00", "5.347345"], ["84259.50", "4.259750"], ["84268.00", "4.894180"], ["84276.50", "4.169117"], ["84285.00", "4.441016"], ["84293.50", "5.075446"], ["84302.00", "5.256712"], ["84310.50", "4.803547"]], "bids": [["84042.79", "0"], ["84038.80", "0.002372"], ["84036.80", "0.006240"], ["84034.80", "0.016421"], ["84032.80", "0.043214"], ["84030.80", "0.113722"], ["84028.80", "0.299268"], ["84026.80", "0.787548"], ["84024.80", "2.072493"], ["84022.80", "5.453929"], ["83993.00", "0.000032"], ["83980.80", "5.256712"], ["83972.30", "4.622282"], ["83963.80", "4.531649"], ["83955.30", "5.166079"], ["83946.80", "3.987851"], ["83938.30", "4.078484"], ["83929.80", "5.075446"], ["83921.30", "4.984813"], ["83912.80", "4.712914"], ["83904.30", "4.259750"], ["83895.80", "3.897218"], ["83887.30", "4.441016"], ["83878.80", "4.803547"], ["83870.30", "4.350383"], ["83861.80", "4.169117"], ["83853.30", "5.437978"], ["83836.30", "4.894180"], ["83827.80", "5.347345"], ["83819.30", "5.528611"], ["83660.14", "0.000016"]], "checksum": -1387228637, "ts": "1742555199244"}], "ts": 1742555199246, "record_time": 1742555199.271663, "EXCHANGE": "BITGET"}
{"action": "update", "arg": {"instType": "SPOT", "channel": "books", "instId": "BTCUSDT"}, "data": [{"asks": [["84043.26", "0.086854"], ["84043.27", "0"], ["84107.00", "8.499233"], ["84109.80", "0.527040"], ["84117.00", "0.904980"], ["84149.00", "4.622282"], ["84157.50", "5.256712"], ["84166.00", "4.803547"], ["84174.50", "4.441016"], ["84191.50", "4.259750"], ["84200.00", "5.075446"], ["84208.50", "5.166079"], ["84217.00", "3.987851"], ["84225.50", "4.984813"], ["84234.00", "4.531649"], ["84242.50", "3.897218"], ["84251.00", "4.894180"], ["84259.50", "5.528611"], ["84268.00", "4.169117"], ["84276.50", "4.350383"], ["84285.00", "5.437978"], ["84293.50", "4.078484"], ["84302.00", "5.619244"], ["84310.50", "5.347345"], ["84525.82", "0"]], "bids": [["84042.13", "0.027859"], ["83980.80", "3.897218"], ["83972.30", "4.894180"], ["83963.80", "4.622282"], ["83955.30", "4.078484"], ["83946.80", "5.166079"], ["83938.30", "3.987851"], ["83929.80", "5.619244"], ["83921.30", "4.803547"], ["83912.80", "5.075446"], ["83904.30", "4.350383"], ["83895.80", "4.169117"], ["83887.30", "5.256712"], ["83878.80", "4.441016"], ["83870.30", "4.712914"], ["83861.80", "5.347345"], ["83844.80", "4.259750"], ["83836.30", "4.531649"], ["83827.80", "5.528611"], ["83819.30", "4.984813"], ["83660.14", "0"]], "checksum": -576902172, "ts": "1742555199452"}], "ts": 1742555199455, "record_time": 1742555199.501976, "EXCHANGE": "BITGET"}
{"action": "update", "arg": {"instType": "SPOT", "channel": "books", "instId": "BTCUSDT"}, "data": [{"asks": [["84052.24", "0.314124"], ["84060.13", "0"], ["84077.21", "0"], ["84089.00", "0.001542"], ["84091.00", "0.004058"], ["84093.00", "0.010678"], ["84095.00", "0.028100"], ["84097.00", "0.073947"], ["84099.00", "0.194599"], ["84101.00", "0.512103"], ["84103.00", "1.347639"], ["84105.00", "3.546419"], ["84107.00", "9.332680"], ["84149.00", "4.169117"], ["84157.50", "4.984813"], ["84166.00", "4.894180"], ["84174.50", "4.259750"], ["84183.00", "5.256712"], ["84191.50", "3.897218"], ["84200.00", "5.619244"], ["84208.50", "5.437978"], ["84217.00", "5.347345"], ["84225.50", "3.987851"], ["84234.00", "5.166079"], ["84242.50", "4.350383"], ["84251.00", "5.075446"], ["84259.50", "4.712914"], ["84268.00", "4.803547"], ["84276.50", "4.531649"], ["84285.00", "5.528611"], ["84293.50", "4.441016"], ["84302.00", "4.078484"], ["84310.50", "4.622282"], ["84525.82", "0.000099"]], "bids": [["84042.13", "0"], ["84036.80", "0.006429"], ["84034.80", "0.016918"], ["84032.80", "0.044521"], ["84030.80", "0.117161"], ["84028.80", "0.308318"], ["84026.80", "0.811363"], ["84024.80", "2.135165"], ["84022.80", "5.618855"], ["84020.90", "0"], ["83993.00", "0.000015"], ["83980.80", "5.528611"], ["83972.30", "4.350383"], ["83963.80", "4.984813"], ["83955.30", "4.622282"], ["83946.80", "4.441016"], ["83929.80", "4.531649"], ["83921.30", "5.347345"], ["83912.80", "4.078484"], ["83904.30", "4.259750"], ["83878.80", "5.075446"], ["83870.30", "5.619244"], ["83861.80", "4.803547"], ["83853.30", "5.166079"], ["83844.80", "3.897218"], ["83836.30", "4.712914"], ["83827.80", "4.894180"], ["83819.30", "5.437978"], ["83660.14", "0.000016"], ["83660.00", "0.001273"]], "checksum": -954016184, "ts": "1742555199655"}], "ts": 1742555199658, "record_time": 1742555199.68386, "EXCHANGE": "BITGET"}
{"action": "update", "arg": {"instType": "SPOT", "channel": "books", "instId": "BTCUSDT"}, "data": [{"asks": [["84043.26", "0"], ["84051.00", "0.152764"], ["84059.00", "0.067068"], ["84077.20", "0"], ["84101.00", "0.512307"], ["84103.00", "1.348176"], ["84105.00", "3.547832"], ["84107.00", "9.336400"], ["84109.40", "0.070830"], ["84109.80", "0.526830"], ["84117.00", "0"], ["84149.00", "4.350383"], ["84157.50", "4.441016"], ["84166.00", "5.256712"], ["84174.50", "4.622282"], ["84183.00", "5.075446"], ["84191.50", "4.259750"], ["84200.00", "3.897218"], ["84208.50", "4.712914"], ["84225.50", "5.166079"], ["84234.00", "4.531649"], ["84242.50", "5.437978"], ["84251.00", "5.619244"], ["84259.50", "5.528611"], ["84268.00", "4.984813"], ["84276.50", "3.987851"], ["84285.00", "4.894180"], ["84293.50", "4.078484"], ["84302.00", "4.169117"], ["84310.50", "4.803547"], ["84527.47", "0.000608"], ["84528.57", "0.000008"]], "bids": [["84036.80", "0.006284"], ["84034.80", "0.016535"], ["84032.80", "0.043515"], ["84030.80", "0.114512"], ["84028.80", "0.301347"], ["84026.80", "0.793018"], ["84024.80", "2.086891"], ["84022.80", "5.491817"], ["84020.90", "0.074430"], ["83980.80", "4.984813"], ["83972.30", "5.075446"], ["83963.80", "4.259750"], ["83955.30", "5.528611"], ["83946.80", "3.987851"], ["83938.30", "5.256712"], ["83929.80", "4.441016"], ["83921.30", "4.622282"], ["83912.80", "3.897218"], ["83904.30", "4.531649"], ["83887.30", "4.894180"], ["83878.80", "5.437978"], ["83870.30", "5.347345"], ["83861.80", "5.619244"], ["83853.30", "4.803547"], ["83844.80", "4.712914"], ["83836.30", "5.166079"], ["83827.80", "4.350383"], ["83819.30", "4.078484"], ["83660.00", "0"]], "checksum": 26272822, "ts": "1742555199873"}], "ts": 1742555199876, "record_time": 1742555199.898738, "EXCHANGE": "BITGET"}
{"action": "update", "arg": {"instType": "SPOT", "channel": "books", "instId": "BTCUSDT"}, "data": [{"asks": [["84043.01", "2.231002"], ["84043.02", "0.020701"], ["84043.25", "0.086854"], ["84077.23", "0.180956"], ["84079.67", "0.062760"], ["84089.00", "0.001690"], ["84091.00", "0.004446"], ["84093.00", "0.011700"], ["84095.00", "0.030789"], ["84097.00", "0.081024"], ["84099.00", "0.213221"], ["84101.00", "0.561108"], ["84103.00", "1.476599"], ["84105.00", "3.885789"], ["84107.00", "10.225759"], ["84149.00", "4.622282"], ["84157.50", "4.350383"], ["84166.00", "3.987851"], ["84174.50", "4.441016"], ["84183.00", "4.712914"], ["84191.50", "5.256712"], ["84200.00", "4.078484"], ["84208.50", "4.531649"], ["84217.00", "3.897218"], ["84225.50", "5.437978"], ["84234.00", "4.803547"], ["84242.50", "4.894180"], ["84259.50", "4.984813"], ["84268.00", "5.166079"], ["84276.50", "5.347345"], ["84285.00", "4.169117"], ["84293.50", "5.075446"], ["84302.00", "4.259750"], ["84310.50", "5.528611"], ["84525.82", "0"], ["84527.47", "0"], ["84528.57", "0"]], "bids": [["84043.00", "0.067689"], ["84034.80", "0.016421"], ["84032.80", "0.043214"], ["84030.80", "0.113722"], ["84028.80", "0.299268"], ["84026.80", "0.787548"], ["84024.80", "2.072493"], ["84022.80", "5.453929"], ["84020.90", "0"], ["84019.90", "0.071760"], ["83991.00", "0"], ["83972.30", "4.259750"], ["83963.80", "3.987851"], ["83955.30", "4.078484"], ["83946.80", "4.622282"], ["83938.30", "5.075446"], ["83929.80", "5.437978"], ["83921.30", "4.803547"], ["83912.80", "5.619244"], ["83904.30", "4.894180"], ["83895.80", "3.897218"], ["83887.30", "4.531649"], ["83878.80", "5.528611"], ["83870.30", "4.350383"], ["83861.80", "4.712914"], ["83853.30", "4.441016"], ["83844.80", "5.166079"], ["83836.30", "4.169117"], ["83827.80", "5.256712"], ["83819.30", "5.347345"], ["83660.00", "0.001273"], ["83659.61", "0.000454"]], "checksum": 2058784671, "ts": "1742555200074"}], "ts": 1742555200080, "record_time": 1742555200.103759, "EXCHANGE": "BITGET"}
{"action": "update", "arg": {"instType": "SPOT", "channel": "books", "instId": "BTCUSDT"}, "data": [{"asks": [["84043.02", "0.046241"], ["84091.00", "0.004572"], ["84093.00", "0.012031"], ["84095.00", "0.031661"], ["84097.00", "0.083319"], ["84099.00", "0.219260"], ["84101.00", "0.577000"], ["84103.00", "1.518421"], ["84105.00", "3.995844"], ["84107.00", "10.515380"], ["84114.80", "1.339650"], ["84116.90", "0"], ["84149.00", "4.078484"], ["84157.50", "4.441016"], ["84166.00", "4.984813"], ["84174.50", "5.075446"], ["84183.00", "5.619244"], ["84191.50", "4.259750"], ["84200.00", "5.347345"], ["84208.50", "5.528611"], ["84225.50", "4.712914"], ["84234.00", "4.169117"], ["84242.50", "3.987851"], ["84251.00", "4.531649"], ["84259.50", "5.437978"], ["84268.00", "4.622282"], ["84276.50", "5.256712"], ["84285.00", "4.350383"], ["84293.50", "4.803547"], ["84302.00", "5.166079"], ["84310.50", "4.894180"], ["84525.82", "0.000099"]], "bids": [["84043.00", "0.048789"], ["84038.80", "0.001868"], ["84036.80", "0.004917"], ["84034.80", "0.012939"], ["84032.80", "0.034050"], ["84031.41", "0"], ["84030.80", "0.089606"], ["84028.80", "0.235804"], ["84026.80", "0.620536"], ["84024.80", "1.632991"], ["84022.80", "4.297344"], ["84022.70", "0.015210"], ["84022.50", "0"], ["83991.00", "0.000017"], ["83980.80", "4.169117"], ["83972.30", "5.619244"], ["83963.80", "3.897218"], ["83955.30", "4.622282"], ["83946.80", "5.075446"], ["83938.30", "5.437978"], ["83929.80", "5.166079"], ["83921.30", "5.347345"], ["83912.80", "4.803547"], ["83904.30", "4.350383"], ["83895.80", "4.712914"], ["83887.30", "5.528611"], ["83878.80", "4.531649"], ["83870.30", "5.256712"], ["83861.80", "4.984813"], ["83853.30", "4.259750"], ["83844.80", "4.441016"], ["83836.30", "3.987851"], ["83827.80", "4.078484"], ["83819.30", "4.894180"]], "checksum": -549227790, "ts": "1742555200281"}], "ts": 1742555200287, "record_time": 1742555200.321818, "EXCHANGE": "BITGET"}
{"action": "update", "arg": {"instType": "SPOT", "channel": "books", "instId": "BTCUSDT"}, "data": [{"asks": [["84043.25", "0"], ["84097.88", "0"], ["84098.01", "0.001598"], ["84099.71", "0"], ["84099.83", "0.001597"], ["84107.00", "10.515250"], ["84107.80", "0.001050"], ["84149.00", "4.984813"], ["84157.50", "5.347345"], ["84166.00", "5.619244"], ["84174.50", "5.256712"], ["84183.00", "4.259750"], ["84191.50", "4.803547"], ["84200.00", "4.169117"], ["84208.50", "5.437978"], ["84217.00", "3.987851"], ["84225.50", "4.441016"], ["84234.00", "4.350383"], ["84242.50", "5.528611"], ["84259.50", "4.712914"], ["84276.50", "4.078484"], ["84285.00", "5.166079"], ["84293.50", "5.075446"], ["84302.00", "4.894180"], ["84310.50", "3.897218"]], "bids": [["84039.99", "0.027859"], ["84034.80", "0.013185"], ["84032.80", "0.034698"], ["84030.80", "0.091310"], ["84028.80", "0.240114"], ["84026.80", "0.631879"], ["84024.80", "1.662839"], ["84022.80", "4.375892"], ["84022.70", "0.001009"], ["84019.89", "0.301859"], ["83987.75", "0.001176"], ["83987.61", "0"], ["83985.70", "0.001173"], ["83985.58", "0"], ["83980.80", "5.619244"], ["83972.30", "4.350383"], ["83963.80", "4.622282"], ["83955.30", "4.984813"], ["83946.80", "4.259750"], ["83938.30", "4.894180"], ["83929.80", "4.803547"], ["83921.30", "4.169117"], ["83912.80", "3.897218"], ["83904.30", "5.437978"], ["83895.80", "5.347345"], ["83887.30", "4.078484"], ["83861.80", "5.528611"], ["83853.30", "4.712914"], ["83827.80", "5.075446"], ["83819.30", "5.166079"], ["83659.61", "0"]], "checksum": -933463444, "ts": "1742555200491"}], "ts": 1742555200495, "record_time": 1742555200.542642, "EXCHANGE": "BITGET"}
{"action": "update", "arg": {"instType": "SPOT", "channel": "books", "instId": "BTCUSDT"}, "data": [{"asks": [["84043.02", "0.020701"], ["84043.24", "0.086854"], ["84101.00", "0.576986"], ["84102.99", "0.034849"], ["84103.00", "1.518383"], ["84105.00", "3.995746"], ["84107.00", "10.515119"], ["84115.10", "0.006870"], ["84116.90", "0.228000"], ["84157.50", "5.166079"], ["84166.00", "5.075446"], ["84174.50", "4.622282"], ["84183.00", "4.441016"], ["84191.50", "4.712914"], ["84200.00", "4.894180"], ["84208.50", "3.897218"], ["84217.00", "5.619244"], ["84225.50", "4.169117"], ["84234.00", "5.347345"], ["84242.50", "4.259750"], ["84259.50", "5.437978"], ["84268.00", "4.350383"], ["84276.50", "3.987851"], ["84285.00", "4.803547"], ["84293.50", "4.078484"], ["84302.00", "5.256712"], ["84310.50", "5.528611"], ["84525.00", "0"], ["84525.82", "0"]], "bids": [["84043.00", "0.257989"], ["84026.80", "0.632053"], ["84024.80", "1.663298"], ["84022.80", "4.377101"], ["84022.30", "0.705990"], ["84021.90", "0.307260"], ["84019.90", "0.071550"], ["84018.50", "0.015000"], ["83992.00", "0.000032"], ["83980.80", "4.078484"], ["83972.30", "5.437978"], ["83963.80", "3.897218"], ["83955.30", "4.259750"], ["83946.80", "4.622282"], ["83938.30", "3.987851"], ["83921.30", "5.075446"], ["83912.80", "4.712914"], ["83904.30", "5.528611"], ["83895.80", "4.531649"], ["83887.30", "5.166079"], ["83878.80", "4.894180"], ["83870.30", "4.984813"], ["83861.80", "5.619244"], ["83853.30", "4.169117"], ["83836.30", "4.350383"], ["83827.80", "5.347345"], ["83819.30", "5.256712"], ["83660.14", "0"], ["83660.00", "0"]], "checksum": -1162926613, "ts": "1742555200711"}], "ts": 1742555200715, "record_time": 1742555200.744178, "EXCHANGE": "BITGET"}
{"action": "update", "arg": {"instType": "SPOT", "channel": "books", "instId": "BTCUSDT"}, "data": [{"asks": [["84043.02", "0.046241"], ["84149.00", "5.166079"], ["84157.50", "4.169117"], ["84166.00", "4.350383"], ["84174.50", "3.897218"], ["84183.00", "4.078484"], ["84191.50", "4.441016"], ["84200.00", "4.712914"], ["84208.50", "5.619244"], ["84217.00", "4.894180"], ["84225.50", "4.531649"], ["84234.00", "4.259750"], ["84242.50", "4.984813"], ["84251.00", "4.622282"], ["84259.50", "5.528611"], ["84268.00", "5.347345"], ["84285.00", "5.437978"], ["84293.50", "5.256712"], ["84302.00", "4.803547"], ["84310.50", "5.075446"]], "bids": [["84039.99", "0"], ["84030.80", "0.091438"], ["84028.80", "0.240625"], ["84026.80", "0.633225"], ["84024.80", "1.666380"], ["84022.80", "4.385210"], ["83980.80", "4.712914"], ["83972.30", "5.256712"], ["83963.80", "3.987851"], ["83955.30", "4.894180"], ["83938.30", "5.528611"], ["83929.80", "5.347345"], ["83921.30", "4.169117"], ["83912.80", "3.897218"], ["83904.30", "4.259750"], ["83895.80", "5.619244"], ["83887.30", "5.437978"], ["83878.80", "4.078484"], ["83861.80", "4.531649"], ["83853.30", "5.166079"], ["83827.80", "4.803547"], ["83819.30", "5.075446"], ["83660.14", "0.000016"]], "checksum": -185248471, "ts": "1742555200929"}], "ts": 1742555200933, "record_time": 1742555200.960774, "EXCHANGE": "BITGET"}
{"action": "update", "arg": {"instType": "SPOT", "channel": "books", "instId": "BTCUSDT"}, "data": [{"asks": [["84043.24", "0"], ["84077.22", "0.125111"], ["84079.67", "0"], ["84086.21", "0"], ["84149.00", "3.897218"], ["84157.50", "4.803547"], ["84166.00", "4.894180"], ["84174.50", "4.712914"], ["84191.50", "5.256712"], ["84200.00", "4.259750"], ["84208.50", "4.441016"], ["84217.00", "4.984813"], ["84225.50", "4.350383"], ["84234.00", "4.622282"], ["84242.50", "5.347345"], ["84251.00", "3.987851"], ["84259.50", "5.075446"], ["84268.00", "5.166079"], ["84276.50", "5.437978"], ["84285.00", "5.528611"], ["84293.50", "4.531649"], ["84302.00", "5.619244"], ["84310.50", "4.169117"], ["84525.00", "0.003689"], ["84525.82", "0.000099"]], "bids": [["84040.63", "0.027859"], ["84020.90", "0.073710"], ["83992.00", "0.000015"], ["83972.30", "5.437978"], ["83963.80", "4.894180"], ["83955.30", "4.531649"], ["83946.80", "4.259750"], ["83938.30", "4.984813"], ["83929.80", "4.078484"], ["83921.30", "5.528611"], ["83912.80", "4.803547"], ["83904.30", "3.897218"], ["83895.80", "4.350383"], ["83887.30", "5.619244"], ["83878.80", "4.441016"], ["83870.30", "4.622282"], ["83861.80", "5.166079"], ["83853.30", "3.987851"], ["83844.80", "5.256712"], ["83836.30", "4.169117"], ["83827.80", "5.347345"], ["83660.71", "0"], ["83660.14", "0"]], "checksum": -2031389546, "ts": "1742555201138"}], "ts": 1742555201155, "record_time": 1742555201.25075, "EXCHANGE": "BITGET"}
{"action": "update", "arg": {"instType": "SPOT", "channel": "books", "instId": "BTCUSDT"}, "data": [{"asks": [["84043.02", "0.020701"], ["84043.23", "0.086854"], ["84105.00", "3.995646"], ["84107.00", "10.514859"], ["84107.20", "0.046170"], ["84108.50", "0.074370"], ["84109.40", "0.070620"], ["84110.10", "0.067800"], ["84116.90", "0"], ["84149.00", "3.987851"], ["84157.50", "4.984813"], ["84166.00", "5.437978"], ["84174.50", "5.075446"], ["84183.00", "4.441016"], ["84191.50", "5.347345"], ["84200.00", "4.622282"], ["84208.50", "4.078484"], ["84217.00", "5.166079"], ["84225.50", "5.619244"], ["84234.00", "5.256712"], ["84242.50", "4.712914"], ["84251.00", "5.528611"], ["84259.50", "4.803547"], ["84268.00", "4.259750"], ["84276.50", "4.894180"], ["84285.00", "4.169117"], ["84302.00", "4.350383"], ["84310.50", "3.897218"], ["84525.82", "0"]], "bids": [["84034.80", "0.012967"], ["84032.80", "0.034123"], ["84030.80", "0.089858"], ["84028.80", "0.236468"], ["84026.80", "0.622285"], ["84024.80", "1.637592"], ["84022.80", "4.309453"], ["84020.90", "0"], ["84019.40", "0.012472"], ["84017.40", "0"], ["84011.50", "0.120000"], ["84011.00", "0.015150"], ["83980.80", "4.984813"], ["83972.30", "5.619244"], ["83963.80", "5.075446"], ["83955.30", "4.712914"], ["83946.80", "5.528611"], ["83938.30", "4.259750"], ["83929.80", "5.256712"], ["83921.30", "4.350383"], ["83912.80", "5.166079"], ["83904.30", "4.441016"], ["83895.80", "3.987851"], ["83887.30", "4.169117"], ["83878.80", "4.622282"], ["83870.30", "4.078484"], ["83861.80", "4.803547"], ["83853.30", "5.347345"], ["83844.80", "3.897218"], ["83836.30", "5.437978"], ["83827.80", "4.894180"], ["83819.30", "4.531649"], ["83660.71", "0.000309"]], "checksum": 1770231097, "ts": "1742555201340"}], "ts": 1742555201343, "record_time": 1742555201.366811, "EXCHANGE": "BITGET"}
{"action": "update", "arg": {"instType": "SPOT", "channel": "books", "instId": "BTCUSDT"}, "data": [{"asks": [["84043.02", "0.046241"], ["84116.60", "0"], ["84149.00", "4.894180"], ["84157.50", "5.075446"], ["84166.00", "5.347345"], ["84174.50", "4.712914"], ["84183.00", "5.619244"], ["84191.50", "4.441016"], ["84200.00", "4.350383"], ["84208.50", "5.166079"], ["84217.00", "4.622282"], ["84225.50", "4.984813"], ["84234.00", "4.259750"], ["84242.50", "4.169117"], ["84251.00", "4.078484"], ["84259.50", "3.987851"], ["84268.00", "5.528611"], ["84276.50", "4.803547"], ["84285.00", "5.256712"], ["84293.50", "3.897218"], ["84302.00", "4.531649"], ["84310.50", "5.437978"], ["84525.82", "0.000099"]], "bids": [["84041.57", "0"], ["84022.80", "4.309583"], ["84017.60", "0.045540"], ["84011.50", "0"], ["84011.00", "0.000032"], ["83993.00", "0.000017"], ["83980.80", "5.256712"], ["83972.30", "4.984813"], ["83963.80", "4.712914"], ["83955.30", "3.897218"], ["83946.80", "4.531649"], ["83938.30", "4.894180"], ["83929.80", "5.528611"], ["83921.30", "4.078484"], ["83912.80", "4.441016"], ["83904.30", "4.259750"], ["83895.80", "4.803547"], ["83878.80", "5.075446"], ["83870.30", "4.622282"], ["83861.80", "4.350383"], ["83853.30", "3.987851"], ["83844.80", "5.347345"], ["83827.80", "5.619244"], ["83819.30", "5.166079"], ["83660.14", "0.000016"]], "checksum": -1324960595, "ts": "1742555201543"}], "ts": 1742555201546, "record_time": 1742555201.586707, "EXCHANGE": "BITGET"}
{"action": "update", "arg": {"instType": "SPOT", "channel": "books", "instId": "BTCUSDT"}, "data": [{"asks": [["84043.23", "0"], ["84149.00", "4.441016"], ["84157.50", "5.256712"], ["84166.00", "4.622282"], ["84174.50", "4.984813"], ["84183.00", "5.437978"], ["84191.50", "4.531649"], ["84200.00", "5.075446"], ["84208.50", "4.350383"], ["84217.00", "5.619244"], ["84225.50", "4.078484"], ["84234.00", "3.897218"], ["84242.50", "4.803547"], ["84251.00", "3.987851"], ["84259.50", "4.712914"], ["84276.50", "5.166079"], ["84285.00", "4.894180"], ["84293.50", "4.259750"], ["84302.00", "5.347345"], ["84310.50", "4.169117"], ["84527.47", "0.000608"]], "bids": [["84034.80", "0.013120"], ["84032.80", "0.034527"], ["84030.80", "0.090860"], ["84028.80", "0.239107"], ["84026.80", "0.629227"], ["84024.80", "1.655863"], ["84022.80", "4.357534"], ["84022.60", "0.002760"], ["84022.40", "0.001047"], ["84022.30", "0.692190"], ["84017.00", "0.071160"], ["83980.80", "4.078484"], ["83972.30", "5.075446"], ["83963.80", "4.803547"], ["83955.30", "4.984813"], ["83946.80", "4.169117"], ["83938.30", "4.350383"], ["83929.80", "5.437978"], ["83921.30", "4.531649"], ["83912.80", "3.987851"], ["83904.30", "4.712914"], ["83895.80", "5.528611"], ["83887.30", "4.259750"], ["83878.80", "4.622282"], ["83870.30", "4.894180"], ["83861.80", "5.256712"], ["83853.30", "3.897218"], ["83844.80", "4.441016"], ["83836.30", "5.166079"], ["83819.30", "5.347345"], ["83660.14", "0"]], "checksum": 1696665444, "ts": "1742555201746"}], "ts": 1742555201749, "record_time": 1742555201.776051, "EXCHANGE": "BITGET"}
{"action": "update", "arg": {"instType": "SPOT", "channel": "books", "instId": "BTCUSDT"}, "data": [{"asks": [["84043.02", "0.020701"], ["84043.22", "0.086854"], ["84114.80", "1.069890"], ["84116.60", "0.356940"], ["84149.00", "5.075446"], ["84157.50", "4.984813"], ["84166.00", "4.712914"], ["84174.50", "5.528611"], ["84183.00", "5.619244"], ["84191.50", "4.078484"], ["84200.00", "4.622282"], ["84208.50", "4.803547"], ["84217.00", "4.350383"], ["84225.50", "4.531649"], ["84234.00", "4.169117"], ["84242.50", "4.259750"], ["84251.00", "5.256712"], ["84259.50", "5.166079"], ["84268.00", "5.347345"], ["84276.50", "4.894180"], ["84285.00", "4.441016"], ["84293.50", "3.897218"], ["84302.00", "3.987851"], ["84310.50", "5.437978"], ["84525.82", "0"], ["84527.47", "0"]], "bids": [["84040.63", "0"], ["84038.80", "0.002300"], ["84036.80", "0.006052"], ["84034.80", "0.015926"], ["84032.80", "0.041911"], ["84031.41", "0.098242"], ["84030.80", "0.110291"], ["84028.80", "0.290241"], ["84026.80", "0.763791"], ["84024.80", "2.009977"], ["84022.80", "5.289412"], ["84020.50", "0.073170"], ["83980.80", "5.619244"], ["83972.30", "4.078484"], ["83963.80", "4.169117"], ["83955.30", "4.441016"], ["83946.80", "5.256712"], ["83938.30", "5.437978"], ["83929.80", "4.894180"], ["83921.30", "4.803547"], ["83912.80", "4.350383"], ["83904.30", "5.528611"], ["83895.80", "4.984813"], ["83887.30", "4.712914"], ["83878.80", "4.531649"], ["83870.30", "3.897218"], ["83861.80", "4.259750"], ["83853.30", "5.166079"], ["83844.80", "4.622282"], ["83836.30", "5.075446"], ["83827.80", "3.987851"], ["83660.71", "0"]], "checksum": 1538359630, "ts": "1742555201953"}], "ts": 1742555201956, "record_time": 1742555201.982067, "EXCHANGE": "BITGET"}
{"action": "update", "arg": {"instType": "SPOT", "channel": "books", "instId": "BTCUSDT"}, "data": [{"asks": [["84043.02", "0.046241"], ["84149.00", "5.347345"], ["84157.50", "4.803547"], ["84166.00", "4.350383"], ["84174.50", "5.166079"], ["84183.00", "4.712914"], ["84191.50", "4.531649"], ["84200.00", "3.987851"], ["84208.50", "5.437978"], ["84217.00", "3.897218"], ["84225.50", "4.078484"], ["84234.00", "5.619244"], ["84242.50", "4.984813"], ["84251.00", "4.622282"], ["84259.50", "4.894180"], ["84268.00", "5.256712"], ["84276.50", "4.169117"], ["84285.00", "5.075446"], ["84293.50", "4.441016"], ["84302.00", "4.259750"], ["84310.50", "5.528611"]], "bids": [["84041.63", "0.027859"], ["84031.41", "0"], ["84022.80", "5.289170"], ["83991.00", "0.000032"], ["83980.80", "4.984813"], ["83972.30", "3.897218"], ["83955.30", "4.350383"], ["83946.80", "4.622282"], ["83929.80", "3.987851"], ["83921.30", "4.441016"], ["83912.80", "5.256712"], ["83904.30", "4.803547"], ["83895.80", "4.712914"], ["83887.30", "4.531649"], ["83878.80", "5.528611"], ["83870.30", "5.619244"], ["83861.80", "4.894180"], ["83844.80", "4.259750"], ["83836.30", "5.347345"], ["83827.80", "5.075446"], ["83819.30", "4.078484"]], "checksum": 1840918982, "ts": "1742555202190"}], "ts": 1742555202193, "record_time": 1742555202.215877, "EXCHANGE": "BITGET"}
{"action": "update", "arg": {"instType": "SPOT", "channel": "books", "instId": "BTCUSDT"}, "data": [{"asks": [["84097.00", "0.083578"], ["84099.00", "0.219943"], ["84101.00", "0.578797"], ["84103.00", "1.523151"], ["84105.00", "4.008291"], ["84107.00", "10.548134"], ["84149.00", "4.259750"], ["84157.50", "4.531649"], ["84166.00", "4.803547"], ["84174.50", "5.347345"], ["84183.00", "4.350383"], ["84191.50", "4.894180"], ["84208.50", "5.256712"], ["84217.00", "5.528611"], ["84225.50", "4.169117"], ["84234.00", "5.437978"], ["84242.50", "5.075446"], ["84251.00", "4.441016"], ["84259.50", "3.897218"], ["84268.00", "4.622282"], ["84276.50", "4.712914"], ["84285.00", "5.166079"], ["84293.50", "4.078484"], ["84302.00", "4.984813"], ["84310.50", "5.619244"]], "bids": [["84043.00", "0.255630"], ["84038.80", "0.001936"], ["84036.80", "0.005094"], ["84034.80", "0.013405"], ["84032.80", "0.035277"], ["84030.80", "0.092834"], ["84028.80", "0.244299"], ["84026.80", "0.642894"], ["84024.80", "1.691825"], ["84022.80", "4.452170"], ["83991.00", "0.000015"], ["83980.80", "4.169117"], ["83972.30", "3.987851"], ["83963.80", "4.350383"], ["83955.30", "5.166079"], ["83938.30", "4.712914"], ["83929.80", "5.619244"], ["83921.30", "4.078484"], ["83912.80", "4.894180"], ["83904.30", "4.441016"], ["83895.80", "3.897218"], ["83887.30", "4.984813"], ["83878.80", "5.256712"], ["83870.30", "4.259750"], ["83861.80", "5.075446"], ["83853.30", "5.437978"], ["83844.80", "5.528611"], ["83836.30", "4.531649"], ["83827.80", "4.803547"], ["83819.30", "5.347345"]], "checksum": -297249018, "ts": "1742555202391"}], "ts": 1742555202395, "record_time": 1742555202.419136, "EXCHANGE": "BITGET"}
{"action": "update", "arg": {"instType": "SPOT", "channel": "books", "instId": "BTCUSDT"}, "data": [{"asks": [["84043.21", "0.086888"], ["84043.22", "0"], ["84063.20", "0.035952"], ["84063.32", "0"], ["84064.85", "0.035961"], ["84064.92", "0"], ["84065.28", "0.006356"], ["84065.36", "0"], ["84065.43", "0.006356"], ["84065.52", "0"], ["84065.78", "0.006356"], ["84065.85", "0"], ["84066.89", "0.010984"], ["84067.03", "0"], ["84067.82", "0.006356"], ["84067.97", "0"], ["84068.30", "0.006356"], ["84068.33", "0.006356"], ["84068.36", "0"], ["84068.46", "0"], ["84068.63", "0.119883"], ["84068.66", "0.016429"], ["84068.72", "0"], ["84068.79", "0"], ["84068.80", "0.006356"], ["84068.91", "0"], ["84070.29", "0.006357"], ["84070.32", "0.010985"], ["84070.38", "0"], ["84070.39", "0"], ["84071.18", "0.009990"], ["84071.29", "0"], ["84073.09", "0.119858"], ["84073.18", "0"], ["84073.24", "0.119867"], ["84073.33", "0"], ["84073.54", "0.015895"], ["84073.67", "0.009989"], ["84073.77", "0"], ["84077.47", "0.015892"], ["84077.56", "0"], ["84078.33", "0.010988"], ["84078.46", "0"], ["84111.20", "0.476970"], ["84116.60", "0"], ["84149.00", "3.897218"], ["84157.50", "4.894180"], ["84174.50", "5.166079"], ["84183.00", "5.528611"], ["84191.50", "4.350383"], ["84200.00", "4.984813"], ["84208.50", "5.619244"], ["84217.00", "4.531649"], ["84225.50", "4.259750"], ["84234.00", "3.987851"], ["84242.50", "4.441016"], ["84251.00", "5.075446"], ["84259.50", "4.078484"], ["84268.00", "4.169117"], ["84276.50", "5.347345"], ["84285.00", "4.622282"], ["84293.50", "5.437978"], ["84302.00", "5.256712"], ["84310.50", "4.712914"], ["84525.82", "0.000099"]], "bids": [["84030.80", "0.093001"], ["84028.80", "0.244740"], ["84026.80", "0.644054"], ["84024.80", "1.694878"], ["84022.98", "0"], ["84022.86", "0.089506"], ["84022.80", "4.460206"], ["84021.22", "0"], ["84021.15", "0.083960"], ["84020.82", "0"], ["84020.74", "0.017821"], ["84020.65", "0"], ["84020.62", "0"], ["84020.55", "0.018259"], ["84020.48", "0.004018"], ["84020.30", "0"], ["84020.23", "0.005948"], ["84019.29", "0"], ["84019.15", "0.055669"], ["84018.50", "0"], ["84018.38", "0"], ["84018.23", "0.007341"], ["84017.86", "0"], ["84017.77", "0"], ["84017.73", "0.007945"], ["84017.71", "0.008996"], ["84017.53", "0"], ["84017.45", "0"], ["84017.40", "0.025190"], ["84017.37", "0.224937"], ["84017.32", "0"], ["84017.29", "0"], ["84017.20", "0.025542"], ["84015.76", "0"], ["84015.69", "0.051976"], ["84015.67", "0.012658"], ["84014.98", "0"], ["84014.87", "0.018521"], ["84013.00", "0.000032"], ["84012.91", "0.222723"], ["84012.82", "0"], ["84012.73", "0.259859"], ["84012.65", "0"], ["84012.52", "0.076131"], ["84012.42", "0"], ["84012.32", "0.021135"], ["84008.65", "0"], ["84008.56", "0.073233"], ["84007.86", "0"], ["84007.73", "0.056381"], ["84006.20", "0"], ["84006.05", "0.000877"], ["83987.70", "0"], ["83987.57", "0.003598"], ["83980.80", "4.622282"], ["83972.30", "4.531649"], ["83963.80", "5.619244"], ["83955.30", "5.528611"], ["83946.80", "4.078484"], ["83938.30", "4.803547"], ["83929.80", "4.441016"], ["83921.30", "4.169117"], ["83912.80", "5.166079"], ["83904.30", "5.075446"], ["83895.80", "4.712914"], ["83887.30", "5.256712"], ["83878.80", "4.894180"], ["83870.30", "3.897218"], ["83861.80", "4.350383"], ["83853.30", "5.347345"], ["83844.80", "4.984813"], ["83836.30", "5.437978"], ["83827.80", "3.987851"], ["83819.30", "4.259750"]], "checksum": 1488662085, "ts": "1742555202595"}], "ts": 1742555202598, "record_time": 1742555202.635524, "EXCHANGE": "BITGET"}
{"action": "update", "arg": {"instType": "SPOT", "channel": "books", "instId": "BTCUSDT"}, "data": [{"asks": [["84105.00", "4.008397"], ["84107.00", "10.548413"], ["84115.10", "0.021870"], ["84116.30", "0"], ["84149.00", "4.169117"], ["84157.50", "4.984813"], ["84166.00", "5.347345"], ["84174.50", "5.256712"], ["84183.00", "5.437978"], ["84191.50", "5.075446"], ["84200.00", "4.531649"], ["84208.50", "4.078484"], ["84217.00", "4.622282"], ["84225.50", "3.897218"], ["84234.00", "4.712914"], ["84242.50", "3.987851"], ["84251.00", "5.166079"], ["84259.50", "4.441016"], ["84268.00", "4.350383"], ["84276.50", "4.894180"], ["84285.00", "5.528611"], ["84293.50", "5.619244"], ["84302.00", "4.803547"], ["84310.50", "4.259750"], ["84527.47", "0.000608"]], "bids": [["84043.00", "0.525130"], ["84038.80", "0.002303"], ["84036.80", "0.006061"], ["84034.80", "0.015950"], ["84032.80", "0.041973"], ["84030.80", "0.110454"], ["84028.80", "0.290668"], ["84026.80", "0.764916"], ["84024.80", "2.012938"], ["84022.80", "5.297206"], ["83972.30", "5.528611"], ["83963.80", "5.166079"], ["83955.30", "4.984813"], ["83946.80", "3.987851"], ["83938.30", "5.619244"], ["83929.80", "5.075446"], ["83921.30", "4.531649"], ["83912.80", "4.078484"], ["83904.30", "4.441016"], ["83895.80", "5.347345"], ["83887.30", "4.350383"], ["83878.80", "4.803547"], ["83870.30", "4.894180"], ["83861.80", "5.256712"], ["83853.30", "3.897218"], ["83844.80", "4.712914"], ["83827.80", "4.259750"], ["83819.30", "4.169117"]], "checksum": -497555592, "ts": "1742555202806"}], "ts": 1742555202809, "record_time": 1742555202.833781, "EXCHANGE": "BITGET"}
{"action": "update", "arg": {"instType": "SPOT", "channel": "books", "instId": "BTCUSDT"}, "data": [{"asks": [["84105.00", "4.008072"], ["84107.00", "10.547558"], ["84149.00", "4.259750"], ["84157.50", "3.987851"], ["84166.00", "3.897218"], ["84174.50", "4.712914"], ["84183.00", "4.894180"], ["84191.50", "4.078484"], ["84200.00", "5.075446"], ["84208.50", "4.622282"], ["84217.00", "5.528611"], ["84225.50", "4.441016"], ["84234.00", "5.256712"], ["84242.50", "5.619244"], ["84251.00", "4.169117"], ["84259.50", "5.437978"], ["84268.00", "5.347345"], ["84276.50", "4.803547"], ["84285.00", "4.531649"], ["84293.50", "4.984813"], ["84302.00", "4.350383"], ["84310.50", "5.166079"]], "bids": [["84043.00", "0.315930"], ["84041.63", "0"], ["84022.80", "5.296945"], ["83992.00", "0.000017"], ["83980.80", "4.350383"], ["83972.30", "4.803547"], ["83963.80", "4.259750"], ["83955.30", "4.169117"], ["83946.80", "5.528611"], ["83938.30", "4.712914"], ["83929.80", "4.622282"], ["83921.30", "4.078484"], ["83912.80", "3.897218"], ["83904.30", "5.166079"], ["83895.80", "5.256712"], ["83887.30", "4.984813"], ["83878.80", "5.347345"], ["83870.30", "4.441016"], ["83861.80", "5.437978"], ["83853.30", "4.531649"], ["83844.80", "5.619244"], ["83836.30", "3.987851"], ["83827.80", "5.075446"], ["83819.30", "4.894180"], ["83660.71", "0.000309"]], "checksum": 323173972, "ts": "1742555203021"}], "ts": 1742555203023, "record_time": 1742555203.047267, "EXCHANGE": "BITGET"}
{"action": "update", "arg": {"instType": "SPOT", "channel": "books", "instId": "BTCUSDT"}, "data": [{"asks": [["84043.20", "0.086888"], ["84043.21", "0"], ["84082.85", "0.010000"], ["84149.00", "5.619244"], ["84157.50", "5.437978"], ["84166.00", "4.350383"], ["84174.50", "4.259750"], ["84183.00", "4.712914"], ["84191.50", "3.897218"], ["84200.00", "4.441016"], ["84208.50", "4.984813"], ["84217.00", "4.803547"], ["84225.50", "5.166079"], ["84234.00", "4.622282"], ["84242.50", "5.528611"], ["84251.00", "5.347345"], ["84259.50", "3.987851"], ["84268.00", "5.256712"], ["84276.50", "4.078484"], ["84293.50", "5.075446"], ["84302.00", "4.169117"], ["84310.50", "4.894180"], ["84527.47", "0"]], "bids": [["84043.00", "0.525130"], ["84039.26", "0.027859"], ["84038.80", "0.001642"], ["84036.80", "0.004321"], ["84034.80", "0.011373"], ["84032.80", "0.029799"], ["84030.80", "0.078418"], ["84028.80", "0.206363"], ["84026.80", "0.543061"], ["84024.80", "1.429107"], ["84022.80", "3.760808"], ["84022.60", "0.014790"], ["84022.40", "0"], ["84020.50", "0"], ["84017.00", "0.000032"], ["84011.50", "0.120000"], ["83980.80", "4.712914"], ["83972.30", "5.619244"], ["83963.80", "5.256712"], ["83955.30", "3.897218"], ["83946.80", "4.169117"], ["83938.30", "4.803547"], ["83929.80", "4.894180"], ["83921.30", "4.622282"], ["83912.80", "4.350383"], ["83904.30", "4.984813"], ["83895.80", "5.347345"], ["83887.30", "4.441016"], ["83878.80", "4.078484"], ["83870.30", "5.075446"], ["83861.80", "4.259750"], ["83853.30", "5.166079"], ["83844.80", "5.437978"], ["83836.30", "5.528611"], ["83827.80", "3.987851"], ["83819.30", "4.531649"]], "checksum": 598734317, "ts": "1742555203232"}], "ts": 1742555203240, "record_time": 1742555203.262729, "EXCHANGE": "BITGET"}
{"action": "update", "arg": {"instType": "SPOT", "channel": "books", "instId": "BTCUSDT"}, "data": [{"asks": [["84082.84", "0.003000"], ["84149.00", "4.894180"], ["84157.50", "4.803547"], ["84174.50", "3.987851"], ["84183.00", "5.528611"], ["84191.50", "4.441016"], ["84200.00", "4.259750"], ["84208.50", "5.256712"], ["84217.00", "5.619244"], ["84225.50", "3.897218"], ["84234.00", "5.437978"], ["84242.50", "4.531649"], ["84251.00", "4.984813"], ["84259.50", "4.622282"], ["84268.00", "4.169117"], ["84276.50", "5.075446"], ["84285.00", "4.078484"], ["84293.50", "5.166079"], ["84302.00", "5.347345"], ["84310.50", "4.712914"], ["84525.82", "0"]], "bids": [["84043.00", "0.315930"], ["84039.26", "0"], ["84022.30", "0.915360"], ["84021.00", "0.854250"], ["84011.50", "0"], ["83980.80", "5.256712"], ["83972.30", "5.437978"], ["83963.80", "5.528611"], ["83955.30", "4.984813"], ["83946.80", "4.350383"], ["83938.30", "3.897218"], ["83929.80", "5.619244"], ["83921.30", "4.441016"], ["83912.80", "4.169117"], ["83904.30", "4.259750"], ["83895.80", "5.166079"], ["83887.30", "5.347345"], ["83878.80", "5.075446"], ["83870.30", "4.622282"], ["83861.80", "4.894180"], ["83853.30", "4.803547"], ["83844.80", "4.712914"], ["83836.30", "4.531649"], ["83827.80", "4.078484"], ["83819.30", "3.987851"], ["83660.14", "0.000016"], ["83660.00", "0.001273"]], "checksum": -1051760969, "ts": "1742555203437"}], "ts": 1742555203441, "record_time": 1742555203.478065, "EXCHANGE": "BITGET"}
{"action": "update", "arg": {"instType": "SPOT", "channel": "books", "instId": "BTCUSDT"}, "data": [{"asks": [["84108.60", "0.581160"], ["84116.10", "0"], ["84149.00", "5.075446"], ["84166.00", "5.619244"], ["84174.50", "5.256712"], ["84183.00", "4.712914"], ["84191.50", "4.622282"], ["84200.00", "4.894180"], ["84208.50", "4.169117"], ["84217.00", "4.531649"], ["84225.50", "5.166079"], ["84234.00", "4.259750"], ["84242.50", "3.987851"], ["84259.50", "5.347345"], ["84268.00", "4.441016"], ["84276.50", "3.897218"], ["84285.00", "5.528611"], ["84293.50", "4.078484"], ["84302.00", "5.437978"], ["84310.50", "4.350383"], ["84525.82", "0.000099"]], "bids": [["84038.80", "0.001012"], ["84038.33", "0.027859"], ["84036.95", "0.010000"], ["84036.80", "0.001034"], ["84034.80", "0.001081"], ["84032.80", "0.002845"], ["84030.80", "0.007487"], ["84028.80", "0.019703"], ["84026.80", "0.051850"], ["84024.80", "0.136448"], ["84022.80", "0.359073"], ["84022.60", "0.001001"], ["84022.30", "0"], ["84021.00", "0.854460"], ["84019.90", "0.071580"], ["84019.30", "0.076650"], ["84017.00", "0.412890"], ["84016.60", "0.066240"], ["84016.40", "0"], ["84014.60", "2.356680"], ["83993.00", "0.000015"], ["83980.80", "4.712914"], ["83972.30", "5.619244"], ["83963.80", "4.531649"], ["83955.30", "4.350383"], ["83946.80", "4.894180"], ["83938.30", "4.803547"], ["83929.80", "4.441016"], ["83921.30", "4.169117"], ["83912.80", "5.528611"], ["83904.30", "3.987851"], ["83895.80", "5.075446"], ["83887.30", "4.984813"], ["83878.80", "5.437978"], ["83870.30", "5.256712"], ["83861.80", "4.078484"], ["83853.30", "5.166079"], ["83844.80", "5.347345"], ["83836.30", "3.897218"], ["83827.80", "4.259750"], ["83819.30", "4.622282"], ["83660.14", "0"], ["83660.00", "0"]], "checksum": 803541809, "ts": "1742555203649"}], "ts": 1742555203651, "record_time": 1742555203.698639, "EXCHANGE": "BITGET"}
{"action": "update", "arg": {"instType": "SPOT", "channel": "books", "instId": "BTCUSDT"}, "data": [{"asks": [["84107.00", "10.547688"], ["84108.50", "0.915720"], ["84108.60", "0.580950"], ["84109.80", "0"], ["84116.10", "0.067800"], ["84149.00", "3.897218"], ["84157.50", "5.347345"], ["84166.00", "4.350383"], ["84174.50", "4.078484"], ["84183.00", "4.894180"], ["84191.50", "4.531649"], ["84200.00", "4.441016"], ["84208.50", "4.259750"], ["84217.00", "5.256712"], ["84225.50", "5.437978"], ["84234.00", "4.803547"], ["84242.50", "4.712914"], ["84251.00", "4.169117"], ["84259.50", "5.528611"], ["84268.00", "5.075446"], ["84276.50", "5.166079"], ["84285.00", "4.984813"], ["84293.50", "5.619244"], ["84302.00", "4.622282"], ["84310.50", "3.987851"]], "bids": [["84034.80", "0.001394"], ["84032.80", "0.003669"], ["84030.80", "0.009655"], ["84028.81", "0.078599"], ["84028.80", "0.025408"], ["84026.80", "0.066864"], ["84024.80", "0.175958"], ["84024.51", "0.922276"], ["84022.80", "0.463047"], ["84021.00", "0.000032"], ["84018.70", "0.233370"], ["84017.90", "0.596430"], ["84017.00", "0.000032"], ["84014.60", "3.593910"], ["84014.50", "0"], ["83980.80", "4.078484"], ["83972.30", "4.531649"], ["83963.80", "4.350383"], ["83955.30", "5.347345"], ["83946.80", "4.169117"], ["83938.30", "3.897218"], ["83929.80", "3.987851"], ["83921.30", "4.803547"], ["83912.80", "4.894180"], ["83904.30", "5.437978"], ["83895.80", "4.259750"], ["83887.30", "4.712914"], ["83878.80", "5.166079"], ["83870.30", "5.528611"], ["83861.80", "4.441016"], ["83853.30", "5.256712"], ["83844.80", "5.075446"], ["83836.30", "5.619244"], ["83827.80", "4.622282"], ["83819.30", "4.984813"], ["83660.14", "0.000016"]], "checksum": 392298056, "ts": "1742555203875"}], "ts": 1742555203879, "record_time": 1742555203.909425, "EXCHANGE": "BITGET"}
{"action": "update", "arg": {"instType": "SPOT", "channel": "books", "instId": "BTCUSDT"}, "data": [{"asks": [["84043.01", "2.270178"], ["84043.19", "0.086888"], ["84043.20", "0"], ["84097.00", "0.083312"], ["84099.00", "0.219242"], ["84101.00", "0.576952"], ["84103.00", "1.518294"], ["84105.00", "3.995512"], ["84107.00", "10.514506"], ["84149.00", "3.987851"], ["84157.50", "4.350383"], ["84166.00", "5.166079"], ["84174.50", "5.347345"], ["84183.00", "4.984813"], ["84191.50", "4.803547"], ["84200.00", "4.712914"], ["84208.50", "4.078484"], ["84217.00", "4.259750"], ["84225.50", "3.897218"], ["84234.00", "4.894180"], ["84242.50", "5.528611"], ["84251.00", "4.441016"], ["84259.50", "4.622282"], ["84268.00", "4.531649"], ["84276.50", "5.619244"], ["84285.00", "4.169117"], ["84293.50", "5.256712"], ["84302.00", "5.437978"], ["84310.50", "5.075446"]], "bids": [["84039.42", "0.027859"], ["84038.33", "0"], ["84034.80", "0.001518"], ["84032.80", "0.003997"], ["84030.80", "0.010516"], ["84028.80", "0.027674"], ["84026.80", "0.072826"], ["84024.80", "0.191649"], ["84024.51", "0.499871"], ["84022.80", "0.504339"], ["84020.10", "0.420870"], ["84019.89", "0.422991"], ["84018.70", "0.381420"], ["84017.90", "0.075030"], ["84017.00", "0.802950"], ["84016.60", "0.281400"], ["83980.80", "5.166079"], ["83963.80", "5.256712"], ["83955.30", "4.350383"], ["83946.80", "4.894180"], ["83938.30", "4.169117"], ["83929.80", "4.259750"], ["83921.30", "3.897218"], ["83912.80", "4.622282"], ["83904.30", "4.078484"], ["83895.80", "4.984813"], ["83887.30", "5.437978"], ["83878.80", "4.803547"], ["83861.80", "5.347345"], ["83853.30", "4.441016"], ["83844.80", "5.619244"], ["83836.30", "4.712914"], ["83827.80", "5.075446"], ["83819.30", "3.987851"], ["83660.14", "0"]], "checksum": -1850768309, "ts": "1742555204083"}], "ts": 1742555204087, "record_time": 1742555204.207586, "EXCHANGE": "BITGET"}
{"action": "update", "arg": {"instType": "SPOT", "channel": "books", "instId": "BTCUSDT"}, "data": [{"asks": [["84043.01", "2.230410"], ["84063.60", "0.119870"], ["84063.69", "0"], ["84067.12", "0.006356"], ["84067.19", "0"], ["84067.29", "0.006356"], ["84067.36", "0"], ["84067.79", "0.016429"], ["84067.86", "0"], ["84068.81", "0.006356"], ["84068.87", "0"], ["84072.11", "0.119850"], ["84072.25", "0"], ["84102.99", "0"], ["84103.00", "1.518273"], ["84105.00", "3.995455"], ["84107.00", "10.514357"], ["84157.50", "4.259750"], ["84166.00", "4.350383"], ["84174.50", "4.712914"], ["84183.00", "5.166079"], ["84191.50", "5.437978"], ["84200.00", "4.531649"], ["84208.50", "5.256712"], ["84217.00", "5.075446"], ["84225.50", "4.894180"], ["84234.00", "3.897218"], ["84242.50", "4.441016"], ["84251.00", "4.169117"], ["84259.50", "5.347345"], ["84268.00", "4.803547"], ["84276.50", "4.984813"], ["84285.00", "5.619244"], ["84293.50", "5.528611"], ["84302.00", "4.078484"], ["84310.50", "4.622282"], ["84527.47", "0.000608"]], "bids": [["84034.80", "0.001389"], ["84032.80", "0.003657"], ["84030.80", "0.009623"], ["84028.80", "0.025324"], ["84026.80", "0.066641"], ["84024.80", "0.175371"], ["84022.80", "0.461503"], ["84022.51", "0"], ["84022.42", "0.247647"], ["84019.91", "0.647407"], ["84019.89", "0"], ["84018.94", "0"], ["84018.88", "0.017107"], ["84018.78", "0"], ["84018.72", "0.007133"], ["84018.40", "0.066210"], ["84018.27", "0"], ["84018.21", "0.028872"], ["84014.10", "0"], ["84013.96", "0.268442"], ["83991.00", "0.000032"], ["83980.80", "4.984813"], ["83972.30", "4.712914"], ["83963.80", "4.803547"], ["83955.30", "5.619244"], ["83946.80", "5.256712"], ["83938.30", "4.441016"], ["83929.80", "5.528611"], ["83921.30", "4.622282"], ["83912.80", "4.894180"], ["83904.30", "4.259750"], ["83895.80", "4.531649"], ["83887.30", "5.166079"], ["83878.80", "4.350383"], ["83870.30", "3.897218"], ["83853.30", "4.078484"], ["83844.80", "3.987851"], ["83836.30", "5.075446"], ["83827.80", "4.169117"], ["83819.30", "5.437978"], ["83660.71", "0"]], "checksum": -1215180510, "ts": "1742555204297"}], "ts": 1742555204301, "record_time": 1742555204.396503, "EXCHANGE": "BITGET"}
{"action": "update", "arg": {"instType": "SPOT", "channel": "books", "instId": "BTCUSDT"}, "data": [{"asks": [["84043.01", "2.117611"], ["84091.00", "0.004442"], ["84093.00", "0.011691"], ["84095.00", "0.030764"], ["84097.00", "0.080960"], ["84099.00", "0.213052"], ["84101.00", "0.560663"], ["84103.00", "1.475428"], ["84105.00", "3.882707"], ["84107.00", "10.217650"], ["84149.00", "4.894180"], ["84157.50", "5.347345"], ["84166.00", "4.622282"], ["84174.50", "4.350383"], ["84183.00", "5.437978"], ["84191.50", "4.169117"], ["84200.00", "5.075446"], ["84208.50", "4.712914"], ["84217.00", "3.987851"], ["84225.50", "5.256712"], ["84234.00", "4.259750"], ["84242.50", "4.078484"], ["84251.00", "5.166079"], ["84259.50", "5.619244"], ["84276.50", "3.897218"], ["84285.00", "5.528611"], ["84293.50", "4.441016"], ["84302.00", "4.531649"], ["84310.50", "4.984813"]], "bids": [["84043.00", "0.295930"], ["84034.80", "0.001511"], ["84032.80", "0.003975"], ["84030.80", "0.010461"], ["84028.80", "0.027529"], ["84026.80", "0.072445"], ["84024.80", "0.190645"], ["84022.80", "0.501698"], ["84022.04", "0"], ["84019.90", "0.083580"], ["84018.10", "0.760290"], ["84017.00", "0.000032"], ["84015.48", "0.314131"], ["84014.61", "1.119364"], ["83991.00", "0.000017"], ["83980.80", "3.897218"], ["83972.30", "4.803547"], ["83963.80", "5.075446"], ["83955.30", "5.437978"], ["83946.80", "4.350383"], ["83938.30", "5.619244"], ["83929.80", "4.894180"], ["83921.30", "3.987851"], ["83912.80", "4.531649"], ["83904.30", "5.256712"], ["83895.80", "5.166079"], ["83887.30", "4.078484"], ["83878.80", "5.347345"], ["83870.30", "4.441016"], ["83861.80", "4.984813"], ["83853.30", "4.712914"], ["83844.80", "4.259750"], ["83836.30", "4.622282"], ["83827.80", "5.528611"], ["83819.30", "4.169117"], ["83661.60", "0"], ["83661.08", "0"]], "checksum": 1100244966, "ts": "1742555204504"}], "ts": 1742555204507, "record_time": 1742555204.531486, "EXCHANGE": "BITGET"}
{"action": "update", "arg": {"instType": "SPOT", "channel": "books", "instId": "BTCUSDT"}, "data": [{"asks": [["84043.01", "2.260232"], ["84043.19", "0"], ["84091.00", "0.004586"], ["84093.00", "0.012069"], ["84095.00", "0.031760"], ["84097.00", "0.083579"], ["84099.00", "0.219944"], ["84101.00", "0.578802"], ["84103.00", "1.523161"], ["84105.00", "4.008319"], ["84107.00", "10.548209"], ["84110.10", "0.388440"], ["84110.30", "0"], ["84149.00", "4.984813"], ["84157.50", "4.712914"], ["84166.00", "4.894180"], ["84174.50", "5.075446"], ["84183.00", "5.256712"], ["84191.50", "5.347345"], ["84200.00", "3.987851"], ["84208.50", "4.078484"], ["84217.00", "4.531649"], ["84225.50", "4.350383"], ["84234.00", "5.166079"], ["84242.50", "4.622282"], ["84251.00", "4.169117"], ["84259.50", "4.803547"], ["84268.00", "4.441016"], ["84276.50", "5.619244"], ["84285.00", "4.259750"], ["84293.50", "5.437978"], ["84302.00", "5.528611"], ["84310.50", "3.897218"], ["84528.57", "0.000008"], ["84530.00", "0.000031"]], "bids": [["84034.80", "0.001387"], ["84032.80", "0.003651"], ["84030.80", "0.009608"], ["84028.80", "0.025283"], ["84026.80", "0.066533"], ["84024.80", "0.175089"], ["84022.80", "0.460759"], ["84021.65", "0.006155"], ["84021.60", "0"], ["84019.90", "0.145380"], ["84018.40", "0.284370"], ["83980.80", "4.984813"], ["83972.30", "4.350383"], ["83963.80", "5.528611"], ["83955.30", "4.531649"], ["83946.80", "4.712914"], ["83938.30", "5.437978"], ["83929.80", "5.166079"], ["83921.30", "4.259750"], ["83912.80", "3.987851"], ["83904.30", "5.619244"], ["83895.80", "4.441016"], ["83887.30", "3.897218"], ["83878.80", "5.075446"], ["83870.30", "4.622282"], ["83861.80", "5.256712"], ["83853.30", "4.169117"], ["83844.80", "4.803547"], ["83836.30", "5.347345"], ["83827.80", "4.078484"], ["83819.30", "4.894180"]], "checksum": 364599684, "ts": "1742555204707"}], "ts": 1742555204711, "record_time": 1742555204.744006, "EXCHANGE": "BITGET"}
{"action": "update", "arg": {"instType": "SPOT", "channel": "books", "instId": "BTCUSDT"}, "data": [{"asks": [["84043.02", "0.020701"], ["84043.18", "0.086888"], ["84149.00", "4.712914"], ["84157.50", "4.078484"], ["84166.00", "5.256712"], ["84174.50", "4.803547"], ["84183.00", "5.437978"], ["84191.50", "5.075446"], ["84200.00", "4.441016"], ["84208.50", "4.622282"], ["84217.00", "5.166079"], ["84225.50", "4.984813"], ["84234.00", "5.347345"], ["84242.50", "4.259750"], ["84251.00", "3.987851"], ["84259.50", "4.531649"], ["84268.00", "5.528611"], ["84276.50", "4.894180"], ["84285.00", "5.619244"], ["84293.50", "4.169117"], ["84302.00", "4.350383"], ["84530.00", "0"]], "bids": [["84028.81", "0"], ["83992.00", "0"], ["83980.80", "4.169117"], ["83972.30", "5.256712"], ["83963.80", "4.441016"], ["83955.30", "4.984813"], ["83946.80", "3.897218"], ["83938.30", "4.531649"], ["83929.80", "5.528611"], ["83921.30", "5.619244"], ["83912.80", "4.803547"], ["83904.30", "4.078484"], ["83895.80", "4.259750"], ["83887.30", "5.166079"], ["83878.80", "4.350383"], ["83870.30", "5.347345"], ["83861.80", "4.622282"], ["83853.30", "5.437978"], ["83844.80", "4.712914"], ["83836.30", "5.075446"], ["83827.80", "3.987851"], ["83661.60", "0.000042"], ["83661.08", "0.004152"]], "checksum": -1776983999, "ts": "1742555204912"}], "ts": 1742555204917, "record_time": 1742555204.945728, "EXCHANGE": "BITGET"}
{"action": "update", "arg": {"instType": "SPOT", "channel": "books", "instId": "BTCUSDT"}, "data": [{"asks": [["84043.01", "2.269831"], ["84043.02", "0.046251"], ["84089.00", "0.001792"], ["84091.00", "0.004714"], ["84093.00", "0.012407"], ["84095.00", "0.032650"], ["84097.00", "0.085921"], ["84099.00", "0.226108"], ["84101.00", "0.595021"], ["84103.00", "1.565845"], ["84105.00", "4.120644"], ["84107.00", "10.843800"], ["84149.00", "5.437978"], ["84157.50", "5.075446"], ["84174.50", "4.531649"], ["84183.00", "4.169117"], ["84191.50", "4.441016"], ["84200.00", "3.987851"], ["84208.50", "4.078484"], ["84217.00", "5.528611"], ["84225.50", "4.894180"], ["84234.00", "3.897218"], ["84242.50", "5.619244"], ["84251.00", "5.347345"], ["84259.50", "4.803547"], ["84268.00", "4.984813"], ["84276.50", "4.259750"], ["84285.00", "4.622282"], ["84293.50", "5.166079"], ["84302.00", "4.712914"], ["84310.50", "4.350383"]], "bids": [["84022.80", "0.460889"], ["84020.10", "0"], ["84019.90", "0.071580"], ["84018.70", "0.381630"], ["84016.50", "0.072210"], ["84011.90", "0"], ["84011.71", "0.078599"], ["84011.70", "0"], ["83992.00", "0.000015"], ["83980.80", "4.803547"], ["83972.30", "4.441016"], ["83963.80", "5.347345"], ["83955.30", "4.712914"], ["83946.80", "5.619244"], ["83938.30", "4.259750"], ["83929.80", "5.075446"], ["83921.30", "3.987851"], ["83912.80", "4.078484"], ["83904.30", "4.350383"], ["83895.80", "5.437978"], ["83887.30", "5.256712"], ["83878.80", "5.528611"], ["83870.30", "4.531649"], ["83861.80", "5.166079"], ["83853.30", "4.169117"], ["83844.80", "3.897218"], ["83836.30", "4.622282"], ["83827.80", "4.894180"], ["83819.30", "4.984813"]], "checksum": -1393703209, "ts": "1742555205131"}], "ts": 1742555205135, "record_time": 1742555205.162957, "EXCHANGE": "BITGET"}
{"action": "update", "arg": {"instType": "SPOT", "channel": "books", "instId": "BTCUSDT"}, "data": [{"asks": [["84043.01", "2.285228"], ["84082.85", "0"], ["84093.00", "0.012194"], ["84095.00", "0.032091"], ["84097.00", "0.084448"], ["84099.00", "0.222232"], ["84101.00", "0.584822"], ["84103.00", "1.539005"], ["84105.00", "4.050014"], ["84107.00", "10.657930"], ["84149.00", "3.897218"], ["84157.50", "4.622282"], ["84166.00", "4.169117"], ["84174.50", "4.078484"], ["84183.00", "4.803547"], ["84191.50", "4.984813"], ["84200.00", "4.350383"], ["84208.50", "4.531649"], ["84217.00", "4.441016"], ["84225.50", "5.166079"], ["84234.00", "4.259750"], ["84237.53", "0"], ["84242.50", "3.987851"], ["84251.00", "5.437978"], ["84259.50", "5.256712"], ["84268.00", "4.894180"], ["84276.50", "5.075446"], ["84285.00", "5.619244"], ["84293.50", "5.347345"], ["84302.00", "5.528611"], ["84310.50", "4.712914"], ["84530.00", "0.000031"], ["84533.01", "0.000591"]], "bids": [["84018.70", "0.668820"], ["84018.40", "0.774660"], ["83993.00", "0.000032"], ["83980.80", "5.437978"], ["83972.30", "4.169117"], ["83963.80", "4.078484"], ["83955.30", "4.803547"], ["83946.80", "4.894180"], ["83938.30", "5.347345"], ["83929.80", "5.256712"], ["83921.30", "4.622282"], ["83912.80", "5.528611"], ["83904.30", "5.166079"], ["83895.80", "4.984813"], ["83887.30", "4.531649"], ["83878.80", "3.987851"], ["83870.30", "5.619244"], ["83861.80", "4.441016"], ["83853.30", "3.897218"], ["83844.80", "4.350383"], ["83836.30", "4.259750"], ["83827.80", "4.712914"], ["83819.30", "5.075446"]], "checksum": 510306973, "ts": "1742555205335"}], "ts": 1742555205339, "record_time": 1742555205.445309, "EXCHANGE": "BITGET"}
{"action": "update", "arg": {"instType": "SPOT", "channel": "books", "instId": "BTCUSDT"}, "data": [{"asks": [["84043.01", "2.269831"], ["84043.18", "0"], ["84082.84", "0"], ["84098.01", "0"], ["84098.02", "0.001598"], ["84149.00", "5.437978"], ["84166.00", "4.350383"], ["84174.50", "4.984813"], ["84183.00", "4.894180"], ["84191.50", "5.347345"], ["84200.00", "4.169117"], ["84208.50", "5.528611"], ["84225.50", "4.712914"], ["84234.00", "5.075446"], ["84234.83", "0.166008"], ["84242.50", "4.531649"], ["84251.00", "5.256712"], ["84259.50", "5.166079"], ["84268.00", "4.259750"], ["84276.50", "5.619244"], ["84285.00", "3.987851"], ["84293.50", "4.078484"], ["84302.00", "4.803547"], ["84310.50", "3.897218"], ["84533.33", "0.003186"]], "bids": [["84034.80", "0.001512"], ["84032.80", "0.003979"], ["84030.80", "0.010471"], ["84028.81", "0.084678"], ["84028.80", "0.027556"], ["84026.80", "0.072515"], ["84024.80", "0.190829"], ["84022.80", "0.502181"], ["84019.30", "0.491850"], ["84012.00", "0.120000"], ["83980.80", "4.259750"], ["83972.30", "3.897218"], ["83963.80", "5.619244"], ["83955.30", "4.350383"], ["83946.80", "4.531649"], ["83938.30", "4.712914"], ["83929.80", "4.078484"], ["83921.30", "5.437978"], ["83912.80", "4.441016"], ["83904.30", "4.894180"], ["83887.30", "5.075446"], ["83878.80", "5.528611"], ["83870.30", "4.169117"], ["83861.80", "5.166079"], ["83853.30", "5.347345"], ["83844.80", "4.803547"], ["83836.30", "5.256712"], ["83827.80", "4.622282"], ["83819.30", "3.987851"], ["83661.08", "0"]], "checksum": 1293660040, "ts": "1742555205541"}], "ts": 1742555205544, "record_time": 1742555205.567977, "EXCHANGE": "BITGET"}
{"action": "update", "arg": {"instType": "SPOT", "channel": "books", "instId": "BTCUSDT"}, "data": [{"asks": [["84043.02", "0.020701"], ["84043.17", "0.086888"], ["84099.83", "0"], ["84099.93", "0.001597"], ["84105.00", "4.049865"], ["84107.00", "10.657540"], ["84149.00", "5.528611"], ["84157.50", "4.894180"], ["84166.00", "5.437978"], ["84174.50", "4.078484"], ["84183.00", "4.531649"], ["84191.50", "4.984813"], ["84200.00", "4.441016"], ["84208.50", "4.350383"], ["84217.00", "4.622282"], ["84225.50", "5.075446"], ["84234.00", "4.259750"], ["84242.50", "5.166079"], ["84251.00", "4.803547"], ["84259.50", "3.897218"], ["84268.00", "4.169117"], ["84276.50", "5.256712"], ["84285.00", "5.619244"], ["84293.50", "3.987851"], ["84302.00", "4.712914"], ["84310.50", "5.347345"], ["84533.33", "0"]], "bids": [["84036.95", "0"], ["84024.80", "0.190645"], ["84022.80", "0.501698"], ["84019.91", "0.960531"], ["84019.30", "0.492060"], ["84018.70", "0.668610"], ["84018.40", "0.284370"], ["84014.61", "0.065629"], ["84012.00", "0.654660"], ["83993.00", "0.000017"], ["83985.80", "0.001173"], ["83985.70", "0"], ["83980.80", "5.347345"], ["83972.30", "4.441016"], ["83963.80", "5.437978"], ["83955.30", "4.531649"], ["83946.80", "3.897218"], ["83938.30", "4.984813"], ["83929.80", "5.075446"], ["83921.30", "5.256712"], ["83912.80", "4.169117"], ["83904.30", "4.078484"], ["83895.80", "4.803547"], ["83887.30", "5.166079"], ["83878.80", "4.894180"], ["83870.30", "4.622282"], ["83861.80", "3.987851"], ["83853.30", "5.619244"], ["83844.80", "4.350383"], ["83836.30", "4.712914"], ["83827.80", "5.528611"], ["83819.30", "4.259750"], ["83661.08", "0.004152"]], "checksum": 1582393460, "ts": "1742555205745"}], "ts": 1742555205747, "record_time": 1742555205.778214, "EXCHANGE": "BITGET"}
{"action": "update", "arg": {"instType": "SPOT", "channel": "books", "instId": "BTCUSDT"}, "data": [{"asks": [["84043.02", "0.046251"], ["84149.00", "4.169117"], ["84157.50", "5.437978"], ["84166.00", "5.619244"], ["84174.50", "5.166079"], ["84183.00", "4.441016"], ["84191.50", "4.803547"], ["84200.00", "3.987851"], ["84208.50", "4.531649"], ["84217.00", "5.256712"], ["84225.50", "4.259750"], ["84234.00", "5.528611"], ["84242.50", "4.984813"], ["84251.00", "4.712914"], ["84259.50", "4.350383"], ["84268.00", "5.347345"], ["84276.50", "4.894180"], ["84285.00", "5.075446"], ["84293.50", "4.078484"], ["84302.00", "3.897218"], ["84310.50", "4.622282"]], "bids": [["84034.80", "0.001511"], ["84032.80", "0.003975"], ["84030.80", "0.010461"], ["84028.80", "0.027529"], ["84026.80", "0.072445"], ["84014.61", "0.800161"], ["83980.80", "4.169117"], ["83972.30", "4.259750"], ["83963.80", "5.619244"], ["83955.30", "5.075446"], ["83946.80", "3.987851"], ["83938.30", "4.441016"], ["83929.80", "4.712914"], ["83921.30", "4.622282"], ["83912.80", "5.528611"], ["83904.30", "3.897218"], ["83895.80", "4.894180"], ["83887.30", "5.256712"], ["83878.80", "5.166079"], ["83870.30", "4.078484"], ["83861.80", "5.347345"], ["83853.30", "4.984813"], ["83844.80", "4.531649"], ["83836.30", "4.350383"], ["83827.80", "4.803547"], ["83819.30", "5.437978"]], "checksum": -352989826, "ts": "1742555205945"}], "ts": 1742555205949, "record_time": 1742555205.970942, "EXCHANGE": "BITGET"}
{"action": "update", "arg": {"instType": "SPOT", "channel": "books", "instId": "BTCUSDT"}, "data": [{"asks": [["84149.00", "4.350383"], ["84157.50", "4.259750"], ["84166.00", "4.984813"], ["84174.50", "4.531649"], ["84183.00", "3.987851"], ["84191.50", "5.347345"], ["84200.00", "5.075446"], ["84208.50", "4.078484"], ["84217.00", "5.619244"], ["84225.50", "4.894180"], ["84234.00", "5.256712"], ["84242.50", "4.622282"], ["84259.50", "4.441016"], ["84268.00", "5.166079"], ["84276.50", "5.437978"], ["84285.00", "3.897218"], ["84293.50", "4.803547"], ["84302.00", "5.528611"], ["84310.50", "4.169117"]], "bids": [["84032.80", "0.004153"], ["84030.80", "0.010931"], ["84028.80", "0.028765"], ["84026.80", "0.075698"], ["84024.80", "0.199205"], ["84022.80", "0.524222"], ["83991.00", "0"], ["83980.80", "4.984813"], ["83972.30", "3.897218"], ["83963.80", "3.987851"], ["83955.30", "4.622282"], ["83946.80", "5.347345"], ["83938.30", "4.259750"], ["83929.80", "5.619244"], ["83921.30", "4.078484"], ["83912.80", "4.712914"], ["83904.30", "5.437978"], ["83895.80", "4.441016"], ["83887.30", "5.528611"], ["83878.80", "4.894180"], ["83870.30", "5.256712"], ["83861.80", "4.169117"], ["83853.30", "5.075446"], ["83844.80", "4.350383"], ["83836.30", "4.803547"], ["83827.80", "4.531649"], ["83819.30", "5.166079"], ["83660.71", "0.000309"]], "checksum": -1181381122, "ts": "1742555206154"}], "ts": 1742555206159, "record_time": 1742555206.18349, "EXCHANGE": "BITGET"}
{"action": "update", "arg": {"instType": "SPOT", "channel": "books", "instId": "BTCUSDT"}, "data": [{"asks": [["84043.01", "2.280679"], ["84107.00", "10.657409"], ["84157.50", "4.803547"], ["84166.00", "5.528611"], ["84174.50", "5.347345"], ["84183.00", "5.437978"], ["84191.50", "5.075446"], ["84200.00", "4.531649"], ["84208.50", "4.984813"], ["84217.00", "4.894180"], ["84225.50", "5.256712"], ["84234.00", "4.441016"], ["84242.50", "3.987851"], ["84251.00", "4.622282"], ["84259.50", "4.078484"], ["84268.00", "4.712914"], ["84276.50", "4.169117"], ["84285.00", "5.619244"], ["84293.50", "3.897218"], ["84302.00", "5.166079"], ["84310.50", "4.259750"]], "bids": [["84039.42", "0"], ["84032.80", "0.003827"], ["84031.68", "0"], ["84030.80", "0.010070"], ["84028.81", "0"], ["84028.80", "0.026499"], ["84026.80", "0.069735"], ["84024.80", "0.183514"], ["84022.80", "0.482930"], ["84020.30", "0.447360"], ["84019.30", "0.076650"], ["83972.30", "5.166079"], ["83963.80", "4.259750"], ["83955.30", "4.712914"], ["83946.80", "4.169117"], ["83938.30", "3.987851"], ["83929.80", "5.256712"], ["83921.30", "4.622282"], ["83912.80", "4.894180"], ["83904.30", "4.350383"], ["83895.80", "4.078484"], ["83887.30", "3.897218"], ["83878.80", "5.347345"], ["83870.30", "5.619244"], ["83861.80", "4.441016"], ["83844.80", "4.803547"], ["83836.30", "5.528611"], ["83819.30", "5.437978"], ["83660.14", "0.000016"], ["83660.00", "0.001273"]], "checksum": 1403321557, "ts": "1742555206357"}], "ts": 1742555206359, "record_time": 1742555206.390158, "EXCHANGE": "BITGET"}
{"action": "update", "arg": {"instType": "SPOT", "channel": "books", "instId": "BTCUSDT"}, "data": [{"asks": [["84043.01", "2.335652"], ["84043.16", "0.086888"], ["84043.17", "0"], ["84088.99", "0"], ["84098.19", "0"], ["84103.00", "1.538884"], ["84105.00", "4.049696"], ["84107.00", "10.657093"], ["84109.50", "0.269760"], ["84112.00", "0.477480"], ["84114.10", "5.283960"], ["84116.10", "0"], ["84157.50", "5.619244"], ["84166.00", "4.803547"], ["84174.50", "4.984813"], ["84183.00", "5.256712"], ["84191.50", "4.622282"], ["84200.00", "5.347345"], ["84208.50", "5.166079"], ["84217.00", "5.075446"], ["84225.50", "4.169117"], ["84234.00", "5.528611"], ["84242.50", "5.437978"], ["84251.00", "4.531649"], ["84259.50", "4.712914"], ["84268.00", "3.897218"], ["84276.50", "4.259750"], ["84285.00", "3.987851"], ["84293.50", "4.078484"], ["84302.00", "4.441016"], ["84310.50", "4.894180"], ["84533.33", "0.003186"]], "bids": [["84038.11", "0.027859"], ["84034.80", "0.001135"], ["84032.80", "0.002987"], ["84030.80", "0.007860"], ["84028.80", "0.020686"], ["84026.80", "0.054437"], ["84024.80", "0.143254"], ["84023.01", "0.014476"], ["84022.80", "0.377115"], ["84020.30", "0"], ["84018.70", "0"], ["84018.40", "0.583620"], ["84018.10", "0"], ["84017.90", "0.007230"], ["84016.50", "0"], ["84014.61", "0"], ["84012.60", "0"], ["84011.90", "0.120000"], ["84011.70", "0.120000"], ["83991.00", "0.000015"], ["83980.80", "5.256712"], ["83972.30", "4.350383"], ["83963.80", "5.528611"], ["83955.30", "4.169117"], ["83946.80", "4.622282"], ["83938.30", "4.712914"], ["83929.80", "5.347345"], ["83921.30", "3.987851"], ["83912.80", "5.166079"], ["83904.30", "4.531649"], ["83895.80", "4.259750"], ["83887.30", "4.803547"], ["83878.80", "5.619244"], ["83870.30", "4.078484"], ["83861.80", "5.437978"], ["83853.30", "4.441016"], ["83844.80", "4.894180"], ["83836.30", "4.984813"], ["83827.80", "3.897218"], ["83819.30", "5.075446"], ["83659.61", "0.000454"]], "checksum": -1684527320, "ts": "1742555206556"}], "ts": 1742555206559, "record_time": 1742555206.583852, "EXCHANGE": "BITGET"}
{"action": "update", "arg": {"instType": "SPOT", "channel": "books", "instId": "BTCUSDT"}, "data": [{"asks": [["84049.00", "0.096325"], ["84114.00", "2.164110"], ["84114.10", "4.175610"], ["84115.10", "0.006870"], ["84149.00", "4.441016"], ["84157.50", "4.712914"], ["84166.00", "5.347345"], ["84174.50", "4.531649"], ["84183.00", "4.169117"], ["84191.50", "4.984813"], ["84200.00", "5.166079"], ["84208.50", "5.256712"], ["84217.00", "4.894180"], ["84225.50", "4.259750"], ["84234.00", "3.987851"], ["84251.00", "4.803547"], ["84259.50", "3.897218"], ["84268.00", "4.622282"], ["84276.50", "5.619244"], ["84285.00", "5.075446"], ["84293.50", "4.350383"], ["84302.00", "5.528611"], ["84310.50", "4.078484"], ["84533.33", "0"]], "bids": [["84032.80", "0.002809"], ["84030.80", "0.007394"], ["84028.80", "0.019457"], ["84026.80", "0.051203"], ["84024.80", "0.134745"], ["84022.80", "0.354590"], ["84019.91", "0.313124"], ["84018.50", "0.015000"], ["84014.61", "1.260188"], ["84013.70", "0.881160"], ["83992.00", "0.000032"], ["83980.80", "4.350383"], ["83972.30", "3.987851"], ["83963.80", "5.619244"], ["83955.30", "4.712914"], ["83946.80", "4.169117"], ["83938.30", "4.078484"], ["83929.80", "4.622282"], ["83921.30", "4.984813"], ["83912.80", "4.803547"], ["83904.30", "4.259750"], ["83895.80", "5.347345"], ["83887.30", "5.528611"], ["83878.80", "4.441016"], ["83870.30", "5.256712"], ["83861.80", "4.531649"], ["83853.30", "5.075446"], ["83844.80", "5.166079"], ["83836.30", "4.894180"], ["83819.30", "5.437978"], ["83660.14", "0"], ["83660.00", "0"], ["83659.61", "0"]], "checksum": 1912832054, "ts": "1742555206766"}], "ts": 1742555206768, "record_time": 1742555206.826334, "EXCHANGE": "BITGET"}
{"action": "update", "arg": {"instType": "SPOT", "channel": "books", "instId": "BTCUSDT"}, "data": [{"asks": [["84043.01", "2.317026"], ["84095.00", "0.032204"], ["84097.00", "0.084748"], ["84099.00", "0.223020"], ["84101.00", "0.586896"], ["84103.00", "1.544463"], ["84105.00", "4.064376"], ["84107.00", "10.695725"], ["84107.40", "0.120630"], ["84108.00", "0"], ["84108.10", "0.068010"], ["84108.50", "0.915510"], ["84111.20", "0.356970"], ["84149.00", "5.075446"], ["84157.50", "4.169117"], ["84166.00", "4.531649"], ["84174.50", "4.259750"], ["84183.00", "4.984813"], ["84191.50", "4.441016"], ["84200.00", "4.078484"], ["84208.50", "4.894180"], ["84217.00", "3.987851"], ["84225.50", "5.437978"], ["84234.00", "5.347345"], ["84242.50", "4.350383"], ["84251.00", "5.166079"], ["84259.50", "5.528611"], ["84276.50", "4.803547"], ["84285.00", "4.712914"], ["84293.50", "3.897218"], ["84302.00", "5.256712"], ["84310.50", "5.619244"]], "bids": [["84034.80", "0.001381"], ["84032.80", "0.003636"], ["84030.80", "0.009567"], ["84028.80", "0.025177"], ["84026.80", "0.066254"], ["84024.80", "0.174353"], ["84022.80", "0.458825"], ["84018.40", "0.284580"], ["84017.70", "1.107420"], ["84014.90", "0.757680"], ["84014.60", "1.237230"], ["84013.70", "0"], ["84012.90", "2.356710"], ["84011.71", "0.272058"], ["84011.70", "0"], ["83980.80", "4.712914"], ["83972.30", "5.619244"], ["83963.80", "4.622282"], ["83955.30", "4.894180"], ["83946.80", "5.075446"], ["83938.30", "5.528611"], ["83929.80", "3.987851"], ["83921.30", "4.531649"], ["83904.30", "4.078484"], ["83895.80", "4.169117"], ["83887.30", "4.984813"], ["83878.80", "3.897218"], ["83861.80", "5.347345"], ["83853.30", "5.437978"], ["83836.30", "4.259750"], ["83827.80", "4.350383"], ["83819.30", "4.441016"], ["83660.71", "0"]], "checksum": -2041331206, "ts": "1742555206978"}], "ts": 1742555206983, "record_time": 1742555207.017632, "EXCHANGE": "BITGET"}
{"action": "update", "arg": {"instType": "SPOT", "channel": "books", "instId": "BTCUSDT"}, "data": [{"asks": [["84043.01", "2.315825"], ["84100.00", "0.004910"], ["84157.50", "4.350383"], ["84166.00", "3.987851"], ["84174.50", "4.984813"], ["84183.00", "4.712914"], ["84191.50", "5.619244"], ["84200.00", "4.259750"], ["84208.50", "4.622282"], ["84217.00", "3.897218"], ["84225.50", "5.166079"], ["84234.00", "4.803547"], ["84242.50", "5.256712"], ["84251.00", "5.528611"], ["84259.50", "4.531649"], ["84268.00", "5.347345"], ["84276.50", "4.078484"], ["84285.00", "5.437978"], ["84293.50", "4.441016"], ["84302.00", "4.169117"], ["84310.50", "4.894180"], ["84533.01", "0"]], "bids": [["84034.80", "0.001068"], ["84032.80", "0.002948"], ["84030.80", "0.007758"], ["84028.80", "0.020417"], ["84026.80", "0.053727"], ["84024.80", "0.141389"], ["84022.80", "0.372074"], ["84019.91", "0.618385"], ["84018.10", "0.073170"], ["84011.90", "0"], ["84011.71", "0.078599"], ["83980.80", "5.075446"], ["83972.30", "5.256712"], ["83963.80", "3.987851"], ["83955.30", "4.259750"], ["83946.80", "4.350383"], ["83938.30", "4.803547"], ["83929.80", "5.437978"], ["83921.30", "4.441016"], ["83912.80", "5.166079"], ["83904.30", "4.894180"], ["83895.80", "4.984813"], ["83887.30", "4.078484"], ["83878.80", "4.622282"], ["83870.30", "5.347345"], ["83861.80", "3.897218"], ["83853.30", "5.619244"], ["83844.80", "4.712914"], ["83836.30", "4.169117"], ["83827.80", "5.528611"], ["83819.30", "4.531649"]], "checksum": -49438202, "ts": "1742555207183"}], "ts": 1742555207186, "record_time": 1742555207.229898, "EXCHANGE": "BITGET"}
{"action": "update", "arg": {"instType": "SPOT", "channel": "books", "instId": "BTCUSDT"}, "data": [{"asks": [["84078.22", "0.010000"], ["84105.00", "4.064199"], ["84107.00", "10.695260"], ["84149.00", "4.350383"], ["84157.50", "5.619244"], ["84166.00", "5.347345"], ["84174.50", "3.987851"], ["84183.00", "4.078484"], ["84191.50", "4.622282"], ["84208.50", "3.897218"], ["84217.00", "5.075446"], ["84225.50", "4.803547"], ["84234.00", "5.528611"], ["84242.50", "4.984813"], ["84251.00", "4.894180"], ["84259.50", "4.441016"], ["84268.00", "5.256712"], ["84276.50", "4.531649"], ["84285.00", "4.169117"], ["84293.50", "5.437978"], ["84302.00", "4.712914"], ["84310.50", "5.166079"], ["84530.00", "0"]], "bids": [["84034.80", "0.001432"], ["84032.80", "0.003768"], ["84030.80", "0.009916"], ["84028.80", "0.026093"], ["84026.80", "0.068553"], ["84024.80", "0.180404"], ["84022.80", "0.474746"], ["84018.90", "0.403620"], ["84018.40", "0.284370"], ["84017.70", "0.592530"], ["84016.70", "1.068030"], ["84014.90", "0"], ["83993.00", "0"], ["83992.00", "0.000017"], ["83980.80", "3.987851"], ["83972.30", "4.259750"], ["83963.80", "5.528611"], ["83955.30", "5.437978"], ["83946.80", "5.075446"], ["83938.30", "3.897218"], ["83929.80", "4.350383"], ["83921.30", "4.984813"], ["83912.80", "4.169117"], ["83904.30", "5.619244"], ["83895.80", "4.894180"], ["83887.30", "4.712914"], ["83870.30", "5.256712"], ["83861.80", "4.531649"], ["83853.30", "4.078484"], ["83844.80", "5.166079"], ["83836.30", "4.803547"], ["83827.80", "5.347345"], ["83819.30", "4.441016"]], "checksum": -1316930599, "ts": "1742555207384"}], "ts": 1742555207386, "record_time": 1742555207.407649, "EXCHANGE": "BITGET"}
{"action": "update", "arg": {"instType": "SPOT", "channel": "books", "instId": "BTCUSDT"}, "data": [{"asks": [["84043.15", "0.086888"], ["84043.16", "0"], ["84149.00", "4.441016"], ["84157.50", "5.437978"], ["84166.00", "3.987851"], ["84174.50", "4.259750"], ["84183.00", "5.619244"], ["84191.50", "5.166079"], ["84200.00", "4.531649"], ["84208.50", "4.803547"], ["84217.00", "4.984813"], ["84225.50", "5.256712"], ["84234.00", "4.078484"], ["84242.50", "3.897218"], ["84251.00", "5.075446"], ["84259.50", "5.347345"], ["84268.00", "5.528611"], ["84276.50", "4.350383"], ["84285.00", "4.622282"], ["84293.50", "4.894180"], ["84310.50", "4.169117"]], "bids": [["84038.11", "0"], ["84034.80", "0.001554"], ["84032.80", "0.004089"], ["84030.80", "0.010760"], ["84028.80", "0.028316"], ["84026.80", "0.074516"], ["84024.80", "0.196095"], ["84022.80", "0.516038"], ["83980.80", "4.984813"], ["83972.30", "3.897218"], ["83963.80", "3.987851"], ["83955.30", "4.441016"], ["83946.80", "5.528611"], ["83938.30", "5.075446"], ["83929.80", "4.078484"], ["83921.30", "5.347345"], ["83912.80", "4.531649"], ["83904.30", "4.259750"], ["83895.80", "4.803547"], ["83887.30", "4.622282"], ["83878.80", "4.169117"], ["83870.30", "5.437978"], ["83861.80", "5.619244"], ["83853.30", "5.166079"], ["83844.80", "5.256712"], ["83836.30", "4.894180"], ["83827.80", "4.712914"], ["83819.30", "4.350383"], ["83660.71", "0.000309"]], "checksum": -1382136081, "ts": "1742555207589"}], "ts": 1742555207593, "record_time": 1742555207.618891, "EXCHANGE": "BITGET"}
{"action": "update", "arg": {"instType": "SPOT", "channel": "books", "instId": "BTCUSDT"}, "data": [{"asks": [["84078.74", "0.000181"], ["84149.00", "5.437978"], ["84157.50", "4.078484"], ["84166.00", "4.531649"], ["84174.50", "4.350383"], ["84183.00", "4.169117"], ["84191.50", "5.075446"], ["84200.00", "5.619244"], ["84208.50", "5.347345"], ["84217.00", "5.528611"], ["84225.50", "4.803547"], ["84234.00", "4.984813"], ["84242.50", "3.987851"], ["84251.00", "4.712914"], ["84259.50", "4.441016"], ["84268.00", "4.622282"], ["84276.50", "3.897218"], ["84285.00", "5.256712"], ["84302.00", "5.166079"], ["84310.50", "4.259750"], ["84528.57", "0"]], "bids": [["84037.96", "0.027859"], ["84034.80", "0.001146"], ["84032.80", "0.003016"], ["84031.99", "0.010000"], ["84030.80", "0.007938"], ["84028.80", "0.020890"], ["84026.80", "0.054974"], ["84024.80", "0.144668"], ["84022.80", "0.380965"], ["84014.80", "0.071070"], ["84012.00", "0.120000"], ["83980.80", "4.441016"], ["83972.30", "5.256712"], ["83963.80", "4.803547"], ["83955.30", "4.350383"], ["83946.80", "3.897218"], ["83938.30", "5.437978"], ["83929.80", "5.528611"], ["83921.30", "4.984813"], ["83912.80", "4.169117"], ["83895.80", "3.987851"], ["83887.30", "5.347345"], ["83878.80", "5.166079"], ["83870.30", "4.622282"], ["83861.80", "4.894180"], ["83853.30", "4.078484"], ["83844.80", "4.531649"], ["83836.30", "4.712914"], ["83827.80", "5.619244"], ["83819.30", "5.075446"], ["83661.60", "0"], ["83661.08", "0"], ["83660.71", "0"]], "checksum": -761587307, "ts": "1742555207794"}], "ts": 1742555207797, "record_time": 1742555207.871932, "EXCHANGE": "BITGET"}
{"action": "update", "arg": {"instType": "SPOT", "channel": "books", "instId": "BTCUSDT"}, "data": [{"asks": [["84091.00", "0.004528"], ["84093.00", "0.011916"], ["84095.00", "0.031359"], ["84097.00", "0.082524"], ["84099.00", "0.217167"], ["84101.00", "0.571492"], ["84103.00", "1.503928"], ["84105.00", "3.957706"], ["84107.00", "10.415014"], ["84149.00", "4.803547"], ["84157.50", "4.894180"], ["84166.00", "4.259750"], ["84174.50", "5.528611"], ["84183.00", "4.712914"], ["84191.50", "4.622282"], ["84200.00", "4.169117"], ["84208.50", "4.984813"], ["84217.00", "5.347345"], ["84225.50", "4.441016"], ["84234.00", "3.987851"], ["84242.50", "4.531649"], ["84251.00", "5.075446"], ["84259.50", "5.619244"], ["84268.00", "5.256712"], ["84276.50", "4.350383"], ["84285.00", "5.437978"], ["84293.50", "3.897218"], ["84310.50", "4.078484"]], "bids": [["84032.80", "0.002869"], ["84030.80", "0.007550"], ["84028.80", "0.019869"], ["84026.80", "0.052288"], ["84024.80", "0.137600"], ["84022.80", "0.362105"], ["83993.00", "0.000015"], ["83991.00", "0.000032"], ["83980.80", "5.619244"], ["83972.30", "4.259750"], ["83963.80", "4.622282"], ["83955.30", "4.169117"], ["83946.80", "4.712914"], ["83938.30", "5.075446"], ["83929.80", "4.078484"], ["83921.30", "5.528611"], ["83912.80", "4.531649"], ["83904.30", "4.441016"], ["83895.80", "5.256712"], ["83887.30", "3.987851"], ["83878.80", "4.984813"], ["83870.30", "4.803547"], ["83861.80", "5.166079"], ["83853.30", "5.437978"], ["83844.80", "3.897218"], ["83836.30", "4.894180"], ["83827.80", "4.350383"], ["83819.30", "5.347345"], ["83661.97", "0"]], "checksum": -1642535645, "ts": "1742555207997"}], "ts": 1742555208001, "record_time": 1742555208.24312, "EXCHANGE": "BITGET"}
{"action": "update", "arg": {"instType": "SPOT", "channel": "books", "instId": "BTCUSDT"}, "data": [{"asks": [["84043.01", "2.355144"], ["84084.14", "0.043725"], ["84105.00", "3.957571"], ["84107.00", "10.414661"], ["84149.00", "4.441016"], ["84157.50", "3.987851"], ["84166.00", "5.347345"], ["84174.50", "4.984813"], ["84183.00", "4.803547"], ["84191.50", "5.619244"], ["84200.00", "5.256712"], ["84208.50", "4.078484"], ["84217.00", "5.166079"], ["84225.50", "5.075446"], ["84234.00", "4.712914"], ["84242.50", "4.350383"], ["84251.00", "4.259750"], ["84259.50", "4.894180"], ["84268.00", "5.528611"], ["84276.50", "3.897218"], ["84285.00", "4.622282"], ["84293.50", "4.531649"], ["84302.00", "4.169117"], ["84310.50", "5.437978"]], "bids": [["84043.00", "0.560630"], ["84037.96", "0"], ["84034.80", "0.001039"], ["84032.80", "0.002734"], ["84030.80", "0.007194"], ["84028.80", "0.018932"], ["84026.80", "0.049819"], ["84024.80", "0.131105"], ["84022.80", "0.344825"], ["84021.90", "0.371970"], ["84018.90", "0.403410"], ["84012.00", "0.000032"], ["83980.80", "4.894180"], ["83972.30", "5.166079"], ["83963.80", "3.987851"], ["83955.30", "4.984813"], ["83946.80", "4.622282"], ["83938.30", "4.169117"], ["83929.80", "4.441016"], ["83921.30", "5.075446"], ["83912.80", "4.078484"], ["83904.30", "4.531649"], ["83895.80", "5.619244"], ["83887.30", "4.803547"], ["83878.80", "3.897218"], ["83870.30", "4.712914"], ["83861.80", "4.350383"], ["83844.80", "4.259750"], ["83836.30", "5.528611"], ["83827.80", "5.347345"], ["83819.30", "5.256712"], ["83661.97", "0.000052"]], "checksum": -1766067493, "ts": "1742555208209"}], "ts": 1742555208212, "record_time": 1742555208.262674, "EXCHANGE": "BITGET"}
{"action": "update", "arg": {"instType": "SPOT", "channel": "books", "instId": "BTCUSDT"}, "data": [{"asks": [["84043.01", "2.348351"], ["84063.20", "0"], ["84063.21", "0.035952"], ["84064.85", "0"], ["84064.86", "0.035961"], ["84065.28", "0"], ["84065.29", "0.006356"], ["84065.43", "0"], ["84065.45", "0.006356"], ["84065.78", "0"], ["84065.79", "0.006356"], ["84066.89", "0"], ["84066.90", "0.010984"], ["84067.82", "0"], ["84067.83", "0.006356"], ["84068.30", "0"], ["84068.31", "0.006356"], ["84068.33", "0"], ["84068.34", "0.006356"], ["84068.63", "0"], ["84068.65", "0.119883"], ["84068.66", "0"], ["84068.67", "0.016429"], ["84068.80", "0"], ["84068.82", "0.006356"], ["84070.29", "0"], ["84070.32", "0.006357"], ["84070.33", "0.010985"], ["84071.18", "0"], ["84071.19", "0.009990"], ["84073.09", "0"], ["84073.11", "0.119858"], ["84073.24", "0"], ["84073.26", "0.119867"], ["84073.54", "0"], ["84073.55", "0.015895"], ["84073.67", "0"], ["84073.70", "0.009989"], ["84077.47", "0"], ["84077.49", "0.015892"], ["84078.33", "0"], ["84078.34", "0.010988"], ["84084.14", "0.234973"], ["84109.50", "0"], ["84149.00", "4.894180"], ["84157.50", "4.259750"], ["84166.00", "5.166079"], ["84174.50", "4.531649"], ["84183.00", "4.441016"], ["84191.50", "4.078484"], ["84200.00", "5.528611"], ["84208.50", "3.987851"], ["84217.00", "4.169117"], ["84225.50", "4.803547"], ["84234.00", "5.347345"], ["84242.50", "5.256712"], ["84251.00", "4.622282"], ["84259.50", "4.350383"], ["84268.00", "5.437978"], ["84276.50", "5.075446"], ["84285.00", "4.712914"], ["84293.50", "5.619244"], ["84302.00", "4.984813"], ["84310.50", "3.897218"], ["84528.57", "0.000008"]], "bids": [["84039.34", "0.027859"], ["84022.87", "0.089506"], ["84022.86", "0"], ["84022.80", "0.345011"], ["84021.16", "0.083960"], ["84021.15", "0"], ["84020.75", "0.017821"], ["84020.74", "0"], ["84020.57", "0.018259"], ["84020.55", "0"], ["84020.24", "0.005948"], ["84020.23", "0"], ["84019.16", "0.055669"], ["84019.15", "0"], ["84018.24", "0.007341"], ["84018.23", "0"], ["84017.80", "1.064970"], ["84017.74", "0.007945"], ["84017.73", "0"], ["84017.72", "0.008996"], ["84017.71", "0"], ["84017.70", "0.210780"], ["84017.41", "0.025190"], ["84017.40", "0"], ["84017.39", "0.224937"], ["84017.37", "0"], ["84017.22", "0.025542"], ["84017.20", "0"], ["84016.70", "0"], ["84015.70", "0.051976"], ["84015.69", "0.012658"], ["84015.67", "0"], ["84014.88", "0.018521"], ["84014.87", "0"], ["84012.93", "0.222723"], ["84012.91", "0"], ["84012.73", "0"], ["84012.53", "0.076131"], ["84012.52", "0"], ["84012.34", "0.021135"], ["84012.32", "0"], ["84008.58", "0.073233"], ["84008.56", "0"], ["84007.74", "0.056381"], ["84007.73", "0"], ["84006.05", "0"], ["84006.04", "0.000877"], ["83987.58", "0.003598"], ["83987.57", "0"], ["83980.80", "3.987851"], ["83972.30", "4.078484"], ["83963.80", "3.897218"], ["83955.30", "5.437978"], ["83938.30", "5.619244"], ["83929.80", "5.166079"], ["83921.30", "5.528611"], ["83912.80", "5.075446"], ["83904.30", "5.256712"], ["83895.80", "4.350383"], ["83887.30", "4.894180"], ["83878.80", "4.169117"], ["83870.30", "4.803547"], ["83861.80", "4.531649"], ["83853.30", "5.347345"], ["83836.30", "4.441016"], ["83827.80", "4.984813"], ["83819.30", "4.712914"]], "checksum": 722427602, "ts": "1742555208411"}], "ts": 1742555208415, "record_time": 1742555208.449923, "EXCHANGE": "BITGET"}
{"action": "update", "arg": {"instType": "SPOT", "channel": "books", "instId": "BTCUSDT"}, "data": [{"asks": [["84043.14", "0.086888"], ["84043.15", "0"], ["84157.50", "4.078484"], ["84166.00", "4.712914"], ["84174.50", "5.619244"], ["84183.00", "5.166079"], ["84191.50", "4.441016"], ["84200.00", "4.350383"], ["84208.50", "4.803547"], ["84217.00", "5.075446"], ["84225.50", "5.528611"], ["84234.00", "4.984813"], ["84242.50", "4.531649"], ["84251.00", "3.897218"], ["84259.50", "5.347345"], ["84268.00", "4.259750"], ["84276.50", "5.437978"], ["84285.00", "3.987851"], ["84293.50", "4.169117"], ["84302.00", "5.256712"], ["84310.50", "4.622282"]], "bids": [["84043.00", "0.560558"], ["84034.80", "0.001352"], ["84032.80", "0.003558"], ["84030.80", "0.009362"], ["84028.80", "0.024637"], ["84026.80", "0.064833"], ["84024.80", "0.170615"], ["84022.80", "0.448985"], ["84018.10", "0"], ["84014.80", "0"], ["84012.75", "0.259859"], ["83980.80", "4.441016"], ["83972.30", "4.984813"], ["83963.80", "5.075446"], ["83955.30", "4.078484"], ["83938.30", "4.712914"], ["83929.80", "5.437978"], ["83921.30", "4.894180"], ["83912.80", "5.619244"], ["83904.30", "4.259750"], ["83895.80", "5.347345"], ["83887.30", "4.803547"], ["83878.80", "5.256712"], ["83870.30", "4.531649"], ["83861.80", "3.897218"], ["83853.30", "4.169117"], ["83844.80", "5.528611"], ["83836.30", "4.350383"], ["83827.80", "5.166079"], ["83819.30", "3.987851"], ["83661.60", "0.000042"]], "checksum": -559621117, "ts": "1742555208614"}], "ts": 1742555208619, "record_time": 1742555208.656636, "EXCHANGE": "BITGET"}
{"action": "update", "arg": {"instType": "SPOT", "channel": "books", "instId": "BTCUSDT"}, "data": [{"asks": [["84115.10", "0.021870"], ["84149.00", "4.441016"], ["84157.50", "5.619244"], ["84166.00", "5.166079"], ["84174.50", "4.078484"], ["84183.00", "4.984813"], ["84191.50", "4.169117"], ["84200.00", "5.437978"], ["84208.50", "4.531649"], ["84217.00", "4.894180"], ["84225.50", "5.075446"], ["84234.00", "4.350383"], ["84242.50", "3.987851"], ["84251.00", "5.528611"], ["84259.50", "4.259750"], ["84268.00", "4.803547"], ["84276.50", "4.712914"], ["84285.00", "4.622282"], ["84293.50", "5.347345"], ["84310.50", "3.897218"]], "bids": [["84034.80", "0.001065"], ["84032.80", "0.002802"], ["84030.80", "0.007374"], ["84028.80", "0.019405"], ["84026.80", "0.050832"], ["84024.80", "0.133769"], ["84022.80", "0.352024"], ["84018.50", "0"], ["84017.70", "0"], ["84017.60", "0"], ["84015.10", "0.165540"], ["84012.00", "0.654660"], ["83992.00", "0"], ["83991.00", "0.000017"], ["83980.80", "4.531649"], ["83972.30", "4.622282"], ["83963.80", "3.987851"], ["83955.30", "5.528611"], ["83946.80", "4.259750"], ["83938.30", "4.078484"], ["83929.80", "4.441016"], ["83921.30", "4.984813"], ["83912.80", "4.350383"], ["83904.30", "4.712914"], ["83895.80", "5.075446"], ["83887.30", "5.437978"], ["83878.80", "3.897218"], ["83870.30", "5.256712"], ["83861.80", "5.619244"], ["83853.30", "4.894180"], ["83844.80", "4.169117"], ["83836.30", "5.347345"], ["83819.30", "4.803547"], ["83661.08", "0.004152"], ["83660.71", "0.000309"], ["83660.14", "0.000016"], ["83660.00", "0.001273"]], "checksum": -1476171521, "ts": "1742555208813"}], "ts": 1742555208815, "record_time": 1742555208.924525, "EXCHANGE": "BITGET"}
{"action": "update", "arg": {"instType": "SPOT", "channel": "books", "instId": "BTCUSDT"}, "data": [{"asks": [["84043.01", "2.345992"], ["84089.00", "0.001670"], ["84091.00", "0.004395"], ["84093.00", "0.011566"], ["84095.00", "0.030436"], ["84097.00", "0.080095"], ["84099.00", "0.210778"], ["84101.00", "0.554679"], ["84103.00", "1.459682"], ["84105.00", "3.841267"], ["84107.00", "10.108598"], ["84149.00", "5.619244"], ["84157.50", "5.075446"], ["84166.00", "5.528611"], ["84174.50", "3.897218"], ["84183.00", "4.350383"], ["84191.50", "4.259750"], ["84200.00", "3.987851"], ["84208.50", "4.078484"], ["84217.00", "4.169117"], ["84225.50", "4.441016"], ["84234.00", "5.437978"], ["84242.50", "5.166079"], ["84251.00", "4.622282"], ["84259.50", "5.256712"], ["84268.00", "4.894180"], ["84276.50", "5.347345"], ["84285.00", "4.712914"], ["84293.50", "4.803547"], ["84302.00", "4.531649"], ["84310.50", "4.984813"]], "bids": [["84039.34", "0"], ["83980.80", "4.259750"], ["83972.30", "4.078484"], ["83963.80", "4.984813"], ["83955.30", "4.712914"], ["83946.80", "3.897218"], ["83938.30", "4.803547"], ["83929.80", "5.619244"], ["83921.30", "5.528611"], ["83912.80", "4.894180"], ["83904.30", "4.622282"], ["83895.80", "5.347345"], ["83887.30", "5.075446"], ["83878.80", "4.350383"], ["83870.30", "5.437978"], ["83861.80", "5.166079"], ["83853.30", "5.256712"], ["83844.80", "4.531649"], ["83836.30", "3.987851"], ["83827.80", "4.441016"], ["83819.30", "4.169117"], ["83659.61", "0.000454"]], "checksum": 2078311573, "ts": "1742555209023"}], "ts": 1742555209025, "record_time": 1742555209.118947, "EXCHANGE": "BITGET"}
{"action": "update", "arg": {"instType": "SPOT", "channel": "books", "instId": "BTCUSDT"}, "data": [{"asks": [["84052.24", "0"], ["84091.00", "0.004528"], ["84093.00", "0.011916"], ["84095.00", "0.031358"], ["84097.00", "0.082521"], ["84099.00", "0.217161"], ["84101.00", "0.571474"], ["84103.00", "1.503880"], ["84105.00", "3.957578"], ["84107.00", "10.414679"], ["84149.00", "3.987851"], ["84157.50", "5.256712"], ["84166.00", "5.619244"], ["84174.50", "5.528611"], ["84191.50", "4.169117"], ["84200.00", "4.259750"], ["84208.50", "5.347345"], ["84217.00", "4.441016"], ["84225.50", "4.531649"], ["84234.00", "5.166079"], ["84242.50", "4.894180"], ["84251.00", "4.803547"], ["84259.50", "3.897218"], ["84268.00", "5.075446"], ["84276.50", "4.984813"], ["84293.50", "4.622282"], ["84302.00", "4.078484"], ["84310.50", "5.437978"], ["84530.00", "0.000031"]], "bids": [["84040.39", "0.027859"], ["84034.80", "0.001373"], ["84032.80", "0.003613"], ["84030.80", "0.009508"], ["84028.80", "0.025021"], ["84026.80", "0.065846"], ["84024.80", "0.173279"], ["84022.80", "0.455998"], ["83980.80", "4.894180"], ["83972.30", "3.987851"], ["83963.80", "5.256712"], ["83955.30", "5.347345"], ["83946.80", "4.078484"], ["83938.30", "5.619244"], ["83929.80", "4.984813"], ["83921.30", "5.075446"], ["83912.80", "4.712914"], ["83904.30", "5.528611"], ["83895.80", "4.169117"], ["83887.30", "4.622282"], ["83878.80", "4.441016"], ["83870.30", "5.166079"], ["83861.80", "4.259750"], ["83853.30", "3.897218"], ["83844.80", "4.803547"], ["83836.30", "5.437978"], ["83827.80", "4.531649"], ["83819.30", "4.350383"], ["83659.61", "0"]], "checksum": 934091711, "ts": "1742555209226"}], "ts": 1742555209234, "record_time": 1742555209.257432, "EXCHANGE": "BITGET"}
{"action": "update", "arg": {"instType": "SPOT", "channel": "books", "instId": "BTCUSDT"}, "data": [{"asks": [["84049.98", "0.314136"], ["84051.00", "0.066888"], ["84077.23", "0"], ["84110.09", "0.085876"], ["84149.00", "5.528611"], ["84166.00", "5.166079"], ["84174.50", "4.169117"], ["84183.00", "4.078484"], ["84191.50", "4.984813"], ["84200.00", "4.894180"], ["84208.50", "4.803547"], ["84217.00", "3.987851"], ["84225.50", "4.350383"], ["84234.00", "5.437978"], ["84242.50", "4.622282"], ["84251.00", "5.075446"], ["84268.00", "5.347345"], ["84276.50", "4.259750"], ["84285.00", "4.441016"], ["84293.50", "5.619244"], ["84302.00", "4.531649"], ["84310.50", "4.712914"], ["84530.00", "0"]], "bids": [["84043.00", "0.559358"], ["83993.00", "0.000032"], ["83992.00", "0.000015"], ["83980.80", "4.441016"], ["83972.30", "5.347345"], ["83963.80", "4.259750"], ["83955.30", "4.984813"], ["83946.80", "3.987851"], ["83938.30", "4.078484"], ["83929.80", "4.531649"], ["83921.30", "5.528611"], ["83912.80", "5.437978"], ["83904.30", "4.622282"], ["83895.80", "4.803547"], ["83887.30", "4.894180"], ["83878.80", "5.075446"], ["83870.30", "5.256712"], ["83861.80", "5.619244"], ["83844.80", "4.169117"], ["83836.30", "4.712914"], ["83827.80", "4.350383"], ["83819.30", "5.166079"], ["83660.00", "0"]], "checksum": -1115010471, "ts": "1742555209429"}], "ts": 1742555209433, "record_time": 1742555209.488666, "EXCHANGE": "BITGET"}
{"event": "subscribe", "arg": {"instType": "SPOT", "channel": "books", "instId": "BTCUSDT"}, "record_time": 1742555346.381744, "EXCHANGE": "BITGET"}
{"action": "snapshot", "arg": {"instType": "SPOT", "channel": "books", "instId": "BTCUSDT"}, "data": [{"asks": [["84029.41", "0.333467"], ["84029.42", "0.000100"], ["84029.43", "0.000100"], ["84029.44", "0.000100"], ["84030.49", "0.088149"], ["84030.70", "0.136319"], ["84036.96", "0.054750"], ["84037.81", "0.000221"], ["84040.67", "0.013964"], ["84040.69", "0.112637"], ["84041.67", "0.000357"], ["84041.92", "0.000679"], ["84041.93", "0.007162"], ["84041.96", "0.000865"], ["84041.97", "0.009407"], ["84042.03", "0.006601"], ["84042.04", "0.006307"], ["84046.22", "0.072066"], ["84046.23", "0.209200"], ["84051.72", "0.035952"], ["84052.15", "0.119870"], ["84053.09", "0.478871"], ["84053.10", "0.017457"], ["84053.42", "0.035961"], ["84053.76", "1.531031"], ["84053.84", "0.006356"], ["84054.07", "0.006356"], ["84054.34", "0.006356"], ["84054.81", "0.225089"], ["84054.82", "0.314141"], ["84055.41", "0.010984"], ["84055.70", "0.006356"], ["84055.85", "0.006356"], ["84056.35", "0.006356"], ["84056.40", "0.016429"], ["84056.52", "0.209200"], ["84056.86", "0.006356"], ["84056.87", "0.006356"], ["84057.19", "0.016429"], ["84057.22", "0.119883"], ["84057.37", "0.006356"], ["84057.38", "0.006356"], ["84058.88", "0.010985"], ["84058.93", "0.006357"], ["84059.01", "0.132230"], ["84059.72", "0.009990"], ["84060.00", "0.002000"], ["84060.65", "0.119850"], ["84061.66", "0.119858"], ["84061.74", "0.119867"], ["84062.01", "0.015895"], ["84062.17", "0.164200"], ["84062.24", "0.009989"], ["84065.95", "0.008064"], ["84065.96", "0.015892"], ["84066.85", "0.010988"], ["84069.00", "0.074566"], ["84069.01", "0.209200"], ["84071.21", "0.012472"], ["84075.66", "0.062760"], ["84079.68", "0.209200"], ["84080.97", "0.182950"], ["84081.74", "0.773683"], ["84081.75", "3.570943"], ["84083.40", "0.001019"], ["84085.39", "0.004110"], ["84085.40", "0.001052"], ["84087.14", "0.010000"], ["84087.33", "0.001598"], ["84087.40", "0.001045"], ["84089.27", "0.001597"], ["84089.40", "0.001004"], ["84090.00", "0.002000"], ["84090.73", "0.011625"], ["84090.74", "0.713514"], ["84091.40", "0.001008"], ["84093.40", "0.002016"], ["84095.00", "0.001000"], ["84095.07", "0.209200"], ["84095.40", "0.005305"], ["84097.40", "0.013846"], ["84099.40", "0.036194"], ["84099.85", "0.402805"], ["84100.00", "0.004910"], ["84101.40", "0.095248"], ["84103.40", "0.250654"], ["84103.48", "0.209200"], ["84103.80", "0.006060"], ["84104.20", "0.001044"], ["84104.40", "0.001024"], ["84105.70", "0.007050"], ["84105.90", "0.001025"], ["84106.70", "0.515880"], ["84107.00", "0.072900"], ["84107.60", "0.901680"], ["84108.10", "0.067980"], ["84108.50", "2.356410"], ["84109.90", "0.402840"], ["84110.10", "0.067800"], ["84110.30", "0.022620"], ["84111.10", "0.009000"], ["84111.40", "0.135780"], ["84111.69", "0.030264"], ["84111.70", "0.576870"], ["84112.10", "0.067800"], ["84112.20", "0.066210"], ["84112.30", "1.069890"], ["84112.60", "0.071520"], ["84112.90", "0.000958"], ["84113.40", "0.003296"], ["84113.41", "0.209200"], ["84113.50", "0.012330"], ["84114.10", "0.067800"], ["84115.30", "0.420000"], ["84115.80", "0.090000"], ["84116.00", "0.035670"], ["84116.40", "2.723370"], ["84116.60", "0.320310"], ["84116.90", "0.015120"], ["84117.10", "0.107070"], ["84118.70", "0.203926"], ["84119.24", "1.783183"], ["84120.00", "0.002000"], ["84126.22", "0.209200"], ["84137.08", "0.000039"], ["84145.40", "4.169293"], ["84145.50", "0.209200"], ["84148.72", "0.001810"], ["84150.00", "0.002064"], ["84153.90", "4.350566"], ["84157.13", "0.003620"], ["84160.20", "0.308828"], ["84162.40", "4.531840"], ["84163.21", "0.125658"], ["84163.36", "0.071253"], ["84164.83", "0.071045"], ["84169.99", "0.209200"], ["84170.90", "5.256934"], ["84171.60", "0.001428"], ["84174.51", "0.000388"], ["84178.41", "0.209200"], ["84178.87", "0.057001"], ["84179.40", "4.803750"], ["84180.00", "0.002000"], ["84186.81", "0.209200"], ["84187.90", "3.988019"], ["84188.00", "0.000202"], ["84195.21", "0.209200"], ["84196.40", "4.622477"], ["84203.61", "0.209200"], ["84204.90", "5.075661"], ["84210.00", "0.002000"], ["84210.70", "0.311078"], ["84212.01", "0.209200"], ["84213.40", "5.619481"], ["84213.46", "0.000163"], ["84216.00", "0.001184"], ["84220.41", "0.209200"], ["84221.90", "5.438208"], ["84222.00", "0.001469"], ["84223.75", "0.010000"], ["84226.33", "0.024945"], ["84228.81", "0.209200"], ["84230.40", "4.441203"], ["84232.06", "0.011010"], ["84233.38", "0.001273"], ["84234.12", "0.000044"], ["84237.21", "0.209200"], ["84238.90", "4.985024"], ["84240.00", "0.002000"], ["84240.71", "0.164840"], ["84245.00", "0.000149"], ["84247.40", "4.259930"], ["84250.00", "0.000684"], ["84252.44", "0.000143"], ["84252.70", "0.307896"], ["84253.92", "0.209200"], ["84255.90", "5.166297"], ["84259.99", "0.000017"], ["84262.10", "0.001403"], ["84264.40", "4.894387"], ["84266.08", "0.000016"], ["84266.67", "0.000078"], ["84269.24", "0.000032"], ["84270.00", "0.002692"], ["84270.70", "0.209200"], ["84270.98", "0.000052"], ["84272.72", "0.000105"], ["84272.90", "3.897382"], ["84275.00", "0.000671"], ["84278.39", "0.001720"], ["84279.10", "0.209200"], ["84280.00", "0.000077"], ["84281.40", "4.713114"], ["84285.00", "0.000031"], ["84285.71", "0.000010"], ["84285.95", "0.000028"], ["84286.79", "0.000016"], ["84287.50", "0.209276"], ["84288.89", "0.000361"], ["84289.90", "5.528845"], ["84294.68", "0.000019"], ["84295.90", "0.209200"], ["84297.06", "0.000035"], ["84298.40", "5.347571"], ["84300.00", "0.023631"], ["84304.31", "0.209200"], ["84306.90", "4.078656"], ["84307.00", "0.000113"], ["84307.23", "0.000008"], ["84309.09", "0.000010"], ["84310.34", "0.000331"], ["84310.35", "0.000146"], ["84311.11", "0.000025"], ["84312.50", "0.000125"], ["84312.72", "0.209200"], ["84313.03", "0.000024"], ["84314.97", "0.000008"], ["84316.67", "0.000322"], ["84317.24", "0.000135"], ["84317.40", "0.000010"], ["84318.59", "0.000027"], ["84319.15", "0.000137"], ["84319.18", "0.000039"], ["84320.00", "0.000019"], ["84321.13", "0.209200"], ["84322.11", "0.000008"], ["84324.32", "0.000059"], ["84325.00", "0.002294"], ["84325.07", "0.000161"], ["84326.09", "0.000010"], ["84326.42", "0.000023"], ["84327.14", "0.000039"], ["84327.73", "0.041940"], ["84328.95", "0.000174"], ["84329.54", "0.209200"], ["84329.64", "0.000026"], ["84330.00", "0.002000"], ["84332.00", "0.000008"], ["84333.33", "0.002262"], ["84333.36", "0.000010"], ["84333.38", "0.000008"], ["84334.48", "0.000096"], ["84334.77", "0.000022"], ["84336.00", "0.000133"], ["84336.23", "0.000013"], ["84336.29", "0.000010"], ["84336.34", "0.000176"], ["84337.25", "0.000067"], ["84337.35", "0.000008"], ["84338.46", "0.000015"], ["84339.21", "0.000010"], ["84339.29", "0.000029"], ["84339.62", "0.000051"], ["84340.00", "0.018287"], ["84340.72", "0.000066"], ["84341.01", "0.000008"], ["84342.11", "0.000051"], ["84342.63", "0.000009"], ["84342.70", "0.000423"], ["84343.07", "0.000014"], ["84343.70", "0.000075"], ["84343.75", "0.000012"], ["84343.97", "0.000188"], ["84345.00", "0.000403"], ["84346.43", "0.000128"], ["84346.94", "0.000085"], ["84347.69", "0.000009"], ["84347.83", "0.016818"], ["84348.21", "0.000036"], ["84348.27", "0.012402"], ["84348.62", "0.000072"], ["84350.00", "0.002253"], ["84350.79", "0.000033"], ["84354.58", "0.000115"], ["84354.64", "0.000018"], ["84354.82", "0.000078"], ["84354.84", "0.000194"], ["84356.98", "0.000048"], ["84357.14", "0.000273"], ["84358.29", "0.000024"], ["84359.83", "0.000010"], ["84360.00", "0.003600"], ["84363.63", "0.000057"], ["84363.64", "0.000078"], ["84366.14", "0.000162"], ["84366.15", "0.000061"], ["84366.19", "0.000022"], ["84366.60", "0.000011"], ["84366.96", "0.000018"], ["84367.10", "0.000014"], ["84367.82", "0.000476"], ["84368.38", "0.000009"], ["84368.42", "0.000284"], ["84370.00", "0.000052"], ["84370.59", "0.000071"], ["84370.97", "0.000020"], ["84371.86", "0.000012"], ["84375.00", "0.004006"], ["84376.31", "0.000016"], ["84378.11", "0.000008"], ["84378.38", "0.000009"], ["84378.45", "0.000015"], ["84380.00", "0.032216"], ["84381.82", "0.000008"], ["84382.00", "0.000035"], ["84382.35", "0.000071"], ["84383.41", "0.000053"], ["84383.69", "0.000248"], ["84384.38", "0.000424"], ["84384.61", "0.000008"], ["84386.19", "0.000019"], ["84386.67", "0.000013"], ["84387.50", "0.006969"], ["84387.76", "0.000024"], ["84389.61", "0.000088"], ["84389.90", "0.000012"], ["84390.00", "0.002000"], ["84390.01", "0.000387"], ["84391.30", "0.000018"], ["84393.31", "0.000050"], ["84396.55", "0.000016"], ["84396.98", "0.007500"], ["84397.57", "1.660014"], ["84397.59", "0.000008"], ["84397.69", "0.000275"], ["84398.26", "0.000068"], ["84399.54", "0.000030"], ["84399.91", "0.000018"], ["84399.99", "0.000022"], ["84400.00", "0.060615"], ["84400.18", "0.000024"], ["84402.40", "0.001273"], ["84403.39", "0.000023"], ["84403.76", "0.000099"], ["84403.98", "0.007500"], ["84404.26", "0.000137"], ["84404.28", "0.000039"], ["84404.90", "0.493801"], ["84405.00", "0.000402"], ["84406.06", "0.000008"], ["84406.83", "0.000064"], ["84407.50", "0.000031"], ["84410.00", "0.000059"], ["84410.04", "0.000025"], ["84411.11", "0.000361"], ["84411.43", "0.000008"], ["84411.76", "0.000101"], ["84411.77", "0.000020"], ["84412.50", "0.000049"], ["84413.04", "0.000010"], ["84413.33", "0.000073"], ["84413.79", "0.000135"], ["84414.29", "0.000074"], ["84414.41", "0.000051"], ["84415.09", "0.000008"], ["84416.67", "0.000355"], ["84418.34", "0.000046"], ["84419.69", "0.000023"], ["84419.90", "0.002343"], ["84420.00", "0.002640"], ["84420.17", "0.041940"], ["84422.71", "0.000010"], ["84423.08", "0.000067"], ["84423.53", "0.000105"], ["84424.00", "0.000022"], ["84424.12", "0.000146"], ["84425.00", "0.002205"], ["84425.69", "0.000314"], ["84426.68", "0.000101"], ["84427.08", "0.000014"], ["84427.92", "0.000323"], ["84428.57", "0.000057"], ["84429.82", "0.000022"], ["84430.50", "0.000113"], ["84430.74", "0.000010"], ["84430.77", "0.000015"], ["84431.23", "0.000039"], ["84432.43", "0.000008"], ["84433.33", "0.000347"], ["84434.78", "0.000008"], ["84435.26", "0.000161"], ["84436.26", "0.000009"], ["84437.14", "0.000017"], ["84437.50", "0.000725"], ["84437.75", "0.000013"], ["84438.44", "0.000176"], ["84440.00", "0.000544"], ["84442.54", "0.000096"], ["84443.07", "0.000423"], ["84444.25", "0.000013"], ["84444.41", "0.000371"], ["84444.44", "0.000574"], ["84444.92", "0.000022"], ["84446.04", "0.000016"], ["84446.38", "0.000013"], ["84446.43", "0.000036"], ["84447.80", "0.000718"], ["84448.75", "0.000066"], ["84448.98", "0.000085"], ["84449.11", "0.000028"], ["84449.34", "0.000010"], ["84450.00", "0.010457"], ["84451.88", "0.000010"], ["84452.66", "0.000009"], ["84453.76", "0.000054"], ["84454.43", "0.000061"], ["84454.53", "0.000019"], ["84454.55", "0.000083"], ["84454.60", "0.000093"], ["84455.31", "0.000028"], ["84456.14", "0.000033"], ["84456.52", "0.002633"], ["84457.00", "0.000009"], ["84458.06", "0.000020"], ["84458.72", "0.000072"], ["84458.82", "0.000071"], ["84458.97", "0.000153"], ["84459.08", "0.000008"], ["84459.22", "0.000188"], ["84459.69", "0.000051"], ["84460.00", "0.000622"], ["84460.23", "0.000010"], ["84460.49", "0.000009"], ["84460.87", "0.000069"], ["84460.91", "0.000012"], ["84461.00", "0.000008"], ["84462.50", "0.000076"], ["84464.28", "0.000008"], ["84465.83", "0.000016"], ["84466.67", "0.000157"], ["84470.34", "0.000017"], ["84470.59", "0.000071"], ["84473.14", "0.000126"], ["84473.68", "0.000192"], ["84474.78", "0.000099"], ["84475.00", "0.009271"], ["84475.81", "0.000039"], ["84476.97", "0.000063"], ["84477.61", "0.000095"], ["84477.67", "0.000008"], ["84478.74", "0.000036"], ["84479.37", "0.000090"], ["84480.00", "0.003246"], ["84481.00", "0.000069"], ["84481.77", "0.000011"], ["84482.67", "0.000133"], ["84482.76", "0.000016"], ["84485.20", "0.000537"], ["84485.39", "0.000020"], ["84485.71", "0.000128"], ["84485.98", "0.000034"], ["84486.49", "0.000009"], ["84486.82", "0.000135"], ["84487.00", "0.000119"], ["84487.16", "0.000035"], ["84487.32", "0.000024"], ["84487.95", "0.000008"], ["84488.88", "0.000025"], ["84489.36", "0.000137"], ["84489.39", "0.000039"], ["84489.80", "0.000010"], ["84490.00", "0.007510"], ["84490.13", "0.000093"], ["84490.91", "0.000018"], ["84491.26", "0.000008"], ["84491.87", "0.000019"], ["84492.06", "0.000009"], ["84496.43", "0.000273"], ["84496.66", "0.004837"], ["84496.73", "0.000043"], ["84497.14", "0.000008"], ["84497.26", "0.000010"], ["84500.00", "0.124015"], ["84500.03", "0.000010"], ["84500.04", "0.000008"], ["84500.11", "0.000012"], ["84501.24", "0.000010"], ["84501.28", "0.000019"], ["84501.32", "0.000326"], ["84501.99", "0.000009"], ["84503.33", "0.010000"], ["84503.57", "0.000074"], ["84504.50", "0.000051"], ["84504.74", "0.000013"], ["84506.54", "0.000008"], ["84508.00", "0.001210"], ["84508.37", "0.000050"], ["84508.46", "0.000013"], ["84508.47", "0.000023"], ["84510.00", "0.000805"], ["84510.34", "0.000135"], ["84512.00", "0.000012"], ["84512.19", "0.000016"], ["84512.61", "0.041940"], ["84512.95", "0.000023"], ["84514.29", "0.000059"], ["84516.67", "0.000010"], ["84517.54", "0.000022"], ["84517.86", "0.000016"]], "bids": [["84029.40", "1.003449"], ["84029.39", "0.000100"], ["84029.38", "0.006024"], ["84029.37", "0.010106"], ["84029.20", "0.088474"], ["84028.51", "0.007470"], ["84028.49", "0.007798"], ["84028.46", "0.009719"], ["84028.45", "0.008242"], ["84028.44", "0.009592"], ["84028.39", "0.007755"], ["84028.21", "0.190916"], ["84027.20", "0.232826"], ["84027.00", "0.000032"], ["84026.00", "0.000032"], ["84025.23", "0.010340"], ["84025.20", "0.612700"], ["84025.19", "0.008716"], ["84025.00", "0.000032"], ["84024.32", "0.005173"], ["84024.30", "0.005121"], ["84024.26", "0.008539"], ["84024.25", "0.005585"], ["84024.24", "0.009868"], ["84024.23", "0.004829"], ["84024.00", "0.000032"], ["84023.49", "1.282661"], ["84023.20", "1.612369"], ["84023.00", "0.000032"], ["84022.84", "3.053422"], ["84022.00", "0.000032"], ["84021.58", "0.209200"], ["84021.20", "4.243076"], ["84021.00", "0.000032"], ["84020.00", "0.001263"], ["84019.20", "11.165859"], ["84019.15", "0.314146"], ["84019.10", "0.075180"], ["84019.00", "0.006060"], ["84018.90", "0.120000"], ["84018.50", "0.884550"], ["84018.10", "2.596740"], ["84018.00", "0.000032"], ["84017.90", "0.567780"], ["84017.60", "0.066690"], ["84017.00", "0.000032"], ["84016.00", "0.000032"], ["84015.90", "0.139170"], ["84015.80", "0.356880"], ["84015.60", "0.070020"], ["84015.54", "0.006203"], ["84015.20", "0.215850"], ["84015.10", "0.356880"], ["84015.00", "0.000956"], ["84014.70", "0.120000"], ["84014.42", "0.014857"], ["84014.41", "0.005773"], ["84014.40", "0.269760"], ["84014.27", "0.008273"], ["84014.20", "2.943990"], ["84014.00", "0.000032"], ["84013.90", "0.090600"], ["84013.80", "0.120000"], ["84013.40", "0.178440"], ["84013.17", "0.209200"], ["84013.00", "0.178440"], ["84012.90", "0.120000"], ["84012.80", "0.017820"], ["84012.60", "0.008064"], ["84012.50", "0.035850"], ["84012.10", "0.120000"], ["84012.00", "0.000032"], ["84011.90", "0.178440"], ["84011.70", "0.428250"], ["84011.50", "0.120000"], ["84011.39", "0.089521"], ["84011.30", "0.178440"], ["84011.20", "0.793140"], ["84011.00", "0.000032"], ["84010.98", "0.247687"], ["84010.79", "0.000957"], ["84010.00", "0.000032"], ["84009.80", "0.153580"], ["84009.72", "0.083974"], ["84009.31", "0.017824"], ["84009.20", "0.018262"], ["84009.00", "0.000032"], ["84008.79", "0.005949"], ["84008.00", "0.000032"], ["84007.68", "0.055678"], ["84007.46", "0.017110"], ["84007.28", "0.007134"], ["84007.19", "0.008431"], ["84007.11", "0.008019"], ["84007.07", "0.006475"], ["84007.03", "0.008601"], ["84007.00", "0.000032"], ["84006.98", "0.013224"], ["84006.83", "0.028876"], ["84006.78", "0.007342"], ["84006.73", "0.004019"], ["84006.28", "0.008998"], ["84006.27", "0.007946"], ["84006.00", "0.000032"], ["84005.96", "0.224973"], ["84005.93", "0.025195"], ["84005.78", "0.008188"], ["84005.77", "0.017358"], ["84005.54", "0.009215"], ["84005.53", "0.006908"], ["84005.45", "0.007308"], ["84005.00", "0.000032"], ["84004.76", "0.209200"], ["84004.31", "0.012660"], ["84004.26", "0.055959"], ["84004.00", "0.000032"], ["84003.42", "0.018524"], ["84003.00", "0.000032"], ["84002.50", "0.268485"], ["84002.00", "0.000032"], ["84001.50", "0.222759"], ["84001.23", "0.259901"], ["84001.01", "0.076143"], ["84001.00", "0.000032"], ["84000.96", "0.000200"], ["84000.90", "0.021138"], ["84000.00", "0.003139"], ["83999.60", "0.000396"], ["83999.00", "0.000032"], ["83998.42", "0.005055"], ["83998.35", "0.008268"], ["83998.26", "0.008097"], ["83998.00", "0.000032"], ["83997.06", "0.073244"], ["83997.00", "0.000032"], ["83996.27", "0.056390"], ["83996.00", "0.000032"], ["83995.80", "0.923521"], ["83995.00", "0.000032"], ["83994.64", "0.000877"], ["83994.00", "0.000032"], ["83993.00", "0.000032"], ["83992.00", "0.000032"], ["83991.00", "0.000032"], ["83990.00", "0.000032"], ["83989.00", "0.000032"], ["83988.00", "0.000032"], ["83987.55", "0.017457"], ["83987.00", "0.000032"], ["83986.40", "0.209200"], ["83986.00", "0.000032"], ["83985.00", "0.000956"], ["83984.00", "0.000032"], ["83983.00", "0.000032"], ["83982.60", "0.007438"], ["83982.00", "0.000032"], ["83981.00", "0.000032"], ["83980.30", "0.199851"], ["83980.00", "0.001263"], ["83979.75", "0.008575"], ["83979.00", "0.000032"], ["83978.56", "0.007340"], ["83978.50", "0.007252"], ["83978.49", "0.007656"], ["83977.20", "4.985024"], ["83977.08", "0.001176"], ["83976.32", "0.003598"], ["83975.60", "0.209200"], ["83975.15", "0.001173"], ["83972.31", "0.071253"], ["83970.20", "0.000948"], ["83970.00", "0.004067"], ["83968.70", "5.347571"], ["83964.20", "0.209200"], ["83960.20", "5.166297"], ["83960.00", "0.001231"], ["83957.16", "0.071045"], ["83955.00", "0.000924"], ["83951.70", "4.259930"], ["83951.58", "0.057001"], ["83951.10", "0.209200"], ["83950.44", "0.005950"], ["83949.70", "0.001810"], ["83946.24", "0.010010"], ["83943.20", "4.169293"], ["83941.30", "0.003620"], ["83940.00", "0.003231"], ["83938.51", "0.209200"], ["83936.10", "0.012367"], ["83934.70", "5.256934"], ["83926.20", "3.988019"], ["83925.07", "0.209200"], ["83920.00", "0.001231"], ["83919.20", "0.306923"], ["83917.70", "5.438208"], ["83917.50", "0.001459"], ["83915.77", "0.209200"], ["83910.54", "0.125658"], ["83910.00", "0.002924"], ["83909.20", "4.803750"], ["83907.35", "0.209200"], ["83903.24", "0.024945"], ["83900.70", "5.075661"], ["83898.93", "0.209200"], ["83895.00", "0.000924"], ["83892.20", "4.531840"], ["83890.51", "0.209200"], ["83883.70", "4.350566"], ["83882.09", "0.209200"], ["83880.00", "0.003231"], ["83877.01", "0.000023"], ["83876.01", "0.005960"], ["83875.20", "4.713114"], ["83875.16", "0.000179"], ["83875.00", "0.000704"], ["83873.68", "0.209200"], ["83873.52", "0.000135"], ["83868.80", "0.296868"], ["83868.70", "0.001444"], ["83868.39", "0.002014"], ["83866.70", "4.894387"], ["83866.67", "0.002945"], ["83865.27", "0.209200"], ["83865.00", "0.000924"], ["83862.50", "0.006969"], ["83860.29", "0.000041"], ["83860.00", "0.001234"], ["83859.54", "0.000008"], ["83858.20", "3.897382"], ["83857.14", "0.000079"], ["83857.13", "0.000019"], ["83856.86", "0.209200"], ["83856.11", "0.010000"], ["83854.55", "0.000009"], ["83854.17", "0.000020"], ["83852.94", "0.000071"], ["83852.50", "0.000043"], ["83851.85", "0.000011"], ["83851.84", "0.000219"], ["83850.00", "0.003028"], ["83849.70", "5.528845"], ["83848.45", "0.209200"], ["83848.39", "0.000020"], ["83848.00", "0.001184"], ["83846.15", "0.000111"], ["83844.83", "0.000008"], ["83843.10", "0.001475"], ["83842.11", "0.000033"], ["83841.20", "4.622477"], ["83841.18", "0.000071"], ["83840.04", "0.209200"], ["83840.00", "0.001282"], ["83839.72", "0.000033"], ["83839.18", "0.000016"], ["83837.84", "0.000009"], ["83837.59", "0.000012"], ["83836.36", "0.000008"], ["83835.56", "0.000009"], ["83835.24", "0.001720"], ["83835.00", "0.000926"], ["83832.70", "4.078656"], ["83831.11", "0.000011"], ["83830.59", "0.000010"], ["83830.00", "0.000063"], ["83828.57", "0.000016"], ["83826.80", "0.303314"], ["83826.67", "0.000073"], ["83825.00", "0.000672"], ["83824.20", "4.441203"], ["83822.12", "0.000067"], ["83820.00", "0.003247"], ["83818.18", "0.001526"], ["83818.17", "0.000029"], ["83816.67", "0.000010"], ["83816.28", "0.000009"], ["83816.00", "0.000008"], ["83815.79", "0.000022"], ["83815.75", "0.000009"], ["83815.70", "5.619481"], ["83815.37", "0.000022"], ["83813.00", "0.000113"], ["83810.74", "0.000019"], ["83808.53", "0.000039"], ["83808.51", "0.000137"], ["83807.88", "0.000051"], ["83807.53", "0.000010"], ["83805.00", "0.000926"], ["83804.35", "0.000010"], ["83803.57", "0.000016"], ["83802.81", "0.000022"], ["83800.91", "0.000012"], ["83800.00", "0.039884"], ["83799.34", "0.000093"], ["83796.61", "0.001213"], ["83795.00", "0.000031"], ["83794.17", "0.000096"], ["83793.10", "0.000016"], ["83791.03", "0.000996"], ["83791.02", "0.000632"], ["83790.15", "0.000024"], ["83790.00", "0.003033"], ["83789.60", "0.000363"], ["83789.29", "0.000074"], ["83788.72", "0.000254"], ["83787.88", "0.000010"], ["83785.71", "0.000081"], ["83784.62", "0.000015"], ["83784.36", "0.000069"], ["83784.02", "0.000022"], ["83783.78", "0.000059"], ["83783.12", "0.000008"], ["83780.48", "0.000016"], ["83780.00", "0.001547"], ["83779.93", "0.000028"], ["83778.35", "0.011010"], ["83777.78", "0.000679"], ["83777.60", "0.000013"], ["83777.18", "0.000013"], ["83775.00", "0.009183"], ["83774.10", "0.000161"], ["83773.31", "0.000154"], ["83773.11", "0.041940"], ["83772.88", "0.000023"], ["83769.28", "0.000972"], ["83768.46", "0.000008"], ["83768.00", "0.000012"], ["83766.84", "0.000023"], ["83765.06", "0.000008"], ["83764.71", "0.000071"], ["83763.64", "0.000010"], ["83762.50", "0.000076"], ["83761.90", "0.000024"], ["83761.29", "0.000020"], ["83760.00", "0.001718"], ["83758.93", "0.000036"], ["83758.00", "0.000353"], ["83757.40", "0.000537"], ["83756.08", "0.000099"], ["83755.56", "0.000134"], ["83754.70", "0.000013"], ["83754.39", "0.000033"], ["83752.94", "0.000071"], ["83752.37", "0.000119"], ["83752.09", "0.000314"], ["83752.00", "0.000034"], ["83750.67", "0.000146"], ["83750.00", "0.041680"], ["83749.66", "0.000016"], ["83749.50", "0.000069"], ["83749.33", "0.000133"], ["83748.54", "0.000012"], ["83746.09", "0.000010"], ["83745.16", "0.000389"], ["83745.00", "0.000926"], ["83743.29", "0.001451"], ["83740.51", "0.000423"], ["83740.00", "0.001311"], ["83739.60", "0.000048"], ["83739.28", "0.000051"], ["83739.13", "0.000008"], ["83737.93", "0.000135"], ["83737.37", "0.000012"], ["83737.00", "0.000009"], ["83736.94", "0.000104"], ["83736.84", "0.000183"], ["83736.33", "0.000025"], ["83734.69", "0.000085"], ["83733.33", "0.003222"], ["83732.10", "0.000009"], ["83731.48", "0.000124"], ["83730.00", "0.002926"], ["83729.73", "0.000009"], ["83729.39", "0.000008"], ["83729.32", "0.000035"], ["83728.57", "0.000017"], ["83728.37", "0.001273"], ["83728.07", "0.000022"], ["83727.71", "0.000009"], ["83727.27", "0.000082"], ["83726.20", "0.000016"], ["83725.07", "1.657985"], ["83725.00", "0.002501"], ["83723.72", "0.000176"], ["83723.64", "0.000009"], ["83723.61", "0.000883"], ["83723.43", "0.000039"], ["83723.40", "0.000205"], ["83721.56", "0.000015"], ["83720.00", "0.003671"], ["83719.46", "0.000053"], ["83718.75", "0.000012"], ["83717.93", "0.000065"], ["83717.46", "0.000009"], ["83717.45", "0.000040"], ["83717.39", "0.000010"], ["83715.48", "0.000010"], ["83715.00", "0.000926"], ["83714.29", "0.009987"], ["83714.28", "0.000836"], ["83713.80", "0.000024"], ["83713.71", "0.000323"], ["83713.40", "0.000161"], ["83711.93", "0.000018"], ["83710.00", "0.000023"], ["83709.88", "0.000107"], ["83707.07", "0.000067"], ["83706.90", "0.000016"], ["83706.67", "0.000013"], ["83705.85", "0.000019"], ["83705.32", "0.000065"], ["83705.18", "0.000009"], ["83703.75", "0.000364"], ["83703.70", "0.000499"], ["83703.00", "0.000024"], ["83702.93", "0.000050"], ["83702.60", "0.000039"], ["83702.50", "0.000033"], ["83702.48", "0.000057"], ["83701.92", "0.000067"], ["83701.28", "0.000248"], ["83700.70", "0.511700"], ["83700.00", "0.007170"], ["83699.88", "0.000008"], ["83699.00", "0.002419"], ["83697.23", "0.000095"], ["83695.65", "0.003535"], ["83695.63", "0.000011"], ["83693.69", "0.000051"], ["83693.28", "0.001536"], ["83692.52", "0.000066"], ["83692.38", "0.000007"], ["83692.31", "0.000031"], ["83691.74", "0.000653"], ["83690.84", "0.000162"], ["83690.48", "0.000248"], ["83689.78", "0.001684"], ["83689.50", "0.000113"], ["83688.89", "0.000009"], ["83688.07", "0.000072"], ["83687.50", "0.006969"], ["83687.00", "0.000008"], ["83686.11", "0.000096"], ["83685.00", "0.000926"], ["83684.21", "0.000102"], ["83683.67", "0.000184"], ["83681.82", "0.000175"], ["83680.67", "0.041940"], ["83680.00", "0.001718"], ["83679.44", "0.000361"], ["83678.41", "0.000010"], ["83678.08", "0.000145"], ["83677.37", "0.000008"], ["83676.47", "0.000080"], ["83675.68", "0.000008"], ["83675.62", "0.000011"], ["83675.36", "0.000013"], ["83675.20", "0.000018"], ["83675.00", "0.002674"], ["83674.70", "0.000008"], ["83674.19", "0.000020"], ["83674.00", "0.001195"], ["83673.87", "0.000022"], ["83673.58", "0.000023"], ["83672.96", "0.002168"], ["83672.50", "0.000031"], ["83672.25", "0.004023"], ["83672.00", "0.000035"], ["83671.36", "0.000099"], ["83670.59", "0.000105"], ["83670.05", "0.000033"], ["83670.00", "0.004426"], ["83669.66", "0.000010"], ["83669.58", "0.000251"], ["83669.09", "0.000135"], ["83667.80", "0.000023"], ["83667.23", "0.012503"], ["83666.67", "0.052199"], ["83666.66", "0.000513"], ["83666.65", "0.000122"], ["83666.00", "0.271427"], ["83664.71", "0.000071"], ["83664.19", "0.000073"], ["83663.98", "0.000008"], ["83663.95", "0.000022"], ["83663.91", "0.000161"], ["83662.50", "0.000077"], ["83661.97", "0.000052"], ["83661.60", "0.000042"], ["83661.08", "0.004152"], ["83660.71", "0.000309"], ["83660.14", "0.000016"], ["83660.00", "0.001273"], ["83659.61", "0.000454"], ["83659.49", "0.000012"], ["83659.44", "0.000613"], ["83658.54", "0.000036"], ["83656.60", "0.000607"], ["83655.00", "0.000926"], ["83654.23", "0.000009"], ["83653.94", "0.000133"]], "checksum": 0, "ts": "1742555346118"}], "ts": 1742555346301, "record_time": 1742555346.38491, "EXCHANGE": "BITGET"}
{"action": "update", "arg": {"instType": "SPOT", "channel": "books", "instId": "BTCUSDT"}, "data": [{"asks": [["84030.45", "0.088149"], ["84030.49", "0"], ["84090.73", "0.045761"], ["84105.30", "0.001020"], ["84106.70", "0.515460"], ["84107.40", "0.022680"], ["84108.10", "0.067800"], ["84109.00", "0.513540"], ["84109.90", "0"], ["84110.30", "0"], ["84117.10", "0"], ["84145.40", "5.438208"], ["84153.90", "5.347571"], ["84162.40", "4.078656"], ["84179.40", "5.619481"], ["84187.90", "4.531840"], ["84196.40", "4.441203"], ["84204.90", "3.988019"], ["84213.40", "5.528845"], ["84221.90", "4.169293"], ["84230.40", "4.622477"], ["84238.90", "4.713114"], ["84247.40", "5.075661"], ["84255.90", "3.897382"], ["84264.40", "5.166297"], ["84272.90", "4.985024"], ["84281.40", "4.259930"], ["84289.90", "4.350566"], ["84298.40", "4.803750"], ["84306.90", "4.894387"]], "bids": [["84029.20", "0.085288"], ["84027.20", "0.224442"], ["84025.20", "0.590636"], ["84023.49", "0.174386"], ["84023.20", "1.554307"], ["84021.20", "4.090280"], ["84019.20", "10.763894"], ["84018.90", "0.120390"], ["84018.50", "1.285290"], ["84018.10", "2.597100"], ["84018.00", "0.120000"], ["84017.90", "0.389340"], ["84016.20", "0.022770"], ["84015.80", "0"], ["84015.50", "0.655320"], ["84015.10", "0.374700"], ["84013.90", "0.187800"], ["84012.10", "0"], ["84011.90", "0"], ["84011.60", "0.178440"], ["84011.30", "0"], ["84011.20", "0"], ["84009.40", "0.004019"], ["84006.73", "0"], ["83977.20", "4.350566"], ["83968.70", "4.531840"], ["83960.20", "4.259930"], ["83951.70", "4.622477"], ["83943.20", "4.441203"], ["83934.70", "5.166297"], ["83926.20", "4.985024"], ["83917.70", "3.897382"], ["83900.70", "5.256934"], ["83892.20", "5.438208"], ["83883.70", "5.619481"], ["83875.20", "4.169293"], ["83866.70", "5.528845"], ["83858.20", "4.894387"], ["83849.70", "5.075661"], ["83841.20", "4.713114"], ["83824.20", "3.988019"], ["83815.70", "5.347571"], ["83653.67", "0.001695"], ["83653.31", "0.000015"]], "checksum": 2020907220, "ts": "1742555346320"}], "ts": 1742555346323, "record_time": 1742555346.385993, "EXCHANGE": "BITGET"}
{"action": "update", "arg": {"instType": "SPOT", "channel": "books", "instId": "BTCUSDT"}, "data": [{"asks": [["84029.41", "0.333484"], ["84040.69", "0"], ["84053.10", "0"], ["84063.35", "0.017455"], ["84087.14", "0"], ["84105.30", "0"], ["84106.70", "0.016470"], ["84107.60", "0.015000"], ["84108.10", "0"], ["84109.00", "0"], ["84111.70", "0.193920"], ["84112.30", "0"], ["84112.60", "0"], ["84116.00", "0.024390"], ["84116.60", "0"], ["84117.10", "0.107070"], ["84117.30", "2.674740"], ["84117.60", "0.609030"], ["84145.40", "4.078656"], ["84153.90", "4.622477"], ["84162.40", "4.985024"], ["84170.90", "5.619481"], ["84179.40", "4.259930"], ["84187.90", "5.528845"], ["84196.40", "5.166297"], ["84204.90", "5.256934"], ["84213.40", "5.438208"], ["84221.90", "3.988019"], ["84230.40", "4.894387"], ["84238.90", "3.897382"], ["84247.40", "5.347571"], ["84255.90", "4.169293"], ["84264.40", "4.350566"], ["84272.90", "4.441203"], ["84281.40", "4.713114"], ["84289.90", "4.531840"], ["84298.40", "5.075661"], ["84306.90", "4.803750"], ["84518.98", "0.000029"], ["84520.00", "0.000854"], ["84520.50", "0.000238"], ["84520.67", "0.002384"], ["84521.85", "0.000033"]], "bids": [["84029.20", "0.087557"], ["84027.20", "0.230413"], ["84025.20", "0.606350"], ["84023.49", "1.967720"], ["84023.20", "1.595657"], ["84021.20", "4.199099"], ["84019.20", "11.050260"], ["84018.00", "0.120180"], ["83997.80", "0.017455"], ["83987.55", "0"], ["83978.00", "0.000017"], ["83977.20", "5.528845"], ["83968.70", "5.166297"], ["83960.20", "3.897382"], ["83951.70", "4.985024"], ["83943.20", "4.169293"], ["83934.70", "5.619481"], ["83926.20", "4.259930"], ["83917.70", "4.803750"], ["83909.20", "4.894387"], ["83900.70", "5.347571"], ["83892.20", "3.988019"], ["83883.70", "4.350566"], ["83875.20", "4.713114"], ["83866.70", "4.441203"], ["83858.20", "4.622477"], ["83849.70", "4.531840"], ["83841.20", "4.078656"], ["83832.70", "5.075661"], ["83824.20", "5.438208"], ["83815.70", "5.256934"], ["83653.31", "0"]], "checksum": 1745617950, "ts": "1742555346522"}], "ts": 1742555346527, "record_time": 1742555346.562023, "EXCHANGE": "BITGET"}
{"action": "update", "arg": {"instType": "SPOT", "channel": "books", "instId": "BTCUSDT"}, "data": [{"asks": [["84029.41", "0.333514"], ["84030.45", "0"], ["84043.79", "0.112625"], ["84063.34", "0.013301"], ["84065.95", "0"], ["84085.39", "0.001244"], ["84101.40", "0.095389"], ["84103.40", "0.251026"], ["84105.40", "0.001041"], ["84106.70", "0.040050"], ["84111.70", "0.319440"], ["84112.30", "0.499230"], ["84117.50", "0.070080"], ["84145.40", "4.713114"], ["84153.90", "5.166297"], ["84162.40", "4.803750"], ["84170.90", "5.347571"], ["84179.40", "5.256934"], ["84187.90", "3.988019"], ["84196.40", "5.619481"], ["84204.90", "4.441203"], ["84213.40", "4.259930"], ["84221.90", "4.985024"], ["84230.40", "4.350566"], ["84238.90", "5.528845"], ["84247.40", "4.894387"], ["84255.90", "4.622477"], ["84264.40", "5.075661"], ["84272.90", "4.169293"], ["84281.40", "5.438208"], ["84289.90", "3.897382"], ["84298.40", "4.078656"], ["84306.90", "4.531840"], ["84520.50", "0"], ["84520.67", "0"], ["84521.85", "0"]], "bids": [["84011.80", "0.452010"], ["84011.50", "0"], ["83978.17", "0.003598"], ["83978.00", "0.000032"], ["83977.20", "4.169293"], ["83976.32", "0"], ["83968.70", "4.531840"], ["83960.20", "4.713114"], ["83951.70", "3.897382"], ["83943.20", "4.259930"], ["83934.70", "4.078656"], ["83926.20", "5.256934"], ["83917.70", "5.347571"], ["83909.20", "4.985024"], ["83900.70", "4.894387"], ["83892.20", "5.528845"], ["83875.20", "5.166297"], ["83866.70", "4.803750"], ["83858.20", "5.438208"], ["83849.70", "5.619481"], ["83841.20", "4.441203"], ["83824.20", "4.622477"], ["83815.70", "3.988019"]], "checksum": 89035240, "ts": "1742555346724"}], "ts": 1742555346726, "record_time": 1742555346.753223, "EXCHANGE": "BITGET"}
{"action": "update", "arg": {"instType": "SPOT", "channel": "books", "instId": "BTCUSDT"}, "data": [{"asks": [["84030.42", "0.088149"], ["84043.78", "0.033788"], ["84097.40", "0.013729"], ["84101.40", "0.095071"], ["84103.40", "0.250189"], ["84106.70", "0.040230"], ["84111.70", "1.370850"], ["84111.90", "0.430830"], ["84112.30", "0"], ["84117.10", "0"], ["84117.20", "0.107070"], ["84117.60", "0.534660"], ["84145.40", "5.166297"], ["84153.90", "5.347571"], ["84162.40", "4.078656"], ["84170.90", "4.713114"], ["84179.40", "5.619481"], ["84187.90", "3.897382"], ["84196.40", "4.803750"], ["84204.90", "4.259930"], ["84213.40", "4.350566"], ["84221.90", "5.256934"], ["84230.40", "4.169293"], ["84238.90", "4.531840"], ["84247.40", "4.622477"], ["84255.90", "5.075661"], ["84264.40", "4.441203"], ["84272.90", "5.528845"], ["84281.40", "4.985024"], ["84289.90", "5.438208"], ["84298.40", "3.988019"], ["84306.90", "4.894387"], ["84518.98", "0"], ["84520.00", "0"]], "bids": [["84021.20", "4.198972"], ["84019.20", "11.049739"], ["84011.80", "0"], ["84011.50", "0.120000"], ["83977.20", "4.531840"], ["83968.70", "4.169293"], ["83960.20", "4.803750"], ["83951.70", "4.985024"], ["83943.20", "5.528845"], ["83934.70", "4.894387"], ["83926.20", "5.166297"], ["83909.20", "5.075661"], ["83900.70", "3.897382"], ["83892.20", "4.441203"], ["83883.70", "5.619481"], ["83875.20", "4.259930"], ["83866.70", "4.078656"], ["83858.20", "4.622477"], ["83849.70", "5.438208"], ["83841.20", "5.256934"], ["83832.70", "4.713114"], ["83824.20", "4.350566"]], "checksum": 489548967, "ts": "1742555346924"}], "ts": 1742555346928, "record_time": 1742555346.954814, "EXCHANGE": "BITGET"}
{"action": "update", "arg": {"instType": "SPOT", "channel": "books", "instId": "BTCUSDT"}, "data": [{"asks": [["84029.41", "0.333497"], ["84080.97", "0"], ["84104.10", "0.001010"], ["84105.40", "0"], ["84109.90", "0.788610"], ["84111.70", "0.339450"], ["84112.60", "0.073950"], ["84116.00", "0.035670"], ["84117.60", "0"], ["84145.40", "5.438208"], ["84153.90", "4.894387"], ["84162.40", "4.803750"], ["84170.90", "4.441203"], ["84179.40", "4.078656"], ["84187.90", "4.985024"], ["84196.40", "3.988019"], ["84204.90", "4.169293"], ["84213.40", "4.259930"], ["84221.90", "5.166297"], ["84230.40", "5.075661"], ["84247.40", "5.347571"], ["84255.90", "4.622477"], ["84264.40", "5.256934"], ["84281.40", "4.350566"], ["84289.90", "5.619481"], ["84298.40", "4.713114"], ["84306.90", "3.897382"]], "bids": [["83979.00", "0.000015"], ["83977.20", "3.988019"], ["83968.70", "5.438208"], ["83960.20", "5.256934"], ["83951.70", "5.347571"], ["83943.20", "4.531840"], ["83926.20", "4.803750"], ["83917.70", "4.713114"], ["83909.20", "4.441203"], ["83892.20", "4.622477"], ["83883.70", "5.528845"], ["83875.20", "5.166297"], ["83866.70", "5.075661"], ["83858.20", "4.259930"], ["83849.70", "4.169293"], ["83841.20", "4.350566"], ["83832.70", "4.985024"], ["83824.20", "4.078656"], ["83815.70", "5.619481"]], "checksum": 816484471, "ts": "1742555347137"}], "ts": 1742555347140, "record_time": 1742555347.269985, "EXCHANGE": "BITGET"}
{"action": "update", "arg": {"instType": "SPOT", "channel": "books", "instId": "BTCUSDT"}, "data": [{"asks": [["84030.38", "0.088149"], ["84030.42", "0"], ["84081.92", "0.177978"], ["84103.40", "0.250300"], ["84104.10", "0"], ["84106.70", "0.040650"], ["84107.40", "0"], ["84108.50", "2.356590"], ["84108.90", "0.022620"], ["84112.90", "0.499230"], ["84145.40", "4.622477"], ["84153.90", "5.347571"], ["84162.40", "4.985024"], ["84170.90", "4.259930"], ["84179.40", "4.350566"], ["84187.90", "3.897382"], ["84196.40", "4.894387"], ["84204.90", "4.531840"], ["84213.40", "4.803750"], ["84221.90", "3.988019"], ["84230.40", "5.619481"], ["84238.90", "5.166297"], ["84240.71", "0"], ["84247.40", "5.438208"], ["84255.90", "4.713114"], ["84281.40", "5.075661"], ["84289.90", "4.078656"], ["84298.40", "4.441203"], ["84306.90", "4.169293"], ["84518.98", "0.000029"]], "bids": [["84012.50", "0.487860"], ["84011.60", "0"], ["84011.50", "0"], ["83977.20", "5.166297"], ["83968.70", "4.169293"], ["83960.20", "5.619481"], ["83943.20", "4.985024"], ["83926.20", "5.256934"], ["83917.70", "3.988019"], ["83909.20", "5.528845"], ["83900.70", "4.803750"], ["83892.20", "4.078656"], ["83883.70", "4.713114"], ["83875.20", "4.622477"], ["83866.70", "3.897382"], ["83849.70", "5.075661"], ["83832.70", "4.531840"], ["83824.20", "5.438208"], ["83815.70", "4.441203"], ["83653.31", "0.000015"], ["83652.80", "0.000119"]], "checksum": -576566705, "ts": "1742555347342"}], "ts": 1742555347344, "record_time": 1742555347.378203, "EXCHANGE": "BITGET"}
{"action": "update", "arg": {"instType": "SPOT", "channel": "books", "instId": "BTCUSDT"}, "data": [{"asks": [["84099.40", "0.036052"], ["84101.40", "0.094874"], ["84103.40", "0.249668"], ["84104.20", "0.001170"], ["84106.70", "0.040230"], ["84109.00", "0.984660"], ["84109.90", "0"], ["84117.50", "0"], ["84145.40", "4.713114"], ["84153.90", "3.897382"], ["84162.40", "4.078656"], ["84170.90", "4.894387"], ["84179.40", "5.619481"], ["84187.90", "5.075661"], ["84196.40", "4.441203"], ["84204.90", "5.438208"], ["84213.40", "5.347571"], ["84221.90", "4.622477"], ["84230.40", "4.169293"], ["84247.40", "4.985024"], ["84255.90", "4.531840"], ["84264.40", "3.988019"], ["84272.90", "4.803750"], ["84281.40", "5.256934"], ["84289.90", "4.259930"], ["84298.40", "5.528845"], ["84306.90", "4.350566"], ["84520.00", "0.000854"]], "bids": [["84021.20", "4.199085"], ["84019.20", "11.050223"], ["83979.00", "0"], ["83977.20", "4.894387"], ["83968.70", "5.438208"], ["83951.70", "4.622477"], ["83943.20", "5.075661"], ["83934.70", "4.259930"], ["83926.20", "4.985024"], ["83917.70", "5.528845"], ["83909.20", "4.531840"], ["83900.70", "4.169293"], ["83892.20", "5.166297"], ["83883.70", "4.803750"], ["83875.20", "4.713114"], ["83866.70", "5.256934"], ["83858.20", "4.350566"], ["83849.70", "3.897382"], ["83841.20", "4.441203"], ["83832.70", "5.347571"], ["83824.20", "3.988019"], ["83815.70", "4.078656"], ["83652.48", "0.000188"]], "checksum": -576566705, "ts": "1742555347545"}], "ts": 1742555347547, "record_time": 1742555347.578433, "EXCHANGE": "BITGET"}
{"action": "update", "arg": {"instType": "SPOT", "channel": "books", "instId": "BTCUSDT"}, "data": [{"asks": [["84030.38", "0"], ["84145.40", "5.528845"], ["84162.40", "4.622477"], ["84170.90", "5.166297"], ["84179.40", "4.894387"], ["84187.90", "5.256934"], ["84196.40", "4.713114"], ["84204.90", "4.803750"], ["84213.40", "5.438208"], ["84221.90", "5.347571"], ["84230.40", "4.350566"], ["84238.90", "4.985024"], ["84243.88", "0.162551"], ["84247.40", "4.259930"], ["84255.90", "3.988019"], ["84264.40", "4.531840"], ["84272.90", "4.169293"], ["84281.40", "5.075661"], ["84289.90", "4.441203"], ["84298.40", "5.619481"], ["84306.90", "4.078656"]], "bids": [["83977.20", "4.441203"], ["83977.00", "0.000017"], ["83968.70", "5.528845"], ["83960.20", "4.169293"], ["83951.70", "5.075661"], ["83943.20", "4.350566"], ["83934.70", "4.985024"], ["83926.20", "4.803750"], ["83917.70", "5.166297"], ["83909.20", "4.713114"], ["83900.70", "4.622477"], ["83892.20", "3.897382"], ["83883.70", "4.894387"], ["83875.20", "5.347571"], ["83866.70", "5.619481"], ["83858.20", "4.259930"], ["83849.70", "4.078656"], ["83841.20", "3.988019"], ["83832.70", "5.438208"], ["83824.20", "4.531840"], ["83815.70", "5.256934"], ["83652.48", "0"]], "checksum": -1752607416, "ts": "1742555347746"}], "ts": 1742555347750, "record_time": 1742555347.777422, "EXCHANGE": "BITGET"}
{"action": "update", "arg": {"instType": "SPOT", "channel": "books", "instId": "BTCUSDT"}, "data": [{"asks": [["84030.35", "0.088149"], ["84036.96", "0"], ["84037.81", "0"], ["84041.66", "0.000221"], ["84093.40", "0.002804"], ["84095.40", "0.007377"], ["84097.40", "0.019413"], ["84099.40", "0.051087"], ["84101.40", "0.134440"], ["84103.40", "0.353791"], ["84104.20", "0.001021"], ["84106.70", "2.397090"], ["84107.00", "1.065300"], ["84107.60", "0"], ["84108.50", "0"], ["84109.00", "0"], ["84110.10", "0.067980"], ["84110.70", "0.387600"], ["84111.90", "0"], ["84112.60", "0"], ["84117.50", "0.070080"], ["84117.60", "0.609030"], ["84117.90", "0.249120"], ["84145.40", "5.347571"], ["84153.90", "4.713114"], ["84162.40", "4.803750"], ["84170.90", "4.259930"], ["84179.40", "4.622477"], ["84187.90", "4.441203"], ["84196.40", "5.256934"], ["84204.90", "4.894387"], ["84213.40", "3.988019"], ["84221.90", "5.438208"], ["84230.40", "4.985024"], ["84238.90", "5.166297"], ["84247.40", "4.531840"], ["84255.90", "4.350566"], ["84264.40", "5.528845"], ["84272.90", "3.897382"], ["84281.40", "4.078656"], ["84289.90", "5.075661"], ["84306.90", "4.169293"], ["84520.50", "0.000238"]], "bids": [["84029.20", "0.085053"], ["84027.20", "0.223826"], ["84025.20", "0.589016"], ["84023.20", "1.550041"], ["84021.20", "4.079056"], ["84019.20", "10.734358"], ["84013.30", "0.015000"], ["84011.70", "0"], ["83977.20", "5.347571"], ["83968.70", "4.985024"], ["83960.20", "4.894387"], ["83951.70", "4.350566"], ["83943.20", "4.531840"], ["83934.70", "5.075661"], ["83926.20", "5.619481"], ["83917.70", "4.441203"], ["83909.20", "4.803750"], ["83900.70", "4.078656"], ["83892.20", "4.259930"], ["83883.70", "5.528845"], ["83875.20", "4.169293"], ["83866.70", "5.256934"], ["83858.20", "5.438208"], ["83849.70", "4.713114"], ["83841.20", "3.897382"], ["83832.70", "4.622477"], ["83824.20", "5.166297"], ["83815.70", "3.988019"]], "checksum": -537053087, "ts": "1742555347955"}], "ts": 1742555347958, "record_time": 1742555347.985651, "EXCHANGE": "BITGET"}
{"action": "update", "arg": {"instType": "SPOT", "channel": "books", "instId": "BTCUSDT"}, "data": [{"asks": [["84029.41", "0.556987"], ["84035.01", "0.051607"], ["84091.40", "0.001941"], ["84093.40", "0.005106"], ["84095.40", "0.013437"], ["84097.40", "0.035554"], ["84099.40", "0.093564"], ["84101.40", "0.246221"], ["84103.40", "0.647950"], ["84104.20", "0"], ["84104.90", "2.357100"], ["84105.10", "0.001005"], ["84105.80", "0.953430"], ["84105.90", "0"], ["84106.10", "0.410130"], ["84106.70", "0.257670"], ["84107.00", "0.072900"], ["84107.60", "0.015000"], ["84110.10", "0.179970"], ["84110.70", "0"], ["84111.70", "0.292200"], ["84112.20", "0"], ["84145.40", "5.166297"], ["84153.90", "5.528845"], ["84162.40", "5.256934"], ["84170.90", "4.713114"], ["84179.40", "5.438208"], ["84187.90", "4.894387"], ["84196.40", "4.259930"], ["84204.90", "4.985024"], ["84213.40", "4.078656"], ["84221.90", "4.350566"], ["84230.40", "3.897382"], ["84238.90", "4.441203"], ["84247.40", "5.619481"], ["84255.90", "4.622477"], ["84264.40", "5.075661"], ["84272.90", "5.347571"], ["84281.40", "4.169293"], ["84289.90", "4.803750"], ["84298.40", "4.531840"], ["84306.90", "3.988019"], ["84520.00", "0"], ["84520.50", "0"]], "bids": [["84015.50", "0.298440"], ["84014.40", "0"], ["84011.70", "0.428250"], ["83977.20", "4.169293"], ["83960.20", "5.166297"], ["83943.20", "4.894387"], ["83934.70", "4.078656"], ["83926.20", "5.528845"], ["83917.70", "4.259930"], ["83915.80", "0.125657"], ["83910.54", "0"], ["83909.20", "4.531840"], ["83900.70", "5.256934"], ["83892.20", "5.619481"], ["83883.70", "4.713114"], ["83875.20", "3.897382"], ["83866.70", "3.988019"], ["83858.20", "5.075661"], ["83849.70", "5.438208"], ["83841.20", "4.441203"], ["83832.70", "4.803750"], ["83824.20", "4.622477"], ["83815.70", "5.347571"]], "checksum": -2064863159, "ts": "1742555348173"}], "ts": 1742555348175, "record_time": 1742555348.205358, "EXCHANGE": "BITGET"}
{"action": "update", "arg": {"instType": "SPOT", "channel": "books", "instId": "BTCUSDT"}, "data": [{"asks": [["84030.35", "0"], ["84033.48", "0.054750"], ["84035.01", "0"], ["84040.66", "0.009797"], ["84089.40", "0.001851"], ["84091.40", "0.004871"], ["84093.40", "0.012818"], ["84095.40", "0.033732"], ["84097.40", "0.088767"], ["84099.40", "0.233599"], ["84101.40", "0.614732"], ["84103.40", "1.617716"], ["84104.80", "2.882130"], ["84104.90", "2.356680"], ["84105.10", "0"], ["84105.80", "0"], ["84106.10", "0"], ["84106.90", "0.066210"], ["84107.00", "0.072720"], ["84110.10", "0.166710"], ["84111.40", "0"], ["84112.60", "0.074520"], ["84117.60", "0.534660"], ["84117.90", "0"], ["84145.40", "5.347571"], ["84153.90", "4.622477"], ["84162.40", "5.166297"], ["84170.90", "4.169293"], ["84179.40", "4.259930"], ["84187.90", "5.256934"], ["84196.40", "5.438208"], ["84204.90", "4.078656"], ["84213.40", "5.528845"], ["84221.90", "3.897382"], ["84230.40", "4.713114"], ["84238.90", "5.619481"], ["84247.40", "4.985024"], ["84255.90", "4.350566"], ["84264.40", "4.441203"], ["84272.90", "4.894387"], ["84281.40", "4.803750"], ["84289.90", "5.075661"], ["84298.40", "3.988019"], ["84306.90", "4.531840"], ["84520.00", "0.000854"], ["84520.50", "0.000238"]], "bids": [["84029.20", "0.066002"], ["84027.20", "0.173689"], ["84025.20", "0.457076"], ["84023.20", "1.202832"], ["84021.20", "3.165347"], ["84019.20", "8.329861"], ["84017.90", "0.067980"], ["84016.87", "0.006200"], ["84015.54", "0"], ["84015.50", "0.120000"], ["84015.20", "0.126630"], ["84015.10", "0"], ["84014.20", "2.392260"], ["84013.40", "0"], ["84013.00", "0.000032"], ["84012.80", "0"], ["84011.70", "0.249810"], ["84011.50", "0.120000"], ["84011.20", "0.017820"], ["84010.90", "0.535320"], ["84010.80", "0.009000"], ["84010.30", "1.732470"], ["84009.90", "0.067800"], ["84009.70", "0.006870"], ["84009.40", "0.534660"], ["83995.99", "0.000877"], ["83994.64", "0"], ["83978.00", "0.000015"], ["83977.20", "5.438208"], ["83977.00", "0.000032"], ["83968.70", "4.350566"], ["83960.20", "4.985024"], ["83951.70", "4.894387"], ["83943.20", "4.713114"], ["83934.70", "4.803750"], ["83926.20", "4.169293"], ["83909.20", "3.897382"], ["83900.70", "5.075661"], ["83892.20", "5.166297"], ["83883.70", "4.622477"], ["83875.20", "5.256934"], ["83866.70", "5.528845"], ["83858.20", "4.441203"], ["83849.70", "3.988019"], ["83841.20", "4.531840"], ["83832.70", "5.619481"], ["83824.20", "5.347571"], ["83815.70", "4.078656"], ["83653.94", "0"], ["83653.67", "0"], ["83653.31", "0"], ["83652.80", "0"]], "checksum": 751673295, "ts": "1742555348387"}], "ts": 1742555348389, "record_time": 1742555348.417678, "EXCHANGE": "BITGET"}
{"action": "update", "arg": {"instType": "SPOT", "channel": "books", "instId": "BTCUSDT"}, "data": [{"asks": [["84029.41", "0.896987"], ["84030.31", "0.088149"], ["84037.82", "0.209200"], ["84071.07", "0.012472"], ["84071.21", "0"], ["84087.33", "0"], ["84087.40", "0.001037"], ["84087.64", "0.010000"], ["84089.27", "0"], ["84089.40", "0.002727"], ["84090.19", "0.001598"], ["84091.40", "0.007178"], ["84092.43", "0.001597"], ["84093.40", "0.018888"], ["84095.40", "0.049707"], ["84097.40", "0.130807"], ["84099.40", "0.344228"], ["84101.40", "0.905863"], ["84103.40", "2.383850"], ["84103.80", "0.530250"], ["84104.80", "0.833880"], ["84104.90", "0"], ["84106.70", "2.630430"], ["84108.80", "0.041070"], ["84110.10", "0.103470"], ["84111.70", "0.726750"], ["84113.10", "0.045540"], ["84117.30", "0"], ["84117.50", "0"], ["84117.60", "0"], ["84145.40", "5.256934"], ["84153.90", "4.985024"], ["84170.90", "3.988019"], ["84179.40", "4.894387"], ["84187.90", "4.622477"], ["84196.40", "4.169293"], ["84204.90", "3.897382"], ["84213.40", "5.619481"], ["84221.90", "4.259930"], ["84230.40", "4.803750"], ["84238.90", "5.528845"], ["84247.40", "4.713114"], ["84264.40", "5.438208"], ["84272.90", "4.441203"], ["84281.40", "5.075661"], ["84289.90", "4.531840"], ["84298.40", "5.347571"], ["84306.90", "4.078656"], ["84520.50", "0"]], "bids": [["84029.20", "0.065380"], ["84027.20", "0.172052"], ["84025.20", "0.452769"], ["84023.20", "1.191498"], ["84021.20", "3.135520"], ["84019.20", "8.251369"], ["84017.60", "0.186690"], ["84015.90", "0.067800"], ["84011.70", "0"], ["84011.20", "0"], ["84010.90", "0"], ["84008.90", "0.476760"], ["83979.94", "0.001176"], ["83978.31", "0.001173"], ["83977.20", "5.256934"], ["83977.08", "0"], ["83975.15", "0"], ["83968.70", "4.169293"], ["83960.20", "4.259930"], ["83951.70", "5.619481"], ["83943.20", "5.528845"], ["83934.70", "4.713114"], ["83926.20", "5.438208"], ["83917.70", "3.988019"], ["83909.20", "4.985024"], ["83900.70", "4.894387"], ["83892.20", "4.531840"], ["83883.70", "5.166297"], ["83875.20", "4.350566"], ["83866.70", "5.347571"], ["83858.20", "5.075661"], ["83849.70", "4.622477"], ["83841.20", "3.897382"], ["83832.70", "4.441203"], ["83824.20", "4.078656"], ["83815.70", "4.803750"], ["83653.94", "0.000133"], ["83653.67", "0.001695"]], "checksum": 577376018, "ts": "1742555348607"}], "ts": 1742555348611, "record_time": 1742555348.638263, "EXCHANGE": "BITGET"}
{"action": "update", "arg": {"instType": "SPOT", "channel": "books", "instId": "BTCUSDT"}, "data": [{"asks": [["84037.81", "0.072557"], ["84040.66", "0"], ["84105.00", "2.356500"], ["84106.70", "0.273990"], ["84110.10", "0.078480"], ["84111.69", "0"], ["84111.70", "0.292200"], ["84117.20", "0"], ["84145.40", "5.438208"], ["84153.90", "4.622477"], ["84162.40", "3.988019"], ["84170.90", "5.256934"], ["84179.40", "5.166297"], ["84187.90", "4.803750"], ["84196.40", "5.075661"], ["84204.90", "4.259930"], ["84213.40", "4.894387"], ["84221.90", "4.531840"], ["84230.40", "4.441203"], ["84238.90", "4.169293"], ["84247.40", "4.078656"], ["84255.90", "5.619481"], ["84264.40", "5.347571"], ["84272.90", "4.713114"], ["84281.40", "3.897382"], ["84289.90", "4.350566"], ["84298.40", "4.985024"], ["84306.90", "5.528845"], ["84520.50", "0.000238"]], "bids": [["84029.40", "1.106496"], ["84019.10", "0.075000"], ["84018.90", "0"], ["84018.50", "0.870570"], ["84018.10", "2.356770"], ["84018.00", "0.000032"], ["84015.50", "0"], ["84014.70", "0"], ["84014.20", "2.073150"], ["84013.90", "0.067800"], ["84013.80", "0"], ["84012.90", "0"], ["84012.00", "0.360000"], ["84008.90", "0"], ["84008.70", "0.120000"], ["84007.90", "1.476000"], ["83977.20", "3.897382"], ["83968.70", "5.075661"], ["83960.20", "4.350566"], ["83951.70", "5.347571"], ["83943.20", "4.531840"], ["83934.70", "4.894387"], ["83926.20", "5.256934"], ["83917.70", "4.441203"], ["83909.20", "5.438208"], ["83900.70", "4.803750"], ["83892.20", "4.713114"], ["83883.70", "4.622477"], ["83875.20", "5.619481"], ["83866.70", "4.169293"], ["83858.20", "4.078656"], ["83849.70", "4.259930"], ["83841.20", "4.985024"], ["83832.70", "5.166297"], ["83824.20", "5.528845"], ["83815.70", "3.988019"], ["83653.31", "0.000015"], ["83652.80", "0.000119"], ["83652.48", "0.000188"], ["83651.65", "0.000018"]], "checksum": -2049961474, "ts": "1742555348817"}], "ts": 1742555348821, "record_time": 1742555348.856056, "EXCHANGE": "BITGET"}
{"action": "update", "arg": {"instType": "SPOT", "channel": "books", "instId": "BTCUSDT"}, "data": [{"asks": [["84029.42", "0.000117"], ["84030.28", "0.088149"], ["84030.31", "0"], ["84051.72", "0"], ["84052.15", "0"], ["84052.92", "0.035952"], ["84053.28", "0.119870"], ["84053.42", "0"], ["84053.84", "0"], ["84054.07", "0"], ["84054.34", "0"], ["84054.46", "0.035961"], ["84054.89", "0.006356"], ["84055.27", "0.006356"], ["84055.38", "0.006356"], ["84055.41", "0"], ["84055.70", "0"], ["84055.85", "0"], ["84056.35", "0"], ["84056.40", "0"], ["84056.61", "0.010984"], ["84056.86", "0"], ["84056.87", "0"], ["84056.95", "0.006356"], ["84057.11", "0.006356"], ["84057.19", "0"], ["84057.22", "0"], ["84057.37", "0"], ["84057.38", "0"], ["84057.40", "0.006356"], ["84057.59", "0.016429"], ["84057.91", "0.006356"], ["84057.99", "0.006356"], ["84058.37", "0.016429"], ["84058.47", "0.119883"], ["84058.55", "0.006356"], ["84058.62", "0.006356"], ["84058.88", "0"], ["84058.93", "0"], ["84060.05", "0.010985"], ["84060.11", "0.006357"], ["84060.65", "0"], ["84061.66", "0"], ["84061.83", "0.119850"], ["84062.01", "0"], ["84062.24", "0"], ["84062.92", "0.119858"], ["84063.24", "0.015895"], ["84063.50", "0.009989"], ["84065.96", "0"], ["84066.85", "0"], ["84067.19", "0.015892"], ["84068.03", "0.010988"], ["84089.40", "0.002321"], ["84091.40", "0.006108"], ["84093.40", "0.016072"], ["84095.40", "0.042295"], ["84097.40", "0.111302"], ["84099.40", "0.292902"], ["84101.40", "0.770794"], ["84103.40", "2.028404"], ["84104.80", "1.903320"], ["84105.00", "0"], ["84107.00", "2.429160"], ["84107.60", "0"], ["84108.80", "0"], ["84110.10", "0.067800"], ["84117.20", "0.107070"], ["84117.30", "2.674740"], ["84117.50", "0.070080"], ["84117.60", "0.609030"], ["84145.40", "5.619481"], ["84153.90", "5.347571"], ["84162.40", "5.438208"], ["84170.90", "4.078656"], ["84179.40", "4.622477"], ["84187.90", "3.897382"], ["84196.40", "4.441203"], ["84204.90", "4.894387"], ["84213.40", "4.531840"], ["84221.90", "5.075661"], ["84230.40", "5.256934"], ["84238.90", "5.166297"], ["84247.40", "4.713114"], ["84255.90", "3.988019"], ["84264.40", "4.259930"], ["84272.90", "4.803750"], ["84281.40", "4.985024"], ["84289.90", "5.528845"], ["84298.40", "4.350566"], ["84306.90", "4.169293"], ["84520.50", "0"]], "bids": [["84029.40", "1.112790"], ["84023.20", "1.191382"], ["84021.20", "3.135217"], ["84019.20", "8.250569"], ["84012.90", "0.120000"], ["84012.58", "0.089521"], ["84012.11", "0.247687"], ["84011.39", "0"], ["84011.20", "0.269760"], ["84010.98", "0"], ["84010.90", "0.071370"], ["84010.77", "0.083974"], ["84010.40", "0.018262"], ["84010.35", "0.017824"], ["84010.30", "1.281840"], ["84009.84", "0.005949"], ["84009.72", "0"], ["84009.50", "0.120000"], ["84009.31", "0"], ["84009.20", "0"], ["84008.88", "0.055678"], ["84008.79", "0"], ["84008.72", "0.017110"], ["84008.54", "0.007134"], ["84008.01", "0.028876"], ["84007.90", "0"], ["84007.82", "0.007342"], ["84007.68", "0"], ["84007.46", "0"], ["84007.40", "0.007946"], ["84007.33", "0.008998"], ["84007.28", "0"], ["84007.21", "0.224973"], ["84007.11", "0.033214"], ["84007.03", "0.025959"], ["84006.96", "0.008188"], ["84006.83", "0"], ["84006.78", "0"], ["84006.28", "0"], ["84006.27", "0"], ["84005.96", "0"], ["84005.93", "0"], ["84005.78", "0"], ["84005.77", "0"], ["84005.49", "0.012660"], ["84005.43", "0.051984"], ["84004.31", "0"], ["84004.26", "0.003975"], ["84003.68", "0.268485"], ["84002.75", "0.222759"], ["84002.50", "0"], ["84002.24", "0.076143"], ["84002.15", "0.021138"], ["84001.50", "0"], ["84001.01", "0"], ["84000.90", "0"], ["83998.28", "0.073244"], ["83997.44", "0.056390"], ["83997.06", "0"], ["83996.27", "0"], ["83979.00", "0.000017"], ["83978.00", "0"], ["83977.20", "5.438208"], ["83968.70", "5.166297"], ["83960.20", "4.441203"], ["83951.70", "4.531840"], ["83943.20", "4.622477"], ["83934.70", "5.256934"], ["83926.20", "3.897382"], ["83917.70", "4.078656"], ["83909.20", "5.528845"], ["83900.70", "4.259930"], ["83892.20", "4.350566"], ["83883.70", "4.169293"], ["83875.20", "4.803750"], ["83866.70", "5.619481"], ["83858.20", "4.985024"], ["83849.70", "5.347571"], ["83841.20", "4.894387"], ["83832.70", "4.713114"], ["83824.20", "5.075661"], ["83652.48", "0"], ["83651.65", "0"]], "checksum": 1436990901, "ts": "1742555349019"}], "ts": 1742555349023, "record_time": 1742555349.061068, "EXCHANGE": "BITGET"}
{"action": "update", "arg": {"instType": "SPOT", "channel": "books", "instId": "BTCUSDT"}, "data": [{"asks": [["84029.41", "0.556987"], ["84059.72", "0"], ["84060.77", "0.009990"], ["84089.40", "0.001333"], ["84091.40", "0.003507"], ["84093.40", "0.009231"], ["84095.40", "0.024291"], ["84097.40", "0.063923"], ["84099.40", "0.168220"], ["84101.40", "0.442683"], ["84103.40", "1.164955"], ["84105.70", "0"], ["84110.60", "0.012720"], ["84145.40", "4.259930"], ["84153.90", "4.441203"], ["84162.40", "5.619481"], ["84170.90", "4.894387"], ["84179.40", "5.528845"], ["84187.90", "4.531840"], ["84196.40", "3.988019"], ["84204.90", "5.166297"], ["84213.40", "5.075661"], ["84221.90", "4.985024"], ["84230.40", "5.438208"], ["84238.90", "4.169293"], ["84247.40", "5.347571"], ["84255.90", "4.078656"], ["84264.40", "4.803750"], ["84272.90", "4.350566"], ["84281.40", "3.897382"], ["84289.90", "4.713114"], ["84298.40", "5.256934"], ["84306.90", "4.622477"]], "bids": [["84013.30", "0"], ["84009.70", "0"], ["84004.46", "0.018524"], ["84003.42", "0"], ["83977.20", "4.622477"], ["83968.70", "3.897382"], ["83960.20", "4.259930"], ["83951.70", "4.894387"], ["83943.20", "5.075661"], ["83934.70", "3.988019"], ["83926.20", "4.985024"], ["83917.70", "4.531840"], ["83900.70", "4.169293"], ["83892.20", "5.619481"], ["83883.70", "5.256934"], ["83875.20", "5.166297"], ["83866.70", "4.441203"], ["83858.20", "5.347571"], ["83849.70", "5.438208"], ["83841.20", "4.078656"], ["83824.20", "4.350566"], ["83815.70", "4.803750"], ["83652.48", "0.000188"], ["83651.65", "0.000018"]], "checksum": 1286647438, "ts": "1742555349222"}], "ts": 1742555349227, "record_time": 1742555349.258691, "EXCHANGE": "BITGET"}
{"action": "update", "arg": {"instType": "SPOT", "channel": "books", "instId": "BTCUSDT"}, "data": [{"asks": [["84030.25", "0.088149"], ["84030.28", "0"], ["84081.92", "0"], ["84089.40", "0.001686"], ["84091.40", "0.004436"], ["84093.40", "0.011674"], ["84095.40", "0.030722"], ["84097.40", "0.080846"], ["84099.40", "0.212754"], ["84101.40", "0.559877"], ["84103.40", "1.473362"], ["84111.70", "0.208500"], ["84112.90", "0.000958"], ["84113.10", "0"], ["84115.70", "0.045540"], ["84145.40", "5.347571"], ["84153.90", "5.075661"], ["84162.40", "4.713114"], ["84170.90", "4.441203"], ["84179.40", "5.256934"], ["84187.90", "4.803750"], ["84196.40", "4.531840"], ["84204.90", "4.169293"], ["84213.40", "4.259930"], ["84221.90", "5.528845"], ["84230.40", "5.166297"], ["84238.90", "5.619481"], ["84247.40", "4.350566"], ["84255.90", "3.897382"], ["84264.40", "4.894387"], ["84272.90", "4.985024"], ["84281.40", "3.988019"], ["84289.90", "4.078656"], ["84298.40", "5.438208"], ["84520.50", "0.000238"]], "bids": [["84029.20", "0.077435"], ["84027.20", "0.203776"], ["84025.20", "0.536253"], ["84023.20", "1.411191"], ["84021.20", "3.713662"], ["84019.20", "9.772793"], ["84012.50", "0.035850"], ["84007.90", "1.476000"], ["83977.20", "4.985024"], ["83968.70", "5.166297"], ["83960.20", "4.713114"], ["83951.70", "4.169293"], ["83943.20", "5.347571"], ["83934.70", "4.078656"], ["83926.20", "4.531840"], ["83917.70", "4.350566"], ["83909.20", "4.894387"], ["83900.70", "5.256934"], ["83892.20", "5.438208"], ["83883.70", "5.619481"], ["83875.20", "3.988019"], ["83866.70", "5.528845"], ["83858.20", "4.622477"], ["83849.70", "4.259930"], ["83841.20", "4.441203"], ["83832.70", "4.803750"], ["83824.20", "3.897382"], ["83815.70", "5.075661"], ["83651.65", "0"]], "checksum": -1863343042, "ts": "1742555349428"}], "ts": 1742555349431, "record_time": 1742555349.458664, "EXCHANGE": "BITGET"}
{"action": "update", "arg": {"instType": "SPOT", "channel": "books", "instId": "BTCUSDT"}, "data": [{"asks": [["84095.40", "0.030472"], ["84097.40", "0.080190"], ["84099.40", "0.211026"], ["84101.40", "0.555333"], ["84103.40", "1.461402"], ["84145.40", "5.256934"], ["84153.90", "4.078656"], ["84162.40", "5.619481"], ["84179.40", "4.259930"], ["84196.40", "4.894387"], ["84204.90", "5.075661"], ["84213.40", "4.531840"], ["84221.90", "5.347571"], ["84230.40", "4.985024"], ["84238.90", "4.622477"], ["84247.40", "3.988019"], ["84255.90", "5.166297"], ["84264.40", "4.350566"], ["84272.90", "4.713114"], ["84281.40", "5.438208"], ["84289.90", "4.169293"], ["84298.40", "5.528845"], ["84306.90", "3.897382"]], "bids": [["84019.20", "9.772570"], ["83977.20", "3.897382"], ["83968.70", "5.619481"], ["83960.20", "4.894387"], ["83951.70", "4.985024"], ["83943.20", "4.350566"], ["83934.70", "4.803750"], ["83926.20", "3.988019"], ["83917.70", "5.438208"], ["83909.20", "4.078656"], ["83900.70", "4.441203"], ["83892.20", "4.622477"], ["83883.70", "5.166297"], ["83875.20", "5.256934"], ["83866.70", "4.259930"], ["83858.20", "5.075661"], ["83849.70", "5.347571"], ["83841.20", "4.169293"], ["83832.70", "5.528845"], ["83824.20", "4.713114"], ["83815.70", "4.531840"]], "checksum": -1863343042, "ts": "1742555349646"}], "ts": 1742555349650, "record_time": 1742555349.679044, "EXCHANGE": "BITGET"}
{"action": "update", "arg": {"instType": "SPOT", "channel": "books", "instId": "BTCUSDT"}, "data": [{"asks": [["84029.42", "0.000100"], ["84080.97", "0.176724"], ["84089.40", "0.001318"], ["84091.40", "0.003468"], ["84093.40", "0.009128"], ["84095.40", "0.023843"], ["84097.40", "0.062745"], ["84099.40", "0.165117"], ["84101.40", "0.434520"], ["84103.40", "1.143472"], ["84103.80", "0.530430"], ["84104.80", "1.903680"], ["84106.70", "0.274170"], ["84106.90", "0.066390"], ["84107.00", "2.429340"], ["84110.10", "0.067980"], ["84110.80", "0.499230"], ["84145.40", "5.075661"], ["84153.90", "4.985024"], ["84162.40", "3.988019"], ["84170.90", "5.438208"], ["84179.40", "5.256934"], ["84196.40", "4.713114"], ["84204.90", "5.619481"], ["84213.40", "4.622477"], ["84221.90", "4.894387"], ["84230.40", "4.259930"], ["84238.90", "5.166297"], ["84247.40", "3.897382"], ["84255.90", "5.528845"], ["84264.40", "4.441203"], ["84272.90", "4.078656"], ["84281.40", "4.350566"], ["84289.90", "4.531840"], ["84298.40", "5.347571"], ["84306.90", "4.169293"], ["84520.00", "0"], ["84520.50", "0"]], "bids": [["84019.10", "0.075180"], ["84018.50", "0.870750"], ["84018.10", "2.356950"], ["84017.90", "0.068160"], ["84010.30", "1.733850"], ["84007.80", "0.120000"], ["83979.00", "0.000032"], ["83977.20", "4.713114"], ["83977.00", "0.000015"], ["83968.70", "3.988019"], ["83960.20", "4.259930"], ["83951.70", "5.075661"], ["83943.20", "4.622477"], ["83934.70", "3.897382"], ["83926.20", "5.256934"], ["83917.70", "4.894387"], ["83909.20", "5.528845"], ["83900.70", "4.169293"], ["83892.20", "4.985024"], ["83883.70", "4.531840"], ["83875.20", "4.350566"], ["83866.70", "5.619481"], ["83858.20", "5.166297"], ["83849.70", "4.441203"], ["83841.20", "5.438208"], ["83832.70", "4.803750"], ["83824.20", "4.078656"], ["83815.70", "5.347571"], ["83652.48", "0"]], "checksum": -2011038766, "ts": "1742555349853"}], "ts": 1742555349859, "record_time": 1742555349.905952, "EXCHANGE": "BITGET"}
{"action": "update", "arg": {"instType": "SPOT", "channel": "books", "instId": "BTCUSDT"}, "data": [{"asks": [["84030.22", "0.088149"], ["84030.25", "0"], ["84106.70", "0.274890"], ["84110.10", "0.067800"], ["84110.80", "0"], ["84117.90", "0.249120"], ["84145.40", "5.256934"], ["84153.90", "4.531840"], ["84162.40", "4.985024"], ["84170.90", "5.528845"], ["84179.40", "4.350566"], ["84187.90", "5.438208"], ["84204.90", "4.259930"], ["84213.40", "5.166297"], ["84221.90", "4.803750"], ["84230.40", "5.619481"], ["84238.90", "4.622477"], ["84255.90", "4.894387"], ["84264.40", "5.075661"], ["84272.90", "3.988019"], ["84281.40", "4.078656"], ["84289.90", "5.347571"], ["84298.40", "4.441203"]], "bids": [["84023.20", "1.411054"], ["84021.20", "3.713096"], ["84019.20", "9.771305"], ["84013.30", "0.015000"], ["84010.30", "1.281840"], ["83977.20", "3.988019"], ["83968.70", "5.528845"], ["83960.20", "4.169293"], ["83951.70", "4.803750"], ["83943.20", "5.347571"], ["83934.70", "4.713114"], ["83926.20", "4.259930"], ["83917.70", "3.897382"], ["83909.20", "4.078656"], ["83900.70", "5.438208"], ["83892.20", "4.441203"], ["83875.20", "4.622477"], ["83866.70", "5.166297"], ["83858.20", "4.350566"], ["83849.70", "4.894387"], ["83841.20", "4.985024"], ["83832.70", "5.256934"], ["83824.20", "5.619481"], ["83815.70", "5.075661"], ["83652.80", "0"]], "checksum": 1618798260, "ts": "1742555350056"}], "ts": 1742555350059, "record_time": 1742555350.09579, "EXCHANGE": "BITGET"}
{"action": "update", "arg": {"instType": "SPOT", "channel": "books", "instId": "BTCUSDT"}, "data": [{"asks": [["84029.41", "0.554628"], ["84032.53", "0.051607"], ["84033.48", "0"], ["84089.40", "0.002439"], ["84091.40", "0.006418"], ["84093.40", "0.016890"], ["84095.40", "0.044447"], ["84097.40", "0.116966"], ["84099.40", "0.307805"], ["84101.40", "0.810014"], ["84103.40", "2.131616"], ["84104.80", "2.267940"], ["84106.00", "0.499410"], ["84106.70", "0.274170"], ["84111.70", "0.161250"], ["84117.90", "0"], ["84145.40", "4.894387"], ["84148.72", "0"], ["84153.90", "4.713114"], ["84157.13", "0"], ["84162.40", "4.169293"], ["84170.90", "5.166297"], ["84179.40", "5.347571"], ["84187.90", "4.350566"], ["84196.40", "5.438208"], ["84204.90", "5.528845"], ["84213.40", "5.256934"], ["84230.40", "5.075661"], ["84238.90", "4.531840"], ["84255.90", "4.259930"], ["84264.40", "4.622477"], ["84272.90", "5.619481"], ["84289.90", "4.985024"], ["84306.90", "3.988019"], ["84520.00", "0.000854"], ["84520.50", "0.000238"]], "bids": [["84029.40", "1.085337"], ["84020.84", "0.027453"], ["84008.58", "0.005774"], ["83978.00", "0.000017"], ["83977.20", "4.441203"], ["83968.70", "5.256934"], ["83960.20", "4.622477"], ["83951.70", "5.528845"], ["83949.70", "0"], ["83943.20", "5.166297"], ["83941.30", "0"], ["83934.70", "5.619481"], ["83926.20", "4.894387"], ["83917.70", "5.075661"], ["83909.20", "4.803750"], ["83900.70", "3.897382"], ["83892.20", "4.259930"], ["83883.70", "5.347571"], ["83875.20", "4.713114"], ["83866.70", "3.988019"], ["83858.20", "4.531840"], ["83849.70", "4.078656"], ["83832.70", "4.169293"], ["83824.20", "4.350566"], ["83815.70", "5.438208"], ["83653.31", "0"]], "checksum": 1586031087, "ts": "1742555350274"}], "ts": 1742555350276, "record_time": 1742555350.311487, "EXCHANGE": "BITGET"}
{"action": "update", "arg": {"instType": "SPOT", "channel": "books", "instId": "BTCUSDT"}, "data": [{"asks": [["84030.19", "0.088149"], ["84030.22", "0"], ["84061.74", "0"], ["84062.45", "0.119867"], ["84093.40", "0.017132"], ["84095.40", "0.045085"], ["84097.40", "0.118645"], ["84099.40", "0.312223"], ["84101.40", "0.821641"], ["84103.40", "2.162213"], ["84104.80", "2.267760"], ["84106.00", "0"], ["84107.60", "0.015000"], ["84145.40", "5.256934"], ["84152.24", "0.001810"], ["84153.90", "4.622477"], ["84161.32", "0.003620"], ["84162.40", "4.894387"], ["84170.90", "5.347571"], ["84179.40", "5.166297"], ["84187.90", "4.713114"], ["84196.40", "4.531840"], ["84204.90", "4.078656"], ["84213.40", "4.803750"], ["84221.90", "4.441203"], ["84230.40", "3.897382"], ["84238.90", "3.988019"], ["84247.40", "5.438208"], ["84255.90", "4.985024"], ["84264.40", "4.350566"], ["84281.40", "4.259930"], ["84289.90", "4.169293"], ["84298.40", "5.528845"], ["84306.90", "5.075661"], ["84520.00", "0"], ["84520.50", "0"]], "bids": [["84029.20", "0.065362"], ["84027.20", "0.172005"], ["84025.20", "0.452643"], ["84023.20", "1.191168"], ["84021.20", "3.134651"], ["84019.20", "8.249081"], ["84015.10", "0.153580"], ["84011.20", "0"], ["84009.80", "0"], ["84007.70", "0.120000"], ["84001.95", "0.259901"], ["84001.23", "0"], ["83985.60", "0.199851"], ["83980.30", "0"], ["83977.20", "5.528845"], ["83968.70", "4.169293"], ["83960.20", "4.894387"], ["83953.36", "0.001810"], ["83951.70", "5.438208"], ["83944.96", "0.003620"], ["83943.20", "5.619481"], ["83934.70", "3.897382"], ["83926.20", "4.078656"], ["83917.70", "4.531840"], ["83909.20", "5.347571"], ["83900.70", "4.713114"], ["83892.20", "5.166297"], ["83883.70", "4.350566"], ["83875.20", "3.988019"], ["83866.70", "4.622477"], ["83858.20", "4.441203"], ["83849.70", "5.256934"], ["83841.20", "4.259930"], ["83832.70", "4.985024"], ["83824.20", "4.803750"], ["83815.70", "5.075661"], ["83653.94", "0"], ["83653.67", "0"]], "checksum": -794968390, "ts": "1742555350477"}], "ts": 1742555350481, "record_time": 1742555350.511427, "EXCHANGE": "BITGET"}
{"action": "update", "arg": {"instType": "SPOT", "channel": "books", "instId": "BTCUSDT"}, "data": [{"asks": [["84029.41", "0.894628"], ["84087.64", "0"], ["84091.40", "0.006582"], ["84093.40", "0.017322"], ["84095.40", "0.045583"], ["84097.40", "0.119956"], ["84099.40", "0.315672"], ["84101.40", "0.830716"], ["84103.40", "2.186095"], ["84145.40", "4.713114"], ["84153.90", "5.528845"], ["84170.90", "4.531840"], ["84179.40", "4.078656"], ["84187.90", "4.441203"], ["84196.40", "4.169293"], ["84204.90", "5.256934"], ["84213.40", "4.259930"], ["84221.90", "4.350566"], ["84230.40", "5.075661"], ["84238.90", "4.622477"], ["84247.40", "4.803750"], ["84255.90", "5.619481"], ["84264.40", "3.988019"], ["84272.90", "3.897382"], ["84281.40", "5.166297"], ["84289.90", "5.438208"], ["84298.40", "5.347571"], ["84306.90", "4.985024"], ["84520.00", "0.000854"]], "bids": [["83977.20", "3.988019"], ["83968.70", "4.350566"], ["83960.20", "4.078656"], ["83951.70", "5.166297"], ["83943.20", "3.897382"], ["83934.70", "4.531840"], ["83926.20", "4.803750"], ["83917.70", "4.985024"], ["83909.20", "5.619481"], ["83892.20", "4.259930"], ["83883.70", "4.441203"], ["83875.20", "5.075661"], ["83866.70", "5.438208"], ["83858.20", "4.169293"], ["83849.70", "5.347571"], ["83841.20", "4.622477"], ["83832.70", "4.894387"], ["83824.20", "5.528845"], ["83815.70", "5.256934"]], "checksum": -913592959, "ts": "1742555350682"}], "ts": 1742555350686, "record_time": 1742555350.713145, "EXCHANGE": "BITGET"}
{"action": "update", "arg": {"instType": "SPOT", "channel": "books", "instId": "BTCUSDT"}, "data": [{"asks": [["84085.39", "0"], ["84145.40", "4.441203"], ["84153.90", "4.803750"], ["84162.40", "4.078656"], ["84170.90", "4.985024"], ["84179.40", "4.531840"], ["84187.90", "5.528845"], ["84196.40", "4.259930"], ["84204.90", "4.713114"], ["84213.40", "5.619481"], ["84221.90", "4.894387"], ["84238.90", "4.350566"], ["84247.40", "4.622477"], ["84255.90", "5.256934"], ["84281.40", "5.347571"], ["84289.90", "5.166297"], ["84298.40", "5.438208"], ["84306.90", "4.169293"], ["84520.50", "0.000238"]], "bids": [["84004.90", "0.000396"], ["83999.60", "0"], ["83977.20", "5.347571"], ["83975.50", "0.000948"], ["83970.20", "0"], ["83968.70", "4.803750"], ["83960.20", "5.075661"], ["83951.70", "3.897382"], ["83943.20", "4.259930"], ["83934.70", "4.894387"], ["83926.20", "4.622477"], ["83917.70", "5.438208"], ["83909.20", "4.441203"], ["83900.70", "5.528845"], ["83892.20", "4.985024"], ["83883.70", "4.169293"], ["83875.20", "5.166297"], ["83866.70", "4.350566"], ["83858.20", "5.256934"], ["83849.70", "4.713114"], ["83841.20", "4.078656"], ["83832.70", "4.531840"], ["83824.20", "3.988019"], ["83815.70", "5.619481"]], "checksum": -913592959, "ts": "1742555350889"}], "ts": 1742555350892, "record_time": 1742555350.919308, "EXCHANGE": "BITGET"}
{"action": "update", "arg": {"instType": "SPOT", "channel": "books", "instId": "BTCUSDT"}, "data": [{"asks": [["84029.41", "0.886736"], ["84030.16", "0.088149"], ["84030.19", "0"], ["84042.67", "0.112619"], ["84043.79", "0"], ["84089.40", "0.001306"], ["84091.40", "0.003437"], ["84093.40", "0.009043"], ["84095.40", "0.023798"], ["84097.40", "0.062626"], ["84099.40", "0.164806"], ["84101.40", "0.433699"], ["84103.40", "1.141315"], ["84104.80", "2.267940"], ["84108.60", "0.683010"], ["84145.40", "3.988019"], ["84153.90", "4.985024"], ["84162.40", "5.075661"], ["84170.90", "5.347571"], ["84179.40", "4.350566"], ["84187.90", "3.897382"], ["84196.40", "5.619481"], ["84204.90", "5.166297"], ["84213.40", "5.438208"], ["84230.40", "5.256934"], ["84238.90", "5.528845"], ["84255.90", "4.803750"], ["84264.40", "4.169293"], ["84272.90", "4.259930"], ["84281.40", "4.441203"], ["84289.90", "4.078656"], ["84298.40", "4.531840"], ["84306.90", "4.713114"], ["84520.50", "0"]], "bids": [["83979.00", "0.000015"], ["83977.20", "4.803750"], ["83968.70", "4.078656"], ["83960.20", "4.713114"], ["83951.70", "5.438208"], ["83934.70", "5.619481"], ["83926.20", "3.988019"], ["83917.70", "4.441203"], ["83909.20", "4.350566"], ["83900.70", "4.531840"], ["83892.20", "5.347571"], ["83883.70", "4.622477"], ["83875.20", "5.075661"], ["83866.70", "3.897382"], ["83849.70", "5.166297"], ["83841.20", "4.169293"], ["83832.70", "4.985024"], ["83824.20", "4.894387"], ["83815.70", "5.528845"]], "checksum": 1620230638, "ts": "1742555351094"}], "ts": 1742555351097, "record_time": 1742555351.123139, "EXCHANGE": "BITGET"}
{"action": "update", "arg": {"instType": "SPOT", "channel": "books", "instId": "BTCUSDT"}, "data": [{"asks": [["84042.66", "0.033786"], ["84043.78", "0"], ["84106.70", "0.274920"], ["84145.40", "5.166297"], ["84153.90", "5.619481"], ["84162.40", "4.350566"], ["84170.90", "3.897382"], ["84179.40", "4.169293"], ["84187.90", "4.803750"], ["84196.40", "5.438208"], ["84204.90", "4.985024"], ["84213.40", "5.347571"], ["84221.90", "4.441203"], ["84230.40", "4.713114"], ["84238.90", "5.256934"], ["84247.40", "4.259930"], ["84255.90", "5.528845"], ["84264.40", "4.894387"], ["84272.90", "4.531840"], ["84281.40", "3.988019"], ["84289.90", "4.622477"], ["84298.40", "4.078656"], ["84306.90", "5.075661"]], "bids": [["84029.40", "1.073789"], ["84023.20", "1.190915"], ["84021.20", "3.133987"], ["84019.20", "8.247333"], ["83977.20", "4.713114"], ["83977.00", "0"], ["83968.70", "3.897382"], ["83960.20", "5.166297"], ["83951.70", "4.078656"], ["83943.20", "4.441203"], ["83934.70", "4.259930"], ["83926.20", "5.347571"], ["83917.70", "4.803750"], ["83909.20", "5.619481"], ["83900.70", "3.988019"], ["83892.20", "5.256934"], ["83875.20", "5.528845"], ["83866.70", "5.438208"], ["83858.20", "4.169293"], ["83849.70", "4.531840"], ["83841.20", "4.350566"], ["83832.70", "5.075661"], ["83815.70", "4.985024"], ["83653.94", "0.000133"]], "checksum": 745933225, "ts": "1742555351298"}], "ts": 1742555351302, "record_time": 1742555351.328165, "EXCHANGE": "BITGET"}
{"action": "update", "arg": {"instType": "SPOT", "channel": "books", "instId": "BTCUSDT"}, "data": [{"asks": [["84029.42", "0.000117"], ["84030.16", "0"], ["84101.40", "0.433544"], ["84103.40", "1.140905"], ["84107.50", "0.022710"], ["84108.90", "0"], ["84145.40", "5.347571"], ["84153.90", "4.259930"], ["84162.40", "3.897382"], ["84170.90", "5.528845"], ["84179.40", "5.438208"], ["84187.90", "4.985024"], ["84196.40", "4.531840"], ["84204.90", "4.894387"], ["84213.40", "4.713114"], ["84221.90", "4.169293"], ["84230.40", "5.619481"], ["84238.90", "5.166297"], ["84247.40", "5.075661"], ["84255.90", "4.350566"], ["84264.40", "3.988019"], ["84272.90", "4.622477"], ["84281.40", "4.078656"], ["84289.90", "4.441203"], ["84298.40", "5.256934"], ["84306.90", "4.803750"], ["84520.50", "0.000238"]], "bids": [["84019.20", "8.247519"], ["84007.82", "0.011361"], ["83977.20", "4.078656"], ["83977.00", "0.000017"], ["83968.70", "5.347571"], ["83951.70", "4.169293"], ["83943.20", "5.256934"], ["83934.70", "5.075661"], ["83926.20", "4.803750"], ["83917.70", "3.988019"], ["83909.20", "5.528845"], ["83900.70", "4.713114"], ["83892.20", "5.438208"], ["83883.70", "4.531840"], ["83875.20", "4.622477"], ["83866.70", "5.619481"], ["83858.20", "4.894387"], ["83849.70", "4.259930"], ["83832.70", "3.897382"], ["83824.20", "4.441203"], ["83653.94", "0"]], "checksum": 444074520, "ts": "1742555351500"}], "ts": 1742555351504, "record_time": 1742555351.530118, "EXCHANGE": "BITGET"}
{"action": "update", "arg": {"instType": "SPOT", "channel": "books", "instId": "BTCUSDT"}, "data": [{"asks": [["84029.41", "0.904974"], ["84030.14", "0.088149"], ["84080.97", "0"], ["84089.40", "0.002087"], ["84091.40", "0.005491"], ["84093.40", "0.014452"], ["84095.40", "0.038030"], ["84097.40", "0.100080"], ["84099.40", "0.263368"], ["84101.40", "0.693074"], ["84103.40", "1.823879"], ["84108.60", "0.635760"], ["84145.40", "4.078656"], ["84153.90", "4.985024"], ["84162.40", "5.619481"], ["84170.90", "4.259930"], ["84179.40", "4.713114"], ["84187.90", "4.894387"], ["84196.40", "4.803750"], ["84204.90", "5.166297"], ["84213.40", "4.169293"], ["84221.90", "4.441203"], ["84230.40", "4.622477"], ["84238.90", "5.256934"], ["84247.40", "3.897382"], ["84255.90", "5.528845"], ["84264.40", "4.531840"], ["84272.90", "4.350566"], ["84281.40", "3.988019"], ["84289.90", "5.075661"], ["84298.40", "5.438208"], ["84306.90", "5.347571"]], "bids": [["84029.20", "0.064652"], ["84027.20", "0.170137"], ["84025.20", "0.447731"], ["84023.20", "1.178237"], ["84021.20", "3.100626"], ["84019.20", "8.159541"], ["83977.20", "3.897382"], ["83968.70", "5.256934"], ["83960.20", "4.078656"], ["83951.70", "4.803750"], ["83943.20", "4.259930"], ["83934.70", "4.985024"], ["83926.20", "4.713114"], ["83917.70", "5.438208"], ["83909.20", "5.347571"], ["83900.70", "5.619481"], ["83892.20", "5.166297"], ["83875.20", "3.988019"], ["83866.70", "4.894387"], ["83858.20", "5.528845"], ["83849.70", "4.441203"], ["83841.20", "4.622477"], ["83832.70", "4.169293"], ["83824.20", "5.075661"], ["83815.70", "4.350566"]], "checksum": 1650604330, "ts": "1742555351707"}], "ts": 1742555351711, "record_time": 1742555351.736615, "EXCHANGE": "BITGET"}
{"action": "update", "arg": {"instType": "SPOT", "channel": "books", "instId": "BTCUSDT"}, "data": [{"asks": [["84080.96", "0.178243"], ["84145.40", "5.438208"], ["84153.90", "4.350566"], ["84162.40", "4.894387"], ["84170.90", "4.713114"], ["84179.40", "5.528845"], ["84187.90", "5.075661"], ["84196.40", "4.441203"], ["84204.90", "4.259930"], ["84221.90", "5.256934"], ["84230.40", "5.347571"], ["84238.90", "4.803750"], ["84247.40", "5.619481"], ["84255.90", "4.622477"], ["84264.40", "5.166297"], ["84272.90", "4.078656"], ["84281.40", "4.531840"], ["84289.90", "3.988019"], ["84298.40", "3.897382"], ["84306.90", "4.985024"], ["84520.50", "0"]], "bids": [["83978.17", "0"], ["83978.00", "0.000032"], ["83977.20", "4.078656"], ["83976.33", "0.003598"], ["83968.70", "4.350566"], ["83960.20", "4.803750"], ["83951.70", "4.259930"], ["83943.20", "5.166297"], ["83934.70", "4.531840"], ["83926.20", "3.988019"], ["83917.70", "4.894387"], ["83909.20", "4.622477"], ["83900.70", "5.075661"], ["83892.20", "5.619481"], ["83883.70", "4.713114"], ["83875.20", "5.256934"], ["83866.70", "5.438208"], ["83858.20", "4.985024"], ["83849.70", "5.528845"], ["83841.20", "5.347571"], ["83832.70", "4.441203"], ["83824.20", "3.897382"], ["83815.70", "4.169293"]], "checksum": 1650604330, "ts": "1742555351911"}], "ts": 1742555351912, "record_time": 1742555351.951792, "EXCHANGE": "BITGET"}
{"action": "update", "arg": {"instType": "SPOT", "channel": "books", "instId": "BTCUSDT"}, "data": [{"asks": [["84029.42", "0.000100"], ["84030.11", "0.088149"], ["84030.14", "0"], ["84145.40", "4.894387"], ["84153.90", "5.075661"], ["84162.40", "5.256934"], ["84170.90", "5.528845"], ["84179.40", "4.169293"], ["84187.90", "3.897382"], ["84196.40", "4.259930"], ["84204.90", "5.438208"], ["84213.40", "4.985024"], ["84221.90", "5.166297"], ["84230.40", "3.988019"], ["84238.90", "4.622477"], ["84247.40", "4.713114"], ["84255.90", "4.350566"], ["84264.40", "4.078656"], ["84272.90", "5.619481"], ["84281.40", "4.803750"], ["84289.90", "4.531840"], ["84298.40", "5.347571"], ["84306.90", "4.441203"]], "bids": [["83978.00", "0.000015"], ["83977.20", "4.441203"], ["83960.20", "3.897382"], ["83951.70", "5.528845"], ["83943.20", "4.169293"], ["83934.70", "4.078656"], ["83926.20", "4.259930"], ["83909.20", "5.166297"], ["83892.20", "4.985024"], ["83883.70", "4.803750"], ["83875.20", "3.988019"], ["83866.70", "5.347571"], ["83858.20", "5.256934"], ["83849.70", "4.713114"], ["83841.20", "5.619481"], ["83832.70", "4.622477"], ["83824.20", "5.438208"], ["83815.70", "4.531840"]], "checksum": 1580517218, "ts": "1742555352134"}], "ts": 1742555352138, "record_time": 1742555352.17381, "EXCHANGE": "BITGET"}
{"action": "update", "arg": {"instType": "SPOT", "channel": "books", "instId": "BTCUSDT"}, "data": [{"asks": [["84087.40", "0.001023"], ["84089.40", "0.002693"], ["84091.40", "0.007087"], ["84093.40", "0.018649"], ["84095.40", "0.049075"], ["84097.40", "0.129145"], ["84099.40", "0.339855"], ["84101.40", "0.894356"], ["84103.40", "2.353570"], ["84104.80", "0.833880"], ["84105.20", "2.356500"], ["84106.70", "0.274170"], ["84107.00", "0.072720"], ["84108.60", "0.635580"], ["84110.10", "0.085740"], ["84117.30", "0"], ["84117.50", "0"], ["84117.60", "0"], ["84145.40", "5.166297"], ["84153.90", "3.988019"], ["84170.90", "4.350566"], ["84179.40", "4.803750"], ["84187.90", "5.438208"], ["84196.40", "4.531840"], ["84204.90", "5.075661"], ["84221.90", "4.713114"], ["84230.40", "5.619481"], ["84238.90", "5.528845"], ["84247.40", "5.347571"], ["84255.90", "4.078656"], ["84264.40", "4.169293"], ["84272.90", "4.441203"], ["84281.40", "3.897382"], ["84289.90", "4.894387"], ["84298.40", "4.259930"], ["84306.90", "4.622477"], ["84520.50", "0.000238"], ["84520.67", "0.002384"]], "bids": [["83977.20", "4.259930"], ["83968.70", "4.622477"], ["83960.20", "4.078656"], ["83951.70", "3.897382"], ["83943.20", "4.441203"], ["83934.70", "5.438208"], ["83926.20", "5.528845"], ["83917.70", "4.169293"], ["83900.70", "4.985024"], ["83892.20", "4.803750"], ["83883.70", "5.075661"], ["83875.20", "4.894387"], ["83866.70", "3.988019"], ["83858.20", "4.350566"], ["83849.70", "4.531840"], ["83832.70", "5.256934"], ["83824.20", "5.347571"], ["83815.70", "4.713114"]], "checksum": 1580517218, "ts": "1742555352338"}], "ts": 1742555352340, "record_time": 1742555352.376263, "EXCHANGE": "BITGET"}
{"action": "update", "arg": {"instType": "SPOT", "channel": "books", "instId": "BTCUSDT"}, "data": [{"asks": [["84030.11", "0"], ["84087.40", "0.001286"], ["84089.40", "0.003383"], ["84091.40", "0.008904"], ["84093.40", "0.023432"], ["84095.40", "0.061662"], ["84097.40", "0.162268"], ["84099.40", "0.427022"], ["84101.40", "1.123741"], ["84103.40", "2.957214"], ["84104.20", "0.001770"], ["84104.80", "0.833460"], ["84110.10", "0.098130"], ["84111.70", "0.593370"], ["84111.80", "1.350000"], ["84117.20", "0"], ["84145.40", "4.259930"], ["84153.90", "5.619481"], ["84162.40", "4.894387"], ["84170.90", "4.531840"], ["84179.40", "4.441203"], ["84196.40", "5.166297"], ["84204.90", "3.988019"], ["84213.40", "4.713114"], ["84221.90", "4.622477"], ["84230.40", "4.169293"], ["84238.90", "5.075661"], ["84247.40", "4.803750"], ["84255.90", "5.528845"], ["84264.40", "3.897382"], ["84272.90", "4.350566"], ["84281.40", "5.256934"], ["84289.90", "4.078656"], ["84298.40", "5.347571"], ["84306.90", "4.985024"]], "bids": [["84029.40", "1.071430"], ["84010.90", "0"], ["83977.20", "3.897382"], ["83968.70", "5.166297"], ["83960.20", "5.256934"], ["83951.70", "4.622477"], ["83943.20", "3.988019"], ["83934.70", "5.347571"], ["83926.20", "4.803750"], ["83917.70", "4.078656"], ["83909.20", "4.713114"], ["83900.70", "4.441203"], ["83892.20", "4.531840"], ["83883.70", "4.894387"], ["83875.20", "5.528845"], ["83866.70", "5.619481"], ["83858.20", "5.075661"], ["83849.70", "4.350566"], ["83841.20", "4.259930"], ["83832.70", "5.438208"], ["83824.20", "4.985024"], ["83815.70", "4.169293"], ["83653.94", "0.000133"]], "checksum": 932061372, "ts": "1742555352543"}], "ts": 1742555352547, "record_time": 1742555352.574428, "EXCHANGE": "BITGET"}
{"action": "update", "arg": {"instType": "SPOT", "channel": "books", "instId": "BTCUSDT"}, "data": [{"asks": [["84029.41", "1.114144"], ["84030.08", "0.088149"], ["84030.69", "0.056378"], ["84032.53", "0"], ["84083.52", "0.010000"], ["84085.40", "0.001496"], ["84087.40", "0.003936"], ["84089.40", "0.010358"], ["84091.40", "0.027259"], ["84093.40", "0.071733"], ["84095.40", "0.188773"], ["84097.40", "0.496770"], ["84099.40", "1.307290"], ["84101.40", "3.440236"], ["84103.40", "9.053252"], ["84105.10", "0.010320"], ["84105.20", "0"], ["84106.10", "0.067800"], ["84106.90", "0"], ["84108.10", "0.067800"], ["84110.20", "0.178290"], ["84116.90", "0"], ["84145.40", "4.803750"], ["84153.90", "5.075661"], ["84162.40", "4.350566"], ["84170.90", "4.985024"], ["84179.40", "4.078656"], ["84187.90", "4.259930"], ["84196.40", "5.528845"], ["84213.40", "5.256934"], ["84221.90", "5.347571"], ["84230.40", "3.897382"], ["84238.90", "4.622477"], ["84247.40", "4.169293"], ["84255.90", "4.713114"], ["84264.40", "5.166297"], ["84272.90", "5.438208"], ["84281.40", "4.531840"], ["84289.90", "5.619481"], ["84298.40", "4.894387"], ["84306.90", "4.441203"], ["84329.54", "0"], ["84520.50", "0"], ["84520.67", "0"]], "bids": [["84029.40", "0.940184"], ["84029.20", "0.034838"], ["84027.20", "0.091680"], ["84025.20", "0.241262"], ["84023.20", "0.634900"], ["84021.20", "1.670790"], ["84019.20", "4.396817"], ["84018.95", "0.028180"], ["84018.10", "0"], ["84017.60", "0.155670"], ["84016.60", "0.240000"], ["84016.50", "0.180000"], ["83979.00", "0.000017"], ["83968.70", "4.894387"], ["83960.20", "4.803750"], ["83951.70", "4.350566"], ["83943.20", "4.622477"], ["83934.70", "5.438208"], ["83926.20", "5.256934"], ["83917.70", "3.988019"], ["83909.20", "4.259930"], ["83900.70", "5.528845"], ["83892.20", "5.347571"], ["83883.70", "5.075661"], ["83875.20", "4.531840"], ["83858.20", "4.985024"], ["83849.70", "4.078656"], ["83841.20", "4.441203"], ["83832.70", "4.169293"], ["83824.20", "4.713114"], ["83815.70", "5.166297"], ["83654.23", "0"], ["83653.94", "0"]], "checksum": -1768810484, "ts": "1742555352747"}], "ts": 1742555352758, "record_time": 1742555352.787788, "EXCHANGE": "BITGET"}
{"action": "update", "arg": {"instType": "SPOT", "channel": "books", "instId": "BTCUSDT"}, "data": [{"asks": [["84029.41", "0.956551"], ["84030.69", "0"], ["84040.67", "0"], ["84081.74", "0.667710"], ["84087.40", "0.004066"], ["84089.40", "0.010699"], ["84091.40", "0.028155"], ["84093.40", "0.074093"], ["84095.40", "0.194982"], ["84097.40", "0.513110"], ["84099.40", "1.350290"], ["84101.40", "3.553395"], ["84103.40", "9.351038"], ["84103.80", "0.959730"], ["84104.80", "0"], ["84105.10", "0.008250"], ["84106.10", "0.067980"], ["84106.50", "0.070380"], ["84106.70", "0.745500"], ["84108.60", "0.089640"], ["84111.30", "0.462270"], ["84112.20", "0.045540"], ["84113.50", "0"], ["84115.70", "0"], ["84116.90", "0.015120"], ["84117.20", "0.107070"], ["84117.30", "2.674740"], ["84117.50", "0.070080"], ["84117.60", "0.534660"], ["84145.40", "5.166297"], ["84153.90", "5.256934"], ["84162.40", "4.713114"], ["84170.90", "5.528845"], ["84179.40", "4.985024"], ["84187.90", "4.803750"], ["84196.40", "4.350566"], ["84204.90", "4.259930"], ["84213.40", "4.078656"], ["84221.90", "4.441203"], ["84230.40", "3.988019"], ["84238.90", "5.619481"], ["84255.90", "3.897382"], ["84264.40", "4.622477"], ["84272.90", "5.075661"], ["84281.40", "5.347571"], ["84289.90", "5.438208"], ["84306.90", "4.531840"], ["84517.86", "0"], ["84518.98", "0"], ["84520.00", "0"]], "bids": [["84029.20", "0.040288"], ["84028.21", "0.103004"], ["84027.20", "0.106019"], ["84025.20", "0.278999"], ["84023.20", "0.734206"], ["84021.48", "0.000019"], ["84021.20", "1.932123"], ["84019.20", "5.084533"], ["84019.15", "0"], ["84019.10", "0.001020"], ["84018.50", "0.454470"], ["84018.10", "0.015000"], ["84017.80", "0.015000"], ["84017.60", "0"], ["84017.50", "0.030210"], ["84017.20", "0.030000"], ["84016.60", "0"], ["84016.50", "0"], ["84016.30", "2.402160"], ["84015.20", "0"], ["84014.20", "2.799060"], ["84013.60", "0.060000"], ["84013.40", "0.360000"], ["84011.50", "0"], ["84007.90", "0"], ["84007.80", "0"], ["84007.70", "0"], ["83977.20", "4.622477"], ["83968.70", "3.988019"], ["83960.20", "4.078656"], ["83951.70", "4.169293"], ["83943.20", "4.713114"], ["83934.70", "4.985024"], ["83926.20", "4.894387"], ["83917.70", "5.256934"], ["83909.20", "5.528845"], ["83900.70", "5.075661"], ["83892.20", "5.166297"], ["83883.70", "5.438208"], ["83875.20", "4.350566"], ["83858.20", "4.259930"], ["83849.70", "5.347571"], ["83832.70", "4.531840"], ["83824.20", "4.803750"], ["83815.70", "3.897382"], ["83654.23", "0.000009"]], "checksum": -132371047, "ts": "1742555352955"}], "ts": 1742555352960, "record_time": 1742555352.987899, "EXCHANGE": "BITGET"}
{"action": "update", "arg": {"instType": "SPOT", "channel": "books", "instId": "BTCUSDT"}, "data": [{"asks": [["84029.41", "0.960051"], ["84030.06", "0.088149"], ["84030.08", "0"], ["84039.65", "0.112617"], ["84042.67", "0"], ["84081.74", "0.712464"], ["84085.40", "0.001260"], ["84087.40", "0.003315"], ["84089.40", "0.008725"], ["84091.40", "0.022959"], ["84093.40", "0.060418"], ["84095.40", "0.158997"], ["84097.40", "0.418412"], ["84099.40", "1.101085"], ["84101.40", "2.897590"], ["84103.40", "7.625237"], ["84105.10", "0"], ["84106.50", "0"], ["84108.60", "0.217110"], ["84110.10", "0.103470"], ["84111.70", "0.161250"], ["84114.50", "0.012510"], ["84153.90", "3.897382"], ["84170.90", "5.619481"], ["84179.40", "5.256934"], ["84187.90", "5.528845"], ["84196.40", "4.259930"], ["84204.90", "5.075661"], ["84213.40", "4.531840"], ["84221.90", "4.350566"], ["84230.40", "5.347571"], ["84238.90", "4.985024"], ["84247.40", "4.078656"], ["84255.90", "4.441203"], ["84264.40", "4.803750"], ["84272.90", "4.169293"], ["84281.40", "5.438208"], ["84289.90", "4.894387"], ["84298.40", "3.988019"], ["84306.90", "4.622477"], ["84517.86", "0.000016"]], "bids": [["84029.40", "1.057467"], ["84029.20", "0.045200"], ["84027.20", "0.118946"], ["84025.20", "0.313017"], ["84023.20", "0.823728"], ["84021.20", "2.167706"], ["84019.21", "0.089238"], ["84019.20", "5.704490"], ["84019.10", "0.074820"], ["84018.95", "0"], ["84018.70", "3.527010"], ["84018.50", "0.249390"], ["84017.90", "0.067980"], ["84017.60", "0.035670"], ["84017.50", "0.030000"], ["84016.30", "0.045540"], ["84014.20", "2.073150"], ["84011.40", "0.120000"], ["84007.90", "1.476000"], ["83977.20", "4.803750"], ["83968.70", "5.166297"], ["83960.20", "5.619481"], ["83951.70", "4.078656"], ["83943.20", "3.897382"], ["83934.70", "5.256934"], ["83926.20", "5.347571"], ["83917.70", "4.441203"], ["83909.20", "4.259930"], ["83900.70", "5.528845"], ["83892.20", "3.988019"], ["83883.70", "4.169293"], ["83875.20", "4.713114"], ["83866.70", "4.894387"], ["83858.20", "5.075661"], ["83849.70", "4.985024"], ["83841.20", "4.531840"], ["83832.70", "5.438208"], ["83824.20", "4.350566"], ["83815.70", "4.622477"], ["83658.54", "0"], ["83656.60", "0"], ["83655.00", "0"], ["83654.23", "0"]], "checksum": -548534947, "ts": "1742555353155"}], "ts": 1742555353164, "record_time": 1742555353.207292, "EXCHANGE": "BITGET"}
{"action": "update", "arg": {"instType": "SPOT", "channel": "books", "instId": "BTCUSDT"}, "data": [{"asks": [["84042.02", "0.003872"], ["84042.66", "0"], ["84087.40", "0.003108"], ["84089.40", "0.008179"], ["84091.40", "0.021523"], ["84093.40", "0.056639"], ["84095.40", "0.149051"], ["84097.40", "0.392241"], ["84099.40", "1.032211"], ["84101.40", "2.716345"], ["84103.40", "7.148278"], ["84111.70", "0.592530"], ["84145.40", "5.619481"], ["84153.90", "5.075661"], ["84162.40", "4.441203"], ["84170.90", "4.259930"], ["84179.40", "4.622477"], ["84187.90", "4.803750"], ["84196.40", "4.169293"], ["84204.90", "5.528845"], ["84213.40", "4.713114"], ["84221.90", "4.078656"], ["84230.40", "4.985024"], ["84238.90", "5.166297"], ["84247.40", "5.347571"], ["84255.90", "4.350566"], ["84264.40", "3.988019"], ["84272.90", "3.897382"], ["84281.40", "5.256934"], ["84289.90", "5.438208"], ["84298.40", "4.531840"], ["84306.90", "4.894387"]], "bids": [["84029.20", "0.045437"], ["84027.20", "0.119448"], ["84025.41", "0.000019"], ["84025.20", "0.314336"], ["84023.20", "0.827201"], ["84021.48", "0"], ["84021.20", "2.176845"], ["84019.20", "5.728540"], ["84016.30", "0"], ["84007.80", "0.120000"], ["83977.20", "5.075661"], ["83977.00", "0.000015"], ["83968.70", "5.528845"], ["83960.20", "4.713114"], ["83951.70", "4.531840"], ["83943.20", "5.347571"], ["83934.70", "3.897382"], ["83926.20", "5.438208"], ["83917.70", "4.259930"], ["83909.20", "4.441203"], ["83900.70", "3.988019"], ["83892.20", "4.078656"], ["83883.70", "4.894387"], ["83875.20", "5.256934"], ["83866.70", "5.166297"], ["83858.20", "4.985024"], ["83849.70", "5.619481"], ["83841.20", "4.169293"], ["83832.70", "4.803750"], ["83824.20", "4.622477"], ["83815.70", "4.350566"]], "checksum": -2063273115, "ts": "1742555353364"}], "ts": 1742555353367, "record_time": 1742555353.393227, "EXCHANGE": "BITGET"}
{"action": "update", "arg": {"instType": "SPOT", "channel": "books", "instId": "BTCUSDT"}, "data": [{"asks": [["84037.80", "0.014146"], ["84106.30", "0.072780"], ["84117.50", "0"], ["84117.60", "0"], ["84145.40", "5.256934"], ["84153.90", "4.985024"], ["84162.40", "4.259930"], ["84170.90", "5.619481"], ["84179.40", "4.441203"], ["84187.90", "3.897382"], ["84204.90", "5.166297"], ["84221.90", "5.438208"], ["84230.40", "5.528845"], ["84238.90", "5.075661"], ["84255.90", "4.894387"], ["84264.40", "4.622477"], ["84272.90", "4.350566"], ["84281.40", "4.803750"], ["84289.90", "4.531840"], ["84298.40", "4.078656"], ["84306.90", "3.988019"]], "bids": [["84029.20", "0.054150"], ["84027.20", "0.142500"], ["84025.20", "0.375000"], ["84023.20", "0.986842"], ["84021.20", "2.596953"], ["84019.20", "6.834086"], ["83977.20", "4.531840"], ["83968.70", "4.894387"], ["83960.20", "5.619481"], ["83951.70", "5.438208"], ["83934.70", "4.713114"], ["83926.20", "4.622477"], ["83917.70", "3.897382"], ["83909.20", "4.078656"], ["83900.70", "5.075661"], ["83892.20", "4.803750"], ["83883.70", "4.350566"], ["83875.20", "5.166297"], ["83866.70", "4.441203"], ["83858.20", "5.256934"], ["83849.70", "4.985024"], ["83841.20", "3.988019"], ["83832.70", "4.259930"], ["83824.20", "4.169293"], ["83815.70", "5.528845"]], "checksum": 646551625, "ts": "1742555353577"}], "ts": 1742555353581, "record_time": 1742555353.606973, "EXCHANGE": "BITGET"}
{"action": "update", "arg": {"instType": "SPOT", "channel": "books", "instId": "BTCUSDT"}, "data": [{"asks": [["84030.03", "0.088149"], ["84030.06", "0"], ["84037.79", "0.004244"], ["84083.06", "0.001598"], ["84084.92", "0.001597"], ["84090.19", "0"], ["84092.43", "0"], ["84145.40", "5.528845"], ["84153.90", "4.531840"], ["84162.40", "4.350566"], ["84170.90", "4.169293"], ["84179.40", "5.438208"], ["84187.90", "4.803750"], ["84196.40", "5.075661"], ["84204.90", "4.622477"], ["84213.40", "5.166297"], ["84221.90", "4.894387"], ["84230.40", "3.988019"], ["84238.90", "5.619481"], ["84247.40", "4.259930"], ["84255.90", "4.078656"], ["84264.40", "4.985024"], ["84272.90", "5.256934"], ["84281.40", "3.897382"], ["84289.90", "4.441203"], ["84298.40", "4.713114"], ["84306.90", "5.347571"], ["84517.86", "0"]], "bids": [["84029.40", "1.049575"], ["84029.20", "0.039782"], ["84028.21", "0.145501"], ["84027.20", "0.104689"], ["84025.20", "0.275497"], ["84023.20", "0.724991"], ["84021.20", "1.907872"], ["84019.21", "0"], ["84019.20", "5.020717"], ["84019.10", "0.435090"], ["84018.80", "0.016560"], ["84018.50", "0"], ["84017.90", "0.068190"], ["83979.94", "0"], ["83978.31", "0"], ["83977.20", "4.078656"], ["83972.81", "0.001176"], ["83970.81", "0.001173"], ["83968.70", "4.169293"], ["83960.20", "4.441203"], ["83951.70", "4.531840"], ["83943.20", "5.256934"], ["83934.70", "3.897382"], ["83926.20", "4.350566"], ["83917.70", "4.985024"], ["83909.20", "4.622477"], ["83900.70", "4.713114"], ["83892.20", "5.528845"], ["83883.70", "3.988019"], ["83875.20", "5.619481"], ["83866.70", "5.075661"], ["83858.20", "5.347571"], ["83849.70", "5.166297"], ["83841.20", "4.894387"], ["83832.70", "5.438208"], ["83824.20", "4.803750"], ["83815.70", "4.259930"], ["83658.54", "0.000036"]], "checksum": -338270257, "ts": "1742555353790"}], "ts": 1742555353793, "record_time": 1742555353.8186, "EXCHANGE": "BITGET"}
{"action": "update", "arg": {"instType": "SPOT", "channel": "books", "instId": "BTCUSDT"}, "data": [{"asks": [["84029.41", "0.967051"], ["84029.42", "0.000117"], ["84087.40", "0.003256"], ["84089.40", "0.008570"], ["84091.40", "0.022552"], ["84093.40", "0.059346"], ["84095.40", "0.156174"], ["84097.40", "0.410985"], ["84099.40", "1.081539"], ["84101.40", "2.846157"], ["84103.40", "7.489885"], ["84153.90", "4.894387"], ["84162.40", "5.166297"], ["84170.90", "5.619481"], ["84179.40", "4.078656"], ["84187.90", "5.438208"], ["84196.40", "4.350566"], ["84204.90", "4.803750"], ["84213.40", "4.531840"], ["84221.90", "4.622477"], ["84230.40", "4.441203"], ["84238.90", "4.169293"], ["84247.40", "4.985024"], ["84255.90", "3.897382"], ["84264.40", "5.256934"], ["84272.90", "5.075661"], ["84281.40", "4.259930"], ["84289.90", "3.988019"]], "bids": [["84029.40", "1.049560"], ["84029.20", "0.040604"], ["84027.20", "0.106977"], ["84025.20", "0.281518"], ["84023.20", "0.740838"], ["84021.20", "1.949573"], ["84019.20", "5.130457"], ["84018.80", "0"], ["84018.70", "3.170940"], ["84017.60", "0.016470"], ["84007.70", "0.120000"], ["83995.99", "0"], ["83992.04", "0.000877"], ["83978.00", "0.000032"], ["83977.20", "4.169293"], ["83968.70", "4.622477"], ["83960.20", "3.897382"], ["83951.70", "5.528845"], ["83943.20", "4.350566"], ["83934.70", "4.985024"], ["83926.20", "4.259930"], ["83917.70", "3.988019"], ["83909.20", "5.075661"], ["83892.20", "4.803750"], ["83883.70", "5.256934"], ["83875.20", "4.078656"], ["83866.70", "4.531840"], ["83858.20", "5.619481"], ["83849.70", "5.347571"], ["83841.20", "5.438208"], ["83832.70", "4.894387"], ["83824.20", "4.441203"], ["83815.70", "5.166297"]], "checksum": 273004136, "ts": "1742555354003"}], "ts": 1742555354007, "record_time": 1742555354.034017, "EXCHANGE": "BITGET"}
{"action": "update", "arg": {"instType": "SPOT", "channel": "books", "instId": "BTCUSDT"}, "data": [{"asks": [["84049.03", "0.035952"], ["84049.55", "0.119870"], ["84050.79", "0.035961"], ["84051.21", "0.006356"], ["84051.36", "0.006356"], ["84051.71", "0.006356"], ["84052.77", "0.010984"], ["84052.92", "0"], ["84053.04", "0.006356"], ["84053.20", "0.006356"], ["84053.28", "0"], ["84053.67", "0.016429"], ["84053.73", "0.006356"], ["84054.23", "0.006356"], ["84054.26", "0.006356"], ["84054.46", "0"], ["84054.56", "0.119883"], ["84054.61", "0.016429"], ["84054.67", "0.006356"], ["84054.71", "0.006356"], ["84054.89", "0"], ["84055.27", "0"], ["84055.38", "0"], ["84056.20", "0.006357"], ["84056.29", "0.010985"], ["84056.61", "0"], ["84056.95", "0"], ["84057.11", "0"], ["84057.40", "0"], ["84057.59", "0"], ["84057.91", "0"], ["84057.94", "0.119850"], ["84057.99", "0"], ["84058.37", "0"], ["84058.47", "0"], ["84058.55", "0"], ["84058.62", "0"], ["84059.01", "0.252088"], ["84059.48", "0.015895"], ["84059.59", "0.009989"], ["84060.05", "0"], ["84060.11", "0"], ["84061.83", "0"], ["84062.92", "0"], ["84063.24", "0"], ["84063.43", "0.015892"], ["84063.50", "0"], ["84064.27", "0.010988"], ["84067.19", "0"], ["84068.03", "0"], ["84080.96", "0"], ["84087.40", "0.003243"], ["84089.40", "0.008533"], ["84091.40", "0.022456"], ["84093.40", "0.059093"], ["84095.40", "0.155509"], ["84097.40", "0.409233"], ["84099.40", "1.076931"], ["84101.40", "2.834027"], ["84103.40", "7.457968"], ["84109.00", "0.070530"], ["84117.30", "0"], ["84145.40", "4.713114"], ["84162.40", "4.078656"], ["84179.40", "5.347571"], ["84187.90", "4.259930"], ["84196.40", "5.166297"], ["84213.40", "3.897382"], ["84221.90", "5.256934"], ["84230.40", "5.528845"], ["84238.90", "4.622477"], ["84247.40", "4.441203"], ["84255.90", "4.169293"], ["84264.40", "4.985024"], ["84272.90", "5.438208"], ["84281.40", "4.350566"], ["84289.90", "4.531840"], ["84298.40", "3.988019"], ["84306.90", "5.075661"], ["84517.86", "0.000016"], ["84518.98", "0.000029"]], "bids": [["84029.20", "0.043265"], ["84027.20", "0.113856"], ["84025.20", "0.299620"], ["84023.20", "0.788474"], ["84021.20", "2.074932"], ["84019.20", "5.460346"], ["84018.70", "0.813750"], ["84017.60", "0.035250"], ["84016.90", "2.356590"], ["84012.58", "0"], ["84012.11", "0"], ["84010.77", "0"], ["84010.40", "0"], ["84010.35", "0"], ["84010.30", "1.844160"], ["84009.84", "0"], ["84008.88", "0"], ["84008.72", "0"], ["84008.69", "0.089521"], ["84008.54", "0"], ["84008.38", "0.247687"], ["84008.01", "0"], ["84007.82", "0.004019"], ["84007.70", "0"], ["84007.40", "0"], ["84007.33", "0"], ["84007.21", "0"], ["84007.11", "0.008019"], ["84007.09", "0.083974"], ["84007.03", "0.008601"], ["84006.96", "0"], ["84006.67", "0.017824"], ["84006.49", "0.018262"], ["84006.17", "0.005949"], ["84005.49", "0"], ["84005.43", "0"], ["84005.04", "0.055678"], ["84004.81", "0.017110"], ["84004.63", "0.007134"], ["84004.15", "0.007342"], ["84004.09", "0.028876"], ["84003.68", "0"], ["84003.67", "0.007946"], ["84003.65", "0.008998"], ["84003.35", "0.025195"], ["84003.30", "0.224973"], ["84003.12", "0.017358"], ["84003.07", "0.008188"], ["84002.75", "0"], ["84002.24", "0"], ["84002.15", "0"], ["84001.67", "0.051984"], ["84001.58", "0.012660"], ["83999.79", "0.268485"], ["83998.84", "0.222759"], ["83998.48", "0.076143"], ["83998.28", "0"], ["83998.25", "0.021138"], ["83997.44", "0"], ["83994.53", "0.073244"], ["83993.69", "0.056390"], ["83977.20", "4.078656"], ["83968.70", "4.531840"], ["83960.20", "4.259930"], ["83943.20", "5.619481"], ["83926.20", "4.169293"], ["83917.70", "3.897382"], ["83909.20", "3.988019"], ["83900.70", "4.803750"], ["83892.20", "5.256934"], ["83883.70", "4.441203"], ["83875.20", "4.350566"], ["83866.70", "4.622477"], ["83858.20", "4.713114"], ["83841.20", "4.894387"], ["83832.70", "5.438208"], ["83824.20", "5.166297"], ["83815.70", "5.075661"], ["83659.49", "0"], ["83659.44", "0"], ["83658.54", "0"]], "checksum": -1145054688, "ts": "1742555354208"}], "ts": 1742555354211, "record_time": 1742555354.241093, "EXCHANGE": "BITGET"}
{"action": "update", "arg": {"instType": "SPOT", "channel": "books", "instId": "BTCUSDT"}, "data": [{"asks": [["84030.01", "0.088149"], ["84030.03", "0"], ["84046.22", "0.100498"], ["84059.01", "0.163918"], ["84106.30", "0.095490"], ["84107.50", "0"], ["84145.40", "4.078656"], ["84153.90", "5.347571"], ["84162.40", "5.075661"], ["84170.90", "4.350566"], ["84179.40", "5.528845"], ["84187.90", "4.803750"], ["84196.40", "4.259930"], ["84204.90", "4.441203"], ["84213.40", "4.713114"], ["84221.90", "5.619481"], ["84230.40", "4.985024"], ["84238.90", "3.988019"], ["84247.40", "4.531840"], ["84255.90", "3.897382"], ["84264.40", "5.256934"], ["84272.90", "4.169293"], ["84281.40", "4.894387"], ["84289.90", "5.438208"], ["84298.40", "4.622477"], ["84306.90", "5.166297"], ["84520.00", "0.000854"]], "bids": [["84029.40", "1.049537"], ["84018.80", "0.010110"], ["84007.80", "0"], ["83978.00", "0.000017"], ["83968.70", "4.985024"], ["83960.20", "4.350566"], ["83951.70", "5.256934"], ["83934.70", "5.166297"], ["83926.20", "3.988019"], ["83909.20", "5.347571"], ["83900.70", "5.438208"], ["83892.20", "5.075661"], ["83883.70", "4.803750"], ["83875.20", "4.169293"], ["83866.70", "4.894387"], ["83858.20", "5.528845"], ["83849.70", "4.259930"], ["83841.20", "4.713114"], ["83832.70", "4.622477"], ["83824.20", "4.441203"], ["83815.70", "4.531840"]], "checksum": -411090337, "ts": "1742555354418"}], "ts": 1742555354420, "record_time": 1742555354.455446, "EXCHANGE": "BITGET"}
{"action": "update", "arg": {"instType": "SPOT", "channel": "books", "instId": "BTCUSDT"}, "data": [{"asks": [["84057.10", "0.009990"], ["84060.77", "0"], ["84078.88", "0.185300"], ["84083.52", "0"], ["84106.69", "0.039647"], ["84145.40", "5.075661"], ["84153.90", "5.166297"], ["84162.40", "4.713114"], ["84170.90", "4.531840"], ["84179.40", "4.350566"], ["84187.90", "4.169293"], ["84196.40", "3.897382"], ["84204.90", "5.438208"], ["84213.40", "4.259930"], ["84221.90", "4.894387"], ["84230.40", "5.256934"], ["84238.90", "4.078656"], ["84247.40", "4.441203"], ["84255.90", "5.528845"], ["84264.40", "4.803750"], ["84272.90", "5.347571"], ["84281.40", "4.622477"], ["84289.90", "3.988019"], ["84298.40", "4.985024"], ["84306.90", "5.619481"], ["84520.00", "0"]], "bids": [["84004.46", "0"], ["84000.80", "0.018524"], ["83977.20", "3.897382"], ["83968.70", "5.347571"], ["83951.70", "4.441203"], ["83943.20", "4.169293"], ["83934.70", "5.256934"], ["83926.20", "4.078656"], ["83917.70", "5.528845"], ["83909.20", "4.259930"], ["83900.70", "3.988019"], ["83892.20", "4.531840"], ["83883.70", "5.438208"], ["83875.20", "5.619481"], ["83866.70", "4.803750"], ["83858.20", "4.985024"], ["83849.70", "5.166297"], ["83832.70", "4.894387"], ["83824.20", "5.075661"], ["83815.70", "4.622477"]], "checksum": -411090337, "ts": "1742555354625"}], "ts": 1742555354629, "record_time": 1742555354.654696, "EXCHANGE": "BITGET"}
{"action": "update", "arg": {"instType": "SPOT", "channel": "books", "instId": "BTCUSDT"}, "data": [{"asks": [["84029.42", "0.000100"], ["84029.99", "0.088149"], ["84030.01", "0"], ["84110.20", "0"], ["84117.30", "2.674740"], ["84145.40", "4.259930"], ["84153.90", "5.075661"], ["84162.40", "4.985024"], ["84170.90", "3.897382"], ["84179.40", "4.713114"], ["84187.90", "4.531840"], ["84196.40", "4.894387"], ["84204.90", "5.347571"], ["84213.40", "5.256934"], ["84221.90", "5.619481"], ["84230.40", "5.438208"], ["84238.90", "5.166297"], ["84247.40", "4.350566"], ["84255.90", "3.988019"], ["84264.40", "4.078656"], ["84272.90", "5.528845"], ["84281.40", "4.169293"], ["84289.90", "4.441203"], ["84298.40", "4.622477"], ["84306.90", "4.803750"]], "bids": [["84029.20", "0.043386"], ["84027.20", "0.113984"], ["84026.34", "0.000019"], ["84025.41", "0"], ["84025.20", "0.299957"], ["84023.20", "0.789360"], ["84021.20", "2.077264"], ["84019.20", "5.466484"], ["84018.80", "0.010350"], ["84010.30", "1.281840"], ["83979.00", "0"], ["83977.20", "5.075661"], ["83968.70", "3.897382"], ["83960.20", "4.259930"], ["83951.70", "4.985024"], ["83943.20", "5.347571"], ["83934.70", "4.169293"], ["83926.20", "4.894387"], ["83917.70", "3.988019"], ["83909.20", "4.713114"], ["83900.70", "4.078656"], ["83892.20", "4.350566"], ["83883.70", "5.166297"], ["83875.20", "5.528845"], ["83866.70", "4.622477"], ["83858.20", "4.803750"], ["83849.70", "5.438208"], ["83841.20", "4.531840"], ["83832.70", "4.441203"], ["83824.20", "5.256934"], ["83815.70", "5.619481"], ["83659.49", "0.000012"]], "checksum": -2076191864, "ts": "1742555354832"}], "ts": 1742555354835, "record_time": 1742555354.863003, "EXCHANGE": "BITGET"}
{"action": "update", "arg": {"instType": "SPOT", "channel": "books", "instId": "BTCUSDT"}, "data": [{"asks": [["84059.01", "0.207936"], ["84087.40", "0.003267"], ["84089.40", "0.008596"], ["84091.40", "0.022622"], ["84093.40", "0.059531"], ["84095.40", "0.156661"], ["84097.40", "0.412266"], ["84099.40", "1.084910"], ["84101.40", "2.855027"], ["84103.40", "7.513228"], ["84106.30", "0.107490"], ["84107.60", "0"], ["84110.20", "0.178290"], ["84116.40", "2.735370"], ["84117.20", "0"], ["84117.30", "0"], ["84145.40", "5.256934"], ["84153.90", "4.894387"], ["84162.40", "5.075661"], ["84170.90", "4.713114"], ["84179.40", "3.897382"], ["84187.90", "5.438208"], ["84196.40", "5.166297"], ["84204.90", "5.528845"], ["84213.40", "4.078656"], ["84221.90", "4.169293"], ["84230.40", "4.803750"], ["84238.90", "3.988019"], ["84247.40", "4.622477"], ["84255.90", "4.259930"], ["84264.40", "4.985024"], ["84272.90", "5.347571"], ["84281.40", "4.350566"], ["84298.40", "5.619481"], ["84306.90", "4.531840"], ["84520.00", "0.000854"], ["84520.50", "0.000238"]], "bids": [["84021.20", "2.077158"], ["84019.20", "5.466224"], ["84018.80", "0"], ["84007.80", "0.120000"], ["83977.20", "4.803750"], ["83968.70", "5.528845"], ["83960.20", "5.256934"], ["83951.70", "5.619481"], ["83943.20", "4.169293"], ["83934.70", "3.988019"], ["83926.20", "4.350566"], ["83917.70", "5.166297"], ["83909.20", "4.441203"], ["83900.70", "4.894387"], ["83892.20", "4.078656"], ["83883.70", "5.075661"], ["83875.20", "4.713114"], ["83858.20", "5.347571"], ["83849.70", "4.985024"], ["83841.20", "4.259930"], ["83832.70", "4.531840"], ["83824.20", "3.897382"], ["83815.70", "5.438208"]], "checksum": -2076191864, "ts": "1742555355039"}], "ts": 1742555355042, "record_time": 1742555355.068605, "EXCHANGE": "BITGET"}
