{"action": "update", "arg": {"instType": "SPOT", "channel": "books", "instId": "BTCUSDT"}, "data": [{"asks": [["84089.99", "2.139535"], ["84090.00", "0.245235"], ["84092.24", "0.017449"], ["84093.60", "0.155822"], ["84095.26", "0.035961"], ["84095.27", "0.006356"], ["84095.46", "0.006356"], ["84097.19", "0.006356"], ["84097.34", "0.006356"], ["84097.46", "0.010984"], ["84098.10", "0.006356"], ["84098.28", "0.006356"], ["84098.35", "0.006356"], ["84098.57", "0.006356"], ["84098.74", "0.006356"], ["84099.60", "0"], ["84100.48", "0.006357"], ["84101.35", "0"], ["84102.39", "0"], ["84103.03", "0"], ["84103.33", "0.015895"], ["84103.59", "0"], ["84103.74", "0"], ["84104.09", "0"], ["84105.14", "0"], ["84105.30", "0"], ["84105.34", "0"], ["84105.67", "0"], ["84106.00", "0"], ["84106.11", "0"], ["84106.30", "0"], ["84106.63", "0"], ["84106.80", "0"], ["84106.85", "0"], ["84107.13", "0"], ["84108.65", "0"], ["84108.66", "0"], ["84111.69", "0"], ["84113.62", "0.010000"], ["84120.00", "0.181293"], ["84121.00", "0.001029"], ["84123.00", "0.001000"], ["84125.00", "0.001033"], ["84127.00", "0.001048"], ["84128.58", "0"], ["84129.00", "0.001247"], ["84129.27", "0"], ["84129.30", "0"], ["84131.00", "0.003283"], ["84131.30", "0"], ["84132.12", "0.713164"], ["84132.20", "0.000958"], ["84133.00", "0.008638"], ["84133.30", "0"], ["84135.00", "0.022732"], ["84135.30", "0"], ["84136.60", "0"], ["84137.00", "0.059822"], ["84137.30", "0"], ["84139.00", "0.157425"], ["84139.30", "0"], ["84141.00", "0.414278"], ["84141.30", "0"], ["84141.80", "0.207473"], ["84142.10", "14.055930"], ["84142.20", "10.843500"], ["84142.30", "2.429550"], ["84142.70", "0.361980"], ["84143.30", "0"], ["84144.10", "0.067980"], ["84144.80", "1.868850"], ["84145.30", "0"], ["84146.10", "0.067980"], ["84146.20", "0.024930"], ["84147.00", "1.246230"], ["84147.30", "0"], ["84148.10", "0.067980"], ["84148.70", "1.000020"], ["84149.20", "1.372830"], ["84149.30", "1.543170"], ["84150.10", "0.067800"], ["84150.50", "0.071460"], ["84152.10", "0.269850"], ["84152.20", "0"], ["84152.80", "0"], ["84153.50", "0.295590"], ["84153.60", "0"], ["84154.20", "0"], ["84155.00", "0.120000"], ["84155.80", "2.569170"], ["84156.10", "0.067800"], ["84156.30", "1.390800"], ["84156.50", "0.011280"], ["84156.70", "0"], ["84156.90", "0"], ["84157.30", "0.249120"], ["84158.10", "1.241610"], ["84158.30", "0.321060"], ["84159.60", "2.569050"], ["84159.70", "0.178200"], ["84159.90", "0"], ["84160.10", "0"], ["84160.30", "0"], ["84160.40", "0"], ["84160.90", "0"], ["84161.60", "0"], ["84161.80", "0"], ["84162.00", "0"], ["84162.10", "0"], ["84162.30", "0"], ["84162.60", "0"], ["84162.70", "0"], ["84163.10", "0"], ["84163.50", "0"], ["84163.90", "0"], ["84164.10", "0"], ["84164.20", "0"], ["84164.30", "0"], ["84164.40", "0"], ["84164.80", "0"], ["84172.50", "0"], ["84182.80", "5.073407"], ["84191.30", "4.076845"], ["84199.80", "4.529828"], ["84208.30", "4.258038"], ["84216.80", "5.345196"], ["84225.30", "4.892214"], ["84233.80", "4.439231"], ["84242.30", "5.435793"], ["84250.80", "3.986248"], ["84259.30", "5.616986"], ["84267.80", "4.620424"], ["84276.30", "4.982810"], ["84284.80", "4.711021"], ["84293.30", "4.167441"], ["84301.80", "5.164003"], ["84310.30", "5.526389"], ["84318.80", "5.254600"], ["84327.30", "3.895652"], ["84335.80", "4.348634"], ["84344.30", "4.801617"], ["84352.80", "0"], ["84535.32", "0.000039"], ["84536.36", "0.000053"], ["84537.04", "0.000958"], ["84538.75", "0.000011"], ["84540.00", "0.001092"], ["84540.54", "0.000184"], ["84540.97", "0.000065"], ["84541.67", "0.000198"], ["84542.37", "0.001213"], ["84543.27", "0.000067"]], "bids": [["84089.98", "0"], ["84089.97", "0"], ["84089.96", "0"], ["84089.95", "0"], ["84089.00", "0"], ["84085.00", "0.000015"], ["84083.38", "0"], ["84083.00", "0"], ["84081.00", "0.000017"], ["84079.93", "0"], ["84079.90", "0"], ["84079.00", "0.000017"], ["84078.05", "0"], ["84077.00", "0.000017"], ["84076.30", "0.001041"], ["84075.85", "0"], ["84075.00", "0.000032"], ["84074.30", "0.001049"], ["84073.66", "0.012472"], ["84073.00", "0.000032"], ["84072.30", "0.001004"], ["84072.10", "0"], ["84071.13", "0"], ["84071.10", "0"], ["84071.00", "0.000032"], ["84070.94", "0"], ["84070.93", "0"], ["84070.92", "0"], ["84070.88", "0"], ["84070.85", "0"], ["84070.74", "0.000233"], ["84070.30", "0.001027"], ["84069.00", "0.000032"], ["84068.30", "0.001038"], ["84067.03", "0"], ["84067.00", "0.000032"], ["84066.98", "0"], ["84066.95", "0"], ["84066.83", "0"], ["84066.82", "0"], ["84066.75", "0"], ["84066.73", "0"], ["84066.39", "0"], ["84066.30", "0.001018"], ["84065.00", "0.000032"], ["84064.80", "0"], ["84064.60", "0"], ["84064.50", "0"], ["84064.30", "0.001002"], ["84064.10", "0"], ["84063.90", "0"], ["84063.43", "0"], ["84062.80", "0"], ["84062.72", "0.015917"], ["84062.68", "0.008499"], ["84062.30", "0.001028"], ["84061.50", "0"], ["84061.40", "0"], ["84061.19", "0"], ["84061.10", "0"], ["84060.99", "0"], ["84060.80", "0"], ["84060.60", "0"], ["84060.30", "0.001029"], ["84060.20", "0"], ["84059.90", "0"], ["84059.80", "0"], ["84059.70", "0"], ["84059.50", "0"], ["84059.31", "0"], ["84059.03", "0"], ["84058.84", "0"], ["84058.61", "0.008711"], ["84058.60", "0"], ["84058.51", "0"], ["84058.30", "0.001005"], ["84058.20", "0"], ["84058.10", "0"], ["84058.00", "0.000032"], ["84057.92", "0"], ["84057.70", "0"], ["84056.89", "0.027453"], ["84056.88", "0"], ["84056.80", "0"], ["84056.70", "0"], ["84056.60", "0"], ["84056.50", "0"], ["84056.39", "0"], ["84056.30", "0.001041"], ["84056.01", "0"], ["84056.00", "0.001011"], ["84055.95", "0"], ["84055.90", "0.001042"], ["84055.70", "0.003600"], ["84055.68", "0"], ["84055.60", "0"], ["84055.56", "0"], ["84055.50", "0"], ["84055.30", "0"], ["84055.18", "0"], ["84055.10", "0.002820"], ["84054.70", "0.008790"], ["84054.32", "0"], ["84054.31", "0"], ["84054.01", "0"], ["84054.00", "0.000032"], ["84053.70", "0"], ["84053.40", "0.120390"], ["84053.24", "0.089456"], ["84053.10", "0.011100"], ["84052.60", "0.120390"], ["84052.50", "0.469200"], ["84052.10", "1.432710"], ["84051.54", "0.083913"], ["84051.20", "0.066180"], ["84050.90", "0.072510"], ["84050.65", "0"], ["84050.64", "0.017811"], ["84050.60", "0.022740"], ["84050.56", "0.018249"], ["84050.24", "3.052115"], ["84049.70", "0.061582"], ["84049.20", "0.120000"], ["84048.93", "0.017098"], ["84048.80", "0.870810"], ["84048.75", "0.007129"], ["84048.70", "2.673330"], ["84048.50", "0.007337"], ["84048.40", "0.120000"], ["84047.96", "0.008991"], ["84047.80", "2.783310"], ["84047.74", "0.007940"], ["84047.53", "0.008267"], ["84047.50", "0.240000"], ["84047.40", "0.012540"], ["84047.20", "0.065640"], ["84046.80", "0.035640"], ["84046.10", "0.144510"], ["84046.06", "0"], ["84045.93", "0"], ["84045.90", "0"], ["84045.88", "0"], ["84045.84", "0.012651"], ["84045.76", "0"], ["84045.72", "0"], ["84045.66", "0"], ["84045.62", "0"], ["84045.50", "0.120000"], ["84045.40", "2.316870"], ["84045.30", "1.350000"], ["84044.60", "0.153580"], ["84043.50", "0"], ["84042.29", "0.076088"], ["84039.75", "0"], ["84038.64", "0"], ["84038.55", "0"], ["84038.51", "0"], ["84038.00", "0.000017"], ["84037.31", "0.009208"], ["84037.26", "0.006904"], ["84035.00", "0.000396"], ["84030.10", "0.005051"], ["84026.66", "0.017449"], ["84024.20", "0"], ["84023.00", "0"], ["84022.78", "0"], ["84019.87", "0"], ["84017.33", "0"], ["84017.31", "0"], ["84017.14", "0"], ["84015.10", "0.200459"], ["84014.50", "4.801617"], ["84014.38", "0.007432"], ["84014.10", "0"], ["84011.47", "0.008570"], ["84009.13", "0.007650"], ["84009.11", "0.007246"], ["84008.97", "0.007334"], ["84006.00", "5.345196"], ["84005.60", "0.000948"], ["83997.50", "4.711021"], ["83989.00", "4.620424"], ["83980.50", "5.526389"], ["83972.00", "4.529828"], ["83963.50", "3.986248"], ["83955.00", "4.076845"], ["83946.50", "5.164003"], ["83938.00", "4.439231"], ["83929.50", "4.258038"], ["83921.00", "4.982810"], ["83912.50", "5.616986"], ["83904.00", "4.892214"], ["83895.50", "5.254600"], ["83887.00", "4.167441"], ["83878.50", "4.348634"], ["83873.68", "0.209200"], ["83870.00", "5.435793"], ["83861.50", "3.895652"], ["83853.00", "5.073407"], ["83658.54", "0.000036"], ["83656.60", "0.000607"], ["83655.00", "0.000926"], ["83654.23", "0.000009"], ["83653.94", "0.000133"], ["83653.67", "0.001695"], ["83653.31", "0.000015"], ["83652.80", "0.000119"], ["83652.48", "0.000188"], ["83651.65", "0.000018"], ["83651.16", "0.000896"], ["83650.84", "0.003326"], ["83650.00", "0.032056"], ["83648.96", "0.000030"], ["83647.46", "0.000224"], ["83647.06", "0.000040"], ["83646.67", "0.000018"], ["83645.83", "0.000014"], ["83644.86", "0.000034"], ["83644.33", "0.000013"], ["83643.18", "0.000052"], ["83641.86", "0.000379"], ["83641.62", "0.002925"], ["83641.38", "0.000135"]], "checksum": 1415084557, "ts": "1742554954297"}], "ts": 1742554954301, "record_time": 1742554954.325897, "EXCHANGE": "BITGET"}
{"action": "update", "arg": {"instType": "SPOT", "channel": "books", "instId": "BTCUSDT"}, "data": [{"asks": [["84082.01", "0.399244"], ["84083.81", "0.209200"], ["84083.91", "1.216200"], ["84085.78", "0.245840"], ["84088.01", "0.298236"], ["84089.01", "0.209200"], ["84089.98", "0.012472"], ["84089.99", "0.320059"], ["84090.00", "0.209759"], ["84092.54", "0.089656"], ["84095.20", "0.006356"], ["84097.14", "0.016429"], ["84098.07", "0"], ["84098.12", "0.119883"], ["84098.40", "0.068481"], ["84098.65", "0.016429"], ["84100.56", "0.010985"], ["84100.86", "0"], ["84100.92", "0.009990"], ["84102.02", "0.119850"], ["84102.68", "0.119858"], ["84103.27", "0.009989"], ["84103.55", "0.119867"], ["84106.10", "0"], ["84106.64", "0"], ["84107.75", "0.015892"], ["84107.90", "0.010988"], ["84109.35", "0"], ["84110.28", "0"], ["84111.19", "0"], ["84111.53", "0"], ["84111.80", "0"], ["84115.72", "0"], ["84116.42", "0"], ["84119.40", "0.001227"], ["84121.00", "0"], ["84121.40", "0.002002"], ["84123.00", "0"], ["84123.40", "0.005269"], ["84125.00", "0"], ["84125.40", "0.013865"], ["84126.21", "0"], ["84127.00", "0"], ["84127.40", "0.036486"], ["84129.00", "0"], ["84129.40", "0.096209"], ["84131.00", "0"], ["84131.40", "0.253182"], ["84133.00", "0"], ["84133.40", "0.666268"], ["84135.00", "0"], ["84135.40", "1.753338"], ["84137.00", "0"], ["84137.40", "4.614047"], ["84139.00", "0"], ["84139.40", "12.142229"], ["84140.00", "0.144690"], ["84140.10", "0.067980"], ["84140.50", "8.611140"], ["84141.00", "0"], ["84142.00", "0.178380"], ["84142.10", "0.068160"], ["84142.20", "0"], ["84142.30", "0"], ["84142.70", "0"], ["84143.00", "0.071640"], ["84143.70", "0.022770"], ["84144.80", "0.586800"], ["84145.90", "0.120180"], ["84147.00", "1.955220"], ["84148.10", "0.067800"], ["84148.70", "0.999660"], ["84149.20", "1.351740"], ["84149.30", "0.048030"], ["84150.50", "0.499410"], ["84150.80", "3.448050"], ["84152.10", "0.067800"], ["84153.50", "0.290160"], ["84154.10", "0.456000"], ["84155.00", "0"], ["84155.70", "1.190190"], ["84156.30", "1.069320"], ["84158.10", "0"], ["84158.30", "0"], ["84158.90", "0"], ["84159.60", "0"], ["84159.70", "0"], ["84181.40", "4.892294"], ["84182.80", "0"], ["84189.90", "4.076912"], ["84191.30", "0"], ["84198.40", "4.439304"], ["84199.80", "0"], ["84206.90", "5.617079"], ["84208.30", "0"], ["84215.40", "5.345284"], ["84216.80", "0"], ["84223.90", "3.986314"], ["84225.30", "0"], ["84232.40", "4.258108"], ["84233.80", "0"], ["84240.90", "4.620500"], ["84242.30", "0"], ["84249.40", "5.254686"], ["84250.80", "0"], ["84257.90", "4.982892"], ["84259.30", "0"], ["84266.40", "3.895716"], ["84267.80", "0"], ["84274.90", "5.164088"], ["84276.30", "0"], ["84283.40", "4.711098"], ["84284.80", "0"], ["84291.90", "5.526480"], ["84293.30", "0"], ["84300.40", "5.073490"], ["84301.80", "0"], ["84308.90", "4.801696"], ["84310.30", "0"], ["84317.40", "4.529902"], ["84318.80", "0"], ["84325.90", "4.348706"], ["84327.30", "0"], ["84334.40", "5.435882"], ["84335.80", "0"], ["84342.90", "4.167510"], ["84344.30", "0"], ["84537.04", "0"], ["84538.75", "0"], ["84540.00", "0"], ["84540.54", "0"], ["84540.97", "0"], ["84541.67", "0"], ["84542.37", "0"], ["84543.27", "0"]], "bids": [["84088.00", "0"], ["84087.00", "0"], ["84086.00", "0"], ["84085.00", "0"], ["84083.90", "0"], ["84076.30", "0"], ["84075.20", "0.001013"], ["84074.30", "0"], ["84073.20", "0.001000"], ["84072.30", "0"], ["84071.20", "0.001003"], ["84070.30", "0"], ["84069.67", "0.019223"], ["84069.50", "0.112976"], ["84069.20", "0.002124"], ["84068.30", "0"], ["84067.20", "0.005478"], ["84066.30", "0"], ["84065.20", "0.014417"], ["84064.30", "0"], ["84063.69", "0.021425"], ["84063.20", "0.037940"], ["84062.30", "0"], ["84061.31", "0.009583"], ["84061.26", "0.007466"], ["84061.25", "0.009713"], ["84061.24", "0.008236"], ["84061.23", "0.007793"], ["84061.20", "0.099841"], ["84060.30", "0"], ["84060.01", "0.055735"], ["84059.20", "0.262740"], ["84058.56", "0.008894"], ["84058.30", "0"], ["84057.20", "0.691420"], ["84057.17", "0.009861"], ["84057.14", "0.005581"], ["84057.13", "0.008532"], ["84057.10", "0.005169"], ["84057.06", "0.004826"], ["84057.05", "0.005117"], ["84056.38", "0.288923"], ["84056.30", "0"], ["84056.00", "0.000032"], ["84055.90", "0"], ["84055.70", "0"], ["84055.35", "0"], ["84055.20", "1.819526"], ["84055.10", "0.001008"], ["84054.97", "0.028180"], ["84054.70", "0.009210"], ["84054.50", "0.001011"], ["84054.20", "0.380610"], ["84053.40", "0"], ["84053.30", "0.820860"], ["84053.02", "0"], ["84052.70", "0.074820"], ["84052.60", "0"], ["84052.50", "0"], ["84052.41", "0.247512"], ["84052.20", "0.610140"], ["84052.10", "0"], ["84052.09", "0"], ["84051.60", "0.071400"], ["84050.99", "0"], ["84050.90", "0"], ["84050.60", "0"], ["84050.42", "0"], ["84049.60", "0.071700"], ["84049.20", "0"], ["84048.70", "0"], ["84048.40", "0"], ["84047.80", "0.870090"], ["84047.54", "0.028855"], ["84047.50", "0"], ["84047.36", "0.025176"], ["84047.20", "0.030000"], ["84047.11", "0.008182"], ["84047.00", "0.240000"], ["84046.90", "0.180000"], ["84046.83", "0.224814"], ["84046.80", "0"], ["84046.77", "0"], ["84046.70", "0.022680"], ["84046.66", "0.017345"], ["84046.30", "0.468990"], ["84045.91", "0.051947"], ["84045.89", "0.008057"], ["84045.79", "0"], ["84045.50", "0"], ["84045.30", "0"], ["84045.00", "0.120000"], ["84044.70", "0.028050"], ["84044.59", "0.018511"], ["84043.84", "0.268295"], ["84043.02", "0.259716"], ["84042.49", "0.222601"], ["84041.90", "0.021123"], ["84038.81", "0.073193"], ["84037.88", "0.008425"], ["84037.68", "0.008595"], ["84037.28", "0.056350"], ["84036.58", "0.008012"], ["84036.55", "0.006470"], ["84036.41", "0.008317"], ["84036.07", "0.007303"], ["84030.15", "0.008263"], ["84029.10", "0.008092"], ["84014.50", "0"], ["84013.20", "4.258108"], ["84006.00", "0"], ["84004.70", "3.895716"], ["83997.50", "0"], ["83996.20", "5.617079"], ["83989.00", "0"], ["83987.70", "4.801696"], ["83980.50", "0"], ["83979.20", "5.345284"], ["83972.00", "0"], ["83970.70", "3.986314"], ["83963.50", "0"], ["83962.20", "4.439304"], ["83955.00", "0.000924"], ["83953.70", "4.620500"], ["83946.50", "0"], ["83945.20", "4.982892"], ["83938.00", "0"], ["83936.70", "4.167510"], ["83929.50", "0"], ["83928.20", "5.073490"], ["83921.00", "0"], ["83919.70", "4.529902"], ["83912.50", "0"], ["83911.20", "5.164088"], ["83904.00", "0"], ["83902.70", "5.254686"], ["83896.00", "0.001184"], ["83895.50", "0"], ["83894.20", "5.526480"], ["83887.00", "0"], ["83885.70", "4.076912"], ["83878.50", "0"], ["83877.20", "5.435882"], ["83870.00", "0"], ["83868.70", "4.348706"], ["83861.50", "0"], ["83860.20", "4.711098"], ["83853.00", "0"], ["83851.70", "4.892294"], ["83659.49", "0"], ["83659.44", "0"], ["83658.54", "0"], ["83656.60", "0"], ["83655.00", "0"], ["83654.23", "0"], ["83653.94", "0"], ["83653.67", "0"], ["83653.31", "0"], ["83652.80", "0"], ["83652.48", "0"], ["83651.65", "0"], ["83651.16", "0"], ["83650.84", "0"], ["83650.00", "0"], ["83648.96", "0"], ["83647.46", "0"], ["83647.06", "0"], ["83646.67", "0"], ["83645.83", "0"], ["83644.86", "0"], ["83644.33", "0"], ["83643.18", "0"], ["83641.86", "0"], ["83641.62", "0"], ["83641.38", "0"]], "checksum": 1454221172, "ts": "1742554954500"}], "ts": 1742554954504, "record_time": 1742554954.528231, "EXCHANGE": "BITGET"}
{"action": "update", "arg": {"instType": "SPOT", "channel": "books", "instId": "BTCUSDT"}, "data": [{"asks": [["84081.01", "0.111000"], ["84081.98", "0.529500"], ["84082.01", "1.144953"], ["84083.91", "0"], ["84085.78", "0"], ["84088.01", "0.101858"], ["84089.00", "0.187777"], ["84089.01", "0"], ["84089.99", "0.026759"], ["84090.00", "0.209659"], ["84090.01", "0"], ["84090.02", "0"], ["84090.03", "0"], ["84091.34", "1.531031"], ["84092.55", "0"], ["84098.11", "0.116483"], ["84098.40", "0"], ["84102.67", "0.173862"], ["84109.69", "0"], ["84118.40", "0.001444"], ["84119.40", "0"], ["84120.00", "0.002000"], ["84120.32", "3.569392"], ["84120.40", "0.002356"], ["84121.40", "0"], ["84122.40", "0.006200"], ["84123.40", "0"], ["84124.40", "0.016316"], ["84125.40", "0"], ["84126.40", "0.042936"], ["84127.40", "0"], ["84128.40", "0.113222"], ["84129.40", "0"], ["84130.40", "0.297952"], ["84131.40", "0"], ["84132.12", "0"], ["84132.40", "0.784085"], ["84133.40", "0"], ["84134.40", "2.063380"], ["84135.40", "0"], ["84136.40", "5.429949"], ["84137.40", "0"], ["84138.40", "14.289338"], ["84139.40", "4.798680"], ["84140.50", "1.435830"], ["84142.00", "0.495240"], ["84143.00", "0"], ["84147.00", "2.328810"], ["84148.70", "1.119660"], ["84149.50", "0.107040"], ["84149.60", "0.120000"], ["84153.80", "0.228000"], ["84154.20", "0.178200"], ["84154.60", "0.192000"], ["84154.70", "0.180000"], ["84155.70", "0"], ["84155.80", "0"], ["84156.10", "0"], ["84156.30", "0"], ["84156.50", "0"], ["84157.30", "0"], ["84180.40", "4.167559"], ["84181.40", "0"], ["84188.90", "4.801752"], ["84189.90", "0"], ["84197.40", "3.986360"], ["84198.40", "0"], ["84199.81", "0.125575"], ["84205.90", "4.076959"], ["84206.90", "0"], ["84214.40", "5.164148"], ["84215.40", "0"], ["84221.19", "0"], ["84222.90", "4.892351"], ["84223.90", "0"], ["84231.40", "5.617144"], ["84232.40", "0"], ["84239.90", "5.073549"], ["84240.90", "0"], ["84248.40", "4.982950"], ["84249.40", "0"], ["84256.90", "4.711153"], ["84257.90", "0"], ["84265.40", "5.345347"], ["84266.40", "0"], ["84273.90", "3.895761"], ["84274.90", "0"], ["84282.40", "5.435946"], ["84283.40", "0"], ["84290.90", "5.526545"], ["84291.90", "0"], ["84299.40", "5.254748"], ["84300.40", "0"], ["84307.90", "4.620554"], ["84308.90", "0"], ["84316.40", "4.348757"], ["84317.40", "0.000010"], ["84324.90", "4.529955"], ["84325.90", "0"], ["84333.40", "4.258158"], ["84334.40", "0"], ["84341.90", "4.439356"], ["84342.90", "0"], ["84433.67", "1.690585"], ["84447.89", "0"], ["84537.04", "0.000958"], ["84538.75", "0.000011"]], "bids": [["84082.00", "0"], ["84075.20", "0"], ["84074.20", "0.001032"], ["84073.20", "0"], ["84072.20", "0.001046"], ["84071.20", "0"], ["84070.20", "0.001037"], ["84069.20", "0"], ["84068.59", "0.010000"], ["84068.20", "0.001012"], ["84067.20", "0"], ["84066.20", "0.002114"], ["84065.20", "0"], ["84064.20", "0.005562"], ["84063.20", "0"], ["84062.20", "0.014636"], ["84061.20", "0.007749"], ["84060.20", "0.038516"], ["84060.01", "0.127590"], ["84059.20", "0"], ["84058.20", "0.101358"], ["84057.47", "0.010333"], ["84057.20", "0"], ["84056.89", "0"], ["84056.38", "0.737260"], ["84056.20", "0.266732"], ["84055.20", "0"], ["84055.10", "0"], ["84054.70", "0"], ["84054.50", "0"], ["84054.20", "0.701927"], ["84053.70", "0.001009"], ["84053.31", "0.696431"], ["84053.30", "0.544980"], ["84053.20", "0.001018"], ["84052.70", "0"], ["84052.20", "0"], ["84051.60", "0"], ["84051.20", "0.066570"], ["84050.60", "0.071610"], ["84049.60", "0"], ["84048.80", "0.871020"], ["84047.70", "0.027453"], ["84047.20", "0"], ["84046.30", "0.498990"], ["84046.11", "0.013533"], ["84044.10", "0.330060"], ["84043.90", "4.539720"], ["84042.90", "0.180000"], ["84042.80", "0.492870"], ["84037.00", "0"], ["84013.20", "0"], ["84012.20", "5.435946"], ["84004.70", "0"], ["84003.70", "5.617144"], ["83996.20", "0"], ["83995.20", "5.164148"], ["83987.70", "0"], ["83986.70", "4.711153"], ["83979.20", "0"], ["83978.20", "5.073549"], ["83970.70", "0"], ["83969.70", "4.620554"], ["83962.20", "0"], ["83961.20", "4.801752"], ["83953.70", "0"], ["83952.70", "5.526545"], ["83945.20", "0"], ["83944.20", "4.892351"], ["83936.70", "0"], ["83935.70", "3.895761"], ["83928.20", "0"], ["83927.20", "5.345347"], ["83919.70", "0"], ["83918.70", "4.167559"], ["83911.20", "0"], ["83910.20", "4.258158"], ["83902.70", "0"], ["83901.70", "4.529955"], ["83896.00", "0"], ["83894.20", "0"], ["83893.20", "4.439356"], ["83885.70", "0"], ["83884.70", "5.254748"], ["83877.20", "0"], ["83876.20", "4.348757"], ["83868.70", "0.001444"], ["83867.70", "4.076959"], ["83865.27", "0.209200"], ["83860.20", "0"], ["83859.20", "3.986360"], ["83851.70", "0"], ["83850.70", "4.982950"], ["83774.99", "0"], ["83760.88", "1.627414"]], "checksum": 545771579, "ts": "1742554954702"}], "ts": 1742554954706, "record_time": 1742554954.729863, "EXCHANGE": "BITGET"}
{"action": "update", "arg": {"instType": "SPOT", "channel": "books", "instId": "BTCUSDT"}, "data": [{"asks": [["84081.01", "2.005494"], ["84081.97", "0.445323"], ["84081.98", "0"], ["84082.01", "0.322176"], ["84083.81", "0"], ["84088.01", "0.015749"], ["84089.99", "0.026537"], ["84090.00", "0.209557"], ["84092.54", "0.044678"], ["84119.99", "0.054989"], ["84120.40", "0.002223"], ["84122.40", "0.005848"], ["84124.40", "0.015392"], ["84125.73", "0.713218"], ["84126.40", "0.040505"], ["84128.40", "0.106591"], ["84130.40", "0.280502"], ["84132.40", "0.738277"], ["84134.40", "1.942834"], ["84136.40", "5.112723"], ["84138.40", "13.454533"], ["84139.30", "0.494790"], ["84139.40", "2.232960"], ["84153.50", "0.287430"], ["84154.30", "0.035670"], ["84154.80", "0.178200"], ["84180.40", "4.076959"], ["84188.90", "5.073549"], ["84197.40", "4.348757"], ["84205.90", "5.164148"], ["84214.40", "4.711153"], ["84222.90", "5.617144"], ["84231.40", "3.895761"], ["84239.90", "4.620554"], ["84248.40", "4.439356"], ["84256.90", "4.892351"], ["84265.40", "4.982950"], ["84273.90", "3.986360"], ["84282.40", "4.801752"], ["84290.90", "4.167559"], ["84299.40", "5.435946"], ["84307.90", "5.345347"], ["84316.40", "4.529955"], ["84324.90", "4.258158"], ["84333.40", "5.254748"], ["84341.90", "5.526545"], ["84535.32", "0"], ["84536.36", "0"], ["84537.04", "0"], ["84538.75", "0"]], "bids": [["84070.74", "0"], ["84068.22", "0.041073"], ["84067.24", "0.000233"], ["84062.40", "0"], ["84060.20", "0.038744"], ["84060.01", "0.055735"], ["84058.20", "0.101957"], ["84056.38", "0.288923"], ["84056.37", "0"], ["84056.20", "0.268308"], ["84054.20", "0.706316"], ["84053.31", "0"], ["84053.30", "0.452400"], ["84053.22", "0.004016"], ["84053.20", "0.000700"], ["84050.25", "0.766035"], ["84047.38", "0.713883"], ["84042.80", "0.612870"], ["84039.00", "0.000015"], ["84012.20", "4.801752"], ["84003.70", "4.167559"], ["83995.20", "3.986360"], ["83986.70", "4.076959"], ["83978.20", "5.617144"], ["83969.70", "4.348757"], ["83961.20", "5.345347"], ["83952.70", "5.254748"], ["83944.20", "4.711153"], ["83935.70", "4.982950"], ["83927.20", "4.439356"], ["83918.70", "5.526545"], ["83910.20", "5.435946"], ["83901.70", "4.620554"], ["83893.20", "5.164148"], ["83884.70", "3.895761"], ["83876.20", "5.073549"], ["83867.70", "4.258158"], ["83859.20", "4.529955"], ["83850.70", "4.892351"], ["83659.61", "0"]], "checksum": 1771449739, "ts": "1742554954903"}], "ts": 1742554954906, "record_time": 1742554954.947117, "EXCHANGE": "BITGET"}
{"action": "update", "arg": {"instType": "SPOT", "channel": "books", "instId": "BTCUSDT"}, "data": [{"asks": [["84081.01", "2.031065"], ["84081.97", "0"], ["84088.00", "0.004725"], ["84108.69", "0.183251"], ["84120.40", "0.002324"], ["84122.40", "0.006117"], ["84124.40", "0.016098"], ["84126.40", "0.042362"], ["84128.40", "0.111479"], ["84130.40", "0.293366"], ["84131.59", "0.001597"], ["84132.40", "0.772017"], ["84134.40", "2.031623"], ["84136.40", "5.346377"], ["84137.98", "0"], ["84138.40", "14.069412"], ["84139.30", "1.102860"], ["84139.40", "1.449780"], ["84148.10", "0.067980"], ["84180.40", "3.986360"], ["84188.90", "4.258158"], ["84197.40", "4.801752"], ["84205.90", "4.076959"], ["84214.40", "3.895761"], ["84222.90", "4.529955"], ["84231.40", "4.439356"], ["84239.90", "5.526545"], ["84248.40", "5.617144"], ["84256.90", "4.620554"], ["84265.40", "4.711153"], ["84273.90", "4.167559"], ["84282.40", "5.435946"], ["84290.90", "5.254748"], ["84299.40", "5.073549"], ["84307.90", "4.982950"], ["84316.40", "4.348757"], ["84324.90", "4.892351"], ["84333.40", "5.164148"], ["84341.90", "5.345347"], ["84534.53", "0"]], "bids": [["84066.20", "0.001056"], ["84064.20", "0.002780"], ["84062.20", "0.007316"], ["84060.20", "0.019253"], ["84058.21", "0.136235"], ["84058.20", "0.050666"], ["84056.38", "0"], ["84056.20", "0.133331"], ["84054.21", "0.596997"], ["84054.20", "0.350870"], ["84053.30", "0.452280"], ["84050.70", "0.921330"], ["84048.80", "0.870810"], ["84044.22", "0"], ["84042.80", "0"], ["84035.50", "0.000876"], ["84025.52", "0"], ["84023.80", "0"], ["84017.41", "0.001173"], ["84017.31", "0.003596"], ["84012.20", "5.345347"], ["84003.70", "4.348757"], ["83995.20", "4.076959"], ["83986.70", "5.164148"], ["83978.20", "4.801752"], ["83969.70", "5.254748"], ["83961.20", "3.986360"], ["83952.70", "4.167559"], ["83935.70", "3.895761"], ["83927.20", "5.073549"], ["83918.70", "5.617144"], ["83910.20", "4.439356"], ["83901.70", "5.435946"], ["83893.20", "5.526545"], ["83884.70", "4.258158"], ["83876.20", "4.982950"], ["83867.70", "4.892351"], ["83850.70", "4.620554"], ["83660.00", "0"]], "checksum": -1833602743, "ts": "1742554955110"}], "ts": 1742554955113, "record_time": 1742554955.13792, "EXCHANGE": "BITGET"}
{"action": "update", "arg": {"instType": "SPOT", "channel": "books", "instId": "BTCUSDT"}, "data": [{"asks": [["84081.01", "1.968852"], ["84088.01", "0"], ["84089.00", "0.507681"], ["84090.00", "0.209200"], ["84097.46", "0"], ["84104.48", "0"], ["84114.90", "0.001021"], ["84116.90", "0.001587"], ["84118.40", "0"], ["84118.90", "0.004176"], ["84120.40", "0"], ["84120.90", "0.010990"], ["84122.40", "0"], ["84122.90", "0.028920"], ["84124.40", "0"], ["84124.90", "0.076104"], ["84126.40", "0"], ["84126.90", "0.200275"], ["84128.40", "0"], ["84128.65", "0.001598"], ["84128.90", "0.527040"], ["84130.40", "0"], ["84130.90", "1.386946"], ["84132.40", "0"], ["84132.90", "3.649859"], ["84134.40", "0"], ["84134.90", "9.604891"], ["84135.30", "0.001035"], ["84135.40", "0.001021"], ["84136.10", "0.067800"], ["84136.14", "0"], ["84136.30", "0.001012"], ["84136.40", "0"], ["84136.50", "0.001050"], ["84137.10", "2.879550"], ["84137.20", "13.434930"], ["84138.10", "0.067980"], ["84138.40", "3.643440"], ["84138.80", "0.180180"], ["84139.30", "0"], ["84139.40", "0.087630"], ["84139.50", "0.045180"], ["84140.00", "0.144510"], ["84140.10", "0.067800"], ["84140.50", "1.073850"], ["84140.70", "0.045000"], ["84140.90", "0.269760"], ["84141.10", "0.071460"], ["84142.00", "0.423420"], ["84142.10", "0.067980"], ["84144.10", "0.067800"], ["84144.79", "0.560830"], ["84144.80", "0.450240"], ["84145.40", "0.480000"], ["84145.80", "2.569470"], ["84145.90", "0.120000"], ["84146.10", "0.067800"], ["84146.70", "1.069320"], ["84146.80", "0.009000"], ["84147.00", "2.328450"], ["84148.10", "0.067800"], ["84148.70", "1.072860"], ["84149.20", "1.350000"], ["84149.30", "0.924120"], ["84149.40", "0.156000"], ["84149.50", "0"], ["84149.60", "0"], ["84149.80", "0"], ["84150.10", "0"], ["84150.50", "0"], ["84150.80", "0"], ["84152.10", "0"], ["84153.50", "0"], ["84153.80", "0"], ["84154.10", "0"], ["84154.20", "0"], ["84154.30", "0"], ["84154.60", "0"], ["84154.70", "0"], ["84154.80", "0"], ["84176.90", "5.073761"], ["84180.40", "0"], ["84185.40", "3.895923"], ["84188.90", "0"], ["84193.90", "4.258335"], ["84197.40", "0"], ["84202.40", "4.167732"], ["84205.90", "0"], ["84210.90", "3.986526"], ["84214.40", "0"], ["84219.40", "4.983158"], ["84222.90", "0"], ["84227.90", "4.892555"], ["84231.40", "0"], ["84236.40", "5.254966"], ["84239.90", "0"], ["84244.90", "4.348938"], ["84248.40", "0"], ["84253.40", "4.620746"], ["84256.90", "0"], ["84261.90", "5.617378"], ["84265.40", "0"], ["84270.40", "4.801952"], ["84273.90", "0"], ["84278.90", "4.711349"], ["84282.40", "0"], ["84287.40", "4.077129"], ["84290.90", "0"], ["84295.90", "5.164363"], ["84299.40", "0"], ["84304.40", "4.530143"], ["84307.90", "0"], ["84312.90", "5.436172"], ["84316.40", "0"], ["84321.40", "4.439541"], ["84324.90", "0"], ["84329.90", "5.345569"], ["84333.40", "0"], ["84338.40", "5.526775"], ["84341.90", "0"]], "bids": [["84081.00", "0"], ["84074.20", "0"], ["84073.66", "0"], ["84072.20", "0"], ["84070.70", "0.001006"], ["84070.20", "0"], ["84069.67", "0"], ["84069.50", "0"], ["84068.79", "0.019223"], ["84068.70", "0.001036"], ["84068.22", "0"], ["84068.20", "0"], ["84067.24", "0"], ["84066.70", "0.001037"], ["84066.51", "0"], ["84066.20", "0"], ["84064.70", "0.001050"], ["84064.20", "0"], ["84062.72", "0"], ["84062.70", "0.001512"], ["84062.68", "0"], ["84062.20", "0"], ["84061.31", "0"], ["84061.26", "0"], ["84061.25", "0"], ["84061.24", "0"], ["84061.23", "0"], ["84061.20", "0"], ["84060.70", "0.003980"], ["84060.20", "0"], ["84060.01", "0"], ["84058.70", "0.010474"], ["84058.61", "0"], ["84058.56", "0"], ["84058.21", "0"], ["84058.20", "0"], ["84057.47", "0"], ["84057.17", "0"], ["84057.14", "0"], ["84057.13", "0"], ["84057.10", "0"], ["84057.06", "0"], ["84057.05", "0"], ["84056.70", "0.027562"], ["84056.20", "0"], ["84056.05", "0"], ["84054.70", "0.072531"], ["84054.20", "0"], ["84053.70", "0"], ["84053.30", "0"], ["84053.10", "0"], ["84052.70", "0.190871"], ["84051.20", "0"], ["84050.70", "0.502293"], ["84050.60", "0.001002"], ["84050.40", "0.001019"], ["84050.30", "0.001049"], ["84050.25", "1.538349"], ["84050.24", "0"], ["84049.70", "0.005944"], ["84048.80", "1.118190"], ["84047.80", "0.870480"], ["84047.53", "0"], ["84047.20", "0.263250"], ["84047.00", "0.240360"], ["84046.90", "0.120000"], ["84046.30", "0.468990"], ["84045.89", "0"], ["84045.41", "0.055881"], ["84044.92", "0.055644"], ["84044.10", "0"], ["84043.90", "2.873310"], ["84042.90", "0"], ["84042.80", "0.612870"], ["84042.60", "0.056100"], ["84042.20", "0.120000"], ["84042.10", "2.673330"], ["84041.80", "0.120000"], ["84041.70", "2.673330"], ["84041.40", "0.045000"], ["84037.88", "0"], ["84037.68", "0"], ["84037.31", "0"], ["84037.26", "0"], ["84030.15", "0"], ["84030.10", "0"], ["84029.10", "0"], ["84025.83", "0"], ["84018.34", "0.001175"], ["84014.38", "0"], ["84012.20", "0"], ["84011.47", "0"], ["84009.13", "0"], ["84009.11", "0"], ["84008.97", "0"], ["84008.70", "4.439541"], ["84003.70", "0"], ["84000.20", "5.073761"], ["83995.20", "0"], ["83991.70", "4.801952"], ["83986.70", "0"], ["83983.20", "4.167732"], ["83978.20", "0"], ["83974.70", "4.530143"], ["83969.70", "0"], ["83966.20", "4.077129"], ["83961.20", "0"], ["83957.70", "4.711349"], ["83952.70", "0"], ["83949.20", "5.254966"], ["83944.20", "0"], ["83940.70", "5.164363"], ["83935.70", "0"], ["83932.20", "4.892555"], ["83927.20", "0"], ["83923.70", "4.620746"], ["83918.70", "0"], ["83915.20", "4.348938"], ["83910.20", "0"], ["83906.70", "4.258335"], ["83901.70", "0"], ["83898.20", "3.895923"], ["83893.20", "0"], ["83889.70", "3.986526"], ["83884.70", "0"], ["83881.20", "5.436172"], ["83876.20", "0"], ["83872.70", "5.526775"], ["83867.70", "0"], ["83864.20", "4.983158"], ["83859.20", "0"], ["83855.70", "5.345569"], ["83850.70", "0"], ["83847.20", "5.617378"], ["83660.00", "0.001273"], ["83659.61", "0.000454"], ["83659.49", "0.000012"], ["83659.44", "0.000613"], ["83658.54", "0.000036"], ["83656.60", "0.000607"], ["83655.00", "0.000926"], ["83654.23", "0.000009"], ["83653.94", "0.000133"], ["83653.67", "0.001695"], ["83653.31", "0.000015"], ["83652.80", "0.000119"], ["83652.48", "0.000188"], ["83651.65", "0.000018"], ["83651.16", "0.000896"], ["83650.84", "0.003326"], ["83650.00", "0.032056"], ["83648.96", "0.000030"], ["83647.46", "0.000224"], ["83647.06", "0.000040"], ["83646.67", "0.000018"], ["83645.83", "0.000014"], ["83644.86", "0.000034"], ["83644.33", "0.000013"], ["83643.18", "0.000052"], ["83641.86", "0.000379"], ["83641.62", "0.002925"], ["83641.38", "0.000135"], ["83641.00", "0.000082"], ["83640.35", "0.000022"], ["83640.15", "0.000423"], ["83640.00", "0.002013"], ["83639.71", "0.000041"], ["83639.70", "0.000010"], ["83639.15", "0.000009"], ["83638.32", "0.000039"], ["83638.30", "0.000137"]], "checksum": -498493613, "ts": "1742554955311"}], "ts": 1742554955314, "record_time": 1742554955.344847, "EXCHANGE": "BITGET"}
{"action": "update", "arg": {"instType": "SPOT", "channel": "books", "instId": "BTCUSDT"}, "data": [{"asks": [["84079.01", "1.511509"], ["84080.01", "0.215993"], ["84081.01", "0.320779"], ["84081.98", "0.000075"], ["84082.01", "0.112976"], ["84082.37", "0.017451"], ["84085.37", "0.313938"], ["84085.76", "0.035952"], ["84086.36", "0.119870"], ["84087.42", "0.035961"], ["84088.00", "0"], ["84088.57", "0.006356"], ["84088.76", "0.006356"], ["84089.08", "0.006356"], ["84089.64", "0.017340"], ["84089.79", "0.006356"], ["84089.99", "0.011892"], ["84090.26", "0.006356"], ["84090.80", "0.006356"], ["84091.14", "0.119883"], ["84091.40", "0.016429"], ["84091.46", "0.006356"], ["84092.06", "0.006356"], ["84092.24", "0"], ["84093.24", "0.006357"], ["84093.37", "0.010985"], ["84093.60", "0"], ["84093.65", "0.009990"], ["84094.78", "0.119850"], ["84095.20", "0"], ["84095.26", "0"], ["84095.27", "0"], ["84095.46", "0"], ["84095.75", "0.119858"], ["84096.07", "0.015895"], ["84096.32", "0.009989"], ["84096.57", "0.119867"], ["84097.19", "0"], ["84097.34", "0"], ["84098.10", "0"], ["84098.12", "0"], ["84098.35", "0"], ["84098.57", "0"], ["84098.65", "0"], ["84098.74", "0"], ["84100.48", "0"], ["84100.56", "0"], ["84100.77", "0.015892"], ["84100.92", "0"], ["84102.02", "0"], ["84102.67", "0"], ["84102.68", "0"], ["84103.27", "0"], ["84103.33", "0"], ["84103.55", "0"], ["84107.75", "0"], ["84107.77", "0.223500"], ["84113.00", "0.001029"], ["84114.90", "0"], ["84115.00", "0.001033"], ["84116.90", "0"], ["84117.00", "0.002874"], ["84118.90", "0"], ["84119.00", "0.007564"], ["84120.36", "0.713263"], ["84120.90", "0"], ["84121.00", "0.019904"], ["84122.90", "0"], ["84123.00", "0.052381"], ["84124.90", "0"], ["84125.00", "0.137845"], ["84125.73", "0"], ["84126.90", "0"], ["84127.00", "0.362748"], ["84128.90", "0"], ["84129.00", "0.954601"], ["84130.90", "0"], ["84131.00", "2.512109"], ["84132.90", "0"], ["84133.00", "6.610812"], ["84133.80", "0.001013"], ["84134.10", "0.068400"], ["84134.40", "1.230600"], ["84134.50", "4.913490"], ["84134.80", "0.420180"], ["84134.90", "1.028460"], ["84135.30", "0"], ["84135.40", "0.006060"], ["84135.80", "0.450420"], ["84136.10", "0.067980"], ["84136.30", "0"], ["84136.50", "0"], ["84136.70", "0.144690"], ["84137.10", "0"], ["84137.20", "0"], ["84137.30", "0.741120"], ["84137.40", "0.022680"], ["84138.10", "0.067800"], ["84138.40", "1.987260"], ["84138.80", "0"], ["84139.40", "0.081720"], ["84139.50", "0.045000"], ["84140.00", "0"], ["84140.50", "0.004140"], ["84140.90", "0"], ["84142.00", "0.289110"], ["84143.70", "0"], ["84144.79", "0"], ["84144.80", "0"], ["84144.90", "0.027360"], ["84145.80", "5.220150"], ["84146.80", "0.020280"], ["84147.00", "0"], ["84148.10", "0"], ["84148.70", "0"], ["84149.20", "0"], ["84149.30", "0"], ["84149.40", "0"], ["84151.59", "0"], ["84175.00", "4.077220"], ["84176.89", "0.407121"], ["84176.90", "0"], ["84183.50", "4.439639"], ["84185.40", "0"], ["84192.00", "3.986615"], ["84193.90", "0"], ["84200.50", "4.620849"], ["84202.40", "0"], ["84209.00", "5.164478"], ["84210.90", "0"], ["84217.50", "4.802059"], ["84219.40", "0"], ["84226.00", "4.711454"], ["84227.90", "0"], ["84234.50", "5.436293"], ["84236.40", "0"], ["84243.00", "4.258430"], ["84244.90", "0"], ["84251.50", "4.892664"], ["84253.40", "0"], ["84260.00", "5.073873"], ["84261.90", "0"], ["84268.50", "4.349034"], ["84270.40", "0"], ["84277.00", "4.167825"], ["84278.90", "0"], ["84285.50", "3.896010"], ["84287.40", "0"], ["84294.00", "4.530244"], ["84295.90", "0.209200"], ["84302.50", "4.983269"], ["84304.40", "0"], ["84311.00", "5.617503"], ["84312.90", "0"], ["84319.50", "5.345688"], ["84321.40", "0"], ["84328.00", "5.526898"], ["84329.90", "0"], ["84336.50", "5.255083"], ["84338.40", "0"], ["84534.53", "0.000461"]], "bids": [["84080.00", "0"], ["84070.70", "0"], ["84068.80", "0.001021"], ["84068.79", "0"], ["84068.70", "0"], ["84066.98", "0.019223"], ["84066.80", "0.001007"], ["84066.70", "0"], ["84065.35", "0.012472"], ["84064.80", "0.001999"], ["84064.70", "0"], ["84063.69", "0"], ["84062.82", "0.112976"], ["84062.80", "0.005259"], ["84062.70", "0"], ["84060.80", "0.013840"], ["84060.70", "0"], ["84058.80", "0.036422"], ["84058.70", "0"], ["84058.28", "0.000233"], ["84057.33", "0.008499"], ["84057.31", "0.015917"], ["84057.00", "0.009617"], ["84056.95", "0.009713"], ["84056.93", "0.008236"], ["84056.92", "0.007793"], ["84056.91", "0.007467"], ["84056.89", "0.007750"], ["84056.80", "0.095847"], ["84056.70", "0"], ["84055.17", "0.021425"], ["84054.80", "0.252230"], ["84054.70", "0"], ["84054.21", "0.412851"], ["84053.25", "0.008711"], ["84053.24", "0"], ["84053.17", "0.010333"], ["84053.12", "0.008894"], ["84052.82", "0.008532"], ["84052.81", "0.009861"], ["84052.80", "0.663763"], ["84052.76", "0.004826"], ["84052.70", "0.005117"], ["84052.69", "0.005169"], ["84052.41", "0"], ["84051.54", "0"], ["84050.80", "1.746743"], ["84050.70", "0"], ["84050.64", "0"], ["84050.60", "0"], ["84050.56", "0"], ["84050.40", "0"], ["84050.30", "0"], ["84049.70", "0"], ["84048.93", "0"], ["84048.80", "4.596692"], ["84048.75", "0.313938"], ["84048.70", "0.016560"], ["84048.60", "0.001025"], ["84048.50", "0"], ["84047.96", "0"], ["84047.90", "0.001031"], ["84047.80", "0.519540"], ["84047.74", "0"], ["84047.40", "0"], ["84047.36", "0"], ["84047.20", "0"], ["84047.11", "0"], ["84047.00", "0.000032"], ["84046.90", "0"], ["84046.83", "0"], ["84046.70", "0"], ["84046.30", "0"], ["84046.10", "0"], ["84046.00", "0.006134"], ["84045.91", "0"], ["84045.84", "0"], ["84045.40", "1.782420"], ["84045.16", "0.247537"], ["84045.00", "0.000956"], ["84044.70", "0.028230"], ["84044.59", "0"], ["84044.01", "0.017813"], ["84043.90", "0.262260"], ["84043.86", "0.018251"], ["84043.84", "0"], ["84043.70", "0.083923"], ["84043.51", "0.005945"], ["84043.40", "0.011130"], ["84043.02", "0"], ["84042.80", "0"], ["84042.60", "0.056310"], ["84042.49", "0"], ["84042.29", "0"], ["84042.10", "0"], ["84041.90", "0"], ["84041.80", "0"], ["84041.70", "0"], ["84041.40", "0"], ["84041.38", "0.017100"], ["84041.20", "0.007130"], ["84040.85", "0.008992"], ["84040.67", "0.007338"], ["84040.53", "0.008057"], ["84040.45", "3.052458"], ["84040.44", "0.008183"], ["84040.40", "0.468990"], ["84040.31", "0.008267"], ["84040.20", "0.007941"], ["84040.12", "0.025179"], ["84039.90", "2.187360"], ["84039.86", "0.224836"], ["84039.80", "0.009000"], ["84039.50", "0.144510"], ["84039.30", "1.425780"], ["84038.81", "0"], ["84038.72", "0.051953"], ["84038.59", "0.012653"], ["84038.40", "0.022680"], ["84038.00", "0.000032"], ["84037.90", "0.120000"], ["84037.70", "0.070050"], ["84037.50", "2.673330"], ["84037.40", "0.010770"], ["84037.33", "0.018513"], ["84037.20", "0.045000"], ["84037.10", "0.045000"], ["84037.00", "0.035670"], ["84036.60", "0.268322"], ["84036.58", "0"], ["84036.55", "0"], ["84036.41", "0"], ["84036.07", "0"], ["84036.00", "0.000032"], ["84035.56", "0.222624"], ["84035.03", "0.076097"], ["84035.00", "0.000428"], ["84034.95", "0.021125"], ["84034.00", "0.000032"], ["84033.00", "0.000032"], ["84032.72", "0.008425"], ["84032.52", "0.008595"], ["84032.00", "0.000032"], ["84031.97", "0.009208"], ["84031.92", "0.006904"], ["84031.83", "0.073200"], ["84030.70", "0.008012"], ["84030.68", "0.014787"], ["84030.01", "0.007303"], ["84026.66", "0"], ["84024.85", "0.008092"], ["84024.81", "0.008263"], ["84024.77", "0.005051"], ["84016.80", "0.017451"], ["84008.70", "0"], ["84008.65", "0.007432"], ["84006.80", "4.167825"], ["84005.74", "0.008570"], ["84003.98", "0.007650"], ["84003.96", "0.007246"], ["84003.71", "0.007334"], ["84000.20", "0"], ["83998.30", "4.802059"], ["83991.70", "0"], ["83989.80", "3.986615"], ["83983.20", "0"], ["83981.30", "5.526898"], ["83974.70", "0"], ["83972.80", "4.711454"], ["83966.20", "0"], ["83964.30", "4.530244"], ["83957.70", "0"], ["83955.80", "3.896010"], ["83949.20", "0"], ["83947.30", "4.439639"], ["83940.70", "0"], ["83938.80", "4.983269"], ["83932.20", "0.001459"], ["83930.30", "5.255083"], ["83923.70", "0"], ["83921.80", "5.617503"], ["83915.20", "0"], ["83913.30", "5.345688"], ["83906.70", "0"], ["83904.80", "4.077220"], ["83898.20", "0"], ["83896.30", "4.258430"], ["83889.70", "0"], ["83887.80", "4.892664"], ["83881.20", "0"], ["83879.30", "5.436293"], ["83872.70", "0"], ["83870.80", "5.073873"], ["83864.20", "0"], ["83862.30", "5.164478"], ["83855.70", "0"], ["83853.80", "4.349034"], ["83847.20", "0"], ["83845.30", "4.620849"], ["83660.00", "0"], ["83659.61", "0"], ["83659.49", "0"], ["83659.44", "0"], ["83658.54", "0"], ["83656.60", "0"], ["83655.00", "0"], ["83654.23", "0"], ["83653.94", "0"], ["83653.67", "0"], ["83653.31", "0"], ["83652.80", "0"], ["83652.48", "0"], ["83651.65", "0"], ["83651.16", "0"], ["83650.84", "0"], ["83650.00", "0"], ["83648.96", "0"], ["83647.46", "0"], ["83647.06", "0"], ["83646.67", "0"], ["83645.83", "0"], ["83644.86", "0"], ["83644.33", "0"], ["83643.18", "0"], ["83641.86", "0"], ["83641.62", "0"], ["83641.38", "0"], ["83641.00", "0"], ["83640.35", "0"], ["83640.15", "0"], ["83640.00", "0"], ["83639.71", "0"], ["83639.70", "0"], ["83639.15", "0"], ["83638.32", "0"], ["83638.30", "0"]], "checksum": -526700469, "ts": "1742554955521"}], "ts": 1742554955525, "record_time": 1742554955.550956, "EXCHANGE": "BITGET"}
{"action": "update", "arg": {"instType": "SPOT", "channel": "books", "instId": "BTCUSDT"}, "data": [{"asks": [["84078.99", "1.221800"], ["84079.00", "0.440000"], ["84079.01", "1.769000"], ["84080.00", "0.014828"], ["84080.01", "0"], ["84081.01", "0.209779"], ["84082.01", "0"], ["84085.36", "0.151716"], ["84092.09", "0.006356"], ["84092.54", "0.118253"], ["84098.11", "0"], ["84098.28", "0"], ["84098.40", "0.067528"], ["84115.00", "0.001115"], ["84117.00", "0.002933"], ["84119.00", "0.007719"], ["84121.00", "0.020312"], ["84123.00", "0.053453"], ["84125.00", "0.140667"], ["84127.00", "0.370175"], ["84129.00", "0.974146"], ["84131.00", "2.563543"], ["84133.00", "6.746164"], ["84134.10", "0.068220"], ["84134.40", "1.031430"], ["84134.50", "1.711980"], ["84134.90", "1.028070"], ["84136.60", "0.071460"], ["84137.30", "0.261630"], ["84138.40", "0.542760"], ["84141.10", "0"], ["84142.40", "0.456000"], ["84143.80", "0.012330"], ["84146.70", "0"], ["84146.80", "0"], ["84175.00", "5.164478"], ["84176.89", "0"], ["84183.50", "4.258430"], ["84192.00", "4.620849"], ["84200.50", "4.077220"], ["84209.00", "4.802059"], ["84217.50", "5.526898"], ["84226.00", "4.439639"], ["84234.50", "5.345688"], ["84243.00", "4.983269"], ["84251.50", "3.986615"], ["84260.00", "5.436293"], ["84268.50", "5.617503"], ["84277.00", "4.530244"], ["84285.50", "4.349034"], ["84294.00", "4.167825"], ["84302.50", "3.896010"], ["84311.00", "4.892664"], ["84319.50", "4.711454"], ["84328.00", "5.073873"], ["84534.53", "0"]], "bids": [["84079.00", "0"], ["84068.59", "0"], ["84064.80", "0.002913"], ["84062.80", "0.007666"], ["84060.80", "0.020172"], ["84058.80", "0.053086"], ["84056.80", "0.139699"], ["84054.80", "0.367628"], ["84052.80", "0.967442"], ["84050.80", "2.545900"], ["84048.80", "6.699739"], ["84046.66", "0"], ["84045.40", "1.782600"], ["84045.20", "0.071430"], ["84044.70", "0.028050"], ["84042.70", "0.144510"], ["84042.60", "0.056100"], ["84040.47", "0.017348"], ["84039.50", "0"], ["84038.80", "0.240000"], ["84038.70", "0.120000"], ["84037.40", "0"], ["84037.20", "0"], ["84037.10", "0"], ["84037.00", "0.000017"], ["84036.04", "0.259747"], ["84006.80", "4.439639"], ["83989.80", "5.617503"], ["83981.30", "4.892664"], ["83972.80", "5.164478"], ["83964.30", "3.986615"], ["83955.80", "4.349034"], ["83947.30", "5.436293"], ["83938.80", "4.620849"], ["83930.30", "4.258430"], ["83921.80", "4.530244"], ["83913.30", "4.983269"], ["83904.80", "5.073873"], ["83896.30", "5.345688"], ["83888.00", "0.001184"], ["83887.80", "4.077220"], ["83879.30", "4.167825"], ["83870.80", "3.896010"], ["83862.30", "4.711454"], ["83853.80", "5.255083"], ["83845.30", "5.526898"]], "checksum": -1341205958, "ts": "1742554955723"}], "ts": 1742554955729, "record_time": 1742554955.75173, "EXCHANGE": "BITGET"}
{"action": "update", "arg": {"instType": "SPOT", "channel": "books", "instId": "BTCUSDT"}, "data": [{"asks": [["84077.01", "1.932440"], ["84078.01", "0.209200"], ["84078.08", "0.210254"], ["84078.98", "1.038946"], ["84078.99", "0.460000"], ["84079.00", "0"], ["84079.01", "0.130476"], ["84080.00", "0"], ["84107.77", "0"], ["84115.51", "0"], ["84133.80", "0"], ["84134.40", "1.501380"], ["84134.50", "4.068060"], ["84136.70", "0.144510"], ["84140.70", "0.165000"], ["84141.50", "0.120000"], ["84142.00", "0.408900"], ["84144.90", "0.255360"], ["84145.80", "0"], ["84145.90", "0"], ["84146.10", "0"], ["84146.20", "0"], ["84175.00", "5.526898"], ["84183.50", "4.711454"], ["84192.00", "4.167825"], ["84200.50", "4.892664"], ["84203.60", "0.062760"], ["84209.00", "4.620849"], ["84217.50", "5.164478"], ["84226.00", "4.530244"], ["84234.49", "0.801084"], ["84234.50", "4.258430"], ["84243.00", "4.802059"], ["84251.50", "5.073873"], ["84260.00", "5.617503"], ["84268.50", "3.986615"], ["84277.00", "3.896010"], ["84285.50", "5.436293"], ["84294.00", "5.345688"], ["84302.50", "4.439639"], ["84311.00", "4.983269"], ["84319.50", "4.077220"], ["84328.00", "4.349034"], ["84534.53", "0.000461"], ["84535.32", "0.000039"]], "bids": [["84078.00", "0"], ["84063.91", "0.041076"], ["84056.81", "0.119324"], ["84054.80", "0.367816"], ["84054.21", "1.088042"], ["84052.80", "0.967937"], ["84050.80", "2.547201"], ["84050.25", "0.766035"], ["84048.80", "6.703161"], ["84006.80", "4.620849"], ["83998.30", "4.439639"], ["83989.80", "5.345688"], ["83981.30", "3.896010"], ["83972.80", "5.073873"], ["83964.30", "5.164478"], ["83938.80", "4.530244"], ["83930.30", "4.077220"], ["83921.80", "5.255083"], ["83913.30", "4.258430"], ["83904.80", "4.983269"], ["83896.30", "3.986615"], ["83887.80", "5.617503"], ["83879.30", "5.526898"], ["83870.80", "4.711454"], ["83862.30", "4.167825"], ["83853.80", "4.892664"], ["83845.30", "4.802059"], ["83660.14", "0"]], "checksum": 1576256877, "ts": "1742554955926"}], "ts": 1742554955929, "record_time": 1742554955.953879, "EXCHANGE": "BITGET"}
{"action": "update", "arg": {"instType": "SPOT", "channel": "books", "instId": "BTCUSDT"}, "data": [{"asks": [["84077.01", "2.270018"], ["84078.00", "0.014828"], ["84078.07", "0.551903"], ["84078.98", "0"], ["84078.99", "0"], ["84079.01", "0.112976"], ["84089.00", "0.187777"], ["84105.77", "0.223200"], ["84113.40", "0"], ["84117.00", "0.002823"], ["84119.00", "0.007431"], ["84121.00", "0.019555"], ["84123.00", "0.051461"], ["84125.00", "0.135424"], ["84127.00", "0.356378"], ["84129.00", "0.937836"], ["84131.00", "2.468103"], ["84133.00", "6.495008"], ["84134.40", "1.472700"], ["84134.50", "2.718060"], ["84138.40", "0.537780"], ["84139.40", "0.081210"], ["84144.90", "0.228000"], ["84145.70", "0.216000"], ["84175.00", "5.617503"], ["84183.50", "4.620849"], ["84192.00", "4.077220"], ["84200.50", "5.073873"], ["84209.00", "3.986615"], ["84217.50", "5.255083"], ["84226.00", "4.711454"], ["84234.49", "0"], ["84234.50", "5.345688"], ["84243.00", "5.436293"], ["84251.50", "3.896010"], ["84260.00", "4.983269"], ["84268.50", "4.258430"], ["84277.00", "4.892664"], ["84285.50", "4.802059"], ["84294.00", "4.349034"], ["84302.50", "4.167825"], ["84311.00", "5.164478"], ["84319.50", "5.526898"], ["84328.00", "4.530244"], ["84336.50", "4.439639"]], "bids": [["84066.80", "0.001109"], ["84064.80", "0.003036"], ["84062.80", "0.007989"], ["84060.80", "0.021022"], ["84058.80", "0.055322"], ["84056.80", "0.145583"], ["84054.80", "0.383114"], ["84052.80", "1.008194"], ["84050.80", "2.653144"], ["84050.25", "1.119950"], ["84048.80", "6.981956"], ["84046.00", "0.074520"], ["84043.90", "0.329850"], ["84037.90", "2.476020"], ["84037.70", "0"], ["84037.50", "0"], ["84006.80", "4.892664"], ["83998.30", "5.617503"], ["83989.80", "4.439639"], ["83981.30", "4.167825"], ["83964.30", "5.436293"], ["83955.80", "3.896010"], ["83947.30", "4.620849"], ["83930.30", "4.711454"], ["83904.80", "3.986615"], ["83896.30", "5.526898"], ["83887.80", "4.983269"], ["83879.30", "4.077220"], ["83870.80", "4.802059"], ["83862.30", "5.164478"], ["83853.80", "5.345688"], ["83845.30", "4.349034"], ["83660.14", "0.000016"], ["83660.00", "0.001273"]], "checksum": -73673658, "ts": "1742554956130"}], "ts": 1742554956133, "record_time": 1742554956.169042, "EXCHANGE": "BITGET"}
{"action": "update", "arg": {"instType": "SPOT", "channel": "books", "instId": "BTCUSDT"}, "data": [{"asks": [["84077.01", "2.278974"], ["84078.00", "0.174557"], ["84078.07", "0"], ["84081.98", "0"], ["84082.36", "0.005235"], ["84108.69", "0"], ["84183.50", "4.349034"], ["84192.00", "4.439639"], ["84200.50", "5.255083"], ["84217.50", "4.167825"], ["84226.00", "5.073873"], ["84243.00", "4.530244"], ["84251.50", "5.436293"], ["84260.00", "4.620849"], ["84268.50", "5.526898"], ["84285.50", "4.983269"], ["84294.00", "4.258430"], ["84302.50", "4.711454"], ["84311.00", "3.896010"], ["84319.50", "4.802059"], ["84328.00", "4.077220"], ["84336.50", "5.164478"], ["84536.36", "0.000053"], ["84537.04", "0.000958"]], "bids": [["84064.35", "0.041077"], ["84063.91", "0"], ["84039.00", "0.000032"], ["84031.00", "0.000017"], ["84030.00", "0.002941"], ["84029.00", "0.000017"], ["84006.80", "3.986615"], ["83998.30", "4.530244"], ["83989.80", "5.255083"], ["83981.30", "5.164478"], ["83972.80", "4.349034"], ["83964.30", "5.073873"], ["83955.80", "4.892664"], ["83947.30", "3.896010"], ["83938.80", "4.711454"], ["83930.30", "4.439639"], ["83921.80", "5.436293"], ["83913.30", "5.617503"], ["83904.80", "4.167825"], ["83896.30", "4.983269"], ["83887.80", "5.526898"], ["83879.30", "4.620849"], ["83862.30", "4.077220"], ["83845.30", "4.258430"], ["83660.14", "0"], ["83660.00", "0"]], "checksum": -162463952, "ts": "1742554956334"}], "ts": 1742554956343, "record_time": 1742554956.386192, "EXCHANGE": "BITGET"}
{"action": "update", "arg": {"instType": "SPOT", "channel": "books", "instId": "BTCUSDT"}, "data": [{"asks": [["84089.00", "0.565350"], ["84113.62", "0"], ["84175.00", "4.349034"], ["84183.50", "5.345688"], ["84192.00", "3.896010"], ["84200.50", "4.530244"], ["84209.00", "4.167825"], ["84217.50", "4.258430"], ["84226.00", "4.711454"], ["84234.50", "4.802059"], ["84243.00", "4.892664"], ["84251.50", "4.077220"], ["84260.00", "5.073873"], ["84268.50", "5.164478"], ["84277.00", "5.617503"], ["84285.50", "5.436293"], ["84294.00", "4.439639"], ["84302.50", "5.526898"], ["84311.00", "5.255083"], ["84319.50", "4.983269"], ["84328.00", "4.620849"], ["84336.50", "3.986615"], ["84538.75", "0.000011"]], "bids": [["84006.80", "4.258430"], ["83998.30", "3.986615"], ["83989.80", "5.436293"], ["83981.30", "4.620849"], ["83972.80", "4.439639"], ["83964.30", "5.255083"], ["83955.80", "4.167825"], ["83947.30", "5.526898"], ["83938.80", "4.349034"], ["83930.30", "5.164478"], ["83921.80", "3.896010"], ["83904.80", "4.077220"], ["83896.30", "5.073873"], ["83887.80", "4.892664"], ["83879.30", "4.530244"], ["83870.80", "4.983269"], ["83862.30", "4.711454"], ["83845.30", "4.802059"]], "checksum": 347442221, "ts": "1742554956536"}], "ts": 1742554956539, "record_time": 1742554957.059815, "EXCHANGE": "BITGET"}
{"action": "update", "arg": {"instType": "SPOT", "channel": "books", "instId": "BTCUSDT"}, "data": [{"asks": [["84077.01", "2.484846"], ["84081.00", "0.068169"], ["84082.36", "0"], ["84089.98", "0"], ["84093.12", "0.012472"], ["84108.14", "0.181582"], ["84139.40", "0.008670"], ["84183.50", "4.892664"], ["84192.00", "4.983269"], ["84201.10", "0"], ["84209.00", "5.526898"], ["84209.52", "0"], ["84217.50", "4.077220"], ["84226.00", "4.439639"], ["84234.50", "4.711454"], ["84243.00", "5.164478"], ["84251.50", "4.167825"], ["84260.00", "5.255083"], ["84268.50", "5.073873"], ["84277.00", "3.896010"], ["84285.50", "3.986615"], ["84294.00", "4.258430"], ["84302.50", "4.620849"], ["84311.00", "5.617503"], ["84319.50", "4.802059"], ["84328.00", "5.436293"], ["84336.50", "5.345688"], ["84540.00", "0.001092"]], "bids": [["84052.80", "1.008318"], ["84050.80", "2.653469"], ["84048.80", "6.982812"], ["84046.00", "0.006134"], ["84043.90", "0.330060"], ["84043.30", "0.072900"], ["84006.80", "4.349034"], ["84004.20", "0"], ["83998.30", "5.526898"], ["83994.09", "0"], ["83989.80", "4.077220"], ["83981.30", "4.983269"], ["83972.80", "4.167825"], ["83964.30", "5.164478"], ["83955.80", "5.345688"], ["83947.30", "4.892664"], ["83938.80", "3.986615"], ["83930.30", "4.802059"], ["83921.80", "4.258430"], ["83913.30", "3.896010"], ["83904.80", "4.620849"], ["83896.30", "5.255083"], ["83887.80", "5.073873"], ["83879.30", "4.711454"], ["83870.80", "5.617503"], ["83862.30", "4.530244"], ["83853.80", "4.439639"], ["83845.30", "5.436293"], ["83660.14", "0.000016"]], "checksum": 709150276, "ts": "1742554956742"}], "ts": 1742554956745, "record_time": 1742554957.062664, "EXCHANGE": "BITGET"}
{"action": "update", "arg": {"instType": "SPOT", "channel": "books", "instId": "BTCUSDT"}, "data": [{"asks": [["84077.01", "2.239006"], ["84078.00", "0.014828"], ["84105.76", "0.124731"], ["84136.10", "0.067800"], ["84136.70", "0"], ["84139.40", "0.080460"], ["84139.80", "0.144510"], ["84175.00", "5.617503"], ["84179.77", "0.001810"], ["84183.50", "5.526898"], ["84188.18", "0.003620"], ["84192.00", "5.345688"], ["84200.50", "4.167825"], ["84209.00", "4.802059"], ["84217.50", "5.164478"], ["84226.00", "4.620849"], ["84234.50", "5.255083"], ["84243.00", "4.077220"], ["84251.50", "4.530244"], ["84260.00", "4.983269"], ["84268.50", "3.896010"], ["84277.00", "5.436293"], ["84285.50", "4.349034"], ["84294.00", "4.892664"], ["84302.50", "4.258430"], ["84311.00", "4.439639"], ["84319.50", "3.986615"], ["84328.00", "4.711454"], ["84336.50", "5.073873"], ["84537.04", "0"], ["84538.75", "0"], ["84540.00", "0"]], "bids": [["84064.85", "0.041077"], ["84064.35", "0"], ["84056.80", "0.145812"], ["84054.80", "0.383717"], ["84052.80", "1.009782"], ["84050.80", "2.657321"], ["84048.80", "6.992949"], ["84043.30", "0"], ["84037.00", "0.000032"], ["84031.00", "0.000032"], ["84030.00", "0.002956"], ["84029.00", "0.000032"], ["84028.00", "0.000015"], ["84006.80", "5.526898"], ["83998.30", "5.255083"], ["83989.80", "5.073873"], ["83986.03", "0.001810"], ["83981.30", "4.620849"], ["83976.59", "0.003620"], ["83972.80", "5.617503"], ["83964.30", "4.077220"], ["83955.80", "4.983269"], ["83947.30", "4.439639"], ["83938.80", "5.164478"], ["83930.30", "3.986615"], ["83921.80", "4.711454"], ["83913.30", "4.802059"], ["83904.80", "5.345688"], ["83896.30", "3.896010"], ["83887.80", "4.167825"], ["83879.30", "5.436293"], ["83870.80", "4.258430"], ["83862.30", "4.892664"], ["83853.80", "4.349034"], ["83845.30", "4.530244"], ["83660.71", "0"], ["83660.14", "0"]], "checksum": -349003322, "ts": "1742554956958"}], "ts": 1742554956961, "record_time": 1742554957.065689, "EXCHANGE": "BITGET"}
{"action": "update", "arg": {"instType": "SPOT", "channel": "books", "instId": "BTCUSDT"}, "data": [{"asks": [["84077.01", "2.752806"], ["84130.99", "0.431915"], ["84133.10", "0.001040"], ["84134.50", "2.717640"], ["84145.70", "0"], ["84175.00", "3.986615"], ["84183.50", "4.077220"], ["84192.00", "5.617503"], ["84200.50", "4.349034"], ["84209.00", "4.167825"], ["84217.50", "5.073873"], ["84226.00", "5.526898"], ["84234.50", "4.530244"], ["84243.00", "4.983269"], ["84251.50", "4.892664"], ["84260.00", "4.711454"], ["84268.50", "5.255083"], ["84277.00", "5.345688"], ["84285.50", "4.620849"], ["84294.00", "4.439639"], ["84302.50", "5.164478"], ["84311.00", "3.896010"], ["84319.50", "4.802059"], ["84328.00", "4.258430"], ["84336.50", "5.436293"], ["84536.36", "0"]], "bids": [["84066.98", "0"], ["84054.80", "0.383544"], ["84052.80", "1.009328"], ["84050.80", "2.656126"], ["84048.80", "6.989806"], ["84047.90", "0"], ["84006.80", "4.711454"], ["83998.30", "4.892664"], ["83989.80", "4.349034"], ["83981.30", "5.617503"], ["83972.80", "4.258430"], ["83964.30", "3.986615"], ["83955.80", "5.345688"], ["83947.30", "5.255083"], ["83938.80", "4.983269"], ["83930.30", "4.167825"], ["83921.80", "3.896010"], ["83904.80", "5.073873"], ["83896.30", "4.620849"], ["83887.80", "5.164478"], ["83879.30", "4.077220"], ["83870.80", "4.439639"], ["83862.30", "4.530244"], ["83853.80", "5.436293"], ["83845.30", "5.526898"], ["83660.71", "0.000309"], ["83660.14", "0.000016"]], "checksum": -349433972, "ts": "1742554957157"}], "ts": 1742554957161, "record_time": 1742554957.188853, "EXCHANGE": "BITGET"}
{"action": "update", "arg": {"instType": "SPOT", "channel": "books", "instId": "BTCUSDT"}, "data": [{"asks": [["84077.01", "3.016146"], ["84117.00", "0.003188"], ["84119.00", "0.008389"], ["84121.00", "0.022076"], ["84123.00", "0.058095"], ["84125.00", "0.152883"], ["84127.00", "0.402322"], ["84129.00", "1.058742"], ["84131.00", "2.786163"], ["84133.00", "7.332008"], ["84175.00", "3.896010"], ["84183.50", "4.258430"], ["84192.00", "4.983269"], ["84200.50", "5.617503"], ["84209.00", "4.620849"], ["84217.50", "5.345688"], ["84226.00", "4.077220"], ["84234.50", "4.711454"], ["84243.00", "4.892664"], ["84251.50", "5.436293"], ["84260.00", "4.530244"], ["84268.50", "5.073873"], ["84277.00", "4.167825"], ["84285.50", "4.439639"], ["84294.00", "5.526898"], ["84302.50", "5.255083"], ["84311.00", "3.986615"], ["84319.50", "4.349034"], ["84328.00", "5.164478"], ["84336.50", "4.802059"]], "bids": [["84069.30", "0.019223"], ["84065.28", "0.041076"], ["84064.85", "0"], ["84064.80", "0.002890"], ["84062.80", "0.007607"], ["84060.80", "0.020017"], ["84058.80", "0.052677"], ["84056.80", "0.138624"], ["84054.80", "0.364800"], ["84052.80", "0.960000"], ["84050.80", "2.526315"], ["84048.80", "6.648198"], ["84048.70", "0.001560"], ["84041.70", "0.022770"], ["84038.40", "0"], ["84028.00", "0.000032"], ["84006.80", "5.073873"], ["83998.30", "4.983269"], ["83989.80", "3.896010"], ["83981.30", "4.620849"], ["83972.80", "5.526898"], ["83964.30", "5.617503"], ["83955.80", "4.439639"], ["83947.30", "4.258430"], ["83938.80", "4.711454"], ["83930.30", "4.892664"], ["83921.80", "4.077220"], ["83913.30", "5.345688"], ["83904.80", "3.986615"], ["83896.30", "4.530244"], ["83887.80", "4.802059"], ["83879.30", "5.255083"], ["83870.80", "4.349034"], ["83862.30", "5.436293"], ["83853.80", "5.164478"], ["83845.30", "4.167825"], ["83660.14", "0"]], "checksum": -304887044, "ts": "1742554957363"}], "ts": 1742554957369, "record_time": 1742554957.396224, "EXCHANGE": "BITGET"}
{"action": "update", "arg": {"instType": "SPOT", "channel": "books", "instId": "BTCUSDT"}, "data": [{"asks": [["84077.01", "2.310751"], ["84117.00", "0.002714"], ["84119.00", "0.007141"], ["84121.00", "0.018792"], ["84123.00", "0.049454"], ["84125.00", "0.130140"], ["84127.00", "0.342475"], ["84129.00", "0.901249"], ["84131.00", "2.371710"], ["84133.00", "6.241342"], ["84142.00", "0.550500"], ["84144.00", "0.321060"], ["84145.40", "0"], ["84175.00", "5.617503"], ["84183.50", "5.345688"], ["84192.00", "4.530244"], ["84200.50", "4.983269"], ["84217.50", "5.164478"], ["84226.00", "3.896010"], ["84234.50", "4.167825"], ["84243.00", "4.258430"], ["84251.50", "4.439639"], ["84260.00", "5.526898"], ["84268.50", "4.802059"], ["84277.00", "4.349034"], ["84285.50", "5.255083"], ["84294.00", "4.892664"], ["84302.50", "3.986615"], ["84311.00", "5.073873"], ["84319.50", "4.077220"], ["84328.00", "4.711454"], ["84336.50", "5.436293"]], "bids": [["84048.80", "6.648328"], ["84048.70", "0.001140"], ["84045.90", "0.073200"], ["84044.60", "0"], ["84043.90", "0.329850"], ["84043.10", "0.070320"], ["84037.90", "0.120000"], ["84034.50", "0.153580"], ["84015.10", "0"], ["84006.80", "5.526898"], ["84005.00", "0.200459"], ["83998.30", "4.802059"], ["83981.30", "4.167825"], ["83972.80", "5.617503"], ["83964.30", "4.077220"], ["83955.80", "5.436293"], ["83947.30", "5.073873"], ["83938.80", "5.345688"], ["83921.80", "3.986615"], ["83913.30", "4.530244"], ["83904.80", "4.983269"], ["83896.30", "4.439639"], ["83887.80", "5.255083"], ["83879.30", "4.711454"], ["83870.80", "5.164478"], ["83862.30", "4.620849"], ["83853.80", "4.349034"], ["83845.30", "4.258430"], ["83661.08", "0"], ["83660.71", "0"]], "checksum": -1081037888, "ts": "1742554957571"}], "ts": 1742554957574, "record_time": 1742554957.613002, "EXCHANGE": "BITGET"}
{"action": "update", "arg": {"instType": "SPOT", "channel": "books", "instId": "BTCUSDT"}, "data": [{"asks": [["84077.01", "2.555878"], ["84093.12", "0"], ["84117.00", "0.003078"], ["84119.00", "0.008098"], ["84121.00", "0.021313"], ["84123.00", "0.056085"], ["84125.00", "0.147593"], ["84127.00", "0.388403"], ["84129.00", "1.022112"], ["84131.00", "2.689770"], ["84133.00", "7.078342"], ["84175.00", "4.802059"], ["84183.50", "4.439639"], ["84192.00", "4.711454"], ["84200.50", "4.167825"], ["84209.00", "5.526898"], ["84217.50", "3.896010"], ["84226.00", "4.349034"], ["84234.50", "3.986615"], ["84243.00", "5.436293"], ["84251.50", "5.345688"], ["84260.00", "4.983269"], ["84268.50", "4.530244"], ["84277.00", "4.258430"], ["84285.50", "4.077220"], ["84294.00", "5.164478"], ["84302.50", "5.073873"], ["84311.00", "5.255083"], ["84319.50", "4.620849"], ["84328.00", "4.892664"], ["84336.50", "5.617503"], ["84427.29", "1.707455"], ["84433.67", "0"], ["84536.36", "0.000053"]], "bids": [["84069.88", "0.019223"], ["84069.30", "0"], ["84054.80", "0.364981"], ["84052.80", "0.960475"], ["84050.80", "2.527566"], ["84048.80", "6.651490"], ["84045.40", "1.782420"], ["84035.00", "0.000032"], ["84024.30", "0.000396"], ["84006.80", "4.983269"], ["84005.60", "0"], ["83998.30", "5.526898"], ["83994.90", "0.000948"], ["83989.80", "4.258430"], ["83981.30", "4.077220"], ["83964.30", "4.802059"], ["83955.80", "5.164478"], ["83947.30", "5.345688"], ["83938.80", "5.073873"], ["83930.30", "4.530244"], ["83921.80", "4.620849"], ["83913.30", "4.349034"], ["83904.80", "5.436293"], ["83896.30", "3.896010"], ["83887.80", "4.892664"], ["83879.30", "5.255083"], ["83870.80", "4.167825"], ["83862.30", "4.439639"], ["83853.80", "3.986615"], ["83845.30", "4.711454"], ["83760.88", "0"], ["83754.56", "1.610544"], ["83661.60", "0"]], "checksum": -48818370, "ts": "1742554957771"}], "ts": 1742554957774, "record_time": 1742554957.848165, "EXCHANGE": "BITGET"}
{"action": "update", "arg": {"instType": "SPOT", "channel": "books", "instId": "BTCUSDT"}, "data": [{"asks": [["84077.01", "2.310038"], ["84101.76", "0.012472"], ["84113.40", "0.064018"], ["84175.00", "5.617503"], ["84192.00", "3.986615"], ["84200.50", "4.349034"], ["84203.60", "0"], ["84209.00", "4.167825"], ["84217.50", "4.802059"], ["84226.00", "4.983269"], ["84234.50", "5.526898"], ["84243.00", "4.711454"], ["84251.50", "3.896010"], ["84260.00", "4.892664"], ["84268.50", "4.258430"], ["84277.00", "5.255083"], ["84285.50", "4.620849"], ["84294.00", "4.530244"], ["84311.00", "4.077220"], ["84319.50", "5.345688"], ["84328.00", "5.164478"], ["84336.50", "5.436293"], ["84536.36", "0"]], "bids": [["84065.64", "0.041076"], ["84065.28", "0"], ["84065.06", "0.010000"], ["84048.80", "6.651676"], ["84027.00", "0.000015"], ["84006.80", "4.349034"], ["83998.30", "4.983269"], ["83989.80", "4.892664"], ["83981.30", "5.255083"], ["83972.80", "3.986615"], ["83964.30", "5.526898"], ["83955.80", "5.617503"], ["83947.30", "5.436293"], ["83938.80", "4.530244"], ["83930.30", "4.077220"], ["83921.80", "4.167825"], ["83913.30", "5.073873"], ["83904.80", "5.164478"], ["83896.30", "4.711454"], ["83887.80", "4.620849"], ["83879.30", "5.345688"], ["83870.80", "3.896010"], ["83862.30", "4.802059"], ["83853.80", "4.258430"], ["83845.30", "4.439639"], ["83662.50", "0"], ["83661.97", "0"]], "checksum": -596997886, "ts": "1742554957972"}], "ts": 1742554957975, "record_time": 1742554957.998311, "EXCHANGE": "BITGET"}
{"action": "update", "arg": {"instType": "SPOT", "channel": "books", "instId": "BTCUSDT"}, "data": [{"asks": [["84077.01", "2.770038"], ["84144.90", "0"], ["84175.00", "3.896010"], ["84192.00", "5.164478"], ["84200.50", "5.345688"], ["84209.00", "4.802059"], ["84217.50", "4.530244"], ["84226.00", "4.892664"], ["84243.00", "5.073873"], ["84251.50", "4.711454"], ["84260.00", "4.983269"], ["84268.50", "5.436293"], ["84277.00", "4.620849"], ["84285.50", "5.255083"], ["84294.00", "4.258430"], ["84302.50", "4.167825"], ["84311.00", "4.349034"], ["84319.50", "3.986615"], ["84328.00", "5.617503"], ["84336.50", "4.077220"], ["84536.36", "0.000053"]], "bids": [["84027.00", "0.000032"], ["84006.80", "5.345688"], ["83989.80", "4.620849"], ["83981.30", "5.436293"], ["83972.80", "5.255083"], ["83964.30", "3.986615"], ["83955.80", "4.167825"], ["83947.30", "5.164478"], ["83938.80", "3.896010"], ["83930.30", "4.711454"], ["83921.80", "5.526898"], ["83904.80", "5.617503"], ["83896.30", "4.439639"], ["83887.80", "4.892664"], ["83879.30", "4.530244"], ["83870.80", "4.258430"], ["83862.30", "4.077220"], ["83853.80", "4.802059"], ["83845.30", "4.349034"]], "checksum": 534472012, "ts": "1742554958180"}], "ts": 1742554958183, "record_time": 1742554958.20493, "EXCHANGE": "BITGET"}
{"action": "update", "arg": {"instType": "SPOT", "channel": "books", "instId": "BTCUSDT"}, "data": [{"asks": [["84077.01", "3.015878"], ["84117.00", "0.002714"], ["84119.00", "0.007141"], ["84121.00", "0.018792"], ["84123.00", "0.049454"], ["84125.00", "0.130140"], ["84127.00", "0.342475"], ["84129.00", "0.901249"], ["84131.00", "2.371710"], ["84133.00", "6.241342"], ["84144.90", "0.228000"], ["84175.00", "4.077220"], ["84183.50", "5.164478"], ["84192.00", "4.711454"], ["84200.50", "4.983269"], ["84209.00", "5.436293"], ["84217.50", "4.802059"], ["84226.00", "4.530244"], ["84234.50", "4.349034"], ["84251.50", "5.345688"], ["84260.00", "4.892664"], ["84268.50", "4.258430"], ["84277.00", "5.255083"], ["84285.50", "5.526898"], ["84294.00", "4.439639"], ["84311.00", "4.620849"], ["84328.00", "3.896010"], ["84336.50", "5.617503"], ["84536.36", "0"]], "bids": [["84065.64", "0"], ["84037.90", "2.476020"], ["84006.80", "5.436293"], ["83998.30", "4.711454"], ["83989.80", "4.077220"], ["83981.30", "4.983269"], ["83972.80", "4.349034"], ["83955.80", "5.164478"], ["83947.30", "4.892664"], ["83938.80", "4.167825"], ["83930.30", "5.073873"], ["83921.80", "5.255083"], ["83913.30", "4.802059"], ["83904.80", "5.526898"], ["83896.30", "4.530244"], ["83887.80", "5.617503"], ["83879.30", "4.439639"], ["83870.80", "3.896010"], ["83862.30", "5.345688"], ["83853.80", "4.620849"], ["83845.30", "4.258430"], ["83662.50", "0.000077"]], "checksum": -1296951195, "ts": "1742554958381"}], "ts": 1742554958386, "record_time": 1742554958.4104, "EXCHANGE": "BITGET"}
{"action": "update", "arg": {"instType": "SPOT", "channel": "books", "instId": "BTCUSDT"}, "data": [{"asks": [["84117.00", "0.003078"], ["84119.00", "0.008098"], ["84121.00", "0.021313"], ["84123.00", "0.056085"], ["84125.00", "0.147593"], ["84127.00", "0.388403"], ["84129.00", "1.022112"], ["84131.00", "2.689770"], ["84133.00", "7.078342"], ["84138.00", "0.070200"], ["84142.90", "0.071070"], ["84144.90", "0"], ["84175.00", "3.986615"], ["84183.50", "4.167825"], ["84192.00", "5.436293"], ["84200.50", "4.530244"], ["84209.00", "5.526898"], ["84217.50", "5.255083"], ["84226.00", "4.258430"], ["84243.00", "4.439639"], ["84251.50", "5.164478"], ["84260.00", "4.077220"], ["84268.50", "5.073873"], ["84277.00", "4.711454"], ["84285.50", "3.896010"], ["84294.00", "4.802059"], ["84302.50", "4.892664"], ["84311.00", "5.617503"], ["84319.50", "5.345688"], ["84328.00", "4.983269"], ["84336.50", "4.620849"], ["84535.32", "0"]], "bids": [["84066.11", "0.041076"], ["84006.80", "4.530244"], ["83998.30", "4.167825"], ["83989.80", "5.345688"], ["83981.30", "4.802059"], ["83964.30", "4.892664"], ["83955.80", "4.258430"], ["83947.30", "5.164478"], ["83938.80", "4.439639"], ["83930.30", "5.526898"], ["83921.80", "4.077220"], ["83913.30", "5.617503"], ["83904.80", "5.255083"], ["83896.30", "4.983269"], ["83887.80", "3.986615"], ["83879.30", "4.711454"], ["83870.80", "5.073873"], ["83862.30", "4.620849"], ["83853.80", "3.896010"], ["83845.30", "5.436293"], ["83662.50", "0"]], "checksum": 1678452631, "ts": "1742554958585"}], "ts": 1742554958590, "record_time": 1742554958.614827, "EXCHANGE": "BITGET"}
{"action": "update", "arg": {"instType": "SPOT", "channel": "books", "instId": "BTCUSDT"}, "data": [{"asks": [["84108.14", "0"], ["84109.72", "0.010000"], ["84117.00", "0.002714"], ["84119.00", "0.007141"], ["84121.00", "0.018792"], ["84123.00", "0.049454"], ["84125.00", "0.130140"], ["84127.00", "0.342475"], ["84129.00", "0.901249"], ["84131.00", "2.371710"], ["84133.00", "6.241546"], ["84138.00", "0"], ["84144.90", "0.228000"], ["84175.00", "4.802059"], ["84183.50", "4.892664"], ["84192.00", "5.164478"], ["84200.50", "5.526898"], ["84209.00", "4.439639"], ["84217.50", "4.077220"], ["84226.00", "3.896010"], ["84234.50", "4.258430"], ["84243.00", "4.349034"], ["84251.50", "3.986615"], ["84260.00", "5.617503"], ["84268.50", "4.711454"], ["84277.00", "5.255083"], ["84285.50", "5.345688"], ["84294.00", "4.620849"], ["84302.50", "4.983269"], ["84311.00", "4.167825"], ["84319.50", "5.073873"], ["84328.00", "5.436293"], ["84336.50", "4.530244"]], "bids": [["84070.71", "0.019223"], ["84069.88", "0"], ["84054.80", "0.364816"], ["84052.80", "0.960043"], ["84050.80", "2.526428"], ["84048.80", "6.648496"], ["84006.80", "5.617503"], ["83998.30", "5.073873"], ["83989.80", "5.164478"], ["83981.30", "4.167825"], ["83972.80", "4.711454"], ["83964.30", "4.258430"], ["83955.80", "4.983269"], ["83947.30", "5.345688"], ["83938.80", "5.526898"], ["83930.30", "5.436293"], ["83921.80", "3.896010"], ["83913.30", "4.349034"], ["83904.80", "4.620849"], ["83896.30", "4.530244"], ["83887.80", "4.439639"], ["83879.30", "3.986615"], ["83870.80", "4.892664"], ["83862.30", "5.255083"], ["83853.80", "4.802059"], ["83845.30", "4.077220"]], "checksum": 510589313, "ts": "1742554958785"}], "ts": 1742554958788, "record_time": 1742554958.811332, "EXCHANGE": "BITGET"}
{"action": "update", "arg": {"instType": "SPOT", "channel": "books", "instId": "BTCUSDT"}, "data": [{"asks": [["84105.43", "0.182918"], ["84105.76", "0.070256"], ["84127.00", "0.342579"], ["84129.00", "0.901523"], ["84131.00", "2.372431"], ["84133.00", "6.243239"], ["84145.40", "0.480000"], ["84175.00", "4.530244"], ["84183.50", "5.617503"], ["84192.00", "5.255083"], ["84200.50", "3.896010"], ["84209.00", "5.436293"], ["84217.50", "5.073873"], ["84226.00", "5.164478"], ["84234.50", "4.077220"], ["84243.00", "4.711454"], ["84251.50", "4.892664"], ["84260.00", "4.439639"], ["84268.50", "5.526898"], ["84277.00", "4.258430"], ["84285.50", "4.802059"], ["84294.00", "4.349034"], ["84302.50", "5.345688"], ["84311.00", "4.620849"], ["84319.50", "4.167825"], ["84328.00", "4.983269"], ["84336.50", "3.986615"], ["84533.33", "0"], ["84534.53", "0"]], "bids": [["84066.51", "0.041076"], ["84066.11", "0"], ["84062.82", "0"], ["84026.00", "0.000032"], ["84006.80", "4.258430"], ["83998.30", "5.255083"], ["83981.30", "4.439639"], ["83972.80", "4.077220"], ["83964.30", "4.711454"], ["83955.80", "5.526898"], ["83947.30", "4.892664"], ["83938.80", "4.530244"], ["83930.30", "4.802059"], ["83921.80", "5.073873"], ["83904.80", "3.986615"], ["83896.30", "4.620849"], ["83887.80", "4.167825"], ["83879.30", "5.345688"], ["83870.80", "4.983269"], ["83862.30", "5.436293"], ["83853.80", "5.617503"], ["83845.30", "3.896010"]], "checksum": -99580961, "ts": "1742554958987"}], "ts": 1742554958990, "record_time": 1742554959.05004, "EXCHANGE": "BITGET"}
{"action": "update", "arg": {"instType": "SPOT", "channel": "books", "instId": "BTCUSDT"}, "data": [{"asks": [["84175.00", "5.436293"], ["84183.50", "5.526898"], ["84200.50", "4.892664"], ["84209.00", "5.164478"], ["84217.50", "4.983269"], ["84226.00", "4.711454"], ["84234.50", "4.167825"], ["84243.00", "4.439639"], ["84251.50", "3.986615"], ["84260.00", "4.349034"], ["84268.50", "4.620849"], ["84277.00", "5.617503"], ["84285.50", "4.077220"], ["84294.00", "4.802059"], ["84302.50", "3.896010"], ["84311.00", "5.345688"], ["84319.50", "4.258430"], ["84328.00", "5.073873"], ["84336.50", "4.530244"]], "bids": [["84061.73", "0.112988"], ["84054.80", "0.364965"], ["84052.80", "0.960435"], ["84050.80", "2.527460"], ["84048.80", "6.651211"], ["84006.80", "4.439639"], ["83998.30", "3.896010"], ["83989.80", "5.255083"], ["83981.30", "4.349034"], ["83972.80", "4.530244"], ["83964.30", "4.802059"], ["83955.80", "4.077220"], ["83947.30", "3.986615"], ["83938.80", "4.892664"], ["83930.30", "4.711454"], ["83921.80", "5.164478"], ["83913.30", "5.073873"], ["83904.80", "5.345688"], ["83887.80", "5.526898"], ["83879.30", "5.436293"], ["83870.80", "4.167825"], ["83862.30", "5.617503"], ["83853.80", "4.258430"], ["83845.30", "4.983269"], ["83663.91", "0"]], "checksum": -874397230, "ts": "1742554959217"}], "ts": 1742554959225, "record_time": 1742554959.24963, "EXCHANGE": "BITGET"}
{"action": "update", "arg": {"instType": "SPOT", "channel": "books", "instId": "BTCUSDT"}, "data": [{"asks": [["84077.01", "2.310038"], ["84175.00", "4.439639"], ["84183.50", "5.436293"], ["84192.00", "5.526898"], ["84200.50", "5.345688"], ["84209.00", "4.802059"], ["84217.50", "5.073873"], ["84226.00", "4.620849"], ["84234.50", "5.617503"], ["84243.00", "4.711454"], ["84251.50", "4.167825"], ["84260.00", "5.255083"], ["84268.50", "4.349034"], ["84277.00", "4.077220"], ["84285.50", "3.896010"], ["84294.00", "4.530244"], ["84302.50", "3.986615"], ["84311.00", "4.258430"], ["84319.50", "4.983269"], ["84328.00", "4.892664"], ["84336.50", "5.164478"]], "bids": [["84052.80", "0.960583"], ["84050.80", "2.527849"], ["84048.80", "6.652234"], ["84044.60", "0.015000"], ["84037.90", "0.120000"], ["84006.80", "4.167825"], ["83998.30", "4.711454"], ["83989.80", "4.620849"], ["83964.30", "3.986615"], ["83955.80", "5.073873"], ["83947.30", "5.345688"], ["83938.80", "4.258430"], ["83930.30", "5.255083"], ["83921.80", "5.617503"], ["83913.30", "4.802059"], ["83904.80", "5.436293"], ["83896.30", "4.892664"], ["83887.80", "4.077220"], ["83879.30", "4.983269"], ["83870.80", "3.896010"], ["83862.30", "5.164478"], ["83853.80", "4.439639"], ["83845.30", "5.526898"], ["83663.95", "0"]], "checksum": -1946260408, "ts": "1742554959434"}], "ts": 1742554959437, "record_time": 1742554959.463129, "EXCHANGE": "BITGET"}
{"action": "update", "arg": {"instType": "SPOT", "channel": "books", "instId": "BTCUSDT"}, "data": [{"asks": [["84095.30", "0.016429"], ["84097.14", "0"], ["84105.41", "0.010988"], ["84107.90", "0"], ["84175.00", "4.167825"], ["84192.00", "3.896010"], ["84200.50", "5.617503"], ["84209.00", "5.255083"], ["84217.50", "4.530244"], ["84226.00", "4.077220"], ["84234.50", "4.892664"], ["84251.50", "4.620849"], ["84260.00", "4.439639"], ["84268.50", "3.986615"], ["84277.00", "4.983269"], ["84285.50", "5.345688"], ["84294.00", "4.802059"], ["84302.50", "4.349034"], ["84311.00", "5.526898"], ["84319.50", "5.073873"], ["84328.00", "4.258430"]], "bids": [["84066.88", "0.041076"], ["84066.51", "0"], ["84047.54", "0"], ["84045.70", "0.028860"], ["84037.28", "0"], ["84034.79", "0.056358"], ["84006.80", "4.711454"], ["83998.30", "4.077220"], ["83981.30", "5.345688"], ["83972.80", "4.892664"], ["83964.30", "5.073873"], ["83955.80", "4.983269"], ["83947.30", "5.617503"], ["83938.80", "5.164478"], ["83930.30", "4.802059"], ["83921.80", "5.526898"], ["83913.30", "4.530244"], ["83904.80", "4.439639"], ["83896.30", "5.255083"], ["83887.80", "3.986615"], ["83879.30", "5.436293"], ["83862.30", "4.349034"], ["83853.80", "4.167825"], ["83845.30", "4.258430"]], "checksum": 1929600888, "ts": "1742554959634"}], "ts": 1742554959639, "record_time": 1742554959.674528, "EXCHANGE": "BITGET"}
{"action": "update", "arg": {"instType": "SPOT", "channel": "books", "instId": "BTCUSDT"}, "data": [{"asks": [["84133.00", "6.242997"], ["84133.90", "0.343650"], ["84134.10", "0.067800"], ["84134.40", "1.472520"], ["84134.90", "0.141840"], ["84135.80", "0"], ["84145.40", "0"], ["84175.00", "4.077220"], ["84192.00", "4.258430"], ["84200.50", "4.530244"], ["84209.00", "4.349034"], ["84217.50", "4.620849"], ["84226.00", "5.164478"], ["84234.50", "5.617503"], ["84243.00", "5.345688"], ["84251.50", "4.892664"], ["84260.00", "3.896010"], ["84268.50", "5.526898"], ["84277.00", "4.711454"], ["84285.50", "5.255083"], ["84302.50", "5.073873"], ["84311.00", "4.983269"], ["84319.50", "4.167825"], ["84328.00", "3.986615"], ["84336.50", "4.439639"], ["84533.33", "0.003186"]], "bids": [["84040.50", "0.071340"], ["84039.60", "2.355960"], ["84037.90", "0"], ["84027.00", "0"], ["84006.80", "5.164478"], ["83998.30", "5.345688"], ["83989.80", "4.167825"], ["83981.30", "4.892664"], ["83972.80", "4.439639"], ["83964.30", "4.530244"], ["83955.80", "5.436293"], ["83947.30", "4.258430"], ["83938.80", "5.617503"], ["83930.30", "3.896010"], ["83921.80", "4.983269"], ["83913.30", "4.077220"], ["83904.80", "4.620849"], ["83896.30", "4.711454"], ["83887.80", "5.526898"], ["83879.30", "4.802059"], ["83870.80", "3.986615"], ["83862.30", "5.255083"], ["83853.80", "4.349034"], ["83845.30", "5.073873"]], "checksum": 1929600888, "ts": "1742554959835"}], "ts": 1742554959837, "record_time": 1742554959.860299, "EXCHANGE": "BITGET"}
{"action": "update", "arg": {"instType": "SPOT", "channel": "books", "instId": "BTCUSDT"}, "data": [{"asks": [["84077.01", "3.015878"], ["84079.01", "0"], ["84105.42", "0.121835"], ["84105.76", "0"], ["84133.90", "0.333870"], ["84134.40", "1.028160"], ["84140.90", "0.450240"], ["84144.90", "0"], ["84175.00", "4.892664"], ["84183.50", "4.167825"], ["84192.00", "5.255083"], ["84200.50", "5.526898"], ["84209.00", "4.077220"], ["84217.50", "5.345688"], ["84226.00", "4.530244"], ["84234.50", "4.349034"], ["84243.00", "5.164478"], ["84251.50", "4.983269"], ["84260.00", "4.711454"], ["84268.50", "4.439639"], ["84277.00", "5.617503"], ["84285.50", "3.896010"], ["84287.20", "0"], ["84294.00", "5.073873"], ["84302.50", "4.258430"], ["84311.00", "3.986615"], ["84319.50", "5.436293"], ["84328.00", "4.802059"], ["84336.50", "4.620849"], ["84534.53", "0.000461"], ["84535.32", "0.000039"]], "bids": [["84066.88", "0"], ["84054.80", "0.364824"], ["84052.80", "0.960061"], ["84050.80", "2.526478"], ["84048.80", "6.648626"], ["84044.60", "0.030000"], ["84040.50", "0"], ["84037.90", "0.120000"], ["84006.80", "5.436293"], ["83998.30", "4.711454"], ["83989.80", "4.892664"], ["83981.30", "4.258430"], ["83972.80", "5.164478"], ["83964.30", "5.526898"], ["83955.80", "3.986615"], ["83947.30", "3.896010"], ["83938.80", "5.345688"], ["83930.30", "4.620849"], ["83921.80", "4.349034"], ["83913.30", "4.439639"], ["83904.80", "4.167825"], ["83896.30", "4.802059"], ["83887.80", "4.983269"], ["83879.30", "5.073873"], ["83870.80", "4.077220"], ["83862.30", "4.530244"], ["83853.80", "5.617503"], ["83845.30", "5.255083"], ["83663.95", "0.000022"]], "checksum": 788856795, "ts": "1742554960035"}], "ts": 1742554960038, "record_time": 1742554960.06053, "EXCHANGE": "BITGET"}
{"action": "update", "arg": {"instType": "SPOT", "channel": "books", "instId": "BTCUSDT"}, "data": [{"asks": [["84077.01", "3.128865"], ["84086.36", "0"], ["84089.64", "0.006356"], ["84091.00", "0.119870"], ["84094.28", "0.010984"], ["84115.00", "0.001012"], ["84119.00", "0.006916"], ["84121.00", "0.018200"], ["84123.00", "0.047896"], ["84125.00", "0.126041"], ["84127.00", "0.331687"], ["84127.67", "0.001597"], ["84129.00", "0.872860"], ["84131.00", "2.297001"], ["84131.59", "0"], ["84133.00", "6.044740"], ["84137.30", "0.464910"], ["84138.30", "0.072870"], ["84142.90", "0"], ["84143.90", "0.321090"], ["84144.00", "0"], ["84175.00", "4.530244"], ["84183.50", "4.892664"], ["84192.00", "4.258430"], ["84209.00", "4.439639"], ["84217.50", "5.073873"], ["84226.00", "5.255083"], ["84234.50", "4.077220"], ["84243.00", "5.345688"], ["84251.50", "4.711454"], ["84260.00", "4.349034"], ["84266.11", "0.167643"], ["84268.50", "4.802059"], ["84277.00", "4.167825"], ["84285.50", "4.620849"], ["84294.00", "4.983269"], ["84302.50", "3.896010"], ["84311.00", "5.164478"], ["84319.50", "3.986615"], ["84328.00", "5.617503"], ["84336.50", "5.436293"], ["84534.53", "0"], ["84535.32", "0"]], "bids": [["84067.23", "0.041075"], ["84065.06", "0"], ["84054.80", "0.364563"], ["84053.22", "0"], ["84052.80", "0.959377"], ["84052.59", "0.004016"], ["84050.80", "2.524675"], ["84049.80", "0.247547"], ["84048.80", "6.643883"], ["84045.16", "0"], ["84037.90", "0"], ["84035.50", "0"], ["84033.41", "0.000876"], ["84025.00", "0.000017"], ["84017.41", "0"], ["84017.31", "0"], ["84015.19", "0.003596"], ["84013.50", "0.001173"], ["84006.80", "4.620849"], ["83998.30", "4.167825"], ["83989.80", "4.530244"], ["83981.30", "4.802059"], ["83972.80", "4.439639"], ["83964.30", "4.983269"], ["83955.80", "5.617503"], ["83947.30", "4.077220"], ["83938.80", "4.258430"], ["83930.30", "5.255083"], ["83921.80", "5.436293"], ["83913.30", "3.986615"], ["83904.80", "5.073873"], ["83896.30", "5.526898"], ["83887.80", "4.349034"], ["83879.30", "3.896010"], ["83870.80", "4.711454"], ["83862.30", "5.164478"], ["83853.80", "5.345688"], ["83845.30", "4.892664"]], "checksum": 255060169, "ts": "1742554960239"}], "ts": 1742554960243, "record_time": 1742554960.266112, "EXCHANGE": "BITGET"}
{"action": "update", "arg": {"instType": "SPOT", "channel": "books", "instId": "BTCUSDT"}, "data": [{"asks": [["84117.00", "0.002589"], ["84119.00", "0.006814"], ["84121.00", "0.017930"], ["84123.00", "0.047184"], ["84125.00", "0.124171"], ["84125.64", "0.001598"], ["84127.00", "0.326764"], ["84128.65", "0"], ["84129.00", "0.859907"], ["84131.00", "2.262700"], ["84133.00", "5.954474"], ["84138.30", "0"], ["84175.00", "5.073873"], ["84183.50", "4.983269"], ["84192.00", "4.620849"], ["84200.50", "4.167825"], ["84209.00", "5.345688"], ["84217.50", "4.258430"], ["84226.00", "4.349034"], ["84234.50", "4.802059"], ["84243.00", "5.436293"], ["84260.00", "5.526898"], ["84268.50", "4.439639"], ["84277.00", "5.617503"], ["84285.50", "4.892664"], ["84294.00", "3.986615"], ["84302.50", "5.164478"], ["84311.00", "3.896010"], ["84319.50", "4.077220"], ["84328.00", "5.255083"], ["84336.50", "4.530244"], ["84534.53", "0.000461"]], "bids": [["84056.80", "0.138513"], ["84052.80", "0.959232"], ["84050.80", "2.524294"], ["84048.80", "6.642878"], ["84046.77", "0.055647"], ["84044.92", "0"], ["84025.00", "0.000032"], ["84018.34", "0"], ["84015.34", "0.001176"], ["84006.80", "5.526898"], ["83998.30", "4.258430"], ["83989.80", "5.345688"], ["83972.80", "5.073873"], ["83964.30", "3.896010"], ["83955.80", "5.436293"], ["83947.30", "4.167825"], ["83938.80", "4.892664"], ["83930.30", "4.439639"], ["83921.80", "5.255083"], ["83913.30", "4.349034"], ["83904.80", "3.986615"], ["83896.30", "4.077220"], ["83887.80", "4.983269"], ["83879.30", "5.617503"], ["83853.80", "4.620849"], ["83845.30", "4.530244"]], "checksum": 255060169, "ts": "1742554960459"}], "ts": 1742554960462, "record_time": 1742554960.484409, "EXCHANGE": "BITGET"}
{"action": "update", "arg": {"instType": "SPOT", "channel": "books", "instId": "BTCUSDT"}, "data": [{"asks": [["84077.01", "2.423025"], ["84109.72", "0"], ["84175.00", "3.896010"], ["84183.50", "5.073873"], ["84192.00", "5.436293"], ["84200.50", "4.258430"], ["84209.00", "4.530244"], ["84217.50", "4.620849"], ["84226.00", "4.167825"], ["84234.50", "3.986615"], ["84243.00", "4.711454"], ["84251.50", "4.892664"], ["84260.00", "4.077220"], ["84268.50", "4.983269"], ["84277.00", "4.349034"], ["84285.50", "4.439639"], ["84294.00", "5.526898"], ["84302.50", "5.345688"], ["84311.00", "5.617503"], ["84319.50", "4.802059"], ["84336.50", "5.164478"], ["84535.32", "0.000039"]], "bids": [["84070.71", "0"], ["84067.48", "0.041075"], ["84067.23", "0"], ["84054.80", "0.364756"], ["84052.80", "0.959885"], ["84050.80", "2.526011"], ["84048.80", "6.647398"], ["84006.80", "5.255083"], ["83998.30", "5.345688"], ["83989.80", "5.073873"], ["83981.30", "4.258430"], ["83972.80", "3.896010"], ["83964.30", "4.077220"], ["83955.80", "4.802059"], ["83947.30", "5.617503"], ["83938.80", "4.711454"], ["83930.30", "5.164478"], ["83921.80", "4.620849"], ["83913.30", "4.439639"], ["83904.80", "5.436293"], ["83896.30", "3.986615"], ["83887.80", "4.349034"], ["83879.30", "4.892664"], ["83870.80", "4.167825"], ["83862.30", "4.530244"], ["83853.80", "5.526898"], ["83845.30", "4.983269"], ["83663.91", "0.000161"]], "checksum": -2091121588, "ts": "1742554960662"}], "ts": 1742554960666, "record_time": 1742554960.688407, "EXCHANGE": "BITGET"}
{"action": "update", "arg": {"instType": "SPOT", "channel": "books", "instId": "BTCUSDT"}, "data": [{"asks": [["84077.01", "2.668865"], ["84085.76", "0"], ["84087.42", "0"], ["84088.57", "0"], ["84088.76", "0"], ["84089.08", "0"], ["84089.64", "0"], ["84089.79", "0"], ["84090.26", "0"], ["84090.80", "0"], ["84090.85", "0.035952"], ["84091.14", "0"], ["84091.40", "0"], ["84091.46", "0"], ["84092.06", "0"], ["84092.09", "0"], ["84092.52", "0.035961"], ["84093.08", "0.006356"], ["84093.24", "0.006356"], ["84093.37", "0"], ["84093.56", "0.006356"], ["84093.65", "0"], ["84094.78", "0"], ["84094.90", "0.006356"], ["84095.06", "0.006356"], ["84095.44", "0.006356"], ["84095.75", "0"], ["84096.00", "0.006356"], ["84096.07", "0.006356"], ["84096.32", "0"], ["84096.33", "0.119883"], ["84096.36", "0.016429"], ["84096.50", "0.006356"], ["84096.57", "0"], ["84096.60", "0.006356"], ["84098.04", "0.006357"], ["84098.08", "0.010985"], ["84098.81", "0.009990"], ["84099.79", "0.119850"], ["84100.77", "0"], ["84100.82", "0.119858"], ["84101.05", "0.119867"], ["84101.18", "0.015895"], ["84101.41", "0.009989"], ["84105.25", "0.015892"], ["84129.00", "0.859794"], ["84131.00", "2.262537"], ["84133.00", "5.954269"], ["84175.00", "4.530244"], ["84192.00", "4.349034"], ["84200.50", "3.986615"], ["84209.00", "4.983269"], ["84217.50", "5.255083"], ["84226.00", "4.077220"], ["84234.50", "5.345688"], ["84243.00", "4.620849"], ["84251.50", "5.617503"], ["84260.00", "5.436293"], ["84268.50", "5.526898"], ["84277.00", "4.167825"], ["84285.50", "3.896010"], ["84294.00", "4.711454"], ["84302.50", "4.892664"], ["84311.00", "5.164478"], ["84319.50", "4.439639"], ["84328.00", "4.802059"], ["84336.50", "4.258430"]], "bids": [["84072.18", "0.019223"], ["84050.49", "0.089470"], ["84048.52", "0.017814"], ["84048.35", "0.018252"], ["84048.00", "0.005977"], ["84046.64", "0.017100"], ["84046.47", "0.007130"], ["84045.84", "0.007338"], ["84045.46", "0.008993"], ["84045.38", "0.007941"], ["84045.08", "0.025180"], ["84045.05", "0.224846"], ["84044.98", "0.008184"], ["84044.88", "0.017348"], ["84044.01", "0"], ["84043.86", "0"], ["84043.70", "0"], ["84043.51", "0"], ["84043.43", "0.051955"], ["84043.39", "0.012653"], ["84042.48", "0.018514"], ["84041.61", "0.268333"], ["84041.38", "0"], ["84041.20", "0"], ["84040.85", "0"], ["84040.67", "0"], ["84040.63", "0.222633"], ["84040.52", "0.259753"], ["84040.47", "0"], ["84040.44", "0"], ["84040.20", "0"], ["84040.14", "0.076100"], ["84040.12", "0"], ["84040.04", "0.021126"], ["84039.86", "0"], ["84038.72", "0"], ["84038.59", "0"], ["84037.33", "0"], ["84036.60", "0"], ["84036.32", "0.073203"], ["84036.04", "0"], ["84035.56", "0"], ["84035.03", "0"], ["84034.95", "0"], ["84031.83", "0"], ["84006.80", "5.164478"], ["83998.30", "4.349034"], ["83989.80", "4.892664"], ["83981.30", "4.530244"], ["83972.80", "3.986615"], ["83964.30", "5.617503"], ["83961.06", "0"], ["83955.80", "5.073873"], ["83947.30", "4.802059"], ["83938.80", "4.258430"], ["83930.30", "4.439639"], ["83921.80", "5.255083"], ["83913.30", "4.983269"], ["83904.80", "4.620849"], ["83896.30", "4.711454"], ["83887.80", "3.896010"], ["83879.30", "5.436293"], ["83870.80", "5.345688"], ["83862.30", "4.167825"], ["83845.30", "4.077220"], ["83662.50", "0.000077"]], "checksum": 1285534051, "ts": "1742554960865"}], "ts": 1742554960869, "record_time": 1742554960.892175, "EXCHANGE": "BITGET"}
{"action": "update", "arg": {"instType": "SPOT", "channel": "books", "instId": "BTCUSDT"}, "data": [{"asks": [["84077.01", "2.883025"], ["84085.36", "0.094181"], ["84092.54", "0.044678"], ["84117.00", "0.002476"], ["84119.00", "0.006516"], ["84121.00", "0.017145"], ["84123.00", "0.045119"], ["84125.00", "0.118736"], ["84127.00", "0.312461"], ["84129.00", "0.822268"], ["84131.00", "2.163861"], ["84133.00", "5.694371"], ["84133.20", "0.001007"], ["84133.30", "0.376950"], ["84133.90", "0"], ["84175.00", "5.617503"], ["84183.50", "5.436293"], ["84192.00", "4.983269"], ["84200.50", "4.711454"], ["84209.00", "3.986615"], ["84217.50", "5.526898"], ["84226.00", "5.073873"], ["84234.50", "4.439639"], ["84243.00", "4.530244"], ["84251.50", "4.077220"], ["84260.00", "4.167825"], ["84268.50", "4.349034"], ["84277.00", "5.255083"], ["84285.50", "4.802059"], ["84294.00", "5.345688"], ["84311.00", "4.620849"], ["84319.50", "3.896010"], ["84328.00", "4.258430"], ["84336.50", "5.164478"], ["84535.32", "0"]], "bids": [["84067.48", "0"], ["84026.00", "0.000015"], ["84006.80", "4.711454"], ["83998.30", "4.530244"], ["83989.80", "4.620849"], ["83981.30", "4.349034"], ["83972.80", "4.439639"], ["83964.30", "5.526898"], ["83955.80", "4.892664"], ["83947.30", "4.983269"], ["83939.24", "0.125590"], ["83938.80", "3.896010"], ["83930.30", "5.436293"], ["83921.80", "5.164478"], ["83913.30", "4.802059"], ["83904.80", "5.073873"], ["83896.30", "3.986615"], ["83887.80", "4.258430"], ["83879.30", "5.345688"], ["83870.80", "4.167825"], ["83862.30", "5.617503"], ["83853.80", "4.077220"], ["83845.30", "5.255083"]], "checksum": -865333952, "ts": "1742554961070"}], "ts": 1742554961073, "record_time": 1742554961.096936, "EXCHANGE": "BITGET"}
{"action": "update", "arg": {"instType": "SPOT", "channel": "books", "instId": "BTCUSDT"}, "data": [{"asks": [["84077.01", "2.423025"], ["84092.54", "0.062601"], ["84121.00", "0.017297"], ["84123.00", "0.045519"], ["84125.00", "0.119786"], ["84127.00", "0.315227"], ["84129.00", "0.829546"], ["84131.00", "2.183016"], ["84133.00", "5.744777"], ["84133.20", "0.001320"], ["84133.30", "0"], ["84134.10", "0.068220"], ["84175.00", "3.986615"], ["84183.50", "4.349034"], ["84192.00", "4.077220"], ["84200.50", "5.436293"], ["84209.00", "5.526898"], ["84217.50", "4.167825"], ["84226.00", "3.896010"], ["84234.50", "5.073873"], ["84243.00", "4.802059"], ["84251.50", "5.164478"], ["84260.00", "4.620849"], ["84268.50", "4.983269"], ["84277.00", "5.617503"], ["84285.50", "5.255083"], ["84294.00", "4.892664"], ["84302.50", "4.439639"], ["84311.00", "4.711454"], ["84319.50", "4.258430"], ["84328.00", "5.345688"], ["84336.50", "4.530244"], ["84535.32", "0.000039"]], "bids": [["84067.93", "0.041075"], ["84062.80", "0.007488"], ["84060.80", "0.019705"], ["84058.80", "0.051856"], ["84056.80", "0.136463"], ["84054.80", "0.359113"], ["84052.80", "0.945034"], ["84050.80", "2.486932"], ["84048.80", "6.544410"], ["84042.70", "0.144750"], ["84026.00", "0"], ["84006.80", "4.802059"], ["83998.30", "4.892664"], ["83989.80", "3.896010"], ["83981.30", "4.167825"], ["83972.80", "4.983269"], ["83964.30", "4.530244"], ["83955.80", "5.073873"], ["83947.30", "5.617503"], ["83938.80", "4.349034"], ["83930.30", "5.345688"], ["83921.80", "5.436293"], ["83913.30", "4.077220"], ["83904.80", "5.164478"], ["83896.30", "4.711454"], ["83887.80", "3.986615"], ["83879.30", "4.439639"], ["83870.80", "4.620849"], ["83862.30", "4.258430"], ["83853.80", "5.255083"], ["83845.30", "5.526898"]], "checksum": 744477945, "ts": "1742554961281"}], "ts": 1742554961287, "record_time": 1742554961.312338, "EXCHANGE": "BITGET"}
{"action": "update", "arg": {"instType": "SPOT", "channel": "books", "instId": "BTCUSDT"}, "data": [{"asks": [["84077.01", "2.668865"], ["84100.81", "0.083424"], ["84117.00", "0.002312"], ["84119.00", "0.006084"], ["84121.00", "0.016012"], ["84123.00", "0.042136"], ["84125.00", "0.110883"], ["84127.00", "0.291797"], ["84129.00", "0.767887"], ["84131.00", "2.020755"], ["84133.00", "5.317777"], ["84175.00", "4.983269"], ["84183.50", "4.258430"], ["84192.00", "5.255083"], ["84200.50", "4.167825"], ["84209.00", "4.892664"], ["84217.50", "3.896010"], ["84226.00", "5.617503"], ["84234.50", "3.986615"], ["84243.00", "5.436293"], ["84251.50", "5.345688"], ["84260.00", "4.439639"], ["84268.50", "4.349034"], ["84277.00", "4.802059"], ["84285.50", "4.711454"], ["84294.00", "4.530244"], ["84302.50", "5.164478"], ["84311.00", "5.526898"], ["84319.50", "4.077220"], ["84328.00", "4.620849"], ["84336.50", "5.073873"], ["84535.32", "0"]], "bids": [["84066.80", "0.001261"], ["84064.80", "0.003467"], ["84062.80", "0.009124"], ["84060.80", "0.024011"], ["84058.80", "0.063187"], ["84056.80", "0.166282"], ["84054.80", "0.437582"], ["84052.80", "1.151532"], ["84050.80", "3.030349"], ["84048.80", "7.974601"], ["84043.90", "0.216720"], ["84040.40", "0"], ["84037.90", "0.120000"], ["84027.00", "0.000017"], ["84006.80", "3.896010"], ["83998.30", "4.258430"], ["83989.80", "4.167825"], ["83981.30", "4.530244"], ["83972.80", "4.892664"], ["83964.30", "5.164478"], ["83955.80", "4.349034"], ["83947.30", "4.439639"], ["83938.80", "4.077220"], ["83930.30", "4.802059"], ["83921.80", "5.073873"], ["83913.30", "3.986615"], ["83904.80", "4.711454"], ["83896.30", "4.983269"], ["83887.80", "5.345688"], ["83879.30", "5.526898"], ["83870.80", "5.255083"], ["83862.30", "5.436293"], ["83853.80", "5.617503"], ["83845.30", "4.620849"], ["83662.50", "0"]], "checksum": -944645633, "ts": "1742554961491"}], "ts": 1742554961494, "record_time": 1742554961.519905, "EXCHANGE": "BITGET"}
{"action": "update", "arg": {"instType": "SPOT", "channel": "books", "instId": "BTCUSDT"}, "data": [{"asks": [["84077.01", "2.423025"], ["84117.00", "0.002191"], ["84119.00", "0.005767"], ["84121.00", "0.015176"], ["84123.00", "0.039935"], ["84125.00", "0.105093"], ["84126.99", "0.318384"], ["84127.00", "0.276562"], ["84129.00", "0.727793"], ["84131.00", "1.915244"], ["84133.00", "5.040116"], ["84175.00", "5.164478"], ["84183.50", "4.983269"], ["84192.00", "5.073873"], ["84200.50", "5.255083"], ["84209.00", "4.258430"], ["84217.50", "4.167825"], ["84226.00", "4.349034"], ["84234.50", "4.620849"], ["84243.00", "5.345688"], ["84251.50", "5.617503"], ["84260.00", "4.892664"], ["84268.50", "4.439639"], ["84277.00", "4.711454"], ["84285.50", "4.077220"], ["84294.00", "5.436293"], ["84302.50", "4.802059"], ["84311.00", "3.986615"], ["84319.50", "5.526898"], ["84328.00", "4.530244"], ["84336.50", "3.896010"], ["84534.53", "0"]], "bids": [["84068.27", "0.041075"], ["84067.93", "0"], ["84064.80", "0.003104"], ["84062.80", "0.008169"], ["84060.80", "0.021497"], ["84058.80", "0.056569"], ["84056.80", "0.148867"], ["84054.80", "0.391756"], ["84052.80", "1.030935"], ["84050.80", "2.712988"], ["84048.80", "7.139443"], ["84044.80", "0.468990"], ["84037.90", "0"], ["84006.80", "4.892664"], ["83998.30", "5.073873"], ["83989.80", "4.711454"], ["83981.30", "5.255083"], ["83972.80", "4.530244"], ["83964.30", "4.258430"], ["83955.80", "4.077220"], ["83947.30", "3.896010"], ["83938.80", "5.617503"], ["83930.30", "4.439639"], ["83921.80", "5.164478"], ["83913.30", "4.802059"], ["83904.80", "4.983269"], ["83896.30", "4.167825"], ["83887.80", "5.526898"], ["83879.30", "4.620849"], ["83870.80", "3.986615"], ["83862.30", "5.345688"], ["83853.80", "4.349034"], ["83845.30", "5.436293"]], "checksum": 1137651347, "ts": "1742554961691"}], "ts": 1742554961695, "record_time": 1742554961.717805, "EXCHANGE": "BITGET"}
{"action": "update", "arg": {"instType": "SPOT", "channel": "books", "instId": "BTCUSDT"}, "data": [{"asks": [["84077.01", "2.668865"], ["84121.00", "0.014943"], ["84123.00", "0.039325"], ["84125.00", "0.103487"], ["84127.00", "0.272334"], ["84129.00", "0.716668"], ["84130.99", "0"], ["84131.00", "1.885969"], ["84133.00", "4.963075"], ["84158.01", "0.082172"], ["84175.00", "4.711454"], ["84183.50", "4.258430"], ["84192.00", "5.164478"], ["84200.50", "3.896010"], ["84209.00", "3.986615"], ["84217.50", "4.439639"], ["84226.00", "4.077220"], ["84234.50", "5.617503"], ["84243.00", "4.620849"], ["84251.50", "4.349034"], ["84260.00", "5.345688"], ["84268.50", "5.073873"], ["84277.00", "5.526898"], ["84285.50", "4.530244"], ["84302.50", "4.983269"], ["84311.00", "4.167825"], ["84319.50", "4.802059"], ["84328.00", "5.255083"], ["84336.50", "4.892664"]], "bids": [["84058.80", "0.056317"], ["84056.80", "0.148204"], ["84054.80", "0.390009"], ["84052.80", "1.026340"], ["84050.80", "2.700895"], ["84048.80", "7.107618"], ["84039.70", "2.355960"], ["84039.60", "0"], ["84006.80", "5.073873"], ["83998.30", "4.530244"], ["83981.30", "4.620849"], ["83972.80", "5.526898"], ["83964.30", "4.802059"], ["83955.80", "4.258430"], ["83947.30", "5.617503"], ["83938.80", "3.986615"], ["83930.30", "4.077220"], ["83921.80", "4.349034"], ["83913.30", "5.436293"], ["83904.80", "4.439639"], ["83896.30", "5.255083"], ["83887.80", "5.345688"], ["83879.30", "4.167825"], ["83870.80", "5.164478"], ["83862.30", "3.896010"], ["83853.80", "4.983269"], ["83845.30", "4.892664"]], "checksum": 1866326874, "ts": "1742554961892"}], "ts": 1742554961896, "record_time": 1742554961.922629, "EXCHANGE": "BITGET"}
{"action": "update", "arg": {"instType": "SPOT", "channel": "books", "instId": "BTCUSDT"}, "data": [{"asks": [["84077.01", "3.128865"], ["84119.00", "0.005652"], ["84121.00", "0.014873"], ["84123.00", "0.039139"], ["84125.00", "0.102999"], ["84127.00", "0.271049"], ["84129.00", "0.713286"], ["84131.00", "1.877070"], ["84133.00", "4.939658"], ["84133.20", "0.313320"], ["84134.10", "0.067800"], ["84134.30", "0.048450"], ["84134.80", "0.420000"], ["84134.90", "0.021840"], ["84144.10", "0"], ["84175.00", "4.167825"], ["84183.50", "5.073873"], ["84192.00", "4.439639"], ["84200.50", "4.802059"], ["84209.00", "4.530244"], ["84217.50", "4.349034"], ["84226.00", "5.255083"], ["84234.50", "4.258430"], ["84251.50", "5.436293"], ["84260.00", "5.526898"], ["84268.50", "4.892664"], ["84277.00", "4.983269"], ["84285.50", "5.345688"], ["84294.00", "3.986615"], ["84302.50", "5.164478"], ["84311.00", "4.077220"], ["84319.50", "5.617503"], ["84328.00", "4.711454"], ["84336.50", "3.896010"]], "bids": [["84065.15", "0.010000"], ["84064.80", "0.003239"], ["84062.80", "0.008523"], ["84060.80", "0.022430"], ["84058.80", "0.059245"], ["84056.80", "0.155906"], ["84054.80", "0.410279"], ["84052.80", "1.079684"], ["84050.80", "2.841272"], ["84048.80", "7.477033"], ["84047.80", "0.715980"], ["84045.80", "0.144720"], ["84045.20", "0.071220"], ["84043.90", "0.173370"], ["84042.70", "0"], ["84027.00", "0.000032"], ["84006.80", "4.802059"], ["83998.30", "5.073873"], ["83989.80", "5.436293"], ["83981.30", "3.896010"], ["83964.30", "4.349034"], ["83938.80", "4.892664"], ["83930.30", "5.345688"], ["83921.80", "4.711454"], ["83913.30", "5.255083"], ["83896.30", "4.983269"], ["83887.80", "3.986615"], ["83879.30", "4.530244"], ["83870.80", "4.167825"], ["83862.30", "5.164478"], ["83853.80", "4.077220"], ["83845.30", "4.620849"], ["83663.91", "0"]], "checksum": 1348890807, "ts": "1742554962099"}], "ts": 1742554962102, "record_time": 1742554962.123771, "EXCHANGE": "BITGET"}
{"action": "update", "arg": {"instType": "SPOT", "channel": "books", "instId": "BTCUSDT"}, "data": [{"asks": [["84077.01", "3.125697"], ["84121.00", "0.014902"], ["84123.00", "0.039216"], ["84125.00", "0.103201"], ["84127.00", "0.271580"], ["84129.00", "0.714686"], ["84131.00", "1.880753"], ["84133.00", "4.949348"], ["84175.00", "3.896010"], ["84183.50", "4.258430"], ["84192.00", "4.711454"], ["84200.50", "5.345688"], ["84217.50", "5.526898"], ["84226.00", "5.436293"], ["84234.50", "4.077220"], ["84243.00", "4.983269"], ["84251.50", "5.164478"], ["84260.00", "4.892664"], ["84268.50", "4.620849"], ["84277.00", "4.439639"], ["84285.50", "5.617503"], ["84302.50", "5.073873"], ["84311.00", "4.167825"], ["84319.50", "4.802059"], ["84328.00", "4.349034"], ["84336.50", "5.255083"]], "bids": [["84068.59", "0.041075"], ["84068.27", "0"], ["84064.80", "0.003102"], ["84062.80", "0.008164"], ["84060.80", "0.021484"], ["84058.80", "0.056318"], ["84056.80", "0.148206"], ["84054.80", "0.390017"], ["84052.80", "1.026359"], ["84050.80", "2.700944"], ["84048.80", "7.107748"], ["84025.00", "0.000015"], ["84006.80", "5.073873"], ["83998.30", "5.436293"], ["83989.80", "5.164478"], ["83981.30", "4.167825"], ["83972.80", "4.983269"], ["83964.30", "5.617503"], ["83955.80", "4.620849"], ["83947.30", "4.892664"], ["83938.80", "3.986615"], ["83930.30", "5.255083"], ["83921.80", "5.526898"], ["83913.30", "4.439639"], ["83904.80", "4.802059"], ["83896.30", "4.077220"], ["83887.80", "5.345688"], ["83870.80", "4.711454"], ["83862.30", "4.258430"], ["83853.80", "4.349034"], ["83845.30", "3.896010"]], "checksum": 1162562729, "ts": "1742554962298"}], "ts": 1742554962302, "record_time": 1742554962.323961, "EXCHANGE": "BITGET"}
{"action": "update", "arg": {"instType": "SPOT", "channel": "books", "instId": "BTCUSDT"}, "data": [{"asks": [["84098.40", "0.093271"], ["84119.00", "0.005755"], ["84121.00", "0.015145"], ["84123.00", "0.039856"], ["84125.00", "0.104884"], ["84127.00", "0.276010"], ["84129.00", "0.726342"], ["84131.00", "1.911428"], ["84133.00", "5.030072"], ["84175.00", "4.167825"], ["84183.50", "5.345688"], ["84192.00", "5.073873"], ["84200.50", "5.255083"], ["84209.00", "4.892664"], ["84217.50", "4.258430"], ["84234.50", "4.711454"], ["84243.00", "4.439639"], ["84251.50", "4.983269"], ["84260.00", "5.164478"], ["84268.50", "4.349034"], ["84277.00", "4.802059"], ["84285.50", "3.896010"], ["84294.00", "5.617503"], ["84302.50", "4.620849"], ["84311.00", "3.986615"], ["84319.50", "4.077220"], ["84328.00", "4.530244"], ["84336.50", "5.526898"]], "bids": [["84073.25", "0.019223"], ["84072.18", "0"], ["84006.80", "4.439639"], ["83998.30", "4.711454"], ["83989.80", "4.077220"], ["83981.30", "5.436293"], ["83972.80", "5.345688"], ["83964.30", "4.167825"], ["83955.80", "4.983269"], ["83947.30", "5.164478"], ["83921.80", "3.896010"], ["83913.30", "4.802059"], ["83904.80", "4.892664"], ["83896.30", "4.258430"], ["83887.80", "4.349034"], ["83879.30", "5.526898"], ["83870.80", "4.530244"], ["83862.30", "5.617503"], ["83853.80", "4.620849"], ["83845.30", "5.073873"]], "checksum": 55518901, "ts": "1742554962501"}], "ts": 1742554962505, "record_time": 1742554962.526901, "EXCHANGE": "BITGET"}
{"action": "update", "arg": {"instType": "SPOT", "channel": "books", "instId": "BTCUSDT"}, "data": [{"asks": [["84077.01", "2.419857"], ["84112.07", "0.010000"], ["84119.00", "0.005734"], ["84121.00", "0.015091"], ["84122.99", "0.043901"], ["84123.00", "0.039712"], ["84125.00", "0.104507"], ["84127.00", "0.275017"], ["84129.00", "0.723729"], ["84131.00", "1.904550"], ["84133.00", "5.011975"], ["84175.00", "4.802059"], ["84183.50", "4.620849"], ["84200.50", "5.345688"], ["84209.00", "4.983269"], ["84217.50", "4.892664"], ["84226.00", "4.530244"], ["84243.00", "4.349034"], ["84251.50", "5.436293"], ["84268.50", "4.258430"], ["84277.00", "4.439639"], ["84285.50", "3.986615"], ["84294.00", "4.077220"], ["84302.50", "4.167825"], ["84311.00", "5.526898"], ["84319.50", "3.896010"], ["84328.00", "5.617503"], ["84336.50", "5.255083"], ["84533.01", "0"], ["84533.33", "0"]], "bids": [["84068.59", "0"], ["84026.00", "0.000017"], ["84006.80", "4.530244"], ["83998.30", "5.617503"], ["83989.80", "3.896010"], ["83981.30", "4.258430"], ["83972.80", "5.526898"], ["83964.30", "5.073873"], ["83955.80", "4.892664"], ["83947.30", "4.802059"], ["83938.80", "4.711454"], ["83930.30", "5.345688"], ["83921.80", "4.349034"], ["83913.30", "5.255083"], ["83904.80", "4.439639"], ["83896.30", "5.436293"], ["83887.80", "4.983269"], ["83879.30", "4.167825"], ["83870.80", "3.986615"], ["83862.30", "4.077220"], ["83845.30", "5.164478"]], "checksum": 15711983, "ts": "1742554962708"}], "ts": 1742554962711, "record_time": 1742554962.733309, "EXCHANGE": "BITGET"}
{"action": "update", "arg": {"instType": "SPOT", "channel": "books", "instId": "BTCUSDT"}, "data": [{"asks": [["84133.00", "5.012123"], ["84175.00", "4.439639"], ["84183.50", "4.167825"], ["84192.00", "4.711454"], ["84200.50", "3.896010"], ["84209.00", "4.892664"], ["84217.50", "5.164478"], ["84226.00", "4.349034"], ["84234.50", "4.530244"], ["84243.00", "5.526898"], ["84251.50", "5.073873"], ["84260.00", "4.258430"], ["84268.50", "4.802059"], ["84277.00", "4.620849"], ["84285.50", "5.255083"], ["84294.00", "5.345688"], ["84302.50", "5.436293"], ["84311.00", "4.077220"], ["84319.50", "5.617503"], ["84328.00", "4.983269"], ["84336.50", "3.986615"]], "bids": [["84068.88", "0.041075"], ["84050.80", "2.700732"], ["84048.80", "7.107190"], ["84025.00", "0"], ["84006.80", "5.073873"], ["83998.30", "3.986615"], ["83989.80", "4.167825"], ["83981.30", "4.802059"], ["83972.80", "4.620849"], ["83964.30", "4.439639"], ["83955.80", "3.896010"], ["83947.30", "4.349034"], ["83938.80", "5.164478"], ["83930.30", "4.530244"], ["83921.80", "4.711454"], ["83904.80", "5.436293"], ["83896.30", "4.892664"], ["83887.80", "5.617503"], ["83879.30", "5.345688"], ["83870.80", "4.258430"], ["83862.30", "5.526898"], ["83853.80", "4.983269"], ["83845.30", "4.077220"]], "checksum": 488060196, "ts": "1742554962907"}], "ts": 1742554962910, "record_time": 1742554962.931997, "EXCHANGE": "BITGET"}
{"action": "update", "arg": {"instType": "SPOT", "channel": "books", "instId": "BTCUSDT"}, "data": [{"asks": [["84121.00", "0.014971"], ["84123.00", "0.039395"], ["84125.00", "0.103672"], ["84127.00", "0.272822"], ["84129.00", "0.717952"], ["84131.00", "1.889347"], ["84133.00", "4.971966"], ["84175.00", "3.896010"], ["84183.50", "5.073873"], ["84192.00", "5.255083"], ["84200.50", "4.258430"], ["84209.00", "4.620849"], ["84217.50", "4.983269"], ["84226.00", "4.167825"], ["84234.50", "4.077220"], ["84243.00", "4.439639"], ["84251.50", "5.617503"], ["84260.00", "5.526898"], ["84268.50", "5.164478"], ["84277.00", "4.892664"], ["84285.50", "4.530244"], ["84294.00", "4.802059"], ["84302.50", "4.349034"], ["84311.00", "5.345688"], ["84319.50", "5.436293"], ["84328.00", "3.986615"], ["84336.50", "4.711454"]], "bids": [["84006.80", "5.436293"], ["83989.80", "4.077220"], ["83981.30", "5.073873"], ["83972.80", "4.439639"], ["83964.30", "5.345688"], ["83955.80", "4.802059"], ["83947.30", "5.617503"], ["83938.80", "4.711454"], ["83930.30", "5.164478"], ["83921.80", "4.892664"], ["83913.30", "3.896010"], ["83904.80", "4.167825"], ["83896.30", "4.349034"], ["83887.80", "5.526898"], ["83879.30", "5.255083"], ["83870.80", "4.620849"], ["83862.30", "4.983269"], ["83853.80", "4.258430"], ["83845.30", "4.530244"]], "checksum": 488060196, "ts": "1742554963128"}], "ts": 1742554963131, "record_time": 1742554963.154324, "EXCHANGE": "BITGET"}
{"action": "update", "arg": {"instType": "SPOT", "channel": "books", "instId": "BTCUSDT"}, "data": [{"asks": [["84077.01", "2.879857"], ["84123.00", "0.039645"], ["84125.00", "0.104327"], ["84127.00", "0.274546"], ["84129.00", "0.722488"], ["84131.00", "1.901285"], ["84133.00", "5.003381"], ["84144.10", "0.067800"], ["84175.00", "4.892664"], ["84183.50", "4.349034"], ["84192.00", "4.620849"], ["84200.50", "5.073873"], ["84209.00", "5.255083"], ["84226.00", "5.164478"], ["84243.00", "5.436293"], ["84251.50", "4.530244"], ["84260.00", "5.345688"], ["84268.50", "5.617503"], ["84277.00", "3.986615"], ["84285.50", "4.439639"], ["84294.00", "4.258430"], ["84302.50", "4.802059"], ["84311.00", "5.526898"], ["84319.50", "3.896010"], ["84328.00", "4.167825"], ["84371.59", "0"]], "bids": [["84069.16", "0.041074"], ["84068.88", "0"], ["84027.00", "0.000015"], ["84006.80", "5.617503"], ["83998.30", "4.167825"], ["83989.80", "4.711454"], ["83981.30", "4.258430"], ["83972.80", "5.255083"], ["83964.30", "5.436293"], ["83955.80", "4.620849"], ["83947.30", "4.892664"], ["83938.80", "4.983269"], ["83930.30", "4.349034"], ["83921.80", "5.164478"], ["83904.80", "4.802059"], ["83896.30", "4.077220"], ["83887.80", "5.345688"], ["83879.30", "4.530244"], ["83870.80", "5.526898"], ["83862.30", "3.986615"], ["83853.80", "4.439639"], ["83845.30", "5.073873"]], "checksum": -221361748, "ts": "1742554963332"}], "ts": 1742554963335, "record_time": 1742554963.357396, "EXCHANGE": "BITGET"}
{"action": "update", "arg": {"instType": "SPOT", "channel": "books", "instId": "BTCUSDT"}, "data": [{"asks": [["84077.01", "3.125697"], ["84112.06", "0.003309"], ["84117.00", "0.002035"], ["84119.00", "0.005356"], ["84121.00", "0.014095"], ["84123.00", "0.037093"], ["84125.00", "0.097613"], ["84127.00", "0.256877"], ["84129.00", "0.675991"], ["84131.00", "1.778924"], ["84133.00", "4.681378"], ["84134.30", "0"], ["84175.00", "4.711454"], ["84183.50", "5.436293"], ["84192.00", "4.439639"], ["84200.50", "4.530244"], ["84209.00", "4.349034"], ["84217.50", "5.164478"], ["84226.00", "4.892664"], ["84234.50", "5.617503"], ["84243.00", "5.526898"], ["84251.50", "4.167825"], ["84260.00", "3.896010"], ["84268.50", "3.986615"], ["84277.00", "4.258430"], ["84285.50", "4.802059"], ["84294.00", "4.983269"], ["84302.50", "5.255083"], ["84311.00", "5.073873"], ["84319.50", "4.077220"], ["84328.00", "5.345688"], ["84336.50", "4.620849"]], "bids": [["84064.80", "0.003441"], ["84062.80", "0.009055"], ["84060.80", "0.023828"], ["84058.80", "0.062706"], ["84056.80", "0.165016"], ["84054.80", "0.434253"], ["84052.80", "1.142771"], ["84050.80", "3.007293"], ["84048.80", "7.913928"], ["84043.90", "0.866880"], ["84041.30", "2.427270"], ["84039.70", "0"], ["84026.00", "0.000032"], ["84006.80", "5.436293"], ["83998.30", "4.802059"], ["83989.80", "3.986615"], ["83981.30", "5.164478"], ["83972.80", "5.073873"], ["83964.30", "4.983269"], ["83955.80", "5.526898"], ["83947.30", "4.530244"], ["83938.80", "4.892664"], ["83930.30", "3.896010"], ["83921.80", "4.439639"], ["83913.30", "5.617503"], ["83904.80", "4.258430"], ["83896.30", "4.167825"], ["83879.30", "4.077220"], ["83870.80", "4.711454"], ["83862.30", "5.255083"], ["83853.80", "4.620849"], ["83845.30", "4.349034"]], "checksum": 1146376469, "ts": "1742554963533"}], "ts": 1742554963542, "record_time": 1742554963.573707, "EXCHANGE": "BITGET"}
{"action": "update", "arg": {"instType": "SPOT", "channel": "books", "instId": "BTCUSDT"}, "data": [{"asks": [["84077.01", "2.793748"], ["84078.08", "0"], ["84119.00", "0.005431"], ["84121.00", "0.014290"], ["84123.00", "0.037606"], ["84125.00", "0.098963"], ["84127.00", "0.260429"], ["84129.00", "0.685341"], ["84131.00", "1.803527"], ["84133.00", "4.746125"], ["84134.49", "0.009219"], ["84144.10", "0"], ["84175.00", "5.073873"], ["84183.50", "5.164478"], ["84192.00", "4.892664"], ["84200.50", "4.439639"], ["84209.00", "5.617503"], ["84217.50", "5.345688"], ["84226.00", "4.530244"], ["84234.50", "4.802059"], ["84243.00", "3.986615"], ["84251.50", "5.255083"], ["84260.00", "5.526898"], ["84268.50", "4.711454"], ["84277.00", "4.349034"], ["84285.50", "3.896010"], ["84294.00", "4.258430"], ["84302.50", "4.620849"], ["84311.00", "4.167825"], ["84319.50", "4.983269"], ["84328.00", "5.436293"], ["84336.50", "4.077220"], ["84533.01", "0.000591"]], "bids": [["84077.00", "0"], ["84076.00", "0"], ["84075.00", "0"], ["84074.00", "0"], ["84073.25", "0.016168"], ["84069.16", "0"], ["84066.80", "0.001434"], ["84064.80", "0.003773"], ["84062.80", "0.009929"], ["84060.80", "0.026129"], ["84058.80", "0.068762"], ["84056.80", "0.181112"], ["84054.80", "0.476610"], ["84052.80", "1.254236"], ["84050.80", "3.300621"], ["84048.80", "8.685847"], ["84045.90", "0.085200"], ["84044.60", "0.015000"], ["84041.30", "2.355930"], ["84006.80", "5.255083"], ["83998.30", "5.345688"], ["83989.80", "3.896010"], ["83981.30", "4.349034"], ["83972.80", "4.892664"], ["83964.30", "4.620849"], ["83955.80", "4.258430"], ["83947.30", "4.983269"], ["83938.80", "5.617503"], ["83930.30", "4.530244"], ["83921.80", "3.986615"], ["83913.30", "4.167825"], ["83904.80", "5.526898"], ["83896.30", "4.711454"], ["83887.80", "5.436293"], ["83870.80", "5.164478"], ["83862.30", "4.439639"], ["83853.80", "4.802059"], ["83845.30", "5.073873"], ["83663.91", "0.000161"], ["83662.50", "0.000077"], ["83661.97", "0.000052"], ["83661.60", "0.000042"], ["83661.08", "0.004152"]], "checksum": 721101390, "ts": "1742554963733"}], "ts": 1742554963736, "record_time": 1742554963.76249, "EXCHANGE": "BITGET"}
{"action": "update", "arg": {"instType": "SPOT", "channel": "books", "instId": "BTCUSDT"}, "data": [{"asks": [["84073.01", "1.675533"], ["84073.26", "0.385151"], ["84073.92", "0.038531"], ["84075.63", "0.654357"], ["84077.01", "0.870155"], ["84078.00", "0"], ["84078.01", "0"], ["84105.43", "0"], ["84105.77", "0"], ["84126.99", "0"], ["84158.01", "0"], ["84175.00", "5.526898"], ["84183.50", "4.439639"], ["84192.00", "3.986615"], ["84200.50", "4.892664"], ["84209.00", "4.167825"], ["84217.50", "4.802059"], ["84226.00", "5.164478"], ["84234.50", "5.073873"], ["84243.00", "4.077220"], ["84251.50", "5.617503"], ["84260.00", "5.345688"], ["84268.50", "4.349034"], ["84277.00", "4.620849"], ["84285.50", "5.255083"], ["84294.00", "4.530244"], ["84302.50", "4.983269"], ["84311.00", "3.896010"], ["84319.50", "5.436293"], ["84328.00", "4.711454"], ["84336.50", "4.258430"], ["84533.33", "0.003186"], ["84534.53", "0.000461"]], "bids": [["84073.25", "0"], ["84073.00", "0.260900"], ["84066.80", "0.001309"], ["84065.35", "0"], ["84064.80", "0.003445"], ["84062.80", "0.009066"], ["84061.74", "0.118108"], ["84060.80", "0.023857"], ["84058.80", "0.062781"], ["84056.80", "0.165213"], ["84054.80", "0.434771"], ["84052.80", "1.144136"], ["84050.80", "3.010883"], ["84050.25", "0.766035"], ["84048.80", "7.923377"], ["84025.00", "0.000017"], ["84006.80", "4.439639"], ["83998.30", "4.077220"], ["83989.80", "4.802059"], ["83981.30", "5.526898"], ["83972.80", "3.986615"], ["83964.30", "4.983269"], ["83955.80", "5.617503"], ["83947.30", "4.530244"], ["83938.80", "4.711454"], ["83930.30", "5.255083"], ["83921.80", "5.345688"], ["83913.30", "5.164478"], ["83904.80", "5.073873"], ["83896.30", "4.620849"], ["83887.80", "4.167825"], ["83879.30", "4.258430"], ["83870.80", "4.892664"], ["83862.30", "3.896010"], ["83853.80", "5.436293"], ["83845.30", "4.349034"]], "checksum": 1684048248, "ts": "1742554963932"}], "ts": 1742554963936, "record_time": 1742554963.958973, "EXCHANGE": "BITGET"}
{"action": "update", "arg": {"instType": "SPOT", "channel": "books", "instId": "BTCUSDT"}, "data": [{"asks": [["84073.01", "2.240678"], ["84073.03", "0.038531"], ["84073.25", "0.140735"], ["84073.26", "0.139311"], ["84073.92", "0"], ["84075.62", "0.351214"], ["84077.01", "0.224949"], ["84101.76", "0.232672"], ["84105.42", "0"], ["84108.18", "0.179409"], ["84138.30", "0.070080"], ["84143.90", "0"], ["84175.00", "5.255083"], ["84183.50", "5.436293"], ["84192.00", "5.617503"], ["84200.50", "5.345688"], ["84209.00", "5.526898"], ["84217.50", "4.620849"], ["84226.00", "5.073873"], ["84234.50", "4.077220"], ["84243.00", "3.986615"], ["84251.50", "5.164478"], ["84260.00", "4.892664"], ["84268.50", "4.439639"], ["84277.00", "4.349034"], ["84285.50", "4.530244"], ["84294.00", "4.167825"], ["84302.50", "3.896010"], ["84311.00", "4.983269"], ["84319.50", "4.258430"], ["84336.50", "4.802059"], ["84533.33", "0"], ["84534.53", "0"]], "bids": [["84073.00", "0.273472"], ["84072.99", "0.000100"], ["84072.98", "0.000100"], ["84072.97", "0.000100"], ["84066.80", "0.001308"], ["84065.15", "0"], ["84064.80", "0.003442"], ["84062.80", "0.009057"], ["84060.80", "0.023833"], ["84058.80", "0.062720"], ["84056.81", "0.179980"], ["84056.80", "0.165052"], ["84054.80", "0.434347"], ["84052.80", "1.143018"], ["84050.80", "3.007943"], ["84048.80", "7.915639"], ["84045.90", "0.073200"], ["84038.40", "0.012480"], ["84006.80", "4.349034"], ["83998.30", "4.711454"], ["83989.80", "4.167825"], ["83981.30", "5.255083"], ["83972.80", "4.983269"], ["83964.30", "4.892664"], ["83955.80", "4.077220"], ["83947.30", "5.436293"], ["83938.80", "5.164478"], ["83930.30", "5.526898"], ["83921.80", "4.620849"], ["83913.30", "4.530244"], ["83904.80", "3.896010"], ["83896.30", "5.073873"], ["83887.80", "4.258430"], ["83879.30", "5.617503"], ["83870.80", "4.802059"], ["83862.30", "3.986615"], ["83853.80", "5.345688"], ["83845.30", "4.439639"], ["83661.97", "0"], ["83661.60", "0"], ["83661.08", "0"]], "checksum": 505945868, "ts": "1742554964132"}], "ts": 1742554964142, "record_time": 1742554964.167228, "EXCHANGE": "BITGET"}
{"action": "update", "arg": {"instType": "SPOT", "channel": "books", "instId": "BTCUSDT"}, "data": [{"asks": [["84073.24", "0.084014"], ["84073.25", "0.013630"], ["84073.26", "0.053200"], ["84075.62", "0"], ["84105.24", "0.008064"], ["84119.00", "0.005608"], ["84121.00", "0.014599"], ["84123.00", "0.038416"], ["84125.00", "0.101095"], ["84127.00", "0.266041"], ["84129.00", "0.700107"], ["84131.00", "1.842387"], ["84133.00", "4.848388"], ["84175.00", "4.802059"], ["84200.50", "3.896010"], ["84209.00", "4.349034"], ["84217.50", "4.892664"], ["84226.00", "4.983269"], ["84234.50", "5.255083"], ["84243.00", "4.077220"], ["84251.50", "4.711454"], ["84260.00", "3.986615"], ["84277.00", "4.167825"], ["84285.50", "5.526898"], ["84294.00", "5.073873"], ["84302.50", "4.620849"], ["84311.00", "5.164478"], ["84319.50", "5.345688"], ["84328.00", "4.530244"], ["84336.50", "4.258430"], ["84533.01", "0"]], "bids": [["84069.59", "0.041076"], ["84066.80", "0.001434"], ["84064.80", "0.003773"], ["84062.80", "0.009929"], ["84060.80", "0.026130"], ["84058.80", "0.068762"], ["84056.80", "0.181116"], ["84054.80", "0.476620"], ["84052.80", "1.254263"], ["84050.80", "3.300692"], ["84050.25", "0.941810"], ["84048.80", "8.686033"], ["84038.40", "0"], ["84027.00", "0"], ["84006.80", "4.711454"], ["83998.30", "3.986615"], ["83989.80", "5.617503"], ["83981.30", "4.530244"], ["83972.80", "4.620849"], ["83964.30", "4.439639"], ["83955.80", "4.802059"], ["83947.30", "3.896010"], ["83938.80", "4.983269"], ["83930.30", "4.167825"], ["83921.80", "5.436293"], ["83913.30", "4.258430"], ["83904.80", "5.255083"], ["83896.30", "5.164478"], ["83887.80", "5.073873"], ["83879.30", "4.077220"], ["83870.80", "5.526898"], ["83862.30", "4.892664"], ["83853.80", "4.349034"], ["83845.30", "5.345688"], ["83661.97", "0.000052"]], "checksum": -164023321, "ts": "1742554964337"}], "ts": 1742554964340, "record_time": 1742554964.371511, "EXCHANGE": "BITGET"}
{"action": "update", "arg": {"instType": "SPOT", "channel": "books", "instId": "BTCUSDT"}, "data": [{"asks": [["84073.01", "2.326787"], ["84073.02", "0.031608"], ["84073.24", "0"], ["84119.00", "0.005521"], ["84121.00", "0.014529"], ["84123.00", "0.038235"], ["84125.00", "0.100618"], ["84127.00", "0.264783"], ["84129.00", "0.696798"], ["84131.00", "1.833680"], ["84133.00", "4.825472"], ["84134.30", "0.050040"], ["84143.80", "0"], ["84175.00", "5.617503"], ["84183.50", "5.526898"], ["84192.00", "4.802059"], ["84209.00", "5.255083"], ["84226.00", "4.711454"], ["84234.50", "4.530244"], ["84243.00", "5.164478"], ["84251.50", "4.167825"], ["84268.50", "4.349034"], ["84277.00", "5.345688"], ["84285.50", "4.258430"], ["84294.00", "4.077220"], ["84302.50", "4.439639"], ["84311.00", "4.983269"], ["84319.50", "5.073873"], ["84328.00", "4.620849"], ["84336.50", "5.436293"], ["84337.79", "0"], ["84533.01", "0.000591"]], "bids": [["84066.80", "0.001309"], ["84064.80", "0.003445"], ["84062.80", "0.009064"], ["84060.80", "0.023855"], ["84058.80", "0.062673"], ["84056.80", "0.165033"], ["84054.80", "0.434298"], ["84052.80", "1.142889"], ["84050.80", "3.007604"], ["84048.80", "7.914746"], ["84038.40", "0.012660"], ["84006.80", "3.896010"], ["83998.30", "4.620849"], ["83989.80", "4.077220"], ["83981.30", "5.617503"], ["83972.80", "4.711454"], ["83964.30", "3.986615"], ["83947.30", "4.530244"], ["83938.80", "5.073873"], ["83930.30", "4.892664"], ["83921.80", "5.526898"], ["83913.30", "4.167825"], ["83904.80", "5.436293"], ["83896.30", "4.349034"], ["83887.80", "4.983269"], ["83879.30", "5.255083"], ["83870.80", "4.258430"], ["83862.30", "4.439639"], ["83853.80", "5.345688"], ["83845.30", "5.164478"], ["83661.97", "0"]], "checksum": 107908292, "ts": "1742554964546"}], "ts": 1742554964550, "record_time": 1742554964.577716, "EXCHANGE": "BITGET"}
{"action": "update", "arg": {"instType": "SPOT", "channel": "books", "instId": "BTCUSDT"}, "data": [{"asks": [["84073.25", "0"], ["84075.62", "0.196307"], ["84095.30", "0"], ["84096.38", "0.016429"], ["84105.41", "0"], ["84106.69", "0.010988"], ["84129.00", "0.697054"], ["84131.00", "1.834351"], ["84133.00", "4.827239"], ["84143.80", "0.012330"], ["84175.00", "4.892664"], ["84183.50", "4.167825"], ["84192.00", "4.530244"], ["84200.50", "4.802059"], ["84209.00", "4.439639"], ["84217.50", "5.345688"], ["84226.00", "5.073873"], ["84234.50", "4.077220"], ["84243.00", "5.617503"], ["84251.50", "5.526898"], ["84260.00", "4.349034"], ["84268.50", "3.986615"], ["84277.00", "4.983269"], ["84285.50", "4.711454"], ["84294.00", "3.896010"], ["84302.50", "5.436293"], ["84311.00", "4.258430"], ["84317.97", "0.001720"], ["84319.50", "4.620849"], ["84328.00", "5.164478"], ["84336.50", "5.255083"], ["84530.00", "0"], ["84533.01", "0"]], "bids": [["84069.59", "0"], ["84058.80", "0.062909"], ["84056.80", "0.165550"], ["84054.80", "0.435659"], ["84052.80", "1.146470"], ["84050.80", "3.017025"], ["84048.80", "7.939540"], ["84046.78", "0.028861"], ["84045.70", "0"], ["84038.40", "0"], ["84036.07", "0.056361"], ["84034.79", "0"], ["84026.00", "0.000015"], ["84006.80", "5.526898"], ["83998.30", "4.802059"], ["83989.80", "4.258430"], ["83981.30", "4.077220"], ["83972.80", "5.345688"], ["83964.30", "4.620849"], ["83955.80", "5.164478"], ["83947.30", "5.073873"], ["83938.80", "4.983269"], ["83930.30", "4.439639"], ["83921.80", "4.349034"], ["83913.30", "3.986615"], ["83904.80", "4.167825"], ["83896.30", "4.530244"], ["83887.80", "5.617503"], ["83879.30", "4.711454"], ["83870.80", "5.436293"], ["83862.30", "3.896010"], ["83853.80", "4.892664"], ["83845.30", "5.255083"], ["83661.97", "0.000052"], ["83661.60", "0.000042"]], "checksum": -92362559, "ts": "1742554964756"}], "ts": 1742554964759, "record_time": 1742554964.781945, "EXCHANGE": "BITGET"}
{"action": "update", "arg": {"instType": "SPOT", "channel": "books", "instId": "BTCUSDT"}, "data": [{"asks": [["84073.01", "2.131305"], ["84073.02", "0.026074"], ["84108.18", "0"], ["84112.07", "0"], ["84119.00", "0.005389"], ["84121.00", "0.013943"], ["84123.00", "0.036690"], ["84125.00", "0.096554"], ["84127.00", "0.254088"], ["84129.00", "0.668653"], ["84131.00", "1.759614"], ["84133.00", "4.630563"], ["84134.30", "0.003240"], ["84136.10", "0.071670"], ["84143.80", "0"], ["84175.00", "3.896010"], ["84183.50", "5.164478"], ["84192.00", "4.167825"], ["84200.50", "4.439639"], ["84209.00", "3.986615"], ["84217.50", "5.436293"], ["84226.00", "4.620849"], ["84234.50", "4.258430"], ["84243.00", "5.345688"], ["84251.50", "4.530244"], ["84260.00", "5.526898"], ["84268.50", "5.617503"], ["84277.00", "5.073873"], ["84285.50", "4.077220"], ["84294.00", "4.983269"], ["84302.50", "4.711454"], ["84311.00", "4.892664"], ["84319.50", "5.255083"], ["84328.00", "4.349034"], ["84336.50", "4.802059"], ["84530.00", "0.000031"], ["84533.01", "0.000591"], ["84533.33", "0.003186"]], "bids": [["84073.00", "0.295872"], ["84069.71", "0.041076"], ["84062.80", "0.008954"], ["84060.80", "0.023562"], ["84058.80", "0.062007"], ["84056.80", "0.163176"], ["84054.80", "0.429410"], ["84052.80", "1.130027"], ["84050.80", "2.973550"], ["84048.80", "7.825132"], ["84025.00", "0.000032"], ["84024.00", "0.000015"], ["84006.80", "4.439639"], ["83998.30", "4.258430"], ["83989.80", "5.073873"], ["83981.30", "4.711454"], ["83972.80", "5.617503"], ["83964.30", "4.802059"], ["83955.80", "5.255083"], ["83947.30", "5.526898"], ["83930.30", "4.167825"], ["83913.30", "5.345688"], ["83904.80", "4.077220"], ["83896.30", "4.892664"], ["83887.80", "3.986615"], ["83879.30", "5.164478"], ["83870.80", "4.530244"], ["83862.30", "4.620849"], ["83853.80", "5.436293"], ["83845.30", "3.896010"], ["83661.97", "0"], ["83661.60", "0"]], "checksum": 716697818, "ts": "1742554964956"}], "ts": 1742554964959, "record_time": 1742554964.981552, "EXCHANGE": "BITGET"}
{"action": "update", "arg": {"instType": "SPOT", "channel": "books", "instId": "BTCUSDT"}, "data": [{"asks": [["84073.01", "1.738595"], ["84073.03", "0"], ["84083.55", "0.038539"], ["84100.81", "0.139056"], ["84101.76", "0.220200"], ["84109.69", "0.012472"], ["84112.06", "0"], ["84117.00", "0.001046"], ["84119.00", "0.001004"], ["84121.00", "0.001017"], ["84123.00", "0.001618"], ["84125.00", "0.004258"], ["84127.00", "0.011203"], ["84129.00", "0.029244"], ["84131.00", "0.076956"], ["84133.00", "0.202517"], ["84133.10", "0"], ["84133.20", "0"], ["84133.80", "0.001001"], ["84134.10", "0"], ["84134.40", "0"], ["84134.50", "0"], ["84134.60", "0.001041"], ["84134.80", "0"], ["84134.90", "0.022260"], ["84136.10", "0.003870"], ["84136.60", "0.071640"], ["84137.30", "0"], ["84138.10", "0"], ["84138.30", "0"], ["84138.40", "0"], ["84139.10", "0.060000"], ["84139.20", "0.403140"], ["84139.60", "0.240000"], ["84139.80", "0"], ["84140.60", "0.155010"], ["84140.70", "0.045000"], ["84140.80", "0.066180"], ["84140.90", "0"], ["84142.40", "0.156000"], ["84143.80", "0.012330"], ["84144.10", "0.067800"], ["84145.40", "0.480000"], ["84145.80", "1.642530"], ["84146.10", "0.067800"], ["84146.60", "0.642240"], ["84146.70", "1.069320"], ["84175.00", "4.077220"], ["84183.50", "3.986615"], ["84192.00", "5.255083"], ["84200.50", "4.802059"], ["84209.00", "3.896010"], ["84217.50", "4.167825"], ["84226.00", "5.345688"], ["84234.50", "5.526898"], ["84243.00", "5.073873"], ["84251.50", "4.258430"], ["84260.00", "4.983269"], ["84268.50", "5.436293"], ["84277.00", "4.620849"], ["84285.50", "4.530244"], ["84294.00", "4.349034"], ["84302.50", "5.164478"], ["84311.00", "5.617503"], ["84319.50", "4.892664"], ["84328.00", "4.439639"], ["84336.50", "4.711454"], ["84533.01", "0"], ["84533.33", "0"]], "bids": [["84073.00", "0.885705"], ["84069.72", "0.012648"], ["84068.80", "0.001349"], ["84066.80", "0.002200"], ["84066.78", "0.010000"], ["84064.80", "0.005791"], ["84062.80", "0.015238"], ["84060.80", "0.040101"], ["84058.80", "0.105368"], ["84056.80", "0.277286"], ["84054.97", "0"], ["84054.80", "0.729700"], ["84052.80", "1.920263"], ["84050.80", "5.053323"], ["84048.80", "13.298219"], ["84047.90", "0.068190"], ["84047.80", "0"], ["84047.70", "0"], ["84046.00", "0.071730"], ["84045.90", "0.073380"], ["84045.80", "0"], ["84045.40", "0.071340"], ["84045.20", "0.142560"], ["84044.80", "0"], ["84043.90", "0.646230"], ["84042.70", "0.249690"], ["84041.80", "0.356700"], ["84041.60", "0.196170"], ["84041.30", "0"], ["84041.20", "0.445860"], ["84040.80", "0.356700"], ["84040.70", "0.017820"], ["84039.90", "2.436480"], ["84039.80", "0"], ["84039.30", "0"], ["84038.80", "0"], ["84038.70", "0"], ["84027.00", "0.000017"], ["84024.00", "0.000032"], ["84006.80", "4.711454"], ["83998.30", "4.892664"], ["83989.80", "5.526898"], ["83981.30", "5.073873"], ["83964.30", "5.436293"], ["83955.80", "4.167825"], ["83947.30", "4.349034"], ["83938.80", "3.896010"], ["83930.30", "4.530244"], ["83921.80", "4.258430"], ["83913.30", "3.986615"], ["83904.80", "5.164478"], ["83896.30", "4.077220"], ["83887.80", "5.255083"], ["83879.30", "4.620849"], ["83870.80", "5.345688"], ["83862.30", "4.439639"], ["83853.80", "4.802059"], ["83845.30", "4.983269"]], "checksum": 1666532914, "ts": "1742554965179"}], "ts": 1742554965186, "record_time": 1742554965.208387, "EXCHANGE": "BITGET"}
{"action": "update", "arg": {"instType": "SPOT", "channel": "books", "instId": "BTCUSDT"}, "data": [{"asks": [["84073.01", "1.919388"], ["84073.02", "0.011559"], ["84080.99", "0.013718"], ["84091.00", "0"], ["84094.28", "0"], ["84094.56", "0.119870"], ["84097.68", "0.010984"], ["84109.68", "0.004050"], ["84110.97", "0.177168"], ["84122.99", "0"], ["84127.67", "0"], ["84133.50", "0.001597"], ["84137.80", "0.781200"], ["84138.40", "0.477810"], ["84139.40", "0.008670"], ["84141.50", "0"], ["84142.00", "0.278160"], ["84142.40", "0"], ["84145.80", "1.176900"], ["84146.60", "0.450240"], ["84146.80", "0.020280"], ["84147.00", "0.070140"], ["84175.00", "4.802059"], ["84183.50", "5.436293"], ["84192.00", "4.711454"], ["84200.50", "5.255083"], ["84209.00", "4.530244"], ["84217.50", "3.986615"], ["84226.00", "4.077220"], ["84234.50", "4.983269"], ["84243.00", "4.439639"], ["84251.50", "5.345688"], ["84260.00", "4.167825"], ["84268.50", "3.896010"], ["84277.00", "4.349034"], ["84285.50", "4.258430"], ["84294.00", "5.617503"], ["84302.50", "5.526898"], ["84311.00", "5.164478"], ["84319.50", "5.073873"], ["84328.00", "4.620849"], ["84336.50", "4.892664"], ["84525.82", "0"], ["84527.47", "0"], ["84528.57", "0"], ["84530.00", "0"]], "bids": [["84073.00", "0.858252"], ["84069.82", "0.041076"], ["84069.71", "0"], ["84066.79", "0.004776"], ["84063.38", "0.027453"], ["84060.80", "0.039994"], ["84058.80", "0.105248"], ["84056.80", "0.276968"], ["84056.03", "0.004017"], ["84054.80", "0.728864"], ["84053.37", "0.247559"], ["84052.80", "1.918063"], ["84052.59", "0"], ["84050.80", "5.047535"], ["84049.80", "0"], ["84048.80", "13.282985"], ["84044.20", "0.240000"], ["84043.00", "0.120000"], ["84040.90", "0.120000"], ["84039.90", "0"], ["84036.81", "0.000876"], ["84033.41", "0"], ["84019.32", "0.001173"], ["84018.29", "0.003596"], ["84015.19", "0"], ["84013.50", "0"], ["83998.30", "5.436293"], ["83989.80", "4.620849"], ["83972.80", "4.349034"], ["83964.30", "4.167825"], ["83955.80", "4.258430"], ["83947.30", "4.530244"], ["83938.80", "5.164478"], ["83930.30", "3.896010"], ["83921.80", "5.526898"], ["83913.30", "4.439639"], ["83904.80", "4.802059"], ["83896.30", "5.345688"], ["83887.80", "3.986615"], ["83879.30", "4.983269"], ["83870.80", "5.617503"], ["83862.30", "5.255083"], ["83853.80", "4.892664"], ["83845.30", "4.077220"], ["83663.95", "0"], ["83663.91", "0"], ["83662.50", "0"]], "checksum": -539184296, "ts": "1742554965385"}], "ts": 1742554965388, "record_time": 1742554965.41631, "EXCHANGE": "BITGET"}
{"action": "update", "arg": {"instType": "SPOT", "channel": "books", "instId": "BTCUSDT"}, "data": [{"asks": [["84073.01", "1.958149"], ["84081.01", "0.209557"], ["84083.55", "0"], ["84092.54", "0.093026"], ["84118.58", "0.010000"], ["84125.64", "0"], ["84131.10", "0.001598"], ["84147.00", "0"], ["84192.00", "5.526898"], ["84200.50", "4.983269"], ["84209.00", "3.896010"], ["84217.50", "5.345688"], ["84226.00", "4.620849"], ["84234.50", "4.711454"], ["84243.00", "4.258430"], ["84251.50", "5.617503"], ["84260.00", "5.255083"], ["84268.50", "4.892664"], ["84277.00", "4.439639"], ["84285.50", "4.077220"], ["84294.00", "4.167825"], ["84302.50", "4.349034"], ["84319.50", "3.986615"], ["84328.00", "4.530244"], ["84336.50", "5.073873"], ["84525.82", "0.000099"]], "bids": [["84069.83", "0.012747"], ["84069.72", "0"], ["84062.44", "0.000233"], ["84058.28", "0"], ["84056.80", "0.277069"], ["84054.80", "0.729129"], ["84052.80", "1.918762"], ["84050.80", "5.049372"], ["84049.93", "0.055649"], ["84048.80", "13.287952"], ["84046.77", "0"], ["84045.10", "0.120000"], ["84044.60", "0.030000"], ["84040.90", "0.655050"], ["84040.70", "0"], ["84015.34", "0"], ["83998.30", "4.983269"], ["83989.80", "3.896010"], ["83981.30", "5.526898"], ["83972.80", "4.258430"], ["83955.80", "4.349034"], ["83947.30", "5.345688"], ["83938.80", "5.617503"], ["83930.30", "4.530244"], ["83921.80", "4.802059"], ["83913.30", "3.986615"], ["83904.80", "5.164478"], ["83896.30", "4.892664"], ["83887.80", "5.436293"], ["83879.30", "4.439639"], ["83870.80", "5.255083"], ["83862.30", "4.077220"], ["83853.80", "5.073873"], ["83845.30", "4.620849"], ["83663.95", "0.000022"]], "checksum": 729464969, "ts": "1742554965586"}], "ts": 1742554965590, "record_time": 1742554965.611587, "EXCHANGE": "BITGET"}
{"action": "update", "arg": {"instType": "SPOT", "channel": "books", "instId": "BTCUSDT"}, "data": [{"asks": [["84073.01", "1.657411"], ["84073.26", "0"], ["84077.01", "0.015749"], ["84090.85", "0"], ["84092.52", "0"], ["84093.08", "0"], ["84093.24", "0"], ["84093.56", "0"], ["84094.90", "0"], ["84095.06", "0"], ["84095.44", "0"], ["84096.00", "0"], ["84096.07", "0"], ["84096.33", "0"], ["84096.36", "0"], ["84096.50", "0"], ["84096.60", "0"], ["84098.04", "0"], ["84098.08", "0"], ["84098.81", "0"], ["84099.79", "0"], ["84100.82", "0"], ["84101.05", "0"], ["84101.18", "0"], ["84101.41", "0"], ["84105.25", "0"], ["84109.68", "0.056694"], ["84127.00", "0.011052"], ["84129.00", "0.029082"], ["84131.00", "0.076532"], ["84133.00", "0.201401"], ["84138.40", "0.477990"], ["84175.00", "4.349034"], ["84183.50", "4.530244"], ["84192.00", "5.164478"], ["84194.53", "0.125599"], ["84199.81", "0"], ["84200.50", "4.439639"], ["84209.00", "4.983269"], ["84217.50", "5.255083"], ["84224.32", "0.010000"], ["84226.00", "3.896010"], ["84234.50", "5.436293"], ["84243.00", "5.526898"], ["84251.50", "4.077220"], ["84260.00", "4.258430"], ["84277.00", "5.073873"], ["84285.50", "4.620849"], ["84294.00", "4.802059"], ["84302.50", "5.345688"], ["84311.00", "5.617503"], ["84319.50", "4.167825"], ["84328.00", "3.986615"], ["84336.50", "4.711454"], ["84527.47", "0.000608"], ["84528.57", "0.000008"], ["84530.00", "0.000031"], ["84533.01", "0.000591"], ["84533.33", "0.003186"], ["84534.53", "0.000461"], ["84535.32", "0.000039"], ["84536.36", "0.000053"], ["84537.04", "0.000958"], ["84538.75", "0.000011"], ["84540.00", "0.001092"], ["84540.54", "0.000184"], ["84540.97", "0.000065"], ["84541.67", "0.000198"], ["84542.37", "0.001213"], ["84543.27", "0.000067"], ["84543.43", "0.000423"], ["84543.86", "0.000033"], ["84543.93", "0.000010"], ["84544.64", "0.000036"], ["84545.16", "0.000020"], ["84545.45", "0.001774"], ["84545.63", "0.000008"]], "bids": [["84073.00", "0.822720"], ["84068.80", "0.001496"], ["84066.80", "0.002442"], ["84066.79", "0.012415"], ["84064.80", "0.006425"], ["84062.80", "0.016907"], ["84061.73", "0"], ["84060.80", "0.044687"], ["84058.80", "0.117597"], ["84056.80", "0.309466"], ["84054.80", "0.814386"], ["84052.80", "2.143121"], ["84050.80", "5.639790"], ["84050.49", "0"], ["84048.80", "14.757628"], ["84048.52", "0"], ["84048.35", "0"], ["84048.00", "0.000032"], ["84046.64", "0"], ["84046.47", "0"], ["84045.84", "0"], ["84045.46", "0"], ["84045.40", "0.071520"], ["84045.38", "0"], ["84045.08", "0"], ["84045.05", "0"], ["84044.98", "0"], ["84044.88", "0"], ["84043.90", "1.772430"], ["84043.43", "0"], ["84043.39", "0"], ["84042.48", "0"], ["84041.61", "0"], ["84040.90", "2.793570"], ["84040.80", "0"], ["84040.63", "0"], ["84040.52", "0"], ["84040.14", "0"], ["84040.04", "0"], ["84039.50", "0.153580"], ["84036.32", "0"], ["84034.50", "0"], ["84032.72", "0"], ["84032.52", "0"], ["84030.70", "0"], ["84030.68", "0"], ["84020.80", "0.001176"], ["84010.00", "0.200459"], ["84006.80", "4.892664"], ["84005.00", "0"], ["84003.98", "0"], ["84003.96", "0"], ["84003.71", "0"], ["83998.30", "4.077220"], ["83989.80", "5.526898"], ["83981.30", "5.436293"], ["83972.80", "5.073873"], ["83964.30", "4.983269"], ["83955.80", "4.530244"], ["83947.30", "4.620849"], ["83938.80", "4.439639"], ["83930.30", "4.167825"], ["83921.80", "5.164478"], ["83913.30", "5.255083"], ["83904.80", "3.896010"], ["83896.30", "4.802059"], ["83887.80", "5.617503"], ["83879.30", "5.345688"], ["83870.80", "4.711454"], ["83862.30", "4.258430"], ["83853.80", "3.986615"], ["83845.30", "4.349034"], ["83663.91", "0.000161"], ["83662.50", "0.000077"], ["83661.97", "0.000052"], ["83661.60", "0.000042"], ["83661.08", "0.004152"], ["83660.71", "0.000309"], ["83660.14", "0.000016"], ["83660.00", "0.001273"], ["83659.61", "0.000454"], ["83659.49", "0.000012"], ["83659.44", "0.000613"], ["83658.54", "0.000036"], ["83656.60", "0.000607"], ["83655.00", "0.000926"], ["83654.23", "0.000009"], ["83653.94", "0.000133"], ["83653.67", "0.001695"], ["83653.31", "0.000015"], ["83652.80", "0.000119"], ["83652.48", "0.000188"], ["83651.65", "0.000018"], ["83651.16", "0.000896"], ["83650.84", "0.003326"], ["83650.00", "0.032056"], ["83648.96", "0.000030"], ["83647.46", "0.000224"], ["83647.06", "0.000040"], ["83646.67", "0.000018"], ["83645.83", "0.000014"]], "checksum": 1532397560, "ts": "1742554965788"}], "ts": 1742554965792, "record_time": 1742554965.815588, "EXCHANGE": "BITGET"}
{"action": "update", "arg": {"instType": "SPOT", "channel": "books", "instId": "BTCUSDT"}, "data": [{"asks": [["84073.01", "0.973650"], ["84073.02", "0"], ["84075.62", "0"], ["84075.79", "0.112993"], ["84077.01", "0"], ["84078.65", "0.009407"], ["84078.68", "0.012908"], ["84078.69", "0.006440"], ["84078.82", "0.007162"], ["84082.37", "0"], ["84088.79", "0.038539"], ["84092.54", "0.040890"], ["84092.63", "0.017449"], ["84094.56", "0"], ["84096.12", "0.035952"], ["84096.38", "0"], ["84097.68", "0"], ["84097.80", "0.035961"], ["84098.40", "0.067528"], ["84100.04", "0.006356"], ["84100.14", "0.006356"], ["84100.21", "0.006356"], ["84100.30", "0.006356"], ["84100.53", "0.006356"], ["84100.65", "0.119870"], ["84100.72", "0.006356"], ["84100.81", "0.083424"], ["84101.27", "0.006356"], ["84101.64", "0.016429"], ["84101.77", "0.006356"], ["84102.05", "0.006356"], ["84103.47", "0.006357"], ["84104.02", "0.010984"], ["84104.08", "0.009990"], ["84105.07", "0.119850"], ["84105.18", "0.016429"], ["84105.24", "0"], ["84105.67", "0.006356"], ["84105.76", "0.119883"], ["84106.10", "0.119858"], ["84106.45", "0.015895"], ["84106.69", "0"], ["84107.11", "0.010985"], ["84107.65", "0.119867"], ["84109.69", "0"], ["84110.70", "0.015892"], ["84110.84", "0.009989"], ["84113.00", "0"], ["84113.86", "0.012472"], ["84115.00", "0"], ["84115.36", "0.010988"], ["84117.00", "0"], ["84118.58", "0"], ["84119.00", "0"], ["84120.36", "0"], ["84121.00", "0"], ["84122.00", "0.001033"], ["84123.00", "0"], ["84124.00", "0.001022"], ["84125.00", "0"], ["84126.00", "0.001028"], ["84127.00", "0"], ["84128.00", "0.001044"], ["84129.00", "0"], ["84129.29", "0.713187"], ["84130.00", "0.001005"], ["84131.00", "0"], ["84132.00", "0.001229"], ["84133.00", "0"], ["84133.80", "0"], ["84134.00", "0.003235"], ["84134.30", "0"], ["84134.60", "0"], ["84134.90", "0"], ["84135.40", "0"], ["84136.00", "0.008513"], ["84136.10", "0"], ["84136.60", "0"], ["84137.40", "0"], ["84137.80", "0"], ["84138.00", "0.022402"], ["84138.40", "0"], ["84139.10", "0"], ["84139.20", "0"], ["84139.40", "0"], ["84139.50", "0"], ["84139.60", "0"], ["84140.00", "0.058954"], ["84140.10", "0"], ["84140.50", "0"], ["84140.60", "0"], ["84140.70", "0"], ["84140.80", "0"], ["84142.00", "0.155143"], ["84142.10", "0.001001"], ["84143.30", "0.241200"], ["84143.70", "0.225780"], ["84143.80", "0"], ["84144.10", "0"], ["84144.80", "0.045180"], ["84145.40", "0"], ["84145.50", "0.071460"], ["84145.80", "1.177080"], ["84146.10", "0"], ["84146.50", "0.196980"], ["84146.60", "0"], ["84146.70", "2.355330"], ["84148.10", "0.067800"], ["84148.70", "0.534660"], ["84149.00", "0.120000"], ["84149.30", "0.924120"], ["84149.80", "0.927390"], ["84150.10", "0.067800"], ["84150.70", "0.300000"], ["84150.80", "0.300930"], ["84151.60", "1.069320"], ["84152.10", "0.067800"], ["84152.30", "0.321090"], ["84153.20", "0.678240"], ["84153.50", "0.392430"], ["84154.20", "0.069780"], ["84154.80", "0.480000"], ["84154.90", "1.391190"], ["84175.00", "0"], ["84183.50", "0"], ["84184.00", "3.986192"], ["84192.00", "0"], ["84192.50", "4.801549"], ["84200.50", "0"], ["84201.00", "5.616906"], ["84209.00", "0"], ["84209.50", "4.257977"], ["84217.50", "0"], ["84218.00", "4.167382"], ["84226.00", "0"], ["84226.50", "4.076787"], ["84234.50", "0"], ["84235.00", "3.895596"], ["84243.00", "0"], ["84243.50", "5.254525"], ["84251.50", "0"], ["84252.00", "5.345120"], ["84260.00", "0"], ["84260.50", "5.435716"], ["84268.50", "0"], ["84269.00", "4.529763"], ["84277.00", "0"], ["84277.50", "4.620358"], ["84285.50", "0"], ["84286.00", "4.710954"], ["84294.00", "0"], ["84294.50", "5.163930"], ["84302.50", "0"], ["84303.00", "5.073335"], ["84311.00", "0"], ["84311.50", "4.439168"], ["84319.50", "0"], ["84320.00", "4.348573"], ["84328.00", "0"], ["84328.50", "4.892144"], ["84336.50", "0"], ["84337.00", "4.982739"], ["84345.50", "5.526311"], ["84534.53", "0"], ["84535.32", "0"], ["84536.36", "0"], ["84537.04", "0"], ["84538.75", "0"], ["84540.00", "0"], ["84540.54", "0"], ["84540.97", "0"], ["84541.67", "0"], ["84542.37", "0"], ["84543.27", "0"], ["84543.43", "0"], ["84543.86", "0"], ["84543.93", "0"], ["84544.64", "0"], ["84545.16", "0"], ["84545.45", "0"], ["84545.63", "0"]], "bids": [["84073.00", "1.282563"], ["84071.80", "0.010756"], ["84069.82", "0"], ["84069.80", "0.028305"], ["84069.53", "0.021425"], ["84068.80", "0"], ["84067.82", "0.112993"], ["84067.80", "0.074488"], ["84066.80", "0"], ["84066.11", "0.005920"], ["84066.03", "0.010000"], ["84066.01", "0.008501"], ["84065.80", "0.196020"], ["84065.15", "0.009585"], ["84065.11", "0.009714"], ["84065.08", "0.007467"], ["84065.05", "0.008236"], ["84065.03", "0.007795"], ["84065.01", "0.007750"], ["84064.80", "0"], ["84063.80", "0.515842"], ["84063.38", "0"], ["84062.80", "0"], ["84061.97", "0.008712"], ["84061.94", "0.010333"], ["84061.92", "0.008896"], ["84061.80", "1.357480"], ["84060.98", "0.008535"], ["84060.95", "0.005581"], ["84060.92", "0.009863"], ["84060.91", "0.005169"], ["84060.87", "0.009944"], ["84060.80", "0"], ["84059.80", "3.572315"], ["84059.45", "0.247559"], ["84058.80", "0"], ["84057.80", "9.400831"], ["84057.70", "0.001048"], ["84057.60", "0.001003"], ["84057.33", "0"], ["84057.31", "0"], ["84057.00", "0.000032"], ["84056.95", "0"], ["84056.93", "0"], ["84056.92", "0"], ["84056.91", "0"], ["84056.89", "0"], ["84056.81", "0.322310"], ["84056.80", "0"], ["84056.70", "4.563270"], ["84056.60", "0.001006"], ["84056.30", "1.350810"], ["84056.27", "0.055649"], ["84055.90", "0.068190"], ["84055.76", "0.089474"], ["84055.68", "0.017815"], ["84055.57", "0.028861"], ["84055.31", "0.018253"], ["84055.17", "0"], ["84055.05", "0.008993"], ["84054.80", "0"], ["84054.59", "0.005945"], ["84054.08", "0.083930"], ["84053.90", "0.067800"], ["84053.50", "0.015000"], ["84053.37", "0"], ["84053.25", "0"], ["84053.17", "0"], ["84053.12", "0"], ["84052.82", "0"], ["84052.81", "0"], ["84052.80", "0"], ["84052.76", "0"], ["84052.70", "0"], ["84052.69", "0"], ["84052.50", "8.582850"], ["84052.46", "0.051957"], ["84051.90", "0.067800"], ["84051.88", "0.017101"], ["84051.84", "0.224857"], ["84051.70", "0.007131"], ["84051.50", "0.025182"], ["84051.11", "0.007339"], ["84050.91", "0.008268"], ["84050.80", "0"], ["84050.70", "2.641140"], ["84050.66", "0.007942"], ["84050.43", "0.008184"], ["84050.25", "0.175775"], ["84050.15", "0.017349"], ["84049.93", "0"], ["84049.90", "0.067800"], ["84049.33", "0.008059"], ["84048.82", "0.012654"], ["84048.80", "2.421330"], ["84048.70", "0"], ["84048.60", "0"], ["84048.03", "0.268346"], ["84048.00", "0.120000"], ["84047.90", "0.067800"], ["84047.75", "0.018515"], ["84046.78", "0"], ["84046.60", "0.120000"], ["84046.46", "0.021127"], ["84046.11", "0"], ["84046.00", "0.071340"], ["84045.97", "0.259766"], ["84045.90", "0.285000"], ["84045.60", "0.090000"], ["84045.41", "0.131985"], ["84045.40", "0.071340"], ["84045.20", "0"], ["84044.74", "0.056361"], ["84044.60", "0.015000"], ["84044.30", "0.035670"], ["84043.90", "0"], ["84043.40", "0"], ["84043.10", "0"], ["84043.00", "0.000032"], ["84042.70", "0"], ["84042.65", "0.008426"], ["84042.60", "0"], ["84042.57", "0.008012"], ["84042.55", "0.006471"], ["84042.43", "0.008319"], ["84042.20", "0"], ["84041.80", "0"], ["84041.76", "0.073206"], ["84041.70", "0"], ["84041.60", "0"], ["84041.20", "0"], ["84040.90", "0"], ["84040.88", "0.009209"], ["84040.79", "0.006905"], ["84040.71", "0.007304"], ["84040.53", "0"], ["84040.45", "0"], ["84040.31", "0"], ["84039.85", "0.008596"], ["84036.07", "0"], ["84035.14", "0.010000"], ["84033.75", "0.008092"], ["84033.70", "0.005051"], ["84033.67", "0.008265"], ["84031.97", "0"], ["84031.92", "0"], ["84030.01", "0"], ["84027.05", "0.017449"], ["84027.00", "0.000032"], ["84026.00", "0.000032"], ["84024.85", "0"], ["84024.81", "0"], ["84024.77", "0"], ["84023.00", "0.000032"], ["84017.91", "0.007435"], ["84016.80", "0"], ["84015.80", "4.167382"], ["84015.07", "0.008572"], ["84013.96", "0.007247"], ["84013.87", "0.007651"], ["84013.74", "0.007337"], ["84008.65", "0"], ["84007.30", "3.895596"], ["84006.80", "0"], ["84005.74", "0"], ["83998.80", "5.616906"], ["83998.30", "0"], ["83990.30", "5.163930"], ["83989.80", "0"], ["83981.80", "4.348573"], ["83981.30", "0"], ["83973.30", "3.986192"], ["83972.80", "0"], ["83964.80", "5.526311"], ["83964.30", "0"], ["83956.30", "4.710954"], ["83955.80", "0"], ["83947.80", "4.892144"], ["83947.30", "0"], ["83939.30", "5.435716"], ["83938.80", "0"], ["83930.80", "4.439168"], ["83930.30", "0"], ["83922.30", "4.801549"], ["83921.80", "0"], ["83913.80", "5.345120"], ["83913.30", "0"], ["83905.30", "5.073335"], ["83904.80", "0"], ["83896.80", "4.620358"], ["83896.30", "0"], ["83888.30", "4.529763"], ["83887.80", "0"], ["83879.80", "4.257977"], ["83879.30", "0"], ["83871.30", "5.254525"], ["83870.80", "0"], ["83862.80", "4.076787"], ["83862.30", "0"], ["83854.30", "4.982739"], ["83853.80", "0"], ["83845.30", "0"], ["83662.50", "0"], ["83661.97", "0"], ["83661.60", "0"], ["83661.08", "0"], ["83660.71", "0"], ["83660.14", "0"], ["83660.00", "0"], ["83659.61", "0"], ["83659.49", "0"], ["83659.44", "0"], ["83658.54", "0"], ["83656.60", "0"], ["83655.00", "0"], ["83654.23", "0"], ["83653.94", "0"], ["83653.67", "0"], ["83653.31", "0"], ["83652.80", "0"], ["83652.48", "0"], ["83651.65", "0"], ["83651.16", "0"], ["83650.84", "0"], ["83650.00", "0"], ["83648.96", "0"], ["83647.46", "0"], ["83647.06", "0"], ["83646.67", "0"], ["83645.83", "0"]], "checksum": -1277344253, "ts": "1742554965991"}], "ts": 1742554965994, "record_time": 1742554966.018559, "EXCHANGE": "BITGET"}
{"action": "update", "arg": {"instType": "SPOT", "channel": "books", "instId": "BTCUSDT"}, "data": [{"asks": [["84073.01", "0.777240"], ["84073.02", "0.000100"], ["84073.03", "0.000100"], ["84073.04", "0.000100"], ["84075.61", "0.000222"], ["84075.79", "0"], ["84080.99", "0"], ["84092.54", "0.016020"], ["84096.12", "0"], ["84097.80", "0"], ["84100.14", "0"], ["84100.30", "0"], ["84100.72", "0"], ["84101.27", "0"], ["84101.64", "0"], ["84101.77", "0"], ["84102.05", "0"], ["84103.47", "0"], ["84103.57", "0.035952"], ["84104.08", "0"], ["84105.06", "0.158737"], ["84105.07", "0"], ["84105.25", "0.035961"], ["84106.10", "0"], ["84106.45", "0"], ["84107.10", "0.006356"], ["84107.27", "0.006356"], ["84108.17", "0.006356"], ["84108.58", "0.006356"], ["84108.72", "0.006356"], ["84109.02", "0.006356"], ["84109.09", "0.016429"], ["84110.50", "0.006357"], ["84110.97", "0"], ["84111.54", "0.009990"], ["84112.52", "0.119850"], ["84113.55", "0.119858"], ["84113.91", "0.015895"], ["84128.00", "0.002296"], ["84130.00", "0.006044"], ["84132.00", "0.015904"], ["84134.00", "0.041853"], ["84136.00", "0.110140"], ["84138.00", "0.289843"], ["84140.00", "0.762743"], ["84142.00", "2.007219"], ["84142.30", "0.771150"], ["84142.90", "0.001020"], ["84143.30", "0.001035"], ["84143.70", "0"], ["84144.80", "0"], ["84145.30", "2.355540"], ["84145.50", "0.071640"], ["84145.80", "0"], ["84146.70", "0"], ["84146.80", "0.011280"], ["84148.10", "0.067980"], ["84148.60", "0.621000"], ["84148.70", "0"], ["84149.00", "0"], ["84149.30", "0.924300"], ["84149.60", "0.066540"], ["84149.80", "0.807390"], ["84150.30", "0.420000"], ["84150.70", "0"], ["84151.00", "0.045000"], ["84152.10", "0.112800"], ["84152.30", "0"], ["84153.10", "0.107040"], ["84153.20", "0.450240"], ["84153.50", "0.272430"], ["84154.80", "0"], ["84154.90", "3.173400"], ["84155.20", "1.360770"], ["84155.60", "0.178200"], ["84155.70", "0.120000"], ["84156.80", "0.012450"], ["84184.00", "4.076787"], ["84192.50", "5.073335"], ["84201.00", "3.986192"], ["84209.50", "4.982739"], ["84218.00", "4.439168"], ["84226.50", "4.892144"], ["84235.00", "4.348573"], ["84243.50", "4.710954"], ["84252.00", "5.163930"], ["84260.50", "5.254525"], ["84269.00", "3.895596"], ["84277.50", "5.345120"], ["84286.00", "4.529763"], ["84294.50", "5.526311"], ["84303.00", "4.801549"], ["84311.50", "5.616906"], ["84320.00", "4.257977"], ["84328.50", "4.167382"], ["84337.00", "4.620358"], ["84345.50", "5.435716"], ["84527.47", "0"], ["84528.57", "0"], ["84530.00", "0"], ["84533.01", "0"], ["84533.33", "0"]], "bids": [["84073.00", "1.437246"], ["84071.80", "0.013212"], ["84069.83", "0.069589"], ["84069.80", "0.034768"], ["84067.82", "0"], ["84067.80", "0.091494"], ["84065.80", "0.240775"], ["84064.81", "0.004017"], ["84063.80", "0.633618"], ["84063.50", "0.027453"], ["84063.21", "0.089474"], ["84062.44", "0"], ["84061.80", "1.667415"], ["84061.53", "0.083930"], ["84060.41", "0.005945"], ["84059.80", "4.387935"], ["84058.84", "0.017101"], ["84058.67", "0.007131"], ["84058.56", "0.007339"], ["84058.10", "0.007942"], ["84057.80", "11.547196"], ["84057.70", "0.001470"], ["84057.60", "0.001500"], ["84057.39", "0.008184"], ["84056.95", "0.017349"], ["84056.70", "3.708060"], ["84056.60", "0"], ["84056.30", "1.350600"], ["84056.03", "0"], ["84055.85", "0.012654"], ["84055.76", "0"], ["84055.70", "0.072870"], ["84055.20", "0.018515"], ["84054.59", "0"], ["84054.33", "0.268346"], ["84054.20", "0.071400"], ["84054.08", "0"], ["84053.90", "0.067980"], ["84053.35", "0.222644"], ["84053.11", "3.052247"], ["84052.86", "0.076104"], ["84052.50", "2.022780"], ["84051.88", "0"], ["84051.70", "0"], ["84051.11", "0"], ["84050.80", "0.240000"], ["84050.70", "1.350000"], ["84050.66", "0"], ["84050.43", "0"], ["84050.20", "0.120000"], ["84050.15", "0"], ["84049.90", "0.560670"], ["84049.60", "0.240000"], ["84049.30", "0.009000"], ["84048.82", "0"], ["84048.80", "1.972170"], ["84048.03", "0"], ["84047.75", "0"], ["84047.50", "0.120000"], ["84046.70", "0.582150"], ["84046.60", "1.309320"], ["84045.90", "0.072990"], ["84045.41", "0.055881"], ["84044.70", "0"], ["84044.60", "0"], ["84044.30", "0"], ["84044.20", "0"], ["84015.80", "4.892144"], ["84007.30", "4.348573"], ["83998.80", "4.801549"], ["83990.30", "3.986192"], ["83981.80", "5.435716"], ["83973.30", "4.439168"], ["83964.80", "5.345120"], ["83956.30", "4.167382"], ["83947.80", "4.076787"], ["83939.30", "4.529763"], ["83930.80", "5.254525"], ["83922.30", "3.895596"], ["83913.80", "4.982739"], ["83905.30", "5.526311"], ["83896.80", "4.710954"], ["83888.30", "5.163930"], ["83879.80", "5.073335"], ["83871.30", "5.616906"], ["83862.80", "4.620358"], ["83854.30", "4.257977"], ["83664.71", "0"], ["83664.19", "0"], ["83663.98", "0"], ["83663.95", "0"], ["83663.91", "0"]], "checksum": 58404772, "ts": "1742554966193"}], "ts": 1742554966200, "record_time": 1742554966.223594, "EXCHANGE": "BITGET"}
{"action": "update", "arg": {"instType": "SPOT", "channel": "books", "instId": "BTCUSDT"}, "data": [{"asks": [["84073.01", "0.937574"], ["84075.62", "0.207082"], ["84078.69", "0.092543"], ["84080.25", "0.112993"], ["84088.78", "0.013718"], ["84092.54", "0"], ["84105.06", "0"], ["84118.95", "0.182490"], ["84126.00", "0.001422"], ["84128.00", "0.003742"], ["84130.00", "0.009846"], ["84132.00", "0.025911"], ["84134.00", "0.068187"], ["84136.00", "0.179439"], ["84138.00", "0.472208"], ["84140.00", "1.242654"], ["84142.00", "3.270140"], ["84142.30", "1.709820"], ["84142.90", "0"], ["84143.30", "0"], ["84148.10", "0.504780"], ["84148.60", "0"], ["84149.60", "0.066720"], ["84152.00", "0.144510"], ["84155.40", "0.120000"], ["84156.80", "0"], ["84184.00", "4.710954"], ["84201.00", "5.163930"], ["84209.50", "4.529763"], ["84218.00", "4.076787"], ["84226.50", "4.801549"], ["84235.00", "5.616906"], ["84243.50", "4.620358"], ["84252.00", "5.435716"], ["84260.50", "3.895596"], ["84269.00", "4.167382"], ["84286.00", "5.254525"], ["84294.50", "4.439168"], ["84303.00", "4.892144"], ["84311.50", "4.348573"], ["84320.00", "4.982739"], ["84328.50", "5.526311"], ["84337.00", "4.257977"], ["84345.50", "3.986192"]], "bids": [["84071.80", "0.013425"], ["84069.83", "0.042732"], ["84069.80", "0.035328"], ["84067.80", "0.092968"], ["84066.79", "0"], ["84065.80", "0.244653"], ["84064.82", "0.014255"], ["84063.80", "0.643824"], ["84061.80", "1.694273"], ["84059.80", "4.458615"], ["84057.80", "11.733196"], ["84053.80", "0.070890"], ["84052.50", "1.525920"], ["84051.90", "0.067980"], ["84051.70", "0.120000"], ["84048.30", "0.120000"], ["84046.50", "0.120000"], ["84045.40", "0"], ["84045.10", "0"], ["84015.80", "4.076787"], ["84007.30", "5.345120"], ["83998.80", "5.163930"], ["83990.30", "3.895596"], ["83981.80", "4.801549"], ["83973.30", "3.986192"], ["83964.80", "5.526311"], ["83956.30", "4.257977"], ["83947.80", "4.439168"], ["83939.30", "4.167382"], ["83930.80", "4.892144"], ["83922.30", "5.435716"], ["83913.80", "5.254525"], ["83905.30", "4.982739"], ["83896.80", "5.073335"], ["83888.30", "4.620358"], ["83879.80", "4.529763"], ["83871.30", "4.348573"], ["83862.80", "4.710954"], ["83854.30", "5.616906"], ["83666.65", "0"], ["83666.00", "0"]], "checksum": -591119505, "ts": "1742554966401"}], "ts": 1742554966405, "record_time": 1742554966.426821, "EXCHANGE": "BITGET"}
{"action": "update", "arg": {"instType": "SPOT", "channel": "books", "instId": "BTCUSDT"}, "data": [{"asks": [["84105.75", "0.091590"], ["84142.00", "3.270029"], ["84142.20", "0.001045"], ["84142.30", "1.645050"], ["84144.30", "2.355390"], ["84145.20", "0.066570"], ["84145.30", "0"], ["84148.10", "0.365610"], ["84149.30", "0.924120"], ["84149.60", "0"], ["84149.80", "1.201800"], ["84150.40", "1.350000"], ["84155.20", "0.010770"], ["84155.60", "0"], ["84155.70", "0"], ["84184.00", "5.435716"], ["84192.50", "4.257977"], ["84201.00", "4.801549"], ["84209.50", "4.892144"], ["84218.00", "5.073335"], ["84226.50", "5.616906"], ["84235.00", "4.348573"], ["84252.00", "4.167382"], ["84260.50", "4.439168"], ["84269.00", "4.529763"], ["84277.50", "3.895596"], ["84286.00", "5.345120"], ["84294.50", "3.986192"], ["84303.00", "5.163930"], ["84311.50", "5.254525"], ["84328.50", "4.710954"], ["84337.00", "4.076787"], ["84345.50", "5.526311"], ["84525.82", "0"]], "bids": [["84067.80", "0.093200"], ["84066.79", "0.322578"], ["84065.80", "0.245157"], ["84063.80", "0.645148"], ["84061.80", "1.697760"], ["84061.74", "1.468557"], ["84059.80", "4.467789"], ["84057.80", "11.757339"], ["84054.21", "0.069369"], ["84053.80", "0"], ["84050.25", "0"], ["84048.80", "1.970520"], ["84048.00", "0.000032"], ["84045.41", "0"], ["84015.80", "3.986192"], ["84007.30", "5.435716"], ["83998.80", "4.620358"], ["83990.30", "4.892144"], ["83981.80", "4.982739"], ["83973.30", "5.163930"], ["83964.80", "4.529763"], ["83956.30", "4.167382"], ["83947.80", "5.616906"], ["83939.30", "5.526311"], ["83930.80", "4.257977"], ["83922.30", "4.710954"], ["83913.80", "5.073335"], ["83905.30", "4.076787"], ["83896.80", "5.254525"], ["83888.30", "4.348573"], ["83879.80", "4.439168"], ["83871.30", "5.345120"], ["83862.80", "4.801549"], ["83854.30", "3.895596"], ["83666.65", "0.000122"], ["83666.00", "0.271427"]], "checksum": 2146593022, "ts": "1742554966612"}], "ts": 1742554966616, "record_time": 1742554966.681983, "EXCHANGE": "BITGET"}
{"action": "update", "arg": {"instType": "SPOT", "channel": "books", "instId": "BTCUSDT"}, "data": [{"asks": [["84078.47", "0.086103"], ["84078.69", "0.006440"], ["84092.62", "0.005235"], ["84098.40", "0.096000"], ["84145.20", "0.254160"], ["84147.40", "0.074190"], ["84149.80", "0.807390"], ["84150.40", "0"], ["84184.00", "3.986192"], ["84192.50", "4.801549"], ["84201.00", "3.895596"], ["84209.50", "5.526311"], ["84218.00", "4.710954"], ["84226.50", "4.257977"], ["84235.00", "4.076787"], ["84243.50", "4.982739"], ["84252.00", "5.163930"], ["84260.50", "5.345120"], ["84269.00", "4.620358"], ["84277.50", "5.435716"], ["84286.00", "4.892144"], ["84294.50", "4.529763"], ["84303.00", "4.348573"], ["84320.00", "5.073335"], ["84328.50", "5.616906"], ["84337.00", "4.439168"], ["84345.50", "4.167382"], ["84524.83", "0"], ["84525.00", "0"]], "bids": [["84065.80", "0.245290"], ["84063.80", "0.645501"], ["84061.80", "1.698687"], ["84059.80", "4.470227"], ["84057.80", "11.763756"], ["84022.00", "0.000017"], ["84015.80", "5.073335"], ["84007.30", "5.163930"], ["83998.80", "5.526311"], ["83990.30", "4.076787"], ["83981.80", "4.439168"], ["83973.30", "4.529763"], ["83964.80", "3.986192"], ["83956.30", "5.435716"], ["83947.80", "4.620358"], ["83939.30", "4.167382"], ["83930.80", "4.892144"], ["83922.30", "4.257977"], ["83913.80", "5.345120"], ["83905.30", "5.254525"], ["83896.80", "4.710954"], ["83879.80", "4.982739"], ["83871.30", "5.616906"], ["83666.00", "0"]], "checksum": -1968776501, "ts": "1742554966831"}], "ts": 1742554966835, "record_time": 1742554966.858084, "EXCHANGE": "BITGET"}
{"action": "update", "arg": {"instType": "SPOT", "channel": "books", "instId": "BTCUSDT"}, "data": [{"asks": [["84126.00", "0.002620"], ["84128.00", "0.006896"], ["84130.00", "0.018146"], ["84132.00", "0.047753"], ["84134.00", "0.125667"], ["84136.00", "0.330701"], ["84138.00", "0.870266"], ["84140.00", "2.290173"], ["84141.79", "0.379542"], ["84142.00", "6.026772"], ["84142.30", "1.132230"], ["84144.30", "0"], ["84145.20", "0"], ["84145.50", "0.071460"], ["84146.50", "0"], ["84149.80", "1.201710"], ["84150.40", "1.350000"], ["84155.60", "0.178200"], ["84184.00", "5.345120"], ["84201.00", "4.620358"], ["84209.50", "4.710954"], ["84218.00", "4.982739"], ["84226.50", "3.986192"], ["84235.00", "5.073335"], ["84243.50", "5.616906"], ["84252.00", "4.167382"], ["84260.50", "5.526311"], ["84269.00", "4.257977"], ["84286.00", "5.254525"], ["84294.50", "5.163930"], ["84311.50", "4.076787"], ["84320.00", "4.439168"], ["84328.50", "3.895596"], ["84337.00", "4.529763"], ["84345.50", "4.892144"], ["84427.29", "0"], ["84436.26", "1.642307"], ["84524.83", "0.000009"]], "bids": [["84073.00", "1.380791"], ["84071.80", "0.011309"], ["84069.80", "0.029762"], ["84067.80", "0.078320"], ["84065.80", "0.206107"], ["84063.80", "0.542385"], ["84061.80", "1.427331"], ["84059.80", "3.756133"], ["84057.80", "9.884561"], ["84057.60", "0.001014"], ["84056.81", "0.344302"], ["84056.70", "3.707010"], ["84055.90", "0.068010"], ["84055.70", "0"], ["84022.00", "0.000032"], ["84015.80", "4.710954"], ["84007.30", "4.348573"], ["83998.80", "4.529763"], ["83990.30", "4.801549"], ["83981.80", "5.254525"], ["83973.30", "5.163930"], ["83964.80", "4.167382"], ["83956.30", "4.076787"], ["83947.80", "5.435716"], ["83939.30", "4.982739"], ["83930.80", "4.257977"], ["83922.30", "4.620358"], ["83913.80", "5.073335"], ["83905.30", "3.986192"], ["83896.80", "3.895596"], ["83888.30", "5.526311"], ["83879.80", "5.616906"], ["83871.30", "5.345120"], ["83862.80", "4.892144"], ["83854.30", "4.439168"], ["83763.45", "1.675701"], ["83754.56", "0"], ["83666.00", "0.271427"]], "checksum": 2045013682, "ts": "1742554967040"}], "ts": 1742554967043, "record_time": 1742554967.066216, "EXCHANGE": "BITGET"}
{"action": "update", "arg": {"instType": "SPOT", "channel": "books", "instId": "BTCUSDT"}, "data": [{"asks": [["84119.99", "0.443750"], ["84126.00", "0.002177"], ["84128.00", "0.005731"], ["84130.00", "0.015080"], ["84132.00", "0.039686"], ["84134.00", "0.104436"], ["84136.00", "0.274831"], ["84138.00", "0.723241"], ["84140.00", "1.903264"], ["84141.79", "0"], ["84142.00", "5.008589"], ["84143.30", "0.305130"], ["84149.40", "0.045540"], ["84149.80", "1.158360"], ["84152.00", "0"], ["84155.60", "0"], ["84184.00", "3.895596"], ["84192.50", "4.257977"], ["84201.00", "5.073335"], ["84209.50", "4.801549"], ["84218.00", "3.986192"], ["84226.50", "4.529763"], ["84235.00", "5.435716"], ["84243.50", "4.076787"], ["84252.00", "4.439168"], ["84260.50", "4.892144"], ["84269.00", "4.982739"], ["84277.50", "5.616906"], ["84286.00", "5.163930"], ["84294.50", "4.167382"], ["84303.00", "4.710954"], ["84311.50", "4.620358"], ["84320.00", "5.254525"], ["84328.50", "4.348573"], ["84337.00", "5.345120"], ["84345.50", "5.526311"], ["84525.00", "0.003286"]], "bids": [["84071.80", "0.012094"], ["84069.80", "0.031826"], ["84067.80", "0.083752"], ["84066.78", "0"], ["84065.80", "0.220401"], ["84063.80", "0.580003"], ["84061.80", "1.526323"], ["84059.80", "4.016638"], ["84057.80", "10.570101"], ["84057.50", "0.001023"], ["84057.40", "0.045960"], ["84056.70", "3.706170"], ["84055.90", "0.067800"], ["84055.70", "0.073980"], ["84051.90", "0.067800"], ["84045.60", "0"], ["84015.80", "3.895596"], ["84007.30", "5.163930"], ["83998.80", "4.620358"], ["83990.30", "4.982739"], ["83981.80", "5.435716"], ["83973.30", "4.257977"], ["83964.80", "5.073335"], ["83956.30", "4.529763"], ["83947.80", "3.986192"], ["83939.30", "4.439168"], ["83930.80", "5.345120"], ["83922.30", "4.801549"], ["83913.80", "4.167382"], ["83905.30", "4.348573"], ["83896.80", "4.892144"], ["83879.80", "4.710954"], ["83871.30", "5.616906"], ["83862.80", "4.076787"], ["83854.30", "5.254525"], ["83666.00", "0"]], "checksum": -98745823, "ts": "1742554967246"}], "ts": 1742554967249, "record_time": 1742554967.27345, "EXCHANGE": "BITGET"}
{"action": "update", "arg": {"instType": "SPOT", "channel": "books", "instId": "BTCUSDT"}, "data": [{"asks": [["84078.27", "0.086103"], ["84078.47", "0"], ["84138.00", "0.723090"], ["84140.00", "1.902868"], ["84142.00", "5.007808"], ["84153.20", "0.984900"], ["84155.40", "0"], ["84184.00", "4.801549"], ["84192.50", "5.073335"], ["84201.00", "4.257977"], ["84209.50", "5.254525"], ["84218.00", "4.620358"], ["84226.50", "5.435716"], ["84235.00", "4.348573"], ["84243.50", "5.616906"], ["84252.00", "3.895596"], ["84260.50", "4.439168"], ["84269.00", "4.076787"], ["84277.50", "5.345120"], ["84286.00", "3.986192"], ["84294.50", "4.710954"], ["84303.00", "4.982739"], ["84311.50", "5.526311"], ["84320.00", "4.529763"], ["84328.50", "4.167382"], ["84337.00", "5.163930"], ["84345.50", "4.892144"], ["84525.82", "0.000099"]], "bids": [["84071.80", "0.011211"], ["84069.80", "0.029505"], ["84067.80", "0.077643"], ["84065.80", "0.204323"], ["84063.80", "0.537693"], ["84061.80", "1.414981"], ["84059.80", "3.723634"], ["84057.80", "9.799038"], ["84055.70", "0"], ["84052.00", "0.069930"], ["84045.90", "0"], ["84023.00", "0.000015"], ["84015.80", "5.254525"], ["84007.30", "4.892144"], ["83998.80", "5.616906"], ["83990.30", "4.439168"], ["83981.80", "3.986192"], ["83973.30", "3.895596"], ["83956.30", "4.076787"], ["83947.80", "5.435716"], ["83939.30", "4.257977"], ["83930.80", "5.526311"], ["83922.30", "5.163930"], ["83913.80", "4.982739"], ["83905.30", "4.620358"], ["83896.80", "4.167382"], ["83888.30", "4.801549"], ["83879.80", "4.348573"], ["83871.30", "4.710954"], ["83862.80", "5.345120"], ["83854.30", "4.529763"], ["83666.00", "0.271427"], ["83664.71", "0.000071"]], "checksum": 1501541423, "ts": "1742554967448"}], "ts": 1742554967451, "record_time": 1742554967.475073, "EXCHANGE": "BITGET"}
{"action": "update", "arg": {"instType": "SPOT", "channel": "books", "instId": "BTCUSDT"}, "data": [{"asks": [["84126.00", "0.002596"], ["84128.00", "0.006832"], ["84130.00", "0.017978"], ["84132.00", "0.047311"], ["84134.00", "0.124502"], ["84136.00", "0.327637"], ["84138.00", "0.862447"], ["84140.00", "2.269599"], ["84142.00", "5.972627"], ["84184.00", "5.254525"], ["84192.50", "3.895596"], ["84201.00", "4.167382"], ["84209.50", "4.710954"], ["84218.00", "4.439168"], ["84226.50", "4.348573"], ["84235.00", "5.345120"], ["84243.50", "5.073335"], ["84252.00", "4.801549"], ["84260.50", "3.986192"], ["84269.00", "5.526311"], ["84277.50", "5.435716"], ["84286.00", "5.163930"], ["84294.50", "4.982739"], ["84303.00", "4.620358"], ["84311.50", "4.892144"], ["84320.00", "4.257977"], ["84328.50", "4.529763"], ["84337.00", "5.616906"], ["84345.50", "4.076787"]], "bids": [["84073.00", "1.231020"], ["84071.80", "0.010807"], ["84069.80", "0.028439"], ["84067.80", "0.074838"], ["84065.80", "0.196943"], ["84063.80", "0.518272"], ["84061.80", "1.363872"], ["84059.80", "3.589137"], ["84057.80", "9.445099"], ["84056.70", "0.445560"], ["84055.90", "0.068010"], ["84053.50", "0.030000"], ["84052.00", "0.000032"], ["84045.90", "0.072990"], ["84015.80", "5.345120"], ["84007.30", "4.257977"], ["83998.80", "4.076787"], ["83990.30", "5.163930"], ["83981.80", "4.439168"], ["83973.30", "5.254525"], ["83964.80", "5.526311"], ["83956.30", "3.895596"], ["83947.80", "5.616906"], ["83939.30", "5.435716"], ["83930.80", "4.710954"], ["83922.30", "3.986192"], ["83913.80", "4.620358"], ["83905.30", "4.892144"], ["83896.80", "5.073335"], ["83879.80", "4.167382"], ["83871.30", "4.529763"], ["83862.80", "4.348573"], ["83854.30", "4.982739"], ["83664.71", "0"]], "checksum": 367590534, "ts": "1742554967648"}], "ts": 1742554967651, "record_time": 1742554967.675533, "EXCHANGE": "BITGET"}
{"action": "update", "arg": {"instType": "SPOT", "channel": "books", "instId": "BTCUSDT"}, "data": [{"asks": [["84085.05", "0.038539"], ["84088.79", "0"], ["84184.00", "4.076787"], ["84192.50", "4.892144"], ["84201.00", "5.345120"], ["84209.50", "4.348573"], ["84218.00", "5.526311"], ["84226.50", "5.073335"], ["84235.00", "5.616906"], ["84243.50", "3.895596"], ["84252.00", "5.435716"], ["84269.00", "4.710954"], ["84277.50", "4.620358"], ["84286.00", "4.529763"], ["84303.00", "5.163930"], ["84311.50", "4.439168"], ["84328.50", "5.254525"], ["84337.00", "4.801549"], ["84345.50", "4.167382"]], "bids": [["84056.81", "0.494073"], ["84054.60", "0.072150"], ["84045.90", "0"], ["84015.80", "4.348573"], ["84007.30", "5.073335"], ["83998.80", "5.254525"], ["83990.30", "4.439168"], ["83981.80", "4.076787"], ["83973.30", "4.710954"], ["83964.80", "4.529763"], ["83956.30", "5.345120"], ["83947.80", "4.620358"], ["83939.30", "5.616906"], ["83930.80", "4.982739"], ["83922.30", "3.895596"], ["83913.80", "4.257977"], ["83905.30", "4.801549"], ["83896.80", "5.435716"], ["83888.30", "4.167382"], ["83879.80", "3.986192"], ["83871.30", "5.163930"], ["83862.80", "4.892144"], ["83854.30", "5.526311"]], "checksum": 1331172974, "ts": "1742554967851"}], "ts": 1742554967854, "record_time": 1742554967.881271, "EXCHANGE": "BITGET"}
{"action": "update", "arg": {"instType": "SPOT", "channel": "books", "instId": "BTCUSDT"}, "data": [{"asks": [["84078.09", "0.086104"], ["84078.27", "0"], ["84121.86", "0.010000"], ["84124.00", "0.001125"], ["84126.00", "0.002960"], ["84128.00", "0.007788"], ["84130.00", "0.020497"], ["84132.00", "0.053939"], ["84134.00", "0.141944"], ["84136.00", "0.373538"], ["84138.00", "0.982993"], ["84140.00", "2.586824"], ["84142.00", "6.807433"], ["84184.00", "4.529763"], ["84192.50", "4.620358"], ["84201.00", "4.439168"], ["84209.50", "3.986192"], ["84218.00", "4.348573"], ["84226.50", "5.526311"], ["84235.00", "5.435716"], ["84252.00", "4.982739"], ["84260.50", "5.163930"], ["84269.00", "4.076787"], ["84277.50", "5.616906"], ["84286.00", "4.167382"], ["84294.50", "5.254525"], ["84303.00", "4.892144"], ["84311.50", "4.801549"], ["84320.00", "5.345120"], ["84328.50", "5.073335"], ["84337.00", "4.710954"], ["84345.50", "4.257977"], ["84525.82", "0"]], "bids": [["84073.00", "1.021820"], ["84065.80", "0.196910"], ["84063.80", "0.518184"], ["84061.80", "1.363641"], ["84059.80", "3.588530"], ["84057.80", "9.443499"], ["84046.00", "0.006134"], ["84023.00", "0"], ["84021.00", "0.000017"], ["84015.80", "5.073335"], ["84007.30", "4.167382"], ["83998.80", "4.348573"], ["83990.30", "4.620358"], ["83981.80", "4.710954"], ["83973.30", "5.616906"], ["83964.80", "3.895596"], ["83956.30", "5.435716"], ["83947.80", "4.439168"], ["83939.30", "5.163930"], ["83930.80", "3.986192"], ["83922.30", "4.801549"], ["83913.80", "5.345120"], ["83905.30", "4.529763"], ["83896.80", "4.892144"], ["83888.30", "4.982739"], ["83879.80", "5.526311"], ["83871.30", "4.076787"], ["83862.80", "4.257977"], ["83854.30", "5.254525"]], "checksum": -1575305782, "ts": "1742554968051"}], "ts": 1742554968054, "record_time": 1742554968.090399, "EXCHANGE": "BITGET"}
{"action": "update", "arg": {"instType": "SPOT", "channel": "books", "instId": "BTCUSDT"}, "data": [{"asks": [["84073.01", "1.146774"], ["84113.40", "0.102522"], ["84118.95", "0"], ["84126.00", "0.002596"], ["84128.00", "0.006831"], ["84130.00", "0.017976"], ["84132.00", "0.047307"], ["84134.00", "0.124492"], ["84136.00", "0.327610"], ["84138.00", "0.862130"], ["84140.00", "2.268764"], ["84142.00", "5.970433"], ["84184.00", "5.616906"], ["84201.00", "5.163930"], ["84209.50", "5.254525"], ["84218.00", "5.073335"], ["84226.50", "4.529763"], ["84235.00", "4.348573"], ["84243.50", "3.986192"], ["84252.00", "3.895596"], ["84260.50", "4.710954"], ["84269.00", "4.892144"], ["84277.50", "4.257977"], ["84286.00", "4.801549"], ["84294.50", "5.435716"], ["84303.00", "5.345120"], ["84311.50", "4.982739"], ["84320.00", "4.439168"], ["84328.50", "5.526311"], ["84337.00", "4.167382"], ["84345.50", "4.076787"], ["84525.82", "0.000099"]], "bids": [["84071.80", "0.009795"], ["84069.80", "0.025778"], ["84067.80", "0.067836"], ["84065.80", "0.178515"], ["84063.80", "0.469776"], ["84061.80", "1.236255"], ["84059.80", "3.253301"], ["84057.80", "8.561320"], ["84047.10", "0.012300"], ["84015.80", "4.529763"], ["84007.30", "3.986192"], ["83998.80", "5.345120"], ["83990.30", "4.982739"], ["83981.80", "3.895596"], ["83973.30", "4.710954"], ["83964.80", "4.892144"], ["83956.30", "4.076787"], ["83947.80", "5.616906"], ["83930.80", "5.254525"], ["83922.30", "5.526311"], ["83913.80", "5.073335"], ["83905.30", "5.435716"], ["83896.80", "4.348573"], ["83888.30", "4.167382"], ["83879.80", "4.257977"], ["83871.30", "4.620358"], ["83862.80", "4.801549"], ["83854.30", "4.439168"], ["83666.00", "0"]], "checksum": -1295588888, "ts": "1742554968263"}], "ts": 1742554968267, "record_time": 1742554968.288673, "EXCHANGE": "BITGET"}
{"action": "update", "arg": {"instType": "SPOT", "channel": "books", "instId": "BTCUSDT"}, "data": [{"asks": [["84077.90", "0.086104"], ["84078.09", "0"], ["84124.00", "0.001251"], ["84126.00", "0.003292"], ["84128.00", "0.008661"], ["84130.00", "0.022793"], ["84132.00", "0.059981"], ["84134.00", "0.157845"], ["84136.00", "0.415383"], ["84138.00", "1.093371"], ["84140.00", "2.877291"], ["84142.00", "7.571818"], ["84155.40", "0.120000"], ["84184.00", "4.529763"], ["84192.50", "5.073335"], ["84201.00", "5.345120"], ["84209.50", "4.167382"], ["84218.00", "5.616906"], ["84226.50", "5.254525"], ["84235.00", "5.526311"], ["84243.50", "4.348573"], ["84252.00", "4.892144"], ["84269.00", "4.620358"], ["84286.00", "3.895596"], ["84294.50", "4.801549"], ["84303.00", "4.076787"], ["84311.50", "3.986192"], ["84320.00", "4.982739"], ["84328.50", "4.439168"], ["84337.00", "5.435716"], ["84345.50", "5.163930"], ["84525.82", "0"]], "bids": [["84071.80", "0.008836"], ["84069.80", "0.023251"], ["84067.80", "0.061187"], ["84065.80", "0.161020"], ["84063.80", "0.423735"], ["84061.80", "1.115094"], ["84059.80", "2.934457"], ["84057.80", "7.722255"], ["84057.40", "0.001040"], ["84054.40", "0.022680"], ["84052.50", "1.525740"], ["84051.80", "0.069570"], ["84046.60", "1.189320"], ["84046.50", "0"], ["84015.80", "4.257977"], ["84007.30", "5.526311"], ["83998.80", "4.892144"], ["83990.30", "5.163930"], ["83981.80", "5.616906"], ["83973.30", "4.620358"], ["83964.80", "4.982739"], ["83956.30", "4.439168"], ["83947.80", "4.348573"], ["83939.30", "4.167382"], ["83930.80", "5.073335"], ["83922.30", "5.345120"], ["83913.80", "4.801549"], ["83905.30", "4.529763"], ["83896.80", "3.895596"], ["83888.30", "5.435716"], ["83879.80", "3.986192"], ["83871.30", "4.076787"], ["83862.80", "5.254525"], ["83854.30", "4.710954"], ["83666.65", "0"]], "checksum": -118920774, "ts": "1742554968463"}], "ts": 1742554968466, "record_time": 1742554968.490385, "EXCHANGE": "BITGET"}
{"action": "update", "arg": {"instType": "SPOT", "channel": "books", "instId": "BTCUSDT"}, "data": [{"asks": [["84117.63", "0.185359"], ["84128.00", "0.008868"], ["84130.00", "0.023337"], ["84132.00", "0.061415"], ["84134.00", "0.161618"], ["84136.00", "0.425310"], ["84138.00", "1.119493"], ["84140.00", "2.946034"], ["84142.00", "7.752722"], ["84146.70", "0.045540"], ["84149.40", "0"], ["84184.00", "3.986192"], ["84192.50", "4.348573"], ["84201.00", "5.073335"], ["84209.50", "4.529763"], ["84218.00", "4.892144"], ["84226.50", "4.167382"], ["84235.00", "4.257977"], ["84243.50", "5.345120"], ["84252.00", "5.163930"], ["84260.50", "5.435716"], ["84269.00", "5.254525"], ["84277.50", "4.439168"], ["84286.00", "5.616906"], ["84294.50", "4.620358"], ["84311.50", "4.710954"], ["84328.50", "5.526311"], ["84337.00", "4.801549"], ["84345.50", "3.895596"], ["84525.00", "0"]], "bids": [["84071.80", "0.007263"], ["84069.83", "0.031778"], ["84069.80", "0.018955"], ["84067.80", "0.049880"], ["84066.79", "0"], ["84065.80", "0.131263"], ["84063.80", "0.345430"], ["84063.50", "0"], ["84061.80", "0.909025"], ["84061.74", "1.152924"], ["84059.80", "2.392171"], ["84057.80", "6.295189"], ["84057.70", "0.041400"], ["84056.70", "1.164270"], ["84056.10", "2.355720"], ["84055.90", "0.067800"], ["84055.02", "0.027453"], ["84054.40", "0.068220"], ["84054.20", "0.071220"], ["84053.90", "0.067800"], ["84053.60", "0.468990"], ["84052.50", "1.525560"], ["84047.10", "0"], ["84046.70", "0"], ["84046.60", "0"], ["84022.00", "0.000015"], ["84021.00", "0.000032"], ["84015.80", "4.167382"], ["84007.30", "5.435716"], ["83998.80", "3.895596"], ["83990.30", "4.348573"], ["83981.80", "4.529763"], ["83973.30", "4.892144"], ["83964.80", "4.439168"], ["83956.30", "4.620358"], ["83947.80", "3.986192"], ["83939.30", "5.526311"], ["83930.80", "4.801549"], ["83922.30", "4.710954"], ["83913.80", "4.257977"], ["83905.30", "4.982739"], ["83896.80", "5.345120"], ["83888.30", "5.073335"], ["83879.80", "5.163930"], ["83862.80", "5.616906"], ["83854.30", "5.254525"], ["83666.65", "0.000122"], ["83666.00", "0.271427"]], "checksum": -1051698905, "ts": "1742554968688"}], "ts": 1742554968691, "record_time": 1742554968.714478, "EXCHANGE": "BITGET"}
{"action": "update", "arg": {"instType": "SPOT", "channel": "books", "instId": "BTCUSDT"}, "data": [{"asks": [["84073.01", "1.312987"], ["84085.05", "0"], ["84098.04", "0.035952"], ["84099.72", "0.035961"], ["84102.63", "0.006356"], ["84103.19", "0.006356"], ["84103.57", "0"], ["84105.25", "0"], ["84108.17", "0"], ["84108.72", "0"], ["84132.00", "0.061655"], ["84134.00", "0.162250"], ["84136.00", "0.426974"], ["84138.00", "1.123615"], ["84140.00", "2.956884"], ["84142.00", "7.781273"], ["84142.30", "1.132410"], ["84143.30", "0.599730"], ["84146.10", "0.067800"], ["84146.60", "0.450240"], ["84146.70", "0"], ["84147.40", "0.074370"], ["84148.10", "0.365790"], ["84153.20", "0.534660"], ["84155.60", "0.178200"], ["84184.00", "3.895596"], ["84192.50", "5.254525"], ["84201.00", "4.710954"], ["84209.50", "4.439168"], ["84218.00", "4.167382"], ["84226.50", "4.801549"], ["84235.00", "4.076787"], ["84243.50", "5.616906"], ["84252.00", "4.620358"], ["84260.50", "5.073335"], ["84269.00", "5.526311"], ["84277.50", "4.529763"], ["84286.00", "4.982739"], ["84294.50", "4.348573"], ["84303.00", "4.892144"], ["84311.50", "5.435716"], ["84320.00", "4.257977"], ["84328.50", "3.986192"], ["84337.00", "5.163930"], ["84345.50", "5.345120"], ["84524.83", "0"]], "bids": [["84073.00", "0.993640"], ["84071.80", "0.005866"], ["84069.83", "0"], ["84069.80", "0.015437"], ["84067.80", "0.040624"], ["84065.81", "0.190525"], ["84065.80", "0.106905"], ["84064.20", "0.028180"], ["84063.80", "0.281327"], ["84063.21", "0"], ["84061.80", "0.740336"], ["84061.53", "0"], ["84059.80", "1.948252"], ["84058.56", "0"], ["84058.10", "0"], ["84057.80", "5.126978"], ["84057.70", "0.001680"], ["84057.68", "0.089474"], ["84056.70", "0.425610"], ["84056.30", "0"], ["84056.10", "0"], ["84055.99", "0.083930"], ["84055.90", "0.068010"], ["84054.60", "0.269640"], ["84054.40", "0.022680"], ["84054.30", "0.062400"], ["84053.03", "0.007339"], ["84052.57", "0.007942"], ["84052.50", "1.047600"], ["84051.90", "0.113340"], ["84051.80", "0"], ["84050.80", "2.595660"], ["84050.70", "0"], ["84049.90", "0.067800"], ["84049.60", "0"], ["84049.30", "1.359000"], ["84047.10", "0.012300"], ["84046.70", "0.582150"], ["84046.60", "1.189320"], ["84015.80", "3.986192"], ["84007.30", "5.163930"], ["83998.80", "4.257977"], ["83990.30", "4.167382"], ["83981.80", "5.254525"], ["83973.30", "4.982739"], ["83964.80", "5.435716"], ["83947.80", "5.526311"], ["83939.30", "4.076787"], ["83930.80", "4.529763"], ["83913.80", "5.073335"], ["83905.30", "5.616906"], ["83888.30", "4.801549"], ["83879.80", "4.439168"], ["83871.30", "3.895596"], ["83862.80", "4.892144"], ["83854.30", "4.348573"]], "checksum": -2107526066, "ts": "1742554968890"}], "ts": 1742554968893, "record_time": 1742554968.915271, "EXCHANGE": "BITGET"}
{"action": "update", "arg": {"instType": "SPOT", "channel": "books", "instId": "BTCUSDT"}, "data": [{"asks": [["84077.72", "0.086104"], ["84077.90", "0"], ["84132.00", "0.061490"], ["84134.00", "0.161816"], ["84136.00", "0.425833"], ["84138.00", "1.120613"], ["84140.00", "2.948982"], ["84142.00", "7.760478"], ["84146.10", "0.113340"], ["84146.50", "0.458580"], ["84147.40", "0.074190"], ["84148.10", "0.067800"], ["84154.90", "4.178370"], ["84155.60", "0"], ["84184.00", "5.254525"], ["84192.50", "4.620358"], ["84201.00", "3.986192"], ["84209.50", "5.526311"], ["84218.00", "4.529763"], ["84226.50", "4.710954"], ["84235.00", "4.801549"], ["84243.50", "5.163930"], ["84252.00", "5.345120"], ["84260.50", "4.439168"], ["84269.00", "4.982739"], ["84277.50", "4.892144"], ["84286.00", "5.435716"], ["84303.00", "5.616906"], ["84311.50", "5.073335"], ["84320.00", "4.076787"], ["84328.50", "3.895596"], ["84337.00", "4.167382"], ["84345.50", "4.257977"]], "bids": [["84071.80", "0.006961"], ["84069.80", "0.018320"], ["84067.80", "0.048211"], ["84065.80", "0.126870"], ["84063.80", "0.333869"], ["84061.80", "0.878603"], ["84061.74", "0.718366"], ["84059.80", "2.312113"], ["84057.81", "0.280948"], ["84057.80", "6.084506"], ["84056.81", "0"], ["84056.70", "0.324030"], ["84052.50", "4.153200"], ["84051.70", "0"], ["84050.80", "0"], ["84048.30", "0"], ["84047.90", "0.187800"], ["84047.50", "0"], ["84047.10", "0.132300"], ["84046.60", "1.069320"], ["84015.80", "4.801549"], ["84007.30", "4.620358"], ["83998.80", "4.710954"], ["83990.30", "4.892144"], ["83981.80", "4.076787"], ["83973.30", "5.073335"], ["83964.80", "5.616906"], ["83956.30", "5.254525"], ["83947.80", "5.345120"], ["83939.30", "4.982739"], ["83930.80", "3.895596"], ["83922.30", "4.348573"], ["83913.80", "5.163930"], ["83905.30", "3.986192"], ["83896.80", "4.529763"], ["83888.30", "5.435716"], ["83879.80", "4.167382"], ["83871.30", "4.439168"], ["83862.80", "4.257977"], ["83854.30", "5.526311"], ["83664.71", "0.000071"], ["83664.19", "0.000073"], ["83663.98", "0.000008"], ["83663.95", "0.000022"]], "checksum": -2096828811, "ts": "1742554969106"}], "ts": 1742554969110, "record_time": 1742554969.132143, "EXCHANGE": "BITGET"}
{"action": "update", "arg": {"instType": "SPOT", "channel": "books", "instId": "BTCUSDT"}, "data": [{"asks": [["84134.00", "0.161821"], ["84136.00", "0.425844"], ["84138.00", "1.120643"], ["84140.00", "2.949059"], ["84142.00", "7.760683"], ["84146.10", "0.067800"], ["84147.60", "0.144540"], ["84184.00", "3.986192"], ["84192.50", "4.076787"], ["84201.00", "4.710954"], ["84209.50", "4.801549"], ["84226.50", "5.073335"], ["84235.00", "3.895596"], ["84243.50", "5.254525"], ["84252.00", "4.982739"], ["84260.50", "4.892144"], ["84269.00", "4.439168"], ["84277.50", "5.526311"], ["84286.00", "4.348573"], ["84294.50", "5.345120"], ["84303.00", "4.257977"], ["84311.50", "4.620358"], ["84320.00", "5.616906"], ["84328.50", "4.167382"], ["84337.00", "5.163930"], ["84345.50", "5.435716"], ["84524.00", "0"]], "bids": [["84061.81", "1.105868"], ["84061.74", "0"], ["84057.81", "1.138294"], ["84054.21", "0"], ["84052.50", "4.152780"], ["84052.10", "0.144540"], ["84051.90", "0.067800"], ["84023.00", "0.000017"], ["84022.00", "0"], ["84015.80", "5.435716"], ["84007.30", "4.982739"], ["83998.80", "5.345120"], ["83990.30", "5.073335"], ["83981.80", "4.892144"], ["83973.30", "5.616906"], ["83964.80", "3.986192"], ["83956.30", "5.526311"], ["83947.80", "4.348573"], ["83939.30", "4.257977"], ["83930.80", "4.529763"], ["83922.30", "4.076787"], ["83905.30", "4.710954"], ["83896.80", "3.895596"], ["83888.30", "4.801549"], ["83871.30", "5.254525"], ["83862.80", "4.439168"], ["83854.30", "4.620358"]], "checksum": -2096828811, "ts": "1742554969314"}], "ts": 1742554969317, "record_time": 1742554969.340836, "EXCHANGE": "BITGET"}
{"action": "update", "arg": {"instType": "SPOT", "channel": "books", "instId": "BTCUSDT"}, "data": [{"asks": [["84077.56", "0.086104"], ["84077.72", "0"], ["84150.20", "0.015000"], ["84155.40", "0"], ["84184.00", "4.801549"], ["84192.50", "4.348573"], ["84201.00", "4.529763"], ["84209.50", "5.163930"], ["84218.00", "5.526311"], ["84226.50", "4.076787"], ["84243.50", "5.616906"], ["84252.00", "5.254525"], ["84269.00", "4.710954"], ["84277.50", "3.986192"], ["84286.00", "4.167382"], ["84303.00", "5.073335"], ["84311.50", "4.257977"], ["84320.00", "4.439168"], ["84328.50", "4.620358"], ["84337.00", "4.982739"]], "bids": [["84072.58", "0.010000"], ["84065.80", "0.127042"], ["84063.80", "0.334320"], ["84061.80", "0.879790"], ["84059.80", "2.315236"], ["84057.80", "6.092728"], ["84053.50", "0.015000"], ["84015.80", "5.254525"], ["84007.30", "4.892144"], ["83998.80", "3.895596"], ["83990.30", "4.076787"], ["83981.80", "4.710954"], ["83973.30", "4.439168"], ["83964.80", "5.163930"], ["83956.30", "5.073335"], ["83947.80", "3.986192"], ["83930.80", "5.345120"], ["83922.30", "5.526311"], ["83913.80", "5.435716"], ["83905.30", "4.801549"], ["83896.80", "4.529763"], ["83888.30", "5.616906"], ["83879.80", "4.348573"], ["83871.30", "4.620358"], ["83862.80", "4.982739"], ["83854.30", "4.167382"], ["83663.95", "0"]], "checksum": 528867753, "ts": "1742554969515"}], "ts": 1742554969522, "record_time": 1742554969.553069, "EXCHANGE": "BITGET"}
{"action": "update", "arg": {"instType": "SPOT", "channel": "books", "instId": "BTCUSDT"}, "data": [{"asks": [["84126.00", "0.003393"], ["84130.00", "0.023500"], ["84132.00", "0.061843"], ["84134.00", "0.162743"], ["84136.00", "0.428271"], ["84138.00", "1.127030"], ["84140.00", "2.965867"], ["84142.00", "7.804913"], ["84184.00", "4.257977"], ["84192.50", "5.073335"], ["84201.00", "5.435716"], ["84209.50", "4.076787"], ["84218.00", "4.439168"], ["84226.50", "4.710954"], ["84235.00", "4.529763"], ["84243.50", "5.254525"], ["84252.00", "4.982739"], ["84260.50", "5.345120"], ["84269.00", "3.986192"], ["84277.50", "5.163930"], ["84286.00", "4.620358"], ["84294.50", "4.348573"], ["84303.00", "4.167382"], ["84311.50", "4.892144"], ["84320.00", "5.616906"], ["84328.50", "5.526311"], ["84337.00", "3.895596"], ["84345.50", "4.801549"]], "bids": [["84054.90", "0.012000"], ["84053.60", "0.541530"], ["84053.50", "0"], ["84015.80", "4.710954"], ["84007.30", "5.163930"], ["83998.80", "4.439168"], ["83994.90", "0"], ["83990.30", "4.620358"], ["83981.80", "3.895596"], ["83973.30", "5.345120"], ["83964.80", "4.801549"], ["83956.30", "5.526311"], ["83947.80", "4.167382"], ["83939.30", "5.254525"], ["83930.80", "4.982739"], ["83922.30", "4.076787"], ["83913.80", "4.257977"], ["83905.30", "4.892144"], ["83896.80", "3.986192"], ["83888.30", "4.348573"], ["83879.80", "5.435716"], ["83871.30", "5.616906"], ["83862.80", "5.073335"], ["83854.30", "4.529763"], ["83663.95", "0.000022"]], "checksum": 528867753, "ts": "1742554969723"}], "ts": 1742554969730, "record_time": 1742554969.752875, "EXCHANGE": "BITGET"}
{"action": "update", "arg": {"instType": "SPOT", "channel": "books", "instId": "BTCUSDT"}, "data": [{"asks": [["84073.01", "1.103787"], ["84124.00", "0.001144"], ["84126.00", "0.003010"], ["84128.00", "0.007922"], ["84130.00", "0.020847"], ["84132.00", "0.054860"], ["84134.00", "0.144368"], ["84136.00", "0.379916"], ["84138.00", "0.999780"], ["84140.00", "2.630999"], ["84142.00", "6.923683"], ["84142.10", "0.002790"], ["84154.90", "3.173400"], ["84184.00", "4.710954"], ["84192.50", "5.345120"], ["84201.00", "5.526311"], ["84209.50", "4.167382"], ["84218.00", "4.076787"], ["84226.50", "5.435716"], ["84235.00", "3.986192"], ["84243.50", "4.801549"], ["84252.00", "5.163930"], ["84260.50", "4.257977"], ["84269.00", "4.892144"], ["84277.50", "4.348573"], ["84286.00", "4.439168"], ["84294.50", "4.529763"], ["84303.00", "5.254525"], ["84311.50", "4.982739"], ["84328.50", "5.073335"], ["84337.00", "4.620358"], ["84345.50", "3.895596"]], "bids": [["84073.00", "1.202840"], ["84071.80", "0.007362"], ["84069.81", "0.026406"], ["84069.80", "0.019374"], ["84067.80", "0.050984"], ["84065.80", "0.134167"], ["84063.80", "0.353072"], ["84061.80", "0.929137"], ["84059.80", "2.445097"], ["84057.80", "6.434465"], ["84056.70", "1.001970"], ["84055.50", "2.355720"], ["84054.30", "0.062190"], ["84052.50", "1.120200"], ["84036.80", "0.000396"], ["84024.30", "0"], ["84023.00", "0.000032"], ["84015.80", "3.986192"], ["84007.40", "0.000948"], ["84007.30", "4.076787"], ["83998.80", "4.167382"], ["83990.30", "5.163930"], ["83981.80", "4.439168"], ["83973.30", "4.710954"], ["83964.80", "4.982739"], ["83947.80", "4.257977"], ["83939.30", "4.348573"], ["83930.80", "5.254525"], ["83922.30", "5.435716"], ["83913.80", "4.892144"], ["83905.30", "5.073335"], ["83896.80", "4.529763"], ["83888.30", "5.345120"], ["83879.80", "3.895596"], ["83862.80", "4.801549"], ["83854.30", "4.620358"], ["83664.19", "0"], ["83663.98", "0"], ["83663.95", "0"]], "checksum": -310347899, "ts": "1742554969927"}], "ts": 1742554969930, "record_time": 1742554969.953481, "EXCHANGE": "BITGET"}
{"event": "subscribe", "arg": {"instType": "SPOT", "channel": "books", "instId": "BTCUSDT"}, "record_time": 1742555025.330872, "EXCHANGE": "BITGET"}
