{"exchange": "BITGET", "timestamp": 1742560342.175945, "message": {"action": "update", "arg": {"instType": "SPOT", "channel": "books", "instId": "BTCUSDT"}, "data": [{"asks": [["84174.00", "0.750428"], ["84174.01", "0.001043"], ["84174.02", "0.000100"], ["84174.03", "0.000100"], ["84174.84", "0.095065"], ["84177.01", "0.014281"], ["84177.39", "0.054775"], ["84189.40", "0.059306"], ["84190.16", "0"], ["84190.36", "0"], ["84191.90", "0"], ["84192.15", "0"], ["84192.23", "0"], ["84193.97", "0"], ["84194.73", "0"], ["84195.02", "0"], ["84195.52", "0"], ["84195.67", "0.119870"], ["84195.79", "0"], ["84196.02", "0.035952"], ["84196.63", "0"], ["84196.71", "0"], ["84196.76", "0"], ["84197.15", "0.006356"], ["84197.48", "0.035961"], ["84197.55", "0"], ["84197.98", "0.006356"], ["84198.19", "0"], ["84198.26", "0.006356"], ["84198.55", "0.016429"], ["84198.87", "0.006356"], ["84199.18", "0.119883"], ["84199.35", "0.006356"], ["84199.56", "0.006356"], ["84199.84", "0.010984"], ["84201.01", "0.006356"], ["84201.02", "0"], ["84201.13", "0.006356"], ["84202.75", "0.013405"], ["84203.00", "0"], ["84203.05", "0.006357"], ["84203.15", "0.010985"], ["84203.82", "0.009990"], ["84204.17", "0.015895"], ["84204.71", "0.119850"], ["84205.19", "0.119858"], ["84205.97", "0.119867"], ["84206.60", "0.009989"], ["84209.55", "0.015892"], ["84210.95", "0.010988"], ["84212.40", "0"], ["84214.40", "0"], ["84215.30", "0.001014"], ["84216.40", "0"], ["84217.30", "0.001023"], ["84218.40", "0"], ["84219.30", "0.001559"], ["84220.40", "0"], ["84221.30", "0.004342"], ["84222.40", "0"], ["84222.59", "0.712397"], ["84223.30", "0.011428"], ["84223.84", "0.061108"], ["84224.40", "0"], ["84225.30", "0.030072"], ["84226.40", "0"], ["84227.30", "0.079138"], ["84228.40", "0"], ["84229.30", "0.208257"], ["84230.40", "0"], ["84231.30", "0.548046"], ["84232.40", "0"], ["84232.80", "0"], ["84232.90", "0"], ["84233.30", "1.442225"], ["84234.50", "0"], ["84235.30", "3.795330"], ["84235.40", "0.001032"], ["84235.50", "0.501780"], ["84236.10", "0"], ["84236.60", "0.070860"], ["84236.70", "0.893940"], ["84236.90", "0"], ["84238.20", "0"], ["84238.90", "0"], ["84239.00", "0"], ["84239.40", "0"], ["84240.60", "0"], ["84241.40", "0"], ["84241.90", "0"], ["84242.10", "15.072750"], ["84242.30", "0"], ["84242.40", "0"], ["84242.60", "0"], ["84243.10", "0"], ["84244.80", "0.071760"], ["84245.80", "0.021600"], ["84246.10", "0.177990"], ["84246.70", "0.180000"], ["84246.80", "0.240000"], ["84247.50", "1.068450"], ["84247.70", "2.670270"], ["84247.80", "1.350000"], ["84248.10", "0.120000"], ["84248.40", "0.015210"], ["84274.50", "0"], ["84277.40", "4.524746"], ["84283.00", "0"], ["84285.90", "4.072271"], ["84291.50", "0"], ["84294.40", "4.343756"], ["84300.00", "0.002000"], ["84302.90", "5.339200"], ["84308.50", "0"], ["84311.40", "4.615240"], ["84317.00", "0"], ["84319.90", "4.253261"], ["84325.50", "0"], ["84328.40", "5.067715"], ["84334.00", "0"], ["84336.90", "5.429695"], ["84342.50", "0"], ["84345.40", "5.248705"], ["84351.00", "0"], ["84353.90", "4.886725"], ["84359.50", "0"], ["84362.40", "4.796230"], ["84368.00", "0"], ["84370.90", "5.158210"], ["84376.50", "0"], ["84379.40", "4.162766"], ["84385.00", "0"], ["84387.90", "5.610684"], ["84393.50", "0"], ["84396.40", "4.705735"], ["84402.00", "0"], ["84404.90", "3.891281"], ["84410.50", "0"], ["84413.40", "5.520189"], ["84419.00", "0"], ["84421.90", "4.977220"], ["84427.50", "0"], ["84430.40", "3.981776"], ["84436.00", "0"], ["84438.90", "4.434251"], ["84570.51", "0"], ["84570.99", "0"], ["84571.43", "0"], ["84571.75", "0"], ["84571.82", "0"], ["84572.75", "0"], ["84573.59", "0"], ["84573.83", "0"], ["84574.00", "0"], ["84574.47", "0"]], "bids": [["84173.99", "0.984423"], ["84171.00", "0.001030"], ["84169.00", "0.001398"], ["84168.10", "0"], ["84167.81", "0.005592"], ["84167.29", "0.009720"], ["84167.00", "0.003933"], ["84166.10", "0"], ["84165.00", "0.010352"], ["84164.10", "0"], ["84163.05", "0.005575"], ["84163.00", "0.027240"], ["84162.10", "0"], ["84161.00", "0.071685"], ["84160.10", "0"], ["84159.00", "0.188646"], ["84158.10", "0"], ["84157.00", "0.496435"], ["84156.77", "0"], ["84156.10", "0"], ["84155.61", "0.089367"], ["84155.00", "1.306409"], ["84154.42", "0.247262"], ["84154.10", "0"], ["84153.70", "0.083830"], ["84153.36", "0.017794"], ["84153.31", "0.018231"], ["84153.00", "3.437917"], ["84152.10", "0"], ["84152.02", "0.055583"], ["84151.04", "0.017081"], ["84151.00", "9.047152"], ["84150.84", "0.004012"], ["84150.45", "0.008982"], ["84150.10", "0"], ["84150.00", "0.025151"], ["84149.90", "0.085860"], ["84149.75", "0"], ["84149.33", "0.017328"], ["84149.10", "0.552060"], ["84148.89", "0.028827"], ["84148.88", "2.994326"], ["84148.75", "0"], ["84148.49", "0.007122"], ["84148.46", "0"], ["84148.43", "0.051895"], ["84148.33", "0.012639"], ["84148.19", "0.007932"], ["84148.11", "1.034160"], ["84148.10", "1.873110"], ["84148.00", "0.006060"], ["84147.90", "0.084600"], ["84147.83", "0.224587"], ["84147.42", "0.018493"], ["84147.40", "0"], ["84147.29", "0"], ["84147.21", "0.008589"], ["84147.20", "0.073530"], ["84147.10", "0"], ["84146.46", "0.268024"], ["84146.16", "0"], ["84145.90", "0.107430"], ["84145.70", "0.293790"], ["84145.60", "0.356310"], ["84145.55", "0"], ["84145.36", "0.259454"], ["84145.16", "0.021102"], ["84144.92", "0.222377"], ["84144.70", "0.008174"], ["84144.35", "0"], ["84144.30", "0"], ["84143.84", "0"], ["84143.10", "0"], ["84143.06", "0.076012"], ["84142.90", "0.356280"], ["84142.44", "0"], ["84142.20", "0.420000"], ["84141.80", "0.249390"], ["84141.08", "0"], ["84141.00", "1.350000"], ["84140.70", "0"], ["84140.52", "0.073119"], ["84140.32", "0"], ["84140.24", "0.056293"], ["84140.02", "0"], ["84138.51", "0"], ["84138.50", "0.045000"], ["84138.20", "2.189160"], ["84137.90", "0"], ["84137.80", "0"], ["84137.70", "0"], ["84136.95", "0"], ["84136.74", "0"], ["84136.60", "0"], ["84136.40", "0"], ["84136.00", "0.000032"], ["84135.90", "0"], ["84135.50", "0"], ["84135.30", "0"], ["84135.20", "0"], ["84134.60", "0"], ["84134.59", "0"], ["84134.40", "0"], ["84132.30", "0"], ["84132.01", "0"], ["84131.00", "0.000428"], ["84123.40", "0.008565"], ["84122.88", "0"], ["84112.40", "0.208446"], ["84108.90", "5.339200"], ["84106.00", "0.000032"], ["84101.50", "0.000948"], ["84100.40", "4.162766"], ["84097.51", "0"], ["84097.50", "0"], ["84093.00", "0.000032"], ["84091.90", "5.158210"], ["84089.00", "0"], ["84083.40", "5.520189"], ["84080.50", "0"], ["84074.90", "3.891281"], ["84072.00", "0"], ["84066.40", "4.253261"], ["84063.50", "0"], ["84057.90", "4.524746"], ["84055.00", "0"], ["84049.40", "5.248705"], ["84046.50", "0"], ["84040.90", "5.067715"], ["84038.00", "0"], ["84032.40", "4.343756"], ["84029.50", "0"], ["84023.90", "4.072271"], ["84021.00", "0"], ["84015.40", "5.610684"], ["84012.50", "0"], ["84006.90", "4.886725"], ["84004.00", "0"], ["83998.40", "3.981776"], ["83995.50", "0"], ["83989.90", "4.434251"], ["83987.00", "0"], ["83981.40", "4.705735"], ["83978.50", "0"], ["83972.90", "4.796230"], ["83970.00", "0.002282"], ["83964.40", "5.429695"], ["83961.50", "0"], ["83955.90", "4.615240"], ["83953.00", "0"], ["83947.40", "4.977220"], ["83944.50", "0"], ["83690.48", "0"], ["83690.00", "0"], ["83689.78", "0"], ["83689.50", "0"], ["83688.89", "0"], ["83688.07", "0"], ["83687.50", "0"]], "checksum": -120570405, "ts": "1742560342144"}], "ts": 1742560342147}}
{"exchange": "BYBIT", "timestamp": 1742560342.340631, "message": {"topic": "orderbook.200.BTCUSDT", "ts": 1742560342320, "type": "delta", "data": {"s": "BTCUSDT", "b": [["84199", "0.992291"], ["84198.1", "0.221476"], ["84187.8", "0.136648"], ["84158", "0.048782"], ["84153.2", "19.501268"], ["84152.3", "0.135565"], ["84125.1", "0"], ["84125", "0"]], "a": [["84215.4", "0.002067"], ["84217", "0.04"], ["84217.9", "0.001277"], ["84218.6", "0.04"], ["84218.7", "0.055818"], ["84219", "0"], ["84220.3", "0.04"], ["84220.5", "0.043833"], ["84222.2", "0.085373"], ["84223.7", "0.04"], ["84257.6", "2.562085"], ["84263.3", "0"], ["84270.4", "0.089075"], ["84271.6", "0.171"], ["84273.1", "0"], ["84273.2", "0"], ["84274.2", "0"], ["84274.5", "0"], ["84275.5", "0"]], "u": 45300, "seq": 67552587389}, "cts": 1742560342315}}
{"exchange": "BITGET", "timestamp": 1742560342.408477, "message": {"action": "update", "arg": {"instType": "SPOT", "channel": "books", "instId": "BTCUSDT"}, "data": [{"asks": [["84174.00", "0.941806"], ["84177.01", "0.028928"], ["84189.40", "0"], ["84221.30", "0.003938"], ["84223.30", "0.010363"], ["84225.30", "0.027273"], ["84227.30", "0.071771"], ["84229.30", "0.188870"], ["84231.30", "0.497025"], ["84233.30", "1.307962"], ["84235.30", "3.442004"], ["84236.60", "0.351300"], ["84236.70", "0.893730"], ["84239.00", "0.069030"], ["84241.30", "0"], ["84243.20", "2.352630"], ["84246.50", "0.178110"], ["84247.50", "1.068090"], ["84247.80", "0"], ["84248.10", "0"], ["84248.40", "0"], ["84277.40", "5.067715"], ["84285.90", "4.524746"], ["84294.40", "5.248705"], ["84302.90", "4.796230"], ["84311.40", "4.162766"], ["84319.90", "4.434251"], ["84328.40", "5.158210"], ["84336.90", "4.253261"], ["84345.40", "4.977220"], ["84353.90", "5.610684"], ["84362.40", "5.339200"], ["84370.90", "5.520189"], ["84379.40", "4.615240"], ["84387.90", "4.343756"], ["84396.40", "3.981776"], ["84404.90", "4.886725"], ["84413.40", "5.429695"], ["84421.90", "3.891281"], ["84430.40", "4.072271"], ["84438.90", "4.705735"], ["84570.51", "0.000170"], ["84570.99", "0.000053"]], "bids": [["84173.99", "1.006018"], ["84167.82", "0.005774"], ["84159.00", "0.188858"], ["84157.00", "0.496993"], ["84155.00", "1.307878"], ["84153.00", "3.441784"], ["84151.00", "9.057326"], ["84149.10", "0.752040"], ["84148.10", "1.835700"], ["84145.60", "0.548310"], ["84144.80", "0.180000"], ["84143.80", "0.132000"], ["84141.40", "0.120000"], ["84139.80", "0.120000"], ["84139.70", "0.129000"], ["84138.60", "0"], ["84138.50", "0"], ["84138.40", "0"], ["84138.20", "0"], ["84108.90", "5.520189"], ["84100.40", "4.615240"], ["84091.90", "4.886725"], ["84083.40", "5.429695"], ["84074.90", "3.981776"], ["84066.40", "5.339200"], ["84049.40", "3.891281"], ["84040.90", "4.343756"], ["84032.40", "4.434251"], ["84023.90", "4.253261"], ["84006.90", "4.072271"], ["83998.40", "5.248705"], ["83989.90", "5.158210"], ["83972.90", "5.067715"], ["83964.40", "4.796230"], ["83955.90", "4.162766"], ["83690.84", "0"]], "checksum": 1860929549, "ts": "1742560342380"}], "ts": 1742560342383}}
{"exchange": "BYBIT", "timestamp": 1742560342.556373, "message": {"topic": "orderbook.200.BTCUSDT", "ts": 1742560342520, "type": "delta", "data": {"s": "BTCUSDT", "b": [["84188.1", "0.023829"], ["84162.2", "0.0828"], ["84155.5", "0.05"], ["84155.4", "0.049551"], ["84152.8", "0.172466"], ["84152.7", "0"], ["84152.3", "0.135557"], ["84126.3", "0"], ["84125.8", "0"]], "a": [["84199.1", "0.075728"], ["84205.2", "0.071288"], ["84206.4", "0"], ["84206.9", "0.003617"], ["84207.5", "0.015"], ["84210", "0.021721"], ["84211.5", "0"], ["84222", "0.04"], ["84222.6", "0.056978"], ["84239.9", "0.122859"], ["84242.7", "0"], ["84251.6", "0.024745"], ["84270.6", "0.164704"]], "u": 45301, "seq": 67552587470}, "cts": 1742560342516}}
{"exchange": "BITGET", "timestamp": 1742560342.664743, "message": {"action": "update", "arg": {"instType": "SPOT", "channel": "books", "instId": "BTCUSDT"}, "data": [{"asks": [["84174.00", "0.965525"], ["84174.01", "0.000550"], ["84174.81", "0.095065"], ["84174.84", "0"], ["84187.81", "0.009401"], ["84236.60", "0.321300"], ["84236.70", "0.893940"], ["84239.40", "0.030000"], ["84277.40", "5.158210"], ["84285.90", "3.891281"], ["84294.40", "4.162766"], ["84302.90", "3.981776"], ["84311.40", "4.705735"], ["84319.90", "4.796230"], ["84328.40", "5.610684"], ["84336.90", "5.248705"], ["84345.40", "4.886725"], ["84353.90", "4.977220"], ["84362.40", "4.615240"], ["84370.90", "5.067715"], ["84379.40", "5.520189"], ["84387.90", "4.524746"], ["84396.40", "4.253261"], ["84404.90", "5.429695"], ["84413.40", "5.339200"], ["84421.90", "4.434251"], ["84430.40", "4.343756"], ["84438.90", "4.072271"], ["84570.51", "0"], ["84570.99", "0"]], "bids": [["84161.02", "0.103838"], ["84145.70", "0.443700"], ["84143.90", "0.228600"], ["84140.60", "0.547290"], ["84139.70", "0.120000"], ["84139.40", "0"], ["84123.00", "0.000015"], ["84122.00", "0.000015"], ["84121.00", "0.000015"], ["84120.00", "0.002028"], ["84119.00", "0.000015"], ["84118.00", "0.000015"], ["84117.00", "0.000015"], ["84116.00", "0.000015"], ["84115.00", "0.000015"], ["84114.00", "0.000015"], ["84113.00", "0.000015"], ["84112.00", "0.000015"], ["84111.00", "0.000015"], ["84110.00", "0.000028"], ["84109.00", "0.000015"], ["84108.90", "4.705735"], ["84108.00", "0.000015"], ["84107.00", "0.000015"], ["84106.00", "0.000015"], ["84105.00", "0.000015"], ["84104.00", "0.000015"], ["84103.00", "0.000015"], ["84102.00", "0.000015"], ["84101.00", "0.000015"], ["84100.40", "3.891281"], ["84100.00", "0.000028"], ["84099.00", "0.000015"], ["84098.00", "0.000015"], ["84097.00", "0.000015"], ["84096.00", "0.000015"], ["84095.00", "0.000015"], ["84093.00", "0.000015"], ["84091.90", "5.339200"], ["84083.40", "5.067715"], ["84074.90", "5.520189"], ["84066.40", "4.162766"], ["84057.90", "4.072271"], ["84049.40", "4.796230"], ["84040.90", "5.610684"], ["84032.40", "4.253261"], ["84023.90", "4.434251"], ["84015.40", "4.977220"], ["84006.90", "3.981776"], ["83998.40", "4.343756"], ["83989.90", "5.429695"], ["83981.40", "5.248705"], ["83972.90", "4.886725"], ["83964.40", "4.615240"], ["83955.90", "4.524746"], ["83947.40", "5.158210"], ["83690.84", "0.000162"]], "checksum": -1495519809, "ts": "1742560342588"}], "ts": 1742560342618}}
{"exchange": "BYBIT", "timestamp": 1742560342.742873, "message": {"topic": "orderbook.200.BTCUSDT", "ts": 1742560342720, "type": "delta", "data": {"s": "BTCUSDT", "b": [["84199", "0.998432"], ["84187.7", "0.049876"], ["84155.5", "0"], ["84155.3", "0.051151"], ["84126.3", "0.003564"]], "a": [["84206.9", "0"], ["84214.5", "0.003975"], ["84218.7", "0.083879"], ["84222.1", "0.035638"], ["84222.2", "0.084644"], ["84240.3", "0.178149"], ["84272.4", "0"]], "u": 45302, "seq": 67552587539}, "cts": 1742560342715}}
{"exchange": "BITGET", "timestamp": 1742560342.826036, "message": {"action": "update", "arg": {"instType": "SPOT", "channel": "books", "instId": "BTCUSDT"}, "data": [{"asks": [["84210.45", "0.827916"], ["84277.40", "3.891281"], ["84285.90", "4.615240"], ["84294.40", "5.520189"], ["84302.90", "4.524746"], ["84311.40", "4.796230"], ["84319.90", "5.067715"], ["84328.40", "4.886725"], ["84336.90", "4.977220"], ["84345.40", "4.705735"], ["84353.90", "4.162766"], ["84362.40", "4.343756"], ["84370.90", "4.434251"], ["84379.40", "3.981776"], ["84387.90", "5.429695"], ["84396.40", "4.072271"], ["84404.90", "4.253261"], ["84413.40", "5.248705"], ["84421.90", "5.158210"], ["84430.40", "5.610684"], ["84438.90", "5.339200"], ["84527.03", "0"], ["84529.89", "1.675616"]], "bids": [["84169.00", "0.001500"], ["84161.00", "0.071947"], ["84159.00", "0.189333"], ["84157.28", "0.696563"], ["84157.00", "0.498246"], ["84155.00", "1.311174"], ["84153.00", "3.450456"], ["84151.00", "9.080148"], ["84148.11", "0.570420"], ["84108.90", "5.520189"], ["84100.40", "3.981776"], ["84091.90", "4.796230"], ["84083.40", "4.253261"], ["84074.90", "5.158210"], ["84066.40", "4.615240"], ["84057.90", "5.339200"], ["84049.40", "4.343756"], ["84040.90", "4.434251"], ["84032.40", "4.886725"], ["84023.90", "5.248705"], ["84015.40", "4.705735"], ["84006.90", "5.429695"], ["83998.40", "4.072271"], ["83989.90", "5.067715"], ["83981.40", "3.891281"], ["83972.90", "4.524746"], ["83964.40", "4.977220"], ["83955.90", "5.610684"], ["83947.40", "4.162766"], ["83856.34", "1.642383"], ["83853.50", "0"]], "checksum": 324330301, "ts": "1742560342793"}], "ts": 1742560342799}}
{"exchange": "BYBIT", "timestamp": 1742560342.939845, "message": {"topic": "orderbook.200.BTCUSDT", "ts": 1742560342920, "type": "delta", "data": {"s": "BTCUSDT", "b": [["84192.5", "0"], ["84159.3", "0.013"], ["84159.2", "0.012882"], ["84156.7", "0"], ["84156.6", "0.000518"], ["84152.3", "0.135578"]], "a": [["84205.2", "0"], ["84207.2", "0.071287"], ["84209.7", "0.071284"], ["84210", "0.045398"], ["84218.5", "0.118793"], ["84237.7", "0.018938"], ["84237.8", "0.012988"], ["84237.9", "0.000615"], ["84238", "0"], ["84272.1", "0"], ["84272.3", "0"]], "u": 45303, "seq": 67552587597}, "cts": 1742560342891}}
{"exchange": "BITGET", "timestamp": 1742560343.080519, "message": {"action": "update", "arg": {"instType": "SPOT", "channel": "books", "instId": "BTCUSDT"}, "data": [{"asks": [["84203.79", "0"], ["84235.90", "0.964110"], ["84236.60", "0.040860"], ["84236.70", "0"], ["84247.80", "1.350000"], ["84277.40", "5.429695"], ["84285.90", "3.891281"], ["84294.40", "3.981776"], ["84319.90", "5.520189"], ["84328.40", "4.072271"], ["84336.90", "4.343756"], ["84345.40", "5.248705"], ["84353.90", "5.067715"], ["84362.40", "4.705735"], ["84379.40", "5.339200"], ["84387.90", "4.886725"], ["84396.40", "4.162766"], ["84404.90", "4.615240"], ["84413.40", "4.253261"], ["84421.90", "5.610684"], ["84430.40", "4.977220"], ["84438.90", "5.158210"]], "bids": [["84108.90", "4.524746"], ["84100.40", "5.610684"], ["84091.90", "4.343756"], ["84083.40", "5.520189"], ["84074.90", "4.886725"], ["84066.40", "4.977220"], ["84057.90", "4.434251"], ["84049.40", "4.162766"], ["84040.90", "4.705735"], ["84032.40", "4.072271"], ["84023.90", "3.891281"], ["84015.40", "5.429695"], ["84006.90", "3.981776"], ["83998.40", "5.248705"], ["83989.90", "4.615240"], ["83981.40", "4.253261"], ["83972.90", "5.339200"], ["83964.40", "4.796230"], ["83955.90", "5.158210"], ["83947.40", "5.067715"]], "checksum": 324330301, "ts": "1742560343001"}], "ts": 1742560343005}}
{"exchange": "BYBIT", "timestamp": 1742560343.140136, "message": {"topic": "orderbook.200.BTCUSDT", "ts": 1742560343120, "type": "delta", "data": {"s": "BTCUSDT", "b": [["84184.5", "0.062107"], ["84177.5", "0.055917"], ["84170.5", "0.124818"], ["84160.4", "0.04"], ["84160.3", "0.039636"], ["84159.4", "0.013333"], ["84159.3", "0.012882"], ["84159.2", "0"], ["84157.7", "0"], ["84157.6", "0"], ["84155.5", "0.05"], ["84155.3", "0.0016"], ["84127.1", "0"], ["84126.3", "0"]], "a": [["84199.1", "0.077328"], ["84218.4", "0.1493"], ["84218.7", "0"], ["84219.5", "0.060183"], ["84221.8", "0"], ["84222.1", "0.078816"], ["84222.2", "0.041466"], ["84226.5", "0.058175"], ["84233.5", "0.120352"], ["84237.6", "0.184"], ["84237.7", "0.018926"], ["84237.8", "0"], ["84238.6", "0.04"], ["84238.7", "0.041333"], ["84238.9", "0"], ["84239", "0"], ["84240.3", "0"], ["84254.8", "2.562085"], ["84257.6", "0"], ["84272.1", "0.003292"], ["84272.3", "0.05728"]], "u": 45304, "seq": 67552587687}, "cts": 1742560343096}}
{"exchange": "BITGET", "timestamp": 1742560343.233256, "message": {"action": "update", "arg": {"instType": "SPOT", "channel": "books", "instId": "BTCUSDT"}, "data": [{"asks": [["84174.78", "0.095065"], ["84174.81", "0"], ["84177.39", "0"], ["84235.50", "0.999570"], ["84236.60", "0"], ["84237.30", "0.248820"], ["84239.00", "0.135060"], ["84242.00", "0.052110"], ["84243.20", "0"], ["84246.81", "0"], ["84247.80", "0"], ["84257.15", "0"], ["84277.40", "4.886725"], ["84285.90", "5.339200"], ["84294.40", "4.705735"], ["84302.90", "4.434251"], ["84311.40", "5.610684"], ["84319.90", "4.343756"], ["84328.40", "4.615240"], ["84336.90", "5.248705"], ["84345.40", "4.162766"], ["84353.90", "3.981776"], ["84362.40", "4.072271"], ["84370.90", "3.891281"], ["84379.40", "5.067715"], ["84387.90", "4.796230"], ["84396.40", "4.977220"], ["84404.90", "5.429695"], ["84413.40", "5.158210"], ["84421.90", "4.253261"], ["84430.40", "4.524746"], ["84438.90", "5.520189"], ["84570.51", "0.000170"], ["84570.99", "0.000053"], ["84571.43", "0.000124"], ["84571.75", "0.001273"]], "bids": [["84173.99", "1.004740"], ["84171.00", "0.001169"], ["84169.00", "0.001907"], ["84167.00", "0.005020"], ["84165.00", "0.013210"], ["84163.00", "0.034763"], ["84161.00", "0.091482"], ["84159.00", "0.240740"], ["84157.00", "0.633527"], ["84155.00", "1.667176"], ["84153.12", "0.077973"], ["84153.00", "4.387305"], ["84151.00", "11.545541"], ["84147.60", "0.125790"], ["84139.70", "0"], ["84108.90", "4.072271"], ["84100.40", "4.705735"], ["84091.90", "5.339200"], ["84083.40", "5.610684"], ["84074.90", "5.067715"], ["84074.07", "0"], ["84066.40", "4.796230"], ["84065.65", "0"], ["84057.90", "5.520189"], ["84049.40", "5.248705"], ["84040.90", "4.615240"], ["84032.40", "4.886725"], ["84023.90", "4.977220"], ["84015.40", "4.343756"], ["84006.90", "3.891281"], ["83998.40", "5.158210"], ["83989.90", "3.981776"], ["83981.40", "4.434251"], ["83972.90", "4.524746"], ["83964.40", "4.253261"], ["83955.90", "5.429695"], ["83947.40", "4.162766"], ["83690.48", "0.000248"], ["83690.00", "0.000013"]], "checksum": 1923003167, "ts": "1742560343205"}], "ts": 1742560343207}}
{"exchange": "BYBIT", "timestamp": 1742560343.339569, "message": {"topic": "orderbook.200.BTCUSDT", "ts": 1742560343319, "type": "delta", "data": {"s": "BTCUSDT", "b": [["84199", "1.004018"], ["84193.3", "0"], ["84193.2", "0.071298"], ["84191.3", "0"], ["84188.6", "0.121841"], ["84188.5", "0.071302"], ["84187.8", "0.063117"], ["84184.5", "0"], ["84177.5", "0"], ["84170.5", "0.000518"], ["84160.4", "0"], ["84160.3", "0"], ["84160.1", "0.039636"], ["84160", "0.039696"], ["84159.4", "0.000333"], ["84159.3", "0"], ["84159.1", "0.012882"], ["84159", "0.012882"], ["84155.5", "0"], ["84155.4", "0"], ["84155.2", "0.049884"], ["84155.1", "0.049551"], ["84152.3", "0"], ["84127.1", "0.118793"], ["84126.3", "0.003564"], ["84125.8", "0.000333"]], "a": [["84205.3", "0.071488"], ["84207.2", "0"], ["84219.5", "0"], ["84226.5", "0"], ["84233.5", "0"], ["84237.3", "0.036754"], ["84237.4", "0.012988"], ["84237.6", "0.171"], ["84237.7", "0.005938"], ["84246", "0.052787"], ["84254.8", "0"], ["84257.6", "2.562085"], ["84272.4", "0.001853"], ["84273.1", "0.000333"]], "u": 45305, "seq": 67552587775}, "cts": 1742560343317}}
{"exchange": "BITGET", "timestamp": 1742560343.455353, "message": {"action": "update", "arg": {"instType": "SPOT", "channel": "books", "instId": "BTCUSDT"}, "data": [{"asks": [["84174.01", "0.000117"], ["84176.51", "0.054775"], ["84177.01", "0.014281"], ["84193.34", "0"], ["84195.06", "0"], ["84195.24", "0"], ["84198.94", "0.006356"], ["84200.56", "0.006356"], ["84201.74", "0.016429"], ["84206.37", "0.179114"], ["84237.30", "0"], ["84239.00", "0.298200"], ["84240.00", "0.066420"], ["84246.81", "0.001810"], ["84247.80", "1.350000"], ["84262.45", "0.003620"], ["84277.40", "5.067715"], ["84285.90", "3.981776"], ["84294.40", "5.158210"], ["84302.90", "5.248705"], ["84319.90", "5.520189"], ["84328.40", "4.253261"], ["84336.90", "4.072271"], ["84345.40", "4.434251"], ["84353.90", "4.343756"], ["84362.40", "4.705735"], ["84370.90", "4.886725"], ["84379.40", "4.615240"], ["84387.90", "5.429695"], ["84396.40", "5.339200"], ["84404.90", "3.891281"], ["84413.40", "4.977220"], ["84421.90", "4.162766"], ["84430.40", "4.796230"], ["84438.90", "4.524746"], ["84570.51", "0"], ["84570.99", "0"], ["84571.43", "0"], ["84571.75", "0"]], "bids": [["84161.00", "0.091583"], ["84159.00", "0.241170"], ["84157.00", "0.634659"], ["84155.00", "1.670155"], ["84153.32", "0.005938"], ["84153.00", "4.395144"], ["84151.00", "11.566168"], ["84150.90", "0.007330"], ["84149.10", "0.106500"], ["84148.10", "0.055320"], ["84147.72", "0"], ["84145.40", "0"], ["84139.70", "0.129000"], ["84123.00", "0"], ["84122.00", "0"], ["84121.00", "0"], ["84120.00", "0.002013"], ["84119.00", "0"], ["84118.00", "0"], ["84117.00", "0"], ["84116.00", "0"], ["84115.00", "0"], ["84114.45", "0.126736"], ["84114.00", "0"], ["84113.00", "0"], ["84112.00", "0"], ["84111.00", "0"], ["84110.00", "0.000013"], ["84109.00", "0"], ["84108.90", "5.520189"], ["84108.00", "0"], ["84107.00", "0"], ["84106.00", "0"], ["84105.00", "0"], ["84104.00", "0"], ["84103.00", "0"], ["84102.00", "0"], ["84101.00", "0"], ["84100.40", "4.796230"], ["84100.00", "0.000013"], ["84099.00", "0"], ["84098.00", "0"], ["84097.00", "0"], ["84096.00", "0"], ["84095.00", "0"], ["84094.00", "0.000017"], ["84083.40", "4.977220"], ["84079.66", "0.001810"], ["84074.90", "4.524746"], ["84071.25", "0.003620"], ["84066.40", "4.253261"], ["84057.90", "5.429695"], ["84040.90", "4.434251"], ["84023.90", "4.615240"], ["84006.90", "5.158210"], ["83998.40", "4.072271"], ["83981.40", "5.067715"], ["83972.90", "3.891281"], ["83964.40", "4.162766"], ["83955.90", "5.610684"], ["83947.40", "4.705735"], ["83689.78", "0.001684"], ["83689.50", "0.000113"], ["83688.89", "0.000009"], ["83688.07", "0.000072"], ["83687.50", "0.006969"], ["83687.00", "0.000008"], ["83686.11", "0.000096"], ["83684.21", "0.000102"], ["83683.67", "0.000184"], ["83681.82", "0.000175"], ["83680.67", "0.041940"], ["83680.00", "0.000495"], ["83679.44", "0.000361"], ["83678.70", "0.000192"], ["83678.41", "0.000010"], ["83678.08", "0.000145"], ["83677.42", "0.000008"], ["83677.37", "0.000008"], ["83676.47", "0.000080"], ["83675.68", "0.000008"], ["83675.62", "0.000011"], ["83675.36", "0.000013"]], "checksum": 1260466496, "ts": "1742560343408"}], "ts": 1742560343418}}
{"exchange": "BYBIT", "timestamp": 1742560343.604173, "message": {"topic": "orderbook.200.BTCUSDT", "ts": 1742560343520, "type": "delta", "data": {"s": "BTCUSDT", "b": [["84199", "1.0058"], ["84191.4", "0.017314"], ["84184", "0.001333"], ["84172.3", "0"], ["84168.1", "0.118793"], ["84162.7", "0.0016"], ["84160.1", "0"], ["84159.9", "0.039636"], ["84159.1", "0"], ["84158.9", "0.012882"], ["84158", "0.01727"], ["84155.3", "0"], ["84155.2", "0.000333"], ["84155", "0.049551"], ["84152.3", "0.135578"], ["84126.3", "0"], ["84125.8", "0"]], "a": [["84199.1", "0.106837"], ["84201.7", "0.023914"], ["84221.3", "0.010307"], ["84237.3", "0.023754"], ["84237.5", "0.012988"], ["84272.4", "0"], ["84273.1", "0"]], "u": 45306, "seq": 67552587839}, "cts": 1742560343506}}
{"exchange": "BITGET", "timestamp": 1742560343.648764, "message": {"action": "update", "arg": {"instType": "SPOT", "channel": "books", "instId": "BTCUSDT"}, "data": [{"asks": [["84174.00", "0.980536"], ["84174.78", "0"], ["84218.53", "0"], ["84277.40", "4.253261"], ["84285.90", "4.343756"], ["84294.40", "4.705735"], ["84302.90", "4.072271"], ["84311.40", "4.162766"], ["84319.90", "5.067715"], ["84328.40", "5.520189"], ["84336.90", "5.248705"], ["84345.40", "5.158210"], ["84353.90", "4.796230"], ["84362.40", "4.615240"], ["84370.90", "4.434251"], ["84379.40", "4.524746"], ["84387.90", "5.339200"], ["84396.40", "3.891281"], ["84404.90", "3.981776"], ["84413.40", "4.886725"], ["84421.90", "4.977220"], ["84430.40", "5.429695"], ["84438.90", "5.610684"], ["84570.51", "0.000170"], ["84570.99", "0.000053"]], "bids": [["84139.90", "0.089070"], ["84139.80", "0"], ["84139.70", "0"], ["84108.90", "3.981776"], ["84100.40", "5.248705"], ["84091.90", "4.253261"], ["84083.41", "0.952696"], ["84083.40", "5.339200"], ["84074.90", "4.886725"], ["84066.40", "5.067715"], ["84057.90", "4.524746"], ["84049.40", "5.520189"], ["84040.90", "4.705735"], ["84032.40", "4.434251"], ["84023.90", "3.891281"], ["84015.40", "5.610684"], ["84006.90", "5.429695"], ["83998.40", "4.796230"], ["83989.90", "4.343756"], ["83981.40", "5.158210"], ["83972.90", "4.977220"], ["83964.40", "4.072271"], ["83955.90", "4.615240"], ["83947.40", "4.162766"], ["83675.20", "0.000018"]], "checksum": 1727791696, "ts": "1742560343616"}], "ts": 1742560343619}}
{"exchange": "BYBIT", "timestamp": 1742560343.740918, "message": {"topic": "orderbook.200.BTCUSDT", "ts": 1742560343720, "type": "delta", "data": {"s": "BTCUSDT", "b": [["84199", "1.006448"], ["84193.2", "0"], ["84190.8", "0.0713"], ["84188.5", "0"], ["84160.1", "0.128327"], ["84159.1", "0.012882"], ["84158.9", "0"], ["84152.3", "0.135594"]], "a": [["84220.9", "0.001174"], ["84221.3", "0.009"], ["84272.3", "0"]], "u": 45307, "seq": 67552587919}, "cts": 1742560343706}}
{"exchange": "BITGET", "timestamp": 1742560343.881616, "message": {"action": "update", "arg": {"instType": "SPOT", "channel": "books", "instId": "BTCUSDT"}, "data": [{"asks": [["84174.00", "1.189736"], ["84174.75", "0.095065"], ["84176.50", "0.030713"], ["84177.01", "0"], ["84231.30", "0.497146"], ["84233.30", "1.308280"], ["84235.30", "3.442841"], ["84277.40", "4.886725"], ["84294.40", "4.615240"], ["84302.90", "5.520189"], ["84311.40", "4.977220"], ["84319.90", "4.524746"], ["84328.40", "4.253261"], ["84336.90", "5.067715"], ["84345.40", "3.981776"], ["84353.90", "3.891281"], ["84362.40", "5.429695"], ["84370.90", "4.162766"], ["84379.40", "5.248705"], ["84387.90", "5.610684"], ["84396.40", "5.339200"], ["84404.90", "4.072271"], ["84413.40", "4.796230"], ["84421.90", "4.434251"], ["84430.40", "4.705735"], ["84438.90", "5.158210"], ["84570.99", "0"]], "bids": [["84173.48", "0.010000"], ["84153.00", "4.395003"], ["84151.00", "11.565796"], ["84144.00", "0.215142"], ["84139.91", "0"], ["84108.90", "4.524746"], ["84100.40", "4.886725"], ["84091.90", "3.891281"], ["84083.40", "4.796230"], ["84074.90", "5.158210"], ["84066.40", "4.162766"], ["84057.90", "4.434251"], ["84049.40", "4.615240"], ["84040.90", "3.981776"], ["84032.40", "4.977220"], ["84023.90", "5.520189"], ["84015.40", "5.248705"], ["84006.90", "4.705735"], ["83998.40", "4.072271"], ["83989.90", "5.610684"], ["83981.40", "4.343756"], ["83972.90", "5.429695"], ["83964.40", "5.067715"], ["83955.90", "4.253261"], ["83947.40", "5.339200"]], "checksum": 2105364756, "ts": "1742560343850"}], "ts": 1742560343855}}
{"exchange": "BYBIT", "timestamp": 1742560343.941117, "message": {"topic": "orderbook.200.BTCUSDT", "ts": 1742560343920, "type": "delta", "data": {"s": "BTCUSDT", "b": [["84199", "0.803732"], ["84198.3", "0.045355"], ["84198.1", "0.020542"], ["84192.6", "0.264018"], ["84190.8", "0"], ["84188.4", "0.071302"], ["84186.9", "0"], ["84160", "0.00006"], ["84159.9", "0"], ["84159.7", "0.039637"], ["84159.6", "0.039637"], ["84159.1", "0"], ["84159", "0"], ["84158.7", "0.014215"], ["84158.6", "0.01324"], ["84155.1", "0.001781"], ["84155", "0"], ["84154.8", "0.049552"], ["84154.7", "0.049552"], ["84153.2", "0"], ["84133.4", "19.073875"], ["84126.3", "0.003564"]], "a": [["84199.1", "0.378075"], ["84210", "0.223547"], ["84220.4", "0.001048"], ["84220.9", "0"], ["84238.4", "0.043294"], ["84238.5", "0.04"], ["84238.6", "0"], ["84238.7", "0.001333"], ["84254.8", "2.562085"], ["84257.6", "0"], ["84270.6", "0.04"]], "u": 45308, "seq": 67552588051}, "cts": 1742560343916}}
{"exchange": "BITGET", "timestamp": 1742560344.12983, "message": {"action": "update", "arg": {"instType": "SPOT", "channel": "books", "instId": "BTCUSDT"}, "data": [{"asks": [["84174.74", "0.059233"], ["84176.50", "0"], ["84219.30", "0.001981"], ["84221.30", "0.005411"], ["84223.30", "0.014241"], ["84225.30", "0.037476"], ["84227.30", "0.098620"], ["84229.30", "0.259527"], ["84231.30", "0.682966"], ["84233.30", "1.797280"], ["84235.30", "4.729682"], ["84239.00", "0.069030"], ["84239.40", "0.015000"], ["84240.00", "0.002000"], ["84248.10", "0.120000"], ["84277.40", "4.343756"], ["84285.90", "5.158210"], ["84294.40", "5.520189"], ["84302.90", "4.072271"], ["84311.40", "4.162766"], ["84336.90", "4.434251"], ["84345.40", "3.891281"], ["84353.90", "4.886725"], ["84362.40", "4.705735"], ["84370.90", "5.610684"], ["84379.40", "5.339200"], ["84387.90", "3.981776"], ["84396.40", "4.615240"], ["84404.90", "5.429695"], ["84413.40", "5.248705"], ["84421.90", "4.977220"], ["84430.40", "4.796230"], ["84438.90", "5.067715"], ["84570.51", "0"]], "bids": [["84171.00", "0.001017"], ["84169.00", "0.001270"], ["84167.00", "0.003234"], ["84165.00", "0.008511"], ["84163.00", "0.022396"], ["84161.01", "0.025507"], ["84161.00", "0.058937"], ["84159.00", "0.155097"], ["84157.00", "0.408152"], ["84155.00", "1.074084"], ["84153.00", "2.826535"], ["84152.49", "0.026168"], ["84151.00", "7.438252"], ["84149.90", "0.085440"], ["84149.10", "0.105660"], ["84147.90", "0.084810"], ["84145.70", "0.266640"], ["84145.60", "0.192000"], ["84142.90", "0"], ["84139.90", "0.173670"], ["84139.80", "0.132330"], ["84139.70", "0.129000"], ["84100.40", "5.520189"], ["84091.90", "5.248705"], ["84083.40", "4.343756"], ["84074.90", "4.977220"], ["84066.40", "4.796230"], ["84057.90", "5.067715"], ["84040.90", "4.072271"], ["84032.40", "5.158210"], ["84023.90", "3.981776"], ["84015.40", "4.253261"], ["84006.90", "5.339200"], ["83998.40", "5.610684"], ["83989.90", "4.705735"], ["83981.40", "4.162766"], ["83972.90", "4.434251"], ["83964.40", "4.886725"], ["83955.90", "3.891281"], ["83947.40", "5.429695"], ["83675.36", "0"], ["83675.20", "0"]], "checksum": 416548066, "ts": "1742560344051"}], "ts": 1742560344056}}
{"exchange": "BYBIT", "timestamp": 1742560344.139367, "message": {"topic": "orderbook.200.BTCUSDT", "ts": 1742560344120, "type": "delta", "data": {"s": "BTCUSDT", "b": [["84192.6", "0.192719"], ["84190.7", "0.0713"], ["84152.3", "0.135598"], ["84126.3", "0"]], "a": [["84207.6", "0.135706"], ["84220.4", "0"], ["84220.5", "0.168537"], ["84223.6", "0.122345"], ["84252", "2.562142"], ["84254.8", "0"], ["84270.4", "0"], ["84272.3", "0.05728"], ["84272.4", "0.001853"]], "u": 45309, "seq": 67552588154}, "cts": 1742560344110}}
{"exchange": "BITGET", "timestamp": 1742560344.283054, "message": {"action": "update", "arg": {"instType": "SPOT", "channel": "books", "instId": "BTCUSDT"}, "data": [{"asks": [["84174.00", "1.189751"], ["84174.72", "0.095065"], ["84174.75", "0"], ["84205.18", "0.191408"], ["84223.84", "0"], ["84231.30", "0.682859"], ["84233.30", "1.796997"], ["84235.30", "4.728938"], ["84235.60", "0.001010"], ["84235.90", "0.963420"], ["84240.60", "2.352690"], ["84248.10", "0"], ["84277.40", "5.158210"], ["84285.90", "4.886725"], ["84294.40", "4.343756"], ["84302.90", "5.339200"], ["84311.40", "4.796230"], ["84319.90", "5.067715"], ["84328.40", "5.429695"], ["84336.90", "5.520189"], ["84353.90", "4.977220"], ["84362.40", "4.524746"], ["84370.90", "4.434251"], ["84379.40", "4.072271"], ["84387.90", "5.610684"], ["84396.40", "4.162766"], ["84404.90", "3.981776"], ["84413.40", "4.253261"], ["84421.90", "5.248705"], ["84430.40", "4.705735"], ["84438.90", "4.615240"], ["84569.23", "0"]], "bids": [["84155.00", "1.073890"], ["84153.12", "1.384750"], ["84153.00", "2.826027"], ["84151.00", "7.436912"], ["84114.45", "0"], ["84108.90", "3.891281"], ["84100.40", "3.981776"], ["84092.00", "0.000032"], ["84091.90", "5.429695"], ["84083.41", "0"], ["84083.40", "5.158210"], ["84066.40", "4.343756"], ["84057.90", "4.072271"], ["84049.40", "5.067715"], ["84040.90", "4.162766"], ["84032.40", "5.520189"], ["84023.90", "4.615240"], ["84015.40", "5.610684"], ["84006.90", "4.796230"], ["83998.40", "5.339200"], ["83989.90", "4.524746"], ["83981.40", "4.253261"], ["83955.90", "4.705735"], ["83947.40", "5.248705"], ["83675.36", "0.000013"], ["83675.20", "0.000018"]], "checksum": -1304854678, "ts": "1742560344253"}], "ts": 1742560344257}}
{"exchange": "BYBIT", "timestamp": 1742560344.340155, "message": {"topic": "orderbook.200.BTCUSDT", "ts": 1742560344320, "type": "delta", "data": {"s": "BTCUSDT", "b": [["84155", "0.049551"], ["84154.9", "0.049551"], ["84154.8", "0"], ["84154.7", "0"], ["84153.2", "18.646907"], ["84133.4", "0"]], "a": [["84214.5", "0.003974"], ["84220.8", "0.001148"], ["84237.2", "0.085938"], ["84272.4", "0"]], "u": 45310, "seq": 67552588252}, "cts": 1742560344313}}
{"exchange": "BITGET", "timestamp": 1742560344.506292, "message": {"action": "update", "arg": {"instType": "SPOT", "channel": "books", "instId": "BTCUSDT"}, "data": [{"asks": [["84174.01", "0.000100"], ["84174.71", "0.059233"], ["84174.74", "0"], ["84210.45", "0.601302"], ["84219.30", "0.002152"], ["84220.45", "0"], ["84221.30", "0.005664"], ["84223.30", "0.014905"], ["84225.30", "0.039223"], ["84227.30", "0.103218"], ["84229.30", "0.271463"], ["84231.30", "0.714377"], ["84233.30", "1.879940"], ["84233.32", "0.001598"], ["84235.30", "4.947209"], ["84235.60", "0.011790"], ["84239.40", "0.030000"], ["84241.50", "0.014310"], ["84247.70", "0"], ["84247.80", "0"], ["84277.40", "5.520189"], ["84285.90", "3.891281"], ["84294.40", "4.434251"], ["84311.40", "4.072271"], ["84319.90", "4.977220"], ["84328.40", "4.886725"], ["84336.90", "3.981776"], ["84345.40", "4.162766"], ["84353.90", "5.067715"], ["84362.40", "4.705735"], ["84370.90", "5.158210"], ["84379.40", "4.524746"], ["84387.90", "4.253261"], ["84396.40", "4.615240"], ["84404.90", "5.429695"], ["84413.40", "5.610684"], ["84421.90", "4.796230"], ["84430.40", "5.248705"], ["84438.90", "4.343756"], ["84569.23", "0.000009"]], "bids": [["84150.42", "0.008174"], ["84148.11", "0"], ["84144.70", "0"], ["84139.30", "0.000875"], ["84127.94", "0"], ["84124.00", "0.000015"], ["84122.88", "0.001174"], ["84110.03", "0"], ["84108.90", "4.524746"], ["84100.40", "4.886725"], ["84092.00", "0.000015"], ["84091.90", "4.796230"], ["84083.40", "4.705735"], ["84074.90", "4.343756"], ["84066.40", "4.072271"], ["84057.90", "4.615240"], ["84049.40", "4.253261"], ["84040.90", "5.067715"], ["84032.40", "3.891281"], ["84023.90", "5.520189"], ["84015.40", "3.981776"], ["84006.90", "4.162766"], ["83998.40", "4.434251"], ["83989.90", "5.339200"], ["83981.40", "5.429695"], ["83972.90", "5.158210"], ["83964.40", "5.248705"], ["83955.90", "4.977220"], ["83947.40", "5.610684"], ["83675.00", "0.000458"]], "checksum": 536226196, "ts": "1742560344476"}], "ts": 1742560344480}}
{"exchange": "BYBIT", "timestamp": 1742560344.54094, "message": {"topic": "orderbook.200.BTCUSDT", "ts": 1742560344520, "type": "delta", "data": {"s": "BTCUSDT", "b": [["84199", "0.804532"], ["84188.4", "0"], ["84177.1", "0.060245"], ["84171.4", "0.056705"], ["84160.2", "0.04"], ["84160.1", "0.167963"], ["84159.7", "0"], ["84159.6", "0"], ["84155.3", "0.049551"], ["84155.2", "0.049884"], ["84155", "0"], ["84154.9", "0"], ["84126.3", "0.003564"], ["84125.8", "0.000333"], ["84125.1", "0.001333"]], "a": [["84199.1", "0.106837"], ["84207.6", "0.082261"], ["84210", "0.045398"], ["84220.8", "0"], ["84223.6", "0.118793"], ["84237.4", "0"], ["84237.6", "0.183989"], ["84272.4", "0.001853"], ["84273.1", "0.000333"]], "u": 45311, "seq": 67552588440}, "cts": 1742560344513}}
{"exchange": "BITGET", "timestamp": 1742560344.708524, "message": {"action": "update", "arg": {"instType": "SPOT", "channel": "books", "instId": "BTCUSDT"}, "data": [{"asks": [["84174.72", "0"], ["84176.51", "0"], ["84221.30", "0.005826"], ["84223.30", "0.015331"], ["84225.30", "0.040343"], ["84226.20", "0"], ["84227.30", "0.106167"], ["84229.30", "0.279254"], ["84231.29", "0.006346"], ["84231.30", "0.734878"], ["84233.30", "1.933890"], ["84235.24", "0.001597"], ["84235.30", "5.089183"], ["84235.60", "0"], ["84247.70", "2.670270"], ["84277.40", "4.615240"], ["84285.90", "4.253261"], ["84294.40", "5.429695"], ["84302.90", "5.067715"], ["84311.40", "4.162766"], ["84319.90", "4.886725"], ["84328.40", "4.705735"], ["84336.90", "4.434251"], ["84345.40", "5.158210"], ["84353.90", "5.339200"], ["84362.40", "4.796230"], ["84370.90", "5.248705"], ["84379.40", "4.072271"], ["84387.90", "4.343756"], ["84396.40", "3.891281"], ["84404.90", "3.981776"], ["84413.40", "4.524746"], ["84421.90", "4.977220"], ["84430.40", "5.520189"], ["84438.90", "5.610684"], ["84570.51", "0.000170"]], "bids": [["84167.00", "0.003597"], ["84165.00", "0.009467"], ["84163.00", "0.024912"], ["84161.00", "0.065559"], ["84159.00", "0.172522"], ["84157.00", "0.454019"], ["84155.00", "1.194788"], ["84153.00", "3.144179"], ["84151.00", "8.274154"], ["84120.93", "0.001171"], ["84111.90", "0"], ["84108.90", "5.520189"], ["84100.40", "4.977220"], ["84091.90", "3.891281"], ["84083.40", "5.248705"], ["84074.90", "4.886725"], ["84066.40", "5.158210"], ["84057.90", "4.343756"], ["84049.40", "4.434251"], ["84040.90", "4.796230"], ["84032.40", "5.429695"], ["84023.90", "4.705735"], ["84015.40", "4.524746"], ["84006.90", "5.339200"], ["83998.40", "3.981776"], ["83989.90", "4.162766"], ["83981.40", "4.072271"], ["83972.90", "5.610684"], ["83964.40", "5.067715"], ["83955.90", "4.253261"], ["83947.40", "4.615240"]], "checksum": -1678850835, "ts": "1742560344676"}], "ts": 1742560344680}}
{"exchange": "BYBIT", "timestamp": 1742560344.740276, "message": {"topic": "orderbook.200.BTCUSDT", "ts": 1742560344719, "type": "delta", "data": {"s": "BTCUSDT", "b": [["84199", "0.975532"], ["84183.5", "0"], ["84160.2", "0"], ["84160", "0.039696"], ["84156", "18.212595"], ["84155.3", "0"], ["84155.1", "0.051332"], ["84153.2", "0"], ["84125", "0.001466"], ["84124.7", "0.003259"], ["84124.6", "0.02112"]], "a": [["84238.4", "0.003294"], ["84238.6", "0.04"], ["84252", "0"], ["84257.6", "2.562142"], ["84273.1", "0"]], "u": 45312, "seq": 67552588521}, "cts": 1742560344714}}
{"exchange": "BITGET", "timestamp": 1742560344.910362, "message": {"action": "update", "arg": {"instType": "SPOT", "channel": "books", "instId": "BTCUSDT"}, "data": [{"asks": [["84174.00", "1.188486"], ["84174.69", "0.095065"], ["84174.71", "0.014281"], ["84176.37", "0.054775"], ["84219.30", "0.001786"], ["84221.30", "0.004937"], ["84223.30", "0.012992"], ["84225.30", "0.034189"], ["84227.30", "0.089971"], ["84229.30", "0.236766"], ["84231.30", "0.623069"], ["84233.30", "1.639656"], ["84235.30", "4.314884"], ["84240.60", "0"], ["84242.90", "2.352630"], ["84247.70", "0"], ["84277.40", "4.886725"], ["84285.90", "3.891281"], ["84294.40", "5.248705"], ["84302.90", "4.072271"], ["84311.40", "4.343756"], ["84319.90", "4.162766"], ["84328.40", "4.253261"], ["84336.90", "5.158210"], ["84345.40", "4.524746"], ["84353.90", "4.705735"], ["84362.40", "4.977220"], ["84370.90", "3.981776"], ["84379.40", "5.520189"], ["84387.90", "4.615240"], ["84396.40", "5.067715"], ["84404.90", "5.429695"], ["84413.40", "4.796230"], ["84421.90", "5.339200"], ["84430.40", "4.434251"], ["84570.51", "0"]], "bids": [["84169.00", "0.001549"], ["84167.00", "0.004077"], ["84165.00", "0.010730"], ["84163.00", "0.028237"], ["84161.00", "0.074308"], ["84159.00", "0.195546"], ["84157.00", "0.514595"], ["84155.00", "1.354198"], ["84153.00", "3.563679"], ["84151.00", "9.378101"], ["84144.90", "0.356310"], ["84142.20", "0.776280"], ["84139.70", "0"], ["84108.90", "4.343756"], ["84091.90", "4.796230"], ["84083.40", "4.162766"], ["84074.90", "5.520189"], ["84066.40", "3.981776"], ["84057.90", "5.339200"], ["84049.40", "4.253261"], ["84040.90", "5.610684"], ["84032.40", "4.705735"], ["84023.90", "4.886725"], ["84015.40", "5.158210"], ["84006.90", "3.891281"], ["83998.40", "4.072271"], ["83989.90", "5.067715"], ["83981.40", "4.434251"], ["83972.90", "5.248705"], ["83964.40", "5.429695"], ["83955.90", "4.615240"], ["83947.40", "4.524746"]], "checksum": 932273680, "ts": "1742560344881"}], "ts": 1742560344885}}
{"exchange": "BYBIT", "timestamp": 1742560344.940024, "message": {"topic": "orderbook.200.BTCUSDT", "ts": 1742560344920, "type": "delta", "data": {"s": "BTCUSDT", "b": [["84124.8", "0.171"], ["84124.6", "0"]], "a": [["84237.5", "0"], ["84237.7", "0.018927"], ["84238.5", "0"], ["84238.7", "0.041333"], ["84254.8", "2.562142"], ["84257.6", "0"], ["84270.4", "0.089075"], ["84273.1", "0.000333"]], "u": 45313, "seq": 67552588608}, "cts": 1742560344899}}
{"exchange": "BYBIT", "timestamp": 1742560345.177843, "message": {"topic": "orderbook.200.BTCUSDT", "ts": 1742560345120, "type": "delta", "data": {"s": "BTCUSDT", "b": [["84199", "0.804532"], ["84160.3", "0.04"], ["84160.2", "0.039636"], ["84160.1", "0.128327"], ["84160", "0.00006"], ["84159.3", "0.013"], ["84159.2", "0.012882"], ["84158.7", "0.001333"], ["84158.6", "0.000358"], ["84155.4", "0.05"], ["84155.3", "0.049551"], ["84155.2", "0.000333"], ["84155.1", "0.001781"], ["84152.3", "0.135603"], ["84126.3", "0"], ["84125.8", "0"], ["84125.1", "0"], ["84125", "0"], ["84124.8", "0"], ["84124.7", "0"]], "a": [["84201.7", "0"], ["84220.1", "0.000987"], ["84222", "0.083332"], ["84222.1", "0.035638"], ["84237.5", "0.013"], ["84237.7", "0.005938"], ["84238.5", "0.04"], ["84238.7", "0.001333"], ["84252", "2.562142"], ["84254.8", "0"], ["84270.6", "0.164704"], ["84272.4", "0"], ["84273.1", "0"]], "u": 45314, "seq": 67552588753}, "cts": 1742560345113}}
{"exchange": "BITGET", "timestamp": 1742560345.177911, "message": {"action": "update", "arg": {"instType": "SPOT", "channel": "books", "instId": "BTCUSDT"}, "data": [{"asks": [["84174.00", "1.188471"], ["84174.68", "0.059233"], ["84174.71", "0"], ["84237.80", "0.066030"], ["84241.10", "2.352690"], ["84242.90", "0"], ["84277.40", "5.429695"], ["84285.90", "5.520189"], ["84294.40", "5.610684"], ["84302.90", "4.977220"], ["84311.40", "4.615240"], ["84319.90", "4.072271"], ["84328.40", "5.067715"], ["84336.90", "4.796230"], ["84345.40", "3.891281"], ["84353.90", "5.158210"], ["84362.40", "4.162766"], ["84379.40", "4.343756"], ["84387.90", "4.886725"], ["84396.40", "5.248705"], ["84404.90", "4.524746"], ["84413.40", "4.705735"], ["84421.90", "4.434251"], ["84430.40", "5.339200"], ["84438.90", "4.253261"], ["84569.23", "0"]], "bids": [["84120.86", "0.003592"], ["84114.38", "0"], ["84108.90", "5.067715"], ["84100.40", "5.339200"], ["84093.00", "0"], ["84091.90", "4.705735"], ["84083.40", "4.977220"], ["84074.90", "5.158210"], ["84066.40", "5.610684"], ["84057.90", "3.891281"], ["84049.40", "4.434251"], ["84040.90", "4.343756"], ["84032.40", "5.520189"], ["84023.90", "4.796230"], ["84015.40", "4.615240"], ["84006.90", "4.524746"], ["83998.40", "4.886725"], ["83989.90", "3.981776"], ["83981.40", "5.429695"], ["83972.90", "4.253261"], ["83964.40", "4.162766"], ["83955.90", "4.072271"], ["83947.40", "5.248705"], ["83674.70", "0.000008"]], "checksum": 924798531, "ts": "1742560345098"}], "ts": 1742560345102}}
{"exchange": "BYBIT", "timestamp": 1742560345.340738, "message": {"topic": "orderbook.200.BTCUSDT", "ts": 1742560345319, "type": "delta", "data": {"s": "BTCUSDT", "b": [["84199", "0.975532"], ["84194.5", "0.001466"], ["84192.8", "0.071299"], ["84189.8", "0.049466"], ["84184.9", "0.061321"], ["84177.9", "0.054263"], ["84172.6", "0.001065"], ["84170.9", "0.11519"], ["84162.1", "0.206638"], ["84160.3", "0.039636"], ["84159.3", "0.012882"], ["84157.9", "0.005938"], ["84155.4", "0.049551"], ["84155", "0.023753"], ["84154.1", "0.027317"], ["84152.6", "0.023753"], ["84151.8", "0.023753"], ["84149.2", "0.023753"], ["84131.3", "0"], ["84130.1", "0"], ["84130", "0"], ["84129.7", "0"], ["84129.3", "0"], ["84129.2", "0"], ["84128.9", "0"], ["84127.3", "0"], ["84127.2", "0"], ["84127.1", "0"]], "a": [["84199.1", "0.003868"], ["84204.8", "0.000297"], ["84206.4", "0.107087"], ["84206.5", "0.075787"], ["84207.6", "0.000518"], ["84209.7", "0"], ["84213.2", "0"], ["84219.9", "0.061506"], ["84220.1", "0"], ["84225.5", "0.001205"], ["84226.9", "0.062044"], ["84229.3", "0"], ["84233.9", "0.109261"], ["84234.6", "0"], ["84237.5", "0.012989"], ["84238.8", "0.023753"], ["84244.2", "0.023753"], ["84252", "0"], ["84257.6", "2.562142"], ["84272.1", "0"], ["84272.3", "0"]], "u": 45315, "seq": 67552589308}, "cts": 1742560345316}}
{"exchange": "BITGET", "timestamp": 1742560345.344214, "message": {"action": "update", "arg": {"instType": "SPOT", "channel": "books", "instId": "BTCUSDT"}, "data": [{"asks": [["84174.01", "0.000593"], ["84174.69", "0"], ["84197.47", "0.066418"], ["84219.30", "0.002240"], ["84221.30", "0.005894"], ["84223.30", "0.015512"], ["84225.30", "0.040821"], ["84227.30", "0.107424"], ["84229.30", "0.282694"], ["84231.30", "0.743932"], ["84233.30", "1.957716"], ["84235.30", "5.151884"], ["84277.40", "4.343756"], ["84285.90", "5.610684"], ["84294.40", "4.162766"], ["84302.90", "4.253261"], ["84311.40", "4.524746"], ["84319.90", "5.158210"], ["84328.40", "4.615240"], ["84336.90", "5.339200"], ["84345.40", "4.072271"], ["84353.90", "4.705735"], ["84362.40", "4.977220"], ["84370.90", "4.434251"], ["84379.40", "3.891281"], ["84396.40", "5.067715"], ["84404.90", "5.248705"], ["84413.40", "3.981776"], ["84421.90", "5.429695"], ["84430.40", "5.520189"], ["84438.90", "4.796230"]], "bids": [["84169.00", "0.001411"], ["84167.00", "0.003712"], ["84165.00", "0.009769"], ["84163.00", "0.025708"], ["84161.00", "0.067652"], ["84159.00", "0.178032"], ["84157.00", "0.468505"], ["84155.00", "1.232908"], ["84153.12", "0"], ["84153.00", "3.244495"], ["84151.00", "8.538144"], ["84123.00", "0.000017"], ["84108.90", "4.705735"], ["84091.90", "5.158210"], ["84083.40", "5.520189"], ["84074.90", "5.248705"], ["84066.40", "3.981776"], ["84057.90", "4.615240"], ["84049.40", "5.429695"], ["84040.90", "4.524746"], ["84032.40", "3.891281"], ["84023.90", "4.162766"], ["84015.40", "4.886725"], ["84006.90", "4.343756"], ["83998.40", "4.072271"], ["83989.90", "5.067715"], ["83981.40", "4.796230"], ["83964.40", "5.610684"], ["83955.90", "4.434251"], ["83947.40", "4.977220"]], "checksum": -23680938, "ts": "1742560345311"}], "ts": 1742560345316}}
{"exchange": "BYBIT", "timestamp": 1742560345.539839, "message": {"topic": "orderbook.200.BTCUSDT", "ts": 1742560345519, "type": "delta", "data": {"s": "BTCUSDT", "b": [["84199.1", "0.821146"], ["84199", "0.290405"], ["84198.3", "0"], ["84198.2", "0"], ["84190.7", "0.0863"], ["84190.6", "0"], ["84189.7", "0.160209"], ["84188.1", "0.067829"], ["84184.9", "0"], ["84183.8", "0.0002"], ["84183", "0.056"], ["84182.2", "0"], ["84179.9", "0.186855"], ["84177.9", "0"], ["84177.6", "0.037979"], ["84177.1", "0.004245"], ["84170.9", "0"], ["84170.8", "0.275508"], ["84169.6", "0.178149"], ["84169.4", "0.178149"], ["84167.5", "0"], ["84160.9", "0.029166"], ["84158", "5.620447"], ["84152.3", "0"], ["84135", "0.010994"], ["84131.3", "0.009"]], "a": [["84199.1", "0"], ["84199.2", "0.033378"], ["84203.7", "0.025314"], ["84207.5", "0"], ["84207.6", "0.015518"], ["84214.9", "0.120043"], ["84219.9", "0.178149"], ["84221.5", "0.008564"], ["84222.1", "0"], ["84224.7", "0.165589"], ["84225.5", "0"], ["84226.9", "0.001466"], ["84233.8", "0.306326"], ["84233.9", "0"], ["84237.5", "0"], ["84237.6", "0.183988"], ["84237.7", "0.018927"], ["84270.6", "0.04"], ["84272.1", "0.003292"], ["84272.3", "0.05728"], ["84272.4", "0.001853"]], "u": 45316, "seq": 67552589528}, "cts": 1742560345517}}
{"exchange": "BITGET", "timestamp": 1742560345.546364, "message": {"action": "update", "arg": {"instType": "SPOT", "channel": "books", "instId": "BTCUSDT"}, "data": [{"asks": [["84174.00", "1.000100"], ["84174.67", "0.095065"], ["84174.68", "0.030713"], ["84206.37", "0"], ["84219.30", "0.001876"], ["84221.30", "0.004937"], ["84223.30", "0.012992"], ["84225.30", "0.034189"], ["84227.30", "0.089971"], ["84229.30", "0.236766"], ["84231.30", "0.623069"], ["84233.30", "1.639656"], ["84235.30", "4.314884"], ["84241.10", "0"], ["84245.60", "0.178110"], ["84246.50", "0"], ["84246.81", "0"], ["84262.45", "0"], ["84277.40", "4.705735"], ["84285.90", "4.524746"], ["84294.40", "5.520189"], ["84302.90", "5.158210"], ["84311.40", "4.615240"], ["84319.90", "5.429695"], ["84328.40", "3.981776"], ["84336.90", "4.072271"], ["84345.40", "4.162766"], ["84353.90", "5.067715"], ["84362.40", "5.339200"], ["84370.90", "4.886725"], ["84379.40", "4.796230"], ["84387.90", "4.253261"], ["84396.40", "4.434251"], ["84413.40", "3.891281"], ["84421.90", "5.610684"], ["84430.40", "4.977220"], ["84438.90", "4.343756"], ["84569.23", "0.000009"], ["84570.51", "0.000170"], ["84570.99", "0.000053"]], "bids": [["84173.99", "0.991335"], ["84169.00", "0.001551"], ["84167.00", "0.004081"], ["84165.00", "0.010738"], ["84163.00", "0.028258"], ["84161.00", "0.074189"], ["84159.00", "0.195236"], ["84157.00", "0.513778"], ["84155.00", "1.352046"], ["84153.00", "3.558017"], ["84151.00", "9.363203"], ["84145.30", "0.356310"], ["84144.90", "0"], ["84114.45", "0.125294"], ["84108.90", "5.248705"], ["84100.40", "4.977220"], ["84091.90", "5.520189"], ["84083.40", "4.886725"], ["84079.66", "0"], ["84074.90", "5.339200"], ["84071.25", "0"], ["84066.40", "5.158210"], ["84057.90", "4.524746"], ["84049.40", "4.072271"], ["84040.90", "4.253261"], ["84032.40", "4.615240"], ["84023.90", "5.610684"], ["84015.40", "3.981776"], ["84006.90", "4.162766"], ["83998.40", "5.067715"], ["83989.90", "5.429695"], ["83981.40", "4.343756"], ["83972.90", "3.891281"], ["83964.40", "4.705735"], ["83947.40", "4.796230"], ["83770.00", "0.000551"], ["83674.19", "0.000020"]], "checksum": -1441863258, "ts": "1742560345516"}], "ts": 1742560345521}}
{"exchange": "BYBIT", "timestamp": 1742560345.740684, "message": {"topic": "orderbook.200.BTCUSDT", "ts": 1742560345720, "type": "delta", "data": {"s": "BTCUSDT", "b": [["84189.7", "0.151416"], ["84185.6", "0.118933"], ["84180.5", "0.107966"], ["84179.9", "0"], ["84179.2", "0.185355"], ["84178.6", "0.216531"], ["84172.2", "0.813463"], ["84171.6", "0.273627"], ["84170.8", "0"], ["84160.3", "0"], ["84160.1", "0.167963"], ["84159.3", "0"], ["84159.1", "0.012882"], ["84156", "17.76968"], ["84155.4", "0.05"]], "a": [["84210", "0.073643"], ["84214.2", "0.109472"], ["84214.9", "0"], ["84218.4", "0.207992"], ["84218.5", "0.228199"], ["84224.7", "0.17092"], ["84225.5", "0.179332"], ["84231.7", "0.274376"], ["84232.5", "0.34091"], ["84233.8", "0"], ["84252", "2.562139"], ["84257.6", "0"]], "u": 45317, "seq": 67552589608}, "cts": 1742560345710}}
{"exchange": "BITGET", "timestamp": 1742560345.748187, "message": {"action": "update", "arg": {"instType": "SPOT", "channel": "books", "instId": "BTCUSDT"}, "data": [{"asks": [["84174.66", "0.059233"], ["84174.68", "0"], ["84204.08", "0.181862"], ["84205.18", "0"], ["84218.19", "0.010000"], ["84263.79", "0.001810"], ["84273.20", "0.003620"], ["84277.40", "4.434251"], ["84285.90", "5.158210"], ["84294.40", "4.072271"], ["84302.90", "4.524746"], ["84311.40", "4.796230"], ["84319.90", "4.886725"], ["84328.40", "4.615240"], ["84336.90", "5.067715"], ["84345.40", "5.610684"], ["84353.90", "3.891281"], ["84370.90", "3.981776"], ["84379.40", "4.705735"], ["84396.40", "4.162766"], ["84413.40", "4.977220"], ["84421.90", "5.429695"], ["84430.40", "4.343756"], ["84438.90", "5.520189"], ["84569.23", "0"], ["84570.51", "0"], ["84570.99", "0"]], "bids": [["84173.99", "1.004740"], ["84116.30", "0.208446"], ["84112.40", "0"], ["84108.90", "4.705735"], ["84100.40", "5.067715"], ["84091.90", "4.615240"], ["84083.40", "4.977220"], ["84079.66", "0.001810"], ["84074.91", "1.601760"], ["84074.90", "4.253261"], ["84071.25", "0.003620"], ["84066.40", "4.434251"], ["84057.90", "4.343756"], ["84049.40", "5.158210"], ["84040.90", "3.891281"], ["84032.40", "4.524746"], ["84023.90", "4.162766"], ["84006.90", "5.429695"], ["83998.40", "5.248705"], ["83989.90", "4.886725"], ["83981.40", "5.610684"], ["83972.90", "5.339200"], ["83964.40", "5.520189"], ["83955.90", "4.072271"], ["83675.00", "0"], ["83674.70", "0"], ["83674.19", "0"]], "checksum": 1259629034, "ts": "1742560345719"}], "ts": 1742560345722}}
{"exchange": "BYBIT", "timestamp": 1742560345.940972, "message": {"topic": "orderbook.200.BTCUSDT", "ts": 1742560345920, "type": "delta", "data": {"s": "BTCUSDT", "b": [["84189.8", "0.159083"], ["84189.7", "0.042185"], ["84185.7", "0.120696"], ["84185.6", "0"], ["84180.5", "0.152256"], ["84179.3", "0.164404"], ["84179.2", "0"], ["84178.7", "0.18077"], ["84178.6", "0.049876"], ["84172.3", "0.286805"], ["84172.2", "0.540618"], ["84171.7", "0.28489"], ["84171.6", "0"], ["84160.2", "0.04"], ["84159.2", "0"], ["84159", "0.012882"], ["84156", "0"], ["84155.4", "0"], ["84155.3", "0.05"], ["84155.2", "0.049884"], ["84136.2", "17.76968"], ["84131.3", "0"]], "a": [["84203.7", "0.001466"], ["84210", "0.045398"], ["84214.2", "0.000333"], ["84214.3", "0.112317"], ["84218.5", "0.118793"], ["84218.6", "0.15201"], ["84222.6", "0.159636"], ["84224.7", "0"], ["84224.8", "0.167435"], ["84225.5", "0"], ["84225.6", "0.167027"], ["84231.7", "0"], ["84231.8", "0.315957"], ["84232.5", "0.059377"], ["84232.6", "0.859761"], ["84237.4", "0.012988"], ["84237.5", "0.012988"], ["84237.6", "0.171"], ["84237.7", "0.005938"], ["84238.4", "0.043294"], ["84238.6", "0"], ["84252", "0"], ["84254.8", "2.562139"], ["84272.4", "0"]], "u": 45318, "seq": 67552589728}, "cts": 1742560345918}}
{"exchange": "BITGET", "timestamp": 1742560345.954846, "message": {"action": "update", "arg": {"instType": "SPOT", "channel": "books", "instId": "BTCUSDT"}, "data": [{"asks": [["84174.01", "0.001043"], ["84174.64", "0.095066"], ["84174.67", "0"], ["84222.58", "0.110507"], ["84231.30", "0.622827"], ["84233.30", "1.639020"], ["84235.30", "4.313210"], ["84277.40", "3.891281"], ["84285.90", "4.072271"], ["84294.40", "4.977220"], ["84302.90", "5.429695"], ["84311.40", "5.339200"], ["84319.90", "4.434251"], ["84328.40", "5.520189"], ["84336.90", "4.162766"], ["84345.40", "4.343756"], ["84353.90", "4.796230"], ["84362.40", "5.158210"], ["84370.90", "4.615240"], ["84379.40", "5.067715"], ["84387.90", "3.981776"], ["84396.40", "4.705735"], ["84413.40", "4.253261"], ["84421.90", "5.610684"], ["84430.40", "4.886725"], ["84438.90", "4.524746"], ["84568.97", "0"]], "bids": [["84173.48", "0"], ["84135.60", "0.000396"], ["84131.00", "0.000032"], ["84123.00", "0.000032"], ["84114.45", "0"], ["84108.90", "5.248705"], ["84106.10", "0.000948"], ["84101.50", "0"], ["84091.90", "4.705735"], ["84074.90", "5.158210"], ["84066.40", "4.072271"], ["84057.90", "4.162766"], ["84049.40", "5.520189"], ["84040.90", "4.615240"], ["84032.40", "4.796230"], ["84023.90", "3.891281"], ["84015.40", "5.429695"], ["84006.90", "4.524746"], ["83998.40", "5.610684"], ["83989.90", "3.981776"], ["83981.40", "4.253261"], ["83972.90", "4.886725"], ["83964.40", "4.434251"], ["83955.90", "4.343756"], ["83947.40", "5.339200"], ["83760.00", "0.004707"], ["83675.00", "0.000458"]], "checksum": -1303819852, "ts": "1742560345922"}], "ts": 1742560345927}}
{"exchange": "BYBIT", "timestamp": 1742560346.227342, "message": {"topic": "orderbook.200.BTCUSDT", "ts": 1742560346119, "type": "delta", "data": {"s": "BTCUSDT", "b": [["84199.1", "0.652527"], ["84199", "0.119405"], ["84160.2", "0"], ["84160", "0.039696"], ["84158", "0.152873"], ["84155.3", "0"], ["84155.1", "0.049551"], ["84136.2", "0"], ["84133.4", "17.76968"], ["84131.3", "0.009"], ["84130.1", "3.358693"]], "a": [["84237.3", "0.036754"], ["84237.5", "0"], ["84238.3", "0.04"], ["84238.5", "0"], ["84252", "2.562139"], ["84254.8", "0"], ["84272.4", "0.001853"]], "u": 45319, "seq": 67552589770}, "cts": 1742560346113}}
{"exchange": "BITGET", "timestamp": 1742560346.227447, "message": {"action": "update", "arg": {"instType": "SPOT", "channel": "books", "instId": "BTCUSDT"}, "data": [{"asks": [["84174.00", "1.220834"], ["84174.01", "0.000550"], ["84174.63", "0.059233"], ["84174.66", "0"], ["84219.30", "0.002239"], ["84221.30", "0.005892"], ["84223.30", "0.015507"], ["84225.30", "0.040808"], ["84227.30", "0.107389"], ["84229.30", "0.282602"], ["84231.30", "0.743690"], ["84233.30", "1.957080"], ["84235.30", "5.150210"], ["84277.40", "5.248705"], ["84285.90", "3.891281"], ["84294.40", "5.067715"], ["84302.90", "4.343756"], ["84311.40", "4.977220"], ["84319.90", "3.981776"], ["84328.40", "5.158210"], ["84336.90", "4.072271"], ["84345.40", "5.429695"], ["84353.90", "5.520189"], ["84362.40", "4.162766"], ["84370.90", "4.524746"], ["84379.40", "4.796230"], ["84387.90", "4.886725"], ["84396.40", "5.610684"], ["84404.90", "4.253261"], ["84413.40", "4.705735"], ["84421.90", "4.434251"], ["84430.40", "5.339200"], ["84438.90", "4.615240"]], "bids": [["84173.99", "0.991335"], ["84166.22", "0.013405"], ["84125.26", "0.006201"], ["84111.27", "0"], ["84108.90", "4.796230"], ["84100.40", "5.248705"], ["84094.00", "0"], ["84091.90", "4.524746"], ["84083.40", "4.434251"], ["84074.91", "0.027335"], ["84074.90", "4.343756"], ["84066.40", "5.158210"], ["84057.90", "4.886725"], ["84032.40", "4.253261"], ["84023.90", "5.339200"], ["84015.40", "5.067715"], ["84006.90", "5.429695"], ["83998.40", "3.891281"], ["83989.90", "4.162766"], ["83981.40", "4.705735"], ["83972.90", "4.977220"], ["83964.40", "5.610684"], ["83955.90", "3.981776"], ["83947.40", "4.072271"], ["83750.00", "0.041122"]], "checksum": 211684493, "ts": "1742560346126"}], "ts": 1742560346130}}
{"exchange": "BYBIT", "timestamp": 1742560346.339636, "message": {"topic": "orderbook.200.BTCUSDT", "ts": 1742560346320, "type": "delta", "data": {"s": "BTCUSDT", "b": [["84199.1", "0.650746"], ["84199", "0.120121"], ["84189.8", "0.049466"], ["84185.7", "0"], ["84179.3", "0"], ["84178.7", "0"], ["84176.2", "0"], ["84173.3", "0"], ["84172.3", "0"], ["84171.7", "0"], ["84160.1", "0.128327"], ["84160", "0.00006"], ["84159.7", "0.039637"], ["84159.6", "0.039637"], ["84159.1", "0"], ["84159", "0"], ["84158.7", "0.014215"], ["84158.6", "0.01324"], ["84155.9", "0.001781"], ["84155.2", "0.050333"], ["84134.9", "0.079756"], ["84130", "0.000333"], ["84129.7", "0.001466"], ["84129.3", "0.001333"], ["84129.2", "0.00009"], ["84128.9", "0.003777"], ["84127.2", "0.235392"]], "a": [["84199.2", "0.133378"], ["84204.1", "0.02362"], ["84204.8", "0.025498"], ["84214.3", "0"], ["84218.6", "0.04"], ["84224.8", "0"], ["84225.6", "0"], ["84231.8", "0.003564"], ["84232.6", "0.551103"], ["84237.3", "0.036742"], ["84273.1", "0.000333"], ["84273.2", "0.001466"]], "u": 45320, "seq": 67552589864}, "cts": 1742560346316}}
{"exchange": "BITGET", "timestamp": 1742560346.380924, "message": {"action": "update", "arg": {"instType": "SPOT", "channel": "books", "instId": "BTCUSDT"}, "data": [{"asks": [["84174.00", "1.222660"], ["84174.64", "0"], ["84204.70", "0.173629"], ["84221.30", "0.006141"], ["84222.58", "0"], ["84223.30", "0.016161"], ["84225.30", "0.042528"], ["84227.30", "0.111917"], ["84229.30", "0.294518"], ["84231.30", "0.775047"], ["84233.30", "2.039599"], ["84235.30", "5.367365"], ["84237.80", "0"], ["84242.10", "15.250860"], ["84245.60", "0"], ["84247.70", "2.670270"], ["84277.40", "5.339200"], ["84285.90", "5.248705"], ["84294.40", "4.615240"], ["84302.90", "4.524746"], ["84311.40", "4.072271"], ["84319.90", "4.796230"], ["84328.40", "4.162766"], ["84336.90", "5.610684"], ["84345.40", "4.977220"], ["84353.90", "3.891281"], ["84362.40", "4.705735"], ["84370.90", "5.067715"], ["84379.40", "4.886725"], ["84387.90", "4.253261"], ["84396.40", "4.343756"], ["84404.90", "4.434251"], ["84413.40", "3.981776"], ["84421.90", "5.158210"], ["84430.40", "5.429695"], ["84438.90", "5.520189"], ["84550.00", "0.007081"], ["84568.97", "0.000024"], ["84569.23", "0.000009"]], "bids": [["84173.99", "1.004740"], ["84169.00", "0.001408"], ["84167.00", "0.003556"], ["84166.22", "0"], ["84165.00", "0.009232"], ["84163.00", "0.024294"], ["84161.00", "0.063933"], ["84159.00", "0.168244"], ["84157.00", "0.442746"], ["84155.00", "1.165123"], ["84153.00", "3.066113"], ["84151.00", "8.068717"], ["84149.10", "0.145680"], ["84147.20", "0.251640"], ["84145.30", "0"], ["84108.90", "4.886725"], ["84100.40", "4.796230"], ["84091.90", "5.610684"], ["84074.90", "4.162766"], ["84066.40", "5.520189"], ["84057.90", "5.339200"], ["84049.40", "5.429695"], ["84032.40", "4.343756"], ["84023.90", "5.248705"], ["84006.90", "4.705735"], ["83989.90", "4.524746"], ["83981.40", "4.253261"], ["83972.90", "5.158210"], ["83964.40", "4.072271"], ["83947.40", "4.977220"], ["83674.70", "0.000008"], ["83674.19", "0.000020"]], "checksum": -1035840301, "ts": "1742560346349"}], "ts": 1742560346353}}
{"exchange": "BYBIT", "timestamp": 1742560346.540006, "message": {"topic": "orderbook.200.BTCUSDT", "ts": 1742560346520, "type": "delta", "data": {"s": "BTCUSDT", "b": [["84192.8", "0"], ["84192.7", "0.071299"], ["84190.7", "0.015"], ["84188.4", "0.071302"], ["84180.5", "0.060107"], ["84171.3", "0.026165"], ["84160.7", "0.051883"], ["84160.6", "0.039636"], ["84159.7", "0.013"], ["84159.6", "0.012882"], ["84158.7", "0.001333"], ["84158.6", "0.000358"], ["84155.8", "0.05"], ["84155.7", "0.069493"], ["84155.2", "0.000333"], ["84155.1", "0"], ["84128.9", "0"], ["84127.2", "0"]], "a": [["84199.2", "0.375671"], ["84215.9", "0.178114"], ["84219.4", "0.178106"], ["84222.6", "0.000333"], ["84234.3", "0.013"], ["84234.4", "0.012988"], ["84235.3", "0.04"], ["84235.4", "0.040518"], ["84237.3", "0.023754"], ["84237.4", "0"], ["84238.3", "0"], ["84238.4", "0.003294"], ["84272.4", "0"], ["84273.1", "0"], ["84273.2", "0"]], "u": 45321, "seq": 67552589981}, "cts": 1742560346514}}
{"exchange": "BITGET", "timestamp": 1742560346.587401, "message": {"action": "update", "arg": {"instType": "SPOT", "channel": "books", "instId": "BTCUSDT"}, "data": [{"asks": [["84174.00", "1.224740"], ["84174.62", "0.095066"], ["84174.63", "0.030713"], ["84233.30", "2.039359"], ["84235.30", "5.366732"], ["84236.60", "0.014400"], ["84241.00", "2.352690"], ["84247.50", "0"], ["84247.70", "0"], ["84277.40", "4.162766"], ["84285.90", "4.072271"], ["84294.40", "5.158210"], ["84302.90", "4.977220"], ["84311.40", "4.434251"], ["84319.90", "4.343756"], ["84328.40", "4.615240"], ["84336.90", "4.705735"], ["84345.40", "4.886725"], ["84353.90", "5.520189"], ["84362.40", "5.248705"], ["84370.90", "3.981776"], ["84379.40", "5.067715"], ["84387.90", "3.891281"], ["84396.40", "4.796230"], ["84404.90", "4.524746"], ["84413.40", "5.339200"], ["84421.90", "4.253261"], ["84438.90", "5.610684"], ["84569.23", "0"]], "bids": [["84153.01", "1.777603"], ["84142.20", "0.420000"], ["84139.70", "0.120000"], ["84108.90", "4.253261"], ["84100.40", "4.072271"], ["84091.90", "4.796230"], ["84083.40", "5.610684"], ["84074.90", "4.343756"], ["84066.40", "5.158210"], ["84057.90", "3.981776"], ["84049.40", "4.162766"], ["84040.90", "5.429695"], ["84032.40", "5.520189"], ["84023.90", "4.977220"], ["84006.90", "4.434251"], ["83981.40", "5.248705"], ["83972.90", "4.615240"], ["83964.40", "4.886725"], ["83955.90", "5.339200"], ["83947.40", "4.705735"], ["83674.70", "0"], ["83674.19", "0"]], "checksum": 1076861886, "ts": "1742560346556"}], "ts": 1742560346561}}
{"exchange": "BYBIT", "timestamp": 1742560346.754867, "message": {"topic": "orderbook.200.BTCUSDT", "ts": 1742560346720, "type": "delta", "data": {"s": "BTCUSDT", "b": [["84199.1", "0.651546"], ["84199", "0.114535"], ["84171.4", "0.166719"], ["84169.6", "0"], ["84169.4", "0"], ["84165.2", "0"], ["84160.7", "0.051519"], ["84159.7", "0.012882"], ["84158", "0.152876"], ["84155.9", "0.051781"], ["84155.8", "0.04955"], ["84155.7", "0.019942"], ["84128.9", "0.003777"], ["84127.2", "0.235392"], ["84127.1", "0.118793"]], "a": [["84234.3", "0"], ["84234.4", "0"], ["84234.5", "0.014321"], ["84234.6", "0.012988"], ["84235.3", "0"], ["84235.4", "0.000518"], ["84235.5", "0.04"], ["84235.6", "0.04"]], "u": 45322, "seq": 67552590085}, "cts": 1742560346713}}
{"exchange": "BITGET", "timestamp": 1742560346.812227, "message": {"action": "update", "arg": {"instType": "SPOT", "channel": "books", "instId": "BTCUSDT"}, "data": [{"asks": [["84174.00", "1.228480"], ["84174.61", "0.059233"], ["84174.63", "0"], ["84236.60", "0"], ["84247.50", "1.068090"], ["84277.40", "5.339200"], ["84285.90", "4.434251"], ["84294.40", "5.429695"], ["84302.90", "4.072271"], ["84311.40", "4.615240"], ["84319.90", "4.253261"], ["84328.40", "5.610684"], ["84336.90", "5.067715"], ["84345.40", "5.520189"], ["84353.90", "4.162766"], ["84370.90", "4.886725"], ["84379.40", "4.343756"], ["84396.40", "5.158210"], ["84404.90", "3.981776"], ["84413.40", "4.977220"], ["84421.90", "4.524746"], ["84430.40", "4.796230"], ["84438.90", "4.705735"], ["84560.00", "0.000412"]], "bids": [["84173.99", "1.003475"], ["84172.18", "0"], ["84169.00", "0.001156"], ["84167.00", "0.003044"], ["84165.00", "0.008010"], ["84163.00", "0.021078"], ["84161.00", "0.055305"], ["84159.00", "0.145539"], ["84157.00", "0.382996"], ["84155.00", "1.007886"], ["84153.00", "2.652331"], ["84151.00", "6.979817"], ["84145.90", "0.158250"], ["84145.70", "0.153580"], ["84145.60", "0"], ["84144.80", "0"], ["84143.90", "0.084600"], ["84143.80", "0"], ["84141.40", "0"], ["84140.60", "0.427290"], ["84139.80", "0.012330"], ["84139.70", "0.009000"], ["84138.80", "0.180000"], ["84138.50", "0.116820"], ["84138.20", "2.169060"], ["84138.00", "0.300000"], ["84108.90", "4.977220"], ["84100.40", "5.610684"], ["84091.90", "3.981776"], ["84083.40", "4.253261"], ["84074.90", "4.886725"], ["84066.40", "5.429695"], ["84057.90", "5.520189"], ["84049.40", "5.248705"], ["84040.90", "4.705735"], ["84032.40", "5.158210"], ["84023.90", "4.434251"], ["84015.40", "4.524746"], ["84006.90", "4.072271"], ["83998.40", "4.615240"], ["83989.90", "4.343756"], ["83981.40", "5.067715"], ["83972.90", "4.162766"], ["83964.40", "5.339200"], ["83955.90", "3.891281"], ["83947.40", "4.796230"], ["83674.70", "0.000008"], ["83674.19", "0.000020"]], "checksum": 864050006, "ts": "1742560346775"}], "ts": 1742560346779}}
{"exchange": "BYBIT", "timestamp": 1742560346.939991, "message": {"topic": "orderbook.200.BTCUSDT", "ts": 1742560346920, "type": "delta", "data": {"s": "BTCUSDT", "b": [["84187.7", "0.019942"], ["84171.4", "0"], ["84168", "0.085224"], ["84160.7", "0.011883"], ["84160.6", "0"], ["84160.3", "0.039636"], ["84160.2", "0.039636"], ["84159.7", "0"], ["84159.6", "0"], ["84159.3", "0.012882"], ["84159.2", "0.012882"], ["84155.9", "0.001781"], ["84155.8", "0"], ["84155.5", "0.049551"], ["84155.4", "0.049551"], ["84127.1", "0"]], "a": [["84216.8", "0.000818"], ["84217.9", "0"], ["84219.4", "0"], ["84222", "0.083859"], ["84234.5", "0.001333"], ["84234.7", "0.131781"], ["84235.5", "0"], ["84235.7", "0.04"], ["84272.4", "0.001853"], ["84273.1", "0.000333"]], "u": 45323, "seq": 67552590191}, "cts": 1742560346917}}
{"exchange": "BITGET", "timestamp": 1742560347.014172, "message": {"action": "update", "arg": {"instType": "SPOT", "channel": "books", "instId": "BTCUSDT"}, "data": [{"asks": [["84174.00", "1.239272"], ["84174.01", "0.000100"], ["84174.62", "0"], ["84219.30", "0.002443"], ["84221.30", "0.006428"], ["84223.30", "0.016916"], ["84225.30", "0.044516"], ["84227.30", "0.117147"], ["84229.30", "0.308281"], ["84231.30", "0.811266"], ["84233.30", "2.134910"], ["84235.30", "5.618186"], ["84277.40", "5.520189"], ["84285.90", "3.891281"], ["84294.40", "4.434251"], ["84302.90", "4.524746"], ["84311.40", "5.158210"], ["84319.90", "4.886725"], ["84328.40", "4.253261"], ["84336.90", "4.072271"], ["84345.40", "4.796230"], ["84362.40", "4.977220"], ["84370.90", "5.429695"], ["84379.40", "5.610684"], ["84387.90", "3.981776"], ["84396.40", "5.339200"], ["84404.90", "4.705735"], ["84413.40", "4.615240"], ["84421.90", "5.248705"], ["84430.40", "5.067715"], ["84438.90", "4.343756"], ["84560.00", "0.000491"], ["84569.23", "0.000009"]], "bids": [["84167.00", "0.002938"], ["84165.00", "0.007733"], ["84163.00", "0.020348"], ["84161.01", "0.000241"], ["84161.00", "0.053548"], ["84159.00", "0.140916"], ["84157.00", "0.370833"], ["84155.00", "0.975876"], ["84153.01", "0.140459"], ["84153.00", "2.567967"], ["84152.59", "0.025266"], ["84151.00", "6.757808"], ["84141.80", "0.071250"], ["84139.60", "0.192000"], ["84138.00", "0.156000"], ["84108.90", "4.343756"], ["84100.40", "5.158210"], ["84092.00", "0"], ["84091.90", "4.977220"], ["84083.40", "4.705735"], ["84074.90", "3.981776"], ["84057.90", "5.248705"], ["84049.40", "4.796230"], ["84040.90", "5.339200"], ["84032.40", "4.886725"], ["84023.90", "4.072271"], ["84015.40", "4.162766"], ["84006.90", "4.434251"], ["83998.40", "5.520189"], ["83989.90", "5.067715"], ["83981.40", "3.891281"], ["83972.90", "4.253261"], ["83964.40", "5.610684"], ["83955.90", "4.524746"], ["83947.40", "4.615240"], ["83674.19", "0"]], "checksum": -2088490724, "ts": "1742560346983"}], "ts": 1742560346988}}
{"exchange": "BYBIT", "timestamp": 1742560347.139929, "message": {"topic": "orderbook.200.BTCUSDT", "ts": 1742560347119, "type": "delta", "data": {"s": "BTCUSDT", "b": [["84160.4", "0.039636"], ["84160.2", "0"], ["84159.4", "0.013215"], ["84159.2", "0"], ["84133.4", "0"], ["84131.1", "0.235392"], ["84130.6", "17.566307"], ["84127.2", "0"], ["84127.1", "0.118793"]], "a": [["84219.9", "0"], ["84221.5", "0.003812"], ["84234.3", "0.012988"], ["84234.4", "0.012988"], ["84234.6", "0"], ["84234.7", "0.118793"], ["84235.3", "0.04"], ["84235.4", "0.040518"], ["84235.6", "0"], ["84235.7", "0"], ["84270.4", "0"], ["84273.2", "0.001466"], ["84274.2", "0.04"]], "u": 45324, "seq": 67552590265}, "cts": 1742560347116}}
{"exchange": "BITGET", "timestamp": 1742560347.27619, "message": {"action": "update", "arg": {"instType": "SPOT", "channel": "books", "instId": "BTCUSDT"}, "data": [{"asks": [["84174.00", "1.252640"], ["84174.01", "0.000117"], ["84174.60", "0.095066"], ["84174.61", "0.030713"], ["84195.67", "0"], ["84195.70", "0.035952"], ["84195.84", "0.119870"], ["84196.02", "0"], ["84197.15", "0"], ["84197.21", "0.035961"], ["84197.48", "0"], ["84197.74", "0.006356"], ["84197.90", "0.006356"], ["84197.98", "0"], ["84198.26", "0"], ["84198.55", "0"], ["84198.87", "0"], ["84199.18", "0"], ["84199.35", "0"], ["84199.36", "0.010984"], ["84199.43", "0.006356"], ["84199.56", "0"], ["84199.59", "0.006356"], ["84199.84", "0"], ["84200.27", "0.016429"], ["84200.79", "0.006356"], ["84200.83", "0.006356"], ["84201.01", "0"], ["84201.11", "0.126239"], ["84201.13", "0"], ["84201.24", "0.006356"], ["84202.71", "0.006357"], ["84202.78", "0.010985"], ["84203.05", "0"], ["84203.15", "0"], ["84203.55", "0.009990"], ["84203.82", "0"], ["84204.17", "0"], ["84204.44", "0.119850"], ["84204.71", "0"], ["84205.19", "0"], ["84205.33", "0.119858"], ["84205.74", "0.119867"], ["84205.97", "0"], ["84206.03", "0.015895"], ["84206.24", "0.009989"], ["84206.60", "0"], ["84209.55", "0"], ["84209.71", "0.015892"], ["84210.68", "0.010988"], ["84210.95", "0"], ["84231.29", "0"], ["84277.40", "5.067715"], ["84285.90", "5.158210"], ["84294.40", "5.520189"], ["84302.90", "5.429695"], ["84311.40", "3.981776"], ["84319.90", "4.977220"], ["84328.40", "4.524746"], ["84336.90", "4.162766"], ["84345.40", "5.339200"], ["84353.90", "4.796230"], ["84362.40", "4.253261"], ["84370.90", "4.705735"], ["84387.90", "3.891281"], ["84396.40", "4.434251"], ["84404.90", "4.072271"], ["84421.90", "4.886725"], ["84430.40", "4.343756"], ["84438.90", "5.248705"], ["84570.51", "0.000170"]], "bids": [["84173.99", "0.990070"], ["84167.00", "0.003086"], ["84165.00", "0.008123"], ["84163.00", "0.021376"], ["84161.02", "0.065994"], ["84161.00", "0.056253"], ["84159.00", "0.148032"], ["84157.00", "0.389559"], ["84155.61", "0"], ["84155.29", "0.089367"], ["84155.00", "1.025156"], ["84154.59", "0.247262"], ["84154.42", "0"], ["84153.70", "0"], ["84153.44", "0.083830"], ["84153.36", "0"], ["84153.31", "0"], ["84153.13", "0.017794"], ["84153.01", "1.699630"], ["84153.00", "2.697778"], ["84152.95", "0.018231"], ["84152.02", "0"], ["84151.55", "0.055583"], ["84151.11", "0.017081"], ["84151.04", "0"], ["84151.03", "0.004012"], ["84151.00", "7.099415"], ["84150.94", "0.007122"], ["84150.84", "0"], ["84150.61", "0.028827"], ["84150.45", "0"], ["84150.16", "0.008982"], ["84150.11", "0.007932"], ["84150.00", "0"], ["84149.77", "0.025151"], ["84149.76", "0.224587"], ["84149.42", "0.017328"], ["84149.33", "0"], ["84148.89", "0"], ["84148.49", "0"], ["84148.43", "0"], ["84148.33", "0"], ["84148.19", "0"], ["84148.07", "0.051895"], ["84147.99", "0.012639"], ["84147.83", "0"], ["84147.42", "0"], ["84147.16", "0.018493"], ["84146.46", "0"], ["84146.19", "0.268024"], ["84145.36", "0"], ["84145.16", "0"], ["84145.13", "0.259454"], ["84145.06", "0.222377"], ["84144.92", "0.076012"], ["84144.79", "0.021102"], ["84143.06", "0"], ["84140.69", "0.073119"], ["84140.52", "0"], ["84140.24", "0"], ["84139.98", "0.056293"], ["84124.00", "0.000032"], ["84108.90", "4.162766"], ["84100.40", "4.343756"], ["84091.90", "5.610684"], ["84083.40", "4.434251"], ["84074.90", "5.520189"], ["84066.40", "4.253261"], ["84057.90", "4.977220"], ["84049.40", "4.615240"], ["84040.90", "4.886725"], ["84032.40", "3.891281"], ["84023.90", "5.429695"], ["84015.40", "5.248705"], ["84006.90", "5.067715"], ["83998.40", "4.796230"], ["83989.90", "5.158210"], ["83981.40", "5.339200"], ["83972.90", "4.072271"], ["83964.40", "4.524746"], ["83955.90", "4.705735"], ["83947.40", "3.981776"]], "checksum": 1814239422, "ts": "1742560347190"}], "ts": 1742560347192}}
{"exchange": "BYBIT", "timestamp": 1742560347.341665, "message": {"topic": "orderbook.200.BTCUSDT", "ts": 1742560347320, "type": "delta", "data": {"s": "BTCUSDT", "b": [["84199.1", "0.624773"], ["84172.6", "0"], ["84168.1", "0"], ["84165.2", "0.178149"], ["84126.3", "0.003564"]], "a": [["84216.8", "0.004369"], ["84222.1", "0.035638"], ["84234.3", "0"], ["84234.5", "0.014321"], ["84235.3", "0"], ["84235.5", "0.04"], ["84237.1", "0.06346"], ["84239.9", "0.059399"], ["84274.2", "0"]], "u": 45325, "seq": 67552590471}, "cts": 1742560347316}}
{"exchange": "BITGET", "timestamp": 1742560347.426153, "message": {"action": "update", "arg": {"instType": "SPOT", "channel": "books", "instId": "BTCUSDT"}, "data": [{"asks": [["84174.59", "0.059233"], ["84174.61", "0"], ["84176.37", "0"], ["84197.47", "0"], ["84203.04", "0.067527"], ["84240.10", "0.084600"], ["84247.50", "0"], ["84277.40", "4.524746"], ["84285.90", "4.434251"], ["84294.40", "4.886725"], ["84302.90", "4.977220"], ["84311.40", "5.248705"], ["84319.90", "3.891281"], ["84328.40", "4.162766"], ["84336.90", "5.067715"], ["84345.40", "4.615240"], ["84353.90", "5.429695"], ["84362.40", "5.520189"], ["84370.90", "5.610684"], ["84379.40", "4.253261"], ["84387.90", "5.339200"], ["84396.40", "3.981776"], ["84404.90", "4.705735"], ["84413.40", "5.158210"], ["84421.90", "4.343756"], ["84430.40", "4.796230"], ["84438.90", "4.072271"], ["84570.99", "0.000053"]], "bids": [["84167.75", "0.013405"], ["84161.00", "0.056269"], ["84159.00", "0.148076"], ["84157.00", "0.389674"], ["84155.00", "1.025459"], ["84153.01", "1.877933"], ["84153.00", "2.698577"], ["84151.00", "7.101517"], ["84108.90", "3.891281"], ["84100.40", "4.162766"], ["84091.90", "5.248705"], ["84083.40", "4.072271"], ["84074.90", "4.615240"], ["84066.40", "4.705735"], ["84049.40", "4.886725"], ["84040.90", "5.339200"], ["84032.40", "5.520189"], ["84023.90", "4.343756"], ["84015.40", "5.610684"], ["83998.40", "3.981776"], ["83989.90", "4.524746"], ["83981.40", "5.158210"], ["83972.90", "4.434251"], ["83964.40", "5.429695"], ["83955.90", "4.253261"], ["83947.40", "4.796230"], ["83674.70", "0"]], "checksum": 1250727486, "ts": "1742560347398"}], "ts": 1742560347400}}
{"exchange": "BYBIT", "timestamp": 1742560347.539467, "message": {"topic": "orderbook.200.BTCUSDT", "ts": 1742560347519, "type": "delta", "data": {"s": "BTCUSDT", "b": [["84199.1", "0.655415"], ["84158", "0.01727"], ["84155.2", "0.13595"]], "a": [["84199.2", "0.204671"], ["84223.5", "0.061308"], ["84234.4", "0"], ["84234.5", "0.001333"], ["84234.6", "0.012988"], ["84234.7", "0.131781"], ["84235.4", "0.000518"], ["84235.5", "0"], ["84235.6", "0.04"], ["84235.7", "0.04"], ["84237.1", "0"], ["84239.9", "0.122859"], ["84273.2", "0"]], "u": 45326, "seq": 67552590565}, "cts": 1742560347516}}
{"exchange": "BITGET", "timestamp": 1742560347.653563, "message": {"action": "update", "arg": {"instType": "SPOT", "channel": "books", "instId": "BTCUSDT"}, "data": [{"asks": [["84174.57", "0.095066"], ["84174.59", "0.042800"], ["84174.60", "0"], ["84219.30", "0.002613"], ["84221.30", "0.006876"], ["84223.30", "0.018094"], ["84225.30", "0.047615"], ["84227.30", "0.125303"], ["84229.30", "0.329746"], ["84231.30", "0.867752"], ["84233.30", "2.283558"], ["84235.30", "6.009362"], ["84247.50", "1.068090"], ["84277.40", "5.429695"], ["84285.90", "4.162766"], ["84294.40", "4.705735"], ["84302.90", "4.886725"], ["84311.40", "4.615240"], ["84319.90", "5.158210"], ["84328.40", "4.434251"], ["84336.90", "4.253261"], ["84345.40", "3.981776"], ["84353.90", "5.248705"], ["84362.40", "5.610684"], ["84370.90", "5.339200"], ["84379.40", "5.067715"], ["84387.90", "4.977220"], ["84396.40", "4.796230"], ["84404.90", "5.520189"], ["84413.40", "4.343756"], ["84421.90", "4.524746"], ["84430.40", "3.891281"], ["84570.99", "0"]], "bids": [["84173.99", "1.003475"], ["84169.00", "0.001311"], ["84167.82", "0.008819"], ["84167.75", "0"], ["84167.00", "0.003452"], ["84165.00", "0.009083"], ["84163.00", "0.023902"], ["84161.00", "0.062901"], ["84159.00", "0.165529"], ["84157.00", "0.435602"], ["84155.00", "1.146322"], ["84153.00", "3.016637"], ["84151.00", "7.938517"], ["84108.90", "5.339200"], ["84091.90", "5.158210"], ["84083.40", "4.434251"], ["84074.90", "4.072271"], ["84066.40", "3.981776"], ["84049.40", "5.520189"], ["84040.90", "4.343756"], ["84032.40", "3.891281"], ["84023.90", "5.429695"], ["84015.40", "4.705735"], ["84006.90", "4.796230"], ["83998.40", "5.067715"], ["83989.90", "5.248705"], ["83981.40", "5.610684"], ["83972.90", "4.615240"], ["83964.40", "4.524746"], ["83955.90", "4.886725"], ["83947.40", "4.253261"], ["83674.70", "0.000008"]], "checksum": -274632052, "ts": "1742560347623"}], "ts": 1742560347628}}
{"exchange": "BYBIT", "timestamp": 1742560347.798638, "message": {"topic": "orderbook.200.BTCUSDT", "ts": 1742560347720, "type": "delta", "data": {"s": "BTCUSDT", "b": [["84160.7", "0.051519"], ["84160.6", "0.039636"], ["84160.4", "0"], ["84160.3", "0"], ["84155.9", "0.051781"], ["84155.8", "0.04955"], ["84155.5", "0"], ["84155.4", "0"], ["84133.4", "17.35629"], ["84130.6", "0"], ["84125.8", "0.000333"], ["84125.1", "0.001333"]], "a": [["84219.9", "0.178149"], ["84221.7", "0.035864"], ["84222", "0.04"], ["84234.6", "0"], ["84234.7", "0.118793"], ["84234.8", "0.012988"], ["84234.9", "0.012988"], ["84235.6", "0"], ["84235.8", "0.04"], ["84244.8", "0.022834"], ["84251.6", "0"], ["84272.3", "0"], ["84272.4", "0"], ["84273.1", "0"]], "u": 45327, "seq": 67552590675}, "cts": 1742560347707}}
{"exchange": "BITGET", "timestamp": 1742560347.86454, "message": {"action": "update", "arg": {"instType": "SPOT", "channel": "books", "instId": "BTCUSDT"}, "data": [{"asks": [["84174.00", "1.239272"], ["84174.01", "0.000132"], ["84174.56", "0.042800"], ["84174.59", "0"], ["84175.82", "0.054775"], ["84218.19", "0"], ["84277.40", "3.981776"], ["84285.90", "5.429695"], ["84294.40", "4.886725"], ["84302.90", "4.796230"], ["84311.40", "5.520189"], ["84319.90", "5.339200"], ["84328.40", "4.253261"], ["84336.90", "3.891281"], ["84345.40", "5.248705"], ["84353.90", "5.158210"], ["84362.40", "5.067715"], ["84370.90", "4.343756"], ["84379.40", "4.524746"], ["84387.90", "4.615240"], ["84396.40", "5.610684"], ["84404.90", "4.072271"], ["84413.40", "4.162766"], ["84421.90", "4.434251"], ["84430.40", "4.977220"], ["84438.90", "4.705735"]], "bids": [["84173.99", "0.990070"], ["84167.82", "0.005774"], ["84165.14", "0.013405"], ["84161.00", "0.062758"], ["84159.00", "0.165154"], ["84157.00", "0.434615"], ["84155.00", "1.143725"], ["84153.00", "3.009802"], ["84151.00", "7.920531"], ["84122.00", "0.000015"], ["84108.90", "4.977220"], ["84100.40", "3.981776"], ["84091.90", "4.615240"], ["84083.40", "4.253261"], ["84074.90", "4.343756"], ["84066.40", "4.796230"], ["84057.90", "5.067715"], ["84049.40", "3.891281"], ["84040.90", "4.524746"], ["84032.40", "5.520189"], ["84023.90", "4.072271"], ["84015.40", "5.339200"], ["84006.90", "4.705735"], ["83998.40", "4.434251"], ["83989.90", "4.162766"], ["83972.90", "4.886725"], ["83964.40", "5.248705"], ["83955.90", "5.158210"], ["83947.40", "5.429695"], ["83675.00", "0"], ["83674.70", "0"]], "checksum": 617667428, "ts": "1742560347829"}], "ts": 1742560347832}}
{"exchange": "BYBIT", "timestamp": 1742560347.942262, "message": {"topic": "orderbook.200.BTCUSDT", "ts": 1742560347919, "type": "delta", "data": {"s": "BTCUSDT", "b": [["84199", "0.113887"], ["84187.9", "0.120963"], ["84177.4", "0.184386"], ["84170.4", "0.297778"], ["84168", "0.203344"], ["84159.7", "0.012882"], ["84159.6", "0.012882"], ["84159.4", "0.000333"], ["84159.3", "0"], ["84155.9", "0.001781"], ["84155.7", "0.069493"], ["84127.1", "0"], ["84126.3", "0"], ["84125.8", "0"], ["84125.1", "0"]], "a": [["84210", "0.078447"], ["84212.4", "0.125153"], ["84216.8", "0.000818"], ["84222.9", "0.174787"], ["84229.9", "0.292784"], ["84234.5", "0.014333"], ["84234.6", "0.012988"], ["84234.8", "0"], ["84234.9", "0"], ["84272.1", "0"]], "u": 45328, "seq": 67552590752}, "cts": 1742560347913}}
{"exchange": "BITGET", "timestamp": 1742560348.061047, "message": {"action": "update", "arg": {"instType": "SPOT", "channel": "books", "instId": "BTCUSDT"}, "data": [{"asks": [["84174.00", "1.228480"], ["84174.57", "0"], ["84219.30", "0.001969"], ["84221.30", "0.005183"], ["84223.30", "0.013639"], ["84225.30", "0.035891"], ["84227.30", "0.094451"], ["84229.30", "0.248556"], ["84231.30", "0.654093"], ["84233.30", "1.721299"], ["84235.30", "4.529732"], ["84236.40", "0.055380"], ["84247.50", "0"], ["84277.40", "5.429695"], ["84285.90", "4.524746"], ["84294.40", "4.977220"], ["84302.90", "5.339200"], ["84311.40", "4.162766"], ["84319.90", "5.067715"], ["84328.40", "4.072271"], ["84362.40", "4.705735"], ["84370.90", "4.615240"], ["84379.40", "4.343756"], ["84387.90", "4.253261"], ["84396.40", "4.796230"], ["84404.90", "4.886725"], ["84413.40", "5.520189"], ["84430.40", "5.610684"], ["84438.90", "3.981776"], ["84570.99", "0.000053"]], "bids": [["84173.99", "1.003475"], ["84172.18", "0.062792"], ["84165.14", "0"], ["84151.00", "7.920326"], ["84108.90", "3.981776"], ["84100.40", "4.434251"], ["84091.90", "4.253261"], ["84083.40", "4.886725"], ["84074.90", "4.705735"], ["84066.40", "5.158210"], ["84057.90", "3.891281"], ["84049.40", "4.162766"], ["84040.90", "5.339200"], ["84032.40", "4.615240"], ["84015.40", "5.520189"], ["84006.90", "4.977220"], ["83998.40", "4.524746"], ["83989.90", "4.343756"], ["83981.40", "4.796230"], ["83972.90", "5.248705"], ["83964.40", "5.067715"], ["83955.90", "5.429695"], ["83947.40", "5.610684"]], "checksum": -326731654, "ts": "1742560348029"}], "ts": 1742560348032}}
{"exchange": "BYBIT", "timestamp": 1742560348.14073, "message": {"topic": "orderbook.200.BTCUSDT", "ts": 1742560348120, "type": "delta", "data": {"s": "BTCUSDT", "b": [["84180.5", "0.107951"]], "a": [["84220.7", "0.035864"], ["84221.7", "0"], ["84234.5", "0.001333"], ["84234.6", "0"], ["84234.7", "0.131781"], ["84234.8", "0.012992"], ["84252", "0"], ["84254.8", "2.562139"]], "u": 45329, "seq": 67552590812}, "cts": 1742560348106}}
{"exchange": "BITGET", "timestamp": 1742560348.324288, "message": {"action": "update", "arg": {"instType": "SPOT", "channel": "books", "instId": "BTCUSDT"}, "data": [{"asks": [["84174.00", "1.227202"], ["84174.55", "0.095066"], ["84174.56", "0.030713"], ["84201.10", "0.111487"], ["84203.04", "0"], ["84219.30", "0.002488"], ["84221.30", "0.006548"], ["84223.30", "0.017232"], ["84225.30", "0.045347"], ["84227.30", "0.119334"], ["84229.30", "0.314036"], ["84231.30", "0.826412"], ["84233.30", "2.174767"], ["84235.30", "5.723071"], ["84236.40", "0"], ["84241.00", "0"], ["84247.50", "1.068090"], ["84277.40", "4.615240"], ["84294.40", "5.248705"], ["84311.40", "3.891281"], ["84319.90", "5.610684"], ["84328.40", "5.429695"], ["84336.90", "4.343756"], ["84345.40", "4.253261"], ["84353.90", "4.796230"], ["84362.40", "4.162766"], ["84370.90", "5.067715"], ["84379.40", "4.705735"], ["84387.90", "4.434251"], ["84396.40", "5.520189"], ["84404.90", "5.158210"], ["84413.40", "4.886725"], ["84421.90", "4.977220"], ["84430.40", "3.981776"], ["84438.90", "4.072271"]], "bids": [["84173.99", "0.968959"], ["84167.00", "0.003450"], ["84165.00", "0.009079"], ["84163.00", "0.023892"], ["84161.00", "0.062874"], ["84159.00", "0.165458"], ["84157.00", "0.435417"], ["84155.00", "1.145833"], ["84153.00", "3.015350"], ["84151.00", "7.935132"], ["84138.20", "2.973090"], ["84108.90", "4.886725"], ["84100.40", "4.796230"], ["84091.90", "5.610684"], ["84083.40", "4.072271"], ["84074.90", "4.162766"], ["84057.90", "5.520189"], ["84049.40", "4.434251"], ["84040.90", "4.615240"], ["84032.40", "4.253261"], ["84023.90", "5.248705"], ["84015.40", "4.705735"], ["84006.90", "4.524746"], ["83998.40", "4.343756"], ["83989.90", "4.977220"], ["83981.40", "3.891281"], ["83972.90", "3.981776"], ["83964.40", "5.339200"], ["83955.90", "5.067715"], ["83947.40", "5.429695"]], "checksum": -1459483173, "ts": "1742560348230"}], "ts": 1742560348235}}
{"exchange": "BYBIT", "timestamp": 1742560348.339134, "message": {"topic": "orderbook.200.BTCUSDT", "ts": 1742560348319, "type": "delta", "data": {"s": "BTCUSDT", "b": [["84199.1", "0.655579"], ["84187.9", "0.116453"], ["84177.4", "0.176569"], ["84170.4", "0.309489"], ["84160.7", "0.011883"], ["84160.6", "0"], ["84160.4", "0.039636"], ["84160.3", "0.039636"], ["84159.7", "0"], ["84159.6", "0"], ["84159.4", "0.013215"], ["84159.3", "0.012882"], ["84155.8", "0"], ["84155.7", "0.019942"], ["84155.6", "0.05"], ["84155.5", "0.049551"], ["84128.9", "0"]], "a": [["84199.2", "0.374798"], ["84210", "0.077486"], ["84212.4", "0.121951"], ["84221.8", "0.014411"], ["84222.9", "0.176527"], ["84229.9", "0.308017"], ["84234.5", "0.014333"], ["84234.6", "0.012992"], ["84234.7", "0.118793"], ["84234.8", "0"], ["84235.5", "0.04"], ["84235.6", "0.04"], ["84235.7", "0"], ["84235.8", "0"], ["84252", "2.562139"], ["84254.8", "0"], ["84271.6", "0"]], "u": 45330, "seq": 67552590893}, "cts": 1742560348315}}
{"exchange": "BITGET", "timestamp": 1742560348.459539, "message": {"action": "update", "arg": {"instType": "SPOT", "channel": "books", "instId": "BTCUSDT"}, "data": [{"asks": [["84174.01", "0.000115"], ["84174.54", "0.059233"], ["84174.56", "0"], ["84198.14", "0.006356"], ["84198.94", "0"], ["84210.45", "0"], ["84247.70", "2.670270"], ["84277.40", "4.796230"], ["84285.90", "5.339200"], ["84294.40", "4.343756"], ["84302.90", "5.520189"], ["84311.40", "5.429695"], ["84319.90", "4.615240"], ["84328.40", "5.248705"], ["84336.90", "4.886725"], ["84345.40", "3.981776"], ["84353.90", "5.158210"], ["84370.90", "4.705735"], ["84379.40", "4.434251"], ["84387.90", "4.253261"], ["84396.40", "3.891281"], ["84404.90", "4.977220"], ["84413.40", "4.072271"], ["84421.90", "5.067715"], ["84430.40", "5.610684"], ["84438.90", "4.524746"]], "bids": [["84171.38", "0.010000"], ["84155.00", "1.145948"], ["84153.32", "0"], ["84153.00", "3.015654"], ["84152.52", "0.005938"], ["84151.00", "7.935932"], ["84123.00", "0.000015"], ["84100.40", "4.705735"], ["84091.90", "5.429695"], ["84083.40", "5.248705"], ["84074.90", "4.524746"], ["84066.40", "5.520189"], ["84057.90", "5.067715"], ["84049.40", "4.162766"], ["84040.90", "4.253261"], ["84032.40", "3.981776"], ["84023.90", "4.615240"], ["84015.40", "4.343756"], ["84006.90", "5.610684"], ["83998.40", "5.339200"], ["83989.90", "4.796230"], ["83981.40", "4.977220"], ["83972.90", "4.072271"], ["83964.40", "4.434251"], ["83955.90", "3.891281"], ["83947.40", "5.158210"], ["83675.20", "0"]], "checksum": -274178463, "ts": "1742560348429"}], "ts": 1742560348434}}
{"exchange": "BYBIT", "timestamp": 1742560348.542274, "message": {"topic": "orderbook.200.BTCUSDT", "ts": 1742560348519, "type": "delta", "data": {"s": "BTCUSDT", "b": [["84199.1", "0.654951"], ["84187.9", "0.117872"], ["84183.8", "0.116847"], ["84177.4", "0.175388"], ["84176.8", "0.219374"], ["84170.4", "0.303194"], ["84169.8", "0.355746"], ["84155.6", "0"], ["84155.4", "0.049551"]], "a": [["84199.2", "0.203798"], ["84210", "0.076809"], ["84212.4", "0.119694"], ["84216.7", "0.11821"], ["84222.8", "0.114266"], ["84222.9", "0.171028"], ["84223.5", "0"], ["84223.7", "0.22078"], ["84229.9", "0.293592"], ["84230.7", "0.273565"], ["84252", "0"]], "u": 45331, "seq": 67552591019}, "cts": 1742560348517}}
{"exchange": "BITGET", "timestamp": 1742560348.672555, "message": {"action": "update", "arg": {"instType": "SPOT", "channel": "books", "instId": "BTCUSDT"}, "data": [{"asks": [["84174.00", "1.229626"], ["84174.53", "0.095066"], ["84174.55", "0"], ["84231.29", "0.473931"], ["84277.40", "5.339200"], ["84285.90", "4.886725"], ["84294.40", "4.977220"], ["84302.90", "4.705735"], ["84311.40", "4.524746"], ["84319.90", "4.072271"], ["84328.40", "5.610684"], ["84336.90", "5.429695"], ["84345.40", "5.520189"], ["84353.90", "4.434251"], ["84370.90", "3.981776"], ["84379.40", "5.248705"], ["84387.90", "5.067715"], ["84396.40", "5.158210"], ["84404.90", "4.615240"], ["84413.40", "4.343756"], ["84421.90", "4.253261"], ["84430.40", "3.891281"], ["84438.90", "4.796230"], ["84570.99", "0"]], "bids": [["84173.99", "1.003507"], ["84108.90", "5.429695"], ["84091.90", "5.520189"], ["84083.40", "4.253261"], ["84074.90", "5.339200"], ["84066.40", "5.610684"], ["84057.90", "3.891281"], ["84049.40", "5.067715"], ["84040.90", "4.434251"], ["84032.40", "4.886725"], ["84023.90", "4.162766"], ["84015.40", "4.524746"], ["84006.90", "5.158210"], ["83998.40", "4.977220"], ["83981.40", "4.072271"], ["83972.90", "5.248705"], ["83964.40", "4.615240"], ["83955.90", "4.343756"], ["83947.40", "3.981776"]], "checksum": 1266667314, "ts": "1742560348637"}], "ts": 1742560348640}}
{"exchange": "BYBIT", "timestamp": 1742560348.739271, "message": {"topic": "orderbook.200.BTCUSDT", "ts": 1742560348719, "type": "delta", "data": {"s": "BTCUSDT", "b": [["84199.1", "0.656732"], ["84180.5", "0.15012"], ["84155.9", "0"], ["84128.9", "0.003777"]], "a": [["84215.5", "0.160194"], ["84234.3", "0.012992"], ["84234.4", "0.012992"], ["84234.5", "0.001333"], ["84234.6", "0"], ["84235.3", "0.04"], ["84235.4", "0.040518"], ["84235.5", "0"], ["84235.6", "0"], ["84252", "2.562139"], ["84271.3", "0"]], "u": 45332, "seq": 67552591081}, "cts": 1742560348703}}
{"exchange": "BITGET", "timestamp": 1742560348.888623, "message": {"action": "update", "arg": {"instType": "SPOT", "channel": "books", "instId": "BTCUSDT"}, "data": [{"asks": [["84174.01", "0.000100"], ["84174.52", "0.059233"], ["84174.54", "0"], ["84200.00", "0.006356"], ["84200.56", "0"], ["84200.94", "0.016429"], ["84201.74", "0"], ["84277.40", "5.248705"], ["84285.90", "5.067715"], ["84294.40", "5.610684"], ["84302.90", "5.520189"], ["84311.40", "3.891281"], ["84319.90", "4.162766"], ["84328.40", "5.158210"], ["84336.90", "4.072271"], ["84345.40", "4.615240"], ["84353.90", "4.343756"], ["84362.40", "5.429695"], ["84370.90", "4.977220"], ["84379.40", "4.524746"], ["84387.90", "4.886725"], ["84396.40", "5.339200"], ["84404.90", "4.796230"], ["84413.40", "4.705735"], ["84421.90", "4.434251"], ["84430.40", "4.253261"], ["84438.90", "3.981776"]], "bids": [["84151.00", "7.935764"], ["84150.90", "0"], ["84150.33", "0.007330"], ["84124.00", "0.000017"], ["84123.00", "0"], ["84108.90", "4.434251"], ["84100.40", "5.248705"], ["84091.90", "5.429695"], ["84083.40", "4.886725"], ["84074.90", "5.520189"], ["84066.40", "4.072271"], ["84057.90", "5.158210"], ["84049.40", "5.339200"], ["84040.90", "4.524746"], ["84032.40", "4.615240"], ["84023.90", "4.343756"], ["84015.40", "4.162766"], ["84006.90", "3.981776"], ["83998.40", "5.610684"], ["83989.90", "5.067715"], ["83981.40", "4.253261"], ["83972.90", "4.796230"], ["83964.40", "4.977220"], ["83955.90", "3.891281"], ["83947.40", "4.705735"], ["83675.20", "0.000018"]], "checksum": -26805298, "ts": "1742560348854"}], "ts": 1742560348858}}
{"exchange": "BYBIT", "timestamp": 1742560348.943588, "message": {"topic": "orderbook.200.BTCUSDT", "ts": 1742560348920, "type": "delta", "data": {"s": "BTCUSDT", "b": [["84187.9", "0"], ["84183.8", "0.0002"], ["84177.4", "0"], ["84176.8", "0.049876"], ["84170.4", "0"], ["84169.8", "0.07296"], ["84160.5", "0.04"], ["84160.3", "0"], ["84159.5", "0.013"], ["84159.3", "0"], ["84155.6", "0.05"], ["84155.4", "0"], ["84127.1", "0.118793"], ["84126.3", "0.003564"], ["84125.8", "0.000333"]], "a": [["84203.6", "0.003551"], ["84210", "0.045398"], ["84212.4", "0"], ["84216.7", "0"], ["84222.9", "0"], ["84223.7", "0.04"], ["84229.9", "0.003293"], ["84230.7", "0.000518"], ["84252", "0"], ["84254.8", "2.562139"], ["84271.3", "0.12"], ["84272.1", "0.003292"]], "u": 45333, "seq": 67552591138}, "cts": 1742560348918}}
{"exchange": "BITGET", "timestamp": 1742560349.093825, "message": {"action": "update", "arg": {"instType": "SPOT", "channel": "books", "instId": "BTCUSDT"}, "data": [{"asks": [["84174.01", "0.000593"], ["84174.53", "0"], ["84239.70", "2.352720"], ["84247.70", "0"], ["84277.40", "3.891281"], ["84285.90", "5.610684"], ["84294.40", "4.615240"], ["84302.90", "4.253261"], ["84311.40", "3.981776"], ["84319.90", "4.343756"], ["84328.40", "4.705735"], ["84336.90", "4.524746"], ["84345.40", "4.796230"], ["84353.90", "5.520189"], ["84362.40", "5.067715"], ["84370.90", "5.429695"], ["84379.40", "4.162766"], ["84387.90", "5.248705"], ["84396.40", "5.158210"], ["84404.90", "4.434251"], ["84413.40", "4.977220"], ["84421.90", "5.339200"], ["84430.40", "4.886725"], ["84438.90", "4.072271"], ["84570.99", "0.000053"]], "bids": [["84169.00", "0.001173"], ["84167.00", "0.003086"], ["84165.00", "0.008122"], ["84163.00", "0.021374"], ["84161.00", "0.056247"], ["84159.00", "0.148019"], ["84157.00", "0.389523"], ["84155.00", "1.024936"], ["84153.00", "2.697198"], ["84151.00", "7.097890"], ["84122.00", "0.000032"], ["84108.90", "4.524746"], ["84100.40", "4.434251"], ["84091.90", "4.705735"], ["84083.40", "5.610684"], ["84074.90", "3.981776"], ["84066.40", "4.796230"], ["84057.90", "4.162766"], ["84040.90", "5.067715"], ["84032.40", "5.248705"], ["84015.40", "4.977220"], ["84006.90", "4.072271"], ["83998.40", "5.520189"], ["83989.90", "4.253261"], ["83981.40", "3.891281"], ["83972.90", "5.429695"], ["83964.40", "4.615240"], ["83955.90", "5.158210"], ["83947.40", "4.886725"]], "checksum": -704272037, "ts": "1742560349061"}], "ts": 1742560349066}}
{"exchange": "BYBIT", "timestamp": 1742560349.139264, "message": {"topic": "orderbook.200.BTCUSDT", "ts": 1742560349119, "type": "delta", "data": {"s": "BTCUSDT", "b": [["84180.5", "0.060107"], ["84160.5", "0"], ["84160.3", "0.039636"], ["84159.5", "0"], ["84159.3", "0.012882"], ["84155.6", "0"], ["84155.4", "0.049551"]], "a": [["84199.2", "0.374798"], ["84222.8", "0"], ["84234.3", "0"], ["84234.5", "0.014325"], ["84235.3", "0"], ["84235.5", "0.04"], ["84237.1", "0.06346"], ["84239.9", "0.059399"], ["84252", "2.562139"], ["84254.8", "0"], ["84271.6", "0.171"]], "u": 45334, "seq": 67552591222}, "cts": 1742560349116}}
{"exchange": "BITGET", "timestamp": 1742560349.37361, "message": {"action": "update", "arg": {"instType": "SPOT", "channel": "books", "instId": "BTCUSDT"}, "data": [{"asks": [["84174.00", "1.236521"], ["84174.51", "0.095066"], ["84174.52", "0"], ["84175.81", "0.030713"], ["84210.45", "0.493100"], ["84231.29", "0"], ["84239.70", "0"], ["84241.00", "2.352690"], ["84277.40", "5.339200"], ["84285.90", "4.977220"], ["84294.40", "4.524746"], ["84302.90", "3.891281"], ["84311.40", "4.615240"], ["84319.90", "4.072271"], ["84328.40", "4.253261"], ["84336.90", "3.981776"], ["84345.40", "5.610684"], ["84353.90", "5.248705"], ["84370.90", "4.886725"], ["84379.40", "5.158210"], ["84387.90", "4.705735"], ["84396.40", "4.434251"], ["84404.90", "4.796230"], ["84413.40", "4.162766"], ["84421.90", "5.520189"], ["84430.40", "5.429695"], ["84438.90", "4.343756"], ["84570.99", "0"]], "bids": [["84141.80", "0"], ["84138.00", "0.300000"], ["84108.90", "3.981776"], ["84100.40", "5.610684"], ["84091.90", "5.339200"], ["84083.40", "4.886725"], ["84074.90", "5.520189"], ["84066.40", "4.615240"], ["84057.90", "4.796230"], ["84049.40", "5.429695"], ["84040.90", "3.891281"], ["84032.40", "4.072271"], ["84023.90", "5.158210"], ["84015.40", "4.434251"], ["84006.90", "4.343756"], ["83998.40", "4.253261"], ["83989.90", "4.977220"], ["83981.40", "4.524746"], ["83972.90", "5.248705"], ["83964.40", "5.067715"], ["83955.90", "4.162766"], ["83947.40", "4.705735"], ["83675.00", "0.000458"]], "checksum": 496892523, "ts": "1742560349262"}], "ts": 1742560349266}}
{"exchange": "BYBIT", "timestamp": 1742560349.374224, "message": {"topic": "orderbook.200.BTCUSDT", "ts": 1742560349320, "type": "delta", "data": {"s": "BTCUSDT", "b": [["84171.4", "0.03128"], ["84160.4", "0"], ["84160.2", "0.039636"], ["84159.5", "0.013"], ["84159.3", "0"], ["84155.6", "0.05"], ["84155.4", "0"], ["84125.8", "0"]], "a": [["84234.3", "0.013"], ["84234.4", "0.012994"], ["84234.5", "0.001333"], ["84235.4", "0.000518"], ["84235.5", "0"], ["84235.6", "0.04"], ["84235.7", "0.04"], ["84271.1", "0"], ["84272.1", "0"]], "u": 45335, "seq": 67552591293}, "cts": 1742560349316}}
{"exchange": "BITGET", "timestamp": 1742560349.52592, "message": {"action": "update", "arg": {"instType": "SPOT", "channel": "books", "instId": "BTCUSDT"}, "data": [{"asks": [["84174.50", "0.059233"], ["84175.81", "0"], ["84235.50", "1.642860"], ["84241.00", "0"], ["84247.70", "2.670270"], ["84247.80", "1.350000"], ["84277.40", "5.610684"], ["84285.90", "5.339200"], ["84294.40", "4.434251"], ["84302.90", "4.615240"], ["84311.40", "4.072271"], ["84319.90", "4.977220"], ["84328.40", "4.343756"], ["84336.90", "4.796230"], ["84345.40", "4.253261"], ["84353.90", "4.886725"], ["84362.40", "4.705735"], ["84370.90", "3.891281"], ["84379.40", "5.067715"], ["84387.90", "4.162766"], ["84396.40", "3.981776"], ["84404.90", "4.524746"], ["84413.40", "5.248705"], ["84421.90", "5.429695"], ["84430.40", "5.158210"], ["84438.90", "5.520189"], ["84570.51", "0"]], "bids": [["84161.00", "0.056238"], ["84159.00", "0.147994"], ["84157.00", "0.389457"], ["84155.00", "1.024887"], ["84153.00", "2.697071"], ["84151.00", "7.097555"], ["84138.00", "0.000032"], ["84108.90", "5.520189"], ["84100.40", "4.253261"], ["84091.90", "4.705735"], ["84083.40", "5.067715"], ["84074.90", "3.891281"], ["84066.40", "5.248705"], ["84057.90", "4.343756"], ["84049.40", "4.977220"], ["84040.90", "4.524746"], ["84032.40", "5.339200"], ["84023.90", "4.162766"], ["84006.90", "4.886725"], ["83998.40", "5.158210"], ["83989.90", "5.429695"], ["83981.40", "4.796230"], ["83972.90", "4.615240"], ["83964.40", "4.072271"], ["83955.90", "3.981776"], ["83947.40", "5.610684"]], "checksum": -1728409387, "ts": "1742560349495"}], "ts": 1742560349499}}
{"exchange": "BYBIT", "timestamp": 1742560349.541176, "message": {"topic": "orderbook.200.BTCUSDT", "ts": 1742560349520, "type": "delta", "data": {"s": "BTCUSDT", "b": [["84160.5", "0.04"], ["84160.4", "0.039636"], ["84160.3", "0"], ["84160.2", "0"]], "a": [["84221.8", "0"], ["84234.1", "0.013"], ["84234.2", "0.016287"], ["84234.3", "0"], ["84234.4", "0"], ["84235.1", "0.04"], ["84235.2", "0.040333"], ["84235.6", "0"], ["84235.7", "0"], ["84272.1", "0.003292"], ["84272.3", "0.05728"], ["84272.4", "0.001853"]], "u": 45336, "seq": 67552591360}, "cts": 1742560349516}}
{"exchange": "BYBIT", "timestamp": 1742560349.741766, "message": {"topic": "orderbook.200.BTCUSDT", "ts": 1742560349720, "type": "delta", "data": {"s": "BTCUSDT", "b": [], "a": [["84203.6", "0"], ["84216.2", "0.003551"], ["84219.6", "0.003"], ["84223.5", "0.061308"], ["84235.1", "0"], ["84235.2", "0.000333"], ["84235.3", "0.04"], ["84235.4", "0.040518"], ["84240.1", "0.003"], ["84272.1", "0"], ["84272.3", "0"], ["84272.4", "0"]], "u": 45337, "seq": 67552591419}, "cts": 1742560349714}}
{"exchange": "BITGET", "timestamp": 1742560349.762095, "message": {"action": "update", "arg": {"instType": "SPOT", "channel": "books", "instId": "BTCUSDT"}, "data": [{"asks": [["84174.01", "0.001043"], ["84174.50", "0.154299"], ["84174.51", "0"], ["84231.17", "0.001598"], ["84233.32", "0"], ["84277.40", "5.429695"], ["84285.90", "4.434251"], ["84294.40", "3.981776"], ["84302.90", "5.520189"], ["84319.90", "3.891281"], ["84328.40", "5.158210"], ["84345.40", "4.705735"], ["84353.90", "4.343756"], ["84362.40", "4.253261"], ["84370.90", "5.248705"], ["84379.40", "4.524746"], ["84387.90", "4.886725"], ["84396.40", "5.067715"], ["84404.90", "4.977220"], ["84413.40", "4.615240"], ["84421.90", "5.610684"], ["84430.40", "4.162766"], ["84438.90", "5.339200"], ["84570.51", "0.000170"]], "bids": [["84161.01", "0"], ["84155.00", "1.024997"], ["84153.00", "2.697361"], ["84151.00", "7.098318"], ["84122.88", "0"], ["84121.00", "0.000015"], ["84120.73", "0.001174"], ["84108.90", "5.158210"], ["84100.40", "5.520189"], ["84091.90", "4.524746"], ["84083.40", "4.434251"], ["84066.40", "4.615240"], ["84057.90", "5.610684"], ["84049.40", "5.429695"], ["84040.90", "5.067715"], ["84032.40", "4.886725"], ["84023.90", "5.248705"], ["84015.40", "4.977220"], ["84006.90", "3.981776"], ["83998.40", "5.339200"], ["83989.90", "4.343756"], ["83981.40", "4.705735"], ["83972.90", "4.072271"], ["83964.40", "4.253261"], ["83955.90", "4.796230"], ["83947.40", "4.162766"]], "checksum": -1118371844, "ts": "1742560349729"}], "ts": 1742560349735}}
{"exchange": "BYBIT", "timestamp": 1742560349.939199, "message": {"topic": "orderbook.200.BTCUSDT", "ts": 1742560349919, "type": "delta", "data": {"s": "BTCUSDT", "b": [["84160.5", "0"], ["84160.3", "0.039636"], ["84159.5", "0"], ["84159.3", "0.012882"], ["84155.6", "0"], ["84155.4", "0.049551"]], "a": [["84234.1", "0"], ["84234.2", "0.003293"], ["84234.5", "0.014333"], ["84234.6", "0.012994"], ["84235.3", "0"], ["84235.4", "0.000518"], ["84235.5", "0.04"], ["84235.6", "0.04"], ["84271.6", "0"]], "u": 45338, "seq": 67552591483}, "cts": 1742560349916}}
{"exchange": "BITGET", "timestamp": 1742560349.9775, "message": {"action": "update", "arg": {"instType": "SPOT", "channel": "books", "instId": "BTCUSDT"}, "data": [{"asks": [["84174.00", "1.246157"], ["84174.01", "0.000550"], ["84174.49", "0.059233"], ["84174.50", "0.095066"], ["84214.32", "0.010000"], ["84231.30", "0.826245"], ["84233.14", "0.001597"], ["84233.30", "2.174329"], ["84235.24", "0"], ["84235.30", "5.721918"], ["84235.50", "0.999570"], ["84239.40", "0.015000"], ["84277.40", "5.158210"], ["84285.90", "4.343756"], ["84294.40", "4.796230"], ["84302.90", "5.339200"], ["84311.40", "5.520189"], ["84319.90", "4.886725"], ["84328.40", "3.891281"], ["84336.90", "5.610684"], ["84345.40", "5.248705"], ["84353.90", "4.072271"], ["84362.40", "4.524746"], ["84370.90", "4.434251"], ["84379.40", "5.067715"], ["84387.90", "4.615240"], ["84396.40", "3.981776"], ["84404.90", "5.429695"], ["84413.40", "4.977220"], ["84421.90", "4.705735"], ["84430.40", "4.253261"], ["84438.90", "4.162766"], ["84569.23", "0"], ["84570.51", "0"]], "bids": [["84172.18", "0"], ["84169.01", "0.000241"], ["84148.20", "0.009000"], ["84124.00", "0"], ["84120.93", "0"], ["84118.83", "0.001171"], ["84108.90", "5.067715"], ["84100.40", "5.248705"], ["84091.90", "4.705735"], ["84083.40", "4.253261"], ["84074.90", "4.072271"], ["84057.90", "4.796230"], ["84049.40", "4.524746"], ["84040.90", "3.981776"], ["84032.40", "5.520189"], ["84023.90", "4.343756"], ["84015.40", "4.434251"], ["84006.90", "5.158210"], ["83998.40", "4.886725"], ["83989.90", "4.162766"], ["83981.40", "4.977220"], ["83972.90", "5.610684"], ["83964.40", "3.891281"], ["83955.90", "5.429695"], ["83947.40", "5.339200"]], "checksum": 1357490654, "ts": "1742560349943"}], "ts": 1742560349947}}
{"exchange": "BYBIT", "timestamp": 1742560350.141619, "message": {"topic": "orderbook.200.BTCUSDT", "ts": 1742560350120, "type": "delta", "data": {"s": "BTCUSDT", "b": [["84187.9", "0.117566"], ["84183.8", "0.120485"], ["84177.4", "0.180324"], ["84176.8", "0.2256"], ["84170.4", "0.276468"], ["84169.8", "0.360612"], ["84159.5", "0.013"], ["84159.3", "0"], ["84155.6", "0.05"], ["84155.4", "0"], ["84128.9", "0"], ["84127.1", "0"], ["84126.3", "0"]], "a": [["84199.2", "0.203798"], ["84210", "0.075895"], ["84212.4", "0.116646"], ["84216.7", "0.110713"], ["84220.7", "0.035317"], ["84222.9", "0.163903"], ["84223.7", "0.209405"], ["84229.9", "0.306292"], ["84230.7", "0.273899"], ["84234.4", "0.013"], ["84234.5", "0.014327"], ["84234.6", "0"], ["84271", "0"], ["84271.2", "0"], ["84271.3", "0"]], "u": 45339, "seq": 67552591570}, "cts": 1742560350114}}
{"exchange": "BITGET", "timestamp": 1742560350.188873, "message": {"action": "update", "arg": {"instType": "SPOT", "channel": "books", "instId": "BTCUSDT"}, "data": [{"asks": [["84174.50", "0"], ["84175.82", "0"], ["84219.30", "0.002124"], ["84221.30", "0.005589"], ["84223.30", "0.014708"], ["84225.30", "0.038706"], ["84227.30", "0.101857"], ["84229.30", "0.268045"], ["84231.30", "0.705382"], ["84233.30", "1.856269"], ["84235.30", "4.884918"], ["84236.10", "0.020280"], ["84247.80", "0"], ["84277.40", "4.072271"], ["84285.90", "5.339200"], ["84302.90", "5.610684"], ["84311.40", "4.886725"], ["84319.90", "5.520189"], ["84328.40", "4.253261"], ["84336.90", "4.977220"], ["84345.40", "4.615240"], ["84353.90", "4.705735"], ["84362.40", "5.158210"], ["84370.90", "5.429695"], ["84379.40", "4.524746"], ["84387.90", "3.891281"], ["84396.40", "5.067715"], ["84404.90", "4.162766"], ["84413.40", "4.343756"], ["84421.90", "5.248705"], ["84430.40", "4.434251"], ["84438.90", "3.981776"], ["84569.23", "0.000009"], ["84570.51", "0.000170"]], "bids": [["84169.00", "0.001311"], ["84167.00", "0.003450"], ["84165.00", "0.009079"], ["84163.00", "0.023893"], ["84161.00", "0.062875"], ["84159.00", "0.165462"], ["84157.00", "0.435427"], ["84155.00", "1.145860"], ["84153.00", "3.015421"], ["84151.00", "7.935318"], ["84150.42", "0"], ["84149.24", "0.008174"], ["84139.30", "0"], ["84138.03", "0.000875"], ["84120.86", "0"], ["84119.63", "0.003592"], ["84108.90", "4.253261"], ["84100.40", "4.615240"], ["84091.90", "5.067715"], ["84083.40", "4.977220"], ["84074.90", "4.524746"], ["84066.40", "3.891281"], ["84057.90", "5.610684"], ["84049.40", "4.162766"], ["84040.90", "5.339200"], ["84032.40", "4.796230"], ["84015.40", "5.158210"], ["84006.90", "5.429695"], ["83998.40", "3.981776"], ["83989.90", "4.705735"], ["83981.40", "4.434251"], ["83972.90", "4.072271"], ["83964.40", "5.520189"], ["83955.90", "5.248705"], ["83947.40", "4.886725"]], "checksum": -1492381167, "ts": "1742560350158"}], "ts": 1742560350161}}
{"exchange": "BYBIT", "timestamp": 1742560350.421687, "message": {"topic": "orderbook.200.BTCUSDT", "ts": 1742560350320, "type": "delta", "data": {"s": "BTCUSDT", "b": [["84199.1", "0.657332"], ["84180.5", "0.159449"], ["84160.7", "0.051519"], ["84160.6", "0.039636"], ["84160.4", "0"], ["84160.3", "0"], ["84159.7", "0.012882"], ["84159.6", "0.012882"], ["84159.5", "0"], ["84159.4", "0.000333"], ["84155.8", "0.04955"], ["84155.7", "0.069493"], ["84155.6", "0"], ["84155.5", "0"], ["84128.9", "0.003777"]], "a": [["84234.4", "0"], ["84234.6", "0.012994"]], "u": 45340, "seq": 67552591644}, "cts": 1742560350316}}
{"exchange": "BITGET", "timestamp": 1742560350.422159, "message": {"action": "update", "arg": {"instType": "SPOT", "channel": "books", "instId": "BTCUSDT"}, "data": [{"asks": [["84174.00", "1.241157"], ["84174.48", "0.095066"], ["84174.49", "0.014281"], ["84174.97", "0.054775"], ["84195.83", "0.061485"], ["84204.08", "0"], ["84219.30", "0.002487"], ["84221.30", "0.006547"], ["84223.30", "0.017228"], ["84225.30", "0.045338"], ["84227.30", "0.119310"], ["84229.30", "0.313973"], ["84231.30", "0.826245"], ["84233.30", "2.174329"], ["84235.30", "5.721918"], ["84236.10", "0"], ["84239.40", "0"], ["84247.80", "1.350000"], ["84277.40", "5.339200"], ["84285.90", "4.434251"], ["84294.40", "5.158210"], ["84302.90", "4.524746"], ["84311.40", "4.615240"], ["84319.90", "5.610684"], ["84328.40", "4.705735"], ["84336.90", "4.162766"], ["84345.40", "4.977220"], ["84353.90", "5.248705"], ["84362.40", "5.520189"], ["84370.90", "4.343756"], ["84379.40", "4.886725"], ["84387.90", "4.253261"], ["84396.40", "5.429695"], ["84404.90", "4.796230"], ["84413.40", "3.981776"], ["84421.90", "5.067715"], ["84430.40", "4.072271"], ["84438.90", "3.891281"], ["84570.51", "0"]], "bids": [["84173.99", "1.002229"], ["84172.18", "0.065792"], ["84159.00", "0.165198"], ["84157.00", "0.434733"], ["84155.00", "1.144033"], ["84153.00", "3.010615"], ["84151.00", "7.922670"], ["84141.60", "0.978840"], ["84138.20", "3.507750"], ["84108.90", "4.072271"], ["84100.40", "5.610684"], ["84091.90", "5.158210"], ["84083.40", "3.981776"], ["84074.90", "4.343756"], ["84066.40", "4.977220"], ["84057.90", "5.248705"], ["84049.40", "4.434251"], ["84040.90", "4.796230"], ["84032.40", "4.253261"], ["84023.90", "4.705735"], ["84015.40", "5.067715"], ["84006.90", "5.339200"], ["83998.40", "4.524746"], ["83989.90", "3.891281"], ["83981.40", "4.615240"], ["83972.90", "5.520189"], ["83964.40", "4.162766"], ["83955.90", "4.886725"], ["83947.40", "5.429695"], ["83675.00", "0"]], "checksum": 1407033843, "ts": "1742560350367"}], "ts": 1742560350372}}
{"exchange": "BYBIT", "timestamp": 1742560350.539949, "message": {"topic": "orderbook.200.BTCUSDT", "ts": 1742560350519, "type": "delta", "data": {"s": "BTCUSDT", "b": [["84199.1", "0.828332"], ["84187.9", "0"], ["84183.8", "0.0002"], ["84177.4", "0"], ["84176.8", "0.049876"], ["84171.4", "0.196606"], ["84170.4", "0"], ["84169.8", "0.07296"], ["84127.1", "0.118793"], ["84126.3", "0.003564"], ["84125.8", "0.000333"]], "a": [["84199.2", "0.103798"], ["84210", "0.045398"], ["84212.4", "0"], ["84216.2", "0"], ["84216.7", "0"], ["84222.9", "0"], ["84223.7", "0.04"], ["84229.9", "0.003293"], ["84230.7", "0.000518"], ["84271", "0.237586"], ["84271.2", "0.12"], ["84271.3", "0.12"], ["84272.1", "0.003292"]], "u": 45341, "seq": 67552591740}, "cts": 1742560350517}}
{"exchange": "BITGET", "timestamp": 1742560350.610506, "message": {"action": "update", "arg": {"instType": "SPOT", "channel": "books", "instId": "BTCUSDT"}, "data": [{"asks": [["84174.00", "1.218430"], ["84174.47", "0.059233"], ["84174.49", "0"], ["84174.97", "0"], ["84201.10", "0"], ["84204.92", "0.179910"], ["84219.30", "0.002124"], ["84221.30", "0.005589"], ["84223.30", "0.014708"], ["84225.30", "0.038706"], ["84227.30", "0.101857"], ["84229.30", "0.268045"], ["84231.30", "0.705382"], ["84233.30", "1.856269"], ["84235.30", "4.884658"], ["84236.30", "0.034020"], ["84239.40", "0.030000"], ["84247.80", "0"], ["84277.40", "4.162766"], ["84285.90", "4.886725"], ["84294.40", "4.796230"], ["84302.90", "5.339200"], ["84311.40", "4.705735"], ["84319.90", "4.524746"], ["84328.40", "4.615240"], ["84336.90", "3.891281"], ["84345.40", "4.253261"], ["84353.90", "5.158210"], ["84362.40", "5.429695"], ["84370.90", "4.434251"], ["84379.40", "4.977220"], ["84387.90", "4.072271"], ["84396.40", "5.067715"], ["84404.90", "3.981776"], ["84413.40", "5.520189"], ["84421.90", "5.610684"], ["84430.40", "5.248705"], ["84438.90", "4.343756"]], "bids": [["84171.38", "0"], ["84148.20", "0"], ["84108.90", "4.434251"], ["84100.40", "4.615240"], ["84091.90", "5.610684"], ["84083.40", "4.977220"], ["84074.90", "3.891281"], ["84066.40", "4.072271"], ["84057.90", "4.705735"], ["84049.40", "3.981776"], ["84040.90", "4.886725"], ["84023.90", "4.524746"], ["84015.40", "5.158210"], ["84006.90", "5.248705"], ["83998.40", "4.796230"], ["83989.90", "4.162766"], ["83981.40", "5.520189"], ["83972.90", "5.067715"], ["83964.40", "5.429695"], ["83955.90", "4.343756"], ["83947.40", "5.339200"], ["83675.00", "0.000458"], ["83674.70", "0.000008"]], "checksum": -421843870, "ts": "1742560350575"}], "ts": 1742560350579}}
{"exchange": "BYBIT", "timestamp": 1742560350.740985, "message": {"topic": "orderbook.200.BTCUSDT", "ts": 1742560350720, "type": "delta", "data": {"s": "BTCUSDT", "b": [["84180.5", "0.060107"], ["84171.4", "0.03128"]], "a": [["84204.8", "0"], ["84220.6", "0.035317"], ["84220.7", "0"], ["84222.3", "0.003551"], ["84234.5", "0.001333"], ["84234.6", "0"], ["84234.7", "0.131787"], ["84234.8", "0.012994"], ["84235.5", "0"], ["84235.6", "0"], ["84235.7", "0.04"], ["84235.8", "0.04"], ["84271.6", "0.171"], ["84272.1", "0"]], "u": 45342, "seq": 67552591808}, "cts": 1742560350709}}
{"exchange": "BITGET", "timestamp": 1742560350.805263, "message": {"action": "update", "arg": {"instType": "SPOT", "channel": "books", "instId": "BTCUSDT"}, "data": [{"asks": [["84174.01", "0.000100"], ["84174.46", "0.095066"], ["84174.47", "0.042800"], ["84174.48", "0"], ["84176.36", "0.054775"], ["84219.30", "0.001879"], ["84221.30", "0.004944"], ["84223.30", "0.013009"], ["84225.30", "0.034236"], ["84227.30", "0.090095"], ["84229.30", "0.237091"], ["84231.30", "0.623923"], ["84233.30", "1.641903"], ["84235.30", "4.320557"], ["84235.60", "0.001009"], ["84235.90", "0.964110"], ["84236.30", "0.256170"], ["84237.60", "0.066000"], ["84242.80", "2.352630"], ["84247.70", "0"], ["84277.40", "5.248705"], ["84285.90", "5.067715"], ["84294.40", "4.162766"], ["84302.90", "5.158210"], ["84311.40", "5.339200"], ["84319.90", "4.253261"], ["84328.40", "4.796230"], ["84336.90", "3.981776"], ["84345.40", "4.977220"], ["84353.90", "4.343756"], ["84362.40", "4.524746"], ["84370.90", "5.610684"], ["84379.40", "4.705735"], ["84396.40", "3.891281"], ["84404.90", "5.429695"], ["84413.40", "4.886725"], ["84421.90", "4.615240"], ["84430.40", "5.520189"], ["84438.90", "4.434251"], ["84568.81", "0"], ["84568.97", "0"], ["84569.23", "0"]], "bids": [["84169.00", "0.001678"], ["84167.00", "0.004415"], ["84165.00", "0.011618"], ["84163.00", "0.030573"], ["84161.00", "0.080457"], ["84159.00", "0.211729"], ["84157.00", "0.557180"], ["84155.00", "1.466265"], ["84153.00", "3.858591"], ["84151.00", "10.154186"], ["84122.00", "0.000017"], ["84100.40", "3.891281"], ["84091.90", "4.524746"], ["84083.40", "4.705735"], ["84074.90", "5.429695"], ["84066.40", "4.796230"], ["84057.90", "4.253261"], ["84049.40", "4.615240"], ["84040.90", "3.981776"], ["84032.40", "5.067715"], ["84023.90", "4.977220"], ["84015.40", "5.520189"], ["84006.90", "4.072271"], ["83998.40", "4.162766"], ["83989.90", "5.610684"], ["83981.40", "5.339200"], ["83972.90", "5.158210"], ["83964.40", "5.248705"], ["83955.90", "4.886725"], ["83947.40", "4.343756"]], "checksum": -2025924424, "ts": "1742560350777"}], "ts": 1742560350780}}
{"exchange": "BYBIT", "timestamp": 1742560350.945083, "message": {"topic": "orderbook.200.BTCUSDT", "ts": 1742560350919, "type": "delta", "data": {"s": "BTCUSDT", "b": [], "a": [["84234.7", "0.118793"], ["84234.9", "0.012994"], ["84235.7", "0"], ["84235.9", "0.063754"]], "u": 45343, "seq": 67552591848}, "cts": 1742560350899}}
{"exchange": "BITGET", "timestamp": 1742560351.011169, "message": {"action": "update", "arg": {"instType": "SPOT", "channel": "books", "instId": "BTCUSDT"}, "data": [{"asks": [["84174.00", "1.226355"], ["84174.01", "0.000117"], ["84174.45", "0.059233"], ["84174.47", "0"], ["84175.46", "0.054775"], ["84176.36", "0"], ["84219.30", "0.002510"], ["84221.30", "0.006605"], ["84223.30", "0.017384"], ["84225.30", "0.045745"], ["84227.30", "0.120382"], ["84229.30", "0.316796"], ["84231.30", "0.833674"], ["84233.30", "2.193759"], ["84235.30", "5.773049"], ["84236.30", "0"], ["84237.60", "0.239640"], ["84240.90", "2.352690"], ["84242.80", "0"], ["84247.70", "2.670270"], ["84247.80", "1.350000"], ["84277.40", "5.610684"], ["84285.90", "5.158210"], ["84294.40", "4.886725"], ["84302.90", "4.434251"], ["84311.40", "3.981776"], ["84319.90", "3.891281"], ["84328.40", "4.977220"], ["84336.90", "5.520189"], ["84345.40", "4.524746"], ["84353.90", "4.072271"], ["84362.40", "4.796230"], ["84370.90", "4.253261"], ["84387.90", "4.615240"], ["84396.40", "5.429695"], ["84404.90", "5.339200"], ["84413.40", "4.162766"], ["84421.90", "5.067715"], ["84430.40", "5.248705"], ["84438.90", "4.343756"], ["84568.60", "0"]], "bids": [["84169.00", "0.001506"], ["84167.00", "0.003962"], ["84165.00", "0.010427"], ["84163.00", "0.027439"], ["84161.02", "0.097828"], ["84161.00", "0.072210"], ["84159.00", "0.190025"], ["84157.00", "0.500066"], ["84155.00", "1.316096"], ["84153.00", "3.463412"], ["84151.00", "9.114242"], ["84123.00", "0.000017"], ["84108.90", "4.886725"], ["84100.40", "5.158210"], ["84091.90", "5.520189"], ["84083.40", "4.072271"], ["84074.91", "0"], ["84074.90", "4.524746"], ["84066.40", "4.253261"], ["84057.90", "4.162766"], ["84049.40", "5.248705"], ["84040.90", "4.343756"], ["84032.40", "4.615240"], ["84023.90", "4.796230"], ["84015.40", "5.067715"], ["84006.90", "5.610684"], ["83998.40", "5.339200"], ["83989.90", "3.891281"], ["83981.40", "5.429695"], ["83972.90", "3.981776"], ["83964.40", "4.705735"], ["83955.90", "4.434251"], ["83947.40", "4.977220"]], "checksum": 1218410162, "ts": "1742560350982"}], "ts": 1742560350986}}
{"exchange": "BYBIT", "timestamp": 1742560351.146987, "message": {"topic": "orderbook.200.BTCUSDT", "ts": 1742560351120, "type": "delta", "data": {"s": "BTCUSDT", "b": [["84199.1", "0.657332"]], "a": [["84220.6", "0"], ["84220.7", "0.035844"], ["84222.3", "0"], ["84234.7", "0.131793"], ["84234.9", "0"], ["84272.1", "0.003292"], ["84272.3", "0.05728"]], "u": 45344, "seq": 67552591913}, "cts": 1742560351113}}
{"exchange": "BITGET", "timestamp": 1742560351.210179, "message": {"action": "update", "arg": {"instType": "SPOT", "channel": "books", "instId": "BTCUSDT"}, "data": [{"asks": [["84174.00", "1.218430"], ["84174.46", "0"], ["84219.30", "0.002391"], ["84221.30", "0.006291"], ["84222.58", "0.026648"], ["84223.30", "0.016556"], ["84225.30", "0.043569"], ["84227.30", "0.114655"], ["84229.30", "0.301722"], ["84231.30", "0.794007"], ["84233.30", "2.089492"], ["84235.30", "5.498495"], ["84236.80", "0.007620"], ["84237.60", "0"], ["84247.49", "0.007925"], ["84247.80", "0"], ["84285.90", "4.162766"], ["84294.40", "4.253261"], ["84302.90", "5.248705"], ["84311.40", "5.339200"], ["84319.90", "4.977220"], ["84328.40", "4.705735"], ["84345.40", "4.615240"], ["84362.40", "4.886725"], ["84370.90", "4.524746"], ["84379.40", "5.429695"], ["84387.90", "3.981776"], ["84396.40", "5.158210"], ["84404.90", "5.067715"], ["84413.40", "3.891281"], ["84421.90", "4.796230"], ["84430.40", "4.434251"]], "bids": [["84169.00", "0.001367"], ["84167.00", "0.003598"], ["84165.00", "0.009468"], ["84163.00", "0.024917"], ["84161.00", "0.065571"], ["84159.00", "0.172555"], ["84157.00", "0.454091"], ["84155.00", "1.194976"], ["84153.00", "3.144673"], ["84151.00", "8.275456"], ["84108.90", "4.162766"], ["84100.40", "4.434251"], ["84091.90", "4.253261"], ["84083.40", "5.248705"], ["84074.90", "4.977220"], ["84066.40", "5.610684"], ["84057.90", "4.072271"], ["84049.40", "3.981776"], ["84040.90", "4.524746"], ["84032.40", "5.339200"], ["84015.40", "4.615240"], ["84006.90", "4.886725"], ["83998.40", "4.343756"], ["83989.90", "5.520189"], ["83981.40", "5.067715"], ["83972.90", "5.158210"], ["83955.90", "5.429695"], ["83947.40", "3.891281"]], "checksum": 820661728, "ts": "1742560351182"}], "ts": 1742560351184}}
{"exchange": "BYBIT", "timestamp": 1742560351.340038, "message": {"topic": "orderbook.200.BTCUSDT", "ts": 1742560351320, "type": "delta", "data": {"s": "BTCUSDT", "b": [["84199.1", "0.655551"], ["84187.3", "0.114723"], ["84183.2", "0.114556"], ["84176.8", "0.236698"], ["84176.2", "0.165723"], ["84169.8", "0.348271"], ["84169.2", "0.299799"], ["84160.7", "0.011883"], ["84160.6", "0"], ["84160.5", "0.039636"], ["84160.4", "0.039636"], ["84159.7", "0"], ["84159.6", "0"], ["84159.5", "0.012882"], ["84159.4", "0.013215"], ["84156.2", "0.001781"], ["84155.8", "0"], ["84155.7", "0.019942"], ["84155.6", "0.049551"], ["84155.5", "0.049551"], ["84129.3", "0"], ["84129.2", "0"], ["84128.9", "0"], ["84127.1", "0"], ["84126.3", "0"], ["84125.8", "0"]], "a": [["84199.2", "0.274798"], ["84210", "0.077503"], ["84211.8", "0.122005"], ["84216.1", "0.116929"], ["84222.3", "0.183187"], ["84223.1", "0.171232"], ["84229.3", "0.310775"], ["84230.1", "0.289363"], ["84234.5", "0.014327"], ["84234.6", "0.012994"], ["84234.7", "0.118793"], ["84234.8", "0"], ["84235.5", "0.04"], ["84235.6", "0.04"], ["84235.8", "0"], ["84235.9", "0.023754"], ["84270.9", "0"], ["84271", "0"], ["84271.2", "0"], ["84271.3", "0"], ["84271.6", "0"], ["84272.1", "0"], ["84272.3", "0"]], "u": 45345, "seq": 67552591992}, "cts": 1742560351314}}
{"exchange": "BITGET", "timestamp": 1742560351.470206, "message": {"action": "update", "arg": {"instType": "SPOT", "channel": "books", "instId": "BTCUSDT"}, "data": [{"asks": [["84174.44", "0.095066"], ["84174.45", "0.030713"], ["84225.30", "0.043413"], ["84227.30", "0.114245"], ["84229.30", "0.300645"], ["84231.30", "0.791170"], ["84233.30", "2.082028"], ["84235.30", "5.479021"], ["84240.90", "0"], ["84285.90", "4.796230"], ["84294.40", "4.886725"], ["84302.90", "5.520189"], ["84311.40", "3.891281"], ["84319.90", "5.429695"], ["84336.90", "4.434251"], ["84345.40", "5.067715"], ["84362.40", "5.339200"], ["84370.90", "3.981776"], ["84379.40", "4.162766"], ["84387.90", "4.524746"], ["84396.40", "4.977220"], ["84404.90", "4.615240"], ["84413.40", "5.248705"], ["84421.90", "4.343756"], ["84430.40", "5.158210"], ["84438.90", "4.253261"]], "bids": [["84108.90", "5.248705"], ["84100.40", "5.158210"], ["84091.90", "3.981776"], ["84083.40", "4.524746"], ["84074.90", "4.615240"], ["84066.40", "4.072271"], ["84057.90", "5.610684"], ["84049.40", "4.434251"], ["84040.90", "4.162766"], ["84032.40", "5.067715"], ["84023.90", "4.253261"], ["84015.40", "4.886725"], ["84006.90", "5.520189"], ["83998.40", "4.705735"], ["83989.90", "5.429695"], ["83981.40", "4.343756"], ["83972.90", "4.796230"], ["83964.40", "4.977220"], ["83955.90", "5.339200"]], "checksum": 432734352, "ts": "1742560351395"}], "ts": 1742560351397}}
{"exchange": "BYBIT", "timestamp": 1742560351.539721, "message": {"topic": "orderbook.200.BTCUSDT", "ts": 1742560351520, "type": "delta", "data": {"s": "BTCUSDT", "b": [["84187.3", "0.109263"], ["84183.2", "0.111968"], ["84180.5", "0.108682"], ["84176.8", "0.219033"], ["84176.2", "0.175875"], ["84169.8", "0.374712"], ["84169.2", "0.282167"], ["84155.7", "0.069942"], ["84155.5", "0"], ["84129.3", "0.001333"]], "a": [["84199.2", "0.103798"], ["84210", "0.045398"], ["84211.8", "0.123969"], ["84216.1", "0.109753"], ["84218.8", "0.096427"], ["84222.3", "0.166573"], ["84223.1", "0.181484"], ["84227.3", "0.273512"], ["84229.3", "0.274609"], ["84230.1", "0.307982"], ["84234.3", "0.012994"], ["84234.4", "0.012994"], ["84234.5", "0.001333"], ["84234.6", "0"], ["84235.3", "0.04"], ["84235.4", "0.040518"], ["84235.5", "0"], ["84235.6", "0"], ["84270.6", "0"]], "u": 45346, "seq": 67552592100}, "cts": 1742560351516}}
{"exchange": "BITGET", "timestamp": 1742560351.633002, "message": {"action": "update", "arg": {"instType": "SPOT", "channel": "books", "instId": "BTCUSDT"}, "data": [{"asks": [["84174.01", "0.000132"], ["84174.43", "0.059233"], ["84174.45", "0"], ["84236.80", "0.324030"], ["84277.40", "5.067715"], ["84285.90", "4.886725"], ["84294.40", "4.977220"], ["84302.90", "4.343756"], ["84319.90", "5.339200"], ["84328.40", "4.434251"], ["84336.90", "4.524746"], ["84345.40", "5.158210"], ["84353.90", "4.615240"], ["84362.40", "4.162766"], ["84370.90", "5.520189"], ["84379.40", "5.429695"], ["84387.90", "4.072271"], ["84396.40", "4.705735"], ["84404.90", "5.610684"], ["84413.40", "4.796230"], ["84421.90", "3.981776"], ["84430.40", "4.253261"], ["84438.90", "5.248705"]], "bids": [["84173.99", "0.999853"], ["84157.00", "0.454194"], ["84155.00", "1.195247"], ["84153.00", "3.145387"], ["84151.00", "8.277335"], ["84124.00", "0.000015"], ["84100.40", "4.796230"], ["84091.90", "5.610684"], ["84074.90", "5.158210"], ["84066.40", "4.253261"], ["84057.90", "5.339200"], ["84049.40", "4.162766"], ["84040.90", "4.977220"], ["84032.40", "4.072271"], ["84023.90", "3.981776"], ["84015.40", "5.067715"], ["84006.90", "4.705735"], ["83998.40", "4.434251"], ["83989.90", "4.343756"], ["83981.40", "4.615240"], ["83972.90", "5.429695"], ["83964.40", "4.886725"], ["83955.90", "3.891281"], ["83947.40", "5.520189"], ["83674.70", "0"]], "checksum": -870058610, "ts": "1742560351604"}], "ts": 1742560351607}}
{"exchange": "BYBIT", "timestamp": 1742560351.743345, "message": {"topic": "orderbook.200.BTCUSDT", "ts": 1742560351720, "type": "delta", "data": {"s": "BTCUSDT", "b": [["84187.3", "0"], ["84183.2", "0"], ["84176.8", "0.049876"], ["84176.2", "0"], ["84171.4", "0.202546"], ["84169.8", "0.07296"], ["84169.2", "0"], ["84155.7", "0.019942"], ["84155.5", "0.049551"], ["84129.2", "0.00009"], ["84128.9", "0.003777"], ["84127.1", "0.118793"]], "a": [["84211.8", "0"], ["84216.1", "0"], ["84218.4", "0.287475"], ["84222.3", "0"], ["84223.1", "0"], ["84229.3", "0"], ["84230.1", "0"], ["84240.1", "0"], ["84270.6", "0.04"], ["84270.9", "0.04"], ["84271", "0.237586"], ["84271.2", "0.12"], ["84271.3", "0.12"], ["84272.1", "0.003292"], ["84272.3", "0.05728"]], "u": 45347, "seq": 67552592177}, "cts": 1742560351716}}
{"exchange": "BITGET", "timestamp": 1742560351.836928, "message": {"action": "update", "arg": {"instType": "SPOT", "channel": "books", "instId": "BTCUSDT"}, "data": [{"asks": [["84174.00", "1.222051"], ["84174.01", "0.000115"], ["84174.43", "0.154299"], ["84174.44", "0"], ["84200.93", "0.056928"], ["84247.80", "1.350000"], ["84277.40", "4.705735"], ["84285.90", "4.253261"], ["84294.40", "4.796230"], ["84302.90", "4.072271"], ["84311.40", "4.886725"], ["84319.90", "4.434251"], ["84328.40", "4.977220"], ["84336.90", "5.429695"], ["84345.40", "3.891281"], ["84353.90", "5.158210"], ["84362.40", "5.520189"], ["84370.90", "4.524746"], ["84379.40", "5.067715"], ["84387.90", "5.610684"], ["84396.40", "4.615240"], ["84404.90", "4.343756"], ["84413.40", "4.162766"], ["84430.40", "5.248705"], ["84438.90", "5.339200"], ["84567.79", "0"]], "bids": [["84122.00", "0"], ["84108.90", "4.977220"], ["84100.40", "4.343756"], ["84091.90", "5.520189"], ["84083.40", "4.072271"], ["84074.90", "4.615240"], ["84066.40", "3.981776"], ["84057.90", "3.891281"], ["84049.40", "5.339200"], ["84040.90", "5.248705"], ["84032.40", "4.524746"], ["84023.90", "5.429695"], ["84015.40", "4.886725"], ["84006.90", "5.158210"], ["83998.40", "4.162766"], ["83989.90", "4.705735"], ["83981.40", "4.253261"], ["83972.90", "4.796230"], ["83964.40", "5.067715"], ["83955.90", "5.610684"], ["83947.40", "4.434251"], ["83674.70", "0.000008"]], "checksum": 896576761, "ts": "1742560351807"}], "ts": 1742560351811}}
{"exchange": "BYBIT", "timestamp": 1742560351.992849, "message": {"topic": "orderbook.200.BTCUSDT", "ts": 1742560351919, "type": "delta", "data": {"s": "BTCUSDT", "b": [["84199.1", "0.657332"], ["84180.5", "0.060107"], ["84171.4", "0.03128"], ["84156.2", "0"], ["84155.8", "0.04955"], ["84155.7", "0.069493"], ["84155.6", "0"], ["84155.5", "0"], ["84126.3", "0.003564"], ["84125.8", "0.000333"]], "a": [["84227.3", "0.099807"], ["84234.3", "0"], ["84234.4", "0"], ["84234.5", "0.014327"], ["84234.6", "0.012994"], ["84235.3", "0"], ["84235.4", "0.000518"], ["84235.5", "0.04"], ["84235.6", "0.04"], ["84271.6", "0.171"], ["84272.3", "0"]], "u": 45348, "seq": 67552592243}, "cts": 1742560351913}}
{"exchange": "BITGET", "timestamp": 1742560352.047126, "message": {"action": "update", "arg": {"instType": "SPOT", "channel": "books", "instId": "BTCUSDT"}, "data": [{"asks": [["84174.00", "1.225080"], ["84174.42", "0.059233"], ["84174.43", "0.095066"], ["84214.32", "0"], ["84222.59", "0"], ["84277.40", "3.981776"], ["84285.90", "5.520189"], ["84294.40", "4.705735"], ["84302.90", "5.610684"], ["84311.40", "4.977220"], ["84319.90", "5.429695"], ["84328.40", "4.434251"], ["84336.90", "4.615240"], ["84345.40", "4.072271"], ["84353.90", "5.067715"], ["84362.40", "4.253261"], ["84379.40", "3.891281"], ["84387.90", "5.158210"], ["84396.40", "5.248705"], ["84404.90", "4.796230"], ["84413.40", "4.343756"], ["84421.90", "4.162766"], ["84430.40", "4.886725"], ["84567.79", "0.000009"]], "bids": [["84108.90", "4.705735"], ["84100.40", "4.524746"], ["84091.90", "4.072271"], ["84083.40", "4.796230"], ["84074.90", "4.343756"], ["84066.40", "5.339200"], ["84057.90", "4.977220"], ["84049.40", "5.158210"], ["84040.90", "4.253261"], ["84032.40", "5.520189"], ["84023.90", "4.886725"], ["84015.40", "4.434251"], ["84006.90", "5.067715"], ["83998.40", "5.429695"], ["83989.90", "4.162766"], ["83981.40", "4.615240"], ["83972.90", "3.891281"], ["83964.40", "3.981776"], ["83947.40", "5.248705"]], "checksum": 454932516, "ts": "1742560352011"}], "ts": 1742560352015}}
{"exchange": "BYBIT", "timestamp": 1742560352.141781, "message": {"topic": "orderbook.200.BTCUSDT", "ts": 1742560352120, "type": "delta", "data": {"s": "BTCUSDT", "b": [["84199.1", "0.617332"], ["84159.7", "0.012882"], ["84159.6", "0.012882"], ["84159.5", "0"], ["84159.4", "0.000333"], ["84125.8", "0"]], "a": [["84199.2", "0.10362"], ["84234.5", "0.001333"], ["84234.7", "0.131787"], ["84235.5", "0"], ["84235.7", "0.04"]], "u": 45349, "seq": 67552592284}, "cts": 1742560352117}}
{"exchange": "BITGET", "timestamp": 1742560352.257257, "message": {"action": "update", "arg": {"instType": "SPOT", "channel": "books", "instId": "BTCUSDT"}, "data": [{"asks": [["84198.93", "0.006356"], ["84199.09", "0.006356"], ["84199.43", "0"], ["84199.59", "0"], ["84199.77", "0.016429"], ["84200.27", "0"], ["84200.32", "0.006356"], ["84200.78", "0.006356"], ["84200.79", "0"], ["84201.24", "0"], ["84202.24", "0.006357"], ["84202.71", "0"], ["84203.97", "0.119850"], ["84204.44", "0"], ["84204.85", "0.119858"], ["84205.33", "0"], ["84205.75", "0.009989"], ["84206.24", "0"], ["84209.23", "0.015892"], ["84209.71", "0"], ["84235.30", "5.478835"], ["84277.40", "5.429695"], ["84285.90", "5.158210"], ["84294.40", "4.524746"], ["84302.90", "4.072271"], ["84311.40", "4.886725"], ["84319.90", "4.705735"], ["84328.40", "4.253261"], ["84336.90", "5.248705"], ["84345.40", "4.796230"], ["84353.90", "4.977220"], ["84362.40", "4.162766"], ["84370.90", "4.434251"], ["84379.40", "4.615240"], ["84387.90", "5.520189"], ["84396.40", "3.981776"], ["84404.90", "3.891281"], ["84421.90", "5.067715"], ["84430.40", "5.339200"], ["84438.90", "5.610684"]], "bids": [["84167.00", "0.003801"], ["84165.00", "0.010003"], ["84163.00", "0.026324"], ["84161.00", "0.069273"], ["84159.00", "0.182297"], ["84157.00", "0.479731"], ["84155.00", "1.262450"], ["84153.00", "3.322236"], ["84151.11", "0"], ["84151.00", "8.742725"], ["84150.94", "0"], ["84150.61", "0.017081"], ["84150.44", "0.007122"], ["84150.11", "0"], ["84150.10", "0.028827"], ["84149.64", "0.007932"], ["84147.99", "0"], ["84147.52", "0.012639"], ["84146.19", "0"], ["84145.72", "0.268024"], ["84145.06", "0"], ["84144.79", "0"], ["84144.58", "0.222377"], ["84144.30", "0.021102"], ["84140.69", "0"], ["84140.21", "0.073119"], ["84108.90", "3.891281"], ["84100.40", "5.248705"], ["84091.90", "5.067715"], ["84083.40", "4.253261"], ["84074.90", "4.162766"], ["84066.40", "5.158210"], ["84057.90", "4.072271"], ["84049.40", "5.610684"], ["84040.90", "4.796230"], ["84032.40", "3.981776"], ["84023.90", "4.343756"], ["84015.40", "4.615240"], ["84006.90", "5.339200"], ["83998.40", "5.520189"], ["83989.90", "4.977220"], ["83981.40", "4.886725"], ["83972.90", "4.434251"], ["83964.40", "4.524746"], ["83955.90", "4.705735"], ["83947.40", "5.429695"]], "checksum": -742327330, "ts": "1742560352227"}], "ts": 1742560352230}}
{"exchange": "BYBIT", "timestamp": 1742560352.340415, "message": {"topic": "orderbook.200.BTCUSDT", "ts": 1742560352320, "type": "delta", "data": {"s": "BTCUSDT", "b": [["84199.1", "0.828332"]], "a": [], "u": 45350, "seq": 67552592333}, "cts": 1742560352317}}
{"exchange": "BITGET", "timestamp": 1742560352.518177, "message": {"action": "update", "arg": {"instType": "SPOT", "channel": "books", "instId": "BTCUSDT"}, "data": [{"asks": [["84174.41", "0.095066"], ["84174.43", "0"], ["84222.59", "0.712397"], ["84236.60", "0.295830"], ["84236.80", "0"], ["84247.80", "0"], ["84277.40", "4.705735"], ["84285.90", "5.067715"], ["84302.90", "4.886725"], ["84311.40", "4.253261"], ["84319.90", "4.343756"], ["84328.40", "4.615240"], ["84336.90", "4.434251"], ["84345.40", "5.429695"], ["84353.90", "5.248705"], ["84362.40", "5.520189"], ["84370.90", "5.610684"], ["84379.40", "5.158210"], ["84387.90", "4.162766"], ["84396.40", "4.796230"], ["84404.90", "3.981776"], ["84413.40", "5.339200"], ["84421.90", "3.891281"], ["84430.40", "4.072271"], ["84438.90", "4.977220"]], "bids": [["84108.90", "4.705735"], ["84100.40", "3.891281"], ["84091.90", "5.429695"], ["84083.40", "3.981776"], ["84074.90", "4.977220"], ["84066.40", "5.339200"], ["84057.90", "4.434251"], ["84049.40", "4.072271"], ["84040.90", "4.886725"], ["84032.40", "4.253261"], ["84023.90", "4.524746"], ["84015.40", "4.162766"], ["84006.90", "4.796230"], ["83998.40", "5.067715"], ["83989.90", "5.520189"], ["83981.40", "5.610684"], ["83972.90", "5.158210"], ["83964.40", "5.248705"], ["83955.90", "4.343756"], ["83947.40", "4.615240"]], "checksum": 1175255333, "ts": "1742560352439"}], "ts": 1742560352442}}
{"exchange": "BYBIT", "timestamp": 1742560352.539416, "message": {"topic": "orderbook.200.BTCUSDT", "ts": 1742560352520, "type": "delta", "data": {"s": "BTCUSDT", "b": [["84199.1", "0.657332"], ["84160.5", "0"], ["84160.3", "0.039636"], ["84159.7", "0"], ["84159.6", "0"], ["84159.4", "0.013215"], ["84159.3", "0.012882"], ["84155.8", "0"], ["84155.7", "0.019942"], ["84155.5", "0.049551"], ["84155.4", "0.049551"]], "a": [["84234.2", "0.016287"], ["84234.3", "0.012994"], ["84234.6", "0"], ["84234.7", "0.118793"]], "u": 45351, "seq": 67552592392}, "cts": 1742560352513}}
{"exchange": "BITGET", "timestamp": 1742560352.680225, "message": {"action": "update", "arg": {"instType": "SPOT", "channel": "books", "instId": "BTCUSDT"}, "data": [{"asks": [["84174.00", "1.225573"], ["84174.01", "0.000100"], ["84174.40", "0.059233"], ["84174.42", "0"], ["84247.80", "1.350000"], ["84277.40", "4.072271"], ["84285.90", "4.253261"], ["84294.40", "4.886725"], ["84302.90", "5.067715"], ["84311.40", "4.524746"], ["84319.90", "4.615240"], ["84328.40", "4.162766"], ["84336.90", "5.248705"], ["84345.40", "3.891281"], ["84353.90", "4.434251"], ["84362.40", "4.796230"], ["84370.90", "3.981776"], ["84387.90", "4.343756"], ["84396.40", "5.610684"], ["84404.90", "5.339200"], ["84413.40", "4.705735"], ["84421.90", "5.520189"], ["84430.40", "5.429695"], ["84567.79", "0"]], "bids": [["84171.72", "0.010000"], ["84167.00", "0.003437"], ["84165.00", "0.009045"], ["84163.00", "0.023804"], ["84161.00", "0.062641"], ["84159.00", "0.164846"], ["84157.00", "0.433804"], ["84155.00", "1.141589"], ["84153.00", "3.004183"], ["84151.00", "7.905744"], ["84124.00", "0.000032"], ["84121.00", "0"], ["84108.90", "4.343756"], ["84100.40", "5.429695"], ["84091.90", "5.520189"], ["84083.40", "4.886725"], ["84074.90", "4.072271"], ["84066.40", "5.158210"], ["84057.90", "4.977220"], ["84049.40", "4.796230"], ["84040.90", "4.162766"], ["84023.90", "3.981776"], ["84015.40", "5.248705"], ["84006.90", "4.524746"], ["83998.40", "4.705735"], ["83989.90", "5.339200"], ["83972.90", "3.891281"], ["83964.40", "5.067715"], ["83955.90", "4.434251"]], "checksum": -471284814, "ts": "1742560352645"}], "ts": 1742560352649}}
{"exchange": "BYBIT", "timestamp": 1742560352.739412, "message": {"topic": "orderbook.200.BTCUSDT", "ts": 1742560352719, "type": "delta", "data": {"s": "BTCUSDT", "b": [["84199.1", "0.655551"], ["84199", "0.135089"], ["84195.4", "0.005956"], ["84194.5", "0.072763"], ["84188.4", "0"], ["84158", "0.035931"], ["84156.4", "0.001781"], ["84126.3", "0"]], "a": [["84199.2", "0.37462"], ["84202.9", "0.006437"], ["84203.5", "0.07129"], ["84206.5", "0.0045"], ["84220.7", "0"], ["84221", "0.038136"], ["84234.2", "0.003293"], ["84234.4", "0.012994"], ["84271.6", "0"], ["84272.1", "0"]], "u": 45352, "seq": 67552592488}, "cts": 1742560352713}}
{"exchange": "BITGET", "timestamp": 1742560352.883263, "message": {"action": "update", "arg": {"instType": "SPOT", "channel": "books", "instId": "BTCUSDT"}, "data": [{"asks": [["84174.41", "0"], ["84195.14", "0.035952"], ["84195.31", "0.119870"], ["84195.70", "0"], ["84195.84", "0"], ["84196.69", "0.035961"], ["84197.19", "0.006356"], ["84197.21", "0"], ["84197.34", "0.006356"], ["84197.74", "0"], ["84197.90", "0"], ["84198.78", "0.010984"], ["84199.36", "0"], ["84200.26", "0.006356"], ["84200.56", "0.006356"], ["84200.59", "0.119883"], ["84200.83", "0"], ["84200.93", "0.083861"], ["84201.11", "0"], ["84202.23", "0.010985"], ["84202.78", "0"], ["84203.03", "0.009990"], ["84203.55", "0"], ["84205.19", "0.119867"], ["84205.51", "0.015895"], ["84205.74", "0"], ["84206.03", "0"], ["84210.16", "0.010988"], ["84210.68", "0"], ["84277.40", "5.520189"], ["84285.90", "5.429695"], ["84294.40", "5.339200"], ["84302.90", "4.886725"], ["84311.40", "5.158210"], ["84319.90", "4.524746"], ["84328.40", "4.072271"], ["84336.90", "4.343756"], ["84345.40", "5.067715"], ["84353.90", "5.248705"], ["84362.40", "3.981776"], ["84365.98", "0"], ["84370.90", "3.891281"], ["84379.40", "5.610684"], ["84387.90", "4.253261"], ["84396.40", "4.434251"], ["84404.90", "4.162766"], ["84421.90", "4.977220"], ["84430.40", "4.796230"], ["84438.90", "4.615240"], ["84567.79", "0.000009"]], "bids": [["84155.29", "0"], ["84154.74", "0.089367"], ["84154.59", "0"], ["84154.06", "0.247262"], ["84153.44", "0"], ["84153.13", "0"], ["84152.95", "0"], ["84152.92", "0.083830"], ["84152.58", "0.017794"], ["84152.39", "0.018231"], ["84151.55", "0"], ["84151.28", "0.004012"], ["84151.03", "0"], ["84150.96", "0.055583"], ["84150.16", "0"], ["84149.77", "0"], ["84149.76", "0"], ["84149.58", "0.008982"], ["84149.42", "0"], ["84149.24", "0.232761"], ["84149.21", "0.025151"], ["84148.87", "0.017328"], ["84148.07", "0"], ["84147.51", "0.051895"], ["84147.16", "0"], ["84146.64", "0.018493"], ["84145.13", "0"], ["84144.92", "0"], ["84144.58", "0.481831"], ["84144.40", "0.076012"], ["84139.98", "0"], ["84139.46", "0.056293"], ["84138.20", "2.551860"], ["84108.90", "4.434251"], ["84100.40", "4.615240"], ["84091.90", "5.158210"], ["84083.40", "4.524746"], ["84074.90", "4.253261"], ["84066.40", "4.977220"], ["84057.90", "5.520189"], ["84049.40", "4.343756"], ["84040.90", "5.067715"], ["84032.40", "3.891281"], ["84023.90", "5.429695"], ["84015.40", "4.886725"], ["84006.90", "4.072271"], ["83998.40", "5.610684"], ["83981.40", "4.162766"], ["83972.90", "4.796230"], ["83964.40", "4.705735"], ["83955.90", "5.248705"], ["83947.40", "3.981776"], ["83674.19", "0.000020"], ["83674.00", "0.001195"]], "checksum": -1623742583, "ts": "1742560352850"}], "ts": 1742560352853}}
{"exchange": "BYBIT", "timestamp": 1742560352.939778, "message": {"topic": "orderbook.200.BTCUSDT", "ts": 1742560352919, "type": "delta", "data": {"s": "BTCUSDT", "b": [["84194.5", "0.001466"], ["84194.2", "0.071297"], ["84192.7", "0"], ["84190.2", "0.071301"], ["84127.1", "0"]], "a": [["84234.3", "0"], ["84234.5", "0.014327"], ["84272.1", "0.003292"]], "u": 45353, "seq": 67552592568}, "cts": 1742560352913}}
{"exchange": "BITGET", "timestamp": 1742560353.084528, "message": {"action": "update", "arg": {"instType": "SPOT", "channel": "books", "instId": "BTCUSDT"}, "data": [{"asks": [["84174.00", "1.258488"], ["84174.40", "0.095066"], ["84175.45", "0.030713"], ["84175.46", "0"], ["84195.83", "0"], ["84200.93", "0.056928"], ["84204.92", "0"], ["84221.30", "0.006557"], ["84223.30", "0.017253"], ["84225.30", "0.045404"], ["84227.30", "0.119485"], ["84229.30", "0.314432"], ["84231.30", "0.827454"], ["84233.30", "2.177509"], ["84235.30", "5.730288"], ["84235.40", "0.370680"], ["84235.60", "0"], ["84235.90", "0.963420"], ["84236.60", "0"], ["84277.40", "4.434251"], ["84302.90", "4.524746"], ["84311.40", "4.343756"], ["84319.90", "4.162766"], ["84328.40", "5.610684"], ["84336.90", "5.158210"], ["84345.40", "4.796230"], ["84353.90", "4.615240"], ["84366.79", "0.166330"], ["84370.90", "4.253261"], ["84379.40", "4.886725"], ["84387.90", "4.977220"], ["84396.40", "4.072271"], ["84404.90", "5.520189"], ["84421.90", "3.891281"], ["84430.40", "5.067715"], ["84438.90", "5.248705"], ["84568.60", "0.000018"], ["84568.81", "0.000072"], ["84568.97", "0.000024"]], "bids": [["84172.18", "0"], ["84169.00", "0.001109"], ["84167.00", "0.002920"], ["84165.00", "0.007682"], ["84163.00", "0.020216"], ["84161.00", "0.053202"], ["84159.00", "0.140003"], ["84157.00", "0.368429"], ["84155.00", "0.969550"], ["84153.00", "2.551449"], ["84151.00", "6.714340"], ["84108.90", "4.162766"], ["84100.40", "5.158210"], ["84091.90", "3.981776"], ["84083.40", "5.429695"], ["84074.90", "4.977220"], ["84066.40", "5.067715"], ["84057.90", "3.891281"], ["84049.40", "5.339200"], ["84040.90", "4.886725"], ["84032.40", "4.524746"], ["84023.90", "4.072271"], ["84015.40", "5.610684"], ["84006.90", "4.615240"], ["83998.40", "4.434251"], ["83989.90", "4.796230"], ["83981.40", "5.248705"], ["83972.90", "4.253261"], ["83955.90", "5.520189"], ["83947.40", "4.343756"], ["83673.87", "0.000022"]], "checksum": 277096666, "ts": "1742560353056"}], "ts": 1742560353058}}
{"exchange": "BYBIT", "timestamp": 1742560353.139924, "message": {"topic": "orderbook.200.BTCUSDT", "ts": 1742560353119, "type": "delta", "data": {"s": "BTCUSDT", "b": [["84171.1", "0.023753"], ["84160.4", "0"], ["84160.2", "0.039636"], ["84159.4", "0.000333"], ["84159.2", "0.012882"], ["84129.2", "0"], ["84128.9", "0"]], "a": [["84199.2", "0.20362"], ["84203.4", "0.055399"], ["84221", "0"], ["84221.8", "0.014411"], ["84222.4", "0.046809"], ["84234.4", "0"], ["84234.5", "0.001333"], ["84234.7", "0.131787"], ["84234.8", "0.012994"], ["84235.6", "0"], ["84235.8", "0.04"], ["84271.3", "0"], ["84272.1", "0"]], "u": 45354, "seq": 67552592649}, "cts": 1742560353113}}
{"exchange": "BITGET", "timestamp": 1742560772.572173, "message": {"event": "subscribe", "arg": {"instType": "SPOT", "channel": "books", "instId": "BTCUSDT"}}}
{"exchange": "BYBIT", "timestamp": 1742560772.572307, "message": {"success": true, "ret_msg": "subscribe", "conn_id": "690955ea-27f4-4577-ac9e-805817596691", "op": "subscribe"}}
{"exchange": "BYBIT", "timestamp": 1742560772.574287, "message": {"topic": "orderbook.200.BTCUSDT", "ts": 1742560772320, "type": "snapshot", "data": {"s": "BTCUSDT", "b": [["83909.3", "0.849512"], ["83909.1", "0.123817"], ["83908.9", "0.222326"], ["83906.5", "0.1"], ["83906.3", "0.00008"], ["83906.2", "0.221"], ["83904.8", "0.003851"], ["83903.2", "0.001466"], ["83903.1", "0.000333"], ["83903", "0.089099"], ["83902.8", "0.0031"], ["83902.4", "0.001845"], ["83902.1", "0.014916"], ["83900.9", "0.015"], ["83900.8", "0.307617"], ["83900.7", "0.122138"], ["83900.6", "0.029247"], ["83900.4", "0.019889"], ["83900", "0.550456"], ["83899.5", "0.056117"], ["83898.9", "0.000333"], ["83898.6", "0.001466"], ["83898.2", "0.001333"], ["83897.9", "0.026531"], ["83897.8", "0.000518"], ["83897.6", "0.0002"], ["83897.3", "0.140268"], ["83897", "0.04"], ["83896.8", "0.044"], ["83896.4", "0.005769"], ["83895.8", "0.171"], ["83895.4", "0.056"], ["83895.1", "0.04"], ["83894.7", "0.000333"], ["83894.6", "0.12007"], ["83894.1", "0.024"], ["83894", "0.002889"], ["83893.7", "0.003259"], ["83893.6", "0.188572"], ["83893.4", "0.044358"], ["83893.2", "0.000518"], ["83892.6", "0.525501"], ["83891.7", "0.044"], ["83891.3", "0.009"], ["83890.9", "0.00625"], ["83890.8", "0.048"], ["83890.5", "0.000333"], ["83890.4", "0.044"], ["83890.2", "0.00253"], ["83890.1", "0.048"], ["83890", "0.0002"], ["83889.8", "0.001333"], ["83889.5", "0.003259"], ["83889.4", "0.001466"], ["83889.3", "0.254582"], ["83889.2", "0.119143"], ["83889", "0.100314"], ["83888.9", "0.052"], ["83888.8", "0.000445"], ["83888.7", "0.003614"], ["83888.6", "0.000518"], ["83888.5", "0.089099"], ["83888.3", "0.004037"], ["83887.4", "0.171"], ["83886.6", "0.021653"], ["83886.3", "0.000333"], ["83886.1", "0.709671"], ["83886", "0.568474"], ["83885.8", "0.023782"], ["83885.6", "0.001423"], ["83885.3", "0.003259"], ["83885", "1.500332"], ["83884.8", "0.001466"], ["83884", "0.000518"], ["83883.5", "0.000657"], ["83883.2", "0.121606"], ["83882.2", "0.000333"], ["83881.8", "0.005871"], ["83881.4", "0.001333"], ["83881.1", "0.003259"], ["83880.4", "0.059399"], ["83880.3", "0.139111"], ["83880.2", "0.119143"], ["83880.1", "0.001466"], ["83880", "0.057502"], ["83879.4", "0.000518"], ["83879", "0.171"], ["83878.6", "0.113502"], ["83878.3", "0.000572"], ["83878", "0.000333"], ["83877.2", "0.001423"], ["83876.9", "0.003259"], ["83876.8", "0.079084"], ["83876.5", "0.0045"], ["83875.5", "0.001466"], ["83875", "0.000436"], ["83874.9", "0.001071"], ["83874.8", "0.119143"], ["83874.7", "0.000518"], ["83874.3", "0.089099"], ["83874.1", "0.0016"], ["83873.8", "0.000333"], ["83873.7", "0.013"], ["83873.6", "0.01288"], ["83873.2", "0.000147"], ["83873.1", "0.001333"], ["83872.7", "0.003259"], ["83871.5", "0.000083"], ["83871.3", "0.001739"], ["83870.9", "0.015222"], ["83870.6", "0.171"], ["83870.1", "0.000518"], ["83869.6", "0.000333"], ["83869.3", "0.099459"], ["83869.2", "0.238185"], ["83869.1", "0.059399"], ["83869", "0.000118"], ["83868.9", "0.001333"], ["83868.8", "0.00009"], ["83868.7", "0.001367"], ["83868.5", "0.003259"], ["83867.6", "0.002134"], ["83866.5", "0.000468"], ["83866.3", "0.001466"], ["83865.5", "0.000518"], ["83865.4", "0.000333"], ["83865.1", "0.490601"], ["83865", "1.420134"], ["83864.8", "0.128779"], ["83864.7", "0.002533"], ["83864.3", "0.003259"], ["83863.6", "0.134889"], ["83863.5", "0.000454"], ["83862.2", "0.171"], ["83861.9", "11.216018"], ["83861.7", "0.001466"], ["83861.3", "0.009"], ["83861.2", "0.000333"], ["83860.9", "0.000518"], ["83860.5", "0.001333"], ["83860.4", "0.00046"], ["83860.1", "0.653987"], ["83860", "1.501139"], ["83859.6", "0.000013"], ["83859.1", "0.238185"], ["83858.3", "0.015"], ["83857.9", "0.011926"], ["83857.4", "0.002639"], ["83857.1", "0.003056"], ["83857", "0.000333"], ["83856.3", "0.001851"], ["83855.9", "0.003259"], ["83855.1", "0.066613"], ["83855", "0.051004"], ["83854.5", "0.000022"], ["83854.2", "0.000016"], ["83853.8", "0.171"], ["83852.8", "0.000333"], ["83852.5", "0.001466"], ["83852.1", "0.001333"], ["83852", "0.00009"], ["83851.8", "0.321148"], ["83851.7", "0.063176"], ["83851.3", "0.00009"], ["83850.4", "0.023837"], ["83850.3", "0.000059"], ["83850.2", "0.005959"], ["83850", "0.080757"], ["83849.7", "3.398878"], ["83849.5", "0.00093"], ["83849.2", "0.000358"], ["83849", "0.238185"], ["83848.6", "0.000333"], ["83848", "0.001034"], ["83847.9", "0.002799"], ["83847.8", "0.018111"], ["83847.6", "0.003259"], ["83847.3", "0.023837"], ["83847.1", "0.000518"], ["83847", "0.000079"], ["83846.5", "0.0045"], ["83846.4", "0.000694"], ["83846.1", "0.023837"], ["83845.9", "0.010933"], ["83845.4", "0.171"], ["83844.9", "0.023837"], ["83844.4", "0.000333"], ["83843.7", "0.001333"], ["83843.6", "0.00009"], ["83843.4", "0.003259"], ["83843.2", "0.236858"], ["83843.1", "0.059399"], ["83842.5", "0.000518"], ["83842.4", "0.004846"], ["83842", "0.000622"], ["83841.9", "0.000413"], ["83841", "0.000334"], ["83840.2", "0.000333"], ["83840", "0.000414"], ["83839.9", "0.000404"]], "a": [["83909.4", "0.054731"], ["83909.8", "0.035752"], ["83910", "0.071504"], ["83910.5", "0.039034"], ["83910.8", "0.001333"], ["83911.3", "0.071538"], ["83911.5", "0.000333"], ["83911.7", "0.000512"], ["83911.8", "0.00426"], ["83912.5", "0.001466"], ["83914.6", "0.10692"], ["83914.7", "0.003283"], ["83915", "0.001333"], ["83915.6", "0.012206"], ["83915.7", "0.000333"], ["83916.3", "0.000512"], ["83917.1", "0.001466"], ["83917.4", "0.005"], ["83917.8", "0.01"], ["83918.9", "0.039459"], ["83919", "0.029533"], ["83919.2", "0.072864"], ["83919.8", "0.024412"], ["83919.9", "0.000533"], ["83920", "0.00024"], ["83920.9", "0.000512"], ["83921.4", "0.030689"], ["83921.7", "0.001466"], ["83922.9", "0.000298"], ["83923.1", "0.003286"], ["83923.4", "0.001333"], ["83923.5", "0.03576"], ["83923.7", "0.071527"], ["83924", "0.000298"], ["83924.1", "0.000333"], ["83924.2", "0.00009"], ["83924.8", "0.076948"], ["83924.9", "0.059399"], ["83925.1", "0.00018"], ["83925.5", "0.000512"], ["83925.6", "0.171"], ["83926.3", "0.001466"], ["83927.2", "0.003286"], ["83927.6", "0.001333"], ["83928.1", "0.018984"], ["83928.3", "0.000333"], ["83929", "0.036512"], ["83929.7", "0.004161"], ["83930.1", "0.0103"], ["83930.2", "0.00112"], ["83930.9", "0.001466"], ["83931.2", "0.04"], ["83931.4", "0.003287"], ["83931.8", "0.001333"], ["83932.5", "0.000333"], ["83932.6", "0.04009"], ["83933", "0.068395"], ["83933.1", "0.270515"], ["83933.3", "0.11355"], ["83933.4", "0.059399"], ["83933.6", "0.011924"], ["83934.7", "0.000512"], ["83935.1", "0.04"], ["83935.5", "0.001466"], ["83935.6", "0.003288"], ["83936", "0.001333"], ["83936.2", "0.023835"], ["83936.3", "0.04596"], ["83936.4", "0.04"], ["83936.5", "0.0045"], ["83936.6", "0.562218"], ["83936.7", "0.000333"], ["83936.8", "0.04"], ["83937.7", "0.04"], ["83937.9", "0.04"], ["83938.1", "0.123719"], ["83938.2", "0.119177"], ["83938.4", "0.04"], ["83938.5", "0.174455"], ["83939.2", "0.023834"], ["83939.4", "0.000512"], ["83939.7", "0.023835"], ["83939.8", "0.043288"], ["83940", "0.00024"], ["83940.1", "0.001466"], ["83940.2", "0.001333"], ["83940.9", "0.000333"], ["83941", "0.00009"], ["83941.1", "0.023835"], ["83941.4", "0.008233"], ["83941.9", "0.173072"], ["83942.1", "0.02376"], ["83944", "0.003802"], ["83944.4", "0.530962"], ["83944.6", "0.023834"], ["83944.8", "0.001466"], ["83945", "0.005958"], ["83945.1", "0.000333"], ["83945.5", "0.059399"], ["83945.6", "0.119143"], ["83945.7", "0.156763"], ["83946.1", "0.354032"], ["83948.2", "0.00329"], ["83948.5", "0.013"], ["83948.6", "0.024683"], ["83948.7", "0.03"], ["83948.8", "0.001787"], ["83948.9", "0.00009"], ["83949.1", "0.04"], ["83949.2", "0.04"], ["83949.3", "0.000691"], ["83949.4", "0.001556"], ["83949.9", "0.003564"], ["83951.3", "1.438401"], ["83952.1", "0.0139"], ["83952.4", "0.00329"], ["83952.8", "0.001333"], ["83952.9", "0.119143"], ["83953", "0.02383"], ["83953.2", "0.219158"], ["83953.5", "0.000333"], ["83954", "0.064929"], ["83955", "0.000118"], ["83955.2", "0.005942"], ["83956", "0.023829"], ["83956.5", "0.02383"], ["83956.6", "0.003279"], ["83957", "0.001333"], ["83957.1", "0.114585"], ["83957.2", "0.178671"], ["83957.7", "0.119447"], ["83957.8", "0.000604"], ["83957.9", "0.02383"], ["83958", "0.059399"], ["83958.6", "0.001466"], ["83959.3", "0.0006"], ["83960", "0.00024"], ["83960.4", "0.0001"], ["83960.8", "0.003283"], ["83960.9", "0.0012"], ["83961.1", "0.119143"], ["83961.2", "0.001333"], ["83961.4", "0.023829"], ["83961.7", "0.089099"], ["83961.8", "0.005957"], ["83961.9", "0.000333"], ["83962.4", "0.000514"], ["83962.6", "0.111261"], ["83963.2", "0.001466"], ["83964.3", "0.0006"], ["83965", "0.174283"], ["83965.2", "0.059557"], ["83965.4", "0.013202"], ["83966.1", "0.000333"], ["83966.2", "0.00009"], ["83966.3", "0.119143"], ["83966.4", "2.606277"], ["83966.5", "0.063899"], ["83967", "0.004286"], ["83967.1", "0.000514"], ["83967.8", "0.005942"], ["83967.9", "0.001466"], ["83968.1", "0.0006"], ["83969", "0.011869"], ["83969.2", "0.003283"], ["83969.4", "0.0006"], ["83969.6", "0.001333"], ["83969.9", "0.024699"], ["83970", "0.022"], ["83970.3", "0.000333"], ["83971.4", "0.000358"], ["83971.5", "0.119143"], ["83971.7", "0.000514"], ["83972.3", "0.100968"], ["83972.5", "0.001466"], ["83973.4", "0.174283"], ["83973.5", "0.011869"], ["83973.8", "0.001333"], ["83974.5", "0.000333"], ["83974.6", "0.00009"], ["83975.6", "0.027597"], ["83975.8", "0.023924"], ["83976.3", "0.000514"], ["83976.7", "0.119143"], ["83976.9", "0.011869"], ["83977", "0.059399"], ["83977.1", "0.000259"], ["83977.6", "0.003291"], ["83977.9", "1.137166"], ["83978", "0.001333"], ["83978.2", "0.011869"], ["83978.6", "0.011869"], ["83978.7", "0.000333"], ["83979.5", "3.734663"], ["83980", "0.00024"], ["83980.4", "0.005942"], ["83980.9", "0.000514"], ["83981.3", "0.009"], ["83981.7", "0.001466"], ["83981.8", "0.174291"]], "u": 47433, "seq": 67552910386}, "cts": 1742560772314}}
{"exchange": "BYBIT", "timestamp": 1742560772.575776, "message": {"topic": "orderbook.200.BTCUSDT", "ts": 1742560772519, "type": "delta", "data": {"s": "BTCUSDT", "b": [["83883.1", "0.03576"], ["83861.9", "0"], ["83853.5", "11.216018"], ["83839.9", "0"]], "a": [["83948.3", "0.013"], ["83948.4", "0.012728"], ["83948.5", "0"], ["83948.6", "0.011955"], ["83981.8", "0"]], "u": 47434, "seq": 67552910437}, "cts": 1742560772460}}
