{"exchange": "BITGET", "timestamp": 1742555359.205927, "message": {"action": "update", "arg": {"instType": "SPOT", "channel": "books", "instId": "BTCUSDT"}, "data": [{"asks": [["84029.41", "0.006374"], ["84035.73", "0.051593"], ["84037.55", "0"], ["84041.67", "0"], ["84041.92", "0"], ["84041.93", "0"], ["84041.96", "0"], ["84041.97", "0"], ["84042.03", "0"], ["84042.04", "0"], ["84049.03", "0"], ["84049.55", "0"], ["84050.79", "0"], ["84051.21", "0"], ["84051.36", "0"], ["84051.71", "0"], ["84052.77", "0"], ["84053.04", "0"], ["84053.20", "0"], ["84053.67", "0"], ["84053.73", "0"], ["84053.76", "0"], ["84054.23", "0"], ["84054.26", "0"], ["84054.56", "0"], ["84054.61", "0"], ["84054.67", "0"], ["84054.71", "0"], ["84056.20", "0"], ["84056.29", "0"], ["84057.94", "0"], ["84059.01", "0.088078"], ["84059.48", "0"], ["84059.59", "0"], ["84060.97", "0.006356"], ["84063.43", "0"], ["84064.27", "0"], ["84075.66", "0.062760"], ["84081.75", "0"], ["84086.70", "0"], ["84086.95", "0.175047"], ["84088.65", "0"], ["84088.70", "0"], ["84090.70", "0"], ["84090.74", "0"], ["84091.10", "0.001040"], ["84092.70", "0"], ["84093.10", "0.001021"], ["84094.70", "0"], ["84095.10", "0.001008"], ["84096.70", "0"], ["84097.10", "0.001034"], ["84098.70", "0"], ["84099.10", "0.001013"], ["84099.85", "0"], ["84100.70", "0"], ["84101.10", "0.002292"], ["84102.70", "0"], ["84103.10", "0.006031"], ["84104.70", "0"], ["84105.10", "0.015871"], ["84106.70", "0"], ["84107.10", "0.041768"], ["84107.60", "0"], ["84109.10", "0.109914"], ["84109.80", "0"], ["84110.10", "0"], ["84110.60", "0"], ["84111.10", "0.289249"], ["84111.90", "1.048950"], ["84112.10", "0.067980"], ["84112.50", "0.001018"], ["84113.00", "0.003270"], ["84113.20", "0.001005"], ["84113.50", "2.356440"], ["84114.10", "0.067980"], ["84114.30", "0"], ["84114.90", "0.465060"], ["84115.20", "0.066780"], ["84117.30", "0"], ["84119.40", "0.213540"], ["84119.80", "1.069890"], ["84119.90", "0.324000"], ["84120.00", "1.031250"], ["84120.10", "0.015150"], ["84121.10", "0.178290"], ["84121.70", "0.460320"], ["84121.80", "0.480000"], ["84148.70", "0"], ["84153.10", "5.347080"], ["84157.20", "0"], ["84161.60", "5.437708"], ["84165.70", "0"], ["84170.10", "5.075195"], ["84174.20", "0"], ["84178.60", "4.350167"], ["84182.70", "0"], ["84187.10", "5.618965"], ["84191.20", "0"], ["84195.60", "4.259538"], ["84199.70", "0"], ["84204.10", "4.168910"], ["84208.20", "0"], ["84212.60", "4.803309"], ["84216.00", "0"], ["84216.70", "0"], ["84221.10", "5.528337"], ["84225.20", "0"], ["84229.60", "4.712681"], ["84233.70", "0"], ["84238.10", "4.078281"], ["84242.20", "0"], ["84246.60", "4.440795"], ["84250.70", "0"], ["84255.10", "5.165823"], ["84259.20", "0"], ["84263.60", "4.893938"], ["84267.70", "0"], ["84272.10", "4.531424"], ["84276.20", "0"], ["84280.60", "3.897025"], ["84284.70", "0"], ["84289.10", "4.622052"], ["84293.20", "0"], ["84297.60", "5.256452"], ["84301.70", "0"], ["84306.10", "4.984566"], ["84310.20", "0"], ["84314.60", "3.987653"], ["84528.57", "0.000008"], ["84530.00", "0.000031"], ["84533.01", "0.000591"], ["84533.33", "0.003186"], ["84534.53", "0.000461"], ["84535.32", "0.000039"], ["84536.36", "0.000053"], ["84537.04", "0.000958"], ["84538.75", "0.000011"], ["84540.00", "0.001367"], ["84540.54", "0.000184"], ["84540.97", "0.000065"], ["84541.67", "0.000198"], ["84542.37", "0.001213"], ["84543.27", "0.000067"], ["84543.43", "0.000423"], ["84543.86", "0.000033"], ["84543.93", "0.000010"], ["84544.64", "0.000036"], ["84545.16", "0.000020"], ["84545.45", "0.001774"], ["84545.63", "0.000008"], ["84547.06", "0.000071"], ["84549.65", "0.000030"], ["84549.96", "0.000012"], ["84550.00", "0.009759"], ["84550.60", "0.000096"], ["84551.02", "0.000085"], ["84552.59", "0.000009"], ["84552.95", "0.000009"], ["84553.04", "0.000129"]], "bids": [["84029.40", "0.692223"], ["84029.38", "0.000100"], ["84029.37", "0.000100"], ["84028.90", "4.626006"], ["84028.51", "0.496899"], ["84028.50", "0"], ["84028.49", "0"], ["84028.46", "0"], ["84028.45", "0"], ["84028.44", "0"], ["84028.39", "0"], ["84026.90", "12.173700"], ["84026.80", "0.001049"], ["84026.50", "0"], ["84026.20", "2.357370"], ["84025.90", "0.068820"], ["84025.60", "0.001050"], ["84025.23", "0"], ["84025.20", "0"], ["84025.19", "0"], ["84024.50", "0"], ["84024.32", "0"], ["84024.30", "0"], ["84024.26", "0"], ["84024.25", "0"], ["84024.24", "0"], ["84024.23", "0"], ["84023.90", "0.068400"], ["84023.40", "0.070830"], ["84022.50", "13.052580"], ["84022.20", "0"], ["84022.10", "0.591330"], ["84020.40", "0.128280"], ["84019.20", "2.386740"], ["84019.10", "0.096360"], ["84018.60", "0"], ["84015.80", "0.356880"], ["84014.27", "0"], ["84013.40", "0"], ["84013.30", "0"], ["84013.20", "0"], ["84012.60", "0"], ["84009.37", "0.008188"], ["84008.69", "0"], ["84008.38", "0"], ["84007.19", "0"], ["84007.11", "0"], ["84007.09", "0"], ["84007.07", "0"], ["84007.03", "0"], ["84006.98", "0"], ["84006.67", "0"], ["84006.49", "0"], ["84006.17", "0"], ["84005.54", "0"], ["84005.53", "0"], ["84005.45", "0"], ["84005.04", "0"], ["84005.00", "0.000428"], ["84004.81", "0"], ["84004.63", "0"], ["84004.15", "0"], ["84004.09", "0"], ["84003.67", "0"], ["84003.65", "0"], ["84003.35", "0"], ["84003.30", "0"], ["84003.12", "0"], ["84003.07", "0"], ["84001.67", "0"], ["84001.58", "0"], ["83999.79", "0"], ["83999.60", "0"], ["83998.84", "0"], ["83998.48", "0"], ["83998.42", "0"], ["83998.35", "0"], ["83998.26", "0"], ["83998.25", "0"], ["83995.96", "0.000877"], ["83994.53", "0"], ["83993.69", "0"], ["83992.04", "0"], ["83989.10", "0.007438"], ["83984.90", "4.984566"], ["83982.60", "0"], ["83980.50", "0"], ["83979.75", "0"], ["83978.56", "0"], ["83978.50", "0"], ["83978.49", "0"], ["83977.00", "0.000032"], ["83976.40", "4.440795"], ["83975.60", "0.210148"], ["83972.00", "0"], ["83970.20", "0"], ["83967.90", "4.712681"], ["83963.50", "0"], ["83959.40", "5.437708"], ["83955.00", "0.000924"], ["83950.90", "4.350167"], ["83946.50", "0"], ["83942.40", "4.893938"], ["83938.00", "0"], ["83933.90", "5.256452"], ["83929.50", "0"], ["83925.40", "5.528337"], ["83921.00", "0"], ["83916.90", "3.897025"], ["83912.50", "0"], ["83908.40", "5.165823"], ["83904.00", "0"], ["83899.90", "4.168910"], ["83895.50", "0"], ["83891.40", "5.347080"], ["83887.00", "0"], ["83882.90", "3.987653"], ["83878.50", "0"], ["83874.40", "4.622052"], ["83870.00", "0"], ["83865.90", "4.531424"], ["83861.50", "0"], ["83857.40", "4.259538"], ["83853.00", "0"], ["83848.90", "5.618965"], ["83844.50", "0"], ["83840.40", "4.078281"], ["83836.00", "0"], ["83831.90", "4.803309"], ["83827.50", "0"], ["83823.40", "5.075195"], ["83819.00", "0"], ["83653.67", "0.001695"], ["83653.31", "0.000015"], ["83652.80", "0.000119"], ["83652.48", "0.000188"], ["83651.65", "0.000018"], ["83651.16", "0.000896"], ["83650.84", "0.003326"], ["83650.00", "0.032056"], ["83648.96", "0.000030"], ["83647.46", "0.000224"], ["83647.06", "0.000040"], ["83646.67", "0.000018"], ["83645.83", "0.000014"], ["83644.86", "0.000034"], ["83644.33", "0.000013"], ["83643.18", "0.000052"], ["83641.86", "0.000379"], ["83641.62", "0.002925"], ["83641.38", "0.000135"], ["83641.00", "0.000082"], ["83640.35", "0.000022"], ["83640.15", "0.000423"], ["83640.00", "0.002013"], ["83639.71", "0.000041"], ["83639.70", "0.000010"], ["83639.15", "0.000009"], ["83638.32", "0.000039"], ["83638.30", "0.000137"], ["83637.17", "0.000027"], ["83636.36", "0.000179"], ["83635.64", "0.000030"], ["83634.09", "0.000124"], ["83634.05", "0.000008"], ["83633.88", "0.000071"], ["83633.63", "0.000521"], ["83633.61", "0.000059"], ["83633.40", "0.000076"], ["83633.33", "0.000970"], ["83633.19", "0.007264"], ["83632.65", "0.000085"], ["83632.10", "0.000012"], ["83632.02", "0.000459"], ["83631.58", "0.000330"], ["83631.57", "0.000019"], ["83631.53", "0.000009"], ["83631.09", "0.002040"], ["83630.43", "0.000010"], ["83629.43", "0.000025"], ["83629.36", "0.000121"], ["83629.03", "0.000039"], ["83629.02", "0.000078"], ["83628.94", "0.000988"], ["83628.50", "0.000989"], ["83627.68", "0.000364"], ["83627.45", "0.000016"]], "checksum": 1687184665, "ts": "1742555359173"}], "ts": 1742555359176}}
{"exchange": "BYBIT", "timestamp": 1742555359.340258, "message": {"topic": "orderbook.200.BTCUSDT", "ts": 1742555359320, "type": "delta", "data": {"s": "BTCUSDT", "b": [["84064.8", "0.386731"], ["84064.1", "0.089689"], ["84064", "0.190358"], ["84063.5", "0.0006"], ["84063.4", "0.174"], ["84061.9", "0.00157"], ["84059.8", "0.0025"], ["84059.5", "0.000516"], ["84059", "0"], ["84053.8", "0.075369"], ["84053.4", "0.04"], ["84052.5", "0"], ["84052.4", "0.001753"], ["84051.2", "0"], ["84050.3", "0.066955"], ["84050.2", "0.141367"], ["84043.2", "0.062317"], ["84036.2", "0.124457"], ["84020.3", "4.462553"], ["84017.5", "0"], ["84006.2", "13.960352"], ["84002.8", "0.003181"], ["83990.2", "0"], ["83989.4", "0"], ["83988.2", "0"], ["83987.3", "0"]], "a": [["84064.1", "0"], ["84064.9", "0.134439"], ["84069.1", "0"], ["84069.9", "0.0025"], ["84072.5", "0"], ["84073.3", "0.015"], ["84073.7", "0.000153"], ["84074.9", "0.051724"], ["84075", "0"], ["84075.2", "0"], ["84075.6", "0.071432"], ["84076.6", "0"], ["84076.9", "0"], ["84079.8", "0.219779"], ["84080", "0.04824"], ["84080.1", "0"], ["84080.6", "0.0119"], ["84081.2", "0"], ["84081.6", "0.04"], ["84083.3", "0.005942"], ["84085.1", "0.052"], ["84085.2", "0.061352"], ["84086.7", "0.178387"], ["84090", "0"], ["84092.2", "0.061512"], ["84099.2", "0.118181"], ["84106.8", "0"], ["84107.4", "0"], ["84107.5", "0"], ["84108.2", "0.014333"], ["84108.3", "0.012847"], ["84108.4", "0"], ["84109.1", "0.04"], ["84109.2", "0.04"], ["84109.7", "0.063438"], ["84138.4", "0.000333"]], "u": 20728, "seq": 67549991086}, "cts": 1742555359306}}
{"exchange": "BITGET", "timestamp": 1742555359.407798, "message": {"action": "update", "arg": {"instType": "SPOT", "channel": "books", "instId": "BTCUSDT"}, "data": [{"asks": [["84037.78", "0"], ["84046.22", "0.000221"], ["84048.36", "0.000679"], ["84048.37", "0.007162"], ["84048.39", "0.000865"], ["84048.40", "0.009407"], ["84048.45", "0.006307"], ["84053.09", "0"], ["84054.81", "0"], ["84055.74", "0.035952"], ["84056.17", "0.119870"], ["84057.10", "0"], ["84057.30", "0.035961"], ["84057.70", "0.006356"], ["84057.78", "0.006356"], ["84058.32", "0.006356"], ["84059.45", "0.010984"], ["84059.53", "0.006356"], ["84059.61", "0.006356"], ["84060.03", "0.016429"], ["84060.34", "0.006356"], ["84060.85", "0.006356"], ["84060.87", "0.006356"], ["84061.05", "0.119883"], ["84061.13", "0.006356"], ["84061.22", "0.016429"], ["84062.66", "0.006357"], ["84062.90", "0.010985"], ["84063.34", "0"], ["84063.59", "0.009990"], ["84064.66", "0.119850"], ["84065.50", "0.119858"], ["84066.00", "0.009989"], ["84066.10", "0.015895"], ["84070.05", "0.015892"], ["84070.89", "0.010988"], ["84081.74", "0"], ["84090.73", "0"], ["84091.10", "0"], ["84091.90", "0.001017"], ["84093.10", "0"], ["84093.90", "0.001028"], ["84095.10", "0"], ["84095.90", "0.001010"], ["84097.10", "0"], ["84097.90", "0.001548"], ["84099.10", "0"], ["84099.28", "0.713442"], ["84099.90", "0.004072"], ["84101.10", "0"], ["84101.90", "0.010717"], ["84103.10", "0"], ["84103.90", "0.028201"], ["84105.10", "0"], ["84105.90", "0.074214"], ["84107.10", "0"], ["84107.90", "0.195301"], ["84109.10", "0"], ["84109.90", "0.513950"], ["84111.10", "0"], ["84111.90", "1.352499"], ["84112.00", "0.001230"], ["84112.10", "0.068400"], ["84113.00", "0"], ["84113.20", "0"], ["84113.50", "3.413280"], ["84114.90", "0.464880"], ["84115.20", "0"], ["84115.30", "0.420180"], ["84115.80", "0.163770"], ["84116.40", "2.723550"], ["84117.40", "0.194280"], ["84118.00", "0.066210"], ["84118.50", "0.391710"], ["84119.40", "0.168000"], ["84120.00", "0.674370"], ["84120.10", "0"], ["84120.90", "0.107070"], ["84121.50", "0.012540"], ["84122.00", "0.045540"], ["84122.40", "0.240000"], ["84153.10", "0"], ["84154.00", "4.531380"], ["84161.60", "0"], ["84162.50", "3.896986"], ["84170.10", "0"], ["84171.00", "4.712635"], ["84178.60", "0"], ["84179.50", "4.984517"], ["84187.10", "0"], ["84188.00", "5.347028"], ["84195.60", "0"], ["84196.50", "4.893890"], ["84204.10", "0"], ["84205.00", "5.256400"], ["84212.60", "0"], ["84213.50", "4.259497"], ["84221.10", "0"], ["84222.00", "4.440752"], ["84229.60", "0"], ["84230.50", "5.075145"], ["84238.10", "0"], ["84239.00", "5.618911"], ["84246.60", "0"], ["84247.50", "4.168869"], ["84255.10", "0"], ["84256.00", "4.350124"], ["84263.60", "0"], ["84264.50", "4.803262"], ["84272.10", "0"], ["84273.00", "5.437655"], ["84280.60", "0"], ["84281.50", "4.078242"], ["84289.10", "0"], ["84290.00", "3.987614"], ["84297.60", "0"], ["84298.50", "5.528283"], ["84306.10", "0"], ["84307.00", "4.622007"], ["84314.60", "0"], ["84315.50", "5.165773"], ["84537.04", "0"], ["84538.75", "0"], ["84540.00", "0"], ["84540.54", "0"], ["84540.97", "0"], ["84541.67", "0"], ["84542.37", "0"], ["84543.27", "0"], ["84543.43", "0"], ["84543.86", "0"], ["84543.93", "0"], ["84544.64", "0"], ["84545.16", "0"], ["84545.45", "0"], ["84545.63", "0"], ["84547.06", "0"], ["84549.65", "0"], ["84549.96", "0"], ["84550.00", "0"], ["84550.60", "0"], ["84551.02", "0"], ["84552.59", "0"], ["84552.95", "0"], ["84553.04", "0"]], "bids": [["84029.40", "0.917783"], ["84028.91", "1.791479"], ["84028.90", "0"], ["84028.51", "0"], ["84027.80", "11.044420"], ["84027.00", "5.333850"], ["84026.90", "2.571450"], ["84026.80", "0"], ["84026.70", "0.006030"], ["84026.20", "0"], ["84025.90", "0.067980"], ["84025.60", "0"], ["84023.90", "0.067980"], ["84023.49", "0.250860"], ["84023.40", "0.070440"], ["84022.50", "4.413840"], ["84022.10", "0.542760"], ["84021.90", "0.067800"], ["84020.69", "0.008273"], ["84020.40", "0.128100"], ["84019.90", "0.067800"], ["84019.30", "0.120000"], ["84019.20", "2.328330"], ["84019.00", "0.000032"], ["84018.98", "0.008064"], ["84015.70", "0.012750"], ["84015.40", "0.089521"], ["84014.99", "0.247687"], ["84014.20", "0.960570"], ["84013.90", "0"], ["84013.80", "0"], ["84013.60", "0.083974"], ["84013.17", "0.227024"], ["84012.90", "0.018262"], ["84012.78", "0.005949"], ["84012.04", "0.009215"], ["84012.03", "0.006908"], ["84011.97", "0.017032"], ["84011.96", "0.007308"], ["84011.91", "0.008019"], ["84011.88", "0.006475"], ["84011.81", "0.008324"], ["84011.76", "0.004900"], ["84011.72", "0.055678"], ["84011.29", "0.017110"], ["84011.04", "0.007134"], ["84010.76", "0.007342"], ["84010.45", "0.028876"], ["84010.28", "0.007946"], ["84010.26", "0.008998"], ["84009.96", "0.025195"], ["84009.79", "0.224973"], ["84009.53", "0.017358"], ["84008.28", "0.051984"], ["84008.04", "0.012660"], ["84007.29", "0.018524"], ["84006.50", "0.268485"], ["84005.33", "0.222759"], ["84005.09", "0.076143"], ["84004.91", "0.005055"], ["84004.83", "0.008268"], ["84004.77", "0.008097"], ["84004.66", "0.021138"], ["84001.14", "0.073244"], ["84000.80", "0"], ["84000.30", "0.056390"], ["83986.25", "0.008575"], ["83985.70", "3.896986"], ["83984.90", "0"], ["83983.43", "0.007252"], ["83983.40", "0.007340"], ["83983.29", "0.007656"], ["83977.20", "5.347028"], ["83976.40", "0"], ["83968.70", "4.078242"], ["83967.90", "0"], ["83960.20", "4.259497"], ["83959.40", "0"], ["83951.70", "5.437655"], ["83950.90", "0"], ["83943.20", "4.440752"], ["83942.40", "0"], ["83934.70", "4.893890"], ["83933.90", "0"], ["83926.20", "5.256400"], ["83925.40", "0"], ["83917.70", "5.528283"], ["83916.90", "0"], ["83909.20", "4.984517"], ["83908.40", "0"], ["83900.70", "5.165773"], ["83899.90", "0"], ["83892.20", "4.350124"], ["83891.40", "0"], ["83883.70", "4.803262"], ["83882.90", "0"], ["83875.20", "5.075145"], ["83874.40", "0"], ["83866.70", "5.618911"], ["83865.90", "0"], ["83858.20", "4.712635"], ["83857.40", "0"], ["83849.70", "3.987614"], ["83848.90", "0"], ["83841.20", "4.622007"], ["83840.40", "0"], ["83832.70", "4.531380"], ["83831.90", "0"], ["83824.20", "4.168869"], ["83823.40", "0"], ["83641.38", "0"], ["83641.00", "0"], ["83640.35", "0"], ["83640.15", "0"], ["83640.00", "0"], ["83639.71", "0"], ["83639.70", "0"], ["83639.15", "0"], ["83638.32", "0"], ["83638.30", "0"], ["83637.17", "0"], ["83636.36", "0"], ["83635.64", "0"], ["83634.09", "0"], ["83634.05", "0"], ["83633.88", "0"], ["83633.63", "0"], ["83633.61", "0"], ["83633.40", "0"], ["83633.33", "0"], ["83633.19", "0"], ["83632.65", "0"], ["83632.10", "0"], ["83632.02", "0"], ["83631.58", "0"], ["83631.57", "0"], ["83631.53", "0"], ["83631.09", "0"], ["83630.43", "0"], ["83629.43", "0"], ["83629.36", "0"], ["83629.03", "0"], ["83629.02", "0"], ["83628.94", "0"], ["83628.50", "0"], ["83627.68", "0"], ["83627.45", "0"]], "checksum": 1814296487, "ts": "1742555359373"}], "ts": 1742555359375}}
{"exchange": "BYBIT", "timestamp": 1742555359.539629, "message": {"topic": "orderbook.200.BTCUSDT", "ts": 1742555359519, "type": "delta", "data": {"s": "BTCUSDT", "b": [["84064", "0.191677"], ["84060.6", "0.0036"], ["84055.2", "0"], ["84047.7", "0"], ["84044.4", "0"], ["84042.3", "0.003575"], ["84035.6", "0.171"], ["84031.9", "0.487506"], ["84026.5", "0.0045"], ["84020.3", "0.234343"], ["84009", "13.960352"], ["84006.2", "0"], ["83990.2", "0.003697"]], "a": [["84079.9", "0.04"], ["84080.6", "0"], ["84084.8", "0.144179"], ["84086.6", "0.118804"], ["84088.6", "0"], ["84110.1", "0.150604"], ["84138.4", "0"]], "u": 20729, "seq": 67549991143}, "cts": 1742555359507}}
{"exchange": "BITGET", "timestamp": 1742555359.616192, "message": {"action": "update", "arg": {"instType": "SPOT", "channel": "books", "instId": "BTCUSDT"}, "data": [{"asks": [["84037.92", "0.088141"], ["84048.37", "0.013763"], ["84113.10", "0.476790"], ["84113.50", "3.366030"], ["84115.50", "0.072270"], ["84116.40", "2.723370"], ["84120.90", "0"], ["84122.40", "0"], ["84154.00", "3.987614"], ["84162.50", "5.075145"], ["84171.00", "4.622007"], ["84179.50", "5.165773"], ["84188.00", "4.712635"], ["84196.50", "5.347028"], ["84205.00", "5.618911"], ["84213.50", "4.531380"], ["84222.00", "5.256400"], ["84230.50", "4.168869"], ["84239.00", "5.437655"], ["84247.50", "4.259497"], ["84256.00", "4.984517"], ["84264.50", "3.896986"], ["84273.00", "4.803262"], ["84281.50", "4.350124"], ["84290.00", "4.078242"], ["84298.50", "4.893890"], ["84307.00", "5.528283"], ["84315.50", "4.440752"], ["84536.36", "0"]], "bids": [["84028.91", "2.043910"], ["84027.80", "11.305006"], ["84027.00", "3.693390"], ["84026.90", "2.152890"], ["84024.20", "0.070440"], ["84023.90", "0.067800"], ["84023.49", "0.004472"], ["84023.40", "0"], ["84022.50", "3.174900"], ["84022.10", "0.542400"], ["84014.20", "0"], ["83985.70", "4.078242"], ["83977.20", "5.165773"], ["83968.70", "3.987614"], ["83960.20", "4.622007"], ["83951.70", "4.531380"], ["83943.20", "4.350124"], ["83934.70", "4.168869"], ["83926.20", "5.618911"], ["83917.70", "5.347028"], ["83909.20", "4.259497"], ["83900.70", "5.528283"], ["83892.20", "4.984517"], ["83883.70", "5.256400"], ["83875.20", "4.803262"], ["83866.70", "5.075145"], ["83858.20", "3.896986"], ["83849.70", "4.440752"], ["83841.20", "4.712635"], ["83832.70", "5.437655"], ["83824.20", "4.893890"], ["83641.38", "0.000135"]], "checksum": -1289838776, "ts": "1742555359576"}], "ts": 1742555359579}}
{"exchange": "BYBIT", "timestamp": 1742555359.740417, "message": {"topic": "orderbook.200.BTCUSDT", "ts": 1742555359720, "type": "delta", "data": {"s": "BTCUSDT", "b": [["84056.4", "0.01"], ["84055.6", "0.005"], ["84032", "0.013"], ["84031.9", "0.500386"], ["84022.9", "0"], ["84022.8", "0.041082"], ["84020.3", "14.194695"], ["84009", "0"], ["83990.9", "1.125122"], ["83990.2", "0"]], "a": [["84089", "0.000099"], ["84138.1", "0"]], "u": 20730, "seq": 67549991161}, "cts": 1742555359702}}
{"exchange": "BITGET", "timestamp": 1742555359.816204, "message": {"action": "update", "arg": {"instType": "SPOT", "channel": "books", "instId": "BTCUSDT"}, "data": [{"asks": [["84062.30", "1.531031"], ["84089.77", "3.570610"], ["84097.90", "0.001500"], ["84117.20", "0.211050"], ["84118.00", "0"], ["84119.19", "0.403378"], ["84154.00", "4.350124"], ["84171.00", "5.256400"], ["84188.00", "4.893890"], ["84196.50", "4.078242"], ["84205.00", "4.712635"], ["84213.50", "3.987614"], ["84222.00", "5.437655"], ["84239.00", "4.440752"], ["84264.50", "5.618911"], ["84273.00", "4.622007"], ["84281.50", "5.347028"], ["84290.00", "4.803262"], ["84298.50", "4.531380"], ["84315.50", "3.896986"], ["84397.57", "0"], ["84406.14", "1.665109"], ["84533.33", "0"], ["84534.53", "0"], ["84535.32", "0"]], "bids": [["84029.40", "0.694293"], ["84027.80", "11.312911"], ["84027.00", "4.037520"], ["84026.90", "2.152680"], ["84014.30", "0"], ["83985.70", "4.984517"], ["83979.00", "0.000015"], ["83977.20", "5.075145"], ["83968.70", "4.440752"], ["83960.20", "4.712635"], ["83951.70", "5.165773"], ["83943.20", "3.987614"], ["83926.20", "5.256400"], ["83917.70", "5.437655"], ["83909.20", "3.896986"], ["83900.70", "4.893890"], ["83892.20", "4.078242"], ["83883.70", "4.531380"], ["83866.70", "5.528283"], ["83858.20", "4.622007"], ["83849.70", "5.347028"], ["83841.20", "4.259497"], ["83832.70", "4.350124"], ["83824.20", "5.618911"], ["83733.57", "1.652890"], ["83725.07", "0"]], "checksum": -559415597, "ts": "1742555359780"}], "ts": 1742555359783}}
{"exchange": "BYBIT", "timestamp": 1742555359.940885, "message": {"topic": "orderbook.200.BTCUSDT", "ts": 1742555359920, "type": "delta", "data": {"s": "BTCUSDT", "b": [["84056.9", "0.061698"]], "a": [], "u": 20731, "seq": 67549991175}, "cts": 1742555359916}}
{"exchange": "BYBIT", "timestamp": 1742556561.61049, "message": {"success": true, "ret_msg": "subscribe", "conn_id": "d59011eb-c49f-46ad-9bdd-f698ff66c36b", "op": "subscribe"}}
{"exchange": "BYBIT", "timestamp": 1742556561.613627, "message": {"topic": "orderbook.200.BTCUSDT", "ts": 1742556560320, "type": "snapshot", "data": {"s": "BTCUSDT", "b": [["83965.5", "0.302454"], ["83965.4", "0.001333"], ["83965", "0.003181"], ["83963.2", "0.001466"], ["83963", "0.071494"], ["83962.5", "0.000516"], ["83961.9", "0.000333"], ["83961.5", "0.002201"], ["83961.2", "0.001333"], ["83960.8", "0.003601"], ["83960.5", "0.000768"], ["83960", "0.00006"], ["83959.7", "0.000359"], ["83959.2", "0.015786"], ["83959.1", "0.011375"], ["83958.6", "0.001466"], ["83958.2", "0.027908"], ["83958.1", "0.005942"], ["83957.8", "0.132596"], ["83957.7", "0.040333"], ["83957.1", "0.01"], ["83957", "0.001537"], ["83956.8", "0.008438"], ["83956.6", "0.003181"], ["83956.3", "0.000127"], ["83956.1", "0.048"], ["83956", "0.04"], ["83955.7", "0.0715"], ["83955.2", "0.0063"], ["83955", "0.053084"], ["83954.9", "0.022751"], ["83954.3", "0.04"], ["83954.2", "0.04"], ["83954", "0.001466"], ["83953.8", "0.133745"], ["83953.7", "0.171"], ["83953.6", "0.004063"], ["83953.5", "0.000333"], ["83953.2", "0.000516"], ["83952.8", "0.001423"], ["83952.7", "0.04"], ["83952.6", "0.062186"], ["83952.4", "0.003181"], ["83952", "0.000272"], ["83951.6", "0.071504"], ["83951.3", "0.009"], ["83951.1", "0.04"], ["83951", "0.04"], ["83950.5", "0.016877"], ["83949.4", "0.001466"], ["83949.3", "0.046815"], ["83949.2", "0.023453"], ["83948.6", "0.001849"], ["83948.5", "0.009912"], ["83948.2", "0.003181"], ["83946.2", "0.006087"], ["83945.3", "0.158757"], ["83945.2", "0.171"], ["83945.1", "0.000333"], ["83944.8", "0.001466"], ["83944.4", "0.001423"], ["83944", "0.003697"], ["83942.1", "0.118804"], ["83941.9", "0.001116"], ["83941.3", "0.005942"], ["83941.1", "0.091643"], ["83940.9", "0.000333"], ["83940.2", "0.002799"], ["83940", "0.00006"], ["83939.8", "0.003181"], ["83939.4", "0.000516"], ["83939", "0.000118"], ["83937.6", "0.000359"], ["83937", "0.124747"], ["83936.9", "0.059399"], ["83936.8", "0.096092"], ["83936.7", "0.171333"], ["83936.5", "0.0045"], ["83936", "0.001423"], ["83935.8", "0.000337"], ["83935.7", "0.003181"], ["83935.5", "0.001556"], ["83935.1", "0.02552"], ["83934.8", "0.000516"], ["83934.7", "0.111958"], ["83932.8", "0.17559"], ["83932.6", "0.48675"], ["83932.5", "0.006179"], ["83931.8", "0.001333"], ["83931.5", "0.003181"], ["83930.9", "0.001466"], ["83930.2", "0.015"], ["83930.1", "0.022891"], ["83929.6", "0.003781"], ["83929", "0.003575"], ["83928.8", "0.011915"], ["83928.6", "0.115917"], ["83928.4", "0.024617"], ["83928.3", "0.000333"], ["83928.2", "0.171"], ["83927.8", "0.00477"], ["83927.6", "0.120227"], ["83927.4", "0.059399"], ["83927.3", "0.003181"], ["83927", "0.023814"], ["83926.5", "0.0016"], ["83926.3", "0.001466"], ["83925.7", "0.128686"], ["83925.5", "0.000516"], ["83924.8", "0.012882"], ["83924.7", "0.012882"], ["83924.5", "0.005942"], ["83924.4", "0.000083"], ["83924.1", "0.000333"], ["83924", "0.256755"], ["83923.9", "0.529799"], ["83923.4", "0.007286"], ["83923.1", "0.003181"], ["83922.9", "0.04"], ["83921.7", "0.001466"], ["83921.6", "0.023814"], ["83921.3", "0.032817"], ["83921.1", "0.071814"], ["83921", "0.04"], ["83920.9", "0.000516"], ["83920.2", "0.135608"], ["83920", "0.023874"], ["83919.9", "0.000333"], ["83919.8", "0.145192"], ["83919.7", "0.171"], ["83919.2", "0.001423"], ["83918.9", "0.003181"], ["83918.2", "0.053795"], ["83917.5", "0.118804"], ["83917.3", "0.030388"], ["83917.1", "0.001466"], ["83917", "0.044"], ["83916.8", "0.059399"], ["83916.3", "0.000516"], ["83915.7", "0.000333"], ["83915.5", "0.000359"], ["83915", "0.002576"], ["83914.7", "0.003181"], ["83913.1", "0.001071"], ["83912.5", "0.001466"], ["83912", "0.012"], ["83911.9", "0.04"], ["83911.7", "0.000516"], ["83911.5", "0.000333"], ["83911.3", "0.171"], ["83910.8", "0.001423"], ["83910.5", "0.003181"], ["83908.7", "0.114"], ["83907.8", "0.001466"], ["83907.7", "0.005942"], ["83907.4", "0.118804"], ["83907.3", "0.000333"], ["83907.1", "0.000516"], ["83906.6", "0.001333"], ["83906.5", "0.0045"], ["83906.3", "0.003181"], ["83905.4", "0.00112"], ["83904.8", "0.04"], ["83903.2", "0.001466"], ["83903.1", "0.000333"], ["83902.9", "0.171"], ["83902.4", "0.001939"], ["83902.2", "0.044"], ["83902.1", "0.164083"], ["83901.6", "0.089099"], ["83900.1", "0.00006"], ["83900", "0.056081"], ["83899.9", "0.059399"], ["83898.9", "0.000333"], ["83898.7", "13.532918"], ["83898.6", "0.001466"], ["83898.2", "0.001333"], ["83898.1", "0.053111"], ["83897.9", "0.003181"], ["83897.8", "0.000516"], ["83897.3", "0.118804"], ["83895.5", "0.003575"], ["83895.1", "0.235392"], ["83894.7", "0.012325"], ["83894.6", "0.000927"], ["83894.5", "0.171"], ["83894", "0.002889"], ["83893.8", "0.011992"], ["83893.7", "0.003181"], ["83893.4", "0.000449"], ["83893.2", "0.000516"], ["83891.3", "0.009"], ["83891.2", "0.04"], ["83890.9", "0.00625"], ["83890.7", "0.353794"], ["83890.6", "0.000333"], ["83890.5", "3.246386"], ["83890.3", "0.011992"], ["83890.2", "0.00253"], ["83890", "0.0002"]], "a": [["83965.6", "0.492059"], ["83968", "0.008438"], ["83970", "0.046494"], ["83970.1", "0.083385"], ["83970.3", "0.000333"], ["83970.6", "0.073187"], ["83971.1", "0.028288"], ["83971.7", "0.000514"], ["83972", "0.012469"], ["83972.5", "0.001466"], ["83973", "0.071485"], ["83973.2", "0.003814"], ["83973.4", "0.003239"], ["83973.8", "0.001333"], ["83974", "0.01"], ["83974.1", "0.0002"], ["83974.3", "0.016877"], ["83974.5", "0.000333"], ["83974.6", "0.00009"], ["83975", "0.0001"], ["83975.6", "0.198134"], ["83975.7", "0.111958"], ["83976.2", "0.024937"], ["83976.3", "0.000514"], ["83976.4", "0.02"], ["83977", "0.008"], ["83977.1", "0.001466"], ["83977.3", "0.066797"], ["83977.4", "0.02"], ["83977.6", "0.003242"], ["83977.9", "0.059399"], ["83978", "0.001333"], ["83978.1", "0.191"], ["83978.7", "0.000333"], ["83978.8", "0.020595"], ["83979.1", "0.04"], ["83979.2", "0.272769"], ["83979.3", "0.048"], ["83979.6", "0.02"], ["83979.8", "0.024411"], ["83980.1", "0.02357"], ["83980.8", "0.04"], ["83980.9", "0.000514"], ["83981", "0.048"], ["83981.4", "0.02"], ["83981.7", "0.001466"], ["83981.8", "0.003242"], ["83982", "0.04"], ["83982.2", "0.001333"], ["83982.3", "0.02"], ["83982.7", "0.5648"], ["83982.9", "0.000333"], ["83983", "0.02009"], ["83983.7", "0.325684"], ["83984.4", "0.048"], ["83984.6", "0.018376"], ["83985.6", "0.000514"], ["83986", "0.051242"], ["83986.1", "0.052"], ["83986.3", "0.001466"], ["83986.4", "0.001333"], ["83986.8", "0.477262"], ["83987", "0.182646"], ["83987.1", "0.000333"], ["83987.5", "0.103286"], ["83987.8", "0.000995"], ["83987.9", "0.0001"], ["83989.4", "0.059535"], ["83990.2", "0.003757"], ["83990.3", "0.059535"], ["83990.4", "0.035737"], ["83990.6", "0.064308"], ["83990.8", "0.023814"], ["83991", "0.001466"], ["83991.3", "0.000333"], ["83991.4", "0.026032"], ["83991.5", "0.04248"], ["83991.6", "0.029772"], ["83992.5", "0.023819"], ["83992.9", "0.029767"], ["83993.1", "0.0002"], ["83993.3", "0.281397"], ["83993.4", "0.079535"], ["83993.8", "0.059535"], ["83994", "0.078954"], ["83994.4", "0.003247"], ["83994.8", "0.001849"], ["83995.5", "0.000333"], ["83995.6", "0.12027"], ["83995.7", "0.049767"], ["83995.8", "0.163321"], ["83996", "0.089099"], ["83996.5", "0.0045"], ["83996.8", "0.071438"], ["83997.1", "0.171"], ["83998", "0.059535"], ["83998.2", "0.012743"], ["83998.3", "0.012743"], ["83998.6", "0.003247"], ["83998.8", "0.04"], ["83998.9", "0.04"], ["83999", "0.001333"], ["83999.4", "0.000516"], ["83999.7", "0.015333"], ["83999.8", "0.00009"], ["83999.9", "0.059399"], ["84000.2", "0.704124"], ["84000.3", "0.031041"], ["84002.8", "0.003247"], ["84003.1", "2.256735"], ["84003.2", "0.001333"], ["84003.3", "0.030042"], ["84003.5", "0.00465"], ["84003.9", "0.000333"], ["84004", "0.000516"], ["84004.1", "0.030042"], ["84004.5", "0.719778"], ["84004.6", "0.118804"], ["84004.7", "0.059545"], ["84004.8", "0.001466"], ["84004.9", "0.105408"], ["84005.4", "0.014068"], ["84005.5", "0.171"], ["84005.8", "0.030042"], ["84005.9", "0.009528"], ["84006.7", "0.005979"], ["84007", "0.003247"], ["84007.2", "0.059545"], ["84007.4", "0.355101"], ["84007.5", "1.556132"], ["84008", "0.000118"], ["84008.1", "0.000933"], ["84008.2", "0.036074"], ["84008.6", "0.000516"], ["84008.9", "0.030042"], ["84009.4", "0.060865"], ["84010", "0.029767"], ["84010.1", "0.030042"], ["84011.2", "3.18373"], ["84011.3", "0.009"], ["84011.4", "0.030042"], ["84011.6", "0.025146"], ["84012.1", "0.023813"], ["84012.3", "0.000333"], ["84012.5", "0.143137"], ["84013.3", "0.000516"], ["84013.9", "0.005953"], ["84014", "0.081293"], ["84014.1", "0.001466"], ["84014.2", "0.201042"], ["84015.4", "0.003248"], ["84015.6", "0.000359"], ["84015.7", "0.023813"], ["84015.8", "0.001333"], ["84016.5", "0.000333"], ["84016.6", "0.00009"], ["84016.8", "3.443935"], ["84017.2", "0.048"], ["84017.5", "0.023813"], ["84017.7", "0.118804"], ["84017.9", "0.000516"], ["84018.4", "0.023813"], ["84018.7", "0.001466"], ["84018.8", "0.059399"], ["84019.6", "0.003248"], ["84020", "0.013885"], ["84020.6", "0.04"], ["84020.7", "0.048333"], ["84022.3", "0.04"], ["84022.4", "0.048"], ["84022.5", "0.000516"], ["84022.6", "0.174"], ["84023.3", "0.001466"], ["84023.8", "0.043248"], ["84024.1", "0.048"], ["84024.2", "0.001333"], ["84024.5", "0.059535"], ["84024.9", "0.000333"], ["84025", "0.006032"], ["84025.3", "0.118804"], ["84025.4", "0.015"], ["84025.5", "0.04"], ["84026.5", "0.0045"], ["84027", "1.124639"], ["84027.1", "0.000516"], ["84027.4", "0.048"], ["84027.5", "0.052"], ["84027.7", "0.027532"], ["84027.8", "0.059399"], ["84027.9", "0.001466"], ["84028", "0.00325"], ["84028.4", "0.001333"], ["84028.5", "0.02501"], ["84028.6", "0.0006"], ["84029", "0.02381"], ["84029.1", "0.000333"], ["84030.6", "0.118804"], ["84030.8", "0.005952"], ["84030.9", "0.089099"], ["84031.1", "0.025312"]], "u": 26619, "seq": 67550548895}, "cts": 1742556560302}}
{"exchange": "BYBIT", "timestamp": 1742556561.615205, "message": {"topic": "orderbook.200.BTCUSDT", "ts": 1742556560520, "type": "delta", "data": {"s": "BTCUSDT", "b": [["83965.5", "0.308817"], ["83949.3", "0.012842"], ["83947.9", "0.059362"], ["83945.3", "0.084198"], ["83941.1", "0"], ["83940.9", "0.061605"], ["83933.9", "0.120928"], ["83924.9", "0.013"], ["83924.7", "0"], ["83890", "0"]], "a": [["83965.6", "0.493845"], ["83982.9", "0.060266"], ["83989.9", "0.056947"], ["83993.3", "0.094406"], ["83996.9", "0.118471"], ["83997.9", "0.013"], ["83998", "0.072278"], ["83998.2", "0"], ["83998.3", "0"], ["83998.5", "0.04"], ["83998.6", "0.043247"], ["83998.8", "0"], ["83998.9", "0"], ["84031", "0.171"], ["84031.1", "0"]], "u": 26620, "seq": 67550548939}, "cts": 1742556560516}}
{"exchange": "BYBIT", "timestamp": 1742556561.616059, "message": {"topic": "orderbook.200.BTCUSDT", "ts": 1742556560719, "type": "delta", "data": {"s": "BTCUSDT", "b": [["83949.3", "0.029923"], ["83920.2", "0.135594"], ["83898.7", "0"], ["83895.9", "13.664616"]], "a": [["83965.6", "0.322845"], ["83997.9", "0.012743"]], "u": 26621, "seq": 67550548965}, "cts": 1742556560717}}
{"exchange": "BYBIT", "timestamp": 1742556561.616793, "message": {"topic": "orderbook.200.BTCUSDT", "ts": 1742556560919, "type": "delta", "data": {"s": "BTCUSDT", "b": [["83965.5", "0.108817"], ["83964.2", "0.012512"], ["83963", "0"], ["83962.1", "0.038586"], ["83962", "0.071495"], ["83959.2", "0.001779"], ["83957.8", "0.066131"], ["83957.7", "0.000333"], ["83956.1", "0"], ["83956", "0"], ["83954.3", "0"], ["83954.2", "0"], ["83953.8", "0.088907"], ["83952.7", "0"], ["83952.6", "0.018186"], ["83951.1", "0"], ["83951", "0"], ["83949.9", "0.04"], ["83947.9", "0"], ["83941", "0.058016"], ["83940.9", "0.000333"], ["83936.9", "0"], ["83936.8", "0.155491"], ["83933.9", "0"], ["83930.2", "0"], ["83928.8", "0"], ["83927", "0"], ["83924.9", "0"], ["83924.7", "0.012882"], ["83924", "0.232938"], ["83923.4", "0.001333"], ["83921.6", "0"], ["83921.3", "0.009"], ["83921.1", "0.048"], ["83920.2", "0"], ["83916.2", "0.011917"], ["83911.9", "0.063819"], ["83911.7", "0.136117"], ["83911", "0.023819"], ["83909.2", "0.023819"], ["83907.4", "0.124758"], ["83905.6", "0.023819"], ["83905.1", "0.023819"], ["83895.9", "0"], ["83890", "0.0002"], ["83889.9", "0.011992"], ["83889.8", "0.001333"], ["83889.5", "0.003181"], ["83889.4", "0.001466"], ["83889", "0.100315"], ["83888.8", "0.000445"]], "a": [["83965.6", "0.577299"], ["83965.8", "0.106766"], ["83965.9", "0.035727"], ["83966.1", "0.035727"], ["83970", "0"], ["83982.2", "0.002332"], ["83982.9", "0.000333"], ["83983.4", "0.011917"], ["83989.9", "0"], ["83994.8", "0.025668"], ["83995.3", "0.023819"], ["83996.9", "0"], ["83997.1", "0.176954"], ["83997.8", "0.012743"], ["83998", "0.059535"], ["83998.9", "0.023819"], ["84000.3", "0.030042"], ["84000.7", "0.023819"], ["84001.6", "0.023819"], ["84004.9", "0.093494"], ["84028.5", "0.0012"], ["84029", "0"], ["84029.1", "0"], ["84030.6", "0"], ["84030.8", "0"], ["84030.9", "0"], ["84031", "0"]], "u": 26622, "seq": 67550549571}, "cts": 1742556560916}}
{"exchange": "BYBIT", "timestamp": 1742556561.617561, "message": {"topic": "orderbook.200.BTCUSDT", "ts": 1742556561120, "type": "delta", "data": {"s": "BTCUSDT", "b": [["83965.5", "0.006363"], ["83962.1", "0"], ["83953.8", "0.150873"], ["83953.3", "0.04"], ["83951.7", "0.048"], ["83951.6", "0.111504"], ["83950.1", "0.04"], ["83949.4", "0.116807"], ["83949.3", "0.012842"], ["83948.4", "0.044"], ["83948.2", "0.043181"], ["83946.7", "0.04"], ["83946.6", "0.04"], ["83946.2", "0.0003"], ["83942.1", "0"], ["83941", "0"], ["83939.6", "0.165868"], ["83934.7", "0"], ["83934.2", "0.111966"], ["83930.5", "0.290315"], ["83924.8", "0"], ["83924.6", "0.012882"], ["83914.6", "0.135601"], ["83911.7", "0.000516"], ["83893.1", "13.664616"], ["83890", "0"], ["83889.9", "0"], ["83889.8", "0"], ["83889.5", "0"], ["83889.4", "0"], ["83889", "0"], ["83888.8", "0"]], "a": [["83965.6", "0.746175"], ["83974.6", "0.116513"], ["83984.4", "0.234846"], ["83993.5", "0.291986"], ["84000.3", "2.286777"], ["84003.1", "0"]], "u": 26623, "seq": 67550549710}, "cts": 1742556561114}}
{"exchange": "BYBIT", "timestamp": 1742556561.618262, "message": {"topic": "orderbook.200.BTCUSDT", "ts": 1742556561320, "type": "delta", "data": {"s": "BTCUSDT", "b": [["83962", "0"], ["83959.2", "0.015786"], ["83955.7", "0"], ["83955", "0.053237"], ["83953.8", "0.222375"], ["83953.4", "0.04"], ["83949.5", "0.061348"], ["83949.4", "0.001466"], ["83949.3", "0.000333"], ["83946.2", "0.006177"], ["83945.3", "0.055493"], ["83939.7", "0.087482"], ["83939.6", "0"], ["83930.5", "0"], ["83890", "0.0002"]], "a": [["83966.3", "0.003576"], ["83974.6", "0.00009"], ["83977.1", "0.090565"], ["83984.4", "0.048"], ["83990.6", "0.060732"], ["83993.5", "0"], ["83997.5", "2.256735"], ["84000.3", "0.030042"], ["84028.6", "0"]], "u": 26624, "seq": 67550549801}, "cts": 1742556561296}}
{"exchange": "BYBIT", "timestamp": 1742556561.618985, "message": {"topic": "orderbook.200.BTCUSDT", "ts": 1742556561519, "type": "delta", "data": {"s": "BTCUSDT", "b": [["83965.5", "0.010612"], ["83964.2", "0.015512"], ["83946.2", "0.0003"], ["83939.7", "0"], ["83889.9", "0.011992"]], "a": [["83965.6", "0.752175"], ["83966.3", "0"], ["83997.8", "0"], ["83997.9", "0"], ["83998.1", "0.012743"], ["83998.2", "0.012743"], ["83998.5", "0"], ["83998.6", "0.003247"], ["83998.8", "0.04"], ["83998.9", "0.063819"], ["84000.2", "0.039256"], ["84028.6", "0.0006"]], "u": 26625, "seq": 67550549848}, "cts": 1742556561515}}
{"exchange": "BITGET", "timestamp": 1742556561.700067, "message": {"event": "subscribe", "arg": {"instType": "SPOT", "channel": "books", "instId": "BTCUSDT"}}}
{"exchange": "BYBIT", "timestamp": 1742556561.738351, "message": {"topic": "orderbook.200.BTCUSDT", "ts": 1742556561720, "type": "delta", "data": {"s": "BTCUSDT", "b": [["83965.5", "0.110612"], ["83963.3", "0.071494"], ["83957.8", "0.050151"], ["83955.7", "0.0715"], ["83953.8", "0.150873"], ["83925", "0.013"], ["83924.9", "0.012882"], ["83924.7", "0"], ["83924.6", "0"], ["83890", "0"], ["83889.9", "0"]], "a": [["83967.4", "0.003576"], ["83977.1", "0.001466"], ["83997.5", "0"], ["83997.8", "0.013"], ["83997.9", "0.012743"], ["83998.1", "0"], ["83998.2", "0"], ["83998.5", "0.04"], ["83998.6", "0.043247"], ["83998.8", "0"], ["83998.9", "0.023819"], ["84000.3", "2.286777"]], "u": 26626, "seq": 67550549907}, "cts": 1742556561715}}
{"exchange": "BITGET", "timestamp": 1742556561.750501, "message": {"action": "snapshot", "arg": {"instType": "SPOT", "channel": "books", "instId": "BTCUSDT"}, "data": [{"asks": [["83945.96", "1.599340"], ["83946.00", "0.124003"], ["83946.01", "0.053200"], ["83946.25", "0.346369"], ["83946.27", "0.013774"], ["83952.01", "0.015749"], ["83953.00", "0.493429"], ["83953.01", "0.209200"], ["83953.46", "1.531031"], ["83955.50", "0.094345"], ["83955.51", "0.314484"], ["83961.12", "0.017476"], ["83962.00", "0.062760"], ["83962.01", "0.209200"], ["83964.51", "0.001145"], ["83966.86", "0.035952"], ["83966.93", "0.049500"], ["83967.26", "0.119870"], ["83968.58", "0.035961"], ["83969.00", "0.006356"], ["83969.11", "0.006356"], ["83969.44", "0.006356"], ["83970.00", "0.002537"], ["83970.55", "0.010984"], ["83970.82", "0.006356"], ["83970.96", "0.006356"], ["83970.99", "0.014055"], ["83971.00", "0.156495"], ["83971.01", "0.209200"], ["83971.47", "0.016429"], ["83971.52", "0.006356"], ["83971.99", "0.006356"], ["83972.00", "0.006356"], ["83972.30", "0.119883"], ["83972.35", "0.016429"], ["83972.51", "0.006356"], ["83972.53", "0.006356"], ["83973.99", "0.006357"], ["83974.00", "0.010985"], ["83974.77", "0.138400"], ["83974.82", "0.009990"], ["83975.48", "0.012472"], ["83975.77", "0.119850"], ["83976.34", "0.079683"], ["83976.77", "0.119858"], ["83976.90", "0.119867"], ["83977.19", "0.015895"], ["83977.33", "0.009989"], ["83979.66", "1.215931"], ["83980.80", "0.183656"], ["83981.14", "0.015892"], ["83981.30", "3.575091"], ["83981.95", "0.010988"], ["83983.00", "0.001142"], ["83983.40", "0.010000"], ["83984.00", "0.062760"], ["83984.01", "0.209200"], ["83985.00", "0.002010"], ["83987.00", "0.005159"], ["83989.00", "0.013576"], ["83990.38", "0.221327"], ["83990.39", "0.714367"], ["83991.00", "0.035728"], ["83993.00", "0.105941"], ["83993.01", "0.209200"], ["83995.00", "0.247422"], ["83996.20", "0.000958"], ["83996.99", "0.476292"], ["83997.00", "0.651110"], ["83999.00", "1.713252"], ["84000.00", "0.002000"], ["84001.00", "4.508557"], ["84002.01", "0.001598"], ["84003.00", "11.864624"], ["84003.10", "0.001860"], ["84003.20", "0.001045"], ["84003.30", "0.001009"], ["84003.40", "3.275280"], ["84003.93", "0.001597"], ["84004.00", "0.068010"], ["84004.41", "0.209200"], ["84005.70", "0.022620"], ["84006.60", "0.074250"], ["84006.90", "0.303000"], ["84007.20", "0.006030"], ["84007.50", "0.026820"], ["84008.00", "0.067800"], ["84008.30", "0.144780"], ["84008.40", "1.138890"], ["84008.50", "0.069090"], ["84009.10", "0.318780"], ["84009.50", "0.071040"], ["84009.70", "0.361800"], ["84009.90", "0.714900"], ["84010.00", "0.067800"], ["84010.40", "0.496590"], ["84010.80", "0.714900"], ["84010.95", "0.000089"], ["84011.60", "0.714900"], ["84011.70", "0.156000"], ["84012.00", "0.067800"], ["84012.60", "0.144000"], ["84013.20", "0.191130"], ["84013.30", "1.021800"], ["84013.40", "0.192000"], ["84013.70", "0.168000"], ["84013.80", "0.180000"], ["84014.00", "0.067800"], ["84014.20", "0.035700"], ["84014.80", "1.055730"], ["84015.90", "0.120000"], ["84016.00", "0.756330"], ["84016.10", "0.534660"], ["84016.70", "0.010015"], ["84016.90", "0.198311"], ["84018.85", "0.209200"], ["84019.10", "0.398112"], ["84021.00", "1.785267"], ["84028.01", "0.043255"], ["84028.02", "0.209200"], ["84030.00", "0.002000"], ["84045.00", "4.174274"], ["84048.41", "0.209200"], ["84052.55", "0.001810"], ["84053.40", "3.902039"], ["84060.00", "0.211200"], ["84060.95", "0.003620"], ["84061.80", "4.083529"], ["84063.92", "0.125776"], ["84068.41", "0.209200"], ["84070.20", "4.990980"], ["84074.74", "0.009541"], ["84078.60", "3.992784"], ["84078.70", "0.307977"], ["84085.77", "0.071253"], ["84087.00", "4.900235"], ["84087.41", "0.057001"], ["84088.99", "0.209200"], ["84089.00", "0.000180"], ["84090.00", "0.002000"], ["84090.31", "0.071045"], ["84093.60", "0.001428"], ["84095.00", "0.001000"], ["84095.40", "4.446509"], ["84103.80", "4.355764"], ["84112.20", "4.809489"], ["84113.41", "0.209200"], ["84113.70", "0.010010"], ["84120.00", "0.002000"], ["84120.60", "5.626195"], ["84121.82", "0.209200"], ["84125.00", "0.000107"], ["84129.00", "5.263215"], ["84134.63", "0.209200"], ["84137.08", "0.000039"], ["84137.40", "5.172470"], ["84138.91", "0.166116"], ["84145.50", "0.209200"], ["84145.80", "5.353960"], ["84150.00", "0.002064"], ["84153.86", "0.012000"], ["84153.90", "0.209200"], ["84154.20", "5.444705"], ["84160.00", "0.001469"], ["84162.60", "4.537254"], ["84166.10", "0.001403"], ["84169.99", "0.209200"], ["84170.40", "0.024945"], ["84171.00", "4.627999"], ["84174.51", "0.000388"], ["84178.41", "0.209200"], ["84179.40", "4.718744"], ["84180.00", "0.002000"], ["84186.10", "0.302524"], ["84186.81", "0.209200"], ["84187.80", "5.081725"], ["84188.00", "0.000202"], ["84192.00", "0.001184"], ["84195.21", "0.209200"], ["84196.20", "4.265019"], ["84203.61", "0.209200"], ["84204.60", "5.535450"], ["84210.00", "0.002000"], ["84212.01", "0.209200"], ["84220.41", "0.209200"], ["84222.50", "0.001720"], ["84228.10", "0.301510"], ["84228.81", "0.209200"], ["84233.38", "0.001273"], ["84234.12", "0.000044"], ["84237.21", "0.209200"], ["84240.00", "0.002000"], ["84245.00", "0.000149"], ["84250.00", "0.000791"], ["84252.44", "0.000143"], ["84253.92", "0.209200"], ["84259.99", "0.000017"], ["84266.08", "0.000016"], ["84266.67", "0.000078"], ["84269.24", "0.000032"], ["84270.00", "0.003095"], ["84270.98", "0.000052"], ["84272.72", "0.000105"], ["84275.00", "0.000671"], ["84280.00", "0.000614"], ["84285.00", "0.000434"], ["84285.71", "0.000010"], ["84285.95", "0.000028"], ["84286.79", "0.000016"], ["84287.50", "0.000076"], ["84288.89", "0.000361"], ["84294.68", "0.000019"], ["84296.85", "1.688998"], ["84297.06", "0.000035"], ["84300.00", "0.024840"], ["84307.00", "0.000113"], ["84307.23", "0.000008"], ["84309.09", "0.000010"], ["84310.34", "0.000331"], ["84310.35", "0.000146"], ["84311.11", "0.000025"], ["84312.50", "0.000125"], ["84313.03", "0.000024"], ["84314.97", "0.000008"], ["84316.67", "0.000322"], ["84317.24", "0.000135"], ["84317.40", "0.000010"], ["84318.59", "0.000027"], ["84319.15", "0.000137"], ["84319.18", "0.000039"], ["84320.00", "0.000288"], ["84322.11", "0.000008"], ["84324.32", "0.000059"], ["84325.00", "0.002294"], ["84325.07", "0.000161"], ["84326.09", "0.000010"], ["84326.42", "0.000023"], ["84327.14", "0.000039"], ["84327.73", "0.041940"], ["84328.95", "0.000174"], ["84329.64", "0.000026"], ["84330.00", "0.002403"], ["84332.00", "0.000008"], ["84333.33", "0.002262"], ["84333.36", "0.000010"], ["84333.38", "0.000008"], ["84334.48", "0.000096"], ["84334.77", "0.000022"], ["84336.00", "0.000133"], ["84336.23", "0.000013"], ["84336.29", "0.000010"], ["84336.34", "0.000176"], ["84337.25", "0.000067"], ["84337.35", "0.000008"], ["84338.46", "0.000015"], ["84339.21", "0.000010"], ["84339.29", "0.000029"], ["84339.62", "0.000051"], ["84340.00", "0.018824"], ["84340.72", "0.000066"], ["84341.01", "0.000008"], ["84342.11", "0.000051"], ["84342.63", "0.000009"], ["84342.70", "0.000423"], ["84343.07", "0.000014"], ["84343.70", "0.000075"], ["84343.97", "0.000188"], ["84345.00", "0.000403"], ["84346.43", "0.000128"], ["84346.94", "0.000085"], ["84347.69", "0.000009"], ["84347.83", "0.016818"], ["84348.21", "0.000036"], ["84348.27", "0.012402"], ["84348.62", "0.000072"], ["84350.00", "0.000041"], ["84350.79", "0.000033"], ["84354.10", "0.520437"], ["84354.58", "0.000115"], ["84354.64", "0.000018"], ["84354.82", "0.000078"], ["84354.84", "0.000194"], ["84356.98", "0.000048"], ["84357.14", "0.000273"], ["84358.29", "0.000024"], ["84359.83", "0.000010"], ["84360.00", "0.002661"], ["84363.63", "0.000057"], ["84363.64", "0.000078"], ["84365.90", "0.002343"], ["84366.14", "0.000162"], ["84366.15", "0.000061"], ["84366.19", "0.000022"], ["84366.60", "0.000011"], ["84366.96", "0.000018"], ["84367.10", "0.000014"], ["84367.82", "0.000476"], ["84368.38", "0.000009"], ["84368.42", "0.000284"], ["84370.00", "0.000052"], ["84370.59", "0.000071"], ["84370.97", "0.000020"], ["84371.86", "0.000012"], ["84375.00", "0.001884"], ["84376.31", "0.000016"], ["84378.11", "0.000008"], ["84378.38", "0.000009"], ["84378.45", "0.000015"], ["84380.00", "0.031680"], ["84381.82", "0.000008"], ["84382.00", "0.000035"], ["84382.35", "0.000071"], ["84383.41", "0.000053"], ["84383.69", "0.000248"], ["84384.38", "0.000424"], ["84384.61", "0.000008"], ["84386.19", "0.000019"], ["84386.67", "0.000013"], ["84387.50", "0.006969"], ["84387.76", "0.000024"], ["84389.61", "0.000088"], ["84390.00", "0.002000"], ["84390.01", "0.000387"], ["84391.30", "0.000018"], ["84393.31", "0.000050"], ["84396.55", "0.000016"], ["84396.98", "0.007500"], ["84397.59", "0.000008"], ["84397.69", "0.000275"], ["84398.26", "0.000068"], ["84399.54", "0.000030"], ["84399.91", "0.000018"], ["84399.99", "0.000022"], ["84400.00", "0.057891"], ["84400.18", "0.000024"], ["84402.40", "0.001273"], ["84403.39", "0.000023"], ["84403.76", "0.000099"], ["84403.98", "0.007500"], ["84404.26", "0.000137"], ["84404.28", "0.000039"], ["84406.06", "0.000008"], ["84406.83", "0.000064"], ["84407.50", "0.000031"], ["84410.00", "0.000059"], ["84410.04", "0.000025"], ["84411.11", "0.000361"], ["84411.43", "0.000008"], ["84411.76", "0.000101"], ["84411.77", "0.000020"], ["84412.50", "0.000049"], ["84413.04", "0.000010"], ["84413.33", "0.000073"], ["84413.79", "0.000135"], ["84414.29", "0.000074"], ["84414.41", "0.000051"], ["84415.09", "0.000008"], ["84416.67", "0.000355"], ["84418.34", "0.000046"], ["84419.69", "0.000023"], ["84420.00", "0.002238"], ["84420.17", "0.041940"], ["84422.71", "0.000010"], ["84423.08", "0.000067"], ["84423.53", "0.000105"], ["84424.00", "0.000022"], ["84424.12", "0.000146"], ["84425.69", "0.000314"], ["84426.68", "0.000101"], ["84427.08", "0.000014"], ["84427.92", "0.000323"], ["84428.57", "0.000057"], ["84429.82", "0.000022"], ["84430.50", "0.000113"], ["84430.74", "0.000010"], ["84430.77", "0.000015"], ["84431.23", "0.000039"], ["84432.43", "0.000008"], ["84433.33", "0.000347"], ["84434.78", "0.000008"], ["84435.26", "0.000161"], ["84436.26", "0.000009"], ["84437.14", "0.000017"], ["84437.50", "0.000725"], ["84437.75", "0.000013"], ["84438.44", "0.000176"], ["84440.00", "0.000008"], ["84442.54", "0.000096"], ["84443.07", "0.000423"], ["84444.25", "0.000013"], ["84444.41", "0.000371"], ["84444.44", "0.000574"], ["84444.92", "0.000022"], ["84446.04", "0.000016"], ["84446.38", "0.000013"], ["84446.43", "0.000036"], ["84447.80", "0.000718"], ["84448.75", "0.000066"], ["84448.98", "0.000085"], ["84449.11", "0.000028"], ["84449.34", "0.000010"], ["84450.00", "0.007851"], ["84451.88", "0.000010"], ["84452.66", "0.000009"], ["84453.76", "0.000054"], ["84454.43", "0.000061"], ["84454.53", "0.000019"], ["84454.55", "0.000083"], ["84454.60", "0.000093"], ["84455.31", "0.000028"], ["84456.14", "0.000033"], ["84456.52", "0.002633"], ["84457.00", "0.000009"], ["84458.06", "0.000020"], ["84458.72", "0.000072"], ["84458.82", "0.000071"], ["84458.97", "0.000153"], ["84459.08", "0.000008"], ["84459.22", "0.000188"], ["84459.69", "0.000051"], ["84460.00", "0.000086"], ["84460.23", "0.000010"], ["84460.49", "0.000009"], ["84460.87", "0.000069"], ["84460.91", "0.000012"], ["84461.00", "0.000008"], ["84462.50", "0.000076"], ["84464.28", "0.000008"], ["84465.83", "0.000016"], ["84466.67", "0.000157"], ["84470.34", "0.000017"], ["84470.59", "0.000071"], ["84473.14", "0.000126"], ["84473.68", "0.000192"], ["84474.78", "0.000099"], ["84475.00", "0.007068"], ["84475.81", "0.000039"], ["84476.97", "0.000063"], ["84477.61", "0.000095"], ["84477.67", "0.000008"], ["84478.74", "0.000036"], ["84479.37", "0.000090"], ["84480.00", "0.002308"], ["84481.00", "0.000069"], ["84481.77", "0.000011"], ["84482.67", "0.000133"], ["84482.76", "0.000016"], ["84485.20", "0.000537"], ["84485.39", "0.000020"], ["84485.71", "0.000128"], ["84485.98", "0.000034"], ["84486.49", "0.000009"], ["84486.82", "0.000135"], ["84487.00", "0.000119"], ["84487.16", "0.000035"], ["84487.32", "0.000024"], ["84487.95", "0.000008"], ["84488.88", "0.000025"], ["84489.36", "0.000137"], ["84489.39", "0.000039"], ["84489.80", "0.000010"], ["84490.00", "0.007510"], ["84490.13", "0.000093"], ["84490.91", "0.000018"], ["84491.26", "0.000008"], ["84491.87", "0.000019"], ["84492.06", "0.000009"], ["84496.43", "0.000273"], ["84496.66", "0.004837"], ["84496.73", "0.000043"], ["84497.14", "0.000008"], ["84497.26", "0.000010"], ["84500.00", "0.121418"], ["84500.03", "0.000010"], ["84500.04", "0.000008"], ["84500.11", "0.000012"], ["84501.24", "0.000010"], ["84501.28", "0.000019"], ["84501.32", "0.000326"], ["84501.99", "0.000009"], ["84503.33", "0.010000"], ["84503.57", "0.000074"], ["84504.50", "0.000051"], ["84504.74", "0.000013"], ["84506.54", "0.000008"], ["84508.00", "0.001210"], ["84508.37", "0.000050"], ["84508.46", "0.000013"], ["84508.47", "0.000023"], ["84510.34", "0.000135"], ["84512.00", "0.000012"], ["84512.19", "0.000016"], ["84512.61", "0.041940"], ["84512.95", "0.000023"], ["84514.29", "0.000059"], ["84516.67", "0.000010"], ["84517.54", "0.000022"], ["84517.86", "0.000016"], ["84518.98", "0.000029"], ["84520.00", "0.000318"]], "bids": [["83945.95", "0.038228"], ["83945.00", "0.000032"], ["83944.00", "0.000032"], ["83943.00", "0.000032"], ["83942.61", "0.014216"], ["83942.01", "0.047852"], ["83942.00", "0.000032"], ["83941.53", "0.002907"], ["83941.00", "0.000032"], ["83940.84", "0.002907"], ["83940.00", "0.003263"], ["83939.00", "0.001048"], ["83938.00", "0.000032"], ["83937.00", "0.001014"], ["83936.20", "0.209200"], ["83936.09", "0.001145"], ["83936.00", "0.000032"], ["83935.00", "0.001292"], ["83934.00", "0.000032"], ["83933.00", "0.003401"], ["83932.12", "0.111965"], ["83932.00", "0.000032"], ["83931.00", "0.008949"], ["83930.00", "0.000649"], ["83929.63", "0.020536"], ["83929.51", "0.006215"], ["83929.00", "0.023654"], ["83928.00", "0.000032"], ["83927.31", "0.270882"], ["83927.00", "0.062249"], ["83926.56", "0.089610"], ["83926.30", "0.008512"], ["83926.29", "0.010013"], ["83926.12", "0.247933"], ["83926.00", "0.000032"], ["83925.98", "0.024965"], ["83925.95", "0.009599"], ["83925.93", "0.008248"], ["83925.07", "0.209200"], ["83925.00", "0.163813"], ["83924.92", "0.084057"], ["83924.50", "0.017842"], ["83924.29", "0.018280"], ["83924.02", "0.004023"], ["83924.00", "0.000032"], ["83923.95", "0.005954"], ["83923.01", "0.608935"], ["83923.00", "0.431085"], ["83922.87", "0.055734"], ["83922.63", "0.017127"], ["83922.44", "0.007141"], ["83922.15", "0.008907"], ["83922.06", "0.008724"], ["83922.02", "0.010347"], ["83922.00", "0.000032"], ["83921.99", "0.007350"], ["83921.94", "0.028905"], ["83921.81", "0.009876"], ["83921.75", "0.008544"], ["83921.70", "0.015132"], ["83921.65", "0.005589"], ["83921.47", "0.009007"], ["83921.46", "0.007954"], ["83921.15", "0.025220"], ["83921.09", "0.225197"], ["83921.08", "0.012472"], ["83921.00", "1.134435"], ["83920.98", "0.017375"], ["83920.97", "0.008196"], ["83920.00", "0.001263"], ["83919.79", "0.314460"], ["83919.44", "0.052036"], ["83919.43", "0.012673"], ["83919.30", "3.055957"], ["83919.00", "2.985356"], ["83918.90", "0.001650"], ["83918.60", "0.001045"], ["83918.57", "0.018543"], ["83918.43", "0.714980"], ["83918.10", "0.962520"], ["83918.07", "0.254273"], ["83918.00", "0.008970"], ["83917.68", "0.268752"], ["83917.40", "0.045240"], ["83917.35", "0.022860"], ["83917.00", "0.000032"], ["83916.90", "0.045210"], ["83916.67", "0.222981"], ["83916.50", "1.045410"], ["83916.46", "0.260159"], ["83916.25", "0.076219"], ["83916.20", "2.608650"], ["83916.05", "0.021159"], ["83916.00", "0.000032"], ["83915.90", "0.304350"], ["83915.77", "0.209200"], ["83915.70", "0.240000"], ["83915.40", "0.135360"], ["83915.00", "0.000032"], ["83914.80", "0.030000"], ["83914.70", "0.480000"], ["83914.00", "0.074865"], ["83913.80", "0.144780"], ["83913.00", "0.000032"], ["83912.30", "0.073317"], ["83912.00", "0.000032"], ["83911.43", "0.056446"], ["83911.11", "0.008279"], ["83911.10", "3.770970"], ["83911.00", "0.009032"], ["83910.40", "0.012660"], ["83910.00", "0.007082"], ["83909.78", "0.000878"], ["83909.74", "0.025188"], ["83909.70", "0.153580"], ["83909.61", "0.008069"], ["83909.50", "0.021600"], ["83909.00", "0.120000"], ["83908.00", "0.000032"], ["83907.35", "0.209200"], ["83907.00", "0.000032"], ["83906.00", "0.000032"], ["83905.00", "0.012065"], ["83904.00", "0.000032"], ["83903.00", "0.000032"], ["83902.15", "0.008024"], ["83902.02", "0.008329"], ["83902.01", "0.008608"], ["83902.00", "0.000032"], ["83901.91", "0.008437"], ["83901.83", "0.005320"], ["83901.73", "0.006481"], ["83901.47", "0.007314"], ["83901.38", "0.009222"], ["83901.35", "0.006767"], ["83901.33", "0.006913"], ["83901.00", "0.000032"], ["83900.00", "0.000032"], ["83899.50", "0.000396"], ["83899.00", "0.000032"], ["83898.93", "0.209200"], ["83898.00", "0.000032"], ["83897.00", "0.000032"], ["83896.00", "0.000032"], ["83895.65", "0.017476"], ["83895.00", "0.000939"], ["83894.39", "0.005058"], ["83894.36", "0.008102"], ["83894.32", "0.008275"], ["83894.00", "0.000017"], ["83891.87", "0.001177"], ["83891.36", "0.003602"], ["83890.51", "0.209200"], ["83890.00", "0.000617"], ["83889.93", "0.001174"], ["83882.09", "0.209200"], ["83880.30", "0.202932"], ["83880.00", "0.003231"], ["83878.52", "0.007443"], ["83877.01", "0.000023"], ["83877.00", "4.990980"], ["83876.01", "0.005960"], ["83875.81", "0.071253"], ["83875.74", "0.008582"], ["83875.16", "0.000179"], ["83875.00", "0.000679"], ["83873.68", "0.209200"], ["83873.52", "0.000135"], ["83873.46", "0.007346"], ["83873.41", "0.007257"], ["83873.29", "0.007660"], ["83873.10", "0.057001"], ["83872.64", "0.071045"], ["83870.20", "0.000948"], ["83870.00", "0.000617"], ["83868.60", "3.992784"], ["83868.39", "0.002014"], ["83866.67", "0.002945"], ["83865.27", "0.209200"], ["83865.00", "0.000924"], ["83862.50", "0.006969"], ["83861.03", "0.001810"], ["83860.29", "0.000041"], ["83860.20", "4.537254"], ["83860.00", "0.001234"], ["83859.54", "0.000008"], ["83857.14", "0.000079"], ["83857.13", "0.000019"], ["83856.86", "0.209200"], ["83856.11", "0.010000"], ["83854.55", "0.000009"], ["83854.17", "0.000020"], ["83852.94", "0.000071"], ["83852.50", "0.000043"], ["83851.99", "0.024945"], ["83851.98", "0.003620"], ["83851.85", "0.000011"], ["83851.84", "0.000219"], ["83851.80", "5.263215"], ["83850.00", "0.003028"], ["83848.45", "0.209200"], ["83848.39", "0.000020"], ["83846.90", "0.296645"], ["83846.15", "0.000111"], ["83844.83", "0.000008"], ["83844.60", "0.001459"], ["83843.40", "4.083529"], ["83842.11", "0.000033"], ["83841.18", "0.000071"], ["83840.04", "0.209200"], ["83840.00", "0.001282"], ["83839.72", "0.000033"], ["83839.18", "0.000016"], ["83837.84", "0.000009"], ["83837.59", "0.000012"], ["83836.36", "0.000008"], ["83835.56", "0.000009"], ["83835.42", "0.012367"], ["83835.00", "5.444705"], ["83831.63", "0.209200"], ["83831.11", "0.000011"], ["83830.59", "0.000010"], ["83830.00", "0.000680"], ["83828.72", "0.010010"], ["83828.57", "0.000016"], ["83826.67", "0.000073"], ["83826.60", "4.355764"], ["83825.00", "0.000672"], ["83823.22", "0.209200"], ["83822.12", "0.000067"], ["83820.00", "0.003247"], ["83819.04", "0.005960"], ["83818.20", "3.902039"], ["83818.18", "0.001526"], ["83818.17", "0.000029"], ["83816.67", "0.000010"], ["83816.28", "0.000009"], ["83816.00", "0.000008"], ["83815.79", "0.000022"], ["83815.75", "0.000009"], ["83815.37", "0.000022"], ["83814.81", "0.209200"], ["83813.00", "0.000113"], ["83811.09", "0.125798"], ["83810.74", "0.000019"], ["83810.00", "0.000617"], ["83809.80", "5.535450"], ["83808.53", "0.000039"], ["83808.51", "0.000137"], ["83807.88", "0.000051"], ["83807.53", "0.000010"], ["83806.41", "0.209200"], ["83805.00", "0.000926"], ["83804.35", "0.000010"], ["83803.57", "0.000016"], ["83802.81", "0.000022"], ["83801.40", "4.900235"], ["83800.91", "0.000012"], ["83800.00", "0.046226"], ["83799.34", "0.000093"], ["83798.01", "0.209200"], ["83796.61", "0.001213"], ["83795.00", "0.000031"], ["83794.17", "0.000096"], ["83793.10", "0.000016"], ["83793.00", "4.809489"], ["83791.03", "0.000996"], ["83791.02", "0.000632"], ["83790.15", "0.000024"], ["83790.00", "0.003033"], ["83789.61", "0.209200"], ["83789.29", "0.000074"], ["83787.88", "0.000010"], ["83785.71", "0.000081"], ["83784.62", "0.000015"], ["83784.60", "4.446509"], ["83784.36", "0.000069"], ["83784.02", "0.000022"], ["83783.78", "0.000059"], ["83783.12", "0.000008"], ["83781.21", "0.209200"], ["83780.48", "0.000016"], ["83780.00", "0.001547"], ["83779.93", "0.000028"], ["83778.10", "0.303659"], ["83777.78", "0.000679"], ["83777.60", "0.000013"], ["83777.18", "0.000013"], ["83776.20", "5.081725"], ["83775.00", "0.010658"], ["83774.10", "0.000161"], ["83773.31", "0.000154"], ["83773.11", "0.041940"], ["83772.88", "0.000023"], ["83770.00", "0.000619"], ["83769.28", "0.000972"], ["83768.46", "0.000008"], ["83768.00", "0.000012"], ["83767.80", "4.174274"], ["83766.84", "0.000023"], ["83765.06", "0.000008"], ["83764.71", "0.000071"], ["83763.64", "0.000010"], ["83762.50", "0.000076"], ["83761.90", "0.000024"], ["83761.29", "0.000020"], ["83760.00", "0.002902"], ["83759.40", "5.353960"], ["83758.93", "0.000036"], ["83758.00", "0.000353"], ["83757.40", "0.000537"], ["83756.08", "0.000099"], ["83755.56", "0.000134"], ["83754.70", "0.000013"], ["83754.39", "0.000033"], ["83752.94", "0.000071"], ["83752.37", "0.000119"], ["83752.09", "0.000314"], ["83752.00", "0.000034"], ["83751.00", "4.627999"], ["83750.67", "0.000146"], ["83750.00", "0.041663"], ["83749.66", "0.000016"], ["83749.50", "0.000069"], ["83749.33", "0.000133"], ["83748.54", "0.000012"], ["83746.09", "0.000010"], ["83745.16", "0.000389"], ["83745.00", "0.000926"], ["83743.29", "0.001451"], ["83742.60", "5.172470"], ["83740.51", "0.000423"], ["83740.00", "0.001311"], ["83739.60", "0.000048"], ["83739.28", "0.000051"], ["83739.13", "0.000008"], ["83737.93", "0.000135"], ["83737.37", "0.000012"], ["83737.00", "0.000009"], ["83736.94", "0.000104"], ["83736.84", "0.000183"], ["83736.33", "0.000025"], ["83736.10", "0.312822"], ["83734.69", "0.000085"], ["83734.31", "0.001720"], ["83734.20", "5.626195"], ["83733.33", "0.003222"], ["83733.10", "0.001444"], ["83732.10", "0.000009"], ["83731.48", "0.000124"], ["83730.00", "0.002926"], ["83729.73", "0.000009"], ["83729.39", "0.000008"], ["83729.32", "0.000035"], ["83728.57", "0.000017"], ["83728.37", "0.001273"], ["83728.07", "0.000022"], ["83727.71", "0.000009"], ["83727.27", "0.000082"], ["83726.20", "0.000016"], ["83725.80", "4.718744"], ["83725.00", "0.002501"], ["83723.72", "0.000176"], ["83723.64", "0.000009"], ["83723.61", "0.000883"], ["83723.43", "0.000039"], ["83723.40", "0.000205"], ["83721.56", "0.000015"], ["83720.00", "0.003671"], ["83719.46", "0.000053"], ["83717.93", "0.000065"], ["83717.46", "0.000009"], ["83717.45", "0.000040"], ["83717.40", "4.265019"], ["83717.39", "0.000010"], ["83715.48", "0.000010"], ["83715.00", "0.000926"], ["83714.29", "0.009987"], ["83714.28", "0.000836"], ["83713.80", "0.000024"], ["83713.71", "0.000323"], ["83713.40", "0.000161"], ["83711.93", "0.000018"], ["83710.00", "0.000642"], ["83709.88", "0.000107"], ["83707.07", "0.000067"], ["83706.90", "0.000016"], ["83706.67", "0.000013"], ["83705.85", "0.000019"], ["83705.32", "0.000065"], ["83705.18", "0.000009"], ["83703.75", "0.000364"], ["83703.70", "0.000499"], ["83703.00", "0.000024"], ["83702.93", "0.000050"], ["83702.60", "0.000039"], ["83702.50", "0.000033"], ["83702.48", "0.000057"], ["83701.92", "0.000067"], ["83701.28", "0.000248"], ["83700.00", "0.007170"], ["83699.88", "0.000008"], ["83697.23", "0.000095"], ["83695.65", "0.003535"], ["83695.63", "0.000011"], ["83693.69", "0.000051"], ["83692.52", "0.000066"], ["83692.38", "0.000007"], ["83692.31", "0.000031"], ["83691.74", "0.000653"], ["83690.84", "0.000162"], ["83690.48", "0.000248"], ["83690.00", "0.000619"], ["83689.78", "0.001684"], ["83689.50", "0.000113"], ["83688.89", "0.000009"], ["83688.07", "0.000072"], ["83687.50", "0.006969"], ["83687.00", "0.000008"], ["83686.11", "0.000096"], ["83685.00", "0.000926"], ["83684.21", "0.000102"], ["83683.67", "0.000184"], ["83681.82", "0.000175"], ["83680.67", "0.041940"], ["83680.00", "0.001718"], ["83679.44", "0.000361"], ["83678.41", "0.000010"], ["83678.08", "0.000145"], ["83677.37", "0.000008"], ["83676.47", "0.000080"], ["83675.68", "0.000008"], ["83675.62", "0.000011"], ["83675.36", "0.000013"], ["83675.20", "0.000018"], ["83675.00", "0.002674"], ["83674.70", "0.000008"], ["83674.19", "0.000020"], ["83674.00", "0.001195"], ["83673.87", "0.000022"], ["83673.58", "0.000023"], ["83672.96", "0.002168"], ["83672.50", "0.000031"], ["83672.25", "0.004023"], ["83672.00", "0.000035"], ["83671.36", "0.000099"], ["83670.59", "0.000105"], ["83670.05", "0.000033"], ["83670.00", "0.004426"], ["83669.66", "0.000010"], ["83669.58", "0.000251"], ["83669.09", "0.000135"], ["83667.80", "0.000023"], ["83667.23", "0.012503"], ["83666.67", "0.052199"], ["83666.66", "0.000513"], ["83666.65", "0.000122"], ["83666.00", "0.271427"], ["83664.71", "0.000071"], ["83664.19", "0.000073"], ["83663.98", "0.000008"], ["83663.95", "0.000022"], ["83663.91", "0.000161"], ["83662.50", "0.000077"], ["83661.97", "0.000052"], ["83661.60", "0.000042"], ["83661.08", "0.004152"], ["83661.06", "0.011010"], ["83660.71", "0.000309"], ["83660.14", "0.000016"], ["83660.00", "0.001273"], ["83659.61", "0.000454"], ["83659.49", "0.000012"], ["83659.44", "0.000613"], ["83658.54", "0.000036"], ["83656.60", "0.000607"], ["83655.00", "0.000926"], ["83654.23", "0.000009"], ["83653.94", "0.000133"], ["83653.67", "0.001695"], ["83653.31", "0.000015"], ["83652.80", "0.000119"], ["83652.48", "0.000188"], ["83651.65", "0.000018"], ["83651.16", "0.000896"], ["83650.84", "0.003326"], ["83650.00", "0.032135"], ["83648.96", "0.000030"], ["83647.46", "0.000224"], ["83647.06", "0.000040"], ["83646.67", "0.000018"], ["83645.83", "0.000014"], ["83644.86", "0.000034"], ["83644.33", "0.000013"], ["83643.18", "0.000052"], ["83643.10", "0.002419"], ["83641.86", "0.000379"], ["83641.62", "0.002925"], ["83641.38", "0.000135"], ["83641.00", "0.000082"]], "checksum": 0, "ts": "1742556561625"}], "ts": 1742556561675}}
{"exchange": "BITGET", "timestamp": 1742556561.862752, "message": {"action": "update", "arg": {"instType": "SPOT", "channel": "books", "instId": "BTCUSDT"}, "data": [{"asks": [["83945.96", "1.199340"], ["84045.00", "4.265019"], ["84053.40", "5.353960"], ["84070.20", "5.626195"], ["84078.60", "5.444705"], ["84087.00", "3.902039"], ["84095.40", "4.537254"], ["84103.80", "5.263215"], ["84112.20", "4.718744"], ["84120.60", "4.174274"], ["84129.00", "4.990980"], ["84137.40", "4.446509"], ["84145.80", "5.081725"], ["84154.20", "3.992784"], ["84162.60", "5.535450"], ["84171.00", "4.355764"], ["84179.40", "4.809489"], ["84187.80", "5.172470"], ["84192.00", "0"], ["84196.20", "4.900235"], ["84204.60", "4.627999"], ["84520.50", "0.000238"]], "bids": [["83945.95", "0.030342"], ["83935.00", "0.001446"], ["83933.00", "0.003807"], ["83931.00", "0.010017"], ["83929.00", "0.026361"], ["83927.00", "0.069372"], ["83925.00", "0.182557"], ["83923.00", "0.480414"], ["83921.00", "1.264246"], ["83919.00", "3.326963"], ["83918.60", "1.010700"], ["83916.50", "0"], ["83915.40", "0.068970"], ["83915.30", "0.071490"], ["83914.90", "0.057660"], ["83877.00", "4.627999"], ["83868.60", "4.446509"], ["83860.20", "4.718744"], ["83851.80", "4.174274"], ["83843.40", "5.353960"], ["83835.00", "5.626195"], ["83826.60", "4.265019"], ["83818.20", "4.537254"], ["83809.80", "5.444705"], ["83801.40", "5.535450"], ["83793.00", "5.172470"], ["83784.60", "4.355764"], ["83776.20", "4.900235"], ["83767.80", "4.809489"], ["83759.40", "3.992784"], ["83751.00", "3.902039"], ["83742.60", "5.263215"], ["83734.20", "5.081725"], ["83725.80", "4.083529"], ["83717.40", "4.990980"], ["83641.00", "0"]], "checksum": 790627976, "ts": "1742556561832"}], "ts": 1742556561836}}
{"exchange": "BYBIT", "timestamp": 1742556561.937044, "message": {"topic": "orderbook.200.BTCUSDT", "ts": 1742556561919, "type": "delta", "data": {"s": "BTCUSDT", "b": [["83963.3", "0"], ["83893.1", "13.914545"], ["83890", "0.0002"]], "a": [], "u": 26627, "seq": 67550549930}, "cts": 1742556561909}}
{"exchange": "BITGET", "timestamp": 1742556562.072317, "message": {"action": "update", "arg": {"instType": "SPOT", "channel": "books", "instId": "BTCUSDT"}, "data": [{"asks": [["83945.96", "1.619340"], ["83985.00", "0.001814"], ["83987.00", "0.004775"], ["83989.00", "0.012564"], ["83991.00", "0.033063"], ["83995.00", "0.228970"], ["83997.00", "0.602554"], ["83999.00", "1.585669"], ["84001.00", "4.172813"], ["84003.00", "10.981087"], ["84045.00", "4.627999"], ["84053.40", "4.265019"], ["84061.80", "4.900235"], ["84070.20", "5.444705"], ["84078.60", "5.353960"], ["84087.00", "4.446509"], ["84095.40", "5.081725"], ["84103.80", "3.902039"], ["84112.20", "4.990980"], ["84120.60", "3.992784"], ["84129.00", "5.626195"], ["84137.40", "4.537254"], ["84145.80", "4.083529"], ["84154.20", "4.174274"], ["84162.60", "4.809489"], ["84171.00", "5.172470"], ["84179.40", "5.263215"], ["84187.80", "4.355764"], ["84196.20", "5.535450"], ["84204.60", "4.718744"]], "bids": [["83933.00", "0.004019"], ["83931.00", "0.010577"], ["83929.00", "0.027835"], ["83927.00", "0.073250"], ["83925.00", "0.192764"], ["83923.00", "0.507530"], ["83921.00", "1.335605"], ["83919.00", "3.514749"], ["83908.60", "0.120000"], ["83893.00", "0.000017"], ["83877.00", "3.902039"], ["83868.60", "3.992784"], ["83860.20", "4.809489"], ["83851.80", "5.444705"], ["83843.40", "4.265019"], ["83835.00", "4.990980"], ["83826.60", "4.537254"], ["83818.20", "5.263215"], ["83809.80", "4.083529"], ["83801.40", "5.172470"], ["83793.00", "5.535450"], ["83784.60", "5.353960"], ["83776.20", "5.081725"], ["83767.80", "4.900235"], ["83759.40", "4.718744"], ["83751.00", "4.355764"], ["83742.60", "4.627999"], ["83734.20", "4.174274"], ["83725.80", "5.626195"], ["83717.40", "4.446509"], ["83641.62", "0"], ["83641.38", "0"]], "checksum": -1610258761, "ts": "1742556562043"}], "ts": 1742556562046}}
{"exchange": "BYBIT", "timestamp": 1742556562.137861, "message": {"topic": "orderbook.200.BTCUSDT", "ts": 1742556562120, "type": "delta", "data": {"s": "BTCUSDT", "b": [["83965.5", "0.110851"], ["83959.2", "0.015787"], ["83958.2", "0.027909"], ["83937.1", "0.037424"], ["83895.9", "13.914545"], ["83893.1", "0"], ["83890", "0"]], "a": [["83965.6", "0.749286"], ["84000.2", "0.718116"]], "u": 26628, "seq": 67550549974}, "cts": 1742556562116}}
{"exchange": "BITGET", "timestamp": 1742556562.274408, "message": {"action": "update", "arg": {"instType": "SPOT", "channel": "books", "instId": "BTCUSDT"}, "data": [{"asks": [["83987.00", "0.004905"], ["83989.00", "0.012908"], ["83991.00", "0.033970"], ["83995.00", "0.235247"], ["83997.00", "0.619070"], ["83999.00", "1.629131"], ["84001.00", "4.287187"], ["84003.00", "11.282072"], ["84045.00", "4.990980"], ["84053.40", "5.172470"], ["84061.80", "4.718744"], ["84070.20", "4.446509"], ["84078.60", "5.263215"], ["84087.00", "5.535450"], ["84095.40", "5.353960"], ["84103.80", "5.626195"], ["84112.20", "4.083529"], ["84120.60", "3.902039"], ["84129.00", "5.444705"], ["84137.40", "4.809489"], ["84145.80", "4.627999"], ["84162.60", "3.992784"], ["84171.00", "5.081725"], ["84179.40", "4.537254"], ["84187.80", "4.265019"], ["84196.20", "4.355764"], ["84204.60", "4.900235"]], "bids": [["83933.00", "0.003631"], ["83931.00", "0.009554"], ["83929.00", "0.025142"], ["83927.00", "0.066165"], ["83925.00", "0.174116"], ["83923.00", "0.458202"], ["83921.00", "1.205794"], ["83919.00", "3.173141"], ["83894.00", "0.000032"], ["83877.00", "5.172470"], ["83868.60", "4.174274"], ["83860.20", "3.992784"], ["83851.80", "4.809489"], ["83843.40", "5.444705"], ["83835.00", "4.627999"], ["83826.60", "4.446509"], ["83809.80", "4.355764"], ["83801.40", "4.537254"], ["83793.00", "4.718744"], ["83784.60", "5.535450"], ["83776.20", "4.265019"], ["83767.80", "5.626195"], ["83759.40", "3.902039"], ["83751.00", "5.081725"], ["83742.60", "4.990980"], ["83734.20", "5.353960"], ["83725.80", "4.083529"], ["83717.40", "4.900235"]], "checksum": 669334484, "ts": "1742556562246"}], "ts": 1742556562248}}
{"exchange": "BYBIT", "timestamp": 1742556562.337642, "message": {"topic": "orderbook.200.BTCUSDT", "ts": 1742556562320, "type": "delta", "data": {"s": "BTCUSDT", "b": [["83965.5", "0.113741"], ["83895.9", "0"], ["83893.1", "13.914545"]], "a": [["84002.1", "0.063449"], ["84004.9", "0.030042"], ["84028.6", "0"]], "u": 26629, "seq": 67550549987}, "cts": 1742556562316}}
{"exchange": "BITGET", "timestamp": 1742556562.493884, "message": {"action": "update", "arg": {"instType": "SPOT", "channel": "books", "instId": "BTCUSDT"}, "data": [{"asks": [["83987.00", "0.005036"], ["83989.00", "0.013251"], ["83991.00", "0.034873"], ["83995.00", "0.241501"], ["83997.00", "0.635527"], ["83999.00", "1.672440"], ["84001.00", "4.401159"], ["84003.00", "11.582183"], ["84045.00", "4.900235"], ["84053.40", "4.265019"], ["84061.80", "4.174274"], ["84070.20", "4.718744"], ["84078.60", "4.627999"], ["84087.00", "3.902039"], ["84095.40", "5.626195"], ["84103.80", "4.083529"], ["84112.20", "4.355764"], ["84120.60", "5.172470"], ["84129.00", "5.263215"], ["84137.40", "4.990980"], ["84145.80", "5.081725"], ["84154.20", "5.444705"], ["84162.60", "4.446509"], ["84171.00", "5.535450"], ["84179.40", "3.992784"], ["84187.80", "4.537254"], ["84196.20", "5.353960"], ["84204.60", "4.809489"]], "bids": [["83942.93", "0.047852"], ["83942.01", "0"], ["83935.88", "0.010000"], ["83933.00", "0.003613"], ["83931.00", "0.009509"], ["83929.00", "0.025023"], ["83927.00", "0.065851"], ["83925.00", "0.173292"], ["83923.00", "0.456031"], ["83921.00", "1.200083"], ["83919.00", "3.158113"], ["83918.70", "0.058650"], ["83918.60", "1.010070"], ["83916.90", "0.045000"], ["83909.00", "0.000032"], ["83908.60", "0"], ["83877.00", "5.081725"], ["83868.60", "3.992784"], ["83860.20", "4.809489"], ["83851.80", "5.444705"], ["83843.40", "5.263215"], ["83835.00", "5.535450"], ["83818.20", "4.265019"], ["83809.80", "5.172470"], ["83801.40", "4.083529"], ["83793.00", "5.626195"], ["83784.60", "3.902039"], ["83776.20", "5.353960"], ["83767.80", "4.990980"], ["83759.40", "4.355764"], ["83751.00", "4.900235"], ["83742.60", "4.174274"], ["83734.20", "4.718744"], ["83725.80", "4.537254"], ["83717.40", "4.627999"], ["83641.86", "0"]], "checksum": 1437248788, "ts": "1742556562456"}], "ts": 1742556562460}}
{"exchange": "BYBIT", "timestamp": 1742556562.538053, "message": {"topic": "orderbook.200.BTCUSDT", "ts": 1742556562520, "type": "delta", "data": {"s": "BTCUSDT", "b": [["83965.5", "0.109492"], ["83955", "0.053084"], ["83950.6", "0.112859"], ["83946.5", "0.118338"], ["83940.1", "0.17966"], ["83939.5", "0.165023"], ["83933.1", "0.295941"], ["83932.5", "0.2905"], ["83895.9", "13.914545"], ["83893.1", "0"], ["83890.7", "0"], ["83890.6", "0"], ["83890.5", "0"], ["83890.3", "0"], ["83890.2", "0"]], "a": [["83967.4", "0"], ["83975.1", "0.114425"], ["83979.4", "0.124006"], ["83985.6", "0.174026"], ["83986.4", "0.179504"], ["83992.6", "0.300499"], ["83993.4", "0.376497"], ["84028.4", "0"], ["84028.5", "0"]], "u": 26630, "seq": 67550550016}, "cts": 1742556562515}}
{"exchange": "BITGET", "timestamp": 1742556562.690335, "message": {"action": "update", "arg": {"instType": "SPOT", "channel": "books", "instId": "BTCUSDT"}, "data": [{"asks": [["84045.00", "4.265019"], ["84053.40", "5.535450"], ["84061.80", "4.809489"], ["84070.20", "4.446509"], ["84078.60", "5.172470"], ["84087.00", "5.263215"], ["84095.40", "5.353960"], ["84103.80", "4.355764"], ["84112.20", "4.174274"], ["84120.60", "5.444705"], ["84129.00", "4.900235"], ["84137.40", "4.627999"], ["84145.80", "4.083529"], ["84154.20", "5.081725"], ["84162.60", "3.902039"], ["84171.00", "4.718744"], ["84179.40", "5.626195"], ["84187.80", "3.992784"], ["84196.20", "4.990980"], ["84204.60", "4.537254"]], "bids": [["83894.00", "0.000015"], ["83877.00", "5.535450"], ["83868.60", "4.083529"], ["83860.20", "3.992784"], ["83851.80", "5.172470"], ["83843.40", "3.902039"], ["83835.00", "4.900235"], ["83826.60", "4.809489"], ["83818.20", "5.444705"], ["83809.80", "4.355764"], ["83801.40", "4.265019"], ["83784.60", "4.537254"], ["83776.20", "4.718744"], ["83767.80", "4.446509"], ["83759.40", "4.990980"], ["83751.00", "4.627999"], ["83742.60", "5.263215"], ["83734.20", "5.081725"], ["83725.80", "5.353960"], ["83717.40", "4.174274"]], "checksum": 1437248788, "ts": "1742556562662"}], "ts": 1742556562664}}
{"exchange": "BYBIT", "timestamp": 1742556562.736988, "message": {"topic": "orderbook.200.BTCUSDT", "ts": 1742556562719, "type": "delta", "data": {"s": "BTCUSDT", "b": [["83949.5", "0.089181"]], "a": [["83976.2", "0.028513"]], "u": 26631, "seq": 67550550035}, "cts": 1742556562696}}
{"exchange": "BITGET", "timestamp": 1742556562.8985, "message": {"action": "update", "arg": {"instType": "SPOT", "channel": "books", "instId": "BTCUSDT"}, "data": [{"asks": [["84053.40", "5.172470"], ["84061.80", "5.535450"], ["84070.20", "4.627999"], ["84078.60", "5.081725"], ["84087.00", "3.992784"], ["84095.40", "4.990980"], ["84103.80", "5.444705"], ["84120.60", "5.263215"], ["84129.00", "4.537254"], ["84137.40", "4.083529"], ["84145.80", "4.446509"], ["84154.20", "4.355764"], ["84162.60", "5.626195"], ["84171.00", "3.902039"], ["84179.40", "5.353960"], ["84187.80", "4.809489"], ["84196.20", "4.900235"], ["84204.60", "4.718744"]], "bids": [["83921.00", "1.200252"], ["83919.00", "3.158559"], ["83877.00", "4.174274"], ["83868.60", "4.718744"], ["83860.20", "4.990980"], ["83851.80", "3.902039"], ["83843.40", "4.446509"], ["83835.00", "5.263215"], ["83826.60", "4.900235"], ["83818.20", "5.353960"], ["83809.80", "5.535450"], ["83801.40", "4.627999"], ["83793.00", "5.172470"], ["83776.20", "4.265019"], ["83767.80", "5.444705"], ["83759.40", "4.083529"], ["83751.00", "4.355764"], ["83742.60", "5.626195"], ["83734.20", "4.809489"], ["83725.80", "3.992784"], ["83717.40", "5.081725"]], "checksum": 1437248788, "ts": "1742556562868"}], "ts": 1742556562871}}
{"exchange": "BYBIT", "timestamp": 1742556562.937511, "message": {"topic": "orderbook.200.BTCUSDT", "ts": 1742556562920, "type": "delta", "data": {"s": "BTCUSDT", "b": [["83957.7", "0.000486"]], "a": [["83965.6", "0.578286"]], "u": 26632, "seq": 67550550055}, "cts": 1742556562907}}
{"exchange": "BITGET", "timestamp": 1742556563.102315, "message": {"action": "update", "arg": {"instType": "SPOT", "channel": "books", "instId": "BTCUSDT"}, "data": [{"asks": [["83945.96", "1.199340"], ["83983.40", "0"], ["84003.00", "11.581997"], ["84045.00", "5.444705"], ["84053.40", "5.353960"], ["84061.80", "4.718744"], ["84070.20", "4.809489"], ["84078.60", "4.900235"], ["84087.00", "4.990980"], ["84095.40", "5.081725"], ["84103.80", "5.535450"], ["84112.20", "4.627999"], ["84120.60", "5.626195"], ["84129.00", "4.446509"], ["84137.40", "4.355764"], ["84145.80", "4.174274"], ["84154.20", "3.902039"], ["84162.60", "4.265019"], ["84171.00", "3.992784"], ["84179.40", "5.263215"], ["84187.80", "5.172470"], ["84196.20", "4.083529"], ["84204.60", "4.537254"], ["84520.67", "0.002384"]], "bids": [["83927.00", "0.066088"], ["83925.00", "0.173917"], ["83923.00", "0.457675"], ["83921.00", "1.204408"], ["83919.00", "3.169496"], ["83909.00", "0.120000"], ["83895.00", "0.000924"], ["83877.00", "5.444705"], ["83868.60", "3.902039"], ["83860.20", "5.263215"], ["83851.80", "5.353960"], ["83835.00", "4.174274"], ["83826.60", "4.718744"], ["83818.20", "5.626195"], ["83809.80", "4.355764"], ["83801.40", "4.809489"], ["83793.00", "3.992784"], ["83776.20", "5.535450"], ["83767.80", "4.627999"], ["83759.40", "4.900235"], ["83751.00", "5.172470"], ["83742.60", "5.081725"], ["83734.20", "4.265019"], ["83725.80", "4.990980"], ["83717.40", "4.083529"]], "checksum": -23829011, "ts": "1742556563072"}], "ts": 1742556563076}}
{"exchange": "BYBIT", "timestamp": 1742556563.137294, "message": {"topic": "orderbook.200.BTCUSDT", "ts": 1742556563120, "type": "delta", "data": {"s": "BTCUSDT", "b": [["83965.5", "0.10978"], ["83950.6", "0"], ["83950.3", "0.113245"], ["83940.5", "0.164644"], ["83940.2", "0.144898"], ["83940.1", "0"], ["83937.1", "0"], ["83933.1", "0"], ["83931.4", "0.298861"], ["83895.9", "0"], ["83893.1", "13.914545"], ["83890.7", "0.353794"]], "a": [["83965.6", "0.749286"], ["83975.1", "0"], ["83975.5", "0.115876"], ["83985.3", "0.175986"], ["83985.6", "0.000514"], ["83992.5", "0.344386"], ["83992.6", "0"], ["83993.3", "0"], ["83994.4", "0.304292"], ["84000.3", "0.030042"], ["84003.1", "2.256735"]], "u": 26633, "seq": 67550550089}, "cts": 1742556563059}}
{"exchange": "BYBIT", "timestamp": 1742556563.340715, "message": {"topic": "orderbook.200.BTCUSDT", "ts": 1742556563320, "type": "delta", "data": {"s": "BTCUSDT", "b": [["83965.5", "0.28078"], ["83950.3", "0"], ["83946.5", "0"], ["83940.5", "0"], ["83940.2", "0.002799"], ["83939.5", "0"], ["83932.5", "0.006179"], ["83931.4", "0"], ["83895.9", "14.172845"], ["83890.6", "0.000333"], ["83890.5", "3.246386"], ["83890.3", "0.011992"], ["83890.2", "0.00253"]], "a": [["83965.6", "0.578286"], ["83975.5", "0"], ["83979.4", "0"], ["83985.3", "0"], ["83986.4", "0.001333"], ["83993.4", "0.079535"], ["83994.4", "0.003247"], ["84028.4", "0.001333"], ["84028.5", "0.0012"], ["84028.6", "0.0006"]], "u": 26634, "seq": 67550550118}, "cts": 1742556563311}}
{"exchange": "BITGET", "timestamp": 1742556563.341048, "message": {"action": "update", "arg": {"instType": "SPOT", "channel": "books", "instId": "BTCUSDT"}, "data": [{"asks": [["83987.00", "0.004900"], ["83989.00", "0.012896"], ["83991.00", "0.033938"], ["83995.00", "0.235025"], ["83997.00", "0.618486"], ["83999.00", "1.627595"], ["84001.00", "4.283144"], ["84003.00", "11.271433"], ["84045.00", "3.902039"], ["84053.40", "5.081725"], ["84061.80", "4.627999"], ["84070.20", "4.990980"], ["84078.60", "4.174274"], ["84087.00", "5.626195"], ["84095.40", "5.535450"], ["84103.80", "5.263215"], ["84104.00", "0.001184"], ["84112.20", "5.353960"], ["84120.60", "4.809489"], ["84129.00", "5.172470"], ["84137.40", "4.900235"], ["84145.80", "5.444705"], ["84154.20", "4.083529"], ["84162.60", "4.446509"], ["84171.00", "4.718744"], ["84179.40", "4.355764"], ["84187.80", "3.992784"], ["84196.20", "4.265019"], ["84520.67", "0"]], "bids": [["83933.00", "0.004016"], ["83931.00", "0.010568"], ["83929.00", "0.027811"], ["83927.00", "0.073185"], ["83925.00", "0.192593"], ["83923.00", "0.506823"], ["83921.00", "1.333746"], ["83919.00", "3.509857"], ["83895.00", "0.000941"], ["83877.00", "4.809489"], ["83868.60", "5.444705"], ["83860.20", "4.083529"], ["83851.80", "5.081725"], ["83843.40", "4.537254"], ["83835.00", "4.900235"], ["83818.20", "4.355764"], ["83809.80", "3.992784"], ["83801.40", "5.626195"], ["83793.00", "5.172470"], ["83784.60", "4.174274"], ["83776.20", "4.990980"], ["83767.80", "5.535450"], ["83759.40", "4.627999"], ["83751.00", "5.353960"], ["83742.60", "3.902039"], ["83734.20", "4.446509"], ["83725.80", "4.265019"], ["83717.40", "5.263215"]], "checksum": -1995458883, "ts": "1742556563306"}], "ts": 1742556563311}}
{"exchange": "BYBIT", "timestamp": 1742556563.537411, "message": {"topic": "orderbook.200.BTCUSDT", "ts": 1742556563519, "type": "delta", "data": {"s": "BTCUSDT", "b": [["83965.5", "0.282683"], ["83962", "0.071495"], ["83949.5", "0.061348"], ["83946.2", "0.006181"], ["83895.9", "0"], ["83893.1", "14.172845"]], "a": [["83965.6", "0.584286"], ["83980.1", "0.02"], ["83986.5", "0.000991"], ["83992.5", "0.023819"], ["84028.6", "0"]], "u": 26635, "seq": 67550550147}, "cts": 1742556563503}}
{"exchange": "BITGET", "timestamp": 1742556563.566156, "message": {"action": "update", "arg": {"instType": "SPOT", "channel": "books", "instId": "BTCUSDT"}, "data": [{"asks": [["83980.80", "0"], ["84045.00", "4.900235"], ["84053.40", "4.809489"], ["84061.80", "4.537254"], ["84070.20", "4.174274"], ["84078.60", "5.444705"], ["84087.00", "4.083529"], ["84095.40", "4.718744"], ["84103.80", "5.535450"], ["84112.20", "5.626195"], ["84120.60", "3.992784"], ["84129.00", "4.446509"], ["84137.40", "5.353960"], ["84145.80", "5.081725"], ["84154.20", "4.355764"], ["84162.60", "4.265019"], ["84171.00", "4.990980"], ["84179.40", "3.902039"], ["84187.80", "5.263215"], ["84196.20", "5.172470"], ["84204.60", "4.627999"], ["84520.67", "0.002384"]], "bids": [["83933.00", "0.003624"], ["83931.00", "0.009537"], ["83929.00", "0.025096"], ["83927.00", "0.066044"], ["83925.00", "0.173798"], ["83923.00", "0.457363"], ["83921.00", "1.203589"], ["83919.00", "3.167338"], ["83877.00", "5.353960"], ["83868.60", "5.263215"], ["83860.20", "4.627999"], ["83851.80", "5.626195"], ["83843.40", "3.902039"], ["83826.60", "4.446509"], ["83818.20", "4.083529"], ["83809.80", "5.444705"], ["83801.40", "4.537254"], ["83793.00", "4.265019"], ["83784.60", "4.990980"], ["83776.20", "4.174274"], ["83767.80", "4.355764"], ["83759.40", "5.535450"], ["83751.00", "4.809489"], ["83742.60", "4.718744"], ["83734.20", "5.172470"], ["83725.80", "5.081725"], ["83717.40", "3.992784"]], "checksum": 1992530809, "ts": "1742556563510"}], "ts": 1742556563513}}
{"exchange": "BYBIT", "timestamp": 1742556563.740289, "message": {"topic": "orderbook.200.BTCUSDT", "ts": 1742556563720, "type": "delta", "data": {"s": "BTCUSDT", "b": [["83900", "0.055816"]], "a": [["83986.5", "0"], ["84028.6", "0.0006"]], "u": 26636, "seq": 67550550161}, "cts": 1742556563694}}
{"exchange": "BITGET", "timestamp": 1742556563.749185, "message": {"action": "update", "arg": {"instType": "SPOT", "channel": "books", "instId": "BTCUSDT"}, "data": [{"asks": [["83945.96", "1.619340"], ["83978.54", "0.177918"], ["83987.00", "0.004769"], ["83989.00", "0.012549"], ["83991.00", "0.033026"], ["83995.00", "0.228711"], ["83997.00", "0.601869"], ["83999.00", "1.583867"], ["84001.00", "4.168070"], ["84003.00", "10.968606"], ["84006.50", "0.120210"], ["84006.60", "0.074040"], ["84016.10", "0"], ["84053.40", "4.174274"], ["84061.80", "3.902039"], ["84070.20", "5.626195"], ["84078.60", "4.537254"], ["84087.00", "5.444705"], ["84095.40", "5.172470"], ["84103.80", "5.353960"], ["84112.20", "5.263215"], ["84120.60", "4.990980"], ["84129.00", "5.081725"], ["84137.40", "4.627999"], ["84145.80", "4.265019"], ["84154.20", "3.992784"], ["84162.60", "4.809489"], ["84171.00", "4.446509"], ["84179.40", "4.355764"], ["84187.80", "4.083529"], ["84196.20", "5.535450"], ["84204.60", "4.718744"], ["84520.67", "0"]], "bids": [["83942.93", "0"], ["83929.51", "0"], ["83921.00", "1.203483"], ["83919.00", "3.167059"], ["83909.00", "0.000032"], ["83877.00", "4.537254"], ["83868.60", "4.355764"], ["83860.20", "4.900235"], ["83851.80", "4.627999"], ["83843.40", "4.809489"], ["83835.00", "5.535450"], ["83826.60", "5.172470"], ["83818.20", "5.081725"], ["83809.80", "4.446509"], ["83801.40", "4.083529"], ["83793.00", "5.263215"], ["83784.60", "4.718744"], ["83776.20", "5.444705"], ["83767.80", "4.990980"], ["83759.40", "3.992784"], ["83751.00", "5.626195"], ["83742.60", "5.353960"], ["83734.20", "3.902039"], ["83725.80", "4.265019"], ["83717.40", "4.174274"], ["83641.86", "0.000379"], ["83641.62", "0.002925"]], "checksum": -2103813414, "ts": "1742556563718"}], "ts": 1742556563722}}
{"exchange": "BYBIT", "timestamp": 1742556563.937845, "message": {"topic": "orderbook.200.BTCUSDT", "ts": 1742556563920, "type": "delta", "data": {"s": "BTCUSDT", "b": [["83965.5", "0.283314"], ["83964.4", "0.071493"], ["83962", "0"], ["83925", "0"], ["83924.8", "0.012882"]], "a": [["83984.1", "0.001014"], ["83987.6", "0.001277"], ["83997.8", "0"], ["83997.9", "0"], ["83998.1", "0.013"], ["83998.2", "0.012743"], ["83998.5", "0"], ["83998.6", "0.003247"], ["83998.8", "0.04"], ["83998.9", "0.063819"], ["84028.5", "0"], ["84028.6", "0"]], "u": 26637, "seq": 67550550190}, "cts": 1742556563906}}
{"exchange": "BITGET", "timestamp": 1742556563.961022, "message": {"action": "update", "arg": {"instType": "SPOT", "channel": "books", "instId": "BTCUSDT"}, "data": [{"asks": [["83976.34", "0.123098"], ["83983.00", "0.001008"], ["83985.00", "0.001288"], ["83987.00", "0.003390"], ["83989.00", "0.008921"], ["83991.00", "0.023476"], ["83995.00", "0.162579"], ["83997.00", "0.427838"], ["83999.00", "1.125891"], ["84001.00", "2.962870"], ["84003.00", "7.797027"], ["84045.00", "5.444705"], ["84053.40", "4.446509"], ["84061.80", "4.083529"], ["84070.20", "3.902039"], ["84078.60", "5.172470"], ["84087.00", "4.627999"], ["84095.40", "5.353960"], ["84103.80", "5.263215"], ["84112.20", "4.990980"], ["84120.60", "4.265019"], ["84129.00", "5.535450"], ["84137.40", "5.626195"], ["84145.80", "4.174274"], ["84154.20", "5.081725"], ["84162.60", "4.900235"], ["84171.00", "4.537254"], ["84179.40", "3.992784"], ["84187.80", "4.809489"], ["84196.20", "4.718744"], ["84204.60", "4.355764"]], "bids": [["83943.78", "0.047852"], ["83935.00", "0.002890"], ["83933.00", "0.007605"], ["83931.00", "0.020012"], ["83929.00", "0.052664"], ["83928.48", "0.006216"], ["83927.00", "0.138589"], ["83925.00", "0.364708"], ["83923.00", "0.959758"], ["83921.00", "2.525679"], ["83919.00", "6.646524"], ["83918.90", "2.361420"], ["83918.70", "0.058020"], ["83917.40", "0.045030"], ["83916.20", "0.249210"], ["83914.90", "0"], ["83909.00", "0.120000"], ["83893.00", "0.000032"], ["83877.00", "4.265019"], ["83868.60", "4.718744"], ["83860.20", "4.627999"], ["83851.80", "5.626195"], ["83843.40", "5.081725"], ["83835.00", "3.992784"], ["83826.60", "3.902039"], ["83818.20", "5.263215"], ["83809.80", "5.172470"], ["83801.40", "5.444705"], ["83793.00", "4.083529"], ["83784.60", "4.174274"], ["83776.20", "4.355764"], ["83767.80", "5.535450"], ["83759.40", "4.446509"], ["83751.00", "4.809489"], ["83734.20", "4.900235"], ["83725.80", "4.537254"], ["83717.40", "4.990980"], ["83641.62", "0"]], "checksum": 1838451820, "ts": "1742556563922"}], "ts": 1742556563934}}
{"exchange": "BYBIT", "timestamp": 1742556564.137466, "message": {"topic": "orderbook.200.BTCUSDT", "ts": 1742556564120, "type": "delta", "data": {"s": "BTCUSDT", "b": [["83965.5", "0.339196"], ["83964.5", "0.026696"], ["83957.8", "0.051646"], ["83956.8", "0"], ["83953.2", "0.072018"], ["83951.6", "0.04"], ["83937.1", "0.037424"], ["83901.5", "14.249587"], ["83893.1", "0"], ["83890.2", "0"]], "a": [["83965.6", "0.582143"], ["83965.8", "0.035727"], ["83976.2", "0.024937"], ["83984.1", "0"], ["83985", "0.00125"], ["83987.6", "0"], ["83989.7", "0.003576"], ["83993.3", "0.132338"], ["83997.9", "0.013"], ["83998", "0.072278"], ["83998.1", "0"], ["83998.2", "0"], ["83998.6", "0.043247"], ["83998.7", "0.04"], ["83998.8", "0"], ["83998.9", "0.023819"], ["84008.2", "0.038217"]], "u": 26638, "seq": 67550550254}, "cts": 1742556564116}}
{"exchange": "BITGET", "timestamp": 1742556564.153976, "message": {"action": "update", "arg": {"instType": "SPOT", "channel": "books", "instId": "BTCUSDT"}, "data": [{"asks": [["83985.00", "0.001030"], ["83987.00", "0.002419"], ["83989.00", "0.006366"], ["83991.00", "0.016752"], ["83995.00", "0.116015"], ["83997.00", "0.305302"], ["83999.00", "0.803426"], ["84001.00", "2.114279"], ["84003.00", "5.563892"], ["84005.10", "0.064620"], ["84006.50", "0.120000"], ["84008.30", "0"], ["84011.20", "0.144780"], ["84016.00", "0.510000"], ["84045.00", "4.355764"], ["84053.40", "4.174274"], ["84061.80", "5.081725"], ["84078.60", "4.627999"], ["84087.00", "4.083529"], ["84095.40", "4.446509"], ["84103.80", "5.444705"], ["84112.20", "4.718744"], ["84137.40", "5.172470"], ["84145.80", "5.626195"], ["84154.20", "4.990980"], ["84162.60", "3.992784"], ["84171.00", "5.353960"], ["84179.40", "5.263215"], ["84196.20", "4.537254"], ["84204.60", "4.900235"], ["84520.50", "0"]], "bids": [["83945.95", "0.773742"], ["83937.00", "0.001395"], ["83935.00", "0.003671"], ["83933.00", "0.009660"], ["83931.00", "0.025421"], ["83929.00", "0.066899"], ["83927.00", "0.176049"], ["83925.00", "0.463288"], ["83923.01", "0.863222"], ["83923.00", "1.219178"], ["83921.00", "3.208363"], ["83919.00", "8.443061"], ["83918.90", "3.537630"], ["83918.80", "0.334020"], ["83918.60", "1.009860"], ["83918.10", "0"], ["83918.07", "0"], ["83916.90", "0.189780"], ["83916.20", "0.045000"], ["83913.80", "0"], ["83908.60", "0.240000"], ["83908.20", "0.120000"], ["83902.15", "0"], ["83901.91", "0"], ["83901.83", "0"], ["83901.73", "0"], ["83893.00", "0.000015"], ["83877.00", "5.263215"], ["83873.29", "0"], ["83868.60", "4.990980"], ["83860.20", "4.355764"], ["83851.80", "5.535450"], ["83843.40", "4.900235"], ["83835.00", "5.444705"], ["83826.60", "4.174274"], ["83818.20", "4.627999"], ["83809.80", "4.537254"], ["83801.40", "4.083529"], ["83793.00", "4.265019"], ["83784.60", "5.626195"], ["83776.20", "5.081725"], ["83767.80", "5.353960"], ["83751.00", "3.992784"], ["83742.60", "3.902039"], ["83734.20", "4.718744"], ["83725.80", "5.172470"], ["83717.40", "4.809489"], ["83641.62", "0.002925"], ["83641.38", "0.000135"], ["83641.00", "0.000082"], ["83640.35", "0.000022"], ["83640.15", "0.000423"]], "checksum": 782542882, "ts": "1742556564124"}], "ts": 1742556564128}}
{"exchange": "BYBIT", "timestamp": 1742556564.337022, "message": {"topic": "orderbook.200.BTCUSDT", "ts": 1742556564319, "type": "delta", "data": {"s": "BTCUSDT", "b": [["83965.5", "0.343496"], ["83901.5", "0"], ["83895.9", "14.249587"]], "a": [["83965.6", "0.584286"], ["83976.4", "0"], ["83985", "0"], ["84003.1", "0"], ["84008.2", "0.036074"], ["84017.3", "2.256735"], ["84028.5", "0.0012"], ["84028.6", "0.0006"]], "u": 26639, "seq": 67550550350}, "cts": 1742556564302}}
{"exchange": "BITGET", "timestamp": 1742556564.364232, "message": {"action": "update", "arg": {"instType": "SPOT", "channel": "books", "instId": "BTCUSDT"}, "data": [{"asks": [["83987.00", "0.002130"], ["83989.00", "0.005604"], ["83991.00", "0.014748"], ["83995.00", "0.102134"], ["83996.99", "0.433037"], ["83997.00", "0.268773"], ["83999.00", "0.707297"], ["84001.00", "1.861308"], ["84003.00", "4.898180"], ["84005.10", "0"], ["84006.50", "0.120210"], ["84010.00", "1.139070"], ["84016.00", "0"], ["84045.00", "5.353960"], ["84061.80", "4.537254"], ["84070.20", "5.263215"], ["84078.60", "5.626195"], ["84087.00", "4.990980"], ["84095.40", "4.083529"], ["84103.80", "4.265019"], ["84112.20", "3.902039"], ["84120.60", "5.444705"], ["84129.00", "4.718744"], ["84137.40", "5.535450"], ["84145.80", "4.446509"], ["84154.20", "4.355764"], ["84162.60", "4.900235"], ["84171.00", "3.992784"], ["84179.40", "4.809489"], ["84187.80", "5.172470"], ["84196.20", "4.627999"], ["84204.60", "5.081725"], ["84520.50", "0.000238"], ["84520.67", "0.002384"]], "bids": [["83937.00", "0.001101"], ["83935.00", "0.002896"], ["83933.00", "0.007620"], ["83932.13", "0.067651"], ["83931.00", "0.020055"], ["83929.00", "0.052774"], ["83927.00", "0.138879"], ["83925.00", "0.365471"], ["83923.00", "0.961767"], ["83921.00", "2.530966"], ["83919.00", "6.660437"], ["83910.60", "0.017850"], ["83908.20", "0"], ["83906.36", "0.008026"], ["83906.18", "0.008440"], ["83906.04", "0.005323"], ["83905.95", "0.006481"], ["83877.49", "0.007663"], ["83877.00", "4.174274"], ["83868.60", "4.446509"], ["83860.20", "4.990980"], ["83851.80", "3.902039"], ["83835.00", "4.537254"], ["83826.60", "5.172470"], ["83809.80", "4.718744"], ["83801.40", "5.081725"], ["83793.00", "5.444705"], ["83784.60", "5.263215"], ["83776.20", "5.535450"], ["83767.80", "4.083529"], ["83759.40", "4.355764"], ["83751.00", "5.626195"], ["83742.60", "5.353960"], ["83734.20", "3.992784"], ["83725.80", "4.265019"], ["83641.86", "0"], ["83641.62", "0"], ["83641.38", "0"], ["83641.00", "0"], ["83640.35", "0"], ["83640.15", "0"]], "checksum": 781896855, "ts": "1742556564326"}], "ts": 1742556564329}}
{"exchange": "BYBIT", "timestamp": 1742556564.537702, "message": {"topic": "orderbook.200.BTCUSDT", "ts": 1742556564520, "type": "delta", "data": {"s": "BTCUSDT", "b": [["83965.5", "0.283314"], ["83964.5", "0"], ["83964.4", "0"], ["83963.3", "0.071494"], ["83953", "0.120704"], ["83952.7", "0.120436"], ["83948.9", "0.111814"], ["83942.9", "0.169068"], ["83942.5", "0.168373"], ["83941.9", "0.185613"], ["83936.2", "0.178645"], ["83935.5", "0.301741"], ["83934.9", "0.297212"], ["83933.8", "0.276549"], ["83901.5", "14.249587"], ["83895.9", "0"], ["83891.3", "0"], ["83891.2", "0"], ["83890.9", "0"], ["83890.7", "0"], ["83890.6", "0"], ["83890.5", "0"], ["83890.3", "0"]], "a": [["83965.6", "0.590286"], ["83977.5", "0.120492"], ["83977.9", "0.168267"], ["83981.8", "0.117712"], ["83987.7", "0.163232"], ["83988", "0.1777"], ["83988.8", "0.177082"], ["83995", "0.299486"], ["83995.8", "0.446882"], ["83996.8", "0.380838"], ["84000.2", "0.039256"], ["84003.1", "2.256735"], ["84017.3", "0"], ["84027.9", "0"], ["84028", "0"], ["84028.4", "0"], ["84028.5", "0"], ["84028.6", "0"]], "u": 26640, "seq": 67550550436}, "cts": 1742556564516}}
{"exchange": "BITGET", "timestamp": 1742556564.563573, "message": {"action": "update", "arg": {"instType": "SPOT", "channel": "books", "instId": "BTCUSDT"}, "data": [{"asks": [["83945.96", "1.583840"], ["83987.00", "0.002435"], ["83989.00", "0.006406"], ["83991.00", "0.016860"], ["83995.00", "0.116758"], ["83996.99", "0"], ["83997.00", "0.307258"], ["83999.00", "0.808572"], ["84001.00", "2.127821"], ["84002.99", "0.432863"], ["84003.00", "5.599530"], ["84006.50", "0"], ["84006.60", "0.074250"], ["84010.00", "0.067800"], ["84016.00", "0.756330"], ["84016.10", "0.534660"], ["84045.00", "5.172470"], ["84053.40", "5.081725"], ["84061.80", "5.535450"], ["84078.60", "3.902039"], ["84095.40", "5.444705"], ["84103.80", "4.809489"], ["84112.20", "4.718744"], ["84120.60", "5.626195"], ["84129.00", "4.083529"], ["84137.40", "4.355764"], ["84145.80", "4.900235"], ["84154.20", "4.627999"], ["84162.60", "4.537254"], ["84171.00", "5.353960"], ["84179.40", "3.992784"], ["84187.80", "4.446509"], ["84196.20", "4.174274"], ["84204.60", "4.265019"], ["84520.67", "0"]], "bids": [["83945.95", "0.564542"], ["83935.88", "0"], ["83929.00", "0.052877"], ["83927.00", "0.139151"], ["83925.00", "0.366187"], ["83923.00", "0.963650"], ["83921.00", "2.535921"], ["83919.00", "6.673475"], ["83877.00", "5.626195"], ["83873.46", "0"], ["83873.41", "0"], ["83868.60", "4.718744"], ["83860.20", "4.083529"], ["83851.80", "5.081725"], ["83843.40", "4.537254"], ["83835.00", "5.535450"], ["83826.60", "4.446509"], ["83809.80", "4.900235"], ["83801.40", "4.809489"], ["83793.00", "5.172470"], ["83784.60", "5.444705"], ["83776.20", "4.265019"], ["83767.80", "5.263215"], ["83759.40", "3.992784"], ["83751.00", "4.174274"], ["83742.60", "4.355764"], ["83734.20", "3.902039"], ["83725.80", "5.353960"], ["83717.40", "4.990980"], ["83641.86", "0.000379"], ["83641.62", "0.002925"], ["83641.38", "0.000135"]], "checksum": -265473859, "ts": "1742556564534"}], "ts": 1742556564537}}
{"exchange": "BYBIT", "timestamp": 1742556564.738041, "message": {"topic": "orderbook.200.BTCUSDT", "ts": 1742556564719, "type": "delta", "data": {"s": "BTCUSDT", "b": [["83953.8", "0.216789"], ["83949.5", "0.088988"], ["83945.3", "0.205138"], ["83943", "0.118804"], ["83893.2", "0"]], "a": [["83985", "0.001251"], ["84027.8", "0"]], "u": 26641, "seq": 67550550457}, "cts": 1742556564701}}
{"exchange": "BITGET", "timestamp": 1742556564.76909, "message": {"action": "update", "arg": {"instType": "SPOT", "channel": "books", "instId": "BTCUSDT"}, "data": [{"asks": [["83987.00", "0.002637"], ["83989.00", "0.006939"], ["83991.00", "0.018260"], ["83995.00", "0.126454"], ["83997.00", "0.332773"], ["83999.00", "0.875718"], ["84001.00", "2.304521"], ["84003.00", "6.064530"], ["84003.40", "3.275070"], ["84016.10", "0"], ["84045.00", "4.718744"], ["84053.40", "4.083529"], ["84061.80", "4.174274"], ["84070.20", "5.172470"], ["84078.60", "4.355764"], ["84087.00", "4.627999"], ["84095.40", "3.992784"], ["84103.80", "3.902039"], ["84112.20", "4.990980"], ["84120.60", "5.081725"], ["84129.00", "5.263215"], ["84137.40", "4.537254"], ["84145.80", "5.444705"], ["84154.20", "4.809489"], ["84162.60", "5.535450"], ["84171.00", "4.265019"], ["84179.40", "4.446509"], ["84187.80", "5.626195"], ["84196.20", "5.353960"], ["84204.60", "4.900235"], ["84520.67", "0.002384"]], "bids": [["83935.00", "0.002156"], ["83933.00", "0.005674"], ["83931.00", "0.014931"], ["83929.00", "0.039293"], ["83927.00", "0.103402"], ["83925.00", "0.272109"], ["83923.00", "0.716077"], ["83921.00", "1.884414"], ["83919.00", "4.958983"], ["83894.00", "0.000017"], ["83877.71", "0.007347"], ["83877.66", "0.007259"], ["83877.00", "5.081725"], ["83868.60", "4.537254"], ["83860.20", "4.990980"], ["83851.80", "4.355764"], ["83843.40", "3.902039"], ["83835.00", "4.174274"], ["83826.60", "3.992784"], ["83818.20", "5.535450"], ["83809.80", "4.718744"], ["83801.40", "5.626195"], ["83784.60", "4.083529"], ["83776.20", "4.900235"], ["83767.80", "4.627999"], ["83759.40", "5.263215"], ["83751.00", "5.444705"], ["83742.60", "4.446509"], ["83734.20", "5.353960"], ["83725.80", "4.265019"], ["83717.40", "4.809489"], ["83641.62", "0"], ["83641.38", "0"]], "checksum": 1172633631, "ts": "1742556564739"}], "ts": 1742556564742}}
{"exchange": "BYBIT", "timestamp": 1742556564.938662, "message": {"topic": "orderbook.200.BTCUSDT", "ts": 1742556564920, "type": "delta", "data": {"s": "BTCUSDT", "b": [["83924.9", "0"], ["83924.7", "0.012882"], ["83901.5", "0"], ["83898.7", "14.181009"]], "a": [["83965.8", "0.106766"], ["83985", "0"], ["83997.9", "0"], ["83998", "0.059535"], ["83998.2", "0.012743"], ["83998.3", "0.012743"], ["83998.6", "0.003247"], ["83998.7", "0"], ["83998.9", "0.063819"], ["83999", "0.041333"], ["84027.8", "0.059399"]], "u": 26642, "seq": 67550550477}, "cts": 1742556564872}}
{"exchange": "BITGET", "timestamp": 1742556564.978518, "message": {"action": "update", "arg": {"instType": "SPOT", "channel": "books", "instId": "BTCUSDT"}, "data": [{"asks": [["83985.00", "0.001190"], ["83987.00", "0.003262"], ["83989.00", "0.008585"], ["83991.00", "0.022591"], ["83995.00", "0.156448"], ["83997.00", "0.411707"], ["83999.00", "1.083438"], ["84001.00", "2.851154"], ["84003.00", "7.503035"], ["84045.00", "4.083529"], ["84053.40", "4.446509"], ["84061.80", "5.444705"], ["84070.20", "5.353960"], ["84078.60", "5.172470"], ["84087.00", "4.537254"], ["84095.40", "4.627999"], ["84103.80", "3.992784"], ["84112.20", "5.263215"], ["84120.60", "4.990980"], ["84129.00", "4.809489"], ["84137.40", "5.626195"], ["84138.91", "0"], ["84145.80", "4.174274"], ["84154.20", "4.355764"], ["84162.60", "4.900235"], ["84171.00", "5.535450"], ["84179.40", "3.902039"], ["84187.80", "4.718744"], ["84196.20", "4.265019"], ["84204.60", "5.081725"], ["84521.85", "0.000033"]], "bids": [["83935.00", "0.001916"], ["83933.00", "0.005042"], ["83931.00", "0.013269"], ["83929.00", "0.034814"], ["83927.00", "0.091616"], ["83925.00", "0.241095"], ["83923.00", "0.634460"], ["83921.00", "1.669631"], ["83919.00", "4.393766"], ["83918.90", "3.900300"], ["83918.80", "0"], ["83914.80", "0"], ["83908.20", "0.600000"], ["83902.02", "0"], ["83902.01", "0"], ["83877.00", "3.902039"], ["83860.20", "4.265019"], ["83851.80", "4.809489"], ["83843.40", "4.718744"], ["83835.00", "4.900235"], ["83826.60", "5.535450"], ["83818.20", "5.353960"], ["83809.80", "3.992784"], ["83801.40", "5.081725"], ["83793.00", "5.444705"], ["83784.60", "4.174274"], ["83776.20", "4.355764"], ["83759.40", "4.446509"], ["83751.00", "4.990980"], ["83742.60", "4.083529"], ["83734.20", "5.172470"], ["83725.80", "5.263215"], ["83717.40", "5.626195"], ["83641.62", "0.002925"], ["83641.38", "0.000135"], ["83641.00", "0.000082"]], "checksum": 1887771555, "ts": "1742556564950"}], "ts": 1742556564952}}
{"exchange": "BYBIT", "timestamp": 1742556565.13677, "message": {"topic": "orderbook.200.BTCUSDT", "ts": 1742556565119, "type": "delta", "data": {"s": "BTCUSDT", "b": [["83963.3", "0"], ["83962.2", "0.038586"], ["83962.1", "0.071495"], ["83959.2", "0.001779"], ["83953", "0"], ["83952.7", "0"], ["83948.9", "0"], ["83942.9", "0"], ["83942.5", "0"], ["83941.9", "0.001116"], ["83936.8", "0.459264"], ["83935.5", "0.001556"], ["83934.9", "0"], ["83933.8", "0"], ["83898.7", "0"], ["83895.9", "14.181009"], ["83893.2", "0.000516"], ["83891.3", "0.009"], ["83891.2", "0.04"], ["83890.9", "0.00625"], ["83890.7", "0.353794"], ["83890.6", "0.000333"]], "a": [["83977.5", "0"], ["83977.9", "0.059399"], ["83981.8", "0.003242"], ["83987.7", "0"], ["83988", "0"], ["83988.8", "0"], ["83995", "0"], ["83995.8", "0.163321"], ["83996.8", "0.071438"], ["83998.1", "0.013"], ["83998.3", "0"], ["83998.8", "0.04"], ["83999", "0.001333"], ["84000.2", "0.73715"], ["84027.9", "0.001466"], ["84028", "0.00325"], ["84028.4", "0.001333"], ["84028.5", "0.0012"]], "u": 26643, "seq": 67550550527}, "cts": 1742556565112}}
{"exchange": "BITGET", "timestamp": 1742556565.186704, "message": {"action": "update", "arg": {"instType": "SPOT", "channel": "books", "instId": "BTCUSDT"}, "data": [{"asks": [["83945.96", "1.164073"], ["83946.25", "0.346136"], ["83981.97", "0.010000"], ["83985.00", "0.001464"], ["83987.00", "0.003853"], ["83989.00", "0.010139"], ["83991.00", "0.026681"], ["83995.00", "0.184774"], ["83997.00", "0.486246"], ["83999.00", "1.279464"], ["84001.00", "3.367012"], ["84003.00", "8.860556"], ["84016.10", "0.534660"], ["84045.00", "5.081725"], ["84053.40", "4.083529"], ["84061.80", "3.992784"], ["84070.20", "4.446509"], ["84087.00", "5.353960"], ["84095.40", "4.990980"], ["84103.80", "5.626195"], ["84112.20", "4.355764"], ["84120.60", "4.627999"], ["84129.00", "5.263215"], ["84137.40", "4.718744"], ["84140.82", "0.164129"], ["84145.80", "4.809489"], ["84154.20", "4.537254"], ["84162.60", "5.535450"], ["84171.00", "3.902039"], ["84179.40", "4.900235"], ["84187.80", "4.174274"], ["84204.60", "5.444705"], ["84520.50", "0"], ["84520.67", "0"], ["84521.85", "0"]], "bids": [["83945.95", "0.030342"], ["83933.00", "0.004883"], ["83931.00", "0.012851"], ["83929.00", "0.033818"], ["83927.00", "0.088995"], ["83925.00", "0.234196"], ["83923.00", "0.616306"], ["83921.00", "1.621859"], ["83919.00", "4.268049"], ["83918.90", "1.540320"], ["83918.60", "1.010070"], ["83917.80", "0.032010"], ["83916.90", "2.549190"], ["83910.60", "0"], ["83906.22", "0.008331"], ["83906.21", "0.008608"], ["83877.00", "5.172470"], ["83868.60", "4.174274"], ["83860.20", "4.900235"], ["83851.80", "4.990980"], ["83843.40", "3.992784"], ["83835.00", "5.081725"], ["83826.60", "4.627999"], ["83818.20", "5.626195"], ["83809.80", "4.083529"], ["83801.40", "5.444705"], ["83793.00", "5.535450"], ["83784.60", "4.265019"], ["83776.20", "4.537254"], ["83767.80", "3.902039"], ["83759.40", "4.718744"], ["83751.00", "5.353960"], ["83742.60", "4.446509"], ["83734.20", "4.809489"], ["83725.80", "4.355764"], ["83717.40", "5.263215"], ["83641.38", "0"], ["83641.00", "0"]], "checksum": -263580384, "ts": "1742556565151"}], "ts": 1742556565157}}
{"exchange": "BYBIT", "timestamp": 1742556565.338862, "message": {"topic": "orderbook.200.BTCUSDT", "ts": 1742556565320, "type": "delta", "data": {"s": "BTCUSDT", "b": [["83965.5", "0.111387"], ["83962.2", "0"], ["83962.1", "0"], ["83961.9", "0.038819"], ["83961.8", "0.071495"], ["83949.5", "0.061348"], ["83946.2", "0.0003"], ["83945.3", "0.084198"], ["83936.8", "0.155491"], ["83917", "0"], ["83890.5", "3.246386"], ["83890.3", "0.011992"]], "a": [["83984.1", "0.001015"], ["83998.1", "0"], ["83998.3", "0.012743"], ["83998.8", "0"], ["83999", "0.041333"]], "u": 26644, "seq": 67550550568}, "cts": 1742556565302}}
{"exchange": "BITGET", "timestamp": 1742556565.398218, "message": {"action": "update", "arg": {"instType": "SPOT", "channel": "books", "instId": "BTCUSDT"}, "data": [{"asks": [["83966.44", "0.035952"], ["83966.84", "0.119870"], ["83966.86", "0"], ["83967.26", "0"], ["83968.11", "0.035961"], ["83968.53", "0.006356"], ["83968.58", "0"], ["83968.69", "0.006356"], ["83969.00", "0"], ["83969.02", "0.006356"], ["83969.11", "0"], ["83969.44", "0"], ["83970.14", "0.010984"], ["83970.35", "0.006356"], ["83970.55", "0.006356"], ["83970.82", "0"], ["83970.96", "0"], ["83971.05", "0.022785"], ["83971.47", "0"], ["83971.52", "0"], ["83971.53", "0.012712"], ["83971.88", "0.119883"], ["83971.89", "0.016429"], ["83971.99", "0"], ["83972.00", "0"], ["83972.04", "0.006356"], ["83972.06", "0.006356"], ["83972.30", "0"], ["83972.35", "0"], ["83972.51", "0"], ["83972.53", "0"], ["83973.57", "0.006357"], ["83973.58", "0.010985"], ["83973.99", "0"], ["83974.00", "0"], ["83974.40", "0.009990"], ["83974.82", "0"], ["83975.28", "0.119850"], ["83975.77", "0"], ["83976.29", "0.119858"], ["83976.48", "0.119867"], ["83976.71", "0.015895"], ["83976.77", "0"], ["83976.90", "0"], ["83977.19", "0"], ["83981.14", "0"], ["83981.53", "0.010988"], ["83981.95", "0"], ["84045.00", "5.353960"], ["84053.40", "4.809489"], ["84061.80", "4.718744"], ["84070.20", "4.627999"], ["84078.60", "4.537254"], ["84087.00", "5.263215"], ["84095.40", "5.535450"], ["84103.80", "3.902039"], ["84112.20", "5.081725"], ["84120.60", "4.900235"], ["84129.00", "3.992784"], ["84137.40", "5.626195"], ["84145.80", "4.355764"], ["84154.20", "4.446509"], ["84162.60", "4.265019"], ["84171.00", "5.444705"], ["84179.40", "4.083529"], ["84187.80", "5.172470"], ["84196.20", "4.174274"], ["84204.60", "4.990980"], ["84520.50", "0.000238"], ["84520.67", "0.002384"], ["84521.85", "0.000033"]], "bids": [["83935.00", "0.001492"], ["83933.00", "0.003926"], ["83932.13", "0"], ["83931.00", "0.010330"], ["83929.00", "0.027186"], ["83927.00", "0.071542"], ["83926.56", "0"], ["83926.15", "0.089610"], ["83926.12", "0"], ["83925.70", "0.247933"], ["83925.00", "0.188269"], ["83924.92", "0"], ["83924.50", "0"], ["83924.45", "0.084057"], ["83924.29", "0"], ["83924.04", "0.017842"], ["83924.02", "0"], ["83923.95", "0"], ["83923.87", "0.018280"], ["83923.55", "0.004023"], ["83923.52", "0.005954"], ["83923.00", "0.495443"], ["83922.87", "0"], ["83922.63", "0"], ["83922.46", "0.055734"], ["83922.44", "0"], ["83922.16", "0.017127"], ["83922.03", "0.007141"], ["83921.99", "0"], ["83921.94", "0"], ["83921.53", "0.028905"], ["83921.52", "0.007350"], ["83921.47", "0"], ["83921.46", "0"], ["83921.15", "0"], ["83921.09", "0"], ["83921.00", "1.303799"], ["83920.99", "0.007954"], ["83920.98", "0"], ["83920.97", "0"], ["83920.68", "0.025220"], ["83920.67", "0.225197"], ["83920.51", "0.017375"], ["83920.50", "0.008196"], ["83919.44", "0"], ["83919.43", "0"], ["83919.01", "0.052036"], ["83919.00", "3.431049"], ["83918.70", "0"], ["83918.57", "0"], ["83918.15", "0.018543"], ["83917.68", "0"], ["83917.19", "0.268752"], ["83916.67", "0"], ["83916.46", "0"], ["83916.25", "0"], ["83916.19", "0.222981"], ["83916.04", "0.260159"], ["83915.77", "0.285419"], ["83915.30", "0"], ["83912.30", "0"], ["83911.43", "0"], ["83911.01", "0.056446"], ["83909.78", "0"], ["83895.00", "0.000956"], ["83891.36", "0"], ["83890.89", "0.003602"], ["83877.00", "4.355764"], ["83868.60", "4.900235"], ["83860.20", "4.083529"], ["83851.80", "3.992784"], ["83843.40", "4.174274"], ["83835.00", "5.172470"], ["83826.60", "5.263215"], ["83818.20", "4.990980"], ["83809.80", "5.353960"], ["83801.40", "5.626195"], ["83793.00", "5.081725"], ["83776.20", "5.444705"], ["83767.80", "4.809489"], ["83759.40", "3.902039"], ["83751.00", "4.627999"], ["83734.20", "5.535450"], ["83725.80", "4.537254"], ["83717.40", "4.718744"], ["83641.38", "0.000135"], ["83641.00", "0.000082"], ["83640.35", "0.000022"], ["83640.15", "0.000423"], ["83640.00", "0.002013"], ["83639.71", "0.000041"], ["83639.70", "0.000010"], ["83639.15", "0.000009"]], "checksum": 1961653499, "ts": "1742556565356"}], "ts": 1742556565359}}
{"exchange": "BYBIT", "timestamp": 1742556565.537402, "message": {"topic": "orderbook.200.BTCUSDT", "ts": 1742556565520, "type": "delta", "data": {"s": "BTCUSDT", "b": [["83965.5", "0.282387"], ["83962.9", "0.071494"], ["83961.9", "0.017371"], ["83961.8", "0"], ["83952.9", "0.117673"], ["83948.8", "0.122106"], ["83942.4", "0.186002"], ["83941.8", "0.178256"], ["83935.4", "0.296199"], ["83934.8", "0.302089"], ["83924.8", "0"], ["83924.6", "0.012882"], ["83911.9", "0.023819"], ["83898.7", "14.181009"], ["83895.9", "0"], ["83890.9", "0"], ["83890.7", "0"], ["83890.6", "0"], ["83890.5", "0"], ["83890.3", "0"]], "a": [["83977.4", "0.135726"], ["83981.7", "0.124538"], ["83984.1", "0"], ["83987.9", "0.18028"], ["83988.7", "0.164581"], ["83994.9", "0.279096"], ["83995.7", "0.334531"], ["83998.2", "0"], ["83998.4", "0.012743"], ["84028.5", "0"]], "u": 26645, "seq": 67550550610}, "cts": 1742556565514}}
{"exchange": "BITGET", "timestamp": 1742556565.593231, "message": {"action": "update", "arg": {"instType": "SPOT", "channel": "books", "instId": "BTCUSDT"}, "data": [{"asks": [["83966.83", "0.060340"], ["83966.93", "0"], ["83980.66", "0.015892"], ["83985.00", "0.001590"], ["83987.00", "0.004184"], ["83989.00", "0.011011"], ["83991.00", "0.028974"], ["83995.00", "0.200654"], ["83997.00", "0.528039"], ["83999.00", "1.389576"], ["84001.00", "3.656778"], ["84003.00", "9.623101"], ["84045.00", "4.718744"], ["84053.40", "4.446509"], ["84061.80", "4.900235"], ["84070.20", "4.809489"], ["84078.60", "4.627999"], ["84087.00", "4.083529"], ["84095.40", "4.265019"], ["84120.60", "5.444705"], ["84137.40", "4.355764"], ["84145.80", "4.174274"], ["84154.20", "5.172470"], ["84162.60", "5.626195"], ["84171.00", "4.990980"], ["84179.40", "5.353960"], ["84187.80", "5.263215"], ["84196.20", "5.535450"], ["84204.60", "4.537254"], ["84521.85", "0"]], "bids": [["83943.78", "0"], ["83935.00", "0.001344"], ["83933.00", "0.003535"], ["83931.00", "0.009302"], ["83929.00", "0.024479"], ["83927.00", "0.064549"], ["83925.00", "0.169866"], ["83923.00", "0.447018"], ["83921.00", "1.176363"], ["83919.00", "3.095691"], ["83918.90", "1.177650"], ["83918.00", "0.245670"], ["83917.80", "0"], ["83917.40", "0.045240"], ["83916.30", "0.030570"], ["83911.82", "0.073317"], ["83909.35", "0.000878"], ["83895.00", "0.000939"], ["83877.00", "5.535450"], ["83868.60", "5.172470"], ["83860.20", "4.265019"], ["83851.80", "4.083529"], ["83843.40", "4.718744"], ["83835.00", "4.809489"], ["83826.60", "4.355764"], ["83818.20", "5.263215"], ["83809.80", "3.992784"], ["83801.40", "4.537254"], ["83793.00", "4.990980"], ["83784.60", "4.627999"], ["83776.20", "4.900235"], ["83767.80", "4.174274"], ["83751.00", "5.081725"], ["83742.60", "5.626195"], ["83734.20", "5.444705"], ["83725.80", "5.353960"], ["83717.40", "4.446509"], ["83639.15", "0"]], "checksum": 1527951055, "ts": "1742556565563"}], "ts": 1742556565567}}
{"exchange": "BYBIT", "timestamp": 1742556565.736933, "message": {"topic": "orderbook.200.BTCUSDT", "ts": 1742556565719, "type": "delta", "data": {"s": "BTCUSDT", "b": [["83952.9", "0"], ["83949.5", "0.090312"], ["83948.8", "0"], ["83945.3", "0.189887"], ["83942.4", "0"], ["83941.8", "0"], ["83935.4", "0"], ["83934.8", "0.000516"], ["83924.8", "0.013"], ["83924.6", "0"], ["83912", "0"], ["83890.9", "0.00625"], ["83890.7", "0.353794"], ["83890.6", "0.000333"], ["83890.5", "3.246386"], ["83890.3", "0.011992"], ["83890.2", "0.00253"]], "a": [["83977.4", "0.02"], ["83981.7", "0.001466"], ["83987.9", "0.0001"], ["83988.7", "0"], ["83994.9", "0"], ["83995.7", "0.049767"], ["83998.2", "0.013"], ["83998.4", "0"], ["84028.5", "0.0012"], ["84028.6", "0.0006"]], "u": 26646, "seq": 67550550634}, "cts": 1742556565684}}
{"exchange": "BITGET", "timestamp": 1742556565.796589, "message": {"action": "update", "arg": {"instType": "SPOT", "channel": "books", "instId": "BTCUSDT"}, "data": [{"asks": [["83945.96", "1.584073"], ["83985.00", "0.001365"], ["83987.00", "0.003591"], ["83989.00", "0.009449"], ["83991.00", "0.024868"], ["83995.00", "0.172213"], ["83996.99", "0.422023"], ["83997.00", "0.453191"], ["83999.00", "1.192610"], ["84001.00", "3.138446"], ["84003.00", "8.259070"], ["84003.50", "0.001597"], ["84003.93", "0"], ["84008.00", "0.068550"], ["84008.40", "1.138200"], ["84028.01", "0"], ["84045.00", "4.627999"], ["84053.40", "4.990980"], ["84061.80", "3.902039"], ["84070.20", "4.537254"], ["84078.60", "5.263215"], ["84087.00", "4.809489"], ["84095.40", "4.900235"], ["84103.80", "4.446509"], ["84112.20", "5.535450"], ["84120.60", "4.355764"], ["84129.00", "4.265019"], ["84137.40", "4.174274"], ["84145.80", "3.992784"], ["84162.60", "4.083529"], ["84171.00", "5.081725"], ["84179.40", "5.444705"], ["84187.80", "5.353960"], ["84196.20", "5.626195"], ["84204.60", "4.718744"]], "bids": [["83944.63", "0.047852"], ["83935.00", "0.001954"], ["83933.00", "0.005141"], ["83931.00", "0.013530"], ["83929.00", "0.035604"], ["83927.00", "0.093694"], ["83925.00", "0.246563"], ["83923.01", "0.608935"], ["83923.00", "0.648850"], ["83921.00", "1.707502"], ["83919.00", "4.493425"], ["83916.30", "0"], ["83889.93", "0"], ["83889.50", "0.001174"], ["83877.00", "5.444705"], ["83868.60", "4.537254"], ["83860.20", "4.809489"], ["83851.80", "4.446509"], ["83843.40", "3.992784"], ["83835.00", "4.083529"], ["83826.60", "4.265019"], ["83818.20", "5.626195"], ["83809.80", "4.718744"], ["83801.40", "3.902039"], ["83793.00", "4.355764"], ["83776.20", "5.353960"], ["83767.80", "5.172470"], ["83759.40", "4.174274"], ["83751.00", "4.990980"], ["83742.60", "5.081725"], ["83734.20", "5.263215"], ["83725.80", "4.900235"], ["83717.40", "5.535450"]], "checksum": 573058069, "ts": "1742556565767"}], "ts": 1742556565770}}
{"exchange": "BYBIT", "timestamp": 1742556565.938814, "message": {"topic": "orderbook.200.BTCUSDT", "ts": 1742556565919, "type": "delta", "data": {"s": "BTCUSDT", "b": [["83965.5", "0.281756"], ["83959.6", "0.000153"], ["83957.7", "0.000333"], ["83949.5", "0.061348"], ["83945.3", "0.084198"], ["83924.9", "0.013"], ["83924.8", "0.012882"], ["83924.7", "0"], ["83890.2", "0"]], "a": [["83989.7", "0"], ["83998.1", "0.013"], ["83998.2", "0.012743"], ["83998.3", "0"], ["84029.1", "0.000333"]], "u": 26647, "seq": 67550550652}, "cts": 1742556565911}}
{"exchange": "BITGET", "timestamp": 1742556566.002874, "message": {"action": "update", "arg": {"instType": "SPOT", "channel": "books", "instId": "BTCUSDT"}, "data": [{"asks": [["83976.90", "0.009989"], ["83977.33", "0"], ["83978.54", "0"], ["83987.00", "0.003721"], ["83989.00", "0.009793"], ["83991.00", "0.025771"], ["83995.00", "0.178466"], ["83997.00", "0.469649"], ["83999.00", "1.235919"], ["84001.00", "3.252418"], ["84001.57", "0.001598"], ["84002.01", "0"], ["84002.99", "0"], ["84003.00", "8.558995"], ["84045.00", "5.263215"], ["84053.40", "4.718744"], ["84063.92", "0"], ["84078.60", "4.083529"], ["84087.00", "4.174274"], ["84095.40", "5.081725"], ["84103.80", "4.265019"], ["84112.20", "5.626195"], ["84120.60", "5.535450"], ["84129.00", "4.990980"], ["84137.40", "4.627999"], ["84145.80", "4.809489"], ["84154.20", "4.446509"], ["84162.60", "3.992784"], ["84171.00", "4.355764"], ["84179.40", "5.172470"], ["84187.80", "4.900235"], ["84196.20", "5.444705"], ["84204.60", "5.353960"], ["84521.85", "0.000033"], ["84522.06", "0.000041"], ["84523.08", "0.000015"]], "bids": [["83935.00", "0.002084"], ["83933.00", "0.005485"], ["83931.00", "0.014435"], ["83929.00", "0.037987"], ["83927.00", "0.100157"], ["83925.00", "0.263569"], ["83923.00", "0.693605"], ["83921.00", "1.825276"], ["83919.00", "4.803357"], ["83916.05", "0"], ["83915.62", "0.021159"], ["83915.20", "0.073140"], ["83891.87", "0"], ["83891.43", "0.001177"], ["83877.00", "4.627999"], ["83860.20", "4.083529"], ["83851.80", "4.718744"], ["83843.40", "4.990980"], ["83835.00", "3.992784"], ["83826.60", "4.446509"], ["83818.20", "5.263215"], ["83809.80", "5.172470"], ["83801.40", "5.535450"], ["83793.00", "4.174274"], ["83784.60", "4.809489"], ["83776.20", "5.626195"], ["83767.80", "5.081725"], ["83759.40", "4.355764"], ["83751.00", "5.444705"], ["83742.60", "5.353960"], ["83734.20", "4.900235"], ["83725.80", "4.265019"], ["83717.40", "3.902039"], ["83639.70", "0"]], "checksum": 666014183, "ts": "1742556565973"}], "ts": 1742556565976}}
{"exchange": "BYBIT", "timestamp": 1742556566.137104, "message": {"topic": "orderbook.200.BTCUSDT", "ts": 1742556566120, "type": "delta", "data": {"s": "BTCUSDT", "b": [["83965.5", "0.279763"], ["83961.9", "0.000333"], ["83959.2", "0.015787"], ["83924.9", "0"], ["83924.8", "0"], ["83898.7", "0"], ["83895.9", "14.181009"], ["83890.2", "0.00253"], ["83890", "0.0002"]], "a": [["83988.6", "0.003576"], ["83998.1", "0"], ["83998.2", "0"], ["83998.8", "0.04"], ["83999", "0.001333"]], "u": 26648, "seq": 67550550678}, "cts": 1742556566115}}
{"exchange": "BITGET", "timestamp": 1742556566.207276, "message": {"action": "update", "arg": {"instType": "SPOT", "channel": "books", "instId": "BTCUSDT"}, "data": [{"asks": [["83976.34", "0.043415"], ["83978.59", "0.175812"], ["83989.00", "0.009684"], ["83991.00", "0.025485"], ["83995.00", "0.176490"], ["83997.00", "0.464446"], ["83999.00", "1.222226"], ["84001.00", "3.216385"], ["84003.00", "8.464172"], ["84028.01", "0.062760"], ["84045.00", "4.265019"], ["84053.40", "5.263215"], ["84061.80", "4.174274"], ["84063.08", "0.125799"], ["84070.20", "5.353960"], ["84078.60", "4.355764"], ["84087.00", "4.627999"], ["84095.40", "5.535450"], ["84103.80", "5.172470"], ["84112.20", "4.446509"], ["84120.60", "4.809489"], ["84137.40", "4.900235"], ["84145.80", "4.083529"], ["84154.20", "5.444705"], ["84171.00", "4.537254"], ["84179.40", "5.626195"], ["84187.80", "3.902039"], ["84196.20", "4.718744"], ["84204.60", "5.081725"], ["84521.85", "0"], ["84522.06", "0"], ["84523.08", "0"]], "bids": [["83929.00", "0.038097"], ["83925.00", "0.263828"], ["83923.00", "0.694284"], ["83921.00", "1.827064"], ["83919.00", "4.807933"], ["83917.00", "0.029670"], ["83915.20", "0"], ["83914.80", "0.015000"], ["83893.00", "0"], ["83877.00", "5.353960"], ["83868.60", "4.900235"], ["83860.20", "4.809489"], ["83851.80", "4.990980"], ["83843.40", "5.535450"], ["83835.00", "5.626195"], ["83826.60", "4.627999"], ["83818.20", "4.355764"], ["83809.80", "5.081725"], ["83801.40", "5.172470"], ["83784.60", "3.992784"], ["83776.20", "5.263215"], ["83767.80", "4.265019"], ["83759.40", "4.446509"], ["83742.60", "4.718744"], ["83734.20", "4.537254"], ["83725.80", "3.902039"], ["83717.40", "4.083529"], ["83639.70", "0.000010"]], "checksum": 666014183, "ts": "1742556566173"}], "ts": 1742556566176}}
{"exchange": "BYBIT", "timestamp": 1742556566.338931, "message": {"topic": "orderbook.200.BTCUSDT", "ts": 1742556566319, "type": "delta", "data": {"s": "BTCUSDT", "b": [["83936.8", "0.197081"], ["83898.7", "14.095676"], ["83895.9", "0"]], "a": [["83965.6", "0.591361"], ["83998.8", "0"], ["83999", "0.041333"], ["84030.6", "0.118804"]], "u": 26649, "seq": 67550550705}, "cts": 1742556566305}}
{"exchange": "BITGET", "timestamp": 1742556566.42123, "message": {"action": "update", "arg": {"instType": "SPOT", "channel": "books", "instId": "BTCUSDT"}, "data": [{"asks": [["83987.00", "0.003679"], ["83989.00", "0.009681"], ["83991.00", "0.025477"], ["83995.00", "0.176435"], ["83997.00", "0.464302"], ["83999.00", "1.221848"], ["84001.00", "3.215389"], ["84003.00", "8.461549"], ["84045.00", "5.535450"], ["84053.39", "0.016923"], ["84053.40", "3.902039"], ["84061.80", "4.355764"], ["84070.20", "4.809489"], ["84078.60", "4.083529"], ["84087.00", "4.265019"], ["84095.40", "5.626195"], ["84103.80", "5.444705"], ["84112.20", "3.992784"], ["84120.60", "4.900235"], ["84129.00", "4.537254"], ["84137.40", "5.353960"], ["84145.80", "4.718744"], ["84154.20", "4.174274"], ["84162.60", "4.627999"], ["84171.00", "4.446509"], ["84179.40", "5.172470"], ["84187.80", "5.263215"], ["84196.20", "4.990980"], ["84520.67", "0"]], "bids": [["83919.31", "0.254287"], ["83893.00", "0.000017"], ["83877.00", "3.992784"], ["83868.60", "5.444705"], ["83860.20", "5.353960"], ["83851.80", "5.172470"], ["83843.40", "5.626195"], ["83835.00", "4.627999"], ["83826.60", "4.265019"], ["83818.20", "4.809489"], ["83809.80", "4.537254"], ["83801.40", "5.081725"], ["83793.00", "4.900235"], ["83784.60", "4.718744"], ["83776.20", "4.083529"], ["83767.80", "5.535450"], ["83759.40", "4.174274"], ["83751.00", "3.902039"], ["83742.60", "5.263215"], ["83734.20", "4.355764"], ["83725.80", "4.990980"], ["83717.40", "4.446509"], ["83639.71", "0"], ["83639.70", "0"]], "checksum": 666014183, "ts": "1742556566385"}], "ts": 1742556566388}}
{"exchange": "BYBIT", "timestamp": 1742556566.537006, "message": {"topic": "orderbook.200.BTCUSDT", "ts": 1742556566519, "type": "delta", "data": {"s": "BTCUSDT", "b": [["83965.5", "0.283053"], ["83945.9", "0.005899"], ["83890", "0"]], "a": [["83974.1", "0"], ["84030.9", "0.089099"]], "u": 26650, "seq": 67550550718}, "cts": 1742556566497}}
{"exchange": "BITGET", "timestamp": 1742556566.615341, "message": {"action": "update", "arg": {"instType": "SPOT", "channel": "books", "instId": "BTCUSDT"}, "data": [{"asks": [["83946.25", "0.343955"], ["83975.27", "0.172123"], ["83976.34", "0"], ["84045.00", "4.990980"], ["84053.39", "0"], ["84053.40", "4.174274"], ["84061.80", "5.263215"], ["84070.20", "3.902039"], ["84078.60", "5.535450"], ["84087.00", "4.355764"], ["84095.40", "4.083529"], ["84112.20", "4.900235"], ["84120.60", "4.537254"], ["84129.00", "5.626195"], ["84137.40", "4.809489"], ["84145.80", "3.992784"], ["84154.20", "4.718744"], ["84162.60", "5.081725"], ["84171.00", "5.353960"], ["84179.40", "4.627999"], ["84187.80", "5.172470"], ["84196.20", "4.446509"], ["84204.60", "4.265019"], ["84520.67", "0.002384"]], "bids": [["83877.00", "4.627999"], ["83868.60", "4.265019"], ["83860.20", "4.990980"], ["83851.80", "5.353960"], ["83843.40", "5.444705"], ["83835.00", "4.809489"], ["83826.60", "5.535450"], ["83818.20", "3.902039"], ["83801.40", "4.355764"], ["83793.00", "4.083529"], ["83784.60", "5.263215"], ["83776.20", "3.992784"], ["83767.80", "4.446509"], ["83759.40", "5.172470"], ["83751.00", "4.174274"], ["83742.60", "4.900235"], ["83734.20", "5.626195"], ["83725.80", "5.081725"], ["83717.40", "4.718744"]], "checksum": 346430852, "ts": "1742556566585"}], "ts": 1742556566588}}
{"exchange": "BITGET", "timestamp": 1742556566.832814, "message": {"action": "update", "arg": {"instType": "SPOT", "channel": "books", "instId": "BTCUSDT"}, "data": [{"asks": [["83945.96", "1.164073"], ["83946.25", "0.337621"], ["83987.00", "0.003810"], ["83989.00", "0.010026"], ["83991.00", "0.026383"], ["83995.00", "0.182710"], ["83997.00", "0.480814"], ["83999.00", "1.265302"], ["84001.00", "3.329742"], ["84003.00", "8.762479"], ["84045.00", "4.265019"], ["84053.40", "4.446509"], ["84061.80", "4.990980"], ["84070.20", "4.900235"], ["84078.60", "5.172470"], ["84087.00", "4.174274"], ["84095.40", "4.627999"], ["84103.80", "3.992784"], ["84112.20", "3.902039"], ["84120.60", "5.626195"], ["84129.00", "5.353960"], ["84137.40", "4.083529"], ["84145.80", "4.355764"], ["84162.60", "4.809489"], ["84171.00", "5.535450"], ["84179.40", "5.444705"], ["84187.80", "5.263215"], ["84196.20", "5.081725"], ["84204.60", "4.537254"]], "bids": [["83877.00", "5.444705"], ["83868.60", "4.446509"], ["83860.20", "3.902039"], ["83851.80", "3.992784"], ["83843.40", "5.535450"], ["83835.00", "4.174274"], ["83826.60", "5.626195"], ["83818.20", "5.263215"], ["83809.80", "4.355764"], ["83801.40", "4.627999"], ["83793.00", "5.172470"], ["83784.60", "4.809489"], ["83776.20", "5.081725"], ["83767.80", "4.083529"], ["83759.40", "4.990980"], ["83751.00", "4.265019"], ["83742.60", "4.537254"], ["83734.20", "4.718744"], ["83725.80", "5.353960"], ["83717.40", "4.900235"]], "checksum": -1483354597, "ts": "1742556566785"}], "ts": 1742556566788}}
{"exchange": "BYBIT", "timestamp": 1742556566.938012, "message": {"topic": "orderbook.200.BTCUSDT", "ts": 1742556566919, "type": "delta", "data": {"s": "BTCUSDT", "b": [], "a": [["83970", "0.005942"], ["83986.8", "0.483204"], ["83991.4", "0.02009"], ["83998.8", "0.04"], ["83999", "0.001333"], ["84003.6", "0.005942"], ["84008.2", "0.030132"], ["84020.4", "0.005942"], ["84025", "0.00009"], ["84028.6", "0"], ["84029.1", "0"], ["84030.6", "0"], ["84030.9", "0"]], "u": 26651, "seq": 67550550755}, "cts": 1742556566899}}
{"exchange": "BITGET", "timestamp": 1742556567.032615, "message": {"action": "update", "arg": {"instType": "SPOT", "channel": "books", "instId": "BTCUSDT"}, "data": [{"asks": [["83945.96", "1.584073"], ["83946.25", "0.337412"], ["84008.40", "0.426390"], ["84009.90", "0"], ["84010.80", "0"], ["84011.60", "0"], ["84016.20", "0.264000"], ["84016.30", "0.012840"], ["84045.00", "4.446509"], ["84053.40", "3.902039"], ["84061.80", "4.900235"], ["84070.20", "5.353960"], ["84087.00", "5.081725"], ["84095.40", "4.083529"], ["84103.80", "5.263215"], ["84112.20", "4.265019"], ["84120.60", "3.992784"], ["84129.00", "4.537254"], ["84137.40", "4.718744"], ["84145.80", "5.444705"], ["84154.20", "4.990980"], ["84162.60", "4.174274"], ["84179.40", "4.809489"], ["84187.80", "5.626195"], ["84196.20", "4.355764"], ["84204.60", "4.627999"], ["84521.85", "0.000033"]], "bids": [["83944.63", "0"], ["83937.14", "0.010000"], ["83935.00", "0.001805"], ["83933.00", "0.004749"], ["83931.00", "0.012497"], ["83929.00", "0.032889"], ["83927.00", "0.086550"], ["83925.00", "0.227761"], ["83923.00", "0.599372"], ["83921.00", "1.577295"], ["83919.00", "4.150776"], ["83918.00", "0.303420"], ["83917.40", "0.045030"], ["83917.00", "0.059640"], ["83915.20", "0.072900"], ["83908.20", "0"], ["83894.00", "0.000015"], ["83877.00", "4.355764"], ["83860.20", "4.265019"], ["83851.80", "5.081725"], ["83843.40", "5.353960"], ["83835.00", "5.172470"], ["83826.60", "4.718744"], ["83818.20", "4.900235"], ["83809.80", "5.444705"], ["83801.40", "4.174274"], ["83793.00", "3.902039"], ["83784.60", "5.626195"], ["83776.20", "3.992784"], ["83767.80", "5.535450"], ["83759.40", "4.627999"], ["83751.00", "4.537254"], ["83742.60", "4.083529"], ["83734.20", "4.990980"], ["83725.80", "5.263215"], ["83717.40", "4.809489"]], "checksum": 1770805367, "ts": "1742556566999"}], "ts": 1742556567002}}
{"exchange": "BYBIT", "timestamp": 1742556567.139519, "message": {"topic": "orderbook.200.BTCUSDT", "ts": 1742556567120, "type": "delta", "data": {"s": "BTCUSDT", "b": [], "a": [["83965.6", "0.590681"], ["83971.3", "0.0002"], ["84028.5", "0"]], "u": 26652, "seq": 67550550766}, "cts": 1742556567102}}
{"exchange": "BITGET", "timestamp": 1742556567.236077, "message": {"action": "update", "arg": {"instType": "SPOT", "channel": "books", "instId": "BTCUSDT"}, "data": [{"asks": [["83981.97", "0"], ["84008.50", "0.062340"], ["84045.00", "4.718744"], ["84053.40", "4.446509"], ["84061.80", "5.172470"], ["84070.20", "4.355764"], ["84078.60", "5.626195"], ["84087.00", "4.174274"], ["84095.40", "4.627999"], ["84103.80", "5.081725"], ["84112.20", "3.902039"], ["84129.00", "4.265019"], ["84137.40", "5.353960"], ["84145.80", "4.809489"], ["84154.20", "4.900235"], ["84162.60", "5.444705"], ["84171.00", "5.263215"], ["84179.40", "4.083529"], ["84187.80", "4.990980"], ["84196.20", "5.535450"], ["84204.60", "4.537254"], ["84522.06", "0.000041"]], "bids": [["83945.00", "0.047884"], ["83935.00", "0.002317"], ["83933.00", "0.006098"], ["83931.00", "0.016046"], ["83929.00", "0.042228"], ["83927.00", "0.111124"], ["83925.00", "0.292434"], ["83923.00", "0.769563"], ["83921.00", "2.025166"], ["83919.00", "5.329384"], ["83917.00", "0.000032"], ["83908.20", "0.120000"], ["83877.00", "5.081725"], ["83868.60", "4.083529"], ["83860.20", "4.900235"], ["83851.80", "4.718744"], ["83843.40", "4.446509"], ["83835.00", "3.992784"], ["83826.60", "4.355764"], ["83818.20", "3.902039"], ["83809.80", "4.990980"], ["83801.40", "4.537254"], ["83793.00", "5.444705"], ["83784.60", "5.172470"], ["83776.20", "5.263215"], ["83759.40", "4.265019"], ["83751.00", "4.809489"], ["83742.60", "5.626195"], ["83734.20", "5.353960"], ["83725.80", "4.174274"], ["83717.40", "4.627999"], ["83640.00", "0"]], "checksum": 2036870497, "ts": "1742556567205"}], "ts": 1742556567209}}
{"exchange": "BYBIT", "timestamp": 1742556567.337686, "message": {"topic": "orderbook.200.BTCUSDT", "ts": 1742556567320, "type": "delta", "data": {"s": "BTCUSDT", "b": [], "a": [["83990.4", "0"], ["83998.8", "0"], ["83999", "0.041333"], ["84028.5", "0.0012"], ["84028.6", "0.0006"]], "u": 26653, "seq": 67550550773}, "cts": 1742556567272}}
{"exchange": "BITGET", "timestamp": 1742556567.435771, "message": {"action": "update", "arg": {"instType": "SPOT", "channel": "books", "instId": "BTCUSDT"}, "data": [{"asks": [["83987.00", "0.003441"], ["83989.00", "0.009055"], ["83991.00", "0.023830"], ["83995.00", "0.165026"], ["83997.00", "0.434280"], ["83999.00", "1.142841"], ["84001.00", "3.007476"], ["84003.00", "7.914412"], ["84045.00", "4.900235"], ["84053.40", "4.083529"], ["84061.80", "4.627999"], ["84070.20", "4.718744"], ["84078.60", "5.535450"], ["84087.00", "4.446509"], ["84095.40", "4.809489"], ["84112.20", "3.992784"], ["84120.60", "4.990980"], ["84129.00", "3.902039"], ["84137.40", "4.174274"], ["84145.80", "4.265019"], ["84154.20", "5.626195"], ["84162.60", "5.263215"], ["84171.00", "5.353960"], ["84179.40", "4.537254"], ["84187.80", "5.172470"], ["84196.20", "5.444705"], ["84204.60", "4.355764"]], "bids": [["83868.60", "4.718744"], ["83860.20", "3.992784"], ["83851.80", "4.990980"], ["83843.40", "5.263215"], ["83835.00", "5.626195"], ["83826.60", "3.902039"], ["83818.20", "4.537254"], ["83809.80", "5.535450"], ["83801.40", "4.446509"], ["83793.00", "4.083529"], ["83784.60", "4.627999"], ["83776.20", "4.265019"], ["83767.80", "4.809489"], ["83759.40", "4.355764"], ["83751.00", "4.900235"], ["83742.60", "5.353960"], ["83734.20", "5.172470"], ["83717.40", "5.444705"]], "checksum": 2036870497, "ts": "1742556567404"}], "ts": 1742556567407}}
{"exchange": "BYBIT", "timestamp": 1742556567.536913, "message": {"topic": "orderbook.200.BTCUSDT", "ts": 1742556567519, "type": "delta", "data": {"s": "BTCUSDT", "b": [], "a": [["83988.6", "0"], ["83989.6", "0.035737"]], "u": 26654, "seq": 67550550782}, "cts": 1742556567483}}
{"exchange": "BITGET", "timestamp": 1742556567.652277, "message": {"action": "update", "arg": {"instType": "SPOT", "channel": "books", "instId": "BTCUSDT"}, "data": [{"asks": [["83945.96", "1.583046"], ["84001.00", "3.007243"], ["84003.00", "7.913798"], ["84008.40", "1.371900"], ["84009.90", "0.714900"], ["84010.80", "0.714900"], ["84011.60", "0.714900"], ["84012.40", "0.714900"], ["84016.10", "0"], ["84016.20", "0"], ["84016.30", "0"], ["84045.00", "4.537254"], ["84053.40", "4.900235"], ["84061.80", "3.992784"], ["84070.20", "4.265019"], ["84078.60", "5.626195"], ["84087.00", "5.444705"], ["84095.40", "5.535450"], ["84103.80", "4.446509"], ["84112.20", "4.083529"], ["84120.60", "5.353960"], ["84129.00", "4.174274"], ["84137.40", "4.718744"], ["84145.80", "3.902039"], ["84154.20", "4.355764"], ["84162.60", "4.809489"], ["84171.00", "4.627999"], ["84179.40", "5.263215"], ["84187.80", "4.990980"], ["84196.20", "5.081725"], ["84204.60", "5.172470"], ["84522.06", "0"]], "bids": [["83935.00", "0.002239"], ["83933.00", "0.005891"], ["83931.00", "0.015503"], ["83929.00", "0.040797"], ["83927.00", "0.107361"], ["83925.00", "0.282530"], ["83923.00", "0.743500"], ["83921.00", "1.956578"], ["83919.00", "5.148889"], ["83914.80", "0.030000"], ["83895.00", "0.000956"], ["83877.00", "4.083529"], ["83868.60", "4.990980"], ["83860.20", "4.174274"], ["83851.80", "4.446509"], ["83843.40", "5.444705"], ["83835.00", "5.535450"], ["83826.60", "5.081725"], ["83818.20", "5.626195"], ["83809.80", "5.353960"], ["83801.40", "3.902039"], ["83793.00", "5.172470"], ["83784.60", "4.537254"], ["83776.20", "3.992784"], ["83767.80", "4.627999"], ["83751.00", "4.265019"], ["83742.60", "4.900235"], ["83734.20", "4.718744"], ["83725.80", "5.263215"], ["83717.40", "4.809489"]], "checksum": 1483985994, "ts": "1742556567623"}], "ts": 1742556567626}}
{"exchange": "BYBIT", "timestamp": 1742556567.738868, "message": {"topic": "orderbook.200.BTCUSDT", "ts": 1742556567720, "type": "delta", "data": {"s": "BTCUSDT", "b": [["83963.9", "0.071493"], ["83962.9", "0"], ["83958.1", "0"], ["83957.6", "0.071498"], ["83953.8", "0.141855"], ["83953.4", "0.045942"], ["83953.2", "0.000516"], ["83947.9", "0.06137"], ["83940.9", "0.054946"], ["83936.6", "0.005942"], ["83933.9", "0.111905"], ["83919.8", "0.151134"], ["83903", "0.005942"], ["83890.6", "0"], ["83890.5", "0"], ["83890.3", "0"], ["83890.2", "0"]], "a": [["83965.6", "0.588538"], ["83982.9", "0.059225"], ["83988.2", "0.003576"], ["83989.9", "0.060109"], ["83996.9", "0.117135"], ["83998.7", "0.04"], ["83998.8", "0.04"], ["83998.9", "0.023819"], ["83999", "0.001333"], ["84007.7", "0.002143"], ["84027.8", "0"], ["84027.9", "0"], ["84028", "0"], ["84028.4", "0"], ["84028.5", "0"], ["84028.6", "0"]], "u": 26655, "seq": 67550550808}, "cts": 1742556567712}}
{"exchange": "BITGET", "timestamp": 1742556567.859756, "message": {"action": "update", "arg": {"instType": "SPOT", "channel": "books", "instId": "BTCUSDT"}, "data": [{"asks": [["83946.01", "0"], ["83985.00", "0.001259"], ["83987.00", "0.003311"], ["83989.00", "0.008715"], ["83991.00", "0.022933"], ["83995.00", "0.158819"], ["83997.00", "0.417698"], ["83999.00", "1.099204"], ["84001.00", "2.892643"], ["84003.00", "7.612217"], ["84045.00", "5.626195"], ["84053.40", "5.081725"], ["84061.80", "4.083529"], ["84070.20", "4.627999"], ["84078.60", "5.172470"], ["84087.00", "5.535450"], ["84095.40", "4.809489"], ["84103.80", "4.355764"], ["84112.20", "4.990980"], ["84120.60", "4.537254"], ["84129.00", "5.263215"], ["84137.40", "4.900235"], ["84145.80", "4.718744"], ["84154.20", "3.902039"], ["84162.60", "4.446509"], ["84171.00", "5.444705"], ["84179.40", "4.174274"], ["84187.80", "5.353960"], ["84196.20", "3.992784"], ["84204.60", "4.265019"], ["84522.06", "0.000041"]], "bids": [["83945.95", "0.239542"], ["83935.00", "0.002936"], ["83933.00", "0.007726"], ["83931.00", "0.020330"], ["83929.00", "0.053501"], ["83927.00", "0.140793"], ["83925.00", "0.370507"], ["83923.00", "0.975019"], ["83921.00", "2.565840"], ["83919.00", "6.752209"], ["83918.70", "2.359560"], ["83918.00", "0.303210"], ["83916.90", "0.189780"], ["83895.00", "0.000941"], ["83877.00", "4.990980"], ["83868.60", "4.174274"], ["83860.20", "4.265019"], ["83851.80", "4.355764"], ["83843.40", "5.172470"], ["83818.20", "5.353960"], ["83809.80", "4.718744"], ["83801.40", "4.537254"], ["83793.00", "4.809489"], ["83784.60", "4.627999"], ["83767.80", "5.626195"], ["83759.40", "5.444705"], ["83751.00", "3.902039"], ["83742.60", "4.083529"], ["83734.20", "5.263215"], ["83725.80", "4.446509"], ["83717.40", "4.900235"], ["83640.15", "0"]], "checksum": -860460940, "ts": "1742556567823"}], "ts": 1742556567828}}
{"exchange": "BYBIT", "timestamp": 1742556567.937161, "message": {"topic": "orderbook.200.BTCUSDT", "ts": 1742556567919, "type": "delta", "data": {"s": "BTCUSDT", "b": [["83941.3", "0"], ["83924.5", "0"], ["83907.7", "0"], ["83890.6", "0.000333"], ["83890.5", "3.246386"], ["83890.3", "0.011992"]], "a": [["83998.6", "0.043247"], ["83998.8", "0"], ["84027.8", "0.059399"]], "u": 26656, "seq": 67550550818}, "cts": 1742556567908}}
{"exchange": "BITGET", "timestamp": 1742556568.058788, "message": {"action": "update", "arg": {"instType": "SPOT", "channel": "books", "instId": "BTCUSDT"}, "data": [{"asks": [["83997.00", "0.417987"], ["83999.00", "1.099967"], ["84001.00", "2.894650"], ["84003.00", "7.617500"], ["84016.00", "0.510000"], ["84045.00", "5.353960"], ["84053.40", "5.172470"], ["84061.80", "5.263215"], ["84070.20", "4.809489"], ["84078.60", "5.081725"], ["84087.00", "4.990980"], ["84095.40", "5.444705"], ["84103.80", "3.902039"], ["84112.20", "5.535450"], ["84120.60", "4.900235"], ["84129.00", "4.265019"], ["84137.40", "4.718744"], ["84145.80", "5.626195"], ["84154.20", "4.174274"], ["84162.60", "4.083529"], ["84171.00", "4.355764"], ["84179.40", "4.537254"], ["84187.80", "4.627999"], ["84196.20", "4.446509"], ["84204.60", "3.992784"]], "bids": [["83945.95", "0.214442"], ["83935.00", "0.002239"], ["83933.00", "0.005891"], ["83931.00", "0.015503"], ["83929.00", "0.040797"], ["83927.00", "0.107361"], ["83925.00", "0.282530"], ["83923.01", "0.863222"], ["83923.00", "0.743500"], ["83921.00", "1.956578"], ["83919.31", "0"], ["83919.00", "5.148889"], ["83918.90", "1.528710"], ["83918.00", "0.066510"], ["83877.00", "4.537254"], ["83868.60", "4.083529"], ["83860.20", "5.535450"], ["83851.80", "4.809489"], ["83835.00", "4.446509"], ["83826.60", "3.902039"], ["83818.20", "3.992784"], ["83801.40", "5.353960"], ["83793.00", "4.355764"], ["83776.20", "5.081725"], ["83767.80", "5.263215"], ["83751.00", "4.174274"], ["83742.60", "4.900235"], ["83734.20", "5.626195"], ["83725.80", "4.265019"], ["83717.40", "4.990980"], ["83640.15", "0.000423"]], "checksum": 1797358664, "ts": "1742556568025"}], "ts": 1742556568028}}
{"exchange": "BYBIT", "timestamp": 1742556568.136914, "message": {"topic": "orderbook.200.BTCUSDT", "ts": 1742556568119, "type": "delta", "data": {"s": "BTCUSDT", "b": [["83959.6", "0"], ["83890.2", "0.00253"]], "a": [["83965.6", "0.590681"], ["83998.6", "0.003247"], ["83998.8", "0.04"], ["83999.3", "0.063449"], ["84002.1", "0"], ["84007.7", "0"]], "u": 26657, "seq": 67550550829}, "cts": 1742556568113}}
{"exchange": "BITGET", "timestamp": 1742556568.255457, "message": {"action": "update", "arg": {"instType": "SPOT", "channel": "books", "instId": "BTCUSDT"}, "data": [{"asks": [["83985.00", "0.001397"], ["83987.00", "0.003676"], ["83989.00", "0.009673"], ["83991.00", "0.025457"], ["83995.00", "0.176295"], ["83997.00", "0.463933"], ["83999.00", "1.220875"], ["84001.00", "3.212830"], ["84003.00", "8.454816"], ["84003.30", "0.059100"], ["84003.40", "3.274860"], ["84006.60", "0.074040"], ["84016.00", "0"], ["84045.00", "4.990980"], ["84053.40", "4.809489"], ["84061.80", "5.535450"], ["84070.20", "4.174274"], ["84078.60", "4.265019"], ["84087.00", "5.172470"], ["84095.40", "4.900235"], ["84103.80", "4.627999"], ["84112.20", "5.263215"], ["84120.60", "4.537254"], ["84129.00", "5.081725"], ["84137.40", "4.355764"], ["84145.80", "5.353960"], ["84154.20", "4.446509"], ["84162.60", "3.902039"], ["84171.00", "4.083529"], ["84179.40", "5.444705"], ["84187.80", "5.626195"], ["84196.20", "4.718744"], ["84523.08", "0.000015"]], "bids": [["83945.95", "0.005242"], ["83945.00", "0.000032"], ["83931.00", "0.015720"], ["83929.00", "0.041368"], ["83927.00", "0.108863"], ["83925.00", "0.286483"], ["83923.00", "0.753902"], ["83921.00", "1.983952"], ["83919.00", "5.220927"], ["83877.00", "4.355764"], ["83868.60", "3.992784"], ["83860.20", "4.627999"], ["83843.40", "5.444705"], ["83826.60", "4.990980"], ["83818.20", "4.537254"], ["83809.80", "4.265019"], ["83801.40", "5.172470"], ["83793.00", "5.535450"], ["83784.60", "5.081725"], ["83776.20", "4.718744"], ["83759.40", "5.626195"], ["83751.00", "3.902039"], ["83742.60", "4.174274"], ["83734.20", "5.353960"], ["83725.80", "4.900235"], ["83717.40", "4.083529"]], "checksum": -728693516, "ts": "1742556568225"}], "ts": 1742556568229}}
{"exchange": "BYBIT", "timestamp": 1742556568.336678, "message": {"topic": "orderbook.200.BTCUSDT", "ts": 1742556568319, "type": "delta", "data": {"s": "BTCUSDT", "b": [], "a": [["83998.6", "0.043247"], ["83998.8", "0"], ["84027.9", "0.001466"]], "u": 26658, "seq": 67550550842}, "cts": 1742556568317}}
{"exchange": "BITGET", "timestamp": 1742556568.46217, "message": {"action": "update", "arg": {"instType": "SPOT", "channel": "books", "instId": "BTCUSDT"}, "data": [{"asks": [["83945.96", "0.959876"], ["83978.59", "0"], ["83997.00", "0.464061"], ["83999.00", "1.221123"], ["84001.00", "3.213720"], ["84003.00", "8.457160"], ["84016.00", "0.510000"], ["84045.00", "5.535450"], ["84053.40", "5.081725"], ["84061.80", "4.083529"], ["84070.20", "5.444705"], ["84078.60", "5.172470"], ["84087.00", "3.902039"], ["84095.40", "5.626195"], ["84103.80", "4.990980"], ["84112.20", "4.627999"], ["84120.60", "4.718744"], ["84129.00", "4.900235"], ["84145.80", "3.992784"], ["84154.20", "4.265019"], ["84162.60", "4.537254"], ["84171.00", "4.809489"], ["84179.40", "4.446509"], ["84187.80", "5.353960"], ["84196.20", "4.174274"], ["84204.60", "5.263215"]], "bids": [["83945.27", "0.037213"], ["83893.00", "0"], ["83877.00", "3.992784"], ["83868.60", "5.444705"], ["83860.20", "4.083529"], ["83851.80", "5.535450"], ["83843.40", "5.353960"], ["83835.00", "5.263215"], ["83826.60", "4.718744"], ["83818.20", "4.900235"], ["83809.80", "4.537254"], ["83801.40", "4.265019"], ["83793.00", "4.446509"], ["83784.60", "5.172470"], ["83776.20", "4.990980"], ["83767.80", "4.809489"], ["83759.40", "4.355764"], ["83751.00", "5.081725"], ["83742.60", "5.626195"], ["83734.20", "4.627999"], ["83725.80", "3.902039"], ["83717.40", "4.174274"]], "checksum": 1825277163, "ts": "1742556568433"}], "ts": 1742556568436}}
{"exchange": "BYBIT", "timestamp": 1742556568.538353, "message": {"topic": "orderbook.200.BTCUSDT", "ts": 1742556568520, "type": "delta", "data": {"s": "BTCUSDT", "b": [["83960.1", "0.000153"], ["83890.2", "0"]], "a": [], "u": 26659, "seq": 67550550852}, "cts": 1742556568492}}
{"exchange": "BITGET", "timestamp": 1742556568.672785, "message": {"action": "update", "arg": {"instType": "SPOT", "channel": "books", "instId": "BTCUSDT"}, "data": [{"asks": [["83975.27", "0.119379"], ["84045.00", "5.081725"], ["84053.40", "5.535450"], ["84061.80", "4.446509"], ["84070.20", "4.265019"], ["84078.60", "3.992784"], ["84087.00", "4.990980"], ["84095.40", "4.537254"], ["84103.80", "5.444705"], ["84112.20", "4.900235"], ["84120.60", "5.263215"], ["84129.00", "5.353960"], ["84137.40", "4.718744"], ["84145.80", "4.355764"], ["84154.20", "4.083529"], ["84162.60", "3.902039"], ["84171.00", "4.627999"], ["84179.40", "4.809489"], ["84187.80", "5.626195"], ["84204.60", "5.172470"]], "bids": [["83893.00", "0.000015"], ["83868.60", "4.446509"], ["83860.20", "4.537254"], ["83851.80", "4.174274"], ["83843.40", "4.990980"], ["83835.00", "5.081725"], ["83826.60", "5.535450"], ["83818.20", "5.172470"], ["83809.80", "4.265019"], ["83801.40", "4.718744"], ["83793.00", "4.809489"], ["83784.60", "5.444705"], ["83776.20", "5.263215"], ["83767.80", "5.626195"], ["83759.40", "4.900235"], ["83751.00", "4.355764"], ["83742.60", "3.902039"], ["83725.80", "5.353960"], ["83717.40", "4.083529"], ["83640.15", "0"]], "checksum": 1825277163, "ts": "1742556568644"}], "ts": 1742556568647}}
{"exchange": "BITGET", "timestamp": 1742556568.874897, "message": {"action": "update", "arg": {"instType": "SPOT", "channel": "books", "instId": "BTCUSDT"}, "data": [{"asks": [["83945.96", "1.583046"], ["83980.94", "0.181321"], ["83985.00", "0.001255"], ["83987.00", "0.003302"], ["83989.00", "0.008690"], ["83991.00", "0.022868"], ["83995.00", "0.158367"], ["83997.00", "0.416757"], ["83999.00", "1.096481"], ["84000.99", "0.003719"], ["84001.00", "2.885476"], ["84003.00", "7.593357"], ["84003.30", "0.001050"], ["84006.60", "0.074250"], ["84045.00", "4.809489"], ["84053.40", "4.446509"], ["84061.80", "3.902039"], ["84070.20", "5.444705"], ["84078.60", "5.081725"], ["84087.00", "5.353960"], ["84095.40", "3.992784"], ["84103.80", "4.265019"], ["84112.20", "4.627999"], ["84120.60", "5.626195"], ["84129.00", "4.174274"], ["84137.40", "5.535450"], ["84145.80", "4.537254"], ["84162.60", "4.718744"], ["84171.00", "4.355764"], ["84179.40", "5.172470"], ["84187.80", "4.900235"], ["84196.20", "5.263215"], ["84204.60", "4.990980"], ["84522.06", "0"], ["84523.08", "0"]], "bids": [["83945.95", "0.219402"], ["83937.14", "0"], ["83918.90", "1.531080"], ["83877.00", "4.718744"], ["83868.60", "5.353960"], ["83860.20", "3.902039"], ["83851.80", "5.535450"], ["83843.40", "4.809489"], ["83826.60", "4.265019"], ["83818.20", "4.537254"], ["83809.80", "4.083529"], ["83801.40", "5.444705"], ["83793.00", "5.626195"], ["83784.60", "5.172470"], ["83776.20", "4.900235"], ["83767.80", "5.263215"], ["83759.40", "4.627999"], ["83751.00", "4.990980"], ["83742.60", "4.355764"], ["83734.20", "4.174274"], ["83725.80", "3.992784"], ["83717.40", "4.446509"], ["83640.15", "0.000423"]], "checksum": 1384643040, "ts": "1742556568844"}], "ts": 1742556568848}}
{"exchange": "BYBIT", "timestamp": 1742556568.986259, "message": {"topic": "orderbook.200.BTCUSDT", "ts": 1742556568920, "type": "delta", "data": {"s": "BTCUSDT", "b": [["83965.5", "0.279763"], ["83964.9", "0.071492"], ["83963.9", "0"], ["83947.9", "0"], ["83940.9", "0.000333"], ["83933.9", "0"], ["83901.5", "14.028077"], ["83898.7", "0"], ["83890.2", "0.00253"], ["83890", "0.0002"]], "a": [["83965.6", "0.594538"], ["83965.8", "0.035727"], ["83982.9", "0.000333"], ["83989.9", "0"], ["83996.9", "0"], ["84011.4", "0.032185"], ["84028", "0.00325"], ["84028.4", "0.001333"]], "u": 26660, "seq": 67550550919}, "cts": 1742556568915}}
{"exchange": "BITGET", "timestamp": 1742556569.098092, "message": {"action": "update", "arg": {"instType": "SPOT", "channel": "books", "instId": "BTCUSDT"}, "data": [{"asks": [["84016.00", "0"], ["84045.00", "4.900235"], ["84053.40", "3.902039"], ["84061.80", "4.990980"], ["84070.20", "5.172470"], ["84078.60", "5.535450"], ["84087.00", "4.174274"], ["84095.40", "4.627999"], ["84103.80", "5.081725"], ["84112.20", "4.809489"], ["84120.60", "4.537254"], ["84129.00", "4.718744"], ["84137.40", "5.263215"], ["84145.80", "4.083529"], ["84154.20", "4.265019"], ["84162.60", "5.626195"], ["84171.00", "5.353960"], ["84179.40", "3.992784"], ["84187.80", "4.446509"], ["84196.20", "5.444705"], ["84204.60", "4.355764"], ["84522.06", "0.000041"]], "bids": [["83945.27", "0"], ["83944.43", "0.047852"], ["83935.00", "0.002545"], ["83933.00", "0.006697"], ["83932.13", "0.057081"], ["83931.00", "0.017624"], ["83929.00", "0.046379"], ["83927.00", "0.122050"], ["83925.00", "0.321185"], ["83923.00", "0.845223"], ["83921.00", "2.224271"], ["83919.00", "5.853346"], ["83877.00", "4.990980"], ["83868.60", "4.809489"], ["83860.20", "5.081725"], ["83851.80", "4.355764"], ["83843.40", "5.535450"], ["83835.00", "3.992784"], ["83826.60", "4.718744"], ["83818.20", "5.263215"], ["83809.80", "4.537254"], ["83801.40", "4.265019"], ["83793.00", "4.446509"], ["83784.60", "5.444705"], ["83776.20", "3.902039"], ["83767.80", "5.172470"], ["83759.40", "4.900235"], ["83751.00", "4.174274"], ["83742.60", "5.626195"], ["83734.20", "4.083529"], ["83725.80", "4.627999"], ["83717.40", "5.353960"], ["83640.15", "0"]], "checksum": 322596237, "ts": "1742556569060"}], "ts": 1742556569066}}
{"exchange": "BYBIT", "timestamp": 1742556569.137578, "message": {"topic": "orderbook.200.BTCUSDT", "ts": 1742556569119, "type": "delta", "data": {"s": "BTCUSDT", "b": [["83901.5", "14.054106"]], "a": [], "u": 26661, "seq": 67550550950}, "cts": 1742556569078}}
{"exchange": "BITGET", "timestamp": 1742556569.296495, "message": {"action": "update", "arg": {"instType": "SPOT", "channel": "books", "instId": "BTCUSDT"}, "data": [{"asks": [["84045.00", "4.355764"], ["84053.40", "5.353960"], ["84061.80", "4.083529"], ["84070.20", "5.081725"], ["84078.60", "4.174274"], ["84087.00", "5.172470"], ["84095.40", "4.990980"], ["84103.80", "5.444705"], ["84112.20", "4.900235"], ["84120.60", "5.535450"], ["84137.40", "5.626195"], ["84145.80", "4.265019"], ["84154.20", "3.902039"], ["84162.60", "4.809489"], ["84171.00", "4.537254"], ["84179.40", "4.627999"], ["84187.80", "5.263215"], ["84196.20", "3.992784"], ["84204.60", "4.446509"]], "bids": [["83945.95", "0.010202"], ["83894.00", "0.000032"], ["83877.00", "3.902039"], ["83868.60", "3.992784"], ["83860.20", "4.174274"], ["83851.80", "5.081725"], ["83843.40", "5.172470"], ["83835.00", "4.537254"], ["83826.60", "4.446509"], ["83818.20", "5.353960"], ["83809.80", "4.627999"], ["83801.40", "4.900235"], ["83793.00", "5.535450"], ["83784.60", "4.809489"], ["83776.20", "4.990980"], ["83767.80", "4.265019"], ["83759.40", "4.718744"], ["83751.00", "4.083529"], ["83742.60", "5.263215"], ["83734.20", "5.444705"], ["83725.80", "5.626195"], ["83717.40", "4.355764"]], "checksum": 264075884, "ts": "1742556569267"}], "ts": 1742556569270}}
{"exchange": "BYBIT", "timestamp": 1742556569.337552, "message": {"topic": "orderbook.200.BTCUSDT", "ts": 1742556569319, "type": "delta", "data": {"s": "BTCUSDT", "b": [["83965.5", "0.28195"], ["83965", "0.029877"], ["83960.8", "0.003181"]], "a": [["83965.6", "0.600538"], ["83975.6", "0.146872"], ["83977.4", "0"], ["84028.5", "0.0012"]], "u": 26662, "seq": 67550551025}, "cts": 1742556569316}}
{"exchange": "BITGET", "timestamp": 1742556569.505436, "message": {"action": "update", "arg": {"instType": "SPOT", "channel": "books", "instId": "BTCUSDT"}, "data": [{"asks": [["83983.48", "0.010000"], ["84045.00", "4.809489"], ["84053.40", "3.992784"], ["84061.80", "4.627999"], ["84070.20", "4.990980"], ["84078.60", "4.083529"], ["84087.00", "5.626195"], ["84095.40", "5.263215"], ["84103.80", "4.900235"], ["84112.20", "4.265019"], ["84120.60", "5.172470"], ["84129.00", "4.355764"], ["84137.40", "4.537254"], ["84145.80", "5.353960"], ["84154.20", "4.718744"], ["84162.60", "5.535450"], ["84171.00", "5.444705"], ["84179.40", "4.174274"], ["84187.80", "4.446509"], ["84196.20", "5.081725"], ["84204.60", "3.902039"], ["84522.06", "0"]], "bids": [["83945.95", "0.219402"], ["83945.43", "0.047852"], ["83944.43", "0"], ["83925.00", "0.321365"], ["83923.00", "0.845696"], ["83921.00", "2.225515"], ["83919.00", "5.856619"], ["83918.90", "1.542120"], ["83894.00", "0.000017"], ["83877.00", "5.626195"], ["83868.60", "3.902039"], ["83860.20", "5.172470"], ["83851.80", "5.353960"], ["83843.40", "4.446509"], ["83835.00", "5.444705"], ["83826.60", "5.263215"], ["83818.20", "4.174274"], ["83809.80", "4.990980"], ["83801.40", "4.265019"], ["83793.00", "4.809489"], ["83784.60", "4.900235"], ["83776.20", "4.537254"], ["83767.80", "3.992784"], ["83759.40", "5.535450"], ["83751.00", "5.081725"], ["83742.60", "4.718744"], ["83734.20", "4.627999"], ["83725.80", "4.355764"], ["83717.40", "4.083529"]], "checksum": 804594113, "ts": "1742556569476"}], "ts": 1742556569479}}
{"exchange": "BYBIT", "timestamp": 1742556569.537441, "message": {"topic": "orderbook.200.BTCUSDT", "ts": 1742556569520, "type": "delta", "data": {"s": "BTCUSDT", "b": [["83964.9", "0"], ["83963.7", "0.071493"], ["83959.2", "0.001779"], ["83958.2", "0"], ["83924.9", "0.013"], ["83924.8", "0.012882"], ["83890", "0"]], "a": [["83997.9", "0.013"], ["83998", "0.072278"], ["84028.5", "0"]], "u": 26663, "seq": 67550551096}, "cts": 1742556569488}}
{"exchange": "BITGET", "timestamp": 1742556569.721419, "message": {"action": "update", "arg": {"instType": "SPOT", "channel": "books", "instId": "BTCUSDT"}, "data": [{"asks": [["84045.00", "4.537254"], ["84053.40", "4.446509"], ["84061.80", "5.263215"], ["84070.20", "5.535450"], ["84078.60", "5.353960"], ["84087.00", "4.627999"], ["84095.40", "4.355764"], ["84103.80", "5.444705"], ["84112.20", "5.172470"], ["84120.60", "4.718744"], ["84129.00", "5.081725"], ["84137.40", "3.902039"], ["84145.80", "3.992784"], ["84154.20", "4.083529"], ["84162.60", "4.174274"], ["84171.00", "4.900235"], ["84179.40", "4.809489"], ["84187.80", "5.626195"], ["84196.20", "4.990980"], ["84204.60", "4.265019"]], "bids": [["83914.80", "0.015000"], ["83877.00", "4.083529"], ["83868.60", "4.718744"], ["83860.20", "4.537254"], ["83851.80", "4.627999"], ["83843.40", "4.174274"], ["83835.00", "5.626195"], ["83826.60", "5.172470"], ["83818.20", "4.355764"], ["83809.80", "5.081725"], ["83801.40", "3.902039"], ["83793.00", "5.535450"], ["83776.20", "5.263215"], ["83767.80", "4.265019"], ["83759.40", "3.992784"], ["83751.00", "4.990980"], ["83742.60", "4.446509"], ["83734.20", "4.809489"], ["83725.80", "5.353960"], ["83717.40", "5.444705"]], "checksum": 804594113, "ts": "1742556569691"}], "ts": 1742556569694}}
{"exchange": "BYBIT", "timestamp": 1742556569.738698, "message": {"topic": "orderbook.200.BTCUSDT", "ts": 1742556569719, "type": "delta", "data": {"s": "BTCUSDT", "b": [["83901.5", "0"], ["83890.7", "0"], ["83890.1", "0.353814"], ["83890", "0.0002"]], "a": [], "u": 26664, "seq": 67550551138}, "cts": 1742556569717}}
{"exchange": "BITGET", "timestamp": 1742556569.922706, "message": {"action": "update", "arg": {"instType": "SPOT", "channel": "books", "instId": "BTCUSDT"}, "data": [{"asks": [["83985.00", "0.001393"], ["83987.00", "0.003665"], ["83989.00", "0.009647"], ["83991.00", "0.025385"], ["83995.00", "0.175798"], ["83997.00", "0.462625"], ["83999.00", "1.217435"], ["84001.00", "3.203776"], ["84003.00", "8.430989"], ["84045.00", "4.990980"], ["84053.40", "5.172470"], ["84061.80", "4.083529"], ["84070.20", "5.444705"], ["84078.60", "4.627999"], ["84087.00", "4.718744"], ["84095.40", "5.626195"], ["84103.80", "4.900235"], ["84112.20", "4.265019"], ["84120.60", "4.809489"], ["84137.40", "4.174274"], ["84145.80", "5.263215"], ["84154.20", "5.535450"], ["84162.60", "5.353960"], ["84171.00", "3.902039"], ["84179.40", "4.446509"], ["84187.80", "4.537254"], ["84196.20", "3.992784"], ["84204.60", "4.355764"]], "bids": [["83945.95", "0.005242"], ["83945.43", "0"], ["83935.00", "0.002349"], ["83933.00", "0.006183"], ["83932.13", "0"], ["83931.00", "0.016271"], ["83929.00", "0.042817"], ["83927.00", "0.112676"], ["83925.00", "0.296516"], ["83923.00", "0.780306"], ["83921.00", "2.053438"], ["83919.00", "5.403784"], ["83895.00", "0.000924"], ["83877.00", "5.081725"], ["83868.60", "5.263215"], ["83860.20", "5.353960"], ["83851.80", "4.809489"], ["83843.40", "4.718744"], ["83835.00", "5.535450"], ["83826.60", "4.174274"], ["83818.20", "5.444705"], ["83809.80", "4.083529"], ["83801.40", "4.627999"], ["83793.00", "4.355764"], ["83784.60", "3.902039"], ["83776.20", "4.900235"], ["83759.40", "5.626195"], ["83742.60", "4.537254"], ["83734.20", "3.992784"], ["83725.80", "5.172470"], ["83717.40", "4.446509"], ["83640.15", "0.000423"], ["83640.00", "0.002013"]], "checksum": 1329820992, "ts": "1742556569891"}], "ts": 1742556569895}}
{"exchange": "BYBIT", "timestamp": 1742556569.936894, "message": {"topic": "orderbook.200.BTCUSDT", "ts": 1742556569920, "type": "delta", "data": {"s": "BTCUSDT", "b": [["83965.5", "0.11095"], ["83965", "0.003181"], ["83953.8", "0.198288"], ["83951.4", "0.121172"], ["83951.1", "0.120101"], ["83947.3", "0.124415"], ["83941.3", "0.179486"], ["83940.9", "0.166933"], ["83940.3", "0.167874"], ["83933.9", "0.277966"], ["83933.3", "0.299021"], ["83932.2", "0.272508"], ["83898.7", "13.934734"], ["83891.3", "0"], ["83891.2", "0"], ["83890.9", "0"], ["83890.6", "0"], ["83890.5", "0"], ["83890.3", "0"], ["83890.2", "0"], ["83890.1", "0"], ["83890", "0"]], "a": [["83965.8", "0.108549"], ["83975.9", "0.112439"], ["83976.3", "0.119424"], ["83980.2", "0.113672"], ["83986.1", "0.221418"], ["83986.4", "0.18886"], ["83987.2", "0.171404"], ["83993.4", "0.368288"], ["83994.2", "0.309771"], ["83995.2", "0.28479"], ["84027.7", "0"], ["84027.8", "0"], ["84027.9", "0"], ["84028", "0"], ["84028.4", "0"]], "u": 26665, "seq": 67550551202}, "cts": 1742556569904}}
{"exchange": "BITGET", "timestamp": 1742556570.125565, "message": {"action": "update", "arg": {"instType": "SPOT", "channel": "books", "instId": "BTCUSDT"}, "data": [{"asks": [["83945.96", "0.925515"], ["83996.99", "0.131052"], ["83999.00", "1.217679"], ["84001.00", "3.204419"], ["84003.00", "8.432682"], ["84016.00", "0.510000"], ["84045.00", "3.902039"], ["84053.40", "4.446509"], ["84061.80", "4.627999"], ["84070.20", "5.353960"], ["84078.60", "4.174274"], ["84087.00", "4.083529"], ["84103.80", "4.718744"], ["84112.20", "5.081725"], ["84120.60", "4.537254"], ["84129.00", "4.355764"], ["84137.40", "4.809489"], ["84145.80", "4.900235"], ["84162.60", "5.172470"], ["84171.00", "3.992784"], ["84179.40", "5.444705"], ["84187.80", "4.265019"], ["84196.20", "4.990980"], ["84204.60", "5.263215"], ["84521.85", "0"]], "bids": [["83942.79", "0.047852"], ["83935.00", "0.001986"], ["83933.00", "0.005225"], ["83931.00", "0.013750"], ["83929.00", "0.036185"], ["83927.00", "0.095223"], ["83925.00", "0.250589"], ["83923.00", "0.659443"], ["83921.00", "1.735378"], ["83919.00", "4.566784"], ["83914.80", "0"], ["83908.20", "0.600000"], ["83877.00", "3.992784"], ["83868.60", "5.626195"], ["83851.80", "4.537254"], ["83843.40", "4.083529"], ["83835.00", "5.263215"], ["83818.20", "4.809489"], ["83809.80", "4.355764"], ["83801.40", "4.446509"], ["83793.00", "4.718744"], ["83784.60", "5.172470"], ["83776.20", "4.265019"], ["83767.80", "4.990980"], ["83759.40", "3.902039"], ["83751.00", "4.627999"], ["83742.60", "4.900235"], ["83734.20", "5.535450"], ["83725.80", "5.444705"], ["83717.40", "5.081725"]], "checksum": 565243436, "ts": "1742556570096"}], "ts": 1742556570099}}
{"exchange": "BYBIT", "timestamp": 1742556570.138101, "message": {"topic": "orderbook.200.BTCUSDT", "ts": 1742556570119, "type": "delta", "data": {"s": "BTCUSDT", "b": [["83965.5", "0.28195"], ["83953.8", "0.141855"], ["83951.4", "0"], ["83951.1", "0"], ["83949.5", "0.092774"], ["83947.3", "0"], ["83945.3", "0.132673"], ["83941.3", "0"], ["83940.9", "0.000333"], ["83940.3", "0"], ["83936.8", "0.366761"], ["83933.9", "0"], ["83933.3", "0"], ["83932.2", "0"], ["83891.3", "0.009"], ["83891.2", "0.04"], ["83890.9", "0.00625"], ["83890.6", "0.000333"], ["83890.5", "3.246386"], ["83890.3", "0.011992"], ["83890.2", "0.00253"], ["83890.1", "0.353814"]], "a": [["83975.9", "0"], ["83976.3", "0.000514"], ["83980.2", "0"], ["83986.1", "0.052"], ["83986.4", "0.001333"], ["83987.2", "0"], ["83993.3", "0.38079"], ["83993.4", "0.079535"], ["83994.2", "0"], ["83995.2", "0"], ["84027.7", "0.027532"], ["84027.8", "0.059399"], ["84027.9", "0.001466"], ["84028", "0.00325"], ["84028.4", "0.001333"]], "u": 26666, "seq": 67550551249}, "cts": 1742556570093}}
{"exchange": "BITGET", "timestamp": 1742556570.32681, "message": {"action": "update", "arg": {"instType": "SPOT", "channel": "books", "instId": "BTCUSDT"}, "data": [{"asks": [["83945.96", "1.128685"], ["84001.00", "3.204299"], ["84003.00", "8.432366"], ["84044.99", "0.228211"], ["84045.00", "4.809489"], ["84053.40", "5.535450"], ["84061.80", "4.446509"], ["84078.60", "3.902039"], ["84087.00", "5.263215"], ["84095.40", "4.265019"], ["84103.80", "4.990980"], ["84112.20", "5.444705"], ["84120.60", "5.081725"], ["84129.00", "4.083529"], ["84137.40", "4.537254"], ["84145.80", "3.992784"], ["84154.20", "4.174274"], ["84162.60", "4.718744"], ["84171.00", "5.626195"], ["84179.40", "4.627999"], ["84187.80", "4.900235"], ["84196.20", "5.172470"], ["84204.60", "4.355764"], ["84520.67", "0"]], "bids": [["83944.93", "0.047852"], ["83942.79", "0"], ["83935.00", "0.002349"], ["83933.00", "0.006183"], ["83931.00", "0.016270"], ["83929.00", "0.042816"], ["83927.00", "0.112673"], ["83925.00", "0.296508"], ["83923.00", "0.780285"], ["83921.00", "2.053381"], ["83919.00", "5.403635"], ["83895.00", "0.000939"], ["83877.00", "5.263215"], ["83868.60", "5.535450"], ["83860.20", "4.537254"], ["83851.80", "4.900235"], ["83843.40", "5.353960"], ["83835.00", "5.172470"], ["83826.60", "4.627999"], ["83818.20", "4.990980"], ["83809.80", "3.902039"], ["83801.40", "3.992784"], ["83793.00", "4.174274"], ["83784.60", "5.081725"], ["83767.80", "5.444705"], ["83759.40", "4.446509"], ["83751.00", "4.718744"], ["83742.60", "4.355764"], ["83734.20", "5.626195"], ["83725.80", "4.083529"], ["83717.40", "4.809489"]], "checksum": 389341836, "ts": "1742556570297"}], "ts": 1742556570301}}
{"exchange": "BYBIT", "timestamp": 1742556570.337625, "message": {"topic": "orderbook.200.BTCUSDT", "ts": 1742556570320, "type": "delta", "data": {"s": "BTCUSDT", "b": [["83965.5", "0.279763"], ["83949.5", "0.061348"], ["83945.3", "0.084198"], ["83936.8", "0.059399"]], "a": [["83965.6", "0.602681"], ["83993.3", "0.132338"], ["84011.4", "0.030042"]], "u": 26667, "seq": 67550551281}, "cts": 1742556570303}}
{"exchange": "BITGET", "timestamp": 1742556570.532156, "message": {"action": "update", "arg": {"instType": "SPOT", "channel": "books", "instId": "BTCUSDT"}, "data": [{"asks": [["83966.32", "0.035952"], ["83966.44", "0"], ["83966.74", "0.119870"], ["83966.84", "0"], ["83968.00", "0.035961"], ["83968.11", "0"], ["83968.43", "0.006356"], ["83968.53", "0"], ["83968.60", "0.006356"], ["83968.69", "0"], ["83968.91", "0.006356"], ["83969.02", "0"], ["83970.01", "0.010984"], ["83970.14", "0"], ["83970.26", "0.006356"], ["83970.35", "0"], ["83970.42", "0.006356"], ["83970.55", "0"], ["83970.93", "0.022785"], ["83971.05", "0"], ["83971.43", "0.012712"], ["83971.53", "0"], ["83971.76", "0.119883"], ["83971.78", "0.016429"], ["83971.88", "0"], ["83971.89", "0"], ["83971.94", "0.006356"], ["83971.96", "0.006356"], ["83972.04", "0"], ["83972.06", "0"], ["83973.46", "0.017342"], ["83973.57", "0"], ["83973.58", "0"], ["83974.31", "0.009990"], ["83974.40", "0"], ["83975.19", "0.119850"], ["83975.28", "0"], ["83976.20", "0.119858"], ["83976.29", "0"], ["83976.38", "0.119867"], ["83976.48", "0"], ["83976.62", "0.015895"], ["83976.71", "0"], ["83980.56", "0.015892"], ["83980.66", "0"], ["83981.43", "0.010988"], ["83981.53", "0"], ["83999.00", "1.217389"], ["84001.00", "3.203656"], ["84003.00", "8.430673"], ["84006.70", "0.120000"], ["84016.00", "0"], ["84045.00", "4.990980"], ["84053.40", "4.627999"], ["84061.80", "4.355764"], ["84070.20", "4.900235"], ["84078.60", "5.263215"], ["84087.00", "4.446509"], ["84095.40", "3.992784"], ["84103.80", "5.626195"], ["84120.60", "4.083529"], ["84129.00", "5.353960"], ["84137.40", "4.809489"], ["84145.80", "5.535450"], ["84154.20", "4.718744"], ["84162.60", "5.081725"], ["84171.00", "5.172470"], ["84179.40", "4.174274"], ["84187.80", "4.265019"], ["84196.20", "3.902039"], ["84204.60", "4.537254"], ["84520.67", "0.002384"]], "bids": [["83926.15", "0"], ["83926.02", "0.089610"], ["83925.70", "0"], ["83925.60", "0.247933"], ["83925.00", "0.296329"], ["83924.45", "0"], ["83924.35", "0.084057"], ["83924.04", "0"], ["83923.94", "0.017842"], ["83923.87", "0"], ["83923.77", "0.018280"], ["83923.55", "0"], ["83923.52", "0"], ["83923.48", "0.004023"], ["83923.41", "0.005954"], ["83923.00", "0.779812"], ["83922.46", "0"], ["83922.33", "0.055734"], ["83922.16", "0"], ["83922.07", "0.017127"], ["83922.03", "0"], ["83921.90", "0.007141"], ["83921.53", "0"], ["83921.52", "0"], ["83921.40", "0.036255"], ["83921.00", "2.052137"], ["83920.99", "0"], ["83920.90", "0.007954"], ["83920.89", "0.009007"], ["83920.68", "0"], ["83920.67", "0"], ["83920.57", "0.025220"], ["83920.56", "0.225197"], ["83920.51", "0"], ["83920.50", "0"], ["83920.41", "0.017375"], ["83920.40", "0.008196"], ["83919.01", "0"], ["83919.00", "5.400361"], ["83918.15", "0"], ["83918.06", "0.018543"], ["83917.19", "0"], ["83917.10", "0.268752"], ["83916.19", "0"], ["83916.09", "0.222981"], ["83916.04", "0"], ["83915.94", "0.260159"], ["83915.77", "0.209200"], ["83915.67", "0.076219"], ["83911.82", "0"], ["83911.73", "0.073317"], ["83911.01", "0"], ["83910.92", "0.056446"], ["83909.35", "0"], ["83909.23", "0.000878"], ["83893.00", "0.000032"], ["83890.89", "0"], ["83890.77", "0.003602"], ["83877.00", "5.535450"], ["83868.60", "5.626195"], ["83860.20", "4.718744"], ["83851.80", "4.809489"], ["83843.40", "5.081725"], ["83835.00", "5.353960"], ["83826.60", "4.355764"], ["83818.20", "4.627999"], ["83809.80", "3.992784"], ["83801.40", "5.444705"], ["83793.00", "4.900235"], ["83784.60", "4.174274"], ["83776.20", "4.537254"], ["83767.80", "4.083529"], ["83759.40", "4.265019"], ["83751.00", "4.446509"], ["83742.60", "4.990980"], ["83734.20", "5.172470"], ["83725.80", "5.263215"], ["83717.40", "3.902039"]], "checksum": -1116758755, "ts": "1742556570500"}], "ts": 1742556570504}}
{"exchange": "BITGET", "timestamp": 1742556570.730755, "message": {"action": "update", "arg": {"instType": "SPOT", "channel": "books", "instId": "BTCUSDT"}, "data": [{"asks": [["83945.96", "0.925515"], ["83966.31", "0.010786"], ["83966.83", "0"], ["83975.27", "0"], ["83980.94", "0"], ["83999.00", "1.217637"], ["84001.00", "3.204306"], ["84003.00", "8.432384"], ["84013.80", "0.252210"], ["84015.90", "0"], ["84045.00", "4.355764"], ["84053.40", "4.718744"], ["84061.80", "4.809489"], ["84070.20", "4.446509"], ["84078.60", "4.990980"], ["84087.00", "4.900235"], ["84095.40", "5.172470"], ["84103.80", "5.444705"], ["84112.20", "4.265019"], ["84120.60", "4.537254"], ["84129.00", "4.174274"], ["84137.40", "5.535450"], ["84145.80", "5.081725"], ["84154.20", "5.626195"], ["84162.60", "5.263215"], ["84171.00", "5.353960"], ["84179.40", "3.902039"], ["84187.80", "4.083529"], ["84196.20", "3.992784"], ["84204.60", "4.627999"], ["84521.85", "0.000033"], ["84522.06", "0.000041"], ["84523.08", "0.000015"]], "bids": [["83925.00", "0.296533"], ["83923.00", "0.780349"], ["83921.00", "2.053551"], ["83919.00", "5.404081"], ["83877.00", "5.263215"], ["83868.60", "4.718744"], ["83860.20", "3.992784"], ["83851.80", "4.537254"], ["83843.40", "5.626195"], ["83835.00", "5.535450"], ["83826.60", "4.174274"], ["83818.20", "5.172470"], ["83809.80", "4.265019"], ["83793.00", "5.081725"], ["83784.60", "4.083529"], ["83776.20", "3.902039"], ["83767.80", "4.446509"], ["83759.40", "5.353960"], ["83751.00", "4.627999"], ["83742.60", "4.355764"], ["83734.20", "4.809489"], ["83725.80", "4.990980"], ["83717.40", "4.900235"]], "checksum": 481040439, "ts": "1742556570701"}], "ts": 1742556570705}}
{"exchange": "BITGET", "timestamp": 1742556570.937906, "message": {"action": "update", "arg": {"instType": "SPOT", "channel": "books", "instId": "BTCUSDT"}, "data": [{"asks": [["83945.96", "1.548685"], ["83954.86", "0.314503"], ["83955.51", "0"], ["83966.73", "0.060340"], ["83999.00", "1.217389"], ["84001.00", "3.203656"], ["84003.00", "8.430673"], ["84003.35", "0.001597"], ["84003.50", "0"], ["84014.80", "0"], ["84045.00", "4.900235"], ["84053.40", "3.902039"], ["84061.80", "4.446509"], ["84070.20", "5.535450"], ["84087.00", "5.172470"], ["84095.40", "5.263215"], ["84103.80", "4.355764"], ["84112.20", "4.083529"], ["84120.60", "4.718744"], ["84129.00", "4.537254"], ["84137.40", "3.992784"], ["84154.20", "4.809489"], ["84162.60", "5.353960"], ["84171.00", "5.444705"], ["84179.40", "4.627999"], ["84187.80", "4.174274"], ["84196.20", "4.265019"], ["84204.60", "5.626195"]], "bids": [["83944.93", "0"], ["83943.82", "0.047852"], ["83936.21", "0.010000"], ["83935.00", "0.001851"], ["83933.00", "0.004872"], ["83931.00", "0.012820"], ["83929.00", "0.033738"], ["83927.00", "0.088785"], ["83925.00", "0.233645"], ["83923.00", "0.614853"], ["83921.00", "1.618035"], ["83919.00", "4.257986"], ["83916.80", "0.057600"], ["83916.10", "0.012000"], ["83908.20", "0"], ["83889.50", "0"], ["83889.35", "0.001174"], ["83877.00", "5.444705"], ["83868.60", "4.900235"], ["83860.20", "4.627999"], ["83851.80", "5.263215"], ["83826.60", "5.081725"], ["83818.20", "4.718744"], ["83801.40", "4.446509"], ["83793.00", "4.083529"], ["83784.60", "5.172470"], ["83776.20", "4.537254"], ["83767.80", "3.902039"], ["83751.00", "4.355764"], ["83742.60", "4.990980"], ["83725.80", "4.174274"], ["83717.40", "3.992784"], ["83640.15", "0"], ["83640.00", "0"]], "checksum": 2012071814, "ts": "1742556570908"}], "ts": 1742556570911}}
{"exchange": "BYBIT", "timestamp": 1742556570.938103, "message": {"topic": "orderbook.200.BTCUSDT", "ts": 1742556570920, "type": "delta", "data": {"s": "BTCUSDT", "b": [["83965.5", "0.118858"], ["83960.1", "0"], ["83943", "0"], ["83890", "0.0002"], ["83889.9", "0.011992"]], "a": [["83965.6", "0.773681"], ["83997.9", "0.012743"]], "u": 26668, "seq": 67550551338}, "cts": 1742556570906}}
{"exchange": "BYBIT", "timestamp": 1742556571.137464, "message": {"topic": "orderbook.200.BTCUSDT", "ts": 1742556571119, "type": "delta", "data": {"s": "BTCUSDT", "b": [["83965.5", "0.289858"], ["83964.7", "0.071492"], ["83963.7", "0"], ["83959.1", "0.082872"], ["83957.6", "0"], ["83947.9", "0.061515"], ["83945.3", "0.053711"], ["83940.9", "0.059867"], ["83934.2", "0"], ["83933.9", "0.109739"], ["83924.9", "0.012882"]], "a": [["83965.6", "0.602681"], ["83982.9", "0.05946"], ["83989.9", "0.059088"], ["83996.9", "0.10956"], ["83997.9", "0"], ["83998.1", "0.012743"], ["83998.6", "0.003247"], ["83998.8", "0.04"], ["84027.9", "0"], ["84028", "0"], ["84028.4", "0"]], "u": 26669, "seq": 67550551376}, "cts": 1742556571117}}
{"exchange": "BITGET", "timestamp": 1742556571.139991, "message": {"action": "update", "arg": {"instType": "SPOT", "channel": "books", "instId": "BTCUSDT"}, "data": [{"asks": [["83945.96", "0.925515"], ["83954.85", "0.094351"], ["83955.50", "0"], ["83976.80", "0.009989"], ["83976.90", "0"], ["83980.93", "0.179633"], ["83999.00", "1.217637"], ["84001.00", "3.204306"], ["84001.43", "0.001598"], ["84001.57", "0"], ["84003.00", "8.432384"], ["84003.30", "0.058590"], ["84006.60", "0.074040"], ["84009.90", "0"], ["84010.80", "0"], ["84011.60", "0"], ["84012.40", "0"], ["84014.80", "1.055730"], ["84015.90", "0.120000"], ["84016.00", "0.756330"], ["84016.10", "0.534660"], ["84045.00", "5.172470"], ["84053.40", "4.355764"], ["84061.80", "4.083529"], ["84070.20", "4.809489"], ["84078.60", "4.900235"], ["84087.00", "4.990980"], ["84095.40", "3.992784"], ["84103.80", "4.265019"], ["84112.20", "4.718744"], ["84120.60", "4.627999"], ["84129.00", "5.535450"], ["84137.40", "5.626195"], ["84145.80", "4.174274"], ["84154.20", "5.444705"], ["84162.60", "4.446509"], ["84171.00", "3.902039"], ["84179.40", "5.081725"], ["84187.80", "4.537254"], ["84196.20", "5.353960"], ["84204.60", "5.263215"], ["84523.08", "0"]], "bids": [["83943.82", "0"], ["83932.12", "0"], ["83915.62", "0"], ["83915.52", "0.021159"], ["83893.00", "0.000017"], ["83891.43", "0"], ["83891.30", "0.001177"], ["83877.00", "4.174274"], ["83860.20", "3.992784"], ["83851.80", "4.627999"], ["83843.40", "5.172470"], ["83835.00", "4.718744"], ["83826.60", "4.990980"], ["83818.20", "5.263215"], ["83809.80", "5.626195"], ["83801.40", "5.444705"], ["83793.00", "5.353960"], ["83784.60", "4.265019"], ["83776.20", "4.446509"], ["83767.80", "4.355764"], ["83759.40", "5.535450"], ["83751.00", "3.902039"], ["83742.60", "4.083529"], ["83734.20", "5.081725"], ["83725.80", "4.809489"], ["83717.40", "4.537254"], ["83640.15", "0.000423"], ["83640.00", "0.002013"]], "checksum": 1037298151, "ts": "1742556571110"}], "ts": 1742556571114}}
{"exchange": "BYBIT", "timestamp": 1742556571.337669, "message": {"topic": "orderbook.200.BTCUSDT", "ts": 1742556571320, "type": "delta", "data": {"s": "BTCUSDT", "b": [["83965.5", "0.28959"], ["83964.2", "0.009175"], ["83959.2", "0.02708"], ["83947.9", "0"], ["83940.9", "0.000333"], ["83934.1", "0.111968"], ["83933.9", "0"], ["83901.4", "13.771465"], ["83898.7", "0"], ["83889.8", "0.001333"]], "a": [["83965.6", "0.600538"], ["83982.9", "0.000333"], ["83989.9", "0"], ["83996.9", "0"], ["83997.9", "0.013"], ["83998.1", "0"], ["83998.6", "0.043247"], ["83998.8", "0"], ["84009.7", "0.002143"], ["84027.9", "0.001466"], ["84028", "0.00325"]], "u": 26670, "seq": 67550551426}, "cts": 1742556571317}}
{"exchange": "BITGET", "timestamp": 1742556571.365041, "message": {"action": "update", "arg": {"instType": "SPOT", "channel": "books", "instId": "BTCUSDT"}, "data": [{"asks": [["83945.96", "1.128685"], ["83985.00", "0.001255"], ["83987.00", "0.003302"], ["83989.00", "0.008691"], ["83991.00", "0.022869"], ["83995.00", "0.158374"], ["83997.00", "0.416774"], ["83999.00", "1.096526"], ["84000.99", "0.403277"], ["84001.00", "2.885596"], ["84003.00", "7.593673"], ["84008.40", "0.462150"], ["84044.99", "0"], ["84045.00", "4.718744"], ["84061.80", "3.992784"], ["84070.20", "4.990980"], ["84078.60", "4.265019"], ["84087.00", "3.902039"], ["84095.40", "4.537254"], ["84103.80", "5.172470"], ["84112.20", "4.083529"], ["84129.00", "4.446509"], ["84137.40", "5.444705"], ["84145.80", "5.263215"], ["84154.20", "5.353960"], ["84162.60", "5.535450"], ["84171.00", "4.900235"], ["84187.80", "5.626195"], ["84196.20", "4.809489"], ["84204.60", "4.174274"], ["84523.08", "0.000015"]], "bids": [["83945.61", "0.047852"], ["83935.00", "0.002697"], ["83933.00", "0.007098"], ["83931.77", "0.111968"], ["83931.00", "0.018678"], ["83929.00", "0.049154"], ["83927.00", "0.129352"], ["83925.00", "0.340400"], ["83923.00", "0.895790"], ["83921.00", "2.357340"], ["83919.00", "6.203528"], ["83916.80", "0"], ["83908.20", "0.120000"], ["83894.00", "0"], ["83877.00", "4.537254"], ["83868.60", "4.355764"], ["83860.20", "4.446509"], ["83851.80", "5.626195"], ["83843.40", "4.809489"], ["83835.00", "4.627999"], ["83826.60", "5.081725"], ["83818.20", "3.992784"], ["83809.80", "5.444705"], ["83801.40", "4.900235"], ["83793.00", "4.083529"], ["83784.60", "4.174274"], ["83776.20", "5.535450"], ["83767.80", "4.990980"], ["83759.40", "4.718744"], ["83751.00", "5.353960"], ["83742.60", "4.265019"], ["83734.20", "3.902039"], ["83725.80", "5.172470"], ["83717.40", "5.263215"], ["83640.00", "0"]], "checksum": 1748203816, "ts": "1742556571332"}], "ts": 1742556571336}}
{"exchange": "BYBIT", "timestamp": 1742556571.537618, "message": {"topic": "orderbook.200.BTCUSDT", "ts": 1742556571519, "type": "delta", "data": {"s": "BTCUSDT", "b": [["83936.8", "0.210875"], ["83901.5", "13.771465"], ["83901.4", "0"]], "a": [["83997.9", "0"], ["83998.1", "0.012743"], ["83998.6", "0.003247"], ["83998.8", "0.04"], ["84028", "0"]], "u": 26671, "seq": 67550551446}, "cts": 1742556571484}}
{"exchange": "BITGET", "timestamp": 1742556571.561702, "message": {"action": "update", "arg": {"instType": "SPOT", "channel": "books", "instId": "BTCUSDT"}, "data": [{"asks": [["83945.96", "0.925515"], ["83987.00", "0.003170"], ["83989.00", "0.008343"], ["83991.00", "0.021954"], ["83995.00", "0.152039"], ["83997.00", "0.400102"], ["83999.00", "1.052900"], ["84001.00", "2.770791"], ["84003.00", "7.291553"], ["84016.10", "0"], ["84045.00", "4.537254"], ["84053.40", "4.900235"], ["84061.80", "4.083529"], ["84070.20", "5.444705"], ["84078.60", "4.627999"], ["84087.00", "5.626195"], ["84095.40", "3.992784"], ["84103.80", "5.081725"], ["84112.20", "5.535450"], ["84120.60", "4.446509"], ["84129.00", "4.355764"], ["84137.40", "5.172470"], ["84145.80", "5.353960"], ["84154.20", "4.265019"], ["84162.60", "4.809489"], ["84171.00", "4.990980"], ["84179.40", "4.174274"], ["84187.80", "4.718744"], ["84196.20", "3.902039"], ["84204.60", "5.263215"], ["84523.48", "0.000015"]], "bids": [["83945.61", "0"], ["83944.79", "0.047852"], ["83935.00", "0.002086"], ["83933.00", "0.005489"], ["83931.00", "0.014447"], ["83929.00", "0.038018"], ["83927.00", "0.100046"], ["83925.00", "0.263280"], ["83923.00", "0.692842"], ["83921.00", "1.823268"], ["83919.00", "4.798075"], ["83916.10", "0"], ["83908.20", "0.600000"], ["83868.60", "4.174274"], ["83860.20", "3.902039"], ["83843.40", "4.265019"], ["83835.00", "3.992784"], ["83826.60", "5.263215"], ["83818.20", "5.353960"], ["83809.80", "5.081725"], ["83801.40", "4.446509"], ["83793.00", "4.809489"], ["83784.60", "5.444705"], ["83776.20", "4.900235"], ["83767.80", "5.172470"], ["83751.00", "4.083529"], ["83742.60", "5.535450"], ["83734.20", "4.355764"], ["83725.80", "4.990980"], ["83717.40", "4.627999"], ["83640.00", "0.002013"]], "checksum": 895330777, "ts": "1742556571532"}], "ts": 1742556571536}}
{"exchange": "BYBIT", "timestamp": 1742556571.739118, "message": {"topic": "orderbook.200.BTCUSDT", "ts": 1742556571720, "type": "delta", "data": {"s": "BTCUSDT", "b": [["83960.3", "0.000153"], ["83901.5", "13.467332"], ["83889.8", "0"]], "a": [], "u": 26672, "seq": 67550551472}, "cts": 1742556571652}}
{"exchange": "BITGET", "timestamp": 1742556571.769129, "message": {"action": "update", "arg": {"instType": "SPOT", "channel": "books", "instId": "BTCUSDT"}, "data": [{"asks": [["84045.00", "4.718744"], ["84053.40", "3.902039"], ["84061.80", "5.535450"], ["84070.20", "5.353960"], ["84078.60", "4.265019"], ["84087.00", "4.446509"], ["84095.40", "5.626195"], ["84103.80", "3.992784"], ["84112.20", "5.444705"], ["84120.60", "4.537254"], ["84129.00", "5.081725"], ["84137.40", "4.990980"], ["84145.80", "4.900235"], ["84154.20", "4.809489"], ["84162.60", "4.083529"], ["84171.00", "4.174274"], ["84179.40", "4.627999"], ["84187.80", "4.355764"], ["84196.20", "5.263215"], ["84204.60", "5.172470"]], "bids": [["83945.65", "0.047852"], ["83944.79", "0"], ["83935.00", "0.002211"], ["83933.00", "0.005819"], ["83931.00", "0.015313"], ["83929.00", "0.040298"], ["83927.00", "0.106046"], ["83925.00", "0.279068"], ["83923.00", "0.734389"], ["83921.00", "1.932603"], ["83919.00", "5.085798"], ["83877.00", "5.444705"], ["83868.60", "4.355764"], ["83860.20", "4.990980"], ["83851.80", "5.535450"], ["83843.40", "4.174274"], ["83835.00", "4.537254"], ["83826.60", "4.446509"], ["83818.20", "5.081725"], ["83809.80", "5.263215"], ["83801.40", "4.809489"], ["83793.00", "4.083529"], ["83784.60", "3.992784"], ["83776.20", "5.172470"], ["83767.80", "4.627999"], ["83759.40", "5.353960"], ["83751.00", "4.718744"], ["83742.60", "4.265019"], ["83734.20", "3.902039"], ["83725.80", "5.626195"], ["83717.40", "4.900235"]], "checksum": -367826325, "ts": "1742556571737"}], "ts": 1742556571740}}
{"exchange": "BYBIT", "timestamp": 1742556571.936837, "message": {"topic": "orderbook.200.BTCUSDT", "ts": 1742556571919, "type": "delta", "data": {"s": "BTCUSDT", "b": [["83965.5", "0.279495"], ["83964.7", "0"], ["83963.7", "0.071493"], ["83925", "0.013"], ["83924.8", "0"], ["83901.5", "0"], ["83898.7", "13.467332"]], "a": [], "u": 26673, "seq": 67550551483}, "cts": 1742556571869}}
{"exchange": "BITGET", "timestamp": 1742556571.994949, "message": {"action": "update", "arg": {"instType": "SPOT", "channel": "books", "instId": "BTCUSDT"}, "data": [{"asks": [["83945.96", "1.548685"], ["83975.18", "0.119379"], ["83987.00", "0.003039"], ["83989.00", "0.007998"], ["83991.00", "0.021048"], ["83995.00", "0.145763"], ["83997.00", "0.383587"], ["83999.00", "1.009686"], ["84000.99", "0.003719"], ["84001.00", "2.657066"], ["84003.00", "6.992279"], ["84016.10", "0.534660"], ["84045.00", "4.809489"], ["84053.40", "5.263215"], ["84061.80", "4.718744"], ["84070.20", "4.900235"], ["84078.60", "3.902039"], ["84087.00", "5.626195"], ["84095.40", "5.081725"], ["84103.80", "5.172470"], ["84112.20", "5.353960"], ["84120.60", "3.992784"], ["84129.00", "4.355764"], ["84137.40", "4.627999"], ["84145.80", "4.537254"], ["84154.20", "4.265019"], ["84162.60", "4.174274"], ["84171.00", "5.444705"], ["84179.40", "4.446509"], ["84187.80", "4.990980"], ["84196.20", "4.083529"], ["84204.60", "5.535450"], ["84523.08", "0"], ["84523.48", "0"]], "bids": [["83935.00", "0.002336"], ["83933.00", "0.006145"], ["83931.00", "0.016172"], ["83929.00", "0.042559"], ["83927.00", "0.111996"], ["83925.00", "0.294728"], ["83923.00", "0.775598"], ["83921.00", "2.041182"], ["83919.00", "5.371531"], ["83895.00", "0.000956"], ["83894.00", "0.000015"], ["83877.00", "4.265019"], ["83868.60", "5.263215"], ["83860.20", "5.081725"], ["83851.80", "4.809489"], ["83843.40", "4.537254"], ["83835.00", "3.992784"], ["83826.60", "5.444705"], ["83818.20", "5.535450"], ["83809.80", "4.355764"], ["83801.40", "4.718744"], ["83793.00", "4.990980"], ["83784.60", "4.083529"], ["83776.20", "3.902039"], ["83767.80", "5.172470"], ["83759.40", "5.626195"], ["83751.00", "4.446509"], ["83742.60", "4.174274"], ["83734.20", "4.627999"], ["83725.80", "5.353960"], ["83640.00", "0"]], "checksum": -838858155, "ts": "1742556571963"}], "ts": 1742556571968}}
{"exchange": "BYBIT", "timestamp": 1742556572.136895, "message": {"topic": "orderbook.200.BTCUSDT", "ts": 1742556572119, "type": "delta", "data": {"s": "BTCUSDT", "b": [["83925", "0"], ["83924.8", "0.012882"]], "a": [["83997.9", "0.013"], ["83998.1", "0"], ["83998.6", "0.043247"], ["83998.8", "0"], ["84028", "0.00325"]], "u": 26674, "seq": 67550551521}, "cts": 1742556572056}}
{"exchange": "BITGET", "timestamp": 1742556572.201646, "message": {"action": "update", "arg": {"instType": "SPOT", "channel": "books", "instId": "BTCUSDT"}, "data": [{"asks": [["84044.99", "0.217419"], ["84045.00", "4.355764"], ["84053.40", "4.809489"], ["84061.80", "4.174274"], ["84070.20", "5.172470"], ["84078.60", "4.537254"], ["84087.00", "4.990980"], ["84095.40", "4.446509"], ["84103.80", "4.627999"], ["84112.20", "5.263215"], ["84120.60", "5.081725"], ["84129.00", "5.353960"], ["84137.40", "3.902039"], ["84145.80", "4.265019"], ["84154.20", "5.444705"], ["84162.60", "4.083529"], ["84171.00", "5.535450"], ["84179.40", "3.992784"], ["84187.80", "5.626195"], ["84196.20", "4.718744"], ["84204.60", "4.900235"], ["84522.06", "0"]], "bids": [["83877.00", "3.902039"], ["83868.60", "5.172470"], ["83860.20", "4.174274"], ["83851.80", "5.263215"], ["83843.40", "5.081725"], ["83835.00", "4.900235"], ["83826.60", "4.718744"], ["83818.20", "4.446509"], ["83809.80", "5.444705"], ["83801.40", "4.537254"], ["83793.00", "4.627999"], ["83784.60", "4.265019"], ["83776.20", "5.535450"], ["83767.80", "5.626195"], ["83759.40", "4.083529"], ["83751.00", "4.809489"], ["83742.60", "4.990980"], ["83734.20", "4.355764"], ["83725.80", "3.992784"], ["83717.40", "5.353960"]], "checksum": -838858155, "ts": "1742556572165"}], "ts": 1742556572168}}
{"exchange": "BYBIT", "timestamp": 1742556572.337447, "message": {"topic": "orderbook.200.BTCUSDT", "ts": 1742556572320, "type": "delta", "data": {"s": "BTCUSDT", "b": [["83965.5", "0.289751"], ["83947.9", "0.06218"], ["83940.9", "0.06031"], ["83933.9", "0.122513"], ["83924.9", "0"], ["83924.7", "0.012882"], ["83890", "0"], ["83889.9", "0"]], "a": [["83982.9", "0.05756"], ["83989.9", "0.057276"], ["83996.9", "0.123709"], ["83997.9", "0"], ["83998.1", "0.012743"], ["83998.6", "0.003247"], ["83998.8", "0.04"], ["84027.8", "0"], ["84027.9", "0"], ["84028", "0"]], "u": 26675, "seq": 67550551538}, "cts": 1742556572288}}
{"exchange": "BITGET", "timestamp": 1742556572.405039, "message": {"action": "update", "arg": {"instType": "SPOT", "channel": "books", "instId": "BTCUSDT"}, "data": [{"asks": [["83945.96", "1.548516"], ["83983.48", "0"], ["83985.00", "0.001021"], ["83987.00", "0.002687"], ["83989.00", "0.007071"], ["83991.00", "0.018607"], ["83995.00", "0.128994"], ["83997.00", "0.339458"], ["83999.00", "0.893310"], ["84001.00", "2.350817"], ["84003.00", "6.186360"], ["84045.00", "5.444705"], ["84053.40", "3.992784"], ["84061.80", "4.083529"], ["84078.60", "4.355764"], ["84087.00", "4.174274"], ["84095.40", "4.627999"], ["84103.80", "4.809489"], ["84112.20", "5.353960"], ["84120.60", "5.626195"], ["84129.00", "4.718744"], ["84137.40", "4.265019"], ["84145.80", "4.900235"], ["84154.20", "4.990980"], ["84162.60", "4.537254"], ["84171.00", "5.263215"], ["84179.40", "4.446509"], ["84187.80", "3.902039"], ["84196.20", "5.081725"], ["84204.60", "5.535450"], ["84522.06", "0.000041"]], "bids": [["83935.00", "0.002215"], ["83933.00", "0.005830"], ["83931.00", "0.015342"], ["83929.00", "0.040373"], ["83927.00", "0.106245"], ["83925.00", "0.279591"], ["83923.00", "0.735603"], ["83921.00", "1.935798"], ["83919.00", "5.094205"], ["83877.00", "4.809489"], ["83868.60", "4.900235"], ["83860.20", "4.083529"], ["83851.80", "3.992784"], ["83843.40", "4.174274"], ["83835.00", "4.627999"], ["83826.60", "4.446509"], ["83818.20", "5.353960"], ["83809.80", "5.626195"], ["83801.40", "5.444705"], ["83793.00", "4.265019"], ["83784.60", "4.990980"], ["83776.20", "5.263215"], ["83767.80", "3.902039"], ["83759.40", "5.081725"], ["83751.00", "4.355764"], ["83742.60", "5.535450"], ["83734.20", "4.537254"], ["83725.80", "4.718744"], ["83717.40", "5.172470"]], "checksum": 773606928, "ts": "1742556572369"}], "ts": 1742556572375}}
{"exchange": "BYBIT", "timestamp": 1742556572.537404, "message": {"topic": "orderbook.200.BTCUSDT", "ts": 1742556572520, "type": "delta", "data": {"s": "BTCUSDT", "b": [["83963.7", "0"], ["83959.2", "0.001779"], ["83959.1", "0.011375"], ["83957.4", "0.071499"], ["83947.9", "0"], ["83945.9", "0.006522"], ["83941", "0.057627"], ["83940.9", "0.000333"], ["83937.1", "0"], ["83933.9", "0"], ["83924.9", "0.013"], ["83924.7", "0"], ["83890", "0.0002"], ["83889.9", "0.011992"]], "a": [["83982.9", "0.000333"], ["83989.9", "0"], ["83996.9", "0"], ["83997.9", "0.013"], ["83998.1", "0"], ["83998.6", "0.043247"], ["83998.8", "0"], ["84027.8", "0.059399"], ["84027.9", "0.001466"], ["84028", "0.00325"]], "u": 26676, "seq": 67550551567}, "cts": 1742556572490}}
{"exchange": "BITGET", "timestamp": 1742556572.604616, "message": {"action": "update", "arg": {"instType": "SPOT", "channel": "books", "instId": "BTCUSDT"}, "data": [{"asks": [["83945.96", "0.925346"], ["84044.99", "0"], ["84045.00", "4.265019"], ["84053.40", "5.263215"], ["84061.80", "4.355764"], ["84070.20", "4.174274"], ["84078.60", "5.535450"], ["84087.00", "3.992784"], ["84095.40", "5.353960"], ["84103.80", "4.537254"], ["84112.20", "4.083529"], ["84120.60", "4.900235"], ["84129.00", "5.081725"], ["84137.40", "5.626195"], ["84145.80", "4.809489"], ["84154.20", "3.902039"], ["84162.60", "5.444705"], ["84171.00", "4.627999"], ["84179.40", "4.718744"], ["84187.80", "4.990980"], ["84196.20", "4.446509"], ["84204.60", "5.172470"], ["84523.08", "0.000015"]], "bids": [["83945.65", "0"], ["83893.00", "0"], ["83868.60", "4.718744"], ["83860.20", "3.902039"], ["83851.80", "5.535450"], ["83843.40", "4.355764"], ["83835.00", "4.900235"], ["83826.60", "4.265019"], ["83809.80", "5.081725"], ["83801.40", "4.627999"], ["83793.00", "4.174274"], ["83784.60", "3.992784"], ["83776.20", "4.083529"], ["83767.80", "5.444705"], ["83759.40", "4.990980"], ["83751.00", "4.537254"], ["83742.60", "5.172470"], ["83734.20", "5.626195"], ["83725.80", "5.263215"], ["83717.40", "4.446509"], ["83640.00", "0.002013"], ["83639.71", "0.000041"]], "checksum": -1668163973, "ts": "1742556572575"}], "ts": 1742556572579}}
{"exchange": "BYBIT", "timestamp": 1742556572.736871, "message": {"topic": "orderbook.200.BTCUSDT", "ts": 1742556572719, "type": "delta", "data": {"s": "BTCUSDT", "b": [["83941", "0"], ["83889.8", "0.001333"]], "a": [["83965.6", "0.606538"]], "u": 26677, "seq": 67550551576}, "cts": 1742556572684}}
{"exchange": "BITGET", "timestamp": 1742556572.80955, "message": {"action": "update", "arg": {"instType": "SPOT", "channel": "books", "instId": "BTCUSDT"}, "data": [{"asks": [["83945.96", "1.162877"], ["83985.00", "0.001205"], ["83987.00", "0.003171"], ["83989.00", "0.008345"], ["83991.00", "0.021960"], ["83995.00", "0.152076"], ["83997.00", "0.400200"], ["83999.00", "1.053158"], ["84001.00", "2.771469"], ["84003.00", "7.293339"], ["84045.00", "4.174274"], ["84053.40", "3.902039"], ["84061.80", "4.627999"], ["84070.20", "4.083529"], ["84078.60", "4.990980"], ["84087.00", "4.355764"], ["84095.40", "5.444705"], ["84103.80", "4.446509"], ["84112.20", "4.900235"], ["84120.60", "4.718744"], ["84129.00", "5.626195"], ["84137.40", "5.353960"], ["84145.80", "4.265019"], ["84154.20", "5.172470"], ["84162.60", "4.537254"], ["84171.00", "5.081725"], ["84179.40", "5.263215"], ["84187.80", "4.809489"], ["84196.20", "3.992784"], ["84204.60", "5.535450"]], "bids": [["83935.00", "0.002411"], ["83933.00", "0.006343"], ["83931.00", "0.016693"], ["83929.00", "0.043929"], ["83927.00", "0.115602"], ["83925.00", "0.304217"], ["83923.00", "0.800571"], ["83921.00", "2.106766"], ["83919.00", "5.544121"], ["83895.00", "0.000941"], ["83877.00", "4.355764"], ["83868.60", "4.446509"], ["83860.20", "4.809489"], ["83851.80", "5.081725"], ["83843.40", "3.902039"], ["83835.00", "4.718744"], ["83826.60", "4.900235"], ["83809.80", "4.083529"], ["83801.40", "4.265019"], ["83793.00", "5.626195"], ["83784.60", "4.537254"], ["83776.20", "3.992784"], ["83767.80", "4.627999"], ["83759.40", "5.172470"], ["83751.00", "5.263215"], ["83742.60", "5.535450"], ["83734.20", "5.444705"], ["83725.80", "4.990980"], ["83717.40", "4.174274"]], "checksum": 1496574792, "ts": "1742556572779"}], "ts": 1742556572782}}
{"exchange": "BYBIT", "timestamp": 1742556572.9372, "message": {"topic": "orderbook.200.BTCUSDT", "ts": 1742556572919, "type": "delta", "data": {"s": "BTCUSDT", "b": [["83965.5", "0.279495"], ["83963.7", "0.071493"], ["83959.2", "0.02708"], ["83958.7", "0.071497"], ["83957.4", "0"], ["83924.9", "0.012882"], ["83914.7", "0.051768"], ["83889.8", "0"]], "a": [["83965.6", "0.608681"], ["83997.9", "0"], ["83998.1", "0.012743"], ["84009.7", "0"], ["84028.4", "0.001333"]], "u": 26678, "seq": 67550551595}, "cts": 1742556572914}}
{"exchange": "BITGET", "timestamp": 1742556573.021324, "message": {"action": "update", "arg": {"instType": "SPOT", "channel": "books", "instId": "BTCUSDT"}, "data": [{"asks": [["83945.96", "0.959707"], ["83985.00", "0.001343"], ["83987.00", "0.003534"], ["83989.00", "0.009301"], ["83991.00", "0.024475"], ["83995.00", "0.169493"], ["83996.99", "0.414950"], ["83997.00", "0.446035"], ["83999.00", "1.173777"], ["84001.00", "3.088886"], ["84003.00", "8.128646"], ["84045.00", "5.172470"], ["84053.40", "5.535450"], ["84061.80", "4.718744"], ["84070.20", "4.174274"], ["84078.60", "5.263215"], ["84087.00", "4.627999"], ["84095.40", "3.902039"], ["84103.80", "4.355764"], ["84112.20", "4.809489"], ["84120.60", "5.626195"], ["84129.00", "4.900235"], ["84137.40", "4.083529"], ["84145.80", "4.537254"], ["84154.20", "4.990980"], ["84162.60", "5.081725"], ["84171.00", "3.992784"], ["84179.40", "4.265019"], ["84187.80", "5.444705"], ["84196.20", "4.446509"], ["84204.60", "5.353960"]], "bids": [["83945.18", "0.047852"], ["83936.21", "0"], ["83935.00", "0.002184"], ["83933.00", "0.005747"], ["83931.00", "0.015123"], ["83929.00", "0.039798"], ["83927.00", "0.104730"], ["83925.00", "0.275607"], ["83923.00", "0.725282"], ["83921.00", "1.908636"], ["83919.00", "5.022725"], ["83877.00", "5.353960"], ["83868.60", "5.444705"], ["83860.20", "3.902039"], ["83851.80", "4.446509"], ["83843.40", "5.081725"], ["83835.00", "5.263215"], ["83826.60", "4.174274"], ["83818.20", "4.900235"], ["83809.80", "4.718744"], ["83801.40", "4.537254"], ["83793.00", "4.627999"], ["83784.60", "4.809489"], ["83767.80", "5.535450"], ["83751.00", "4.083529"], ["83742.60", "5.626195"], ["83734.20", "4.355764"], ["83725.80", "4.265019"], ["83717.40", "4.990980"]], "checksum": -15477584, "ts": "1742556572987"}], "ts": 1742556572993}}
{"exchange": "BYBIT", "timestamp": 1742556573.138034, "message": {"topic": "orderbook.200.BTCUSDT", "ts": 1742556573120, "type": "delta", "data": {"s": "BTCUSDT", "b": [["83924.9", "0"], ["83924.7", "0.012882"]], "a": [["83998", "0.059535"], ["83998.1", "0"], ["83998.3", "0.012743"], ["83998.4", "0.012743"], ["83998.6", "0.003247"], ["83998.7", "0"], ["83999", "0.041333"], ["83999.1", "0.04"], ["84028.4", "0"]], "u": 26679, "seq": 67550551622}, "cts": 1742556573113}}
{"exchange": "BITGET", "timestamp": 1742556573.220059, "message": {"action": "update", "arg": {"instType": "SPOT", "channel": "books", "instId": "BTCUSDT"}, "data": [{"asks": [["83980.93", "0"], ["83987.00", "0.003665"], ["83989.00", "0.009645"], ["83991.00", "0.025381"], ["83995.00", "0.175769"], ["83997.00", "0.462550"], ["83999.00", "1.217239"], ["84001.00", "3.203260"], ["84003.00", "8.429632"], ["84045.00", "4.627999"], ["84053.40", "4.265019"], ["84061.80", "4.174274"], ["84070.20", "5.263215"], ["84078.60", "4.900235"], ["84087.00", "4.718744"], ["84095.40", "4.809489"], ["84103.80", "3.902039"], ["84112.20", "4.355764"], ["84120.60", "4.446509"], ["84129.00", "3.992784"], ["84137.40", "4.990980"], ["84145.80", "5.081725"], ["84154.20", "5.626195"], ["84162.60", "5.444705"], ["84171.00", "5.172470"], ["84179.40", "5.353960"], ["84187.80", "5.535450"], ["84196.20", "4.083529"], ["84204.60", "4.537254"], ["84523.48", "0.000015"]], "bids": [["83927.00", "0.104546"], ["83925.00", "0.275122"], ["83923.00", "0.724006"], ["83921.00", "1.905279"], ["83919.00", "5.013890"], ["83894.00", "0.000032"], ["83877.00", "4.718744"], ["83868.60", "5.172470"], ["83860.20", "5.353960"], ["83851.80", "5.535450"], ["83843.40", "4.809489"], ["83835.00", "5.444705"], ["83826.60", "4.990980"], ["83818.20", "3.992784"], ["83809.80", "4.900235"], ["83801.40", "4.627999"], ["83793.00", "4.537254"], ["83784.60", "5.263215"], ["83776.20", "4.174274"], ["83767.80", "4.355764"], ["83759.40", "4.446509"], ["83751.00", "5.626195"], ["83742.60", "4.265019"], ["83734.20", "5.081725"], ["83725.80", "4.083529"], ["83717.40", "3.902039"]], "checksum": -15477584, "ts": "1742556573191"}], "ts": 1742556573193}}
{"exchange": "BYBIT", "timestamp": 1742556573.337086, "message": {"topic": "orderbook.200.BTCUSDT", "ts": 1742556573320, "type": "delta", "data": {"s": "BTCUSDT", "b": [["83965.5", "0.288736"], ["83925", "0.013"], ["83924.9", "0.012882"], ["83924.8", "0"], ["83924.7", "0"]], "a": [["83969.2", "0.071489"], ["83971.1", "0.015101"], ["83973", "0"], ["83998", "0.072535"], ["83998.1", "0.012743"], ["83998.3", "0"], ["83998.4", "0"], ["84028.4", "0.001333"]], "u": 26680, "seq": 67550551646}, "cts": 1742556573306}}
{"exchange": "BITGET", "timestamp": 1742556573.420783, "message": {"action": "update", "arg": {"instType": "SPOT", "channel": "books", "instId": "BTCUSDT"}, "data": [{"asks": [["83985.00", "0.001518"], ["83987.00", "0.003997"], ["83989.00", "0.010517"], ["83991.00", "0.027677"], ["83995.00", "0.191667"], ["83997.00", "0.504386"], ["83999.00", "1.327331"], ["84001.00", "3.492977"], ["84003.00", "9.192046"], ["84045.00", "4.809489"], ["84053.40", "3.902039"], ["84061.80", "3.992784"], ["84070.20", "4.627999"], ["84078.60", "4.446509"], ["84087.00", "5.353960"], ["84095.40", "4.990980"], ["84103.80", "5.444705"], ["84112.20", "5.172470"], ["84120.60", "4.265019"], ["84129.00", "4.537254"], ["84137.40", "5.626195"], ["84145.80", "5.263215"], ["84154.20", "4.900235"], ["84162.60", "4.718744"], ["84171.00", "4.355764"], ["84179.40", "4.083529"], ["84187.80", "5.081725"], ["84196.20", "4.174274"], ["84204.60", "5.535450"]], "bids": [["83929.00", "0.039953"], ["83927.00", "0.105140"], ["83925.00", "0.276685"], ["83923.00", "0.728118"], ["83921.00", "1.916099"], ["83919.00", "5.042367"], ["83893.00", "0.000015"], ["83877.00", "4.083529"], ["83868.60", "5.263215"], ["83860.20", "4.809489"], ["83851.80", "5.172470"], ["83843.40", "4.900235"], ["83835.00", "3.902039"], ["83826.60", "5.353960"], ["83818.20", "5.626195"], ["83809.80", "4.265019"], ["83801.40", "5.444705"], ["83793.00", "4.990980"], ["83784.60", "5.081725"], ["83776.20", "4.627999"], ["83767.80", "4.446509"], ["83759.40", "4.718744"], ["83751.00", "3.992784"], ["83742.60", "5.535450"], ["83734.20", "4.174274"], ["83725.80", "4.355764"], ["83717.40", "4.537254"], ["83639.71", "0"]], "checksum": -15477584, "ts": "1742556573393"}], "ts": 1742556573395}}
{"exchange": "BYBIT", "timestamp": 1742556573.537087, "message": {"topic": "orderbook.200.BTCUSDT", "ts": 1742556573520, "type": "delta", "data": {"s": "BTCUSDT", "b": [["83965.5", "0.287313"], ["83937.1", "0.037424"], ["83889.9", "0"]], "a": [["83986.7", "0.001032"], ["83998.7", "0.04"], ["83998.8", "0.04"], ["83999", "0.001333"], ["83999.1", "0"], ["84028", "0"], ["84028.4", "0"]], "u": 26681, "seq": 67550551687}, "cts": 1742556573510}}
{"exchange": "BITGET", "timestamp": 1742556573.635862, "message": {"action": "update", "arg": {"instType": "SPOT", "channel": "books", "instId": "BTCUSDT"}, "data": [{"asks": [["83980.92", "0.185269"], ["83985.00", "0.001254"], ["83987.00", "0.003301"], ["83989.00", "0.008687"], ["83991.00", "0.022860"], ["83995.00", "0.158313"], ["83997.00", "0.416613"], ["83999.00", "1.096349"], ["84001.00", "2.885129"], ["84003.00", "7.592446"], ["84045.00", "5.081725"], ["84053.40", "5.444705"], ["84061.80", "4.083529"], ["84070.20", "4.265019"], ["84078.60", "4.174274"], ["84087.00", "3.992784"], ["84095.40", "4.627999"], ["84103.80", "4.900235"], ["84112.20", "4.446509"], ["84120.60", "5.172470"], ["84137.40", "5.353960"], ["84145.80", "4.355764"], ["84154.20", "4.809489"], ["84162.60", "4.990980"], ["84171.00", "3.902039"], ["84179.40", "5.626195"], ["84187.80", "5.263215"], ["84196.20", "4.718744"], ["84523.48", "0"]], "bids": [["83935.00", "0.002355"], ["83933.00", "0.006198"], ["83931.00", "0.016308"], ["83929.00", "0.042916"], ["83927.00", "0.112938"], ["83925.00", "0.297206"], ["83923.00", "0.782119"], ["83921.00", "2.058208"], ["83919.00", "5.416339"], ["83914.80", "0.015000"], ["83908.20", "0.120000"], ["83877.00", "4.990980"], ["83868.60", "4.718744"], ["83860.20", "4.627999"], ["83851.80", "5.081725"], ["83843.40", "4.809489"], ["83835.00", "4.174274"], ["83826.60", "4.265019"], ["83818.20", "5.263215"], ["83809.80", "5.535450"], ["83801.40", "3.902039"], ["83793.00", "4.900235"], ["83784.60", "5.172470"], ["83776.20", "4.083529"], ["83767.80", "5.626195"], ["83759.40", "4.355764"], ["83751.00", "5.353960"], ["83742.60", "4.537254"], ["83734.20", "4.446509"], ["83725.80", "3.992784"], ["83717.40", "5.444705"], ["83640.00", "0"]], "checksum": -1802601319, "ts": "1742556573606"}], "ts": 1742556573609}}
{"exchange": "BYBIT", "timestamp": 1742556573.737277, "message": {"topic": "orderbook.200.BTCUSDT", "ts": 1742556573719, "type": "delta", "data": {"s": "BTCUSDT", "b": [], "a": [["83965.6", "0.614681"], ["83984.9", "0.001218"], ["83986.7", "0"]], "u": 26682, "seq": 67550551705}, "cts": 1742556573694}}
{"exchange": "BITGET", "timestamp": 1742556573.835658, "message": {"action": "update", "arg": {"instType": "SPOT", "channel": "books", "instId": "BTCUSDT"}, "data": [{"asks": [["84045.00", "4.809489"], ["84053.40", "4.265019"], ["84061.80", "4.990980"], ["84070.20", "5.081725"], ["84078.60", "5.263215"], ["84087.00", "5.444705"], ["84095.40", "4.718744"], ["84103.80", "5.172470"], ["84112.20", "4.537254"], ["84120.60", "4.900235"], ["84129.00", "5.535450"], ["84145.80", "4.627999"], ["84154.20", "3.992784"], ["84162.60", "4.355764"], ["84187.80", "4.446509"], ["84196.20", "4.174274"], ["84204.60", "4.083529"]], "bids": [["83945.18", "0"], ["83868.60", "5.626195"], ["83860.20", "3.902039"], ["83843.40", "4.900235"], ["83835.00", "4.265019"], ["83826.60", "5.353960"], ["83809.80", "4.809489"], ["83801.40", "4.174274"], ["83793.00", "4.083529"], ["83784.60", "4.627999"], ["83776.20", "5.535450"], ["83767.80", "3.992784"], ["83759.40", "5.444705"], ["83751.00", "4.718744"], ["83742.60", "4.355764"], ["83734.20", "4.537254"], ["83725.80", "4.446509"], ["83717.40", "5.172470"], ["83640.00", "0.002013"]], "checksum": -998768098, "ts": "1742556573806"}], "ts": 1742556573810}}
