{"exchange": "BYBIT", "timestamp": 1742555346.229761, "message": {"success": true, "ret_msg": "subscribe", "conn_id": "a7beb424-a566-41eb-baaf-debfaa516def", "op": "subscribe"}}
{"exchange": "BYBIT", "timestamp": 1742555346.231522, "message": {"topic": "orderbook.200.BTCUSDT", "ts": 1742555345319, "type": "snapshot", "data": {"s": "BTCUSDT", "b": [["84061.1", "0.216339"], ["84060", "0.00006"], ["84059.4", "0.000319"], ["84056.1", "0.0025"], ["84055.7", "0.005362"], ["84055.2", "0.0039"], ["84055", "0.000297"], ["84054.9", "0.055211"], ["84054.8", "0.171"], ["84054.7", "0.011317"], ["84054.3", "0.000333"], ["84053.6", "0.001333"], ["84053.3", "0.019358"], ["84053.2", "0.003213"], ["84052.8", "0.045826"], ["84052.7", "0.015"], ["84052.5", "0.001753"], ["84051.6", "0.023718"], ["84051.2", "0.048"], ["84051", "0.041466"], ["84050.5", "0.022636"], ["84050.3", "0.102025"], ["84050.2", "0.114851"], ["84050.1", "0.000333"], ["84050", "0.00086"], ["84049.9", "0.122034"], ["84049.5", "0.056"], ["84049.4", "0.041569"], ["84049", "0.003181"], ["84048.7", "0.005942"], ["84047.7", "0.08"], ["84047.4", "0.005943"], ["84047.2", "0.052512"], ["84046.4", "0.001466"], ["84046.1", "0.234192"], ["84046", "0.084"], ["84045.9", "0.000333"], ["84045.6", "0.000516"], ["84045.3", "0.003"], ["84045.2", "0.011059"], ["84045", "0.000594"], ["84044.8", "0.003181"], ["84044.7", "0.005959"], ["84044.4", "0.04"], ["84044.3", "0.04"], ["84044.1", "0.171"], ["84041.8", "0.001466"], ["84041.7", "0.000333"], ["84041.3", "0.009"], ["84041", "0.001849"], ["84040.6", "0.003181"], ["84040.1", "0.170042"], ["84040", "0.00006"], ["84039.8", "0.286414"], ["84039.7", "0.187489"], ["84039.1", "0.179727"], ["84038.1", "0.059399"], ["84037.9", "0.528097"], ["84037.7", "0.122482"], ["84037.6", "0.021653"], ["84037.5", "0.000333"], ["84037.4", "0.000337"], ["84037.3", "0.035695"], ["84037.2", "0.001466"], ["84036.8", "0.001423"], ["84036.4", "0.003697"], ["84035.6", "0.171629"], ["84034.8", "0.112631"], ["84034.3", "0.089099"], ["84033.4", "0.118804"], ["84033.3", "0.19568"], ["84032.7", "0.310207"], ["84032.6", "0.001333"], ["84032.5", "0.001466"], ["84032.2", "0.003181"], ["84032.1", "0.303378"], ["84031.9", "0.485906"], ["84031.8", "0.000516"], ["84031", "0.294372"], ["84030.2", "0.004768"], ["84029.1", "0.000333"], ["84028.6", "0.118217"], ["84028.4", "0.001423"], ["84028", "0.003181"], ["84027.9", "0.001466"], ["84027.6", "0.118804"], ["84027.3", "0.059399"], ["84027.1", "0.195621"], ["84026.5", "0.0061"], ["84025.9", "0.0264"], ["84025", "0.000199"], ["84024.9", "0.000333"], ["84024.8", "0.0001"], ["84024.3", "0.048729"], ["84024.2", "0.001333"], ["84023.8", "0.003181"], ["84023.6", "0.012881"], ["84023.5", "0.012881"], ["84023.3", "0.001466"], ["84022.7", "0.017619"], ["84022.5", "0.000516"], ["84021.6", "0.118804"], ["84020.7", "0.128873"], ["84020.6", "0.000119"], ["84020.5", "0.011902"], ["84020.3", "0.232559"], ["84020.2", "0.4"], ["84020", "0.001483"], ["84019.7", "0.00009"], ["84019.6", "0.003181"], ["84019.3", "0.135511"], ["84018.7", "0.001466"], ["84018.6", "0.171"], ["84018.2", "0.059399"], ["84017.9", "0.000516"], ["84016.5", "1.940534"], ["84016.4", "2.950057"], ["84016.2", "3.521913"], ["84016", "0.000118"], ["84015.8", "0.001333"], ["84015.4", "0.003181"], ["84015.3", "0.0001"], ["84015.1", "0.005942"], ["84014.1", "0.001466"], ["84013.3", "0.000516"], ["84012.3", "0.000333"], ["84012", "0.011903"], ["84011.6", "0.001423"], ["84011.3", "0.009"], ["84011.2", "0.003181"], ["84011", "0.00107"], ["84010.5", "0.327005"], ["84010.4", "0.213321"], ["84010.3", "0.04"], ["84010.1", "0.171"], ["84010", "0.066146"], ["84009.7", "0.015"], ["84009.4", "0.001466"], ["84009.1", "0.076061"], ["84009", "17.620531"], ["84008.7", "0.004644"], ["84008.5", "0.003575"], ["84008.4", "0.118804"], ["84008.1", "0.021264"], ["84008", "0.023791"], ["84007.4", "0.001333"], ["84007", "0.003181"], ["84005.6", "0.04"], ["84004.8", "0.001466"], ["84004", "0.000516"], ["84003.9", "0.000333"], ["84003.5", "0.005947"], ["84003.2", "0.001423"], ["84002.8", "0.026973"], ["84001.6", "0.171"], ["84001.3", "0.059399"], ["84001.1", "0.023792"], ["84000.8", "0.000014"], ["84000.2", "0.001466"], ["84000.1", "1.091681"], ["84000", "3.678938"], ["83999.7", "0.000333"], ["83999.6", "0.057829"], ["83999.4", "0.000516"], ["83999.3", "0.023792"], ["83999", "0.041333"], ["83998.8", "0.000106"], ["83998.6", "0.003181"], ["83998.3", "0.124746"], ["83998", "0.000532"], ["83996.5", "0.0045"], ["83996", "0.235392"], ["83995.7", "0.023792"], ["83995.6", "0.001466"], ["83995.5", "0.000333"], ["83995.2", "0.023792"], ["83994.8", "0.001939"], ["83994.7", "0.089099"], ["83994.4", "0.003181"], ["83993.2", "0.04"], ["83993.1", "0.171"], ["83992.2", "0.005943"], ["83991.4", "0.203256"], ["83991.3", "0.000333"], ["83991", "0.001466"], ["83990.8", "0.000166"], ["83990.7", "0.00005"], ["83990.6", "0.001333"], ["83990.2", "0.003697"], ["83989.4", "0.195"], ["83988.5", "0.353413"], ["83988.2", "0.118804"], ["83987.3", "0.04"], ["83987.2", "0.013097"], ["83987.1", "0.000333"], ["83986.9", "0.028076"], ["83986.6", "0.000337"], ["83986.4", "0.001423"], ["83986.3", "0.001466"], ["83986", "0.003181"]], "a": [["84061.2", "0.134848"], ["84061.7", "0.003213"], ["84062", "0.001333"], ["84062.1", "0.012222"], ["84062.7", "0.000333"], ["84063.5", "0.00119"], ["84064.1", "0.000516"], ["84064.9", "0.001466"], ["84065.2", "0.005942"], ["84065.9", "0.003213"], ["84066.2", "0.004034"], ["84066.9", "0.000333"], ["84067.3", "0.000153"], ["84067.5", "0.013774"], ["84067.6", "0.012503"], ["84068.7", "0.002483"], ["84069.5", "0.001466"], ["84069.6", "0.015"], ["84070", "0.00329"], ["84070.1", "0.003214"], ["84070.4", "0.001333"], ["84071.1", "0.000333"], ["84071.3", "0.005917"], ["84071.4", "0.000297"], ["84071.5", "0.04"], ["84071.6", "0.044"], ["84071.8", "0.025006"], ["84072.4", "0.223165"], ["84072.5", "0.067374"], ["84073.2", "0.059399"], ["84073.4", "0.000516"], ["84074.2", "0.001466"], ["84074.3", "0.003215"], ["84074.6", "0.001333"], ["84074.7", "0.302107"], ["84075", "0.088"], ["84075.1", "0.123027"], ["84075.2", "0.048"], ["84075.3", "0.000333"], ["84075.4", "0.17109"], ["84075.5", "0.04"], ["84075.6", "0.232094"], ["84076.1", "0.0012"], ["84076.2", "0.03899"], ["84076.3", "0.005948"], ["84076.6", "0.088"], ["84077.4", "0.178442"], ["84077.7", "0.112637"], ["84077.9", "0.035695"], ["84078", "0.000516"], ["84078.2", "0.048"], ["84078.5", "0.18162"], ["84078.6", "0.023627"], ["84078.8", "0.002799"], ["84079", "0.117871"], ["84079.5", "0.000333"], ["84079.8", "0.220942"], ["84080", "0.00024"], ["84080.1", "0.052"], ["84080.2", "0.178401"], ["84081.1", "0.0012"], ["84082", "0.005942"], ["84082.5", "0.059399"], ["84082.6", "0.000516"], ["84082.7", "0.003225"], ["84083", "0.001333"], ["84083.1", "0.011202"], ["84083.4", "0.001466"], ["84083.7", "0.000333"], ["84083.8", "0.00009"], ["84083.9", "0.459606"], ["84084.8", "0.126103"], ["84084.9", "0.168015"], ["84085.2", "0.176054"], ["84085.6", "0.018458"], ["84086", "0.187392"], ["84086.5", "0.0045"], ["84086.7", "0.003447"], ["84086.9", "0.122038"], ["84087.2", "0.013745"], ["84087.3", "0.171"], ["84087.9", "0.003433"], ["84088", "0.001466"], ["84088.9", "0.011902"], ["84090.7", "0.217219"], ["84090.8", "0.540353"], ["84091.1", "0.003234"], ["84091.4", "0.001333"], ["84091.9", "0.059917"], ["84092", "0.118804"], ["84092.1", "0.000333"], ["84092.2", "0.290599"], ["84092.7", "0.001466"], ["84093", "0.278513"], ["84094", "0.288472"], ["84094.2", "0.019638"], ["84094.3", "0.023789"], ["84094.5", "0.0006"], ["84095", "0.023789"], ["84095.3", "0.003236"], ["84095.6", "0.001333"], ["84095.9", "0.005947"], ["84096", "0.000118"], ["84096.2", "0.004597"], ["84096.3", "0.000333"], ["84096.4", "0.0012"], ["84096.5", "0.000518"], ["84097.3", "0.001466"], ["84097.4", "0.082549"], ["84097.5", "0.118804"], ["84097.8", "0.003575"], ["84098.5", "0.023789"], ["84098.7", "0.0006"], ["84098.8", "0.005942"], ["84099.1", "0.04"], ["84099.3", "0.044"], ["84099.5", "0.003236"], ["84099.6", "0.089221"], ["84099.7", "0.002141"], ["84099.8", "0.001333"], ["84100", "0.00693"], ["84100.3", "0.024389"], ["84100.5", "0.000333"], ["84100.6", "0.00009"], ["84101", "0.05993"], ["84101.1", "0.609174"], ["84101.2", "0.194789"], ["84101.3", "0.009"], ["84101.4", "0.012846"], ["84101.5", "0.012846"], ["84101.9", "0.001466"], ["84102.3", "0.04"], ["84102.4", "0.04"], ["84102.6", "0.048"], ["84103", "0.004201"], ["84103.1", "1.426821"], ["84103.7", "0.003236"], ["84104", "0.064766"], ["84104.3", "0.048"], ["84104.7", "0.000333"], ["84104.8", "0.118804"], ["84105.6", "0.015"], ["84105.7", "0.000518"], ["84105.9", "0.048"], ["84106.2", "0.138911"], ["84106.3", "0.353419"], ["84106.4", "0.089099"], ["84106.5", "0.001466"], ["84106.9", "0.014061"], ["84107.9", "0.003236"], ["84108.2", "0.001333"], ["84109", "0.000423"], ["84110.2", "0.118804"], ["84110.3", "0.059399"], ["84110.4", "0.000518"], ["84110.5", "0.17141"], ["84111.2", "0.02525"], ["84111.9", "0.023784"], ["84112.1", "0.003236"], ["84112.4", "0.001333"], ["84112.8", "0.028772"], ["84112.9", "0.04"], ["84113.2", "0.000333"], ["84113.3", "0.052"], ["84115", "0.000518"], ["84115.4", "0.023784"], ["84115.5", "3.062956"], ["84115.6", "0.005942"], ["84115.8", "0.001466"], ["84116.2", "2.257053"], ["84116.3", "0.003237"], ["84116.5", "0.0045"], ["84116.6", "0.001333"], ["84116.9", "0.118804"], ["84117.2", "0.023784"], ["84117.3", "0.00009"], ["84117.4", "0.000423"], ["84118.1", "0.023784"], ["84119.6", "0.000518"], ["84120", "0.00034"], ["84120.4", "0.001466"], ["84120.5", "0.003237"], ["84120.9", "0.001333"], ["84121.6", "0.051633"], ["84121.7", "0.171"], ["84123.2", "0.059399"], ["84124.2", "0.000518"], ["84124.7", "0.003237"], ["84125", "0.001466"], ["84125.1", "0.001333"], ["84125.4", "0.118804"], ["84125.8", "0.000423"], ["84126.6", "0.00234"], ["84128.1", "0.059449"], ["84128.3", "3.600751"], ["84128.5", "0.0001"], ["84128.9", "0.003755"], ["84129.3", "0.041333"], ["84129.7", "0.090565"], ["84130", "0.000333"]], "u": 20661, "seq": 67549987617}, "cts": 1742555345277}}
{"exchange": "BYBIT", "timestamp": 1742555346.232835, "message": {"topic": "orderbook.200.BTCUSDT", "ts": 1742555345520, "type": "delta", "data": {"s": "BTCUSDT", "b": [["84052.2", "0.002999"], ["84033.3", "0.397453"], ["84023.6", "0.013"], ["83986", "0"]], "a": [["84084.8", "0.245102"], ["84090.6", "0.001278"], ["84130", "0"]], "u": 20662, "seq": 67549987642}, "cts": 1742555345499}}
{"exchange": "BYBIT", "timestamp": 1742555346.233627, "message": {"topic": "orderbook.200.BTCUSDT", "ts": 1742555345720, "type": "delta", "data": {"s": "BTCUSDT", "b": [["84052.2", "0.005998"], ["84011.8", "17.620531"], ["84009", "0"]], "a": [["84090.5", "0.001246"], ["84090.6", "0"]], "u": 20663, "seq": 67549987658}, "cts": 1742555345702}}
{"exchange": "BYBIT", "timestamp": 1742555346.234721, "message": {"topic": "orderbook.200.BTCUSDT", "ts": 1742555345919, "type": "delta", "data": {"s": "BTCUSDT", "b": [["84061.6", "0.348431"], ["84061.2", "0.097553"], ["84061.1", "0.172389"], ["84060.4", "0.089099"], ["84056.6", "0.0025"], ["84056.1", "0"], ["84055", "0"], ["84053.3", "0"], ["84053.2", "0.018213"], ["84052.8", "0.071301"], ["84052.7", "0"], ["84050.9", "0.089099"], ["84050.3", "0.072655"], ["84050.2", "0.000516"], ["84049.9", "0"], ["84046.1", "0.124062"], ["84040.1", "0"], ["84039.7", "0"], ["84039.1", "0"], ["84037.8", "0.003576"], ["84033.4", "0.141623"], ["84032.7", "0"], ["84032.1", "0"], ["84031", "0"], ["84027.1", "0.171516"], ["84020.7", "0.000333"], ["84011.8", "0"], ["83986.9", "0"], ["83986.4", "17.630738"], ["83986", "0.003181"], ["83985.6", "0.000516"], ["83984.4", "0.059399"], ["83984", "0.04"], ["83983.2", "0.160747"], ["83982.9", "0.000333"], ["83982.5", "0.011992"]], "a": [["84061.2", "0"], ["84061.7", "0.054962"], ["84066.2", "0.001534"], ["84066.7", "0.0025"], ["84067.3", "0"], ["84067.5", "0"], ["84069.6", "0.005"], ["84070.1", "0.013214"], ["84071.3", "0"], ["84071.5", "0"], ["84071.6", "0"], ["84071.7", "0.000297"], ["84072.4", "0.145346"], ["84073.2", "0"], ["84074.7", "0"], ["84075", "0.04"], ["84075.1", "0.003762"], ["84075.5", "0"], ["84075.6", "0.071432"], ["84076.6", "0.04"], ["84077.1", "0.008842"], ["84077.3", "0.04"], ["84077.4", "0"], ["84077.9", "0"], ["84078.2", "0"], ["84078.5", "0.003215"], ["84079", "0"], ["84079.8", "0.256636"], ["84080.2", "0"], ["84083.4", "0.01915"], ["84084.9", "0"], ["84085.2", "0"], ["84086", "0.023792"], ["84090.5", "0"], ["84092.2", "0.00009"], ["84093", "0"], ["84094", "0"], ["84099.6", "0"], ["84101.4", "0"], ["84101.5", "0"], ["84102.3", "0"], ["84102.4", "0"], ["84104", "0.001333"], ["84104.7", "0.013333"], ["84104.8", "0.13165"], ["84105.6", "0.055"], ["84105.7", "0.040518"], ["84106.8", "0.063433"], ["84112.8", "0.005946"], ["84116.2", "0"], ["84117.5", "0.024954"], ["84124.7", "2.26029"], ["84130", "0.000333"], ["84130.9", "0.118804"], ["84131", "0.001428"], ["84131.2", "0.059449"], ["84131.3", "0.009"], ["84132", "0.0018"], ["84132.1", "0.059449"], ["84132.2", "0.027508"], ["84132.4", "0.005942"], ["84132.8", "0.059399"], ["84133.1", "0.006786"], ["84133.5", "0.001851"], ["84134.2", "0.000423"], ["84134.3", "0.001466"], ["84137.1", "0.4"], ["84137.2", "0.029723"], ["84137.3", "0.003211"], ["84137.4", "0.013073"], ["84137.7", "0.001333"]], "u": 20664, "seq": 67549987955}, "cts": 1742555345917}}
{"exchange": "BYBIT", "timestamp": 1742555346.235638, "message": {"topic": "orderbook.200.BTCUSDT", "ts": 1742555346120, "type": "delta", "data": {"s": "BTCUSDT", "b": [["84061.6", "0.378173"], ["84061.2", "0.05181"], ["84061.1", "0.17232"], ["84060.4", "0"], ["84039.8", "0"], ["84033.3", "0.000333"], ["83998.2", "0.028134"], ["83989.2", "17.629315"], ["83986.4", "0.001423"], ["83984.6", "0.171"], ["83982.5", "0"]], "a": [["84061.7", "0.084706"], ["84069.6", "0"], ["84070.1", "0.018214"], ["84071.3", "0.00586"], ["84072.4", "0.101127"], ["84074.5", "0.000153"], ["84077.4", "0.044"], ["84079.8", "0.220942"], ["84080", "0.035934"], ["84080.7", "0.048"], ["84082.4", "0.048"], ["84084", "0.048"], ["84084.8", "0.108564"], ["84099.1", "0"], ["84099.3", "0"], ["84099.6", "0.08922"], ["84102.6", "0"], ["84104.3", "0"], ["84104.7", "0.000333"], ["84104.9", "0.012846"], ["84105.6", "0.015"], ["84105.8", "0.04"], ["84119.2", "2.257053"], ["84124.7", "0.003237"], ["84130.2", "0.171"], ["84134.3", "0"], ["84137.1", "0"], ["84137.2", "0"], ["84137.3", "0"], ["84137.4", "0"], ["84137.7", "0"]], "u": 20665, "seq": 67549988021}, "cts": 1742555346117}}
{"exchange": "BYBIT", "timestamp": 1742555346.339546, "message": {"topic": "orderbook.200.BTCUSDT", "ts": 1742555346319, "type": "delta", "data": {"s": "BTCUSDT", "b": [["84061.6", "0.378246"], ["84060", "0.089159"], ["84048.5", "0.060583"], ["84041.5", "0.055305"], ["84034.5", "0.120536"], ["84024.4", "0.013"], ["84024.3", "0.06161"], ["84023.6", "0"], ["84023.5", "0"], ["84017.5", "17.629315"], ["83989.2", "0"], ["83983.2", "0"], ["83982.9", "0"]], "a": [["84061.7", "0.037122"], ["84072.3", "0.059399"], ["84082.3", "0.04"], ["84083.5", "0.059708"], ["84090.5", "0.054484"], ["84097.5", "0.22801"], ["84099.6", "0"], ["84105.9", "0"], ["84119.2", "0"], ["84134.2", "0"]], "u": 20666, "seq": 67549988098}, "cts": 1742555346318}}
{"exchange": "BITGET", "timestamp": 1742555346.381246, "message": {"event": "subscribe", "arg": {"instType": "SPOT", "channel": "books", "instId": "BTCUSDT"}}}
{"exchange": "BITGET", "timestamp": 1742555346.384256, "message": {"action": "snapshot", "arg": {"instType": "SPOT", "channel": "books", "instId": "BTCUSDT"}, "data": [{"asks": [["84029.41", "0.333467"], ["84029.42", "0.000100"], ["84029.43", "0.000100"], ["84029.44", "0.000100"], ["84030.49", "0.088149"], ["84030.70", "0.136319"], ["84036.96", "0.054750"], ["84037.81", "0.000221"], ["84040.67", "0.013964"], ["84040.69", "0.112637"], ["84041.67", "0.000357"], ["84041.92", "0.000679"], ["84041.93", "0.007162"], ["84041.96", "0.000865"], ["84041.97", "0.009407"], ["84042.03", "0.006601"], ["84042.04", "0.006307"], ["84046.22", "0.072066"], ["84046.23", "0.209200"], ["84051.72", "0.035952"], ["84052.15", "0.119870"], ["84053.09", "0.478871"], ["84053.10", "0.017457"], ["84053.42", "0.035961"], ["84053.76", "1.531031"], ["84053.84", "0.006356"], ["84054.07", "0.006356"], ["84054.34", "0.006356"], ["84054.81", "0.225089"], ["84054.82", "0.314141"], ["84055.41", "0.010984"], ["84055.70", "0.006356"], ["84055.85", "0.006356"], ["84056.35", "0.006356"], ["84056.40", "0.016429"], ["84056.52", "0.209200"], ["84056.86", "0.006356"], ["84056.87", "0.006356"], ["84057.19", "0.016429"], ["84057.22", "0.119883"], ["84057.37", "0.006356"], ["84057.38", "0.006356"], ["84058.88", "0.010985"], ["84058.93", "0.006357"], ["84059.01", "0.132230"], ["84059.72", "0.009990"], ["84060.00", "0.002000"], ["84060.65", "0.119850"], ["84061.66", "0.119858"], ["84061.74", "0.119867"], ["84062.01", "0.015895"], ["84062.17", "0.164200"], ["84062.24", "0.009989"], ["84065.95", "0.008064"], ["84065.96", "0.015892"], ["84066.85", "0.010988"], ["84069.00", "0.074566"], ["84069.01", "0.209200"], ["84071.21", "0.012472"], ["84075.66", "0.062760"], ["84079.68", "0.209200"], ["84080.97", "0.182950"], ["84081.74", "0.773683"], ["84081.75", "3.570943"], ["84083.40", "0.001019"], ["84085.39", "0.004110"], ["84085.40", "0.001052"], ["84087.14", "0.010000"], ["84087.33", "0.001598"], ["84087.40", "0.001045"], ["84089.27", "0.001597"], ["84089.40", "0.001004"], ["84090.00", "0.002000"], ["84090.73", "0.011625"], ["84090.74", "0.713514"], ["84091.40", "0.001008"], ["84093.40", "0.002016"], ["84095.00", "0.001000"], ["84095.07", "0.209200"], ["84095.40", "0.005305"], ["84097.40", "0.013846"], ["84099.40", "0.036194"], ["84099.85", "0.402805"], ["84100.00", "0.004910"], ["84101.40", "0.095248"], ["84103.40", "0.250654"], ["84103.48", "0.209200"], ["84103.80", "0.006060"], ["84104.20", "0.001044"], ["84104.40", "0.001024"], ["84105.70", "0.007050"], ["84105.90", "0.001025"], ["84106.70", "0.515880"], ["84107.00", "0.072900"], ["84107.60", "0.901680"], ["84108.10", "0.067980"], ["84108.50", "2.356410"], ["84109.90", "0.402840"], ["84110.10", "0.067800"], ["84110.30", "0.022620"], ["84111.10", "0.009000"], ["84111.40", "0.135780"], ["84111.69", "0.030264"], ["84111.70", "0.576870"], ["84112.10", "0.067800"], ["84112.20", "0.066210"], ["84112.30", "1.069890"], ["84112.60", "0.071520"], ["84112.90", "0.000958"], ["84113.40", "0.003296"], ["84113.41", "0.209200"], ["84113.50", "0.012330"], ["84114.10", "0.067800"], ["84115.30", "0.420000"], ["84115.80", "0.090000"], ["84116.00", "0.035670"], ["84116.40", "2.723370"], ["84116.60", "0.320310"], ["84116.90", "0.015120"], ["84117.10", "0.107070"], ["84118.70", "0.203926"], ["84119.24", "1.783183"], ["84120.00", "0.002000"], ["84126.22", "0.209200"], ["84137.08", "0.000039"], ["84145.40", "4.169293"], ["84145.50", "0.209200"], ["84148.72", "0.001810"], ["84150.00", "0.002064"], ["84153.90", "4.350566"], ["84157.13", "0.003620"], ["84160.20", "0.308828"], ["84162.40", "4.531840"], ["84163.21", "0.125658"], ["84163.36", "0.071253"], ["84164.83", "0.071045"], ["84169.99", "0.209200"], ["84170.90", "5.256934"], ["84171.60", "0.001428"], ["84174.51", "0.000388"], ["84178.41", "0.209200"], ["84178.87", "0.057001"], ["84179.40", "4.803750"], ["84180.00", "0.002000"], ["84186.81", "0.209200"], ["84187.90", "3.988019"], ["84188.00", "0.000202"], ["84195.21", "0.209200"], ["84196.40", "4.622477"], ["84203.61", "0.209200"], ["84204.90", "5.075661"], ["84210.00", "0.002000"], ["84210.70", "0.311078"], ["84212.01", "0.209200"], ["84213.40", "5.619481"], ["84213.46", "0.000163"], ["84216.00", "0.001184"], ["84220.41", "0.209200"], ["84221.90", "5.438208"], ["84222.00", "0.001469"], ["84223.75", "0.010000"], ["84226.33", "0.024945"], ["84228.81", "0.209200"], ["84230.40", "4.441203"], ["84232.06", "0.011010"], ["84233.38", "0.001273"], ["84234.12", "0.000044"], ["84237.21", "0.209200"], ["84238.90", "4.985024"], ["84240.00", "0.002000"], ["84240.71", "0.164840"], ["84245.00", "0.000149"], ["84247.40", "4.259930"], ["84250.00", "0.000684"], ["84252.44", "0.000143"], ["84252.70", "0.307896"], ["84253.92", "0.209200"], ["84255.90", "5.166297"], ["84259.99", "0.000017"], ["84262.10", "0.001403"], ["84264.40", "4.894387"], ["84266.08", "0.000016"], ["84266.67", "0.000078"], ["84269.24", "0.000032"], ["84270.00", "0.002692"], ["84270.70", "0.209200"], ["84270.98", "0.000052"], ["84272.72", "0.000105"], ["84272.90", "3.897382"], ["84275.00", "0.000671"], ["84278.39", "0.001720"], ["84279.10", "0.209200"], ["84280.00", "0.000077"], ["84281.40", "4.713114"], ["84285.00", "0.000031"], ["84285.71", "0.000010"], ["84285.95", "0.000028"], ["84286.79", "0.000016"], ["84287.50", "0.209276"], ["84288.89", "0.000361"], ["84289.90", "5.528845"], ["84294.68", "0.000019"], ["84295.90", "0.209200"], ["84297.06", "0.000035"], ["84298.40", "5.347571"], ["84300.00", "0.023631"], ["84304.31", "0.209200"], ["84306.90", "4.078656"], ["84307.00", "0.000113"], ["84307.23", "0.000008"], ["84309.09", "0.000010"], ["84310.34", "0.000331"], ["84310.35", "0.000146"], ["84311.11", "0.000025"], ["84312.50", "0.000125"], ["84312.72", "0.209200"], ["84313.03", "0.000024"], ["84314.97", "0.000008"], ["84316.67", "0.000322"], ["84317.24", "0.000135"], ["84317.40", "0.000010"], ["84318.59", "0.000027"], ["84319.15", "0.000137"], ["84319.18", "0.000039"], ["84320.00", "0.000019"], ["84321.13", "0.209200"], ["84322.11", "0.000008"], ["84324.32", "0.000059"], ["84325.00", "0.002294"], ["84325.07", "0.000161"], ["84326.09", "0.000010"], ["84326.42", "0.000023"], ["84327.14", "0.000039"], ["84327.73", "0.041940"], ["84328.95", "0.000174"], ["84329.54", "0.209200"], ["84329.64", "0.000026"], ["84330.00", "0.002000"], ["84332.00", "0.000008"], ["84333.33", "0.002262"], ["84333.36", "0.000010"], ["84333.38", "0.000008"], ["84334.48", "0.000096"], ["84334.77", "0.000022"], ["84336.00", "0.000133"], ["84336.23", "0.000013"], ["84336.29", "0.000010"], ["84336.34", "0.000176"], ["84337.25", "0.000067"], ["84337.35", "0.000008"], ["84338.46", "0.000015"], ["84339.21", "0.000010"], ["84339.29", "0.000029"], ["84339.62", "0.000051"], ["84340.00", "0.018287"], ["84340.72", "0.000066"], ["84341.01", "0.000008"], ["84342.11", "0.000051"], ["84342.63", "0.000009"], ["84342.70", "0.000423"], ["84343.07", "0.000014"], ["84343.70", "0.000075"], ["84343.75", "0.000012"], ["84343.97", "0.000188"], ["84345.00", "0.000403"], ["84346.43", "0.000128"], ["84346.94", "0.000085"], ["84347.69", "0.000009"], ["84347.83", "0.016818"], ["84348.21", "0.000036"], ["84348.27", "0.012402"], ["84348.62", "0.000072"], ["84350.00", "0.002253"], ["84350.79", "0.000033"], ["84354.58", "0.000115"], ["84354.64", "0.000018"], ["84354.82", "0.000078"], ["84354.84", "0.000194"], ["84356.98", "0.000048"], ["84357.14", "0.000273"], ["84358.29", "0.000024"], ["84359.83", "0.000010"], ["84360.00", "0.003600"], ["84363.63", "0.000057"], ["84363.64", "0.000078"], ["84366.14", "0.000162"], ["84366.15", "0.000061"], ["84366.19", "0.000022"], ["84366.60", "0.000011"], ["84366.96", "0.000018"], ["84367.10", "0.000014"], ["84367.82", "0.000476"], ["84368.38", "0.000009"], ["84368.42", "0.000284"], ["84370.00", "0.000052"], ["84370.59", "0.000071"], ["84370.97", "0.000020"], ["84371.86", "0.000012"], ["84375.00", "0.004006"], ["84376.31", "0.000016"], ["84378.11", "0.000008"], ["84378.38", "0.000009"], ["84378.45", "0.000015"], ["84380.00", "0.032216"], ["84381.82", "0.000008"], ["84382.00", "0.000035"], ["84382.35", "0.000071"], ["84383.41", "0.000053"], ["84383.69", "0.000248"], ["84384.38", "0.000424"], ["84384.61", "0.000008"], ["84386.19", "0.000019"], ["84386.67", "0.000013"], ["84387.50", "0.006969"], ["84387.76", "0.000024"], ["84389.61", "0.000088"], ["84389.90", "0.000012"], ["84390.00", "0.002000"], ["84390.01", "0.000387"], ["84391.30", "0.000018"], ["84393.31", "0.000050"], ["84396.55", "0.000016"], ["84396.98", "0.007500"], ["84397.57", "1.660014"], ["84397.59", "0.000008"], ["84397.69", "0.000275"], ["84398.26", "0.000068"], ["84399.54", "0.000030"], ["84399.91", "0.000018"], ["84399.99", "0.000022"], ["84400.00", "0.060615"], ["84400.18", "0.000024"], ["84402.40", "0.001273"], ["84403.39", "0.000023"], ["84403.76", "0.000099"], ["84403.98", "0.007500"], ["84404.26", "0.000137"], ["84404.28", "0.000039"], ["84404.90", "0.493801"], ["84405.00", "0.000402"], ["84406.06", "0.000008"], ["84406.83", "0.000064"], ["84407.50", "0.000031"], ["84410.00", "0.000059"], ["84410.04", "0.000025"], ["84411.11", "0.000361"], ["84411.43", "0.000008"], ["84411.76", "0.000101"], ["84411.77", "0.000020"], ["84412.50", "0.000049"], ["84413.04", "0.000010"], ["84413.33", "0.000073"], ["84413.79", "0.000135"], ["84414.29", "0.000074"], ["84414.41", "0.000051"], ["84415.09", "0.000008"], ["84416.67", "0.000355"], ["84418.34", "0.000046"], ["84419.69", "0.000023"], ["84419.90", "0.002343"], ["84420.00", "0.002640"], ["84420.17", "0.041940"], ["84422.71", "0.000010"], ["84423.08", "0.000067"], ["84423.53", "0.000105"], ["84424.00", "0.000022"], ["84424.12", "0.000146"], ["84425.00", "0.002205"], ["84425.69", "0.000314"], ["84426.68", "0.000101"], ["84427.08", "0.000014"], ["84427.92", "0.000323"], ["84428.57", "0.000057"], ["84429.82", "0.000022"], ["84430.50", "0.000113"], ["84430.74", "0.000010"], ["84430.77", "0.000015"], ["84431.23", "0.000039"], ["84432.43", "0.000008"], ["84433.33", "0.000347"], ["84434.78", "0.000008"], ["84435.26", "0.000161"], ["84436.26", "0.000009"], ["84437.14", "0.000017"], ["84437.50", "0.000725"], ["84437.75", "0.000013"], ["84438.44", "0.000176"], ["84440.00", "0.000544"], ["84442.54", "0.000096"], ["84443.07", "0.000423"], ["84444.25", "0.000013"], ["84444.41", "0.000371"], ["84444.44", "0.000574"], ["84444.92", "0.000022"], ["84446.04", "0.000016"], ["84446.38", "0.000013"], ["84446.43", "0.000036"], ["84447.80", "0.000718"], ["84448.75", "0.000066"], ["84448.98", "0.000085"], ["84449.11", "0.000028"], ["84449.34", "0.000010"], ["84450.00", "0.010457"], ["84451.88", "0.000010"], ["84452.66", "0.000009"], ["84453.76", "0.000054"], ["84454.43", "0.000061"], ["84454.53", "0.000019"], ["84454.55", "0.000083"], ["84454.60", "0.000093"], ["84455.31", "0.000028"], ["84456.14", "0.000033"], ["84456.52", "0.002633"], ["84457.00", "0.000009"], ["84458.06", "0.000020"], ["84458.72", "0.000072"], ["84458.82", "0.000071"], ["84458.97", "0.000153"], ["84459.08", "0.000008"], ["84459.22", "0.000188"], ["84459.69", "0.000051"], ["84460.00", "0.000622"], ["84460.23", "0.000010"], ["84460.49", "0.000009"], ["84460.87", "0.000069"], ["84460.91", "0.000012"], ["84461.00", "0.000008"], ["84462.50", "0.000076"], ["84464.28", "0.000008"], ["84465.83", "0.000016"], ["84466.67", "0.000157"], ["84470.34", "0.000017"], ["84470.59", "0.000071"], ["84473.14", "0.000126"], ["84473.68", "0.000192"], ["84474.78", "0.000099"], ["84475.00", "0.009271"], ["84475.81", "0.000039"], ["84476.97", "0.000063"], ["84477.61", "0.000095"], ["84477.67", "0.000008"], ["84478.74", "0.000036"], ["84479.37", "0.000090"], ["84480.00", "0.003246"], ["84481.00", "0.000069"], ["84481.77", "0.000011"], ["84482.67", "0.000133"], ["84482.76", "0.000016"], ["84485.20", "0.000537"], ["84485.39", "0.000020"], ["84485.71", "0.000128"], ["84485.98", "0.000034"], ["84486.49", "0.000009"], ["84486.82", "0.000135"], ["84487.00", "0.000119"], ["84487.16", "0.000035"], ["84487.32", "0.000024"], ["84487.95", "0.000008"], ["84488.88", "0.000025"], ["84489.36", "0.000137"], ["84489.39", "0.000039"], ["84489.80", "0.000010"], ["84490.00", "0.007510"], ["84490.13", "0.000093"], ["84490.91", "0.000018"], ["84491.26", "0.000008"], ["84491.87", "0.000019"], ["84492.06", "0.000009"], ["84496.43", "0.000273"], ["84496.66", "0.004837"], ["84496.73", "0.000043"], ["84497.14", "0.000008"], ["84497.26", "0.000010"], ["84500.00", "0.124015"], ["84500.03", "0.000010"], ["84500.04", "0.000008"], ["84500.11", "0.000012"], ["84501.24", "0.000010"], ["84501.28", "0.000019"], ["84501.32", "0.000326"], ["84501.99", "0.000009"], ["84503.33", "0.010000"], ["84503.57", "0.000074"], ["84504.50", "0.000051"], ["84504.74", "0.000013"], ["84506.54", "0.000008"], ["84508.00", "0.001210"], ["84508.37", "0.000050"], ["84508.46", "0.000013"], ["84508.47", "0.000023"], ["84510.00", "0.000805"], ["84510.34", "0.000135"], ["84512.00", "0.000012"], ["84512.19", "0.000016"], ["84512.61", "0.041940"], ["84512.95", "0.000023"], ["84514.29", "0.000059"], ["84516.67", "0.000010"], ["84517.54", "0.000022"], ["84517.86", "0.000016"]], "bids": [["84029.40", "1.003449"], ["84029.39", "0.000100"], ["84029.38", "0.006024"], ["84029.37", "0.010106"], ["84029.20", "0.088474"], ["84028.51", "0.007470"], ["84028.49", "0.007798"], ["84028.46", "0.009719"], ["84028.45", "0.008242"], ["84028.44", "0.009592"], ["84028.39", "0.007755"], ["84028.21", "0.190916"], ["84027.20", "0.232826"], ["84027.00", "0.000032"], ["84026.00", "0.000032"], ["84025.23", "0.010340"], ["84025.20", "0.612700"], ["84025.19", "0.008716"], ["84025.00", "0.000032"], ["84024.32", "0.005173"], ["84024.30", "0.005121"], ["84024.26", "0.008539"], ["84024.25", "0.005585"], ["84024.24", "0.009868"], ["84024.23", "0.004829"], ["84024.00", "0.000032"], ["84023.49", "1.282661"], ["84023.20", "1.612369"], ["84023.00", "0.000032"], ["84022.84", "3.053422"], ["84022.00", "0.000032"], ["84021.58", "0.209200"], ["84021.20", "4.243076"], ["84021.00", "0.000032"], ["84020.00", "0.001263"], ["84019.20", "11.165859"], ["84019.15", "0.314146"], ["84019.10", "0.075180"], ["84019.00", "0.006060"], ["84018.90", "0.120000"], ["84018.50", "0.884550"], ["84018.10", "2.596740"], ["84018.00", "0.000032"], ["84017.90", "0.567780"], ["84017.60", "0.066690"], ["84017.00", "0.000032"], ["84016.00", "0.000032"], ["84015.90", "0.139170"], ["84015.80", "0.356880"], ["84015.60", "0.070020"], ["84015.54", "0.006203"], ["84015.20", "0.215850"], ["84015.10", "0.356880"], ["84015.00", "0.000956"], ["84014.70", "0.120000"], ["84014.42", "0.014857"], ["84014.41", "0.005773"], ["84014.40", "0.269760"], ["84014.27", "0.008273"], ["84014.20", "2.943990"], ["84014.00", "0.000032"], ["84013.90", "0.090600"], ["84013.80", "0.120000"], ["84013.40", "0.178440"], ["84013.17", "0.209200"], ["84013.00", "0.178440"], ["84012.90", "0.120000"], ["84012.80", "0.017820"], ["84012.60", "0.008064"], ["84012.50", "0.035850"], ["84012.10", "0.120000"], ["84012.00", "0.000032"], ["84011.90", "0.178440"], ["84011.70", "0.428250"], ["84011.50", "0.120000"], ["84011.39", "0.089521"], ["84011.30", "0.178440"], ["84011.20", "0.793140"], ["84011.00", "0.000032"], ["84010.98", "0.247687"], ["84010.79", "0.000957"], ["84010.00", "0.000032"], ["84009.80", "0.153580"], ["84009.72", "0.083974"], ["84009.31", "0.017824"], ["84009.20", "0.018262"], ["84009.00", "0.000032"], ["84008.79", "0.005949"], ["84008.00", "0.000032"], ["84007.68", "0.055678"], ["84007.46", "0.017110"], ["84007.28", "0.007134"], ["84007.19", "0.008431"], ["84007.11", "0.008019"], ["84007.07", "0.006475"], ["84007.03", "0.008601"], ["84007.00", "0.000032"], ["84006.98", "0.013224"], ["84006.83", "0.028876"], ["84006.78", "0.007342"], ["84006.73", "0.004019"], ["84006.28", "0.008998"], ["84006.27", "0.007946"], ["84006.00", "0.000032"], ["84005.96", "0.224973"], ["84005.93", "0.025195"], ["84005.78", "0.008188"], ["84005.77", "0.017358"], ["84005.54", "0.009215"], ["84005.53", "0.006908"], ["84005.45", "0.007308"], ["84005.00", "0.000032"], ["84004.76", "0.209200"], ["84004.31", "0.012660"], ["84004.26", "0.055959"], ["84004.00", "0.000032"], ["84003.42", "0.018524"], ["84003.00", "0.000032"], ["84002.50", "0.268485"], ["84002.00", "0.000032"], ["84001.50", "0.222759"], ["84001.23", "0.259901"], ["84001.01", "0.076143"], ["84001.00", "0.000032"], ["84000.96", "0.000200"], ["84000.90", "0.021138"], ["84000.00", "0.003139"], ["83999.60", "0.000396"], ["83999.00", "0.000032"], ["83998.42", "0.005055"], ["83998.35", "0.008268"], ["83998.26", "0.008097"], ["83998.00", "0.000032"], ["83997.06", "0.073244"], ["83997.00", "0.000032"], ["83996.27", "0.056390"], ["83996.00", "0.000032"], ["83995.80", "0.923521"], ["83995.00", "0.000032"], ["83994.64", "0.000877"], ["83994.00", "0.000032"], ["83993.00", "0.000032"], ["83992.00", "0.000032"], ["83991.00", "0.000032"], ["83990.00", "0.000032"], ["83989.00", "0.000032"], ["83988.00", "0.000032"], ["83987.55", "0.017457"], ["83987.00", "0.000032"], ["83986.40", "0.209200"], ["83986.00", "0.000032"], ["83985.00", "0.000956"], ["83984.00", "0.000032"], ["83983.00", "0.000032"], ["83982.60", "0.007438"], ["83982.00", "0.000032"], ["83981.00", "0.000032"], ["83980.30", "0.199851"], ["83980.00", "0.001263"], ["83979.75", "0.008575"], ["83979.00", "0.000032"], ["83978.56", "0.007340"], ["83978.50", "0.007252"], ["83978.49", "0.007656"], ["83977.20", "4.985024"], ["83977.08", "0.001176"], ["83976.32", "0.003598"], ["83975.60", "0.209200"], ["83975.15", "0.001173"], ["83972.31", "0.071253"], ["83970.20", "0.000948"], ["83970.00", "0.004067"], ["83968.70", "5.347571"], ["83964.20", "0.209200"], ["83960.20", "5.166297"], ["83960.00", "0.001231"], ["83957.16", "0.071045"], ["83955.00", "0.000924"], ["83951.70", "4.259930"], ["83951.58", "0.057001"], ["83951.10", "0.209200"], ["83950.44", "0.005950"], ["83949.70", "0.001810"], ["83946.24", "0.010010"], ["83943.20", "4.169293"], ["83941.30", "0.003620"], ["83940.00", "0.003231"], ["83938.51", "0.209200"], ["83936.10", "0.012367"], ["83934.70", "5.256934"], ["83926.20", "3.988019"], ["83925.07", "0.209200"], ["83920.00", "0.001231"], ["83919.20", "0.306923"], ["83917.70", "5.438208"], ["83917.50", "0.001459"], ["83915.77", "0.209200"], ["83910.54", "0.125658"], ["83910.00", "0.002924"], ["83909.20", "4.803750"], ["83907.35", "0.209200"], ["83903.24", "0.024945"], ["83900.70", "5.075661"], ["83898.93", "0.209200"], ["83895.00", "0.000924"], ["83892.20", "4.531840"], ["83890.51", "0.209200"], ["83883.70", "4.350566"], ["83882.09", "0.209200"], ["83880.00", "0.003231"], ["83877.01", "0.000023"], ["83876.01", "0.005960"], ["83875.20", "4.713114"], ["83875.16", "0.000179"], ["83875.00", "0.000704"], ["83873.68", "0.209200"], ["83873.52", "0.000135"], ["83868.80", "0.296868"], ["83868.70", "0.001444"], ["83868.39", "0.002014"], ["83866.70", "4.894387"], ["83866.67", "0.002945"], ["83865.27", "0.209200"], ["83865.00", "0.000924"], ["83862.50", "0.006969"], ["83860.29", "0.000041"], ["83860.00", "0.001234"], ["83859.54", "0.000008"], ["83858.20", "3.897382"], ["83857.14", "0.000079"], ["83857.13", "0.000019"], ["83856.86", "0.209200"], ["83856.11", "0.010000"], ["83854.55", "0.000009"], ["83854.17", "0.000020"], ["83852.94", "0.000071"], ["83852.50", "0.000043"], ["83851.85", "0.000011"], ["83851.84", "0.000219"], ["83850.00", "0.003028"], ["83849.70", "5.528845"], ["83848.45", "0.209200"], ["83848.39", "0.000020"], ["83848.00", "0.001184"], ["83846.15", "0.000111"], ["83844.83", "0.000008"], ["83843.10", "0.001475"], ["83842.11", "0.000033"], ["83841.20", "4.622477"], ["83841.18", "0.000071"], ["83840.04", "0.209200"], ["83840.00", "0.001282"], ["83839.72", "0.000033"], ["83839.18", "0.000016"], ["83837.84", "0.000009"], ["83837.59", "0.000012"], ["83836.36", "0.000008"], ["83835.56", "0.000009"], ["83835.24", "0.001720"], ["83835.00", "0.000926"], ["83832.70", "4.078656"], ["83831.11", "0.000011"], ["83830.59", "0.000010"], ["83830.00", "0.000063"], ["83828.57", "0.000016"], ["83826.80", "0.303314"], ["83826.67", "0.000073"], ["83825.00", "0.000672"], ["83824.20", "4.441203"], ["83822.12", "0.000067"], ["83820.00", "0.003247"], ["83818.18", "0.001526"], ["83818.17", "0.000029"], ["83816.67", "0.000010"], ["83816.28", "0.000009"], ["83816.00", "0.000008"], ["83815.79", "0.000022"], ["83815.75", "0.000009"], ["83815.70", "5.619481"], ["83815.37", "0.000022"], ["83813.00", "0.000113"], ["83810.74", "0.000019"], ["83808.53", "0.000039"], ["83808.51", "0.000137"], ["83807.88", "0.000051"], ["83807.53", "0.000010"], ["83805.00", "0.000926"], ["83804.35", "0.000010"], ["83803.57", "0.000016"], ["83802.81", "0.000022"], ["83800.91", "0.000012"], ["83800.00", "0.039884"], ["83799.34", "0.000093"], ["83796.61", "0.001213"], ["83795.00", "0.000031"], ["83794.17", "0.000096"], ["83793.10", "0.000016"], ["83791.03", "0.000996"], ["83791.02", "0.000632"], ["83790.15", "0.000024"], ["83790.00", "0.003033"], ["83789.60", "0.000363"], ["83789.29", "0.000074"], ["83788.72", "0.000254"], ["83787.88", "0.000010"], ["83785.71", "0.000081"], ["83784.62", "0.000015"], ["83784.36", "0.000069"], ["83784.02", "0.000022"], ["83783.78", "0.000059"], ["83783.12", "0.000008"], ["83780.48", "0.000016"], ["83780.00", "0.001547"], ["83779.93", "0.000028"], ["83778.35", "0.011010"], ["83777.78", "0.000679"], ["83777.60", "0.000013"], ["83777.18", "0.000013"], ["83775.00", "0.009183"], ["83774.10", "0.000161"], ["83773.31", "0.000154"], ["83773.11", "0.041940"], ["83772.88", "0.000023"], ["83769.28", "0.000972"], ["83768.46", "0.000008"], ["83768.00", "0.000012"], ["83766.84", "0.000023"], ["83765.06", "0.000008"], ["83764.71", "0.000071"], ["83763.64", "0.000010"], ["83762.50", "0.000076"], ["83761.90", "0.000024"], ["83761.29", "0.000020"], ["83760.00", "0.001718"], ["83758.93", "0.000036"], ["83758.00", "0.000353"], ["83757.40", "0.000537"], ["83756.08", "0.000099"], ["83755.56", "0.000134"], ["83754.70", "0.000013"], ["83754.39", "0.000033"], ["83752.94", "0.000071"], ["83752.37", "0.000119"], ["83752.09", "0.000314"], ["83752.00", "0.000034"], ["83750.67", "0.000146"], ["83750.00", "0.041680"], ["83749.66", "0.000016"], ["83749.50", "0.000069"], ["83749.33", "0.000133"], ["83748.54", "0.000012"], ["83746.09", "0.000010"], ["83745.16", "0.000389"], ["83745.00", "0.000926"], ["83743.29", "0.001451"], ["83740.51", "0.000423"], ["83740.00", "0.001311"], ["83739.60", "0.000048"], ["83739.28", "0.000051"], ["83739.13", "0.000008"], ["83737.93", "0.000135"], ["83737.37", "0.000012"], ["83737.00", "0.000009"], ["83736.94", "0.000104"], ["83736.84", "0.000183"], ["83736.33", "0.000025"], ["83734.69", "0.000085"], ["83733.33", "0.003222"], ["83732.10", "0.000009"], ["83731.48", "0.000124"], ["83730.00", "0.002926"], ["83729.73", "0.000009"], ["83729.39", "0.000008"], ["83729.32", "0.000035"], ["83728.57", "0.000017"], ["83728.37", "0.001273"], ["83728.07", "0.000022"], ["83727.71", "0.000009"], ["83727.27", "0.000082"], ["83726.20", "0.000016"], ["83725.07", "1.657985"], ["83725.00", "0.002501"], ["83723.72", "0.000176"], ["83723.64", "0.000009"], ["83723.61", "0.000883"], ["83723.43", "0.000039"], ["83723.40", "0.000205"], ["83721.56", "0.000015"], ["83720.00", "0.003671"], ["83719.46", "0.000053"], ["83718.75", "0.000012"], ["83717.93", "0.000065"], ["83717.46", "0.000009"], ["83717.45", "0.000040"], ["83717.39", "0.000010"], ["83715.48", "0.000010"], ["83715.00", "0.000926"], ["83714.29", "0.009987"], ["83714.28", "0.000836"], ["83713.80", "0.000024"], ["83713.71", "0.000323"], ["83713.40", "0.000161"], ["83711.93", "0.000018"], ["83710.00", "0.000023"], ["83709.88", "0.000107"], ["83707.07", "0.000067"], ["83706.90", "0.000016"], ["83706.67", "0.000013"], ["83705.85", "0.000019"], ["83705.32", "0.000065"], ["83705.18", "0.000009"], ["83703.75", "0.000364"], ["83703.70", "0.000499"], ["83703.00", "0.000024"], ["83702.93", "0.000050"], ["83702.60", "0.000039"], ["83702.50", "0.000033"], ["83702.48", "0.000057"], ["83701.92", "0.000067"], ["83701.28", "0.000248"], ["83700.70", "0.511700"], ["83700.00", "0.007170"], ["83699.88", "0.000008"], ["83699.00", "0.002419"], ["83697.23", "0.000095"], ["83695.65", "0.003535"], ["83695.63", "0.000011"], ["83693.69", "0.000051"], ["83693.28", "0.001536"], ["83692.52", "0.000066"], ["83692.38", "0.000007"], ["83692.31", "0.000031"], ["83691.74", "0.000653"], ["83690.84", "0.000162"], ["83690.48", "0.000248"], ["83689.78", "0.001684"], ["83689.50", "0.000113"], ["83688.89", "0.000009"], ["83688.07", "0.000072"], ["83687.50", "0.006969"], ["83687.00", "0.000008"], ["83686.11", "0.000096"], ["83685.00", "0.000926"], ["83684.21", "0.000102"], ["83683.67", "0.000184"], ["83681.82", "0.000175"], ["83680.67", "0.041940"], ["83680.00", "0.001718"], ["83679.44", "0.000361"], ["83678.41", "0.000010"], ["83678.08", "0.000145"], ["83677.37", "0.000008"], ["83676.47", "0.000080"], ["83675.68", "0.000008"], ["83675.62", "0.000011"], ["83675.36", "0.000013"], ["83675.20", "0.000018"], ["83675.00", "0.002674"], ["83674.70", "0.000008"], ["83674.19", "0.000020"], ["83674.00", "0.001195"], ["83673.87", "0.000022"], ["83673.58", "0.000023"], ["83672.96", "0.002168"], ["83672.50", "0.000031"], ["83672.25", "0.004023"], ["83672.00", "0.000035"], ["83671.36", "0.000099"], ["83670.59", "0.000105"], ["83670.05", "0.000033"], ["83670.00", "0.004426"], ["83669.66", "0.000010"], ["83669.58", "0.000251"], ["83669.09", "0.000135"], ["83667.80", "0.000023"], ["83667.23", "0.012503"], ["83666.67", "0.052199"], ["83666.66", "0.000513"], ["83666.65", "0.000122"], ["83666.00", "0.271427"], ["83664.71", "0.000071"], ["83664.19", "0.000073"], ["83663.98", "0.000008"], ["83663.95", "0.000022"], ["83663.91", "0.000161"], ["83662.50", "0.000077"], ["83661.97", "0.000052"], ["83661.60", "0.000042"], ["83661.08", "0.004152"], ["83660.71", "0.000309"], ["83660.14", "0.000016"], ["83660.00", "0.001273"], ["83659.61", "0.000454"], ["83659.49", "0.000012"], ["83659.44", "0.000613"], ["83658.54", "0.000036"], ["83656.60", "0.000607"], ["83655.00", "0.000926"], ["83654.23", "0.000009"], ["83653.94", "0.000133"]], "checksum": 0, "ts": "1742555346118"}], "ts": 1742555346301}}
{"exchange": "BITGET", "timestamp": 1742555346.385767, "message": {"action": "update", "arg": {"instType": "SPOT", "channel": "books", "instId": "BTCUSDT"}, "data": [{"asks": [["84030.45", "0.088149"], ["84030.49", "0"], ["84090.73", "0.045761"], ["84105.30", "0.001020"], ["84106.70", "0.515460"], ["84107.40", "0.022680"], ["84108.10", "0.067800"], ["84109.00", "0.513540"], ["84109.90", "0"], ["84110.30", "0"], ["84117.10", "0"], ["84145.40", "5.438208"], ["84153.90", "5.347571"], ["84162.40", "4.078656"], ["84179.40", "5.619481"], ["84187.90", "4.531840"], ["84196.40", "4.441203"], ["84204.90", "3.988019"], ["84213.40", "5.528845"], ["84221.90", "4.169293"], ["84230.40", "4.622477"], ["84238.90", "4.713114"], ["84247.40", "5.075661"], ["84255.90", "3.897382"], ["84264.40", "5.166297"], ["84272.90", "4.985024"], ["84281.40", "4.259930"], ["84289.90", "4.350566"], ["84298.40", "4.803750"], ["84306.90", "4.894387"]], "bids": [["84029.20", "0.085288"], ["84027.20", "0.224442"], ["84025.20", "0.590636"], ["84023.49", "0.174386"], ["84023.20", "1.554307"], ["84021.20", "4.090280"], ["84019.20", "10.763894"], ["84018.90", "0.120390"], ["84018.50", "1.285290"], ["84018.10", "2.597100"], ["84018.00", "0.120000"], ["84017.90", "0.389340"], ["84016.20", "0.022770"], ["84015.80", "0"], ["84015.50", "0.655320"], ["84015.10", "0.374700"], ["84013.90", "0.187800"], ["84012.10", "0"], ["84011.90", "0"], ["84011.60", "0.178440"], ["84011.30", "0"], ["84011.20", "0"], ["84009.40", "0.004019"], ["84006.73", "0"], ["83977.20", "4.350566"], ["83968.70", "4.531840"], ["83960.20", "4.259930"], ["83951.70", "4.622477"], ["83943.20", "4.441203"], ["83934.70", "5.166297"], ["83926.20", "4.985024"], ["83917.70", "3.897382"], ["83900.70", "5.256934"], ["83892.20", "5.438208"], ["83883.70", "5.619481"], ["83875.20", "4.169293"], ["83866.70", "5.528845"], ["83858.20", "4.894387"], ["83849.70", "5.075661"], ["83841.20", "4.713114"], ["83824.20", "3.988019"], ["83815.70", "5.347571"], ["83653.67", "0.001695"], ["83653.31", "0.000015"]], "checksum": 2020907220, "ts": "1742555346320"}], "ts": 1742555346323}}
{"exchange": "BYBIT", "timestamp": 1742555346.539965, "message": {"topic": "orderbook.200.BTCUSDT", "ts": 1742555346520, "type": "delta", "data": {"s": "BTCUSDT", "b": [["84061.2", "0.072663"], ["84048.5", "0"], ["84041.5", "0"], ["84034.5", "0"], ["84033.5", "0.191738"], ["84024.4", "0"], ["84024.3", "0.048729"], ["84024.1", "0.013"], ["84024", "0.012881"], ["84017.5", "0"], ["84006.2", "17.629315"], ["83983.2", "0.160747"]], "a": [["84061.7", "0.084706"], ["84071.3", "0"], ["84075.1", "0"], ["84077.7", "0"], ["84080.8", "0.112625"], ["84083.5", "0"], ["84090.5", "0"], ["84097.5", "0.118804"], ["84104.8", "0.118804"], ["84104.9", "0"], ["84105.7", "0.013518"], ["84105.8", "0.012845"], ["84106.6", "0.04"], ["84106.7", "0.04"], ["84119.1", "2.25704"], ["84134.2", "0.000423"], ["84134.3", "0.001466"]], "u": 20667, "seq": 67549988241}, "cts": 1742555346509}}
{"exchange": "BITGET", "timestamp": 1742555346.561282, "message": {"action": "update", "arg": {"instType": "SPOT", "channel": "books", "instId": "BTCUSDT"}, "data": [{"asks": [["84029.41", "0.333484"], ["84040.69", "0"], ["84053.10", "0"], ["84063.35", "0.017455"], ["84087.14", "0"], ["84105.30", "0"], ["84106.70", "0.016470"], ["84107.60", "0.015000"], ["84108.10", "0"], ["84109.00", "0"], ["84111.70", "0.193920"], ["84112.30", "0"], ["84112.60", "0"], ["84116.00", "0.024390"], ["84116.60", "0"], ["84117.10", "0.107070"], ["84117.30", "2.674740"], ["84117.60", "0.609030"], ["84145.40", "4.078656"], ["84153.90", "4.622477"], ["84162.40", "4.985024"], ["84170.90", "5.619481"], ["84179.40", "4.259930"], ["84187.90", "5.528845"], ["84196.40", "5.166297"], ["84204.90", "5.256934"], ["84213.40", "5.438208"], ["84221.90", "3.988019"], ["84230.40", "4.894387"], ["84238.90", "3.897382"], ["84247.40", "5.347571"], ["84255.90", "4.169293"], ["84264.40", "4.350566"], ["84272.90", "4.441203"], ["84281.40", "4.713114"], ["84289.90", "4.531840"], ["84298.40", "5.075661"], ["84306.90", "4.803750"], ["84518.98", "0.000029"], ["84520.00", "0.000854"], ["84520.50", "0.000238"], ["84520.67", "0.002384"], ["84521.85", "0.000033"]], "bids": [["84029.20", "0.087557"], ["84027.20", "0.230413"], ["84025.20", "0.606350"], ["84023.49", "1.967720"], ["84023.20", "1.595657"], ["84021.20", "4.199099"], ["84019.20", "11.050260"], ["84018.00", "0.120180"], ["83997.80", "0.017455"], ["83987.55", "0"], ["83978.00", "0.000017"], ["83977.20", "5.528845"], ["83968.70", "5.166297"], ["83960.20", "3.897382"], ["83951.70", "4.985024"], ["83943.20", "4.169293"], ["83934.70", "5.619481"], ["83926.20", "4.259930"], ["83917.70", "4.803750"], ["83909.20", "4.894387"], ["83900.70", "5.347571"], ["83892.20", "3.988019"], ["83883.70", "4.350566"], ["83875.20", "4.713114"], ["83866.70", "4.441203"], ["83858.20", "4.622477"], ["83849.70", "4.531840"], ["83841.20", "4.078656"], ["83832.70", "5.075661"], ["83824.20", "5.438208"], ["83815.70", "5.256934"], ["83653.31", "0"]], "checksum": 1745617950, "ts": "1742555346522"}], "ts": 1742555346527}}
{"exchange": "BYBIT", "timestamp": 1742555346.739444, "message": {"topic": "orderbook.200.BTCUSDT", "ts": 1742555346719, "type": "delta", "data": {"s": "BTCUSDT", "b": [["84061.9", "0.343837"], ["84061.7", "0.056085"], ["84061.6", "0.171"], ["84061.2", "0.0006"], ["84061.1", "0.00132"], ["84057.5", "0.003214"], ["84056.9", "0.0025"], ["84056.6", "0"], ["84053.5", "0.01"], ["84053.2", "0.008213"], ["84048.7", "0.065394"], ["84045.3", "0"], ["84041.7", "0.058199"], ["84034.7", "0.112482"], ["84024.2", "0.014333"], ["84024.1", "0.012881"], ["84024", "0"], ["83984.4", "0"], ["83984", "0"], ["83983.2", "0"]], "a": [["84061.7", "0"], ["84062", "0.026194"], ["84066.7", "0"], ["84067", "0.0025"], ["84070.1", "0.003214"], ["84070.4", "0.016333"], ["84079.9", "0.026194"], ["84080", "0.00024"], ["84083.7", "0.055152"], ["84084.9", "0.004043"], ["84090.7", "0.27181"], ["84097.4", "0.057349"], ["84097.7", "0.121131"], ["84105.6", "0.028"], ["84105.7", "0.013363"], ["84105.8", "0"], ["84134.3", "0"]], "u": 20668, "seq": 67549988403}, "cts": 1742555346705}}
{"exchange": "BITGET", "timestamp": 1742555346.752821, "message": {"action": "update", "arg": {"instType": "SPOT", "channel": "books", "instId": "BTCUSDT"}, "data": [{"asks": [["84029.41", "0.333514"], ["84030.45", "0"], ["84043.79", "0.112625"], ["84063.34", "0.013301"], ["84065.95", "0"], ["84085.39", "0.001244"], ["84101.40", "0.095389"], ["84103.40", "0.251026"], ["84105.40", "0.001041"], ["84106.70", "0.040050"], ["84111.70", "0.319440"], ["84112.30", "0.499230"], ["84117.50", "0.070080"], ["84145.40", "4.713114"], ["84153.90", "5.166297"], ["84162.40", "4.803750"], ["84170.90", "5.347571"], ["84179.40", "5.256934"], ["84187.90", "3.988019"], ["84196.40", "5.619481"], ["84204.90", "4.441203"], ["84213.40", "4.259930"], ["84221.90", "4.985024"], ["84230.40", "4.350566"], ["84238.90", "5.528845"], ["84247.40", "4.894387"], ["84255.90", "4.622477"], ["84264.40", "5.075661"], ["84272.90", "4.169293"], ["84281.40", "5.438208"], ["84289.90", "3.897382"], ["84298.40", "4.078656"], ["84306.90", "4.531840"], ["84520.50", "0"], ["84520.67", "0"], ["84521.85", "0"]], "bids": [["84011.80", "0.452010"], ["84011.50", "0"], ["83978.17", "0.003598"], ["83978.00", "0.000032"], ["83977.20", "4.169293"], ["83976.32", "0"], ["83968.70", "4.531840"], ["83960.20", "4.713114"], ["83951.70", "3.897382"], ["83943.20", "4.259930"], ["83934.70", "4.078656"], ["83926.20", "5.256934"], ["83917.70", "5.347571"], ["83909.20", "4.985024"], ["83900.70", "4.894387"], ["83892.20", "5.528845"], ["83875.20", "5.166297"], ["83866.70", "4.803750"], ["83858.20", "5.438208"], ["83849.70", "5.619481"], ["83841.20", "4.441203"], ["83824.20", "4.622477"], ["83815.70", "3.988019"]], "checksum": 89035240, "ts": "1742555346724"}], "ts": 1742555346726}}
{"exchange": "BYBIT", "timestamp": 1742555346.939281, "message": {"topic": "orderbook.200.BTCUSDT", "ts": 1742555346919, "type": "delta", "data": {"s": "BTCUSDT", "b": [["84061.9", "0.343911"], ["84053.5", "0.015"], ["84053.2", "0.003213"], ["84017.5", "17.629315"], ["84006.2", "0"], ["83990.6", "1.126459"]], "a": [["84072.6", "0.00599"], ["84074.2", "0.005509"], ["84074.5", "0"], ["84084.9", "0"], ["84106.5", "0.041466"], ["84106.7", "0"], ["84134.3", "0.001466"], ["84137.1", "0.4"]], "u": 20669, "seq": 67549988428}, "cts": 1742555346914}}
{"exchange": "BITGET", "timestamp": 1742555346.954596, "message": {"action": "update", "arg": {"instType": "SPOT", "channel": "books", "instId": "BTCUSDT"}, "data": [{"asks": [["84030.42", "0.088149"], ["84043.78", "0.033788"], ["84097.40", "0.013729"], ["84101.40", "0.095071"], ["84103.40", "0.250189"], ["84106.70", "0.040230"], ["84111.70", "1.370850"], ["84111.90", "0.430830"], ["84112.30", "0"], ["84117.10", "0"], ["84117.20", "0.107070"], ["84117.60", "0.534660"], ["84145.40", "5.166297"], ["84153.90", "5.347571"], ["84162.40", "4.078656"], ["84170.90", "4.713114"], ["84179.40", "5.619481"], ["84187.90", "3.897382"], ["84196.40", "4.803750"], ["84204.90", "4.259930"], ["84213.40", "4.350566"], ["84221.90", "5.256934"], ["84230.40", "4.169293"], ["84238.90", "4.531840"], ["84247.40", "4.622477"], ["84255.90", "5.075661"], ["84264.40", "4.441203"], ["84272.90", "5.528845"], ["84281.40", "4.985024"], ["84289.90", "5.438208"], ["84298.40", "3.988019"], ["84306.90", "4.894387"], ["84518.98", "0"], ["84520.00", "0"]], "bids": [["84021.20", "4.198972"], ["84019.20", "11.049739"], ["84011.80", "0"], ["84011.50", "0.120000"], ["83977.20", "4.531840"], ["83968.70", "4.169293"], ["83960.20", "4.803750"], ["83951.70", "4.985024"], ["83943.20", "5.528845"], ["83934.70", "4.894387"], ["83926.20", "5.166297"], ["83909.20", "5.075661"], ["83900.70", "3.897382"], ["83892.20", "4.441203"], ["83883.70", "5.619481"], ["83875.20", "4.259930"], ["83866.70", "4.078656"], ["83858.20", "4.622477"], ["83849.70", "5.438208"], ["83841.20", "5.256934"], ["83832.70", "4.713114"], ["83824.20", "4.350566"]], "checksum": 489548967, "ts": "1742555346924"}], "ts": 1742555346928}}
{"exchange": "BITGET", "timestamp": 1742555347.268447, "message": {"action": "update", "arg": {"instType": "SPOT", "channel": "books", "instId": "BTCUSDT"}, "data": [{"asks": [["84029.41", "0.333497"], ["84080.97", "0"], ["84104.10", "0.001010"], ["84105.40", "0"], ["84109.90", "0.788610"], ["84111.70", "0.339450"], ["84112.60", "0.073950"], ["84116.00", "0.035670"], ["84117.60", "0"], ["84145.40", "5.438208"], ["84153.90", "4.894387"], ["84162.40", "4.803750"], ["84170.90", "4.441203"], ["84179.40", "4.078656"], ["84187.90", "4.985024"], ["84196.40", "3.988019"], ["84204.90", "4.169293"], ["84213.40", "4.259930"], ["84221.90", "5.166297"], ["84230.40", "5.075661"], ["84247.40", "5.347571"], ["84255.90", "4.622477"], ["84264.40", "5.256934"], ["84281.40", "4.350566"], ["84289.90", "5.619481"], ["84298.40", "4.713114"], ["84306.90", "3.897382"]], "bids": [["83979.00", "0.000015"], ["83977.20", "3.988019"], ["83968.70", "5.438208"], ["83960.20", "5.256934"], ["83951.70", "5.347571"], ["83943.20", "4.531840"], ["83926.20", "4.803750"], ["83917.70", "4.713114"], ["83909.20", "4.441203"], ["83892.20", "4.622477"], ["83883.70", "5.528845"], ["83875.20", "5.166297"], ["83866.70", "5.075661"], ["83858.20", "4.259930"], ["83849.70", "4.169293"], ["83841.20", "4.350566"], ["83832.70", "4.985024"], ["83824.20", "4.078656"], ["83815.70", "5.619481"]], "checksum": 816484471, "ts": "1742555347137"}], "ts": 1742555347140}}
{"exchange": "BYBIT", "timestamp": 1742555347.353971, "message": {"topic": "orderbook.200.BTCUSDT", "ts": 1742555347320, "type": "delta", "data": {"s": "BTCUSDT", "b": [["84061.1", "0.0006"], ["84025", "0.128733"]], "a": [], "u": 20670, "seq": 67549988452}, "cts": 1742555347288}}
{"exchange": "BITGET", "timestamp": 1742555347.377373, "message": {"action": "update", "arg": {"instType": "SPOT", "channel": "books", "instId": "BTCUSDT"}, "data": [{"asks": [["84030.38", "0.088149"], ["84030.42", "0"], ["84081.92", "0.177978"], ["84103.40", "0.250300"], ["84104.10", "0"], ["84106.70", "0.040650"], ["84107.40", "0"], ["84108.50", "2.356590"], ["84108.90", "0.022620"], ["84112.90", "0.499230"], ["84145.40", "4.622477"], ["84153.90", "5.347571"], ["84162.40", "4.985024"], ["84170.90", "4.259930"], ["84179.40", "4.350566"], ["84187.90", "3.897382"], ["84196.40", "4.894387"], ["84204.90", "4.531840"], ["84213.40", "4.803750"], ["84221.90", "3.988019"], ["84230.40", "5.619481"], ["84238.90", "5.166297"], ["84240.71", "0"], ["84247.40", "5.438208"], ["84255.90", "4.713114"], ["84281.40", "5.075661"], ["84289.90", "4.078656"], ["84298.40", "4.441203"], ["84306.90", "4.169293"], ["84518.98", "0.000029"]], "bids": [["84012.50", "0.487860"], ["84011.60", "0"], ["84011.50", "0"], ["83977.20", "5.166297"], ["83968.70", "4.169293"], ["83960.20", "5.619481"], ["83943.20", "4.985024"], ["83926.20", "5.256934"], ["83917.70", "3.988019"], ["83909.20", "5.528845"], ["83900.70", "4.803750"], ["83892.20", "4.078656"], ["83883.70", "4.713114"], ["83875.20", "4.622477"], ["83866.70", "3.897382"], ["83849.70", "5.075661"], ["83832.70", "4.531840"], ["83824.20", "5.438208"], ["83815.70", "4.441203"], ["83653.31", "0.000015"], ["83652.80", "0.000119"]], "checksum": -576566705, "ts": "1742555347342"}], "ts": 1742555347344}}
{"exchange": "BYBIT", "timestamp": 1742555347.541484, "message": {"topic": "orderbook.200.BTCUSDT", "ts": 1742555347520, "type": "delta", "data": {"s": "BTCUSDT", "b": [["84061.9", "0.344711"], ["84060.5", "0.0037"], ["84055.2", "0"], ["84038.2", "0.177322"], ["84037.3", "0"], ["84031.8", "0.002016"], ["84026.5", "0.0045"]], "a": [["84105.7", "0.013362"]], "u": 20671, "seq": 67549988489}, "cts": 1742555347495}}
{"exchange": "BITGET", "timestamp": 1742555347.575669, "message": {"action": "update", "arg": {"instType": "SPOT", "channel": "books", "instId": "BTCUSDT"}, "data": [{"asks": [["84099.40", "0.036052"], ["84101.40", "0.094874"], ["84103.40", "0.249668"], ["84104.20", "0.001170"], ["84106.70", "0.040230"], ["84109.00", "0.984660"], ["84109.90", "0"], ["84117.50", "0"], ["84145.40", "4.713114"], ["84153.90", "3.897382"], ["84162.40", "4.078656"], ["84170.90", "4.894387"], ["84179.40", "5.619481"], ["84187.90", "5.075661"], ["84196.40", "4.441203"], ["84204.90", "5.438208"], ["84213.40", "5.347571"], ["84221.90", "4.622477"], ["84230.40", "4.169293"], ["84247.40", "4.985024"], ["84255.90", "4.531840"], ["84264.40", "3.988019"], ["84272.90", "4.803750"], ["84281.40", "5.256934"], ["84289.90", "4.259930"], ["84298.40", "5.528845"], ["84306.90", "4.350566"], ["84520.00", "0.000854"]], "bids": [["84021.20", "4.199085"], ["84019.20", "11.050223"], ["83979.00", "0"], ["83977.20", "4.894387"], ["83968.70", "5.438208"], ["83951.70", "4.622477"], ["83943.20", "5.075661"], ["83934.70", "4.259930"], ["83926.20", "4.985024"], ["83917.70", "5.528845"], ["83909.20", "4.531840"], ["83900.70", "4.169293"], ["83892.20", "5.166297"], ["83883.70", "4.803750"], ["83875.20", "4.713114"], ["83866.70", "5.256934"], ["83858.20", "4.350566"], ["83849.70", "3.897382"], ["83841.20", "4.441203"], ["83832.70", "5.347571"], ["83824.20", "3.988019"], ["83815.70", "4.078656"], ["83652.48", "0.000188"]], "checksum": -576566705, "ts": "1742555347545"}], "ts": 1742555347547}}
{"exchange": "BYBIT", "timestamp": 1742555347.740263, "message": {"topic": "orderbook.200.BTCUSDT", "ts": 1742555347720, "type": "delta", "data": {"s": "BTCUSDT", "b": [["84039.9", "0.026194"], ["84001.3", "0.294791"], ["83996", "0"]], "a": [], "u": 20672, "seq": 67549988500}, "cts": 1742555347672}}
{"exchange": "BITGET", "timestamp": 1742555347.777066, "message": {"action": "update", "arg": {"instType": "SPOT", "channel": "books", "instId": "BTCUSDT"}, "data": [{"asks": [["84030.38", "0"], ["84145.40", "5.528845"], ["84162.40", "4.622477"], ["84170.90", "5.166297"], ["84179.40", "4.894387"], ["84187.90", "5.256934"], ["84196.40", "4.713114"], ["84204.90", "4.803750"], ["84213.40", "5.438208"], ["84221.90", "5.347571"], ["84230.40", "4.350566"], ["84238.90", "4.985024"], ["84243.88", "0.162551"], ["84247.40", "4.259930"], ["84255.90", "3.988019"], ["84264.40", "4.531840"], ["84272.90", "4.169293"], ["84281.40", "5.075661"], ["84289.90", "4.441203"], ["84298.40", "5.619481"], ["84306.90", "4.078656"]], "bids": [["83977.20", "4.441203"], ["83977.00", "0.000017"], ["83968.70", "5.528845"], ["83960.20", "4.169293"], ["83951.70", "5.075661"], ["83943.20", "4.350566"], ["83934.70", "4.985024"], ["83926.20", "4.803750"], ["83917.70", "5.166297"], ["83909.20", "4.713114"], ["83900.70", "4.622477"], ["83892.20", "3.897382"], ["83883.70", "4.894387"], ["83875.20", "5.347571"], ["83866.70", "5.619481"], ["83858.20", "4.259930"], ["83849.70", "4.078656"], ["83841.20", "3.988019"], ["83832.70", "5.438208"], ["83824.20", "4.531840"], ["83815.70", "5.256934"], ["83652.48", "0"]], "checksum": -1752607416, "ts": "1742555347746"}], "ts": 1742555347750}}
{"exchange": "BYBIT", "timestamp": 1742555347.940422, "message": {"topic": "orderbook.200.BTCUSDT", "ts": 1742555347920, "type": "delta", "data": {"s": "BTCUSDT", "b": [["84061.9", "0.348279"], ["84061.7", "0.056285"], ["84060", "0.00006"], ["84053.9", "0.110429"], ["84053.8", "0.115882"], ["84052.8", "0"], ["84050.3", "0.100535"], ["84049.7", "0.117066"], ["84048.7", "0.005942"], ["84043.3", "0.174618"], ["84042.7", "0.176633"], ["84041.7", "0.000333"], ["84036.3", "0.277467"], ["84035.7", "0.290452"], ["84034.7", "0"], ["84024.2", "0.014214"], ["84011", "0"], ["83986.3", "0"], ["83986", "0"], ["83985.6", "0"], ["83984.6", "0"]], "a": [["84062", "0.029394"], ["84078.3", "0.124323"], ["84082.6", "0.109765"], ["84083.7", "0.000333"], ["84088.8", "0.171519"], ["84089.6", "0.175417"], ["84090.7", "0.217219"], ["84095.8", "0.298894"], ["84096.6", "0.279394"], ["84097.7", "0"], ["84106.4", "0.129099"], ["84106.6", "0"], ["84134.2", "0"], ["84134.3", "0"], ["84137.1", "0"]], "u": 20673, "seq": 67549988536}, "cts": 1742555347915}}
{"exchange": "BITGET", "timestamp": 1742555347.985019, "message": {"action": "update", "arg": {"instType": "SPOT", "channel": "books", "instId": "BTCUSDT"}, "data": [{"asks": [["84030.35", "0.088149"], ["84036.96", "0"], ["84037.81", "0"], ["84041.66", "0.000221"], ["84093.40", "0.002804"], ["84095.40", "0.007377"], ["84097.40", "0.019413"], ["84099.40", "0.051087"], ["84101.40", "0.134440"], ["84103.40", "0.353791"], ["84104.20", "0.001021"], ["84106.70", "2.397090"], ["84107.00", "1.065300"], ["84107.60", "0"], ["84108.50", "0"], ["84109.00", "0"], ["84110.10", "0.067980"], ["84110.70", "0.387600"], ["84111.90", "0"], ["84112.60", "0"], ["84117.50", "0.070080"], ["84117.60", "0.609030"], ["84117.90", "0.249120"], ["84145.40", "5.347571"], ["84153.90", "4.713114"], ["84162.40", "4.803750"], ["84170.90", "4.259930"], ["84179.40", "4.622477"], ["84187.90", "4.441203"], ["84196.40", "5.256934"], ["84204.90", "4.894387"], ["84213.40", "3.988019"], ["84221.90", "5.438208"], ["84230.40", "4.985024"], ["84238.90", "5.166297"], ["84247.40", "4.531840"], ["84255.90", "4.350566"], ["84264.40", "5.528845"], ["84272.90", "3.897382"], ["84281.40", "4.078656"], ["84289.90", "5.075661"], ["84306.90", "4.169293"], ["84520.50", "0.000238"]], "bids": [["84029.20", "0.085053"], ["84027.20", "0.223826"], ["84025.20", "0.589016"], ["84023.20", "1.550041"], ["84021.20", "4.079056"], ["84019.20", "10.734358"], ["84013.30", "0.015000"], ["84011.70", "0"], ["83977.20", "5.347571"], ["83968.70", "4.985024"], ["83960.20", "4.894387"], ["83951.70", "4.350566"], ["83943.20", "4.531840"], ["83934.70", "5.075661"], ["83926.20", "5.619481"], ["83917.70", "4.441203"], ["83909.20", "4.803750"], ["83900.70", "4.078656"], ["83892.20", "4.259930"], ["83883.70", "5.528845"], ["83875.20", "4.169293"], ["83866.70", "5.256934"], ["83858.20", "5.438208"], ["83849.70", "4.713114"], ["83841.20", "3.897382"], ["83832.70", "4.622477"], ["83824.20", "5.166297"], ["83815.70", "3.988019"]], "checksum": -537053087, "ts": "1742555347955"}], "ts": 1742555347958}}
{"exchange": "BYBIT", "timestamp": 1742555348.141408, "message": {"topic": "orderbook.200.BTCUSDT", "ts": 1742555348119, "type": "delta", "data": {"s": "BTCUSDT", "b": [["84061.9", "0.195664"], ["84061.7", "0.0002"], ["84061.6", "0"], ["84053.9", "0.048935"], ["84053.8", "0"], ["84050.9", "0"], ["84050.3", "0.072655"], ["84049.7", "0"], ["84043.3", "0"], ["84042.7", "0"], ["84037.8", "0"], ["84036.3", "0"], ["84035.7", "0"], ["84024.3", "0.061729"], ["84024.1", "0"], ["84016.8", "0.001784"], ["83986.3", "0.001466"], ["83986", "0.003181"], ["83985.6", "0.000516"], ["83984.4", "0.059399"], ["83984", "0.04"], ["83983.2", "0.160747"], ["83982.9", "0.000333"], ["83982.5", "0.011992"], ["83982.2", "0.001333"]], "a": [["84062", "0.200632"], ["84077.1", "0"], ["84078.3", "0"], ["84082.6", "0.000516"], ["84088.8", "0"], ["84089.6", "0"], ["84095.8", "0"], ["84096.6", "0"], ["84105.5", "0.013"], ["84105.6", "0.027844"], ["84105.7", "0.000518"], ["84119.1", "2.257032"], ["84134.2", "0.000423"], ["84134.3", "0.001466"], ["84137.1", "0.4"], ["84137.2", "0.029723"], ["84137.3", "0.003211"]], "u": 20674, "seq": 67549988593}, "cts": 1742555348088}}
{"exchange": "BITGET", "timestamp": 1742555348.204812, "message": {"action": "update", "arg": {"instType": "SPOT", "channel": "books", "instId": "BTCUSDT"}, "data": [{"asks": [["84029.41", "0.556987"], ["84035.01", "0.051607"], ["84091.40", "0.001941"], ["84093.40", "0.005106"], ["84095.40", "0.013437"], ["84097.40", "0.035554"], ["84099.40", "0.093564"], ["84101.40", "0.246221"], ["84103.40", "0.647950"], ["84104.20", "0"], ["84104.90", "2.357100"], ["84105.10", "0.001005"], ["84105.80", "0.953430"], ["84105.90", "0"], ["84106.10", "0.410130"], ["84106.70", "0.257670"], ["84107.00", "0.072900"], ["84107.60", "0.015000"], ["84110.10", "0.179970"], ["84110.70", "0"], ["84111.70", "0.292200"], ["84112.20", "0"], ["84145.40", "5.166297"], ["84153.90", "5.528845"], ["84162.40", "5.256934"], ["84170.90", "4.713114"], ["84179.40", "5.438208"], ["84187.90", "4.894387"], ["84196.40", "4.259930"], ["84204.90", "4.985024"], ["84213.40", "4.078656"], ["84221.90", "4.350566"], ["84230.40", "3.897382"], ["84238.90", "4.441203"], ["84247.40", "5.619481"], ["84255.90", "4.622477"], ["84264.40", "5.075661"], ["84272.90", "5.347571"], ["84281.40", "4.169293"], ["84289.90", "4.803750"], ["84298.40", "4.531840"], ["84306.90", "3.988019"], ["84520.00", "0"], ["84520.50", "0"]], "bids": [["84015.50", "0.298440"], ["84014.40", "0"], ["84011.70", "0.428250"], ["83977.20", "4.169293"], ["83960.20", "5.166297"], ["83943.20", "4.894387"], ["83934.70", "4.078656"], ["83926.20", "5.528845"], ["83917.70", "4.259930"], ["83915.80", "0.125657"], ["83910.54", "0"], ["83909.20", "4.531840"], ["83900.70", "5.256934"], ["83892.20", "5.619481"], ["83883.70", "4.713114"], ["83875.20", "3.897382"], ["83866.70", "3.988019"], ["83858.20", "5.075661"], ["83849.70", "5.438208"], ["83841.20", "4.441203"], ["83832.70", "4.803750"], ["83824.20", "4.622477"], ["83815.70", "5.347571"]], "checksum": -2064863159, "ts": "1742555348173"}], "ts": 1742555348175}}
{"exchange": "BYBIT", "timestamp": 1742555348.339826, "message": {"topic": "orderbook.200.BTCUSDT", "ts": 1742555348319, "type": "delta", "data": {"s": "BTCUSDT", "b": [["84061.9", "0.17647"], ["84038.1", "0"], ["84038", "0.059399"], ["84033.4", "0"], ["84017.5", "0"], ["84009", "17.255012"], ["83984.6", "0.171"]], "a": [["84067.5", "0.011976"], ["84080.6", "0.118804"], ["84083.4", "0.001466"], ["84099.6", "0.08922"], ["84104", "0.064765"], ["84106.8", "0"], ["84116.2", "2.257032"], ["84119.1", "0"], ["84137.2", "0"], ["84137.3", "0"]], "u": 20675, "seq": 67549988652}, "cts": 1742555348310}}
{"exchange": "BITGET", "timestamp": 1742555348.416618, "message": {"action": "update", "arg": {"instType": "SPOT", "channel": "books", "instId": "BTCUSDT"}, "data": [{"asks": [["84030.35", "0"], ["84033.48", "0.054750"], ["84035.01", "0"], ["84040.66", "0.009797"], ["84089.40", "0.001851"], ["84091.40", "0.004871"], ["84093.40", "0.012818"], ["84095.40", "0.033732"], ["84097.40", "0.088767"], ["84099.40", "0.233599"], ["84101.40", "0.614732"], ["84103.40", "1.617716"], ["84104.80", "2.882130"], ["84104.90", "2.356680"], ["84105.10", "0"], ["84105.80", "0"], ["84106.10", "0"], ["84106.90", "0.066210"], ["84107.00", "0.072720"], ["84110.10", "0.166710"], ["84111.40", "0"], ["84112.60", "0.074520"], ["84117.60", "0.534660"], ["84117.90", "0"], ["84145.40", "5.347571"], ["84153.90", "4.622477"], ["84162.40", "5.166297"], ["84170.90", "4.169293"], ["84179.40", "4.259930"], ["84187.90", "5.256934"], ["84196.40", "5.438208"], ["84204.90", "4.078656"], ["84213.40", "5.528845"], ["84221.90", "3.897382"], ["84230.40", "4.713114"], ["84238.90", "5.619481"], ["84247.40", "4.985024"], ["84255.90", "4.350566"], ["84264.40", "4.441203"], ["84272.90", "4.894387"], ["84281.40", "4.803750"], ["84289.90", "5.075661"], ["84298.40", "3.988019"], ["84306.90", "4.531840"], ["84520.00", "0.000854"], ["84520.50", "0.000238"]], "bids": [["84029.20", "0.066002"], ["84027.20", "0.173689"], ["84025.20", "0.457076"], ["84023.20", "1.202832"], ["84021.20", "3.165347"], ["84019.20", "8.329861"], ["84017.90", "0.067980"], ["84016.87", "0.006200"], ["84015.54", "0"], ["84015.50", "0.120000"], ["84015.20", "0.126630"], ["84015.10", "0"], ["84014.20", "2.392260"], ["84013.40", "0"], ["84013.00", "0.000032"], ["84012.80", "0"], ["84011.70", "0.249810"], ["84011.50", "0.120000"], ["84011.20", "0.017820"], ["84010.90", "0.535320"], ["84010.80", "0.009000"], ["84010.30", "1.732470"], ["84009.90", "0.067800"], ["84009.70", "0.006870"], ["84009.40", "0.534660"], ["83995.99", "0.000877"], ["83994.64", "0"], ["83978.00", "0.000015"], ["83977.20", "5.438208"], ["83977.00", "0.000032"], ["83968.70", "4.350566"], ["83960.20", "4.985024"], ["83951.70", "4.894387"], ["83943.20", "4.713114"], ["83934.70", "4.803750"], ["83926.20", "4.169293"], ["83909.20", "3.897382"], ["83900.70", "5.075661"], ["83892.20", "5.166297"], ["83883.70", "4.622477"], ["83875.20", "5.256934"], ["83866.70", "5.528845"], ["83858.20", "4.441203"], ["83849.70", "3.988019"], ["83841.20", "4.531840"], ["83832.70", "5.619481"], ["83824.20", "5.347571"], ["83815.70", "4.078656"], ["83653.94", "0"], ["83653.67", "0"], ["83653.31", "0"], ["83652.80", "0"]], "checksum": 751673295, "ts": "1742555348387"}], "ts": 1742555348389}}
{"exchange": "BYBIT", "timestamp": 1742555348.54053, "message": {"topic": "orderbook.200.BTCUSDT", "ts": 1742555348520, "type": "delta", "data": {"s": "BTCUSDT", "b": [["84061.9", "0.098392"], ["84051.8", "0.019358"], ["84039.9", "0"], ["84039.6", "0.035694"], ["84029.1", "0.023024"], ["84025.1", "0.08939"], ["84024.3", "0"], ["84024.2", "0.001333"], ["84023.9", "0.013"], ["84023.8", "0.016062"], ["84010.5", "5.476883"], ["84009", "0"], ["84003.3", "17.255012"], ["83982.5", "0"], ["83982.2", "0"]], "a": [["84068.9", "0.000153"], ["84074.8", "0.107338"], ["84101", "0.062055"], ["84102", "0.012844"], ["84102.1", "0.012844"], ["84103", "0"], ["84104", "0.001333"], ["84105.5", "0"], ["84105.6", "0.015"], ["84106.8", "0.063432"], ["84113.2", "0.02468"], ["84116.2", "0"], ["84117.5", "0"], ["84124.9", "2.257032"], ["84134.3", "0"], ["84137.1", "0"]], "u": 20676, "seq": 67549988725}, "cts": 1742555348511}}
{"exchange": "BITGET", "timestamp": 1742555348.637677, "message": {"action": "update", "arg": {"instType": "SPOT", "channel": "books", "instId": "BTCUSDT"}, "data": [{"asks": [["84029.41", "0.896987"], ["84030.31", "0.088149"], ["84037.82", "0.209200"], ["84071.07", "0.012472"], ["84071.21", "0"], ["84087.33", "0"], ["84087.40", "0.001037"], ["84087.64", "0.010000"], ["84089.27", "0"], ["84089.40", "0.002727"], ["84090.19", "0.001598"], ["84091.40", "0.007178"], ["84092.43", "0.001597"], ["84093.40", "0.018888"], ["84095.40", "0.049707"], ["84097.40", "0.130807"], ["84099.40", "0.344228"], ["84101.40", "0.905863"], ["84103.40", "2.383850"], ["84103.80", "0.530250"], ["84104.80", "0.833880"], ["84104.90", "0"], ["84106.70", "2.630430"], ["84108.80", "0.041070"], ["84110.10", "0.103470"], ["84111.70", "0.726750"], ["84113.10", "0.045540"], ["84117.30", "0"], ["84117.50", "0"], ["84117.60", "0"], ["84145.40", "5.256934"], ["84153.90", "4.985024"], ["84170.90", "3.988019"], ["84179.40", "4.894387"], ["84187.90", "4.622477"], ["84196.40", "4.169293"], ["84204.90", "3.897382"], ["84213.40", "5.619481"], ["84221.90", "4.259930"], ["84230.40", "4.803750"], ["84238.90", "5.528845"], ["84247.40", "4.713114"], ["84264.40", "5.438208"], ["84272.90", "4.441203"], ["84281.40", "5.075661"], ["84289.90", "4.531840"], ["84298.40", "5.347571"], ["84306.90", "4.078656"], ["84520.50", "0"]], "bids": [["84029.20", "0.065380"], ["84027.20", "0.172052"], ["84025.20", "0.452769"], ["84023.20", "1.191498"], ["84021.20", "3.135520"], ["84019.20", "8.251369"], ["84017.60", "0.186690"], ["84015.90", "0.067800"], ["84011.70", "0"], ["84011.20", "0"], ["84010.90", "0"], ["84008.90", "0.476760"], ["83979.94", "0.001176"], ["83978.31", "0.001173"], ["83977.20", "5.256934"], ["83977.08", "0"], ["83975.15", "0"], ["83968.70", "4.169293"], ["83960.20", "4.259930"], ["83951.70", "5.619481"], ["83943.20", "5.528845"], ["83934.70", "4.713114"], ["83926.20", "5.438208"], ["83917.70", "3.988019"], ["83909.20", "4.985024"], ["83900.70", "4.894387"], ["83892.20", "4.531840"], ["83883.70", "5.166297"], ["83875.20", "4.350566"], ["83866.70", "5.347571"], ["83858.20", "5.075661"], ["83849.70", "4.622477"], ["83841.20", "3.897382"], ["83832.70", "4.441203"], ["83824.20", "4.078656"], ["83815.70", "4.803750"], ["83653.94", "0.000133"], ["83653.67", "0.001695"]], "checksum": 577376018, "ts": "1742555348607"}], "ts": 1742555348611}}
{"exchange": "BYBIT", "timestamp": 1742555348.74396, "message": {"topic": "orderbook.200.BTCUSDT", "ts": 1742555348719, "type": "delta", "data": {"s": "BTCUSDT", "b": [["84023.9", "0"], ["84023.8", "0.003181"], ["84023.5", "0.013"], ["84023.4", "0.012881"], ["84010.5", "0.327005"], ["84009", "17.085633"], ["84003.3", "0"], ["83982.9", "0"]], "a": [["84100.5", "0.002458"], ["84101", "0.05993"], ["84102", "0"], ["84102.1", "0"], ["84102.7", "0.013"], ["84102.8", "0.012844"], ["84104", "0.064765"], ["84106.8", "0"], ["84124.7", "2.260269"], ["84124.9", "0"], ["84134.3", "0.001466"], ["84137.1", "0.4"]], "u": 20677, "seq": 67549988756}, "cts": 1742555348636}}
{"exchange": "BITGET", "timestamp": 1742555348.855632, "message": {"action": "update", "arg": {"instType": "SPOT", "channel": "books", "instId": "BTCUSDT"}, "data": [{"asks": [["84037.81", "0.072557"], ["84040.66", "0"], ["84105.00", "2.356500"], ["84106.70", "0.273990"], ["84110.10", "0.078480"], ["84111.69", "0"], ["84111.70", "0.292200"], ["84117.20", "0"], ["84145.40", "5.438208"], ["84153.90", "4.622477"], ["84162.40", "3.988019"], ["84170.90", "5.256934"], ["84179.40", "5.166297"], ["84187.90", "4.803750"], ["84196.40", "5.075661"], ["84204.90", "4.259930"], ["84213.40", "4.894387"], ["84221.90", "4.531840"], ["84230.40", "4.441203"], ["84238.90", "4.169293"], ["84247.40", "4.078656"], ["84255.90", "5.619481"], ["84264.40", "5.347571"], ["84272.90", "4.713114"], ["84281.40", "3.897382"], ["84289.90", "4.350566"], ["84298.40", "4.985024"], ["84306.90", "5.528845"], ["84520.50", "0.000238"]], "bids": [["84029.40", "1.106496"], ["84019.10", "0.075000"], ["84018.90", "0"], ["84018.50", "0.870570"], ["84018.10", "2.356770"], ["84018.00", "0.000032"], ["84015.50", "0"], ["84014.70", "0"], ["84014.20", "2.073150"], ["84013.90", "0.067800"], ["84013.80", "0"], ["84012.90", "0"], ["84012.00", "0.360000"], ["84008.90", "0"], ["84008.70", "0.120000"], ["84007.90", "1.476000"], ["83977.20", "3.897382"], ["83968.70", "5.075661"], ["83960.20", "4.350566"], ["83951.70", "5.347571"], ["83943.20", "4.531840"], ["83934.70", "4.894387"], ["83926.20", "5.256934"], ["83917.70", "4.441203"], ["83909.20", "5.438208"], ["83900.70", "4.803750"], ["83892.20", "4.713114"], ["83883.70", "4.622477"], ["83875.20", "5.619481"], ["83866.70", "4.169293"], ["83858.20", "4.078656"], ["83849.70", "4.259930"], ["83841.20", "4.985024"], ["83832.70", "5.166297"], ["83824.20", "5.528845"], ["83815.70", "3.988019"], ["83653.31", "0.000015"], ["83652.80", "0.000119"], ["83652.48", "0.000188"], ["83651.65", "0.000018"]], "checksum": -2049961474, "ts": "1742555348817"}], "ts": 1742555348821}}
{"exchange": "BYBIT", "timestamp": 1742555348.939504, "message": {"topic": "orderbook.200.BTCUSDT", "ts": 1742555348920, "type": "delta", "data": {"s": "BTCUSDT", "b": [["84023.8", "0.016062"], ["84023.7", "0.012881"], ["84023.5", "0"], ["84023.4", "0"], ["83982.9", "0.000333"]], "a": [["84099.4", "0.002125"], ["84100.5", "0.000333"], ["84101.9", "0.01431"], ["84102", "0.012844"], ["84102.7", "0"], ["84102.8", "0.04"], ["84102.9", "0.04"], ["84106.4", "0.089099"], ["84106.5", "0.001466"], ["84116.2", "2.257032"], ["84124.7", "0.003237"], ["84134.2", "0"], ["84134.3", "0"], ["84137.1", "0"]], "u": 20678, "seq": 67549988780}, "cts": 1742555348881}}
{"exchange": "BITGET", "timestamp": 1742555349.060617, "message": {"action": "update", "arg": {"instType": "SPOT", "channel": "books", "instId": "BTCUSDT"}, "data": [{"asks": [["84029.42", "0.000117"], ["84030.28", "0.088149"], ["84030.31", "0"], ["84051.72", "0"], ["84052.15", "0"], ["84052.92", "0.035952"], ["84053.28", "0.119870"], ["84053.42", "0"], ["84053.84", "0"], ["84054.07", "0"], ["84054.34", "0"], ["84054.46", "0.035961"], ["84054.89", "0.006356"], ["84055.27", "0.006356"], ["84055.38", "0.006356"], ["84055.41", "0"], ["84055.70", "0"], ["84055.85", "0"], ["84056.35", "0"], ["84056.40", "0"], ["84056.61", "0.010984"], ["84056.86", "0"], ["84056.87", "0"], ["84056.95", "0.006356"], ["84057.11", "0.006356"], ["84057.19", "0"], ["84057.22", "0"], ["84057.37", "0"], ["84057.38", "0"], ["84057.40", "0.006356"], ["84057.59", "0.016429"], ["84057.91", "0.006356"], ["84057.99", "0.006356"], ["84058.37", "0.016429"], ["84058.47", "0.119883"], ["84058.55", "0.006356"], ["84058.62", "0.006356"], ["84058.88", "0"], ["84058.93", "0"], ["84060.05", "0.010985"], ["84060.11", "0.006357"], ["84060.65", "0"], ["84061.66", "0"], ["84061.83", "0.119850"], ["84062.01", "0"], ["84062.24", "0"], ["84062.92", "0.119858"], ["84063.24", "0.015895"], ["84063.50", "0.009989"], ["84065.96", "0"], ["84066.85", "0"], ["84067.19", "0.015892"], ["84068.03", "0.010988"], ["84089.40", "0.002321"], ["84091.40", "0.006108"], ["84093.40", "0.016072"], ["84095.40", "0.042295"], ["84097.40", "0.111302"], ["84099.40", "0.292902"], ["84101.40", "0.770794"], ["84103.40", "2.028404"], ["84104.80", "1.903320"], ["84105.00", "0"], ["84107.00", "2.429160"], ["84107.60", "0"], ["84108.80", "0"], ["84110.10", "0.067800"], ["84117.20", "0.107070"], ["84117.30", "2.674740"], ["84117.50", "0.070080"], ["84117.60", "0.609030"], ["84145.40", "5.619481"], ["84153.90", "5.347571"], ["84162.40", "5.438208"], ["84170.90", "4.078656"], ["84179.40", "4.622477"], ["84187.90", "3.897382"], ["84196.40", "4.441203"], ["84204.90", "4.894387"], ["84213.40", "4.531840"], ["84221.90", "5.075661"], ["84230.40", "5.256934"], ["84238.90", "5.166297"], ["84247.40", "4.713114"], ["84255.90", "3.988019"], ["84264.40", "4.259930"], ["84272.90", "4.803750"], ["84281.40", "4.985024"], ["84289.90", "5.528845"], ["84298.40", "4.350566"], ["84306.90", "4.169293"], ["84520.50", "0"]], "bids": [["84029.40", "1.112790"], ["84023.20", "1.191382"], ["84021.20", "3.135217"], ["84019.20", "8.250569"], ["84012.90", "0.120000"], ["84012.58", "0.089521"], ["84012.11", "0.247687"], ["84011.39", "0"], ["84011.20", "0.269760"], ["84010.98", "0"], ["84010.90", "0.071370"], ["84010.77", "0.083974"], ["84010.40", "0.018262"], ["84010.35", "0.017824"], ["84010.30", "1.281840"], ["84009.84", "0.005949"], ["84009.72", "0"], ["84009.50", "0.120000"], ["84009.31", "0"], ["84009.20", "0"], ["84008.88", "0.055678"], ["84008.79", "0"], ["84008.72", "0.017110"], ["84008.54", "0.007134"], ["84008.01", "0.028876"], ["84007.90", "0"], ["84007.82", "0.007342"], ["84007.68", "0"], ["84007.46", "0"], ["84007.40", "0.007946"], ["84007.33", "0.008998"], ["84007.28", "0"], ["84007.21", "0.224973"], ["84007.11", "0.033214"], ["84007.03", "0.025959"], ["84006.96", "0.008188"], ["84006.83", "0"], ["84006.78", "0"], ["84006.28", "0"], ["84006.27", "0"], ["84005.96", "0"], ["84005.93", "0"], ["84005.78", "0"], ["84005.77", "0"], ["84005.49", "0.012660"], ["84005.43", "0.051984"], ["84004.31", "0"], ["84004.26", "0.003975"], ["84003.68", "0.268485"], ["84002.75", "0.222759"], ["84002.50", "0"], ["84002.24", "0.076143"], ["84002.15", "0.021138"], ["84001.50", "0"], ["84001.01", "0"], ["84000.90", "0"], ["83998.28", "0.073244"], ["83997.44", "0.056390"], ["83997.06", "0"], ["83996.27", "0"], ["83979.00", "0.000017"], ["83978.00", "0"], ["83977.20", "5.438208"], ["83968.70", "5.166297"], ["83960.20", "4.441203"], ["83951.70", "4.531840"], ["83943.20", "4.622477"], ["83934.70", "5.256934"], ["83926.20", "3.897382"], ["83917.70", "4.078656"], ["83909.20", "5.528845"], ["83900.70", "4.259930"], ["83892.20", "4.350566"], ["83883.70", "4.169293"], ["83875.20", "4.803750"], ["83866.70", "5.619481"], ["83858.20", "4.985024"], ["83849.70", "5.347571"], ["83841.20", "4.894387"], ["83832.70", "4.713114"], ["83824.20", "5.075661"], ["83652.48", "0"], ["83651.65", "0"]], "checksum": 1436990901, "ts": "1742555349019"}], "ts": 1742555349023}}
{"exchange": "BYBIT", "timestamp": 1742555349.139892, "message": {"topic": "orderbook.200.BTCUSDT", "ts": 1742555349120, "type": "delta", "data": {"s": "BTCUSDT", "b": [["84061.9", "0.269392"], ["84049.4", "0.130668"], ["84023.8", "0.003181"], ["84023.7", "0"], ["84023.4", "0.013"], ["84023.3", "0.014347"]], "a": [["84062", "0.029632"], ["84101.9", "0.001466"], ["84102", "0"], ["84102.8", "0.012844"], ["84102.9", "0.012844"], ["84103.7", "0.043236"], ["84103.8", "0.04"]], "u": 20679, "seq": 67549988801}, "cts": 1742555349108}}
{"exchange": "BITGET", "timestamp": 1742555349.258336, "message": {"action": "update", "arg": {"instType": "SPOT", "channel": "books", "instId": "BTCUSDT"}, "data": [{"asks": [["84029.41", "0.556987"], ["84059.72", "0"], ["84060.77", "0.009990"], ["84089.40", "0.001333"], ["84091.40", "0.003507"], ["84093.40", "0.009231"], ["84095.40", "0.024291"], ["84097.40", "0.063923"], ["84099.40", "0.168220"], ["84101.40", "0.442683"], ["84103.40", "1.164955"], ["84105.70", "0"], ["84110.60", "0.012720"], ["84145.40", "4.259930"], ["84153.90", "4.441203"], ["84162.40", "5.619481"], ["84170.90", "4.894387"], ["84179.40", "5.528845"], ["84187.90", "4.531840"], ["84196.40", "3.988019"], ["84204.90", "5.166297"], ["84213.40", "5.075661"], ["84221.90", "4.985024"], ["84230.40", "5.438208"], ["84238.90", "4.169293"], ["84247.40", "5.347571"], ["84255.90", "4.078656"], ["84264.40", "4.803750"], ["84272.90", "4.350566"], ["84281.40", "3.897382"], ["84289.90", "4.713114"], ["84298.40", "5.256934"], ["84306.90", "4.622477"]], "bids": [["84013.30", "0"], ["84009.70", "0"], ["84004.46", "0.018524"], ["84003.42", "0"], ["83977.20", "4.622477"], ["83968.70", "3.897382"], ["83960.20", "4.259930"], ["83951.70", "4.894387"], ["83943.20", "5.075661"], ["83934.70", "3.988019"], ["83926.20", "4.985024"], ["83917.70", "4.531840"], ["83900.70", "4.169293"], ["83892.20", "5.619481"], ["83883.70", "5.256934"], ["83875.20", "5.166297"], ["83866.70", "4.441203"], ["83858.20", "5.347571"], ["83849.70", "5.438208"], ["83841.20", "4.078656"], ["83824.20", "4.350566"], ["83815.70", "4.803750"], ["83652.48", "0.000188"], ["83651.65", "0.000018"]], "checksum": 1286647438, "ts": "1742555349222"}], "ts": 1742555349227}}
{"exchange": "BITGET", "timestamp": 1742555349.458048, "message": {"action": "update", "arg": {"instType": "SPOT", "channel": "books", "instId": "BTCUSDT"}, "data": [{"asks": [["84030.25", "0.088149"], ["84030.28", "0"], ["84081.92", "0"], ["84089.40", "0.001686"], ["84091.40", "0.004436"], ["84093.40", "0.011674"], ["84095.40", "0.030722"], ["84097.40", "0.080846"], ["84099.40", "0.212754"], ["84101.40", "0.559877"], ["84103.40", "1.473362"], ["84111.70", "0.208500"], ["84112.90", "0.000958"], ["84113.10", "0"], ["84115.70", "0.045540"], ["84145.40", "5.347571"], ["84153.90", "5.075661"], ["84162.40", "4.713114"], ["84170.90", "4.441203"], ["84179.40", "5.256934"], ["84187.90", "4.803750"], ["84196.40", "4.531840"], ["84204.90", "4.169293"], ["84213.40", "4.259930"], ["84221.90", "5.528845"], ["84230.40", "5.166297"], ["84238.90", "5.619481"], ["84247.40", "4.350566"], ["84255.90", "3.897382"], ["84264.40", "4.894387"], ["84272.90", "4.985024"], ["84281.40", "3.988019"], ["84289.90", "4.078656"], ["84298.40", "5.438208"], ["84520.50", "0.000238"]], "bids": [["84029.20", "0.077435"], ["84027.20", "0.203776"], ["84025.20", "0.536253"], ["84023.20", "1.411191"], ["84021.20", "3.713662"], ["84019.20", "9.772793"], ["84012.50", "0.035850"], ["84007.90", "1.476000"], ["83977.20", "4.985024"], ["83968.70", "5.166297"], ["83960.20", "4.713114"], ["83951.70", "4.169293"], ["83943.20", "5.347571"], ["83934.70", "4.078656"], ["83926.20", "4.531840"], ["83917.70", "4.350566"], ["83909.20", "4.894387"], ["83900.70", "5.256934"], ["83892.20", "5.438208"], ["83883.70", "5.619481"], ["83875.20", "3.988019"], ["83866.70", "5.528845"], ["83858.20", "4.622477"], ["83849.70", "4.259930"], ["83841.20", "4.441203"], ["83832.70", "4.803750"], ["83824.20", "3.897382"], ["83815.70", "5.075661"], ["83651.65", "0"]], "checksum": -1863343042, "ts": "1742555349428"}], "ts": 1742555349431}}
{"exchange": "BITGET", "timestamp": 1742555349.678462, "message": {"action": "update", "arg": {"instType": "SPOT", "channel": "books", "instId": "BTCUSDT"}, "data": [{"asks": [["84095.40", "0.030472"], ["84097.40", "0.080190"], ["84099.40", "0.211026"], ["84101.40", "0.555333"], ["84103.40", "1.461402"], ["84145.40", "5.256934"], ["84153.90", "4.078656"], ["84162.40", "5.619481"], ["84179.40", "4.259930"], ["84196.40", "4.894387"], ["84204.90", "5.075661"], ["84213.40", "4.531840"], ["84221.90", "5.347571"], ["84230.40", "4.985024"], ["84238.90", "4.622477"], ["84247.40", "3.988019"], ["84255.90", "5.166297"], ["84264.40", "4.350566"], ["84272.90", "4.713114"], ["84281.40", "5.438208"], ["84289.90", "4.169293"], ["84298.40", "5.528845"], ["84306.90", "3.897382"]], "bids": [["84019.20", "9.772570"], ["83977.20", "3.897382"], ["83968.70", "5.619481"], ["83960.20", "4.894387"], ["83951.70", "4.985024"], ["83943.20", "4.350566"], ["83934.70", "4.803750"], ["83926.20", "3.988019"], ["83917.70", "5.438208"], ["83909.20", "4.078656"], ["83900.70", "4.441203"], ["83892.20", "4.622477"], ["83883.70", "5.166297"], ["83875.20", "5.256934"], ["83866.70", "4.259930"], ["83858.20", "5.075661"], ["83849.70", "5.347571"], ["83841.20", "4.169293"], ["83832.70", "5.528845"], ["83824.20", "4.713114"], ["83815.70", "4.531840"]], "checksum": -1863343042, "ts": "1742555349646"}], "ts": 1742555349650}}
{"exchange": "BYBIT", "timestamp": 1742555349.740452, "message": {"topic": "orderbook.200.BTCUSDT", "ts": 1742555349720, "type": "delta", "data": {"s": "BTCUSDT", "b": [["84061.9", "0.229392"]], "a": [["84062", "0.029495"]], "u": 20680, "seq": 67549988833}, "cts": 1742555349717}}
{"exchange": "BITGET", "timestamp": 1742555349.905561, "message": {"action": "update", "arg": {"instType": "SPOT", "channel": "books", "instId": "BTCUSDT"}, "data": [{"asks": [["84029.42", "0.000100"], ["84080.97", "0.176724"], ["84089.40", "0.001318"], ["84091.40", "0.003468"], ["84093.40", "0.009128"], ["84095.40", "0.023843"], ["84097.40", "0.062745"], ["84099.40", "0.165117"], ["84101.40", "0.434520"], ["84103.40", "1.143472"], ["84103.80", "0.530430"], ["84104.80", "1.903680"], ["84106.70", "0.274170"], ["84106.90", "0.066390"], ["84107.00", "2.429340"], ["84110.10", "0.067980"], ["84110.80", "0.499230"], ["84145.40", "5.075661"], ["84153.90", "4.985024"], ["84162.40", "3.988019"], ["84170.90", "5.438208"], ["84179.40", "5.256934"], ["84196.40", "4.713114"], ["84204.90", "5.619481"], ["84213.40", "4.622477"], ["84221.90", "4.894387"], ["84230.40", "4.259930"], ["84238.90", "5.166297"], ["84247.40", "3.897382"], ["84255.90", "5.528845"], ["84264.40", "4.441203"], ["84272.90", "4.078656"], ["84281.40", "4.350566"], ["84289.90", "4.531840"], ["84298.40", "5.347571"], ["84306.90", "4.169293"], ["84520.00", "0"], ["84520.50", "0"]], "bids": [["84019.10", "0.075180"], ["84018.50", "0.870750"], ["84018.10", "2.356950"], ["84017.90", "0.068160"], ["84010.30", "1.733850"], ["84007.80", "0.120000"], ["83979.00", "0.000032"], ["83977.20", "4.713114"], ["83977.00", "0.000015"], ["83968.70", "3.988019"], ["83960.20", "4.259930"], ["83951.70", "5.075661"], ["83943.20", "4.622477"], ["83934.70", "3.897382"], ["83926.20", "5.256934"], ["83917.70", "4.894387"], ["83909.20", "5.528845"], ["83900.70", "4.169293"], ["83892.20", "4.985024"], ["83883.70", "4.531840"], ["83875.20", "4.350566"], ["83866.70", "5.619481"], ["83858.20", "5.166297"], ["83849.70", "4.441203"], ["83841.20", "5.438208"], ["83832.70", "4.803750"], ["83824.20", "4.078656"], ["83815.70", "5.347571"], ["83652.48", "0"]], "checksum": -2011038766, "ts": "1742555349853"}], "ts": 1742555349859}}
{"exchange": "BYBIT", "timestamp": 1742555349.94007, "message": {"topic": "orderbook.200.BTCUSDT", "ts": 1742555349920, "type": "delta", "data": {"s": "BTCUSDT", "b": [["84061.9", "0.100176"], ["84061.7", "0"], ["84052.2", "0"], ["84010.5", "5.426069"], ["83994.5", "0.35341"], ["83988.5", "0"], ["83982.5", "0.011992"], ["83982.2", "0.001333"]], "a": [["84062", "0.200495"]], "u": 20681, "seq": 67549988855}, "cts": 1742555349915}}
{"exchange": "BITGET", "timestamp": 1742555350.095095, "message": {"action": "update", "arg": {"instType": "SPOT", "channel": "books", "instId": "BTCUSDT"}, "data": [{"asks": [["84030.22", "0.088149"], ["84030.25", "0"], ["84106.70", "0.274890"], ["84110.10", "0.067800"], ["84110.80", "0"], ["84117.90", "0.249120"], ["84145.40", "5.256934"], ["84153.90", "4.531840"], ["84162.40", "4.985024"], ["84170.90", "5.528845"], ["84179.40", "4.350566"], ["84187.90", "5.438208"], ["84204.90", "4.259930"], ["84213.40", "5.166297"], ["84221.90", "4.803750"], ["84230.40", "5.619481"], ["84238.90", "4.622477"], ["84255.90", "4.894387"], ["84264.40", "5.075661"], ["84272.90", "3.988019"], ["84281.40", "4.078656"], ["84289.90", "5.347571"], ["84298.40", "4.441203"]], "bids": [["84023.20", "1.411054"], ["84021.20", "3.713096"], ["84019.20", "9.771305"], ["84013.30", "0.015000"], ["84010.30", "1.281840"], ["83977.20", "3.988019"], ["83968.70", "5.528845"], ["83960.20", "4.169293"], ["83951.70", "4.803750"], ["83943.20", "5.347571"], ["83934.70", "4.713114"], ["83926.20", "4.259930"], ["83917.70", "3.897382"], ["83909.20", "4.078656"], ["83900.70", "5.438208"], ["83892.20", "4.441203"], ["83875.20", "4.622477"], ["83866.70", "5.166297"], ["83858.20", "4.350566"], ["83849.70", "4.894387"], ["83841.20", "4.985024"], ["83832.70", "5.256934"], ["83824.20", "5.619481"], ["83815.70", "5.075661"], ["83652.80", "0"]], "checksum": 1618798260, "ts": "1742555350056"}], "ts": 1742555350059}}
{"exchange": "BYBIT", "timestamp": 1742555350.140588, "message": {"topic": "orderbook.200.BTCUSDT", "ts": 1742555350120, "type": "delta", "data": {"s": "BTCUSDT", "b": [["84023.9", "0.013"], ["84023.8", "0.016062"], ["84023.4", "0"], ["84023.3", "0.001466"], ["84009", "0"], ["84006.2", "17.085633"]], "a": [["84101.9", "0.014313"], ["84102", "0.012847"], ["84102.8", "0.04"], ["84102.9", "0.04"], ["84103.7", "0.003236"], ["84103.8", "0"]], "u": 20682, "seq": 67549988873}, "cts": 1742555350117}}
{"exchange": "BITGET", "timestamp": 1742555350.311097, "message": {"action": "update", "arg": {"instType": "SPOT", "channel": "books", "instId": "BTCUSDT"}, "data": [{"asks": [["84029.41", "0.554628"], ["84032.53", "0.051607"], ["84033.48", "0"], ["84089.40", "0.002439"], ["84091.40", "0.006418"], ["84093.40", "0.016890"], ["84095.40", "0.044447"], ["84097.40", "0.116966"], ["84099.40", "0.307805"], ["84101.40", "0.810014"], ["84103.40", "2.131616"], ["84104.80", "2.267940"], ["84106.00", "0.499410"], ["84106.70", "0.274170"], ["84111.70", "0.161250"], ["84117.90", "0"], ["84145.40", "4.894387"], ["84148.72", "0"], ["84153.90", "4.713114"], ["84157.13", "0"], ["84162.40", "4.169293"], ["84170.90", "5.166297"], ["84179.40", "5.347571"], ["84187.90", "4.350566"], ["84196.40", "5.438208"], ["84204.90", "5.528845"], ["84213.40", "5.256934"], ["84230.40", "5.075661"], ["84238.90", "4.531840"], ["84255.90", "4.259930"], ["84264.40", "4.622477"], ["84272.90", "5.619481"], ["84289.90", "4.985024"], ["84306.90", "3.988019"], ["84520.00", "0.000854"], ["84520.50", "0.000238"]], "bids": [["84029.40", "1.085337"], ["84020.84", "0.027453"], ["84008.58", "0.005774"], ["83978.00", "0.000017"], ["83977.20", "4.441203"], ["83968.70", "5.256934"], ["83960.20", "4.622477"], ["83951.70", "5.528845"], ["83949.70", "0"], ["83943.20", "5.166297"], ["83941.30", "0"], ["83934.70", "5.619481"], ["83926.20", "4.894387"], ["83917.70", "5.075661"], ["83909.20", "4.803750"], ["83900.70", "3.897382"], ["83892.20", "4.259930"], ["83883.70", "5.347571"], ["83875.20", "4.713114"], ["83866.70", "3.988019"], ["83858.20", "4.531840"], ["83849.70", "4.078656"], ["83832.70", "4.169293"], ["83824.20", "4.350566"], ["83815.70", "5.438208"], ["83653.31", "0"]], "checksum": 1586031087, "ts": "1742555350274"}], "ts": 1742555350276}}
{"exchange": "BYBIT", "timestamp": 1742555350.340872, "message": {"topic": "orderbook.200.BTCUSDT", "ts": 1742555350319, "type": "delta", "data": {"s": "BTCUSDT", "b": [["84061.9", "0.103147"], ["84049.4", "0.041569"], ["84010.5", "0.327005"]], "a": [["84062", "0.204573"], ["84101.7", "0.013"], ["84101.8", "0.012847"], ["84101.9", "0.001466"], ["84102", "0"], ["84102.6", "0.04"], ["84102.7", "0.04"], ["84102.8", "0"], ["84102.9", "0"], ["84133.5", "0"]], "u": 20683, "seq": 67549988918}, "cts": 1742555350311}}
{"exchange": "BITGET", "timestamp": 1742555350.510809, "message": {"action": "update", "arg": {"instType": "SPOT", "channel": "books", "instId": "BTCUSDT"}, "data": [{"asks": [["84030.19", "0.088149"], ["84030.22", "0"], ["84061.74", "0"], ["84062.45", "0.119867"], ["84093.40", "0.017132"], ["84095.40", "0.045085"], ["84097.40", "0.118645"], ["84099.40", "0.312223"], ["84101.40", "0.821641"], ["84103.40", "2.162213"], ["84104.80", "2.267760"], ["84106.00", "0"], ["84107.60", "0.015000"], ["84145.40", "5.256934"], ["84152.24", "0.001810"], ["84153.90", "4.622477"], ["84161.32", "0.003620"], ["84162.40", "4.894387"], ["84170.90", "5.347571"], ["84179.40", "5.166297"], ["84187.90", "4.713114"], ["84196.40", "4.531840"], ["84204.90", "4.078656"], ["84213.40", "4.803750"], ["84221.90", "4.441203"], ["84230.40", "3.897382"], ["84238.90", "3.988019"], ["84247.40", "5.438208"], ["84255.90", "4.985024"], ["84264.40", "4.350566"], ["84281.40", "4.259930"], ["84289.90", "4.169293"], ["84298.40", "5.528845"], ["84306.90", "5.075661"], ["84520.00", "0"], ["84520.50", "0"]], "bids": [["84029.20", "0.065362"], ["84027.20", "0.172005"], ["84025.20", "0.452643"], ["84023.20", "1.191168"], ["84021.20", "3.134651"], ["84019.20", "8.249081"], ["84015.10", "0.153580"], ["84011.20", "0"], ["84009.80", "0"], ["84007.70", "0.120000"], ["84001.95", "0.259901"], ["84001.23", "0"], ["83985.60", "0.199851"], ["83980.30", "0"], ["83977.20", "5.528845"], ["83968.70", "4.169293"], ["83960.20", "4.894387"], ["83953.36", "0.001810"], ["83951.70", "5.438208"], ["83944.96", "0.003620"], ["83943.20", "5.619481"], ["83934.70", "3.897382"], ["83926.20", "4.078656"], ["83917.70", "4.531840"], ["83909.20", "5.347571"], ["83900.70", "4.713114"], ["83892.20", "5.166297"], ["83883.70", "4.350566"], ["83875.20", "3.988019"], ["83866.70", "4.622477"], ["83858.20", "4.441203"], ["83849.70", "5.256934"], ["83841.20", "4.259930"], ["83832.70", "4.985024"], ["83824.20", "4.803750"], ["83815.70", "5.075661"], ["83653.94", "0"], ["83653.67", "0"]], "checksum": -794968390, "ts": "1742555350477"}], "ts": 1742555350481}}
{"exchange": "BYBIT", "timestamp": 1742555350.540258, "message": {"topic": "orderbook.200.BTCUSDT", "ts": 1742555350520, "type": "delta", "data": {"s": "BTCUSDT", "b": [["84023.9", "0"], ["84023.7", "0.012881"], ["83982.6", "0.04406"], ["83982.2", "0"]], "a": [["84101.7", "0"], ["84101.9", "0.014313"], ["84102.6", "0"], ["84102.8", "0.04"], ["84133.5", "0.001851"]], "u": 20684, "seq": 67549988965}, "cts": 1742555350502}}
{"exchange": "BITGET", "timestamp": 1742555350.712765, "message": {"action": "update", "arg": {"instType": "SPOT", "channel": "books", "instId": "BTCUSDT"}, "data": [{"asks": [["84029.41", "0.894628"], ["84087.64", "0"], ["84091.40", "0.006582"], ["84093.40", "0.017322"], ["84095.40", "0.045583"], ["84097.40", "0.119956"], ["84099.40", "0.315672"], ["84101.40", "0.830716"], ["84103.40", "2.186095"], ["84145.40", "4.713114"], ["84153.90", "5.528845"], ["84170.90", "4.531840"], ["84179.40", "4.078656"], ["84187.90", "4.441203"], ["84196.40", "4.169293"], ["84204.90", "5.256934"], ["84213.40", "4.259930"], ["84221.90", "4.350566"], ["84230.40", "5.075661"], ["84238.90", "4.622477"], ["84247.40", "4.803750"], ["84255.90", "5.619481"], ["84264.40", "3.988019"], ["84272.90", "3.897382"], ["84281.40", "5.166297"], ["84289.90", "5.438208"], ["84298.40", "5.347571"], ["84306.90", "4.985024"], ["84520.00", "0.000854"]], "bids": [["83977.20", "3.988019"], ["83968.70", "4.350566"], ["83960.20", "4.078656"], ["83951.70", "5.166297"], ["83943.20", "3.897382"], ["83934.70", "4.531840"], ["83926.20", "4.803750"], ["83917.70", "4.985024"], ["83909.20", "5.619481"], ["83892.20", "4.259930"], ["83883.70", "4.441203"], ["83875.20", "5.075661"], ["83866.70", "5.438208"], ["83858.20", "4.169293"], ["83849.70", "5.347571"], ["83841.20", "4.622477"], ["83832.70", "4.894387"], ["83824.20", "5.528845"], ["83815.70", "5.256934"]], "checksum": -913592959, "ts": "1742555350682"}], "ts": 1742555350686}}
{"exchange": "BYBIT", "timestamp": 1742555350.740022, "message": {"topic": "orderbook.200.BTCUSDT", "ts": 1742555350720, "type": "delta", "data": {"s": "BTCUSDT", "b": [], "a": [["84062", "0.033098"], ["84101.8", "0.013"]], "u": 20685, "seq": 67549988986}, "cts": 1742555350701}}
{"exchange": "BITGET", "timestamp": 1742555350.918842, "message": {"action": "update", "arg": {"instType": "SPOT", "channel": "books", "instId": "BTCUSDT"}, "data": [{"asks": [["84085.39", "0"], ["84145.40", "4.441203"], ["84153.90", "4.803750"], ["84162.40", "4.078656"], ["84170.90", "4.985024"], ["84179.40", "4.531840"], ["84187.90", "5.528845"], ["84196.40", "4.259930"], ["84204.90", "4.713114"], ["84213.40", "5.619481"], ["84221.90", "4.894387"], ["84238.90", "4.350566"], ["84247.40", "4.622477"], ["84255.90", "5.256934"], ["84281.40", "5.347571"], ["84289.90", "5.166297"], ["84298.40", "5.438208"], ["84306.90", "4.169293"], ["84520.50", "0.000238"]], "bids": [["84004.90", "0.000396"], ["83999.60", "0"], ["83977.20", "5.347571"], ["83975.50", "0.000948"], ["83970.20", "0"], ["83968.70", "4.803750"], ["83960.20", "5.075661"], ["83951.70", "3.897382"], ["83943.20", "4.259930"], ["83934.70", "4.894387"], ["83926.20", "4.622477"], ["83917.70", "5.438208"], ["83909.20", "4.441203"], ["83900.70", "5.528845"], ["83892.20", "4.985024"], ["83883.70", "4.169293"], ["83875.20", "5.166297"], ["83866.70", "4.350566"], ["83858.20", "5.256934"], ["83849.70", "4.713114"], ["83841.20", "4.078656"], ["83832.70", "4.531840"], ["83824.20", "3.988019"], ["83815.70", "5.619481"]], "checksum": -913592959, "ts": "1742555350889"}], "ts": 1742555350892}}
{"exchange": "BYBIT", "timestamp": 1742555350.941092, "message": {"topic": "orderbook.200.BTCUSDT", "ts": 1742555350920, "type": "delta", "data": {"s": "BTCUSDT", "b": [["84061.9", "0.274747"], ["84039.6", "0"], ["84039.5", "0.033098"]], "a": [["84072.4", "0.158303"], ["84101.8", "0.012847"]], "u": 20686, "seq": 67549989018}, "cts": 1742555350906}}
{"exchange": "BITGET", "timestamp": 1742555351.122871, "message": {"action": "update", "arg": {"instType": "SPOT", "channel": "books", "instId": "BTCUSDT"}, "data": [{"asks": [["84029.41", "0.886736"], ["84030.16", "0.088149"], ["84030.19", "0"], ["84042.67", "0.112619"], ["84043.79", "0"], ["84089.40", "0.001306"], ["84091.40", "0.003437"], ["84093.40", "0.009043"], ["84095.40", "0.023798"], ["84097.40", "0.062626"], ["84099.40", "0.164806"], ["84101.40", "0.433699"], ["84103.40", "1.141315"], ["84104.80", "2.267940"], ["84108.60", "0.683010"], ["84145.40", "3.988019"], ["84153.90", "4.985024"], ["84162.40", "5.075661"], ["84170.90", "5.347571"], ["84179.40", "4.350566"], ["84187.90", "3.897382"], ["84196.40", "5.619481"], ["84204.90", "5.166297"], ["84213.40", "5.438208"], ["84230.40", "5.256934"], ["84238.90", "5.528845"], ["84255.90", "4.803750"], ["84264.40", "4.169293"], ["84272.90", "4.259930"], ["84281.40", "4.441203"], ["84289.90", "4.078656"], ["84298.40", "4.531840"], ["84306.90", "4.713114"], ["84520.50", "0"]], "bids": [["83979.00", "0.000015"], ["83977.20", "4.803750"], ["83968.70", "4.078656"], ["83960.20", "4.713114"], ["83951.70", "5.438208"], ["83934.70", "5.619481"], ["83926.20", "3.988019"], ["83917.70", "4.441203"], ["83909.20", "4.350566"], ["83900.70", "4.531840"], ["83892.20", "5.347571"], ["83883.70", "4.622477"], ["83875.20", "5.075661"], ["83866.70", "3.897382"], ["83849.70", "5.166297"], ["83841.20", "4.169293"], ["83832.70", "4.985024"], ["83824.20", "4.894387"], ["83815.70", "5.528845"]], "checksum": 1620230638, "ts": "1742555351094"}], "ts": 1742555351097}}
{"exchange": "BYBIT", "timestamp": 1742555351.140155, "message": {"topic": "orderbook.200.BTCUSDT", "ts": 1742555351119, "type": "delta", "data": {"s": "BTCUSDT", "b": [["84023.8", "0.003181"], ["84023.7", "0"], ["84023.6", "0.013"], ["84023.5", "0.012881"], ["83982.5", "0"]], "a": [["84079.7", "0.112619"], ["84080.8", "0"], ["84101.8", "0"], ["84101.9", "0.001466"], ["84102.4", "0.013"], ["84102.5", "0.012847"], ["84102.7", "0"], ["84102.8", "0"], ["84103.3", "0.04"], ["84103.4", "0.04"], ["84133.5", "0"]], "u": 20687, "seq": 67549989037}, "cts": 1742555351054}}
{"exchange": "BITGET", "timestamp": 1742555351.327711, "message": {"action": "update", "arg": {"instType": "SPOT", "channel": "books", "instId": "BTCUSDT"}, "data": [{"asks": [["84042.66", "0.033786"], ["84043.78", "0"], ["84106.70", "0.274920"], ["84145.40", "5.166297"], ["84153.90", "5.619481"], ["84162.40", "4.350566"], ["84170.90", "3.897382"], ["84179.40", "4.169293"], ["84187.90", "4.803750"], ["84196.40", "5.438208"], ["84204.90", "4.985024"], ["84213.40", "5.347571"], ["84221.90", "4.441203"], ["84230.40", "4.713114"], ["84238.90", "5.256934"], ["84247.40", "4.259930"], ["84255.90", "5.528845"], ["84264.40", "4.894387"], ["84272.90", "4.531840"], ["84281.40", "3.988019"], ["84289.90", "4.622477"], ["84298.40", "4.078656"], ["84306.90", "5.075661"]], "bids": [["84029.40", "1.073789"], ["84023.20", "1.190915"], ["84021.20", "3.133987"], ["84019.20", "8.247333"], ["83977.20", "4.713114"], ["83977.00", "0"], ["83968.70", "3.897382"], ["83960.20", "5.166297"], ["83951.70", "4.078656"], ["83943.20", "4.441203"], ["83934.70", "4.259930"], ["83926.20", "5.347571"], ["83917.70", "4.803750"], ["83909.20", "5.619481"], ["83900.70", "3.988019"], ["83892.20", "5.256934"], ["83875.20", "5.528845"], ["83866.70", "5.438208"], ["83858.20", "4.169293"], ["83849.70", "4.531840"], ["83841.20", "4.350566"], ["83832.70", "5.075661"], ["83815.70", "4.985024"], ["83653.94", "0.000133"]], "checksum": 745933225, "ts": "1742555351298"}], "ts": 1742555351302}}
{"exchange": "BYBIT", "timestamp": 1742555351.340104, "message": {"topic": "orderbook.200.BTCUSDT", "ts": 1742555351320, "type": "delta", "data": {"s": "BTCUSDT", "b": [], "a": [["84078.6", "0"], ["84133.5", "0.001851"]], "u": 20688, "seq": 67549989049}, "cts": 1742555351280}}
{"exchange": "BITGET", "timestamp": 1742555351.529734, "message": {"action": "update", "arg": {"instType": "SPOT", "channel": "books", "instId": "BTCUSDT"}, "data": [{"asks": [["84029.42", "0.000117"], ["84030.16", "0"], ["84101.40", "0.433544"], ["84103.40", "1.140905"], ["84107.50", "0.022710"], ["84108.90", "0"], ["84145.40", "5.347571"], ["84153.90", "4.259930"], ["84162.40", "3.897382"], ["84170.90", "5.528845"], ["84179.40", "5.438208"], ["84187.90", "4.985024"], ["84196.40", "4.531840"], ["84204.90", "4.894387"], ["84213.40", "4.713114"], ["84221.90", "4.169293"], ["84230.40", "5.619481"], ["84238.90", "5.166297"], ["84247.40", "5.075661"], ["84255.90", "4.350566"], ["84264.40", "3.988019"], ["84272.90", "4.622477"], ["84281.40", "4.078656"], ["84289.90", "4.441203"], ["84298.40", "5.256934"], ["84306.90", "4.803750"], ["84520.50", "0.000238"]], "bids": [["84019.20", "8.247519"], ["84007.82", "0.011361"], ["83977.20", "4.078656"], ["83977.00", "0.000017"], ["83968.70", "5.347571"], ["83951.70", "4.169293"], ["83943.20", "5.256934"], ["83934.70", "5.075661"], ["83926.20", "4.803750"], ["83917.70", "3.988019"], ["83909.20", "5.528845"], ["83900.70", "4.713114"], ["83892.20", "5.438208"], ["83883.70", "4.531840"], ["83875.20", "4.622477"], ["83866.70", "5.619481"], ["83858.20", "4.894387"], ["83849.70", "4.259930"], ["83832.70", "3.897382"], ["83824.20", "4.441203"], ["83653.94", "0"]], "checksum": 444074520, "ts": "1742555351500"}], "ts": 1742555351504}}
{"exchange": "BYBIT", "timestamp": 1742555351.539358, "message": {"topic": "orderbook.200.BTCUSDT", "ts": 1742555351520, "type": "delta", "data": {"s": "BTCUSDT", "b": [["84009", "16.570662"], ["84006.2", "0"]], "a": [["84080.4", "0.023812"], ["84098.4", "0.002125"], ["84099.4", "0"], ["84133.5", "0"]], "u": 20689, "seq": 67549989059}, "cts": 1742555351458}}
{"exchange": "BITGET", "timestamp": 1742555351.736308, "message": {"action": "update", "arg": {"instType": "SPOT", "channel": "books", "instId": "BTCUSDT"}, "data": [{"asks": [["84029.41", "0.904974"], ["84030.14", "0.088149"], ["84080.97", "0"], ["84089.40", "0.002087"], ["84091.40", "0.005491"], ["84093.40", "0.014452"], ["84095.40", "0.038030"], ["84097.40", "0.100080"], ["84099.40", "0.263368"], ["84101.40", "0.693074"], ["84103.40", "1.823879"], ["84108.60", "0.635760"], ["84145.40", "4.078656"], ["84153.90", "4.985024"], ["84162.40", "5.619481"], ["84170.90", "4.259930"], ["84179.40", "4.713114"], ["84187.90", "4.894387"], ["84196.40", "4.803750"], ["84204.90", "5.166297"], ["84213.40", "4.169293"], ["84221.90", "4.441203"], ["84230.40", "4.622477"], ["84238.90", "5.256934"], ["84247.40", "3.897382"], ["84255.90", "5.528845"], ["84264.40", "4.531840"], ["84272.90", "4.350566"], ["84281.40", "3.988019"], ["84289.90", "5.075661"], ["84298.40", "5.438208"], ["84306.90", "5.347571"]], "bids": [["84029.20", "0.064652"], ["84027.20", "0.170137"], ["84025.20", "0.447731"], ["84023.20", "1.178237"], ["84021.20", "3.100626"], ["84019.20", "8.159541"], ["83977.20", "3.897382"], ["83968.70", "5.256934"], ["83960.20", "4.078656"], ["83951.70", "4.803750"], ["83943.20", "4.259930"], ["83934.70", "4.985024"], ["83926.20", "4.713114"], ["83917.70", "5.438208"], ["83909.20", "5.347571"], ["83900.70", "5.619481"], ["83892.20", "5.166297"], ["83875.20", "3.988019"], ["83866.70", "4.894387"], ["83858.20", "5.528845"], ["83849.70", "4.441203"], ["83841.20", "4.622477"], ["83832.70", "4.169293"], ["83824.20", "5.075661"], ["83815.70", "4.350566"]], "checksum": 1650604330, "ts": "1742555351707"}], "ts": 1742555351711}}
{"exchange": "BYBIT", "timestamp": 1742555351.739906, "message": {"topic": "orderbook.200.BTCUSDT", "ts": 1742555351720, "type": "delta", "data": {"s": "BTCUSDT", "b": [["84061.9", "0.276531"], ["84010.5", "5.271578"]], "a": [], "u": 20690, "seq": 67549989072}, "cts": 1742555351667}}
{"exchange": "BYBIT", "timestamp": 1742555351.93975, "message": {"topic": "orderbook.200.BTCUSDT", "ts": 1742555351920, "type": "delta", "data": {"s": "BTCUSDT", "b": [["84023.6", "0"], ["84023.4", "0.012881"], ["84009", "0"], ["84006.2", "16.570662"]], "a": [["84102.4", "0"], ["84102.5", "0"], ["84102.6", "0.012847"], ["84102.7", "0.012847"], ["84103.3", "0"], ["84103.4", "0"], ["84103.5", "0.04"], ["84103.6", "0.04"]], "u": 20691, "seq": 67549989085}, "cts": 1742555351850}}
{"exchange": "BITGET", "timestamp": 1742555351.951356, "message": {"action": "update", "arg": {"instType": "SPOT", "channel": "books", "instId": "BTCUSDT"}, "data": [{"asks": [["84080.96", "0.178243"], ["84145.40", "5.438208"], ["84153.90", "4.350566"], ["84162.40", "4.894387"], ["84170.90", "4.713114"], ["84179.40", "5.528845"], ["84187.90", "5.075661"], ["84196.40", "4.441203"], ["84204.90", "4.259930"], ["84221.90", "5.256934"], ["84230.40", "5.347571"], ["84238.90", "4.803750"], ["84247.40", "5.619481"], ["84255.90", "4.622477"], ["84264.40", "5.166297"], ["84272.90", "4.078656"], ["84281.40", "4.531840"], ["84289.90", "3.988019"], ["84298.40", "3.897382"], ["84306.90", "4.985024"], ["84520.50", "0"]], "bids": [["83978.17", "0"], ["83978.00", "0.000032"], ["83977.20", "4.078656"], ["83976.33", "0.003598"], ["83968.70", "4.350566"], ["83960.20", "4.803750"], ["83951.70", "4.259930"], ["83943.20", "5.166297"], ["83934.70", "4.531840"], ["83926.20", "3.988019"], ["83917.70", "4.894387"], ["83909.20", "4.622477"], ["83900.70", "5.075661"], ["83892.20", "5.619481"], ["83883.70", "4.713114"], ["83875.20", "5.256934"], ["83866.70", "5.438208"], ["83858.20", "4.985024"], ["83849.70", "5.528845"], ["83841.20", "5.347571"], ["83832.70", "4.441203"], ["83824.20", "3.897382"], ["83815.70", "4.169293"]], "checksum": 1650604330, "ts": "1742555351911"}], "ts": 1742555351912}}
{"exchange": "BYBIT", "timestamp": 1742555352.140296, "message": {"topic": "orderbook.200.BTCUSDT", "ts": 1742555352120, "type": "delta", "data": {"s": "BTCUSDT", "b": [["84061.9", "0.105531"], ["84023.6", "0.013"], ["84023.4", "0"], ["84016.8", "0"], ["84010.5", "0.327005"], ["83982.5", "0.011992"]], "a": [["84062", "0.204098"], ["84068.9", "0"], ["84102.9", "0.04"], ["84103", "0.04"], ["84103.5", "0"], ["84103.6", "0"], ["84133.5", "0.001851"]], "u": 20692, "seq": 67549989140}, "cts": 1742555352098}}
{"exchange": "BITGET", "timestamp": 1742555352.173473, "message": {"action": "update", "arg": {"instType": "SPOT", "channel": "books", "instId": "BTCUSDT"}, "data": [{"asks": [["84029.42", "0.000100"], ["84030.11", "0.088149"], ["84030.14", "0"], ["84145.40", "4.894387"], ["84153.90", "5.075661"], ["84162.40", "5.256934"], ["84170.90", "5.528845"], ["84179.40", "4.169293"], ["84187.90", "3.897382"], ["84196.40", "4.259930"], ["84204.90", "5.438208"], ["84213.40", "4.985024"], ["84221.90", "5.166297"], ["84230.40", "3.988019"], ["84238.90", "4.622477"], ["84247.40", "4.713114"], ["84255.90", "4.350566"], ["84264.40", "4.078656"], ["84272.90", "5.619481"], ["84281.40", "4.803750"], ["84289.90", "4.531840"], ["84298.40", "5.347571"], ["84306.90", "4.441203"]], "bids": [["83978.00", "0.000015"], ["83977.20", "4.441203"], ["83960.20", "3.897382"], ["83951.70", "5.528845"], ["83943.20", "4.169293"], ["83934.70", "4.078656"], ["83926.20", "4.259930"], ["83909.20", "5.166297"], ["83892.20", "4.985024"], ["83883.70", "4.803750"], ["83875.20", "3.988019"], ["83866.70", "5.347571"], ["83858.20", "5.256934"], ["83849.70", "4.713114"], ["83841.20", "5.619481"], ["83832.70", "4.622477"], ["83824.20", "5.438208"], ["83815.70", "4.531840"]], "checksum": 1580517218, "ts": "1742555352134"}], "ts": 1742555352138}}
{"exchange": "BYBIT", "timestamp": 1742555352.340366, "message": {"topic": "orderbook.200.BTCUSDT", "ts": 1742555352320, "type": "delta", "data": {"s": "BTCUSDT", "b": [["84023.7", "0.012881"], ["84023.6", "0.012881"], ["84023.5", "0"], ["84009", "15.868419"], ["84006.2", "0"]], "a": [["84102.1", "0.012847"], ["84102.2", "0.012847"], ["84102.6", "0"], ["84102.7", "0"], ["84102.9", "0"], ["84103.1", "1.466821"], ["84134.2", "0.000423"]], "u": 20693, "seq": 67549989156}, "cts": 1742555352272}}
{"exchange": "BITGET", "timestamp": 1742555352.375847, "message": {"action": "update", "arg": {"instType": "SPOT", "channel": "books", "instId": "BTCUSDT"}, "data": [{"asks": [["84087.40", "0.001023"], ["84089.40", "0.002693"], ["84091.40", "0.007087"], ["84093.40", "0.018649"], ["84095.40", "0.049075"], ["84097.40", "0.129145"], ["84099.40", "0.339855"], ["84101.40", "0.894356"], ["84103.40", "2.353570"], ["84104.80", "0.833880"], ["84105.20", "2.356500"], ["84106.70", "0.274170"], ["84107.00", "0.072720"], ["84108.60", "0.635580"], ["84110.10", "0.085740"], ["84117.30", "0"], ["84117.50", "0"], ["84117.60", "0"], ["84145.40", "5.166297"], ["84153.90", "3.988019"], ["84170.90", "4.350566"], ["84179.40", "4.803750"], ["84187.90", "5.438208"], ["84196.40", "4.531840"], ["84204.90", "5.075661"], ["84221.90", "4.713114"], ["84230.40", "5.619481"], ["84238.90", "5.528845"], ["84247.40", "5.347571"], ["84255.90", "4.078656"], ["84264.40", "4.169293"], ["84272.90", "4.441203"], ["84281.40", "3.897382"], ["84289.90", "4.894387"], ["84298.40", "4.259930"], ["84306.90", "4.622477"], ["84520.50", "0.000238"], ["84520.67", "0.002384"]], "bids": [["83977.20", "4.259930"], ["83968.70", "4.622477"], ["83960.20", "4.078656"], ["83951.70", "3.897382"], ["83943.20", "4.441203"], ["83934.70", "5.438208"], ["83926.20", "5.528845"], ["83917.70", "4.169293"], ["83900.70", "4.985024"], ["83892.20", "4.803750"], ["83883.70", "5.075661"], ["83875.20", "4.894387"], ["83866.70", "3.988019"], ["83858.20", "4.350566"], ["83849.70", "4.531840"], ["83832.70", "5.256934"], ["83824.20", "5.347571"], ["83815.70", "4.713114"]], "checksum": 1580517218, "ts": "1742555352338"}], "ts": 1742555352340}}
{"exchange": "BYBIT", "timestamp": 1742555352.539668, "message": {"topic": "orderbook.200.BTCUSDT", "ts": 1742555352520, "type": "delta", "data": {"s": "BTCUSDT", "b": [["84061.9", "0.103747"], ["84023.8", "0.016062"], ["84023.6", "0"], ["84018.4", "0.001784"], ["84009", "0"], ["84006.2", "15.868419"]], "a": [["84097.2", "0.002125"], ["84098.4", "0"], ["84101.8", "0.012847"], ["84101.9", "0.014313"], ["84102.1", "0"], ["84102.2", "0"], ["84134.3", "0.001466"]], "u": 20694, "seq": 67549989176}, "cts": 1742555352470}}
{"exchange": "BITGET", "timestamp": 1742555352.574092, "message": {"action": "update", "arg": {"instType": "SPOT", "channel": "books", "instId": "BTCUSDT"}, "data": [{"asks": [["84030.11", "0"], ["84087.40", "0.001286"], ["84089.40", "0.003383"], ["84091.40", "0.008904"], ["84093.40", "0.023432"], ["84095.40", "0.061662"], ["84097.40", "0.162268"], ["84099.40", "0.427022"], ["84101.40", "1.123741"], ["84103.40", "2.957214"], ["84104.20", "0.001770"], ["84104.80", "0.833460"], ["84110.10", "0.098130"], ["84111.70", "0.593370"], ["84111.80", "1.350000"], ["84117.20", "0"], ["84145.40", "4.259930"], ["84153.90", "5.619481"], ["84162.40", "4.894387"], ["84170.90", "4.531840"], ["84179.40", "4.441203"], ["84196.40", "5.166297"], ["84204.90", "3.988019"], ["84213.40", "4.713114"], ["84221.90", "4.622477"], ["84230.40", "4.169293"], ["84238.90", "5.075661"], ["84247.40", "4.803750"], ["84255.90", "5.528845"], ["84264.40", "3.897382"], ["84272.90", "4.350566"], ["84281.40", "5.256934"], ["84289.90", "4.078656"], ["84298.40", "5.347571"], ["84306.90", "4.985024"]], "bids": [["84029.40", "1.071430"], ["84010.90", "0"], ["83977.20", "3.897382"], ["83968.70", "5.166297"], ["83960.20", "5.256934"], ["83951.70", "4.622477"], ["83943.20", "3.988019"], ["83934.70", "5.347571"], ["83926.20", "4.803750"], ["83917.70", "4.078656"], ["83909.20", "4.713114"], ["83900.70", "4.441203"], ["83892.20", "4.531840"], ["83883.70", "4.894387"], ["83875.20", "5.528845"], ["83866.70", "5.619481"], ["83858.20", "5.075661"], ["83849.70", "4.350566"], ["83841.20", "4.259930"], ["83832.70", "5.438208"], ["83824.20", "4.985024"], ["83815.70", "4.169293"], ["83653.94", "0.000133"]], "checksum": 932061372, "ts": "1742555352543"}], "ts": 1742555352547}}
{"exchange": "BYBIT", "timestamp": 1742555352.739939, "message": {"topic": "orderbook.200.BTCUSDT", "ts": 1742555352720, "type": "delta", "data": {"s": "BTCUSDT", "b": [["84061.9", "0.100774"], ["84060.5", "0"], ["84051.6", "0"], ["84038", "0"], ["84034.3", "0"], ["84029.1", "0.000333"], ["84027.6", "0"], ["84025", "0.000199"], ["84023.8", "0.003181"], ["84023.7", "0"], ["84023.6", "0.012881"], ["84023.5", "0.012881"], ["84019.3", "0"], ["84013.6", "0.135511"], ["83990.6", "0.001333"], ["83982.2", "0.001333"], ["83981.8", "0.0032"], ["83981.7", "0.001466"], ["83981.5", "0.005942"]], "a": [["84062", "0.375098"], ["84069.2", "0.089099"], ["84085.5", "0.089099"], ["84094.1", "0.002125"], ["84097.2", "0"], ["84101.8", "0"], ["84101.9", "0.001466"], ["84102.3", "0.013"], ["84102.4", "0.012847"], ["84103", "0"], ["84103.1", "1.426821"], ["84103.2", "0.04"], ["84103.3", "0.04"], ["84113.2", "0.000333"], ["84116.2", "0"], ["84124.7", "2.260269"], ["84133.5", "0"], ["84134.2", "0"], ["84134.3", "0"]], "u": 20695, "seq": 67549989238}, "cts": 1742555352716}}
{"exchange": "BITGET", "timestamp": 1742555352.787356, "message": {"action": "update", "arg": {"instType": "SPOT", "channel": "books", "instId": "BTCUSDT"}, "data": [{"asks": [["84029.41", "1.114144"], ["84030.08", "0.088149"], ["84030.69", "0.056378"], ["84032.53", "0"], ["84083.52", "0.010000"], ["84085.40", "0.001496"], ["84087.40", "0.003936"], ["84089.40", "0.010358"], ["84091.40", "0.027259"], ["84093.40", "0.071733"], ["84095.40", "0.188773"], ["84097.40", "0.496770"], ["84099.40", "1.307290"], ["84101.40", "3.440236"], ["84103.40", "9.053252"], ["84105.10", "0.010320"], ["84105.20", "0"], ["84106.10", "0.067800"], ["84106.90", "0"], ["84108.10", "0.067800"], ["84110.20", "0.178290"], ["84116.90", "0"], ["84145.40", "4.803750"], ["84153.90", "5.075661"], ["84162.40", "4.350566"], ["84170.90", "4.985024"], ["84179.40", "4.078656"], ["84187.90", "4.259930"], ["84196.40", "5.528845"], ["84213.40", "5.256934"], ["84221.90", "5.347571"], ["84230.40", "3.897382"], ["84238.90", "4.622477"], ["84247.40", "4.169293"], ["84255.90", "4.713114"], ["84264.40", "5.166297"], ["84272.90", "5.438208"], ["84281.40", "4.531840"], ["84289.90", "5.619481"], ["84298.40", "4.894387"], ["84306.90", "4.441203"], ["84329.54", "0"], ["84520.50", "0"], ["84520.67", "0"]], "bids": [["84029.40", "0.940184"], ["84029.20", "0.034838"], ["84027.20", "0.091680"], ["84025.20", "0.241262"], ["84023.20", "0.634900"], ["84021.20", "1.670790"], ["84019.20", "4.396817"], ["84018.95", "0.028180"], ["84018.10", "0"], ["84017.60", "0.155670"], ["84016.60", "0.240000"], ["84016.50", "0.180000"], ["83979.00", "0.000017"], ["83968.70", "4.894387"], ["83960.20", "4.803750"], ["83951.70", "4.350566"], ["83943.20", "4.622477"], ["83934.70", "5.438208"], ["83926.20", "5.256934"], ["83917.70", "3.988019"], ["83909.20", "4.259930"], ["83900.70", "5.528845"], ["83892.20", "5.347571"], ["83883.70", "5.075661"], ["83875.20", "4.531840"], ["83858.20", "4.985024"], ["83849.70", "4.078656"], ["83841.20", "4.441203"], ["83832.70", "4.169293"], ["83824.20", "4.713114"], ["83815.70", "5.166297"], ["83654.23", "0"], ["83653.94", "0"]], "checksum": -1768810484, "ts": "1742555352747"}], "ts": 1742555352758}}
{"exchange": "BYBIT", "timestamp": 1742555352.939611, "message": {"topic": "orderbook.200.BTCUSDT", "ts": 1742555352920, "type": "delta", "data": {"s": "BTCUSDT", "b": [["84061.9", "0.094057"], ["84055.7", "0.001466"], ["84050.3", "0.100751"], ["84045.8", "0.003896"], ["84039.5", "0"], ["84038", "0.059399"], ["84037.4", "0.036032"], ["84028.6", "0"], ["84027.4", "0.197349"], ["84025.1", "0"], ["84022.8", "0.024825"], ["84016.5", "2.07604"], ["84013.6", "0"], ["84006.2", "0"], ["84000.5", "15.324506"]], "a": [["84062", "0.213228"], ["84069.2", "0"], ["84075.6", "0.112018"], ["84086.2", "0.003576"], ["84107", "0.022631"], ["84133.1", "0"]], "u": 20696, "seq": 67549989351}, "cts": 1742555352905}}
{"exchange": "BITGET", "timestamp": 1742555352.987495, "message": {"action": "update", "arg": {"instType": "SPOT", "channel": "books", "instId": "BTCUSDT"}, "data": [{"asks": [["84029.41", "0.956551"], ["84030.69", "0"], ["84040.67", "0"], ["84081.74", "0.667710"], ["84087.40", "0.004066"], ["84089.40", "0.010699"], ["84091.40", "0.028155"], ["84093.40", "0.074093"], ["84095.40", "0.194982"], ["84097.40", "0.513110"], ["84099.40", "1.350290"], ["84101.40", "3.553395"], ["84103.40", "9.351038"], ["84103.80", "0.959730"], ["84104.80", "0"], ["84105.10", "0.008250"], ["84106.10", "0.067980"], ["84106.50", "0.070380"], ["84106.70", "0.745500"], ["84108.60", "0.089640"], ["84111.30", "0.462270"], ["84112.20", "0.045540"], ["84113.50", "0"], ["84115.70", "0"], ["84116.90", "0.015120"], ["84117.20", "0.107070"], ["84117.30", "2.674740"], ["84117.50", "0.070080"], ["84117.60", "0.534660"], ["84145.40", "5.166297"], ["84153.90", "5.256934"], ["84162.40", "4.713114"], ["84170.90", "5.528845"], ["84179.40", "4.985024"], ["84187.90", "4.803750"], ["84196.40", "4.350566"], ["84204.90", "4.259930"], ["84213.40", "4.078656"], ["84221.90", "4.441203"], ["84230.40", "3.988019"], ["84238.90", "5.619481"], ["84255.90", "3.897382"], ["84264.40", "4.622477"], ["84272.90", "5.075661"], ["84281.40", "5.347571"], ["84289.90", "5.438208"], ["84306.90", "4.531840"], ["84517.86", "0"], ["84518.98", "0"], ["84520.00", "0"]], "bids": [["84029.20", "0.040288"], ["84028.21", "0.103004"], ["84027.20", "0.106019"], ["84025.20", "0.278999"], ["84023.20", "0.734206"], ["84021.48", "0.000019"], ["84021.20", "1.932123"], ["84019.20", "5.084533"], ["84019.15", "0"], ["84019.10", "0.001020"], ["84018.50", "0.454470"], ["84018.10", "0.015000"], ["84017.80", "0.015000"], ["84017.60", "0"], ["84017.50", "0.030210"], ["84017.20", "0.030000"], ["84016.60", "0"], ["84016.50", "0"], ["84016.30", "2.402160"], ["84015.20", "0"], ["84014.20", "2.799060"], ["84013.60", "0.060000"], ["84013.40", "0.360000"], ["84011.50", "0"], ["84007.90", "0"], ["84007.80", "0"], ["84007.70", "0"], ["83977.20", "4.622477"], ["83968.70", "3.988019"], ["83960.20", "4.078656"], ["83951.70", "4.169293"], ["83943.20", "4.713114"], ["83934.70", "4.985024"], ["83926.20", "4.894387"], ["83917.70", "5.256934"], ["83909.20", "5.528845"], ["83900.70", "5.075661"], ["83892.20", "5.166297"], ["83883.70", "5.438208"], ["83875.20", "4.350566"], ["83858.20", "4.259930"], ["83849.70", "5.347571"], ["83832.70", "4.531840"], ["83824.20", "4.803750"], ["83815.70", "3.897382"], ["83654.23", "0.000009"]], "checksum": -132371047, "ts": "1742555352955"}], "ts": 1742555352960}}
{"exchange": "BYBIT", "timestamp": 1742555353.140133, "message": {"topic": "orderbook.200.BTCUSDT", "ts": 1742555353120, "type": "delta", "data": {"s": "BTCUSDT", "b": [["84050.3", "0.072655"], ["84023.6", "0"], ["84023.4", "0.012881"], ["84006.2", "15.324506"], ["84000.5", "0"], ["83982.6", "0.043784"]], "a": [["84088.8", "0.002125"], ["84094.1", "0"], ["84107.9", "2.260268"], ["84124.7", "0.003237"]], "u": 20697, "seq": 67549989404}, "cts": 1742555353082}}
{"exchange": "BITGET", "timestamp": 1742555353.206866, "message": {"action": "update", "arg": {"instType": "SPOT", "channel": "books", "instId": "BTCUSDT"}, "data": [{"asks": [["84029.41", "0.960051"], ["84030.06", "0.088149"], ["84030.08", "0"], ["84039.65", "0.112617"], ["84042.67", "0"], ["84081.74", "0.712464"], ["84085.40", "0.001260"], ["84087.40", "0.003315"], ["84089.40", "0.008725"], ["84091.40", "0.022959"], ["84093.40", "0.060418"], ["84095.40", "0.158997"], ["84097.40", "0.418412"], ["84099.40", "1.101085"], ["84101.40", "2.897590"], ["84103.40", "7.625237"], ["84105.10", "0"], ["84106.50", "0"], ["84108.60", "0.217110"], ["84110.10", "0.103470"], ["84111.70", "0.161250"], ["84114.50", "0.012510"], ["84153.90", "3.897382"], ["84170.90", "5.619481"], ["84179.40", "5.256934"], ["84187.90", "5.528845"], ["84196.40", "4.259930"], ["84204.90", "5.075661"], ["84213.40", "4.531840"], ["84221.90", "4.350566"], ["84230.40", "5.347571"], ["84238.90", "4.985024"], ["84247.40", "4.078656"], ["84255.90", "4.441203"], ["84264.40", "4.803750"], ["84272.90", "4.169293"], ["84281.40", "5.438208"], ["84289.90", "4.894387"], ["84298.40", "3.988019"], ["84306.90", "4.622477"], ["84517.86", "0.000016"]], "bids": [["84029.40", "1.057467"], ["84029.20", "0.045200"], ["84027.20", "0.118946"], ["84025.20", "0.313017"], ["84023.20", "0.823728"], ["84021.20", "2.167706"], ["84019.21", "0.089238"], ["84019.20", "5.704490"], ["84019.10", "0.074820"], ["84018.95", "0"], ["84018.70", "3.527010"], ["84018.50", "0.249390"], ["84017.90", "0.067980"], ["84017.60", "0.035670"], ["84017.50", "0.030000"], ["84016.30", "0.045540"], ["84014.20", "2.073150"], ["84011.40", "0.120000"], ["84007.90", "1.476000"], ["83977.20", "4.803750"], ["83968.70", "5.166297"], ["83960.20", "5.619481"], ["83951.70", "4.078656"], ["83943.20", "3.897382"], ["83934.70", "5.256934"], ["83926.20", "5.347571"], ["83917.70", "4.441203"], ["83909.20", "4.259930"], ["83900.70", "5.528845"], ["83892.20", "3.988019"], ["83883.70", "4.169293"], ["83875.20", "4.713114"], ["83866.70", "4.894387"], ["83858.20", "5.075661"], ["83849.70", "4.985024"], ["83841.20", "4.531840"], ["83832.70", "5.438208"], ["83824.20", "4.350566"], ["83815.70", "4.622477"], ["83658.54", "0"], ["83656.60", "0"], ["83655.00", "0"], ["83654.23", "0"]], "checksum": -548534947, "ts": "1742555353155"}], "ts": 1742555353164}}
{"exchange": "BYBIT", "timestamp": 1742555353.3411, "message": {"topic": "orderbook.200.BTCUSDT", "ts": 1742555353320, "type": "delta", "data": {"s": "BTCUSDT", "b": [["83982.6", "0"], ["83982.3", "0.043784"]], "a": [["84101.6", "0.04"], ["84101.7", "0.04"], ["84103.2", "0"], ["84103.3", "0"]], "u": 20698, "seq": 67549989419}, "cts": 1742555353315}}
{"exchange": "BITGET", "timestamp": 1742555353.392848, "message": {"action": "update", "arg": {"instType": "SPOT", "channel": "books", "instId": "BTCUSDT"}, "data": [{"asks": [["84042.02", "0.003872"], ["84042.66", "0"], ["84087.40", "0.003108"], ["84089.40", "0.008179"], ["84091.40", "0.021523"], ["84093.40", "0.056639"], ["84095.40", "0.149051"], ["84097.40", "0.392241"], ["84099.40", "1.032211"], ["84101.40", "2.716345"], ["84103.40", "7.148278"], ["84111.70", "0.592530"], ["84145.40", "5.619481"], ["84153.90", "5.075661"], ["84162.40", "4.441203"], ["84170.90", "4.259930"], ["84179.40", "4.622477"], ["84187.90", "4.803750"], ["84196.40", "4.169293"], ["84204.90", "5.528845"], ["84213.40", "4.713114"], ["84221.90", "4.078656"], ["84230.40", "4.985024"], ["84238.90", "5.166297"], ["84247.40", "5.347571"], ["84255.90", "4.350566"], ["84264.40", "3.988019"], ["84272.90", "3.897382"], ["84281.40", "5.256934"], ["84289.90", "5.438208"], ["84298.40", "4.531840"], ["84306.90", "4.894387"]], "bids": [["84029.20", "0.045437"], ["84027.20", "0.119448"], ["84025.41", "0.000019"], ["84025.20", "0.314336"], ["84023.20", "0.827201"], ["84021.48", "0"], ["84021.20", "2.176845"], ["84019.20", "5.728540"], ["84016.30", "0"], ["84007.80", "0.120000"], ["83977.20", "5.075661"], ["83977.00", "0.000015"], ["83968.70", "5.528845"], ["83960.20", "4.713114"], ["83951.70", "4.531840"], ["83943.20", "5.347571"], ["83934.70", "3.897382"], ["83926.20", "5.438208"], ["83917.70", "4.259930"], ["83909.20", "4.441203"], ["83900.70", "3.988019"], ["83892.20", "4.078656"], ["83883.70", "4.894387"], ["83875.20", "5.256934"], ["83866.70", "5.166297"], ["83858.20", "4.985024"], ["83849.70", "5.619481"], ["83841.20", "4.169293"], ["83832.70", "4.803750"], ["83824.20", "4.622477"], ["83815.70", "4.350566"]], "checksum": -2063273115, "ts": "1742555353364"}], "ts": 1742555353367}}
{"exchange": "BYBIT", "timestamp": 1742555353.539847, "message": {"topic": "orderbook.200.BTCUSDT", "ts": 1742555353520, "type": "delta", "data": {"s": "BTCUSDT", "b": [["84051.1", "0.023755"], ["84001.3", "0.059399"], ["83996", "0.235392"], ["83985.3", "1.125197"], ["83982.3", "0"], ["83981.7", "0"], ["83981.5", "0"]], "a": [["84086.2", "0"], ["84107.9", "0.003236"], ["84116.2", "2.257032"]], "u": 20699, "seq": 67549989453}, "cts": 1742555353502}}
{"exchange": "BITGET", "timestamp": 1742555353.60651, "message": {"action": "update", "arg": {"instType": "SPOT", "channel": "books", "instId": "BTCUSDT"}, "data": [{"asks": [["84037.80", "0.014146"], ["84106.30", "0.072780"], ["84117.50", "0"], ["84117.60", "0"], ["84145.40", "5.256934"], ["84153.90", "4.985024"], ["84162.40", "4.259930"], ["84170.90", "5.619481"], ["84179.40", "4.441203"], ["84187.90", "3.897382"], ["84204.90", "5.166297"], ["84221.90", "5.438208"], ["84230.40", "5.528845"], ["84238.90", "5.075661"], ["84255.90", "4.894387"], ["84264.40", "4.622477"], ["84272.90", "4.350566"], ["84281.40", "4.803750"], ["84289.90", "4.531840"], ["84298.40", "4.078656"], ["84306.90", "3.988019"]], "bids": [["84029.20", "0.054150"], ["84027.20", "0.142500"], ["84025.20", "0.375000"], ["84023.20", "0.986842"], ["84021.20", "2.596953"], ["84019.20", "6.834086"], ["83977.20", "4.531840"], ["83968.70", "4.894387"], ["83960.20", "5.619481"], ["83951.70", "5.438208"], ["83934.70", "4.713114"], ["83926.20", "4.622477"], ["83917.70", "3.897382"], ["83909.20", "4.078656"], ["83900.70", "5.075661"], ["83892.20", "4.803750"], ["83883.70", "4.350566"], ["83875.20", "5.166297"], ["83866.70", "4.441203"], ["83858.20", "5.256934"], ["83849.70", "4.985024"], ["83841.20", "3.988019"], ["83832.70", "4.259930"], ["83824.20", "4.169293"], ["83815.70", "5.528845"]], "checksum": 646551625, "ts": "1742555353577"}], "ts": 1742555353581}}
{"exchange": "BYBIT", "timestamp": 1742555353.739966, "message": {"topic": "orderbook.200.BTCUSDT", "ts": 1742555353720, "type": "delta", "data": {"s": "BTCUSDT", "b": [["84061.9", "0.093957"], ["84050.3", "0.100382"], ["84048.1", "0.116556"], ["84038.3", "0.178031"], ["84029.2", "0.30373"], ["83982.5", "0"], ["83982.2", "0"], ["83981.8", "0"]], "a": [["84062", "0.213328"], ["84073.3", "0.112239"], ["84083.1", "0.188725"], ["84092.2", "0.296091"], ["84101", "0.059399"], ["84101.6", "0"], ["84101.8", "0.04"], ["84132.8", "0"]], "u": 20700, "seq": 67549989488}, "cts": 1742555353710}}
{"exchange": "BITGET", "timestamp": 1742555353.818287, "message": {"action": "update", "arg": {"instType": "SPOT", "channel": "books", "instId": "BTCUSDT"}, "data": [{"asks": [["84030.03", "0.088149"], ["84030.06", "0"], ["84037.79", "0.004244"], ["84083.06", "0.001598"], ["84084.92", "0.001597"], ["84090.19", "0"], ["84092.43", "0"], ["84145.40", "5.528845"], ["84153.90", "4.531840"], ["84162.40", "4.350566"], ["84170.90", "4.169293"], ["84179.40", "5.438208"], ["84187.90", "4.803750"], ["84196.40", "5.075661"], ["84204.90", "4.622477"], ["84213.40", "5.166297"], ["84221.90", "4.894387"], ["84230.40", "3.988019"], ["84238.90", "5.619481"], ["84247.40", "4.259930"], ["84255.90", "4.078656"], ["84264.40", "4.985024"], ["84272.90", "5.256934"], ["84281.40", "3.897382"], ["84289.90", "4.441203"], ["84298.40", "4.713114"], ["84306.90", "5.347571"], ["84517.86", "0"]], "bids": [["84029.40", "1.049575"], ["84029.20", "0.039782"], ["84028.21", "0.145501"], ["84027.20", "0.104689"], ["84025.20", "0.275497"], ["84023.20", "0.724991"], ["84021.20", "1.907872"], ["84019.21", "0"], ["84019.20", "5.020717"], ["84019.10", "0.435090"], ["84018.80", "0.016560"], ["84018.50", "0"], ["84017.90", "0.068190"], ["83979.94", "0"], ["83978.31", "0"], ["83977.20", "4.078656"], ["83972.81", "0.001176"], ["83970.81", "0.001173"], ["83968.70", "4.169293"], ["83960.20", "4.441203"], ["83951.70", "4.531840"], ["83943.20", "5.256934"], ["83934.70", "3.897382"], ["83926.20", "4.350566"], ["83917.70", "4.985024"], ["83909.20", "4.622477"], ["83900.70", "4.713114"], ["83892.20", "5.528845"], ["83883.70", "3.988019"], ["83875.20", "5.619481"], ["83866.70", "5.075661"], ["83858.20", "5.347571"], ["83849.70", "5.166297"], ["83841.20", "4.894387"], ["83832.70", "5.438208"], ["83824.20", "4.803750"], ["83815.70", "4.259930"], ["83658.54", "0.000036"]], "checksum": -338270257, "ts": "1742555353790"}], "ts": 1742555353793}}
{"exchange": "BYBIT", "timestamp": 1742555353.944791, "message": {"topic": "orderbook.200.BTCUSDT", "ts": 1742555353920, "type": "delta", "data": {"s": "BTCUSDT", "b": [["84038", "0"], ["84034.8", "0"], ["83982.5", "0.011992"], ["83982.2", "0.001333"]], "a": [["84079.8", "0.310448"], ["84107.8", "2.257032"], ["84116.2", "0"]], "u": 20701, "seq": 67549989518}, "cts": 1742555353902}}
{"exchange": "BITGET", "timestamp": 1742555354.033676, "message": {"action": "update", "arg": {"instType": "SPOT", "channel": "books", "instId": "BTCUSDT"}, "data": [{"asks": [["84029.41", "0.967051"], ["84029.42", "0.000117"], ["84087.40", "0.003256"], ["84089.40", "0.008570"], ["84091.40", "0.022552"], ["84093.40", "0.059346"], ["84095.40", "0.156174"], ["84097.40", "0.410985"], ["84099.40", "1.081539"], ["84101.40", "2.846157"], ["84103.40", "7.489885"], ["84153.90", "4.894387"], ["84162.40", "5.166297"], ["84170.90", "5.619481"], ["84179.40", "4.078656"], ["84187.90", "5.438208"], ["84196.40", "4.350566"], ["84204.90", "4.803750"], ["84213.40", "4.531840"], ["84221.90", "4.622477"], ["84230.40", "4.441203"], ["84238.90", "4.169293"], ["84247.40", "4.985024"], ["84255.90", "3.897382"], ["84264.40", "5.256934"], ["84272.90", "5.075661"], ["84281.40", "4.259930"], ["84289.90", "3.988019"]], "bids": [["84029.40", "1.049560"], ["84029.20", "0.040604"], ["84027.20", "0.106977"], ["84025.20", "0.281518"], ["84023.20", "0.740838"], ["84021.20", "1.949573"], ["84019.20", "5.130457"], ["84018.80", "0"], ["84018.70", "3.170940"], ["84017.60", "0.016470"], ["84007.70", "0.120000"], ["83995.99", "0"], ["83992.04", "0.000877"], ["83978.00", "0.000032"], ["83977.20", "4.169293"], ["83968.70", "4.622477"], ["83960.20", "3.897382"], ["83951.70", "5.528845"], ["83943.20", "4.350566"], ["83934.70", "4.985024"], ["83926.20", "4.259930"], ["83917.70", "3.988019"], ["83909.20", "5.075661"], ["83892.20", "4.803750"], ["83883.70", "5.256934"], ["83875.20", "4.078656"], ["83866.70", "4.531840"], ["83858.20", "5.619481"], ["83849.70", "5.347571"], ["83841.20", "5.438208"], ["83832.70", "4.894387"], ["83824.20", "4.441203"], ["83815.70", "5.166297"]], "checksum": 273004136, "ts": "1742555354003"}], "ts": 1742555354007}}
{"exchange": "BYBIT", "timestamp": 1742555354.139784, "message": {"topic": "orderbook.200.BTCUSDT", "ts": 1742555354119, "type": "delta", "data": {"s": "BTCUSDT", "b": [["84038.4", "0.059399"], ["84037.7", "0"], ["84036.5", "0.112616"], ["84029.3", "0.207226"], ["84027.4", "0.118804"], ["84023.6", "0.012881"], ["84023.4", "0"], ["83982.5", "0"], ["83982.2", "0"]], "a": [["84100.7", "0.013"], ["84100.8", "0.012845"], ["84101.6", "0.04"], ["84101.8", "0"], ["84102.3", "0"], ["84102.4", "0"]], "u": 20702, "seq": 67549989548}, "cts": 1742555354091}}
{"exchange": "BITGET", "timestamp": 1742555354.240585, "message": {"action": "update", "arg": {"instType": "SPOT", "channel": "books", "instId": "BTCUSDT"}, "data": [{"asks": [["84049.03", "0.035952"], ["84049.55", "0.119870"], ["84050.79", "0.035961"], ["84051.21", "0.006356"], ["84051.36", "0.006356"], ["84051.71", "0.006356"], ["84052.77", "0.010984"], ["84052.92", "0"], ["84053.04", "0.006356"], ["84053.20", "0.006356"], ["84053.28", "0"], ["84053.67", "0.016429"], ["84053.73", "0.006356"], ["84054.23", "0.006356"], ["84054.26", "0.006356"], ["84054.46", "0"], ["84054.56", "0.119883"], ["84054.61", "0.016429"], ["84054.67", "0.006356"], ["84054.71", "0.006356"], ["84054.89", "0"], ["84055.27", "0"], ["84055.38", "0"], ["84056.20", "0.006357"], ["84056.29", "0.010985"], ["84056.61", "0"], ["84056.95", "0"], ["84057.11", "0"], ["84057.40", "0"], ["84057.59", "0"], ["84057.91", "0"], ["84057.94", "0.119850"], ["84057.99", "0"], ["84058.37", "0"], ["84058.47", "0"], ["84058.55", "0"], ["84058.62", "0"], ["84059.01", "0.252088"], ["84059.48", "0.015895"], ["84059.59", "0.009989"], ["84060.05", "0"], ["84060.11", "0"], ["84061.83", "0"], ["84062.92", "0"], ["84063.24", "0"], ["84063.43", "0.015892"], ["84063.50", "0"], ["84064.27", "0.010988"], ["84067.19", "0"], ["84068.03", "0"], ["84080.96", "0"], ["84087.40", "0.003243"], ["84089.40", "0.008533"], ["84091.40", "0.022456"], ["84093.40", "0.059093"], ["84095.40", "0.155509"], ["84097.40", "0.409233"], ["84099.40", "1.076931"], ["84101.40", "2.834027"], ["84103.40", "7.457968"], ["84109.00", "0.070530"], ["84117.30", "0"], ["84145.40", "4.713114"], ["84162.40", "4.078656"], ["84179.40", "5.347571"], ["84187.90", "4.259930"], ["84196.40", "5.166297"], ["84213.40", "3.897382"], ["84221.90", "5.256934"], ["84230.40", "5.528845"], ["84238.90", "4.622477"], ["84247.40", "4.441203"], ["84255.90", "4.169293"], ["84264.40", "4.985024"], ["84272.90", "5.438208"], ["84281.40", "4.350566"], ["84289.90", "4.531840"], ["84298.40", "3.988019"], ["84306.90", "5.075661"], ["84517.86", "0.000016"], ["84518.98", "0.000029"]], "bids": [["84029.20", "0.043265"], ["84027.20", "0.113856"], ["84025.20", "0.299620"], ["84023.20", "0.788474"], ["84021.20", "2.074932"], ["84019.20", "5.460346"], ["84018.70", "0.813750"], ["84017.60", "0.035250"], ["84016.90", "2.356590"], ["84012.58", "0"], ["84012.11", "0"], ["84010.77", "0"], ["84010.40", "0"], ["84010.35", "0"], ["84010.30", "1.844160"], ["84009.84", "0"], ["84008.88", "0"], ["84008.72", "0"], ["84008.69", "0.089521"], ["84008.54", "0"], ["84008.38", "0.247687"], ["84008.01", "0"], ["84007.82", "0.004019"], ["84007.70", "0"], ["84007.40", "0"], ["84007.33", "0"], ["84007.21", "0"], ["84007.11", "0.008019"], ["84007.09", "0.083974"], ["84007.03", "0.008601"], ["84006.96", "0"], ["84006.67", "0.017824"], ["84006.49", "0.018262"], ["84006.17", "0.005949"], ["84005.49", "0"], ["84005.43", "0"], ["84005.04", "0.055678"], ["84004.81", "0.017110"], ["84004.63", "0.007134"], ["84004.15", "0.007342"], ["84004.09", "0.028876"], ["84003.68", "0"], ["84003.67", "0.007946"], ["84003.65", "0.008998"], ["84003.35", "0.025195"], ["84003.30", "0.224973"], ["84003.12", "0.017358"], ["84003.07", "0.008188"], ["84002.75", "0"], ["84002.24", "0"], ["84002.15", "0"], ["84001.67", "0.051984"], ["84001.58", "0.012660"], ["83999.79", "0.268485"], ["83998.84", "0.222759"], ["83998.48", "0.076143"], ["83998.28", "0"], ["83998.25", "0.021138"], ["83997.44", "0"], ["83994.53", "0.073244"], ["83993.69", "0.056390"], ["83977.20", "4.078656"], ["83968.70", "4.531840"], ["83960.20", "4.259930"], ["83943.20", "5.619481"], ["83926.20", "4.169293"], ["83917.70", "3.897382"], ["83909.20", "3.988019"], ["83900.70", "4.803750"], ["83892.20", "5.256934"], ["83883.70", "4.441203"], ["83875.20", "4.350566"], ["83866.70", "4.622477"], ["83858.20", "4.713114"], ["83841.20", "4.894387"], ["83832.70", "5.438208"], ["83824.20", "5.166297"], ["83815.70", "5.075661"], ["83659.49", "0"], ["83659.44", "0"], ["83658.54", "0"]], "checksum": -1145054688, "ts": "1742555354208"}], "ts": 1742555354211}}
{"exchange": "BYBIT", "timestamp": 1742555354.340427, "message": {"topic": "orderbook.200.BTCUSDT", "ts": 1742555354320, "type": "delta", "data": {"s": "BTCUSDT", "b": [], "a": [["84091.4", "0.002485"], ["84097.4", "0.084699"], ["84100.7", "0.012845"], ["84107.8", "0"], ["84113.4", "2.257032"]], "u": 20703, "seq": 67549989565}, "cts": 1742555354309}}
{"exchange": "BITGET", "timestamp": 1742555354.454982, "message": {"action": "update", "arg": {"instType": "SPOT", "channel": "books", "instId": "BTCUSDT"}, "data": [{"asks": [["84030.01", "0.088149"], ["84030.03", "0"], ["84046.22", "0.100498"], ["84059.01", "0.163918"], ["84106.30", "0.095490"], ["84107.50", "0"], ["84145.40", "4.078656"], ["84153.90", "5.347571"], ["84162.40", "5.075661"], ["84170.90", "4.350566"], ["84179.40", "5.528845"], ["84187.90", "4.803750"], ["84196.40", "4.259930"], ["84204.90", "4.441203"], ["84213.40", "4.713114"], ["84221.90", "5.619481"], ["84230.40", "4.985024"], ["84238.90", "3.988019"], ["84247.40", "4.531840"], ["84255.90", "3.897382"], ["84264.40", "5.256934"], ["84272.90", "4.169293"], ["84281.40", "4.894387"], ["84289.90", "5.438208"], ["84298.40", "4.622477"], ["84306.90", "5.166297"], ["84520.00", "0.000854"]], "bids": [["84029.40", "1.049537"], ["84018.80", "0.010110"], ["84007.80", "0"], ["83978.00", "0.000017"], ["83968.70", "4.985024"], ["83960.20", "4.350566"], ["83951.70", "5.256934"], ["83934.70", "5.166297"], ["83926.20", "3.988019"], ["83909.20", "5.347571"], ["83900.70", "5.438208"], ["83892.20", "5.075661"], ["83883.70", "4.803750"], ["83875.20", "4.169293"], ["83866.70", "4.894387"], ["83858.20", "5.528845"], ["83849.70", "4.259930"], ["83841.20", "4.713114"], ["83832.70", "4.622477"], ["83824.20", "4.441203"], ["83815.70", "4.531840"]], "checksum": -411090337, "ts": "1742555354418"}], "ts": 1742555354420}}
{"exchange": "BYBIT", "timestamp": 1742555354.539617, "message": {"topic": "orderbook.200.BTCUSDT", "ts": 1742555354519, "type": "delta", "data": {"s": "BTCUSDT", "b": [["84061.9", "0.076071"], ["84055", "0.000297"], ["84050.3", "0.072655"], ["84048.1", "0"], ["84038.3", "0"], ["84029.2", "0"], ["83982.5", "0.011992"], ["83982.2", "0.001333"]], "a": [["84062", "0.215329"], ["84073.3", "0"], ["84083.1", "0.011202"], ["84091.4", "0.001333"], ["84092.2", "0.00009"], ["84100.7", "0"], ["84100.9", "0.012845"], ["84110.6", "2.257032"], ["84113.4", "0"], ["84132.8", "0.059399"]], "u": 20704, "seq": 67549989608}, "cts": 1742555354516}}
{"exchange": "BITGET", "timestamp": 1742555354.654422, "message": {"action": "update", "arg": {"instType": "SPOT", "channel": "books", "instId": "BTCUSDT"}, "data": [{"asks": [["84057.10", "0.009990"], ["84060.77", "0"], ["84078.88", "0.185300"], ["84083.52", "0"], ["84106.69", "0.039647"], ["84145.40", "5.075661"], ["84153.90", "5.166297"], ["84162.40", "4.713114"], ["84170.90", "4.531840"], ["84179.40", "4.350566"], ["84187.90", "4.169293"], ["84196.40", "3.897382"], ["84204.90", "5.438208"], ["84213.40", "4.259930"], ["84221.90", "4.894387"], ["84230.40", "5.256934"], ["84238.90", "4.078656"], ["84247.40", "4.441203"], ["84255.90", "5.528845"], ["84264.40", "4.803750"], ["84272.90", "5.347571"], ["84281.40", "4.622477"], ["84289.90", "3.988019"], ["84298.40", "4.985024"], ["84306.90", "5.619481"], ["84520.00", "0"]], "bids": [["84004.46", "0"], ["84000.80", "0.018524"], ["83977.20", "3.897382"], ["83968.70", "5.347571"], ["83951.70", "4.441203"], ["83943.20", "4.169293"], ["83934.70", "5.256934"], ["83926.20", "4.078656"], ["83917.70", "5.528845"], ["83909.20", "4.259930"], ["83900.70", "3.988019"], ["83892.20", "4.531840"], ["83883.70", "5.438208"], ["83875.20", "5.619481"], ["83866.70", "4.803750"], ["83858.20", "4.985024"], ["83849.70", "5.166297"], ["83832.70", "4.894387"], ["83824.20", "5.075661"], ["83815.70", "4.622477"]], "checksum": -411090337, "ts": "1742555354625"}], "ts": 1742555354629}}
{"exchange": "BYBIT", "timestamp": 1742555354.73996, "message": {"topic": "orderbook.200.BTCUSDT", "ts": 1742555354719, "type": "delta", "data": {"s": "BTCUSDT", "b": [["84061.9", "0.090941"], ["84029.3", "0"], ["84023.8", "0.016181"], ["84023.7", "0.012881"], ["84023.6", "0"], ["84023.5", "0"], ["83994.5", "0"], ["83991.3", "0.353746"], ["83981.8", "0.0032"], ["83981.7", "0.001466"], ["83981.5", "0.005942"]], "a": [["84062", "0.2302"], ["84100.2", "0.012845"], ["84100.3", "0.037234"], ["84100.8", "0"], ["84100.9", "0"], ["84101.3", "0.049"], ["84101.4", "0.04"], ["84101.6", "0"], ["84101.7", "0"], ["84107.9", "2.260268"], ["84110.6", "0"], ["84133.1", "0.006786"], ["84133.5", "0.001851"], ["84134.2", "0.000423"]], "u": 20705, "seq": 67549989645}, "cts": 1742555354714}}
{"exchange": "BITGET", "timestamp": 1742555354.861325, "message": {"action": "update", "arg": {"instType": "SPOT", "channel": "books", "instId": "BTCUSDT"}, "data": [{"asks": [["84029.42", "0.000100"], ["84029.99", "0.088149"], ["84030.01", "0"], ["84110.20", "0"], ["84117.30", "2.674740"], ["84145.40", "4.259930"], ["84153.90", "5.075661"], ["84162.40", "4.985024"], ["84170.90", "3.897382"], ["84179.40", "4.713114"], ["84187.90", "4.531840"], ["84196.40", "4.894387"], ["84204.90", "5.347571"], ["84213.40", "5.256934"], ["84221.90", "5.619481"], ["84230.40", "5.438208"], ["84238.90", "5.166297"], ["84247.40", "4.350566"], ["84255.90", "3.988019"], ["84264.40", "4.078656"], ["84272.90", "5.528845"], ["84281.40", "4.169293"], ["84289.90", "4.441203"], ["84298.40", "4.622477"], ["84306.90", "4.803750"]], "bids": [["84029.20", "0.043386"], ["84027.20", "0.113984"], ["84026.34", "0.000019"], ["84025.41", "0"], ["84025.20", "0.299957"], ["84023.20", "0.789360"], ["84021.20", "2.077264"], ["84019.20", "5.466484"], ["84018.80", "0.010350"], ["84010.30", "1.281840"], ["83979.00", "0"], ["83977.20", "5.075661"], ["83968.70", "3.897382"], ["83960.20", "4.259930"], ["83951.70", "4.985024"], ["83943.20", "5.347571"], ["83934.70", "4.169293"], ["83926.20", "4.894387"], ["83917.70", "3.988019"], ["83909.20", "4.713114"], ["83900.70", "4.078656"], ["83892.20", "4.350566"], ["83883.70", "5.166297"], ["83875.20", "5.528845"], ["83866.70", "4.622477"], ["83858.20", "4.803750"], ["83849.70", "5.438208"], ["83841.20", "4.531840"], ["83832.70", "4.441203"], ["83824.20", "5.256934"], ["83815.70", "5.619481"], ["83659.49", "0.000012"]], "checksum": -2076191864, "ts": "1742555354832"}], "ts": 1742555354835}}
{"exchange": "BYBIT", "timestamp": 1742555354.939887, "message": {"topic": "orderbook.200.BTCUSDT", "ts": 1742555354920, "type": "delta", "data": {"s": "BTCUSDT", "b": [], "a": [["84078", "0.036211"], ["84079.9", "0"], ["84101.1", "0.649174"], ["84101.2", "0.234789"], ["84101.3", "0.009"], ["84101.4", "0"], ["84134.3", "0.001466"], ["84136.7", "1.123173"]], "u": 20706, "seq": 67549989658}, "cts": 1742555354915}}
{"exchange": "BITGET", "timestamp": 1742555355.068116, "message": {"action": "update", "arg": {"instType": "SPOT", "channel": "books", "instId": "BTCUSDT"}, "data": [{"asks": [["84059.01", "0.207936"], ["84087.40", "0.003267"], ["84089.40", "0.008596"], ["84091.40", "0.022622"], ["84093.40", "0.059531"], ["84095.40", "0.156661"], ["84097.40", "0.412266"], ["84099.40", "1.084910"], ["84101.40", "2.855027"], ["84103.40", "7.513228"], ["84106.30", "0.107490"], ["84107.60", "0"], ["84110.20", "0.178290"], ["84116.40", "2.735370"], ["84117.20", "0"], ["84117.30", "0"], ["84145.40", "5.256934"], ["84153.90", "4.894387"], ["84162.40", "5.075661"], ["84170.90", "4.713114"], ["84179.40", "3.897382"], ["84187.90", "5.438208"], ["84196.40", "5.166297"], ["84204.90", "5.528845"], ["84213.40", "4.078656"], ["84221.90", "4.169293"], ["84230.40", "4.803750"], ["84238.90", "3.988019"], ["84247.40", "4.622477"], ["84255.90", "4.259930"], ["84264.40", "4.985024"], ["84272.90", "5.347571"], ["84281.40", "4.350566"], ["84298.40", "5.619481"], ["84306.90", "4.531840"], ["84520.00", "0.000854"], ["84520.50", "0.000238"]], "bids": [["84021.20", "2.077158"], ["84019.20", "5.466224"], ["84018.80", "0"], ["84007.80", "0.120000"], ["83977.20", "4.803750"], ["83968.70", "5.528845"], ["83960.20", "5.256934"], ["83951.70", "5.619481"], ["83943.20", "4.169293"], ["83934.70", "3.988019"], ["83926.20", "4.350566"], ["83917.70", "5.166297"], ["83909.20", "4.441203"], ["83900.70", "4.894387"], ["83892.20", "4.078656"], ["83883.70", "5.075661"], ["83875.20", "4.713114"], ["83858.20", "5.347571"], ["83849.70", "4.985024"], ["83841.20", "4.259930"], ["83832.70", "4.531840"], ["83824.20", "3.897382"], ["83815.70", "5.438208"]], "checksum": -2076191864, "ts": "1742555355039"}], "ts": 1742555355042}}
{"exchange": "BYBIT", "timestamp": 1742555355.141182, "message": {"topic": "orderbook.200.BTCUSDT", "ts": 1742555355120, "type": "delta", "data": {"s": "BTCUSDT", "b": [["84061.9", "0.088154"], ["84050.3", "0.099934"], ["84048.1", "0.115064"], ["84044", "0.112513"], ["84037.6", "0.199236"], ["84037", "0.178077"], ["84030.6", "0.286619"], ["84030", "0.297432"], ["84027.5", "0.114186"], ["83982.9", "0"], ["83982.5", "0"], ["83982.2", "0"], ["83981.8", "0"], ["83981.7", "0"], ["83981.5", "0"]], "a": [["84072.6", "0.11762"], ["84076.9", "0.109763"], ["84083.1", "0.183556"], ["84083.9", "0.631837"], ["84090.1", "0.287217"], ["84090.9", "0.281298"], ["84134.2", "0"], ["84134.3", "0"], ["84136.7", "0"]], "u": 20707, "seq": 67549989698}, "cts": 1742555355098}}
{"exchange": "BITGET", "timestamp": 1742555355.29247, "message": {"action": "update", "arg": {"instType": "SPOT", "channel": "books", "instId": "BTCUSDT"}, "data": [{"asks": [["84029.41", "0.967081"], ["84029.99", "0"], ["84084.91", "0.001837"], ["84145.40", "4.894387"], ["84153.90", "5.438208"], ["84162.40", "5.166297"], ["84170.90", "4.622477"], ["84179.40", "4.169293"], ["84187.90", "4.713114"], ["84196.40", "4.259930"], ["84204.90", "4.350566"], ["84213.40", "3.988019"], ["84221.90", "5.075661"], ["84230.40", "4.078656"], ["84238.90", "5.528845"], ["84247.40", "5.619481"], ["84255.90", "3.897382"], ["84264.40", "5.256934"], ["84281.40", "4.985024"], ["84289.90", "4.531840"], ["84298.40", "4.803750"], ["84306.90", "4.441203"]], "bids": [["84019.00", "0.012360"], ["84016.40", "0.009000"], ["84013.30", "0"], ["84007.80", "0"], ["83979.00", "0.000015"], ["83977.20", "5.256934"], ["83977.00", "0.000032"], ["83968.70", "5.438208"], ["83960.20", "4.894387"], ["83951.70", "5.166297"], ["83943.20", "4.713114"], ["83934.70", "4.078656"], ["83926.20", "5.075661"], ["83917.70", "4.169293"], ["83909.20", "5.528845"], ["83900.70", "4.441203"], ["83892.20", "4.622477"], ["83883.70", "3.988019"], ["83875.20", "4.531840"], ["83866.70", "5.619481"], ["83858.20", "4.803750"], ["83849.70", "4.350566"], ["83841.20", "3.897382"], ["83832.70", "5.347571"], ["83824.20", "4.985024"], ["83815.70", "4.259930"]], "checksum": -1116578869, "ts": "1742555355262"}], "ts": 1742555355266}}
{"exchange": "BYBIT", "timestamp": 1742555355.340901, "message": {"topic": "orderbook.200.BTCUSDT", "ts": 1742555355320, "type": "delta", "data": {"s": "BTCUSDT", "b": [["84023.8", "0.016062"]], "a": [["84107.9", "0.003236"], ["84116.2", "2.257032"], ["84133.5", "0"]], "u": 20708, "seq": 67549989711}, "cts": 1742555355285}}
{"exchange": "BITGET", "timestamp": 1742555355.517164, "message": {"action": "update", "arg": {"instType": "SPOT", "channel": "books", "instId": "BTCUSDT"}, "data": [{"asks": [["84029.97", "0.088149"], ["84087.40", "0.003118"], ["84089.40", "0.008206"], ["84091.40", "0.021593"], ["84093.40", "0.056824"], ["84095.40", "0.149538"], ["84097.40", "0.393521"], ["84099.40", "1.035582"], ["84101.40", "2.725216"], ["84103.40", "7.171435"], ["84106.30", "0.034710"], ["84107.40", "0.071520"], ["84109.00", "0"], ["84111.70", "0.161250"], ["84111.80", "0"], ["84117.20", "0.107070"], ["84117.30", "2.674740"], ["84145.40", "5.347571"], ["84153.90", "4.169293"], ["84162.40", "4.803750"], ["84170.90", "5.256934"], ["84179.40", "4.259930"], ["84187.90", "5.528845"], ["84196.40", "4.531840"], ["84204.90", "4.713114"], ["84213.40", "4.441203"], ["84221.90", "4.985024"], ["84230.40", "3.897382"], ["84238.90", "3.988019"], ["84247.40", "5.075661"], ["84255.90", "4.894387"], ["84264.40", "5.166297"], ["84272.90", "4.078656"], ["84281.40", "4.622477"], ["84289.90", "5.438208"], ["84298.40", "4.350566"], ["84306.90", "5.619481"], ["84520.00", "0"], ["84520.50", "0"]], "bids": [["84029.20", "0.043308"], ["84027.20", "0.113967"], ["84025.20", "0.299914"], ["84023.20", "0.789248"], ["84021.20", "2.076967"], ["84019.20", "5.465703"], ["84019.00", "0.006060"], ["84007.80", "0.120000"], ["83968.70", "4.078656"], ["83960.20", "4.169293"], ["83951.70", "4.531840"], ["83943.20", "5.438208"], ["83934.70", "3.897382"], ["83926.20", "4.441203"], ["83917.70", "5.619481"], ["83909.20", "5.347571"], ["83900.70", "4.803750"], ["83892.20", "4.985024"], ["83875.20", "4.350566"], ["83866.70", "5.075661"], ["83858.20", "4.713114"], ["83849.70", "4.259930"], ["83841.20", "4.622477"], ["83832.70", "5.166297"], ["83824.20", "4.894387"], ["83815.70", "5.528845"], ["83659.49", "0"]], "checksum": 808424976, "ts": "1742555355475"}], "ts": 1742555355480}}
{"exchange": "BYBIT", "timestamp": 1742555355.540817, "message": {"topic": "orderbook.200.BTCUSDT", "ts": 1742555355520, "type": "delta", "data": {"s": "BTCUSDT", "b": [["84061.9", "0.265938"], ["84055.2", "0.0039"], ["84050.3", "0.072655"], ["84048.1", "0"], ["84044", "0"], ["84037.6", "0.021653"], ["84037", "0"], ["84031.8", "0.000516"], ["84030.6", "0"], ["84030", "0"], ["84027", "0.022686"], ["84026.5", "0.0061"], ["84022.8", "0"], ["84018.4", "0"], ["83982.9", "0.000333"], ["83982.5", "0.011992"], ["83982.2", "0.001333"], ["83981.8", "0.0032"], ["83981.7", "0.001466"]], "a": [["84062", "0.0592"], ["84072.6", "0.00599"], ["84076.9", "0"], ["84080.6", "0"], ["84083.1", "0.011202"], ["84083.9", "0.459606"], ["84090.1", "0"], ["84090.8", "0.541363"], ["84090.9", "0"], ["84100.2", "0"], ["84100.3", "0.024389"], ["84100.4", "0.012845"], ["84100.5", "0.013178"], ["84101.1", "0.609174"], ["84101.2", "0.194789"], ["84101.3", "0.049"], ["84101.4", "0.04"], ["84107", "0"], ["84111.3", "0.024257"], ["84113.5", "2.257032"], ["84116.2", "0"], ["84133.5", "0.001851"], ["84134.2", "0.000423"], ["84134.3", "0.001466"]], "u": 20709, "seq": 67549989783}, "cts": 1742555355507}}
{"exchange": "BITGET", "timestamp": 1742555355.712414, "message": {"action": "update", "arg": {"instType": "SPOT", "channel": "books", "instId": "BTCUSDT"}, "data": [{"asks": [["84029.41", "0.627081"], ["84085.40", "0.001108"], ["84087.40", "0.002792"], ["84089.40", "0.007346"], ["84091.40", "0.019332"], ["84093.40", "0.050873"], ["84095.40", "0.133878"], ["84097.40", "0.352309"], ["84099.40", "0.927131"], ["84101.40", "2.439817"], ["84103.40", "6.420571"], ["84103.80", "0.960090"], ["84105.00", "0.202830"], ["84107.00", "0.072900"], ["84107.40", "0"], ["84108.10", "0.067980"], ["84110.10", "0.067800"], ["84110.20", "0"], ["84112.20", "0"], ["84115.50", "0.045540"], ["84117.50", "0.070080"], ["84117.60", "0.534660"], ["84145.40", "4.169293"], ["84153.90", "4.078656"], ["84162.40", "4.622477"], ["84179.40", "3.988019"], ["84187.90", "3.897382"], ["84196.40", "4.441203"], ["84204.90", "4.350566"], ["84213.40", "5.528845"], ["84230.40", "4.803750"], ["84238.90", "4.894387"], ["84247.40", "5.619481"], ["84255.90", "4.531840"], ["84272.90", "5.438208"], ["84281.40", "4.713114"], ["84289.90", "5.347571"], ["84298.40", "5.075661"], ["84306.90", "4.259930"], ["84518.98", "0"]], "bids": [["84029.20", "0.070765"], ["84027.20", "0.186224"], ["84025.20", "0.490063"], ["84023.20", "1.289638"], ["84021.20", "3.393785"], ["84019.20", "8.931013"], ["84019.10", "0.435270"], ["84018.70", "0.813930"], ["84017.90", "0.068370"], ["84007.70", "0.120000"], ["83977.20", "4.441203"], ["83968.70", "4.350566"], ["83960.20", "4.713114"], ["83951.70", "5.528845"], ["83934.70", "5.256934"], ["83926.20", "4.078656"], ["83917.70", "5.075661"], ["83909.20", "3.897382"], ["83900.70", "4.985024"], ["83892.20", "5.619481"], ["83883.70", "4.169293"], ["83875.20", "3.988019"], ["83866.70", "4.259930"], ["83858.20", "4.531840"], ["83849.70", "4.894387"], ["83824.20", "4.803750"], ["83815.70", "5.347571"], ["83659.61", "0"]], "checksum": 941873220, "ts": "1742555355678"}], "ts": 1742555355685}}
{"exchange": "BYBIT", "timestamp": 1742555355.740335, "message": {"topic": "orderbook.200.BTCUSDT", "ts": 1742555355720, "type": "delta", "data": {"s": "BTCUSDT", "b": [["84023.8", "0.003181"], ["84023.7", "0"], ["84023.5", "0.012881"], ["84023.4", "0.012881"], ["84019.3", "0.135504"], ["84016.5", "1.940534"], ["84009", "14.237049"], ["84006.2", "0"], ["83981.8", "0"], ["83981.7", "0"]], "a": [["84079.7", "0.231423"], ["84085.5", "0"], ["84090.8", "0.540353"], ["84100.4", "0"], ["84100.5", "0.000333"], ["84101.1", "0.622019"], ["84101.2", "0.207634"], ["84101.3", "0.009"], ["84101.4", "0"], ["84102", "0.04"], ["84102.1", "0.04"], ["84110.7", "2.257032"], ["84113.5", "0"], ["84136.7", "1.123173"]], "u": 20710, "seq": 67549989825}, "cts": 1742555355715}}
{"exchange": "BITGET", "timestamp": 1742555355.912466, "message": {"action": "update", "arg": {"instType": "SPOT", "channel": "books", "instId": "BTCUSDT"}, "data": [{"asks": [["84029.41", "0.627051"], ["84029.95", "0.088149"], ["84029.97", "0"], ["84059.21", "0.119867"], ["84062.45", "0"], ["84108.60", "0.217290"], ["84117.60", "0.609030"], ["84145.40", "5.438208"], ["84153.90", "3.988019"], ["84162.40", "4.169293"], ["84170.90", "4.531840"], ["84179.40", "4.803750"], ["84187.90", "4.622477"], ["84196.40", "5.166297"], ["84204.90", "5.075661"], ["84213.40", "5.347571"], ["84221.90", "4.259930"], ["84230.40", "5.256934"], ["84247.40", "3.897382"], ["84255.90", "5.619481"], ["84264.40", "4.713114"], ["84272.90", "4.985024"], ["84281.40", "4.441203"], ["84289.90", "4.078656"], ["84298.40", "4.350566"], ["84306.90", "5.528845"]], "bids": [["84015.10", "0"], ["84010.90", "0.071370"], ["84007.70", "0"], ["84001.95", "0"], ["83998.71", "0.259901"], ["83977.20", "4.803750"], ["83977.00", "0.000017"], ["83968.70", "5.528845"], ["83960.20", "5.256934"], ["83951.70", "5.075661"], ["83943.20", "4.985024"], ["83934.70", "4.259930"], ["83926.20", "4.531840"], ["83917.70", "4.622477"], ["83909.20", "5.619481"], ["83900.70", "4.078656"], ["83892.20", "5.347571"], ["83883.70", "5.438208"], ["83875.20", "3.897382"], ["83866.70", "4.350566"], ["83858.20", "4.441203"], ["83841.20", "5.166297"], ["83832.70", "4.713114"], ["83824.20", "4.169293"], ["83815.70", "3.988019"], ["83659.61", "0.000454"]], "checksum": 1714081262, "ts": "1742555355884"}], "ts": 1742555355886}}
{"exchange": "BYBIT", "timestamp": 1742555355.939895, "message": {"topic": "orderbook.200.BTCUSDT", "ts": 1742555355919, "type": "delta", "data": {"s": "BTCUSDT", "b": [["84061.9", "0.265269"], ["84047.3", "0.056422"], ["84040.3", "0.057439"], ["84033.3", "0.109834"], ["84023.5", "0"], ["84023.3", "0.014347"], ["83982.2", "0"]], "a": [["84082.3", "0.101291"], ["84089.3", "0.061027"], ["84096.3", "0.122619"], ["84101.1", "0.609174"], ["84101.2", "0.194789"], ["84101.4", "0.012845"], ["84101.5", "0.012845"], ["84102", "0"], ["84102.1", "0"], ["84102.3", "0.04"], ["84102.4", "0.04"], ["84110.7", "0"], ["84134.3", "0"], ["84136.7", "0"]], "u": 20711, "seq": 67549989848}, "cts": 1742555355878}}
{"exchange": "BITGET", "timestamp": 1742555356.130053, "message": {"action": "update", "arg": {"instType": "SPOT", "channel": "books", "instId": "BTCUSDT"}, "data": [{"asks": [["84029.41", "0.967051"], ["84081.74", "0.753854"], ["84087.40", "0.002667"], ["84089.40", "0.007019"], ["84091.40", "0.018472"], ["84093.40", "0.048610"], ["84095.40", "0.127922"], ["84097.40", "0.336636"], ["84099.40", "0.885884"], ["84101.40", "2.331274"], ["84103.40", "6.135136"], ["84103.80", "1.208010"], ["84105.00", "0.203610"], ["84105.30", "0.918660"], ["84106.60", "0.034440"], ["84106.70", "0.056550"], ["84107.00", "0.072720"], ["84107.60", "0.015000"], ["84108.10", "0.067800"], ["84108.60", "0.217110"], ["84117.50", "0"], ["84117.60", "0"], ["84145.40", "4.350566"], ["84153.90", "5.619481"], ["84162.40", "3.897382"], ["84170.90", "4.713114"], ["84179.40", "4.894387"], ["84187.90", "4.441203"], ["84196.40", "5.347571"], ["84204.90", "4.078656"], ["84213.40", "4.985024"], ["84221.90", "4.803750"], ["84230.40", "5.528845"], ["84238.90", "5.256934"], ["84247.40", "5.166297"], ["84255.90", "4.622477"], ["84264.40", "3.988019"], ["84272.90", "4.531840"], ["84281.40", "5.438208"], ["84289.90", "4.169293"], ["84298.40", "4.259930"], ["84306.90", "5.075661"], ["84517.86", "0"]], "bids": [["84018.60", "2.356950"], ["84017.90", "0.068190"], ["84017.60", "0.035040"], ["84016.90", "0"], ["84016.40", "0"], ["84009.80", "0.153580"], ["84007.70", "0.120000"], ["83985.60", "0"], ["83980.30", "0.199851"], ["83978.00", "0"], ["83977.20", "5.528845"], ["83968.70", "5.347571"], ["83960.20", "3.897382"], ["83951.70", "5.256934"], ["83934.70", "5.619481"], ["83926.20", "5.075661"], ["83917.70", "4.259930"], ["83909.20", "4.622477"], ["83900.70", "4.894387"], ["83892.20", "5.166297"], ["83883.70", "4.713114"], ["83875.20", "4.078656"], ["83866.70", "4.803750"], ["83858.20", "4.350566"], ["83849.70", "4.531840"], ["83841.20", "4.441203"], ["83832.70", "4.169293"], ["83824.20", "5.438208"]], "checksum": -1861821494, "ts": "1742555356089"}], "ts": 1742555356094}}
{"exchange": "BYBIT", "timestamp": 1742555356.139119, "message": {"topic": "orderbook.200.BTCUSDT", "ts": 1742555356119, "type": "delta", "data": {"s": "BTCUSDT", "b": [], "a": [["84087.9", "0.004373"], ["84110.7", "2.257032"], ["84134.2", "0"]], "u": 20712, "seq": 67549989856}, "cts": 1742555356002}}
{"exchange": "BITGET", "timestamp": 1742555356.334736, "message": {"action": "update", "arg": {"instType": "SPOT", "channel": "books", "instId": "BTCUSDT"}, "data": [{"asks": [["84106.30", "0.022710"], ["84106.60", "0"], ["84106.70", "0.056730"], ["84107.00", "0.072900"], ["84107.60", "0.030000"], ["84108.10", "0.067980"], ["84108.60", "0.217290"], ["84116.40", "2.723370"], ["84117.50", "0.070080"], ["84117.60", "0.609030"], ["84145.40", "5.347571"], ["84153.90", "4.894387"], ["84162.40", "5.075661"], ["84170.90", "4.622477"], ["84179.40", "4.169293"], ["84187.90", "5.528845"], ["84196.40", "4.441203"], ["84204.90", "5.619481"], ["84213.40", "5.438208"], ["84221.90", "4.259930"], ["84230.40", "4.713114"], ["84238.90", "4.531840"], ["84247.40", "4.803750"], ["84255.90", "5.256934"], ["84264.40", "4.350566"], ["84272.90", "3.988019"], ["84281.40", "4.078656"], ["84289.90", "4.985024"], ["84298.40", "3.897382"], ["84306.90", "5.166297"], ["84517.54", "0"]], "bids": [["84029.20", "0.058698"], ["84027.52", "0.000019"], ["84027.20", "0.154468"], ["84026.34", "0"], ["84025.20", "0.406494"], ["84023.20", "1.069722"], ["84021.20", "2.815057"], ["84019.20", "7.408045"], ["83977.20", "5.256934"], ["83968.70", "5.528845"], ["83960.20", "4.894387"], ["83951.70", "4.713114"], ["83943.20", "3.988019"], ["83934.70", "4.803750"], ["83926.20", "4.259930"], ["83917.70", "5.347571"], ["83909.20", "4.985024"], ["83900.70", "5.438208"], ["83892.20", "4.350566"], ["83883.70", "4.622477"], ["83875.20", "4.169293"], ["83866.70", "5.075661"], ["83858.20", "3.897382"], ["83849.70", "5.166297"], ["83841.20", "4.078656"], ["83832.70", "4.441203"], ["83824.20", "4.531840"], ["83815.70", "5.619481"]], "checksum": -257220881, "ts": "1742555356305"}], "ts": 1742555356308}}
{"exchange": "BYBIT", "timestamp": 1742555356.340717, "message": {"topic": "orderbook.200.BTCUSDT", "ts": 1742555356320, "type": "delta", "data": {"s": "BTCUSDT", "b": [["84036.6", "0.086383"], ["84010.5", "4.571494"], ["83982.5", "0"]], "a": [["84087.9", "0.003433"], ["84094.2", "0.053869"], ["84110.7", "0"], ["84113.5", "2.257032"]], "u": 20713, "seq": 67549989874}, "cts": 1742555356295}}
{"exchange": "BYBIT", "timestamp": 1742555356.541315, "message": {"topic": "orderbook.200.BTCUSDT", "ts": 1742555356520, "type": "delta", "data": {"s": "BTCUSDT", "b": [["84023.6", "0.013"], ["84023.5", "0.012881"], ["84023.4", "0"], ["84023.3", "0.001466"], ["83982.9", "0"]], "a": [["84101", "0.072399"], ["84101.1", "0.622019"], ["84101.4", "0"], ["84101.5", "0"], ["84101.9", "0.041466"], ["84102", "0.04"], ["84102.3", "0"], ["84102.4", "0"], ["84134.2", "0.000423"], ["84134.3", "0.001466"], ["84136.7", "1.123173"]], "u": 20714, "seq": 67549989889}, "cts": 1742555356496}}
{"exchange": "BITGET", "timestamp": 1742555356.549407, "message": {"action": "update", "arg": {"instType": "SPOT", "channel": "books", "instId": "BTCUSDT"}, "data": [{"asks": [["84029.42", "0.000117"], ["84029.93", "0.088149"], ["84029.95", "0"], ["84099.40", "0.886013"], ["84101.40", "2.331613"], ["84103.40", "6.135824"], ["84105.10", "0.025020"], ["84108.60", "0.217110"], ["84145.40", "5.619481"], ["84153.90", "4.259930"], ["84162.40", "5.438208"], ["84170.90", "4.894387"], ["84179.40", "5.256934"], ["84187.90", "4.622477"], ["84196.40", "5.528845"], ["84204.90", "3.897382"], ["84213.40", "4.441203"], ["84221.90", "3.988019"], ["84238.90", "4.985024"], ["84247.40", "5.166297"], ["84255.90", "5.075661"], ["84264.40", "4.531840"], ["84272.90", "4.803750"], ["84281.40", "4.169293"], ["84289.90", "4.350566"], ["84298.40", "4.078656"], ["84306.90", "5.347571"], ["84516.67", "0"]], "bids": [["84029.20", "0.065703"], ["84027.20", "0.172904"], ["84025.20", "0.455009"], ["84023.20", "1.197393"], ["84021.20", "3.151035"], ["84019.20", "8.292196"], ["83979.00", "0.000032"], ["83978.00", "0.000015"], ["83977.20", "5.528845"], ["83968.70", "4.622477"], ["83960.20", "4.259930"], ["83951.70", "5.166297"], ["83943.20", "5.347571"], ["83934.70", "4.713114"], ["83926.20", "3.988019"], ["83917.70", "5.619481"], ["83909.20", "3.897382"], ["83900.70", "5.256934"], ["83892.20", "4.169293"], ["83883.70", "5.438208"], ["83875.20", "4.894387"], ["83858.20", "4.078656"], ["83849.70", "4.803750"], ["83841.20", "4.441203"], ["83832.70", "4.350566"], ["83824.20", "4.985024"], ["83815.70", "4.531840"], ["83659.61", "0"]], "checksum": 1963444797, "ts": "1742555356520"}], "ts": 1742555356523}}
{"exchange": "BYBIT", "timestamp": 1742555356.739778, "message": {"topic": "orderbook.200.BTCUSDT", "ts": 1742555356719, "type": "delta", "data": {"s": "BTCUSDT", "b": [["84033.6", "0.118804"], ["84023.6", "0"], ["84023.5", "0"], ["84023.4", "0.013"], ["84023.3", "0.014347"]], "a": [["84101", "0.059399"], ["84101.1", "0.609174"], ["84101.4", "0.013"], ["84101.5", "0.012845"], ["84101.9", "0.001466"], ["84102", "0"], ["84102.3", "0.04"], ["84102.4", "0.04"], ["84134.2", "0"], ["84134.3", "0"], ["84136.7", "0"]], "u": 20715, "seq": 67549989910}, "cts": 1742555356675}}
{"exchange": "BITGET", "timestamp": 1742555356.752312, "message": {"action": "update", "arg": {"instType": "SPOT", "channel": "books", "instId": "BTCUSDT"}, "data": [{"asks": [["84087.40", "0.002784"], ["84089.40", "0.007325"], ["84091.40", "0.019277"], ["84093.40", "0.050729"], ["84095.40", "0.133498"], ["84097.40", "0.351311"], ["84099.40", "0.924501"], ["84101.40", "2.432897"], ["84103.40", "6.402362"], ["84105.10", "0"], ["84108.60", "0.217290"], ["84145.40", "5.347571"], ["84153.90", "3.897382"], ["84162.40", "4.894387"], ["84170.90", "4.350566"], ["84179.40", "5.619481"], ["84187.90", "4.803750"], ["84196.40", "4.078656"], ["84204.90", "3.988019"], ["84213.40", "4.985024"], ["84221.90", "4.531840"], ["84230.40", "4.259930"], ["84238.90", "5.075661"], ["84247.40", "4.169293"], ["84255.90", "5.528845"], ["84264.40", "4.622477"], ["84272.90", "5.438208"], ["84281.40", "4.713114"], ["84289.90", "5.166297"], ["84298.40", "4.441203"], ["84306.90", "5.256934"], ["84516.67", "0.000010"]], "bids": [["84029.20", "0.065957"], ["84027.20", "0.173571"], ["84025.20", "0.456767"], ["84023.20", "1.202018"], ["84021.20", "3.163206"], ["84019.20", "8.324225"], ["84004.90", "0"], ["83999.60", "0.000396"], ["83975.50", "0"], ["83968.70", "4.441203"], ["83960.20", "5.256934"], ["83951.70", "4.078656"], ["83943.20", "4.350566"], ["83934.70", "3.988019"], ["83926.20", "5.166297"], ["83917.70", "5.347571"], ["83909.20", "5.619481"], ["83900.70", "4.803750"], ["83892.20", "4.531840"], ["83883.70", "4.622477"], ["83875.20", "5.075661"], ["83866.70", "4.713114"], ["83858.20", "4.169293"], ["83849.70", "4.259930"], ["83841.20", "4.985024"], ["83832.70", "4.894387"], ["83824.20", "3.897382"], ["83815.70", "5.438208"], ["83659.61", "0.000454"]], "checksum": -1396130344, "ts": "1742555356721"}], "ts": 1742555356725}}
{"exchange": "BYBIT", "timestamp": 1742555356.939465, "message": {"topic": "orderbook.200.BTCUSDT", "ts": 1742555356919, "type": "delta", "data": {"s": "BTCUSDT", "b": [["84023.4", "0.012881"]], "a": [["84101.4", "0.012845"], ["84102.2", "0.04"], ["84102.4", "0"], ["84113.4", "2.257032"], ["84113.5", "0"]], "u": 20716, "seq": 67549989925}, "cts": 1742555356906}}
{"exchange": "BITGET", "timestamp": 1742555356.954994, "message": {"action": "update", "arg": {"instType": "SPOT", "channel": "books", "instId": "BTCUSDT"}, "data": [{"asks": [["84029.91", "0.088149"], ["84029.93", "0"], ["84088.65", "0.010000"], ["84097.40", "0.351185"], ["84099.40", "0.924171"], ["84101.40", "2.432028"], ["84103.40", "6.400074"], ["84145.40", "5.256934"], ["84153.90", "4.622477"], ["84162.40", "4.350566"], ["84170.90", "4.713114"], ["84179.40", "5.347571"], ["84187.90", "3.897382"], ["84196.40", "4.985024"], ["84204.90", "4.259930"], ["84213.40", "5.075661"], ["84221.90", "5.438208"], ["84230.40", "5.166297"], ["84238.90", "4.441203"], ["84247.40", "5.528845"], ["84255.90", "4.894387"], ["84264.40", "4.169293"], ["84272.90", "5.619481"], ["84281.40", "3.988019"], ["84289.90", "4.078656"], ["84298.40", "4.803750"], ["84306.90", "4.531840"], ["84516.67", "0"]], "bids": [["84029.40", "1.041410"], ["83977.20", "3.988019"], ["83970.20", "0.000948"], ["83968.70", "4.713114"], ["83960.20", "4.985024"], ["83951.70", "4.894387"], ["83943.20", "4.622477"], ["83934.70", "4.259930"], ["83926.20", "5.256934"], ["83917.70", "4.441203"], ["83909.20", "3.897382"], ["83900.70", "4.078656"], ["83892.20", "5.347571"], ["83883.70", "5.528845"], ["83875.20", "5.438208"], ["83866.70", "4.169293"], ["83858.20", "4.803750"], ["83849.70", "5.619481"], ["83841.20", "5.166297"], ["83832.70", "4.350566"], ["83824.20", "5.075661"], ["83815.70", "4.531840"], ["83659.61", "0"]], "checksum": 1557809820, "ts": "1742555356924"}], "ts": 1742555356930}}
{"exchange": "BYBIT", "timestamp": 1742555357.140345, "message": {"topic": "orderbook.200.BTCUSDT", "ts": 1742555357120, "type": "delta", "data": {"s": "BTCUSDT", "b": [["84047.3", "0.05761"], ["84040.3", "0.055017"], ["84033.3", "0.117211"], ["84023.5", "0.013"], ["84023.3", "0.001466"], ["83983.2", "0"]], "a": [["84082.3", "0.099016"], ["84089.3", "0.061082"], ["84096.3", "0.114204"], ["84101.1", "0.622174"], ["84101.2", "0.207634"], ["84101.4", "0"], ["84101.5", "0"], ["84102", "0.04"], ["84102.1", "0.04"], ["84102.2", "0"], ["84102.3", "0"], ["84113.4", "0"], ["84113.5", "2.257032"], ["84134.2", "0.000423"], ["84134.3", "0.001466"]], "u": 20717, "seq": 67549989956}, "cts": 1742555357045}}
{"exchange": "BITGET", "timestamp": 1742555357.15802, "message": {"action": "update", "arg": {"instType": "SPOT", "channel": "books", "instId": "BTCUSDT"}, "data": [{"asks": [["84075.66", "0.110505"], ["84101.40", "2.432141"], ["84103.40", "6.400372"], ["84105.20", "0.025440"], ["84106.69", "0"], ["84108.60", "0.217110"], ["84145.40", "3.897382"], ["84153.90", "4.894387"], ["84162.40", "4.713114"], ["84170.90", "4.985024"], ["84179.40", "4.622477"], ["84187.90", "4.078656"], ["84196.40", "4.259930"], ["84204.90", "5.166297"], ["84213.40", "4.350566"], ["84221.90", "4.531840"], ["84230.40", "5.619481"], ["84238.90", "5.075661"], ["84247.40", "5.438208"], ["84255.90", "4.169293"], ["84264.40", "5.528845"], ["84272.90", "5.347571"], ["84281.40", "4.441203"], ["84289.90", "3.988019"], ["84298.40", "5.256934"], ["84306.90", "4.803750"]], "bids": [["84007.82", "0"], ["84005.86", "0.004019"], ["83977.20", "4.259930"], ["83976.33", "0"], ["83973.61", "0.003598"], ["83968.70", "4.078656"], ["83960.20", "5.166297"], ["83951.70", "3.897382"], ["83943.20", "5.256934"], ["83934.70", "4.985024"], ["83926.20", "5.347571"], ["83917.70", "4.531840"], ["83909.20", "5.075661"], ["83900.70", "4.350566"], ["83892.20", "5.438208"], ["83883.70", "5.619481"], ["83875.20", "5.528845"], ["83866.70", "4.894387"], ["83858.20", "3.988019"], ["83849.70", "4.803750"], ["83841.20", "4.622477"], ["83832.70", "4.441203"], ["83824.20", "4.713114"], ["83815.70", "4.169293"]], "checksum": 1557809820, "ts": "1742555357126"}], "ts": 1742555357129}}
{"exchange": "BYBIT", "timestamp": 1742555357.344677, "message": {"topic": "orderbook.200.BTCUSDT", "ts": 1742555357320, "type": "delta", "data": {"s": "BTCUSDT", "b": [["84022.8", "0.041082"], ["83984", "0"]], "a": [["84113.4", "2.257032"], ["84113.5", "0"]], "u": 20718, "seq": 67549989965}, "cts": 1742555357277}}
{"exchange": "BITGET", "timestamp": 1742555357.373521, "message": {"action": "update", "arg": {"instType": "SPOT", "channel": "books", "instId": "BTCUSDT"}, "data": [{"asks": [["84029.42", "0.000100"], ["84103.40", "6.400186"], ["84105.20", "0"], ["84108.60", "0.217290"], ["84145.40", "4.713114"], ["84153.90", "5.438208"], ["84162.40", "5.528845"], ["84170.90", "4.078656"], ["84179.40", "4.894387"], ["84187.90", "4.259930"], ["84196.40", "5.166297"], ["84204.90", "3.988019"], ["84213.40", "4.531840"], ["84221.90", "5.075661"], ["84230.40", "5.347571"], ["84238.90", "4.622477"], ["84247.40", "5.619481"], ["84255.90", "4.441203"], ["84264.40", "4.350566"], ["84272.90", "4.985024"], ["84281.40", "4.803750"], ["84289.90", "5.256934"], ["84298.40", "4.169293"], ["84306.90", "3.897382"], ["84516.67", "0.000010"]], "bids": [["84029.20", "0.065222"], ["84027.20", "0.171636"], ["84025.20", "0.451674"], ["84023.20", "1.188616"], ["84021.20", "3.127937"], ["84019.20", "8.231411"], ["83977.20", "4.350566"], ["83977.00", "0"], ["83960.20", "5.347571"], ["83951.70", "3.988019"], ["83943.20", "4.531840"], ["83934.70", "3.897382"], ["83926.20", "5.256934"], ["83917.70", "4.985024"], ["83900.70", "4.441203"], ["83875.20", "4.713114"], ["83858.20", "4.169293"], ["83849.70", "5.166297"], ["83841.20", "4.259930"], ["83832.70", "4.622477"], ["83824.20", "5.528845"], ["83815.70", "4.803750"], ["83659.61", "0.000454"]], "checksum": -1216793052, "ts": "1742555357330"}], "ts": 1742555357334}}
{"exchange": "BYBIT", "timestamp": 1742555357.540443, "message": {"topic": "orderbook.200.BTCUSDT", "ts": 1742555357519, "type": "delta", "data": {"s": "BTCUSDT", "b": [["84061.9", "0.265639"], ["84057.8", "0.001333"], ["84047.3", "0"], ["84040.3", "0"], ["84033.3", "0.000333"], ["83984", "0.04"]], "a": [["84062", "0.058438"], ["84082.3", "0.04"], ["84089.3", "0"], ["84096.3", "0.000333"], ["84136.7", "1.123173"]], "u": 20719, "seq": 67549989978}, "cts": 1742555357511}}
{"exchange": "BITGET", "timestamp": 1742555357.576043, "message": {"action": "update", "arg": {"instType": "SPOT", "channel": "books", "instId": "BTCUSDT"}, "data": [{"asks": [["84029.89", "0.088149"], ["84029.91", "0"], ["84145.40", "4.985024"], ["84153.90", "4.441203"], ["84162.40", "5.075661"], ["84170.90", "4.169293"], ["84179.40", "3.897382"], ["84187.90", "5.438208"], ["84196.40", "4.713114"], ["84204.90", "4.350566"], ["84213.40", "4.622477"], ["84221.90", "5.619481"], ["84230.40", "4.894387"], ["84238.90", "5.528845"], ["84247.40", "4.803750"], ["84255.90", "4.531840"], ["84264.40", "3.988019"], ["84272.90", "4.078656"], ["84281.40", "4.259930"], ["84289.90", "5.347571"], ["84298.40", "5.256934"], ["84306.90", "5.166297"]], "bids": [["83979.00", "0.000017"], ["83977.20", "5.256934"], ["83968.70", "3.897382"], ["83960.20", "4.985024"], ["83951.70", "4.622477"], ["83943.20", "4.713114"], ["83934.70", "5.166297"], ["83926.20", "5.438208"], ["83917.70", "4.078656"], ["83909.20", "4.350566"], ["83900.70", "4.803750"], ["83892.20", "4.894387"], ["83883.70", "4.259930"], ["83875.20", "4.441203"], ["83866.70", "5.075661"], ["83858.20", "4.531840"], ["83849.70", "3.988019"], ["83841.20", "5.528845"], ["83832.70", "4.169293"], ["83824.20", "5.347571"], ["83815.70", "5.619481"]], "checksum": 140442302, "ts": "1742555357537"}], "ts": 1742555357541}}
{"exchange": "BYBIT", "timestamp": 1742555357.739261, "message": {"topic": "orderbook.200.BTCUSDT", "ts": 1742555357719, "type": "delta", "data": {"s": "BTCUSDT", "b": [], "a": [["84094.2", "0.019638"]], "u": 20720, "seq": 67549989988}, "cts": 1742555357677}}
{"exchange": "BITGET", "timestamp": 1742555357.769845, "message": {"action": "update", "arg": {"instType": "SPOT", "channel": "books", "instId": "BTCUSDT"}, "data": [{"asks": [["84087.40", "0.002931"], ["84089.40", "0.007713"], ["84091.40", "0.020299"], ["84093.40", "0.053419"], ["84095.40", "0.140576"], ["84097.40", "0.369935"], ["84099.40", "0.973515"], ["84101.40", "2.561882"], ["84103.40", "6.741793"], ["84145.40", "4.894387"], ["84153.90", "4.169293"], ["84162.40", "3.988019"], ["84170.90", "3.897382"], ["84179.40", "4.259930"], ["84187.90", "4.622477"], ["84196.40", "5.528845"], ["84213.40", "4.531840"], ["84221.90", "5.438208"], ["84230.40", "5.075661"], ["84238.90", "5.166297"], ["84255.90", "4.078656"], ["84264.40", "4.985024"], ["84272.90", "5.619481"], ["84281.40", "4.713114"], ["84298.40", "4.441203"], ["84306.90", "5.256934"]], "bids": [["84019.20", "8.231356"], ["83977.20", "5.075661"], ["83968.70", "4.441203"], ["83960.20", "5.438208"], ["83951.70", "4.531840"], ["83943.20", "3.988019"], ["83934.70", "4.894387"], ["83926.20", "3.897382"], ["83917.70", "4.803750"], ["83915.80", "0"], ["83912.77", "0.125658"], ["83909.20", "5.256934"], ["83900.70", "5.528845"], ["83892.20", "4.985024"], ["83883.70", "5.619481"], ["83875.20", "4.169293"], ["83866.70", "4.713114"], ["83858.20", "4.350566"], ["83849.70", "4.078656"], ["83841.20", "5.347571"], ["83832.70", "5.166297"], ["83824.20", "4.259930"], ["83815.70", "4.622477"]], "checksum": 140442302, "ts": "1742555357742"}], "ts": 1742555357744}}
{"exchange": "BYBIT", "timestamp": 1742555357.939433, "message": {"topic": "orderbook.200.BTCUSDT", "ts": 1742555357919, "type": "delta", "data": {"s": "BTCUSDT", "b": [["84061.9", "0.405954"], ["84057.3", "0.084029"], ["84057.2", "0.089099"], ["84055", "0"], ["84054.9", "0.000516"], ["84045.8", "0"], ["84044.1", "0.260099"], ["84043.4", "0.0885"], ["84032.7", "0.024855"], ["84030.1", "0.241751"], ["84027", "0"], ["84023.5", "0"], ["84023.4", "0"], ["84022.9", "0.013"], ["84022.8", "0.053963"], ["84011.8", "14.109492"], ["84009", "0"], ["83985.3", "0"]], "a": [["84062", "0.036157"], ["84067.5", "0"], ["84072.3", "0"], ["84072.4", "0.101127"], ["84072.6", "0"], ["84074.8", "0"], ["84079.7", "0.112619"], ["84089.3", "0.11896"], ["84101.1", "0.609174"], ["84101.2", "0.194789"], ["84102", "0"], ["84102.1", "0"], ["84103.9", "0.012847"], ["84104", "0.01418"], ["84104.8", "0.158804"], ["84104.9", "0.04"], ["84111.3", "0"], ["84113.4", "0"], ["84116.9", "0.142639"], ["84119.2", "2.257032"], ["84136.7", "0"], ["84137.1", "0.4"], ["84137.2", "0.029723"], ["84137.3", "0.003211"], ["84137.4", "0.013073"], ["84137.7", "0.001333"]], "u": 20721, "seq": 67549990088}, "cts": 1742555357917}}
{"exchange": "BITGET", "timestamp": 1742555357.986249, "message": {"action": "update", "arg": {"instType": "SPOT", "channel": "books", "instId": "BTCUSDT"}, "data": [{"asks": [["84029.41", "0.403561"], ["84029.89", "0"], ["84037.78", "0.000221"], ["84037.79", "0"], ["84037.81", "0"], ["84037.82", "0"], ["84041.66", "0"], ["84042.02", "0"], ["84071.07", "0"], ["84087.40", "0.001019"], ["84089.40", "0.001043"], ["84091.40", "0.001546"], ["84093.40", "0.004069"], ["84095.40", "0.010708"], ["84097.40", "0.028180"], ["84099.40", "0.074156"], ["84101.40", "0.195147"], ["84103.40", "0.513546"], ["84103.80", "0.006330"], ["84104.20", "0.001980"], ["84105.00", "0.001008"], ["84105.10", "0.001028"], ["84105.30", "0"], ["84108.60", "0.046920"], ["84110.20", "0.244440"], ["84110.50", "0.464880"], ["84111.30", "0"], ["84117.50", "0"], ["84117.60", "0"], ["84162.40", "4.531840"], ["84170.90", "4.078656"], ["84179.40", "5.438208"], ["84187.90", "4.713114"], ["84204.90", "5.619481"], ["84213.40", "3.988019"], ["84221.90", "4.985024"], ["84230.40", "3.897382"], ["84238.90", "4.803750"], ["84247.40", "4.350566"], ["84255.90", "5.256934"], ["84264.40", "5.075661"], ["84272.90", "4.622477"], ["84281.40", "5.347571"], ["84289.90", "5.166297"], ["84306.90", "4.259930"], ["84517.54", "0.000022"], ["84517.86", "0.000016"], ["84518.98", "0.000029"], ["84520.00", "0.000854"], ["84520.50", "0.000238"], ["84520.67", "0.002384"], ["84521.85", "0.000033"]], "bids": [["84029.40", "1.068863"], ["84029.20", "0.077292"], ["84027.52", "0"], ["84027.20", "0.203400"], ["84025.20", "0.535263"], ["84023.20", "1.408586"], ["84021.20", "3.706806"], ["84020.84", "0"], ["84019.20", "9.754751"], ["84019.10", "0.778590"], ["84010.30", "1.846380"], ["84007.90", "3.614520"], ["84007.70", "0"], ["83978.00", "0.000032"], ["83968.70", "5.256934"], ["83960.20", "4.350566"], ["83951.70", "4.894387"], ["83943.20", "5.347571"], ["83934.70", "4.259930"], ["83926.20", "5.619481"], ["83917.70", "5.166297"], ["83909.20", "5.438208"], ["83900.70", "3.897382"], ["83892.20", "4.169293"], ["83883.70", "4.985024"], ["83875.20", "4.713114"], ["83866.70", "4.078656"], ["83858.20", "4.622477"], ["83849.70", "5.528845"], ["83841.20", "4.441203"], ["83832.70", "3.988019"], ["83824.20", "4.531840"], ["83815.70", "4.803750"], ["83659.49", "0.000012"], ["83659.44", "0.000613"], ["83658.54", "0.000036"]], "checksum": 1732985330, "ts": "1742555357943"}], "ts": 1742555357946}}
{"exchange": "BYBIT", "timestamp": 1742555358.140107, "message": {"topic": "orderbook.200.BTCUSDT", "ts": 1742555358120, "type": "delta", "data": {"s": "BTCUSDT", "b": [["84063.4", "0.077636"], ["84062.6", "0.328563"], ["84061.9", "0.313923"], ["84058.5", "0.000333"], ["84057.6", "0.0025"], ["84057.4", "0.003896"], ["84056.9", "0.009194"], ["84054.7", "0"], ["84054.2", "0.01"], ["84054", "0.047174"], ["84053.9", "0"], ["84053.6", "0.001423"], ["84053.5", "0.005"], ["84051.8", "0"], ["84050.5", "0"], ["84047.2", "0"], ["84046.1", "0.200347"], ["84045.2", "0.001423"], ["84044.7", "0"], ["84038", "0.003576"], ["84030.2", "0.000083"], ["84011.8", "0"], ["84010.5", "0.327005"], ["84009", "14.109492"], ["83984.4", "0"], ["83984", "0"]], "a": [["84062", "0"], ["84062.1", "0"], ["84062.7", "0"], ["84063.5", "0.000814"], ["84067", "0"], ["84067.7", "0.0025"], ["84070.4", "0.006333"], ["84071.1", "0.010333"], ["84072.3", "0.059399"], ["84072.5", "0"], ["84074.2", "0.001466"], ["84076.2", "0.0006"], ["84076.9", "0.067371"], ["84078", "0.000516"], ["84084", "0.052043"], ["84086", "0"], ["84092.6", "0.03725"], ["84099.6", "0"], ["84103.9", "0"], ["84104", "0.001333"], ["84104.8", "0.118804"], ["84104.9", "0"], ["84105.8", "0.013"], ["84105.9", "0.012847"], ["84106.7", "0.04"], ["84106.8", "0.04"], ["84119.2", "0"], ["84122", "2.257032"], ["84137.8", "0.04"]], "u": 20722, "seq": 67549990288}, "cts": 1742555358117}}
{"exchange": "BITGET", "timestamp": 1742555358.181207, "message": {"action": "update", "arg": {"instType": "SPOT", "channel": "books", "instId": "BTCUSDT"}, "data": [{"asks": [["84029.41", "0.351984"], ["84036.93", "0.054744"], ["84084.91", "0.001117"], ["84091.40", "0.001041"], ["84093.40", "0.001661"], ["84095.40", "0.004370"], ["84097.40", "0.011500"], ["84099.40", "0.030025"], ["84101.40", "0.079013"], ["84103.40", "0.207929"], ["84105.00", "0"], ["84106.10", "0"], ["84106.30", "0.023130"], ["84108.10", "0.067800"], ["84108.60", "0"], ["84110.20", "0.989550"], ["84110.30", "2.356350"], ["84112.20", "0.066240"], ["84112.60", "0"], ["84115.50", "0"], ["84116.00", "0"], ["84117.50", "0.070080"], ["84117.60", "0.534660"], ["84145.40", "4.259930"], ["84153.90", "3.897382"], ["84162.40", "4.894387"], ["84170.90", "4.622477"], ["84179.40", "4.985024"], ["84187.90", "4.078656"], ["84196.40", "5.256934"], ["84204.90", "5.166297"], ["84213.40", "5.075661"], ["84221.90", "5.619481"], ["84230.40", "5.528845"], ["84238.90", "4.441203"], ["84255.90", "4.713114"], ["84264.40", "5.347571"], ["84272.90", "4.169293"], ["84281.40", "4.531840"], ["84289.90", "4.803750"], ["84298.40", "3.988019"], ["84306.90", "5.438208"], ["84522.06", "0.000041"]], "bids": [["84029.40", "1.092665"], ["84029.20", "0.080684"], ["84028.21", "0.206532"], ["84027.20", "0.212326"], ["84025.20", "0.558753"], ["84023.20", "1.470403"], ["84021.20", "3.869483"], ["84019.20", "10.182849"], ["84018.70", "1.275540"], ["84018.10", "0"], ["84017.90", "0.496800"], ["84017.80", "0"], ["84017.70", "0.269940"], ["84017.60", "0.463470"], ["84017.50", "0"], ["84017.40", "0.017820"], ["84017.30", "0.035670"], ["84017.20", "0"], ["84016.80", "0.071370"], ["84016.50", "0.178440"], ["84015.90", "0.157020"], ["84015.80", "0.484230"], ["84014.20", "2.522640"], ["84013.80", "0.468900"], ["84013.60", "0"], ["84013.40", "0"], ["84013.30", "0.178440"], ["84013.20", "0.374700"], ["84012.60", "0.178440"], ["84011.70", "0.285480"], ["84011.60", "0.287580"], ["84011.30", "0.017820"], ["84011.00", "0.356880"], ["84010.80", "0"], ["84010.30", "0"], ["84009.90", "0"], ["84009.50", "0"], ["84009.40", "0"], ["84008.70", "0"], ["84007.90", "0"], ["84007.80", "0"], ["83977.20", "5.528845"], ["83977.00", "0.000015"], ["83968.70", "5.347571"], ["83960.20", "4.985024"], ["83943.20", "4.803750"], ["83934.70", "5.256934"], ["83926.20", "4.169293"], ["83917.70", "4.350566"], ["83909.20", "4.078656"], ["83900.70", "5.075661"], ["83892.20", "4.622477"], ["83883.70", "4.441203"], ["83875.20", "3.988019"], ["83866.70", "4.531840"], ["83858.20", "3.897382"], ["83849.70", "5.619481"], ["83841.20", "4.713114"], ["83832.70", "5.438208"], ["83824.20", "4.259930"], ["83815.70", "5.166297"], ["83656.60", "0.000607"]], "checksum": 678969545, "ts": "1742555358151"}], "ts": 1742555358154}}
{"exchange": "BYBIT", "timestamp": 1742555358.340005, "message": {"topic": "orderbook.200.BTCUSDT", "ts": 1742555358319, "type": "delta", "data": {"s": "BTCUSDT", "b": [["84064", "0.149676"], ["84063.4", "0.52102"], ["84062.6", "0.171"], ["84061.9", "0.142923"], ["84058.4", "0.0025"], ["84057.6", "0"], ["84055.3", "0.04"], ["84054.2", "0.015"], ["84054", "0.023883"], ["84053.5", "0"], ["84051", "0.001466"], ["84020.3", "0.234343"], ["84017.5", "14.109492"], ["84010.5", "4.533227"], ["84009", "0"], ["83984.6", "0"]], "a": [["84063.5", "0"], ["84067.6", "0"], ["84067.7", "0"], ["84068.5", "0.0025"], ["84070.4", "0.001333"], ["84071.1", "0.005333"], ["84071.4", "0"], ["84071.7", "0"], ["84071.8", "0"], ["84071.9", "0.01"], ["84072.2", "0.000297"], ["84072.4", "0"], ["84074.9", "0.000297"], ["84080.4", "0"], ["84086.7", "0"], ["84088.3", "0.000099"], ["84091.2", "0.178437"], ["84092.5", "0.031253"], ["84094.2", "0"], ["84095.4", "0.178437"], ["84097.4", "0.057349"], ["84103.1", "0"], ["84105.8", "0"], ["84105.9", "0"], ["84106.3", "0.366266"], ["84106.4", "0.101946"], ["84106.7", "0"], ["84106.8", "0.063432"], ["84107.2", "0.04"], ["84107.3", "0.04"], ["84119.1", "2.257083"], ["84122", "0"], ["84137.9", "0.044"], ["84138.1", "0.000518"], ["84138.4", "0.000333"], ["84138.9", "0.001466"]], "u": 20723, "seq": 67549990471}, "cts": 1742555358317}}
{"exchange": "BITGET", "timestamp": 1742555358.398039, "message": {"action": "update", "arg": {"instType": "SPOT", "channel": "books", "instId": "BTCUSDT"}, "data": [{"asks": [["84036.93", "0"], ["84037.55", "0.054744"], ["84049.67", "0.000181"], ["84083.40", "0"], ["84085.40", "0"], ["84086.70", "0.001018"], ["84087.40", "0"], ["84088.70", "0.001049"], ["84089.40", "0"], ["84090.70", "0.001038"], ["84091.40", "0"], ["84092.70", "0.001009"], ["84093.40", "0"], ["84094.70", "0.001007"], ["84095.40", "0"], ["84096.70", "0.001045"], ["84097.40", "0"], ["84098.70", "0.001030"], ["84099.40", "0"], ["84100.70", "0.001957"], ["84101.40", "0"], ["84102.70", "0.005152"], ["84103.40", "0"], ["84103.80", "0"], ["84104.20", "0"], ["84104.40", "0"], ["84104.70", "0.013556"], ["84105.10", "0"], ["84106.30", "0"], ["84106.70", "0.035675"], ["84107.00", "0"], ["84107.60", "0.015810"], ["84108.10", "0"], ["84109.80", "0.095910"], ["84110.10", "0.067980"], ["84110.20", "0"], ["84110.30", "0"], ["84110.50", "0"], ["84111.10", "0.466530"], ["84111.70", "0"], ["84111.90", "1.740990"], ["84112.10", "0.067980"], ["84112.20", "0.153840"], ["84114.30", "0.066240"], ["84114.70", "2.356230"], ["84114.90", "0.464880"], ["84115.80", "0.092700"], ["84116.90", "0"], ["84117.20", "0"], ["84117.50", "0"], ["84117.60", "0.609030"], ["84117.90", "1.322640"], ["84118.20", "0.424170"], ["84118.40", "0.057330"], ["84118.50", "0.320250"], ["84119.10", "0.120000"], ["84119.20", "2.674740"], ["84145.40", "0"], ["84148.70", "4.622297"], ["84153.90", "0"], ["84157.20", "4.803563"], ["84162.40", "0"], ["84165.70", "5.075463"], ["84170.90", "0"], ["84174.20", "4.712930"], ["84179.40", "0"], ["84182.70", "5.619263"], ["84187.90", "0"], ["84191.20", "5.347363"], ["84196.40", "0"], ["84199.70", "3.897231"], ["84204.90", "0"], ["84208.20", "5.166096"], ["84213.40", "0"], ["84216.70", "4.078497"], ["84221.90", "0"], ["84225.20", "4.259764"], ["84230.40", "0"], ["84233.70", "5.256730"], ["84238.90", "0"], ["84242.20", "3.987864"], ["84247.40", "0"], ["84250.70", "4.984830"], ["84255.90", "0"], ["84259.20", "4.894197"], ["84264.40", "0"], ["84267.70", "4.531664"], ["84272.90", "0"], ["84276.20", "4.441030"], ["84281.40", "0"], ["84284.70", "5.528630"], ["84289.90", "0"], ["84293.20", "5.437996"], ["84298.40", "0"], ["84301.70", "4.350397"], ["84306.90", "0"], ["84310.20", "4.169131"], ["84523.08", "0.000015"], ["84523.48", "0.000015"], ["84523.81", "0.000024"]], "bids": [["84029.40", "1.100792"], ["84029.20", "0"], ["84028.50", "0.512845"], ["84027.20", "0"], ["84026.50", "1.349592"], ["84025.20", "0.008901"], ["84024.50", "3.551557"], ["84023.20", "0.314143"], ["84022.50", "9.346202"], ["84022.20", "0.001002"], ["84022.10", "21.491010"], ["84021.90", "0.068190"], ["84021.20", "0"], ["84019.90", "0.067980"], ["84019.30", "0.120180"], ["84019.20", "2.403660"], ["84019.10", "0.800130"], ["84018.70", "0.813720"], ["84018.60", "0.070020"], ["84018.50", "0.120000"], ["84017.90", "0.496230"], ["84017.70", "0.269760"], ["84017.60", "0.548250"], ["84017.30", "0"], ["84016.20", "0"], ["84015.60", "0"], ["84015.10", "0.120000"], ["84014.30", "0.120000"], ["84014.20", "0.988950"], ["84013.40", "0.240000"], ["84012.90", "0"], ["84012.50", "0"], ["84012.40", "0.453720"], ["84012.00", "0.000032"], ["84011.70", "0"], ["84011.60", "0"], ["84011.40", "0"], ["84011.30", "0"], ["84011.00", "0.000032"], ["84010.90", "0"], ["83980.50", "3.987864"], ["83977.20", "0"], ["83972.00", "3.897231"], ["83968.70", "0"], ["83963.50", "4.712930"], ["83960.20", "0"], ["83955.00", "5.347363"], ["83951.70", "0"], ["83946.50", "4.441030"], ["83943.20", "0"], ["83938.00", "4.984830"], ["83934.70", "0"], ["83929.50", "4.078497"], ["83926.20", "0"], ["83921.00", "4.169131"], ["83917.70", "0"], ["83912.50", "4.259764"], ["83909.20", "0"], ["83904.00", "5.166096"], ["83900.70", "0"], ["83895.50", "5.619263"], ["83892.20", "0"], ["83887.00", "4.622297"], ["83883.70", "0"], ["83878.50", "5.256730"], ["83875.20", "0"], ["83870.00", "4.894197"], ["83866.70", "0"], ["83861.50", "5.528630"], ["83858.20", "0"], ["83853.00", "5.075463"], ["83849.70", "0"], ["83844.50", "5.437996"], ["83841.20", "0"], ["83836.00", "4.350397"], ["83832.70", "0"], ["83827.50", "4.531664"], ["83824.20", "0"], ["83819.00", "4.803563"], ["83815.70", "0"]], "checksum": -65472891, "ts": "1742555358351"}], "ts": 1742555358355}}
{"exchange": "BYBIT", "timestamp": 1742555358.540444, "message": {"topic": "orderbook.200.BTCUSDT", "ts": 1742555358520, "type": "delta", "data": {"s": "BTCUSDT", "b": [["84064", "0.425913"], ["84063.5", "0.152508"], ["84063.4", "0.361358"], ["84063.1", "0.000531"], ["84062.6", "0"], ["84059", "0.0025"], ["84058.4", "0"], ["84057.3", "0.119229"], ["84056.5", "0.116036"], ["84056.2", "0.116126"], ["84055.4", "0.048"], ["84054", "0"], ["84053.8", "0.064683"], ["84053.7", "0.056"], ["84053.6", "0.041423"], ["84052.4", "0.120389"], ["84052.1", "0.04"], ["84049.4", "0.001569"], ["84048.5", "0.04"], ["84047.7", "0.04"], ["84046.4", "0.188565"], ["84046", "0.254361"], ["84045.4", "0.174699"], ["84044.7", "0.006006"], ["84044.3", "0"], ["84039", "0.295603"], ["84038.4", "0.350241"], ["84037.3", "0.280107"], ["84010.5", "0.327005"], ["83990.2", "0"], ["83989.4", "0"], ["83988.2", "0"], ["83987.3", "0"], ["83987.2", "0"], ["83987.1", "0"], ["83986.6", "0"], ["83986.4", "0"], ["83986.3", "0"], ["83986", "0"], ["83985.6", "0"]], "a": [["84064.1", "0.009489"], ["84068.5", "0"], ["84069.1", "0.0025"], ["84071.1", "0.000333"], ["84071.9", "0.005"], ["84072.5", "0.01"], ["84074.1", "0.000153"], ["84075.7", "0.006026"], ["84081", "0.120075"], ["84081.4", "0.123908"], ["84085.3", "0.10919"], ["84088.3", "0"], ["84091.2", "0.165035"], ["84091.5", "0.185407"], ["84092.3", "0.181943"], ["84098.5", "0.328617"], ["84099.3", "0.294665"], ["84099.6", "0.178435"], ["84100.3", "0.333067"], ["84101.1", "0.09207"], ["84106.3", "0.353419"], ["84106.4", "0.089099"], ["84106.6", "0.012847"], ["84106.7", "0.012847"], ["84107.2", "0"], ["84107.3", "0"], ["84107.5", "0.04"], ["84107.6", "0.04"], ["84134.3", "0"], ["84137.1", "0"], ["84137.2", "0"], ["84137.3", "0"], ["84137.4", "0"], ["84137.7", "0"], ["84137.8", "0"], ["84137.9", "0"], ["84138.1", "0"], ["84138.4", "0"], ["84138.9", "0"]], "u": 20724, "seq": 67549990610}, "cts": 1742555358515}}
{"exchange": "BITGET", "timestamp": 1742555358.619866, "message": {"action": "update", "arg": {"instType": "SPOT", "channel": "books", "instId": "BTCUSDT"}, "data": [{"asks": [["84033.04", "0.088146"], ["84084.91", "0"], ["84100.70", "0.002110"], ["84102.70", "0.005310"], ["84104.70", "0.013974"], ["84106.70", "0.036772"], ["84111.90", "2.340360"], ["84112.10", "0.067800"], ["84112.20", "0"], ["84113.00", "2.356260"], ["84114.30", "0.150120"], ["84114.70", "0"], ["84115.80", "0.090000"], ["84117.90", "1.073520"], ["84118.40", "0.058050"], ["84148.70", "5.347363"], ["84157.20", "4.441030"], ["84165.70", "4.622297"], ["84174.20", "4.350397"], ["84191.20", "4.712930"], ["84199.70", "5.528630"], ["84208.20", "4.984830"], ["84216.70", "5.075463"], ["84225.20", "4.169131"], ["84233.70", "5.437996"], ["84242.20", "4.531664"], ["84243.88", "0"], ["84250.70", "3.987864"], ["84259.20", "5.256730"], ["84267.70", "5.166096"], ["84276.20", "4.078497"], ["84284.70", "4.894197"], ["84293.20", "4.803563"], ["84301.70", "3.897231"], ["84310.20", "4.259764"], ["84524.00", "0.000035"], ["84524.83", "0.000009"]], "bids": [["84028.51", "0.603234"], ["84028.50", "0.448041"], ["84028.21", "0"], ["84026.50", "1.179296"], ["84024.50", "3.103411"], ["84023.49", "0.174386"], ["84022.50", "8.166869"], ["84022.10", "15.016710"], ["84021.90", "0.067980"], ["84019.20", "2.403450"], ["84017.60", "0.788250"], ["84014.20", "0.996240"], ["84013.40", "0.360000"], ["84012.40", "0"], ["83980.50", "4.169131"], ["83979.00", "0"], ["83972.00", "4.350397"], ["83963.50", "5.256730"], ["83955.00", "3.897231"], ["83946.50", "5.075463"], ["83938.00", "4.441030"], ["83929.50", "4.894197"], ["83921.00", "5.166096"], ["83904.00", "4.622297"], ["83895.50", "4.712930"], ["83887.00", "4.531664"], ["83878.50", "5.619263"], ["83870.00", "5.347363"], ["83861.50", "3.987864"], ["83853.00", "5.528630"], ["83844.50", "4.078497"], ["83836.00", "4.803563"], ["83827.50", "5.437996"], ["83819.00", "4.984830"], ["83655.00", "0.000926"], ["83654.23", "0.000009"], ["83653.94", "0.000133"]], "checksum": -1105813772, "ts": "1742555358569"}], "ts": 1742555358572}}
{"exchange": "BYBIT", "timestamp": 1742555358.742007, "message": {"topic": "orderbook.200.BTCUSDT", "ts": 1742555358720, "type": "delta", "data": {"s": "BTCUSDT", "b": [["84064", "0.351069"], ["84063.4", "0.364358"], ["84061.4", "0.003"], ["84056.5", "0"], ["84056.2", "0.117493"], ["84053.8", "0.043629"], ["84052.4", "0"], ["84051.2", "0"], ["84050.4", "0.044"], ["84050.3", "0.041943"], ["84050.2", "0.040516"], ["84049.5", "0"], ["84046.4", "0.166971"], ["84046", "0"], ["84045.4", "0"], ["84043.2", "0.004695"], ["84039.1", "0.353255"], ["84039", "0"], ["84038.4", "0.059399"], ["84038.2", "0"], ["84038", "0"], ["84037.3", "0.305129"], ["84018.9", "0.04"], ["83990.2", "0.003697"], ["83989.4", "0.195"], ["83988.2", "0.118804"], ["83987.3", "0.04"]], "a": [["84071.9", "0"], ["84072.5", "0.015"], ["84081", "0"], ["84081.4", "0.110685"], ["84085.3", "0"], ["84086.9", "0.003234"], ["84088.6", "0.000099"], ["84090", "0.178435"], ["84090.7", "0.349782"], ["84091.2", "0.182985"], ["84091.5", "0"], ["84092.3", "0"], ["84095.4", "0"], ["84098.5", "0.023789"], ["84099.3", "0"], ["84099.6", "0"], ["84100.3", "0.330305"], ["84106.6", "0"], ["84106.7", "0"], ["84107.4", "0.013"], ["84107.5", "0.012847"], ["84107.6", "0"], ["84108.3", "0.04"], ["84108.4", "0.04"], ["84119.1", "2.257034"], ["84134.3", "0.001466"], ["84137.1", "0.4"], ["84137.2", "0.029723"], ["84137.3", "0.003211"], ["84137.4", "0.013073"], ["84137.7", "0.001333"]], "u": 20725, "seq": 67549990713}, "cts": 1742555358708}}
{"exchange": "BITGET", "timestamp": 1742555358.800834, "message": {"action": "update", "arg": {"instType": "SPOT", "channel": "books", "instId": "BTCUSDT"}, "data": [{"asks": [["84029.41", "0.006387"], ["84046.22", "0"], ["84100.70", "0.001770"], ["84102.70", "0.004899"], ["84104.70", "0.012892"], ["84106.70", "0.033926"], ["84111.10", "2.823030"], ["84111.90", "1.047720"], ["84113.00", "0"], ["84118.40", "0.050550"], ["84119.40", "0.045540"], ["84148.70", "4.622297"], ["84157.20", "5.437996"], ["84165.70", "4.984830"], ["84174.20", "4.712930"], ["84182.70", "4.259764"], ["84191.20", "3.987864"], ["84208.20", "3.897231"], ["84216.70", "4.350397"], ["84225.20", "4.078497"], ["84233.70", "5.619263"], ["84242.20", "5.256730"], ["84250.70", "5.166096"], ["84259.20", "4.531664"], ["84267.70", "4.169131"], ["84276.20", "4.894197"], ["84284.70", "4.441030"], ["84293.20", "5.075463"], ["84301.70", "5.347363"], ["84310.20", "4.803563"], ["84525.00", "0.003807"]], "bids": [["84029.40", "0.782213"], ["84028.51", "0.504369"], ["84028.50", "0.448695"], ["84026.50", "1.180776"], ["84024.50", "3.107305"], ["84023.49", "1.475095"], ["84022.50", "8.177118"], ["84022.10", "10.978800"], ["84019.20", "2.387100"], ["84018.70", "0.813540"], ["84012.60", "0.008064"], ["83980.50", "3.897231"], ["83963.50", "5.437996"], ["83955.00", "4.259764"], ["83946.50", "5.166096"], ["83938.00", "4.531664"], ["83929.50", "5.619263"], ["83921.00", "4.894197"], ["83912.50", "4.984830"], ["83904.00", "4.803563"], ["83895.50", "3.987864"], ["83887.00", "4.441030"], ["83878.50", "4.622297"], ["83870.00", "4.078497"], ["83861.50", "4.169131"], ["83844.50", "4.712930"], ["83836.00", "5.075463"], ["83827.50", "5.347363"], ["83819.00", "5.256730"]], "checksum": 550550449, "ts": "1742555358771"}], "ts": 1742555358773}}
{"exchange": "BYBIT", "timestamp": 1742555358.940901, "message": {"topic": "orderbook.200.BTCUSDT", "ts": 1742555358920, "type": "delta", "data": {"s": "BTCUSDT", "b": [["84056.2", "0"], ["84055.6", "0.01"], ["84054.2", "0.005"], ["84051.2", "0.003575"], ["84050.3", "0.087294"], ["84046.4", "0.001466"], ["84046.1", "0.124062"], ["84039.1", "0"], ["84037.3", "0"], ["84022.2", "0.048"], ["84017.2", "0.044"], ["83987.3", "0"]], "a": [["84064.1", "0.021489"], ["84081.2", "0.009489"], ["84081.4", "0"], ["84084.8", "0.064751"], ["84091.2", "0"], ["84100.3", "0.024389"], ["84137.8", "0.04"]], "u": 20726, "seq": 67549990771}, "cts": 1742555358906}}
{"exchange": "BITGET", "timestamp": 1742555359.008772, "message": {"action": "update", "arg": {"instType": "SPOT", "channel": "books", "instId": "BTCUSDT"}, "data": [{"asks": [["84029.41", "0.006357"], ["84033.04", "0"], ["84078.88", "0"], ["84083.06", "0"], ["84084.92", "0"], ["84088.79", "0.001598"], ["84090.64", "0.001597"], ["84102.70", "0.004587"], ["84104.70", "0.012072"], ["84106.70", "0.031769"], ["84115.20", "0.066600"], ["84118.40", "0"], ["84118.50", "0.373500"], ["84119.40", "0"], ["84148.70", "4.350397"], ["84157.20", "5.528630"], ["84165.70", "5.437996"], ["84174.20", "4.441030"], ["84182.70", "5.075463"], ["84191.20", "4.259764"], ["84199.70", "5.619263"], ["84208.20", "4.531664"], ["84216.70", "4.894197"], ["84225.20", "5.347363"], ["84233.70", "4.984830"], ["84242.20", "3.897231"], ["84248.52", "0.164046"], ["84250.70", "4.803563"], ["84259.20", "4.622297"], ["84267.70", "4.712930"], ["84276.20", "4.169131"], ["84284.70", "4.078497"], ["84293.20", "5.166096"], ["84301.70", "3.987864"], ["84310.20", "5.256730"], ["84525.82", "0.000099"], ["84527.47", "0.000608"]], "bids": [["84029.40", "0.700728"], ["84028.50", "0.509359"], ["84026.50", "1.340416"], ["84024.50", "3.527413"], ["84023.49", "1.547011"], ["84022.50", "9.282665"], ["84022.10", "10.468260"], ["83980.50", "4.894197"], ["83978.53", "0.001176"], ["83978.00", "0.000017"], ["83976.52", "0.001173"], ["83972.81", "0"], ["83972.00", "4.712930"], ["83970.81", "0"], ["83963.50", "4.350397"], ["83955.00", "4.984830"], ["83938.00", "4.078497"], ["83929.50", "3.987864"], ["83921.00", "4.803563"], ["83912.50", "5.619263"], ["83904.00", "4.622297"], ["83895.50", "4.531664"], ["83887.00", "3.897231"], ["83878.50", "4.441030"], ["83870.00", "4.169131"], ["83861.50", "5.075463"], ["83853.00", "4.259764"], ["83844.50", "5.528630"], ["83836.00", "5.347363"], ["83827.50", "5.437996"]], "checksum": 928135536, "ts": "1742555358972"}], "ts": 1742555358977}}
{"exchange": "BYBIT", "timestamp": 1742555359.139601, "message": {"topic": "orderbook.200.BTCUSDT", "ts": 1742555359119, "type": "delta", "data": {"s": "BTCUSDT", "b": [["84055.6", "0.015"], ["84054.2", "0"], ["84050.3", "0.041943"], ["84001.4", "0.235392"], ["83996", "0"], ["83987.3", "0.04"]], "a": [["84072.2", "0"], ["84072.3", "0"], ["84074.1", "0"], ["84074.8", "0.000297"], ["84074.9", "0.078124"], ["84090.7", "0.217219"], ["84137.9", "0.044"], ["84138.1", "0.000518"]], "u": 20727, "seq": 67549990798}, "cts": 1742555359109}}
