{"exchange": "BYBIT", "timestamp": 1742556573.937828, "message": {"topic": "orderbook.200.BTCUSDT", "ts": 1742556573920, "type": "delta", "data": {"s": "BTCUSDT", "b": [["83901.4", "13.158558"], ["83898.7", "0"]], "a": [["83984.9", "0"], ["84028", "0.00325"]], "u": 26683, "seq": 67550551724}, "cts": 1742556573886}}
{"exchange": "BITGET", "timestamp": 1742556574.041313, "message": {"action": "update", "arg": {"instType": "SPOT", "channel": "books", "instId": "BTCUSDT"}, "data": [{"asks": [["84045.00", "4.537254"], ["84053.40", "4.990980"], ["84061.80", "5.081725"], ["84070.20", "5.444705"], ["84078.60", "4.083529"], ["84087.00", "3.992784"], ["84095.40", "5.353960"], ["84103.80", "4.265019"], ["84112.20", "5.263215"], ["84120.60", "4.627999"], ["84129.00", "4.718744"], ["84137.40", "4.809489"], ["84145.80", "4.446509"], ["84154.20", "4.900235"], ["84162.60", "4.174274"], ["84179.40", "5.172470"], ["84187.80", "5.626195"], ["84196.20", "4.355764"], ["84204.60", "5.535450"]], "bids": [["83944.99", "0.037213"], ["83895.00", "0.000924"], ["83877.00", "3.902039"], ["83868.60", "4.265019"], ["83860.20", "5.081725"], ["83851.80", "4.537254"], ["83835.00", "4.809489"], ["83826.60", "4.718744"], ["83818.20", "4.627999"], ["83809.80", "4.174274"], ["83801.40", "5.172470"], ["83793.00", "4.355764"], ["83784.60", "4.446509"], ["83776.20", "3.992784"], ["83767.80", "5.626195"], ["83759.40", "4.083529"], ["83751.00", "4.990980"], ["83742.60", "5.353960"], ["83734.20", "5.444705"], ["83725.80", "5.535450"], ["83717.40", "5.263215"], ["83640.00", "0"]], "checksum": 881208288, "ts": "1742556574012"}], "ts": 1742556574015}}
{"exchange": "BITGET", "timestamp": 1742556574.257342, "message": {"action": "update", "arg": {"instType": "SPOT", "channel": "books", "instId": "BTCUSDT"}, "data": [{"asks": [["83945.96", "1.582877"], ["83995.00", "0.158195"], ["83997.00", "0.416305"], ["83999.00", "1.095538"], ["84001.00", "2.882995"], ["84003.00", "7.586828"], ["84045.00", "3.992784"], ["84053.40", "3.902039"], ["84061.80", "5.263215"], ["84070.20", "4.083529"], ["84078.60", "4.537254"], ["84087.00", "5.353960"], ["84095.40", "5.081725"], ["84103.80", "4.900235"], ["84112.20", "4.718744"], ["84120.60", "5.626195"], ["84129.00", "4.446509"], ["84137.40", "5.172470"], ["84145.80", "5.535450"], ["84154.20", "4.627999"], ["84162.60", "4.990980"], ["84171.00", "5.444705"], ["84179.40", "4.809489"], ["84187.80", "4.265019"], ["84196.20", "4.174274"], ["84204.60", "4.355764"]], "bids": [["83914.80", "0.030000"], ["83894.00", "0.000017"], ["83877.00", "4.355764"], ["83868.60", "5.535450"], ["83851.80", "5.353960"], ["83843.40", "4.083529"], ["83826.60", "4.990980"], ["83809.80", "4.718744"], ["83801.40", "4.174274"], ["83793.00", "5.626195"], ["83791.02", "0.000351"], ["83784.60", "4.900235"], ["83767.80", "3.902039"], ["83759.40", "4.265019"], ["83751.00", "5.172470"], ["83742.60", "4.446509"], ["83734.20", "5.263215"], ["83725.80", "4.537254"], ["83717.40", "5.444705"]], "checksum": -1238935366, "ts": "1742556574227"}], "ts": 1742556574230}}
{"exchange": "BYBIT", "timestamp": 1742556574.338466, "message": {"topic": "orderbook.200.BTCUSDT", "ts": 1742556574320, "type": "delta", "data": {"s": "BTCUSDT", "b": [["83965.5", "0.278072"]], "a": [["83965.6", "0.613475"], ["83987", "0.183747"]], "u": 26684, "seq": 67550551753}, "cts": 1742556574316}}
{"exchange": "BITGET", "timestamp": 1742556574.468307, "message": {"action": "update", "arg": {"instType": "SPOT", "channel": "books", "instId": "BTCUSDT"}, "data": [{"asks": [["84045.00", "5.353960"], ["84053.40", "5.263215"], ["84061.80", "4.446509"], ["84070.20", "4.537254"], ["84078.60", "4.083529"], ["84087.00", "5.535450"], ["84095.40", "3.902039"], ["84103.80", "5.626195"], ["84112.20", "4.355764"], ["84120.60", "4.990980"], ["84129.00", "5.081725"], ["84137.40", "4.718744"], ["84145.80", "4.809489"], ["84154.20", "5.172470"], ["84162.60", "4.900235"], ["84171.00", "4.265019"], ["84179.40", "3.992784"], ["84187.80", "4.627999"], ["84204.60", "5.444705"]], "bids": [["83877.00", "4.083529"], ["83868.60", "4.446509"], ["83860.20", "4.627999"], ["83851.80", "4.990980"], ["83843.40", "5.263215"], ["83835.00", "4.718744"], ["83826.60", "3.992784"], ["83818.20", "5.444705"], ["83809.80", "4.809489"], ["83801.40", "5.081725"], ["83793.00", "4.537254"], ["83784.60", "5.535450"], ["83776.20", "3.902039"], ["83767.80", "5.172470"], ["83759.40", "5.626195"], ["83751.00", "4.900235"], ["83742.60", "5.353960"], ["83734.20", "4.265019"], ["83725.80", "4.174274"], ["83717.40", "4.355764"]], "checksum": -1238935366, "ts": "1742556574439"}], "ts": 1742556574442}}
{"exchange": "BYBIT", "timestamp": 1742556574.538528, "message": {"topic": "orderbook.200.BTCUSDT", "ts": 1742556574519, "type": "delta", "data": {"s": "BTCUSDT", "b": [["83901.4", "0"], ["83898.7", "12.839205"]], "a": [["83965.6", "0.619475"], ["83979.6", "0.023513"], ["83987", "0.182646"]], "u": 26685, "seq": 67550551781}, "cts": 1742556574499}}
{"exchange": "BITGET", "timestamp": 1742556574.679297, "message": {"action": "update", "arg": {"instType": "SPOT", "channel": "books", "instId": "BTCUSDT"}, "data": [{"asks": [["83983.15", "0.010000"], ["84045.00", "4.083529"], ["84053.40", "4.718744"], ["84061.80", "5.263215"], ["84070.20", "4.174274"], ["84078.60", "4.537254"], ["84087.00", "5.353960"], ["84095.40", "5.172470"], ["84103.80", "4.265019"], ["84112.20", "4.990980"], ["84120.60", "4.809489"], ["84129.00", "5.535450"], ["84137.40", "5.081725"], ["84145.80", "3.902039"], ["84154.20", "4.355764"], ["84162.60", "3.992784"], ["84171.00", "5.444705"], ["84179.40", "4.627999"], ["84187.80", "4.446509"], ["84196.20", "5.626195"], ["84204.60", "4.900235"], ["84523.08", "0"]], "bids": [["83941.53", "0"], ["83925.00", "0.297099"], ["83923.00", "0.781840"], ["83921.00", "2.057474"], ["83919.00", "5.414404"], ["83893.00", "0.000032"], ["83877.00", "4.446509"], ["83868.60", "5.353960"], ["83860.20", "5.172470"], ["83851.80", "4.537254"], ["83843.40", "4.718744"], ["83835.00", "5.081725"], ["83826.60", "4.083529"], ["83818.20", "4.355764"], ["83809.80", "3.902039"], ["83801.40", "5.263215"], ["83793.00", "3.992784"], ["83776.20", "4.265019"], ["83767.80", "4.174274"], ["83759.40", "4.900235"], ["83751.00", "4.990980"], ["83742.60", "4.627999"], ["83734.20", "5.444705"], ["83725.80", "5.626195"], ["83717.40", "4.809489"], ["83640.00", "0.002013"]], "checksum": -271323806, "ts": "1742556574643"}], "ts": 1742556574647}}
{"exchange": "BYBIT", "timestamp": 1742556574.737891, "message": {"topic": "orderbook.200.BTCUSDT", "ts": 1742556574720, "type": "delta", "data": {"s": "BTCUSDT", "b": [["83965.5", "0.449739"], ["83965.3", "0.071492"], ["83963.8", "0.022043"], ["83963.7", "0"], ["83960.2", "0.071496"], ["83955.7", "0"], ["83925", "0"], ["83924.8", "0.012882"], ["83890", "0"]], "a": [["83965.6", "0.448475"], ["83965.8", "0.035727"], ["83984.1", "0.000997"], ["83995.6", "0.001466"], ["83995.7", "0.168571"], ["83998", "0.072278"], ["84028", "0"]], "u": 26686, "seq": 67550551814}, "cts": 1742556574717}}
{"exchange": "BITGET", "timestamp": 1742556574.873168, "message": {"action": "update", "arg": {"instType": "SPOT", "channel": "books", "instId": "BTCUSDT"}, "data": [{"asks": [["83985.00", "0.001078"], ["83987.00", "0.002837"], ["83989.00", "0.007465"], ["83991.00", "0.019647"], ["83995.00", "0.136057"], ["83997.00", "0.358044"], ["83999.00", "0.941975"], ["84001.00", "2.478882"], ["84003.00", "6.523373"], ["84003.40", "0.914880"], ["84005.00", "2.359500"], ["84005.70", "0.482010"], ["84016.00", "0.510000"], ["84016.10", "0"], ["84045.00", "5.626195"], ["84053.40", "4.809489"], ["84061.80", "5.081725"], ["84070.20", "5.172470"], ["84078.60", "5.263215"], ["84087.00", "4.900235"], ["84095.40", "4.174274"], ["84103.80", "4.627999"], ["84112.20", "3.992784"], ["84120.60", "4.446509"], ["84129.00", "4.718744"], ["84137.40", "4.537254"], ["84145.80", "4.990980"], ["84154.20", "4.265019"], ["84162.60", "5.444705"], ["84171.00", "5.353960"], ["84179.40", "4.083529"], ["84187.80", "3.902039"], ["84196.20", "5.535450"], ["84204.60", "4.355764"]], "bids": [["83945.95", "0.417612"], ["83935.00", "0.003008"], ["83933.00", "0.007915"], ["83931.00", "0.020829"], ["83929.00", "0.054812"], ["83927.00", "0.144242"], ["83925.00", "0.379584"], ["83923.00", "0.998907"], ["83921.00", "2.628702"], ["83919.00", "6.917638"], ["83910.60", "0.017850"], ["83908.20", "0"], ["83877.00", "4.809489"], ["83868.60", "5.444705"], ["83860.20", "4.627999"], ["83851.80", "5.172470"], ["83843.40", "5.081725"], ["83835.00", "4.446509"], ["83826.60", "4.990980"], ["83818.20", "5.626195"], ["83809.80", "5.263215"], ["83801.40", "4.718744"], ["83793.00", "4.265019"], ["83784.60", "4.900235"], ["83776.20", "5.535450"], ["83767.80", "3.902039"], ["83759.40", "4.083529"], ["83751.00", "4.537254"], ["83742.60", "4.355764"], ["83734.20", "5.353960"], ["83725.80", "4.174274"], ["83717.40", "3.992784"]], "checksum": 982664322, "ts": "1742556574843"}], "ts": 1742556574847}}
{"exchange": "BYBIT", "timestamp": 1742556574.938864, "message": {"topic": "orderbook.200.BTCUSDT", "ts": 1742556574920, "type": "delta", "data": {"s": "BTCUSDT", "b": [["83965.5", "0.460302"], ["83965.4", "0.027082"], ["83963.8", "0"], ["83961.8", "0.0497"], ["83961.7", "0.071495"], ["83960.2", "0"], ["83959.2", "0.001779"], ["83957.8", "0.03015"], ["83924.9", "0"], ["83924.7", "0.012882"], ["83901.5", "12.658757"], ["83898.7", "0"]], "a": [["83965.6", "0.452093"], ["83968", "0"], ["83970.3", "0.012248"], ["83978.1", "0.171"], ["83978.8", "0.000595"], ["83979.6", "0.003513"], ["83980.1", "0"], ["83984.1", "0"], ["83998", "0.059535"], ["83998.1", "0"], ["83998.6", "0.016247"], ["83998.7", "0.012743"], ["83998.8", "0"], ["83999.3", "0.103449"], ["83999.4", "0.040516"], ["84003.1", "0"], ["84007.7", "0.002143"], ["84017.3", "2.256638"], ["84028", "0.00325"], ["84028.4", "0.001333"], ["84028.5", "0.0012"], ["84028.6", "0.0006"]], "u": 26687, "seq": 67550551914}, "cts": 1742556574916}}
{"exchange": "BITGET", "timestamp": 1742556575.091511, "message": {"action": "update", "arg": {"instType": "SPOT", "channel": "books", "instId": "BTCUSDT"}, "data": [{"asks": [["83987.00", "0.001050"], ["83989.00", "0.002376"], ["83991.00", "0.006255"], ["83995.00", "0.043314"], ["83997.00", "0.113986"], ["83999.00", "0.299963"], ["84001.00", "0.789375"], ["84003.00", "2.077304"], ["84004.80", "2.359530"], ["84005.00", "0"], ["84005.20", "0.242520"], ["84006.40", "0.066390"], ["84008.40", "0.792930"], ["84011.20", "0"], ["84011.50", "1.071270"], ["84014.10", "0.144780"], ["84014.80", "0"], ["84015.90", "0"], ["84016.00", "0"], ["84045.00", "5.353960"], ["84053.40", "4.083529"], ["84061.80", "4.627999"], ["84070.20", "4.809489"], ["84078.60", "5.626195"], ["84087.00", "4.265019"], ["84095.40", "4.355764"], ["84103.80", "5.263215"], ["84112.20", "5.444705"], ["84120.60", "5.535450"], ["84129.00", "4.537254"], ["84137.40", "3.992784"], ["84145.80", "4.446509"], ["84154.20", "4.990980"], ["84162.60", "4.900235"], ["84171.00", "5.172470"], ["84179.40", "4.718744"], ["84187.80", "4.174274"], ["84196.20", "3.902039"], ["84204.60", "5.081725"]], "bids": [["83944.99", "0"], ["83935.00", "0.002607"], ["83933.00", "0.006638"], ["83931.78", "0.062638"], ["83931.00", "0.017468"], ["83929.00", "0.045968"], ["83927.00", "0.120968"], ["83925.00", "0.318337"], ["83923.00", "0.837730"], ["83921.00", "2.204551"], ["83919.00", "5.801452"], ["83910.60", "0.287610"], ["83895.00", "0.000939"], ["83877.00", "4.083529"], ["83868.60", "4.446509"], ["83860.20", "4.265019"], ["83851.80", "3.992784"], ["83843.40", "5.626195"], ["83835.00", "4.900235"], ["83818.20", "5.444705"], ["83809.80", "5.353960"], ["83801.40", "5.172470"], ["83793.00", "3.902039"], ["83784.60", "5.263215"], ["83776.20", "4.537254"], ["83767.80", "4.174274"], ["83759.40", "5.535450"], ["83751.00", "4.355764"], ["83742.60", "4.718744"], ["83734.20", "5.081725"], ["83725.80", "4.809489"], ["83717.40", "4.627999"]], "checksum": -861734378, "ts": "1742556575057"}], "ts": 1742556575064}}
{"exchange": "BYBIT", "timestamp": 1742556575.137361, "message": {"topic": "orderbook.200.BTCUSDT", "ts": 1742556575120, "type": "delta", "data": {"s": "BTCUSDT", "b": [["83965.5", "0.458809"], ["83961.8", "0.028252"], ["83961.7", "0"], ["83960.3", "0.071649"], ["83925.2", "0.013"], ["83925.1", "0.012882"], ["83924.8", "0"], ["83924.7", "0"], ["83890", "0.0002"]], "a": [["83977", "0.17862"], ["83984.1", "0.000997"], ["84000.2", "0.039256"], ["84028.6", "0"]], "u": 26688, "seq": 67550552051}, "cts": 1742556575116}}
{"exchange": "BITGET", "timestamp": 1742556575.291051, "message": {"action": "update", "arg": {"instType": "SPOT", "channel": "books", "instId": "BTCUSDT"}, "data": [{"asks": [["83945.96", "1.575545"], ["83993.00", "0.062760"], ["83996.99", "0.131052"], ["84000.99", "0.327079"], ["84045.00", "4.809489"], ["84053.40", "5.353960"], ["84061.80", "5.626195"], ["84070.20", "5.172470"], ["84078.60", "4.446509"], ["84087.00", "4.083529"], ["84095.40", "5.081725"], ["84103.80", "4.537254"], ["84129.00", "5.263215"], ["84137.40", "4.990980"], ["84145.80", "4.355764"], ["84154.20", "4.265019"], ["84162.60", "3.992784"], ["84171.00", "4.174274"], ["84179.40", "4.627999"], ["84187.80", "4.718744"], ["84204.60", "4.900235"]], "bids": [["83945.81", "0.047852"], ["83941.75", "0.010000"], ["83877.00", "4.265019"], ["83868.60", "5.172470"], ["83860.20", "4.627999"], ["83851.80", "4.446509"], ["83843.40", "5.353960"], ["83835.00", "4.990980"], ["83826.60", "4.718744"], ["83818.20", "3.992784"], ["83809.80", "5.626195"], ["83801.40", "4.174274"], ["83793.00", "4.083529"], ["83784.60", "4.809489"], ["83776.20", "3.902039"], ["83767.80", "4.537254"], ["83759.40", "5.263215"], ["83751.00", "5.535450"], ["83742.60", "4.900235"], ["83734.20", "4.355764"], ["83725.80", "5.444705"], ["83717.40", "5.081725"], ["83640.15", "0"], ["83640.00", "0"]], "checksum": -793420279, "ts": "1742556575257"}], "ts": 1742556575260}}
{"exchange": "BYBIT", "timestamp": 1742556575.337754, "message": {"topic": "orderbook.200.BTCUSDT", "ts": 1742556575320, "type": "delta", "data": {"s": "BTCUSDT", "b": [["83961.8", "0.046169"], ["83960.3", "0.071496"], ["83925.3", "0.013"], ["83925.2", "0.012882"], ["83925.1", "0"]], "a": [["83984.1", "0"], ["83989.6", "0"], ["83998.5", "0.013"], ["83998.6", "0.01599"], ["83998.7", "0"], ["83999.3", "0.063449"], ["83999.4", "0.000516"], ["83999.7", "0.055333"], ["83999.8", "0.04009"], ["84003.1", "2.256638"], ["84017.3", "0"], ["84028.6", "0.0006"], ["84029.1", "0.000333"]], "u": 26689, "seq": 67550552195}, "cts": 1742556575316}}
{"exchange": "BITGET", "timestamp": 1742556575.5068, "message": {"action": "update", "arg": {"instType": "SPOT", "channel": "books", "instId": "BTCUSDT"}, "data": [{"asks": [["83945.96", "1.582877"], ["83980.92", "0"], ["84010.40", "0"], ["84045.00", "4.990980"], ["84052.55", "0"], ["84053.40", "5.081725"], ["84060.95", "0"], ["84061.80", "4.718744"], ["84070.20", "5.444705"], ["84078.60", "5.353960"], ["84087.00", "5.263215"], ["84095.40", "4.627999"], ["84103.80", "4.265019"], ["84112.20", "3.992784"], ["84120.60", "5.626195"], ["84129.00", "4.809489"], ["84137.40", "5.172470"], ["84145.80", "4.083529"], ["84154.20", "4.900235"], ["84162.60", "4.446509"], ["84171.00", "3.902039"], ["84179.40", "4.355764"], ["84187.80", "4.174274"], ["84196.20", "5.535450"], ["84204.60", "4.537254"], ["84523.08", "0.000015"], ["84523.48", "0.000015"], ["84523.81", "0.000024"], ["84524.00", "0.000035"]], "bids": [["83945.90", "0.047852"], ["83945.81", "0"], ["83877.00", "4.900235"], ["83868.60", "3.902039"], ["83861.03", "0"], ["83860.20", "5.172470"], ["83851.98", "0"], ["83851.80", "3.992784"], ["83843.40", "4.083529"], ["83826.60", "4.355764"], ["83818.20", "4.718744"], ["83809.80", "5.353960"], ["83793.00", "4.537254"], ["83784.60", "5.263215"], ["83776.20", "5.626195"], ["83767.80", "4.446509"], ["83759.40", "5.081725"], ["83751.00", "5.444705"], ["83742.60", "4.265019"], ["83734.20", "4.809489"], ["83725.80", "4.627999"], ["83717.40", "5.535450"], ["83640.15", "0.000423"], ["83640.00", "0.002013"]], "checksum": -916216991, "ts": "1742556575464"}], "ts": 1742556575469}}
{"exchange": "BYBIT", "timestamp": 1742556575.538746, "message": {"topic": "orderbook.200.BTCUSDT", "ts": 1742556575519, "type": "delta", "data": {"s": "BTCUSDT", "b": [["83950.5", "0"], ["83889.9", "0.011992"]], "a": [["83965.6", "0.452332"], ["83976.2", "0.203559"], ["83977", "0"], ["83979.7", "0.178615"], ["83988.2", "0"], ["83988.5", "0.003576"], ["83989.6", "0.035737"], ["83998.5", "0"], ["83998.6", "0.003247"], ["83998.7", "0.013"], ["83998.8", "0.012743"], ["83999.4", "0.040516"], ["83999.5", "0.04"], ["83999.7", "0.015333"], ["83999.8", "0.00009"], ["84000.2", "0.719869"], ["84028.5", "0"], ["84028.6", "0"], ["84029.1", "0"]], "u": 26690, "seq": 67550552285}, "cts": 1742556575511}}
{"exchange": "BITGET", "timestamp": 1742556575.718482, "message": {"action": "update", "arg": {"instType": "SPOT", "channel": "books", "instId": "BTCUSDT"}, "data": [{"asks": [["83945.96", "1.162877"], ["83966.32", "0"], ["83966.33", "0.035952"], ["83966.74", "0"], ["83966.76", "0.119870"], ["83968.00", "0"], ["83968.02", "0.035961"], ["83968.43", "0"], ["83968.45", "0.006356"], ["83968.60", "0"], ["83968.62", "0.006356"], ["83968.91", "0"], ["83968.93", "0.006356"], ["83970.01", "0"], ["83970.02", "0.010984"], ["83970.26", "0"], ["83970.27", "0.006356"], ["83970.42", "0"], ["83970.44", "0.006356"], ["83970.93", "0"], ["83970.94", "0.022785"], ["83971.43", "0"], ["83971.44", "0.006356"], ["83971.45", "0.006356"], ["83971.76", "0"], ["83971.78", "0.119883"], ["83971.80", "0.016429"], ["83971.94", "0"], ["83971.98", "0.006356"], ["83973.46", "0"], ["83973.48", "0.017342"], ["83974.31", "0"], ["83974.32", "0.009990"], ["83975.19", "0"], ["83975.21", "0.119850"], ["83976.20", "0"], ["83976.21", "0.119858"], ["83976.38", "0"], ["83976.40", "0.119867"], ["83976.62", "0"], ["83976.63", "0.015895"], ["83980.56", "0"], ["83980.58", "0.015892"], ["83981.43", "0"], ["83981.45", "0.010988"], ["83982.11", "0.176197"], ["83987.00", "0.001340"], ["83989.00", "0.003526"], ["83991.00", "0.009280"], ["83995.00", "0.064264"], ["83997.00", "0.169117"], ["83999.00", "0.445043"], ["84001.00", "1.171168"], ["84003.00", "3.082020"], ["84006.70", "0"], ["84014.80", "1.055730"], ["84045.00", "4.265019"], ["84053.40", "4.446509"], ["84056.16", "0.001810"], ["84061.80", "4.990980"], ["84064.57", "0.003620"], ["84070.20", "5.081725"], ["84078.60", "5.444705"], ["84087.00", "5.353960"], ["84095.40", "5.263215"], ["84103.80", "4.718744"], ["84112.20", "5.626195"], ["84120.60", "3.902039"], ["84129.00", "4.355764"], ["84145.80", "5.535450"], ["84154.20", "4.083529"], ["84162.60", "3.992784"], ["84171.00", "4.900235"], ["84179.40", "4.627999"], ["84196.20", "4.537254"], ["84204.60", "4.809489"], ["84523.08", "0"], ["84523.48", "0"], ["84523.81", "0"], ["84524.00", "0"]], "bids": [["83945.90", "0"], ["83926.04", "0.089610"], ["83926.02", "0"], ["83925.62", "0.247933"], ["83925.60", "0"], ["83924.37", "0.084057"], ["83924.35", "0"], ["83923.96", "0.017842"], ["83923.94", "0"], ["83923.79", "0.018280"], ["83923.77", "0"], ["83923.48", "0"], ["83923.46", "0.004023"], ["83923.43", "0.005954"], ["83923.41", "0"], ["83923.00", "0.837528"], ["83922.34", "0.055734"], ["83922.33", "0"], ["83922.09", "0.017127"], ["83922.07", "0"], ["83921.92", "0.007141"], ["83921.90", "0"], ["83921.42", "0.028905"], ["83921.41", "0.007350"], ["83921.40", "0"], ["83921.00", "2.204021"], ["83920.91", "0.016961"], ["83920.90", "0"], ["83920.89", "0"], ["83920.59", "0.025220"], ["83920.58", "0.225197"], ["83920.57", "0"], ["83920.56", "0"], ["83920.43", "0.017375"], ["83920.41", "0.008196"], ["83920.40", "0"], ["83919.00", "5.800057"], ["83918.91", "0.064709"], ["83918.08", "0.018543"], ["83918.06", "0"], ["83917.12", "0.268752"], ["83917.10", "0"], ["83916.11", "0.222981"], ["83916.09", "0"], ["83915.95", "0.260159"], ["83915.94", "0"], ["83915.69", "0.076219"], ["83915.67", "0"], ["83911.74", "0.073317"], ["83911.73", "0"], ["83910.93", "0.056446"], ["83910.92", "0"], ["83910.60", "0.017850"], ["83909.25", "0.000878"], ["83909.23", "0"], ["83890.78", "0.003602"], ["83890.77", "0"], ["83868.60", "4.627999"], ["83861.37", "0.001810"], ["83860.20", "5.081725"], ["83852.98", "0.003620"], ["83851.80", "4.083529"], ["83843.40", "4.809489"], ["83835.00", "5.263215"], ["83826.60", "3.902039"], ["83818.20", "5.626195"], ["83811.54", "0.125802"], ["83811.09", "0"], ["83809.80", "4.990980"], ["83801.40", "5.535450"], ["83793.00", "5.172470"], ["83784.60", "4.174274"], ["83776.20", "3.992784"], ["83767.80", "4.265019"], ["83759.40", "5.353960"], ["83751.00", "4.355764"], ["83742.60", "5.444705"], ["83734.20", "4.718744"], ["83725.80", "4.537254"], ["83717.40", "4.446509"], ["83640.15", "0"], ["83640.00", "0"]], "checksum": -2030485014, "ts": "1742556575666"}], "ts": 1742556575672}}
{"exchange": "BYBIT", "timestamp": 1742556575.744212, "message": {"topic": "orderbook.200.BTCUSDT", "ts": 1742556575719, "type": "delta", "data": {"s": "BTCUSDT", "b": [["83917.4", "0.135557"], ["83914.6", "0"], ["83901.5", "12.62963"]], "a": [["83985.7", "0.001168"], ["83989.6", "0.035738"], ["83998.5", "0.013"], ["83998.6", "0.01599"], ["83998.7", "0"], ["83998.8", "0"], ["83999.2", "0.04"], ["83999.3", "0.04"], ["83999.4", "0.000516"], ["83999.5", "0"], ["84002.1", "0.063449"], ["84028.4", "0"]], "u": 26691, "seq": 67550552315}, "cts": 1742556575701}}
{"exchange": "BITGET", "timestamp": 1742556575.896366, "message": {"action": "update", "arg": {"instType": "SPOT", "channel": "books", "instId": "BTCUSDT"}, "data": [{"asks": [["83945.96", "1.582877"], ["83987.00", "0.001192"], ["83989.00", "0.003137"], ["83991.00", "0.008257"], ["83995.00", "0.057178"], ["83997.00", "0.150469"], ["83999.00", "0.395716"], ["84001.00", "1.041357"], ["84003.00", "2.740412"], ["84008.40", "0.426390"], ["84011.50", "0"], ["84045.00", "4.900235"], ["84053.40", "4.083529"], ["84061.80", "4.265019"], ["84070.20", "4.537254"], ["84078.60", "5.353960"], ["84087.00", "5.263215"], ["84095.40", "5.626195"], ["84103.80", "4.355764"], ["84112.20", "4.446509"], ["84120.60", "4.990980"], ["84129.00", "4.627999"], ["84137.40", "3.902039"], ["84145.80", "5.444705"], ["84154.20", "5.081725"], ["84162.60", "4.809489"], ["84171.00", "4.718744"], ["84179.40", "3.992784"], ["84187.80", "5.535450"], ["84196.20", "5.172470"], ["84204.60", "4.174274"], ["84523.08", "0.000015"]], "bids": [["83945.84", "0.047852"], ["83894.00", "0"], ["83893.00", "0.000017"], ["83877.00", "5.172470"], ["83868.60", "5.444705"], ["83860.20", "3.992784"], ["83851.80", "4.537254"], ["83843.40", "3.902039"], ["83835.00", "4.265019"], ["83826.60", "5.626195"], ["83818.20", "4.990980"], ["83809.80", "4.627999"], ["83801.40", "4.355764"], ["83793.00", "4.083529"], ["83776.20", "5.263215"], ["83767.80", "4.446509"], ["83759.40", "4.900235"], ["83751.00", "5.081725"], ["83742.60", "4.809489"], ["83734.20", "5.535450"], ["83725.80", "5.353960"], ["83717.40", "4.718744"]], "checksum": 1430879679, "ts": "1742556575866"}], "ts": 1742556575870}}
{"exchange": "BYBIT", "timestamp": 1742556575.937209, "message": {"topic": "orderbook.200.BTCUSDT", "ts": 1742556575919, "type": "delta", "data": {"s": "BTCUSDT", "b": [["83965.5", "0.448246"], ["83914.7", "0.003181"]], "a": [["83965.6", "0.454475"], ["83985.7", "0"], ["83989.6", "0"], ["84007.7", "0"], ["84028.4", "0.001333"], ["84028.5", "0.0012"], ["84028.6", "0.0006"]], "u": 26692, "seq": 67550552336}, "cts": 1742556575900}}
{"exchange": "BITGET", "timestamp": 1742556576.106581, "message": {"action": "update", "arg": {"instType": "SPOT", "channel": "books", "instId": "BTCUSDT"}, "data": [{"asks": [["83987.00", "0.001340"], ["83989.00", "0.003528"], ["83991.00", "0.009283"], ["83995.00", "0.064287"], ["83997.00", "0.169177"], ["83999.00", "0.445202"], ["84001.00", "1.171585"], ["84003.00", "3.083117"], ["84003.35", "0"], ["84003.36", "0.001597"], ["84045.00", "5.081725"], ["84053.40", "5.626195"], ["84061.80", "4.083529"], ["84070.20", "4.627999"], ["84078.60", "5.535450"], ["84095.40", "4.537254"], ["84103.80", "4.446509"], ["84112.20", "4.355764"], ["84120.60", "4.718744"], ["84129.00", "5.444705"], ["84137.40", "4.900235"], ["84145.80", "4.174274"], ["84154.20", "3.992784"], ["84162.60", "5.172470"], ["84171.00", "4.809489"], ["84179.40", "5.353960"], ["84187.80", "4.990980"], ["84196.20", "4.265019"], ["84204.60", "3.902039"]], "bids": [["83889.36", "0.001174"], ["83889.35", "0"], ["83877.00", "5.535450"], ["83868.60", "5.081725"], ["83860.20", "5.444705"], ["83851.80", "4.627999"], ["83843.40", "4.990980"], ["83835.00", "4.174274"], ["83826.60", "4.718744"], ["83818.20", "4.809489"], ["83809.80", "5.263215"], ["83801.40", "4.446509"], ["83793.00", "5.626195"], ["83784.60", "4.355764"], ["83776.20", "4.265019"], ["83767.80", "5.172470"], ["83759.40", "5.353960"], ["83751.00", "4.083529"], ["83742.60", "3.992784"], ["83734.20", "4.900235"], ["83725.80", "4.537254"], ["83717.40", "3.902039"]], "checksum": 1430879679, "ts": "1742556576076"}], "ts": 1742556576079}}
{"exchange": "BYBIT", "timestamp": 1742556576.140835, "message": {"topic": "orderbook.200.BTCUSDT", "ts": 1742556576119, "type": "delta", "data": {"s": "BTCUSDT", "b": [["83962", "0.071495"], ["83960.3", "0"], ["83891.2", "0"], ["83889.8", "0.001333"]], "a": [["83965.6", "0.452332"], ["83988.5", "0"], ["83989.6", "0.035738"], ["83998.5", "0"], ["83998.6", "0.003247"], ["83998.7", "0.013"], ["83998.8", "0.012743"], ["83999.2", "0"], ["83999.3", "0"], ["83999.4", "0.040516"], ["83999.5", "0.04"], ["84008.6", "0.002659"]], "u": 26693, "seq": 67550552381}, "cts": 1742556576109}}
{"exchange": "BITGET", "timestamp": 1742556576.30858, "message": {"action": "update", "arg": {"instType": "SPOT", "channel": "books", "instId": "BTCUSDT"}, "data": [{"asks": [["83945.96", "1.581733"], ["83987.00", "0.001139"], ["83989.00", "0.002801"], ["83991.00", "0.007372"], ["83995.00", "0.051051"], ["83997.00", "0.134346"], ["83999.00", "0.353543"], ["84001.00", "0.930375"], ["84003.00", "2.448355"], ["84004.80", "0"], ["84005.20", "0.242730"], ["84006.70", "2.359260"], ["84045.00", "4.355764"], ["84053.40", "4.446509"], ["84061.80", "4.174274"], ["84070.20", "5.444705"], ["84078.60", "3.902039"], ["84087.00", "4.083529"], ["84095.40", "5.263215"], ["84103.80", "5.172470"], ["84112.20", "4.900235"], ["84120.60", "4.537254"], ["84129.00", "4.718744"], ["84137.40", "5.081725"], ["84140.82", "0"], ["84145.80", "4.265019"], ["84154.20", "5.626195"], ["84162.60", "5.535450"], ["84171.00", "4.990980"], ["84187.80", "4.627999"], ["84196.20", "3.992784"], ["84204.60", "4.809489"], ["84523.48", "0.000015"]], "bids": [["83945.84", "0"], ["83914.80", "0.015000"], ["83877.00", "4.083529"], ["83868.60", "4.265019"], ["83860.20", "4.900235"], ["83851.80", "5.444705"], ["83843.40", "5.263215"], ["83835.00", "5.535450"], ["83826.60", "5.081725"], ["83818.20", "5.353960"], ["83809.80", "4.174274"], ["83801.40", "4.718744"], ["83793.00", "3.992784"], ["83784.60", "4.537254"], ["83776.20", "5.626195"], ["83767.80", "3.902039"], ["83759.40", "4.809489"], ["83751.00", "4.627999"], ["83742.60", "5.172470"], ["83734.20", "4.446509"], ["83725.80", "4.355764"], ["83717.40", "4.990980"], ["83640.15", "0.000423"]], "checksum": -470785914, "ts": "1742556576276"}], "ts": 1742556576281}}
{"exchange": "BYBIT", "timestamp": 1742556576.337289, "message": {"topic": "orderbook.200.BTCUSDT", "ts": 1742556576320, "type": "delta", "data": {"s": "BTCUSDT", "b": [["83965.5", "0.460184"], ["83962.1", "0.028306"], ["83962", "0"], ["83961.8", "0"], ["83960.5", "0.000846"], ["83960.3", "0.071496"], ["83958.7", "0"], ["83936.2", "0"], ["83889.5", "0.003181"], ["83889.4", "0.001466"]], "a": [["83998.7", "0"], ["83998.8", "0"], ["83999.4", "0.000516"], ["83999.5", "0"], ["84000.5", "0.013"], ["84000.6", "0.012743"], ["84001.2", "0.04"], ["84001.3", "0.04"], ["84028.6", "0"]], "u": 26694, "seq": 67550552458}, "cts": 1742556576316}}
{"exchange": "BITGET", "timestamp": 1742556576.511792, "message": {"action": "update", "arg": {"instType": "SPOT", "channel": "books", "instId": "BTCUSDT"}, "data": [{"asks": [["83976.80", "0"], ["83976.82", "0.009989"], ["83983.15", "0"], ["83987.00", "0.001212"], ["83989.00", "0.003191"], ["83991.00", "0.008395"], ["83995.00", "0.058139"], ["83997.00", "0.152997"], ["83999.00", "0.402624"], ["84001.00", "1.059535"], ["84001.43", "0"], ["84001.44", "0.001598"], ["84003.00", "2.788252"], ["84003.40", "1.095420"], ["84005.30", "2.359290"], ["84005.70", "0.579390"], ["84006.70", "0"], ["84007.20", "0.028680"], ["84014.10", "0.145110"], ["84045.00", "5.535450"], ["84053.40", "4.174274"], ["84061.80", "4.537254"], ["84078.60", "4.355764"], ["84087.00", "4.718744"], ["84095.40", "3.902039"], ["84103.80", "5.353960"], ["84112.20", "4.083529"], ["84120.60", "5.172470"], ["84129.00", "4.990980"], ["84137.40", "4.446509"], ["84145.80", "4.809489"], ["84146.07", "0.161572"], ["84154.20", "4.265019"], ["84162.60", "5.626195"], ["84171.00", "5.263215"], ["84179.40", "3.992784"], ["84187.80", "4.900235"], ["84196.20", "5.081725"], ["84204.60", "4.627999"]], "bids": [["83937.00", "0.001013"], ["83935.00", "0.002221"], ["83933.00", "0.005846"], ["83931.00", "0.015385"], ["83929.00", "0.040485"], ["83927.00", "0.106540"], ["83925.00", "0.280368"], ["83923.00", "0.737811"], ["83921.00", "1.941608"], ["83919.00", "5.109494"], ["83916.30", "0.071460"], ["83915.54", "0.021159"], ["83915.52", "0"], ["83912.00", "0.178650"], ["83910.60", "0.553800"], ["83909.90", "0.017850"], ["83909.50", "0"], ["83909.00", "0.000032"], ["83908.60", "0"], ["83895.00", "0.000956"], ["83891.31", "0.001177"], ["83891.30", "0"], ["83877.00", "5.263215"], ["83868.60", "4.355764"], ["83860.20", "5.353960"], ["83851.80", "5.626195"], ["83843.40", "4.627999"], ["83835.00", "3.902039"], ["83826.60", "3.992784"], ["83818.20", "4.718744"], ["83809.80", "4.900235"], ["83801.40", "4.537254"], ["83793.00", "5.535450"], ["83784.60", "4.083529"], ["83776.20", "4.990980"], ["83767.80", "4.809489"], ["83759.40", "5.172470"], ["83751.00", "5.444705"], ["83742.60", "4.446509"], ["83734.20", "4.265019"], ["83725.80", "5.081725"], ["83717.40", "4.174274"]], "checksum": -1014820765, "ts": "1742556576477"}], "ts": 1742556576480}}
{"exchange": "BYBIT", "timestamp": 1742556576.53745, "message": {"topic": "orderbook.200.BTCUSDT", "ts": 1742556576520, "type": "delta", "data": {"s": "BTCUSDT", "b": [["83965.5", "0.345163"], ["83962.1", "0.04624"], ["83960.5", "0.000768"], ["83958.2", "0.071498"], ["83936.8", "0.157282"], ["83925.5", "0.013516"], ["83925.4", "0.012882"], ["83925.3", "0"], ["83925.2", "0"]], "a": [["83989.6", "0"], ["84028.6", "0.0006"]], "u": 26695, "seq": 67550552512}, "cts": 1742556576514}}
{"exchange": "BITGET", "timestamp": 1742556576.719836, "message": {"action": "update", "arg": {"instType": "SPOT", "channel": "books", "instId": "BTCUSDT"}, "data": [{"asks": [["83989.00", "0.003336"], ["83991.00", "0.008778"], ["83995.00", "0.060789"], ["83997.00", "0.159971"], ["83999.00", "0.420976"], ["84001.00", "1.107832"], ["84003.00", "2.915345"], ["84005.70", "0.459390"], ["84014.10", "0.144780"], ["84053.40", "4.446509"], ["84061.80", "4.355764"], ["84070.20", "5.263215"], ["84078.60", "5.081725"], ["84087.00", "5.353960"], ["84095.40", "4.990980"], ["84103.80", "3.992784"], ["84112.20", "4.265019"], ["84120.60", "5.626195"], ["84129.00", "4.718744"], ["84137.40", "4.174274"], ["84154.20", "4.627999"], ["84162.60", "4.537254"], ["84171.00", "4.083529"], ["84179.40", "3.902039"], ["84187.80", "5.444705"], ["84196.20", "4.900235"], ["84204.60", "5.172470"]], "bids": [["83945.15", "0.047852"], ["83937.00", "0.001137"], ["83935.00", "0.002993"], ["83933.00", "0.007875"], ["83931.00", "0.020725"], ["83929.00", "0.054539"], ["83927.00", "0.143524"], ["83925.00", "0.377694"], ["83923.00", "0.993933"], ["83921.00", "2.615613"], ["83919.00", "6.883190"], ["83916.30", "0"], ["83915.30", "0.071460"], ["83912.00", "0.000032"], ["83911.80", "0.178860"], ["83911.00", "0.187650"], ["83910.00", "0.185700"], ["83909.90", "0"], ["83894.00", "0.000015"], ["83877.00", "4.990980"], ["83868.60", "5.626195"], ["83860.20", "5.444705"], ["83851.80", "4.900235"], ["83843.40", "4.355764"], ["83835.00", "5.353960"], ["83826.60", "4.627999"], ["83818.20", "5.263215"], ["83809.80", "4.809489"], ["83801.40", "4.083529"], ["83793.00", "4.718744"], ["83784.60", "5.172470"], ["83776.20", "4.537254"], ["83767.80", "4.265019"], ["83759.40", "4.174274"], ["83751.00", "3.992784"], ["83742.60", "3.902039"], ["83734.20", "5.535450"], ["83725.80", "4.446509"], ["83717.40", "5.081725"], ["83640.35", "0"], ["83640.15", "0"]], "checksum": 1628926558, "ts": "1742556576690"}], "ts": 1742556576693}}
{"exchange": "BYBIT", "timestamp": 1742556576.736847, "message": {"topic": "orderbook.200.BTCUSDT", "ts": 1742556576719, "type": "delta", "data": {"s": "BTCUSDT", "b": [["83965.5", "0.516163"], ["83960.7", "0.000153"], ["83901.5", "12.611418"], ["83889.4", "0"]], "a": [["83989.6", "0.035737"], ["84028.6", "0"]], "u": 26696, "seq": 67550552554}, "cts": 1742556576700}}
{"exchange": "BITGET", "timestamp": 1742556576.921047, "message": {"action": "update", "arg": {"instType": "SPOT", "channel": "books", "instId": "BTCUSDT"}, "data": [{"asks": [["84005.40", "0.120000"], ["84014.80", "0"], ["84045.00", "5.172470"], ["84053.40", "4.537254"], ["84061.80", "3.992784"], ["84070.20", "5.444705"], ["84078.60", "5.263215"], ["84095.40", "5.535450"], ["84103.80", "5.626195"], ["84112.20", "4.355764"], ["84120.60", "4.174274"], ["84129.00", "4.446509"], ["84137.40", "4.718744"], ["84145.80", "4.265019"], ["84154.20", "3.902039"], ["84162.60", "4.083529"], ["84171.00", "5.081725"], ["84179.40", "4.900235"], ["84187.80", "4.809489"], ["84196.20", "4.627999"], ["84204.60", "4.990980"]], "bids": [["83923.00", "0.994035"], ["83921.00", "2.615881"], ["83919.00", "6.883897"], ["83914.80", "0"], ["83909.90", "0.017850"], ["83877.00", "4.900235"], ["83868.60", "5.535450"], ["83860.20", "4.627999"], ["83851.80", "4.446509"], ["83843.40", "4.265019"], ["83835.00", "4.355764"], ["83826.60", "5.172470"], ["83818.20", "4.083529"], ["83809.80", "5.626195"], ["83801.40", "4.174274"], ["83793.00", "4.537254"], ["83784.60", "3.902039"], ["83776.20", "5.263215"], ["83767.80", "3.992784"], ["83759.40", "4.809489"], ["83751.00", "4.718744"], ["83742.60", "5.353960"], ["83734.20", "5.444705"], ["83725.80", "4.990980"]], "checksum": 1628926558, "ts": "1742556576892"}], "ts": 1742556576895}}
{"exchange": "BYBIT", "timestamp": 1742556576.937472, "message": {"topic": "orderbook.200.BTCUSDT", "ts": 1742556576920, "type": "delta", "data": {"s": "BTCUSDT", "b": [["83961.6", "0.0002"], ["83889.5", "0"]], "a": [["83965.6", "0.454475"], ["84008.6", "0.000516"]], "u": 26697, "seq": 67550552587}, "cts": 1742556576916}}
{"exchange": "BITGET", "timestamp": 1742556577.133715, "message": {"action": "update", "arg": {"instType": "SPOT", "channel": "books", "instId": "BTCUSDT"}, "data": [{"asks": [["84045.00", "4.718744"], ["84053.40", "5.353960"], ["84061.80", "4.083529"], ["84070.20", "4.355764"], ["84087.00", "4.537254"], ["84095.40", "4.900235"], ["84103.80", "3.902039"], ["84112.20", "4.265019"], ["84120.60", "5.444705"], ["84137.40", "4.809489"], ["84145.80", "4.174274"], ["84154.20", "4.627999"], ["84162.60", "3.992784"], ["84179.40", "4.990980"], ["84187.80", "5.626195"], ["84196.20", "5.172470"], ["84204.60", "5.535450"]], "bids": [["83919.00", "6.883693"], ["83877.00", "4.083529"], ["83868.60", "5.353960"], ["83860.20", "4.265019"], ["83851.80", "5.263215"], ["83843.40", "4.537254"], ["83835.00", "4.446509"], ["83826.60", "5.081725"], ["83818.20", "4.990980"], ["83809.80", "5.444705"], ["83801.40", "3.902039"], ["83793.00", "4.809489"], ["83784.60", "5.172470"], ["83776.20", "4.355764"], ["83759.40", "4.174274"], ["83742.60", "5.535450"], ["83734.20", "4.627999"], ["83725.80", "5.626195"], ["83717.40", "4.900235"]], "checksum": 1628926558, "ts": "1742556577104"}], "ts": 1742556577106}}
{"exchange": "BYBIT", "timestamp": 1742556577.13862, "message": {"topic": "orderbook.200.BTCUSDT", "ts": 1742556577120, "type": "delta", "data": {"s": "BTCUSDT", "b": [], "a": [["83989.6", "0"], ["84028.6", "0.0006"]], "u": 26698, "seq": 67550552617}, "cts": 1742556577109}}
{"exchange": "BYBIT", "timestamp": 1742556577.336836, "message": {"topic": "orderbook.200.BTCUSDT", "ts": 1742556577319, "type": "delta", "data": {"s": "BTCUSDT", "b": [["83965.5", "0.504225"], ["83925.5", "0.000516"], ["83925.3", "0.012882"], ["83889.8", "0"]], "a": [["83989.6", "0.035738"], ["84028.6", "0"]], "u": 26699, "seq": 67550552650}, "cts": 1742556577308}}
{"exchange": "BITGET", "timestamp": 1742556577.338036, "message": {"action": "update", "arg": {"instType": "SPOT", "channel": "books", "instId": "BTCUSDT"}, "data": [{"asks": [["83989.00", "0.003333"], ["83991.00", "0.008769"], ["83995.00", "0.060729"], ["83997.00", "0.159812"], ["83999.00", "0.420560"], ["84001.00", "1.106736"], ["84003.00", "2.912462"], ["84003.30", "0.058770"], ["84003.40", "1.095600"], ["84004.00", "0.068190"], ["84005.20", "0.242910"], ["84005.30", "2.359470"], ["84005.40", "0.120180"], ["84005.70", "0.459570"], ["84006.40", "0.066570"], ["84006.60", "0.074220"], ["84053.40", "3.992784"], ["84061.80", "5.535450"], ["84070.20", "4.537254"], ["84078.60", "4.990980"], ["84087.00", "4.265019"], ["84095.40", "4.355764"], ["84103.80", "4.446509"], ["84112.20", "5.172470"], ["84120.60", "5.081725"], ["84129.00", "5.444705"], ["84137.40", "4.083529"], ["84145.80", "5.353960"], ["84154.20", "4.174274"], ["84162.60", "4.809489"], ["84171.00", "5.626195"], ["84179.40", "3.902039"], ["84187.80", "4.627999"], ["84196.20", "5.263215"], ["84204.60", "4.900235"]], "bids": [["83941.75", "0"], ["83921.00", "2.615775"], ["83918.90", "1.542480"], ["83918.70", "2.359740"], ["83918.60", "1.010250"], ["83918.00", "0.066690"], ["83917.40", "0.045210"], ["83916.90", "0.190140"], ["83909.50", "0.021600"], ["83893.00", "0"], ["83877.00", "3.992784"], ["83868.60", "3.902039"], ["83860.20", "4.174274"], ["83851.80", "4.900235"], ["83843.40", "4.627999"], ["83835.00", "5.444705"], ["83826.60", "5.535450"], ["83818.20", "4.718744"], ["83809.80", "5.626195"], ["83801.40", "4.083529"], ["83793.00", "4.990980"], ["83784.60", "4.537254"], ["83776.20", "4.446509"], ["83767.80", "5.353960"], ["83759.40", "5.263215"], ["83751.00", "4.809489"], ["83742.60", "5.081725"], ["83734.20", "4.355764"], ["83725.80", "4.265019"], ["83717.40", "5.172470"], ["83640.35", "0.000022"]], "checksum": 243320401, "ts": "1742556577309"}], "ts": 1742556577312}}
{"exchange": "BYBIT", "timestamp": 1742556577.538098, "message": {"topic": "orderbook.200.BTCUSDT", "ts": 1742556577520, "type": "delta", "data": {"s": "BTCUSDT", "b": [["83961.9", "0.071828"], ["83960.3", "0"], ["83925.5", "0.013516"], ["83925.3", "0"], ["83889.8", "0.001333"], ["83889.5", "0.003181"]], "a": [["83989.6", "0.035737"]], "u": 26700, "seq": 67550552682}, "cts": 1742556577512}}
{"exchange": "BITGET", "timestamp": 1742556577.54997, "message": {"action": "update", "arg": {"instType": "SPOT", "channel": "books", "instId": "BTCUSDT"}, "data": [{"asks": [["83987.00", "0.001326"], ["83989.00", "0.003490"], ["83991.00", "0.009184"], ["83995.00", "0.063602"], ["83997.00", "0.167373"], ["83999.00", "0.440456"], ["84001.00", "1.159096"], ["84003.00", "3.050251"], ["84045.00", "5.535450"], ["84061.80", "4.174274"], ["84070.20", "4.355764"], ["84078.60", "4.718744"], ["84087.00", "4.083529"], ["84095.40", "4.990980"], ["84103.80", "4.900235"], ["84112.20", "3.902039"], ["84120.60", "5.172470"], ["84129.00", "4.265019"], ["84137.40", "5.263215"], ["84145.80", "5.444705"], ["84154.20", "4.446509"], ["84162.60", "5.626195"], ["84171.00", "4.537254"], ["84179.40", "4.627999"], ["84187.80", "5.081725"], ["84196.20", "4.809489"], ["84204.60", "5.353960"]], "bids": [["83937.00", "0.001247"], ["83935.00", "0.003283"], ["83933.00", "0.008640"], ["83931.00", "0.022735"], ["83929.00", "0.059831"], ["83927.00", "0.157448"], ["83925.00", "0.414338"], ["83923.00", "1.090362"], ["83921.00", "2.869375"], ["83919.00", "7.550986"], ["83877.00", "4.083529"], ["83868.60", "5.535450"], ["83860.20", "5.626195"], ["83851.80", "4.990980"], ["83843.40", "4.537254"], ["83835.00", "4.809489"], ["83826.60", "5.263215"], ["83818.20", "4.446509"], ["83809.80", "4.718744"], ["83801.40", "4.174274"], ["83793.00", "5.081725"], ["83784.60", "4.265019"], ["83776.20", "3.902039"], ["83767.80", "5.172470"], ["83759.40", "5.353960"], ["83751.00", "4.627999"], ["83742.60", "5.444705"], ["83734.20", "4.900235"], ["83725.80", "4.355764"], ["83717.40", "3.992784"]], "checksum": -558990796, "ts": "1742556577518"}], "ts": 1742556577524}}
{"exchange": "BYBIT", "timestamp": 1742556577.737084, "message": {"topic": "orderbook.200.BTCUSDT", "ts": 1742556577719, "type": "delta", "data": {"s": "BTCUSDT", "b": [["83965.5", "0.515734"], ["83901.5", "12.59417"]], "a": [["83965.6", "0.460475"], ["83989.6", "0"], ["83991.6", "0"], ["84028.6", "0.0006"], ["84029.1", "0.000333"]], "u": 26701, "seq": 67550552730}, "cts": 1742556577716}}
{"exchange": "BITGET", "timestamp": 1742556577.769736, "message": {"action": "update", "arg": {"instType": "SPOT", "channel": "books", "instId": "BTCUSDT"}, "data": [{"asks": [["83945.96", "1.161733"], ["83991.00", "0.009411"], ["83995.00", "0.065173"], ["83997.00", "0.171508"], ["83999.00", "0.451336"], ["84001.00", "1.187728"], ["84003.00", "3.125600"], ["84003.30", "0.058140"], ["84003.40", "0"], ["84004.00", "0.068820"], ["84005.20", "0.242730"], ["84005.30", "1.016640"], ["84005.40", "0"], ["84005.80", "2.359290"], ["84006.60", "0.074040"], ["84045.00", "3.902039"], ["84053.40", "5.263215"], ["84061.80", "4.265019"], ["84070.20", "5.535450"], ["84078.60", "4.990980"], ["84087.00", "3.992784"], ["84095.40", "5.444705"], ["84103.80", "5.081725"], ["84112.20", "4.809489"], ["84120.60", "4.627999"], ["84129.00", "5.353960"], ["84137.40", "4.355764"], ["84145.80", "4.174274"], ["84154.20", "4.900235"], ["84171.00", "4.083529"], ["84179.40", "5.172470"], ["84187.80", "4.446509"], ["84196.20", "4.537254"], ["84204.60", "4.718744"], ["84523.81", "0.000024"]], "bids": [["83914.80", "0.015000"], ["83909.50", "0"], ["83895.00", "0.000941"], ["83877.00", "4.627999"], ["83868.60", "3.902039"], ["83860.20", "3.992784"], ["83851.80", "4.174274"], ["83843.40", "4.355764"], ["83835.00", "4.446509"], ["83826.60", "4.718744"], ["83818.20", "5.172470"], ["83809.80", "4.900235"], ["83801.40", "5.353960"], ["83793.00", "4.537254"], ["83784.60", "4.083529"], ["83776.20", "4.265019"], ["83767.80", "4.990980"], ["83759.40", "5.081725"], ["83751.00", "5.626195"], ["83742.60", "5.535450"], ["83734.20", "5.263215"], ["83725.80", "4.809489"], ["83717.40", "5.444705"]], "checksum": 1834817126, "ts": "1742556577731"}], "ts": 1742556577734}}
{"exchange": "BYBIT", "timestamp": 1742556577.937651, "message": {"topic": "orderbook.200.BTCUSDT", "ts": 1742556577920, "type": "delta", "data": {"s": "BTCUSDT", "b": [["83965.5", "0.516534"], ["83964.5", "0.011915"], ["83960.7", "0"], ["83943.5", "0.119096"], ["83931.8", "0.090432"], ["83925.5", "0.000516"], ["83925.3", "0.012882"], ["83909.9", "0.015"], ["83889.9", "0"], ["83889.8", "0"], ["83889.5", "0"]], "a": [["83965.6", "0.337422"], ["83969.2", "0"], ["83970.3", "0.000333"], ["83970.6", "0.0017"], ["83971.1", "0"], ["83973.2", "0"], ["83973.3", "0.025944"], ["83973.7", "0.071485"], ["83974.3", "0"], ["83981.4", "0"], ["83989.4", "0"], ["83996", "0"], ["84000.5", "0"], ["84000.7", "0.036562"], ["84001.2", "0"], ["84001.4", "0.04"], ["84003.1", "0"], ["84008.5", "0.002143"], ["84020.1", "2.256638"], ["84030.6", "0.118804"], ["84030.9", "0.089099"], ["84031.1", "0.025312"], ["84031.8", "0.000516"], ["84032.2", "0.00325"]], "u": 26702, "seq": 67550552862}, "cts": 1742556577916}}
{"exchange": "BITGET", "timestamp": 1742556577.969403, "message": {"action": "update", "arg": {"instType": "SPOT", "channel": "books", "instId": "BTCUSDT"}, "data": [{"asks": [["83945.96", "1.372533"], ["83946.25", "0.121262"], ["83987.00", "0.001001"], ["83989.00", "0.001805"], ["83991.00", "0.004751"], ["83995.00", "0.032902"], ["83997.00", "0.086585"], ["83999.00", "0.227856"], ["84001.00", "0.599621"], ["84003.00", "1.577950"], ["84003.30", "0.057930"], ["84004.00", "0.001032"], ["84005.20", "0"], ["84005.80", "0"], ["84045.00", "5.626195"], ["84053.40", "5.535450"], ["84061.80", "4.446509"], ["84070.20", "3.902039"], ["84078.60", "5.444705"], ["84087.00", "5.263215"], ["84095.40", "4.265019"], ["84112.20", "4.990980"], ["84120.60", "4.718744"], ["84129.00", "5.172470"], ["84137.40", "3.992784"], ["84145.80", "4.537254"], ["84154.20", "4.355764"], ["84162.60", "4.627999"], ["84171.00", "4.900235"], ["84179.40", "5.353960"], ["84187.80", "4.174274"], ["84196.20", "4.809489"], ["84204.60", "4.083529"], ["84524.00", "0.000035"], ["84524.83", "0.000009"]], "bids": [["83945.95", "0.911512"], ["83933.00", "0.008757"], ["83931.00", "0.023045"], ["83929.00", "0.060644"], ["83927.00", "0.159589"], ["83925.00", "0.419972"], ["83923.00", "1.105188"], ["83921.00", "2.908390"], ["83919.00", "7.653658"], ["83918.00", "0.134490"], ["83909.74", "0"], ["83894.00", "0.000032"], ["83877.00", "4.355764"], ["83868.60", "5.444705"], ["83860.20", "5.353960"], ["83851.80", "4.446509"], ["83843.40", "3.992784"], ["83835.00", "4.537254"], ["83826.60", "4.990980"], ["83809.80", "4.265019"], ["83801.40", "5.626195"], ["83793.00", "4.900235"], ["83784.60", "4.627999"], ["83776.20", "4.809489"], ["83767.80", "3.902039"], ["83759.40", "5.535450"], ["83751.00", "5.081725"], ["83742.60", "4.083529"], ["83725.80", "4.174274"], ["83717.40", "4.718744"], ["83640.15", "0.000423"]], "checksum": -250632015, "ts": "1742556577939"}], "ts": 1742556577943}}
{"exchange": "BYBIT", "timestamp": 1742556578.139157, "message": {"topic": "orderbook.200.BTCUSDT", "ts": 1742556578120, "type": "delta", "data": {"s": "BTCUSDT", "b": [["83945.3", "0.082725"]], "a": [["83965.6", "0.385054"], ["83965.8", "0.107219"], ["83971.5", "0.051725"], ["83971.6", "0.071487"], ["83973.3", "0"], ["83983", "0.023923"], ["83987.5", "0"], ["84000.2", "0.093558"], ["84017.3", "2.256638"], ["84020.1", "0"], ["84031", "0.171"], ["84032.2", "0"]], "u": 26703, "seq": 67550552980}, "cts": 1742556578114}}
{"exchange": "BITGET", "timestamp": 1742556578.175546, "message": {"action": "update", "arg": {"instType": "SPOT", "channel": "books", "instId": "BTCUSDT"}, "data": [{"asks": [["83946.00", "0.040511"], ["83952.93", "0.006971"], ["83989.00", "0.001047"], ["83991.00", "0.002754"], ["83995.00", "0.019071"], ["83996.99", "0"], ["83997.00", "0.050188"], ["83999.00", "0.132074"], ["84001.00", "0.347562"], ["84003.00", "0.914897"], ["84003.30", "0.057960"], ["84003.70", "0.001025"], ["84004.00", "0"], ["84005.20", "0.223890"], ["84005.30", "0"], ["84005.70", "0.973230"], ["84006.40", "0"], ["84006.60", "0.074430"], ["84008.40", "1.427850"], ["84008.50", "0.250080"], ["84009.30", "0.066390"], ["84010.30", "1.071270"], ["84010.40", "0.459390"], ["84011.70", "2.515110"], ["84045.00", "4.900235"], ["84053.40", "4.355764"], ["84061.80", "5.626195"], ["84070.20", "4.537254"], ["84078.60", "4.627999"], ["84087.00", "5.081725"], ["84095.40", "4.990980"], ["84103.80", "4.174274"], ["84112.20", "4.083529"], ["84120.60", "4.809489"], ["84129.00", "5.353960"], ["84137.40", "3.902039"], ["84145.80", "3.992784"], ["84154.20", "5.444705"], ["84162.60", "5.172470"], ["84171.00", "4.718744"], ["84179.40", "4.446509"], ["84187.80", "4.265019"], ["84196.20", "5.263215"], ["84204.60", "5.535450"], ["84524.00", "0"], ["84524.83", "0"]], "bids": [["83936.21", "0.066735"], ["83935.42", "0.025188"], ["83935.00", "0.003485"], ["83933.00", "0.009170"], ["83932.99", "0.022860"], ["83931.00", "0.024132"], ["83929.00", "0.063505"], ["83927.00", "0.167119"], ["83925.00", "0.439788"], ["83923.01", "0.608935"], ["83923.00", "1.157337"], ["83921.00", "3.045488"], ["83919.00", "8.014442"], ["83918.00", "0.134670"], ["83917.35", "0"], ["83914.90", "0.017850"], ["83913.60", "0.269760"], ["83911.50", "0.470580"], ["83910.70", "0.535950"], ["83910.40", "0"], ["83910.00", "0.002956"], ["83909.90", "0"], ["83905.59", "0.009224"], ["83905.57", "0.006768"], ["83901.38", "0"], ["83901.35", "0"], ["83877.00", "4.083529"], ["83868.60", "5.353960"], ["83860.20", "4.809489"], ["83851.80", "4.355764"], ["83843.40", "5.172470"], ["83835.00", "5.444705"], ["83826.60", "4.446509"], ["83818.20", "4.900235"], ["83801.40", "3.992784"], ["83793.00", "5.263215"], ["83776.20", "4.990980"], ["83767.80", "5.535450"], ["83759.40", "4.174274"], ["83751.00", "4.718744"], ["83742.60", "4.537254"], ["83734.20", "3.902039"], ["83725.80", "5.626195"], ["83717.40", "5.081725"], ["83641.38", "0"], ["83641.00", "0"], ["83640.35", "0"], ["83640.15", "0"]], "checksum": 1800062811, "ts": "1742556578143"}], "ts": 1742556578147}}
{"exchange": "BYBIT", "timestamp": 1742556578.338816, "message": {"topic": "orderbook.200.BTCUSDT", "ts": 1742556578320, "type": "delta", "data": {"s": "BTCUSDT", "b": [], "a": [["83965.6", "0.38684"], ["83990", "0.035738"], ["84003.1", "2.256638"], ["84017.3", "0"], ["84031.8", "0"]], "u": 26704, "seq": 67550553048}, "cts": 1742556578314}}
{"exchange": "BITGET", "timestamp": 1742556578.379319, "message": {"action": "update", "arg": {"instType": "SPOT", "channel": "books", "instId": "BTCUSDT"}, "data": [{"asks": [["84001.00", "0.347710"], ["84003.00", "0.915027"], ["84003.10", "0.002310"], ["84003.70", "0"], ["84005.20", "0.415020"], ["84005.69", "0.214544"], ["84006.20", "0.434190"], ["84006.60", "0.074220"], ["84009.80", "2.359170"], ["84011.70", "0.156000"], ["84045.00", "4.355764"], ["84053.40", "4.174274"], ["84061.80", "4.900235"], ["84070.20", "5.626195"], ["84078.60", "4.718744"], ["84087.00", "4.627999"], ["84103.80", "3.992784"], ["84112.20", "3.902039"], ["84120.60", "4.537254"], ["84129.00", "4.265019"], ["84137.40", "5.444705"], ["84145.80", "5.081725"], ["84154.20", "4.446509"], ["84162.60", "4.809489"], ["84171.00", "5.263215"], ["84179.40", "5.535450"], ["84187.80", "5.353960"], ["84196.20", "4.083529"], ["84204.60", "5.172470"], ["84523.48", "0"], ["84523.81", "0"]], "bids": [["83923.01", "0.733849"], ["83877.00", "3.992784"], ["83868.60", "4.446509"], ["83860.20", "5.353960"], ["83843.40", "4.990980"], ["83835.00", "4.718744"], ["83826.60", "5.626195"], ["83818.20", "4.627999"], ["83809.80", "5.081725"], ["83801.40", "5.535450"], ["83793.00", "4.265019"], ["83784.60", "5.263215"], ["83776.20", "4.537254"], ["83767.80", "4.900235"], ["83759.40", "5.444705"], ["83751.00", "4.174274"], ["83742.60", "3.902039"], ["83734.20", "4.809489"], ["83725.80", "4.083529"], ["83717.40", "5.172470"]], "checksum": 1800062811, "ts": "1742556578349"}], "ts": 1742556578352}}
{"exchange": "BYBIT", "timestamp": 1742556578.539594, "message": {"topic": "orderbook.200.BTCUSDT", "ts": 1742556578520, "type": "delta", "data": {"s": "BTCUSDT", "b": [["83965.5", "0.515345"], ["83947.3", "0.496196"], ["83941.7", "0.532546"], ["83932.6", "0"], ["83923.9", "0"], ["83914.4", "3.309275"], ["83890", "0"]], "a": [["83969.7", "0.071488"], ["83971.5", "0.030279"], ["83973.7", "0"], ["83979.2", "0.146324"], ["83979.6", "0"], ["83982.7", "0.048"], ["83986.8", "0.005942"], ["83996.9", "0.486726"], ["83999", "0.520883"], ["84000.6", "0"], ["84000.8", "0.012743"], ["84001.3", "0"], ["84001.5", "0.04"]], "u": 26705, "seq": 67550553126}, "cts": 1742556578514}}
{"exchange": "BITGET", "timestamp": 1742556578.595369, "message": {"action": "update", "arg": {"instType": "SPOT", "channel": "books", "instId": "BTCUSDT"}, "data": [{"asks": [["83945.96", "1.588704"], ["83952.93", "0"], ["83989.00", "0.001186"], ["83991.00", "0.003120"], ["83995.00", "0.021611"], ["83997.00", "0.056871"], ["83999.00", "0.149661"], ["84001.00", "0.393843"], ["84003.00", "1.036429"], ["84004.50", "2.010810"], ["84005.20", "0"], ["84005.70", "0"], ["84006.20", "0"], ["84045.00", "4.627999"], ["84053.40", "4.265019"], ["84061.80", "4.990980"], ["84078.60", "5.353960"], ["84087.00", "4.809489"], ["84095.40", "5.263215"], ["84103.80", "4.718744"], ["84112.20", "5.535450"], ["84120.60", "4.083529"], ["84129.00", "4.900235"], ["84137.40", "3.902039"], ["84154.20", "4.537254"], ["84162.60", "5.172470"], ["84171.00", "4.355764"], ["84179.40", "4.174274"], ["84187.80", "3.992784"], ["84196.20", "5.444705"], ["84204.60", "4.446509"], ["84523.48", "0.000015"], ["84523.81", "0.000024"], ["84524.00", "0.000035"]], "bids": [["83945.95", "0.702312"], ["83945.15", "0"], ["83936.21", "0"], ["83935.42", "0"], ["83935.00", "0.003328"], ["83933.00", "0.008758"], ["83931.00", "0.023047"], ["83929.00", "0.060648"], ["83927.00", "0.159600"], ["83925.00", "0.420001"], ["83923.10", "0.025188"], ["83923.00", "1.105266"], ["83921.00", "2.908595"], ["83919.00", "7.654198"], ["83918.00", "0.155310"], ["83917.40", "0"], ["83916.90", "0.189960"], ["83910.60", "0.017850"], ["83905.55", "0.006915"], ["83901.33", "0"], ["83898.62", "0.005059"], ["83895.00", "0.000924"], ["83894.39", "0"], ["83893.00", "0.000015"], ["83877.00", "4.990980"], ["83868.60", "5.172470"], ["83860.20", "4.265019"], ["83851.80", "4.174274"], ["83843.40", "5.626195"], ["83835.00", "3.992784"], ["83826.60", "5.444705"], ["83818.20", "4.718744"], ["83809.80", "4.809489"], ["83801.40", "4.355764"], ["83793.00", "3.902039"], ["83784.60", "4.083529"], ["83776.20", "4.446509"], ["83767.80", "5.263215"], ["83759.40", "4.627999"], ["83751.00", "5.081725"], ["83742.60", "5.353960"], ["83734.20", "4.537254"], ["83725.80", "5.535450"], ["83717.40", "4.900235"], ["83641.38", "0.000135"], ["83641.00", "0.000082"]], "checksum": 1870823126, "ts": "1742556578551"}], "ts": 1742556578555}}
{"exchange": "BYBIT", "timestamp": 1742556578.73844, "message": {"topic": "orderbook.200.BTCUSDT", "ts": 1742556578720, "type": "delta", "data": {"s": "BTCUSDT", "b": [["83964.5", "0"], ["83949.5", "0.204495"], ["83932.8", "0.023633"], ["83924", "0"], ["83904.4", "12.57841"], ["83901.5", "0"], ["83890.5", "0"], ["83890", "0.0002"], ["83889.9", "0.011992"], ["83889.8", "0.001333"]], "a": [["83983.7", "0.127167"]], "u": 26706, "seq": 67550553161}, "cts": 1742556578696}}
{"exchange": "BITGET", "timestamp": 1742556578.785563, "message": {"action": "update", "arg": {"instType": "SPOT", "channel": "books", "instId": "BTCUSDT"}, "data": [{"asks": [["83987.00", "0.001200"], ["83989.00", "0.003157"], ["83990.45", "0.010000"], ["83991.00", "0.008309"], ["83995.00", "0.057541"], ["83997.00", "0.151424"], ["83999.00", "0.398485"], ["84001.00", "1.048644"], ["84003.00", "2.759719"], ["84003.30", "0.057750"], ["84003.40", "2.687640"], ["84003.70", "0.261840"], ["84004.50", "0"], ["84007.80", "2.359230"], ["84008.40", "0.838020"], ["84009.30", "0"], ["84009.80", "0"], ["84045.00", "3.902039"], ["84061.80", "4.355764"], ["84070.20", "5.263215"], ["84078.60", "4.174274"], ["84087.00", "5.626195"], ["84095.40", "4.446509"], ["84103.80", "4.537254"], ["84112.20", "4.718744"], ["84120.60", "5.535450"], ["84129.00", "5.081725"], ["84137.40", "4.900235"], ["84145.80", "3.992784"], ["84154.20", "4.627999"], ["84162.60", "4.083529"], ["84171.00", "4.990980"], ["84179.40", "5.444705"], ["84187.80", "5.353960"], ["84196.20", "5.172470"], ["84204.60", "4.809489"], ["84524.00", "0"]], "bids": [["83945.95", "0.750164"], ["83937.00", "0.001245"], ["83935.00", "0.003277"], ["83933.00", "0.008622"], ["83931.00", "0.022690"], ["83929.00", "0.059711"], ["83927.00", "0.157134"], ["83925.00", "0.413510"], ["83923.01", "0.800584"], ["83923.00", "1.088184"], ["83921.00", "2.863642"], ["83919.00", "7.535902"], ["83913.60", "0"], ["83868.60", "4.809489"], ["83860.20", "4.083529"], ["83851.80", "5.263215"], ["83835.00", "5.353960"], ["83818.20", "4.537254"], ["83809.80", "4.900235"], ["83801.40", "3.992784"], ["83793.00", "5.535450"], ["83784.60", "4.446509"], ["83776.20", "5.172470"], ["83767.80", "4.265019"], ["83759.40", "3.902039"], ["83751.00", "4.355764"], ["83742.60", "4.718744"], ["83734.20", "5.081725"], ["83725.80", "4.627999"], ["83717.40", "4.174274"], ["83640.35", "0.000022"]], "checksum": -1769870464, "ts": "1742556578754"}], "ts": 1742556578757}}
{"exchange": "BYBIT", "timestamp": 1742556578.937669, "message": {"topic": "orderbook.200.BTCUSDT", "ts": 1742556578919, "type": "delta", "data": {"s": "BTCUSDT", "b": [["83925.5", "0.013516"], ["83925.3", "0"], ["83889.5", "0.003181"]], "a": [], "u": 26707, "seq": 67550553164}, "cts": 1742556578894}}
{"exchange": "BITGET", "timestamp": 1742556578.990383, "message": {"action": "update", "arg": {"instType": "SPOT", "channel": "books", "instId": "BTCUSDT"}, "data": [{"asks": [["83997.00", "0.151297"], ["83999.00", "0.398152"], ["84001.00", "1.047767"], ["84003.00", "2.757283"], ["84003.30", "0.057960"], ["84003.40", "2.687850"], ["84003.70", "0.262050"], ["84008.40", "1.429980"], ["84010.70", "0.714900"], ["84011.60", "0.714900"], ["84012.40", "0.714900"], ["84013.30", "1.736700"], ["84045.00", "5.081725"], ["84053.40", "5.263215"], ["84061.80", "4.900235"], ["84070.20", "4.990980"], ["84078.60", "5.353960"], ["84087.00", "5.444705"], ["84095.40", "4.174274"], ["84112.20", "4.355764"], ["84120.60", "3.902039"], ["84129.00", "4.809489"], ["84137.40", "4.446509"], ["84145.80", "4.265019"], ["84154.20", "3.992784"], ["84162.60", "4.718744"], ["84171.00", "5.626195"], ["84179.40", "5.172470"], ["84187.80", "5.535450"], ["84196.20", "4.083529"], ["84204.60", "4.627999"], ["84523.08", "0"], ["84523.48", "0"], ["84523.81", "0"]], "bids": [["83925.00", "0.413301"], ["83923.00", "1.087634"], ["83921.00", "2.862193"], ["83919.00", "7.532089"], ["83905.68", "0.007316"], ["83901.47", "0"], ["83898.59", "0.008104"], ["83894.36", "0"], ["83882.74", "0.007445"], ["83879.96", "0.008584"], ["83878.52", "0"], ["83877.00", "5.263215"], ["83875.74", "0"], ["83868.60", "4.718744"], ["83860.20", "4.446509"], ["83851.80", "5.081725"], ["83843.40", "4.990980"], ["83835.00", "4.083529"], ["83818.20", "4.174274"], ["83809.80", "4.265019"], ["83801.40", "4.355764"], ["83793.00", "5.626195"], ["83784.60", "5.353960"], ["83776.20", "4.627999"], ["83767.80", "3.992784"], ["83759.40", "4.809489"], ["83751.00", "5.172470"], ["83742.60", "4.900235"], ["83734.20", "4.537254"], ["83725.80", "5.535450"], ["83717.40", "3.902039"]], "checksum": -1769870464, "ts": "1742556578962"}], "ts": 1742556578964}}
{"exchange": "BYBIT", "timestamp": 1742556579.137606, "message": {"topic": "orderbook.200.BTCUSDT", "ts": 1742556579119, "type": "delta", "data": {"s": "BTCUSDT", "b": [["83914.5", "1.000689"], ["83889.5", "0"]], "a": [], "u": 26708, "seq": 67550553171}, "cts": 1742556579097}}
{"exchange": "BITGET", "timestamp": 1742556579.215065, "message": {"action": "update", "arg": {"instType": "SPOT", "channel": "books", "instId": "BTCUSDT"}, "data": [{"asks": [["83945.96", "1.588333"], ["84008.40", "0.838020"], ["84010.70", "0"], ["84011.60", "0"], ["84012.40", "0"], ["84013.30", "1.021800"], ["84014.80", "1.055730"], ["84045.00", "4.900235"], ["84053.40", "4.265019"], ["84061.80", "5.444705"], ["84070.20", "4.083529"], ["84078.60", "5.263215"], ["84087.00", "4.537254"], ["84095.40", "3.992784"], ["84103.80", "4.355764"], ["84112.20", "5.353960"], ["84120.60", "4.627999"], ["84129.00", "5.172470"], ["84137.40", "5.081725"], ["84145.80", "4.446509"], ["84154.20", "3.902039"], ["84162.60", "5.535450"], ["84171.00", "4.174274"], ["84179.40", "4.990980"], ["84187.80", "4.809489"], ["84196.20", "5.626195"], ["84204.60", "4.718744"], ["84523.08", "0.000015"], ["84523.48", "0.000015"]], "bids": [["83877.00", "4.174274"], ["83868.60", "3.902039"], ["83860.20", "4.627999"], ["83851.80", "4.446509"], ["83843.40", "5.353960"], ["83835.00", "5.626195"], ["83826.60", "4.537254"], ["83818.20", "4.355764"], ["83809.80", "5.081725"], ["83801.40", "3.992784"], ["83793.00", "5.263215"], ["83784.60", "4.718744"], ["83776.20", "4.809489"], ["83767.80", "5.444705"], ["83759.40", "4.083529"], ["83751.00", "5.535450"], ["83742.60", "5.172470"], ["83734.20", "4.900235"], ["83725.80", "4.265019"], ["83717.40", "4.990980"]], "checksum": 108982329, "ts": "1742556579163"}], "ts": 1742556579167}}
{"exchange": "BYBIT", "timestamp": 1742556579.337149, "message": {"topic": "orderbook.200.BTCUSDT", "ts": 1742556579319, "type": "delta", "data": {"s": "BTCUSDT", "b": [["83904.4", "0"], ["83901.5", "12.57841"]], "a": [], "u": 26709, "seq": 67550553180}, "cts": 1742556579259}}
{"exchange": "BITGET", "timestamp": 1742556579.40949, "message": {"action": "update", "arg": {"instType": "SPOT", "channel": "books", "instId": "BTCUSDT"}, "data": [{"asks": [["84000.99", "0.541623"], ["84028.01", "0"], ["84045.00", "4.174274"], ["84053.40", "4.355764"], ["84061.80", "4.718744"], ["84070.20", "4.627999"], ["84078.60", "5.535450"], ["84087.00", "5.263215"], ["84095.40", "4.265019"], ["84103.80", "3.992784"], ["84112.20", "4.083529"], ["84120.60", "4.809489"], ["84129.00", "4.446509"], ["84137.40", "5.626195"], ["84145.80", "5.444705"], ["84154.20", "5.081725"], ["84162.60", "4.900235"], ["84171.00", "3.902039"], ["84179.40", "5.172470"], ["84187.80", "5.353960"], ["84196.20", "4.537254"], ["84204.60", "4.990980"], ["84523.81", "0.000024"]], "bids": [["83894.00", "0.000017"], ["83893.00", "0.000032"], ["83877.00", "4.355764"], ["83868.60", "3.992784"], ["83860.20", "5.172470"], ["83851.80", "5.353960"], ["83843.40", "4.900235"], ["83835.00", "5.535450"], ["83826.60", "5.263215"], ["83818.20", "4.809489"], ["83809.80", "5.444705"], ["83801.40", "3.902039"], ["83793.00", "4.990980"], ["83784.60", "5.081725"], ["83776.20", "4.265019"], ["83767.80", "4.627999"], ["83759.40", "4.446509"], ["83751.00", "4.718744"], ["83742.60", "5.626195"], ["83734.20", "4.537254"], ["83725.80", "4.174274"], ["83717.40", "4.083529"]], "checksum": 108982329, "ts": "1742556579377"}], "ts": 1742556579381}}
{"exchange": "BYBIT", "timestamp": 1742556579.539271, "message": {"topic": "orderbook.200.BTCUSDT", "ts": 1742556579520, "type": "delta", "data": {"s": "BTCUSDT", "b": [["83956.1", "0.0062"], ["83955.2", "0"], ["83927.4", "0.060999"], ["83926.5", "0"], ["83904.4", "12.57841"], ["83901.5", "0"], ["83889.5", "0.003181"]], "a": [], "u": 26710, "seq": 67550553215}, "cts": 1742556579509}}
{"exchange": "BITGET", "timestamp": 1742556579.629691, "message": {"action": "update", "arg": {"instType": "SPOT", "channel": "books", "instId": "BTCUSDT"}, "data": [{"asks": [["84003.40", "1.614750"], ["84005.69", "0"], ["84007.20", "0.006030"], ["84007.80", "0"], ["84008.40", "1.501110"], ["84009.10", "0.341460"], ["84009.60", "2.359170"], ["84013.80", "0.180000"], ["84015.90", "0.120000"], ["84045.00", "5.353960"], ["84053.40", "4.718744"], ["84061.80", "5.444705"], ["84070.20", "4.355764"], ["84078.60", "3.902039"], ["84087.00", "5.081725"], ["84095.40", "4.446509"], ["84103.80", "5.535450"], ["84112.20", "4.809489"], ["84120.60", "4.537254"], ["84129.00", "4.900235"], ["84137.40", "4.627999"], ["84145.80", "4.990980"], ["84154.20", "4.174274"], ["84162.60", "4.083529"], ["84171.00", "5.263215"], ["84179.40", "3.992784"], ["84187.80", "5.626195"], ["84196.20", "5.172470"], ["84204.60", "4.265019"]], "bids": [["83941.75", "0.010000"], ["83921.00", "2.862024"], ["83919.00", "7.531642"], ["83914.80", "0"], ["83910.60", "0.553800"], ["83894.32", "0"], ["83877.00", "4.265019"], ["83868.60", "4.718744"], ["83860.20", "4.627999"], ["83851.80", "4.446509"], ["83835.00", "4.990980"], ["83826.60", "5.444705"], ["83818.20", "4.355764"], ["83809.80", "5.353960"], ["83801.40", "4.174274"], ["83793.00", "5.626195"], ["83784.60", "4.537254"], ["83776.20", "4.809489"], ["83767.80", "5.172470"], ["83759.40", "5.263215"], ["83751.00", "4.083529"], ["83742.60", "3.992784"], ["83734.20", "5.081725"], ["83725.80", "5.535450"], ["83717.40", "3.902039"], ["83640.15", "0.000423"]], "checksum": 1613973594, "ts": "1742556579593"}], "ts": 1742556579598}}
{"exchange": "BYBIT", "timestamp": 1742556579.738645, "message": {"topic": "orderbook.200.BTCUSDT", "ts": 1742556579719, "type": "delta", "data": {"s": "BTCUSDT", "b": [["83953.2", "0.113593"], ["83945.3", "0.238862"], ["83942.7", "0.164003"], ["83935.7", "0.308445"], ["83889.5", "0"]], "a": [["83965.6", "0.299305"], ["83976.2", "0.024937"], ["83977.7", "0.119762"], ["83988.2", "0.170914"], ["83994", "0"], ["83995.2", "0.30605"], ["84000.2", "0.763762"], ["84002.1", "0"], ["84003.1", "0"], ["84004.9", "0.093491"], ["84017.3", "2.256638"], ["84031.1", "0"]], "u": 26711, "seq": 67550553348}, "cts": 1742556579717}}
{"exchange": "BITGET", "timestamp": 1742556579.824176, "message": {"action": "update", "arg": {"instType": "SPOT", "channel": "books", "instId": "BTCUSDT"}, "data": [{"asks": [["83975.48", "0"], ["83977.09", "0.012472"], ["83987.00", "0.001091"], ["83989.00", "0.002485"], ["83991.00", "0.006539"], ["83995.00", "0.045286"], ["83997.00", "0.119175"], ["83999.00", "0.313618"], ["84001.00", "0.825309"], ["84003.00", "2.171866"], ["84003.40", "0.222540"], ["84006.60", "0.074430"], ["84014.10", "0"], ["84045.00", "4.718744"], ["84053.40", "4.083529"], ["84061.80", "5.535450"], ["84070.20", "5.263215"], ["84078.60", "4.355764"], ["84087.00", "5.626195"], ["84095.40", "4.627999"], ["84103.80", "4.809489"], ["84112.20", "4.900235"], ["84120.60", "5.444705"], ["84129.00", "4.174274"], ["84137.40", "5.353960"], ["84145.80", "4.446509"], ["84154.20", "3.992784"], ["84162.60", "4.537254"], ["84171.00", "3.902039"], ["84179.40", "4.265019"], ["84187.80", "5.172470"], ["84196.20", "5.081725"], ["84204.60", "4.990980"], ["84524.00", "0.000035"]], "bids": [["83898.56", "0.008277"], ["83877.00", "5.263215"], ["83868.60", "5.444705"], ["83860.20", "3.902039"], ["83851.80", "4.627999"], ["83843.40", "4.083529"], ["83835.00", "5.626195"], ["83826.60", "4.355764"], ["83818.20", "5.535450"], ["83801.40", "4.446509"], ["83793.00", "4.990980"], ["83784.60", "4.174274"], ["83776.20", "4.537254"], ["83759.40", "3.992784"], ["83751.00", "4.718744"], ["83742.60", "4.900235"], ["83734.20", "4.265019"], ["83725.80", "4.809489"], ["83717.40", "5.081725"], ["83640.15", "0"]], "checksum": 1613973594, "ts": "1742556579796"}], "ts": 1742556579798}}
{"exchange": "BYBIT", "timestamp": 1742556579.936641, "message": {"topic": "orderbook.200.BTCUSDT", "ts": 1742556579919, "type": "delta", "data": {"s": "BTCUSDT", "b": [["83953.2", "0.000516"], ["83942.8", "0.118804"], ["83942.7", "0"], ["83935.7", "0.003181"]], "a": [["83965.6", "0.3136"], ["83965.8", "0.071492"], ["83965.9", "0"], ["83966.1", "0"], ["83977.7", "0"], ["83988.2", "0"], ["83990", "0"], ["83990.1", "0.035737"], ["83995.2", "0"], ["84000.2", "0.093558"], ["84031.1", "0.025312"], ["84031.8", "0.000516"], ["84032.2", "0.00325"], ["84032.5", "0.001466"], ["84032.6", "0.001333"]], "u": 26712, "seq": 67550553460}, "cts": 1742556579913}}
{"exchange": "BITGET", "timestamp": 1742556580.037332, "message": {"action": "update", "arg": {"instType": "SPOT", "channel": "books", "instId": "BTCUSDT"}, "data": [{"asks": [["83995.00", "0.045284"], ["83997.00", "0.119168"], ["83999.00", "0.313601"], ["84001.00", "0.825267"], ["84003.00", "2.171755"], ["84003.30", "0.001033"], ["84005.50", "0.495750"], ["84009.50", "0"], ["84015.90", "0"], ["84045.00", "4.083529"], ["84053.40", "3.992784"], ["84061.80", "4.809489"], ["84078.60", "5.353960"], ["84087.00", "4.174274"], ["84095.40", "5.444705"], ["84103.80", "4.265019"], ["84112.20", "5.535450"], ["84120.60", "4.990980"], ["84129.00", "4.355764"], ["84137.40", "4.627999"], ["84145.80", "4.537254"], ["84154.20", "3.902039"], ["84162.60", "4.718744"], ["84171.00", "5.626195"], ["84179.40", "4.446509"], ["84187.80", "5.081725"], ["84196.20", "5.172470"], ["84204.60", "4.900235"], ["84524.83", "0.000009"]], "bids": [["83935.00", "0.003455"], ["83933.00", "0.009092"], ["83931.00", "0.023928"], ["83929.00", "0.062968"], ["83927.00", "0.165935"], ["83925.00", "0.436671"], ["83923.00", "1.149134"], ["83921.00", "3.024037"], ["83919.00", "7.957991"], ["83877.00", "4.718744"], ["83868.60", "5.081725"], ["83860.20", "4.265019"], ["83851.80", "5.444705"], ["83843.40", "5.626195"], ["83835.00", "4.537254"], ["83826.60", "5.263215"], ["83818.20", "5.172470"], ["83809.80", "4.900235"], ["83801.40", "5.353960"], ["83784.60", "4.355764"], ["83776.20", "4.083529"], ["83767.80", "5.535450"], ["83751.00", "4.446509"], ["83742.60", "4.174274"], ["83734.20", "3.902039"], ["83725.80", "4.627999"], ["83717.40", "4.809489"]], "checksum": -1261294148, "ts": "1742556580006"}], "ts": 1742556580009}}
{"exchange": "BYBIT", "timestamp": 1742556580.138508, "message": {"topic": "orderbook.200.BTCUSDT", "ts": 1742556580120, "type": "delta", "data": {"s": "BTCUSDT", "b": [["83964.2", "0.003"]], "a": [["84003.1", "2.256638"], ["84017.3", "0"]], "u": 26713, "seq": 67550553521}, "cts": 1742556580111}}
{"exchange": "BITGET", "timestamp": 1742556580.251092, "message": {"action": "update", "arg": {"instType": "SPOT", "channel": "books", "instId": "BTCUSDT"}, "data": [{"asks": [["84003.40", "1.342440"], ["84005.60", "0.969600"], ["84006.60", "0.074220"], ["84008.40", "0.838020"], ["84009.50", "0.071580"], ["84015.10", "0.144780"], ["84045.00", "4.355764"], ["84053.40", "4.990980"], ["84070.20", "3.902039"], ["84078.60", "3.992784"], ["84087.00", "4.537254"], ["84095.40", "4.083529"], ["84103.80", "5.444705"], ["84112.20", "5.353960"], ["84120.60", "5.263215"], ["84129.00", "5.172470"], ["84145.80", "5.081725"], ["84154.20", "4.265019"], ["84162.60", "4.174274"], ["84171.00", "4.718744"], ["84179.40", "4.900235"], ["84187.80", "5.626195"], ["84196.20", "4.446509"], ["84204.60", "5.535450"], ["84523.81", "0"], ["84524.00", "0"], ["84524.83", "0"]], "bids": [["83895.00", "0.000939"], ["83877.00", "4.900235"], ["83868.60", "5.263215"], ["83860.20", "3.902039"], ["83851.80", "4.537254"], ["83843.40", "5.172470"], ["83835.00", "4.265019"], ["83826.60", "5.626195"], ["83818.20", "4.083529"], ["83809.80", "4.446509"], ["83801.40", "4.627999"], ["83793.00", "3.992784"], ["83776.20", "5.353960"], ["83767.80", "4.174274"], ["83759.40", "4.809489"], ["83751.00", "5.444705"], ["83742.60", "5.535450"], ["83734.20", "4.990980"], ["83725.80", "5.081725"], ["83717.40", "4.718744"]], "checksum": -1261294148, "ts": "1742556580211"}], "ts": 1742556580214}}
{"exchange": "BYBIT", "timestamp": 1742556580.337721, "message": {"topic": "orderbook.200.BTCUSDT", "ts": 1742556580320, "type": "delta", "data": {"s": "BTCUSDT", "b": [["83917.9", "0.125051"], ["83904.4", "0"], ["83901.5", "12.577979"], ["83889.8", "0"]], "a": [], "u": 26714, "seq": 67550553552}, "cts": 1742556580315}}
{"exchange": "BITGET", "timestamp": 1742556580.445213, "message": {"action": "update", "arg": {"instType": "SPOT", "channel": "books", "instId": "BTCUSDT"}, "data": [{"asks": [["83996.99", "0.130431"], ["84003.40", "0.634290"], ["84007.00", "0.022620"], ["84008.40", "1.501290"], ["84009.10", "0.318780"], ["84014.80", "0"], ["84015.10", "0"], ["84045.00", "4.265019"], ["84053.40", "3.992784"], ["84061.80", "5.263215"], ["84063.08", "0"], ["84063.79", "0.125802"], ["84070.20", "4.900235"], ["84078.60", "4.627999"], ["84087.00", "4.355764"], ["84095.40", "5.353960"], ["84103.80", "4.809489"], ["84112.20", "4.990980"], ["84120.60", "5.626195"], ["84129.00", "5.444705"], ["84137.40", "5.081725"], ["84145.80", "4.083529"], ["84154.20", "5.535450"], ["84162.60", "4.718744"], ["84171.00", "3.902039"], ["84179.40", "5.172470"], ["84187.80", "4.174274"], ["84196.20", "4.537254"], ["84204.60", "4.446509"]], "bids": [["83933.00", "0.008983"], ["83931.00", "0.023639"], ["83929.00", "0.062208"], ["83927.00", "0.163705"], ["83925.00", "0.430803"], ["83923.00", "1.133693"], ["83921.00", "2.983240"], ["83919.00", "7.850632"], ["83914.80", "0.015000"], ["83910.60", "0.017850"], ["83894.00", "0"], ["83877.00", "4.265019"], ["83868.60", "5.535450"], ["83860.20", "4.809489"], ["83851.80", "4.627999"], ["83843.40", "5.263215"], ["83835.00", "3.992784"], ["83826.60", "4.446509"], ["83818.20", "4.174274"], ["83809.80", "5.626195"], ["83801.40", "4.718744"], ["83793.00", "4.083529"], ["83784.60", "5.444705"], ["83776.20", "5.081725"], ["83767.80", "4.900235"], ["83759.40", "5.353960"], ["83751.00", "3.902039"], ["83742.60", "4.990980"], ["83734.20", "5.172470"], ["83725.80", "4.355764"], ["83717.40", "4.537254"]], "checksum": 1327568977, "ts": "1742556580412"}], "ts": 1742556580415}}
{"exchange": "BYBIT", "timestamp": 1742556580.536947, "message": {"topic": "orderbook.200.BTCUSDT", "ts": 1742556580520, "type": "delta", "data": {"s": "BTCUSDT", "b": [["83965.5", "0.515414"], ["83925.5", "0.000516"], ["83925.3", "0.012882"], ["83889.9", "0"]], "a": [["83965.6", "0.315386"], ["84000.7", "0.023819"], ["84000.9", "0.012743"], ["84001.4", "0"], ["84001.6", "0.063819"]], "u": 26715, "seq": 67550553583}, "cts": 1742556580517}}
{"exchange": "BITGET", "timestamp": 1742556580.6643, "message": {"action": "update", "arg": {"instType": "SPOT", "channel": "books", "instId": "BTCUSDT"}, "data": [{"asks": [["83989.00", "0.001575"], ["83991.00", "0.004145"], ["83995.00", "0.028702"], ["83997.00", "0.075533"], ["83999.00", "0.198771"], ["84000.99", "0"], ["84001.00", "0.523082"], ["84003.00", "1.376716"], ["84003.40", "0"], ["84003.70", "0.262680"], ["84005.40", "0.555030"], ["84014.80", "1.055730"], ["84028.01", "0.062760"], ["84045.00", "4.446509"], ["84053.40", "5.353960"], ["84061.80", "4.537254"], ["84070.20", "4.174274"], ["84078.60", "4.900235"], ["84087.00", "4.809489"], ["84095.40", "3.902039"], ["84103.80", "4.990980"], ["84112.20", "4.083529"], ["84120.60", "4.265019"], ["84129.00", "5.626195"], ["84137.40", "5.444705"], ["84145.80", "5.535450"], ["84154.20", "4.627999"], ["84162.60", "5.172470"], ["84171.00", "4.355764"], ["84179.40", "5.263215"], ["84187.80", "4.718744"], ["84196.20", "3.992784"], ["84204.60", "5.081725"], ["84523.48", "0"]], "bids": [["83933.00", "0.009103"], ["83931.00", "0.023957"], ["83929.00", "0.063043"], ["83927.00", "0.165904"], ["83925.00", "0.436589"], ["83923.00", "1.148919"], ["83921.00", "3.023472"], ["83919.00", "7.956503"], ["83877.00", "5.626195"], ["83868.60", "5.081725"], ["83860.20", "4.537254"], ["83851.80", "3.992784"], ["83843.40", "4.446509"], ["83835.00", "5.263215"], ["83826.60", "5.444705"], ["83818.20", "4.265019"], ["83809.80", "4.355764"], ["83793.00", "3.902039"], ["83784.60", "5.353960"], ["83776.20", "4.627999"], ["83767.80", "5.535450"], ["83759.40", "5.172470"], ["83751.00", "4.809489"], ["83742.60", "4.083529"], ["83734.20", "4.900235"], ["83725.80", "4.174274"], ["83717.40", "4.990980"]], "checksum": 2139975409, "ts": "1742556580635"}], "ts": 1742556580638}}
{"exchange": "BYBIT", "timestamp": 1742556580.737451, "message": {"topic": "orderbook.200.BTCUSDT", "ts": 1742556580720, "type": "delta", "data": {"s": "BTCUSDT", "b": [["83901.5", "12.577696"]], "a": [], "u": 26716, "seq": 67550553612}, "cts": 1742556580681}}
{"exchange": "BITGET", "timestamp": 1742556580.88279, "message": {"action": "update", "arg": {"instType": "SPOT", "channel": "books", "instId": "BTCUSDT"}, "data": [{"asks": [["83945.96", "1.168333"], ["83989.00", "0.002357"], ["83991.00", "0.006202"], ["83995.00", "0.042949"], ["83996.99", "0"], ["83997.00", "0.113022"], ["83999.00", "0.297427"], ["84001.00", "0.782704"], ["84003.00", "2.059745"], ["84005.40", "0.555240"], ["84008.00", "0.067800"], ["84009.50", "0.072450"], ["84045.00", "5.263215"], ["84053.39", "0.478863"], ["84053.40", "5.535450"], ["84061.80", "5.444705"], ["84070.20", "4.537254"], ["84078.60", "4.446509"], ["84087.00", "3.992784"], ["84095.40", "5.081725"], ["84103.80", "5.626195"], ["84112.20", "4.355764"], ["84120.60", "3.902039"], ["84129.00", "4.627999"], ["84137.40", "4.809489"], ["84145.80", "4.718744"], ["84154.20", "4.083529"], ["84171.00", "4.174274"], ["84179.40", "4.265019"], ["84187.80", "4.990980"], ["84196.20", "4.900235"], ["84204.60", "5.353960"]], "bids": [["83936.21", "0.073748"], ["83935.00", "0.003325"], ["83933.00", "0.008751"], ["83931.00", "0.023028"], ["83929.00", "0.060599"], ["83927.00", "0.159471"], ["83925.00", "0.419661"], ["83923.00", "1.104372"], ["83921.00", "2.906241"], ["83919.00", "7.648004"], ["83877.00", "4.446509"], ["83868.60", "5.626195"], ["83860.20", "5.081725"], ["83851.80", "4.990980"], ["83843.40", "5.353960"], ["83835.00", "5.444705"], ["83826.60", "4.627999"], ["83818.20", "4.537254"], ["83809.80", "5.263215"], ["83801.40", "4.809489"], ["83793.00", "4.265019"], ["83784.60", "3.902039"], ["83776.20", "4.174274"], ["83759.40", "3.992784"], ["83751.00", "4.900235"], ["83742.60", "5.172470"], ["83734.20", "4.718744"], ["83725.80", "4.083529"], ["83717.40", "4.355764"], ["83640.35", "0"]], "checksum": 1628382456, "ts": "1742556580847"}], "ts": 1742556580850}}
{"exchange": "BYBIT", "timestamp": 1742556580.937024, "message": {"topic": "orderbook.200.BTCUSDT", "ts": 1742556580919, "type": "delta", "data": {"s": "BTCUSDT", "b": [["83965.5", "0.513631"], ["83932.8", "0.036497"]], "a": [["84000.2", "0.744727"], ["84000.4", "0.012743"], ["84000.5", "0.012743"], ["84000.8", "0"], ["84000.9", "0"], ["84001.1", "0.04"], ["84001.2", "0.04"], ["84001.5", "0"], ["84001.6", "0.023819"], ["84032.6", "0"]], "u": 26717, "seq": 67550553688}, "cts": 1742556580906}}
{"exchange": "BITGET", "timestamp": 1742556581.105902, "message": {"action": "update", "arg": {"instType": "SPOT", "channel": "books", "instId": "BTCUSDT"}, "data": [{"asks": [["83966.33", "0"], ["83966.69", "0.035952"], ["83966.76", "0"], ["83967.11", "0.119870"], ["83968.02", "0"], ["83968.38", "0.035961"], ["83968.45", "0"], ["83968.62", "0"], ["83968.81", "0.006356"], ["83968.93", "0"], ["83968.97", "0.006356"], ["83969.29", "0.006356"], ["83970.02", "0"], ["83970.27", "0"], ["83970.38", "0.010984"], ["83970.44", "0"], ["83970.63", "0.006356"], ["83970.80", "0.006356"], ["83970.94", "0"], ["83971.30", "0.022785"], ["83971.44", "0"], ["83971.45", "0"], ["83971.78", "0"], ["83971.80", "0.006356"], ["83971.81", "0.006356"], ["83971.96", "0"], ["83971.98", "0"], ["83972.14", "0.119883"], ["83972.15", "0.016429"], ["83972.31", "0.006356"], ["83972.32", "0.006356"], ["83973.48", "0"], ["83973.84", "0.017342"], ["83974.32", "0"], ["83974.68", "0.009990"], ["83975.21", "0"], ["83975.57", "0.119850"], ["83976.21", "0"], ["83976.40", "0"], ["83976.57", "0.119858"], ["83976.63", "0"], ["83976.75", "0.119867"], ["83976.99", "0.015895"], ["83980.58", "0"], ["83981.45", "0"], ["83981.81", "0.010988"], ["83989.00", "0.002075"], ["83990.45", "0"], ["83991.00", "0.005459"], ["83995.00", "0.037803"], ["83997.00", "0.099482"], ["83999.00", "0.261794"], ["84001.00", "0.688932"], ["84003.00", "1.812979"], ["84003.70", "0.001011"], ["84006.60", "0.074430"], ["84007.80", "0.218130"], ["84045.00", "4.627999"], ["84053.40", "4.083529"], ["84061.80", "5.535450"], ["84070.20", "5.626195"], ["84078.60", "4.355764"], ["84087.00", "5.353960"], ["84095.40", "4.446509"], ["84103.80", "4.900235"], ["84112.20", "4.718744"], ["84129.00", "5.263215"], ["84137.40", "4.990980"], ["84145.80", "4.537254"], ["84154.20", "5.172470"], ["84162.60", "5.444705"], ["84171.00", "4.265019"], ["84179.40", "3.992784"], ["84187.80", "4.809489"], ["84196.20", "4.174274"], ["84204.60", "5.081725"], ["84523.48", "0.000015"]], "bids": [["83926.40", "0.089610"], ["83926.04", "0"], ["83925.98", "0.272898"], ["83925.62", "0"], ["83924.73", "0.084057"], ["83924.37", "0"], ["83924.31", "0.017842"], ["83924.14", "0.018280"], ["83923.96", "0"], ["83923.79", "0.005954"], ["83923.43", "0"], ["83923.00", "1.104181"], ["83922.70", "0.055734"], ["83922.45", "0.017127"], ["83922.34", "0"], ["83922.28", "0.007141"], ["83922.09", "0"], ["83921.92", "0"], ["83921.78", "0.028905"], ["83921.77", "0.007350"], ["83921.42", "0"], ["83921.41", "0"], ["83921.27", "0.016961"], ["83921.00", "2.905740"], ["83920.95", "0.025220"], ["83920.93", "0.225197"], ["83920.91", "0"], ["83920.77", "0.025571"], ["83920.59", "0"], ["83920.58", "0"], ["83920.43", "0"], ["83920.41", "0"], ["83919.27", "0.064709"], ["83919.00", "7.646683"], ["83918.91", "0"], ["83918.44", "0.018543"], ["83918.08", "0"], ["83917.48", "0.268752"], ["83917.12", "0"], ["83916.47", "0.222981"], ["83916.31", "0.260159"], ["83916.11", "0"], ["83916.05", "0.076219"], ["83915.95", "0"], ["83915.69", "0"], ["83912.10", "0.073317"], ["83911.74", "0"], ["83911.29", "0.056446"], ["83910.93", "0"], ["83909.63", "0.000878"], ["83909.25", "0"], ["83895.00", "0.000956"], ["83893.00", "0.000017"], ["83877.00", "5.535450"], ["83868.60", "5.444705"], ["83860.20", "4.718744"], ["83851.80", "4.627999"], ["83843.40", "4.355764"], ["83835.00", "3.902039"], ["83826.60", "5.081725"], ["83818.20", "4.446509"], ["83809.80", "5.626195"], ["83801.40", "4.537254"], ["83793.00", "4.900235"], ["83784.60", "4.174274"], ["83776.20", "4.809489"], ["83767.80", "5.172470"], ["83759.40", "4.083529"], ["83751.00", "4.990980"], ["83742.60", "5.263215"], ["83734.20", "5.353960"], ["83725.80", "4.265019"], ["83717.40", "3.992784"], ["83640.35", "0.000022"], ["83640.15", "0.000423"]], "checksum": -301624329, "ts": "1742556581069"}], "ts": 1742556581073}}
{"exchange": "BYBIT", "timestamp": 1742556581.137389, "message": {"topic": "orderbook.200.BTCUSDT", "ts": 1742556581119, "type": "delta", "data": {"s": "BTCUSDT", "b": [], "a": [["83965.6", "0.3136"]], "u": 26718, "seq": 67550553709}, "cts": 1742556581116}}
{"exchange": "BITGET", "timestamp": 1742556581.360369, "message": {"action": "update", "arg": {"instType": "SPOT", "channel": "books", "instId": "BTCUSDT"}, "data": [{"asks": [["83966.31", "0"], ["84013.50", "0.045990"], ["84045.00", "3.992784"], ["84053.40", "5.444705"], ["84061.80", "4.990980"], ["84070.20", "4.809489"], ["84078.60", "4.627999"], ["84087.00", "3.902039"], ["84087.41", "0"], ["84095.40", "5.535450"], ["84103.80", "5.172470"], ["84112.20", "4.083529"], ["84120.60", "4.174274"], ["84129.00", "5.081725"], ["84137.40", "5.263215"], ["84145.80", "4.446509"], ["84154.20", "5.353960"], ["84162.60", "4.265019"], ["84171.00", "4.537254"], ["84179.40", "4.718744"], ["84187.80", "4.355764"], ["84196.20", "5.626195"], ["84204.60", "4.900235"], ["84523.81", "0.000024"]], "bids": [["83929.63", "0"], ["83929.00", "0.060813"], ["83927.00", "0.160033"], ["83925.00", "0.421140"], ["83923.00", "1.108264"], ["83921.00", "2.916483"], ["83919.00", "7.674955"], ["83916.90", "0.045000"], ["83910.60", "0.553800"], ["83877.00", "4.446509"], ["83873.10", "0"], ["83868.60", "4.537254"], ["83860.20", "5.535450"], ["83851.80", "5.081725"], ["83843.40", "5.444705"], ["83835.00", "4.265019"], ["83826.60", "5.353960"], ["83818.20", "5.263215"], ["83809.80", "5.172470"], ["83801.40", "4.355764"], ["83784.60", "5.626195"], ["83776.20", "4.627999"], ["83767.80", "4.718744"], ["83759.40", "4.174274"], ["83742.60", "4.083529"], ["83734.20", "3.902039"], ["83725.80", "3.992784"], ["83717.40", "4.809489"], ["83640.00", "0.002013"], ["83639.71", "0.000041"]], "checksum": -1368286077, "ts": "1742556581272"}], "ts": 1742556581275}}
{"exchange": "BYBIT", "timestamp": 1742556581.360551, "message": {"topic": "orderbook.200.BTCUSDT", "ts": 1742556581320, "type": "delta", "data": {"s": "BTCUSDT", "b": [["83942.8", "0"], ["83889.9", "0.011992"]], "a": [["83965.6", "0.317529"], ["84008.5", "0"], ["84032.6", "0.001333"]], "u": 26719, "seq": 67550553744}, "cts": 1742556581316}}
{"exchange": "BITGET", "timestamp": 1742556581.518599, "message": {"action": "update", "arg": {"instType": "SPOT", "channel": "books", "instId": "BTCUSDT"}, "data": [{"asks": [["83989.00", "0.002465"], ["83991.00", "0.006486"], ["83995.00", "0.044918"], ["83997.00", "0.118206"], ["83999.00", "0.311068"], ["84000.99", "0.552409"], ["84001.00", "0.818602"], ["84003.00", "2.154215"], ["84004.00", "0.413220"], ["84005.40", "0.554820"], ["84005.50", "0"], ["84014.80", "0"], ["84045.00", "5.626195"], ["84053.39", "0"], ["84061.80", "4.627999"], ["84070.20", "3.992784"], ["84078.60", "3.902039"], ["84087.00", "5.353960"], ["84095.40", "4.174274"], ["84103.80", "5.263215"], ["84112.20", "4.537254"], ["84120.60", "4.718744"], ["84129.00", "4.083529"], ["84137.40", "5.535450"], ["84145.80", "5.172470"], ["84154.20", "4.265019"], ["84162.60", "4.900235"], ["84171.00", "4.446509"], ["84179.40", "4.990980"], ["84196.20", "5.081725"], ["84204.60", "4.809489"], ["84524.00", "0.000035"]], "bids": [["83877.00", "4.900235"], ["83868.60", "5.626195"], ["83860.20", "4.627999"], ["83851.80", "3.902039"], ["83843.40", "5.535450"], ["83835.00", "4.174274"], ["83818.20", "4.265019"], ["83809.80", "5.263215"], ["83801.40", "4.990980"], ["83793.00", "4.083529"], ["83784.60", "5.444705"], ["83776.20", "5.081725"], ["83759.40", "5.172470"], ["83751.00", "4.809489"], ["83742.60", "4.537254"], ["83734.20", "4.446509"], ["83717.40", "4.355764"]], "checksum": -1368286077, "ts": "1742556581478"}], "ts": 1742556581485}}
{"exchange": "BYBIT", "timestamp": 1742556581.619352, "message": {"topic": "orderbook.200.BTCUSDT", "ts": 1742556581520, "type": "delta", "data": {"s": "BTCUSDT", "b": [["83965.5", "0.286413"], ["83965.4", "0.001333"], ["83901.5", "0"], ["83889.8", "0.001333"]], "a": [["83965.6", "0.488517"]], "u": 26720, "seq": 67550553788}, "cts": 1742556581517}}
{"exchange": "BYBIT", "timestamp": 1742556581.693137, "message": {"success": true, "ret_msg": "pong", "conn_id": "d59011eb-c49f-46ad-9bdd-f698ff66c36b", "op": "ping"}}
{"exchange": "BITGET", "timestamp": 1742556581.767393, "message": {"action": "update", "arg": {"instType": "SPOT", "channel": "books", "instId": "BTCUSDT"}, "data": [{"asks": [["83985.00", "0.001237"], ["83987.00", "0.003254"], ["83989.00", "0.008564"], ["83991.00", "0.022538"], ["83995.00", "0.156076"], ["83997.00", "0.410834"], ["83999.00", "1.081142"], ["84001.00", "2.845111"], ["84003.00", "7.487132"], ["84004.00", "0"], ["84005.40", "0.789330"], ["84005.60", "0"], ["84006.90", "0.303210"], ["84007.00", "2.382060"], ["84007.80", "0"], ["84008.50", "0.062340"], ["84009.60", "0"], ["84011.40", "1.350000"], ["84014.80", "1.055730"], ["84015.90", "0.120000"], ["84016.00", "0.510000"], ["84045.00", "4.446509"], ["84053.40", "5.263215"], ["84061.80", "4.083529"], ["84070.20", "4.627999"], ["84078.60", "4.990980"], ["84087.00", "4.809489"], ["84095.40", "5.353960"], ["84103.80", "5.535450"], ["84112.20", "3.902039"], ["84120.60", "5.172470"], ["84129.00", "4.355764"], ["84137.40", "4.174274"], ["84145.80", "4.265019"], ["84154.20", "5.626195"], ["84162.60", "5.081725"], ["84171.00", "4.537254"], ["84179.40", "4.900235"], ["84187.80", "3.992784"], ["84196.20", "4.718744"], ["84204.60", "5.444705"]], "bids": [["83945.95", "0.269942"], ["83942.52", "0.047852"], ["83941.75", "0"], ["83937.00", "0.001123"], ["83936.21", "0"], ["83935.00", "0.002623"], ["83933.00", "0.006903"], ["83932.99", "0"], ["83931.00", "0.018165"], ["83929.00", "0.047803"], ["83927.00", "0.125797"], ["83925.00", "0.331045"], ["83923.10", "0"], ["83923.00", "0.871171"], ["83922.60", "0.022860"], ["83921.00", "2.292555"], ["83919.00", "6.033040"], ["83918.90", "1.424130"], ["83918.00", "0.134490"], ["83915.30", "0"], ["83914.90", "0"], ["83914.80", "0.030000"], ["83913.22", "0.025188"], ["83911.80", "0"], ["83910.70", "0"], ["83910.40", "0.012660"], ["83910.00", "0.007050"], ["83909.90", "0.017850"], ["83909.50", "0.021600"], ["83909.00", "0.120000"], ["83893.00", "0"], ["83877.00", "4.083529"], ["83868.60", "5.081725"], ["83860.20", "4.446509"], ["83851.80", "5.626195"], ["83843.40", "4.809489"], ["83835.00", "5.263215"], ["83826.60", "3.902039"], ["83818.20", "4.174274"], ["83809.80", "3.992784"], ["83801.40", "4.265019"], ["83793.00", "5.353960"], ["83784.60", "4.537254"], ["83776.20", "4.718744"], ["83767.80", "4.990980"], ["83751.00", "4.355764"], ["83742.60", "5.535450"], ["83734.20", "4.900235"], ["83725.80", "5.444705"], ["83717.40", "4.627999"], ["83639.70", "0.000010"], ["83639.15", "0.000009"], ["83638.32", "0.000039"]], "checksum": -175687683, "ts": "1742556581696"}], "ts": 1742556581699}}
{"exchange": "BYBIT", "timestamp": 1742556581.767544, "message": {"topic": "orderbook.200.BTCUSDT", "ts": 1742556581720, "type": "delta", "data": {"s": "BTCUSDT", "b": [["83965.5", "0.286652"], ["83964.2", "0"], ["83961.9", "0.000333"], ["83960.2", "0.071496"], ["83947.3", "0"], ["83937", "0.005943"], ["83936.3", "0.496196"], ["83932.7", "0.118804"], ["83925.4", "0"], ["83925.3", "0"], ["83925.2", "0.012882"], ["83925.1", "0.012882"], ["83901.5", "12.582856"], ["83889.9", "0"], ["83889.8", "0"]], "a": [["83965.7", "0.070302"], ["83976.2", "0.203559"], ["83986", "0.537968"], ["83986.4", "0.090432"], ["83988", "0.51955"], ["83990.7", "0.003576"], ["83996.9", "0"], ["83999", "0.001333"], ["84032.5", "0"], ["84032.6", "0"]], "u": 26721, "seq": 67550553865}, "cts": 1742556581711}}
{"exchange": "BYBIT", "timestamp": 1742556581.947513, "message": {"topic": "orderbook.200.BTCUSDT", "ts": 1742556581920, "type": "delta", "data": {"s": "BTCUSDT", "b": [["83965.5", "0.457652"], ["83960.3", "0.000153"], ["83949.5", "0.061348"], ["83941.8", "0.118804"], ["83937.1", "0"], ["83936.8", "0.293905"], ["83890", "0"]], "a": [["83965.6", "0.317517"], ["83965.7", "0"], ["83970.1", "0.080385"], ["83974.8", "0.023831"], ["83983.7", "0.310407"], ["83986.4", "0.001333"], ["83987.9", "0.231421"], ["84000.4", "0"], ["84000.5", "0"], ["84000.6", "0.012743"], ["84000.7", "0.036562"], ["84001.1", "0"], ["84001.2", "0"], ["84001.3", "0.04"], ["84001.4", "0.04"], ["84032.5", "0.001466"]], "u": 26722, "seq": 67550553944}, "cts": 1742556581917}}
{"exchange": "BITGET", "timestamp": 1742556581.947565, "message": {"action": "update", "arg": {"instType": "SPOT", "channel": "books", "instId": "BTCUSDT"}, "data": [{"asks": [["83945.96", "1.588333"], ["83976.82", "0"], ["83977.14", "0.009989"], ["83980.92", "0.015892"], ["83987.00", "0.003052"], ["83989.00", "0.008031"], ["83991.00", "0.021135"], ["83995.00", "0.146364"], ["83997.00", "0.385169"], ["83999.00", "1.013601"], ["84001.00", "2.667371"], ["84001.44", "0"], ["84002.05", "0.001598"], ["84003.00", "7.019398"], ["84003.30", "0.059460"], ["84003.36", "0"], ["84003.70", "0"], ["84003.97", "0.001597"], ["84007.00", "2.381850"], ["84008.40", "0.838020"], ["84010.40", "0"], ["84010.80", "0.045600"], ["84013.50", "0"], ["84015.90", "0.125970"], ["84045.00", "4.900235"], ["84061.80", "5.081725"], ["84078.60", "4.174274"], ["84095.40", "4.083529"], ["84103.80", "3.992784"], ["84112.20", "4.446509"], ["84120.60", "4.990980"], ["84129.00", "5.353960"], ["84137.40", "4.537254"], ["84154.20", "3.902039"], ["84162.60", "5.626195"], ["84171.00", "4.718744"], ["84179.40", "4.355764"], ["84187.80", "5.444705"], ["84196.20", "5.172470"], ["84204.60", "5.535450"], ["84524.83", "0.000009"]], "bids": [["83945.95", "0.479142"], ["83943.78", "0.047852"], ["83942.52", "0"], ["83937.00", "0.001002"], ["83927.00", "0.125931"], ["83925.00", "0.331396"], ["83923.69", "0.004023"], ["83923.46", "0"], ["83923.00", "0.872095"], ["83921.00", "2.294986"], ["83919.00", "6.039439"], ["83915.86", "0.021159"], ["83915.54", "0"], ["83911.50", "0"], ["83908.80", "0.535950"], ["83894.00", "0.000015"], ["83891.91", "0.001177"], ["83891.31", "0"], ["83891.11", "0.003602"], ["83890.78", "0"], ["83889.97", "0.001174"], ["83889.36", "0"], ["83877.00", "3.992784"], ["83868.60", "4.990980"], ["83860.20", "5.172470"], ["83851.80", "4.174274"], ["83843.40", "4.355764"], ["83835.00", "5.626195"], ["83826.60", "4.265019"], ["83818.20", "5.081725"], ["83809.80", "4.446509"], ["83801.40", "5.535450"], ["83793.00", "4.809489"], ["83784.60", "5.353960"], ["83776.20", "4.537254"], ["83767.80", "4.718744"], ["83759.40", "4.900235"], ["83751.00", "4.083529"], ["83742.60", "4.627999"], ["83734.20", "3.902039"], ["83725.80", "5.263215"], ["83717.40", "5.444705"], ["83638.32", "0"]], "checksum": 1577994978, "ts": "1742556581899"}], "ts": 1742556581902}}
{"exchange": "BYBIT", "timestamp": 1742556582.136567, "message": {"topic": "orderbook.200.BTCUSDT", "ts": 1742556582119, "type": "delta", "data": {"s": "BTCUSDT", "b": [["83965.4", "0.02433"], ["83960.3", "0"], ["83946.2", "0.007143"], ["83890", "0.0002"]], "a": [["83965.6", "0.315731"], ["84000.6", "0"], ["84000.8", "0.012743"], ["84001.3", "0"], ["84001.5", "0.04"]], "u": 26723, "seq": 67550554034}, "cts": 1742556582116}}
{"exchange": "BITGET", "timestamp": 1742556582.140468, "message": {"action": "update", "arg": {"instType": "SPOT", "channel": "books", "instId": "BTCUSDT"}, "data": [{"asks": [["83985.00", "0.001022"], ["83987.00", "0.002863"], ["83989.00", "0.007533"], ["83991.00", "0.019824"], ["83995.00", "0.137285"], ["83997.00", "0.361276"], ["83999.00", "0.950725"], ["84001.00", "2.501910"], ["84003.00", "6.583972"], ["84003.30", "0.001045"], ["84005.60", "0.459600"], ["84007.00", "0.022620"], ["84007.30", "2.359230"], ["84011.40", "0"], ["84015.90", "0.005970"], ["84016.00", "0"], ["84045.00", "4.174274"], ["84053.40", "5.626195"], ["84061.80", "4.627999"], ["84070.20", "3.902039"], ["84078.60", "5.263215"], ["84087.00", "5.535450"], ["84095.40", "4.537254"], ["84103.80", "5.081725"], ["84112.20", "5.444705"], ["84120.60", "4.265019"], ["84129.00", "4.355764"], ["84137.40", "4.446509"], ["84145.80", "5.172470"], ["84154.20", "4.718744"], ["84162.60", "5.353960"], ["84171.00", "4.900235"], ["84179.40", "3.992784"], ["84187.80", "4.809489"], ["84196.20", "4.083529"], ["84204.60", "4.990980"]], "bids": [["83945.95", "0.499142"], ["83945.94", "0.047852"], ["83943.78", "0"], ["83937.00", "0.001136"], ["83935.00", "0.002727"], ["83933.00", "0.007175"], ["83931.00", "0.018882"], ["83929.00", "0.049691"], ["83927.00", "0.130764"], ["83925.00", "0.344116"], ["83923.00", "0.905569"], ["83921.00", "2.383075"], ["83919.00", "6.271250"], ["83918.90", "1.178010"], ["83914.90", "0.017850"], ["83910.70", "0.535950"], ["83909.00", "0.000032"], ["83908.80", "0"], ["83877.00", "4.174274"], ["83868.60", "4.265019"], ["83860.20", "5.081725"], ["83851.80", "3.992784"], ["83843.40", "4.990980"], ["83835.00", "5.353960"], ["83826.60", "4.355764"], ["83818.20", "4.809489"], ["83809.80", "4.627999"], ["83801.40", "4.537254"], ["83793.00", "4.083529"], ["83784.60", "5.172470"], ["83776.20", "4.900235"], ["83767.80", "5.535450"], ["83759.40", "5.626195"], ["83751.00", "4.446509"], ["83742.60", "5.263215"], ["83725.80", "4.718744"], ["83639.15", "0"]], "checksum": -473538408, "ts": "1742556582104"}], "ts": 1742556582111}}
{"exchange": "BYBIT", "timestamp": 1742556582.337366, "message": {"topic": "orderbook.200.BTCUSDT", "ts": 1742556582320, "type": "delta", "data": {"s": "BTCUSDT", "b": [["83965.5", "0.286652"]], "a": [["83965.6", "0.486731"]], "u": 26724, "seq": 67550554062}, "cts": 1742556582280}}
{"exchange": "BITGET", "timestamp": 1742556582.339122, "message": {"action": "update", "arg": {"instType": "SPOT", "channel": "books", "instId": "BTCUSDT"}, "data": [{"asks": [["83991.00", "0.019626"], ["83995.00", "0.135913"], ["83997.00", "0.357667"], ["83999.00", "0.941228"], ["84001.00", "2.476917"], ["84003.00", "6.518203"], ["84011.40", "1.350000"], ["84015.90", "0"], ["84045.00", "4.718744"], ["84053.40", "5.263215"], ["84070.20", "5.535450"], ["84078.60", "4.083529"], ["84087.00", "4.174274"], ["84095.40", "4.990980"], ["84103.80", "5.626195"], ["84112.20", "4.809489"], ["84145.80", "5.444705"], ["84154.20", "5.172470"], ["84162.60", "3.992784"], ["84179.40", "5.081725"], ["84187.80", "5.353960"], ["84196.20", "3.902039"], ["84204.60", "4.537254"]], "bids": [["83915.00", "0.071460"], ["83914.80", "0.015000"], ["83909.70", "0"], ["83909.50", "0"], ["83894.00", "0.000032"], ["83881.20", "0.202932"], ["83880.30", "0"], ["83877.00", "3.902039"], ["83868.60", "3.992784"], ["83860.20", "5.263215"], ["83851.80", "4.265019"], ["83843.40", "4.537254"], ["83835.00", "4.446509"], ["83826.60", "4.174274"], ["83818.20", "5.081725"], ["83809.80", "4.083529"], ["83801.40", "5.626195"], ["83793.00", "5.353960"], ["83784.60", "4.627999"], ["83776.20", "4.809489"], ["83759.40", "4.355764"], ["83751.00", "5.444705"], ["83742.60", "4.718744"], ["83734.20", "4.900235"], ["83725.80", "4.990980"], ["83717.40", "5.172470"], ["83639.15", "0.000009"], ["83638.32", "0.000039"]], "checksum": -473538408, "ts": "1742556582310"}], "ts": 1742556582313}}
{"exchange": "BYBIT", "timestamp": 1742556582.662798, "message": {"topic": "orderbook.200.BTCUSDT", "ts": 1742556582519, "type": "delta", "data": {"s": "BTCUSDT", "b": [["83965.4", "0.001333"], ["83957.5", "0.000153"], ["83920.2", "0.135593"], ["83917.4", "0"], ["83890", "0"]], "a": [["83965.6", "0.488517"]], "u": 26725, "seq": 67550554132}, "cts": 1742556582516}}
{"exchange": "BITGET", "timestamp": 1742556582.662962, "message": {"action": "update", "arg": {"instType": "SPOT", "channel": "books", "instId": "BTCUSDT"}, "data": [{"asks": [["83996.99", "0.390269"], ["83999.00", "0.941360"], ["84001.00", "2.477263"], ["84003.00", "6.519114"], ["84015.90", "0.005970"], ["84028.01", "0"], ["84045.00", "4.174274"], ["84053.40", "4.627999"], ["84061.80", "5.081725"], ["84070.20", "4.718744"], ["84078.60", "4.265019"], ["84087.00", "5.353960"], ["84095.40", "4.083529"], ["84103.80", "4.809489"], ["84112.20", "4.900235"], ["84120.60", "5.535450"], ["84129.00", "3.902039"], ["84137.40", "4.355764"], ["84145.80", "4.446509"], ["84162.60", "4.537254"], ["84171.00", "4.990980"], ["84179.40", "3.992784"], ["84187.80", "5.263215"], ["84196.20", "5.444705"], ["84204.60", "5.626195"], ["84524.83", "0"]], "bids": [["83945.94", "0"], ["83944.07", "0.047852"], ["83919.00", "6.271139"], ["83915.00", "0.000032"], ["83909.50", "0.021600"], ["83868.60", "5.535450"], ["83860.20", "5.626195"], ["83851.80", "5.263215"], ["83843.40", "4.990980"], ["83826.60", "4.900235"], ["83818.20", "3.992784"], ["83809.80", "5.081725"], ["83801.40", "4.809489"], ["83784.60", "4.265019"], ["83776.20", "5.172470"], ["83767.80", "4.174274"], ["83759.40", "5.444705"], ["83751.00", "4.627999"], ["83742.60", "4.355764"], ["83734.20", "4.083529"], ["83725.80", "4.718744"], ["83717.40", "4.537254"], ["83638.32", "0"]], "checksum": 2084422981, "ts": "1742556582544"}], "ts": 1742556582547}}
{"exchange": "BYBIT", "timestamp": 1742556582.808818, "message": {"topic": "orderbook.200.BTCUSDT", "ts": 1742556582720, "type": "delta", "data": {"s": "BTCUSDT", "b": [["83965.5", "0.178387"], ["83965.3", "0"], ["83964.4", "0.071493"], ["83962.1", "0"], ["83960.2", "0"], ["83959.2", "0.027081"], ["83957.8", "0.047911"], ["83955.2", "0.0715"], ["83941.8", "0"], ["83939", "0"], ["83931.8", "0.001333"], ["83925.2", "0"], ["83925.1", "0"], ["83924.9", "0.012882"], ["83924.8", "0.012882"], ["83901.5", "0"], ["83896", "0.235392"], ["83895.9", "12.584332"], ["83895.1", "0"], ["83890", "0.0002"], ["83889.9", "0.011992"], ["83889.8", "0.001333"]], "a": [["83965.6", "0.486374"], ["83965.7", "0.076552"], ["83968.4", "0.089099"], ["83969.5", "0.023833"], ["83974.8", "0"], ["83974.9", "0.089099"], ["83986.5", "0.089099"], ["84000.7", "0.023819"], ["84000.8", "0"], ["84000.9", "0.013"], ["84001", "0.012743"], ["84001.4", "0"], ["84001.5", "0"], ["84001.6", "0.063819"], ["84001.7", "0.04"], ["84014.6", "0.001786"], ["84031", "0"], ["84031.1", "0"], ["84031.8", "0"], ["84032.2", "0"], ["84032.5", "0"]], "u": 26726, "seq": 67550554238}, "cts": 1742556582702}}
{"exchange": "BITGET", "timestamp": 1742556582.808967, "message": {"action": "update", "arg": {"instType": "SPOT", "channel": "books", "instId": "BTCUSDT"}, "data": [{"asks": [["83985.00", "0.001341"], ["83987.00", "0.003530"], ["83989.00", "0.009289"], ["83991.00", "0.024445"], ["83993.00", "0.064329"], ["83995.00", "0.169286"], ["83997.00", "0.445490"], ["83999.00", "1.172343"], ["84000.99", "0"], ["84001.00", "3.085111"], ["84003.00", "8.118714"], ["84005.30", "2.359500"], ["84006.90", "0.303000"], ["84007.30", "0"], ["84015.90", "0.125970"], ["84016.00", "0.510000"], ["84028.01", "0.062760"], ["84045.00", "4.627999"], ["84053.40", "4.809489"], ["84061.80", "4.355764"], ["84070.20", "3.902039"], ["84078.60", "4.083529"], ["84095.40", "4.537254"], ["84103.80", "5.172470"], ["84120.60", "5.263215"], ["84129.00", "5.081725"], ["84137.40", "4.174274"], ["84145.80", "5.444705"], ["84154.20", "5.626195"], ["84162.60", "4.446509"], ["84187.80", "5.535450"], ["84196.20", "4.718744"], ["84204.60", "4.265019"], ["84524.00", "0"]], "bids": [["83945.95", "0.289942"], ["83944.07", "0"], ["83940.69", "0.047852"], ["83935.00", "0.001747"], ["83933.00", "0.004595"], ["83931.78", "0"], ["83931.00", "0.012092"], ["83929.00", "0.031823"], ["83927.00", "0.083744"], ["83925.00", "0.220378"], ["83923.00", "0.579942"], ["83921.00", "1.526165"], ["83919.00", "4.016224"], ["83918.00", "0.134700"], ["83917.00", "0.117690"], ["83915.10", "0.065010"], ["83914.90", "0"], ["83911.00", "0.009000"], ["83910.70", "0"], ["83910.60", "0.153580"], ["83909.90", "0"], ["83909.00", "0.120000"], ["83908.60", "0.240000"], ["83908.20", "0.600000"], ["83895.00", "0.000941"], ["83860.20", "4.990980"], ["83851.80", "4.627999"], ["83843.40", "4.446509"], ["83835.00", "3.992784"], ["83826.60", "4.083529"], ["83818.20", "4.355764"], ["83801.40", "5.263215"], ["83793.00", "4.809489"], ["83784.60", "4.174274"], ["83776.20", "5.353960"], ["83767.80", "5.626195"], ["83751.00", "4.265019"], ["83742.60", "4.718744"], ["83734.20", "4.900235"], ["83725.80", "4.537254"], ["83717.40", "5.172470"], ["83638.32", "0.000039"]], "checksum": -726615418, "ts": "1742556582744"}], "ts": 1742556582747}}
{"exchange": "BYBIT", "timestamp": 1742556582.986031, "message": {"topic": "orderbook.200.BTCUSDT", "ts": 1742556582919, "type": "delta", "data": {"s": "BTCUSDT", "b": [["83965.5", "0.007148"], ["83964.4", "0"], ["83959.2", "0.001779"], ["83958.2", "0"], ["83957.8", "0.000516"], ["83957.5", "0"], ["83957.1", "0.057954"], ["83957", "0.073036"], ["83955.2", "0"], ["83953.3", "0.040153"], ["83953", "0.071502"], ["83941.7", "0"], ["83936.2", "0.178645"], ["83932.7", "0"], ["83928.6", "0.648463"], ["83921.2", "0.067233"], ["83920.2", "0.135607"], ["83915", "0.001333"], ["83895.9", "0"], ["83893.1", "12.584332"], ["83889.5", "0.003181"], ["83889.4", "0.001466"], ["83889", "0.100315"]], "a": [["83965.6", "0.657374"], ["83969.7", "0"], ["83971.5", "0.04794"], ["83973", "0.071485"], ["83987.8", "0.119799"], ["83990.5", "0.004629"], ["84003.5", "0"]], "u": 26727, "seq": 67550554339}, "cts": 1742556582881}}
{"exchange": "BITGET", "timestamp": 1742556582.986144, "message": {"action": "update", "arg": {"instType": "SPOT", "channel": "books", "instId": "BTCUSDT"}, "data": [{"asks": [["83944.01", "1.379571"], ["83945.01", "0.353345"], ["83945.95", "0.601144"], ["83945.96", "0.332505"], ["83946.00", "0"], ["83982.11", "0"], ["83982.64", "0.010000"], ["83985.00", "0.001634"], ["83987.00", "0.004559"], ["83989.00", "0.011997"], ["83991.00", "0.031570"], ["83993.00", "0.083079"], ["83995.00", "0.218828"], ["83997.00", "0.575862"], ["83999.00", "1.515426"], ["84001.00", "3.987963"], ["84003.00", "10.494641"], ["84005.30", "3.356250"], ["84005.40", "0"], ["84005.60", "0"], ["84006.90", "0.303210"], ["84008.40", "0.883620"], ["84010.80", "0"], ["84013.20", "0.184500"], ["84015.80", "0.269760"], ["84015.90", "0.120000"], ["84016.00", "0.756330"], ["84045.00", "5.535450"], ["84053.39", "0.099380"], ["84053.40", "5.626195"], ["84061.80", "4.174274"], ["84070.20", "4.809489"], ["84087.00", "4.990980"], ["84103.80", "4.265019"], ["84112.20", "4.355764"], ["84120.60", "5.444705"], ["84129.00", "5.263215"], ["84137.40", "3.902039"], ["84145.80", "3.992784"], ["84154.20", "5.172470"], ["84171.00", "4.718744"], ["84179.40", "5.081725"], ["84187.80", "4.900235"], ["84196.20", "5.353960"], ["84204.60", "4.627999"], ["84523.81", "0"]], "bids": [["83945.95", "0"], ["83945.00", "0"], ["83944.00", "0.038026"], ["83942.61", "0"], ["83940.69", "0"], ["83937.00", "0.001014"], ["83935.00", "0.001021"], ["83933.00", "0.001948"], ["83931.00", "0.005126"], ["83929.00", "0.013491"], ["83927.31", "0"], ["83927.00", "0.035501"], ["83925.00", "0.093423"], ["83923.00", "0.245851"], ["83921.00", "0.646976"], ["83919.31", "0.333520"], ["83919.00", "1.702570"], ["83918.90", "0.002280"], ["83918.80", "1.407030"], ["83917.00", "0.000032"], ["83915.80", "0.045600"], ["83915.10", "0"], ["83914.80", "0"], ["83914.00", "0.141240"], ["83912.20", "0.066390"], ["83908.60", "0"], ["83908.20", "0"], ["83895.00", "0.000924"], ["83877.00", "5.353960"], ["83868.60", "4.809489"], ["83860.20", "3.902039"], ["83851.80", "3.992784"], ["83843.40", "4.265019"], ["83835.00", "4.174274"], ["83826.60", "5.172470"], ["83818.20", "5.535450"], ["83809.80", "4.718744"], ["83801.40", "4.990980"], ["83793.00", "4.537254"], ["83784.60", "5.263215"], ["83776.20", "4.627999"], ["83767.80", "4.355764"], ["83759.40", "4.900235"], ["83751.00", "4.083529"], ["83742.60", "5.444705"], ["83734.20", "5.626195"], ["83725.80", "4.446509"], ["83717.40", "5.081725"], ["83638.30", "0.000137"], ["83637.17", "0.000027"], ["83636.36", "0.000179"], ["83635.64", "0.000030"], ["83634.90", "0.519383"]], "checksum": -937200396, "ts": "1742556582947"}], "ts": 1742556582950}}
{"exchange": "BYBIT", "timestamp": 1742556583.160996, "message": {"topic": "orderbook.200.BTCUSDT", "ts": 1742556583119, "type": "delta", "data": {"s": "BTCUSDT", "b": [["83965.5", "0"], ["83965.4", "0"], ["83965", "0"], ["83960.5", "0"], ["83959.1", "0"], ["83958.2", "0.000768"], ["83957.1", "0"], ["83957", "0.001537"], ["83955.1", "0.037815"], ["83955", "0.124585"], ["83954.9", "0"], ["83954.8", "0.01"], ["83953.8", "0.163619"], ["83953", "0.083418"], ["83952.8", "0.001333"], ["83945.9", "0.000623"], ["83945.3", "0.089439"], ["83936.2", "0"], ["83934.1", "0"], ["83926.3", "0.180116"], ["83924.9", "0"], ["83924.8", "0"], ["83924.6", "0.012882"], ["83924.5", "0.012881"], ["83920.2", "0"], ["83917.9", "0"], ["83917.4", "0.135607"], ["83888.8", "0.000445"], ["83888.7", "0.003614"], ["83888.6", "0.000516"], ["83888.3", "0.004037"], ["83887.9", "0.04"], ["83887.8", "0.05"], ["83887.3", "0.027526"]], "a": [["83963.3", "0.707743"], ["83963.4", "0.106918"], ["83965.1", "0.001786"], ["83965.4", "0.166461"], ["83965.5", "0.216042"], ["83965.6", "0.180868"], ["83965.7", "0"], ["83965.8", "0.035729"], ["83968.3", "0.083934"], ["83968.6", "0.071489"], ["83969.2", "0.00329"], ["83969.6", "0.001333"], ["83970.6", "0"], ["83971.5", "0.027689"], ["83972", "0"], ["83973", "0"], ["83973.8", "0.005166"], ["83973.9", "0.01"], ["83974", "0"], ["83976.2", "0.178622"], ["83978.4", "0.048"], ["83983", "0.02009"], ["83985.5", "0.0006"], ["83990.7", "0"], ["84002.1", "0.063449"], ["84003.1", "0"], ["84004.9", "0.030042"], ["84005.2", "1.428081"], ["84007.5", "0.128051"], ["84014.2", "0.171"], ["84020.1", "2.25664"], ["84027.9", "0"], ["84028", "0"], ["84028.4", "0"], ["84028.5", "0"], ["84028.6", "0"], ["84029.1", "0"], ["84030.6", "0"], ["84030.9", "0"]], "u": 26728, "seq": 67550554762}, "cts": 1742556583117}}
{"exchange": "BITGET", "timestamp": 1742556583.308894, "message": {"action": "update", "arg": {"instType": "SPOT", "channel": "books", "instId": "BTCUSDT"}, "data": [{"asks": [["83944.01", "1.691736"], ["83945.00", "0.426609"], ["83945.95", "0.093374"], ["83945.96", "0.211710"], ["83961.12", "0"], ["83970.99", "0"], ["83980.76", "0.175743"], ["83983.00", "0.001211"], ["83985.00", "0.001975"], ["83987.00", "0.005199"], ["83989.00", "0.013681"], ["83991.00", "0.036227"], ["83993.00", "0.095334"], ["83994.15", "0.024502"], ["83995.00", "0.250881"], ["83996.99", "0"], ["83997.00", "0.660211"], ["83999.00", "1.737397"], ["84001.00", "4.572098"], ["84003.00", "12.031838"], ["84005.30", "0.164400"], ["84005.40", "0.045810"], ["84008.40", "0.838020"], ["84015.80", "0"], ["84015.90", "0"], ["84016.00", "0"], ["84028.01", "0"], ["84045.00", "3.902039"], ["84053.39", "0"], ["84053.40", "4.990980"], ["84061.80", "4.537254"], ["84070.20", "4.355764"], ["84087.00", "5.172470"], ["84095.40", "5.353960"], ["84103.80", "5.081725"], ["84112.20", "5.626195"], ["84120.60", "4.265019"], ["84129.00", "4.446509"], ["84137.40", "5.444705"], ["84145.80", "4.809489"], ["84154.20", "3.992784"], ["84162.60", "4.174274"], ["84171.00", "5.535450"], ["84179.40", "4.718744"], ["84196.20", "5.263215"], ["84523.81", "0.000024"], ["84524.00", "0.000035"], ["84524.83", "0.000009"], ["84525.00", "0.000010"]], "bids": [["83940.08", "0.037213"], ["83934.20", "0.010000"], ["83933.00", "0.001005"], ["83931.78", "0.014295"], ["83931.77", "0"], ["83931.00", "0.002192"], ["83929.00", "0.005767"], ["83927.00", "0.015020"], ["83925.00", "0.039527"], ["83923.01", "0.421355"], ["83923.00", "0.104017"], ["83921.00", "0.273729"], ["83919.00", "0.720341"], ["83918.90", "0.001860"], ["83918.80", "0"], ["83918.70", "0"], ["83918.60", "0"], ["83918.00", "0.076980"], ["83916.90", "0.045210"], ["83916.20", "0.045210"], ["83915.90", "0"], ["83915.80", "0"], ["83915.70", "0.240210"], ["83915.20", "0"], ["83914.00", "0.219540"], ["83913.30", "2.359500"], ["83912.90", "0.045990"], ["83909.10", "0.012510"], ["83895.65", "0"], ["83877.00", "4.990980"], ["83868.60", "5.535450"], ["83860.20", "4.355764"], ["83851.80", "4.446509"], ["83843.40", "5.444705"], ["83835.00", "4.083529"], ["83826.60", "5.081725"], ["83818.20", "5.626195"], ["83801.40", "4.265019"], ["83793.00", "4.900235"], ["83784.60", "4.537254"], ["83776.20", "4.809489"], ["83767.80", "5.172470"], ["83759.40", "3.992784"], ["83751.00", "5.353960"], ["83742.60", "5.263215"], ["83734.20", "4.627999"], ["83725.80", "3.902039"], ["83717.40", "4.174274"], ["83634.09", "0.000124"], ["83634.05", "0.000008"]], "checksum": -1854804173, "ts": "1742556583146"}], "ts": 1742556583150}}
{"exchange": "BYBIT", "timestamp": 1742556583.337275, "message": {"topic": "orderbook.200.BTCUSDT", "ts": 1742556583319, "type": "delta", "data": {"s": "BTCUSDT", "b": [["83963.2", "0"], ["83963.1", "0.071494"], ["83962.6", "0.000272"], ["83958.2", "0"], ["83958.1", "0.000768"], ["83954.8", "0"], ["83954.7", "0.01"], ["83945.8", "0.005978"], ["83932.5", "0.118146"], ["83924.6", "0.012881"], ["83921.2", "0"], ["83917.9", "0.125055"], ["83895.9", "12.584332"], ["83893.1", "0"], ["83887.8", "0"], ["83887.3", "0"]], "a": [["83963.2", "0.631947"], ["83963.3", "0.311718"], ["83963.4", "0"], ["83965.1", "0"], ["83965.4", "0"], ["83965.5", "0.045042"], ["83965.6", "0.172875"], ["83965.8", "0"], ["83967.9", "0.001466"], ["83968.2", "0.0017"], ["83968.3", "0.082234"], ["83975", "0.0481"], ["83976.6", "0.04"], ["83980.1", "0.048"], ["83980.8", "0"], ["83981.6", "0.048"], ["83981.8", "0.055242"], ["83982.7", "0"], ["83986", "0.489968"], ["83988", "0.520777"], ["83997.3", "0.04"], ["83997.4", "0.04"], ["84000.2", "0.093558"], ["84001.6", "0.023819"], ["84001.7", "0"], ["84005.1", "1.428081"], ["84005.2", "0"], ["84027.8", "0"]], "u": 26729, "seq": 67550554899}, "cts": 1742556583304}}
{"exchange": "BITGET", "timestamp": 1742556583.486578, "message": {"action": "update", "arg": {"instType": "SPOT", "channel": "books", "instId": "BTCUSDT"}, "data": [{"asks": [["83945.00", "0.106004"], ["83945.95", "0"], ["83950.67", "0.017478"], ["83961.99", "0.014031"], ["83991.00", "0.036010"], ["83993.00", "0.094764"], ["83995.00", "0.249380"], ["83997.00", "0.656261"], ["83999.00", "1.727003"], ["84001.00", "4.544745"], ["84003.00", "11.959856"], ["84009.50", "0.076410"], ["84014.80", "0"], ["84045.00", "5.353960"], ["84053.40", "4.355764"], ["84061.80", "4.446509"], ["84070.20", "4.990980"], ["84078.60", "4.537254"], ["84087.00", "4.265019"], ["84095.40", "5.081725"], ["84103.80", "5.444705"], ["84112.20", "4.627999"], ["84120.60", "5.626195"], ["84129.00", "5.172470"], ["84137.40", "4.083529"], ["84145.80", "4.174274"], ["84154.20", "5.535450"], ["84162.60", "3.902039"], ["84171.00", "3.992784"], ["84187.80", "4.809489"], ["84196.20", "4.900235"], ["84204.60", "5.263215"]], "bids": [["83935.00", "0.001127"], ["83933.00", "0.002967"], ["83931.00", "0.007807"], ["83930.04", "0.111967"], ["83929.00", "0.020732"], ["83927.00", "0.054558"], ["83925.99", "0.203228"], ["83925.00", "0.143363"], ["83923.01", "0.266831"], ["83923.00", "0.377272"], ["83921.00", "0.992821"], ["83919.31", "0.799495"], ["83919.00", "2.612686"], ["83918.00", "0.394170"], ["83917.70", "0.905670"], ["83916.20", "0.045000"], ["83915.70", "0.240000"], ["83915.40", "3.381750"], ["83913.30", "0"], ["83910.60", "0"], ["83909.70", "0.153580"], ["83909.10", "0"], ["83885.20", "0.017478"], ["83881.20", "0"], ["83880.30", "0.202932"], ["83877.00", "4.174274"], ["83868.60", "5.263215"], ["83860.20", "5.172470"], ["83851.80", "5.444705"], ["83843.40", "4.537254"], ["83835.00", "4.900235"], ["83826.60", "3.992784"], ["83818.20", "4.990980"], ["83809.80", "5.353960"], ["83801.40", "5.081725"], ["83793.00", "4.355764"], ["83784.60", "4.718744"], ["83767.80", "3.902039"], ["83759.40", "4.265019"], ["83751.00", "5.535450"], ["83742.60", "4.446509"], ["83734.20", "4.083529"], ["83725.80", "5.626195"], ["83717.40", "4.627999"], ["83634.09", "0"], ["83634.05", "0"]], "checksum": 179803794, "ts": "1742556583347"}], "ts": 1742556583350}}
{"exchange": "BYBIT", "timestamp": 1742556583.667108, "message": {"topic": "orderbook.200.BTCUSDT", "ts": 1742556583520, "type": "delta", "data": {"s": "BTCUSDT", "b": [["83956.1", "0"], ["83955.2", "0.0063"], ["83953", "0.071502"], ["83927.4", "0.059399"], ["83926.5", "0.0016"], ["83924.6", "0"], ["83924.5", "0"], ["83924.3", "0.012881"], ["83924.2", "0.012881"], ["83887.9", "0"]], "a": [["83963.2", "0.651912"], ["83965.5", "0.030042"], ["83965.6", "0.175075"], ["83967.6", "0.003"], ["83976.7", "0.048"], ["83979.3", "0"], ["83981", "0"], ["83984.4", "0"], ["83986.1", "0"], ["83987.3", "0.001043"], ["83988", "0.51955"], ["83997.3", "0"], ["83997.4", "0"], ["83998", "0.099535"], ["83998.1", "0.04"], ["84000.3", "2.286682"], ["84020.1", "0"], ["84027.8", "0.059399"], ["84027.9", "0.001466"], ["84028", "0.00325"]], "u": 26730, "seq": 67550554954}, "cts": 1742556583499}}
{"exchange": "BITGET", "timestamp": 1742556583.667364, "message": {"action": "update", "arg": {"instType": "SPOT", "channel": "books", "instId": "BTCUSDT"}, "data": [{"asks": [["83945.88", "0.093374"], ["83945.95", "0.104024"], ["84045.00", "5.626195"], ["84053.40", "3.992784"], ["84061.80", "5.172470"], ["84070.20", "5.444705"], ["84078.60", "4.174274"], ["84087.00", "5.535450"], ["84095.40", "4.809489"], ["84103.80", "4.627999"], ["84112.20", "4.537254"], ["84120.60", "4.718744"], ["84129.00", "4.355764"], ["84137.40", "4.446509"], ["84145.80", "3.902039"], ["84154.20", "5.263215"], ["84162.60", "4.083529"], ["84171.00", "5.353960"], ["84179.40", "4.990980"], ["84187.80", "4.265019"], ["84196.20", "5.081725"], ["84204.60", "4.900235"], ["84524.83", "0"], ["84525.00", "0"]], "bids": [["83918.60", "0.470250"], ["83918.00", "1.181940"], ["83917.30", "2.359410"], ["83916.90", "0.045000"], ["83915.40", "0.313830"], ["83909.00", "0.000032"], ["83893.00", "0.000032"], ["83868.60", "4.537254"], ["83860.20", "4.809489"], ["83851.80", "4.355764"], ["83843.40", "4.900235"], ["83835.00", "3.902039"], ["83826.60", "5.444705"], ["83818.20", "4.718744"], ["83809.80", "5.535450"], ["83801.40", "4.990980"], ["83793.00", "5.172470"], ["83784.60", "5.263215"], ["83776.20", "4.446509"], ["83767.80", "5.626195"], ["83759.40", "4.083529"], ["83751.00", "5.353960"], ["83742.60", "4.265019"], ["83734.20", "5.081725"], ["83725.80", "4.627999"], ["83717.40", "3.992784"], ["83636.36", "0"], ["83635.64", "0"], ["83634.90", "0"]], "checksum": -1831928165, "ts": "1742556583570"}], "ts": 1742556583575}}
{"exchange": "BYBIT", "timestamp": 1742556583.818534, "message": {"topic": "orderbook.200.BTCUSDT", "ts": 1742556583719, "type": "delta", "data": {"s": "BTCUSDT", "b": [["83963.1", "0.083575"], ["83952.8", "0.001423"], ["83949.5", "0.090425"], ["83947.7", "0.10904"], ["83937.2", "0.182013"], ["83930.2", "0.285239"], ["83888.7", "0"], ["83888.6", "0"], ["83888.3", "0"]], "a": [["83963.2", "0.338608"], ["83963.3", "0.140718"], ["83971.5", "0.060308"], ["83972.2", "0.12027"], ["83974.9", "0.129099"], ["83979.1", "0"], ["83982.7", "0.185023"], ["83987.3", "0"], ["83989.7", "0.281123"], ["84000.2", "0.738445"], ["84028", "0"]], "u": 26731, "seq": 67550554979}, "cts": 1742556583702}}
{"exchange": "BITGET", "timestamp": 1742556583.819074, "message": {"action": "update", "arg": {"instType": "SPOT", "channel": "books", "instId": "BTCUSDT"}, "data": [{"asks": [["83996.99", "0.155678"], ["84045.00", "4.718744"], ["84053.40", "5.535450"], ["84061.80", "4.900235"], ["84070.20", "4.083529"], ["84078.60", "4.627999"], ["84087.00", "4.265019"], ["84095.40", "5.353960"], ["84103.80", "5.081725"], ["84112.20", "3.992784"], ["84120.60", "4.174274"], ["84129.00", "4.446509"], ["84137.40", "3.902039"], ["84145.80", "4.537254"], ["84154.20", "5.626195"], ["84162.60", "4.990980"], ["84171.00", "5.172470"], ["84179.40", "5.444705"], ["84187.80", "4.809489"], ["84196.20", "5.263215"], ["84204.60", "4.355764"], ["84524.00", "0"]], "bids": [["83928.48", "0"], ["83927.00", "0.054350"], ["83925.00", "0.143025"], ["83923.00", "0.376383"], ["83921.00", "0.990481"], ["83919.00", "2.606530"], ["83914.80", "0.015000"], ["83909.50", "0"], ["83877.00", "4.537254"], ["83868.60", "4.083529"], ["83860.20", "3.902039"], ["83851.80", "3.992784"], ["83843.40", "4.265019"], ["83835.00", "5.263215"], ["83826.60", "5.353960"], ["83818.20", "4.627999"], ["83809.80", "4.900235"], ["83801.40", "4.446509"], ["83793.00", "4.809489"], ["83784.60", "4.174274"], ["83776.20", "4.990980"], ["83767.80", "5.444705"], ["83759.40", "4.355764"], ["83751.00", "5.535450"], ["83742.60", "4.718744"], ["83734.20", "5.172470"], ["83725.80", "5.081725"], ["83717.40", "5.626195"], ["83636.36", "0.000179"]], "checksum": -1436109860, "ts": "1742556583778"}], "ts": 1742556583781}}
{"exchange": "BYBIT", "timestamp": 1742556583.995218, "message": {"topic": "orderbook.200.BTCUSDT", "ts": 1742556583920, "type": "delta", "data": {"s": "BTCUSDT", "b": [["83963.1", "0.354575"], ["83953.3", "0.04"], ["83949.5", "0.061348"], ["83947.7", "0"], ["83939", "0.000118"], ["83937.2", "0"], ["83932.8", "0.287085"], ["83930.2", "0"], ["83924.3", "0"], ["83924.2", "0"], ["83924.1", "0.013333"], ["83924", "0.012882"], ["83888.7", "0.003614"], ["83888.6", "0.000516"], ["83888.3", "0.004037"]], "a": [["83963.2", "0.32164"], ["83963.3", "0.078849"], ["83965.5", "0"], ["83968.3", "0.055982"], ["83968.4", "0"], ["83971.5", "0.027689"], ["83971.6", "0.081487"], ["83972.2", "0"], ["83973.9", "0"], ["83974.9", "0.04"], ["83975.6", "0.234658"], ["83982.7", "0"], ["83987.8", "0.000995"], ["83989.7", "0"], ["83997.7", "0.013"], ["83997.8", "0.012743"], ["83998", "0.059535"], ["83998.1", "0"], ["83998.4", "0.04"], ["83998.5", "0.04"], ["84000.9", "0"], ["84001", "0"], ["84028", "0.00325"], ["84028.4", "0.001333"], ["84028.5", "0.0012"], ["84028.6", "0.0006"], ["84029.1", "0.000333"]], "u": 26732, "seq": 67550555075}, "cts": 1742556583906}}
{"exchange": "BITGET", "timestamp": 1742556584.054162, "message": {"action": "update", "arg": {"instType": "SPOT", "channel": "books", "instId": "BTCUSDT"}, "data": [{"asks": [["83945.81", "0.093374"], ["83945.88", "0"], ["83987.00", "0.004941"], ["83989.00", "0.013004"], ["83991.00", "0.034221"], ["83993.00", "0.090054"], ["83995.00", "0.236985"], ["83997.00", "0.623644"], ["83999.00", "1.641169"], ["84001.00", "4.318866"], ["84003.00", "11.365437"], ["84006.40", "0.030210"], ["84006.90", "0.303000"], ["84010.30", "0"], ["84045.00", "5.626195"], ["84053.40", "3.902039"], ["84061.80", "5.172470"], ["84070.20", "5.081725"], ["84078.60", "4.900235"], ["84087.00", "5.263215"], ["84095.40", "4.083529"], ["84103.80", "4.627999"], ["84112.20", "4.990980"], ["84120.60", "4.355764"], ["84137.40", "4.809489"], ["84154.20", "4.265019"], ["84162.60", "4.174274"], ["84171.00", "4.718744"], ["84187.80", "5.535450"], ["84196.20", "5.353960"], ["84204.60", "3.992784"]], "bids": [["83940.08", "0"], ["83935.00", "0.002595"], ["83933.00", "0.006831"], ["83931.00", "0.017976"], ["83929.00", "0.047304"], ["83928.50", "0.006215"], ["83927.00", "0.124485"], ["83925.00", "0.327591"], ["83923.00", "0.862082"], ["83921.00", "2.268637"], ["83919.00", "5.970098"], ["83917.70", "0"], ["83877.00", "4.900235"], ["83868.60", "5.535450"], ["83860.20", "5.172470"], ["83851.80", "5.626195"], ["83843.40", "4.174274"], ["83835.00", "4.355764"], ["83826.60", "4.809489"], ["83818.20", "3.992784"], ["83809.80", "3.902039"], ["83801.40", "4.537254"], ["83793.00", "5.081725"], ["83784.60", "4.718744"], ["83776.20", "5.353960"], ["83767.80", "4.990980"], ["83759.40", "5.263215"], ["83751.00", "4.083529"], ["83742.60", "4.627999"], ["83734.20", "5.444705"], ["83725.80", "4.446509"], ["83717.40", "4.265019"], ["83635.64", "0.000030"]], "checksum": 783890424, "ts": "1742556583978"}], "ts": 1742556583982}}
{"exchange": "BYBIT", "timestamp": 1742556584.14305, "message": {"topic": "orderbook.200.BTCUSDT", "ts": 1742556584119, "type": "delta", "data": {"s": "BTCUSDT", "b": [["83955.9", "0.000153"], ["83936.2", "0.17865"], ["83932.9", "0.118804"], ["83932.8", "0"], ["83895.9", "12.591061"], ["83888.6", "0"], ["83888.3", "0"]], "a": [["83963.2", "0.380558"], ["83963.3", "0.073487"], ["83965.5", "0.052523"], ["83968.3", "0.095429"], ["83969.5", "0"], ["83970.4", "0.17865"], ["83971.5", "0.077822"], ["83974.6", "0.17874"], ["83987.8", "0.119799"], ["83990.2", "0.004893"], ["84029.1", "0"]], "u": 26733, "seq": 67550555108}, "cts": 1742556584107}}
{"exchange": "BITGET", "timestamp": 1742556584.239769, "message": {"action": "update", "arg": {"instType": "SPOT", "channel": "books", "instId": "BTCUSDT"}, "data": [{"asks": [["83995.00", "0.236981"], ["83997.00", "0.623635"], ["83999.00", "1.641145"], ["84001.00", "4.318802"], ["84003.00", "11.365270"], ["84003.30", "0.059010"], ["84006.60", "0.074220"], ["84014.80", "1.055730"], ["84045.00", "4.083529"], ["84053.40", "4.174274"], ["84061.80", "5.353960"], ["84070.20", "4.627999"], ["84078.60", "4.355764"], ["84087.00", "5.081725"], ["84095.40", "5.626195"], ["84103.80", "4.718744"], ["84112.20", "3.992784"], ["84120.60", "5.535450"], ["84129.00", "5.444705"], ["84145.80", "5.263215"], ["84154.20", "4.537254"], ["84162.60", "4.990980"], ["84171.00", "4.265019"], ["84179.40", "3.902039"], ["84187.80", "4.900235"], ["84196.20", "4.446509"], ["84204.60", "5.172470"], ["84523.81", "0"]], "bids": [["83941.59", "0.047852"], ["83935.00", "0.002050"], ["83933.00", "0.005395"], ["83931.00", "0.014199"], ["83929.00", "0.037366"], ["83927.00", "0.098330"], ["83925.00", "0.258764"], ["83923.00", "0.680734"], ["83921.00", "1.791406"], ["83919.00", "4.714226"], ["83918.00", "0.836280"], ["83917.90", "0.058890"], ["83909.50", "0.021600"], ["83877.00", "5.263215"], ["83868.60", "4.718744"], ["83860.20", "3.902039"], ["83851.80", "4.355764"], ["83843.40", "5.535450"], ["83835.00", "5.172470"], ["83826.60", "5.353960"], ["83818.20", "4.446509"], ["83809.80", "4.990980"], ["83801.40", "5.626195"], ["83784.60", "5.444705"], ["83776.20", "4.083529"], ["83767.80", "4.627999"], ["83759.40", "4.265019"], ["83751.00", "3.992784"], ["83742.60", "4.537254"], ["83734.20", "4.900235"], ["83725.80", "4.174274"], ["83717.40", "4.809489"], ["83637.17", "0"], ["83636.36", "0"], ["83635.64", "0"]], "checksum": 534668580, "ts": "1742556584183"}], "ts": 1742556584186}}
{"exchange": "BYBIT", "timestamp": 1742556584.336969, "message": {"topic": "orderbook.200.BTCUSDT", "ts": 1742556584320, "type": "delta", "data": {"s": "BTCUSDT", "b": [["83963.1", "0.282547"], ["83962", "0.071495"], ["83925", "0.013"], ["83924.9", "0.012881"], ["83924.1", "0.000333"], ["83924", "0"], ["83888.8", "0"], ["83888.7", "0"]], "a": [["83963.2", "0.359499"], ["83982.6", "0.003576"], ["83990.2", "0.003757"], ["83996.8", "0.084438"], ["83996.9", "0.012743"], ["83997.5", "0.04"], ["83997.6", "0.04"], ["83997.7", "0"], ["83997.8", "0"], ["83998.4", "0"], ["83998.5", "0"]], "u": 26734, "seq": 67550555153}, "cts": 1742556584303}}
{"exchange": "BITGET", "timestamp": 1742556584.433532, "message": {"action": "update", "arg": {"instType": "SPOT", "channel": "books", "instId": "BTCUSDT"}, "data": [{"asks": [["83944.01", "1.703536"], ["83945.81", "0"], ["84001.00", "4.319001"], ["84003.00", "11.365790"], ["84004.90", "0.022770"], ["84007.00", "0"], ["84015.90", "0.120000"], ["84045.00", "4.627999"], ["84070.20", "4.718744"], ["84078.60", "3.902039"], ["84087.00", "4.355764"], ["84095.40", "4.900235"], ["84103.80", "5.081725"], ["84112.20", "4.446509"], ["84120.60", "5.263215"], ["84129.00", "4.537254"], ["84137.40", "4.990980"], ["84145.80", "5.172470"], ["84154.20", "4.265019"], ["84162.60", "4.083529"], ["84171.00", "5.535450"], ["84179.40", "5.444705"], ["84187.80", "4.809489"], ["84196.20", "5.626195"], ["84204.60", "3.992784"]], "bids": [["83944.00", "0.038009"], ["83935.00", "0.001910"], ["83933.00", "0.005026"], ["83931.00", "0.013227"], ["83929.00", "0.034808"], ["83927.00", "0.091599"], ["83925.00", "0.241052"], ["83923.00", "0.634347"], ["83921.00", "1.669335"], ["83919.00", "4.392985"], ["83894.00", "0.000017"], ["83877.00", "3.992784"], ["83868.60", "4.265019"], ["83860.20", "5.535450"], ["83851.80", "5.172470"], ["83843.40", "4.537254"], ["83835.00", "4.446509"], ["83826.60", "4.718744"], ["83818.20", "4.990980"], ["83809.80", "5.263215"], ["83801.40", "4.355764"], ["83793.00", "4.900235"], ["83784.60", "4.627999"], ["83776.20", "5.081725"], ["83767.80", "5.444705"], ["83759.40", "5.626195"], ["83751.00", "3.902039"], ["83742.60", "5.353960"], ["83734.20", "4.174274"], ["83725.80", "4.809489"], ["83717.40", "4.083529"]], "checksum": 1957617827, "ts": "1742556584396"}], "ts": 1742556584401}}
{"exchange": "BYBIT", "timestamp": 1742556584.58033, "message": {"topic": "orderbook.200.BTCUSDT", "ts": 1742556584520, "type": "delta", "data": {"s": "BTCUSDT", "b": [["83962.6", "0"], ["83925", "0"], ["83924.8", "0.012881"], ["83888.8", "0.000445"]], "a": [["83963.2", "0.373719"], ["83996.8", "0.071438"], ["83996.9", "0"], ["83997.1", "0.189954"], ["83997.2", "0.012743"], ["83997.5", "0"], ["83997.6", "0"], ["83997.8", "0.04"], ["83997.9", "0.04"]], "u": 26735, "seq": 67550555167}, "cts": 1742556584508}}
{"exchange": "BITGET", "timestamp": 1742556584.737636, "message": {"action": "update", "arg": {"instType": "SPOT", "channel": "books", "instId": "BTCUSDT"}, "data": [{"asks": [["83944.01", "1.283536"], ["83945.76", "0.093375"], ["84009.90", "0.714900"], ["84010.70", "0.714900"], ["84011.60", "0.714900"], ["84012.40", "0.714900"], ["84014.80", "0"], ["84015.90", "0"], ["84045.00", "4.718744"], ["84061.80", "5.081725"], ["84070.20", "5.535450"], ["84078.60", "4.627999"], ["84087.00", "4.809489"], ["84095.40", "5.172470"], ["84103.80", "5.263215"], ["84112.20", "4.990980"], ["84120.60", "4.265019"], ["84129.00", "4.355764"], ["84137.40", "5.626195"], ["84145.80", "4.083529"], ["84154.20", "3.992784"], ["84162.60", "3.902039"], ["84171.00", "5.353960"], ["84187.80", "4.537254"], ["84196.20", "4.900235"], ["84204.60", "4.446509"], ["84522.06", "0"], ["84523.08", "0"], ["84523.48", "0"]], "bids": [["83927.00", "0.091492"], ["83925.00", "0.240768"], ["83923.00", "0.633600"], ["83921.00", "1.667179"], ["83919.00", "4.387312"], ["83877.00", "5.353960"], ["83868.60", "5.172470"], ["83860.20", "4.809489"], ["83851.80", "4.627999"], ["83843.40", "3.992784"], ["83835.00", "4.265019"], ["83826.60", "5.535450"], ["83818.20", "5.081725"], ["83809.80", "5.444705"], ["83801.40", "5.626195"], ["83793.00", "4.718744"], ["83784.60", "3.902039"], ["83776.20", "4.355764"], ["83767.80", "4.083529"], ["83759.40", "4.537254"], ["83751.00", "4.990980"], ["83742.60", "4.174274"], ["83734.20", "4.446509"], ["83725.80", "5.263215"], ["83717.40", "4.900235"]], "checksum": -1143785489, "ts": "1742556584605"}], "ts": 1742556584608}}
{"exchange": "BYBIT", "timestamp": 1742556584.738288, "message": {"topic": "orderbook.200.BTCUSDT", "ts": 1742556584720, "type": "delta", "data": {"s": "BTCUSDT", "b": [["83963.1", "0.282997"], ["83915", "0.002579"], ["83898.7", "12.591061"], ["83895.9", "0"]], "a": [], "u": 26736, "seq": 67550555176}, "cts": 1742556584643}}
{"exchange": "BITGET", "timestamp": 1742556584.871097, "message": {"action": "update", "arg": {"instType": "SPOT", "channel": "books", "instId": "BTCUSDT"}, "data": [{"asks": [["83944.01", "1.703536"], ["83983.00", "0.001087"], ["83985.00", "0.001774"], ["83987.00", "0.004668"], ["83989.00", "0.012283"], ["83991.00", "0.032326"], ["83993.00", "0.141205"], ["83995.00", "0.223862"], ["83996.99", "0"], ["83997.00", "0.589110"], ["83999.00", "1.550288"], ["84001.00", "4.079706"], ["84003.00", "10.736069"], ["84005.40", "0"], ["84006.60", "0.074430"], ["84008.00", "0.113400"], ["84008.40", "1.534680"], ["84019.09", "0.014473"], ["84045.00", "5.353960"], ["84053.40", "4.809489"], ["84061.80", "4.718744"], ["84070.20", "4.355764"], ["84078.60", "4.900235"], ["84087.00", "4.083529"], ["84095.40", "4.446509"], ["84103.80", "4.990980"], ["84112.20", "4.174274"], ["84120.60", "5.626195"], ["84129.00", "5.263215"], ["84137.40", "4.537254"], ["84145.80", "5.535450"], ["84154.20", "4.627999"], ["84162.60", "5.172470"], ["84171.00", "5.444705"], ["84179.40", "3.902039"], ["84187.80", "4.265019"], ["84196.20", "3.992784"], ["84204.60", "5.081725"], ["84522.06", "0.000041"]], "bids": [["83941.59", "0"], ["83919.00", "4.387554"], ["83877.00", "4.900235"], ["83868.60", "5.263215"], ["83860.20", "5.172470"], ["83851.80", "5.444705"], ["83843.40", "4.990980"], ["83835.00", "3.902039"], ["83826.60", "4.627999"], ["83818.20", "4.718744"], ["83809.80", "5.626195"], ["83801.40", "5.535450"], ["83793.00", "3.992784"], ["83784.60", "4.083529"], ["83776.20", "5.353960"], ["83767.80", "4.537254"], ["83759.40", "4.809489"], ["83751.00", "4.355764"], ["83725.80", "4.265019"], ["83717.40", "5.081725"], ["83637.17", "0.000027"]], "checksum": -785092643, "ts": "1742556584816"}], "ts": 1742556584819}}
{"exchange": "BYBIT", "timestamp": 1742556585.022806, "message": {"topic": "orderbook.200.BTCUSDT", "ts": 1742556584920, "type": "delta", "data": {"s": "BTCUSDT", "b": [["83963", "0.071494"], ["83962", "0"], ["83929", "0"], ["83898.7", "12.603019"], ["83895.5", "0"], ["83888.7", "0.003614"], ["83888.6", "0.000516"]], "a": [["83982.6", "0"], ["84005.9", "0.005953"], ["84029.1", "0.000333"]], "u": 26737, "seq": 67550555200}, "cts": 1742556584904}}
{"exchange": "BITGET", "timestamp": 1742556585.05537, "message": {"action": "update", "arg": {"instType": "SPOT", "channel": "books", "instId": "BTCUSDT"}, "data": [{"asks": [["83945.00", "0.224789"], ["83945.76", "0"], ["83945.95", "0"], ["83980.76", "0"], ["83982.64", "0"], ["83987.00", "0.004791"], ["83989.00", "0.012610"], ["83991.00", "0.032962"], ["83995.00", "0.228266"], ["83997.00", "0.600701"], ["83999.00", "1.580792"], ["84001.00", "4.159977"], ["84003.00", "10.947309"], ["84009.90", "0"], ["84011.60", "0"], ["84012.40", "0"], ["84014.80", "1.055730"], ["84045.00", "5.263215"], ["84053.40", "5.626195"], ["84061.80", "3.992784"], ["84070.20", "4.809489"], ["84087.00", "4.627999"], ["84095.40", "4.083529"], ["84103.80", "5.535450"], ["84112.20", "4.355764"], ["84120.60", "5.081725"], ["84129.00", "4.718744"], ["84145.80", "4.174274"], ["84154.20", "5.172470"], ["84162.60", "4.446509"], ["84171.00", "4.990980"], ["84179.40", "5.444705"], ["84187.80", "5.353960"], ["84196.20", "4.265019"], ["84204.60", "3.902039"], ["84523.08", "0.000015"], ["84523.48", "0.000015"], ["84523.81", "0.000024"], ["84524.00", "0.000035"], ["84524.83", "0.000009"], ["84525.00", "0.000010"]], "bids": [["83931.00", "0.013344"], ["83929.00", "0.035115"], ["83927.00", "0.092196"], ["83925.00", "0.242621"], ["83923.01", "0.810387"], ["83923.00", "0.638475"], ["83921.00", "1.680198"], ["83919.31", "0.333520"], ["83919.00", "4.421573"], ["83895.00", "0.000941"], ["83877.00", "3.902039"], ["83868.60", "4.809489"], ["83860.20", "5.535450"], ["83851.80", "5.081725"], ["83835.00", "4.627999"], ["83826.60", "3.992784"], ["83818.20", "5.172470"], ["83801.40", "5.353960"], ["83793.00", "4.083529"], ["83784.60", "4.355764"], ["83776.20", "4.718744"], ["83759.40", "4.446509"], ["83751.00", "4.900235"], ["83742.60", "4.265019"], ["83734.20", "5.444705"], ["83725.80", "4.174274"], ["83717.40", "5.263215"]], "checksum": -623397140, "ts": "1742556585019"}], "ts": 1742556585023}}
{"exchange": "BYBIT", "timestamp": 1742556585.138338, "message": {"topic": "orderbook.200.BTCUSDT", "ts": 1742556585120, "type": "delta", "data": {"s": "BTCUSDT", "b": [["83963.1", "0.283597"], ["83930.2", "0.167765"], ["83925", "0.013"], ["83924.8", "0"], ["83888.6", "0"]], "a": [["83963.2", "0.379719"], ["83980.1", "0.051575"], ["83997.1", "0.189697"], ["83997.7", "0.04"], ["83997.9", "0"]], "u": 26738, "seq": 67550555218}, "cts": 1742556585106}}
{"exchange": "BITGET", "timestamp": 1742556585.295321, "message": {"action": "update", "arg": {"instType": "SPOT", "channel": "books", "instId": "BTCUSDT"}, "data": [{"asks": [["83945.69", "0.093375"], ["83977.66", "0.183328"], ["84008.40", "0.838020"], ["84010.70", "0"], ["84015.90", "0.120000"], ["84045.00", "4.718744"], ["84053.40", "5.081725"], ["84061.80", "4.900235"], ["84070.20", "5.353960"], ["84078.60", "3.902039"], ["84087.00", "4.809489"], ["84095.40", "5.263215"], ["84103.80", "4.446509"], ["84112.20", "4.537254"], ["84120.60", "4.990980"], ["84129.00", "5.626195"], ["84137.40", "4.265019"], ["84145.80", "3.992784"], ["84154.20", "4.355764"], ["84162.60", "4.174274"], ["84171.00", "5.444705"], ["84179.40", "5.535450"], ["84187.80", "5.172470"], ["84196.20", "4.627999"], ["84204.60", "4.083529"], ["84524.83", "0"], ["84525.00", "0"]], "bids": [["83942.09", "0.037215"], ["83934.20", "0"], ["83929.00", "0.034960"], ["83927.00", "0.092000"], ["83925.00", "0.242104"], ["83923.00", "0.637116"], ["83921.00", "1.676621"], ["83919.31", "0.410463"], ["83919.00", "4.412162"], ["83895.00", "0.000956"], ["83877.00", "5.535450"], ["83868.60", "3.902039"], ["83860.20", "4.265019"], ["83851.80", "5.444705"], ["83835.00", "4.355764"], ["83818.20", "5.626195"], ["83811.54", "0"], ["83811.49", "0.125803"], ["83809.80", "4.446509"], ["83801.40", "4.809489"], ["83793.00", "4.537254"], ["83784.60", "4.627999"], ["83776.20", "5.353960"], ["83767.80", "4.174274"], ["83759.40", "5.172470"], ["83751.00", "4.718744"], ["83742.60", "5.081725"], ["83734.20", "4.900235"], ["83725.80", "5.263215"], ["83717.40", "4.083529"]], "checksum": 1639020322, "ts": "1742556585238"}], "ts": 1742556585241}}
{"exchange": "BYBIT", "timestamp": 1742556585.339457, "message": {"topic": "orderbook.200.BTCUSDT", "ts": 1742556585320, "type": "delta", "data": {"s": "BTCUSDT", "b": [["83963.1", "0.2716"], ["83925", "0"], ["83924.8", "0.012881"], ["83898.7", "0"], ["83895.9", "12.603019"]], "a": [["83987.5", "0.001088"], ["83997.7", "0"], ["83997.9", "0.04"], ["84029.1", "0"]], "u": 26739, "seq": 67550555240}, "cts": 1742556585300}}
{"exchange": "BITGET", "timestamp": 1742556585.482598, "message": {"action": "update", "arg": {"instType": "SPOT", "channel": "books", "instId": "BTCUSDT"}, "data": [{"asks": [["83945.00", "0.106004"], ["83945.96", "0.211477"], ["83987.00", "0.004760"], ["83989.00", "0.012525"], ["84045.00", "4.446509"], ["84053.40", "5.353960"], ["84061.80", "4.174274"], ["84070.20", "4.627999"], ["84078.60", "4.537254"], ["84087.00", "3.992784"], ["84095.40", "4.265019"], ["84103.80", "4.083529"], ["84112.20", "5.263215"], ["84120.60", "5.626195"], ["84129.00", "5.444705"], ["84137.40", "3.902039"], ["84145.80", "5.081725"], ["84162.60", "4.900235"], ["84171.00", "4.718744"], ["84179.40", "4.809489"], ["84196.20", "4.990980"], ["84204.60", "5.535450"]], "bids": [["83933.00", "0.004901"], ["83931.00", "0.012897"], ["83929.00", "0.033941"], ["83927.00", "0.089317"], ["83925.00", "0.235044"], ["83923.00", "0.618538"], ["83921.00", "1.627732"], ["83919.00", "4.283506"], ["83877.00", "4.083529"], ["83868.60", "5.353960"], ["83860.20", "4.718744"], ["83851.80", "4.809489"], ["83843.40", "5.444705"], ["83835.00", "5.535450"], ["83826.60", "4.265019"], ["83818.20", "4.537254"], ["83809.80", "5.081725"], ["83801.40", "4.627999"], ["83793.00", "5.626195"], ["83784.60", "3.902039"], ["83776.20", "4.990980"], ["83767.80", "5.263215"], ["83751.00", "3.992784"], ["83742.60", "4.174274"], ["83734.20", "4.355764"], ["83725.80", "4.900235"], ["83717.40", "4.446509"]], "checksum": 1127740653, "ts": "1742556585453"}], "ts": 1742556585456}}
{"exchange": "BYBIT", "timestamp": 1742556585.645882, "message": {"topic": "orderbook.200.BTCUSDT", "ts": 1742556585519, "type": "delta", "data": {"s": "BTCUSDT", "b": [], "a": [["83965.5", "0.060692"], ["83967.6", "0"], ["83987.5", "0"], ["84029.1", "0.000333"], ["84030.6", "0.118804"]], "u": 26740, "seq": 67550555254}, "cts": 1742556585512}}
{"exchange": "BITGET", "timestamp": 1742556585.825478, "message": {"action": "update", "arg": {"instType": "SPOT", "channel": "books", "instId": "BTCUSDT"}, "data": [{"asks": [["83944.01", "1.283769"], ["83945.63", "0.093375"], ["83945.68", "0.131966"], ["83945.69", "0"], ["84009.10", "0.319680"], ["84009.50", "0.075540"], ["84045.00", "4.718744"], ["84053.40", "3.992784"], ["84061.80", "5.444705"], ["84070.20", "5.353960"], ["84078.60", "5.263215"], ["84087.00", "4.809489"], ["84095.40", "4.627999"], ["84103.80", "4.900235"], ["84112.20", "4.265019"], ["84120.60", "4.537254"], ["84129.00", "4.174274"], ["84137.40", "5.081725"], ["84145.80", "3.902039"], ["84154.20", "4.446509"], ["84162.60", "5.172470"], ["84171.00", "4.083529"], ["84179.40", "4.990980"], ["84187.80", "5.535450"], ["84196.20", "5.626195"], ["84204.60", "4.355764"], ["84524.00", "0"]], "bids": [["83923.00", "0.618783"], ["83921.00", "1.628375"], ["83919.00", "4.285198"], ["83911.11", "0"], ["83894.00", "0"], ["83893.00", "0.000015"], ["83877.00", "4.537254"], ["83868.60", "5.535450"], ["83851.80", "4.990980"], ["83843.40", "4.265019"], ["83835.00", "4.900235"], ["83826.60", "4.627999"], ["83818.20", "5.353960"], ["83809.80", "4.174274"], ["83801.40", "4.083529"], ["83793.00", "5.263215"], ["83776.20", "5.172470"], ["83767.80", "3.992784"], ["83759.40", "4.446509"], ["83751.00", "5.444705"], ["83742.60", "5.626195"], ["83734.20", "4.809489"], ["83725.80", "5.081725"], ["83717.40", "4.355764"], ["83636.36", "0.000179"], ["83635.64", "0.000030"]], "checksum": -709677761, "ts": "1742556585664"}], "ts": 1742556585669}}
{"exchange": "BYBIT", "timestamp": 1742556585.826321, "message": {"topic": "orderbook.200.BTCUSDT", "ts": 1742556585720, "type": "delta", "data": {"s": "BTCUSDT", "b": [["83963.1", "0.282932"], ["83898.7", "12.603019"], ["83895.9", "0"]], "a": [], "u": 26741, "seq": 67550555270}, "cts": 1742556585711}}
{"exchange": "BITGET", "timestamp": 1742556586.000674, "message": {"action": "update", "arg": {"instType": "SPOT", "channel": "books", "instId": "BTCUSDT"}, "data": [{"asks": [["83995.00", "0.227804"], ["83997.00", "0.599484"], ["83999.00", "1.577590"], ["84001.00", "4.151552"], ["84003.00", "10.925138"], ["84045.00", "5.263215"], ["84053.40", "4.627999"], ["84061.80", "4.446509"], ["84070.20", "5.535450"], ["84078.60", "5.172470"], ["84087.00", "5.353960"], ["84095.40", "4.809489"], ["84103.80", "3.992784"], ["84112.20", "4.900235"], ["84120.60", "5.444705"], ["84129.00", "4.718744"], ["84137.40", "4.265019"], ["84145.80", "4.990980"], ["84154.20", "3.902039"], ["84162.60", "4.537254"], ["84171.00", "4.174274"], ["84179.40", "5.081725"], ["84187.80", "5.626195"], ["84196.20", "4.083529"]], "bids": [["83914.80", "0"], ["83877.00", "5.535450"], ["83868.60", "4.355764"], ["83860.20", "5.626195"], ["83851.80", "5.081725"], ["83843.40", "5.444705"], ["83835.00", "4.083529"], ["83826.60", "4.718744"], ["83818.20", "3.902039"], ["83809.80", "4.900235"], ["83801.40", "4.265019"], ["83793.00", "4.537254"], ["83784.60", "5.172470"], ["83776.20", "4.174274"], ["83767.80", "4.809489"], ["83759.40", "5.353960"], ["83751.00", "4.627999"], ["83742.60", "3.992784"], ["83734.20", "4.446509"], ["83725.80", "4.990980"], ["83717.40", "5.263215"], ["83634.90", "0.519383"]], "checksum": -709677761, "ts": "1742556585869"}], "ts": 1742556585871}}
{"exchange": "BYBIT", "timestamp": 1742556586.001973, "message": {"topic": "orderbook.200.BTCUSDT", "ts": 1742556585920, "type": "delta", "data": {"s": "BTCUSDT", "b": [["83924.9", "0"], ["83924.7", "0.012881"]], "a": [["83980.1", "0.048"]], "u": 26742, "seq": 67550555292}, "cts": 1742556585908}}
{"exchange": "BITGET", "timestamp": 1742556586.176254, "message": {"action": "update", "arg": {"instType": "SPOT", "channel": "books", "instId": "BTCUSDT"}, "data": [{"asks": [["83944.01", "1.703769"], ["83945.00", "0.224719"], ["83945.57", "0.093375"], ["83945.63", "0"], ["83945.68", "0"], ["83987.00", "0.004491"], ["83989.00", "0.011820"], ["83991.00", "0.031105"], ["83995.00", "0.215408"], ["83997.00", "0.566864"], ["83999.00", "1.491748"], ["84001.00", "3.925652"], ["84003.00", "10.330663"], ["84045.00", "5.081725"], ["84053.40", "5.263215"], ["84061.80", "4.809489"], ["84078.60", "3.902039"], ["84087.00", "4.627999"], ["84095.40", "4.083529"], ["84103.80", "5.444705"], ["84112.20", "4.718744"], ["84120.60", "4.355764"], ["84129.00", "5.353960"], ["84145.80", "4.537254"], ["84154.20", "4.990980"], ["84162.60", "4.446509"], ["84171.00", "3.992784"], ["84179.40", "4.174274"], ["84187.80", "4.900235"], ["84196.20", "5.626195"], ["84204.60", "5.172470"], ["84524.00", "0.000035"]], "bids": [["83942.09", "0"], ["83935.00", "0.002011"], ["83933.00", "0.005294"], ["83931.00", "0.013931"], ["83929.00", "0.036661"], ["83927.00", "0.096475"], ["83925.00", "0.253697"], ["83923.00", "0.667625"], ["83921.00", "1.756907"], ["83919.00", "4.623439"], ["83915.32", "0.008281"], ["83915.20", "0.072210"], ["83909.50", "0"], ["83893.00", "0"], ["83877.00", "5.263215"], ["83868.60", "4.990980"], ["83860.20", "5.172470"], ["83851.80", "4.174274"], ["83843.40", "5.353960"], ["83826.60", "4.446509"], ["83818.20", "5.081725"], ["83809.80", "5.626195"], ["83801.40", "4.627999"], ["83793.00", "4.718744"], ["83784.60", "3.902039"], ["83776.20", "4.265019"], ["83767.80", "4.355764"], ["83759.40", "3.992784"], ["83751.00", "5.444705"], ["83742.60", "4.537254"], ["83734.20", "4.809489"], ["83725.80", "4.900235"], ["83717.40", "5.535450"], ["83634.09", "0.000124"]], "checksum": 2093411441, "ts": "1742556586077"}], "ts": 1742556586080}}
{"exchange": "BYBIT", "timestamp": 1742556586.17653, "message": {"topic": "orderbook.200.BTCUSDT", "ts": 1742556586119, "type": "delta", "data": {"s": "BTCUSDT", "b": [["83955.9", "0"], ["83928.6", "0.734143"], ["83888.6", "0.000516"]], "a": [["83984", "0.003575"], ["84030.6", "0"]], "u": 26743, "seq": 67550555301}, "cts": 1742556586062}}
{"exchange": "BITGET", "timestamp": 1742556586.352164, "message": {"action": "update", "arg": {"instType": "SPOT", "channel": "books", "instId": "BTCUSDT"}, "data": [{"asks": [["83945.00", "0.106004"], ["83965.97", "0.119870"], ["83967.11", "0"], ["83967.33", "0.035961"], ["83967.75", "0.006356"], ["83968.14", "0.006356"], ["83968.38", "0"], ["83968.81", "0"], ["83968.97", "0"], ["83969.29", "0"], ["83969.32", "0.010984"], ["83969.57", "0.006356"], ["83969.74", "0.006356"], ["83970.24", "0.022785"], ["83970.38", "0"], ["83970.63", "0"], ["83970.74", "0.006356"], ["83970.76", "0.006356"], ["83970.80", "0"], ["83970.98", "0.119883"], ["83971.09", "0.016429"], ["83971.27", "0.012712"], ["83971.30", "0"], ["83971.80", "0"], ["83971.81", "0"], ["83972.14", "0"], ["83972.15", "0"], ["83972.31", "0"], ["83972.32", "0"], ["83972.69", "0.010985"], ["83972.78", "0.006357"], ["83973.53", "0.009990"], ["83973.84", "0"], ["83974.52", "0.119850"], ["83974.68", "0"], ["83975.53", "0.119858"], ["83975.57", "0"], ["83975.59", "0.119867"], ["83975.95", "0.015895"], ["83976.57", "0"], ["83976.75", "0"], ["83976.99", "0"], ["83980.66", "0.010988"], ["83981.81", "0"], ["84045.00", "4.900235"], ["84053.40", "4.627999"], ["84061.80", "3.992784"], ["84070.20", "4.355764"], ["84078.60", "4.809489"], ["84087.00", "4.265019"], ["84095.40", "4.990980"], ["84103.80", "5.353960"], ["84112.20", "4.174274"], ["84120.60", "5.626195"], ["84129.00", "4.718744"], ["84137.40", "4.537254"], ["84145.80", "5.081725"], ["84154.20", "4.446509"], ["84162.60", "3.902039"], ["84171.00", "5.263215"], ["84179.40", "5.535450"], ["84187.80", "5.444705"], ["84196.20", "5.172470"], ["84204.60", "4.083529"], ["84524.83", "0.000009"]], "bids": [["83944.00", "0.038026"], ["83942.94", "0.047852"], ["83927.00", "0.096370"], ["83926.22", "0.010350"], ["83925.98", "0.024965"], ["83924.84", "0.247939"], ["83924.73", "0"], ["83924.31", "0"], ["83924.14", "0"], ["83923.79", "0"], ["83923.68", "0.084059"], ["83923.26", "0.017842"], ["83923.00", "0.667383"], ["83922.99", "0.018281"], ["83922.70", "0"], ["83922.65", "0.005955"], ["83922.45", "0"], ["83922.28", "0"], ["83922.02", "0"], ["83921.78", "0"], ["83921.77", "0"], ["83921.64", "0.055735"], ["83921.38", "0.017128"], ["83921.27", "0"], ["83921.22", "0.007141"], ["83921.00", "1.756271"], ["83920.95", "0"], ["83920.93", "0"], ["83920.77", "0"], ["83920.72", "0.028906"], ["83920.71", "0.007350"], ["83920.22", "0.009007"], ["83920.21", "0.007954"], ["83919.89", "0.025220"], ["83919.77", "0.225202"], ["83919.73", "0.025572"], ["83919.27", "0"], ["83919.00", "4.621765"], ["83918.44", "0"], ["83918.21", "0.012673"], ["83918.13", "0.052037"], ["83917.48", "0"], ["83917.28", "0.018543"], ["83916.47", "0"], ["83916.43", "0.268758"], ["83916.31", "0"], ["83916.05", "0"], ["83915.42", "0.222986"], ["83915.15", "0.260165"], ["83915.00", "0.076253"], ["83912.10", "0"], ["83911.29", "0"], ["83911.06", "0.073319"], ["83910.15", "0.056447"], ["83909.63", "0"], ["83908.55", "0.000878"], ["83877.00", "4.446509"], ["83868.60", "4.537254"], ["83860.20", "5.535450"], ["83851.80", "4.355764"], ["83843.40", "4.265019"], ["83835.00", "4.627999"], ["83826.60", "4.174274"], ["83818.20", "4.718744"], ["83809.80", "5.444705"], ["83801.40", "5.353960"], ["83793.00", "5.172470"], ["83784.60", "3.992784"], ["83776.20", "5.263215"], ["83767.80", "4.083529"], ["83759.40", "5.081725"], ["83751.00", "4.900235"], ["83742.60", "4.990980"], ["83734.20", "3.902039"], ["83725.80", "4.809489"], ["83717.40", "5.626195"], ["83635.64", "0"], ["83634.90", "0"], ["83634.09", "0"]], "checksum": 1450148254, "ts": "1742556586280"}], "ts": 1742556586284}}
{"exchange": "BYBIT", "timestamp": 1742556586.352387, "message": {"topic": "orderbook.200.BTCUSDT", "ts": 1742556586319, "type": "delta", "data": {"s": "BTCUSDT", "b": [["83957.9", "0.000153"], ["83888.6", "0"]], "a": [], "u": 26744, "seq": 67550555311}, "cts": 1742556586301}}
{"exchange": "BITGET", "timestamp": 1742556586.527918, "message": {"action": "update", "arg": {"instType": "SPOT", "channel": "books", "instId": "BTCUSDT"}, "data": [{"asks": [["83945.56", "0.131966"], ["83965.54", "0.035952"], ["83966.69", "0"], ["83966.73", "0"], ["83967.82", "0.006356"], ["83987.00", "0.004626"], ["83989.00", "0.012174"], ["83991.00", "0.032038"], ["83994.15", "0"], ["83995.00", "0.221710"], ["83997.00", "0.583447"], ["83999.00", "1.535387"], ["84001.00", "4.040493"], ["84003.00", "10.632876"], ["84012.80", "0.012540"], ["84015.90", "0"], ["84045.00", "4.627999"], ["84053.40", "4.900235"], ["84061.80", "4.990980"], ["84070.20", "4.809489"], ["84078.60", "4.174274"], ["84087.00", "5.263215"], ["84095.40", "5.444705"], ["84103.80", "5.535450"], ["84112.20", "4.537254"], ["84120.60", "5.353960"], ["84129.00", "5.081725"], ["84137.40", "5.172470"], ["84145.80", "4.446509"], ["84154.20", "4.718744"], ["84171.00", "4.265019"], ["84179.40", "3.992784"], ["84187.80", "4.355764"], ["84196.20", "5.626195"]], "bids": [["83942.94", "0"], ["83935.00", "0.001862"], ["83933.00", "0.004899"], ["83931.00", "0.012892"], ["83929.00", "0.033927"], ["83927.00", "0.089282"], ["83926.40", "0"], ["83925.25", "0.089612"], ["83925.00", "0.234953"], ["83923.00", "0.618296"], ["83921.00", "1.627096"], ["83919.00", "4.281832"], ["83915.20", "0"], ["83914.80", "0.015000"], ["83877.00", "5.626195"], ["83868.60", "4.446509"], ["83860.20", "4.900235"], ["83851.80", "4.990980"], ["83843.40", "4.809489"], ["83835.00", "5.172470"], ["83826.60", "3.902039"], ["83818.20", "5.353960"], ["83809.80", "3.992784"], ["83801.40", "4.265019"], ["83793.00", "4.627999"], ["83784.60", "4.718744"], ["83776.20", "4.174274"], ["83767.80", "5.081725"], ["83759.40", "5.444705"], ["83751.00", "4.537254"], ["83742.60", "4.083529"], ["83734.20", "4.355764"], ["83725.80", "5.263215"], ["83717.40", "5.535450"], ["83635.64", "0.000030"]], "checksum": 323828388, "ts": "1742556586486"}], "ts": 1742556586490}}
{"exchange": "BYBIT", "timestamp": 1742556586.537502, "message": {"topic": "orderbook.200.BTCUSDT", "ts": 1742556586520, "type": "delta", "data": {"s": "BTCUSDT", "b": [["83924.9", "0.013"], ["83924.7", "0"]], "a": [["83996.9", "0.013"], ["83997", "0.012743"], ["83997.1", "0.176954"], ["83997.2", "0"], ["83997.6", "0.04"], ["83997.7", "0.04"], ["83997.8", "0"], ["83997.9", "0"], ["84029.1", "0"]], "u": 26745, "seq": 67550555319}, "cts": 1742556586507}}
{"exchange": "BITGET", "timestamp": 1742556586.71875, "message": {"action": "update", "arg": {"instType": "SPOT", "channel": "books", "instId": "BTCUSDT"}, "data": [{"asks": [["83945.51", "0.093375"], ["83945.57", "0"], ["83965.53", "0.046747"], ["83989.00", "0.012296"], ["83991.00", "0.032359"], ["83995.00", "0.224093"], ["83997.00", "0.589719"], ["83999.00", "1.551892"], ["84001.00", "4.083926"], ["84003.00", "10.747173"], ["84012.80", "0"], ["84015.90", "0.120000"], ["84045.00", "5.535450"], ["84053.40", "4.990980"], ["84061.80", "5.444705"], ["84078.60", "4.083529"], ["84087.00", "5.626195"], ["84095.40", "3.992784"], ["84103.80", "4.718744"], ["84112.20", "4.355764"], ["84120.60", "4.627999"], ["84129.00", "4.265019"], ["84137.40", "4.446509"], ["84145.80", "4.537254"], ["84154.20", "5.353960"], ["84162.60", "5.263215"], ["84171.00", "4.174274"], ["84179.40", "5.172470"], ["84187.80", "3.902039"], ["84196.20", "4.900235"], ["84204.60", "5.081725"], ["84524.83", "0"]], "bids": [["83942.40", "0.037215"], ["83927.00", "0.089108"], ["83925.00", "0.234495"], ["83923.00", "0.617090"], ["83921.00", "1.623923"], ["83919.00", "4.273480"], ["83909.50", "0.024300"], ["83877.00", "5.353960"], ["83868.60", "5.263215"], ["83860.20", "3.992784"], ["83851.80", "4.265019"], ["83843.40", "5.535450"], ["83835.00", "4.990980"], ["83826.60", "5.626195"], ["83818.20", "3.902039"], ["83809.80", "4.900235"], ["83801.40", "4.355764"], ["83793.00", "5.081725"], ["83784.60", "5.444705"], ["83776.20", "4.809489"], ["83767.80", "4.446509"], ["83759.40", "4.627999"], ["83751.00", "5.172470"], ["83742.60", "4.537254"], ["83734.20", "4.083529"], ["83725.80", "4.174274"], ["83717.40", "4.718744"], ["83636.36", "0"], ["83635.64", "0"]], "checksum": -883060386, "ts": "1742556586689"}], "ts": 1742556586692}}
{"exchange": "BITGET", "timestamp": 1742556587.058913, "message": {"action": "update", "arg": {"instType": "SPOT", "channel": "books", "instId": "BTCUSDT"}, "data": [{"asks": [["83967.32", "0.031214"], ["83980.78", "0.010000"], ["84045.00", "4.174274"], ["84053.40", "3.992784"], ["84061.80", "5.626195"], ["84070.20", "5.172470"], ["84078.60", "5.444705"], ["84087.00", "5.263215"], ["84095.40", "4.537254"], ["84103.80", "4.355764"], ["84112.20", "5.353960"], ["84129.00", "3.902039"], ["84137.40", "4.718744"], ["84145.80", "4.900235"], ["84154.20", "5.535450"], ["84162.60", "4.265019"], ["84171.00", "4.446509"], ["84179.40", "5.081725"], ["84187.80", "4.990980"], ["84196.20", "4.809489"], ["84204.60", "4.083529"], ["84523.81", "0"], ["84524.00", "0"]], "bids": [["83935.00", "0.002378"], ["83933.00", "0.006258"], ["83931.00", "0.016468"], ["83929.00", "0.043337"], ["83927.00", "0.114046"], ["83925.00", "0.300120"], ["83923.00", "0.789790"], ["83921.00", "2.078395"], ["83919.00", "5.469460"], ["83909.50", "0.021600"], ["83894.00", "0.000015"], ["83877.00", "5.263215"], ["83868.60", "3.992784"], ["83860.20", "5.535450"], ["83851.80", "5.172470"], ["83843.40", "4.809489"], ["83835.00", "4.718744"], ["83818.20", "4.265019"], ["83809.80", "5.353960"], ["83793.00", "5.444705"], ["83784.60", "4.446509"], ["83776.20", "4.537254"], ["83767.80", "4.990980"], ["83759.40", "4.174274"], ["83751.00", "4.900235"], ["83742.60", "4.627999"], ["83734.20", "3.902039"], ["83725.80", "5.081725"], ["83717.40", "4.083529"], ["83637.17", "0"]], "checksum": 1399219119, "ts": "1742556586896"}], "ts": 1742556586899}}
{"exchange": "BYBIT", "timestamp": 1742556587.060611, "message": {"topic": "orderbook.200.BTCUSDT", "ts": 1742556586919, "type": "delta", "data": {"s": "BTCUSDT", "b": [["83939.2", "0.035737"], ["83930.1", "0.000516"], ["83888.7", "0"]], "a": [["83979.6", "0.035738"], ["83990.1", "0"]], "u": 26746, "seq": 67550555330}, "cts": 1742556586917}}
{"exchange": "BYBIT", "timestamp": 1742556587.238826, "message": {"topic": "orderbook.200.BTCUSDT", "ts": 1742556587120, "type": "delta", "data": {"s": "BTCUSDT", "b": [["83925.1", "0.013"], ["83925", "0.012881"], ["83924.9", "0"], ["83924.8", "0"]], "a": [["83996.7", "0.013"], ["83996.8", "0.084181"], ["83996.9", "0"], ["83997", "0"], ["83997.4", "0.04"], ["83997.5", "0.04"], ["83997.6", "0"], ["83997.7", "0"], ["84029.1", "0.000333"]], "u": 26747, "seq": 67550555340}, "cts": 1742556587103}}
{"exchange": "BITGET", "timestamp": 1742556587.238958, "message": {"action": "update", "arg": {"instType": "SPOT", "channel": "books", "instId": "BTCUSDT"}, "data": [{"asks": [["83945.51", "0"], ["83995.00", "0.223933"], ["83997.00", "0.589298"], ["83999.00", "1.550785"], ["84001.00", "4.081014"], ["84003.00", "10.739510"], ["84012.90", "0.012420"], ["84015.90", "0"], ["84045.00", "4.446509"], ["84053.40", "5.263215"], ["84061.80", "4.990980"], ["84070.20", "4.718744"], ["84078.60", "4.174274"], ["84087.00", "4.083529"], ["84095.40", "3.992784"], ["84103.80", "5.626195"], ["84112.20", "5.535450"], ["84120.60", "3.902039"], ["84129.00", "5.172470"], ["84137.40", "4.900235"], ["84145.80", "5.444705"], ["84154.20", "5.081725"], ["84162.60", "4.627999"], ["84171.00", "5.353960"], ["84179.40", "4.265019"], ["84187.80", "4.355764"], ["84196.20", "4.537254"], ["84204.60", "4.809489"], ["84523.81", "0.000024"]], "bids": [["83942.40", "0"], ["83915.30", "0.045600"], ["83912.90", "0"], ["83909.50", "0"], ["83894.00", "0.000032"], ["83877.00", "4.809489"], ["83868.60", "4.446509"], ["83860.20", "4.355764"], ["83851.80", "4.627999"], ["83843.40", "4.718744"], ["83835.00", "5.444705"], ["83826.60", "5.263215"], ["83818.20", "5.626195"], ["83809.80", "5.081725"], ["83801.40", "4.900235"], ["83793.00", "5.535450"], ["83784.60", "3.902039"], ["83776.20", "3.992784"], ["83759.40", "4.083529"], ["83751.00", "4.265019"], ["83742.60", "4.174274"], ["83734.20", "5.172470"], ["83725.80", "4.537254"], ["83717.40", "5.353960"], ["83637.17", "0.000027"], ["83636.36", "0.000179"]], "checksum": -1269682207, "ts": "1742556587106"}], "ts": 1742556587109}}
{"exchange": "BYBIT", "timestamp": 1742556587.33796, "message": {"topic": "orderbook.200.BTCUSDT", "ts": 1742556587320, "type": "delta", "data": {"s": "BTCUSDT", "b": [["83923", "0.041695"], ["83888.8", "0"]], "a": [], "u": 26748, "seq": 67550555346}, "cts": 1742556587311}}
{"exchange": "BITGET", "timestamp": 1742556587.378427, "message": {"action": "update", "arg": {"instType": "SPOT", "channel": "books", "instId": "BTCUSDT"}, "data": [{"asks": [["83945.00", "0.196707"], ["83945.46", "0.093375"], ["83945.56", "0"], ["83977.66", "0"], ["84000.28", "0.001598"], ["84002.05", "0"], ["84002.27", "0.001597"], ["84003.97", "0"], ["84045.00", "4.537254"], ["84053.40", "5.626195"], ["84061.80", "3.992784"], ["84066.33", "0.057001"], ["84070.20", "5.263215"], ["84078.60", "5.353960"], ["84087.00", "4.174274"], ["84095.40", "4.900235"], ["84103.80", "4.083529"], ["84120.60", "4.355764"], ["84129.00", "4.265019"], ["84137.40", "4.990980"], ["84145.80", "3.902039"], ["84154.20", "5.444705"], ["84162.60", "4.809489"], ["84171.00", "4.627999"], ["84179.40", "4.446509"], ["84187.80", "5.081725"], ["84196.20", "4.718744"], ["84204.60", "5.172470"]], "bids": [["83943.00", "0.047884"], ["83936.03", "0.010000"], ["83928.84", "0.020536"], ["83927.00", "0.114257"], ["83925.00", "0.300676"], ["83923.00", "0.791254"], ["83921.00", "2.082247"], ["83919.00", "5.479597"], ["83891.91", "0"], ["83890.14", "0.001177"], ["83889.97", "0"], ["83888.28", "0.001175"], ["83877.00", "4.537254"], ["83868.60", "5.263215"], ["83860.20", "4.627999"], ["83856.42", "0.057001"], ["83851.80", "4.355764"], ["83843.40", "4.809489"], ["83826.60", "4.990980"], ["83818.20", "5.353960"], ["83809.80", "3.992784"], ["83801.40", "4.083529"], ["83793.00", "5.172470"], ["83784.60", "5.535450"], ["83776.20", "5.081725"], ["83767.80", "4.446509"], ["83759.40", "4.900235"], ["83751.00", "4.718744"], ["83734.20", "3.902039"], ["83725.80", "5.626195"], ["83717.40", "4.265019"], ["83638.30", "0"], ["83637.17", "0"], ["83636.36", "0"]], "checksum": -1797430035, "ts": "1742556587327"}], "ts": 1742556587333}}
{"exchange": "BYBIT", "timestamp": 1742556587.537371, "message": {"topic": "orderbook.200.BTCUSDT", "ts": 1742556587519, "type": "delta", "data": {"s": "BTCUSDT", "b": [["83925.1", "0"], ["83924.9", "0.012881"]], "a": [["83996.7", "0"], ["83996.9", "0.012743"], ["83997.4", "0"], ["83997.6", "0.04"]], "u": 26749, "seq": 67550555353}, "cts": 1742556587484}}
{"exchange": "BITGET", "timestamp": 1742556587.565428, "message": {"action": "update", "arg": {"instType": "SPOT", "channel": "books", "instId": "BTCUSDT"}, "data": [{"asks": [["83944.01", "1.283769"], ["83975.18", "0"], ["83987.00", "0.004793"], ["83989.00", "0.012613"], ["83991.00", "0.033194"], ["83995.00", "0.229872"], ["83996.99", "0.129458"], ["83997.00", "0.604927"], ["83999.00", "1.591784"], ["84001.00", "4.188907"], ["84003.00", "11.023439"], ["84045.00", "4.627999"], ["84053.40", "4.355764"], ["84061.80", "5.626195"], ["84070.20", "4.083529"], ["84087.00", "5.081725"], ["84103.80", "3.902039"], ["84112.20", "5.444705"], ["84120.60", "4.446509"], ["84129.00", "4.174274"], ["84137.40", "5.172470"], ["84145.80", "4.718744"], ["84154.20", "4.265019"], ["84162.60", "5.535450"], ["84171.00", "4.990980"], ["84179.40", "4.537254"], ["84187.80", "5.263215"], ["84196.20", "4.809489"], ["84204.60", "3.992784"]], "bids": [["83923.00", "0.791139"], ["83921.00", "2.082042"], ["83919.00", "5.478797"], ["83915.20", "0.072990"], ["83910.00", "0.002956"], ["83877.00", "3.992784"], ["83868.60", "5.535450"], ["83860.20", "4.174274"], ["83851.80", "5.444705"], ["83843.40", "5.263215"], ["83835.00", "4.809489"], ["83826.60", "5.081725"], ["83818.20", "5.626195"], ["83809.80", "4.990980"], ["83801.40", "4.446509"], ["83793.00", "4.718744"], ["83784.60", "4.900235"], ["83776.20", "5.353960"], ["83767.80", "4.083529"], ["83759.40", "4.537254"], ["83751.00", "5.172470"], ["83742.60", "4.627999"], ["83734.20", "4.265019"], ["83725.80", "4.355764"], ["83717.40", "3.902039"], ["83638.32", "0"]], "checksum": -1583666921, "ts": "1742556587534"}], "ts": 1742556587538}}
{"exchange": "BYBIT", "timestamp": 1742556587.738589, "message": {"topic": "orderbook.200.BTCUSDT", "ts": 1742556587720, "type": "delta", "data": {"s": "BTCUSDT", "b": [], "a": [["83965.6", "0.174"], ["83984", "0"], ["84005.1", "0"], ["84030.6", "0.118804"], ["84030.9", "0.089099"]], "u": 26750, "seq": 67550555365}, "cts": 1742556587712}}
{"exchange": "BITGET", "timestamp": 1742556587.766513, "message": {"action": "update", "arg": {"instType": "SPOT", "channel": "books", "instId": "BTCUSDT"}, "data": [{"asks": [["83944.01", "1.703769"], ["83945.41", "0.093375"], ["83945.46", "0"], ["83975.76", "0.009989"], ["83977.14", "0"], ["83977.77", "0.174661"], ["83979.64", "0.015892"], ["83980.92", "0"], ["84045.00", "4.809489"], ["84053.40", "4.537254"], ["84061.80", "5.353960"], ["84070.20", "5.172470"], ["84078.60", "4.627999"], ["84087.00", "4.083529"], ["84095.40", "4.446509"], ["84112.20", "4.990980"], ["84120.60", "4.174274"], ["84129.00", "5.263215"], ["84137.40", "5.081725"], ["84145.80", "5.626195"], ["84154.20", "4.900235"], ["84162.60", "4.718744"], ["84171.00", "5.535450"], ["84179.40", "4.355764"], ["84187.80", "3.992784"], ["84196.20", "5.444705"], ["84204.60", "4.265019"], ["84523.81", "0"]], "bids": [["83943.00", "0.000032"], ["83927.00", "0.113913"], ["83926.30", "0"], ["83925.00", "0.299771"], ["83923.69", "0"], ["83923.00", "0.788871"], ["83922.15", "0.004023"], ["83921.00", "2.075978"], ["83919.00", "5.463099"], ["83915.86", "0"], ["83914.80", "0.030000"], ["83914.48", "0.021160"], ["83891.11", "0"], ["83889.82", "0.003602"], ["83868.60", "4.990980"], ["83860.20", "5.263215"], ["83851.80", "4.809489"], ["83843.40", "4.083529"], ["83835.00", "3.902039"], ["83826.60", "5.353960"], ["83818.20", "4.900235"], ["83809.80", "4.174274"], ["83801.40", "4.265019"], ["83793.00", "5.444705"], ["83784.60", "5.172470"], ["83776.20", "5.081725"], ["83767.80", "5.626195"], ["83759.40", "4.718744"], ["83751.00", "4.537254"], ["83734.20", "4.446509"], ["83717.40", "5.535450"], ["83638.32", "0.000039"], ["83638.30", "0.000137"]], "checksum": -1420405633, "ts": "1742556587734"}], "ts": 1742556587738}}
{"exchange": "BYBIT", "timestamp": 1742556587.938814, "message": {"topic": "orderbook.200.BTCUSDT", "ts": 1742556587919, "type": "delta", "data": {"s": "BTCUSDT", "b": [], "a": [["83986.6", "0.003575"], ["84004.5", "0.304208"], ["84030.9", "0"]], "u": 26751, "seq": 67550555375}, "cts": 1742556587904}}
{"exchange": "BITGET", "timestamp": 1742556587.975536, "message": {"action": "update", "arg": {"instType": "SPOT", "channel": "books", "instId": "BTCUSDT"}, "data": [{"asks": [["83944.01", "1.697415"], ["83945.00", "0.106004"], ["83975.52", "0.135823"], ["83996.99", "0"], ["84003.00", "11.023178"], ["84045.00", "5.263215"], ["84053.40", "5.444705"], ["84070.20", "4.990980"], ["84087.00", "3.902039"], ["84095.40", "5.626195"], ["84103.80", "5.081725"], ["84112.20", "4.174274"], ["84120.60", "4.446509"], ["84129.00", "4.537254"], ["84137.40", "4.809489"], ["84145.80", "5.535450"], ["84154.20", "4.718744"], ["84162.60", "4.083529"], ["84171.00", "4.355764"], ["84179.40", "3.992784"], ["84187.80", "4.900235"], ["84196.20", "5.172470"]], "bids": [["83935.00", "0.002011"], ["83933.00", "0.005293"], ["83931.00", "0.013928"], ["83930.50", "0.008513"], ["83929.00", "0.036654"], ["83927.00", "0.096458"], ["83926.37", "0.008909"], ["83925.00", "0.253835"], ["83923.00", "0.667987"], ["83921.00", "1.757861"], ["83919.00", "4.625950"], ["83915.20", "0"], ["83910.00", "0.007050"], ["83893.00", "0.000015"], ["83877.00", "5.081725"], ["83868.60", "3.992784"], ["83860.20", "4.990980"], ["83851.80", "4.537254"], ["83843.40", "4.446509"], ["83835.00", "4.355764"], ["83826.60", "5.263215"], ["83818.20", "4.627999"], ["83809.80", "5.444705"], ["83801.40", "4.718744"], ["83793.00", "5.353960"], ["83784.60", "4.900235"], ["83776.20", "4.083529"], ["83759.40", "4.809489"], ["83751.00", "3.902039"], ["83742.60", "4.174274"], ["83734.20", "5.172470"], ["83725.80", "4.265019"], ["83638.32", "0"], ["83638.30", "0"]], "checksum": 483606031, "ts": "1742556587943"}], "ts": 1742556587947}}
{"exchange": "BYBIT", "timestamp": 1742556588.140641, "message": {"topic": "orderbook.200.BTCUSDT", "ts": 1742556588120, "type": "delta", "data": {"s": "BTCUSDT", "b": [["83957.9", "0"], ["83939.3", "0.012647"], ["83925", "0"], ["83924.8", "0.012881"]], "a": [["83963.2", "0.376194"], ["83996.8", "0.071438"], ["83996.9", "0"], ["83997", "0.013"], ["83997.1", "0.189697"], ["83997.5", "0"], ["83997.6", "0"], ["83997.7", "0.04"], ["83997.8", "0.04"]], "u": 26752, "seq": 67550555398}, "cts": 1742556588077}}
{"exchange": "BITGET", "timestamp": 1742556588.186443, "message": {"action": "update", "arg": {"instType": "SPOT", "channel": "books", "instId": "BTCUSDT"}, "data": [{"asks": [["83945.40", "0.131966"], ["83945.41", "0"], ["83995.00", "0.230009"], ["83997.00", "0.605286"], ["83999.00", "1.592859"], ["84001.00", "4.191734"], ["84003.00", "11.030879"], ["84012.90", "0"], ["84015.90", "0.120000"], ["84053.40", "4.083529"], ["84061.80", "5.172470"], ["84070.20", "5.081725"], ["84078.60", "4.265019"], ["84087.00", "5.353960"], ["84095.40", "3.902039"], ["84103.80", "4.718744"], ["84112.20", "5.444705"], ["84120.60", "4.537254"], ["84129.00", "4.627999"], ["84137.40", "4.900235"], ["84145.80", "4.174274"], ["84154.20", "4.355764"], ["84162.60", "4.446509"], ["84171.00", "4.809489"], ["84179.40", "4.990980"], ["84187.80", "5.535450"], ["84196.20", "3.992784"], ["84204.60", "5.626195"]], "bids": [["83935.00", "0.001038"], ["83933.00", "0.002448"], ["83931.00", "0.006444"], ["83929.00", "0.016956"], ["83927.00", "0.044623"], ["83925.00", "0.117427"], ["83923.00", "0.308777"], ["83921.00", "0.812573"], ["83919.00", "2.138349"], ["83893.00", "0.000032"], ["83877.00", "4.174274"], ["83868.60", "4.718744"], ["83860.20", "5.172470"], ["83851.80", "4.446509"], ["83843.40", "4.355764"], ["83835.00", "4.265019"], ["83826.60", "4.083529"], ["83818.20", "4.900235"], ["83809.80", "4.809489"], ["83801.40", "5.353960"], ["83793.00", "3.902039"], ["83784.60", "5.263215"], ["83776.20", "5.081725"], ["83767.80", "4.537254"], ["83759.40", "5.444705"], ["83751.00", "3.992784"], ["83742.60", "5.626195"], ["83734.20", "4.990980"], ["83725.80", "4.627999"]], "checksum": 349949119, "ts": "1742556588145"}], "ts": 1742556588148}}
{"exchange": "BYBIT", "timestamp": 1742556588.338206, "message": {"topic": "orderbook.200.BTCUSDT", "ts": 1742556588320, "type": "delta", "data": {"s": "BTCUSDT", "b": [["83924.9", "0"], ["83924.7", "0.012881"], ["83898.7", "0"], ["83896", "0"], ["83895.9", "12.638834"], ["83895.1", "0.235392"]], "a": [["83997", "0"], ["83997.1", "0.176954"], ["83997.3", "0.012743"], ["83997.4", "0.012743"], ["83997.7", "0"], ["83997.8", "0"], ["83998", "0.099535"], ["83998.1", "0.04"]], "u": 26753, "seq": 67550555413}, "cts": 1742556588316}}
{"exchange": "BITGET", "timestamp": 1742556588.375007, "message": {"action": "update", "arg": {"instType": "SPOT", "channel": "books", "instId": "BTCUSDT"}, "data": [{"asks": [["83945.36", "0.093375"], ["84045.00", "5.444705"], ["84053.40", "5.263215"], ["84061.80", "4.265019"], ["84070.20", "3.992784"], ["84078.60", "5.626195"], ["84087.00", "4.355764"], ["84095.40", "4.537254"], ["84103.80", "4.627999"], ["84112.20", "5.535450"], ["84120.60", "4.083529"], ["84129.00", "4.446509"], ["84137.40", "4.174274"], ["84145.80", "4.718744"], ["84154.20", "4.900235"], ["84162.60", "4.809489"], ["84171.00", "5.353960"], ["84179.40", "5.172470"], ["84187.80", "4.990980"], ["84196.20", "3.902039"], ["84204.60", "5.081725"], ["84523.48", "0"]], "bids": [["83942.46", "0.047852"], ["83929.00", "0.017067"], ["83927.00", "0.044684"], ["83925.00", "0.117590"], ["83923.01", "0.387559"], ["83923.00", "0.309446"], ["83921.00", "0.814333"], ["83919.00", "2.142980"], ["83917.80", "0.917910"], ["83914.80", "0.015000"], ["83910.00", "0.002956"], ["83877.00", "4.446509"], ["83868.60", "4.809489"], ["83860.20", "4.265019"], ["83851.80", "3.902039"], ["83843.40", "4.537254"], ["83835.00", "4.627999"], ["83826.60", "5.444705"], ["83818.20", "4.174274"], ["83809.80", "4.718744"], ["83801.40", "5.172470"], ["83793.00", "4.083529"], ["83784.60", "4.355764"], ["83776.20", "5.626195"], ["83767.80", "5.263215"], ["83759.40", "5.535450"], ["83742.60", "5.353960"], ["83734.20", "5.081725"], ["83725.80", "4.900235"], ["83717.40", "4.990980"], ["83639.70", "0"], ["83639.15", "0"]], "checksum": -1027327486, "ts": "1742556588345"}], "ts": 1742556588349}}
{"exchange": "BYBIT", "timestamp": 1742556588.538741, "message": {"topic": "orderbook.200.BTCUSDT", "ts": 1742556588520, "type": "delta", "data": {"s": "BTCUSDT", "b": [["83925", "0.013"], ["83924.9", "0.012881"], ["83924.8", "0"], ["83924.7", "0"]], "a": [["83997", "0.013"], ["83997.1", "0.189697"], ["83997.3", "0"], ["83997.4", "0"], ["83997.7", "0.04"], ["83997.8", "0.04"], ["83998", "0.059535"], ["83998.1", "0"]], "u": 26754, "seq": 67550555431}, "cts": 1742556588453}}
{"exchange": "BITGET", "timestamp": 1742556588.579344, "message": {"action": "update", "arg": {"instType": "SPOT", "channel": "books", "instId": "BTCUSDT"}, "data": [{"asks": [["83945.00", "0.224719"], ["83945.40", "0"], ["83987.00", "0.004796"], ["83989.00", "0.012621"], ["83991.00", "0.033213"], ["83999.00", "1.593028"], ["84001.00", "4.192179"], ["84003.00", "11.032051"], ["84045.00", "4.265019"], ["84053.40", "4.809489"], ["84061.80", "4.174274"], ["84070.20", "4.990980"], ["84078.60", "4.718744"], ["84087.00", "4.900235"], ["84095.40", "5.535450"], ["84103.80", "5.444705"], ["84112.20", "5.172470"], ["84120.60", "3.902039"], ["84129.00", "5.626195"], ["84137.40", "4.355764"], ["84145.80", "4.446509"], ["84154.20", "5.353960"], ["84162.60", "4.083529"], ["84171.00", "4.537254"], ["84179.40", "4.627999"], ["84187.80", "3.992784"], ["84196.20", "5.263215"], ["84523.48", "0.000015"]], "bids": [["83929.00", "0.016901"], ["83927.00", "0.044477"], ["83925.00", "0.117045"], ["83923.00", "0.308012"], ["83921.00", "0.810558"], ["83919.31", "0"], ["83919.00", "2.133048"], ["83914.80", "0.030000"], ["83877.00", "4.809489"], ["83868.60", "5.535450"], ["83860.20", "5.626195"], ["83851.80", "4.446509"], ["83843.40", "5.081725"], ["83835.00", "3.992784"], ["83826.60", "4.990980"], ["83818.20", "5.263215"], ["83809.80", "4.174274"], ["83801.40", "4.265019"], ["83793.00", "5.172470"], ["83784.60", "4.900235"], ["83776.20", "4.627999"], ["83767.80", "3.902039"], ["83759.40", "5.444705"], ["83751.00", "4.083529"], ["83742.60", "4.537254"], ["83734.20", "4.718744"], ["83725.80", "4.355764"], ["83717.40", "5.353960"], ["83639.70", "0.000010"]], "checksum": 227111692, "ts": "1742556588547"}], "ts": 1742556588552}}
{"exchange": "BYBIT", "timestamp": 1742556588.739113, "message": {"topic": "orderbook.200.BTCUSDT", "ts": 1742556588720, "type": "delta", "data": {"s": "BTCUSDT", "b": [["83956.5", "0.000153"], ["83925", "0"], ["83924.8", "0.012881"], ["83889", "0"]], "a": [["83997", "0.012743"], ["83997.6", "0.04"], ["83997.8", "0"]], "u": 26755, "seq": 67550555437}, "cts": 1742556588644}}
{"exchange": "BITGET", "timestamp": 1742556588.792284, "message": {"action": "update", "arg": {"instType": "SPOT", "channel": "books", "instId": "BTCUSDT"}, "data": [{"asks": [["83945.36", "0"], ["84045.00", "5.444705"], ["84053.40", "3.992784"], ["84061.80", "4.083529"], ["84070.20", "4.265019"], ["84078.60", "4.627999"], ["84087.00", "5.263215"], ["84095.40", "5.172470"], ["84103.80", "4.900235"], ["84112.20", "4.537254"], ["84120.60", "4.355764"], ["84129.00", "5.353960"], ["84137.40", "5.626195"], ["84145.80", "5.535450"], ["84154.20", "5.081725"], ["84162.60", "4.174274"], ["84171.00", "4.990980"], ["84179.40", "3.902039"], ["84187.80", "4.446509"], ["84196.20", "4.809489"], ["84204.60", "4.718744"], ["84523.81", "0.000024"]], "bids": [["83925.00", "0.116814"], ["83923.00", "0.307405"], ["83921.00", "0.808961"], ["83919.31", "0.833385"], ["83919.00", "2.128844"], ["83894.00", "0"], ["83877.00", "5.172470"], ["83868.60", "3.992784"], ["83860.20", "5.353960"], ["83851.80", "4.718744"], ["83843.40", "3.902039"], ["83835.00", "4.083529"], ["83826.60", "4.809489"], ["83818.20", "4.627999"], ["83809.80", "4.446509"], ["83801.40", "5.263215"], ["83793.00", "4.355764"], ["83784.60", "4.990980"], ["83776.20", "4.537254"], ["83767.80", "4.265019"], ["83759.40", "5.081725"], ["83751.00", "5.626195"], ["83742.60", "4.900235"], ["83734.20", "5.535450"], ["83725.80", "5.444705"], ["83717.40", "4.174274"]], "checksum": -845255437, "ts": "1742556588751"}], "ts": 1742556588754}}
{"exchange": "BYBIT", "timestamp": 1742556588.937046, "message": {"topic": "orderbook.200.BTCUSDT", "ts": 1742556588919, "type": "delta", "data": {"s": "BTCUSDT", "b": [["83955.1", "0.02489"], ["83955", "0.071501"]], "a": [["83963.2", "0.368298"], ["83977.9", "0.062974"], ["83986.6", "0"], ["83997", "0"], ["83997.1", "0.176954"], ["83997.2", "0.012743"], ["83997.3", "0.012743"], ["83997.6", "0"], ["83997.7", "0"], ["83997.9", "0.04"], ["83998", "0.099535"], ["84030.9", "0.089099"]], "u": 26756, "seq": 67550555479}, "cts": 1742556588902}}
{"exchange": "BITGET", "timestamp": 1742556588.982598, "message": {"action": "update", "arg": {"instType": "SPOT", "channel": "books", "instId": "BTCUSDT"}, "data": [{"asks": [["83945.30", "0.093375"], ["83980.78", "0"], ["84045.00", "3.992784"], ["84053.40", "3.902039"], ["84061.80", "4.990980"], ["84070.20", "5.172470"], ["84078.60", "4.718744"], ["84095.40", "4.627999"], ["84103.80", "5.353960"], ["84112.20", "5.444705"], ["84120.60", "4.537254"], ["84129.00", "4.809489"], ["84137.40", "4.355764"], ["84145.80", "5.626195"], ["84154.20", "5.535450"], ["84171.00", "5.081725"], ["84179.40", "4.265019"], ["84187.80", "4.083529"], ["84196.20", "4.900235"], ["84204.60", "4.446509"]], "bids": [["83942.46", "0"], ["83941.38", "0.047852"], ["83916.20", "0.054000"], ["83914.80", "0"], ["83877.00", "4.446509"], ["83868.60", "4.990980"], ["83860.20", "4.537254"], ["83851.80", "5.444705"], ["83835.00", "4.809489"], ["83826.60", "4.900235"], ["83818.20", "4.174274"], ["83809.80", "5.626195"], ["83801.40", "5.535450"], ["83793.00", "4.265019"], ["83784.60", "4.355764"], ["83776.20", "5.172470"], ["83767.80", "4.627999"], ["83759.40", "5.263215"], ["83751.00", "5.353960"], ["83742.60", "4.718744"], ["83734.20", "3.992784"], ["83725.80", "5.081725"], ["83717.40", "4.083529"], ["83639.15", "0.000009"]], "checksum": 56094009, "ts": "1742556588953"}], "ts": 1742556588956}}
{"exchange": "BYBIT", "timestamp": 1742556589.138119, "message": {"topic": "orderbook.200.BTCUSDT", "ts": 1742556589119, "type": "delta", "data": {"s": "BTCUSDT", "b": [["83952.1", "0.05309"], ["83925", "0.013"], ["83924.8", "0"], ["83898.7", "12.657518"], ["83895.9", "0"], ["83889.4", "0"]], "a": [["83997", "0.013"], ["83997.1", "0.189697"], ["83997.2", "0"], ["83997.3", "0"], ["83997.7", "0.04"], ["83997.8", "0.04"], ["83997.9", "0"], ["83998", "0.059535"]], "u": 26757, "seq": 67550555493}, "cts": 1742556589093}}
{"exchange": "BITGET", "timestamp": 1742556589.193553, "message": {"action": "update", "arg": {"instType": "SPOT", "channel": "books", "instId": "BTCUSDT"}, "data": [{"asks": [["84045.00", "3.902039"], ["84053.40", "4.446509"], ["84061.80", "3.992784"], ["84078.60", "4.083529"], ["84087.00", "5.535450"], ["84095.40", "4.537254"], ["84103.80", "4.627999"], ["84112.20", "4.990980"], ["84120.60", "5.444705"], ["84129.00", "4.718744"], ["84137.40", "5.263215"], ["84145.80", "5.081725"], ["84154.20", "4.355764"], ["84162.60", "5.353960"], ["84171.00", "4.809489"], ["84179.40", "4.900235"], ["84187.80", "4.265019"], ["84196.20", "5.626195"], ["84204.60", "4.174274"]], "bids": [["83941.38", "0"], ["83877.00", "4.083529"], ["83868.60", "4.446509"], ["83860.20", "5.081725"], ["83851.80", "4.718744"], ["83843.40", "3.992784"], ["83835.00", "5.444705"], ["83826.60", "4.537254"], ["83818.20", "4.990980"], ["83809.80", "4.900235"], ["83801.40", "3.902039"], ["83793.00", "4.809489"], ["83784.60", "5.535450"], ["83776.20", "5.353960"], ["83767.80", "5.626195"], ["83759.40", "4.265019"], ["83751.00", "4.355764"], ["83742.60", "5.172470"], ["83734.20", "5.263215"], ["83725.80", "4.627999"], ["83717.40", "4.174274"], ["83638.32", "0.000039"]], "checksum": -933925802, "ts": "1742556589158"}], "ts": 1742556589163}}
{"exchange": "BYBIT", "timestamp": 1742560334.026785, "message": {"success": true, "ret_msg": "subscribe", "conn_id": "cef7da9d-6f5c-442f-b95b-8b77bc7ba856", "op": "subscribe"}}
