{"exchange": "BITGET", "timestamp": 1742560772.62716, "message": {"action": "snapshot", "arg": {"instType": "SPOT", "channel": "books", "instId": "BTCUSDT"}, "data": [{"asks": [["83888.42", "0.868863"], ["83888.43", "0.000100"], ["83888.44", "0.000100"], ["83888.45", "0.000100"], ["83889.09", "0.133678"], ["83896.05", "0.006914"], ["83896.11", "0.041804"], ["83896.12", "0.008242"], ["83896.14", "0.007471"], ["83896.18", "0.009588"], ["83896.40", "0.096111"], ["83896.87", "0.008610"], ["83896.88", "0.020300"], ["83896.89", "0.006594"], ["83896.94", "0.009400"], ["83901.56", "0.483191"], ["83901.57", "1.592789"], ["83902.62", "0.000358"], ["83904.93", "0.017490"], ["83910.01", "0.062760"], ["83910.02", "0.209200"], ["83912.32", "0.001554"], ["83915.15", "0.035952"], ["83915.95", "0.119870"], ["83916.82", "0.035961"], ["83916.89", "0.084700"], ["83917.36", "0.006356"], ["83917.63", "0.006356"], ["83917.90", "0.006356"], ["83918.41", "0.014916"], ["83918.42", "0.209200"], ["83919.16", "0.006356"], ["83919.19", "0.010984"], ["83919.64", "0.006356"], ["83920.08", "0.180069"], ["83920.09", "0.006356"], ["83920.14", "0.016429"], ["83920.59", "0.012712"], ["83920.78", "0.006356"], ["83920.94", "0.016429"], ["83920.96", "0.119883"], ["83921.12", "0.006356"], ["83922.27", "0.006357"], ["83923.48", "0.009990"], ["83924.20", "0.119850"], ["83924.38", "0.010985"], ["83925.43", "0.119858"], ["83925.79", "0.015895"], ["83926.81", "0.209200"], ["83927.74", "0.009989"], ["83928.65", "0.119867"], ["83929.09", "0.201714"], ["83929.10", "3.720136"], ["83931.10", "0.001010"], ["83932.57", "0.714859"], ["83933.10", "0.001023"], ["83933.52", "0.015892"], ["83934.71", "0.010988"], ["83935.10", "0.001044"], ["83935.99", "0.041824"], ["83936.37", "0.209200"], ["83937.10", "0.002929"], ["83939.10", "0.007708"], ["83940.00", "0.002000"], ["83941.10", "0.020283"], ["83943.10", "0.053279"], ["83943.70", "0.000958"], ["83944.77", "0.209200"], ["83945.10", "0.140207"], ["83947.10", "0.368967"], ["83947.72", "0.001598"], ["83949.10", "0.970967"], ["83950.27", "0.245545"], ["83951.10", "2.555175"], ["83951.40", "0.003450"], ["83951.50", "0.006240"], ["83951.60", "0.001041"], ["83951.61", "0.001597"], ["83951.70", "1.717950"], ["83951.94", "0.013444"], ["83952.40", "0.303210"], ["83953.45", "0.209200"], ["83953.90", "0.030000"], ["83954.00", "0.114780"], ["83954.20", "0.134670"], ["83954.40", "0.039780"], ["83954.50", "0.015000"], ["83954.60", "0.021030"], ["83954.70", "0.074640"], ["83954.90", "0.198750"], ["83955.10", "0.330360"], ["83955.30", "0.205041"], ["83955.40", "2.360700"], ["83956.00", "0.084600"], ["83956.50", "0.948480"], ["83956.90", "0.060000"], ["83957.40", "0.144780"], ["83957.50", "0.240000"], ["83957.74", "1.786613"], ["83958.00", "0.084780"], ["83958.50", "0.032460"], ["83959.10", "0.014550"], ["83959.50", "2.400000"], ["83959.90", "0.056220"], ["83960.00", "0.084600"], ["83960.70", "0.767640"], ["83961.40", "0.144780"], ["83970.00", "0.002000"], ["83977.53", "0.001810"], ["83979.01", "0.209200"], ["83985.93", "0.003620"], ["83988.19", "0.125871"], ["83993.10", "4.540060"], ["83993.46", "0.209200"], ["84000.00", "0.002000"], ["84001.50", "4.086054"], ["84009.90", "5.629674"], ["84012.16", "0.209200"], ["84012.25", "0.057001"], ["84017.51", "0.071045"], ["84018.30", "3.995253"], ["84020.08", "0.010010"], ["84022.00", "0.209200"], ["84026.70", "5.357271"], ["84030.00", "0.002000"], ["84030.40", "0.209200"], ["84035.10", "4.630861"], ["84037.50", "0.071253"], ["84043.50", "4.812464"], ["84044.70", "0.209200"], ["84051.90", "5.175668"], ["84057.01", "0.209200"], ["84060.00", "0.002000"], ["84060.30", "4.903265"], ["84067.01", "0.209200"], ["84068.70", "5.538873"], ["84071.41", "0.162687"], ["84073.15", "0.004837"], ["84076.01", "0.209200"], ["84077.10", "3.904452"], ["84085.50", "4.449259"], ["84086.18", "0.209200"], ["84090.00", "0.002000"], ["84093.90", "5.448072"], ["84096.00", "0.001184"], ["84096.18", "0.209200"], ["84100.00", "0.015527"], ["84102.30", "5.084867"], ["84104.58", "0.209200"], ["84110.70", "4.994066"], ["84118.86", "0.209200"], ["84119.10", "4.358458"], ["84120.00", "0.002000"], ["84127.27", "0.209200"], ["84127.50", "4.176855"], ["84135.90", "4.721662"], ["84136.51", "0.209200"], ["84144.30", "4.267656"], ["84149.19", "0.209200"], ["84150.00", "0.002000"], ["84152.70", "5.266470"], ["84157.85", "0.209200"], ["84158.29", "0.001720"], ["84169.30", "0.001428"], ["84172.18", "0.209200"], ["84173.99", "0.004301"], ["84174.51", "0.000388"], ["84180.00", "0.002000"], ["84180.58", "0.209200"], ["84200.00", "0.000269"], ["84205.10", "0.309821"], ["84206.65", "0.006915"], ["84207.01", "0.209200"], ["84210.00", "0.002672"], ["84214.30", "0.001469"], ["84225.00", "0.000403"], ["84233.38", "0.001273"], ["84240.00", "0.002806"], ["84242.28", "1.728229"], ["84250.00", "0.000269"], ["84252.44", "0.000143"], ["84252.70", "0.305281"], ["84255.20", "0.296078"], ["84259.99", "0.000017"], ["84260.00", "0.000269"], ["84261.00", "0.000130"], ["84266.08", "0.000016"], ["84266.67", "0.000078"], ["84269.24", "0.000032"], ["84270.00", "0.002269"], ["84270.98", "0.000052"], ["84272.72", "0.000105"], ["84279.98", "0.000239"], ["84280.00", "0.000346"], ["84285.00", "0.000031"], ["84285.71", "0.000010"], ["84285.95", "0.000028"], ["84286.79", "0.000016"], ["84287.50", "0.000076"], ["84288.89", "0.000361"], ["84294.68", "0.000019"], ["84297.06", "0.000035"], ["84300.00", "0.010544"], ["84307.00", "0.000113"], ["84309.09", "0.000010"], ["84309.40", "0.026820"], ["84310.34", "0.000315"], ["84310.35", "0.000146"], ["84314.97", "0.000008"], ["84317.40", "0.000010"], ["84318.59", "0.000027"], ["84319.15", "0.000137"], ["84319.18", "0.000039"], ["84324.32", "0.000008"], ["84325.00", "0.000082"], ["84325.07", "0.000161"], ["84326.09", "0.000010"], ["84326.42", "0.000023"], ["84327.14", "0.000039"], ["84327.73", "0.041940"], ["84328.95", "0.000174"], ["84329.64", "0.000026"], ["84330.00", "0.002000"], ["84332.00", "0.010008"], ["84333.33", "0.002262"], ["84333.36", "0.000010"], ["84333.38", "0.000008"], ["84334.48", "0.000096"], ["84334.77", "0.000022"], ["84336.00", "0.000133"], ["84336.23", "0.000013"], ["84336.29", "0.000010"], ["84336.34", "0.000176"], ["84337.25", "0.000067"], ["84337.35", "0.000008"], ["84338.46", "0.000015"], ["84339.21", "0.000010"], ["84339.29", "0.000029"], ["84339.62", "0.000051"], ["84340.00", "0.018287"], ["84340.72", "0.000066"], ["84341.01", "0.000008"], ["84342.11", "0.000051"], ["84342.63", "0.000009"], ["84342.70", "0.000423"], ["84343.07", "0.000014"], ["84343.70", "0.000075"], ["84343.97", "0.000188"], ["84345.20", "0.001403"], ["84346.43", "0.000128"], ["84346.94", "0.000085"], ["84347.69", "0.000009"], ["84347.83", "0.016818"], ["84348.21", "0.000036"], ["84348.27", "0.012402"], ["84348.62", "0.000072"], ["84350.00", "0.000041"], ["84350.79", "0.000033"], ["84354.58", "0.000115"], ["84354.64", "0.000018"], ["84354.82", "0.000078"], ["84354.84", "0.000194"], ["84356.98", "0.000048"], ["84357.14", "0.000273"], ["84358.29", "0.000024"], ["84359.83", "0.000010"], ["84360.00", "0.003121"], ["84363.63", "0.000057"], ["84363.64", "0.000078"], ["84366.14", "0.000162"], ["84366.15", "0.000061"], ["84366.19", "0.000022"], ["84366.60", "0.000011"], ["84366.96", "0.000018"], ["84367.10", "0.000014"], ["84367.82", "0.000476"], ["84368.38", "0.000009"], ["84368.42", "0.000284"], ["84370.00", "0.000052"], ["84370.59", "0.000071"], ["84370.97", "0.000020"], ["84371.86", "0.000012"], ["84375.00", "0.001884"], ["84375.80", "0.000583"], ["84376.31", "0.000016"], ["84378.11", "0.000008"], ["84378.38", "0.000009"], ["84378.45", "0.000015"], ["84379.70", "0.002343"], ["84380.00", "0.031680"], ["84381.82", "0.000008"], ["84382.00", "0.000035"], ["84382.35", "0.000071"], ["84383.41", "0.000053"], ["84383.69", "0.000248"], ["84384.38", "0.000424"], ["84384.61", "0.000008"], ["84386.19", "0.000019"], ["84386.67", "0.000013"], ["84387.50", "0.006969"], ["84387.76", "0.000024"], ["84389.61", "0.000088"], ["84390.00", "0.002000"], ["84390.01", "0.000387"], ["84391.30", "0.000018"], ["84393.31", "0.000050"], ["84393.33", "0.000008"], ["84396.55", "0.000016"], ["84396.98", "0.007500"], ["84397.59", "0.000008"], ["84397.69", "0.000275"], ["84398.26", "0.000068"], ["84399.54", "0.000030"], ["84399.91", "0.000018"], ["84399.99", "0.000022"], ["84400.00", "0.057899"], ["84400.18", "0.000024"], ["84402.40", "0.001273"], ["84403.39", "0.000023"], ["84403.76", "0.000099"], ["84403.98", "0.007500"], ["84404.26", "0.000137"], ["84404.28", "0.000039"], ["84406.06", "0.000008"], ["84406.83", "0.000064"], ["84407.50", "0.000031"], ["84410.00", "0.000059"], ["84410.04", "0.000025"], ["84411.11", "0.000361"], ["84411.43", "0.000008"], ["84411.76", "0.000101"], ["84411.77", "0.000020"], ["84412.50", "0.000049"], ["84413.04", "0.000010"], ["84413.33", "0.000073"], ["84413.79", "0.000135"], ["84414.29", "0.000074"], ["84414.41", "0.000061"], ["84415.09", "0.000008"], ["84416.67", "0.000355"], ["84418.34", "0.000046"], ["84419.69", "0.000023"], ["84420.00", "0.002238"], ["84420.17", "0.041940"], ["84422.71", "0.000010"], ["84423.08", "0.000067"], ["84423.53", "0.000105"], ["84424.00", "0.000022"], ["84424.12", "0.000146"], ["84425.69", "0.000314"], ["84426.68", "0.000101"], ["84427.08", "0.000014"], ["84427.92", "0.000323"], ["84428.57", "0.000057"], ["84429.82", "0.000022"], ["84430.50", "0.000113"], ["84430.74", "0.000010"], ["84430.77", "0.000015"], ["84431.23", "0.000039"], ["84432.43", "0.000008"], ["84433.33", "0.000347"], ["84434.78", "0.000008"], ["84435.26", "0.000161"], ["84436.26", "0.000009"], ["84437.14", "0.000017"], ["84437.50", "0.000725"], ["84437.75", "0.000013"], ["84438.44", "0.000176"], ["84440.00", "0.000008"], ["84442.54", "0.000096"], ["84443.07", "0.000423"], ["84444.25", "0.000013"], ["84444.41", "0.000371"], ["84444.44", "0.000530"], ["84444.92", "0.000022"], ["84446.04", "0.000016"], ["84446.38", "0.000013"], ["84446.43", "0.000036"], ["84447.80", "0.000718"], ["84448.75", "0.000066"], ["84448.98", "0.000085"], ["84449.11", "0.000028"], ["84449.34", "0.000010"], ["84450.00", "0.007851"], ["84451.88", "0.000010"], ["84452.66", "0.000009"], ["84453.76", "0.000054"], ["84454.43", "0.000061"], ["84454.53", "0.000019"], ["84454.55", "0.000083"], ["84454.60", "0.000093"], ["84454.70", "0.508335"], ["84455.31", "0.000028"], ["84456.14", "0.000033"], ["84456.52", "0.002633"], ["84457.00", "0.000009"], ["84458.06", "0.000020"], ["84458.72", "0.000072"], ["84458.82", "0.000071"], ["84458.97", "0.000153"], ["84459.08", "0.000008"], ["84459.22", "0.000188"], ["84459.69", "0.000051"], ["84460.00", "0.000086"], ["84460.23", "0.000010"], ["84460.49", "0.000009"], ["84460.87", "0.000069"], ["84460.91", "0.000012"], ["84461.00", "0.000008"], ["84462.50", "0.000076"], ["84464.28", "0.000008"], ["84465.83", "0.000016"], ["84466.67", "0.000157"], ["84470.34", "0.000017"], ["84470.59", "0.000071"], ["84473.14", "0.000126"], ["84473.68", "0.000192"], ["84474.78", "0.000099"], ["84475.00", "0.007068"], ["84475.81", "0.000039"], ["84476.97", "0.000063"], ["84477.61", "0.000095"], ["84477.67", "0.000008"], ["84478.74", "0.000036"], ["84479.37", "0.000090"], ["84480.00", "0.002308"], ["84481.00", "0.000069"], ["84481.77", "0.000011"], ["84482.67", "0.000133"], ["84482.76", "0.000016"], ["84485.20", "0.000537"], ["84485.39", "0.000020"], ["84485.71", "0.000128"], ["84485.98", "0.000034"], ["84486.49", "0.000009"], ["84486.82", "0.000135"], ["84487.00", "0.000119"], ["84487.16", "0.000035"], ["84487.32", "0.000024"], ["84487.95", "0.000008"], ["84488.88", "0.000025"], ["84489.36", "0.000137"], ["84489.39", "0.000039"], ["84489.80", "0.000010"], ["84490.00", "0.007510"], ["84490.13", "0.000093"], ["84490.32", "0.000008"], ["84490.91", "0.000018"], ["84491.26", "0.000008"], ["84491.87", "0.000019"], ["84492.06", "0.000009"], ["84496.43", "0.000273"], ["84496.73", "0.000043"], ["84497.14", "0.000008"], ["84497.26", "0.000010"], ["84500.00", "1.106468"], ["84500.03", "0.000010"], ["84500.04", "0.000008"], ["84500.11", "0.000012"], ["84501.24", "0.000010"], ["84501.28", "0.000019"], ["84501.99", "0.000009"], ["84503.33", "0.010000"], ["84503.57", "0.000074"], ["84504.50", "0.000061"], ["84504.74", "0.000013"], ["84506.54", "0.000008"], ["84506.67", "0.000008"], ["84508.00", "0.001210"], ["84508.37", "0.000050"], ["84508.46", "0.000013"], ["84508.47", "0.000023"], ["84510.34", "0.000135"], ["84512.00", "0.000012"], ["84512.19", "0.000016"], ["84512.61", "0.041940"], ["84512.95", "0.000023"], ["84514.29", "0.000059"], ["84516.67", "0.000010"], ["84517.54", "0.000022"], ["84517.86", "0.000016"], ["84518.98", "0.000029"], ["84520.00", "0.000318"], ["84520.50", "0.000238"], ["84520.67", "0.002384"], ["84521.85", "0.000033"], ["84522.06", "0.000041"], ["84523.08", "0.000015"], ["84523.48", "0.000015"], ["84523.81", "0.000024"], ["84524.00", "0.000035"], ["84524.83", "0.000009"], ["84525.00", "0.000010"], ["84525.82", "0.000099"], ["84527.47", "0.000608"], ["84528.57", "0.000008"], ["84530.00", "0.000031"], ["84533.01", "0.000591"], ["84533.33", "0.003186"], ["84534.53", "0.000461"]], "bids": [["83888.41", "0.971411"], ["83888.00", "0.000032"], ["83887.10", "0.001010"], ["83887.00", "0.000115"], ["83886.00", "0.000032"], ["83885.75", "0.001554"], ["83885.10", "0.001315"], ["83885.00", "0.000032"], ["83884.36", "0.006400"], ["83884.35", "0.005608"], ["83884.34", "0.008543"], ["83884.29", "0.007435"], ["83884.00", "0.000032"], ["83883.55", "0.013797"], ["83883.54", "0.009751"], ["83883.10", "0.003461"], ["83883.00", "0.000032"], ["83882.00", "0.000032"], ["83881.10", "0.009335"], ["83881.00", "0.000032"], ["83880.20", "0.008731"], ["83880.11", "0.019273"], ["83880.00", "0.003276"], ["83879.50", "0.050653"], ["83879.39", "0.009883"], ["83879.35", "0.024166"], ["83879.32", "0.005129"], ["83879.31", "0.000016"], ["83879.10", "0.024567"], ["83879.00", "0.000032"], ["83878.00", "0.000032"], ["83877.91", "0.013909"], ["83877.29", "0.000024"], ["83877.10", "0.064651"], ["83877.01", "0.000023"], ["83877.00", "0.000032"], ["83876.00", "0.000032"], ["83875.28", "0.439775"], ["83875.16", "0.000179"], ["83875.10", "0.170134"], ["83875.00", "0.000819"], ["83874.88", "0.089671"], ["83874.84", "0.248103"], ["83874.29", "0.004025"], ["83874.00", "0.000032"], ["83873.87", "0.000061"], ["83873.52", "0.000135"], ["83873.19", "0.084115"], ["83873.16", "0.017854"], ["83873.10", "0.447719"], ["83873.00", "0.000032"], ["83872.56", "0.018293"], ["83872.43", "0.005959"], ["83872.00", "0.000032"], ["83871.54", "0.055772"], ["83871.15", "0.007146"], ["83871.10", "1.178208"], ["83871.01", "0.017139"], ["83871.00", "0.000032"], ["83870.64", "0.028925"], ["83870.59", "0.007355"], ["83870.32", "1.918016"], ["83870.31", "0.209200"], ["83870.08", "0.016972"], ["83870.00", "0.000662"], ["83869.85", "0.052072"], ["83869.78", "0.225351"], ["83869.76", "0.025237"], ["83869.61", "0.008202"], ["83869.27", "0.017387"], ["83869.25", "0.008286"], ["83869.10", "3.100548"], ["83869.00", "0.000032"], ["83868.97", "3.001746"], ["83868.78", "0.008445"], ["83868.74", "0.005948"], ["83868.72", "0.006486"], ["83868.68", "0.008031"], ["83868.60", "0.010053"], ["83868.39", "0.002014"], ["83868.24", "0.260337"], ["83868.00", "0.000032"], ["83867.74", "0.012682"], ["83867.57", "0.008076"], ["83867.42", "0.007811"], ["83867.38", "0.009229"], ["83867.33", "0.007775"], ["83867.32", "0.007319"], ["83867.27", "0.018556"], ["83867.19", "1.073714"], ["83867.10", "8.159336"], ["83867.00", "0.000032"], ["83866.90", "0.406620"], ["83866.80", "0.006240"], ["83866.67", "0.002945"], ["83866.60", "2.050770"], ["83866.49", "0.021174"], ["83866.40", "0.405960"], ["83866.20", "0.405960"], ["83866.15", "0.268936"], ["83866.10", "3.711210"], ["83866.00", "0.084780"], ["83865.70", "0.710970"], ["83865.36", "0.223134"], ["83865.00", "0.000956"], ["83864.90", "0.710970"], ["83864.88", "0.076271"], ["83864.72", "0.073368"], ["83864.60", "0.752460"], ["83864.23", "0.056485"], ["83864.00", "0.084600"], ["83863.50", "0.068490"], ["83863.00", "0.000032"], ["83862.70", "0.008111"], ["83862.50", "0.006969"], ["83862.00", "0.084600"], ["83861.90", "0.209200"], ["83861.60", "0.107400"], ["83861.00", "0.000032"], ["83860.83", "0.021641"], ["83860.34", "0.019085"], ["83860.30", "0.008282"], ["83860.29", "0.005105"], ["83860.00", "0.084600"], ["83859.56", "0.006221"], ["83859.54", "0.000008"], ["83859.00", "0.132000"], ["83858.70", "3.174060"], ["83858.20", "0.132000"], ["83858.06", "0.000008"], ["83858.01", "0.014153"], ["83858.00", "8.421180"], ["83857.80", "0.072510"], ["83857.40", "0.240000"], ["83857.30", "0.153580"], ["83857.20", "0.120000"], ["83857.14", "0.000079"], ["83857.13", "0.000019"], ["83857.00", "0.000032"], ["83856.60", "0.012450"], ["83856.46", "0.715508"], ["83856.11", "0.010000"], ["83856.00", "0.000032"], ["83855.90", "0.120000"], ["83855.44", "0.000008"], ["83855.42", "0.000008"], ["83855.30", "0.035730"], ["83855.00", "0.010830"], ["83854.78", "0.013994"], ["83854.72", "0.000878"], ["83854.55", "0.000009"], ["83854.17", "0.000020"], ["83854.00", "0.000032"], ["83853.50", "0.209200"], ["83853.00", "0.000032"], ["83852.94", "0.000071"], ["83852.50", "0.000043"], ["83852.00", "0.000032"], ["83851.85", "0.000011"], ["83851.84", "0.000219"], ["83851.00", "0.000032"], ["83850.00", "0.002993"], ["83849.00", "0.000032"], ["83848.39", "0.000020"], ["83848.00", "0.000032"], ["83847.20", "0.000396"], ["83847.00", "0.000032"], ["83846.15", "0.000111"], ["83846.00", "0.000032"], ["83845.10", "0.209200"], ["83845.00", "0.000032"], ["83844.83", "0.000008"], ["83844.69", "0.314647"], ["83844.53", "0.007450"], ["83844.00", "0.000032"], ["83843.34", "0.003604"], ["83843.00", "0.000032"], ["83842.11", "0.000033"], ["83842.00", "0.000032"], ["83841.66", "0.008591"], ["83841.18", "0.000071"], ["83841.00", "0.000032"], ["83840.49", "0.000200"], ["83840.17", "0.007352"], ["83840.12", "0.007264"], ["83840.03", "0.007669"], ["83840.00", "0.001077"], ["83839.72", "0.000033"], ["83839.51", "0.017490"], ["83839.18", "0.000016"], ["83839.00", "0.000032"], ["83838.00", "0.000032"], ["83837.84", "0.000009"], ["83837.69", "0.001175"], ["83837.65", "0.001178"], ["83837.59", "0.000012"], ["83837.00", "0.000017"], ["83836.70", "0.209200"], ["83836.36", "0.000008"], ["83835.56", "0.000009"], ["83835.00", "0.000522"], ["83834.48", "0.000135"], ["83831.11", "0.000011"], ["83830.59", "0.000010"], ["83830.00", "0.000693"], ["83828.57", "0.000016"], ["83828.30", "0.209200"], ["83827.90", "0.208446"], ["83826.67", "0.000081"], ["83825.10", "5.084867"], ["83822.22", "0.000025"], ["83822.12", "0.000067"], ["83820.00", "0.002643"], ["83819.90", "0.209200"], ["83818.18", "0.001568"], ["83818.17", "0.000029"], ["83817.80", "0.000948"], ["83816.70", "4.721662"], ["83816.67", "0.000010"], ["83816.28", "0.000009"], ["83816.00", "0.000008"], ["83815.79", "0.000022"], ["83815.75", "0.000009"], ["83815.37", "0.000022"], ["83813.00", "0.000113"], ["83811.50", "0.209200"], ["83811.34", "0.071253"], ["83810.74", "0.000019"], ["83810.12", "0.057001"], ["83810.00", "0.000630"], ["83808.53", "0.000039"], ["83808.51", "0.000137"], ["83808.30", "4.812464"], ["83807.88", "0.000051"], ["83807.53", "0.000010"], ["83806.78", "0.071045"], ["83804.35", "0.000010"], ["83803.57", "0.000016"], ["83803.10", "0.209200"], ["83802.81", "0.000022"], ["83800.91", "0.000012"], ["83800.00", "0.041881"], ["83799.90", "4.449259"], ["83799.34", "0.000093"], ["83796.61", "0.001213"], ["83795.82", "0.001810"], ["83795.00", "0.000031"], ["83794.70", "0.209200"], ["83794.17", "0.000096"], ["83793.10", "0.000016"], ["83791.50", "4.994066"], ["83791.03", "0.000996"], ["83791.02", "0.000351"], ["83790.15", "0.000024"], ["83790.00", "0.002737"], ["83789.29", "0.000074"], ["83787.88", "0.000010"], ["83786.90", "0.003620"], ["83786.30", "0.209200"], ["83785.71", "0.000081"], ["83785.15", "0.010010"], ["83784.62", "0.000015"], ["83784.36", "0.000069"], ["83784.22", "0.012345"], ["83784.02", "0.000022"], ["83783.78", "0.000069"], ["83783.12", "0.000008"], ["83783.10", "3.995253"], ["83780.48", "0.000016"], ["83780.00", "0.000943"], ["83779.93", "0.000028"], ["83777.90", "0.209200"], ["83777.78", "0.000679"], ["83777.60", "0.000013"], ["83777.18", "0.000013"], ["83775.00", "0.006969"], ["83774.70", "5.629674"], ["83774.10", "0.000161"], ["83773.31", "0.000154"], ["83773.11", "0.041940"], ["83772.88", "0.000023"], ["83770.40", "0.295591"], ["83770.00", "0.000630"], ["83769.50", "0.209200"], ["83769.28", "0.000972"], ["83768.46", "0.000008"], ["83768.00", "0.000012"], ["83767.74", "0.000008"], ["83767.68", "0.026822"], ["83766.84", "0.000023"], ["83766.30", "5.266470"], ["83765.06", "0.000008"], ["83764.71", "0.000071"], ["83763.64", "0.000010"], ["83762.70", "0.001459"], ["83762.50", "0.000076"], ["83761.90", "0.000024"], ["83761.29", "0.000020"], ["83761.11", "0.209200"], ["83760.00", "0.004786"], ["83758.93", "0.000036"], ["83758.00", "0.000353"], ["83757.90", "4.267656"], ["83757.40", "0.000537"], ["83756.08", "0.000099"], ["83755.56", "0.000134"], ["83754.70", "0.000013"], ["83754.39", "0.000033"], ["83752.94", "0.000071"], ["83752.72", "0.209200"], ["83752.37", "0.000119"], ["83752.09", "0.000314"], ["83752.00", "0.000034"], ["83750.67", "0.000146"], ["83750.44", "0.000067"], ["83750.00", "0.041201"], ["83749.66", "0.000016"], ["83749.50", "4.176855"], ["83749.33", "0.000133"], ["83748.54", "0.000012"], ["83746.09", "0.000010"], ["83745.16", "0.000389"], ["83743.29", "0.001451"], ["83741.88", "0.005970"], ["83741.10", "5.175668"], ["83740.92", "0.005970"], ["83740.51", "0.000423"], ["83740.00", "0.000709"], ["83739.60", "0.000048"], ["83739.28", "0.000051"], ["83739.13", "0.000008"], ["83737.93", "0.000135"], ["83737.37", "0.000012"], ["83737.00", "0.000009"], ["83736.94", "0.000104"], ["83736.84", "0.000183"], ["83736.35", "0.125895"], ["83736.33", "0.000025"], ["83734.69", "0.000085"], ["83733.33", "0.003222"], ["83732.70", "5.448072"], ["83732.10", "0.000009"], ["83731.48", "0.000124"], ["83730.00", "0.002632"], ["83729.73", "0.000009"], ["83729.39", "0.000008"], ["83729.32", "0.000035"], ["83728.57", "0.000017"], ["83728.37", "0.001273"], ["83728.07", "0.000022"], ["83727.71", "0.000009"], ["83727.27", "0.000082"], ["83726.20", "0.000016"], ["83725.00", "0.000286"], ["83724.30", "3.904452"], ["83723.72", "0.000176"], ["83723.64", "0.000009"], ["83723.61", "0.000883"], ["83723.43", "0.000039"], ["83723.40", "0.000205"], ["83721.56", "0.000015"], ["83720.00", "0.003069"], ["83719.46", "0.000053"], ["83717.93", "0.000065"], ["83717.46", "0.000009"], ["83717.45", "0.000040"], ["83717.39", "0.000010"], ["83715.90", "4.540060"], ["83715.48", "0.000010"], ["83714.29", "0.009987"], ["83714.28", "0.000836"], ["83713.80", "0.000024"], ["83713.71", "0.000323"], ["83713.40", "0.000161"], ["83713.33", "0.000008"], ["83711.93", "0.000018"], ["83710.00", "0.000655"], ["83709.88", "0.000107"], ["83709.30", "0.308301"], ["83707.50", "4.903265"], ["83707.07", "0.000067"], ["83706.90", "0.000016"], ["83706.67", "0.000013"], ["83705.85", "0.000019"], ["83705.32", "0.000065"], ["83705.18", "0.000009"], ["83705.07", "0.000860"], ["83705.06", "0.000860"], ["83704.00", "0.001184"], ["83703.70", "0.000455"], ["83703.00", "0.000024"], ["83702.93", "0.000050"], ["83702.60", "0.000039"], ["83702.50", "0.000033"], ["83702.48", "0.000057"], ["83701.92", "0.000067"], ["83701.28", "0.000248"], ["83700.00", "0.030866"], ["83699.88", "0.000008"], ["83699.20", "0.001475"], ["83699.10", "4.358458"], ["83697.23", "0.000095"], ["83695.65", "0.003535"], ["83695.63", "0.000011"], ["83693.69", "0.000061"], ["83692.52", "0.000066"], ["83692.38", "0.000007"], ["83692.31", "0.000031"], ["83691.74", "0.000653"], ["83690.84", "0.000162"], ["83690.70", "4.086054"], ["83690.48", "0.000248"], ["83690.00", "0.000632"], ["83689.78", "0.001684"], ["83689.50", "0.000113"], ["83688.89", "0.000009"], ["83688.07", "0.000072"], ["83687.50", "0.006969"], ["83687.00", "0.000008"], ["83686.11", "0.000096"], ["83684.21", "0.000102"], ["83683.67", "0.000184"], ["83682.30", "5.357271"], ["83681.82", "0.000175"], ["83680.67", "0.041940"], ["83680.00", "0.001114"], ["83679.44", "0.000361"], ["83678.41", "0.000010"], ["83678.10", "0.307713"], ["83678.08", "0.000145"], ["83677.42", "0.000008"], ["83677.37", "0.000008"], ["83676.47", "0.000080"], ["83675.68", "0.000008"], ["83675.62", "0.000011"], ["83675.36", "0.000013"], ["83675.20", "0.000018"], ["83675.00", "0.000458"], ["83674.70", "0.000008"], ["83674.19", "0.000020"], ["83674.00", "0.001195"], ["83673.90", "5.538873"], ["83673.87", "0.000022"], ["83673.58", "0.000023"], ["83672.96", "0.002168"], ["83672.50", "0.000031"], ["83672.25", "0.003958"], ["83672.00", "0.000035"], ["83671.36", "0.000099"], ["83670.59", "0.000105"], ["83670.05", "0.000033"], ["83670.00", "0.004119"], ["83669.66", "0.000010"], ["83669.58", "0.000251"], ["83669.09", "0.000135"], ["83667.80", "0.000023"], ["83667.23", "0.012503"], ["83667.20", "0.001444"], ["83666.67", "0.052199"], ["83666.66", "0.000513"], ["83666.65", "0.000122"], ["83666.00", "0.118134"], ["83665.50", "4.630861"], ["83664.71", "0.000071"], ["83664.19", "0.000073"], ["83663.98", "0.000008"], ["83663.95", "0.000022"], ["83663.91", "0.000161"], ["83662.50", "0.000077"], ["83661.97", "0.000052"], ["83661.60", "0.000042"], ["83661.08", "0.004152"], ["83660.71", "0.000309"], ["83660.14", "0.000016"], ["83660.00", "0.000656"], ["83659.61", "0.000454"], ["83659.49", "0.000012"], ["83659.44", "0.000613"], ["83658.54", "0.000036"], ["83656.60", "0.000607"], ["83654.23", "0.000009"], ["83653.94", "0.000133"], ["83653.67", "0.001695"], ["83653.31", "0.000015"], ["83652.80", "0.000119"], ["83652.48", "0.000188"], ["83651.65", "0.000018"], ["83651.16", "0.000896"], ["83650.84", "0.003326"], ["83650.00", "0.030656"], ["83648.96", "0.000030"], ["83647.46", "0.000224"], ["83647.06", "0.000040"], ["83646.67", "0.000018"], ["83645.83", "0.000014"], ["83644.86", "0.000034"], ["83644.33", "0.000013"], ["83643.18", "0.000052"], ["83641.86", "0.000379"], ["83641.62", "0.002925"]], "checksum": 0, "ts": "1742560772536"}], "ts": 1742560772546}}
{"exchange": "BYBIT", "timestamp": 1742560772.740986, "message": {"topic": "orderbook.200.BTCUSDT", "ts": 1742560772720, "type": "delta", "data": {"s": "BTCUSDT", "b": [["83909.7", "0.888968"], ["83909.4", "0.18525"], ["83909.3", "0.373529"], ["83909.1", "0"], ["83908.9", "0.051326"], ["83901.3", "0.01"], ["83900.9", "0.005"], ["83898.2", "0.111404"], ["83888.4", "0.164484"], ["83879.3", "0.289188"], ["83873.7", "0.01288"], ["83861.9", "11.425261"], ["83853.5", "0"], ["83841.9", "0"], ["83841", "0"], ["83840.2", "0"], ["83840", "0"]], "a": [["83909.4", "0"], ["83909.8", "0.048731"], ["83911.3", "0"], ["83917.4", "0"], ["83917.8", "0.015"], ["83918.9", "0.003286"], ["83919.2", "0.001333"], ["83921.4", "0.06601"], ["83921.5", "0.071529"], ["83923.4", "0.112755"], ["83923.7", "0"], ["83924.8", "0.121514"], ["83925.2", "0.071526"], ["83933.2", "0.182468"], ["83942.3", "0.279915"], ["83948.3", "0"], ["83948.4", "0"], ["83948.5", "0.012728"], ["83948.6", "0.024683"], ["83954", "0.064928"], ["83966.4", "0"], ["83972", "2.606277"], ["83981.8", "0.003291"]], "u": 47435, "seq": 67552910743}, "cts": 1742560772715}}
{"exchange": "BITGET", "timestamp": 1742560772.778132, "message": {"action": "update", "arg": {"instType": "SPOT", "channel": "books", "instId": "BTCUSDT"}, "data": [{"asks": [["83888.42", "0.728863"], ["83937.10", "0.001753"], ["83939.10", "0.004612"], ["83941.10", "0.012137"], ["83943.10", "0.031939"], ["83945.10", "0.084050"], ["83947.10", "0.221184"], ["83949.10", "0.582064"], ["83951.10", "1.531747"], ["83951.40", "0.003660"], ["83951.70", "0.379170"], ["83953.90", "0.030210"], ["83954.00", "0.114990"], ["83955.40", "0"], ["83956.50", "1.661940"], ["83957.70", "2.360640"], ["83961.20", "0.322590"], ["83961.40", "0"], ["83993.10", "4.176855"], ["84001.50", "5.084867"], ["84009.90", "5.175668"], ["84018.30", "4.812464"], ["84026.70", "4.630861"], ["84035.10", "4.267656"], ["84043.50", "4.994066"], ["84051.90", "5.448072"], ["84068.70", "3.904452"], ["84077.10", "5.629674"], ["84085.50", "3.995253"], ["84093.90", "4.721662"], ["84102.30", "4.540060"], ["84110.70", "5.357271"], ["84119.10", "4.086054"], ["84127.50", "4.358458"], ["84135.90", "5.538873"], ["84144.30", "4.449259"]], "bids": [["83888.41", "1.168549"], ["83879.93", "0.113579"], ["83875.28", "0.323703"], ["83859.80", "0.269760"], ["83855.00", "0.000032"], ["83825.10", "5.629674"], ["83816.70", "4.086054"], ["83808.30", "3.904452"], ["83799.90", "4.812464"], ["83791.50", "5.084867"], ["83774.70", "5.448072"], ["83766.30", "4.267656"], ["83757.90", "4.540060"], ["83749.50", "4.358458"], ["83741.10", "5.266470"], ["83732.70", "4.176855"], ["83724.30", "5.538873"], ["83715.90", "4.449259"], ["83707.50", "5.357271"], ["83699.10", "4.630861"], ["83690.70", "5.175668"], ["83682.30", "4.903265"], ["83673.90", "4.994066"], ["83665.50", "4.721662"], ["83641.86", "0"], ["83641.62", "0"]], "checksum": 1156373433, "ts": "1742560772748"}], "ts": 1742560772751}}
{"exchange": "BYBIT", "timestamp": 1742560773.022151, "message": {"topic": "orderbook.200.BTCUSDT", "ts": 1742560772919, "type": "delta", "data": {"s": "BTCUSDT", "b": [["83909.9", "0.870322"], ["83909.8", "0.125801"], ["83909.7", "0.221076"], ["83909.4", "0"], ["83909.3", "0.192231"], ["83906.5", "0"], ["83906.3", "0.067535"], ["83902.3", "0.113608"], ["83901.5", "0.005"], ["83901.3", "0.005"], ["83900.1", "0.119143"], ["83899.3", "0.116605"], ["83898.2", "0.001333"], ["83897.7", "0.048"], ["83896.4", "0"], ["83895.5", "0.124269"], ["83889.5", "0.189014"], ["83888.5", "0.263861"], ["83888.4", "0"], ["83886.1", "0.713246"], ["83881.5", "0.290184"], ["83880.4", "0.36626"], ["83879.3", "0"], ["83878.6", "0"], ["83871", "0.056022"], ["83867.6", "11.427395"], ["83866.3", "0.01339"], ["83861.9", "0"], ["83855.7", "0.023835"], ["83843.5", "0.000149"], ["83843.2", "0"], ["83843.1", "0"], ["83842.5", "0"], ["83842.4", "0"], ["83842", "0"]], "a": [["83909.8", "0"], ["83910", "0.021948"], ["83910.5", "0.003282"], ["83911.1", "0.089678"], ["83919", "0"], ["83921.4", "0"], ["83921.5", "0"], ["83922.9", "0"], ["83923.4", "0.001333"], ["83923.5", "0"], ["83924", "0"], ["83924.5", "0.117705"], ["83924.8", "0"], ["83924.9", "0"], ["83925.2", "0"], ["83925.6", "0"], ["83927.8", "0.027252"], ["83927.9", "0.071524"], ["83928.1", "0"], ["83928.4", "0.114308"], ["83929", "0.079781"], ["83930.1", "0.000512"], ["83931.2", "0"], ["83931.5", "0.178763"], ["83932.5", "0.000631"], ["83933.2", "0"], ["83933.3", "0"], ["83934.3", "0.175965"], ["83935.1", "0"], ["83935.4", "0.186483"], ["83936.6", "0"], ["83936.8", "0"], ["83937.7", "0"], ["83937.9", "0"], ["83938.2", "0"], ["83938.4", "0"], ["83939.8", "0.003288"], ["83942.3", "0"], ["83942.4", "0.307939"], ["83943.4", "0.297381"], ["83945.6", "0"], ["83948.3", "0.562218"], ["83948.5", "0"], ["83948.6", "0.011955"], ["83949.1", "0"], ["83949.2", "0"], ["83949.3", "0.013691"], ["83949.4", "0.014284"], ["83949.9", "0.043564"], ["83950", "0.04"], ["83951.2", "0.545816"], ["83954", "0.001466"], ["83956.8", "0.063462"], ["83961.7", "0"], ["83965.4", "0.001333"], ["83969", "0"], ["83972", "0"], ["83975.3", "0.003564"], ["83977.7", "2.606277"], ["83981.8", "0.174291"], ["83982.2", "0.001333"], ["83982.6", "0.011991"], ["83982.9", "0.000333"], ["83983", "3.423114"], ["83983.6", "0.119143"], ["83985.5", "0.000514"], ["83985.7", "0.059399"], ["83986", "0.003292"], ["83986.3", "0.001466"], ["83986.4", "0.013324"], ["83987.1", "0.000333"], ["83988.3", "0.011991"], ["83988.6", "0.625678"], ["83988.7", "0.011991"]], "u": 47436, "seq": 67552911618}, "cts": 1742560772917}}
{"exchange": "BITGET", "timestamp": 1742560773.023769, "message": {"action": "update", "arg": {"instType": "SPOT", "channel": "books", "instId": "BTCUSDT"}, "data": [{"asks": [["83888.42", "0.572460"], ["83896.11", "0"], ["83896.40", "0"], ["83896.88", "0.015502"], ["83897.39", "0.096110"], ["83904.37", "0.042853"], ["83915.15", "0"], ["83915.95", "0"], ["83916.82", "0"], ["83917.90", "0"], ["83918.41", "0"], ["83919.19", "0"], ["83921.12", "0"], ["83926.66", "0.006356"], ["83931.10", "0"], ["83932.40", "0.001035"], ["83933.10", "0"], ["83934.40", "0.001034"], ["83935.10", "0"], ["83936.40", "0.001047"], ["83937.10", "0"], ["83938.40", "0.001011"], ["83939.10", "0"], ["83940.40", "0.001002"], ["83941.10", "0"], ["83942.40", "0.001771"], ["83943.10", "0"], ["83944.40", "0.004776"], ["83945.10", "0"], ["83946.40", "0.012568"], ["83947.10", "0"], ["83948.40", "0.033073"], ["83949.10", "0"], ["83950.40", "0.087036"], ["83951.10", "0"], ["83951.40", "0"], ["83951.50", "0"], ["83951.60", "0"], ["83951.70", "0"], ["83952.40", "0.229040"], ["83953.10", "0.001032"], ["83953.90", "0.031260"], ["83954.00", "0.030630"], ["83954.20", "0.298710"], ["83954.70", "0"], ["83954.90", "0"], ["83955.10", "0.330540"], ["83956.00", "0.159240"], ["83956.50", "1.662150"], ["83956.90", "0.222390"], ["83957.00", "0.066480"], ["83957.40", "0.024780"], ["83957.60", "0.379350"], ["83957.70", "0"], ["83958.30", "1.144110"], ["83959.10", "0"], ["83959.90", "0"], ["83960.70", "1.478550"], ["83961.20", "0"], ["83961.40", "0.144780"], ["83961.60", "0.012630"], ["83961.70", "0.029460"], ["83961.90", "0.005730"], ["83962.00", "0.296610"], ["83962.10", "1.560000"], ["83993.10", "0"], ["83994.40", "4.267591"], ["84001.50", "0"], ["84002.80", "4.085992"], ["84009.90", "0"], ["84011.20", "4.721590"], ["84018.30", "0"], ["84019.60", "4.812390"], ["84026.70", "0"], ["84028.00", "5.266389"], ["84035.10", "0"], ["84036.40", "4.993990"], ["84043.50", "0"], ["84044.80", "5.538789"], ["84051.90", "0"], ["84053.20", "4.903190"], ["84060.30", "0"], ["84061.60", "5.447989"], ["84068.70", "0"], ["84070.00", "3.995192"], ["84077.10", "0"], ["84078.40", "4.176792"], ["84085.50", "0"], ["84086.80", "5.084790"], ["84093.90", "0"], ["84095.20", "4.539991"], ["84102.30", "0"], ["84103.60", "5.175589"], ["84110.70", "0"], ["84112.00", "4.630791"], ["84119.10", "0"], ["84120.40", "4.449191"], ["84127.50", "0"], ["84128.80", "3.904392"], ["84135.90", "0"], ["84137.20", "5.357189"], ["84144.30", "0"], ["84145.60", "5.629589"], ["84152.70", "0"], ["84154.00", "4.358391"], ["84535.32", "0.000039"], ["84536.36", "0.000053"], ["84537.04", "0.000958"], ["84538.75", "0.000011"], ["84540.00", "0.000021"], ["84540.54", "0.000184"], ["84540.97", "0.000065"]], "bids": [["83888.41", "1.229425"], ["83888.40", "0.001365"], ["83887.10", "0"], ["83886.40", "0.002226"], ["83885.75", "0"], ["83885.10", "0"], ["83884.40", "0.005999"], ["83883.10", "0"], ["83882.40", "0.015786"], ["83881.10", "0"], ["83880.63", "0.021641"], ["83880.40", "0.041541"], ["83879.94", "0.076823"], ["83879.50", "0"], ["83879.10", "0"], ["83878.40", "0.109320"], ["83877.10", "0"], ["83876.40", "0.287684"], ["83875.15", "0.008202"], ["83875.10", "0"], ["83874.88", "0"], ["83874.84", "0"], ["83874.40", "0.757063"], ["83873.19", "0"], ["83873.10", "0"], ["83872.93", "0.019085"], ["83872.43", "0"], ["83872.40", "1.992270"], ["83871.54", "0"], ["83871.10", "0"], ["83870.40", "5.242816"], ["83869.61", "0"], ["83869.10", "0"], ["83868.97", "0"], ["83868.40", "13.796885"], ["83868.30", "0.001011"], ["83868.20", "0.001046"], ["83868.00", "0.085620"], ["83867.70", "0.001022"], ["83867.60", "0.001041"], ["83867.10", "9.136110"], ["83866.90", "0"], ["83866.80", "0.006030"], ["83866.60", "0"], ["83866.40", "0"], ["83866.20", "0"], ["83866.10", "0"], ["83864.90", "0.710790"], ["83864.80", "0.068490"], ["83864.60", "0.574170"], ["83863.50", "0"], ["83860.83", "0"], ["83860.34", "0"], ["83858.80", "0.970680"], ["83856.60", "0"], ["83855.90", "0"], ["83855.30", "0"], ["83837.00", "0.000032"], ["83826.40", "4.539991"], ["83825.10", "0"], ["83818.00", "4.812390"], ["83816.70", "0"], ["83809.60", "4.903190"], ["83808.30", "0"], ["83801.20", "4.449191"], ["83799.90", "0"], ["83792.80", "4.721590"], ["83791.50", "0"], ["83784.40", "3.995192"], ["83783.10", "0"], ["83776.00", "5.357189"], ["83774.70", "0"], ["83767.60", "4.358391"], ["83766.30", "0"], ["83759.20", "5.538789"], ["83757.90", "0"], ["83750.80", "5.447989"], ["83749.50", "0.000069"], ["83742.40", "4.267591"], ["83741.10", "0"], ["83734.00", "5.084790"], ["83732.70", "0"], ["83725.60", "5.175589"], ["83724.30", "0"], ["83717.20", "5.266389"], ["83715.90", "0"], ["83708.80", "4.176792"], ["83707.50", "0"], ["83700.40", "4.085992"], ["83699.10", "0"], ["83692.00", "5.629589"], ["83690.70", "0"], ["83683.60", "3.904392"], ["83682.30", "0"], ["83675.20", "4.630791"], ["83673.90", "0"], ["83666.80", "4.993990"], ["83665.50", "0"], ["83641.86", "0.000379"], ["83641.62", "0.002925"], ["83641.38", "0.000135"], ["83641.00", "0.000082"], ["83640.35", "0.000022"], ["83640.15", "0.000423"], ["83640.00", "0.001436"], ["83639.71", "0.000041"], ["83639.70", "0.000010"]], "checksum": 111095012, "ts": "1742560772949"}], "ts": 1742560772954}}
{"exchange": "BYBIT", "timestamp": 1742560773.140731, "message": {"topic": "orderbook.200.BTCUSDT", "ts": 1742560773120, "type": "delta", "data": {"s": "BTCUSDT", "b": [["83911.4", "0.927494"], ["83911.1", "0.157171"], ["83911", "0.221"], ["83910.4", "0.050077"], ["83909.9", "0"], ["83909.8", "0"], ["83909.7", "0.05"], ["83906.6", "0.001333"], ["83906.3", "0.070818"], ["83904.4", "0.011635"], ["83903.2", "0.041466"], ["83903", "0.099099"], ["83902.4", "0.001935"], ["83902.3", "0"], ["83902.1", "0.003281"], ["83901.3", "0"], ["83900.9", "0"], ["83900.6", "0"], ["83900", "0.531662"], ["83899.5", "0.100117"], ["83899.3", "0"], ["83898.2", "0.053333"], ["83897.9", "0.003259"], ["83897.8", "0.044518"], ["83896.5", "0.044"], ["83895.5", "0"], ["83890.8", "0"], ["83890.4", "0"], ["83889.5", "0.003259"], ["83888.5", "0.089099"], ["83886.1", "0.709671"], ["83881.5", "0"], ["83880.4", "0.059399"], ["83869.3", "0.234373"], ["83867.6", "0.002134"], ["83863.6", "0"], ["83861.9", "11.425261"], ["83843.2", "0.236858"], ["83843.1", "0.059399"], ["83842.5", "0.000518"], ["83842.4", "0.004846"]], "a": [["83910", "0"], ["83910.5", "0"], ["83910.8", "0"], ["83911.1", "0"], ["83911.5", "0.062904"], ["83914.6", "0"], ["83915.6", "0"], ["83917.7", "0.071532"], ["83917.8", "0.01"], ["83918.1", "0.012206"], ["83919.5", "0.030124"], ["83919.8", "0.10692"], ["83919.9", "0.005533"], ["83924.2", "0"], ["83924.5", "0"], ["83925.4", "0.000298"], ["83926.8", "0.071525"], ["83927.8", "0.051698"], ["83927.9", "0.171"], ["83928.4", "0"], ["83929", "0"], ["83929.3", "0.071523"], ["83931.5", "0"], ["83932.5", "0.000333"], ["83932.6", "0.00009"], ["83932.9", "0.078284"], ["83933.1", "0"], ["83934.3", "0"], ["83935.4", "0"], ["83936.4", "0"], ["83937.3", "0.018984"], ["83938", "0.04"], ["83938.1", "0"], ["83938.4", "0.075966"], ["83939.3", "0.009788"], ["83941.7", "0.04"], ["83941.9", "0.336997"], ["83942.4", "0"], ["83943.1", "0.04"], ["83943.4", "0.04"], ["83944.8", "0.041466"], ["83949.3", "0.000691"], ["83949.4", "0.001556"], ["83949.9", "0.003564"], ["83950", "0"], ["83950.3", "0.013"], ["83950.4", "0.012728"], ["83950.9", "0.04"], ["83951", "0.04"], ["83951.3", "0.009"], ["83956.8", "0"], ["83959.6", "0.063462"], ["83977.7", "0"], ["83980.5", "2.606277"], ["83988.8", "0.011992"]], "u": 47437, "seq": 67552912264}, "cts": 1742560773115}}
{"exchange": "BITGET", "timestamp": 1742560773.186593, "message": {"action": "update", "arg": {"instType": "SPOT", "channel": "books", "instId": "BTCUSDT"}, "data": [{"asks": [["83901.56", "0"], ["83916.88", "0.029224"], ["83920.54", "0.035952"], ["83920.95", "0.119870"], ["83922.22", "0.035961"], ["83923.39", "0.006356"], ["83924.61", "0.010984"], ["83928.64", "0.013564"], ["83948.40", "0.033181"], ["83950.40", "0.087219"], ["83952.40", "0.229784"], ["83953.90", "0.001029"], ["83954.00", "0.001003"], ["83954.20", "0.135060"], ["83954.40", "0.024780"], ["83954.50", "0"], ["83955.10", "0.330750"], ["83956.00", "0.160320"], ["83956.50", "0.804570"], ["83956.90", "0"], ["83957.00", "0"], ["83957.50", "0"], ["83958.30", "0"], ["83958.60", "0.170580"], ["83958.70", "0.060000"], ["83959.50", "2.430000"], ["83959.70", "0.066450"], ["83960.70", "1.429650"], ["83961.40", "0.024780"], ["83962.10", "1.611930"], ["83962.30", "0.057930"], ["83962.60", "0.180000"], ["84002.80", "5.175589"], ["84011.20", "3.995192"], ["84019.60", "5.629589"], ["84028.00", "4.630791"], ["84036.40", "5.538789"], ["84044.80", "4.085992"], ["84053.20", "5.357189"], ["84061.60", "5.266389"], ["84070.00", "5.084790"], ["84078.40", "4.539991"], ["84086.80", "4.721590"], ["84095.20", "3.904392"], ["84103.60", "4.903190"], ["84112.00", "4.176792"], ["84120.40", "4.812390"], ["84128.80", "4.358391"], ["84137.20", "4.993990"], ["84145.60", "4.449191"], ["84154.00", "5.447989"], ["84536.36", "0"], ["84537.04", "0"], ["84538.75", "0"], ["84540.00", "0"], ["84540.54", "0"], ["84540.97", "0"]], "bids": [["83888.41", "1.306845"], ["83888.40", "0.001491"], ["83886.40", "0.002432"], ["83884.40", "0.006402"], ["83882.40", "0.016845"], ["83880.63", "0"], ["83880.40", "0.044331"], ["83880.27", "0.089671"], ["83879.93", "0"], ["83879.84", "0.248103"], ["83878.59", "0.084115"], ["83878.40", "0.116659"], ["83877.91", "0.005959"], ["83876.95", "0.055772"], ["83876.40", "0.306999"], ["83876.27", "3.001684"], ["83874.40", "0.807991"], ["83872.40", "2.126524"], ["83871.00", "0.021673"], ["83870.40", "5.596118"], ["83868.40", "14.726624"], ["83868.00", "0.085440"], ["83867.10", "6.369840"], ["83864.60", "0.573810"], ["83856.00", "0.356610"], ["83826.40", "4.812390"], ["83818.00", "5.084790"], ["83809.60", "5.629589"], ["83801.20", "5.175589"], ["83792.80", "3.904392"], ["83784.40", "4.630791"], ["83776.00", "4.358391"], ["83767.60", "5.538789"], ["83759.20", "5.266389"], ["83742.40", "3.995192"], ["83734.00", "4.903190"], ["83725.60", "4.085992"], ["83717.20", "5.357189"], ["83708.80", "4.721590"], ["83700.40", "4.449191"], ["83692.00", "4.993990"], ["83683.60", "4.176792"], ["83675.20", "4.267591"], ["83666.80", "4.539991"], ["83640.00", "0"], ["83639.71", "0"], ["83639.70", "0"]], "checksum": 542267603, "ts": "1742560773153"}], "ts": 1742560773157}}
{"exchange": "BYBIT", "timestamp": 1742560773.341193, "message": {"topic": "orderbook.200.BTCUSDT", "ts": 1742560773320, "type": "delta", "data": {"s": "BTCUSDT", "b": [["83911.4", "0.927571"], ["83911.1", "0.103067"], ["83910.4", "0.05"], ["83906.5", "0.106033"], ["83906.4", "0.113595"], ["83906.3", "0.003363"], ["83903", "0.104099"], ["83902.9", "0.044"], ["83901.5", "0.056"], ["83901.2", "0.04"], ["83897.3", "0.0909"], ["83897", "0"], ["83896.8", "0"], ["83896.2", "0.048"], ["83895.4", "0"], ["83893.4", "0.000358"], ["83891.7", "0"], ["83890.1", "0"], ["83888.9", "0"], ["83879.7", "0.001143"], ["83867.6", "11.427395"], ["83861.9", "0"], ["83842", "0.000622"]], "a": [["83911.5", "0.065756"], ["83916.6", "0.071533"], ["83917.7", "0"], ["83917.8", "0.005"], ["83919.5", "0"], ["83919.9", "0.010533"], ["83925.4", "0"], ["83926.6", "0.000298"], ["83926.7", "0.036057"], ["83927.8", "0"], ["83929.2", "0.075632"], ["83931.5", "0.17876"], ["83933.2", "0.001229"], ["83938.4", "0.115966"], ["83939.7", "0.063835"], ["83940", "0.04024"], ["83941.3", "0.04"], ["83941.9", "0.213035"], ["83945.1", "0.040333"], ["83950.3", "0"], ["83950.4", "0"], ["83950.5", "0.012728"], ["83950.6", "0.012728"], ["83950.9", "0"], ["83951", "0"], ["83951.1", "0.04"], ["83951.2", "0.04"], ["83951.8", "0.17876"], ["83954", "0.064931"], ["83956", "0.202589"], ["83959.6", "0"], ["83972", "2.606422"], ["83972.3", "0.089099"], ["83980.5", "0"], ["83982.6", "0"], ["83988.3", "0"]], "u": 47438, "seq": 67552912449}, "cts": 1742560773317}}
{"exchange": "BITGET", "timestamp": 1742560773.394062, "message": {"action": "update", "arg": {"instType": "SPOT", "channel": "books", "instId": "BTCUSDT"}, "data": [{"asks": [["83888.42", "0.570007"], ["83897.39", "0"], ["83904.37", "0"], ["83918.41", "0.220790"], ["83940.40", "0.001033"], ["83942.40", "0.001823"], ["83944.40", "0.004797"], ["83946.40", "0.012623"], ["83948.40", "0.033218"], ["83950.40", "0.087417"], ["83952.39", "0.237955"], ["83952.40", "0.230045"], ["83955.20", "1.067910"], ["83955.90", "0.462030"], ["83956.00", "0.159540"], ["83956.50", "0"], ["83956.60", "0.015000"], ["83957.60", "0"], ["83958.00", "0.084600"], ["83961.40", "0.168690"], ["83962.10", "2.360490"], ["83962.30", "0"], ["83962.60", "0"], ["83994.40", "4.449191"], ["84002.80", "4.812390"], ["84011.20", "4.903190"], ["84019.60", "4.358391"], ["84028.00", "3.904392"], ["84044.80", "4.993990"], ["84053.20", "5.447989"], ["84061.60", "5.357189"], ["84070.00", "4.267591"], ["84078.40", "5.175589"], ["84086.80", "4.085992"], ["84095.20", "5.084790"], ["84103.60", "4.630791"], ["84112.00", "5.266389"], ["84120.40", "5.629589"], ["84128.80", "4.539991"], ["84137.20", "3.995192"], ["84145.60", "4.176792"], ["84154.00", "4.721590"], ["84536.36", "0.000053"]], "bids": [["83888.41", "1.266636"], ["83884.35", "0.119203"], ["83883.55", "0.054885"], ["83868.00", "0.085620"], ["83867.10", "6.220230"], ["83865.70", "0.710790"], ["83864.90", "0.733620"], ["83858.20", "0.158400"], ["83856.00", "0.000032"], ["83838.00", "0.000015"], ["83826.40", "4.903190"], ["83818.00", "4.812390"], ["83809.60", "3.995192"], ["83801.20", "4.176792"], ["83792.80", "4.993990"], ["83784.40", "4.539991"], ["83776.00", "4.449191"], ["83767.60", "3.904392"], ["83759.20", "5.357189"], ["83750.80", "5.175589"], ["83742.40", "5.084790"], ["83734.00", "4.630791"], ["83725.60", "5.447989"], ["83717.20", "4.085992"], ["83708.80", "5.629589"], ["83700.40", "4.721590"], ["83692.00", "5.538789"], ["83683.60", "4.267591"], ["83675.20", "4.358391"], ["83666.80", "5.266389"]], "checksum": -1572212935, "ts": "1742560773360"}], "ts": 1742560773364}}
{"exchange": "BYBIT", "timestamp": 1742560773.547063, "message": {"topic": "orderbook.200.BTCUSDT", "ts": 1742560773520, "type": "delta", "data": {"s": "BTCUSDT", "b": [["83911.1", "0.156484"], ["83908.3", "0.0028"], ["83902.8", "0"], ["83895.1", "0"], ["83879.6", "0.0016"], ["83874.1", "0"], ["83841.9", "0.000413"]], "a": [["83911.5", "0.068735"], ["83916.6", "0"], ["83917.8", "0"], ["83919.3", "0.071531"], ["83919.9", "0.015533"], ["83926.8", "0"], ["83927.4", "0.0518"], ["83931.8", "0.072853"], ["83933.2", "0"], ["83934.7", "0.00149"], ["83938.3", "0.114903"], ["83938.4", "0.04"], ["83948.4", "0.113595"], ["83951.8", "0"], ["83972", "0"], ["83974.9", "2.606422"], ["83988.9", "0.011991"]], "u": 47439, "seq": 67552912567}, "cts": 1742560773518}}
{"exchange": "BITGET", "timestamp": 1742560773.597731, "message": {"action": "update", "arg": {"instType": "SPOT", "channel": "books", "instId": "BTCUSDT"}, "data": [{"asks": [["83888.42", "0.365986"], ["83890.52", "0.113595"], ["83897.10", "0.096110"], ["83920.08", "0"], ["83929.09", "0.481493"], ["83952.39", "0"], ["83952.40", "0.230175"], ["83955.20", "0"], ["83955.90", "0"], ["83956.00", "0.160140"], ["83959.50", "3.179340"], ["83960.70", "0.392640"], ["83962.10", "0.051930"], ["83962.30", "0.057930"], ["83962.60", "0.180000"], ["83962.70", "0.240000"], ["83962.90", "0.016200"], ["83994.40", "4.267591"], ["84002.80", "4.449191"], ["84011.20", "4.539991"], ["84019.60", "5.175589"], ["84036.40", "3.995192"], ["84044.80", "4.721590"], ["84053.20", "4.358391"], ["84061.60", "5.084790"], ["84070.00", "4.630791"], ["84078.40", "5.357189"], ["84086.80", "5.538789"], ["84095.20", "4.176792"], ["84103.60", "5.447989"], ["84112.00", "5.629589"], ["84120.40", "4.085992"], ["84128.80", "5.266389"], ["84137.20", "4.812390"], ["84145.60", "4.993990"], ["84154.00", "4.903190"], ["84242.28", "0"], ["84246.04", "1.675883"], ["84535.32", "0"], ["84536.36", "0"]], "bids": [["83888.41", "1.306983"], ["83884.36", "0.039754"], ["83880.02", "0.209200"], ["83809.60", "4.085992"], ["83801.20", "4.721590"], ["83792.80", "4.449191"], ["83784.40", "5.538789"], ["83776.00", "5.266389"], ["83767.60", "4.993990"], ["83752.72", "0"], ["83750.80", "4.267591"], ["83742.40", "4.176792"], ["83734.00", "5.175589"], ["83725.60", "5.629589"], ["83717.20", "4.539991"], ["83708.80", "4.630791"], ["83700.40", "3.995192"], ["83692.00", "4.358391"], ["83683.60", "5.447989"], ["83675.20", "3.904392"], ["83666.80", "5.084790"]], "checksum": -845584881, "ts": "1742560773564"}], "ts": 1742560773570}}
{"exchange": "BYBIT", "timestamp": 1742560773.739851, "message": {"topic": "orderbook.200.BTCUSDT", "ts": 1742560773719, "type": "delta", "data": {"s": "BTCUSDT", "b": [["83911.6", "0.890474"], ["83911.5", "0.120586"], ["83911.4", "0.171"], ["83911.1", "0"], ["83911", "0.05"], ["83907.3", "0.000333"], ["83904.9", "0.112688"], ["83903.2", "0.046466"], ["83903", "0.099099"], ["83900.1", "0"], ["83895.1", "0.169159"], ["83894.6", "0.000927"], ["83886", "0.842418"], ["83867.6", "0.002134"], ["83853.5", "11.55671"], ["83842.5", "0"], ["83842.4", "0"], ["83842", "0"], ["83841.9", "0"]], "a": [["83911.5", "0"], ["83911.7", "0.003491"], ["83919.3", "0"], ["83926.7", "0.000298"], ["83927", "0.071525"], ["83929.3", "0"], ["83930.1", "0.118604"], ["83931.5", "0"], ["83931.8", "0.001333"], ["83934.7", "0.000512"], ["83939.9", "0.183068"], ["83948.4", "0"], ["83949", "0.290338"], ["83950.5", "0"], ["83950.6", "0"], ["83951.1", "0"], ["83951.2", "0"], ["83951.9", "0.013"], ["83952", "0.012728"], ["83952.5", "0.04"], ["83952.6", "0.04"], ["83954", "0.001466"], ["83956", "0.023829"], ["83972", "2.606422"], ["83974.9", "0"], ["83989", "0.011991"], ["83989.1", "0.120743"]], "u": 47440, "seq": 67552912903}, "cts": 1742560773717}}
{"exchange": "BITGET", "timestamp": 1742560773.795316, "message": {"action": "update", "arg": {"instType": "SPOT", "channel": "books", "instId": "BTCUSDT"}, "data": [{"asks": [["83888.42", "0.611826"], ["83890.52", "0"], ["83901.56", "0.483191"], ["83929.09", "0"], ["83936.40", "0.001048"], ["83938.40", "0.001021"], ["83940.40", "0.001048"], ["83942.40", "0.002564"], ["83944.40", "0.006746"], ["83946.40", "0.017754"], ["83948.40", "0.046720"], ["83950.40", "0.122948"], ["83952.40", "0.323547"], ["83953.90", "0.249000"], ["83954.00", "0"], ["83954.10", "0.001041"], ["83954.20", "0.136110"], ["83955.20", "0.845700"], ["83956.00", "0.074640"], ["83956.20", "0.519030"], ["83959.50", "3.179130"], ["83959.70", "0"], ["83960.20", "0.653910"], ["83960.70", "0"], ["83961.10", "0.143910"], ["83961.40", "0.024780"], ["83962.90", "0"], ["83994.40", "5.266389"], ["84002.80", "4.812390"], ["84011.20", "4.721590"], ["84019.60", "4.539991"], ["84028.00", "4.267591"], ["84036.40", "5.175589"], ["84044.80", "4.358391"], ["84053.20", "5.084790"], ["84061.60", "4.449191"], ["84070.00", "5.357189"], ["84078.40", "5.538789"], ["84086.80", "4.085992"], ["84095.20", "5.629589"], ["84103.60", "4.903190"], ["84112.00", "3.904392"], ["84120.40", "4.176792"], ["84128.80", "4.993990"], ["84137.20", "4.630791"], ["84145.60", "3.995192"], ["84154.00", "5.447989"]], "bids": [["83888.41", "1.055015"], ["83888.40", "0.001377"], ["83886.40", "0.002247"], ["83884.40", "0.005914"], ["83884.35", "0.005608"], ["83882.40", "0.015561"], ["83881.19", "0.113568"], ["83880.40", "0.040951"], ["83879.94", "1.147995"], ["83878.40", "0.107765"], ["83876.40", "0.283432"], ["83875.28", "0.860516"], ["83874.40", "0.745874"], ["83872.93", "0"], ["83872.40", "1.962825"], ["83871.00", "0.000032"], ["83870.41", "1.368811"], ["83870.40", "5.165330"], ["83870.32", "0"], ["83868.40", "13.592973"], ["83867.19", "0"], ["83867.10", "5.650080"], ["83864.90", "0.022830"], ["83863.20", "0.019085"], ["83861.95", "0.021641"], ["83858.20", "0.132000"], ["83858.00", "5.741730"], ["83826.40", "5.629589"], ["83818.00", "4.903190"], ["83809.60", "4.176792"], ["83801.20", "4.993990"], ["83792.80", "4.085992"], ["83784.40", "5.266389"], ["83776.00", "5.447989"], ["83767.60", "5.538789"], ["83759.20", "4.358391"], ["83750.80", "4.630791"], ["83742.40", "4.812390"], ["83734.00", "4.539991"], ["83725.60", "5.357189"], ["83717.20", "3.904392"], ["83708.80", "5.175589"], ["83700.40", "4.721590"], ["83692.00", "4.267591"], ["83683.60", "3.995192"], ["83675.20", "4.449191"], ["83640.15", "0"]], "checksum": -972197722, "ts": "1742560773763"}], "ts": 1742560773766}}
{"exchange": "BYBIT", "timestamp": 1742560773.9404, "message": {"topic": "orderbook.200.BTCUSDT", "ts": 1742560773919, "type": "delta", "data": {"s": "BTCUSDT", "b": [["83911.6", "0.843773"], ["83911.5", "0.061238"], ["83909.3", "0"], ["83904.9", "0"], ["83903.2", "0.056466"], ["83903", "0.089099"], ["83897.8", "0.137878"], ["83897.3", "0"], ["83895.1", "0"], ["83886", "0.568474"], ["83842.5", "0.000518"], ["83842.4", "0.004846"], ["83842", "0.000622"], ["83841.9", "0.000413"]], "a": [["83911.7", "0.018389"], ["83911.9", "0.071537"], ["83919.4", "0.067102"], ["83919.5", "0.100981"], ["83919.9", "0.010533"], ["83920.1", "0.005"], ["83921.7", "0.02441"], ["83921.8", "0.071529"], ["83924.7", "0.023994"], ["83926.2", "0.004768"], ["83927", "0"], ["83929.2", "0"], ["83930.1", "0.000512"], ["83936.1", "0.003"], ["83939.9", "0"], ["83945.7", "0.357192"], ["83946", "0.119143"], ["83948.3", "0.675788"], ["83949", "0"], ["83951.2", "0.063465"], ["83969.2", "2.609705"], ["83972", "0"], ["83988.7", "0"], ["83988.8", "0"], ["83988.9", "0"], ["83989", "0"], ["83989.1", "0"]], "u": 47441, "seq": 67552913014}, "cts": 1742560773902}}
{"exchange": "BITGET", "timestamp": 1742560774.073557, "message": {"action": "update", "arg": {"instType": "SPOT", "channel": "books", "instId": "BTCUSDT"}, "data": [{"asks": [["83896.81", "0.209200"], ["83897.10", "0"], ["83930.86", "0.182413"], ["83936.40", "0.001196"], ["83938.40", "0.003147"], ["83940.40", "0.008283"], ["83942.40", "0.021797"], ["83944.40", "0.057361"], ["83946.40", "0.150804"], ["83948.40", "0.396851"], ["83950.40", "1.044347"], ["83952.40", "2.748280"], ["83952.50", "0.369180"], ["83952.60", "0.847980"], ["83953.10", "0"], ["83953.90", "0"], ["83954.10", "0"], ["83954.20", "0.135060"], ["83955.10", "0.330360"], ["83955.20", "0"], ["83956.20", "0"], ["83956.50", "3.863220"], ["83958.60", "0"], ["83959.50", "2.430000"], ["83960.20", "0.365160"], ["83961.60", "0"], ["83962.90", "0.072720"], ["83994.40", "4.358391"], ["84002.80", "4.630791"], ["84011.20", "4.903190"], ["84019.60", "5.266389"], ["84028.00", "5.538789"], ["84036.40", "4.267591"], ["84044.80", "4.085992"], ["84053.20", "5.357189"], ["84070.00", "4.176792"], ["84078.40", "3.904392"], ["84086.80", "4.539991"], ["84095.20", "5.084790"], ["84103.60", "4.993990"], ["84112.00", "5.447989"], ["84120.40", "5.175589"], ["84128.80", "3.995192"], ["84137.20", "5.629589"], ["84145.60", "4.721590"], ["84154.00", "4.812390"], ["84535.32", "0.000039"], ["84536.36", "0.000053"]], "bids": [["83888.41", "1.030968"], ["83884.36", "0.006400"], ["83880.40", "0.041059"], ["83878.40", "0.108051"], ["83876.40", "0.284343"], ["83874.40", "0.748271"], ["83872.40", "1.969134"], ["83870.40", "5.181933"], ["83868.40", "13.636664"], ["83859.80", "0"], ["83858.80", "3.115470"], ["83857.60", "0.012390"], ["83838.00", "0"], ["83826.40", "5.175589"], ["83818.00", "4.267591"], ["83809.60", "4.358391"], ["83801.20", "4.539991"], ["83792.80", "5.629589"], ["83784.40", "4.903190"], ["83776.00", "5.357189"], ["83767.60", "4.085992"], ["83759.20", "3.904392"], ["83750.80", "4.993990"], ["83742.40", "5.084790"], ["83734.00", "4.630791"], ["83725.60", "4.812390"], ["83717.20", "5.538789"], ["83708.80", "4.721590"], ["83700.40", "4.176792"], ["83692.00", "4.449191"], ["83675.20", "5.447989"], ["83666.80", "5.266389"], ["83640.15", "0.000423"]], "checksum": -1884640177, "ts": "1742560773975"}], "ts": 1742560773979}}
{"exchange": "BYBIT", "timestamp": 1742560774.143327, "message": {"topic": "orderbook.200.BTCUSDT", "ts": 1742560774120, "type": "delta", "data": {"s": "BTCUSDT", "b": [["83911.5", "0.104883"], ["83874.9", "0.014071"], ["83874.8", "0.132024"], ["83873.7", "0"], ["83873.6", "0"], ["83859.1", "11.794895"], ["83853.5", "0"], ["83841", "0.000334"], ["83840.2", "0.000333"], ["83840", "0.000414"]], "a": [["83919.4", "0.045643"], ["83919.5", "0.02945"], ["83919.9", "0.005533"], ["83920.1", "0.01"], ["83924.5", "0.083699"], ["83924.6", "0.071527"], ["83927.4", "0"], ["83947.5", "0.113704"], ["83948.3", "0.562218"], ["83951.1", "0.013"], ["83951.2", "0.076194"], ["83951.9", "0"], ["83952", "0"], ["83966.4", "2.606416"], ["83969.2", "0.003283"], ["83987.1", "0"], ["83988.6", "0"]], "u": 47442, "seq": 67552913119}, "cts": 1742560774116}}
{"exchange": "BITGET", "timestamp": 1742560774.217167, "message": {"action": "update", "arg": {"instType": "SPOT", "channel": "books", "instId": "BTCUSDT"}, "data": [{"asks": [["83890.29", "0.113704"], ["83896.75", "0.096111"], ["83896.80", "0.069994"], ["83896.88", "0.020300"], ["83935.99", "0"], ["83944.40", "0.057473"], ["83946.40", "0.151141"], ["83948.40", "0.397738"], ["83950.40", "1.046679"], ["83952.40", "2.754418"], ["83952.50", "0.386820"], ["83952.60", "0.685710"], ["83960.80", "0.143910"], ["83961.10", "0"], ["83962.90", "0"], ["83994.40", "4.993990"], ["84002.80", "4.085992"], ["84011.20", "4.176792"], ["84019.60", "5.447989"], ["84028.00", "4.812390"], ["84036.40", "3.995192"], ["84044.80", "4.903190"], ["84053.20", "4.358391"], ["84061.60", "4.721590"], ["84070.00", "4.539991"], ["84078.40", "4.267591"], ["84086.80", "5.629589"], ["84095.20", "5.357189"], ["84103.60", "5.084790"], ["84112.00", "5.175589"], ["84120.40", "5.266389"], ["84128.80", "4.449191"], ["84137.20", "3.904392"], ["84145.60", "5.538789"], ["84154.00", "4.630791"], ["84536.36", "0"]], "bids": [["83888.41", "1.024621"], ["83883.55", "0.082452"], ["83878.40", "0.108294"], ["83876.40", "0.284983"], ["83874.40", "0.749956"], ["83872.40", "1.973569"], ["83870.41", "1.404992"], ["83870.40", "5.193602"], ["83868.40", "13.667373"], ["83867.10", "5.208150"], ["83836.00", "0.000017"], ["83826.40", "3.995192"], ["83818.00", "4.176792"], ["83809.60", "4.267591"], ["83801.20", "4.449191"], ["83792.80", "4.358391"], ["83784.40", "5.357189"], ["83776.00", "5.175589"], ["83767.60", "4.903190"], ["83759.20", "5.538789"], ["83750.80", "5.084790"], ["83742.40", "4.721590"], ["83734.00", "5.266389"], ["83725.60", "4.539991"], ["83717.20", "4.085992"], ["83708.80", "3.904392"], ["83700.40", "4.630791"], ["83692.00", "4.812390"], ["83683.60", "5.629589"], ["83675.20", "4.993990"], ["83666.80", "5.447989"], ["83640.15", "0"]], "checksum": -2072080553, "ts": "1742560774187"}], "ts": 1742560774191}}
{"exchange": "BYBIT", "timestamp": 1742560774.341633, "message": {"topic": "orderbook.200.BTCUSDT", "ts": 1742560774320, "type": "delta", "data": {"s": "BTCUSDT", "b": [["83911.6", "0.602581"], ["83911.5", "0.043645"], ["83911.4", "0"], ["83911", "0.02"], ["83910.4", "0.02"], ["83894.8", "0.059851"], ["83894.3", "0.119143"], ["83887.8", "0.056373"], ["83880.8", "0.121316"], ["83874.9", "0.013952"], ["83859.1", "0.238185"], ["83853.5", "11.55671"], ["83841.9", "0"], ["83841", "0"], ["83840.2", "0"], ["83840", "0"]], "a": [["83911.7", "0.208381"], ["83919.7", "0.071531"], ["83919.9", "0.000533"], ["83920.1", "0.015"], ["83921.7", "0.039362"], ["83924.2", "0.00009"], ["83924.4", "0.059399"], ["83924.5", "0.06224"], ["83924.6", "0"], ["83926.1", "0.063269"], ["83929.8", "0.059764"], ["83935.3", "0.001082"], ["83935.7", "0.001189"], ["83936.8", "0.061939"], ["83943.8", "0.121763"], ["83951.1", "0"], ["83951.3", "0.021729"], ["83966.4", "0"], ["83969.2", "2.609699"], ["83983.6", "0"], ["83985.5", "0"], ["83985.7", "0"], ["83986", "0"], ["83986.3", "0"], ["83986.4", "0"]], "u": 47443, "seq": 67552913234}, "cts": 1742560774315}}
{"exchange": "BITGET", "timestamp": 1742560774.422935, "message": {"action": "update", "arg": {"instType": "SPOT", "channel": "books", "instId": "BTCUSDT"}, "data": [{"asks": [["83936.40", "0.001996"], ["83938.40", "0.005254"], ["83939.09", "0.010000"], ["83940.40", "0.013827"], ["83942.40", "0.036387"], ["83944.40", "0.095755"], ["83946.40", "0.251987"], ["83948.40", "0.663123"], ["83950.40", "1.745061"], ["83952.40", "4.592266"], ["83952.50", "0.862800"], ["83952.60", "0.408780"], ["83960.20", "0.768480"], ["83960.80", "1.493910"], ["83962.90", "0.072720"], ["83994.40", "5.357189"], ["84002.80", "4.903190"], ["84011.20", "4.721590"], ["84019.60", "4.358391"], ["84028.00", "4.267591"], ["84036.40", "5.084790"], ["84044.80", "5.266389"], ["84053.20", "4.085992"], ["84061.60", "5.538789"], ["84070.00", "3.904392"], ["84078.40", "5.175589"], ["84086.80", "4.630791"], ["84095.20", "3.995192"], ["84103.60", "5.629589"], ["84112.00", "4.812390"], ["84120.40", "4.993990"], ["84137.20", "5.447989"], ["84145.60", "4.539991"], ["84154.00", "4.176792"], ["84534.53", "0"], ["84535.32", "0"]], "bids": [["83888.40", "0.001164"], ["83886.40", "0.001898"], ["83884.40", "0.004997"], ["83882.40", "0.013149"], ["83880.40", "0.034602"], ["83878.40", "0.091058"], ["83876.40", "0.239627"], ["83874.40", "0.630597"], ["83872.40", "1.659465"], ["83870.40", "4.367013"], ["83868.40", "11.492140"], ["83861.60", "0"], ["83858.70", "2.874270"], ["83858.00", "5.591730"], ["83826.40", "4.176792"], ["83818.00", "4.812390"], ["83809.60", "5.357189"], ["83801.20", "4.267591"], ["83792.80", "4.993990"], ["83784.40", "3.995192"], ["83776.00", "5.629589"], ["83767.60", "4.630791"], ["83742.40", "4.903190"], ["83734.00", "4.539991"], ["83725.60", "4.085992"], ["83717.20", "5.266389"], ["83708.80", "4.449191"], ["83700.40", "5.447989"], ["83692.00", "3.904392"], ["83683.60", "4.721590"], ["83675.20", "5.175589"], ["83666.80", "4.358391"], ["83640.15", "0.000423"]], "checksum": 2048267656, "ts": "1742560774393"}], "ts": 1742560774396}}
{"exchange": "BYBIT", "timestamp": 1742560774.597594, "message": {"topic": "orderbook.200.BTCUSDT", "ts": 1742560774519, "type": "delta", "data": {"s": "BTCUSDT", "b": [["83911.4", "0.000659"], ["83909.7", "0.02"], ["83903", "0"]], "a": [["83929.7", "0.024533"], ["83932.8", "0.001086"], ["83935.3", "0"], ["83935.7", "0"], ["83950.4", "0.04"], ["83950.5", "0.04"], ["83952.5", "0"], ["83952.6", "0"], ["83960.7", "2.606416"], ["83969.2", "0.003283"]], "u": 47444, "seq": 67552913292}, "cts": 1742560774505}}
{"exchange": "BITGET", "timestamp": 1742560774.632879, "message": {"action": "update", "arg": {"instType": "SPOT", "channel": "books", "instId": "BTCUSDT"}, "data": [{"asks": [["83888.42", "0.691826"], ["83896.46", "0.096111"], ["83896.75", "0"], ["83924.61", "0"], ["83936.40", "0.002857"], ["83938.40", "0.007519"], ["83940.40", "0.019785"], ["83942.40", "0.052068"], ["83944.40", "0.137021"], ["83946.40", "0.360581"], ["83948.40", "0.948896"], ["83950.40", "2.497096"], ["83951.94", "0"], ["83952.40", "6.571306"], ["83952.50", "1.428840"], ["83952.60", "0.408960"], ["83954.20", "0.135240"], ["83955.10", "0.330540"], ["83956.50", "0.794340"], ["83962.10", "0.105510"], ["83962.90", "0"], ["83994.40", "4.993990"], ["84002.80", "4.176792"], ["84011.20", "4.812390"], ["84019.60", "3.904392"], ["84028.00", "5.538789"], ["84036.40", "5.175589"], ["84044.80", "5.357189"], ["84053.20", "5.084790"], ["84061.60", "4.358391"], ["84070.00", "4.721590"], ["84078.40", "5.266389"], ["84086.80", "3.995192"], ["84095.20", "4.539991"], ["84103.60", "4.449191"], ["84112.00", "4.630791"], ["84120.40", "4.267591"], ["84128.80", "4.903190"], ["84137.20", "4.085992"], ["84145.60", "5.447989"], ["84154.00", "5.629589"], ["84534.53", "0.000461"], ["84535.32", "0.000039"], ["84536.36", "0.000053"]], "bids": [["83888.40", "0.001041"], ["83886.40", "0.001578"], ["83884.40", "0.004153"], ["83882.40", "0.010928"], ["83880.40", "0.028759"], ["83878.40", "0.075680"], ["83876.95", "0"], ["83876.40", "0.199158"], ["83874.40", "0.524101"], ["83872.40", "1.379214"], ["83870.40", "3.629510"], ["83868.40", "9.551342"], ["83867.60", "0"], ["83862.00", "0.136500"], ["83858.80", "0.970680"], ["83858.00", "5.441940"], ["83826.40", "5.357189"], ["83818.00", "5.447989"], ["83809.60", "4.267591"], ["83801.20", "4.721590"], ["83792.80", "3.904392"], ["83784.40", "4.812390"], ["83776.00", "5.175589"], ["83767.60", "5.084790"], ["83759.20", "4.903190"], ["83750.80", "4.176792"], ["83742.40", "5.538789"], ["83734.00", "3.995192"], ["83725.60", "5.266389"], ["83717.20", "4.358391"], ["83700.40", "4.993990"], ["83692.00", "4.085992"], ["83683.60", "4.630791"], ["83675.20", "4.539991"], ["83666.80", "5.629589"], ["83640.00", "0.001436"], ["83639.71", "0.000041"]], "checksum": 1532576774, "ts": "1742560774595"}], "ts": 1742560774601}}
{"exchange": "BYBIT", "timestamp": 1742560774.742102, "message": {"topic": "orderbook.200.BTCUSDT", "ts": 1742560774720, "type": "delta", "data": {"s": "BTCUSDT", "b": [["83911.6", "0.696988"], ["83911.5", "0.024596"], ["83908.9", "0.021326"], ["83908.3", "0"], ["83898.1", "0.029332"], ["83894.8", "0"], ["83887.8", "0"], ["83885.8", "0"], ["83881.2", "0.023343"], ["83880.8", "0"], ["83875.4", "0.013"], ["83875.3", "0.012881"], ["83874.9", "0.001071"], ["83874.8", "0.119143"], ["83869.3", "0.099459"], ["83869.2", "0.373113"], ["83853.5", "0"], ["83850.6", "11.483722"], ["83841.9", "0.000413"]], "a": [["83911.8", "0.027646"], ["83921.7", "0.042257"], ["83924.5", "0.118281"], ["83925.7", "0.018291"], ["83927.7", "0.009788"], ["83929.7", "0.004161"], ["83929.8", "0"], ["83932.8", "0"], ["83933.1", "0.04"], ["83936.8", "0"], ["83937.3", "0"], ["83938", "0"], ["83939.3", "0"], ["83940.1", "0.120639"], ["83943.8", "0"], ["83949.6", "0.013"], ["83949.7", "0.012729"], ["83950.2", "0.04"], ["83950.3", "0.04"], ["83950.4", "0"], ["83950.5", "0"], ["83951.2", "0.063465"], ["83951.3", "0.009"], ["83960.7", "0"], ["83965.2", "0.083803"], ["83969.9", "0"], ["83977.7", "2.606416"], ["83983.6", "0.119143"], ["83985.5", "0.000514"], ["83985.7", "0.059399"]], "u": 47445, "seq": 67552913537}, "cts": 1742560774715}}
{"exchange": "BITGET", "timestamp": 1742560774.826073, "message": {"action": "update", "arg": {"instType": "SPOT", "channel": "books", "instId": "BTCUSDT"}, "data": [{"asks": [["83919.31", "0.010984"], ["83921.42", "0.013448"], ["83934.40", "0.001024"], ["83936.40", "0.002695"], ["83938.40", "0.007093"], ["83940.40", "0.018666"], ["83942.40", "0.049120"], ["83944.40", "0.129264"], ["83946.40", "0.340168"], ["83948.40", "0.895180"], ["83950.40", "2.355736"], ["83952.40", "6.199510"], ["83952.50", "0.863190"], ["83954.20", "0.135060"], ["83954.40", "2.385510"], ["83956.00", "0.218550"], ["83960.80", "1.350000"], ["83961.30", "0.178290"], ["83962.70", "0"], ["83994.40", "5.357189"], ["84002.80", "5.629589"], ["84019.60", "5.447989"], ["84028.00", "5.266389"], ["84036.40", "5.084790"], ["84044.80", "4.267591"], ["84053.20", "4.721590"], ["84061.60", "4.539991"], ["84070.00", "3.904392"], ["84078.40", "3.995192"], ["84086.80", "4.176792"], ["84095.20", "5.175589"], ["84103.60", "4.903190"], ["84120.40", "4.358391"], ["84128.80", "4.993990"], ["84137.20", "4.449191"], ["84145.60", "4.085992"], ["84154.00", "5.538789"], ["84535.32", "0"], ["84536.36", "0"]], "bids": [["83888.40", "0.012062"], ["83886.40", "0.001477"], ["83884.40", "0.003886"], ["83882.40", "0.010074"], ["83880.40", "0.026509"], ["83878.40", "0.069761"], ["83876.40", "0.183582"], ["83875.28", "0.545431"], ["83874.40", "0.483110"], ["83872.40", "1.271342"], ["83871.66", "0.055772"], ["83870.40", "3.345638"], ["83868.40", "8.804310"], ["83868.00", "0.085440"], ["83867.20", "0.045510"], ["83867.10", "5.207940"], ["83858.80", "3.115470"], ["83858.70", "2.104020"], ["83858.00", "5.442300"], ["83847.20", "0"], ["83826.40", "5.084790"], ["83818.00", "4.449191"], ["83809.60", "5.175589"], ["83801.20", "4.176792"], ["83792.80", "4.267591"], ["83784.40", "3.995192"], ["83776.00", "3.904392"], ["83767.60", "5.538789"], ["83759.20", "5.447989"], ["83750.80", "4.721590"], ["83742.40", "5.629589"], ["83734.00", "4.358391"], ["83725.60", "4.903190"], ["83717.20", "4.993990"], ["83708.80", "4.539991"], ["83700.40", "4.630791"], ["83692.00", "5.357189"], ["83683.60", "5.266389"], ["83675.20", "4.085992"], ["83666.80", "4.812390"], ["83639.71", "0"]], "checksum": -850894501, "ts": "1742560774796"}], "ts": 1742560774799}}
{"exchange": "BYBIT", "timestamp": 1742560774.941048, "message": {"topic": "orderbook.200.BTCUSDT", "ts": 1742560774919, "type": "delta", "data": {"s": "BTCUSDT", "b": [["83911.6", "0.696395"], ["83853.5", "11.483722"], ["83850.6", "0"]], "a": [["83951.1", "0.136036"], ["83951.2", "0"], ["83954", "0.064931"]], "u": 47446, "seq": 67552913641}, "cts": 1742560774915}}
{"exchange": "BITGET", "timestamp": 1742560775.027155, "message": {"action": "update", "arg": {"instType": "SPOT", "channel": "books", "instId": "BTCUSDT"}, "data": [{"asks": [["83896.46", "0"], ["83952.50", "1.428870"], ["83952.60", "0.408750"], ["83962.70", "0.240000"], ["83994.40", "4.267591"], ["84002.80", "5.357189"], ["84011.20", "4.539991"], ["84019.60", "5.629589"], ["84028.00", "4.085992"], ["84036.40", "4.449191"], ["84044.80", "5.084790"], ["84053.20", "4.812390"], ["84061.60", "4.176792"], ["84070.00", "4.903190"], ["84086.80", "4.630791"], ["84095.20", "3.904392"], ["84103.60", "4.358391"], ["84112.00", "5.538789"], ["84120.40", "5.175589"], ["84137.20", "5.447989"], ["84145.60", "5.266389"], ["84154.00", "4.721590"], ["84248.80", "0.001403"], ["84345.20", "0"]], "bids": [["83870.41", "0"], ["83857.20", "0"], ["83848.00", "0.000428"], ["83836.00", "0.000032"], ["83818.60", "0.000948"], ["83818.00", "4.630791"], ["83817.80", "0"], ["83809.60", "4.176792"], ["83801.20", "4.903190"], ["83792.80", "5.266389"], ["83784.40", "4.449191"], ["83776.00", "5.538789"], ["83767.60", "4.993990"], ["83759.20", "3.995192"], ["83750.80", "5.447989"], ["83742.40", "4.812390"], ["83734.00", "5.629589"], ["83725.60", "4.267591"], ["83717.20", "4.085992"], ["83708.80", "5.357189"], ["83700.40", "3.904392"], ["83692.00", "4.358391"], ["83683.60", "4.539991"], ["83675.20", "4.721590"], ["83666.80", "5.175589"], ["83639.71", "0.000041"], ["83639.70", "0.000010"]], "checksum": -1638242525, "ts": "1742560774997"}], "ts": 1742560775001}}
{"exchange": "BYBIT", "timestamp": 1742560775.140221, "message": {"topic": "orderbook.200.BTCUSDT", "ts": 1742560775120, "type": "delta", "data": {"s": "BTCUSDT", "b": [["83911.6", "0.525395"], ["83900.9", "0.119143"], ["83899.3", "0.122387"], ["83898.1", "0"], ["83888.8", "0.166711"], ["83881.8", "0.303302"], ["83841.9", "0"]], "a": [["83911.7", "0.292246"], ["83919.5", "0"], ["83921.7", "0.074304"], ["83923.8", "0.123821"], ["83933.4", "0.099399"], ["83934.3", "0.180194"], ["83934.7", "0.040512"], ["83935.1", "0.04"], ["83936.3", "0.08596"], ["83939.7", "0.023835"], ["83939.8", "0.043288"], ["83940.1", "0.160639"], ["83941.3", "0.308247"], ["83945.1", "0.000333"], ["83946", "0"], ["83951.2", "0.063465"], ["83953.6", "1.429362"], ["83954", "0.001466"], ["83955.1", "2.606416"], ["83977.7", "0"], ["83983.6", "0"], ["83985.5", "0"], ["83985.7", "0"]], "u": 47447, "seq": 67552913733}, "cts": 1742560775114}}
