{"exchange": "BYBIT", "timestamp": 1742560334.03046, "message": {"topic": "orderbook.200.BTCUSDT", "ts": 1742560331319, "type": "snapshot", "data": {"s": "BTCUSDT", "b": [["84167.9", "0.734572"], ["84167.8", "0.000333"], ["84167.1", "0.001333"], ["84166.9", "0.0003"], ["84166.8", "0.003268"], ["84166.7", "0.001466"], ["84165.9", "0.000518"], ["84163.8", "0.003936"], ["84163.6", "0.000333"], ["84162.9", "0.001333"], ["84162.6", "0.003268"], ["84162.2", "0.143492"], ["84162.1", "0.171"], ["84162", "0.001466"], ["84161.3", "0.009518"], ["84161.2", "0.011919"], ["84160.6", "0.121257"], ["84160.4", "0.048"], ["84160.3", "0.001773"], ["84160", "0.00006"], ["84159.7", "0.01887"], ["84159.6", "0.145861"], ["84159.5", "0.04701"], ["84159.4", "0.000333"], ["84158.9", "0.064"], ["84158.7", "0.045333"], ["84158.6", "0.000358"], ["84158.4", "0.003268"], ["84157.4", "0.061352"], ["84157", "0.12384"], ["84156.9", "0.0073"], ["84156.6", "0.000518"], ["84156.2", "0.07133"], ["84155.7", "0.019942"], ["84155.4", "0.06"], ["84155.3", "0.048"], ["84155.2", "0.000333"], ["84154.5", "0.001333"], ["84154.4", "0.00009"], ["84154.3", "0.124581"], ["84154.2", "0.003259"], ["84153.9", "0.052"], ["84153.6", "0.056"], ["84153.1", "0.000297"], ["84152.9", "0.059399"], ["84152.8", "0.172466"], ["84152", "0.000518"], ["84151", "0.000333"], ["84150.4", "0.178252"], ["84150.3", "0.001333"], ["84150.1", "0.777045"], ["84150", "2.379967"], ["84149.8", "0.005942"], ["84148.8", "0.002442"], ["84148.2", "0.001466"], ["84148.1", "0.0002"], ["84147.4", "0.000518"], ["84147", "0.020211"], ["84146.9", "0.0002"], ["84146.8", "0.000333"], ["84146.5", "0.0045"], ["84146.1", "0.001333"], ["84146", "0.00018"], ["84145.7", "0.003259"], ["84145.2", "0.089099"], ["84143.5", "0.001566"], ["84142.7", "0.000518"], ["84142.6", "0.000333"], ["84142.5", "0.004583"], ["84142", "0.404068"], ["84141.9", "0.001333"], ["84141.8", "0.171"], ["84141.5", "0.003259"], ["84140.6", "0.118793"], ["84140.5", "0.4"], ["84140", "0.00006"], ["84139.3", "0.178215"], ["84139", "0.000332"], ["84138.9", "0.001466"], ["84138.6", "0.557231"], ["84138.5", "0.029037"], ["84138.4", "0.000333"], ["84138.1", "0.000518"], ["84137.7", "0.001333"], ["84137.6", "0.00009"], ["84137.3", "0.003259"], ["84136.9", "0.024035"], ["84136.5", "0.000358"], ["84136", "0.000083"], ["84135.3", "0.035651"], ["84134.3", "0.001466"], ["84134.2", "0.000333"], ["84134", "0.011887"], ["84133.6", "0.205266"], ["84133.5", "0.001851"], ["84133.3", "0.171"], ["84133.1", "0.003259"], ["84132.9", "0.059399"], ["84132.3", "0.0001"], ["84132.2", "0.118793"], ["84131.3", "0.009"], ["84130.8", "0.499416"], ["84130.7", "0.024825"], ["84130.3", "0.039635"], ["84130.2", "0.039635"], ["84130", "0.000333"], ["84129.7", "0.001466"], ["84129.6", "0.115744"], ["84129.3", "0.014214"], ["84129.2", "0.012971"], ["84128.9", "0.003777"], ["84128.2", "0.005164"], ["84127.2", "0.128378"], ["84127.1", "0.118793"], ["84125.8", "0.000333"], ["84125.5", "0.05"], ["84125.4", "0.04955"], ["84125.1", "0.001333"], ["84125", "0.001584"], ["84124.9", "0.109391"], ["84124.8", "0.171"], ["84124.7", "0.003259"], ["84124.6", "0.02112"], ["84124.4", "0.059399"], ["84124.2", "0.000518"], ["84124.1", "0.00594"], ["84124", "0.001782"], ["84123.9", "0.089099"], ["84122.5", "0.00002"], ["84121.8", "0.00477"], ["84121.6", "0.000333"], ["84121.2", "0.023762"], ["84120.8", "0.001423"], ["84120.5", "0.003259"], ["84120.4", "0.001466"], ["84120.3", "0.023762"], ["84120.1", "0.850819"], ["84120", "2.377615"], ["84119.6", "0.000518"], ["84118.8", "0.023762"], ["84118.7", "0.013719"], ["84118", "0.023761"], ["84117.4", "0.000333"], ["84116.9", "0.023757"], ["84116.6", "0.001333"], ["84116.5", "0.0045"], ["84116.3", "0.174259"], ["84115.8", "0.001466"], ["84115.6", "3.657776"], ["84115.4", "0.023762"], ["84115.3", "0.124751"], ["84115", "0.000518"], ["84114.4", "0.000358"], ["84113.2", "0.000333"], ["84113", "0.118793"], ["84112.4", "0.001423"], ["84112.1", "0.018259"], ["84111.1", "0.001466"], ["84110.9", "0.003614"], ["84110.4", "0.000518"], ["84109.6", "0.044"], ["84109.4", "0.001367"], ["84108.9", "0.000333"], ["84108.2", "0.001333"], ["84107.9", "0.122052"], ["84107.8", "0.171"], ["84107.1", "0.059399"], ["84106.9", "0.048"], ["84106.5", "0.001466"], ["84105.7", "0.000518"], ["84104.7", "0.000333"], ["84104.6", "0.048"], ["84104", "0.001423"], ["84103.9", "0.00009"], ["84103.7", "0.003259"], ["84102.6", "0.005871"], ["84102.5", "0.118793"], ["84102.4", "3.256341"], ["84102.3", "19.531634"], ["84101.9", "0.001466"], ["84101.3", "0.009"], ["84101.1", "0.000518"], ["84101", "0.003509"], ["84100.5", "0.000333"], ["84100.4", "0.052"], ["84100", "0.010271"], ["84099.8", "0.001333"], ["84099.5", "0.003259"], ["84099.3", "0.171"], ["84099.1", "0.01183"], ["84098.1", "0.165081"], ["84097.8", "0.027758"], ["84097.3", "0.001466"], ["84097.1", "0.237567"], ["84096.6", "0.235392"], ["84096.5", "0.000518"], ["84096.4", "0.0001"], ["84096.3", "0.000333"], ["84095.9", "0.06"], ["84095.7", "0.01183"]], "a": [["84168", "0.375133"], ["84168.9", "0.071319"], ["84173", "0.0002"], ["84174", "0.071315"], ["84174.7", "0.011842"], ["84175.1", "0.000518"], ["84175.2", "0.003268"], ["84175.5", "0.001333"], ["84175.9", "0.024301"], ["84176.3", "0.000333"], ["84176.4", "0.198714"], ["84176.5", "0.171"], ["84176.9", "0.011879"], ["84178.1", "0.071311"], ["84178.9", "0.023683"], ["84179.4", "0.003268"], ["84179.8", "0.001851"], ["84180", "0.00024"], ["84180.5", "0.000333"], ["84180.6", "0.001466"], ["84183.4", "0.04334"], ["84183.5", "0.058923"], ["84183.6", "0.003269"], ["84184", "0.001333"], ["84184.2", "0.04"], ["84184.4", "0.000518"], ["84184.5", "0.04"], ["84184.6", "0.00009"], ["84184.7", "0.000333"], ["84185.2", "0.001466"], ["84185.5", "0.035651"], ["84185.9", "0.04"], ["84186", "0.099106"], ["84186.1", "0.08"], ["84187.5", "0.04"], ["84187.8", "0.003269"], ["84188.1", "0.030066"], ["84188.2", "0.001333"], ["84188.3", "0.171"], ["84188.9", "0.004166"], ["84189", "0.119311"], ["84189.1", "0.161816"], ["84189.2", "0.04"], ["84189.3", "0.04"], ["84189.4", "0.005942"], ["84189.5", "0.04"], ["84189.6", "0.178106"], ["84189.8", "0.001466"], ["84190.9", "0.0006"], ["84191.2", "0.04"], ["84191.8", "0.01933"], ["84192", "0.003269"], ["84192.4", "0.001333"], ["84192.5", "0.050124"], ["84193", "0.00009"], ["84193.1", "0.000333"], ["84193.7", "0.002585"], ["84194.1", "0.009187"], ["84194.4", "0.04453"], ["84194.5", "0.001466"], ["84195.1", "0.27292"], ["84195.5", "0.050124"], ["84196.3", "0.003269"], ["84196.6", "0.001333"], ["84196.7", "0.118793"], ["84196.8", "0.478027"], ["84197.1", "0.005939"], ["84197.3", "0.000333"], ["84197.4", "0.201066"], ["84197.9", "0.059399"], ["84198.1", "0.05939"], ["84198.3", "0.000518"], ["84199.1", "0.001466"], ["84199.2", "0.00099"], ["84199.9", "0.0018"], ["84200", "0.00024"], ["84200.5", "0.003293"], ["84200.8", "0.001333"], ["84201.4", "0.011977"], ["84201.5", "0.000333"], ["84201.7", "0.004687"], ["84201.8", "0.099641"], ["84202", "0.005942"], ["84202.3", "0.05939"], ["84202.5", "0.000734"], ["84202.9", "0.000518"], ["84203.7", "0.001466"], ["84204.1", "0.118793"], ["84204.4", "0.05939"], ["84204.7", "0.003293"], ["84205", "0.001333"], ["84205.7", "0.000333"], ["84205.8", "0.003564"], ["84206.5", "0.0045"], ["84206.7", "0.013"], ["84206.8", "0.012973"], ["84207.4", "0.000296"], ["84207.6", "0.000518"], ["84207.7", "0.171"], ["84207.8", "0.04"], ["84207.9", "0.04"], ["84208.4", "0.001466"], ["84208.7", "0.063463"], ["84208.9", "0.003293"], ["84209.2", "0.001333"], ["84209.8", "0.434239"], ["84209.9", "0.119126"], ["84210", "2.444781"], ["84211", "0.000118"], ["84211.9", "0.04428"], ["84212", "0.115828"], ["84212.2", "0.000518"], ["84212.3", "0.013716"], ["84212.4", "2.585653"], ["84212.5", "0.029692"], ["84212.6", "0.05939"], ["84213", "0.001466"], ["84213.1", "0.122084"], ["84213.4", "0.001333"], ["84213.6", "0.0006"], ["84213.7", "0.549999"], ["84214.2", "0.000333"], ["84214.5", "0.000358"], ["84214.6", "0.005942"], ["84215.5", "0.023757"], ["84216.1", "0.130344"], ["84216.6", "0.118793"], ["84216.8", "0.000518"], ["84216.9", "0.179186"], ["84217.3", "0.003294"], ["84217.6", "0.002799"], ["84217.7", "0.023759"], ["84217.8", "0.005938"], ["84217.9", "0.029695"], ["84218.2", "0.00009"], ["84218.4", "0.000333"], ["84218.7", "0.051005"], ["84219", "0.023757"], ["84220", "0.00024"], ["84220.4", "0.023757"], ["84220.5", "0.124712"], ["84220.8", "0.005939"], ["84221.3", "0.009"], ["84221.5", "0.063196"], ["84221.9", "0.016323"], ["84222.2", "0.001466"], ["84222.3", "0.059399"], ["84222.6", "0.056374"], ["84222.8", "0.003564"], ["84223.4", "0.059393"], ["84223.6", "0.118793"], ["84225.5", "0.089099"], ["84225.7", "0.003293"], ["84226.1", "0.001851"], ["84226.6", "0.00009"], ["84226.8", "0.000333"], ["84226.9", "0.001466"], ["84227.2", "0.005942"], ["84227.3", "0.099271"], ["84227.9", "0.005939"], ["84228.2", "0.001782"], ["84229", "0.143712"], ["84229.1", "0.171"], ["84229.2", "0.04"], ["84229.3", "3.209371"], ["84229.8", "0.096795"], ["84229.9", "0.003293"], ["84230.3", "0.001333"], ["84230.7", "0.000518"], ["84231", "0.000333"], ["84231.4", "0.059399"], ["84231.5", "0.001466"], ["84231.6", "0.059393"], ["84231.8", "0.003564"], ["84232.4", "0.023754"], ["84232.5", "0.059377"], ["84234.2", "0.003293"], ["84234.5", "0.001333"], ["84234.6", "0.023755"], ["84234.7", "0.118793"], ["84235", "0.00009"], ["84235.2", "0.000333"], ["84235.4", "0.000518"], ["84235.8", "0.015"], ["84235.9", "0.023754"], ["84236.1", "0.001466"], ["84236.5", "0.0045"], ["84236.6", "0.000358"], ["84237.3", "0.023754"], ["84237.6", "0.171"], ["84237.7", "0.005938"], ["84237.9", "0.000615"], ["84238.4", "0.003294"], ["84238.7", "0.001333"], ["84239.4", "0.000333"], ["84239.8", "0.124735"], ["84239.9", "0.059399"], ["84240", "0.002077"], ["84240.6", "0.00315"], ["84240.8", "0.001466"]], "u": 45245, "seq": 67552577867}, "cts": 1742560331316}}
{"exchange": "BYBIT", "timestamp": 1742560334.031825, "message": {"topic": "orderbook.200.BTCUSDT", "ts": 1742560331520, "type": "delta", "data": {"s": "BTCUSDT", "b": [["84167.9", "0.736354"], ["84130.4", "0.04"], ["84130.2", "0"], ["84129.6", "0"], ["84129.4", "0.013"], ["84129.2", "0.00009"], ["84124", "0"], ["84095.6", "0.001423"]], "a": [["84212.4", "0.023759"], ["84218", "2.561894"], ["84240.8", "0"]], "u": 45246, "seq": 67552577913}, "cts": 1742560331510}}
{"exchange": "BYBIT", "timestamp": 1742560334.033, "message": {"topic": "orderbook.200.BTCUSDT", "ts": 1742560331719, "type": "delta", "data": {"s": "BTCUSDT", "b": [["84140.6", "0"], ["84127.3", "0.074151"], ["84124", "0.135489"], ["84095.6", "0"]], "a": [["84210", "1.724318"], ["84218", "0"], ["84223.7", "2.561894"]], "u": 45247, "seq": 67552577974}, "cts": 1742560331715}}
{"exchange": "BYBIT", "timestamp": 1742560334.03405, "message": {"topic": "orderbook.200.BTCUSDT", "ts": 1742560331919, "type": "delta", "data": {"s": "BTCUSDT", "b": [["84130.4", "0"], ["84130.2", "0.039635"], ["84129.4", "0"], ["84129.2", "0.012971"], ["84125.5", "0"], ["84125.3", "0.04955"], ["84124", "0.135493"], ["84095.6", "0.001423"]], "a": [["84206.7", "0.012973"], ["84215.2", "2.561894"], ["84223.7", "0"]], "u": 45248, "seq": 67552578041}, "cts": 1742560331916}}
{"exchange": "BYBIT", "timestamp": 1742560334.034885, "message": {"topic": "orderbook.200.BTCUSDT", "ts": 1742560332120, "type": "delta", "data": {"s": "BTCUSDT", "b": [["84130.4", "0.04"], ["84130.2", "0"], ["84125.5", "0.05"], ["84125.3", "0"]], "a": [["84168", "0.375074"], ["84197.8", "0.042222"], ["84240.6", "0"]], "u": 45249, "seq": 67552578067}, "cts": 1742560332117}}
{"exchange": "BYBIT", "timestamp": 1742560334.035694, "message": {"topic": "orderbook.200.BTCUSDT", "ts": 1742560332320, "type": "delta", "data": {"s": "BTCUSDT", "b": [["84167.9", "0.492252"], ["84167", "0.024243"], ["84166.9", "0.071621"], ["84155.7", "0.140915"], ["84155.4", "0.182512"], ["84145.6", "0.170615"], ["84145.2", "0.272449"], ["84138.2", "0.289491"], ["84136.5", "0.312032"], ["84130.4", "0"], ["84130.2", "0.039635"], ["84129.4", "0.013"], ["84129.2", "0.00009"], ["84124", "0.135498"], ["84123.9", "0.090881"], ["84096.3", "0"], ["84095.9", "0"], ["84095.7", "0"], ["84095.6", "0"]], "a": [["84168", "0.546115"], ["84176.4", "0.261047"], ["84180.2", "0.124413"], ["84180.6", "0.120459"], ["84190.4", "0.182316"], ["84190.7", "0.166459"], ["84197.7", "0.308627"], ["84199.5", "0.27915"], ["84238.7", "0"], ["84239.4", "0"], ["84239.8", "0"], ["84239.9", "0"], ["84240", "0"]], "u": 45250, "seq": 67552578127}, "cts": 1742560332316}}
{"exchange": "BYBIT", "timestamp": 1742560334.036585, "message": {"topic": "orderbook.200.BTCUSDT", "ts": 1742560332520, "type": "delta", "data": {"s": "BTCUSDT", "b": [["84167.9", "0.76996"], ["84167", "0"], ["84166.9", "0.0003"], ["84162.2", "0.182144"], ["84159.6", "0"], ["84159", "0.137172"], ["84155.7", "0.019942"], ["84155.4", "0.06"], ["84145.6", "0"], ["84145.2", "0.089099"], ["84138.7", "0.118793"], ["84138.2", "0"], ["84136.5", "0.000358"], ["84129.4", "0"], ["84129.2", "0.012971"], ["84125.5", "0"], ["84125.3", "0.04955"], ["84096.3", "0.000333"], ["84095.9", "0.06"], ["84095.7", "0.01183"]], "a": [["84168", "0.375115"], ["84176.4", "0.198714"], ["84180.2", "0"], ["84180.6", "0.001466"], ["84190.4", "0"], ["84190.7", "0"], ["84197.7", "0"], ["84199.5", "0"], ["84212.4", "2.585653"], ["84215.2", "0"], ["84221.8", "0.014411"], ["84238.7", "0.001333"], ["84239.4", "0.000333"], ["84239.8", "0.124735"], ["84239.9", "0.059399"], ["84240", "0.002077"]], "u": 45251, "seq": 67552578195}, "cts": 1742560332513}}
{"exchange": "BYBIT", "timestamp": 1742560334.037452, "message": {"topic": "orderbook.200.BTCUSDT", "ts": 1742560332719, "type": "delta", "data": {"s": "BTCUSDT", "b": [["84130.4", "0.04"], ["84130.2", "0"], ["84129.4", "0.013"], ["84129.2", "0.00009"], ["84125.5", "0.05"], ["84125.3", "0"], ["84095.7", "0"]], "a": [], "u": 45252, "seq": 67552578245}, "cts": 1742560332716}}
{"exchange": "BYBIT", "timestamp": 1742560334.039382, "message": {"topic": "orderbook.200.BTCUSDT", "ts": 1742560332920, "type": "delta", "data": {"s": "BTCUSDT", "b": [["84144.1", "0.003576"], ["84124", "0.135506"], ["84095.9", "0"]], "a": [], "u": 45253, "seq": 67552578305}, "cts": 1742560332916}}
{"exchange": "BYBIT", "timestamp": 1742560334.040222, "message": {"topic": "orderbook.200.BTCUSDT", "ts": 1742560333120, "type": "delta", "data": {"s": "BTCUSDT", "b": [["84167.9", "0.803553"], ["84160.1", "0.071326"], ["84156.2", "0"], ["84129.4", "0"], ["84129.2", "0.012971"], ["84123.9", "0.089099"], ["84095.9", "0.06"]], "a": [["84175.9", "0.001466"], ["84176.4", "0.113205"], ["84176.5", "0"], ["84192.5", "0.030066"], ["84212.4", "0.023759"], ["84223.7", "2.561894"]], "u": 45254, "seq": 67552578411}, "cts": 1742560333115}}
{"exchange": "BYBIT", "timestamp": 1742560334.040999, "message": {"topic": "orderbook.200.BTCUSDT", "ts": 1742560333320, "type": "delta", "data": {"s": "BTCUSDT", "b": [["84167.9", "0.796941"], ["84130.4", "0"], ["84130.2", "0.039635"], ["84126.9", "0.135493"], ["84125.5", "0.049549"], ["84124", "0"]], "a": [["84168", "0.375074"], ["84174", "0"], ["84176", "0.071313"], ["84176.5", "0.171"], ["84184.8", "0.003431"], ["84189", "0.000518"], ["84189.1", "0.120161"], ["84206.7", "0"], ["84206.8", "0"], ["84207.3", "0.012973"], ["84207.4", "0.013269"], ["84207.8", "0"], ["84207.9", "0"], ["84208.4", "0.041466"], ["84208.5", "0.04"], ["84212.6", "0"], ["84215", "0.024675"], ["84229", "0.118793"]], "u": 45255, "seq": 67552578524}, "cts": 1742560333310}}
{"exchange": "BYBIT", "timestamp": 1742560334.041774, "message": {"topic": "orderbook.200.BTCUSDT", "ts": 1742560333520, "type": "delta", "data": {"s": "BTCUSDT", "b": [["84162.5", "0.071324"], ["84160.6", "0.049931"], ["84127.3", "0.10553"], ["84125.6", "0.05"], ["84125.4", "0"], ["84095.9", "0"]], "a": [["84176.5", "0"], ["84185.5", "0"], ["84185.6", "0.035652"], ["84196.9", "0.001173"], ["84220.9", "2.561894"], ["84223.7", "0"]], "u": 45256, "seq": 67552578577}, "cts": 1742560333502}}
{"exchange": "BYBIT", "timestamp": 1742560334.042488, "message": {"topic": "orderbook.200.BTCUSDT", "ts": 1742560333720, "type": "delta", "data": {"s": "BTCUSDT", "b": [], "a": [["84176.5", "0.171"], ["84189", "0.119311"], ["84196.9", "0"]], "u": 45257, "seq": 67552578633}, "cts": 1742560333713}}
{"exchange": "BYBIT", "timestamp": 1742560334.043188, "message": {"topic": "orderbook.200.BTCUSDT", "ts": 1742560333920, "type": "delta", "data": {"s": "BTCUSDT", "b": [["84167.9", "0.800774"], ["84167.8", "0.071827"], ["84144.1", "0"], ["84129.5", "0.013"], ["84129.4", "0.012881"], ["84129.3", "0.001333"], ["84129.2", "0.00009"], ["84096.3", "0"]], "a": [["84176.5", "0"], ["84207", "0.013"], ["84207.1", "0.012973"], ["84207.3", "0"], ["84207.4", "0.000296"], ["84221.8", "0"], ["84240.6", "0.00315"]], "u": 45258, "seq": 67552578688}, "cts": 1742560333917}}
{"exchange": "BITGET", "timestamp": 1742560334.173014, "message": {"event": "subscribe", "arg": {"instType": "SPOT", "channel": "books", "instId": "BTCUSDT"}}}
{"exchange": "BYBIT", "timestamp": 1742560334.17306, "message": {"topic": "orderbook.200.BTCUSDT", "ts": 1742560334120, "type": "delta", "data": {"s": "BTCUSDT", "b": [["84130.4", "0.039635"], ["84130.2", "0"], ["84129.5", "0"], ["84129.3", "0.014214"], ["84125.6", "0"], ["84125.4", "0.04955"], ["84096.3", "0.000333"]], "a": [["84173.9", "0.071315"], ["84176", "0"], ["84193.8", "0.001031"], ["84207", "0"], ["84207.2", "0.012973"], ["84208.2", "0.04"], ["84208.3", "0.04"], ["84208.4", "0.001466"], ["84208.5", "0"], ["84218", "2.561894"], ["84220.9", "0"], ["84240", "0"], ["84240.6", "0"]], "u": 45259, "seq": 67552578723}, "cts": 1742560334114}}
{"exchange": "BITGET", "timestamp": 1742560334.175277, "message": {"action": "snapshot", "arg": {"instType": "SPOT", "channel": "books", "instId": "BTCUSDT"}, "data": [{"asks": [["84144.01", "1.269608"], ["84145.03", "0.113441"], ["84146.34", "0.009588"], ["84146.35", "0.015713"], ["84146.45", "0.095061"], ["84147.23", "0.006307"], ["84149.31", "0.054775"], ["84149.96", "0.006594"], ["84150.12", "0.009400"], ["84150.84", "0.017438"], ["84151.71", "0.477489"], ["84151.72", "1.591631"], ["84155.08", "0.140795"], ["84155.09", "0.256724"], ["84157.05", "0.209200"], ["84165.70", "0.004154"], ["84165.71", "0.013847"], ["84167.24", "0.119870"], ["84167.48", "0.035952"], ["84168.56", "0.035961"], ["84169.57", "0.006356"], ["84169.66", "0.006356"], ["84169.78", "0.013794"], ["84170.09", "0.006356"], ["84171.04", "0.010984"], ["84171.07", "0.006356"], ["84171.24", "0.006356"], ["84171.53", "0.006356"], ["84171.63", "0.016429"], ["84172.02", "0.006356"], ["84172.36", "0.119883"], ["84172.58", "0.006356"], ["84172.63", "0.006356"], ["84172.76", "0.006356"], ["84172.93", "0.016429"], ["84173.87", "0.006357"], ["84173.99", "0.048326"], ["84174.00", "0.004524"], ["84174.01", "0.209200"], ["84174.06", "0.010985"], ["84174.56", "0.013393"], ["84174.87", "0.009990"], ["84174.96", "0.115200"], ["84175.41", "0.184416"], ["84175.75", "0.119850"], ["84176.74", "0.119858"], ["84177.21", "0.015895"], ["84177.56", "0.119867"], ["84178.00", "0.009989"], ["84180.00", "0.002000"], ["84180.79", "0.840154"], ["84180.80", "3.709187"], ["84181.33", "0.015892"], ["84182.02", "0.010988"], ["84183.01", "0.209200"], ["84185.20", "0.001046"], ["84187.20", "0.001034"], ["84188.74", "0.712684"], ["84189.20", "0.001148"], ["84191.20", "0.003022"], ["84193.20", "0.007953"], ["84194.80", "0.209200"], ["84195.20", "0.020927"], ["84197.20", "0.055073"], ["84198.77", "0.019526"], ["84199.20", "0.144928"], ["84201.20", "0.381389"], ["84201.46", "0.001598"], ["84203.20", "1.003515"], ["84203.40", "0.205041"], ["84204.04", "0.001597"], ["84205.20", "2.640828"], ["84205.30", "0.001018"], ["84205.60", "0.006030"], ["84205.90", "0.001026"], ["84206.40", "0.001001"], ["84206.60", "0.060210"], ["84206.70", "0.511560"], ["84207.01", "0.209200"], ["84207.60", "0.430950"], ["84208.90", "0.069510"], ["84209.30", "0.974580"], ["84209.60", "0.009000"], ["84210.00", "0.060000"], ["84210.10", "0.848880"], ["84210.90", "0.066060"], ["84211.30", "0.030000"], ["84211.90", "0.022890"], ["84212.00", "0.007350"], ["84212.10", "0.084600"], ["84212.70", "0.012390"], ["84213.10", "0.030000"], ["84213.40", "2.353470"], ["84213.60", "0.060000"], ["84214.10", "0.084600"], ["84214.30", "0.120000"], ["84215.20", "0.240000"], ["84215.30", "0.120000"], ["84215.43", "0.209200"], ["84215.50", "1.021350"], ["84216.00", "0.053070"], ["84216.10", "0.340140"], ["84216.30", "0.120000"], ["84216.40", "1.780170"], ["84220.99", "0.259335"], ["84223.85", "0.209200"], ["84224.73", "1.780949"], ["84236.01", "0.208963"], ["84240.00", "0.002000"], ["84241.77", "0.001810"], ["84247.29", "0.066593"], ["84247.30", "4.254781"], ["84250.19", "0.003620"], ["84254.31", "0.209200"], ["84255.80", "5.612690"], ["84258.00", "0.006437"], ["84260.61", "0.057001"], ["84261.00", "0.000130"], ["84264.30", "4.345309"], ["84264.53", "0.071045"], ["84270.00", "0.002000"], ["84271.01", "0.209200"], ["84272.80", "4.797945"], ["84280.96", "0.209200"], ["84281.30", "4.979000"], ["84284.98", "0.000605"], ["84286.28", "0.071253"], ["84289.80", "5.069527"], ["84290.98", "0.209200"], ["84298.30", "4.073727"], ["84299.41", "0.209200"], ["84300.00", "0.002000"], ["84304.70", "0.010000"], ["84306.80", "4.435836"], ["84315.30", "5.250581"], ["84316.01", "0.209200"], ["84323.80", "5.341109"], ["84325.00", "0.002294"], ["84325.07", "0.000161"], ["84325.29", "0.209200"], ["84326.09", "0.000010"], ["84326.42", "0.000023"], ["84327.14", "0.000039"], ["84327.73", "0.041940"], ["84328.95", "0.000174"], ["84329.64", "0.000026"], ["84330.00", "0.002580"], ["84332.00", "0.010008"], ["84332.30", "4.526363"], ["84333.33", "0.002262"], ["84333.36", "0.000010"], ["84333.38", "0.000008"], ["84334.48", "0.000096"], ["84334.77", "0.000022"], ["84336.00", "0.000133"], ["84336.23", "0.000013"], ["84336.29", "0.000010"], ["84336.34", "0.000176"], ["84337.25", "0.000067"], ["84337.35", "0.000008"], ["84338.09", "0.209200"], ["84338.46", "0.000015"], ["84339.21", "0.000010"], ["84339.29", "0.000029"], ["84339.62", "0.000051"], ["84340.00", "0.018824"], ["84340.72", "0.000066"], ["84340.80", "3.892672"], ["84341.01", "0.000008"], ["84342.11", "0.000051"], ["84342.63", "0.000009"], ["84342.70", "0.000423"], ["84343.07", "0.000014"], ["84343.70", "0.000075"], ["84343.97", "0.000188"], ["84345.00", "0.000403"], ["84346.43", "0.000128"], ["84346.50", "0.209200"], ["84346.94", "0.000085"], ["84347.69", "0.000009"], ["84347.83", "0.016818"], ["84348.21", "0.000036"], ["84348.27", "0.012402"], ["84348.62", "0.000072"], ["84349.30", "5.522163"], ["84350.00", "0.002253"], ["84350.18", "0.168606"], ["84350.79", "0.000033"], ["84352.00", "0.001184"], ["84354.58", "0.000115"], ["84354.64", "0.000018"], ["84354.82", "0.000078"], ["84354.84", "0.000194"], ["84354.92", "0.209200"], ["84356.98", "0.000048"], ["84357.14", "0.000273"], ["84357.80", "4.616891"], ["84358.29", "0.000024"], ["84359.83", "0.000010"], ["84360.00", "0.004060"], ["84363.34", "0.209200"], ["84363.63", "0.000057"], ["84363.64", "0.000078"], ["84366.14", "0.000162"], ["84366.15", "0.000061"], ["84366.19", "0.000022"], ["84366.30", "5.431636"], ["84366.60", "0.000011"], ["84366.96", "0.000018"], ["84367.10", "0.000014"], ["84367.82", "0.000476"], ["84368.30", "0.309821"], ["84368.38", "0.000009"], ["84368.42", "0.000284"], ["84370.00", "0.000052"], ["84370.59", "0.000071"], ["84370.97", "0.000020"], ["84371.76", "0.209200"], ["84371.86", "0.000012"], ["84374.80", "4.164254"], ["84375.00", "0.004089"], ["84375.80", "0.000583"], ["84376.31", "0.000016"], ["84378.11", "0.000008"], ["84378.38", "0.000009"], ["84378.45", "0.000015"], ["84380.00", "0.032485"], ["84380.18", "0.209200"], ["84381.82", "0.000008"], ["84382.00", "0.000035"], ["84382.35", "0.000071"], ["84383.30", "5.160054"], ["84383.41", "0.000053"], ["84383.69", "0.000248"], ["84384.38", "0.000424"], ["84384.61", "0.000008"], ["84384.90", "0.001428"], ["84386.19", "0.000019"], ["84386.67", "0.000013"], ["84387.50", "0.006969"], ["84387.76", "0.000024"], ["84388.60", "0.209200"], ["84389.61", "0.000088"], ["84390.00", "0.002000"], ["84390.01", "0.000387"], ["84391.30", "0.000018"], ["84391.80", "4.707418"], ["84393.31", "0.000050"], ["84396.55", "0.000016"], ["84396.98", "0.007500"], ["84397.02", "0.209200"], ["84397.59", "0.000008"], ["84397.69", "0.000275"], ["84398.26", "0.000068"], ["84399.54", "0.000030"], ["84399.91", "0.000018"], ["84399.99", "0.000022"], ["84400.00", "0.060632"], ["84400.18", "0.000024"], ["84400.30", "4.888472"], ["84402.40", "0.001273"], ["84402.76", "0.001720"], ["84403.39", "0.000023"], ["84403.76", "0.000099"], ["84403.98", "0.007500"], ["84404.26", "0.000137"], ["84404.28", "0.000039"], ["84405.00", "0.000402"], ["84405.44", "0.209200"], ["84406.06", "0.000008"], ["84406.10", "0.305281"], ["84406.83", "0.000064"], ["84407.50", "0.000031"], ["84408.80", "3.983200"], ["84410.00", "0.000328"], ["84410.04", "0.000025"], ["84411.11", "0.000361"], ["84411.43", "0.000008"], ["84411.76", "0.000101"], ["84411.77", "0.000020"], ["84412.50", "0.000049"], ["84413.04", "0.000010"], ["84413.33", "0.000073"], ["84413.79", "0.000135"], ["84413.86", "0.209200"], ["84414.29", "0.000074"], ["84414.41", "0.000051"], ["84415.09", "0.000008"], ["84416.67", "0.000355"], ["84418.34", "0.000046"], ["84419.69", "0.000023"], ["84420.00", "0.003524"], ["84420.17", "0.041940"], ["84422.28", "0.209200"], ["84422.71", "0.000010"], ["84423.08", "0.000067"], ["84423.53", "0.000105"], ["84424.00", "0.000022"], ["84424.12", "0.000146"], ["84425.00", "0.002205"], ["84425.69", "0.000314"], ["84426.68", "0.000101"], ["84427.08", "0.000014"], ["84427.92", "0.000323"], ["84428.57", "0.000057"], ["84429.82", "0.000022"], ["84430.50", "0.000113"], ["84430.74", "0.000010"], ["84430.77", "0.000015"], ["84431.23", "0.000039"], ["84432.43", "0.000008"], ["84433.33", "0.000347"], ["84434.78", "0.000008"], ["84435.00", "0.000403"], ["84435.26", "0.000161"], ["84435.62", "0.026792"], ["84436.26", "0.000009"], ["84437.14", "0.000017"], ["84437.50", "0.000725"], ["84437.75", "0.000013"], ["84438.44", "0.000176"], ["84440.00", "0.001506"], ["84440.60", "0.001403"], ["84442.54", "0.000096"], ["84443.07", "0.000423"], ["84443.60", "0.001469"], ["84444.25", "0.000013"], ["84444.41", "0.000371"], ["84444.44", "0.000530"], ["84444.92", "0.000022"], ["84446.04", "0.000016"], ["84446.38", "0.000013"], ["84446.43", "0.000036"], ["84447.80", "0.000718"], ["84448.20", "0.296078"], ["84448.75", "0.000066"], ["84448.98", "0.000085"], ["84449.11", "0.000028"], ["84449.34", "0.000010"], ["84450.00", "0.010978"], ["84451.88", "0.000010"], ["84452.66", "0.000009"], ["84453.76", "0.000054"], ["84454.43", "0.000061"], ["84454.53", "0.000019"], ["84454.55", "0.000083"], ["84454.60", "0.000093"], ["84455.31", "0.000028"], ["84456.14", "0.000033"], ["84456.52", "0.002633"], ["84457.00", "0.000009"], ["84458.06", "0.000020"], ["84458.72", "0.000072"], ["84458.82", "0.000071"], ["84458.97", "0.000153"], ["84459.08", "0.000008"], ["84459.22", "0.000188"], ["84459.69", "0.000051"], ["84460.00", "0.001316"], ["84460.23", "0.000010"], ["84460.49", "0.000009"], ["84460.87", "0.000069"], ["84460.91", "0.000012"], ["84461.00", "0.000008"], ["84462.50", "0.000076"], ["84464.28", "0.000008"], ["84465.00", "0.000521"], ["84465.83", "0.000016"], ["84466.67", "0.000157"], ["84470.00", "0.000269"], ["84470.34", "0.000017"], ["84470.59", "0.000071"], ["84473.14", "0.000126"], ["84473.68", "0.000192"], ["84474.78", "0.000099"], ["84475.00", "0.009271"], ["84475.81", "0.000039"], ["84476.97", "0.000063"], ["84477.61", "0.000095"], ["84477.67", "0.000008"], ["84478.74", "0.000036"], ["84479.37", "0.000090"], ["84480.00", "0.003868"], ["84481.00", "0.000069"], ["84481.77", "0.000011"], ["84482.67", "0.000133"], ["84482.76", "0.000016"], ["84485.20", "0.000537"], ["84485.39", "0.000020"], ["84485.71", "0.000128"], ["84485.98", "0.000034"], ["84486.49", "0.000009"], ["84486.82", "0.000135"], ["84487.00", "0.000119"], ["84487.16", "0.000035"], ["84487.32", "0.000024"], ["84487.95", "0.000008"], ["84488.88", "0.000025"], ["84489.36", "0.000137"], ["84489.39", "0.000039"], ["84489.80", "0.000010"], ["84490.00", "0.007779"], ["84490.13", "0.000093"], ["84490.91", "0.000018"], ["84491.26", "0.000008"], ["84491.87", "0.000019"], ["84492.06", "0.000009"], ["84495.00", "0.000403"], ["84496.43", "0.000273"], ["84496.73", "0.000043"], ["84497.14", "0.000008"], ["84497.26", "0.000010"], ["84499.68", "1.723914"], ["84500.00", "1.110091"], ["84500.03", "0.000010"], ["84500.04", "0.000008"], ["84500.11", "0.000012"], ["84501.24", "0.000010"], ["84501.28", "0.000019"], ["84501.99", "0.000009"], ["84503.33", "0.010000"], ["84503.57", "0.000074"], ["84504.50", "0.000061"], ["84504.74", "0.000013"], ["84506.54", "0.000008"], ["84506.67", "0.000008"], ["84508.00", "0.001210"], ["84508.37", "0.000050"], ["84508.46", "0.000013"], ["84508.47", "0.000023"], ["84510.00", "0.000923"], ["84510.34", "0.000135"], ["84512.00", "0.000012"], ["84512.19", "0.000016"], ["84512.61", "0.041940"], ["84512.95", "0.000023"], ["84514.29", "0.000059"], ["84516.67", "0.000010"], ["84517.54", "0.000022"], ["84517.86", "0.000016"], ["84518.98", "0.000029"], ["84520.00", "0.001011"], ["84520.50", "0.000238"], ["84520.67", "0.002384"], ["84521.85", "0.000033"], ["84522.06", "0.000041"], ["84523.08", "0.000015"], ["84523.48", "0.000015"], ["84523.81", "0.000024"], ["84524.00", "0.000035"], ["84524.83", "0.000009"], ["84525.00", "0.003807"], ["84525.82", "0.000099"], ["84527.47", "0.000608"], ["84528.57", "0.000008"], ["84530.00", "0.000031"], ["84533.01", "0.000591"], ["84533.33", "0.003186"], ["84534.53", "0.000461"], ["84535.32", "0.000039"], ["84536.36", "0.000053"], ["84537.04", "0.000958"], ["84538.75", "0.000011"], ["84540.00", "0.001635"], ["84540.54", "0.000184"], ["84540.97", "0.000065"], ["84541.67", "0.000198"], ["84542.37", "0.001213"], ["84543.27", "0.000067"], ["84543.43", "0.000423"], ["84543.86", "0.000033"], ["84543.93", "0.000010"], ["84544.64", "0.000036"], ["84545.16", "0.000020"], ["84545.45", "0.001774"], ["84545.63", "0.000008"], ["84547.06", "0.000071"], ["84549.65", "0.000030"], ["84549.96", "0.000012"], ["84550.00", "0.006885"], ["84550.60", "0.000096"], ["84551.02", "0.000085"], ["84552.59", "0.000009"], ["84552.95", "0.000009"], ["84553.04", "0.000129"], ["84554.00", "0.000113"], ["84555.00", "0.005926"], ["84555.08", "0.000022"], ["84555.35", "0.000016"], ["84555.56", "0.000130"], ["84555.60", "0.000016"], ["84556.52", "0.000013"], ["84556.79", "0.000066"], ["84557.29", "0.000014"], ["84557.67", "0.000041"], ["84558.82", "0.000080"], ["84559.10", "0.000036"], ["84559.47", "0.000010"], ["84560.00", "0.000255"], ["84561.11", "0.000134"]], "bids": [["84144.00", "0.905948"], ["84143.59", "0.003010"], ["84143.58", "0.010000"], ["84142.00", "0.000032"], ["84141.00", "0.000032"], ["84140.90", "0.001025"], ["84140.00", "0.000045"], ["84139.00", "0.000032"], ["84138.90", "0.001384"], ["84138.03", "0.006673"], ["84138.02", "0.010010"], ["84138.00", "0.000032"], ["84137.36", "0.008515"], ["84137.00", "0.000032"], ["84136.90", "0.003641"], ["84136.00", "0.000032"], ["84135.00", "0.000032"], ["84134.90", "0.009581"], ["84134.65", "0.007160"], ["84134.63", "0.005589"], ["84134.59", "0.072005"], ["84134.58", "0.209200"], ["84134.00", "0.000032"], ["84133.75", "0.009718"], ["84133.15", "0.010321"], ["84133.11", "0.008701"], ["84133.00", "0.000032"], ["84132.90", "0.025364"], ["84132.41", "0.005163"], ["84132.36", "0.008524"], ["84132.31", "0.004821"], ["84132.25", "0.009851"], ["84132.00", "0.000032"], ["84131.00", "0.000032"], ["84130.91", "0.078561"], ["84130.90", "0.066767"], ["84130.38", "0.000241"], ["84130.35", "0.008886"], ["84130.00", "0.000045"], ["84129.55", "0.005112"], ["84129.51", "0.005575"], ["84129.03", "0.000008"], ["84129.00", "0.000032"], ["84128.90", "0.175704"], ["84128.00", "0.000032"], ["84127.09", "0.089399"], ["84127.00", "0.000032"], ["84126.91", "0.554244"], ["84126.90", "0.462377"], ["84126.53", "0.014172"], ["84126.00", "0.247382"], ["84125.00", "0.000032"], ["84124.98", "0.017800"], ["84124.90", "1.216782"], ["84124.80", "0.083859"], ["84124.73", "0.018237"], ["84124.49", "0.005940"], ["84124.33", "0.025266"], ["84124.00", "0.004045"], ["84123.25", "0.055602"], ["84123.00", "0.000032"], ["84122.91", "2.058464"], ["84122.90", "3.202058"], ["84122.87", "0.209200"], ["84122.77", "0.017087"], ["84122.61", "0.007125"], ["84122.00", "0.000032"], ["84121.99", "0.028837"], ["84121.97", "0.008985"], ["84121.89", "0.007332"], ["84121.60", "0.025160"], ["84121.36", "0.007935"], ["84121.09", "0.017334"], ["84121.06", "0.026168"], ["84121.03", "0.224667"], ["84121.00", "0.000032"], ["84120.92", "0.013393"], ["84120.91", "0.008177"], ["84120.90", "8.426470"], ["84120.80", "0.006240"], ["84120.00", "0.002045"], ["84119.90", "0.202800"], ["84119.51", "0.008257"], ["84119.37", "0.051913"], ["84119.20", "0.036060"], ["84119.18", "0.012643"], ["84119.00", "0.000032"], ["84118.49", "0.018499"], ["84118.30", "0.178320"], ["84118.00", "0.000032"], ["84117.90", "0.084780"], ["84117.74", "0.008052"], ["84117.52", "0.268119"], ["84117.41", "0.005927"], ["84117.39", "0.026611"], ["84117.34", "0.009175"], ["84117.29", "0.008418"], ["84117.27", "0.006463"], ["84117.20", "0.704430"], ["84117.10", "1.423080"], ["84117.00", "0.000032"], ["84116.98", "0.259547"], ["84116.57", "0.021109"], ["84116.49", "0.222456"], ["84116.12", "0.076039"], ["84116.00", "0.000032"], ["84115.92", "0.007749"], ["84115.91", "0.009198"], ["84115.90", "0.084600"], ["84115.88", "0.006898"], ["84115.84", "0.007295"], ["84115.83", "0.007785"], ["84115.71", "0.000200"], ["84115.60", "0.267300"], ["84115.40", "0.007170"], ["84115.00", "0.000032"], ["84114.71", "0.033089"], ["84114.64", "0.018474"], ["84114.44", "0.209200"], ["84114.40", "0.057000"], ["84114.20", "0.035640"], ["84114.00", "0.000032"], ["84113.40", "0.356430"], ["84113.00", "0.000032"], ["84112.90", "0.740760"], ["84112.68", "0.713328"], ["84112.62", "2.995499"], ["84112.50", "1.350000"], ["84112.33", "0.073145"], ["84112.30", "0.192000"], ["84112.00", "0.000032"], ["84111.90", "0.084600"], ["84111.80", "0.071100"], ["84111.50", "0.180000"], ["84111.42", "0.008083"], ["84111.40", "0.269760"], ["84111.34", "0.056313"], ["84111.27", "0.006202"], ["84111.20", "0.153580"], ["84111.10", "0.178230"], ["84111.00", "0.009032"], ["84110.60", "0.300000"], ["84110.50", "0.132000"], ["84110.30", "0.106920"], ["84110.00", "0.000045"], ["84109.31", "0.000875"], ["84109.00", "0.000032"], ["84108.84", "0.008255"], ["84108.80", "0.017820"], ["84108.71", "0.005045"], ["84108.00", "0.000032"], ["84107.00", "0.000032"], ["84106.01", "0.209200"], ["84106.00", "0.000032"], ["84105.00", "0.000032"], ["84104.00", "0.000032"], ["84103.00", "0.000032"], ["84102.00", "0.000032"], ["84101.10", "0.000396"], ["84101.00", "0.000032"], ["84100.00", "0.000045"], ["84099.00", "0.000032"], ["84098.00", "0.000032"], ["84097.58", "0.209200"], ["84097.00", "0.000032"], ["84096.00", "0.000032"], ["84095.89", "0.007425"], ["84095.00", "0.000032"], ["84094.00", "0.000032"], ["84092.00", "0.000015"], ["84091.76", "0.003593"], ["84091.06", "0.001175"], ["84090.07", "0.008563"], ["84090.00", "0.002013"], ["84089.76", "0.001172"], ["84089.15", "0.209200"], ["84088.78", "0.007239"], ["84088.68", "0.007327"], ["84088.61", "0.007644"], ["84085.23", "0.017438"], ["84082.92", "0.000386"], ["84081.80", "0.208446"], ["84080.72", "0.209200"], ["84080.00", "0.000013"], ["84078.80", "4.979000"], ["84072.29", "0.209200"], ["84071.60", "0.000948"], ["84070.30", "5.160054"], ["84070.00", "0.000013"], ["84063.86", "0.209200"], ["84061.80", "4.435836"], ["84061.21", "0.012390"], ["84060.16", "0.001810"], ["84060.00", "0.002013"], ["84058.43", "0.071045"], ["84056.31", "0.071253"], ["84055.44", "0.209200"], ["84053.30", "3.983200"], ["84053.15", "0.057001"], ["84050.37", "0.003620"], ["84050.00", "0.000013"], ["84047.02", "0.209200"], ["84044.80", "5.250581"], ["84041.50", "0.001459"], ["84040.00", "0.000013"], ["84038.71", "0.000008"], ["84038.60", "0.209200"], ["84037.30", "0.295591"], ["84036.30", "4.164254"], ["84030.18", "0.209200"], ["84030.00", "0.002013"], ["84027.80", "4.254781"], ["84021.76", "0.209200"], ["84020.41", "0.000022"], ["84020.00", "0.000013"], ["84019.30", "4.526363"], ["84019.00", "0.020000"], ["84016.80", "0.005950"], ["84013.34", "0.209200"], ["84012.21", "0.000079"], ["84012.00", "0.000134"], ["84010.80", "4.073727"], ["84010.00", "0.000282"], ["84009.88", "0.000111"], ["84002.30", "4.797945"], ["84001.00", "0.010000"], ["84000.00", "0.006715"], ["83993.80", "5.522163"], ["83990.00", "0.000282"], ["83985.30", "4.888472"], ["83985.19", "0.001532"], ["83980.00", "0.000282"], ["83979.78", "0.005950"], ["83977.88", "0.000027"], ["83976.80", "3.892672"], ["83975.20", "0.308301"], ["83974.10", "0.001475"], ["83970.00", "0.002282"], ["83969.74", "0.011010"], ["83968.30", "5.069527"], ["83965.52", "0.000146"], ["83963.96", "0.000010"], ["83962.77", "0.026787"], ["83960.00", "0.000282"], ["83959.80", "5.612690"], ["83959.56", "0.000388"], ["83953.44", "0.018392"], ["83952.00", "0.001184"], ["83951.30", "4.616891"], ["83950.71", "0.003372"], ["83950.63", "0.000008"], ["83950.00", "0.007987"], ["83948.39", "0.000008"], ["83948.26", "0.000028"], ["83945.45", "0.000010"], ["83944.70", "0.307713"], ["83942.80", "5.341109"], ["83942.73", "0.001720"], ["83940.00", "0.002290"], ["83937.50", "0.000076"], ["83936.50", "0.000113"], ["83934.80", "0.001444"], ["83934.30", "4.345309"], ["83930.00", "0.000282"], ["83928.70", "0.000016"], ["83928.57", "0.000010"], ["83926.71", "0.000052"], ["83925.80", "5.431636"], ["83924.00", "0.004480"], ["83922.22", "0.000363"], ["83920.00", "0.001321"], ["83919.00", "0.001216"], ["83918.14", "0.000035"], ["83917.50", "0.000031"], ["83917.30", "4.707418"], ["83910.00", "0.002937"], ["83909.09", "0.000105"], ["83908.04", "0.000315"], ["83906.16", "0.000016"], ["83905.71", "0.000017"], ["83904.35", "0.000032"], ["83901.67", "0.000019"], ["83900.00", "0.031356"], ["83896.37", "0.001273"], ["83895.00", "0.000924"], ["83893.64", "0.000039"], ["83893.62", "0.000137"], ["83892.29", "0.000143"], ["83891.89", "0.000008"], ["83890.00", "0.000630"], ["83888.91", "0.000010"], ["83880.00", "0.003244"], ["83879.31", "0.000016"], ["83877.29", "0.000024"], ["83877.01", "0.000023"], ["83875.45", "0.000363"], ["83875.16", "0.000179"], ["83875.00", "0.000787"], ["83873.87", "0.000061"], ["83873.52", "0.000135"], ["83870.00", "0.000630"], ["83868.39", "0.002014"], ["83866.67", "0.002945"], ["83865.00", "0.000924"], ["83862.50", "0.006969"], ["83860.29", "0.000041"], ["83860.00", "0.002261"], ["83859.54", "0.000008"], ["83858.06", "0.000008"], ["83857.14", "0.000079"], ["83857.13", "0.000019"], ["83856.11", "0.010000"], ["83855.44", "0.000008"], ["83855.42", "0.000008"], ["83854.55", "0.000009"], ["83854.17", "0.000020"], ["83852.94", "0.000071"], ["83852.50", "0.000043"], ["83851.85", "0.000011"], ["83851.84", "0.000219"], ["83850.00", "0.002961"], ["83848.39", "0.000020"], ["83846.15", "0.000111"], ["83844.83", "0.000008"], ["83842.11", "0.000033"], ["83841.18", "0.000071"], ["83840.00", "0.001045"], ["83839.72", "0.000033"], ["83839.18", "0.000016"], ["83837.84", "0.000009"], ["83837.59", "0.000012"], ["83836.80", "0.002419"], ["83836.36", "0.000008"], ["83835.56", "0.000009"], ["83835.20", "0.503004"], ["83835.00", "0.000522"], ["83834.48", "0.000135"], ["83831.11", "0.000011"], ["83830.59", "0.000010"], ["83830.00", "0.000693"], ["83828.57", "0.000016"], ["83826.67", "0.000081"], ["83826.37", "1.594085"], ["83822.22", "0.000025"], ["83822.12", "0.000067"], ["83820.00", "0.002643"], ["83818.18", "0.001568"], ["83818.17", "0.000029"], ["83816.67", "0.000010"], ["83816.28", "0.000009"], ["83816.00", "0.000008"], ["83815.79", "0.000022"], ["83815.75", "0.000009"], ["83815.37", "0.000022"], ["83813.00", "0.000113"], ["83810.74", "0.000019"], ["83810.00", "0.000630"], ["83808.53", "0.000039"], ["83808.51", "0.000137"], ["83807.88", "0.000051"], ["83807.53", "0.000010"], ["83807.42", "0.001534"], ["83804.35", "0.000010"], ["83803.57", "0.000016"], ["83802.81", "0.000022"], ["83800.91", "0.000012"], ["83800.00", "0.041881"], ["83799.34", "0.000093"], ["83796.61", "0.001213"], ["83795.00", "0.000031"], ["83794.17", "0.000096"], ["83793.10", "0.000016"], ["83791.03", "0.000996"], ["83791.02", "0.000351"], ["83790.15", "0.000024"], ["83790.00", "0.002737"], ["83789.60", "0.000363"], ["83789.29", "0.000074"], ["83787.88", "0.000010"], ["83785.71", "0.000081"], ["83784.62", "0.000015"], ["83784.36", "0.000069"], ["83784.02", "0.000022"], ["83783.78", "0.000069"], ["83783.12", "0.000008"], ["83780.48", "0.000016"], ["83780.00", "0.000943"], ["83779.93", "0.000028"], ["83777.78", "0.000679"], ["83777.60", "0.000013"], ["83777.18", "0.000013"], ["83775.00", "0.006969"], ["83774.10", "0.000161"], ["83773.31", "0.000154"], ["83773.11", "0.041940"], ["83772.88", "0.000023"], ["83770.00", "0.000630"], ["83769.28", "0.000972"], ["83768.46", "0.000008"], ["83768.00", "0.000012"], ["83767.74", "0.000008"], ["83766.84", "0.000023"], ["83765.06", "0.000008"], ["83764.71", "0.000071"], ["83763.64", "0.000010"], ["83762.50", "0.000076"], ["83761.90", "0.000024"], ["83761.29", "0.000020"], ["83760.00", "0.004786"], ["83758.93", "0.000036"], ["83758.00", "0.000353"], ["83757.40", "0.000537"], ["83756.08", "0.000099"], ["83755.56", "0.000134"], ["83754.70", "0.000013"], ["83754.39", "0.000033"], ["83752.94", "0.000071"], ["83752.37", "0.000119"], ["83752.09", "0.000314"], ["83752.00", "0.000034"], ["83750.67", "0.000146"], ["83750.44", "0.000067"], ["83750.00", "0.040932"], ["83749.66", "0.000016"], ["83749.50", "0.000069"], ["83749.33", "0.000133"], ["83748.54", "0.000012"], ["83746.09", "0.000010"], ["83745.16", "0.000389"], ["83743.29", "0.001451"], ["83740.51", "0.000423"], ["83740.00", "0.000090"], ["83739.60", "0.000048"], ["83739.28", "0.000051"], ["83739.13", "0.000008"], ["83737.93", "0.000135"], ["83737.37", "0.000012"], ["83737.00", "0.000009"], ["83736.94", "0.000104"], ["83736.84", "0.000183"], ["83736.33", "0.000025"], ["83734.69", "0.000085"], ["83733.33", "0.003222"], ["83732.10", "0.000009"], ["83731.48", "0.000124"], ["83730.00", "0.002013"], ["83729.73", "0.000009"], ["83729.39", "0.000008"], ["83729.32", "0.000035"], ["83728.57", "0.000017"], ["83728.37", "0.001273"], ["83728.07", "0.000022"], ["83727.71", "0.000009"], ["83727.27", "0.000082"], ["83726.20", "0.000016"], ["83725.00", "0.000286"], ["83723.72", "0.000176"], ["83723.64", "0.000009"], ["83723.61", "0.000883"], ["83723.43", "0.000039"], ["83723.40", "0.000205"], ["83721.56", "0.000015"], ["83720.00", "0.002450"], ["83719.46", "0.000053"], ["83717.93", "0.000065"], ["83717.46", "0.000009"], ["83717.45", "0.000040"], ["83717.39", "0.000010"], ["83715.48", "0.000010"], ["83714.29", "0.009987"], ["83714.28", "0.000836"], ["83713.80", "0.000024"], ["83713.71", "0.000323"], ["83713.40", "0.000161"], ["83713.33", "0.000008"], ["83711.93", "0.000018"], ["83710.00", "0.000036"], ["83709.88", "0.000107"], ["83707.07", "0.000067"], ["83706.90", "0.000016"], ["83706.67", "0.000013"], ["83705.85", "0.000019"], ["83705.32", "0.000065"], ["83705.18", "0.000009"], ["83703.75", "0.000363"], ["83703.70", "0.000455"], ["83703.00", "0.000024"], ["83702.93", "0.000050"], ["83702.60", "0.000039"], ["83702.50", "0.000033"], ["83702.48", "0.000057"], ["83701.92", "0.000067"], ["83701.28", "0.000248"], ["83700.00", "0.006005"], ["83699.88", "0.000008"], ["83697.23", "0.000095"], ["83695.65", "0.003535"], ["83695.63", "0.000011"], ["83693.69", "0.000061"], ["83692.52", "0.000066"]], "checksum": 0, "ts": "1742560333951"}], "ts": 1742560334096}}
{"exchange": "BITGET", "timestamp": 1742560334.188238, "message": {"action": "update", "arg": {"instType": "SPOT", "channel": "books", "instId": "BTCUSDT"}, "data": [{"asks": [["84146.35", "0.110774"], ["84146.45", "0"], ["84189.20", "0.001364"], ["84191.20", "0.003589"], ["84193.20", "0.009445"], ["84195.20", "0.024856"], ["84197.20", "0.065411"], ["84199.20", "0.172134"], ["84201.20", "0.452983"], ["84203.20", "1.192060"], ["84205.20", "3.137002"], ["84205.90", "0"], ["84206.70", "0.511770"], ["84208.30", "1.051470"], ["84209.30", "0.211230"], ["84211.40", "2.353530"], ["84213.40", "0"], ["84216.60", "0.240000"], ["84247.30", "4.707418"], ["84255.80", "5.250581"], ["84264.30", "4.526363"], ["84272.80", "4.979000"], ["84281.30", "4.164254"], ["84289.80", "3.892672"], ["84298.30", "5.160054"], ["84306.80", "4.345309"], ["84315.30", "5.069527"], ["84323.80", "5.612690"], ["84332.30", "5.522163"], ["84340.80", "4.616891"], ["84349.30", "4.797945"], ["84357.80", "5.431636"], ["84366.30", "4.888472"], ["84374.80", "4.254781"], ["84383.30", "5.341109"], ["84391.80", "3.983200"], ["84400.30", "4.073727"], ["84408.80", "4.435836"]], "bids": [["84078.80", "4.164254"], ["84070.30", "4.345309"], ["84061.80", "5.250581"], ["84053.30", "5.341109"], ["84044.80", "4.797945"], ["84036.30", "4.707418"], ["84027.80", "4.616891"], ["84019.30", "4.979000"], ["84010.80", "5.160054"], ["84002.30", "5.069527"], ["83993.80", "5.612690"], ["83985.30", "4.435836"], ["83976.80", "3.983200"], ["83968.30", "3.892672"], ["83959.80", "5.431636"], ["83951.30", "4.254781"], ["83942.80", "4.888472"], ["83934.30", "5.522163"], ["83925.80", "4.073727"], ["83917.30", "4.526363"]], "checksum": 2055676642, "ts": "1742560334158"}], "ts": 1742560334160}}
{"exchange": "BYBIT", "timestamp": 1742560334.339997, "message": {"topic": "orderbook.200.BTCUSDT", "ts": 1742560334320, "type": "delta", "data": {"s": "BTCUSDT", "b": [["84172.9", "0.838716"], ["84168", "0.096991"], ["84167.9", "0.228788"], ["84164.9", "0.071322"], ["84164.5", "0.01"], ["84162.8", "0.00009"], ["84162.3", "0.108005"], ["84162.2", "0.059399"], ["84161.2", "0"], ["84160.3", "0"], ["84160.1", "0"], ["84159.5", "0.005"], ["84159.4", "0.089432"], ["84157", "0.1"], ["84150.3", "0.004909"], ["84125.9", "0.049555"], ["84125.8", "0.049888"], ["84125.5", "0"], ["84125.4", "0"], ["84096.4", "0"], ["84096.3", "0"]], "a": [["84168", "0"], ["84168.9", "0"], ["84173", "0.010024"], ["84173.9", "0"], ["84174.7", "0"], ["84176.4", "0.028515"], ["84178.9", "0"], ["84180.7", "0.071309"], ["84181.4", "0.01"], ["84185.6", "0"], ["84186.1", "0.04"], ["84189", "0.000518"], ["84189.3", "0"], ["84193.7", "0.006278"], ["84193.8", "0"], ["84194.9", "0.001242"], ["84198.1", "0"], ["84207.1", "0"], ["84207.2", "0"], ["84208.2", "0"], ["84208.3", "0.012973"], ["84208.4", "0.014439"], ["84208.7", "0"], ["84209.4", "0.04"], ["84209.5", "0.04"], ["84210", "0.299591"], ["84214.4", "0.063463"], ["84216.1", "0.861597"], ["84218", "0"], ["84226.5", "2.561894"], ["84240", "0.002077"], ["84240.6", "0.00315"], ["84240.8", "0.001466"], ["84240.9", "0.01656"], ["84242.6", "0.003294"], ["84242.9", "0.001333"], ["84243.4", "0.00009"]], "u": 45260, "seq": 67552578992}, "cts": 1742560334314}}
{"exchange": "BITGET", "timestamp": 1742560334.40211, "message": {"action": "update", "arg": {"instType": "SPOT", "channel": "books", "instId": "BTCUSDT"}, "data": [{"asks": [["84144.01", "1.220939"], ["84149.31", "0"], ["84149.82", "0.054775"], ["84150.84", "0"], ["84155.09", "0.209556"], ["84162.27", "0.017436"], ["84189.20", "0.001148"], ["84191.20", "0.003021"], ["84193.20", "0.007950"], ["84195.20", "0.020921"], ["84197.20", "0.055055"], ["84199.20", "0.144883"], ["84201.20", "0.381271"], ["84203.20", "1.003345"], ["84205.20", "2.640382"], ["84206.70", "0.060210"], ["84207.60", "0"], ["84208.30", "0"], ["84210.00", "0.002000"], ["84210.10", "0.200400"], ["84211.40", "0"], ["84211.80", "2.353500"], ["84212.10", "0.144600"], ["84213.60", "0"], ["84216.60", "0.180000"], ["84216.70", "1.068090"], ["84217.80", "0.035610"], ["84247.30", "5.341109"], ["84255.80", "5.431636"], ["84264.30", "5.612690"], ["84272.80", "4.435836"], ["84281.30", "4.888472"], ["84298.30", "4.254781"], ["84315.30", "5.522163"], ["84323.80", "4.073727"], ["84332.30", "4.797945"], ["84340.80", "4.526363"], ["84349.30", "4.979000"], ["84357.80", "5.069527"], ["84366.30", "4.616891"], ["84374.80", "4.164254"], ["84383.30", "4.707418"], ["84391.80", "5.160054"], ["84400.30", "3.983200"], ["84408.80", "5.250581"], ["84562.50", "0.006969"]], "bids": [["84144.00", "0.918063"], ["84138.90", "0.001575"], ["84136.90", "0.004143"], ["84134.90", "0.010904"], ["84132.90", "0.028695"], ["84130.90", "0.075512"], ["84130.38", "0"], ["84128.90", "0.198717"], ["84126.90", "0.522940"], ["84124.90", "1.376157"], ["84122.90", "3.621467"], ["84120.92", "0"], ["84120.90", "9.530175"], ["84115.90", "0.264600"], ["84115.40", "0.541800"], ["84112.62", "0"], ["84112.60", "0.356400"], ["84111.30", "0.045000"], ["84110.20", "0.045000"], ["84108.80", "0"], ["84096.64", "0.017436"], ["84085.23", "0"], ["84078.80", "5.522163"], ["84070.30", "4.164254"], ["84061.80", "5.069527"], ["84053.30", "4.254781"], ["84044.80", "3.983200"], ["84036.30", "5.250581"], ["84027.80", "4.526363"], ["84019.30", "4.616891"], ["84010.80", "4.888472"], ["84002.30", "5.341109"], ["83993.80", "5.431636"], ["83985.30", "4.797945"], ["83976.80", "4.435836"], ["83968.30", "4.073727"], ["83959.80", "3.892672"], ["83951.30", "4.345309"], ["83942.80", "4.979000"], ["83934.30", "5.612690"], ["83925.80", "5.160054"], ["83917.30", "4.707418"], ["83750.00", "0.041201"], ["83692.38", "0.000007"]], "checksum": -666076792, "ts": "1742560334365"}], "ts": 1742560334368}}
{"exchange": "BYBIT", "timestamp": 1742560334.541897, "message": {"topic": "orderbook.200.BTCUSDT", "ts": 1742560334519, "type": "delta", "data": {"s": "BTCUSDT", "b": [["84172.9", "0.838954"], ["84167.9", "0.227006"], ["84166.9", "0"], ["84164.5", "0.04701"], ["84163.4", "0.167167"], ["84162.3", "0"], ["84159.5", "0"], ["84150.3", "0.001333"], ["84130.8", "0.539416"], ["84130.7", "0.064464"], ["84130.4", "0"], ["84130.3", "0"], ["84123.3", "0.001782"], ["84096.4", "0.0001"], ["84096.3", "0.000333"], ["84095.9", "0.06"]], "a": [["84173", "0.057782"], ["84176.4", "0.023515"], ["84181.4", "0.08969"], ["84188.1", "0.065716"], ["84190.6", "0.04"], ["84193.7", "0.046278"], ["84194.7", "0.032195"], ["84194.9", "0"], ["84197", "0.001119"], ["84197.8", "0"], ["84209.2", "0.041333"], ["84209.3", "0.04"], ["84209.4", "0"], ["84209.5", "0"], ["84209.8", "0.00009"], ["84214.4", "0"], ["84216.1", "0.130344"], ["84243.6", "0.000423"]], "u": 45261, "seq": 67552579085}, "cts": 1742560334516}}
{"exchange": "BITGET", "timestamp": 1742560334.601286, "message": {"action": "update", "arg": {"instType": "SPOT", "channel": "books", "instId": "BTCUSDT"}, "data": [{"asks": [["84162.26", "0.009385"], ["84165.70", "0"], ["84203.20", "1.003557"], ["84205.20", "2.640940"], ["84208.10", "0.873120"], ["84209.00", "0.402030"], ["84210.10", "0.896580"], ["84215.10", "0.072780"], ["84217.80", "0"], ["84247.30", "4.888472"], ["84255.80", "4.616891"], ["84264.30", "5.522163"], ["84272.80", "4.254781"], ["84281.30", "5.612690"], ["84298.30", "4.526363"], ["84306.80", "4.797945"], ["84315.30", "5.160054"], ["84323.80", "4.345309"], ["84332.30", "4.073727"], ["84340.80", "4.435836"], ["84349.30", "5.069527"], ["84357.80", "5.250581"], ["84366.30", "4.979000"], ["84374.80", "4.707418"], ["84383.30", "3.983200"], ["84391.80", "4.164254"], ["84400.30", "5.341109"], ["84408.80", "5.431636"], ["84561.11", "0"], ["84562.50", "0"]], "bids": [["84144.00", "0.708863"], ["84139.01", "0.000241"], ["84128.90", "0.198881"], ["84126.90", "0.523371"], ["84124.90", "1.377535"], ["84122.90", "3.625092"], ["84121.82", "2.995338"], ["84120.90", "9.539717"], ["84117.20", "0.882630"], ["84115.50", "0.153580"], ["84112.90", "1.707630"], ["84111.90", "0.441000"], ["84111.30", "0.579600"], ["84111.20", "0"], ["84110.60", "0.144000"], ["84110.50", "0"], ["84110.30", "0"], ["84110.20", "0"], ["84093.00", "0.000017"], ["84086.10", "0.208446"], ["84081.80", "0"], ["84078.80", "4.254781"], ["84070.30", "4.888472"], ["84061.80", "4.073727"], ["84053.30", "4.616891"], ["84044.80", "5.612690"], ["84036.30", "4.435836"], ["84027.80", "5.160054"], ["84019.30", "4.707418"], ["84010.80", "4.979000"], ["84002.30", "5.431636"], ["83993.80", "4.345309"], ["83985.30", "5.069527"], ["83976.80", "3.983200"], ["83968.30", "3.892672"], ["83959.80", "5.522163"], ["83951.30", "4.797945"], ["83942.80", "4.164254"], ["83934.30", "5.250581"], ["83925.80", "4.526363"], ["83917.30", "5.341109"]], "checksum": -1408315482, "ts": "1742560334567"}], "ts": 1742560334571}}
{"exchange": "BYBIT", "timestamp": 1742560334.743394, "message": {"topic": "orderbook.200.BTCUSDT", "ts": 1742560334720, "type": "delta", "data": {"s": "BTCUSDT", "b": [["84172.9", "0.667954"], ["84171.8", "0.021395"], ["84171.7", "0.071317"], ["84162.2", "0.168424"], ["84159.4", "0.000333"], ["84158.4", "0.112946"], ["84152.4", "0.180383"], ["84151.4", "0.183598"], ["84144.4", "0.276524"], ["84143.3", "0.287032"], ["84130.8", "0.539055"], ["84129.8", "0.012883"], ["84129.7", "0.014349"], ["84129.4", "0"], ["84129.3", "0.001333"], ["84097.1", "0"], ["84096.6", "0"], ["84096.5", "0"], ["84096.4", "0"], ["84096.3", "0"], ["84095.9", "0"]], "a": [["84173", "0.129097"], ["84187.4", "0.119335"], ["84191.3", "0.118079"], ["84197", "0"], ["84197.2", "0.17744"], ["84198.3", "0.177233"], ["84205.3", "0.275119"], ["84206.3", "0.2788"], ["84208.1", "0.012973"], ["84208.2", "0.012973"], ["84208.3", "0"], ["84208.4", "0.001466"], ["84208.7", "0.06346"], ["84220.9", "2.561742"], ["84226.5", "0"], ["84240.8", "0"], ["84240.9", "0"], ["84242.6", "0"], ["84242.9", "0"], ["84243.4", "0"], ["84243.6", "0"]], "u": 45262, "seq": 67552579176}, "cts": 1742560334713}}
{"exchange": "BITGET", "timestamp": 1742560334.796906, "message": {"action": "update", "arg": {"instType": "SPOT", "channel": "books", "instId": "BTCUSDT"}, "data": [{"asks": [["84145.02", "0.072033"], ["84146.26", "0.095061"], ["84146.35", "0.015713"], ["84167.48", "0"], ["84168.35", "0.035952"], ["84168.56", "0"], ["84169.57", "0"], ["84169.66", "0"], ["84169.88", "0.035961"], ["84170.09", "0"], ["84170.51", "0.006356"], ["84170.61", "0.006356"], ["84170.97", "0.006356"], ["84171.04", "0"], ["84171.07", "0"], ["84171.24", "0"], ["84171.53", "0"], ["84171.90", "0.010984"], ["84172.02", "0"], ["84172.35", "0.006356"], ["84172.36", "0"], ["84172.52", "0.006356"], ["84172.63", "0"], ["84172.76", "0"], ["84172.86", "0.006356"], ["84172.93", "0"], ["84173.35", "0.006356"], ["84173.50", "0.006356"], ["84173.68", "0.119883"], ["84173.87", "0"], ["84173.97", "0.016429"], ["84174.03", "0.006356"], ["84174.06", "0"], ["84174.87", "0"], ["84175.20", "0.006357"], ["84175.40", "0.181948"], ["84175.75", "0"], ["84176.20", "0.009990"], ["84177.07", "0.119850"], ["84177.21", "0"], ["84177.56", "0"], ["84178.00", "0"], ["84178.54", "0.015895"], ["84178.59", "0.119867"], ["84178.87", "0.009989"], ["84181.33", "0"], ["84182.02", "0"], ["84182.59", "0.015892"], ["84183.35", "0.010988"], ["84189.20", "0.001910"], ["84191.20", "0.005252"], ["84193.20", "0.013822"], ["84195.20", "0.036372"], ["84197.20", "0.095716"], ["84199.20", "0.251886"], ["84201.20", "0.662858"], ["84203.20", "1.744361"], ["84204.04", "0"], ["84205.20", "4.590424"], ["84206.70", "0.285480"], ["84207.36", "0.001597"], ["84208.10", "0"], ["84209.00", "0"], ["84210.10", "1.214490"], ["84213.60", "1.350000"], ["84216.70", "0"], ["84247.29", "0"], ["84247.30", "4.345309"], ["84255.80", "3.983200"], ["84264.30", "4.164254"], ["84272.80", "5.160054"], ["84281.30", "5.522163"], ["84289.80", "5.250581"], ["84298.30", "4.888472"], ["84306.80", "5.069527"], ["84315.30", "5.431636"], ["84323.80", "5.341109"], ["84332.30", "4.254781"], ["84340.80", "5.612690"], ["84349.30", "4.073727"], ["84357.80", "3.892672"], ["84366.30", "4.616891"], ["84374.80", "4.797945"], ["84383.30", "4.979000"], ["84391.80", "4.707418"], ["84400.30", "4.526363"], ["84408.80", "4.435836"], ["84561.11", "0.000134"]], "bids": [["84144.00", "0.695470"], ["84136.46", "0.013393"], ["84128.90", "0.198720"], ["84127.96", "0.089399"], ["84127.09", "0"], ["84126.90", "0.522948"], ["84126.13", "0.083859"], ["84126.01", "0.017800"], ["84125.58", "0.018237"], ["84125.36", "0.005940"], ["84124.98", "0"], ["84124.90", "1.376179"], ["84124.80", "0"], ["84124.73", "0"], ["84124.49", "0"], ["84124.10", "0.055602"], ["84124.05", "0.017087"], ["84123.88", "0.007125"], ["84123.25", "0"], ["84123.21", "0.007332"], ["84122.90", "3.621523"], ["84122.84", "0.008985"], ["84122.77", "0"], ["84122.69", "0.007935"], ["84122.63", "0.025160"], ["84122.61", "0"], ["84122.37", "0.017334"], ["84122.35", "0.224667"], ["84121.97", "0"], ["84121.89", "0"], ["84121.60", "0"], ["84121.36", "0"], ["84121.09", "0"], ["84121.03", "0"], ["84120.90", "9.530324"], ["84120.70", "0.051913"], ["84120.51", "0.012643"], ["84119.82", "0.018499"], ["84119.37", "0"], ["84119.18", "0"], ["84118.84", "0.268119"], ["84118.49", "0"], ["84118.01", "0.259547"], ["84117.52", "0"], ["84117.45", "0.076039"], ["84117.44", "0.021109"], ["84116.98", "0"], ["84116.57", "0"], ["84116.12", "0"], ["84113.59", "0.073145"], ["84112.66", "0.056313"], ["84112.33", "0"], ["84111.40", "0"], ["84111.34", "0"], ["84110.60", "0.300000"], ["84093.08", "0.001172"], ["84092.63", "0.003593"], ["84091.76", "0"], ["84089.76", "0"], ["84078.80", "4.888472"], ["84070.30", "4.797945"], ["84061.80", "3.983200"], ["84044.80", "5.250581"], ["84036.30", "5.431636"], ["84027.80", "4.435836"], ["84019.30", "4.979000"], ["84010.80", "5.612690"], ["84002.30", "4.073727"], ["83993.80", "5.341109"], ["83985.30", "4.345309"], ["83976.80", "4.707418"], ["83968.30", "5.160054"], ["83959.80", "3.892672"], ["83951.30", "5.522163"], ["83942.80", "4.254781"], ["83934.30", "5.069527"], ["83917.30", "4.164254"]], "checksum": 1800172339, "ts": "1742560334769"}], "ts": 1742560334771}}
{"exchange": "BYBIT", "timestamp": 1742560334.940137, "message": {"topic": "orderbook.200.BTCUSDT", "ts": 1742560334920, "type": "delta", "data": {"s": "BTCUSDT", "b": [["84167.9", "0.223173"], ["84164.9", "0"], ["84160.4", "0.119326"], ["84154.3", "0.196803"], ["84147", "0.196681"], ["84097.1", "0.237567"]], "a": [["84208.7", "0"], ["84211.6", "0.06346"], ["84220.9", "0"], ["84240.8", "0.001466"]], "u": 45263, "seq": 67552579233}, "cts": 1742560334916}}
{"exchange": "BITGET", "timestamp": 1742560335.004754, "message": {"action": "update", "arg": {"instType": "SPOT", "channel": "books", "instId": "BTCUSDT"}, "data": [{"asks": [["84172.58", "0"], ["84173.91", "0.006356"], ["84180.79", "0.603115"], ["84206.70", "0.165750"], ["84216.60", "0"], ["84247.30", "5.522163"], ["84255.80", "4.254781"], ["84264.30", "4.345309"], ["84272.80", "4.797945"], ["84281.30", "5.069527"], ["84289.80", "3.983200"], ["84298.30", "4.707418"], ["84306.80", "4.435836"], ["84315.30", "4.164254"], ["84323.80", "4.073727"], ["84332.30", "5.250581"], ["84340.80", "4.526363"], ["84349.30", "4.979000"], ["84357.80", "5.431636"], ["84366.30", "5.612690"], ["84374.80", "4.616891"], ["84383.30", "5.160054"], ["84391.80", "3.892672"], ["84400.30", "5.341109"], ["84408.80", "4.888472"], ["84562.50", "0.006969"]], "bids": [["84136.46", "0"], ["84128.90", "0.198557"], ["84126.90", "0.522517"], ["84124.90", "1.375045"], ["84122.90", "3.618540"], ["84122.24", "0.008177"], ["84120.91", "0"], ["84120.90", "9.522475"], ["84078.80", "4.073727"], ["84070.30", "5.160054"], ["84061.80", "5.250581"], ["84053.30", "4.345309"], ["84044.80", "4.526363"], ["84036.30", "4.979000"], ["84027.80", "5.341109"], ["84019.30", "4.888472"], ["84010.80", "5.522163"], ["84002.30", "4.797945"], ["83993.80", "5.612690"], ["83985.30", "5.069527"], ["83968.30", "3.892672"], ["83959.80", "3.983200"], ["83951.30", "5.431636"], ["83942.80", "4.435836"], ["83934.30", "4.164254"], ["83925.80", "4.616891"], ["83917.30", "4.254781"], ["83692.31", "0.000031"]], "checksum": -1773051284, "ts": "1742560334972"}], "ts": 1742560334974}}
{"exchange": "BYBIT", "timestamp": 1742560335.221065, "message": {"topic": "orderbook.200.BTCUSDT", "ts": 1742560335120, "type": "delta", "data": {"s": "BTCUSDT", "b": [["84167.9", "0.193239"], ["84167.8", "0.000333"], ["84162.2", "0.059399"], ["84158.4", "0.003268"], ["84152.4", "0"], ["84151.4", "0"], ["84144.4", "0"], ["84143.3", "0"], ["84096.6", "0.235392"], ["84096.5", "0.000518"], ["84096.4", "0.0001"], ["84096.3", "0.000333"]], "a": [["84173", "0.333363"], ["84178", "0.023541"], ["84180.6", "0.094135"], ["84183.4", "0"], ["84187.4", "0"], ["84191.3", "0"], ["84194.7", "0"], ["84194.8", "0.001211"], ["84195.1", "0.305152"], ["84197.2", "0"], ["84198.3", "0.000518"], ["84205.3", "0"], ["84206.3", "0"], ["84223.7", "2.561742"], ["84240.9", "0.01656"], ["84242.6", "0.003294"], ["84242.9", "0.001333"], ["84243.4", "0.00009"]], "u": 45264, "seq": 67552579367}, "cts": 1742560335116}}
{"exchange": "BITGET", "timestamp": 1742560335.22165, "message": {"action": "update", "arg": {"instType": "SPOT", "channel": "books", "instId": "BTCUSDT"}, "data": [{"asks": [["84146.18", "0.095061"], ["84146.26", "0"], ["84201.20", "0.662656"], ["84203.20", "1.743831"], ["84205.20", "4.589029"], ["84247.30", "4.707418"], ["84255.80", "5.069527"], ["84264.30", "4.888472"], ["84272.80", "4.616891"], ["84281.30", "4.797945"], ["84289.80", "5.341109"], ["84298.30", "4.345309"], ["84306.80", "5.431636"], ["84323.80", "4.526363"], ["84332.30", "4.254781"], ["84340.80", "4.073727"], ["84349.30", "5.522163"], ["84357.80", "5.250581"], ["84366.30", "3.983200"], ["84374.80", "5.160054"], ["84383.30", "4.979000"], ["84391.80", "5.612690"], ["84400.30", "3.892672"], ["84408.80", "4.435836"]], "bids": [["84144.00", "0.708863"], ["84094.00", "0.000015"], ["84092.00", "0"], ["84078.80", "4.435836"], ["84070.30", "4.707418"], ["84053.30", "5.160054"], ["84044.80", "4.073727"], ["84036.30", "4.888472"], ["84027.80", "4.797945"], ["84019.30", "3.892672"], ["84010.80", "4.979000"], ["84002.30", "5.341109"], ["83993.80", "4.254781"], ["83985.30", "4.345309"], ["83976.80", "5.431636"], ["83968.30", "5.522163"], ["83959.80", "4.616891"], ["83951.30", "3.983200"], ["83942.80", "4.164254"], ["83934.30", "5.069527"], ["83925.80", "4.526363"], ["83917.30", "5.612690"], ["83691.74", "0.000653"]], "checksum": 1048121878, "ts": "1742560335176"}], "ts": 1742560335179}}
{"exchange": "BYBIT", "timestamp": 1742560335.342598, "message": {"topic": "orderbook.200.BTCUSDT", "ts": 1742560335320, "type": "delta", "data": {"s": "BTCUSDT", "b": [["84167.9", "0.190942"], ["84164.3", "0.071323"], ["84162.5", "0"], ["84161.1", "0.121255"], ["84157.3", "0.119866"], ["84154.3", "0.124581"], ["84151.3", "0.172705"], ["84150.3", "0.187734"], ["84147", "0.020211"], ["84143.3", "0.288688"], ["84142.2", "0.272344"], ["84130.9", "0.04"], ["84130.7", "0.024825"], ["84129.9", "0.013"], ["84129.7", "0.001466"], ["84126", "0.05"], ["84125.8", "0.000333"], ["84098.1", "0"], ["84097.8", "0"], ["84097.3", "0"], ["84097.1", "0"], ["84096.6", "0"], ["84096.5", "0"], ["84096.4", "0"], ["84096.3", "0"]], "a": [["84173", "0.222325"], ["84186.3", "0.119089"], ["84190.2", "0.122716"], ["84194.8", "0"], ["84196.1", "0.169428"], ["84197.2", "0.168697"], ["84204.2", "0.288254"], ["84205.2", "0.294409"], ["84208", "0.013"], ["84208.2", "0"], ["84209.1", "0.04"], ["84209.3", "0"], ["84215.2", "2.561742"], ["84223.7", "0"], ["84240.8", "0"], ["84240.9", "0"], ["84242.6", "0"], ["84242.9", "0"], ["84243.4", "0"]], "u": 45265, "seq": 67552579421}, "cts": 1742560335308}}
{"exchange": "BITGET", "timestamp": 1742560335.416278, "message": {"action": "update", "arg": {"instType": "SPOT", "channel": "books", "instId": "BTCUSDT"}, "data": [{"asks": [["84144.01", "1.070139"], ["84167.24", "0"], ["84168.56", "0.119870"], ["84171.63", "0"], ["84172.81", "0.016429"], ["84176.74", "0"], ["84177.90", "0.119858"], ["84255.80", "4.073727"], ["84264.30", "4.164254"], ["84272.80", "5.250581"], ["84281.30", "4.345309"], ["84289.80", "3.983200"], ["84298.30", "5.160054"], ["84306.80", "3.892672"], ["84315.30", "4.979000"], ["84323.80", "5.522163"], ["84332.30", "4.526363"], ["84340.80", "4.616891"], ["84349.30", "5.431636"], ["84357.80", "4.254781"], ["84366.30", "4.435836"], ["84374.80", "5.341109"], ["84383.30", "5.069527"], ["84400.30", "4.797945"], ["84408.80", "4.888472"]], "bids": [["84127.33", "0.247350"], ["84126.00", "0.000032"], ["84124.10", "0.059615"], ["84124.00", "0.000032"], ["84123.16", "0.028837"], ["84121.99", "0"], ["84119.20", "0.001030"], ["84117.90", "0.084990"], ["84117.65", "0.222456"], ["84116.49", "0"], ["84110.68", "0.000875"], ["84109.31", "0"], ["84078.80", "4.707418"], ["84070.30", "3.983200"], ["84061.80", "5.612690"], ["84053.30", "4.616891"], ["84044.80", "5.160054"], ["84036.30", "5.431636"], ["84027.80", "4.979000"], ["84019.30", "4.345309"], ["84010.80", "4.797945"], ["84002.30", "4.073727"], ["83985.30", "4.526363"], ["83976.80", "3.892672"], ["83968.30", "5.069527"], ["83959.80", "4.888472"], ["83951.30", "4.164254"], ["83942.80", "5.341109"], ["83934.30", "4.435836"], ["83925.80", "5.522163"], ["83917.30", "5.250581"], ["83691.74", "0"]], "checksum": -1436093111, "ts": "1742560335381"}], "ts": 1742560335384}}
{"exchange": "BYBIT", "timestamp": 1742560335.542354, "message": {"topic": "orderbook.200.BTCUSDT", "ts": 1742560335520, "type": "delta", "data": {"s": "BTCUSDT", "b": [["84161.2", "0.0071"], ["84156.9", "0"], ["84132.5", "0.0016"], ["84130.9", "0"], ["84130.7", "0.064464"], ["84129.9", "0"], ["84129.7", "0.014349"], ["84128.2", "0.003564"], ["84126", "0"], ["84125.8", "0.049888"], ["84100.9", "0.235392"], ["84098.1", "0.165081"]], "a": [["84189.1", "0.177593"], ["84189.4", "0.124735"], ["84201.8", "0.238771"], ["84208", "0"], ["84208.2", "0.012973"], ["84209.1", "0"], ["84209.3", "0.04"]], "u": 45266, "seq": 67552579452}, "cts": 1742560335499}}
{"exchange": "BITGET", "timestamp": 1742560335.614536, "message": {"action": "update", "arg": {"instType": "SPOT", "channel": "books", "instId": "BTCUSDT"}, "data": [{"asks": [["84144.01", "1.220939"], ["84247.30", "4.888472"], ["84255.80", "4.254781"], ["84264.30", "5.160054"], ["84272.80", "4.526363"], ["84281.30", "4.707418"], ["84298.30", "4.164254"], ["84306.80", "4.616891"], ["84315.30", "5.612690"], ["84323.80", "4.435836"], ["84332.30", "5.069527"], ["84340.80", "5.341109"], ["84349.30", "4.345309"], ["84357.80", "5.250581"], ["84366.30", "4.979000"], ["84374.80", "4.797945"], ["84383.30", "5.522163"], ["84391.80", "4.073727"], ["84400.30", "5.431636"], ["84408.80", "3.892672"]], "bids": [["84124.90", "1.375182"], ["84122.90", "3.618901"], ["84120.90", "9.523423"], ["84078.80", "4.254781"], ["84070.30", "4.073727"], ["84061.80", "5.069527"], ["84053.30", "5.250581"], ["84044.80", "5.522163"], ["84036.30", "3.983200"], ["84027.80", "4.616891"], ["84019.30", "4.707418"], ["84010.80", "4.526363"], ["84002.30", "4.435836"], ["83993.80", "5.160054"], ["83985.30", "5.341109"], ["83976.80", "4.979000"], ["83968.30", "4.797945"], ["83959.80", "5.612690"], ["83951.30", "3.892672"], ["83942.80", "4.164254"], ["83934.30", "5.431636"], ["83925.80", "4.888472"], ["83917.30", "4.345309"]], "checksum": -1717274529, "ts": "1742560335583"}], "ts": 1742560335589}}
{"exchange": "BYBIT", "timestamp": 1742560335.744486, "message": {"topic": "orderbook.200.BTCUSDT", "ts": 1742560335719, "type": "delta", "data": {"s": "BTCUSDT", "b": [["84161.1", "0"], ["84157.3", "0"], ["84151.3", "0"], ["84150.3", "0.001333"], ["84143.3", "0"], ["84142.2", "0"], ["84097.8", "0.027758"], ["84097.3", "0.001466"], ["84097.1", "0.237567"], ["84096.5", "0.000518"], ["84096.4", "0.0001"]], "a": [["84173", "0.393325"], ["84186.3", "0"], ["84190.2", "0"], ["84195.1", "0.27292"], ["84196.1", "0"], ["84197.2", "0"], ["84204.2", "0"], ["84205.2", "0"], ["84207.9", "0.013"], ["84208", "0.012973"], ["84208.1", "0"], ["84208.2", "0"], ["84209", "0.04"], ["84209.1", "0.04"], ["84209.2", "0.001333"], ["84209.3", "0"], ["84240.8", "0.001466"], ["84240.9", "0.01656"], ["84242.6", "0.003294"], ["84242.9", "0.001333"], ["84243.4", "0.00009"]], "u": 45267, "seq": 67552579498}, "cts": 1742560335716}}
{"exchange": "BITGET", "timestamp": 1742560335.823349, "message": {"action": "update", "arg": {"instType": "SPOT", "channel": "books", "instId": "BTCUSDT"}, "data": [{"asks": [["84146.10", "0.095062"], ["84146.18", "0"], ["84173.67", "0.112842"], ["84173.99", "0"], ["84175.41", "0"], ["84215.20", "0.120000"], ["84216.60", "0.180000"], ["84247.30", "4.254781"], ["84255.80", "4.345309"], ["84264.30", "5.522163"], ["84272.80", "3.892672"], ["84281.30", "4.888472"], ["84289.80", "5.431636"], ["84298.30", "5.069527"], ["84306.80", "4.526363"], ["84315.30", "4.616891"], ["84323.80", "3.983200"], ["84332.30", "5.250581"], ["84340.80", "4.435836"], ["84349.30", "4.797945"], ["84357.80", "5.612690"], ["84366.30", "5.341109"], ["84374.80", "5.160054"], ["84383.30", "4.073727"], ["84391.80", "4.979000"], ["84400.30", "4.164254"], ["84408.80", "4.707418"]], "bids": [["84078.80", "4.164254"], ["84070.30", "5.341109"], ["84061.80", "4.616891"], ["84053.30", "5.612690"], ["84044.80", "5.069527"], ["84036.30", "4.797945"], ["84027.80", "4.526363"], ["84019.30", "5.431636"], ["84010.80", "5.522163"], ["84002.30", "4.707418"], ["83993.80", "4.345309"], ["83985.30", "4.254781"], ["83976.80", "3.983200"], ["83968.30", "4.888472"], ["83959.80", "4.979000"], ["83951.30", "5.250581"], ["83942.80", "4.435836"], ["83934.30", "3.892672"], ["83925.80", "4.073727"], ["83917.30", "5.160054"]], "checksum": 1033670640, "ts": "1742560335789"}], "ts": 1742560335793}}
{"exchange": "BYBIT", "timestamp": 1742560335.939395, "message": {"topic": "orderbook.200.BTCUSDT", "ts": 1742560335919, "type": "delta", "data": {"s": "BTCUSDT", "b": [["84172.9", "0.852615"], ["84172.8", "0.071494"], ["84096.4", "0"]], "a": [["84173", "0.222325"], ["84178.7", "0.0002"], ["84201.8", "0.099641"], ["84209", "0"], ["84209.2", "0.041333"]], "u": 45268, "seq": 67552579552}, "cts": 1742560335912}}
{"exchange": "BITGET", "timestamp": 1742560336.022113, "message": {"action": "update", "arg": {"instType": "SPOT", "channel": "books", "instId": "BTCUSDT"}, "data": [{"asks": [["84144.01", "1.219661"], ["84144.02", "0.000017"], ["84175.35", "0.175222"], ["84175.40", "0.010985"], ["84188.35", "0.010000"], ["84197.19", "0.095259"], ["84201.20", "0.662846"], ["84203.20", "1.744333"], ["84205.20", "4.590350"], ["84215.30", "0"], ["84216.70", "1.068090"], ["84247.30", "4.435836"], ["84255.80", "5.612690"], ["84264.30", "4.345309"], ["84272.80", "4.526363"], ["84281.30", "4.254781"], ["84289.80", "5.341109"], ["84306.80", "4.797945"], ["84315.30", "5.431636"], ["84323.80", "4.979000"], ["84332.30", "3.892672"], ["84340.80", "5.160054"], ["84349.30", "4.616891"], ["84357.80", "4.073727"], ["84366.30", "4.707418"], ["84374.80", "5.522163"], ["84383.30", "4.888472"], ["84391.80", "4.164254"], ["84400.30", "3.983200"], ["84408.80", "5.250581"], ["84559.47", "0"], ["84560.00", "0"], ["84561.11", "0"], ["84562.50", "0"]], "bids": [["84128.90", "0.198739"], ["84126.90", "0.522996"], ["84124.90", "1.376305"], ["84122.90", "3.621855"], ["84120.90", "9.531198"], ["84092.00", "0.000017"], ["84078.80", "5.522163"], ["84070.30", "4.707418"], ["84061.80", "5.160054"], ["84053.30", "5.250581"], ["84044.80", "4.164254"], ["84036.30", "4.979000"], ["84027.80", "4.616891"], ["84019.30", "4.345309"], ["84010.80", "5.612690"], ["84002.30", "3.983200"], ["83993.80", "4.435836"], ["83985.30", "5.069527"], ["83976.80", "4.254781"], ["83959.80", "5.341109"], ["83951.30", "4.797945"], ["83942.80", "5.431636"], ["83934.30", "4.526363"], ["83917.30", "3.892672"], ["83692.31", "0"]], "checksum": 981529375, "ts": "1742560335992"}], "ts": 1742560335996}}
{"exchange": "BYBIT", "timestamp": 1742560336.140981, "message": {"topic": "orderbook.200.BTCUSDT", "ts": 1742560336120, "type": "delta", "data": {"s": "BTCUSDT", "b": [], "a": [["84209", "0.04"], ["84209.2", "0.001333"], ["84243.4", "0"]], "u": 45269, "seq": 67552579575}, "cts": 1742560336056}}
{"exchange": "BITGET", "timestamp": 1742560336.270814, "message": {"action": "update", "arg": {"instType": "SPOT", "channel": "books", "instId": "BTCUSDT"}, "data": [{"asks": [["84144.02", "0.000032"], ["84146.10", "0"], ["84149.82", "0"], ["84205.20", "4.590201"], ["84247.30", "5.612690"], ["84255.80", "4.707418"], ["84264.30", "5.250581"], ["84272.80", "5.431636"], ["84281.30", "3.983200"], ["84289.80", "5.522163"], ["84298.30", "4.435836"], ["84306.80", "5.160054"], ["84315.30", "4.526363"], ["84323.80", "3.892672"], ["84332.30", "5.341109"], ["84340.80", "4.164254"], ["84349.30", "4.797945"], ["84357.80", "4.979000"], ["84366.30", "4.073727"], ["84374.80", "4.254781"], ["84383.30", "4.616891"], ["84391.80", "5.069527"], ["84400.30", "4.345309"], ["84408.80", "4.888472"], ["84559.47", "0.000010"], ["84560.00", "0.000255"]], "bids": [["84120.90", "9.531012"], ["84093.00", "0.000032"], ["84078.80", "4.888472"], ["84070.30", "4.345309"], ["84061.80", "3.983200"], ["84053.30", "4.254781"], ["84044.80", "5.522163"], ["84027.80", "5.612690"], ["84019.30", "3.892672"], ["84010.80", "4.435836"], ["84002.30", "4.073727"], ["83993.80", "4.707418"], ["83985.30", "5.250581"], ["83976.80", "5.069527"], ["83968.30", "5.341109"], ["83959.80", "4.797945"], ["83951.30", "5.160054"], ["83942.80", "4.164254"], ["83934.30", "5.431636"], ["83925.80", "4.526363"], ["83917.30", "4.616891"]], "checksum": -1163473769, "ts": "1742560336198"}], "ts": 1742560336203}}
{"exchange": "BYBIT", "timestamp": 1742560336.340144, "message": {"topic": "orderbook.200.BTCUSDT", "ts": 1742560336320, "type": "delta", "data": {"s": "BTCUSDT", "b": [], "a": [["84207.9", "0"], ["84208", "0"], ["84208.1", "0.012973"], ["84208.2", "0.012973"], ["84209", "0"], ["84209.1", "0"], ["84209.2", "0.041333"], ["84209.3", "0.04"], ["84215", "0.974625"], ["84215.2", "0"], ["84218", "2.561742"], ["84243.4", "0.00009"]], "u": 45270, "seq": 67552579598}, "cts": 1742560336301}}
{"exchange": "BITGET", "timestamp": 1742560336.44088, "message": {"action": "update", "arg": {"instType": "SPOT", "channel": "books", "instId": "BTCUSDT"}, "data": [{"asks": [["84145.02", "0.043515"], ["84146.04", "0.095062"], ["84148.46", "0.054775"], ["84209.70", "0.022650"], ["84211.90", "0"], ["84213.10", "0"], ["84247.30", "4.164254"], ["84264.30", "5.160054"], ["84272.80", "4.616891"], ["84281.30", "5.522163"], ["84289.80", "5.612690"], ["84298.30", "3.892672"], ["84306.80", "4.979000"], ["84315.30", "3.983200"], ["84323.80", "5.250581"], ["84332.30", "4.073727"], ["84340.80", "4.888472"], ["84349.30", "4.526363"], ["84357.80", "4.435836"], ["84366.30", "5.069527"], ["84374.80", "4.345309"], ["84383.30", "5.431636"], ["84391.80", "4.797945"], ["84400.30", "4.254781"], ["84408.80", "5.341109"], ["84560.00", "0"]], "bids": [["84143.59", "0"], ["84116.70", "0.030000"], ["84110.60", "0.144000"], ["84078.80", "4.164254"], ["84070.30", "4.888472"], ["84061.80", "4.435836"], ["84053.30", "4.616891"], ["84044.80", "4.345309"], ["84036.30", "5.431636"], ["84027.80", "4.073727"], ["84019.30", "4.526363"], ["84010.80", "4.707418"], ["84002.30", "4.979000"], ["83993.80", "3.983200"], ["83985.30", "5.069527"], ["83976.80", "4.797945"], ["83968.30", "5.250581"], ["83959.80", "4.254781"], ["83951.30", "5.522163"], ["83942.80", "3.892672"], ["83934.30", "5.341109"], ["83925.80", "5.612690"], ["83917.30", "5.160054"]], "checksum": 1465857663, "ts": "1742560336399"}], "ts": 1742560336402}}
{"exchange": "BYBIT", "timestamp": 1742560336.539956, "message": {"topic": "orderbook.200.BTCUSDT", "ts": 1742560336519, "type": "delta", "data": {"s": "BTCUSDT", "b": [["84137.9", "0.03565"], ["84135.3", "0"]], "a": [["84215", "1.4496"], ["84218", "0"], ["84220.9", "2.561742"]], "u": 45271, "seq": 67552579654}, "cts": 1742560336517}}
{"exchange": "BITGET", "timestamp": 1742560336.63319, "message": {"action": "update", "arg": {"instType": "SPOT", "channel": "books", "instId": "BTCUSDT"}, "data": [{"asks": [["84145.02", "0.083026"], ["84247.30", "4.073727"], ["84255.80", "5.160054"], ["84264.30", "4.888472"], ["84272.80", "4.345309"], ["84281.30", "5.431636"], ["84289.80", "4.707418"], ["84298.30", "5.250581"], ["84306.80", "5.069527"], ["84315.30", "4.979000"], ["84323.80", "5.612690"], ["84332.30", "5.341109"], ["84340.80", "3.892672"], ["84349.30", "3.983200"], ["84357.80", "4.616891"], ["84366.30", "5.522163"], ["84374.80", "4.797945"], ["84383.30", "4.164254"], ["84391.80", "4.435836"], ["84400.30", "4.526363"], ["84408.80", "4.254781"]], "bids": [["84143.59", "0.003010"], ["84078.80", "5.612690"], ["84070.30", "3.983200"], ["84061.80", "4.797945"], ["84053.30", "5.069527"], ["84044.80", "5.250581"], ["84036.30", "4.435836"], ["84027.80", "5.522163"], ["84019.30", "5.431636"], ["84010.80", "4.979000"], ["84002.30", "4.526363"], ["83993.80", "4.164254"], ["83985.30", "4.888472"], ["83976.80", "3.892672"], ["83968.30", "4.254781"], ["83959.80", "4.707418"], ["83951.30", "5.341109"], ["83942.80", "4.616891"], ["83934.30", "5.160054"], ["83925.80", "4.345309"], ["83917.30", "4.073727"], ["83692.38", "0"]], "checksum": 33986520, "ts": "1742560336601"}], "ts": 1742560336603}}
{"exchange": "BYBIT", "timestamp": 1742560336.792682, "message": {"topic": "orderbook.200.BTCUSDT", "ts": 1742560336720, "type": "delta", "data": {"s": "BTCUSDT", "b": [], "a": [["84207.6", "0.121194"]], "u": 45272, "seq": 67552579673}, "cts": 1742560336699}}
{"exchange": "BITGET", "timestamp": 1742560336.844294, "message": {"action": "update", "arg": {"instType": "SPOT", "channel": "books", "instId": "BTCUSDT"}, "data": [{"asks": [["84146.04", "0"], ["84175.34", "0.174497"], ["84197.19", "0"], ["84201.20", "0.662734"], ["84203.20", "1.744036"], ["84205.20", "4.589569"], ["84214.30", "0"], ["84247.30", "4.254781"], ["84255.80", "5.069527"], ["84264.30", "4.707418"], ["84272.80", "4.435836"], ["84281.30", "4.979000"], ["84289.80", "5.612690"], ["84306.80", "5.341109"], ["84315.30", "4.526363"], ["84323.80", "5.160054"], ["84332.30", "4.888472"], ["84340.80", "5.431636"], ["84349.30", "4.164254"], ["84357.80", "4.797945"], ["84366.30", "4.616891"], ["84374.80", "4.073727"], ["84383.30", "5.522163"], ["84391.80", "3.983200"], ["84400.30", "4.345309"], ["84408.80", "3.892672"], ["84560.00", "0.000255"], ["84561.11", "0.000134"]], "bids": [["84078.80", "3.892672"], ["84070.30", "4.254781"], ["84061.80", "4.526363"], ["84053.30", "5.160054"], ["84044.80", "4.073727"], ["84036.30", "3.983200"], ["84027.80", "4.164254"], ["84010.80", "5.069527"], ["84002.30", "4.345309"], ["83993.80", "4.797945"], ["83985.30", "5.522163"], ["83976.80", "4.707418"], ["83968.30", "5.341109"], ["83959.80", "4.616891"], ["83951.30", "5.612690"], ["83942.80", "4.435836"], ["83934.30", "4.979000"], ["83925.80", "5.250581"], ["83917.30", "4.888472"]], "checksum": -1428502242, "ts": "1742560336806"}], "ts": 1742560336811}}
{"exchange": "BYBIT", "timestamp": 1742560336.939821, "message": {"topic": "orderbook.200.BTCUSDT", "ts": 1742560336919, "type": "delta", "data": {"s": "BTCUSDT", "b": [["84126", "0.05"], ["84125.8", "0.000333"], ["84096.5", "0"]], "a": [], "u": 45273, "seq": 67552579727}, "cts": 1742560336899}}
{"exchange": "BITGET", "timestamp": 1742560337.045896, "message": {"action": "update", "arg": {"instType": "SPOT", "channel": "books", "instId": "BTCUSDT"}, "data": [{"asks": [["84144.02", "0"], ["84145.02", "0.043515"], ["84145.95", "0.095062"], ["84189.20", "0.001747"], ["84191.20", "0.004597"], ["84193.20", "0.012098"], ["84195.20", "0.031838"], ["84197.20", "0.083783"], ["84199.20", "0.220483"], ["84201.20", "0.580216"], ["84203.20", "1.526886"], ["84205.20", "4.018121"], ["84215.20", "0"], ["84247.30", "4.979000"], ["84255.80", "4.888472"], ["84264.30", "4.164254"], ["84272.80", "4.526363"], ["84281.30", "5.522163"], ["84289.80", "4.616891"], ["84298.30", "5.431636"], ["84306.80", "5.250581"], ["84315.30", "5.341109"], ["84323.80", "5.069527"], ["84332.30", "4.707418"], ["84340.80", "4.073727"], ["84349.30", "4.435836"], ["84357.80", "3.983200"], ["84366.30", "5.160054"], ["84374.80", "4.254781"], ["84383.30", "4.797945"], ["84391.80", "3.892672"], ["84400.30", "5.612690"], ["84408.80", "4.345309"], ["84562.50", "0.006969"]], "bids": [["84144.00", "0.708315"], ["84094.00", "0"], ["84093.00", "0.000015"], ["84078.80", "4.616891"], ["84070.30", "5.522163"], ["84061.80", "4.707418"], ["84053.30", "4.526363"], ["84044.80", "4.164254"], ["84036.30", "4.073727"], ["84027.80", "5.612690"], ["84019.30", "4.979000"], ["84010.80", "5.250581"], ["84002.30", "4.254781"], ["83993.80", "5.341109"], ["83985.30", "3.983200"], ["83976.80", "4.797945"], ["83968.30", "3.892672"], ["83959.80", "4.435836"], ["83951.30", "4.888472"], ["83942.80", "4.345309"], ["83934.30", "5.160054"], ["83925.80", "5.069527"], ["83917.30", "5.431636"], ["83692.38", "0.000007"]], "checksum": 23827171, "ts": "1742560337014"}], "ts": 1742560337018}}
{"exchange": "BYBIT", "timestamp": 1742560337.13978, "message": {"topic": "orderbook.200.BTCUSDT", "ts": 1742560337120, "type": "delta", "data": {"s": "BTCUSDT", "b": [["84172.9", "1.024415"], ["84161.7", "0.120785"], ["84151.9", "0.175838"], ["84142.8", "0.281955"], ["84126", "0"], ["84125.8", "0.049888"], ["84097.3", "0"], ["84097.1", "0"]], "a": [["84173", "0.162363"], ["84186.9", "0.11529"], ["84196.7", "0.286317"], ["84205.8", "0.314554"], ["84218", "2.561742"], ["84220.9", "0"], ["84243.4", "0"]], "u": 45274, "seq": 67552579813}, "cts": 1742560337099}}
{"exchange": "BITGET", "timestamp": 1742560337.317856, "message": {"action": "update", "arg": {"instType": "SPOT", "channel": "books", "instId": "BTCUSDT"}, "data": [{"asks": [["84145.02", "0.083026"], ["84210.10", "0.895230"], ["84247.30", "4.797945"], ["84255.80", "3.983200"], ["84264.30", "4.888472"], ["84281.30", "4.345309"], ["84298.30", "4.707418"], ["84306.80", "4.164254"], ["84315.30", "3.892672"], ["84323.80", "5.522163"], ["84332.30", "4.979000"], ["84340.80", "5.250581"], ["84357.80", "5.069527"], ["84374.80", "5.431636"], ["84383.30", "5.341109"], ["84391.80", "4.254781"], ["84400.30", "4.073727"], ["84408.80", "5.612690"]], "bids": [["84078.80", "4.888472"], ["84070.30", "3.892672"], ["84053.30", "4.435836"], ["84044.80", "5.431636"], ["84027.80", "5.522163"], ["84019.30", "5.069527"], ["84010.80", "4.979000"], ["84002.30", "4.345309"], ["83993.80", "4.164254"], ["83985.30", "5.250581"], ["83976.80", "5.612690"], ["83968.30", "5.160054"], ["83959.80", "4.254781"], ["83951.30", "4.616891"], ["83942.80", "5.341109"], ["83934.30", "4.797945"], ["83925.80", "4.526363"], ["83917.30", "3.983200"]], "checksum": -1483088979, "ts": "1742560337220"}], "ts": 1742560337222}}
{"exchange": "BYBIT", "timestamp": 1742560337.339995, "message": {"topic": "orderbook.200.BTCUSDT", "ts": 1742560337320, "type": "delta", "data": {"s": "BTCUSDT", "b": [["84172.9", "0.853415"], ["84147", "0.112201"]], "a": [["84207.9", "0.013"], ["84208", "0.012973"], ["84208.1", "0"], ["84208.2", "0"], ["84209", "0.04"], ["84209.1", "0.04"], ["84209.2", "0.001333"], ["84209.3", "0"], ["84218", "0"], ["84221.8", "0.014411"], ["84223.7", "2.561742"], ["84242.6", "0"], ["84242.9", "0"]], "u": 45275, "seq": 67552579845}, "cts": 1742560337312}}
{"exchange": "BITGET", "timestamp": 1742560337.475699, "message": {"action": "update", "arg": {"instType": "SPOT", "channel": "books", "instId": "BTCUSDT"}, "data": [{"asks": [["84145.88", "0.095062"], ["84145.95", "0"], ["84209.00", "0.966810"], ["84213.60", "0"], ["84217.80", "0.035610"], ["84217.90", "0.178110"], ["84247.30", "4.345309"], ["84255.80", "5.341109"], ["84264.30", "3.892672"], ["84272.80", "5.069527"], ["84281.30", "5.160054"], ["84289.80", "4.073727"], ["84298.30", "4.979000"], ["84306.80", "5.431636"], ["84315.30", "4.888472"], ["84323.80", "4.435836"], ["84332.30", "4.616891"], ["84349.30", "4.707418"], ["84357.80", "4.254781"], ["84366.30", "3.983200"], ["84374.80", "4.526363"], ["84383.30", "5.522163"], ["84391.80", "5.612690"], ["84400.30", "4.797945"], ["84408.80", "4.164254"], ["84561.11", "0"], ["84562.50", "0"]], "bids": [["84144.00", "0.707037"], ["84078.80", "5.431636"], ["84070.30", "4.164254"], ["84061.80", "4.526363"], ["84053.30", "5.160054"], ["84044.80", "4.345309"], ["84036.30", "5.069527"], ["84027.80", "4.888472"], ["84019.30", "5.341109"], ["84010.80", "3.983200"], ["84002.30", "4.616891"], ["83993.80", "5.522163"], ["83976.80", "4.073727"], ["83968.30", "4.979000"], ["83959.80", "4.435836"], ["83951.30", "3.892672"], ["83942.80", "5.612690"], ["83934.30", "4.254781"], ["83925.80", "4.707418"], ["83917.30", "4.797945"]], "checksum": -851496305, "ts": "1742560337437"}], "ts": 1742560337442}}
{"exchange": "BYBIT", "timestamp": 1742560337.53957, "message": {"topic": "orderbook.200.BTCUSDT", "ts": 1742560337519, "type": "delta", "data": {"s": "BTCUSDT", "b": [["84172.9", "1.024415"], ["84172.7", "0.04545"], ["84172.6", "0.071316"], ["84172.3", "0.089099"], ["84171.8", "0"], ["84171.7", "0"], ["84166", "0.071321"], ["84161.8", "0.11007"], ["84161.7", "0.089099"], ["84160.4", "0.048"], ["84154.3", "0.128289"], ["84152", "0.170758"], ["84151.9", "0"], ["84151.4", "0.177774"], ["84150.4", "0"], ["84148.8", "0"], ["84146", "0.503746"], ["84142.9", "0.309756"], ["84142.8", "0"], ["84130.8", "0"], ["84130.6", "0.039639"], ["84129.8", "0"], ["84129.6", "0.012883"], ["84125.9", "0"], ["84125.7", "0.049555"], ["84097.8", "0"]], "a": [["84173", "0.162125"], ["84178", "0"], ["84180.6", "0.001466"], ["84186.9", "0"], ["84187", "0.115107"], ["84188.1", "0.03565"], ["84189.1", "0.120161"], ["84189.4", "0.005942"], ["84195.5", "0.030066"], ["84196.7", "0"], ["84196.8", "0.665282"], ["84197.9", "0"], ["84205.8", "0.003564"], ["84205.9", "0.293234"], ["84207.9", "0"], ["84208", "0"], ["84209", "0"], ["84209.1", "0.013"], ["84209.2", "0.014306"], ["84210.2", "0.04"], ["84210.3", "0.04"], ["84211.6", "0"], ["84213.1", "0.062693"], ["84214.4", "0.06346"], ["84223.7", "0"], ["84229.3", "5.771113"], ["84242.6", "0.003294"], ["84242.9", "0.001333"], ["84243.4", "0.00009"], ["84243.6", "0.000423"]], "u": 45276, "seq": 67552579997}, "cts": 1742560337517}}
{"exchange": "BITGET", "timestamp": 1742560337.675211, "message": {"action": "update", "arg": {"instType": "SPOT", "channel": "books", "instId": "BTCUSDT"}, "data": [{"asks": [["84144.01", "0.011800"], ["84145.02", "0"], ["84145.88", "0"], ["84146.34", "0"], ["84146.35", "0"], ["84147.23", "0"], ["84148.46", "0"], ["84149.96", "0"], ["84150.12", "0"], ["84151.71", "0"], ["84151.72", "0"], ["84154.43", "0.009588"], ["84154.44", "0.015713"], ["84155.06", "0.006594"], ["84155.07", "0.006307"], ["84155.09", "0.000356"], ["84157.33", "0.009400"], ["84174.56", "0"], ["84175.35", "0"], ["84180.80", "0"], ["84185.20", "0"], ["84187.20", "0"], ["84188.35", "0"], ["84188.74", "0"], ["84189.20", "0"], ["84189.70", "0.001044"], ["84191.20", "0"], ["84191.70", "0.001047"], ["84193.20", "0.000958"], ["84193.70", "0.001038"], ["84195.20", "0"], ["84195.70", "0.001041"], ["84197.20", "0"], ["84197.70", "0.001037"], ["84198.77", "0"], ["84199.20", "0"], ["84199.70", "0.001006"], ["84201.20", "0"], ["84201.70", "0.001028"], ["84203.20", "0"], ["84203.70", "0.001032"], ["84205.20", "0"], ["84205.30", "0"], ["84205.60", "0"], ["84205.70", "0.002044"], ["84206.40", "0"], ["84206.60", "0"], ["84206.70", "0"], ["84207.70", "0.005379"], ["84208.90", "0"], ["84209.00", "0"], ["84209.30", "0"], ["84209.60", "0"], ["84209.70", "0.014155"], ["84210.10", "0.001001"], ["84210.90", "0.001027"], ["84211.30", "0"], ["84211.70", "0.001013"], ["84211.80", "0.781740"], ["84211.90", "0.001014"], ["84212.10", "0"], ["84214.10", "0"], ["84215.10", "0"], ["84215.30", "0.090000"], ["84216.00", "0"], ["84216.30", "0"], ["84216.40", "0"], ["84216.60", "0"], ["84216.70", "0"], ["84217.80", "0"], ["84217.90", "0"], ["84218.10", "0.151050"], ["84218.50", "0.120180"], ["84219.00", "2.273940"], ["84219.40", "0.240000"], ["84219.50", "0.120000"], ["84219.80", "0.420870"], ["84220.10", "0.084600"], ["84220.60", "0.009000"], ["84221.70", "0.534660"], ["84222.10", "0.084600"], ["84222.70", "5.037390"], ["84223.60", "0.120000"], ["84223.70", "0.120000"], ["84247.30", "0"], ["84251.80", "4.164032"], ["84255.80", "0"], ["84260.30", "3.892465"], ["84264.30", "0"], ["84264.53", "0"], ["84268.80", "5.069256"], ["84272.80", "0"], ["84277.30", "4.888211"], ["84281.30", "0"], ["84285.80", "4.978734"], ["84289.80", "0"], ["84291.74", "0.071045"], ["84294.30", "4.435599"], ["84298.30", "0"], ["84302.80", "4.345077"], ["84306.80", "0"], ["84311.30", "5.250301"], ["84315.30", "0"], ["84319.80", "4.797689"], ["84323.80", "0"], ["84328.30", "5.612391"], ["84332.30", "0"], ["84336.80", "4.073510"], ["84340.80", "0"], ["84345.30", "5.159779"], ["84349.30", "0"], ["84353.80", "4.707167"], ["84357.80", "0"], ["84362.30", "5.340824"], ["84366.30", "0"], ["84370.80", "5.521868"], ["84374.80", "0"], ["84379.30", "3.982987"], ["84383.30", "0"], ["84387.80", "4.526122"], ["84391.80", "0"], ["84396.30", "5.431346"], ["84400.30", "0"], ["84404.80", "4.254555"], ["84408.80", "0"], ["84413.30", "4.616644"], ["84561.11", "0.000134"], ["84562.50", "0.006969"], ["84565.22", "0.003438"], ["84566.67", "0.001061"], ["84567.79", "0.000009"], ["84568.60", "0.000018"], ["84568.81", "0.000072"], ["84568.97", "0.000024"], ["84569.23", "0.000009"], ["84570.51", "0.000170"], ["84570.99", "0.000053"], ["84571.43", "0.000124"], ["84571.75", "0.001273"], ["84571.82", "0.000046"], ["84572.75", "0.000009"]], "bids": [["84144.00", "0.953949"], ["84143.58", "0"], ["84143.40", "0.002140"], ["84142.49", "0.005592"], ["84141.84", "0.009720"], ["84141.40", "0.005631"], ["84140.90", "0"], ["84140.36", "0.008705"], ["84139.81", "0.008528"], ["84139.40", "0.014817"], ["84138.90", "0"], ["84138.21", "0.010326"], ["84137.70", "0.005166"], ["84137.62", "0.004823"], ["84137.60", "0.005578"], ["84137.55", "0.009855"], ["84137.40", "0.038994"], ["84137.36", "0"], ["84137.01", "0.025266"], ["84136.90", "0"], ["84135.40", "0.102616"], ["84134.90", "0"], ["84134.65", "0"], ["84134.63", "0"], ["84133.75", "0"], ["84133.40", "0.270042"], ["84133.15", "0"], ["84133.11", "0"], ["84132.90", "0"], ["84132.41", "0"], ["84132.36", "0"], ["84132.31", "0"], ["84132.25", "0"], ["84131.40", "0.710636"], ["84130.90", "0"], ["84130.57", "0.018474"], ["84130.35", "0"], ["84129.55", "0"], ["84129.51", "0"], ["84129.40", "1.870094"], ["84128.90", "0"], ["84127.40", "4.921300"], ["84127.04", "0.008419"], ["84126.90", "0"], ["84125.40", "12.950789"], ["84125.30", "0.701010"], ["84125.10", "0.001008"], ["84125.01", "0.005929"], ["84125.00", "0.008039"], ["84124.99", "0.010024"], ["84124.96", "0.008589"], ["84124.90", "0"], ["84124.70", "0.001003"], ["84124.60", "0.001002"], ["84124.33", "0"], ["84123.90", "0.094012"], ["84123.83", "0.007298"], ["84123.82", "0.007788"], ["84122.90", "0.178320"], ["84122.30", "0.249120"], ["84122.20", "1.079040"], ["84121.90", "0.084600"], ["84121.06", "0"], ["84120.90", "9.527640"], ["84120.80", "0.006030"], ["84119.90", "0.084600"], ["84119.51", "0"], ["84119.20", "0"], ["84118.79", "0.008085"], ["84118.30", "0"], ["84117.90", "0.084780"], ["84117.80", "0.269760"], ["84117.74", "0"], ["84117.41", "0"], ["84117.39", "0"], ["84117.34", "0"], ["84117.29", "0"], ["84117.27", "0"], ["84117.20", "0.882240"], ["84117.10", "0.125040"], ["84116.69", "0.005047"], ["84115.92", "0"], ["84115.91", "0"], ["84115.88", "0"], ["84115.84", "0"], ["84115.83", "0"], ["84114.64", "0"], ["84114.20", "0"], ["84113.80", "1.068090"], ["84113.70", "0.356430"], ["84113.00", "1.782780"], ["84111.90", "0"], ["84111.80", "0"], ["84111.50", "0"], ["84111.42", "0"], ["84111.30", "0"], ["84111.10", "0"], ["84111.00", "0.000032"], ["84110.60", "0"], ["84108.71", "0"], ["84101.07", "0.007428"], ["84098.06", "0.008565"], ["84096.38", "0.007241"], ["84096.21", "0.007644"], ["84095.89", "0"], ["84090.07", "0"], ["84088.78", "0"], ["84088.68", "0"], ["84088.61", "0"], ["84083.30", "5.521868"], ["84078.80", "0"], ["84074.80", "5.340824"], ["84070.30", "0"], ["84066.30", "4.073510"], ["84061.80", "0"], ["84057.80", "4.254555"], ["84053.30", "0"], ["84049.30", "4.978734"], ["84044.80", "0"], ["84040.80", "5.612391"], ["84036.30", "0"], ["84032.30", "4.797689"], ["84027.80", "0"], ["84023.80", "3.982987"], ["84019.30", "0"], ["84015.30", "4.164032"], ["84010.80", "0"], ["84006.80", "4.526122"], ["84002.30", "0"], ["83998.30", "4.345077"], ["83993.80", "0"], ["83989.80", "4.435599"], ["83985.30", "0"], ["83981.30", "4.707167"], ["83976.80", "0"], ["83972.80", "4.616644"], ["83968.30", "0"], ["83964.30", "5.159779"], ["83959.80", "0"], ["83955.80", "3.892465"], ["83951.30", "0"], ["83947.30", "4.888211"], ["83942.80", "0"], ["83938.80", "5.069256"], ["83934.30", "0"], ["83930.30", "5.250301"], ["83925.80", "0"], ["83921.80", "5.431346"], ["83917.30", "0"], ["83692.31", "0.000031"], ["83691.74", "0.000653"], ["83690.84", "0.000162"], ["83690.48", "0.000248"], ["83690.00", "0.000013"], ["83689.78", "0.001684"], ["83689.50", "0.000113"], ["83688.89", "0.000009"], ["83688.07", "0.000072"], ["83687.50", "0.006969"]], "checksum": -1493390530, "ts": "1742560337638"}], "ts": 1742560337641}}
{"exchange": "BYBIT", "timestamp": 1742560337.740503, "message": {"topic": "orderbook.200.BTCUSDT", "ts": 1742560337719, "type": "delta", "data": {"s": "BTCUSDT", "b": [["84183.9", "0.778178"], ["84183.5", "0.304377"], ["84183.4", "0.190942"], ["84182.6", "0.190942"], ["84181.3", "0.034794"], ["84180.1", "0.04231"], ["84180", "0.089159"], ["84179.3", "0.001999"], ["84178.6", "0.049876"], ["84176.8", "0.049876"], ["84176.3", "0.050209"], ["84176.2", "0.000216"], ["84175.9", "0.072779"], ["84175.5", "0.012003"], ["84175.2", "0.003268"], ["84175.1", "0.000518"], ["84175", "0.050276"], ["84174.2", "0.01"], ["84173.1", "0.229364"], ["84173", "0.0006"], ["84172.9", "0.405537"], ["84172.8", "0.071316"], ["84172.7", "0"], ["84172.6", "0"], ["84172.1", "0.000333"], ["84171.3", "0.002799"], ["84171.2", "0.00009"], ["84171", "0.003268"], ["84170.5", "0.000518"], ["84168", "0"], ["84167.9", "0.024942"], ["84166", "0"], ["84164.5", "0"], ["84164.3", "0"], ["84161.8", "0"], ["84161.5", "0.059879"], ["84161.2", "0.010675"], ["84160.5", "0.052"], ["84159", "0.096332"], ["84157.4", "0.001466"], ["84155.5", "0.540618"], ["84154.3", "0.192013"], ["84152.3", "0.005566"], ["84152.1", "0.118793"], ["84152", "0.000518"], ["84151.4", "0"], ["84146.1", "0.120126"], ["84142.9", "0"], ["84142.5", "0.016468"], ["84139.3", "0"], ["84138.6", "0.017714"], ["84138.5", "0"], ["84137.1", "0.003564"], ["84135.4", "0.022801"], ["84135.3", "0.135473"], ["84134.4", "0.01402"], ["84133.6", "0.143532"], ["84130.7", "0.039639"], ["84127.2", "0"], ["84126.9", "0"], ["84118.7", "0"], ["84109.7", "0.235392"], ["84104.6", "0"], ["84104", "0"], ["84103.9", "0"], ["84103.7", "0"], ["84102.6", "0"], ["84102.5", "0"], ["84102.4", "0"], ["84102.3", "0"], ["84101.9", "0"], ["84101.3", "0"], ["84101.1", "0"], ["84101", "0"], ["84100.9", "0"], ["84100.5", "0"], ["84100.4", "0"], ["84100", "0"], ["84099.8", "0"], ["84099.5", "0"], ["84099.3", "0"], ["84099.1", "0"], ["84098.1", "0"]], "a": [["84173", "0"], ["84175.1", "0"], ["84175.2", "0"], ["84175.5", "0"], ["84175.9", "0"], ["84176.3", "0"], ["84176.4", "0"], ["84176.9", "0"], ["84178.1", "0"], ["84178.7", "0"], ["84179.4", "0"], ["84179.8", "0"], ["84180", "0"], ["84180.5", "0"], ["84180.6", "0"], ["84180.7", "0"], ["84181.4", "0"], ["84183.5", "0"], ["84183.6", "0"], ["84184.2", "0"], ["84184.5", "0"], ["84184.6", "0"], ["84184.8", "0"], ["84185.9", "0"], ["84186", "0"], ["84186.1", "0"], ["84187", "0"], ["84187.5", "0"], ["84188.1", "0"], ["84188.3", "0"], ["84188.9", "0.000333"], ["84189.1", "0.033709"], ["84189.2", "0"], ["84189.5", "0.071302"], ["84189.6", "0"], ["84190", "0.0002"], ["84190.6", "0"], ["84191.2", "0"], ["84191.8", "0"], ["84191.9", "0.0813"], ["84192.4", "0.044013"], ["84192.5", "0"], ["84193.7", "0.006278"], ["84194.1", "0"], ["84194.3", "0.086401"], ["84195.1", "0"], ["84195.5", "0"], ["84196.8", "0"], ["84197.6", "0.016407"], ["84199.7", "0.003833"], ["84200.4", "0.045152"], ["84201.4", "0.00009"], ["84201.7", "0"], ["84201.8", "0"], ["84202.3", "0.024632"], ["84202.4", "0.05933"], ["84204.1", "0"], ["84204.4", "0"], ["84204.7", "0.012822"], ["84205.6", "0.005571"], ["84205.8", "0"], ["84205.9", "0"], ["84209.1", "0.482181"], ["84209.2", "0.001333"], ["84210", "0.311476"], ["84210.2", "0"], ["84210.3", "0"], ["84212", "0"], ["84212.3", "0"], ["84212.5", "0"], ["84214.4", "0"], ["84214.9", "0.551329"], ["84215", "0"], ["84216.1", "0"], ["84217.9", "0"], ["84218", "0.012973"], ["84218.1", "0.012973"], ["84218.5", "0.011878"], ["84219", "0.063757"], ["84219.1", "0.04"], ["84219.7", "0.023322"], ["84220.5", "0"], ["84222.9", "0.063455"], ["84229.3", "3.209371"], ["84229.8", "0"], ["84231.6", "0"], ["84243.5", "2.561742"], ["84244.5", "0.002721"], ["84244.6", "0.000518"], ["84245.4", "0.001466"], ["84245.6", "0.027477"], ["84246.8", "0.003292"], ["84247.1", "0.001333"], ["84247.8", "0.000333"], ["84249", "0.237586"], ["84249.3", "0.000916"], ["84249.4", "0.059367"], ["84249.5", "0.032054"], ["84249.6", "0.059399"], ["84250", "0.001466"], ["84250.8", "3.664679"], ["84251", "0.003292"], ["84251.3", "0.010333"], ["84251.8", "0.00009"], ["84252.1", "0.089432"], ["84252.4", "0.005942"], ["84252.9", "0.059367"], ["84253.2", "0.05"], ["84253.9", "0.00052"], ["84254", "0.000146"], ["84254.7", "0.051466"], ["84255.2", "0.003293"], ["84255.5", "0.05"], ["84255.6", "0.001333"], ["84256", "0.05"], ["84256.3", "0.000333"], ["84257.1", "0.003564"], ["84257.5", "0.059367"], ["84258", "0.237586"], ["84258.5", "0.00052"], ["84258.7", "0.000358"], ["84259.3", "0.001466"], ["84259.4", "0.003293"], ["84259.8", "0.001333"], ["84260", "0.059399"], ["84260.2", "0.00009"], ["84260.5", "0.000333"], ["84261.2", "0.101605"], ["84262.1", "0.003"]], "u": 45277, "seq": 67552581905}, "cts": 1742560337717}}
{"exchange": "BITGET", "timestamp": 1742560337.898544, "message": {"action": "update", "arg": {"instType": "SPOT", "channel": "books", "instId": "BTCUSDT"}, "data": [{"asks": [["84144.01", "0.011900"], ["84144.02", "0.000100"], ["84144.03", "0.000100"], ["84144.04", "0.000100"], ["84152.71", "0.095054"], ["84154.66", "0.054775"], ["84155.08", "0"], ["84157.05", "0"], ["84160.85", "0.209200"], ["84168.35", "0"], ["84168.56", "0"], ["84169.88", "0"], ["84170.51", "0"], ["84170.61", "0"], ["84170.97", "0"], ["84171.90", "0"], ["84172.35", "0"], ["84172.52", "0"], ["84172.81", "0"], ["84172.86", "0"], ["84173.35", "0"], ["84173.50", "0"], ["84173.68", "0"], ["84173.91", "0"], ["84173.97", "0"], ["84174.03", "0"], ["84175.11", "0.035952"], ["84175.20", "0"], ["84175.34", "0"], ["84175.40", "0"], ["84175.68", "0.119870"], ["84176.20", "0"], ["84176.88", "0.035961"], ["84177.07", "0.006356"], ["84177.33", "0.006356"], ["84177.73", "0.006356"], ["84177.90", "0"], ["84178.54", "0"], ["84178.87", "0.010984"], ["84179.31", "0.006356"], ["84179.48", "0.006356"], ["84179.59", "0.016429"], ["84179.86", "0.006356"], ["84180.06", "0.013393"], ["84180.22", "0.006356"], ["84180.30", "0.006356"], ["84180.43", "0.016429"], ["84180.64", "0.119883"], ["84180.79", "0"], ["84180.91", "0.006356"], ["84180.99", "0.006356"], ["84181.55", "0.177409"], ["84182.18", "0.006357"], ["84182.21", "0.010985"], ["84183.18", "0.009990"], ["84184.07", "0.119850"], ["84185.17", "0.119858"], ["84185.50", "0.015895"], ["84185.69", "0.009989"], ["84189.70", "0"], ["84191.70", "0"], ["84192.20", "0.001017"], ["84193.70", "0"], ["84194.20", "0.001021"], ["84195.70", "0"], ["84196.20", "0.001003"], ["84197.70", "0"], ["84198.20", "0.001013"], ["84199.15", "0.712596"], ["84199.70", "0"], ["84200.20", "0.001029"], ["84201.70", "0"], ["84202.20", "0.001023"], ["84203.70", "0"], ["84204.20", "0.001033"], ["84205.70", "0"], ["84206.20", "0.001008"], ["84207.70", "0"], ["84208.20", "0.001046"], ["84209.70", "0"], ["84210.10", "0"], ["84210.20", "0.001023"], ["84210.90", "0"], ["84211.70", "0"], ["84211.80", "0"], ["84211.90", "0"], ["84212.00", "0"], ["84212.20", "0.001110"], ["84212.30", "0.001025"], ["84212.70", "0"], ["84215.30", "0"], ["84215.50", "0.001049"], ["84215.60", "0.001004"], ["84215.90", "0.069720"], ["84216.00", "0.001011"], ["84216.10", "0.255540"], ["84218.10", "0.084600"], ["84218.20", "0.007170"], ["84218.50", "0"], ["84219.00", "0.558600"], ["84219.40", "0"], ["84219.50", "0.893820"], ["84219.80", "0"], ["84220.40", "0.131160"], ["84220.90", "0.090000"], ["84221.70", "0"], ["84222.00", "0.066450"], ["84222.70", "0.321180"], ["84223.60", "0"], ["84223.70", "0"], ["84223.90", "0.120000"], ["84224.00", "0.177990"], ["84224.50", "2.473140"], ["84225.00", "0.015120"], ["84225.30", "0.180000"], ["84225.90", "0.089130"], ["84226.20", "0.240000"], ["84226.40", "0.035640"], ["84226.50", "0.120000"], ["84226.80", "0.012510"], ["84227.10", "0.968430"], ["84251.80", "0"], ["84254.30", "4.344947"], ["84260.30", "0"], ["84262.80", "5.069105"], ["84268.80", "0"], ["84271.30", "5.521703"], ["84277.30", "0"], ["84279.80", "5.159624"], ["84285.80", "0"], ["84288.30", "4.073388"], ["84294.30", "0"], ["84296.80", "3.892348"], ["84302.80", "0"], ["84305.30", "4.978585"], ["84311.30", "0"], ["84313.80", "4.797545"], ["84319.80", "0"], ["84322.30", "3.982868"], ["84328.30", "0"], ["84330.80", "4.525986"], ["84336.80", "0"], ["84339.30", "4.707026"], ["84345.30", "0"], ["84347.80", "5.612223"], ["84353.80", "0"], ["84356.30", "4.435467"], ["84362.30", "0"], ["84364.80", "5.431183"], ["84370.80", "0"], ["84373.30", "4.616506"], ["84379.30", "0"], ["84381.80", "4.888065"], ["84387.80", "0"], ["84390.30", "4.254427"], ["84396.30", "0"], ["84398.80", "5.250144"], ["84404.80", "0"], ["84407.30", "4.163907"], ["84413.30", "0"], ["84415.80", "5.340664"], ["84568.60", "0"], ["84568.81", "0"], ["84568.97", "0"], ["84569.23", "0"], ["84570.51", "0"], ["84570.99", "0"], ["84571.43", "0"], ["84571.75", "0"], ["84571.82", "0"], ["84572.75", "0"]], "bids": [["84144.00", "1.046257"], ["84143.90", "0.004232"], ["84143.59", "0.006558"], ["84143.40", "0"], ["84141.90", "0.011136"], ["84141.40", "0"], ["84140.37", "0.008889"], ["84139.90", "0.029307"], ["84139.79", "0.005114"], ["84139.40", "0"], ["84139.01", "0"], ["84137.90", "0.077124"], ["84137.40", "0"], ["84137.01", "0"], ["84135.90", "0.202956"], ["84135.40", "0"], ["84134.71", "0.089399"], ["84134.44", "0.247350"], ["84133.90", "0.534096"], ["84133.40", "0"], ["84133.12", "0.083859"], ["84132.47", "0.017800"], ["84132.39", "0.018237"], ["84132.12", "0.005940"], ["84131.90", "1.405516"], ["84131.40", "0"], ["84131.07", "0.055602"], ["84130.84", "0.007125"], ["84130.50", "0.017087"], ["84130.21", "0.007332"], ["84129.94", "0.028837"], ["84129.90", "3.698727"], ["84129.64", "0.007935"], ["84129.55", "0.008985"], ["84129.51", "0.008261"], ["84129.40", "0"], ["84129.32", "0.017334"], ["84129.30", "0.224667"], ["84129.24", "0.008177"], ["84129.10", "0.025160"], ["84127.96", "0"], ["84127.90", "9.733492"], ["84127.75", "0.008054"], ["84127.70", "5.331960"], ["84127.60", "0.700020"], ["84127.51", "0.051913"], ["84127.50", "7.313130"], ["84127.48", "0.012643"], ["84127.40", "0"], ["84127.33", "0"], ["84127.05", "0.006467"], ["84126.79", "0.018499"], ["84126.60", "0.089100"], ["84126.53", "0"], ["84126.50", "0.178200"], ["84126.13", "0"], ["84126.06", "0.007750"], ["84126.01", "0"], ["84125.90", "0.084600"], ["84125.84", "0.268119"], ["84125.58", "0"], ["84125.40", "1.503300"], ["84125.36", "0"], ["84125.30", "0.686310"], ["84125.10", "0"], ["84124.95", "0.009177"], ["84124.91", "0.222456"], ["84124.70", "0.420000"], ["84124.60", "0"], ["84124.40", "0.076039"], ["84124.30", "0.153580"], ["84124.26", "0.021109"], ["84124.20", "0.073080"], ["84124.10", "0.004013"], ["84124.05", "0"], ["84123.90", "0.084600"], ["84123.88", "0"], ["84123.86", "0.006899"], ["84123.40", "0.125040"], ["84123.21", "0"], ["84123.16", "0"], ["84122.90", "0"], ["84122.84", "0"], ["84122.69", "0"], ["84122.63", "0"], ["84122.37", "0"], ["84122.35", "0"], ["84122.24", "0"], ["84122.10", "0.192000"], ["84121.82", "0"], ["84121.60", "0.007350"], ["84120.90", "2.282220"], ["84120.70", "0"], ["84120.51", "0"], ["84120.10", "0.045000"], ["84119.82", "0"], ["84119.33", "0.008258"], ["84119.10", "0.045000"], ["84118.84", "0"], ["84118.10", "0.480000"], ["84117.90", "0.204780"], ["84117.80", "0"], ["84117.65", "0"], ["84117.45", "0"], ["84117.44", "0"], ["84117.20", "2.316660"], ["84117.00", "0.120000"], ["84116.70", "1.782570"], ["84115.90", "0"], ["84115.60", "0"], ["84115.50", "0"], ["84115.40", "0"], ["84114.40", "0"], ["84114.20", "0.000396"], ["84113.80", "0"], ["84113.70", "0"], ["84113.40", "0"], ["84113.00", "0.000032"], ["84112.90", "0"], ["84112.60", "0"], ["84112.50", "0"], ["84112.30", "0"], ["84108.84", "0"], ["84101.10", "0"], ["84098.45", "0.007330"], ["84094.90", "0.208446"], ["84094.00", "0.000017"], ["84092.00", "0.000032"], ["84086.10", "0"], ["84085.80", "4.344947"], ["84084.70", "0.000948"], ["84083.30", "0"], ["84077.30", "5.250144"], ["84074.80", "0"], ["84071.60", "0"], ["84068.80", "4.254427"], ["84066.30", "0"], ["84060.30", "5.521703"], ["84057.80", "0"], ["84051.80", "5.612223"], ["84049.30", "0"], ["84043.30", "4.073388"], ["84040.80", "0"], ["84034.80", "3.982868"], ["84032.30", "0"], ["84026.30", "4.525986"], ["84023.80", "0"], ["84017.80", "4.435467"], ["84015.30", "0"], ["84009.30", "5.069105"], ["84006.80", "0"], ["84000.80", "5.159624"], ["83998.30", "0"], ["83992.30", "4.163907"], ["83989.80", "0"], ["83983.80", "4.797545"], ["83981.30", "0"], ["83975.30", "5.340664"], ["83972.80", "0"], ["83966.80", "4.978585"], ["83964.30", "0"], ["83958.30", "5.431183"], ["83955.80", "0"], ["83949.80", "4.707026"], ["83947.30", "0"], ["83941.30", "3.892348"], ["83938.80", "0"], ["83932.80", "4.616506"], ["83930.30", "0"], ["83924.30", "4.888065"], ["83921.80", "0"], ["83689.78", "0"], ["83689.50", "0"], ["83688.89", "0"], ["83688.07", "0"], ["83687.50", "0"]], "checksum": -2030331918, "ts": "1742560337865"}], "ts": 1742560337870}}
{"exchange": "BYBIT", "timestamp": 1742560337.940127, "message": {"topic": "orderbook.200.BTCUSDT", "ts": 1742560337919, "type": "delta", "data": {"s": "BTCUSDT", "b": [["84187.7", "0.461234"], ["84185.3", "0.116022"], ["84185.1", "0.205794"], ["84184.7", "0.186611"], ["84184.6", "0.171"], ["84183.9", "0.019942"], ["84183.6", "0.071306"], ["84183.5", "0"], ["84183.4", "0.019942"], ["84182.6", "0.262436"], ["84181.3", "0.019942"], ["84180.6", "0.001466"], ["84180.5", "0.000333"], ["84180.1", "0.017117"], ["84180", "0.00006"], ["84179.8", "0.001851"], ["84179.4", "0.003269"], ["84177", "0.119263"], ["84175.7", "0.02134"], ["84175.1", "0.262684"], ["84174.2", "0.033834"], ["84173.1", "0.059399"], ["84172.9", "0.399396"], ["84171.3", "0.021669"], ["84168", "0.047496"], ["84167.1", "0.049333"], ["84167", "0.04"], ["84165.7", "0.064"], ["84165.4", "0.044"], ["84163.8", "0"], ["84162", "0.049466"], ["84160.9", "0.030107"], ["84160.6", "0.009931"], ["84160.4", "0.056"], ["84159.7", "0"], ["84159", "0.238609"], ["84158.1", "0.306899"], ["84155.3", "0"], ["84154.3", "0.124581"], ["84153.9", "0"], ["84147", "0.202824"], ["84145.7", "0.006823"], ["84142", "0.267872"], ["84140.4", "0.128357"], ["84136.9", "0"], ["84128.2", "0"], ["84127.3", "0.031379"], ["84116.7", "0.000668"], ["84110.4", "0"], ["84109.7", "0"], ["84109.6", "0"], ["84109.4", "0"], ["84108.9", "0"], ["84108.2", "0"], ["84107.9", "0"], ["84107.8", "0"], ["84107.1", "0"], ["84106.9", "0"], ["84106.5", "0"], ["84105.7", "0"], ["84104.7", "0"]], "a": [["84184", "0"], ["84184.4", "0"], ["84184.7", "0"], ["84185.2", "0"], ["84187.8", "0.080788"], ["84189.1", "0"], ["84189.5", "0"], ["84191.8", "0.049805"], ["84192.6", "0.03201"], ["84193.1", "0.005333"], ["84193.7", "0.004211"], ["84194.4", "0"], ["84195", "0.071297"], ["84195.6", "0.04"], ["84195.8", "0.04"], ["84196.9", "0.04"], ["84197.3", "0.040333"], ["84197.6", "0.04"], ["84199.6", "0.028685"], ["84200.4", "0"], ["84200.9", "0.04"], ["84201.1", "0.044695"], ["84202.2", "0.122214"], ["84202.6", "0.04"], ["84202.8", "0.002067"], ["84207.6", "0.222546"], ["84210", "0.011885"], ["84212", "0.168397"], ["84213.5", "0.04424"], ["84213.6", "0.1657"], ["84214.9", "0"], ["84218", "0"], ["84218.1", "0"], ["84218.5", "0"], ["84218.9", "0.004673"], ["84219", "0.023757"], ["84219.1", "0"], ["84219.5", "0.013"], ["84219.6", "0.012973"], ["84220.1", "0.063451"], ["84220.6", "0.04"], ["84220.7", "0.04"], ["84221.1", "0.288451"], ["84222.9", "0"], ["84223.4", "0"], ["84227.9", "0"], ["84233.3", "0.01395"], ["84237.8", "2.561331"], ["84243.5", "0"], ["84246.1", "0.171"], ["84248.4", "0.005985"], ["84254.6", "0.171"], ["84258.7", "0"], ["84259.3", "0"], ["84259.4", "0"], ["84259.8", "0"], ["84260", "0"], ["84260.2", "0"], ["84260.5", "0"], ["84261.2", "0"], ["84262.1", "0"]], "u": 45278, "seq": 67552582514}, "cts": 1742560337916}}
{"exchange": "BITGET", "timestamp": 1742560338.106574, "message": {"action": "update", "arg": {"instType": "SPOT", "channel": "books", "instId": "BTCUSDT"}, "data": [{"asks": [["84152.71", "0"], ["84154.43", "0"], ["84154.44", "0"], ["84155.06", "0"], ["84155.07", "0"], ["84155.09", "0"], ["84160.84", "0.062760"], ["84162.11", "1.591631"], ["84173.67", "0"], ["84178.59", "0"], ["84182.59", "0"], ["84183.35", "0"], ["84191.06", "3.708563"], ["84192.20", "0"], ["84194.20", "0"], ["84196.00", "0.001028"], ["84196.20", "0"], ["84198.00", "0.001040"], ["84198.20", "0"], ["84200.00", "0.001039"], ["84200.20", "0"], ["84202.00", "0.001033"], ["84202.20", "0"], ["84204.00", "0.001048"], ["84204.20", "0"], ["84206.00", "0.001015"], ["84206.20", "0"], ["84208.00", "0.001023"], ["84208.20", "0"], ["84210.20", "0"], ["84212.00", "0.001011"], ["84212.20", "0"], ["84212.30", "0"], ["84214.00", "0.001024"], ["84215.50", "0"], ["84215.60", "0"], ["84215.90", "0"], ["84216.50", "0.001024"], ["84218.10", "0.085080"], ["84218.50", "0.001017"], ["84218.90", "0.001026"], ["84219.00", "0.408690"], ["84219.60", "0.069450"], ["84219.70", "0.440430"], ["84220.40", "0"], ["84222.70", "1.002060"], ["84225.00", "0"], ["84225.40", "0.015180"], ["84227.20", "2.131890"], ["84227.30", "2.670270"], ["84227.80", "0.026760"], ["84254.30", "0"], ["84258.10", "4.797325"], ["84262.80", "0"], ["84266.60", "5.340418"], ["84271.30", "0"], ["84275.10", "4.978356"], ["84279.80", "0"], ["84283.60", "3.892169"], ["84288.30", "0"], ["84292.10", "4.706809"], ["84296.80", "0"], ["84300.60", "5.521449"], ["84305.30", "0"], ["84309.10", "4.163716"], ["84313.80", "0"], ["84317.60", "5.430934"], ["84322.30", "0"], ["84326.10", "4.073200"], ["84330.80", "0"], ["84334.60", "4.344747"], ["84339.30", "0"], ["84343.10", "5.068871"], ["84347.80", "0"], ["84351.60", "4.887840"], ["84356.30", "0"], ["84360.10", "4.616294"], ["84364.80", "0"], ["84368.60", "5.159387"], ["84373.30", "0"], ["84377.10", "4.525778"], ["84381.80", "0"], ["84385.60", "4.435263"], ["84390.30", "0"], ["84394.10", "3.982685"], ["84398.80", "0"], ["84402.60", "4.254232"], ["84407.30", "0"], ["84411.10", "5.611965"], ["84415.80", "0"], ["84419.60", "5.249903"], ["84568.60", "0.000018"], ["84568.81", "0.000072"], ["84568.97", "0.000024"], ["84569.23", "0.000009"], ["84570.51", "0.000170"], ["84570.99", "0.000053"]], "bids": [["84144.00", "1.093793"], ["84143.91", "0.014224"], ["84143.90", "0"], ["84143.80", "0.019004"], ["84142.49", "0"], ["84141.90", "0"], ["84141.84", "0"], ["84141.80", "0.050012"], ["84139.91", "0.049778"], ["84139.90", "0"], ["84139.81", "0"], ["84139.80", "0.131610"], ["84138.21", "0"], ["84138.03", "0"], ["84137.90", "0"], ["84137.80", "0.346342"], ["84137.70", "0"], ["84137.62", "0"], ["84137.60", "0"], ["84137.55", "0"], ["84135.90", "0"], ["84135.80", "0.911427"], ["84133.90", "0"], ["84133.80", "2.398490"], ["84131.90", "0"], ["84131.80", "6.311817"], ["84131.60", "19.533180"], ["84131.40", "0.001045"], ["84131.30", "0.001003"], ["84131.20", "0.656190"], ["84130.65", "2.994996"], ["84129.90", "0.084810"], ["84128.60", "0.001018"], ["84127.90", "3.779880"], ["84127.70", "0"], ["84127.60", "0.699600"], ["84127.50", "1.973400"], ["84125.40", "0.836940"], ["84125.30", "0"], ["84125.01", "0"], ["84125.00", "0.000032"], ["84124.99", "0"], ["84124.96", "0"], ["84124.95", "0"], ["84124.20", "0"], ["84123.86", "0"], ["84123.83", "0"], ["84123.82", "0"], ["84122.91", "0.756907"], ["84122.80", "0.180000"], ["84122.30", "0.249990"], ["84122.20", "0"], ["84122.00", "0.156000"], ["84121.90", "0.360600"], ["84120.90", "2.230740"], ["84119.60", "0.926940"], ["84118.01", "0"], ["84117.80", "0.120000"], ["84117.60", "0.120000"], ["84117.10", "0"], ["84117.00", "0.000032"], ["84116.70", "0"], ["84116.69", "0"], ["84113.59", "0"], ["84112.66", "0"], ["84101.07", "0"], ["84098.06", "0"], ["84096.38", "0"], ["84096.21", "0"], ["84089.70", "4.344747"], ["84085.80", "0"], ["84081.20", "4.706809"], ["84077.30", "0"], ["84072.70", "5.068871"], ["84068.80", "0"], ["84064.20", "4.978356"], ["84060.30", "0"], ["84055.70", "4.073200"], ["84051.80", "0"], ["84047.20", "5.521449"], ["84043.30", "0"], ["84038.70", "5.430934"], ["84034.80", "0"], ["84030.20", "5.340418"], ["84026.30", "0"], ["84021.70", "3.982685"], ["84017.80", "0"], ["84013.20", "4.435263"], ["84009.30", "0"], ["84004.70", "4.797325"], ["84000.80", "0"], ["83996.20", "4.254232"], ["83992.30", "0"], ["83987.70", "4.616294"], ["83983.80", "0"], ["83979.20", "4.887840"], ["83975.30", "0"], ["83970.70", "5.611965"], ["83966.80", "0"], ["83962.20", "4.525778"], ["83958.30", "0"], ["83953.70", "3.892169"], ["83949.80", "0"], ["83945.20", "5.159387"], ["83941.30", "0"], ["83936.70", "4.163716"], ["83932.80", "0"], ["83928.20", "5.249903"], ["83924.30", "0"], ["83689.78", "0.001684"], ["83689.50", "0.000113"], ["83688.89", "0.000009"], ["83688.07", "0.000072"], ["83687.50", "0.006969"], ["83687.00", "0.000008"], ["83686.11", "0.000096"], ["83684.21", "0.000102"], ["83683.67", "0.000184"], ["83681.82", "0.000175"], ["83680.67", "0.041940"], ["83680.00", "0.000495"], ["83679.44", "0.000361"], ["83678.70", "0.000192"], ["83678.41", "0.000010"], ["83678.08", "0.000145"], ["83677.42", "0.000008"], ["83677.37", "0.000008"]], "checksum": -527759816, "ts": "1742560338066"}], "ts": 1742560338068}}
{"exchange": "BYBIT", "timestamp": 1742560338.141748, "message": {"topic": "orderbook.200.BTCUSDT", "ts": 1742560338120, "type": "delta", "data": {"s": "BTCUSDT", "b": [["84187.7", "0.620489"], ["84185.3", "0"], ["84185.1", "0.190942"], ["84184.7", "0.097118"], ["84184.6", "0"], ["84183.6", "0"], ["84180.1", "0"], ["84178.7", "0.060633"], ["84178.6", "0.053812"], ["84177.1", "0.110891"], ["84177", "0"], ["84176.8", "0.073709"], ["84175.1", "0.193754"], ["84175", "0.049876"], ["84174.2", "0.01"], ["84168", "0.129738"], ["84167.7", "0.052"], ["84166.6", "0.172391"], ["84163.7", "0.048"], ["84162.5", "0.06"], ["84161.5", "0"], ["84160.9", "0"], ["84159.6", "0.302866"], ["84158.9", "0"], ["84158.7", "0.001333"], ["84158.1", "0"], ["84157", "0.052"], ["84156.6", "0.024615"], ["84155.4", "0"], ["84153.6", "0"], ["84152.4", "0.023756"], ["84136.6", "0.04956"], ["84136.5", "0.049918"], ["84135.3", "0.135491"], ["84125.8", "0.000333"], ["84125.7", "0"], ["84119.3", "19.525413"], ["84110.4", "0.000518"], ["84110.3", "0.027538"]], "a": [["84187.8", "0.084619"], ["84194.3", "0.122611"], ["84197.3", "0.159126"], ["84197.7", "0.003704"], ["84197.8", "0.001277"], ["84198.7", "0.023679"], ["84199.2", "0.0829"], ["84199.3", "0.04"], ["84199.6", "0"], ["84200.6", "0.04"], ["84201.1", "0"], ["84201.5", "0.045563"], ["84201.6", "0.118834"], ["84202.1", "0.037252"], ["84202.2", "0"], ["84202.3", "0"], ["84212", "0"], ["84212.1", "0.180902"], ["84219.1", "0.275101"], ["84219.5", "0"], ["84219.6", "0"], ["84219.7", "0.036295"], ["84219.8", "0.012973"], ["84220.6", "0"], ["84220.7", "0"], ["84220.8", "0.045939"], ["84220.9", "0.04"], ["84221.1", "0"], ["84227.3", "1.0533"], ["84229.2", "0"], ["84253.2", "0"], ["84254.7", "0.001466"], ["84258.7", "0.000358"]], "u": 45279, "seq": 67552582715}, "cts": 1742560338116}}
{"exchange": "BITGET", "timestamp": 1742560338.365669, "message": {"action": "update", "arg": {"instType": "SPOT", "channel": "books", "instId": "BTCUSDT"}, "data": [{"asks": [["84160.80", "0.017059"], ["84160.81", "0.008242"], ["84160.84", "0.532404"], ["84161.36", "0.006594"], ["84161.44", "0.006307"], ["84181.55", "0"], ["84186.99", "0.119867"], ["84190.98", "0.015892"], ["84191.74", "0.010988"], ["84216.10", "0.256770"], ["84216.50", "0.006240"], ["84217.30", "0.001028"], ["84218.50", "0"], ["84218.90", "0.012000"], ["84225.40", "0"], ["84226.40", "0"], ["84258.10", "4.616294"], ["84266.60", "5.430934"], ["84275.10", "4.435263"], ["84283.60", "4.887840"], ["84292.10", "4.254232"], ["84309.10", "5.159387"], ["84317.60", "5.068871"], ["84326.10", "4.525778"], ["84334.60", "3.892169"], ["84343.10", "5.611965"], ["84351.60", "3.982685"], ["84360.10", "4.163716"], ["84368.60", "4.073200"], ["84377.10", "5.249903"], ["84385.60", "4.978356"], ["84394.10", "5.340418"], ["84402.60", "4.706809"], ["84411.10", "4.797325"], ["84419.60", "4.344747"], ["84568.97", "0"], ["84569.23", "0"], ["84570.51", "0"], ["84570.99", "0"]], "bids": [["84143.98", "0.008528"], ["84143.97", "0.005578"], ["84143.96", "0.004823"], ["84143.91", "0.024079"], ["84143.80", "0.025052"], ["84143.59", "0.014193"], ["84141.80", "0.065927"], ["84139.80", "0.173711"], ["84137.80", "0.457135"], ["84135.80", "1.202985"], ["84133.80", "3.165750"], ["84131.80", "8.330921"], ["84131.60", "5.665860"], ["84131.40", "0"], ["84131.32", "0.005929"], ["84131.31", "0.008007"], ["84131.30", "0.010024"], ["84131.27", "0.008589"], ["84131.26", "0.009177"], ["84131.20", "0.655980"], ["84130.21", "0.014231"], ["84130.18", "0.007298"], ["84130.17", "0.007788"], ["84128.60", "0"], ["84127.90", "1.940160"], ["84127.50", "1.549770"], ["84126.40", "0.259547"], ["84123.05", "0.005047"], ["84122.50", "1.068090"], ["84121.97", "0.073145"], ["84121.05", "0.056313"], ["84120.90", "2.503200"], ["84120.80", "0"], ["84119.50", "0.012000"], ["84117.90", "0.084780"], ["84117.80", "0"], ["84117.60", "0"], ["84117.20", "0"], ["84104.40", "0.008565"], ["84102.69", "0.007241"], ["84102.52", "0.007644"], ["84089.70", "4.525778"], ["84081.20", "3.982685"], ["84072.70", "4.706809"], ["84055.70", "4.435263"], ["84047.20", "5.249903"], ["84038.70", "5.159387"], ["84030.20", "4.797325"], ["84021.70", "5.611965"], ["84013.20", "5.340418"], ["84004.70", "4.073200"], ["83987.70", "4.344747"], ["83979.20", "4.163716"], ["83970.70", "4.616294"], ["83962.20", "5.521449"], ["83953.70", "5.068871"], ["83945.20", "5.430934"], ["83936.70", "3.892169"], ["83928.20", "4.887840"], ["83686.11", "0"], ["83684.21", "0"], ["83683.67", "0"], ["83681.82", "0"], ["83680.67", "0"], ["83680.00", "0"], ["83679.44", "0"], ["83678.70", "0"], ["83678.41", "0"], ["83678.08", "0"], ["83677.42", "0"], ["83677.37", "0"]], "checksum": -1479994137, "ts": "1742560338273"}], "ts": 1742560338278}}
{"exchange": "BYBIT", "timestamp": 1742560338.365873, "message": {"topic": "orderbook.200.BTCUSDT", "ts": 1742560338320, "type": "delta", "data": {"s": "BTCUSDT", "b": [["84187.7", "0.625228"], ["84185.2", "0.057283"], ["84178.7", "0.029926"], ["84177.1", "0"], ["84171.4", "0.034237"], ["84168.2", "0.059868"], ["84168", "0.083958"], ["84166.6", "0"], ["84163.4", "0.241516"], ["84159.6", "0"], ["84157", "0"], ["84136.7", "0.05"], ["84136.5", "0.000358"], ["84135.3", "0.135502"]], "a": [["84187.8", "0.099529"], ["84194.3", "0.181537"], ["84195.5", "0.027"], ["84198.6", "0.047117"], ["84198.7", "0.059325"], ["84199.2", "0.00099"], ["84201.5", "0.000333"], ["84201.6", "0"], ["84201.7", "0.044399"], ["84202.1", "0.068953"], ["84211.9", "0.01728"], ["84212", "0.259753"], ["84212.1", "0"], ["84213.6", "0.0006"], ["84219.1", "0"], ["84219.7", "0.023322"], ["84219.9", "0.012973"], ["84249.5", "0"], ["84258.7", "0"]], "u": 45280, "seq": 67552582825}, "cts": 1742560338317}}
{"exchange": "BITGET", "timestamp": 1742560338.511313, "message": {"action": "update", "arg": {"instType": "SPOT", "channel": "books", "instId": "BTCUSDT"}, "data": [{"asks": [["84154.65", "0.360000"], ["84156.22", "0.095050"], ["84169.77", "0.004138"], ["84192.67", "0.178974"], ["84208.00", "0.001048"], ["84212.00", "0.001010"], ["84214.00", "0.001010"], ["84216.00", "0.001135"], ["84216.50", "0.006060"], ["84218.90", "0.001002"], ["84220.20", "0.030000"], ["84220.60", "0"], ["84228.20", "0.240000"], ["84258.10", "3.982685"], ["84266.60", "4.435263"], ["84275.10", "4.978356"], ["84292.10", "4.706809"], ["84300.60", "5.340418"], ["84326.10", "5.521449"], ["84334.60", "5.611965"], ["84343.10", "4.344747"], ["84351.60", "5.249903"], ["84360.10", "4.616294"], ["84368.60", "4.254232"], ["84377.10", "3.892169"], ["84385.60", "4.525778"], ["84394.10", "5.430934"], ["84402.60", "4.797325"], ["84411.10", "4.163716"], ["84419.60", "4.073200"], ["84565.22", "0"], ["84566.67", "0"], ["84567.79", "0"], ["84568.60", "0"], ["84568.81", "0"]], "bids": [["84143.92", "0.036818"], ["84143.80", "0.025153"], ["84143.59", "0"], ["84141.80", "0.066191"], ["84139.80", "0.174187"], ["84137.80", "0.458386"], ["84135.80", "1.206281"], ["84133.80", "3.174422"], ["84131.80", "8.353744"], ["84131.60", "4.983840"], ["84131.20", "0"], ["84130.18", "0.016500"], ["84127.90", "1.940370"], ["84123.30", "0.009270"], ["84119.50", "0"], ["84117.90", "0.204780"], ["84117.80", "0.120000"], ["84107.35", "0.007428"], ["84089.70", "4.073200"], ["84081.20", "4.706809"], ["84072.70", "4.254232"], ["84064.20", "4.887840"], ["84055.70", "5.068871"], ["84047.20", "3.892169"], ["84038.70", "4.163716"], ["84030.20", "5.521449"], ["84021.70", "4.525778"], ["84013.20", "5.611965"], ["84004.70", "4.797325"], ["83996.20", "4.344747"], ["83987.70", "4.978356"], ["83979.20", "3.982685"], ["83970.70", "5.249903"], ["83962.20", "5.430934"], ["83953.70", "4.435263"], ["83945.20", "5.340418"], ["83936.70", "5.159387"], ["83928.20", "4.616294"], ["83687.00", "0"]], "checksum": 1753335350, "ts": "1742560338473"}], "ts": 1742560338477}}
{"exchange": "BYBIT", "timestamp": 1742560338.541092, "message": {"topic": "orderbook.200.BTCUSDT", "ts": 1742560338520, "type": "delta", "data": {"s": "BTCUSDT", "b": [["84179.3", "0.011999"], ["84174.2", "0"], ["84172.3", "0"], ["84171.4", "0.018602"], ["84163.4", "0.167167"], ["84161.2", "0.0071"], ["84160.9", "0.02948"], ["84159", "0.165439"], ["84149.4", "0.178173"]], "a": [["84187.8", "0.151168"], ["84191.9", "0.0713"], ["84196.2", "0.01"], ["84201.6", "0.061865"], ["84202.1", "0.031701"], ["84258", "0"], ["84258.5", "0"]], "u": 45281, "seq": 67552582906}, "cts": 1742560338516}}
{"exchange": "BITGET", "timestamp": 1742560338.71073, "message": {"action": "update", "arg": {"instType": "SPOT", "channel": "books", "instId": "BTCUSDT"}, "data": [{"asks": [["84174.00", "0.067284"], ["84216.50", "0.006240"], ["84218.90", "0"], ["84222.00", "0.174000"], ["84223.80", "0.066060"], ["84228.20", "0"], ["84258.10", "3.892169"], ["84266.60", "4.887840"], ["84275.10", "4.073200"], ["84283.60", "4.616294"], ["84292.10", "4.254232"], ["84300.60", "5.430934"], ["84309.10", "4.344747"], ["84317.60", "5.340418"], ["84326.10", "4.797325"], ["84334.60", "3.982685"], ["84343.10", "4.163716"], ["84351.60", "5.521449"], ["84360.10", "4.435263"], ["84368.60", "4.706809"], ["84377.10", "4.525778"], ["84385.60", "4.978356"], ["84394.10", "5.068871"], ["84402.60", "5.159387"], ["84411.10", "5.611965"], ["84419.60", "5.249903"], ["84565.22", "0.003438"]], "bids": [["84139.91", "0.188116"], ["84127.90", "1.938090"], ["84117.60", "0.120000"], ["84092.00", "0.000015"], ["84089.70", "4.706809"], ["84081.20", "4.435263"], ["84072.70", "4.797325"], ["84064.20", "5.159387"], ["84055.70", "4.073200"], ["84047.20", "4.525778"], ["84038.70", "5.068871"], ["84030.20", "4.254232"], ["84021.70", "5.249903"], ["84004.70", "3.892169"], ["83996.20", "4.978356"], ["83987.70", "5.430934"], ["83979.20", "4.887840"], ["83970.70", "4.616294"], ["83962.20", "4.163716"], ["83953.70", "3.982685"], ["83945.20", "5.521449"], ["83936.70", "5.340418"], ["83928.20", "4.344747"], ["83687.50", "0"]], "checksum": -146226988, "ts": "1742560338674"}], "ts": 1742560338676}}
{"exchange": "BYBIT", "timestamp": 1742560338.741351, "message": {"topic": "orderbook.200.BTCUSDT", "ts": 1742560338720, "type": "delta", "data": {"s": "BTCUSDT", "b": [["84183.5", "0.00008"], ["84179.3", "0.016999"], ["84176.2", "0.12475"], ["84168.9", "0.003575"], ["84168", "0.12251"], ["84167.9", "0.019942"], ["84166.4", "0.168489"], ["84157.3", "0.287556"], ["84136.7", "0.04956"], ["84111.1", "0"], ["84110.9", "0"], ["84110.4", "0"], ["84110.3", "0"]], "a": [["84187.8", "0.157168"], ["84198.6", "0.105365"], ["84201.3", "0.178145"], ["84201.4", "0.109194"], ["84211.2", "0.169527"], ["84216.5", "0.100413"], ["84219.8", "0"], ["84219.9", "0"], ["84220.3", "0.289705"], ["84220.5", "0.137694"], ["84220.6", "0.012973"], ["84220.8", "0.005939"], ["84220.9", "0"], ["84221.5", "0.103196"], ["84221.6", "0.04"], ["84256", "0"], ["84256.3", "0"], ["84257.1", "0"], ["84257.5", "0"]], "u": 45282, "seq": 67552582992}, "cts": 1742560338711}}
{"exchange": "BYBIT", "timestamp": 1742560338.939532, "message": {"topic": "orderbook.200.BTCUSDT", "ts": 1742560338919, "type": "delta", "data": {"s": "BTCUSDT", "b": [["84187.7", "0.796228"], ["84185.2", "0.128588"], ["84182.6", "0.190942"], ["84178.7", "0.055909"], ["84178.2", "0.071311"], ["84176.2", "0.000216"], ["84172.8", "0"], ["84171.5", "0.060498"], ["84168.9", "0"], ["84168", "0.083958"], ["84166.4", "0"], ["84164.5", "0.059527"], ["84159", "0.243067"], ["84157.5", "0.116069"], ["84157.3", "0"], ["84135.3", "0.135506"]], "a": [["84187.8", "0.153605"], ["84191.8", "0"], ["84193.1", "0.000333"], ["84196.2", "0.015"], ["84197.3", "0.040333"], ["84197.4", "0.171"], ["84198.7", "0.023679"], ["84198.8", "0.035646"], ["84201.2", "0.118793"], ["84201.3", "0"], ["84201.4", "0.00009"], ["84206.5", "0.060472"], ["84211.2", "0"], ["84213.5", "0.099967"], ["84218.7", "0.242516"], ["84220.1", "0"], ["84220.3", "0"], ["84220.5", "0.246679"], ["84220.7", "0.012973"], ["84221.5", "0.063196"], ["84221.7", "0.04"], ["84222.9", "0.063451"]], "u": 45283, "seq": 67552583079}, "cts": 1742560338912}}
{"exchange": "BITGET", "timestamp": 1742560339.000543, "message": {"action": "update", "arg": {"instType": "SPOT", "channel": "books", "instId": "BTCUSDT"}, "data": [{"asks": [["84154.66", "0"], ["84155.82", "0.095051"], ["84156.22", "0"], ["84160.89", "0.054775"], ["84162.27", "0"], ["84174.95", "0.101111"], ["84176.14", "0.017433"], ["84208.00", "0.002352"], ["84210.00", "0.006189"], ["84212.00", "0.016287"], ["84214.00", "0.042861"], ["84216.00", "0.112790"], ["84218.10", "0.001045"], ["84218.90", "0.001005"], ["84219.50", "0"], ["84222.00", "0"], ["84223.80", "0.145350"], ["84225.30", "0.246030"], ["84228.20", "0.120000"], ["84258.10", "4.616294"], ["84266.60", "5.249903"], ["84275.10", "4.344747"], ["84283.60", "4.163716"], ["84292.10", "5.159387"], ["84300.60", "5.068871"], ["84309.10", "3.892169"], ["84317.60", "5.611965"], ["84326.10", "3.982685"], ["84334.60", "5.430934"], ["84343.10", "4.254232"], ["84351.60", "4.978356"], ["84360.10", "4.525778"], ["84368.60", "4.073200"], ["84377.10", "4.706809"], ["84385.60", "4.887840"], ["84394.10", "4.435263"], ["84402.60", "4.797325"], ["84411.10", "5.521449"], ["84419.60", "5.340418"], ["84565.22", "0"]], "bids": [["84134.59", "1.105468"], ["84110.51", "0.017433"], ["84096.64", "0"], ["84093.00", "0"], ["84089.70", "4.435263"], ["84081.20", "4.073200"], ["84072.70", "4.706809"], ["84064.20", "4.344747"], ["84055.70", "3.892169"], ["84047.20", "4.254232"], ["84038.70", "5.249903"], ["84030.20", "3.982685"], ["84021.70", "4.887840"], ["84013.20", "5.521449"], ["84004.70", "4.978356"], ["83996.20", "4.525778"], ["83987.70", "5.159387"], ["83979.20", "4.163716"], ["83970.70", "4.797325"], ["83962.20", "5.068871"], ["83953.70", "4.616294"], ["83945.20", "5.611965"], ["83928.20", "5.430934"], ["83687.50", "0.006969"]], "checksum": -23321359, "ts": "1742560338877"}], "ts": 1742560338880}}
{"exchange": "BITGET", "timestamp": 1742560339.115679, "message": {"action": "update", "arg": {"instType": "SPOT", "channel": "books", "instId": "BTCUSDT"}, "data": [{"asks": [["84144.01", "0.010622"], ["84162.26", "0"], ["84165.70", "0.004154"], ["84180.06", "0"], ["84183.34", "0.013405"], ["84214.00", "0.042712"], ["84216.00", "0.112400"], ["84218.10", "0"], ["84219.00", "0.001045"], ["84219.70", "0"], ["84220.10", "0"], ["84222.70", "0.321000"], ["84223.70", "0.915450"], ["84223.90", "0"], ["84224.50", "0"], ["84225.30", "0.300210"], ["84226.20", "0"], ["84227.80", "0"], ["84228.10", "2.425110"], ["84228.20", "0.240000"], ["84258.10", "4.073200"], ["84266.60", "5.521449"], ["84275.10", "4.163716"], ["84283.60", "5.249903"], ["84292.10", "3.982685"], ["84309.10", "4.616294"], ["84317.60", "4.435263"], ["84326.10", "5.340418"], ["84334.60", "5.159387"], ["84343.10", "3.892169"], ["84351.60", "4.344747"], ["84360.10", "4.797325"], ["84368.60", "4.525778"], ["84385.60", "5.430934"], ["84394.10", "4.978356"], ["84402.60", "5.611965"], ["84411.10", "4.254232"], ["84419.60", "4.887840"], ["84565.22", "0.003438"], ["84566.67", "0.001061"], ["84567.79", "0.000009"], ["84568.60", "0.000018"], ["84568.81", "0.000072"]], "bids": [["84144.00", "1.103793"], ["84143.80", "0.025892"], ["84141.80", "0.068136"], ["84139.80", "0.179306"], ["84137.80", "0.471738"], ["84135.80", "1.241417"], ["84133.80", "3.266886"], ["84131.80", "8.597069"], ["84131.60", "4.983210"], ["84130.91", "1.037315"], ["84126.91", "0"], ["84122.91", "0"], ["84089.70", "4.797325"], ["84081.20", "3.982685"], ["84072.70", "5.430934"], ["84064.20", "4.073200"], ["84055.70", "4.525778"], ["84047.20", "4.706809"], ["84038.70", "4.254232"], ["84030.20", "5.611965"], ["84021.70", "5.249903"], ["84013.20", "5.340418"], ["84004.70", "4.435263"], ["83996.20", "5.068871"], ["83987.70", "4.887840"], ["83979.20", "5.159387"], ["83970.70", "4.344747"], ["83962.20", "3.892169"], ["83945.20", "5.521449"], ["83936.70", "4.163716"], ["83928.20", "4.978356"], ["83687.00", "0.000008"], ["83686.11", "0.000096"]], "checksum": 602925251, "ts": "1742560339086"}], "ts": 1742560339090}}
{"exchange": "BYBIT", "timestamp": 1742560339.139843, "message": {"topic": "orderbook.200.BTCUSDT", "ts": 1742560339119, "type": "delta", "data": {"s": "BTCUSDT", "b": [["84186.5", "0.071304"], ["84185.2", "0.057283"], ["84173.3", "0.009826"], ["84171.6", "0.025624"], ["84171.5", "0"], ["84171.4", "0"], ["84164.5", "0"], ["84163.2", "0.003575"], ["84160.6", "0"], ["84157.5", "0"], ["84156", "0.004605"], ["84142.5", "0.011885"], ["84141.7", "0.039643"], ["84141.6", "0.039643"], ["84140.7", "0.012884"], ["84140.6", "0.012884"], ["84138.6", "0.092776"], ["84136.8", "0.049559"], ["84136.6", "0"], ["84135.4", "0"], ["84130.7", "0"], ["84130.6", "0"], ["84129.7", "0.001466"], ["84129.6", "0"]], "a": [["84205.4", "0.178136"], ["84206.5", "0.0045"], ["84213.5", "0.04424"], ["84218.7", "0.173157"], ["84219.7", "0"], ["84220.5", "0.124721"], ["84220.6", "0"], ["84220.7", "0"], ["84221.5", "0.076196"], ["84221.6", "0.012973"], ["84221.7", "0"], ["84222.5", "0.04"], ["84222.6", "0.11747"], ["84222.9", "0"], ["84228.6", "0.063451"], ["84245.6", "0"], ["84256", "0.05"], ["84256.3", "0.000333"], ["84257.1", "0.003564"]], "u": 45284, "seq": 67552583157}, "cts": 1742560339114}}
{"exchange": "BITGET", "timestamp": 1742560339.320183, "message": {"action": "update", "arg": {"instType": "SPOT", "channel": "books", "instId": "BTCUSDT"}, "data": [{"asks": [["84144.01", "0"], ["84144.02", "0"], ["84144.03", "0"], ["84144.04", "0"], ["84145.03", "0"], ["84154.65", "0"], ["84155.82", "0"], ["84157.33", "0"], ["84160.80", "0"], ["84160.81", "0"], ["84160.84", "0"], ["84160.85", "0"], ["84160.89", "0"], ["84161.36", "0"], ["84161.44", "0"], ["84162.11", "0"], ["84165.70", "0"], ["84165.71", "0"], ["84169.78", "0"], ["84169.96", "0.007471"], ["84170.46", "0.006594"], ["84170.54", "0.006307"], ["84170.61", "0.009400"], ["84174.96", "0"], ["84175.11", "0"], ["84175.68", "0"], ["84176.88", "0"], ["84177.73", "0"], ["84178.87", "0"], ["84179.31", "0"], ["84179.48", "0"], ["84179.59", "0"], ["84180.30", "0"], ["84180.64", "0"], ["84180.91", "0"], ["84180.99", "0"], ["84182.21", "0"], ["84183.34", "0"], ["84184.07", "0"], ["84184.93", "0.035952"], ["84185.17", "0"], ["84185.50", "0"], ["84185.62", "0.119870"], ["84185.69", "0"], ["84186.99", "0"], ["84188.75", "0.010984"], ["84189.41", "0.016429"], ["84190.45", "0.006356"], ["84190.63", "0.119883"], ["84190.98", "0"], ["84191.02", "0.006356"], ["84191.05", "0.806351"], ["84191.06", "0"], ["84191.74", "0"], ["84193.20", "0"], ["84195.65", "0.015895"], ["84196.00", "0"], ["84198.00", "0"], ["84199.15", "0"], ["84200.00", "0"], ["84201.46", "0"], ["84202.00", "0"], ["84203.40", "0"], ["84204.00", "0"], ["84205.30", "0.001036"], ["84205.69", "0.010000"], ["84206.00", "0"], ["84207.30", "0.001026"], ["84208.00", "0"], ["84209.30", "0.001038"], ["84210.00", "0.002000"], ["84211.30", "0.001014"], ["84212.00", "0"], ["84213.17", "0.712477"], ["84213.30", "0.001021"], ["84214.00", "0"], ["84215.30", "0.001040"], ["84216.00", "0"], ["84216.10", "0"], ["84216.50", "0"], ["84216.70", "0.000958"], ["84218.20", "0"], ["84218.90", "0"], ["84219.00", "0"], ["84219.30", "0.001006"], ["84219.60", "0"], ["84220.20", "0"], ["84220.90", "0"], ["84221.30", "0.001049"], ["84222.10", "0"], ["84222.70", "0"], ["84223.30", "0.001036"], ["84223.70", "0"], ["84223.80", "0"], ["84224.00", "0"], ["84224.73", "0"], ["84225.30", "0.001040"], ["84225.40", "0.001017"], ["84225.90", "0.089340"], ["84226.40", "0.001021"], ["84226.50", "0.001005"], ["84227.10", "0"], ["84227.20", "2.132100"], ["84227.30", "0"], ["84228.10", "0"], ["84228.20", "0.015000"], ["84229.00", "0.009000"], ["84229.20", "0.015180"], ["84229.60", "1.780170"], ["84231.10", "0.177990"], ["84231.40", "3.916170"], ["84232.30", "1.068090"], ["84232.90", "0.009000"], ["84233.30", "0.026790"], ["84233.90", "1.424130"], ["84235.40", "6.679890"], ["84235.50", "0.180000"], ["84235.80", "0.240000"], ["84237.70", "0.831120"], ["84240.00", "0.120000"], ["84240.30", "5.130750"], ["84240.90", "0.932370"], ["84241.30", "0.009000"], ["84242.10", "0.035640"], ["84258.10", "0"], ["84260.61", "0"], ["84266.60", "0"], ["84267.40", "4.977810"], ["84275.10", "0"], ["84275.90", "5.068316"], ["84283.60", "0"], ["84284.40", "3.891743"], ["84292.10", "0"], ["84292.90", "4.072754"], ["84300.60", "0"], ["84301.40", "4.796799"], ["84309.10", "0"], ["84309.90", "4.163259"], ["84317.60", "0"], ["84318.40", "4.706293"], ["84326.10", "0"], ["84326.90", "4.615788"], ["84334.60", "0"], ["84335.40", "4.344271"], ["84343.10", "0"], ["84343.90", "4.887304"], ["84351.60", "0"], ["84352.40", "5.249327"], ["84360.10", "0"], ["84360.90", "5.611350"], ["84368.60", "0"], ["84369.40", "5.158821"], ["84377.10", "0"], ["84377.90", "3.982248"], ["84385.60", "0"], ["84386.40", "5.520844"], ["84394.10", "0"], ["84394.90", "5.339833"], ["84402.60", "0"], ["84403.40", "4.253765"], ["84411.10", "0"], ["84411.90", "4.434776"], ["84419.60", "0"], ["84420.40", "4.525282"], ["84428.90", "5.430338"], ["84455.96", "0.209200"], ["84568.97", "0.000024"], ["84569.23", "0.000009"], ["84570.51", "0.000170"], ["84570.99", "0.000053"], ["84571.43", "0.000124"], ["84571.75", "0.001273"], ["84571.82", "0.000046"], ["84572.75", "0.000009"], ["84573.59", "0.000177"], ["84573.83", "0.000215"], ["84574.00", "0.508335"], ["84574.47", "0.000349"], ["84574.50", "0.000039"], ["84574.67", "0.000010"], ["84575.00", "0.000015"], ["84577.11", "0.000008"], ["84577.78", "0.000009"], ["84578.31", "0.000008"], ["84578.95", "0.000183"], ["84579.32", "0.000025"], ["84579.76", "0.000051"], ["84580.67", "0.000013"], ["84582.14", "0.000011"], ["84583.28", "0.000010"], ["84583.33", "0.000009"], ["84585.00", "0.002343"], ["84588.23", "0.000008"], ["84588.93", "0.000299"], ["84588.97", "0.000018"]], "bids": [["84161.00", "0.001016"], ["84159.00", "0.001006"], ["84157.00", "0.002472"], ["84155.00", "0.006504"], ["84154.64", "0.218860"], ["84153.64", "0.008705"], ["84153.17", "0.008528"], ["84153.11", "0.004823"], ["84153.06", "0.009855"], ["84153.00", "0.017116"], ["84151.00", "0.045044"], ["84149.00", "0.118536"], ["84147.00", "0.311936"], ["84145.00", "0.820884"], ["84144.43", "0.010326"], ["84144.00", "0.957955"], ["84143.98", "0"], ["84143.97", "0"], ["84143.96", "0"], ["84143.92", "0"], ["84143.91", "0.014224"], ["84143.80", "0"], ["84143.00", "2.160221"], ["84141.80", "0"], ["84141.03", "0.008054"], ["84141.00", "5.684792"], ["84140.37", "0"], ["84140.36", "0"], ["84140.32", "0.005929"], ["84139.90", "0.084600"], ["84139.80", "0"], ["84139.79", "0"], ["84139.75", "0.028837"], ["84139.70", "11.105760"], ["84139.60", "0.491820"], ["84139.50", "11.109240"], ["84139.40", "0.932160"], ["84139.34", "0.016952"], ["84139.31", "0.006899"], ["84139.29", "0.224667"], ["84139.20", "0.008177"], ["84138.40", "0.608400"], ["84137.90", "0.084780"], ["84137.80", "0.178470"], ["84136.80", "0.491820"], ["84136.60", "0.107400"], ["84135.90", "0.084600"], ["84135.80", "0.073560"], ["84135.30", "0.107400"], ["84134.71", "0"], ["84134.70", "0.120000"], ["84134.55", "0.076039"], ["84134.44", "0"], ["84133.90", "0.084600"], ["84133.80", "0"], ["84133.30", "0.180000"], ["84133.12", "0"], ["84132.20", "1.780170"], ["84132.14", "0.005047"], ["84132.12", "0"], ["84132.08", "0.008085"], ["84131.90", "0.084600"], ["84131.80", "6.687660"], ["84131.60", "1.225860"], ["84131.32", "0"], ["84131.31", "0"], ["84131.30", "0"], ["84131.27", "0"], ["84131.26", "0"], ["84131.07", "0"], ["84130.84", "0"], ["84130.65", "0"], ["84130.57", "0"], ["84130.50", "0"], ["84130.21", "0.007332"], ["84130.18", "0"], ["84130.17", "0"], ["84129.94", "0"], ["84129.90", "0.084600"], ["84129.64", "0"], ["84129.51", "0"], ["84129.32", "0"], ["84129.30", "0"], ["84129.24", "0"], ["84128.80", "2.670270"], ["84128.70", "0.045000"], ["84128.50", "0.045000"], ["84128.20", "2.670270"], ["84127.91", "0.402701"], ["84127.90", "0.620130"], ["84127.75", "0"], ["84127.60", "2.670270"], ["84127.51", "0"], ["84127.50", "2.249370"], ["84127.05", "0"], ["84127.04", "0"], ["84126.40", "0"], ["84126.06", "0"], ["84125.90", "1.782480"], ["84125.84", "0"], ["84125.40", "0"], ["84124.91", "0"], ["84124.70", "0"], ["84124.40", "0"], ["84124.30", "0"], ["84124.26", "0"], ["84124.10", "0"], ["84123.90", "0"], ["84123.40", "0"], ["84123.30", "0"], ["84123.05", "0"], ["84122.80", "0"], ["84122.50", "0"], ["84122.30", "0"], ["84122.10", "0"], ["84122.00", "0.000032"], ["84121.97", "0"], ["84121.90", "0"], ["84121.60", "0"], ["84121.05", "0"], ["84120.90", "0"], ["84120.10", "0"], ["84119.90", "0"], ["84119.60", "0"], ["84119.33", "0"], ["84119.10", "0"], ["84118.79", "0"], ["84118.10", "0"], ["84117.90", "0"], ["84117.80", "0"], ["84117.60", "0"], ["84117.10", "0.000396"], ["84114.20", "0"], ["84111.69", "0.007241"], ["84111.61", "0.007330"], ["84111.52", "0.007644"], ["84110.68", "0"], ["84110.03", "0.001175"], ["84107.35", "0"], ["84104.40", "0"], ["84102.69", "0"], ["84102.52", "0"], ["84098.90", "4.977810"], ["84098.45", "0"], ["84097.07", "0.071045"], ["84094.90", "0"], ["84091.06", "0"], ["84090.40", "5.430338"], ["84089.70", "0"], ["84087.60", "0.000948"], ["84084.70", "0"], ["84081.90", "5.249327"], ["84081.20", "0"], ["84073.40", "4.344271"], ["84072.70", "0"], ["84064.90", "3.982248"], ["84064.20", "0"], ["84058.43", "0"], ["84056.40", "4.253765"], ["84056.31", "0"], ["84055.70", "0"], ["84047.90", "4.615788"], ["84047.20", "0"], ["84039.40", "4.072754"], ["84038.70", "0"], ["84030.90", "5.611350"], ["84030.20", "0"], ["84022.40", "4.887304"], ["84021.70", "0"], ["84013.90", "4.163259"], ["84013.34", "0"], ["84013.20", "0"], ["84005.40", "5.158821"], ["84004.70", "0"], ["83996.90", "3.891743"], ["83996.20", "0"], ["83988.40", "5.520844"], ["83987.70", "0"], ["83979.90", "5.339833"], ["83979.20", "0"], ["83971.40", "5.068316"], ["83970.70", "0"], ["83962.90", "4.434776"], ["83962.20", "0"], ["83954.40", "4.796799"], ["83953.70", "0"], ["83945.90", "4.525282"], ["83945.20", "0"], ["83937.40", "4.706293"], ["83936.70", "0"], ["83928.20", "0"], ["83684.21", "0.000102"], ["83683.67", "0.000184"], ["83681.82", "0.000175"], ["83680.67", "0.041940"], ["83680.00", "0.000495"], ["83679.44", "0.000361"], ["83678.70", "0.000192"], ["83678.41", "0.000010"], ["83678.08", "0.000145"], ["83677.42", "0.000008"], ["83677.37", "0.000008"], ["83676.47", "0.000080"], ["83675.68", "0.000008"], ["83675.62", "0.000011"], ["83675.36", "0.000013"], ["83675.20", "0.000018"], ["83675.00", "0.000458"], ["83674.70", "0.000008"], ["83674.19", "0.000020"], ["83674.00", "0.001195"], ["83673.87", "0.000022"], ["83673.58", "0.000023"], ["83672.96", "0.002168"], ["83672.50", "0.000031"], ["83672.25", "0.003958"], ["83672.00", "0.000035"], ["83671.36", "0.000099"], ["83670.59", "0.000105"], ["83670.05", "0.000033"]], "checksum": 1957760042, "ts": "1742560339286"}], "ts": 1742560339289}}
{"exchange": "BYBIT", "timestamp": 1742560339.414616, "message": {"topic": "orderbook.200.BTCUSDT", "ts": 1742560339319, "type": "delta", "data": {"s": "BTCUSDT", "b": [["84193.6", "0.960192"], ["84193", "0.06"], ["84192.5", "0.301348"], ["84192.4", "0.200934"], ["84192.3", "0.019942"], ["84191.8", "0.340876"], ["84191.6", "0.356396"], ["84190.8", "0.086346"], ["84190.3", "0.003936"], ["84188.9", "0.108339"], ["84188.8", "0.163267"], ["84188.2", "0.001333"], ["84187.8", "0.003269"], ["84187.7", "0.085718"], ["84187.2", "0.120876"], ["84187.1", "0.071304"], ["84186.5", "0"], ["84186.2", "0.009826"], ["84185.3", "0.059399"], ["84185.2", "0.032981"], ["84185.1", "0.019942"], ["84184.7", "0.097451"], ["84184.4", "0.000518"], ["84184", "0.011333"], ["84183.8", "0.0482"], ["84183.7", "0.01887"], ["84183.6", "0.003269"], ["84183.1", "0.116076"], ["84180.9", "0.023832"], ["84179.6", "0.00009"], ["84179.3", "0.006999"], ["84178.7", "0.029926"], ["84178.6", "0.049876"], ["84178.2", "0"], ["84177.1", "0.056"], ["84176.8", "0.049876"], ["84176.7", "0.176358"], ["84176.1", "0.314966"], ["84175.9", "0.001466"], ["84175.7", "0"], ["84175.5", "0.001333"], ["84173.3", "0"], ["84172.2", "0.540618"], ["84171.6", "0"], ["84171.4", "0.025624"], ["84171.3", "0.042799"], ["84169.7", "0.293513"], ["84169.1", "0.289005"], ["84168.2", "0"], ["84167.5", "0.037977"], ["84164.2", "0.503566"], ["84163.2", "0"], ["84162.9", "0.025973"], ["84162.4", "0.005942"], ["84162.3", "0.118793"], ["84160.7", "0.011883"], ["84159", "0.165439"], ["84155.5", "0"], ["84154.1", "0.003564"], ["84152.4", "0"], ["84152.3", "0"], ["84149.5", "0.135533"], ["84149.4", "0"], ["84146.9", "0"], ["84146", "0.00018"], ["84145.7", "0.003259"], ["84142.5", "0"], ["84141", "0.005939"], ["84140.4", "0"], ["84138.1", "0.024274"], ["84137.2", "0.023756"], ["84137.1", "0"], ["84136.9", "0.05"], ["84136.7", "0"], ["84135.7", "0.023756"], ["84135.3", "0"], ["84134.9", "0.023756"], ["84134.4", "0"], ["84134", "0"], ["84132.3", "0.023856"], ["84130.1", "3.358693"], ["84120.8", "0"], ["84120.5", "0"], ["84120.4", "0"], ["84120.3", "0"], ["84120.1", "0"], ["84120", "0"], ["84119.6", "0"], ["84119.3", "0"], ["84118.8", "0"], ["84118", "0"], ["84117.4", "0"], ["84116.9", "0"], ["84116.7", "0"], ["84116.6", "0"], ["84116.5", "0"], ["84116.3", "0"], ["84115.8", "0"], ["84115.6", "0"], ["84115.4", "0"], ["84115.3", "0"], ["84115", "0"], ["84114.4", "0"], ["84113.2", "0"], ["84113", "0"], ["84112.4", "0"], ["84112.1", "0"]], "a": [["84187.8", "0"], ["84188.2", "0"], ["84188.9", "0"], ["84189", "0"], ["84189.4", "0"], ["84189.8", "0"], ["84190", "0"], ["84190.9", "0"], ["84191.9", "0"], ["84192", "0"], ["84192.4", "0"], ["84192.6", "0"], ["84193", "0"], ["84193.1", "0"], ["84194.3", "0"], ["84195", "0"], ["84195.5", "0"], ["84195.6", "0"], ["84195.8", "0"], ["84196.9", "0"], ["84197.1", "0"], ["84197.3", "0.000333"], ["84197.4", "0"], ["84197.6", "0"], ["84197.7", "0"], ["84198.6", "0"], ["84198.7", "0"], ["84198.8", "0"], ["84199.3", "0"], ["84199.7", "0"], ["84200.6", "0"], ["84200.9", "0"], ["84201.2", "0"], ["84201.6", "0"], ["84201.7", "0"], ["84202.1", "0.042811"], ["84202.4", "0"], ["84202.6", "0"], ["84202.8", "0"], ["84203.3", "0.023678"], ["84204.7", "0.003293"], ["84205.4", "0"], ["84205.6", "0"], ["84206.6", "0.0003"], ["84207.5", "0.000297"], ["84207.6", "0.081845"], ["84208", "0.071286"], ["84208.2", "0.04"], ["84208.9", "0.047773"], ["84209.1", "0"], ["84209.9", "0.000333"], ["84210", "0"], ["84210.6", "0.003833"], ["84211", "0"], ["84211.7", "0.125009"], ["84211.9", "0"], ["84212", "0"], ["84212.4", "0"], ["84213.1", "0.019028"], ["84213.2", "0.005939"], ["84213.7", "0"], ["84214.9", "0.04"], ["84215.5", "0"], ["84216", "0.113894"], ["84216.6", "0"], ["84216.8", "0.119311"], ["84217.7", "0.01933"], ["84217.8", "0"], ["84218.9", "0"], ["84219", "0"], ["84220", "0.009769"], ["84220.3", "0.482181"], ["84220.4", "0"], ["84220.5", "0"], ["84220.8", "0"], ["84221.5", "0.003812"], ["84221.6", "0"], ["84222.2", "0.173742"], ["84222.3", "0"], ["84222.4", "0.059399"], ["84222.5", "0"], ["84222.6", "0.07747"], ["84222.8", "0"], ["84223", "0.166721"], ["84225.5", "0"], ["84228.1", "0.011883"], ["84228.6", "0"], ["84229.2", "0.287308"], ["84229.3", "0.023755"], ["84230", "0.300906"], ["84231.6", "0.013"], ["84231.7", "0.087446"], ["84232.6", "0.591103"], ["84232.7", "0.04"], ["84235.8", "0"], ["84237.8", "0"], ["84245.5", "0.063451"], ["84250.8", "0"], ["84254", "0"], ["84257.3", "3.21334"], ["84257.5", "0.059367"], ["84258", "0.237586"], ["84258.5", "0.00052"], ["84258.7", "0.000358"], ["84259.3", "0.001466"], ["84259.4", "0.003293"], ["84259.8", "0.001333"], ["84260", "0.059399"], ["84260.1", "0.027743"], ["84260.2", "0.00009"], ["84260.5", "0.000333"], ["84261.2", "0.101605"], ["84262.1", "0.003"], ["84262.3", "0.12"], ["84263", "0.000203"], ["84263.1", "0.118793"], ["84263.2", "0.00052"], ["84263.6", "0.003293"], ["84263.9", "0.001466"], ["84264", "0.001333"], ["84264.3", "0.247212"], ["84264.7", "0.000333"], ["84265", "0.005942"], ["84266", "0.000332"], ["84266.1", "0.096842"], ["84266.5", "0.0045"], ["84267.6", "0.01183"], ["84267.8", "0.00052"], ["84267.9", "0.003292"], ["84268.2", "0.001333"], ["84268.6", "0.001556"], ["84268.9", "0.000333"], ["84269.3", "0.003"], ["84270.6", "0.164721"], ["84270.9", "0.04"], ["84271", "0.237586"], ["84271.1", "0.000146"], ["84271.2", "0.12"], ["84271.3", "0.12"], ["84272", "0.62359"], ["84272.1", "0.003292"], ["84272.3", "0.05728"]], "u": 45285, "seq": 67552584929}, "cts": 1742560339317}}
{"exchange": "BITGET", "timestamp": 1742560339.532132, "message": {"action": "update", "arg": {"instType": "SPOT", "channel": "books", "instId": "BTCUSDT"}, "data": [{"asks": [["84169.77", "0"], ["84169.96", "0"], ["84170.46", "0"], ["84170.54", "0"], ["84170.61", "0"], ["84174.95", "0.009044"], ["84176.14", "0"], ["84177.02", "0.017059"], ["84177.03", "0.008242"], ["84177.07", "0"], ["84177.33", "0"], ["84177.46", "0.006594"], ["84177.56", "0.006307"], ["84177.63", "0.009400"], ["84179.86", "0"], ["84180.22", "0"], ["84180.43", "0"], ["84182.18", "0"], ["84183.18", "0"], ["84184.93", "0"], ["84187.06", "0.035961"], ["84187.71", "0.006356"], ["84187.82", "0.017430"], ["84188.74", "0.013908"], ["84188.75", "0"], ["84189.20", "0.006356"], ["84190.04", "0.006356"], ["84190.16", "0.035952"], ["84190.86", "0.006356"], ["84191.05", "0"], ["84191.90", "0.006356"], ["84192.15", "0.006356"], ["84192.67", "0"], ["84193.97", "0.010984"], ["84194.32", "0.112900"], ["84194.73", "0.010985"], ["84195.02", "0.006356"], ["84195.06", "0.006356"], ["84195.24", "0.016429"], ["84195.79", "0.006357"], ["84196.64", "0.119858"], ["84196.71", "0.009990"], ["84196.76", "0.119850"], ["84197.55", "0.119867"], ["84198.19", "0.009989"], ["84199.72", "0.013405"], ["84201.02", "0.015892"], ["84203.00", "0.010988"], ["84205.30", "0"], ["84205.69", "0"], ["84207.30", "0"], ["84207.36", "0"], ["84209.30", "0"], ["84211.30", "0"], ["84212.40", "0.001042"], ["84213.30", "0"], ["84214.40", "0.001026"], ["84215.30", "0"], ["84216.40", "0.001044"], ["84217.30", "0"], ["84218.40", "0.001024"], ["84219.30", "0"], ["84220.40", "0.002328"], ["84220.45", "0.001598"], ["84220.99", "0"], ["84221.30", "0"], ["84222.40", "0.006127"], ["84223.30", "0"], ["84224.40", "0.016122"], ["84225.30", "0"], ["84225.40", "0"], ["84225.90", "0"], ["84226.20", "0.001597"], ["84226.40", "0.042427"], ["84226.50", "0"], ["84226.80", "0"], ["84227.20", "0"], ["84228.20", "0"], ["84228.40", "0.111650"], ["84229.00", "0"], ["84229.20", "0"], ["84229.60", "0"], ["84230.40", "0.293817"], ["84231.10", "0"], ["84231.40", "0"], ["84231.70", "0.205041"], ["84232.30", "0"], ["84232.40", "0.773202"], ["84232.80", "0.001036"], ["84232.90", "0.010860"], ["84233.30", "0"], ["84233.90", "0"], ["84234.90", "0.002730"], ["84235.30", "0.007350"], ["84235.40", "0.174570"], ["84235.50", "0"], ["84235.80", "0"], ["84237.20", "0.066030"], ["84237.70", "0.007830"], ["84238.20", "0.012660"], ["84238.90", "0.120000"], ["84239.20", "0.066030"], ["84239.40", "0.420000"], ["84239.50", "0.072780"], ["84240.00", "0.002000"], ["84240.90", "0"], ["84241.40", "0.015000"], ["84241.58", "1.780593"], ["84241.77", "0"], ["84241.90", "0.030090"], ["84242.10", "15.102750"], ["84242.30", "0.120000"], ["84242.60", "0.150000"], ["84243.10", "0.120000"], ["84245.10", "3.740880"], ["84245.60", "0.120000"], ["84245.80", "0.021600"], ["84245.90", "0.480000"], ["84246.10", "0.177990"], ["84250.19", "0"], ["84267.40", "0"], ["84274.50", "5.429878"], ["84275.90", "0"], ["84283.00", "5.610874"], ["84284.40", "0"], ["84287.30", "0.057001"], ["84291.50", "4.705895"], ["84292.90", "0"], ["84300.00", "4.072409"], ["84301.40", "0"], ["84308.50", "4.253405"], ["84309.90", "0"], ["84317.00", "3.981911"], ["84318.40", "0"], ["84325.50", "5.339380"], ["84326.90", "0"], ["84334.00", "4.524899"], ["84335.40", "0"], ["84342.50", "4.434401"], ["84343.90", "0"], ["84351.00", "5.520376"], ["84352.40", "0"], ["84359.50", "5.067887"], ["84360.90", "0"], ["84368.00", "4.615397"], ["84369.40", "0"], ["84376.50", "5.158384"], ["84377.90", "0"], ["84385.00", "3.891413"], ["84386.40", "0"], ["84393.50", "4.162907"], ["84394.90", "0"], ["84402.00", "4.977389"], ["84403.40", "0"], ["84410.50", "5.248882"], ["84411.90", "0"], ["84419.00", "4.796393"], ["84420.40", "0"], ["84427.50", "4.343903"], ["84428.90", "0"], ["84436.00", "4.886891"], ["84499.68", "0"], ["84527.03", "1.596475"], ["84577.78", "0"], ["84578.31", "0"], ["84578.95", "0"], ["84579.32", "0"], ["84579.76", "0"], ["84580.67", "0"], ["84582.14", "0"], ["84583.28", "0"], ["84583.33", "0"], ["84585.00", "0"], ["84588.23", "0"], ["84588.93", "0"], ["84588.97", "0"]], "bids": [["84173.99", "0.035500"], ["84169.76", "0.113419"], ["84168.29", "0.154831"], ["84168.10", "0.001026"], ["84166.10", "0.001248"], ["84165.69", "0.455524"], ["84165.21", "0.218860"], ["84164.96", "0.007162"], ["84164.91", "0.008517"], ["84164.10", "0.003284"], ["84162.10", "0.008642"], ["84161.53", "0.005592"], ["84161.01", "0.074800"], ["84161.00", "0.006297"], ["84160.67", "0.010326"], ["84160.66", "0.008705"], ["84160.64", "0.008889"], ["84160.28", "0.005166"], ["84160.23", "0.008528"], ["84160.17", "0.004823"], ["84160.13", "0.009855"], ["84160.10", "0.022742"], ["84159.00", "0"], ["84158.10", "0.059849"], ["84157.01", "0.002693"], ["84157.00", "0"], ["84156.77", "0.005578"], ["84156.10", "0.157497"], ["84155.00", "0"], ["84154.64", "0"], ["84154.10", "0.414466"], ["84153.64", "0"], ["84153.17", "0"], ["84153.11", "0"], ["84153.06", "0"], ["84153.00", "0"], ["84152.10", "1.090698"], ["84151.00", "0"], ["84150.10", "2.870258"], ["84149.81", "0.008261"], ["84149.75", "0.089376"], ["84149.00", "0"], ["84148.10", "7.553311"], ["84148.05", "0.008054"], ["84147.90", "0.086070"], ["84147.40", "1.529160"], ["84147.30", "0.001047"], ["84147.29", "0.017795"], ["84147.26", "0.005929"], ["84147.25", "0.018031"], ["84147.21", "0.026821"], ["84147.20", "0.130437"], ["84147.14", "0.008419"], ["84147.10", "8.416560"], ["84147.00", "0"], ["84146.36", "0.016952"], ["84146.32", "0.006899"], ["84146.30", "0.007298"], ["84146.28", "0.007788"], ["84146.16", "0.055588"], ["84145.90", "0.084600"], ["84145.40", "0.007331"], ["84145.02", "0.371245"], ["84145.00", "0"], ["84144.70", "1.445520"], ["84144.43", "0"], ["84144.40", "0.015150"], ["84144.35", "0.008983"], ["84144.00", "0.499462"], ["84143.90", "0.084600"], ["84143.74", "0.018474"], ["84143.29", "0.083859"], ["84143.00", "0"], ["84142.90", "1.079040"], ["84142.44", "0.025154"], ["84142.09", "0.005940"], ["84141.90", "0.084600"], ["84141.60", "3.186150"], ["84141.08", "0.012640"], ["84141.03", "0"], ["84141.00", "1.462830"], ["84140.70", "0.125790"], ["84140.60", "0.427290"], ["84140.55", "0.007125"], ["84140.50", "0.356310"], ["84140.32", "0.018495"], ["84140.05", "0.017087"], ["84140.02", "0.051913"], ["84139.90", "0.173670"], ["84139.79", "0.007935"], ["84139.70", "0"], ["84139.60", "0"], ["84139.54", "0.004013"], ["84139.50", "0"], ["84139.40", "0"], ["84139.34", "0"], ["84139.31", "0"], ["84139.27", "0.008258"], ["84139.16", "0.005047"], ["84139.09", "0.008085"], ["84138.51", "0.268119"], ["84138.40", "0.269760"], ["84138.37", "0.017334"], ["84138.30", "0.153580"], ["84138.20", "0.929910"], ["84137.80", "0"], ["84136.95", "0.259547"], ["84136.80", "0"], ["84136.74", "0.021109"], ["84136.38", "0.222456"], ["84136.20", "0.125790"], ["84136.00", "0.017790"], ["84134.70", "0"], ["84134.60", "0.106860"], ["84134.59", "0.072005"], ["84134.30", "0.178170"], ["84133.00", "1.020150"], ["84132.47", "0"], ["84132.39", "0"], ["84132.30", "0.056313"], ["84132.20", "0"], ["84132.14", "0"], ["84132.08", "0"], ["84132.04", "0.713164"], ["84132.01", "0.073145"], ["84131.90", "0"], ["84131.80", "0"], ["84131.60", "0"], ["84130.21", "0"], ["84129.90", "0"], ["84129.55", "0"], ["84129.10", "0"], ["84128.80", "0"], ["84128.70", "0"], ["84128.50", "0"], ["84128.20", "0.000396"], ["84127.94", "0.000875"], ["84127.90", "0"], ["84127.60", "0"], ["84127.50", "0"], ["84127.48", "0"], ["84126.79", "0"], ["84126.60", "0"], ["84126.50", "0"], ["84125.90", "0"], ["84123.53", "0.007428"], ["84122.17", "0.017430"], ["84118.62", "0.007241"], ["84118.54", "0.007330"], ["84118.46", "0.007644"], ["84117.10", "0.008565"], ["84114.38", "0.003592"], ["84112.68", "0"], ["84111.90", "0.001171"], ["84111.69", "0"], ["84111.61", "0"], ["84111.52", "0"], ["84110.51", "0"], ["84108.90", "0.208446"], ["84106.00", "5.339380"], ["84098.90", "0"], ["84098.70", "0.000948"], ["84097.75", "0.071253"], ["84097.50", "4.524899"], ["84093.08", "0"], ["84092.63", "0"], ["84090.40", "0"], ["84089.00", "5.520376"], ["84087.60", "0"], ["84085.25", "0.057001"], ["84081.90", "0"], ["84080.50", "5.158384"], ["84073.40", "0"], ["84072.00", "5.429878"], ["84064.90", "0"], ["84063.50", "5.248882"], ["84060.16", "0"], ["84056.40", "0"], ["84055.00", "4.886891"], ["84053.15", "0"], ["84050.37", "0"], ["84047.90", "0"], ["84046.50", "5.067887"], ["84039.40", "0"], ["84038.00", "4.796393"], ["84030.90", "0"], ["84029.50", "5.610874"], ["84022.40", "0"], ["84021.00", "4.343903"], ["84013.90", "0"], ["84012.50", "4.162907"], ["84005.40", "0"], ["84004.00", "3.981911"], ["84000.00", "0.017169"], ["83996.90", "0"], ["83995.50", "4.615397"], ["83988.40", "0"], ["83987.00", "4.253405"], ["83979.90", "0"], ["83978.50", "4.072409"], ["83971.40", "0"], ["83970.00", "4.705895"], ["83962.90", "0"], ["83961.50", "4.977389"], ["83954.40", "0"], ["83953.00", "4.434401"], ["83945.90", "0"], ["83944.50", "3.891413"], ["83937.40", "0"], ["83853.50", "1.721524"], ["83826.37", "0"], ["83690.00", "0"], ["83689.78", "0"], ["83689.50", "0"], ["83688.89", "0"], ["83688.07", "0"], ["83687.50", "0"], ["83687.00", "0"], ["83686.11", "0"], ["83684.21", "0"], ["83683.67", "0"], ["83681.82", "0"], ["83680.67", "0"], ["83680.00", "0"], ["83679.44", "0"], ["83678.70", "0"], ["83678.41", "0"], ["83678.08", "0"], ["83677.42", "0"], ["83677.37", "0"], ["83676.47", "0"], ["83675.68", "0"], ["83675.62", "0"], ["83675.36", "0"], ["83675.20", "0"], ["83675.00", "0"], ["83674.70", "0"], ["83674.19", "0"], ["83674.00", "0"], ["83673.87", "0"], ["83673.58", "0"], ["83672.96", "0"], ["83672.50", "0"], ["83672.25", "0"], ["83672.00", "0"], ["83671.36", "0"], ["83670.59", "0"], ["83670.05", "0"]], "checksum": -1739126047, "ts": "1742560339488"}], "ts": 1742560339493}}
{"exchange": "BYBIT", "timestamp": 1742560339.540226, "message": {"topic": "orderbook.200.BTCUSDT", "ts": 1742560339520, "type": "delta", "data": {"s": "BTCUSDT", "b": [["84198.1", "0.521193"], ["84193.7", "0.094793"], ["84193.6", "0.315976"], ["84193.1", "0.000333"], ["84192.5", "0.177764"], ["84192.4", "0.172333"], ["84192", "0.003269"], ["84191.8", "0.310942"], ["84191.6", "0"], ["84191.4", "0.011914"], ["84190.8", "0.071494"], ["84189.8", "0.001466"], ["84189", "0.000518"], ["84188.8", "0.020342"], ["84188", "0.00009"], ["84187.7", "0.07146"], ["84187.2", "0"], ["84185.4", "0.064"], ["84185.2", "0.006466"], ["84184.7", "0.16965"], ["84184.2", "0.071306"], ["84184", "0.017133"], ["84183.6", "0.051269"], ["84183.1", "0"], ["84182.2", "0.044"], ["84181.8", "0.048"], ["84180.9", "0"], ["84180.4", "0.052"], ["84179.3", "0.001999"], ["84178.7", "0.095332"], ["84177.7", "0.003575"], ["84176.7", "0"], ["84176.1", "0.139143"], ["84175.6", "0.06"], ["84175.1", "0.29133"], ["84171.4", "0.185555"], ["84169.8", "0.07296"], ["84169.7", "0"], ["84169.1", "0"], ["84168", "0.234426"], ["84167.1", "0.001333"], ["84167", "0"], ["84165.7", "0"], ["84165.4", "0"], ["84165.2", "0.178161"], ["84162", "0.001466"], ["84161.2", "0"], ["84160.4", "0"], ["84159", "0"], ["84156.7", "0.014749"], ["84156.6", "0.000518"], ["84155.3", "0.0016"], ["84152.5", "0.05"], ["84152.4", "0.049553"], ["84152.2", "0.014046"], ["84147", "0"], ["84136.9", "0"], ["84136.8", "0"], ["84132.5", "0"], ["84123.3", "0"], ["84122.5", "0"], ["84121.8", "0"], ["84121.6", "0"], ["84121.2", "0"]], "a": [["84193.7", "0"], ["84194.5", "0"], ["84196.2", "0"], ["84196.3", "0"], ["84196.6", "0"], ["84197.3", "0"], ["84197.8", "0"], ["84198.2", "0.274207"], ["84201.4", "0"], ["84202.1", "0.041701"], ["84203.3", "0"], ["84204.4", "0.071289"], ["84204.9", "0.011839"], ["84205.3", "0.0002"], ["84206", "0.071288"], ["84207.4", "0"], ["84207.6", "0.143792"], ["84208", "0"], ["84208.9", "0.003293"], ["84209.9", "0.044886"], ["84210", "0.208628"], ["84211.6", "0.04"], ["84211.7", "0"], ["84212.1", "0.04"], ["84213.1", "0.003294"], ["84213.9", "0.04"], ["84215.4", "0.04"], ["84215.6", "0.04"], ["84216", "0"], ["84217", "0.04"], ["84222.1", "0.059399"], ["84222.2", "0.001466"], ["84222.4", "0"], ["84223", "0"], ["84227.3", "0.263862"], ["84229.2", "0"], ["84230", "0"], ["84231.6", "0"], ["84231.7", "0.254494"], ["84232.6", "0.551103"], ["84232.7", "0"], ["84233", "0.013"], ["84233.1", "0.012973"], ["84233.3", "0"], ["84233.6", "0.011876"], ["84234", "0.04"], ["84234.1", "0.04"], ["84236.2", "0.004576"], ["84237.2", "0.06188"], ["84239.7", "0.063758"], ["84245.4", "0.073289"], ["84248.3", "0.01404"], ["84263.1", "0.289793"], ["84270.6", "0.04"], ["84271.6", "0.171"], ["84272", "0"], ["84272.1", "0"], ["84272.3", "0"]], "u": 45286, "seq": 67552585505}, "cts": 1742560339515}}
{"exchange": "BITGET", "timestamp": 1742560339.727464, "message": {"action": "update", "arg": {"instType": "SPOT", "channel": "books", "instId": "BTCUSDT"}, "data": [{"asks": [["84174.00", "1.396699"], ["84174.95", "0.013150"], ["84182.71", "1.591631"], ["84183.00", "0.062760"], ["84184.92", "0.046747"], ["84189.40", "0.059306"], ["84194.31", "0.115343"], ["84206.74", "0.179074"], ["84210.46", "3.707925"], ["84213.16", "0.277412"], ["84216.40", "0.002534"], ["84218.40", "0.006669"], ["84220.40", "0.017550"], ["84222.40", "0.046183"], ["84224.40", "0.121534"], ["84226.40", "0.319827"], ["84228.40", "0.841651"], ["84230.40", "2.214871"], ["84232.40", "5.828608"], ["84233.60", "0.144990"], ["84234.00", "0.040710"], ["84234.90", "0"], ["84235.30", "0.007170"], ["84235.40", "0.938670"], ["84236.10", "0.069030"], ["84237.20", "0"], ["84238.10", "0.084600"], ["84238.80", "2.352750"], ["84239.20", "0"], ["84239.50", "0"], ["84239.93", "0.260003"], ["84241.40", "0.135000"], ["84241.90", "0.015000"], ["84242.30", "0.240000"], ["84242.40", "0.120000"], ["84242.60", "0.030000"], ["84245.60", "0"], ["84245.80", "0"], ["84245.90", "0"], ["84246.10", "0"], ["84274.50", "4.343903"], ["84283.00", "5.158384"], ["84291.50", "5.610874"], ["84300.00", "4.705895"], ["84317.00", "4.886891"], ["84325.50", "4.615397"], ["84334.00", "3.981911"], ["84342.50", "4.524899"], ["84351.00", "3.891413"], ["84359.50", "5.429878"], ["84368.00", "4.072409"], ["84376.50", "5.248882"], ["84385.00", "5.067887"], ["84393.50", "4.434401"], ["84402.00", "4.162907"], ["84410.50", "5.520376"], ["84427.50", "4.977389"], ["84436.00", "5.339380"], ["84573.83", "0"], ["84574.00", "0"], ["84574.47", "0"], ["84574.50", "0"], ["84574.67", "0"], ["84575.00", "0"], ["84577.11", "0"]], "bids": [["84173.99", "0.953968"], ["84172.17", "0.208288"], ["84169.77", "0.076530"], ["84169.76", "0"], ["84168.29", "0"], ["84166.10", "0.001498"], ["84165.70", "0.205243"], ["84165.21", "0"], ["84164.10", "0.003941"], ["84162.10", "0.010372"], ["84161.02", "0.065994"], ["84161.01", "0.061395"], ["84160.21", "0.005114"], ["84160.10", "0.027296"], ["84158.10", "0.071829"], ["84157.27", "0.209200"], ["84157.01", "0.172926"], ["84156.10", "0.189026"], ["84154.10", "0.497435"], ["84153.12", "0.023051"], ["84152.10", "1.309041"], ["84150.10", "3.444844"], ["84148.10", "9.065380"], ["84147.90", "0.085440"], ["84147.40", "0.178950"], ["84147.30", "0"], ["84147.20", "0.016170"], ["84147.14", "0.014886"], ["84147.10", "0.330840"], ["84145.90", "0.084810"], ["84144.70", "0.857610"], ["84144.40", "0"], ["84144.30", "0.073530"], ["84144.00", "0.480318"], ["84143.91", "0"], ["84143.20", "0.178140"], ["84142.90", "0"], ["84141.60", "0.528660"], ["84141.00", "1.355430"], ["84140.15", "2.994480"], ["84139.40", "0.192000"], ["84138.20", "1.279200"], ["84137.80", "1.068090"], ["84136.40", "0.180000"], ["84135.80", "0"], ["84135.50", "0.132000"], ["84135.20", "0.120000"], ["84133.30", "0.300000"], ["84133.00", "0.000032"], ["84130.91", "0.078561"], ["84127.91", "0"], ["84106.00", "4.343903"], ["84097.50", "4.253405"], ["84093.00", "0.000017"], ["84080.50", "5.248882"], ["84072.00", "4.886891"], ["84063.50", "4.162907"], ["84055.00", "3.981911"], ["84046.50", "4.977389"], ["84038.00", "5.158384"], ["84029.50", "4.072409"], ["84021.76", "0"], ["84021.00", "5.429878"], ["84012.50", "3.891413"], ["84004.00", "5.339380"], ["83995.50", "4.434401"], ["83987.00", "4.796393"], ["83978.50", "5.067887"], ["83970.00", "4.524899"], ["83961.50", "4.705895"], ["83953.00", "5.610874"], ["83944.50", "4.615397"], ["83692.52", "0"], ["83692.38", "0"], ["83692.31", "0"], ["83691.74", "0"], ["83690.84", "0"], ["83690.48", "0"]], "checksum": -1144963392, "ts": "1742560339690"}], "ts": 1742560339694}}
{"exchange": "BYBIT", "timestamp": 1742560339.740247, "message": {"topic": "orderbook.200.BTCUSDT", "ts": 1742560339719, "type": "delta", "data": {"s": "BTCUSDT", "b": [["84198.1", "0.721894"], ["84197", "0.063498"], ["84196.9", "0.071295"], ["84193.7", "0"], ["84193.6", "0.301124"], ["84192.5", "0.124988"], ["84192.4", "0.001333"], ["84189.7", "0.042185"], ["84189.2", "0.071302"], ["84187.7", "0.056611"], ["84187.2", "0.04"], ["84184.2", "0"], ["84183.7", "0.07087"], ["84180.5", "0.065912"], ["84178.7", "0"], ["84171.4", "0.025624"], ["84171.3", "0.002799"], ["84168", "0.235692"], ["84163.7", "0"], ["84162.5", "0"], ["84160.5", "0"], ["84156.7", "0"], ["84154.2", "0.027805"], ["84153", "0.05"], ["84152.9", "0.108952"], ["84152.5", "0"], ["84152.4", "0"], ["84152.3", "0.135529"], ["84149.5", "0"], ["84138.6", "0.017714"], ["84127.7", "19.525072"], ["84123.7", "0.235392"], ["84123.3", "0.001782"]], "a": [["84198.2", "0.174501"], ["84202.1", "0.015"], ["84206.6", "0.06446"], ["84206.9", "0.003648"], ["84209.9", "0.000333"], ["84210", "0.25167"], ["84210.4", "0.04"], ["84213.7", "0.04"], ["84215.4", "0.042067"], ["84216.8", "0.169311"], ["84217.8", "0.03564"], ["84217.9", "0.05"], ["84218.5", "0.05"], ["84219", "0.047114"], ["84222.6", "0.021429"], ["84227.3", "0.099807"], ["84233", "0"], ["84233.1", "0"], ["84233.5", "0.012973"], ["84233.6", "0.024849"], ["84234", "0"], ["84234.1", "0"], ["84234.5", "0.041333"], ["84234.6", "0.063755"], ["84237.1", "0.063454"], ["84240.2", "1.424499"], ["84242", "0.022853"], ["84245.5", "0"], ["84254.8", "2.561732"], ["84255.5", "0"], ["84256", "0"], ["84262.1", "0"], ["84271.1", "0"], ["84271.2", "0"], ["84271.3", "0"], ["84271.6", "0"]], "u": 45287, "seq": 67552585763}, "cts": 1742560339710}}
{"exchange": "BITGET", "timestamp": 1742560339.941283, "message": {"action": "update", "arg": {"instType": "SPOT", "channel": "books", "instId": "BTCUSDT"}, "data": [{"asks": [["84174.00", "1.491765"], ["84182.70", "0.540249"], ["84183.00", "0"], ["84216.40", "0.002102"], ["84218.40", "0.005534"], ["84220.40", "0.014329"], ["84222.40", "0.037708"], ["84223.76", "0.019526"], ["84224.40", "0.099230"], ["84226.40", "0.261133"], ["84228.40", "0.687191"], ["84230.40", "1.808397"], ["84232.40", "4.758940"], ["84233.40", "0.001050"], ["84233.60", "0"], ["84234.00", "0.373470"], ["84235.00", "0.066420"], ["84235.40", "0.174090"], ["84238.80", "0"], ["84240.60", "2.352690"], ["84240.80", "0.070620"], ["84243.90", "0.178110"], ["84246.81", "0.001810"], ["84257.15", "0.003620"], ["84274.49", "0.323890"], ["84274.50", "4.705895"], ["84283.00", "3.981911"], ["84291.50", "4.434401"], ["84300.00", "5.248882"], ["84308.50", "4.072409"], ["84317.00", "5.429878"], ["84325.50", "5.067887"], ["84334.00", "5.520376"], ["84342.50", "5.339380"], ["84359.50", "4.253405"], ["84368.00", "4.615397"], ["84376.50", "4.524899"], ["84385.00", "4.162907"], ["84393.50", "4.886891"], ["84402.00", "4.977389"], ["84410.50", "5.158384"], ["84427.50", "5.610874"], ["84436.00", "4.343903"], ["84570.51", "0"], ["84570.99", "0"], ["84571.43", "0"], ["84571.75", "0"], ["84571.82", "0"], ["84572.75", "0"], ["84573.59", "0"]], "bids": [["84173.99", "0.905063"], ["84172.18", "0.062486"], ["84171.67", "0.037116"], ["84169.78", "0.023267"], ["84169.77", "0"], ["84165.70", "0.139782"], ["84165.69", "0.418400"], ["84162.11", "0.014915"], ["84161.00", "0.041941"], ["84158.10", "0.072074"], ["84156.10", "0.189668"], ["84154.10", "0.499127"], ["84153.12", "1.214697"], ["84152.10", "1.313491"], ["84150.10", "3.456556"], ["84148.10", "9.096200"], ["84141.60", "0.978840"], ["84137.80", "1.224090"], ["84137.70", "0.144000"], ["84134.40", "0.120000"], ["84133.90", "0"], ["84133.30", "0"], ["84132.04", "0"], ["84130.91", "0"], ["84106.00", "5.339380"], ["84097.50", "4.524899"], ["84089.00", "4.886891"], ["84080.50", "4.615397"], ["84074.07", "0.001810"], ["84072.00", "4.162907"], ["84065.65", "0.003620"], ["84063.50", "4.343903"], ["84055.00", "4.072409"], ["84046.50", "4.796393"], ["84038.00", "3.981911"], ["84029.50", "4.253405"], ["84021.00", "5.610874"], ["84004.00", "4.434401"], ["83995.50", "5.248882"], ["83987.00", "4.977389"], ["83970.00", "4.705895"], ["83961.50", "5.158384"], ["83953.00", "5.520376"], ["83944.50", "5.429878"], ["83695.65", "0"], ["83695.63", "0"], ["83693.69", "0"]], "checksum": -9053546, "ts": "1742560339906"}], "ts": 1742560339910}}
{"exchange": "BYBIT", "timestamp": 1742560339.941662, "message": {"topic": "orderbook.200.BTCUSDT", "ts": 1742560339920, "type": "delta", "data": {"s": "BTCUSDT", "b": [["84198.1", "0.718405"], ["84197.9", "0.103788"], ["84197.8", "0.071294"], ["84197", "0"], ["84196.9", "0"], ["84188.8", "0.019942"], ["84188.2", "0.111318"], ["84187.7", "0.05047"], ["84184.1", "0.123413"], ["84182.1", "0.06"], ["84177.7", "0.177013"], ["84177.1", "0.225421"], ["84175.6", "0"], ["84170.7", "0.306761"], ["84170.1", "0.278785"], ["84167.7", "0"], ["84153.2", "19.525072"], ["84153", "0"], ["84152.8", "0.222019"], ["84146.2", "0.064269"], ["84140.9", "0.010994"], ["84140.8", "0.010994"], ["84139", "0.040332"], ["84137.4", "0.021988"], ["84137.3", "0.067259"], ["84132.2", "0.170793"], ["84127.7", "0"], ["84126.3", "0.003564"], ["84124.4", "0"], ["84124.2", "0"], ["84124.1", "0"], ["84123.9", "0"], ["84123.7", "0"], ["84123.3", "0"]], "a": [["84198.2", "0.103473"], ["84202.1", "0.01"], ["84206.6", "0.06946"], ["84210", "0.283286"], ["84212.7", "0.119488"], ["84215.5", "0.161995"], ["84216.5", "0"], ["84217", "0.164646"], ["84223.2", "0.169143"], ["84224", "0.179894"], ["84230.2", "0.298435"], ["84231", "0.312714"], ["84233.5", "0"], ["84233.7", "0.012973"], ["84234.5", "0.001333"], ["84234.7", "0.158793"], ["84245.4", "0.001466"], ["84252", "2.561732"], ["84254.8", "0"], ["84269.3", "0"], ["84270.6", "0"], ["84270.9", "0"], ["84271", "0"]], "u": 45288, "seq": 67552585943}, "cts": 1742560339909}}
{"exchange": "BITGET", "timestamp": 1742560340.13787, "message": {"action": "update", "arg": {"instType": "SPOT", "channel": "books", "instId": "BTCUSDT"}, "data": [{"asks": [["84174.01", "0"], ["84216.40", "0.001287"], ["84218.40", "0.003388"], ["84220.40", "0.008914"], ["84222.40", "0.023458"], ["84224.40", "0.061732"], ["84226.40", "0.162453"], ["84228.40", "0.427508"], ["84230.40", "1.125020"], ["84232.40", "2.960581"], ["84234.00", "0"], ["84235.00", "0.066630"], ["84235.40", "0.497340"], ["84235.70", "1.008090"], ["84244.43", "0.209200"], ["84274.50", "5.610874"], ["84283.00", "5.339380"], ["84291.50", "4.796393"], ["84300.00", "4.886891"], ["84308.50", "5.248882"], ["84317.00", "5.067887"], ["84325.50", "4.072409"], ["84334.00", "4.253405"], ["84342.50", "3.981911"], ["84351.00", "4.615397"], ["84359.50", "4.705895"], ["84368.00", "5.520376"], ["84376.50", "3.891413"], ["84385.00", "4.343903"], ["84393.50", "5.158384"], ["84402.00", "4.524899"], ["84410.50", "5.429878"], ["84419.00", "4.977389"], ["84427.50", "4.162907"], ["84436.00", "4.434401"]], "bids": [["84173.99", "0.918468"], ["84169.78", "0"], ["84157.28", "0.270372"], ["84157.01", "0"], ["84148.11", "0.982901"], ["84145.02", "0"], ["84143.20", "0"], ["84140.33", "0.713094"], ["84139.91", "0.049778"], ["84114.71", "0"], ["84106.00", "4.796393"], ["84097.50", "3.981911"], ["84089.00", "5.158384"], ["84080.50", "5.429878"], ["84072.00", "4.705895"], ["84063.50", "4.886891"], ["84055.00", "4.253405"], ["84046.50", "4.977389"], ["84038.00", "5.520376"], ["84029.50", "4.615397"], ["84021.00", "4.072409"], ["84012.50", "5.610874"], ["83995.50", "4.524899"], ["83987.00", "5.067887"], ["83978.50", "3.891413"], ["83970.00", "4.343903"], ["83961.50", "5.339380"], ["83953.00", "5.248882"], ["83944.50", "4.162907"], ["83695.65", "0.003535"], ["83695.63", "0.000011"]], "checksum": -1200244409, "ts": "1742560340107"}], "ts": 1742560340112}}
{"exchange": "BYBIT", "timestamp": 1742560340.140451, "message": {"topic": "orderbook.200.BTCUSDT", "ts": 1742560340119, "type": "delta", "data": {"s": "BTCUSDT", "b": [["84189.7", "0.052185"], ["84188.2", "0.001333"], ["84184.1", "0"], ["84184", "0.007133"], ["84180.5", "0.160572"], ["84177.7", "0.003575"], ["84177.1", "0.056"], ["84173.3", "0.02365"], ["84171.4", "0.196731"], ["84170.7", "0"], ["84170.1", "0"], ["84152.3", "0.135544"], ["84124.9", "0"], ["84124.4", "0.059399"], ["84124.2", "0.000518"], ["84124.1", "0.00594"]], "a": [["84199", "0.024152"], ["84211.1", "0.05892"], ["84212.7", "0"], ["84217", "0.04"], ["84217.8", "0"], ["84217.9", "0.08564"], ["84220.5", "0.124706"], ["84223.2", "0"], ["84224", "0"], ["84227.3", "0.270576"], ["84230.2", "0"], ["84231", "0.000333"], ["84233.6", "0.011876"], ["84233.7", "0"], ["84233.9", "0.012987"], ["84234", "0.012987"], ["84234.6", "0.023755"], ["84234.7", "0.118793"], ["84234.9", "0.04"], ["84235", "0.04009"], ["84237.1", "0"], ["84239.7", "0.489994"], ["84242.7", "0.063454"]], "u": 45289, "seq": 67552586070}, "cts": 1742560340113}}
{"exchange": "BYBIT", "timestamp": 1742560340.340873, "message": {"topic": "orderbook.200.BTCUSDT", "ts": 1742560340320, "type": "delta", "data": {"s": "BTCUSDT", "b": [["84198.1", "0.724546"], ["84190.8", "0"], ["84188.9", "0.159651"], ["84188", "0.109633"], ["84187.7", "0.170948"], ["84183.9", "0.129423"], ["84180.5", "0.065912"], ["84177.9", "0.171201"], ["84177.5", "0.174682"], ["84176.9", "0.163364"], ["84173.3", "0.027201"], ["84171.4", "0.025624"], ["84170.5", "0.305558"], ["84169.9", "0.281281"], ["84168.8", "0.292128"], ["84155", "0.128335"], ["84154.3", "6.03141"], ["84153", "0.05"], ["84152.8", "0.172466"], ["84150", "2.380085"], ["84125", "0.001466"], ["84124.8", "0"], ["84124.7", "0"], ["84124.6", "0"], ["84124.4", "0"], ["84124.2", "0"], ["84124.1", "0"]], "a": [["84202.1", "0"], ["84206.6", "0.07946"], ["84210", "0.329405"], ["84212.5", "0.11501"], ["84212.9", "0.112463"], ["84216.8", "0.283052"], ["84222.6", "0.035004"], ["84222.7", "0.163111"], ["84223", "0.181836"], ["84223.8", "0.18494"], ["84227.3", "0.099807"], ["84230", "0.278015"], ["84230.8", "0.311375"], ["84231.8", "0.30451"], ["84267.6", "0"], ["84267.8", "0"], ["84267.9", "0"], ["84268.2", "0"], ["84268.6", "0"], ["84268.9", "0"]], "u": 45290, "seq": 67552586163}, "cts": 1742560340316}}
{"exchange": "BITGET", "timestamp": 1742560340.342581, "message": {"action": "update", "arg": {"instType": "SPOT", "channel": "books", "instId": "BTCUSDT"}, "data": [{"asks": [["84210.45", "0.601302"], ["84230.40", "1.124908"], ["84232.40", "2.960283"], ["84232.90", "0.001860"], ["84233.30", "0.391680"], ["84235.00", "0.307020"], ["84236.90", "0.066420"], ["84243.90", "0"], ["84274.49", "0"], ["84274.50", "3.981911"], ["84283.00", "4.162907"], ["84291.50", "4.886891"], ["84300.00", "5.067887"], ["84308.50", "4.434401"], ["84317.00", "4.705895"], ["84325.50", "4.343903"], ["84342.50", "5.158384"], ["84351.00", "4.072409"], ["84359.50", "4.524899"], ["84376.50", "5.339380"], ["84385.00", "4.977389"], ["84393.50", "5.610874"], ["84402.00", "4.615397"], ["84410.50", "4.796393"], ["84419.00", "3.891413"], ["84427.50", "5.248882"], ["84436.00", "5.429878"], ["84569.23", "0"]], "bids": [["84173.99", "0.917190"], ["84171.67", "0"], ["84152.10", "1.313674"], ["84150.10", "3.457036"], ["84148.10", "9.097465"], ["84144.50", "0.022770"], ["84141.60", "1.513500"], ["84138.20", "0.922860"], ["84106.00", "4.524899"], ["84097.50", "4.343903"], ["84094.00", "0.000032"], ["84089.00", "4.162907"], ["84080.50", "5.248882"], ["84072.00", "5.067887"], ["84063.50", "5.610874"], ["84055.00", "4.615397"], ["84046.50", "5.429878"], ["84038.00", "4.434401"], ["84029.50", "4.796393"], ["84021.00", "3.981911"], ["84012.50", "4.072409"], ["84004.00", "5.339380"], ["83995.50", "4.705895"], ["83987.00", "5.520376"], ["83970.00", "5.158384"], ["83961.50", "4.977389"], ["83953.00", "4.253405"], ["83944.50", "4.886891"]], "checksum": 1646843399, "ts": "1742560340306"}], "ts": 1742560340310}}
{"exchange": "BITGET", "timestamp": 1742560340.540042, "message": {"action": "update", "arg": {"instType": "SPOT", "channel": "books", "instId": "BTCUSDT"}, "data": [{"asks": [["84174.00", "1.590498"], ["84213.16", "0"], ["84230.40", "1.124759"], ["84232.40", "2.959892"], ["84233.30", "0.511590"], ["84233.40", "0"], ["84235.00", "0"], ["84236.60", "0.030000"], ["84236.90", "0.195330"], ["84239.00", "0.066000"], ["84274.50", "4.615397"], ["84283.00", "5.158384"], ["84291.50", "5.248882"], ["84300.00", "5.610874"], ["84308.50", "4.162907"], ["84317.00", "4.434401"], ["84342.50", "3.981911"], ["84351.00", "4.796393"], ["84359.50", "5.067887"], ["84368.00", "5.429878"], ["84376.50", "4.977389"], ["84385.00", "4.705895"], ["84393.50", "5.339380"], ["84402.00", "3.891413"], ["84410.50", "4.072409"], ["84419.00", "5.520376"], ["84427.50", "4.524899"], ["84436.00", "4.886891"], ["84569.23", "0.000009"]], "bids": [["84171.75", "0.037116"], ["84165.71", "0.111790"], ["84165.70", "0"], ["84148.75", "0.247262"], ["84144.00", "0.232968"], ["84139.70", "0.009000"], ["84138.60", "0.007350"], ["84136.20", "0"], ["84106.00", "4.253405"], ["84089.00", "5.158384"], ["84080.50", "4.977389"], ["84072.00", "5.339380"], ["84063.50", "4.072409"], ["84055.00", "4.162907"], ["84046.50", "4.434401"], ["84038.00", "4.705895"], ["84029.50", "4.615397"], ["84021.00", "5.067887"], ["84012.50", "4.886891"], ["84004.00", "5.610874"], ["83995.50", "3.981911"], ["83987.00", "4.796393"], ["83978.50", "5.520376"], ["83970.00", "3.891413"], ["83961.50", "4.524899"], ["83953.00", "5.248882"], ["83944.50", "5.429878"], ["83697.23", "0"], ["83695.65", "0"], ["83695.63", "0"]], "checksum": -1811044782, "ts": "1742560340509"}], "ts": 1742560340512}}
{"exchange": "BYBIT", "timestamp": 1742560340.540203, "message": {"topic": "orderbook.200.BTCUSDT", "ts": 1742560340519, "type": "delta", "data": {"s": "BTCUSDT", "b": [["84189.7", "0.057185"], ["84185.2", "0.001466"], ["84180.5", "0.210489"], ["84153", "0"], ["84152.8", "0.222019"], ["84135.6", "0.052"]], "a": [["84222.6", "0.192273"], ["84233", "0.000118"], ["84266.5", "0"]], "u": 45291, "seq": 67552586253}, "cts": 1742560340516}}
{"exchange": "BITGET", "timestamp": 1742560340.743062, "message": {"action": "update", "arg": {"instType": "SPOT", "channel": "books", "instId": "BTCUSDT"}, "data": [{"asks": [["84206.74", "0"], ["84226.40", "0.162348"], ["84228.40", "0.427231"], ["84230.40", "1.124293"], ["84232.40", "2.958665"], ["84274.50", "5.339380"], ["84283.00", "5.610874"], ["84291.50", "4.615397"], ["84300.00", "4.977389"], ["84308.50", "5.067887"], ["84317.00", "4.343903"], ["84325.50", "3.891413"], ["84334.00", "4.886891"], ["84342.50", "4.524899"], ["84351.00", "5.248882"], ["84359.50", "4.705895"], ["84368.00", "4.253405"], ["84376.50", "4.072409"], ["84385.00", "5.158384"], ["84393.50", "4.434401"], ["84402.00", "4.162907"], ["84410.50", "5.429878"], ["84419.00", "4.796393"], ["84427.50", "3.981911"], ["84436.00", "5.520376"], ["84570.51", "0.000170"]], "bids": [["84134.30", "0"], ["84106.00", "4.977389"], ["84097.50", "5.610874"], ["84094.00", "0.000015"], ["84089.00", "3.891413"], ["84080.50", "3.981911"], ["84072.00", "5.158384"], ["84063.50", "4.886891"], ["84055.00", "4.434401"], ["84046.50", "4.162907"], ["84038.00", "4.796393"], ["84029.50", "5.248882"], ["84021.00", "4.705895"], ["84012.50", "4.072409"], ["84004.00", "5.520376"], ["83995.50", "5.429878"], ["83987.00", "5.339380"], ["83978.50", "4.343903"], ["83970.00", "4.253405"], ["83961.50", "5.067887"], ["83953.00", "4.524899"], ["83944.50", "4.615397"], ["83697.23", "0.000095"]], "checksum": -1811044782, "ts": "1742560340710"}], "ts": 1742560340714}}
{"exchange": "BYBIT", "timestamp": 1742560340.743315, "message": {"topic": "orderbook.200.BTCUSDT", "ts": 1742560340720, "type": "delta", "data": {"s": "BTCUSDT", "b": [["84171.4", "0.284602"], ["84152.3", "0.135553"]], "a": [["84218.7", "0.25609"]], "u": 45292, "seq": 67552586303}, "cts": 1742560340693}}
{"exchange": "BYBIT", "timestamp": 1742560340.987187, "message": {"topic": "orderbook.200.BTCUSDT", "ts": 1742560340919, "type": "delta", "data": {"s": "BTCUSDT", "b": [["84188.9", "0.108339"], ["84188", "0.00009"], ["84187.7", "0.05047"], ["84183.9", "0.019942"], ["84177.9", "0"], ["84177.5", "0"], ["84176.9", "0"], ["84170.5", "0.000518"], ["84169.9", "0"], ["84168.8", "0"], ["84157.8", "0.039637"], ["84157.7", "0.039638"], ["84153", "0.05"], ["84152.8", "0.172466"], ["84141.7", "0"], ["84141.6", "0"], ["84124.7", "0.003259"], ["84124.6", "0.02112"], ["84124.4", "0.059399"], ["84124.2", "0.000518"]], "a": [["84199", "0"], ["84207.6", "0.102691"], ["84210", "0.274304"], ["84212.5", "0"], ["84212.9", "0"], ["84216.8", "0.169311"], ["84222.7", "0"], ["84223", "0"], ["84223.8", "0"], ["84230", "0"], ["84230.8", "0"], ["84231.8", "0.003564"], ["84234.5", "0.041333"], ["84234.6", "0.063755"], ["84234.9", "0"], ["84235", "0.00009"], ["84266.5", "0.0045"], ["84267.6", "0.01183"], ["84267.8", "0.00052"], ["84267.9", "0.003292"], ["84268.2", "0.001333"], ["84268.6", "0.001556"], ["84268.9", "0.000333"], ["84269.3", "0.003"], ["84270.6", "0.04"]], "u": 45293, "seq": 67552586395}, "cts": 1742560340916}}
{"exchange": "BITGET", "timestamp": 1742560340.987421, "message": {"action": "update", "arg": {"instType": "SPOT", "channel": "books", "instId": "BTCUSDT"}, "data": [{"asks": [["84174.00", "1.596398"], ["84203.79", "0.183712"], ["84230.40", "1.124102"], ["84232.40", "2.958163"], ["84274.50", "5.248882"], ["84283.00", "5.158384"], ["84291.50", "3.891413"], ["84300.00", "5.067887"], ["84308.50", "4.705895"], ["84317.00", "4.886891"], ["84325.50", "5.610874"], ["84334.00", "4.343903"], ["84342.50", "5.429878"], ["84351.00", "5.339380"], ["84359.50", "4.796393"], ["84368.00", "4.072409"], ["84376.50", "4.162907"], ["84385.00", "4.524899"], ["84393.50", "4.253405"], ["84402.00", "3.981911"], ["84410.50", "5.520376"], ["84419.00", "4.434401"], ["84427.50", "4.615397"], ["84436.00", "4.977389"], ["84570.51", "0"]], "bids": [["84171.83", "0.037116"], ["84171.75", "0"], ["84166.10", "0.001681"], ["84164.10", "0.004423"], ["84162.10", "0.011639"], ["84160.10", "0.030629"], ["84158.10", "0.080602"], ["84156.10", "0.212111"], ["84154.10", "0.558188"], ["84152.10", "1.468915"], ["84150.10", "3.865567"], ["84148.10", "10.172545"], ["84106.00", "4.705895"], ["84097.50", "4.615397"], ["84092.00", "0"], ["84089.00", "4.253405"], ["84080.50", "4.886891"], ["84072.00", "4.162907"], ["84063.50", "4.977389"], ["84046.50", "4.524899"], ["84038.00", "4.072409"], ["84021.00", "3.891413"], ["84012.50", "4.796393"], ["84004.00", "5.067887"], ["83995.50", "5.610874"], ["83978.50", "5.520376"], ["83970.00", "3.981911"], ["83961.50", "5.429878"], ["83953.00", "5.158384"], ["83944.50", "4.343903"], ["83695.65", "0.003535"]], "checksum": -1784363549, "ts": "1742560340918"}], "ts": 1742560340922}}
{"exchange": "BYBIT", "timestamp": 1742560341.140095, "message": {"topic": "orderbook.200.BTCUSDT", "ts": 1742560341120, "type": "delta", "data": {"s": "BTCUSDT", "b": [["84180.5", "0.065912"], ["84171.4", "0.025624"], ["84156.8", "0.013"], ["84156.7", "0.012882"], ["84153", "0"], ["84152.8", "0.222019"], ["84152.3", "0.135564"], ["84140.7", "0"], ["84140.6", "0"], ["84124.8", "0.171"]], "a": [["84222.6", "0.037641"], ["84233.4", "0.013"], ["84233.5", "0.012988"], ["84233.9", "0"], ["84234", "0"], ["84234.4", "0.04"], ["84234.6", "0.023755"], ["84270.6", "0"]], "u": 45294, "seq": 67552586505}, "cts": 1742560341116}}
{"exchange": "BITGET", "timestamp": 1742560341.15884, "message": {"action": "update", "arg": {"instType": "SPOT", "channel": "books", "instId": "BTCUSDT"}, "data": [{"asks": [["84190.04", "0"], ["84195.52", "0.006356"], ["84232.40", "2.958032"], ["84233.30", "0.780720"], ["84234.50", "0.947160"], ["84235.40", "0.296460"], ["84235.70", "0"], ["84238.00", "0.052350"], ["84274.50", "4.615397"], ["84283.00", "4.886891"], ["84291.50", "5.158384"], ["84300.00", "5.520376"], ["84308.50", "5.248882"], ["84317.00", "4.072409"], ["84325.50", "4.977389"], ["84334.00", "4.253405"], ["84342.50", "4.524899"], ["84359.50", "4.434401"], ["84368.00", "4.796393"], ["84385.00", "3.981911"], ["84393.50", "4.705895"], ["84402.00", "4.343903"], ["84410.50", "5.429878"], ["84419.00", "3.891413"], ["84427.50", "5.610874"], ["84436.00", "5.067887"], ["84569.23", "0"]], "bids": [["84158.10", "0.080863"], ["84156.10", "0.212798"], ["84154.10", "0.559993"], ["84152.10", "1.473667"], ["84150.10", "3.878070"], ["84148.11", "0"], ["84148.10", "10.205448"], ["84145.55", "0.017081"], ["84143.84", "0.017328"], ["84140.05", "0"], ["84138.37", "0"], ["84106.00", "5.610874"], ["84097.50", "4.524899"], ["84089.00", "4.343903"], ["84080.50", "4.072409"], ["84072.00", "4.886891"], ["84063.50", "5.067887"], ["84055.00", "4.253405"], ["84046.50", "3.891413"], ["84038.00", "4.434401"], ["84029.50", "5.429878"], ["84021.00", "5.158384"], ["84012.50", "4.705895"], ["84004.00", "4.615397"], ["83995.50", "4.977389"], ["83970.00", "4.162907"], ["83961.50", "4.796393"], ["83953.00", "3.981911"], ["83944.50", "5.248882"], ["83695.63", "0.000011"]], "checksum": -589478266, "ts": "1742560341126"}], "ts": 1742560341130}}
{"exchange": "BYBIT", "timestamp": 1742560341.339774, "message": {"topic": "orderbook.200.BTCUSDT", "ts": 1742560341320, "type": "delta", "data": {"s": "BTCUSDT", "b": [["84178", "0.003552"], ["84173.3", "0.02365"], ["84157.9", "0.039506"], ["84124.4", "0"], ["84124.2", "0"]], "a": [], "u": 45295, "seq": 67552586568}, "cts": 1742560341316}}
{"exchange": "BITGET", "timestamp": 1742560341.35753, "message": {"action": "update", "arg": {"instType": "SPOT", "channel": "books", "instId": "BTCUSDT"}, "data": [{"asks": [["84174.00", "1.730878"], ["84174.01", "0.000493"], ["84233.30", "0.780990"], ["84238.00", "0"], ["84240.80", "0"], ["84283.00", "3.891413"], ["84308.50", "4.705895"], ["84317.00", "5.429878"], ["84325.50", "3.981911"], ["84334.00", "5.610874"], ["84342.50", "4.253405"], ["84351.00", "4.072409"], ["84359.50", "4.343903"], ["84368.00", "4.524899"], ["84385.00", "4.434401"], ["84393.50", "4.886891"], ["84402.00", "5.339380"], ["84410.50", "5.248882"], ["84419.00", "4.796393"], ["84427.50", "5.067887"], ["84436.00", "4.977389"], ["84569.23", "0.000009"]], "bids": [["84144.50", "0"], ["84143.10", "0.022710"], ["84122.88", "0.068008"], ["84106.00", "4.615397"], ["84097.50", "5.610874"], ["84092.00", "0.000017"], ["84089.00", "5.520376"], ["84080.50", "4.253405"], ["84072.00", "5.429878"], ["84063.50", "4.072409"], ["84055.00", "5.067887"], ["84046.50", "4.796393"], ["84038.00", "4.977389"], ["84029.50", "5.158384"], ["84021.00", "5.339380"], ["84012.50", "4.886891"], ["84004.00", "5.248882"], ["83995.50", "3.891413"], ["83987.00", "4.705895"], ["83978.50", "4.434401"], ["83961.50", "3.981911"], ["83953.00", "4.524899"], ["83944.50", "4.343903"], ["83695.65", "0"], ["83695.63", "0"]], "checksum": -1899795450, "ts": "1742560341328"}], "ts": 1742560341331}}
{"exchange": "BYBIT", "timestamp": 1742560341.539652, "message": {"topic": "orderbook.200.BTCUSDT", "ts": 1742560341520, "type": "delta", "data": {"s": "BTCUSDT", "b": [["84157.9", "0.075146"], ["84156.8", "0.012882"], ["84153", "0.05"], ["84152.8", "0.172466"], ["84137.9", "0"]], "a": [["84233.4", "0"], ["84233.6", "0.024864"], ["84234.4", "0"], ["84234.6", "0.063755"], ["84270.6", "0.04"], ["84270.9", "0.04"]], "u": 45296, "seq": 67552586613}, "cts": 1742560341506}}
{"exchange": "BITGET", "timestamp": 1742560341.575624, "message": {"action": "update", "arg": {"instType": "SPOT", "channel": "books", "instId": "BTCUSDT"}, "data": [{"asks": [["84185.62", "0"], ["84187.06", "0"], ["84187.71", "0"], ["84190.36", "0.119870"], ["84192.23", "0.035961"], ["84193.34", "0.006356"], ["84196.63", "0.117888"], ["84218.53", "0.010000"], ["84226.40", "0.162211"], ["84228.40", "0.426871"], ["84230.40", "1.123204"], ["84232.40", "2.955800"], ["84274.50", "3.891413"], ["84283.00", "4.705895"], ["84291.50", "5.429878"], ["84300.00", "4.434401"], ["84308.50", "5.067887"], ["84317.00", "4.615397"], ["84325.50", "4.524899"], ["84342.50", "5.158384"], ["84350.18", "0"], ["84359.50", "3.981911"], ["84368.00", "5.248882"], ["84385.00", "5.520376"], ["84393.50", "5.339380"], ["84402.00", "4.977389"], ["84410.50", "4.886891"], ["84419.00", "4.253405"], ["84427.50", "4.796393"], ["84436.00", "4.343903"], ["84569.23", "0"]], "bids": [["84171.90", "0.037116"], ["84171.83", "0"], ["84160.10", "0.030376"], ["84158.10", "0.079937"], ["84156.10", "0.210361"], ["84154.10", "0.553582"], ["84152.10", "1.456794"], ["84150.10", "3.833669"], ["84148.46", "0.083830"], ["84148.10", "10.088603"], ["84147.72", "0.005938"], ["84143.29", "0"], ["84142.09", "0"], ["84097.51", "0.844369"], ["84097.50", "4.253405"], ["84089.00", "3.981911"], ["84080.50", "5.067887"], ["84072.00", "4.977389"], ["84063.50", "4.705895"], ["84055.00", "4.524899"], ["84046.50", "4.162907"], ["84038.00", "5.339380"], ["84029.50", "4.072409"], ["84021.00", "4.343903"], ["84012.50", "3.891413"], ["84004.00", "5.429878"], ["83995.50", "4.434401"], ["83987.00", "5.610874"], ["83978.50", "5.248882"], ["83970.00", "5.520376"], ["83961.50", "4.796393"], ["83953.00", "4.886891"], ["83944.50", "5.158384"], ["83697.23", "0"]], "checksum": 62360459, "ts": "1742560341535"}], "ts": 1742560341538}}
{"exchange": "BYBIT", "timestamp": 1742560341.740657, "message": {"topic": "orderbook.200.BTCUSDT", "ts": 1742560341720, "type": "delta", "data": {"s": "BTCUSDT", "b": [["84178", "0"], ["84157.9", "0.115146"], ["84157.7", "0"], ["84124.4", "0.059399"], ["84124.2", "0.000518"]], "a": [], "u": 45297, "seq": 67552586645}, "cts": 1742560341715}}
{"exchange": "BITGET", "timestamp": 1742560341.779954, "message": {"action": "update", "arg": {"instType": "SPOT", "channel": "books", "instId": "BTCUSDT"}, "data": [{"asks": [["84184.92", "0"], ["84189.40", "0.085947"], ["84283.00", "4.977389"], ["84291.50", "5.520376"], ["84300.00", "4.705895"], ["84308.50", "4.796393"], ["84317.00", "4.162907"], ["84325.50", "5.339380"], ["84334.00", "4.253405"], ["84342.50", "4.434401"], ["84359.50", "4.524899"], ["84365.98", "0.173773"], ["84368.00", "5.067887"], ["84376.50", "5.429878"], ["84385.00", "5.248882"], ["84393.50", "4.615397"], ["84402.00", "5.610874"], ["84410.50", "4.343903"], ["84419.00", "5.158384"], ["84427.50", "4.886891"], ["84436.00", "3.981911"]], "bids": [["84173.99", "0.907190"], ["84106.00", "4.524899"], ["84097.50", "5.429878"], ["84089.00", "4.343903"], ["84080.50", "3.891413"], ["84063.50", "4.253405"], ["84055.00", "4.162907"], ["84046.50", "5.248882"], ["84038.00", "3.981911"], ["84029.50", "4.886891"], ["84021.00", "5.067887"], ["84012.50", "5.610874"], ["84004.00", "4.072409"], ["83995.50", "4.796393"], ["83987.00", "5.339380"], ["83978.50", "4.615397"], ["83970.00", "4.705895"], ["83961.50", "5.158384"], ["83953.00", "4.434401"], ["83944.50", "5.520376"]], "checksum": 564040283, "ts": "1742560341738"}], "ts": 1742560341747}}
{"exchange": "BYBIT", "timestamp": 1742560341.939087, "message": {"topic": "orderbook.200.BTCUSDT", "ts": 1742560341919, "type": "delta", "data": {"s": "BTCUSDT", "b": [["84198.1", "0.725946"], ["84192.5", "0.214087"], ["84192.2", "0.071494"], ["84191.3", "0.0713"], ["84189.2", "0"], ["84181", "0.003552"], ["84179.3", "0"], ["84177.7", "0"], ["84176.2", "0.000716"], ["84157.9", "0.03564"], ["84157.7", "0.039638"], ["84154.2", "0.003259"], ["84153.2", "0"], ["84153", "0"], ["84152.8", "0.222019"], ["84124.1", "0.00594"]], "a": [["84198.2", "0.028972"], ["84200.8", "0.072625"], ["84204.4", "0"], ["84206", "0"], ["84209.7", "0.071284"], ["84216.8", "0.050518"], ["84217.9", "0.05"], ["84220.3", "0"], ["84222.1", "0"], ["84231.4", "0.54158"], ["84233.5", "0"], ["84233.6", "0.011876"], ["84234.5", "0.001333"], ["84234.6", "0.023755"], ["84235.2", "0.013333"], ["84235.3", "0.012988"], ["84236.2", "0.044576"], ["84236.3", "0.04"], ["84242", "0"], ["84252", "0"], ["84257.6", "2.561732"], ["84271", "0.237586"], ["84271.1", "0.000146"], ["84271.2", "0.12"]], "u": 45298, "seq": 67552586807}, "cts": 1742560341917}}
{"exchange": "BITGET", "timestamp": 1742560342.035832, "message": {"action": "update", "arg": {"instType": "SPOT", "channel": "books", "instId": "BTCUSDT"}, "data": [{"asks": [["84174.00", "1.299539"], ["84174.95", "0"], ["84189.20", "0"], ["84189.41", "0"], ["84190.45", "0"], ["84190.63", "0"], ["84190.86", "0"], ["84191.02", "0"], ["84195.65", "0"], ["84196.64", "0"], ["84199.72", "0"], ["84213.17", "0"], ["84233.30", "0.391950"], ["84274.50", "5.067887"], ["84283.00", "4.615397"], ["84291.50", "4.977389"], ["84300.00", "4.253405"], ["84308.50", "4.072409"], ["84317.00", "4.434401"], ["84325.50", "4.886891"], ["84334.00", "4.343903"], ["84342.50", "3.891413"], ["84351.00", "4.162907"], ["84359.50", "5.429878"], ["84368.00", "5.610874"], ["84376.50", "4.705895"], ["84385.00", "5.339380"], ["84393.50", "5.520376"], ["84402.00", "4.524899"], ["84410.50", "4.796393"], ["84419.00", "3.981911"], ["84427.50", "5.158384"], ["84436.00", "5.248882"], ["84569.23", "0.000009"], ["84570.51", "0.000170"], ["84570.99", "0.000053"], ["84571.43", "0.000124"], ["84571.75", "0.001273"], ["84571.82", "0.000046"], ["84572.75", "0.000009"], ["84573.59", "0.000177"], ["84573.83", "0.000215"], ["84574.00", "0.508335"], ["84574.47", "0.000349"]], "bids": [["84173.99", "1.150906"], ["84171.90", "0"], ["84161.53", "0"], ["84161.01", "0.051675"], ["84144.00", "0.209200"], ["84140.55", "0"], ["84140.15", "0"], ["84139.79", "0"], ["84139.75", "0"], ["84139.54", "0"], ["84139.29", "0"], ["84139.20", "0"], ["84138.30", "0"], ["84136.38", "0"], ["84134.55", "0"], ["84128.20", "0"], ["84117.10", "0"], ["84108.90", "0"], ["84106.00", "5.429878"], ["84098.70", "0"], ["84097.50", "3.981911"], ["84089.00", "4.072409"], ["84080.50", "4.434401"], ["84072.00", "4.162907"], ["84063.50", "4.524899"], ["84055.00", "5.520376"], ["84046.50", "5.067887"], ["84038.00", "4.886891"], ["84029.50", "4.796393"], ["84021.00", "4.705895"], ["84012.50", "5.158384"], ["84004.00", "5.248882"], ["83995.50", "4.615397"], ["83987.00", "4.253405"], ["83978.50", "5.339380"], ["83970.00", "4.343903"], ["83961.50", "5.610874"], ["83953.00", "4.977389"], ["83944.50", "3.891413"], ["83697.23", "0.000095"], ["83695.65", "0.003535"], ["83695.63", "0.000011"], ["83693.69", "0.000061"], ["83692.52", "0.000066"], ["83692.38", "0.000007"], ["83692.31", "0.000031"], ["83691.74", "0.000653"], ["83690.84", "0.000162"], ["83690.48", "0.000248"], ["83690.00", "0.000013"], ["83689.78", "0.001684"], ["83689.50", "0.000113"], ["83688.89", "0.000009"], ["83688.07", "0.000072"], ["83687.50", "0.006969"]], "checksum": 1547841186, "ts": "1742560341938"}], "ts": 1742560341942}}
{"exchange": "BYBIT", "timestamp": 1742560342.139825, "message": {"topic": "orderbook.200.BTCUSDT", "ts": 1742560342119, "type": "delta", "data": {"s": "BTCUSDT", "b": [["84199", "1.178775"], ["84198.3", "0.094288"], ["84198.2", "0.1"], ["84198.1", "0.227617"], ["84197.9", "0"], ["84197.8", "0"], ["84193.7", "0.000518"], ["84193.6", "0.030124"], ["84193.3", "0.071298"], ["84192.6", "0.192719"], ["84192.5", "0.089099"], ["84190.6", "0.015"], ["84189.7", "0.042185"], ["84188.9", "0.000333"], ["84187.8", "0.105477"], ["84187.1", "0"], ["84186.9", "0.001956"], ["84181", "0"], ["84172.3", "0.118793"], ["84171.9", "0.004704"], ["84157.8", "0"], ["84157.6", "0.039638"], ["84156.8", "0"], ["84156.6", "0.0134"], ["84156", "0"], ["84155", "0"], ["84154.3", "0.124581"], ["84152.9", "0.059399"], ["84152.7", "0.049553"], ["84137.9", "0.023753"], ["84127.2", "0.235392"], ["84124.8", "0"], ["84124.7", "0"], ["84124.6", "0"], ["84124.4", "0"], ["84124.2", "0"], ["84124.1", "0"]], "a": [["84198.2", "0"], ["84198.3", "0"], ["84199.1", "0.004435"], ["84200.8", "0.001333"], ["84206.4", "0.000296"], ["84206.6", "0.06446"], ["84207.5", "0.015297"], ["84207.6", "0.000518"], ["84208.2", "0"], ["84209.7", "0"], ["84210", "0.055106"], ["84210.4", "0"], ["84210.6", "0"], ["84211.5", "0.071283"], ["84211.6", "0"], ["84212.1", "0"], ["84213.5", "0"], ["84213.7", "0"], ["84213.9", "0"], ["84214.9", "0"], ["84215.5", "0.115665"], ["84215.6", "0"], ["84217", "0"], ["84217.1", "0.04"], ["84218.5", "0"], ["84218.7", "0.082933"], ["84218.9", "0.04"], ["84220.5", "0.003833"], ["84222.2", "0.041466"], ["84223.9", "0.04"], ["84228.6", "0.04422"], ["84231.3", "0.406031"], ["84231.7", "0"], ["84235.2", "0.000333"], ["84235.3", "0"], ["84236.2", "0.004576"], ["84236.3", "0"], ["84237.9", "0.013603"], ["84238", "0.012988"], ["84238.9", "0.04"], ["84239", "0.04"], ["84257.6", "0"], ["84260.1", "0"], ["84263.3", "2.562085"], ["84271.3", "0.12"], ["84272.1", "0.003292"], ["84272.3", "0.05728"], ["84272.4", "0.001853"], ["84273.1", "0.000333"], ["84273.2", "0.001466"], ["84274.2", "0.04"], ["84274.5", "0.059399"], ["84275.5", "0.04"]], "u": 45299, "seq": 67552587224}, "cts": 1742560342116}}
