{"topic": "orderbook.200.BTCUSDT", "ts": 1742560772320, "type": "snapshot", "data": {"s": "BTCUSDT", "b": [["83909.3", "0.849512"], ["83909.1", "0.123817"], ["83908.9", "0.222326"], ["83906.5", "0.1"], ["83906.3", "0.00008"], ["83906.2", "0.221"], ["83904.8", "0.003851"], ["83903.2", "0.001466"], ["83903.1", "0.000333"], ["83903", "0.089099"], ["83902.8", "0.0031"], ["83902.4", "0.001845"], ["83902.1", "0.014916"], ["83900.9", "0.015"], ["83900.8", "0.307617"], ["83900.7", "0.122138"], ["83900.6", "0.029247"], ["83900.4", "0.019889"], ["83900", "0.550456"], ["83899.5", "0.056117"], ["83898.9", "0.000333"], ["83898.6", "0.001466"], ["83898.2", "0.001333"], ["83897.9", "0.026531"], ["83897.8", "0.000518"], ["83897.6", "0.0002"], ["83897.3", "0.140268"], ["83897", "0.04"], ["83896.8", "0.044"], ["83896.4", "0.005769"], ["83895.8", "0.171"], ["83895.4", "0.056"], ["83895.1", "0.04"], ["83894.7", "0.000333"], ["83894.6", "0.12007"], ["83894.1", "0.024"], ["83894", "0.002889"], ["83893.7", "0.003259"], ["83893.6", "0.188572"], ["83893.4", "0.044358"], ["83893.2", "0.000518"], ["83892.6", "0.525501"], ["83891.7", "0.044"], ["83891.3", "0.009"], ["83890.9", "0.00625"], ["83890.8", "0.048"], ["83890.5", "0.000333"], ["83890.4", "0.044"], ["83890.2", "0.00253"], ["83890.1", "0.048"], ["83890", "0.0002"], ["83889.8", "0.001333"], ["83889.5", "0.003259"], ["83889.4", "0.001466"], ["83889.3", "0.254582"], ["83889.2", "0.119143"], ["83889", "0.100314"], ["83888.9", "0.052"], ["83888.8", "0.000445"], ["83888.7", "0.003614"], ["83888.6", "0.000518"], ["83888.5", "0.089099"], ["83888.3", "0.004037"], ["83887.4", "0.171"], ["83886.6", "0.021653"], ["83886.3", "0.000333"], ["83886.1", "0.709671"], ["83886", "0.568474"], ["83885.8", "0.023782"], ["83885.6", "0.001423"], ["83885.3", "0.003259"], ["83885", "1.500332"], ["83884.8", "0.001466"], ["83884", "0.000518"], ["83883.5", "0.000657"], ["83883.2", "0.121606"], ["83882.2", "0.000333"], ["83881.8", "0.005871"], ["83881.4", "0.001333"], ["83881.1", "0.003259"], ["83880.4", "0.059399"], ["83880.3", "0.139111"], ["83880.2", "0.119143"], ["83880.1", "0.001466"], ["83880", "0.057502"], ["83879.4", "0.000518"], ["83879", "0.171"], ["83878.6", "0.113502"], ["83878.3", "0.000572"], ["83878", "0.000333"], ["83877.2", "0.001423"], ["83876.9", "0.003259"], ["83876.8", "0.079084"], ["83876.5", "0.0045"], ["83875.5", "0.001466"], ["83875", "0.000436"], ["83874.9", "0.001071"], ["83874.8", "0.119143"], ["83874.7", "0.000518"], ["83874.3", "0.089099"], ["83874.1", "0.0016"], ["83873.8", "0.000333"], ["83873.7", "0.013"], ["83873.6", "0.01288"], ["83873.2", "0.000147"], ["83873.1", "0.001333"], ["83872.7", "0.003259"], ["83871.5", "0.000083"], ["83871.3", "0.001739"], ["83870.9", "0.015222"], ["83870.6", "0.171"], ["83870.1", "0.000518"], ["83869.6", "0.000333"], ["83869.3", "0.099459"], ["83869.2", "0.238185"], ["83869.1", "0.059399"], ["83869", "0.000118"], ["83868.9", "0.001333"], ["83868.8", "0.00009"], ["83868.7", "0.001367"], ["83868.5", "0.003259"], ["83867.6", "0.002134"], ["83866.5", "0.000468"], ["83866.3", "0.001466"], ["83865.5", "0.000518"], ["83865.4", "0.000333"], ["83865.1", "0.490601"], ["83865", "1.420134"], ["83864.8", "0.128779"], ["83864.7", "0.002533"], ["83864.3", "0.003259"], ["83863.6", "0.134889"], ["83863.5", "0.000454"], ["83862.2", "0.171"], ["83861.9", "11.216018"], ["83861.7", "0.001466"], ["83861.3", "0.009"], ["83861.2", "0.000333"], ["83860.9", "0.000518"], ["83860.5", "0.001333"], ["83860.4", "0.00046"], ["83860.1", "0.653987"], ["83860", "1.501139"], ["83859.6", "0.000013"], ["83859.1", "0.238185"], ["83858.3", "0.015"], ["83857.9", "0.011926"], ["83857.4", "0.002639"], ["83857.1", "0.003056"], ["83857", "0.000333"], ["83856.3", "0.001851"], ["83855.9", "0.003259"], ["83855.1", "0.066613"], ["83855", "0.051004"], ["83854.5", "0.000022"], ["83854.2", "0.000016"], ["83853.8", "0.171"], ["83852.8", "0.000333"], ["83852.5", "0.001466"], ["83852.1", "0.001333"], ["83852", "0.00009"], ["83851.8", "0.321148"], ["83851.7", "0.063176"], ["83851.3", "0.00009"], ["83850.4", "0.023837"], ["83850.3", "0.000059"], ["83850.2", "0.005959"], ["83850", "0.080757"], ["83849.7", "3.398878"], ["83849.5", "0.00093"], ["83849.2", "0.000358"], ["83849", "0.238185"], ["83848.6", "0.000333"], ["83848", "0.001034"], ["83847.9", "0.002799"], ["83847.8", "0.018111"], ["83847.6", "0.003259"], ["83847.3", "0.023837"], ["83847.1", "0.000518"], ["83847", "0.000079"], ["83846.5", "0.0045"], ["83846.4", "0.000694"], ["83846.1", "0.023837"], ["83845.9", "0.010933"], ["83845.4", "0.171"], ["83844.9", "0.023837"], ["83844.4", "0.000333"], ["83843.7", "0.001333"], ["83843.6", "0.00009"], ["83843.4", "0.003259"], ["83843.2", "0.236858"], ["83843.1", "0.059399"], ["83842.5", "0.000518"], ["83842.4", "0.004846"], ["83842", "0.000622"], ["83841.9", "0.000413"], ["83841", "0.000334"], ["83840.2", "0.000333"], ["83840", "0.000414"], ["83839.9", "0.000404"]], "a": [["83909.4", "0.054731"], ["83909.8", "0.035752"], ["83910", "0.071504"], ["83910.5", "0.039034"], ["83910.8", "0.001333"], ["83911.3", "0.071538"], ["83911.5", "0.000333"], ["83911.7", "0.000512"], ["83911.8", "0.00426"], ["83912.5", "0.001466"], ["83914.6", "0.10692"], ["83914.7", "0.003283"], ["83915", "0.001333"], ["83915.6", "0.012206"], ["83915.7", "0.000333"], ["83916.3", "0.000512"], ["83917.1", "0.001466"], ["83917.4", "0.005"], ["83917.8", "0.01"], ["83918.9", "0.039459"], ["83919", "0.029533"], ["83919.2", "0.072864"], ["83919.8", "0.024412"], ["83919.9", "0.000533"], ["83920", "0.00024"], ["83920.9", "0.000512"], ["83921.4", "0.030689"], ["83921.7", "0.001466"], ["83922.9", "0.000298"], ["83923.1", "0.003286"], ["83923.4", "0.001333"], ["83923.5", "0.03576"], ["83923.7", "0.071527"], ["83924", "0.000298"], ["83924.1", "0.000333"], ["83924.2", "0.00009"], ["83924.8", "0.076948"], ["83924.9", "0.059399"], ["83925.1", "0.00018"], ["83925.5", "0.000512"], ["83925.6", "0.171"], ["83926.3", "0.001466"], ["83927.2", "0.003286"], ["83927.6", "0.001333"], ["83928.1", "0.018984"], ["83928.3", "0.000333"], ["83929", "0.036512"], ["83929.7", "0.004161"], ["83930.1", "0.0103"], ["83930.2", "0.00112"], ["83930.9", "0.001466"], ["83931.2", "0.04"], ["83931.4", "0.003287"], ["83931.8", "0.001333"], ["83932.5", "0.000333"], ["83932.6", "0.04009"], ["83933", "0.068395"], ["83933.1", "0.270515"], ["83933.3", "0.11355"], ["83933.4", "0.059399"], ["83933.6", "0.011924"], ["83934.7", "0.000512"], ["83935.1", "0.04"], ["83935.5", "0.001466"], ["83935.6", "0.003288"], ["83936", "0.001333"], ["83936.2", "0.023835"], ["83936.3", "0.04596"], ["83936.4", "0.04"], ["83936.5", "0.0045"], ["83936.6", "0.562218"], ["83936.7", "0.000333"], ["83936.8", "0.04"], ["83937.7", "0.04"], ["83937.9", "0.04"], ["83938.1", "0.123719"], ["83938.2", "0.119177"], ["83938.4", "0.04"], ["83938.5", "0.174455"], ["83939.2", "0.023834"], ["83939.4", "0.000512"], ["83939.7", "0.023835"], ["83939.8", "0.043288"], ["83940", "0.00024"], ["83940.1", "0.001466"], ["83940.2", "0.001333"], ["83940.9", "0.000333"], ["83941", "0.00009"], ["83941.1", "0.023835"], ["83941.4", "0.008233"], ["83941.9", "0.173072"], ["83942.1", "0.02376"], ["83944", "0.003802"], ["83944.4", "0.530962"], ["83944.6", "0.023834"], ["83944.8", "0.001466"], ["83945", "0.005958"], ["83945.1", "0.000333"], ["83945.5", "0.059399"], ["83945.6", "0.119143"], ["83945.7", "0.156763"], ["83946.1", "0.354032"], ["83948.2", "0.00329"], ["83948.5", "0.013"], ["83948.6", "0.024683"], ["83948.7", "0.03"], ["83948.8", "0.001787"], ["83948.9", "0.00009"], ["83949.1", "0.04"], ["83949.2", "0.04"], ["83949.3", "0.000691"], ["83949.4", "0.001556"], ["83949.9", "0.003564"], ["83951.3", "1.438401"], ["83952.1", "0.0139"], ["83952.4", "0.00329"], ["83952.8", "0.001333"], ["83952.9", "0.119143"], ["83953", "0.02383"], ["83953.2", "0.219158"], ["83953.5", "0.000333"], ["83954", "0.064929"], ["83955", "0.000118"], ["83955.2", "0.005942"], ["83956", "0.023829"], ["83956.5", "0.02383"], ["83956.6", "0.003279"], ["83957", "0.001333"], ["83957.1", "0.114585"], ["83957.2", "0.178671"], ["83957.7", "0.119447"], ["83957.8", "0.000604"], ["83957.9", "0.02383"], ["83958", "0.059399"], ["83958.6", "0.001466"], ["83959.3", "0.0006"], ["83960", "0.00024"], ["83960.4", "0.0001"], ["83960.8", "0.003283"], ["83960.9", "0.0012"], ["83961.1", "0.119143"], ["83961.2", "0.001333"], ["83961.4", "0.023829"], ["83961.7", "0.089099"], ["83961.8", "0.005957"], ["83961.9", "0.000333"], ["83962.4", "0.000514"], ["83962.6", "0.111261"], ["83963.2", "0.001466"], ["83964.3", "0.0006"], ["83965", "0.174283"], ["83965.2", "0.059557"], ["83965.4", "0.013202"], ["83966.1", "0.000333"], ["83966.2", "0.00009"], ["83966.3", "0.119143"], ["83966.4", "2.606277"], ["83966.5", "0.063899"], ["83967", "0.004286"], ["83967.1", "0.000514"], ["83967.8", "0.005942"], ["83967.9", "0.001466"], ["83968.1", "0.0006"], ["83969", "0.011869"], ["83969.2", "0.003283"], ["83969.4", "0.0006"], ["83969.6", "0.001333"], ["83969.9", "0.024699"], ["83970", "0.022"], ["83970.3", "0.000333"], ["83971.4", "0.000358"], ["83971.5", "0.119143"], ["83971.7", "0.000514"], ["83972.3", "0.100968"], ["83972.5", "0.001466"], ["83973.4", "0.174283"], ["83973.5", "0.011869"], ["83973.8", "0.001333"], ["83974.5", "0.000333"], ["83974.6", "0.00009"], ["83975.6", "0.027597"], ["83975.8", "0.023924"], ["83976.3", "0.000514"], ["83976.7", "0.119143"], ["83976.9", "0.011869"], ["83977", "0.059399"], ["83977.1", "0.000259"], ["83977.6", "0.003291"], ["83977.9", "1.137166"], ["83978", "0.001333"], ["83978.2", "0.011869"], ["83978.6", "0.011869"], ["83978.7", "0.000333"], ["83979.5", "3.734663"], ["83980", "0.00024"], ["83980.4", "0.005942"], ["83980.9", "0.000514"], ["83981.3", "0.009"], ["83981.7", "0.001466"], ["83981.8", "0.174291"]], "u": 47433, "seq": 67552910386}, "cts": 1742560772314, "record_time": 1742560772.574852, "EXCHANGE": "BYBIT"}
{"topic": "orderbook.200.BTCUSDT", "ts": 1742560772519, "type": "delta", "data": {"s": "BTCUSDT", "b": [["83883.1", "0.03576"], ["83861.9", "0"], ["83853.5", "11.216018"], ["83839.9", "0"]], "a": [["83948.3", "0.013"], ["83948.4", "0.012728"], ["83948.5", "0"], ["83948.6", "0.011955"], ["83981.8", "0"]], "u": 47434, "seq": 67552910437}, "cts": 1742560772460, "record_time": 1742560772.576022, "EXCHANGE": "BYBIT"}
{"topic": "orderbook.200.BTCUSDT", "ts": 1742560772720, "type": "delta", "data": {"s": "BTCUSDT", "b": [["83909.7", "0.888968"], ["83909.4", "0.18525"], ["83909.3", "0.373529"], ["83909.1", "0"], ["83908.9", "0.051326"], ["83901.3", "0.01"], ["83900.9", "0.005"], ["83898.2", "0.111404"], ["83888.4", "0.164484"], ["83879.3", "0.289188"], ["83873.7", "0.01288"], ["83861.9", "11.425261"], ["83853.5", "0"], ["83841.9", "0"], ["83841", "0"], ["83840.2", "0"], ["83840", "0"]], "a": [["83909.4", "0"], ["83909.8", "0.048731"], ["83911.3", "0"], ["83917.4", "0"], ["83917.8", "0.015"], ["83918.9", "0.003286"], ["83919.2", "0.001333"], ["83921.4", "0.06601"], ["83921.5", "0.071529"], ["83923.4", "0.112755"], ["83923.7", "0"], ["83924.8", "0.121514"], ["83925.2", "0.071526"], ["83933.2", "0.182468"], ["83942.3", "0.279915"], ["83948.3", "0"], ["83948.4", "0"], ["83948.5", "0.012728"], ["83948.6", "0.024683"], ["83954", "0.064928"], ["83966.4", "0"], ["83972", "2.606277"], ["83981.8", "0.003291"]], "u": 47435, "seq": 67552910743}, "cts": 1742560772715, "record_time": 1742560772.741395, "EXCHANGE": "BYBIT"}
{"topic": "orderbook.200.BTCUSDT", "ts": 1742560772919, "type": "delta", "data": {"s": "BTCUSDT", "b": [["83909.9", "0.870322"], ["83909.8", "0.125801"], ["83909.7", "0.221076"], ["83909.4", "0"], ["83909.3", "0.192231"], ["83906.5", "0"], ["83906.3", "0.067535"], ["83902.3", "0.113608"], ["83901.5", "0.005"], ["83901.3", "0.005"], ["83900.1", "0.119143"], ["83899.3", "0.116605"], ["83898.2", "0.001333"], ["83897.7", "0.048"], ["83896.4", "0"], ["83895.5", "0.124269"], ["83889.5", "0.189014"], ["83888.5", "0.263861"], ["83888.4", "0"], ["83886.1", "0.713246"], ["83881.5", "0.290184"], ["83880.4", "0.36626"], ["83879.3", "0"], ["83878.6", "0"], ["83871", "0.056022"], ["83867.6", "11.427395"], ["83866.3", "0.01339"], ["83861.9", "0"], ["83855.7", "0.023835"], ["83843.5", "0.000149"], ["83843.2", "0"], ["83843.1", "0"], ["83842.5", "0"], ["83842.4", "0"], ["83842", "0"]], "a": [["83909.8", "0"], ["83910", "0.021948"], ["83910.5", "0.003282"], ["83911.1", "0.089678"], ["83919", "0"], ["83921.4", "0"], ["83921.5", "0"], ["83922.9", "0"], ["83923.4", "0.001333"], ["83923.5", "0"], ["83924", "0"], ["83924.5", "0.117705"], ["83924.8", "0"], ["83924.9", "0"], ["83925.2", "0"], ["83925.6", "0"], ["83927.8", "0.027252"], ["83927.9", "0.071524"], ["83928.1", "0"], ["83928.4", "0.114308"], ["83929", "0.079781"], ["83930.1", "0.000512"], ["83931.2", "0"], ["83931.5", "0.178763"], ["83932.5", "0.000631"], ["83933.2", "0"], ["83933.3", "0"], ["83934.3", "0.175965"], ["83935.1", "0"], ["83935.4", "0.186483"], ["83936.6", "0"], ["83936.8", "0"], ["83937.7", "0"], ["83937.9", "0"], ["83938.2", "0"], ["83938.4", "0"], ["83939.8", "0.003288"], ["83942.3", "0"], ["83942.4", "0.307939"], ["83943.4", "0.297381"], ["83945.6", "0"], ["83948.3", "0.562218"], ["83948.5", "0"], ["83948.6", "0.011955"], ["83949.1", "0"], ["83949.2", "0"], ["83949.3", "0.013691"], ["83949.4", "0.014284"], ["83949.9", "0.043564"], ["83950", "0.04"], ["83951.2", "0.545816"], ["83954", "0.001466"], ["83956.8", "0.063462"], ["83961.7", "0"], ["83965.4", "0.001333"], ["83969", "0"], ["83972", "0"], ["83975.3", "0.003564"], ["83977.7", "2.606277"], ["83981.8", "0.174291"], ["83982.2", "0.001333"], ["83982.6", "0.011991"], ["83982.9", "0.000333"], ["83983", "3.423114"], ["83983.6", "0.119143"], ["83985.5", "0.000514"], ["83985.7", "0.059399"], ["83986", "0.003292"], ["83986.3", "0.001466"], ["83986.4", "0.013324"], ["83987.1", "0.000333"], ["83988.3", "0.011991"], ["83988.6", "0.625678"], ["83988.7", "0.011991"]], "u": 47436, "seq": 67552911618}, "cts": 1742560772917, "record_time": 1742560773.022565, "EXCHANGE": "BYBIT"}
{"topic": "orderbook.200.BTCUSDT", "ts": 1742560773120, "type": "delta", "data": {"s": "BTCUSDT", "b": [["83911.4", "0.927494"], ["83911.1", "0.157171"], ["83911", "0.221"], ["83910.4", "0.050077"], ["83909.9", "0"], ["83909.8", "0"], ["83909.7", "0.05"], ["83906.6", "0.001333"], ["83906.3", "0.070818"], ["83904.4", "0.011635"], ["83903.2", "0.041466"], ["83903", "0.099099"], ["83902.4", "0.001935"], ["83902.3", "0"], ["83902.1", "0.003281"], ["83901.3", "0"], ["83900.9", "0"], ["83900.6", "0"], ["83900", "0.531662"], ["83899.5", "0.100117"], ["83899.3", "0"], ["83898.2", "0.053333"], ["83897.9", "0.003259"], ["83897.8", "0.044518"], ["83896.5", "0.044"], ["83895.5", "0"], ["83890.8", "0"], ["83890.4", "0"], ["83889.5", "0.003259"], ["83888.5", "0.089099"], ["83886.1", "0.709671"], ["83881.5", "0"], ["83880.4", "0.059399"], ["83869.3", "0.234373"], ["83867.6", "0.002134"], ["83863.6", "0"], ["83861.9", "11.425261"], ["83843.2", "0.236858"], ["83843.1", "0.059399"], ["83842.5", "0.000518"], ["83842.4", "0.004846"]], "a": [["83910", "0"], ["83910.5", "0"], ["83910.8", "0"], ["83911.1", "0"], ["83911.5", "0.062904"], ["83914.6", "0"], ["83915.6", "0"], ["83917.7", "0.071532"], ["83917.8", "0.01"], ["83918.1", "0.012206"], ["83919.5", "0.030124"], ["83919.8", "0.10692"], ["83919.9", "0.005533"], ["83924.2", "0"], ["83924.5", "0"], ["83925.4", "0.000298"], ["83926.8", "0.071525"], ["83927.8", "0.051698"], ["83927.9", "0.171"], ["83928.4", "0"], ["83929", "0"], ["83929.3", "0.071523"], ["83931.5", "0"], ["83932.5", "0.000333"], ["83932.6", "0.00009"], ["83932.9", "0.078284"], ["83933.1", "0"], ["83934.3", "0"], ["83935.4", "0"], ["83936.4", "0"], ["83937.3", "0.018984"], ["83938", "0.04"], ["83938.1", "0"], ["83938.4", "0.075966"], ["83939.3", "0.009788"], ["83941.7", "0.04"], ["83941.9", "0.336997"], ["83942.4", "0"], ["83943.1", "0.04"], ["83943.4", "0.04"], ["83944.8", "0.041466"], ["83949.3", "0.000691"], ["83949.4", "0.001556"], ["83949.9", "0.003564"], ["83950", "0"], ["83950.3", "0.013"], ["83950.4", "0.012728"], ["83950.9", "0.04"], ["83951", "0.04"], ["83951.3", "0.009"], ["83956.8", "0"], ["83959.6", "0.063462"], ["83977.7", "0"], ["83980.5", "2.606277"], ["83988.8", "0.011992"]], "u": 47437, "seq": 67552912264}, "cts": 1742560773115, "record_time": 1742560773.141159, "EXCHANGE": "BYBIT"}
{"topic": "orderbook.200.BTCUSDT", "ts": 1742560773320, "type": "delta", "data": {"s": "BTCUSDT", "b": [["83911.4", "0.927571"], ["83911.1", "0.103067"], ["83910.4", "0.05"], ["83906.5", "0.106033"], ["83906.4", "0.113595"], ["83906.3", "0.003363"], ["83903", "0.104099"], ["83902.9", "0.044"], ["83901.5", "0.056"], ["83901.2", "0.04"], ["83897.3", "0.0909"], ["83897", "0"], ["83896.8", "0"], ["83896.2", "0.048"], ["83895.4", "0"], ["83893.4", "0.000358"], ["83891.7", "0"], ["83890.1", "0"], ["83888.9", "0"], ["83879.7", "0.001143"], ["83867.6", "11.427395"], ["83861.9", "0"], ["83842", "0.000622"]], "a": [["83911.5", "0.065756"], ["83916.6", "0.071533"], ["83917.7", "0"], ["83917.8", "0.005"], ["83919.5", "0"], ["83919.9", "0.010533"], ["83925.4", "0"], ["83926.6", "0.000298"], ["83926.7", "0.036057"], ["83927.8", "0"], ["83929.2", "0.075632"], ["83931.5", "0.17876"], ["83933.2", "0.001229"], ["83938.4", "0.115966"], ["83939.7", "0.063835"], ["83940", "0.04024"], ["83941.3", "0.04"], ["83941.9", "0.213035"], ["83945.1", "0.040333"], ["83950.3", "0"], ["83950.4", "0"], ["83950.5", "0.012728"], ["83950.6", "0.012728"], ["83950.9", "0"], ["83951", "0"], ["83951.1", "0.04"], ["83951.2", "0.04"], ["83951.8", "0.17876"], ["83954", "0.064931"], ["83956", "0.202589"], ["83959.6", "0"], ["83972", "2.606422"], ["83972.3", "0.089099"], ["83980.5", "0"], ["83982.6", "0"], ["83988.3", "0"]], "u": 47438, "seq": 67552912449}, "cts": 1742560773317, "record_time": 1742560773.341536, "EXCHANGE": "BYBIT"}
{"topic": "orderbook.200.BTCUSDT", "ts": 1742560773520, "type": "delta", "data": {"s": "BTCUSDT", "b": [["83911.1", "0.156484"], ["83908.3", "0.0028"], ["83902.8", "0"], ["83895.1", "0"], ["83879.6", "0.0016"], ["83874.1", "0"], ["83841.9", "0.000413"]], "a": [["83911.5", "0.068735"], ["83916.6", "0"], ["83917.8", "0"], ["83919.3", "0.071531"], ["83919.9", "0.015533"], ["83926.8", "0"], ["83927.4", "0.0518"], ["83931.8", "0.072853"], ["83933.2", "0"], ["83934.7", "0.00149"], ["83938.3", "0.114903"], ["83938.4", "0.04"], ["83948.4", "0.113595"], ["83951.8", "0"], ["83972", "0"], ["83974.9", "2.606422"], ["83988.9", "0.011991"]], "u": 47439, "seq": 67552912567}, "cts": 1742560773518, "record_time": 1742560773.547575, "EXCHANGE": "BYBIT"}
{"topic": "orderbook.200.BTCUSDT", "ts": 1742560773719, "type": "delta", "data": {"s": "BTCUSDT", "b": [["83911.6", "0.890474"], ["83911.5", "0.120586"], ["83911.4", "0.171"], ["83911.1", "0"], ["83911", "0.05"], ["83907.3", "0.000333"], ["83904.9", "0.112688"], ["83903.2", "0.046466"], ["83903", "0.099099"], ["83900.1", "0"], ["83895.1", "0.169159"], ["83894.6", "0.000927"], ["83886", "0.842418"], ["83867.6", "0.002134"], ["83853.5", "11.55671"], ["83842.5", "0"], ["83842.4", "0"], ["83842", "0"], ["83841.9", "0"]], "a": [["83911.5", "0"], ["83911.7", "0.003491"], ["83919.3", "0"], ["83926.7", "0.000298"], ["83927", "0.071525"], ["83929.3", "0"], ["83930.1", "0.118604"], ["83931.5", "0"], ["83931.8", "0.001333"], ["83934.7", "0.000512"], ["83939.9", "0.183068"], ["83948.4", "0"], ["83949", "0.290338"], ["83950.5", "0"], ["83950.6", "0"], ["83951.1", "0"], ["83951.2", "0"], ["83951.9", "0.013"], ["83952", "0.012728"], ["83952.5", "0.04"], ["83952.6", "0.04"], ["83954", "0.001466"], ["83956", "0.023829"], ["83972", "2.606422"], ["83974.9", "0"], ["83989", "0.011991"], ["83989.1", "0.120743"]], "u": 47440, "seq": 67552912903}, "cts": 1742560773717, "record_time": 1742560773.740221, "EXCHANGE": "BYBIT"}
{"topic": "orderbook.200.BTCUSDT", "ts": 1742560773919, "type": "delta", "data": {"s": "BTCUSDT", "b": [["83911.6", "0.843773"], ["83911.5", "0.061238"], ["83909.3", "0"], ["83904.9", "0"], ["83903.2", "0.056466"], ["83903", "0.089099"], ["83897.8", "0.137878"], ["83897.3", "0"], ["83895.1", "0"], ["83886", "0.568474"], ["83842.5", "0.000518"], ["83842.4", "0.004846"], ["83842", "0.000622"], ["83841.9", "0.000413"]], "a": [["83911.7", "0.018389"], ["83911.9", "0.071537"], ["83919.4", "0.067102"], ["83919.5", "0.100981"], ["83919.9", "0.010533"], ["83920.1", "0.005"], ["83921.7", "0.02441"], ["83921.8", "0.071529"], ["83924.7", "0.023994"], ["83926.2", "0.004768"], ["83927", "0"], ["83929.2", "0"], ["83930.1", "0.000512"], ["83936.1", "0.003"], ["83939.9", "0"], ["83945.7", "0.357192"], ["83946", "0.119143"], ["83948.3", "0.675788"], ["83949", "0"], ["83951.2", "0.063465"], ["83969.2", "2.609705"], ["83972", "0"], ["83988.7", "0"], ["83988.8", "0"], ["83988.9", "0"], ["83989", "0"], ["83989.1", "0"]], "u": 47441, "seq": 67552913014}, "cts": 1742560773902, "record_time": 1742560773.940878, "EXCHANGE": "BYBIT"}
{"topic": "orderbook.200.BTCUSDT", "ts": 1742560774120, "type": "delta", "data": {"s": "BTCUSDT", "b": [["83911.5", "0.104883"], ["83874.9", "0.014071"], ["83874.8", "0.132024"], ["83873.7", "0"], ["83873.6", "0"], ["83859.1", "11.794895"], ["83853.5", "0"], ["83841", "0.000334"], ["83840.2", "0.000333"], ["83840", "0.000414"]], "a": [["83919.4", "0.045643"], ["83919.5", "0.02945"], ["83919.9", "0.005533"], ["83920.1", "0.01"], ["83924.5", "0.083699"], ["83924.6", "0.071527"], ["83927.4", "0"], ["83947.5", "0.113704"], ["83948.3", "0.562218"], ["83951.1", "0.013"], ["83951.2", "0.076194"], ["83951.9", "0"], ["83952", "0"], ["83966.4", "2.606416"], ["83969.2", "0.003283"], ["83987.1", "0"], ["83988.6", "0"]], "u": 47442, "seq": 67552913119}, "cts": 1742560774116, "record_time": 1742560774.144477, "EXCHANGE": "BYBIT"}
{"topic": "orderbook.200.BTCUSDT", "ts": 1742560774320, "type": "delta", "data": {"s": "BTCUSDT", "b": [["83911.6", "0.602581"], ["83911.5", "0.043645"], ["83911.4", "0"], ["83911", "0.02"], ["83910.4", "0.02"], ["83894.8", "0.059851"], ["83894.3", "0.119143"], ["83887.8", "0.056373"], ["83880.8", "0.121316"], ["83874.9", "0.013952"], ["83859.1", "0.238185"], ["83853.5", "11.55671"], ["83841.9", "0"], ["83841", "0"], ["83840.2", "0"], ["83840", "0"]], "a": [["83911.7", "0.208381"], ["83919.7", "0.071531"], ["83919.9", "0.000533"], ["83920.1", "0.015"], ["83921.7", "0.039362"], ["83924.2", "0.00009"], ["83924.4", "0.059399"], ["83924.5", "0.06224"], ["83924.6", "0"], ["83926.1", "0.063269"], ["83929.8", "0.059764"], ["83935.3", "0.001082"], ["83935.7", "0.001189"], ["83936.8", "0.061939"], ["83943.8", "0.121763"], ["83951.1", "0"], ["83951.3", "0.021729"], ["83966.4", "0"], ["83969.2", "2.609699"], ["83983.6", "0"], ["83985.5", "0"], ["83985.7", "0"], ["83986", "0"], ["83986.3", "0"], ["83986.4", "0"]], "u": 47443, "seq": 67552913234}, "cts": 1742560774315, "record_time": 1742560774.341932, "EXCHANGE": "BYBIT"}
{"topic": "orderbook.200.BTCUSDT", "ts": 1742560774519, "type": "delta", "data": {"s": "BTCUSDT", "b": [["83911.4", "0.000659"], ["83909.7", "0.02"], ["83903", "0"]], "a": [["83929.7", "0.024533"], ["83932.8", "0.001086"], ["83935.3", "0"], ["83935.7", "0"], ["83950.4", "0.04"], ["83950.5", "0.04"], ["83952.5", "0"], ["83952.6", "0"], ["83960.7", "2.606416"], ["83969.2", "0.003283"]], "u": 47444, "seq": 67552913292}, "cts": 1742560774505, "record_time": 1742560774.598311, "EXCHANGE": "BYBIT"}
{"topic": "orderbook.200.BTCUSDT", "ts": 1742560774720, "type": "delta", "data": {"s": "BTCUSDT", "b": [["83911.6", "0.696988"], ["83911.5", "0.024596"], ["83908.9", "0.021326"], ["83908.3", "0"], ["83898.1", "0.029332"], ["83894.8", "0"], ["83887.8", "0"], ["83885.8", "0"], ["83881.2", "0.023343"], ["83880.8", "0"], ["83875.4", "0.013"], ["83875.3", "0.012881"], ["83874.9", "0.001071"], ["83874.8", "0.119143"], ["83869.3", "0.099459"], ["83869.2", "0.373113"], ["83853.5", "0"], ["83850.6", "11.483722"], ["83841.9", "0.000413"]], "a": [["83911.8", "0.027646"], ["83921.7", "0.042257"], ["83924.5", "0.118281"], ["83925.7", "0.018291"], ["83927.7", "0.009788"], ["83929.7", "0.004161"], ["83929.8", "0"], ["83932.8", "0"], ["83933.1", "0.04"], ["83936.8", "0"], ["83937.3", "0"], ["83938", "0"], ["83939.3", "0"], ["83940.1", "0.120639"], ["83943.8", "0"], ["83949.6", "0.013"], ["83949.7", "0.012729"], ["83950.2", "0.04"], ["83950.3", "0.04"], ["83950.4", "0"], ["83950.5", "0"], ["83951.2", "0.063465"], ["83951.3", "0.009"], ["83960.7", "0"], ["83965.2", "0.083803"], ["83969.9", "0"], ["83977.7", "2.606416"], ["83983.6", "0.119143"], ["83985.5", "0.000514"], ["83985.7", "0.059399"]], "u": 47445, "seq": 67552913537}, "cts": 1742560774715, "record_time": 1742560774.743414, "EXCHANGE": "BYBIT"}
{"topic": "orderbook.200.BTCUSDT", "ts": 1742560774919, "type": "delta", "data": {"s": "BTCUSDT", "b": [["83911.6", "0.696395"], ["83853.5", "11.483722"], ["83850.6", "0"]], "a": [["83951.1", "0.136036"], ["83951.2", "0"], ["83954", "0.064931"]], "u": 47446, "seq": 67552913641}, "cts": 1742560774915, "record_time": 1742560774.941456, "EXCHANGE": "BYBIT"}
{"topic": "orderbook.200.BTCUSDT", "ts": 1742560775120, "type": "delta", "data": {"s": "BTCUSDT", "b": [["83911.6", "0.525395"], ["83900.9", "0.119143"], ["83899.3", "0.122387"], ["83898.1", "0"], ["83888.8", "0.166711"], ["83881.8", "0.303302"], ["83841.9", "0"]], "a": [["83911.7", "0.292246"], ["83919.5", "0"], ["83921.7", "0.074304"], ["83923.8", "0.123821"], ["83933.4", "0.099399"], ["83934.3", "0.180194"], ["83934.7", "0.040512"], ["83935.1", "0.04"], ["83936.3", "0.08596"], ["83939.7", "0.023835"], ["83939.8", "0.043288"], ["83940.1", "0.160639"], ["83941.3", "0.308247"], ["83945.1", "0.000333"], ["83946", "0"], ["83951.2", "0.063465"], ["83953.6", "1.429362"], ["83954", "0.001466"], ["83955.1", "2.606416"], ["83977.7", "0"], ["83983.6", "0"], ["83985.5", "0"], ["83985.7", "0"]], "u": 47447, "seq": 67552913733}, "cts": 1742560775114, "record_time": 1742560775.140531, "EXCHANGE": "BYBIT"}
{"topic": "orderbook.200.BTCUSDT", "ts": 1742560775319, "type": "delta", "data": {"s": "BTCUSDT", "b": [["83911.6", "0.525007"], ["83911.5", "0.042982"], ["83911.4", "0.072197"], ["83906.2", "0.191"], ["83902.9", "0.115545"], ["83900.4", "0.091436"], ["83881.9", "0.223074"], ["83880.3", "0"]], "a": [["83917.6", "0.084774"], ["83917.7", "0.071532"], ["83919.4", "0"], ["83921.8", "0"], ["83936.7", "0.040333"], ["83938", "0.04"], ["83940", "0.00024"], ["83943.1", "0"], ["83943.4", "0"], ["83944.8", "0.001466"], ["83983.6", "0.119143"]], "u": 47448, "seq": 67552913801}, "cts": 1742560775315, "record_time": 1742560775.341009, "EXCHANGE": "BYBIT"}
{"topic": "orderbook.200.BTCUSDT", "ts": 1742560775519, "type": "delta", "data": {"s": "BTCUSDT", "b": [], "a": [["83941.7", "0"], ["83985.5", "0.000514"]], "u": 47449, "seq": 67552913845}, "cts": 1742560775515, "record_time": 1742560775.54118, "EXCHANGE": "BYBIT"}
{"topic": "orderbook.200.BTCUSDT", "ts": 1742560775720, "type": "delta", "data": {"s": "BTCUSDT", "b": [["83911.6", "0.504768"], ["83911", "0"], ["83875.5", "0.014347"], ["83875.4", "0.012881"], ["83875.3", "0"], ["83850.3", "0"], ["83841.9", "0.000413"], ["83841", "0.000334"], ["83840.2", "0.000333"]], "a": [["83911.7", "0.469246"], ["83917.2", "0.138402"], ["83917.3", "0.178759"], ["83917.6", "0"], ["83919.4", "0.0002"], ["83919.9", "0.000333"], ["83949.6", "0"], ["83949.8", "0.012729"], ["83950.2", "0"], ["83950.4", "0.04"], ["83955.1", "2.606442"], ["83983.6", "0"], ["83985.5", "0"]], "u": 47450, "seq": 67552913907}, "cts": 1742560775717, "record_time": 1742560775.740919, "EXCHANGE": "BYBIT"}
{"topic": "orderbook.200.BTCUSDT", "ts": 1742560775919, "type": "delta", "data": {"s": "BTCUSDT", "b": [["83911.6", "0.494627"], ["83911.5", "0"], ["83911.4", "0.000659"], ["83910.4", "0"], ["83909.7", "0"], ["83908.9", "0.001326"], ["83906.2", "0.171"], ["83902.9", "0.044"], ["83902.7", "0.071545"], ["83900.9", "0"], ["83900.7", "0.092138"], ["83900.1", "0.119143"], ["83899.3", "0"], ["83890.6", "0.029671"], ["83888.8", "0.000445"], ["83881.8", "0.005871"], ["83875.5", "0.001466"], ["83875.4", "0"], ["83874.7", "0.013518"], ["83874.6", "0.012881"], ["83853.5", "0"], ["83850.6", "11.552738"], ["83843.3", "0.235392"], ["83843.2", "0.001466"], ["83840", "0.000414"]], "a": [["83911.7", "0.509199"], ["83917.2", "0.093871"], ["83917.3", "0"], ["83919.5", "0.030321"], ["83921.7", "0.001466"], ["83923.8", "0"], ["83924.4", "0"], ["83934.3", "0"], ["83936.1", "0"], ["83941.3", "0"], ["83947.4", "0.119143"], ["83951.1", "0.54784"], ["83983.6", "0.119143"], ["83985.5", "0.000514"], ["83985.7", "0.059399"], ["83986", "0.003292"]], "u": 47451, "seq": 67552914113}, "cts": 1742560775915, "record_time": 1742560775.940583, "EXCHANGE": "BYBIT"}
{"topic": "orderbook.200.BTCUSDT", "ts": 1742560776120, "type": "delta", "data": {"s": "BTCUSDT", "b": [["83881.9", "0"], ["83869.7", "0.003462"]], "a": [["83911.7", "0.338199"], ["83933.7", "0.003575"], ["83986", "0"]], "u": 47452, "seq": 67552914189}, "cts": 1742560776108, "record_time": 1742560776.173168, "EXCHANGE": "BYBIT"}
{"topic": "orderbook.200.BTCUSDT", "ts": 1742560776320, "type": "delta", "data": {"s": "BTCUSDT", "b": [["83911.6", "0.493125"]], "a": [["83911.7", "0.515199"], ["83933.7", "0"], ["83936.4", "0.003575"]], "u": 47453, "seq": 67552914257}, "cts": 1742560776284, "record_time": 1742560776.340811, "EXCHANGE": "BYBIT"}
{"topic": "orderbook.200.BTCUSDT", "ts": 1742560776519, "type": "delta", "data": {"s": "BTCUSDT", "b": [["83911.6", "0.493364"], ["83906.3", "0.003283"], ["83853.5", "11.552738"], ["83850.6", "0"]], "a": [["83911.7", "0.344199"]], "u": 47454, "seq": 67552914312}, "cts": 1742560776516, "record_time": 1742560776.540018, "EXCHANGE": "BYBIT"}
{"topic": "orderbook.200.BTCUSDT", "ts": 1742560776720, "type": "delta", "data": {"s": "BTCUSDT", "b": [["83911.6", "0.664364"], ["83910.3", "0.027128"], ["83910.2", "0.089099"], ["83901.7", "0.089099"], ["83899.3", "0.121859"], ["83895.2", "0.112329"], ["83888.8", "0.175411"], ["83888.2", "0.173927"], ["83881.8", "0.304273"], ["83881.2", "0.320692"], ["83875.6", "0.013"], ["83875.5", "0.014347"], ["83874.7", "0.000518"], ["83874.6", "0"], ["83842.4", "0"], ["83842", "0"], ["83841.9", "0"], ["83841", "0"], ["83840.2", "0"], ["83840", "0"]], "a": [["83911.7", "0.266334"], ["83911.8", "0.00426"], ["83923.8", "0.120647"], ["83928.1", "0.124412"], ["83934.3", "0.171168"], ["83935.1", "0.206115"], ["83936.4", "0"], ["83941.3", "0.272858"], ["83942.1", "0.302012"], ["83948.2", "0.01629"], ["83948.3", "0.57495"], ["83948.8", "0.041787"], ["83948.9", "0.04009"], ["83949.7", "0"], ["83949.8", "0"], ["83950.3", "0"], ["83950.4", "0"], ["83955.1", "0"], ["83980.5", "2.606442"], ["83986", "0.003292"]], "u": 47455, "seq": 67552914407}, "cts": 1742560776716, "record_time": 1742560776.743403, "EXCHANGE": "BYBIT"}
{"topic": "orderbook.200.BTCUSDT", "ts": 1742560776919, "type": "delta", "data": {"s": "BTCUSDT", "b": [["83911.3", "0.048589"], ["83911.2", "0.071538"], ["83910.3", "0"], ["83905.6", "0.071543"], ["83900.4", "0.019889"], ["83899.3", "0"], ["83895.2", "0"], ["83888.8", "0.000445"], ["83888.2", "0"], ["83881.9", "0.31257"], ["83881.8", "0.005871"], ["83881.2", "0.023343"], ["83875.6", "0"], ["83875.4", "0.012881"]], "a": [["83911.7", "0.166334"], ["83917.7", "0.071533"], ["83919.7", "0"], ["83922.1", "0.022971"], ["83922.2", "0.071529"], ["83923.8", "0"], ["83928.1", "0"], ["83934.3", "0"], ["83935.1", "0.04"], ["83941.2", "0.344837"], ["83941.3", "0"], ["83941.9", "0"], ["83942.1", "0.02376"], ["83947.4", "0"], ["83948.2", "0.00329"], ["83948.3", "0.562218"], ["83948.6", "0.024687"], ["83948.7", "0.042732"], ["83948.8", "0.001787"], ["83948.9", "0.00009"], ["83949.1", "0.04"], ["83949.2", "0.04"], ["83980.5", "0"], ["83983.3", "2.606442"], ["83986.3", "0.001466"], ["83986.4", "0.013324"]], "u": 47456, "seq": 67552914493}, "cts": 1742560776916, "record_time": 1742560776.940122, "EXCHANGE": "BYBIT"}
{"topic": "orderbook.200.BTCUSDT", "ts": 1742560777120, "type": "delta", "data": {"s": "BTCUSDT", "b": [["83911.4", "0"], ["83881.9", "0"], ["83879.7", "0"], ["83842.4", "0.004846"], ["83842", "0.000622"], ["83841.9", "0.000413"]], "a": [["83911.7", "0.172334"], ["83932.9", "0.128498"], ["83941.2", "0"], ["83947.4", "0.119143"], ["83948.6", "0.011955"], ["83948.8", "0.014519"], ["83949.1", "0"], ["83949.2", "0"], ["83949.3", "0.040691"], ["83949.4", "0.041556"], ["83955.1", "2.606442"], ["83983.3", "0"], ["83987.1", "0.000333"], ["83988.6", "0.625678"]], "u": 47457, "seq": 67552914537}, "cts": 1742560777117, "record_time": 1742560777.217393, "EXCHANGE": "BYBIT"}
{"topic": "orderbook.200.BTCUSDT", "ts": 1742560777319, "type": "delta", "data": {"s": "BTCUSDT", "b": [["83911.6", "0.664066"], ["83900.7", "0.090397"]], "a": [["83949.2", "0.04"], ["83949.4", "0.001556"], ["83988.6", "0"]], "u": 47458, "seq": 67552914594}, "cts": 1742560777305, "record_time": 1742560777.339845, "EXCHANGE": "BYBIT"}
{"topic": "orderbook.200.BTCUSDT", "ts": 1742560777520, "type": "delta", "data": {"s": "BTCUSDT", "b": [["83905.6", "0"], ["83905.1", "0.071543"], ["83904.9", "0.001741"], ["83903.3", "0.003"], ["83879.6", "0"], ["83875.6", "0.013"], ["83875.4", "0"], ["83874.6", "0.0016"], ["83856.3", "11.652402"], ["83853.5", "0"], ["83841.9", "0"]], "a": [["83911.7", "0.184334"], ["83948.6", "0.024955"], ["83948.8", "0.001787"]], "u": 47459, "seq": 67552914669}, "cts": 1742560777504, "record_time": 1742560777.540656, "EXCHANGE": "BYBIT"}
{"topic": "orderbook.200.BTCUSDT", "ts": 1742560777719, "type": "delta", "data": {"s": "BTCUSDT", "b": [["83911.8", "0.83362"], ["83911.7", "0.118001"], ["83911.6", "0.231375"], ["83911.3", "0"], ["83907", "0.000512"], ["83905.1", "0"], ["83903.4", "0.01"], ["83903.2", "0.046466"], ["83901.7", "0.199967"], ["83900.1", "0.19069"], ["83891.9", "0.163167"], ["83882.8", "0.288286"], ["83875.7", "0.013"], ["83875.6", "0.012881"], ["83875.5", "0.001466"], ["83856.3", "0.001851"], ["83843.2", "0"], ["83843.1", "0"], ["83842.5", "0"], ["83842.4", "0"], ["83842", "0"]], "a": [["83911.7", "0"], ["83911.8", "0"], ["83911.9", "0.074516"], ["83917.2", "0.069412"], ["83920.1", "0.005"], ["83920.3", "0.01"], ["83926.9", "0.124346"], ["83936.7", "0.217872"], ["83945.8", "0.305638"], ["83948.5", "0.013"], ["83948.6", "0.024688"], ["83948.7", "0.03"], ["83949.1", "0.04"], ["83949.3", "0.000691"], ["83986.3", "0"], ["83986.4", "0"], ["83987.1", "0"]], "u": 47460, "seq": 67552914881}, "cts": 1742560777717, "record_time": 1742560777.744315, "EXCHANGE": "BYBIT"}
{"topic": "orderbook.200.BTCUSDT", "ts": 1742560777920, "type": "delta", "data": {"s": "BTCUSDT", "b": [["83911.8", "0.833701"], ["83911.6", "0.221636"], ["83905.1", "0.071543"], ["83903.4", "0.015"], ["83903.2", "0.041466"], ["83900.1", "0.119143"], ["83880.5", "0.12288"], ["83875.7", "0"], ["83875.5", "0.014347"], ["83853.5", "11.733086"], ["83843.4", "0"], ["83843.3", "0"]], "a": [["83920.1", "0"], ["83920.3", "0.015"], ["83944.3", "0.168766"], ["83946.2", "0.113668"], ["83947.4", "0"], ["83947.5", "0"], ["83948.5", "0"], ["83948.6", "0.011955"], ["83948.7", "0.043"], ["83948.8", "0.01452"], ["83949.1", "0"], ["83949.2", "0"], ["83949.3", "0.040691"], ["83949.4", "0.041556"], ["83951.2", "0"], ["83954", "0.064931"], ["83955.1", "0"], ["83977.7", "2.606442"], ["83986.3", "0.001466"], ["83986.4", "0.013324"], ["83987.1", "0.000333"], ["83988.6", "0.625678"], ["83988.7", "0.011991"]], "u": 47461, "seq": 67552914974}, "cts": 1742560777916, "record_time": 1742560777.941658, "EXCHANGE": "BYBIT"}
{"topic": "orderbook.200.BTCUSDT", "ts": 1742560778120, "type": "delta", "data": {"s": "BTCUSDT", "b": [["83859.1", "11.971271"], ["83853.5", "0"], ["83843.4", "0.003259"]], "a": [["83948.7", "0.042733"]], "u": 47462, "seq": 67552915023}, "cts": 1742560778110, "record_time": 1742560778.140757, "EXCHANGE": "BYBIT"}
{"topic": "orderbook.200.BTCUSDT", "ts": 1742560778320, "type": "delta", "data": {"s": "BTCUSDT", "b": [["83911.8", "0.808672"], ["83875.7", "0.013"], ["83875.5", "0.001466"], ["83843.4", "0"]], "a": [["83944.9", "0.023835"], ["83951.2", "0.063465"], ["83954", "0.001466"], ["83966.4", "2.606435"], ["83977.7", "0"], ["83988.6", "0"], ["83988.7", "0"]], "u": 47463, "seq": 67552915052}, "cts": 1742560778312, "record_time": 1742560778.342878, "EXCHANGE": "BYBIT"}
{"topic": "orderbook.200.BTCUSDT", "ts": 1742560778520, "type": "delta", "data": {"s": "BTCUSDT", "b": [["83875.7", "0"], ["83875.5", "0.014347"], ["83843.4", "0.003259"]], "a": [["83941.4", "0.014175"], ["83948.7", "0.03"], ["83948.9", "0.012823"], ["83949.3", "0.000691"], ["83949.5", "0.04"], ["83954", "0.007408"], ["83955.2", "0"], ["83966.4", "0"], ["83966.6", "0.005942"], ["83967.8", "0"], ["83969.2", "2.609718"], ["83979.2", "0.005942"], ["83980.4", "0"], ["83988.6", "0.625678"]], "u": 47464, "seq": 67552915118}, "cts": 1742560778517, "record_time": 1742560778.540632, "EXCHANGE": "BYBIT"}
{"topic": "orderbook.200.BTCUSDT", "ts": 1742560778720, "type": "delta", "data": {"s": "BTCUSDT", "b": [["83901.7", "0.089099"], ["83896.8", "0.056243"], ["83891.9", "0"], ["83889.8", "0.055657"], ["83882.8", "0.11735"], ["83859.1", "12.059636"]], "a": [["83911.9", "0.080516"], ["83926.9", "0"], ["83931.7", "0.017855"], ["83931.8", "0.059093"], ["83936.7", "0.040333"], ["83938.8", "0.059855"], ["83945.8", "0.117117"], ["83948.8", "0.001787"], ["83949", "0.012733"], ["83949.4", "0.001556"], ["83949.6", "0.04"], ["83966.4", "2.606435"], ["83969.2", "0.003283"], ["83986.3", "0"], ["83986.4", "0"], ["83987.1", "0"], ["83988.6", "0"]], "u": 47465, "seq": 67552915184}, "cts": 1742560778709, "record_time": 1742560778.793957, "EXCHANGE": "BYBIT"}
{"topic": "orderbook.200.BTCUSDT", "ts": 1742560778919, "type": "delta", "data": {"s": "BTCUSDT", "b": [["83911.7", "0.03705"], ["83911.6", "0.020636"], ["83910.2", "0"], ["83905.1", "0"], ["83904.9", "0.073284"], ["83896.8", "0"], ["83889.8", "0.001333"], ["83882.8", "0"], ["83875.6", "0"], ["83875.5", "0.001466"], ["83875.4", "0.013"], ["83875.3", "0.012881"], ["83859.1", "0.238185"], ["83850.6", "11.821451"], ["83843.3", "0.235392"], ["83843.2", "0.001466"]], "a": [["83911.9", "0.186516"], ["83922.1", "0.03792"], ["83924.4", "0.059399"], ["83931.7", "0"], ["83931.8", "0.001333"], ["83938.8", "0"], ["83945.8", "0"], ["83961", "0.045179"], ["83986.3", "0.001466"]], "u": 47466, "seq": 67552915315}, "cts": 1742560778915, "record_time": 1742560778.941735, "EXCHANGE": "BYBIT"}
{"topic": "orderbook.200.BTCUSDT", "ts": 1742560779119, "type": "delta", "data": {"s": "BTCUSDT", "b": [["83911.8", "0.637268"], ["83911.7", "0"], ["83911.6", "0.000636"], ["83911.2", "0"], ["83904.9", "0.001741"], ["83900.3", "0.071547"], ["83900.1", "0"], ["83899.7", "0.111345"], ["83889.9", "0.171818"], ["83880.8", "0.272977"], ["83875.4", "0"], ["83875.3", "0"], ["83875.1", "0.012881"], ["83875", "0.013317"], ["83869.2", "0.238185"], ["83866.3", "0.148294"]], "a": [["83911.9", "0.276416"], ["83924.9", "0.113294"], ["83934.7", "0.204972"], ["83943.8", "0.307264"], ["83946", "0.119143"], ["83963.5", "2.606435"], ["83966.4", "0"], ["83985.7", "0"], ["83986", "0"], ["83986.3", "0"]], "u": 47467, "seq": 67552915498}, "cts": 1742560779109, "record_time": 1742560779.140039, "EXCHANGE": "BYBIT"}
{"topic": "orderbook.200.BTCUSDT", "ts": 1742560779319, "type": "delta", "data": {"s": "BTCUSDT", "b": [["83911.8", "0.429907"], ["83900.4", "0"], ["83900.1", "0.119143"], ["83899.7", "0"], ["83889.9", "0"], ["83880.9", "0.204773"], ["83880.8", "0"], ["83880.5", "0"], ["83866.3", "0.148276"], ["83850.6", "0"], ["83843.1", "0.059399"], ["83842.5", "0.000518"], ["83842.4", "0.358911"], ["83842", "0.000622"]], "a": [["83922.1", "0.040791"], ["83924.9", "0"], ["83934.7", "0.040512"], ["83943.8", "0"], ["83985.7", "0.059399"], ["83986", "0.003292"]], "u": 47468, "seq": 67552915659}, "cts": 1742560779318, "record_time": 1742560779.339688, "EXCHANGE": "BYBIT"}
{"topic": "orderbook.200.BTCUSDT", "ts": 1742560779519, "type": "delta", "data": {"s": "BTCUSDT", "b": [["83911.8", "0.386016"], ["83911.5", "0.021859"], ["83911.4", "0.071538"], ["83904.6", "0.071544"], ["83902.7", "0"], ["83894.4", "0.019263"], ["83880.9", "0"], ["83869.1", "0.194285"], ["83866.3", "0.01339"], ["83850.6", "11.821451"], ["83842.5", "0"], ["83842.4", "0"], ["83842", "0"]], "a": [["83911.9", "0.176416"]], "u": 47469, "seq": 67552915740}, "cts": 1742560779516, "record_time": 1742560779.540989, "EXCHANGE": "BYBIT"}
{"topic": "orderbook.200.BTCUSDT", "ts": 1742560779720, "type": "delta", "data": {"s": "BTCUSDT", "b": [["83911.6", "0"], ["83875.4", "0.012881"], ["83875.3", "0.012881"], ["83875.1", "0"], ["83875", "0.000436"], ["83856.3", "11.787629"], ["83850.6", "0"], ["83842.5", "0.000518"]], "a": [["83948.6", "0.024684"], ["83948.7", "0.042729"], ["83948.9", "0.00009"], ["83949", "0"], ["83949.2", "0.04"], ["83949.3", "0.040691"], ["83949.5", "0"], ["83949.6", "0"], ["83986.3", "0.001466"], ["83986.4", "0.013324"]], "u": 47470, "seq": 67552915774}, "cts": 1742560779705, "record_time": 1742560779.743313, "EXCHANGE": "BYBIT"}
{"topic": "orderbook.200.BTCUSDT", "ts": 1742560779919, "type": "delta", "data": {"s": "BTCUSDT", "b": [["83911.8", "0.422394"], ["83911.5", "0"], ["83911.4", "0"], ["83908.5", "0.021462"], ["83908.4", "0.07154"], ["83904.6", "0"], ["83901.7", "0"], ["83900.1", "0"], ["83897.2", "0.07155"], ["83875.4", "0"], ["83875.3", "0"], ["83874.7", "0.013399"], ["83874.6", "0.014481"], ["83869.1", "0.059399"], ["83866.3", "0.14826"], ["83856.3", "0.001851"], ["83853.5", "11.785778"], ["83842.4", "0.358911"], ["83842", "0.000622"], ["83841.9", "0.000413"]], "a": [["83911.9", "0.447416"], ["83935.9", "0.003575"], ["83948.6", "0.011955"], ["83948.7", "0.03"], ["83948.9", "0.012819"], ["83949", "0.012729"], ["83949.2", "0"], ["83949.3", "0.000691"], ["83949.5", "0.04"], ["83949.6", "0.04"], ["83986", "0"], ["83986.3", "0"], ["83986.4", "0"]], "u": 47471, "seq": 67552915920}, "cts": 1742560779888, "record_time": 1742560779.940653, "EXCHANGE": "BYBIT"}
{"topic": "orderbook.200.BTCUSDT", "ts": 1742560780120, "type": "delta", "data": {"s": "BTCUSDT", "b": [["83911.8", "0.493931"], ["83908.5", "0"], ["83908.4", "0"], ["83904.2", "0.071544"], ["83897.2", "0"], ["83874.7", "0.000518"], ["83874.6", "0.0016"], ["83874.1", "0.012881"], ["83874", "0.012881"]], "a": [["83911.9", "0.443839"], ["83935.9", "0"], ["83948.9", "0.00009"], ["83949", "0"], ["83949.1", "0.012729"], ["83949.2", "0.012729"], ["83949.5", "0"], ["83949.6", "0"], ["83949.7", "0.04"], ["83949.8", "0.04"]], "u": 47472, "seq": 67552915989}, "cts": 1742560780117, "record_time": 1742560780.141028, "EXCHANGE": "BYBIT"}
{"topic": "orderbook.200.BTCUSDT", "ts": 1742560780320, "type": "delta", "data": {"s": "BTCUSDT", "b": [["83911.8", "0.422394"], ["83909.5", "0.02186"], ["83909.4", "0.071539"], ["83904.2", "0"], ["83902.3", "0.071546"], ["83901.6", "0.245453"], ["83900.8", "0"], ["83900.3", "0"], ["83898.5", "0.071549"], ["83842", "0"], ["83841.9", "0"]], "a": [], "u": 47473, "seq": 67552916059}, "cts": 1742560780316, "record_time": 1742560780.366127, "EXCHANGE": "BYBIT"}
{"topic": "orderbook.200.BTCUSDT", "ts": 1742560780520, "type": "delta", "data": {"s": "BTCUSDT", "b": [["83911.8", "0.42303"], ["83900.1", "0.119143"], ["83866.3", "0.01339"], ["83863.5", "0.135299"], ["83842.4", "0"]], "a": [["83911.9", "0.449839"]], "u": 47474, "seq": 67552916096}, "cts": 1742560780512, "record_time": 1742560780.541473, "EXCHANGE": "BYBIT"}
{"topic": "orderbook.200.BTCUSDT", "ts": 1742560780720, "type": "delta", "data": {"s": "BTCUSDT", "b": [["83911.6", "0.021859"], ["83911.5", "0.071538"], ["83909.5", "0"], ["83909.4", "0"], ["83875.6", "0.013"], ["83875.5", "0.014347"], ["83874.1", "0"], ["83874", "0"], ["83842.4", "0.358911"]], "a": [["83933", "0.07197"], ["83947.6", "0.013"], ["83947.7", "0.012732"], ["83948.2", "0.04329"], ["83948.3", "0.602218"], ["83948.5", "0.015"], ["83949.1", "0"], ["83949.2", "0"], ["83949.7", "0"], ["83949.8", "0"], ["83986", "0.003292"]], "u": 47475, "seq": 67552916140}, "cts": 1742560780682, "record_time": 1742560780.743128, "EXCHANGE": "BYBIT"}
{"topic": "orderbook.200.BTCUSDT", "ts": 1742560780919, "type": "delta", "data": {"s": "BTCUSDT", "b": [["83911.8", "0.382157"], ["83911.6", "0"], ["83911.5", "0"], ["83908.6", "0.07154"], ["83902.3", "0"], ["83900.4", "0.071547"], ["83900.1", "0"], ["83875.6", "0.012881"], ["83842", "0.000622"], ["83841.9", "0.000413"]], "a": [["83947.6", "0.012732"], ["83948.1", "0.04"], ["83948.3", "0.562218"], ["83986", "0"]], "u": 47476, "seq": 67552916182}, "cts": 1742560780913, "record_time": 1742560780.939881, "EXCHANGE": "BYBIT"}
{"topic": "orderbook.200.BTCUSDT", "ts": 1742560781120, "type": "delta", "data": {"s": "BTCUSDT", "b": [["83909.6", "0.02186"], ["83909.5", "0.071539"], ["83908.6", "0"], ["83880.5", "0.12288"], ["83869.7", "0.001601"], ["83842", "0"], ["83841.9", "0"]], "a": [["83911.9", "0.461839"], ["83926", "0.125131"], ["83933", "0.068395"], ["83947.4", "0.013"], ["83947.5", "0.012731"], ["83947.6", "0"], ["83947.7", "0"], ["83948", "0.04"], ["83948.2", "0.00329"], ["83985.5", "0"], ["83985.7", "0"]], "u": 47477, "seq": 67552916246}, "cts": 1742560781116, "record_time": 1742560781.140607, "EXCHANGE": "BYBIT"}
{"topic": "orderbook.200.BTCUSDT", "ts": 1742560781319, "type": "delta", "data": {"s": "BTCUSDT", "b": [["83911.1", "0.021859"], ["83911", "0.071538"], ["83909.6", "0"], ["83909.5", "0"], ["83902.3", "0.071546"], ["83900.4", "0"]], "a": [["83911.9", "0.467839"]], "u": 47478, "seq": 67552916281}, "cts": 1742560781316, "record_time": 1742560781.412362, "EXCHANGE": "BYBIT"}
{"topic": "orderbook.200.BTCUSDT", "ts": 1742560781520, "type": "delta", "data": {"s": "BTCUSDT", "b": [["83911", "0"], ["83909.8", "0.071539"], ["83903.3", "0"], ["83903.2", "0.044566"], ["83900.1", "0.119143"], ["83900", "0.60321"], ["83898.5", "0"], ["83874.6", "0"], ["83874.5", "0.0015"], ["83866.3", "0.148195"], ["83863.5", "0.000454"], ["83843.3", "0"], ["83843.2", "0.236858"], ["83842.1", "0.125131"], ["83842", "0.000622"]], "a": [["83911.9", "0.473839"], ["83931", "0.003575"], ["83983.6", "0"]], "u": 47479, "seq": 67552916348}, "cts": 1742560781510, "record_time": 1742560781.54107, "EXCHANGE": "BYBIT"}
{"topic": "orderbook.200.BTCUSDT", "ts": 1742560781720, "type": "delta", "data": {"s": "BTCUSDT", "b": [["83911.8", "0.293864"], ["83911.1", "0"], ["83909.8", "0"], ["83906.9", "0.071542"], ["83906.5", "0.061953"], ["83906.4", "0"], ["83904.8", "0"], ["83903.2", "0.155149"], ["83902.3", "0"], ["83900.7", "0.0613"], ["83900.1", "0"], ["83900", "0.531662"], ["83899.9", "0.071548"], ["83897.7", "0.119549"], ["83896.9", "0.003825"], ["83894.1", "0"], ["83889.9", "0.009097"], ["83883.1", "0"], ["83882.8", "0.035761"], ["83875.6", "0"], ["83875.5", "0.001466"], ["83873.8", "0.013214"], ["83873.7", "0.012881"], ["83869.7", "0"], ["83866.3", "0.01339"], ["83864.8", "0"], ["83860.7", "0.134805"], ["83853.5", "0"], ["83847.8", "11.699406"], ["83841.9", "0.000413"], ["83841", "0.000334"], ["83840.2", "0.000333"], ["83840", "0.000414"], ["83839.9", "0.000404"]], "a": [["83911.9", "0.479695"], ["83918.4", "0.0002"], ["83919.4", "0"], ["83931", "0"], ["83940.1", "0.041466"], ["83947.3", "0.04"], ["83947.4", "0.053"], ["83948", "0"], ["83948.1", "0"], ["83963.5", "0"], ["83972", "2.606435"], ["83977.9", "0.011869"], ["83983.6", "0.119143"], ["83985.5", "0.000514"]], "u": 47480, "seq": 67552916532}, "cts": 1742560781716, "record_time": 1742560781.74059, "EXCHANGE": "BYBIT"}
{"topic": "orderbook.200.BTCUSDT", "ts": 1742560781920, "type": "delta", "data": {"s": "BTCUSDT", "b": [["83911.8", "0.2462"], ["83906.9", "0"], ["83906.5", "0"], ["83906.2", "0"], ["83903.2", "0.001466"], ["83902.9", "0"], ["83901.6", "0.171889"], ["83901.5", "0"], ["83901.2", "0"], ["83900", "0.511662"], ["83899.9", "0"], ["83899.5", "0"], ["83898.2", "0.001333"], ["83897.8", "0.093878"], ["83897.7", "0.048"], ["83896.5", "0"], ["83896.2", "0"], ["83895.2", "0.071552"], ["83894.4", "0"], ["83894.3", "0"], ["83893.6", "0"], ["83892.6", "0"], ["83890.6", "0"], ["83890.4", "0.04"], ["83889.3", "0.117204"], ["83889.2", "0"], ["83888.5", "0"], ["83886.2", "0.119143"], ["83886", "0"], ["83882.8", "0"], ["83881.2", "0"], ["83880.1", "0.526967"], ["83873.8", "0.000333"], ["83873.7", "0"], ["83873.5", "0.568474"], ["83872.3", "0.023377"], ["83869.2", "0.251185"], ["83869.1", "0.072282"], ["83860.7", "0"], ["83852.2", "0.134814"], ["83847.8", "0.018111"], ["83843.5", "0"], ["83839.5", "0.001333"], ["83839.2", "0.003259"], ["83839.1", "0.000412"], ["83838.9", "0.142925"], ["83838.6", "0.001466"], ["83838", "0.027646"], ["83837.9", "0.000518"], ["83837", "0.014117"], ["83836", "0.000333"], ["83835.3", "0.001333"], ["83835.2", "0.00009"], ["83835", "0.003259"], ["83834.6", "0.059399"], ["83834.2", "0.000332"], ["83834", "0.001466"], ["83833.3", "0.00222"], ["83833.2", "0.000518"]], "a": [["83911.9", "0.675322"], ["83912.8", "0.023834"], ["83913.9", "0.023834"], ["83915.5", "0.119172"], ["83915.6", "0.059586"], ["83915.8", "0.004021"], ["83916.3", "0.203104"], ["83917.4", "0.023834"], ["83918.7", "0.119172"], ["83922.1", "0.062422"], ["83923.6", "0.089099"], ["83924.1", "0.119505"], ["83925.7", "0"], ["83926.1", "0"], ["83929.7", "0"], ["83932", "0.529629"], ["83935.1", "0.043575"], ["83935.9", "0.562218"], ["83938.2", "0.119143"], ["83939.7", "0.112934"], ["83944.4", "0.001333"], ["83944.9", "0"], ["83948.3", "0"], ["83952.2", "2.606435"], ["83954.4", "0.098008"], ["83956.3", "0.023673"], ["83965.2", "0.059557"], ["83972", "0"], ["83981.3", "0"], ["83981.7", "0"], ["83981.8", "0"], ["83982.2", "0"], ["83982.9", "0"], ["83983", "0"], ["83983.6", "0"], ["83985.5", "0"]], "u": 47481, "seq": 67552916877}, "cts": 1742560781916, "record_time": 1742560781.94494, "EXCHANGE": "BYBIT"}
{"topic": "orderbook.200.BTCUSDT", "ts": 1742560782119, "type": "delta", "data": {"s": "BTCUSDT", "b": [["83911.8", "0.294103"], ["83903.2", "0.073011"], ["83897.7", "0"], ["83894.2", "0.062249"], ["83894.1", "0.113669"], ["83892.4", "0.04"], ["83891.7", "0.071555"], ["83889.4", "0.060865"], ["83888.8", "0.044445"], ["83887.2", "0.052"], ["83887.1", "0.044"], ["83886.1", "0.488778"], ["83885.8", "0.044"], ["83882.1", "0.019263"], ["83870.9", "0.001466"], ["83869.2", "0.238185"], ["83869.1", "0.059399"], ["83865.7", "0.012884"], ["83865.6", "0.012884"], ["83856", "0.013803"], ["83855", "0.185818"], ["83852.2", "0"], ["83838", "0"], ["83837", "0.185117"], ["83835.3", "0"], ["83835.2", "0"], ["83835", "0"], ["83834.6", "0"], ["83834.2", "0"], ["83834", "0"], ["83833.3", "0"], ["83833.2", "0"]], "a": [["83912.9", "0.023834"], ["83913.8", "0.063469"], ["83913.9", "0"], ["83914.1", "0.023834"], ["83915.5", "0.143006"], ["83915.7", "0.010121"], ["83916.2", "0.172184"], ["83916.3", "0.000512"], ["83916.5", "0.059586"], ["83916.6", "0.262178"], ["83917.2", "0"], ["83918.7", "0"], ["83919.1", "0.238344"], ["83922.1", "0.144966"], ["83923.6", "0"], ["83923.7", "0.059586"], ["83923.8", "0.059586"], ["83927.7", "0"], ["83933", "0"], ["83944.3", "0"], ["83945.7", "0.156763"], ["83949.8", "0.068366"], ["83952.2", "0"], ["83953.2", "0.171514"], ["83957.7", "0.000333"], ["83964.5", "1.125476"], ["83965.2", "0"], ["83966.4", "2.606242"], ["83979.5", "0"], ["83980", "0"], ["83980.9", "0"]], "u": 47482, "seq": 67552917080}, "cts": 1742560782118, "record_time": 1742560782.140019, "EXCHANGE": "BYBIT"}
{"topic": "orderbook.200.BTCUSDT", "ts": 1742560782320, "type": "delta", "data": {"s": "BTCUSDT", "b": [["83894.2", "0.096468"], ["83892.1", "0.044"], ["83890.8", "0.056"], ["83888.9", "0.048"], ["83885.4", "0.048"], ["83875.8", "0.035763"], ["83873.6", "0.231419"], ["83871", "0"], ["83855", "0.18581"], ["83838.9", "0"], ["83838.6", "0"], ["83837.9", "0"], ["83837", "0"], ["83836", "0"]], "a": [["83911.9", "0.794494"], ["83912.9", "0.113213"], ["83913.8", "0.151826"], ["83914.4", "0.065544"], ["83915.5", "0.202592"], ["83915.7", "0.188879"], ["83916.2", "0.338357"], ["83916.6", "0.440936"], ["83917.1", "0.180224"], ["83918.2", "0.029793"], ["83923.4", "0.007291"], ["83931.9", "0.159016"], ["83935.1", "0.04"], ["83946.6", "0.178759"], ["83951.2", "0.063462"], ["83957.1", "0"], ["83978.6", "0"], ["83978.7", "0"], ["83979.2", "0"]], "u": 47483, "seq": 67552917206}, "cts": 1742560782311, "record_time": 1742560782.341157, "EXCHANGE": "BYBIT"}
{"topic": "orderbook.200.BTCUSDT", "ts": 1742560782519, "type": "delta", "data": {"s": "BTCUSDT", "b": [["83911.8", "0.294172"], ["83904.6", "0.029454"], ["83904.5", "0.071544"], ["83903.2", "0.001466"], ["83897.3", "0.07155"], ["83891.7", "0"], ["83889.4", "0.001466"], ["83889.1", "0.059399"], ["83839.5", "0"], ["83839.2", "0"], ["83839.1", "0"]], "a": [["83913.8", "0.111094"], ["83915.7", "0.010121"], ["83916.2", "0.172184"], ["83916.6", "0.262178"], ["83917.1", "0.001466"], ["83932.9", "0.270368"], ["83941.7", "0.04"], ["83941.8", "0.04"], ["83947.3", "0"], ["83947.4", "0.013"], ["83952.2", "2.606242"], ["83966.4", "0"], ["83978.2", "0"]], "u": 47484, "seq": 67552917292}, "cts": 1742560782517, "record_time": 1742560782.545707, "EXCHANGE": "BYBIT"}
{"topic": "orderbook.200.BTCUSDT", "ts": 1742560782720, "type": "delta", "data": {"s": "BTCUSDT", "b": [["83904.6", "0"], ["83904.5", "0"], ["83903.3", "0.071545"], ["83897.3", "0"], ["83892.9", "0.071554"], ["83865.7", "0"], ["83865.5", "0.013402"], ["83857.8", "0.134808"], ["83855", "0.051004"], ["83842.2", "11.681295"]], "a": [["83912.8", "0.134333"], ["83913.8", "0"], ["83914.4", "0.089378"], ["83915.5", "0.143006"], ["83916.2", "0.248978"], ["83916.6", "0.321764"], ["83919.1", "0.119172"], ["83919.4", "0.119172"]], "u": 47485, "seq": 67552917353}, "cts": 1742560782716, "record_time": 1742560782.74094, "EXCHANGE": "BYBIT"}
{"topic": "orderbook.200.BTCUSDT", "ts": 1742560782919, "type": "delta", "data": {"s": "BTCUSDT", "b": [["83845", "11.496709"], ["83842.2", "0"]], "a": [["83946.6", "0"], ["83978.2", "0.011869"]], "u": 47486, "seq": 67552917374}, "cts": 1742560782896, "record_time": 1742560782.986966, "EXCHANGE": "BYBIT"}
{"topic": "orderbook.200.BTCUSDT", "ts": 1742560783120, "type": "delta", "data": {"s": "BTCUSDT", "b": [["83904.6", "0.029454"], ["83904.5", "0.071544"], ["83903.3", "0"], ["83897.3", "0.07155"], ["83892.9", "0"], ["83890.6", "0.030395"], ["83840", "0"], ["83839.9", "0"]], "a": [["83911.9", "0.487818"], ["83912.8", "0.098581"], ["83912.9", "0.023834"], ["83914.1", "0"], ["83914.4", "0.023834"], ["83915.2", "0.119172"], ["83915.5", "0.08342"], ["83916.1", "0.035763"], ["83916.6", "0.38504"], ["83918.7", "0.059586"], ["83919.1", "0.12513"], ["83922.1", "0.09547"], ["83922.3", "0.059586"], ["83924.1", "0.059919"], ["83926.2", "0"], ["83938.2", "0"], ["83941.7", "0"], ["83941.8", "0"], ["83942", "0.04"], ["83942.1", "0.06376"], ["83948.8", "0"], ["83978.6", "0.011869"]], "u": 47487, "seq": 67552917451}, "cts": 1742560783102, "record_time": 1742560783.143476, "EXCHANGE": "BYBIT"}
{"topic": "orderbook.200.BTCUSDT", "ts": 1742560783320, "type": "delta", "data": {"s": "BTCUSDT", "b": [["83880.5", "0.26517"], ["83866", "0.012884"], ["83865.9", "0.012884"], ["83865.6", "0"], ["83865.5", "0.000518"], ["83840.2", "0"]], "a": [["83911.9", "0.658818"], ["83916.1", "0"], ["83916.8", "0.089379"], ["83919", "0.071531"], ["83919.4", "0.178758"], ["83920", "0.018531"], ["83922.2", "0"], ["83941.4", "0.026902"], ["83941.5", "0.012727"], ["83947.4", "0"], ["83947.5", "0"], ["83978.7", "0.000333"]], "u": 47488, "seq": 67552917501}, "cts": 1742560783315, "record_time": 1742560783.341028, "EXCHANGE": "BYBIT"}
{"topic": "orderbook.200.BTCUSDT", "ts": 1742560783519, "type": "delta", "data": {"s": "BTCUSDT", "b": [["83890.4", "0.0438"], ["83874.5", "0"], ["83861.7", "0.003066"], ["83847.8", "11.51482"], ["83845", "0"], ["83840.2", "0.000333"], ["83840", "0.000414"]], "a": [["83916.1", "0.035764"], ["83916.2", "0.349661"], ["83934.3", "0.001016"], ["83941.4", "0.027175"], ["83978.6", "0"], ["83978.7", "0"]], "u": 47489, "seq": 67552917555}, "cts": 1742560783516, "record_time": 1742560783.542099, "EXCHANGE": "BYBIT"}
{"topic": "orderbook.200.BTCUSDT", "ts": 1742560783719, "type": "delta", "data": {"s": "BTCUSDT", "b": [["83847.8", "0.018111"], ["83845", "11.496709"], ["83840", "0"]], "a": [["83911.9", "0.487818"], ["83915.7", "0.000333"], ["83916.1", "0.035763"], ["83934.3", "0"], ["83935.4", "0.001299"], ["83938.5", "0.171"], ["83951.1", "1.263943"], ["83952.2", "0"], ["83969.2", "2.609332"], ["83978.6", "0.011869"]], "u": 47490, "seq": 67552917615}, "cts": 1742560783717, "record_time": 1742560783.740215, "EXCHANGE": "BYBIT"}
{"topic": "orderbook.200.BTCUSDT", "ts": 1742560783920, "type": "delta", "data": {"s": "BTCUSDT", "b": [["83860.7", "0.134811"], ["83857.8", "0"], ["83847.8", "11.348082"], ["83845", "0"], ["83840", "0.000414"]], "a": [["83911.9", "0.658818"], ["83926.9", "0.009788"], ["83935.4", "0"], ["83951.1", "0"], ["83978.7", "0.000333"]], "u": 47491, "seq": 67552917682}, "cts": 1742560783897, "record_time": 1742560783.942284, "EXCHANGE": "BYBIT"}
{"topic": "orderbook.200.BTCUSDT", "ts": 1742560784120, "type": "delta", "data": {"s": "BTCUSDT", "b": [], "a": [["83911.9", "0.487818"], ["83913.8", "0.059586"], ["83915.5", "0.023834"], ["83916.1", "0.035764"], ["83916.6", "0.325454"], ["83918.4", "0.119372"], ["83919.1", "0.005958"], ["83932.2", "0.003529"], ["83934", "0.000946"], ["83952.2", "2.606049"], ["83969.2", "0.003283"], ["83978", "0"], ["83978.2", "0"], ["83978.6", "0"], ["83978.7", "0"]], "u": 47492, "seq": 67552917740}, "cts": 1742560784109, "record_time": 1742560784.141291, "EXCHANGE": "BYBIT"}
{"topic": "orderbook.200.BTCUSDT", "ts": 1742560784319, "type": "delta", "data": {"s": "BTCUSDT", "b": [["83904.5", "0"], ["83903.6", "0.071544"], ["83895.1", "0.113568"], ["83894.2", "0.062249"], ["83894.1", "0"], ["83847.8", "0.018111"], ["83845", "11.329971"], ["83840", "0"]], "a": [["83911.9", "0.664818"], ["83912.8", "0.1441"], ["83914.1", "0.023834"], ["83915.7", "0.179091"], ["83916.1", "0"], ["83916.4", "0.178758"], ["83916.6", "0.38504"], ["83917.1", "0.180224"], ["83934", "0"]], "u": 47493, "seq": 67552917820}, "cts": 1742560784309, "record_time": 1742560784.341005, "EXCHANGE": "BYBIT"}
{"topic": "orderbook.200.BTCUSDT", "ts": 1742560784520, "type": "delta", "data": {"s": "BTCUSDT", "b": [["83904.5", "0.071544"], ["83903.6", "0"]], "a": [["83916.2", "0.385424"], ["83916.4", "0"], ["83978", "0.001333"]], "u": 47494, "seq": 67552917847}, "cts": 1742560784504, "record_time": 1742560784.557261, "EXCHANGE": "BYBIT"}
{"success": true, "ret_msg": "subscribe", "conn_id": "fa371f6b-40ba-4710-a354-60d92f86e1a1", "op": "subscribe", "record_time": 1742561031.051741, "EXCHANGE": "BYBIT"}
{"topic": "orderbook.200.BTCUSDT", "ts": 1742561030319, "type": "snapshot", "data": {"s": "BTCUSDT", "b": [["83714.2", "0.004691"], ["83713.8", "0.001333"], ["83713.5", "0.003196"], ["83713.4", "0.000508"], ["83712.8", "0.000083"], ["83711.3", "0.009"], ["83710.4", "0.000333"], ["83709.7", "0.001133"], ["83709.6", "0.00221"], ["83709.3", "0.003524"], ["83708.8", "0.000864"], ["83708", "0.001969"], ["83707.9", "0.000231"], ["83707.7", "0.005767"], ["83707.1", "0.00015"], ["83706.3", "0.00006"], ["83706.2", "0.005456"], ["83705.9", "0.098093"], ["83705.8", "0.176"], ["83705.5", "0.001333"], ["83705.1", "0.003259"], ["83705", "0.001466"], ["83704.9", "0.00065"], ["83704.6", "0.04"], ["83704.4", "0.04"], ["83704.2", "0.000518"], ["83703.6", "0.000125"], ["83703", "0.000218"], ["83702.9", "0.052"], ["83702.7", "0.04"], ["83702.2", "0.000051"], ["83702", "0.000333"], ["83701.3", "0.001333"], ["83701.1", "0.054875"], ["83701", "0.000313"], ["83700.9", "0.047259"], ["83700.8", "0.00009"], ["83700.6", "0.251952"], ["83700.5", "0.001979"], ["83700.4", "0.001525"], ["83700.3", "0.000119"], ["83700.2", "0.000306"], ["83700.1", "0.119299"], ["83700", "0.612068"], ["83699.7", "0.000171"], ["83699.6", "0.000518"], ["83699.4", "0.044"], ["83698.4", "0.00306"], ["83698.2", "0.0002"], ["83698", "0.000467"], ["83697.9", "0.101"], ["83697.8", "0.000333"], ["83697.7", "0.048"], ["83697.6", "0.0071"], ["83697.1", "0.001333"], ["83697", "0.149276"], ["83696.9", "0.048"], ["83696.8", "0.003259"], ["83696.6", "0.001548"], ["83696.5", "0.0045"], ["83696.3", "0.001259"], ["83696", "0.171"], ["83695.8", "0.001466"], ["83695.6", "0.004318"], ["83695.5", "0.001116"], ["83695.4", "0.000359"], ["83695", "0.119817"], ["83694.8", "0.071723"], ["83694.5", "0.000358"], ["83693.6", "0.000333"], ["83693.5", "0.018932"], ["83692.9", "0.001517"], ["83692.6", "0.003259"], ["83692.4", "0.061355"], ["83692.3", "0.000495"], ["83692.2", "0.000825"], ["83692", "0.000268"], ["83691.8", "0.000241"], ["83691.6", "0.00022"], ["83691.5", "0.000539"], ["83691.2", "0.001638"], ["83690.7", "0.006531"], ["83690.5", "0.009729"], ["83690.4", "0.000518"], ["83690", "0.000695"], ["83689.9", "0.059399"], ["83689.8", "0.119299"], ["83689.5", "0.000385"], ["83689.4", "0.000333"], ["83689", "0.000236"], ["83688.9", "0.00013"], ["83688.8", "0.000133"], ["83688.7", "0.001333"], ["83688.4", "0.003259"], ["83688.2", "0.000315"], ["83688", "0.001194"], ["83687.7", "0.205699"], ["83687.6", "0.171"], ["83687.4", "0.012263"], ["83687.2", "0.000383"], ["83686.8", "0.504033"], ["83686.6", "0.001585"], ["83686.5", "0.018111"], ["83686.3", "0.0015"], ["83686.2", "0.000016"], ["83686.1", "0.000022"], ["83685.8", "0.000518"], ["83685.6", "0.000267"], ["83685.3", "0.001592"], ["83685", "0.000321"], ["83684.6", "0.004627"], ["83684.5", "0.001333"], ["83684.3", "0.067354"], ["83684.2", "0.131197"], ["83684.1", "0.001944"], ["83684", "0.00009"], ["83683.6", "0.00478"], ["83683.5", "0.000121"], ["83682.9", "0.00009"], ["83682", "0.00794"], ["83681.8", "0.000448"], ["83681.7", "0.000128"], ["83681.3", "0.009"], ["83681.2", "0.001455"], ["83681.1", "0.059732"], ["83680.5", "0.01002"], ["83680.4", "0.001333"], ["83680", "0.004561"], ["83679.6", "0.125142"], ["83679.5", "0.247714"], ["83679.2", "0.171"], ["83679.1", "0.142632"], ["83678.5", "0.000203"], ["83677.7", "1.003598"], ["83677.6", "3.318604"], ["83677.4", "0.001466"], ["83676.9", "0.000333"], ["83676.6", "0.001039"], ["83676.2", "0.001333"], ["83676", "0.004128"], ["83675.8", "0.003259"], ["83675.6", "0.000269"], ["83675.4", "0.001537"], ["83674.7", "0.000473"], ["83674.2", "0.49579"], ["83674", "0.000913"], ["83673.9", "0.000539"], ["83673.7", "0.01766"], ["83673.3", "0.000522"], ["83673.2", "0.001455"], ["83672.9", "0.119299"], ["83672.8", "0.001466"], ["83672.7", "0.000333"], ["83672.6", "0.015"], ["83672.4", "0.01231"], ["83672", "0.001851"], ["83671.7", "0.003259"], ["83671.2", "0.007502"], ["83670.8", "0.171167"], ["83670.5", "0.000133"], ["83670", "0.010014"], ["83669", "0.011352"], ["83668.5", "0.000333"], ["83668.4", "0.059399"], ["83668.3", "0.000422"], ["83668.2", "0.001466"], ["83668", "0.000693"], ["83667.8", "0.001333"], ["83667.5", "0.005602"], ["83667.4", "0.000518"], ["83667.3", "0.000472"], ["83667.2", "0.02398"], ["83667.1", "0.001581"], ["83667", "0.000059"], ["83666.9", "0.000035"], ["83666.6", "0.00752"], ["83666.5", "0.009205"], ["83666.4", "0.003614"], ["83666.3", "0.024967"], ["83666", "0.012884"], ["83665.9", "0.012885"], ["83665.2", "0.000024"], ["83665", "0.003886"], ["83664.8", "0.02389"], ["83664.5", "0.119323"], ["83664.3", "0.000333"], ["83664.2", "0.00081"], ["83663.6", "0.00313"], ["83663.3", "0.003259"], ["83662.8", "0.000518"], ["83662.6", "0.001007"], ["83662.5", "0.00067"], ["83662.4", "0.171"], ["83661.6", "0.013764"], ["83661.4", "0.024039"], ["83661", "0.005871"], ["83660.9", "0.000436"], ["83660.4", "0.02389"], ["83660.2", "0.000333"], ["83660", "0.000214"]], "a": [["83714.3", "0.758763"], ["83714.6", "0.211358"], ["83714.7", "0.05717"], ["83716.3", "0.319009"], ["83718.1", "0.153"], ["83718.7", "0.252781"], ["83718.8", "0.062986"], ["83718.9", "0.05"], ["83719.2", "0.17917"], ["83719.6", "0.023889"], ["83719.7", "0.03"], ["83720", "0.11969"], ["83720.6", "0.059725"], ["83721", "0.089099"], ["83721.4", "0.179177"], ["83721.6", "0.00717"], ["83721.9", "0.003149"], ["83722.2", "0.082513"], ["83722.3", "0.03"], ["83722.5", "0.02"], ["83722.6", "0.054133"], ["83722.8", "0.119451"], ["83722.9", "0.000333"], ["83723.2", "0.119716"], ["83723.4", "0.001466"], ["83723.6", "0.050401"], ["83723.9", "0.007169"], ["83724.4", "0.0002"], ["83724.7", "0.005"], ["83725.1", "0.003888"], ["83726.1", "0.021554"], ["83726.2", "0.226972"], ["83726.4", "0.001333"], ["83727", "0.068379"], ["83727.1", "0.000333"], ["83727.2", "0.059725"], ["83727.3", "0.005508"], ["83727.4", "0.065007"], ["83727.8", "0.089099"], ["83728", "0.001466"], ["83728.5", "0.012"], ["83728.7", "0.001"], ["83729.3", "0.059399"], ["83730.2", "0.003165"], ["83730.3", "0.00903"], ["83730.6", "0.001333"], ["83731", "0.00009"], ["83731.3", "0.000333"], ["83731.5", "0.303009"], ["83731.9", "0.000508"], ["83732.6", "0.001466"], ["83732.9", "0.04"], ["83733.1", "0.044"], ["83733.6", "0.470034"], ["83733.7", "0.021411"], ["83733.9", "0.04"], ["83734.2", "0.04"], ["83734.4", "0.003165"], ["83734.8", "0.001333"], ["83735", "0.04"], ["83735.5", "0.000333"], ["83735.7", "0.04"], ["83736.5", "0.040508"], ["83737.3", "0.001466"], ["83737.7", "0.153838"], ["83737.8", "0.099698"], ["83737.9", "0.221"], ["83738.2", "0.04"], ["83738.4", "0.089099"], ["83738.6", "0.003167"], ["83739", "0.001333"], ["83739.4", "0.00009"], ["83739.7", "0.000333"], ["83740", "0.00024"], ["83741.1", "0.000508"], ["83741.6", "0.001682"], ["83741.9", "0.001466"], ["83742.2", "0.150743"], ["83742.3", "0.05971"], ["83742.5", "0.004674"], ["83742.8", "0.003172"], ["83743.1", "0.001333"], ["83743.3", "0.17913"], ["83743.5", "0.0006"], ["83743.8", "0.11942"], ["83743.9", "0.000333"], ["83744.7", "0.131355"], ["83744.8", "0.11942"], ["83745.3", "0.04469"], ["83745.7", "0.000508"], ["83746", "0.0006"], ["83746.5", "0.060865"], ["83746.6", "0.171"], ["83746.7", "0.03584"], ["83747", "0.003172"], ["83747.3", "0.001333"], ["83747.8", "0.00009"], ["83748", "0.000333"], ["83749.6", "0.011951"], ["83749.9", "0.954769"], ["83750", "0.473987"], ["83750.2", "0.063477"], ["83750.3", "0.000508"], ["83750.4", "0.060068"], ["83751.1", "0.001466"], ["83751.2", "0.003172"], ["83751.5", "2.606251"], ["83751.9", "0.119299"], ["83752.2", "0.000333"], ["83752.3", "0.197472"], ["83754.2", "0.089099"], ["83754.7", "0.011884"], ["83754.9", "0.000508"], ["83755.4", "0.086458"], ["83755.6", "0.073887"], ["83755.7", "0.002799"], ["83755.8", "0.003564"], ["83756.1", "1.43253"], ["83756.2", "0.00009"], ["83756.4", "0.191333"], ["83756.5", "0.0045"], ["83756.6", "0.012525"], ["83756.7", "0.012524"], ["83756.8", "0.02389"], ["83757.7", "0.002129"], ["83757.8", "0.119299"], ["83758", "0.638937"], ["83758.1", "0.04"], ["83758.2", "0.576322"], ["83758.5", "0.023887"], ["83759.5", "0.000508"], ["83759.6", "0.003172"], ["83759.9", "0.001333"], ["83760", "0.00024"], ["83760.3", "0.051466"], ["83760.6", "0.000333"], ["83760.7", "0.013887"], ["83760.9", "0.023887"], ["83762", "0.018287"], ["83762.9", "0.024596"], ["83763.3", "0.119299"], ["83763.7", "0.003174"], ["83763.8", "0.059399"], ["83764.1", "0.001843"], ["83764.3", "0.005971"], ["83764.6", "0.00009"], ["83764.8", "0.000333"], ["83764.9", "0.001466"], ["83765", "0.003564"], ["83765.3", "3.134453"], ["83766", "0.000118"], ["83767.6", "0.354837"], ["83767.9", "0.003175"], ["83768", "0.098008"], ["83768.3", "0.172333"], ["83768.4", "0.119299"], ["83768.7", "0.00051"], ["83769", "0.001447"], ["83769.5", "0.001466"], ["83771", "0.05791"], ["83771.1", "0.059694"], ["83771.3", "0.009"], ["83771.5", "0.011884"], ["83772.1", "0.003179"], ["83772.2", "0.023881"], ["83772.3", "0.059399"], ["83772.4", "0.023881"], ["83772.5", "0.001691"], ["83773", "0.00009"], ["83773.2", "0.000333"], ["83773.3", "0.00051"], ["83773.6", "0.023882"], ["83774.1", "0.001466"], ["83774.5", "0.003564"], ["83775", "0.0006"], ["83775.2", "0.059918"], ["83775.3", "0.14318"], ["83776.3", "0.003179"], ["83776.6", "0.001333"], ["83777.4", "0.171333"], ["83777.7", "0.023881"], ["83777.9", "0.00051"], ["83778.7", "0.001466"], ["83780", "0.00024"], ["83780.5", "0.003269"], ["83780.8", "0.001333"], ["83781.1", "0.00597"], ["83781.4", "0.00009"], ["83781.6", "0.000333"], ["83781.7", "0.059399"], ["83782.5", "0.00051"], ["83783.3", "0.001466"], ["83783.8", "1.127904"], ["83784.4", "0.028129"], ["83784.5", "0.000034"], ["83784.7", "0.003179"], ["83785", "0.013325"], ["83785.3", "0.119299"], ["83785.6", "0.101091"], ["83785.7", "0.000333"]], "u": 48723, "seq": 67553226376}, "cts": 1742561030313, "record_time": 1742561031.053174, "EXCHANGE": "BYBIT"}
{"topic": "orderbook.200.BTCUSDT", "ts": 1742561030519, "type": "delta", "data": {"s": "BTCUSDT", "b": [["83714.2", "0.034591"], ["83707.7", "0.005768"], ["83706.2", "0.000456"], ["83705.8", "0.181"], ["83704.4", "0.111715"], ["83703.2", "0.023096"], ["83700.1", "0"], ["83696.8", "0.07498"], ["83694.8", "0"], ["83692.6", "0.074984"], ["83688.1", "0.021344"], ["83683.6", "0"], ["83683.5", "0.004901"], ["83666", "0"], ["83665.9", "0"], ["83665.6", "0.013"], ["83665.5", "0.012884"], ["83662.6", "0.100267"], ["83659.9", "0.059482"]], "a": [["83714.3", "0.595197"], ["83714.6", "0.063904"], ["83714.7", "0.00717"], ["83716.3", "0.171"], ["83717.3", "0.000078"], ["83718.1", "0.123"], ["83719.9", "0.012"], ["83721", "0"], ["83722.2", "0.093128"], ["83722.7", "0.005"], ["83727", "0.113517"], ["83727.3", "0.000508"], ["83728.5", "0"], ["83729.6", "0.04"], ["83742.2", "0"], ["83751.5", "0.001333"], ["83752.3", "0.599212"], ["83758", "0"]], "u": 48724, "seq": 67553226570}, "cts": 1742561030518, "record_time": 1742561031.05426, "EXCHANGE": "BYBIT"}
{"topic": "orderbook.200.BTCUSDT", "ts": 1742561030720, "type": "delta", "data": {"s": "BTCUSDT", "b": [["83704.4", "0.04"], ["83700.1", "0.119299"], ["83694.2", "0.119064"], ["83688.1", "0"], ["83687.2", "0.173188"], ["83686.1", "0.023645"], ["83680.2", "0.275634"], ["83665.4", "0.09926"], ["83662.6", "0.001007"], ["83660.2", "0"], ["83660", "0"], ["83659.9", "0"]], "a": [["83714.6", "0.089556"], ["83717.9", "0.023898"], ["83727.1", "0.125255"], ["83734.1", "0.177154"], ["83734.2", "0"], ["83741.1", "0.31131"], ["83743.2", "0.089745"], ["83749.9", "0.19805"], ["83750.2", "0.063473"], ["83751.5", "2.606031"], ["83785.6", "0"], ["83785.7", "0"]], "u": 48725, "seq": 67553226643}, "cts": 1742561030717, "record_time": 1742561031.055238, "EXCHANGE": "BYBIT"}
{"topic": "orderbook.200.BTCUSDT", "ts": 1742561030919, "type": "delta", "data": {"s": "BTCUSDT", "b": [["83668.2", "0.10071"], ["83665.4", "0"], ["83660.2", "0.000333"]], "a": [["83714.3", "0.601197"], ["83717.3", "0"], ["83722.7", "0.01"], ["83724.7", "0"], ["83725.3", "0.024712"], ["83749.9", "0.973745"], ["83785.6", "0.101091"]], "u": 48726, "seq": 67553226697}, "cts": 1742561030908, "record_time": 1742561031.056056, "EXCHANGE": "BYBIT"}
{"topic": "orderbook.200.BTCUSDT", "ts": 1742561031120, "type": "delta", "data": {"s": "BTCUSDT", "b": [["83714.2", "0.463993"], ["83707.9", "0.023675"], ["83699.3", "0.071719"], ["83696.8", "0.003259"], ["83694.2", "0"], ["83692.6", "0.003259"], ["83687.2", "0.000383"], ["83680.2", "0"], ["83665.8", "0.013"], ["83665.7", "0.012884"], ["83665.6", "0"], ["83665.5", "0"], ["83660", "0.000214"]], "a": [["83714.3", "0.206917"], ["83714.6", "0"], ["83716.3", "0"], ["83717.9", "0.024051"], ["83718.1", "0.103"], ["83718.9", "0"], ["83719.2", "0"], ["83719.7", "0"], ["83720", "0.00024"], ["83720.6", "0"], ["83722.5", "0"], ["83722.8", "0"], ["83723.6", "0.030401"], ["83726.2", "0.204823"], ["83727", "0.068379"], ["83727.1", "0.000333"], ["83727.2", "0"], ["83727.8", "0"], ["83734.1", "0"], ["83738.4", "0"], ["83741", "0.204749"], ["83741.1", "0.000508"], ["83743.2", "0"], ["83745.7", "0.013508"], ["83745.8", "0.01252"], ["83746.2", "0.04"], ["83746.3", "0.04"], ["83750.2", "0"], ["83751.5", "0.001333"], ["83753", "0.063473"], ["83756.6", "0"], ["83756.7", "0"], ["83758.1", "0"], ["83758.2", "0.536322"], ["83776.9", "2.604698"], ["83785.7", "0.000333"], ["83786.5", "0.0045"], ["83787.1", "0.00051"], ["83787.5", "0.011992"], ["83787.6", "0.258216"], ["83787.9", "0.001466"], ["83788.3", "0.011884"], ["83788.9", "0.003182"], ["83789.2", "0.001333"], ["83789.8", "0.00009"], ["83789.9", "0.000333"]], "u": 48727, "seq": 67553226852}, "cts": 1742561031117, "record_time": 1742561031.137462, "EXCHANGE": "BYBIT"}
{"topic": "orderbook.200.BTCUSDT", "ts": 1742561031320, "type": "delta", "data": {"s": "BTCUSDT", "b": [["83718.6", "0.789902"], ["83718.4", "0.107019"], ["83718.3", "0.356396"], ["83714.6", "0.000333"], ["83714.3", "0.212752"], ["83714.2", "0.412398"], ["83713.3", "0.071707"], ["83712.8", "0.089182"], ["83710.7", "0.04"], ["83710.2", "0.005"], ["83707.9", "0.000231"], ["83707.6", "0.023094"], ["83707.3", "0.110658"], ["83707.2", "0.071712"], ["83706.7", "0.003849"], ["83706", "0.119299"], ["83705.9", "0.283811"], ["83705.8", "0.176"], ["83704.3", "0.009729"], ["83704.2", "0.044518"], ["83703.2", "0.552033"], ["83702.2", "0.08915"], ["83701.2", "0.059399"], ["83701.1", "0"], ["83700", "0.671805"], ["83699.3", "0"], ["83693.8", "0.003576"], ["83693.5", "0"], ["83692.4", "0.057506"], ["83690.6", "0.49579"], ["83690.5", "0"], ["83688.1", "0.021391"], ["83686.8", "0"], ["83685.6", "0.089366"], ["83684.6", "0.029398"], ["83680.8", "0.011951"], ["83679.6", "0.099236"], ["83679.1", "0.119455"], ["83674.2", "0"], ["83668.2", "0.001466"], ["83665.8", "0.012884"], ["83663.6", "0"], ["83663.3", "0"], ["83662.8", "0"], ["83662.6", "0"], ["83662.5", "0"], ["83662.4", "0"], ["83661.6", "0"], ["83661.4", "0"], ["83661", "0"], ["83660.9", "0"], ["83660.4", "0"], ["83660.2", "0"], ["83660", "0"]], "a": [["83714.3", "0"], ["83714.7", "0"], ["83717.9", "0"], ["83718.1", "0"], ["83718.7", "0.050197"], ["83718.8", "0"], ["83719.6", "0"], ["83719.9", "0"], ["83721.4", "0"], ["83721.6", "0"], ["83722.2", "0.001333"], ["83722.3", "0"], ["83722.6", "0.000508"], ["83723.2", "0"], ["83723.6", "0.000401"], ["83723.9", "0"], ["83725.1", "0"], ["83725.3", "0"], ["83726.1", "0.003149"], ["83726.2", "0.003823"], ["83727", "0"], ["83727.4", "0"], ["83729.3", "0"], ["83729.5", "0.01454"], ["83729.6", "0.012"], ["83729.7", "0.024711"], ["83730.3", "0"], ["83731.5", "0"], ["83732.9", "0"], ["83733.1", "0"], ["83733.6", "0"], ["83733.9", "0"], ["83734.8", "0.005221"], ["83735", "0"], ["83735.6", "0.000153"], ["83735.7", "0.065"], ["83736.5", "0.000508"], ["83737.7", "0.109586"], ["83737.8", "0.059698"], ["83738.2", "0"], ["83739.4", "0.04009"], ["83741", "0"], ["83742.3", "0"], ["83742.5", "0.023079"], ["83743.3", "0"], ["83743.8", "0"], ["83744.1", "0.04"], ["83744.3", "0.00903"], ["83744.8", "0"], ["83745.7", "0.040508"], ["83745.8", "0"], ["83746.2", "0"], ["83746.3", "0"], ["83749.9", "0.668084"], ["83751.9", "0"], ["83753", "0"], ["83754.1", "0.013"], ["83754.2", "0.01252"], ["83754.6", "0.04"], ["83754.7", "0.051884"], ["83756.1", "0"], ["83757.8", "0"], ["83758.1", "0.185178"], ["83762.9", "0"], ["83763.6", "0.00215"], ["83768.4", "0.144327"], ["83772.8", "0.063473"], ["83776.9", "0"], ["83783.8", "0"], ["83785.8", "0.171"], ["83787.6", "0"], ["83790.2", "0.023984"], ["83790.3", "0.059399"], ["83790.6", "0.011992"], ["83791", "0.022305"], ["83791.4", "0.0442"], ["83791.8", "0.00051"], ["83792.5", "0.120765"], ["83793.1", "0.003182"], ["83793.4", "0.001333"], ["83794.1", "0.000333"], ["83794.6", "0.000358"], ["83796.4", "0.00051"], ["83796.7", "0.011894"], ["83796.8", "0.0006"], ["83797.1", "0.001466"], ["83797.3", "0.003182"], ["83797.5", "0.011894"], ["83797.6", "0.001333"], ["83797.9", "0.357954"], ["83798.1", "0.1"], ["83798.2", "0.00009"], ["83798.3", "0.050333"], ["83798.7", "0.044535"], ["83798.8", "0.05"], ["83799", "0.00315"], ["83799.1", "0.004165"], ["83799.4", "0.119299"], ["83799.5", "0.059399"], ["83799.9", "0.011895"], ["83800.1", "0.22957"]], "u": 48728, "seq": 67553227689}, "cts": 1742561031316, "record_time": 1742561031.341908, "EXCHANGE": "BYBIT"}
{"topic": "orderbook.200.BTCUSDT", "ts": 1742561031520, "type": "delta", "data": {"s": "BTCUSDT", "b": [["83718.6", "0.853791"], ["83718.4", "0"], ["83718.3", "0"], ["83713.1", "0.0135"], ["83710.2", "0.01"], ["83709.2", "0.00009"], ["83709", "0.135836"], ["83708.9", "0.04"], ["83708.7", "0.119701"], ["83707.3", "0.052"], ["83705.8", "0.171"], ["83705.7", "0.044"], ["83704.4", "0"], ["83702.9", "0"], ["83699.4", "0"], ["83698.2", "0.178588"], ["83697.9", "0.057"], ["83697.7", "0"], ["83697", "0"], ["83696.1", "0.090703"], ["83692.4", "0.199066"], ["83691.2", "0.313543"], ["83687.7", "0.062273"], ["83686.3", "0"], ["83684.4", "0.0016"], ["83679.6", "0"], ["83671.1", "0.099236"]], "a": [["83718.7", "0.127468"], ["83719.5", "0.00717"], ["83722.7", "0.005"], ["83725.9", "0.007169"], ["83726.6", "0.091795"], ["83727", "0.053625"], ["83727.1", "0.005333"], ["83729.5", "0"], ["83729.6", "0.015814"], ["83733.2", "0.120385"], ["83735.5", "0.000632"], ["83737.2", "0.04"], ["83737.6", "0.000299"], ["83737.8", "0.059399"], ["83740.9", "0.022752"], ["83741", "0.044"], ["83742.5", "0.018405"], ["83743.7", "0.186884"], ["83744.4", "0.043529"], ["83750.4", "0.000358"], ["83750.7", "0.286422"], ["83752.3", "0.197472"], ["83754.1", "0"], ["83754.2", "0"], ["83754.6", "0"], ["83754.7", "0.011884"], ["83755.1", "0.01252"], ["83755.2", "0.01252"], ["83755.6", "0.113887"], ["83755.7", "0.042799"], ["83761.9", "0.063164"], ["83765.2", "1.172762"], ["83765.6", "0.246436"], ["83770", "0.063473"], ["83772.8", "0"], ["83782.6", "0.12542"], ["83788.2", "2.604698"], ["83794.2", "0.171"], ["83797.1", "0"], ["83797.3", "0"], ["83797.5", "0"], ["83797.6", "0"], ["83797.9", "0"], ["83798.1", "0"], ["83798.2", "0"], ["83798.3", "0"], ["83798.7", "0"], ["83798.8", "0"], ["83799", "0"], ["83799.1", "0"], ["83799.4", "0"], ["83799.5", "0"], ["83799.9", "0"], ["83800.1", "0"]], "u": 48729, "seq": 67553227888}, "cts": 1742561031515, "record_time": 1742561031.541725, "EXCHANGE": "BYBIT"}
{"topic": "orderbook.200.BTCUSDT", "ts": 1742561031719, "type": "delta", "data": {"s": "BTCUSDT", "b": [["83718.6", "0.782088"], ["83718.5", "0.021611"], ["83718.4", "0.071703"], ["83714.3", "0.147105"], ["83713.3", "0"], ["83712.8", "0.000083"], ["83709.4", "0.07171"], ["83708.7", "0"], ["83707.3", "0.096"], ["83707.2", "0"], ["83705.6", "0.044473"], ["83705.3", "0.071714"], ["83704.6", "0"], ["83704.5", "0.048"], ["83702.7", "0"], ["83702.4", "0.052"], ["83702.2", "0.000051"], ["83701.2", "0"], ["83698.2", "0.0002"], ["83697.9", "0.005"], ["83693.8", "0"], ["83691.2", "0.001638"], ["83679.6", "0.099236"], ["83671.1", "0"]], "a": [["83722.7", "0"], ["83726.5", "0.043626"], ["83727", "0.116207"], ["83727.1", "0.181333"], ["83727.9", "0.007169"], ["83729.6", "0"], ["83732.3", "0.016516"], ["83732.4", "0.023791"], ["83733.2", "0"], ["83739.9", "0.04"], ["83740.9", "0.074571"], ["83741", "0.084"], ["83741.7", "0.04"], ["83742.7", "0.04"], ["83743.7", "0"], ["83750.7", "0"], ["83755.1", "0.017134"], ["83758", "0.119299"], ["83761.5", "0.063472"], ["83770", "0"], ["83776.9", "2.604698"], ["83780", "0.089826"], ["83788.2", "0"], ["83791.4", "0"], ["83796.7", "0"], ["83796.8", "0"]], "u": 48730, "seq": 67553228035}, "cts": 1742561031714, "record_time": 1742561031.736404, "EXCHANGE": "BYBIT"}
{"topic": "orderbook.200.BTCUSDT", "ts": 1742561031920, "type": "delta", "data": {"s": "BTCUSDT", "b": [["83718.4", "0"], ["83717.5", "0.071703"], ["83710.2", "0.015"], ["83700.9", "0.003259"], ["83700.7", "0.059399"], ["83699.1", "0.006759"], ["83696.9", "0"], ["83673.2", "0.015154"], ["83664.2", "0"]], "a": [["83718.7", "0.127946"], ["83727.1", "0.186333"], ["83731.8", "0.012"], ["83749.9", "0.470034"], ["83796.4", "0"]], "u": 48731, "seq": 67553228094}, "cts": 1742561031912, "record_time": 1742561031.938837, "EXCHANGE": "BYBIT"}
{"topic": "orderbook.200.BTCUSDT", "ts": 1742561032119, "type": "delta", "data": {"s": "BTCUSDT", "b": [["83718.5", "0.071703"], ["83717.5", "0"], ["83707.7", "0.001977"], ["83705.6", "0"], ["83705.5", "0.045866"], ["83698.6", "0.018353"], ["83698.4", "0.00006"], ["83674.1", "0.012883"], ["83674", "0.013796"], ["83665.8", "0"], ["83665.7", "0"], ["83664.2", "0.00081"], ["83663.6", "0.00313"]], "a": [["83718.7", "0.128185"], ["83726.5", "0.029781"], ["83727", "0.070058"], ["83727.1", "0.015333"], ["83740.3", "0.003"], ["83749.8", "0.285357"], ["83754.6", "0.01253"], ["83754.7", "0.024414"], ["83755.1", "0.004614"], ["83755.2", "0"], ["83782.6", "0"], ["83794.6", "0"]], "u": 48732, "seq": 67553228142}, "cts": 1742561032117, "record_time": 1742561032.136502, "EXCHANGE": "BYBIT"}
{"topic": "orderbook.200.BTCUSDT", "ts": 1742561032320, "type": "delta", "data": {"s": "BTCUSDT", "b": [["83698.6", "0"], ["83698.5", "0.018338"], ["83666.8", "5.676043"], ["83663.6", "0"]], "a": [["83754.6", "0"], ["83754.7", "0.011884"], ["83754.8", "0.01253"], ["83754.9", "0.013038"]], "u": 48733, "seq": 67553228164}, "cts": 1742561032304, "record_time": 1742561032.394871, "EXCHANGE": "BYBIT"}
{"topic": "orderbook.200.BTCUSDT", "ts": 1742561032520, "type": "delta", "data": {"s": "BTCUSDT", "b": [["83718.6", "0.297616"], ["83705.5", "0.001333"], ["83698.5", "0"], ["83698.4", "0.018666"], ["83666.8", "0"], ["83663.9", "0.129088"], ["83663.6", "0.00313"]], "a": [["83718.7", "0.165828"], ["83728.7", "0"], ["83736.2", "0.011884"], ["83753", "0.011884"], ["83754.7", "0"], ["83755.3", "0.04"], ["83755.4", "0.126458"], ["83755.6", "0.073887"], ["83755.7", "0.002799"], ["83769", "0.000333"], ["83769.8", "0.011884"], ["83771.5", "0"], ["83776.9", "0"], ["83779.7", "2.604683"], ["83786.6", "0.011884"], ["83788.3", "0"], ["83792", "1.127793"], ["83794.1", "0"], ["83794.2", "0"]], "u": 48734, "seq": 67553228239}, "cts": 1742561032504, "record_time": 1742561032.588598, "EXCHANGE": "BYBIT"}
{"topic": "orderbook.200.BTCUSDT", "ts": 1742561032720, "type": "delta", "data": {"s": "BTCUSDT", "b": [["83721.8", "0.437035"], ["83720", "0.00006"], ["83718.7", "0.0513"], ["83718.6", "0.171"], ["83718.5", "0"], ["83714.3", "0.097305"], ["83714.2", "0.241398"], ["83713.4", "0.015508"], ["83710.2", "0"], ["83709.4", "0"], ["83708.7", "0.071711"], ["83707.6", "0"], ["83706.2", "0.072169"], ["83705.3", "0"], ["83704.8", "0.089099"], ["83698.4", "0.00006"], ["83693.5", "0.023563"], ["83687.7", "0.087856"], ["83684.6", "0.004627"], ["83674.2", "0.012884"], ["83674", "0.000913"], ["83663.9", "0"], ["83663.6", "0"]], "a": [["83718.7", "0"], ["83719.5", "0"], ["83720", "0"], ["83721.9", "0.162485"], ["83722", "0.000401"], ["83723.6", "0"], ["83725.9", "0"], ["83726.5", "0.043626"], ["83727", "0.053625"], ["83727.1", "0.000333"], ["83729.7", "0"], ["83730.3", "0.022169"], ["83731", "0"], ["83731.8", "0"], ["83732.3", "0"], ["83732.4", "0"], ["83735.2", "0.000299"], ["83735.5", "0.000333"], ["83736.1", "0.083924"], ["83737.2", "0"], ["83737.6", "0.059698"], ["83737.7", "0"], ["83737.8", "0"], ["83739.4", "0.00009"], ["83739.9", "0"], ["83740.9", "0.041306"], ["83741", "0"], ["83741.7", "0"], ["83742.7", "0"], ["83744.1", "0"], ["83744.4", "0.003529"], ["83745.7", "0.000508"], ["83747.6", "0.044"], ["83751", "0.04"], ["83754.8", "0"], ["83754.9", "0.000508"], ["83755.3", "0"], ["83755.4", "0.086458"], ["83755.6", "0.086887"], ["83755.7", "0.015329"], ["83756.1", "0.04"], ["83756.2", "0.04009"], ["83758", "0"], ["83758.2", "0"], ["83761.5", "0"], ["83765.3", "0.002078"], ["83768.4", "0.119299"], ["83772.8", "0.063469"], ["83774.8", "0.536322"], ["83777.4", "0.195043"], ["83779.7", "0"], ["83785.6", "0.089099"], ["83790.4", "3.132375"], ["83792", "0"], ["83794.1", "0.000333"], ["83794.6", "0.000358"], ["83796.4", "0.00051"], ["83796.7", "0.011894"], ["83796.8", "0.0006"], ["83797.1", "0.001466"], ["83797.3", "0.003182"], ["83797.5", "0.011894"], ["83797.6", "0.001333"], ["83797.9", "0.357954"], ["83798.1", "0.6271"], ["83798.2", "0.00009"], ["83798.3", "0.000333"], ["83799", "0.00315"], ["83799.1", "0.004165"]], "u": 48735, "seq": 67553228759}, "cts": 1742561032711, "record_time": 1742561032.737893, "EXCHANGE": "BYBIT"}
{"topic": "orderbook.200.BTCUSDT", "ts": 1742561032919, "type": "delta", "data": {"s": "BTCUSDT", "b": [["83721.8", "0.434288"], ["83710.4", "0.109074"], ["83706.7", "0.055849"], ["83704.8", "0"], ["83702.4", "0"], ["83700.6", "0.41829"], ["83693.5", "0"], ["83691.5", "0.300262"], ["83674.2", "0"], ["83674.1", "0"], ["83673.6", "0.013"], ["83673.5", "0.012884"], ["83663.6", "0.00313"], ["83663.3", "0.003259"], ["83662.8", "0.000518"]], "a": [["83721.9", "0.165471"], ["83724.9", "0.000153"], ["83735.5", "0.142338"], ["83735.6", "0.10905"], ["83736.1", "0"], ["83740.9", "0.03215"], ["83741", "0.08"], ["83742.7", "0.04"], ["83745.4", "0.184176"], ["83747.3", "0.041333"], ["83747.7", "0.04"], ["83748.6", "0.04"], ["83749.3", "0.04"], ["83754.5", "0.292623"], ["83755.6", "0.073887"], ["83755.7", "0.002799"], ["83755.9", "0.013"], ["83756", "0.01253"], ["83756.1", "0"], ["83756.2", "0.00009"], ["83756.4", "0.231333"], ["83756.5", "0.0445"], ["83758.1", "0"], ["83765.2", "0"], ["83770", "0.063469"], ["83772.8", "0"], ["83777.4", "0.171333"], ["83794.2", "0.171"], ["83797.6", "0"], ["83797.9", "0"], ["83798.1", "0"], ["83798.2", "0"], ["83798.3", "0"], ["83799", "0"], ["83799.1", "0"]], "u": 48736, "seq": 67553228917}, "cts": 1742561032917, "record_time": 1742561032.938702, "EXCHANGE": "BYBIT"}
{"topic": "orderbook.200.BTCUSDT", "ts": 1742561033119, "type": "delta", "data": {"s": "BTCUSDT", "b": [["83721.8", "0.608274"], ["83719", "0.071702"], ["83710.9", "0.071709"], ["83710.4", "0.000333"], ["83706.2", "0.000456"], ["83700.6", "0.251952"], ["83691.5", "0.000539"], ["83687.4", "0.036005"], ["83682.4", "0.099202"], ["83679.6", "0"], ["83663.3", "0"], ["83662.8", "0"]], "a": [["83721.9", "0.172641"], ["83724.9", "0"], ["83734.7", "0.012"], ["83735.6", "0"], ["83740.9", "0.053331"], ["83742.7", "0.084"], ["83743.7", "0.04"], ["83744.3", "0.04903"], ["83745", "0.04"], ["83745.4", "0"], ["83746", "0.0406"], ["83747.6", "0"], ["83751", "0"], ["83754.5", "0"], ["83755.8", "0.043564"], ["83755.9", "0.053"], ["83756.4", "0.191333"], ["83756.5", "0.0045"], ["83764.3", "0.06944"], ["83770", "0"], ["83771.2", "0.023874"], ["83782.6", "2.730166"], ["83793.5", "1.127773"], ["83797.6", "0.001333"]], "u": 48737, "seq": 67553229035}, "cts": 1742561033114, "record_time": 1742561033.136954, "EXCHANGE": "BYBIT"}
{"topic": "orderbook.200.BTCUSDT", "ts": 1742561033320, "type": "delta", "data": {"s": "BTCUSDT", "b": [["83720.1", "0.071701"], ["83719", "0"], ["83683.5", "0.000121"]], "a": [["83721.9", "0.072624"], ["83732.8", "0.012675"], ["83734.3", "0.000153"], ["83748.6", "0"], ["83749.3", "0"], ["83755.3", "0.013"], ["83755.4", "0.098981"], ["83755.6", "0.113887"], ["83755.7", "0.042799"], ["83755.8", "0.003564"], ["83755.9", "0"], ["83756", "0"], ["83756.7", "0.032087"], ["83763.7", "1.435776"], ["83776.9", "2.604751"], ["83782.6", "0.125415"], ["83797.6", "0"]], "u": 48738, "seq": 67553229093}, "cts": 1742561033317, "record_time": 1742561033.337494, "EXCHANGE": "BYBIT"}
{"topic": "orderbook.200.BTCUSDT", "ts": 1742561033519, "type": "delta", "data": {"s": "BTCUSDT", "b": [["83721.2", "0.0717"], ["83720.1", "0"], ["83715", "0.0134"], ["83714.5", "0.03579"], ["83714.4", "0.119299"], ["83713.1", "0"], ["83713", "0.071707"], ["83710.9", "0"], ["83693.1", "0.035842"], ["83686.3", "0.0016"], ["83684.4", "0"], ["83674.2", "0.012884"], ["83674.1", "0.012884"], ["83673.6", "0"], ["83673.5", "0"], ["83666.8", "5.575677"], ["83664.5", "0"], ["83664.3", "0"], ["83664.2", "0"], ["83663.6", "0"]], "a": [["83721.9", "0.072385"], ["83726.5", "0"], ["83734.3", "0"], ["83735.5", "0.085757"], ["83737.6", "0.000299"], ["83737.8", "0.059399"], ["83737.9", "0.201"], ["83755.3", "0"], ["83755.4", "0.086458"], ["83755.5", "0.013"], ["83755.6", "0.08641"], ["83755.7", "0.002799"], ["83756", "0.04"], ["83756.1", "0.04"], ["83776.9", "0"], ["83779.7", "2.604751"], ["83797.5", "0"]], "u": 48739, "seq": 67553229185}, "cts": 1742561033504, "record_time": 1742561033.536615, "EXCHANGE": "BYBIT"}
{"topic": "orderbook.200.BTCUSDT", "ts": 1742561033719, "type": "delta", "data": {"s": "BTCUSDT", "b": [["83721.8", "0.508274"], ["83715", "0.024946"], ["83714.5", "0"], ["83714.4", "0"], ["83712", "0.108709"], ["83702.2", "0.168157"], ["83693.1", "0.335444"], ["83674.3", "0.012884"], ["83674.1", "0"], ["83669.7", "5.424295"], ["83666.8", "0"], ["83664.5", "0.119323"]], "a": [["83721.9", "0.072624"], ["83728.7", "0.012356"], ["83737.2", "0.122113"], ["83747", "0.166557"], ["83755.5", "0"], ["83755.7", "0.015322"], ["83756", "0"], ["83756.1", "0.321238"], ["83756.2", "0.04009"], ["83787.5", "0"], ["83797.5", "0.011894"]], "u": 48740, "seq": 67553229393}, "cts": 1742561033716, "record_time": 1742561033.736234, "EXCHANGE": "BYBIT"}
{"topic": "orderbook.200.BTCUSDT", "ts": 1742561033920, "type": "delta", "data": {"s": "BTCUSDT", "b": [["83721.8", "0.15081"], ["83721.2", "0"], ["83718.7", "0"], ["83718.6", "0"], ["83715", "0.011546"], ["83714.3", "0.072576"], ["83714.2", "0.172466"], ["83713", "0"], ["83712", "0"], ["83708.7", "0"], ["83706.6", "0.071713"], ["83702.2", "0.000051"], ["83700.7", "0"], ["83700.2", "0.059705"], ["83693.2", "0.308246"], ["83693.1", "0"], ["83692.4", "0.00009"], ["83686.1", "0.000022"], ["83682.4", "0"], ["83679.6", "0.099204"], ["83669.7", "0"], ["83664.3", "0.000333"], ["83664.2", "0.00081"], ["83663.6", "0.00313"], ["83663.3", "0.003259"], ["83662.8", "0.000518"], ["83662.6", "0.001007"], ["83662.5", "0.00067"]], "a": [["83721.9", "0.252393"], ["83726.5", "0.043626"], ["83732.8", "0"], ["83733.2", "0.019922"], ["83733.3", "0.024309"], ["83735.5", "0.129533"], ["83737.2", "0"], ["83747", "0.003172"], ["83751.6", "0.000994"], ["83756", "0.119299"], ["83756.1", "0.04"], ["83779.7", "0"], ["83785.4", "2.604751"], ["83797.1", "0"], ["83797.3", "0"], ["83797.5", "0"]], "u": 48741, "seq": 67553229558}, "cts": 1742561033916, "record_time": 1742561033.963825, "EXCHANGE": "BYBIT"}
{"topic": "orderbook.200.BTCUSDT", "ts": 1742561034120, "type": "delta", "data": {"s": "BTCUSDT", "b": [["83721.8", "0.152269"], ["83716.3", "0.025075"], ["83716.2", "0.071705"], ["83706.7", "0.127562"], ["83706.6", "0"], ["83705.4", "0.018932"], ["83704", "0.071715"], ["83699.1", "0"], ["83693.2", "0"], ["83691.9", "0.024206"], ["83679.6", "0"], ["83676.8", "0.099205"], ["83674.3", "0"], ["83674.2", "0"], ["83673.6", "0.012884"], ["83673.5", "0.012884"], ["83662.6", "0"], ["83662.5", "0"]], "a": [["83721.9", "0.423393"], ["83723.7", "0.023888"], ["83726.4", "0.061054"], ["83727", "0.054625"], ["83731", "0.00009"], ["83732.1", "0.020361"], ["83733.2", "0"], ["83740.3", "0"], ["83740.6", "0.06935"], ["83740.9", "0"], ["83782.6", "0"], ["83785.4", "0"], ["83788.2", "2.604751"]], "u": 48742, "seq": 67553229669}, "cts": 1742561034109, "record_time": 1742561034.164113, "EXCHANGE": "BYBIT"}
{"topic": "orderbook.200.BTCUSDT", "ts": 1742561034320, "type": "delta", "data": {"s": "BTCUSDT", "b": [["83721.8", "0.152986"], ["83716.3", "0"], ["83716.2", "0"], ["83706.7", "0.055849"], ["83706.6", "0.071713"], ["83691.7", "0.035842"]], "a": [["83726.4", "0.001333"], ["83751.6", "0"], ["83761.9", "0.50409"], ["83779.7", "2.604751"], ["83788.2", "0"], ["83797.1", "0.001466"]], "u": 48743, "seq": 67553229732}, "cts": 1742561034317, "record_time": 1742561034.336431, "EXCHANGE": "BYBIT"}
{"topic": "orderbook.200.BTCUSDT", "ts": 1742561034519, "type": "delta", "data": {"s": "BTCUSDT", "b": [["83721.8", "0.152747"], ["83715.3", "0.071705"], ["83706.6", "0"], ["83706", "0.191012"], ["83704", "0"], ["83701.7", "0.071717"]], "a": [["83729.7", "0.061772"], ["83729.8", "0.179148"], ["83732.1", "0.071558"], ["83733.1", "0.179141"], ["83750.2", "0.001105"], ["83750.5", "0.001188"], ["83771.3", "2.613751"], ["83779.7", "0"], ["83796.4", "0"], ["83796.7", "0"], ["83796.8", "0"], ["83797.1", "0"]], "u": 48744, "seq": 67553229782}, "cts": 1742561034515, "record_time": 1742561034.537279, "EXCHANGE": "BYBIT"}
{"topic": "orderbook.200.BTCUSDT", "ts": 1742561034720, "type": "delta", "data": {"s": "BTCUSDT", "b": [["83721.8", "0.14761"], ["83715.3", "0"], ["83710.7", "0"], ["83709", "0.095836"], ["83708.9", "0"], ["83707.3", "0"], ["83706", "0.071713"], ["83705.7", "0"], ["83704.2", "0.000518"], ["83703.2", "0.504033"], ["83701.8", "0.071717"], ["83701.7", "0"], ["83700.2", "0.000306"], ["83691.7", "0"], ["83689.2", "0.007494"], ["83687.4", "0.012263"], ["83679.5", "0"], ["83676.8", "0"], ["83676", "0.029198"], ["83665.4", "0.099205"], ["83662.6", "0.001007"], ["83662.5", "0.00067"], ["83661.4", "0.024039"], ["83661", "0.005871"], ["83660.9", "0.000436"], ["83660.4", "0.02389"]], "a": [["83721.9", "0.423154"], ["83726.2", "0.112551"], ["83726.4", "0.120775"], ["83726.5", "0"], ["83726.9", "0.035832"], ["83729.2", "0.119443"], ["83729.7", "0"], ["83729.8", "0"], ["83732.1", "0.020361"], ["83733.1", "0"], ["83733.6", "0.059721"], ["83746.8", "0.089099"], ["83750.2", "0"], ["83750.5", "0"], ["83750.9", "0.001322"], ["83755.3", "0.119299"], ["83756", "0"], ["83759.3", "0.536322"], ["83759.8", "0.024495"], ["83765.6", "2.851187"], ["83767.6", "0"], ["83771.2", "0"], ["83771.3", "0.009"], ["83774.8", "0"], ["83775.2", "0.414779"], ["83793.5", "0"], ["83796.4", "0.00051"], ["83796.7", "0.011894"], ["83796.8", "0.0006"]], "u": 48745, "seq": 67553229910}, "cts": 1742561034714, "record_time": 1742561034.738715, "EXCHANGE": "BYBIT"}
{"topic": "orderbook.200.BTCUSDT", "ts": 1742561034920, "type": "delta", "data": {"s": "BTCUSDT", "b": [["83721.8", "0.153766"], ["83711.6", "0.071709"], ["83709", "0"], ["83706.7", "0.003849"], ["83706", "0"], ["83704.5", "0"], ["83704.2", "0.072233"], ["83701.9", "0.04"], ["83701.8", "0"], ["83700.2", "0.044306"], ["83700", "0.743523"], ["83698.5", "0.044"], ["83698.1", "0.052"], ["83696.9", "0.048"], ["83691.9", "0"], ["83690.7", "0.030605"], ["83688.1", "0"], ["83685.2", "0.243139"], ["83673.6", "0"], ["83673.5", "0"], ["83672.8", "0.014351"], ["83672.7", "0.013218"], ["83665.4", "0.099272"], ["83662.4", "0.171"], ["83660.2", "0.000333"]], "a": [["83721.9", "0.596185"], ["83722.1", "0.059721"], ["83723.6", "0.240571"], ["83725.4", "0.059721"], ["83725.9", "0.089581"], ["83726.2", "0.003823"], ["83726.4", "0.240218"], ["83728.7", "0.091952"], ["83728.9", "0.059721"], ["83732.1", "0.038278"], ["83752.9", "0.04"], ["83753", "0.051884"], ["83756.1", "0"], ["83756.2", "0.00009"], ["83762.8", "2.604751"], ["83765.6", "0.246436"], ["83794.1", "0"], ["83794.2", "0"], ["83794.6", "0"], ["83796.4", "0"], ["83796.7", "0"], ["83796.8", "0"]], "u": 48746, "seq": 67553230050}, "cts": 1742561034916, "record_time": 1742561035.013954, "EXCHANGE": "BYBIT"}
{"topic": "orderbook.200.BTCUSDT", "ts": 1742561035119, "type": "delta", "data": {"s": "BTCUSDT", "b": [["83712.6", "0.071708"], ["83711.6", "0"], ["83705.9", "0.40311"], ["83704.1", "0.04"], ["83703.6", "0.040125"], ["83702.4", "0.052"], ["83700.1", "0.178698"], ["83700", "0.791523"], ["83697.1", "0.045333"], ["83688.4", "0.039103"], ["83676.7", "0.099272"], ["83665.4", "0"], ["83660.4", "0"], ["83660.2", "0"]], "a": [["83721.9", "0.425185"], ["83722.1", "0"], ["83723.6", "0.18085"], ["83725.4", "0"], ["83725.9", "0"], ["83726.9", "0"], ["83727", "0.233788"], ["83751.8", "0.04"], ["83751.9", "0.04"], ["83752.9", "0"], ["83753", "0.011884"], ["83782.6", "0.125415"], ["83794.1", "0.000333"], ["83794.6", "0.000358"]], "u": 48747, "seq": 67553230177}, "cts": 1742561035117, "record_time": 1742561035.210681, "EXCHANGE": "BYBIT"}
{"topic": "orderbook.200.BTCUSDT", "ts": 1742561035320, "type": "delta", "data": {"s": "BTCUSDT", "b": [["83721.8", "0.153707"], ["83712.6", "0"], ["83706.4", "0.028164"], ["83700", "0.719805"], ["83689.2", "0"], ["83676.7", "0"], ["83671", "0.099272"], ["83660.4", "0.02389"]], "a": [["83721.9", "0.600393"], ["83723.6", "0.06575"], ["83723.7", "0"], ["83724.4", "0.024088"], ["83726.4", "0.001333"], ["83727", "0.114346"], ["83727.5", "0.048367"], ["83727.7", "0.119442"], ["83728.7", "0.012356"], ["83728.9", "0"], ["83729.2", "0"], ["83732.1", "0"], ["83733.2", "0.019922"], ["83733.6", "0"], ["83750.9", "0"], ["83751.8", "0"], ["83751.9", "0"], ["83752.7", "0.04"], ["83752.8", "0.04"], ["83755.2", "0.119299"], ["83755.3", "0"], ["83762.8", "0"], ["83776.9", "2.604751"], ["83794.2", "0.171"], ["83796.4", "0.00051"], ["83796.7", "0.011894"]], "u": 48748, "seq": 67553230308}, "cts": 1742561035317, "record_time": 1742561035.339184, "EXCHANGE": "BYBIT"}
{"topic": "orderbook.200.BTCUSDT", "ts": 1742561035520, "type": "delta", "data": {"s": "BTCUSDT", "b": [["83721.8", "0.153946"], ["83711.9", "0.071708"], ["83706.4", "0"], ["83703.3", "0.0141"], ["83701.9", "0.111717"], ["83686.3", "0"], ["83674.6", "0.0016"], ["83673.6", "0.013"], ["83673.5", "0.012884"], ["83672.8", "0.001466"], ["83672.7", "0.000333"], ["83671", "0"], ["83668.2", "0.100711"], ["83660.9", "0"], ["83660.4", "0"]], "a": [["83721.9", "0.602184"], ["83723.6", "0.136798"], ["83724.4", "0.023888"], ["83725.9", "0.119442"], ["83726.9", "0.125413"], ["83727", "0.293509"], ["83727.2", "0.125413"], ["83727.5", "0.133693"], ["83727.6", "0.0002"], ["83728.8", "0.119443"], ["83729.7", "0.059721"], ["83730.2", "0.062886"], ["83730.7", "0.119443"], ["83732.6", "0.039304"], ["83732.7", "0.059721"], ["83733.2", "0"], ["83746.7", "0"], ["83751", "0.012521"], ["83751.1", "0.013987"], ["83755.6", "0.073887"], ["83755.7", "0.002799"], ["83756.7", "0.196322"], ["83758.7", "0.063469"], ["83764.3", "0.005971"], ["83768.4", "2.72405"], ["83776.9", "0"], ["83782.6", "0"], ["83793.4", "0"], ["83794.1", "0"], ["83794.2", "0"], ["83794.6", "0"], ["83796.4", "0"], ["83796.7", "0"]], "u": 48749, "seq": 67553230385}, "cts": 1742561035511, "record_time": 1742561035.538901, "EXCHANGE": "BYBIT"}
{"success": true, "ret_msg": "subscribe", "conn_id": "5bb2e287-9dc1-4e90-b73e-cf54f90a98a8", "op": "subscribe", "record_time": 1742561130.66261, "EXCHANGE": "BYBIT"}
{"topic": "orderbook.200.BTCUSDT", "ts": 1742561129319, "type": "snapshot", "data": {"s": "BTCUSDT", "b": [["83810.1", "0.4334"], ["83807.6", "0.001163"], ["83806.4", "0.005764"], ["83806", "0.001333"], ["83805.6", "0.003691"], ["83803.5", "0.011529"], ["83802.5", "0.000333"], ["83802.1", "0.059042"], ["83801.8", "0.002799"], ["83801.7", "0.015119"], ["83801.6", "0.00009"], ["83801.4", "0.003181"], ["83801", "0.00051"], ["83800.4", "0.002854"], ["83800", "0.114675"], ["83799.4", "0.0087"], ["83799.3", "0.023061"], ["83799.2", "0.071634"], ["83799", "0.0037"], ["83798.3", "0.083749"], ["83797.6", "0.001333"], ["83797.3", "0.003181"], ["83797.1", "0.001466"], ["83796.9", "0.072629"], ["83796.4", "0.00051"], ["83795.8", "0.171"], ["83795.7", "0.04"], ["83795.6", "0.04"], ["83795.1", "0.004637"], ["83795", "0.0006"], ["83794.1", "0.052333"], ["83793.9", "0.296266"], ["83793.7", "0.018111"], ["83793.4", "0.001333"], ["83793.2", "0.00009"], ["83793.1", "0.00318"], ["83792.5", "0.001466"], ["83792.2", "0.044"], ["83791.7", "0.00051"], ["83791.5", "0.048"], ["83790.8", "0.180697"], ["83790.6", "0.044"], ["83790.1", "0.577314"], ["83789.9", "0.000333"], ["83789.2", "0.001333"], ["83788.9", "0.032271"], ["83788.8", "0.048"], ["83788.6", "0.044"], ["83788.1", "0.027593"], ["83787.9", "0.001466"], ["83787.1", "0.00051"], ["83786.3", "0.006412"], ["83786", "0.035804"], ["83785.8", "0.059399"], ["83785.7", "0.214546"], ["83785.1", "0.455835"], ["83785", "0.001333"], ["83784.8", "0.00009"], ["83784.7", "0.003178"], ["83783.5", "0.023423"], ["83783.3", "0.172466"], ["83782.5", "0.00051"], ["83782", "0.004664"], ["83781.7", "0.003"], ["83781.6", "0.000333"], ["83781.2", "0.024094"], ["83780.8", "0.001333"], ["83780.5", "0.003775"], ["83780", "0.00024"], ["83778.7", "0.001466"], ["83777.9", "0.00051"], ["83777.4", "0.000533"], ["83777", "0.0006"], ["83776.7", "0.067678"], ["83776.6", "0.001333"], ["83776.4", "0.00009"], ["83776.3", "0.003174"], ["83775", "0.059399"], ["83774.9", "0.171"], ["83774.7", "0.011884"], ["83774.1", "0.001466"], ["83773.3", "0.00051"], ["83773.2", "0.000333"], ["83772.5", "0.001333"], ["83772.1", "0.003163"], ["83771.9", "0.000689"], ["83771.4", "0.014633"], ["83771.3", "0.009"], ["83771.1", "0.037978"], ["83770.7", "0.0016"], ["83769.5", "0.001466"], ["83769", "0.000333"], ["83768.7", "0.056755"], ["83768.5", "0.003396"], ["83768.3", "0.001333"], ["83768", "0.00009"], ["83767.9", "0.003161"], ["83767.1", "0.00009"], ["83765.9", "0.059399"], ["83765.2", "0.089099"], ["83764.9", "0.001466"], ["83764.8", "0.000333"], ["83764.4", "0.012884"], ["83764.3", "0.012884"], ["83764.1", "0.001843"], ["83763.7", "0.003161"], ["83761.7", "0.099667"], ["83760.8", "0.187848"], ["83760.6", "0.000333"], ["83760.3", "0.001466"], ["83760", "0.00018"], ["83759.9", "0.001333"], ["83759.6", "0.00325"], ["83759.5", "0.129451"], ["83757.9", "0.03575"], ["83757.7", "0.020928"], ["83757.1", "0.119299"], ["83757", "1.09678"], ["83756.9", "3.512148"], ["83756.5", "0.0045"], ["83756.4", "0.059732"], ["83756", "0.016606"], ["83755.9", "0.023866"], ["83755.7", "0.002799"], ["83755.4", "0.00376"], ["83754.9", "0.00051"], ["83754.5", "5.562365"], ["83753", "0.000118"], ["83752.4", "0.0001"], ["83752.3", "0.023866"], ["83752.2", "0.000333"], ["83752.1", "0.011941"], ["83752", "2.581148"], ["83751.9", "3.268535"], ["83751.8", "0.119299"], ["83751.5", "0.001333"], ["83751.2", "0.003248"], ["83751.1", "0.001466"], ["83750.3", "0.000508"], ["83750", "0.004192"], ["83748", "0.059732"], ["83747.3", "0.001333"], ["83747", "0.003157"], ["83746.5", "0.001466"], ["83746.4", "0.005967"], ["83746.1", "0.058712"], ["83746", "0.171"], ["83745.7", "0.000508"], ["83744.4", "0.023867"], ["83744", "0.354525"], ["83743.9", "0.000333"], ["83743.4", "0.128571"], ["83743.1", "0.001333"], ["83742.8", "0.003243"], ["83742", "0.119299"], ["83741.9", "0.003775"], ["83741.3", "0.009"], ["83741.2", "0.041322"], ["83741.1", "0.036262"], ["83740.8", "0.089099"], ["83740.6", "0.04"], ["83740.2", "0.03887"], ["83740", "0.00006"], ["83739.7", "0.000333"], ["83739.3", "0.059399"], ["83739.1", "0.02387"], ["83739", "0.001333"], ["83738.9", "0.04"], ["83738.7", "0.118134"], ["83738.6", "0.003153"], ["83737.4", "0.04"], ["83737.3", "0.045466"], ["83736.8", "0.119332"], ["83736.7", "0.171"], ["83736.5", "0.000508"], ["83736.1", "0.000149"], ["83735.6", "0.044"], ["83735.5", "0.024203"], ["83734.8", "0.001333"], ["83734.4", "0.003243"], ["83732.6", "0.001798"], ["83732", "0.0006"], ["83731.9", "0.000508"], ["83731.3", "0.000333"], ["83730.6", "0.627748"], ["83730.4", "0.027813"], ["83730.2", "0.954485"], ["83730.1", "0.059399"], ["83729.4", "0.119299"], ["83728.8", "0.0237"], ["83728.7", "0.044096"], ["83728.3", "0.171"], ["83728", "0.001466"], ["83727.9", "0.089941"], ["83727.7", "0.052"], ["83727.6", "0.023873"], ["83727.3", "0.000508"], ["83727.1", "0.000333"], ["83726.5", "0.0045"], ["83726.4", "0.001333"]], "a": [["83810.2", "0.507486"], ["83810.9", "0.000333"], ["83811", "0.001466"], ["83811.5", "0.001381"], ["83812.5", "0.0006"], ["83813.7", "0.001601"], ["83813.9", "0.006173"], ["83814", "0.003227"], ["83814.4", "0.001333"], ["83814.5", "0.054003"], ["83814.6", "0.178966"], ["83814.8", "0.00051"], ["83815.1", "0.000333"], ["83815.2", "0.0002"], ["83815.3", "0.026914"], ["83815.6", "0.001466"], ["83816.2", "0.119299"], ["83816.3", "0.250876"], ["83816.4", "0.178963"], ["83816.5", "0.0045"], ["83816.7", "0.000358"], ["83816.8", "0.012347"], ["83817", "0.001"], ["83817.3", "0.023944"], ["83817.5", "0.0006"], ["83817.6", "0.0006"], ["83818", "0.178959"], ["83818.2", "0.003227"], ["83818.3", "0.006126"], ["83818.4", "0.000298"], ["83818.5", "0.114357"], ["83818.6", "0.015"], ["83818.7", "0.178976"], ["83819", "0.0006"], ["83819.3", "0.000333"], ["83819.4", "0.175463"], ["83820.2", "0.001466"], ["83821", "0.024693"], ["83821.8", "0.154244"], ["83821.9", "0.119299"], ["83822.2", "0.190916"], ["83822.4", "0.003226"], ["83822.6", "0.00009"], ["83822.7", "0.001333"], ["83823.4", "0.00009"], ["83823.5", "0.000333"], ["83823.9", "0.167518"], ["83824", "0.00051"], ["83824.8", "0.001466"], ["83825.4", "0.084"], ["83825.6", "0.08"], ["83825.7", "0.064993"], ["83826.2", "0.0006"], ["83826.6", "0.003242"], ["83826.7", "0.003347"], ["83826.9", "0.001333"], ["83827.6", "0.000333"], ["83827.7", "0.178698"], ["83827.8", "0.171"], ["83828", "0.084658"], ["83828.3", "0.04"], ["83828.6", "0.00051"], ["83829", "0.04"], ["83829.4", "0.001466"], ["83830.4", "0.023867"], ["83830.7", "0.04"], ["83830.8", "0.003244"], ["83831", "0.0012"], ["83831.1", "0.001333"], ["83831.3", "0.009"], ["83831.5", "0.06464"], ["83831.6", "0.119317"], ["83831.8", "0.000423"], ["83832.2", "0.162946"], ["83832.3", "0.059892"], ["83833.2", "0.00051"], ["83833.6", "0.04314"], ["83834", "0.001466"], ["83834.1", "0.009602"], ["83834.9", "0.119299"], ["83835", "0.003244"], ["83835.3", "0.001333"], ["83836", "0.000333"], ["83836.2", "0.206804"], ["83837", "0.000118"], ["83837.9", "0.00051"], ["83838.5", "0.023867"], ["83838.6", "0.001466"], ["83838.7", "0.064127"], ["83838.8", "0.089457"], ["83839.2", "0.003244"], ["83839.5", "0.001333"], ["83840", "0.119299"], ["83840.2", "0.000423"], ["83841.2", "0.059399"], ["83841.8", "0.107584"], ["83841.9", "0.023867"], ["83842", "0.024524"], ["83842.1", "0.01264"], ["83842.2", "0.04"], ["83842.3", "0.04"], ["83842.5", "0.000512"], ["83842.8", "0.004604"], ["83843.2", "0.001466"], ["83843.3", "0.023867"], ["83843.4", "0.003244"], ["83843.7", "0.001333"], ["83844.1", "0.015"], ["83844.2", "0.023867"], ["83844.4", "0.000333"], ["83844.6", "0.171"], ["83845.2", "0.352469"], ["83845.3", "0.547719"], ["83846.1", "0.004262"], ["83846.2", "0.119299"], ["83846.4", "0.063471"], ["83846.5", "0.0045"], ["83846.6", "0.000083"], ["83846.8", "0.486089"], ["83847.1", "0.000512"], ["83847.2", "0.005966"], ["83847.6", "0.003244"], ["83847.9", "0.002799"], ["83848.6", "0.000423"], ["83849.6", "0.609708"], ["83850.3", "0.00596"], ["83850.4", "0.177583"], ["83850.6", "0.114"], ["83851.6", "0.003564"], ["83851.7", "0.003756"], ["83851.8", "0.125298"], ["83852", "1.626093"], ["83852.1", "0.001333"], ["83852.2", "0.125283"], ["83852.4", "0.059399"], ["83852.5", "0.001466"], ["83852.8", "0.000333"], ["83853", "0.171"], ["83853.1", "0.001431"], ["83854.2", "0.00315"], ["83854.3", "0.037946"], ["83854.4", "0.119306"], ["83855", "0.000203"], ["83855.9", "0.003244"], ["83856.3", "0.001845"], ["83857", "0.000423"], ["83857.1", "0.001466"], ["83857.4", "0.01387"], ["83858.1", "0.042721"], ["83858.2", "0.04"], ["83858.4", "0.354544"], ["83858.8", "0.011884"], ["83858.9", "0.178872"], ["83859.6", "0.000332"], ["83860.1", "0.003244"], ["83860.4", "0.4"], ["83860.5", "0.001333"], ["83860.6", "0.0006"], ["83860.9", "0.00087"], ["83861.2", "0.000333"], ["83861.3", "0.009"], ["83861.4", "0.409612"], ["83861.7", "2.607218"], ["83864.3", "0.003244"], ["83864.6", "0.059399"], ["83864.7", "0.001423"], ["83864.9", "0.098009"], ["83865.1", "0.024712"], ["83865.4", "0.000423"], ["83865.5", "0.000512"], ["83865.8", "0.04"], ["83866.1", "0.04"], ["83866.3", "0.001466"], ["83867.5", "0.044"], ["83867.6", "0.003564"], ["83868.5", "0.003244"], ["83868.7", "0.04"], ["83868.9", "0.001333"], ["83869.4", "0.011994"], ["83869.6", "0.000333"], ["83869.8", "0.171"], ["83870.1", "0.000512"], ["83870.9", "0.001466"], ["83871.5", "0.119299"], ["83872", "1.126718"], ["83872.7", "0.003244"], ["83872.8", "0.011994"], ["83873", "0.001333"], ["83873.8", "0.000423"], ["83874.5", "0.059399"], ["83874.7", "0.000512"], ["83875.5", "0.01346"], ["83875.6", "0.011884"], ["83876.5", "0.0045"], ["83876.7", "0.04"], ["83876.9", "0.003244"], ["83877.1", "0.011994"], ["83877.2", "0.001333"], ["83878", "0.000333"], ["83878.2", "0.171"]], "u": 49218, "seq": 67553306771}, "cts": 1742561129317, "record_time": 1742561130.664319, "EXCHANGE": "BYBIT"}
{"topic": "orderbook.200.BTCUSDT", "ts": 1742561129520, "type": "delta", "data": {"s": "BTCUSDT", "b": [["83807.9", "0.071626"], ["83799.5", "0.071633"], ["83799.2", "0"], ["83788.9", "0.066497"], ["83768.5", "0"], ["83763", "5.562365"], ["83762.2", "0.119299"], ["83754.5", "0"], ["83752", "1.000447"], ["83726.4", "0"]], "a": [["83810.2", "0.506233"], ["83821.8", "0.149132"]], "u": 49219, "seq": 67553306802}, "cts": 1742561129493, "record_time": 1742561130.66537, "EXCHANGE": "BYBIT"}
{"topic": "orderbook.200.BTCUSDT", "ts": 1742561129719, "type": "delta", "data": {"s": "BTCUSDT", "b": [["83808.8", "0.071625"], ["83807.9", "0"], ["83768.5", "0.003396"], ["83727.9", "0.089922"], ["83726.5", "0"]], "a": [["83811.7", "0.000153"], ["83818.5", "0.054958"], ["83878.2", "0"]], "u": 49220, "seq": 67553306818}, "cts": 1742561129705, "record_time": 1742561130.666199, "EXCHANGE": "BYBIT"}
{"topic": "orderbook.200.BTCUSDT", "ts": 1742561129919, "type": "delta", "data": {"s": "BTCUSDT", "b": [["83810.1", "0.540749"], ["83809.9", "0.071624"], ["83808.8", "0"], ["83802.2", "0.095386"], ["83802.1", "0.071631"], ["83796.9", "0.000994"], ["83765.1", "0.012883"], ["83765", "0.012883"], ["83764.4", "0"], ["83764.3", "0"], ["83728.8", "0"], ["83728.7", "0.023835"], ["83728.6", "0.044888"], ["83727.9", "0.088935"], ["83727.1", "0"]], "a": [["83810.2", "0.305143"], ["83811.7", "0"], ["83841.2", "0.072399"], ["83841.3", "0.01264"], ["83841.7", "0.04"], ["83841.8", "0.147584"], ["83842", "0.011884"], ["83842.1", "0"], ["83842.2", "0"], ["83842.3", "0"], ["83879.4", "0.000512"], ["83880.1", "0.001466"]], "u": 49221, "seq": 67553306857}, "cts": 1742561129915, "record_time": 1742561130.669188, "EXCHANGE": "BYBIT"}
{"topic": "orderbook.200.BTCUSDT", "ts": 1742561130120, "type": "delta", "data": {"s": "BTCUSDT", "b": [["83810.1", "0.711749"], ["83810", "0.021836"], ["83802.2", "0.098386"], ["83793.8", "0.00333"], ["83790.5", "0.089099"], ["83781.7", "0"], ["83765.8", "5.508846"], ["83765.1", "0"], ["83765", "0"], ["83764.4", "0.012884"], ["83764.3", "0.012884"], ["83763", "0"], ["83729", "0.022277"], ["83728.7", "0"], ["83727.6", "0"], ["83727.3", "0"]], "a": [["83810.2", "0.283354"], ["83814.6", "0.181966"], ["83816.2", "0"], ["83816.3", "0.370175"], ["83838.8", "0.000358"], ["83841.2", "0.059399"], ["83841.3", "0"], ["83841.4", "0.01264"], ["83841.5", "0.01264"], ["83841.7", "0"], ["83841.8", "0.107584"], ["83841.9", "0.063867"], ["83842", "0.051884"], ["83853.1", "0"], ["83856.1", "0.001431"], ["83861.7", "0.001466"], ["83867.4", "2.605752"], ["83878.2", "0.171"], ["83880.1", "0"]], "u": 49222, "seq": 67553306929}, "cts": 1742561130114, "record_time": 1742561130.669975, "EXCHANGE": "BYBIT"}
{"topic": "orderbook.200.BTCUSDT", "ts": 1742561130319, "type": "delta", "data": {"s": "BTCUSDT", "b": [["83810.1", "0.7044"], ["83798.3", "0.082749"], ["83768.5", "0.001759"], ["83729.4", "0.140036"], ["83729", "0"], ["83728.6", "0"], ["83728.5", "0.044346"], ["83727.9", "0.044295"], ["83727.7", "0.096146"], ["83727.6", "0.023873"]], "a": [["83810.2", "0.289354"], ["83821.8", "0.089474"], ["83838.7", "0"], ["83864.6", "2.665151"], ["83867.4", "0"], ["83880.1", "0.001466"], ["83880.7", "0.011994"]], "u": 49223, "seq": 67553306966}, "cts": 1742561130314, "record_time": 1742561130.670719, "EXCHANGE": "BYBIT"}
{"topic": "orderbook.200.BTCUSDT", "ts": 1742561130520, "type": "delta", "data": {"s": "BTCUSDT", "b": [["83810.1", "0.702259"], ["83804.7", "0.024947"], ["83804.6", "0.071629"], ["83799.5", "0"], ["83793.8", "0"], ["83791.8", "0.006755"], ["83786.3", "0"], ["83768.7", "1.693152"], ["83768.5", "0.003559"], ["83765", "0.012883"], ["83764.9", "0.014349"], ["83764.4", "0"], ["83764.3", "0"], ["83729.4", "0.119299"], ["83729.3", "0.020737"], ["83728.5", "0"], ["83728.4", "0.044346"], ["83727.9", "0"], ["83727.7", "0.096714"], ["83727.6", "0.068515"], ["83727.3", "0.000508"]], "a": [["83810.2", "0.069661"], ["83816.3", "0.250876"], ["83817", "0"], ["83819.4", "0.17151"], ["83820.4", "0.000153"], ["83836.2", "0.171"], ["83841.3", "0.01264"], ["83841.5", "0"], ["83841.8", "0.147584"], ["83842", "0.011884"], ["83864.6", "0.059399"], ["83875.9", "2.605752"], ["83880.7", "0"]], "u": 49224, "seq": 67553307047}, "cts": 1742561130501, "record_time": 1742561130.67137, "EXCHANGE": "BYBIT"}
{"topic": "orderbook.200.BTCUSDT", "ts": 1742561130720, "type": "delta", "data": {"s": "BTCUSDT", "b": [["83798.2", "0.108993"], ["83794.1", "0.169001"], ["83787.7", "0.173658"], ["83787.1", "0.170611"], ["83780.7", "0.307193"], ["83780.1", "0.276539"], ["83768.8", "0.119299"], ["83765.8", "0"], ["83765", "0"], ["83764.8", "0.013216"], ["83754.5", "5.516203"], ["83728", "0"], ["83727.7", "0"], ["83727.6", "0"], ["83727.3", "0"]], "a": [["83810.2", "0.277574"], ["83814.5", "0.054903"], ["83816.2", "0.119299"], ["83820.4", "0"], ["83822.7", "0.112355"], ["83826.4", "0.035804"], ["83827", "0.109666"], ["83828.2", "0.003953"], ["83833.2", "0.179539"], ["83834", "0.18331"], ["83840.2", "0.310493"], ["83841", "0.309929"], ["83873.1", "2.605752"], ["83875.9", "0"], ["83878", "0"], ["83878.2", "0"], ["83879.4", "0"], ["83880.1", "0"]], "u": 49225, "seq": 67553307125}, "cts": 1742561130705, "record_time": 1742561130.745926, "EXCHANGE": "BYBIT"}
{"topic": "orderbook.200.BTCUSDT", "ts": 1742561130920, "type": "delta", "data": {"s": "BTCUSDT", "b": [["83810.1", "0.538608"], ["83804.7", "0"], ["83804.6", "0"], ["83799.7", "0.071633"], ["83790.5", "0"], ["83768.7", "0.056755"], ["83754.5", "0"], ["83746", "5.687203"], ["83728", "0.001466"], ["83727.7", "0.052"], ["83727.6", "0.113712"]], "a": [["83813.9", "0.006326"], ["83821.8", "0.134606"], ["83822", "0.059658"], ["83826.4", "0"], ["83826.5", "0.035804"], ["83841.2", "0.072039"], ["83841.4", "0"], ["83841.6", "0.04"], ["83841.7", "0.04"], ["83841.8", "0.107584"], ["83841.9", "0.023867"], ["83864.6", "2.665151"], ["83873.1", "0"], ["83877.2", "0"]], "u": 49226, "seq": 67553307221}, "cts": 1742561130912, "record_time": 1742561130.971639, "EXCHANGE": "BYBIT"}
{"topic": "orderbook.200.BTCUSDT", "ts": 1742561131120, "type": "delta", "data": {"s": "BTCUSDT", "b": [["83810.1", "0.438369"], ["83810", "0"], ["83809.9", "0"], ["83804.2", "0.024947"], ["83802.1", "0"], ["83798.2", "0"], ["83794.1", "0.052333"], ["83787.7", "0"], ["83787.1", "0.00051"], ["83780.7", "0"], ["83780.1", "0"], ["83768.8", "0"], ["83763", "5.516203"], ["83746", "0.171"], ["83729.3", "0"], ["83729", "0.020631"], ["83728.4", "0"], ["83728.3", "0.215758"], ["83727.6", "0.023873"], ["83727.4", "0.044514"], ["83727.3", "0.000508"], ["83727.1", "0.044903"], ["83726.5", "0.0045"], ["83726.4", "0.001333"], ["83726.1", "0.003147"], ["83726", "0.00009"]], "a": [["83810.2", "0.470363"], ["83813.9", "0.006173"], ["83818.4", "0.059697"], ["83822.7", "0.001333"], ["83827", "0"], ["83833.2", "0.00051"], ["83834", "0.001466"], ["83838.4", "0.089099"], ["83840.2", "0.000423"], ["83840.9", "0.226676"], ["83841", "0"], ["83841.6", "0"], ["83841.8", "0.04"], ["83877.2", "0.001333"]], "u": 49227, "seq": 67553307364}, "cts": 1742561131116, "record_time": 1742561131.140764, "EXCHANGE": "BYBIT"}
{"topic": "orderbook.200.BTCUSDT", "ts": 1742561131319, "type": "delta", "data": {"s": "BTCUSDT", "b": [["83810.1", "0.538608"], ["83808.7", "0.071625"], ["83804.2", "0"], ["83801", "0.020113"], ["83796.6", "0.071636"], ["83727.1", "0.000333"], ["83726.3", "0.044341"], ["83726.1", "0"], ["83726", "0"]], "a": [["83810.2", "0.450363"], ["83818.4", "0.000298"], ["83840.9", "0"], ["83841.2", "0.059399"], ["83841.3", "0"], ["83841.4", "0.013"], ["83841.5", "0.01264"], ["83841.7", "0"], ["83841.8", "0"], ["83841.9", "0.063867"], ["83842", "0.051884"], ["83878", "0.000333"], ["83879.4", "0.000512"]], "u": 49228, "seq": 67553307421}, "cts": 1742561131306, "record_time": 1742561131.340567, "EXCHANGE": "BYBIT"}
{"topic": "orderbook.200.BTCUSDT", "ts": 1742561131520, "type": "delta", "data": {"s": "BTCUSDT", "b": [["83801.6", "0.071722"], ["83799.6", "0.0087"], ["83799.4", "0"], ["83796.6", "0"], ["83770.9", "0.0016"], ["83770.7", "0"], ["83765", "0.012883"], ["83764.8", "0.000333"], ["83763.1", "1.777005"], ["83726.3", "0"]], "a": [["83841", "0.013"], ["83841.1", "0.01264"], ["83841.4", "0"], ["83841.5", "0"], ["83878.2", "0.171"], ["83879.4", "0"]], "u": 49229, "seq": 67553307479}, "cts": 1742561131507, "record_time": 1742561131.542653, "EXCHANGE": "BYBIT"}
{"topic": "orderbook.200.BTCUSDT", "ts": 1742561131719, "type": "delta", "data": {"s": "BTCUSDT", "b": [["83809.7", "0.071625"], ["83808.7", "0"], ["83791.8", "0"], ["83728.3", "0.171"], ["83726.6", "0.044384"]], "a": [["83810.2", "0.451794"], ["83840.9", "0.013"], ["83841", "0.01264"], ["83841.1", "0"], ["83841.4", "0.04"], ["83841.5", "0.04"], ["83841.9", "0.023867"], ["83842", "0.011884"], ["83856.1", "0"], ["83861.7", "2.607218"], ["83864.6", "0.059399"], ["83878.2", "0"]], "u": 49230, "seq": 67553307512}, "cts": 1742561131696, "record_time": 1742561131.742481, "EXCHANGE": "BYBIT"}
{"topic": "orderbook.200.BTCUSDT", "ts": 1742561131920, "type": "delta", "data": {"s": "BTCUSDT", "b": [["83765", "0"], ["83764.8", "0.013216"], ["83729", "0"], ["83726.6", "0"], ["83726.1", "0.023839"], ["83726", "0.00009"], ["83725", "0.044703"]], "a": [["83826.5", "0"], ["83826.7", "0.035804"], ["83840.9", "0"], ["83841.1", "0.01264"], ["83841.4", "0"], ["83841.6", "0.04"], ["83861.7", "0.001466"], ["83864.6", "2.665151"], ["83879.4", "0.000512"]], "u": 49231, "seq": 67553307547}, "cts": 1742561131900, "record_time": 1742561132.018199, "EXCHANGE": "BYBIT"}
{"topic": "orderbook.200.BTCUSDT", "ts": 1742561132119, "type": "delta", "data": {"s": "BTCUSDT", "b": [["83810.1", "0.537847"], ["83768.5", "0.001759"], ["83727.7", "0.096155"], ["83727.1", "0.02105"], ["83726.1", "0.003147"], ["83726", "0.045173"], ["83725", "0.00009"]], "a": [["83810.2", "0.280794"], ["83841.4", "0.108293"], ["83879.4", "0"]], "u": 49232, "seq": 67553307591}, "cts": 1742561132116, "record_time": 1742561132.144565, "EXCHANGE": "BYBIT"}
{"topic": "orderbook.200.BTCUSDT", "ts": 1742561132319, "type": "delta", "data": {"s": "BTCUSDT", "b": [["83810.1", "0.530498"], ["83809.8", "0.021836"], ["83804.1", "0.024947"], ["83804", "0.071629"], ["83799.7", "0"], ["83765.8", "5.534002"], ["83763", "0"], ["83726", "0"], ["83725", "0"]], "a": [["83810.2", "0.279363"], ["83821.8", "0.094586"], ["83822", "0"], ["83853.5", "0.001431"]], "u": 49233, "seq": 67553307688}, "cts": 1742561132312, "record_time": 1742561132.340755, "EXCHANGE": "BYBIT"}
{"topic": "orderbook.200.BTCUSDT", "ts": 1742561132519, "type": "delta", "data": {"s": "BTCUSDT", "b": [["83810.1", "0.529698"], ["83804.1", "0"], ["83804", "0"], ["83799.3", "0.094694"], ["83765.2", "0.102099"], ["83765.1", "0.012883"], ["83764.9", "0.001466"], ["83764.8", "0.000333"], ["83763.1", "0"], ["83726", "0.045173"], ["83725", "0.00009"]], "a": [["83840.9", "0.013"], ["83841.1", "0"], ["83841.4", "0.148293"], ["83841.6", "0"], ["83879.4", "0.000512"]], "u": 49234, "seq": 67553307739}, "cts": 1742561132506, "record_time": 1742561132.542571, "EXCHANGE": "BYBIT"}
{"topic": "orderbook.200.BTCUSDT", "ts": 1742561132720, "type": "delta", "data": {"s": "BTCUSDT", "b": [["83783.5", "0"], ["83768.7", "1.708464"], ["83765.2", "0.089099"], ["83765", "0.012883"]], "a": [["83810.2", "0.470363"], ["83821.9", "0.178957"], ["83840.9", "0"], ["83841", "0"], ["83841.1", "0.01264"], ["83841.2", "0.072039"], ["83841.4", "0.108293"], ["83841.5", "0"], ["83841.6", "0.04"], ["83841.7", "0.04"], ["83878.2", "0.171"], ["83879.4", "0"]], "u": 49235, "seq": 67553307803}, "cts": 1742561132714, "record_time": 1742561132.740885, "EXCHANGE": "BYBIT"}
{"topic": "orderbook.200.BTCUSDT", "ts": 1742561132919, "type": "delta", "data": {"s": "BTCUSDT", "b": [["83810.1", "0.53586"], ["83809.8", "0"], ["83809.7", "0"], ["83808.8", "0.021836"], ["83808.7", "0.071625"], ["83801.7", "0.08675"], ["83801.6", "0.00009"], ["83765.8", "5.567491"]], "a": [], "u": 49236, "seq": 67553307857}, "cts": 1742561132917, "record_time": 1742561132.942729, "EXCHANGE": "BYBIT"}
{"topic": "orderbook.200.BTCUSDT", "ts": 1742561133120, "type": "delta", "data": {"s": "BTCUSDT", "b": [["83808.8", "0"], ["83808.7", "0"], ["83807.1", "0.071627"], ["83801.7", "0.015119"], ["83796.6", "0.071636"], ["83765.8", "0"], ["83765.1", "0"], ["83765", "0"], ["83764.8", "0.013216"], ["83764.7", "0.012883"], ["83754.5", "5.567491"], ["83727.7", "0.052"], ["83727.4", "0"], ["83726.4", "0.045815"], ["83726", "0.044311"], ["83725.4", "0.044357"], ["83724.7", "0.161243"]], "a": [["83810.2", "0.471794"], ["83838.3", "0.071727"], ["83841.1", "0"], ["83841.2", "0.059399"], ["83841.3", "0.01264"], ["83841.4", "0.120933"], ["83841.6", "0"], ["83841.7", "0"], ["83841.8", "0.04"], ["83841.9", "0.063867"], ["83853.5", "0"], ["83861.7", "2.607218"], ["83864.6", "0.059399"], ["83879.4", "0.000512"]], "u": 49237, "seq": 67553307925}, "cts": 1742561133117, "record_time": 1742561133.144297, "EXCHANGE": "BYBIT"}
{"topic": "orderbook.200.BTCUSDT", "ts": 1742561133320, "type": "delta", "data": {"s": "BTCUSDT", "b": [["83810.1", "0.529698"], ["83809.7", "0.071625"], ["83807.1", "0"], ["83801.2", "0.071632"], ["83796.6", "0"], ["83768.7", "0.056755"], ["83760.2", "5.567491"], ["83754.5", "0"], ["83736.5", "0.000657"], ["83736.1", "0"], ["83726.4", "0.045558"], ["83724.3", "0.011884"]], "a": [["83850.4", "0"], ["83880.1", "0.001466"]], "u": 49238, "seq": 67553307956}, "cts": 1742561133316, "record_time": 1742561133.341637, "EXCHANGE": "BYBIT"}
{"topic": "orderbook.200.BTCUSDT", "ts": 1742561133520, "type": "delta", "data": {"s": "BTCUSDT", "b": [["83810.1", "0.496698"], ["83809.7", "0"], ["83808.7", "0.071625"], ["83727.1", "0.000333"], ["83726", "0.00009"], ["83725.8", "0.02083"], ["83725.4", "0"], ["83724.8", "0.044221"], ["83724.3", "0"]], "a": [["83810.2", "0.477794"], ["83834.1", "0.010581"], ["83841.3", "0.05264"], ["83841.4", "0.160933"], ["83841.8", "0"], ["83841.9", "0.023867"], ["83849.3", "0.175531"]], "u": 49239, "seq": 67553307986}, "cts": 1742561133507, "record_time": 1742561133.590632, "EXCHANGE": "BYBIT"}
{"topic": "orderbook.200.BTCUSDT", "ts": 1742561133719, "type": "delta", "data": {"s": "BTCUSDT", "b": [["83810.1", "0.496862"], ["83793.5", "0.024162"], ["83765.2", "0.101982"], ["83765.1", "0.012883"], ["83764.8", "0.000333"], ["83764.7", "0"], ["83760.3", "2.844844"], ["83757", "0.023866"], ["83724.7", "0"]], "a": [["83834.1", "0.009602"], ["83834.6", "0.001087"], ["83840.7", "0.013"], ["83840.8", "0.01264"], ["83841.3", "0.04"], ["83841.4", "0.148293"], ["83849.3", "0"], ["83879.4", "0"], ["83880.1", "0"]], "u": 49240, "seq": 67553308022}, "cts": 1742561133704, "record_time": 1742561133.741067, "EXCHANGE": "BYBIT"}
{"topic": "orderbook.200.BTCUSDT", "ts": 1742561133920, "type": "delta", "data": {"s": "BTCUSDT", "b": [["83810.1", "0.378607"], ["83808.7", "0"], ["83807.1", "0.071627"], ["83802.2", "0.055678"], ["83801.2", "0"], ["83801", "0.00051"], ["83799.6", "0"], ["83799.3", "0.023061"], ["83798.6", "0.071634"], ["83796.1", "0.071636"], ["83793.5", "0"], ["83788.9", "0.045554"], ["83788.1", "0"], ["83786", "0"], ["83785.5", "0.035804"], ["83781.2", "0"], ["83776.1", "0.02448"], ["83765.2", "0.089099"], ["83765.1", "0"], ["83764.5", "0.012884"], ["83764.4", "0.012884"], ["83761.7", "0"], ["83760.2", "0"], ["83758.9", "0.099499"], ["83746", "5.812402"], ["83727.5", "0.044426"], ["83726.4", "0.001333"], ["83725.8", "0.020707"], ["83725.2", "0.088678"], ["83724.8", "0"], ["83724.7", "0.205634"]], "a": [["83810.2", "0.556338"], ["83816.4", "0.182916"], ["83818.3", "0.000298"], ["83821.8", "0.058791"], ["83822.2", "0.01194"], ["83824.2", "0.089099"], ["83828.2", "0"], ["83831.6", "0"], ["83834.6", "0"], ["83841.2", "0.099399"], ["83841.4", "0.108293"], ["83849.3", "0.175365"], ["83856", "0.001431"], ["83860", "0.022756"], ["83861.7", "0.001466"], ["83865.1", "0"], ["83870.2", "2.605752"], ["83878.2", "0"]], "u": 49241, "seq": 67553308185}, "cts": 1742561133916, "record_time": 1742561133.941373, "EXCHANGE": "BYBIT"}
{"topic": "orderbook.200.BTCUSDT", "ts": 1742561134120, "type": "delta", "data": {"s": "BTCUSDT", "b": [["83810.1", "0.408437"], ["83807.1", "0"], ["83802.2", "0.058678"], ["83798.6", "0"], ["83796.1", "0"], ["83788.9", "0.031371"], ["83788.7", "0.024114"], ["83785.5", "0"], ["83785.4", "0.035805"], ["83760.3", "0.001466"], ["83751.7", "5.641402"], ["83746", "0.171"], ["83726.9", "0.021145"], ["83725.9", "0.044166"], ["83725.8", "0"], ["83724.7", "0.161243"]], "a": [["83810.2", "0.58617"], ["83818.3", "0"], ["83821.8", "0.105135"], ["83822.2", "0.190916"], ["83879.4", "0.000512"]], "u": 49242, "seq": 67553308301}, "cts": 1742561134114, "record_time": 1742561134.141594, "EXCHANGE": "BYBIT"}
{"topic": "orderbook.200.BTCUSDT", "ts": 1742561134320, "type": "delta", "data": {"s": "BTCUSDT", "b": [["83810.1", "0.401466"], ["83800.5", "0.071632"], ["83796", "0.071636"], ["83788.9", "0.052901"], ["83768.5", "0"], ["83763", "5.641402"], ["83761.7", "0.099499"], ["83758.9", "0"], ["83751.7", "0"], ["83727.5", "0"], ["83727.4", "0.044479"], ["83724.7", "0"]], "a": [["83861.7", "2.607218"], ["83870.2", "0"], ["83878.2", "0.171"]], "u": 49243, "seq": 67553308326}, "cts": 1742561134313, "record_time": 1742561134.350136, "EXCHANGE": "BYBIT"}
{"topic": "orderbook.200.BTCUSDT", "ts": 1742561134519, "type": "delta", "data": {"s": "BTCUSDT", "b": [["83810.1", "0.57389"], ["83803.6", "0.024948"], ["83802.6", "0.071631"], ["83799.9", "0.001"], ["83796", "0"], ["83765.8", "5.641402"], ["83763", "0"], ["83726.9", "0.020686"], ["83725.2", "0"], ["83725", "0"]], "a": [["83810.2", "0.586648"], ["83824.2", "0"], ["83840.6", "0.04"], ["83840.7", "0.053"], ["83841.2", "0.059399"], ["83841.3", "0"], ["83880.1", "0.001466"]], "u": 49244, "seq": 67553308358}, "cts": 1742561134514, "record_time": 1742561134.539641, "EXCHANGE": "BYBIT"}
{"topic": "orderbook.200.BTCUSDT", "ts": 1742561134720, "type": "delta", "data": {"s": "BTCUSDT", "b": [["83810.1", "0.506066"], ["83808.9", "0.071625"], ["83803.6", "0"], ["83802.6", "0"], ["83798.2", "0.071634"], ["83728.6", "0.044713"], ["83727.4", "0"]], "a": [["83840.6", "0"], ["83840.8", "0.05264"], ["83880.7", "0.011994"]], "u": 49245, "seq": 67553308379}, "cts": 1742561134713, "record_time": 1742561134.740523, "EXCHANGE": "BYBIT"}
{"topic": "orderbook.200.BTCUSDT", "ts": 1742561134920, "type": "delta", "data": {"s": "BTCUSDT", "b": [["83768.7", "1.732391"], ["83764.9", "0.014349"], ["83764.8", "0.013216"], ["83764.5", "0"], ["83764.4", "0"], ["83725.2", "0.044744"], ["83725.1", "0.043916"]], "a": [["83832.6", "0.001225"], ["83840.1", "0.01264"], ["83840.2", "0.013063"], ["83840.6", "0.04"], ["83840.7", "0.04"], ["83840.8", "0"], ["83847.9", "0.003916"], ["83880.1", "0"], ["83880.7", "0"]], "u": 49246, "seq": 67553308398}, "cts": 1742561134899, "record_time": 1742561134.940875, "EXCHANGE": "BYBIT"}
{"topic": "orderbook.200.BTCUSDT", "ts": 1742561135119, "type": "delta", "data": {"s": "BTCUSDT", "b": [["83810.1", "0.57769"], ["83808.9", "0"], ["83805.7", "0.006915"], ["83802.2", "0.094356"], ["83800.9", "0.089099"], ["83798.3", "0.207384"], ["83798.2", "0"], ["83795.5", "0.458539"], ["83788.1", "0.027104"], ["83785.7", "0.303645"], ["83785.1", "0"], ["83768.8", "0.119299"], ["83765.8", "0"], ["83765", "0.013"], ["83764.8", "0.000333"], ["83734.7", "5.655645"], ["83725.9", "0"], ["83725.2", "0"], ["83725.1", "0"]], "a": [["83810.2", "0.354203"], ["83814.5", "0"], ["83814.6", "0"], ["83816.2", "0"], ["83816.3", "0"], ["83816.4", "0.178963"], ["83817.2", "0.111106"], ["83818", "0"], ["83820.9", "0.012512"], ["83821.8", "0"], ["83821.9", "0"], ["83822.2", "0.01194"], ["83823.9", "0.175524"], ["83826", "0.003938"], ["83826.7", "0"], ["83827.6", "0.059732"], ["83827.7", "0"], ["83829.8", "0.119299"], ["83832.6", "0"], ["83838.4", "0"], ["83840.1", "0"], ["83840.2", "0.000423"], ["83840.6", "0"], ["83840.7", "0"], ["83841.9", "0.036867"], ["83842", "0.024524"], ["83842.4", "0.04"], ["83842.5", "0.040512"], ["83861.7", "0.001466"], ["83878.7", "2.605752"], ["83880.1", "0.001466"], ["83880.7", "0.011994"], ["83880.9", "0.12"], ["83881.1", "0.015238"], ["83881.2", "0.00018"], ["83881.4", "0.029514"], ["83881.6", "0.119299"], ["83882.1", "0.000333"]], "u": 49247, "seq": 67553308551}, "cts": 1742561135111, "record_time": 1742561135.165349, "EXCHANGE": "BYBIT"}
{"topic": "orderbook.200.BTCUSDT", "ts": 1742561135320, "type": "delta", "data": {"s": "BTCUSDT", "b": [["83810.1", "0.580201"], ["83800.9", "0"], ["83788.7", "0"], ["83785.7", "0.089432"], ["83768.7", "0.056755"], ["83737.5", "5.655645"], ["83734.7", "0"], ["83727", "0.044454"], ["83726.3", "0.088894"]], "a": [["83810.2", "0.357185"], ["83816.3", "0.227196"], ["83823.8", "0.119299"], ["83826.8", "0.035804"], ["83838.3", "0.044997"], ["83881.4", "0"], ["83881.6", "0"], ["83882.1", "0"]], "u": 49248, "seq": 67553308603}, "cts": 1742561135314, "record_time": 1742561135.341069, "EXCHANGE": "BYBIT"}
{"success": true, "ret_msg": "subscribe", "conn_id": "fb29d157-5a79-4cb5-bdf1-a2459dba93da", "op": "subscribe", "record_time": 1742561183.736862, "EXCHANGE": "BYBIT"}
{"topic": "orderbook.200.BTCUSDT", "ts": 1742561183320, "type": "snapshot", "data": {"s": "BTCUSDT", "b": [["83795.1", "0.002274"], ["83795", "0.0006"], ["83794.1", "0.000333"], ["83793.4", "0.001333"], ["83793.1", "0.00318"], ["83792.5", "0.001466"], ["83792.1", "0.07164"], ["83791.7", "0.00051"], ["83790.8", "0.000994"], ["83790.3", "0.0003"], ["83789.9", "0.000333"], ["83789.2", "0.001333"], ["83788.9", "0.003178"], ["83787.9", "0.001466"], ["83787.6", "0.001739"], ["83787.1", "0.00051"], ["83786.7", "0.015"], ["83786.5", "0.0045"], ["83785.7", "0.000631"], ["83785.6", "0.131901"], ["83785.5", "0.004062"], ["83785", "0.001333"], ["83784.8", "0.00009"], ["83784.7", "0.003178"], ["83783.5", "0.000298"], ["83783.4", "0.119299"], ["83783.3", "0.226594"], ["83783.2", "0.071647"], ["83782.9", "0.000358"], ["83782.5", "0.00051"], ["83781.6", "0.000333"], ["83781.3", "0.089436"], ["83781.2", "0.071649"], ["83780.8", "0.001333"], ["83780.5", "0.003775"], ["83780.2", "0.04"], ["83780.1", "0.04"], ["83780", "0.00024"], ["83779.7", "0.004758"], ["83778.7", "0.001466"], ["83778.6", "0.052"], ["83778.5", "0.058275"], ["83778.3", "0.02378"], ["83777.9", "0.00051"], ["83777.4", "0.000333"], ["83777", "0.0006"], ["83776.8", "0.044"], ["83776.6", "0.326106"], ["83776.5", "0.048"], ["83776.4", "0.011974"], ["83776.3", "0.003174"], ["83775.9", "0.559664"], ["83775.7", "0.003"], ["83775.1", "0.163299"], ["83774.9", "0.200264"], ["83774.8", "0.052"], ["83774.1", "0.001466"], ["83773.7", "0.044"], ["83773.5", "0.009234"], ["83773.4", "0.048"], ["83773.3", "0.00051"], ["83773.2", "0.000333"], ["83772.5", "0.001333"], ["83772.1", "0.003163"], ["83771.9", "0.000689"], ["83771.3", "0.009"], ["83771.2", "0.004775"], ["83769.5", "0.001466"], ["83769", "0.000451"], ["83768.7", "0.00051"], ["83768.3", "0.001333"], ["83768", "0.119389"], ["83767.9", "0.003161"], ["83767.1", "0.00009"], ["83766.6", "0.193204"], ["83766.5", "0.171"], ["83766.1", "0.488044"], ["83765.7", "0.000083"], ["83765.1", "0.00092"], ["83764.9", "0.001466"], ["83764.8", "0.005032"], ["83764.1", "0.001843"], ["83763.7", "0.003161"], ["83762.4", "0.0002"], ["83762.1", "0.119299"], ["83760.8", "0.002558"], ["83760.6", "0.000333"], ["83760.3", "0.001466"], ["83760", "0.00006"], ["83759.9", "0.001333"], ["83759.6", "0.015134"], ["83759.5", "0.00051"], ["83759.4", "0.093519"], ["83758.1", "0.171"], ["83757.7", "0.020928"], ["83756.5", "0.0045"], ["83756.4", "0.000333"], ["83755.7", "0.002799"], ["83755.4", "0.00376"], ["83755", "0.023834"], ["83754.9", "0.00051"], ["83754.8", "0.062172"], ["83754.7", "0.06083"], ["83754.5", "0.013"], ["83754.4", "0.012882"], ["83753.9", "0.119299"], ["83753", "0.013795"], ["83752.4", "0.0001"], ["83752.2", "0.000333"], ["83751.5", "0.001333"], ["83751.2", "0.003248"], ["83751.1", "0.001466"], ["83750.3", "0.000508"], ["83750", "0.004192"], ["83749.8", "0.090087"], ["83749.7", "0.171"], ["83748.2", "0.119299"], ["83748", "0.000333"], ["83747.3", "0.001333"], ["83747", "0.003157"], ["83746.5", "0.001466"], ["83746.3", "0.011942"], ["83746.2", "0.059399"], ["83745.7", "0.000508"], ["83743.9", "0.000333"], ["83743.1", "0.001333"], ["83742.8", "0.015127"], ["83742.6", "0.023865"], ["83742", "0.119299"], ["83741.9", "0.101006"], ["83741.3", "0.18"], ["83741.1", "0.000508"], ["83740.8", "0.443504"], ["83740.3", "0.005966"], ["83740", "0.00006"], ["83739.7", "0.000333"], ["83739", "0.001333"], ["83738.7", "0.000358"], ["83738.6", "0.003153"], ["83737.5", "0.062811"], ["83737.4", "0.063865"], ["83737.3", "0.001466"], ["83736.8", "0.119332"], ["83736.5", "0.024373"], ["83735.5", "0.000333"], ["83734.8", "0.001333"], ["83734.4", "0.003243"], ["83732.9", "0.171"], ["83732.6", "0.001798"], ["83732", "0.024465"], ["83731.9", "0.000508"], ["83731.6", "0.023865"], ["83731.3", "0.000333"], ["83730.6", "0.001333"], ["83730.5", "0.013137"], ["83730.2", "0.954485"], ["83730.1", "0.059399"], ["83729.5", "0.235392"], ["83729.4", "0.119299"], ["83728", "0.001466"], ["83727.7", "0.052"], ["83727.3", "0.000508"], ["83727.1", "0.000333"], ["83726.7", "0.000149"], ["83726.5", "0.0045"], ["83726.4", "0.001333"], ["83726.2", "8.227373"], ["83726.1", "0.003147"], ["83726", "0.00009"], ["83725", "0.00009"], ["83724.5", "0.171"], ["83723.8", "3.7328"], ["83723.4", "0.001466"], ["83723", "0.027823"], ["83722.9", "0.119632"], ["83722.6", "0.000508"], ["83722.5", "0.044"], ["83722.2", "0.001333"], ["83721.9", "0.003147"], ["83720.4", "0.089099"], ["83718.8", "0.001466"], ["83718.7", "0.000392"], ["83718.3", "0.059399"], ["83718", "0.001841"], ["83717.7", "0.003147"], ["83717.6", "0.00009"], ["83717.1", "0.052"], ["83716.8", "0.119299"], ["83716.6", "0.000358"], ["83716.2", "0.005871"], ["83716.1", "0.171"], ["83716", "0.015004"], ["83715.6", "0.626527"], ["83714.6", "0.000333"], ["83714.2", "0.001466"], ["83713.9", "3.333814"], ["83713.8", "0.001333"], ["83713.5", "0.003147"], ["83713.4", "0.000508"], ["83712.8", "0.000083"]], "a": [["83795.2", "0.758637"], ["83795.3", "0.003576"], ["83795.4", "0.064321"], ["83795.5", "0.1249"], ["83795.7", "0.035801"], ["83795.9", "0.035801"], ["83796.2", "0.035801"], ["83799.6", "0.066056"], ["83799.7", "0.179008"], ["83801", "0.00051"], ["83801.4", "0.00321"], ["83801.8", "0.002799"], ["83801.9", "0.014326"], ["83802.5", "0.000333"], ["83802.6", "0.130672"], ["83802.9", "0.024175"], ["83803", "0.089099"], ["83803.5", "0.053625"], ["83803.6", "0.015"], ["83805.5", "0.059399"], ["83805.6", "0.003721"], ["83805.7", "0.02"], ["83806", "0.001333"], ["83806.2", "0.014325"], ["83806.4", "0.001466"], ["83806.6", "0.00009"], ["83806.7", "0.179316"], ["83808.3", "0.005966"], ["83809.5", "0.065774"], ["83809.8", "0.003213"], ["83810", "0.12035"], ["83810.1", "0.04"], ["83810.2", "0.229187"], ["83810.3", "0.125306"], ["83810.7", "0.003875"], ["83810.8", "0.000999"], ["83810.9", "0.000333"], ["83811", "0.103515"], ["83811.7", "0.04"], ["83811.9", "0.044"], ["83813.5", "0.04"], ["83813.6", "0.04"], ["83814", "0.003216"], ["83814.4", "0.001333"], ["83814.8", "0.036319"], ["83814.9", "0.119339"], ["83815", "0.00009"], ["83815.1", "0.000933"], ["83815.2", "0.081027"], ["83815.3", "0.04"], ["83815.4", "0.089099"], ["83815.6", "0.001466"], ["83816.7", "0.0493"], ["83816.9", "0.04"], ["83817.1", "0.003"], ["83818.2", "0.003216"], ["83818.3", "0.0006"], ["83818.5", "0.019578"], ["83819.3", "0.000333"], ["83819.4", "0.00051"], ["83819.6", "0.023865"], ["83820.2", "0.078556"], ["83820.3", "0.171"], ["83820.4", "0.0006"], ["83821.3", "0.059399"], ["83822.4", "0.003216"], ["83822.7", "0.001333"], ["83823", "0.000994"], ["83823.4", "0.00009"], ["83823.5", "0.000333"], ["83823.6", "0.02"], ["83823.8", "0.01194"], ["83824", "0.00051"], ["83824.7", "0.04288"], ["83824.8", "0.001466"], ["83825.1", "0.02"], ["83825.4", "0.023865"], ["83825.7", "0.023865"], ["83826", "0.023865"], ["83826.6", "0.003216"], ["83826.7", "0.02"], ["83826.9", "0.014333"], ["83827", "0.01262"], ["83827.2", "0.023865"], ["83827.4", "0.04"], ["83827.5", "0.04"], ["83827.6", "0.000454"], ["83827.7", "0.026424"], ["83828.3", "0.005966"], ["83828.6", "0.00051"], ["83829.4", "0.314328"], ["83829.5", "0.191"], ["83829.8", "0.004164"], ["83829.9", "0.461734"], ["83830.1", "0.0012"], ["83830.8", "0.003218"], ["83831.1", "0.001333"], ["83831.3", "0.009"], ["83831.6", "0.0002"], ["83831.8", "0.000423"], ["83831.9", "0.079399"], ["83832.1", "0.037843"], ["83833.2", "0.00051"], ["83834", "0.001466"], ["83834.1", "0.05009"], ["83835", "0.003222"], ["83835.3", "0.001333"], ["83835.4", "0.05009"], ["83835.7", "0.004614"], ["83836", "0.000333"], ["83836.4", "0.023864"], ["83836.8", "0.119299"], ["83836.9", "0.736435"], ["83837", "1.431093"], ["83837.5", "0.01199"], ["83837.6", "0.02398"], ["83837.7", "0.089099"], ["83837.8", "0.00051"], ["83838", "0.22109"], ["83838.1", "0.003564"], ["83838.6", "0.001466"], ["83838.8", "0.000358"], ["83838.9", "0.022725"], ["83839", "0.557165"], ["83839.1", "2.605725"], ["83839.2", "0.003222"], ["83839.5", "0.001333"], ["83840.2", "0.000423"], ["83840.3", "0.109489"], ["83840.4", "0.144396"], ["83841.9", "0.119299"], ["83842.2", "0.023864"], ["83842.5", "0.024374"], ["83842.6", "0.05009"], ["83842.8", "0.023863"], ["83843.2", "0.001466"], ["83843.4", "0.003222"], ["83843.5", "0.05009"], ["83843.6", "0.161658"], ["83843.7", "0.013217"], ["83844", "0.023864"], ["83844.4", "0.000333"], ["83844.8", "0.016828"], ["83845.1", "0.005966"], ["83845.2", "0.015"], ["83846.5", "0.0045"], ["83847", "0.003564"], ["83847.1", "0.00051"], ["83847.5", "0.119299"], ["83847.6", "0.003822"], ["83847.9", "0.195282"], ["83848.6", "0.000423"], ["83848.8", "0.014085"], ["83849.5", "0.354507"], ["83849.7", "0.059638"], ["83850.4", "0.059399"], ["83850.6", "0.079459"], ["83851.7", "0.003756"], ["83852", "0.195"], ["83852.1", "0.001333"], ["83852.5", "0.001466"], ["83852.8", "0.000333"], ["83853", "0.08"], ["83854", "0.000118"], ["83854.2", "0.00315"], ["83854.7", "0.044"], ["83855", "0.000203"], ["83855.7", "0.001745"], ["83855.8", "0.01199"], ["83855.9", "0.003244"], ["83856", "0.002147"], ["83856.3", "0.001845"], ["83856.5", "0.04"], ["83857", "0.000423"], ["83857.1", "0.001466"], ["83858.1", "0.002721"], ["83859.4", "0.119299"], ["83859.5", "0.230756"], ["83859.6", "0.040332"], ["83859.8", "0.04"], ["83860.1", "0.003244"], ["83860.3", "0.059399"], ["83860.4", "0.4"], ["83860.5", "0.013217"], ["83860.9", "0.00087"], ["83861.2", "0.000333"], ["83861.3", "0.009"], ["83861.4", "0.171"], ["83861.7", "0.001466"], ["83863.1", "0.059638"], ["83864.3", "0.092343"], ["83864.7", "0.001423"], ["83865.4", "0.000423"], ["83865.5", "0.000512"], ["83866.3", "0.001466"], ["83868.5", "0.003244"], ["83868.9", "0.120632"], ["83869", "3.152803"], ["83869.6", "0.000333"], ["83869.8", "0.171"]], "u": 49488, "seq": 67553365657}, "cts": 1742561183314, "record_time": 1742561183.738241, "EXCHANGE": "BYBIT"}
{"topic": "orderbook.200.BTCUSDT", "ts": 1742561183519, "type": "delta", "data": {"s": "BTCUSDT", "b": [["83795.1", "0.005257"], ["83792.1", "0"], ["83786.9", "0.000298"], ["83786.8", "0.027641"], ["83785.7", "0.000333"], ["83785.5", "0"], ["83783.5", "0"], ["83783.2", "0"], ["83781.2", "0"], ["83779.7", "0"], ["83778.4", "0.071651"], ["83775.5", "0.004062"], ["83774.9", "0.171"], ["83772.4", "0.157924"], ["83759.4", "0"], ["83754.5", "0"], ["83754.4", "0"], ["83753.6", "0.013"], ["83753.5", "0.012882"], ["83741.9", "0.001466"], ["83739", "0.100873"], ["83729", "8.227373"], ["83726.2", "0"], ["83716", "0.009655"], ["83713.9", "3.28972"], ["83711.7", "0.119299"], ["83711.5", "0.021783"]], "a": [["83798.6", "0.029511"], ["83805.1", "0.018245"], ["83811", "0.111035"], ["83815.2", "0.082201"], ["83818.5", "0.001333"], ["83826.9", "0.001333"], ["83827", "0"], ["83827.2", "0.036865"], ["83827.3", "0.01262"], ["83827.4", "0"], ["83827.5", "0"], ["83827.7", "0.066424"], ["83827.8", "0.04"], ["83836.3", "2.605725"], ["83839.1", "0"], ["83852.9", "0.089268"], ["83855.7", "0"], ["83869.8", "0"]], "u": 49489, "seq": 67553365910}, "cts": 1742561183516, "record_time": 1742561183.739306, "EXCHANGE": "BYBIT"}
{"topic": "orderbook.200.BTCUSDT", "ts": 1742561183719, "type": "delta", "data": {"s": "BTCUSDT", "b": [["83786.9", "0"], ["83786.8", "0"], ["83785.7", "0.000631"], ["83780.7", "0.071649"], ["83777.4", "0.118067"], ["83772.5", "0.054573"], ["83772.4", "0"], ["83769.9", "0.157699"], ["83767.6", "0.173277"], ["83758.5", "0.291292"], ["83739", "0.100869"], ["83729", "8.037114"], ["83711.5", "0"]], "a": [["83795.4", "0.042961"], ["83795.5", "0.035801"], ["83802.6", "0.239424"], ["83812.4", "0.169007"], ["83815.2", "0.081027"], ["83821.5", "0.297542"], ["83827.2", "0.076865"], ["83827.3", "0.05262"], ["83827.7", "0.026424"], ["83827.8", "0"], ["83833.5", "2.605725"], ["83836.3", "0"], ["83869.6", "0"]], "u": 49490, "seq": 67553366100}, "cts": 1742561183716, "record_time": 1742561183.740059, "EXCHANGE": "BYBIT"}
{"topic": "orderbook.200.BTCUSDT", "ts": 1742561183919, "type": "delta", "data": {"s": "BTCUSDT", "b": [["83790.3", "0"], ["83789.7", "0.071642"], ["83786.8", "0.000298"], ["83782.6", "0.071648"], ["83780.7", "0"], ["83777.4", "0.000333"], ["83774.8", "0.082141"], ["83767.6", "0"], ["83758.5", "0"], ["83753.6", "0"], ["83753.5", "0"], ["83753.1", "0.013"], ["83753", "0.026677"], ["83741.9", "0.101002"], ["83739", "0.001333"], ["83715.5", "0.0003"], ["83711.5", "0.021783"]], "a": [["83795.2", "0.758626"], ["83802.6", "0.130672"], ["83812.4", "0"], ["83821.5", "0"], ["83826.5", "0.013"], ["83826.6", "0.015836"], ["83827", "0.04"], ["83827.1", "0.04"], ["83827.2", "0.023865"], ["83827.3", "0"]], "u": 49491, "seq": 67553366239}, "cts": 1742561183916, "record_time": 1742561183.936804, "EXCHANGE": "BYBIT"}
{"topic": "orderbook.200.BTCUSDT", "ts": 1742561184120, "type": "delta", "data": {"s": "BTCUSDT", "b": [["83789.7", "0.003"], ["83744.7", "0.099536"], ["83741.9", "0.001466"], ["83731.9", "8.037622"], ["83729", "0"]], "a": [["83795.2", "0.764626"], ["83816.7", "0.050247"]], "u": 49492, "seq": 67553366324}, "cts": 1742561184107, "record_time": 1742561184.1379, "EXCHANGE": "BYBIT"}
{"topic": "orderbook.200.BTCUSDT", "ts": 1742561184319, "type": "delta", "data": {"s": "BTCUSDT", "b": [["83795.1", "0"], ["83795", "0"], ["83794.1", "0"], ["83793.7", "0.075038"], ["83786.7", "0.01"], ["83785.3", "0.005"], ["83784.7", "0.074824"], ["83781.3", "0.066514"], ["83778.4", "0"], ["83758.2", "0.059028"], ["83753.1", "0"], ["83752.9", "0.012882"], ["83711.3", "0.009"]], "a": [["83793.8", "1.504524"], ["83794.2", "0.13719"], ["83795.1", "0.227002"], ["83795.2", "0.472059"], ["83795.4", "0"], ["83798.3", "0.000333"], ["83798.6", "0"], ["83799.2", "0.014326"], ["83802.2", "0.005"], ["83803", "0"], ["83803.6", "0.01"], ["83806.2", "0"], ["83815", "0.00069"], ["83816.7", "0.0493"], ["83826.5", "0"], ["83826.7", "0.03262"], ["83827", "0"], ["83827.2", "0.063865"]], "u": 49493, "seq": 67553366490}, "cts": 1742561184317, "record_time": 1742561184.336771, "EXCHANGE": "BYBIT"}
{"topic": "orderbook.200.BTCUSDT", "ts": 1742561184520, "type": "delta", "data": {"s": "BTCUSDT", "b": [["83790.8", "0"], ["83789.4", "0.000995"], ["83786.7", "0"], ["83785.3", "0.015"], ["83773", "0.055226"], ["83766", "0.055429"], ["83762.2", "0.036657"], ["83759", "0.123852"], ["83753.3", "0.013"], ["83753.2", "0.012882"], ["83753", "0.013795"], ["83752.9", "0"], ["83746.3", "0.059875"], ["83744.7", "0"], ["83742.1", "0.225341"], ["83741.9", "0.100981"], ["83734.7", "8.037114"], ["83731.9", "0.000508"], ["83716", "0.009488"], ["83713.4", "0"], ["83712.8", "0"], ["83711.7", "0"], ["83711.5", "0"], ["83711.3", "0"]], "a": [["83793.8", "1.58393"], ["83794.2", "0"], ["83795.1", "0.116585"], ["83795.2", "0.368"], ["83795.5", "0"], ["83795.7", "0"], ["83795.9", "0"], ["83796.2", "0"], ["83802.2", "0.015"], ["83803.6", "0"], ["83808", "0.054595"], ["83815", "0.063032"], ["83815.2", "0.103529"], ["83822", "0.122826"], ["83825", "0.081638"], ["83826.1", "0.01262"], ["83826.2", "0.01262"], ["83826.5", "0.04"], ["83826.6", "0.043216"], ["83826.7", "0.02"], ["83827.1", "0"], ["83827.2", "0.023865"], ["83832.1", "0.810485"], ["83833.5", "0"], ["83835.6", "1.431093"], ["83837", "0"], ["83842", "2.605725"], ["83869.6", "0.000333"]], "u": 49494, "seq": 67553366578}, "cts": 1742561184517, "record_time": 1742561184.537556, "EXCHANGE": "BYBIT"}
{"topic": "orderbook.200.BTCUSDT", "ts": 1742561184719, "type": "delta", "data": {"s": "BTCUSDT", "b": [["83759.1", "0.096184"], ["83758.2", "0"], ["83753.4", "0.013"], ["83753.3", "0.012882"], ["83753.2", "0"], ["83746.3", "0.011942"]], "a": [["83795", "0.060273"], ["83795.1", "0"], ["83795.2", "0.191"], ["83815", "0.063033"], ["83826", "0.036865"], ["83826.2", "0"], ["83832.1", "0.458095"], ["83836.9", "0"], ["83842", "2.605769"], ["83870.1", "0.000512"], ["83870.4", "0.04"]], "u": 49495, "seq": 67553366655}, "cts": 1742561184716, "record_time": 1742561184.736662, "EXCHANGE": "BYBIT"}
{"topic": "orderbook.200.BTCUSDT", "ts": 1742561184919, "type": "delta", "data": {"s": "BTCUSDT", "b": [["83793.7", "0.275955"], ["83786.8", "0.022843"], ["83786.7", "0.071644"], ["83784.7", "0.003178"], ["83773", "0"], ["83766", "0"], ["83759", "0"], ["83746.4", "0.021655"], ["83737.5", "7.951702"], ["83734.7", "0"], ["83713.4", "0.000508"], ["83712.8", "0.000083"]], "a": [["83795.3", "0"], ["83801.3", "0.029452"], ["83808", "0"], ["83815", "0.001806"], ["83822", "0"], ["83837.6", "0.327113"], ["83839.1", "2.605769"], ["83842", "0"], ["83869.8", "0.171"], ["83870.9", "0.001466"]], "u": 49496, "seq": 67553366744}, "cts": 1742561184914, "record_time": 1742561184.988338, "EXCHANGE": "BYBIT"}
{"topic": "orderbook.200.BTCUSDT", "ts": 1742561185120, "type": "delta", "data": {"s": "BTCUSDT", "b": [["83793.7", "0.075038"], ["83759.1", "0.059028"], ["83753.4", "0"], ["83753.3", "0"], ["83753.1", "0.013"], ["83753", "0.026677"], ["83739.4", "0.128972"]], "a": [["83803.2", "0.178991"], ["83815", "0.00069"], ["83818.2", "0.006792"], ["83826", "0.023865"], ["83826.2", "0.01262"], ["83826.5", "0"], ["83826.7", "0.06"], ["83837.6", "1.070952"], ["83839.1", "0"], ["83842", "2.605769"], ["83858", "1.126906"], ["83870.4", "0"], ["83870.9", "0"]], "u": 49497, "seq": 67553366829}, "cts": 1742561185108, "record_time": 1742561185.137735, "EXCHANGE": "BYBIT"}
{"topic": "orderbook.200.BTCUSDT", "ts": 1742561185320, "type": "delta", "data": {"s": "BTCUSDT", "b": [["83759.3", "0.023841"], ["83755", "0"], ["83753.4", "0.013"], ["83753.3", "0.012882"], ["83753.1", "0"], ["83753", "0.013795"], ["83737.5", "0.062811"], ["83735.5", "0.015333"], ["83734.7", "7.888891"], ["83713.4", "0"], ["83712.8", "0"]], "a": [["83826", "0.036865"], ["83826.2", "0"], ["83826.5", "0.04"], ["83826.7", "0.02"], ["83837.6", "0.327113"], ["83838.9", "0"], ["83840.4", "0.912283"], ["83870.4", "0.04"]], "u": 49498, "seq": 67553366912}, "cts": 1742561185313, "record_time": 1742561185.337573, "EXCHANGE": "BYBIT"}
{"topic": "orderbook.200.BTCUSDT", "ts": 1742561185520, "type": "delta", "data": {"s": "BTCUSDT", "b": [["83793.7", "0.0042"], ["83792.5", "0.073105"], ["83786.9", "0.000298"], ["83782.4", "0.0096"], ["83773.2", "0.06031"], ["83766.2", "0.05948"], ["83760.8", "0.000958"], ["83759.2", "0.118806"], ["83753.7", "0.0016"], ["83753.4", "0"], ["83753.2", "0.012882"], ["83737.5", "7.951702"], ["83734.7", "0"], ["83714.2", "0"], ["83713.9", "0"], ["83713.8", "0"], ["83713.5", "0"]], "a": [["83808.2", "0.060405"], ["83811.1", "0.004774"], ["83814.8", "0.00051"], ["83815.2", "0.158946"], ["83822.2", "0.11659"], ["83826", "0.023865"], ["83826.2", "0.01262"], ["83826.5", "0"], ["83826.7", "0.06"], ["83842", "0"], ["83843.2", "0.025474"], ["83844.8", "2.622597"], ["83870.1", "0"], ["83870.4", "0"]], "u": 49499, "seq": 67553366981}, "cts": 1742561185492, "record_time": 1742561185.537297, "EXCHANGE": "BYBIT"}
{"topic": "orderbook.200.BTCUSDT", "ts": 1742561185720, "type": "delta", "data": {"s": "BTCUSDT", "b": [["83793.7", "0.276755"], ["83792.5", "0.001466"], ["83775.6", "0.056596"], ["83773.2", "0.000333"], ["83768.6", "0.05838"], ["83766.2", "0"], ["83761.6", "0.120033"], ["83759.3", "0.118511"], ["83759.2", "0"], ["83759.1", "0"], ["83753.3", "0"], ["83753.2", "0"], ["83753.1", "0.013"], ["83753", "0.026677"], ["83737.5", "7.658334"], ["83714.2", "0.001466"]], "a": [["83808.2", "0"], ["83810.6", "0.058076"], ["83815.2", "0.103529"], ["83817.6", "0.05932"], ["83822.2", "0"], ["83824.6", "0.114594"], ["83840.4", "0.144396"], ["83869.8", "0"]], "u": 49500, "seq": 67553367091}, "cts": 1742561185704, "record_time": 1742561185.73724, "EXCHANGE": "BYBIT"}
{"topic": "orderbook.200.BTCUSDT", "ts": 1742561185920, "type": "delta", "data": {"s": "BTCUSDT", "b": [["83793.7", "0.502437"], ["83788.7", "0.08124"], ["83788.6", "0.119299"], ["83788.4", "0.071643"], ["83786.9", "0"], ["83786.8", "0"], ["83782.6", "0"], ["83782", "0.089099"], ["83775.6", "0"], ["83775.5", "0"], ["83768.6", "0"], ["83767.8", "0.089099"], ["83766.7", "0.059399"], ["83766.2", "0.025061"], ["83761.6", "0"], ["83759.3", "0.059028"], ["83741.9", "0.001466"], ["83739.4", "0"], ["83737.5", "0.062811"], ["83715.6", "0.626538"], ["83714.2", "0.045298"], ["83713.9", "3.28972"]], "a": [["83793.8", "0.18928"], ["83795", "0"], ["83795.2", "0"], ["83799.2", "0"], ["83799.6", "0"], ["83799.7", "0"], ["83801.3", "0"], ["83801.9", "0"], ["83802.6", "0"], ["83803.1", "0.149382"], ["83805.1", "0"], ["83807.1", "0.014325"], ["83809.3", "0.014325"], ["83810.6", "0"], ["83811", "0.001466"], ["83811.1", "0"], ["83811.8", "0.051205"], ["83814.3", "0.035809"], ["83814.9", "0"], ["83815.2", "0.081027"], ["83815.4", "0"], ["83817.6", "0"], ["83817.9", "0.018245"], ["83818.2", "0.003216"], ["83824.5", "0.12932"], ["83824.6", "0"], ["83825", "0"], ["83826.1", "0"], ["83826.2", "0"], ["83826.6", "0.003216"], ["83826.7", "0.02"], ["83827.7", "0.039424"], ["83827.8", "0.01262"], ["83828.2", "0.04"], ["83828.3", "0.045966"], ["83829.4", "0.250845"], ["83836.8", "0"], ["83837.7", "0"], ["83840.8", "0.063484"], ["83841.9", "0"], ["83843.2", "0.001466"], ["83844.8", "0.016828"], ["83850.1", "0.022775"], ["83858", "0"], ["83870.1", "0.000512"], ["83870.4", "0.04"], ["83870.9", "0.001466"], ["83871.3", "0.044988"], ["83872.3", "0.04"], ["83872.7", "0.003244"], ["83873", "0.001333"], ["83873.4", "0.017903"], ["83873.7", "0.028169"], ["83873.8", "0.000423"], ["83874", "0.119299"]], "u": 49501, "seq": 67553367421}, "cts": 1742561185916, "record_time": 1742561185.938168, "EXCHANGE": "BYBIT"}
{"topic": "orderbook.200.BTCUSDT", "ts": 1742561186120, "type": "delta", "data": {"s": "BTCUSDT", "b": [["83789.2", "0.005395"], ["83766.7", "0"], ["83739", "0.100841"], ["83715.6", "0.0003"], ["83715.5", "0"], ["83713.8", "0.001333"], ["83713.5", "0.003147"]], "a": [["83793.8", "0.195485"], ["83796.3", "0.014327"], ["83805.2", "0.014325"], ["83807.1", "0"], ["83808.1", "0.184074"], ["83810", "0"], ["83811.3", "0.030305"], ["83814.3", "0"], ["83814.5", "0.035809"], ["83817.1", "0"], ["83824.5", "0.071056"], ["83827.7", "0.039044"], ["83869.8", "0.171"], ["83871.3", "0.04416"], ["83873.8", "0"], ["83874", "0"]], "u": 49502, "seq": 67553367628}, "cts": 1742561186114, "record_time": 1742561186.13693, "EXCHANGE": "BYBIT"}
{"topic": "orderbook.200.BTCUSDT", "ts": 1742561186319, "type": "delta", "data": {"s": "BTCUSDT", "b": [["83747.5", "0.099509"], ["83746", "7.595523"], ["83739", "0.001333"], ["83716", "0"], ["83715.4", "0.009488"], ["83714.2", "0.671836"], ["83713.8", "0"], ["83713.5", "0"]], "a": [["83802.9", "0.014326"], ["83809.3", "0"], ["83832.3", "0.063484"], ["83840.8", "0"], ["83844.8", "2.622597"], ["83873.3", "0.626538"]], "u": 49503, "seq": 67553367727}, "cts": 1742561186313, "record_time": 1742561186.337931, "EXCHANGE": "BYBIT"}
{"topic": "orderbook.200.BTCUSDT", "ts": 1742561186520, "type": "delta", "data": {"s": "BTCUSDT", "b": [["83793.7", "0.264022"], ["83782", "0"], ["83774.8", "0.052"], ["83746.4", "2.297605"], ["83745.5", "0.128963"], ["83714.3", "0.0445"], ["83714.2", "0.628004"], ["83713.9", "0"]], "a": [["83793.8", "0.407201"], ["83796.3", "0"], ["83800.8", "0.014326"], ["83805.2", "0"], ["83808.4", "0.024151"], ["83817.6", "0.003576"], ["83838.9", "0.119299"], ["83864.3", "1.219164"], ["83873.4", "0"], ["83873.7", "0"]], "u": 49504, "seq": 67553367895}, "cts": 1742561186516, "record_time": 1742561186.553817, "EXCHANGE": "BYBIT"}
{"topic": "orderbook.200.BTCUSDT", "ts": 1742561186719, "type": "delta", "data": {"s": "BTCUSDT", "b": [["83755.4", "0.01676"], ["83755.3", "0.012881"], ["83753.1", "0"], ["83753", "0.013795"], ["83746", "7.581881"], ["83716", "0.05"], ["83715.4", "0"], ["83714.3", "0.044277"]], "a": [["83793.8", "0.413201"], ["83826.7", "0.03262"], ["83826.8", "0.01262"], ["83827.7", "0.026424"], ["83827.8", "0"], ["83829.4", "0.314329"], ["83832.3", "0"], ["83843.6", "0"], ["83871.3", "0"], ["83873.4", "0.017903"], ["83873.7", "0.028169"], ["83873.8", "0.000423"]], "u": 49505, "seq": 67553367993}, "cts": 1742561186715, "record_time": 1742561186.738367, "EXCHANGE": "BYBIT"}
{"topic": "orderbook.200.BTCUSDT", "ts": 1742561186919, "type": "delta", "data": {"s": "BTCUSDT", "b": [["83793.7", "0.276785"], ["83781.3", "0.091487"], ["83780.6", "0.11096"], ["83770.8", "0.179229"], ["83761.7", "0.285648"], ["83755.4", "0.00376"], ["83755.3", "0"], ["83755.2", "0.012881"], ["83755.1", "0.012881"], ["83747.5", "0.099538"], ["83715.6", "0"], ["83714.6", "0"], ["83714.3", "0"], ["83714.2", "0"]], "a": [["83793.8", "0.419201"], ["83805.8", "0.123982"], ["83815.2", "0.131353"], ["83815.6", "0.164492"], ["83824.7", "0.335096"], ["83826.7", "0.02"], ["83826.8", "0"], ["83826.9", "0.013953"], ["83827", "0.01262"], ["83827.3", "0.04"], ["83827.4", "0.04"], ["83828.2", "0"], ["83828.3", "0.005966"], ["83832.5", "0.156723"], ["83840.4", "0.064315"], ["83873.4", "0"], ["83873.7", "0"], ["83873.8", "0"]], "u": 49506, "seq": 67553368105}, "cts": 1742561186913, "record_time": 1742561186.937074, "EXCHANGE": "BYBIT"}
{"topic": "orderbook.200.BTCUSDT", "ts": 1742561187120, "type": "delta", "data": {"s": "BTCUSDT", "b": [["83793.7", "0.307857"], ["83781.3", "0.066514"], ["83780.6", "0"], ["83770.8", "0"], ["83762.2", "0.117289"], ["83761.7", "0"], ["83715.6", "0.0003"], ["83714.6", "0.000333"], ["83714.5", "0.016747"]], "a": [["83805.8", "0"], ["83815.2", "0.081027"], ["83815.6", "0.001466"], ["83824.5", "0.173725"], ["83824.7", "0.04288"], ["83826.9", "0.001333"], ["83827", "0"], ["83827.1", "0.01262"], ["83827.2", "0.036485"], ["83827.3", "0"], ["83827.4", "0"], ["83827.6", "0.040454"], ["83827.7", "0.066424"], ["83873.4", "0.017903"], ["83873.7", "0.028169"], ["83873.8", "0.000423"]], "u": 49507, "seq": 67553368203}, "cts": 1742561187111, "record_time": 1742561187.13733, "EXCHANGE": "BYBIT"}
{"topic": "orderbook.200.BTCUSDT", "ts": 1742561187319, "type": "delta", "data": {"s": "BTCUSDT", "b": [["83793.7", "0.53322"], ["83785.7", "0.000333"], ["83774.8", "0.082571"], ["83766.7", "0.059399"], ["83762.2", "0.036657"], ["83755.2", "0.013"], ["83747.5", "0.099531"], ["83716.7", "0.044446"], ["83716.2", "0.050005"], ["83716.1", "0.221"], ["83716", "0"], ["83715.6", "0"], ["83714.5", "0.016723"]], "a": [["83793.8", "0.207485"], ["83800.8", "0"], ["83805.3", "0.014325"], ["83805.7", "0"], ["83808.4", "0"], ["83817.6", "0"], ["83824.5", "0.071056"], ["83827.1", "0"], ["83827.2", "0.023865"], ["83827.6", "0.000454"], ["83827.7", "0.026424"], ["83827.8", "0.013"], ["83827.9", "0.01262"], ["83828.3", "0.045966"], ["83828.4", "0.04"], ["83838.9", "0"], ["83874", "0.119299"], ["83874.5", "0.099399"]], "u": 49508, "seq": 67553368363}, "cts": 1742561187316, "record_time": 1742561187.339087, "EXCHANGE": "BYBIT"}
{"topic": "orderbook.200.BTCUSDT", "ts": 1742561187520, "type": "delta", "data": {"s": "BTCUSDT", "b": [["83789.4", "0.010195"], ["83782.4", "0"], ["83760.7", "0.0016"], ["83755.5", "0.013"], ["83755.4", "0.016641"], ["83755.2", "0"], ["83755.1", "0"], ["83753.7", "0"], ["83729.5", "0"], ["83729.4", "0.354691"], ["83714.2", "0.628004"], ["83714.1", "0.045852"], ["83713.9", "3.28972"]], "a": [["83794.2", "0.014327"], ["83827.1", "0.013"], ["83827.2", "0.036486"], ["83827.8", "0"], ["83827.9", "0"], ["83844.7", "0.895514"], ["83874.5", "0"]], "u": 49509, "seq": 67553368524}, "cts": 1742561187516, "record_time": 1742561187.601413, "EXCHANGE": "BYBIT"}
{"topic": "orderbook.200.BTCUSDT", "ts": 1742561187719, "type": "delta", "data": {"s": "BTCUSDT", "b": [["83793.7", "0.48331"], ["83790", "0.005738"], ["83746", "7.615897"], ["83713.9", "0"]], "a": [["83793.8", "0.213485"], ["83797.5", "0.006204"], ["83801", "0.014836"], ["83802.9", "0"], ["83827.6", "0.040454"], ["83827.7", "0.066424"], ["83828.3", "0.005966"], ["83828.4", "0"], ["83874.5", "0.099399"]], "u": 49510, "seq": 67553368641}, "cts": 1742561187717, "record_time": 1742561187.736283, "EXCHANGE": "BYBIT"}
{"topic": "orderbook.200.BTCUSDT", "ts": 1742561187919, "type": "delta", "data": {"s": "BTCUSDT", "b": [["83793.7", "0.306619"], ["83788.7", "0.045451"], ["83788.6", "0"], ["83787.6", "0"], ["83787.1", "0.002294"], ["83776", "0.059507"], ["83774.8", "0.052"], ["83774.7", "0.029299"], ["83771.2", "0"], ["83769", "0.059992"], ["83766.7", "0"], ["83762", "0.110797"], ["83755.5", "0"], ["83755.3", "0.012881"], ["83747.5", "0.099538"], ["83746", "0"], ["83734.7", "7.615897"], ["83716.8", "0.163745"], ["83716.7", "0"], ["83714.7", "0.016723"], ["83714.5", "0"], ["83713.9", "3.28972"], ["83713.8", "0.001333"]], "a": [["83793.8", "0.410874"], ["83803.5", "0.067951"], ["83805.3", "0"], ["83811", "0.061444"], ["83814.5", "0"], ["83815.2", "0.099601"], ["83817.1", "0.003576"], ["83818", "0.058489"], ["83825", "0.110136"], ["83827.1", "0"], ["83827.3", "0.012621"], ["83827.6", "0.000454"], ["83827.8", "0.04"], ["83838.9", "0.119299"], ["83842", "2.605769"], ["83844.8", "0.016828"], ["83847.9", "0.173799"], ["83873.7", "0"], ["83873.8", "0"], ["83874", "0"], ["83874.5", "0"]], "u": 49511, "seq": 67553368839}, "cts": 1742561187915, "record_time": 1742561187.936767, "EXCHANGE": "BYBIT"}
{"topic": "orderbook.200.BTCUSDT", "ts": 1742561188120, "type": "delta", "data": {"s": "BTCUSDT", "b": [["83793.7", "0.306702"], ["83776", "0.056147"], ["83769", "0.060482"], ["83766.2", "0"], ["83762.2", "0.065314"], ["83762", "0.108642"], ["83761.9", "0.023319"], ["83755.4", "0.00376"], ["83755.2", "0.012881"], ["83746.4", "0.021655"], ["83746", "7.615897"], ["83734.7", "0"], ["83713.8", "0"]], "a": [["83810.3", "0.148643"], ["83811", "0.063359"], ["83818", "0.059811"], ["83825", "0.122612"], ["83844.7", "0"], ["83845.9", "0.023679"], ["83850.1", "0"], ["83873.7", "0.028169"]], "u": 49512, "seq": 67553368971}, "cts": 1742561188118, "record_time": 1742561188.14069, "EXCHANGE": "BYBIT"}
{"topic": "orderbook.200.BTCUSDT", "ts": 1742561188319, "type": "delta", "data": {"s": "BTCUSDT", "b": [["83793.7", "0.298102"], ["83776", "0"], ["83769", "0.000451"], ["83762", "0"], ["83726.7", "0"], ["83725.9", "0.000149"], ["83716.2", "0.049977"], ["83713.8", "0.001333"], ["83713.5", "0.003147"]], "a": [["83793.8", "0.416874"], ["83811", "0.001466"], ["83818", "0"], ["83825", "0"], ["83827.2", "0.076486"], ["83827.3", "0.052621"], ["83827.7", "0.026424"], ["83827.8", "0"], ["83873.8", "0.000423"], ["83874", "0.119299"], ["83874.5", "0.099399"]], "u": 49513, "seq": 67553369056}, "cts": 1742561188314, "record_time": 1742561188.33635, "EXCHANGE": "BYBIT"}
{"topic": "orderbook.200.BTCUSDT", "ts": 1742561188520, "type": "delta", "data": {"s": "BTCUSDT", "b": [["83793.7", "0.469102"], ["83793.4", "0.013262"], ["83776.4", "0.074001"], ["83769.4", "0.092622"], ["83762.4", "0.123118"], ["83762.2", "0.036657"], ["83755.6", "0.013"], ["83755.5", "0.012881"], ["83755.3", "0"], ["83755.2", "0"], ["83747.5", "0.099542"], ["83713.5", "0"]], "a": [["83793.8", "0.316874"], ["83806", "0.022816"], ["83811.3", "0.111999"], ["83811.4", "0.061631"], ["83811.8", "0"], ["83818.4", "0.058824"], ["83825.4", "0.146648"], ["83826.6", "0.016216"], ["83826.7", "0.032621"], ["83827.2", "0.063865"], ["83827.3", "0.04"], ["83874.5", "0"]], "u": 49514, "seq": 67553369180}, "cts": 1742561188517, "record_time": 1742561188.540974, "EXCHANGE": "BYBIT"}
{"topic": "orderbook.200.BTCUSDT", "ts": 1742561188719, "type": "delta", "data": {"s": "BTCUSDT", "b": [["83793.7", "0.273563"], ["83789.7", "0"], ["83789.2", "0.001333"], ["83788.7", "0"], ["83788.4", "0"], ["83786.8", "0.022843"], ["83784.2", "0.071646"], ["83781.3", "0"], ["83780.2", "0"], ["83780.1", "0"], ["83778.6", "0"], ["83778.5", "0"], ["83776.8", "0"], ["83776.5", "0"], ["83776.4", "0.011974"], ["83775.3", "0.004062"], ["83775.1", "0.119299"], ["83774.8", "0"], ["83774.7", "0"], ["83773.7", "0"], ["83773.4", "0"], ["83771.4", "0.018275"], ["83769.9", "0"], ["83769.4", "0"], ["83769", "0.000333"], ["83767.8", "0"], ["83765.1", "0"], ["83762.4", "0.0002"], ["83755.6", "0"], ["83755.4", "0.016641"], ["83754.9", "0.059909"], ["83754.7", "0.001431"], ["83747.5", "0"], ["83746.2", "0"], ["83746.1", "0.059399"], ["83746", "0"], ["83735.5", "0.000333"], ["83733.4", "0.099537"], ["83716.8", "0.119299"], ["83716.2", "0.005871"], ["83716.1", "0.171"], ["83715.3", "0.05"], ["83714.2", "0.001466"], ["83714.1", "0"], ["83713.5", "0.003147"], ["83713.4", "0.044954"], ["83712.8", "0.000083"], ["83712.7", "0.043955"], ["83711.8", "0.125308"], ["83711.7", "0.119299"], ["83711.5", "0.021783"], ["83711.3", "0.009"], ["83710.6", "0.044856"], ["83710.4", "0.000333"], ["83710.3", "0.00043"], ["83709.7", "0.001333"], ["83709.6", "0.001466"], ["83709.2", "0.00009"], ["83709", "0.048"], ["83708.8", "0.000508"]], "a": [["83793.8", "0.623676"], ["83794.1", "0.035802"], ["83794.2", "0.02774"], ["83794.3", "0.035802"], ["83794.4", "0.014327"], ["83794.5", "0.035802"], ["83794.8", "0.035802"], ["83796.5", "0.005836"], ["83799.8", "0.014819"], ["83799.9", "0.018245"], ["83800.6", "0.003875"], ["83801", "0.00051"], ["83801.7", "0.023626"], ["83803.1", "0"], ["83803.2", "0"], ["83803.4", "0.042435"], ["83803.5", "0.053625"], ["83806.7", "0.000333"], ["83808.1", "0"], ["83810.3", "0.023337"], ["83810.7", "0"], ["83811.3", "0.081694"], ["83811.4", "0"], ["83815.2", "0.081027"], ["83816.7", "0.04"], ["83817.9", "0"], ["83818.4", "0"], ["83819.4", "0.03632"], ["83825.4", "0.023865"], ["83826.6", "0.003216"], ["83826.7", "0.02"], ["83827", "0.012621"], ["83827.1", "0.012621"], ["83827.2", "0.023865"], ["83827.3", "0"], ["83827.5", "0.04"], ["83827.6", "0.040454"], ["83832.4", "0.089099"], ["83847.9", "0.271807"], ["83872.7", "0"], ["83873", "0"], ["83873.3", "0"], ["83873.4", "0"], ["83873.7", "0"], ["83873.8", "0"], ["83874", "0"]], "u": 49515, "seq": 67553369574}, "cts": 1742561188717, "record_time": 1742561188.737772, "EXCHANGE": "BYBIT"}
{"topic": "orderbook.200.BTCUSDT", "ts": 1742561188920, "type": "delta", "data": {"s": "BTCUSDT", "b": [["83793.7", "0.276785"], ["83788.8", "0.045464"], ["83788.7", "0.071643"], ["83786.8", "0"], ["83784.2", "0"], ["83781.1", "0.083209"], ["83778.9", "0.156167"], ["83776.9", "0.121896"], ["83772.5", "0.001333"], ["83769.9", "0.170382"], ["83762.9", "0.279731"], ["83755.5", "0"], ["83755.3", "0.012881"], ["83754.8", "0"], ["83745.2", "0.179011"], ["83715.6", "0.016126"], ["83714.7", "0.016714"], ["83713.4", "0.000508"], ["83712.7", "0"], ["83712.3", "0.043905"], ["83710.6", "0"], ["83710.4", "0.045189"], ["83709.7", "0"], ["83709.6", "0"], ["83709.2", "0"], ["83709", "0"], ["83708.8", "0"]], "a": [["83793.8", "0.619261"], ["83794", "0.050972"], ["83794.2", "0"], ["83799.3", "0.014326"], ["83799.6", "0.068509"], ["83799.7", "0.179011"], ["83799.8", "0"], ["83799.9", "0"], ["83807.8", "0.018245"], ["83809.7", "0.089561"], ["83809.8", "0.112135"], ["83816.8", "0.170492"], ["83823.8", "0.290042"], ["83826.6", "0.016216"], ["83826.7", "0.032621"], ["83827", "0"], ["83827.1", "0"], ["83827.2", "0.063865"], ["83827.3", "0.04"], ["83827.5", "0"], ["83827.6", "0.000454"], ["83870.9", "0"], ["83872.3", "0"]], "u": 49516, "seq": 67553369790}, "cts": 1742561188917, "record_time": 1742561188.937209, "EXCHANGE": "BYBIT"}
{"topic": "orderbook.200.BTCUSDT", "ts": 1742561189120, "type": "delta", "data": {"s": "BTCUSDT", "b": [["83793.7", "0.487579"], ["83781.1", "0.056281"], ["83776.9", "0"], ["83774.6", "0.030562"], ["83769.9", "0"], ["83769.2", "0.03581"], ["83766.7", "0.059399"], ["83762.9", "0"], ["83755.4", "0.00376"], ["83755.3", "0"], ["83755.1", "0.012881"], ["83755", "0.012881"], ["83747.5", "0.099537"], ["83746", "7.628808"], ["83745.2", "0"], ["83733.4", "0"], ["83715.6", "0.025828"], ["83715.3", "0"], ["83714.7", "0"], ["83714.2", "0.628004"], ["83712.3", "0.043972"], ["83711.1", "0.016714"], ["83710.4", "0.046077"]], "a": [["83793.8", "0.316635"], ["83794", "0"], ["83794.3", "0"], ["83794.5", "0"], ["83794.8", "0"], ["83799.2", "0.015151"], ["83799.6", "0"], ["83799.7", "0"], ["83800.6", "0"], ["83801.7", "0.014326"], ["83805.3", "0.000078"], ["83809.8", "0.003213"], ["83811.3", "0.111098"], ["83815", "0.00999"], ["83816.8", "0"], ["83823.8", "0.01194"], ["83826.5", "0.012622"], ["83826.6", "0.015838"], ["83826.7", "0.02"], ["83870.9", "0.001466"], ["83872.3", "0.04"], ["83872.7", "0.003244"], ["83873", "0.001333"], ["83873.3", "0.626538"]], "u": 49517, "seq": 67553370040}, "cts": 1742561189116, "record_time": 1742561189.177348, "EXCHANGE": "BYBIT"}
{"topic": "orderbook.200.BTCUSDT", "ts": 1742561189319, "type": "delta", "data": {"s": "BTCUSDT", "b": [["83793.7", "0.493868"], ["83767.5", "0.023868"], ["83762.5", "0.12388"], ["83755.2", "0.013"], ["83755", "0.05846"], ["83712.4", "0.044106"], ["83712.3", "0"], ["83711.8", "0"], ["83711.1", "0"], ["83710.8", "0.01581"], ["83710.4", "0"], ["83710.3", "0"]], "a": [["83793.8", "0.300669"], ["83794.1", "0"], ["83796.5", "0"], ["83803.4", "0.072455"], ["83811.1", "0.003875"], ["83811.5", "0.179011"], ["83826.5", "0"], ["83826.6", "0.003216"], ["83827", "0.013"], ["83827.1", "0.012622"], ["83827.2", "0.023865"], ["83827.3", "0"], ["83827.5", "0.04"], ["83827.6", "0.040454"], ["83840.4", "0.838006"], ["83842", "0"], ["83847.6", "2.609591"]], "u": 49518, "seq": 67553370433}, "cts": 1742561189312, "record_time": 1742561189.340234, "EXCHANGE": "BYBIT"}
{"topic": "orderbook.200.BTCUSDT", "ts": 1742561189519, "type": "delta", "data": {"s": "BTCUSDT", "b": [["83793.7", "0.542976"], ["83786.1", "0.04"], ["83786", "0.04"], ["83785.1", "0.018275"], ["83784.3", "0.052"], ["83782.8", "0.044"], ["83782.5", "0.04851"], ["83781.1", "0.080712"], ["83780.7", "0.044"], ["83779.7", "0.044"], ["83779.4", "0.048"], ["83771.4", "0"], ["83764.7", "0.089099"], ["83762.5", "0"], ["83755.2", "0"], ["83755.1", "0"], ["83754.9", "0.07279"], ["83754.8", "0.012881"], ["83754.7", "0.013371"], ["83751.7", "7.628808"], ["83750.4", "0.099537"], ["83747.5", "0"], ["83746", "0"], ["83716.8", "0.163779"], ["83716.2", "0.049995"], ["83715.6", "0.013581"], ["83714.1", "0.045852"], ["83713.4", "0"], ["83712.8", "0"], ["83712.4", "0"], ["83711.7", "0"], ["83711.5", "0"], ["83711.3", "0"], ["83710.8", "0"]], "a": [["83793.8", "0.179825"], ["83794.4", "0"], ["83795.5", "0.014327"], ["83799.2", "0"], ["83799.3", "0"], ["83801.7", "0"], ["83803.4", "0.042435"], ["83804.4", "0.014325"], ["83805.3", "0"], ["83807.8", "0"], ["83807.9", "0.164777"], ["83808", "0.178981"], ["83809.7", "0"], ["83811.3", "0.081694"], ["83811.5", "0"], ["83817.1", "0"], ["83819.4", "0.00051"], ["83827", "0"], ["83827.1", "0"], ["83827.5", "0"], ["83827.6", "0.000454"], ["83828.3", "0.018966"], ["83828.4", "0.012622"], ["83828.8", "0.04"], ["83828.9", "0.04"], ["83829.4", "0.250845"], ["83835.1", "0.063484"], ["83838.9", "0"], ["83840.4", "0.064315"], ["83847.6", "0.003822"], ["83856.1", "2.605769"], ["83873.4", "0.017903"], ["83873.7", "0.028169"], ["83873.8", "0.000423"], ["83874", "0.119299"]], "u": 49519, "seq": 67553370924}, "cts": 1742561189511, "record_time": 1742561189.536679, "EXCHANGE": "BYBIT"}
{"topic": "orderbook.200.BTCUSDT", "ts": 1742561189720, "type": "delta", "data": {"s": "BTCUSDT", "b": [["83793.7", "0.767132"], ["83788.8", "0.063781"], ["83788.7", "0"], ["83787.3", "0.009234"], ["83786.4", "0.04"], ["83785.5", "0.004062"], ["83785", "0.072979"], ["83782.7", "0.052"], ["83781.2", "0.190375"], ["83781.1", "0.310978"], ["83775.3", "0"], ["83773.5", "0"], ["83713.8", "0"], ["83713.5", "0"]], "a": [["83793.8", "0.121748"], ["83795.3", "0.014327"], ["83795.5", "0"], ["83806.8", "0.014325"], ["83807.8", "0.000298"], ["83809.7", "0.000153"], ["83811.5", "0.179011"], ["83817.8", "0.018245"], ["83819.6", "0"], ["83825.4", "0"], ["83828.3", "0"], ["83828.4", "0"], ["83828.5", "0.012622"], ["83828.7", "0.012622"], ["83828.8", "0"], ["83828.9", "0"], ["83829", "0.04"], ["83829.2", "0.04"], ["83835.1", "0"], ["83837.5", "0"], ["83837.6", "0.303133"], ["83837.9", "0.063484"], ["83838.9", "0.119299"], ["83847.6", "2.609591"], ["83856.1", "0"], ["83873.8", "0"], ["83874", "0"]], "u": 49520, "seq": 67553371137}, "cts": 1742561189682, "record_time": 1742561189.738156, "EXCHANGE": "BYBIT"}
{"topic": "orderbook.200.BTCUSDT", "ts": 1742561189920, "type": "delta", "data": {"s": "BTCUSDT", "b": [["83793.7", "0.656649"], ["83769", "0.000451"], ["83717.2", "0.044996"], ["83716.8", "0.119299"], ["83716.2", "0.05027"], ["83716.1", "0.221"], ["83715.6", "0"], ["83715.4", "0.015963"], ["83714.2", "0.678004"], ["83714.1", "0"]], "a": [["83793.8", "0.136667"], ["83811.3", "0.111128"], ["83819.6", "0.035809"], ["83844.8", "2.622597"], ["83847.6", "0.003822"], ["83873.7", "0"]], "u": 49521, "seq": 67553371194}, "cts": 1742561189906, "record_time": 1742561189.937085, "EXCHANGE": "BYBIT"}
{"topic": "orderbook.200.BTCUSDT", "ts": 1742561190119, "type": "delta", "data": {"s": "BTCUSDT", "b": [["83793.7", "0.662613"], ["83743.7", "0.04"], ["83717.2", "0"], ["83716.8", "0.163863"], ["83716.2", "0.050265"], ["83715.4", "0"], ["83715", "0.015874"]], "a": [["83793.8", "0.042988"], ["83811.3", "0.081694"]], "u": 49522, "seq": 67553371254}, "cts": 1742561190116, "record_time": 1742561190.223226, "EXCHANGE": "BYBIT"}
{"topic": "orderbook.200.BTCUSDT", "ts": 1742561190320, "type": "delta", "data": {"s": "BTCUSDT", "b": [["83781.2", "0.097081"], ["83781.1", "0"], ["83779.5", "0.055912"], ["83772.5", "0.059771"], ["83766.7", "0"], ["83765.5", "0.121335"], ["83764.8", "0.076976"], ["83762.2", "0"], ["83751.7", "0"], ["83737.5", "7.769398"], ["83714.2", "0.628004"], ["83714.1", "0.045852"], ["83713.8", "0.001333"]], "a": [["83793.8", "0.121682"], ["83795.3", "0"], ["83796.4", "0.000358"], ["83802", "0.014326"], ["83805", "0.000153"], ["83806.8", "0"], ["83809.7", "0"], ["83811.3", "0.111898"], ["83814.5", "0.059173"], ["83821.5", "0.057457"], ["83828.5", "0.131041"], ["83873.3", "0"], ["83873.4", "0"]], "u": 49523, "seq": 67553371361}, "cts": 1742561190304, "record_time": 1742561190.337428, "EXCHANGE": "BYBIT"}
{"topic": "orderbook.200.BTCUSDT", "ts": 1742561190519, "type": "delta", "data": {"s": "BTCUSDT", "b": [["83793.7", "0.663413"], ["83779.5", "0"], ["83772.5", "0.001333"], ["83766.7", "0.059399"], ["83765.5", "0"], ["83755.5", "0.013"], ["83755.4", "0.016641"], ["83754.9", "0.059909"], ["83754.8", "0"], ["83740.4", "7.706587"], ["83737.5", "0.062811"]], "a": [["83793.8", "0.061719"], ["83802", "0"], ["83805", "0"], ["83814.5", "0"], ["83821.5", "0"], ["83826.3", "0.013"], ["83826.4", "0.012622"], ["83826.8", "0.04"], ["83826.9", "0.041333"], ["83828.5", "0"], ["83828.7", "0"], ["83829", "0"], ["83829.2", "0"], ["83873.3", "0.626538"], ["83873.4", "0.017903"], ["83873.7", "0.028169"], ["83873.8", "0.000423"], ["83874", "0.119299"]], "u": 49524, "seq": 67553371460}, "cts": 1742561190514, "record_time": 1742561190.537218, "EXCHANGE": "BYBIT"}
{"topic": "orderbook.200.BTCUSDT", "ts": 1742561190719, "type": "delta", "data": {"s": "BTCUSDT", "b": [["83804.4", "0.488338"], ["83803.5", "0.553656"], ["83803.4", "0.171"], ["83802.1", "0.171"], ["83800", "0.00006"], ["83798.3", "0.000333"], ["83796.3", "0.033617"], ["83795.1", "0.005"], ["83794.1", "0.000333"], ["83794", "0.0002"], ["83793.8", "0.100562"], ["83793.7", "0.279237"], ["83793.2", "0.00009"], ["83792.7", "0.089099"], ["83790", "0"], ["83789.5", "0.024"], ["83788.8", "0.045464"], ["83788.3", "0.059148"], ["83787.9", "0.006466"], ["83787.1", "0.00051"], ["83786.7", "0"], ["83785.6", "0.221"], ["83785.3", "0.005"], ["83785", "0.001333"], ["83783.3", "0.172466"], ["83767.5", "0"], ["83762.4", "0"], ["83755.5", "0"], ["83755.4", "0.00376"], ["83754.8", "0.013"], ["83754.7", "0.026253"], ["83746", "7.719118"], ["83740.4", "0"], ["83724.5", "0.797465"], ["83724.3", "0.001784"], ["83717.6", "0"], ["83717.1", "0"], ["83716.8", "0"], ["83716.6", "0"], ["83716.2", "0"], ["83716.1", "0"], ["83715", "0"], ["83714.6", "0"], ["83714.2", "0"], ["83714.1", "0"], ["83713.9", "0"], ["83713.8", "0"]], "a": [["83793.8", "0"], ["83796.4", "0"], ["83797.5", "0"], ["83798.3", "0"], ["83801", "0"], ["83801.4", "0"], ["83801.8", "0"], ["83802.2", "0"], ["83802.5", "0"], ["83803.4", "0"], ["83803.5", "0"], ["83804.4", "0"], ["83804.5", "0.045797"], ["83804.8", "0.01"], ["83805.1", "0.035796"], ["83805.3", "0.035796"], ["83806.6", "0"], ["83807.8", "0"], ["83807.9", "0"], ["83808", "0"], ["83809.4", "0.057993"], ["83810.2", "0.058187"], ["83812.8", "0.000153"], ["83819.6", "0"], ["83823.3", "0.058286"], ["83824.8", "0.120793"], ["83826.3", "0"], ["83826.4", "0"], ["83826.8", "0"], ["83826.9", "0.001333"], ["83829.8", "0.0006"], ["83830.3", "0.057913"], ["83832.4", "0"], ["83835.6", "0.012624"], ["83835.7", "0.017238"], ["83836.1", "0.04"], ["83836.2", "0.04"], ["83837.9", "0"], ["83838.9", "0"], ["83843.6", "0.063484"], ["83844.7", "0.925576"], ["83844.8", "0.016828"], ["83847.5", "0"], ["83854.3", "0.119299"], ["83867.4", "2.605769"], ["83872.6", "0.003564"], ["83873.3", "0"], ["83874.5", "0.099399"], ["83874.7", "0.000512"], ["83875.5", "0.001466"], ["83876.5", "0.0045"], ["83876.9", "0.003244"], ["83877.2", "0.001333"], ["83877.3", "0.011884"], ["83877.8", "0.043961"], ["83878", "0.000333"], ["83879.4", "0.000512"]], "u": 49525, "seq": 67553372107}, "cts": 1742561190717, "record_time": 1742561190.746124, "EXCHANGE": "BYBIT"}
{"topic": "orderbook.200.BTCUSDT", "ts": 1742561190919, "type": "delta", "data": {"s": "BTCUSDT", "b": [["83804.4", "0.507421"], ["83803.6", "0.093846"], ["83803.5", "0"], ["83796.4", "0.012548"], ["83796.3", "0.036825"], ["83796", "0.005"], ["83795.1", "0"], ["83789.3", "0.080856"], ["83789.2", "0.120632"], ["83788.8", "0"], ["83788.3", "0"], ["83787.9", "0.011466"], ["83785.6", "0.28262"], ["83785.3", "0"], ["83773.8", "0.1131"], ["83753.2", "0.099586"], ["83750.4", "0"], ["83746", "0"], ["83734.7", "7.719118"]], "a": [["83804.5", "0.049018"], ["83805", "0.035796"], ["83805.5", "0.095195"], ["83809.4", "0"], ["83809.5", "0"], ["83810.1", "0"], ["83810.2", "0.018187"], ["83810.3", "0"], ["83811.3", "0.081694"], ["83811.7", "0"], ["83811.9", "0"], ["83812.8", "0.053625"], ["83813", "0.023514"], ["83813.5", "0"], ["83813.6", "0"], ["83814.8", "0.014834"], ["83815.2", "0"], ["83815.3", "0"], ["83816.7", "0"], ["83816.9", "0"], ["83817.7", "0.024768"], ["83817.8", "0.032568"], ["83819", "0.044"], ["83819.4", "0.04459"], ["83822.4", "0.043216"], ["83823.3", "0"], ["83826.5", "0.035806"], ["83829.9", "0"], ["83830.3", "0"], ["83832.1", "0"], ["83832.5", "0"], ["83835.6", "0"], ["83835.7", "0.004614"], ["83836.1", "0"], ["83836.2", "0"], ["83836.3", "0.15561"], ["83837.2", "0.012624"], ["83837.3", "0.012624"], ["83837.7", "0.04"], ["83837.8", "0.04051"], ["83843.6", "0.063476"], ["83843.9", "0.471496"], ["83844.7", "0"], ["83847.8", "0.119299"], ["83867.4", "0"], ["83875.9", "2.605436"], ["83877.8", "0"], ["83878.2", "0.171"], ["83880", "0.05"], ["83880.1", "0.001466"], ["83881.1", "0.003244"], ["83881.2", "0.00018"], ["83881.4", "0.120632"], ["83881.9", "0.05"], ["83882.1", "0.000333"], ["83882.2", "0.00009"], ["83882.7", "0.000146"], ["83883", "0.050358"]], "u": 49526, "seq": 67553372360}, "cts": 1742561190917, "record_time": 1742561190.936628, "EXCHANGE": "BYBIT"}
{"topic": "orderbook.200.BTCUSDT", "ts": 1742561191120, "type": "delta", "data": {"s": "BTCUSDT", "b": [["83804.4", "0.507021"], ["83803.6", "0.0973"], ["83792.9", "0.109285"], ["83788.8", "0.121898"], ["83782.4", "0.178709"], ["83781.8", "0.187208"], ["83775.4", "0.307635"], ["83774.8", "0.295688"], ["83763", "7.719118"], ["83761.9", "0"], ["83756", "0.099601"], ["83753.2", "0"], ["83734.7", "0"], ["83718.8", "0"], ["83718.7", "0"], ["83718.3", "0"], ["83718", "0"], ["83717.7", "0"]], "a": [["83812.9", "0.005"], ["83816.1", "0.000153"], ["83817.3", "0.114552"], ["83817.4", "0.121868"], ["83817.7", "0"], ["83819", "0.084"], ["83820.2", "0.126741"], ["83820.7", "0.04"], ["83821.2", "0.04"], ["83821.7", "0.112739"], ["83823.8", "0.05194"], ["83824", "0.04051"], ["83826.5", "0"], ["83826.6", "0.039022"], ["83827.9", "0.173657"], ["83828.7", "0.165053"], ["83829.4", "0.001466"], ["83834.9", "0.288037"], ["83835.7", "0.286248"], ["83840.8", "0.063476"], ["83843.6", "0"], ["83845.9", "0"], ["83858.9", "2.605436"], ["83875.9", "0"], ["83881.2", "0"], ["83881.4", "0"], ["83881.9", "0"], ["83882.1", "0"], ["83882.2", "0"], ["83882.7", "0"], ["83883", "0"]], "u": 49527, "seq": 67553372491}, "cts": 1742561191114, "record_time": 1742561191.137192, "EXCHANGE": "BYBIT"}
{"topic": "orderbook.200.BTCUSDT", "ts": 1742561191320, "type": "delta", "data": {"s": "BTCUSDT", "b": [["83804.4", "0.57865"], ["83797.6", "0.001333"], ["83797.1", "0.001466"], ["83796.4", "0.013056"], ["83796.3", "0.104754"], ["83792.9", "0"], ["83792.7", "0"], ["83788.8", "0"], ["83782.4", "0"], ["83781.8", "0"], ["83775.4", "0"], ["83774.8", "0"], ["83766.3", "0.024277"], ["83764.8", "2.376662"], ["83756", "0.099621"], ["83718.8", "0.001466"], ["83718.7", "0.000392"], ["83718.3", "0.059399"], ["83718", "0.001841"]], "a": [["83804.5", "0.050569"], ["83804.9", "0.014325"], ["83811.3", "0.033794"], ["83811.5", "0"], ["83814.7", "0.0002"], ["83817.2", "0.073992"], ["83817.3", "0.08"], ["83817.4", "0"], ["83817.5", "0.014323"], ["83817.8", "0.018245"], ["83819.3", "0.044413"], ["83819.4", "0.00051"], ["83821.7", "0"], ["83822.9", "0.04"], ["83823.9", "0.114903"], ["83824.5", "0"], ["83827.9", "0"], ["83828.7", "0"], ["83831.6", "0"], ["83834.9", "0"], ["83835.7", "0.004614"], ["83837.9", "0.063474"], ["83840.8", "0"], ["83850", "0.178988"], ["83850.2", "0.024491"], ["83854.2", "0.182138"], ["83856.1", "2.605606"], ["83858.9", "0"]], "u": 49528, "seq": 67553372711}, "cts": 1742561191315, "record_time": 1742561191.337976, "EXCHANGE": "BYBIT"}
{"topic": "orderbook.200.BTCUSDT", "ts": 1742561191519, "type": "delta", "data": {"s": "BTCUSDT", "b": [["83805.5", "0.6432"], ["83805.2", "0.104745"], ["83805", "0.300081"], ["83804.9", "0.02991"], ["83804.4", "0.02991"], ["83803.6", "0"], ["83803.4", "0"], ["83802.2", "0.078048"], ["83798.7", "0.004062"], ["83798.4", "0.089099"], ["83797.3", "0.003208"], ["83797.1", "0.011466"], ["83796.4", "0.063804"], ["83796.3", "0.101546"], ["83796", "0"], ["83794.5", "0.119299"], ["83794.1", "0.009333"], ["83793.8", "0.274318"], ["83793.7", "0.278837"], ["83793.3", "0.04"], ["83793", "0.559664"], ["83791.7", "0.04051"], ["83789.4", "0.000995"], ["83788.4", "0.044"], ["83788.2", "0.048"], ["83788", "0.016293"], ["83787.9", "0.006466"], ["83786.4", "0"], ["83785.5", "0"], ["83782.5", "0.00051"], ["83781.6", "0.493091"], ["83776.7", "0.059399"], ["83775.9", "0"], ["83773.8", "0"], ["83766.3", "0"], ["83766.1", "0"], ["83765.5", "0.013743"], ["83765.4", "0.0016"], ["83764.8", "2.371963"], ["83763", "0"], ["83760.7", "0"], ["83758.9", "0.099621"], ["83756", "0"], ["83754.8", "3.7458"], ["83754.5", "7.719118"], ["83754.2", "0.023865"], ["83753.3", "0.023865"], ["83753", "0"], ["83748.8", "0.023865"], ["83748.4", "0.023865"], ["83745.5", "0"], ["83727.8", "0.05"], ["83723.8", "0"], ["83723", "0.045015"], ["83722.6", "0"], ["83722.5", "0"], ["83722.2", "0"], ["83721.9", "0"], ["83720.4", "0"], ["83718.8", "0"], ["83718.7", "0"], ["83718.3", "0"], ["83718", "0"]], "a": [["83804.5", "0"], ["83804.8", "0"], ["83804.9", "0"], ["83805", "0"], ["83805.1", "0"], ["83805.3", "0"], ["83805.5", "0"], ["83805.6", "0.013721"], ["83810.8", "0"], ["83811.1", "0"], ["83811.3", "0"], ["83812.7", "0.059399"], ["83812.9", "0.01"], ["83813", "0"], ["83814", "0.008216"], ["83814.8", "0.00051"], ["83815", "0.00069"], ["83816.1", "0"], ["83817.1", "0.000298"], ["83817.2", "0.050998"], ["83817.5", "0"], ["83817.8", "0"], ["83819", "0.04"], ["83819.3", "0.000333"], ["83819.6", "0.044345"], ["83819.9", "0.023602"], ["83822.4", "0.003216"], ["83822.8", "0.003875"], ["83823.8", "0.01194"], ["83823.9", "0.083402"], ["83824", "0.00051"], ["83824.8", "0.001466"], ["83825.7", "0"], ["83826.6", "0.003216"], ["83827.2", "0"], ["83827.4", "0.014322"], ["83828.9", "0.000999"], ["83829.4", "0.087318"], ["83830.5", "0.009088"], ["83836.3", "0"], ["83837.2", "0"], ["83837.3", "0"], ["83837.7", "0"], ["83837.8", "0.00051"], ["83837.9", "0"], ["83839", "0"], ["83841.2", "0.013"], ["83841.3", "0.012626"], ["83841.7", "0.04"], ["83841.8", "0.04"], ["83847.8", "0"], ["83847.9", "0.173799"], ["83850", "0"], ["83850.2", "0"], ["83852.1", "0.064806"], ["83854.2", "0.00315"], ["83855.8", "0"], ["83856.1", "0"], ["83857.2", "0.562963"], ["83864.3", "0.092343"], ["83880", "0"], ["83881.2", "0.00018"], ["83881.4", "0.120632"], ["83882.1", "0.000333"], ["83882.2", "0.00009"], ["83882.7", "0.000146"], ["83883", "0.000358"], ["83883.3", "0.059399"], ["83883.7", "0.62645"], ["83883.9", "0.032055"], ["83884", "0.000512"], ["83884.8", "0.001466"], ["83885.2", "3.703209"], ["83885.3", "0.092343"], ["83885.6", "0.001333"], ["83886", "0.000672"]], "u": 49529, "seq": 67553373735}, "cts": 1742561191516, "record_time": 1742561191.537141, "EXCHANGE": "BYBIT"}
{"success": true, "ret_msg": "subscribe", "conn_id": "2410e6c8-83c2-48f8-b7e6-ade66696c08d", "op": "subscribe", "record_time": 1742561258.893709, "EXCHANGE": "BYBIT"}
