{"topic": "orderbook.200.BTCUSDT", "ts": 1742584908520, "type": "delta", "data": {"s": "BTCUSDT", "b": [["84081.7", "0"], ["84080.9", "0.074367"], ["84079.4", "0.000333"], ["84078.4", "0"], ["84077.1", "0.007115"], ["84072.8", "0.0714"], ["84072.4", "0"], ["84066.2", "0.118801"], ["84062.1", "0.109484"], ["84060.2", "0.024323"], ["84056.4", "0"], ["84055.7", "0.286783"], ["84055.5", "0.001466"], ["84055.1", "0.186866"], ["84054.7", "0.036216"], ["84053.3", "0.1784"], ["84048.7", "0.307645"], ["84048.2", "0"], ["84048.1", "0.28492"], ["84046.1", "0"], ["84046", "0"], ["84044.9", "0.039633"], ["84044.8", "0.039634"], ["84044.4", "0"], ["84044.3", "0"], ["84044", "0"], ["84043.2", "0.012881"], ["84043.1", "0.012881"], ["84042.6", "0"], ["84042.5", "0"], ["84041.4", "0.049546"], ["84041.3", "0.049546"], ["84028.1", "0"], ["84022.9", "0.005238"], ["84006.9", "0"]], "a": [["84081", "0.767658"], ["84081.6", "0.091386"], ["84081.8", "0.324665"], ["84082.1", "0"], ["84082.3", "0.050089"], ["84083.3", "0.019226"], ["84084.8", "0.004969"], ["84085.9", "0.005468"], ["84086.3", "0"], ["84087.1", "0.148216"], ["84087.7", "0.091266"], ["84089.4", "0.1"], ["84089.6", "0.00009"], ["84090.2", "0.228487"], ["84090.4", "0.04"], ["84090.7", "0.144243"], ["84091.9", "0.029816"], ["84094.5", "0.03"], ["84094.6", "0"], ["84095", "0.110259"], ["84095.8", "0.012849"], ["84096.2", "0.000333"], ["84101.2", "0.18508"], ["84102", "0.180897"], ["84107.7", "0"], ["84108.2", "0.308094"], ["84109", "0.29975"], ["84115", "0.035688"], ["84118.2", "0.051467"], ["84118.3", "0.092979"], ["84122.9", "1.426146"], ["84123.7", "0"], ["84130.7", "0"], ["84132.2", "0.362457"], ["84137.1", "0"], ["84146.6", "0"], ["84146.9", "0"], ["84147.2", "0"], ["84148", "0"], ["84148.2", "0"], ["84148.4", "0"], ["84148.6", "0"], ["84148.9", "0"]], "u": 168013, "seq": 67577199646}, "cts": 1742584908515, "record_time": 1742584908.623295, "EXCHANGE": "BYBIT"}
{"topic": "orderbook.200.BTCUSDT", "ts": 1742584908719, "type": "delta", "data": {"s": "BTCUSDT", "b": [["84080.9", "0"], ["84080", "0"], ["84079.4", "0"], ["84078.6", "0"], ["84078.3", "0.071396"], ["84077.1", "0"], ["84076.1", "0"], ["84075.3", "0"], ["84075.2", "0.000333"], ["84075", "0"], ["84074.5", "0.007115"], ["84072.8", "0"], ["84071.6", "0.028463"], ["84070.8", "0"], ["84067.4", "0.114103"], ["84067.2", "0.074323"], ["84066.2", "0"], ["84062.1", "0"], ["84060.2", "0"], ["84058.8", "0.467047"], ["84057.5", "0.035136"], ["84055.7", "0.111667"], ["84055.1", "0"], ["84054.7", "0.000528"], ["84048.7", "0"], ["84048.1", "0.005682"], ["84044.9", "0"], ["84044.8", "0"], ["84044.6", "0.039631"], ["84044.5", "0.039631"], ["84043.8", "0.003531"], ["84043.2", "0"], ["84043.1", "0"], ["84042.9", "0.01288"], ["84042.8", "0.01288"], ["84041.4", "0"], ["84041.3", "0"], ["84041.1", "0.049543"], ["84041", "0.049543"], ["84037.4", "0.125213"], ["84028.3", "0.356984"], ["84028.2", "0.001333"], ["84020", "0.00006"], ["84006.9", "0.003"], ["84006.1", "0.005238"], ["84005.2", "0.00595"], ["84004.7", "0.001466"], ["84003.9", "0.000884"], ["84003.7", "0.000333"], ["84003", "0.401333"], ["84002.7", "15.13568"]], "a": [["84078.4", "0.904793"], ["84080", "0.00024"], ["84080.1", "0.002497"], ["84080.9", "0.11418"], ["84081", "0.225265"], ["84081.6", "0"], ["84081.8", "0.153665"], ["84082.2", "0.004969"], ["84082.9", "0.001333"], ["84083.2", "0.010691"], ["84083.6", "0.000333"], ["84084.1", "0.071391"], ["84084.8", "0"], ["84085.1", "0.019879"], ["84086.8", "0.06"], ["84087.7", "0.071388"], ["84087.8", "0.040333"], ["84089.3", "0.029817"], ["84089.4", "0.04"], ["84089.9", "0"], ["84090.1", "0.129228"], ["84090.2", "0.208398"], ["84090.7", "0.03"], ["84091.2", "0.001"], ["84091.9", "0"], ["84092.1", "0"], ["84092.9", "0"], ["84095", "0"], ["84100", "0.00024"], ["84101.2", "0"], ["84102", "0"], ["84108.2", "0"], ["84109", "0"], ["84120.3", "1.48561"], ["84122.9", "0"], ["84130.7", "0.356984"], ["84132.2", "0.005472"], ["84145.9", "0"]], "u": 168014, "seq": 67577200036}, "cts": 1742584908715, "record_time": 1742584908.823397, "EXCHANGE": "BYBIT"}
{"topic": "orderbook.200.BTCUSDT", "ts": 1742584908919, "type": "delta", "data": {"s": "BTCUSDT", "b": [["84074.8", "0"], ["84072.1", "0.071401"], ["84071", "0.152816"], ["84070.8", "0.00528"], ["84069.9", "0.244703"], ["84067.4", "0.042698"], ["84054.3", "0.039263"], ["84044.6", "0"], ["84044.5", "0"], ["84044.2", "0.04"], ["84044.1", "0.039632"], ["84042.9", "0"], ["84042.8", "0"], ["84042.5", "0.013"], ["84042.4", "0.012881"], ["84041.1", "0"], ["84041", "0"], ["84040.7", "0.05"], ["84040.6", "0.049544"], ["84028.4", "0.356985"], ["84028.3", "0"], ["84018.7", "0.183643"], ["84005.4", "15.470293"], ["84003", "0"], ["84002.7", "0"]], "a": [["84078.4", "0.908958"], ["84081", "0.221089"], ["84081.8", "0.150089"], ["84085.8", "0.383518"], ["84085.9", "0.105788"], ["84086.8", "0.26911"], ["84087.1", "0.001861"], ["84087.6", "0.105985"], ["84092.8", "0"], ["84095.1", "0.012849"], ["84095.8", "0"], ["84107.5", "0"], ["84113.1", "0.8237"], ["84113.2", "2.621241"], ["84118.2", "0.051468"], ["84119.8", "0.04"], ["84119.9", "0.04"], ["84121.5", "0"], ["84121.6", "0"], ["84123", "0"], ["84123.1", "0.04"], ["84130.7", "0.356983"], ["84145.6", "0"]], "u": 168015, "seq": 67577200252}, "cts": 1742584908912, "record_time": 1742584909.021913, "EXCHANGE": "BYBIT"}
{"topic": "orderbook.200.BTCUSDT", "ts": 1742584909119, "type": "delta", "data": {"s": "BTCUSDT", "b": [["84078.3", "0"], ["84077.8", "0"], ["84077.5", "0"], ["84077.4", "0"], ["84075.2", "0"], ["84074.5", "0"], ["84072.1", "0"], ["84071.6", "0"], ["84071", "0.000333"], ["84070.9", "0"], ["84070.8", "0"], ["84069.9", "0.1733"], ["84069.3", "0.171"], ["84068.9", "0.028464"], ["84067.7", "0.00625"], ["84067.6", "0"], ["84067.4", "0.071405"], ["84067.2", "0"], ["84066.7", "0.000933"], ["84065.4", "0"], ["84064.9", "0.095733"], ["84064.7", "0.044165"], ["84063.4", "0.071408"], ["84062.9", "0.055886"], ["84062.7", "0"], ["84060.9", "0"], ["84059.2", "0.024011"], ["84058.8", "0.167484"], ["84057.6", "0.001333"], ["84057.5", "0.05"], ["84056.8", "0.025911"], ["84055.7", "0"], ["84055.2", "0.051333"], ["84055.1", "0.009225"], ["84054.3", "0.003575"], ["84053.3", "0"], ["84052.5", "0"], ["84048.3", "0.023787"], ["84046.8", "0.039686"], ["84046.4", "0"], ["84045.6", "0"], ["84044.2", "0"], ["84044.1", "0"], ["84042.7", "0.211"], ["84042.6", "0.03963"], ["84042.5", "0"], ["84042.4", "0"], ["84042.1", "0.526534"], ["84042", "0.00009"], ["84041", "0.013"], ["84040.9", "0.01288"], ["84040.7", "0"], ["84040.6", "0"], ["84039.7", "0.017207"], ["84039.2", "0.05"], ["84039.1", "0.049541"], ["84036.9", "0.587997"], ["84031.8", "0"], ["84028.4", "0.284153"], ["84027.8", "0.001466"], ["84025", "3.601827"], ["84022.7", "0.023787"], ["84022", "0.357007"], ["84018.7", "0.005238"], ["84005.4", "0"], ["84003", "0.401333"], ["84001.9", "0.094675"], ["84001.7", "0.118539"], ["84001.4", "0.003"], ["84001.2", "0.00595"], ["84000.8", "0.05"], ["84000.5", "0.064"], ["84000.2", "0.059399"], ["84000.1", "0.013095"]], "a": [["84074.5", "0.689132"], ["84074.6", "0.114589"], ["84075.7", "0.171"], ["84077.5", "0.003576"], ["84077.9", "0.05437"], ["84078.3", "0.01714"], ["84078.4", "0.221089"], ["84079.1", "0.00497"], ["84079.4", "0.000333"], ["84080.1", "0"], ["84080.9", "0.135005"], ["84081", "0.101422"], ["84081.7", "0.005466"], ["84081.8", "0.050089"], ["84082", "0.091272"], ["84082.2", "0"], ["84082.4", "0.000528"], ["84083.2", "0.001466"], ["84084.2", "0.029314"], ["84085.1", "0"], ["84085.8", "0.272241"], ["84085.9", "0.005468"], ["84086.2", "0.029818"], ["84086.3", "0.06"], ["84086.8", "0.20911"], ["84087.1", "0.025648"], ["84087.2", "0.102273"], ["84087.7", "0"], ["84087.9", "0.001466"], ["84088", "0.201"], ["84088.9", "0.04"], ["84089", "0.022782"], ["84089.3", "0.188636"], ["84090", "0.118539"], ["84090.1", "0.03275"], ["84090.7", "0.036268"], ["84092.6", "0.053326"], ["84093.7", "0.04"], ["84094.1", "0.072248"], ["84094.4", "0.005475"], ["84095.1", "0"], ["84098.3", "0.536105"], ["84103", "0.023787"], ["84108.1", "0.025617"], ["84108.4", "0"], ["84112", "0.283871"], ["84112.5", "0.051468"], ["84113.2", "0"], ["84113.9", "0"], ["84116.4", "1.426146"], ["84118.2", "0"], ["84118.7", "2.621241"], ["84119", "0.04"], ["84119.1", "0.04"], ["84119.8", "0"], ["84119.9", "0"], ["84120.3", "0.059464"], ["84123.9", "0"], ["84124.5", "0"], ["84125.8", "0.357012"], ["84126.7", "0"], ["84130.7", "0"], ["84142.8", "0"], ["84143.4", "0"], ["84143.7", "0"], ["84143.8", "0"], ["84144.2", "0"], ["84144.8", "0"], ["84144.9", "0"], ["84145", "0"], ["84145.3", "0"], ["84145.4", "0"]], "u": 168016, "seq": 67577201299}, "cts": 1742584909114, "record_time": 1742584909.223315, "EXCHANGE": "BYBIT"}
{"topic": "orderbook.200.BTCUSDT", "ts": 1742584909320, "type": "delta", "data": {"s": "BTCUSDT", "b": [["84074.4", "0.001453"], ["84070.6", "0.007116"], ["84070", "0.000297"], ["84066.9", "0.00528"], ["84057.5", "0"], ["84057.2", "0.11"], ["84053.1", "0.005458"], ["84052.6", "0.112065"], ["84052.5", "0.111667"], ["84050.8", "0.178413"], ["84044", "0.178413"], ["84042.7", "0.171"], ["84042.6", "0"], ["84042.4", "0.03963"], ["84042.3", "0.03963"], ["84041", "0"], ["84040.9", "0"], ["84040.7", "0.01288"], ["84040.6", "0.01288"], ["84039.8", "0.178413"], ["84039.2", "0"], ["84039.1", "0"], ["84038.9", "0.049541"], ["84038.8", "0.049541"], ["84033.6", "0.00009"], ["84025.8", "0.357004"], ["84022", "0"], ["84001.9", "0"], ["84001.7", "0"], ["84001.4", "0"], ["84001.2", "0"], ["84000.8", "0"], ["84000.5", "0"], ["84000.2", "0"], ["84000.1", "0"]], "a": [["84074.5", "0.693308"], ["84077.5", "0"], ["84077.8", "0.003576"], ["84078.3", "0"], ["84081.8", "0.228502"], ["84082", "0.120199"], ["84082.9", "0.061333"], ["84083.7", "0.090089"], ["84086", "0.228502"], ["84086.3", "0"], ["84087", "0.071388"], ["84087.2", "0.142273"], ["84089.3", "0.102252"], ["84090.2", "0.03"], ["84090.6", "0.04"], ["84092.5", "0.1033"], ["84093.7", "0"], ["84100.9", "0.08012"], ["84106.5", "0"], ["84108.1", "0.001333"], ["84113.1", "0"], ["84119.2", "0.024284"], ["84125.8", "0"], ["84127", "0.357"], ["84132.1", "0.032982"], ["84142.8", "0.051333"]], "u": 168017, "seq": 67577201430}, "cts": 1742584909317, "record_time": 1742584909.423401, "EXCHANGE": "BYBIT"}
{"topic": "orderbook.200.BTCUSDT", "ts": 1742584909520, "type": "delta", "data": {"s": "BTCUSDT", "b": [["84069.6", "0.0039"], ["84052.6", "0.185081"], ["84048.3", "0.2022"], ["84047.4", "0.00588"], ["84040.9", "0.0016"], ["84040.1", "0.096383"], ["84039", "0.05"], ["84038.8", "0"], ["84033.6", "0.58782"], ["84022.9", "0.094445"], ["84003.9", "0"], ["84003.7", "0"], ["84003", "0"]], "a": [["84080.9", "0.18672"], ["84081.8", "0.299895"], ["84083.9", "0.04"], ["84085.6", "0.059399"], ["84085.7", "0.04"], ["84087", "0"], ["84088.5", "0"], ["84088.6", "0"], ["84088.7", "0.04"], ["84090.5", "0.04"], ["84092", "0.000333"], ["84093.5", "0"], ["84095.2", "0"], ["84095.3", "0"], ["84107.6", "2.621555"], ["84118.7", "0"], ["84125.8", "0.357003"], ["84127", "0"], ["84143.4", "0.001466"], ["84143.7", "0.024382"]], "u": 168018, "seq": 67577201491}, "cts": 1742584909507, "record_time": 1742584909.622438, "EXCHANGE": "BYBIT"}
{"topic": "orderbook.200.BTCUSDT", "ts": 1742584909720, "type": "delta", "data": {"s": "BTCUSDT", "b": [["84074.4", "0"], ["84074", "0.072865"], ["84070", "0"], ["84069.9", "0.005"], ["84065.6", "0.055"], ["84053.1", "0"], ["84051.5", "0.062089"], ["84048.4", "0.100247"], ["84046.8", "0"], ["84042.4", "0"], ["84042.3", "0"], ["84041.5", "0.040333"], ["84041.4", "0.03963"], ["84040.7", "0"], ["84040.6", "0"], ["84039.8", "0.191413"], ["84039.7", "0.030087"], ["84039", "0"], ["84038.9", "0"], ["84038", "0.073232"], ["84037.9", "0.049542"], ["84025.8", "0"], ["84023", "0.357005"], ["84003.9", "0.000884"], ["84003.7", "0.000333"], ["84003", "0.401333"], ["84001.9", "0.094675"], ["84001.7", "0.118539"], ["84001.4", "0.003"]], "a": [["84074.1", "0.690909"], ["84074.4", "0.170186"], ["84074.5", "0.271"], ["84074.6", "0.091488"], ["84075.7", "0"], ["84077.8", "0"], ["84077.9", "0.05934"], ["84078.6", "0.001333"], ["84079.1", "0"], ["84082.5", "0.06"], ["84082.9", "0.001333"], ["84086.8", "0"], ["84090.1", "0.005475"], ["84090.4", "0"], ["84092.5", "0.06221"], ["84103", "0"], ["84116", "1.426146"], ["84116.4", "0"], ["84143.8", "3.572392"], ["84144.2", "0.0018"]], "u": 168019, "seq": 67577201680}, "cts": 1742584909708, "record_time": 1742584909.841412, "EXCHANGE": "BYBIT"}
{"topic": "orderbook.200.BTCUSDT", "ts": 1742584909919, "type": "delta", "data": {"s": "BTCUSDT", "b": [["84069.9", "0"], ["84067.7", "0"], ["84065.6", "0.06"], ["84064.8", "0.000617"], ["84063.5", "0"], ["84062.2", "0.0003"], ["84061.3", "0.05"], ["84058.8", "0.126558"], ["84056.8", "0"], ["84056.6", "0.05"], ["84055.2", "0.077646"], ["84043.8", "0"], ["84023", "0"], ["84022", "0.357006"], ["84007.6", "0"], ["84001.2", "0.00595"], ["84000.5", "0.064"], ["84000.2", "0.059399"]], "a": [["84105.3", "1.082645"], ["84123", "0.000118"], ["84144.2", "0"]], "u": 168020, "seq": 67577201737}, "cts": 1742584909907, "record_time": 1742584910.022556, "EXCHANGE": "BYBIT"}
{"topic": "orderbook.200.BTCUSDT", "ts": 1742584910120, "type": "delta", "data": {"s": "BTCUSDT", "b": [["84074", "0.073665"], ["84067.3", "0.000153"], ["84065.6", "0.1733"], ["84058.8", "0.156143"], ["84044", "0"], ["84041.5", "0.000333"], ["84041.4", "0"], ["84041.3", "0.03963"], ["84041.2", "0.03963"], ["84039.8", "0.178413"], ["84039.7", "0.017207"], ["84039.6", "0.01288"], ["84039.5", "0.01288"], ["84038", "0.023232"], ["84037.9", "0.05"], ["84037.8", "0.049542"], ["84022", "0"], ["84017.3", "0.357011"], ["84001.4", "0"], ["84001.2", "0"], ["84000.5", "0"], ["84000.2", "0"]], "a": [["84074.1", "0.690248"], ["84080.9", "0.276407"], ["84082.5", "0.26911"], ["84110.1", "0"], ["84115.7", "0.04"], ["84115.8", "0.04"], ["84119", "0"], ["84119.1", "0"], ["84139.5", "1.026867"]], "u": 168021, "seq": 67577201795}, "cts": 1742584910102, "record_time": 1742584910.221966, "EXCHANGE": "BYBIT"}
{"topic": "orderbook.200.BTCUSDT", "ts": 1742584910320, "type": "delta", "data": {"s": "BTCUSDT", "b": [["84074", "0.00139"], ["84069.6", "0"], ["84069.3", "0"], ["84067.4", "0"], ["84067.3", "0"], ["84066.2", "0.006069"], ["84063.4", "0"], ["84046.7", "0"], ["84045.3", "0"], ["84040.1", "0"], ["84039.8", "0"], ["84038", "0"], ["84037.9", "0"], ["84037.7", "0.049542"], ["84035.5", "0.183727"], ["84033.5", "0"], ["84031.3", "0.183727"], ["84022.9", "0.005238"], ["84001.4", "0.003"], ["84001.2", "0.00595"], ["84000.5", "0.064"], ["84000.2", "0.059399"], ["84000.1", "0.013095"], ["84000", "15.966994"], ["83999.5", "0.000333"], ["83999.2", "0.221992"], ["83998.8", "0.001333"], ["83997.7", "0.005238"]], "a": [["84074.1", "0.694345"], ["84077.9", "0.056843"], ["84092.6", "0.03"], ["84092.8", "0.118943"], ["84097.4", "0"], ["84107.6", "0.000297"], ["84121.1", "0"], ["84138", "2.621712"], ["84144.2", "0.0018"]], "u": 168022, "seq": 67577201864}, "cts": 1742584910317, "record_time": 1742584910.422457, "EXCHANGE": "BYBIT"}
{"topic": "orderbook.200.BTCUSDT", "ts": 1742584910519, "type": "delta", "data": {"s": "BTCUSDT", "b": [["84074", "0"], ["84073.3", "0"], ["84073.2", "0"], ["84071", "0"], ["84070.6", "0"], ["84070.2", "0"], ["84070.1", "0"], ["84069.4", "0.027009"], ["84068.9", "0"], ["84066.9", "0"], ["84066.2", "0"], ["84065.7", "0.000297"], ["84065.6", "0.005"], ["84064.9", "0.005327"], ["84064.8", "0"], ["84064.7", "0.001466"], ["84064.1", "0"], ["84063.9", "0.071936"], ["84062.8", "0"], ["84062.4", "0.216464"], ["84062.3", "0"], ["84061.3", "0"], ["84061", "0.055"], ["84060.6", "0"], ["84060.5", "0.071411"], ["84060.2", "0.05"], ["84059.5", "0.000617"], ["84059.2", "0"], ["84059", "0"], ["84058.8", "0.066558"], ["84057.3", "0"], ["84057.2", "0"], ["84056.7", "0.038314"], ["84056.6", "0"], ["84055.9", "0"], ["84055.2", "0"], ["84055.1", "0"], ["84054.3", "0"], ["84053.8", "0.05"], ["84052.9", "0.073703"], ["84052.2", "0.026187"], ["84051.5", "0.0264"], ["84050.8", "0.005458"], ["84050.5", "0.178402"], ["84048.8", "0.051333"], ["84048.4", "0.064568"], ["84045.8", "0.178424"], ["84045.2", "0.003575"], ["84042.8", "0.209287"], ["84041.3", "0.051947"], ["84041.2", "0"], ["84040.2", "0.118949"], ["84039.7", "0.005313"], ["84039.6", "0"], ["84039.5", "0"], ["84039.4", "0.004686"], ["84038.6", "0"], ["84038.2", "0.04"], ["84038.1", "0.039629"], ["84037.8", "0"], ["84037.7", "0"], ["84037.5", "0.351353"], ["84036.5", "0.013"], ["84036.4", "0.01288"], ["84035.5", "0.005313"], ["84034.7", "0.05"], ["84034.6", "0.049541"], ["84033.6", "0.00009"], ["84031.6", "0.098367"], ["84031.3", "0.005313"], ["84028.5", "0.144398"], ["84025", "3.511796"], ["84024.5", "0"], ["84022.1", "0.090083"], ["84012.9", "0.000149"], ["84009", "0"], ["84000.2", "0.230399"], ["83997.4", "0.000563"], ["83997", "0.059483"], ["83996.7", "0.000119"], ["83996.2", "0.0001"], ["83995.4", "0.013466"], ["83995.3", "0.001833"], ["83994.8", "1.137106"], ["83994.7", "0.003"], ["83994.6", "0.001859"]], "a": [["84069.5", "0.874613"], ["84073.1", "0.104855"], ["84073.3", "0.225265"], ["84073.4", "0.102497"], ["84074", "0.02211"], ["84074.1", "0.078964"], ["84074.4", "0.001333"], ["84074.5", "0"], ["84074.6", "0.020089"], ["84075.2", "0.000333"], ["84075.7", "0.02411"], ["84076.9", "0.01988"], ["84077.5", "0.005464"], ["84077.8", "0.000528"], ["84077.9", "0.111873"], ["84078.3", "0.088685"], ["84078.6", "0.002799"], ["84079.7", "0.071395"], ["84080.9", "0"], ["84081.1", "0.029819"], ["84081.2", "0.00009"], ["84081.8", "0.121482"], ["84082", "0"], ["84082.5", "0"], ["84083.1", "0.04"], ["84083.7", "0.07"], ["84084.1", "0"], ["84084.2", "0.009225"], ["84085.8", "0"], ["84085.9", "0.191208"], ["84086", "0.208413"], ["84086.2", "0"], ["84087.6", "0"], ["84091.2", "0"], ["84092.8", "0"], ["84096.8", "0.246972"], ["84100.8", "0.086098"], ["84105.3", "0.296268"], ["84110.9", "0.14409"], ["84111.4", "1.426146"], ["84116", "0"], ["84118.2", "0.357031"], ["84120.1", "0"], ["84121.8", "0"], ["84125.8", "0"], ["84126.6", "0.000145"], ["84138", "0.00053"], ["84138.2", "0.000333"], ["84139.5", "0"], ["84143.4", "0"], ["84143.7", "0"], ["84143.8", "0"], ["84144.2", "0"]], "u": 168023, "seq": 67577202519}, "cts": 1742584910517, "record_time": 1742584910.623304, "EXCHANGE": "BYBIT"}
{"topic": "orderbook.200.BTCUSDT", "ts": 1742584910719, "type": "delta", "data": {"s": "BTCUSDT", "b": [["84069.4", "0.198009"], ["84065.7", "0"], ["84065.6", "0.007116"], ["84064", "0.021581"], ["84062.7", "0.028467"], ["84062.4", "0.111764"], ["84061.9", "0.00528"], ["84061", "0.173355"], ["84060.4", "0"], ["84058.8", "0.00009"], ["84058.5", "0.042703"], ["84057.5", "0.07894"], ["84057.4", "0.048"], ["84057.2", "0.064"], ["84055.7", "0.092"], ["84054.1", "0.064333"], ["84053.9", "0.064"], ["84053.8", "0"], ["84053.4", "0.051333"], ["84052.9", "0.023703"], ["84052.8", "0.05"], ["84052.4", "0.06"], ["84052.2", "0.06"], ["84051.9", "0.009467"], ["84051.5", "0.05234"], ["84050.8", "0"], ["84050.6", "0.06"], ["84050.5", "0.238402"], ["84048.3", "0.023787"], ["84048", "0.027009"], ["84047.1", "0.018516"], ["84038.2", "0"], ["84038", "0.039629"], ["84036.5", "0"], ["84036.3", "0.01288"], ["84035.3", "0.051189"], ["84035.2", "0.04954"], ["84034.7", "0"], ["84034.6", "0"], ["84031.6", "0.000526"], ["84023.8", "0.013717"], ["84022.2", "0.357014"], ["84017.3", "0"], ["84010.3", "0.183662"], ["84001.9", "0.005476"], ["83998.8", "0"], ["83997.7", "0"], ["83997.4", "0"], ["83997", "0"], ["83996.7", "0"], ["83996.2", "0"], ["83995.4", "0"], ["83995.3", "0"], ["83994.8", "0"], ["83994.7", "0"], ["83994.6", "0"]], "a": [["84069.5", "0.707789"], ["84073.3", "0.221089"], ["84074", "0.00497"], ["84075.7", "0"], ["84076.7", "0.003576"], ["84077", "0.10032"], ["84077.4", "0.160925"], ["84077.5", "0.076861"], ["84077.9", "0.320983"], ["84078.3", "0"], ["84078.7", "0.105985"], ["84079.7", "0"], ["84080.9", "0.215008"], ["84081.8", "0.299906"], ["84084.1", "0.04"], ["84087.8", "0.000333"], ["84089.4", "0"], ["84090", "0.230212"], ["84106", "0.004595"], ["84107.6", "2.621479"], ["84109.3", "0"], ["84116.3", "0.024631"], ["84118.2", "0"], ["84123", "0.357132"], ["84132.4", "1.026953"], ["84142.4", "0"], ["84142.6", "0"], ["84142.8", "0"]], "u": 168024, "seq": 67577202768}, "cts": 1742584910715, "record_time": 1742584910.822283, "EXCHANGE": "BYBIT"}
{"topic": "orderbook.200.BTCUSDT", "ts": 1742584910919, "type": "delta", "data": {"s": "BTCUSDT", "b": [["84069.4", "0.269412"], ["84055.7", "0.156"], ["84053.7", "0.322003"], ["84053.6", "0.178458"], ["84052.9", "0"], ["84052.6", "0"], ["84052.1", "0.178461"], ["84051", "0.178463"], ["84048.9", "0.040102"], ["84048.4", "0"], ["84048.3", "0.202211"], ["84045.8", "0"], ["84044", "0.178424"], ["84039.8", "0.178424"], ["84038.9", "0.04"], ["84038.8", "0.039628"], ["84038.1", "0"], ["84038", "0"], ["84035.4", "0.05"], ["84035.3", "0.050729"], ["84035.2", "0"], ["84031.6", "0.044843"], ["84027.6", "0.023211"], ["84025.8", "0.357"], ["84025", "3.601879"], ["84022.9", "0.09445"], ["84022.2", "0"], ["84022.1", "0"], ["84012.3", "0.178545"], ["84010.3", "0.005238"], ["84002.7", "16.10169"], ["84001.9", "0.094688"], ["84000.2", "0"], ["84000.1", "0"], ["84000", "0"], ["83999.5", "0"], ["83999.2", "0"]], "a": [["84069.5", "0.482985"], ["84071.1", "0.071402"], ["84072.2", "0.058733"], ["84073.1", "0"], ["84073.3", "0.020089"], ["84073.4", "0.1"], ["84074.1", "0.048964"], ["84077.5", "0.005464"], ["84077.9", "0.342816"], ["84079.4", "0.071728"], ["84105.3", "1.061532"], ["84107.6", "0.000297"], ["84110.9", "0.553923"], ["84113.2", "2.621256"], ["84114.6", "0.04"], ["84114.7", "0.04"], ["84115.7", "0"], ["84115.8", "0"], ["84118.6", "0.002498"], ["84123", "0.000118"], ["84127", "0.357"], ["84140", "0"], ["84140.3", "0"], ["84140.6", "0"], ["84141.7", "0"]], "u": 168025, "seq": 67577202951}, "cts": 1742584910914, "record_time": 1742584911.02251, "EXCHANGE": "BYBIT"}
{"topic": "orderbook.200.BTCUSDT", "ts": 1742584911120, "type": "delta", "data": {"s": "BTCUSDT", "b": [["84048.9", "0.088616"], ["84044", "0"], ["84035.5", "0.183737"], ["84035.4", "0.04954"], ["84000.2", "0.059399"]], "a": [["84105.3", "0"], ["84110.9", "1.28907"], ["84114.4", "0.100064"], ["84114.5", "0.04"], ["84114.6", "0"], ["84114.7", "0"], ["84125.8", "0.357005"], ["84127", "0"], ["84140", "0.00042"], ["84140.3", "0.118539"]], "u": 168026, "seq": 67577203039}, "cts": 1742584911117, "record_time": 1742584911.2236, "EXCHANGE": "BYBIT"}
{"topic": "orderbook.200.BTCUSDT", "ts": 1742584911319, "type": "delta", "data": {"s": "BTCUSDT", "b": [["84069.4", "0.440412"], ["84064.4", "0.006286"], ["84062.6", "0.000153"], ["84051.5", "0.052301"], ["84042.8", "0.327826"], ["84038.9", "0.039628"], ["84037.2", "0.012879"], ["84037.1", "0.012879"], ["84036.4", "0"], ["84036.3", "0"], ["84028.5", "0.240411"], ["84002.7", "16.101113"], ["84000.5", "0"], ["84000.2", "0"]], "a": [["84069.5", "0.338063"], ["84071.1", "0"], ["84072.1", "0.062074"], ["84072.2", "0.071401"], ["84073.3", "0"], ["84074.1", "0.028875"], ["84074.6", "0"], ["84076.7", "0"], ["84077.9", "0.322727"], ["84078.4", "0.201"], ["84079.4", "0.000333"], ["84081", "0.081333"], ["84081.8", "0.279817"], ["84082.3", "0.03"], ["84084.4", "0.071391"], ["84106.5", "0.310207"], ["84114.4", "0.060064"], ["84114.6", "0.04"]], "u": 168027, "seq": 67577203135}, "cts": 1742584911317, "record_time": 1742584911.422095, "EXCHANGE": "BYBIT"}
{"topic": "orderbook.200.BTCUSDT", "ts": 1742584911520, "type": "delta", "data": {"s": "BTCUSDT", "b": [["84062.9", "0.060186"], ["84062.6", "0"], ["84058.1", "0.023345"], ["84055.4", "0.190454"], ["84054.8", "0.051333"], ["84053.6", "0"], ["84048.8", "0"], ["84044", "0.178424"], ["84042.8", "0.416925"], ["84042", "0.051423"], ["84041.3", "0.117798"], ["84041.1", "0.118949"], ["84040.9", "0"], ["84038.9", "0"], ["84038.7", "0.063415"], ["84037.2", "0"], ["84037", "0.03825"], ["84035.5", "0.005313"], ["84035.4", "0"], ["84035.2", "0.04954"], ["84034.2", "0.1725"], ["84027.6", "0"], ["84025.9", "0.025713"], ["84021.2", "0.023489"], ["84000.5", "0.064"]], "a": [["84069.5", "0.150735"], ["84072.1", "0"], ["84072.2", "0"], ["84077.9", "0.292727"], ["84078.4", "0.171"], ["84081", "0.051333"], ["84081.8", "0.178424"], ["84082.3", "0"], ["84084.4", "0"], ["84088", "0.319949"], ["84090", "0.111673"], ["84090.7", "0.03"], ["84113.2", "0"], ["84114.5", "0"], ["84114.7", "0.04"], ["84116.3", "0"], ["84121.7", "0.023155"], ["84124.2", "2.621256"], ["84125.8", "0"], ["84127", "0.357002"], ["84140.6", "0.005473"], ["84141.7", "0.060832"], ["84142.4", "0.000333"], ["84142.6", "0.00053"]], "u": 168028, "seq": 67577203321}, "cts": 1742584911517, "record_time": 1742584911.62262, "EXCHANGE": "BYBIT"}
{"topic": "orderbook.200.BTCUSDT", "ts": 1742584911720, "type": "delta", "data": {"s": "BTCUSDT", "b": [["84069.4", "0.440565"], ["84058.6", "0.018516"], ["84057.5", "0.157209"], ["84053", "0.023665"], ["84047.1", "0"], ["84035.5", "0.055313"], ["84035.4", "0.04954"], ["84035.3", "0.001189"], ["84035.2", "0"], ["84032.6", "0.023247"], ["84028.6", "0.356981"], ["84027.8", "0.091549"], ["84025.8", "0"], ["84025", "3.511796"], ["84019.2", "0.017792"], ["84005.4", "16.101113"], ["84002.7", "0"], ["84001.4", "0"], ["84001.2", "0"], ["84000.5", "0"]], "a": [["84069.5", "0.183438"], ["84073.3", "0.040653"], ["84080.9", "0.144376"], ["84081", "0"], ["84086.9", "0.122722"], ["84089.4", "0.071386"], ["84090.2", "0.208424"], ["84110.9", "0.571934"], ["84114.6", "0"], ["84114.7", "0"], ["84114.8", "0.04062"], ["84114.9", "0.04"], ["84119.2", "0"], ["84127", "0"], ["84132.2", "0.362456"], ["84132.4", "0"], ["84142.8", "0.051333"], ["84143", "0.028136"]], "u": 168029, "seq": 67577203451}, "cts": 1742584911714, "record_time": 1742584911.829817, "EXCHANGE": "BYBIT"}
{"topic": "orderbook.200.BTCUSDT", "ts": 1742584911920, "type": "delta", "data": {"s": "BTCUSDT", "b": [["84069.4", "0.289323"], ["84044.1", "0.345671"], ["84042.8", "0.207638"], ["84035.6", "0.049539"], ["84035.5", "0.054852"], ["84035.4", "0"], ["84028.5", "0.144398"], ["84008.2", "16.101449"], ["84005.4", "0"], ["84001.7", "0"]], "a": [["84069.5", "0.354438"], ["84084.8", "0.07139"], ["84086.9", "0.051333"], ["84093.2", "0.006061"], ["84118.7", "2.621209"], ["84124.2", "0"], ["84132.1", "0.389963"], ["84132.2", "0.005472"], ["84142.8", "0"], ["84143", "0"]], "u": 168030, "seq": 67577203527}, "cts": 1742584911917, "record_time": 1742584912.02243, "EXCHANGE": "BYBIT"}
{"topic": "orderbook.200.BTCUSDT", "ts": 1742584912120, "type": "delta", "data": {"s": "BTCUSDT", "b": [["84069.4", "0.460323"], ["84039.1", "0.04"], ["84039", "0.039628"], ["84038.8", "0"], ["84038.7", "0.023787"], ["84031.7", "0.356979"], ["84028.7", "0.286231"], ["84028.6", "0"], ["84028.5", "0"], ["84001.9", "0"]], "a": [["84069.5", "0.183438"], ["84076.5", "0.071397"], ["84114.2", "0.04"], ["84114.3", "0.04"], ["84114.8", "0.00062"], ["84114.9", "0"], ["84118.3", "0.90553"], ["84132", "0.356979"], ["84132.1", "0.032982"], ["84141.7", "0"], ["84142.4", "0"], ["84142.6", "0"]], "u": 168031, "seq": 67577203555}, "cts": 1742584912111, "record_time": 1742584912.223302, "EXCHANGE": "BYBIT"}
{"topic": "orderbook.200.BTCUSDT", "ts": 1742584912320, "type": "delta", "data": {"s": "BTCUSDT", "b": [["84050.8", "0.178424"], ["84037.4", "0.138213"], ["84037.3", "0.013212"], ["84037.1", "0"], ["84037", "0.025371"], ["84035.4", "0.096388"], ["84031.8", "0.151569"], ["84031.6", "0.000526"], ["84028.7", "0"], ["84003", "0"]], "a": [["84131.9", "0.356979"], ["84132", "0"]], "u": 168032, "seq": 67577203579}, "cts": 1742584912312, "record_time": 1742584912.423539, "EXCHANGE": "BYBIT"}
{"topic": "orderbook.200.BTCUSDT", "ts": 1742584912519, "type": "delta", "data": {"s": "BTCUSDT", "b": [["84061.8", "0.001486"], ["84048.3", "0.023787"], ["84031.7", "0"], ["84028.5", "0.536116"], ["84008.2", "16.100985"]], "a": [["84131.8", "0.356982"], ["84131.9", "0"]], "u": 168033, "seq": 67577203614}, "cts": 1742584912516, "record_time": 1742584912.62216, "EXCHANGE": "BYBIT"}
{"topic": "orderbook.200.BTCUSDT", "ts": 1742584912720, "type": "delta", "data": {"s": "BTCUSDT", "b": [["84061.8", "0.001333"], ["84048.9", "0"], ["84031.8", "0.044475"], ["84028.6", "0.35698"], ["84028.5", "0.179136"]], "a": [["84076.5", "0"], ["84109.7", "0.03569"], ["84115", "0"], ["84131.7", "0.357579"], ["84131.8", "0"], ["84134.2", "0.353321"], ["84141.7", "0.060832"]], "u": 168034, "seq": 67577203646}, "cts": 1742584912717, "record_time": 1742584912.822112, "EXCHANGE": "BYBIT"}
{"topic": "orderbook.200.BTCUSDT", "ts": 1742584912920, "type": "delta", "data": {"s": "BTCUSDT", "b": [["84062.6", "0.000153"], ["84057.9", "0.112371"], ["84048.4", "0.019147"], ["84048.1", "0.175708"], ["84039", "0.350557"], ["84031.6", "0.357505"], ["84028.6", "0"], ["84003.9", "0"], ["84003.7", "0"]], "a": [["84073.3", "0"], ["84083.1", "0.149588"], ["84092.9", "0.167753"], ["84102", "0.287327"], ["84114.2", "0"], ["84114.3", "0"], ["84114.6", "0.04"], ["84114.7", "0.04"], ["84131.7", "0.0006"], ["84132.2", "0.362451"], ["84136.2", "1.026907"], ["84140.6", "0"], ["84141.7", "0"]], "u": 168035, "seq": 67577203672}, "cts": 1742584912905, "record_time": 1742584913.022083, "EXCHANGE": "BYBIT"}
{"topic": "orderbook.200.BTCUSDT", "ts": 1742584913120, "type": "delta", "data": {"s": "BTCUSDT", "b": [["84041.3", "0.23805"], ["84039.1", "0"], ["84039", "0.310929"], ["84038.7", "0.063787"], ["84038.6", "0.039629"], ["84037.4", "0.125213"], ["84037.3", "0.000333"], ["84037", "0.038371"], ["84036.9", "0.600876"], ["84035.6", "0"], ["84035.5", "0.055313"], ["84035.4", "0.145928"], ["84031.9", "0.356975"], ["84031.6", "0.000526"], ["84030.6", "0.090083"], ["84027.8", "0.001466"], ["84004.7", "0"]], "a": [["84078.2", "0.071396"], ["84084.8", "0"], ["84087.2", "0.213661"], ["84093.2", "0"], ["84100.8", "0.162284"], ["84114.6", "0"], ["84114.7", "0"], ["84115.2", "0.04"], ["84115.3", "0.0415"], ["84118.7", "0"], ["84121.5", "2.621209"], ["84132.2", "0.005472"], ["84133.9", "0.356976"], ["84140.6", "0.005473"]], "u": 168036, "seq": 67577203741}, "cts": 1742584913113, "record_time": 1742584913.222011, "EXCHANGE": "BYBIT"}
{"topic": "orderbook.200.BTCUSDT", "ts": 1742584913320, "type": "delta", "data": {"s": "BTCUSDT", "b": [["84069.4", "0.460117"], ["84063", "0.01"], ["84058.1", "0"], ["84038.7", "0.023787"], ["84038.5", "0.039629"], ["84037", "0.025371"], ["84036.8", "0.01288"], ["84035.5", "0.005313"], ["84035.4", "0.096388"], ["84035.1", "0.04954"], ["84035", "0.04954"], ["84032", "0.178592"], ["84031.9", "0"], ["84031.8", "0"], ["84030.7", "0.356977"], ["84008.3", "16.100985"], ["84008.2", "0"], ["84007", "0"], ["84006.9", "0"], ["84006.1", "0"], ["84005.2", "0"]], "a": [["84069.5", "0.143438"], ["84078.2", "0"], ["84092.5", "0.097945"], ["84109.7", "0"], ["84115.2", "0"], ["84115.3", "0.0015"], ["84115.9", "0.063784"], ["84116", "0.04"], ["84132.5", "0.356977"], ["84133.9", "0"], ["84141.7", "0.060832"], ["84142.4", "0.000333"]], "u": 168037, "seq": 67577203805}, "cts": 1742584913317, "record_time": 1742584913.423374, "EXCHANGE": "BYBIT"}
{"topic": "orderbook.200.BTCUSDT", "ts": 1742584913519, "type": "delta", "data": {"s": "BTCUSDT", "b": [["84069.4", "0.460917"], ["84067", "0.004"], ["84063", "0"], ["84062.9", "0.055886"], ["84057.9", "0.114923"], ["84048.4", "0.067762"], ["84048.1", "0.192825"], ["84039", "0.31078"], ["84038.3", "0.0016"], ["84037.2", "0.013"], ["84037.1", "0.012879"], ["84036.9", "0.587997"], ["84036.8", "0"], ["84035.4", "0.145928"], ["84035.3", "0.050729"], ["84035.1", "0"], ["84035", "0"], ["84034.2", "0.171"]], "a": [["84069.5", "0.183438"], ["84080.9", "0.145375"], ["84083.1", "0.161615"], ["84092.9", "0.172485"], ["84102", "0.293246"], ["84109.8", "0.03569"], ["84121.5", "2.621195"], ["84132.2", "0.362449"], ["84132.5", "0"]], "u": 168038, "seq": 67577203913}, "cts": 1742584913517, "record_time": 1742584913.622103, "EXCHANGE": "BYBIT"}
{"topic": "orderbook.200.BTCUSDT", "ts": 1742584913719, "type": "delta", "data": {"s": "BTCUSDT", "b": [["84062.6", "0"], ["84057.9", "0"], ["84048.1", "0.005682"], ["84048", "0"], ["84039", "0"], ["84038.9", "0.039628"], ["84038.8", "0.039628"], ["84038.6", "0"], ["84038.5", "0"], ["84037.2", "0.012879"], ["84030.7", "0"], ["84030.6", "0.090085"], ["84028.6", "0.35698"], ["84025.9", "0"], ["84007", "0.06"], ["84006.9", "0.003"], ["84006.1", "0.005238"], ["84005.2", "0.00595"], ["84004.7", "0.001466"]], "a": [["84075.9", "0.071398"], ["84083.1", "0.04"], ["84085", "0.07139"], ["84087.2", "0.142273"], ["84092.9", "0"], ["84102", "0"], ["84114.8", "0.04062"], ["84114.9", "0.04"], ["84115.9", "0.023784"], ["84116", "0"], ["84132.1", "0.389962"], ["84132.2", "0.005472"]], "u": 168039, "seq": 67577204018}, "cts": 1742584913716, "record_time": 1742584913.821877, "EXCHANGE": "BYBIT"}
{"topic": "orderbook.200.BTCUSDT", "ts": 1742584913920, "type": "delta", "data": {"s": "BTCUSDT", "b": [["84049.4", "0.03569"], ["84048.4", "0"], ["84041.3", "0"], ["84039.2", "0.04"], ["84039.1", "0.039628"], ["84038.9", "0"], ["84038.8", "0"], ["84037.5", "0.364353"], ["84037.4", "0.138092"], ["84037.2", "0"], ["84037.1", "0"], ["84035.7", "0.05"], ["84035.6", "0.049539"], ["84035.4", "0.096388"], ["84035.3", "0.001189"], ["84032", "0"], ["84030.7", "0.356979"], ["84028.6", "0"], ["84003.9", "0.000884"], ["84003.7", "0.000333"]], "a": [["84092.5", "0.06221"], ["84093.2", "0.006314"], ["84100.8", "0.086098"], ["84113.9", "0.04"], ["84114", "0.04"], ["84114.8", "0.00062"], ["84114.9", "0"], ["84118.7", "2.621195"], ["84121.5", "0"], ["84132", "0.356978"], ["84132.1", "0.032982"], ["84136.4", "0.005472"], ["84140.6", "0"], ["84141.7", "0"], ["84142.4", "0"]], "u": 168040, "seq": 67577204091}, "cts": 1742584913906, "record_time": 1742584914.023557, "EXCHANGE": "BYBIT"}
{"topic": "orderbook.200.BTCUSDT", "ts": 1742584914119, "type": "delta", "data": {"s": "BTCUSDT", "b": [["84069.4", "0.461375"], ["84054.1", "0.184946"], ["84053.5", "0.05"], ["84053.4", "0.001333"], ["84047.9", "0.003576"], ["84047.1", "0.183294"], ["84040.1", "0.297168"], ["84031.6", "0.178962"], ["84030.8", "0.356979"], ["84030.7", "0"], ["84023.1", "0.027179"], ["84005.2", "0"], ["84004.7", "0"], ["84003.9", "0"], ["84003.7", "0"]], "a": [["84069.5", "0.183217"], ["84075.9", "0"], ["84077", "0.171717"], ["84087", "0.116423"], ["84093.2", "0"], ["84094", "0.184944"], ["84098.5", "0.000904"], ["84101", "0.282853"], ["84131.9", "0.356978"], ["84132", "0"], ["84140", "0"], ["84140.3", "0"]], "u": 168041, "seq": 67577204164}, "cts": 1742584914116, "record_time": 1742584914.222133, "EXCHANGE": "BYBIT"}
{"topic": "orderbook.200.BTCUSDT", "ts": 1742584914319, "type": "delta", "data": {"s": "BTCUSDT", "b": [["84047.9", "0"], ["84039.2", "0"], ["84039.1", "0"], ["84038.9", "0.039628"], ["84038.8", "0.039628"], ["84037.5", "0.351353"], ["84037.4", "0.125213"], ["84037.2", "0.012879"], ["84037.1", "0.012879"], ["84035.7", "0"], ["84035.6", "0"], ["84035.4", "0.145928"], ["84035.3", "0.050729"], ["84030.9", "0.356978"], ["84030.8", "0"], ["84005.2", "0.00595"]], "a": [["84080.9", "0.146374"], ["84085.6", "0.062975"], ["84098.5", "0"], ["84100.8", "0.160942"], ["84113.9", "0"], ["84114", "0"], ["84114.6", "0.04"], ["84114.7", "0.04"], ["84131.9", "0"], ["84132.2", "0.36245"], ["84140", "0.00042"], ["84140.3", "0.118539"]], "u": 168042, "seq": 67577204222}, "cts": 1742584914308, "record_time": 1742584914.422466, "EXCHANGE": "BYBIT"}
{"topic": "orderbook.200.BTCUSDT", "ts": 1742584914520, "type": "delta", "data": {"s": "BTCUSDT", "b": [["84038.9", "0"], ["84038.7", "0.063415"], ["84037.5", "0.364353"], ["84037.4", "0.138092"], ["84037.2", "0"], ["84037.1", "0"], ["84035.6", "0.05"], ["84035.5", "0.054852"], ["84035.4", "0.096388"], ["84035.3", "0.001189"], ["84030.9", "0"], ["84030.6", "0.090093"], ["84028.6", "0.35698"], ["84004.7", "0.001466"], ["84003.9", "0.000884"]], "a": [["84085.6", "0.059399"], ["84114.6", "0"], ["84114.7", "0"], ["84114.9", "0.04"], ["84115", "0.04"], ["84132.2", "0.362449"]], "u": 168043, "seq": 67577204263}, "cts": 1742584914498, "record_time": 1742584914.622559, "EXCHANGE": "BYBIT"}
{"topic": "orderbook.200.BTCUSDT", "ts": 1742584914720, "type": "delta", "data": {"s": "BTCUSDT", "b": [["84069.4", "0.290375"], ["84056.7", "0.150497"], ["84054.1", "0.064333"], ["84047.1", "0"], ["84046.2", "0.164723"], ["84040.1", "0"], ["84039.2", "0.30293"], ["84039", "0.04"], ["84038.9", "0.039628"], ["84038.8", "0"], ["84038.7", "0.023787"], ["84037.5", "0.351353"], ["84037.4", "0.125213"], ["84037.3", "0.013333"], ["84037.2", "0.012879"], ["84035.6", "0"], ["84035.5", "0.005313"], ["84035.4", "0.145928"], ["84035.3", "0.050729"], ["84031.6", "0.000526"], ["84030.7", "0.35698"], ["84028.6", "0"], ["84003.9", "0"]], "a": [["84069.5", "0.354217"], ["84073.3", "0.040653"], ["84077", "0.10032"], ["84077.6", "0.071396"], ["84078.6", "0.004736"], ["84081.2", "0.120727"], ["84087", "0"], ["84087.6", "0.071388"], ["84089.4", "0"], ["84091.7", "0.172853"], ["84094", "0"], ["84098.6", "0.006476"], ["84098.7", "0.282184"], ["84101", "0"], ["84114.5", "0.04"], ["84114.6", "0.04"], ["84114.9", "0"], ["84115", "0"]], "u": 168044, "seq": 67577204349}, "cts": 1742584914716, "record_time": 1742584914.82342, "EXCHANGE": "BYBIT"}
{"topic": "orderbook.200.BTCUSDT", "ts": 1742584914920, "type": "delta", "data": {"s": "BTCUSDT", "b": [["84069.4", "0.461375"], ["84056.7", "0.038314"], ["84046.2", "0"], ["84039.2", "0"], ["84039", "0.039628"], ["84037.3", "0.013212"], ["84030.7", "0.356977"], ["84003.9", "0.000884"], ["84003.7", "0.000333"]], "a": [["84069.5", "0.183217"], ["84081.2", "0.00009"], ["84089.3", "0.170273"], ["84090.2", "0.03"], ["84091.7", "0.000528"], ["84098.6", "0.005475"], ["84098.7", "0"], ["84100.8", "0.086098"], ["84115.9", "2.644979"], ["84118.7", "0"], ["84140.6", "0.005473"], ["84141.7", "0.060832"]], "u": 168045, "seq": 67577204436}, "cts": 1742584914911, "record_time": 1742584915.023597, "EXCHANGE": "BYBIT"}
{"topic": "orderbook.200.BTCUSDT", "ts": 1742584915120, "type": "delta", "data": {"s": "BTCUSDT", "b": [["84052.9", "0.05"], ["84052.8", "0"], ["84031.6", "0.357503"], ["84030.7", "0"], ["84003", "0.401333"]], "a": [["84076.3", "0.071398"], ["84077.6", "0"], ["84089.3", "0.102252"], ["84093.2", "0.006137"], ["84118.3", "0.092979"], ["84141.7", "0"]], "u": 168046, "seq": 67577204476}, "cts": 1742584915106, "record_time": 1742584915.222868, "EXCHANGE": "BYBIT"}
{"topic": "orderbook.200.BTCUSDT", "ts": 1742584915320, "type": "delta", "data": {"s": "BTCUSDT", "b": [["84062.9", "0.056039"], ["84040.5", "0.025713"], ["84039", "0"], ["84038.8", "0.039628"], ["84037.3", "0.000333"], ["84037.1", "0.012879"], ["84035.4", "0.096388"], ["84035.2", "0.04954"], ["84031.7", "0.178596"], ["84031.6", "0.000526"], ["84030.7", "0.356977"], ["84023.1", "0.001466"], ["84005.2", "0"], ["84004.7", "0"], ["84003.9", "0"], ["84003.7", "0"], ["84003", "0"]], "a": [["84073.3", "0"], ["84087.1", "0.001861"], ["84111.4", "0"], ["84113.5", "0.864714"], ["84114.5", "0"], ["84114.6", "0"], ["84115", "0.04"], ["84115.1", "0.04"], ["84115.9", "0.023784"], ["84132.5", "2.621195"], ["84133.8", "0"], ["84141.7", "0.060832"], ["84142.4", "0.000333"]], "u": 168047, "seq": 67577204529}, "cts": 1742584915316, "record_time": 1742584915.423393, "EXCHANGE": "BYBIT"}
{"topic": "orderbook.200.BTCUSDT", "ts": 1742584915520, "type": "delta", "data": {"s": "BTCUSDT", "b": [["84074", "0.685012"], ["84073.9", "0.1"], ["84073.5", "0.027393"], ["84073.3", "0.091311"], ["84070.4", "0.009225"], ["84070.1", "0.007116"], ["84069.5", "0.099608"], ["84069.4", "0.301174"], ["84068.1", "0.004"], ["84067.2", "0.028465"], ["84067", "0"], ["84066.8", "0.051333"], ["84066.5", "0.00528"], ["84065.6", "0.08624"], ["84065.4", "0.081018"], ["84065.3", "0.089099"], ["84065.2", "0.005947"], ["84064.9", "0.065327"], ["84064.5", "0.009063"], ["84064", "0"], ["84063.5", "0.005947"], ["84063", "0.0427"], ["84062.9", "0.055886"], ["84062.8", "0.064"], ["84062.7", "0.048"], ["84062.4", "0.236447"], ["84061.9", "0"], ["84061.3", "0.021175"], ["84061", "0.092"], ["84060.5", "0"], ["84060.4", "0.178443"], ["84059.8", "0.064"], ["84059.5", "0.064617"], ["84058.5", "0"], ["84057.6", "0.060732"], ["84057.5", "0.089099"], ["84057.4", "0"], ["84057.2", "0"], ["84056.7", "0"], ["84056.2", "0.06"], ["84056", "0.587997"], ["84055.7", "0.064"], ["84055.4", "0.012"], ["84054.8", "0"], ["84054", "0.5269"], ["84053.5", "0"], ["84053", "0.029612"], ["84052.9", "0"], ["84052.1", "0"], ["84051.9", "0"], ["84051.2", "0.349422"], ["84051", "0"], ["84050.8", "0"], ["84050.6", "0"], ["84050.5", "0.229177"], ["84048.8", "0.023789"], ["84048.5", "0.118949"], ["84044", "0"], ["84043.5", "0.025713"], ["84042.9", "0.356931"], ["84042.2", "0.023489"], ["84042.1", "0"], ["84041.1", "0"], ["84040.5", "0"], ["84040.4", "0.023826"], ["84040.2", "0"], ["84039.8", "0"], ["84039.4", "0.0016"], ["84039.2", "0.284117"], ["84038.9", "0"], ["84038.8", "0"], ["84038.3", "0.04"], ["84038.2", "0.039629"], ["84038", "0.011894"], ["84037.2", "0"], ["84037.1", "0"], ["84036.9", "0"], ["84036.6", "0.014333"], ["84036.5", "0.01288"], ["84035.4", "0"], ["84035.3", "0.001189"], ["84035.2", "0"], ["84034.7", "0.05"], ["84034.6", "0.049541"], ["84032.6", "0"], ["84030.7", "0"], ["84028.4", "0"], ["84023.8", "0"], ["84021.2", "0"], ["84008.3", "0"]], "a": [["84069.5", "0"], ["84073.4", "0"], ["84074", "0"], ["84074.1", "0.118458"], ["84076.3", "0"], ["84076.9", "0"], ["84077", "0"], ["84077.2", "0.00497"], ["84077.4", "0"], ["84077.9", "0"], ["84078.4", "0"], ["84080.1", "0.01988"], ["84080.9", "0.001998"], ["84081.1", "0"], ["84081.2", "0"], ["84081.6", "0.10032"], ["84081.8", "0"], ["84082.5", "0.23171"], ["84083.1", "0"], ["84083.3", "0"], ["84083.7", "0"], ["84083.9", "0"], ["84084.1", "0"], ["84084.2", "0"], ["84084.3", "0.029818"], ["84084.7", "0.022782"], ["84085", "0"], ["84085.6", "0.07572"], ["84085.7", "0"], ["84085.9", "0.005468"], ["84086", "0"], ["84086.9", "0"], ["84087.2", "0.072273"], ["84087.6", "0"], ["84088", "0.171"], ["84088.7", "0"], ["84088.9", "0"], ["84089", "0"], ["84089.3", "0"], ["84090", "0"], ["84090.2", "0"], ["84090.5", "0"], ["84090.6", "0"], ["84090.7", "0"], ["84092.5", "0.133117"], ["84092.7", "0.04"], ["84093.2", "0"], ["84093.4", "0.009225"], ["84094.2", "0"], ["84095.3", "0.118949"], ["84095.6", "0.071381"], ["84096.6", "0.019226"], ["84096.9", "0"], ["84098.3", "0.122712"], ["84098.9", "0"], ["84102.9", "0.009938"], ["84106", "0"], ["84106.6", "0"], ["84107", "0.005445"], ["84108.5", "0"], ["84109.4", "0.005947"], ["84109.6", "0.001078"], ["84109.8", "0"], ["84110.2", "0.536635"], ["84110.9", "0"], ["84112", "0"], ["84112.5", "0"], ["84113.5", "0.08763"], ["84114.1", "0.028875"], ["84114.4", "0.0006"], ["84115", "0"], ["84115.1", "0"], ["84118.5", "0.04"], ["84118.6", "0.042498"], ["84119.4", "0.588465"], ["84121.7", "0"], ["84123", "0"], ["84128", "0.289443"], ["84129.5", "0.052935"], ["84129.6", "0.023301"], ["84132.2", "0.005472"], ["84132.5", "0"], ["84136.2", "0"], ["84136.8", "1.784239"], ["84142.6", "0.00053"], ["84142.8", "0.051333"], ["84143.4", "0.001466"], ["84143.7", "0.024382"], ["84143.8", "3.572392"], ["84144.2", "0.0018"], ["84144.8", "0.005475"], ["84144.9", "0.023781"], ["84145.3", "0.0015"], ["84145.4", "0.012"], ["84145.6", "0.118539"], ["84145.9", "0.001333"], ["84146.6", "0.000333"], ["84146.9", "3.917687"], ["84147.2", "0.00053"], ["84148", "0.001466"], ["84148.2", "0.000358"], ["84148.4", "0.00009"], ["84148.6", "0.000358"], ["84148.9", "0.04"], ["84149", "0.005477"], ["84149.1", "0.089207"], ["84149.8", "0.0006"], ["84150.1", "0.001333"], ["84150.8", "0.158539"], ["84150.9", "0.000333"], ["84151.6", "0.059399"], ["84151.8", "0.000528"], ["84152.1", "0.0006"], ["84152.2", "0.0012"], ["84152.5", "0.0006"]], "u": 168048, "seq": 67577205474}, "cts": 1742584915517, "record_time": 1742584915.623107, "EXCHANGE": "BYBIT"}
{"topic": "orderbook.200.BTCUSDT", "ts": 1742584915719, "type": "delta", "data": {"s": "BTCUSDT", "b": [["84074", "0.957044"], ["84073.5", "0"], ["84073.3", "0.019911"], ["84069.5", "0.101808"], ["84069.4", "0.295474"], ["84065.7", "0.125421"], ["84065.6", "0.1133"], ["84065.4", "0"], ["84064.8", "0.000617"], ["84064.6", "0.185434"], ["84061.5", "0.064"], ["84061.2", "0.184387"], ["84059.5", "0.064"], ["84058.2", "0.05"], ["84058.1", "0.06"], ["84058", "0.06"], ["84056.4", "0.06"], ["84056.3", "0.025968"], ["84056.1", "0.200247"], ["84055.9", "0.178414"], ["84055.7", "0"], ["84054.5", "0.05"], ["84054.1", "0.000333"], ["84053.9", "0"], ["84052.5", "0.230206"], ["84052.4", "0.178414"], ["84051.5", "0.0264"], ["84050.5", "0.169177"], ["84048.2", "0.178414"], ["84044.2", "0.356922"], ["84044.1", "0"], ["84042.9", "0"], ["84041.2", "0.013919"], ["84039.1", "0.090093"], ["84037.5", "0"], ["84031.7", "0"], ["84030.6", "0"], ["84028.5", "0"], ["84011", "16.101051"], ["84009.8", "0.028095"], ["84008.7", "0"], ["84008.5", "0"], ["84008.4", "0"], ["84007.9", "0"], ["84007.2", "0"], ["84007", "0"], ["84006.9", "0"], ["84006.1", "0"]], "a": [["84074.1", "0.130947"], ["84082.5", "0.26911"], ["84089.2", "0.039605"], ["84089.3", "0.08"], ["84090.9", "0.04"], ["84091.1", "0.04"], ["84092.5", "0.149482"], ["84092.6", "0"], ["84094.3", "0.04"], ["84094.4", "0.045475"], ["84095.6", "0"], ["84095.9", "0.07"], ["84096", "0.111381"], ["84096.8", "0.098706"], ["84098.3", "0.071379"], ["84101.2", "0.051333"], ["84102.2", "0.111679"], ["84102.8", "0.183859"], ["84106.5", "0"], ["84113.5", "0"], ["84114.1", "0"], ["84114.8", "0.036308"], ["84118.5", "0"], ["84118.6", "0.002498"], ["84120", "0.04024"], ["84120.1", "0.04"], ["84120.3", "0"], ["84121.3", "0.004582"], ["84126.7", "0.051469"], ["84129.5", "0.001466"], ["84141.6", "0.356923"], ["84143.6", "2.621195"], ["84145", "0.171"], ["84150.8", "0"], ["84150.9", "0"], ["84151.6", "0"], ["84151.8", "0"], ["84152.1", "0"], ["84152.2", "0"], ["84152.5", "0"]], "u": 168049, "seq": 67577205795}, "cts": 1742584915713, "record_time": 1742584915.824594, "EXCHANGE": "BYBIT"}
{"topic": "orderbook.200.BTCUSDT", "ts": 1742584915919, "type": "delta", "data": {"s": "BTCUSDT", "b": [["84074", "1.187564"], ["84052.2", "0"], ["84048.5", "0"], ["84048.3", "0"], ["84044.2", "0"], ["84042.9", "0.356926"], ["84035.5", "0.055313"], ["84035.4", "0.049545"], ["84034.7", "0"], ["84034.6", "0"], ["84024.5", "0.000149"], ["84012.9", "0"], ["84011", "0"], ["84008.5", "0.000526"], ["84008.4", "0.00018"], ["84007.9", "0.000333"], ["84007.2", "0.001333"], ["84007", "0.06"]], "a": [["84074.1", "0.098482"], ["84092.6", "0.04"], ["84095.3", "0"], ["84099.8", "0.023789"], ["84100.8", "0.181495"], ["84102.8", "0.005445"], ["84114.8", "0.00062"], ["84123.8", "0.056921"], ["84126.6", "0"], ["84126.7", "0"], ["84132.5", "2.621195"], ["84138.2", "0.000478"], ["84141.6", "0.356926"], ["84143.6", "0"], ["84150.8", "0.158539"]], "u": 168050, "seq": 67577205887}, "cts": 1742584915912, "record_time": 1742584916.048431, "EXCHANGE": "BYBIT"}
{"topic": "orderbook.200.BTCUSDT", "ts": 1742584916120, "type": "delta", "data": {"s": "BTCUSDT", "b": [["84074", "0.831015"], ["84057.6", "0.308022"], ["84056.3", "0.025958"], ["84056.1", "0.059399"], ["84052.5", "0.111667"], ["84043.5", "0"], ["84043", "0.35692"], ["84042.9", "0"], ["84029.7", "0.025713"], ["84008.7", "0.171"], ["84007", "0"]], "a": [["84074.1", "0.131185"], ["84085.7", "0.024224"], ["84093.7", "0.071383"], ["84098.3", "0"], ["84116.1", "0.035687"], ["84119.6", "0.183866"], ["84120", "0.00024"], ["84120.1", "0"], ["84120.2", "0.041466"], ["84120.3", "0.04"], ["84123.8", "0.235335"], ["84132.5", "2.621052"], ["84141.6", "0"], ["84143.7", "0.381306"], ["84150.8", "0"]], "u": 168051, "seq": 67577205962}, "cts": 1742584916117, "record_time": 1742584916.223348, "EXCHANGE": "BYBIT"}
{"topic": "orderbook.200.BTCUSDT", "ts": 1742584916319, "type": "delta", "data": {"s": "BTCUSDT", "b": [["84070.4", "0"], ["84065.6", "0.1733"], ["84065.5", "0.009225"], ["84065", "0.000153"], ["84064.9", "0.005327"], ["84054.3", "0.004605"], ["84045.2", "0.026754"], ["84043.1", "0.600068"], ["84043", "0"], ["84042.2", "0"], ["84040.4", "0"], ["84037.7", "0.013"], ["84037.6", "0.13142"], ["84036.6", "0.001333"], ["84036.5", "0"], ["84035.7", "0.05"], ["84035.6", "0.049545"], ["84035.5", "0.005313"], ["84035.4", "0"], ["84031.9", "0.023489"], ["84030.3", "16.098533"], ["84008.4", "0"], ["84007.9", "0"], ["84007.2", "0"]], "a": [["84086.5", "0.071389"], ["84096.8", "0.062918"], ["84101.2", "0"], ["84119.6", "0.005452"], ["84123.8", "0.056921"], ["84129.8", "2.621385"], ["84132.5", "0"], ["84143.6", "0.356924"], ["84143.7", "0.024382"]], "u": 168052, "seq": 67577206040}, "cts": 1742584916318, "record_time": 1742584916.422781, "EXCHANGE": "BYBIT"}
{"topic": "orderbook.200.BTCUSDT", "ts": 1742584916519, "type": "delta", "data": {"s": "BTCUSDT", "b": [["84074", "0.834074"], ["84065", "0"], ["84062.4", "0.286447"], ["84060.3", "0.05"], ["84060.2", "0"], ["84058.2", "0"], ["84052.6", "0.118539"], ["84046", "0.356918"], ["84043.1", "0"], ["84039.3", "0.039632"], ["84039.2", "0.323749"], ["84038.3", "0"], ["84038.2", "0"], ["84037.7", "0"], ["84037.5", "0.012881"], ["84035.7", "0.049545"], ["84030.3", "0"], ["84024.9", "16.096674"], ["84008.4", "0.00018"], ["84007.9", "0.000333"]], "a": [["84074.5", "0.01069"], ["84093.7", "0"], ["84095.4", "0.051333"], ["84098.6", "0.076854"], ["84100.8", "0.086098"], ["84110.1", "0.204479"], ["84116.1", "0"], ["84119.6", "0.045452"], ["84119.7", "0.04"], ["84120.2", "0.001466"], ["84120.3", "0"], ["84123", "0.000118"], ["84123.8", "0.005452"], ["84126.7", "0.051466"], ["84128", "0.200236"], ["84129.8", "0.000333"], ["84132.5", "2.621052"], ["84143.6", "0"], ["84148.8", "0.356915"], ["84149", "0"], ["84149.1", "0"], ["84149.8", "0"], ["84150.1", "0"]], "u": 168053, "seq": 67577206129}, "cts": 1742584916506, "record_time": 1742584916.622806, "EXCHANGE": "BYBIT"}
{"topic": "orderbook.200.BTCUSDT", "ts": 1742584916719, "type": "delta", "data": {"s": "BTCUSDT", "b": [["84074", "0.831015"], ["84062.4", "0.336447"], ["84062.2", "0"], ["84061.6", "0.05"], ["84061.1", "0.05"], ["84060.3", "0"], ["84058.4", "0.025945"], ["84056.3", "0"], ["84054.5", "0"], ["84039.3", "0"], ["84039.1", "0.129725"], ["84037.6", "0.118539"], ["84037.4", "0.138094"], ["84035.7", "0"], ["84035.5", "0.054858"], ["84027.6", "16.096674"], ["84024.9", "0"], ["84007.2", "0.001333"], ["84007", "0.06"], ["84006.9", "0.003"]], "a": [["84086.5", "0"], ["84087.6", "0.071388"], ["84119.6", "0.005452"], ["84119.7", "0"], ["84119.8", "0.04"], ["84119.9", "0.04"], ["84128", "0.37865"], ["84132.2", "0.183886"], ["84148.9", "0"]], "u": 168054, "seq": 67577206197}, "cts": 1742584916713, "record_time": 1742584916.821661, "EXCHANGE": "BYBIT"}
{"topic": "orderbook.200.BTCUSDT", "ts": 1742584916920, "type": "delta", "data": {"s": "BTCUSDT", "b": [["84074", "0.801015"], ["84065.7", "0.175421"], ["84065.3", "0"], ["84062.4", "0.286447"], ["84058.5", "0.025945"], ["84058.4", "0"], ["84046", "0"], ["84039.3", "0.356935"], ["84006.1", "0.005238"]], "a": [["84087.6", "0"], ["84093.5", "0.071383"], ["84098.6", "0.183889"], ["84102.8", "0.183859"], ["84116.1", "0.035687"], ["84119.8", "0"], ["84120", "0.04024"], ["84123.8", "0.056918"], ["84126.7", "0"], ["84127", "2.621052"], ["84128", "0.200236"], ["84132.2", "0.005472"], ["84132.5", "0"], ["84141.6", "0.356931"], ["84148.8", "0"], ["84148.9", "0.04"]], "u": 168055, "seq": 67577206295}, "cts": 1742584916916, "record_time": 1742584917.023265, "EXCHANGE": "BYBIT"}
{"topic": "orderbook.200.BTCUSDT", "ts": 1742584917119, "type": "delta", "data": {"s": "BTCUSDT", "b": [["84059.7", "0.196959"], ["84058.5", "0"], ["84045.2", "0.003575"], ["84040.9", "0.02416"], ["84039.3", "0.396935"], ["84039.1", "0.090093"], ["84037.6", "0.131539"], ["84037.4", "0.125213"], ["84035.7", "0.049545"], ["84035.5", "0.005313"], ["84006.1", "0"]], "a": [["84081.5", "0.113567"], ["84085.7", "0"], ["84116.1", "0"], ["84119.6", "0.045452"], ["84119.7", "0.04"], ["84119.9", "0"], ["84120", "0.00024"], ["84125.1", "0.023721"], ["84128", "0.289443"], ["84129.6", "0"], ["84140.2", "0.356937"], ["84141.6", "0"], ["84149", "0.005477"]], "u": 168056, "seq": 67577206409}, "cts": 1742584917115, "record_time": 1742584917.22164, "EXCHANGE": "BYBIT"}
{"topic": "orderbook.200.BTCUSDT", "ts": 1742584917320, "type": "delta", "data": {"s": "BTCUSDT", "b": [["84069.5", "0.099608"], ["84039.3", "0.039632"], ["84037.7", "0.356946"], ["84037.6", "0.13142"], ["84006.9", "0"]], "a": [["84096.8", "0.108577"], ["84116", "1.426602"], ["84116.1", "0.035687"], ["84136.4", "0.362422"], ["84140.2", "0"], ["84149", "0"]], "u": 168057, "seq": 67577206455}, "cts": 1742584917316, "record_time": 1742584917.423113, "EXCHANGE": "BYBIT"}
{"topic": "orderbook.200.BTCUSDT", "ts": 1742584917520, "type": "delta", "data": {"s": "BTCUSDT", "b": [["84074", "0.797982"], ["84072.7", "0.0037"], ["84068.1", "0"], ["84067.3", "0.071405"], ["84063.9", "0.000528"], ["84044", "0.0016"], ["84039.4", "0.356946"], ["84037.8", "0.301531"], ["84037.7", "0"], ["84027.6", "16.097564"], ["84007.2", "0"], ["84007", "0"]], "a": [["84080.9", "0.000999"], ["84085.4", "0.07139"], ["84086.1", "0.023867"], ["84089.2", "0.066793"], ["84091.3", "0.072718"], ["84096", "0.04"], ["84098.2", "0.00615"], ["84115.9", "0.47837"], ["84127", "0"], ["84132.5", "2.621052"], ["84136.4", "0.005472"], ["84140.2", "0.356945"], ["84148.2", "0"], ["84148.4", "0"], ["84148.6", "0"], ["84148.9", "0"]], "u": 168058, "seq": 67577206556}, "cts": 1742584917516, "record_time": 1742584917.623105, "EXCHANGE": "BYBIT"}
{"topic": "orderbook.200.BTCUSDT", "ts": 1742584917720, "type": "delta", "data": {"s": "BTCUSDT", "b": [["84069.4", "0.293574"], ["84065.4", "0.000153"], ["84063.1", "0.116323"], ["84059.3", "0.109918"], ["84055.8", "0.035687"], ["84053.3", "0.181517"], ["84052.6", "0"], ["84052.3", "0.17899"], ["84049.4", "0"], ["84045.3", "0.277586"], ["84044.2", "0.300399"], ["84037.8", "0"], ["84008.5", "0"], ["84008.4", "0"], ["84007.9", "0"]], "a": [["84074.1", "0.124289"], ["84081.5", "0"], ["84088.2", "0.14995"], ["84088.3", "0.12095"], ["84089.2", "0"], ["84092.2", "0.110107"], ["84098.1", "0.179451"], ["84099.2", "0.163411"], ["84106.2", "0.303002"], ["84107.2", "0.29036"], ["84116.1", "0"], ["84140.2", "0"], ["84141.6", "0.356941"], ["84142.5", "0.003"], ["84145.9", "0"], ["84146.6", "0"], ["84146.9", "0"], ["84147.2", "0"], ["84148", "0"]], "u": 168059, "seq": 67577206648}, "cts": 1742584917710, "record_time": 1742584917.822469, "EXCHANGE": "BYBIT"}
{"topic": "orderbook.200.BTCUSDT", "ts": 1742584917920, "type": "delta", "data": {"s": "BTCUSDT", "b": [["84065.8", "0.000153"], ["84065.4", "0"], ["84063.1", "0"], ["84059.3", "0.000528"], ["84053.3", "0"], ["84052.3", "0.005326"], ["84045.3", "0"], ["84044.2", "0"], ["84029.7", "0"], ["84008.5", "0.000526"], ["84008.4", "0.00018"], ["84007.9", "0.000333"], ["84007.2", "0.001333"], ["84007", "0.06"]], "a": [["84074.1", "0.126299"], ["84088.2", "0.071743"], ["84088.3", "0"], ["84092.2", "0"], ["84096.8", "0.207573"], ["84098.1", "0"], ["84099.2", "0"], ["84106.2", "0"], ["84107.2", "0"], ["84116.1", "0.035687"], ["84141.5", "0.356939"], ["84141.6", "0"], ["84145.9", "0.001333"], ["84146.6", "0.000333"], ["84146.9", "3.917687"], ["84147.2", "0.00053"], ["84148", "0.001466"]], "u": 168060, "seq": 67577206734}, "cts": 1742584917917, "record_time": 1742584918.021799, "EXCHANGE": "BYBIT"}
{"topic": "orderbook.200.BTCUSDT", "ts": 1742584918120, "type": "delta", "data": {"s": "BTCUSDT", "b": [["84074", "0.884"], ["84065.8", "0"], ["84061.3", "0.14561"], ["84039.5", "0.356939"], ["84039.4", "0"], ["84039.3", "0"], ["84039.2", "0.284117"], ["84039.1", "0.129725"], ["84039", "0.039633"], ["84037.6", "0.118539"], ["84037.5", "0"], ["84037.4", "0.138094"], ["84037.3", "0.013214"], ["84035.7", "0.05"], ["84006.9", "0.003"], ["84006.1", "0.005238"]], "a": [["84096.8", "0.118287"], ["84116.1", "0"], ["84116.2", "0.035687"], ["84119.6", "0.005452"], ["84119.7", "0"], ["84120.2", "0.041466"], ["84120.3", "0.04"], ["84123.8", "0.005452"], ["84126.7", "0.051466"], ["84141.4", "0.356939"], ["84141.5", "0"], ["84148", "0"]], "u": 168061, "seq": 67577206844}, "cts": 1742584918113, "record_time": 1742584918.223465, "EXCHANGE": "BYBIT"}
{"topic": "orderbook.200.BTCUSDT", "ts": 1742584918320, "type": "delta", "data": {"s": "BTCUSDT", "b": [["84042.9", "0.356932"], ["84039.5", "0"], ["84037.6", "0.13142"], ["84037.5", "0.012881"], ["84037.4", "0.125213"], ["84037.3", "0.000333"], ["84035.7", "0.049545"], ["84027.6", "16.097442"], ["84006.1", "0"]], "a": [["84080.9", "0"], ["84085.4", "0"], ["84086.5", "0.071389"], ["84088.2", "0.050328"], ["84091.3", "0.001333"], ["84096.1", "0.071381"], ["84141.4", "0"], ["84143.7", "0.381312"], ["84148", "0.001466"]], "u": 168062, "seq": 67577206956}, "cts": 1742584918315, "record_time": 1742584918.42336, "EXCHANGE": "BYBIT"}
{"topic": "orderbook.200.BTCUSDT", "ts": 1742584918519, "type": "delta", "data": {"s": "BTCUSDT", "b": [["84043", "0.236098"], ["84040.4", "0.096383"], ["84030.3", "16.097442"], ["84027.6", "0"], ["84007", "0"], ["84006.9", "0"]], "a": [["84085.3", "0.07139"], ["84086.5", "0"], ["84091.7", "0.071912"], ["84093.5", "0"], ["84118.3", "0.296137"], ["84143.6", "0.356929"], ["84143.7", "0.024382"], ["84146.1", "1.026786"], ["84148", "0"]], "u": 168063, "seq": 67577207016}, "cts": 1742584918509, "record_time": 1742584918.622239, "EXCHANGE": "BYBIT"}
{"topic": "orderbook.200.BTCUSDT", "ts": 1742584918719, "type": "delta", "data": {"s": "BTCUSDT", "b": [["84048.3", "0.023789"], ["84043.1", "0.356929"], ["84042.9", "0"], ["84038.3", "0.05"], ["84038.2", "0.049542"], ["84035.7", "0"], ["84035.6", "0"], ["84030.3", "0"], ["84024.9", "16.097442"], ["84007.2", "0"]], "a": [["84074.1", "0.093596"], ["84084.2", "0.120078"], ["84084.3", "0.101209"], ["84085.3", "0"], ["84085.6", "0"], ["84090.1", "0.076861"], ["84096.1", "0"], ["84098.2", "0"], ["84099.8", "0"], ["84116.2", "0"], ["84123.8", "0.056918"], ["84126.7", "0"], ["84143.5", "0.35693"], ["84143.6", "0"], ["84148", "0.001466"], ["84148.2", "0.000358"], ["84148.4", "0.00009"], ["84148.6", "0.000358"], ["84148.9", "0.04"], ["84149", "0.005477"]], "u": 168064, "seq": 67577207083}, "cts": 1742584918710, "record_time": 1742584918.821713, "EXCHANGE": "BYBIT"}
{"topic": "orderbook.200.BTCUSDT", "ts": 1742584918920, "type": "delta", "data": {"s": "BTCUSDT", "b": [["84074", "0.884153"], ["84043.1", "0"], ["84043", "0"], ["84041.9", "0.04"], ["84041.8", "0.03963"], ["84040.2", "0.013"], ["84040.1", "0.01288"], ["84039.3", "0.356942"], ["84039.1", "0.090093"], ["84039", "0"], ["84038.4", "0.05"], ["84038.3", "0.049542"], ["84038.2", "0"], ["84037.6", "0.118539"], ["84037.5", "0"], ["84030.4", "16.097442"], ["84024.9", "0"], ["84007.9", "0"]], "a": [["84074.1", "0.126299"], ["84083.5", "0.071391"], ["84084.3", "0.029818"], ["84088.2", "0.086868"], ["84117.7", "0.035687"], ["84129.8", "2.621455"], ["84132.5", "0"], ["84140.2", "0.356944"], ["84143.5", "0"], ["84149", "0"]], "u": 168065, "seq": 67577207187}, "cts": 1742584918915, "record_time": 1742584919.022077, "EXCHANGE": "BYBIT"}
{"topic": "orderbook.200.BTCUSDT", "ts": 1742584919120, "type": "delta", "data": {"s": "BTCUSDT", "b": [["84074", "0.885427"], ["84067", "0.048"], ["84065.3", "0.092"], ["84062.7", "0"], ["84061", "0"], ["84050.5", "0.168107"], ["84041.9", "0"], ["84041.7", "0.03963"], ["84040.2", "0"], ["84040.1", "0"], ["84040", "0.01294"], ["84039.9", "0.01288"], ["84039.3", "0.356944"], ["84038.4", "0"], ["84038.3", "0"], ["84038.2", "0.049542"], ["84038.1", "0.049542"], ["84007.9", "0.000333"]], "a": [["84083.5", "0"], ["84120.2", "0.001466"], ["84120.3", "0"], ["84120.9", "0.04"], ["84121", "0.063784"], ["84140.1", "0.356944"], ["84140.2", "0"], ["84149", "0.005477"]], "u": 168066, "seq": 67577207270}, "cts": 1742584919115, "record_time": 1742584919.223315, "EXCHANGE": "BYBIT"}
{"topic": "orderbook.200.BTCUSDT", "ts": 1742584919319, "type": "delta", "data": {"s": "BTCUSDT", "b": [["84074", "0.88558"], ["84065.7", "0.125421"], ["84065.6", "0.2233"], ["84060.2", "0.023453"], ["84059.7", "0.171"], ["84041.8", "0"], ["84041.6", "0.041096"], ["84040", "0.00006"], ["84039.8", "0.01288"], ["84039.4", "0.356943"], ["84039.3", "0"], ["84038.2", "0"], ["84038", "0.061436"]], "a": [["84120.9", "0"], ["84121.1", "0.04"], ["84129.8", "0.000333"], ["84140", "0.357364"], ["84140.1", "0"], ["84149.1", "0.089207"]], "u": 168067, "seq": 67577207340}, "cts": 1742584919317, "record_time": 1742584919.421688, "EXCHANGE": "BYBIT"}
{"topic": "orderbook.200.BTCUSDT", "ts": 1742584919520, "type": "delta", "data": {"s": "BTCUSDT", "b": [["84040.1", "0.013"], ["84040", "0.01294"], ["84039.9", "0"], ["84039.8", "0"], ["84039.4", "0"], ["84038.3", "0.049542"], ["84038.2", "0.406491"], ["84038.1", "0"], ["84038", "0.011894"], ["84007.2", "0.001333"]], "a": [["84129.8", "2.621455"], ["84139.9", "0.356945"], ["84140", "0.00042"], ["84149.1", "0"]], "u": 168068, "seq": 67577207421}, "cts": 1742584919515, "record_time": 1742584919.623397, "EXCHANGE": "BYBIT"}
{"topic": "orderbook.200.BTCUSDT", "ts": 1742584919719, "type": "delta", "data": {"s": "BTCUSDT", "b": [["84041.7", "0.04"], ["84040.2", "0.269153"], ["84040.1", "0.01288"], ["84039.3", "0.356945"], ["84038.3", "0.05"], ["84038.2", "0.049542"], ["84007.9", "0"], ["84007.2", "0"]], "a": [["84074.1", "0.127773"], ["84108.2", "0.087016"], ["84129.8", "0.000333"], ["84132.5", "2.621122"], ["84139.9", "0"], ["84140.2", "0.356943"], ["84142.5", "0"], ["84149", "0"]], "u": 168069, "seq": 67577207498}, "cts": 1742584919717, "record_time": 1742584919.822145, "EXCHANGE": "BYBIT"}
{"topic": "orderbook.200.BTCUSDT", "ts": 1742584919919, "type": "delta", "data": {"s": "BTCUSDT", "b": [["84074", "1.038396"], ["84069.5", "0.153308"], ["84067.9", "0.089099"], ["84067.4", "0.064"], ["84065.7", "0.175489"], ["84065.5", "0"], ["84065.3", "0.142"], ["84064.8", "0"], ["84062.8", "0"], ["84062.2", "0.06"], ["84060.8", "0.06"], ["84058", "0"], ["84056.2", "0"], ["84042.9", "0.35693"], ["84042.1", "0.04"], ["84042", "0.091053"], ["84041.7", "0"], ["84041.6", "0.001466"], ["84040.3", "0.013"], ["84040.2", "0.282033"], ["84040.1", "0"], ["84040", "0.00006"], ["84039.3", "0"], ["84038.5", "0.05"], ["84038.4", "0.049541"], ["84038.3", "0"], ["84038.2", "0"], ["84034.8", "0.017792"], ["84033.2", "16.097539"], ["84030.4", "0"], ["84024.5", "0.025862"], ["84019.2", "0"], ["84007.9", "0.000333"]], "a": [["84084.7", "0"], ["84085.8", "0.071389"], ["84089.2", "0.022734"], ["84090.1", "0.005475"], ["84094.2", "0.071382"], ["84098.2", "0.005985"], ["84107", "0.183859"], ["84117.7", "0"], ["84117.8", "0.035686"], ["84123.8", "0.056919"], ["84132.5", "0"], ["84135.3", "2.621123"], ["84140.2", "0"], ["84145.5", "0.356928"], ["84148.4", "0"], ["84148.6", "0"], ["84148.9", "0"]], "u": 168070, "seq": 67577207698}, "cts": 1742584919917, "record_time": 1742584920.021857, "EXCHANGE": "BYBIT"}
{"topic": "orderbook.200.BTCUSDT", "ts": 1742584920120, "type": "delta", "data": {"s": "BTCUSDT", "b": [["84074", "1.038243"], ["84070.1", "0.030904"], ["84067.5", "0.064"], ["84065.8", "0.064"], ["84065.7", "0.239489"], ["84065.5", "0.118942"], ["84048.3", "0"], ["84042.9", "0.356931"], ["84040.2", "0.01288"], ["84039.6", "0.05"], ["84039.5", "0.04954"], ["84038.5", "0"], ["84038.4", "0"], ["84033.2", "0"], ["84022.7", "0"], ["84016.6", "16.097539"], ["84007.9", "0"]], "a": [["84084.8", "0.07139"], ["84085.8", "0"], ["84088.2", "0.072273"], ["84090.2", "0.071386"], ["84091.7", "0.000528"], ["84100.8", "0.166095"], ["84105.5", "0.023789"], ["84107", "0.005445"], ["84117.8", "0"], ["84121", "0.023784"], ["84121.1", "0"], ["84122.3", "0.04"], ["84122.4", "0.04"], ["84129.8", "2.621456"], ["84135.3", "0"], ["84143.7", "0.381311"], ["84145.5", "0"]], "u": 168071, "seq": 67577207831}, "cts": 1742584920112, "record_time": 1742584920.223179, "EXCHANGE": "BYBIT"}
{"topic": "orderbook.200.BTCUSDT", "ts": 1742584920320, "type": "delta", "data": {"s": "BTCUSDT", "b": [["84074", "0.893378"], ["84070.1", "0.031022"], ["84064.1", "0.06"], ["84062.4", "0.346447"], ["84061.5", "0"], ["84059.8", "0"], ["84059.5", "0"], ["84056.4", "0"], ["84042.9", "0"], ["84041.2", "0.026799"], ["84041.1", "0.01288"], ["84040.5", "0.356937"], ["84040.3", "0"], ["84040.2", "0"], ["84039.6", "0"], ["84039.5", "0"], ["84039.4", "0.04954"], ["84039.3", "0.04954"], ["84031.4", "0.001427"], ["84030.4", "16.097539"], ["84016.6", "0"], ["84007.9", "0.000333"], ["84007.2", "0.001333"], ["84007", "0.06"]], "a": [["84083.8", "0.071391"], ["84084.8", "0"], ["84118.5", "0.035686"], ["84129.8", "2.621571"], ["84141.6", "0.35694"], ["84143.7", "0.024382"], ["84148", "0"], ["84148.2", "0"]], "u": 168072, "seq": 67577207957}, "cts": 1742584920314, "record_time": 1742584920.423231, "EXCHANGE": "BYBIT"}
{"topic": "orderbook.200.BTCUSDT", "ts": 1742584920520, "type": "delta", "data": {"s": "BTCUSDT", "b": [["84074", "0.893225"], ["84058.1", "0"], ["84040.5", "0"], ["84037.7", "0.356946"], ["84006.9", "0.003"]], "a": [["84088.8", "0.071387"], ["84094.2", "0"], ["84118.5", "0"], ["84120.3", "0.283843"], ["84140.2", "0.356944"], ["84141.6", "0"]], "u": 168073, "seq": 67577208027}, "cts": 1742584920514, "record_time": 1742584920.623251, "EXCHANGE": "BYBIT"}
{"topic": "orderbook.200.BTCUSDT", "ts": 1742584920720, "type": "delta", "data": {"s": "BTCUSDT", "b": [["84074", "0.893031"], ["84053", "0.005947"], ["84043", "0.039629"], ["84042.9", "0.039629"], ["84042.1", "0"], ["84042", "0.051423"], ["84039.6", "0.05"], ["84039.5", "0.04954"], ["84039.4", "0"], ["84039.3", "0"], ["84037.8", "0.626359"], ["84037.7", "0"], ["84006.9", "0"]], "a": [["84090.2", "0"], ["84092.6", "0.111384"], ["84107", "0.183859"], ["84118.6", "0.038185"], ["84121", "0.075252"], ["84122", "0.108449"], ["84122.1", "0.099399"], ["84122.2", "0.04"], ["84122.3", "0"], ["84122.4", "0"], ["84123.8", "0.005452"], ["84140.2", "0.356946"], ["84148", "0.001466"], ["84148.2", "0.000358"]], "u": 168074, "seq": 67577208093}, "cts": 1742584920715, "record_time": 1742584920.822606, "EXCHANGE": "BYBIT"}
{"topic": "orderbook.200.BTCUSDT", "ts": 1742584920919, "type": "delta", "data": {"s": "BTCUSDT", "b": [["84074.3", "1.09103"], ["84074.2", "0.179144"], ["84074", "0.29231"], ["84073.9", "0"], ["84072.4", "0.023788"], ["84071.7", "0.065418"], ["84071", "0.000333"], ["84070.2", "0.120275"], ["84070.1", "0.023906"], ["84069.6", "0.178424"], ["84068.5", "0.055999"], ["84068.3", "0.071404"], ["84068.1", "0.118942"], ["84068", "0.05"], ["84067.4", "0.182942"], ["84067.3", "0"], ["84067.2", "0.00009"], ["84066.9", "0.059471"], ["84066.2", "0.178431"], ["84065.9", "0.119471"], ["84065.7", "0.26303"], ["84065.6", "0.1633"], ["84065.3", "0.092"], ["84064.6", "0.007"], ["84063.8", "0.05"], ["84063", "0"], ["84062.9", "0"], ["84062.2", "0.178942"], ["84061.6", "0.187772"], ["84061.3", "0"], ["84061.2", "0.005946"], ["84061.1", "0"], ["84060.4", "0"], ["84059.3", "0.036214"], ["84056.1", "0.178342"], ["84055.8", "0"], ["84051", "0.059471"], ["84050.3", "0.023788"], ["84049.3", "0.059471"], ["84048.3", "0.118539"], ["84046.3", "0.027179"], ["84043.1", "0.039629"], ["84042.9", "0"], ["84041.3", "0.01288"], ["84041.1", "0"], ["84040.5", "0.356941"], ["84039.6", "0"], ["84039.4", "0.04954"], ["84037.8", "0"], ["84031.4", "0"], ["84024.5", "0.000149"], ["84010.9", "0"], ["84010.3", "0"], ["84009.8", "0"], ["84009.3", "0"], ["84008.7", "0"], ["84008.5", "0"], ["84008.4", "0"], ["84007.9", "0"], ["84007.2", "0"], ["84007", "0"]], "a": [["84074.1", "0"], ["84074.4", "0.040238"], ["84074.5", "0"], ["84075.2", "0"], ["84077.2", "0"], ["84078.2", "0.004966"], ["84078.7", "0"], ["84082.5", "0.20911"], ["84083.8", "0"], ["84084.2", "0"], ["84085.6", "0.06"], ["84086.1", "0"], ["84088.8", "0"], ["84089.2", "0"], ["84092.6", "0.04"], ["84093.4", "0"], ["84093.5", "0.022733"], ["84093.6", "0.071383"], ["84094.5", "0"], ["84098.2", "0"], ["84098.6", "0.005475"], ["84102.2", "0"], ["84102.8", "0.005445"], ["84103.1", "0.118943"], ["84107", "0.005445"], ["84118.6", "0.002498"], ["84121", "0.023784"], ["84122.1", "0.059399"], ["84122.2", "0"], ["84124.2", "0.04"], ["84124.3", "0.04"], ["84128", "0.200236"], ["84129.5", "0.052935"], ["84129.8", "0.000333"], ["84140.2", "0"], ["84141.6", "0.356941"], ["84146.3", "2.621238"], ["84148.4", "0.00009"], ["84148.6", "0.000358"], ["84148.9", "0.04"], ["84149", "0.005477"], ["84149.1", "0.089207"], ["84149.8", "0.0006"], ["84150.1", "0.001333"]], "u": 168075, "seq": 67577208432}, "cts": 1742584920917, "record_time": 1742584921.02236, "EXCHANGE": "BYBIT"}
{"topic": "orderbook.200.BTCUSDT", "ts": 1742584921119, "type": "delta", "data": {"s": "BTCUSDT", "b": [["84077.4", "0.926191"], ["84077.3", "0.270551"], ["84077.2", "0.356396"], ["84076.7", "0.009063"], ["84074.3", "0.528823"], ["84074.2", "0"], ["84074", "0.12131"], ["84073.6", "0.007121"], ["84072.7", "0.055033"], ["84070.7", "0.028488"], ["84070.2", "0.138791"], ["84069.8", "0.05"], ["84069.5", "0.260447"], ["84068.3", "0"], ["84068", "0"], ["84067.9", "0.178427"], ["84067.3", "0.065417"], ["84066.9", "0.109471"], ["84066.8", "0"], ["84066.5", "0.048014"], ["84066.3", "0.533327"], ["84066", "0.051333"], ["84065.7", "0.087541"], ["84065.6", "0.2133"], ["84065.5", "0.648624"], ["84064.7", "0.273374"], ["84064.5", "0"], ["84063.8", "0"], ["84062.7", "0.059471"], ["84062.4", "0.296447"], ["84061.6", "0"], ["84061.5", "0.023264"], ["84060.9", "0.178414"], ["84060.2", "0"], ["84058.6", "0"], ["84058.1", "0.059471"], ["84055.9", "0"], ["84054.9", "0.003575"], ["84054.1", "0.118872"], ["84054", "0.000366"], ["84052.4", "0.18199"], ["84050.4", "0.023669"], ["84050.3", "0"], ["84046.4", "0.013"], ["84046.3", "0.040058"], ["84046", "0.356907"], ["84044.7", "0.049538"], ["84044.6", "0.049538"], ["84044.1", "16.097792"], ["84041.3", "0"], ["84041.2", "0.013919"], ["84040.5", "0"], ["84039.5", "0"], ["84039.4", "0"], ["84031.9", "0"], ["84030.4", "0"], ["84028.1", "0.023788"], ["84016.3", "0.000333"], ["84012.1", "0"], ["84011.8", "0"], ["84011.4", "0"]], "a": [["84074.4", "0"], ["84077.5", "0.008675"], ["84078.2", "0"], ["84080.1", "0"], ["84080.3", "0.003584"], ["84081.3", "0.004965"], ["84081.5", "0.000297"], ["84084.2", "0.019862"], ["84084.3", "0"], ["84085.6", "0"], ["84085.9", "0.065468"], ["84086.7", "0.105985"], ["84087.2", "0.062273"], ["84088.2", "0"], ["84088.4", "0.029792"], ["84089.2", "0.050328"], ["84092.5", "0.06221"], ["84093.6", "0"], ["84095.4", "0"], ["84095.9", "0.04"], ["84096.8", "0.055781"], ["84099.5", "0.071378"], ["84100.8", "0.086098"], ["84103.1", "0.170276"], ["84103.2", "0"], ["84104.7", "0.111686"], ["84105.5", "0"], ["84107.6", "0"], ["84116", "0"], ["84120.8", "0.120339"], ["84124.2", "0"], ["84124.3", "0"], ["84124.6", "0.04"], ["84124.7", "0.04"], ["84129.5", "0.001466"], ["84132.3", "0.091469"], ["84141.6", "0"], ["84144.9", "0.202188"], ["84146.3", "0"], ["84149.1", "2.799645"], ["84150.8", "0.158539"], ["84150.9", "0.000333"], ["84151.6", "0.059399"], ["84151.8", "0.000528"], ["84152.1", "0.0006"]], "u": 168076, "seq": 67577208823}, "cts": 1742584921107, "record_time": 1742584921.22253, "EXCHANGE": "BYBIT"}
{"success": true, "ret_msg": "pong", "conn_id": "db9a9825-b0cd-4231-ad46-55f33c5e50d2", "op": "ping", "record_time": 1742584921.422841, "EXCHANGE": "BYBIT"}
{"topic": "orderbook.200.BTCUSDT", "ts": 1742584921320, "type": "delta", "data": {"s": "BTCUSDT", "b": [["84064.6", "0.030547"], ["84061.5", "0"], ["84058.4", "0.124885"], ["84055.2", "0.023788"], ["84052.4", "0.178414"], ["84047.7", "0.013"], ["84047.6", "0.012879"], ["84046.4", "0"], ["84046.3", "0.027179"], ["84046", "0"], ["84045.9", "0.108936"], ["84045.8", "0.049537"], ["84044.8", "0.356912"], ["84044.7", "0"], ["84044.6", "0"], ["84044.1", "0"], ["84016.6", "16.097792"], ["84012.3", "0"]], "a": [["84077.5", "0.005702"], ["84092.1", "0.071384"], ["84092.5", "0.102436"], ["84096.6", "0"], ["84096.8", "0.091636"], ["84098.1", "0.071379"], ["84099.5", "0"], ["84100.7", "0.071377"], ["84104", "0.019584"], ["84110.2", "0.560423"], ["84115.9", "0.023784"], ["84120.4", "0.011648"], ["84124.6", "0"], ["84124.7", "0"], ["84126.6", "0.04"], ["84126.7", "0.091469"], ["84132.3", "0.04"], ["84132.5", "2.621296"], ["84144.9", "0.023781"], ["84148.8", "0.356915"], ["84149.1", "0"], ["84151.8", "0"], ["84152.1", "0"]], "u": 168077, "seq": 67577208935}, "cts": 1742584921317, "record_time": 1742584921.423349, "EXCHANGE": "BYBIT"}
{"topic": "orderbook.200.BTCUSDT", "ts": 1742584921520, "type": "delta", "data": {"s": "BTCUSDT", "b": [["84076.1", "0.0035"], ["84072.7", "0.051333"], ["84054.9", "0.007151"], ["84047.4", "0.00748"], ["84044.8", "0"], ["84044", "0"], ["84043.2", "0.356917"]], "a": [["84077.5", "0.008675"], ["84090.8", "0.071385"], ["84092.1", "0"], ["84096.4", "0.07138"], ["84100.7", "0"], ["84100.8", "0.133862"], ["84120.4", "0.005946"], ["84120.9", "0.008675"], ["84122", "0.053166"], ["84136.5", "0.349407"], ["84140.7", "0.178407"], ["84148.7", "0.356918"], ["84148.8", "0"], ["84150.9", "0"], ["84151.6", "0"]], "u": 168078, "seq": 67577208986}, "cts": 1742584921507, "record_time": 1742584921.622648, "EXCHANGE": "BYBIT"}
{"topic": "orderbook.200.BTCUSDT", "ts": 1742584921720, "type": "delta", "data": {"s": "BTCUSDT", "b": [["84077.4", "0.916813"], ["84069", "0.06"], ["84068", "0.009225"], ["84065.9", "0.059471"], ["84054.9", "0.003575"], ["84049.5", "0.04"], ["84049.4", "0.039626"], ["84043.3", "0.259871"], ["84043.1", "0"], ["84043", "0"], ["84030.4", "16.096103"], ["84016.6", "0"], ["84013.9", "0"], ["84013.1", "0"], ["84012.7", "0"]], "a": [["84077.5", "0.005464"], ["84090.8", "0"], ["84095.8", "0.071381"], ["84096.4", "0"], ["84096.8", "0.055781"], ["84098.1", "0"], ["84100.1", "0.071377"], ["84103", "0.071375"], ["84113.5", "0.04747"], ["84148.7", "0"], ["84149.1", "0.089203"], ["84150.8", "0"]], "u": 168079, "seq": 67577209250}, "cts": 1742584921714, "record_time": 1742584921.822481, "EXCHANGE": "BYBIT"}
{"topic": "orderbook.200.BTCUSDT", "ts": 1742584921920, "type": "delta", "data": {"s": "BTCUSDT", "b": [["84078.5", "0.888757"], ["84077.5", "0.251816"], ["84077.4", "0.299427"], ["84077.3", "0"], ["84075.8", "0.001"], ["84074.8", "0.007121"], ["84074.4", "0.245311"], ["84074.3", "0.357823"], ["84073.6", "0"], ["84073.3", "0.025376"], ["84073.2", "0.000528"], ["84070.2", "0.120275"], ["84069.4", "0.222171"], ["84068", "0"], ["84067.5", "0.087787"], ["84066.5", "0.042734"], ["84065.8", "0.198766"], ["84065.6", "0.1"], ["84064.7", "0.001466"], ["84056.6", "0.178407"], ["84056.1", "0.20213"], ["84055.3", "0.005075"], ["84050.4", "0.307748"], ["84049.5", "0"], ["84049.4", "0"], ["84049.3", "0.099097"], ["84049.2", "0.040959"], ["84048.2", "0"], ["84047.7", "0"], ["84047.6", "0"], ["84047.5", "0.012879"], ["84047.4", "0.020359"], ["84046", "0.356907"], ["84045.9", "0.059399"], ["84045.8", "0"], ["84045.7", "0.04987"], ["84045.6", "0.049537"], ["84043.2", "0"], ["84042.5", "0.023788"], ["84039.2", "0"], ["84016.8", "1.188231"]], "a": [["84077.5", "0"], ["84077.8", "0"], ["84081.3", "0"], ["84081.6", "0"], ["84082.3", "0.004965"], ["84082.5", "0"], ["84085.9", "0.005468"], ["84087", "0.06"], ["84087.2", "0"], ["84088", "0"], ["84089.2", "0"], ["84089.3", "0"], ["84089.6", "0"], ["84090.9", "0"], ["84091.1", "0"], ["84092.5", "0.026441"], ["84092.6", "0"], ["84092.7", "0"], ["84094.1", "0.012849"], ["84094.3", "0"], ["84094.4", "0.005475"], ["84095.8", "0"], ["84095.9", "0"], ["84096", "0"], ["84096.8", "0.088697"], ["84099", "0.071378"], ["84100.1", "0"], ["84103", "0"], ["84104.2", "0.071374"], ["84107.6", "0.071371"], ["84109.6", "0"], ["84120.9", "0.005464"], ["84126.6", "0"], ["84126.7", "0.051469"], ["84127.8", "0.04"], ["84127.9", "0.04"], ["84132.5", "0"], ["84135.3", "2.621296"], ["84150.8", "0.158539"], ["84150.9", "0.000333"], ["84151.6", "0.059399"], ["84151.8", "0.000528"], ["84152.1", "0.0006"], ["84152.2", "0.0012"], ["84152.5", "0.0006"], ["84152.6", "0.001466"], ["84153.2", "0.005184"], ["84154.2", "0.02971"], ["84154.4", "0.001333"], ["84155.1", "0.000333"], ["84156.4", "0.0012"], ["84156.5", "0.000528"], ["84156.6", "0.027459"]], "u": 168080, "seq": 67577209551}, "cts": 1742584921914, "record_time": 1742584922.022064, "EXCHANGE": "BYBIT"}
{"topic": "orderbook.200.BTCUSDT", "ts": 1742584922120, "type": "delta", "data": {"s": "BTCUSDT", "b": [["84079.3", "0.612873"], ["84078.7", "0.298155"], ["84078.5", "0.492064"], ["84077.5", "0.0024"], ["84077.4", "0.128427"], ["84076.6", "0.001"], ["84074.4", "0.246644"], ["84074", "0.122776"], ["84072.8", "0.048"], ["84072.6", "0.064"], ["84071.8", "0.00528"], ["84071", "0.092333"], ["84070.9", "0.1133"], ["84070.2", "0.525302"], ["84070.1", "0.087906"], ["84070", "0.064"], ["84069.5", "0"], ["84068.4", "0.06"], ["84068.3", "0.06"], ["84067.4", "0.118942"], ["84067", "0"], ["84066.6", "0.127503"], ["84066", "0.111333"], ["84065.8", "0.064"], ["84065.3", "0"], ["84063.4", "0.178405"], ["84060.9", "0"], ["84060.8", "0"], ["84056.1", "0.083187"], ["84046.9", "0.05"], ["84046.8", "0.049537"], ["84045.7", "0.000333"], ["84045.6", "0"], ["84043.3", "0"], ["84030.4", "0"], ["84015.8", "0"], ["84015.6", "0"], ["84014.5", "0"], ["84014.3", "0"], ["84014.2", "0"], ["84014", "0"]], "a": [["84078.6", "0"], ["84079.4", "0.003306"], ["84081.5", "0"], ["84086.6", "0.000297"], ["84086.9", "0.10032"], ["84087", "0"], ["84087.8", "0.269443"], ["84087.9", "0.172466"], ["84092.5", "0.036819"], ["84094", "0.04"], ["84094.2", "0.04"], ["84095.9", "0.04"], ["84096.7", "0.000297"], ["84096.8", "0.142609"], ["84097.5", "0.04"], ["84097.8", "0.04"], ["84097.9", "0.071379"], ["84099", "0"], ["84099.2", "0.04"], ["84099.4", "0.04"], ["84100.8", "0.173862"], ["84101", "0.04"], ["84104.2", "0"], ["84106.1", "0.071372"], ["84107.1", "0"], ["84107.6", "0"], ["84120.9", "0"], ["84134.2", "0"], ["84140.7", "0"], ["84150.7", "0.356905"], ["84153.5", "0.171"], ["84154.4", "0"], ["84155.1", "0"], ["84156.4", "0"], ["84156.5", "0"], ["84156.6", "0"]], "u": 168081, "seq": 67577209920}, "cts": 1742584922116, "record_time": 1742584922.224213, "EXCHANGE": "BYBIT"}
{"topic": "orderbook.200.BTCUSDT", "ts": 1742584922319, "type": "delta", "data": {"s": "BTCUSDT", "b": [["84071.9", "0.064"], ["84067.5", "0.023787"], ["84066.6", "0.187503"], ["84065.8", "0"], ["84065.7", "0.023541"], ["84064.6", "0.030054"], ["84064.1", "0"], ["84062.4", "0.111764"], ["84062.2", "0.118942"], ["84050.6", "0.04"], ["84050.5", "0.207734"], ["84049.3", "0.059471"], ["84049.2", "0.001333"], ["84048.8", "0.036789"], ["84048.7", "0.012879"], ["84047.5", "0"], ["84047.4", "0.00748"], ["84047", "0.05"], ["84046.9", "0.049538"], ["84046.8", "0"], ["84041.9", "0.090047"], ["84039.1", "0"], ["84034.8", "0.077792"]], "a": [["84079.4", "0.000571"], ["84087.9", "0.001466"], ["84092.5", "0.058022"], ["84093.5", "0"], ["84095.9", "0.08"], ["84097.9", "0"], ["84102.9", "0"], ["84122.4", "0.004758"], ["84123.1", "0"], ["84126.7", "0"], ["84127.3", "0.04"], ["84127.4", "0.04"], ["84127.8", "0"], ["84127.9", "0"], ["84129.5", "0.052935"], ["84132.2", "0.183875"], ["84135.3", "2.621358"], ["84150.6", "0.356906"], ["84150.7", "0"], ["84151.5", "0.353352"], ["84154.4", "0.001333"], ["84155.1", "0.000333"], ["84156.4", "0.0012"]], "u": 168082, "seq": 67577210067}, "cts": 1742584922318, "record_time": 1742584922.422239, "EXCHANGE": "BYBIT"}
{"topic": "orderbook.200.BTCUSDT", "ts": 1742584922520, "type": "delta", "data": {"s": "BTCUSDT", "b": [["84087", "0.781869"], ["84086.8", "0.164192"], ["84086.6", "0.190911"], ["84085.5", "0.356396"], ["84084.9", "0.023784"], ["84084", "0.023784"], ["84082.6", "0.005946"], ["84081.9", "0.000153"], ["84081.6", "0.255064"], ["84081.5", "0.368289"], ["84080.6", "0.051333"], ["84080.3", "0.001"], ["84080", "0.00006"], ["84079.9", "0.238998"], ["84079.4", "0.000333"], ["84079.3", "0.064779"], ["84078.7", "0"], ["84078.6", "0.057799"], ["84078.5", "0.220911"], ["84077.8", "0.000528"], ["84077.5", "0.007865"], ["84077.4", "0.109911"], ["84077.2", "0"], ["84076.2", "0.007121"], ["84075.6", "0.00009"], ["84075.3", "0.05"], ["84075.2", "0.000333"], ["84074.8", "0"], ["84074.4", "0.001333"], ["84074.3", "0.033364"], ["84074", "0.051377"], ["84073.2", "0.08501"], ["84072.4", "0.05"], ["84072.2", "0.05"], ["84071.8", "0"], ["84071.5", "0.05"], ["84071.2", "0.05"], ["84070.9", "0"], ["84070.7", "0"], ["84070.2", "0.418247"], ["84070.1", "0.183052"], ["84069.8", "0"], ["84069.6", "0"], ["84069", "0.047732"], ["84068.5", "0.178387"], ["84067.9", "0"], ["84066.9", "0.059471"], ["84066.6", "0.06"], ["84066.5", "0"], ["84066.4", "0.059399"], ["84066.2", "0"], ["84066", "0.061333"], ["84065.6", "0"], ["84065.2", "0"], ["84064.7", "0.024394"], ["84064.6", "0.007"], ["84064.4", "0"], ["84063.6", "0.003575"], ["84063.4", "0"], ["84061.4", "0.025713"], ["84060.6", "0.118924"], ["84060.4", "0.059467"], ["84059.7", "0.289935"], ["84056.7", "0.356867"], ["84056.1", "0.059399"], ["84055.2", "0"], ["84052.4", "0"], ["84052.1", "0.011898"], ["84050.6", "0"], ["84050.5", "0.168107"], ["84050.3", "0.04"], ["84050.2", "0.039627"], ["84048.9", "0.092426"], ["84048.8", "0.023789"], ["84048.7", "0"], ["84048.5", "0.013"], ["84048.4", "0.012879"], ["84047.6", "0.090031"], ["84047", "0"], ["84046.9", "0"], ["84046.7", "0.05"], ["84046.6", "0.049538"], ["84046.3", "0.001466"], ["84046.1", "0.267942"], ["84046", "0"], ["84041.9", "0"], ["84040.9", "0"], ["84040.4", "0"], ["84038.2", "0.005946"], ["84038", "0"], ["84036.5", "0.064"], ["84030.8", "0.178506"], ["84028.1", "0"], ["84026.8", "0"], ["84021.9", "0"], ["84021.3", "0"], ["84020.5", "0"], ["84020", "0"], ["84019.8", "0"], ["84018.7", "0"], ["84018.5", "0"], ["84017.7", "0"], ["84017.2", "0"], ["84017.1", "0"], ["84016.8", "0"], ["84016.5", "0"], ["84016.3", "0"], ["84016", "0"], ["84015.9", "0"]], "a": [["84079.4", "0"], ["84080", "0"], ["84080.3", "0"], ["84081.7", "0"], ["84082.3", "0"], ["84082.4", "0"], ["84082.9", "0"], ["84083.2", "0"], ["84083.6", "0"], ["84084.2", "0"], ["84085.9", "0"], ["84086.6", "0"], ["84086.7", "0"], ["84086.9", "0"], ["84087.8", "0.000333"], ["84088.4", "0"], ["84092.5", "0.001466"], ["84093.9", "0.000297"], ["84094", "0"], ["84094.2", "0"], ["84095.5", "0.061333"], ["84095.9", "0"], ["84096.8", "0.086601"], ["84097.8", "0"], ["84097.9", "0.022732"], ["84099.4", "0"], ["84100.8", "0.053764"], ["84100.9", "0.05012"], ["84101", "0"], ["84103.1", "0"], ["84104.7", "0"], ["84106.1", "0"], ["84108.2", "0"], ["84108.3", "0"], ["84108.8", "0.051687"], ["84110.1", "0"], ["84110.2", "0.00053"], ["84111", "0.001466"], ["84111.1", "0.051333"], ["84112.5", "0.071367"], ["84112.8", "0.009938"], ["84113.3", "0"], ["84117.6", "0"], ["84120.9", "0.011898"], ["84122.4", "0"], ["84123.1", "0.539264"], ["84124.3", "0.005466"], ["84125.1", "0"], ["84127.3", "0"], ["84127.4", "0"], ["84128.4", "0"], ["84129.5", "0.001466"], ["84132.1", "0.180944"], ["84132.2", "0.045472"], ["84132.5", "0.02266"], ["84135.1", "0.05147"], ["84135.3", "0"], ["84136.3", "0.020426"], ["84136.5", "0.171"], ["84144.1", "0.013787"], ["84146.1", "0"], ["84149.1", "2.621358"], ["84150.6", "0"], ["84150.8", "1.185268"], ["84156.5", "0.000528"], ["84156.6", "0.027459"], ["84156.8", "0.00009"], ["84157", "0.158539"], ["84157.3", "0.001466"], ["84157.4", "0.005184"], ["84157.5", "0.567447"], ["84158.2", "0.01872"], ["84158.6", "0.001333"], ["84159.3", "0.000333"], ["84160", "0.0012"], ["84160.4", "0.059399"], ["84161.1", "0.000528"], ["84161.7", "0.005184"], ["84161.9", "0.001466"], ["84162.8", "0.001333"], ["84163.5", "0.118872"], ["84163.6", "0.624377"], ["84164", "0.000083"], ["84164.4", "0.000333"], ["84165.2", "0.00009"], ["84165.6", "0.04"], ["84165.7", "0.000528"], ["84165.9", "0.005184"], ["84166.5", "0.001466"]], "u": 168083, "seq": 67577211538}, "cts": 1742584922517, "record_time": 1742584922.623567, "EXCHANGE": "BYBIT"}
{"topic": "orderbook.200.BTCUSDT", "ts": 1742584922720, "type": "delta", "data": {"s": "BTCUSDT", "b": [["84087", "0.806737"], ["84086.1", "0.000153"], ["84083.2", "0.007126"], ["84081.9", "0"], ["84081.6", "0.191917"], ["84080.3", "0.029508"], ["84079.9", "0.188427"], ["84079.5", "0.00528"], ["84079.3", "0.049911"], ["84079.2", "0.178403"], ["84078.7", "0.240947"], ["84078.6", "0.176099"], ["84077.4", "0.336318"], ["84077.3", "0.064"], ["84076.2", "0"], ["84076.1", "0.224674"], ["84075.7", "0.092"], ["84075.6", "0.05009"], ["84074.9", "0.128"], ["84074.4", "0.110147"], ["84073.7", "0.111686"], ["84073.4", "0.165941"], ["84073.3", "0.085376"], ["84073.2", "0.116523"], ["84072.8", "0"], ["84072.6", "0"], ["84072.2", "0"], ["84071", "0.000333"], ["84070.7", "0.06"], ["84070.3", "0.022997"], ["84069", "0"], ["84068.7", "0.004585"], ["84068.5", "0"], ["84067.4", "0.30469"], ["84066.3", "0.307975"], ["84066", "0.001333"], ["84064.7", "0.001466"], ["84062", "0.003575"], ["84060.8", "0.178387"], ["84060.6", "0"], ["84060.4", "0.350312"], ["84059.8", "0.118539"], ["84059.7", "0.171"], ["84059.4", "0.023785"], ["84056.7", "0"], ["84055.3", "0.0015"], ["84055.1", "0.014044"], ["84054.3", "0"], ["84054.2", "0.356872"], ["84052.8", "0.05"], ["84052.7", "0.04954"], ["84052.5", "0"], ["84046.7", "0"], ["84046.6", "0"], ["84046.1", "0"], ["84044", "0.089193"], ["84042.5", "0"], ["84041.2", "0"], ["84036.5", "0.064149"], ["84024.5", "0"], ["84023.4", "0"], ["84023.1", "0"], ["84022.9", "0"], ["84022.5", "0"], ["84022.3", "0"]], "a": [["84087.8", "0.002722"], ["84090.9", "0.004961"], ["84093.7", "0.000297"], ["84093.8", "0.019844"], ["84094.6", "0.10032"], ["84095.5", "0.270443"], ["84096.3", "0.106513"], ["84096.7", "0"], ["84096.8", "0.000999"], ["84097", "0.07153"], ["84097.5", "0"], ["84098", "0.029854"], ["84099.2", "0"], ["84100.8", "0.092978"], ["84101.5", "0.04"], ["84101.7", "0.041466"], ["84103.5", "0.04"], ["84103.6", "0.071374"], ["84104", "0.000358"], ["84104.7", "0.04"], ["84106.4", "0.041556"], ["84106.6", "0.138226"], ["84106.7", "0.04"], ["84107.3", "0.122461"], ["84107.8", "0.04"], ["84108.3", "0.04"], ["84108.4", "0.04"], ["84108.8", "0.000333"], ["84110.3", "0.077926"], ["84110.4", "0.111687"], ["84111", "0.072834"], ["84112.1", "0.019226"], ["84112.5", "0"], ["84113.5", "0.03207"], ["84114.3", "0.170559"], ["84114.4", "0.024385"], ["84114.9", "0.190289"], ["84121.3", "0.296151"], ["84124.3", "0"], ["84132.1", "0.140944"], ["84132.2", "0.183859"], ["84132.3", "0.08"], ["84132.4", "0.04"], ["84132.5", "0"], ["84134.1", "0.006109"], ["84135.1", "0.051466"], ["84136.5", "0.349387"], ["84138.2", "0.000333"], ["84149.1", "2.710551"], ["84150.2", "0.000145"], ["84150.8", "0.158539"], ["84156.6", "0"], ["84160", "0"], ["84160.4", "0"], ["84161.1", "0"], ["84161.7", "0"], ["84161.9", "0"], ["84162.8", "0"], ["84163.5", "0"], ["84163.6", "0"], ["84164", "0"], ["84164.4", "0"], ["84165.2", "0"], ["84165.6", "0"], ["84165.7", "0"], ["84165.9", "0"], ["84166.5", "0"]], "u": 168084, "seq": 67577211796}, "cts": 1742584922709, "record_time": 1742584922.824281, "EXCHANGE": "BYBIT"}
{"topic": "orderbook.200.BTCUSDT", "ts": 1742584922919, "type": "delta", "data": {"s": "BTCUSDT", "b": [["84086.1", "0"], ["84085.8", "0.000153"], ["84084.9", "0"], ["84078.7", "0.344146"], ["84076.7", "0.073063"], ["84074.4", "0.001333"], ["84071.9", "0"], ["84071.5", "0.11"], ["84071", "0.17872"], ["84070.3", "0.022955"], ["84070.1", "0.119052"], ["84070", "0"], ["84068.4", "0"], ["84068.3", "0"], ["84067.4", "0.118942"], ["84066.6", "0"], ["84066.3", "0.227044"], ["84065.7", "0"], ["84060.4", "0.059467"], ["84054.6", "0.013"], ["84054.5", "0.012879"], ["84054.3", "0.380755"], ["84054.2", "0"], ["84048.5", "0"], ["84048.4", "0"], ["84033.2", "16.095519"], ["84026", "0.028566"], ["84023.4", "0.023789"], ["84023.1", "0.001466"], ["84022.9", "0.09445"], ["84022.5", "0.0176"], ["84022.3", "0.000526"], ["84021.9", "0.118539"]], "a": [["84087.1", "0.005072"], ["84103", "0.071375"], ["84103.6", "0"], ["84106", "0.04"], ["84106.3", "0.113954"], ["84106.6", "0"], ["84107.3", "0"], ["84109.2", "0.07137"], ["84110.3", "0.10746"], ["84111", "0.001466"], ["84111.2", "0.076813"], ["84114.3", "0"], ["84114.9", "0.118924"], ["84120.3", "0"], ["84121.3", "0"], ["84126.5", "0"], ["84127.1", "0"], ["84128.6", "0.005072"], ["84132.3", "0"], ["84132.4", "0"], ["84132.5", "0.04"], ["84132.6", "0.158539"], ["84138.5", "0.023847"], ["84143.6", "2.621184"], ["84149.1", "0.089193"], ["84158.1", "1.02664"], ["84160", "0.0012"]], "u": 168085, "seq": 67577211915}, "cts": 1742584922915, "record_time": 1742584923.02205, "EXCHANGE": "BYBIT"}
{"topic": "orderbook.200.BTCUSDT", "ts": 1742584923119, "type": "delta", "data": {"s": "BTCUSDT", "b": [["84087", "0.811955"], ["84086.8", "0"], ["84085.8", "0"], ["84084.9", "0.023784"], ["84082.9", "0.001333"], ["84082.4", "0.000528"], ["84081.7", "0.005465"], ["84081.6", "0.186452"], ["84078", "0.023268"], ["84071.1", "0.318277"], ["84070.2", "0.120275"], ["84062.8", "0.003557"], ["84062.4", "0.210983"], ["84060.9", "0.35685"], ["84056.1", "0.099399"], ["84056", "0.627626"], ["84054.6", "0"], ["84054.5", "0"], ["84054.3", "0.036886"], ["84054.2", "0.01288"], ["84052.8", "0"], ["84052.7", "0"], ["84052.5", "0.05"], ["84052.4", "0.04954"], ["84050.3", "0"], ["84050.2", "0"], ["84049.8", "16.09151"], ["84033.2", "0"], ["84022.5", "0"], ["84022.3", "0"], ["84021.9", "0"]], "a": [["84087.1", "0.003211"], ["84097", "0"], ["84098", "0.029764"], ["84102.4", "0.024284"], ["84103", "0"], ["84103.9", "0.001333"], ["84105", "0.059399"], ["84109.2", "0"], ["84111.2", "0.005445"], ["84113.4", "0"], ["84113.5", "0.070874"], ["84114.4", "0.09575"], ["84117.5", "0.071363"], ["84126", "0"], ["84129", "1.426383"], ["84132.2", "0.005472"], ["84132.5", "0"], ["84132.6", "0.118539"], ["84133.2", "0.040556"], ["84133.3", "0.041863"], ["84135.1", "0"], ["84136.5", "0.171"], ["84138", "0.051996"], ["84160.4", "0.059399"], ["84161.1", "0.000528"], ["84161.7", "0.005184"]], "u": 168086, "seq": 67577212059}, "cts": 1742584923116, "record_time": 1742584923.242404, "EXCHANGE": "BYBIT"}
{"topic": "orderbook.200.BTCUSDT", "ts": 1742584923319, "type": "delta", "data": {"s": "BTCUSDT", "b": [["84094", "0.718926"], ["84093.8", "0.234212"], ["84091.3", "0.184644"], ["84091.2", "0.226907"], ["84090.8", "0.000153"], ["84090", "0.149911"], ["84089.8", "0.356396"], ["84087.9", "0.001466"], ["84087.8", "0.000333"], ["84087.1", "0.047076"], ["84087", "0.2186"], ["84086.6", "0.019911"], ["84086.4", "0.051333"], ["84086.2", "0.008126"], ["84085.9", "0.005467"], ["84085.5", "0"], ["84084", "0.023874"], ["84083.6", "0.000333"], ["84083.3", "0.028507"], ["84083.2", "0.001466"], ["84081.6", "0.224003"], ["84081.5", "0.011893"], ["84081.2", "0.178399"], ["84080.6", "0.1784"], ["84080.3", "0.001"], ["84079.5", "0"], ["84079.2", "0.059808"], ["84079.1", "0.042762"], ["84078.6", "0.062799"], ["84077.5", "0.005465"], ["84077.4", "0.157911"], ["84076.2", "0.059399"], ["84076.1", "0.18191"], ["84076", "0.05"], ["84075.7", "0.142"], ["84074.4", "0.253638"], ["84074.3", "0.001427"], ["84073.5", "0.178372"], ["84073.4", "0"], ["84072.7", "0.372089"], ["84072.2", "0.05665"], ["84071.5", "0.06"], ["84071.2", "0"], ["84071", "0.000333"], ["84065.6", "0.118539"], ["84065.2", "0.121669"], ["84061.4", "0"], ["84060.9", "0"], ["84060.8", "0"], ["84060.3", "0.023784"], ["84059.9", "0.356853"], ["84056.6", "0"], ["84056.1", "0.059399"], ["84056", "0.587997"], ["84055.9", "0.039629"], ["84055.8", "0.039629"], ["84055.6", "0.023784"], ["84054.3", "0.023886"], ["84054.2", "0"], ["84054", "0.026126"], ["84053.9", "0.023784"], ["84053.3", "0.090036"], ["84052.5", "0"], ["84052.4", "0"], ["84052.2", "0.099082"], ["84050", "0.017792"], ["84049.9", "4.920123"], ["84049.8", "0.023784"], ["84049.1", "0.025713"], ["84048.9", "0"], ["84047.6", "0"], ["84046.4", "0.023784"], ["84043.6", "0"], ["84040.3", "0.023784"], ["84035.9", "16.086641"], ["84034.8", "0.06"], ["84031.5", "0"], ["84031.3", "0"], ["84030.8", "0"], ["84030.2", "0"], ["84029.5", "0"], ["84028.9", "0"], ["84028.2", "0"], ["84027.8", "0"], ["84027.1", "0"], ["84027", "0"], ["84026", "0"], ["84025.7", "0"], ["84025.4", "0"], ["84025.3", "0"], ["84025.2", "0"], ["84025", "0"], ["84024.7", "0"], ["84024", "0"], ["84023.5", "0"], ["84023.4", "0"], ["84023.1", "0"], ["84022.9", "0"]], "a": [["84087.1", "0"], ["84087.8", "0"], ["84087.9", "0"], ["84090.1", "0"], ["84090.9", "0"], ["84091.3", "0"], ["84091.7", "0"], ["84092", "0"], ["84092.5", "0"], ["84093.7", "0"], ["84093.8", "0"], ["84093.9", "0"], ["84094.1", "0.017019"], ["84094.6", "0"], ["84095.5", "0.001333"], ["84096.3", "0.000528"], ["84097.1", "0.001466"], ["84097.9", "0"], ["84098", "0"], ["84098.6", "0.176475"], ["84100.8", "0.053764"], ["84100.9", "0.00053"], ["84101.6", "0.06864"], ["84102.2", "0.022684"], ["84102.5", "0.06"], ["84104.7", "0"], ["84105", "0"], ["84106.4", "0.001556"], ["84109.4", "0"], ["84110.3", "0.077926"], ["84112.1", "0.025315"], ["84113.5", "0.108842"], ["84114.2", "0.061925"], ["84114.4", "0.0006"], ["84115.4", "0.08923"], ["84115.9", "0"], ["84120.4", "0"], ["84120.9", "0"], ["84121", "0"], ["84121.2", "0.055827"], ["84121.9", "0"], ["84122", "0.211671"], ["84122.4", "0.04968"], ["84126.8", "0"], ["84127.8", "0.005946"], ["84128", "0.176452"], ["84128.2", "0.115377"], ["84128.6", "0"], ["84128.9", "0.468855"], ["84129", "0"], ["84130.1", "0.011897"], ["84132.1", "0"], ["84133.2", "0.000556"], ["84133.3", "0.001863"], ["84133.6", "0.009225"], ["84135.4", "0.638533"], ["84137", "0"], ["84137.2", "0.04"], ["84137.3", "0.045945"], ["84137.5", "0.001333"], ["84143.6", "0"], ["84149.1", "0"], ["84151.9", "2.621045"], ["84161.9", "0.001466"], ["84162.8", "0.001333"], ["84163.5", "0.118872"], ["84164", "0.000083"], ["84164.4", "0.000333"], ["84165.2", "0.00009"], ["84165.6", "0.04"], ["84165.7", "0.000528"], ["84165.9", "0.005184"], ["84166.5", "0.001466"], ["84166.9", "0.010992"], ["84167", "0.001333"], ["84167.7", "0.000349"], ["84168", "0.051333"], ["84168.2", "0.013069"], ["84169.1", "0.177938"], ["84170", "0.002841"], ["84170.1", "0.094387"]], "u": 168087, "seq": 67577213583}, "cts": 1742584923317, "record_time": 1742584923.421945, "EXCHANGE": "BYBIT"}
{"topic": "orderbook.200.BTCUSDT", "ts": 1742584923519, "type": "delta", "data": {"s": "BTCUSDT", "b": [["84097", "0.807915"], ["84096.2", "0.536225"], ["84096.1", "0.099911"], ["84095.7", "0.22357"], ["84095.4", "0.049911"], ["84094", "0.064779"], ["84092.8", "0.051333"], ["84092.5", "0.0026"], ["84092", "0.000333"], ["84091.7", "0.000528"], ["84091.3", "0.001333"], ["84091.2", "0.055907"], ["84090.8", "0"], ["84090.2", "0.007126"], ["84090.1", "0.005467"], ["84090", "0.049911"], ["84089.9", "0.109638"], ["84089.2", "0.009063"], ["84089", "0.178382"], ["84087.3", "0.028505"], ["84087.1", "0.212012"], ["84087", "0.2029"], ["84086.5", "0.00528"], ["84086.4", "0"], ["84086.2", "0.001"], ["84086.1", "0.064"], ["84085.6", "0.173245"], ["84084.2", "0.05"], ["84083.3", "0"], ["84083.1", "0.09076"], ["84083", "0.078855"], ["84081.6", "0.392789"], ["84081.5", "0.167893"], ["84081.3", "0.05"], ["84081.2", "0"], ["84081", "0.06"], ["84080.8", "0.05"], ["84080.6", "0"], ["84080.4", "0.579682"], ["84080.1", "0.05"], ["84079.9", "0.068427"], ["84079.5", "0.06"], ["84079.3", "0.109911"], ["84079.2", "0"], ["84079.1", "0"], ["84078.6", "0.181167"], ["84078.2", "0.056106"], ["84077.4", "0.097911"], ["84077.3", "0"], ["84076.7", "0"], ["84076.1", "0"], ["84076", "0"], ["84075.7", "0.092"], ["84075.6", "0.022022"], ["84075.3", "0"], ["84073.7", "0.230596"], ["84073.5", "0"], ["84073.2", "0.060528"], ["84072.4", "0"], ["84072.2", "0.003575"], ["84071.5", "0"], ["84071.2", "0.118539"], ["84070.7", "0"], ["84070.3", "0"], ["84069.5", "0.946005"], ["84069.2", "0.178372"], ["84066.8", "0.049202"], ["84065.5", "0.118942"], ["84065.2", "0"], ["84065", "0.178372"], ["84063.8", "0.0016"], ["84063.5", "0"], ["84062.8", "0"], ["84060.3", "0"], ["84059.9", "0"], ["84059.4", "0"], ["84058.9", "0.024771"], ["84058.2", "0.049544"], ["84058.1", "0.109015"], ["84056.1", "0.149413"], ["84056", "0"], ["84054.3", "0"], ["84053.3", "0"], ["84052.2", "0"], ["84052", "0.023783"], ["84050.4", "0.284259"], ["84049.9", "0.000333"], ["84049.1", "0"], ["84047.4", "0.00588"], ["84045.2", "0"], ["84035.9", "0"], ["84034", "0"], ["84033.6", "0"], ["84033.1", "0"], ["84032.9", "0"], ["84032.7", "0"], ["84032.4", "0"], ["84031.6", "0"]], "a": [["84094.1", "0"], ["84094.4", "0"], ["84095.5", "0"], ["84096.2", "0"], ["84096.3", "0"], ["84096.8", "0"], ["84097.1", "0"], ["84098.6", "0.005475"], ["84100.8", "0.006"], ["84101.5", "0"], ["84101.6", "0.10032"], ["84101.7", "0.001466"], ["84102.2", "0"], ["84102.5", "0.209055"], ["84103.3", "0.105985"], ["84103.5", "0"], ["84104.2", "0.06"], ["84106", "0"], ["84106.3", "0"], ["84106.4", "0.001466"], ["84106.7", "0"], ["84106.8", "0.022683"], ["84107.8", "0"], ["84108.3", "0"], ["84108.4", "0"], ["84108.6", "0.04"], ["84109.4", "0.054347"], ["84109.5", "0.04"], ["84110.3", "0"], ["84110.4", "0"], ["84111.1", "0"], ["84112.1", "0"], ["84112.8", "0"], ["84113.5", "0.065192"], ["84114.2", "0"], ["84114.8", "0.04062"], ["84114.9", "0"], ["84115.2", "0.04"], ["84115.3", "0.0415"], ["84115.4", "0.017448"], ["84117.5", "0.051333"], ["84119.4", "0.00053"], ["84120.8", "0.0018"], ["84121.1", "0.11891"], ["84121.2", "0"], ["84123.1", "0"], ["84123.7", "0.023782"], ["84126.2", "0.009938"], ["84127.8", "0"], ["84127.9", "0.104216"], ["84128.2", "0"], ["84128.9", "0"], ["84132.1", "0.079583"], ["84133.6", "0"], ["84135.1", "0.539264"], ["84135.7", "0"], ["84136.3", "0"], ["84137.1", "0.589132"], ["84137.2", "0"], ["84137.3", "0.005945"], ["84138", "0.00053"], ["84138.5", "0"], ["84140.2", "0.09615"], ["84142.6", "0.04053"], ["84143.1", "0.023868"], ["84143.2", "0.04"], ["84143.7", "2.37627"], ["84143.8", "0"], ["84146.9", "0"], ["84149.3", "0.051463"], ["84151.9", "0"], ["84158.1", "0"], ["84162", "0.171"], ["84170.3", "0.040358"], ["84170.4", "0.002128"], ["84170.5", "0.018099"], ["84170.7", "0.027445"], ["84171.2", "0.002799"], ["84171.9", "0.000333"], ["84172.1", "0.04"], ["84172.3", "0.04"], ["84172.9", "3.593482"], ["84173", "0.001158"], ["84173.6", "0.00009"], ["84174.2", "0.12"], ["84174.3", "0.005184"], ["84174.5", "0.04"], ["84175", "0.007671"], ["84175.2", "0.004125"], ["84175.3", "0.0015"], ["84175.4", "0.013333"]], "u": 168088, "seq": 67577214785}, "cts": 1742584923517, "record_time": 1742584923.62317, "EXCHANGE": "BYBIT"}
{"topic": "orderbook.200.BTCUSDT", "ts": 1742584923719, "type": "delta", "data": {"s": "BTCUSDT", "b": [["84105", "0.828249"], ["84104", "0.000153"], ["84102.8", "0.005468"], ["84102.7", "0.22204"], ["84102.5", "0.356396"], ["84101.7", "0.001466"], ["84100.9", "0.000528"], ["84100.4", "0.000333"], ["84100", "0.051393"], ["84099.9", "0.169911"], ["84099.7", "0.001333"], ["84098.9", "0.007125"], ["84098.6", "0.005468"], ["84098.5", "0.161801"], ["84098.4", "0.356396"], ["84097.5", "0.01056"], ["84097.2", "0.007"], ["84097.1", "0.005266"], ["84097", "0.227876"], ["84096.7", "0.178366"], ["84096.6", "0.247555"], ["84096.3", "0.000528"], ["84096.2", "0.000333"], ["84096.1", "0.22253"], ["84096", "0.028502"], ["84095.7", "0.171999"], ["84095.5", "0.001333"], ["84095", "0.17837"], ["84094.4", "0.005468"], ["84094.1", "0.0019"], ["84094", "0.049911"], ["84093.8", "0"], ["84092.8", "0"], ["84092.5", "0.004066"], ["84092.4", "0.00009"], ["84092.3", "0.003403"], ["84091.8", "0.042755"], ["84091.6", "0.018516"], ["84091.3", "0.084335"], ["84090.2", "0.17838"], ["84089.9", "0"], ["84089.8", "0.064"], ["84089", "0"], ["84088", "0.064"], ["84087.3", "0.221619"], ["84087.2", "0.165752"], ["84087.1", "0.007806"], ["84087", "0.201"], ["84086.5", "0.056099"], ["84086.1", "0.069945"], ["84085.6", "0.06"], ["84085.2", "0.059399"], ["84085.1", "0.58919"], ["84084.2", "0"], ["84083.2", "0.120365"], ["84083.1", "0.048"], ["84083", "0"], ["84082.9", "0.027046"], ["84081.8", "0.178348"], ["84081.5", "0.156"], ["84081.3", "0"], ["84081.1", "0.06"], ["84080.8", "0"], ["84080.7", "0.003575"], ["84080.4", "0.529682"], ["84080.1", "0"], ["84079.9", "0.049911"], ["84079.8", "0.064"], ["84078.8", "0.118539"], ["84078.7", "0.240947"], ["84078.6", "0.002799"], ["84078.2", "0"], ["84078.1", "0.311716"], ["84077.6", "0.178348"], ["84077.4", "0.049911"], ["84076.3", "0.356787"], ["84075.7", "0"], ["84075.6", "0.00009"], ["84074.9", "0.064"], ["84073.7", "0"], ["84073.3", "0.025376"], ["84073.2", "0.000528"], ["84073", "0.011895"], ["84071.2", "0.142319"], ["84071.1", "0.537402"], ["84070.3", "0.023782"], ["84070.2", "0.210289"], ["84069.5", "0"], ["84069.2", "0"], ["84068.7", "0"], ["84068.1", "0.402961"], ["84066.8", "0.023489"], ["84066.5", "0.166666"], ["84066.3", "0"], ["84065", "0.139177"], ["84064.9", "0.054874"], ["84064.6", "0"], ["84063.3", "0.02378"], ["84061.2", "0"], ["84058.9", "0"], ["84058.2", "0"], ["84058.1", "0.059471"], ["84057.6", "0.001333"], ["84057.2", "0.02378"], ["84056.1", "0.059399"], ["84055.1", "0.005945"], ["84054.9", "0"], ["84054.7", "3.533085"], ["84052.1", "0"], ["84051.4", "0.178462"], ["84050.4", "0.00018"], ["84048.2", "0.000149"], ["84045.5", "0"], ["84045", "0"], ["84044", "0"], ["84043.9", "0"], ["84042.8", "0"], ["84042.7", "0"], ["84042", "0"], ["84041.6", "0"], ["84041.5", "0"], ["84040.8", "0"], ["84040.3", "0"], ["84040", "0"], ["84039.7", "0"], ["84038.7", "0"], ["84038.2", "0"], ["84037.6", "0"], ["84037.4", "0"], ["84037.3", "0"], ["84037", "0"], ["84036.6", "0"], ["84036.5", "0"], ["84036.2", "0"], ["84035.8", "0"], ["84035.5", "0"], ["84035.3", "0"], ["84034.8", "0"], ["84034.2", "0"]], "a": [["84098.6", "0"], ["84099.7", "0"], ["84100", "0"], ["84100.4", "0"], ["84100.8", "0"], ["84100.9", "0"], ["84101.6", "0"], ["84101.7", "0"], ["84102.4", "0"], ["84102.5", "0"], ["84102.8", "0"], ["84103.3", "0"], ["84103.9", "0"], ["84104", "0"], ["84104.2", "0"], ["84104.6", "0"], ["84105.1", "0.009582"], ["84105.6", "0"], ["84106.4", "0"], ["84106.8", "0"], ["84107", "0"], ["84108.6", "0"], ["84108.9", "0.00018"], ["84109.4", "0"], ["84109.5", "0"], ["84112.6", "0.09276"], ["84112.7", "0.022683"], ["84113.5", "0.06"], ["84113.6", "0"], ["84114.3", "0.04235"], ["84114.8", "0.00062"], ["84115.2", "0"], ["84115.3", "0.0015"], ["84117.5", "0"], ["84118.3", "0.055576"], ["84118.6", "0"], ["84120.4", "0.04"], ["84120.8", "0.0424"], ["84121.1", "0"], ["84121.9", "0.071359"], ["84122", "0.053166"], ["84122.2", "0.115087"], ["84122.7", "0.012508"], ["84123", "0"], ["84123.7", "0.019226"], ["84125.9", "0"], ["84127.9", "0"], ["84129.6", "0.051333"], ["84130.1", "0"], ["84130.3", "0"], ["84130.6", "0.071351"], ["84132", "0.170375"], ["84132.2", "0.18382"], ["84132.8", "0.059399"], ["84134.1", "0.001466"], ["84136.5", "0.349348"], ["84137.9", "0"], ["84138.8", "0.001466"], ["84140.1", "0.111957"], ["84140.2", "0.025038"], ["84140.3", "0.130434"], ["84141.1", "0.284561"], ["84142.6", "0.00053"], ["84143.1", "0.02378"], ["84143.2", "0"], ["84143.6", "0.112179"], ["84143.7", "0.0006"], ["84144.1", "0"], ["84144.5", "0.005945"], ["84144.6", "0.035675"], ["84148.2", "0.024138"], ["84148.4", "0.283838"], ["84149.1", "0.02378"], ["84149.2", "0.063724"], ["84149.3", "0"], ["84149.4", "0.04"], ["84149.5", "0.04"], ["84149.9", "0.020426"], ["84150.2", "0"], ["84151.9", "0.004582"], ["84154", "0.02378"], ["84157.5", "0"], ["84160.6", "0.051463"], ["84161.9", "0.001611"], ["84162.9", "0.00214"], ["84166.8", "0.000669"], ["84166.9", "0"], ["84170.1", "0.005184"], ["84170.5", "0.189099"], ["84170.7", "0"], ["84175.8", "0.120005"], ["84175.9", "1.026423"], ["84176.1", "0.040333"], ["84176.2", "0.12"], ["84176.3", "0.04"], ["84177.1", "3.925682"], ["84177.8", "0.246684"], ["84178.3", "0.059399"], ["84178.5", "0.005184"], ["84179.6", "0.001861"], ["84180.3", "0.000333"], ["84180.4", "0.001466"], ["84181.1", "0.118539"], ["84182", "0.00018"], ["84182.3", "0.003"], ["84182.7", "0.005184"], ["84183.8", "0.001333"]], "u": 168089, "seq": 67577216475}, "cts": 1742584923717, "record_time": 1742584923.823503, "EXCHANGE": "BYBIT"}
{"topic": "orderbook.200.BTCUSDT", "ts": 1742584923919, "type": "delta", "data": {"s": "BTCUSDT", "b": [["84107.1", "0.15"], ["84105", "0.945922"], ["84104", "0"], ["84102.4", "0.009063"], ["84101.2", "0.007125"], ["84098.9", "0"], ["84098.6", "0.359536"], ["84098.2", "0.028501"], ["84097.5", "0.01584"], ["84097.2", "0"], ["84097.1", "0.068758"], ["84097", "0.109911"], ["84096.6", "0.322245"], ["84096.1", "0.28767"], ["84096", "0"], ["84094.4", "0.183839"], ["84094", "0.092665"], ["84093", "0.05"], ["84092.7", "0.05"], ["84092.5", "0.063515"], ["84092", "0.112019"], ["84091.8", "0"], ["84091.5", "0.048"], ["84091.4", "0.064"], ["84091.3", "0.153281"], ["84090.2", "0"], ["84089.8", "0.206"], ["84089.2", "0"], ["84088.9", "0.05"], ["84088.7", "0.05"], ["84087.9", "0.023315"], ["84087.3", "0.354924"], ["84087.2", "0"], ["84086.4", "0.06"], ["84086.3", "0.06"], ["84085.9", "0.010163"], ["84084.8", "0.06"], ["84084.6", "0.06"], ["84083.1", "0"], ["84082.6", "0"], ["84081.5", "0"], ["84079.5", "0"], ["84079.4", "0.125177"], ["84079.3", "0.049911"], ["84078.7", "0.333248"], ["84078.1", "0"], ["84076.3", "0"], ["84075", "0.356784"], ["84074.9", "0"], ["84074.4", "0.001333"], ["84073.4", "0.143664"], ["84072.9", "0.0141"], ["84071.1", "0.318277"], ["84070.2", "0.210641"], ["84067.3", "0"], ["84065", "0.089177"], ["84064.9", "0.005327"], ["84064.3", "0.05"], ["84064.2", "0.049548"], ["84062.7", "0"], ["84062.4", "0.111764"], ["84051.5", "0.04839"], ["84051.2", "0.360417"], ["84045.9", "0"], ["84045.7", "0"]], "a": [["84105.1", "0"], ["84107.2", "0.001257"], ["84108.9", "0.00514"], ["84109.5", "0.0003"], ["84111.9", "0.01984"], ["84114.3", "0.105985"], ["84114.8", "0.00053"], ["84116.1", "0.029759"], ["84119.1", "0.04"], ["84119.8", "0.04"], ["84121.6", "0.04"], ["84121.9", "0"], ["84122.2", "0"], ["84122.3", "0.071359"], ["84122.5", "0.04"], ["84124.2", "0.04"], ["84124.8", "0.04"], ["84126.2", "0"], ["84126.3", "0.04"], ["84126.5", "0.04"], ["84129.6", "0"], ["84130.6", "0"], ["84130.8", "0"], ["84132", "0"], ["84132.3", "0.051333"], ["84132.6", "0.07135"], ["84135", "0.118539"], ["84135.2", "0.111686"], ["84135.3", "0.071347"], ["84135.7", "0.009938"], ["84141.1", "0"], ["84142.8", "0"], ["84144.6", "0"], ["84148.9", "0"], ["84149.4", "0"], ["84149.5", "0"], ["84151", "0.04"], ["84151.1", "0.04"], ["84164.5", "0.013894"], ["84179", "0.171"], ["84179.6", "0"], ["84180.3", "0"], ["84180.4", "0"], ["84181.1", "0"], ["84182", "0"], ["84182.3", "0"], ["84182.7", "0"], ["84183.8", "0"]], "u": 168090, "seq": 67577216765}, "cts": 1742584923917, "record_time": 1742584924.022117, "EXCHANGE": "BYBIT"}
{"topic": "orderbook.200.BTCUSDT", "ts": 1742584924120, "type": "delta", "data": {"s": "BTCUSDT", "b": [["84110.9", "0.527264"], ["84107.3", "0.137039"], ["84107.1", "0.320911"], ["84105.6", "0.000528"], ["84105", "0.220911"], ["84104.6", "0.000333"], ["84103.9", "0.001333"], ["84103.4", "0.01584"], ["84103.3", "0.035623"], ["84102.8", "0.131043"], ["84102.7", "0.05104"], ["84102.5", "0.678641"], ["84101.2", "0"], ["84100.8", "0.00009"], ["84100", "0.29879"], ["84099.6", "0.008"], ["84099.5", "0.17836"], ["84099.1", "0.042751"], ["84098.6", "0.005468"], ["84098.5", "0.061801"], ["84098.4", "0"], ["84098.2", "0"], ["84097.8", "0.178364"], ["84097.5", "0"], ["84096.7", "0"], ["84096.6", "0"], ["84096.1", "0.049911"], ["84095.8", "0.156749"], ["84095.5", "0.051333"], ["84095", "0"], ["84094.4", "0.233839"], ["84094", "0.049911"], ["84093", "0"], ["84092.7", "0"], ["84092.3", "0"], ["84092.2", "0.05"], ["84091.2", "0.228247"], ["84090.4", "0.021977"], ["84089.8", "0.156"], ["84088.9", "0"], ["84088.7", "0"], ["84087.9", "0.001466"], ["84082.9", "0.001333"], ["84081.6", "0.051695"], ["84081.1", "0"], ["84081", "0"], ["84079.8", "0"], ["84078.7", "0.092301"], ["84078", "0"], ["84075.1", "0.271171"], ["84075", "0"], ["84073.4", "0"], ["84072.8", "0.356798"], ["84072.1", "0.02378"], ["84070.9", "0.025713"], ["84070.2", "0.210647"], ["84062.6", "0.023681"], ["84052.5", "15.88277"], ["84047.4", "0"], ["84046.4", "0"], ["84046.3", "0"]], "a": [["84107.2", "0"], ["84108.1", "0"], ["84108.8", "0"], ["84108.9", "0"], ["84109.5", "0"], ["84110.2", "0"], ["84111", "0.004976"], ["84111.9", "0"], ["84112.6", "0"], ["84113.5", "0"], ["84114.3", "0"], ["84116.1", "0"], ["84117.8", "0.019839"], ["84118.3", "0.107879"], ["84118.5", "0.0792"], ["84119.4", "0.06053"], ["84120.2", "0.096891"], ["84120.4", "0"], ["84122", "0.125524"], ["84122.3", "0"], ["84126.4", "0.078948"], ["84128.3", "0.02378"], ["84130.5", "0.022908"], ["84131.6", "0.118981"], ["84131.7", "0.071951"], ["84132.1", "0.113088"], ["84132.2", "0.005472"], ["84132.6", "0"], ["84134", "0.000333"], ["84135.2", "0"], ["84135.3", "0"], ["84136.5", "0.171"], ["84136.8", "1.895925"], ["84140.1", "0"], ["84146", "0.005445"], ["84149.2", "0.072949"], ["84151", "0"], ["84151.1", "0"], ["84151.4", "0.19592"], ["84152.4", "0.04"], ["84152.5", "0.0406"], ["84153.1", "0.024035"], ["84157.8", "0.051456"], ["84160.6", "0"], ["84172", "0.356797"], ["84179.5", "2.620772"], ["84179.6", "0.001861"], ["84180.3", "0.000333"], ["84180.4", "0.001466"], ["84181.1", "0.118539"], ["84182", "0.00018"], ["84182.3", "0.003"], ["84182.7", "0.005184"], ["84183.8", "0.001333"]], "u": 168091, "seq": 67577217297}, "cts": 1742584924117, "record_time": 1742584924.22321, "EXCHANGE": "BYBIT"}
{"topic": "orderbook.200.BTCUSDT", "ts": 1742584924319, "type": "delta", "data": {"s": "BTCUSDT", "b": [["84110.9", "0.375865"], ["84107.7", "0.000153"], ["84107.1", "0.328035"], ["84103.3", "0.028499"], ["84102.5", "0.382245"], ["84097.7", "0.109293"], ["84095.5", "0.001333"], ["84095.4", "0.099911"], ["84095", "0.05"], ["84094.4", "0.183839"], ["84093", "0.009225"], ["84090.7", "0.185318"], ["84090.4", "0.021834"], ["84086", "0.178336"], ["84085.6", "0"], ["84083.7", "0.310296"], ["84077.6", "0"], ["84074.1", "0.356796"], ["84072.8", "0"], ["84070.3", "0"], ["84067.8", "0.05"], ["84067.7", "0.04955"], ["84067.2", "0.031588"], ["84064.3", "0"], ["84064.2", "0"], ["84055.2", "15.88277"], ["84052.5", "0"], ["84052", "0"], ["84048.3", "0"], ["84048.2", "0"], ["84048.1", "0"]], "a": [["84114.8", "0.005489"], ["84118.3", "0.159729"], ["84118.5", "0.08976"], ["84119", "0.071361"], ["84120.2", "0.107451"], ["84122.7", "0.0012"], ["84124.8", "0.08"], ["84128", "0.247806"], ["84130.5", "0"], ["84130.6", "0.124407"], ["84132.1", "0.033505"], ["84132.2", "0.183808"], ["84136.5", "0.349336"], ["84137.6", "0.177894"], ["84144.6", "0.274615"], ["84146", "0"], ["84146.7", "0.005445"], ["84168.5", "2.620772"], ["84172", "0"], ["84172.8", "0.356796"], ["84179.5", "0"], ["84182.3", "0"], ["84182.7", "0"], ["84183.8", "0"]], "u": 168092, "seq": 67577217471}, "cts": 1742584924302, "record_time": 1742584924.422, "EXCHANGE": "BYBIT"}
{"topic": "orderbook.200.BTCUSDT", "ts": 1742584924520, "type": "delta", "data": {"s": "BTCUSDT", "b": [["84110.9", "0.374863"], ["84107.7", "0"], ["84094", "0.050574"], ["84091.6", "0.246549"], ["84091.3", "0.001333"], ["84090.8", "0.064"], ["84090.4", "0"], ["84090.3", "0.021834"], ["84074.1", "0.356791"], ["84070.2", "0.210622"], ["84067.9", "0.05"], ["84067.8", "0.04955"], ["84067.7", "0"], ["84063.6", "15.886345"], ["84055.2", "0"], ["84048.3", "0.118539"]], "a": [["84130.5", "0.184409"], ["84132.1", "0"], ["84168.5", "2.620922"], ["84172.8", "0"], ["84177", "0.356794"]], "u": 168093, "seq": 67577217586}, "cts": 1742584924516, "record_time": 1742584924.621893, "EXCHANGE": "BYBIT"}
{"topic": "orderbook.200.BTCUSDT", "ts": 1742584924720, "type": "delta", "data": {"s": "BTCUSDT", "b": [["84110.9", "0.545863"], ["84108.7", "0.000153"], ["84101.7", "0.120707"], ["84097.7", "0"], ["84096.7", "0.048"], ["84096.6", "0.064"], ["84095.8", "0.216922"], ["84095.1", "0.092"], ["84095", "0.114"], ["84092.1", "0.056093"], ["84091.9", "0.17675"], ["84091.6", "0.306549"], ["84091.4", "0"], ["84090.7", "0"], ["84090", "0.109911"], ["84089.9", "0.06"], ["84089.8", "0.092"], ["84086.5", "0"], ["84086.1", "0.005945"], ["84085.3", "0.118539"], ["84084.8", "0"], ["84084.6", "0"], ["84083.8", "0.375777"], ["84083.7", "0"], ["84082.8", "0.297432"], ["84076", "0.283993"], ["84075.2", "0.357121"], ["84074.1", "0"], ["84072.1", "0"], ["84071.2", "0.118539"], ["84070.2", "0.210608"], ["84069.9", "0.049548"], ["84069.8", "0.049548"], ["84068.1", "0.118942"], ["84067.9", "0"], ["84067.8", "0"], ["84066.3", "15.88277"], ["84065.6", "0.136331"], ["84063.6", "0.003575"], ["84062.6", "0"], ["84060", "0.000178"], ["84054", "0.049758"], ["84050", "0"], ["84048.3", "0"]], "a": [["84112.7", "0"], ["84118.4", "0.193681"], ["84119", "0"], ["84122", "0.082923"], ["84122.1", "0"], ["84126.4", "0.132183"], ["84126.9", "0.116766"], ["84128", "0.176452"], ["84128.3", "0"], ["84129", "0.071353"], ["84130.2", "0.023368"], ["84130.6", "0"], ["84132.2", "0.005472"], ["84136.5", "0.171"], ["84136.7", "0.182657"], ["84137.6", "0"], ["84144.6", "0"], ["84145", "0.171118"], ["84145.8", "0.285834"], ["84146.7", "0"], ["84147.6", "0.005445"], ["84148.3", "0.151173"], ["84148.4", "0.00009"], ["84149.2", "0.009225"], ["84149.9", "0"], ["84157.5", "0.178336"], ["84161.4", "0.020426"], ["84161.7", "0.18352"], ["84177", "0"], ["84178.9", "0.356787"], ["84182.3", "0.003"]], "u": 168094, "seq": 67577217786}, "cts": 1742584924717, "record_time": 1742584924.823343, "EXCHANGE": "BYBIT"}
{"topic": "orderbook.200.BTCUSDT", "ts": 1742584924920, "type": "delta", "data": {"s": "BTCUSDT", "b": [["84110.9", "0.374863"], ["84101.7", "0.001466"], ["84101.6", "0.120789"], ["84097.6", "0.023603"], ["84093.3", "0.064"], ["84091.9", "0"], ["84091.8", "0.183643"], ["84091.7", "0.060528"], ["84091.5", "0"], ["84089.8", "0"], ["84086.4", "0"], ["84086.3", "0"], ["84082.8", "0"], ["84082.7", "0.280585"], ["84078.7", "0.175991"], ["84075.3", "0.271272"], ["84075.2", "0.357117"], ["84075.1", "0"], ["84071.6", "0.012882"], ["84071.5", "0.012882"], ["84069.9", "0"], ["84069.7", "0.049548"], ["84069", "14.605753"], ["84066.3", "0"], ["84054", "0.023998"], ["84048.8", "0"]], "a": [["84115.5", "0.023625"], ["84123.7", "0"], ["84126.8", "0.12392"], ["84126.9", "0.001142"], ["84130.5", "0.093586"], ["84131.6", "0.137055"], ["84136.6", "0.178327"], ["84136.7", "0"], ["84145.7", "0.300842"], ["84145.8", "0"], ["84148.3", "0"], ["84156.9", "0.12461"], ["84168.5", "2.621141"], ["84178.9", "0"], ["84181", "0.356784"], ["84182.3", "0"]], "u": 168095, "seq": 67577217907}, "cts": 1742584924914, "record_time": 1742584925.022496, "EXCHANGE": "BYBIT"}
{"topic": "orderbook.200.BTCUSDT", "ts": 1742584925120, "type": "delta", "data": {"s": "BTCUSDT", "b": [["84108.7", "0"], ["84107.1", "0.157035"], ["84101.6", "0"], ["84099.6", "0"], ["84097.6", "0"], ["84096.8", "0.023506"], ["84092.1", "0.333742"], ["84091.8", "0"], ["84091.6", "0.078516"], ["84090.4", "0.021985"], ["84090.3", "0"], ["84088.7", "0.005445"], ["84088", "0"], ["84085.3", "0"], ["84082.7", "0"], ["84079.4", "0.125357"], ["84075.2", "0.000333"], ["84073.6", "0.04"], ["84073.5", "0.039635"], ["84071.8", "0.369796"], ["84071.7", "0.0783"], ["84071.6", "0"], ["84071.5", "0"], ["84070.2", "0.21062"], ["84069.9", "0.049548"], ["84069.7", "0"], ["84069", "0"], ["84060.8", "14.605753"], ["84059.3", "0.000528"], ["84055.9", "0"], ["84055.8", "0"], ["84048.8", "0.023789"], ["84048.3", "0.118539"], ["84048.2", "0.000149"], ["84048.1", "0.005682"], ["84047.4", "0.00588"], ["84046.4", "0.023784"], ["84046.3", "0.001466"]], "a": [["84118.2", "0.071362"], ["84121.5", "0.059399"], ["84126.8", "0"], ["84126.9", "0.072497"], ["84131.7", "0.0006"], ["84136.6", "0"], ["84143.6", "0.178957"], ["84145.7", "0"], ["84149.1", "0.112948"], ["84151.7", "0.04"], ["84151.8", "0.040528"], ["84152.4", "0"], ["84152.5", "0.0006"], ["84157.5", "0"], ["84161.7", "0.005184"], ["84170.1", "0.094352"], ["84174.4", "0.3568"], ["84181", "0"], ["84182.3", "0.003"], ["84182.7", "0.005184"]], "u": 168096, "seq": 67577218012}, "cts": 1742584925117, "record_time": 1742584925.222002, "EXCHANGE": "BYBIT"}
{"topic": "orderbook.200.BTCUSDT", "ts": 1742584925319, "type": "delta", "data": {"s": "BTCUSDT", "b": [["84071.8", "0.369682"], ["84070", "0.05"], ["84069.8", "0"]], "a": [["84115.3", "0.014762"], ["84132.2", "0.183808"], ["84136.5", "0.349336"], ["84142.8", "0.051333"], ["84143.6", "0.112179"], ["84153", "1.425975"], ["84156.9", "0"], ["84174.1", "0.356801"], ["84174.4", "0"], ["84182.7", "0"]], "u": 168097, "seq": 67577218058}, "cts": 1742584925313, "record_time": 1742584925.421956, "EXCHANGE": "BYBIT"}
{"topic": "orderbook.200.BTCUSDT", "ts": 1742584925520, "type": "delta", "data": {"s": "BTCUSDT", "b": [["84109.6", "0.0017"], ["84107.1", "0.127035"], ["84092.5", "0.060915"], ["84080.9", "0.0016"], ["84072.8", "0.356799"], ["84071.8", "0.012881"], ["84063.8", "0"], ["84046.4", "0"], ["84046.3", "0"]], "a": [["84121.5", "0"], ["84151.4", "0.630433"], ["84151.5", "0.393352"], ["84151.6", "0.099399"], ["84151.7", "0"], ["84151.8", "0.000528"], ["84174.1", "0"], ["84175.7", "0.356795"], ["84182.7", "0.005184"], ["84183.8", "0.001333"]], "u": 168098, "seq": 67577218164}, "cts": 1742584925515, "record_time": 1742584925.622602, "EXCHANGE": "BYBIT"}
{"topic": "orderbook.200.BTCUSDT", "ts": 1742584925719, "type": "delta", "data": {"s": "BTCUSDT", "b": [["84110.9", "0.375101"], ["84106.4", "0.001466"], ["84101.9", "0.122314"], ["84095.4", "0.049911"], ["84095", "0.064"], ["84094.1", "0"], ["84092.2", "0"], ["84091.4", "0.183653"], ["84090.4", "0"], ["84084.4", "0.275718"], ["84074.1", "0.356791"], ["84073.6", "0"], ["84073.5", "0"], ["84073.4", "0.039635"], ["84073.3", "0.065011"], ["84072.8", "0"], ["84071.8", "0"], ["84071.7", "0.065418"], ["84071.6", "0.012882"], ["84071.5", "0.012882"], ["84070.1", "0.169052"], ["84070", "0.049548"], ["84069.9", "0"]], "a": [["84111", "0.00321"], ["84115.3", "0.0015"], ["84118.2", "0"], ["84120", "0.0716"], ["84126.4", "0.256882"], ["84126.9", "0.001142"], ["84132.2", "0.005472"], ["84132.8", "0.130749"], ["84136.5", "0.171"], ["84136.9", "0.173582"], ["84143.9", "0.276383"], ["84149", "0.09037"], ["84149.1", "0.02378"], ["84151.5", "0.353352"], ["84151.6", "0.059399"], ["84152.1", "0.0406"], ["84152.2", "0.0412"], ["84175.7", "0"], ["84178.2", "0.356791"], ["84183.8", "0"]], "u": 168099, "seq": 67577218289}, "cts": 1742584925708, "record_time": 1742584925.822092, "EXCHANGE": "BYBIT"}
{"topic": "orderbook.200.BTCUSDT", "ts": 1742584925920, "type": "delta", "data": {"s": "BTCUSDT", "b": [["84110.9", "0.546101"], ["84110.4", "0.006207"], ["84097.1", "0.066858"], ["84095.4", "0.099911"], ["84095", "0.114"], ["84092.2", "0.05"], ["84090.4", "0.022009"], ["84084.5", "0.118539"], ["84075.8", "0"], ["84074.1", "0"], ["84073.5", "0.356792"], ["84071.8", "0.013"], ["84071.7", "0.0783"], ["84071.6", "0"], ["84071.5", "0"], ["84070.2", "0.210612"], ["84070.1", "0.119052"], ["84070", "0.05"], ["84069.9", "0.049548"], ["84063.5", "13.872482"], ["84060.8", "0"], ["84048.2", "0"], ["84048.1", "0"], ["84047.4", "0"]], "a": [["84111", "0.00351"], ["84120", "0.00024"], ["84120.6", "0.07136"], ["84126.3", "0.125958"], ["84126.4", "0.124699"], ["84129", "0"], ["84130.5", "0.164938"], ["84131.5", "0.006083"], ["84132.8", "0.059399"], ["84134.6", "0.071348"], ["84140.2", "0.099719"], ["84143.6", "0.17162"], ["84149", "0.005477"], ["84151.9", "0.044582"], ["84152", "0.04"], ["84152.1", "0.0006"], ["84152.2", "0.0012"], ["84171.4", "0.00046"], ["84178.1", "0.356793"], ["84178.2", "0"], ["84181.1", "0"], ["84182", "0"], ["84182.3", "0"], ["84182.7", "0"]], "u": 168100, "seq": 67577218440}, "cts": 1742584925917, "record_time": 1742584926.023243, "EXCHANGE": "BYBIT"}
{"topic": "orderbook.200.BTCUSDT", "ts": 1742584926120, "type": "delta", "data": {"s": "BTCUSDT", "b": [["84110.9", "0.447269"], ["84104.6", "0.071706"], ["84101.9", "0"], ["84091.4", "0"], ["84084.4", "0"], ["84076.6", "0"], ["84073.6", "0.039635"], ["84073.5", "0.039635"], ["84073.4", "0"], ["84073.3", "0.025376"], ["84072.8", "0.356795"], ["84071.8", "0.012881"], ["84070.2", "0.210617"], ["84070", "0.049548"], ["84063.5", "0"], ["84060.8", "13.872482"], ["84048.2", "0.000149"], ["84048.1", "0.005682"], ["84047.4", "0.00588"]], "a": [["84116.7", "0.071363"], ["84120.6", "0"], ["84126.4", "0"], ["84128", "0.247806"], ["84134.6", "0"], ["84135", "1.136995"], ["84135.4", "0.0024"], ["84136.9", "0"], ["84143.9", "0"], ["84149.1", "0.112948"], ["84151.6", "0.099399"], ["84151.7", "0.04"], ["84151.9", "0.004582"], ["84152", "0"], ["84157.5", "0.178336"], ["84161.7", "0.18352"], ["84175.7", "0.356795"], ["84178.1", "0"], ["84181.1", "0.118539"], ["84182", "0.00018"], ["84182.3", "0.003"]], "u": 168101, "seq": 67577218532}, "cts": 1742584926115, "record_time": 1742584926.22322, "EXCHANGE": "BYBIT"}
{"topic": "orderbook.200.BTCUSDT", "ts": 1742584926320, "type": "delta", "data": {"s": "BTCUSDT", "b": [["84099.5", "0.249738"], ["84096.7", "0.10831"], ["84089.7", "0.059388"], ["84082.7", "0.115033"], ["84073.6", "0"], ["84073.4", "0.039635"], ["84072.8", "0"], ["84071.8", "0.3568"], ["84071.6", "0.012882"], ["84070", "0.05"], ["84048.1", "0"], ["84047.4", "0"]], "a": [["84115.3", "0.014762"], ["84116.7", "0"], ["84118.3", "0.231091"], ["84131.7", "0.058799"], ["84132.2", "0.183808"], ["84136.5", "0.349336"], ["84138.7", "0.057959"], ["84143.6", "0.112179"], ["84145.7", "0.121448"], ["84151.6", "0.059399"], ["84151.7", "0"], ["84152", "0.04"], ["84152.1", "0.0406"], ["84157.5", "0"], ["84161.7", "0.005184"], ["84175.6", "0.356801"], ["84175.7", "0"]], "u": 168102, "seq": 67577218630}, "cts": 1742584926312, "record_time": 1742584926.422545, "EXCHANGE": "BYBIT"}
{"topic": "orderbook.200.BTCUSDT", "ts": 1742584926520, "type": "delta", "data": {"s": "BTCUSDT", "b": [["84096.7", "0.048"], ["84089.7", "0"], ["84082.7", "0"], ["84080.3", "0"], ["84072.8", "0.356796"], ["84071.8", "0"], ["84070", "0"], ["84069.8", "0.049548"], ["84048.1", "0.005682"], ["84047.4", "0.00588"], ["84046.4", "0.023784"]], "a": [["84115.3", "0.0015"], ["84115.4", "0.046884"], ["84117.3", "0.071363"], ["84118.3", "0.159729"], ["84130.5", "0.210042"], ["84131.7", "0.0006"], ["84138.7", "0"], ["84145.7", "0"], ["84151.8", "0.040528"], ["84151.9", "0.044582"], ["84152", "0"], ["84152.1", "0.0006"], ["84175.6", "0"], ["84175.7", "0.356796"], ["84182.7", "0.005184"], ["84183.8", "0.001333"]], "u": 168103, "seq": 67577218715}, "cts": 1742584926511, "record_time": 1742584926.622075, "EXCHANGE": "BYBIT"}
{"topic": "orderbook.200.BTCUSDT", "ts": 1742584926719, "type": "delta", "data": {"s": "BTCUSDT", "b": [["84110.9", "0.618269"], ["84101.5", "0.114701"], ["84091.7", "0.245259"], ["84082.6", "0.277159"], ["84073.6", "0.356794"], ["84072.8", "0"], ["84047.4", "0"], ["84046.4", "0"]], "a": [["84115.4", "0.017448"], ["84126.3", "0.170633"], ["84126.7", "0.113378"], ["84136.5", "0.534793"], ["84145.6", "0.421902"], ["84149", "0.09037"], ["84175.7", "0"], ["84177.7", "0.356794"], ["84183.8", "0"]], "u": 168104, "seq": 67577218804}, "cts": 1742584926711, "record_time": 1742584926.822373, "EXCHANGE": "BYBIT"}
{"topic": "orderbook.200.BTCUSDT", "ts": 1742584926919, "type": "delta", "data": {"s": "BTCUSDT", "b": [["84110.9", "0.447269"], ["84101.5", "0"], ["84096.5", "0.058852"], ["84091.7", "0.060528"], ["84089.5", "0.058401"], ["84082.6", "0"], ["84082.5", "0.114685"], ["84073.6", "0"], ["84071.8", "0.356797"], ["84070.2", "0.210622"], ["84070", "0.05"], ["84069.8", "0"], ["84060.8", "13.486643"], ["84048.1", "0"]], "a": [["84115.3", "0.03617"], ["84126.7", "0"], ["84131.5", "0.063979"], ["84136.5", "0.349336"], ["84138.5", "0.061367"], ["84143.6", "0.179714"], ["84145.5", "0.109716"], ["84145.6", "0.118539"], ["84151.6", "0.099399"], ["84151.7", "0.04"], ["84151.8", "0.000528"], ["84151.9", "0.004582"], ["84175.7", "0.356797"], ["84177.7", "0"], ["84182.3", "0"], ["84182.7", "0"]], "u": 168105, "seq": 67577218902}, "cts": 1742584926916, "record_time": 1742584927.022564, "EXCHANGE": "BYBIT"}
{"topic": "orderbook.200.BTCUSDT", "ts": 1742584927119, "type": "delta", "data": {"s": "BTCUSDT", "b": [["84110.9", "0.618269"], ["84107.9", "0.000153"], ["84101.9", "0.111693"], ["84096.5", "0"], ["84091.4", "0.180179"], ["84089.5", "0"], ["84084.4", "0.303664"], ["84082.5", "0"], ["84073.6", "0.356792"], ["84073.5", "0"], ["84073.3", "0.065011"], ["84071.8", "0"], ["84071.7", "0.065418"], ["84071.5", "0.012882"], ["84070", "0"], ["84069.9", "0"], ["84069.8", "0.05"], ["84069.7", "0.049548"], ["84063.6", "0.356898"], ["84048.2", "0"]], "a": [["84115.3", "0.0015"], ["84117.3", "0"], ["84120.6", "0.07136"], ["84126.3", "0.125958"], ["84126.4", "0.115965"], ["84128", "0.176452"], ["84131.5", "0.006083"], ["84132.2", "0.005472"], ["84133.4", "0.071349"], ["84136.5", "0.171"], ["84136.9", "0.172719"], ["84138.5", "0"], ["84143.9", "0.303748"], ["84145.5", "0"], ["84149.1", "0.02378"], ["84151.6", "0.059399"], ["84151.7", "0"], ["84151.9", "0.044582"], ["84152", "0.04"], ["84175.7", "0"], ["84178.2", "0.356792"], ["84181.1", "0"], ["84182", "0"]], "u": 168106, "seq": 67577219022}, "cts": 1742584927117, "record_time": 1742584927.221859, "EXCHANGE": "BYBIT"}
{"topic": "orderbook.200.BTCUSDT", "ts": 1742584927320, "type": "delta", "data": {"s": "BTCUSDT", "b": [["84108.9", "0.000118"], ["84101.9", "0"], ["84095.5", "0.051333"], ["84095.4", "0.049911"], ["84095.2", "0.05"], ["84095", "0.064"], ["84094", "0.049911"], ["84092.3", "0.05"], ["84092.2", "0"], ["84091.5", "0.05"], ["84091.4", "0"], ["84090.4", "0.021711"], ["84086.2", "0"], ["84084.4", "0"], ["84075.4", "0.356784"], ["84073.6", "0"], ["84070.1", "0.118934"], ["84063.5", "13.486643"], ["84060.8", "0"], ["84048.2", "0.000149"]], "a": [["84111", "0.003082"], ["84126.4", "0"], ["84130.5", "0.164938"], ["84136.9", "0"], ["84143.9", "0"], ["84149", "0.005477"], ["84151.9", "0.004582"], ["84152", "0"], ["84152.1", "0.0406"], ["84152.2", "0.0412"], ["84155", "0.051462"], ["84157.8", "0"], ["84178.2", "0"], ["84181.1", "0.118539"], ["84182", "0.00018"], ["84182.3", "0.003"], ["84182.7", "0.005184"], ["84183.8", "0.001333"]], "u": 168107, "seq": 67577219108}, "cts": 1742584927295, "record_time": 1742584927.422031, "EXCHANGE": "BYBIT"}
{"topic": "orderbook.200.BTCUSDT", "ts": 1742584927520, "type": "delta", "data": {"s": "BTCUSDT", "b": [["84110.9", "0.447269"], ["84107.9", "0"], ["84084.5", "0"], ["84075.5", "0.302781"], ["84075.4", "0"], ["84075.3", "0"], ["84073.5", "0.356793"], ["84073.4", "0"], ["84073.2", "0.040163"], ["84071.6", "0"], ["84071.4", "0.012882"], ["84069.8", "0"], ["84069.6", "0.049548"], ["84048.1", "0.005682"], ["84047.4", "0.00588"], ["84046.4", "0.023784"]], "a": [["84120.6", "0"], ["84128.3", "0.071353"], ["84133.4", "0"], ["84143.6", "0.112179"], ["84152.1", "0.0006"], ["84152.3", "0.04"], ["84168.5", "2.621245"], ["84177.7", "0.356793"], ["84183.8", "0"]], "u": 168108, "seq": 67577219215}, "cts": 1742584927516, "record_time": 1742584927.621956, "EXCHANGE": "BYBIT"}
{"topic": "orderbook.200.BTCUSDT", "ts": 1742584927720, "type": "delta", "data": {"s": "BTCUSDT", "b": [["84110.9", "0.449597"], ["84110.4", "0"], ["84095.7", "0.171"], ["84073.5", "0"], ["84070.3", "0.356802"], ["84069.8", "0.049548"], ["84069.6", "0"], ["84046.3", "0.001466"]], "a": [["84111", "0.00351"], ["84115.3", "0.034513"], ["84117.1", "0.074363"], ["84126.1", "0.071713"], ["84126.2", "0.051333"], ["84128.3", "0"], ["84132.2", "0.183808"], ["84132.3", "0"], ["84136.5", "0.349336"], ["84149.1", "0.112948"], ["84174.1", "0.356802"], ["84177.7", "0"]], "u": 168109, "seq": 67577219311}, "cts": 1742584927702, "record_time": 1742584927.823225, "EXCHANGE": "BYBIT"}
{"topic": "orderbook.200.BTCUSDT", "ts": 1742584927920, "type": "delta", "data": {"s": "BTCUSDT", "b": [["84110.9", "0.387041"], ["84108", "0.000153"], ["84107.3", "0.095982"], ["84105", "0.190911"], ["84102.7", "0.02104"], ["84101.3", "0.023788"], ["84100", "0.247457"], ["84097.1", "0.001466"], ["84096.8", "0"], ["84094.2", "0.051333"], ["84093.9", "0.058897"], ["84092.5", "0.001466"], ["84086.9", "0.059322"], ["84079.9", "0.159616"], ["84077.6", "0.178336"], ["84075.5", "0"], ["84071.6", "0.013"], ["84071.4", "0"], ["84070.9", "0"], ["84070.3", "0"], ["84070.2", "0.210631"], ["84067", "0.356816"], ["84063.5", "0"], ["84058.1", "12.97546"], ["84046.4", "0"], ["84046.3", "0"]], "a": [["84111", "0.100355"], ["84114.9", "0.014612"], ["84115.3", "0.0015"], ["84117.1", "0.003"], ["84120.1", "0.059399"], ["84122", "0.110544"], ["84123.5", "0.071358"], ["84126.1", "0.20361"], ["84126.3", "0.04"], ["84128.9", "0.061797"], ["84130.2", "0"], ["84130.5", "0.093586"], ["84135.9", "0.055079"], ["84142.9", "0.121086"], ["84149", "0.09037"], ["84152.1", "0.052062"], ["84155", "0"], ["84165.7", "2.621773"], ["84168.4", "0.356816"], ["84168.5", "0"], ["84174.1", "0"], ["84182", "0"], ["84182.3", "0"], ["84182.7", "0"]], "u": 168110, "seq": 67577219465}, "cts": 1742584927916, "record_time": 1742584928.022544, "EXCHANGE": "BYBIT"}
{"topic": "orderbook.200.BTCUSDT", "ts": 1742584928120, "type": "delta", "data": {"s": "BTCUSDT", "b": [["84110.9", "0.291757"], ["84108", "0"], ["84107.1", "0.107124"], ["84099.9", "0.139911"], ["84098.5", "0.031801"], ["84093.9", "0"], ["84090.6", "0.021711"], ["84090.4", "0"], ["84086.9", "0"], ["84086", "0"], ["84081.8", "0"], ["84079.9", "0.049911"], ["84077.6", "0"], ["84068.2", "0.356813"], ["84067", "0"], ["84066.8", "0"], ["84065", "0"], ["84062.3", "0.025713"], ["84046.4", "0.023784"], ["84046.3", "0.001466"], ["84045.9", "0.059399"], ["84045.7", "0.000333"], ["84045.5", "0.000526"], ["84045", "0.001333"], ["84044", "0.089193"]], "a": [["84111", "0.271355"], ["84112.8", "0.02151"], ["84112.9", "0.071366"], ["84122", "0.141466"], ["84128.9", "0"], ["84135.9", "0"], ["84142.9", "0"], ["84161.4", "0.04471"], ["84168.4", "0"], ["84170.4", "0.358942"], ["84182", "0.00018"], ["84182.3", "0.003"]], "u": 168111, "seq": 67577219591}, "cts": 1742584928110, "record_time": 1742584928.223297, "EXCHANGE": "BYBIT"}
{"topic": "orderbook.200.BTCUSDT", "ts": 1742584928319, "type": "delta", "data": {"s": "BTCUSDT", "b": [["84108.1", "0.000153"], ["84104.1", "0.005978"], ["84099.9", "0.264928"], ["84089.4", "0.165767"], ["84083.8", "0"], ["84082.4", "0.288127"], ["84070.3", "0.356806"], ["84070", "0.05"], ["84069.9", "0.049548"], ["84069.8", "0"], ["84069.7", "0"], ["84068.2", "0"], ["84065", "0.178336"], ["84062", "0"], ["84060.8", "0.178336"], ["84045.5", "0"], ["84045", "0"], ["84044", "0"]], "a": [["84111", "0.1056"], ["84112.8", "0"], ["84112.9", "0"], ["84113.9", "0.037848"], ["84114", "0.071366"], ["84114.9", "0"], ["84120.1", "0"], ["84124.4", "0.120577"], ["84134.9", "0.179439"], ["84141.9", "0.308922"], ["84170.4", "0.002128"], ["84172", "0.356808"], ["84182", "0"], ["84182.3", "0"]], "u": 168112, "seq": 67577219642}, "cts": 1742584928314, "record_time": 1742584928.422646, "EXCHANGE": "BYBIT"}
{"topic": "orderbook.200.BTCUSDT", "ts": 1742584928520, "type": "delta", "data": {"s": "BTCUSDT", "b": [["84099.9", "0.139911"], ["84089.4", "0"], ["84082.4", "0.000528"], ["84081.8", "0.178336"], ["84077.6", "0.178336"], ["84072.5", "0.096346"], ["84071.8", "0.356801"], ["84070.3", "0"], ["84070.2", "0.210627"], ["84070", "0"], ["84069.9", "0"], ["84069.8", "0.049548"], ["84069.7", "0.049548"], ["84065", "0"], ["84060.8", "0"]], "a": [["84124.1", "0.059929"], ["84124.4", "0"], ["84134.9", "0"], ["84141.9", "0"], ["84172", "0"], ["84175.7", "0.356801"], ["84182", "0.00018"], ["84182.3", "0.003"], ["84182.7", "0.005184"]], "u": 168113, "seq": 67577219715}, "cts": 1742584928515, "record_time": 1742584928.621726, "EXCHANGE": "BYBIT"}
{"topic": "orderbook.200.BTCUSDT", "ts": 1742584928720, "type": "delta", "data": {"s": "BTCUSDT", "b": [["84110.9", "0.292342"], ["84071.8", "0"], ["84070.3", "0.356805"]], "a": [["84111", "0.100355"], ["84172.8", "0.356805"], ["84175.7", "0"]], "u": 168114, "seq": 67577219756}, "cts": 1742584928714, "record_time": 1742584928.82332, "EXCHANGE": "BYBIT"}
{"topic": "orderbook.200.BTCUSDT", "ts": 1742584928920, "type": "delta", "data": {"s": "BTCUSDT", "b": [["84108.1", "0"], ["84073.4", "0.039635"], ["84073.2", "0.000528"], ["84071.6", "0.012882"], ["84070.3", "0"], ["84070.2", "0.210656"], ["84070", "0.05"], ["84069.9", "0.406355"], ["84069.8", "0"], ["84069.7", "0"], ["84065", "0.089168"]], "a": [["84152.1", "0.092062"], ["84152.3", "0"], ["84156.9", "0.055673"], ["84172", "0.356808"], ["84172.8", "0"]], "u": 168115, "seq": 67577219807}, "cts": 1742584928913, "record_time": 1742584929.023425, "EXCHANGE": "BYBIT"}
{"topic": "orderbook.200.BTCUSDT", "ts": 1742584929120, "type": "delta", "data": {"s": "BTCUSDT", "b": [["84095.5", "0.101333"], ["84095.2", "0"], ["84093.9", "0.003361"], ["84092.6", "0.05"], ["84092.3", "0"], ["84091.7", "0.110528"], ["84088.6", "0.178336"], ["84083.2", "0.001466"], ["84081.8", "0"], ["84078.9", "0.275991"], ["84078.7", "0"], ["84077.6", "0"], ["84073.6", "0.04"], ["84073.5", "0.039635"], ["84073.4", "0.178336"], ["84073.3", "0.025376"], ["84071.8", "0.013"], ["84071.7", "0.0783"], ["84071.6", "0"], ["84071.5", "0"], ["84070.2", "0.210648"], ["84069.9", "0.049548"], ["84069.2", "0.178336"], ["84068.2", "0.356809"], ["84065", "0"], ["84045.7", "0"]], "a": [["84111", "0.1056"], ["84131.6", "0.018164"], ["84151.7", "0.04"], ["84151.8", "0.040528"], ["84152.1", "0.052062"], ["84152.2", "0.0012"], ["84182.7", "0"]], "u": 168116, "seq": 67577219893}, "cts": 1742584929102, "record_time": 1742584929.222663, "EXCHANGE": "BYBIT"}
{"topic": "orderbook.200.BTCUSDT", "ts": 1742584929320, "type": "delta", "data": {"s": "BTCUSDT", "b": [["84110.9", "0.236735"], ["84101.3", "0"], ["84100", "0.154866"], ["84099.5", "0.071378"], ["84097.8", "0"], ["84097.7", "0.111202"], ["84095.8", "0.266922"], ["84095.6", "0.178368"], ["84095.5", "0.051333"], ["84094.4", "0.005468"], ["84093.7", "0.178372"], ["84091.7", "0.288905"], ["84090.8", "0.086041"], ["84090.6", "0"], ["84087.9", "0.186585"], ["84078.8", "0.3991"], ["84073.6", "0"], ["84073.4", "0.217971"], ["84071.8", "0"], ["84071.6", "0.012882"], ["84070", "0"], ["84069.8", "0.049548"], ["84068.3", "0.356811"], ["84068.2", "0"], ["84060.4", "0.083919"], ["84054", "0.000366"], ["84045.7", "0.000333"]], "a": [["84111", "0.361022"], ["84112.6", "0.02151"], ["84112.7", "0.071367"], ["84113.9", "0"], ["84114", "0"], ["84115.3", "0.015662"], ["84120.6", "0.023789"], ["84122.9", "0.114188"], ["84132.7", "0.180249"], ["84141.8", "0.291198"], ["84151.7", "0"], ["84151.9", "0.044582"], ["84172", "0.35681"], ["84181.1", "0"], ["84182", "0"], ["84182.3", "0"]], "u": 168117, "seq": 67577219987}, "cts": 1742584929317, "record_time": 1742584929.44634, "EXCHANGE": "BYBIT"}
{"topic": "orderbook.200.BTCUSDT", "ts": 1742584929519, "type": "delta", "data": {"s": "BTCUSDT", "b": [["84104.1", "0"], ["84097.7", "0"], ["84087.9", "0.001466"], ["84078.8", "0.118539"], ["84070.1", "0.168934"], ["84070", "0.049548"], ["84069.9", "0"], ["84069.8", "0"], ["84068.4", "0.356812"], ["84068.3", "0"], ["84058.1", "0.059471"], ["84055.3", "12.917489"], ["84045.5", "0.000526"], ["84045", "0.001333"], ["84044", "0.089193"]], "a": [["84111", "0.190022"], ["84122.9", "0"], ["84123.5", "0.180636"], ["84132.7", "0"], ["84141.8", "0"], ["84162.9", "2.623385"], ["84165.7", "0.000528"], ["84171.9", "0.357145"], ["84172", "0"], ["84181.1", "0.118539"], ["84182", "0.00018"], ["84182.3", "0.003"], ["84182.7", "0.005184"]], "u": 168118, "seq": 67577220072}, "cts": 1742584929515, "record_time": 1742584929.622345, "EXCHANGE": "BYBIT"}
{"topic": "orderbook.200.BTCUSDT", "ts": 1742584929720, "type": "delta", "data": {"s": "BTCUSDT", "b": [["84110.5", "0.000153"], ["84100.8", "0.00109"], ["84098.7", "0.123581"], ["84094.6", "0.115563"], ["84088.2", "0.185699"], ["84087.6", "0.16375"], ["84081.2", "0.29724"], ["84080.6", "0.306514"], ["84073.6", "0.04"], ["84073.4", "0"], ["84071.3", "0.356803"], ["84070.2", "0.21065"], ["84070.1", "0.118934"], ["84069.9", "0.049548"], ["84069.2", "0"], ["84068.4", "0"], ["84046.4", "0"], ["84046.3", "0"], ["84045.9", "0"], ["84045.7", "0"], ["84045.5", "0"], ["84045", "0"], ["84044", "0"]], "a": [["84112.6", "0"], ["84112.7", "0"], ["84113.7", "0.037848"], ["84113.8", "0.071366"], ["84115.3", "0.0015"], ["84117.1", "0"], ["84123.2", "0.115905"], ["84123.5", "0.071358"], ["84127.5", "0.166221"], ["84133.7", "0.167283"], ["84134.5", "0.172999"], ["84135", "1.14057"], ["84140.7", "0.288119"], ["84141.5", "0.29658"], ["84151.5", "0.393352"], ["84151.6", "0.099399"], ["84151.8", "0.000528"], ["84151.9", "0.004582"], ["84171.9", "0.000333"], ["84174.1", "0.356803"], ["84181.1", "0"], ["84182", "0"], ["84182.3", "0"], ["84182.7", "0"]], "u": 168119, "seq": 67577220145}, "cts": 1742584929716, "record_time": 1742584929.822588, "EXCHANGE": "BYBIT"}
{"topic": "orderbook.200.BTCUSDT", "ts": 1742584929919, "type": "delta", "data": {"s": "BTCUSDT", "b": [["84104.1", "0.00598"], ["84100", "0.224895"], ["84098.7", "0"], ["84098.1", "0.178363"], ["84096.5", "0.178367"], ["84096.1", "0.228278"], ["84095.8", "0.248929"], ["84095.6", "0"], ["84094.6", "0"], ["84093.7", "0"], ["84092.2", "0.024222"], ["84092.1", "0.438363"], ["84091.7", "0.110528"], ["84088.6", "0"], ["84088.2", "0"], ["84087.6", "0"], ["84081.8", "0.178336"], ["84081.2", "0"], ["84080.6", "0"], ["84077.6", "0.178336"], ["84074.1", "0.356792"], ["84073.6", "0.039635"], ["84071.9", "0.013"], ["84071.8", "0.012881"], ["84071.7", "0.065418"], ["84071.6", "0"], ["84071.3", "0"], ["84070.2", "0.210645"], ["84070.1", "0.168482"], ["84069.9", "0"], ["84065", "0.089168"], ["84062.9", "0.023489"], ["84057.9", "12.337641"], ["84055.3", "0.0015"]], "a": [["84111", "0.100355"], ["84113.8", "0"], ["84115.1", "0.071365"], ["84123.2", "0.00009"], ["84127.5", "0.041904"], ["84133.7", "0"], ["84134.5", "0"], ["84140.7", "0"], ["84141.5", "0"], ["84151.5", "0.353352"], ["84151.6", "0.059399"], ["84151.7", "0.04"], ["84151.8", "0.040528"], ["84161.4", "0.020426"], ["84162.9", "0.00214"], ["84165.7", "2.621773"], ["84174.1", "0"], ["84178.2", "0.356792"], ["84181.1", "0.118539"], ["84182", "0.00018"], ["84182.3", "0.003"]], "u": 168120, "seq": 67577220281}, "cts": 1742584929916, "record_time": 1742584930.022581, "EXCHANGE": "BYBIT"}
{"topic": "orderbook.200.BTCUSDT", "ts": 1742584930119, "type": "delta", "data": {"s": "BTCUSDT", "b": [["84110.5", "0"], ["84092.1", "0.333742"], ["84090.8", "0.086005"], ["84078.8", "0.142317"], ["84074.2", "0.330794"], ["84074.1", "0"], ["84072.8", "0.356797"], ["84071.9", "0.012881"], ["84058.1", "11.829363"], ["84057.9", "0"], ["84046.4", "0.023784"]], "a": [["84114.1", "0.071366"], ["84115.1", "0"], ["84133.8", "0.023778"], ["84175.7", "0.356798"], ["84178.2", "0"], ["84182.3", "0"]], "u": 168121, "seq": 67577220363}, "cts": 1742584930115, "record_time": 1742584930.222218, "EXCHANGE": "BYBIT"}
{"topic": "orderbook.200.BTCUSDT", "ts": 1742584930320, "type": "delta", "data": {"s": "BTCUSDT", "b": [["84110.9", "0.236804"], ["84073.8", "0.04"], ["84073.7", "0.039635"], ["84073.6", "0"], ["84073.5", "0"], ["84072.8", "0"], ["84072", "0.013"], ["84071.8", "0"], ["84071.3", "0.356803"], ["84070.2", "0.260645"], ["84070", "0"], ["84047.5", "0.011841"]], "a": [["84150.9", "0.040333"], ["84151", "0.04"], ["84151.7", "0"], ["84151.8", "0.000528"], ["84162.9", "2.623385"], ["84165.7", "0.000528"], ["84174.1", "0.356803"], ["84175.7", "0"]], "u": 168122, "seq": 67577220396}, "cts": 1742584930305, "record_time": 1742584930.422476, "EXCHANGE": "BYBIT"}
{"topic": "orderbook.200.BTCUSDT", "ts": 1742584930520, "type": "delta", "data": {"s": "BTCUSDT", "b": [["84108.1", "0.000153"], ["84103.2", "0.071375"], ["84099.5", "0"], ["84074.2", "0"], ["84073.8", "0"], ["84073.6", "0.039635"], ["84071.4", "0.356804"], ["84071.3", "0"], ["84070.2", "0.210659"], ["84070", "0.049548"], ["84046.4", "0"]], "a": [["84111", "0.1056"], ["84121.3", "0.071359"], ["84126.1", "0.132255"], ["84150.9", "0.000333"], ["84151", "0"], ["84151.3", "0.04"], ["84151.4", "0.670433"], ["84157.7", "0.283717"], ["84162.9", "0.00214"], ["84165.7", "2.621773"], ["84174", "0.356803"], ["84174.1", "0"], ["84181.1", "0"], ["84182", "0"]], "u": 168123, "seq": 67577220465}, "cts": 1742584930512, "record_time": 1742584930.621938, "EXCHANGE": "BYBIT"}
{"topic": "orderbook.200.BTCUSDT", "ts": 1742584930719, "type": "delta", "data": {"s": "BTCUSDT", "b": [["84089.3", "0.178336"], ["84071.8", "0.356801"], ["84071.4", "0"], ["84070.2", "0.260659"], ["84070", "0"], ["84047.6", "0.011841"], ["84047.4", "0"]], "a": [["84111", "0.100355"], ["84135", "1.136995"], ["84174", "0"], ["84175.7", "0.356801"]], "u": 168124, "seq": 67577220497}, "cts": 1742584930717, "record_time": 1742584930.821982, "EXCHANGE": "BYBIT"}
{"topic": "orderbook.200.BTCUSDT", "ts": 1742584930920, "type": "delta", "data": {"s": "BTCUSDT", "b": [["84108.1", "0"], ["84096.1", "0.049911"], ["84093.5", "0.178373"], ["84073.9", "0.04"], ["84073.8", "0.039634"], ["84073.7", "0"], ["84073.6", "0"], ["84072.1", "0.013"], ["84072", "0.012881"], ["84071.9", "0"], ["84071.8", "0"], ["84070.3", "0.406807"], ["84070.2", "0.260174"], ["84070.1", "0.118934"]], "a": [["84112.4", "0.02151"], ["84112.5", "0.071367"], ["84113.7", "0"], ["84114.1", "0"], ["84115.3", "0.014762"], ["84151", "0.04"], ["84151.1", "0.04"], ["84151.3", "0"], ["84151.4", "0.630433"], ["84172.8", "0.356806"], ["84175.7", "0"], ["84180.4", "0"]], "u": 168125, "seq": 67577220567}, "cts": 1742584930899, "record_time": 1742584931.021982, "EXCHANGE": "BYBIT"}
{"topic": "orderbook.200.BTCUSDT", "ts": 1742584931120, "type": "delta", "data": {"s": "BTCUSDT", "b": [["84093", "0.066709"], ["84086", "0.062027"], ["84081.9", "0.246097"], ["84081.8", "0"], ["84079", "0.111295"], ["84077.6", "0"], ["84073.9", "0"], ["84073.7", "0.039635"], ["84073.4", "0.178336"], ["84072.1", "0"], ["84071.9", "0.012881"], ["84070.3", "0"], ["84070.2", "0.260627"], ["84070.1", "0.168482"], ["84069.5", "0.35681"], ["84069.2", "0.178336"], ["84065", "0"], ["84058.1", "0.059471"], ["84052.5", "11.769892"], ["84048.1", "0"], ["84047.6", "0"], ["84047.5", "0"]], "a": [["84111", "0.2766"], ["84128", "0.238398"], ["84135", "1.193432"], ["84142", "0.112877"], ["84151", "0"], ["84151.2", "0.04"], ["84172", "0.356808"], ["84172.8", "0"], ["84180.3", "0"]], "u": 168126, "seq": 67577220625}, "cts": 1742584931111, "record_time": 1742584931.223664, "EXCHANGE": "BYBIT"}
{"topic": "orderbook.200.BTCUSDT", "ts": 1742584931320, "type": "delta", "data": {"s": "BTCUSDT", "b": [["84093", "0.009225"], ["84086", "0"], ["84079", "0"], ["84069.5", "0"], ["84068.2", "0.356813"], ["84057.9", "11.33754"], ["84052.5", "0"], ["84048.1", "0.005682"], ["84047.6", "0.011841"]], "a": [["84111", "0.271355"], ["84128", "0.176452"], ["84135", "1.136995"], ["84142", "0"], ["84156.4", "0.0162"], ["84180.3", "0.000333"]], "u": 168127, "seq": 67577220664}, "cts": 1742584931295, "record_time": 1742584931.422114, "EXCHANGE": "BYBIT"}
{"topic": "orderbook.200.BTCUSDT", "ts": 1742584931520, "type": "delta", "data": {"s": "BTCUSDT", "b": [["84110.9", "0.236004"], ["84108.5", "0.000153"], ["84100.6", "0.001"], ["84077.6", "0.178336"], ["84070.3", "0.356807"], ["84070.2", "0.260629"], ["84069.2", "0"], ["84068.3", "0.024108"], ["84068.2", "0"], ["84060.4", "0.059467"], ["84058.1", "11.397011"], ["84057.9", "0"], ["84048.1", "0"], ["84047.6", "0"]], "a": [["84111", "0.1056"], ["84112.4", "0"], ["84112.5", "0"], ["84113.6", "0.036948"], ["84113.7", "0.071366"], ["84115.3", "0.0015"], ["84172", "0"], ["84172.8", "0.356807"]], "u": 168128, "seq": 67577220738}, "cts": 1742584931514, "record_time": 1742584931.622492, "EXCHANGE": "BYBIT"}
{"topic": "orderbook.200.BTCUSDT", "ts": 1742584931719, "type": "delta", "data": {"s": "BTCUSDT", "b": [["84095.9", "0.05"], ["84095.8", "0.198929"], ["84091.8", "0.05"], ["84091.7", "0.060528"], ["84090.8", "0.085807"], ["84081.8", "0.178336"], ["84073.4", "0"], ["84048.3", "0"], ["84048.2", "0"]], "a": [["84162.9", "2.623385"], ["84165.7", "0.000528"], ["84172.2", "0.356807"], ["84172.8", "0"]], "u": 168129, "seq": 67577220784}, "cts": 1742584931716, "record_time": 1742584931.822117, "EXCHANGE": "BYBIT"}
{"topic": "orderbook.200.BTCUSDT", "ts": 1742584931920, "type": "delta", "data": {"s": "BTCUSDT", "b": [["84110.9", "0.23513"], ["84090.9", "0.021799"], ["84090.8", "0.064"], ["84070.2", "0.260631"], ["84065", "0.089168"], ["84049.2", "0"], ["84048.8", "0"]], "a": [["84136.8", "1.784239"], ["84150.9", "0.040333"], ["84151", "0.04"], ["84151.1", "0"], ["84151.2", "0"], ["84172.2", "0"], ["84174.1", "0.356807"], ["84180.4", "0.001466"]], "u": 168130, "seq": 67577220818}, "cts": 1742584931900, "record_time": 1742584932.022048, "EXCHANGE": "BYBIT"}
{"topic": "orderbook.200.BTCUSDT", "ts": 1742584932119, "type": "delta", "data": {"s": "BTCUSDT", "b": [["84108.5", "0"], ["84108.2", "0.000153"], ["84073.4", "0.184527"], ["84072.1", "0.013"], ["84071.9", "0"], ["84070.4", "0.356807"], ["84070.3", "0.05"], ["84070.2", "0.26018"], ["84070.1", "0.118934"], ["84049.8", "0"], ["84049.3", "0"]], "a": [["84112.6", "0.02151"], ["84112.7", "0.071367"], ["84113.6", "0.015538"], ["84113.7", "0"], ["84135.4", "0.117636"], ["84150.9", "0.000333"], ["84151", "0"], ["84151.1", "0.04"], ["84151.2", "0.04"], ["84162.9", "0.00214"], ["84165.7", "2.621773"], ["84172.8", "0.356807"], ["84174.1", "0"], ["84180.3", "0"], ["84180.4", "0"]], "u": 168131, "seq": 67577220883}, "cts": 1742584932117, "record_time": 1742584932.221927, "EXCHANGE": "BYBIT"}
{"topic": "orderbook.200.BTCUSDT", "ts": 1742584932320, "type": "delta", "data": {"s": "BTCUSDT", "b": [["84081.8", "0"], ["84077.6", "0"], ["84073.8", "0"], ["84073.6", "0.039635"], ["84072.1", "0"], ["84072", "0"], ["84071.9", "0.012881"], ["84071.8", "0.012881"], ["84070.4", "0"], ["84070.3", "0"], ["84070.2", "0.260633"], ["84070.1", "0.168482"], ["84068.2", "0.356811"], ["84065", "0"], ["84058.1", "0.059471"], ["84055.3", "11.034052"], ["84049.8", "0.023784"], ["84049.3", "0.059471"], ["84049.2", "0.001333"], ["84048.8", "0.023789"]], "a": [["84111", "0.271355"], ["84111.5", "0.02191"], ["84111.6", "0.071368"], ["84112.6", "0"], ["84112.7", "0"], ["84119.3", "0.071361"], ["84121.3", "0"], ["84136.5", "0.171"], ["84151.1", "0"], ["84151.3", "0.04"], ["84162.9", "2.623385"], ["84165.7", "0.000528"], ["84172", "0.356809"], ["84172.8", "0"]], "u": 168132, "seq": 67577220990}, "cts": 1742584932309, "record_time": 1742584932.423565, "EXCHANGE": "BYBIT"}
{"topic": "orderbook.200.BTCUSDT", "ts": 1742584932519, "type": "delta", "data": {"s": "BTCUSDT", "b": [["84108.2", "0"], ["84080.7", "0.181911"], ["84072", "0.013"], ["84071.8", "0"], ["84069.5", "0.356812"], ["84068.2", "0"], ["84059.6", "0.089168"], ["84058.1", "11.092023"], ["84055.3", "0.0015"]], "a": [["84111", "0.100355"], ["84111.6", "0"], ["84112.7", "0.071367"], ["84135.3", "0.178336"], ["84162.9", "0.00214"], ["84165.7", "2.621773"], ["84171.9", "0.357148"], ["84172", "0"]], "u": 168133, "seq": 67577221112}, "cts": 1742584932514, "record_time": 1742584932.621941, "EXCHANGE": "BYBIT"}
{"topic": "orderbook.200.BTCUSDT", "ts": 1742584932720, "type": "delta", "data": {"s": "BTCUSDT", "b": [["84110.9", "0.235495"], ["84108.5", "0.000153"], ["84099.4", "0.116118"], ["84096", "0.302017"], ["84095.8", "0"], ["84095.3", "0.115252"], ["84088.9", "0.170819"], ["84088.3", "0.163798"], ["84084.9", "0.20212"], ["84081.9", "0.553273"], ["84081.3", "0.296694"], ["84073.8", "0.04"], ["84073.6", "0"], ["84069.6", "0.356809"], ["84069.5", "0"], ["84050.1", "0"], ["84049.9", "0"], ["84049.8", "0"], ["84049.3", "0"], ["84049.2", "0"], ["84048.8", "0"]], "a": [["84123.9", "0.110876"], ["84128.2", "0.11496"], ["84134.4", "0.17956"], ["84135.2", "0.16764"], ["84141.4", "0.285846"], ["84142.2", "0.292992"], ["84151.1", "0.04"], ["84151.3", "0"], ["84162.9", "2.623385"], ["84165.7", "0.000528"], ["84171.9", "0.000333"], ["84172.2", "0.356808"], ["84176.3", "0"], ["84177.1", "0"], ["84177.8", "0"], ["84178.3", "0"], ["84178.5", "0"], ["84179", "0"], ["84179.6", "0"]], "u": 168134, "seq": 67577221170}, "cts": 1742584932701, "record_time": 1742584932.823579, "EXCHANGE": "BYBIT"}
{"topic": "orderbook.200.BTCUSDT", "ts": 1742584932920, "type": "delta", "data": {"s": "BTCUSDT", "b": [["84108.5", "0"], ["84108.2", "0.000153"], ["84099.4", "0"], ["84095.3", "0"], ["84088.9", "0"], ["84088.3", "0"], ["84081.9", "0.246097"], ["84081.3", "0"], ["84070.2", "0.260631"], ["84069.6", "0"], ["84068.2", "0.356809"], ["84050.1", "0.000528"], ["84049.9", "0.000333"], ["84049.8", "0.023784"], ["84049.3", "0.059471"], ["84049.2", "0.001333"]], "a": [["84111", "0.025755"], ["84123.9", "0"], ["84128.2", "0"], ["84134.4", "0"], ["84135.2", "0"], ["84135.4", "0.114061"], ["84140.2", "0.264035"], ["84141.4", "0"], ["84142.2", "0"], ["84172.2", "0"], ["84174.1", "0.356809"], ["84176.3", "0.04"], ["84177.1", "3.925682"], ["84177.8", "0.246684"], ["84178.3", "0.059399"], ["84178.5", "0.005184"], ["84179.6", "0.001861"]], "u": 168135, "seq": 67577221248}, "cts": 1742584932915, "record_time": 1742584933.02178, "EXCHANGE": "BYBIT"}
{"topic": "orderbook.200.BTCUSDT", "ts": 1742584933120, "type": "delta", "data": {"s": "BTCUSDT", "b": [["84108.3", "0.000153"], ["84108.2", "0"], ["84089.3", "0"], ["84070.3", "0.356806"], ["84068.2", "0"], ["84048.8", "0.023789"]], "a": [["84119.3", "0"], ["84121.3", "0.071359"], ["84140.2", "0.099719"], ["84152.1", "0.0006"], ["84155", "0.051462"], ["84174", "0.356807"], ["84174.1", "0"], ["84179.6", "0"]], "u": 168136, "seq": 67577221305}, "cts": 1742584933116, "record_time": 1742584933.222059, "EXCHANGE": "BYBIT"}
{"topic": "orderbook.200.BTCUSDT", "ts": 1742584933320, "type": "delta", "data": {"s": "BTCUSDT", "b": [["84062.3", "0"], ["84048.3", "0.118539"]], "a": [["84172.8", "0.356808"], ["84174", "0"]], "u": 168137, "seq": 67577221331}, "cts": 1742584933307, "record_time": 1742584933.422647, "EXCHANGE": "BYBIT"}
{"topic": "orderbook.200.BTCUSDT", "ts": 1742584933520, "type": "delta", "data": {"s": "BTCUSDT", "b": [["84110.9", "0.237278"], ["84108.3", "0"], ["84099.9", "0.24959"], ["84091.6", "0.128516"], ["84091.5", "0"], ["84090.1", "0.171543"], ["84081", "0.277365"], ["84074.3", "0"], ["84071.3", "0.356805"], ["84070.3", "0"], ["84070.2", "0.260629"], ["84048.2", "0.000149"], ["84048.1", "0.005682"]], "a": [["84111", "0.025696"], ["84125.1", "0.110142"], ["84134.9", "0.175111"], ["84144", "0.291956"], ["84172.8", "0"], ["84174.4", "0.356805"], ["84177.8", "0"], ["84178.3", "0"], ["84178.5", "0"]], "u": 168138, "seq": 67577221391}, "cts": 1742584933511, "record_time": 1742584933.622312, "EXCHANGE": "BYBIT"}
{"topic": "orderbook.200.BTCUSDT", "ts": 1742584933720, "type": "delta", "data": {"s": "BTCUSDT", "b": [["84110.9", "0.235495"], ["84100.8", "0.00009"], ["84099.9", "0.139911"], ["84095.9", "0"], ["84095.8", "0.05"], ["84091.8", "0"], ["84091.7", "0.110528"], ["84091.6", "0.078516"], ["84091.5", "0.05"], ["84090.9", "0"], ["84090.8", "0.086088"], ["84090.1", "0.005467"], ["84089.3", "0.178336"], ["84084.9", "0.023784"], ["84081", "0"], ["84080.7", "0.003575"], ["84073.8", "0.039634"], ["84072", "0.012881"], ["84071.3", "0"], ["84070.2", "0.260176"], ["84068.2", "0.356811"], ["84067", "0.001783"], ["84060.6", "0.025713"], ["84053.6", "0.000149"], ["84048.2", "0"], ["84048.1", "0"]], "a": [["84111", "0.276541"], ["84125.1", "0"], ["84134.9", "0"], ["84144", "0"], ["84161.9", "0.001466"], ["84167.3", "0.000145"], ["84172", "0.356811"], ["84174.4", "0"], ["84177.8", "0.246684"], ["84178.3", "0.059399"]], "u": 168139, "seq": 67577221500}, "cts": 1742584933714, "record_time": 1742584933.82254, "EXCHANGE": "BYBIT"}
{"topic": "orderbook.200.BTCUSDT", "ts": 1742584933919, "type": "delta", "data": {"s": "BTCUSDT", "b": [["84070.2", "0.260178"], ["84069.5", "0.356811"], ["84068.2", "0"]], "a": [["84111", "0.100296"], ["84126.9", "0.179478"], ["84135.3", "0"], ["84135.9", "0.003575"]], "u": 168140, "seq": 67577221574}, "cts": 1742584933899, "record_time": 1742584934.022483, "EXCHANGE": "BYBIT"}
{"topic": "orderbook.200.BTCUSDT", "ts": 1742584934120, "type": "delta", "data": {"s": "BTCUSDT", "b": [["84084.9", "0.321011"], ["84080.7", "0.181911"], ["84070.3", "0.35681"], ["84069.5", "0"]], "a": [["84111", "0.105541"], ["84131.8", "0.118891"], ["84135.3", "0.178336"], ["84152.1", "0.052062"], ["84155", "0"], ["84178.3", "0"]], "u": 168141, "seq": 67577221617}, "cts": 1742584934118, "record_time": 1742584934.223309, "EXCHANGE": "BYBIT"}
{"topic": "orderbook.200.BTCUSDT", "ts": 1742584934320, "type": "delta", "data": {"s": "BTCUSDT", "b": [["84108.4", "0.000153"], ["84084.9", "0.142675"], ["84080.7", "0.003575"], ["84070.3", "0"], ["84068.2", "0.356815"], ["84058.1", "0.059471"], ["84055.3", "11.191494"], ["84048.3", "0"]], "a": [["84111", "0.271296"], ["84172", "0.356816"]], "u": 168142, "seq": 67577221668}, "cts": 1742584934312, "record_time": 1742584934.422502, "EXCHANGE": "BYBIT"}
{"topic": "orderbook.200.BTCUSDT", "ts": 1742584934520, "type": "delta", "data": {"s": "BTCUSDT", "b": [["84108.4", "0"], ["84095.8", "0"], ["84095.7", "0.221"], ["84095.5", "0.001333"], ["84095.4", "0.099911"], ["84092.6", "0"], ["84092.5", "0.051466"], ["84091.5", "0"], ["84091.4", "0.05"], ["84090.8", "0.085797"], ["84069.5", "0.356813"], ["84068.2", "0"], ["84058", "11.242472"], ["84055.3", "0.0015"], ["84048.3", "0.118539"], ["84048.1", "0.005682"]], "a": [["84135.3", "0"], ["84178.3", "0.059399"]], "u": 168143, "seq": 67577221712}, "cts": 1742584934500, "record_time": 1742584934.622988, "EXCHANGE": "BYBIT"}
{"topic": "orderbook.200.BTCUSDT", "ts": 1742584934719, "type": "delta", "data": {"s": "BTCUSDT", "b": [["84069.5", "0"], ["84068.2", "0.356814"], ["84053.9", "0.047562"]], "a": [], "u": 168144, "seq": 67577221738}, "cts": 1742584934705, "record_time": 1742584934.821927, "EXCHANGE": "BYBIT"}
{"topic": "orderbook.200.BTCUSDT", "ts": 1742584934919, "type": "delta", "data": {"s": "BTCUSDT", "b": [["84100", "0.154866"], ["84098.1", "0"], ["84096.5", "0"], ["84095.2", "0.178369"], ["84093.5", "0.356746"], ["84074", "0.091011"], ["84073.9", "0.039634"], ["84073.8", "0"], ["84073.7", "0"], ["84070.4", "0.049547"], ["84070.3", "0.049547"], ["84070.2", "0.210631"], ["84070.1", "0.118934"], ["84068.2", "0.356813"], ["84059.6", "0"], ["84058", "0"], ["84055.3", "11.243972"], ["84047.6", "0.011841"], ["84047.5", "0.011841"]], "a": [["84111.2", "0.027355"], ["84111.3", "0.071368"], ["84111.5", "0"], ["84112.7", "0"], ["84119", "0.071361"], ["84123.5", "0"], ["84150.7", "0.04"], ["84150.8", "0.198539"], ["84151.1", "0"], ["84151.2", "0"], ["84170.4", "0.358945"], ["84172", "0"], ["84178.5", "0.005184"], ["84179.6", "0.001861"], ["84180.3", "0.000333"]], "u": 168145, "seq": 67577221788}, "cts": 1742584934913, "record_time": 1742584935.022064, "EXCHANGE": "BYBIT"}
{"topic": "orderbook.200.BTCUSDT", "ts": 1742584935120, "type": "delta", "data": {"s": "BTCUSDT", "b": [["84105", "0.171"], ["84074", "0.051377"], ["84073.9", "0"], ["84073.7", "0.039635"], ["84073.6", "0.039635"], ["84072", "0"], ["84071.8", "0.012881"], ["84070.4", "0"], ["84070.3", "0"], ["84070.2", "0.210637"], ["84070.1", "0.168482"], ["84070", "0.049548"], ["84068.2", "0"], ["84067", "0.358604"], ["84055.4", "0.190336"], ["84051.2", "0.538753"], ["84047.4", "0.00588"]], "a": [["84150.7", "0"], ["84150.8", "0.158539"], ["84151.4", "0.670433"], ["84151.5", "0.393352"], ["84170", "0.359662"], ["84170.4", "0.002128"], ["84179", "0.171"]], "u": 168146, "seq": 67577221839}, "cts": 1742584935117, "record_time": 1742584935.221809, "EXCHANGE": "BYBIT"}
{"topic": "orderbook.200.BTCUSDT", "ts": 1742584935320, "type": "delta", "data": {"s": "BTCUSDT", "b": [["84107.3", "0"], ["84105", "0"], ["84102.7", "0.001129"], ["84102.4", "0"], ["84097", "0.079911"], ["84096.1", "0.019911"], ["84096", "0.204929"], ["84095.4", "0.069911"], ["84095.2", "0"], ["84094.2", "0"], ["84093.5", "0"], ["84093.1", "0.009063"], ["84092", "0.290395"], ["84091.2", "0.049911"], ["84090.3", "0.17838"], ["84089.3", "0"], ["84088.7", "0.183828"], ["84087.8", "0.051666"], ["84086.8", "0.178336"], ["84078.8", "0.023778"], ["84070.2", "0.120633"], ["84067.4", "0.208946"], ["84067", "0.001783"], ["84062.9", "0"], ["84060.5", "0.356848"], ["84046.6", "0.011841"], ["84046.4", "0.023784"], ["84046.3", "0.001466"], ["84045.9", "0.059399"]], "a": [["84111", "0.274871"], ["84113.6", "0.035005"], ["84117", "0.071363"], ["84118.3", "0.23174"], ["84119", "0"], ["84120.1", "0.051333"], ["84120.6", "0.041863"], ["84126", "0.118539"], ["84126.2", "0"], ["84131.6", "0.00009"], ["84135.9", "0"], ["84149.9", "0.024284"], ["84154.6", "2.621245"], ["84161.1", "0.022588"], ["84162.8", "0.35818"], ["84162.9", "0.00214"], ["84170", "0.002841"], ["84179.6", "0"], ["84180.3", "0"]], "u": 168147, "seq": 67577221925}, "cts": 1742584935308, "record_time": 1742584935.422119, "EXCHANGE": "BYBIT"}
{"topic": "orderbook.200.BTCUSDT", "ts": 1742584935520, "type": "delta", "data": {"s": "BTCUSDT", "b": [["84107.1", "0.007124"], ["84104.1", "0"], ["84100.6", "0"], ["84094", "0.019911"], ["84078.9", "0.194062"], ["84071.1", "0.368277"], ["84071", "0.04988"], ["84070.1", "0.118934"], ["84070", "0"], ["84067.4", "0.208944"], ["84062.5", "0.357175"], ["84060.5", "0"], ["84055.4", "0.012"], ["84047", "0.178336"], ["84045.7", "0.000333"], ["84045.5", "0.000526"], ["84045", "0.001333"]], "a": [["84126.1", "0.091306"], ["84126.9", "0.001142"], ["84132.2", "0.005472"], ["84139.9", "0.016587"], ["84140.2", "0.074681"], ["84151.4", "1.405931"], ["84162.8", "0.001333"], ["84165.5", "0.356841"], ["84178.5", "0"], ["84179", "0"]], "u": 168148, "seq": 67577221978}, "cts": 1742584935517, "record_time": 1742584935.642345, "EXCHANGE": "BYBIT"}
{"topic": "orderbook.200.BTCUSDT", "ts": 1742584935720, "type": "delta", "data": {"s": "BTCUSDT", "b": [["84110.9", "0.405284"], ["84109.6", "0"], ["84104.6", "0.000333"], ["84103.9", "0.072707"], ["84103.2", "0"], ["84102", "0.071376"], ["84100.8", "0.006233"], ["84099.9", "0.12"], ["84093.9", "0"], ["84092.5", "0.163122"], ["84092", "0.000333"], ["84090.3", "0"], ["84089.3", "0.178382"], ["84088.7", "0"], ["84087.6", "0.178385"], ["84087.3", "0.390598"], ["84086.8", "0"], ["84086.3", "0.178388"], ["84072.7", "0.051333"], ["84071.1", "0.367823"], ["84067.4", "0.118942"], ["84065.6", "0.118539"], ["84064.6", "0.090008"], ["84062.6", "0.356841"], ["84062.5", "0.000333"], ["84061.9", "0.023489"], ["84060.6", "0"], ["84060.5", "0.025713"], ["84055.3", "0.0015"], ["84051.2", "0.360417"], ["84047", "0"]], "a": [["84111", "0.189963"], ["84120.6", "0.018074"], ["84122", "0.188701"], ["84122.7", "0.179536"], ["84130.5", "0"], ["84130.9", "0.118891"], ["84137.9", "0.016587"], ["84139.9", "0"], ["84142.7", "0.293063"], ["84149.9", "0"], ["84154.6", "0"], ["84161.1", "0.000528"], ["84162.9", "2.623385"], ["84165.4", "0.356841"], ["84165.5", "0"], ["84178.5", "0.005184"]], "u": 168149, "seq": 67577222215}, "cts": 1742584935716, "record_time": 1742584935.823216, "EXCHANGE": "BYBIT"}
{"topic": "orderbook.200.BTCUSDT", "ts": 1742584935920, "type": "delta", "data": {"s": "BTCUSDT", "b": [["84110.9", "0.404569"], ["84098.6", "0.125192"], ["84091.2", "0.228289"], ["84089.3", "0"], ["84088.8", "0.172724"], ["84087.3", "0.354924"], ["84087.2", "0.035674"], ["84086.8", "0.178336"], ["84084.9", "0.321011"], ["84080.7", "0.181911"], ["84079.7", "0.27851"], ["84073.4", "0"], ["84071.2", "0.168539"], ["84071", "0.000333"], ["84062.7", "0.356842"], ["84062.6", "0"], ["84060.5", "0"], ["84055.3", "11.545703"], ["84045", "0"]], "a": [["84118.5", "0.268096"], ["84123.8", "0.130113"], ["84127.8", "0.026"], ["84133.6", "0.170083"], ["84134.7", "0.003575"], ["84142.7", "0.30536"], ["84151.4", "0.04"], ["84160.2", "2.621245"], ["84162.9", "0.00214"], ["84165.3", "0.356844"], ["84165.4", "0"], ["84177.1", "0"], ["84177.8", "0"], ["84178.3", "0"], ["84178.5", "0"]], "u": 168150, "seq": 67577222302}, "cts": 1742584935915, "record_time": 1742584936.022381, "EXCHANGE": "BYBIT"}
{"topic": "orderbook.200.BTCUSDT", "ts": 1742584936120, "type": "delta", "data": {"s": "BTCUSDT", "b": [["84110.9", "0.233569"], ["84098.6", "0.005468"], ["84088.8", "0"], ["84084.9", "0.142675"], ["84084.3", "0.178336"], ["84080.7", "0.003575"], ["84079.7", "0"], ["84073", "0.024895"], ["84072.9", "0.026981"], ["84071.9", "0"], ["84071.8", "0"], ["84071.1", "0.049546"], ["84067.4", "0.208931"], ["84064.6", "0"], ["84063.7", "0.356837"], ["84062.7", "0"], ["84045", "0.001333"], ["84043.9", "0.005318"], ["84043.1", "4.054545"], ["84042.8", "0.207638"]], "a": [["84111", "0.360963"], ["84123.8", "0.005452"], ["84133.6", "0"], ["84142.7", "0"], ["84160.2", "0"], ["84162.9", "2.623385"], ["84165.3", "0"], ["84167.9", "0.356837"], ["84177.1", "3.925682"], ["84177.8", "0.246684"], ["84178.3", "0.059399"]], "u": 168151, "seq": 67577222385}, "cts": 1742584936115, "record_time": 1742584936.22216, "EXCHANGE": "BYBIT"}
{"topic": "orderbook.200.BTCUSDT", "ts": 1742584936320, "type": "delta", "data": {"s": "BTCUSDT", "b": [["84092.1", "0.260145"], ["84091.7", "0.060528"], ["84091.6", "0.128516"], ["84091.4", "0"], ["84063.7", "0"], ["84060.5", "0.356846"], ["84059.6", "0.178336"], ["84055.4", "0.190336"]], "a": [["84126", "0"], ["84161.9", "0.358313"], ["84167.9", "0"], ["84178.5", "0.005184"], ["84179.6", "0.001861"]], "u": 168152, "seq": 67577222425}, "cts": 1742584936291, "record_time": 1742584936.423223, "EXCHANGE": "BYBIT"}
{"topic": "orderbook.200.BTCUSDT", "ts": 1742584936520, "type": "delta", "data": {"s": "BTCUSDT", "b": [["84110.9", "0.404569"], ["84099.3", "0.000153"], ["84098.6", "0.119407"], ["84098.3", "0.001"], ["84090.8", "0.064"], ["84090.7", "0.021936"], ["84088.8", "0.186933"], ["84084.9", "0.321011"], ["84084.3", "0"], ["84080.7", "0.181911"], ["84079.7", "0.311376"], ["84062.5", "0.357176"], ["84060.5", "0"], ["84059.6", "0.089168"], ["84055.4", "0.012"], ["84043.9", "0"], ["84043.1", "0"], ["84042.8", "0"]], "a": [["84111", "0.189963"], ["84123.8", "0.125399"], ["84133.6", "0.175603"], ["84142.7", "0.300558"], ["84161.9", "0.001466"], ["84165.5", "0.356843"], ["84178.3", "0"], ["84178.5", "0"], ["84179.6", "0"]], "u": 168153, "seq": 67577222485}, "cts": 1742584936516, "record_time": 1742584936.622059, "EXCHANGE": "BYBIT"}
{"topic": "orderbook.200.BTCUSDT", "ts": 1742584936720, "type": "delta", "data": {"s": "BTCUSDT", "b": [["84110.9", "0.233569"], ["84100.1", "0.000153"], ["84099.3", "0"], ["84098.6", "0.005468"], ["84088.8", "0"], ["84086.8", "0"], ["84084.9", "0.142675"], ["84080.7", "0.003575"], ["84079.7", "0"], ["84074.8", "0.04"], ["84074.7", "0.039634"], ["84073.7", "0"], ["84073.6", "0"], ["84067.4", "0.208935"], ["84062.5", "0.000333"], ["84060.5", "0.356846"], ["84059.6", "0.178336"], ["84055.4", "0.190336"], ["84043.9", "0.005318"], ["84043.1", "4.054545"]], "a": [["84111", "0.360963"], ["84123.8", "0.005452"], ["84133.6", "0"], ["84134.7", "0"], ["84142.7", "0"], ["84148.9", "0.04"], ["84149", "0.13037"], ["84151.4", "0"], ["84151.5", "0.353352"], ["84161.9", "0.358314"], ["84165.5", "0"], ["84178.3", "0.059399"], ["84178.5", "0.005184"], ["84179.6", "0.001861"], ["84180.3", "0.000333"]], "u": 168154, "seq": 67577222547}, "cts": 1742584936716, "record_time": 1742584936.823367, "EXCHANGE": "BYBIT"}
{"topic": "orderbook.200.BTCUSDT", "ts": 1742584936920, "type": "delta", "data": {"s": "BTCUSDT", "b": [["84110.9", "0.406265"], ["84106", "0.02157"], ["84105.9", "0.071372"], ["84103.9", "0.001333"], ["84090.7", "0.021867"], ["84084.3", "0.178336"], ["84076.3", "0.118539"], ["84074.8", "0"], ["84074.7", "0"], ["84074.3", "0.04"], ["84074.2", "0.039634"], ["84073", "0.011895"], ["84072.9", "0.0141"], ["84072.5", "0.109346"], ["84072.4", "0.012881"], ["84071.2", "0.118539"], ["84071.1", "0"], ["84070.7", "0.05"], ["84070.6", "0.049547"], ["84067.4", "0.208924"], ["84060.6", "0.356852"], ["84060.5", "0"], ["84045.9", "0"], ["84045.7", "0"], ["84045.5", "0"], ["84045", "0"], ["84043.9", "0"], ["84043.1", "0"]], "a": [["84111", "0.189537"], ["84118.1", "0.071362"], ["84121.3", "0"], ["84130.8", "0.003575"], ["84148.9", "0"], ["84149", "0.09037"], ["84150.2", "0.04"], ["84150.3", "0.04"], ["84161.8", "0.356852"], ["84161.9", "0.001466"], ["84178.5", "0"], ["84179.6", "0"], ["84180.3", "0"]], "u": 168155, "seq": 67577222628}, "cts": 1742584936911, "record_time": 1742584937.023209, "EXCHANGE": "BYBIT"}
{"topic": "orderbook.200.BTCUSDT", "ts": 1742584937120, "type": "delta", "data": {"s": "BTCUSDT", "b": [["84110.9", "0.405311"], ["84099", "0.001"], ["84098.3", "0.002"], ["84094.8", "0.124822"], ["84087.8", "0.238686"], ["84086.8", "0.178336"], ["84084.9", "0.321011"], ["84084.3", "0"], ["84080.8", "0.299818"], ["84080.7", "0.181911"], ["84072.5", "0.109227"], ["84070.8", "0.05"], ["84070.7", "0.049547"], ["84070.6", "0"], ["84063.7", "0.35684"], ["84060.6", "0"], ["84059.6", "0.089168"], ["84055.4", "0.012"], ["84046.6", "0"], ["84046.4", "0"], ["84046.3", "0"]], "a": [["84127.7", "0.122626"], ["84134.7", "0.16627"], ["84141.7", "0.345936"], ["84161.8", "0"], ["84167.9", "0.356838"], ["84177.8", "0"], ["84178.3", "0"]], "u": 168156, "seq": 67577222674}, "cts": 1742584937109, "record_time": 1742584937.223204, "EXCHANGE": "BYBIT"}
{"topic": "orderbook.200.BTCUSDT", "ts": 1742584937320, "type": "delta", "data": {"s": "BTCUSDT", "b": [["84094.8", "0"], ["84090.7", "0.021831"], ["84087.8", "0.051666"], ["84087.7", "0.542725"], ["84087.3", "0"], ["84080.8", "0"], ["84070.8", "0"], ["84070.6", "0.049547"], ["84070.2", "0.210615"], ["84068.2", "0.356822"], ["84067.4", "0.118942"], ["84063.7", "0"], ["84061.3", "0.025713"], ["84055.3", "11.622857"], ["84046.6", "0.011841"]], "a": [["84111", "0.09987"], ["84126.1", "0.178026"], ["84126.9", "0.179478"], ["84127.7", "0"], ["84130.8", "0.104982"], ["84134.7", "0"], ["84141.7", "0.060832"], ["84148.5", "0.283748"], ["84157.7", "0"], ["84162.9", "0.00214"], ["84165.7", "2.621773"], ["84167.9", "0"], ["84170", "0.359665"], ["84177.8", "0.246684"], ["84178.3", "0.059399"], ["84178.5", "0.005184"]], "u": 168157, "seq": 67577222749}, "cts": 1742584937316, "record_time": 1742584937.429714, "EXCHANGE": "BYBIT"}
{"topic": "orderbook.200.BTCUSDT", "ts": 1742584937520, "type": "delta", "data": {"s": "BTCUSDT", "b": [["84107.9", "0.0018"], ["84100.1", "0"], ["84080.9", "0"], ["84079.2", "0.0015"], ["84074.5", "0.04"], ["84074.4", "0.040967"], ["84074.3", "0"], ["84074.2", "0"], ["84072.7", "0.064214"], ["84072.6", "0.012881"], ["84072.5", "0.096346"], ["84072.4", "0"], ["84071", "0.050333"], ["84070.9", "0.049547"], ["84070.7", "0"], ["84070.6", "0"], ["84070.2", "0.210613"], ["84058.1", "11.680828"], ["84055.3", "0.0015"], ["84046.4", "0.023784"], ["84046.3", "0.001466"]], "a": [["84149.4", "0.04"], ["84149.5", "0.04"], ["84150.2", "0"], ["84150.3", "0"], ["84162.9", "2.623385"], ["84165.7", "0.000528"], ["84170", "0.002841"], ["84172", "0.356818"], ["84178.5", "0"]], "u": 168158, "seq": 67577222850}, "cts": 1742584937502, "record_time": 1742584937.621799, "EXCHANGE": "BYBIT"}
{"topic": "orderbook.200.BTCUSDT", "ts": 1742584937719, "type": "delta", "data": {"s": "BTCUSDT", "b": [["84110.9", "0.216468"], ["84090.7", "0.021804"], ["84084.9", "0.142675"], ["84080.7", "0.003575"], ["84074.6", "0.04"], ["84074.5", "0.039634"], ["84074.4", "0.001333"], ["84072.8", "0.013"], ["84072.6", "0"], ["84068.3", "0.380928"], ["84068.2", "0"], ["84061.3", "0"], ["84059.6", "0"], ["84058.1", "0.059471"], ["84049.8", "11.645141"], ["84045.9", "0.059399"], ["84045.7", "0.000333"]], "a": [["84111", "0.28586"], ["84113.6", "0.018538"], ["84115.4", "0.088812"], ["84117", "0"], ["84126.1", "0.091306"], ["84126.9", "0.001142"], ["84130.8", "0.101407"], ["84149.4", "0"], ["84149.6", "0.04"], ["84170", "0.359663"], ["84172", "0"], ["84178.5", "0.005184"], ["84179.6", "0.001861"]], "u": 168159, "seq": 67577222934}, "cts": 1742584937708, "record_time": 1742584937.821483, "EXCHANGE": "BYBIT"}
{"topic": "orderbook.200.BTCUSDT", "ts": 1742584937919, "type": "delta", "data": {"s": "BTCUSDT", "b": [["84098.2", "0.001"], ["84070.2", "0.210611"], ["84068.3", "0.024108"], ["84067", "0.358609"], ["84055.3", "11.622857"], ["84049.8", "0.023784"], ["84045.7", "0"]], "a": [["84111", "0.11486"], ["84113.6", "0.038005"], ["84114.9", "0.003575"], ["84160.2", "2.621245"], ["84162.9", "0.00214"], ["84169", "0.356824"], ["84170", "0.002841"], ["84178.3", "0"], ["84178.5", "0"], ["84179.6", "0"]], "u": 168160, "seq": 67577223022}, "cts": 1742584937916, "record_time": 1742584938.021728, "EXCHANGE": "BYBIT"}
{"topic": "orderbook.200.BTCUSDT", "ts": 1742584938120, "type": "delta", "data": {"s": "BTCUSDT", "b": [["84110.9", "0.217268"], ["84098.3", "0.002999"], ["84084.3", "0.178336"], ["84070.2", "0.120633"], ["84067.4", "0.20892"], ["84067", "0.001783"], ["84063.9", "0.178864"], ["84063.7", "0.356833"], ["84059.6", "0.178336"], ["84046.4", "0"], ["84046.3", "0"], ["84045.9", "0"]], "a": [["84111", "0.297669"], ["84111.7", "0.003575"], ["84114.9", "0"], ["84154.6", "2.621245"], ["84160.2", "0"], ["84167.9", "0.35683"], ["84169", "0"]], "u": 168161, "seq": 67577223112}, "cts": 1742584938116, "record_time": 1742584938.223207, "EXCHANGE": "BYBIT"}
{"topic": "orderbook.200.BTCUSDT", "ts": 1742584938320, "type": "delta", "data": {"s": "BTCUSDT", "b": [["84106", "0"], ["84086.8", "0"], ["84074.6", "0"], ["84074.4", "0.040967"], ["84073", "0.024895"], ["84072.9", "0.026981"], ["84072.8", "0"], ["84072.7", "0.051333"], ["84071.3", "0.049546"], ["84071.2", "0.168085"], ["84071", "0.000333"], ["84070.9", "0"], ["84070.3", "0.262521"], ["84063.9", "0.000528"], ["84063.7", "0"], ["84061.9", "0"], ["84060.5", "0.356847"], ["84059.6", "0"], ["84055.4", "0.190336"], ["84051.2", "0.538753"], ["84046.4", "0.023784"], ["84046.3", "0.001466"], ["84045.9", "0.059399"], ["84045.7", "0.000333"], ["84045.5", "0.000526"]], "a": [["84111", "0.299809"], ["84111.7", "0"], ["84124.7", "0.003575"], ["84148.4", "0.195858"], ["84149", "0.005477"], ["84149.5", "0"], ["84149.7", "0.04"], ["84161.2", "0.024284"], ["84162.9", "0"], ["84163.4", "0.356848"], ["84167.9", "0"]], "u": 168162, "seq": 67577223179}, "cts": 1742584938316, "record_time": 1742584938.421853, "EXCHANGE": "BYBIT"}
{"topic": "orderbook.200.BTCUSDT", "ts": 1742584938520, "type": "delta", "data": {"s": "BTCUSDT", "b": [["84074.5", "0"], ["84074.3", "0.039634"], ["84073", "0.011895"], ["84072.9", "0.0141"], ["84072.6", "0.012881"], ["84072.5", "0.109227"], ["84071.3", "0"], ["84071.2", "0.118539"], ["84070.8", "0.049547"], ["84070.7", "0.049547"], ["84060.5", "0"], ["84058.5", "0.356855"], ["84055.4", "0.012"], ["84051.2", "0.360417"], ["84045.7", "0"], ["84045.5", "0"]], "a": [["84149.6", "0"], ["84149.7", "0"], ["84149.9", "0.04"], ["84150", "0.04"], ["84161.9", "0.35832"], ["84163.4", "0"], ["84178.3", "0.059399"]], "u": 168163, "seq": 67577223216}, "cts": 1742584938511, "record_time": 1742584938.623233, "EXCHANGE": "BYBIT"}
{"topic": "orderbook.200.BTCUSDT", "ts": 1742584938720, "type": "delta", "data": {"s": "BTCUSDT", "b": [["84106", "0.02157"], ["84074.5", "0.04"], ["84074.3", "0"], ["84072.7", "0.064333"], ["84072.5", "0.096346"], ["84070.9", "0.05"], ["84070.7", "0"], ["84067.4", "0.118942"], ["84064.6", "0.089978"], ["84063.9", "0.178864"], ["84059.6", "0.178336"], ["84046.4", "0"], ["84046.3", "0"], ["84045.9", "0"]], "a": [["84111", "0.301593"], ["84124.7", "0"], ["84149.6", "0.04"], ["84149.7", "0.04"], ["84149.9", "0"], ["84150", "0"], ["84178.5", "0.005184"]], "u": 168164, "seq": 67577223244}, "cts": 1742584938715, "record_time": 1742584938.822362, "EXCHANGE": "BYBIT"}
{"topic": "orderbook.200.BTCUSDT", "ts": 1742584938920, "type": "delta", "data": {"s": "BTCUSDT", "b": [["84106", "0"], ["84105.9", "0"], ["84104.1", "0.071374"], ["84097", "0.191407"], ["84087.2", "0.22047"], ["84078.1", "0.27888"], ["84074.7", "0.04"], ["84074.6", "0.039634"], ["84074.5", "0"], ["84074.4", "0.001333"], ["84071.3", "0.049546"], ["84071.2", "0.168085"], ["84070.9", "0"], ["84070.8", "0"], ["84064.6", "0"], ["84063.9", "0.000528"], ["84061.8", "0.091311"], ["84059.6", "0"], ["84055.4", "0.190336"], ["84051.2", "0.538753"], ["84046.4", "0.023784"], ["84046.3", "0.001466"]], "a": [["84111", "0.299809"], ["84120.4", "0.023778"], ["84122.2", "0.11836"], ["84132", "0.166814"], ["84135.7", "0.013513"], ["84141.1", "0.297655"], ["84149.4", "0.04"], ["84149.5", "0.04"], ["84149.6", "0"], ["84149.7", "0"], ["84177.1", "0"], ["84177.8", "0"], ["84178.3", "0"], ["84178.5", "0"]], "u": 168165, "seq": 67577223285}, "cts": 1742584938892, "record_time": 1742584939.02328, "EXCHANGE": "BYBIT"}
{"topic": "orderbook.200.BTCUSDT", "ts": 1742584939119, "type": "delta", "data": {"s": "BTCUSDT", "b": [["84110.9", "0.388268"], ["84106.6", "0.02201"], ["84106.5", "0.071372"], ["84102.7", "0.001282"], ["84102", "0"], ["84097", "0.079911"], ["84095.4", "0.019911"], ["84095.2", "0.05"], ["84093.6", "0.055351"], ["84092.5", "0.113122"], ["84092.3", "0.05"], ["84091.6", "0.078516"], ["84091.5", "0.05"], ["84087.2", "0.035674"], ["84086.8", "0.178336"], ["84086.6", "0.076357"], ["84084.9", "0.321011"], ["84084.3", "0"], ["84080.7", "0.181911"], ["84079.6", "0.115404"], ["84078.1", "0"], ["84074.7", "0"], ["84074.6", "0"], ["84074.4", "0.041333"], ["84074.3", "0.039634"], ["84072.7", "0.051333"], ["84072.5", "0.109227"], ["84071.3", "0"], ["84071.2", "0.118539"], ["84070.8", "0.05"], ["84070.7", "0.049547"], ["84070.2", "0.210619"], ["84062.5", "0.357177"], ["84061.8", "0.001333"], ["84059.6", "0.089168"], ["84058.5", "0"], ["84055.4", "0.012"], ["84051.2", "0.360417"], ["84047.5", "0"], ["84047.4", "0"], ["84046.6", "0"], ["84046.4", "0"], ["84046.3", "0"]], "a": [["84111", "0.216236"], ["84113.6", "0.035005"], ["84120.4", "0"], ["84122.2", "0"], ["84128.6", "0.057953"], ["84132", "0"], ["84135.6", "0.05779"], ["84141.1", "0"], ["84142.6", "0.112571"], ["84149.4", "0"], ["84149.5", "0"], ["84149.7", "0.04"], ["84149.8", "0.0406"], ["84153.5", "0.172783"], ["84154.6", "0"], ["84157.4", "2.626429"], ["84161.9", "0.001466"], ["84165.5", "0.356848"], ["84177.1", "3.925682"], ["84177.8", "0.246684"], ["84178.3", "0.059399"]], "u": 168166, "seq": 67577223378}, "cts": 1742584939117, "record_time": 1742584939.222125, "EXCHANGE": "BYBIT"}
{"topic": "orderbook.200.BTCUSDT", "ts": 1742584939320, "type": "delta", "data": {"s": "BTCUSDT", "b": [["84095.7", "0.171"], ["84095.5", "0.051333"], ["84093.6", "0.060727"], ["84090.7", "0"], ["84090.6", "0.021832"], ["84086.6", "0.07981"], ["84079.6", "0.114647"], ["84074.1", "0.103713"], ["84070.8", "0.049547"], ["84066", "0.358162"], ["84062.5", "0.000333"], ["84058.1", "11.827012"], ["84055.3", "0.0015"], ["84047.6", "0"]], "a": [["84115.4", "0.017448"], ["84116.5", "0.072696"], ["84118.1", "0"], ["84120.1", "0.122693"], ["84126.1", "0.159502"], ["84126.9", "0.179478"], ["84128.6", "0.060878"], ["84135.6", "0.057202"], ["84142.6", "0.120885"], ["84152", "0.521538"], ["84165.5", "0"], ["84169", "0.356829"]], "u": 168167, "seq": 67577223449}, "cts": 1742584939305, "record_time": 1742584939.422583, "EXCHANGE": "BYBIT"}
{"topic": "orderbook.200.BTCUSDT", "ts": 1742584939520, "type": "delta", "data": {"s": "BTCUSDT", "b": [["84110.9", "0.217268"], ["84102.7", "0.001129"], ["84095.2", "0"], ["84095.1", "0.142"], ["84093.6", "0"], ["84092.3", "0"], ["84092.2", "0.074222"], ["84091.5", "0"], ["84091.4", "0.05"], ["84090.6", "0"], ["84090.5", "0.02205"], ["84086.6", "0.019911"], ["84079.6", "0"], ["84070.2", "0.21062"], ["84066", "0.001333"], ["84063.7", "0.356833"], ["84058.1", "0.059471"], ["84055.3", "11.769041"], ["84047.6", "0.011841"], ["84047.5", "0.011841"], ["84047.4", "0.00588"]], "a": [["84111", "0.390811"], ["84126.1", "0.091306"], ["84126.9", "0.001142"], ["84128.6", "0"], ["84135.6", "0"], ["84135.7", "0.009938"], ["84142.6", "0.00053"], ["84167.9", "0.356833"], ["84169", "0"], ["84178.5", "0.005184"], ["84179.6", "0.001861"]], "u": 168168, "seq": 67577223519}, "cts": 1742584939507, "record_time": 1742584939.623239, "EXCHANGE": "BYBIT"}
{"topic": "orderbook.200.BTCUSDT", "ts": 1742584939720, "type": "delta", "data": {"s": "BTCUSDT", "b": [["84074.5", "0.04"], ["84074.4", "0.040967"], ["84074.3", "0"], ["84072.7", "0.064333"], ["84072.5", "0.096346"], ["84070.9", "0.05"], ["84070.7", "0"], ["84070.2", "0.210573"], ["84063.8", "0.356834"], ["84063.7", "0"]], "a": [["84111", "0.2198"], ["84113.6", "0.038005"], ["84149.6", "0.04"], ["84149.8", "0.0006"], ["84167.8", "0.356834"], ["84167.9", "0"], ["84179.6", "0"]], "u": 168169, "seq": 67577223556}, "cts": 1742584939702, "record_time": 1742584939.822633, "EXCHANGE": "BYBIT"}
{"topic": "orderbook.200.BTCUSDT", "ts": 1742584939920, "type": "delta", "data": {"s": "BTCUSDT", "b": [["84110.9", "0.132944"], ["84107.9", "0"], ["84106.6", "0"], ["84106.5", "0"], ["84105.8", "0.071372"], ["84102.8", "0.005468"], ["84102.7", "0"], ["84100.8", "0.00009"], ["84095.1", "0.092"], ["84093", "0"], ["84092.7", "0.05"], ["84092.2", "0.024222"], ["84091.4", "0"], ["84091.2", "0.049911"], ["84089.8", "0.009225"], ["84088.2", "0.178384"], ["84087.2", "0"], ["84086.8", "0"], ["84084.9", "0.023784"], ["84080.7", "0.003575"], ["84076.3", "0"], ["84074.5", "0"], ["84074.3", "0.039634"], ["84072.7", "0.051333"], ["84072.5", "0.109227"], ["84070.9", "0"], ["84070.7", "0.049547"], ["84070.2", "0.120633"], ["84070.1", "0"], ["84063.8", "0"], ["84061.8", "0.091273"], ["84060.4", "0"], ["84059.6", "0"], ["84055.4", "0.368869"], ["84055.3", "0.0015"], ["84046.6", "0.011841"], ["84046.4", "0.023784"], ["84046.3", "0.001466"], ["84045.9", "0.059399"], ["84045.7", "0.000333"], ["84045.5", "0.000526"], ["84045", "0.001333"], ["84043.9", "0.005318"], ["84043.1", "4.054545"]], "a": [["84111", "0.394366"], ["84111.6", "0.001"], ["84113.6", "0.05698"], ["84117.4", "0.071363"], ["84118.5", "0.08976"], ["84120.1", "0.051333"], ["84120.4", "0.023778"], ["84122.9", "0.009938"], ["84130", "0.118891"], ["84135.7", "0"], ["84144.5", "0.030229"], ["84148.6", "0.023264"], ["84149.3", "0.051462"], ["84149.6", "0"], ["84149.7", "0"], ["84149.8", "0.0406"], ["84149.9", "0.04"], ["84152.1", "0.0006"], ["84153.1", "0"], ["84153.5", "0.171"], ["84157.3", "0.358335"], ["84157.4", "0.027244"], ["84161.2", "0"], ["84167.8", "0"], ["84178.5", "0"]], "u": 168170, "seq": 67577224006}, "cts": 1742584939917, "record_time": 1742584940.022142, "EXCHANGE": "BYBIT"}
{"topic": "orderbook.200.BTCUSDT", "ts": 1742584940120, "type": "delta", "data": {"s": "BTCUSDT", "b": [["84110.9", "0.217907"], ["84104.1", "0"], ["84103.4", "0.162742"], ["84101.9", "0.071376"], ["84095.5", "0.001333"], ["84093", "0.05"], ["84092.2", "0"], ["84090.5", "0"], ["84090.3", "0.17838"], ["84088.2", "0"], ["84088.1", "0.02169"], ["84087.7", "0.389354"], ["84081.7", "0.183801"], ["84076.5", "0.178336"], ["84072.3", "0.178336"], ["84071.8", "0.049546"], ["84071.7", "0.114964"], ["84070.8", "0"], ["84070.7", "0"], ["84064.6", "0.08994"], ["84061.8", "0.001333"], ["84061.5", "0.048"], ["84061.3", "0.064"], ["84059.9", "0.356853"], ["84059.8", "0.182539"], ["84059.7", "0.263"], ["84057.9", "0.064"], ["84056.2", "0.06"], ["84055.4", "0.012"], ["84054.7", "3.593085"], ["84054.6", "0.06"], ["84046.4", "0"], ["84046.3", "0"], ["84045.9", "0"], ["84045.7", "0"], ["84045.5", "0"], ["84045", "0"], ["84043.9", "0"], ["84043.1", "0"]], "a": [["84113.6", "0.05398"], ["84114", "0.051333"], ["84118.5", "0.268096"], ["84119.2", "0.04"], ["84120.1", "0"], ["84129.9", "0.118539"], ["84144.5", "0.005945"], ["84157.3", "0.001466"], ["84160.9", "0.024284"], ["84161.9", "0.358319"], ["84177.1", "0"], ["84177.8", "0"], ["84178.3", "0"]], "u": 168171, "seq": 67577224115}, "cts": 1742584940115, "record_time": 1742584940.222055, "EXCHANGE": "BYBIT"}
{"topic": "orderbook.200.BTCUSDT", "ts": 1742584940320, "type": "delta", "data": {"s": "BTCUSDT", "b": [["84110.9", "0.218145"], ["84085.4", "0.035675"], ["84075.3", "0.04"], ["84075.2", "0.039966"], ["84074.4", "0.001333"], ["84074.3", "0"], ["84071.9", "0.05"], ["84071.7", "0.065418"], ["84061.6", "0.356848"], ["84059.9", "0"], ["84055.3", "11.843563"], ["84047.4", "0"], ["84046.6", "0"]], "a": [["84124.8", "0.04"], ["84126.1", "0.158967"], ["84147.2", "0.04053"], ["84147.3", "0.04"], ["84149.8", "0.0006"], ["84149.9", "0"], ["84154.6", "2.621245"], ["84161.9", "0.001466"], ["84163.4", "0.356847"], ["84176.2", "0"], ["84176.3", "0"]], "u": 168172, "seq": 67577224154}, "cts": 1742584940296, "record_time": 1742584940.422647, "EXCHANGE": "BYBIT"}
{"topic": "orderbook.200.BTCUSDT", "ts": 1742584940520, "type": "delta", "data": {"s": "BTCUSDT", "b": [["84100.8", "0.006282"], ["84098.3", "0.001999"], ["84079.7", "0.023778"], ["84074.1", "0.174113"], ["84073.7", "0.013"], ["84073.6", "0.012881"], ["84072.6", "0"], ["84072.5", "0.096346"], ["84061.6", "0"], ["84059.9", "0.356854"], ["84047.6", "0"], ["84047.5", "0"]], "a": [["84126.9", "0.179478"]], "u": 168173, "seq": 67577224184}, "cts": 1742584940513, "record_time": 1742584940.62171, "EXCHANGE": "BYBIT"}
{"topic": "orderbook.200.BTCUSDT", "ts": 1742584940719, "type": "delta", "data": {"s": "BTCUSDT", "b": [["84110.9", "0.146777"], ["84108.8", "0.07137"], ["84105.8", "0"], ["84103.6", "0.071374"], ["84103.4", "0.01584"], ["84102.6", "0.136712"], ["84101.9", "0"], ["84100.8", "0.00009"], ["84100", "0.226243"], ["84096.9", "0.11429"], ["84092.8", "0.111931"], ["84086.4", "0.165562"], ["84085.8", "0.185131"], ["84085.3", "0.059399"], ["84085.2", "0"], ["84079.4", "0.422876"], ["84078.8", "0.330508"], ["84075.5", "0.04"], ["84075.4", "0.039633"], ["84075.3", "0"], ["84075.2", "0.000333"], ["84071.9", "0"], ["84071.7", "0.114964"], ["84059.9", "0"], ["84059.6", "0.089168"], ["84058.2", "0.356862"], ["84055.3", "0.0015"], ["84049.8", "0"], ["84049.3", "0"], ["84049.2", "0"], ["84048.8", "0"], ["84048.3", "0"], ["84048.1", "0"]], "a": [["84121.4", "0.116763"], ["84125.7", "0.116325"], ["84131.9", "0.177446"], ["84132.7", "0.180873"], ["84138.9", "0.305246"], ["84139.7", "0.289141"], ["84146.5", "0.051462"], ["84146.8", "0.04"], ["84146.9", "0.04"], ["84147.2", "0.00053"], ["84147.3", "0"], ["84149.3", "0"], ["84161.9", "0.358328"], ["84163.4", "0"], ["84175.3", "0"], ["84175.4", "0"], ["84175.8", "0"], ["84175.9", "0"], ["84176.1", "0"]], "u": 168174, "seq": 67577224286}, "cts": 1742584940716, "record_time": 1742584940.842088, "EXCHANGE": "BYBIT"}
{"topic": "orderbook.200.BTCUSDT", "ts": 1742584940920, "type": "delta", "data": {"s": "BTCUSDT", "b": [["84110.9", "0.218145"], ["84108.8", "0"], ["84105.2", "0.071373"], ["84100", "0.154866"], ["84097.4", "0.123353"], ["84096.9", "0"], ["84092.8", "0"], ["84086.9", "0.175735"], ["84086.4", "0"], ["84085.8", "0"], ["84079.9", "0.345169"], ["84079.4", "0.125357"], ["84078.8", "0.023778"], ["84075.5", "0.039633"], ["84073.7", "0.012881"], ["84071.9", "0.05"], ["84071.7", "0.065418"], ["84058.5", "0.356858"], ["84058.2", "0"], ["84049.8", "0.023784"]], "a": [["84121.4", "0.000333"], ["84121.9", "0.115375"], ["84125.7", "0"], ["84131.9", "0"], ["84132.4", "0.170867"], ["84132.7", "0"], ["84138.8", "0.254589"], ["84138.9", "0"], ["84139.4", "0.279"], ["84139.7", "0"], ["84140.2", "0"], ["84146.8", "0"], ["84147", "0.04"], ["84154.6", "0"], ["84157.4", "2.648489"], ["84161.9", "0.001466"], ["84163.4", "0.356858"], ["84175.3", "0.0015"], ["84175.4", "0.013333"], ["84175.8", "0.120005"]], "u": 168175, "seq": 67577224374}, "cts": 1742584940913, "record_time": 1742584941.02257, "EXCHANGE": "BYBIT"}
{"topic": "orderbook.200.BTCUSDT", "ts": 1742584941119, "type": "delta", "data": {"s": "BTCUSDT", "b": [["84100.8", "0.00618"], ["84098.3", "0.000999"]], "a": [["84111", "0.400366"], ["84138.8", "0.001466"], ["84145.7", "0.035675"], ["84147.6", "0"], ["84152.1", "0"], ["84152.2", "0"], ["84152.5", "0"], ["84156.4", "0.015"], ["84160", "0"], ["84161.9", "0.358325"], ["84163.4", "0"], ["84175.9", "1.026423"], ["84176.1", "0.040333"], ["84176.2", "0.12"], ["84176.3", "0.04"], ["84177.1", "3.925682"]], "u": 168176, "seq": 67577224416}, "cts": 1742584941108, "record_time": 1742584941.221492, "EXCHANGE": "BYBIT"}
{"success": true, "ret_msg": "pong", "conn_id": "db9a9825-b0cd-4231-ad46-55f33c5e50d2", "op": "ping", "record_time": 1742584941.418711, "EXCHANGE": "BYBIT"}
{"topic": "orderbook.200.BTCUSDT", "ts": 1742584941319, "type": "delta", "data": {"s": "BTCUSDT", "b": [["84099", "0"], ["84089.6", "0.024128"]], "a": [["84111", "0.404715"], ["84114.9", "0.071365"], ["84117.4", "0"], ["84146.9", "0"], ["84147.1", "0.04"], ["84151.5", "0"], ["84154.6", "2.621245"], ["84157.4", "0.027244"], ["84161.9", "0.001466"], ["84163.4", "0.356857"], ["84177.1", "0"]], "u": 168177, "seq": 67577224449}, "cts": 1742584941316, "record_time": 1742584941.421741, "EXCHANGE": "BYBIT"}
{"topic": "orderbook.200.BTCUSDT", "ts": 1742584941520, "type": "delta", "data": {"s": "BTCUSDT", "b": [["84110.9", "0.146777"], ["84109.7", "0.071369"], ["84105.2", "0"], ["84103.9", "0.003333"], ["84101.3", "0.071376"], ["84097.4", "0"], ["84097", "0.198722"], ["84092.9", "0.120725"], ["84086.9", "0"], ["84086.5", "0.184632"], ["84085.9", "0.196484"], ["84079.9", "0.049911"], ["84079.5", "0.289515"], ["84079.2", "0"], ["84078.9", "0.495428"], ["84076.6", "0.118539"], ["84075.2", "0.001933"], ["84058.5", "0.35686"], ["84049.9", "0"], ["84049.8", "0"]], "a": [["84121.5", "0.117089"], ["84121.9", "0"], ["84125.8", "0.124204"], ["84126.1", "0.221032"], ["84132", "0.182544"], ["84132.4", "0"], ["84132.8", "0.223877"], ["84139", "0.295523"], ["84139.4", "0"], ["84139.8", "0.293659"], ["84146.8", "0.04"], ["84146.9", "0.04"], ["84147", "0"], ["84147.1", "0"], ["84161.9", "0.358324"], ["84163.4", "0"], ["84175.8", "0.47325"], ["84176.3", "0"]], "u": 168178, "seq": 67577224534}, "cts": 1742584941513, "record_time": 1742584941.621735, "EXCHANGE": "BYBIT"}
{"topic": "orderbook.200.BTCUSDT", "ts": 1742584941720, "type": "delta", "data": {"s": "BTCUSDT", "b": [["84110.9", "0.155989"], ["84097.2", "0.121901"], ["84097", "0.079911"], ["84093.1", "0.132283"], ["84092.9", "0"], ["84086.7", "0.177296"], ["84086.5", "0"], ["84086.1", "0.174214"], ["84085.9", "0.010163"], ["84079.7", "0.300229"], ["84079.5", "0.426115"], ["84079.1", "0.28273"], ["84078.9", "0"], ["84058.5", "0"], ["84058", "0.35686"]], "a": [["84121.5", "0"], ["84121.7", "0.110396"], ["84125.8", "0"], ["84126", "0.112318"], ["84132", "0"], ["84132.2", "0.169876"], ["84132.8", "0.059399"], ["84133", "0.166843"], ["84139", "0"], ["84139.2", "0.30564"], ["84139.8", "0"], ["84140", "0.30014"], ["84176.3", "0.04"]], "u": 168179, "seq": 67577224618}, "cts": 1742584941713, "record_time": 1742584941.823561, "EXCHANGE": "BYBIT"}
{"topic": "orderbook.200.BTCUSDT", "ts": 1742584941919, "type": "delta", "data": {"s": "BTCUSDT", "b": [["84105.1", "0.071373"], ["84103.6", "0"], ["84102.6", "0"], ["84098.2", "0"], ["84097.2", "0"], ["84093.1", "0.009063"], ["84086.7", "0"], ["84086.1", "0.005945"], ["84079.7", "0.023778"], ["84079.1", "0"], ["84058", "0"], ["84056.3", "0.356866"], ["84049.9", "0.000333"], ["84049.8", "0.023784"], ["84049.3", "0.059471"], ["84049.2", "0.001333"], ["84048.8", "0.023789"]], "a": [["84121.7", "0"], ["84126", "0"], ["84132.2", "0.005472"], ["84133", "0"], ["84139.2", "0"], ["84140", "0.00042"], ["84146.8", "0"], ["84146.9", "0"], ["84147", "0.04"], ["84147.1", "0.04"], ["84160.3", "0.356866"], ["84161.9", "0.001466"], ["84177.1", "3.925682"], ["84177.8", "0.246684"], ["84178.3", "0.059399"]], "u": 168180, "seq": 67577224663}, "cts": 1742584941899, "record_time": 1742584942.022495, "EXCHANGE": "BYBIT"}
{"topic": "orderbook.200.BTCUSDT", "ts": 1742584942119, "type": "delta", "data": {"s": "BTCUSDT", "b": [["84110.9", "0.15592"], ["84109.7", "0"], ["84108.7", "0.07137"], ["84105.1", "0"], ["84103.4", "0.087214"], ["84100.8", "0.00009"], ["84099.8", "0.000153"], ["84098.3", "0"], ["84092.7", "0"], ["84092.6", "0.05"], ["84090.3", "0"], ["84088.1", "0"], ["84088", "0.021751"], ["84087.6", "0.35677"], ["84085.4", "0"], ["84085.3", "0.095074"], ["84084.9", "0"], ["84084", "0.00009"], ["84076.6", "0"], ["84076.5", "0"], ["84075.5", "0"], ["84075.4", "0"], ["84074.7", "0.04"], ["84074.6", "0.039634"], ["84073.7", "0"], ["84073.6", "0"], ["84072.9", "0.0271"], ["84072.8", "0.012881"], ["84072.3", "0"], ["84071.9", "0"], ["84071.8", "0"], ["84071.1", "0.05"], ["84071", "0.04988"], ["84059.6", "0"], ["84056.3", "0"], ["84054.8", "0.356874"], ["84048.3", "0.118539"], ["84048.1", "0.005682"], ["84047.6", "0.011841"], ["84047.5", "0.011841"], ["84047.4", "0.00588"], ["84047", "11.790191"], ["84046.6", "0.011841"], ["84046.4", "0.023784"], ["84046.3", "0.001466"], ["84045.9", "0.059399"]], "a": [["84160.3", "0.356864"]], "u": 168181, "seq": 67577224762}, "cts": 1742584942114, "record_time": 1742584942.222257, "EXCHANGE": "BYBIT"}
{"topic": "orderbook.200.BTCUSDT", "ts": 1742584942320, "type": "delta", "data": {"s": "BTCUSDT", "b": [["84110.9", "0.17972"], ["84109.7", "0.071369"], ["84108.7", "0"], ["84104.9", "0.071373"], ["84103.4", "0.01584"], ["84100.2", "0.006139"], ["84097.3", "0.115988"], ["84093", "0"], ["84092.9", "0.05"], ["84092.1", "0.195099"], ["84087.5", "0.185116"], ["84079.5", "0"], ["84078.4", "0.272711"], ["84076.5", "0.178336"], ["84074.1", "0.103713"], ["84072.9", "0.0141"], ["84072.7", "0.064214"], ["84072.3", "0.178336"], ["84059.9", "0.356853"], ["84054.8", "0"], ["84047.4", "0"], ["84047", "0"], ["84046.6", "0"], ["84046.4", "0"], ["84046.3", "0"], ["84045.9", "0"]], "a": [["84111", "0.410715"], ["84113.5", "0.001"], ["84122.5", "0.158"], ["84131.5", "0"], ["84132.3", "0.179552"], ["84141.4", "0.286195"], ["84146.6", "0.040333"], ["84146.7", "0.04"], ["84147", "0"], ["84147.1", "0"], ["84160.3", "0"], ["84163.4", "0.356851"], ["84178.3", "0"]], "u": 168182, "seq": 67577224839}, "cts": 1742584942308, "record_time": 1742584942.422293, "EXCHANGE": "BYBIT"}
{"topic": "orderbook.200.BTCUSDT", "ts": 1742584942520, "type": "delta", "data": {"s": "BTCUSDT", "b": [["84110.9", "0.17892"], ["84101.9", "0.000153"], ["84099.8", "0"], ["84097.3", "0"], ["84087.5", "0"], ["84078.4", "0"], ["84074.7", "0"], ["84074.5", "0.039634"], ["84071.1", "0"], ["84070.9", "0.049547"], ["84059.9", "0"], ["84058.5", "0.35686"], ["84047.4", "0.00588"], ["84047", "11.790191"], ["84046.6", "0.011841"]], "a": [["84122.5", "0.04"], ["84132.3", "0"], ["84140.2", "0.160539"], ["84141.4", "0"], ["84146.5", "0.051464"], ["84161.9", "0.358326"], ["84163.4", "0"], ["84178.3", "0.059399"], ["84178.5", "0.005184"]], "u": 168183, "seq": 67577224874}, "cts": 1742584942504, "record_time": 1742584942.623395, "EXCHANGE": "BYBIT"}
{"topic": "orderbook.200.BTCUSDT", "ts": 1742584942720, "type": "delta", "data": {"s": "BTCUSDT", "b": [["84101.9", "0"], ["84074.7", "0.04"], ["84074.5", "0"], ["84071.1", "0.05"], ["84070.9", "0"], ["84059.6", "0.089168"]], "a": [["84140.2", "0"], ["84178.3", "0.087245"], ["84179.6", "0.001861"]], "u": 168184, "seq": 67577224895}, "cts": 1742584942689, "record_time": 1742584942.822171, "EXCHANGE": "BYBIT"}
{"topic": "orderbook.200.BTCUSDT", "ts": 1742584942920, "type": "delta", "data": {"s": "BTCUSDT", "b": [], "a": [["84135.7", "0.00337"], ["84179.6", "0"]], "u": 168185, "seq": 67577224904}, "cts": 1742584942910, "record_time": 1742584943.022859, "EXCHANGE": "BYBIT"}
{"topic": "orderbook.200.BTCUSDT", "ts": 1742584943120, "type": "delta", "data": {"s": "BTCUSDT", "b": [["84110.9", "0.250288"], ["84109.7", "0"], ["84102.5", "0.382398"], ["84088", "0.021744"], ["84072.9", "0.0271"], ["84072.7", "0.051333"], ["84059.9", "0.356858"], ["84058.5", "0"], ["84046.4", "0.023784"]], "a": [["84111", "0.41314"], ["84131.5", "0.006236"], ["84161.9", "0.001466"], ["84163.4", "0.356857"], ["84178.3", "0"], ["84178.5", "0"]], "u": 168186, "seq": 67577224961}, "cts": 1742584943110, "record_time": 1742584943.221821, "EXCHANGE": "BYBIT"}
{"topic": "orderbook.200.BTCUSDT", "ts": 1742584943319, "type": "delta", "data": {"s": "BTCUSDT", "b": [["84102.5", "0.382245"], ["84076.6", "0.118539"], ["84076.2", "0.060444"], ["84059.9", "0.356859"], ["84046.4", "0"]], "a": [["84161.9", "0.358325"], ["84163.4", "0"], ["84178.3", "0.087245"]], "u": 168187, "seq": 67577224983}, "cts": 1742584943315, "record_time": 1742584943.422582, "EXCHANGE": "BYBIT"}
{"topic": "orderbook.200.BTCUSDT", "ts": 1742584943520, "type": "delta", "data": {"s": "BTCUSDT", "b": [["84106.2", "0.071372"], ["84103.4", "0.141375"], ["84103.2", "0.000153"], ["84101.3", "0"], ["84089.1", "0.003575"], ["84088", "0.021686"], ["84074.7", "0"], ["84074.6", "0"], ["84074.4", "0.040967"], ["84074.3", "0.039634"], ["84072.9", "0.0141"], ["84072.8", "0"], ["84072.6", "0.012881"], ["84072.5", "0.109227"], ["84071.1", "0"], ["84071", "0.000333"], ["84070.8", "0.049547"], ["84070.7", "0.049547"], ["84063.6", "0.353323"], ["84059.9", "0.356858"], ["84055.2", "11.648433"], ["84047.4", "0"], ["84047", "0"], ["84046.6", "0"]], "a": [["84135", "1.14057"], ["84140.2", "0.074681"], ["84146.6", "0.000333"], ["84146.7", "0"], ["84147.1", "0.04"], ["84147.2", "0.04053"], ["84154.6", "0"], ["84157.4", "2.626425"], ["84161.9", "0.001466"], ["84163.4", "0.356855"], ["84178.3", "0"]], "u": 168188, "seq": 67577225041}, "cts": 1742584943477, "record_time": 1742584943.622216, "EXCHANGE": "BYBIT"}
{"topic": "orderbook.200.BTCUSDT", "ts": 1742584943719, "type": "delta", "data": {"s": "BTCUSDT", "b": [["84092.6", "0"], ["84092.5", "0.163122"], ["84088", "0"], ["84087.9", "0.023405"], ["84078.6", "0.278264"], ["84074.4", "0.001333"], ["84074.2", "0.039634"], ["84072.6", "0"], ["84072.4", "0.012881"], ["84070.8", "0.05"], ["84055.2", "0"], ["84053.6", "0"], ["84049.7", "11.68608"], ["84047.9", "0.000149"], ["84047.4", "0.00588"]], "a": [["84131.5", "0.007219"], ["84161.6", "0.000145"], ["84167.3", "0"]], "u": 168189, "seq": 67577225083}, "cts": 1742584943716, "record_time": 1742584943.821492, "EXCHANGE": "BYBIT"}
{"topic": "orderbook.200.BTCUSDT", "ts": 1742584943919, "type": "delta", "data": {"s": "BTCUSDT", "b": [["84110.9", "0.15512"], ["84109.8", "0.071369"], ["84106.2", "0"], ["84103.2", "0"], ["84102.5", "0.45362"], ["84092.9", "0"], ["84092.8", "0.05"], ["84092.2", "0.056546"], ["84085.2", "0.055954"], ["84078.2", "0.112624"], ["84074.5", "0.04"], ["84074.4", "0.040967"], ["84074.3", "0"], ["84074.2", "0"], ["84072.7", "0.064333"], ["84072.6", "0.012881"], ["84072.5", "0.096346"], ["84072.4", "0"], ["84070.9", "0.049547"], ["84070.8", "0.049547"], ["84070.7", "0"], ["84059.9", "0"], ["84058.5", "0.356859"], ["84055.2", "11.68608"], ["84049.7", "0"], ["84047.4", "0"]], "a": [["84111.6", "0"], ["84127.2", "0.061986"], ["84134.2", "0.056927"], ["84135", "1.136995"], ["84141.2", "0.110405"], ["84146.6", "0.040333"], ["84146.7", "0.04"], ["84147.1", "0"], ["84147.2", "0.00053"], ["84161.9", "0.358324"], ["84163.4", "0"], ["84177.8", "0"]], "u": 168190, "seq": 67577225132}, "cts": 1742584943895, "record_time": 1742584944.022076, "EXCHANGE": "BYBIT"}
{"topic": "orderbook.200.BTCUSDT", "ts": 1742584944120, "type": "delta", "data": {"s": "BTCUSDT", "b": [["84103.4", "0.01584"], ["84074.7", "0.04"], ["84074.6", "0.039634"], ["84074.5", "0"], ["84074.4", "0.001333"], ["84072.9", "0.0271"], ["84072.8", "0.012881"], ["84072.7", "0.051333"], ["84072.6", "0"], ["84071.1", "0.05"], ["84071", "0.04988"], ["84070.9", "0"], ["84070.8", "0"], ["84060", "0.00006"]], "a": [["84131.5", "0.006236"]], "u": 168191, "seq": 67577225156}, "cts": 1742584944110, "record_time": 1742584944.221896, "EXCHANGE": "BYBIT"}
{"topic": "orderbook.200.BTCUSDT", "ts": 1742584944320, "type": "delta", "data": {"s": "BTCUSDT", "b": [["84110.9", "0.15592"], ["84110.6", "0.071368"], ["84109.8", "0"], ["84103.3", "0.028652"], ["84092.2", "0"], ["84085.2", "0"], ["84078.2", "0"], ["84076.6", "0"], ["84058.5", "0"], ["84057.6", "0.358197"], ["84055.2", "0"], ["84049.7", "11.541003"], ["84047.4", "0.00588"], ["84046.6", "0.011841"], ["84046.4", "0.023784"], ["84046.3", "0.001466"], ["84045.9", "0.059399"]], "a": [["84111", "0.416715"], ["84127.2", "0"], ["84134.2", "0"], ["84141.2", "0"], ["84161.3", "0.02206"], ["84161.9", "0.358325"], ["84177.8", "0.246684"], ["84178.3", "0.087245"]], "u": 168192, "seq": 67577225209}, "cts": 1742584944289, "record_time": 1742584944.423231, "EXCHANGE": "BYBIT"}
{"topic": "orderbook.200.BTCUSDT", "ts": 1742584944519, "type": "delta", "data": {"s": "BTCUSDT", "b": [["84058.5", "0.356864"], ["84057.6", "0.001333"], ["84049.8", "11.564787"], ["84049.7", "0"]], "a": [], "u": 168193, "seq": 67577225231}, "cts": 1742584944493, "record_time": 1742584944.621876, "EXCHANGE": "BYBIT"}
{"topic": "orderbook.200.BTCUSDT", "ts": 1742584944720, "type": "delta", "data": {"s": "BTCUSDT", "b": [["84058.6", "0.356861"], ["84058.5", "0"]], "a": [["84135.7", "0"], ["84161.8", "0.356861"], ["84161.9", "0.001466"]], "u": 168194, "seq": 67577225247}, "cts": 1742584944623, "record_time": 1742584944.82331, "EXCHANGE": "BYBIT"}
{"topic": "orderbook.200.BTCUSDT", "ts": 1742584944920, "type": "delta", "data": {"s": "BTCUSDT", "b": [["84110.6", "0"], ["84103.3", "0.028499"], ["84096.4", "0.056091"], ["84092.1", "0.139006"], ["84080.2", "0.118891"], ["84076.5", "0"], ["84074.7", "0"], ["84074.5", "0.039634"], ["84074.1", "0.144285"], ["84072.9", "0.0141"], ["84072.7", "0.064214"], ["84068.1", "0.297278"], ["84058.6", "0"], ["84058.5", "0.356862"], ["84054.8", "0.023778"], ["84045.9", "0"]], "a": [["84111", "0.422715"], ["84131.8", "0"], ["84151.9", "2.625819"], ["84157.4", "0.005184"], ["84161.7", "0.362047"], ["84161.8", "0"], ["84178.5", "0.005184"], ["84179.6", "0.001861"]], "u": 168195, "seq": 67577225309}, "cts": 1742584944916, "record_time": 1742584945.022477, "EXCHANGE": "BYBIT"}
{"topic": "orderbook.200.BTCUSDT", "ts": 1742584945119, "type": "delta", "data": {"s": "BTCUSDT", "b": [["84104.9", "0"], ["84104.2", "0.071374"], ["84102.5", "0.382245"], ["84102.4", "0.000153"], ["84100.7", "0.071377"], ["84092.5", "0.113122"], ["84092.4", "0.05009"], ["84091.4", "0.059633"], ["84087.9", "0.001466"], ["84084.4", "0.060214"], ["84078.6", "0.002799"], ["84077.4", "0.168707"], ["84071.1", "0"], ["84070.9", "0.049547"], ["84060", "0.000178"], ["84058.5", "0"], ["84054.8", "0.380653"], ["84046.6", "0"], ["84046.4", "0"], ["84046.3", "0"]], "a": [["84126.4", "0.06175"], ["84130.8", "0.065785"], ["84133.4", "0.058765"], ["84140.4", "0.112536"], ["84160.3", "0.356866"], ["84161.7", "0.005184"], ["84177.8", "0"], ["84178.3", "0"], ["84178.5", "0"], ["84179.6", "0"]], "u": 168196, "seq": 67577225390}, "cts": 1742584945115, "record_time": 1742584945.22228, "EXCHANGE": "BYBIT"}
{"topic": "orderbook.200.BTCUSDT", "ts": 1742584945320, "type": "delta", "data": {"s": "BTCUSDT", "b": [["84102.4", "0"], ["84074.6", "0"], ["84074.5", "0"], ["84074.3", "0.039634"], ["84074.2", "0.039634"], ["84072.8", "0"], ["84072.7", "0.051333"], ["84072.5", "0.109346"], ["84072.4", "0.012881"], ["84072.3", "0"], ["84071", "0.000333"], ["84070.9", "0"], ["84070.8", "0.05"], ["84070.7", "0.049547"], ["84059.6", "0"], ["84056.2", "0.416873"], ["84054.8", "0.023778"], ["84046.6", "0.011841"], ["84046.4", "0.023784"]], "a": [], "u": 168197, "seq": 67577225467}, "cts": 1742584945313, "record_time": 1742584945.422631, "EXCHANGE": "BYBIT"}
{"success": true, "ret_msg": "subscribe", "conn_id": "5f021373-0be7-49f6-9677-e8a641867612", "op": "subscribe", "record_time": 1742585763.864646, "EXCHANGE": "BYBIT"}
