{"success": true, "ret_msg": "subscribe", "conn_id": "0a057d1e-99ed-4273-9bc3-ea60d3f1a2bb", "op": "subscribe", "record_time": 1742576770.586584, "EXCHANGE": "BYBIT"}
{"topic": "orderbook.200.BTCUSDT", "ts": 1742576768320, "type": "snapshot", "data": {"s": "BTCUSDT", "b": [["83930.5", "0.678304"], ["83930.1", "0.160704"], ["83929.9", "0.294388"], ["83927.8", "0.006878"], ["83927.1", "0.193285"], ["83927", "0.036012"], ["83926.3", "0.005713"], ["83925.4", "0.072048"], ["83924", "0.023185"], ["83923.6", "0.090009"], ["83923.5", "0.089099"], ["83923.4", "0.001002"], ["83923.3", "0.001333"], ["83923", "0.071528"], ["83922.2", "0.010737"], ["83922.1", "0.02"], ["83922", "0.009843"], ["83921.7", "0.003996"], ["83921.6", "0.001466"], ["83920.8", "0.117908"], ["83920", "0.00006"], ["83919.8", "0.034614"], ["83919.7", "0.115931"], ["83919.6", "0.05819"], ["83919.1", "0.001333"], ["83918.8", "0.06215"], ["83918.7", "0.171"], ["83918", "0.004266"], ["83917.9", "0.032193"], ["83917.3", "0.04"], ["83917.1", "0.04"], ["83916.9", "0.001466"], ["83916.1", "0.000522"], ["83916", "0.00009"], ["83915.9", "0.11274"], ["83915.7", "0.001"], ["83915.6", "0.044333"], ["83915.4", "0.052"], ["83914.9", "0.001333"], ["83913.9", "0.04"], ["83913.8", "0.004265"], ["83913.7", "0.07576"], ["83913.2", "0.089099"], ["83913.1", "0.02"], ["83912.3", "0.001466"], ["83912.2", "0.04"], ["83912", "0.044"], ["83911.8", "0.248054"], ["83911.7", "0.019739"], ["83911.5", "0.000522"], ["83911.4", "0.179093"], ["83911", "0.173049"], ["83910.7", "0.001333"], ["83910.6", "0.04"], ["83910.4", "0.048"], ["83909.7", "0.178764"], ["83909.6", "0.004263"], ["83909.5", "0.021787"], ["83908.9", "0.178719"], ["83908.4", "0.0206"], ["83907.7", "0.001466"], ["83907.6", "0.02069"], ["83907.2", "0.0869"], ["83906.9", "0.000522"], ["83906.5", "0.001333"], ["83906", "0.178719"], ["83905.9", "0.02"], ["83905.5", "0.023633"], ["83905.4", "0.004263"], ["83904.9", "0.02"], ["83904.4", "0.02"], ["83904.2", "0.118835"], ["83903.5", "0.178719"], ["83903.1", "0.001466"], ["83903", "0.196102"], ["83902.9", "0.191"], ["83902.4", "0.022"], ["83902.3", "0.001853"], ["83902.2", "0.02"], ["83901.9", "0.27624"], ["83901.7", "0.023799"], ["83901.5", "0.023575"], ["83901.2", "0.004249"], ["83900", "0.00006"], ["83899.3", "0.178719"], ["83899.2", "0.00009"], ["83898.8", "0.000333"], ["83898.6", "0.118835"], ["83898.5", "0.116093"], ["83898.3", "0.005958"], ["83898.1", "0.001333"], ["83897.7", "0.00052"], ["83897.6", "0.02"], ["83897.1", "0.207781"], ["83897", "0.004248"], ["83896.9", "0.609094"], ["83896.7", "0.035755"], ["83894.7", "0.089099"], ["83894.6", "0.370347"], ["83894.5", "0.191"], ["83893.9", "0.002799"], ["83893.8", "0.02"], ["83893.5", "0.0016"], ["83893.4", "0.119195"], ["83893.3", "0.52786"], ["83893.1", "0.00052"], ["83892.9", "0.013"], ["83892.8", "0.345881"], ["83892.7", "0.049912"], ["83892.6", "0.003575"], ["83892.4", "0.023829"], ["83892.3", "0.004568"], ["83892.2", "0.125103"], ["83890.8", "0.00009"], ["83890.7", "0.023829"], ["83890.4", "0.000333"], ["83890.2", "0.0176"], ["83889.7", "0.051333"], ["83889.6", "0.049548"], ["83889.3", "0.001466"], ["83889.2", "0.029912"], ["83889.1", "0.133293"], ["83889", "0.013806"], ["83888.7", "0.024891"], ["83888.6", "0.004248"], ["83888.5", "0.00052"], ["83888.4", "0.029912"], ["83887.6", "0.357599"], ["83887.5", "0.039637"], ["83887.4", "0.039637"], ["83886.7", "1.365281"], ["83886.6", "4.550938"], ["83886.2", "0.000333"], ["83886.1", "0.029912"], ["83885.9", "0.177814"], ["83885.8", "0.118835"], ["83885.6", "0.059399"], ["83885.5", "0.001333"], ["83885.4", "0.200945"], ["83884.6", "0.001466"], ["83884.4", "0.004248"], ["83883.8", "0.00052"], ["83883.7", "0.030545"], ["83883.1", "0.126538"], ["83882.7", "0.024942"], ["83882.4", "0.00018"], ["83882", "0.000333"], ["83881.5", "0.011922"], ["83881.3", "0.001333"], ["83880.6", "0.118835"], ["83880.4", "0.009225"], ["83880.2", "0.004248"], ["83880", "0.001526"], ["83879.2", "0.00052"], ["83878.6", "0.125169"], ["83878.3", "0.172807"], ["83877.8", "0.024163"], ["83877.2", "0.059399"], ["83877.1", "0.025175"], ["83877", "0.0006"], ["83876.9", "0.0006"], ["83876.7", "0.059605"], ["83876.5", "0.11921"], ["83876", "0.00419"], ["83875.9", "0.0006"], ["83875.7", "0.354054"], ["83875.6", "0.023835"], ["83875.5", "0.059605"], ["83875.4", "0.001466"], ["83874.7", "0.118835"], ["83874.6", "0.00302"], ["83874", "0.00009"], ["83873.9", "0.023835"], ["83873.6", "0.059938"], ["83873.3", "0.11921"], ["83873.2", "0.02383"], ["83872.9", "0.001333"], ["83872.6", "0.023835"], ["83872.5", "0.003"], ["83871.8", "0.175187"], ["83871.3", "0.00036"], ["83871", "0.000118"], ["83870.8", "0.001466"], ["83870", "0.00052"], ["83869.8", "0.023835"], ["83869.4", "0.000933"], ["83869.1", "0.00596"], ["83869", "0.145327"], ["83868.9", "0.118835"], ["83868.7", "0.0027"], ["83867.8", "0.089099"], ["83867.6", "0.004217"], ["83867.4", "0.000422"], ["83867.3", "0.003575"], ["83866.5", "0.184743"], ["83866.2", "0.001466"], ["83865.6", "0.059505"], ["83865.4", "0.000524"], ["83865.3", "0.000333"], ["83864.5", "0.001333"]], "a": [["83930.6", "0.009233"], ["83930.8", "0.001466"], ["83931.7", "0.001333"], ["83932.4", "0.000333"], ["83933.6", "0.006212"], ["83933.9", "0.071519"], ["83934.4", "0.000993"], ["83934.5", "0.016138"], ["83934.6", "0.000522"], ["83934.7", "0.004237"], ["83935.4", "0.001466"], ["83935.9", "0.001333"], ["83936.4", "0.058355"], ["83936.5", "0.024847"], ["83936.6", "0.000569"], ["83938.3", "0.024112"], ["83938.4", "0.00009"], ["83938.5", "0.068416"], ["83938.6", "0.171"], ["83938.9", "0.004239"], ["83939", "0.02"], ["83939.2", "0.000522"], ["83940", "0.002306"], ["83940.1", "0.001333"], ["83940.6", "0.005959"], ["83940.7", "0.037269"], ["83940.8", "0.000333"], ["83940.9", "0.000729"], ["83941.1", "0.071513"], ["83941.5", "0.063957"], ["83942.4", "0.006748"], ["83943.1", "0.004243"], ["83943.2", "0.059399"], ["83943.5", "0.07151"], ["83943.6", "0.039686"], ["83943.8", "0.000522"], ["83944.1", "0.009225"], ["83944.3", "0.001333"], ["83944.6", "0.001466"], ["83945", "0.000333"], ["83945.5", "0.087437"], ["83946", "0.112444"], ["83946.8", "0.00009"], ["83947", "0.171"], ["83947.1", "0.0006"], ["83947.3", "0.004243"], ["83947.4", "0.004766"], ["83948", "0.044063"], ["83948.2", "0.04"], ["83948.4", "0.001333"], ["83948.5", "0.000522"], ["83949.2", "0.000333"], ["83949.3", "0.001826"], ["83949.5", "0.04"], ["83949.9", "0.04"], ["83950.1", "0.0012"], ["83950.4", "0.064014"], ["83951.3", "0.018757"], ["83951.4", "0.04"], ["83951.5", "0.00425"], ["83951.6", "0.04"], ["83951.7", "0.000358"], ["83952.2", "0.005957"], ["83952.4", "0.000083"], ["83952.6", "0.001333"], ["83953.1", "0.040522"], ["83953.3", "0.04"], ["83953.4", "0.000333"], ["83953.9", "0.116084"], ["83954.1", "0.013892"], ["83954.4", "0.059399"], ["83954.5", "0.296545"], ["83954.6", "0.195"], ["83954.7", "0.04"], ["83954.9", "0.04"], ["83955.2", "0.00009"], ["83955.4", "0.171"], ["83955.7", "0.057729"], ["83955.8", "0.185775"], ["83955.9", "0.0056"], ["83956", "0.000118"], ["83956.7", "0.220259"], ["83956.8", "0.001333"], ["83956.9", "0.506146"], ["83957.6", "0.000333"], ["83957.7", "0.000522"], ["83957.8", "0.042894"], ["83958", "0.011921"], ["83958.5", "0.001466"], ["83959.9", "0.004262"], ["83961", "0.001333"], ["83961.2", "0.015333"], ["83961.8", "0.000333"], ["83962.2", "0.004061"], ["83962.3", "0.000524"], ["83962.7", "0.090141"], ["83962.8", "0.118835"], ["83963.1", "0.025296"], ["83963.2", "0.005957"], ["83963.6", "0.00009"], ["83963.7", "0.011914"], ["83963.8", "0.171"], ["83964.1", "0.004262"], ["83964.6", "0.00315"], ["83964.9", "0.320658"], ["83965.2", "0.001333"], ["83966", "0.000333"], ["83966.9", "0.000524"], ["83967.7", "0.001466"], ["83967.8", "0.252089"], ["83967.9", "0.591841"], ["83968.3", "0.182496"], ["83968.5", "0.002735"], ["83969", "0.02383"], ["83969.2", "0.037727"], ["83969.4", "0.001333"], ["83970.2", "0.000333"], ["83970.7", "0.02383"], ["83971.3", "0.0001"], ["83971.4", "0.179079"], ["83971.6", "0.000524"], ["83972", "0.00018"], ["83972.2", "0.171"], ["83972.3", "0.001466"], ["83972.4", "0.002144"], ["83972.5", "0.044262"], ["83972.6", "0.04"], ["83973.6", "0.001333"], ["83974.3", "0.000333"], ["83974.6", "0.0025"], ["83974.8", "0.297554"], ["83976", "0.125103"], ["83976.2", "0.000524"], ["83976.6", "0.051343"], ["83976.7", "0.004262"], ["83977", "0.001466"], ["83977.7", "0.3541"], ["83977.8", "0.001333"], ["83978.5", "0.000333"], ["83978.6", "0.059399"], ["83979", "0.178719"], ["83980.4", "0.00009"], ["83980.6", "0.171"], ["83980.7", "0.118835"], ["83980.8", "0.000524"], ["83980.9", "0.118262"], ["83981.6", "0.001466"], ["83982", "0.001333"], ["83982.3", "0.00018"], ["83982.7", "0.000333"], ["83982.8", "0.021935"], ["83984.7", "0.015"], ["83984.8", "0.02383"], ["83985.1", "0.004264"], ["83985.3", "3.37292"], ["83985.4", "0.000524"], ["83985.7", "0.022914"], ["83985.8", "0.35"], ["83986", "0.118835"], ["83986.2", "0.002799"], ["83986.9", "0.000333"], ["83987.8", "0.357599"], ["83987.9", "0.059399"], ["83988", "0.125109"], ["83988.8", "0.00009"], ["83989", "0.171"], ["83989.3", "0.004264"], ["83990", "0.000524"], ["83990.4", "0.001333"], ["83990.8", "0.041466"], ["83991", "0.000204"], ["83991.1", "0.000333"], ["83991.4", "0.118835"], ["83991.5", "2.611883"], ["83993.5", "0.004624"], ["83994.1", "0.027875"], ["83994.6", "0.001857"], ["83995.3", "0.000333"], ["83995.4", "0.001466"], ["83996.5", "0.118835"], ["83997", "0.125103"], ["83997.2", "0.059489"], ["83997.4", "0.171"], ["83997.7", "0.004156"], ["83998.5", "0.011994"], ["83998.8", "0.001333"], ["83999.3", "0.000524"], ["83999.5", "0.000333"], ["84000", "0.022729"], ["84000.1", "0.001466"], ["84000.4", "0.000145"], ["84000.5", "0.04"], ["84000.6", "0.246684"], ["84000.7", "0.04"], ["84001.2", "0.005956"], ["84001.5", "0.0006"], ["84001.9", "0.063576"], ["84002.8", "3.943553"], ["84003", "0.001333"], ["84003.1", "0.04"]], "u": 127349, "seq": 67571033676}, "cts": 1742576768303, "record_time": 1742576770.588586, "EXCHANGE": "BYBIT"}
{"topic": "orderbook.200.BTCUSDT", "ts": 1742576768520, "type": "delta", "data": {"s": "BTCUSDT", "b": [["83930.5", "0.678777"], ["83923.6", "0.064519"], ["83920.8", "0.000522"], ["83911", "0"], ["83905.5", "0"], ["83905.2", "0.023829"], ["83901.9", "0"], ["83894.5", "0.203881"], ["83894.4", "0.012881"], ["83892.9", "0"], ["83892.8", "0.333"], ["83891.3", "0.049546"], ["83891.2", "0.049546"], ["83889.7", "0.001333"], ["83889.6", "0"], ["83889.2", "0.387507"], ["83887.6", "0"], ["83873.2", "0"], ["83863.8", "0.120732"], ["83863.6", "0.118835"], ["83863.4", "0.004217"]], "a": [["83933.9", "0"], ["83936", "0.071517"], ["83938.3", "0"], ["83938.4", "0"], ["83938.5", "0"], ["83938.8", "0.024026"], ["83940.6", "0"], ["83941.1", "0"], ["83941.4", "0.005959"], ["83942.4", "0"], ["83946", "0"], ["83946.3", "0.071508"], ["83947.4", "0"], ["83948.2", "0.046255"], ["83955.8", "0"], ["83958.7", "0.023829"], ["83964.9", "0.02383"], ["83972.5", "0.004262"], ["83972.6", "0"], ["83972.8", "0.04"], ["83972.9", "0.04"], ["83987.8", "0"], ["83988.9", "0.357595"], ["84003.7", "0.000333"], ["84003.9", "0.000524"], ["84004.1", "0.102454"], ["84004.2", "0.04"]], "u": 127350, "seq": 67571033798}, "cts": 1742576768515, "record_time": 1742576770.589584, "EXCHANGE": "BYBIT"}
{"topic": "orderbook.200.BTCUSDT", "ts": 1742576768720, "type": "delta", "data": {"s": "BTCUSDT", "b": [["83894.7", "0.102099"], ["83894.6", "0.383228"], ["83894.5", "0.191"], ["83894.4", "0"], ["83891.5", "0.05"], ["83891.4", "0.049546"], ["83891.3", "0"], ["83891.2", "0"], ["83889.2", "0.387501"], ["83863.4", "0.175217"], ["83863", "0.059605"]], "a": [["83935.2", "0.071518"], ["83936", "0"], ["83938.8", "0"], ["83941.7", "0.071512"], ["83946.3", "0"], ["83973.9", "0.178719"], ["83988.9", "0"], ["83990.7", "0.35759"]], "u": 127351, "seq": 67571033856}, "cts": 1742576768714, "record_time": 1742576770.591585, "EXCHANGE": "BYBIT"}
{"topic": "orderbook.200.BTCUSDT", "ts": 1742576768920, "type": "delta", "data": {"s": "BTCUSDT", "b": [["83896", "0.096549"], ["83891.7", "0.05"], ["83891.6", "0.049545"], ["83891.5", "0"], ["83891.4", "0"], ["83863", "0"]], "a": [["83940.6", "0.005959"], ["83941.4", "0"], ["83991.5", "2.612081"]], "u": 127352, "seq": 67571033896}, "cts": 1742576768912, "record_time": 1742576770.592585, "EXCHANGE": "BYBIT"}
{"topic": "orderbook.200.BTCUSDT", "ts": 1742576769120, "type": "delta", "data": {"s": "BTCUSDT", "b": [["83930.5", "0.678846"], ["83897.1", "0.247781"], ["83897", "0.043879"], ["83894.8", "0.01288"], ["83894.7", "0.101979"], ["83894.6", "0.370347"], ["83891.7", "0"], ["83891.5", "0.049546"], ["83887.5", "0"], ["83887.4", "0"], ["83863", "0.059605"]], "a": [["83940.6", "0"], ["83941.4", "0.005959"], ["83971.8", "0.04"], ["83971.9", "0.04"], ["83972.5", "1.433303"], ["83972.8", "0"], ["83972.9", "0"], ["83988.9", "0.357591"], ["83990.7", "0"]], "u": 127353, "seq": 67571033979}, "cts": 1742576769113, "record_time": 1742576770.593584, "EXCHANGE": "BYBIT"}
{"topic": "orderbook.200.BTCUSDT", "ts": 1742576769319, "type": "delta", "data": {"s": "BTCUSDT", "b": [["83930.5", "0.638846"], ["83920.7", "0.024193"], ["83907.2", "0.159378"], ["83901.7", "0"], ["83897.4", "0.024504"], ["83897.1", "0.207781"], ["83897", "0.004248"], ["83896.8", "0.039631"], ["83896.7", "0.075386"], ["83894.8", "0"], ["83894.7", "0.089099"], ["83894.6", "0.383228"], ["83894.5", "0.203881"], ["83891.6", "0"], ["83891.5", "0"], ["83891.4", "0.049546"], ["83891.3", "0.049546"], ["83863", "0"]], "a": [["83930.6", "0.009217"], ["83935.2", "0"], ["83935.5", "0.071517"], ["83941.5", "0.087931"], ["83941.7", "0"], ["83946.2", "0.071508"], ["83948.2", "0.04"], ["83948.4", "0.010566"], ["83971.4", "0.00036"], ["83971.8", "0"], ["83971.9", "0"], ["83972.3", "0.041466"], ["83972.4", "0.616267"], ["83981.5", "0.02377"], ["83985.7", "0"], ["83988.9", "0"], ["83990.7", "0.357593"], ["84004.7", "0.001466"], ["84004.9", "0.005956"]], "u": 127354, "seq": 67571034070}, "cts": 1742576769317, "record_time": 1742576770.595169, "EXCHANGE": "BYBIT"}
{"topic": "orderbook.200.BTCUSDT", "ts": 1742576769519, "type": "delta", "data": {"s": "BTCUSDT", "b": [["83936.3", "1.225125"], ["83934.7", "0.01992"], ["83934.6", "0.342725"], ["83934.5", "0.06159"], ["83934.3", "0.356396"], ["83932.8", "0.023837"], ["83931.7", "0.072853"], ["83931", "0.005718"], ["83930.8", "0.001466"], ["83930.7", "0.220239"], ["83930.5", "0.272518"], ["83930.1", "0"], ["83930", "0.000522"], ["83929.9", "0.123388"], ["83929.2", "0.0022"], ["83928.2", "0.000333"], ["83928.1", "0.022875"], ["83927.5", "0.001333"], ["83927.2", "0.092117"], ["83927", "0"], ["83926.4", "0.004276"], ["83926.3", "0"], ["83926.2", "0.021466"], ["83925.4", "0.000522"], ["83924.4", "0.00009"], ["83924", "0.000333"], ["83923.9", "0.066587"], ["83923.5", "0"], ["83923", "0.023829"], ["83922.2", "0.004266"], ["83922.1", "0"], ["83920.9", "0.060087"], ["83919.8", "0.000333"], ["83919.6", "0.01056"], ["83918.8", "0"], ["83917.9", "0"], ["83914.5", "0.119146"], ["83913.9", "0.10045"], ["83911.7", "0"], ["83911.5", "0.059921"], ["83911.4", "0.000333"], ["83909.9", "0.003575"], ["83909.8", "0.118835"], ["83909.7", "0"], ["83905.2", "0"], ["83902.8", "0.011919"], ["83900.5", "0.0016"], ["83898.3", "0"], ["83894.8", "0.357575"], ["83893.5", "0"], ["83892.3", "0"], ["83889.4", "0.023829"], ["83889.2", "0.029912"], ["83886.1", "0"], ["83885.8", "0.124792"], ["83885.4", "0.171"], ["83883.7", "0.0006"], ["83881.5", "0"], ["83881.1", "0.023829"], ["83878.3", "0.148965"], ["83868.7", "0"], ["83867.8", "0"], ["83867.6", "0"], ["83867.4", "0"], ["83867.3", "0"], ["83866.5", "0"], ["83866.2", "0"], ["83865.6", "0"], ["83865.4", "0"], ["83865.3", "0"], ["83864.5", "0"], ["83863.8", "0"], ["83863.6", "0"], ["83863.4", "0"]], "a": [["83930.6", "0"], ["83930.8", "0"], ["83931.7", "0"], ["83932.4", "0"], ["83933.6", "0"], ["83934.4", "0"], ["83934.5", "0"], ["83934.6", "0"], ["83934.7", "0"], ["83935.4", "0"], ["83935.5", "0"], ["83935.9", "0"], ["83936.4", "0"], ["83936.5", "0"], ["83938.6", "0"], ["83939", "0"], ["83939.2", "0.020522"], ["83940.7", "0"], ["83941.2", "0.02482"], ["83941.4", "0"], ["83941.5", "0"], ["83943.5", "0"], ["83944.1", "0"], ["83945.4", "0.037229"], ["83946.2", "0"], ["83948", "0.04"], ["83948.4", "0.001333"], ["83949.4", "0.005959"], ["83951.4", "0.049225"], ["83952.2", "0"], ["83953.9", "0.001466"], ["83954.1", "0.009317"], ["83955.9", "0.062159"], ["83958", "0"], ["83959.9", "0.123408"], ["83962.8", "0"], ["83963.2", "0"], ["83963.7", "0"], ["83964.9", "0"], ["83969", "0"], ["83970", "0.023832"], ["83970.7", "0"], ["83972.3", "0.001466"], ["83972.4", "0.576267"], ["83972.5", "0.010219"], ["83973.9", "0"], ["83974.8", "0.118835"], ["83975.3", "0.04"], ["83975.4", "0.04"], ["83976", "0.148932"], ["83976.6", "0"], ["83979.5", "0.051346"], ["83980.1", "0.023829"], ["83981.8", "0.023829"], ["83990.7", "0"], ["83991.5", "0"], ["83996.4", "0.357585"], ["83997", "2.737184"], ["83998.5", "0"], ["84005", "0.04"], ["84005.2", "1.028508"], ["84005.3", "0.000083"], ["84005.6", "0.00009"], ["84005.9", "0.005"], ["84006.1", "0.004156"], ["84006.3", "0.04"], ["84006.6", "0.118835"], ["84007.2", "0.001333"], ["84007.9", "0.000333"], ["84008", "0.059399"], ["84008.5", "0.000524"], ["84009", "0.125104"], ["84009.3", "0.001466"], ["84009.9", "0.011868"], ["84010.3", "0.004156"], ["84011", "0.238066"], ["84011.2", "0.015"], ["84011.4", "0.001333"], ["84012", "0.000333"], ["84012.1", "0.000333"], ["84012.3", "0.625516"], ["84013.1", "0.000524"], ["84013.9", "0.001466"], ["84014", "0.656749"]], "u": 127355, "seq": 67571035033}, "cts": 1742576769517, "record_time": 1742576770.596173, "EXCHANGE": "BYBIT"}
{"topic": "orderbook.200.BTCUSDT", "ts": 1742576769720, "type": "delta", "data": {"s": "BTCUSDT", "b": [["83939.1", "0.887016"], ["83936.5", "0.1"], ["83936.4", "0.129614"], ["83936.3", "0.220912"], ["83935.9", "0.003894"], ["83935.5", "0.005718"], ["83934.7", "0.004276"], ["83934.6", "0.049912"], ["83934.5", "0.133108"], ["83934.3", "0"], ["83932.6", "0.022873"], ["83932.4", "0.000333"], ["83932.3", "0.003871"], ["83931.6", "0.05819"], ["83931", "0"], ["83930.8", "0.156191"], ["83930.7", "0.120239"], ["83930.6", "0.004276"], ["83930.5", "0.272449"], ["83929.9", "0.051866"], ["83928.4", "0.034312"], ["83928.1", "0"], ["83927.2", "0.065892"], ["83924", "0.05947"], ["83923.9", "0.032273"], ["83923.6", "0"], ["83922.7", "0.04"], ["83921.1", "0.044"], ["83920.9", "0.052"], ["83919.7", "0.073721"], ["83919.6", "0"], ["83919.3", "0.04"], ["83919.2", "0.04"], ["83917.5", "0.044"], ["83917.3", "0"], ["83916.1", "0.040522"], ["83915.8", "0.048"], ["83915.6", "0.000333"], ["83915.4", "0"], ["83914", "0.178701"], ["83913.9", "0.04"], ["83913.7", "0.03576"], ["83912", "0"], ["83911.8", "0"], ["83911", "0.178701"], ["83909.8", "0.123418"], ["83909.3", "0.023827"], ["83908.9", "0"], ["83907.7", "0.508861"], ["83906", "0"], ["83899.3", "0"], ["83897.4", "0"], ["83896.1", "0.40712"], ["83896", "0.146099"], ["83894.8", "0"], ["83894.7", "0.222421"], ["83892.8", "0.004248"], ["83891.4", "0"], ["83891.3", "0"], ["83889.4", "4.670347"], ["83889.1", "0"], ["83888.4", "0"], ["83886.6", "0.023829"], ["83874.1", "1.31534"], ["83871.2", "0.125095"], ["83869.8", "0"], ["83869.4", "0"], ["83869.1", "0"], ["83869", "0"], ["83868.9", "0"]], "a": [["83936.6", "0"], ["83938.9", "0"], ["83939.2", "0.005282"], ["83941.2", "0"], ["83942.8", "0.006205"], ["83943.2", "0"], ["83943.6", "0"], ["83945.4", "0.000297"], ["83945.7", "0.024819"], ["83947.6", "0.02"], ["83947.9", "0.005958"], ["83948", "0.006916"], ["83948.2", "0"], ["83948.3", "0.0003"], ["83948.4", "0.059688"], ["83949.4", "0"], ["83949.5", "0"], ["83949.8", "0.017066"], ["83949.9", "0.07681"], ["83950.4", "0"], ["83951.3", "0"], ["83951.4", "0.009225"], ["83951.6", "0"], ["83953.1", "0.000522"], ["83953.3", "0"], ["83953.9", "0.072968"], ["83954.1", "0"], ["83954.5", "0.434488"], ["83954.7", "0"], ["83954.9", "0"], ["83955.6", "0.002073"], ["83955.8", "0.11461"], ["83955.9", "0.0056"], ["83956", "0"], ["83956.1", "0.0715"], ["83956.3", "0.178701"], ["83957.6", "0.004396"], ["83958", "0.178701"], ["83958.6", "0.048646"], ["83958.7", "0"], ["83959.1", "0.04"], ["83959.3", "0.178701"], ["83959.4", "0.04"], ["83961.6", "0.018757"], ["83962.2", "0.182762"], ["83962.7", "0"], ["83963.7", "0.054023"], ["83964.4", "0.009317"], ["83968.8", "0.004602"], ["83969.2", "0.02383"], ["83972.4", "0.002144"], ["83975.3", "0"], ["83975.4", "0"], ["83978.2", "0.04"], ["83978.3", "0.04"], ["83979", "0"], ["83979.5", "0"], ["83981.5", "0"], ["83982.3", "0.051526"], ["83986", "0.143776"], ["83987", "0.328384"], ["83994.1", "0"], ["83996.3", "0.357566"], ["83996.4", "0"], ["83997", "0.125103"], ["84002.5", "2.612081"], ["84005.8", "0.171"], ["84007", "0.04"], ["84009", "0"], ["84011", "0"], ["84012.3", "0"], ["84014.4", "0.011869"], ["84014.5", "0.004156"]], "u": 127356, "seq": 67571035568}, "cts": 1742576769717, "record_time": 1742576770.598173, "EXCHANGE": "BYBIT"}
{"topic": "orderbook.200.BTCUSDT", "ts": 1742576769919, "type": "delta", "data": {"s": "BTCUSDT", "b": [["83939.1", "1.061105"], ["83936.4", "0.089754"], ["83931.7", "0.182864"], ["83930.8", "0.063616"], ["83930.5", "0.269525"], ["83929.9", "0.049912"], ["83927.1", "0.1916"], ["83922.5", "0.04"], ["83918.6", "0.114609"], ["83917.7", "0.04"], ["83917.1", "0"], ["83913.9", "0"], ["83910.6", "0"], ["83910.4", "0"], ["83907.2", "0.0869"], ["83903", "0.059732"], ["83902", "0.022746"], ["83898.5", "0.001466"], ["83896.4", "0.05"], ["83896.3", "0.04955"], ["83896.1", "0"], ["83896", "0.096549"], ["83894.9", "4.767837"], ["83894.8", "0.357572"], ["83894.7", "0.222407"], ["83889.4", "0.023829"], ["83886.7", "0"], ["83871.1", "0.044"], ["83871", "0"], ["83870.8", "0"], ["83870", "0"]], "a": [["83939.2", "0.005521"], ["83945.3", "0.000297"], ["83945.4", "0.059399"], ["83947.9", "0"], ["83948", "0.005958"], ["83948.1", "0.024223"], ["83949.8", "0.039531"], ["83952.7", "0.04"], ["83953.7", "0.004767"], ["83953.9", "0.001466"], ["83954.2", "0.04"], ["83954.3", "0.04"], ["83956", "0.04"], ["83956.7", "0.04154"], ["83957.7", "0.080522"], ["83958.5", "0.072964"], ["83958.6", "0.174107"], ["83978.2", "0"], ["83978.4", "0.04"], ["83982.3", "0.051521"], ["83984.8", "0"], ["83985.2", "0.013707"], ["83996.2", "0.357568"], ["83996.3", "0"], ["83997", "2.737059"], ["84002.5", "0"], ["84013.1", "0"], ["84013.9", "0"], ["84014", "0"], ["84014.4", "0"], ["84014.5", "0"]], "u": 127357, "seq": 67571035757}, "cts": 1742576769917, "record_time": 1742576770.600436, "EXCHANGE": "BYBIT"}
{"topic": "orderbook.200.BTCUSDT", "ts": 1742576770120, "type": "delta", "data": {"s": "BTCUSDT", "b": [["83939.1", "0.139977"], ["83936.4", "0"], ["83936.3", "0"], ["83935.8", "0.071517"], ["83934.6", "0.02"], ["83934.5", "0.06159"], ["83932.8", "0"], ["83931.7", "0.111344"], ["83930.5", "0.021"], ["83929.9", "0.02"], ["83928.8", "0.071523"], ["83927.8", "0"], ["83923", "0"], ["83913.2", "0"], ["83912.2", "0"], ["83911.5", "0.000522"], ["83909.8", "0.004583"], ["83904.1", "0.125091"], ["83896.6", "0.05"], ["83896.5", "0.04955"], ["83896.4", "0"], ["83896.3", "0"], ["83894.9", "0"], ["83894.8", "0"], ["83894.7", "0.089099"], ["83889.1", "0.133339"], ["83883.2", "0.357602"], ["83875.5", "4.827442"], ["83870.8", "0.001466"], ["83870", "0.00052"], ["83869.8", "0.023835"], ["83869.4", "0.000933"]], "a": [["83939.2", "0.24218"], ["83943.6", "0.019005"], ["83948", "0"], ["83948.3", "0.000453"], ["83948.7", "0.006753"], ["83949.8", "0.070174"], ["83952.5", "0.04"], ["83953.7", "0"], ["83956", "0.08"], ["83956.1", "0"], ["83958.4", "0.118835"], ["83958.5", "0.001466"], ["83967", "0.125091"], ["83978.3", "0"], ["83978.5", "0.040333"], ["83982.3", "0.051523"], ["83983.1", "0.08935"], ["83985.2", "0.371309"], ["83986.3", "0.022831"], ["83989.2", "0.022883"], ["83990.8", "0.001466"], ["83994.2", "2.611956"], ["83996.2", "0"], ["83997", "0.125103"], ["84009", "0.027657"], ["84010.3", "0"], ["84011.2", "0"], ["84011.4", "0"], ["84012", "0"], ["84012.1", "0"]], "u": 127358, "seq": 67571036045}, "cts": 1742576770117, "record_time": 1742576770.601434, "EXCHANGE": "BYBIT"}
{"topic": "orderbook.200.BTCUSDT", "ts": 1742576770320, "type": "delta", "data": {"s": "BTCUSDT", "b": [["83939.1", "0.140057"], ["83938.2", "0.071515"], ["83935.9", "0"], ["83935.8", "0"], ["83932.3", "0"], ["83930.8", "0.135137"], ["83930.7", "0.130239"], ["83928.8", "0"], ["83926.7", "0.071525"], ["83926.2", "0.011466"], ["83921.9", "0.003871"], ["83920.7", "0"], ["83919.8", "0.024554"], ["83919.6", "0.019739"], ["83915.3", "0.178752"], ["83897.2", "0.05"], ["83897.1", "0.25733"], ["83896.6", "0"], ["83896.5", "0"], ["83889.1", "0"], ["83888.7", "0"], ["83886.2", "0.133672"], ["83883.3", "0.357622"], ["83883.2", "0"], ["83882.7", "0"], ["83875.5", "0.059605"], ["83869.1", "0.00596"], ["83869", "0.005958"], ["83868.9", "0.118835"], ["83868.7", "0.0027"]], "a": [["83939.2", "0.313694"], ["83943.6", "0.038382"], ["83944.2", "0.07151"], ["83945.1", "0.001"], ["83945.5", "0.126294"], ["83948.3", "0.0003"], ["83948.4", "0.131194"], ["83949.8", "0.151798"], ["83950.9", "0.009225"], ["83951", "0.178676"], ["83951.4", "0"], ["83952.7", "0.218672"], ["83953.8", "0.005521"], ["83954.4", "0.238067"], ["83957.6", "0.000333"], ["83958.3", "0.118835"], ["83958.4", "0"], ["83959.3", "0"], ["83975.9", "0.195105"], ["83976.6", "0.051343"], ["83980.5", "0.357623"], ["83982.3", "0.00018"], ["83985.2", "0.013707"], ["83991.5", "2.611956"], ["83994.2", "0"], ["84007.9", "0"], ["84008", "0"], ["84008.5", "0"], ["84009", "0"], ["84009.3", "0"], ["84009.9", "0"]], "u": 127359, "seq": 67571036254}, "cts": 1742576770317, "record_time": 1742576770.602434, "EXCHANGE": "BYBIT"}
{"topic": "orderbook.200.BTCUSDT", "ts": 1742576770520, "type": "delta", "data": {"s": "BTCUSDT", "b": [["83939.1", "0.214495"], ["83938.2", "0"], ["83932.8", "0.07152"], ["83930.7", "0.140239"], ["83926.7", "0"], ["83926.2", "0.001466"], ["83924.8", "0.006998"], ["83919.7", "0.147017"], ["83900.4", "0.012881"], ["83900.3", "0.012881"], ["83897.2", "0.049549"], ["83894.7", "0.222412"], ["83894.6", "0.370347"], ["83894.5", "0.191"], ["83889.4", "4.791666"], ["83886.3", "0.357604"], ["83886.2", "0.000333"], ["83883.3", "0"], ["83873.5", "0.016476"], ["83869", "0"], ["83868.9", "0"], ["83868.7", "0"]], "a": [["83939.2", "0.31696"], ["83942.7", "0.005959"], ["83945.4", "0.060399"], ["83946.8", "0.004153"], ["83948", "0.000153"], ["83950.9", "0"], ["83954.2", "0.218701"], ["83958.6", "0.126578"], ["83963.8", "0.174575"], ["83980.5", "0"], ["83985.2", "0.371311"], ["83993.4", "0.16059"], ["84007.2", "0"]], "u": 127360, "seq": 67571036409}, "cts": 1742576770517, "record_time": 1742576770.712303, "EXCHANGE": "BYBIT"}
{"topic": "orderbook.200.BTCUSDT", "ts": 1742576770720, "type": "delta", "data": {"s": "BTCUSDT", "b": [["83939.1", "0.143781"], ["83938.4", "0.071515"], ["83932.9", "0.071519"], ["83932.8", "0"], ["83915.7", "0"], ["83913.6", "0.035748"], ["83911.1", "0.236466"], ["83902.6", "0.04"], ["83902.5", "0.039634"], ["83900.4", "0.013"], ["83897.2", "0.05"], ["83896.8", "0"], ["83896.7", "0"], ["83889.5", "0.357594"], ["83886.3", "0"], ["83869.4", "0"], ["83869.1", "0"]], "a": [["83939.2", "0.245446"], ["83940.5", "0.052259"], ["83940.6", "0.071513"], ["83942.7", "0"], ["83943.6", "0"], ["83944.2", "0"], ["83945.5", "0.127294"], ["83946", "0.071508"], ["83948", "0"], ["83977", "0.001584"], ["83977.1", "0.04"], ["83977.2", "0.04"], ["83978.4", "0"], ["83978.5", "0.000333"], ["83985.2", "0.013707"], ["83991.3", "0.357594"], ["84007", "0"]], "u": 127361, "seq": 67571036532}, "cts": 1742576770710, "record_time": 1742576770.912366, "EXCHANGE": "BYBIT"}
{"success": true, "ret_msg": "subscribe", "conn_id": "19509ed8-4793-4a07-bfdc-43cc4694d4d9", "op": "subscribe", "record_time": 1742576907.725757, "EXCHANGE": "BYBIT"}
{"topic": "orderbook.200.BTCUSDT", "ts": 1742576906319, "type": "snapshot", "data": {"s": "BTCUSDT", "b": [["83947.2", "0.54989"], ["83943.8", "0.148268"], ["83943.7", "0.535645"], ["83941.9", "0.089099"], ["83941.5", "0.00143"], ["83940.8", "0.000333"], ["83940.7", "0.022993"], ["83940.5", "0.0016"], ["83940.2", "0.145741"], ["83940.1", "0.001333"], ["83940", "0.224189"], ["83939.9", "0.071514"], ["83939.2", "0.000522"], ["83938.9", "0.00439"], ["83938.8", "0.02"], ["83938.7", "0.049877"], ["83938.6", "0.0006"], ["83936.6", "0.000333"], ["83936.5", "0.034492"], ["83936.3", "0.009329"], ["83936.2", "0.068805"], ["83935.9", "0.001333"], ["83935.4", "0.011916"], ["83935.1", "0.124463"], ["83935", "0.221391"], ["83934.7", "0.00439"], ["83934.6", "0.000522"], ["83934.1", "0.089099"], ["83933.8", "0.00378"], ["83933.6", "0.04"], ["83933.4", "0.04"], ["83932.9", "0.023403"], ["83932.8", "0.00009"], ["83932.6", "0.001"], ["83932.4", "0.000333"], ["83931.9", "0.044"], ["83931.8", "0.054618"], ["83931.7", "0.001333"], ["83931.4", "0.0024"], ["83930.8", "0.001466"], ["83930.6", "0.004339"], ["83930.3", "0.04"], ["83930.1", "0.04"], ["83930", "0.000522"], ["83929.8", "0.052"], ["83928.7", "0.04"], ["83928.4", "0.044"], ["83928.3", "0.022"], ["83928.2", "0.000333"], ["83927.6", "0.139906"], ["83927.5", "0.001333"], ["83927.2", "0.032622"], ["83926.9", "0.019715"], ["83926.8", "0.04"], ["83926.7", "0.048"], ["83926.4", "0.004327"], ["83926.2", "0.001466"], ["83925.5", "0.059569"], ["83925.4", "0.000522"], ["83925.3", "0.023827"], ["83924.4", "0.00009"], ["83924", "0.000333"], ["83923.7", "0.005956"], ["83923.3", "0.001333"], ["83923.1", "0.120214"], ["83923", "0.171"], ["83922.2", "0.004327"], ["83921.6", "0.001466"], ["83920.8", "0.000522"], ["83920.1", "0.322816"], ["83920", "0.178759"], ["83919.8", "0.000333"], ["83919.2", "0.024525"], ["83919.1", "0.001333"], ["83918.4", "0.089099"], ["83918", "0.004327"], ["83917.6", "0.118835"], ["83916.9", "0.001466"], ["83916.4", "0.023824"], ["83916.1", "0.000522"], ["83916", "0.00009"], ["83915.8", "0.003575"], ["83915.6", "0.000333"], ["83915.5", "0.023825"], ["83915.1", "0.406143"], ["83915", "0.125089"], ["83914.9", "0.001333"], ["83914.1", "0.171"], ["83913.8", "0.360022"], ["83913.2", "0.04"], ["83913.1", "0.039628"], ["83912.6", "0.035555"], ["83912.5", "0.013"], ["83912.4", "0.01288"], ["83912.3", "0.001466"], ["83912.2", "0.595402"], ["83912.1", "0.004615"], ["83911.9", "0.004766"], ["83911.8", "0.0016"], ["83911.7", "0.059399"], ["83911.5", "0.000522"], ["83911.4", "0.36826"], ["83911.3", "0.114365"], ["83911.2", "0.011918"], ["83910.7", "0.001333"], ["83910.1", "0.059569"], ["83909.6", "0.004263"], ["83909.3", "0.05"], ["83909.2", "0.049544"], ["83908.8", "0.005957"], ["83908.6", "0.535448"], ["83908.4", "0.0006"], ["83907.7", "0.001466"], ["83907.6", "0.0053"], ["83907.2", "0.000333"], ["83906.9", "0.000522"], ["83906.5", "0.001333"], ["83905.4", "0.004263"], ["83905.1", "0.174912"], ["83905", "0.028466"], ["83903.7", "0.013898"], ["83903.5", "0.357522"], ["83903.4", "0.118835"], ["83903.2", "10.330359"], ["83903.1", "0.001466"], ["83903", "3.127885"], ["83902.9", "0.171"], ["83902.8", "0.011919"], ["83902.3", "0.001853"], ["83901.2", "0.004249"], ["83901", "0.024942"], ["83900.7", "0.129099"], ["83900", "0.00006"], ["83899.2", "0.00009"], ["83898.8", "0.000333"], ["83898.5", "0.001466"], ["83898.1", "0.001333"], ["83897.7", "0.119355"], ["83897.2", "0.04"], ["83897", "0.004248"], ["83894.8", "0.059399"], ["83894.6", "0.024159"], ["83894.5", "0.171"], ["83894", "0.125091"], ["83893.9", "0.002799"], ["83893.4", "0.00036"], ["83893.1", "0.00052"], ["83892.8", "0.004248"], ["83892.6", "0.118835"], ["83892.4", "0.023828"], ["83892.1", "0.009225"], ["83892", "0.000118"], ["83891.1", "0.023824"], ["83890.8", "0.00009"], ["83890.7", "0.023828"], ["83890.6", "0.02376"], ["83890.4", "0.000333"], ["83889.7", "0.001333"], ["83889.5", "0.063818"], ["83889.4", "0.023828"], ["83889.3", "0.126563"], ["83888.6", "0.004248"], ["83888.5", "0.00052"], ["83888.1", "0.04"], ["83886.8", "0.118835"], ["83886.6", "0.023828"], ["83886.2", "0.000333"], ["83886.1", "0.04"], ["83885.9", "0.059399"], ["83885.8", "0.005957"], ["83885.5", "0.29626"], ["83885.4", "0.171"], ["83884.6", "0.001466"], ["83884.4", "0.004248"], ["83884.3", "0.353944"], ["83883.8", "0.00052"], ["83883.7", "0.0006"], ["83882.8", "0.015"], ["83882.4", "0.00018"], ["83882", "0.000333"], ["83881.3", "0.001333"], ["83880.8", "0.056493"], ["83880.7", "0.118835"], ["83880.2", "0.052248"], ["83880", "0.001526"], ["83879.2", "0.00052"], ["83879", "0.003575"], ["83878.7", "0.624383"], ["83878.3", "0.059605"], ["83877.9", "0.04"], ["83877.8", "0.024164"], ["83877.2", "0.059399"], ["83877.1", "0.001333"], ["83877", "0.1716"], ["83876.9", "0.0006"], ["83876.5", "0.11921"], ["83876.3", "0.052"], ["83876", "0.00419"], ["83875.9", "0.0006"], ["83875.8", "0.044"]], "a": [["83947.3", "0.009712"], ["83948.4", "0.003715"], ["83948.5", "0.000522"], ["83949.2", "0.000333"], ["83949.3", "0.001826"], ["83950.1", "0.0012"], ["83950.8", "0.006171"], ["83951.5", "0.00425"], ["83951.9", "0.000297"], ["83952.1", "0.05731"], ["83952.2", "0.1722"], ["83952.4", "0.000083"], ["83952.6", "0.001333"], ["83953", "0.06369"], ["83953.1", "0.000522"], ["83953.4", "0.000333"], ["83953.8", "0.024685"], ["83953.9", "0.001466"], ["83954.2", "0.039154"], ["83954.3", "0.109783"], ["83954.6", "0.1956"], ["83955.3", "0.0006"], ["83955.6", "0.0715"], ["83955.7", "0.024251"], ["83955.9", "0.0056"], ["83956", "0.0006"], ["83956.7", "0.005958"], ["83956.8", "0.008035"], ["83957", "0.003894"], ["83957.6", "0.02446"], ["83957.7", "0.000522"], ["83957.8", "0.059399"], ["83958", "0.037025"], ["83958.5", "0.001466"], ["83959.1", "0.0006"], ["83959.9", "0.004262"], ["83960", "0.013878"], ["83960.1", "0.027462"], ["83960.7", "0.0418"], ["83960.8", "0.04"], ["83961", "0.001333"], ["83961.2", "0.015333"], ["83961.8", "0.000333"], ["83962.3", "0.000524"], ["83962.4", "0.023835"], ["83962.5", "0.111494"], ["83963.1", "0.001466"], ["83963.5", "0.169554"], ["83963.6", "0.00009"], ["83963.7", "0.0006"], ["83963.8", "0.171"], ["83964.1", "0.004262"], ["83964.2", "0.08"], ["83964.3", "0.009792"], ["83964.6", "0.00315"], ["83965.1", "0.071492"], ["83965.2", "0.001333"], ["83965.3", "0.178684"], ["83965.5", "0.003"], ["83965.8", "0.045957"], ["83966", "0.000333"], ["83966.9", "0.000524"], ["83967.2", "0.176177"], ["83967.5", "0.04"], ["83967.7", "0.001466"], ["83968.3", "0.104871"], ["83968.5", "0.002735"], ["83968.9", "0.023825"], ["83969.4", "0.001333"], ["83970.2", "0.000333"], ["83970.3", "0.114348"], ["83970.9", "0.253494"], ["83971", "0.521346"], ["83971.4", "0.00036"], ["83971.6", "0.000524"], ["83972", "0.00018"], ["83972.2", "0.171"], ["83972.3", "0.001466"], ["83972.4", "0.011919"], ["83972.5", "0.004262"], ["83973.6", "0.001333"], ["83973.7", "0.004633"], ["83974", "0.005956"], ["83974.3", "0.000333"], ["83974.6", "0.0025"], ["83975.5", "0.002031"], ["83976.2", "0.000524"], ["83976.7", "0.004262"], ["83977", "0.001584"], ["83977.8", "0.091065"], ["83977.9", "0.125089"], ["83978.2", "0.000358"], ["83978.5", "0.000333"], ["83978.6", "0.059399"], ["83979.4", "0.265586"], ["83980.4", "0.00009"], ["83980.6", "0.171"], ["83980.7", "0.118835"], ["83980.8", "0.610611"], ["83980.9", "0.118262"], ["83981", "0.005956"], ["83981.5", "0.002978"], ["83981.6", "0.001466"], ["83982", "0.001333"], ["83982.4", "0.023827"], ["83982.7", "0.000333"], ["83982.8", "0.021935"], ["83984.3", "0.04"], ["83984.5", "0.023826"], ["83984.7", "0.015"], ["83985", "0.558121"], ["83985.1", "0.028088"], ["83985.4", "0.000524"], ["83985.8", "0.35"], ["83986", "0.118835"], ["83986.2", "0.002799"], ["83986.9", "0.000333"], ["83987.9", "0.059399"], ["83988.6", "0.023826"], ["83988.8", "0.00009"], ["83989", "0.171"], ["83989.1", "0.04"], ["83989.2", "0.04"], ["83989.3", "0.004264"], ["83990", "0.000524"], ["83990.3", "0.023826"], ["83990.4", "0.001333"], ["83990.8", "0.001466"], ["83991", "0.000204"], ["83991.1", "0.000333"], ["83991.4", "0.474264"], ["83992.5", "0.00018"], ["83992.6", "0.001786"], ["83993.5", "0.004624"], ["83993.6", "0.051348"], ["83994.6", "0.001857"], ["83995.3", "0.000333"], ["83995.4", "0.001466"], ["83996.5", "0.118835"], ["83997.2", "0.059489"], ["83997.4", "0.171"], ["83997.7", "0.004156"], ["83998.8", "0.001333"], ["83998.9", "0.125089"], ["83999.3", "0.000524"], ["83999.5", "0.000333"], ["83999.6", "0.0016"], ["84000", "0.02252"], ["84000.1", "0.001466"], ["84000.5", "0.04"], ["84000.7", "0.04"], ["84001.5", "0.0006"], ["84001.9", "0.004156"], ["84002.3", "1.787096"], ["84002.5", "0.023824"], ["84002.7", "0.04"], ["84003", "3.939411"], ["84003.1", "0.04"], ["84003.3", "0.022995"], ["84003.7", "0.000333"], ["84003.9", "0.000524"], ["84004.1", "0.013094"], ["84004.2", "0.04"], ["84004.7", "0.001466"], ["84004.9", "0.005956"], ["84005", "0.04"], ["84005.3", "0.000083"], ["84005.5", "0.353953"], ["84005.6", "0.00009"], ["84005.8", "0.171"], ["84005.9", "0.005"], ["84006.1", "0.004156"], ["84006.2", "0.357522"], ["84006.3", "0.04"], ["84006.6", "0.118835"], ["84007", "0.04"], ["84007.2", "0.001333"], ["84007.9", "0.000333"], ["84008", "0.059399"], ["84008.5", "0.000524"], ["84009.3", "0.001466"], ["84010", "0.011994"], ["84010.3", "0.004156"], ["84010.8", "2.612353"], ["84011", "3.342186"], ["84011.2", "0.015"], ["84011.4", "0.001333"], ["84012", "0.000333"], ["84012.1", "0.000333"], ["84013.1", "0.000524"], ["84013.2", "0.011864"], ["84013.4", "0.656573"], ["84013.6", "0.011994"], ["84013.9", "0.001466"], ["84014", "0.012174"], ["84014.4", "0.12"], ["84014.5", "0.004156"], ["84015.6", "0.001693"], ["84015.7", "0.05942"], ["84016", "0.000145"]], "u": 128039, "seq": 67571128310}, "cts": 1742576906316, "record_time": 1742576907.727987, "EXCHANGE": "BYBIT"}
{"topic": "orderbook.200.BTCUSDT", "ts": 1742576906520, "type": "delta", "data": {"s": "BTCUSDT", "b": [["83947.2", "0.408002"], ["83941.9", "0"], ["83932.6", "0"], ["83927.6", "0.076434"], ["83923.1", "0"], ["83920.1", "0.192333"], ["83917.5", "0.178684"], ["83914.8", "0.04"], ["83914.7", "0.03963"], ["83913.3", "0.178684"], ["83913.2", "0"], ["83913.1", "0"], ["83911.9", "0"], ["83905.2", "0.35752"], ["83903.5", "0"], ["83903.2", "10.330353"], ["83903", "0.134045"], ["83891.8", "0.178684"], ["83875.4", "0.001466"]], "a": [["83947.3", "0.009951"], ["83957.2", "0.000153"], ["83960", "0.054809"], ["83960.7", "0.113296"], ["83962.4", "0.063835"], ["83965.1", "0"], ["83965.8", "0.085957"], ["83967.2", "0"], ["83967.4", "0.04"], ["83967.8", "0.178684"], ["83972", "0.178864"], ["83975.5", "0.011743"], ["83977.8", "0.001333"], ["83984.3", "0"], ["83985", "0.165578"], ["84000", "0.201204"], ["84005.3", "2.612345"], ["84005.7", "0.357517"], ["84006.2", "0"], ["84010.8", "0"], ["84014.2", "0.171"], ["84015.1", "0.125079"], ["84016", "0"]], "u": 128040, "seq": 67571128399}, "cts": 1742576906516, "record_time": 1742576907.728988, "EXCHANGE": "BYBIT"}
{"topic": "orderbook.200.BTCUSDT", "ts": 1742576906720, "type": "delta", "data": {"s": "BTCUSDT", "b": [["83943.7", "0.537402"], ["83931.8", "0.132275"], ["83931", "0.178718"], ["83930.3", "0.154344"], ["83929.3", "0.178722"], ["83916.6", "0.009951"], ["83914.8", "0"], ["83914.6", "0.03963"], ["83912.5", "0"], ["83912.3", "0.014346"], ["83911.3", "0"], ["83909.3", "0"], ["83909.1", "0.049545"], ["83905.3", "0.155616"], ["83905.1", "0"], ["83892.3", "0.089342"], ["83891.8", "0"], ["83889.1", "0.178807"], ["83878.8", "0.000149"], ["83875.9", "0"], ["83875.8", "0"], ["83875.4", "0"]], "a": [["83957", "0.004047"], ["83957.2", "0"], ["83967.7", "0.129305"], ["83989.1", "0"], ["83989.3", "0.044264"], ["83997.2", "0.148831"], ["84000", "0.02252"], ["84005.7", "0"], ["84007.9", "0.357849"], ["84015.1", "0"], ["84016.3", "0.059888"], ["84016.7", "0.130699"], ["84016.8", "0.011994"], ["84017.4", "0.011993"]], "u": 128041, "seq": 67571128465}, "cts": 1742576906717, "record_time": 1742576907.730988, "EXCHANGE": "BYBIT"}
{"topic": "orderbook.200.BTCUSDT", "ts": 1742576906919, "type": "delta", "data": {"s": "BTCUSDT", "b": [["83943.7", "0.535616"], ["83924.5", "0.178684"], ["83923.1", "0.053195"], ["83910.3", "0.125079"], ["83905.4", "0.36178"], ["83905.2", "0"], ["83901.6", "0.001786"], ["83876.5", "0"], ["83876.3", "0"], ["83876", "0"]], "a": [["83956.7", "0"], ["83956.9", "0.000153"], ["83957", "0.003894"], ["83957.5", "0.005958"], ["83969.8", "0.178684"], ["83973.2", "0.125079"], ["83988.9", "0.227164"], ["83994.2", "0.125079"], ["84007.9", "0.000333"], ["84010.9", "0.357508"], ["84015.6", "0"], ["84015.7", "0"], ["84016.3", "0"], ["84016.7", "0"], ["84016.8", "0"], ["84017.4", "0"]], "u": 128042, "seq": 67571128504}, "cts": 1742576906913, "record_time": 1742576907.731987, "EXCHANGE": "BYBIT"}
{"topic": "orderbook.200.BTCUSDT", "ts": 1742576907119, "type": "delta", "data": {"s": "BTCUSDT", "b": [["83943.7", "0.524015"], ["83934.1", "0"], ["83927.6", "0.113492"], ["83905.5", "0.156894"], ["83905.4", "0.004263"], ["83905.3", "0"], ["83903.5", "0.357519"]], "a": [["83952", "0.096047"], ["83954.5", "0.071501"], ["83955.6", "0"], ["83956.7", "0.005958"], ["83956.9", "0"], ["83957.5", "0"], ["83965.5", "0"], ["83967.3", "0.178684"], ["83969.8", "0"], ["83977.8", "0.056887"], ["84006.5", "0.35752"], ["84010.9", "0"], ["84015.6", "0.001693"]], "u": 128043, "seq": 67571128560}, "cts": 1742576907116, "record_time": 1742576907.732988, "EXCHANGE": "BYBIT"}
{"topic": "orderbook.200.BTCUSDT", "ts": 1742576907320, "type": "delta", "data": {"s": "BTCUSDT", "b": [["83905.6", "0.357518"], ["83903.5", "0"]], "a": [["83952", "0"], ["83967.2", "0.205884"], ["83967.7", "0.001466"], ["83990.8", "0.052813"], ["83991.7", "0.014089"], ["83993.6", "0"], ["84002.7", "2.652262"], ["84005.3", "0.000083"], ["84006.5", "0"], ["84007.9", "0.357851"], ["84015.7", "0.05942"]], "u": 128044, "seq": 67571128597}, "cts": 1742576907317, "record_time": 1742576907.734988, "EXCHANGE": "BYBIT"}
{"topic": "orderbook.200.BTCUSDT", "ts": 1742576907519, "type": "delta", "data": {"s": "BTCUSDT", "b": [["83947.2", "0.422603"], ["83945.9", "0.0013"], ["83940.5", "0"], ["83940.2", "0.060428"], ["83940", "0.053189"], ["83917.2", "0.0016"], ["83911.8", "0"], ["83905.7", "0.156894"], ["83905.6", "0.357513"], ["83905.5", "0"]], "a": [["83969.8", "0.178684"], ["83994.1", "0.038621"], ["84007.9", "0.000333"], ["84010.9", "0.357509"], ["84014.5", "0"], ["84015.6", "0"], ["84015.7", "0"]], "u": 128045, "seq": 67571128684}, "cts": 1742576907516, "record_time": 1742576907.735988, "EXCHANGE": "BYBIT"}
{"topic": "orderbook.200.BTCUSDT", "ts": 1742576907720, "type": "delta", "data": {"s": "BTCUSDT", "b": [["83905.8", "0.357518"], ["83905.6", "0"]], "a": [["83952", "0.096047"], ["83956.4", "0.000153"], ["84006.9", "0.357518"], ["84010.9", "0"], ["84014.2", "0"], ["84014.4", "0"]], "u": 128046, "seq": 67571128711}, "cts": 1742576907717, "record_time": 1742576907.907931, "EXCHANGE": "BYBIT"}
{"topic": "orderbook.200.BTCUSDT", "ts": 1742576907919, "type": "delta", "data": {"s": "BTCUSDT", "b": [["83943.6", "0.006805"], ["83931.8", "0.189429"], ["83931.5", "0.032702"], ["83927.2", "0"], ["83905.9", "0.156894"], ["83905.7", "0"], ["83903.2", "10.33033"], ["83876.9", "0"]], "a": [["83954.5", "0"], ["83956.1", "0.005958"], ["83956.2", "0.0715"], ["83956.4", "0"], ["83956.7", "0"], ["83960.7", "0.0418"], ["83961", "0.072829"], ["83962.5", "0.04"], ["83964.8", "0.071492"], ["84002.7", "0.04"], ["84005.3", "2.612345"], ["84006.9", "0"], ["84007.9", "0.357851"], ["84014.4", "0.12"]], "u": 128047, "seq": 67571128798}, "cts": 1742576907917, "record_time": 1742576908.10769, "EXCHANGE": "BYBIT"}
{"topic": "orderbook.200.BTCUSDT", "ts": 1742576908119, "type": "delta", "data": {"s": "BTCUSDT", "b": [["83947.2", "0.420728"], ["83905.8", "0"], ["83905", "0.003575"], ["83903.5", "0.35752"], ["83903.3", "3.203138"], ["83903", "0.000333"], ["83877", "0"]], "a": [["83954.9", "0.071501"], ["83956.1", "0"], ["83956.2", "0"], ["83956.7", "0.005958"], ["84002.7", "2.652262"], ["84005.3", "0.000083"], ["84006.5", "0.35752"], ["84007.9", "0.000333"], ["84014.4", "0"]], "u": 128048, "seq": 67571128853}, "cts": 1742576908109, "record_time": 1742576908.307439, "EXCHANGE": "BYBIT"}
{"topic": "orderbook.200.BTCUSDT", "ts": 1742576908320, "type": "delta", "data": {"s": "BTCUSDT", "b": [["83943.8", "0.107848"], ["83943.7", "0.351258"], ["83940", "0.033224"], ["83906", "0.357517"], ["83903.5", "0"]], "a": [["83954.1", "0.071501"], ["83954.9", "0"], ["83955.6", "0.005958"], ["83956.1", "0.000153"], ["83956.7", "0"], ["83959.6", "0.071497"], ["83964.8", "0"], ["83989.2", "1.468756"], ["83999", "0.023316"], ["84003.3", "0"], ["84006.5", "0"], ["84007.9", "0.35785"]], "u": 128049, "seq": 67571128932}, "cts": 1742576908316, "record_time": 1742576908.507383, "EXCHANGE": "BYBIT"}
{"topic": "orderbook.200.BTCUSDT", "ts": 1742576908520, "type": "delta", "data": {"s": "BTCUSDT", "b": [["83919.2", "0"], ["83914.8", "0.024766"], ["83914.7", "0"], ["83914.5", "0.03963"], ["83912.4", "0"], ["83912.2", "0.608282"], ["83909.2", "0"], ["83909", "0.049545"], ["83906.1", "0.149426"], ["83906", "0"], ["83905.9", "0"], ["83903.5", "0.357519"], ["83877", "0.0006"]], "a": [["83955.6", "0"], ["83956.7", "0.005958"], ["83988.9", "0.6428"], ["83989.2", "1.428756"], ["83989.3", "0.004264"], ["83989.5", "0.04"], ["83989.6", "0.04"], ["84006.2", "0.357523"], ["84007.9", "0.000333"], ["84013.6", "0"], ["84013.9", "0"], ["84014", "0"]], "u": 128050, "seq": 67571128989}, "cts": 1742576908513, "record_time": 1742576908.70809, "EXCHANGE": "BYBIT"}
{"topic": "orderbook.200.BTCUSDT", "ts": 1742576908720, "type": "delta", "data": {"s": "BTCUSDT", "b": [["83877", "0.1716"]], "a": [["84006.1", "0.361681"], ["84006.2", "0"], ["84013.6", "0.011994"]], "u": 128051, "seq": 67571129028}, "cts": 1742576908716, "record_time": 1742576908.907767, "EXCHANGE": "BYBIT"}
{"topic": "orderbook.200.BTCUSDT", "ts": 1742576908920, "type": "delta", "data": {"s": "BTCUSDT", "b": [["83947.2", "0.307507"], ["83943.6", "0"], ["83940.2", "0.039475"], ["83940", "0.003312"], ["83938.7", "0.029912"], ["83931.8", "0.091588"], ["83931", "0"], ["83929.3", "0"], ["83928", "0.178725"], ["83903.5", "0"], ["83903.2", "0.192666"], ["83894.9", "0.357534"], ["83892.1", "10.419239"], ["83876.9", "0.0006"], ["83876.5", "0.11921"]], "a": [["83947.3", "0.101225"], ["83952.9", "0.005958"], ["83954.1", "0"], ["83956.7", "0"], ["83958", "0.108523"], ["83959.6", "0"], ["83988", "0.051347"], ["83989.5", "0"], ["83989.6", "0"], ["83989.7", "0.04"], ["83989.8", "0.04"], ["83990.8", "0.001466"], ["84000.4", "0.357534"], ["84006.1", "0.004156"]], "u": 128052, "seq": 67571129179}, "cts": 1742576908915, "record_time": 1742576909.107701, "EXCHANGE": "BYBIT"}
{"topic": "orderbook.200.BTCUSDT", "ts": 1742576909120, "type": "delta", "data": {"s": "BTCUSDT", "b": [["83926.3", "0.178728"], ["83909.2", "0.049544"], ["83909", "0"], ["83906.1", "0.042171"], ["83903.3", "0.161839"], ["83897.8", "0.357538"], ["83894.9", "0"], ["83876.5", "0"]], "a": [["83947.3", "0.09973"], ["83952.2", "0.243703"], ["83988", "0"], ["83990.8", "0.052813"], ["84002.7", "0.04"], ["84010.8", "2.612262"]], "u": 128053, "seq": 67571129320}, "cts": 1742576909117, "record_time": 1742576909.307478, "EXCHANGE": "BYBIT"}
{"topic": "orderbook.200.BTCUSDT", "ts": 1742576909320, "type": "delta", "data": {"s": "BTCUSDT", "b": [["83947.2", "0.188878"], ["83945.9", "0"], ["83943.8", "0"], ["83943.7", "0.105748"], ["83942", "0.071512"], ["83940", "0.001526"], ["83938.7", "0"], ["83936.3", "0"], ["83935.1", "0.093052"], ["83935", "0.171514"], ["83932.9", "0"], ["83928.1", "0.220496"], ["83928", "0"], ["83927.6", "0"], ["83926.3", "0"], ["83925.5", "0"], ["83925.3", "0"], ["83920.1", "0.132934"], ["83918.4", "0"], ["83917.6", "0"], ["83916.6", "0"], ["83915.8", "0.039318"], ["83914.8", "0"], ["83910.1", "0.083515"], ["83909.2", "0"], ["83909", "0.049545"], ["83901", "0"], ["83897.8", "0"], ["83897.3", "0.357554"], ["83892.1", "0.009225"], ["83881.1", "10.410014"], ["83876.5", "0.11921"], ["83876.3", "0.052"], ["83876.2", "1.786836"], ["83876", "0.00419"], ["83875.9", "0.0006"], ["83875.8", "0.044"], ["83875.4", "0.001466"], ["83874.8", "0.120716"], ["83874.7", "0.118835"], ["83874.6", "0.00302"], ["83874.4", "3.953577"], ["83874", "0.00009"]], "a": [["83947.3", "0.326964"], ["83947.6", "0.023371"], ["83947.7", "0.071507"], ["83952.2", "0.1722"], ["83952.9", "0"], ["83953.4", "0.071835"], ["83956.1", "0"], ["83958", "0.037025"], ["83960", "0"], ["83961", "0.001333"], ["83962.4", "0.04"], ["83969.5", "0.003576"], ["83969.8", "0"], ["83970.2", "0.119455"], ["83970.8", "0.118835"], ["83990.1", "0.022831"], ["83994.1", "0.063265"], ["83996.4", "0.357553"], ["83997.4", "0.193883"], ["83999", "0"], ["84000.4", "0"], ["84010.8", "0"], ["84013.9", "0.001466"]], "u": 128054, "seq": 67571129563}, "cts": 1742576909305, "record_time": 1742576909.508852, "EXCHANGE": "BYBIT"}
{"topic": "orderbook.200.BTCUSDT", "ts": 1742576909520, "type": "delta", "data": {"s": "BTCUSDT", "b": [["83947.2", "0.18261"], ["83943.2", "0.071511"], ["83942", "0"], ["83941.5", "0.072942"], ["83940.8", "0.015742"], ["83940.2", "0"], ["83939.9", "0"], ["83936.6", "0.006984"], ["83928.5", "0.157392"], ["83928.1", "0"], ["83925.4", "0.179252"], ["83925.3", "0.009329"], ["83924.5", "0"], ["83922", "0.178684"], ["83920.2", "0.059399"], ["83920", "0.00006"], ["83918.9", "0.119122"], ["83917.6", "0.118835"], ["83915.8", "0.003575"], ["83915", "0.125079"], ["83913.3", "0.214428"], ["83909.4", "0.05"], ["83909.3", "0.049544"], ["83909.1", "0"], ["83909", "0"], ["83903.2", "0.192667"], ["83897.3", "0"], ["83894.9", "0.357561"], ["83874.4", "0"], ["83874", "0"]], "a": [["83947.3", "0.291125"], ["83947.5", "0.005958"], ["83947.7", "0"], ["83948.9", "0.071506"], ["83952.3", "0.009225"], ["83953.1", "0.003522"], ["83955.5", "0.04"], ["83955.7", "0.064251"], ["83955.9", "0.0771"], ["83958.3", "0.061009"], ["83958.9", "0.04"], ["83960.1", "0.018237"], ["83960.6", "0.04"], ["83960.7", "0.0818"], ["83962.4", "0"], ["83962.5", "0"], ["83963.6", "0.178774"], ["83965", "0.003576"], ["83965.3", "0"], ["83965.8", "0.045957"], ["83968.5", "0.117071"], ["83969.5", "0"], ["83970.2", "0.000333"], ["83970.3", "0"], ["83972", "0.00018"], ["83985.1", "0.079435"], ["83990.8", "0.001466"], ["83994", "0.357561"], ["83996.4", "0"], ["84013.6", "0"], ["84013.9", "0"]], "u": 128055, "seq": 67571129818}, "cts": 1742576909516, "record_time": 1742576909.707901, "EXCHANGE": "BYBIT"}
{"topic": "orderbook.200.BTCUSDT", "ts": 1742576909720, "type": "delta", "data": {"s": "BTCUSDT", "b": [["83947.2", "0.373605"], ["83943.8", "0.053607"], ["83943.2", "0"], ["83943", "0.071511"], ["83941.5", "0.00143"], ["83940.8", "0.000333"], ["83940.2", "0.029966"], ["83938.9", "0.075904"], ["83928.5", "0.103787"], ["83920", "0.178744"], ["83912.5", "0.01288"], ["83912.4", "0.01288"], ["83912.3", "0.001466"], ["83912.2", "0.595402"], ["83909.4", "0"], ["83909.2", "0.049544"], ["83903.2", "0.192661"], ["83897.8", "0.357555"], ["83894.9", "0"], ["83883.8", "10.410534"], ["83881.1", "0"], ["83874.8", "0"], ["83874.7", "0"], ["83874.6", "0"]], "a": [["83947.3", "0.100243"], ["83947.5", "0"], ["83947.6", "0"], ["83948.9", "0"], ["83951.9", "0.006255"], ["83953.8", "0.064685"], ["83954", "0.04"], ["83954.3", "0.163723"], ["83957.2", "0.04"], ["83957.3", "0.04"], ["83959", "0.04"], ["83960.8", "0"], ["83962.8", "0.178684"], ["83964.2", "0.04"], ["83965.8", "0.005957"], ["83967.4", "0"], ["83967.5", "0"], ["83970.8", "0"], ["83972", "0.178864"], ["83988.4", "0.04"], ["83990.1", "0"], ["83994", "0"], ["83997.1", "2.612262"], ["83998.8", "0.358879"], ["84013.6", "0.011994"], ["84013.9", "0.001466"]], "u": 128056, "seq": 67571129974}, "cts": 1742576909716, "record_time": 1742576909.907648, "EXCHANGE": "BYBIT"}
{"topic": "orderbook.200.BTCUSDT", "ts": 1742576909919, "type": "delta", "data": {"s": "BTCUSDT", "b": [["83947.2", "0.202605"], ["83929.7", "0.023565"], ["83914.9", "0.041333"], ["83914.8", "0.03963"], ["83914.6", "0"], ["83914.5", "0"], ["83912.6", "0.048555"], ["83912.4", "0"], ["83909.4", "0.05"], ["83909.2", "0"], ["83897.9", "0.357543"], ["83897.8", "0"], ["83886.6", "10.433842"], ["83883.8", "0.00052"], ["83874.8", "0.120716"]], "a": [["83947.3", "0.10009"], ["83949.1", "0.0221"], ["83949.2", "0.071839"], ["83950.7", "0.005958"], ["83951.9", "0.000297"], ["83953.4", "0.000333"], ["83954.4", "0.071501"], ["83955.9", "0.0056"], ["83957.9", "0.071498"], ["83960.7", "0.0418"], ["83962.7", "0.179678"], ["83962.8", "0"], ["83963.5", "0"], ["83964.2", "0"], ["83965", "0"], ["83965.3", "0.178684"], ["83969.8", "0.178684"], ["83970.9", "0.372329"], ["83986.8", "0.04"], ["83986.9", "0.040333"], ["83989.7", "0"], ["83989.8", "0"], ["83993.5", "0.044624"], ["83998.8", "0.001333"], ["84000.4", "0.357541"], ["84013.4", "0"], ["84013.6", "0"], ["84013.9", "0"]], "u": 128057, "seq": 67571130078}, "cts": 1742576909916, "record_time": 1742576910.107146, "EXCHANGE": "BYBIT"}
{"topic": "orderbook.200.BTCUSDT", "ts": 1742576910119, "type": "delta", "data": {"s": "BTCUSDT", "b": [["83947.2", "0.211572"], ["83932.1", "0.155396"], ["83931.8", "0"], ["83930.3", "0.214688"], ["83923.3", "0.058244"], ["83923.1", "0.11797"], ["83916.3", "0.118522"], ["83914.9", "0.001333"], ["83914.7", "0.03963"], ["83912.6", "0.035555"], ["83912.4", "0.01288"], ["83909.4", "0"], ["83909.2", "0.049544"], ["83903.2", "0.192652"], ["83898", "0.357551"], ["83897.9", "0"], ["83892.1", "10.645634"], ["83886.6", "0.023828"], ["83875.8", "0"], ["83875.4", "0"], ["83874.8", "0"]], "a": [["83965.3", "0.23407"], ["83972.3", "0.058952"], ["83979.3", "0.114145"], ["83986.7", "0.04"], ["83986.9", "0.000333"], ["83998.8", "0.358884"], ["84000.4", "0"], ["84013.2", "0"]], "u": 128058, "seq": 67571130184}, "cts": 1742576910115, "record_time": 1742576910.307273, "EXCHANGE": "BYBIT"}
{"topic": "orderbook.200.BTCUSDT", "ts": 1742576910319, "type": "delta", "data": {"s": "BTCUSDT", "b": [["83947.2", "0.191577"], ["83936.6", "0.000333"], ["83932.1", "0.111932"], ["83930.3", "0.154344"], ["83929.7", "0"], ["83923.3", "0.001333"], ["83916.3", "0"], ["83898.1", "0.157679"], ["83898", "0"], ["83897.3", "0.357556"], ["83892.1", "0.009225"], ["83886.6", "10.660237"], ["83875.8", "0.044"], ["83875.4", "0.001466"]], "a": [["83947.3", "0.360142"], ["83947.9", "0.005958"], ["83948", "0.025158"], ["83948.1", "0.071507"], ["83949.1", "0"], ["83949.2", "0.000333"], ["83950.7", "0"], ["83952.3", "0"], ["83956.7", "0.071499"], ["83957.9", "0"], ["83965.3", "0"], ["83969.8", "0"], ["83971.7", "0.003576"], ["83972", "0.00018"], ["83972.3", "0.001466"], ["83975.5", "0.002031"], ["83979.3", "0"], ["83986.7", "0"], ["83986.9", "0.040333"], ["83996.4", "0.357558"], ["83997", "2.612262"], ["83997.1", "0"], ["83997.4", "0.216714"], ["83998.8", "0.001333"], ["84013.2", "0.011864"], ["84013.4", "0.656573"]], "u": 128059, "seq": 67571130327}, "cts": 1742576910316, "record_time": 1742576910.507285, "EXCHANGE": "BYBIT"}
{"topic": "orderbook.200.BTCUSDT", "ts": 1742576910520, "type": "delta", "data": {"s": "BTCUSDT", "b": [["83943.8", "0"], ["83898.2", "0.357553"], ["83897.3", "0"], ["83874.8", "0.120716"]], "a": [["83947.3", "0.366253"], ["83947.9", "0"], ["83962.7", "0.113"], ["83962.8", "0.178684"], ["83973.6", "0.037077"]], "u": 128060, "seq": 67571130383}, "cts": 1742576910515, "record_time": 1742576910.707312, "EXCHANGE": "BYBIT"}
{"topic": "orderbook.200.BTCUSDT", "ts": 1742576910719, "type": "delta", "data": {"s": "BTCUSDT", "b": [["83936.5", "0.041286"], ["83922", "0"], ["83920.3", "0.059399"], ["83920.2", "0"], ["83920", "0.00006"], ["83919.5", "0.178684"], ["83917.6", "0"], ["83917.5", "0"], ["83915", "0"], ["83913.3", "0.035744"], ["83898.2", "0"], ["83898.1", "0.001333"], ["83897.3", "0.536239"], ["83892.3", "0"], ["83874.7", "0.118835"], ["83874.6", "0.00302"], ["83874.4", "3.953577"], ["83874", "0.00009"]], "a": [["83947.3", "0.356875"], ["83950.7", "0.009225"], ["83952.9", "0.071503"], ["83954.4", "0"], ["83959.8", "0.002384"], ["83986.8", "0"], ["83987", "0.04"], ["84013.2", "0"], ["84013.4", "0"]], "u": 128061, "seq": 67571130445}, "cts": 1742576910686, "record_time": 1742576910.907399, "EXCHANGE": "BYBIT"}
{"topic": "orderbook.200.BTCUSDT", "ts": 1742576910919, "type": "delta", "data": {"s": "BTCUSDT", "b": [["83947.2", "0.190793"], ["83927", "0.024427"], ["83923.1", "0.053195"], ["83922", "0.178684"], ["83920.1", "0"], ["83920", "0.178744"], ["83919.5", "0"], ["83897.8", "0.357554"], ["83897.3", "0"], ["83894.3", "0.353923"], ["83892.1", "10.645634"], ["83886.6", "0.023828"], ["83884.3", "0"]], "a": [["83947.3", "0.36689"], ["83950.7", "0"], ["84013.2", "0.011864"]], "u": 128062, "seq": 67571130487}, "cts": 1742576910915, "record_time": 1742576911.106379, "EXCHANGE": "BYBIT"}
{"topic": "orderbook.200.BTCUSDT", "ts": 1742576911120, "type": "delta", "data": {"s": "BTCUSDT", "b": [["83943.7", "0.108748"], ["83920.1", "0.099408"], ["83917.5", "0.178684"], ["83915", "0.125079"], ["83913.3", "0.214428"], ["83903.2", "0.192663"], ["83892.1", "0.009225"], ["83886.6", "10.783031"], ["83874.6", "0"], ["83874.4", "0"], ["83874", "0"]], "a": [["83947.3", "0.360932"], ["83947.9", "0.005958"], ["83996.4", "0"], ["83998.8", "0.358884"]], "u": 128063, "seq": 67571130516}, "cts": 1742576911107, "record_time": 1742576911.307702, "EXCHANGE": "BYBIT"}
{"topic": "orderbook.200.BTCUSDT", "ts": 1742576911320, "type": "delta", "data": {"s": "BTCUSDT", "b": [["83914.8", "0"], ["83914.7", "0"], ["83914.6", "0.04"], ["83914.5", "0.03963"], ["83912.5", "0"], ["83912.4", "0"], ["83912.3", "0.014466"], ["83912.2", "0.608282"], ["83909.3", "0"], ["83909.2", "0"], ["83909.1", "0.05"], ["83909", "0.049545"], ["83897.8", "0.357545"], ["83892.3", "0.089342"], ["83889.4", "10.783031"], ["83886.6", "0.023828"], ["83874.6", "0.00302"]], "a": [["83947.3", "0.351707"], ["83957.5", "0.009225"], ["83974.7", "0.003438"], ["83986.9", "0.000333"], ["83987", "0"], ["83987.5", "0.04"], ["83987.6", "0.04"], ["83996.4", "0.357553"], ["83998.8", "0.001333"], ["84012", "0"], ["84012.1", "0"], ["84013.1", "0"], ["84013.2", "0"]], "u": 128064, "seq": 67571130561}, "cts": 1742576911303, "record_time": 1742576911.507806, "EXCHANGE": "BYBIT"}
{"topic": "orderbook.200.BTCUSDT", "ts": 1742576911519, "type": "delta", "data": {"s": "BTCUSDT", "b": [["83947.2", "0.201821"], ["83943.7", "0.105748"], ["83940.5", "0.0016"], ["83935.1", "0.135395"], ["83926.1", "0.178729"], ["83925.4", "0.000522"], ["83920", "0.00006"], ["83917.2", "0"], ["83915", "0"], ["83914.6", "0"], ["83914.4", "0.039631"], ["83912.3", "0.001466"], ["83912.1", "0.017495"], ["83911.8", "0.0016"], ["83909.1", "0"], ["83908.9", "0.049545"], ["83900.8", "0.357543"], ["83897.8", "0"], ["83892.3", "0"]], "a": [["83947.3", "0.337664"], ["83947.9", "0"], ["83948", "0.071507"], ["83948.1", "0"], ["83950.9", "0.009225"], ["83952.9", "0"], ["83953.3", "0.003"], ["83954.3", "0.235224"], ["83956.8", "0.001333"], ["83957.5", "0"], ["83958.3", "0.108385"], ["83967.3", "0"], ["83971.7", "0"], ["83972", "0.178864"], ["83987.5", "0"], ["83987.7", "0.04"], ["83996.4", "0"], ["83997", "0"], ["84000.4", "0.357547"], ["84008.1", "2.612262"], ["84012", "0.000333"], ["84012.1", "0.000333"], ["84013.1", "0.000524"], ["84013.2", "0.011864"]], "u": 128065, "seq": 67571130756}, "cts": 1742576911515, "record_time": 1742576911.707045, "EXCHANGE": "BYBIT"}
{"topic": "orderbook.200.BTCUSDT", "ts": 1742576911720, "type": "delta", "data": {"s": "BTCUSDT", "b": [["83935.1", "0.093052"], ["83933.8", "0.121773"], ["83926.1", "0"], ["83925.3", "0.188059"], ["83924", "0.163546"], ["83920", "0.178744"], ["83917.5", "0"], ["83914.9", "0.297585"], ["83913.3", "0.035744"], ["83912.5", "0.013"], ["83912.4", "0.01288"], ["83912.2", "0.595402"], ["83912.1", "0.004615"], ["83909.3", "0.049544"], ["83909.2", "0.049544"], ["83909", "0"], ["83908.9", "0"], ["83903.2", "0.059399"], ["83900.8", "0"], ["83900.4", "0.133264"], ["83894.6", "0.381728"], ["83892.3", "0.089342"], ["83874.6", "0"]], "a": [["83947.3", "0.346736"], ["83947.9", "0.023371"], ["83950.9", "0"], ["83956.8", "0.008172"], ["83958.3", "0.143451"], ["83959", "0.158236"], ["83959.3", "0.178658"], ["83961", "0.179987"], ["83962.3", "0.179208"], ["83962.6", "0.178651"], ["83965.3", "0.178684"], ["83967.2", "0.128275"], ["83968.8", "0.164106"], ["83971.1", "0.003576"], ["83972", "0.00018"], ["83977.9", "0.420603"], ["83993.4", "0.357565"], ["84000.4", "0"], ["84002.6", "2.612262"], ["84005", "0"], ["84008.1", "0"], ["84012", "0"], ["84012.1", "0"], ["84013.1", "0"], ["84013.2", "0"]], "u": 128066, "seq": 67571130855}, "cts": 1742576911693, "record_time": 1742576911.907361, "EXCHANGE": "BYBIT"}
{"topic": "orderbook.200.BTCUSDT", "ts": 1742576911919, "type": "delta", "data": {"s": "BTCUSDT", "b": [["83934.1", "0.113258"], ["83933.8", "0.00378"], ["83924", "0.000333"], ["83923.6", "0.183668"], ["83917.5", "0.178684"], ["83916.6", "0.308851"], ["83914.9", "0.041333"], ["83914.8", "0.03963"], ["83914.5", "0"], ["83914.4", "0"], ["83913.3", "0.214428"], ["83912.6", "0.048555"], ["83912.5", "0.01288"], ["83912.4", "0"], ["83909.4", "0.05"], ["83909.2", "0"], ["83894.6", "0.024159"], ["83894.1", "0.357569"], ["83892.1", "10.796533"], ["83889.4", "0.023828"], ["83878.7", "0.4"], ["83875.4", "0"], ["83874.8", "0"], ["83874.7", "0"]], "a": [["83947.3", "0.331553"], ["83947.8", "0.005958"], ["83958.2", "0.009225"], ["83958.6", "0.124388"], ["83959", "0.04"], ["83962.7", "0.206086"], ["83968.8", "0"], ["83969.1", "0.165261"], ["83971.1", "0"], ["83976.1", "0.284646"], ["83977.9", "0.125089"], ["83987", "0.04"], ["83987.1", "0.04"], ["83987.6", "0"], ["83987.7", "0"], ["83991.8", "0.04"], ["83997", "2.612262"], ["84002.6", "0"], ["84010.3", "0"], ["84011", "0"], ["84011.2", "0"], ["84011.4", "0"]], "u": 128067, "seq": 67571130920}, "cts": 1742576911916, "record_time": 1742576912.10665, "EXCHANGE": "BYBIT"}
{"topic": "orderbook.200.BTCUSDT", "ts": 1742576912119, "type": "delta", "data": {"s": "BTCUSDT", "b": [["83947.2", "0.209549"], ["83934.1", "0"], ["83933.9", "0.117963"], ["83930.1", "0.160787"], ["83924.1", "0.182758"], ["83923.7", "0.186076"], ["83923.6", "0"], ["83923.1", "0.185598"], ["83916.7", "0.118835"], ["83916.6", "0"], ["83916.1", "0.276997"], ["83915", "0.471901"], ["83914.9", "0.040963"], ["83914.8", "0"], ["83912.7", "0.013"], ["83912.6", "0.048435"], ["83912.5", "0"], ["83909.5", "0.05"], ["83909.4", "0.049544"], ["83909.3", "0"], ["83905.4", "0.100801"], ["83894.1", "0"], ["83892.7", "0.357569"]], "a": [["83947.8", "0"], ["83947.9", "0"], ["83948", "0"], ["83950.1", "0.007158"], ["83950.2", "0.071505"], ["83953.4", "0.003328"], ["83954.3", "0.163723"], ["83958.3", "0.206242"], ["83958.6", "0"], ["83959.1", "0.113286"], ["83959.7", "0.071497"], ["83963", "0.123561"], ["83968.9", "0.197931"], ["83969.1", "0"], ["83970", "0.184234"], ["83976.1", "0"], ["83977", "0.282028"], ["83978", "0.299749"], ["83986.7", "0.04"], ["83986.8", "0.04"], ["83987", "0"], ["83987.1", "0"], ["84010.3", "0.004156"]], "u": 128068, "seq": 67571130982}, "cts": 1742576912096, "record_time": 1742576912.307279, "EXCHANGE": "BYBIT"}
{"topic": "orderbook.200.BTCUSDT", "ts": 1742576912320, "type": "delta", "data": {"s": "BTCUSDT", "b": [["83947.2", "0.189554"], ["83933.9", "0"], ["83930.1", "0.04"], ["83924.1", "0"], ["83923.1", "0"], ["83920", "0.00006"], ["83916.8", "0.118835"], ["83916.7", "0"], ["83916.1", "0.000522"], ["83915", "0.125079"], ["83914.8", "0.03963"], ["83912.7", "0"], ["83912.5", "0.01288"], ["83909.5", "0"], ["83909.3", "0.049544"], ["83909.1", "0.178684"], ["83897.8", "0.049081"]], "a": [["83947.3", "0.346736"], ["83950.1", "0.0012"], ["83958.2", "0"], ["83959.1", "0.0006"], ["83962.5", "0.310874"], ["83962.7", "0"], ["83963", "0"], ["83964.7", "0.003576"], ["83965.3", "0"], ["83968.9", "0.023825"], ["83970", "0"], ["83977", "0.001584"], ["83978", "0"], ["83986.7", "0"], ["83986.9", "0.040333"], ["84011", "3.342186"], ["84011.2", "0.015"], ["84011.4", "0.001333"], ["84012", "0.000333"], ["84012.1", "0.000333"]], "u": 128069, "seq": 67571131068}, "cts": 1742576912309, "record_time": 1742576912.507688, "EXCHANGE": "BYBIT"}
{"topic": "orderbook.200.BTCUSDT", "ts": 1742576912520, "type": "delta", "data": {"s": "BTCUSDT", "b": [["83947.2", "0.188754"], ["83923.7", "0.130975"], ["83915", "0.303763"], ["83912.7", "0.013"], ["83912.5", "0"], ["83909.5", "0.05"], ["83909.3", "0"], ["83892.8", "0.361819"], ["83892.7", "0"], ["83875.4", "0.001466"]], "a": [["83947.3", "0.346889"], ["83949.3", "0.023278"], ["83949.4", "0.071506"], ["83950.2", "0"], ["83962.5", "0.221273"]], "u": 128070, "seq": 67571131113}, "cts": 1742576912515, "record_time": 1742576912.707283, "EXCHANGE": "BYBIT"}
{"topic": "orderbook.200.BTCUSDT", "ts": 1742576912719, "type": "delta", "data": {"s": "BTCUSDT", "b": [["83912.7", "0"], ["83912.5", "0.01288"], ["83909.5", "0"], ["83909.3", "0.049544"], ["83892.9", "0.35757"], ["83892.8", "0.004248"], ["83875.4", "0"]], "a": [], "u": 128071, "seq": 67571131158}, "cts": 1742576912708, "record_time": 1742576912.907215, "EXCHANGE": "BYBIT"}
{"topic": "orderbook.200.BTCUSDT", "ts": 1742576912919, "type": "delta", "data": {"s": "BTCUSDT", "b": [["83914.9", "0.001333"], ["83914.8", "0"], ["83914.7", "0.03963"], ["83914.6", "0.03963"], ["83912.6", "0.035555"], ["83912.5", "0"], ["83912.4", "0.01288"], ["83912.3", "0.014346"], ["83909.4", "0"], ["83909.3", "0"], ["83909.2", "0.049544"], ["83909.1", "0.228229"], ["83893", "0.357571"], ["83892.9", "0"], ["83892.1", "10.692674"]], "a": [["83976.2", "0.089866"], ["83986.8", "0"], ["83986.9", "0.000333"], ["83987.1", "0.04"], ["83987.2", "0.04"], ["84012.1", "0"]], "u": 128072, "seq": 67571131192}, "cts": 1742576912912, "record_time": 1742576913.107761, "EXCHANGE": "BYBIT"}
{"topic": "orderbook.200.BTCUSDT", "ts": 1742576913119, "type": "delta", "data": {"s": "BTCUSDT", "b": [["83943.7", "0.108748"], ["83932.1", "0.077629"], ["83930.3", "0.04"], ["83928.9", "0.056295"], ["83925.6", "0.114326"], ["83921.9", "0.058884"], ["83914.9", "0.112278"], ["83912.6", "0.048555"], ["83912.5", "0.01288"], ["83912.4", "0"], ["83912.3", "0.001466"], ["83909.4", "0.05"], ["83909.3", "0.049544"], ["83909.2", "0"], ["83909.1", "0.178684"], ["83906.1", "0.065861"], ["83894.9", "0.357566"], ["83893", "0"], ["83876.2", "0"], ["83876", "0"], ["83875.9", "0"], ["83875.8", "0"]], "a": [["83947.3", "0.340778"], ["83949.2", "0.006291"], ["83949.4", "0"], ["83952.3", "0.071503"], ["83956.7", "0"], ["83956.8", "0.001333"], ["83961.4", "0.071495"], ["83963.9", "0.055242"], ["83970.9", "0.430401"], ["83976.1", "0.084667"], ["83977.8", "0.001333"], ["83977.9", "0.240703"], ["83993.4", "0"], ["83994", "0.357564"], ["84011.4", "0"], ["84012", "0"]], "u": 128073, "seq": 67571131248}, "cts": 1742576913117, "record_time": 1742576913.307076, "EXCHANGE": "BYBIT"}
{"topic": "orderbook.200.BTCUSDT", "ts": 1742576913320, "type": "delta", "data": {"s": "BTCUSDT", "b": [["83947.2", "0.437241"], ["83943.8", "0.054507"], ["83928.9", "0"], ["83925.3", "0.009329"], ["83921.9", "0"], ["83920", "0.178744"], ["83915", "0.125079"], ["83914.9", "0.001333"], ["83914.8", "0.04"], ["83914.6", "0"], ["83912.6", "0.035555"], ["83912.4", "0.01288"], ["83909.4", "0"], ["83909.2", "0.049544"], ["83909.1", "0"], ["83876.2", "1.786836"]], "a": [["83947.3", "0.164853"], ["83949.2", "0.000333"], ["83949.3", "0.001826"], ["83950.7", "0.005958"], ["83952", "0.16755"], ["83952.3", "0"], ["83957.1", "0.071499"], ["83961.4", "0"], ["83962.8", "0"], ["83963.9", "0"], ["83964.7", "0"], ["83965.3", "0.178684"], ["83970.9", "0.253494"], ["83977.9", "0.125089"], ["83986.9", "0.040333"], ["83987", "0.04"], ["83987.1", "0"], ["83987.2", "0"], ["83994", "0"], ["83996.4", "0.35756"], ["84011.4", "0.001333"], ["84012", "0.000333"], ["84012.1", "0.000333"]], "u": 128074, "seq": 67571131358}, "cts": 1742576913317, "record_time": 1742576913.525231, "EXCHANGE": "BYBIT"}
{"topic": "orderbook.200.BTCUSDT", "ts": 1742576913520, "type": "delta", "data": {"s": "BTCUSDT", "b": [["83947.2", "0.418046"], ["83940.5", "0.0015"], ["83939.8", "0.011918"], ["83933.5", "0.001"], ["83927.4", "0.178726"], ["83924.5", "0.178684"], ["83924.1", "0.178733"], ["83922", "0"], ["83914.9", "0.041333"], ["83914.8", "0.03963"], ["83914.7", "0"], ["83912.6", "0.048555"], ["83912.4", "0"], ["83909.4", "0.05"], ["83909.2", "0"], ["83903.2", "0.1922"], ["83900.8", "0.357538"], ["83900.6", "0.024891"], ["83900.4", "0"], ["83899.7", "0.024942"], ["83894.9", "10.683449"], ["83892.1", "0.009225"], ["83876.9", "0"], ["83876.5", "0"], ["83876.3", "0"], ["83876.2", "0"]], "a": [["83950.7", "0"], ["83951.2", "0.071504"], ["83952", "0.096047"], ["83952.1", "0.063268"], ["83953.1", "0.000522"], ["83957.3", "0.046762"], ["83958.3", "0.137215"], ["83959", "0.049225"], ["83959.3", "0"], ["83960.1", "0.019803"], ["83961", "0.001333"], ["83962.3", "0.000524"], ["83962.6", "0"], ["83967.3", "0.178684"], ["83970.5", "0.0001"], ["83970.9", "0.253394"], ["83972", "0.178864"], ["83986.8", "0.04"], ["83987", "0"], ["83996.4", "0"], ["83997.4", "0.193831"], ["83999.2", "0.0016"], ["83999.6", "0"], ["84002.2", "0.357536"]], "u": 128075, "seq": 67571131526}, "cts": 1742576913514, "record_time": 1742576913.708304, "EXCHANGE": "BYBIT"}
{"topic": "orderbook.200.BTCUSDT", "ts": 1742576913719, "type": "delta", "data": {"s": "BTCUSDT", "b": [["83960.8", "0.239416"], ["83959", "0.000298"], ["83958.9", "0.3422"], ["83957.3", "0.089099"], ["83956.9", "0.031362"], ["83956.8", "0.001333"], ["83955.7", "0.004395"], ["83955.6", "0.023405"], ["83951.2", "0.089099"], ["83949.6", "0.00009"], ["83949.3", "0.001999"], ["83948.5", "0.02"], ["83947.3", "0.13983"], ["83947.2", "0.416283"], ["83945", "0.000333"], ["83944.6", "0.001466"], ["83944.3", "0.001333"], ["83944.1", "0.023824"], ["83944", "0.042077"], ["83943.9", "0.059399"], ["83943.8", "0.000522"], ["83943.7", "0.003"], ["83943.1", "0.004395"], ["83943", "0"], ["83941.2", "0.00009"], ["83940.7", "0"], ["83939.8", "0"], ["83938.9", "0.05653"], ["83938.8", "0"], ["83938", "0.058355"], ["83936.5", "0.006794"], ["83936.2", "0"], ["83935.5", "0.059399"], ["83935.4", "0.001466"], ["83935.1", "0.127251"], ["83933.8", "0"], ["83933.5", "0.025891"], ["83932.6", "0.005955"], ["83932.4", "0.003908"], ["83932.1", "0.258093"], ["83931.7", "0.005113"], ["83931.5", "0"], ["83930.9", "0.089099"], ["83928.5", "0.19321"], ["83927.4", "0"], ["83926.9", "0"], ["83925.5", "0.024942"], ["83925.3", "0"], ["83924.6", "0.118835"], ["83924.5", "0"], ["83924.1", "0"], ["83923.7", "0"], ["83920", "0.00006"], ["83917.5", "0"], ["83917", "0.217961"], ["83915", "0"], ["83914.9", "0.001333"], ["83914.8", "0"], ["83913.3", "0.035744"], ["83912.9", "0.04"], ["83912.8", "0.039632"], ["83912.6", "0.035555"], ["83912.5", "0"], ["83912.2", "0"], ["83911.2", "0.024918"], ["83910.5", "0.012881"], ["83910.3", "0"], ["83909.4", "0"], ["83909.3", "0"], ["83909.2", "0.023824"], ["83908.8", "0"], ["83908.6", "0"], ["83907.5", "0.023824"], ["83907.4", "0.05"], ["83907.3", "0.049547"], ["83906.2", "0.023824"], ["83903.4", "0.142659"], ["83902.8", "0"], ["83902.6", "0.005955"], ["83900.8", "0"], ["83900.6", "0"], ["83899.7", "0"], ["83897.9", "0.357543"], ["83897.7", "10.802804"], ["83894.9", "0"], ["83894", "0"], ["83892.3", "0"], ["83892.1", "0"], ["83889.3", "0.001466"], ["83889.1", "0"], ["83879", "0"], ["83877.9", "0"], ["83877.8", "0"], ["83877.2", "0"], ["83877.1", "0"], ["83877", "0"]], "a": [["83947.3", "0"], ["83948.4", "0"], ["83948.5", "0"], ["83949.2", "0"], ["83949.3", "0"], ["83950.1", "0"], ["83950.8", "0"], ["83951.2", "0"], ["83951.5", "0"], ["83951.9", "0"], ["83952", "0"], ["83952.1", "0"], ["83952.2", "0"], ["83952.4", "0"], ["83952.6", "0"], ["83953", "0"], ["83953.1", "0"], ["83953.3", "0"], ["83953.4", "0"], ["83953.8", "0"], ["83953.9", "0"], ["83954", "0"], ["83954.2", "0"], ["83954.3", "0"], ["83954.6", "0"], ["83955.3", "0"], ["83955.5", "0"], ["83955.7", "0"], ["83955.9", "0"], ["83956", "0"], ["83956.8", "0"], ["83957", "0"], ["83957.1", "0"], ["83957.2", "0"], ["83957.3", "0"], ["83957.6", "0"], ["83957.7", "0"], ["83957.8", "0"], ["83958", "0"], ["83958.3", "0"], ["83958.5", "0"], ["83958.9", "0"], ["83959", "0"], ["83959.1", "0"], ["83959.7", "0"], ["83959.8", "0"], ["83959.9", "0"], ["83960.1", "0"], ["83960.6", "0"], ["83960.7", "0"], ["83960.9", "0.003821"], ["83961", "0"], ["83961.2", "0"], ["83961.8", "0"], ["83962.3", "0"], ["83962.5", "0"], ["83963.1", "0.081054"], ["83963.6", "0"], ["83963.7", "0.024421"], ["83963.8", "0"], ["83964.3", "0"], ["83964.8", "0.001194"], ["83965.3", "0"], ["83965.8", "0"], ["83966.1", "0.059553"], ["83967.2", "0"], ["83967.3", "0"], ["83967.4", "0.01"], ["83967.8", "0"], ["83968.3", "0.004262"], ["83968.4", "0.0018"], ["83968.5", "0.002735"], ["83970.9", "0"], ["83971", "0"], ["83971.5", "0.181"], ["83972", "0"], ["83972.2", "0"], ["83972.4", "0"], ["83973.2", "0"], ["83974", "0"], ["83976.1", "0"], ["83976.2", "0.000524"], ["83977", "0.001466"], ["83977.8", "0.007288"], ["83977.9", "0"], ["83978.2", "0"], ["83978.6", "0"], ["83978.8", "0.092945"], ["83979.4", "0"], ["83979.9", "0.171"], ["83980.4", "0"], ["83980.6", "0"], ["83980.7", "0"], ["83980.8", "0.000524"], ["83981", "0"], ["83981.4", "0.005956"], ["83982.4", "0"], ["83984.5", "0"], ["83984.7", "0"], ["83985.1", "0.051909"], ["83986", "0"], ["83986.8", "0"], ["83986.9", "0.000333"], ["83987.6", "0.005955"], ["83987.9", "0"], ["83988.3", "0.171"], ["83988.6", "0"], ["83988.8", "0.178324"], ["83989", "0"], ["83989.2", "0"], ["83989.6", "0.04132"], ["83990.3", "0.005955"], ["83991.4", "0.355429"], ["83991.7", "0.08608"], ["83992.6", "0"], ["83992.9", "0.011916"], ["83993.5", "0.068445"], ["83994.1", "0.024644"], ["83994.2", "0"], ["83995.3", "0.006288"], ["83996.4", "0.02382"], ["83996.5", "0"], ["83996.9", "0.118835"], ["83997", "0"], ["83997.2", "0.00009"], ["83997.4", "0.171"], ["83998.9", "0.023824"], ["83999.1", "0.02382"], ["84002.1", "0.059399"], ["84002.2", "0"], ["84002.5", "0"], ["84002.8", "0.009225"], ["84002.9", "0.118835"], ["84003", "0.025153"], ["84004.3", "0.04"], ["84004.4", "0.04"], ["84004.9", "0"], ["84005.5", "0"], ["84006.6", "0"], ["84008", "0"], ["84010", "0"], ["84010.9", "0.118835"], ["84011", "0"], ["84012", "0.059732"], ["84013.1", "0.000524"], ["84013.4", "0.656573"], ["84013.9", "0.001466"], ["84014", "0.00018"], ["84014.4", "0.12"], ["84014.5", "0.004156"], ["84015.3", "1.028385"], ["84015.5", "0.003894"], ["84015.6", "0.008006"], ["84015.7", "0.05942"], ["84016.3", "0.059888"], ["84016.6", "0.027746"], ["84016.7", "0.118835"], ["84017.7", "0.000524"], ["84018.4", "0.005955"], ["84018.5", "0.001466"], ["84018.7", "0.004156"], ["84019.8", "0.004483"], ["84020.2", "0.12"], ["84020.5", "0.000333"], ["84021.3", "0.12"], ["84022.4", "0.000614"], ["84022.9", "0.004156"], ["84023.1", "0.059399"], ["84023.2", "0.001466"], ["84023.7", "0.002735"], ["84024", "0.001333"], ["84024.6", "0.0025"], ["84024.7", "0.000333"], ["84025.3", "0.0005"], ["84026.8", "0.118835"], ["84026.9", "0.000145"], ["84027", "0.000524"], ["84027.1", "0.004156"], ["84027.6", "0.051355"], ["84027.8", "0.001466"], ["84028.2", "0.041333"], ["84028.7", "0.00595"], ["84029", "0.000333"], ["84030", "0.029192"], ["84030.8", "0.04009"], ["84031.3", "0.004156"], ["84031.5", "0.059399"], ["84031.6", "0.000524"], ["84032.4", "0.002799"], ["84033.2", "0.000333"], ["84035.5", "0.004156"], ["84036.2", "0.000524"], ["84036.6", "0.001333"], ["84036.9", "0.118835"], ["84037", "0.001466"], ["84037.4", "0.000333"], ["84037.6", "0.021638"], ["84037.7", "0.00036"], ["84039.2", "0.00009"], ["84039.7", "0.004156"], ["84040.6", "0.246684"], ["84040.8", "0.001333"], ["84040.9", "0.000524"], ["84041.6", "0.000333"], ["84041.7", "0.001466"], ["84043.9", "0.004156"], ["84044.4", "0.04"], ["84045", "0.041333"], ["84045.5", "0.000524"], ["84045.8", "0.000333"], ["84046.3", "0.001466"], ["84047", "0.118835"], ["84047.6", "0.00009"], ["84048.2", "0.08"], ["84048.3", "0.059399"], ["84048.4", "0.04"], ["84048.9", "1.284967"], ["84049.2", "0.001333"], ["84049.4", "0.006"], ["84050.1", "0.000524"], ["84050.9", "0.001466"], ["84051.2", "0.011864"]], "u": 128076, "seq": 67571133234}, "cts": 1742576913717, "record_time": 1742576913.908935, "EXCHANGE": "BYBIT"}
{"topic": "orderbook.200.BTCUSDT", "ts": 1742576913919, "type": "delta", "data": {"s": "BTCUSDT", "b": [["83963", "0.392648"], ["83960.8", "0"], ["83960", "0.00006"], ["83959.5", "0.005851"], ["83959", "0"], ["83958.9", "0.0002"], ["83957.3", "0"], ["83957", "0.044116"], ["83956.9", "0.00145"], ["83955.5", "0.068805"], ["83954.7", "0.01562"], ["83953.6", "0.03314"], ["83952.3", "0.035109"], ["83951.4", "0.071504"], ["83951.2", "0"], ["83947.3", "0.073585"], ["83947.2", "0.237555"], ["83946.4", "0.048"], ["83945.4", "0.044"], ["83945.3", "0.00378"], ["83945.1", "0.034194"], ["83944.6", "0.069323"], ["83944.4", "0.154451"], ["83944.3", "0.5054"], ["83944.1", "0"], ["83944", "0"], ["83943.9", "0"], ["83941.3", "0.044"], ["83941", "0.5837"], ["83940.4", "0.048"], ["83940.2", "0"], ["83939.5", "0.04"], ["83938.9", "0.00439"], ["83938.7", "0.044"], ["83938", "0"], ["83937.5", "0.044"], ["83936.5", "0"], ["83936", "0.009225"], ["83935.4", "0.120566"], ["83935.1", "0.093052"], ["83934.3", "0.17865"], ["83933.5", "0.001"], ["83933.4", "0"], ["83932.1", "0.077629"], ["83931.9", "0.044358"], ["83931.7", "0.001333"], ["83930.1", "0.17865"], ["83930", "0.018582"], ["83928.9", "0.355693"], ["83928.7", "0"], ["83928.5", "0.103787"], ["83928.4", "0"], ["83927.7", "0.02382"], ["83927", "0"], ["83926.9", "0.026352"], ["83925.5", "0"], ["83924.6", "0"], ["83920.9", "0.013824"], ["83918.9", "0"], ["83916.9", "0.026408"], ["83916.8", "0"], ["83916.4", "0"], ["83915.5", "0"], ["83915.1", "0"], ["83914.6", "0.132801"], ["83914.2", "0.357497"], ["83913.8", "0.004265"], ["83912.1", "0"], ["83911.8", "3.363345"], ["83911.4", "0.024153"], ["83910.1", "0.059569"], ["83905.4", "0.004263"], ["83904.8", "3.893012"], ["83903.7", "0"], ["83903.4", "0.023824"], ["83903.2", "0.059399"], ["83897.9", "0"], ["83897.7", "0.00052"], ["83895.3", "1.423369"], ["83892.6", "0"], ["83892", "0"], ["83891.1", "0"], ["83889.3", "0.126521"], ["83886.8", "0"], ["83885.9", "0.086847"], ["83883.8", "0.551067"], ["83880.7", "0"], ["83878.3", "0"]], "a": [["83960.9", "0"], ["83963.1", "0.216801"], ["83963.7", "0.0006"], ["83964.8", "0"], ["83965.9", "0.001741"], ["83966.1", "0"], ["83966.6", "0.00606"], ["83968", "0.037237"], ["83968.4", "0.007757"], ["83968.6", "0.04"], ["83968.9", "0.04"], ["83969.4", "0.013247"], ["83969.6", "0.024242"], ["83970.7", "0.059399"], ["83970.8", "0.037338"], ["83971.4", "0.057785"], ["83971.9", "0.04"], ["83972.4", "0.04"], ["83973.6", "0.001333"], ["83973.7", "0.04"], ["83973.8", "0.036361"], ["83974", "0.04"], ["83974.1", "0.118835"], ["83974.3", "0.007681"], ["83974.7", "0"], ["83975.6", "0.05"], ["83976.9", "0.04"], ["83977.8", "0.001333"], ["83978.8", "0"], ["83979.6", "0.149988"], ["83979.7", "0.178234"], ["83979.9", "0.174894"], ["83980.4", "0.17874"], ["83980.5", "0.1191"], ["83981.4", "0"], ["83982.8", "0"], ["83983.5", "0.02382"], ["83984.4", "0.01871"], ["83984.6", "0.17865"], ["83985", "0"], ["83985.1", "0.123099"], ["83985.6", "0.03574"], ["83985.7", "0.10594"], ["83985.8", "0"], ["83987.2", "0.009186"], ["83987.6", "0"], ["83988.7", "0.059399"], ["83988.8", "0.00009"], ["83988.9", "0"], ["83990.4", "0.007288"], ["83991.4", "0"], ["83991.7", "0"], ["83991.8", "0.118835"], ["83993.5", "0.044624"], ["83994.1", "0"], ["83995.7", "0.02382"], ["83998.9", "0"], ["84001.7", "0.02382"], ["84002.8", "0"], ["84004.1", "0"], ["84004.3", "0"], ["84004.4", "0"], ["84004.5", "0.592238"], ["84006.2", "0.357497"], ["84006.7", "0.566122"], ["84006.8", "0.04"], ["84013.4", "0"], ["84014.2", "0.171"], ["84014.4", "0"], ["84015.3", "0"], ["84015.5", "0"], ["84016.3", "0.000333"], ["84016.6", "0"], ["84020.2", "0"], ["84021.3", "0"], ["84022.6", "0.171"], ["84025.2", "0.013091"], ["84027.6", "0"], ["84031", "0.171"], ["84036.1", "0.125055"], ["84039.4", "0.171"], ["84042.6", "0.05"], ["84043.5", "0.0003"], ["84044.2", "0.05"], ["84045.2", "0.05"], ["84045.5", "0"], ["84045.8", "0"], ["84046.3", "0"], ["84047", "0"], ["84047.6", "0"], ["84048.2", "0"], ["84048.3", "0"], ["84048.4", "0"], ["84048.9", "0"], ["84049.2", "0"], ["84049.4", "0"], ["84050.1", "0"], ["84050.9", "0"], ["84051.2", "0"]], "u": 128077, "seq": 67571134048}, "cts": 1742576913917, "record_time": 1742576914.107815, "EXCHANGE": "BYBIT"}
{"topic": "orderbook.200.BTCUSDT", "ts": 1742576914120, "type": "delta", "data": {"s": "BTCUSDT", "b": [["83963", "0.464142"], ["83957.6", "0.000333"], ["83957", "0.083487"], ["83956.9", "0.001117"], ["83954.7", "0.06776"], ["83954.1", "0.071501"], ["83953.8", "0.058355"], ["83953.4", "0.000333"], ["83952.1", "0.006813"], ["83951.8", "0.001999"], ["83949.2", "0.000333"], ["83947.9", "0.04"], ["83947.3", "0.106269"], ["83947.2", "0.236489"], ["83946.2", "0.056"], ["83944.4", "0.16378"], ["83941.2", "0.04809"], ["83939.5", "0"], ["83939", "0.003576"], ["83935.1", "0.271702"], ["83933.6", "0"], ["83931.9", "0.000358"], ["83930.3", "0"], ["83929.8", "0"], ["83926.9", "0"], ["83926.8", "0"], ["83917.1", "0.357478"], ["83915.6", "0.026685"], ["83915", "0.125055"], ["83914.2", "0"], ["83905.9", "0.005"], ["83904.4", "0.17865"], ["83903.3", "0"], ["83894", "0.125055"], ["83890.4", "0.121027"], ["83886.3", "0.550512"], ["83883.8", "0.00052"], ["83883.3", "0.625275"], ["83882.4", "0"], ["83882", "0"], ["83881.3", "0"], ["83880.8", "0"], ["83880.2", "0"], ["83880", "0"], ["83879.2", "0"], ["83878.8", "0"], ["83878.7", "0"]], "a": [["83963.1", "0.220372"], ["83964.8", "0.0003"], ["83965.9", "0"], ["83968", "0.069012"], ["83968.4", "0.0018"], ["83968.5", "0.127527"], ["83971.4", "0.14737"], ["83972", "0.04"], ["83972.6", "0.024074"], ["83974.4", "0.018503"], ["83975.6", "0"], ["83976.8", "0.02494"], ["83976.9", "0.08"], ["83979.6", "0.214011"], ["83980.4", "0.35739"], ["83985.6", "0"], ["83985.7", "0"], ["83985.8", "0.071475"], ["83988.4", "0"], ["83988.5", "0.071472"], ["83992.2", "0.114324"], ["83993.7", "0.004569"], ["83997.9", "0.020368"], ["83998.9", "0.125055"], ["84006.2", "0"], ["84006.4", "0.013775"], ["84014.1", "0.357471"], ["84019.9", "0.125055"], ["84021.9", "0.051349"], ["84027.7", "0.17865"], ["84029", "0.028316"], ["84033", "2.612042"], ["84036", "0.011993"], ["84039.3", "0.011993"], ["84039.7", "0"], ["84040.6", "0"], ["84040.8", "0"], ["84040.9", "0"], ["84041.6", "0"], ["84041.7", "0"], ["84042.6", "0"], ["84043.5", "0"], ["84043.9", "0"], ["84044.2", "0"], ["84044.4", "0"], ["84045", "0"], ["84045.2", "0"]], "u": 128078, "seq": 67571134302}, "cts": 1742576914111, "record_time": 1742576914.308775, "EXCHANGE": "BYBIT"}
{"topic": "orderbook.200.BTCUSDT", "ts": 1742576914319, "type": "delta", "data": {"s": "BTCUSDT", "b": [["83963", "0.293142"], ["83957.7", "0.000522"], ["83956.9", "0.000595"], ["83953.9", "0.001466"], ["83953.1", "0.000522"], ["83952.6", "0.001333"], ["83951.5", "0.004395"], ["83949.3", "0.003465"], ["83948.5", "0.020522"], ["83948.4", "0.001333"], ["83947.3", "0.110664"], ["83947.2", "0.221057"], ["83944.8", "0.044"], ["83944.1", "0.114324"], ["83943.1", "0.048395"], ["83938.7", "0"], ["83937.5", "0"], ["83932.4", "0.008538"], ["83928.5", "0.022936"], ["83926.7", "0"], ["83925.6", "0"], ["83923.1", "0.075161"], ["83921.8", "0.05"], ["83921.7", "0.049548"], ["83917.4", "0.132816"], ["83914.6", "0"], ["83914.2", "10.607953"], ["83913.3", "0.125069"], ["83911.3", "0.048"], ["83907.4", "0"], ["83907.3", "0"], ["83892.3", "0.089325"], ["83885.5", "0"], ["83885.4", "0"], ["83884.6", "0"], ["83884.4", "0"], ["83883.8", "0"], ["83883.7", "0"], ["83883.3", "0"], ["83882.8", "0"]], "a": [["83967.3", "0.005957"], ["83968.5", "0.12157"], ["83972.2", "0.071486"], ["83973.8", "0.036514"], ["83975.4", "0.006731"], ["83989.3", "0.040002"], ["83993.5", "0.004624"], ["83997.2", "0.089415"], ["83999.3", "0.051873"], ["84002.2", "0.615582"], ["84010.4", "0.04"], ["84012.6", "0.023266"], ["84014.1", "0"], ["84015.6", "0.365474"], ["84018.2", "0.089325"], ["84019.1", "2.612042"], ["84021.9", "0"], ["84033", "0"], ["84037.6", "0"], ["84037.7", "0"], ["84039.2", "0"], ["84039.3", "0"], ["84039.4", "0"]], "u": 128079, "seq": 67571134507}, "cts": 1742576914316, "record_time": 1742576914.508256, "EXCHANGE": "BYBIT"}
{"topic": "orderbook.200.BTCUSDT", "ts": 1742576914520, "type": "delta", "data": {"s": "BTCUSDT", "b": [["83963", "0.47187"], ["83954.6", "0.02"], ["83952.2", "0.001999"], ["83948.5", "0.000522"], ["83947.2", "0.223214"], ["83944.5", "0.178689"], ["83944.4", "0.273179"], ["83942.8", "0.178693"], ["83939.6", "0.17865"], ["83917.5", "0.35747"], ["83917.1", "0"], ["83911.2", "0.039918"], ["83904.4", "0"], ["83889.3", "0.001466"], ["83886.7", "0.550505"], ["83886.3", "0"], ["83886.2", "0"], ["83886.1", "0"], ["83885.9", "0"], ["83885.8", "0"]], "a": [["83963.1", "0.200337"], ["83967.3", "0"], ["83967.4", "0"], ["83968.8", "0.005957"], ["83970.7", "0"], ["83971.5", "0.191"], ["83972.2", "0"], ["83973.8", "0.036361"], ["83975.4", "0"], ["83981.4", "0.178611"], ["83984.9", "0.17865"], ["83989.3", "0.004264"], ["83999.3", "0.000524"], ["84002.1", "0.110748"], ["84015.5", "0.357469"], ["84015.6", "0.008006"], ["84019.1", "0"], ["84021.9", "2.612046"], ["84027.7", "0"], ["84036.1", "0"], ["84037.6", "0.021638"], ["84037.7", "0.00036"], ["84039.2", "0.00009"]], "u": 128080, "seq": 67571134635}, "cts": 1742576914515, "record_time": 1742576914.70768, "EXCHANGE": "BYBIT"}
{"topic": "orderbook.200.BTCUSDT", "ts": 1742576914719, "type": "delta", "data": {"s": "BTCUSDT", "b": [["83953.6", "0.037229"], ["83941.2", "0.226787"], ["83902.6", "0.184734"], ["83889.4", "0.574329"], ["83886.7", "0"], ["83886.2", "0.000333"]], "a": [["83963.1", "0.198596"], ["83970.5", "0.001881"], ["83971.3", "0.059399"], ["83972.6", "0"], ["83973.6", "0.072818"], ["83976.1", "0.026375"], ["83976.8", "0"], ["83979.6", "0.313186"], ["84015.4", "0.357468"], ["84015.5", "0"]], "u": 128081, "seq": 67571134714}, "cts": 1742576914707, "record_time": 1742576914.90667, "EXCHANGE": "BYBIT"}
{"topic": "orderbook.200.BTCUSDT", "ts": 1742576914919, "type": "delta", "data": {"s": "BTCUSDT", "b": [["83963", "0.64287"], ["83958.5", "0.001466"], ["83953.6", "0.068324"], ["83931.2", "0.125055"], ["83923.4", "0.096517"], ["83923.1", "0.432612"], ["83921.8", "0"], ["83921.7", "0"], ["83921.2", "0.05"], ["83921.1", "0.049549"], ["83919.8", "10.608286"], ["83917.5", "0"], ["83916", "0.000208"], ["83914.2", "0"], ["83892.8", "0.01611"], ["83889.8", "0.562337"], ["83889.4", "0.023828"], ["83886.6", "0"], ["83886.2", "0"]], "a": [["83963.1", "0.003216"], ["83968.8", "0"], ["83972.3", "0.007423"], ["83973.6", "0.001333"], ["83974.3", "0.000333"], ["83974.6", "0.026055"], ["83976.1", "0.062716"], ["83984.5", "0.169415"], ["83985.8", "0"], ["83991.1", "0.071803"], ["84002.1", "0.059399"], ["84003.1", "0"], ["84004.9", "0.051349"], ["84006", "0.000118"], ["84006.3", "0"], ["84015.4", "0"], ["84019.8", "0.361934"], ["84021.9", "0"], ["84024.7", "2.612379"], ["84039.3", "0.011993"], ["84039.7", "0.004156"], ["84040.6", "0.246684"]], "u": 128082, "seq": 67571134850}, "cts": 1742576914918, "record_time": 1742576915.107558, "EXCHANGE": "BYBIT"}
{"topic": "orderbook.200.BTCUSDT", "ts": 1742576915119, "type": "delta", "data": {"s": "BTCUSDT", "b": [["83963", "0.47187"], ["83953.6", "0.037229"], ["83926.9", "0.04"], ["83926.8", "0.039634"], ["83924.5", "0.013"], ["83924.4", "0.012971"], ["83923.1", "0.075161"], ["83921.3", "0.357457"], ["83912.9", "0"], ["83912.8", "0"], ["83911.2", "0.026918"], ["83910.5", "0"], ["83910.3", "0.125055"], ["83889.9", "0.550478"], ["83889.8", "0.011862"], ["83889.5", "0"], ["83888.5", "0"], ["83888.1", "0"]], "a": [["83971.8", "0.005957"], ["83972.3", "0.001466"], ["83974.6", "0.0025"], ["83975.7", "0.04782"], ["83975.8", "0.071483"], ["83976.1", "0"], ["83989.2", "0.027516"], ["83994.2", "0.125055"], ["84005.1", "0.009225"], ["84005.6", "0.04009"], ["84005.7", "0.04"], ["84006.7", "0.526122"], ["84006.8", "0"], ["84008.7", "0.04"], ["84015.1", "0.125055"], ["84018.1", "0.357456"], ["84019.8", "0.004483"], ["84037", "0"], ["84037.4", "0"], ["84037.6", "0"], ["84037.7", "0"], ["84039.2", "0"], ["84039.3", "0"], ["84039.7", "0"], ["84040.6", "0"]], "u": 128083, "seq": 67571134946}, "cts": 1742576915113, "record_time": 1742576915.306805, "EXCHANGE": "BYBIT"}
{"topic": "orderbook.200.BTCUSDT", "ts": 1742576915320, "type": "delta", "data": {"s": "BTCUSDT", "b": [["83941.1", "0.247239"], ["83939", "0"]], "a": [["83974.6", "0.073984"], ["83975.7", "0.026375"], ["83975.8", "0"], ["83976.5", "0.000153"], ["83985.9", "0.071474"], ["83991.1", "0.000333"], ["84018.1", "0"], ["84019.8", "0.361939"], ["84021.9", "2.612046"], ["84024.7", "0.000333"], ["84036.9", "0"]], "u": 128084, "seq": 67571134969}, "cts": 1742576915315, "record_time": 1742576915.507763, "EXCHANGE": "BYBIT"}
{"topic": "orderbook.200.BTCUSDT", "ts": 1742576915519, "type": "delta", "data": {"s": "BTCUSDT", "b": [["83963", "0.472378"], ["83956.5", "0.0007"], ["83948.4", "0.004908"], ["83940.5", "0"], ["83927.8", "0.0015"], ["83921.3", "0.357455"], ["83911.8", "3.361745"], ["83888.6", "0"]], "a": [["83963.1", "0.174216"], ["83970.7", "0.005957"], ["83971.8", "0"], ["83973.2", "0.071485"], ["83974.6", "0.0025"], ["83976.5", "0"], ["84004.4", "0.448886"], ["84021.9", "0"], ["84024.7", "2.612379"]], "u": 128085, "seq": 67571135046}, "cts": 1742576915515, "record_time": 1742576915.706918, "EXCHANGE": "BYBIT"}
{"topic": "orderbook.200.BTCUSDT", "ts": 1742576915719, "type": "delta", "data": {"s": "BTCUSDT", "b": [["83963", "0.301378"], ["83953.6", "0.068987"], ["83948.4", "0.001333"], ["83944.5", "0"], ["83944.1", "0"], ["83942.8", "0"], ["83941.2", "0.04809"], ["83939.6", "0"], ["83935.1", "0.093052"], ["83934.3", "0"], ["83931.2", "0"], ["83930.1", "0"], ["83926.9", "0"], ["83926.7", "0.039634"], ["83924.5", "0"], ["83924.3", "0.012881"], ["83921.3", "0.05"], ["83921.2", "0.049549"], ["83921.1", "0"], ["83920.4", "0.357458"], ["83919.8", "0.000333"], ["83916.9", "0.001466"], ["83915", "0"], ["83913.3", "0.035744"], ["83911.9", "1.008524"], ["83902.6", "0.005955"], ["83892.1", "10.070936"], ["83889.9", "0.550488"], ["83888.6", "0.004248"], ["83888.5", "0.00052"], ["83888.1", "0.04"], ["83886.6", "0.023828"], ["83886.2", "0.000333"], ["83886.1", "0.04"]], "a": [["83963.1", "0.197505"], ["83966.5", "0.005957"], ["83970.7", "0"], ["83971.2", "0.071487"], ["83972", "0.04009"], ["83973.2", "0"], ["83974.7", "0.023414"], ["83975.4", "0.006667"], ["83975.7", "0.060089"], ["83980.4", "0.00009"], ["83981.4", "0"], ["83983.1", "0.071477"], ["83984.6", "0"], ["83984.9", "0"], ["83988.5", "0"], ["83994.2", "0"], ["83997.2", "0.00009"], ["83998.9", "0"], ["84002.1", "0.110748"], ["84004.9", "0"], ["84005", "0.476163"], ["84018.1", "0.357459"], ["84019.8", "0.004483"], ["84021.9", "2.612046"], ["84024.7", "0.000333"], ["84036.9", "0.118835"]], "u": 128086, "seq": 67571135202}, "cts": 1742576915716, "record_time": 1742576915.907784, "EXCHANGE": "BYBIT"}
{"topic": "orderbook.200.BTCUSDT", "ts": 1742576915919, "type": "delta", "data": {"s": "BTCUSDT", "b": [["83963", "0.281478"], ["83954.1", "0"], ["83953.6", "0.037229"], ["83944.4", "0.16378"], ["83943.9", "0.114321"], ["83935.5", "0"], ["83935.1", "0.17865"], ["83934.3", "0.17865"], ["83930.9", "0"], ["83930.1", "0.17865"], ["83929.1", "0.035738"], ["83929", "0.059399"], ["83924.8", "0.012881"], ["83924.7", "0.012881"], ["83924.4", "0.00009"], ["83924.3", "0"], ["83921.6", "0.051466"], ["83921.5", "0.049549"], ["83921.3", "0"], ["83921.2", "0"], ["83920.4", "0"], ["83917.4", "0"], ["83915.6", "0.000333"], ["83913.3", "0.089325"], ["83911.7", "0.192213"], ["83910.3", "0"], ["83909.4", "0.17865"], ["83906.2", "0.381321"], ["83892.1", "0"], ["83889.9", "0"], ["83889.4", "9.449138"], ["83886.7", "0.550545"], ["83886.1", "0.211"], ["83885.9", "0.086847"]], "a": [["83963.1", "0.412789"], ["83971.2", "0.001"], ["83972.6", "0.000153"], ["83975.7", "0.026375"], ["83979.6", "0.200607"], ["83980.2", "0.071479"], ["83980.4", "0.35739"], ["83984.5", "0"], ["83984.6", "0.17865"], ["83985.9", "0"], ["83997.2", "0.089415"], ["83999.3", "0.051873"], ["84002.1", "0.059399"], ["84004.3", "0.022831"], ["84005", "1.428489"], ["84005.1", "0.187875"], ["84008.3", "0.355357"], ["84008.6", "0.357497"], ["84012.5", "0.021421"], ["84016.4", "2.612046"], ["84018.1", "0"], ["84021.9", "0"], ["84036", "0"], ["84036.2", "0"], ["84036.6", "0"], ["84036.9", "0"]], "u": 128087, "seq": 67571135454}, "cts": 1742576915916, "record_time": 1742576916.107768, "EXCHANGE": "BYBIT"}
{"topic": "orderbook.200.BTCUSDT", "ts": 1742576916120, "type": "delta", "data": {"s": "BTCUSDT", "b": [["83954.1", "0.071501"], ["83927.5", "0.041333"], ["83927.4", "0.039633"], ["83926.8", "0"], ["83926.7", "0"], ["83925.1", "0.013"], ["83925", "0.012881"], ["83924.8", "0"], ["83924.7", "0"], ["83921.8", "0.05"], ["83921.7", "0.049548"], ["83921.6", "0.001466"], ["83921.5", "0"], ["83920.1", "0"], ["83912", "0.357494"], ["83911.7", "0.192214"], ["83911.5", "9.425832"], ["83906.2", "0.023824"], ["83889.4", "0.023828"], ["83889.3", "0.126521"], ["83885.9", "0"]], "a": [["83969.1", "0.071489"], ["83979.6", "0.304165"], ["84003.6", "0.04"], ["84003.7", "0.040333"], ["84005.6", "0.00009"], ["84005.7", "0"], ["84008.6", "0"], ["84010.3", "0.36165"]], "u": 128088, "seq": 67571135573}, "cts": 1742576916091, "record_time": 1742576916.307418, "EXCHANGE": "BYBIT"}
{"topic": "orderbook.200.BTCUSDT", "ts": 1742576916319, "type": "delta", "data": {"s": "BTCUSDT", "b": [["83940.9", "0.178697"], ["83939.6", "0.17865"], ["83939.1", "0.178701"], ["83935.2", "0.160445"], ["83927.5", "0.001333"], ["83927.3", "0.039633"], ["83925.1", "0"], ["83924.9", "0.012881"], ["83921.8", "0"], ["83921.6", "0.051014"], ["83917.4", "0.132815"], ["83915", "0.125055"], ["83914.2", "9.42531"], ["83911.7", "0.059399"], ["83911.5", "0.000522"], ["83909.4", "0"], ["83898.9", "0.178787"], ["83888.6", "0"], ["83888.5", "0"], ["83888.1", "0"], ["83886.7", "0"], ["83886.6", "0"], ["83886.2", "0"], ["83886.1", "0"]], "a": [["83967.6", "0.07149"], ["83969.1", "0"], ["83972.4", "0.040153"], ["83972.6", "0"], ["83975.7", "0.067435"], ["83975.9", "0.147854"], ["83977.6", "0.178619"], ["83979.9", "0.353544"], ["83998.9", "0.125055"], ["84003.6", "0"], ["84003.8", "0.04"], ["84005.1", "0.009225"], ["84033.2", "0"], ["84035.5", "0"]], "u": 128089, "seq": 67571135666}, "cts": 1742576916311, "record_time": 1742576916.507703, "EXCHANGE": "BYBIT"}
{"topic": "orderbook.200.BTCUSDT", "ts": 1742576916520, "type": "delta", "data": {"s": "BTCUSDT", "b": [["83931.2", "0.125055"], ["83914.2", "0"], ["83912", "0"], ["83910.3", "0.125055"], ["83906.2", "0.381317"], ["83906", "9.42531"], ["83889.3", "0"]], "a": [["83975.7", "0.115888"], ["84010.3", "0.004156"], ["84010.8", "0.357493"], ["84032.4", "0"]], "u": 128090, "seq": 67571135758}, "cts": 1742576916515, "record_time": 1742576916.707839, "EXCHANGE": "BYBIT"}
{"topic": "orderbook.200.BTCUSDT", "ts": 1742576916720, "type": "delta", "data": {"s": "BTCUSDT", "b": [["83938.4", "0.178702"], ["83912", "0.357492"], ["83911.5", "9.425832"], ["83906.2", "0.023824"], ["83906", "0"], ["83889.4", "0"]], "a": [["83967.6", "0"], ["83969.4", "0.084735"], ["83972.2", "0.000153"], ["83972.4", "0.04"], ["83974.4", "0"], ["83996.8", "0.189092"], ["84010.8", "0.357492"], ["84026.9", "0"], ["84032.4", "0.002799"]], "u": 128091, "seq": 67571135845}, "cts": 1742576916717, "record_time": 1742576916.907843, "EXCHANGE": "BYBIT"}
{"topic": "orderbook.200.BTCUSDT", "ts": 1742576916920, "type": "delta", "data": {"s": "BTCUSDT", "b": [["83963", "0.27108"]], "a": [["83968.3", "0.075751"], ["83969.4", "0.013247"], ["83971.8", "0.000153"], ["83972.2", "0"], ["84004.3", "0"], ["84033.2", "0.000333"]], "u": 128092, "seq": 67571135939}, "cts": 1742576916915, "record_time": 1742576917.10769, "EXCHANGE": "BYBIT"}
{"topic": "orderbook.200.BTCUSDT", "ts": 1742576917120, "type": "delta", "data": {"s": "BTCUSDT", "b": [["83937.1", "0.17865"], ["83912", "0"], ["83904.9", "0.357493"], ["83889.7", "0"]], "a": [["84010.3", "0.361652"], ["84010.8", "0"], ["84013.1", "0.023355"], ["84035.5", "0.004156"]], "u": 128093, "seq": 67571135990}, "cts": 1742576917076, "record_time": 1742576917.308253, "EXCHANGE": "BYBIT"}
{"topic": "orderbook.200.BTCUSDT", "ts": 1742576917320, "type": "delta", "data": {"s": "BTCUSDT", "b": [["83941.1", "0.429236"], ["83905", "0.361073"], ["83904.9", "0"], ["83889.7", "0.001333"]], "a": [["83963.1", "0.418746"], ["83966.5", "0"], ["83975.5", "0"], ["83979.9", "0.34965"], ["84009.2", "0.004062"], ["84010.3", "0.361651"], ["84036", "0.011993"]], "u": 128094, "seq": 67571136043}, "cts": 1742576917308, "record_time": 1742576917.507379, "EXCHANGE": "BYBIT"}
{"topic": "orderbook.200.BTCUSDT", "ts": 1742576917520, "type": "delta", "data": {"s": "BTCUSDT", "b": [["83947.2", "0.221057"], ["83937.1", "0"], ["83933.5", "0"], ["83932.1", "0.2252"], ["83905.1", "0.357496"], ["83905", "0.003575"], ["83889.4", "0.023828"]], "a": [["83963.1", "0.412789"], ["83966.5", "0.005957"], ["83968.9", "0.043894"], ["83971.6", "0.000677"], ["83971.8", "0"], ["84011.9", "0.04"], ["84036", "0"]], "u": 128095, "seq": 67571136087}, "cts": 1742576917513, "record_time": 1742576917.707874, "EXCHANGE": "BYBIT"}
{"topic": "orderbook.200.BTCUSDT", "ts": 1742576917719, "type": "delta", "data": {"s": "BTCUSDT", "b": [["83912", "0.357491"], ["83905.1", "0"]], "a": [["83971.6", "0.000524"], ["83988.2", "0.095808"], ["83992.2", "0"], ["84010.3", "0.004156"], ["84010.8", "0.357493"], ["84035.5", "0"]], "u": 128096, "seq": 67571136130}, "cts": 1742576917711, "record_time": 1742576917.906861, "EXCHANGE": "BYBIT"}
{"topic": "orderbook.200.BTCUSDT", "ts": 1742576917920, "type": "delta", "data": {"s": "BTCUSDT", "b": [["83949.3", "0.001466"], ["83912", "0"], ["83904.9", "0.357494"]], "a": [["83963.1", "0.415176"], ["83984.6", "0.29296"], ["84010.3", "0.36165"], ["84010.8", "0"], ["84035.5", "0.004156"]], "u": 128097, "seq": 67571136176}, "cts": 1742576917911, "record_time": 1742576918.107284, "EXCHANGE": "BYBIT"}
{"topic": "orderbook.200.BTCUSDT", "ts": 1742576918120, "type": "delta", "data": {"s": "BTCUSDT", "b": [["83963", "0.27028"], ["83951.8", "0"], ["83906.2", "0.381315"], ["83904.9", "0"], ["83889.3", "0.001466"], ["83888.6", "0.004248"]], "a": [["83971.1", "0.000153"], ["84010.3", "0.004156"], ["84011.8", "0.357491"], ["84033.2", "0"], ["84035.5", "0"]], "u": 128098, "seq": 67571136243}, "cts": 1742576918117, "record_time": 1742576918.309347, "EXCHANGE": "BYBIT"}
{"topic": "orderbook.200.BTCUSDT", "ts": 1742576918319, "type": "delta", "data": {"s": "BTCUSDT", "b": [["83906.2", "0.023824"], ["83904.9", "0.357493"], ["83888.6", "0"]], "a": [["84010.3", "0.361649"], ["84011.8", "0"], ["84033.2", "0.000333"]], "u": 128099, "seq": 67571136274}, "cts": 1742576918289, "record_time": 1742576918.507142, "EXCHANGE": "BYBIT"}
{"topic": "orderbook.200.BTCUSDT", "ts": 1742576918519, "type": "delta", "data": {"s": "BTCUSDT", "b": [], "a": [["83974.4", "0.018697"], ["84033.2", "0"]], "u": 128100, "seq": 67571136329}, "cts": 1742576918516, "record_time": 1742576918.707346, "EXCHANGE": "BYBIT"}
{"topic": "orderbook.200.BTCUSDT", "ts": 1742576918719, "type": "delta", "data": {"s": "BTCUSDT", "b": [["83963", "0.274945"], ["83952.2", "0"], ["83944.7", "0.253143"], ["83944.4", "0.009329"], ["83912", "0.35749"], ["83904.9", "0"]], "a": [["83971.1", "0"], ["83971.8", "0.000153"], ["84010.3", "0.004156"], ["84011.8", "0.35749"], ["84032.4", "0"]], "u": 128101, "seq": 67571136410}, "cts": 1742576918715, "record_time": 1742576918.90747, "EXCHANGE": "BYBIT"}
{"topic": "orderbook.200.BTCUSDT", "ts": 1742576918919, "type": "delta", "data": {"s": "BTCUSDT", "b": [["83958.9", "0"], ["83935.4", "0.001466"], ["83927.7", "0"], ["83923.5", "0.134245"], ["83923.1", "0"], ["83912.1", "0.357491"], ["83912", "0"], ["83911.5", "7.563369"], ["83904.9", "0.02382"], ["83888.6", "0.004248"]], "a": [["83971.8", "0"], ["83980.5", "0"], ["83984.5", "0.12867"], ["83999.3", "0.000524"], ["84002.1", "0.110748"], ["84002.3", "0"], ["84011.7", "0.357491"], ["84011.8", "0"], ["84016.4", "0"], ["84019.1", "2.612297"], ["84032.4", "0.002799"], ["84033.2", "0.000333"]], "u": 128102, "seq": 67571136477}, "cts": 1742576918888, "record_time": 1742576919.106928, "EXCHANGE": "BYBIT"}
{"topic": "orderbook.200.BTCUSDT", "ts": 1742576919120, "type": "delta", "data": {"s": "BTCUSDT", "b": [["83927.4", "0"], ["83927.2", "0.039633"], ["83925", "0"], ["83924.8", "0.012881"], ["83921.7", "0"], ["83921.5", "0.049549"], ["83912.1", "0"], ["83904.9", "0.381315"], ["83888.5", "0.00052"]], "a": [["83974.4", "0.018685"], ["83977.6", "0.2501"], ["83983.1", "0"], ["84002.2", "0"], ["84003.7", "0.000333"], ["84003.9", "0.040524"], ["84010.3", "0.361645"], ["84011.7", "0"], ["84016.4", "2.612297"], ["84019.1", "0"], ["84035.5", "0.004156"], ["84036", "0.011993"], ["84036.1", "0.000145"]], "u": 128103, "seq": 67571136542}, "cts": 1742576919116, "record_time": 1742576919.30801, "EXCHANGE": "BYBIT"}
{"topic": "orderbook.200.BTCUSDT", "ts": 1742576919319, "type": "delta", "data": {"s": "BTCUSDT", "b": [["83906.2", "0.381318"], ["83904.9", "0.02382"]], "a": [["83968.3", "0.004262"], ["83969.4", "0.084735"], ["83977.6", "0.178619"], ["83983.1", "0.071477"], ["84010.2", "0.357494"], ["84010.3", "0.004156"], ["84036", "0"], ["84036.1", "0"]], "u": 128104, "seq": 67571136593}, "cts": 1742576919311, "record_time": 1742576919.50666, "EXCHANGE": "BYBIT"}
{"topic": "orderbook.200.BTCUSDT", "ts": 1742576919520, "type": "delta", "data": {"s": "BTCUSDT", "b": [["83963", "0.267217"], ["83953.6", "0.078106"], ["83950.2", "0.034192"], ["83949.7", "0.121575"], ["83945.1", "0"], ["83939.9", "0.165148"], ["83930.8", "0.291236"], ["83925.3", "0.012881"], ["83925.2", "0.012881"], ["83924.9", "0"], ["83924.8", "0"], ["83922", "0.049548"], ["83921.9", "0.049548"], ["83921.6", "0.001466"], ["83921.5", "0"], ["83906.2", "0.381317"], ["83889.3", "0"], ["83888.6", "0"], ["83888.5", "0"]], "a": [["83970.8", "0"], ["83970.9", "0.000153"], ["83974.9", "0.118538"], ["83975.9", "0.18519"], ["83984.7", "0.17913"], ["83993.8", "0.294257"], ["84008.4", "0.004062"], ["84009.2", "0"], ["84010.1", "0.357493"], ["84010.2", "0"], ["84032.4", "0"], ["84033.2", "0"], ["84035.5", "0"]], "u": 128105, "seq": 67571136662}, "cts": 1742576919515, "record_time": 1742576919.733223, "EXCHANGE": "BYBIT"}
{"topic": "orderbook.200.BTCUSDT", "ts": 1742576919720, "type": "delta", "data": {"s": "BTCUSDT", "b": [["83963", "0.267817"], ["83927.7", "0.04"], ["83927.6", "0.039633"], ["83927.3", "0"], ["83927.2", "0"]], "a": [["83999.3", "0.051877"], ["84002.1", "0.059399"], ["84002.6", "0.04"], ["84002.7", "0.08"], ["84003.8", "0"], ["84003.9", "0.000524"], ["84010", "0.357493"], ["84010.1", "0"]], "u": 128106, "seq": 67571136725}, "cts": 1742576919716, "record_time": 1742576919.907525, "EXCHANGE": "BYBIT"}
{"topic": "orderbook.200.BTCUSDT", "ts": 1742576919920, "type": "delta", "data": {"s": "BTCUSDT", "b": [["83963", "0.274961"], ["83953.6", "0.037229"], ["83949.7", "0"], ["83939.9", "0"], ["83930.8", "0.001466"], ["83928.4", "0.04109"], ["83889.3", "0.001466"]], "a": [["83971.2", "0"], ["83974.9", "0"], ["83984.7", "0"], ["83991.7", "0.140344"], ["83993.8", "0"], ["84000.7", "0"], ["84005.5", "0.04"], ["84009.9", "0.357493"], ["84010", "0"], ["84013.7", "2.612297"], ["84016.4", "0"], ["84031.8", "1.028183"], ["84032.4", "0.002799"], ["84033.2", "0.000333"]], "u": 128107, "seq": 67571136797}, "cts": 1742576919905, "record_time": 1742576920.107624, "EXCHANGE": "BYBIT"}
{"topic": "orderbook.200.BTCUSDT", "ts": 1742576920119, "type": "delta", "data": {"s": "BTCUSDT", "b": [["83906.3", "0.357493"], ["83906.2", "0.023824"], ["83889.3", "0"]], "a": [["83964.8", "0"], ["83991.7", "0"], ["84009.8", "0.357493"], ["84009.9", "0"], ["84035.5", "0.004156"], ["84036", "0.011993"]], "u": 128108, "seq": 67571136850}, "cts": 1742576920114, "record_time": 1742576920.307563, "EXCHANGE": "BYBIT"}
{"topic": "orderbook.200.BTCUSDT", "ts": 1742576920320, "type": "delta", "data": {"s": "BTCUSDT", "b": [["83906.4", "0.357491"], ["83906.3", "0"]], "a": [["84000.5", "0"], ["84009.7", "0.357491"], ["84009.8", "0"], ["84036.1", "0.000145"]], "u": 128109, "seq": 67571136917}, "cts": 1742576920306, "record_time": 1742576920.508079, "EXCHANGE": "BYBIT"}
{"topic": "orderbook.200.BTCUSDT", "ts": 1742576920519, "type": "delta", "data": {"s": "BTCUSDT", "b": [["83963", "0.275761"], ["83927.7", "0"], ["83927.5", "0.040966"], ["83925.4", "0.013522"], ["83925.2", "0"], ["83922.1", "0.05"], ["83921.9", "0"], ["83906.5", "0.358824"], ["83906.4", "0"], ["83889.3", "0.001466"], ["83888.6", "0.004248"], ["83888.5", "0.00052"]], "a": [["83963.1", "0.421133"], ["83966.5", "0"], ["83970", "0.000153"], ["83970.9", "0"], ["84002.6", "0"], ["84002.7", "0.04"], ["84002.9", "0.158835"], ["84003", "0.065153"], ["84005.4", "0.04"], ["84009.6", "0.357491"], ["84009.7", "0"], ["84036.2", "0.000524"]], "u": 128110, "seq": 67571136971}, "cts": 1742576920502, "record_time": 1742576920.708206, "EXCHANGE": "BYBIT"}
{"topic": "orderbook.200.BTCUSDT", "ts": 1742576920720, "type": "delta", "data": {"s": "BTCUSDT", "b": [["83963", "0.186061"], ["83927.8", "0.0415"], ["83927.7", "0.039633"], ["83927.6", "0"], ["83927.5", "0.001333"], ["83906.6", "0.357491"], ["83906.5", "0.001333"], ["83888.5", "0"]], "a": [["83963.1", "0.415176"], ["83966.5", "0.005957"], ["83973.1", "0.01871"], ["83984.4", "0"], ["83999.3", "0.000524"], ["84002.1", "0.110752"], ["84002.7", "0.08"], ["84002.8", "0.04"], ["84002.9", "0.118835"], ["84003", "0.025153"], ["84009.5", "0.357493"], ["84009.6", "0"], ["84036.1", "0"], ["84036.2", "0"]], "u": 128111, "seq": 67571137004}, "cts": 1742576920709, "record_time": 1742576920.90756, "EXCHANGE": "BYBIT"}
{"topic": "orderbook.200.BTCUSDT", "ts": 1742576920920, "type": "delta", "data": {"s": "BTCUSDT", "b": [["83963", "0.204059"], ["83944.2", "0.057822"], ["83937.2", "0.054444"], ["83930.2", "0.115803"], ["83927.8", "0.0015"], ["83927.6", "0.039633"], ["83925.4", "0.000522"], ["83925.2", "0.012881"], ["83922.1", "0"], ["83921.9", "0.049548"], ["83917.5", "0.105892"], ["83911.5", "6.218571"], ["83906.6", "0"], ["83906.2", "0.381316"], ["83889.8", "0"], ["83889.7", "0"], ["83889.4", "0"], ["83889.3", "0"], ["83888.6", "0"]], "a": [["83970", "0"], ["83979.2", "0.057777"], ["83986.2", "0.058606"], ["83993.2", "0.123574"], ["84002", "0.124679"], ["84002.7", "0.04"], ["84002.9", "0.158835"], ["84008.2", "0.004062"], ["84008.4", "0"], ["84009.4", "0.357492"], ["84009.5", "0"], ["84013.7", "0"], ["84016.4", "2.612297"], ["84035.5", "0"], ["84036", "0"]], "u": 128112, "seq": 67571137067}, "cts": 1742576920903, "record_time": 1742576921.107826, "EXCHANGE": "BYBIT"}
{"topic": "orderbook.200.BTCUSDT", "ts": 1742576921119, "type": "delta", "data": {"s": "BTCUSDT", "b": [["83927.7", "0"], ["83927.6", "0"], ["83927.5", "0.040966"], ["83927.4", "0.039633"], ["83925.3", "0"], ["83925.2", "0"], ["83925.1", "0.012881"], ["83925", "0.012881"], ["83922.4", "0.05"], ["83922.3", "0.049548"], ["83922", "0"], ["83921.9", "0"], ["83889.8", "0.011862"]], "a": [["84004.2", "0"], ["84008.9", "0.04"], ["84009.4", "0"], ["84010.3", "0.361648"], ["84035.5", "0.004156"]], "u": 128113, "seq": 67571137107}, "cts": 1742576921115, "record_time": 1742576921.30748, "EXCHANGE": "BYBIT"}
{"topic": "orderbook.200.BTCUSDT", "ts": 1742576921320, "type": "delta", "data": {"s": "BTCUSDT", "b": [["83927.9", "0.04"], ["83927.8", "0.041133"], ["83927.5", "0.001333"], ["83927.4", "0"], ["83925.5", "0.013"], ["83925.4", "0.013403"], ["83925.1", "0"], ["83925", "0"], ["83922.4", "0"], ["83922.3", "0"], ["83922.2", "0.054327"], ["83922.1", "0.049548"], ["83912", "0.357489"], ["83906.2", "0.023824"], ["83889.7", "0.001333"]], "a": [["84010.2", "0.357493"], ["84010.3", "0.004156"], ["84035.5", "0"]], "u": 128114, "seq": 67571137165}, "cts": 1742576921315, "record_time": 1742576921.507441, "EXCHANGE": "BYBIT"}
{"topic": "orderbook.200.BTCUSDT", "ts": 1742576921520, "type": "delta", "data": {"s": "BTCUSDT", "b": [["83963", "0.204128"], ["83912", "0"], ["83906.2", "0.381314"], ["83889.4", "0.023828"]], "a": [["83999.3", "0.051877"], ["84002.1", "0.059399"], ["84010.1", "0.357492"], ["84010.2", "0"]], "u": 128115, "seq": 67571137214}, "cts": 1742576921516, "record_time": 1742576921.707723, "EXCHANGE": "BYBIT"}
{"topic": "orderbook.200.BTCUSDT", "ts": 1742576921720, "type": "delta", "data": {"s": "BTCUSDT", "b": [["83944.2", "0.061565"], ["83937.2", "0.059067"], ["83930.2", "0.123943"], ["83927.9", "0.039633"], ["83925.5", "0.012881"], ["83922.2", "0.053875"], ["83912", "0.357486"], ["83906.2", "0.023824"], ["83889.4", "0"]], "a": [["83979.2", "0.054722"], ["83986.2", "0.064986"], ["83993.2", "0.112324"], ["84002.8", "0"], ["84002.9", "0.118835"], ["84003", "0.065153"], ["84003.1", "0.04"], ["84010.1", "0"], ["84010.3", "0.361644"], ["84016.4", "0"], ["84019.1", "2.612297"], ["84035.5", "0.004156"]], "u": 128116, "seq": 67571137276}, "cts": 1742576921711, "record_time": 1742576921.907601, "EXCHANGE": "BYBIT"}
{"topic": "orderbook.200.BTCUSDT", "ts": 1742576921920, "type": "delta", "data": {"s": "BTCUSDT", "b": [["83963", "0.25845"], ["83944.2", "0"], ["83943.6", "0.178691"], ["83942", "0.178695"], ["83941.3", "0.103399"], ["83940.9", "0"], ["83939.2", "0.004098"], ["83939.1", "0"], ["83938.7", "0.089099"], ["83937.2", "0"], ["83930.2", "0"], ["83927.9", "0"], ["83927.8", "0.0015"], ["83926", "0.039634"], ["83925.9", "0.039635"], ["83925.5", "0"], ["83925.4", "0.000522"], ["83923.6", "0.012882"], ["83923.5", "0.147127"], ["83922.2", "0.004327"], ["83922.1", "0"], ["83920.3", "0.108949"], ["83920.2", "0.04955"], ["83917.6", "0.357464"], ["83914.2", "5.673243"], ["83913.8", "0.029207"], ["83913.2", "0.026352"], ["83912", "0"], ["83911.5", "0.000522"], ["83889.7", "0"]], "a": [["83963.1", "0.370892"], ["83966.5", "0"], ["83968", "0"], ["83968.5", "0.008692"], ["83969.4", "0.013247"], ["83971.3", "0"], ["83974.1", "0"], ["83975.3", "0.000153"], ["83975.7", "0.037576"], ["83975.9", "0.037336"], ["83977.6", "0"], ["83979.2", "0"], ["83979.5", "0.118835"], ["83979.7", "0.059399"], ["83979.9", "0.171"], ["83980.2", "0"], ["83986.2", "0.074273"], ["83993.2", "0"], ["83999.3", "0.000524"], ["84002.1", "0.110752"], ["84003", "0.025153"], ["84003.1", "0"], ["84006.6", "0.02344"], ["84007.1", "0.04"], ["84007.2", "0.041333"], ["84008.2", "0"], ["84010.3", "0.004156"], ["84012.5", "0"], ["84013.1", "0.000524"], ["84016.6", "0.357464"], ["84019.1", "0"], ["84024.7", "2.61263"], ["84036", "0.011993"], ["84036.1", "0.000145"], ["84036.2", "0.000524"], ["84036.6", "0.001333"], ["84036.9", "0.118835"], ["84037", "0.001466"], ["84037.4", "0.000333"]], "u": 128117, "seq": 67571137540}, "cts": 1742576921916, "record_time": 1742576922.107693, "EXCHANGE": "BYBIT"}
{"topic": "orderbook.200.BTCUSDT", "ts": 1742576922120, "type": "delta", "data": {"s": "BTCUSDT", "b": [["83963", "0.20395"], ["83944.7", "0.363257"], ["83944.2", "0.055737"], ["83943.6", "0"], ["83942", "0"], ["83941.3", "0.044"], ["83941", "0.762397"], ["83939.3", "0.178701"], ["83939.2", "0.000522"], ["83938.7", "0"], ["83937.2", "0.055648"], ["83930.2", "0.112142"], ["83917.6", "0"], ["83914.3", "2.816368"], ["83914.2", "0"], ["83913.2", "0"], ["83911.9", "0"], ["83906.2", "0.381304"], ["83906", "5.673243"], ["83889.7", "0.001333"]], "a": [["83966.5", "0.005957"], ["83968.3", "0.078698"], ["83968.4", "0.120635"], ["83968.5", "0.002735"], ["83969.4", "0.014247"], ["83970", "0.000153"], ["83971.3", "0.059399"], ["83974.4", "0.13752"], ["83975.3", "0"], ["83975.7", "0.086466"], ["83975.9", "0.215959"], ["83979.2", "0.240918"], ["83979.9", "0.34965"], ["83980.8", "0.072003"], ["83986.2", "0.061696"], ["83993.2", "0.114399"], ["83999.3", "0.051877"], ["84002", "0"], ["84002.1", "0.059399"], ["84004.4", "0.943557"], ["84008.8", "0.357492"], ["84016.6", "0"], ["84019.1", "2.612297"], ["84024.7", "0.000333"], ["84036.6", "0"], ["84036.9", "0"], ["84037", "0"], ["84037.4", "0"]], "u": 128118, "seq": 67571137718}, "cts": 1742576922116, "record_time": 1742576922.308068, "EXCHANGE": "BYBIT"}
{"topic": "orderbook.200.BTCUSDT", "ts": 1742576922320, "type": "delta", "data": {"s": "BTCUSDT", "b": [["83944.7", "0.253143"], ["83939.6", "0"], ["83937.1", "0.17865"], ["83935.1", "0"], ["83934.3", "0"], ["83930.1", "0"], ["83928.9", "0.359107"], ["83914.3", "0"], ["83913.8", "0.004265"], ["83889.4", "0.023828"], ["83889.3", "0.001466"], ["83888.6", "0.004248"], ["83888.5", "0.00052"]], "a": [["83968.7", "0.071489"], ["83980.4", "0.17874"], ["83983.1", "0"], ["83983.3", "0.071477"], ["83999.3", "0.000524"], ["84002.1", "0.110752"], ["84005.4", "0.042031"], ["84006.6", "0"], ["84008.8", "0"], ["84010.3", "0.361648"], ["84016.4", "2.612297"], ["84019.1", "0"], ["84036.6", "0.001333"]], "u": 128119, "seq": 67571137795}, "cts": 1742576922314, "record_time": 1742576922.506943, "EXCHANGE": "BYBIT"}
{"topic": "orderbook.200.BTCUSDT", "ts": 1742576922519, "type": "delta", "data": {"s": "BTCUSDT", "b": [["83939.6", "0.17865"], ["83937.1", "0"], ["83935.2", "0"], ["83922.2", "0.054327"], ["83922.1", "0.049548"], ["83920.3", "0.059399"], ["83920.2", "0"], ["83908.7", "5.673243"], ["83906", "0"], ["83888.3", "0.000149"]], "a": [["83975.7", "0.13395"], ["83977.9", "0.17865"], ["84003.6", "0.002031"], ["84005.4", "0.04"], ["84010.2", "0.357493"], ["84010.3", "0.004156"], ["84036.1", "0"], ["84036.2", "0"], ["84036.6", "0"]], "u": 128120, "seq": 67571137890}, "cts": 1742576922509, "record_time": 1742576922.707325, "EXCHANGE": "BYBIT"}
{"topic": "orderbook.200.BTCUSDT", "ts": 1742576922720, "type": "delta", "data": {"s": "BTCUSDT", "b": [["83935.1", "0.17865"], ["83934.6", "0.179172"], ["83930.4", "0.17865"], ["83922.2", "0.053875"], ["83908.8", "0.357494"], ["83906.2", "0.023824"], ["83888.6", "0"], ["83888.5", "0"], ["83888.3", "0"]], "a": [["84010.1", "0.357493"], ["84010.2", "0"]], "u": 128121, "seq": 67571138009}, "cts": 1742576922716, "record_time": 1742576922.907418, "EXCHANGE": "BYBIT"}
{"topic": "orderbook.200.BTCUSDT", "ts": 1742576922920, "type": "delta", "data": {"s": "BTCUSDT", "b": [["83927.8", "0.0415"], ["83927.7", "0.039633"], ["83926", "0"], ["83925.9", "0"], ["83908.9", "0.357494"], ["83908.8", "0"], ["83908.7", "5.28012"], ["83888.6", "0.004248"]], "a": [["83970", "0"], ["83972.5", "0.004415"], ["84003.3", "0.04"], ["84003.4", "0.04"], ["84007.1", "0"], ["84007.2", "0.001333"], ["84010", "0.357494"], ["84010.1", "0"]], "u": 128122, "seq": 67571138102}, "cts": 1742576922912, "record_time": 1742576923.10779, "EXCHANGE": "BYBIT"}
{"topic": "orderbook.200.BTCUSDT", "ts": 1742576923120, "type": "delta", "data": {"s": "BTCUSDT", "b": [["83927.8", "0.041133"], ["83909", "0.357489"], ["83908.9", "0"]], "a": [["83972.5", "0.004262"], ["83984.6", "0.17865"], ["83999.3", "0.051877"], ["84002.1", "0.059399"], ["84010", "0"], ["84010.3", "0.361645"], ["84036.1", "0.000145"]], "u": 128123, "seq": 67571138202}, "cts": 1742576923116, "record_time": 1742576923.307246, "EXCHANGE": "BYBIT"}
{"topic": "orderbook.200.BTCUSDT", "ts": 1742576923320, "type": "delta", "data": {"s": "BTCUSDT", "b": [["83963", "0.185952"], ["83944.2", "0"], ["83937.2", "0"], ["83935.2", "0.160145"], ["83930.2", "0"], ["83922.3", "0.049548"], ["83922.1", "0"], ["83909", "0"], ["83906.2", "0.381318"], ["83888.5", "0.00052"], ["83888.3", "0.000149"], ["83888.1", "0.264383"]], "a": [["83975.7", "0.091163"], ["83977.9", "0"], ["83979.2", "0.178616"], ["83983.2", "0.114292"], ["83986.2", "0.002799"], ["83993.2", "0"], ["84002", "0.097883"], ["84008.8", "0.357494"], ["84010.3", "0.004156"], ["84036.1", "0"]], "u": 128124, "seq": 67571138329}, "cts": 1742576923316, "record_time": 1742576923.507272, "EXCHANGE": "BYBIT"}
{"topic": "orderbook.200.BTCUSDT", "ts": 1742576923520, "type": "delta", "data": {"s": "BTCUSDT", "b": [["83937.1", "0.17865"], ["83928", "0.04"], ["83927.9", "0.039633"], ["83927.8", "0.0015"], ["83927.7", "0"], ["83925.7", "0.013"], ["83925.6", "0.012881"], ["83923.6", "0"], ["83923.5", "0.134245"], ["83922.4", "0.05"], ["83922.2", "0.004327"], ["83888.6", "0"], ["83888.5", "0"], ["83888.3", "0"], ["83888.1", "0"]], "a": [["83971.3", "0.060641"], ["83975.7", "0.133363"], ["83977.9", "0.17865"], ["83984.5", "0"], ["84002.9", "0.158835"], ["84003", "0.065153"], ["84003.3", "0"], ["84003.4", "0"], ["84036.1", "0.000145"], ["84036.2", "0.000524"]], "u": 128125, "seq": 67571138448}, "cts": 1742576923516, "record_time": 1742576923.707675, "EXCHANGE": "BYBIT"}
{"topic": "orderbook.200.BTCUSDT", "ts": 1742576923719, "type": "delta", "data": {"s": "BTCUSDT", "b": [["83963", "0.185152"], ["83944", "0.056274"], ["83937", "0.055045"], ["83930", "0.138217"], ["83911.9", "0.357488"], ["83906.2", "0.023824"], ["83889.7", "0"], ["83889.4", "0"], ["83889.3", "0"]], "a": [["83971.3", "0.059399"], ["83975.4", "0.008219"], ["83979", "0.054927"], ["83986", "0.056307"], ["83993", "0.11417"], ["84008.8", "0"], ["84010.8", "0.357487"], ["84036", "0"], ["84036.1", "0"], ["84036.2", "0"]], "u": 128126, "seq": 67571138587}, "cts": 1742576923716, "record_time": 1742576923.907951, "EXCHANGE": "BYBIT"}
{"topic": "orderbook.200.BTCUSDT", "ts": 1742576923919, "type": "delta", "data": {"s": "BTCUSDT", "b": [["83963", "0.202129"], ["83944", "0"], ["83943.1", "0.227087"], ["83941", "0.5837"], ["83937.1", "0"], ["83937", "0"], ["83936.3", "0.1191"], ["83930", "0.018582"], ["83928", "0"], ["83927.8", "0.041133"], ["83925.7", "0"], ["83925.5", "0.012881"], ["83922.4", "0"], ["83922.2", "0.053875"], ["83908.7", "4.773297"], ["83889.7", "0.001333"], ["83889.4", "0.023828"], ["83889.3", "0.001466"], ["83888.6", "0.004248"]], "a": [["83968.7", "0"], ["83970.2", "0.071821"], ["83979", "0"], ["83980.4", "0.35739"], ["83980.7", "0.1191"], ["83986", "0"], ["83993", "0"], ["84002.9", "0.118835"], ["84003", "0.025153"], ["84003.2", "0.04"], ["84003.3", "0.04"], ["84010.3", "0.361644"], ["84010.8", "0"], ["84036", "0.011993"], ["84036.1", "0.000145"]], "u": 128127, "seq": 67571138740}, "cts": 1742576923916, "record_time": 1742576924.107858, "EXCHANGE": "BYBIT"}
{"topic": "orderbook.200.BTCUSDT", "ts": 1742576924120, "type": "delta", "data": {"s": "BTCUSDT", "b": [["83963", "0.264029"], ["83939.7", "0.059399"], ["83914.2", "0.357478"], ["83911.9", "0"], ["83888.6", "0"]], "a": [["83963.1", "0.199892"], ["83966.5", "0"], ["83968.5", "0.008692"], ["83970.2", "0.000333"], ["83971.4", "0.218857"], ["83973.4", "0.00122"], ["83975.7", "0.037576"], ["83975.9", "0.037336"], ["83977.9", "0"], ["83979.2", "0"], ["83979.9", "0.171"], ["84010.3", "0.004156"], ["84014.1", "0.357482"], ["84036.2", "0.000524"]], "u": 128128, "seq": 67571138922}, "cts": 1742576924116, "record_time": 1742576924.30749, "EXCHANGE": "BYBIT"}
{"topic": "orderbook.200.BTCUSDT", "ts": 1742576924320, "type": "delta", "data": {"s": "BTCUSDT", "b": [["83950.5", "0.001999"], ["83931.9", "0.024178"], ["83927.9", "0"], ["83927.7", "0.039633"], ["83925.6", "0"], ["83925.5", "0.013"], ["83925.4", "0.013403"], ["83922.3", "0"], ["83922.2", "0.054327"], ["83922.1", "0.049548"], ["83915.1", "0.357477"], ["83914.2", "0"], ["83913", "0.026352"], ["83912.9", "0.024942"], ["83911.9", "1.008524"], ["83911.5", "4.773819"], ["83908.7", "0"], ["83889.4", "0"], ["83889.3", "0"]], "a": [["83968.2", "0.005957"], ["83968.5", "0.002735"], ["83970.2", "0.071821"], ["83971.4", "0.14737"], ["83973.4", "0"], ["83974.2", "0.000153"], ["83975.4", "0.006667"], ["83980.6", "0.178613"], ["83982.4", "0.17865"], ["83983.4", "0.101523"], ["84003.2", "0"], ["84003.4", "0.04"], ["84014", "0.357656"], ["84014.1", "0"], ["84036", "0"], ["84036.1", "0"], ["84036.2", "0"]], "u": 128129, "seq": 67571139070}, "cts": 1742576924316, "record_time": 1742576924.508248, "EXCHANGE": "BYBIT"}
{"topic": "orderbook.200.BTCUSDT", "ts": 1742576924519, "type": "delta", "data": {"s": "BTCUSDT", "b": [["83927.8", "0.0015"], ["83927.7", "0"], ["83927.6", "0.039633"], ["83927.5", "0.040966"], ["83925.5", "0"], ["83925.4", "0.000522"], ["83925.3", "0.012881"], ["83925.2", "0.012881"], ["83922.2", "0.004327"], ["83922.1", "0"], ["83922", "0.049548"], ["83921.9", "0.049548"], ["83915.1", "0"], ["83913.4", "0.357483"], ["83889.8", "0"], ["83889.7", "0"]], "a": [["83963.1", "0.370892"], ["83966.5", "0.005957"], ["83968.2", "0"], ["83974.2", "0"], ["83975.7", "0.059646"], ["83977.6", "0.087724"], ["83979.9", "0.34965"], ["83980.6", "0"], ["83982.4", "0"], ["83989.2", "0"], ["83989.5", "0.035738"], ["84003.3", "0"], ["84003.4", "0"], ["84003.7", "0.040333"], ["84003.8", "0.04"], ["84011.8", "0.357483"], ["84014", "0.00018"], ["84036", "0.011993"], ["84036.1", "0.000145"]], "u": 128130, "seq": 67571139191}, "cts": 1742576924488, "record_time": 1742576924.706865, "EXCHANGE": "BYBIT"}
{"topic": "orderbook.200.BTCUSDT", "ts": 1742576924720, "type": "delta", "data": {"s": "BTCUSDT", "b": [["83920.1", "0.13294"], ["83917.4", "0"], ["83914.2", "5.130778"], ["83913.4", "0"], ["83913", "0"], ["83911.5", "0.000522"], ["83889.8", "0.011862"]], "a": [["83972.4", "0.040153"], ["84003.7", "0.000333"], ["84003.8", "0"], ["84003.9", "0.040524"], ["84004", "0.04"], ["84011.8", "0"], ["84011.9", "0.397481"], ["84036.2", "0.000524"]], "u": 128131, "seq": 67571139267}, "cts": 1742576924718, "record_time": 1742576924.907747, "EXCHANGE": "BYBIT"}
{"success": true, "ret_msg": "subscribe", "conn_id": "a40f0371-7187-42e8-8ca7-9acd5f2ba35c", "op": "subscribe", "record_time": 1742577042.824169, "EXCHANGE": "BYBIT"}
{"topic": "orderbook.200.BTCUSDT", "ts": 1742577041319, "type": "snapshot", "data": {"s": "BTCUSDT", "b": [["84001.9", "0.044325"], ["84001.5", "0.001"], ["84000.1", "0.001466"], ["84000", "0.00006"], ["83999.5", "0.000333"], ["83999.3", "0.000524"], ["83999.1", "0.010505"], ["83998.8", "0.001333"], ["83998.7", "0.02"], ["83997.7", "0.004325"], ["83997", "0.044069"], ["83995.4", "0.001466"], ["83995.3", "0.000333"], ["83995.2", "0.005225"], ["83994.6", "0.001857"], ["83993.8", "0.001"], ["83993.5", "0.004325"], ["83992.8", "0.034673"], ["83992.3", "0.04"], ["83992", "0.024214"], ["83991.8", "0.002062"], ["83991.6", "0.00009"], ["83991.1", "0.000333"], ["83991", "0.044"], ["83990.8", "0.001466"], ["83990.4", "0.001333"], ["83990", "0.000524"], ["83989.9", "0.075046"], ["83989.8", "0.171"], ["83989.7", "0.033165"], ["83989.3", "0.004415"], ["83988.7", "0.005952"], ["83988.3", "0.0005"], ["83987.6", "0.003981"], ["83987.3", "0.118615"], ["83987.2", "0.035729"], ["83986.9", "0.000333"], ["83986.5", "0.00168"], ["83986.2", "0.002799"], ["83985.4", "0.000524"], ["83985.1", "0.004415"], ["83983.6", "0.003675"], ["83983.2", "0.00009"], ["83982.7", "0.000333"], ["83982", "0.001333"], ["83981.9", "0.0006"], ["83981.8", "0.00036"], ["83981.6", "0.001466"], ["83981.2", "0.090654"], ["83980.9", "0.004415"], ["83980.8", "0.000524"], ["83980", "0.00006"], ["83978.5", "0.020098"], ["83978", "0.548935"], ["83977.8", "0.502352"], ["83977.7", "0.171"], ["83977", "0.037185"], ["83976.7", "0.004404"], ["83976.6", "0.02552"], ["83976.3", "0.005952"], ["83976.2", "0.000524"], ["83976.1", "0.059399"], ["83975.5", "0.680293"], ["83975.2", "0.003575"], ["83974.8", "0.119086"], ["83974.6", "0.0025"], ["83974.3", "0.000333"], ["83973.6", "0.001333"], ["83973", "0.039993"], ["83972.5", "0.004403"], ["83972.4", "0.011909"], ["83972.3", "0.001466"], ["83971.6", "0.000524"], ["83970.2", "0.000333"], ["83970.1", "0.039631"], ["83970", "0.039631"], ["83969.4", "0.001333"], ["83969.2", "0.171"], ["83968.3", "0.004403"], ["83968.2", "0.596752"], ["83968.1", "1.784961"], ["83967.7", "0.014466"], ["83967.6", "0.012881"], ["83967.4", "0.023807"], ["83967", "0.023807"], ["83966.9", "0.000524"], ["83966.6", "0.059399"], ["83966.5", "0.118835"], ["83966.4", "0.00018"], ["83966", "0.000333"], ["83965.5", "0.003575"], ["83965.2", "0.001333"], ["83964.7", "0.023808"], ["83964.4", "0.05"], ["83964.3", "0.049546"], ["83964.1", "0.004403"], ["83964", "0.011911"], ["83963.1", "0.001466"], ["83962.3", "0.000524"], ["83961.8", "0.000333"], ["83961.7", "0.015"], ["83961.6", "0.001785"], ["83961.3", "0.198666"], ["83961.2", "0.038807"], ["83961", "0.001333"], ["83960.7", "0.171"], ["83960.1", "0.014112"], ["83960", "0.00006"], ["83959.9", "0.004403"], ["83959.7", "0.00036"], ["83958.5", "0.120301"], ["83958.3", "0.353832"], ["83958", "0.059607"], ["83957.7", "0.000524"], ["83957.6", "0.000333"], ["83957.1", "0.023807"], ["83956.8", "0.001333"], ["83956.7", "0.015097"], ["83956.6", "0.023809"], ["83955.9", "0.005"], ["83955.7", "0.013627"], ["83954.9", "0.0016"], ["83953.9", "0.001466"], ["83953.6", "0.187476"], ["83953.5", "0.053478"], ["83953.4", "0.000333"], ["83953.2", "0.118835"], ["83953.1", "0.000524"], ["83953", "0.005952"], ["83952.6", "0.001333"], ["83952.3", "0.023809"], ["83952.2", "0.171"], ["83952", "0.4"], ["83951.5", "0.004397"], ["83951.4", "0.132971"], ["83950.9", "0.02112"], ["83949.6", "0.00009"], ["83949.3", "0.001466"], ["83949.2", "0.000333"], ["83948.5", "0.000524"], ["83948.4", "0.001333"], ["83947.5", "0.357337"], ["83947.4", "0.118835"], ["83947.3", "0.004396"], ["83946.5", "0.059399"], ["83946.1", "0.089099"], ["83945", "0.000333"], ["83944.6", "0.001466"], ["83944.3", "0.001333"], ["83943.8", "0.000523"], ["83943.7", "0.171"], ["83943.1", "0.004394"], ["83942.8", "0.04"], ["83941.3", "0.044"], ["83941.2", "0.118925"], ["83940.8", "0.000333"], ["83940.1", "0.001333"], ["83940", "0.001526"], ["83939.7", "3.790181"], ["83939.6", "0.048"], ["83939.4", "0.056"], ["83939.2", "0.179234"], ["83938.9", "0.005594"], ["83938.7", "0.224383"], ["83938.5", "0.000358"], ["83937.9", "0.044086"], ["83937.7", "0.044"], ["83937.6", "0.00036"], ["83937", "0.005885"], ["83936.6", "0.000333"], ["83936.2", "0.044"], ["83935.9", "0.060732"], ["83935.8", "0.000333"], ["83935.4", "0.001466"], ["83935.2", "0.289835"], ["83935", "0.179077"], ["83934.7", "0.00439"], ["83934.6", "0.089621"], ["83934.5", "0.044"], ["83934.3", "0.048"], ["83932.8", "0.00009"], ["83932.4", "0.000333"], ["83931.7", "0.001333"], ["83931.4", "0.0006"], ["83930.8", "0.001466"], ["83930.6", "0.004339"], ["83930", "0.000522"], ["83929.6", "0.118835"], ["83929.4", "3.331208"], ["83928.8", "1.209475"], ["83928.2", "0.000333"], ["83927.7", "0.124994"], ["83927.5", "0.001333"], ["83926.6", "0.059399"], ["83926.4", "0.004327"], ["83926.3", "0.636954"], ["83926.2", "0.001466"], ["83925.6", "0.023853"], ["83925.4", "0.121165"], ["83925", "0.02382"]], "a": [["84002", "0.85048"], ["84003.1", "0.10695"], ["84003.7", "0.325768"], ["84003.8", "0.327985"], ["84007.2", "0.034868"], ["84007.6", "0.333678"], ["84007.9", "0.000333"], ["84008.5", "0.000524"], ["84009.3", "0.001466"], ["84009.9", "0.0013"], ["84010.3", "0.004331"], ["84010.5", "0.024522"], ["84011.2", "0.050472"], ["84011.3", "0.071453"], ["84011.4", "0.001333"], ["84012.1", "0.057588"], ["84012.2", "0.031735"], ["84012.9", "0.042405"], ["84013", "0.001"], ["84013.1", "0.000524"], ["84013.9", "0.001466"], ["84014", "0.00009"], ["84014.5", "0.004334"], ["84014.6", "0.100789"], ["84014.7", "0.036782"], ["84014.9", "0.059399"], ["84015.2", "0.001"], ["84015.5", "0.001"], ["84015.6", "0.021333"], ["84015.8", "0.038456"], ["84016.2", "0.00138"], ["84016.3", "0.000333"], ["84016.5", "0.04"], ["84016.7", "0.171"], ["84017.7", "0.001124"], ["84018.4", "0.003783"], ["84018.5", "0.001466"], ["84018.7", "0.004334"], ["84019.8", "0.001333"], ["84020", "0.00024"], ["84020.5", "0.000333"], ["84021", "0.060191"], ["84022.4", "0.040614"], ["84022.7", "0.001"], ["84022.9", "0.004436"], ["84023.2", "0.001466"], ["84023.9", "0.119042"], ["84024", "0.041333"], ["84024.7", "0.000333"], ["84025.5", "0.04"], ["84025.7", "0.177531"], ["84025.8", "0.04"], ["84027", "0.000524"], ["84027.1", "0.004436"], ["84027.4", "0.04"], ["84027.5", "0.005588"], ["84027.8", "0.001466"], ["84027.9", "0.020035"], ["84028.2", "0.001333"], ["84028.7", "0.04136"], ["84028.9", "0.040333"], ["84029", "0.118996"], ["84029.1", "0.059399"], ["84029.2", "0.191035"], ["84029.7", "0.08515"], ["84030", "0.029192"], ["84030.4", "0.04"], ["84030.6", "0.04"], ["84030.8", "0.00009"], ["84031.3", "0.01039"], ["84031.6", "0.000524"], ["84031.8", "0.050035"], ["84032.4", "0.002799"], ["84032.5", "0.003576"], ["84033.2", "0.000333"], ["84035", "0.115145"], ["84035.1", "0.523503"], ["84035.4", "0.050035"], ["84035.5", "0.004437"], ["84035.6", "0.034939"], ["84036.2", "0.000524"], ["84036.3", "0.005952"], ["84036.4", "0.163441"], ["84036.6", "0.001333"], ["84037", "0.001466"], ["84037.3", "0.114057"], ["84037.4", "0.000333"], ["84037.6", "0.021638"], ["84037.7", "0.00036"], ["84038.6", "0.0016"], ["84038.8", "0.295018"], ["84039", "0.118996"], ["84039.1", "0.075135"], ["84039.2", "0.062946"], ["84039.4", "0.171"], ["84039.7", "0.004156"], ["84040", "0.190712"], ["84040.8", "0.001333"], ["84040.9", "0.000524"], ["84041.6", "0.006285"], ["84041.7", "0.052824"], ["84042.1", "0.023805"], ["84042.6", "0.004632"], ["84043.9", "0.480067"], ["84044.2", "0.178563"], ["84044.7", "0.0006"], ["84045", "0.001333"], ["84045.2", "0.023808"], ["84045.5", "0.000524"], ["84045.7", "0.951822"], ["84045.8", "0.000333"], ["84046.2", "0.023808"], ["84046.3", "0.001466"], ["84047.2", "0.005951"], ["84047.4", "0.357319"], ["84047.5", "0.701079"], ["84047.6", "0.119086"], ["84047.7", "0.178556"], ["84047.8", "0.193831"], ["84048.1", "0.004156"], ["84048.3", "0.059399"], ["84049.2", "0.001333"], ["84049.4", "0.006"], ["84050", "0.000333"], ["84050.1", "0.000524"], ["84050.4", "0.124994"], ["84050.9", "0.001466"], ["84051", "0.023808"], ["84051.8", "0.04"], ["84051.9", "0.04"], ["84052.3", "0.004156"], ["84053.4", "0.208912"], ["84053.5", "0.126318"], ["84053.9", "0.569722"], ["84054.2", "0.000333"], ["84054.7", "0.000524"], ["84054.8", "0.118996"], ["84055.5", "0.001466"], ["84055.6", "0.024163"], ["84055.9", "0.005"], ["84056", "0.00018"], ["84056.2", "0.171"], ["84056.5", "0.027263"], ["84056.6", "0.000366"], ["84057.7", "0.001333"], ["84058.1", "0.002528"], ["84058.2", "0.000083"], ["84058.4", "0.000333"], ["84058.5", "0.005951"], ["84059", "0.024007"], ["84059.3", "0.000524"], ["84059.7", "0.079559"], ["84059.8", "0.00036"], ["84059.9", "0.118996"], ["84060", "0.281467"], ["84060.1", "0.892465"], ["84060.7", "0.004156"], ["84061.2", "0.015"], ["84061.9", "0.001333"], ["84062", "1.785826"], ["84062.1", "0.023804"], ["84062.6", "0.000333"], ["84062.8", "0.000333"], ["84063.1", "0.023804"], ["84064", "0.000524"], ["84064.4", "0.00009"], ["84064.6", "0.171"], ["84064.8", "0.001466"], ["84064.9", "0.004156"], ["84066.1", "0.001333"], ["84066.4", "0.118996"], ["84066.6", "0.023804"], ["84066.8", "0.000333"], ["84067.7", "0.04"], ["84067.9", "0.023804"], ["84068.6", "0.000524"], ["84069.2", "0.004156"], ["84069.4", "0.001466"], ["84069.7", "0.04"], ["84070.3", "0.001333"], ["84070.6", "0.001785"], ["84071", "0.000333"], ["84071.5", "0.000427"], ["84072.2", "0.238066"], ["84072.4", "0.589801"], ["84072.5", "0.023802"], ["84072.7", "0.072482"], ["84072.8", "0.00009"], ["84072.9", "0.04"], ["84073", "0.171"], ["84073.2", "0.000524"], ["84073.4", "0.004156"], ["84074", "0.001466"], ["84074.5", "0.001333"], ["84074.6", "0.0025"], ["84075", "0.00315"], ["84075.2", "0.000333"], ["84076.6", "0.015"], ["84077.3", "0.118835"], ["84077.6", "0.004156"]], "u": 128711, "seq": 67571251468}, "cts": 1742577041317, "record_time": 1742577042.82517, "EXCHANGE": "BYBIT"}
{"topic": "orderbook.200.BTCUSDT", "ts": 1742577041520, "type": "delta", "data": {"s": "BTCUSDT", "b": [["84001.9", "0"], ["84001.5", "0"], ["84000.1", "0"], ["84000", "0"], ["83999.5", "0"], ["83999.3", "0"], ["83999.1", "0"], ["83998.8", "0"], ["83998.7", "0.022976"], ["83997", "0"], ["83995.2", "0"], ["83994.9", "0.005778"], ["83993.8", "0"], ["83992.8", "0"], ["83992.3", "0"], ["83992", "0.023116"], ["83991.8", "0"], ["83991.6", "0"], ["83991", "0"], ["83990.4", "0.022288"], ["83989.9", "0"], ["83989.8", "0"], ["83989.7", "0"], ["83989.6", "0.002063"], ["83988.7", "0"], ["83987.8", "0.034676"], ["83987.3", "0"], ["83987.2", "0"], ["83986.6", "0.068918"], ["83986.5", "0.073154"], ["83984.9", "0.033169"], ["83984.2", "0.071476"], ["83983.9", "0.044"], ["83983.6", "0.0001"], ["83982.7", "0.09536"], ["83982.6", "0.056"], ["83982.2", "0.048"], ["83981.2", "0"], ["83980.7", "0.044"], ["83978.5", "0.000333"], ["83978", "0"], ["83977.5", "0.048"], ["83977", "0.001466"], ["83976.1", "0"], ["83975.9", "0.11405"], ["83975.7", "0.009171"], ["83975.5", "0"], ["83974.8", "0.00009"], ["83973", "0.00464"], ["83972.4", "0"], ["83970.1", "0"], ["83970", "0"], ["83969.8", "0.023809"], ["83967.7", "0.001466"], ["83967.6", "0"], ["83967", "0"], ["83966.6", "0.099029"], ["83966.5", "0.158465"], ["83964.4", "0"], ["83964.3", "0"], ["83964.1", "0.017283"], ["83964", "0.024791"], ["83961.2", "0.015"], ["83960.9", "0.049544"], ["83960.8", "0.049544"], ["83960.1", "0"], ["83959.2", "0.563884"], ["83958.2", "0.023809"], ["83952.4", "0.023809"], ["83947.5", "0"], ["83944.4", "0.178574"], ["83943.8", "0.35788"], ["83940.2", "0.003575"], ["83939.2", "0.000671"], ["83935", "0.000514"], ["83933.6", "5.175189"], ["83926.7", "0.171"], ["83926.3", "0.011994"], ["83924.6", "0.015607"], ["83924.5", "0.118835"], ["83924.4", "0.001387"], ["83924", "0.000333"], ["83923.5", "0.05"], ["83923.3", "0.001333"], ["83922.4", "0.089287"], ["83922.3", "0.011994"], ["83922.2", "0.004327"], ["83921.6", "0.001466"], ["83920.8", "0.000522"], ["83920.2", "0.1"]], "a": [["83998.8", "0.818653"], ["84000.2", "0.1"], ["84001.4", "0.075634"], ["84002", "0.170035"], ["84002.6", "0.006131"], ["84002.9", "0.0009"], ["84003", "0.001333"], ["84003.1", "0"], ["84003.7", "0.000333"], ["84003.8", "0.050035"], ["84003.9", "0.000524"], ["84004.7", "0.001466"], ["84004.8", "0.071458"], ["84005.5", "0.024523"], ["84005.9", "0.003783"], ["84006.1", "0.004332"], ["84006.5", "0.009462"], ["84006.9", "0.023847"], ["84007.1", "0.04169"], ["84007.2", "0.01553"], ["84007.5", "0.100203"], ["84007.6", "0.327548"], ["84008", "0.042405"], ["84009.4", "0.06308"], ["84009.5", "0.05819"], ["84009.7", "0.04036"], ["84009.9", "0"], ["84010.3", "0.042787"], ["84010.5", "0"], ["84011.2", "0"], ["84011.3", "0"], ["84011.7", "0.04"], ["84012.1", "0.000333"], ["84012.4", "0.04"], ["84012.9", "0"], ["84014.7", "0"], ["84015.8", "0"], ["84016.7", "0.211"], ["84017.1", "0.018623"], ["84017.2", "0.04"], ["84017.4", "0.04"], ["84018.3", "0.11405"], ["84018.4", "0"], ["84018.9", "0.04"], ["84021", "0.050729"], ["84022.6", "0.04"], ["84023.9", "0"], ["84025.8", "0"], ["84026.4", "0.023809"], ["84027.5", "0"], ["84028.9", "0.000333"], ["84029.7", "0.029144"], ["84030.4", "0"], ["84030.6", "0"], ["84031.6", "0.014035"], ["84032.5", "0"], ["84035.5", "0.576803"], ["84037.3", "0"], ["84038.6", "0"], ["84038.9", "0.051358"], ["84040", "0.012149"], ["84040.7", "1.427733"], ["84041.6", "0.363639"], ["84041.7", "0.001466"], ["84042.6", "0.178574"], ["84043.9", "0.004156"], ["84044.2", "0"], ["84045.7", "0"], ["84047.4", "0"], ["84047.5", "0.253237"], ["84047.7", "0"], ["84048.4", "0.089287"], ["84050", "0.000451"], ["84053.9", "0"], ["84069.4", "0.090753"], ["84073.2", "0"], ["84073.4", "0"], ["84074", "0"], ["84074.5", "0"], ["84074.6", "0"], ["84075", "0"], ["84075.2", "0"], ["84076.6", "0"], ["84077.3", "0"], ["84077.6", "0"]], "u": 128712, "seq": 67571252269}, "cts": 1742577041513, "record_time": 1742577042.828169, "EXCHANGE": "BYBIT"}
{"topic": "orderbook.200.BTCUSDT", "ts": 1742577041720, "type": "delta", "data": {"s": "BTCUSDT", "b": [["83998.7", "0"], ["83997.7", "0.004564"], ["83994.9", "0"], ["83993.9", "0.005779"], ["83990.3", "0.176"], ["83989.3", "0.019415"], ["83984.5", "0.044"], ["83984.3", "0.04"], ["83984.2", "0"], ["83982.8", "0.075635"], ["83982.7", "0.048333"], ["83980.9", "0.048415"], ["83977.9", "0.265831"], ["83975.9", "0"], ["83973", "0"], ["83972.1", "0.019765"], ["83969.8", "0"], ["83968.3", "0.024403"], ["83966.6", "0.059399"], ["83966.5", "0.118835"], ["83965.6", "0.119049"], ["83964.1", "0.004403"], ["83964", "0.011911"], ["83962.6", "0.039633"], ["83962.5", "0.039633"], ["83960.9", "0"], ["83960.8", "0"], ["83960.3", "0.022966"], ["83960.2", "0.012881"], ["83960.1", "0.012881"], ["83959.6", "0.004608"], ["83958.3", "0"], ["83956.9", "0.049548"], ["83956.8", "0.050881"], ["83946.3", "0.013721"], ["83946.2", "0.357348"], ["83943.9", "0.22086"], ["83943.8", "0.000523"], ["83941.9", "5.353765"], ["83939.2", "0.000522"], ["83938.7", "0"], ["83933.6", "0"], ["83928.8", "1.181632"], ["83924.4", "0.000263"], ["83923.5", "0"], ["83923.3", "0"], ["83922.4", "0"], ["83922.3", "0"], ["83922.2", "0"], ["83921.6", "0"], ["83920.8", "0"], ["83920.2", "0"]], "a": [["83997.8", "0.663938"], ["83998.6", "0.190838"], ["83998.8", "0.42557"], ["84001.4", "0"], ["84001.6", "0.006131"], ["84002.6", "0"], ["84003", "0.010558"], ["84003.3", "0.00558"], ["84006.8", "0.169444"], ["84007.1", "0.057255"], ["84007.2", "0.001333"], ["84007.5", "0"], ["84009.4", "0.073444"], ["84009.5", "0"], ["84009.7", "0.036784"], ["84010", "0.04"], ["84010.7", "0.04"], ["84011.2", "0.003576"], ["84012.2", "0"], ["84012.8", "0.04"], ["84013.3", "0.24526"], ["84013.4", "0.178574"], ["84013.6", "0.119049"], ["84014.6", "0"], ["84014.8", "0.178574"], ["84016.5", "0"], ["84016.9", "0.04"], ["84017.1", "0"], ["84017.3", "0.060864"], ["84017.4", "0"], ["84019", "0.178574"], ["84022.4", "0.000614"], ["84022.7", "0"], ["84024", "0.001333"], ["84025.5", "0"], ["84025.7", "0.137531"], ["84026.3", "0.004687"], ["84026.4", "0"], ["84027.4", "0"], ["84038.9", "0.051359"], ["84039.7", "1.431889"], ["84039.8", "0.014085"], ["84040.1", "0.178576"], ["84040.7", "0"], ["84041.6", "0.006285"], ["84042.6", "0"], ["84044.4", "0.022842"], ["84047.4", "0.357348"], ["84047.5", "0"], ["84047.8", "0.171"], ["84053.4", "0"], ["84064.9", "0.032326"], ["84069.1", "0.000145"], ["84069.4", "0.001466"], ["84072.5", "0"], ["84072.7", "0"], ["84072.8", "0"], ["84072.9", "0"], ["84073", "0"]], "u": 128713, "seq": 67571252729}, "cts": 1742577041714, "record_time": 1742577042.83017, "EXCHANGE": "BYBIT"}
{"topic": "orderbook.200.BTCUSDT", "ts": 1742577041919, "type": "delta", "data": {"s": "BTCUSDT", "b": [["83997.7", "0"], ["83993.9", "0"], ["83992", "0"], ["83991.6", "0.005779"], ["83990.3", "0"], ["83989.3", "0.004415"], ["83988.7", "0.023117"], ["83987.8", "0"], ["83987", "0.191"], ["83986.5", "0.00168"], ["83984.5", "0.078678"], ["83980.6", "0.122507"], ["83979.4", "0.044"], ["83976.6", "0"], ["83970.1", "0.181827"], ["83968.4", "0.004803"], ["83968.3", "0.004403"], ["83963.1", "0.303617"], ["83962.6", "0"], ["83962.4", "0.039631"], ["83960.2", "0"], ["83960", "0.01294"], ["83956.9", "0"], ["83956.7", "0.064642"], ["83946.2", "0"], ["83945.5", "0.35365"], ["83944.4", "0"], ["83941.9", "5.142228"], ["83938", "0.357362"], ["83927.7", "0"], ["83923.3", "0.001333"], ["83922.4", "0.089287"]], "a": [["83995.5", "0.575474"], ["83996.1", "0.071466"], ["83997.6", "0.23375"], ["83997.7", "0.01714"], ["83997.8", "0.221035"], ["83998.6", "0"], ["83998.8", "0.25457"], ["83999.3", "0.006131"], ["84000.1", "0.101555"], ["84001.6", "0"], ["84001.9", "0.004332"], ["84002.2", "0.024524"], ["84003", "0.001333"], ["84003.3", "0"], ["84004.4", "0.005414"], ["84004.8", "0"], ["84005.1", "0.123361"], ["84005.3", "0.05819"], ["84005.5", "0"], ["84005.6", "0.00009"], ["84006.1", "0.044332"], ["84006.4", "0.036785"], ["84007", "0.031735"], ["84007.6", "0.256092"], ["84007.8", "0.04"], ["84009.7", "0"], ["84013.4", "0"], ["84015.6", "0.206631"], ["84021", "0.014187"], ["84022.6", "0.320255"], ["84029.4", "0.125003"], ["84036.1", "0.05136"], ["84037.4", "1.428066"], ["84038.9", "0.357362"], ["84039.7", "0.004156"], ["84040.1", "0"], ["84047.4", "0"], ["84055.1", "2.612782"], ["84064.1", "1.027788"], ["84069.1", "0"], ["84069.2", "0"], ["84069.4", "0"], ["84069.7", "0"], ["84070.3", "0"], ["84070.6", "0"], ["84071", "0"], ["84071.5", "0"], ["84072.2", "0"], ["84072.4", "0"]], "u": 128714, "seq": 67571253196}, "cts": 1742577041917, "record_time": 1742577042.83117, "EXCHANGE": "BYBIT"}
{"topic": "orderbook.200.BTCUSDT", "ts": 1742577042120, "type": "delta", "data": {"s": "BTCUSDT", "b": [["83995.4", "0.004442"], ["83987.6", "0"], ["83986.6", "0"], ["83982.9", "0.071477"], ["83982.8", "0.115225"], ["83981.8", "0.005927"], ["83980.6", "0"], ["83978.9", "0.07148"], ["83977.2", "0.003981"], ["83972.1", "0.312396"], ["83970.5", "0.178581"], ["83970.1", "0"], ["83968.6", "0.178581"], ["83968.4", "0"], ["83967.8", "0.004763"], ["83964.4", "0.178581"], ["83963.1", "0.001466"], ["83962.5", "0"], ["83962.4", "0"], ["83961.9", "0.039631"], ["83961.8", "0.039964"], ["83960.8", "0.299028"], ["83960.1", "0"], ["83960", "0.00006"], ["83959.5", "0.012881"], ["83959.4", "0.012881"], ["83956.8", "0.001333"], ["83956.7", "0.015097"], ["83956.2", "0.049546"], ["83956.1", "0.049546"], ["83951.4", "0"], ["83948.5", "0.13348"], ["83943.4", "0.089291"], ["83938.1", "0.357362"], ["83938", "0"], ["83924.5", "0"], ["83924.4", "0"], ["83924", "0"], ["83923.3", "0"], ["83922.4", "0"]], "a": [["83995.5", "0.652462"], ["83996", "0.092498"], ["83997.6", "0"], ["83997.7", "0"], ["83998.8", "0.235232"], ["84000.1", "0.155523"], ["84001", "0.071462"], ["84002.8", "0.07146"], ["84003.9", "0.020524"], ["84005", "0.059399"], ["84005.1", "0"], ["84008.3", "0.178581"], ["84009.2", "0.04"], ["84009.4", "0.118803"], ["84009.6", "0.04"], ["84010.6", "0.178581"], ["84010.7", "0"], ["84011.3", "0.04"], ["84012.4", "0"], ["84014.4", "0.04"], ["84015.6", "0.001333"], ["84016.9", "0"], ["84017.2", "0"], ["84018.9", "0"], ["84019", "0"], ["84022", "0.04115"], ["84022.5", "0.118996"], ["84022.6", "0.04"], ["84027.4", "0.089291"], ["84038.9", "0"], ["84045.4", "0.022831"], ["84047.5", "0.357362"], ["84055.1", "0"], ["84056.7", "0.04"], ["84066.6", "0"], ["84066.8", "0"], ["84067.7", "0"], ["84067.9", "0"], ["84068.6", "0"]], "u": 128715, "seq": 67571253428}, "cts": 1742577042108, "record_time": 1742577042.83217, "EXCHANGE": "BYBIT"}
{"topic": "orderbook.200.BTCUSDT", "ts": 1742577042319, "type": "delta", "data": {"s": "BTCUSDT", "b": [["83995.4", "0"], ["83995.3", "0"], ["83994.6", "0"], ["83993.5", "0"], ["83991.6", "0"], ["83991.1", "0"], ["83990.8", "0"], ["83990.4", "0"], ["83990", "0"], ["83989.6", "0"], ["83989.3", "0"], ["83988.7", "0"], ["83988.3", "0"], ["83987", "0"], ["83986.9", "0.002729"], ["83984.9", "0"], ["83984.5", "0"], ["83984.3", "0"], ["83983.9", "0"], ["83983.6", "0"], ["83983.2", "0"], ["83982.9", "0"], ["83982.8", "0"], ["83982.7", "0.000333"], ["83982.6", "0"], ["83982.2", "0"], ["83981.8", "0.00036"], ["83980.9", "0.004415"], ["83980.7", "0"], ["83979.4", "0"], ["83978.9", "0"], ["83978.5", "0.020333"], ["83977.9", "0.032792"], ["83977.8", "0.001333"], ["83977.5", "0"], ["83975.7", "0"], ["83975.2", "0"], ["83973.7", "0.110336"], ["83973.6", "0.045333"], ["83973.2", "0.005952"], ["83973.1", "0.056"], ["83972.1", "0"], ["83971.5", "0.048"], ["83970.5", "0"], ["83968.6", "0"], ["83968.3", "0.048403"], ["83968.1", "1.832961"], ["83967.8", "0"], ["83967.4", "0"], ["83966.6", "0"], ["83966.5", "0"], ["83965.7", "0.146559"], ["83965.6", "0"], ["83965.5", "0.523885"], ["83964.7", "0"], ["83964.4", "0"], ["83964", "0"], ["83962.8", "0.009171"], ["83961.9", "0"], ["83961.8", "0.000333"], ["83961.7", "0.034765"], ["83960.9", "0.059399"], ["83960.3", "0"], ["83960.2", "0.178599"], ["83959.5", "0"], ["83959.4", "0"], ["83959", "0.023813"], ["83958.2", "0"], ["83958", "0.000208"], ["83957.9", "0.178599"], ["83957.1", "0"], ["83956.6", "0"], ["83956.2", "0"], ["83956.1", "0"], ["83956", "0.178599"], ["83955.7", "0.044031"], ["83955.4", "0.039629"], ["83954.2", "0.024346"], ["83953.8", "0.011912"], ["83953", "0"], ["83952.9", "0.01288"], ["83952.8", "0.01288"], ["83952.4", "0"], ["83952.3", "0"], ["83949.9", "0.023811"], ["83949.8", "0.05"], ["83949.6", "0.049634"], ["83948.8", "0.023813"], ["83948.6", "0.125019"], ["83948.5", "0.000524"], ["83946.8", "0.023812"], ["83946.1", "0"], ["83945.3", "0.125019"], ["83943.4", "0"], ["83943", "0.023813"], ["83942.3", "0.30131"], ["83941.9", "0"], ["83939.7", "0"], ["83938.1", "0"], ["83938", "0.023813"], ["83937.2", "0.132956"], ["83934.5", "0"], ["83928.8", "0"], ["83927.7", "0.125019"], ["83926.8", "0.357405"], ["83925.4", "0.000522"], ["83924.5", "0.118835"], ["83924.4", "0.000263"], ["83924.3", "0.125019"], ["83924", "0.000333"], ["83923.3", "0.001333"], ["83922.5", "5.142228"], ["83922.3", "0.011994"], ["83922.2", "0.004327"], ["83921.8", "0.000149"], ["83921.6", "0.001466"], ["83920.8", "0.000522"], ["83919.8", "0.000333"], ["83919.7", "0.224383"], ["83919.3", "0.011859"], ["83919.1", "0.001333"], ["83919", "0.011994"], ["83918.8", "0.118835"], ["83918", "0.004327"], ["83916.9", "0.001466"], ["83916.5", "0.027903"], ["83916.2", "0.011994"], ["83916.1", "0.000522"], ["83916", "0.00009"], ["83915.9", "0.059399"], ["83915.8", "0.089099"], ["83915.6", "0.000333"], ["83915.5", "0.00036"], ["83915", "0.011994"], ["83914.9", "0.001333"], ["83914.6", "0.011994"], ["83913.8", "0.016124"], ["83913.5", "0.118835"]], "a": [["83987", "0.576238"], ["83987.1", "0.275258"], ["83988.3", "0.124216"], ["83988.4", "0.292198"], ["83991.6", "0.121855"], ["83991.7", "0.050035"], ["83992.1", "0.000999"], ["83993.5", "0.004331"], ["83994.3", "0.071467"], ["83994.5", "0.03168"], ["83994.6", "0.001857"], ["83995.3", "0.036853"], ["83995.4", "0.060865"], ["83995.5", "0.089701"], ["83996.1", "0"], ["83996.2", "0.02651"], ["83997.2", "0.071555"], ["83997.7", "0.004331"], ["83997.8", "0.050035"], ["83998.4", "0.024536"], ["83998.8", "0.222368"], ["83999.3", "0.000524"], ["83999.5", "0.000333"], ["84000.1", "0.115275"], ["84000.2", "0"], ["84000.9", "0.04"], ["84001", "0"], ["84002", "0.050035"], ["84002.2", "0"], ["84002.6", "0.036802"], ["84002.8", "0"], ["84003.3", "0.178599"], ["84004.8", "0.038456"], ["84005", "0.185116"], ["84005.1", "0.04"], ["84005.3", "0"], ["84005.7", "0.04"], ["84006", "0.04"], ["84006.4", "0.178599"], ["84006.8", "0"], ["84007", "0"], ["84007.1", "0"], ["84007.6", "0.255877"], ["84008", "0"], ["84008.3", "0.125019"], ["84010.3", "0.004331"], ["84011.2", "0"], ["84011.3", "0"], ["84011.6", "0.125019"], ["84012.8", "0"], ["84013.6", "0"], ["84014.8", "0"], ["84016.6", "0.118996"], ["84017.3", "0"], ["84019.1", "0.532897"], ["84021", "0.060725"], ["84022.6", "0"], ["84024.7", "0.006286"], ["84025.2", "0.023813"], ["84025.3", "0.0005"], ["84025.8", "0.295064"], ["84026.9", "0.018"], ["84027.6", "0.05136"], ["84028.3", "0.023813"], ["84028.6", "0.357405"], ["84028.9", "1.428066"], ["84029.3", "0.023813"], ["84030.3", "0.022831"], ["84032.6", "0.125019"], ["84034.1", "0.023813"], ["84035.1", "0"], ["84036.1", "0"], ["84036.3", "0"], ["84037.4", "0.000333"], ["84038.7", "0.023811"], ["84038.8", "0"], ["84039.1", "0.098665"], ["84040", "0.023347"], ["84044.4", "0"], ["84045.4", "0"], ["84047.2", "0"], ["84047.5", "0"], ["84050.4", "0"], ["84053.5", "0.001333"], ["84056.5", "0.004156"], ["84059", "0.000204"], ["84061.9", "0"], ["84062", "0"], ["84062.1", "0"], ["84062.6", "0"], ["84062.8", "0"], ["84063.1", "0"], ["84064", "0"], ["84064.1", "0"], ["84064.4", "0"], ["84064.6", "0"], ["84064.8", "0"], ["84064.9", "0"], ["84066.1", "0"], ["84066.4", "0"]], "u": 128716, "seq": 67571255072}, "cts": 1742577042317, "record_time": 1742577042.833169, "EXCHANGE": "BYBIT"}
{"topic": "orderbook.200.BTCUSDT", "ts": 1742577042520, "type": "delta", "data": {"s": "BTCUSDT", "b": [["83986.9", "0.007768"], ["83983.8", "0.0003"], ["83983.1", "0.005747"], ["83982.8", "0.001763"], ["83980.2", "0.022991"], ["83976", "0.034488"], ["83975", "0.044"], ["83974.8", "0.04009"], ["83973.8", "0.104354"], ["83973.7", "0.071485"], ["83973.3", "0.048"], ["83971.4", "0.024343"], ["83970.9", "0.071487"], ["83969.9", "0.044"], ["83965.1", "0.06175"], ["83964.6", "0.178599"], ["83963", "0.114049"], ["83960.2", "0.183363"], ["83958.1", "0.05984"], ["83957.9", "0"], ["83955.7", "0.004402"], ["83955.4", "0"], ["83955.2", "0.039629"], ["83955.1", "0.03963"], ["83952.9", "0"], ["83952.7", "0.01288"], ["83951.1", "0.117465"], ["83949.8", "0"], ["83949.6", "0.00009"], ["83949.5", "0.049544"], ["83949.4", "0.049544"], ["83943.4", "0.0893"], ["83942.8", "0"], ["83940", "0.134464"], ["83939.4", "0"], ["83937.2", "0"], ["83935.3", "0.357391"], ["83934.3", "0"], ["83928.1", "5.142228"], ["83926.8", "0"], ["83922.5", "0"], ["83922.4", "0.0893"], ["83918", "0"], ["83916.9", "0"], ["83916.5", "0"], ["83916.2", "0"], ["83916.1", "0"], ["83916", "0"], ["83915.9", "0"], ["83915.8", "0"], ["83915.6", "0"], ["83915.5", "0"], ["83915", "0"], ["83914.9", "0"], ["83914.6", "0"], ["83913.8", "0"], ["83913.5", "0"]], "a": [["83987", "0.636041"], ["83988.5", "0.000215"], ["83990.8", "0.006166"], ["83993.7", "0.024664"], ["83994.5", "0.05819"], ["83995.3", "0.078543"], ["83995.5", "0.08357"], ["83996", "0.138222"], ["83996.2", "0.07414"], ["83997.9", "0.036994"], ["83998.4", "0"], ["83999.1", "0.04"], ["83999.2", "0.04"], ["84000", "0.039"], ["84000.1", "0.112131"], ["84000.7", "0.04"], ["84002.6", "0"], ["84003.3", "0"], ["84004.8", "0"], ["84004.9", "0.040423"], ["84005", "0.284487"], ["84005.9", "0"], ["84006.4", "0"], ["84006.9", "0"], ["84007.1", "0.054426"], ["84010", "0"], ["84010.6", "0"], ["84011.7", "0"], ["84013.3", "0"], ["84013.5", "0.04115"], ["84014.1", "0.112874"], ["84016.7", "0.171"], ["84028.6", "0"], ["84034.9", "0.357389"], ["84061.2", "0"]], "u": 128717, "seq": 67571255296}, "cts": 1742577042511, "record_time": 1742577042.835169, "EXCHANGE": "BYBIT"}
{"topic": "orderbook.200.BTCUSDT", "ts": 1742577042719, "type": "delta", "data": {"s": "BTCUSDT", "b": [["83986.9", "0.002635"], ["83983.8", "0.071776"], ["83982.8", "0"], ["83977.9", "0"], ["83977.2", "0"], ["83975", "0"], ["83974.8", "0.00009"], ["83973.8", "0.069949"], ["83973.6", "0.001333"], ["83973.3", "0"], ["83973.1", "0"], ["83972.3", "0.007029"], ["83971.5", "0"], ["83971.4", "0"], ["83970.8", "0.032716"], ["83969.9", "0"], ["83969.5", "0.053672"], ["83968.5", "0.003981"], ["83968.3", "0.004403"], ["83968.2", "0"], ["83968.1", "0"], ["83967.8", "0.056"], ["83965.7", "0.250234"], ["83965.1", "0"], ["83964.6", "0"], ["83964.5", "0.044"], ["83963", "0"], ["83962.7", "0.048"], ["83961.5", "0.114049"], ["83960.9", "0"], ["83960.2", "0"], ["83959.3", "0.059399"], ["83959", "0"], ["83958.1", "0"], ["83957.9", "0.178599"], ["83956", "0"], ["83955.2", "0"], ["83955.1", "0"], ["83954.2", "0"], ["83953.1", "0.040155"], ["83953", "0.039632"], ["83952.8", "0"], ["83952.7", "0"], ["83951.6", "0.119066"], ["83951.1", "0"], ["83950.7", "0.012881"], ["83950.6", "0.012881"], ["83949.5", "0"], ["83949.4", "0"], ["83948.6", "0"], ["83947.4", "0.168381"], ["83947.3", "0.053942"], ["83944.9", "0.009225"], ["83943.4", "0"], ["83941.9", "0.178599"], ["83941.3", "0"], ["83940", "0.134473"], ["83936.3", "0.357394"], ["83936.2", "0"], ["83935.3", "0"], ["83928.1", "0"], ["83924.6", "0.0025"], ["83922.5", "5.142228"], ["83918", "0.004327"], ["83916.9", "0.001466"], ["83916.2", "0.011994"], ["83916.1", "0.000522"], ["83916", "0.00009"], ["83915.9", "0.059399"], ["83915.8", "0.089099"], ["83915.6", "0.000333"], ["83915.5", "0.00036"], ["83915", "0.011994"], ["83914.9", "0.001333"], ["83914.6", "0.011994"], ["83913.8", "0.016124"], ["83913.5", "0.118835"], ["83912.6", "0.035555"], ["83912.3", "0.121466"]], "a": [["83987", "0.648653"], ["83987.1", "0.346731"], ["83988.3", "0.089574"], ["83991.6", "0.121455"], ["83993.2", "0.023666"], ["83994.6", "0.00564"], ["83995.5", "0.069373"], ["83996", "0.263666"], ["83998.3", "0.178599"], ["84000.1", "0.134547"], ["84001.2", "0.04"], ["84001.9", "0.123398"], ["84002.2", "0.04"], ["84002.6", "0.04"], ["84004.9", "0"], ["84006.1", "0.004332"], ["84007.1", "0"], ["84007.8", "0"], ["84009.2", "0"], ["84009.4", "0.045359"], ["84009.6", "0"], ["84011.6", "0"], ["84011.8", "0.023813"], ["84014.1", "0"], ["84022", "0"], ["84022.5", "0.297595"], ["84028.7", "0"], ["84030.3", "0"], ["84033", "2.612733"], ["84034.8", "0.357394"], ["84034.9", "0"], ["84039.1", "0.075135"], ["84061.2", "0.015"], ["84061.9", "0.001333"], ["84062", "1.785826"]], "u": 128718, "seq": 67571255580}, "cts": 1742577042717, "record_time": 1742577042.908697, "EXCHANGE": "BYBIT"}
{"topic": "orderbook.200.BTCUSDT", "ts": 1742577042919, "type": "delta", "data": {"s": "BTCUSDT", "b": [["83986.9", "0.005611"], ["83973.8", "0.05385"], ["83971", "0.071487"], ["83970.9", "0"], ["83969.7", "0.044"], ["83969.5", "0.119357"], ["83968", "0.048"], ["83966.2", "0.044"], ["83966.1", "0.044"], ["83964.4", "0.048"], ["83962.9", "0.044"], ["83956.7", "0"], ["83956", "0.178599"], ["83953.1", "0.000524"], ["83953", "0"], ["83952.8", "0.039632"], ["83952.7", "0.039632"], ["83952", "0.403393"], ["83951.8", "0.178599"], ["83950.7", "0"], ["83950.6", "0"], ["83950.4", "0.012881"], ["83950.3", "0.012881"], ["83947.6", "0.023152"], ["83947.4", "0.118835"], ["83947.3", "0.004396"], ["83947.1", "0.049546"], ["83947", "0.049547"], ["83940", "0.134448"], ["83939.6", "0"], ["83937.9", "0.000086"], ["83937.7", "0"], ["83936.4", "0.357392"], ["83936.3", "0"], ["83925.3", "5.473007"], ["83922.5", "0"], ["83918.3", "0.171"], ["83915.8", "0"], ["83915.6", "0"], ["83915.5", "0"], ["83915", "0"], ["83914.9", "0"], ["83914.6", "0"], ["83913.8", "0"], ["83913.5", "0"], ["83912.6", "0"], ["83912.3", "0"]], "a": [["83995.4", "0.080865"], ["83998", "0.178599"], ["84002.2", "0.218599"], ["84003.9", "0.000524"], ["84005", "0.185116"], ["84009.4", "0"], ["84014.4", "0"], ["84032.9", "0.022919"], ["84033", "2.61267"], ["84034.8", "0"], ["84035.3", "0.357392"]], "u": 128719, "seq": 67571255811}, "cts": 1742577042914, "record_time": 1742577043.109293, "EXCHANGE": "BYBIT"}
{"topic": "orderbook.200.BTCUSDT", "ts": 1742577043120, "type": "delta", "data": {"s": "BTCUSDT", "b": [["83986.9", "0.006396"], ["83977.8", "0.06671"], ["83975.8", "0.071483"], ["83973.8", "0.085777"], ["83972.3", "0.001466"], ["83971.1", "0.118996"], ["83971", "0"], ["83970.7", "0.12264"], ["83965.8", "0.118996"], ["83960.9", "0.185357"], ["83956.6", "0.005611"], ["83952.8", "0"], ["83952.7", "0"], ["83951.9", "0.039633"], ["83951.8", "0.325878"], ["83950.4", "0"], ["83950.3", "0"], ["83949.5", "0.012881"], ["83949.4", "0.012881"], ["83947.1", "0"], ["83947", "0"], ["83946.2", "0.049548"], ["83946.1", "0.049548"], ["83946", "0.003"], ["83943.4", "0.0893"], ["83936.5", "0.357391"], ["83936.4", "0"], ["83930.8", "5.474473"], ["83925.3", "0"], ["83916.9", "0"], ["83916.2", "0"], ["83916.1", "0"], ["83916", "0"], ["83915.9", "0"]], "a": [["83987.1", "0.349731"], ["83995.9", "0.112827"], ["84005.7", "0.224801"], ["84011.9", "0.003576"], ["84014.8", "0.276594"], ["84016.6", "0"], ["84027.4", "2.701961"], ["84027.6", "0.051357"], ["84033", "0"], ["84035.2", "0.357391"], ["84035.3", "0"], ["84045.2", "0.063808"], ["84062", "0"]], "u": 128720, "seq": 67571255989}, "cts": 1742577043117, "record_time": 1742577043.309275, "EXCHANGE": "BYBIT"}
{"topic": "orderbook.200.BTCUSDT", "ts": 1742577043319, "type": "delta", "data": {"s": "BTCUSDT", "b": [["83986.9", "0.003215"], ["83983.8", "0"], ["83983.5", "0.071476"], ["83977.8", "0.001333"], ["83977.7", "0"], ["83975.8", "0"], ["83971.2", "0.071487"], ["83970.7", "0"], ["83970.4", "0.023947"], ["83962.1", "0.178599"], ["83961.5", "0"], ["83960.9", "0"], ["83958.3", "0.001189"], ["83951.9", "0"], ["83951.8", "0"], ["83951.7", "0.039633"], ["83951.6", "0.158699"], ["83949.5", "0"], ["83949.4", "0"], ["83949.3", "0.014347"], ["83949.2", "0.013214"], ["83948.6", "0.125019"], ["83947.5", "0.202773"], ["83946.2", "0"], ["83946.1", "0"], ["83946", "0.052548"], ["83945.9", "0.049548"], ["83941.9", "0"], ["83936.5", "0"], ["83935.3", "0.357393"], ["83916.9", "0.001466"], ["83916.2", "0.011994"], ["83916.1", "0.000522"], ["83916", "0.00009"]], "a": [["83987", "0.724247"], ["83988.3", "0"], ["83991.1", "0.000333"], ["83995.9", "0"], ["84004.9", "0.178599"], ["84005", "0.254058"], ["84005.7", "0.04"], ["84014.8", "0"], ["84022.5", "0.118996"], ["84025.7", "1.503505"], ["84034.9", "0.357393"], ["84035.2", "0"], ["84035.6", "0"], ["84062", "1.785826"], ["84062.6", "0.000333"]], "u": 128721, "seq": 67571256218}, "cts": 1742577043313, "record_time": 1742577043.508422, "EXCHANGE": "BYBIT"}
{"topic": "orderbook.200.BTCUSDT", "ts": 1742577043520, "type": "delta", "data": {"s": "BTCUSDT", "b": [["83986.9", "0"], ["83986.5", "0.004895"], ["83983.5", "0"], ["83978.5", "0.000333"], ["83978.2", "0.020657"], ["83978.1", "0.02"], ["83975.7", "0.0006"], ["83973", "0.001"], ["83972", "0.005624"], ["83971.2", "0"], ["83971", "0.071487"], ["83961.3", "0.312714"], ["83954.9", "0"], ["83951.8", "0.178599"], ["83951.6", "0.158698"], ["83947", "0.0016"], ["83946", "0.052547"], ["83945.9", "0.049547"], ["83935.4", "0.358862"], ["83935.3", "0"], ["83916.2", "0"], ["83916.1", "0"], ["83916", "0"]], "a": [["83986.6", "0.745834"], ["83986.9", "0.205535"], ["83987", "0.1718"], ["83988.3", "0.0001"], ["83988.4", "0.121198"], ["84002.9", "0"], ["84005.6", "0.004853"], ["84015.5", "0"], ["84017", "0.0016"], ["84028.5", "1.427733"], ["84028.9", "0.000333"], ["84031.6", "0.012435"], ["84034.8", "0.357396"], ["84034.9", "0"], ["84051.8", "1.067938"], ["84061.9", "0"], ["84062", "0"], ["84062.6", "0"]], "u": 128722, "seq": 67571256525}, "cts": 1742577043516, "record_time": 1742577043.709568, "EXCHANGE": "BYBIT"}
{"topic": "orderbook.200.BTCUSDT", "ts": 1742577043719, "type": "delta", "data": {"s": "BTCUSDT", "b": [["83983.7", "0.0003"], ["83970.4", "0"], ["83970", "0.099266"], ["83969.5", "0.04"], ["83964.6", "0.121998"], ["83957.6", "0.169676"], ["83956.6", "0.004895"], ["83951.7", "0"], ["83951.5", "0.04403"], ["83950.6", "0.303886"], ["83949.3", "0.001466"], ["83949.1", "0.012881"], ["83946", "0.003"], ["83945.8", "0.049548"], ["83935.4", "0.001466"], ["83934.7", "0.361787"], ["83918.8", "0"], ["83918.3", "0"], ["83918", "0"], ["83916.9", "0"]], "a": [["83986.6", "0.736609"], ["83986.9", "0.188395"], ["83991.8", "0.009225"], ["83995", "0.02"], ["83995.4", "0.060865"], ["83997.5", "0.115703"], ["84000.1", "0.221112"], ["84004.5", "0.182066"], ["84011.5", "0.286129"], ["84025.8", "0.335064"], ["84025.9", "0.04"], ["84034.8", "0"], ["84035.3", "0.357396"], ["84051.8", "1.027938"], ["84051.9", "0"], ["84059.9", "0"], ["84060", "0"], ["84060.1", "0"], ["84060.7", "0"], ["84061.2", "0"]], "u": 128723, "seq": 67571256760}, "cts": 1742577043716, "record_time": 1742577043.909081, "EXCHANGE": "BYBIT"}
{"topic": "orderbook.200.BTCUSDT", "ts": 1742577043920, "type": "delta", "data": {"s": "BTCUSDT", "b": [["83986.5", "0"], ["83978.1", "0"], ["83977.8", "0.021333"], ["83972", "0"], ["83964.6", "0"], ["83957.6", "0.000333"], ["83951.5", "0.044029"], ["83950.6", "0"], ["83945.8", "0.049547"], ["83940", "0.134436"], ["83935.3", "0.357393"], ["83934.7", "0.00439"], ["83930.8", "5.629723"], ["83918.8", "0.118835"], ["83918", "0.004327"], ["83916.9", "0.001466"], ["83916.2", "0.011994"]], "a": [["83986.3", "0.591303"], ["83986.5", "0.291622"], ["83986.6", "0.305232"], ["83986.9", "0"], ["83987", "0.0008"], ["83991.8", "0"], ["83997.5", "0"], ["84004.5", "0"], ["84011.5", "0"], ["84027.6", "0.051358"], ["84028.2", "1.429066"], ["84028.5", "0"], ["84035.3", "0"], ["84036.4", "0.113406"], ["84038.9", "0.357393"], ["84059.9", "0.118996"], ["84060", "0.00024"], ["84060.1", "0.892465"], ["84060.7", "0.004156"]], "u": 128724, "seq": 67571257052}, "cts": 1742577043917, "record_time": 1742577044.10905, "EXCHANGE": "BYBIT"}
{"topic": "orderbook.200.BTCUSDT", "ts": 1742577044120, "type": "delta", "data": {"s": "BTCUSDT", "b": [["83986.2", "0"], ["83985.4", "0"], ["83985.2", "0.07126"], ["83983.1", "0"], ["83981.4", "0.005747"], ["83978.2", "0.03952"], ["83977.8", "0.001333"], ["83976.8", "0.02"], ["83976.4", "0.071482"], ["83973.1", "0.001"], ["83971", "0"], ["83967.1", "0.023485"], ["83956.6", "0"], ["83951.6", "0.119066"], ["83951.5", "0.044028"], ["83951.4", "0.039631"], ["83949.2", "0.000333"], ["83949.1", "0.013"], ["83949", "0.012881"], ["83945.9", "0"], ["83945.8", "0.049546"], ["83945.7", "0.049546"], ["83940", "0.134435"], ["83936", "0.357392"], ["83935.3", "0"], ["83918", "0"], ["83916.9", "0"], ["83916.2", "0"]], "a": [["83985.3", "0.748132"], ["83986.2", "0.273893"], ["83986.3", "0.171"], ["83986.5", "0"], ["83986.6", "0.120035"], ["83987.1", "0.278258"], ["83988.5", "0"], ["83989.3", "0.006166"], ["83990", "0.000524"], ["83990.4", "0.001333"], ["83990.8", "0.001466"], ["83993.2", "0"], ["83994", "0.02399"], ["84001.4", "0.001503"], ["84007.6", "0.221035"], ["84011.9", "0"], ["84027.2", "1.427733"], ["84027.6", "0.051355"], ["84028.2", "0.001333"], ["84035.4", "0"], ["84060", "0"], ["84060.1", "0"], ["84060.7", "0"]], "u": 128725, "seq": 67571257417}, "cts": 1742577044111, "record_time": 1742577044.310519, "EXCHANGE": "BYBIT"}
{"topic": "orderbook.200.BTCUSDT", "ts": 1742577044319, "type": "delta", "data": {"s": "BTCUSDT", "b": [["83985.2", "0.069481"], ["83971.9", "0.005536"], ["83957.9", "0"], ["83955.6", "0.035728"], ["83953.6", "0.329138"], ["83951.8", "0"], ["83951.5", "0.004397"], ["83951.4", "0"], ["83951.3", "0.039632"], ["83951.2", "0.039632"], ["83949.1", "0"], ["83949", "0"], ["83948.9", "0.012881"], ["83948.8", "0.036694"], ["83945.8", "0"], ["83945.7", "0.05"], ["83945.6", "0.049546"]], "a": [["83985.3", "0.676657"], ["83986.2", "0.184354"], ["83987.7", "0.071473"], ["83994", "0"], ["83994.3", "0"], ["83994.8", "0.023349"], ["84000", "0.110462"], ["84001.4", "0"], ["84004.8", "0.21731"], ["84005", "0.059399"], ["84025.8", "0.295064"], ["84025.9", "0"], ["84026.4", "0.04"], ["84026.5", "0.04"], ["84038.9", "0.357388"], ["84039.2", "0.059489"], ["84059.9", "0"]], "u": 128726, "seq": 67571257573}, "cts": 1742577044315, "record_time": 1742577044.509228, "EXCHANGE": "BYBIT"}
{"topic": "orderbook.200.BTCUSDT", "ts": 1742577044519, "type": "delta", "data": {"s": "BTCUSDT", "b": [["83985.2", "0"], ["83985.1", "0"], ["83983.7", "0.002696"], ["83981.4", "0"], ["83981", "0.071479"], ["83980.2", "0"], ["83979.9", "0.005747"], ["83978.2", "0"], ["83977.1", "0.032599"], ["83977", "0.024458"], ["83976.8", "0.052635"], ["83976.7", "0.009404"], ["83976.4", "0"], ["83976", "0"], ["83975.3", "0.015"], ["83973.7", "0"], ["83972.8", "0.03449"], ["83971.9", "0"], ["83971.5", "0.071487"], ["83968.7", "0.071489"], ["83966.9", "0.120484"], ["83962.1", "0"], ["83958.3", "0"], ["83957.7", "0.001425"], ["83957.1", "0.178553"], ["83956", "0"], ["83954.5", "0.178606"], ["83951.3", "0"], ["83951.1", "0.03963"], ["83948.9", "0"], ["83948.7", "0.01288"], ["83945.7", "0"], ["83945.6", "0"], ["83945.5", "0.403196"], ["83945.4", "0.049545"], ["83945.3", "0"], ["83943.4", "0"], ["83936", "0"], ["83930.9", "0.357407"], ["83930.8", "0.001466"], ["83925.3", "5.628257"], ["83922.4", "0"], ["83918", "0.004327"], ["83916.9", "0.001466"], ["83916.2", "0.011994"], ["83916.1", "0.000522"], ["83916", "0.00009"], ["83915.9", "0.059399"]], "a": [["83983.8", "0.909896"], ["83985.1", "0.164065"], ["83985.2", "0.23065"], ["83985.3", "0.08503"], ["83986.2", "0"], ["83986.3", "0"], ["83986.6", "0.020035"], ["83987.6", "0.006166"], ["83987.7", "0.000999"], ["83988.3", "0.046253"], ["83989.3", "0.004323"], ["83990.5", "0.024665"], ["83992.1", "0.119095"], ["83992.8", "0.071469"], ["83993.6", "0.105325"], ["83993.7", "0.02"], ["83994.7", "0.036995"], ["83995", "0"], ["83997.9", "0"], ["84000", "0.039"], ["84011", "0.311538"], ["84019", "0.160441"], ["84024.7", "2.619009"], ["84025.7", "2.931238"], ["84027.2", "0"], ["84027.4", "0.089291"], ["84032.5", "0.357407"], ["84034.6", "0.003365"], ["84038.9", "0"], ["84058.4", "0"], ["84058.5", "0"], ["84059", "0"], ["84059.3", "0"], ["84059.7", "0"], ["84059.8", "0"]], "u": 128727, "seq": 67571258083}, "cts": 1742577044517, "record_time": 1742577044.709187, "EXCHANGE": "BYBIT"}
{"topic": "orderbook.200.BTCUSDT", "ts": 1742577044720, "type": "delta", "data": {"s": "BTCUSDT", "b": [["83983.7", "0"], ["83982.7", "0"], ["83982.2", "0.076269"], ["83981", "0"], ["83979.9", "0"], ["83978.4", "0.005748"], ["83977.1", "0"], ["83976.7", "0.004404"], ["83975.3", "0"], ["83974.1", "0.002381"], ["83973.8", "0.105777"], ["83970", "0.163338"], ["83967.1", "0"], ["83966.9", "0.000524"], ["83965.5", "0.52031"], ["83959.6", "0"], ["83957.7", "0.000524"], ["83957.3", "0.000839"], ["83957.1", "0"], ["83956.1", "0.003575"], ["83955.6", "0"], ["83951.2", "0"], ["83951.1", "0"], ["83950.7", "0.039629"], ["83950.6", "0.039629"], ["83948.8", "0.023813"], ["83948.7", "0"], ["83948.3", "0.01288"], ["83948.2", "0.01288"], ["83946.3", "0"], ["83945.5", "0.35365"], ["83945.4", "0"], ["83945", "0.049876"], ["83944.9", "0.058769"], ["83943.8", "0.097017"], ["83931", "0.357404"], ["83930.9", "0"], ["83930.8", "0.180072"], ["83930.2", "0.178606"], ["83926.6", "0.238005"], ["83919.7", "0"], ["83918.3", "0.171"], ["83915.8", "0.089099"], ["83915.6", "0.000333"], ["83915.5", "0.00036"], ["83915", "0.011994"], ["83914.9", "0.001333"]], "a": [["83982.3", "0.627409"], ["83983.6", "0.214559"], ["83983.8", "0.406393"], ["83985.1", "0"], ["83985.2", "0"], ["83985.3", "0.084877"], ["83986.1", "0.006166"], ["83986.9", "0.000333"], ["83987.6", "0"], ["83989.4", "0.009225"], ["83992.1", "0.000999"], ["83994.5", "0"], ["83995.3", "0.000333"], ["83996.2", "0"], ["84000.7", "0.08"], ["84003.4", "0.003576"], ["84004.4", "0"], ["84005.1", "0"], ["84011", "0"], ["84024.2", "1.427733"], ["84024.8", "0.051355"], ["84025.7", "0.137531"], ["84027.6", "0"], ["84032.5", "0"], ["84034.6", "0"], ["84034.9", "0.357399"], ["84041.8", "0.011994"], ["84058.4", "0.000333"]], "u": 128728, "seq": 67571258602}, "cts": 1742577044717, "record_time": 1742577044.909976, "EXCHANGE": "BYBIT"}
{"topic": "orderbook.200.BTCUSDT", "ts": 1742577044919, "type": "delta", "data": {"s": "BTCUSDT", "b": [["83982.2", "0.005092"], ["83980.9", "0.075894"], ["83974.1", "0"], ["83974", "0.002382"], ["83973.8", "0.066311"], ["83971.1", "0.005475"], ["83970", "0.153564"], ["83968.7", "0"], ["83968.6", "0.071489"], ["83955", "0.035729"], ["83931.1", "0.3574"], ["83931", "0"], ["83930.8", "5.971395"], ["83925.3", "0"]], "a": [["83982.3", "0.627562"], ["83982.5", "0.071477"], ["83983.8", "0.334917"], ["83988.3", "0.140947"], ["83989.8", "0.05819"], ["83990.6", "0.07821"], ["83991.5", "0.07414"], ["84004.4", "0.005485"], ["84024.7", "2.619102"], ["84032.5", "0.357405"], ["84034.9", "0"], ["84056.7", "0"], ["84057.7", "0"], ["84058.1", "0"], ["84058.2", "0"], ["84058.4", "0"]], "u": 128729, "seq": 67571258894}, "cts": 1742577044914, "record_time": 1742577045.109364, "EXCHANGE": "BYBIT"}
{"topic": "orderbook.200.BTCUSDT", "ts": 1742577045120, "type": "delta", "data": {"s": "BTCUSDT", "b": [["83982.2", "0.07657"], ["83980.9", "0.004415"], ["83974.1", "0.097048"], ["83974", "0.071484"], ["83973.8", "0.02"], ["83971.6", "0.11952"], ["83970", "0.099266"], ["83968.6", "0"], ["83964.5", "0.068276"], ["83946.8", "0.028437"], ["83946", "0"], ["83940", "0.134429"], ["83934.7", "0.361788"], ["83933.6", "0.014084"], ["83931.1", "0"], ["83914.6", "0.011994"]], "a": [["83982.3", "0.627409"], ["83982.5", "0"], ["83983.7", "0.071476"], ["83989.4", "0"], ["83997", "0.009225"], ["84024.8", "0.051357"], ["84028", "0.000118"], ["84032.5", "0"], ["84034.9", "0.357403"], ["84050", "0.000333"], ["84056.6", "0"]], "u": 128730, "seq": 67571259067}, "cts": 1742577045117, "record_time": 1742577045.309357, "EXCHANGE": "BYBIT"}
{"topic": "orderbook.200.BTCUSDT", "ts": 1742577045320, "type": "delta", "data": {"s": "BTCUSDT", "b": [["83982.2", "0.072578"], ["83971.9", "0.002381"], ["83955", "0"], ["83954.5", "0"], ["83953", "0.023815"], ["83950.7", "0"], ["83950.6", "0"], ["83949.4", "0.03963"], ["83949.3", "0.041097"], ["83948.3", "0"], ["83948.2", "0"], ["83947", "0.01448"], ["83946.9", "0.01288"], ["83945", "0.000333"], ["83944.9", "0.009225"], ["83943.7", "0.220545"], ["83943.6", "0.049545"], ["83936", "0.357391"], ["83934.7", "0.00439"]], "a": [["83982.3", "0.636841"], ["83983.5", "0.005956"], ["83983.7", "0"], ["83983.8", "0.32072"], ["83984.8", "0.071475"], ["83990.7", "0.02"], ["83993.7", "0"], ["83994.3", "0.039"], ["84000", "0"], ["84001.5", "0.04"], ["84011.8", "0"], ["84013", "0"], ["84015.2", "0"], ["84024.7", "2.618764"], ["84032.9", "0"], ["84034.9", "0"], ["84036.3", "0.357391"], ["84041.5", "0.022863"], ["84056.6", "0.000366"]], "u": 128731, "seq": 67571259247}, "cts": 1742577045314, "record_time": 1742577045.509718, "EXCHANGE": "BYBIT"}
{"topic": "orderbook.200.BTCUSDT", "ts": 1742577045519, "type": "delta", "data": {"s": "BTCUSDT", "b": [["83977.1", "0.026599"], ["83972.1", "0.002383"], ["83971.9", "0"], ["83957", "0.178609"], ["83954", "0.035729"], ["83949.4", "0"], ["83949.2", "0.039964"], ["83930.8", "5.792789"], ["83930.2", "0"], ["83926.6", "0.059399"], ["83914.6", "0"]], "a": [["83983.8", "0.29072"], ["83984.8", "0"], ["83985.3", "0.054877"], ["83986.3", "0.071474"], ["83988.1", "0.0001"], ["83988.3", "0.140847"], ["83992.8", "0"], ["83994.9", "0.04"], ["83995.1", "0.071467"], ["83996.6", "0.04"], ["83999.2", "0"], ["84000.9", "0"], ["84001.6", "0.04"], ["84003.4", "0"], ["84005.7", "0"], ["84006", "0"], ["84016.8", "0.0016"], ["84017", "0"], ["84021", "1.266963"], ["84024.7", "0.006286"], ["84024.8", "0.051356"], ["84033", "2.612478"], ["84036.3", "0"], ["84038.9", "0.357389"]], "u": 128732, "seq": 67571259461}, "cts": 1742577045517, "record_time": 1742577045.709433, "EXCHANGE": "BYBIT"}
{"topic": "orderbook.200.BTCUSDT", "ts": 1742577045720, "type": "delta", "data": {"s": "BTCUSDT", "b": [["83972.9", "0.001"], ["83964.6", "0.178647"], ["83962.8", "0.187822"], ["83961.2", "0.193654"], ["83960.4", "0.178609"], ["83960.2", "0.178609"], ["83957.1", "0.072608"], ["83957", "0"], ["83956", "0.178609"], ["83952", "0.4"], ["83949.3", "0.001466"], ["83949.2", "0.040333"], ["83949.1", "0.039631"], ["83947", "0.0016"], ["83946.9", "0"], ["83946.8", "0.041437"], ["83946.7", "0.01288"], ["83943.7", "0.171"], ["83943.6", "0"], ["83943.5", "0.049545"], ["83943.4", "0.049545"], ["83940", "0.134441"], ["83936", "0.357385"], ["83930.8", "0.001466"], ["83925.3", "5.791323"], ["83922.6", "0.178736"], ["83922.4", "0.089305"], ["83916.9", "0"], ["83916.2", "0"], ["83916.1", "0"], ["83916", "0"], ["83915.9", "0"], ["83915.8", "0"], ["83915.6", "0"], ["83915.5", "0"], ["83915", "0"], ["83914.9", "0"]], "a": [["83982.3", "0.397219"], ["83983.5", "0"], ["83983.6", "0.120015"], ["83983.8", "0.099685"], ["83985.3", "0.034842"], ["83985.7", "0.000153"], ["83986.3", "0"], ["83986.6", "0"], ["83987.1", "0.228223"], ["83991.7", "0.020035"], ["83995.1", "0"], ["83996", "0.138222"], ["83997.2", "0.00009"], ["83998", "0"], ["83998.3", "0.04"], ["84000.2", "0.071462"], ["84002.2", "0.04"], ["84002.6", "0"], ["84006.4", "0.178609"], ["84010.6", "0.178609"], ["84021", "0"], ["84024.7", "2.618764"], ["84025.1", "0.04"], ["84025.2", "0.063813"], ["84026.4", "0"], ["84026.5", "0"], ["84033", "0"], ["84036.3", "0.357391"], ["84038.9", "0"], ["84056.7", "0.04"], ["84057.7", "0.001333"], ["84058.1", "0.002528"], ["84058.2", "0.000083"], ["84058.4", "0.000333"]], "u": 128733, "seq": 67571259787}, "cts": 1742577045717, "record_time": 1742577045.909567, "EXCHANGE": "BYBIT"}
{"topic": "orderbook.200.BTCUSDT", "ts": 1742577045919, "type": "delta", "data": {"s": "BTCUSDT", "b": [["83960.4", "0"], ["83949.4", "0.03963"], ["83949.3", "0.041097"], ["83949.2", "0.000333"], ["83949.1", "0"], ["83947", "0.01448"], ["83946.9", "0.01288"], ["83946.8", "0.028437"], ["83946.7", "0"], ["83945.3", "0.125026"], ["83943.7", "0.220545"], ["83943.6", "0.049545"], ["83943.5", "0"], ["83943.4", "0"], ["83940", "0.134364"], ["83936", "0"], ["83935.3", "0.357394"], ["83925.3", "0"], ["83922.5", "11.91721"], ["83922.4", "0"], ["83916.9", "0.001466"], ["83916.2", "0.011994"]], "a": [["83982.3", "0.391248"], ["83983.5", "0.005956"], ["83984.7", "0.000153"], ["83985.7", "0"], ["84000.1", "0.162602"], ["84002.2", "0.218609"], ["84010.6", "0"], ["84024.3", "0.04"], ["84024.4", "0.04"], ["84025.1", "0"], ["84025.2", "0.023813"], ["84034.9", "0.357394"], ["84036.3", "0"], ["84058.4", "0"]], "u": 128734, "seq": 67571259952}, "cts": 1742577045918, "record_time": 1742577046.108731, "EXCHANGE": "BYBIT"}
{"topic": "orderbook.200.BTCUSDT", "ts": 1742577046120, "type": "delta", "data": {"s": "BTCUSDT", "b": [["83962.1", "0.178609"], ["83960.4", "0.178609"], ["83949.4", "0"], ["83949.3", "0.001466"], ["83949.2", "0.039964"], ["83949.1", "0.039631"], ["83947", "0.0016"], ["83946.9", "0.013"], ["83946.8", "0.041317"], ["83943.7", "0.171"], ["83943.5", "0.049545"], ["83943.4", "0.089305"], ["83936", "0.35739"], ["83935.3", "0"], ["83930.8", "5.960071"], ["83922.5", "0"], ["83922.4", "0.089305"], ["83918.3", "0"], ["83918", "0"], ["83916.9", "0"], ["83916.2", "0"]], "a": [["83982.3", "0.397204"], ["83983.5", "0"], ["83983.8", "0.099838"], ["83984.7", "0"], ["83994.8", "0.063349"], ["83996.5", "0.04"], ["84003.3", "0.178609"], ["84024.3", "0"], ["84024.4", "0"], ["84024.7", "2.658764"], ["84024.8", "0.091356"], ["84034.9", "0"], ["84036.3", "0.35739"], ["84058.4", "0.000333"], ["84058.5", "0.005951"]], "u": 128735, "seq": 67571260119}, "cts": 1742577046105, "record_time": 1742577046.309713, "EXCHANGE": "BYBIT"}
{"topic": "orderbook.200.BTCUSDT", "ts": 1742577046320, "type": "delta", "data": {"s": "BTCUSDT", "b": [["83977.1", "0.044719"], ["83976.1", "0.071483"], ["83971.5", "0"], ["83962.4", "0.060188"], ["83962.1", "0"], ["83961.4", "0.481778"], ["83960.8", "0"], ["83960.4", "0"], ["83960.2", "0"], ["83957", "0.178609"], ["83956", "0"], ["83955.4", "0.058408"], ["83949.4", "0.04"], ["83949.3", "0.041097"], ["83949.2", "0.000333"], ["83949.1", "0"], ["83948.4", "0.110048"], ["83947", "0.0146"], ["83946.9", "0.01288"], ["83946.8", "0.028437"], ["83945.3", "0"], ["83943.7", "0.221"], ["83943.5", "0"], ["83943.4", "0"], ["83936", "0"], ["83934.7", "0.361785"], ["83930.8", "6.13868"], ["83930.2", "0.178609"], ["83926.6", "0.238008"], ["83922.4", "0"], ["83918", "0.004327"], ["83916.9", "0.001466"], ["83916.2", "0.011994"], ["83916.1", "0.000522"], ["83916", "0.00009"]], "a": [["83983.8", "0.099685"], ["83985.9", "0.071474"], ["83992.1", "0"], ["83995.7", "0.071466"], ["83997.4", "0.056816"], ["83999.1", "0"], ["84000.1", "0.249625"], ["84000.7", "0.04"], ["84004.4", "0.060053"], ["84010.6", "0.178609"], ["84011.4", "0.112671"], ["84024.5", "0.04"], ["84024.6", "0.04"], ["84024.7", "2.618764"], ["84024.8", "0.051356"], ["84034.9", "0.357397"], ["84036.3", "0"], ["84058.1", "0"], ["84058.2", "0"], ["84058.4", "0"], ["84058.5", "0"]], "u": 128736, "seq": 67571260304}, "cts": 1742577046316, "record_time": 1742577046.509993, "EXCHANGE": "BYBIT"}
{"topic": "orderbook.200.BTCUSDT", "ts": 1742577046520, "type": "delta", "data": {"s": "BTCUSDT", "b": [["83982.2", "0.243578"], ["83962.4", "0"], ["83960.4", "0.178609"], ["83960.2", "0.178609"], ["83957", "0"], ["83956", "0.178609"], ["83955.4", "0"], ["83949.4", "0.03963"], ["83948.4", "0.001333"], ["83947", "0.01448"], ["83945.3", "0.125026"], ["83943.7", "0.220545"], ["83942.9", "0.132875"], ["83940", "0.001526"], ["83936", "0.35739"], ["83934.7", "0.00439"], ["83930.8", "5.960071"], ["83930.2", "0"], ["83926.6", "0.059399"], ["83918.3", "0.171"], ["83916.2", "0"], ["83916.1", "0"], ["83916", "0"]], "a": [["83982.3", "0.242177"], ["83985.2", "0.005956"], ["83985.9", "0"], ["83987.3", "0.071473"], ["83997.4", "0"], ["84004.4", "0.005485"], ["84011.4", "0.001333"], ["84024.1", "1.2605"], ["84034.9", "0"], ["84038.9", "0.357387"], ["84057.7", "0"]], "u": 128737, "seq": 67571260474}, "cts": 1742577046517, "record_time": 1742577046.709213, "EXCHANGE": "BYBIT"}
{"topic": "orderbook.200.BTCUSDT", "ts": 1742577046720, "type": "delta", "data": {"s": "BTCUSDT", "b": [["83982.2", "0.243647"], ["83964.6", "0.357256"], ["83949.4", "0"], ["83949.2", "0.039964"], ["83947", "0.0016"], ["83946.8", "0.041317"], ["83943.7", "0.171"], ["83943.5", "0.049545"], ["83943.4", "0.089305"], ["83922.4", "0.089305"], ["83918", "0"], ["83916.9", "0"]], "a": [["83987.3", "0"], ["83989.3", "0.075794"], ["83995.7", "0"], ["83998", "0.071464"], ["84024.5", "0"], ["84024.6", "0"], ["84025", "0.04"], ["84025.1", "0.04"], ["84057.7", "0.001333"]], "u": 128738, "seq": 67571260571}, "cts": 1742577046714, "record_time": 1742577046.909704, "EXCHANGE": "BYBIT"}
{"topic": "orderbook.200.BTCUSDT", "ts": 1742577046919, "type": "delta", "data": {"s": "BTCUSDT", "b": [["83973", "0.002"], ["83965.7", "0.353138"], ["83949.3", "0.001466"], ["83949.1", "0.039631"], ["83946.9", "0"], ["83946.7", "0.01288"], ["83943.6", "0"], ["83943.4", "0.13885"], ["83930.8", "6.189212"]], "a": [["83989.3", "0.004323"], ["83990.6", "0.14968"], ["83998", "0"], ["84002.2", "0.04"], ["84002.7", "0.07146"], ["84025", "0"], ["84025.2", "0.063813"], ["84058.1", "0.002528"]], "u": 128739, "seq": 67571260647}, "cts": 1742577046917, "record_time": 1742577047.109499, "EXCHANGE": "BYBIT"}
{"topic": "orderbook.200.BTCUSDT", "ts": 1742577047120, "type": "delta", "data": {"s": "BTCUSDT", "b": [["83943.6", "0.049545"], ["83943.4", "0.089305"], ["83918.3", "0"]], "a": [["83982.3", "0.194918"], ["83985.2", "0"], ["83986", "0.005956"], ["83989.6", "0.071471"], ["83990.6", "0.07821"], ["83998.1", "0.071464"], ["84000.2", "0"], ["84005.8", "0.178609"], ["84022.5", "0"], ["84038.9", "0.357384"], ["84040", "0.00024"], ["84058.1", "0"]], "u": 128740, "seq": 67571260755}, "cts": 1742577047116, "record_time": 1742577047.309787, "EXCHANGE": "BYBIT"}
{"topic": "orderbook.200.BTCUSDT", "ts": 1742577047319, "type": "delta", "data": {"s": "BTCUSDT", "b": [["83982.2", "0.41429"], ["83981.3", "0.089099"], ["83977.2", "0.083743"], ["83977.1", "0.118996"], ["83961.4", "0.570877"], ["83952.6", "0.024724"], ["83951.6", "0"], ["83949.2", "0.000333"], ["83949", "0.039631"], ["83947.6", "0"], ["83946.8", "0.028437"], ["83946.6", "0.01288"], ["83945.7", "0.132871"], ["83943.6", "0"], ["83943.5", "0"], ["83943.4", "0.13885"], ["83943.3", "0.049545"], ["83942.9", "0"], ["83942.4", "0.357363"], ["83936.6", "0.024999"], ["83936.4", "6.187746"], ["83936", "0"], ["83930.8", "0.001466"], ["83919", "0"], ["83918.8", "0"]], "a": [["83982.3", "0.162182"], ["83983.6", "0"], ["83983.8", "0"], ["83986", "0"], ["83987.1", "0.225223"], ["83989.6", "0"], ["83990.4", "0.007288"], ["83991.7", "0"], ["83994.1", "0.071467"], ["83994.8", "0.04"], ["83995.4", "0.001466"], ["83995.5", "0.019338"], ["83997.8", "0.020035"], ["83998.1", "0"], ["83998.8", "0.192368"], ["84004.3", "0.071459"], ["84004.9", "0"], ["84009.9", "0.178609"], ["84024.7", "0.006286"], ["84025.1", "0"], ["84025.2", "0.023813"], ["84025.9", "0.04"], ["84026", "0.04"], ["84038.5", "2.612478"], ["84038.9", "0"], ["84045.1", "0.357375"], ["84058.1", "0.002528"], ["84058.2", "0.000083"]], "u": 128741, "seq": 67571260955}, "cts": 1742577047317, "record_time": 1742577047.508787, "EXCHANGE": "BYBIT"}
{"topic": "orderbook.200.BTCUSDT", "ts": 1742577047520, "type": "delta", "data": {"s": "BTCUSDT", "b": [["83982.2", "0.417375"], ["83981.3", "0"], ["83980.9", "0.004715"], ["83975.7", "0"], ["83973", "0.001"], ["83970", "0.15245"], ["83967.8", "0.23464"], ["83966.1", "0.222644"], ["83964.6", "0.178609"], ["83962.8", "0.009171"], ["83957.3", "0"], ["83955.8", "0.119073"], ["83952.2", "0.1726"], ["83949.1", "0"], ["83948.9", "0.039631"], ["83948.5", "0.133395"], ["83947", "0"], ["83946.8", "0.041437"], ["83946.6", "0"], ["83945.7", "0"], ["83943.8", "0.000523"], ["83943.5", "0.05"], ["83943.3", "0"], ["83942.4", "0"], ["83940.5", "0.024666"], ["83939.1", "6.187746"], ["83936.6", "0.000333"], ["83936.5", "0.357367"], ["83936.4", "0"], ["83934.7", "0.029332"], ["83919", "0.011994"], ["83918.8", "0.118835"], ["83918", "0.004327"], ["83916.9", "0.001466"]], "a": [["83982.3", "0.192528"], ["83988.3", "0"], ["83992.7", "0.071469"], ["83994.1", "0"], ["83995.5", "0"], ["83996", "0.095294"], ["83997", "0.024166"], ["83997.8", "0"], ["84000.1", "0.160089"], ["84000.7", "0.111462"], ["84001.9", "0.004332"], ["84002.7", "0"], ["84002.8", "0.019338"], ["84003.3", "0"], ["84003.8", "0.05926"], ["84005.6", "0.00009"], ["84007.1", "0.035728"], ["84007.8", "0.114052"], ["84008.3", "0"], ["84018.3", "0"], ["84024.1", "0"], ["84024.8", "0"], ["84025.9", "0"], ["84026", "0"], ["84027.4", "0"], ["84027.5", "0.04"], ["84027.6", "0.091356"], ["84029.4", "0.125026"], ["84038.5", "0"], ["84039.3", "0.04"], ["84041.3", "2.612478"], ["84041.5", "0"], ["84044.3", "0.04"], ["84045.1", "0.357361"], ["84046.5", "0.024858"], ["84050.4", "0.125026"], ["84051.8", "0"], ["84058.4", "0.000333"], ["84058.5", "0.005951"], ["84059", "0.000204"], ["84059.3", "0.000524"], ["84059.7", "0.079559"]], "u": 128742, "seq": 67571261297}, "cts": 1742577047516, "record_time": 1742577047.73563, "EXCHANGE": "BYBIT"}
{"topic": "orderbook.200.BTCUSDT", "ts": 1742577047719, "type": "delta", "data": {"s": "BTCUSDT", "b": [["83982.2", "0.246375"], ["83949.2", "0.040333"], ["83949.1", "0.039631"], ["83949", "0"], ["83948.9", "0"], ["83939.2", "0.357891"], ["83936.5", "0"], ["83918.3", "0.171"], ["83916.2", "0.011994"]], "a": [["83982.3", "0.194918"], ["83988.3", "0.138542"], ["83989.7", "0.005955"], ["83990.4", "0.001333"], ["83991.5", "0.14561"], ["83991.6", "0.081927"], ["83992.7", "0"], ["83994", "0.000999"], ["84024.1", "0.43735"], ["84027.3", "0.04"], ["84027.4", "0.129305"], ["84027.5", "0"], ["84027.6", "0.051356"], ["84035.7", "2.612478"], ["84037.6", "0.061638"], ["84038.9", "0.357369"], ["84039.3", "0.08"], ["84041.3", "0"], ["84045.1", "0"], ["84053.5", "1.787425"], ["84058.5", "0"], ["84059", "0"], ["84059.3", "0"], ["84059.7", "0"]], "u": 128743, "seq": 67571261479}, "cts": 1742577047716, "record_time": 1742577047.90929, "EXCHANGE": "BYBIT"}
{"topic": "orderbook.200.BTCUSDT", "ts": 1742577047920, "type": "delta", "data": {"s": "BTCUSDT", "b": [["83941.3", "0.357368"], ["83939.2", "0.000522"], ["83939.1", "6.434075"], ["83916.2", "0"]], "a": [["84038.9", "0"], ["84044.2", "0.35737"]], "u": 128744, "seq": 67571261523}, "cts": 1742577047917, "record_time": 1742577048.112425, "EXCHANGE": "BYBIT"}
{"topic": "orderbook.200.BTCUSDT", "ts": 1742577048120, "type": "delta", "data": {"s": "BTCUSDT", "b": [["83982.2", "0.41836"], ["83973.1", "0"], ["83961.6", "0"], ["83943.9", "0.322247"], ["83941.3", "0"], ["83939.2", "0.35789"], ["83916.2", "0.011994"], ["83916.1", "0.000522"], ["83916", "0.00009"]], "a": [["83982.3", "0.196518"], ["83987", "0"], ["83988.3", "0"], ["83989.7", "0"], ["83990.4", "0.007288"], ["83991.5", "0.07414"], ["83992.9", "0.071468"], ["84057.5", "1.027868"], ["84058.5", "0.005951"]], "u": 128745, "seq": 67571261645}, "cts": 1742577048116, "record_time": 1742577048.309875, "EXCHANGE": "BYBIT"}
{"topic": "orderbook.200.BTCUSDT", "ts": 1742577048319, "type": "delta", "data": {"s": "BTCUSDT", "b": [["83939.3", "0.357369"], ["83939.2", "0.000522"], ["83916", "0"]], "a": [["84035.7", "0"], ["84038.5", "2.612478"]], "u": 128746, "seq": 67571261718}, "cts": 1742577048316, "record_time": 1742577048.508556, "EXCHANGE": "BYBIT"}
{"topic": "orderbook.200.BTCUSDT", "ts": 1742577048520, "type": "delta", "data": {"s": "BTCUSDT", "b": [["83949.4", "0.04"], ["83949.3", "0.041097"], ["83949.2", "0.000333"], ["83949.1", "0"], ["83943.7", "0.221"], ["83943.6", "0.049545"], ["83943.5", "0"], ["83943.4", "0.089305"], ["83940.5", "0"], ["83939.4", "0.35737"], ["83939.3", "0"], ["83938.5", "0.025024"], ["83916", "0.00009"]], "a": [["83990.4", "0.001333"], ["83990.5", "0.03062"], ["83994.6", "0.001857"], ["84003.2", "0.003899"], ["84026.9", "0.058"], ["84027", "0.040524"], ["84027.3", "0"], ["84027.4", "0.089305"]], "u": 128747, "seq": 67571261808}, "cts": 1742577048517, "record_time": 1742577048.709603, "EXCHANGE": "BYBIT"}
{"topic": "orderbook.200.BTCUSDT", "ts": 1742577048719, "type": "delta", "data": {"s": "BTCUSDT", "b": [["83948.5", "0.133378"], ["83947", "0.013"], ["83946.9", "0.01288"], ["83946.8", "0.028437"], ["83946.7", "0"], ["83946.6", "0.09649"], ["83939.5", "0.357369"], ["83939.4", "0"], ["83916.1", "0"], ["83916", "0"]], "a": [["83987.7", "0"], ["84026.7", "0.04"], ["84026.8", "0.04"], ["84026.9", "0.018"], ["84027", "0.000524"], ["84035.7", "2.612478"], ["84038.5", "0"], ["84058.5", "0"]], "u": 128748, "seq": 67571261880}, "cts": 1742577048716, "record_time": 1742577048.909072, "EXCHANGE": "BYBIT"}
{"topic": "orderbook.200.BTCUSDT", "ts": 1742577048919, "type": "delta", "data": {"s": "BTCUSDT", "b": [["83982.2", "0.24736"], ["83977.2", "0.047864"], ["83977.1", "0"], ["83949.4", "0.03963"], ["83944.1", "0.05"], ["83944", "0.049545"], ["83943.7", "0.171"], ["83943.6", "0"], ["83939.5", "0"], ["83939.1", "6.767043"], ["83938.5", "0.000358"], ["83936", "0.357377"], ["83934.7", "0.00439"]], "a": [["83988.3", "0.117101"], ["83989.7", "0.005955"], ["83990.5", "0.024665"], ["83992.9", "0"], ["83996.4", "0.000153"], ["83998.8", "0.263831"], ["84004.3", "0"], ["84009.9", "0"], ["84025.7", "0.31543"], ["84026.7", "0"], ["84026.8", "0"], ["84026.9", "0.058"], ["84027", "0.040524"], ["84033", "2.612478"], ["84035.7", "0"], ["84039", "0.476373"], ["84042", "0.023752"], ["84044.2", "0"], ["84046.5", "0"], ["84057.8", "0.353696"], ["84058.5", "0.005951"], ["84059", "0.000204"]], "u": 128749, "seq": 67571262009}, "cts": 1742577048914, "record_time": 1742577049.108897, "EXCHANGE": "BYBIT"}
{"topic": "orderbook.200.BTCUSDT", "ts": 1742577049120, "type": "delta", "data": {"s": "BTCUSDT", "b": [["83965", "0.059404"], ["83963.8", "0.003"], ["83958", "0.061007"], ["83951", "0.123908"], ["83948.5", "0.000524"], ["83947.2", "0.013"], ["83947.1", "0.01288"], ["83947", "0"], ["83946.9", "0"], ["83945.7", "0.132855"], ["83944.1", "0"], ["83944", "0"], ["83943.9", "0.270405"], ["83943.8", "0.050068"], ["83939.2", "0.3579"], ["83939.1", "0"], ["83936.4", "6.767043"], ["83936", "0"], ["83916.2", "0"]], "a": [["83987", "0.067567"], ["83987.1", "0.228223"], ["83990.5", "0.096135"], ["83996.4", "0"], ["84000", "0.058714"], ["84007", "0.057972"], ["84014", "0.111733"], ["84033", "0"], ["84035.7", "2.612478"], ["84039", "0.118996"], ["84044.2", "0.357377"], ["84058.4", "0"], ["84058.5", "0"], ["84059", "0"]], "u": 128750, "seq": 67571262108}, "cts": 1742577049104, "record_time": 1742577049.308813, "EXCHANGE": "BYBIT"}
{"topic": "orderbook.200.BTCUSDT", "ts": 1742577049319, "type": "delta", "data": {"s": "BTCUSDT", "b": [["83949.7", "0.04"], ["83949.6", "0.03972"], ["83949.4", "0"], ["83949.3", "0.001466"], ["83947.3", "0.017396"], ["83947.2", "0.01288"], ["83947.1", "0"], ["83944", "0.05"], ["83943.8", "0.000523"], ["83939.3", "0.357373"], ["83939.2", "0.000522"], ["83916.9", "0"]], "a": [["83994.4", "0.000153"], ["84026.2", "0.04"], ["84026.3", "0.044687"], ["84026.9", "0.018"], ["84027", "0.000524"], ["84058.1", "0"], ["84058.2", "0"]], "u": 128751, "seq": 67571262159}, "cts": 1742577049298, "record_time": 1742577049.50938, "EXCHANGE": "BYBIT"}
{"topic": "orderbook.200.BTCUSDT", "ts": 1742577049520, "type": "delta", "data": {"s": "BTCUSDT", "b": [["83982.2", "0.248848"], ["83977.2", "0.07758"], ["83977.1", "0.118996"], ["83965", "0"], ["83958", "0.000208"], ["83951", "0"], ["83949.7", "0"], ["83949.5", "0.03963"], ["83947.3", "0.004396"], ["83947.1", "0.01288"], ["83944", "0"], ["83943.8", "0.050068"], ["83939.4", "0.357373"], ["83939.3", "0"], ["83916.9", "0.001466"]], "a": [["83994.4", "0"], ["84000", "0"], ["84007", "0"], ["84014", "0.00009"], ["84026.2", "0"], ["84026.3", "0.004687"], ["84026.5", "0.04"], ["84026.6", "0.04"], ["84027.6", "0.051355"], ["84030.2", "2.612478"], ["84035.7", "0"], ["84058.1", "0.002528"], ["84058.2", "0.000083"]], "u": 128752, "seq": 67571262221}, "cts": 1742577049516, "record_time": 1742577049.70953, "EXCHANGE": "BYBIT"}
{"topic": "orderbook.200.BTCUSDT", "ts": 1742577049719, "type": "delta", "data": {"s": "BTCUSDT", "b": [["83982.2", "0.248833"], ["83972.9", "0"], ["83949.7", "0.03963"], ["83949.5", "0"], ["83948.5", "0.133379"], ["83945.7", "0"], ["83939.5", "0.357375"], ["83939.4", "0"], ["83916.2", "0.011994"], ["83916.1", "0.000522"]], "a": [["83994", "0.001152"], ["84026.3", "0.044687"], ["84026.4", "0.04"], ["84026.5", "0"], ["84026.6", "0"], ["84030.2", "0"], ["84035.7", "2.612421"], ["84058.4", "0.000333"]], "u": 128753, "seq": 67571262289}, "cts": 1742577049708, "record_time": 1742577049.908784, "EXCHANGE": "BYBIT"}
{"topic": "orderbook.200.BTCUSDT", "ts": 1742577049919, "type": "delta", "data": {"s": "BTCUSDT", "b": [["83948.5", "0.133396"], ["83947.3", "0.017396"], ["83947.1", "0"], ["83944", "0.05"], ["83943.8", "0.000523"], ["83939.5", "0"], ["83936.5", "0.357376"]], "a": [["83994", "0.000999"], ["84026.3", "0.004687"], ["84026.5", "0.04"], ["84039.1", "0.432512"], ["84044.2", "0"]], "u": 128754, "seq": 67571262351}, "cts": 1742577049916, "record_time": 1742577050.108329, "EXCHANGE": "BYBIT"}
{"topic": "orderbook.200.BTCUSDT", "ts": 1742577050120, "type": "delta", "data": {"s": "BTCUSDT", "b": [["83936.6", "0.357708"], ["83936.5", "0"], ["83936.4", "7.158604"], ["83916", "0.00009"]], "a": [["83982.3", "0.231374"], ["83985.3", "0"], ["83993.6", "0.105478"], ["84014.8", "0.070514"], ["84039.1", "0.075135"], ["84044.2", "0.357376"], ["84058.4", "0"]], "u": 128755, "seq": 67571262401}, "cts": 1742577050117, "record_time": 1742577050.309265, "EXCHANGE": "BYBIT"}
{"topic": "orderbook.200.BTCUSDT", "ts": 1742577050319, "type": "delta", "data": {"s": "BTCUSDT", "b": [["83982.2", "0.249433"], ["83936.7", "0.357374"], ["83936.6", "0.000333"], ["83916", "0"]], "a": [["83993.6", "0.105325"], ["84027.4", "2.701726"], ["84035.7", "0"], ["84058.4", "0.000333"]], "u": 128756, "seq": 67571262443}, "cts": 1742577050317, "record_time": 1742577050.509342, "EXCHANGE": "BYBIT"}
{"topic": "orderbook.200.BTCUSDT", "ts": 1742577050519, "type": "delta", "data": {"s": "BTCUSDT", "b": [["83944", "0.049545"], ["83936.8", "0.357373"], ["83936.7", "0"]], "a": [["83993.5", "0.004484"], ["84009.1", "0.023815"], ["84026.2", "0.04"], ["84026.3", "0.044687"], ["84026.4", "0"], ["84026.5", "0"]], "u": 128757, "seq": 67571262492}, "cts": 1742577050517, "record_time": 1742577050.708635, "EXCHANGE": "BYBIT"}
{"topic": "orderbook.200.BTCUSDT", "ts": 1742577050720, "type": "delta", "data": {"s": "BTCUSDT", "b": [["83977.2", "0.047864"], ["83977.1", "0"], ["83970", "0.275686"], ["83965.9", "0.122543"], ["83959.5", "0.16374"], ["83958.9", "0.176807"], ["83952.5", "0.30917"], ["83951.9", "0.300169"], ["83947.4", "0.131835"], ["83947.3", "0.017276"], ["83947.2", "0"], ["83936.9", "0.357374"], ["83936.8", "0"], ["83916.9", "0"], ["83916.2", "0"], ["83916.1", "0"]], "a": [["83994.5", "0.113231"], ["83998.8", "0.386577"], ["84005", "0.232319"], ["84005.8", "0.362678"], ["84012", "0.284234"], ["84012.8", "0.306396"], ["84055.8", "0.589917"], ["84057.8", "0"], ["84058.1", "0"], ["84058.2", "0"], ["84058.4", "0"]], "u": 128758, "seq": 67571262550}, "cts": 1742577050710, "record_time": 1742577050.909203, "EXCHANGE": "BYBIT"}
{"topic": "orderbook.200.BTCUSDT", "ts": 1742577050919, "type": "delta", "data": {"s": "BTCUSDT", "b": [["83982.2", "0.168133"], ["83973", "0"], ["83970", "0.15245"], ["83965.9", "0"], ["83961.4", "0.481778"], ["83959.5", "0"], ["83958.9", "0"], ["83952.5", "0"], ["83951.9", "0"], ["83948.5", "0.000524"], ["83945.7", "0.132875"], ["83944.1", "0.05"], ["83943.9", "0.22086"], ["83936.9", "0"], ["83936.4", "0"], ["83930.8", "7.520582"], ["83929.7", "0.357387"], ["83916.9", "0.001466"], ["83916.2", "0.011994"], ["83916.1", "0.000522"], ["83916", "0.00009"], ["83915.9", "0.059399"]], "a": [["83986", "0.005956"], ["83989.5", "0.071471"], ["83989.7", "0"], ["83990.5", "0.024665"], ["83993.5", "0.004331"], ["83994.5", "0"], ["83996", "0.148895"], ["83996.9", "0.071465"], ["83998.8", "0.192368"], ["84005", "0.059399"], ["84005.8", "0.178609"], ["84011.6", "0.125026"], ["84012", "0"], ["84012.8", "0"], ["84026.2", "0"], ["84026.4", "0.04"], ["84037.5", "0.357387"], ["84044.2", "0"]], "u": 128759, "seq": 67571262728}, "cts": 1742577050915, "record_time": 1742577051.108486, "EXCHANGE": "BYBIT"}
{"topic": "orderbook.200.BTCUSDT", "ts": 1742577051119, "type": "delta", "data": {"s": "BTCUSDT", "b": [["83982.2", "0.078433"], ["83949.8", "0.04"], ["83949.6", "0.00009"], ["83936", "0.357384"], ["83929.7", "0"], ["83915.9", "0"]], "a": [["83982.3", "0.402374"], ["83988.5", "0.071472"], ["83989.5", "0"], ["83992.7", "0.000153"], ["83995.9", "0.059399"], ["84005.8", "0"], ["84010.5", "0.09159"], ["84018.9", "0.118996"], ["84025.9", "0.04"], ["84026", "0.04"], ["84026.3", "0.004687"], ["84026.4", "0"], ["84037.4", "0.357721"], ["84037.5", "0"], ["84047.5", "0.011859"], ["84056.6", "0"], ["84056.7", "0"], ["84057.5", "0"], ["84057.7", "0"]], "u": 128760, "seq": 67571262794}, "cts": 1742577051116, "record_time": 1742577051.308851, "EXCHANGE": "BYBIT"}
{"topic": "orderbook.200.BTCUSDT", "ts": 1742577051319, "type": "delta", "data": {"s": "BTCUSDT", "b": [["83982.2", "0.264423"], ["83949.9", "0.063811"], ["83949.8", "0.03963"], ["83949.7", "0"], ["83947.5", "0.215773"], ["83947.4", "0.131715"], ["83947.3", "0.004396"], ["83944.2", "0.05"], ["83944.1", "0.049544"], ["83944", "0"], ["83933.6", "7.5332"], ["83930.8", "0.001466"], ["83915.9", "0.059399"]], "a": [["83982.3", "0.212323"], ["83992.7", "0"], ["83995.1", "0.071467"], ["84000.1", "0.114882"], ["84000.7", "0.04"], ["84003.3", "0.178609"], ["84005.1", "0.003576"], ["84025.6", "0.04"], ["84025.7", "0.35543"], ["84025.9", "0"], ["84026", "0"], ["84037.4", "0.000333"], ["84037.5", "0.357385"], ["84050.4", "0"], ["84056.5", "0"]], "u": 128761, "seq": 67571262910}, "cts": 1742577051318, "record_time": 1742577051.509682, "EXCHANGE": "BYBIT"}
{"topic": "orderbook.200.BTCUSDT", "ts": 1742577051520, "type": "delta", "data": {"s": "BTCUSDT", "b": [["83965.1", "0.060089"], ["83958.1", "0.055704"], ["83951.1", "0.113727"], ["83949.9", "0.023811"], ["83949.7", "0.03963"], ["83947.5", "0.202773"], ["83947.4", "0.131835"], ["83947.3", "0.017276"], ["83944.2", "0"], ["83944.1", "0"], ["83944", "0.05"], ["83943.9", "0.270405"], ["83916.1", "0"], ["83916", "0"], ["83915.9", "0"]], "a": [["83992.5", "0.000153"], ["84000.1", "0.177047"], ["84005.1", "0"], ["84007.1", "0.097283"], ["84014.1", "0.118676"], ["84025.6", "0"], ["84025.7", "0.31543"], ["84025.9", "0.04"], ["84026", "0.04"], ["84037.5", "0"], ["84038.9", "0.357385"], ["84056", "0"], ["84056.2", "0"]], "u": 128762, "seq": 67571262963}, "cts": 1742577051456, "record_time": 1742577051.708988, "EXCHANGE": "BYBIT"}
{"topic": "orderbook.200.BTCUSDT", "ts": 1742577051719, "type": "delta", "data": {"s": "BTCUSDT", "b": [["83965.1", "0"], ["83958.1", "0"], ["83951.1", "0"], ["83949.8", "0"], ["83949.6", "0.03972"], ["83947.4", "0.118835"], ["83947.2", "0.01288"], ["83921.8", "0"], ["83916.1", "0.000522"], ["83916", "0.00009"], ["83915.9", "0.059399"], ["83915.8", "0.089099"]], "a": [["83982.3", "0.210545"], ["83992.3", "0.000153"], ["83992.5", "0"], ["83994", "0"], ["83995.1", "0"], ["83999.5", "0.071796"], ["84000.1", "0.114882"], ["84007.1", "0.035728"], ["84008.3", "0.125026"], ["84014.1", "0"], ["84018.9", "0"], ["84025.9", "0"], ["84026", "0"], ["84026.4", "0.04"], ["84026.5", "0.04"], ["84042", "0"], ["84056", "0.00018"], ["84056.5", "0.004156"], ["84056.6", "0.000366"], ["84056.7", "0.04"]], "u": 128763, "seq": 67571263028}, "cts": 1742577051707, "record_time": 1742577051.908826, "EXCHANGE": "BYBIT"}
{"topic": "orderbook.200.BTCUSDT", "ts": 1742577051920, "type": "delta", "data": {"s": "BTCUSDT", "b": [["83982.2", "0.354123"], ["83949.8", "0.04"], ["83949.6", "0.00009"], ["83947.4", "0.131835"], ["83947.2", "0"], ["83944.1", "0.049544"], ["83944", "0.049545"], ["83943.9", "0.22086"], ["83915.8", "0"]], "a": [["83992.3", "0"], ["84025.9", "0.04"], ["84026", "0.04"], ["84026.4", "0"], ["84026.5", "0"], ["84033.6", "0.023231"], ["84056.2", "0.171"], ["84056.7", "0"]], "u": 128764, "seq": 67571263098}, "cts": 1742577051914, "record_time": 1742577052.108873, "EXCHANGE": "BYBIT"}
{"topic": "orderbook.200.BTCUSDT", "ts": 1742577052119, "type": "delta", "data": {"s": "BTCUSDT", "b": [["83970.8", "0.153021"], ["83966.7", "0.114592"], ["83960.3", "0.18628"], ["83959.7", "0.173004"], ["83953.3", "0.310332"], ["83952.7", "0.301503"], ["83949.8", "0"], ["83949.6", "0.03972"], ["83944.1", "0.05"], ["83916.1", "0"], ["83916", "0"], ["83915.9", "0"]], "a": [["83991.8", "0.000153"], ["83995.3", "0.119659"], ["83999.6", "0.120783"], ["84005.8", "0.167386"], ["84006.6", "0.181156"], ["84012.8", "0.285764"], ["84013.6", "0.283953"], ["84025.7", "1.076919"], ["84025.9", "0"], ["84026", "0"], ["84026.4", "0.04"], ["84026.5", "0.04"], ["84038.9", "0.357383"], ["84055.8", "0"], ["84055.9", "0"], ["84056", "0"], ["84056.2", "0"], ["84056.5", "0"], ["84056.6", "0"]], "u": 128765, "seq": 67571263170}, "cts": 1742577052019, "record_time": 1742577052.309383, "EXCHANGE": "BYBIT"}
{"topic": "orderbook.200.BTCUSDT", "ts": 1742577052320, "type": "delta", "data": {"s": "BTCUSDT", "b": [["83970.8", "0.032716"], ["83966.7", "0"], ["83960.3", "0"], ["83959.7", "0.00036"], ["83953.3", "0"], ["83952.7", "0"], ["83949.7", "0"], ["83949.6", "0.04009"], ["83949.5", "0.03963"], ["83948.5", "0.133399"], ["83947.4", "0.118835"], ["83947.3", "0.004396"], ["83947.2", "0.013"], ["83947.1", "0.01288"], ["83945.7", "0"], ["83944.1", "0"], ["83944", "0"], ["83943.9", "0.27086"], ["83943.8", "0.050068"], ["83916.1", "0.000522"], ["83916", "0.00009"], ["83915.9", "0.059399"], ["83915.8", "0.089099"], ["83915.6", "0.000333"]], "a": [["83982.3", "0.21053"], ["83986", "0"], ["83986.9", "0.006289"], ["83991.8", "0"], ["83995.3", "0.000333"], ["83999.6", "0"], ["84005.8", "0"], ["84006.6", "0"], ["84012.8", "0"], ["84013.6", "0"], ["84026.4", "0"], ["84026.6", "0.04"], ["84038.9", "0"], ["84039.2", "0.416872"], ["84055.8", "0.589917"], ["84055.9", "0.005"], ["84056", "0.00018"], ["84056.5", "0.004156"], ["84056.6", "0.000366"], ["84056.7", "0.04"], ["84057.5", "1.027868"], ["84057.7", "0.001333"]], "u": 128766, "seq": 67571263262}, "cts": 1742577052315, "record_time": 1742577052.509915, "EXCHANGE": "BYBIT"}
{"topic": "orderbook.200.BTCUSDT", "ts": 1742577052519, "type": "delta", "data": {"s": "BTCUSDT", "b": [["83955.8", "0"], ["83944", "0.05"], ["83943.9", "0.270405"], ["83943.8", "0.000523"]], "a": [["84006.5", "0.128535"], ["84039.2", "0.059489"], ["84044.2", "0.357382"], ["84056.2", "0.171"], ["84057.5", "0"], ["84057.7", "0"]], "u": 128767, "seq": 67571263316}, "cts": 1742577052474, "record_time": 1742577052.708119, "EXCHANGE": "BYBIT"}
{"topic": "orderbook.200.BTCUSDT", "ts": 1742577052720, "type": "delta", "data": {"s": "BTCUSDT", "b": [["83949.7", "0.04"], ["83949.6", "0.03972"], ["83949.5", "0"], ["83948.5", "0.133397"], ["83947.3", "0.017396"], ["83947.2", "0.01288"], ["83947.1", "0"], ["83915.5", "0.00036"]], "a": [["83982.3", "0.175674"], ["84005.8", "0.178609"], ["84026.4", "0.04"], ["84026.6", "0"], ["84044.1", "0.357379"], ["84044.2", "0"], ["84056.7", "0"]], "u": 128768, "seq": 67571263402}, "cts": 1742577052685, "record_time": 1742577052.91849, "EXCHANGE": "BYBIT"}
