{"success": true, "ret_msg": "subscribe", "conn_id": "4137d158-a774-46db-a7ee-dbdc5eb26575", "op": "subscribe", "record_time": 1742554938.759265, "EXCHANGE": "BYBIT"}
{"topic": "orderbook.200.BTCUSDT", "ts": 1742554937320, "type": "snapshot", "data": {"s": "BTCUSDT", "b": [["84120.3", "0.458586"], ["84120", "0.00006"], ["84119.9", "0.003926"], ["84119.7", "0.057182"], ["84119.5", "0.171"], ["84119", "0.048"], ["84118.8", "0.04"], ["84117.4", "0.102309"], ["84116.2", "0.089099"], ["84115.7", "0.04"], ["84115.6", "0.023775"], ["84115.3", "0.0025"], ["84115.2", "0.005943"], ["84115.1", "0.04"], ["84115", "0.009578"], ["84114.9", "0.005942"], ["84114.6", "0.0006"], ["84114.4", "0.052"], ["84113.7", "0.04"], ["84113.6", "0.04"], ["84113.2", "0.261152"], ["84113.1", "0.171"], ["84112.4", "0.001333"], ["84112.3", "0.119998"], ["84112.2", "0.067"], ["84112.1", "0.003221"], ["84112", "0.04"], ["84111.9", "0.015"], ["84111.7", "0.027229"], ["84111.2", "0.001466"], ["84111.1", "0.023777"], ["84110.9", "0.521137"], ["84110.4", "0.000518"], ["84110.2", "0.04"], ["84109", "0.000333"], ["84108.6", "0.226431"], ["84108.5", "0.05944"], ["84108.2", "0.001333"], ["84107.9", "0.0924"], ["84106.9", "0.178444"], ["84106.8", "0.05944"], ["84106.7", "0.118884"], ["84106.5", "0.007411"], ["84106.4", "0.023545"], ["84105.7", "0.000518"], ["84104.7", "0.151135"], ["84104.4", "0.023778"], ["84104.1", "0.118881"], ["84104", "0.001423"], ["84103.7", "0.17482"], ["84102.5", "0.168696"], ["84101.9", "0.001466"], ["84101.6", "0.059445"], ["84101.5", "0.118881"], ["84101.1", "0.000518"], ["84100.5", "0.000333"], ["84100.3", "0.156576"], ["84100.2", "0.04356"], ["84100", "0.00006"], ["84099.9", "0.178338"], ["84099.8", "0.185615"], ["84099.5", "0.009152"], ["84098.4", "0.059446"], ["84097.9", "0.023166"], ["84097.7", "0.083224"], ["84097.3", "0.001466"], ["84096.8", "0.004618"], ["84096.5", "0.082652"], ["84096.4", "0.089099"], ["84096.3", "0.000333"], ["84095.6", "0.001423"], ["84095.3", "0.003209"], ["84094.5", "0.059446"], ["84093.9", "0.118804"], ["84093.4", "0.284273"], ["84092.7", "0.001466"], ["84092.2", "0.167282"], ["84092.1", "0.119213"], ["84091.9", "0.000618"], ["84091.8", "0.171"], ["84091.6", "0.0006"], ["84091.4", "0.001333"], ["84091.1", "0.003209"], ["84090.6", "0.023778"], ["84090.1", "0.012879"], ["84090", "0.012879"], ["84089.5", "0.013983"], ["84088.6", "0.118804"], ["84088.5", "0.11894"], ["84088.2", "0.000111"], ["84088", "0.064508"], ["84087.9", "0.059732"], ["84087.2", "0.137548"], ["84086.9", "0.003208"], ["84086.5", "0.0045"], ["84085.8", "0.005946"], ["84085.4", "0.12483"], ["84084.1", "0.05944"], ["84083.7", "0.000333"], ["84083.6", "4.939064"], ["84083.5", "0.118804"], ["84083.4", "0.001466"], ["84083.3", "0.089099"], ["84083.1", "0.171083"], ["84083", "0.060779"], ["84082.7", "0.009124"], ["84082.6", "0.000516"], ["84082.5", "16.069726"], ["84080", "0.00006"], ["84079.5", "0.000333"], ["84078.8", "0.002889"], ["84078.5", "0.039458"], ["84078.4", "0.118804"], ["84078.2", "0.0016"], ["84078", "0.000516"], ["84076.7", "0.04"], ["84075.3", "0.000333"], ["84074.9", "0.023775"], ["84074.6", "0.001333"], ["84074.3", "0.003181"], ["84074.2", "1.03761"], ["84074", "0.083174"], ["84073.4", "0.000516"], ["84072.1", "0.023775"], ["84072", "0.118804"], ["84071.9", "3.209375"], ["84071.3", "0.009"], ["84071.2", "1.119964"], ["84071.1", "3.49795"], ["84070.7", "0.00061"], ["84070.4", "0.001423"], ["84070.3", "0.005943"], ["84070.1", "0.003181"], ["84069.6", "0.171"], ["84069.5", "0.005041"], ["84068.7", "0.000516"], ["84068.5", "0.023775"], ["84068", "0.023775"], ["84066.9", "0.000333"], ["84066.7", "0.063138"], ["84066.6", "0.118804"], ["84066.2", "0.001333"], ["84065.9", "0.009123"], ["84065.1", "0.059399"], ["84064.9", "0.001466"], ["84064.1", "0.000516"], ["84063.6", "0.089171"], ["84062.7", "0.000333"], ["84062.6", "0.10147"], ["84062", "0.001423"], ["84061.8", "0.00009"], ["84061.7", "0.003181"], ["84061.3", "0.101954"], ["84061.2", "0.118804"], ["84061.1", "0.171"], ["84060.3", "0.001466"], ["84060", "0.00006"], ["84059.5", "0.000516"], ["84058.8", "0.140494"], ["84058.5", "0.000333"], ["84058", "0.023779"], ["84057.8", "0.041333"], ["84057.7", "0.04"], ["84057.6", "0.04"], ["84057.5", "0.015175"], ["84057.2", "0.011994"], ["84057.1", "0.023779"], ["84056.5", "0.0045"], ["84055.9", "0.02368"], ["84055.8", "0.035979"], ["84055.7", "0.001466"], ["84055.2", "0.023779"], ["84055", "0.000118"], ["84054.9", "0.059915"], ["84054.8", "0.125994"], ["84054.3", "0.000333"], ["84054.1", "0.013086"], ["84054", "0.235392"], ["84053.6", "0.001423"], ["84053.4", "0.005944"], ["84053.2", "0.003181"], ["84053.1", "0.027982"], ["84053", "0.099417"], ["84052.9", "0.118804"], ["84052.8", "0.011994"], ["84052.6", "0.171"], ["84051.6", "0.023779"], ["84051.2", "0.00012"], ["84051.1", "0.023779"], ["84051", "0.001466"], ["84050.7", "0.04"], ["84050.2", "0.000516"], ["84050.1", "0.000333"], ["84050", "0.00086"], ["84049.4", "0.016333"], ["84049.1", "0.057942"], ["84049", "0.003181"], ["84047.6", "0.011992"], ["84047.5", "0.011993"], ["84047.4", "0.005943"]], "a": [["84120.4", "0.004312"], ["84120.5", "0.00321"], ["84120.9", "0.001333"], ["84121.6", "0.000333"], ["84123.1", "0.0003"], ["84123.7", "0.0012"], ["84124.2", "0.000518"], ["84124.7", "0.003211"], ["84125", "0.001466"], ["84125.1", "0.001333"], ["84125.4", "0.0025"], ["84125.8", "0.000333"], ["84126.5", "0.003445"], ["84126.9", "0.05"], ["84128.8", "0.015"], ["84128.9", "0.174729"], ["84129.3", "0.001333"], ["84129.7", "0.001466"], ["84130", "0.000333"], ["84131.3", "0.009"], ["84132.8", "0.005942"], ["84132.9", "0.000153"], ["84133.1", "0.003211"], ["84133.5", "0.001851"], ["84134.2", "0.000423"], ["84134.3", "0.001466"], ["84134.6", "0.014477"], ["84135.8", "0.04286"], ["84137.3", "0.003211"], ["84137.4", "0.000297"], ["84137.5", "0.121655"], ["84137.7", "0.001333"], ["84138.1", "0.000518"], ["84138.4", "0.000333"], ["84138.8", "0.003825"], ["84138.9", "0.007433"], ["84139.6", "0.000297"], ["84139.7", "0.159855"], ["84139.9", "0.059399"], ["84140.8", "0.04"], ["84140.9", "0.044"], ["84141.5", "0.003211"], ["84141.6", "0.171"], ["84141.9", "0.001333"], ["84142.2", "0.112995"], ["84142.5", "0.04"], ["84142.6", "0.000423"], ["84142.7", "0.000518"], ["84142.8", "0.048"], ["84143.5", "0.001466"], ["84144.1", "0.055031"], ["84144.2", "0.04"], ["84144.3", "0.048"], ["84144.8", "0.0016"], ["84145.3", "0.02146"], ["84145.8", "0.003212"], ["84145.9", "0.04"], ["84146", "0.063"], ["84146.1", "0.001333"], ["84146.5", "0.0045"], ["84146.8", "0.000333"], ["84147.2", "0.00214"], ["84147.3", "0.319728"], ["84147.4", "0.000518"], ["84147.5", "0.071831"], ["84147.7", "0.052"], ["84148.2", "0.001466"], ["84149.3", "0.009395"], ["84149.6", "0.005942"], ["84150", "0.123216"], ["84150.1", "0.182893"], ["84150.3", "0.001333"], ["84151", "0.000423"], ["84151.9", "0.019878"], ["84152", "0.059917"], ["84152.8", "0.001466"], ["84153", "0.019216"], ["84153.9", "0.004756"], ["84154.2", "0.003212"], ["84154.5", "0.001333"], ["84155.2", "0.000333"], ["84156.2", "0.023775"], ["84156.3", "0.096366"], ["84156.4", "0.291644"], ["84156.6", "0.000518"], ["84157.4", "0.001466"], ["84157.5", "0.118804"], ["84158.4", "0.003212"], ["84158.6", "0.171"], ["84158.7", "0.001333"], ["84158.9", "0.0006"], ["84159.1", "0.023775"], ["84159.4", "0.000513"], ["84159.9", "0.005943"], ["84160.5", "0.192286"], ["84161.2", "0.059399"], ["84161.3", "0.134339"], ["84162.1", "0.001466"], ["84162.2", "0.531713"], ["84162.5", "0.000238"], ["84162.6", "0.003212"], ["84162.7", "0.023775"], ["84162.9", "0.001333"], ["84163", "0.023775"], ["84163.6", "0.000333"], ["84164", "0.234823"], ["84164.1", "0.118804"], ["84164.6", "0.023775"], ["84165.5", "0.004699"], ["84165.9", "0.000518"], ["84166.4", "0.005942"], ["84166.7", "0.001466"], ["84166.8", "0.003213"], ["84167.1", "0.172333"], ["84167.3", "0.353213"], ["84167.8", "0.000423"], ["84168.2", "0.012895"], ["84168.3", "0.012903"], ["84169", "0.103479"], ["84169.1", "0.103433"], ["84169.2", "0.04"], ["84169.9", "0.059399"], ["84170.1", "0.118804"], ["84170.4", "0.017845"], ["84170.5", "0.000342"], ["84171", "0.001976"], ["84171.3", "0.002799"], ["84172.1", "0.000333"], ["84172.3", "0.053386"], ["84175.2", "0.003732"], ["84175.5", "0.001333"], ["84175.6", "0.171"], ["84175.9", "0.001466"], ["84176.2", "0.00009"], ["84176.3", "0.000333"], ["84176.5", "0.0045"], ["84177.1", "0.12374"], ["84177.2", "0.118804"], ["84177.3", "0.059411"], ["84177.4", "0.0012"], ["84177.5", "0.103196"], ["84178.4", "2.257414"], ["84178.8", "0.059399"], ["84179.4", "0.003214"], ["84179.8", "0.001851"], ["84180.3", "0.017079"], ["84180.4", "0.060611"], ["84180.5", "0.000333"], ["84180.6", "0.001466"], ["84182.2", "0.023675"], ["84182.3", "0.118804"], ["84182.8", "0.0036"], ["84183.2", "0.005942"], ["84183.6", "0.003214"], ["84184", "0.001333"], ["84184.1", "0.171"], ["84184.4", "0.000518"], ["84184.6", "0.00009"], ["84184.7", "0.000333"], ["84184.8", "0.001189"], ["84185.2", "0.001466"], ["84185.4", "0.00315"], ["84185.5", "0.4"], ["84187.5", "0.059399"], ["84187.6", "0.118804"], ["84187.8", "0.003214"], ["84188.2", "0.001333"], ["84188.4", "0.013065"], ["84188.8", "0.0005"], ["84188.9", "0.000333"], ["84189", "0.000518"], ["84189.3", "0.002793"], ["84189.8", "0.003595"], ["84190.2", "0.0144"], ["84190.9", "0.071854"], ["84191.3", "0.012"], ["84191.4", "0.011837"], ["84191.7", "0.005942"], ["84192", "0.003288"], ["84192.4", "0.001333"], ["84192.5", "0.0002"], ["84192.6", "0.171"], ["84193", "0.00009"], ["84193.1", "0.000333"], ["84193.2", "0.0001"], ["84193.3", "0.003"], ["84193.4", "0.118804"], ["84193.6", "0.084"], ["84193.7", "0.000518"], ["84194.4", "0.011837"], ["84194.5", "0.001466"], ["84195", "0.027976"], ["84195.2", "0.011991"], ["84195.3", "0.048"], ["84196.3", "0.003188"], ["84196.5", "0.006"], ["84196.6", "0.001333"], ["84197", "0.107399"], ["84197.1", "0.00234"], ["84197.2", "0.019949"]], "u": 18689, "seq": 67549813845}, "cts": 1742554937316, "record_time": 1742554938.76037, "EXCHANGE": "BYBIT"}
{"topic": "orderbook.200.BTCUSDT", "ts": 1742554937520, "type": "delta", "data": {"s": "BTCUSDT", "b": [["84114.1", "0.0001"], ["84112.3", "0"], ["84106.9", "0.178344"], ["84102.5", "0"], ["84096.5", "0.157667"], ["84095.3", "0.007965"], ["84093.4", "0"], ["84088.5", "0.112998"], ["84088", "0.112147"], ["84085.4", "0.12643"], ["84078.2", "0"], ["84077", "0.000118"], ["84055", "0"], ["84047.3", "0.04"], ["84047.2", "0.02368"], ["84047.1", "0.011993"]], "a": [["84123.7", "0.0016"], ["84134.6", "0.048487"], ["84137.5", "0"], ["84144.8", "0"], ["84147.3", "0.147075"], ["84152.4", "0.0016"], ["84156.3", "0.171814"], ["84156.4", "0"], ["84162", "0.000118"], ["84197.3", "0.000333"]], "u": 18690, "seq": 67549813964}, "cts": 1742554937504, "record_time": 1742554938.761269, "EXCHANGE": "BYBIT"}
{"topic": "orderbook.200.BTCUSDT", "ts": 1742554937719, "type": "delta", "data": {"s": "BTCUSDT", "b": [["84100.3", "0.199186"], ["84100.2", "0"], ["84096.5", "0.082652"], ["84082.5", "0"], ["84076.8", "16.410822"], ["84047", "0.04"]], "a": [["84134.6", "0.014477"], ["84156.3", "0.096366"], ["84162.4", "1.425816"], ["84178.4", "0"], ["84184.1", "2.428414"]], "u": 18691, "seq": 67549814055}, "cts": 1742554937707, "record_time": 1742554938.761946, "EXCHANGE": "BYBIT"}
{"topic": "orderbook.200.BTCUSDT", "ts": 1742554937919, "type": "delta", "data": {"s": "BTCUSDT", "b": [["84120.3", "0.475834"], ["84083.6", "0.137063"]], "a": [["84168.2", "0.012903"]], "u": 18692, "seq": 67549814118}, "cts": 1742554937886, "record_time": 1742554938.762451, "EXCHANGE": "BYBIT"}
{"topic": "orderbook.200.BTCUSDT", "ts": 1742554938120, "type": "delta", "data": {"s": "BTCUSDT", "b": [["84087.2", "0.13755"], ["84075.2", "0.001426"], ["84047", "0"]], "a": [["84178.4", "2.257414"], ["84184.1", "0.171"], ["84197.3", "0"]], "u": 18693, "seq": 67549814156}, "cts": 1742554938113, "record_time": 1742554938.762916, "EXCHANGE": "BYBIT"}
{"topic": "orderbook.200.BTCUSDT", "ts": 1742554938320, "type": "delta", "data": {"s": "BTCUSDT", "b": [["84120.3", "0.481773"], ["84115.8", "0.001466"], ["84113.6", "0.093634"], ["84112.6", "0.006021"], ["84100.3", "0.156576"], ["84100.2", "0.043495"], ["84090.2", "0.012879"], ["84090", "0"], ["84047.3", "0"], ["84047.2", "0"], ["84047.1", "0"]], "a": [["84120.4", "0.002971"], ["84149.9", "0.118804"], ["84150", "0.004412"], ["84168.2", "0"], ["84168.3", "0"], ["84168.4", "0.012903"], ["84168.5", "0.012903"], ["84169.1", "0.063433"], ["84169.2", "0"], ["84169.3", "0.04"], ["84169.4", "0.04"], ["84197.1", "0"], ["84197.2", "0"]], "u": 18694, "seq": 67549814292}, "cts": 1742554938316, "record_time": 1742554938.763385, "EXCHANGE": "BYBIT"}
{"topic": "orderbook.200.BTCUSDT", "ts": 1742554938519, "type": "delta", "data": {"s": "BTCUSDT", "b": [["84120.3", "0.487781"], ["84119.7", "0"], ["84109.7", "0.058573"], ["84102.7", "0.061521"], ["84095.7", "0.12135"], ["84078.5", "4.969726"], ["84047.5", "0"], ["84047.4", "0"]], "a": [["84128.9", "0.003729"], ["84135.7", "0.071347"], ["84144.7", "0.054796"], ["84151.7", "0.055919"], ["84153.9", "0"], ["84158.7", "0.120557"], ["84168.4", "0"], ["84168.6", "0.012903"], ["84169.3", "0"], ["84169.5", "0.04"], ["84178.4", "0"], ["84181.3", "2.257414"], ["84196.6", "0"], ["84197", "0"]], "u": 18695, "seq": 67549814452}, "cts": 1742554938516, "record_time": 1742554938.763903, "EXCHANGE": "BYBIT"}
{"topic": "orderbook.200.BTCUSDT", "ts": 1742554938719, "type": "delta", "data": {"s": "BTCUSDT", "b": [["84100", "0.118864"], ["84090.3", "0.013"], ["84090.1", "0"], ["84087.2", "0.137533"], ["84076.8", "16.810207"]], "a": [["84138.9", "0.001466"], ["84153.9", "0.004756"], ["84168.2", "0.013"], ["84168.3", "0.012903"], ["84168.5", "0"], ["84168.6", "0"], ["84181.3", "2.257531"], ["84196.5", "0"]], "u": 18696, "seq": 67549814563}, "cts": 1742554938711, "record_time": 1742554938.76433, "EXCHANGE": "BYBIT"}
{"topic": "orderbook.200.BTCUSDT", "ts": 1742554938920, "type": "delta", "data": {"s": "BTCUSDT", "b": [["84120.3", "0.489537"], ["84116.2", "0.100987"], ["84113.6", "0.04"], ["84109.7", "0"], ["84102.7", "0"], ["84100.4", "0.059399"], ["84100.3", "0.199483"], ["84100.2", "0"], ["84095.7", "0"], ["84090.3", "0.012879"], ["84047.5", "0.011993"], ["84047.4", "0.005943"], ["84047.3", "0.04"]], "a": [["84128.9", "0.174729"], ["84130.4", "0.000153"], ["84132.9", "0"], ["84134.6", "0.03416"], ["84139.1", "0.005823"], ["84144.1", "0.076111"], ["84144.7", "0"], ["84151.7", "0"], ["84158.7", "0.001333"], ["84168.2", "0"], ["84168.3", "0"], ["84168.8", "0.012903"], ["84168.9", "0.012903"], ["84169.4", "0"], ["84169.5", "0"], ["84169.7", "0.04"], ["84169.8", "0.04"], ["84196.5", "0.006"]], "u": 18697, "seq": 67549814692}, "cts": 1742554938916, "record_time": 1742554938.935718, "EXCHANGE": "BYBIT"}
{"topic": "orderbook.200.BTCUSDT", "ts": 1742554939119, "type": "delta", "data": {"s": "BTCUSDT", "b": [["84120.3", "0.490963"], ["84113.3", "0.053634"], ["84100.3", "0.156576"], ["84100.2", "0.043715"], ["84100", "0.00006"], ["84090.3", "0"], ["84090.1", "0.012879"], ["84082.5", "16.810207"], ["84076.8", "0"], ["84075.2", "0"], ["84061.9", "0.235392"], ["84054", "0"], ["84047.3", "0"]], "a": [["84126.5", "0"], ["84128.9", "0.003729"], ["84153.9", "0"], ["84168.8", "0"], ["84168.9", "0.013"], ["84169", "0.116382"], ["84169.7", "0"], ["84169.9", "0.099399"], ["84181.3", "2.25753"], ["84196.6", "0.001333"], ["84197", "0.107399"], ["84197.1", "0.00234"], ["84197.2", "0.019949"]], "u": 18698, "seq": 67549814753}, "cts": 1742554939116, "record_time": 1742554939.136293, "EXCHANGE": "BYBIT"}
{"topic": "orderbook.200.BTCUSDT", "ts": 1742554939319, "type": "delta", "data": {"s": "BTCUSDT", "b": [["84106.4", "0"], ["84100.2", "0.042669"], ["84078.5", "0.039458"], ["84047.3", "0.04"]], "a": [["84120.4", "0.00296"], ["84128.9", "0.174729"], ["84153.9", "0.004756"], ["84160.5", "0.637619"], ["84168.9", "0"], ["84169", "0.103479"], ["84169.1", "0.076433"], ["84169.2", "0.012903"], ["84169.8", "0"], ["84169.9", "0.059399"], ["84170", "0.04"], ["84170.1", "0.158804"], ["84197.2", "0"]], "u": 18699, "seq": 67549814819}, "cts": 1742554939297, "record_time": 1742554939.363657, "EXCHANGE": "BYBIT"}
{"topic": "orderbook.200.BTCUSDT", "ts": 1742554939519, "type": "delta", "data": {"s": "BTCUSDT", "b": [["84120.3", "0.492648"], ["84119.6", "0.0777"], ["84090.2", "0"], ["84090", "0.012879"], ["84083.6", "5.161209"], ["84082.5", "0"], ["84074", "16.893381"]], "a": [["84120.4", "0.001561"], ["84134.6", "0.051458"], ["84138.6", "0.065862"], ["84153.9", "0"], ["84168.6", "0.012903"], ["84168.7", "0.012903"], ["84169.1", "0.063433"], ["84169.2", "0"], ["84169.5", "0.04"], ["84169.6", "0.04"], ["84170", "0"], ["84170.1", "0.118804"], ["84197", "0"], ["84197.1", "0"]], "u": 18700, "seq": 67549814886}, "cts": 1742554939517, "record_time": 1742554939.542044, "EXCHANGE": "BYBIT"}
{"topic": "orderbook.200.BTCUSDT", "ts": 1742554939720, "type": "delta", "data": {"s": "BTCUSDT", "b": [["84116.2", "0.011888"], ["84087.2", "0.137519"], ["84083.6", "0.137063"], ["84076.8", "17.058221"], ["84074", "0.083174"], ["84047.3", "0"]], "a": [["84168.4", "0.013"], ["84168.5", "0.012903"], ["84168.6", "0"], ["84168.7", "0"], ["84169.3", "0.04"], ["84169.4", "0.04"], ["84169.5", "0"], ["84169.6", "0"], ["84181.3", "2.257531"]], "u": 18701, "seq": 67549814950}, "cts": 1742554939714, "record_time": 1742554939.736741, "EXCHANGE": "BYBIT"}
{"topic": "orderbook.200.BTCUSDT", "ts": 1742554939920, "type": "delta", "data": {"s": "BTCUSDT", "b": [["84120.3", "0.491222"], ["84112.6", "0"], ["84082.5", "17.058221"], ["84077.5", "0.001426"], ["84076.8", "0"]], "a": [["84153.9", "0.004756"], ["84168.4", "0.012903"], ["84196.6", "0"]], "u": 18702, "seq": 67549814986}, "cts": 1742554939912, "record_time": 1742554939.936925, "EXCHANGE": "BYBIT"}
{"topic": "orderbook.200.BTCUSDT", "ts": 1742554940120, "type": "delta", "data": {"s": "BTCUSDT", "b": [["84120.3", "0.492648"], ["84100.2", "0.043541"], ["84088.2", "0.000337"], ["84082.5", "0"], ["84077.5", "0"], ["84071.2", "18.178185"], ["84047.3", "0.04"], ["84047.2", "0.02368"]], "a": [["84126.9", "0"], ["84128.7", "0.000297"], ["84128.8", "0.068358"], ["84137.4", "0"], ["84153.9", "0"], ["84196.6", "0.001333"], ["84197", "0.107399"]], "u": 18703, "seq": 67549815042}, "cts": 1742554940117, "record_time": 1742554940.136357, "EXCHANGE": "BYBIT"}
{"topic": "orderbook.200.BTCUSDT", "ts": 1742554940319, "type": "delta", "data": {"s": "BTCUSDT", "b": [["84120.3", "0.491848"], ["84082.5", "17.058221"], ["84071.2", "1.119964"], ["84047.2", "0"]], "a": [["84169.2", "0.04"], ["84169.4", "0"], ["84178.4", "2.257531"], ["84181.3", "0"]], "u": 18704, "seq": 67549815073}, "cts": 1742554940310, "record_time": 1742554940.33553, "EXCHANGE": "BYBIT"}
{"topic": "orderbook.200.BTCUSDT", "ts": 1742554940520, "type": "delta", "data": {"s": "BTCUSDT", "b": [["84120.3", "0.486855"], ["84109.4", "0.006049"], ["84100.4", "0"], ["84083.6", "5.235613"], ["84082.5", "0"], ["84077.6", "0.001426"], ["84071.2", "18.178185"]], "a": [["84153.9", "0.004756"], ["84169.2", "0"], ["84169.4", "0.04"], ["84197", "0"]], "u": 18705, "seq": 67549815112}, "cts": 1742554940512, "record_time": 1742554940.554034, "EXCHANGE": "BYBIT"}
{"topic": "orderbook.200.BTCUSDT", "ts": 1742554940719, "type": "delta", "data": {"s": "BTCUSDT", "b": [["84083.6", "0.137063"]], "a": [], "u": 18706, "seq": 67549815126}, "cts": 1742554940696, "record_time": 1742554940.73687, "EXCHANGE": "BYBIT"}
{"topic": "orderbook.200.BTCUSDT", "ts": 1742554940920, "type": "delta", "data": {"s": "BTCUSDT", "b": [["84120.3", "0.490421"], ["84117.9", "0.089099"], ["84107.9", "0.09232"], ["84090.2", "0.013"], ["84090", "0"], ["84047.3", "0"]], "a": [["84168.3", "0.013"], ["84168.5", "0"], ["84169.2", "0.04"], ["84169.4", "0"]], "u": 18707, "seq": 67549815143}, "cts": 1742554940902, "record_time": 1742554940.939351, "EXCHANGE": "BYBIT"}
{"topic": "orderbook.200.BTCUSDT", "ts": 1742554941119, "type": "delta", "data": {"s": "BTCUSDT", "b": [["84120.3", "0.491847"], ["84077.6", "0"], ["84047.3", "0.04"]], "a": [], "u": 18708, "seq": 67549815155}, "cts": 1742554941099, "record_time": 1742554941.136696, "EXCHANGE": "BYBIT"}
{"topic": "orderbook.200.BTCUSDT", "ts": 1742554941320, "type": "delta", "data": {"s": "BTCUSDT", "b": [["84082.5", "17.058221"], ["84071.2", "1.119964"], ["84047.3", "0"]], "a": [["84178.4", "0"], ["84181.3", "2.257531"]], "u": 18709, "seq": 67549815175}, "cts": 1742554941316, "record_time": 1742554941.349916, "EXCHANGE": "BYBIT"}
{"topic": "orderbook.200.BTCUSDT", "ts": 1742554941520, "type": "delta", "data": {"s": "BTCUSDT", "b": [], "a": [["84178.4", "2.257531"], ["84181.3", "0"]], "u": 18710, "seq": 67549815205}, "cts": 1742554941502, "record_time": 1742554941.566813, "EXCHANGE": "BYBIT"}
{"topic": "orderbook.200.BTCUSDT", "ts": 1742554941720, "type": "delta", "data": {"s": "BTCUSDT", "b": [["84083.6", "5.235613"]], "a": [["84130.4", "0"], ["84197", "0.107399"]], "u": 18711, "seq": 67549815224}, "cts": 1742554941702, "record_time": 1742554941.752943, "EXCHANGE": "BYBIT"}
{"topic": "orderbook.200.BTCUSDT", "ts": 1742554941919, "type": "delta", "data": {"s": "BTCUSDT", "b": [["84120.3", "0.487655"], ["84117.9", "0"], ["84090.2", "0.012879"], ["84082.5", "0"], ["84076.4", "0.001426"], ["84071.2", "18.429572"], ["84047.3", "0.04"]], "a": [["84128", "0.000153"], ["84168.3", "0.012903"], ["84197", "0"]], "u": 18712, "seq": 67549815262}, "cts": 1742554941915, "record_time": 1742554941.949925, "EXCHANGE": "BYBIT"}
{"topic": "orderbook.200.BTCUSDT", "ts": 1742554942119, "type": "delta", "data": {"s": "BTCUSDT", "b": [["84120.3", "0.491221"], ["84120.1", "0.023553"], ["84087.2", "0.137535"], ["84083.6", "0.137063"], ["84047.3", "0"]], "a": [], "u": 18713, "seq": 67549815296}, "cts": 1742554942109, "record_time": 1742554942.19303, "EXCHANGE": "BYBIT"}
{"topic": "orderbook.200.BTCUSDT", "ts": 1742554942320, "type": "delta", "data": {"s": "BTCUSDT", "b": [], "a": [["84155.3", "1.375317"], ["84196.6", "0"]], "u": 18714, "seq": 67549815304}, "cts": 1742554942275, "record_time": 1742554942.359368, "EXCHANGE": "BYBIT"}
{"topic": "orderbook.200.BTCUSDT", "ts": 1742554942520, "type": "delta", "data": {"s": "BTCUSDT", "b": [["84100.2", "0.042775"], ["84082.5", "17.363718"], ["84071.2", "1.119964"], ["84047.4", "0"]], "a": [["84134.6", "0.034235"], ["84135.7", "0"], ["84144", "0.178266"], ["84151.9", "0.43766"]], "u": 18715, "seq": 67549815325}, "cts": 1742554942513, "record_time": 1742554942.547759, "EXCHANGE": "BYBIT"}
{"topic": "orderbook.200.BTCUSDT", "ts": 1742554942920, "type": "delta", "data": {"s": "BTCUSDT", "b": [["84090.3", "0.013"], ["84090.1", "0"], ["84083.6", "5.327262"], ["84082.5", "17.411534"]], "a": [["84142.2", "0"], ["84167.8", "0.013423"], ["84167.9", "0.012903"], ["84168.3", "0"], ["84168.4", "0"], ["84168.7", "0.04"], ["84168.8", "0.04"], ["84169.2", "0"], ["84169.3", "0"], ["84196.6", "0.001333"], ["84197", "0.107399"]], "u": 18716, "seq": 67549815355}, "cts": 1742554942885, "record_time": 1742554942.95246, "EXCHANGE": "BYBIT"}
{"topic": "orderbook.200.BTCUSDT", "ts": 1742554943119, "type": "delta", "data": {"s": "BTCUSDT", "b": [["84120.3", "0.492647"], ["84106.5", "0.001466"], ["84090.3", "0.012879"], ["84085.8", "0"], ["84076.4", "0"], ["84047.4", "0.005943"], ["84047.3", "0.04"]], "a": [["84142.7", "0.113497"], ["84167.8", "0.000423"], ["84168", "0.012903"], ["84168.7", "0"], ["84168.9", "0.04"], ["84197", "0"]], "u": 18717, "seq": 67549815396}, "cts": 1742554943113, "record_time": 1742554943.147177, "EXCHANGE": "BYBIT"}
{"topic": "orderbook.200.BTCUSDT", "ts": 1742554943319, "type": "delta", "data": {"s": "BTCUSDT", "b": [["84120.3", "0.494953"], ["84090.3", "0"], ["84090.1", "0.012879"], ["84082.5", "0"], ["84068.4", "17.411534"]], "a": [["84167.9", "0"], ["84168", "0"], ["84168.3", "0.012903"], ["84168.4", "0.012903"], ["84168.8", "0"], ["84168.9", "0"], ["84169.2", "0.04"], ["84169.3", "0.04"]], "u": 18718, "seq": 67549815418}, "cts": 1742554943301, "record_time": 1742554943.350329, "EXCHANGE": "BYBIT"}
{"topic": "orderbook.200.BTCUSDT", "ts": 1742554943520, "type": "delta", "data": {"s": "BTCUSDT", "b": [["84095.3", "0.003209"], ["84093.6", "0.004756"], ["84083.6", "0.137063"], ["84074", "17.494708"], ["84068.4", "0"]], "a": [["84151.2", "0.000988"], ["84196.6", "0"]], "u": 18719, "seq": 67549815457}, "cts": 1742554943514, "record_time": 1742554943.563719, "EXCHANGE": "BYBIT"}
{"topic": "orderbook.200.BTCUSDT", "ts": 1742554943720, "type": "delta", "data": {"s": "BTCUSDT", "b": [["84090.3", "0.012879"], ["84090.1", "0"], ["84076.8", "17.517298"], ["84074", "0.083174"], ["84047.3", "0"]], "a": [["84143.9", "0.120031"], ["84144.1", "0"], ["84151.2", "0"], ["84152", "0.061094"], ["84168", "0.012903"], ["84168.1", "0.012903"], ["84168.3", "0"], ["84168.4", "0"], ["84168.9", "0.04"], ["84169", "0.143479"], ["84169.2", "0"], ["84169.3", "0"], ["84196.6", "0.001333"], ["84197", "0.107399"]], "u": 18720, "seq": 67549815499}, "cts": 1742554943713, "record_time": 1742554943.746063, "EXCHANGE": "BYBIT"}
{"topic": "orderbook.200.BTCUSDT", "ts": 1742554943920, "type": "delta", "data": {"s": "BTCUSDT", "b": [], "a": [["84152", "0.059917"]], "u": 18721, "seq": 67549815524}, "cts": 1742554943908, "record_time": 1742554943.95257, "EXCHANGE": "BYBIT"}
{"topic": "orderbook.200.BTCUSDT", "ts": 1742554944119, "type": "delta", "data": {"s": "BTCUSDT", "b": [["84120.3", "0.166209"], ["84120.1", "0"], ["84119.9", "0"], ["84119.6", "0"], ["84119.5", "0"], ["84119", "0"], ["84118.8", "0"], ["84117.4", "0"], ["84116.2", "0"], ["84115.7", "0"], ["84115.6", "0"], ["84115.2", "0"], ["84115.1", "0"], ["84115", "0.000518"], ["84114.4", "0"], ["84114.1", "0"], ["84113.7", "0"], ["84113.6", "0"], ["84113.3", "0"], ["84113.2", "0.000333"], ["84113.1", "0"], ["84112.2", "0"], ["84112", "0"], ["84111.7", "0"], ["84111.1", "0"], ["84110.9", "0"], ["84110.2", "0"], ["84109.9", "0.003926"], ["84109.4", "0"], ["84109", "0.014294"], ["84108.9", "0.04"], ["84108.6", "0"], ["84108.5", "0"], ["84107.9", "0.003221"], ["84106.9", "0"], ["84106.8", "0"], ["84106.7", "0"], ["84104.7", "0.065871"], ["84104.4", "0"], ["84104.1", "0"], ["84102.3", "0.019241"], ["84101.6", "0"], ["84101.5", "0"], ["84101.1", "0.040518"], ["84100.3", "0.034322"], ["84099.9", "0"], ["84099.8", "0.001333"], ["84099.5", "0.049152"], ["84098.4", "0"], ["84098.1", "0.00906"], ["84097.9", "0"], ["84097.7", "0"], ["84097", "0.005943"], ["84096.5", "0.000518"], ["84096.4", "0"], ["84094.5", "0"], ["84093.9", "0"], ["84093.6", "0"], ["84092.1", "0.000333"], ["84090.9", "0.023775"], ["84090.6", "0"], ["84090.3", "0"], ["84090.2", "0"], ["84088.6", "0"], ["84088.5", "0"], ["84088", "0.147816"], ["84087.2", "0.001941"], ["84085.4", "0.0016"], ["84084.1", "0"], ["84083.5", "0"], ["84083.3", "0"], ["84083", "0.001333"], ["84080.8", "0.013"], ["84080.7", "0.012882"], ["84078.5", "5.301668"], ["84076.8", "0"], ["84072.5", "0.001426"], ["84067.3", "0.13555"], ["84063.6", "0"], ["84057.5", "0.003181"], ["84055.2", "0.202095"], ["84054.8", "0.114"], ["84053", "1.882576"], ["84047.3", "0.04"], ["84047.2", "0.02368"], ["84047.1", "0.011993"], ["84047", "0.04"], ["84046.9", "0.283362"], ["84046.5", "0.011993"], ["84046.4", "0.001466"], ["84045.9", "0.000333"], ["84045.6", "0.000516"], ["84045.2", "0.001423"], ["84045", "0.000594"], ["84044.9", "0.118804"], ["84044.8", "0.003181"], ["84044.7", "0.059399"], ["84044.2", "0.02112"], ["84043.9", "0.044118"], ["84041.8", "0.001466"], ["84041.7", "0.050333"], ["84041.3", "0.009"], ["84041", "0.001849"], ["84040.6", "0.003181"], ["84039.5", "0.003575"], ["84039.3", "0.118804"], ["84037.6", "0.08522"], ["84037.5", "0.000333"], ["84037.4", "0.000337"], ["84037.3", "0.195"], ["84037.2", "0.001466"], ["84037.1", "0.044304"], ["84036.8", "0.001423"], ["84036.4", "0.003697"], ["84034.2", "0.472071"], ["84033.5", "0.04"], ["84033.3", "0.000333"], ["84033", "0.044"], ["84032.8", "0.059464"], ["84032.6", "0.001333"], ["84032.5", "0.001466"], ["84032.3", "0.005942"], ["84032.2", "0.003181"], ["84031.8", "0.000516"], ["84030.2", "0.000083"]], "a": [["84120.4", "0.470194"], ["84120.9", "0.036996"], ["84125.6", "0.015466"], ["84128", "0"], ["84128.7", "0.059399"], ["84130.5", "0.03437"], ["84130.6", "0.089099"], ["84132.1", "0.019216"], ["84133.2", "0.003575"], ["84134.4", "0.043409"], ["84134.6", "0"], ["84137.2", "0.118804"], ["84137.3", "0.060606"], ["84137.4", "0.052"], ["84138.6", "0"], ["84138.8", "0"], ["84139.1", "0"], ["84141.6", "0.182895"], ["84143.8", "0.118804"], ["84144", "0"], ["84144.8", "0.531713"], ["84146.3", "0.491447"], ["84147.5", "0.023831"], ["84149.3", "0"], ["84151.5", "0.089099"], ["84153", "0"], ["84157.8", "0.063438"], ["84161.3", "0.009518"], ["84162.2", "0"], ["84165.5", "0"], ["84169.1", "0"], ["84177.5", "0.089099"], ["84178.4", "0"], ["84182.2", "0"], ["84187.7", "1.783159"], ["84197", "0"]], "u": 18722, "seq": 67549816511}, "cts": 1742554944117, "record_time": 1742554944.148852, "EXCHANGE": "BYBIT"}
{"topic": "orderbook.200.BTCUSDT", "ts": 1742554944319, "type": "delta", "data": {"s": "BTCUSDT", "b": [["84120.3", "0.183472"], ["84109.9", "0"], ["84109.2", "0.021226"], ["84109.1", "0.023881"], ["84109", "0.000333"], ["84108.9", "0"], ["84106.1", "0.04"], ["84104.4", "0.04"], ["84102.7", "0.04"], ["84102.2", "0.006004"], ["84101", "0.04"], ["84100.3", "0.022667"], ["84100.2", "0"], ["84099.7", "0.003926"], ["84092.2", "0"], ["84091.9", "0.098782"], ["84091.5", "0.112975"], ["84089.5", "0"], ["84088", "0.001466"], ["84084.6", "0.521137"], ["84083.6", "0"], ["84080.8", "0"], ["84080.7", "0"], ["84080.6", "0.013"], ["84080.5", "0.012882"], ["84078.5", "0.039458"], ["84074.1", "0.013787"], ["84067.3", "0"], ["84064.5", "0.13555"], ["84044.1", "0.171"], ["84043.9", "0"], ["84041", "0.046363"], ["84038.8", "0.043506"], ["84037.6", "0.039635"], ["84036.2", "0.044686"], ["84035.6", "0.171"], ["84033", "0"], ["84032.8", "0"], ["84032.6", "0"], ["84032.5", "0"], ["84032.3", "0"], ["84032.2", "0"], ["84031.8", "0"], ["84030.2", "0"]], "a": [["84120.4", "0.485793"], ["84120.5", "0.009156"], ["84120.8", "0.048911"], ["84121.1", "0.035663"], ["84121.3", "0.035663"], ["84121.5", "0.035663"], ["84127.3", "0.003825"], ["84129.3", "0.067202"], ["84130.5", "0.064639"], ["84130.7", "0.044"], ["84132.4", "0.048"], ["84134.1", "0.048"], ["84134.4", "0.07751"], ["84135.5", "0.04"], ["84135.8", "0.09086"], ["84142.5", "0"], ["84142.8", "0"], ["84144.3", "0"], ["84147.3", "0.151747"], ["84147.5", "0"], ["84147.7", "0"], ["84157.8", "0"], ["84160.5", "0"], ["84160.6", "0.063438"], ["84163", "0.037787"], ["84169", "0.100449"], ["84196.3", "0"], ["84196.5", "0"], ["84196.6", "0"]], "u": 18723, "seq": 67549816688}, "cts": 1742554944316, "record_time": 1742554944.338579, "EXCHANGE": "BYBIT"}
{"topic": "orderbook.200.BTCUSDT", "ts": 1742554944519, "type": "delta", "data": {"s": "BTCUSDT", "b": [["84120.3", "0"], ["84120", "0"], ["84115.8", "0.045631"], ["84115.3", "0"], ["84111.9", "0.005"], ["84110.8", "0.0025"], ["84109.2", "0"], ["84109.1", "0"], ["84107.4", "0.01"], ["84106.1", "0"], ["84104.7", "0.000333"], ["84104.4", "0"], ["84104", "0.001333"], ["84103.8", "0.078241"], ["84102.8", "0.04"], ["84102.7", "0"], ["84102.3", "0"], ["84102.2", "0"], ["84101.2", "0.044"], ["84101.1", "0.000518"], ["84101", "0"], ["84100.3", "0"], ["84099.5", "0.009152"], ["84098.5", "0.028045"], ["84098.1", "0"], ["84097.9", "0.052"], ["84097.8", "0.04"], ["84096.8", "0"], ["84096.2", "0.013829"], ["84096.1", "0.04"], ["84092", "0.019241"], ["84091.9", "0.064889"], ["84091.5", "0"], ["84090.9", "0"], ["84087.9", "0.000333"], ["84084.7", "0.21574"], ["84082.6", "0.005131"], ["84080.6", "0"], ["84080.5", "0"], ["84078.4", "0"], ["84076.7", "0"], ["84075", "0.012882"], ["84074.9", "0.012882"], ["84074", "0.059399"], ["84072.1", "0"], ["84070.3", "0"], ["84068.5", "0"], ["84068", "0"], ["84064.5", "0"], ["84062.6", "0.08963"], ["84056", "0.13555"], ["84055.2", "0.023779"], ["84054.1", "0"], ["84053.1", "0"], ["84041.7", "0.013869"], ["84036.2", "0"], ["84033", "0.088713"], ["84032.8", "0.059464"], ["84032.6", "0.001333"], ["84032.5", "0.001466"], ["84032.3", "0.005942"], ["84032.2", "0.003181"], ["84031.8", "0.000516"], ["84030.6", "0.01309"], ["84030.2", "0.000083"], ["84029.1", "0.000333"], ["84028.6", "0.118804"], ["84028.4", "0.001423"], ["84028.2", "0.106201"], ["84028", "0.003181"]], "a": [["84115.9", "0.606788"], ["84116.2", "0.035664"], ["84120", "0.00024"], ["84120.2", "0.059399"], ["84120.3", "0.1871"], ["84120.4", "0.465633"], ["84120.8", "0"], ["84120.9", "0.003833"], ["84121.5", "0"], ["84121.8", "0.003825"], ["84123.5", "0.022784"], ["84123.6", "0.009395"], ["84124.3", "0.01"], ["84125.4", "0"], ["84125.6", "0"], ["84125.7", "0.04"], ["84125.8", "0.000423"], ["84125.9", "0.048"], ["84127.3", "0"], ["84127.6", "0.048"], ["84128", "0.024202"], ["84128.5", "0.109819"], ["84128.6", "0.118804"], ["84128.8", "0.005"], ["84129.3", "0.001333"], ["84130.5", "0.099993"], ["84130.6", "0.129099"], ["84133.2", "0"], ["84134", "0.04"], ["84134.4", "0.111647"], ["84137.2", "0.158804"], ["84137.3", "0.051211"], ["84140", "0.00024"], ["84140.8", "0"], ["84140.9", "0"], ["84144.2", "0"], ["84145.9", "0"], ["84146", "0.015"], ["84146.3", "0"], ["84147.3", "0.004672"], ["84150.2", "2.257448"], ["84152.1", "0.063437"], ["84155.3", "0"], ["84157.9", "1.425816"], ["84160", "0.00024"], ["84160.6", "0"], ["84161.3", "0.134339"], ["84162.4", "0"], ["84172.9", "3.274911"], ["84179.6", "0.027779"], ["84193.3", "0"], ["84193.4", "0"], ["84193.6", "0"], ["84193.7", "0"], ["84194.4", "0"], ["84194.5", "0"], ["84195", "0"], ["84195.2", "0"], ["84195.3", "0"]], "u": 18724, "seq": 67549817376}, "cts": 1742554944516, "record_time": 1742554944.5416, "EXCHANGE": "BYBIT"}
{"topic": "orderbook.200.BTCUSDT", "ts": 1742554944720, "type": "delta", "data": {"s": "BTCUSDT", "b": [["84115.8", "0.088986"], ["84101.2", "0"], ["84099.7", "0"], ["84096.4", "0.040329"], ["84096.3", "0.048333"], ["84096.2", "0.04"], ["84094.2", "0.061819"], ["84092.1", "0.004259"], ["84091.2", "0.04"], ["84089.7", "0.04"], ["84089.5", "0.04"], ["84087.2", "0.062826"], ["84086.3", "0.00906"], ["84082.7", "0.122099"], ["84080.2", "0.123305"], ["84078.5", "0.003182"], ["84077.8", "0.024002"], ["84075", "0"], ["84074.9", "0"], ["84073.4", "0.013516"], ["84073.3", "0.012883"], ["84061.9", "0"], ["84055.2", "0.202104"], ["84041.7", "0.000333"], ["84041", "0.001849"], ["84039.9", "0.235392"], ["84039.3", "0.146738"], ["84038.8", "0"], ["84037.1", "0"], ["84036.6", "0.043197"], ["84036", "0.624139"], ["84035.5", "0.044181"], ["84033", "0.044"], ["84031.7", "0.043783"], ["84030.6", "0"], ["84030.2", "0"], ["84029.1", "0"], ["84028.6", "0"], ["84028.4", "0"], ["84028.2", "0"], ["84028", "0"]], "a": [["84115.9", "0.486869"], ["84116.6", "0.035664"], ["84116.8", "0.035664"], ["84117", "0.035664"], ["84117.4", "0.003825"], ["84120.3", "0.135595"], ["84120.4", "0.467099"], ["84121.1", "0"], ["84121.3", "0"], ["84121.8", "0"], ["84123.3", "0.055239"], ["84123.4", "0.04"], ["84123.5", "0.044"], ["84124.3", "0.015"], ["84128.6", "0.166804"], ["84128.7", "0.099399"], ["84128.8", "0"], ["84129.2", "0.060631"], ["84130.1", "0.048"], ["84130.2", "0.052"], ["84130.3", "0.04"], ["84130.5", "0.064262"], ["84130.6", "0.089099"], ["84132.4", "0"], ["84134.1", "0"], ["84135.5", "0"], ["84136.2", "0.058667"], ["84137.2", "0.118804"], ["84137.3", "0.003211"], ["84139.7", "0"], ["84143.2", "0.115848"], ["84150.1", "0.860654"], ["84150.2", "2.257338"], ["84151.9", "0.019878"], ["84157.5", "1.54462"], ["84157.9", "0"], ["84162", "0.024636"], ["84167.9", "0.128315"], ["84192.6", "0"], ["84193", "0"], ["84193.1", "0"], ["84193.2", "0"]], "u": 18725, "seq": 67549817633}, "cts": 1742554944717, "record_time": 1742554944.735964, "EXCHANGE": "BYBIT"}
{"topic": "orderbook.200.BTCUSDT", "ts": 1742554944920, "type": "delta", "data": {"s": "BTCUSDT", "b": [["84115.8", "0.09493"], ["84111.9", "0"], ["84107.4", "0.015"], ["84103.8", "0.053041"], ["84103.4", "0.023703"], ["84102.8", "0"], ["84094.2", "0"], ["84087.2", "0.001941"], ["84080.2", "0"], ["84074.7", "0.035675"], ["84064.5", "0.135545"], ["84056", "0"], ["84037.6", "0.021653"], ["84036.6", "0"], ["84035.5", "0"], ["84034.4", "17.389623"], ["84033.9", "0.029835"], ["84032.4", "0.044328"], ["84031.7", "0.023478"], ["84030.6", "0.01309"]], "a": [["84115.9", "0.498869"], ["84116.5", "0.023776"], ["84122", "0.023776"], ["84123", "0.02972"], ["84125.8", "0.030143"], ["84126.9", "0.059441"], ["84128.2", "0.059441"], ["84128.5", "0.167681"], ["84129.2", "0"], ["84130.5", "0.064012"], ["84130.7", "0"], ["84131", "0.059441"], ["84134", "0"], ["84135.8", "0.04286"], ["84136.1", "0.005944"], ["84136.2", "0"], ["84137.4", "0"], ["84143.2", "0"], ["84165.6", "0.048"], ["84192.4", "0"], ["84192.5", "0"]], "u": 18726, "seq": 67549817789}, "cts": 1742554944913, "record_time": 1742554944.969448, "EXCHANGE": "BYBIT"}
{"topic": "orderbook.200.BTCUSDT", "ts": 1742554945119, "type": "delta", "data": {"s": "BTCUSDT", "b": [["84093", "0.04"], ["84091.9", "0.094728"], ["84091.3", "0.044"], ["84085.9", "0.481239"], ["84084.8", "0.118804"], ["84083.2", "0.089912"], ["84058.8", "0.224251"], ["84037.3", "17.584623"], ["84034.4", "0"], ["84032.2", "0"], ["84031.8", "0"], ["84031.7", "0"], ["84030.6", "0"]], "a": [["84115.9", "0.495293"], ["84128.6", "0.048"], ["84133.4", "0.003576"], ["84134.4", "0.051901"], ["84150.2", "2.257282"], ["84192", "0"]], "u": 18727, "seq": 67549817902}, "cts": 1742554945113, "record_time": 1742554945.15191, "EXCHANGE": "BYBIT"}
{"topic": "orderbook.200.BTCUSDT", "ts": 1742554945320, "type": "delta", "data": {"s": "BTCUSDT", "b": [["84115.8", "0.097583"], ["84091.8", "0.22465"], ["84086", "0.354654"], ["84084.7", "0.059399"], ["84032.3", "0"]], "a": [["84115.9", "0.495282"], ["84116.5", "0"], ["84119.3", "0.023776"], ["84123", "0"], ["84124.5", "0.02972"], ["84128.2", "0"], ["84129.4", "0.059441"], ["84129.6", "0.059441"], ["84191.7", "0"]], "u": 18728, "seq": 67549817961}, "cts": 1742554945316, "record_time": 1742554945.350403, "EXCHANGE": "BYBIT"}
{"topic": "orderbook.200.BTCUSDT", "ts": 1742554945520, "type": "delta", "data": {"s": "BTCUSDT", "b": [["84098.9", "0.001"], ["84085.4", "0"], ["84070.2", "0.0016"], ["84069.5", "0.001466"], ["84067.3", "0.135521"], ["84064.5", "0"], ["84032.5", "0.025029"], ["84032.4", "0"]], "a": [["84115.9", "0.448045"], ["84118.6", "0.0001"], ["84123.7", "0.0012"], ["84128.9", "0.178305"], ["84133.4", "0"], ["84147.3", "0.006272"], ["84152.4", "0"], ["84191.7", "0.005942"]], "u": 18729, "seq": 67549818026}, "cts": 1742554945513, "record_time": 1742554945.536707, "EXCHANGE": "BYBIT"}
{"topic": "orderbook.200.BTCUSDT", "ts": 1742554945719, "type": "delta", "data": {"s": "BTCUSDT", "b": [["84115.8", "0.098622"], ["84073.8", "0.013"], ["84073.7", "0.012882"], ["84073.4", "0.000516"], ["84073.3", "0"], ["84032.5", "0"]], "a": [["84119.4", "0.003576"], ["84128.9", "0.174729"], ["84148.5", "0.012895"], ["84148.6", "0.012895"], ["84149.4", "0.04"], ["84149.5", "0.04"], ["84150.2", "2.256968"], ["84168", "0"], ["84168.1", "0"], ["84168.9", "0"], ["84169", "0.060449"], ["84191.4", "0"], ["84191.7", "0"]], "u": 18730, "seq": 67549818078}, "cts": 1742554945715, "record_time": 1742554945.755374, "EXCHANGE": "BYBIT"}
{"topic": "orderbook.200.BTCUSDT", "ts": 1742554945920, "type": "delta", "data": {"s": "BTCUSDT", "b": [["84115.8", "0.149433"], ["84103.4", "0"], ["84082.7", "0.009124"], ["84080.8", "0.112975"], ["84067.3", "0"], ["84064.5", "0.135533"]], "a": [["84115.9", "0.456185"], ["84119.2", "0.204116"], ["84119.4", "0"], ["84120.3", "0"], ["84121.8", "0.112975"], ["84131.8", "0.003576"], ["84142.7", "0.000518"], ["84147.2", "0"], ["84156.3", "0.512065"]], "u": 18731, "seq": 67549818159}, "cts": 1742554945911, "record_time": 1742554945.935817, "EXCHANGE": "BYBIT"}
{"topic": "orderbook.200.BTCUSDT", "ts": 1742554946119, "type": "delta", "data": {"s": "BTCUSDT", "b": [["84084.8", "0"], ["84077.8", "0.142806"], ["84037.3", "0.195"], ["84034.4", "17.567644"]], "a": [["84123.1", "0"], ["84123.2", "0.0003"], ["84124.9", "0.035675"], ["84142", "0.059441"], ["84151.8", "0.059441"], ["84153.9", "0"], ["84190.9", "0"], ["84191.3", "0"]], "u": 18732, "seq": 67549818235}, "cts": 1742554946114, "record_time": 1742554946.145904, "EXCHANGE": "BYBIT"}
{"topic": "orderbook.200.BTCUSDT", "ts": 1742554946320, "type": "delta", "data": {"s": "BTCUSDT", "b": [["84115.8", "0.149194"], ["84073.8", "0"], ["84073.6", "0.012882"], ["84066.7", "0.08996"], ["84037.3", "17.762644"], ["84034.4", "0"], ["84032.5", "0.001466"]], "a": [["84123.3", "0.082993"], ["84148.2", "0.014466"], ["84148.3", "0.012895"], ["84148.5", "0"], ["84148.6", "0"], ["84149.1", "0.04"], ["84149.2", "0.04"], ["84149.4", "0"], ["84149.5", "0"], ["84190.9", "0.071854"]], "u": 18733, "seq": 67549818303}, "cts": 1742554946315, "record_time": 1742554946.343238, "EXCHANGE": "BYBIT"}
{"topic": "orderbook.200.BTCUSDT", "ts": 1742554946519, "type": "delta", "data": {"s": "BTCUSDT", "b": [["84114.9", "0.008942"], ["84100.5", "0.10639"], ["84100.4", "0.119409"], ["84100.1", "0.123159"], ["84098.5", "0"], ["84096.4", "0.080152"], ["84096.3", "0.15788"], ["84090.7", "0.005783"], ["84090.3", "0.163572"], ["84089.9", "0.169265"], ["84089.3", "0.179248"], ["84082.9", "0.299363"], ["84082.3", "0.302576"], ["84081.2", "0.295195"], ["84034.2", "0"], ["84033.9", "0"], ["84033.5", "0"], ["84033.3", "0"], ["84033", "0"], ["84032.8", "0"], ["84032.6", "0"], ["84032.5", "0"]], "a": [["84115.9", "0.457968"], ["84123.3", "0.150589"], ["84124.9", "0.154992"], ["84125.3", "0.117567"], ["84129.2", "0.113896"], ["84131.8", "0"], ["84135.1", "0.178793"], ["84135.4", "0.182798"], ["84136.2", "0.18458"], ["84142.4", "0.287179"], ["84143.2", "0.291809"], ["84144.2", "0.28978"], ["84188.8", "0"], ["84188.9", "0"], ["84189", "0"], ["84189.3", "0"], ["84189.8", "0"], ["84190.2", "0"], ["84190.9", "0"]], "u": 18734, "seq": 67549818376}, "cts": 1742554946507, "record_time": 1742554946.540075, "EXCHANGE": "BYBIT"}
{"topic": "orderbook.200.BTCUSDT", "ts": 1742554946720, "type": "delta", "data": {"s": "BTCUSDT", "b": [["84115.8", "0.149524"], ["84100.4", "0"], ["84096.3", "0.048333"], ["84091.9", "0.262453"], ["84089.9", "0"], ["84089.3", "0"], ["84083.3", "0.118804"], ["84082.9", "0"], ["84082.3", "0"], ["84034.2", "0.472071"], ["84033.9", "0.029835"], ["84033.5", "0.04"], ["84033.3", "0.000333"]], "a": [["84124.9", "0.035675"], ["84129.2", "0"], ["84134.4", "0.209265"], ["84135.4", "0"], ["84136.2", "0"], ["84142.4", "0"], ["84143.2", "0"], ["84167.9", "0"], ["84188.8", "0.0005"], ["84188.9", "0.000333"], ["84189", "0.000518"], ["84189.3", "0.002793"], ["84189.8", "0.003595"], ["84190.2", "0.0144"]], "u": 18735, "seq": 67549818421}, "cts": 1742554946717, "record_time": 1742554946.735249, "EXCHANGE": "BYBIT"}
{"topic": "orderbook.200.BTCUSDT", "ts": 1742554946920, "type": "delta", "data": {"s": "BTCUSDT", "b": [["84100.5", "0.093992"], ["84096.4", "0.040329"], ["84091.9", "0.169663"]], "a": [["84120.8", "0.003576"], ["84123", "0.05"], ["84134.4", "0.099051"], ["84143.9", "0.245195"], ["84189.8", "0"], ["84190.2", "0"]], "u": 18736, "seq": 67549818474}, "cts": 1742554946913, "record_time": 1742554946.935184, "EXCHANGE": "BYBIT"}
{"topic": "orderbook.200.BTCUSDT", "ts": 1742554947120, "type": "delta", "data": {"s": "BTCUSDT", "b": [["84074.7", "0"], ["84033", "0.044"]], "a": [["84120.8", "0"], ["84123.2", "0"], ["84124.3", "0.060591"], ["84181.4", "1.122576"], ["84189.8", "0.003595"]], "u": 18737, "seq": 67549818556}, "cts": 1742554947110, "record_time": 1742554947.135472, "EXCHANGE": "BYBIT"}
{"topic": "orderbook.200.BTCUSDT", "ts": 1742554947319, "type": "delta", "data": {"s": "BTCUSDT", "b": [["84115.8", "0.146541"], ["84100.5", "0.057044"], ["84100.1", "0"], ["84090.3", "0"], ["84084.5", "0.035675"], ["84083.3", "0"], ["84083.2", "0.167231"], ["84081.2", "0"], ["84032.8", "0.059464"], ["84032.6", "0.001333"], ["84032.5", "0.001466"]], "a": [["84120.4", "0.517099"], ["84123", "0"], ["84124.3", "0.015"], ["84124.7", "0.053211"], ["84124.9", "0.085675"], ["84125.3", "0"], ["84135.1", "0"], ["84144.2", "0"], ["84190.2", "0.0144"], ["84190.9", "0.071854"], ["84191.3", "0.012"], ["84191.4", "0.011837"]], "u": 18738, "seq": 67549818609}, "cts": 1742554947307, "record_time": 1742554947.33859, "EXCHANGE": "BYBIT"}
{"topic": "orderbook.200.BTCUSDT", "ts": 1742554947519, "type": "delta", "data": {"s": "BTCUSDT", "b": [["84091.9", "0.120592"], ["84090.7", "0"], ["84083.2", "0.089912"], ["84073.7", "0"], ["84073.5", "0.012882"], ["84032.3", "0.005942"]], "a": [["84115.9", "0.304863"], ["84123.2", "0.026266"], ["84123.3", "0.104898"], ["84124.7", "0.047769"], ["84124.9", "0.035675"], ["84134.4", "0.051901"], ["84143.9", "0.120031"], ["84148.2", "0.014361"], ["84191.4", "0"]], "u": 18739, "seq": 67549818658}, "cts": 1742554947513, "record_time": 1742554947.548786, "EXCHANGE": "BYBIT"}
{"topic": "orderbook.200.BTCUSDT", "ts": 1742554947719, "type": "delta", "data": {"s": "BTCUSDT", "b": [["84115.8", "0.147914"], ["84100.5", "0.087642"], ["84100.1", "0.115862"], ["84090.3", "0.173856"], ["84081.2", "0.283423"], ["84055.2", "0.023779"], ["84032.6", "0"], ["84032.5", "0"], ["84032.3", "0"]], "a": [["84119", "0.065874"], ["84120.3", "0.05"], ["84120.4", "0.467099"], ["84124.6", "0.04559"], ["84124.7", "0.003211"], ["84124.8", "0.05"], ["84125.3", "0.119523"], ["84135.1", "0.180524"], ["84144.2", "0.293504"], ["84188.9", "0"], ["84189", "0"], ["84189.3", "0"], ["84189.8", "0"], ["84190.2", "0"], ["84190.9", "0"], ["84191.3", "0"]], "u": 18740, "seq": 67549818729}, "cts": 1742554947713, "record_time": 1742554947.808121, "EXCHANGE": "BYBIT"}
{"topic": "orderbook.200.BTCUSDT", "ts": 1742554947920, "type": "delta", "data": {"s": "BTCUSDT", "b": [["84115.8", "0.162775"], ["84100.5", "0.057044"], ["84100.1", "0"], ["84096.4", "0.06497"], ["84095.5", "0.058941"], ["84090.3", "0"], ["84088.5", "0.054691"], ["84081.5", "0.117468"], ["84081.2", "0"], ["84073.8", "0.013"], ["84073.7", "0.012882"], ["84073.6", "0"], ["84073.5", "0"]], "a": [["84115.9", "0.325725"], ["84124.6", "0"], ["84124.7", "0.048801"], ["84124.8", "0"], ["84124.9", "0.085675"], ["84125.3", "0"], ["84130.5", "0.121378"], ["84134.4", "0.09957"], ["84135.1", "0"], ["84137.5", "0.055637"], ["84144.2", "0"], ["84144.5", "0.109828"], ["84148.2", "0.001466"], ["84148.3", "0.013"], ["84148.4", "0.012895"], ["84149.1", "0"], ["84149.3", "0.04"], ["84188.9", "0.000333"], ["84189", "0.000518"]], "u": 18741, "seq": 67549818797}, "cts": 1742554947916, "record_time": 1742554947.949554, "EXCHANGE": "BYBIT"}
{"topic": "orderbook.200.BTCUSDT", "ts": 1742554948119, "type": "delta", "data": {"s": "BTCUSDT", "b": [["84090.7", "0.005913"], ["84063.6", "0.089163"], ["84033", "0"], ["84032.8", "0"]], "a": [["84115.9", "0.32525"], ["84120.3", "0"], ["84120.4", "0.517099"], ["84134.4", "0.051901"], ["84148.4", "0.016311"], ["84151.4", "0.083471"], ["84151.9", "0"], ["84189.3", "0.002793"]], "u": 18742, "seq": 67549818837}, "cts": 1742554948116, "record_time": 1742554948.148616, "EXCHANGE": "BYBIT"}
{"topic": "orderbook.200.BTCUSDT", "ts": 1742554948319, "type": "delta", "data": {"s": "BTCUSDT", "b": [["84115.8", "0.163375"], ["84095.5", "0"], ["84088.5", "0"], ["84081.5", "0"], ["84077.9", "0.042877"], ["84073.9", "0.013"], ["84073.8", "0.012882"], ["84073.7", "0"], ["84033", "0.044"], ["84032.8", "0.059464"]], "a": [["84120.2", "0.109399"], ["84120.4", "0.467099"], ["84124.7", "0.097969"], ["84124.9", "0.035675"], ["84130.5", "0.064012"], ["84137.5", "0"], ["84139.2", "0.003576"], ["84144.5", "0"], ["84148.2", "0.014466"], ["84148.3", "0.012895"], ["84148.4", "0.003416"], ["84149.1", "0.04"], ["84149.3", "0"], ["84183.8", "0.001956"]], "u": 18743, "seq": 67549818917}, "cts": 1742554948315, "record_time": 1742554948.348647, "EXCHANGE": "BYBIT"}
{"topic": "orderbook.200.BTCUSDT", "ts": 1742554948520, "type": "delta", "data": {"s": "BTCUSDT", "b": [["84073.9", "0"], ["84073.7", "0.012882"]], "a": [["84120.4", "0.343466"], ["84139.2", "0"], ["84148.2", "0.014361"], ["84149", "0.04"], ["84149.2", "0"], ["84189.8", "0.003595"]], "u": 18744, "seq": 67549818965}, "cts": 1742554948513, "record_time": 1742554948.546194, "EXCHANGE": "BYBIT"}
{"topic": "orderbook.200.BTCUSDT", "ts": 1742554948719, "type": "delta", "data": {"s": "BTCUSDT", "b": [["84115.8", "0.161167"]], "a": [["84115.9", "0.324023"], ["84128.5", "0.34598"], ["84148.1", "0.012895"], ["84148.3", "0"]], "u": 18745, "seq": 67549819026}, "cts": 1742554948713, "record_time": 1742554948.752808, "EXCHANGE": "BYBIT"}
{"topic": "orderbook.200.BTCUSDT", "ts": 1742554948920, "type": "delta", "data": {"s": "BTCUSDT", "b": [["84067.4", "0.135466"], ["84064.5", "0"]], "a": [["84123.3", "0.144552"], ["84124.9", "0"], ["84125.1", "0.132463"], ["84190.2", "0.0144"]], "u": 18746, "seq": 67549819073}, "cts": 1742554948917, "record_time": 1742554949.024442, "EXCHANGE": "BYBIT"}
{"topic": "orderbook.200.BTCUSDT", "ts": 1742554949119, "type": "delta", "data": {"s": "BTCUSDT", "b": [], "a": [["84148.4", "0"], ["84190.9", "0.071854"]], "u": 18747, "seq": 67549819095}, "cts": 1742554949112, "record_time": 1742554949.152531, "EXCHANGE": "BYBIT"}
{"topic": "orderbook.200.BTCUSDT", "ts": 1742554949320, "type": "delta", "data": {"s": "BTCUSDT", "b": [["84115.8", "0.163278"]], "a": [["84119.3", "0"], ["84125.2", "0.035674"], ["84141.4", "0.074346"], ["84142", "0"], ["84148.1", "0"], ["84148.2", "0.001466"], ["84148.6", "0.013"], ["84148.7", "0.012895"], ["84149", "0"], ["84149.1", "0"], ["84149.5", "0.04"], ["84149.6", "0.045942"]], "u": 18748, "seq": 67549819165}, "cts": 1742554949310, "record_time": 1742554949.33684, "EXCHANGE": "BYBIT"}
{"topic": "orderbook.200.BTCUSDT", "ts": 1742554949519, "type": "delta", "data": {"s": "BTCUSDT", "b": [["84115.8", "0.112467"], ["84037.3", "18.723646"]], "a": [["84124.7", "0.047969"], ["84124.8", "0.05"], ["84148.6", "0"], ["84148.8", "0.012895"], ["84149.5", "0"], ["84149.7", "0.04"], ["84190.9", "0"]], "u": 18749, "seq": 67549819209}, "cts": 1742554949490, "record_time": 1742554949.53429, "EXCHANGE": "BYBIT"}
{"topic": "orderbook.200.BTCUSDT", "ts": 1742554949720, "type": "delta", "data": {"s": "BTCUSDT", "b": [["84040.1", "18.746288"], ["84037.3", "0.195"], ["84032.8", "0"]], "a": [["84115.9", "0.154725"], ["84122", "0"], ["84190.9", "0.071854"]], "u": 18750, "seq": 67549819247}, "cts": 1742554949711, "record_time": 1742554949.736959, "EXCHANGE": "BYBIT"}
{"topic": "orderbook.200.BTCUSDT", "ts": 1742554949919, "type": "delta", "data": {"s": "BTCUSDT", "b": [], "a": [["84115.9", "0.323942"]], "u": 18751, "seq": 67549819260}, "cts": 1742554949913, "record_time": 1742554949.934735, "EXCHANGE": "BYBIT"}
{"topic": "orderbook.200.BTCUSDT", "ts": 1742554950120, "type": "delta", "data": {"s": "BTCUSDT", "b": [["84115.8", "0.127328"], ["84074.2", "1.05061"], ["84074.1", "0.026669"], ["84073.8", "0"], ["84073.7", "0"], ["84033.9", "0.001774"], ["84032.8", "0.059464"], ["84032.6", "0.001333"]], "a": [["84115.9", "0.338804"], ["84123.2", "0.028826"], ["84124.5", "0.074478"], ["84124.7", "0.003211"], ["84148.3", "0.013"], ["84148.4", "0.012895"], ["84148.7", "0"], ["84148.8", "0"], ["84149.2", "0.04"], ["84149.3", "0.04"], ["84149.6", "0.005942"], ["84149.7", "0"], ["84190.9", "0"]], "u": 18752, "seq": 67549819309}, "cts": 1742554950112, "record_time": 1742554950.1415, "EXCHANGE": "BYBIT"}
{"topic": "orderbook.200.BTCUSDT", "ts": 1742554950320, "type": "delta", "data": {"s": "BTCUSDT", "b": [["84115.8", "0.134471"], ["84095", "0.05422"], ["84088", "0.063581"], ["84081", "0.117992"], ["84032.8", "0"], ["84032.6", "0"]], "a": [["84115.9", "0.344804"], ["84130", "0.056024"], ["84137", "0.061746"], ["84144", "0.115101"], ["84148.1", "0.013"], ["84148.2", "0.014361"], ["84148.3", "0"], ["84148.4", "0"], ["84149", "0.04"], ["84149.1", "0.04"], ["84149.2", "0"], ["84149.3", "0"], ["84161.1", "0.085955"], ["84189.8", "0"], ["84190.2", "0"]], "u": 18753, "seq": 67549819330}, "cts": 1742554950266, "record_time": 1742554950.337623, "EXCHANGE": "BYBIT"}
{"topic": "orderbook.200.BTCUSDT", "ts": 1742554950520, "type": "delta", "data": {"s": "BTCUSDT", "b": [["84114.9", "0.005942"], ["84100.5", "0.085806"], ["84100.1", "0.109741"], ["84095", "0"], ["84089.6", "0.186246"], ["84088", "0.001466"], ["84085.6", "0.003"], ["84082.6", "0.287004"], ["84081", "0"], ["84033", "0"]], "a": [["84115.9", "0.346587"], ["84124.5", "0.044758"], ["84124.6", "0.116321"], ["84125.8", "0.000423"], ["84126.9", "0"], ["84129.6", "0"], ["84130", "0.000333"], ["84130.5", "0.039062"], ["84130.6", "0"], ["84135.1", "0.173006"], ["84137", "0"], ["84142.1", "0.301108"], ["84144", "0"], ["84150.2", "0"], ["84164.3", "2.256968"], ["84174.4", "0.128306"], ["84189.8", "0.003595"]], "u": 18754, "seq": 67549819403}, "cts": 1742554950489, "record_time": 1742554950.539569, "EXCHANGE": "BYBIT"}
{"topic": "orderbook.200.BTCUSDT", "ts": 1742554950720, "type": "delta", "data": {"s": "BTCUSDT", "b": [["84115.8", "0.133671"], ["84100.5", "0.057044"], ["84100.1", "0"], ["84089.6", "0"], ["84083.2", "0.163235"], ["84082.6", "0.005131"], ["84074.2", "1.050492"], ["84063.6", "0"], ["84033", "0.044"], ["84032.8", "0.059464"], ["84032.6", "0.001333"]], "a": [["84115.9", "0.352587"], ["84119.7", "0.023776"], ["84123.3", "0.199438"], ["84123.4", "0.129099"], ["84123.7", "0.024976"], ["84124.6", "0"], ["84125.1", "0.162183"], ["84128", "0.053922"], ["84128.5", "0.405421"], ["84130.2", "0.111997"], ["84130.3", "0.099441"], ["84130.5", "0"], ["84134.4", "0.186414"], ["84135.1", "0"], ["84142.1", "0"], ["84148.1", "0"], ["84148.2", "0.001466"], ["84148.5", "0.013"], ["84148.6", "0.012895"], ["84149", "0"], ["84149.1", "0"], ["84149.3", "0.04"], ["84149.4", "0.04"], ["84150.1", "0.182893"], ["84154", "0.353174"], ["84158.7", "2.258301"], ["84164.3", "0"], ["84167.3", "0"], ["84190.2", "0.0144"], ["84190.9", "0.071854"], ["84191.3", "0.012"]], "u": 18755, "seq": 67549819467}, "cts": 1742554950704, "record_time": 1742554950.737369, "EXCHANGE": "BYBIT"}
{"topic": "orderbook.200.BTCUSDT", "ts": 1742554950919, "type": "delta", "data": {"s": "BTCUSDT", "b": [["84083.2", "0.089912"], ["84066.7", "0.063138"], ["84040.1", "0"], ["84037.3", "19.154769"], ["84032.5", "0.001466"]], "a": [["84130.2", "0.144852"], ["84134.4", "0.141"], ["84148.3", "0.013"], ["84148.4", "0.012895"], ["84148.5", "0"], ["84148.6", "0"], ["84149.2", "0.04"], ["84149.4", "0"], ["84150.2", "2.256968"], ["84158.7", "0.001333"], ["84164", "0.10281"], ["84191.3", "0"]], "u": 18756, "seq": 67549819488}, "cts": 1742554950895, "record_time": 1742554950.935796, "EXCHANGE": "BYBIT"}
{"topic": "orderbook.200.BTCUSDT", "ts": 1742554951320, "type": "delta", "data": {"s": "BTCUSDT", "b": [["84077", "0"], ["84063.6", "0.089163"]], "a": [["84148.3", "0"], ["84148.5", "0.012895"], ["84149.2", "0"], ["84149.4", "0.04"]], "u": 18757, "seq": 67549819516}, "cts": 1742554951315, "record_time": 1742554951.337209, "EXCHANGE": "BYBIT"}
{"topic": "orderbook.200.BTCUSDT", "ts": 1742554951520, "type": "delta", "data": {"s": "BTCUSDT", "b": [["84074.2", "1.03761"], ["84074", "0.072281"]], "a": [["84138.2", "0.003576"], ["84148.4", "0"], ["84148.6", "0.012895"], ["84149.3", "0"], ["84149.5", "0.04"], ["84150.1", "0.86051"], ["84190.9", "0"]], "u": 18758, "seq": 67549819531}, "cts": 1742554951504, "record_time": 1742554951.537599, "EXCHANGE": "BYBIT"}
{"topic": "orderbook.200.BTCUSDT", "ts": 1742554951720, "type": "delta", "data": {"s": "BTCUSDT", "b": [["84115.8", "0.112671"], ["84074.2", "1.05061"], ["84074", "0.059399"], ["84063.6", "0"], ["84032.3", "0.005942"]], "a": [["84148.3", "0.013"], ["84148.4", "0.012895"], ["84148.5", "0"], ["84148.6", "0"], ["84149.2", "0.04"], ["84149.3", "0.04"], ["84149.4", "0"], ["84149.5", "0"]], "u": 18759, "seq": 67549819575}, "cts": 1742554951690, "record_time": 1742554951.735263, "EXCHANGE": "BYBIT"}
{"topic": "orderbook.200.BTCUSDT", "ts": 1742554951920, "type": "delta", "data": {"s": "BTCUSDT", "b": [["84115.8", "0.000009"], ["84091.8", "0.171"], ["84090.7", "0"], ["84074.2", "1.050492"], ["84032.2", "0.003181"]], "a": [["84115.9", "0.355797"], ["84117.2", "0.089099"], ["84148.3", "0"], ["84148.4", "0"], ["84148.5", "0.012895"], ["84148.6", "0.012895"], ["84149.2", "0"], ["84149.4", "0.04"], ["84190.2", "0"]], "u": 18760, "seq": 67549819635}, "cts": 1742554951917, "record_time": 1742554951.935527, "EXCHANGE": "BYBIT"}
{"topic": "orderbook.200.BTCUSDT", "ts": 1742554952120, "type": "delta", "data": {"s": "BTCUSDT", "b": [["84115.8", "0"], ["84115", "0.00349"], ["84110.8", "0"], ["84110", "0.0025"], ["84107.4", "0"], ["84106.6", "0.015"], ["84103.8", "0"], ["84103.7", "0.00382"], ["84100.5", "0.033619"], ["84094.7", "0.111076"], ["84084.2", "0.173227"], ["84077.2", "0.291615"], ["84074.2", "1.03761"], ["84074.1", "0.013787"], ["84073.1", "0.012882"], ["84073", "0.012882"], ["84062.6", "0.000531"], ["84055.9", "0"], ["84047.2", "0"], ["84037.3", "0.195"], ["84032.2", "0"]], "a": [["84115.1", "0.329783"], ["84115.7", "0.035664"], ["84115.8", "0.127224"], ["84115.9", "0.1718"], ["84116.1", "0.035664"], ["84116.6", "0"], ["84117", "0"], ["84119.2", "0.243225"], ["84120.1", "0.0025"], ["84120.4", "0.172466"], ["84120.9", "0.001333"], ["84123.5", "0.059"], ["84124.3", "0"], ["84124.5", "0"], ["84124.8", "0"], ["84128.4", "0.272684"], ["84128.5", "0.23774"], ["84129.7", "0.187972"], ["84136.7", "0.299784"], ["84136.8", "0.490366"], ["84149.3", "0.103436"], ["84152.1", "0"], ["84157.1", "1.425816"], ["84157.5", "0.118804"], ["84189", "0"], ["84189.3", "0"], ["84189.8", "0"]], "u": 18761, "seq": 67549819908}, "cts": 1742554952116, "record_time": 1742554952.14164, "EXCHANGE": "BYBIT"}
{"topic": "orderbook.200.BTCUSDT", "ts": 1742554952319, "type": "delta", "data": {"s": "BTCUSDT", "b": [["84115", "0"], ["84114.9", "0"], ["84114.6", "0"], ["84110", "0"], ["84109.6", "0.0025"], ["84100.5", "0.000333"], ["84094.7", "0"], ["84094.3", "0.118605"], ["84085", "0.004757"], ["84084.5", "0"], ["84084.2", "0"], ["84083.8", "0.175714"], ["84080.8", "0"], ["84080.7", "0.112975"], ["84078", "0.11932"], ["84077.8", "0.024002"], ["84077.2", "0"], ["84076.8", "0.27911"], ["84073.1", "0"], ["84073", "0"], ["84072.9", "0.012882"], ["84072.8", "0.012882"], ["84059.4", "0.178328"], ["84058.8", "0.175211"], ["84055.2", "0.202107"], ["84032.2", "0.003181"], ["84031.8", "0.000516"]], "a": [["84114.7", "0.402712"], ["84115", "0.158898"], ["84115.1", "0.171"], ["84115.6", "0.035664"], ["84115.8", "0.00321"], ["84115.9", "0.0008"], ["84116", "0.005942"], ["84116.2", "0"], ["84116.8", "0"], ["84118.8", "0.120211"], ["84119.2", "0.129653"], ["84119.6", "0.000518"], ["84119.7", "0.026276"], ["84120.1", "0"], ["84128.4", "0.166428"], ["84129.3", "0.166128"], ["84129.7", "0.001466"], ["84136.3", "0.296563"], ["84136.7", "0"], ["84138.2", "0"], ["84142.2", "0.023777"], ["84145.8", "0.026989"], ["84147.7", "0.023777"], ["84148.5", "0"], ["84148.6", "0"], ["84148.8", "0.012888"], ["84148.9", "0.012895"], ["84149.3", "0.063436"], ["84149.4", "0"], ["84149.7", "0.04"], ["84149.8", "0.04"], ["84150.2", "0"], ["84156.7", "1.425816"], ["84157.1", "0"], ["84172.8", "2.256989"], ["84187.8", "0"], ["84188.2", "0"], ["84188.4", "0"], ["84188.8", "0"], ["84188.9", "0"]], "u": 18762, "seq": 67549820115}, "cts": 1742554952316, "record_time": 1742554952.342762, "EXCHANGE": "BYBIT"}
{"topic": "orderbook.200.BTCUSDT", "ts": 1742554952520, "type": "delta", "data": {"s": "BTCUSDT", "b": [["84113.2", "0.00321"], ["84109.6", "0"], ["84108.2", "0.003833"], ["84098", "0.029823"], ["84097", "0"], ["84094.3", "0"], ["84085.6", "0"], ["84085", "0"], ["84083.9", "0.143166"], ["84083.8", "0"], ["84083.2", "0"], ["84083", "0.00609"], ["84080.9", "0.112975"], ["84080.7", "0"], ["84077.9", "0.085574"], ["84077", "0.000118"], ["84076.8", "0"], ["84072.9", "0"], ["84072.8", "0"], ["84070.4", "0.014306"], ["84070.3", "0.012883"], ["84067.4", "0"], ["84061.7", "0.138692"], ["84055.2", "0.023779"], ["84042.9", "0.023777"], ["84030.6", "0.01309"], ["84030.2", "0.000083"], ["84029.1", "0.000333"], ["84028.8", "19.187519"], ["84028.6", "0.118804"], ["84028.4", "0.001423"]], "a": [["84113.3", "1.876319"], ["84113.4", "0.035665"], ["84113.9", "0.035665"], ["84114.2", "0.127684"], ["84114.3", "0.035665"], ["84114.7", "0.1714"], ["84115", "0"], ["84115.1", "0"], ["84115.6", "0"], ["84115.7", "0"], ["84116.1", "0"], ["84117.4", "0.004158"], ["84118.3", "0.0025"], ["84118.8", "0"], ["84119.7", "0.023776"], ["84123.1", "0.005"], ["84123.2", "0"], ["84123.3", "0.086615"], ["84123.4", "0.04"], ["84123.5", "0.054"], ["84124.4", "0.04"], ["84125.1", "0.031053"], ["84126.1", "0.04"], ["84129.3", "0.001333"], ["84130.3", "0.059441"], ["84134.4", "0.370591"], ["84134.6", "0.0006"], ["84136.3", "0"], ["84150.1", "0.182893"], ["84155.3", "1.425816"], ["84156.7", "0"], ["84187.6", "0"], ["84187.7", "0"]], "u": 18763, "seq": 67549820439}, "cts": 1742554952517, "record_time": 1742554952.545419, "EXCHANGE": "BYBIT"}
{"topic": "orderbook.200.BTCUSDT", "ts": 1742554952720, "type": "delta", "data": {"s": "BTCUSDT", "b": [["84113.2", "0"], ["84112.4", "0.009572"], ["84108.2", "0.001333"], ["84107.4", "0.0025"], ["84088", "0.057137"], ["84083.9", "0.091879"], ["84083.1", "0.17584"], ["84083", "0.001333"], ["84081", "0.0602"], ["84077.9", "0"], ["84074", "0.175803"], ["84063.6", "0.178331"], ["84028.4", "0"]], "a": [["84112.5", "0.356689"], ["84113.2", "0.088788"], ["84113.3", "0.270792"], ["84113.4", "0"], ["84113.9", "0"], ["84114.2", "0"], ["84114.3", "0"], ["84114.7", "0"], ["84117.5", "0.0025"], ["84118.3", "0"], ["84121.7", "0.005"], ["84123", "0.057989"], ["84123.1", "0"], ["84128.5", "0.059441"], ["84128.7", "0.059399"], ["84130", "0.060936"], ["84134.4", "0.141"], ["84137", "0.113598"], ["84147.3", "2.263261"], ["84154.5", "1.427149"], ["84155.3", "0"], ["84156.3", "0.096366"], ["84172.8", "0"], ["84187.6", "0.118804"], ["84187.7", "1.783159"], ["84187.8", "0.003214"]], "u": 18764, "seq": 67549820607}, "cts": 1742554952717, "record_time": 1742554952.743704, "EXCHANGE": "BYBIT"}
{"topic": "orderbook.200.BTCUSDT", "ts": 1742554952919, "type": "delta", "data": {"s": "BTCUSDT", "b": [["84106.6", "0.005"], ["84104", "0.011333"], ["84092.8", "0.109203"], ["84092.2", "0.053652"], ["84088", "0.001466"], ["84083", "0.188437"], ["84081", "0"], ["84078", "0.000516"], ["84074", "0.059399"], ["84073.9", "0.301567"], ["84064.5", "0.135497"], ["84061.7", "0.003181"], ["84031.6", "19.413789"], ["84030.2", "0"], ["84029.1", "0"], ["84028.8", "0"], ["84028.6", "0"]], "a": [["84112.5", "0.362689"], ["84118", "0.11095"], ["84120.9", "0.016333"], ["84121.7", "0"], ["84123", "0"], ["84123.5", "0.044"], ["84127.8", "0.185048"], ["84130", "0.000333"], ["84136.9", "0.296833"], ["84137", "0"]], "u": 18765, "seq": 67549820646}, "cts": 1742554952914, "record_time": 1742554952.946502, "EXCHANGE": "BYBIT"}
{"topic": "orderbook.200.BTCUSDT", "ts": 1742554953120, "type": "delta", "data": {"s": "BTCUSDT", "b": [["84083.9", "0.136525"]], "a": [["84127.7", "0.258575"], ["84128.4", "0.118804"], ["84146.6", "0.04"], ["84146.7", "0.04"], ["84149.7", "0"], ["84149.8", "0"], ["84187.8", "0"]], "u": 18766, "seq": 67549820669}, "cts": 1742554953111, "record_time": 1742554953.143508, "EXCHANGE": "BYBIT"}
{"topic": "orderbook.200.BTCUSDT", "ts": 1742554953320, "type": "delta", "data": {"s": "BTCUSDT", "b": [["84106.6", "0"], ["84104", "0.016333"], ["84092.8", "0"], ["84092", "0.042741"], ["84083", "0.001333"], ["84073.9", "0"], ["84030.2", "0.000083"], ["84029.1", "0.000333"], ["84028.6", "0.118804"]], "a": [["84112.5", "0.370472"], ["84113.3", "0.269009"], ["84118", "0"], ["84119.2", "0.133229"], ["84127.8", "0"], ["84136.9", "0"], ["84187.8", "0.003214"], ["84188.2", "0.001333"], ["84188.4", "0.013065"]], "u": 18767, "seq": 67549820694}, "cts": 1742554953295, "record_time": 1742554953.343623, "EXCHANGE": "BYBIT"}
{"topic": "orderbook.200.BTCUSDT", "ts": 1742554953520, "type": "delta", "data": {"s": "BTCUSDT", "b": [["84112.4", "0.00321"], ["84083.9", "0.091879"], ["84070.8", "0.013"], ["84070.7", "0.013492"], ["84070.4", "0.001423"], ["84070.3", "0"], ["84031.6", "0"], ["84028.8", "19.413789"]], "a": [["84112.5", "0.37689"], ["84116.6", "0.001333"], ["84145.7", "0.013"], ["84145.8", "0.039877"], ["84147.2", "0.807614"], ["84148.8", "0"], ["84148.9", "0"], ["84188.4", "0"]], "u": 18768, "seq": 67549820735}, "cts": 1742554953517, "record_time": 1742554953.560195, "EXCHANGE": "BYBIT"}
{"topic": "orderbook.200.BTCUSDT", "ts": 1742554953720, "type": "delta", "data": {"s": "BTCUSDT", "b": [], "a": [["84112.5", "0.383302"]], "u": 18769, "seq": 67549820769}, "cts": 1742554953709, "record_time": 1742554953.755181, "EXCHANGE": "BYBIT"}
{"topic": "orderbook.200.BTCUSDT", "ts": 1742554953919, "type": "delta", "data": {"s": "BTCUSDT", "b": [["84064.5", "0"], ["84061.7", "0.138666"], ["84028.4", "0.001423"]], "a": [["84120.3", "0.178316"], ["84127.7", "0.167419"], ["84128.4", "0"]], "u": 18770, "seq": 67549820778}, "cts": 1742554953761, "record_time": 1742554953.935446, "EXCHANGE": "BYBIT"}
{"topic": "orderbook.200.BTCUSDT", "ts": 1742554954119, "type": "delta", "data": {"s": "BTCUSDT", "b": [["84112.4", "0"], ["84112.1", "0"], ["84111.2", "0.000097"], ["84107.4", "0"], ["84106.2", "0.0025"], ["84104", "0.011333"], ["84102.8", "0.005"], ["84098.9", "0"], ["84098", "0"], ["84097.9", "0"], ["84097.8", "0"], ["84096.4", "0"], ["84096.3", "0.000333"], ["84096.2", "0"], ["84096.1", "0"], ["84095.6", "0.001333"], ["84093.5", "0.052"], ["84091.9", "0.066762"], ["84091.2", "0"], ["84089.7", "0"], ["84089.5", "0"], ["84084.7", "0"], ["84084.4", "0.005784"], ["84083.1", "0.171083"], ["84080.9", "0.005944"], ["84077.8", "0"], ["84074.2", "1.025715"], ["84072", "0"], ["84071.9", "0"], ["84071.1", "0.022333"], ["84070.8", "0"], ["84070.7", "0.00061"], ["84070", "0.023035"], ["84069.7", "0.012882"], ["84069.6", "0.183882"], ["84063.9", "0.011896"], ["84063.6", "0"], ["84061.7", "0.003181"], ["84061.3", "0.142708"], ["84059.4", "0"], ["84057.2", "0"], ["84052.8", "0"], ["84046.9", "0"], ["84036", "0"], ["84031.4", "0.624164"], ["84028.8", "0"], ["84028.2", "0.106201"], ["84028", "0.003181"], ["84027.9", "0.001466"], ["84027.8", "0.059399"], ["84027.3", "1.124635"], ["84027.1", "0.000516"], ["84026.5", "0.0045"], ["84025.2", "0.05"], ["84024.9", "0.000333"], ["84024.8", "0.0001"], ["84024.2", "0.001333"], ["84023.8", "0.003181"], ["84023.3", "0.001466"], ["84023.2", "0.033132"], ["84023.1", "19.582068"], ["84023", "0.05"], ["84022.9", "0.000626"]], "a": [["84111.3", "1.946977"], ["84112.2", "0.004565"], ["84112.4", "0.222766"], ["84112.5", "0.1774"], ["84113.1", "0.035665"], ["84113.2", "0"], ["84113.3", "0.098009"], ["84113.5", "0.035665"], ["84116.3", "0.0025"], ["84117.5", "0"], ["84119.2", "0.129653"], ["84120.1", "0.05"], ["84120.2", "0.059399"], ["84120.3", "0.197532"], ["84120.6", "0.01"], ["84120.9", "0.006333"], ["84121.5", "0.04"], ["84123.3", "0.134615"], ["84123.5", "0.067777"], ["84128.5", "0.118885"], ["84128.6", "0.166804"], ["84132.1", "0"], ["84132.6", "0.023777"], ["84134.3", "0.06091"], ["84134.6", "0.030322"], ["84138.1", "0.059962"], ["84139.3", "0.023778"], ["84139.6", "0.059741"], ["84140.9", "0.029722"], ["84143", "0.005944"], ["84146.1", "0.025111"], ["84146.2", "0.059444"], ["84147.3", "0.006272"], ["84150.1", "0.171"], ["84153.3", "0.059444"], ["84153.7", "1.425816"], ["84154.3", "0.023473"], ["84154.5", "0.001333"], ["84162", "0.000118"], ["84167.1", "2.429258"], ["84174.4", "0"], ["84181.4", "0"], ["84184.4", "0"], ["84184.6", "0"], ["84184.7", "0"], ["84184.8", "0"], ["84185.2", "0"], ["84185.4", "0"], ["84185.5", "0"], ["84187.5", "0"], ["84187.6", "0"], ["84187.7", "0"], ["84187.8", "0"], ["84188.2", "0"]], "u": 18771, "seq": 67549821517}, "cts": 1742554954117, "record_time": 1742554954.135788, "EXCHANGE": "BYBIT"}
{"topic": "orderbook.200.BTCUSDT", "ts": 1742554954320, "type": "delta", "data": {"s": "BTCUSDT", "b": [["84111.2", "0"], ["84110.4", "0"], ["84109", "0"], ["84108.2", "0"], ["84107.9", "0"], ["84106.5", "0"], ["84106.2", "0"], ["84105.7", "0"], ["84104.7", "0"], ["84104", "0"], ["84103.7", "0"], ["84102.8", "0"], ["84096.9", "0.0025"], ["84094.4", "0.005"], ["84093.5", "0.005"], ["84093", "0"], ["84092.2", "0"], ["84092.1", "0.000333"], ["84092", "0"], ["84091.9", "0.000618"], ["84091.8", "0"], ["84091.3", "0"], ["84090.7", "0.048"], ["84089.2", "0.001774"], ["84086.3", "0"], ["84086", "0"], ["84085.9", "0"], ["84084.6", "0"], ["84084.4", "0"], ["84083.9", "0.058342"], ["84083.5", "0.044"], ["84083.4", "0.041466"], ["84082.6", "0.000516"], ["84080.5", "0.005866"], ["84079.7", "0.019884"], ["84079.6", "0.019241"], ["84079", "0.04"], ["84078.9", "0.04"], ["84074.2", "0.024004"], ["84074.1", "0"], ["84072", "0.112976"], ["84071.2", "0"], ["84070.1", "0.069715"], ["84069.7", "0"], ["84069.6", "0.171"], ["84067.6", "0.02378"], ["84066.6", "0"], ["84061.3", "0.101954"], ["84059.2", "0.013"], ["84059.1", "0.012883"], ["84057.6", "0.054016"], ["84046.5", "0"], ["84044.8", "0.138673"], ["84039.9", "0"], ["84039.3", "0.118804"], ["84033.9", "0"], ["84031.4", "0.235392"], ["84027.3", "0"], ["84027.1", "0.171516"], ["84026.7", "0.027614"], ["84025.2", "0"], ["84024.6", "0.000626"], ["84024.4", "0.05"], ["84023.2", "0"], ["84023.1", "0"], ["84023", "0"], ["84022.9", "0"], ["84022.6", "0.624214"], ["84022.5", "0.000516"], ["84021.4", "0.048"], ["84021.1", "0.05"], ["84020.7", "0.000333"], ["84020.6", "0.000119"], ["84020.3", "0.039826"], ["84020", "0.001423"], ["84019.7", "0.00009"], ["84019.6", "0.003181"], ["84018.7", "0.001466"], ["84018.5", "0.118804"], ["84018.3", "0.04"], ["84018.2", "0.059399"], ["84017.9", "0.000516"], ["84017.2", "0.05"], ["84016.5", "0.000333"], ["84016.4", "0.0001"]], "a": [["84102", "1.80613"], ["84102.4", "0.035671"], ["84102.8", "0.035671"], ["84102.9", "0.385658"], ["84103.1", "0.098009"], ["84105.8", "0.003923"], ["84107", "0.0025"], ["84107.9", "0.003221"], ["84108.2", "0.001333"], ["84108.3", "0.029903"], ["84108.4", "0.098009"], ["84109", "0.000333"], ["84110.3", "0.134436"], ["84110.4", "0.044518"], ["84110.5", "0.059399"], ["84111.2", "0.001466"], ["84111.3", "0.171"], ["84112", "0.009395"], ["84112.1", "0.003221"], ["84112.2", "0"], ["84112.4", "0.001333"], ["84112.5", "0.024382"], ["84113.1", "0"], ["84113.2", "0.000333"], ["84113.3", "0"], ["84113.4", "0.043561"], ["84113.5", "0"], ["84115", "0.000518"], ["84115.2", "0.04"], ["84115.5", "0.048"], ["84115.8", "0.001466"], ["84116.3", "0.003221"], ["84116.4", "0.048"], ["84116.6", "0.053333"], ["84117.2", "0"], ["84117.4", "0.004248"], ["84119", "0"], ["84119.2", "0.188612"], ["84120.1", "0"], ["84120.3", "0.019216"], ["84120.5", "0.032934"], ["84120.6", "0.015"], ["84120.9", "0.001333"], ["84121.5", "0.041155"], ["84123.1", "0.152789"], ["84123.2", "0.118804"], ["84123.3", "0.048"], ["84123.6", "0"], ["84123.7", "0.025576"], ["84124", "0.02378"], ["84125.7", "0"], ["84125.9", "0.048999"], ["84126.1", "0"], ["84127.6", "0"], ["84127.9", "0.04237"], ["84128", "0.02972"], ["84133.7", "0.004649"], ["84133.9", "0.059445"], ["84136.8", "0"], ["84138", "0.063429"], ["84144", "1.425816"], ["84144.8", "0"], ["84147.2", "0"], ["84147.3", "0.0016"], ["84149.3", "0"], ["84153.7", "0"], ["84161.3", "0.009518"], ["84163", "0.023775"], ["84167.1", "0.172333"], ["84172.8", "2.256925"], ["84177.4", "0"], ["84177.5", "0"], ["84178.8", "0"], ["84179.4", "0"], ["84179.6", "0"], ["84179.8", "0"], ["84180.3", "0"], ["84180.4", "0"], ["84180.5", "0"], ["84180.6", "0"], ["84182.3", "0"], ["84182.8", "0"], ["84183.2", "0"], ["84183.6", "0"], ["84183.8", "0"], ["84184", "0"], ["84184.1", "0"]], "u": 18772, "seq": 67549823249}, "cts": 1742554954313, "record_time": 1742554954.336536, "EXCHANGE": "BYBIT"}
{"topic": "orderbook.200.BTCUSDT", "ts": 1742554954519, "type": "delta", "data": {"s": "BTCUSDT", "b": [["84101.9", "0"], ["84101.1", "0.000018"], ["84096.9", "0"], ["84096.1", "0.0025"], ["84094.4", "0"], ["84093.5", "0.01"], ["84092.7", "0.006466"], ["84091.3", "0.022826"], ["84090.7", "0"], ["84086.5", "0.027277"], ["84084.1", "0.052"], ["84083.9", "0.129757"], ["84082.4", "0.003774"], ["84082.2", "0.04"], ["84080.5", "0"], ["84076.6", "0.060884"], ["84075.4", "0.00906"], ["84074.2", "0.050944"], ["84073.4", "0.005754"], ["84071.1", "0.000333"], ["84070", "0"], ["84069.6", "0.226665"], ["84066.7", "0"], ["84064.4", "0.004702"], ["84062.6", "0.111004"], ["84057.8", "0.001333"], ["84057.7", "0"], ["84057.6", "0.014016"], ["84050.4", "0.135492"], ["84044.8", "0.003181"], ["84024.6", "0"], ["84024.4", "0"], ["84021.5", "0.0003"], ["84021.1", "0"], ["84020.3", "0"], ["84018.6", "0.171"], ["84017.2", "0"], ["84015.8", "0.001333"], ["84015.4", "0.003181"]], "a": [["84101.2", "0.627562"], ["84101.9", "0.668023"], ["84102", "1.539975"], ["84102.9", "0.071342"], ["84105.7", "0.000259"], ["84105.8", "0.00214"], ["84106.2", "0.0025"], ["84106.4", "0.030653"], ["84106.5", "0.001466"], ["84107", "0"], ["84107.1", "0.003906"], ["84108.3", "0.0004"], ["84110.3", "0.172739"], ["84111.4", "0.04"], ["84111.5", "0.048"], ["84111.6", "0.05971"], ["84112.6", "0.024774"], ["84113.2", "0.048333"], ["84113.4", "0.072511"], ["84113.5", "0.04"], ["84117.4", "0.000423"], ["84118.6", "0.057541"], ["84119.2", "0.129653"], ["84121.5", "0"], ["84122.6", "0.118903"], ["84123.3", "0"], ["84123.4", "0"], ["84123.5", "0.023777"], ["84124.4", "0"], ["84125.6", "0.11861"], ["84125.9", "0.000999"], ["84128.6", "0.118804"], ["84130.1", "0"], ["84130.2", "0.092852"], ["84134.4", "0.180471"], ["84143.2", "0.475272"], ["84144", "0.950544"], ["84150.2", "2.256925"], ["84161.1", "0"], ["84163.9", "0.027926"], ["84172.8", "0"], ["84175.5", "0"], ["84175.6", "0"], ["84175.9", "0"], ["84176.2", "0"], ["84176.3", "0"], ["84176.5", "0"], ["84177.1", "0"], ["84177.2", "0"], ["84177.3", "0"]], "u": 18773, "seq": 67549823595}, "cts": 1742554954517, "record_time": 1742554954.5352, "EXCHANGE": "BYBIT"}
{"topic": "orderbook.200.BTCUSDT", "ts": 1742554954720, "type": "delta", "data": {"s": "BTCUSDT", "b": [["84101.1", "0.00439"], ["84093.5", "0.005"], ["84092.7", "0.011466"], ["84086.5", "0.0045"], ["84085.7", "0.0276"], ["84085.6", "0.04"], ["84084.8", "0.048"], ["84081.4", "0.04"], ["84079.7", "0.047663"], ["84076.6", "0"], ["84073.4", "0.000516"], ["84072.6", "0.004757"], ["84069.6", "0.171"], ["84066.9", "0.17869"], ["84065", "0.024325"], ["84062.6", "0.000531"], ["84059.2", "0"], ["84059", "0.012882"], ["84058.8", "0.048"], ["84045.9", "0.040333"], ["84040.9", "0.04"], ["84018.2", "0"], ["84017.9", "0"], ["84016.5", "0"], ["84016.4", "0"], ["84015.8", "0"], ["84015.4", "0"]], "a": [["84101.2", "0.651208"], ["84101.8", "0.003576"], ["84101.9", "0.048905"], ["84102", "0.172783"], ["84102.4", "0"], ["84102.8", "0"], ["84102.9", "0"], ["84108.3", "0"], ["84111.6", "0"], ["84118.6", "0.0001"], ["84125.6", "0"], ["84136.1", "2.262869"], ["84138", "0.063432"], ["84143.2", "1.425816"], ["84144", "0"], ["84149.2", "0.023986"], ["84150.2", "0"], ["84154.3", "0"], ["84171.9", "1.122703"], ["84175.5", "0.001333"], ["84175.9", "0.001466"], ["84176.2", "0.00009"], ["84176.3", "0.000333"], ["84176.5", "0.0045"], ["84177.2", "0.118804"]], "u": 18774, "seq": 67549823765}, "cts": 1742554954716, "record_time": 1742554954.73667, "EXCHANGE": "BYBIT"}
{"topic": "orderbook.200.BTCUSDT", "ts": 1742554954920, "type": "delta", "data": {"s": "BTCUSDT", "b": [["84079.7", "0.019884"], ["84058.8", "0"], ["84018.2", "0.059399"]], "a": [["84101.2", "0.652991"], ["84101.9", "0.075124"], ["84102", "0.171"], ["84109", "0.000909"], ["84123.1", "0"], ["84130.4", "2.256973"], ["84136.1", "0.005944"], ["84139.1", "0.01378"], ["84143.9", "0"], ["84175.6", "0.171"], ["84177.2", "0"]], "u": 18775, "seq": 67549823819}, "cts": 1742554954910, "record_time": 1742554954.947326, "EXCHANGE": "BYBIT"}
{"topic": "orderbook.200.BTCUSDT", "ts": 1742554955120, "type": "delta", "data": {"s": "BTCUSDT", "b": [["84101.1", "0.000018"]], "a": [["84101.2", "0.655131"], ["84105.8", "0"], ["84106.4", "0.048583"], ["84107.8", "0.065873"], ["84109.6", "0.01"], ["84120.6", "0.005"], ["84130.4", "2.256955"], ["84176.5", "0"]], "u": 18776, "seq": 67549823925}, "cts": 1742554955117, "record_time": 1742554955.137228, "EXCHANGE": "BYBIT"}
{"topic": "orderbook.200.BTCUSDT", "ts": 1742554955319, "type": "delta", "data": {"s": "BTCUSDT", "b": [["84101.1", "0"], ["84100.5", "0"], ["84100", "0"], ["84099.8", "0"], ["84099.5", "0.000078"], ["84096.1", "0"], ["84095.5", "0.0025"], ["84092.7", "0.001466"], ["84092.1", "0.010333"], ["84091.3", "0"], ["84087.2", "0.001851"], ["84085.7", "0"], ["84085.6", "0"], ["84084.1", "0"], ["84083.9", "0"], ["84083.5", "0"], ["84083.4", "0.001466"], ["84082.2", "0"], ["84080.3", "0.023685"], ["84079", "0"], ["84078.9", "0"], ["84077.8", "0.04"], ["84074.6", "0.055932"], ["84074.2", "0.001466"], ["84074", "0"], ["84072.6", "0"], ["84072", "0"], ["84067.6", "0.062161"], ["84067", "0.087435"], ["84066.9", "0.000333"], ["84065", "0"], ["84063.9", "0"], ["84061.2", "0"], ["84060.6", "0.122986"], ["84059.1", "0"], ["84059", "0"], ["84058.9", "0.023767"], ["84058", "0"], ["84057.1", "0"], ["84055.8", "0"], ["84055.3", "0.011897"], ["84055.2", "0"], ["84054.7", "0.012883"], ["84054.6", "0.012883"], ["84053.4", "0"], ["84053.1", "0.68928"], ["84053", "1.783159"], ["84051.6", "0"], ["84051.1", "0"], ["84050.4", "0"], ["84047.6", "0.147506"], ["84047.4", "0.029724"], ["84046.4", "0.025247"], ["84046.3", "0.023781"], ["84043", "0.005945"], ["84042.3", "0.023781"], ["84040.9", "0.063781"], ["84040", "0.00006"], ["84031.4", "0"], ["84024.9", "0.235725"], ["84017.9", "0.000516"], ["84016.5", "0.000333"], ["84016.4", "0.0001"], ["84015.8", "0.001333"], ["84015.4", "0.003181"], ["84015.3", "0.0001"], ["84014.1", "0.001466"], ["84013.3", "0.000516"], ["84012.3", "0.000333"], ["84011.8", "19.798655"], ["84011.6", "0.001423"], ["84011.4", "0.102258"], ["84011.3", "0.009"], ["84011.2", "0.003181"], ["84010.3", "0.040705"], ["84010", "0.118146"], ["84009.7", "0.015"]], "a": [["84099.6", "0.565495"], ["84099.7", "0.098009"], ["84099.9", "0.167894"], ["84100", "0.035911"], ["84100.1", "0.0002"], ["84100.3", "0.035671"], ["84100.4", "0.035671"], ["84101.1", "0.002069"], ["84101.2", "0.342"], ["84101.8", "0"], ["84101.9", "0"], ["84102", "0"], ["84103.7", "0.00322"], ["84104", "0.001333"], ["84104.6", "0.0025"], ["84104.7", "0.000333"], ["84106.1", "0.02378"], ["84106.2", "0"], ["84106.4", "0.030653"], ["84107.3", "0.019216"], ["84108.4", "0"], ["84109", "0.000999"], ["84109.6", "0.073604"], ["84110.2", "0.024774"], ["84112.6", "0"], ["84116", "0.103951"], ["84116.6", "0.111271"], ["84117.1", "0.059452"], ["84117.9", "0.118804"], ["84119.7", "0"], ["84120.3", "0"], ["84120.6", "0"], ["84122.6", "0.011897"], ["84123.6", "0.112353"], ["84124", "0"], ["84125.3", "0.023781"], ["84128.9", "0.19851"], ["84130.4", "0"], ["84130.8", "0.023781"], ["84134.9", "0.04"], ["84135", "0.04"], ["84135.8", "0"], ["84141.5", "1.429027"], ["84141.6", "0.171"], ["84143.1", "0.022995"], ["84143.2", "0"], ["84146.6", "0"], ["84146.7", "0"], ["84149.2", "0"], ["84159.1", "0"], ["84164.6", "0"], ["84171.9", "0"], ["84172.8", "2.256955"], ["84175.5", "0"], ["84175.6", "0"], ["84175.9", "0"], ["84176.2", "0"], ["84176.3", "0"]], "u": 18777, "seq": 67549824942}, "cts": 1742554955317, "record_time": 1742554955.335839, "EXCHANGE": "BYBIT"}
{"topic": "orderbook.200.BTCUSDT", "ts": 1742554955520, "type": "delta", "data": {"s": "BTCUSDT", "b": [["84099.5", "0"], ["84097.3", "0.004676"], ["84095.5", "0"], ["84093.5", "0"], ["84092.3", "0.0025"], ["84092.1", "0.000333"], ["84091.1", "0.008209"], ["84088.9", "0.01"], ["84086.7", "0.022828"], ["84084.8", "0"], ["84083.2", "0.074873"], ["84081.4", "0"], ["84080.9", "0"], ["84080", "0.009323"], ["84079.7", "0.043763"], ["84078.6", "0.048"], ["84078.4", "0.04"], ["84077", "0"], ["84074.6", "0.001333"], ["84073.7", "0.025783"], ["84073.6", "0.044"], ["84073.4", "0.040516"], ["84071.9", "0.04"], ["84071.7", "0.04"], ["84070.2", "0"], ["84067.7", "0.059399"], ["84067.6", "0"], ["84067", "0.023062"], ["84066.1", "0.004758"], ["84065.1", "0"], ["84062.8", "0.112976"], ["84061.2", "0.118804"], ["84060.6", "0"], ["84057.6", "0"], ["84055.2", "0.178365"], ["84054.7", "0"], ["84054.6", "0"], ["84052.3", "0.012883"], ["84052.2", "0.012883"], ["84051.3", "0.0016"], ["84047.7", "0.099073"], ["84047.6", "0.011992"], ["84045", "0.128696"], ["84044.8", "0.138695"], ["84041", "0.058669"], ["84026.7", "0"], ["84022.6", "0"], ["84021.5", "0"], ["84017.5", "0.62426"], ["84015.3", "0.0004"], ["84014.7", "0.027901"], ["84011.8", "0"], ["84010.3", "0"], ["84010", "0"], ["84009.7", "0"]], "a": [["84097.4", "0.621459"], ["84097.8", "0.035671"], ["84097.9", "0.035671"], ["84098.2", "0.035671"], ["84099.5", "0.092178"], ["84099.6", "0.17314"], ["84099.9", "0"], ["84100", "0.00024"], ["84100.3", "0"], ["84100.4", "0"], ["84101.1", "0.08677"], ["84101.2", "0.176942"], ["84102.4", "0.0025"], ["84103.1", "0.138009"], ["84103.2", "0.044"], ["84104.6", "0"], ["84105.2", "0.105096"], ["84105.3", "0.178348"], ["84105.5", "0.004757"], ["84105.7", "0.000518"], ["84106.4", "0"], ["84107.1", "0.04951"], ["84107.8", "0"], ["84108", "0.024775"], ["84108.1", "0.04"], ["84108.3", "0.048"], ["84109.6", "0.015"], ["84109.8", "0.048"], ["84110", "0.052"], ["84110.2", "0"], ["84113.4", "0.137585"], ["84114.8", "0.059454"], ["84115.2", "0"], ["84116.6", "0.053333"], ["84121.2", "0.059454"], ["84123.1", "0.113291"], ["84123.6", "0"], ["84125.2", "0"], ["84125.3", "0.083235"], ["84138", "0"], ["84139.3", "1.449594"], ["84140.8", "0.063432"], ["84141.4", "0.47853"], ["84141.5", "0.003211"], ["84143.7", "0.089259"], ["84166.8", "0.016282"], ["84167.5", "0.059453"], ["84170.1", "0"], ["84170.4", "0"], ["84170.5", "0"], ["84171", "0"], ["84171.3", "0"], ["84172.1", "0"], ["84172.3", "0"], ["84172.8", "0"], ["84172.9", "0"], ["84175.2", "0"]], "u": 18778, "seq": 67549825332}, "cts": 1742554955514, "record_time": 1742554955.53595, "EXCHANGE": "BYBIT"}
{"topic": "orderbook.200.BTCUSDT", "ts": 1742554955720, "type": "delta", "data": {"s": "BTCUSDT", "b": [["84097.3", "0.005585"], ["84079.7", "0.068378"], ["84076.9", "0.052"], ["84076.8", "0.04"], ["84075.2", "0.04"], ["84073.7", "0.04656"], ["84067", "0"], ["84055.3", "0.117581"], ["84050.7", "0"], ["84049.1", "0.005942"], ["84047.7", "0"], ["84047.6", "0.147506"], ["84047.3", "0"], ["84044.8", "0.003181"], ["84017.5", "20.44778"], ["84015.5", "0.0003"], ["84015.3", "0.0001"]], "a": [["84097.4", "0.629599"], ["84099.5", "0.074949"], ["84099.6", "0.171"], ["84101.1", "0.127782"], ["84104.8", "0.04"], ["84104.9", "0.048"], ["84106.4", "0.04"], ["84106.6", "0.048"], ["84110.3", "0.094436"], ["84110.4", "0.000518"], ["84111.4", "0"], ["84111.5", "0"], ["84113.2", "0.000333"], ["84113.5", "0"], ["84115.5", "0"], ["84116.4", "0"], ["84116.6", "0.001333"], ["84127.5", "2.256782"], ["84129.5", "0.063429"], ["84139.2", "0.558717"], ["84140.8", "0"], ["84141.4", "0"], ["84154.9", "0.128335"], ["84169", "0"]], "u": 18779, "seq": 67549825441}, "cts": 1742554955702, "record_time": 1742554955.735884, "EXCHANGE": "BYBIT"}
{"topic": "orderbook.200.BTCUSDT", "ts": 1742554955920, "type": "delta", "data": {"s": "BTCUSDT", "b": [["84080", "0.00206"], ["84047.7", "0.087073"], ["84046.4", "0.039113"], ["84011.2", "0"]], "a": [["84097.4", "0.631199"], ["84101.1", "0.151563"], ["84102.7", "0.029727"], ["84105.8", "0.01"], ["84107.1", "0.003906"], ["84109.6", "0.005"], ["84113.4", "0.069185"], ["84115.9", "0"], ["84123.7", "0.0018"], ["84125.1", "0.001333"], ["84127.4", "0.885142"], ["84127.7", "0"], ["84130.4", "0.04"], ["84130.5", "0.04"], ["84134.9", "0"], ["84135", "0"], ["84145.1", "0.04"], ["84164", "1.225618"], ["84167.8", "0"], ["84169.9", "0"]], "u": 18780, "seq": 67549825501}, "cts": 1742554955916, "record_time": 1742554955.935611, "EXCHANGE": "BYBIT"}
{"topic": "orderbook.200.BTCUSDT", "ts": 1742554956119, "type": "delta", "data": {"s": "BTCUSDT", "b": [["84073.6", "0.049806"], ["84052.7", "0.012883"], ["84052.6", "0.183883"], ["84052.3", "0"], ["84052.2", "0"], ["84011.2", "0.003181"]], "a": [["84097.4", "0.631999"], ["84102.9", "0.065874"], ["84105.8", "0.015"], ["84109.6", "0"], ["84112.5", "0"], ["84120.5", "0.026988"], ["84123.1", "0"], ["84129.8", "0.012879"], ["84129.9", "0.012879"], ["84130.2", "0.132685"], ["84130.4", "0"], ["84130.5", "0"], ["84130.7", "0.04"], ["84130.8", "0.063781"], ["84134.4", "0.141"], ["84145.7", "0"], ["84145.8", "0.026989"], ["84167.8", "0.000423"], ["84169.9", "0.059399"]], "u": 18781, "seq": 67549825545}, "cts": 1742554956067, "record_time": 1742554956.157886, "EXCHANGE": "BYBIT"}
{"topic": "orderbook.200.BTCUSDT", "ts": 1742554956320, "type": "delta", "data": {"s": "BTCUSDT", "b": [["84052.9", "0.131804"], ["84052.8", "0.012883"], ["84052.7", "0"], ["84052.6", "0.171"]], "a": [["84097.4", "0.637999"], ["84101", "0.024037"], ["84123.1", "0.07067"], ["84129.3", "0.014333"], ["84129.4", "0.07232"], ["84129.8", "0"], ["84129.9", "0"], ["84130.2", "0.172685"], ["84130.3", "0.099441"], ["84130.7", "0"], ["84130.8", "0.023781"], ["84170.1", "0.118804"]], "u": 18782, "seq": 67549825561}, "cts": 1742554956259, "record_time": 1742554956.348171, "EXCHANGE": "BYBIT"}
{"topic": "orderbook.200.BTCUSDT", "ts": 1742554956519, "type": "delta", "data": {"s": "BTCUSDT", "b": [["84097.3", "0.006385"], ["84091.1", "0.003209"], ["84088.9", "0.015"], ["84078.5", "0.114722"], ["84072.5", "0"], ["84068", "0.187432"], ["84061", "0.293748"], ["84055", "0.000118"], ["84011.3", "0"], ["84011.2", "0"]], "a": [["84103", "0.112395"], ["84113.5", "0.175216"], ["84120.5", "0.321137"], ["84140", "0.000358"], ["84162", "0"], ["84170.1", "0"]], "u": 18783, "seq": 67549825601}, "cts": 1742554956516, "record_time": 1742554957.059695, "EXCHANGE": "BYBIT"}
{"topic": "orderbook.200.BTCUSDT", "ts": 1742554956720, "type": "delta", "data": {"s": "BTCUSDT", "b": [["84079.7", "0.098763"], ["84073.6", "0.044"], ["84070.1", "0.120808"], ["84061.3", "0.170064"], ["84052.9", "0.118804"], ["84052.7", "0.012883"], ["84029.1", "0.00176"], ["84011.4", "0"]], "a": [["84100.9", "0.059399"], ["84101.1", "0.208836"], ["84113.4", "0.112862"], ["84119.2", "0.20215"], ["84129.3", "0.001333"], ["84129.4", "0.059441"], ["84129.8", "0.013"], ["84129.9", "0.012879"], ["84130.2", "0.132685"], ["84130.3", "0.059441"], ["84130.5", "0.04"], ["84130.6", "0.04"], ["84166.8", "0"], ["84167.1", "0"], ["84167.5", "0"], ["84167.8", "0"], ["84169.9", "0"]], "u": 18784, "seq": 67549825640}, "cts": 1742554956663, "record_time": 1742554957.062836, "EXCHANGE": "BYBIT"}
{"topic": "orderbook.200.BTCUSDT", "ts": 1742554956919, "type": "delta", "data": {"s": "BTCUSDT", "b": [["84097.3", "0.00321"], ["84079.7", "0.068378"], ["84078.5", "0.003182"], ["84068", "0"], ["84061", "0"], ["84011.4", "0.102258"], ["84011.3", "0.009"]], "a": [["84099.5", "0"], ["84101.9", "0.001466"], ["84103", "0"], ["84113.5", "0"], ["84120.5", "0.032964"], ["84127.5", "0"], ["84129.6", "0.012879"], ["84129.7", "0.014345"], ["84129.8", "0"], ["84129.9", "0"], ["84130.5", "2.296782"], ["84166.8", "0.016282"], ["84167.1", "0.001333"], ["84167.5", "0.059453"], ["84167.8", "0.000423"]], "u": 18785, "seq": 67549825688}, "cts": 1742554956917, "record_time": 1742554957.065916, "EXCHANGE": "BYBIT"}
{"topic": "orderbook.200.BTCUSDT", "ts": 1742554957120, "type": "delta", "data": {"s": "BTCUSDT", "b": [["84097.3", "0.003351"], ["84077.9", "0.053669"], ["84070.1", "0.069715"], ["84061.3", "0.101954"], ["84011.3", "0"]], "a": [["84098.1", "0.091536"], ["84113.4", "0.069185"], ["84119.2", "0.129653"], ["84127.4", "0"], ["84129.7", "0.01434"], ["84130.2", "0.80474"], ["84167.1", "0.172333"]], "u": 18786, "seq": 67549825713}, "cts": 1742554957102, "record_time": 1742554957.135982, "EXCHANGE": "BYBIT"}
{"topic": "orderbook.200.BTCUSDT", "ts": 1742554957319, "type": "delta", "data": {"s": "BTCUSDT", "b": [["84053", "1.796159"], ["84052.9", "0.131687"], ["84052.8", "0"], ["84052.7", "0"], ["84011.3", "0.009"], ["84011.2", "0.003181"]], "a": [["84101.1", "0.206767"], ["84102.6", "0.112982"], ["84113", "0.000991"], ["84121.8", "0"], ["84128.4", "0.194207"], ["84129.4", "0.072441"], ["84129.5", "0.076303"], ["84129.6", "0"], ["84129.7", "0.001466"], ["84167.8", "0"]], "u": 18787, "seq": 67549825730}, "cts": 1742554957314, "record_time": 1742554957.334909, "EXCHANGE": "BYBIT"}
{"topic": "orderbook.200.BTCUSDT", "ts": 1742554957519, "type": "delta", "data": {"s": "BTCUSDT", "b": [["84080", "0.00006"], ["84079.7", "0.070378"], ["84053", "1.783159"], ["84052.9", "0.118804"], ["84052.7", "0.012883"], ["84052.6", "0.183883"], ["84051.3", "0"], ["84051", "0.003066"]], "a": [["84097.4", "0.634423"], ["84129.4", "0.059441"], ["84129.5", "0.063429"], ["84129.8", "0.013"], ["84129.9", "0.012874"], ["84130.5", "2.256782"], ["84130.6", "0"], ["84130.7", "0.04"], ["84130.8", "0.063781"], ["84167.1", "0"], ["84167.5", "0"]], "u": 18788, "seq": 67549825761}, "cts": 1742554957517, "record_time": 1742554957.540472, "EXCHANGE": "BYBIT"}
{"topic": "orderbook.200.BTCUSDT", "ts": 1742554957720, "type": "delta", "data": {"s": "BTCUSDT", "b": [["84097.3", "0.003621"]], "a": [["84114.7", "0.003575"], ["84146.8", "0.048333"], ["84166.8", "0"]], "u": 18789, "seq": 67549825783}, "cts": 1742554957716, "record_time": 1742554957.747574, "EXCHANGE": "BYBIT"}
{"topic": "orderbook.200.BTCUSDT", "ts": 1742554957919, "type": "delta", "data": {"s": "BTCUSDT", "b": [["84052.9", "0.131804"], ["84052.8", "0.012883"], ["84052.7", "0"], ["84052.6", "0.171"]], "a": [["84129", "0.013"], ["84129.1", "0.012874"], ["84129.8", "0"], ["84129.9", "0"]], "u": 18790, "seq": 67549825793}, "cts": 1742554957898, "record_time": 1742554957.939921, "EXCHANGE": "BYBIT"}
{"topic": "orderbook.200.BTCUSDT", "ts": 1742554958120, "type": "delta", "data": {"s": "BTCUSDT", "b": [["84097.3", "0.004054"], ["84077.9", "0"], ["84073.5", "0.00594"], ["84053", "1.796159"], ["84052.9", "0.131687"], ["84052.8", "0"], ["84010", "0.118146"]], "a": [["84097.4", "0.640423"], ["84102.9", "0"], ["84109", "0.000423"], ["84110.1", "0.065869"], ["84129", "0"], ["84129.2", "0.012874"], ["84130", "0.040333"], ["84130.1", "0.04"], ["84130.7", "0"], ["84130.8", "0.023781"], ["84143.6", "0.048"], ["84166.7", "0"]], "u": 18791, "seq": 67549825827}, "cts": 1742554958109, "record_time": 1742554958.152863, "EXCHANGE": "BYBIT"}
{"topic": "orderbook.200.BTCUSDT", "ts": 1742554958319, "type": "delta", "data": {"s": "BTCUSDT", "b": [["84097.3", "0"], ["84096.5", "0.00349"], ["84092.3", "0"], ["84091.5", "0.0025"], ["84088.9", "0.005"], ["84088.1", "0.01"], ["84079.7", "0.116627"], ["84078.4", "0.093669"], ["84078", "0.11293"], ["84067.5", "0.168292"], ["84060.5", "0.289539"], ["84011.3", "1.133849"], ["84011.2", "0"], ["84010", "0"]], "a": [["84096.6", "0.393042"], ["84096.7", "0.00214"], ["84097.1", "0.035672"], ["84097.2", "0.211484"], ["84097.4", "0.327072"], ["84097.9", "0"], ["84098.1", "0"], ["84098.2", "0"], ["84099.6", "0"], ["84101.6", "0.0025"], ["84102.4", "0"], ["84102.5", "0.111654"], ["84105", "0.01"], ["84105.8", "0.005"], ["84110.1", "0"], ["84113", "0.183246"], ["84114.7", "0"], ["84120", "0.298543"], ["84128.9", "0.21151"], ["84129", "0.012874"], ["84129.1", "0"], ["84129.2", "0"], ["84129.8", "0.04"], ["84129.9", "0.04"], ["84130", "0.000333"], ["84130.1", "0"], ["84138.5", "1.425816"], ["84139.3", "0.023778"], ["84140.2", "0.044"], ["84141.9", "0.049333"], ["84147", "0.052"], ["84165.6", "0"], ["84165.9", "0"], ["84166.4", "0"]], "u": 18792, "seq": 67549826012}, "cts": 1742554958314, "record_time": 1742554958.345664, "EXCHANGE": "BYBIT"}
{"topic": "orderbook.200.BTCUSDT", "ts": 1742554958519, "type": "delta", "data": {"s": "BTCUSDT", "b": [["84088.9", "0"], ["84088.1", "0.015"], ["84078", "0.000516"], ["84070.1", "0.115066"], ["84067.5", "0"], ["84061.3", "0.168801"], ["84060.5", "0"], ["84053", "1.796042"], ["84011.2", "0.003181"], ["84010", "0.118146"], ["84009.7", "0.015"]], "a": [["84097", "0.035672"], ["84097.2", "0.108158"], ["84097.8", "0"], ["84101.1", "0.209767"], ["84102.5", "0"], ["84105", "0.015"], ["84105.8", "0"], ["84113", "0.000991"], ["84120", "0.00024"], ["84134.4", "0.576329"], ["84139.2", "0.139578"], ["84165.6", "0.048"], ["84165.9", "0.000518"]], "u": 18793, "seq": 67549826050}, "cts": 1742554958510, "record_time": 1742554958.5358, "EXCHANGE": "BYBIT"}
{"topic": "orderbook.200.BTCUSDT", "ts": 1742554958720, "type": "delta", "data": {"s": "BTCUSDT", "b": [["84096.5", "0.004371"], ["84070.1", "0.069715"], ["84061.3", "0.101954"], ["84055.2", "0"], ["84010.1", "0.171"]], "a": [["84104.9", "0.051576"], ["84105.2", "0.077819"], ["84105.3", "0"], ["84166.4", "0.005942"]], "u": 18794, "seq": 67549826093}, "cts": 1742554958705, "record_time": 1742554958.736691, "EXCHANGE": "BYBIT"}
{"success": true, "ret_msg": "pong", "conn_id": "4137d158-a774-46db-a7ee-dbdc5eb26575", "op": "ping", "record_time": 1742554958.755197, "EXCHANGE": "BYBIT"}
{"topic": "orderbook.200.BTCUSDT", "ts": 1742554958919, "type": "delta", "data": {"s": "BTCUSDT", "b": [["84055.3", "0.011897"], ["84055.2", "0.178366"], ["84009.7", "0"]], "a": [["84129.5", "0.06343"]], "u": 18795, "seq": 67549826108}, "cts": 1742554958916, "record_time": 1742554958.936575, "EXCHANGE": "BYBIT"}
{"topic": "orderbook.200.BTCUSDT", "ts": 1742554959120, "type": "delta", "data": {"s": "BTCUSDT", "b": [["84096.5", "0.004661"], ["84062.8", "0"], ["84061.7", "0.116169"], ["84053", "1.783159"], ["84052.8", "0.012883"], ["84024.9", "0.000333"], ["84020.7", "0.235725"]], "a": [["84104.9", "0.048"], ["84128.8", "0.012874"], ["84128.9", "0.211384"], ["84129", "0"], ["84129.7", "0.041466"], ["84129.9", "0"], ["84141.8", "0.04"]], "u": 18796, "seq": 67549826156}, "cts": 1742554959112, "record_time": 1742554959.136067, "EXCHANGE": "BYBIT"}
{"topic": "orderbook.200.BTCUSDT", "ts": 1742554959519, "type": "delta", "data": {"s": "BTCUSDT", "b": [["84053.1", "0.70228"], ["84053", "1.796042"], ["84052.9", "0.118804"], ["84052.8", "0"], ["84009.7", "0.015"]], "a": [["84097.4", "0.209072"], ["84110.5", "0.062975"], ["84128.7", "0.072399"], ["84128.9", "0.19851"], ["84129.6", "0.04"], ["84129.8", "0"]], "u": 18797, "seq": 67549826188}, "cts": 1742554959506, "record_time": 1742554959.534922, "EXCHANGE": "BYBIT"}
{"topic": "orderbook.200.BTCUSDT", "ts": 1742554959719, "type": "delta", "data": {"s": "BTCUSDT", "b": [["84096.5", "0.005074"], ["84055.3", "0.117617"], ["84053.1", "0.68928"], ["84053", "1.783159"], ["84052.9", "0.131687"], ["84052.8", "0.012883"], ["84009.7", "0"]], "a": [["84096.6", "0.399042"], ["84104.4", "0.065873"], ["84110.5", "0.059399"], ["84128.7", "0.059399"], ["84128.9", "0.211384"], ["84129.6", "0"], ["84129.8", "0.04"], ["84166.4", "0"]], "u": 18798, "seq": 67549826219}, "cts": 1742554959700, "record_time": 1742554959.735823, "EXCHANGE": "BYBIT"}
{"topic": "orderbook.200.BTCUSDT", "ts": 1742554959919, "type": "delta", "data": {"s": "BTCUSDT", "b": [["84096.5", "0.002972"]], "a": [["84096.6", "0.58409"], ["84097.2", "0"], ["84097.4", "0.038072"], ["84101.1", "0.210283"], ["84117.5", "0.003576"]], "u": 18799, "seq": 67549826283}, "cts": 1742554959917, "record_time": 1742554959.937163, "EXCHANGE": "BYBIT"}
{"topic": "orderbook.200.BTCUSDT", "ts": 1742554960120, "type": "delta", "data": {"s": "BTCUSDT", "b": [["84089.2", "0.001775"], ["84066.9", "0.178699"], ["84061.4", "0.118804"], ["84061.2", "0"], ["84052.9", "0.118804"], ["84052.7", "0.012883"], ["84015.5", "0"], ["84011.8", "0.0003"], ["84010", "0"]], "a": [["84101", "0"], ["84102.6", "0.112987"], ["84102.7", "0.079727"], ["84128.8", "0"], ["84128.9", "0.19851"], ["84129.3", "0.014207"], ["84129.4", "0.072315"], ["84129.7", "0.001466"], ["84129.8", "0"], ["84130.2", "0.84474"], ["84130.3", "0.099441"], ["84140.1", "0.04"], ["84166.4", "0.005942"], ["84166.7", "0.001466"]], "u": 18800, "seq": 67549826342}, "cts": 1742554960114, "record_time": 1742554960.136412, "EXCHANGE": "BYBIT"}
{"topic": "orderbook.200.BTCUSDT", "ts": 1742554960320, "type": "delta", "data": {"s": "BTCUSDT", "b": [["84061.3", "0"], ["84052.9", "0.131804"], ["84052.7", "0"], ["84010", "0.118146"], ["84009.7", "0.015"]], "a": [["84096.6", "0.41309"], ["84129", "0.013"], ["84129.1", "0.012874"], ["84129.3", "0.001333"], ["84129.4", "0.059441"], ["84133.1", "0.356434"], ["84154", "0"], ["84166.7", "0"]], "u": 18801, "seq": 67549826368}, "cts": 1742554960312, "record_time": 1742554960.336068, "EXCHANGE": "BYBIT"}
{"topic": "orderbook.200.BTCUSDT", "ts": 1742554960520, "type": "delta", "data": {"s": "BTCUSDT", "b": [["84096.5", "0.173972"], ["84079.7", "0.070378"], ["84078.4", "0.04"], ["84061.5", "0.023782"], ["84009.7", "0"]], "a": [["84096.6", "0.352042"], ["84097", "0.08733"], ["84099.7", "0"], ["84104.3", "0.024377"], ["84104.4", "0"], ["84129.9", "0.04"], ["84130", "0.040333"], ["84130.2", "0.80474"], ["84130.3", "0.059441"]], "u": 18802, "seq": 67549826415}, "cts": 1742554960517, "record_time": 1742554960.536571, "EXCHANGE": "BYBIT"}
{"topic": "orderbook.200.BTCUSDT", "ts": 1742554960720, "type": "delta", "data": {"s": "BTCUSDT", "b": [["84096.5", "0.174335"], ["84079.3", "0.053669"], ["84061.8", "0.136759"], ["84010", "0"]], "a": [["84096.6", "0.395394"], ["84097", "0.057927"], ["84135.3", "0.003575"], ["84166.4", "0"]], "u": 18803, "seq": 67549826443}, "cts": 1742554960686, "record_time": 1742554960.736045, "EXCHANGE": "BYBIT"}
{"topic": "orderbook.200.BTCUSDT", "ts": 1742554961120, "type": "delta", "data": {"s": "BTCUSDT", "b": [["84096.5", "0.175511"], ["84088.2", "0.015093"]], "a": [["84096.6", "0.513086"], ["84104.9", "0.113872"]], "u": 18804, "seq": 67549826494}, "cts": 1742554961072, "record_time": 1742554961.135948, "EXCHANGE": "BYBIT"}
{"topic": "orderbook.200.BTCUSDT", "ts": 1742554961319, "type": "delta", "data": {"s": "BTCUSDT", "b": [["84096.5", "0.149165"]], "a": [["84096.6", "0.517886"], ["84097.4", "0.035672"]], "u": 18805, "seq": 67549826538}, "cts": 1742554961302, "record_time": 1742554961.336052, "EXCHANGE": "BYBIT"}
{"topic": "orderbook.200.BTCUSDT", "ts": 1742554961520, "type": "delta", "data": {"s": "BTCUSDT", "b": [["84096.5", "0.149765"], ["84052.9", "0.118804"], ["84052.7", "0.012883"], ["84010.1", "0"]], "a": [["84096.6", "0.378968"], ["84103.1", "0.04"], ["84129", "0"], ["84129.1", "0"], ["84129.2", "0.012874"], ["84129.3", "0.014207"], ["84129.9", "0"], ["84130", "0.000333"], ["84130.1", "0.04"], ["84130.2", "0.84474"], ["84166.4", "0.005942"]], "u": 18806, "seq": 67549826573}, "cts": 1742554961507, "record_time": 1742554961.535384, "EXCHANGE": "BYBIT"}
{"topic": "orderbook.200.BTCUSDT", "ts": 1742554961720, "type": "delta", "data": {"s": "BTCUSDT", "b": [["84067", "0.060179"], ["84052.9", "0.131804"], ["84052.7", "0"]], "a": [["84096.6", "0.362842"], ["84104.3", "0"], ["84110.5", "0.062838"], ["84129", "0.013"], ["84129.1", "0.012874"], ["84129.2", "0"], ["84129.3", "0.001333"], ["84129.9", "0.04"], ["84130", "0.040333"], ["84130.1", "0"], ["84130.2", "0.80474"]], "u": 18807, "seq": 67549826612}, "cts": 1742554961716, "record_time": 1742554961.73531, "EXCHANGE": "BYBIT"}
{"topic": "orderbook.200.BTCUSDT", "ts": 1742554961919, "type": "delta", "data": {"s": "BTCUSDT", "b": [], "a": [["84096.6", "0.374842"], ["84105.3", "0.024327"], ["84166.4", "0"]], "u": 18808, "seq": 67549826636}, "cts": 1742554961910, "record_time": 1742554961.934517, "EXCHANGE": "BYBIT"}
{"topic": "orderbook.200.BTCUSDT", "ts": 1742554962119, "type": "delta", "data": {"s": "BTCUSDT", "b": [], "a": [["84096.9", "0.035811"], ["84097", "0.035672"], ["84100", "0.012155"], ["84165.9", "0"]], "u": 18809, "seq": 67549826661}, "cts": 1742554962077, "record_time": 1742554962.134936, "EXCHANGE": "BYBIT"}
{"topic": "orderbook.200.BTCUSDT", "ts": 1742554962319, "type": "delta", "data": {"s": "BTCUSDT", "b": [["84052.9", "0.118804"], ["84052.7", "0.012883"], ["84011.2", "0"]], "a": [["84117.5", "0"], ["84129", "0"], ["84129.2", "0.012874"], ["84129.9", "0"], ["84130.1", "0.04"], ["84165.9", "0.000518"]], "u": 18810, "seq": 67549826675}, "cts": 1742554962259, "record_time": 1742554962.333911, "EXCHANGE": "BYBIT"}
{"topic": "orderbook.200.BTCUSDT", "ts": 1742554962520, "type": "delta", "data": {"s": "BTCUSDT", "b": [["84096.5", "0.160645"]], "a": [["84096.6", "0.376808"], ["84101.1", "0.207283"], ["84105.3", "0"], ["84117.5", "0.003576"]], "u": 18811, "seq": 67549826708}, "cts": 1742554962511, "record_time": 1742554962.535034, "EXCHANGE": "BYBIT"}
{"topic": "orderbook.200.BTCUSDT", "ts": 1742554962720, "type": "delta", "data": {"s": "BTCUSDT", "b": [], "a": [["84100.1", "0"], ["84120.5", "0.026988"], ["84166.4", "0.005942"]], "u": 18812, "seq": 67549826719}, "cts": 1742554962640, "record_time": 1742554962.73497, "EXCHANGE": "BYBIT"}
{"topic": "orderbook.200.BTCUSDT", "ts": 1742554962919, "type": "delta", "data": {"s": "BTCUSDT", "b": [["84096.5", "0.149382"], ["84052.9", "0.131804"], ["84052.7", "0"], ["84011.2", "0.003181"]], "a": [["84096.6", "0.38875"], ["84101.2", "0.171"], ["84104.1", "0.089099"], ["84116", "0.098009"], ["84119.2", "0.096219"], ["84129", "0.013"], ["84129.2", "0"], ["84130", "0.000333"], ["84130.2", "0.84474"], ["84132.8", "0"], ["84145", "0.005942"], ["84149.6", "0"], ["84161.8", "0.005942"], ["84166.4", "0"]], "u": 18813, "seq": 67549826769}, "cts": 1742554962916, "record_time": 1742554962.934881, "EXCHANGE": "BYBIT"}
{"topic": "orderbook.200.BTCUSDT", "ts": 1742554963120, "type": "delta", "data": {"s": "BTCUSDT", "b": [["84096.5", "0.150182"]], "a": [["84096.6", "0.394678"], ["84104.1", "0"], ["84111.4", "0.005942"], ["84117.5", "0"], ["84128.2", "0.005942"], ["84129.9", "0.04"], ["84130", "0.040333"], ["84130.1", "0"], ["84130.2", "0.80474"]], "u": 18814, "seq": 67549826803}, "cts": 1742554963112, "record_time": 1742554963.135414, "EXCHANGE": "BYBIT"}
{"topic": "orderbook.200.BTCUSDT", "ts": 1742554963520, "type": "delta", "data": {"s": "BTCUSDT", "b": [["84096.5", "0.321592"], ["84082.7", "0.003182"], ["84078.1", "0.005942"], ["84065.9", "0.003181"], ["84061.3", "0.005942"], ["84049.1", "0"], ["84044.5", "0.005942"], ["84032.3", "0"], ["84027.7", "0.005942"], ["84011.3", "0"], ["84011.2", "0"]], "a": [["84096.6", "0.406263"], ["84105.2", "0.110836"], ["84105.4", "0.024341"], ["84114.2", "0.000968"], ["84114.4", "0.001007"], ["84114.7", "0.001071"], ["84120.5", "0.030564"], ["84164", "0"], ["84164.1", "0"], ["84165.6", "0"], ["84165.9", "0"]], "u": 18815, "seq": 67549826920}, "cts": 1742554963507, "record_time": 1742554963.54136, "EXCHANGE": "BYBIT"}
{"topic": "orderbook.200.BTCUSDT", "ts": 1742554963720, "type": "delta", "data": {"s": "BTCUSDT", "b": [["84096.5", "0.150661"], ["84081", "0.115685"], ["84070.5", "0.176421"], ["84063.5", "0.287545"], ["84052.9", "0.118804"], ["84052.8", "0"], ["84052.7", "0.012883"], ["84052.6", "0.183883"], ["84011.8", "0"], ["84011.6", "0"], ["84011.4", "0"]], "a": [["84096.6", "0.374248"], ["84098.5", "0.006016"], ["84105.5", "0.121862"], ["84114.2", "0"], ["84114.4", "0"], ["84114.7", "0"], ["84116", "0.275605"], ["84123", "0.2968"], ["84129", "0"], ["84129.1", "0"], ["84129.9", "0"], ["84130", "0.013333"], ["84130.1", "0.012874"], ["84130.9", "0.04"], ["84131", "0.099441"], ["84164", "1.122808"], ["84164.1", "0.118804"]], "u": 18816, "seq": 67549826986}, "cts": 1742554963713, "record_time": 1742554963.735823, "EXCHANGE": "BYBIT"}
{"topic": "orderbook.200.BTCUSDT", "ts": 1742554963919, "type": "delta", "data": {"s": "BTCUSDT", "b": [["84096.5", "0.151911"], ["84081", "0"], ["84070.6", "0.124022"], ["84070.5", "0"], ["84070.1", "0.003181"], ["84063.5", "0"], ["84017.5", "19.137581"], ["84011.8", "0.0003"], ["84011.6", "0.001423"]], "a": [["84105.5", "0.004757"], ["84113.4", "0.111793"], ["84114.9", "0.001119"], ["84116", "0.098009"], ["84122.9", "0.15971"], ["84123", "0"], ["84123.1", "0"], ["84129.5", "0.076304"], ["84129.6", "0.012874"], ["84130", "0.000333"], ["84130.1", "0"]], "u": 18817, "seq": 67549827021}, "cts": 1742554963889, "record_time": 1742554963.935429, "EXCHANGE": "BYBIT"}
{"topic": "orderbook.200.BTCUSDT", "ts": 1742554964120, "type": "delta", "data": {"s": "BTCUSDT", "b": [["84096.5", "0.140031"], ["84080.8", "0.116394"], ["84070.6", "0"], ["84070.3", "0.17831"], ["84063.3", "0.311417"], ["84020.3", "18.513321"], ["84017.5", "0.62426"], ["84012.3", "0"], ["84011.8", "0"], ["84011.6", "0"]], "a": [["84105.3", "0.117183"], ["84113.4", "0.069185"], ["84115.8", "0.182312"], ["84122.8", "0.306161"], ["84122.9", "0"], ["84129.4", "0.072441"], ["84129.6", "0"], ["84130.3", "0.099441"], ["84130.4", "0.04"], ["84130.5", "0"], ["84130.9", "0"], ["84131", "0.059441"], ["84133.2", "2.256803"]], "u": 18818, "seq": 67549827057}, "cts": 1742554964113, "record_time": 1742554964.136764, "EXCHANGE": "BYBIT"}
{"topic": "orderbook.200.BTCUSDT", "ts": 1742554964320, "type": "delta", "data": {"s": "BTCUSDT", "b": [["84096.5", "0.132046"], ["84080.8", "0"], ["84075.6", "0.08555"], ["84073.7", "0"], ["84070.3", "0"], ["84063.3", "0"], ["84052.8", "0.013"], ["84052.6", "0.171"], ["84012.3", "0.000333"], ["84011.8", "0.0003"]], "a": [["84096.6", "0.380248"], ["84105.3", "0"], ["84113.4", "0.113104"], ["84114.9", "0"], ["84115.8", "0.001466"], ["84122.8", "0"], ["84129.4", "0.059441"], ["84129.6", "0.012874"], ["84130.3", "0.059441"], ["84130.5", "0.04"], ["84165.6", "0.048"]], "u": 18819, "seq": 67549827120}, "cts": 1742554964307, "record_time": 1742554964.335491, "EXCHANGE": "BYBIT"}
{"topic": "orderbook.200.BTCUSDT", "ts": 1742554964520, "type": "delta", "data": {"s": "BTCUSDT", "b": [["84096.5", "0.139516"], ["84052.8", "0"], ["84052.7", "0"], ["84052.6", "0.183883"], ["84052.5", "0.012883"], ["84011.6", "0.001423"]], "a": [["84113.4", "0.069185"], ["84116.9", "0.000989"], ["84129.5", "0.06343"], ["84129.6", "0"], ["84129.9", "0.013"], ["84130", "0.013207"], ["84130.4", "0"], ["84130.5", "0"], ["84130.8", "0.063781"], ["84130.9", "0.04"]], "u": 18820, "seq": 67549827167}, "cts": 1742554964516, "record_time": 1742554964.537192, "EXCHANGE": "BYBIT"}
{"topic": "orderbook.200.BTCUSDT", "ts": 1742554964719, "type": "delta", "data": {"s": "BTCUSDT", "b": [["84069.7", "0.069714"], ["84052.7", "0.013"], ["84052.5", "0"], ["84011.6", "0"]], "a": [["84116.9", "0"], ["84118.1", "0.001309"], ["84129.6", "0.013"], ["84129.7", "0.01434"], ["84129.9", "0"], ["84130", "0.000333"], ["84130.5", "0.04"], ["84130.6", "0.04"], ["84130.8", "0.023781"], ["84130.9", "0"], ["84165.6", "0"]], "u": 18821, "seq": 67549827190}, "cts": 1742554964649, "record_time": 1742554964.73482, "EXCHANGE": "BYBIT"}
{"topic": "orderbook.200.BTCUSDT", "ts": 1742554964920, "type": "delta", "data": {"s": "BTCUSDT", "b": [["84052.7", "0"], ["84052.5", "0.012883"]], "a": [["84118.1", "0"], ["84123.1", "0.07067"], ["84129.6", "0"], ["84129.8", "0.012874"], ["84130.5", "0"], ["84130.7", "0.04"]], "u": 18822, "seq": 67549827231}, "cts": 1742554964905, "record_time": 1742554964.937211, "EXCHANGE": "BYBIT"}
{"topic": "orderbook.200.BTCUSDT", "ts": 1742554965119, "type": "delta", "data": {"s": "BTCUSDT", "b": [["84096.5", "0.310516"], ["84079.7", "0.103004"], ["84073.9", "0.519957"], ["84067.8", "0.118804"], ["84066.9", "0.000333"], ["84063.3", "0.089099"], ["84055.2", "0"], ["84052.6", "0.171"], ["84052.4", "0.012883"], ["84048.2", "0.236047"], ["84044.2", "0.199486"], ["84040.5", "3.467761"], ["84020.3", "0"], ["84014.1", "0"], ["84013.3", "0"], ["84012.3", "0"], ["84011.8", "0"]], "a": [["84096.6", "0.378227"], ["84096.7", "0"], ["84096.9", "0"], ["84100.9", "0"], ["84101.1", "0.094033"], ["84101.2", "0"], ["84102.6", "0"], ["84102.7", "0.05"], ["84105.2", "0.077819"], ["84105.4", "0"], ["84105.5", "0"], ["84106.1", "0"], ["84107.3", "0"], ["84107.8", "0.035682"], ["84110.5", "0.059399"], ["84111.7", "0.000078"], ["84113.4", "0.019924"], ["84114.8", "0"], ["84115", "0.001648"], ["84116", "0"], ["84117.1", "0"], ["84117.9", "0"], ["84119.7", "0.01919"], ["84120.5", "0.00321"], ["84121.2", "0"], ["84123", "0.118804"], ["84123.2", "0"], ["84125.3", "0.023781"], ["84129.5", "0"], ["84129.7", "0.001466"], ["84129.8", "0"], ["84130.6", "0"], ["84130.7", "0"], ["84133.2", "0"], ["84133.9", "0"], ["84134.1", "0.013"], ["84134.2", "0.013297"], ["84134.9", "0.04"], ["84135", "0.04"], ["84140.8", "0.06343"], ["84142.9", "0.00214"], ["84154.9", "0"], ["84164", "0"], ["84165.6", "0.048"], ["84165.9", "0.000518"], ["84166.7", "0.001466"], ["84166.8", "0.016282"], ["84167.1", "0.001333"], ["84167.5", "0.059453"], ["84167.8", "0.000423"], ["84169", "0.003575"], ["84169.9", "0.059399"], ["84170", "2.256803"], ["84170.1", "0.118804"], ["84170.4", "0.017845"], ["84170.5", "0.000342"], ["84171", "0.001976"]], "u": 18823, "seq": 67549827439}, "cts": 1742554965116, "record_time": 1742554965.135084, "EXCHANGE": "BYBIT"}
{"topic": "orderbook.200.BTCUSDT", "ts": 1742554965320, "type": "delta", "data": {"s": "BTCUSDT", "b": [["84075.6", "0.213042"], ["84067", "0"], ["84055.3", "0.011897"], ["84048.3", "0.162047"], ["84047.7", "0"], ["84026", "18.59995"], ["84016.7", "1.124777"], ["84014.7", "0"]], "a": [["84098.5", "0"], ["84105.5", "0.112993"], ["84107.8", "0"], ["84107.9", "0.038903"], ["84113.4", "0"], ["84115", "0.000518"], ["84123.1", "0"], ["84130.2", "0.132685"], ["84141.7", "2.256803"], ["84167.1", "0.172333"], ["84170", "0"], ["84171.3", "0.002799"], ["84172.1", "0.000333"], ["84172.9", "3.274911"]], "u": 18824, "seq": 67549827533}, "cts": 1742554965317, "record_time": 1742554965.335074, "EXCHANGE": "BYBIT"}
{"topic": "orderbook.200.BTCUSDT", "ts": 1742554965520, "type": "delta", "data": {"s": "BTCUSDT", "b": [["84084.2", "0.0018"], ["84079.7", "0.101004"], ["84055.5", "0.0016"], ["84051", "0.001466"], ["84044.2", "0.02112"], ["84015.4", "0"], ["84015.3", "0"]], "a": [["84105", "0.020986"], ["84111.7", "0"], ["84112.6", "0.024287"], ["84135.1", "0.06343"], ["84140.8", "0"]], "u": 18825, "seq": 67549827615}, "cts": 1742554965513, "record_time": 1742554965.536237, "EXCHANGE": "BYBIT"}
{"topic": "orderbook.200.BTCUSDT", "ts": 1742554965719, "type": "delta", "data": {"s": "BTCUSDT", "b": [["84096.5", "0.311116"], ["84054.4", "0.013"], ["84054.3", "0.013215"], ["84052.5", "0"], ["84052.4", "0"], ["84015.4", "0.003181"]], "a": [["84102.7", "0"], ["84104.7", "0.050333"], ["84119.5", "0.003519"], ["84133.5", "0.014851"], ["84133.6", "0.012874"], ["84134.1", "0"], ["84134.2", "0.000423"], ["84134.4", "0.616329"], ["84134.5", "0.04"], ["84134.9", "0"], ["84135", "0"], ["84174.1", "0.001095"]], "u": 18826, "seq": 67549827685}, "cts": 1742554965716, "record_time": 1742554965.736435, "EXCHANGE": "BYBIT"}
{"topic": "orderbook.200.BTCUSDT", "ts": 1742554965919, "type": "delta", "data": {"s": "BTCUSDT", "b": [["84096.5", "0.32221"], ["84092.6", "0.02083"], ["84090.3", "0.033202"], ["84090.2", "0.089099"], ["84088.2", "0.032291"], ["84087.2", "0.001941"], ["84087", "0.009586"], ["84084.6", "0.052"], ["84082.9", "0.04"], ["84080.8", "0.089099"], ["84079.7", "0.068378"], ["84079.6", "0"], ["84079.3", "0"], ["84077", "0.059399"], ["84076.9", "0"], ["84076.8", "0"], ["84075.4", "0"], ["84070.2", "0.005945"], ["84069.5", "0.007411"], ["84064", "0.024145"], ["84061.5", "0"], ["84058.9", "0"], ["84056.1", "0.135468"], ["84047.6", "0.011992"], ["84046.4", "0.025247"], ["84030.4", "0.028084"], ["84026", "0"], ["84023.1", "18.887585"], ["84016.7", "0"], ["84016.5", "0"], ["84016.4", "0"], ["84015.8", "0"], ["84015.4", "0"]], "a": [["84096.6", "0.131671"], ["84097", "0"], ["84097.1", "0"], ["84097.4", "0"], ["84101.1", "0.000516"], ["84103.1", "0"], ["84103.2", "0"], ["84104.6", "0.0196"], ["84104.8", "0"], ["84104.9", "0"], ["84105", "0.015"], ["84105.2", "0"], ["84105.5", "0"], ["84106.4", "0"], ["84106.6", "0"], ["84107.1", "0"], ["84107.9", "0.003221"], ["84108.1", "0"], ["84108.3", "0"], ["84109.8", "0"], ["84110", "0"], ["84111", "0.112993"], ["84112", "0"], ["84112.3", "0.048"], ["84112.6", "0"], ["84117.3", "0.003906"], ["84119.5", "0"], ["84122.4", "0.009074"], ["84123.5", "0"], ["84128", "0"], ["84128.5", "0"], ["84129.4", "0"], ["84130.2", "0.209818"], ["84130.3", "0"], ["84131", "0"], ["84132.6", "0"], ["84133.5", "0.001851"], ["84133.6", "0"], ["84134.3", "0.001466"], ["84134.4", "0.48723"], ["84134.5", "0"], ["84134.6", "0.0006"], ["84135.1", "0"], ["84136.1", "0"], ["84138.1", "0.000518"], ["84138.6", "0.025748"], ["84139.3", "0.063778"], ["84139.4", "0.04"], ["84139.6", "0.000297"], ["84141.7", "0"], ["84143.1", "0"], ["84146.5", "0.06793"], ["84148.2", "0.026384"], ["84162.7", "0"], ["84167.5", "0"], ["84175.2", "0.003732"], ["84175.4", "0.05"], ["84175.5", "0.001333"], ["84175.6", "2.256803"], ["84175.9", "0.001466"], ["84176.2", "0.05009"], ["84176.3", "0.000333"], ["84176.5", "0.0045"], ["84177.2", "0.743064"], ["84177.3", "0.05"], ["84177.4", "0.0012"], ["84177.5", "0.133855"], ["84178.6", "0.005942"], ["84178.8", "0.059399"], ["84179.4", "0.003214"], ["84179.8", "0.001851"], ["84180.3", "0.017079"], ["84180.4", "0.100611"], ["84180.5", "0.000333"], ["84180.6", "0.357767"], ["84182", "0.000146"], ["84182.3", "0.118804"], ["84182.8", "0.0036"], ["84183.6", "0.003214"], ["84183.8", "0.001956"], ["84184", "0.001333"], ["84184.4", "0.000518"]], "u": 18827, "seq": 67549828243}, "cts": 1742554965916, "record_time": 1742554965.935413, "EXCHANGE": "BYBIT"}
{"topic": "orderbook.200.BTCUSDT", "ts": 1742554966120, "type": "delta", "data": {"s": "BTCUSDT", "b": [["84096.5", "0.428281"], ["84096", "0.036564"], ["84095.9", "0.089099"], ["84094.9", "0.005942"], ["84090.3", "0.049613"], ["84088.3", "0.048"], ["84088.2", "0.089041"], ["84087.3", "0.023"], ["84085.5", "0.04"], ["84083.5", "0.125459"], ["84083.4", "0.045466"], ["84083.2", "0"], ["84083.1", "0.211083"], ["84082.4", "0"], ["84082.1", "0.04"], ["84081.4", "0.04"], ["84079.7", "0.048078"], ["84078.4", "0"], ["84075.2", "0"], ["84074", "0.118804"], ["84073.6", "0"], ["84073.4", "0.000516"], ["84071.7", "0"], ["84068.9", "0.178366"], ["84064", "0"], ["84061.1", "0.18479"], ["84058.9", "0.13544"], ["84056.1", "0"], ["84048.3", "0"], ["84026.2", "1.12465"], ["84023.1", "0"], ["84018.9", "0.044393"], ["84018.3", "0"], ["84018.2", "0"], ["84017.9", "0"], ["84017.5", "0"]], "a": [["84096.6", "0.073901"], ["84104.6", "0"], ["84104.7", "0.000333"], ["84110.2", "0.000297"], ["84110.3", "0.140955"], ["84111", "0"], ["84111.1", "0.04"], ["84111.2", "0.045466"], ["84116.1", "0.029065"], ["84116.2", "0.048"], ["84116.3", "0.043221"], ["84117.5", "0.04"], ["84118.6", "0.0521"], ["84119.2", "0.07125"], ["84119.7", "0"], ["84120.7", "0.048"], ["84122.9", "0.045701"], ["84123", "0"], ["84125.3", "0"], ["84128.4", "0"], ["84128.7", "0.078589"], ["84128.9", "0.174729"], ["84130.2", "0.132685"], ["84130.8", "0"], ["84138.6", "0"], ["84139.3", "0.023778"], ["84139.4", "0"], ["84140.2", "0"], ["84140.3", "0.012874"], ["84140.4", "0.012874"], ["84140.9", "0"], ["84141.1", "0.04"], ["84141.2", "0.04"], ["84145.1", "0"], ["84146.2", "0"], ["84146.5", "0.0045"], ["84147", "0"], ["84148.2", "0.001466"], ["84149.3", "0.06343"], ["84173.7", "0.05"], ["84174.1", "0"], ["84175.4", "0"], ["84175.6", "0.171"], ["84176.2", "0.00009"], ["84177.3", "0"], ["84177.5", "0.089099"], ["84178.5", "0.001094"], ["84181.3", "2.25685"], ["84181.7", "0.05"], ["84183", "0.040013"], ["84184.1", "0.171"], ["84184.4", "0"]], "u": 18828, "seq": 67549828872}, "cts": 1742554966116, "record_time": 1742554966.135705, "EXCHANGE": "BYBIT"}
{"topic": "orderbook.200.BTCUSDT", "ts": 1742554966320, "type": "delta", "data": {"s": "BTCUSDT", "b": [["84096.2", "0.003774"], ["84096", "0"], ["84095.9", "0"], ["84090.3", "0.033202"], ["84090.2", "0"], ["84085.3", "0.04"], ["84079.7", "0.033678"], ["84078.6", "0"], ["84077.8", "0"], ["84077", "0"], ["84074", "0"], ["84073.9", "0"], ["84071.9", "0"], ["84058.9", "0.135478"], ["84040.5", "0"], ["84019.2", "0.044175"], ["84018.9", "0"], ["84018.3", "0.04"], ["84018.2", "0.059399"], ["84017.9", "0.000516"], ["84017.5", "0.62426"], ["84017.3", "0.031609"], ["84016.8", "0.05"], ["84016.5", "0.000333"], ["84016.4", "0.0001"]], "a": [["84096.6", "0.126563"], ["84109.5", "0.010553"], ["84111.2", "0.051405"], ["84114.9", "0.065864"], ["84115.4", "0.112506"], ["84115.5", "0.291359"], ["84115.7", "0.04"], ["84116", "0.035679"], ["84116.1", "0"], ["84117.5", "0.088"], ["84122.9", "0"], ["84140.1", "0"], ["84141.8", "0"], ["84143.6", "0.06343"], ["84144.5", "2.25685"], ["84146.8", "0.000333"], ["84149.3", "0"], ["84151.1", "0.04"], ["84151.2", "0.044"], ["84156.2", "0.063775"], ["84172.9", "0"], ["84173.7", "0"], ["84176.5", "0.022374"], ["84180.3", "0.017379"], ["84181.3", "0"], ["84183", "0"]], "u": 18829, "seq": 67549829100}, "cts": 1742554966316, "record_time": 1742554966.335498, "EXCHANGE": "BYBIT"}
{"topic": "orderbook.200.BTCUSDT", "ts": 1742554966520, "type": "delta", "data": {"s": "BTCUSDT", "b": [["84080.3", "0"], ["84079.7", "0"], ["84075.6", "0"], ["84070.6", "0.024416"], ["84060.8", "0.013"], ["84060.7", "0.01288"], ["84054.4", "0"], ["84054.3", "0.000333"], ["84048.5", "0.04"], ["84026", "18.887585"], ["84016.6", "0.045125"], ["84016.5", "0"], ["84016.4", "0"]], "a": [["84119.9", "0.024232"], ["84140", "0.013358"], ["84140.1", "0.012877"], ["84140.3", "0"], ["84140.4", "0"], ["84140.8", "0.063431"], ["84143.6", "0"], ["84154.8", "0.023879"], ["84157.7", "0.048"], ["84157.9", "0.052"], ["84183.8", "0"], ["84184", "0"], ["84184.1", "0"]], "u": 18830, "seq": 67549829189}, "cts": 1742554966510, "record_time": 1742554966.535816, "EXCHANGE": "BYBIT"}
{"topic": "orderbook.200.BTCUSDT", "ts": 1742554966719, "type": "delta", "data": {"s": "BTCUSDT", "b": [["84096.5", "0.427481"], ["84060.8", "0.01288"], ["84058.9", "0.135474"], ["84031.6", "19.358415"], ["84026", "0"]], "a": [], "u": 18831, "seq": 67549829221}, "cts": 1742554966700, "record_time": 1742554966.734816, "EXCHANGE": "BYBIT"}
{"topic": "orderbook.200.BTCUSDT", "ts": 1742554966920, "type": "delta", "data": {"s": "BTCUSDT", "b": [["84096.5", "0.431047"], ["84069.7", "0.151935"], ["84060.9", "0.01288"], ["84060.7", "0"], ["84058.9", "0.135468"], ["84031.6", "0"], ["84028.8", "19.358415"]], "a": [["84109.5", "0"], ["84128.5", "0.112576"], ["84139.7", "0.012877"], ["84139.8", "0.012877"], ["84140", "0.000358"], ["84140.1", "0"], ["84140.5", "0.04"], ["84140.6", "0.04"], ["84141.1", "0"], ["84141.2", "0"], ["84183.6", "0"]], "u": 18832, "seq": 67549829261}, "cts": 1742554966914, "record_time": 1742554966.935593, "EXCHANGE": "BYBIT"}
{"topic": "orderbook.200.BTCUSDT", "ts": 1742554967119, "type": "delta", "data": {"s": "BTCUSDT", "b": [["84096.5", "0.428771"], ["84066.1", "0"], ["84016.8", "0.044742"], ["84016.5", "0.000333"]], "a": [["84096.6", "0.126762"], ["84139.6", "0.013174"], ["84139.8", "0"], ["84140.3", "0.04"], ["84140.4", "0.04"], ["84140.5", "0"], ["84140.6", "0"], ["84140.8", "0"], ["84143.6", "0.063431"], ["84183.6", "0.003214"]], "u": 18833, "seq": 67549829315}, "cts": 1742554967094, "record_time": 1742554967.13545, "EXCHANGE": "BYBIT"}
{"topic": "orderbook.200.BTCUSDT", "ts": 1742554967320, "type": "delta", "data": {"s": "BTCUSDT", "b": [["84092.8", "0.023216"], ["84087.1", "0.04"], ["84075.5", "0.035679"], ["84058.9", "0.135473"], ["84016.8", "0"], ["84016.6", "0"], ["84016.5", "0"]], "a": [["84139.5", "0.013"], ["84139.7", "0"], ["84140.8", "0.063431"], ["84143.6", "0"]], "u": 18834, "seq": 67549829378}, "cts": 1742554967317, "record_time": 1742554967.33654, "EXCHANGE": "BYBIT"}
{"topic": "orderbook.200.BTCUSDT", "ts": 1742554967520, "type": "delta", "data": {"s": "BTCUSDT", "b": [["84095.2", "0.0012"], ["84092.8", "0"], ["84089", "0.053662"], ["84088.2", "0.110948"], ["84084.2", "0"], ["84082.9", "0.061964"], ["84075.9", "0.055083"], ["84068.9", "0.287185"], ["84066.5", "0.0016"], ["84055.5", "0"], ["84017.3", "0"]], "a": [["84096.6", "0.12716"], ["84117.9", "0.057248"], ["84124.9", "0.06158"], ["84131.9", "0.119358"], ["84138.4", "0.040333"], ["84138.5", "1.465816"], ["84140.3", "0"], ["84140.4", "0"], ["84158.3", "0.178236"], ["84182.8", "0"], ["84183.6", "0"]], "u": 18835, "seq": 67549829435}, "cts": 1742554967511, "record_time": 1742554967.535851, "EXCHANGE": "BYBIT"}
{"topic": "orderbook.200.BTCUSDT", "ts": 1742554967720, "type": "delta", "data": {"s": "BTCUSDT", "b": [["84096.5", "0.428995"], ["84082.9", "0"], ["84076", "0.016525"], ["84075.9", "0"], ["84068.9", "0.178366"], ["84061.6", "0.013"], ["84061.5", "0.01288"], ["84060.9", "0"], ["84060.8", "0"], ["84017.3", "0.031609"]], "a": [["84096.6", "0.127359"], ["84117.9", "0"], ["84124.9", "0"], ["84131.9", "0"], ["84137.6", "0.013"], ["84137.7", "0.01421"], ["84139.5", "0"], ["84139.6", "0.000297"], ["84173.9", "0.01378"], ["84176.5", "0.0045"], ["84182.8", "0.0036"], ["84183.6", "0.003214"]], "u": 18836, "seq": 67549829475}, "cts": 1742554967716, "record_time": 1742554967.735831, "EXCHANGE": "BYBIT"}
{"topic": "orderbook.200.BTCUSDT", "ts": 1742554967920, "type": "delta", "data": {"s": "BTCUSDT", "b": [["84092", "0.023314"], ["84080.8", "0"], ["84076", "0"], ["84061.6", "0"], ["84061.5", "0"], ["84061.3", "0.018822"], ["84061.2", "0.01288"], ["84058.9", "0.135483"], ["84055", "0.052293"], ["84016.8", "0.044742"], ["84016.6", "0.045125"]], "a": [["84117.1", "0.003576"], ["84119.2", "0.123423"], ["84119.5", "0.118804"], ["84119.6", "0.131886"], ["84137.6", "0"], ["84137.7", "0.001333"], ["84138.3", "0.013"], ["84138.4", "0.01321"], ["84138.5", "1.425816"], ["84139.1", "0.05378"], ["84139.2", "0.179578"], ["84143.7", "0.731339"], ["84182.8", "0"], ["84183.6", "0"]], "u": 18837, "seq": 67549829515}, "cts": 1742554967915, "record_time": 1742554967.935725, "EXCHANGE": "BYBIT"}
{"topic": "orderbook.200.BTCUSDT", "ts": 1742554968120, "type": "delta", "data": {"s": "BTCUSDT", "b": [["84096.5", "0.408244"], ["84061.3", "0.005942"], ["84061.1", "0.19767"]], "a": [["84097.5", "0.000398"], ["84138.3", "0"], ["84138.5", "1.438693"], ["84139.1", "0.01378"], ["84139.3", "0.063778"], ["84175", "1.122662"], ["84182.3", "0"]], "u": 18838, "seq": 67549829542}, "cts": 1742554968112, "record_time": 1742554968.135499, "EXCHANGE": "BYBIT"}
{"topic": "orderbook.200.BTCUSDT", "ts": 1742554968319, "type": "delta", "data": {"s": "BTCUSDT", "b": [["84096.5", "0.237244"], ["84088.6", "0.019461"], ["84061.3", "0.018822"], ["84061.1", "0.18479"], ["84016.6", "0"]], "a": [["84097.5", "0.000597"], ["84138.4", "0.000333"], ["84138.5", "1.438816"], ["84138.6", "0.012882"], ["84139.2", "0.139578"], ["84139.4", "0.04"], ["84163.5", "0.128322"], ["84180.6", "0"], ["84181.7", "0"], ["84182", "0"]], "u": 18839, "seq": 67549829587}, "cts": 1742554968292, "record_time": 1742554968.33464, "EXCHANGE": "BYBIT"}
{"topic": "orderbook.200.BTCUSDT", "ts": 1742554968520, "type": "delta", "data": {"s": "BTCUSDT", "b": [["84096.2", "0"], ["84092.6", "0"], ["84090.3", "0.045952"], ["84088.4", "0.003774"], ["84061.3", "0.005942"], ["84061.2", "0"], ["84061.1", "0.19767"], ["84061", "0.01288"], ["84016.6", "0.045125"]], "a": [["84096.6", "0.298359"], ["84097.5", "0.000796"], ["84117.1", "0"], ["84138.5", "1.425816"], ["84138.6", "0"], ["84138.7", "0.012882"], ["84138.8", "0.012882"], ["84139.3", "0.023778"], ["84139.4", "0"], ["84139.5", "0.04"], ["84139.6", "0.040297"], ["84140.8", "0.066431"]], "u": 18840, "seq": 67549829623}, "cts": 1742554968502, "record_time": 1742554968.535278, "EXCHANGE": "BYBIT"}
{"topic": "orderbook.200.BTCUSDT", "ts": 1742554968719, "type": "delta", "data": {"s": "BTCUSDT", "b": [["84061.4", "0.131804"], ["84061.3", "0.018822"], ["84061.1", "0.18479"], ["84061", "0"], ["84016.5", "0.000333"]], "a": [["84097.5", "0.000995"], ["84118.3", "0.003576"], ["84137.8", "0.013"], ["84137.9", "0.012882"], ["84138.7", "0"], ["84138.8", "0"], ["84154.5", "0.049333"], ["84180.5", "0"]], "u": 18841, "seq": 67549829650}, "cts": 1742554968704, "record_time": 1742554968.734942, "EXCHANGE": "BYBIT"}
{"topic": "orderbook.200.BTCUSDT", "ts": 1742554968920, "type": "delta", "data": {"s": "BTCUSDT", "b": [["84095.2", "0"], ["84092", "0"], ["84075.5", "0"], ["84074.3", "0.03886"], ["84070.6", "0"], ["84069", "0.118804"], ["84067.8", "0"], ["84064.1", "0.023732"], ["84063.4", "0.02673"], ["84061.4", "0.118804"], ["84061.3", "0.005942"], ["84061.1", "0.19767"], ["84061", "0.01288"], ["84058.9", "0.135489"], ["84028.8", "0"], ["84026.2", "0"], ["84026", "19.875768"], ["84016.4", "0.0001"], ["84015.8", "0.001333"], ["84015.4", "0.003181"]], "a": [["84107.8", "0.000297"], ["84115.4", "0.15771"], ["84117.2", "0.01919"], ["84118.3", "0"], ["84124.9", "0.089099"], ["84128.7", "0.059399"], ["84137.8", "0"], ["84137.9", "0"], ["84138.5", "1.438816"], ["84138.6", "0.012882"], ["84139.6", "0.04"], ["84144.5", "0"], ["84148.3", "0.023067"], ["84149.8", "0.113992"], ["84154.8", "0"], ["84155.8", "2.25685"], ["84170.4", "0"], ["84180.4", "0"]], "u": 18842, "seq": 67549829796}, "cts": 1742554968913, "record_time": 1742554968.935355, "EXCHANGE": "BYBIT"}
{"topic": "orderbook.200.BTCUSDT", "ts": 1742554969120, "type": "delta", "data": {"s": "BTCUSDT", "b": [["84096.5", "0.408244"], ["84091.8", "0.023626"], ["84061.5", "0.013"], ["84061.4", "0.131684"], ["84061.1", "0.18479"], ["84061", "0"], ["84058.9", "0.135485"], ["84015.4", "0"]], "a": [["84096.6", "0.127359"], ["84124.6", "0.028959"], ["84138.1", "0.013518"], ["84138.2", "0.012882"], ["84138.5", "1.425816"], ["84138.6", "0"], ["84139", "0.04"], ["84139.1", "0.05378"], ["84139.5", "0"], ["84139.6", "0"], ["84143.7", "0"], ["84144.5", "2.25685"], ["84155.8", "0"], ["84163.5", "0"], ["84180.4", "0.100611"], ["84180.5", "0.000333"]], "u": 18843, "seq": 67549829833}, "cts": 1742554969113, "record_time": 1742554969.135549, "EXCHANGE": "BYBIT"}
{"topic": "orderbook.200.BTCUSDT", "ts": 1742554969320, "type": "delta", "data": {"s": "BTCUSDT", "b": [["84096.5", "0.237244"]], "a": [["84096.6", "0.298359"], ["84138.9", "0.041466"], ["84139.1", "0.01378"]], "u": 18844, "seq": 67549829851}, "cts": 1742554969310, "record_time": 1742554969.335697, "EXCHANGE": "BYBIT"}
{"topic": "orderbook.200.BTCUSDT", "ts": 1742554969519, "type": "delta", "data": {"s": "BTCUSDT", "b": [["84096.5", "0.239602"], ["84061.6", "0.013"], ["84061.5", "0.01288"], ["84061.4", "0.118804"], ["84016.8", "0.044613"], ["84015.8", "0"]], "a": [["84137.6", "0.013"], ["84137.7", "0.014215"], ["84138.1", "0.000518"], ["84138.2", "0"], ["84138.4", "0.040333"], ["84138.5", "1.465816"], ["84138.9", "0.001466"], ["84139", "0"], ["84180.6", "0.357767"]], "u": 18845, "seq": 67549829869}, "cts": 1742554969510, "record_time": 1742554969.534936, "EXCHANGE": "BYBIT"}
{"topic": "orderbook.200.BTCUSDT", "ts": 1742554969719, "type": "delta", "data": {"s": "BTCUSDT", "b": [["84057.6", "0.003575"], ["84016.4", "0"]], "a": [], "u": 18846, "seq": 67549829880}, "cts": 1742554969700, "record_time": 1742554969.735045, "EXCHANGE": "BYBIT"}
{"topic": "orderbook.200.BTCUSDT", "ts": 1742554969920, "type": "delta", "data": {"s": "BTCUSDT", "b": [["84096.5", "0.411202"], ["84061.6", "0"], ["84061.4", "0.131684"], ["84058.9", "0.135503"], ["84016.4", "0.0001"]], "a": [["84096.6", "0.127121"], ["84117.4", "0.003999"], ["84133.1", "0.003211"], ["84137.6", "0"], ["84137.7", "0.001333"], ["84138.1", "0.013518"], ["84138.2", "0.012882"], ["84138.4", "0.000333"], ["84138.5", "1.425816"], ["84138.9", "0.041466"], ["84139", "0.04"], ["84140.8", "0.003"], ["84143.6", "0.063431"], ["84146.7", "0.35325"], ["84158.8", "0.128329"], ["84180.3", "0"], ["84180.4", "0"], ["84180.5", "0"], ["84180.6", "0"]], "u": 18847, "seq": 67549829919}, "cts": 1742554969916, "record_time": 1742554969.935725, "EXCHANGE": "BYBIT"}
{"success": true, "ret_msg": "subscribe", "conn_id": "e0564216-e394-4db7-a56f-f8abea9c84dd", "op": "subscribe", "record_time": 1742555025.291338, "EXCHANGE": "BYBIT"}
{"topic": "orderbook.200.BTCUSDT", "ts": 1742555024320, "type": "snapshot", "data": {"s": "BTCUSDT", "b": [["84101.9", "0.190078"], ["84101.1", "0.000518"], ["84101", "0.000766"], ["84100.5", "0.000333"], ["84100", "0.00006"], ["84099.8", "0.001333"], ["84099.5", "0.003216"], ["84098.5", "0.005706"], ["84097.3", "0.001466"], ["84096.9", "0.0025"], ["84096.7", "0.0011"], ["84096.6", "0.059413"], ["84096.5", "0.001555"], ["84096.3", "0.000333"], ["84095.6", "0.001423"], ["84095.3", "0.003209"], ["84094.1", "0.018857"], ["84093.5", "0.015"], ["84093", "0.000199"], ["84092.9", "0.04"], ["84092.7", "0.001466"], ["84092.5", "0.171"], ["84092.3", "0.023238"], ["84092.1", "0.006278"], ["84091.9", "0.000618"], ["84091.8", "0.05174"], ["84091.6", "0.0006"], ["84091.4", "0.001333"], ["84091.3", "0.052"], ["84091.1", "0.003209"], ["84090.2", "0.059601"], ["84090", "0.000118"], ["84089.9", "0.009387"], ["84089.5", "0.048"], ["84089.4", "0.00389"], ["84089.2", "0.001774"], ["84089.1", "0.005843"], ["84088.8", "0.000179"], ["84088.2", "0.000337"], ["84088", "0.001466"], ["84087.9", "0.059649"], ["84087.8", "0.04"], ["84087.7", "0.04"], ["84087.2", "0.001941"], ["84086.9", "0.003208"], ["84086.5", "0.0045"], ["84086.2", "0.04"], ["84086", "0.04"], ["84084.5", "0.044"], ["84083.7", "0.000333"], ["84083.4", "0.001466"], ["84083.2", "0.103836"], ["84083.1", "0.171083"], ["84083", "0.001333"], ["84082.7", "0.043182"], ["84082.6", "0.040516"], ["84081.7", "0.004615"], ["84080", "0.00006"], ["84079.5", "0.000333"], ["84078.8", "0.002889"], ["84078.5", "0.003182"], ["84078", "0.000516"], ["84076.3", "0.185318"], ["84076.2", "0.059399"], ["84076.1", "0.02024"], ["84075.8", "0.023873"], ["84075.7", "0.519412"], ["84075.3", "0.000333"], ["84075.2", "0.11293"], ["84074.6", "0.001333"], ["84074.5", "0.155603"], ["84074.4", "0.489227"], ["84074.3", "0.021525"], ["84074.2", "0.001466"], ["84073.4", "0.006458"], ["84071.3", "0.009"], ["84071.1", "0.000333"], ["84070.7", "0.00061"], ["84070.4", "0.001423"], ["84070.1", "0.003181"], ["84069.6", "0.171"], ["84069.5", "0.007411"], ["84068.7", "0.000516"], ["84068", "0.0016"], ["84067.7", "0.059399"], ["84066.9", "0.000333"], ["84066.6", "0.169422"], ["84066.5", "0.118804"], ["84066.4", "0.01288"], ["84066.3", "0.01288"], ["84066.2", "0.001333"], ["84065.9", "0.003181"], ["84064.9", "0.001466"], ["84064.5", "0.4"], ["84064.2", "0.001783"], ["84064.1", "0.000516"], ["84063.8", "0.011896"], ["84063.4", "0.003422"], ["84062.7", "1.077426"], ["84062.6", "3.264048"], ["84062", "0.001423"], ["84061.8", "0.00009"], ["84061.7", "0.003181"], ["84061.4", "0.118804"], ["84061.1", "0.171"], ["84060.4", "0.013852"], ["84060.3", "0.001466"], ["84060", "0.00006"], ["84059.5", "0.000516"], ["84058.5", "0.000333"], ["84057.9", "0.048"], ["84057.8", "0.001333"], ["84057.6", "1.108232"], ["84057.5", "3.468167"], ["84057.4", "0.04"], ["84056.6", "0.005942"], ["84056.5", "0.0045"], ["84056", "0.135611"], ["84055.7", "0.001466"], ["84055", "0.000118"], ["84054.9", "0.059915"], ["84054.8", "0.114"], ["84054.3", "0.000333"], ["84053.6", "0.001423"], ["84053.2", "0.003181"], ["84053", "0.100617"], ["84052.9", "0.118804"], ["84052.6", "0.171"], ["84052.2", "0.044"], ["84051.2", "0.00012"], ["84051", "0.001466"], ["84050.2", "0.000516"], ["84050.1", "0.052333"], ["84050", "0.00086"], ["84049.9", "0.04"], ["84049.4", "0.016333"], ["84049", "0.003181"], ["84048.5", "0.04"], ["84048.3", "0.117233"], ["84048.2", "0.236047"], ["84047.6", "0.011992"], ["84047.5", "0.011993"], ["84047.4", "0.029724"], ["84047.1", "0.011993"], ["84047", "0.04"], ["84046.7", "1.783293"], ["84046.4", "0.025247"], ["84046.3", "0.023781"], ["84045.9", "0.040333"], ["84045.6", "0.000516"], ["84045.2", "0.001423"], ["84045", "0.128696"], ["84044.9", "0.118804"], ["84044.8", "0.003181"], ["84044.7", "0.059399"], ["84044.3", "0.290073"], ["84044.2", "0.02112"], ["84044.1", "0.171"], ["84043", "0.005945"], ["84042.3", "0.023781"], ["84041.8", "0.001466"], ["84041.7", "0.000333"], ["84041.3", "0.244392"], ["84041", "0.001849"], ["84040.9", "0.063781"], ["84040.6", "0.003181"], ["84040", "0.00006"], ["84039.8", "0.005942"], ["84039.5", "0.003575"], ["84039.3", "0.118804"], ["84037.6", "0.021653"], ["84037.5", "0.000333"], ["84037.4", "0.000337"], ["84037.3", "11.733984"], ["84037.2", "0.001466"], ["84036.8", "0.001423"], ["84036.4", "0.003697"], ["84035.6", "0.171"], ["84034.2", "0.118804"], ["84033.3", "0.000333"], ["84032.8", "0.059464"], ["84032.6", "0.09051"], ["84032.5", "0.001466"], ["84032.2", "0.003181"], ["84031.8", "0.040516"], ["84030.6", "0.01309"], ["84030.5", "0.027924"], ["84030.2", "0.000083"], ["84029.3", "0.353195"], ["84029.1", "0.000333"], ["84028.6", "0.118804"], ["84028.4", "0.001423"], ["84028.2", "0.106201"], ["84028", "0.003181"], ["84027.9", "0.001466"], ["84027.8", "0.059399"], ["84027.1", "0.171516"], ["84026.5", "0.0045"], ["84025", "0.000199"], ["84024.9", "0.000333"]], "a": [["84102", "0.391356"], ["84102.2", "0.0522"], ["84104.7", "0.011896"], ["84104.8", "0.174"], ["84105.4", "0.006194"], ["84105.6", "0.028976"], ["84105.7", "0.071373"], ["84106.8", "0.005942"], ["84107", "0.0025"], ["84107.9", "0.003216"], ["84108.1", "0.011889"], ["84108.2", "0.001333"], ["84109", "0.000333"], ["84110.4", "0.015518"], ["84110.7", "0.026012"], ["84110.8", "0.059399"], ["84110.9", "0.065673"], ["84111.2", "0.001466"], ["84111.3", "0.178355"], ["84112.1", "0.003217"], ["84112.4", "0.001333"], ["84113.2", "0.000333"], ["84113.3", "0.04"], ["84114", "0.124302"], ["84114.1", "0.167842"], ["84114.7", "0.003787"], ["84115", "0.000518"], ["84115.1", "0.048"], ["84115.4", "0.044"], ["84115.5", "0.178347"], ["84115.7", "0.065867"], ["84115.8", "0.001466"], ["84116.3", "0.003221"], ["84116.5", "0.0012"], ["84116.6", "0.001333"], ["84116.9", "0.001"], ["84117", "0.04"], ["84117.4", "0.000423"], ["84118.3", "0.0401"], ["84118.7", "0.129712"], ["84118.8", "0.048"], ["84119.5", "0.07794"], ["84119.6", "0.003518"], ["84120", "0.04824"], ["84120.1", "0.1"], ["84120.4", "0.001466"], ["84120.5", "0.00321"], ["84120.9", "0.001333"], ["84121.4", "0.003576"], ["84121.6", "0.000333"], ["84121.8", "0.001034"], ["84123.6", "0.005942"], ["84123.7", "0.0018"], ["84124.2", "0.000518"], ["84124.7", "0.003211"], ["84124.8", "0.000297"], ["84125", "0.001763"], ["84125.1", "0.001333"], ["84125.8", "0.000423"], ["84126.3", "0.124831"], ["84126.7", "0.011888"], ["84127", "0.009488"], ["84127.8", "0.165749"], ["84127.9", "0.04237"], ["84128.4", "0.231762"], ["84128.5", "0.097002"], ["84128.7", "0.059399"], ["84128.9", "0.174729"], ["84129", "0.059443"], ["84129.3", "0.001333"], ["84129.7", "0.001466"], ["84130", "0.000333"], ["84131.1", "0.001079"], ["84131.2", "0.258539"], ["84131.3", "0.009"], ["84131.4", "0.059443"], ["84131.7", "0.011896"], ["84132.6", "0.004641"], ["84132.9", "0.531643"], ["84133.1", "0.003211"], ["84133.5", "0.001851"], ["84133.6", "0.118804"], ["84134.2", "0.000423"], ["84134.3", "0.001466"], ["84134.6", "0.0006"], ["84134.7", "0.150451"], ["84134.8", "0.496108"], ["84137.2", "0.005944"], ["84137.3", "0.003211"], ["84137.7", "0.001333"], ["84138", "0.063443"], ["84138.1", "0.000518"], ["84138.4", "0.000333"], ["84138.6", "0.153301"], ["84138.7", "0.118804"], ["84138.9", "0.001466"], ["84139.3", "0.023778"], ["84139.7", "0.01289"], ["84139.8", "0.01289"], ["84139.9", "0.059399"], ["84140", "0.000358"], ["84140.2", "0.011895"], ["84140.4", "0.045942"], ["84140.5", "0.04"], ["84141.5", "0.003211"], ["84141.6", "0.171"], ["84141.9", "0.001333"], ["84142.2", "0.023777"], ["84142.3", "0.089099"], ["84142.6", "0.000423"], ["84142.7", "0.000518"], ["84143", "0.005944"], ["84143.5", "0.001466"], ["84143.7", "1.161087"], ["84143.8", "0.118804"], ["84144", "1.425924"], ["84144.5", "2.271057"], ["84145.3", "0.02146"], ["84145.8", "0.026989"], ["84146", "0.015"], ["84146.1", "0.025111"], ["84146.5", "0.0045"], ["84146.8", "0.000333"], ["84147", "0.0016"], ["84147.4", "0.040518"], ["84147.7", "0.023777"], ["84148.2", "0.001466"], ["84149.2", "0.048"], ["84149.9", "0.118804"], ["84150", "0.004412"], ["84150.1", "0.171"], ["84150.3", "0.001333"], ["84151", "0.000423"], ["84152", "0.059917"], ["84152.8", "0.123288"], ["84152.9", "0.353196"], ["84154.1", "0.048"], ["84154.2", "0.003212"], ["84154.5", "0.001333"], ["84155.2", "0.000333"], ["84156.2", "0.023775"], ["84156.6", "0.000518"], ["84157.1", "0.136271"], ["84157.2", "0.005942"], ["84157.4", "0.001466"], ["84157.5", "0.118804"], ["84158.4", "0.003212"], ["84158.6", "0.171"], ["84158.7", "0.001333"], ["84158.9", "0.0006"], ["84159.4", "0.000513"], ["84159.9", "0.005943"], ["84160", "0.02495"], ["84160.8", "0.052"], ["84161.2", "0.059399"], ["84161.3", "0.009518"], ["84162.1", "0.001466"], ["84162.5", "0.000238"], ["84162.6", "0.003212"], ["84162.9", "0.001333"], ["84163", "0.023775"], ["84163.6", "0.000333"], ["84163.9", "0.178224"], ["84164.1", "0.118804"], ["84164.5", "0.04"], ["84165.6", "0.048"], ["84165.9", "0.000518"], ["84166.7", "0.001466"], ["84166.8", "0.003213"], ["84167.1", "0.172333"], ["84167.8", "0.000423"], ["84169", "0.003575"], ["84169.9", "0.059399"], ["84170.1", "0.118804"], ["84170.5", "0.000342"], ["84170.9", "0.006771"], ["84171", "0.001976"], ["84171.3", "0.002799"], ["84172.1", "0.000333"], ["84174", "0.005942"], ["84175.2", "0.003732"], ["84175.5", "0.001333"], ["84175.6", "0.171"], ["84175.9", "0.001466"], ["84176.1", "0.128303"], ["84176.2", "0.00009"], ["84176.3", "0.000333"], ["84176.5", "0.0045"], ["84177.2", "0.118804"], ["84177.3", "4.42951"], ["84177.4", "0.0012"], ["84177.5", "0.089099"], ["84178.8", "0.059399"], ["84179.1", "0.027866"], ["84179.4", "0.003214"], ["84179.8", "0.001851"], ["84180.3", "0.017079"], ["84180.4", "0.100611"], ["84180.5", "0.000333"], ["84180.6", "0.001466"]], "u": 19109, "seq": 67549850075}, "cts": 1742555024316, "record_time": 1742555025.29258, "EXCHANGE": "BYBIT"}
{"topic": "orderbook.200.BTCUSDT", "ts": 1742555024520, "type": "delta", "data": {"s": "BTCUSDT", "b": [["84092", "0.003"], ["84074.5", "0.274407"], ["84066.5", "0.131804"], ["84066.3", "0"]], "a": [["84102", "0.392156"], ["84121.8", "0"], ["84124.1", "0.035677"], ["84125", "0.005118"], ["84139.6", "0.013"], ["84139.8", "0"]], "u": 19110, "seq": 67549850099}, "cts": 1742555024480, "record_time": 1742555025.293574, "EXCHANGE": "BYBIT"}
{"topic": "orderbook.200.BTCUSDT", "ts": 1742555024719, "type": "delta", "data": {"s": "BTCUSDT", "b": [["84074.5", "0.155603"], ["84040.1", "12.530133"], ["84037.3", "0.195"], ["84024.9", "0"]], "a": [["84102", "0.391585"]], "u": 19111, "seq": 67549850124}, "cts": 1742555024624, "record_time": 1742555025.294262, "EXCHANGE": "BYBIT"}
{"topic": "orderbook.200.BTCUSDT", "ts": 1742555024919, "type": "delta", "data": {"s": "BTCUSDT", "b": [["84069.7", "0.071978"], ["84025", "0"]], "a": [["84121.4", "0"], ["84124", "0.013973"], ["84125", "0.006324"], ["84139.6", "0"], ["84139.7", "0"], ["84139.8", "0.013"], ["84139.9", "0.072289"], ["84140.4", "0.005942"], ["84140.5", "0"], ["84140.6", "0.04"], ["84140.7", "0.04"], ["84149.1", "0.103192"], ["84180.6", "0"]], "u": 19112, "seq": 67549850152}, "cts": 1742555024904, "record_time": 1742555025.294778, "EXCHANGE": "BYBIT"}
{"topic": "orderbook.200.BTCUSDT", "ts": 1742555025120, "type": "delta", "data": {"s": "BTCUSDT", "b": [["84101.9", "0.2409"], ["84091.8", "0.086484"], ["84088.7", "0.123566"], ["84078.2", "0.17284"], ["84071.2", "0.310289"], ["84027.8", "0"], ["84027.1", "0"], ["84026.5", "0"]], "a": [["84110.9", "0.093587"], ["84113.2", "0.11495"], ["84114.6", "0.003576"], ["84122.2", "0.001128"], ["84123.7", "0.17633"], ["84125", "0.005118"], ["84130.7", "0.31116"], ["84180.3", "0"], ["84180.4", "0"], ["84180.5", "0"]], "u": 19113, "seq": 67549850209}, "cts": 1742555025109, "record_time": 1742555025.295289, "EXCHANGE": "BYBIT"}
{"topic": "orderbook.200.BTCUSDT", "ts": 1742555025319, "type": "delta", "data": {"s": "BTCUSDT", "b": [["84091.8", "0.055881"], ["84088.7", "0"], ["84078.2", "0"], ["84071.2", "0"], ["84066.5", "0.118804"], ["84066.4", "0"], ["84066.1", "0.013"], ["84066", "0.012881"], ["84040.1", "13.096951"], ["84027.8", "0.059399"], ["84027.1", "0.000516"]], "a": [["84110.9", "0.067441"], ["84112.8", "0.000099"], ["84113.2", "0.000333"], ["84114.6", "0"], ["84116.9", "0"], ["84122.2", "0"], ["84123.7", "0.0018"], ["84130.7", "0"], ["84180.3", "0.017079"], ["84180.4", "0.100611"], ["84180.5", "0.000333"]], "u": 19114, "seq": 67549850264}, "cts": 1742555025299, "record_time": 1742555025.339147, "EXCHANGE": "BYBIT"}
{"topic": "orderbook.200.BTCUSDT", "ts": 1742555025520, "type": "delta", "data": {"s": "BTCUSDT", "b": [["84101.9", "0.248054"], ["84066.7", "0.013"], ["84066.6", "0.182302"], ["84066.1", "0"], ["84066", "0"], ["84027.1", "0.171516"], ["84026.5", "0.0045"]], "a": [["84102", "0.397585"]], "u": 19115, "seq": 67549850297}, "cts": 1742555025517, "record_time": 1742555025.535324, "EXCHANGE": "BYBIT"}
{"topic": "orderbook.200.BTCUSDT", "ts": 1742555025720, "type": "delta", "data": {"s": "BTCUSDT", "b": [], "a": [["84102", "0.403585"]], "u": 19116, "seq": 67549850325}, "cts": 1742555025715, "record_time": 1742555025.736326, "EXCHANGE": "BYBIT"}
{"topic": "orderbook.200.BTCUSDT", "ts": 1742555025920, "type": "delta", "data": {"s": "BTCUSDT", "b": [["84066.7", "0"], ["84066.6", "0.169422"], ["84066.4", "0.013"], ["84066.3", "0.01288"], ["84026.5", "0"]], "a": [["84107.7", "0.003576"], ["84139.7", "0.013"], ["84139.8", "0.01289"], ["84139.9", "0.059399"], ["84140.5", "0.04"], ["84140.7", "0"], ["84180.4", "0"], ["84180.5", "0"]], "u": 19117, "seq": 67549850338}, "cts": 1742555025899, "record_time": 1742555025.955838, "EXCHANGE": "BYBIT"}
{"topic": "orderbook.200.BTCUSDT", "ts": 1742555026120, "type": "delta", "data": {"s": "BTCUSDT", "b": [["84075.8", "0"], ["84071.5", "0.022887"]], "a": [["84102", "0.407161"], ["84107.7", "0"], ["84180.4", "0.100611"]], "u": 19118, "seq": 67549850364}, "cts": 1742555026104, "record_time": 1742555026.145993, "EXCHANGE": "BYBIT"}
{"topic": "orderbook.200.BTCUSDT", "ts": 1742555026319, "type": "delta", "data": {"s": "BTCUSDT", "b": [["84066.8", "0.013"], ["84066.7", "0.01288"], ["84066.4", "0"], ["84066.3", "0"], ["84056.1", "0.13558"], ["84056", "0"]], "a": [["84102", "0.403585"]], "u": 19119, "seq": 67549850390}, "cts": 1742555026310, "record_time": 1742555026.340149, "EXCHANGE": "BYBIT"}
{"topic": "orderbook.200.BTCUSDT", "ts": 1742555026519, "type": "delta", "data": {"s": "BTCUSDT", "b": [["84066.8", "0"], ["84066.7", "0"], ["84066.3", "0.013"], ["84066.2", "0.014213"], ["84026.5", "0.0045"]], "a": [["84111.7", "0.003576"], ["84139.7", "0"], ["84139.9", "0.072289"], ["84140.5", "0"], ["84140.7", "0.04"], ["84155.7", "0.02334"], ["84160", "0.00024"], ["84180.4", "0"]], "u": 19120, "seq": 67549850426}, "cts": 1742555026515, "record_time": 1742555026.536497, "EXCHANGE": "BYBIT"}
{"topic": "orderbook.200.BTCUSDT", "ts": 1742555026720, "type": "delta", "data": {"s": "BTCUSDT", "b": [["84066.3", "0"], ["84066.1", "0.01288"], ["84040.1", "0"], ["84037.3", "13.728751"], ["84025.1", "1.124664"]], "a": [["84140.5", "0.04"], ["84140.7", "0"]], "u": 19121, "seq": 67549850440}, "cts": 1742555026688, "record_time": 1742555026.736429, "EXCHANGE": "BYBIT"}
{"topic": "orderbook.200.BTCUSDT", "ts": 1742555026920, "type": "delta", "data": {"s": "BTCUSDT", "b": [["84066.2", "0.014333"], ["84040.1", "14.143465"], ["84037.3", "0.195"], ["84025.1", "0"]], "a": [["84111.7", "0"], ["84127", "0.013064"], ["84139.7", "0.013"], ["84139.9", "0.059399"]], "u": 19122, "seq": 67549850455}, "cts": 1742555026913, "record_time": 1742555027.006167, "EXCHANGE": "BYBIT"}
{"topic": "orderbook.200.BTCUSDT", "ts": 1742555027120, "type": "delta", "data": {"s": "BTCUSDT", "b": [["84101.9", "0.246658"]], "a": [["84106.5", "0.001466"], ["84125", "0.001763"], ["84180.3", "0"]], "u": 19123, "seq": 67549850483}, "cts": 1742555027110, "record_time": 1742555027.190616, "EXCHANGE": "BYBIT"}
{"topic": "orderbook.200.BTCUSDT", "ts": 1742555027319, "type": "delta", "data": {"s": "BTCUSDT", "b": [["84066.6", "0.182422"], ["84066.5", "0.131684"], ["84066.2", "0.001333"], ["84066.1", "0"], ["84040.1", "0"], ["84037.3", "14.338465"], ["84025.1", "1.124664"], ["84025", "0.000199"]], "a": [["84128.3", "0.001079"], ["84131.1", "0"]], "u": 19124, "seq": 67549850497}, "cts": 1742555027312, "record_time": 1742555027.33534, "EXCHANGE": "BYBIT"}
{"topic": "orderbook.200.BTCUSDT", "ts": 1742555027520, "type": "delta", "data": {"s": "BTCUSDT", "b": [["84040.1", "14.143465"], ["84037.3", "0.195"], ["84025", "0"]], "a": [["84145.8", "0.380193"], ["84152.9", "0"], ["84180.3", "0.017079"]], "u": 19125, "seq": 67549850513}, "cts": 1742555027463, "record_time": 1742555027.537194, "EXCHANGE": "BYBIT"}
{"topic": "orderbook.200.BTCUSDT", "ts": 1742555027719, "type": "delta", "data": {"s": "BTCUSDT", "b": [["84066.6", "0.182302"], ["84041.3", "0.009"], ["84037.6", "0.257045"]], "a": [["84102", "0.397651"], ["84139.7", "0"], ["84139.9", "0.072289"], ["84140.5", "0"], ["84140.7", "0.04"], ["84152.8", "0.001466"], ["84180.4", "0.100611"]], "u": 19126, "seq": 67549850538}, "cts": 1742555027706, "record_time": 1742555027.735051, "EXCHANGE": "BYBIT"}
{"topic": "orderbook.200.BTCUSDT", "ts": 1742555027919, "type": "delta", "data": {"s": "BTCUSDT", "b": [["84066.6", "0.169422"], ["84066.5", "0.118804"], ["84066.3", "0.013"], ["84066.2", "0.014213"], ["84025.1", "0"]], "a": [["84102.4", "0.005815"], ["84110.7", "0.001783"], ["84180.4", "0"]], "u": 19127, "seq": 67549850568}, "cts": 1742555027916, "record_time": 1742555027.934727, "EXCHANGE": "BYBIT"}
{"topic": "orderbook.200.BTCUSDT", "ts": 1742555028120, "type": "delta", "data": {"s": "BTCUSDT", "b": [["84101.9", "0.241749"], ["84088.4", "0.111799"], ["84078.6", "0.177098"], ["84066.6", "0.182422"], ["84066.5", "0.131684"], ["84066.3", "0"], ["84066.2", "0.001333"], ["84026.5", "0"]], "a": [["84102", "0.379253"], ["84102.1", "0.0002"], ["84113.6", "0.11911"], ["84123.4", "0.184914"], ["84139.7", "0.013"], ["84139.9", "0.059399"], ["84140.5", "0.04"], ["84140.7", "0"], ["84179.1", "0"], ["84179.4", "0"], ["84179.8", "0"], ["84180.3", "0"]], "u": 19128, "seq": 67549850611}, "cts": 1742555028117, "record_time": 1742555028.13649, "EXCHANGE": "BYBIT"}
{"topic": "orderbook.200.BTCUSDT", "ts": 1742555028320, "type": "delta", "data": {"s": "BTCUSDT", "b": [["84091.8", "0.082436"], ["84069.5", "0.300686"]], "a": [["84102", "0.399253"], ["84123.3", "0.070763"], ["84124", "0"], ["84132.5", "0.277983"], ["84178.8", "0"]], "u": 19129, "seq": 67549850636}, "cts": 1742555028303, "record_time": 1742555028.336189, "EXCHANGE": "BYBIT"}
{"topic": "orderbook.200.BTCUSDT", "ts": 1742555028520, "type": "delta", "data": {"s": "BTCUSDT", "b": [["84069.7", "0.150963"], ["84066.6", "0.169422"], ["84066.5", "0.118804"], ["84066.3", "0.013"], ["84066.2", "0.014213"], ["84027.1", "0"]], "a": [["84127", "0.009488"], ["84139.7", "0"], ["84139.9", "0.072289"], ["84140.5", "0"], ["84140.7", "0.04"], ["84178.8", "0.059399"]], "u": 19130, "seq": 67549850654}, "cts": 1742555028510, "record_time": 1742555028.576668, "EXCHANGE": "BYBIT"}
{"topic": "orderbook.200.BTCUSDT", "ts": 1742555028719, "type": "delta", "data": {"s": "BTCUSDT", "b": [["84101.9", "0.190927"], ["84091.8", "0.055881"], ["84088.4", "0"], ["84078.6", "0"], ["84069.5", "0.007411"], ["84066.6", "0.182422"], ["84066.5", "0.131684"], ["84066.3", "0"], ["84066.2", "0.001333"], ["84027.1", "0.000516"], ["84026.5", "0.0045"], ["84025.1", "1.124664"]], "a": [["84102", "0.407036"], ["84110.7", "0"], ["84113.6", "0"], ["84123.4", "0"], ["84124.8", "0.003873"], ["84126.9", "0.001079"], ["84128.3", "0"], ["84132.5", "0"], ["84139.7", "0.013"], ["84139.9", "0.059399"], ["84140.5", "0.04"], ["84140.7", "0"], ["84179.1", "0.027866"], ["84179.4", "0.003214"], ["84179.8", "0.001851"]], "u": 19131, "seq": 67549850691}, "cts": 1742555028716, "record_time": 1742555028.768362, "EXCHANGE": "BYBIT"}
{"topic": "orderbook.200.BTCUSDT", "ts": 1742555028919, "type": "delta", "data": {"s": "BTCUSDT", "b": [["84069.7", "0.071978"], ["84027.1", "0.171516"]], "a": [["84123.3", "0"], ["84180.3", "0.017079"]], "u": 19132, "seq": 67549850701}, "cts": 1742555028915, "record_time": 1742555028.935019, "EXCHANGE": "BYBIT"}
{"topic": "orderbook.200.BTCUSDT", "ts": 1742555029120, "type": "delta", "data": {"s": "BTCUSDT", "b": [["84066.8", "0.013"], ["84066.7", "0.01288"], ["84066.6", "0.169422"], ["84066.5", "0.118804"], ["84026.5", "0"], ["84025.1", "0"]], "a": [["84102.4", "0"], ["84139.7", "0"], ["84139.8", "0"], ["84139.9", "0.072289"], ["84140", "0.013248"], ["84140.5", "0"], ["84140.6", "0"], ["84140.7", "0.04"], ["84140.8", "0.04"], ["84176.1", "0"], ["84180.4", "0.100611"], ["84180.5", "0.000333"], ["84180.6", "0.001466"], ["84181.4", "1.783293"]], "u": 19133, "seq": 67549850731}, "cts": 1742555029066, "record_time": 1742555029.135519, "EXCHANGE": "BYBIT"}
{"topic": "orderbook.200.BTCUSDT", "ts": 1742555029319, "type": "delta", "data": {"s": "BTCUSDT", "b": [["84101.9", "0.361927"], ["84066.8", "0"], ["84066.6", "0.182302"], ["84026.5", "0.0045"]], "a": [["84105.6", "0.047205"], ["84107.4", "0.005864"], ["84108.2", "0.072703"], ["84120", "0.051816"], ["84124", "0.014039"], ["84124.8", "0.000297"], ["84139.9", "0.059399"], ["84140.1", "0.01289"], ["84140.7", "0"], ["84140.9", "0.04"], ["84151.9", "0.034278"], ["84180.4", "0"], ["84180.5", "0"], ["84180.6", "0"], ["84181.4", "0"]], "u": 19134, "seq": 67549850772}, "cts": 1742555029309, "record_time": 1742555029.337894, "EXCHANGE": "BYBIT"}
{"topic": "orderbook.200.BTCUSDT", "ts": 1742555029520, "type": "delta", "data": {"s": "BTCUSDT", "b": [["84101.9", "0.191165"]], "a": [["84102", "0.413036"], ["84144.5", "0.013823"], ["84155.8", "2.257374"], ["84180.3", "0"]], "u": 19135, "seq": 67549850799}, "cts": 1742555029472, "record_time": 1742555029.630744, "EXCHANGE": "BYBIT"}
{"topic": "orderbook.200.BTCUSDT", "ts": 1742555029720, "type": "delta", "data": {"s": "BTCUSDT", "b": [["84101.9", "0.191023"]], "a": [["84102", "0.412236"], ["84111.9", "0.02421"], ["84143.7", "0.097174"], ["84179.8", "0"]], "u": 19136, "seq": 67549850830}, "cts": 1742555029710, "record_time": 1742555029.815635, "EXCHANGE": "BYBIT"}
{"topic": "orderbook.200.BTCUSDT", "ts": 1742555029919, "type": "delta", "data": {"s": "BTCUSDT", "b": [["84099.7", "0.011896"], ["84074.5", "0.274407"], ["84026.5", "0"]], "a": [["84102", "0.3203"], ["84102.2", "0"], ["84104.7", "0.0522"], ["84104.8", "0.171"], ["84105.6", "0.04726"], ["84107.4", "0"], ["84108.1", "0"], ["84108.7", "0.005822"], ["84110.8", "0"], ["84110.9", "0.013934"], ["84111.3", "0"], ["84111.9", "0"], ["84115.5", "0"], ["84120", "0.04824"], ["84126.3", "0"], ["84129", "0"], ["84131.4", "0"], ["84137.2", "0"], ["84147.4", "0.042301"], ["84179.8", "0.001851"], ["84180.3", "0.017079"], ["84180.4", "0.100611"], ["84180.5", "0.000333"], ["84180.6", "0.001466"], ["84181.4", "1.783293"], ["84181.5", "0.05"], ["84182.3", "0.118804"], ["84182.8", "0.0012"], ["84183.6", "0.003214"]], "u": 19137, "seq": 67549850911}, "cts": 1742555029917, "record_time": 1742555029.93644, "EXCHANGE": "BYBIT"}
{"topic": "orderbook.200.BTCUSDT", "ts": 1742555030120, "type": "delta", "data": {"s": "BTCUSDT", "b": [["84089.2", "0.001775"], ["84066.7", "0"], ["84066.6", "0.169422"], ["84066.5", "0.131684"], ["84066.4", "0.01288"]], "a": [["84126.3", "0.124848"], ["84139.5", "0.013"], ["84139.6", "0.01289"], ["84140", "0.000358"], ["84140.1", "0"], ["84140.3", "0.04"], ["84140.4", "0.045942"], ["84140.8", "0"], ["84140.9", "0"], ["84183.6", "0"]], "u": 19138, "seq": 67549850964}, "cts": 1742555030116, "record_time": 1742555030.149915, "EXCHANGE": "BYBIT"}
{"topic": "orderbook.200.BTCUSDT", "ts": 1742555030319, "type": "delta", "data": {"s": "BTCUSDT", "b": [["84066.8", "0.013"], ["84066.7", "0.01288"], ["84066.5", "0.118804"], ["84066.4", "0"], ["84027.1", "0"]], "a": [["84102", "0.3263"], ["84113.7", "0.023798"], ["84124.5", "0.003576"], ["84143.7", "0.589878"], ["84182.3", "0"], ["84182.8", "0"]], "u": 19139, "seq": 67549850999}, "cts": 1742555030313, "record_time": 1742555030.340182, "EXCHANGE": "BYBIT"}
{"topic": "orderbook.200.BTCUSDT", "ts": 1742555030520, "type": "delta", "data": {"s": "BTCUSDT", "b": [["84101.9", "0.191623"], ["84099.7", "0.014896"], ["84092", "0"], ["84091.8", "0.086064"], ["84088.3", "0.123893"], ["84077.8", "0.177445"], ["84070.8", "0.287601"], ["84027.9", "0"], ["84027.8", "0"]], "a": [["84104.8", "0.174"], ["84110.9", "0.049057"], ["84112.8", "0.122979"], ["84123.3", "0.165685"], ["84130.3", "0.280415"], ["84181.4", "0"], ["84181.5", "0"]], "u": 19140, "seq": 67549851036}, "cts": 1742555030516, "record_time": 1742555030.536909, "EXCHANGE": "BYBIT"}
{"topic": "orderbook.200.BTCUSDT", "ts": 1742555030719, "type": "delta", "data": {"s": "BTCUSDT", "b": [["84101.9", "0.191385"], ["84070.9", "0.159822"], ["84069.7", "0"], ["84066.8", "0"], ["84066.6", "0.182302"], ["84027.9", "0.001466"]], "a": [["84139.4", "0.01289"], ["84139.5", "0.01289"], ["84139.6", "0"], ["84140.2", "0.051895"], ["84140.4", "0.005942"]], "u": 19141, "seq": 67549851076}, "cts": 1742555030666, "record_time": 1742555030.735614, "EXCHANGE": "BYBIT"}
{"topic": "orderbook.200.BTCUSDT", "ts": 1742555030919, "type": "delta", "data": {"s": "BTCUSDT", "b": [["84066.7", "0"], ["84066.6", "0.169422"], ["84066.5", "0.131804"], ["84066.4", "0.01288"]], "a": [], "u": 19142, "seq": 67549851093}, "cts": 1742555030877, "record_time": 1742555030.935336, "EXCHANGE": "BYBIT"}
{"topic": "orderbook.200.BTCUSDT", "ts": 1742555031120, "type": "delta", "data": {"s": "BTCUSDT", "b": [["84101.9", "0.021185"], ["84091.8", "0.055881"], ["84088.3", "0"], ["84077.8", "0"], ["84074.5", "0.155603"], ["84070.8", "0"], ["84027.8", "0.059399"], ["84027.1", "0.000516"], ["84026.5", "0.0045"]], "a": [["84104.4", "0.07893"], ["84104.5", "0.089099"], ["84104.7", "0"], ["84110.9", "0.013934"], ["84112.8", "0.000099"], ["84114.3", "0.089099"], ["84123.3", "0"], ["84130.3", "0"]], "u": 19143, "seq": 67549851138}, "cts": 1742555031112, "record_time": 1742555031.19758, "EXCHANGE": "BYBIT"}
{"topic": "orderbook.200.BTCUSDT", "ts": 1742555031319, "type": "delta", "data": {"s": "BTCUSDT", "b": [["84099.7", "0.003"], ["84070.9", "0"], ["84066.7", "0.013"], ["84066.6", "0.182302"], ["84066.5", "0.118804"], ["84066.4", "0"], ["84027.1", "0.171516"], ["84025.1", "1.124664"]], "a": [], "u": 19144, "seq": 67549851175}, "cts": 1742555031302, "record_time": 1742555031.390199, "EXCHANGE": "BYBIT"}
{"topic": "orderbook.200.BTCUSDT", "ts": 1742555031520, "type": "delta", "data": {"s": "BTCUSDT", "b": [["84101.9", "0.192185"], ["84066.7", "0"], ["84066.6", "0.169422"], ["84066.5", "0.131804"], ["84066.4", "0.01288"]], "a": [["84102", "0.325731"], ["84102.1", "0"], ["84104.4", "0.0522"], ["84104.5", "0"], ["84138.9", "2.258719"], ["84155.8", "0"], ["84181.4", "1.783293"], ["84181.5", "0.05"], ["84182.3", "0.118804"]], "u": 19145, "seq": 67549851230}, "cts": 1742555031514, "record_time": 1742555031.536771, "EXCHANGE": "BYBIT"}
{"topic": "orderbook.200.BTCUSDT", "ts": 1742555031719, "type": "delta", "data": {"s": "BTCUSDT", "b": [["84066.8", "0.013"], ["84066.7", "0.01288"], ["84066.5", "0.118804"], ["84066.4", "0"], ["84025.1", "0"]], "a": [["84138.6", "0.843048"], ["84139.4", "0"], ["84139.6", "0.01289"], ["84140.2", "0.011895"], ["84140.4", "0.045942"]], "u": 19146, "seq": 67549851288}, "cts": 1742555031686, "record_time": 1742555031.742446, "EXCHANGE": "BYBIT"}
{"topic": "orderbook.200.BTCUSDT", "ts": 1742555031920, "type": "delta", "data": {"s": "BTCUSDT", "b": [["84066.8", "0"], ["84066.7", "0"], ["84066.5", "0.131804"], ["84066.4", "0.01288"], ["84025.1", "1.124664"]], "a": [["84102", "0.331731"]], "u": 19147, "seq": 67549851323}, "cts": 1742555031906, "record_time": 1742555031.936966, "EXCHANGE": "BYBIT"}
{"topic": "orderbook.200.BTCUSDT", "ts": 1742555032119, "type": "delta", "data": {"s": "BTCUSDT", "b": [["84066.8", "0.013"], ["84066.7", "0.01288"], ["84066.5", "0.118804"], ["84066.4", "0"], ["84025.1", "0"]], "a": [["84140.2", "0.051895"], ["84140.4", "0.005942"]], "u": 19148, "seq": 67549851355}, "cts": 1742555032103, "record_time": 1742555032.135067, "EXCHANGE": "BYBIT"}
{"topic": "orderbook.200.BTCUSDT", "ts": 1742555032320, "type": "delta", "data": {"s": "BTCUSDT", "b": [["84066.8", "0"], ["84066.6", "0.182302"], ["84025.1", "1.124664"]], "a": [["84138.9", "0.001466"], ["84140.1", "0.04"], ["84140.3", "0"], ["84144.5", "2.271076"], ["84170.1", "0.247116"]], "u": 19149, "seq": 67549851393}, "cts": 1742555032311, "record_time": 1742555032.335716, "EXCHANGE": "BYBIT"}
{"topic": "orderbook.200.BTCUSDT", "ts": 1742555032519, "type": "delta", "data": {"s": "BTCUSDT", "b": [["84101.9", "0.185031"], ["84069.7", "0.071978"], ["84055", "0"]], "a": [["84102", "0.339514"], ["84138.6", "0.153301"], ["84139.2", "0.013"], ["84139.3", "0.036668"], ["84139.5", "0"], ["84139.6", "0"], ["84147.4", "0.040518"], ["84182.8", "0.0012"]], "u": 19150, "seq": 67549851436}, "cts": 1742555032516, "record_time": 1742555032.53809, "EXCHANGE": "BYBIT"}
{"topic": "orderbook.200.BTCUSDT", "ts": 1742555032720, "type": "delta", "data": {"s": "BTCUSDT", "b": [["84082.9", "0.057247"], ["84075.9", "0.055181"], ["84068.9", "0.115116"], ["84066.7", "0"], ["84066.6", "0.169422"], ["84066.5", "0.131804"], ["84066.4", "0.01288"], ["84027.1", "0"], ["84026.5", "0"], ["84025.1", "0"]], "a": [["84117.9", "0.059219"], ["84124.5", "0"], ["84124.9", "0.055598"], ["84131.9", "0.110673"], ["84139.9", "0.099399"], ["84140", "0.040358"], ["84140.1", "0"], ["84140.2", "0.011895"], ["84182.8", "0"]], "u": 19151, "seq": 67549851484}, "cts": 1742555032715, "record_time": 1742555032.779175, "EXCHANGE": "BYBIT"}
{"topic": "orderbook.200.BTCUSDT", "ts": 1742555032920, "type": "delta", "data": {"s": "BTCUSDT", "b": [["84101.9", "0.19116"], ["84082.9", "0"], ["84075.9", "0"], ["84074.5", "0.274407"], ["84068.9", "0"], ["84066.7", "0.01288"], ["84066.6", "0.182302"], ["84066.5", "0.118804"], ["84066.4", "0"], ["84027.1", "0.000516"], ["84026.5", "0.0045"], ["84025.1", "1.124664"]], "a": [["84117.9", "0"], ["84123.6", "0.009518"], ["84124.9", "0"], ["84131.9", "0"], ["84139.2", "0"], ["84139.3", "0.023778"], ["84139.5", "0.01289"], ["84139.6", "0.01289"], ["84139.9", "0.059399"], ["84140", "0.000358"], ["84140.2", "0.051895"], ["84140.3", "0.04"], ["84182.8", "0.0012"]], "u": 19152, "seq": 67549851522}, "cts": 1742555032902, "record_time": 1742555032.973073, "EXCHANGE": "BYBIT"}
{"topic": "orderbook.200.BTCUSDT", "ts": 1742555033119, "type": "delta", "data": {"s": "BTCUSDT", "b": [["84101.9", "0.191398"], ["84027.1", "0.171516"]], "a": [["84102", "0.340083"], ["84102.3", "0.03567"], ["84114.3", "0"], ["84139.4", "0.013"], ["84139.5", "0.012878"], ["84139.6", "0"]], "u": 19153, "seq": 67549851575}, "cts": 1742555033116, "record_time": 1742555033.136751, "EXCHANGE": "BYBIT"}
{"topic": "orderbook.200.BTCUSDT", "ts": 1742555033320, "type": "delta", "data": {"s": "BTCUSDT", "b": [["84066.7", "0"], ["84066.6", "0.169422"], ["84066.5", "0.131804"], ["84066.4", "0.01288"]], "a": [["84121.8", "0.001032"], ["84140.1", "0.04"], ["84140.3", "0"], ["84144.5", "0.013823"], ["84155.8", "2.257253"], ["84182.3", "0"], ["84182.8", "0"]], "u": 19154, "seq": 67549851609}, "cts": 1742555033316, "record_time": 1742555033.335152, "EXCHANGE": "BYBIT"}
{"topic": "orderbook.200.BTCUSDT", "ts": 1742555033520, "type": "delta", "data": {"s": "BTCUSDT", "b": [["84101", "0.002811"], ["84066.6", "0.182302"], ["84066.5", "0.131684"], ["84066.4", "0"], ["84063.4", "0"], ["84025", "0.000199"], ["84024.9", "0.000333"]], "a": [["84121.8", "0"], ["84123.6", "0.005942"], ["84139.4", "0"], ["84139.6", "0.012878"], ["84140.1", "0"], ["84140.3", "0.04"], ["84182.3", "0.118804"]], "u": 19155, "seq": 67549851647}, "cts": 1742555033506, "record_time": 1742555033.535792, "EXCHANGE": "BYBIT"}
{"topic": "orderbook.200.BTCUSDT", "ts": 1742555033720, "type": "delta", "data": {"s": "BTCUSDT", "b": [["84101.9", "0.19116"], ["84066.6", "0.169422"], ["84066.5", "0.118804"], ["84066.2", "0.014213"], ["84066.1", "0.01288"], ["84064.3", "0.003575"], ["84055", "0.000118"], ["84025.1", "0"], ["84025", "0"], ["84024.9", "0"]], "a": [["84125.4", "0.003576"], ["84182.3", "0"]], "u": 19156, "seq": 67549851675}, "cts": 1742555033704, "record_time": 1742555033.822443, "EXCHANGE": "BYBIT"}
{"topic": "orderbook.200.BTCUSDT", "ts": 1742555033919, "type": "delta", "data": {"s": "BTCUSDT", "b": [["84101.9", "0.191398"]], "a": [], "u": 19157, "seq": 67549851691}, "cts": 1742555033916, "record_time": 1742555034.015031, "EXCHANGE": "BYBIT"}
{"topic": "orderbook.200.BTCUSDT", "ts": 1742555034120, "type": "delta", "data": {"s": "BTCUSDT", "b": [["84066.2", "0.001333"], ["84066", "0.012881"], ["84026.5", "0"]], "a": [["84102", "0.3383"], ["84125.4", "0"], ["84145.3", "0.023243"], ["84182.3", "0.118804"]], "u": 19158, "seq": 67549851711}, "cts": 1742555034117, "record_time": 1742555034.1418, "EXCHANGE": "BYBIT"}
{"topic": "orderbook.200.BTCUSDT", "ts": 1742555034320, "type": "delta", "data": {"s": "BTCUSDT", "b": [["84101.9", "0.362398"], ["84066.5", "0.131804"], ["84066.4", "0.01288"], ["84066.1", "0"], ["84066", "0"], ["84040.1", "0"], ["84037.3", "17.622667"], ["84026.5", "0.0045"], ["84025.1", "1.124664"]], "a": [["84139.4", "0.013"], ["84139.6", "0"]], "u": 19159, "seq": 67549851767}, "cts": 1742555034309, "record_time": 1742555034.34508, "EXCHANGE": "BYBIT"}
{"topic": "orderbook.200.BTCUSDT", "ts": 1742555034520, "type": "delta", "data": {"s": "BTCUSDT", "b": [["84099.7", "0"], ["84040.1", "17.476737"], ["84037.3", "0.195"]], "a": [], "u": 19160, "seq": 67549851823}, "cts": 1742555034503, "record_time": 1742555034.536442, "EXCHANGE": "BYBIT"}
{"success": true, "ret_msg": "subscribe", "conn_id": "d254c3be-961e-4554-aae4-742fef071034", "op": "subscribe", "record_time": 1742555170.054664, "EXCHANGE": "BYBIT"}
