{"topic": "orderbook.200.BTCUSDT", "ts": 1742556560320, "type": "snapshot", "data": {"s": "BTCUSDT", "b": [["83965.5", "0.302454"], ["83965.4", "0.001333"], ["83965", "0.003181"], ["83963.2", "0.001466"], ["83963", "0.071494"], ["83962.5", "0.000516"], ["83961.9", "0.000333"], ["83961.5", "0.002201"], ["83961.2", "0.001333"], ["83960.8", "0.003601"], ["83960.5", "0.000768"], ["83960", "0.00006"], ["83959.7", "0.000359"], ["83959.2", "0.015786"], ["83959.1", "0.011375"], ["83958.6", "0.001466"], ["83958.2", "0.027908"], ["83958.1", "0.005942"], ["83957.8", "0.132596"], ["83957.7", "0.040333"], ["83957.1", "0.01"], ["83957", "0.001537"], ["83956.8", "0.008438"], ["83956.6", "0.003181"], ["83956.3", "0.000127"], ["83956.1", "0.048"], ["83956", "0.04"], ["83955.7", "0.0715"], ["83955.2", "0.0063"], ["83955", "0.053084"], ["83954.9", "0.022751"], ["83954.3", "0.04"], ["83954.2", "0.04"], ["83954", "0.001466"], ["83953.8", "0.133745"], ["83953.7", "0.171"], ["83953.6", "0.004063"], ["83953.5", "0.000333"], ["83953.2", "0.000516"], ["83952.8", "0.001423"], ["83952.7", "0.04"], ["83952.6", "0.062186"], ["83952.4", "0.003181"], ["83952", "0.000272"], ["83951.6", "0.071504"], ["83951.3", "0.009"], ["83951.1", "0.04"], ["83951", "0.04"], ["83950.5", "0.016877"], ["83949.4", "0.001466"], ["83949.3", "0.046815"], ["83949.2", "0.023453"], ["83948.6", "0.001849"], ["83948.5", "0.009912"], ["83948.2", "0.003181"], ["83946.2", "0.006087"], ["83945.3", "0.158757"], ["83945.2", "0.171"], ["83945.1", "0.000333"], ["83944.8", "0.001466"], ["83944.4", "0.001423"], ["83944", "0.003697"], ["83942.1", "0.118804"], ["83941.9", "0.001116"], ["83941.3", "0.005942"], ["83941.1", "0.091643"], ["83940.9", "0.000333"], ["83940.2", "0.002799"], ["83940", "0.00006"], ["83939.8", "0.003181"], ["83939.4", "0.000516"], ["83939", "0.000118"], ["83937.6", "0.000359"], ["83937", "0.124747"], ["83936.9", "0.059399"], ["83936.8", "0.096092"], ["83936.7", "0.171333"], ["83936.5", "0.0045"], ["83936", "0.001423"], ["83935.8", "0.000337"], ["83935.7", "0.003181"], ["83935.5", "0.001556"], ["83935.1", "0.02552"], ["83934.8", "0.000516"], ["83934.7", "0.111958"], ["83932.8", "0.17559"], ["83932.6", "0.48675"], ["83932.5", "0.006179"], ["83931.8", "0.001333"], ["83931.5", "0.003181"], ["83930.9", "0.001466"], ["83930.2", "0.015"], ["83930.1", "0.022891"], ["83929.6", "0.003781"], ["83929", "0.003575"], ["83928.8", "0.011915"], ["83928.6", "0.115917"], ["83928.4", "0.024617"], ["83928.3", "0.000333"], ["83928.2", "0.171"], ["83927.8", "0.00477"], ["83927.6", "0.120227"], ["83927.4", "0.059399"], ["83927.3", "0.003181"], ["83927", "0.023814"], ["83926.5", "0.0016"], ["83926.3", "0.001466"], ["83925.7", "0.128686"], ["83925.5", "0.000516"], ["83924.8", "0.012882"], ["83924.7", "0.012882"], ["83924.5", "0.005942"], ["83924.4", "0.000083"], ["83924.1", "0.000333"], ["83924", "0.256755"], ["83923.9", "0.529799"], ["83923.4", "0.007286"], ["83923.1", "0.003181"], ["83922.9", "0.04"], ["83921.7", "0.001466"], ["83921.6", "0.023814"], ["83921.3", "0.032817"], ["83921.1", "0.071814"], ["83921", "0.04"], ["83920.9", "0.000516"], ["83920.2", "0.135608"], ["83920", "0.023874"], ["83919.9", "0.000333"], ["83919.8", "0.145192"], ["83919.7", "0.171"], ["83919.2", "0.001423"], ["83918.9", "0.003181"], ["83918.2", "0.053795"], ["83917.5", "0.118804"], ["83917.3", "0.030388"], ["83917.1", "0.001466"], ["83917", "0.044"], ["83916.8", "0.059399"], ["83916.3", "0.000516"], ["83915.7", "0.000333"], ["83915.5", "0.000359"], ["83915", "0.002576"], ["83914.7", "0.003181"], ["83913.1", "0.001071"], ["83912.5", "0.001466"], ["83912", "0.012"], ["83911.9", "0.04"], ["83911.7", "0.000516"], ["83911.5", "0.000333"], ["83911.3", "0.171"], ["83910.8", "0.001423"], ["83910.5", "0.003181"], ["83908.7", "0.114"], ["83907.8", "0.001466"], ["83907.7", "0.005942"], ["83907.4", "0.118804"], ["83907.3", "0.000333"], ["83907.1", "0.000516"], ["83906.6", "0.001333"], ["83906.5", "0.0045"], ["83906.3", "0.003181"], ["83905.4", "0.00112"], ["83904.8", "0.04"], ["83903.2", "0.001466"], ["83903.1", "0.000333"], ["83902.9", "0.171"], ["83902.4", "0.001939"], ["83902.2", "0.044"], ["83902.1", "0.164083"], ["83901.6", "0.089099"], ["83900.1", "0.00006"], ["83900", "0.056081"], ["83899.9", "0.059399"], ["83898.9", "0.000333"], ["83898.7", "13.532918"], ["83898.6", "0.001466"], ["83898.2", "0.001333"], ["83898.1", "0.053111"], ["83897.9", "0.003181"], ["83897.8", "0.000516"], ["83897.3", "0.118804"], ["83895.5", "0.003575"], ["83895.1", "0.235392"], ["83894.7", "0.012325"], ["83894.6", "0.000927"], ["83894.5", "0.171"], ["83894", "0.002889"], ["83893.8", "0.011992"], ["83893.7", "0.003181"], ["83893.4", "0.000449"], ["83893.2", "0.000516"], ["83891.3", "0.009"], ["83891.2", "0.04"], ["83890.9", "0.00625"], ["83890.7", "0.353794"], ["83890.6", "0.000333"], ["83890.5", "3.246386"], ["83890.3", "0.011992"], ["83890.2", "0.00253"], ["83890", "0.0002"]], "a": [["83965.6", "0.492059"], ["83968", "0.008438"], ["83970", "0.046494"], ["83970.1", "0.083385"], ["83970.3", "0.000333"], ["83970.6", "0.073187"], ["83971.1", "0.028288"], ["83971.7", "0.000514"], ["83972", "0.012469"], ["83972.5", "0.001466"], ["83973", "0.071485"], ["83973.2", "0.003814"], ["83973.4", "0.003239"], ["83973.8", "0.001333"], ["83974", "0.01"], ["83974.1", "0.0002"], ["83974.3", "0.016877"], ["83974.5", "0.000333"], ["83974.6", "0.00009"], ["83975", "0.0001"], ["83975.6", "0.198134"], ["83975.7", "0.111958"], ["83976.2", "0.024937"], ["83976.3", "0.000514"], ["83976.4", "0.02"], ["83977", "0.008"], ["83977.1", "0.001466"], ["83977.3", "0.066797"], ["83977.4", "0.02"], ["83977.6", "0.003242"], ["83977.9", "0.059399"], ["83978", "0.001333"], ["83978.1", "0.191"], ["83978.7", "0.000333"], ["83978.8", "0.020595"], ["83979.1", "0.04"], ["83979.2", "0.272769"], ["83979.3", "0.048"], ["83979.6", "0.02"], ["83979.8", "0.024411"], ["83980.1", "0.02357"], ["83980.8", "0.04"], ["83980.9", "0.000514"], ["83981", "0.048"], ["83981.4", "0.02"], ["83981.7", "0.001466"], ["83981.8", "0.003242"], ["83982", "0.04"], ["83982.2", "0.001333"], ["83982.3", "0.02"], ["83982.7", "0.5648"], ["83982.9", "0.000333"], ["83983", "0.02009"], ["83983.7", "0.325684"], ["83984.4", "0.048"], ["83984.6", "0.018376"], ["83985.6", "0.000514"], ["83986", "0.051242"], ["83986.1", "0.052"], ["83986.3", "0.001466"], ["83986.4", "0.001333"], ["83986.8", "0.477262"], ["83987", "0.182646"], ["83987.1", "0.000333"], ["83987.5", "0.103286"], ["83987.8", "0.000995"], ["83987.9", "0.0001"], ["83989.4", "0.059535"], ["83990.2", "0.003757"], ["83990.3", "0.059535"], ["83990.4", "0.035737"], ["83990.6", "0.064308"], ["83990.8", "0.023814"], ["83991", "0.001466"], ["83991.3", "0.000333"], ["83991.4", "0.026032"], ["83991.5", "0.04248"], ["83991.6", "0.029772"], ["83992.5", "0.023819"], ["83992.9", "0.029767"], ["83993.1", "0.0002"], ["83993.3", "0.281397"], ["83993.4", "0.079535"], ["83993.8", "0.059535"], ["83994", "0.078954"], ["83994.4", "0.003247"], ["83994.8", "0.001849"], ["83995.5", "0.000333"], ["83995.6", "0.12027"], ["83995.7", "0.049767"], ["83995.8", "0.163321"], ["83996", "0.089099"], ["83996.5", "0.0045"], ["83996.8", "0.071438"], ["83997.1", "0.171"], ["83998", "0.059535"], ["83998.2", "0.012743"], ["83998.3", "0.012743"], ["83998.6", "0.003247"], ["83998.8", "0.04"], ["83998.9", "0.04"], ["83999", "0.001333"], ["83999.4", "0.000516"], ["83999.7", "0.015333"], ["83999.8", "0.00009"], ["83999.9", "0.059399"], ["84000.2", "0.704124"], ["84000.3", "0.031041"], ["84002.8", "0.003247"], ["84003.1", "2.256735"], ["84003.2", "0.001333"], ["84003.3", "0.030042"], ["84003.5", "0.00465"], ["84003.9", "0.000333"], ["84004", "0.000516"], ["84004.1", "0.030042"], ["84004.5", "0.719778"], ["84004.6", "0.118804"], ["84004.7", "0.059545"], ["84004.8", "0.001466"], ["84004.9", "0.105408"], ["84005.4", "0.014068"], ["84005.5", "0.171"], ["84005.8", "0.030042"], ["84005.9", "0.009528"], ["84006.7", "0.005979"], ["84007", "0.003247"], ["84007.2", "0.059545"], ["84007.4", "0.355101"], ["84007.5", "1.556132"], ["84008", "0.000118"], ["84008.1", "0.000933"], ["84008.2", "0.036074"], ["84008.6", "0.000516"], ["84008.9", "0.030042"], ["84009.4", "0.060865"], ["84010", "0.029767"], ["84010.1", "0.030042"], ["84011.2", "3.18373"], ["84011.3", "0.009"], ["84011.4", "0.030042"], ["84011.6", "0.025146"], ["84012.1", "0.023813"], ["84012.3", "0.000333"], ["84012.5", "0.143137"], ["84013.3", "0.000516"], ["84013.9", "0.005953"], ["84014", "0.081293"], ["84014.1", "0.001466"], ["84014.2", "0.201042"], ["84015.4", "0.003248"], ["84015.6", "0.000359"], ["84015.7", "0.023813"], ["84015.8", "0.001333"], ["84016.5", "0.000333"], ["84016.6", "0.00009"], ["84016.8", "3.443935"], ["84017.2", "0.048"], ["84017.5", "0.023813"], ["84017.7", "0.118804"], ["84017.9", "0.000516"], ["84018.4", "0.023813"], ["84018.7", "0.001466"], ["84018.8", "0.059399"], ["84019.6", "0.003248"], ["84020", "0.013885"], ["84020.6", "0.04"], ["84020.7", "0.048333"], ["84022.3", "0.04"], ["84022.4", "0.048"], ["84022.5", "0.000516"], ["84022.6", "0.174"], ["84023.3", "0.001466"], ["84023.8", "0.043248"], ["84024.1", "0.048"], ["84024.2", "0.001333"], ["84024.5", "0.059535"], ["84024.9", "0.000333"], ["84025", "0.006032"], ["84025.3", "0.118804"], ["84025.4", "0.015"], ["84025.5", "0.04"], ["84026.5", "0.0045"], ["84027", "1.124639"], ["84027.1", "0.000516"], ["84027.4", "0.048"], ["84027.5", "0.052"], ["84027.7", "0.027532"], ["84027.8", "0.059399"], ["84027.9", "0.001466"], ["84028", "0.00325"], ["84028.4", "0.001333"], ["84028.5", "0.02501"], ["84028.6", "0.0006"], ["84029", "0.02381"], ["84029.1", "0.000333"], ["84030.6", "0.118804"], ["84030.8", "0.005952"], ["84030.9", "0.089099"], ["84031.1", "0.025312"]], "u": 26619, "seq": 67550548895}, "cts": 1742556560302, "record_time": 1742556561.614196, "EXCHANGE": "BYBIT"}
{"topic": "orderbook.200.BTCUSDT", "ts": 1742556560520, "type": "delta", "data": {"s": "BTCUSDT", "b": [["83965.5", "0.308817"], ["83949.3", "0.012842"], ["83947.9", "0.059362"], ["83945.3", "0.084198"], ["83941.1", "0"], ["83940.9", "0.061605"], ["83933.9", "0.120928"], ["83924.9", "0.013"], ["83924.7", "0"], ["83890", "0"]], "a": [["83965.6", "0.493845"], ["83982.9", "0.060266"], ["83989.9", "0.056947"], ["83993.3", "0.094406"], ["83996.9", "0.118471"], ["83997.9", "0.013"], ["83998", "0.072278"], ["83998.2", "0"], ["83998.3", "0"], ["83998.5", "0.04"], ["83998.6", "0.043247"], ["83998.8", "0"], ["83998.9", "0"], ["84031", "0.171"], ["84031.1", "0"]], "u": 26620, "seq": 67550548939}, "cts": 1742556560516, "record_time": 1742556561.615433, "EXCHANGE": "BYBIT"}
{"topic": "orderbook.200.BTCUSDT", "ts": 1742556560719, "type": "delta", "data": {"s": "BTCUSDT", "b": [["83949.3", "0.029923"], ["83920.2", "0.135594"], ["83898.7", "0"], ["83895.9", "13.664616"]], "a": [["83965.6", "0.322845"], ["83997.9", "0.012743"]], "u": 26621, "seq": 67550548965}, "cts": 1742556560717, "record_time": 1742556561.616246, "EXCHANGE": "BYBIT"}
{"topic": "orderbook.200.BTCUSDT", "ts": 1742556560919, "type": "delta", "data": {"s": "BTCUSDT", "b": [["83965.5", "0.108817"], ["83964.2", "0.012512"], ["83963", "0"], ["83962.1", "0.038586"], ["83962", "0.071495"], ["83959.2", "0.001779"], ["83957.8", "0.066131"], ["83957.7", "0.000333"], ["83956.1", "0"], ["83956", "0"], ["83954.3", "0"], ["83954.2", "0"], ["83953.8", "0.088907"], ["83952.7", "0"], ["83952.6", "0.018186"], ["83951.1", "0"], ["83951", "0"], ["83949.9", "0.04"], ["83947.9", "0"], ["83941", "0.058016"], ["83940.9", "0.000333"], ["83936.9", "0"], ["83936.8", "0.155491"], ["83933.9", "0"], ["83930.2", "0"], ["83928.8", "0"], ["83927", "0"], ["83924.9", "0"], ["83924.7", "0.012882"], ["83924", "0.232938"], ["83923.4", "0.001333"], ["83921.6", "0"], ["83921.3", "0.009"], ["83921.1", "0.048"], ["83920.2", "0"], ["83916.2", "0.011917"], ["83911.9", "0.063819"], ["83911.7", "0.136117"], ["83911", "0.023819"], ["83909.2", "0.023819"], ["83907.4", "0.124758"], ["83905.6", "0.023819"], ["83905.1", "0.023819"], ["83895.9", "0"], ["83890", "0.0002"], ["83889.9", "0.011992"], ["83889.8", "0.001333"], ["83889.5", "0.003181"], ["83889.4", "0.001466"], ["83889", "0.100315"], ["83888.8", "0.000445"]], "a": [["83965.6", "0.577299"], ["83965.8", "0.106766"], ["83965.9", "0.035727"], ["83966.1", "0.035727"], ["83970", "0"], ["83982.2", "0.002332"], ["83982.9", "0.000333"], ["83983.4", "0.011917"], ["83989.9", "0"], ["83994.8", "0.025668"], ["83995.3", "0.023819"], ["83996.9", "0"], ["83997.1", "0.176954"], ["83997.8", "0.012743"], ["83998", "0.059535"], ["83998.9", "0.023819"], ["84000.3", "0.030042"], ["84000.7", "0.023819"], ["84001.6", "0.023819"], ["84004.9", "0.093494"], ["84028.5", "0.0012"], ["84029", "0"], ["84029.1", "0"], ["84030.6", "0"], ["84030.8", "0"], ["84030.9", "0"], ["84031", "0"]], "u": 26622, "seq": 67550549571}, "cts": 1742556560916, "record_time": 1742556561.617009, "EXCHANGE": "BYBIT"}
{"topic": "orderbook.200.BTCUSDT", "ts": 1742556561120, "type": "delta", "data": {"s": "BTCUSDT", "b": [["83965.5", "0.006363"], ["83962.1", "0"], ["83953.8", "0.150873"], ["83953.3", "0.04"], ["83951.7", "0.048"], ["83951.6", "0.111504"], ["83950.1", "0.04"], ["83949.4", "0.116807"], ["83949.3", "0.012842"], ["83948.4", "0.044"], ["83948.2", "0.043181"], ["83946.7", "0.04"], ["83946.6", "0.04"], ["83946.2", "0.0003"], ["83942.1", "0"], ["83941", "0"], ["83939.6", "0.165868"], ["83934.7", "0"], ["83934.2", "0.111966"], ["83930.5", "0.290315"], ["83924.8", "0"], ["83924.6", "0.012882"], ["83914.6", "0.135601"], ["83911.7", "0.000516"], ["83893.1", "13.664616"], ["83890", "0"], ["83889.9", "0"], ["83889.8", "0"], ["83889.5", "0"], ["83889.4", "0"], ["83889", "0"], ["83888.8", "0"]], "a": [["83965.6", "0.746175"], ["83974.6", "0.116513"], ["83984.4", "0.234846"], ["83993.5", "0.291986"], ["84000.3", "2.286777"], ["84003.1", "0"]], "u": 26623, "seq": 67550549710}, "cts": 1742556561114, "record_time": 1742556561.617741, "EXCHANGE": "BYBIT"}
{"topic": "orderbook.200.BTCUSDT", "ts": 1742556561320, "type": "delta", "data": {"s": "BTCUSDT", "b": [["83962", "0"], ["83959.2", "0.015786"], ["83955.7", "0"], ["83955", "0.053237"], ["83953.8", "0.222375"], ["83953.4", "0.04"], ["83949.5", "0.061348"], ["83949.4", "0.001466"], ["83949.3", "0.000333"], ["83946.2", "0.006177"], ["83945.3", "0.055493"], ["83939.7", "0.087482"], ["83939.6", "0"], ["83930.5", "0"], ["83890", "0.0002"]], "a": [["83966.3", "0.003576"], ["83974.6", "0.00009"], ["83977.1", "0.090565"], ["83984.4", "0.048"], ["83990.6", "0.060732"], ["83993.5", "0"], ["83997.5", "2.256735"], ["84000.3", "0.030042"], ["84028.6", "0"]], "u": 26624, "seq": 67550549801}, "cts": 1742556561296, "record_time": 1742556561.618462, "EXCHANGE": "BYBIT"}
{"topic": "orderbook.200.BTCUSDT", "ts": 1742556561519, "type": "delta", "data": {"s": "BTCUSDT", "b": [["83965.5", "0.010612"], ["83964.2", "0.015512"], ["83946.2", "0.0003"], ["83939.7", "0"], ["83889.9", "0.011992"]], "a": [["83965.6", "0.752175"], ["83966.3", "0"], ["83997.8", "0"], ["83997.9", "0"], ["83998.1", "0.012743"], ["83998.2", "0.012743"], ["83998.5", "0"], ["83998.6", "0.003247"], ["83998.8", "0.04"], ["83998.9", "0.063819"], ["84000.2", "0.039256"], ["84028.6", "0.0006"]], "u": 26625, "seq": 67550549848}, "cts": 1742556561515, "record_time": 1742556561.619172, "EXCHANGE": "BYBIT"}
{"topic": "orderbook.200.BTCUSDT", "ts": 1742556561720, "type": "delta", "data": {"s": "BTCUSDT", "b": [["83965.5", "0.110612"], ["83963.3", "0.071494"], ["83957.8", "0.050151"], ["83955.7", "0.0715"], ["83953.8", "0.150873"], ["83925", "0.013"], ["83924.9", "0.012882"], ["83924.7", "0"], ["83924.6", "0"], ["83890", "0"], ["83889.9", "0"]], "a": [["83967.4", "0.003576"], ["83977.1", "0.001466"], ["83997.5", "0"], ["83997.8", "0.013"], ["83997.9", "0.012743"], ["83998.1", "0"], ["83998.2", "0"], ["83998.5", "0.04"], ["83998.6", "0.043247"], ["83998.8", "0"], ["83998.9", "0.023819"], ["84000.3", "2.286777"]], "u": 26626, "seq": 67550549907}, "cts": 1742556561715, "record_time": 1742556561.738694, "EXCHANGE": "BYBIT"}
{"topic": "orderbook.200.BTCUSDT", "ts": 1742556561919, "type": "delta", "data": {"s": "BTCUSDT", "b": [["83963.3", "0"], ["83893.1", "13.914545"], ["83890", "0.0002"]], "a": [], "u": 26627, "seq": 67550549930}, "cts": 1742556561909, "record_time": 1742556561.937318, "EXCHANGE": "BYBIT"}
{"topic": "orderbook.200.BTCUSDT", "ts": 1742556562120, "type": "delta", "data": {"s": "BTCUSDT", "b": [["83965.5", "0.110851"], ["83959.2", "0.015787"], ["83958.2", "0.027909"], ["83937.1", "0.037424"], ["83895.9", "13.914545"], ["83893.1", "0"], ["83890", "0"]], "a": [["83965.6", "0.749286"], ["84000.2", "0.718116"]], "u": 26628, "seq": 67550549974}, "cts": 1742556562116, "record_time": 1742556562.138215, "EXCHANGE": "BYBIT"}
{"topic": "orderbook.200.BTCUSDT", "ts": 1742556562320, "type": "delta", "data": {"s": "BTCUSDT", "b": [["83965.5", "0.113741"], ["83895.9", "0"], ["83893.1", "13.914545"]], "a": [["84002.1", "0.063449"], ["84004.9", "0.030042"], ["84028.6", "0"]], "u": 26629, "seq": 67550549987}, "cts": 1742556562316, "record_time": 1742556562.339685, "EXCHANGE": "BYBIT"}
{"topic": "orderbook.200.BTCUSDT", "ts": 1742556562520, "type": "delta", "data": {"s": "BTCUSDT", "b": [["83965.5", "0.109492"], ["83955", "0.053084"], ["83950.6", "0.112859"], ["83946.5", "0.118338"], ["83940.1", "0.17966"], ["83939.5", "0.165023"], ["83933.1", "0.295941"], ["83932.5", "0.2905"], ["83895.9", "13.914545"], ["83893.1", "0"], ["83890.7", "0"], ["83890.6", "0"], ["83890.5", "0"], ["83890.3", "0"], ["83890.2", "0"]], "a": [["83967.4", "0"], ["83975.1", "0.114425"], ["83979.4", "0.124006"], ["83985.6", "0.174026"], ["83986.4", "0.179504"], ["83992.6", "0.300499"], ["83993.4", "0.376497"], ["84028.4", "0"], ["84028.5", "0"]], "u": 26630, "seq": 67550550016}, "cts": 1742556562515, "record_time": 1742556562.538871, "EXCHANGE": "BYBIT"}
{"topic": "orderbook.200.BTCUSDT", "ts": 1742556562719, "type": "delta", "data": {"s": "BTCUSDT", "b": [["83949.5", "0.089181"]], "a": [["83976.2", "0.028513"]], "u": 26631, "seq": 67550550035}, "cts": 1742556562696, "record_time": 1742556562.737327, "EXCHANGE": "BYBIT"}
{"topic": "orderbook.200.BTCUSDT", "ts": 1742556562920, "type": "delta", "data": {"s": "BTCUSDT", "b": [["83957.7", "0.000486"]], "a": [["83965.6", "0.578286"]], "u": 26632, "seq": 67550550055}, "cts": 1742556562907, "record_time": 1742556562.937775, "EXCHANGE": "BYBIT"}
{"topic": "orderbook.200.BTCUSDT", "ts": 1742556563120, "type": "delta", "data": {"s": "BTCUSDT", "b": [["83965.5", "0.10978"], ["83950.6", "0"], ["83950.3", "0.113245"], ["83940.5", "0.164644"], ["83940.2", "0.144898"], ["83940.1", "0"], ["83937.1", "0"], ["83933.1", "0"], ["83931.4", "0.298861"], ["83895.9", "0"], ["83893.1", "13.914545"], ["83890.7", "0.353794"]], "a": [["83965.6", "0.749286"], ["83975.1", "0"], ["83975.5", "0.115876"], ["83985.3", "0.175986"], ["83985.6", "0.000514"], ["83992.5", "0.344386"], ["83992.6", "0"], ["83993.3", "0"], ["83994.4", "0.304292"], ["84000.3", "0.030042"], ["84003.1", "2.256735"]], "u": 26633, "seq": 67550550089}, "cts": 1742556563059, "record_time": 1742556563.13769, "EXCHANGE": "BYBIT"}
{"topic": "orderbook.200.BTCUSDT", "ts": 1742556563320, "type": "delta", "data": {"s": "BTCUSDT", "b": [["83965.5", "0.28078"], ["83950.3", "0"], ["83946.5", "0"], ["83940.5", "0"], ["83940.2", "0.002799"], ["83939.5", "0"], ["83932.5", "0.006179"], ["83931.4", "0"], ["83895.9", "14.172845"], ["83890.6", "0.000333"], ["83890.5", "3.246386"], ["83890.3", "0.011992"], ["83890.2", "0.00253"]], "a": [["83965.6", "0.578286"], ["83975.5", "0"], ["83979.4", "0"], ["83985.3", "0"], ["83986.4", "0.001333"], ["83993.4", "0.079535"], ["83994.4", "0.003247"], ["84028.4", "0.001333"], ["84028.5", "0.0012"], ["84028.6", "0.0006"]], "u": 26634, "seq": 67550550118}, "cts": 1742556563311, "record_time": 1742556563.341607, "EXCHANGE": "BYBIT"}
{"topic": "orderbook.200.BTCUSDT", "ts": 1742556563519, "type": "delta", "data": {"s": "BTCUSDT", "b": [["83965.5", "0.282683"], ["83962", "0.071495"], ["83949.5", "0.061348"], ["83946.2", "0.006181"], ["83895.9", "0"], ["83893.1", "14.172845"]], "a": [["83965.6", "0.584286"], ["83980.1", "0.02"], ["83986.5", "0.000991"], ["83992.5", "0.023819"], ["84028.6", "0"]], "u": 26635, "seq": 67550550147}, "cts": 1742556563503, "record_time": 1742556563.537744, "EXCHANGE": "BYBIT"}
{"topic": "orderbook.200.BTCUSDT", "ts": 1742556563720, "type": "delta", "data": {"s": "BTCUSDT", "b": [["83900", "0.055816"]], "a": [["83986.5", "0"], ["84028.6", "0.0006"]], "u": 26636, "seq": 67550550161}, "cts": 1742556563694, "record_time": 1742556563.74147, "EXCHANGE": "BYBIT"}
{"topic": "orderbook.200.BTCUSDT", "ts": 1742556563920, "type": "delta", "data": {"s": "BTCUSDT", "b": [["83965.5", "0.283314"], ["83964.4", "0.071493"], ["83962", "0"], ["83925", "0"], ["83924.8", "0.012882"]], "a": [["83984.1", "0.001014"], ["83987.6", "0.001277"], ["83997.8", "0"], ["83997.9", "0"], ["83998.1", "0.013"], ["83998.2", "0.012743"], ["83998.5", "0"], ["83998.6", "0.003247"], ["83998.8", "0.04"], ["83998.9", "0.063819"], ["84028.5", "0"], ["84028.6", "0"]], "u": 26637, "seq": 67550550190}, "cts": 1742556563906, "record_time": 1742556563.938143, "EXCHANGE": "BYBIT"}
{"topic": "orderbook.200.BTCUSDT", "ts": 1742556564120, "type": "delta", "data": {"s": "BTCUSDT", "b": [["83965.5", "0.339196"], ["83964.5", "0.026696"], ["83957.8", "0.051646"], ["83956.8", "0"], ["83953.2", "0.072018"], ["83951.6", "0.04"], ["83937.1", "0.037424"], ["83901.5", "14.249587"], ["83893.1", "0"], ["83890.2", "0"]], "a": [["83965.6", "0.582143"], ["83965.8", "0.035727"], ["83976.2", "0.024937"], ["83984.1", "0"], ["83985", "0.00125"], ["83987.6", "0"], ["83989.7", "0.003576"], ["83993.3", "0.132338"], ["83997.9", "0.013"], ["83998", "0.072278"], ["83998.1", "0"], ["83998.2", "0"], ["83998.6", "0.043247"], ["83998.7", "0.04"], ["83998.8", "0"], ["83998.9", "0.023819"], ["84008.2", "0.038217"]], "u": 26638, "seq": 67550550254}, "cts": 1742556564116, "record_time": 1742556564.137828, "EXCHANGE": "BYBIT"}
{"topic": "orderbook.200.BTCUSDT", "ts": 1742556564319, "type": "delta", "data": {"s": "BTCUSDT", "b": [["83965.5", "0.343496"], ["83901.5", "0"], ["83895.9", "14.249587"]], "a": [["83965.6", "0.584286"], ["83976.4", "0"], ["83985", "0"], ["84003.1", "0"], ["84008.2", "0.036074"], ["84017.3", "2.256735"], ["84028.5", "0.0012"], ["84028.6", "0.0006"]], "u": 26639, "seq": 67550550350}, "cts": 1742556564302, "record_time": 1742556564.337487, "EXCHANGE": "BYBIT"}
{"topic": "orderbook.200.BTCUSDT", "ts": 1742556564520, "type": "delta", "data": {"s": "BTCUSDT", "b": [["83965.5", "0.283314"], ["83964.5", "0"], ["83964.4", "0"], ["83963.3", "0.071494"], ["83953", "0.120704"], ["83952.7", "0.120436"], ["83948.9", "0.111814"], ["83942.9", "0.169068"], ["83942.5", "0.168373"], ["83941.9", "0.185613"], ["83936.2", "0.178645"], ["83935.5", "0.301741"], ["83934.9", "0.297212"], ["83933.8", "0.276549"], ["83901.5", "14.249587"], ["83895.9", "0"], ["83891.3", "0"], ["83891.2", "0"], ["83890.9", "0"], ["83890.7", "0"], ["83890.6", "0"], ["83890.5", "0"], ["83890.3", "0"]], "a": [["83965.6", "0.590286"], ["83977.5", "0.120492"], ["83977.9", "0.168267"], ["83981.8", "0.117712"], ["83987.7", "0.163232"], ["83988", "0.1777"], ["83988.8", "0.177082"], ["83995", "0.299486"], ["83995.8", "0.446882"], ["83996.8", "0.380838"], ["84000.2", "0.039256"], ["84003.1", "2.256735"], ["84017.3", "0"], ["84027.9", "0"], ["84028", "0"], ["84028.4", "0"], ["84028.5", "0"], ["84028.6", "0"]], "u": 26640, "seq": 67550550436}, "cts": 1742556564516, "record_time": 1742556564.538066, "EXCHANGE": "BYBIT"}
{"topic": "orderbook.200.BTCUSDT", "ts": 1742556564719, "type": "delta", "data": {"s": "BTCUSDT", "b": [["83953.8", "0.216789"], ["83949.5", "0.088988"], ["83945.3", "0.205138"], ["83943", "0.118804"], ["83893.2", "0"]], "a": [["83985", "0.001251"], ["84027.8", "0"]], "u": 26641, "seq": 67550550457}, "cts": 1742556564701, "record_time": 1742556564.73855, "EXCHANGE": "BYBIT"}
{"topic": "orderbook.200.BTCUSDT", "ts": 1742556564920, "type": "delta", "data": {"s": "BTCUSDT", "b": [["83924.9", "0"], ["83924.7", "0.012882"], ["83901.5", "0"], ["83898.7", "14.181009"]], "a": [["83965.8", "0.106766"], ["83985", "0"], ["83997.9", "0"], ["83998", "0.059535"], ["83998.2", "0.012743"], ["83998.3", "0.012743"], ["83998.6", "0.003247"], ["83998.7", "0"], ["83998.9", "0.063819"], ["83999", "0.041333"], ["84027.8", "0.059399"]], "u": 26642, "seq": 67550550477}, "cts": 1742556564872, "record_time": 1742556564.939918, "EXCHANGE": "BYBIT"}
{"topic": "orderbook.200.BTCUSDT", "ts": 1742556565119, "type": "delta", "data": {"s": "BTCUSDT", "b": [["83963.3", "0"], ["83962.2", "0.038586"], ["83962.1", "0.071495"], ["83959.2", "0.001779"], ["83953", "0"], ["83952.7", "0"], ["83948.9", "0"], ["83942.9", "0"], ["83942.5", "0"], ["83941.9", "0.001116"], ["83936.8", "0.459264"], ["83935.5", "0.001556"], ["83934.9", "0"], ["83933.8", "0"], ["83898.7", "0"], ["83895.9", "14.181009"], ["83893.2", "0.000516"], ["83891.3", "0.009"], ["83891.2", "0.04"], ["83890.9", "0.00625"], ["83890.7", "0.353794"], ["83890.6", "0.000333"]], "a": [["83977.5", "0"], ["83977.9", "0.059399"], ["83981.8", "0.003242"], ["83987.7", "0"], ["83988", "0"], ["83988.8", "0"], ["83995", "0"], ["83995.8", "0.163321"], ["83996.8", "0.071438"], ["83998.1", "0.013"], ["83998.3", "0"], ["83998.8", "0.04"], ["83999", "0.001333"], ["84000.2", "0.73715"], ["84027.9", "0.001466"], ["84028", "0.00325"], ["84028.4", "0.001333"], ["84028.5", "0.0012"]], "u": 26643, "seq": 67550550527}, "cts": 1742556565112, "record_time": 1742556565.137071, "EXCHANGE": "BYBIT"}
{"topic": "orderbook.200.BTCUSDT", "ts": 1742556565320, "type": "delta", "data": {"s": "BTCUSDT", "b": [["83965.5", "0.111387"], ["83962.2", "0"], ["83962.1", "0"], ["83961.9", "0.038819"], ["83961.8", "0.071495"], ["83949.5", "0.061348"], ["83946.2", "0.0003"], ["83945.3", "0.084198"], ["83936.8", "0.155491"], ["83917", "0"], ["83890.5", "3.246386"], ["83890.3", "0.011992"]], "a": [["83984.1", "0.001015"], ["83998.1", "0"], ["83998.3", "0.012743"], ["83998.8", "0"], ["83999", "0.041333"]], "u": 26644, "seq": 67550550568}, "cts": 1742556565302, "record_time": 1742556565.339577, "EXCHANGE": "BYBIT"}
{"topic": "orderbook.200.BTCUSDT", "ts": 1742556565520, "type": "delta", "data": {"s": "BTCUSDT", "b": [["83965.5", "0.282387"], ["83962.9", "0.071494"], ["83961.9", "0.017371"], ["83961.8", "0"], ["83952.9", "0.117673"], ["83948.8", "0.122106"], ["83942.4", "0.186002"], ["83941.8", "0.178256"], ["83935.4", "0.296199"], ["83934.8", "0.302089"], ["83924.8", "0"], ["83924.6", "0.012882"], ["83911.9", "0.023819"], ["83898.7", "14.181009"], ["83895.9", "0"], ["83890.9", "0"], ["83890.7", "0"], ["83890.6", "0"], ["83890.5", "0"], ["83890.3", "0"]], "a": [["83977.4", "0.135726"], ["83981.7", "0.124538"], ["83984.1", "0"], ["83987.9", "0.18028"], ["83988.7", "0.164581"], ["83994.9", "0.279096"], ["83995.7", "0.334531"], ["83998.2", "0"], ["83998.4", "0.012743"], ["84028.5", "0"]], "u": 26645, "seq": 67550550610}, "cts": 1742556565514, "record_time": 1742556565.537728, "EXCHANGE": "BYBIT"}
{"topic": "orderbook.200.BTCUSDT", "ts": 1742556565719, "type": "delta", "data": {"s": "BTCUSDT", "b": [["83952.9", "0"], ["83949.5", "0.090312"], ["83948.8", "0"], ["83945.3", "0.189887"], ["83942.4", "0"], ["83941.8", "0"], ["83935.4", "0"], ["83934.8", "0.000516"], ["83924.8", "0.013"], ["83924.6", "0"], ["83912", "0"], ["83890.9", "0.00625"], ["83890.7", "0.353794"], ["83890.6", "0.000333"], ["83890.5", "3.246386"], ["83890.3", "0.011992"], ["83890.2", "0.00253"]], "a": [["83977.4", "0.02"], ["83981.7", "0.001466"], ["83987.9", "0.0001"], ["83988.7", "0"], ["83994.9", "0"], ["83995.7", "0.049767"], ["83998.2", "0.013"], ["83998.4", "0"], ["84028.5", "0.0012"], ["84028.6", "0.0006"]], "u": 26646, "seq": 67550550634}, "cts": 1742556565684, "record_time": 1742556565.737357, "EXCHANGE": "BYBIT"}
{"topic": "orderbook.200.BTCUSDT", "ts": 1742556565919, "type": "delta", "data": {"s": "BTCUSDT", "b": [["83965.5", "0.281756"], ["83959.6", "0.000153"], ["83957.7", "0.000333"], ["83949.5", "0.061348"], ["83945.3", "0.084198"], ["83924.9", "0.013"], ["83924.8", "0.012882"], ["83924.7", "0"], ["83890.2", "0"]], "a": [["83989.7", "0"], ["83998.1", "0.013"], ["83998.2", "0.012743"], ["83998.3", "0"], ["84029.1", "0.000333"]], "u": 26647, "seq": 67550550652}, "cts": 1742556565911, "record_time": 1742556565.939876, "EXCHANGE": "BYBIT"}
{"topic": "orderbook.200.BTCUSDT", "ts": 1742556566120, "type": "delta", "data": {"s": "BTCUSDT", "b": [["83965.5", "0.279763"], ["83961.9", "0.000333"], ["83959.2", "0.015787"], ["83924.9", "0"], ["83924.8", "0"], ["83898.7", "0"], ["83895.9", "14.181009"], ["83890.2", "0.00253"], ["83890", "0.0002"]], "a": [["83988.6", "0.003576"], ["83998.1", "0"], ["83998.2", "0"], ["83998.8", "0.04"], ["83999", "0.001333"]], "u": 26648, "seq": 67550550678}, "cts": 1742556566115, "record_time": 1742556566.137436, "EXCHANGE": "BYBIT"}
{"topic": "orderbook.200.BTCUSDT", "ts": 1742556566319, "type": "delta", "data": {"s": "BTCUSDT", "b": [["83936.8", "0.197081"], ["83898.7", "14.095676"], ["83895.9", "0"]], "a": [["83965.6", "0.591361"], ["83998.8", "0"], ["83999", "0.041333"], ["84030.6", "0.118804"]], "u": 26649, "seq": 67550550705}, "cts": 1742556566305, "record_time": 1742556566.33929, "EXCHANGE": "BYBIT"}
{"topic": "orderbook.200.BTCUSDT", "ts": 1742556566519, "type": "delta", "data": {"s": "BTCUSDT", "b": [["83965.5", "0.283053"], ["83945.9", "0.005899"], ["83890", "0"]], "a": [["83974.1", "0"], ["84030.9", "0.089099"]], "u": 26650, "seq": 67550550718}, "cts": 1742556566497, "record_time": 1742556566.537359, "EXCHANGE": "BYBIT"}
{"topic": "orderbook.200.BTCUSDT", "ts": 1742556566919, "type": "delta", "data": {"s": "BTCUSDT", "b": [], "a": [["83970", "0.005942"], ["83986.8", "0.483204"], ["83991.4", "0.02009"], ["83998.8", "0.04"], ["83999", "0.001333"], ["84003.6", "0.005942"], ["84008.2", "0.030132"], ["84020.4", "0.005942"], ["84025", "0.00009"], ["84028.6", "0"], ["84029.1", "0"], ["84030.6", "0"], ["84030.9", "0"]], "u": 26651, "seq": 67550550755}, "cts": 1742556566899, "record_time": 1742556566.938369, "EXCHANGE": "BYBIT"}
{"topic": "orderbook.200.BTCUSDT", "ts": 1742556567120, "type": "delta", "data": {"s": "BTCUSDT", "b": [], "a": [["83965.6", "0.590681"], ["83971.3", "0.0002"], ["84028.5", "0"]], "u": 26652, "seq": 67550550766}, "cts": 1742556567102, "record_time": 1742556567.139866, "EXCHANGE": "BYBIT"}
{"topic": "orderbook.200.BTCUSDT", "ts": 1742556567320, "type": "delta", "data": {"s": "BTCUSDT", "b": [], "a": [["83990.4", "0"], ["83998.8", "0"], ["83999", "0.041333"], ["84028.5", "0.0012"], ["84028.6", "0.0006"]], "u": 26653, "seq": 67550550773}, "cts": 1742556567272, "record_time": 1742556567.338142, "EXCHANGE": "BYBIT"}
{"topic": "orderbook.200.BTCUSDT", "ts": 1742556567519, "type": "delta", "data": {"s": "BTCUSDT", "b": [], "a": [["83988.6", "0"], ["83989.6", "0.035737"]], "u": 26654, "seq": 67550550782}, "cts": 1742556567483, "record_time": 1742556567.537267, "EXCHANGE": "BYBIT"}
{"topic": "orderbook.200.BTCUSDT", "ts": 1742556567720, "type": "delta", "data": {"s": "BTCUSDT", "b": [["83963.9", "0.071493"], ["83962.9", "0"], ["83958.1", "0"], ["83957.6", "0.071498"], ["83953.8", "0.141855"], ["83953.4", "0.045942"], ["83953.2", "0.000516"], ["83947.9", "0.06137"], ["83940.9", "0.054946"], ["83936.6", "0.005942"], ["83933.9", "0.111905"], ["83919.8", "0.151134"], ["83903", "0.005942"], ["83890.6", "0"], ["83890.5", "0"], ["83890.3", "0"], ["83890.2", "0"]], "a": [["83965.6", "0.588538"], ["83982.9", "0.059225"], ["83988.2", "0.003576"], ["83989.9", "0.060109"], ["83996.9", "0.117135"], ["83998.7", "0.04"], ["83998.8", "0.04"], ["83998.9", "0.023819"], ["83999", "0.001333"], ["84007.7", "0.002143"], ["84027.8", "0"], ["84027.9", "0"], ["84028", "0"], ["84028.4", "0"], ["84028.5", "0"], ["84028.6", "0"]], "u": 26655, "seq": 67550550808}, "cts": 1742556567712, "record_time": 1742556567.73941, "EXCHANGE": "BYBIT"}
{"topic": "orderbook.200.BTCUSDT", "ts": 1742556567919, "type": "delta", "data": {"s": "BTCUSDT", "b": [["83941.3", "0"], ["83924.5", "0"], ["83907.7", "0"], ["83890.6", "0.000333"], ["83890.5", "3.246386"], ["83890.3", "0.011992"]], "a": [["83998.6", "0.043247"], ["83998.8", "0"], ["84027.8", "0.059399"]], "u": 26656, "seq": 67550550818}, "cts": 1742556567908, "record_time": 1742556567.937617, "EXCHANGE": "BYBIT"}
{"topic": "orderbook.200.BTCUSDT", "ts": 1742556568119, "type": "delta", "data": {"s": "BTCUSDT", "b": [["83959.6", "0"], ["83890.2", "0.00253"]], "a": [["83965.6", "0.590681"], ["83998.6", "0.003247"], ["83998.8", "0.04"], ["83999.3", "0.063449"], ["84002.1", "0"], ["84007.7", "0"]], "u": 26657, "seq": 67550550829}, "cts": 1742556568113, "record_time": 1742556568.137399, "EXCHANGE": "BYBIT"}
{"topic": "orderbook.200.BTCUSDT", "ts": 1742556568319, "type": "delta", "data": {"s": "BTCUSDT", "b": [], "a": [["83998.6", "0.043247"], ["83998.8", "0"], ["84027.9", "0.001466"]], "u": 26658, "seq": 67550550842}, "cts": 1742556568317, "record_time": 1742556568.336986, "EXCHANGE": "BYBIT"}
{"topic": "orderbook.200.BTCUSDT", "ts": 1742556568520, "type": "delta", "data": {"s": "BTCUSDT", "b": [["83960.1", "0.000153"], ["83890.2", "0"]], "a": [], "u": 26659, "seq": 67550550852}, "cts": 1742556568492, "record_time": 1742556568.538816, "EXCHANGE": "BYBIT"}
{"topic": "orderbook.200.BTCUSDT", "ts": 1742556568920, "type": "delta", "data": {"s": "BTCUSDT", "b": [["83965.5", "0.279763"], ["83964.9", "0.071492"], ["83963.9", "0"], ["83947.9", "0"], ["83940.9", "0.000333"], ["83933.9", "0"], ["83901.5", "14.028077"], ["83898.7", "0"], ["83890.2", "0.00253"], ["83890", "0.0002"]], "a": [["83965.6", "0.594538"], ["83965.8", "0.035727"], ["83982.9", "0.000333"], ["83989.9", "0"], ["83996.9", "0"], ["84011.4", "0.032185"], ["84028", "0.00325"], ["84028.4", "0.001333"]], "u": 26660, "seq": 67550550919}, "cts": 1742556568915, "record_time": 1742556568.986823, "EXCHANGE": "BYBIT"}
{"topic": "orderbook.200.BTCUSDT", "ts": 1742556569119, "type": "delta", "data": {"s": "BTCUSDT", "b": [["83901.5", "14.054106"]], "a": [], "u": 26661, "seq": 67550550950}, "cts": 1742556569078, "record_time": 1742556569.137966, "EXCHANGE": "BYBIT"}
{"topic": "orderbook.200.BTCUSDT", "ts": 1742556569319, "type": "delta", "data": {"s": "BTCUSDT", "b": [["83965.5", "0.28195"], ["83965", "0.029877"], ["83960.8", "0.003181"]], "a": [["83965.6", "0.600538"], ["83975.6", "0.146872"], ["83977.4", "0"], ["84028.5", "0.0012"]], "u": 26662, "seq": 67550551025}, "cts": 1742556569316, "record_time": 1742556569.337815, "EXCHANGE": "BYBIT"}
{"topic": "orderbook.200.BTCUSDT", "ts": 1742556569520, "type": "delta", "data": {"s": "BTCUSDT", "b": [["83964.9", "0"], ["83963.7", "0.071493"], ["83959.2", "0.001779"], ["83958.2", "0"], ["83924.9", "0.013"], ["83924.8", "0.012882"], ["83890", "0"]], "a": [["83997.9", "0.013"], ["83998", "0.072278"], ["84028.5", "0"]], "u": 26663, "seq": 67550551096}, "cts": 1742556569488, "record_time": 1742556569.537742, "EXCHANGE": "BYBIT"}
{"topic": "orderbook.200.BTCUSDT", "ts": 1742556569719, "type": "delta", "data": {"s": "BTCUSDT", "b": [["83901.5", "0"], ["83890.7", "0"], ["83890.1", "0.353814"], ["83890", "0.0002"]], "a": [], "u": 26664, "seq": 67550551138}, "cts": 1742556569717, "record_time": 1742556569.74009, "EXCHANGE": "BYBIT"}
{"topic": "orderbook.200.BTCUSDT", "ts": 1742556569920, "type": "delta", "data": {"s": "BTCUSDT", "b": [["83965.5", "0.11095"], ["83965", "0.003181"], ["83953.8", "0.198288"], ["83951.4", "0.121172"], ["83951.1", "0.120101"], ["83947.3", "0.124415"], ["83941.3", "0.179486"], ["83940.9", "0.166933"], ["83940.3", "0.167874"], ["83933.9", "0.277966"], ["83933.3", "0.299021"], ["83932.2", "0.272508"], ["83898.7", "13.934734"], ["83891.3", "0"], ["83891.2", "0"], ["83890.9", "0"], ["83890.6", "0"], ["83890.5", "0"], ["83890.3", "0"], ["83890.2", "0"], ["83890.1", "0"], ["83890", "0"]], "a": [["83965.8", "0.108549"], ["83975.9", "0.112439"], ["83976.3", "0.119424"], ["83980.2", "0.113672"], ["83986.1", "0.221418"], ["83986.4", "0.18886"], ["83987.2", "0.171404"], ["83993.4", "0.368288"], ["83994.2", "0.309771"], ["83995.2", "0.28479"], ["84027.7", "0"], ["84027.8", "0"], ["84027.9", "0"], ["84028", "0"], ["84028.4", "0"]], "u": 26665, "seq": 67550551202}, "cts": 1742556569904, "record_time": 1742556569.937316, "EXCHANGE": "BYBIT"}
{"topic": "orderbook.200.BTCUSDT", "ts": 1742556570119, "type": "delta", "data": {"s": "BTCUSDT", "b": [["83965.5", "0.28195"], ["83953.8", "0.141855"], ["83951.4", "0"], ["83951.1", "0"], ["83949.5", "0.092774"], ["83947.3", "0"], ["83945.3", "0.132673"], ["83941.3", "0"], ["83940.9", "0.000333"], ["83940.3", "0"], ["83936.8", "0.366761"], ["83933.9", "0"], ["83933.3", "0"], ["83932.2", "0"], ["83891.3", "0.009"], ["83891.2", "0.04"], ["83890.9", "0.00625"], ["83890.6", "0.000333"], ["83890.5", "3.246386"], ["83890.3", "0.011992"], ["83890.2", "0.00253"], ["83890.1", "0.353814"]], "a": [["83975.9", "0"], ["83976.3", "0.000514"], ["83980.2", "0"], ["83986.1", "0.052"], ["83986.4", "0.001333"], ["83987.2", "0"], ["83993.3", "0.38079"], ["83993.4", "0.079535"], ["83994.2", "0"], ["83995.2", "0"], ["84027.7", "0.027532"], ["84027.8", "0.059399"], ["84027.9", "0.001466"], ["84028", "0.00325"], ["84028.4", "0.001333"]], "u": 26666, "seq": 67550551249}, "cts": 1742556570093, "record_time": 1742556570.138819, "EXCHANGE": "BYBIT"}
{"topic": "orderbook.200.BTCUSDT", "ts": 1742556570320, "type": "delta", "data": {"s": "BTCUSDT", "b": [["83965.5", "0.279763"], ["83949.5", "0.061348"], ["83945.3", "0.084198"], ["83936.8", "0.059399"]], "a": [["83965.6", "0.602681"], ["83993.3", "0.132338"], ["84011.4", "0.030042"]], "u": 26667, "seq": 67550551281}, "cts": 1742556570303, "record_time": 1742556570.337843, "EXCHANGE": "BYBIT"}
{"topic": "orderbook.200.BTCUSDT", "ts": 1742556570920, "type": "delta", "data": {"s": "BTCUSDT", "b": [["83965.5", "0.118858"], ["83960.1", "0"], ["83943", "0"], ["83890", "0.0002"], ["83889.9", "0.011992"]], "a": [["83965.6", "0.773681"], ["83997.9", "0.012743"]], "u": 26668, "seq": 67550551338}, "cts": 1742556570906, "record_time": 1742556570.938747, "EXCHANGE": "BYBIT"}
{"topic": "orderbook.200.BTCUSDT", "ts": 1742556571119, "type": "delta", "data": {"s": "BTCUSDT", "b": [["83965.5", "0.289858"], ["83964.7", "0.071492"], ["83963.7", "0"], ["83959.1", "0.082872"], ["83957.6", "0"], ["83947.9", "0.061515"], ["83945.3", "0.053711"], ["83940.9", "0.059867"], ["83934.2", "0"], ["83933.9", "0.109739"], ["83924.9", "0.012882"]], "a": [["83965.6", "0.602681"], ["83982.9", "0.05946"], ["83989.9", "0.059088"], ["83996.9", "0.10956"], ["83997.9", "0"], ["83998.1", "0.012743"], ["83998.6", "0.003247"], ["83998.8", "0.04"], ["84027.9", "0"], ["84028", "0"], ["84028.4", "0"]], "u": 26669, "seq": 67550551376}, "cts": 1742556571117, "record_time": 1742556571.137941, "EXCHANGE": "BYBIT"}
{"topic": "orderbook.200.BTCUSDT", "ts": 1742556571320, "type": "delta", "data": {"s": "BTCUSDT", "b": [["83965.5", "0.28959"], ["83964.2", "0.009175"], ["83959.2", "0.02708"], ["83947.9", "0"], ["83940.9", "0.000333"], ["83934.1", "0.111968"], ["83933.9", "0"], ["83901.4", "13.771465"], ["83898.7", "0"], ["83889.8", "0.001333"]], "a": [["83965.6", "0.600538"], ["83982.9", "0.000333"], ["83989.9", "0"], ["83996.9", "0"], ["83997.9", "0.013"], ["83998.1", "0"], ["83998.6", "0.043247"], ["83998.8", "0"], ["84009.7", "0.002143"], ["84027.9", "0.001466"], ["84028", "0.00325"]], "u": 26670, "seq": 67550551426}, "cts": 1742556571317, "record_time": 1742556571.338319, "EXCHANGE": "BYBIT"}
{"topic": "orderbook.200.BTCUSDT", "ts": 1742556571519, "type": "delta", "data": {"s": "BTCUSDT", "b": [["83936.8", "0.210875"], ["83901.5", "13.771465"], ["83901.4", "0"]], "a": [["83997.9", "0"], ["83998.1", "0.012743"], ["83998.6", "0.003247"], ["83998.8", "0.04"], ["84028", "0"]], "u": 26671, "seq": 67550551446}, "cts": 1742556571484, "record_time": 1742556571.537953, "EXCHANGE": "BYBIT"}
{"topic": "orderbook.200.BTCUSDT", "ts": 1742556571720, "type": "delta", "data": {"s": "BTCUSDT", "b": [["83960.3", "0.000153"], ["83901.5", "13.467332"], ["83889.8", "0"]], "a": [], "u": 26672, "seq": 67550551472}, "cts": 1742556571652, "record_time": 1742556571.740148, "EXCHANGE": "BYBIT"}
{"topic": "orderbook.200.BTCUSDT", "ts": 1742556571919, "type": "delta", "data": {"s": "BTCUSDT", "b": [["83965.5", "0.279495"], ["83964.7", "0"], ["83963.7", "0.071493"], ["83925", "0.013"], ["83924.8", "0"], ["83901.5", "0"], ["83898.7", "13.467332"]], "a": [], "u": 26673, "seq": 67550551483}, "cts": 1742556571869, "record_time": 1742556571.937274, "EXCHANGE": "BYBIT"}
{"topic": "orderbook.200.BTCUSDT", "ts": 1742556572119, "type": "delta", "data": {"s": "BTCUSDT", "b": [["83925", "0"], ["83924.8", "0.012882"]], "a": [["83997.9", "0.013"], ["83998.1", "0"], ["83998.6", "0.043247"], ["83998.8", "0"], ["84028", "0.00325"]], "u": 26674, "seq": 67550551521}, "cts": 1742556572056, "record_time": 1742556572.137382, "EXCHANGE": "BYBIT"}
{"topic": "orderbook.200.BTCUSDT", "ts": 1742556572320, "type": "delta", "data": {"s": "BTCUSDT", "b": [["83965.5", "0.289751"], ["83947.9", "0.06218"], ["83940.9", "0.06031"], ["83933.9", "0.122513"], ["83924.9", "0"], ["83924.7", "0.012882"], ["83890", "0"], ["83889.9", "0"]], "a": [["83982.9", "0.05756"], ["83989.9", "0.057276"], ["83996.9", "0.123709"], ["83997.9", "0"], ["83998.1", "0.012743"], ["83998.6", "0.003247"], ["83998.8", "0.04"], ["84027.8", "0"], ["84027.9", "0"], ["84028", "0"]], "u": 26675, "seq": 67550551538}, "cts": 1742556572288, "record_time": 1742556572.337758, "EXCHANGE": "BYBIT"}
{"topic": "orderbook.200.BTCUSDT", "ts": 1742556572520, "type": "delta", "data": {"s": "BTCUSDT", "b": [["83963.7", "0"], ["83959.2", "0.001779"], ["83959.1", "0.011375"], ["83957.4", "0.071499"], ["83947.9", "0"], ["83945.9", "0.006522"], ["83941", "0.057627"], ["83940.9", "0.000333"], ["83937.1", "0"], ["83933.9", "0"], ["83924.9", "0.013"], ["83924.7", "0"], ["83890", "0.0002"], ["83889.9", "0.011992"]], "a": [["83982.9", "0.000333"], ["83989.9", "0"], ["83996.9", "0"], ["83997.9", "0.013"], ["83998.1", "0"], ["83998.6", "0.043247"], ["83998.8", "0"], ["84027.8", "0.059399"], ["84027.9", "0.001466"], ["84028", "0.00325"]], "u": 26676, "seq": 67550551567}, "cts": 1742556572490, "record_time": 1742556572.537693, "EXCHANGE": "BYBIT"}
{"topic": "orderbook.200.BTCUSDT", "ts": 1742556572719, "type": "delta", "data": {"s": "BTCUSDT", "b": [["83941", "0"], ["83889.8", "0.001333"]], "a": [["83965.6", "0.606538"]], "u": 26677, "seq": 67550551576}, "cts": 1742556572684, "record_time": 1742556572.737298, "EXCHANGE": "BYBIT"}
{"topic": "orderbook.200.BTCUSDT", "ts": 1742556572919, "type": "delta", "data": {"s": "BTCUSDT", "b": [["83965.5", "0.279495"], ["83963.7", "0.071493"], ["83959.2", "0.02708"], ["83958.7", "0.071497"], ["83957.4", "0"], ["83924.9", "0.012882"], ["83914.7", "0.051768"], ["83889.8", "0"]], "a": [["83965.6", "0.608681"], ["83997.9", "0"], ["83998.1", "0.012743"], ["84009.7", "0"], ["84028.4", "0.001333"]], "u": 26678, "seq": 67550551595}, "cts": 1742556572914, "record_time": 1742556572.937711, "EXCHANGE": "BYBIT"}
{"topic": "orderbook.200.BTCUSDT", "ts": 1742556573120, "type": "delta", "data": {"s": "BTCUSDT", "b": [["83924.9", "0"], ["83924.7", "0.012882"]], "a": [["83998", "0.059535"], ["83998.1", "0"], ["83998.3", "0.012743"], ["83998.4", "0.012743"], ["83998.6", "0.003247"], ["83998.7", "0"], ["83999", "0.041333"], ["83999.1", "0.04"], ["84028.4", "0"]], "u": 26679, "seq": 67550551622}, "cts": 1742556573113, "record_time": 1742556573.138519, "EXCHANGE": "BYBIT"}
{"topic": "orderbook.200.BTCUSDT", "ts": 1742556573320, "type": "delta", "data": {"s": "BTCUSDT", "b": [["83965.5", "0.288736"], ["83925", "0.013"], ["83924.9", "0.012882"], ["83924.8", "0"], ["83924.7", "0"]], "a": [["83969.2", "0.071489"], ["83971.1", "0.015101"], ["83973", "0"], ["83998", "0.072535"], ["83998.1", "0.012743"], ["83998.3", "0"], ["83998.4", "0"], ["84028.4", "0.001333"]], "u": 26680, "seq": 67550551646}, "cts": 1742556573306, "record_time": 1742556573.337433, "EXCHANGE": "BYBIT"}
{"topic": "orderbook.200.BTCUSDT", "ts": 1742556573520, "type": "delta", "data": {"s": "BTCUSDT", "b": [["83965.5", "0.287313"], ["83937.1", "0.037424"], ["83889.9", "0"]], "a": [["83986.7", "0.001032"], ["83998.7", "0.04"], ["83998.8", "0.04"], ["83999", "0.001333"], ["83999.1", "0"], ["84028", "0"], ["84028.4", "0"]], "u": 26681, "seq": 67550551687}, "cts": 1742556573510, "record_time": 1742556573.537463, "EXCHANGE": "BYBIT"}
{"topic": "orderbook.200.BTCUSDT", "ts": 1742556573719, "type": "delta", "data": {"s": "BTCUSDT", "b": [], "a": [["83965.6", "0.614681"], ["83984.9", "0.001218"], ["83986.7", "0"]], "u": 26682, "seq": 67550551705}, "cts": 1742556573694, "record_time": 1742556573.737604, "EXCHANGE": "BYBIT"}
{"topic": "orderbook.200.BTCUSDT", "ts": 1742556573920, "type": "delta", "data": {"s": "BTCUSDT", "b": [["83901.4", "13.158558"], ["83898.7", "0"]], "a": [["83984.9", "0"], ["84028", "0.00325"]], "u": 26683, "seq": 67550551724}, "cts": 1742556573886, "record_time": 1742556573.938317, "EXCHANGE": "BYBIT"}
{"topic": "orderbook.200.BTCUSDT", "ts": 1742556574320, "type": "delta", "data": {"s": "BTCUSDT", "b": [["83965.5", "0.278072"]], "a": [["83965.6", "0.613475"], ["83987", "0.183747"]], "u": 26684, "seq": 67550551753}, "cts": 1742556574316, "record_time": 1742556574.340143, "EXCHANGE": "BYBIT"}
{"topic": "orderbook.200.BTCUSDT", "ts": 1742556574519, "type": "delta", "data": {"s": "BTCUSDT", "b": [["83901.4", "0"], ["83898.7", "12.839205"]], "a": [["83965.6", "0.619475"], ["83979.6", "0.023513"], ["83987", "0.182646"]], "u": 26685, "seq": 67550551781}, "cts": 1742556574499, "record_time": 1742556574.538964, "EXCHANGE": "BYBIT"}
{"topic": "orderbook.200.BTCUSDT", "ts": 1742556574720, "type": "delta", "data": {"s": "BTCUSDT", "b": [["83965.5", "0.449739"], ["83965.3", "0.071492"], ["83963.8", "0.022043"], ["83963.7", "0"], ["83960.2", "0.071496"], ["83955.7", "0"], ["83925", "0"], ["83924.8", "0.012882"], ["83890", "0"]], "a": [["83965.6", "0.448475"], ["83965.8", "0.035727"], ["83984.1", "0.000997"], ["83995.6", "0.001466"], ["83995.7", "0.168571"], ["83998", "0.072278"], ["84028", "0"]], "u": 26686, "seq": 67550551814}, "cts": 1742556574717, "record_time": 1742556574.738299, "EXCHANGE": "BYBIT"}
{"topic": "orderbook.200.BTCUSDT", "ts": 1742556574920, "type": "delta", "data": {"s": "BTCUSDT", "b": [["83965.5", "0.460302"], ["83965.4", "0.027082"], ["83963.8", "0"], ["83961.8", "0.0497"], ["83961.7", "0.071495"], ["83960.2", "0"], ["83959.2", "0.001779"], ["83957.8", "0.03015"], ["83924.9", "0"], ["83924.7", "0.012882"], ["83901.5", "12.658757"], ["83898.7", "0"]], "a": [["83965.6", "0.452093"], ["83968", "0"], ["83970.3", "0.012248"], ["83978.1", "0.171"], ["83978.8", "0.000595"], ["83979.6", "0.003513"], ["83980.1", "0"], ["83984.1", "0"], ["83998", "0.059535"], ["83998.1", "0"], ["83998.6", "0.016247"], ["83998.7", "0.012743"], ["83998.8", "0"], ["83999.3", "0.103449"], ["83999.4", "0.040516"], ["84003.1", "0"], ["84007.7", "0.002143"], ["84017.3", "2.256638"], ["84028", "0.00325"], ["84028.4", "0.001333"], ["84028.5", "0.0012"], ["84028.6", "0.0006"]], "u": 26687, "seq": 67550551914}, "cts": 1742556574916, "record_time": 1742556574.939188, "EXCHANGE": "BYBIT"}
{"topic": "orderbook.200.BTCUSDT", "ts": 1742556575120, "type": "delta", "data": {"s": "BTCUSDT", "b": [["83965.5", "0.458809"], ["83961.8", "0.028252"], ["83961.7", "0"], ["83960.3", "0.071649"], ["83925.2", "0.013"], ["83925.1", "0.012882"], ["83924.8", "0"], ["83924.7", "0"], ["83890", "0.0002"]], "a": [["83977", "0.17862"], ["83984.1", "0.000997"], ["84000.2", "0.039256"], ["84028.6", "0"]], "u": 26688, "seq": 67550552051}, "cts": 1742556575116, "record_time": 1742556575.137809, "EXCHANGE": "BYBIT"}
{"topic": "orderbook.200.BTCUSDT", "ts": 1742556575320, "type": "delta", "data": {"s": "BTCUSDT", "b": [["83961.8", "0.046169"], ["83960.3", "0.071496"], ["83925.3", "0.013"], ["83925.2", "0.012882"], ["83925.1", "0"]], "a": [["83984.1", "0"], ["83989.6", "0"], ["83998.5", "0.013"], ["83998.6", "0.01599"], ["83998.7", "0"], ["83999.3", "0.063449"], ["83999.4", "0.000516"], ["83999.7", "0.055333"], ["83999.8", "0.04009"], ["84003.1", "2.256638"], ["84017.3", "0"], ["84028.6", "0.0006"], ["84029.1", "0.000333"]], "u": 26689, "seq": 67550552195}, "cts": 1742556575316, "record_time": 1742556575.338135, "EXCHANGE": "BYBIT"}
{"topic": "orderbook.200.BTCUSDT", "ts": 1742556575519, "type": "delta", "data": {"s": "BTCUSDT", "b": [["83950.5", "0"], ["83889.9", "0.011992"]], "a": [["83965.6", "0.452332"], ["83976.2", "0.203559"], ["83977", "0"], ["83979.7", "0.178615"], ["83988.2", "0"], ["83988.5", "0.003576"], ["83989.6", "0.035737"], ["83998.5", "0"], ["83998.6", "0.003247"], ["83998.7", "0.013"], ["83998.8", "0.012743"], ["83999.4", "0.040516"], ["83999.5", "0.04"], ["83999.7", "0.015333"], ["83999.8", "0.00009"], ["84000.2", "0.719869"], ["84028.5", "0"], ["84028.6", "0"], ["84029.1", "0"]], "u": 26690, "seq": 67550552285}, "cts": 1742556575511, "record_time": 1742556575.539719, "EXCHANGE": "BYBIT"}
{"topic": "orderbook.200.BTCUSDT", "ts": 1742556575719, "type": "delta", "data": {"s": "BTCUSDT", "b": [["83917.4", "0.135557"], ["83914.6", "0"], ["83901.5", "12.62963"]], "a": [["83985.7", "0.001168"], ["83989.6", "0.035738"], ["83998.5", "0.013"], ["83998.6", "0.01599"], ["83998.7", "0"], ["83998.8", "0"], ["83999.2", "0.04"], ["83999.3", "0.04"], ["83999.4", "0.000516"], ["83999.5", "0"], ["84002.1", "0.063449"], ["84028.4", "0"]], "u": 26691, "seq": 67550552315}, "cts": 1742556575701, "record_time": 1742556575.744475, "EXCHANGE": "BYBIT"}
{"topic": "orderbook.200.BTCUSDT", "ts": 1742556575919, "type": "delta", "data": {"s": "BTCUSDT", "b": [["83965.5", "0.448246"], ["83914.7", "0.003181"]], "a": [["83965.6", "0.454475"], ["83985.7", "0"], ["83989.6", "0"], ["84007.7", "0"], ["84028.4", "0.001333"], ["84028.5", "0.0012"], ["84028.6", "0.0006"]], "u": 26692, "seq": 67550552336}, "cts": 1742556575900, "record_time": 1742556575.93764, "EXCHANGE": "BYBIT"}
{"topic": "orderbook.200.BTCUSDT", "ts": 1742556576119, "type": "delta", "data": {"s": "BTCUSDT", "b": [["83962", "0.071495"], ["83960.3", "0"], ["83891.2", "0"], ["83889.8", "0.001333"]], "a": [["83965.6", "0.452332"], ["83988.5", "0"], ["83989.6", "0.035738"], ["83998.5", "0"], ["83998.6", "0.003247"], ["83998.7", "0.013"], ["83998.8", "0.012743"], ["83999.2", "0"], ["83999.3", "0"], ["83999.4", "0.040516"], ["83999.5", "0.04"], ["84008.6", "0.002659"]], "u": 26693, "seq": 67550552381}, "cts": 1742556576109, "record_time": 1742556576.141208, "EXCHANGE": "BYBIT"}
{"topic": "orderbook.200.BTCUSDT", "ts": 1742556576320, "type": "delta", "data": {"s": "BTCUSDT", "b": [["83965.5", "0.460184"], ["83962.1", "0.028306"], ["83962", "0"], ["83961.8", "0"], ["83960.5", "0.000846"], ["83960.3", "0.071496"], ["83958.7", "0"], ["83936.2", "0"], ["83889.5", "0.003181"], ["83889.4", "0.001466"]], "a": [["83998.7", "0"], ["83998.8", "0"], ["83999.4", "0.000516"], ["83999.5", "0"], ["84000.5", "0.013"], ["84000.6", "0.012743"], ["84001.2", "0.04"], ["84001.3", "0.04"], ["84028.6", "0"]], "u": 26694, "seq": 67550552458}, "cts": 1742556576316, "record_time": 1742556576.337797, "EXCHANGE": "BYBIT"}
{"topic": "orderbook.200.BTCUSDT", "ts": 1742556576520, "type": "delta", "data": {"s": "BTCUSDT", "b": [["83965.5", "0.345163"], ["83962.1", "0.04624"], ["83960.5", "0.000768"], ["83958.2", "0.071498"], ["83936.8", "0.157282"], ["83925.5", "0.013516"], ["83925.4", "0.012882"], ["83925.3", "0"], ["83925.2", "0"]], "a": [["83989.6", "0"], ["84028.6", "0.0006"]], "u": 26695, "seq": 67550552512}, "cts": 1742556576514, "record_time": 1742556576.537841, "EXCHANGE": "BYBIT"}
{"topic": "orderbook.200.BTCUSDT", "ts": 1742556576719, "type": "delta", "data": {"s": "BTCUSDT", "b": [["83965.5", "0.516163"], ["83960.7", "0.000153"], ["83901.5", "12.611418"], ["83889.4", "0"]], "a": [["83989.6", "0.035737"], ["84028.6", "0"]], "u": 26696, "seq": 67550552554}, "cts": 1742556576700, "record_time": 1742556576.737088, "EXCHANGE": "BYBIT"}
{"topic": "orderbook.200.BTCUSDT", "ts": 1742556576920, "type": "delta", "data": {"s": "BTCUSDT", "b": [["83961.6", "0.0002"], ["83889.5", "0"]], "a": [["83965.6", "0.454475"], ["84008.6", "0.000516"]], "u": 26697, "seq": 67550552587}, "cts": 1742556576916, "record_time": 1742556576.937843, "EXCHANGE": "BYBIT"}
{"topic": "orderbook.200.BTCUSDT", "ts": 1742556577120, "type": "delta", "data": {"s": "BTCUSDT", "b": [], "a": [["83989.6", "0"], ["84028.6", "0.0006"]], "u": 26698, "seq": 67550552617}, "cts": 1742556577109, "record_time": 1742556577.13931, "EXCHANGE": "BYBIT"}
{"topic": "orderbook.200.BTCUSDT", "ts": 1742556577319, "type": "delta", "data": {"s": "BTCUSDT", "b": [["83965.5", "0.504225"], ["83925.5", "0.000516"], ["83925.3", "0.012882"], ["83889.8", "0"]], "a": [["83989.6", "0.035738"], ["84028.6", "0"]], "u": 26699, "seq": 67550552650}, "cts": 1742556577308, "record_time": 1742556577.337232, "EXCHANGE": "BYBIT"}
{"topic": "orderbook.200.BTCUSDT", "ts": 1742556577520, "type": "delta", "data": {"s": "BTCUSDT", "b": [["83961.9", "0.071828"], ["83960.3", "0"], ["83925.5", "0.013516"], ["83925.3", "0"], ["83889.8", "0.001333"], ["83889.5", "0.003181"]], "a": [["83989.6", "0.035737"]], "u": 26700, "seq": 67550552682}, "cts": 1742556577512, "record_time": 1742556577.53894, "EXCHANGE": "BYBIT"}
{"topic": "orderbook.200.BTCUSDT", "ts": 1742556577719, "type": "delta", "data": {"s": "BTCUSDT", "b": [["83965.5", "0.515734"], ["83901.5", "12.59417"]], "a": [["83965.6", "0.460475"], ["83989.6", "0"], ["83991.6", "0"], ["84028.6", "0.0006"], ["84029.1", "0.000333"]], "u": 26701, "seq": 67550552730}, "cts": 1742556577716, "record_time": 1742556577.737609, "EXCHANGE": "BYBIT"}
{"topic": "orderbook.200.BTCUSDT", "ts": 1742556577920, "type": "delta", "data": {"s": "BTCUSDT", "b": [["83965.5", "0.516534"], ["83964.5", "0.011915"], ["83960.7", "0"], ["83943.5", "0.119096"], ["83931.8", "0.090432"], ["83925.5", "0.000516"], ["83925.3", "0.012882"], ["83909.9", "0.015"], ["83889.9", "0"], ["83889.8", "0"], ["83889.5", "0"]], "a": [["83965.6", "0.337422"], ["83969.2", "0"], ["83970.3", "0.000333"], ["83970.6", "0.0017"], ["83971.1", "0"], ["83973.2", "0"], ["83973.3", "0.025944"], ["83973.7", "0.071485"], ["83974.3", "0"], ["83981.4", "0"], ["83989.4", "0"], ["83996", "0"], ["84000.5", "0"], ["84000.7", "0.036562"], ["84001.2", "0"], ["84001.4", "0.04"], ["84003.1", "0"], ["84008.5", "0.002143"], ["84020.1", "2.256638"], ["84030.6", "0.118804"], ["84030.9", "0.089099"], ["84031.1", "0.025312"], ["84031.8", "0.000516"], ["84032.2", "0.00325"]], "u": 26702, "seq": 67550552862}, "cts": 1742556577916, "record_time": 1742556577.938067, "EXCHANGE": "BYBIT"}
{"topic": "orderbook.200.BTCUSDT", "ts": 1742556578120, "type": "delta", "data": {"s": "BTCUSDT", "b": [["83945.3", "0.082725"]], "a": [["83965.6", "0.385054"], ["83965.8", "0.107219"], ["83971.5", "0.051725"], ["83971.6", "0.071487"], ["83973.3", "0"], ["83983", "0.023923"], ["83987.5", "0"], ["84000.2", "0.093558"], ["84017.3", "2.256638"], ["84020.1", "0"], ["84031", "0.171"], ["84032.2", "0"]], "u": 26703, "seq": 67550552980}, "cts": 1742556578114, "record_time": 1742556578.140466, "EXCHANGE": "BYBIT"}
{"topic": "orderbook.200.BTCUSDT", "ts": 1742556578320, "type": "delta", "data": {"s": "BTCUSDT", "b": [], "a": [["83965.6", "0.38684"], ["83990", "0.035738"], ["84003.1", "2.256638"], ["84017.3", "0"], ["84031.8", "0"]], "u": 26704, "seq": 67550553048}, "cts": 1742556578314, "record_time": 1742556578.339968, "EXCHANGE": "BYBIT"}
{"topic": "orderbook.200.BTCUSDT", "ts": 1742556578520, "type": "delta", "data": {"s": "BTCUSDT", "b": [["83965.5", "0.515345"], ["83947.3", "0.496196"], ["83941.7", "0.532546"], ["83932.6", "0"], ["83923.9", "0"], ["83914.4", "3.309275"], ["83890", "0"]], "a": [["83969.7", "0.071488"], ["83971.5", "0.030279"], ["83973.7", "0"], ["83979.2", "0.146324"], ["83979.6", "0"], ["83982.7", "0.048"], ["83986.8", "0.005942"], ["83996.9", "0.486726"], ["83999", "0.520883"], ["84000.6", "0"], ["84000.8", "0.012743"], ["84001.3", "0"], ["84001.5", "0.04"]], "u": 26705, "seq": 67550553126}, "cts": 1742556578514, "record_time": 1742556578.540863, "EXCHANGE": "BYBIT"}
{"topic": "orderbook.200.BTCUSDT", "ts": 1742556578720, "type": "delta", "data": {"s": "BTCUSDT", "b": [["83964.5", "0"], ["83949.5", "0.204495"], ["83932.8", "0.023633"], ["83924", "0"], ["83904.4", "12.57841"], ["83901.5", "0"], ["83890.5", "0"], ["83890", "0.0002"], ["83889.9", "0.011992"], ["83889.8", "0.001333"]], "a": [["83983.7", "0.127167"]], "u": 26706, "seq": 67550553161}, "cts": 1742556578696, "record_time": 1742556578.738882, "EXCHANGE": "BYBIT"}
{"topic": "orderbook.200.BTCUSDT", "ts": 1742556578919, "type": "delta", "data": {"s": "BTCUSDT", "b": [["83925.5", "0.013516"], ["83925.3", "0"], ["83889.5", "0.003181"]], "a": [], "u": 26707, "seq": 67550553164}, "cts": 1742556578894, "record_time": 1742556578.937956, "EXCHANGE": "BYBIT"}
{"topic": "orderbook.200.BTCUSDT", "ts": 1742556579119, "type": "delta", "data": {"s": "BTCUSDT", "b": [["83914.5", "1.000689"], ["83889.5", "0"]], "a": [], "u": 26708, "seq": 67550553171}, "cts": 1742556579097, "record_time": 1742556579.137922, "EXCHANGE": "BYBIT"}
{"topic": "orderbook.200.BTCUSDT", "ts": 1742556579319, "type": "delta", "data": {"s": "BTCUSDT", "b": [["83904.4", "0"], ["83901.5", "12.57841"]], "a": [], "u": 26709, "seq": 67550553180}, "cts": 1742556579259, "record_time": 1742556579.337746, "EXCHANGE": "BYBIT"}
{"topic": "orderbook.200.BTCUSDT", "ts": 1742556579520, "type": "delta", "data": {"s": "BTCUSDT", "b": [["83956.1", "0.0062"], ["83955.2", "0"], ["83927.4", "0.060999"], ["83926.5", "0"], ["83904.4", "12.57841"], ["83901.5", "0"], ["83889.5", "0.003181"]], "a": [], "u": 26710, "seq": 67550553215}, "cts": 1742556579509, "record_time": 1742556579.539922, "EXCHANGE": "BYBIT"}
{"topic": "orderbook.200.BTCUSDT", "ts": 1742556579719, "type": "delta", "data": {"s": "BTCUSDT", "b": [["83953.2", "0.113593"], ["83945.3", "0.238862"], ["83942.7", "0.164003"], ["83935.7", "0.308445"], ["83889.5", "0"]], "a": [["83965.6", "0.299305"], ["83976.2", "0.024937"], ["83977.7", "0.119762"], ["83988.2", "0.170914"], ["83994", "0"], ["83995.2", "0.30605"], ["84000.2", "0.763762"], ["84002.1", "0"], ["84003.1", "0"], ["84004.9", "0.093491"], ["84017.3", "2.256638"], ["84031.1", "0"]], "u": 26711, "seq": 67550553348}, "cts": 1742556579717, "record_time": 1742556579.739463, "EXCHANGE": "BYBIT"}
{"topic": "orderbook.200.BTCUSDT", "ts": 1742556579919, "type": "delta", "data": {"s": "BTCUSDT", "b": [["83953.2", "0.000516"], ["83942.8", "0.118804"], ["83942.7", "0"], ["83935.7", "0.003181"]], "a": [["83965.6", "0.3136"], ["83965.8", "0.071492"], ["83965.9", "0"], ["83966.1", "0"], ["83977.7", "0"], ["83988.2", "0"], ["83990", "0"], ["83990.1", "0.035737"], ["83995.2", "0"], ["84000.2", "0.093558"], ["84031.1", "0.025312"], ["84031.8", "0.000516"], ["84032.2", "0.00325"], ["84032.5", "0.001466"], ["84032.6", "0.001333"]], "u": 26712, "seq": 67550553460}, "cts": 1742556579913, "record_time": 1742556579.936922, "EXCHANGE": "BYBIT"}
{"topic": "orderbook.200.BTCUSDT", "ts": 1742556580120, "type": "delta", "data": {"s": "BTCUSDT", "b": [["83964.2", "0.003"]], "a": [["84003.1", "2.256638"], ["84017.3", "0"]], "u": 26713, "seq": 67550553521}, "cts": 1742556580111, "record_time": 1742556580.138965, "EXCHANGE": "BYBIT"}
{"topic": "orderbook.200.BTCUSDT", "ts": 1742556580320, "type": "delta", "data": {"s": "BTCUSDT", "b": [["83917.9", "0.125051"], ["83904.4", "0"], ["83901.5", "12.577979"], ["83889.8", "0"]], "a": [], "u": 26714, "seq": 67550553552}, "cts": 1742556580315, "record_time": 1742556580.338216, "EXCHANGE": "BYBIT"}
{"topic": "orderbook.200.BTCUSDT", "ts": 1742556580520, "type": "delta", "data": {"s": "BTCUSDT", "b": [["83965.5", "0.515414"], ["83925.5", "0.000516"], ["83925.3", "0.012882"], ["83889.9", "0"]], "a": [["83965.6", "0.315386"], ["84000.7", "0.023819"], ["84000.9", "0.012743"], ["84001.4", "0"], ["84001.6", "0.063819"]], "u": 26715, "seq": 67550553583}, "cts": 1742556580517, "record_time": 1742556580.537249, "EXCHANGE": "BYBIT"}
{"topic": "orderbook.200.BTCUSDT", "ts": 1742556580720, "type": "delta", "data": {"s": "BTCUSDT", "b": [["83901.5", "12.577696"]], "a": [], "u": 26716, "seq": 67550553612}, "cts": 1742556580681, "record_time": 1742556580.737771, "EXCHANGE": "BYBIT"}
{"topic": "orderbook.200.BTCUSDT", "ts": 1742556580919, "type": "delta", "data": {"s": "BTCUSDT", "b": [["83965.5", "0.513631"], ["83932.8", "0.036497"]], "a": [["84000.2", "0.744727"], ["84000.4", "0.012743"], ["84000.5", "0.012743"], ["84000.8", "0"], ["84000.9", "0"], ["84001.1", "0.04"], ["84001.2", "0.04"], ["84001.5", "0"], ["84001.6", "0.023819"], ["84032.6", "0"]], "u": 26717, "seq": 67550553688}, "cts": 1742556580906, "record_time": 1742556580.937388, "EXCHANGE": "BYBIT"}
{"topic": "orderbook.200.BTCUSDT", "ts": 1742556581119, "type": "delta", "data": {"s": "BTCUSDT", "b": [], "a": [["83965.6", "0.3136"]], "u": 26718, "seq": 67550553709}, "cts": 1742556581116, "record_time": 1742556581.137919, "EXCHANGE": "BYBIT"}
{"topic": "orderbook.200.BTCUSDT", "ts": 1742556581320, "type": "delta", "data": {"s": "BTCUSDT", "b": [["83942.8", "0"], ["83889.9", "0.011992"]], "a": [["83965.6", "0.317529"], ["84008.5", "0"], ["84032.6", "0.001333"]], "u": 26719, "seq": 67550553744}, "cts": 1742556581316, "record_time": 1742556581.361491, "EXCHANGE": "BYBIT"}
{"topic": "orderbook.200.BTCUSDT", "ts": 1742556581520, "type": "delta", "data": {"s": "BTCUSDT", "b": [["83965.5", "0.286413"], ["83965.4", "0.001333"], ["83901.5", "0"], ["83889.8", "0.001333"]], "a": [["83965.6", "0.488517"]], "u": 26720, "seq": 67550553788}, "cts": 1742556581517, "record_time": 1742556581.620506, "EXCHANGE": "BYBIT"}
{"success": true, "ret_msg": "pong", "conn_id": "d59011eb-c49f-46ad-9bdd-f698ff66c36b", "op": "ping", "record_time": 1742556581.693532, "EXCHANGE": "BYBIT"}
{"topic": "orderbook.200.BTCUSDT", "ts": 1742556581720, "type": "delta", "data": {"s": "BTCUSDT", "b": [["83965.5", "0.286652"], ["83964.2", "0"], ["83961.9", "0.000333"], ["83960.2", "0.071496"], ["83947.3", "0"], ["83937", "0.005943"], ["83936.3", "0.496196"], ["83932.7", "0.118804"], ["83925.4", "0"], ["83925.3", "0"], ["83925.2", "0.012882"], ["83925.1", "0.012882"], ["83901.5", "12.582856"], ["83889.9", "0"], ["83889.8", "0"]], "a": [["83965.7", "0.070302"], ["83976.2", "0.203559"], ["83986", "0.537968"], ["83986.4", "0.090432"], ["83988", "0.51955"], ["83990.7", "0.003576"], ["83996.9", "0"], ["83999", "0.001333"], ["84032.5", "0"], ["84032.6", "0"]], "u": 26721, "seq": 67550553865}, "cts": 1742556581711, "record_time": 1742556581.768443, "EXCHANGE": "BYBIT"}
{"topic": "orderbook.200.BTCUSDT", "ts": 1742556581920, "type": "delta", "data": {"s": "BTCUSDT", "b": [["83965.5", "0.457652"], ["83960.3", "0.000153"], ["83949.5", "0.061348"], ["83941.8", "0.118804"], ["83937.1", "0"], ["83936.8", "0.293905"], ["83890", "0"]], "a": [["83965.6", "0.317517"], ["83965.7", "0"], ["83970.1", "0.080385"], ["83974.8", "0.023831"], ["83983.7", "0.310407"], ["83986.4", "0.001333"], ["83987.9", "0.231421"], ["84000.4", "0"], ["84000.5", "0"], ["84000.6", "0.012743"], ["84000.7", "0.036562"], ["84001.1", "0"], ["84001.2", "0"], ["84001.3", "0.04"], ["84001.4", "0.04"], ["84032.5", "0.001466"]], "u": 26722, "seq": 67550553944}, "cts": 1742556581917, "record_time": 1742556581.948051, "EXCHANGE": "BYBIT"}
{"topic": "orderbook.200.BTCUSDT", "ts": 1742556582119, "type": "delta", "data": {"s": "BTCUSDT", "b": [["83965.4", "0.02433"], ["83960.3", "0"], ["83946.2", "0.007143"], ["83890", "0.0002"]], "a": [["83965.6", "0.315731"], ["84000.6", "0"], ["84000.8", "0.012743"], ["84001.3", "0"], ["84001.5", "0.04"]], "u": 26723, "seq": 67550554034}, "cts": 1742556582116, "record_time": 1742556582.136869, "EXCHANGE": "BYBIT"}
{"topic": "orderbook.200.BTCUSDT", "ts": 1742556582320, "type": "delta", "data": {"s": "BTCUSDT", "b": [["83965.5", "0.286652"]], "a": [["83965.6", "0.486731"]], "u": 26724, "seq": 67550554062}, "cts": 1742556582280, "record_time": 1742556582.337773, "EXCHANGE": "BYBIT"}
{"topic": "orderbook.200.BTCUSDT", "ts": 1742556582519, "type": "delta", "data": {"s": "BTCUSDT", "b": [["83965.4", "0.001333"], ["83957.5", "0.000153"], ["83920.2", "0.135593"], ["83917.4", "0"], ["83890", "0"]], "a": [["83965.6", "0.488517"]], "u": 26725, "seq": 67550554132}, "cts": 1742556582516, "record_time": 1742556582.667683, "EXCHANGE": "BYBIT"}
{"topic": "orderbook.200.BTCUSDT", "ts": 1742556582720, "type": "delta", "data": {"s": "BTCUSDT", "b": [["83965.5", "0.178387"], ["83965.3", "0"], ["83964.4", "0.071493"], ["83962.1", "0"], ["83960.2", "0"], ["83959.2", "0.027081"], ["83957.8", "0.047911"], ["83955.2", "0.0715"], ["83941.8", "0"], ["83939", "0"], ["83931.8", "0.001333"], ["83925.2", "0"], ["83925.1", "0"], ["83924.9", "0.012882"], ["83924.8", "0.012882"], ["83901.5", "0"], ["83896", "0.235392"], ["83895.9", "12.584332"], ["83895.1", "0"], ["83890", "0.0002"], ["83889.9", "0.011992"], ["83889.8", "0.001333"]], "a": [["83965.6", "0.486374"], ["83965.7", "0.076552"], ["83968.4", "0.089099"], ["83969.5", "0.023833"], ["83974.8", "0"], ["83974.9", "0.089099"], ["83986.5", "0.089099"], ["84000.7", "0.023819"], ["84000.8", "0"], ["84000.9", "0.013"], ["84001", "0.012743"], ["84001.4", "0"], ["84001.5", "0"], ["84001.6", "0.063819"], ["84001.7", "0.04"], ["84014.6", "0.001786"], ["84031", "0"], ["84031.1", "0"], ["84031.8", "0"], ["84032.2", "0"], ["84032.5", "0"]], "u": 26726, "seq": 67550554238}, "cts": 1742556582702, "record_time": 1742556582.809841, "EXCHANGE": "BYBIT"}
{"topic": "orderbook.200.BTCUSDT", "ts": 1742556582919, "type": "delta", "data": {"s": "BTCUSDT", "b": [["83965.5", "0.007148"], ["83964.4", "0"], ["83959.2", "0.001779"], ["83958.2", "0"], ["83957.8", "0.000516"], ["83957.5", "0"], ["83957.1", "0.057954"], ["83957", "0.073036"], ["83955.2", "0"], ["83953.3", "0.040153"], ["83953", "0.071502"], ["83941.7", "0"], ["83936.2", "0.178645"], ["83932.7", "0"], ["83928.6", "0.648463"], ["83921.2", "0.067233"], ["83920.2", "0.135607"], ["83915", "0.001333"], ["83895.9", "0"], ["83893.1", "12.584332"], ["83889.5", "0.003181"], ["83889.4", "0.001466"], ["83889", "0.100315"]], "a": [["83965.6", "0.657374"], ["83969.7", "0"], ["83971.5", "0.04794"], ["83973", "0.071485"], ["83987.8", "0.119799"], ["83990.5", "0.004629"], ["84003.5", "0"]], "u": 26727, "seq": 67550554339}, "cts": 1742556582881, "record_time": 1742556582.98722, "EXCHANGE": "BYBIT"}
{"topic": "orderbook.200.BTCUSDT", "ts": 1742556583119, "type": "delta", "data": {"s": "BTCUSDT", "b": [["83965.5", "0"], ["83965.4", "0"], ["83965", "0"], ["83960.5", "0"], ["83959.1", "0"], ["83958.2", "0.000768"], ["83957.1", "0"], ["83957", "0.001537"], ["83955.1", "0.037815"], ["83955", "0.124585"], ["83954.9", "0"], ["83954.8", "0.01"], ["83953.8", "0.163619"], ["83953", "0.083418"], ["83952.8", "0.001333"], ["83945.9", "0.000623"], ["83945.3", "0.089439"], ["83936.2", "0"], ["83934.1", "0"], ["83926.3", "0.180116"], ["83924.9", "0"], ["83924.8", "0"], ["83924.6", "0.012882"], ["83924.5", "0.012881"], ["83920.2", "0"], ["83917.9", "0"], ["83917.4", "0.135607"], ["83888.8", "0.000445"], ["83888.7", "0.003614"], ["83888.6", "0.000516"], ["83888.3", "0.004037"], ["83887.9", "0.04"], ["83887.8", "0.05"], ["83887.3", "0.027526"]], "a": [["83963.3", "0.707743"], ["83963.4", "0.106918"], ["83965.1", "0.001786"], ["83965.4", "0.166461"], ["83965.5", "0.216042"], ["83965.6", "0.180868"], ["83965.7", "0"], ["83965.8", "0.035729"], ["83968.3", "0.083934"], ["83968.6", "0.071489"], ["83969.2", "0.00329"], ["83969.6", "0.001333"], ["83970.6", "0"], ["83971.5", "0.027689"], ["83972", "0"], ["83973", "0"], ["83973.8", "0.005166"], ["83973.9", "0.01"], ["83974", "0"], ["83976.2", "0.178622"], ["83978.4", "0.048"], ["83983", "0.02009"], ["83985.5", "0.0006"], ["83990.7", "0"], ["84002.1", "0.063449"], ["84003.1", "0"], ["84004.9", "0.030042"], ["84005.2", "1.428081"], ["84007.5", "0.128051"], ["84014.2", "0.171"], ["84020.1", "2.25664"], ["84027.9", "0"], ["84028", "0"], ["84028.4", "0"], ["84028.5", "0"], ["84028.6", "0"], ["84029.1", "0"], ["84030.6", "0"], ["84030.9", "0"]], "u": 26728, "seq": 67550554762}, "cts": 1742556583117, "record_time": 1742556583.161875, "EXCHANGE": "BYBIT"}
{"topic": "orderbook.200.BTCUSDT", "ts": 1742556583319, "type": "delta", "data": {"s": "BTCUSDT", "b": [["83963.2", "0"], ["83963.1", "0.071494"], ["83962.6", "0.000272"], ["83958.2", "0"], ["83958.1", "0.000768"], ["83954.8", "0"], ["83954.7", "0.01"], ["83945.8", "0.005978"], ["83932.5", "0.118146"], ["83924.6", "0.012881"], ["83921.2", "0"], ["83917.9", "0.125055"], ["83895.9", "12.584332"], ["83893.1", "0"], ["83887.8", "0"], ["83887.3", "0"]], "a": [["83963.2", "0.631947"], ["83963.3", "0.311718"], ["83963.4", "0"], ["83965.1", "0"], ["83965.4", "0"], ["83965.5", "0.045042"], ["83965.6", "0.172875"], ["83965.8", "0"], ["83967.9", "0.001466"], ["83968.2", "0.0017"], ["83968.3", "0.082234"], ["83975", "0.0481"], ["83976.6", "0.04"], ["83980.1", "0.048"], ["83980.8", "0"], ["83981.6", "0.048"], ["83981.8", "0.055242"], ["83982.7", "0"], ["83986", "0.489968"], ["83988", "0.520777"], ["83997.3", "0.04"], ["83997.4", "0.04"], ["84000.2", "0.093558"], ["84001.6", "0.023819"], ["84001.7", "0"], ["84005.1", "1.428081"], ["84005.2", "0"], ["84027.8", "0"]], "u": 26729, "seq": 67550554899}, "cts": 1742556583304, "record_time": 1742556583.337539, "EXCHANGE": "BYBIT"}
{"topic": "orderbook.200.BTCUSDT", "ts": 1742556583520, "type": "delta", "data": {"s": "BTCUSDT", "b": [["83956.1", "0"], ["83955.2", "0.0063"], ["83953", "0.071502"], ["83927.4", "0.059399"], ["83926.5", "0.0016"], ["83924.6", "0"], ["83924.5", "0"], ["83924.3", "0.012881"], ["83924.2", "0.012881"], ["83887.9", "0"]], "a": [["83963.2", "0.651912"], ["83965.5", "0.030042"], ["83965.6", "0.175075"], ["83967.6", "0.003"], ["83976.7", "0.048"], ["83979.3", "0"], ["83981", "0"], ["83984.4", "0"], ["83986.1", "0"], ["83987.3", "0.001043"], ["83988", "0.51955"], ["83997.3", "0"], ["83997.4", "0"], ["83998", "0.099535"], ["83998.1", "0.04"], ["84000.3", "2.286682"], ["84020.1", "0"], ["84027.8", "0.059399"], ["84027.9", "0.001466"], ["84028", "0.00325"]], "u": 26730, "seq": 67550554954}, "cts": 1742556583499, "record_time": 1742556583.669495, "EXCHANGE": "BYBIT"}
{"topic": "orderbook.200.BTCUSDT", "ts": 1742556583719, "type": "delta", "data": {"s": "BTCUSDT", "b": [["83963.1", "0.083575"], ["83952.8", "0.001423"], ["83949.5", "0.090425"], ["83947.7", "0.10904"], ["83937.2", "0.182013"], ["83930.2", "0.285239"], ["83888.7", "0"], ["83888.6", "0"], ["83888.3", "0"]], "a": [["83963.2", "0.338608"], ["83963.3", "0.140718"], ["83971.5", "0.060308"], ["83972.2", "0.12027"], ["83974.9", "0.129099"], ["83979.1", "0"], ["83982.7", "0.185023"], ["83987.3", "0"], ["83989.7", "0.281123"], ["84000.2", "0.738445"], ["84028", "0"]], "u": 26731, "seq": 67550554979}, "cts": 1742556583702, "record_time": 1742556583.819956, "EXCHANGE": "BYBIT"}
{"topic": "orderbook.200.BTCUSDT", "ts": 1742556583920, "type": "delta", "data": {"s": "BTCUSDT", "b": [["83963.1", "0.354575"], ["83953.3", "0.04"], ["83949.5", "0.061348"], ["83947.7", "0"], ["83939", "0.000118"], ["83937.2", "0"], ["83932.8", "0.287085"], ["83930.2", "0"], ["83924.3", "0"], ["83924.2", "0"], ["83924.1", "0.013333"], ["83924", "0.012882"], ["83888.7", "0.003614"], ["83888.6", "0.000516"], ["83888.3", "0.004037"]], "a": [["83963.2", "0.32164"], ["83963.3", "0.078849"], ["83965.5", "0"], ["83968.3", "0.055982"], ["83968.4", "0"], ["83971.5", "0.027689"], ["83971.6", "0.081487"], ["83972.2", "0"], ["83973.9", "0"], ["83974.9", "0.04"], ["83975.6", "0.234658"], ["83982.7", "0"], ["83987.8", "0.000995"], ["83989.7", "0"], ["83997.7", "0.013"], ["83997.8", "0.012743"], ["83998", "0.059535"], ["83998.1", "0"], ["83998.4", "0.04"], ["83998.5", "0.04"], ["84000.9", "0"], ["84001", "0"], ["84028", "0.00325"], ["84028.4", "0.001333"], ["84028.5", "0.0012"], ["84028.6", "0.0006"], ["84029.1", "0.000333"]], "u": 26732, "seq": 67550555075}, "cts": 1742556583906, "record_time": 1742556583.996302, "EXCHANGE": "BYBIT"}
{"topic": "orderbook.200.BTCUSDT", "ts": 1742556584119, "type": "delta", "data": {"s": "BTCUSDT", "b": [["83955.9", "0.000153"], ["83936.2", "0.17865"], ["83932.9", "0.118804"], ["83932.8", "0"], ["83895.9", "12.591061"], ["83888.6", "0"], ["83888.3", "0"]], "a": [["83963.2", "0.380558"], ["83963.3", "0.073487"], ["83965.5", "0.052523"], ["83968.3", "0.095429"], ["83969.5", "0"], ["83970.4", "0.17865"], ["83971.5", "0.077822"], ["83974.6", "0.17874"], ["83987.8", "0.119799"], ["83990.2", "0.004893"], ["84029.1", "0"]], "u": 26733, "seq": 67550555108}, "cts": 1742556584107, "record_time": 1742556584.143823, "EXCHANGE": "BYBIT"}
{"topic": "orderbook.200.BTCUSDT", "ts": 1742556584320, "type": "delta", "data": {"s": "BTCUSDT", "b": [["83963.1", "0.282547"], ["83962", "0.071495"], ["83925", "0.013"], ["83924.9", "0.012881"], ["83924.1", "0.000333"], ["83924", "0"], ["83888.8", "0"], ["83888.7", "0"]], "a": [["83963.2", "0.359499"], ["83982.6", "0.003576"], ["83990.2", "0.003757"], ["83996.8", "0.084438"], ["83996.9", "0.012743"], ["83997.5", "0.04"], ["83997.6", "0.04"], ["83997.7", "0"], ["83997.8", "0"], ["83998.4", "0"], ["83998.5", "0"]], "u": 26734, "seq": 67550555153}, "cts": 1742556584303, "record_time": 1742556584.33725, "EXCHANGE": "BYBIT"}
{"topic": "orderbook.200.BTCUSDT", "ts": 1742556584520, "type": "delta", "data": {"s": "BTCUSDT", "b": [["83962.6", "0"], ["83925", "0"], ["83924.8", "0.012881"], ["83888.8", "0.000445"]], "a": [["83963.2", "0.373719"], ["83996.8", "0.071438"], ["83996.9", "0"], ["83997.1", "0.189954"], ["83997.2", "0.012743"], ["83997.5", "0"], ["83997.6", "0"], ["83997.8", "0.04"], ["83997.9", "0.04"]], "u": 26735, "seq": 67550555167}, "cts": 1742556584508, "record_time": 1742556584.581948, "EXCHANGE": "BYBIT"}
{"topic": "orderbook.200.BTCUSDT", "ts": 1742556584720, "type": "delta", "data": {"s": "BTCUSDT", "b": [["83963.1", "0.282997"], ["83915", "0.002579"], ["83898.7", "12.591061"], ["83895.9", "0"]], "a": [], "u": 26736, "seq": 67550555176}, "cts": 1742556584643, "record_time": 1742556584.739057, "EXCHANGE": "BYBIT"}
{"topic": "orderbook.200.BTCUSDT", "ts": 1742556584920, "type": "delta", "data": {"s": "BTCUSDT", "b": [["83963", "0.071494"], ["83962", "0"], ["83929", "0"], ["83898.7", "12.603019"], ["83895.5", "0"], ["83888.7", "0.003614"], ["83888.6", "0.000516"]], "a": [["83982.6", "0"], ["84005.9", "0.005953"], ["84029.1", "0.000333"]], "u": 26737, "seq": 67550555200}, "cts": 1742556584904, "record_time": 1742556585.023419, "EXCHANGE": "BYBIT"}
{"topic": "orderbook.200.BTCUSDT", "ts": 1742556585120, "type": "delta", "data": {"s": "BTCUSDT", "b": [["83963.1", "0.283597"], ["83930.2", "0.167765"], ["83925", "0.013"], ["83924.8", "0"], ["83888.6", "0"]], "a": [["83963.2", "0.379719"], ["83980.1", "0.051575"], ["83997.1", "0.189697"], ["83997.7", "0.04"], ["83997.9", "0"]], "u": 26738, "seq": 67550555218}, "cts": 1742556585106, "record_time": 1742556585.138977, "EXCHANGE": "BYBIT"}
{"topic": "orderbook.200.BTCUSDT", "ts": 1742556585320, "type": "delta", "data": {"s": "BTCUSDT", "b": [["83963.1", "0.2716"], ["83925", "0"], ["83924.8", "0.012881"], ["83898.7", "0"], ["83895.9", "12.603019"]], "a": [["83987.5", "0.001088"], ["83997.7", "0"], ["83997.9", "0.04"], ["84029.1", "0"]], "u": 26739, "seq": 67550555240}, "cts": 1742556585300, "record_time": 1742556585.339792, "EXCHANGE": "BYBIT"}
{"topic": "orderbook.200.BTCUSDT", "ts": 1742556585519, "type": "delta", "data": {"s": "BTCUSDT", "b": [], "a": [["83965.5", "0.060692"], ["83967.6", "0"], ["83987.5", "0"], ["84029.1", "0.000333"], ["84030.6", "0.118804"]], "u": 26740, "seq": 67550555254}, "cts": 1742556585512, "record_time": 1742556585.646598, "EXCHANGE": "BYBIT"}
{"topic": "orderbook.200.BTCUSDT", "ts": 1742556585720, "type": "delta", "data": {"s": "BTCUSDT", "b": [["83963.1", "0.282932"], ["83898.7", "12.603019"], ["83895.9", "0"]], "a": [], "u": 26741, "seq": 67550555270}, "cts": 1742556585711, "record_time": 1742556585.827051, "EXCHANGE": "BYBIT"}
{"topic": "orderbook.200.BTCUSDT", "ts": 1742556585920, "type": "delta", "data": {"s": "BTCUSDT", "b": [["83924.9", "0"], ["83924.7", "0.012881"]], "a": [["83980.1", "0.048"]], "u": 26742, "seq": 67550555292}, "cts": 1742556585908, "record_time": 1742556586.003568, "EXCHANGE": "BYBIT"}
{"topic": "orderbook.200.BTCUSDT", "ts": 1742556586119, "type": "delta", "data": {"s": "BTCUSDT", "b": [["83955.9", "0"], ["83928.6", "0.734143"], ["83888.6", "0.000516"]], "a": [["83984", "0.003575"], ["84030.6", "0"]], "u": 26743, "seq": 67550555301}, "cts": 1742556586062, "record_time": 1742556586.177265, "EXCHANGE": "BYBIT"}
{"topic": "orderbook.200.BTCUSDT", "ts": 1742556586319, "type": "delta", "data": {"s": "BTCUSDT", "b": [["83957.9", "0.000153"], ["83888.6", "0"]], "a": [], "u": 26744, "seq": 67550555311}, "cts": 1742556586301, "record_time": 1742556586.352988, "EXCHANGE": "BYBIT"}
{"topic": "orderbook.200.BTCUSDT", "ts": 1742556586520, "type": "delta", "data": {"s": "BTCUSDT", "b": [["83924.9", "0.013"], ["83924.7", "0"]], "a": [["83996.9", "0.013"], ["83997", "0.012743"], ["83997.1", "0.176954"], ["83997.2", "0"], ["83997.6", "0.04"], ["83997.7", "0.04"], ["83997.8", "0"], ["83997.9", "0"], ["84029.1", "0"]], "u": 26745, "seq": 67550555319}, "cts": 1742556586507, "record_time": 1742556586.537944, "EXCHANGE": "BYBIT"}
{"topic": "orderbook.200.BTCUSDT", "ts": 1742556586919, "type": "delta", "data": {"s": "BTCUSDT", "b": [["83939.2", "0.035737"], ["83930.1", "0.000516"], ["83888.7", "0"]], "a": [["83979.6", "0.035738"], ["83990.1", "0"]], "u": 26746, "seq": 67550555330}, "cts": 1742556586917, "record_time": 1742556587.064089, "EXCHANGE": "BYBIT"}
{"topic": "orderbook.200.BTCUSDT", "ts": 1742556587120, "type": "delta", "data": {"s": "BTCUSDT", "b": [["83925.1", "0.013"], ["83925", "0.012881"], ["83924.9", "0"], ["83924.8", "0"]], "a": [["83996.7", "0.013"], ["83996.8", "0.084181"], ["83996.9", "0"], ["83997", "0"], ["83997.4", "0.04"], ["83997.5", "0.04"], ["83997.6", "0"], ["83997.7", "0"], ["84029.1", "0.000333"]], "u": 26747, "seq": 67550555340}, "cts": 1742556587103, "record_time": 1742556587.240602, "EXCHANGE": "BYBIT"}
{"topic": "orderbook.200.BTCUSDT", "ts": 1742556587320, "type": "delta", "data": {"s": "BTCUSDT", "b": [["83923", "0.041695"], ["83888.8", "0"]], "a": [], "u": 26748, "seq": 67550555346}, "cts": 1742556587311, "record_time": 1742556587.338253, "EXCHANGE": "BYBIT"}
{"topic": "orderbook.200.BTCUSDT", "ts": 1742556587519, "type": "delta", "data": {"s": "BTCUSDT", "b": [["83925.1", "0"], ["83924.9", "0.012881"]], "a": [["83996.7", "0"], ["83996.9", "0.012743"], ["83997.4", "0"], ["83997.6", "0.04"]], "u": 26749, "seq": 67550555353}, "cts": 1742556587484, "record_time": 1742556587.538011, "EXCHANGE": "BYBIT"}
{"topic": "orderbook.200.BTCUSDT", "ts": 1742556587720, "type": "delta", "data": {"s": "BTCUSDT", "b": [], "a": [["83965.6", "0.174"], ["83984", "0"], ["84005.1", "0"], ["84030.6", "0.118804"], ["84030.9", "0.089099"]], "u": 26750, "seq": 67550555365}, "cts": 1742556587712, "record_time": 1742556587.739565, "EXCHANGE": "BYBIT"}
{"topic": "orderbook.200.BTCUSDT", "ts": 1742556587919, "type": "delta", "data": {"s": "BTCUSDT", "b": [], "a": [["83986.6", "0.003575"], ["84004.5", "0.304208"], ["84030.9", "0"]], "u": 26751, "seq": 67550555375}, "cts": 1742556587904, "record_time": 1742556587.939833, "EXCHANGE": "BYBIT"}
{"topic": "orderbook.200.BTCUSDT", "ts": 1742556588120, "type": "delta", "data": {"s": "BTCUSDT", "b": [["83957.9", "0"], ["83939.3", "0.012647"], ["83925", "0"], ["83924.8", "0.012881"]], "a": [["83963.2", "0.376194"], ["83996.8", "0.071438"], ["83996.9", "0"], ["83997", "0.013"], ["83997.1", "0.189697"], ["83997.5", "0"], ["83997.6", "0"], ["83997.7", "0.04"], ["83997.8", "0.04"]], "u": 26752, "seq": 67550555398}, "cts": 1742556588077, "record_time": 1742556588.141454, "EXCHANGE": "BYBIT"}
{"topic": "orderbook.200.BTCUSDT", "ts": 1742556588320, "type": "delta", "data": {"s": "BTCUSDT", "b": [["83924.9", "0"], ["83924.7", "0.012881"], ["83898.7", "0"], ["83896", "0"], ["83895.9", "12.638834"], ["83895.1", "0.235392"]], "a": [["83997", "0"], ["83997.1", "0.176954"], ["83997.3", "0.012743"], ["83997.4", "0.012743"], ["83997.7", "0"], ["83997.8", "0"], ["83998", "0.099535"], ["83998.1", "0.04"]], "u": 26753, "seq": 67550555413}, "cts": 1742556588316, "record_time": 1742556588.338572, "EXCHANGE": "BYBIT"}
{"topic": "orderbook.200.BTCUSDT", "ts": 1742556588520, "type": "delta", "data": {"s": "BTCUSDT", "b": [["83925", "0.013"], ["83924.9", "0.012881"], ["83924.8", "0"], ["83924.7", "0"]], "a": [["83997", "0.013"], ["83997.1", "0.189697"], ["83997.3", "0"], ["83997.4", "0"], ["83997.7", "0.04"], ["83997.8", "0.04"], ["83998", "0.059535"], ["83998.1", "0"]], "u": 26754, "seq": 67550555431}, "cts": 1742556588453, "record_time": 1742556588.539168, "EXCHANGE": "BYBIT"}
{"topic": "orderbook.200.BTCUSDT", "ts": 1742556588720, "type": "delta", "data": {"s": "BTCUSDT", "b": [["83956.5", "0.000153"], ["83925", "0"], ["83924.8", "0.012881"], ["83889", "0"]], "a": [["83997", "0.012743"], ["83997.6", "0.04"], ["83997.8", "0"]], "u": 26755, "seq": 67550555437}, "cts": 1742556588644, "record_time": 1742556588.739459, "EXCHANGE": "BYBIT"}
{"topic": "orderbook.200.BTCUSDT", "ts": 1742556588919, "type": "delta", "data": {"s": "BTCUSDT", "b": [["83955.1", "0.02489"], ["83955", "0.071501"]], "a": [["83963.2", "0.368298"], ["83977.9", "0.062974"], ["83986.6", "0"], ["83997", "0"], ["83997.1", "0.176954"], ["83997.2", "0.012743"], ["83997.3", "0.012743"], ["83997.6", "0"], ["83997.7", "0"], ["83997.9", "0.04"], ["83998", "0.099535"], ["84030.9", "0.089099"]], "u": 26756, "seq": 67550555479}, "cts": 1742556588902, "record_time": 1742556588.937383, "EXCHANGE": "BYBIT"}
{"topic": "orderbook.200.BTCUSDT", "ts": 1742556589119, "type": "delta", "data": {"s": "BTCUSDT", "b": [["83952.1", "0.05309"], ["83925", "0.013"], ["83924.8", "0"], ["83898.7", "12.657518"], ["83895.9", "0"], ["83889.4", "0"]], "a": [["83997", "0.013"], ["83997.1", "0.189697"], ["83997.2", "0"], ["83997.3", "0"], ["83997.7", "0.04"], ["83997.8", "0.04"], ["83997.9", "0"], ["83998", "0.059535"]], "u": 26757, "seq": 67550555493}, "cts": 1742556589093, "record_time": 1742556589.138977, "EXCHANGE": "BYBIT"}
{"success": true, "ret_msg": "subscribe", "conn_id": "cef7da9d-6f5c-442f-b95b-8b77bc7ba856", "op": "subscribe", "record_time": 1742560334.027259, "EXCHANGE": "BYBIT"}
{"topic": "orderbook.200.BTCUSDT", "ts": 1742560331319, "type": "snapshot", "data": {"s": "BTCUSDT", "b": [["84167.9", "0.734572"], ["84167.8", "0.000333"], ["84167.1", "0.001333"], ["84166.9", "0.0003"], ["84166.8", "0.003268"], ["84166.7", "0.001466"], ["84165.9", "0.000518"], ["84163.8", "0.003936"], ["84163.6", "0.000333"], ["84162.9", "0.001333"], ["84162.6", "0.003268"], ["84162.2", "0.143492"], ["84162.1", "0.171"], ["84162", "0.001466"], ["84161.3", "0.009518"], ["84161.2", "0.011919"], ["84160.6", "0.121257"], ["84160.4", "0.048"], ["84160.3", "0.001773"], ["84160", "0.00006"], ["84159.7", "0.01887"], ["84159.6", "0.145861"], ["84159.5", "0.04701"], ["84159.4", "0.000333"], ["84158.9", "0.064"], ["84158.7", "0.045333"], ["84158.6", "0.000358"], ["84158.4", "0.003268"], ["84157.4", "0.061352"], ["84157", "0.12384"], ["84156.9", "0.0073"], ["84156.6", "0.000518"], ["84156.2", "0.07133"], ["84155.7", "0.019942"], ["84155.4", "0.06"], ["84155.3", "0.048"], ["84155.2", "0.000333"], ["84154.5", "0.001333"], ["84154.4", "0.00009"], ["84154.3", "0.124581"], ["84154.2", "0.003259"], ["84153.9", "0.052"], ["84153.6", "0.056"], ["84153.1", "0.000297"], ["84152.9", "0.059399"], ["84152.8", "0.172466"], ["84152", "0.000518"], ["84151", "0.000333"], ["84150.4", "0.178252"], ["84150.3", "0.001333"], ["84150.1", "0.777045"], ["84150", "2.379967"], ["84149.8", "0.005942"], ["84148.8", "0.002442"], ["84148.2", "0.001466"], ["84148.1", "0.0002"], ["84147.4", "0.000518"], ["84147", "0.020211"], ["84146.9", "0.0002"], ["84146.8", "0.000333"], ["84146.5", "0.0045"], ["84146.1", "0.001333"], ["84146", "0.00018"], ["84145.7", "0.003259"], ["84145.2", "0.089099"], ["84143.5", "0.001566"], ["84142.7", "0.000518"], ["84142.6", "0.000333"], ["84142.5", "0.004583"], ["84142", "0.404068"], ["84141.9", "0.001333"], ["84141.8", "0.171"], ["84141.5", "0.003259"], ["84140.6", "0.118793"], ["84140.5", "0.4"], ["84140", "0.00006"], ["84139.3", "0.178215"], ["84139", "0.000332"], ["84138.9", "0.001466"], ["84138.6", "0.557231"], ["84138.5", "0.029037"], ["84138.4", "0.000333"], ["84138.1", "0.000518"], ["84137.7", "0.001333"], ["84137.6", "0.00009"], ["84137.3", "0.003259"], ["84136.9", "0.024035"], ["84136.5", "0.000358"], ["84136", "0.000083"], ["84135.3", "0.035651"], ["84134.3", "0.001466"], ["84134.2", "0.000333"], ["84134", "0.011887"], ["84133.6", "0.205266"], ["84133.5", "0.001851"], ["84133.3", "0.171"], ["84133.1", "0.003259"], ["84132.9", "0.059399"], ["84132.3", "0.0001"], ["84132.2", "0.118793"], ["84131.3", "0.009"], ["84130.8", "0.499416"], ["84130.7", "0.024825"], ["84130.3", "0.039635"], ["84130.2", "0.039635"], ["84130", "0.000333"], ["84129.7", "0.001466"], ["84129.6", "0.115744"], ["84129.3", "0.014214"], ["84129.2", "0.012971"], ["84128.9", "0.003777"], ["84128.2", "0.005164"], ["84127.2", "0.128378"], ["84127.1", "0.118793"], ["84125.8", "0.000333"], ["84125.5", "0.05"], ["84125.4", "0.04955"], ["84125.1", "0.001333"], ["84125", "0.001584"], ["84124.9", "0.109391"], ["84124.8", "0.171"], ["84124.7", "0.003259"], ["84124.6", "0.02112"], ["84124.4", "0.059399"], ["84124.2", "0.000518"], ["84124.1", "0.00594"], ["84124", "0.001782"], ["84123.9", "0.089099"], ["84122.5", "0.00002"], ["84121.8", "0.00477"], ["84121.6", "0.000333"], ["84121.2", "0.023762"], ["84120.8", "0.001423"], ["84120.5", "0.003259"], ["84120.4", "0.001466"], ["84120.3", "0.023762"], ["84120.1", "0.850819"], ["84120", "2.377615"], ["84119.6", "0.000518"], ["84118.8", "0.023762"], ["84118.7", "0.013719"], ["84118", "0.023761"], ["84117.4", "0.000333"], ["84116.9", "0.023757"], ["84116.6", "0.001333"], ["84116.5", "0.0045"], ["84116.3", "0.174259"], ["84115.8", "0.001466"], ["84115.6", "3.657776"], ["84115.4", "0.023762"], ["84115.3", "0.124751"], ["84115", "0.000518"], ["84114.4", "0.000358"], ["84113.2", "0.000333"], ["84113", "0.118793"], ["84112.4", "0.001423"], ["84112.1", "0.018259"], ["84111.1", "0.001466"], ["84110.9", "0.003614"], ["84110.4", "0.000518"], ["84109.6", "0.044"], ["84109.4", "0.001367"], ["84108.9", "0.000333"], ["84108.2", "0.001333"], ["84107.9", "0.122052"], ["84107.8", "0.171"], ["84107.1", "0.059399"], ["84106.9", "0.048"], ["84106.5", "0.001466"], ["84105.7", "0.000518"], ["84104.7", "0.000333"], ["84104.6", "0.048"], ["84104", "0.001423"], ["84103.9", "0.00009"], ["84103.7", "0.003259"], ["84102.6", "0.005871"], ["84102.5", "0.118793"], ["84102.4", "3.256341"], ["84102.3", "19.531634"], ["84101.9", "0.001466"], ["84101.3", "0.009"], ["84101.1", "0.000518"], ["84101", "0.003509"], ["84100.5", "0.000333"], ["84100.4", "0.052"], ["84100", "0.010271"], ["84099.8", "0.001333"], ["84099.5", "0.003259"], ["84099.3", "0.171"], ["84099.1", "0.01183"], ["84098.1", "0.165081"], ["84097.8", "0.027758"], ["84097.3", "0.001466"], ["84097.1", "0.237567"], ["84096.6", "0.235392"], ["84096.5", "0.000518"], ["84096.4", "0.0001"], ["84096.3", "0.000333"], ["84095.9", "0.06"], ["84095.7", "0.01183"]], "a": [["84168", "0.375133"], ["84168.9", "0.071319"], ["84173", "0.0002"], ["84174", "0.071315"], ["84174.7", "0.011842"], ["84175.1", "0.000518"], ["84175.2", "0.003268"], ["84175.5", "0.001333"], ["84175.9", "0.024301"], ["84176.3", "0.000333"], ["84176.4", "0.198714"], ["84176.5", "0.171"], ["84176.9", "0.011879"], ["84178.1", "0.071311"], ["84178.9", "0.023683"], ["84179.4", "0.003268"], ["84179.8", "0.001851"], ["84180", "0.00024"], ["84180.5", "0.000333"], ["84180.6", "0.001466"], ["84183.4", "0.04334"], ["84183.5", "0.058923"], ["84183.6", "0.003269"], ["84184", "0.001333"], ["84184.2", "0.04"], ["84184.4", "0.000518"], ["84184.5", "0.04"], ["84184.6", "0.00009"], ["84184.7", "0.000333"], ["84185.2", "0.001466"], ["84185.5", "0.035651"], ["84185.9", "0.04"], ["84186", "0.099106"], ["84186.1", "0.08"], ["84187.5", "0.04"], ["84187.8", "0.003269"], ["84188.1", "0.030066"], ["84188.2", "0.001333"], ["84188.3", "0.171"], ["84188.9", "0.004166"], ["84189", "0.119311"], ["84189.1", "0.161816"], ["84189.2", "0.04"], ["84189.3", "0.04"], ["84189.4", "0.005942"], ["84189.5", "0.04"], ["84189.6", "0.178106"], ["84189.8", "0.001466"], ["84190.9", "0.0006"], ["84191.2", "0.04"], ["84191.8", "0.01933"], ["84192", "0.003269"], ["84192.4", "0.001333"], ["84192.5", "0.050124"], ["84193", "0.00009"], ["84193.1", "0.000333"], ["84193.7", "0.002585"], ["84194.1", "0.009187"], ["84194.4", "0.04453"], ["84194.5", "0.001466"], ["84195.1", "0.27292"], ["84195.5", "0.050124"], ["84196.3", "0.003269"], ["84196.6", "0.001333"], ["84196.7", "0.118793"], ["84196.8", "0.478027"], ["84197.1", "0.005939"], ["84197.3", "0.000333"], ["84197.4", "0.201066"], ["84197.9", "0.059399"], ["84198.1", "0.05939"], ["84198.3", "0.000518"], ["84199.1", "0.001466"], ["84199.2", "0.00099"], ["84199.9", "0.0018"], ["84200", "0.00024"], ["84200.5", "0.003293"], ["84200.8", "0.001333"], ["84201.4", "0.011977"], ["84201.5", "0.000333"], ["84201.7", "0.004687"], ["84201.8", "0.099641"], ["84202", "0.005942"], ["84202.3", "0.05939"], ["84202.5", "0.000734"], ["84202.9", "0.000518"], ["84203.7", "0.001466"], ["84204.1", "0.118793"], ["84204.4", "0.05939"], ["84204.7", "0.003293"], ["84205", "0.001333"], ["84205.7", "0.000333"], ["84205.8", "0.003564"], ["84206.5", "0.0045"], ["84206.7", "0.013"], ["84206.8", "0.012973"], ["84207.4", "0.000296"], ["84207.6", "0.000518"], ["84207.7", "0.171"], ["84207.8", "0.04"], ["84207.9", "0.04"], ["84208.4", "0.001466"], ["84208.7", "0.063463"], ["84208.9", "0.003293"], ["84209.2", "0.001333"], ["84209.8", "0.434239"], ["84209.9", "0.119126"], ["84210", "2.444781"], ["84211", "0.000118"], ["84211.9", "0.04428"], ["84212", "0.115828"], ["84212.2", "0.000518"], ["84212.3", "0.013716"], ["84212.4", "2.585653"], ["84212.5", "0.029692"], ["84212.6", "0.05939"], ["84213", "0.001466"], ["84213.1", "0.122084"], ["84213.4", "0.001333"], ["84213.6", "0.0006"], ["84213.7", "0.549999"], ["84214.2", "0.000333"], ["84214.5", "0.000358"], ["84214.6", "0.005942"], ["84215.5", "0.023757"], ["84216.1", "0.130344"], ["84216.6", "0.118793"], ["84216.8", "0.000518"], ["84216.9", "0.179186"], ["84217.3", "0.003294"], ["84217.6", "0.002799"], ["84217.7", "0.023759"], ["84217.8", "0.005938"], ["84217.9", "0.029695"], ["84218.2", "0.00009"], ["84218.4", "0.000333"], ["84218.7", "0.051005"], ["84219", "0.023757"], ["84220", "0.00024"], ["84220.4", "0.023757"], ["84220.5", "0.124712"], ["84220.8", "0.005939"], ["84221.3", "0.009"], ["84221.5", "0.063196"], ["84221.9", "0.016323"], ["84222.2", "0.001466"], ["84222.3", "0.059399"], ["84222.6", "0.056374"], ["84222.8", "0.003564"], ["84223.4", "0.059393"], ["84223.6", "0.118793"], ["84225.5", "0.089099"], ["84225.7", "0.003293"], ["84226.1", "0.001851"], ["84226.6", "0.00009"], ["84226.8", "0.000333"], ["84226.9", "0.001466"], ["84227.2", "0.005942"], ["84227.3", "0.099271"], ["84227.9", "0.005939"], ["84228.2", "0.001782"], ["84229", "0.143712"], ["84229.1", "0.171"], ["84229.2", "0.04"], ["84229.3", "3.209371"], ["84229.8", "0.096795"], ["84229.9", "0.003293"], ["84230.3", "0.001333"], ["84230.7", "0.000518"], ["84231", "0.000333"], ["84231.4", "0.059399"], ["84231.5", "0.001466"], ["84231.6", "0.059393"], ["84231.8", "0.003564"], ["84232.4", "0.023754"], ["84232.5", "0.059377"], ["84234.2", "0.003293"], ["84234.5", "0.001333"], ["84234.6", "0.023755"], ["84234.7", "0.118793"], ["84235", "0.00009"], ["84235.2", "0.000333"], ["84235.4", "0.000518"], ["84235.8", "0.015"], ["84235.9", "0.023754"], ["84236.1", "0.001466"], ["84236.5", "0.0045"], ["84236.6", "0.000358"], ["84237.3", "0.023754"], ["84237.6", "0.171"], ["84237.7", "0.005938"], ["84237.9", "0.000615"], ["84238.4", "0.003294"], ["84238.7", "0.001333"], ["84239.4", "0.000333"], ["84239.8", "0.124735"], ["84239.9", "0.059399"], ["84240", "0.002077"], ["84240.6", "0.00315"], ["84240.8", "0.001466"]], "u": 45245, "seq": 67552577867}, "cts": 1742560331316, "record_time": 1742560334.030907, "EXCHANGE": "BYBIT"}
{"topic": "orderbook.200.BTCUSDT", "ts": 1742560331520, "type": "delta", "data": {"s": "BTCUSDT", "b": [["84167.9", "0.736354"], ["84130.4", "0.04"], ["84130.2", "0"], ["84129.6", "0"], ["84129.4", "0.013"], ["84129.2", "0.00009"], ["84124", "0"], ["84095.6", "0.001423"]], "a": [["84212.4", "0.023759"], ["84218", "2.561894"], ["84240.8", "0"]], "u": 45246, "seq": 67552577913}, "cts": 1742560331510, "record_time": 1742560334.032235, "EXCHANGE": "BYBIT"}
{"topic": "orderbook.200.BTCUSDT", "ts": 1742560331719, "type": "delta", "data": {"s": "BTCUSDT", "b": [["84140.6", "0"], ["84127.3", "0.074151"], ["84124", "0.135489"], ["84095.6", "0"]], "a": [["84210", "1.724318"], ["84218", "0"], ["84223.7", "2.561894"]], "u": 45247, "seq": 67552577974}, "cts": 1742560331715, "record_time": 1742560334.033322, "EXCHANGE": "BYBIT"}
{"topic": "orderbook.200.BTCUSDT", "ts": 1742560331919, "type": "delta", "data": {"s": "BTCUSDT", "b": [["84130.4", "0"], ["84130.2", "0.039635"], ["84129.4", "0"], ["84129.2", "0.012971"], ["84125.5", "0"], ["84125.3", "0.04955"], ["84124", "0.135493"], ["84095.6", "0.001423"]], "a": [["84206.7", "0.012973"], ["84215.2", "2.561894"], ["84223.7", "0"]], "u": 45248, "seq": 67552578041}, "cts": 1742560331916, "record_time": 1742560334.034303, "EXCHANGE": "BYBIT"}
{"topic": "orderbook.200.BTCUSDT", "ts": 1742560332120, "type": "delta", "data": {"s": "BTCUSDT", "b": [["84130.4", "0.04"], ["84130.2", "0"], ["84125.5", "0.05"], ["84125.3", "0"]], "a": [["84168", "0.375074"], ["84197.8", "0.042222"], ["84240.6", "0"]], "u": 45249, "seq": 67552578067}, "cts": 1742560332117, "record_time": 1742560334.035078, "EXCHANGE": "BYBIT"}
{"topic": "orderbook.200.BTCUSDT", "ts": 1742560332320, "type": "delta", "data": {"s": "BTCUSDT", "b": [["84167.9", "0.492252"], ["84167", "0.024243"], ["84166.9", "0.071621"], ["84155.7", "0.140915"], ["84155.4", "0.182512"], ["84145.6", "0.170615"], ["84145.2", "0.272449"], ["84138.2", "0.289491"], ["84136.5", "0.312032"], ["84130.4", "0"], ["84130.2", "0.039635"], ["84129.4", "0.013"], ["84129.2", "0.00009"], ["84124", "0.135498"], ["84123.9", "0.090881"], ["84096.3", "0"], ["84095.9", "0"], ["84095.7", "0"], ["84095.6", "0"]], "a": [["84168", "0.546115"], ["84176.4", "0.261047"], ["84180.2", "0.124413"], ["84180.6", "0.120459"], ["84190.4", "0.182316"], ["84190.7", "0.166459"], ["84197.7", "0.308627"], ["84199.5", "0.27915"], ["84238.7", "0"], ["84239.4", "0"], ["84239.8", "0"], ["84239.9", "0"], ["84240", "0"]], "u": 45250, "seq": 67552578127}, "cts": 1742560332316, "record_time": 1742560334.03593, "EXCHANGE": "BYBIT"}
{"topic": "orderbook.200.BTCUSDT", "ts": 1742560332520, "type": "delta", "data": {"s": "BTCUSDT", "b": [["84167.9", "0.76996"], ["84167", "0"], ["84166.9", "0.0003"], ["84162.2", "0.182144"], ["84159.6", "0"], ["84159", "0.137172"], ["84155.7", "0.019942"], ["84155.4", "0.06"], ["84145.6", "0"], ["84145.2", "0.089099"], ["84138.7", "0.118793"], ["84138.2", "0"], ["84136.5", "0.000358"], ["84129.4", "0"], ["84129.2", "0.012971"], ["84125.5", "0"], ["84125.3", "0.04955"], ["84096.3", "0.000333"], ["84095.9", "0.06"], ["84095.7", "0.01183"]], "a": [["84168", "0.375115"], ["84176.4", "0.198714"], ["84180.2", "0"], ["84180.6", "0.001466"], ["84190.4", "0"], ["84190.7", "0"], ["84197.7", "0"], ["84199.5", "0"], ["84212.4", "2.585653"], ["84215.2", "0"], ["84221.8", "0.014411"], ["84238.7", "0.001333"], ["84239.4", "0.000333"], ["84239.8", "0.124735"], ["84239.9", "0.059399"], ["84240", "0.002077"]], "u": 45251, "seq": 67552578195}, "cts": 1742560332513, "record_time": 1742560334.036797, "EXCHANGE": "BYBIT"}
{"topic": "orderbook.200.BTCUSDT", "ts": 1742560332719, "type": "delta", "data": {"s": "BTCUSDT", "b": [["84130.4", "0.04"], ["84130.2", "0"], ["84129.4", "0.013"], ["84129.2", "0.00009"], ["84125.5", "0.05"], ["84125.3", "0"], ["84095.7", "0"]], "a": [], "u": 45252, "seq": 67552578245}, "cts": 1742560332716, "record_time": 1742560334.037681, "EXCHANGE": "BYBIT"}
{"topic": "orderbook.200.BTCUSDT", "ts": 1742560332920, "type": "delta", "data": {"s": "BTCUSDT", "b": [["84144.1", "0.003576"], ["84124", "0.135506"], ["84095.9", "0"]], "a": [], "u": 45253, "seq": 67552578305}, "cts": 1742560332916, "record_time": 1742560334.039595, "EXCHANGE": "BYBIT"}
{"topic": "orderbook.200.BTCUSDT", "ts": 1742560333120, "type": "delta", "data": {"s": "BTCUSDT", "b": [["84167.9", "0.803553"], ["84160.1", "0.071326"], ["84156.2", "0"], ["84129.4", "0"], ["84129.2", "0.012971"], ["84123.9", "0.089099"], ["84095.9", "0.06"]], "a": [["84175.9", "0.001466"], ["84176.4", "0.113205"], ["84176.5", "0"], ["84192.5", "0.030066"], ["84212.4", "0.023759"], ["84223.7", "2.561894"]], "u": 45254, "seq": 67552578411}, "cts": 1742560333115, "record_time": 1742560334.040429, "EXCHANGE": "BYBIT"}
{"topic": "orderbook.200.BTCUSDT", "ts": 1742560333320, "type": "delta", "data": {"s": "BTCUSDT", "b": [["84167.9", "0.796941"], ["84130.4", "0"], ["84130.2", "0.039635"], ["84126.9", "0.135493"], ["84125.5", "0.049549"], ["84124", "0"]], "a": [["84168", "0.375074"], ["84174", "0"], ["84176", "0.071313"], ["84176.5", "0.171"], ["84184.8", "0.003431"], ["84189", "0.000518"], ["84189.1", "0.120161"], ["84206.7", "0"], ["84206.8", "0"], ["84207.3", "0.012973"], ["84207.4", "0.013269"], ["84207.8", "0"], ["84207.9", "0"], ["84208.4", "0.041466"], ["84208.5", "0.04"], ["84212.6", "0"], ["84215", "0.024675"], ["84229", "0.118793"]], "u": 45255, "seq": 67552578524}, "cts": 1742560333310, "record_time": 1742560334.04119, "EXCHANGE": "BYBIT"}
{"topic": "orderbook.200.BTCUSDT", "ts": 1742560333520, "type": "delta", "data": {"s": "BTCUSDT", "b": [["84162.5", "0.071324"], ["84160.6", "0.049931"], ["84127.3", "0.10553"], ["84125.6", "0.05"], ["84125.4", "0"], ["84095.9", "0"]], "a": [["84176.5", "0"], ["84185.5", "0"], ["84185.6", "0.035652"], ["84196.9", "0.001173"], ["84220.9", "2.561894"], ["84223.7", "0"]], "u": 45256, "seq": 67552578577}, "cts": 1742560333502, "record_time": 1742560334.04196, "EXCHANGE": "BYBIT"}
{"topic": "orderbook.200.BTCUSDT", "ts": 1742560333720, "type": "delta", "data": {"s": "BTCUSDT", "b": [], "a": [["84176.5", "0.171"], ["84189", "0.119311"], ["84196.9", "0"]], "u": 45257, "seq": 67552578633}, "cts": 1742560333713, "record_time": 1742560334.04266, "EXCHANGE": "BYBIT"}
{"topic": "orderbook.200.BTCUSDT", "ts": 1742560333920, "type": "delta", "data": {"s": "BTCUSDT", "b": [["84167.9", "0.800774"], ["84167.8", "0.071827"], ["84144.1", "0"], ["84129.5", "0.013"], ["84129.4", "0.012881"], ["84129.3", "0.001333"], ["84129.2", "0.00009"], ["84096.3", "0"]], "a": [["84176.5", "0"], ["84207", "0.013"], ["84207.1", "0.012973"], ["84207.3", "0"], ["84207.4", "0.000296"], ["84221.8", "0"], ["84240.6", "0.00315"]], "u": 45258, "seq": 67552578688}, "cts": 1742560333917, "record_time": 1742560334.043384, "EXCHANGE": "BYBIT"}
{"topic": "orderbook.200.BTCUSDT", "ts": 1742560334120, "type": "delta", "data": {"s": "BTCUSDT", "b": [["84130.4", "0.039635"], ["84130.2", "0"], ["84129.5", "0"], ["84129.3", "0.014214"], ["84125.6", "0"], ["84125.4", "0.04955"], ["84096.3", "0.000333"]], "a": [["84173.9", "0.071315"], ["84176", "0"], ["84193.8", "0.001031"], ["84207", "0"], ["84207.2", "0.012973"], ["84208.2", "0.04"], ["84208.3", "0.04"], ["84208.4", "0.001466"], ["84208.5", "0"], ["84218", "2.561894"], ["84220.9", "0"], ["84240", "0"], ["84240.6", "0"]], "u": 45259, "seq": 67552578723}, "cts": 1742560334114, "record_time": 1742560334.17384, "EXCHANGE": "BYBIT"}
{"topic": "orderbook.200.BTCUSDT", "ts": 1742560334320, "type": "delta", "data": {"s": "BTCUSDT", "b": [["84172.9", "0.838716"], ["84168", "0.096991"], ["84167.9", "0.228788"], ["84164.9", "0.071322"], ["84164.5", "0.01"], ["84162.8", "0.00009"], ["84162.3", "0.108005"], ["84162.2", "0.059399"], ["84161.2", "0"], ["84160.3", "0"], ["84160.1", "0"], ["84159.5", "0.005"], ["84159.4", "0.089432"], ["84157", "0.1"], ["84150.3", "0.004909"], ["84125.9", "0.049555"], ["84125.8", "0.049888"], ["84125.5", "0"], ["84125.4", "0"], ["84096.4", "0"], ["84096.3", "0"]], "a": [["84168", "0"], ["84168.9", "0"], ["84173", "0.010024"], ["84173.9", "0"], ["84174.7", "0"], ["84176.4", "0.028515"], ["84178.9", "0"], ["84180.7", "0.071309"], ["84181.4", "0.01"], ["84185.6", "0"], ["84186.1", "0.04"], ["84189", "0.000518"], ["84189.3", "0"], ["84193.7", "0.006278"], ["84193.8", "0"], ["84194.9", "0.001242"], ["84198.1", "0"], ["84207.1", "0"], ["84207.2", "0"], ["84208.2", "0"], ["84208.3", "0.012973"], ["84208.4", "0.014439"], ["84208.7", "0"], ["84209.4", "0.04"], ["84209.5", "0.04"], ["84210", "0.299591"], ["84214.4", "0.063463"], ["84216.1", "0.861597"], ["84218", "0"], ["84226.5", "2.561894"], ["84240", "0.002077"], ["84240.6", "0.00315"], ["84240.8", "0.001466"], ["84240.9", "0.01656"], ["84242.6", "0.003294"], ["84242.9", "0.001333"], ["84243.4", "0.00009"]], "u": 45260, "seq": 67552578992}, "cts": 1742560334314, "record_time": 1742560334.340413, "EXCHANGE": "BYBIT"}
{"topic": "orderbook.200.BTCUSDT", "ts": 1742560334519, "type": "delta", "data": {"s": "BTCUSDT", "b": [["84172.9", "0.838954"], ["84167.9", "0.227006"], ["84166.9", "0"], ["84164.5", "0.04701"], ["84163.4", "0.167167"], ["84162.3", "0"], ["84159.5", "0"], ["84150.3", "0.001333"], ["84130.8", "0.539416"], ["84130.7", "0.064464"], ["84130.4", "0"], ["84130.3", "0"], ["84123.3", "0.001782"], ["84096.4", "0.0001"], ["84096.3", "0.000333"], ["84095.9", "0.06"]], "a": [["84173", "0.057782"], ["84176.4", "0.023515"], ["84181.4", "0.08969"], ["84188.1", "0.065716"], ["84190.6", "0.04"], ["84193.7", "0.046278"], ["84194.7", "0.032195"], ["84194.9", "0"], ["84197", "0.001119"], ["84197.8", "0"], ["84209.2", "0.041333"], ["84209.3", "0.04"], ["84209.4", "0"], ["84209.5", "0"], ["84209.8", "0.00009"], ["84214.4", "0"], ["84216.1", "0.130344"], ["84243.6", "0.000423"]], "u": 45261, "seq": 67552579085}, "cts": 1742560334516, "record_time": 1742560334.5422, "EXCHANGE": "BYBIT"}
{"topic": "orderbook.200.BTCUSDT", "ts": 1742560334720, "type": "delta", "data": {"s": "BTCUSDT", "b": [["84172.9", "0.667954"], ["84171.8", "0.021395"], ["84171.7", "0.071317"], ["84162.2", "0.168424"], ["84159.4", "0.000333"], ["84158.4", "0.112946"], ["84152.4", "0.180383"], ["84151.4", "0.183598"], ["84144.4", "0.276524"], ["84143.3", "0.287032"], ["84130.8", "0.539055"], ["84129.8", "0.012883"], ["84129.7", "0.014349"], ["84129.4", "0"], ["84129.3", "0.001333"], ["84097.1", "0"], ["84096.6", "0"], ["84096.5", "0"], ["84096.4", "0"], ["84096.3", "0"], ["84095.9", "0"]], "a": [["84173", "0.129097"], ["84187.4", "0.119335"], ["84191.3", "0.118079"], ["84197", "0"], ["84197.2", "0.17744"], ["84198.3", "0.177233"], ["84205.3", "0.275119"], ["84206.3", "0.2788"], ["84208.1", "0.012973"], ["84208.2", "0.012973"], ["84208.3", "0"], ["84208.4", "0.001466"], ["84208.7", "0.06346"], ["84220.9", "2.561742"], ["84226.5", "0"], ["84240.8", "0"], ["84240.9", "0"], ["84242.6", "0"], ["84242.9", "0"], ["84243.4", "0"], ["84243.6", "0"]], "u": 45262, "seq": 67552579176}, "cts": 1742560334713, "record_time": 1742560334.746091, "EXCHANGE": "BYBIT"}
{"topic": "orderbook.200.BTCUSDT", "ts": 1742560334920, "type": "delta", "data": {"s": "BTCUSDT", "b": [["84167.9", "0.223173"], ["84164.9", "0"], ["84160.4", "0.119326"], ["84154.3", "0.196803"], ["84147", "0.196681"], ["84097.1", "0.237567"]], "a": [["84208.7", "0"], ["84211.6", "0.06346"], ["84220.9", "0"], ["84240.8", "0.001466"]], "u": 45263, "seq": 67552579233}, "cts": 1742560334916, "record_time": 1742560334.940591, "EXCHANGE": "BYBIT"}
{"topic": "orderbook.200.BTCUSDT", "ts": 1742560335120, "type": "delta", "data": {"s": "BTCUSDT", "b": [["84167.9", "0.193239"], ["84167.8", "0.000333"], ["84162.2", "0.059399"], ["84158.4", "0.003268"], ["84152.4", "0"], ["84151.4", "0"], ["84144.4", "0"], ["84143.3", "0"], ["84096.6", "0.235392"], ["84096.5", "0.000518"], ["84096.4", "0.0001"], ["84096.3", "0.000333"]], "a": [["84173", "0.333363"], ["84178", "0.023541"], ["84180.6", "0.094135"], ["84183.4", "0"], ["84187.4", "0"], ["84191.3", "0"], ["84194.7", "0"], ["84194.8", "0.001211"], ["84195.1", "0.305152"], ["84197.2", "0"], ["84198.3", "0.000518"], ["84205.3", "0"], ["84206.3", "0"], ["84223.7", "2.561742"], ["84240.9", "0.01656"], ["84242.6", "0.003294"], ["84242.9", "0.001333"], ["84243.4", "0.00009"]], "u": 45264, "seq": 67552579367}, "cts": 1742560335116, "record_time": 1742560335.221904, "EXCHANGE": "BYBIT"}
{"topic": "orderbook.200.BTCUSDT", "ts": 1742560335320, "type": "delta", "data": {"s": "BTCUSDT", "b": [["84167.9", "0.190942"], ["84164.3", "0.071323"], ["84162.5", "0"], ["84161.1", "0.121255"], ["84157.3", "0.119866"], ["84154.3", "0.124581"], ["84151.3", "0.172705"], ["84150.3", "0.187734"], ["84147", "0.020211"], ["84143.3", "0.288688"], ["84142.2", "0.272344"], ["84130.9", "0.04"], ["84130.7", "0.024825"], ["84129.9", "0.013"], ["84129.7", "0.001466"], ["84126", "0.05"], ["84125.8", "0.000333"], ["84098.1", "0"], ["84097.8", "0"], ["84097.3", "0"], ["84097.1", "0"], ["84096.6", "0"], ["84096.5", "0"], ["84096.4", "0"], ["84096.3", "0"]], "a": [["84173", "0.222325"], ["84186.3", "0.119089"], ["84190.2", "0.122716"], ["84194.8", "0"], ["84196.1", "0.169428"], ["84197.2", "0.168697"], ["84204.2", "0.288254"], ["84205.2", "0.294409"], ["84208", "0.013"], ["84208.2", "0"], ["84209.1", "0.04"], ["84209.3", "0"], ["84215.2", "2.561742"], ["84223.7", "0"], ["84240.8", "0"], ["84240.9", "0"], ["84242.6", "0"], ["84242.9", "0"], ["84243.4", "0"]], "u": 45265, "seq": 67552579421}, "cts": 1742560335308, "record_time": 1742560335.343964, "EXCHANGE": "BYBIT"}
{"topic": "orderbook.200.BTCUSDT", "ts": 1742560335520, "type": "delta", "data": {"s": "BTCUSDT", "b": [["84161.2", "0.0071"], ["84156.9", "0"], ["84132.5", "0.0016"], ["84130.9", "0"], ["84130.7", "0.064464"], ["84129.9", "0"], ["84129.7", "0.014349"], ["84128.2", "0.003564"], ["84126", "0"], ["84125.8", "0.049888"], ["84100.9", "0.235392"], ["84098.1", "0.165081"]], "a": [["84189.1", "0.177593"], ["84189.4", "0.124735"], ["84201.8", "0.238771"], ["84208", "0"], ["84208.2", "0.012973"], ["84209.1", "0"], ["84209.3", "0.04"]], "u": 45266, "seq": 67552579452}, "cts": 1742560335499, "record_time": 1742560335.54399, "EXCHANGE": "BYBIT"}
{"topic": "orderbook.200.BTCUSDT", "ts": 1742560335719, "type": "delta", "data": {"s": "BTCUSDT", "b": [["84161.1", "0"], ["84157.3", "0"], ["84151.3", "0"], ["84150.3", "0.001333"], ["84143.3", "0"], ["84142.2", "0"], ["84097.8", "0.027758"], ["84097.3", "0.001466"], ["84097.1", "0.237567"], ["84096.5", "0.000518"], ["84096.4", "0.0001"]], "a": [["84173", "0.393325"], ["84186.3", "0"], ["84190.2", "0"], ["84195.1", "0.27292"], ["84196.1", "0"], ["84197.2", "0"], ["84204.2", "0"], ["84205.2", "0"], ["84207.9", "0.013"], ["84208", "0.012973"], ["84208.1", "0"], ["84208.2", "0"], ["84209", "0.04"], ["84209.1", "0.04"], ["84209.2", "0.001333"], ["84209.3", "0"], ["84240.8", "0.001466"], ["84240.9", "0.01656"], ["84242.6", "0.003294"], ["84242.9", "0.001333"], ["84243.4", "0.00009"]], "u": 45267, "seq": 67552579498}, "cts": 1742560335716, "record_time": 1742560335.744974, "EXCHANGE": "BYBIT"}
{"topic": "orderbook.200.BTCUSDT", "ts": 1742560335919, "type": "delta", "data": {"s": "BTCUSDT", "b": [["84172.9", "0.852615"], ["84172.8", "0.071494"], ["84096.4", "0"]], "a": [["84173", "0.222325"], ["84178.7", "0.0002"], ["84201.8", "0.099641"], ["84209", "0"], ["84209.2", "0.041333"]], "u": 45268, "seq": 67552579552}, "cts": 1742560335912, "record_time": 1742560335.93971, "EXCHANGE": "BYBIT"}
{"topic": "orderbook.200.BTCUSDT", "ts": 1742560336120, "type": "delta", "data": {"s": "BTCUSDT", "b": [], "a": [["84209", "0.04"], ["84209.2", "0.001333"], ["84243.4", "0"]], "u": 45269, "seq": 67552579575}, "cts": 1742560336056, "record_time": 1742560336.141347, "EXCHANGE": "BYBIT"}
{"topic": "orderbook.200.BTCUSDT", "ts": 1742560336320, "type": "delta", "data": {"s": "BTCUSDT", "b": [], "a": [["84207.9", "0"], ["84208", "0"], ["84208.1", "0.012973"], ["84208.2", "0.012973"], ["84209", "0"], ["84209.1", "0"], ["84209.2", "0.041333"], ["84209.3", "0.04"], ["84215", "0.974625"], ["84215.2", "0"], ["84218", "2.561742"], ["84243.4", "0.00009"]], "u": 45270, "seq": 67552579598}, "cts": 1742560336301, "record_time": 1742560336.340607, "EXCHANGE": "BYBIT"}
{"topic": "orderbook.200.BTCUSDT", "ts": 1742560336519, "type": "delta", "data": {"s": "BTCUSDT", "b": [["84137.9", "0.03565"], ["84135.3", "0"]], "a": [["84215", "1.4496"], ["84218", "0"], ["84220.9", "2.561742"]], "u": 45271, "seq": 67552579654}, "cts": 1742560336517, "record_time": 1742560336.540474, "EXCHANGE": "BYBIT"}
{"topic": "orderbook.200.BTCUSDT", "ts": 1742560336720, "type": "delta", "data": {"s": "BTCUSDT", "b": [], "a": [["84207.6", "0.121194"]], "u": 45272, "seq": 67552579673}, "cts": 1742560336699, "record_time": 1742560336.793179, "EXCHANGE": "BYBIT"}
{"topic": "orderbook.200.BTCUSDT", "ts": 1742560336919, "type": "delta", "data": {"s": "BTCUSDT", "b": [["84126", "0.05"], ["84125.8", "0.000333"], ["84096.5", "0"]], "a": [], "u": 45273, "seq": 67552579727}, "cts": 1742560336899, "record_time": 1742560336.940107, "EXCHANGE": "BYBIT"}
{"topic": "orderbook.200.BTCUSDT", "ts": 1742560337120, "type": "delta", "data": {"s": "BTCUSDT", "b": [["84172.9", "1.024415"], ["84161.7", "0.120785"], ["84151.9", "0.175838"], ["84142.8", "0.281955"], ["84126", "0"], ["84125.8", "0.049888"], ["84097.3", "0"], ["84097.1", "0"]], "a": [["84173", "0.162363"], ["84186.9", "0.11529"], ["84196.7", "0.286317"], ["84205.8", "0.314554"], ["84218", "2.561742"], ["84220.9", "0"], ["84243.4", "0"]], "u": 45274, "seq": 67552579813}, "cts": 1742560337099, "record_time": 1742560337.140197, "EXCHANGE": "BYBIT"}
{"topic": "orderbook.200.BTCUSDT", "ts": 1742560337320, "type": "delta", "data": {"s": "BTCUSDT", "b": [["84172.9", "0.853415"], ["84147", "0.112201"]], "a": [["84207.9", "0.013"], ["84208", "0.012973"], ["84208.1", "0"], ["84208.2", "0"], ["84209", "0.04"], ["84209.1", "0.04"], ["84209.2", "0.001333"], ["84209.3", "0"], ["84218", "0"], ["84221.8", "0.014411"], ["84223.7", "2.561742"], ["84242.6", "0"], ["84242.9", "0"]], "u": 45275, "seq": 67552579845}, "cts": 1742560337312, "record_time": 1742560337.34041, "EXCHANGE": "BYBIT"}
{"topic": "orderbook.200.BTCUSDT", "ts": 1742560337519, "type": "delta", "data": {"s": "BTCUSDT", "b": [["84172.9", "1.024415"], ["84172.7", "0.04545"], ["84172.6", "0.071316"], ["84172.3", "0.089099"], ["84171.8", "0"], ["84171.7", "0"], ["84166", "0.071321"], ["84161.8", "0.11007"], ["84161.7", "0.089099"], ["84160.4", "0.048"], ["84154.3", "0.128289"], ["84152", "0.170758"], ["84151.9", "0"], ["84151.4", "0.177774"], ["84150.4", "0"], ["84148.8", "0"], ["84146", "0.503746"], ["84142.9", "0.309756"], ["84142.8", "0"], ["84130.8", "0"], ["84130.6", "0.039639"], ["84129.8", "0"], ["84129.6", "0.012883"], ["84125.9", "0"], ["84125.7", "0.049555"], ["84097.8", "0"]], "a": [["84173", "0.162125"], ["84178", "0"], ["84180.6", "0.001466"], ["84186.9", "0"], ["84187", "0.115107"], ["84188.1", "0.03565"], ["84189.1", "0.120161"], ["84189.4", "0.005942"], ["84195.5", "0.030066"], ["84196.7", "0"], ["84196.8", "0.665282"], ["84197.9", "0"], ["84205.8", "0.003564"], ["84205.9", "0.293234"], ["84207.9", "0"], ["84208", "0"], ["84209", "0"], ["84209.1", "0.013"], ["84209.2", "0.014306"], ["84210.2", "0.04"], ["84210.3", "0.04"], ["84211.6", "0"], ["84213.1", "0.062693"], ["84214.4", "0.06346"], ["84223.7", "0"], ["84229.3", "5.771113"], ["84242.6", "0.003294"], ["84242.9", "0.001333"], ["84243.4", "0.00009"], ["84243.6", "0.000423"]], "u": 45276, "seq": 67552579997}, "cts": 1742560337517, "record_time": 1742560337.539997, "EXCHANGE": "BYBIT"}
{"topic": "orderbook.200.BTCUSDT", "ts": 1742560337719, "type": "delta", "data": {"s": "BTCUSDT", "b": [["84183.9", "0.778178"], ["84183.5", "0.304377"], ["84183.4", "0.190942"], ["84182.6", "0.190942"], ["84181.3", "0.034794"], ["84180.1", "0.04231"], ["84180", "0.089159"], ["84179.3", "0.001999"], ["84178.6", "0.049876"], ["84176.8", "0.049876"], ["84176.3", "0.050209"], ["84176.2", "0.000216"], ["84175.9", "0.072779"], ["84175.5", "0.012003"], ["84175.2", "0.003268"], ["84175.1", "0.000518"], ["84175", "0.050276"], ["84174.2", "0.01"], ["84173.1", "0.229364"], ["84173", "0.0006"], ["84172.9", "0.405537"], ["84172.8", "0.071316"], ["84172.7", "0"], ["84172.6", "0"], ["84172.1", "0.000333"], ["84171.3", "0.002799"], ["84171.2", "0.00009"], ["84171", "0.003268"], ["84170.5", "0.000518"], ["84168", "0"], ["84167.9", "0.024942"], ["84166", "0"], ["84164.5", "0"], ["84164.3", "0"], ["84161.8", "0"], ["84161.5", "0.059879"], ["84161.2", "0.010675"], ["84160.5", "0.052"], ["84159", "0.096332"], ["84157.4", "0.001466"], ["84155.5", "0.540618"], ["84154.3", "0.192013"], ["84152.3", "0.005566"], ["84152.1", "0.118793"], ["84152", "0.000518"], ["84151.4", "0"], ["84146.1", "0.120126"], ["84142.9", "0"], ["84142.5", "0.016468"], ["84139.3", "0"], ["84138.6", "0.017714"], ["84138.5", "0"], ["84137.1", "0.003564"], ["84135.4", "0.022801"], ["84135.3", "0.135473"], ["84134.4", "0.01402"], ["84133.6", "0.143532"], ["84130.7", "0.039639"], ["84127.2", "0"], ["84126.9", "0"], ["84118.7", "0"], ["84109.7", "0.235392"], ["84104.6", "0"], ["84104", "0"], ["84103.9", "0"], ["84103.7", "0"], ["84102.6", "0"], ["84102.5", "0"], ["84102.4", "0"], ["84102.3", "0"], ["84101.9", "0"], ["84101.3", "0"], ["84101.1", "0"], ["84101", "0"], ["84100.9", "0"], ["84100.5", "0"], ["84100.4", "0"], ["84100", "0"], ["84099.8", "0"], ["84099.5", "0"], ["84099.3", "0"], ["84099.1", "0"], ["84098.1", "0"]], "a": [["84173", "0"], ["84175.1", "0"], ["84175.2", "0"], ["84175.5", "0"], ["84175.9", "0"], ["84176.3", "0"], ["84176.4", "0"], ["84176.9", "0"], ["84178.1", "0"], ["84178.7", "0"], ["84179.4", "0"], ["84179.8", "0"], ["84180", "0"], ["84180.5", "0"], ["84180.6", "0"], ["84180.7", "0"], ["84181.4", "0"], ["84183.5", "0"], ["84183.6", "0"], ["84184.2", "0"], ["84184.5", "0"], ["84184.6", "0"], ["84184.8", "0"], ["84185.9", "0"], ["84186", "0"], ["84186.1", "0"], ["84187", "0"], ["84187.5", "0"], ["84188.1", "0"], ["84188.3", "0"], ["84188.9", "0.000333"], ["84189.1", "0.033709"], ["84189.2", "0"], ["84189.5", "0.071302"], ["84189.6", "0"], ["84190", "0.0002"], ["84190.6", "0"], ["84191.2", "0"], ["84191.8", "0"], ["84191.9", "0.0813"], ["84192.4", "0.044013"], ["84192.5", "0"], ["84193.7", "0.006278"], ["84194.1", "0"], ["84194.3", "0.086401"], ["84195.1", "0"], ["84195.5", "0"], ["84196.8", "0"], ["84197.6", "0.016407"], ["84199.7", "0.003833"], ["84200.4", "0.045152"], ["84201.4", "0.00009"], ["84201.7", "0"], ["84201.8", "0"], ["84202.3", "0.024632"], ["84202.4", "0.05933"], ["84204.1", "0"], ["84204.4", "0"], ["84204.7", "0.012822"], ["84205.6", "0.005571"], ["84205.8", "0"], ["84205.9", "0"], ["84209.1", "0.482181"], ["84209.2", "0.001333"], ["84210", "0.311476"], ["84210.2", "0"], ["84210.3", "0"], ["84212", "0"], ["84212.3", "0"], ["84212.5", "0"], ["84214.4", "0"], ["84214.9", "0.551329"], ["84215", "0"], ["84216.1", "0"], ["84217.9", "0"], ["84218", "0.012973"], ["84218.1", "0.012973"], ["84218.5", "0.011878"], ["84219", "0.063757"], ["84219.1", "0.04"], ["84219.7", "0.023322"], ["84220.5", "0"], ["84222.9", "0.063455"], ["84229.3", "3.209371"], ["84229.8", "0"], ["84231.6", "0"], ["84243.5", "2.561742"], ["84244.5", "0.002721"], ["84244.6", "0.000518"], ["84245.4", "0.001466"], ["84245.6", "0.027477"], ["84246.8", "0.003292"], ["84247.1", "0.001333"], ["84247.8", "0.000333"], ["84249", "0.237586"], ["84249.3", "0.000916"], ["84249.4", "0.059367"], ["84249.5", "0.032054"], ["84249.6", "0.059399"], ["84250", "0.001466"], ["84250.8", "3.664679"], ["84251", "0.003292"], ["84251.3", "0.010333"], ["84251.8", "0.00009"], ["84252.1", "0.089432"], ["84252.4", "0.005942"], ["84252.9", "0.059367"], ["84253.2", "0.05"], ["84253.9", "0.00052"], ["84254", "0.000146"], ["84254.7", "0.051466"], ["84255.2", "0.003293"], ["84255.5", "0.05"], ["84255.6", "0.001333"], ["84256", "0.05"], ["84256.3", "0.000333"], ["84257.1", "0.003564"], ["84257.5", "0.059367"], ["84258", "0.237586"], ["84258.5", "0.00052"], ["84258.7", "0.000358"], ["84259.3", "0.001466"], ["84259.4", "0.003293"], ["84259.8", "0.001333"], ["84260", "0.059399"], ["84260.2", "0.00009"], ["84260.5", "0.000333"], ["84261.2", "0.101605"], ["84262.1", "0.003"]], "u": 45277, "seq": 67552581905}, "cts": 1742560337717, "record_time": 1742560337.740997, "EXCHANGE": "BYBIT"}
{"topic": "orderbook.200.BTCUSDT", "ts": 1742560337919, "type": "delta", "data": {"s": "BTCUSDT", "b": [["84187.7", "0.461234"], ["84185.3", "0.116022"], ["84185.1", "0.205794"], ["84184.7", "0.186611"], ["84184.6", "0.171"], ["84183.9", "0.019942"], ["84183.6", "0.071306"], ["84183.5", "0"], ["84183.4", "0.019942"], ["84182.6", "0.262436"], ["84181.3", "0.019942"], ["84180.6", "0.001466"], ["84180.5", "0.000333"], ["84180.1", "0.017117"], ["84180", "0.00006"], ["84179.8", "0.001851"], ["84179.4", "0.003269"], ["84177", "0.119263"], ["84175.7", "0.02134"], ["84175.1", "0.262684"], ["84174.2", "0.033834"], ["84173.1", "0.059399"], ["84172.9", "0.399396"], ["84171.3", "0.021669"], ["84168", "0.047496"], ["84167.1", "0.049333"], ["84167", "0.04"], ["84165.7", "0.064"], ["84165.4", "0.044"], ["84163.8", "0"], ["84162", "0.049466"], ["84160.9", "0.030107"], ["84160.6", "0.009931"], ["84160.4", "0.056"], ["84159.7", "0"], ["84159", "0.238609"], ["84158.1", "0.306899"], ["84155.3", "0"], ["84154.3", "0.124581"], ["84153.9", "0"], ["84147", "0.202824"], ["84145.7", "0.006823"], ["84142", "0.267872"], ["84140.4", "0.128357"], ["84136.9", "0"], ["84128.2", "0"], ["84127.3", "0.031379"], ["84116.7", "0.000668"], ["84110.4", "0"], ["84109.7", "0"], ["84109.6", "0"], ["84109.4", "0"], ["84108.9", "0"], ["84108.2", "0"], ["84107.9", "0"], ["84107.8", "0"], ["84107.1", "0"], ["84106.9", "0"], ["84106.5", "0"], ["84105.7", "0"], ["84104.7", "0"]], "a": [["84184", "0"], ["84184.4", "0"], ["84184.7", "0"], ["84185.2", "0"], ["84187.8", "0.080788"], ["84189.1", "0"], ["84189.5", "0"], ["84191.8", "0.049805"], ["84192.6", "0.03201"], ["84193.1", "0.005333"], ["84193.7", "0.004211"], ["84194.4", "0"], ["84195", "0.071297"], ["84195.6", "0.04"], ["84195.8", "0.04"], ["84196.9", "0.04"], ["84197.3", "0.040333"], ["84197.6", "0.04"], ["84199.6", "0.028685"], ["84200.4", "0"], ["84200.9", "0.04"], ["84201.1", "0.044695"], ["84202.2", "0.122214"], ["84202.6", "0.04"], ["84202.8", "0.002067"], ["84207.6", "0.222546"], ["84210", "0.011885"], ["84212", "0.168397"], ["84213.5", "0.04424"], ["84213.6", "0.1657"], ["84214.9", "0"], ["84218", "0"], ["84218.1", "0"], ["84218.5", "0"], ["84218.9", "0.004673"], ["84219", "0.023757"], ["84219.1", "0"], ["84219.5", "0.013"], ["84219.6", "0.012973"], ["84220.1", "0.063451"], ["84220.6", "0.04"], ["84220.7", "0.04"], ["84221.1", "0.288451"], ["84222.9", "0"], ["84223.4", "0"], ["84227.9", "0"], ["84233.3", "0.01395"], ["84237.8", "2.561331"], ["84243.5", "0"], ["84246.1", "0.171"], ["84248.4", "0.005985"], ["84254.6", "0.171"], ["84258.7", "0"], ["84259.3", "0"], ["84259.4", "0"], ["84259.8", "0"], ["84260", "0"], ["84260.2", "0"], ["84260.5", "0"], ["84261.2", "0"], ["84262.1", "0"]], "u": 45278, "seq": 67552582514}, "cts": 1742560337916, "record_time": 1742560337.940476, "EXCHANGE": "BYBIT"}
{"topic": "orderbook.200.BTCUSDT", "ts": 1742560338120, "type": "delta", "data": {"s": "BTCUSDT", "b": [["84187.7", "0.620489"], ["84185.3", "0"], ["84185.1", "0.190942"], ["84184.7", "0.097118"], ["84184.6", "0"], ["84183.6", "0"], ["84180.1", "0"], ["84178.7", "0.060633"], ["84178.6", "0.053812"], ["84177.1", "0.110891"], ["84177", "0"], ["84176.8", "0.073709"], ["84175.1", "0.193754"], ["84175", "0.049876"], ["84174.2", "0.01"], ["84168", "0.129738"], ["84167.7", "0.052"], ["84166.6", "0.172391"], ["84163.7", "0.048"], ["84162.5", "0.06"], ["84161.5", "0"], ["84160.9", "0"], ["84159.6", "0.302866"], ["84158.9", "0"], ["84158.7", "0.001333"], ["84158.1", "0"], ["84157", "0.052"], ["84156.6", "0.024615"], ["84155.4", "0"], ["84153.6", "0"], ["84152.4", "0.023756"], ["84136.6", "0.04956"], ["84136.5", "0.049918"], ["84135.3", "0.135491"], ["84125.8", "0.000333"], ["84125.7", "0"], ["84119.3", "19.525413"], ["84110.4", "0.000518"], ["84110.3", "0.027538"]], "a": [["84187.8", "0.084619"], ["84194.3", "0.122611"], ["84197.3", "0.159126"], ["84197.7", "0.003704"], ["84197.8", "0.001277"], ["84198.7", "0.023679"], ["84199.2", "0.0829"], ["84199.3", "0.04"], ["84199.6", "0"], ["84200.6", "0.04"], ["84201.1", "0"], ["84201.5", "0.045563"], ["84201.6", "0.118834"], ["84202.1", "0.037252"], ["84202.2", "0"], ["84202.3", "0"], ["84212", "0"], ["84212.1", "0.180902"], ["84219.1", "0.275101"], ["84219.5", "0"], ["84219.6", "0"], ["84219.7", "0.036295"], ["84219.8", "0.012973"], ["84220.6", "0"], ["84220.7", "0"], ["84220.8", "0.045939"], ["84220.9", "0.04"], ["84221.1", "0"], ["84227.3", "1.0533"], ["84229.2", "0"], ["84253.2", "0"], ["84254.7", "0.001466"], ["84258.7", "0.000358"]], "u": 45279, "seq": 67552582715}, "cts": 1742560338116, "record_time": 1742560338.142166, "EXCHANGE": "BYBIT"}
{"topic": "orderbook.200.BTCUSDT", "ts": 1742560338320, "type": "delta", "data": {"s": "BTCUSDT", "b": [["84187.7", "0.625228"], ["84185.2", "0.057283"], ["84178.7", "0.029926"], ["84177.1", "0"], ["84171.4", "0.034237"], ["84168.2", "0.059868"], ["84168", "0.083958"], ["84166.6", "0"], ["84163.4", "0.241516"], ["84159.6", "0"], ["84157", "0"], ["84136.7", "0.05"], ["84136.5", "0.000358"], ["84135.3", "0.135502"]], "a": [["84187.8", "0.099529"], ["84194.3", "0.181537"], ["84195.5", "0.027"], ["84198.6", "0.047117"], ["84198.7", "0.059325"], ["84199.2", "0.00099"], ["84201.5", "0.000333"], ["84201.6", "0"], ["84201.7", "0.044399"], ["84202.1", "0.068953"], ["84211.9", "0.01728"], ["84212", "0.259753"], ["84212.1", "0"], ["84213.6", "0.0006"], ["84219.1", "0"], ["84219.7", "0.023322"], ["84219.9", "0.012973"], ["84249.5", "0"], ["84258.7", "0"]], "u": 45280, "seq": 67552582825}, "cts": 1742560338317, "record_time": 1742560338.366393, "EXCHANGE": "BYBIT"}
{"topic": "orderbook.200.BTCUSDT", "ts": 1742560338520, "type": "delta", "data": {"s": "BTCUSDT", "b": [["84179.3", "0.011999"], ["84174.2", "0"], ["84172.3", "0"], ["84171.4", "0.018602"], ["84163.4", "0.167167"], ["84161.2", "0.0071"], ["84160.9", "0.02948"], ["84159", "0.165439"], ["84149.4", "0.178173"]], "a": [["84187.8", "0.151168"], ["84191.9", "0.0713"], ["84196.2", "0.01"], ["84201.6", "0.061865"], ["84202.1", "0.031701"], ["84258", "0"], ["84258.5", "0"]], "u": 45281, "seq": 67552582906}, "cts": 1742560338516, "record_time": 1742560338.542017, "EXCHANGE": "BYBIT"}
{"topic": "orderbook.200.BTCUSDT", "ts": 1742560338720, "type": "delta", "data": {"s": "BTCUSDT", "b": [["84183.5", "0.00008"], ["84179.3", "0.016999"], ["84176.2", "0.12475"], ["84168.9", "0.003575"], ["84168", "0.12251"], ["84167.9", "0.019942"], ["84166.4", "0.168489"], ["84157.3", "0.287556"], ["84136.7", "0.04956"], ["84111.1", "0"], ["84110.9", "0"], ["84110.4", "0"], ["84110.3", "0"]], "a": [["84187.8", "0.157168"], ["84198.6", "0.105365"], ["84201.3", "0.178145"], ["84201.4", "0.109194"], ["84211.2", "0.169527"], ["84216.5", "0.100413"], ["84219.8", "0"], ["84219.9", "0"], ["84220.3", "0.289705"], ["84220.5", "0.137694"], ["84220.6", "0.012973"], ["84220.8", "0.005939"], ["84220.9", "0"], ["84221.5", "0.103196"], ["84221.6", "0.04"], ["84256", "0"], ["84256.3", "0"], ["84257.1", "0"], ["84257.5", "0"]], "u": 45282, "seq": 67552582992}, "cts": 1742560338711, "record_time": 1742560338.742096, "EXCHANGE": "BYBIT"}
{"topic": "orderbook.200.BTCUSDT", "ts": 1742560338919, "type": "delta", "data": {"s": "BTCUSDT", "b": [["84187.7", "0.796228"], ["84185.2", "0.128588"], ["84182.6", "0.190942"], ["84178.7", "0.055909"], ["84178.2", "0.071311"], ["84176.2", "0.000216"], ["84172.8", "0"], ["84171.5", "0.060498"], ["84168.9", "0"], ["84168", "0.083958"], ["84166.4", "0"], ["84164.5", "0.059527"], ["84159", "0.243067"], ["84157.5", "0.116069"], ["84157.3", "0"], ["84135.3", "0.135506"]], "a": [["84187.8", "0.153605"], ["84191.8", "0"], ["84193.1", "0.000333"], ["84196.2", "0.015"], ["84197.3", "0.040333"], ["84197.4", "0.171"], ["84198.7", "0.023679"], ["84198.8", "0.035646"], ["84201.2", "0.118793"], ["84201.3", "0"], ["84201.4", "0.00009"], ["84206.5", "0.060472"], ["84211.2", "0"], ["84213.5", "0.099967"], ["84218.7", "0.242516"], ["84220.1", "0"], ["84220.3", "0"], ["84220.5", "0.246679"], ["84220.7", "0.012973"], ["84221.5", "0.063196"], ["84221.7", "0.04"], ["84222.9", "0.063451"]], "u": 45283, "seq": 67552583079}, "cts": 1742560338912, "record_time": 1742560338.940004, "EXCHANGE": "BYBIT"}
{"topic": "orderbook.200.BTCUSDT", "ts": 1742560339119, "type": "delta", "data": {"s": "BTCUSDT", "b": [["84186.5", "0.071304"], ["84185.2", "0.057283"], ["84173.3", "0.009826"], ["84171.6", "0.025624"], ["84171.5", "0"], ["84171.4", "0"], ["84164.5", "0"], ["84163.2", "0.003575"], ["84160.6", "0"], ["84157.5", "0"], ["84156", "0.004605"], ["84142.5", "0.011885"], ["84141.7", "0.039643"], ["84141.6", "0.039643"], ["84140.7", "0.012884"], ["84140.6", "0.012884"], ["84138.6", "0.092776"], ["84136.8", "0.049559"], ["84136.6", "0"], ["84135.4", "0"], ["84130.7", "0"], ["84130.6", "0"], ["84129.7", "0.001466"], ["84129.6", "0"]], "a": [["84205.4", "0.178136"], ["84206.5", "0.0045"], ["84213.5", "0.04424"], ["84218.7", "0.173157"], ["84219.7", "0"], ["84220.5", "0.124721"], ["84220.6", "0"], ["84220.7", "0"], ["84221.5", "0.076196"], ["84221.6", "0.012973"], ["84221.7", "0"], ["84222.5", "0.04"], ["84222.6", "0.11747"], ["84222.9", "0"], ["84228.6", "0.063451"], ["84245.6", "0"], ["84256", "0.05"], ["84256.3", "0.000333"], ["84257.1", "0.003564"]], "u": 45284, "seq": 67552583157}, "cts": 1742560339114, "record_time": 1742560339.140262, "EXCHANGE": "BYBIT"}
{"topic": "orderbook.200.BTCUSDT", "ts": 1742560339319, "type": "delta", "data": {"s": "BTCUSDT", "b": [["84193.6", "0.960192"], ["84193", "0.06"], ["84192.5", "0.301348"], ["84192.4", "0.200934"], ["84192.3", "0.019942"], ["84191.8", "0.340876"], ["84191.6", "0.356396"], ["84190.8", "0.086346"], ["84190.3", "0.003936"], ["84188.9", "0.108339"], ["84188.8", "0.163267"], ["84188.2", "0.001333"], ["84187.8", "0.003269"], ["84187.7", "0.085718"], ["84187.2", "0.120876"], ["84187.1", "0.071304"], ["84186.5", "0"], ["84186.2", "0.009826"], ["84185.3", "0.059399"], ["84185.2", "0.032981"], ["84185.1", "0.019942"], ["84184.7", "0.097451"], ["84184.4", "0.000518"], ["84184", "0.011333"], ["84183.8", "0.0482"], ["84183.7", "0.01887"], ["84183.6", "0.003269"], ["84183.1", "0.116076"], ["84180.9", "0.023832"], ["84179.6", "0.00009"], ["84179.3", "0.006999"], ["84178.7", "0.029926"], ["84178.6", "0.049876"], ["84178.2", "0"], ["84177.1", "0.056"], ["84176.8", "0.049876"], ["84176.7", "0.176358"], ["84176.1", "0.314966"], ["84175.9", "0.001466"], ["84175.7", "0"], ["84175.5", "0.001333"], ["84173.3", "0"], ["84172.2", "0.540618"], ["84171.6", "0"], ["84171.4", "0.025624"], ["84171.3", "0.042799"], ["84169.7", "0.293513"], ["84169.1", "0.289005"], ["84168.2", "0"], ["84167.5", "0.037977"], ["84164.2", "0.503566"], ["84163.2", "0"], ["84162.9", "0.025973"], ["84162.4", "0.005942"], ["84162.3", "0.118793"], ["84160.7", "0.011883"], ["84159", "0.165439"], ["84155.5", "0"], ["84154.1", "0.003564"], ["84152.4", "0"], ["84152.3", "0"], ["84149.5", "0.135533"], ["84149.4", "0"], ["84146.9", "0"], ["84146", "0.00018"], ["84145.7", "0.003259"], ["84142.5", "0"], ["84141", "0.005939"], ["84140.4", "0"], ["84138.1", "0.024274"], ["84137.2", "0.023756"], ["84137.1", "0"], ["84136.9", "0.05"], ["84136.7", "0"], ["84135.7", "0.023756"], ["84135.3", "0"], ["84134.9", "0.023756"], ["84134.4", "0"], ["84134", "0"], ["84132.3", "0.023856"], ["84130.1", "3.358693"], ["84120.8", "0"], ["84120.5", "0"], ["84120.4", "0"], ["84120.3", "0"], ["84120.1", "0"], ["84120", "0"], ["84119.6", "0"], ["84119.3", "0"], ["84118.8", "0"], ["84118", "0"], ["84117.4", "0"], ["84116.9", "0"], ["84116.7", "0"], ["84116.6", "0"], ["84116.5", "0"], ["84116.3", "0"], ["84115.8", "0"], ["84115.6", "0"], ["84115.4", "0"], ["84115.3", "0"], ["84115", "0"], ["84114.4", "0"], ["84113.2", "0"], ["84113", "0"], ["84112.4", "0"], ["84112.1", "0"]], "a": [["84187.8", "0"], ["84188.2", "0"], ["84188.9", "0"], ["84189", "0"], ["84189.4", "0"], ["84189.8", "0"], ["84190", "0"], ["84190.9", "0"], ["84191.9", "0"], ["84192", "0"], ["84192.4", "0"], ["84192.6", "0"], ["84193", "0"], ["84193.1", "0"], ["84194.3", "0"], ["84195", "0"], ["84195.5", "0"], ["84195.6", "0"], ["84195.8", "0"], ["84196.9", "0"], ["84197.1", "0"], ["84197.3", "0.000333"], ["84197.4", "0"], ["84197.6", "0"], ["84197.7", "0"], ["84198.6", "0"], ["84198.7", "0"], ["84198.8", "0"], ["84199.3", "0"], ["84199.7", "0"], ["84200.6", "0"], ["84200.9", "0"], ["84201.2", "0"], ["84201.6", "0"], ["84201.7", "0"], ["84202.1", "0.042811"], ["84202.4", "0"], ["84202.6", "0"], ["84202.8", "0"], ["84203.3", "0.023678"], ["84204.7", "0.003293"], ["84205.4", "0"], ["84205.6", "0"], ["84206.6", "0.0003"], ["84207.5", "0.000297"], ["84207.6", "0.081845"], ["84208", "0.071286"], ["84208.2", "0.04"], ["84208.9", "0.047773"], ["84209.1", "0"], ["84209.9", "0.000333"], ["84210", "0"], ["84210.6", "0.003833"], ["84211", "0"], ["84211.7", "0.125009"], ["84211.9", "0"], ["84212", "0"], ["84212.4", "0"], ["84213.1", "0.019028"], ["84213.2", "0.005939"], ["84213.7", "0"], ["84214.9", "0.04"], ["84215.5", "0"], ["84216", "0.113894"], ["84216.6", "0"], ["84216.8", "0.119311"], ["84217.7", "0.01933"], ["84217.8", "0"], ["84218.9", "0"], ["84219", "0"], ["84220", "0.009769"], ["84220.3", "0.482181"], ["84220.4", "0"], ["84220.5", "0"], ["84220.8", "0"], ["84221.5", "0.003812"], ["84221.6", "0"], ["84222.2", "0.173742"], ["84222.3", "0"], ["84222.4", "0.059399"], ["84222.5", "0"], ["84222.6", "0.07747"], ["84222.8", "0"], ["84223", "0.166721"], ["84225.5", "0"], ["84228.1", "0.011883"], ["84228.6", "0"], ["84229.2", "0.287308"], ["84229.3", "0.023755"], ["84230", "0.300906"], ["84231.6", "0.013"], ["84231.7", "0.087446"], ["84232.6", "0.591103"], ["84232.7", "0.04"], ["84235.8", "0"], ["84237.8", "0"], ["84245.5", "0.063451"], ["84250.8", "0"], ["84254", "0"], ["84257.3", "3.21334"], ["84257.5", "0.059367"], ["84258", "0.237586"], ["84258.5", "0.00052"], ["84258.7", "0.000358"], ["84259.3", "0.001466"], ["84259.4", "0.003293"], ["84259.8", "0.001333"], ["84260", "0.059399"], ["84260.1", "0.027743"], ["84260.2", "0.00009"], ["84260.5", "0.000333"], ["84261.2", "0.101605"], ["84262.1", "0.003"], ["84262.3", "0.12"], ["84263", "0.000203"], ["84263.1", "0.118793"], ["84263.2", "0.00052"], ["84263.6", "0.003293"], ["84263.9", "0.001466"], ["84264", "0.001333"], ["84264.3", "0.247212"], ["84264.7", "0.000333"], ["84265", "0.005942"], ["84266", "0.000332"], ["84266.1", "0.096842"], ["84266.5", "0.0045"], ["84267.6", "0.01183"], ["84267.8", "0.00052"], ["84267.9", "0.003292"], ["84268.2", "0.001333"], ["84268.6", "0.001556"], ["84268.9", "0.000333"], ["84269.3", "0.003"], ["84270.6", "0.164721"], ["84270.9", "0.04"], ["84271", "0.237586"], ["84271.1", "0.000146"], ["84271.2", "0.12"], ["84271.3", "0.12"], ["84272", "0.62359"], ["84272.1", "0.003292"], ["84272.3", "0.05728"]], "u": 45285, "seq": 67552584929}, "cts": 1742560339317, "record_time": 1742560339.415635, "EXCHANGE": "BYBIT"}
{"topic": "orderbook.200.BTCUSDT", "ts": 1742560339520, "type": "delta", "data": {"s": "BTCUSDT", "b": [["84198.1", "0.521193"], ["84193.7", "0.094793"], ["84193.6", "0.315976"], ["84193.1", "0.000333"], ["84192.5", "0.177764"], ["84192.4", "0.172333"], ["84192", "0.003269"], ["84191.8", "0.310942"], ["84191.6", "0"], ["84191.4", "0.011914"], ["84190.8", "0.071494"], ["84189.8", "0.001466"], ["84189", "0.000518"], ["84188.8", "0.020342"], ["84188", "0.00009"], ["84187.7", "0.07146"], ["84187.2", "0"], ["84185.4", "0.064"], ["84185.2", "0.006466"], ["84184.7", "0.16965"], ["84184.2", "0.071306"], ["84184", "0.017133"], ["84183.6", "0.051269"], ["84183.1", "0"], ["84182.2", "0.044"], ["84181.8", "0.048"], ["84180.9", "0"], ["84180.4", "0.052"], ["84179.3", "0.001999"], ["84178.7", "0.095332"], ["84177.7", "0.003575"], ["84176.7", "0"], ["84176.1", "0.139143"], ["84175.6", "0.06"], ["84175.1", "0.29133"], ["84171.4", "0.185555"], ["84169.8", "0.07296"], ["84169.7", "0"], ["84169.1", "0"], ["84168", "0.234426"], ["84167.1", "0.001333"], ["84167", "0"], ["84165.7", "0"], ["84165.4", "0"], ["84165.2", "0.178161"], ["84162", "0.001466"], ["84161.2", "0"], ["84160.4", "0"], ["84159", "0"], ["84156.7", "0.014749"], ["84156.6", "0.000518"], ["84155.3", "0.0016"], ["84152.5", "0.05"], ["84152.4", "0.049553"], ["84152.2", "0.014046"], ["84147", "0"], ["84136.9", "0"], ["84136.8", "0"], ["84132.5", "0"], ["84123.3", "0"], ["84122.5", "0"], ["84121.8", "0"], ["84121.6", "0"], ["84121.2", "0"]], "a": [["84193.7", "0"], ["84194.5", "0"], ["84196.2", "0"], ["84196.3", "0"], ["84196.6", "0"], ["84197.3", "0"], ["84197.8", "0"], ["84198.2", "0.274207"], ["84201.4", "0"], ["84202.1", "0.041701"], ["84203.3", "0"], ["84204.4", "0.071289"], ["84204.9", "0.011839"], ["84205.3", "0.0002"], ["84206", "0.071288"], ["84207.4", "0"], ["84207.6", "0.143792"], ["84208", "0"], ["84208.9", "0.003293"], ["84209.9", "0.044886"], ["84210", "0.208628"], ["84211.6", "0.04"], ["84211.7", "0"], ["84212.1", "0.04"], ["84213.1", "0.003294"], ["84213.9", "0.04"], ["84215.4", "0.04"], ["84215.6", "0.04"], ["84216", "0"], ["84217", "0.04"], ["84222.1", "0.059399"], ["84222.2", "0.001466"], ["84222.4", "0"], ["84223", "0"], ["84227.3", "0.263862"], ["84229.2", "0"], ["84230", "0"], ["84231.6", "0"], ["84231.7", "0.254494"], ["84232.6", "0.551103"], ["84232.7", "0"], ["84233", "0.013"], ["84233.1", "0.012973"], ["84233.3", "0"], ["84233.6", "0.011876"], ["84234", "0.04"], ["84234.1", "0.04"], ["84236.2", "0.004576"], ["84237.2", "0.06188"], ["84239.7", "0.063758"], ["84245.4", "0.073289"], ["84248.3", "0.01404"], ["84263.1", "0.289793"], ["84270.6", "0.04"], ["84271.6", "0.171"], ["84272", "0"], ["84272.1", "0"], ["84272.3", "0"]], "u": 45286, "seq": 67552585505}, "cts": 1742560339515, "record_time": 1742560339.540763, "EXCHANGE": "BYBIT"}
{"topic": "orderbook.200.BTCUSDT", "ts": 1742560339719, "type": "delta", "data": {"s": "BTCUSDT", "b": [["84198.1", "0.721894"], ["84197", "0.063498"], ["84196.9", "0.071295"], ["84193.7", "0"], ["84193.6", "0.301124"], ["84192.5", "0.124988"], ["84192.4", "0.001333"], ["84189.7", "0.042185"], ["84189.2", "0.071302"], ["84187.7", "0.056611"], ["84187.2", "0.04"], ["84184.2", "0"], ["84183.7", "0.07087"], ["84180.5", "0.065912"], ["84178.7", "0"], ["84171.4", "0.025624"], ["84171.3", "0.002799"], ["84168", "0.235692"], ["84163.7", "0"], ["84162.5", "0"], ["84160.5", "0"], ["84156.7", "0"], ["84154.2", "0.027805"], ["84153", "0.05"], ["84152.9", "0.108952"], ["84152.5", "0"], ["84152.4", "0"], ["84152.3", "0.135529"], ["84149.5", "0"], ["84138.6", "0.017714"], ["84127.7", "19.525072"], ["84123.7", "0.235392"], ["84123.3", "0.001782"]], "a": [["84198.2", "0.174501"], ["84202.1", "0.015"], ["84206.6", "0.06446"], ["84206.9", "0.003648"], ["84209.9", "0.000333"], ["84210", "0.25167"], ["84210.4", "0.04"], ["84213.7", "0.04"], ["84215.4", "0.042067"], ["84216.8", "0.169311"], ["84217.8", "0.03564"], ["84217.9", "0.05"], ["84218.5", "0.05"], ["84219", "0.047114"], ["84222.6", "0.021429"], ["84227.3", "0.099807"], ["84233", "0"], ["84233.1", "0"], ["84233.5", "0.012973"], ["84233.6", "0.024849"], ["84234", "0"], ["84234.1", "0"], ["84234.5", "0.041333"], ["84234.6", "0.063755"], ["84237.1", "0.063454"], ["84240.2", "1.424499"], ["84242", "0.022853"], ["84245.5", "0"], ["84254.8", "2.561732"], ["84255.5", "0"], ["84256", "0"], ["84262.1", "0"], ["84271.1", "0"], ["84271.2", "0"], ["84271.3", "0"], ["84271.6", "0"]], "u": 45287, "seq": 67552585763}, "cts": 1742560339710, "record_time": 1742560339.740752, "EXCHANGE": "BYBIT"}
{"topic": "orderbook.200.BTCUSDT", "ts": 1742560339920, "type": "delta", "data": {"s": "BTCUSDT", "b": [["84198.1", "0.718405"], ["84197.9", "0.103788"], ["84197.8", "0.071294"], ["84197", "0"], ["84196.9", "0"], ["84188.8", "0.019942"], ["84188.2", "0.111318"], ["84187.7", "0.05047"], ["84184.1", "0.123413"], ["84182.1", "0.06"], ["84177.7", "0.177013"], ["84177.1", "0.225421"], ["84175.6", "0"], ["84170.7", "0.306761"], ["84170.1", "0.278785"], ["84167.7", "0"], ["84153.2", "19.525072"], ["84153", "0"], ["84152.8", "0.222019"], ["84146.2", "0.064269"], ["84140.9", "0.010994"], ["84140.8", "0.010994"], ["84139", "0.040332"], ["84137.4", "0.021988"], ["84137.3", "0.067259"], ["84132.2", "0.170793"], ["84127.7", "0"], ["84126.3", "0.003564"], ["84124.4", "0"], ["84124.2", "0"], ["84124.1", "0"], ["84123.9", "0"], ["84123.7", "0"], ["84123.3", "0"]], "a": [["84198.2", "0.103473"], ["84202.1", "0.01"], ["84206.6", "0.06946"], ["84210", "0.283286"], ["84212.7", "0.119488"], ["84215.5", "0.161995"], ["84216.5", "0"], ["84217", "0.164646"], ["84223.2", "0.169143"], ["84224", "0.179894"], ["84230.2", "0.298435"], ["84231", "0.312714"], ["84233.5", "0"], ["84233.7", "0.012973"], ["84234.5", "0.001333"], ["84234.7", "0.158793"], ["84245.4", "0.001466"], ["84252", "2.561732"], ["84254.8", "0"], ["84269.3", "0"], ["84270.6", "0"], ["84270.9", "0"], ["84271", "0"]], "u": 45288, "seq": 67552585943}, "cts": 1742560339909, "record_time": 1742560339.942585, "EXCHANGE": "BYBIT"}
{"topic": "orderbook.200.BTCUSDT", "ts": 1742560340119, "type": "delta", "data": {"s": "BTCUSDT", "b": [["84189.7", "0.052185"], ["84188.2", "0.001333"], ["84184.1", "0"], ["84184", "0.007133"], ["84180.5", "0.160572"], ["84177.7", "0.003575"], ["84177.1", "0.056"], ["84173.3", "0.02365"], ["84171.4", "0.196731"], ["84170.7", "0"], ["84170.1", "0"], ["84152.3", "0.135544"], ["84124.9", "0"], ["84124.4", "0.059399"], ["84124.2", "0.000518"], ["84124.1", "0.00594"]], "a": [["84199", "0.024152"], ["84211.1", "0.05892"], ["84212.7", "0"], ["84217", "0.04"], ["84217.8", "0"], ["84217.9", "0.08564"], ["84220.5", "0.124706"], ["84223.2", "0"], ["84224", "0"], ["84227.3", "0.270576"], ["84230.2", "0"], ["84231", "0.000333"], ["84233.6", "0.011876"], ["84233.7", "0"], ["84233.9", "0.012987"], ["84234", "0.012987"], ["84234.6", "0.023755"], ["84234.7", "0.118793"], ["84234.9", "0.04"], ["84235", "0.04009"], ["84237.1", "0"], ["84239.7", "0.489994"], ["84242.7", "0.063454"]], "u": 45289, "seq": 67552586070}, "cts": 1742560340113, "record_time": 1742560340.140686, "EXCHANGE": "BYBIT"}
{"topic": "orderbook.200.BTCUSDT", "ts": 1742560340320, "type": "delta", "data": {"s": "BTCUSDT", "b": [["84198.1", "0.724546"], ["84190.8", "0"], ["84188.9", "0.159651"], ["84188", "0.109633"], ["84187.7", "0.170948"], ["84183.9", "0.129423"], ["84180.5", "0.065912"], ["84177.9", "0.171201"], ["84177.5", "0.174682"], ["84176.9", "0.163364"], ["84173.3", "0.027201"], ["84171.4", "0.025624"], ["84170.5", "0.305558"], ["84169.9", "0.281281"], ["84168.8", "0.292128"], ["84155", "0.128335"], ["84154.3", "6.03141"], ["84153", "0.05"], ["84152.8", "0.172466"], ["84150", "2.380085"], ["84125", "0.001466"], ["84124.8", "0"], ["84124.7", "0"], ["84124.6", "0"], ["84124.4", "0"], ["84124.2", "0"], ["84124.1", "0"]], "a": [["84202.1", "0"], ["84206.6", "0.07946"], ["84210", "0.329405"], ["84212.5", "0.11501"], ["84212.9", "0.112463"], ["84216.8", "0.283052"], ["84222.6", "0.035004"], ["84222.7", "0.163111"], ["84223", "0.181836"], ["84223.8", "0.18494"], ["84227.3", "0.099807"], ["84230", "0.278015"], ["84230.8", "0.311375"], ["84231.8", "0.30451"], ["84267.6", "0"], ["84267.8", "0"], ["84267.9", "0"], ["84268.2", "0"], ["84268.6", "0"], ["84268.9", "0"]], "u": 45290, "seq": 67552586163}, "cts": 1742560340316, "record_time": 1742560340.341317, "EXCHANGE": "BYBIT"}
{"topic": "orderbook.200.BTCUSDT", "ts": 1742560340519, "type": "delta", "data": {"s": "BTCUSDT", "b": [["84189.7", "0.057185"], ["84185.2", "0.001466"], ["84180.5", "0.210489"], ["84153", "0"], ["84152.8", "0.222019"], ["84135.6", "0.052"]], "a": [["84222.6", "0.192273"], ["84233", "0.000118"], ["84266.5", "0"]], "u": 45291, "seq": 67552586253}, "cts": 1742560340516, "record_time": 1742560340.54075, "EXCHANGE": "BYBIT"}
{"topic": "orderbook.200.BTCUSDT", "ts": 1742560340720, "type": "delta", "data": {"s": "BTCUSDT", "b": [["84171.4", "0.284602"], ["84152.3", "0.135553"]], "a": [["84218.7", "0.25609"]], "u": 45292, "seq": 67552586303}, "cts": 1742560340693, "record_time": 1742560340.744556, "EXCHANGE": "BYBIT"}
{"topic": "orderbook.200.BTCUSDT", "ts": 1742560340919, "type": "delta", "data": {"s": "BTCUSDT", "b": [["84188.9", "0.108339"], ["84188", "0.00009"], ["84187.7", "0.05047"], ["84183.9", "0.019942"], ["84177.9", "0"], ["84177.5", "0"], ["84176.9", "0"], ["84170.5", "0.000518"], ["84169.9", "0"], ["84168.8", "0"], ["84157.8", "0.039637"], ["84157.7", "0.039638"], ["84153", "0.05"], ["84152.8", "0.172466"], ["84141.7", "0"], ["84141.6", "0"], ["84124.7", "0.003259"], ["84124.6", "0.02112"], ["84124.4", "0.059399"], ["84124.2", "0.000518"]], "a": [["84199", "0"], ["84207.6", "0.102691"], ["84210", "0.274304"], ["84212.5", "0"], ["84212.9", "0"], ["84216.8", "0.169311"], ["84222.7", "0"], ["84223", "0"], ["84223.8", "0"], ["84230", "0"], ["84230.8", "0"], ["84231.8", "0.003564"], ["84234.5", "0.041333"], ["84234.6", "0.063755"], ["84234.9", "0"], ["84235", "0.00009"], ["84266.5", "0.0045"], ["84267.6", "0.01183"], ["84267.8", "0.00052"], ["84267.9", "0.003292"], ["84268.2", "0.001333"], ["84268.6", "0.001556"], ["84268.9", "0.000333"], ["84269.3", "0.003"], ["84270.6", "0.04"]], "u": 45293, "seq": 67552586395}, "cts": 1742560340916, "record_time": 1742560340.987943, "EXCHANGE": "BYBIT"}
{"topic": "orderbook.200.BTCUSDT", "ts": 1742560341120, "type": "delta", "data": {"s": "BTCUSDT", "b": [["84180.5", "0.065912"], ["84171.4", "0.025624"], ["84156.8", "0.013"], ["84156.7", "0.012882"], ["84153", "0"], ["84152.8", "0.222019"], ["84152.3", "0.135564"], ["84140.7", "0"], ["84140.6", "0"], ["84124.8", "0.171"]], "a": [["84222.6", "0.037641"], ["84233.4", "0.013"], ["84233.5", "0.012988"], ["84233.9", "0"], ["84234", "0"], ["84234.4", "0.04"], ["84234.6", "0.023755"], ["84270.6", "0"]], "u": 45294, "seq": 67552586505}, "cts": 1742560341116, "record_time": 1742560341.140375, "EXCHANGE": "BYBIT"}
{"topic": "orderbook.200.BTCUSDT", "ts": 1742560341320, "type": "delta", "data": {"s": "BTCUSDT", "b": [["84178", "0.003552"], ["84173.3", "0.02365"], ["84157.9", "0.039506"], ["84124.4", "0"], ["84124.2", "0"]], "a": [], "u": 45295, "seq": 67552586568}, "cts": 1742560341316, "record_time": 1742560341.340281, "EXCHANGE": "BYBIT"}
{"topic": "orderbook.200.BTCUSDT", "ts": 1742560341520, "type": "delta", "data": {"s": "BTCUSDT", "b": [["84157.9", "0.075146"], ["84156.8", "0.012882"], ["84153", "0.05"], ["84152.8", "0.172466"], ["84137.9", "0"]], "a": [["84233.4", "0"], ["84233.6", "0.024864"], ["84234.4", "0"], ["84234.6", "0.063755"], ["84270.6", "0.04"], ["84270.9", "0.04"]], "u": 45296, "seq": 67552586613}, "cts": 1742560341506, "record_time": 1742560341.54017, "EXCHANGE": "BYBIT"}
{"topic": "orderbook.200.BTCUSDT", "ts": 1742560341720, "type": "delta", "data": {"s": "BTCUSDT", "b": [["84178", "0"], ["84157.9", "0.115146"], ["84157.7", "0"], ["84124.4", "0.059399"], ["84124.2", "0.000518"]], "a": [], "u": 45297, "seq": 67552586645}, "cts": 1742560341715, "record_time": 1742560341.741617, "EXCHANGE": "BYBIT"}
{"topic": "orderbook.200.BTCUSDT", "ts": 1742560341919, "type": "delta", "data": {"s": "BTCUSDT", "b": [["84198.1", "0.725946"], ["84192.5", "0.214087"], ["84192.2", "0.071494"], ["84191.3", "0.0713"], ["84189.2", "0"], ["84181", "0.003552"], ["84179.3", "0"], ["84177.7", "0"], ["84176.2", "0.000716"], ["84157.9", "0.03564"], ["84157.7", "0.039638"], ["84154.2", "0.003259"], ["84153.2", "0"], ["84153", "0"], ["84152.8", "0.222019"], ["84124.1", "0.00594"]], "a": [["84198.2", "0.028972"], ["84200.8", "0.072625"], ["84204.4", "0"], ["84206", "0"], ["84209.7", "0.071284"], ["84216.8", "0.050518"], ["84217.9", "0.05"], ["84220.3", "0"], ["84222.1", "0"], ["84231.4", "0.54158"], ["84233.5", "0"], ["84233.6", "0.011876"], ["84234.5", "0.001333"], ["84234.6", "0.023755"], ["84235.2", "0.013333"], ["84235.3", "0.012988"], ["84236.2", "0.044576"], ["84236.3", "0.04"], ["84242", "0"], ["84252", "0"], ["84257.6", "2.561732"], ["84271", "0.237586"], ["84271.1", "0.000146"], ["84271.2", "0.12"]], "u": 45298, "seq": 67552586807}, "cts": 1742560341917, "record_time": 1742560341.939413, "EXCHANGE": "BYBIT"}
{"topic": "orderbook.200.BTCUSDT", "ts": 1742560342119, "type": "delta", "data": {"s": "BTCUSDT", "b": [["84199", "1.178775"], ["84198.3", "0.094288"], ["84198.2", "0.1"], ["84198.1", "0.227617"], ["84197.9", "0"], ["84197.8", "0"], ["84193.7", "0.000518"], ["84193.6", "0.030124"], ["84193.3", "0.071298"], ["84192.6", "0.192719"], ["84192.5", "0.089099"], ["84190.6", "0.015"], ["84189.7", "0.042185"], ["84188.9", "0.000333"], ["84187.8", "0.105477"], ["84187.1", "0"], ["84186.9", "0.001956"], ["84181", "0"], ["84172.3", "0.118793"], ["84171.9", "0.004704"], ["84157.8", "0"], ["84157.6", "0.039638"], ["84156.8", "0"], ["84156.6", "0.0134"], ["84156", "0"], ["84155", "0"], ["84154.3", "0.124581"], ["84152.9", "0.059399"], ["84152.7", "0.049553"], ["84137.9", "0.023753"], ["84127.2", "0.235392"], ["84124.8", "0"], ["84124.7", "0"], ["84124.6", "0"], ["84124.4", "0"], ["84124.2", "0"], ["84124.1", "0"]], "a": [["84198.2", "0"], ["84198.3", "0"], ["84199.1", "0.004435"], ["84200.8", "0.001333"], ["84206.4", "0.000296"], ["84206.6", "0.06446"], ["84207.5", "0.015297"], ["84207.6", "0.000518"], ["84208.2", "0"], ["84209.7", "0"], ["84210", "0.055106"], ["84210.4", "0"], ["84210.6", "0"], ["84211.5", "0.071283"], ["84211.6", "0"], ["84212.1", "0"], ["84213.5", "0"], ["84213.7", "0"], ["84213.9", "0"], ["84214.9", "0"], ["84215.5", "0.115665"], ["84215.6", "0"], ["84217", "0"], ["84217.1", "0.04"], ["84218.5", "0"], ["84218.7", "0.082933"], ["84218.9", "0.04"], ["84220.5", "0.003833"], ["84222.2", "0.041466"], ["84223.9", "0.04"], ["84228.6", "0.04422"], ["84231.3", "0.406031"], ["84231.7", "0"], ["84235.2", "0.000333"], ["84235.3", "0"], ["84236.2", "0.004576"], ["84236.3", "0"], ["84237.9", "0.013603"], ["84238", "0.012988"], ["84238.9", "0.04"], ["84239", "0.04"], ["84257.6", "0"], ["84260.1", "0"], ["84263.3", "2.562085"], ["84271.3", "0.12"], ["84272.1", "0.003292"], ["84272.3", "0.05728"], ["84272.4", "0.001853"], ["84273.1", "0.000333"], ["84273.2", "0.001466"], ["84274.2", "0.04"], ["84274.5", "0.059399"], ["84275.5", "0.04"]], "u": 45299, "seq": 67552587224}, "cts": 1742560342116, "record_time": 1742560342.14023, "EXCHANGE": "BYBIT"}
{"topic": "orderbook.200.BTCUSDT", "ts": 1742560342320, "type": "delta", "data": {"s": "BTCUSDT", "b": [["84199", "0.992291"], ["84198.1", "0.221476"], ["84187.8", "0.136648"], ["84158", "0.048782"], ["84153.2", "19.501268"], ["84152.3", "0.135565"], ["84125.1", "0"], ["84125", "0"]], "a": [["84215.4", "0.002067"], ["84217", "0.04"], ["84217.9", "0.001277"], ["84218.6", "0.04"], ["84218.7", "0.055818"], ["84219", "0"], ["84220.3", "0.04"], ["84220.5", "0.043833"], ["84222.2", "0.085373"], ["84223.7", "0.04"], ["84257.6", "2.562085"], ["84263.3", "0"], ["84270.4", "0.089075"], ["84271.6", "0.171"], ["84273.1", "0"], ["84273.2", "0"], ["84274.2", "0"], ["84274.5", "0"], ["84275.5", "0"]], "u": 45300, "seq": 67552587389}, "cts": 1742560342315, "record_time": 1742560342.340982, "EXCHANGE": "BYBIT"}
{"topic": "orderbook.200.BTCUSDT", "ts": 1742560342520, "type": "delta", "data": {"s": "BTCUSDT", "b": [["84188.1", "0.023829"], ["84162.2", "0.0828"], ["84155.5", "0.05"], ["84155.4", "0.049551"], ["84152.8", "0.172466"], ["84152.7", "0"], ["84152.3", "0.135557"], ["84126.3", "0"], ["84125.8", "0"]], "a": [["84199.1", "0.075728"], ["84205.2", "0.071288"], ["84206.4", "0"], ["84206.9", "0.003617"], ["84207.5", "0.015"], ["84210", "0.021721"], ["84211.5", "0"], ["84222", "0.04"], ["84222.6", "0.056978"], ["84239.9", "0.122859"], ["84242.7", "0"], ["84251.6", "0.024745"], ["84270.6", "0.164704"]], "u": 45301, "seq": 67552587470}, "cts": 1742560342516, "record_time": 1742560342.557304, "EXCHANGE": "BYBIT"}
{"topic": "orderbook.200.BTCUSDT", "ts": 1742560342720, "type": "delta", "data": {"s": "BTCUSDT", "b": [["84199", "0.998432"], ["84187.7", "0.049876"], ["84155.5", "0"], ["84155.3", "0.051151"], ["84126.3", "0.003564"]], "a": [["84206.9", "0"], ["84214.5", "0.003975"], ["84218.7", "0.083879"], ["84222.1", "0.035638"], ["84222.2", "0.084644"], ["84240.3", "0.178149"], ["84272.4", "0"]], "u": 45302, "seq": 67552587539}, "cts": 1742560342715, "record_time": 1742560342.744421, "EXCHANGE": "BYBIT"}
{"topic": "orderbook.200.BTCUSDT", "ts": 1742560342920, "type": "delta", "data": {"s": "BTCUSDT", "b": [["84192.5", "0"], ["84159.3", "0.013"], ["84159.2", "0.012882"], ["84156.7", "0"], ["84156.6", "0.000518"], ["84152.3", "0.135578"]], "a": [["84205.2", "0"], ["84207.2", "0.071287"], ["84209.7", "0.071284"], ["84210", "0.045398"], ["84218.5", "0.118793"], ["84237.7", "0.018938"], ["84237.8", "0.012988"], ["84237.9", "0.000615"], ["84238", "0"], ["84272.1", "0"], ["84272.3", "0"]], "u": 45303, "seq": 67552587597}, "cts": 1742560342891, "record_time": 1742560342.940158, "EXCHANGE": "BYBIT"}
{"topic": "orderbook.200.BTCUSDT", "ts": 1742560343120, "type": "delta", "data": {"s": "BTCUSDT", "b": [["84184.5", "0.062107"], ["84177.5", "0.055917"], ["84170.5", "0.124818"], ["84160.4", "0.04"], ["84160.3", "0.039636"], ["84159.4", "0.013333"], ["84159.3", "0.012882"], ["84159.2", "0"], ["84157.7", "0"], ["84157.6", "0"], ["84155.5", "0.05"], ["84155.3", "0.0016"], ["84127.1", "0"], ["84126.3", "0"]], "a": [["84199.1", "0.077328"], ["84218.4", "0.1493"], ["84218.7", "0"], ["84219.5", "0.060183"], ["84221.8", "0"], ["84222.1", "0.078816"], ["84222.2", "0.041466"], ["84226.5", "0.058175"], ["84233.5", "0.120352"], ["84237.6", "0.184"], ["84237.7", "0.018926"], ["84237.8", "0"], ["84238.6", "0.04"], ["84238.7", "0.041333"], ["84238.9", "0"], ["84239", "0"], ["84240.3", "0"], ["84254.8", "2.562085"], ["84257.6", "0"], ["84272.1", "0.003292"], ["84272.3", "0.05728"]], "u": 45304, "seq": 67552587687}, "cts": 1742560343096, "record_time": 1742560343.140559, "EXCHANGE": "BYBIT"}
{"topic": "orderbook.200.BTCUSDT", "ts": 1742560343319, "type": "delta", "data": {"s": "BTCUSDT", "b": [["84199", "1.004018"], ["84193.3", "0"], ["84193.2", "0.071298"], ["84191.3", "0"], ["84188.6", "0.121841"], ["84188.5", "0.071302"], ["84187.8", "0.063117"], ["84184.5", "0"], ["84177.5", "0"], ["84170.5", "0.000518"], ["84160.4", "0"], ["84160.3", "0"], ["84160.1", "0.039636"], ["84160", "0.039696"], ["84159.4", "0.000333"], ["84159.3", "0"], ["84159.1", "0.012882"], ["84159", "0.012882"], ["84155.5", "0"], ["84155.4", "0"], ["84155.2", "0.049884"], ["84155.1", "0.049551"], ["84152.3", "0"], ["84127.1", "0.118793"], ["84126.3", "0.003564"], ["84125.8", "0.000333"]], "a": [["84205.3", "0.071488"], ["84207.2", "0"], ["84219.5", "0"], ["84226.5", "0"], ["84233.5", "0"], ["84237.3", "0.036754"], ["84237.4", "0.012988"], ["84237.6", "0.171"], ["84237.7", "0.005938"], ["84246", "0.052787"], ["84254.8", "0"], ["84257.6", "2.562085"], ["84272.4", "0.001853"], ["84273.1", "0.000333"]], "u": 45305, "seq": 67552587775}, "cts": 1742560343317, "record_time": 1742560343.340047, "EXCHANGE": "BYBIT"}
{"topic": "orderbook.200.BTCUSDT", "ts": 1742560343520, "type": "delta", "data": {"s": "BTCUSDT", "b": [["84199", "1.0058"], ["84191.4", "0.017314"], ["84184", "0.001333"], ["84172.3", "0"], ["84168.1", "0.118793"], ["84162.7", "0.0016"], ["84160.1", "0"], ["84159.9", "0.039636"], ["84159.1", "0"], ["84158.9", "0.012882"], ["84158", "0.01727"], ["84155.3", "0"], ["84155.2", "0.000333"], ["84155", "0.049551"], ["84152.3", "0.135578"], ["84126.3", "0"], ["84125.8", "0"]], "a": [["84199.1", "0.106837"], ["84201.7", "0.023914"], ["84221.3", "0.010307"], ["84237.3", "0.023754"], ["84237.5", "0.012988"], ["84272.4", "0"], ["84273.1", "0"]], "u": 45306, "seq": 67552587839}, "cts": 1742560343506, "record_time": 1742560343.604643, "EXCHANGE": "BYBIT"}
{"topic": "orderbook.200.BTCUSDT", "ts": 1742560343720, "type": "delta", "data": {"s": "BTCUSDT", "b": [["84199", "1.006448"], ["84193.2", "0"], ["84190.8", "0.0713"], ["84188.5", "0"], ["84160.1", "0.128327"], ["84159.1", "0.012882"], ["84158.9", "0"], ["84152.3", "0.135594"]], "a": [["84220.9", "0.001174"], ["84221.3", "0.009"], ["84272.3", "0"]], "u": 45307, "seq": 67552587919}, "cts": 1742560343706, "record_time": 1742560343.741674, "EXCHANGE": "BYBIT"}
{"topic": "orderbook.200.BTCUSDT", "ts": 1742560343920, "type": "delta", "data": {"s": "BTCUSDT", "b": [["84199", "0.803732"], ["84198.3", "0.045355"], ["84198.1", "0.020542"], ["84192.6", "0.264018"], ["84190.8", "0"], ["84188.4", "0.071302"], ["84186.9", "0"], ["84160", "0.00006"], ["84159.9", "0"], ["84159.7", "0.039637"], ["84159.6", "0.039637"], ["84159.1", "0"], ["84159", "0"], ["84158.7", "0.014215"], ["84158.6", "0.01324"], ["84155.1", "0.001781"], ["84155", "0"], ["84154.8", "0.049552"], ["84154.7", "0.049552"], ["84153.2", "0"], ["84133.4", "19.073875"], ["84126.3", "0.003564"]], "a": [["84199.1", "0.378075"], ["84210", "0.223547"], ["84220.4", "0.001048"], ["84220.9", "0"], ["84238.4", "0.043294"], ["84238.5", "0.04"], ["84238.6", "0"], ["84238.7", "0.001333"], ["84254.8", "2.562085"], ["84257.6", "0"], ["84270.6", "0.04"]], "u": 45308, "seq": 67552588051}, "cts": 1742560343916, "record_time": 1742560343.941556, "EXCHANGE": "BYBIT"}
{"topic": "orderbook.200.BTCUSDT", "ts": 1742560344120, "type": "delta", "data": {"s": "BTCUSDT", "b": [["84192.6", "0.192719"], ["84190.7", "0.0713"], ["84152.3", "0.135598"], ["84126.3", "0"]], "a": [["84207.6", "0.135706"], ["84220.4", "0"], ["84220.5", "0.168537"], ["84223.6", "0.122345"], ["84252", "2.562142"], ["84254.8", "0"], ["84270.4", "0"], ["84272.3", "0.05728"], ["84272.4", "0.001853"]], "u": 45309, "seq": 67552588154}, "cts": 1742560344110, "record_time": 1742560344.139603, "EXCHANGE": "BYBIT"}
{"topic": "orderbook.200.BTCUSDT", "ts": 1742560344320, "type": "delta", "data": {"s": "BTCUSDT", "b": [["84155", "0.049551"], ["84154.9", "0.049551"], ["84154.8", "0"], ["84154.7", "0"], ["84153.2", "18.646907"], ["84133.4", "0"]], "a": [["84214.5", "0.003974"], ["84220.8", "0.001148"], ["84237.2", "0.085938"], ["84272.4", "0"]], "u": 45310, "seq": 67552588252}, "cts": 1742560344313, "record_time": 1742560344.340465, "EXCHANGE": "BYBIT"}
{"topic": "orderbook.200.BTCUSDT", "ts": 1742560344520, "type": "delta", "data": {"s": "BTCUSDT", "b": [["84199", "0.804532"], ["84188.4", "0"], ["84177.1", "0.060245"], ["84171.4", "0.056705"], ["84160.2", "0.04"], ["84160.1", "0.167963"], ["84159.7", "0"], ["84159.6", "0"], ["84155.3", "0.049551"], ["84155.2", "0.049884"], ["84155", "0"], ["84154.9", "0"], ["84126.3", "0.003564"], ["84125.8", "0.000333"], ["84125.1", "0.001333"]], "a": [["84199.1", "0.106837"], ["84207.6", "0.082261"], ["84210", "0.045398"], ["84220.8", "0"], ["84223.6", "0.118793"], ["84237.4", "0"], ["84237.6", "0.183989"], ["84272.4", "0.001853"], ["84273.1", "0.000333"]], "u": 45311, "seq": 67552588440}, "cts": 1742560344513, "record_time": 1742560344.541501, "EXCHANGE": "BYBIT"}
{"topic": "orderbook.200.BTCUSDT", "ts": 1742560344719, "type": "delta", "data": {"s": "BTCUSDT", "b": [["84199", "0.975532"], ["84183.5", "0"], ["84160.2", "0"], ["84160", "0.039696"], ["84156", "18.212595"], ["84155.3", "0"], ["84155.1", "0.051332"], ["84153.2", "0"], ["84125", "0.001466"], ["84124.7", "0.003259"], ["84124.6", "0.02112"]], "a": [["84238.4", "0.003294"], ["84238.6", "0.04"], ["84252", "0"], ["84257.6", "2.562142"], ["84273.1", "0"]], "u": 45312, "seq": 67552588521}, "cts": 1742560344714, "record_time": 1742560344.740654, "EXCHANGE": "BYBIT"}
{"topic": "orderbook.200.BTCUSDT", "ts": 1742560344920, "type": "delta", "data": {"s": "BTCUSDT", "b": [["84124.8", "0.171"], ["84124.6", "0"]], "a": [["84237.5", "0"], ["84237.7", "0.018927"], ["84238.5", "0"], ["84238.7", "0.041333"], ["84254.8", "2.562142"], ["84257.6", "0"], ["84270.4", "0.089075"], ["84273.1", "0.000333"]], "u": 45313, "seq": 67552588608}, "cts": 1742560344899, "record_time": 1742560344.940434, "EXCHANGE": "BYBIT"}
{"topic": "orderbook.200.BTCUSDT", "ts": 1742560345120, "type": "delta", "data": {"s": "BTCUSDT", "b": [["84199", "0.804532"], ["84160.3", "0.04"], ["84160.2", "0.039636"], ["84160.1", "0.128327"], ["84160", "0.00006"], ["84159.3", "0.013"], ["84159.2", "0.012882"], ["84158.7", "0.001333"], ["84158.6", "0.000358"], ["84155.4", "0.05"], ["84155.3", "0.049551"], ["84155.2", "0.000333"], ["84155.1", "0.001781"], ["84152.3", "0.135603"], ["84126.3", "0"], ["84125.8", "0"], ["84125.1", "0"], ["84125", "0"], ["84124.8", "0"], ["84124.7", "0"]], "a": [["84201.7", "0"], ["84220.1", "0.000987"], ["84222", "0.083332"], ["84222.1", "0.035638"], ["84237.5", "0.013"], ["84237.7", "0.005938"], ["84238.5", "0.04"], ["84238.7", "0.001333"], ["84252", "2.562142"], ["84254.8", "0"], ["84270.6", "0.164704"], ["84272.4", "0"], ["84273.1", "0"]], "u": 45314, "seq": 67552588753}, "cts": 1742560345113, "record_time": 1742560345.178318, "EXCHANGE": "BYBIT"}
{"topic": "orderbook.200.BTCUSDT", "ts": 1742560345319, "type": "delta", "data": {"s": "BTCUSDT", "b": [["84199", "0.975532"], ["84194.5", "0.001466"], ["84192.8", "0.071299"], ["84189.8", "0.049466"], ["84184.9", "0.061321"], ["84177.9", "0.054263"], ["84172.6", "0.001065"], ["84170.9", "0.11519"], ["84162.1", "0.206638"], ["84160.3", "0.039636"], ["84159.3", "0.012882"], ["84157.9", "0.005938"], ["84155.4", "0.049551"], ["84155", "0.023753"], ["84154.1", "0.027317"], ["84152.6", "0.023753"], ["84151.8", "0.023753"], ["84149.2", "0.023753"], ["84131.3", "0"], ["84130.1", "0"], ["84130", "0"], ["84129.7", "0"], ["84129.3", "0"], ["84129.2", "0"], ["84128.9", "0"], ["84127.3", "0"], ["84127.2", "0"], ["84127.1", "0"]], "a": [["84199.1", "0.003868"], ["84204.8", "0.000297"], ["84206.4", "0.107087"], ["84206.5", "0.075787"], ["84207.6", "0.000518"], ["84209.7", "0"], ["84213.2", "0"], ["84219.9", "0.061506"], ["84220.1", "0"], ["84225.5", "0.001205"], ["84226.9", "0.062044"], ["84229.3", "0"], ["84233.9", "0.109261"], ["84234.6", "0"], ["84237.5", "0.012989"], ["84238.8", "0.023753"], ["84244.2", "0.023753"], ["84252", "0"], ["84257.6", "2.562142"], ["84272.1", "0"], ["84272.3", "0"]], "u": 45315, "seq": 67552589308}, "cts": 1742560345316, "record_time": 1742560345.3411, "EXCHANGE": "BYBIT"}
{"topic": "orderbook.200.BTCUSDT", "ts": 1742560345519, "type": "delta", "data": {"s": "BTCUSDT", "b": [["84199.1", "0.821146"], ["84199", "0.290405"], ["84198.3", "0"], ["84198.2", "0"], ["84190.7", "0.0863"], ["84190.6", "0"], ["84189.7", "0.160209"], ["84188.1", "0.067829"], ["84184.9", "0"], ["84183.8", "0.0002"], ["84183", "0.056"], ["84182.2", "0"], ["84179.9", "0.186855"], ["84177.9", "0"], ["84177.6", "0.037979"], ["84177.1", "0.004245"], ["84170.9", "0"], ["84170.8", "0.275508"], ["84169.6", "0.178149"], ["84169.4", "0.178149"], ["84167.5", "0"], ["84160.9", "0.029166"], ["84158", "5.620447"], ["84152.3", "0"], ["84135", "0.010994"], ["84131.3", "0.009"]], "a": [["84199.1", "0"], ["84199.2", "0.033378"], ["84203.7", "0.025314"], ["84207.5", "0"], ["84207.6", "0.015518"], ["84214.9", "0.120043"], ["84219.9", "0.178149"], ["84221.5", "0.008564"], ["84222.1", "0"], ["84224.7", "0.165589"], ["84225.5", "0"], ["84226.9", "0.001466"], ["84233.8", "0.306326"], ["84233.9", "0"], ["84237.5", "0"], ["84237.6", "0.183988"], ["84237.7", "0.018927"], ["84270.6", "0.04"], ["84272.1", "0.003292"], ["84272.3", "0.05728"], ["84272.4", "0.001853"]], "u": 45316, "seq": 67552589528}, "cts": 1742560345517, "record_time": 1742560345.540272, "EXCHANGE": "BYBIT"}
{"topic": "orderbook.200.BTCUSDT", "ts": 1742560345720, "type": "delta", "data": {"s": "BTCUSDT", "b": [["84189.7", "0.151416"], ["84185.6", "0.118933"], ["84180.5", "0.107966"], ["84179.9", "0"], ["84179.2", "0.185355"], ["84178.6", "0.216531"], ["84172.2", "0.813463"], ["84171.6", "0.273627"], ["84170.8", "0"], ["84160.3", "0"], ["84160.1", "0.167963"], ["84159.3", "0"], ["84159.1", "0.012882"], ["84156", "17.76968"], ["84155.4", "0.05"]], "a": [["84210", "0.073643"], ["84214.2", "0.109472"], ["84214.9", "0"], ["84218.4", "0.207992"], ["84218.5", "0.228199"], ["84224.7", "0.17092"], ["84225.5", "0.179332"], ["84231.7", "0.274376"], ["84232.5", "0.34091"], ["84233.8", "0"], ["84252", "2.562139"], ["84257.6", "0"]], "u": 45317, "seq": 67552589608}, "cts": 1742560345710, "record_time": 1742560345.741199, "EXCHANGE": "BYBIT"}
{"topic": "orderbook.200.BTCUSDT", "ts": 1742560345920, "type": "delta", "data": {"s": "BTCUSDT", "b": [["84189.8", "0.159083"], ["84189.7", "0.042185"], ["84185.7", "0.120696"], ["84185.6", "0"], ["84180.5", "0.152256"], ["84179.3", "0.164404"], ["84179.2", "0"], ["84178.7", "0.18077"], ["84178.6", "0.049876"], ["84172.3", "0.286805"], ["84172.2", "0.540618"], ["84171.7", "0.28489"], ["84171.6", "0"], ["84160.2", "0.04"], ["84159.2", "0"], ["84159", "0.012882"], ["84156", "0"], ["84155.4", "0"], ["84155.3", "0.05"], ["84155.2", "0.049884"], ["84136.2", "17.76968"], ["84131.3", "0"]], "a": [["84203.7", "0.001466"], ["84210", "0.045398"], ["84214.2", "0.000333"], ["84214.3", "0.112317"], ["84218.5", "0.118793"], ["84218.6", "0.15201"], ["84222.6", "0.159636"], ["84224.7", "0"], ["84224.8", "0.167435"], ["84225.5", "0"], ["84225.6", "0.167027"], ["84231.7", "0"], ["84231.8", "0.315957"], ["84232.5", "0.059377"], ["84232.6", "0.859761"], ["84237.4", "0.012988"], ["84237.5", "0.012988"], ["84237.6", "0.171"], ["84237.7", "0.005938"], ["84238.4", "0.043294"], ["84238.6", "0"], ["84252", "0"], ["84254.8", "2.562139"], ["84272.4", "0"]], "u": 45318, "seq": 67552589728}, "cts": 1742560345918, "record_time": 1742560345.941477, "EXCHANGE": "BYBIT"}
{"topic": "orderbook.200.BTCUSDT", "ts": 1742560346119, "type": "delta", "data": {"s": "BTCUSDT", "b": [["84199.1", "0.652527"], ["84199", "0.119405"], ["84160.2", "0"], ["84160", "0.039696"], ["84158", "0.152873"], ["84155.3", "0"], ["84155.1", "0.049551"], ["84136.2", "0"], ["84133.4", "17.76968"], ["84131.3", "0.009"], ["84130.1", "3.358693"]], "a": [["84237.3", "0.036754"], ["84237.5", "0"], ["84238.3", "0.04"], ["84238.5", "0"], ["84252", "2.562139"], ["84254.8", "0"], ["84272.4", "0.001853"]], "u": 45319, "seq": 67552589770}, "cts": 1742560346113, "record_time": 1742560346.227992, "EXCHANGE": "BYBIT"}
{"topic": "orderbook.200.BTCUSDT", "ts": 1742560346320, "type": "delta", "data": {"s": "BTCUSDT", "b": [["84199.1", "0.650746"], ["84199", "0.120121"], ["84189.8", "0.049466"], ["84185.7", "0"], ["84179.3", "0"], ["84178.7", "0"], ["84176.2", "0"], ["84173.3", "0"], ["84172.3", "0"], ["84171.7", "0"], ["84160.1", "0.128327"], ["84160", "0.00006"], ["84159.7", "0.039637"], ["84159.6", "0.039637"], ["84159.1", "0"], ["84159", "0"], ["84158.7", "0.014215"], ["84158.6", "0.01324"], ["84155.9", "0.001781"], ["84155.2", "0.050333"], ["84134.9", "0.079756"], ["84130", "0.000333"], ["84129.7", "0.001466"], ["84129.3", "0.001333"], ["84129.2", "0.00009"], ["84128.9", "0.003777"], ["84127.2", "0.235392"]], "a": [["84199.2", "0.133378"], ["84204.1", "0.02362"], ["84204.8", "0.025498"], ["84214.3", "0"], ["84218.6", "0.04"], ["84224.8", "0"], ["84225.6", "0"], ["84231.8", "0.003564"], ["84232.6", "0.551103"], ["84237.3", "0.036742"], ["84273.1", "0.000333"], ["84273.2", "0.001466"]], "u": 45320, "seq": 67552589864}, "cts": 1742560346316, "record_time": 1742560346.33999, "EXCHANGE": "BYBIT"}
{"topic": "orderbook.200.BTCUSDT", "ts": 1742560346520, "type": "delta", "data": {"s": "BTCUSDT", "b": [["84192.8", "0"], ["84192.7", "0.071299"], ["84190.7", "0.015"], ["84188.4", "0.071302"], ["84180.5", "0.060107"], ["84171.3", "0.026165"], ["84160.7", "0.051883"], ["84160.6", "0.039636"], ["84159.7", "0.013"], ["84159.6", "0.012882"], ["84158.7", "0.001333"], ["84158.6", "0.000358"], ["84155.8", "0.05"], ["84155.7", "0.069493"], ["84155.2", "0.000333"], ["84155.1", "0"], ["84128.9", "0"], ["84127.2", "0"]], "a": [["84199.2", "0.375671"], ["84215.9", "0.178114"], ["84219.4", "0.178106"], ["84222.6", "0.000333"], ["84234.3", "0.013"], ["84234.4", "0.012988"], ["84235.3", "0.04"], ["84235.4", "0.040518"], ["84237.3", "0.023754"], ["84237.4", "0"], ["84238.3", "0"], ["84238.4", "0.003294"], ["84272.4", "0"], ["84273.1", "0"], ["84273.2", "0"]], "u": 45321, "seq": 67552589981}, "cts": 1742560346514, "record_time": 1742560346.540324, "EXCHANGE": "BYBIT"}
{"topic": "orderbook.200.BTCUSDT", "ts": 1742560346720, "type": "delta", "data": {"s": "BTCUSDT", "b": [["84199.1", "0.651546"], ["84199", "0.114535"], ["84171.4", "0.166719"], ["84169.6", "0"], ["84169.4", "0"], ["84165.2", "0"], ["84160.7", "0.051519"], ["84159.7", "0.012882"], ["84158", "0.152876"], ["84155.9", "0.051781"], ["84155.8", "0.04955"], ["84155.7", "0.019942"], ["84128.9", "0.003777"], ["84127.2", "0.235392"], ["84127.1", "0.118793"]], "a": [["84234.3", "0"], ["84234.4", "0"], ["84234.5", "0.014321"], ["84234.6", "0.012988"], ["84235.3", "0"], ["84235.4", "0.000518"], ["84235.5", "0.04"], ["84235.6", "0.04"]], "u": 45322, "seq": 67552590085}, "cts": 1742560346713, "record_time": 1742560346.756249, "EXCHANGE": "BYBIT"}
{"topic": "orderbook.200.BTCUSDT", "ts": 1742560346920, "type": "delta", "data": {"s": "BTCUSDT", "b": [["84187.7", "0.019942"], ["84171.4", "0"], ["84168", "0.085224"], ["84160.7", "0.011883"], ["84160.6", "0"], ["84160.3", "0.039636"], ["84160.2", "0.039636"], ["84159.7", "0"], ["84159.6", "0"], ["84159.3", "0.012882"], ["84159.2", "0.012882"], ["84155.9", "0.001781"], ["84155.8", "0"], ["84155.5", "0.049551"], ["84155.4", "0.049551"], ["84127.1", "0"]], "a": [["84216.8", "0.000818"], ["84217.9", "0"], ["84219.4", "0"], ["84222", "0.083859"], ["84234.5", "0.001333"], ["84234.7", "0.131781"], ["84235.5", "0"], ["84235.7", "0.04"], ["84272.4", "0.001853"], ["84273.1", "0.000333"]], "u": 45323, "seq": 67552590191}, "cts": 1742560346917, "record_time": 1742560346.94035, "EXCHANGE": "BYBIT"}
{"topic": "orderbook.200.BTCUSDT", "ts": 1742560347119, "type": "delta", "data": {"s": "BTCUSDT", "b": [["84160.4", "0.039636"], ["84160.2", "0"], ["84159.4", "0.013215"], ["84159.2", "0"], ["84133.4", "0"], ["84131.1", "0.235392"], ["84130.6", "17.566307"], ["84127.2", "0"], ["84127.1", "0.118793"]], "a": [["84219.9", "0"], ["84221.5", "0.003812"], ["84234.3", "0.012988"], ["84234.4", "0.012988"], ["84234.6", "0"], ["84234.7", "0.118793"], ["84235.3", "0.04"], ["84235.4", "0.040518"], ["84235.6", "0"], ["84235.7", "0"], ["84270.4", "0"], ["84273.2", "0.001466"], ["84274.2", "0.04"]], "u": 45324, "seq": 67552590265}, "cts": 1742560347116, "record_time": 1742560347.140343, "EXCHANGE": "BYBIT"}
{"topic": "orderbook.200.BTCUSDT", "ts": 1742560347320, "type": "delta", "data": {"s": "BTCUSDT", "b": [["84199.1", "0.624773"], ["84172.6", "0"], ["84168.1", "0"], ["84165.2", "0.178149"], ["84126.3", "0.003564"]], "a": [["84216.8", "0.004369"], ["84222.1", "0.035638"], ["84234.3", "0"], ["84234.5", "0.014321"], ["84235.3", "0"], ["84235.5", "0.04"], ["84237.1", "0.06346"], ["84239.9", "0.059399"], ["84274.2", "0"]], "u": 45325, "seq": 67552590471}, "cts": 1742560347316, "record_time": 1742560347.343317, "EXCHANGE": "BYBIT"}
{"topic": "orderbook.200.BTCUSDT", "ts": 1742560347519, "type": "delta", "data": {"s": "BTCUSDT", "b": [["84199.1", "0.655415"], ["84158", "0.01727"], ["84155.2", "0.13595"]], "a": [["84199.2", "0.204671"], ["84223.5", "0.061308"], ["84234.4", "0"], ["84234.5", "0.001333"], ["84234.6", "0.012988"], ["84234.7", "0.131781"], ["84235.4", "0.000518"], ["84235.5", "0"], ["84235.6", "0.04"], ["84235.7", "0.04"], ["84237.1", "0"], ["84239.9", "0.122859"], ["84273.2", "0"]], "u": 45326, "seq": 67552590565}, "cts": 1742560347516, "record_time": 1742560347.539742, "EXCHANGE": "BYBIT"}
{"topic": "orderbook.200.BTCUSDT", "ts": 1742560347720, "type": "delta", "data": {"s": "BTCUSDT", "b": [["84160.7", "0.051519"], ["84160.6", "0.039636"], ["84160.4", "0"], ["84160.3", "0"], ["84155.9", "0.051781"], ["84155.8", "0.04955"], ["84155.5", "0"], ["84155.4", "0"], ["84133.4", "17.35629"], ["84130.6", "0"], ["84125.8", "0.000333"], ["84125.1", "0.001333"]], "a": [["84219.9", "0.178149"], ["84221.7", "0.035864"], ["84222", "0.04"], ["84234.6", "0"], ["84234.7", "0.118793"], ["84234.8", "0.012988"], ["84234.9", "0.012988"], ["84235.6", "0"], ["84235.8", "0.04"], ["84244.8", "0.022834"], ["84251.6", "0"], ["84272.3", "0"], ["84272.4", "0"], ["84273.1", "0"]], "u": 45327, "seq": 67552590675}, "cts": 1742560347707, "record_time": 1742560347.799363, "EXCHANGE": "BYBIT"}
{"topic": "orderbook.200.BTCUSDT", "ts": 1742560347919, "type": "delta", "data": {"s": "BTCUSDT", "b": [["84199", "0.113887"], ["84187.9", "0.120963"], ["84177.4", "0.184386"], ["84170.4", "0.297778"], ["84168", "0.203344"], ["84159.7", "0.012882"], ["84159.6", "0.012882"], ["84159.4", "0.000333"], ["84159.3", "0"], ["84155.9", "0.001781"], ["84155.7", "0.069493"], ["84127.1", "0"], ["84126.3", "0"], ["84125.8", "0"], ["84125.1", "0"]], "a": [["84210", "0.078447"], ["84212.4", "0.125153"], ["84216.8", "0.000818"], ["84222.9", "0.174787"], ["84229.9", "0.292784"], ["84234.5", "0.014333"], ["84234.6", "0.012988"], ["84234.8", "0"], ["84234.9", "0"], ["84272.1", "0"]], "u": 45328, "seq": 67552590752}, "cts": 1742560347913, "record_time": 1742560347.942942, "EXCHANGE": "BYBIT"}
{"topic": "orderbook.200.BTCUSDT", "ts": 1742560348120, "type": "delta", "data": {"s": "BTCUSDT", "b": [["84180.5", "0.107951"]], "a": [["84220.7", "0.035864"], ["84221.7", "0"], ["84234.5", "0.001333"], ["84234.6", "0"], ["84234.7", "0.131781"], ["84234.8", "0.012992"], ["84252", "0"], ["84254.8", "2.562139"]], "u": 45329, "seq": 67552590812}, "cts": 1742560348106, "record_time": 1742560348.141014, "EXCHANGE": "BYBIT"}
{"topic": "orderbook.200.BTCUSDT", "ts": 1742560348319, "type": "delta", "data": {"s": "BTCUSDT", "b": [["84199.1", "0.655579"], ["84187.9", "0.116453"], ["84177.4", "0.176569"], ["84170.4", "0.309489"], ["84160.7", "0.011883"], ["84160.6", "0"], ["84160.4", "0.039636"], ["84160.3", "0.039636"], ["84159.7", "0"], ["84159.6", "0"], ["84159.4", "0.013215"], ["84159.3", "0.012882"], ["84155.8", "0"], ["84155.7", "0.019942"], ["84155.6", "0.05"], ["84155.5", "0.049551"], ["84128.9", "0"]], "a": [["84199.2", "0.374798"], ["84210", "0.077486"], ["84212.4", "0.121951"], ["84221.8", "0.014411"], ["84222.9", "0.176527"], ["84229.9", "0.308017"], ["84234.5", "0.014333"], ["84234.6", "0.012992"], ["84234.7", "0.118793"], ["84234.8", "0"], ["84235.5", "0.04"], ["84235.6", "0.04"], ["84235.7", "0"], ["84235.8", "0"], ["84252", "2.562139"], ["84254.8", "0"], ["84271.6", "0"]], "u": 45330, "seq": 67552590893}, "cts": 1742560348315, "record_time": 1742560348.339413, "EXCHANGE": "BYBIT"}
{"topic": "orderbook.200.BTCUSDT", "ts": 1742560348519, "type": "delta", "data": {"s": "BTCUSDT", "b": [["84199.1", "0.654951"], ["84187.9", "0.117872"], ["84183.8", "0.116847"], ["84177.4", "0.175388"], ["84176.8", "0.219374"], ["84170.4", "0.303194"], ["84169.8", "0.355746"], ["84155.6", "0"], ["84155.4", "0.049551"]], "a": [["84199.2", "0.203798"], ["84210", "0.076809"], ["84212.4", "0.119694"], ["84216.7", "0.11821"], ["84222.8", "0.114266"], ["84222.9", "0.171028"], ["84223.5", "0"], ["84223.7", "0.22078"], ["84229.9", "0.293592"], ["84230.7", "0.273565"], ["84252", "0"]], "u": 45331, "seq": 67552591019}, "cts": 1742560348517, "record_time": 1742560348.542851, "EXCHANGE": "BYBIT"}
{"topic": "orderbook.200.BTCUSDT", "ts": 1742560348719, "type": "delta", "data": {"s": "BTCUSDT", "b": [["84199.1", "0.656732"], ["84180.5", "0.15012"], ["84155.9", "0"], ["84128.9", "0.003777"]], "a": [["84215.5", "0.160194"], ["84234.3", "0.012992"], ["84234.4", "0.012992"], ["84234.5", "0.001333"], ["84234.6", "0"], ["84235.3", "0.04"], ["84235.4", "0.040518"], ["84235.5", "0"], ["84235.6", "0"], ["84252", "2.562139"], ["84271.3", "0"]], "u": 45332, "seq": 67552591081}, "cts": 1742560348703, "record_time": 1742560348.739588, "EXCHANGE": "BYBIT"}
{"topic": "orderbook.200.BTCUSDT", "ts": 1742560348920, "type": "delta", "data": {"s": "BTCUSDT", "b": [["84187.9", "0"], ["84183.8", "0.0002"], ["84177.4", "0"], ["84176.8", "0.049876"], ["84170.4", "0"], ["84169.8", "0.07296"], ["84160.5", "0.04"], ["84160.3", "0"], ["84159.5", "0.013"], ["84159.3", "0"], ["84155.6", "0.05"], ["84155.4", "0"], ["84127.1", "0.118793"], ["84126.3", "0.003564"], ["84125.8", "0.000333"]], "a": [["84203.6", "0.003551"], ["84210", "0.045398"], ["84212.4", "0"], ["84216.7", "0"], ["84222.9", "0"], ["84223.7", "0.04"], ["84229.9", "0.003293"], ["84230.7", "0.000518"], ["84252", "0"], ["84254.8", "2.562139"], ["84271.3", "0.12"], ["84272.1", "0.003292"]], "u": 45333, "seq": 67552591138}, "cts": 1742560348918, "record_time": 1742560348.945033, "EXCHANGE": "BYBIT"}
{"topic": "orderbook.200.BTCUSDT", "ts": 1742560349119, "type": "delta", "data": {"s": "BTCUSDT", "b": [["84180.5", "0.060107"], ["84160.5", "0"], ["84160.3", "0.039636"], ["84159.5", "0"], ["84159.3", "0.012882"], ["84155.6", "0"], ["84155.4", "0.049551"]], "a": [["84199.2", "0.374798"], ["84222.8", "0"], ["84234.3", "0"], ["84234.5", "0.014325"], ["84235.3", "0"], ["84235.5", "0.04"], ["84237.1", "0.06346"], ["84239.9", "0.059399"], ["84252", "2.562139"], ["84254.8", "0"], ["84271.6", "0.171"]], "u": 45334, "seq": 67552591222}, "cts": 1742560349116, "record_time": 1742560349.139559, "EXCHANGE": "BYBIT"}
{"topic": "orderbook.200.BTCUSDT", "ts": 1742560349320, "type": "delta", "data": {"s": "BTCUSDT", "b": [["84171.4", "0.03128"], ["84160.4", "0"], ["84160.2", "0.039636"], ["84159.5", "0.013"], ["84159.3", "0"], ["84155.6", "0.05"], ["84155.4", "0"], ["84125.8", "0"]], "a": [["84234.3", "0.013"], ["84234.4", "0.012994"], ["84234.5", "0.001333"], ["84235.4", "0.000518"], ["84235.5", "0"], ["84235.6", "0.04"], ["84235.7", "0.04"], ["84271.1", "0"], ["84272.1", "0"]], "u": 45335, "seq": 67552591293}, "cts": 1742560349316, "record_time": 1742560349.375129, "EXCHANGE": "BYBIT"}
{"topic": "orderbook.200.BTCUSDT", "ts": 1742560349520, "type": "delta", "data": {"s": "BTCUSDT", "b": [["84160.5", "0.04"], ["84160.4", "0.039636"], ["84160.3", "0"], ["84160.2", "0"]], "a": [["84221.8", "0"], ["84234.1", "0.013"], ["84234.2", "0.016287"], ["84234.3", "0"], ["84234.4", "0"], ["84235.1", "0.04"], ["84235.2", "0.040333"], ["84235.6", "0"], ["84235.7", "0"], ["84272.1", "0.003292"], ["84272.3", "0.05728"], ["84272.4", "0.001853"]], "u": 45336, "seq": 67552591360}, "cts": 1742560349516, "record_time": 1742560349.542006, "EXCHANGE": "BYBIT"}
{"topic": "orderbook.200.BTCUSDT", "ts": 1742560349720, "type": "delta", "data": {"s": "BTCUSDT", "b": [], "a": [["84203.6", "0"], ["84216.2", "0.003551"], ["84219.6", "0.003"], ["84223.5", "0.061308"], ["84235.1", "0"], ["84235.2", "0.000333"], ["84235.3", "0.04"], ["84235.4", "0.040518"], ["84240.1", "0.003"], ["84272.1", "0"], ["84272.3", "0"], ["84272.4", "0"]], "u": 45337, "seq": 67552591419}, "cts": 1742560349714, "record_time": 1742560349.742139, "EXCHANGE": "BYBIT"}
{"topic": "orderbook.200.BTCUSDT", "ts": 1742560349919, "type": "delta", "data": {"s": "BTCUSDT", "b": [["84160.5", "0"], ["84160.3", "0.039636"], ["84159.5", "0"], ["84159.3", "0.012882"], ["84155.6", "0"], ["84155.4", "0.049551"]], "a": [["84234.1", "0"], ["84234.2", "0.003293"], ["84234.5", "0.014333"], ["84234.6", "0.012994"], ["84235.3", "0"], ["84235.4", "0.000518"], ["84235.5", "0.04"], ["84235.6", "0.04"], ["84271.6", "0"]], "u": 45338, "seq": 67552591483}, "cts": 1742560349916, "record_time": 1742560349.939572, "EXCHANGE": "BYBIT"}
{"topic": "orderbook.200.BTCUSDT", "ts": 1742560350120, "type": "delta", "data": {"s": "BTCUSDT", "b": [["84187.9", "0.117566"], ["84183.8", "0.120485"], ["84177.4", "0.180324"], ["84176.8", "0.2256"], ["84170.4", "0.276468"], ["84169.8", "0.360612"], ["84159.5", "0.013"], ["84159.3", "0"], ["84155.6", "0.05"], ["84155.4", "0"], ["84128.9", "0"], ["84127.1", "0"], ["84126.3", "0"]], "a": [["84199.2", "0.203798"], ["84210", "0.075895"], ["84212.4", "0.116646"], ["84216.7", "0.110713"], ["84220.7", "0.035317"], ["84222.9", "0.163903"], ["84223.7", "0.209405"], ["84229.9", "0.306292"], ["84230.7", "0.273899"], ["84234.4", "0.013"], ["84234.5", "0.014327"], ["84234.6", "0"], ["84271", "0"], ["84271.2", "0"], ["84271.3", "0"]], "u": 45339, "seq": 67552591570}, "cts": 1742560350114, "record_time": 1742560350.14242, "EXCHANGE": "BYBIT"}
{"topic": "orderbook.200.BTCUSDT", "ts": 1742560350320, "type": "delta", "data": {"s": "BTCUSDT", "b": [["84199.1", "0.657332"], ["84180.5", "0.159449"], ["84160.7", "0.051519"], ["84160.6", "0.039636"], ["84160.4", "0"], ["84160.3", "0"], ["84159.7", "0.012882"], ["84159.6", "0.012882"], ["84159.5", "0"], ["84159.4", "0.000333"], ["84155.8", "0.04955"], ["84155.7", "0.069493"], ["84155.6", "0"], ["84155.5", "0"], ["84128.9", "0.003777"]], "a": [["84234.4", "0"], ["84234.6", "0.012994"]], "u": 45340, "seq": 67552591644}, "cts": 1742560350316, "record_time": 1742560350.422537, "EXCHANGE": "BYBIT"}
{"topic": "orderbook.200.BTCUSDT", "ts": 1742560350519, "type": "delta", "data": {"s": "BTCUSDT", "b": [["84199.1", "0.828332"], ["84187.9", "0"], ["84183.8", "0.0002"], ["84177.4", "0"], ["84176.8", "0.049876"], ["84171.4", "0.196606"], ["84170.4", "0"], ["84169.8", "0.07296"], ["84127.1", "0.118793"], ["84126.3", "0.003564"], ["84125.8", "0.000333"]], "a": [["84199.2", "0.103798"], ["84210", "0.045398"], ["84212.4", "0"], ["84216.2", "0"], ["84216.7", "0"], ["84222.9", "0"], ["84223.7", "0.04"], ["84229.9", "0.003293"], ["84230.7", "0.000518"], ["84271", "0.237586"], ["84271.2", "0.12"], ["84271.3", "0.12"], ["84272.1", "0.003292"]], "u": 45341, "seq": 67552591740}, "cts": 1742560350517, "record_time": 1742560350.540259, "EXCHANGE": "BYBIT"}
{"topic": "orderbook.200.BTCUSDT", "ts": 1742560350720, "type": "delta", "data": {"s": "BTCUSDT", "b": [["84180.5", "0.060107"], ["84171.4", "0.03128"]], "a": [["84204.8", "0"], ["84220.6", "0.035317"], ["84220.7", "0"], ["84222.3", "0.003551"], ["84234.5", "0.001333"], ["84234.6", "0"], ["84234.7", "0.131787"], ["84234.8", "0.012994"], ["84235.5", "0"], ["84235.6", "0"], ["84235.7", "0.04"], ["84235.8", "0.04"], ["84271.6", "0.171"], ["84272.1", "0"]], "u": 45342, "seq": 67552591808}, "cts": 1742560350709, "record_time": 1742560350.741294, "EXCHANGE": "BYBIT"}
{"topic": "orderbook.200.BTCUSDT", "ts": 1742560350919, "type": "delta", "data": {"s": "BTCUSDT", "b": [], "a": [["84234.7", "0.118793"], ["84234.9", "0.012994"], ["84235.7", "0"], ["84235.9", "0.063754"]], "u": 45343, "seq": 67552591848}, "cts": 1742560350899, "record_time": 1742560350.94586, "EXCHANGE": "BYBIT"}
{"topic": "orderbook.200.BTCUSDT", "ts": 1742560351120, "type": "delta", "data": {"s": "BTCUSDT", "b": [["84199.1", "0.657332"]], "a": [["84220.6", "0"], ["84220.7", "0.035844"], ["84222.3", "0"], ["84234.7", "0.131793"], ["84234.9", "0"], ["84272.1", "0.003292"], ["84272.3", "0.05728"]], "u": 45344, "seq": 67552591913}, "cts": 1742560351113, "record_time": 1742560351.147608, "EXCHANGE": "BYBIT"}
{"topic": "orderbook.200.BTCUSDT", "ts": 1742560351320, "type": "delta", "data": {"s": "BTCUSDT", "b": [["84199.1", "0.655551"], ["84187.3", "0.114723"], ["84183.2", "0.114556"], ["84176.8", "0.236698"], ["84176.2", "0.165723"], ["84169.8", "0.348271"], ["84169.2", "0.299799"], ["84160.7", "0.011883"], ["84160.6", "0"], ["84160.5", "0.039636"], ["84160.4", "0.039636"], ["84159.7", "0"], ["84159.6", "0"], ["84159.5", "0.012882"], ["84159.4", "0.013215"], ["84156.2", "0.001781"], ["84155.8", "0"], ["84155.7", "0.019942"], ["84155.6", "0.049551"], ["84155.5", "0.049551"], ["84129.3", "0"], ["84129.2", "0"], ["84128.9", "0"], ["84127.1", "0"], ["84126.3", "0"], ["84125.8", "0"]], "a": [["84199.2", "0.274798"], ["84210", "0.077503"], ["84211.8", "0.122005"], ["84216.1", "0.116929"], ["84222.3", "0.183187"], ["84223.1", "0.171232"], ["84229.3", "0.310775"], ["84230.1", "0.289363"], ["84234.5", "0.014327"], ["84234.6", "0.012994"], ["84234.7", "0.118793"], ["84234.8", "0"], ["84235.5", "0.04"], ["84235.6", "0.04"], ["84235.8", "0"], ["84235.9", "0.023754"], ["84270.9", "0"], ["84271", "0"], ["84271.2", "0"], ["84271.3", "0"], ["84271.6", "0"], ["84272.1", "0"], ["84272.3", "0"]], "u": 45345, "seq": 67552591992}, "cts": 1742560351314, "record_time": 1742560351.340366, "EXCHANGE": "BYBIT"}
{"topic": "orderbook.200.BTCUSDT", "ts": 1742560351520, "type": "delta", "data": {"s": "BTCUSDT", "b": [["84187.3", "0.109263"], ["84183.2", "0.111968"], ["84180.5", "0.108682"], ["84176.8", "0.219033"], ["84176.2", "0.175875"], ["84169.8", "0.374712"], ["84169.2", "0.282167"], ["84155.7", "0.069942"], ["84155.5", "0"], ["84129.3", "0.001333"]], "a": [["84199.2", "0.103798"], ["84210", "0.045398"], ["84211.8", "0.123969"], ["84216.1", "0.109753"], ["84218.8", "0.096427"], ["84222.3", "0.166573"], ["84223.1", "0.181484"], ["84227.3", "0.273512"], ["84229.3", "0.274609"], ["84230.1", "0.307982"], ["84234.3", "0.012994"], ["84234.4", "0.012994"], ["84234.5", "0.001333"], ["84234.6", "0"], ["84235.3", "0.04"], ["84235.4", "0.040518"], ["84235.5", "0"], ["84235.6", "0"], ["84270.6", "0"]], "u": 45346, "seq": 67552592100}, "cts": 1742560351516, "record_time": 1742560351.540074, "EXCHANGE": "BYBIT"}
{"topic": "orderbook.200.BTCUSDT", "ts": 1742560351720, "type": "delta", "data": {"s": "BTCUSDT", "b": [["84187.3", "0"], ["84183.2", "0"], ["84176.8", "0.049876"], ["84176.2", "0"], ["84171.4", "0.202546"], ["84169.8", "0.07296"], ["84169.2", "0"], ["84155.7", "0.019942"], ["84155.5", "0.049551"], ["84129.2", "0.00009"], ["84128.9", "0.003777"], ["84127.1", "0.118793"]], "a": [["84211.8", "0"], ["84216.1", "0"], ["84218.4", "0.287475"], ["84222.3", "0"], ["84223.1", "0"], ["84229.3", "0"], ["84230.1", "0"], ["84240.1", "0"], ["84270.6", "0.04"], ["84270.9", "0.04"], ["84271", "0.237586"], ["84271.2", "0.12"], ["84271.3", "0.12"], ["84272.1", "0.003292"], ["84272.3", "0.05728"]], "u": 45347, "seq": 67552592177}, "cts": 1742560351716, "record_time": 1742560351.744365, "EXCHANGE": "BYBIT"}
{"topic": "orderbook.200.BTCUSDT", "ts": 1742560351919, "type": "delta", "data": {"s": "BTCUSDT", "b": [["84199.1", "0.657332"], ["84180.5", "0.060107"], ["84171.4", "0.03128"], ["84156.2", "0"], ["84155.8", "0.04955"], ["84155.7", "0.069493"], ["84155.6", "0"], ["84155.5", "0"], ["84126.3", "0.003564"], ["84125.8", "0.000333"]], "a": [["84227.3", "0.099807"], ["84234.3", "0"], ["84234.4", "0"], ["84234.5", "0.014327"], ["84234.6", "0.012994"], ["84235.3", "0"], ["84235.4", "0.000518"], ["84235.5", "0.04"], ["84235.6", "0.04"], ["84271.6", "0.171"], ["84272.3", "0"]], "u": 45348, "seq": 67552592243}, "cts": 1742560351913, "record_time": 1742560351.993398, "EXCHANGE": "BYBIT"}
{"topic": "orderbook.200.BTCUSDT", "ts": 1742560352120, "type": "delta", "data": {"s": "BTCUSDT", "b": [["84199.1", "0.617332"], ["84159.7", "0.012882"], ["84159.6", "0.012882"], ["84159.5", "0"], ["84159.4", "0.000333"], ["84125.8", "0"]], "a": [["84199.2", "0.10362"], ["84234.5", "0.001333"], ["84234.7", "0.131787"], ["84235.5", "0"], ["84235.7", "0.04"]], "u": 45349, "seq": 67552592284}, "cts": 1742560352117, "record_time": 1742560352.142171, "EXCHANGE": "BYBIT"}
{"topic": "orderbook.200.BTCUSDT", "ts": 1742560352320, "type": "delta", "data": {"s": "BTCUSDT", "b": [["84199.1", "0.828332"]], "a": [], "u": 45350, "seq": 67552592333}, "cts": 1742560352317, "record_time": 1742560352.341059, "EXCHANGE": "BYBIT"}
{"topic": "orderbook.200.BTCUSDT", "ts": 1742560352520, "type": "delta", "data": {"s": "BTCUSDT", "b": [["84199.1", "0.657332"], ["84160.5", "0"], ["84160.3", "0.039636"], ["84159.7", "0"], ["84159.6", "0"], ["84159.4", "0.013215"], ["84159.3", "0.012882"], ["84155.8", "0"], ["84155.7", "0.019942"], ["84155.5", "0.049551"], ["84155.4", "0.049551"]], "a": [["84234.2", "0.016287"], ["84234.3", "0.012994"], ["84234.6", "0"], ["84234.7", "0.118793"]], "u": 45351, "seq": 67552592392}, "cts": 1742560352513, "record_time": 1742560352.539738, "EXCHANGE": "BYBIT"}
{"topic": "orderbook.200.BTCUSDT", "ts": 1742560352719, "type": "delta", "data": {"s": "BTCUSDT", "b": [["84199.1", "0.655551"], ["84199", "0.135089"], ["84195.4", "0.005956"], ["84194.5", "0.072763"], ["84188.4", "0"], ["84158", "0.035931"], ["84156.4", "0.001781"], ["84126.3", "0"]], "a": [["84199.2", "0.37462"], ["84202.9", "0.006437"], ["84203.5", "0.07129"], ["84206.5", "0.0045"], ["84220.7", "0"], ["84221", "0.038136"], ["84234.2", "0.003293"], ["84234.4", "0.012994"], ["84271.6", "0"], ["84272.1", "0"]], "u": 45352, "seq": 67552592488}, "cts": 1742560352713, "record_time": 1742560352.739887, "EXCHANGE": "BYBIT"}
{"topic": "orderbook.200.BTCUSDT", "ts": 1742560352919, "type": "delta", "data": {"s": "BTCUSDT", "b": [["84194.5", "0.001466"], ["84194.2", "0.071297"], ["84192.7", "0"], ["84190.2", "0.071301"], ["84127.1", "0"]], "a": [["84234.3", "0"], ["84234.5", "0.014327"], ["84272.1", "0.003292"]], "u": 45353, "seq": 67552592568}, "cts": 1742560352913, "record_time": 1742560352.940168, "EXCHANGE": "BYBIT"}
{"topic": "orderbook.200.BTCUSDT", "ts": 1742560353119, "type": "delta", "data": {"s": "BTCUSDT", "b": [["84171.1", "0.023753"], ["84160.4", "0"], ["84160.2", "0.039636"], ["84159.4", "0.000333"], ["84159.2", "0.012882"], ["84129.2", "0"], ["84128.9", "0"]], "a": [["84199.2", "0.20362"], ["84203.4", "0.055399"], ["84221", "0"], ["84221.8", "0.014411"], ["84222.4", "0.046809"], ["84234.4", "0"], ["84234.5", "0.001333"], ["84234.7", "0.131787"], ["84234.8", "0.012994"], ["84235.6", "0"], ["84235.8", "0.04"], ["84271.3", "0"], ["84272.1", "0"]], "u": 45354, "seq": 67552592649}, "cts": 1742560353113, "record_time": 1742560353.140246, "EXCHANGE": "BYBIT"}
{"success": true, "ret_msg": "subscribe", "conn_id": "690955ea-27f4-4577-ac9e-805817596691", "op": "subscribe", "record_time": 1742560772.573014, "EXCHANGE": "BYBIT"}
