{"topic": "orderbook.200.BTCUSDT", "ts": 1742142246010, "type": "delta", "data": {"s": "BTCUSDT", "b": [["84375.19", "0.152702"], ["84374.39", "0.005"], ["84373.59", "0.017526"], ["84373.58", "0.00567"], ["84369.37", "0.005634"], ["84369.19", "0.0192"], ["84368.7", "0"], ["84368.54", "0.005993"], ["84367.84", "0.001333"], ["84367.81", "0.001467"], ["84367.79", "0.000612"], ["84367.64", "0.000252"], ["84366.87", "0.0002"], ["84365.92", "0.000234"], ["84365.74", "0"], ["84365.4", "0.000234"], ["84363.53", "0.121051"], ["84361.82", "0.059045"], ["84361.8", "0.000089"], ["84361.6", "0.10571"], ["84360.96", "0.059948"], ["84360.94", "0"], ["84360.93", "0.162"], ["84360.37", "0"], ["84359.41", "0.000296"], ["84359.39", "0"], ["84358.99", "0.041212"], ["84358.98", "0"], ["84358.67", "0.068395"], ["84357.71", "0"], ["84355.86", "0.015736"], ["84354.71", "0.011852"], ["84354.21", "0.000448"], ["84354", "0.261663"], ["84353.75", "0.062947"], ["84353.36", "0"], ["84353.24", "0.181148"], ["84353", "0"], ["84351.77", "0.059948"], ["84351.28", "0.089922"], ["84350.92", "0.000613"], ["84350.91", "0.256608"], ["84350.9", "0.04"], ["84350.51", "0"], ["84350.46", "0"], ["84349.75", "0"], ["84346.36", "0"], ["84344.99", "0"], ["84344.88", "0.297102"], ["84344.65", "0.118519"], ["84342.68", "0"], ["84342.15", "0"], ["84338.99", "0.071147"], ["84338", "0"], ["84336.97", "0.0001"], ["84336.63", "0"], ["84333.78", "0"], ["84332.32", "0"], ["84332.26", "0"], ["84332.15", "0.17779"], ["84331.08", "0"], ["84329.72", "0.017778"], ["84328.82", "0.000089"], ["84325.51", "0.237128"], ["84324.73", "0"], ["84323.56", "0"], ["84322.3", "0.355601"], ["84321.19", "0.04"], ["84321.18", "0.039645"], ["84319.56", "0.237128"], ["84319.55", "0.000089"], ["84318.6", "0"], ["84318.5", "0"], ["84317.23", "0"], ["84317.19", "0"], ["84317.13", "0"], ["84316.97", "0"], ["84316.78", "0"], ["84316.61", "0"], ["84316.32", "0"], ["84316.26", "0"], ["84316.1", "0"], ["84314.94", "0"], ["84314.9", "0"]], "a": [["84369.38", "0"], ["84369.4", "0"], ["84370.04", "0"], ["84370.21", "0"], ["84370.45", "0"], ["84370.56", "0"], ["84371.93", "0"], ["84372.01", "0"], ["84372.05", "0"], ["84372.28", "0"], ["84372.45", "0"], ["84373", "0"], ["84373.45", "0"], ["84373.59", "0"], ["84374.44", "0"], ["84374.46", "0"], ["84374.68", "0"], ["84374.7", "0"], ["84376.12", "0"], ["84377.36", "0"], ["84377.37", "0"], ["84378.19", "0"], ["84379.58", "0"], ["84379.97", "0"], ["84381.54", "0"], ["84382.79", "0"], ["84384.3", "0"], ["84384.71", "0.001333"], ["84386.25", "0"], ["84386.48", "0"], ["84388.01", "0"], ["84388.87", "0"], ["84389.2", "0"], ["84389.69", "0"], ["84389.72", "0.011851"], ["84389.82", "0"], ["84390.05", "0"], ["84390.7", "0.056"], ["84391.25", "0"], ["84392.09", "0"], ["84392.37", "0"], ["84392.55", "0.112246"], ["84392.67", "0"], ["84394.05", "0"], ["84394.32", "0.108796"], ["84394.49", "0"], ["84394.84", "0"], ["84395.26", "0"], ["84395.35", "0"], ["84395.49", "0"], ["84396.59", "0.005"], ["84397.41", "0"], ["84398.29", "0"], ["84398.3", "0"], ["84398.56", "0"], ["84399.47", "0.059948"], ["84399.57", "0"], ["84399.75", "0"], ["84400.39", "0.068395"], ["84400.56", "0"], ["84400.57", "0"], ["84400.73", "0"], ["84400.92", "0.168833"], ["84401.03", "0"], ["84401.93", "0"], ["84402.34", "0"], ["84403.21", "0"], ["84403.78", "0"], ["84405.33", "0.024212"], ["84405.91", "0"], ["84405.94", "0"], ["84409.11", "0"], ["84409.28", "0.267518"], ["84409.38", "0.0013"], ["84410.69", "0.017778"], ["84411.55", "0"], ["84411.72", "0.023703"], ["84412.22", "0"], ["84413.06", "0"], ["84413.07", "0"], ["84414.65", "0.04"], ["84414.66", "0.04"], ["84414.97", "0.0002"], ["84415.03", "0.001"], ["84415.58", "0.000089"], ["84415.84", "0.0045"], ["84416.04", "0.0045"], ["84416.42", "0.17779"], ["84416.45", "0.000235"], ["84416.97", "0.005"], ["84416.98", "0.000324"], ["84417.5", "0.0002"], ["84418.43", "0.000612"], ["84418.47", "0.001333"], ["84418.69", "0.000253"], ["84418.79", "0.000111"], ["84418.86", "0.001467"], ["84418.94", "0.03181"], ["84419.39", "0.17779"], ["84420.03", "0.0002"], ["84420.2", "0.246059"], ["84420.78", "0.322941"], ["84421.09", "0.000235"], ["84421.62", "0.000235"], ["84422.57", "0.0002"], ["84422.65", "0.000612"], ["84422.69", "0.001333"], ["84423.34", "0.000253"], ["84423.43", "0.0045"], ["84423.44", "0.0045"], ["84423.51", "0.001467"], ["84423.63", "0.0045"], ["84423.64", "0.0045"], ["84423.9", "0.352306"], ["84424.06", "0.11863"], ["84424.09", "0.000089"], ["84424.4", "0.000335"], ["84424.88", "0.059948"], ["84424.97", "0.017796"], ["84425.1", "0.0002"], ["84425.74", "0.000235"], ["84426.26", "0.000235"], ["84426.56", "0.367178"], ["84426.87", "0.000612"], ["84426.91", "0.001333"], ["84427.14", "0.068395"], ["84427.98", "0.000253"], ["84428.15", "0.001467"], ["84428.34", "0.020969"], ["84428.91", "0.285395"], ["84429.86", "0.00315"], ["84430.28", "0.027614"], ["84430.38", "0.000235"]], "u": 7510750, "seq": 66889396534}, "cts": 1742142246007, "record_time": 1742142245.11988}
{"topic": "orderbook.200.BTCUSDT", "ts": 1742142246209, "type": "delta", "data": {"s": "BTCUSDT", "b": [["84376.26", "0.195613"], ["84375.43", "0.009042"], ["84375.21", "0.018201"], ["84375.2", "0.05"], ["84375.19", "0"], ["84373.59", "0"], ["84373.58", "0.00417"], ["84372.05", "0.011852"], ["84372.01", "0.000612"], ["84371.93", "0.0002"], ["84370.57", "0.0193"], ["84370.56", "0.000234"], ["84369.4", "0.0002"], ["84369.38", "0.001989"], ["84369.37", "0.005234"], ["84369.2", "0.034535"], ["84369.19", "0"], ["84368.54", "0.011852"], ["84367.84", "0.0485"], ["84367.83", "0.04906"], ["84365.73", "0"], ["84365.16", "0"], ["84363.67", "0.254154"], ["84363.66", "0.237069"], ["84363.53", "0"], ["84362.63", "0"], ["84361.98", "0.237074"], ["84361.6", "0"], ["84360.29", "0.220346"], ["84359.73", "0.011851"], ["84359.27", "0.000448"], ["84358.99", "0.026282"], ["84357.4", "0.008453"], ["84356", "0.237036"], ["84354.71", "0"], ["84354.21", "0.0002"], ["84353.24", "0"], ["84349.01", "0"], ["84347.6", "0.048"], ["84347.57", "0"], ["84345.89", "0.248007"], ["84344.88", "0"], ["84344.15", "0"], ["84342.7", "0"], ["84338.04", "0"], ["84335.06", "0.017777"], ["84329.72", "0"], ["84326.08", "0.35558"], ["84322.3", "0"], ["84319.01", "0"], ["84319", "0"], ["84318.8", "0"], ["84318.79", "0"], ["84318.7", "0"]], "a": [["84375.2", "0"], ["84376.23", "0"], ["84376.27", "0.002518"], ["84381.2", "0.020087"], ["84381.94", "0.004402"], ["84383.01", "0.01185"], ["84383.31", "0.080346"], ["84386.36", "0.121719"], ["84388.04", "0"], ["84388.89", "0.23774"], ["84390.69", "0.103809"], ["84392.55", "0"], ["84393.9", "0.048"], ["84394.32", "0"], ["84396.43", "0"], ["84396.77", "0.093875"], ["84398.56", "0.000089"], ["84399.46", "0.108141"], ["84399.48", "0.023705"], ["84400.39", "0"], ["84400.76", "1.44526"], ["84400.91", "0.009462"], ["84400.92", "0"], ["84403.55", "0.145361"], ["84405.24", "0.068395"], ["84406.54", "0.258067"], ["84407.99", "0.237036"], ["84409.28", "0"], ["84410.69", "0"], ["84410.77", "0.237036"], ["84413.94", "0.11863"], ["84414.27", "0.017796"], ["84414.65", "0"], ["84414.66", "0"], ["84415.45", "0.017777"], ["84415.75", "0.04"], ["84415.76", "0.04"], ["84416.55", "0.071081"], ["84419.39", "0"], ["84420.58", "0.162"], ["84423.89", "0.35558"], ["84424", "0.071075"], ["84426.26", "0"], ["84426.56", "0"], ["84426.87", "0"], ["84426.91", "0"], ["84427.14", "0"], ["84427.98", "0"], ["84428.15", "0"], ["84428.34", "0"], ["84428.91", "0"], ["84429.86", "0"], ["84430.28", "0"], ["84430.38", "0"]], "u": 7510751, "seq": 66889397268}, "cts": 1742142246207, "record_time": 1742142245.308186}
{"topic": "orderbook.200.BTCUSDT", "ts": 1742142246410, "type": "delta", "data": {"s": "BTCUSDT", "b": [["84376.26", "0.094413"], ["84375.9", "0.001243"], ["84375.43", "0"], ["84375.21", "0.017781"], ["84372.63", "0.0194"], ["84372.62", "0.000099"], ["84372.05", "0.005432"], ["84371.36", "0.027188"], ["84371.35", "0.071119"], ["84370.57", "0"], ["84369.2", "0"], ["84367.84", "0.017411"], ["84363.68", "0.000296"], ["84363.67", "0.386393"], ["84363.11", "0.105754"], ["84362.34", "0.015735"], ["84360.23", "0.062941"], ["84359.73", "0.012099"], ["84359.27", "0.0002"], ["84358.99", "0.096644"], ["84357.85", "0.003"], ["84357.65", "0.003"], ["84357.45", "0.003"], ["84357.43", "0.237033"], ["84357.4", "0.048453"], ["84356.78", "0.000797"], ["84356.2", "0.04"], ["84356.13", "0.221973"], ["84355.86", "0"], ["84354.82", "0.177335"], ["84353.75", "0"], ["84353.29", "0"], ["84350.91", "0"], ["84350.9", "0.08"], ["84350.7", "0.04"], ["84350.48", "0.019095"], ["84349.2", "0"], ["84348.27", "0"], ["84346.82", "0.279964"], ["84345.89", "0.080463"], ["84344.95", "0.023703"], ["84344.65", "0"], ["84343.9", "0"], ["84343.8", "0"], ["84341.12", "0"], ["84340.92", "0"], ["84340.72", "0"], ["84340.16", "1.498261"], ["84332.82", "0"], ["84331.23", "0.000136"], ["84326.08", "0"], ["84325.96", "0.000988"], ["84324.03", "0.355598"], ["84324.02", "0"], ["84321.57", "0.2"], ["84321.18", "0"], ["84320.81", "0"], ["84320.8", "0"], ["84319.56", "0"], ["84319.55", "0"], ["84319.54", "0"], ["84319.53", "0"], ["84319.09", "0"]], "a": [["84377.1", "0.008014"], ["84378.83", "0.071113"], ["84381.2", "0"], ["84381.94", "0.011851"], ["84383.29", "0.073701"], ["84383.3", "0.237128"], ["84383.31", "0"], ["84384.96", "0"], ["84387.48", "0.020085"], ["84389.59", "0.080341"], ["84389.72", "0"], ["84390.15", "0.011851"], ["84390.69", "0.070136"], ["84392.99", "0"], ["84394.05", "0.102539"], ["84394.66", "0.139818"], ["84398.44", "0.023409"], ["84399.88", "0.000988"], ["84400.39", "0.173394"], ["84401.93", "0.00347"], ["84402.69", "0.118517"], ["84403.08", "0.172516"], ["84403.78", "0.237033"], ["84404.87", "0.023703"], ["84406.73", "0.027408"], ["84408.39", "0.279397"], ["84410.77", "0"], ["84413.05", "0"], ["84415.75", "0"], ["84415.76", "0"], ["84415.84", "0"], ["84416.04", "0"], ["84416.62", "0.04"], ["84416.63", "0.04"], ["84420.19", "0.355598"], ["84422.8", "0.001235"], ["84423.43", "0"], ["84423.63", "0"], ["84423.89", "0"], ["84423.9", "0"], ["84424", "0"], ["84424.06", "0"], ["84424.09", "0"], ["84424.4", "0"], ["84424.88", "0"], ["84424.97", "0"], ["84425.1", "0"], ["84425.74", "0"]], "u": 7510752, "seq": 66889397844}, "cts": 1742142246407, "record_time": 1742142245.509746}
{"topic": "orderbook.200.BTCUSDT", "ts": 1742142246610, "type": "delta", "data": {"s": "BTCUSDT", "b": [["84372.05", "0.011852"], ["84363.35", "0.112337"], ["84363.11", "0"], ["84363.06", "0.114966"], ["84362.52", "0.109884"], ["84361.82", "0"], ["84360.23", "0.063189"], ["84359.81", "0.118376"], ["84359.73", "0.011851"], ["84358.99", "0.247769"], ["84357.9", "0.04"], ["84356.12", "0.176242"], ["84355.7", "0.04"], ["84355.06", "0.169332"], ["84354.82", "0"], ["84354", "0.301663"], ["84352.8", "0.04"], ["84352.3", "0.04"], ["84352.15", "0.167387"], ["84351.82", "0.178434"], ["84350.9", "0.04"], ["84350.6", "0"], ["84348.9", "0"], ["84348.13", "0.271528"], ["84347.07", "0.266161"], ["84346.82", "0"], ["84345.6", "0"], ["84343.82", "0.284336"], ["84341.76", "0.275619"], ["84331.35", "0.025445"], ["84331.34", "0.000254"], ["84331.23", "0"], ["84324.04", "0.35559"], ["84324.03", "0"], ["84322.09", "0"], ["84321.59", "0"], ["84321.57", "0"], ["84321.45", "0"], ["84321.42", "0"], ["84321.4", "0"], ["84321.32", "0"], ["84321.25", "0"], ["84321.19", "0"]], "a": [["84377.1", "0"], ["84390.05", "0.000089"], ["84392.13", "0.108387"], ["84392.64", "0.107928"], ["84393.7", "0.105106"], ["84394.19", "0.110897"], ["84397.37", "0.069728"], ["84399.46", "0.512609"], ["84400.1", "0.15756"], ["84400.39", "0"], ["84400.64", "0.181264"], ["84402.19", "0.170342"], ["84403.08", "0"], ["84403.18", "0.237033"], ["84403.33", "0.169433"], ["84405.24", "0"], ["84408.1", "0.294725"], ["84408.39", "0"], ["84408.63", "0.27127"], ["84410.19", "0.285183"], ["84413.72", "0.266982"], ["84420.19", "0"], ["84422.57", "0"], ["84422.65", "0"], ["84422.69", "0"], ["84422.8", "0"], ["84423.34", "0"], ["84423.44", "0"], ["84423.51", "0"], ["84423.64", "0"]], "u": 7510753, "seq": 66889398067}, "cts": 1742142246607, "record_time": 1742142245.708932}
{"topic": "orderbook.200.BTCUSDT", "ts": 1742142246809, "type": "delta", "data": {"s": "BTCUSDT", "b": [["84384.7", "0.11188"], ["84384.23", "0.000153"], ["84383.62", "0.005"], ["84382.05", "0.0002"], ["84380.45", "0.000611"], ["84379.84", "0.000234"], ["84379.32", "0.000234"], ["84376.94", "0.022516"], ["84376.93", "0.038925"], ["84376.92", "0.002109"], ["84376.91", "0.032519"], ["84376.27", "0.010078"], ["84376.26", "0.00417"], ["84376.23", "0.000611"], ["84375.21", "0"], ["84375.2", "0.000234"], ["84374.68", "0.000234"], ["84374.46", "0.0002"], ["84374.39", "0"], ["84373.58", "0"], ["84372.63", "0"], ["84372.61", "0.031871"], ["84372.6", "0.05495"], ["84372.59", "0.089922"], ["84372.45", "0.001467"], ["84372.28", "0.000252"], ["84372.05", "0.001333"], ["84371.49", "0.059948"], ["84371.36", "0"], ["84371.35", "0"], ["84370.25", "0.000089"], ["84370.04", "0.000234"], ["84369.9", "0.062931"], ["84369.37", "0"], ["84368.94", "0.01185"], ["84368.54", "0"], ["84367.85", "0.069713"], ["84367.84", "0.001333"], ["84367.83", "0"], ["84366.74", "0.068395"], ["84366.5", "0.04"], ["84365.12", "0.089922"], ["84365", "0.04"], ["84364.04", "0"], ["84363.68", "0.000544"], ["84363.66", "0"], ["84363.35", "0"], ["84363.06", "0"], ["84362.52", "0"], ["84362.34", "0"], ["84361.99", "0.059402"], ["84361.98", "0"], ["84361.6", "0.04"], ["84361.2", "0.118505"], ["84360.29", "0"], ["84360.23", "0"], ["84359.81", "0"], ["84359.73", "0"], ["84358.67", "0"], ["84357.9", "0"], ["84357.43", "0"], ["84356.32", "0.009541"], ["84356.13", "0"], ["84356.12", "0.000234"], ["84356", "0"], ["84355.06", "0"], ["84354.87", "0.017796"], ["84354.84", "0.071133"], ["84353.22", "0"], ["84352.15", "0"], ["84351.82", "0"], ["84351.79", "0"], ["84351.33", "0.005925"], ["84350.91", "0.128933"], ["84348.71", "0.017774"], ["84348.13", "0"], ["84347.2", "0"], ["84347.08", "0.234549"], ["84347.07", "0"], ["84346.57", "0.07114"], ["84346.35", "0.000335"], ["84345.89", "0"], ["84345.7", "0"], ["84344.95", "0"], ["84343.82", "0"], ["84342.64", "0.023701"], ["84341.77", "0.554324"], ["84341.76", "0"], ["84339.97", "0.025167"], ["84339.49", "0.11"], ["84338.99", "0"], ["84337.68", "0.005925"], ["84336.94", "0"], ["84336.53", "0.004578"], ["84335.06", "0"], ["84334.4", "0.000988"], ["84334.34", "0.355544"], ["84334", "0.0237"], ["84333.19", "0.0237"], ["84332.16", "0.237128"], ["84332.15", "0.23701"], ["84331.47", "0"], ["84329.66", "0"], ["84329.42", "0"], ["84328.63", "0"], ["84327.94", "0.23701"], ["84327.89", "0.023703"], ["84326.89", "0"], ["84325.96", "0"], ["84324.4", "0.24702"], ["84324.24", "0"], ["84324.17", "0"], ["84324.04", "0"], ["84323.85", "0"], ["84323.65", "0"], ["84323.1", "0"], ["84323.08", "0"], ["84322.29", "0"]], "a": [["84376.27", "0"], ["84376.92", "0"], ["84376.99", "0"], ["84377.09", "0"], ["84378.83", "0"], ["84379.32", "0"], ["84379.52", "0"], ["84379.84", "0"], ["84380", "0"], ["84380.18", "0"], ["84380.45", "0"], ["84380.49", "0"], ["84381.35", "0"], ["84381.56", "0"], ["84381.7", "0"], ["84381.73", "0"], ["84381.94", "0"], ["84382.05", "0"], ["84382.38", "0"], ["84382.6", "0"], ["84383.01", "0"], ["84383.14", "0"], ["84383.29", "0"], ["84383.3", "0"], ["84383.96", "0"], ["84384.48", "0"], ["84384.59", "0"], ["84384.67", "0"], ["84384.97", "0"], ["84386.1", "0"], ["84386.2", "0.000253"], ["84386.36", "0"], ["84386.53", "0.011065"], ["84387.1", "0"], ["84387.48", "0"], ["84388.89", "0.000612"], ["84388.9", "0"], ["84389", "0"], ["84389.42", "0"], ["84389.45", "0"], ["84389.59", "0"], ["84389.62", "0"], ["84389.65", "0.0002"], ["84390.05", "0"], ["84390.15", "0"], ["84390.69", "0"], ["84390.7", "0"], ["84390.9", "0"], ["84391.96", "0"], ["84392.13", "0"], ["84392.38", "0"], ["84392.64", "0"], ["84392.8", "0"], ["84392.82", "0"], ["84393.7", "0"], ["84393.9", "0"], ["84394.05", "0"], ["84394.19", "0"], ["84394.66", "0"], ["84395.7", "0.06"], ["84395.82", "0.005925"], ["84395.9", "0.04"], ["84396.13", "0.080341"], ["84396.59", "0"], ["84396.77", "0"], ["84397.37", "0.001333"], ["84398.44", "0"], ["84398.9", "0.04"], ["84399.19", "0.139815"], ["84399.46", "0.045681"], ["84399.47", "0"], ["84399.48", "0"], ["84399.88", "0"], ["84400.1", "0"], ["84400.53", "0"], ["84400.64", "0"], ["84400.76", "0"], ["84401.1", "0.056"], ["84401.93", "0"], ["84402.19", "0"], ["84402.68", "0.381556"], ["84402.69", "0"], ["84403", "0"], ["84403.16", "0.011849"], ["84403.18", "0"], ["84403.33", "0"], ["84403.55", "0"], ["84403.7", "0"], ["84403.78", "0"], ["84404.87", "0"], ["84405.33", "0"], ["84405.5", "0.005"], ["84405.54", "0"], ["84406.55", "0"], ["84406.73", "0"], ["84407.99", "0"], ["84408.1", "0"], ["84408.32", "0.000988"], ["84408.63", "0"], ["84408.94", "0"], ["84410.19", "0"], ["84410.34", "0.068395"], ["84411", "0.118505"], ["84411.19", "0"], ["84411.27", "0.019104"], ["84411.34", "0"], ["84411.72", "0"], ["84411.92", "0"], ["84411.93", "0.0008"], ["84412.31", "0"], ["84412.44", "0.0239"], ["84413.72", "0"], ["84414.18", "0.024689"], ["84415.45", "0"], ["84416.42", "0"], ["84416.55", "0"], ["84416.62", "0"], ["84416.63", "0"], ["84417.4", "0.0237"], ["84418.94", "0"], ["84418.95", "0.0237"], ["84421.45", "0.0237"], ["84422.28", "0.008453"], ["84422.32", "0.023701"], ["84422.57", "0.0002"], ["84422.65", "0.000612"], ["84422.69", "0.001333"], ["84422.8", "0.001235"], ["84423.08", "0.005925"], ["84423.34", "0.000253"], ["84423.44", "0.0045"], ["84423.51", "0.001467"], ["84423.64", "0.0045"], ["84423.9", "0.352306"], ["84424.06", "0.11863"], ["84424.09", "0.000089"], ["84424.4", "0.000335"], ["84424.6", "0.041473"], ["84424.88", "0.059948"], ["84424.97", "0.017796"], ["84425.1", "0.0002"], ["84425.18", "0.013811"], ["84425.74", "0.000235"], ["84426.26", "0.000235"], ["84426.42", "0.04"], ["84426.43", "0.04"], ["84426.56", "0.367178"], ["84426.87", "0.000612"], ["84426.91", "0.001333"], ["84427.63", "0.0002"], ["84427.98", "0.000253"], ["84428.15", "0.001467"], ["84428.34", "0.020969"], ["84428.64", "0.000889"], ["84429.86", "0.00315"], ["84430.02", "0.03181"], ["84430.17", "0.0002"], ["84430.38", "0.000235"], ["84430.45", "0.009"], ["84430.65", "0.009"], ["84430.91", "0.000235"], ["84431.09", "0.000612"], ["84431.13", "0.001333"], ["84432.38", "0.015"], ["84432.58", "0.000357"], ["84432.6", "0.000089"], ["84432.62", "0.000253"], ["84432.7", "0.0002"], ["84432.79", "0.001467"], ["84433.14", "0.0025"], ["84434.18", "0.11863"], ["84434.2", "0.068"], ["84434.42", "0.430025"], ["84435.02", "0.000235"], ["84435.23", "0.0002"], ["84435.31", "0.000612"], ["84435.36", "0.001333"], ["84435.55", "0.000235"], ["84435.61", "0.071065"], ["84436.88", "1.777896"], ["84436.94", "0.23701"], ["84437.27", "0.000253"], ["84437.44", "0.001467"], ["84437.46", "0.001"], ["84438.68", "0.059296"], ["84439.53", "0.000612"], ["84439.58", "0.001333"], ["84439.67", "0.000235"], ["84440.19", "0.000235"], ["84440.47", "0.23701"], ["84441.11", "0.000089"], ["84441.16", "0.23701"], ["84441.74", "0.059948"], ["84441.91", "0.000253"], ["84442.08", "0.001467"], ["84442.38", "0.000158"], ["84442.42", "0.285349"], ["84443.76", "0.000612"]], "u": 7510754, "seq": 66889400462}, "cts": 1742142246808, "record_time": 1742142245.909055}
{"topic": "orderbook.200.BTCUSDT", "ts": 1742142247009, "type": "delta", "data": {"s": "BTCUSDT", "b": [["84384.7", "0.026928"], ["84384.23", "0"], ["84382.06", "0.0193"], ["84379.52", "0.0002"], ["84377.02", "0.038475"], ["84377.01", "0.033278"], ["84377", "0.038575"], ["84376.99", "0.0002"], ["84376.97", "0.038725"], ["84376.94", "0"], ["84376.93", "0"], ["84376.92", "0.001709"], ["84376.91", "0.031719"], ["84376.27", "0.050393"], ["84372.62", "0"], ["84372.61", "0"], ["84372.6", "0"], ["84372.59", "0"], ["84371.98", "0.028038"], ["84371.49", "0"], ["84369.91", "0.015732"], ["84369.67", "0.111211"], ["84369.38", "0.116428"], ["84368.94", "0"], ["84368.87", "0.118798"], ["84368.17", "0.003"], ["84367.97", "0.003"], ["84367.86", "0.000296"], ["84367.77", "0.003"], ["84367.1", "0.04"], ["84366.27", "0.111592"], ["84365.92", "0.000482"], ["84365.7", "0.04"], ["84365.12", "0"], ["84364.57", "0.21668"], ["84364.1", "0.01185"], ["84363.7", "0.04"], ["84363.68", "0.000296"], ["84363.67", "0.132239"], ["84362.5", "0.160813"], ["84361.41", "0.166494"], ["84361.1", "0.04"], ["84360.5", "0.04"], ["84360.3", "0.04"], ["84359.41", "0"], ["84358.99", "0"], ["84358.52", "0.159927"], ["84358.31", "0.179549"], ["84356.2", "0"], ["84355.7", "0"], ["84354.84", "0"], ["84354.53", "0.275703"], ["84354", "0.125192"], ["84353.45", "0.298947"], ["84352.8", "0"], ["84352.3", "0"], ["84351.29", "0.080367"], ["84350.91", "0"], ["84350.9", "0"], ["84350.7", "0"], ["84350.34", "0.288784"], ["84349.38", "0.023497"], ["84348.71", "0"], ["84348.17", "0.301409"], ["84347.08", "0"], ["84344.42", "0.323234"], ["84343.79", "0.017776"], ["84342.41", "0.071144"], ["84340.17", "0.237128"], ["84339.49", "0"], ["84336.83", "0"], ["84334.34", "0"], ["84333.14", "0.0025"], ["84332.38", "0.015"], ["84331.59", "0"], ["84328.28", "0"], ["84328", "0"], ["84327.94", "0"], ["84327.89", "0"], ["84327.13", "0"], ["84326.38", "0"], ["84326.07", "0"], ["84326.06", "0"], ["84325.89", "0"], ["84325.66", "0"], ["84325.62", "0"], ["84325.51", "0"], ["84324.52", "0"], ["84324.4", "0"]], "a": [["84384.71", "0.002518"], ["84386.53", "0"], ["84387.67", "0.025852"], ["84388.04", "0.071105"], ["84388.92", "0.011849"], ["84390.83", "0.016602"], ["84391.45", "0.011849"], ["84394.05", "0.128756"], ["84395.06", "0.020085"], ["84395.7", "0"], ["84395.9", "0"], ["84397.77", "0.01185"], ["84398.34", "0.114493"], ["84398.42", "0"], ["84398.85", "0.117876"], ["84398.89", "0.060271"], ["84398.9", "0"], ["84399.46", "0"], ["84399.86", "0"], ["84399.93", "0.11019"], ["84400.4", "0.06"], ["84400.52", "0.107884"], ["84401.1", "0"], ["84402.5", "0.044"], ["84402.67", "0.202351"], ["84402.68", "0"], ["84403.16", "0"], ["84405.5", "0"], ["84406.3", "0.177895"], ["84406.54", "0"], ["84406.8", "0.048"], ["84406.81", "0.176411"], ["84407.2", "0.048"], ["84408.3", "1.511065"], ["84408.48", "0.164659"], ["84409.49", "0.169637"], ["84409.8", "0.068"], ["84409.84", "0.005"], ["84409.9", "0.003749"], ["84411.97", "0.03181"], ["84414.18", "0"], ["84414.26", "0.26688"], ["84414.36", "0.004587"], ["84414.77", "0.284209"], ["84414.86", "0"], ["84415.17", "0.23701"], ["84416.45", "0.268355"], ["84419.39", "0.23701"], ["84419.77", "0.026928"], ["84419.84", "0.30059"], ["84420.37", "0.017775"], ["84420.78", "0"], ["84422.8", "0"], ["84423.6", "0.02024"], ["84423.89", "0.355577"], ["84424.6", "0.023699"], ["84426.42", "0"], ["84426.43", "0"], ["84427.12", "0.04"], ["84427.13", "0.04"], ["84427.85", "0.071072"], ["84429.02", "0.162"], ["84430.02", "0"], ["84430.65", "0.0045"], ["84436.88", "0"], ["84436.94", "0"], ["84437.27", "0"], ["84437.44", "0"], ["84437.46", "0"], ["84438.68", "0"], ["84439.53", "0"], ["84439.58", "0"], ["84439.67", "0"], ["84440.19", "0"], ["84440.47", "0"], ["84441.11", "0"], ["84441.16", "0"], ["84441.74", "0"], ["84441.91", "0"], ["84442.08", "0"], ["84442.38", "0"], ["84442.42", "0"], ["84443.76", "0"]], "u": 7510755, "seq": 66889401407}, "cts": 1742142247006, "record_time": 1742142246.108557}
{"topic": "orderbook.200.BTCUSDT", "ts": 1742142247209, "type": "delta", "data": {"s": "BTCUSDT", "b": [["84384.7", "0.149334"], ["84384.43", "0.028712"], ["84384.42", "0.071108"], ["84381.13", "0.000099"], ["84380.5", "0.014027"], ["84380.49", "0.011851"], ["84377.96", "0.011851"], ["84377.02", "0"], ["84377.01", "0"], ["84377", "0"], ["84376.97", "0"], ["84376.28", "0.017126"], ["84376.26", "0"], ["84373.38", "0.112436"], ["84373.09", "0.120128"], ["84372.52", "0.114751"], ["84371.98", "0"], ["84371.62", "0.000296"], ["84369.93", "0.042329"], ["84369.92", "0.060244"], ["84369.8", "0.113453"], ["84369.67", "0"], ["84369.38", "0.001989"], ["84368.87", "0"], ["84367.86", "0"], ["84367.85", "0.161048"], ["84366.84", "0.001428"], ["84366.27", "0"], ["84366.15", "0.172777"], ["84365.92", "0.000234"], ["84365.2", "0.23701"], ["84365.12", "0.178418"], ["84363.68", "0"], ["84362.5", "0"], ["84362.23", "0.171768"], ["84361.84", "0.180725"], ["84361.41", "0"], ["84360.98", "0.23701"], ["84358.52", "0"], ["84358.31", "0"], ["84358.18", "0.293606"], ["84357.4", "0.008453"], ["84357.16", "0.294358"], ["84355.6", "0.048"], ["84354.53", "0"], ["84354", "0.085192"], ["84353.87", "0.274281"], ["84353.45", "0"], ["84351.87", "0.263385"], ["84350.34", "0"], ["84348.17", "0"], ["84347.6", "0"], ["84334.34", "0.355553"], ["84330.4", "0"], ["84329.88", "0"], ["84329.84", "0"], ["84328.91", "0"], ["84328.82", "0"], ["84328.81", "0"]], "a": [["84384.71", "0.041669"], ["84387.67", "0"], ["84388.04", "0"], ["84390.83", "0"], ["84398.34", "0"], ["84398.84", "0.089531"], ["84398.85", "0"], ["84398.89", "0"], ["84399.93", "0"], ["84400.3", "0.04"], ["84400.52", "0"], ["84401", "0.04"], ["84402.05", "0.108699"], ["84402.56", "0.113673"], ["84402.67", "0"], ["84403.55", "0.082386"], ["84403.58", "0.107758"], ["84403.8", "0.06"], ["84404.05", "0.119951"], ["84404.9", "0.068"], ["84405.4", "0.056"], ["84406.3", "0.0006"], ["84406.81", "0"], ["84407.79", "0.02329"], ["84408.48", "0"], ["84409.49", "0"], ["84409.95", "0.175407"], ["84410.52", "0.171112"], ["84412.01", "0.179614"], ["84413.2", "0.162663"], ["84414.26", "0"], ["84414.77", "0"], ["84415.17", "0"], ["84416.45", "0.000235"], ["84417.92", "0.278606"], ["84418.37", "0.022639"], ["84418.48", "0.282543"], ["84419.77", "0"], ["84419.84", "0"], ["84419.97", "0.282488"], ["84423.55", "0.27863"], ["84423.89", "0"], ["84429.64", "0.027942"], ["84435.31", "0"], ["84435.36", "0"], ["84435.55", "0"], ["84435.61", "0"]], "u": 7510756, "seq": 66889402009}, "cts": 1742142247207, "record_time": 1742142246.309058}
{"topic": "orderbook.200.BTCUSDT", "ts": 1742142247409, "type": "delta", "data": {"s": "BTCUSDT", "b": [["84384.7", "0.149487"], ["84383.87", "0.01185"], ["84383.86", "0.0192"], ["84382.06", "0"], ["84380.5", "0.033732"], ["84377.97", "0.059522"], ["84376.92", "0.001961"], ["84376.91", "0.031467"], ["84376.28", "0.046951"], ["84373.38", "0"], ["84373.09", "0"], ["84372.66", "0.110221"], ["84372.53", "0.047299"], ["84372.52", "0"], ["84369.93", "0"], ["84369.8", "0"], ["84369", "0.01185"], ["84367.85", "0.292541"], ["84367.79", "0.00086"], ["84366.84", "0.00118"], ["84366.29", "0.171502"], ["84366.15", "0"], ["84365.12", "0"], ["84365", "0.041243"], ["84364.1", "0"], ["84364", "0.048"], ["84362.23", "0"], ["84361.99", "0"], ["84361.84", "0"], ["84361.2", "0"], ["84360.94", "0.008702"], ["84358.18", "0"], ["84357.16", "0"], ["84355.6", "0"], ["84353.87", "0"], ["84353.68", "0.071134"], ["84351.87", "0"], ["84351.29", "0"], ["84348.98", "0.017775"], ["84343.79", "0"], ["84342.41", "0"], ["84336.37", "0.23701"], ["84329.88", "0.001333"], ["84329.84", "0.000613"], ["84328.91", "0.0002"], ["84328.82", "0.000089"], ["84328.81", "0.000233"], ["84328.28", "0.000233"], ["84328.19", "0.0237"], ["84328", "0.000089"], ["84327.89", "0.023703"]], "a": [["84384.71", "0.040484"], ["84388.92", "0"], ["84397.77", "0"], ["84402.05", "0"], ["84402.4", "0.01185"], ["84402.56", "0"], ["84403.55", "0.1956"], ["84403.58", "0"], ["84403.72", "0.105938"], ["84404.05", "0"], ["84407.79", "0"], ["84407.93", "0.023592"], ["84408.29", "0.622435"], ["84408.3", "1.451065"], ["84409.8", "0"], ["84409.95", "0"], ["84410.1", "0.163194"], ["84410.52", "0"], ["84411", "0"], ["84412.01", "0"], ["84413.2", "0"], ["84415.17", "0.23701"], ["84415.84", "0.23701"], ["84417.92", "0"], ["84418.48", "0"], ["84419.97", "0"], ["84420.06", "0.23701"], ["84423.55", "0"], ["84427.12", "0"], ["84427.13", "0"], ["84427.62", "0.04"], ["84427.63", "0.0402"], ["84427.85", "0"], ["84428.63", "0.071071"], ["84434.17", "0.35555"], ["84435.31", "0.000612"], ["84435.36", "0.001333"], ["84435.55", "0.000235"], ["84435.61", "0.071065"], ["84436.88", "1.777896"], ["84436.94", "0.177757"], ["84437.27", "0.000253"], ["84437.44", "0.001467"], ["84437.46", "0.001"]], "u": 7510757, "seq": 66889402413}, "cts": 1742142247407, "record_time": 1742142246.509058}
{"topic": "orderbook.200.BTCUSDT", "ts": 1742142247609, "type": "delta", "data": {"s": "BTCUSDT", "b": [["84380.49", "0.013184"], ["84377.09", "0.001467"], ["84376.92", "0.000252"], ["84376.91", "0.03"], ["84376.28", "0.209165"], ["84375.57", "0.237035"], ["84373.88", "0.23704"], ["84372.66", "0"], ["84372.53", "0.109097"], ["84372.19", "0.237045"], ["84370.49", "0.104989"], ["84370.41", "0.000797"], ["84367.85", "0.292789"], ["84367.79", "0.000612"], ["84366.29", "0"], ["84365.86", "0.23701"], ["84365.2", "0"], ["84364.57", "0"], ["84362.52", "0.163296"], ["84361.65", "0.23701"], ["84360.98", "0"], ["84356.78", "0"], ["84354.56", "0.297243"], ["84353.88", "0.023701"], ["84353.22", "0.177757"], ["84351.63", "0.017765"], ["84344.43", "0.146003"], ["84339.45", "0.05"], ["84339.44", "0.005563"], ["84336.37", "0"], ["84334.34", "0.355549"], ["84332.15", "0.177757"], ["84331.35", "0"], ["84331.34", "0"], ["84328.91", "0"], ["84328.82", "0"], ["84328.81", "0"], ["84328.28", "0"], ["84328.19", "0"], ["84328", "0"], ["84327.89", "0"]], "a": [["84384.71", "0.034037"], ["84394.05", "0"], ["84400.91", "0"], ["84401", "0"], ["84403.72", "0"], ["84404.73", "0.108348"], ["84410.1", "0"], ["84412.21", "0.23701"], ["84412.69", "0.172724"], ["84414.2", "0.023701"], ["84415.16", "0.158995"], ["84415.17", "0"], ["84415.84", "0"], ["84416.42", "0.23701"], ["84419.39", "0"], ["84420.06", "0"], ["84420.62", "0.035559"], ["84420.66", "0.267424"], ["84429.64", "0"], ["84434.17", "0.355545"], ["84436.94", "0"], ["84437.46", "0.163"], ["84437.49", "0.177757"], ["84438.9", "0.024"], ["84439.1", "0.009"]], "u": 7510758, "seq": 66889402855}, "cts": 1742142247607, "record_time": 1742142246.708714}
{"topic": "orderbook.200.BTCUSDT", "ts": 1742142247810, "type": "delta", "data": {"s": "BTCUSDT", "b": [["84386.36", "0.982393"], ["84386.21", "0.042126"], ["84386.2", "0.000153"], ["84386.19", "0.03"], ["84385.52", "0.0193"], ["84384.7", "0.000959"], ["84384.43", "0"], ["84383.86", "0"], ["84381.56", "0.000252"], ["84380.5", "0.058087"], ["84377.48", "0.089922"], ["84377.32", "0.075324"], ["84376.35", "0.083666"], ["84376.28", "0"], ["84375.57", "0"], ["84374.29", "0.237005"], ["84373.88", "0"], ["84373.73", "0.011849"], ["84373.64", "0.237005"], ["84372.38", "0.015731"], ["84370.49", "0"], ["84370.07", "0.237005"], ["84369.92", "0.060492"], ["84369.91", "0"], ["84369.48", "0.162"], ["84369.42", "0.237005"], ["84369", "0"], ["84368.33", "0.089922"], ["84367.85", "0.142608"], ["84365.86", "0"], ["84363.67", "0.222984"], ["84362.52", "0"], ["84361.65", "0"], ["84358.42", "0.006017"], ["84356.92", "0.139809"], ["84354.57", "0.243597"], ["84354.56", "0"], ["84354", "0"], ["84353.98", "0.017774"], ["84351.29", "0.049016"], ["84348.98", "0"], ["84344.76", "0.0237"], ["84341.75", "0.05"], ["84341.74", "0.015329"], ["84341", "0.000119"], ["84340.18", "0.355532"], ["84339.45", "0"], ["84339.44", "0"], ["84336.03", "0.000988"], ["84334.4", "0"], ["84334.34", "0"], ["84334.33", "0"], ["84334", "0.27072"], ["84332.15", "0"], ["84331.52", "0"], ["84331.44", "0"], ["84330.69", "0"], ["84330.65", "0"], ["84330.53", "0"], ["84330.39", "0"], ["84329.88", "0"], ["84329.84", "0"]], "a": [["84384.71", "0"], ["84386.2", "0"], ["84386.37", "0.003464"], ["84391.45", "0"], ["84393.11", "0.012461"], ["84394.06", "0"], ["84395.06", "0"], ["84395.82", "0"], ["84396.12", "0.237128"], ["84397.5", "0.020085"], ["84398.84", "0"], ["84399.19", "0"], ["84400.3", "0"], ["84400.4", "0"], ["84402.4", "0"], ["84402.5", "0"], ["84403.55", "0.082386"], ["84403.8", "0"], ["84404.73", "0"], ["84404.9", "0"], ["84405.4", "0"], ["84406.76", "0.011849"], ["84406.8", "0"], ["84407.2", "0"], ["84408.32", "0"], ["84408.5", "0.06"], ["84409.84", "0"], ["84409.99", "0.0016"], ["84410.4", "0.068"], ["84411.34", "0.106981"], ["84411.69", "0.162"], ["84411.97", "0"], ["84412.13", "0.233348"], ["84412.14", "0"], ["84412.44", "0.0002"], ["84412.69", "0"], ["84414.17", "0.00951"], ["84414.18", "0.005"], ["84415.16", "0"], ["84416.41", "0.087865"], ["84417.4", "0"], ["84417.5", "0.118703"], ["84418.95", "0"], ["84420.06", "0.237005"], ["84420.19", "0.237963"], ["84420.2", "0"], ["84420.37", "0"], ["84420.62", "0"], ["84420.63", "0.237005"], ["84420.66", "0"], ["84422.32", "0"], ["84423.08", "0"], ["84423.35", "0.0237"], ["84424.28", "0.237005"], ["84424.42", "0.03181"], ["84425.26", "0.017774"], ["84427", "0.000119"], ["84427.62", "0"], ["84427.63", "0.0002"], ["84428.33", "0.04"], ["84428.34", "0.060969"], ["84428.36", "0.0237"], ["84431.53", "0.0237"], ["84431.76", "0.0237"], ["84434.04", "0.005925"], ["84434.17", "0"], ["84439.53", "0.000612"], ["84439.58", "0.001333"], ["84439.67", "0.000235"], ["84439.7", "0.246059"], ["84440.19", "0.000235"], ["84440.47", "0.237005"], ["84441.11", "0.000089"], ["84441.74", "0.059948"], ["84441.91", "0.000253"], ["84442.08", "0.001467"]], "u": 7510759, "seq": 66889404214}, "cts": 1742142247808, "record_time": 1742142246.909061}
{"topic": "orderbook.200.BTCUSDT", "ts": 1742142248009, "type": "delta", "data": {"s": "BTCUSDT", "b": [["84390.99", "0.226602"], ["84388.89", "0.015924"], ["84388.88", "0.031572"], ["84388.59", "0.041367"], ["84387.12", "0.0002"], ["84386.37", "0.0004"], ["84386.36", "0.00417"], ["84386.21", "0"], ["84386.2", "0.000252"], ["84385.52", "0"], ["84384.71", "0.001333"], ["84384.67", "0.000612"], ["84384.59", "0.0002"], ["84384.48", "0.000234"], ["84384.42", "0"], ["84383.96", "0.000234"], ["84382.79", "0.07168"], ["84382.78", "0.237015"], ["84381.73", "0.001467"], ["84381.68", "0.117056"], ["84381.13", "0"], ["84380.94", "0.23702"], ["84380.5", "0.099388"], ["84380.35", "0.108343"], ["84378.7", "0.000089"], ["84378.08", "0.01573"], ["84377.92", "0.162"], ["84377.32", "0"], ["84376.91", "0"], ["84376.35", "0.21068"], ["84376.27", "0.001333"], ["84375.97", "0.062921"], ["84374.72", "0.068395"], ["84373.98", "0.175213"], ["84373.3", "0.04"], ["84372.53", "0.292336"], ["84372.45", "0.001715"], ["84372.38", "0"], ["84372.19", "0"], ["84371.79", "0.003"], ["84370.53", "0.164119"], ["84369.92", "0.060244"], ["84369.9", "0"], ["84369.42", "0"], ["84368.34", "0.100282"], ["84367.85", "0"], ["84367.7", "0.118499"], ["84366.96", "0.0001"], ["84366.74", "0"], ["84366.01", "0.28949"], ["84363.67", "0.132239"], ["84361.41", "0.071128"], ["84360.18", "0.268214"], ["84358.42", "0.006008"], ["84356.93", "0.045005"], ["84355.89", "0.023698"], ["84354.73", "0.023701"], ["84354.57", "0"], ["84353.69", "0.146738"], ["84346.57", "0"], ["84344.44", "0.355766"], ["84342.64", "0"], ["84341.75", "0"], ["84341.74", "0"], ["84341.55", "0.05"], ["84341.54", "0.015329"], ["84340.18", "0"], ["84337.56", "0"], ["84336.97", "0"], ["84336.53", "0"], ["84336.5", "0"], ["84336.45", "0"], ["84336.03", "0"], ["84335.33", "0"], ["84335.16", "0"], ["84334.1", "0"], ["84334.05", "0"], ["84334", "0"], ["84333.97", "0"], ["84333.45", "0"], ["84333.19", "0"], ["84333.14", "0"], ["84332.92", "0"], ["84332.8", "0"], ["84332.38", "0"], ["84332.3", "0"], ["84332.16", "0"]], "a": [["84386.37", "0"], ["84387.12", "0"], ["84387.68", "0"], ["84388.6", "0"], ["84388.89", "0"], ["84388.93", "0"], ["84389.12", "0"], ["84389.65", "0"], ["84390.84", "0"], ["84391", "0.002639"], ["84393.11", "0.000612"], ["84396.12", "0"], ["84396.13", "0"], ["84397.5", "0"], ["84398.56", "0"], ["84403.15", "0.026037"], ["84403.17", "0.020084"], ["84404.62", "0.080335"], ["84408.02", "0"], ["84408.3", "1.491065"], ["84408.5", "0.12"], ["84409.38", "0"], ["84409.9", "0.0002"], ["84410.35", "0.107487"], ["84411.26", "0.059948"], ["84411.41", "0.114986"], ["84411.69", "0"], ["84411.8", "0.04"], ["84412.13", "0.130174"], ["84412.21", "0"], ["84413.15", "0.005856"], ["84413.5", "0.056"], ["84414.2", "0"], ["84414.9", "0.048"], ["84415.3", "0.048"], ["84416.42", "0"], ["84417.5", "0.0002"], ["84417.78", "0.158883"], ["84418.37", "0"], ["84418.4", "0.005"], ["84420.05", "0.201233"], ["84420.06", "0"], ["84420.19", "0"], ["84421.5", "0.176777"], ["84424.13", "0.024708"], ["84424.42", "0"], ["84425.26", "0"], ["84425.74", "0.297781"], ["84428.27", "0.0012"], ["84428.33", "0"], ["84428.34", "0.020969"], ["84428.63", "0"], ["84428.64", "0"], ["84430.08", "0.017773"], ["84431.85", "0.267261"], ["84435.73", "0.04"], ["84435.74", "0.04"], ["84436.07", "0.03181"], ["84437.76", "0.0002"], ["84439.42", "0.071062"], ["84440.3", "0.0002"], ["84440.47", "0"], ["84440.5", "0.009"], ["84440.7", "0.009"], ["84442.38", "0.000158"], ["84443.76", "0.000612"]], "u": 7510760, "seq": 66889404996}, "cts": 1742142248007, "record_time": 1742142247.108956}
{"topic": "orderbook.200.BTCUSDT", "ts": 1742142248210, "type": "delta", "data": {"s": "BTCUSDT", "b": [["84391.73", "0.173073"], ["84391", "0.025382"], ["84390.99", "0.071256"], ["84390.89", "0.0192"], ["84390.16", "0.011849"], ["84388.91", "0.046174"], ["84388.9", "0.05953"], ["84388.89", "0.0004"], ["84388.88", "0"], ["84388.59", "0.039867"], ["84387.42", "0.000099"], ["84386.78", "0.01185"], ["84386.37", "0.001867"], ["84386.36", "0"], ["84382.56", "0.04906"], ["84381.68", "0"], ["84381.5", "0.116322"], ["84380.95", "0.210258"], ["84380.5", "0"], ["84380.49", "0.001333"], ["84380.35", "0"], ["84379.21", "0.059274"], ["84378.89", "0.011848"], ["84377.97", "0"], ["84377.96", "0"], ["84377.86", "0.236992"], ["84375.9", "0.001491"], ["84375.2", "0.162901"], ["84375", "0.04"], ["84373.98", "0"], ["84373.8", "0.04"], ["84373.73", "0"], ["84372.53", "0.176659"], ["84372.45", "0.001467"], ["84371.7", "0.04"], ["84370.53", "0"], ["84370.2", "0.04"], ["84369.98", "0.019095"], ["84368.6", "0.04"], ["84368.34", "0.189655"], ["84368.3", "0.04"], ["84367.7", "0"], ["84367.32", "0.278163"], ["84366.01", "0"], ["84365.7", "0"], ["84365", "0.001243"], ["84363.93", "0.272968"], ["84363.67", "0.204694"], ["84360.5", "0"], ["84360.3", "0"], ["84360.18", "0"], ["84358.33", "0.017773"], ["84354.82", "0.323194"], ["84353.98", "0"], ["84350.48", "0"], ["84344.45", "0.355507"], ["84344.44", "0.000252"], ["84344.42", "0"], ["84340.16", "0"], ["84339.8", "0"], ["84339.03", "0"], ["84338.31", "0"], ["84338.27", "0"], ["84338.08", "0"], ["84337.68", "0"]], "a": [["84391", "0"], ["84391.01", "0"], ["84391.63", "0"], ["84391.74", "0.007245"], ["84401.54", "0.007601"], ["84401.81", "0.071094"], ["84403.15", "0.001243"], ["84406.76", "0"], ["84407.93", "0"], ["84408.81", "0.139808"], ["84410.2", "0.044"], ["84410.35", "0"], ["84411.17", "0.011848"], ["84411.27", "0"], ["84411.33", "0.149418"], ["84411.41", "0"], ["84412.13", "0"], ["84412.23", "0.118266"], ["84413.15", "0"], ["84414.18", "0"], ["84415.29", "0.066452"], ["84416.41", "0"], ["84417.6", "0.003484"], ["84417.78", "0"], ["84418.53", "0.180037"], ["84421.5", "0"], ["84422.8", "0.118496"], ["84423.89", "0.454736"], ["84424.85", "0.236992"], ["84425.74", "0.000235"], ["84426.16", "0.019104"], ["84426.41", "0.295237"], ["84428.5", "0.236992"], ["84431.85", "0"], ["84433.19", "0.473748"], ["84435.73", "0"], ["84435.74", "0"], ["84436.43", "0.04"], ["84436.44", "0.04"], ["84442.38", "0"], ["84443.76", "0"]], "u": 7510761, "seq": 66889405722}, "cts": 1742142248205, "record_time": 1742142247.309736}
{"topic": "orderbook.200.BTCUSDT", "ts": 1742142248409, "type": "delta", "data": {"s": "BTCUSDT", "b": [["84403.14", "0.162594"], ["84402.53", "0.023944"], ["84401.54", "0.0004"], ["84401.53", "0.077594"], ["84399.78", "0.0002"], ["84399.75", "0.00115"], ["84398.41", "0.000234"], ["84397.88", "0.000234"], ["84397.37", "0.001333"], ["84397.32", "0.000612"], ["84395.47", "0.031138"], ["84394.78", "0.067778"], ["84394.77", "0.150482"], ["84394.73", "0.005"], ["84394.7", "0.086374"], ["84393.76", "0.000234"], ["84393.75", "0.010235"], ["84393.24", "0.000234"], ["84393.23", "0.032006"], ["84393.15", "0.001333"], ["84393.11", "0.000612"], ["84392.2", "0.059948"], ["84392.19", "0.050607"], ["84391.74", "0.0004"], ["84391.73", "0.16637"], ["84391.01", "0.001467"], ["84391", "0.0006"], ["84390.99", "0"], ["84390.89", "0"], ["84390.84", "0.000252"], ["84390.16", "0"], ["84389.65", "0.0002"], ["84389.12", "0.000234"], ["84388.93", "0.001333"], ["84388.91", "0.045413"], ["84388.89", "0.000612"], ["84388.6", "0.000234"], ["84388.59", "0"], ["84388.54", "0.11787"], ["84388.32", "0.089922"], ["84387.42", "0"], ["84387.15", "0.000089"], ["84386.78", "0"], ["84386.37", "0.001467"], ["84386.19", "0"], ["84385.69", "0.003"], ["84385.49", "0.003"], ["84385.29", "0.003"], ["84384.7", "0"], ["84384.37", "0.16004"], ["84384.28", "0.011848"], ["84383.87", "0"], ["84383.78", "0.068395"], ["84383.62", "0"], ["84383.19", "0.015727"], ["84382.79", "0.040655"], ["84382.78", "0"], ["84382.71", "0.008701"], ["84382.56", "0"], ["84382", "0.04"], ["84381.59", "0.165072"], ["84381.5", "0"], ["84381.26", "0.062908"], ["84380.96", "0.059948"], ["84380.94", "0"], ["84379.9", "0.04"], ["84379.21", "0"], ["84378.89", "0"], ["84378.08", "0"], ["84377.86", "0"], ["84376.66", "0.009898"], ["84376.49", "0.300312"], ["84375.97", "0"], ["84375.9", "0.001243"], ["84375.7", "0.118479"], ["84375.5", "0.04"], ["84375.2", "0.000234"], ["84374.9", "0.04"], ["84374.72", "0"], ["84374.29", "0"], ["84374.06", "0.000797"], ["84373.8", "0"], ["84373.64", "0"], ["84372", "0.048"], ["84371.35", "0.292941"], ["84370.41", "0"], ["84370.07", "0"], ["84370", "0.04"], ["84368.92", "0.071121"], ["84367.77", "0"], ["84367.32", "0"], ["84367.1", "0"], ["84366.8", "0.023696"], ["84366.57", "0.323149"], ["84366.5", "0"], ["84364", "0"], ["84363.94", "0.21065"], ["84363.93", "0"], ["84363.9", "0.017772"], ["84363.7", "0"], ["84363.67", "0"], ["84361.6", "0"], ["84361.1", "0"], ["84359.76", "0.068395"], ["84358.33", "0"], ["84357.85", "0"], ["84357.65", "0"], ["84357.48", "1.484762"], ["84357.45", "0"], ["84357.4", "0"], ["84356.94", "0.355454"], ["84356.86", "0.004695"], ["84356.85", "0.023696"], ["84356.32", "0"], ["84356.13", "0.04999"], ["84354.82", "0"], ["84354.73", "0"], ["84354.56", "0.005924"], ["84353.88", "0"], ["84353.7", "0.237128"], ["84353.68", "0"], ["84353.22", "0"], ["84350.07", "0.023696"], ["84349.3", "0"], ["84348.67", "0"], ["84348.47", "0"], ["84348.27", "0.059067"], ["84345.96", "0.237128"], ["84345.06", "0.023696"], ["84344.9", "0"], ["84344.76", "0"], ["84344.61", "0"], ["84344.45", "0"], ["84344.44", "0"], ["84344.43", "0"], ["84344.09", "0"], ["84343.23", "0"], ["84343.2", "0"], ["84342.81", "0"], ["84342.72", "0"], ["84342.53", "0"], ["84342.52", "0"], ["84342.49", "0"], ["84342.2", "0"], ["84341.77", "0"], ["84341.56", "0"], ["84341.55", "0"], ["84341.54", "0"], ["84341", "0"], ["84340.17", "0"], ["84340", "0"], ["84339.97", "0"]], "a": [["84391.74", "0"], ["84392.18", "0"], ["84393.11", "0"], ["84393.15", "0"], ["84393.24", "0"], ["84393.76", "0"], ["84394.71", "0"], ["84394.78", "0"], ["84395.48", "0"], ["84395.65", "0"], ["84397.24", "0"], ["84397.33", "0"], ["84397.37", "0"], ["84397.88", "0"], ["84398.41", "0"], ["84399.78", "0"], ["84400", "0"], ["84400.13", "0"], ["84400.29", "0"], ["84401.54", "0"], ["84401.59", "0"], ["84401.81", "0"], ["84402.29", "0"], ["84402.31", "0"], ["84402.52", "0"], ["84403.05", "0"], ["84403.15", "0.00324"], ["84403.17", "0"], ["84403.38", "0.006319"], ["84403.55", "0"], ["84403.56", "0"], ["84404.62", "0"], ["84404.93", "0.016286"], ["84407.07", "0"], ["84408.29", "0"], ["84408.3", "0"], ["84408.5", "0"], ["84408.65", "0"], ["84408.81", "0"], ["84409.99", "0.000612"], ["84410.2", "0"], ["84410.34", "0"], ["84410.4", "0"], ["84410.55", "0.080342"], ["84410.79", "0.005924"], ["84411.17", "0"], ["84411.22", "0.071086"], ["84411.26", "0"], ["84411.33", "0"], ["84411.34", "0"], ["84411.8", "0"], ["84411.93", "0"], ["84412.23", "0"], ["84413.15", "0.005914"], ["84413.5", "0"], ["84413.92", "0.237128"], ["84413.94", "0"], ["84414.17", "0"], ["84414.27", "0"], ["84414.36", "0"], ["84414.9", "0"], ["84415.29", "0"], ["84415.3", "0"], ["84415.36", "0.000987"], ["84415.8", "0.011848"], ["84416.96", "0.085402"], ["84417.1", "0.044"], ["84417.6", "0"], ["84418.3", "0.06"], ["84418.4", "0"], ["84418.53", "0"], ["84418.99", "0.237128"], ["84420.58", "0"], ["84420.63", "0"], ["84421.45", "0"], ["84422.28", "0"], ["84422.42", "0.105142"], ["84422.8", "0.005"], ["84424.13", "0"], ["84424.27", "0.059948"], ["84424.28", "0"], ["84424.57", "0.0008"], ["84424.6", "0"], ["84424.85", "0"], ["84424.88", "0"], ["84424.97", "0"], ["84425.18", "0"], ["84426.08", "0.023696"], ["84426.41", "0"], ["84426.56", "0"], ["84427", "0"], ["84427.61", "0.118479"], ["84427.7", "0.178842"], ["84428.34", "0"], ["84428.5", "0"], ["84430.08", "0"], ["84430.3", "0.157943"], ["84430.86", "0.004586"], ["84431.53", "0"], ["84432.01", "0.176515"], ["84432.48", "0.00951"], ["84433.18", "0.059948"], ["84433.19", "0"], ["84433.71", "0.023696"], ["84434.42", "0"], ["84434.83", "0.008453"], ["84435.58", "0.26366"], ["84435.61", "0"], ["84436.07", "0"], ["84436.43", "0"], ["84436.44", "0"], ["84437.33", "0.023695"], ["84437.49", "0"], ["84439.1", "0.0045"], ["84439.35", "0.017771"], ["84439.42", "0"], ["84439.48", "0.002062"], ["84440.5", "0.0045"], ["84440.7", "0.0045"], ["84442.24", "0.023695"], ["84442.38", "0.000158"], ["84442.83", "0.0002"], ["84443.76", "0.000612"], ["84443.8", "0.001333"], ["84443.9", "0.002703"], ["84444.03", "0.04"], ["84444.04", "0.04"], ["84444.3", "0.11863"], ["84444.31", "0.000235"], ["84444.84", "0.000235"], ["84445.25", "0.013757"], ["84445.36", "0.0002"], ["84446.51", "0.000335"], ["84446.56", "0.000253"], ["84446.72", "0.001467"], ["84447.9", "0.0002"], ["84447.98", "0.000612"], ["84448.02", "0.001333"], ["84448.5", "0.071054"], ["84448.96", "0.000235"], ["84449.48", "0.000235"], ["84449.62", "0.000089"], ["84450", "0.000065"], ["84450.13", "0.000199"], ["84450.43", "0.0002"], ["84451.2", "0.000253"], ["84451.37", "0.001467"], ["84451.92", "0.071052"], ["84452.2", "0.000612"], ["84452.24", "0.369082"], ["84452.6", "0.03181"], ["84452.96", "0.0002"], ["84453.6", "0.000235"], ["84454.13", "0.000235"], ["84454.42", "0.11863"], ["84455.01", "0.017796"], ["84455.3", "0.003"], ["84455.85", "0.000253"], ["84455.95", "0.000889"], ["84456.01", "0.001467"], ["84456.42", "0.000612"], ["84456.47", "0.001333"], ["84456.78", "0.031731"], ["84457.17", "0.0045"], ["84457.18", "0.0045"], ["84457.37", "0.0045"], ["84457.38", "0.0045"], ["84458.13", "0.000089"], ["84458.25", "0.000235"], ["84458.46", "0.000089"], ["84458.6", "0.059948"], ["84458.77", "0.000235"], ["84458.88", "0.000823"]], "u": 7510762, "seq": 66889407625}, "cts": 1742142248408, "record_time": 1742142247.509634}
{"topic": "orderbook.200.BTCUSDT", "ts": 1742142248609, "type": "delta", "data": {"s": "BTCUSDT", "b": [["84403.14", "0.116733"], ["84402.31", "0.004886"], ["84401.53", "0.076094"], ["84399.57", "0.000099"], ["84398.93", "0.011848"], ["84397.39", "0.051221"], ["84397.38", "0.059159"], ["84397.24", "0.0002"], ["84396.4", "0.011848"], ["84394.78", "0"], ["84394.77", "0"], ["84394.71", "0.0002"], ["84394.7", "0.050779"], ["84392.18", "0.0002"], ["84391.73", "0.16617"], ["84388.91", "0.048392"], ["84388.9", "0"], ["84388.76", "0.011847"], ["84388.54", "0"], ["84386.36", "0.015726"], ["84385.49", "0.003248"], ["84384.38", "0.160453"], ["84384.37", "0"], ["84384.28", "0"], ["84383.8", "0.04"], ["84383.3", "0.04"], ["84383.19", "0"], ["84383.15", "0.000797"], ["84382.79", "0"], ["84382.71", "0.008453"], ["84381.6", "0.04"], ["84381.59", "0"], ["84380.95", "0"], ["84380.3", "0.048"], ["84378.2", "0.04"], ["84377.86", "0.236958"], ["84376.8", "0.04"], ["84376.5", "0.04"], ["84376.49", "0"], ["84376.35", "0.059506"], ["84375.7", "0"], ["84375.5", "0"], ["84375", "0"], ["84374.06", "0"], ["84372", "0"], ["84371.7", "0"], ["84371.35", "0"], ["84370.2", "0"], ["84370.04", "0.023928"], ["84368.6", "0"], ["84368.5", "0.017771"], ["84368.3", "0"], ["84363.94", "0"], ["84363.9", "0"], ["84357.43", "0.236958"], ["84356.94", "0"], ["84356.34", "0.05"], ["84356.33", "0.026668"], ["84355.89", "0"], ["84353.71", "0.355468"], ["84353.69", "0"], ["84353.22", "0.236958"], ["84351.33", "0"], ["84350.88", "0.023695"], ["84348.2", "0.24702"], ["84345.96", "0"], ["84345.06", "0"]], "a": [["84403.15", "0.004424"], ["84403.38", "0"], ["84404.93", "0.001467"], ["84405.86", "0"], ["84409.89", "0.011846"], ["84410.79", "0"], ["84411.22", "0"], ["84411.52", "0.020085"], ["84413.15", "0"], ["84413.96", "0.071083"], ["84415.58", "0"], ["84415.8", "0"], ["84416.96", "0"], ["84417.1", "0"], ["84418.3", "0"], ["84418.98", "0.105026"], ["84420.05", "0"], ["84420.12", "0.011847"], ["84421.58", "0.139806"], ["84422.42", "0"], ["84422.8", "0"], ["84423.35", "0"], ["84423.88", "0.059948"], ["84423.89", "0"], ["84423.9", "0"], ["84424.27", "0"], ["84427.4", "0.04"], ["84427.61", "0"], ["84427.7", "0.04"], ["84428.36", "0"], ["84428.8", "0.068395"], ["84430.3", "0"], ["84431.76", "0"], ["84432.01", "0"], ["84432.1", "0.005"], ["84432.6", "0.056089"], ["84434.04", "0"], ["84435.58", "0"], ["84436.71", "0.023695"], ["84438.9", "0.009"], ["84441.2", "1.479043"], ["84441.42", "0.118479"], ["84441.72", "0.023695"], ["84444.03", "0"], ["84444.04", "0"], ["84445.13", "0.023695"], ["84445.91", "0.162"], ["84446.43", "0.04"], ["84446.44", "0.04"], ["84447.85", "0.005923"], ["84451.91", "0.355468"], ["84454.36", "0.162"], ["84455.01", "0"], ["84455.95", "0"], ["84460.49", "0.000253"], ["84460.65", "0.000612"], ["84460.66", "0.001467"], ["84460.69", "0.001333"], ["84460.83", "0.068395"], ["84461.02", "0.428893"], ["84462.2", "0.0006"]], "u": 7510763, "seq": 66889408979}, "cts": 1742142248604, "record_time": 1742142247.709051}
{"topic": "orderbook.200.BTCUSDT", "ts": 1742142248810, "type": "delta", "data": {"s": "BTCUSDT", "b": [["84403.14", "0.037827"], ["84402.53", "0"], ["84402.31", "0"], ["84402.3", "0.0193"], ["84401.54", "0"], ["84401.53", "0.005"], ["84397.4", "0.028826"], ["84394.11", "0.000153"], ["84393.24", "0.012606"], ["84392.2", "0"], ["84392.19", "0"], ["84391.74", "0"], ["84391.73", "0"], ["84388.91", "0"], ["84388.76", "0"], ["84388.35", "0.1191"], ["84388.32", "0"], ["84385.49", "0.003"], ["84384.38", "0.090812"], ["84384.16", "0.012096"], ["84382.08", "0.16668"], ["84379.91", "0.171467"], ["84377.86", "0"], ["84377.48", "0"], ["84376.35", "0"], ["84374.24", "0.278893"], ["84373.3", "0"], ["84372.53", "0.109097"], ["84370", "0"], ["84368.92", "0"], ["84368.5", "0"], ["84368.46", "0.000335"], ["84368.34", "0.100282"], ["84364.1", "0.017772"], ["84356.34", "0"], ["84356.33", "0"], ["84356.24", "0.05"], ["84356.23", "0.026668"], ["84356", "0.071132"], ["84353.71", "0"], ["84353.7", "0"], ["84352.79", "0.000987"], ["84352.54", "0.177718"], ["84348.28", "0.355494"], ["84345.96", "0.237128"], ["84345.06", "0.023696"], ["84344.9", "0.000089"], ["84344.76", "0.0237"], ["84344.61", "0.001467"]], "a": [["84407.17", "0.011814"], ["84407.36", "0.011847"], ["84409.58", "0.0293"], ["84410.54", "0.106641"], ["84413.96", "0"], ["84415.25", "0.011848"], ["84415.36", "0"], ["84418.92", "0.107002"], ["84420.12", "0"], ["84423.87", "0.067565"], ["84423.9", "0.06"], ["84425.2", "0.180904"], ["84425.4", "0.044"], ["84426.77", "0.000987"], ["84426.81", "0.005"], ["84427.4", "0.1"], ["84427.69", "0.08915"], ["84429.8", "0.068"], ["84430.4", "0.048"], ["84430.6", "0.048"], ["84433.04", "0.291376"], ["84436.03", "0.03181"], ["84440.29", "0.071061"], ["84440.47", "0.236958"], ["84440.98", "0.024533"], ["84441.42", "0"], ["84444.29", "0.355494"], ["84444.69", "0.223935"], ["84446.56", "0.038127"], ["84451.91", "0"], ["84451.92", "0"], ["84452.6", "0"], ["84453.62", "0.027942"], ["84457.37", "0"], ["84457.38", "0"], ["84458.13", "0"], ["84458.25", "0"], ["84458.46", "0"], ["84458.6", "0"], ["84458.77", "0"], ["84458.88", "0"], ["84460.49", "0"], ["84460.65", "0"], ["84460.66", "0"], ["84460.69", "0"], ["84460.83", "0"], ["84461.02", "0"], ["84462.2", "0"]], "u": 7510764, "seq": 66889409710}, "cts": 1742142248806, "record_time": 1742142247.908691}
{"topic": "orderbook.200.BTCUSDT", "ts": 1742142249010, "type": "delta", "data": {"s": "BTCUSDT", "b": [["84403.14", "0.04729"], ["84395.65", "0.001467"], ["84395.48", "0.000252"], ["84394.7", "0.04906"], ["84394.11", "0"], ["84393.24", "0.080776"], ["84390.53", "0.059948"], ["84390.52", "0.236958"], ["84389.39", "0.14824"], ["84389.38", "0.118069"], ["84389.09", "0.109461"], ["84388.44", "0.112802"], ["84388.35", "0"], ["84387.48", "0.003"], ["84387.28", "0.003"], ["84387.08", "0.003"], ["84386.65", "0.115654"], ["84386.37", "0.001715"], ["84386.3", "0.236958"], ["84384.38", "0.133093"], ["84384.16", "0.011848"], ["84382.16", "0.179164"], ["84382.08", "0"], ["84381.25", "0.165353"], ["84379.91", "0"], ["84378.81", "0.176989"], ["84378.4", "0.159799"], ["84374.32", "0.269478"], ["84374.24", "0"], ["84373.41", "0.283907"], ["84370.97", "0.2896"], ["84368.21", "0.29599"], ["84367.87", "1.431595"], ["84361.42", "0.237128"], ["84357.48", "0"], ["84357.05", "0.05"], ["84357.04", "0.049554"], ["84356.24", "0"], ["84356.23", "0"], ["84353.22", "0.414676"], ["84352.55", "0.592609"], ["84349.38", "0"], ["84349.25", "0"], ["84349.15", "0"], ["84349.08", "0"], ["84348.28", "0"], ["84348.27", "0"], ["84348.2", "0"], ["84347.36", "0"], ["84346.84", "0"], ["84346.75", "0"], ["84346.7", "0"], ["84346.62", "0"], ["84346.35", "0"], ["84345.96", "0"], ["84345.06", "0"], ["84344.9", "0"], ["84344.76", "0"], ["84344.61", "0"]], "a": [["84403.15", "0.019414"], ["84407.17", "0.000235"], ["84415.58", "0.000089"], ["84417", "0.095355"], ["84417.6", "0.113182"], ["84418.1", "0.107563"], ["84418.92", "0"], ["84419.01", "0.110824"], ["84420.05", "0.162"], ["84420.36", "0.106991"], ["84422.5", "0.04"], ["84423.87", "0.146387"], ["84425.2", "0"], ["84425.28", "0.166213"], ["84425.94", "0.174962"], ["84427.4", "0.06"], ["84427.8", "0.056"], ["84428.2", "0.165699"], ["84428.58", "0.160881"], ["84432.46", "0.017796"], ["84432.6", "0.000089"], ["84433.04", "0"], ["84433.12", "0.288348"], ["84433.78", "0.283846"], ["84434.16", "0.017772"], ["84434.57", "0.024185"], ["84436.04", "0.262798"], ["84436.94", "0.236958"], ["84438.77", "0.292072"], ["84438.9", "0.0045"], ["84439.1", "0"], ["84439.35", "0"], ["84440.5", "0"], ["84440.7", "0"], ["84441.16", "0.236958"], ["84444.29", "0"], ["84444.69", "0"], ["84452.23", "0.355481"], ["84452.96", "0"], ["84453.6", "0"], ["84453.62", "0"], ["84454.13", "0"], ["84454.36", "0"], ["84454.42", "0"], ["84455.3", "0"], ["84455.85", "0"], ["84456.01", "0"], ["84456.42", "0"], ["84456.47", "0"], ["84456.78", "0"], ["84457.17", "0"], ["84457.18", "0"]], "u": 7510765, "seq": 66889410125}, "cts": 1742142249007, "record_time": 1742142248.109163}
{"topic": "orderbook.200.BTCUSDT", "ts": 1742142249209, "type": "delta", "data": {"s": "BTCUSDT", "b": [["84403.14", "0.11795"], ["84401.54", "0.026959"], ["84398.4", "0.071097"], ["84397.4", "0"], ["84393.24", "0.151596"], ["84389.8", "0.107166"], ["84389.52", "0.105494"], ["84389.39", "0.082606"], ["84389.38", "0"], ["84389.09", "0"], ["84388.51", "0.117442"], ["84388.44", "0"], ["84386.97", "0.119524"], ["84386.65", "0"], ["84386.37", "0.001467"], ["84382.71", "0.245411"], ["84382.24", "0.160805"], ["84382.16", "0"], ["84381.68", "0.179372"], ["84381.25", "0"], ["84379.91", "0.174439"], ["84379.13", "0.178925"], ["84378.82", "0.181059"], ["84378.81", "0"], ["84378.5", "0.236958"], ["84378.4", "0"], ["84376.98", "0.017796"], ["84374.4", "0.274797"], ["84374.32", "0"], ["84373.84", "0.263596"], ["84373.41", "0"], ["84371.29", "0.273531"], ["84370.97", "0"], ["84369.38", "0"], ["84368.63", "0.299832"], ["84368.35", "0.237128"], ["84368.21", "0"], ["84357.43", "0"], ["84357.05", "0"], ["84357.04", "0"], ["84356.75", "0.05"], ["84356.74", "0.049754"], ["84354.87", "0"], ["84353.23", "0.355473"], ["84353.22", "0.177718"], ["84352.55", "0.237128"], ["84350.88", "0"], ["84350.07", "0"]], "a": [["84403.15", "0.054949"], ["84405.77", "0.003612"], ["84405.89", "0.07109"], ["84409.58", "0.001467"], ["84417", "0"], ["84417.6", "0"], ["84418.01", "0.070088"], ["84418.02", "0.110534"], ["84418.1", "0"], ["84418.53", "0.119315"], ["84418.98", "0.226741"], ["84419.01", "0"], ["84419.09", "0.112201"], ["84420.36", "0"], ["84420.68", "0.11017"], ["84425.28", "0"], ["84425.36", "0.173005"], ["84425.94", "0"], ["84426.37", "0.174794"], ["84426.47", "0.003426"], ["84428.2", "0"], ["84428.52", "0.165591"], ["84428.58", "0"], ["84429", "0.17283"], ["84433.12", "0"], ["84433.2", "0.280955"], ["84433.27", "0.236958"], ["84433.78", "0"], ["84434.21", "0.271181"], ["84436.04", "0"], ["84436.36", "0.29742"], ["84437.49", "0.236958"], ["84438.77", "0"], ["84439.19", "0.262669"], ["84451.37", "0"], ["84452.2", "0"], ["84452.23", "0"], ["84452.24", "0"]], "u": 7510766, "seq": 66889410572}, "cts": 1742142249207, "record_time": 1742142248.308075}
{"topic": "orderbook.200.BTCUSDT", "ts": 1742142249410, "type": "delta", "data": {"s": "BTCUSDT", "b": [["84397.81", "0.000153"], ["84393.24", "0.153618"], ["84389.8", "0.112084"], ["84389.52", "0.107316"], ["84389.39", "0.143368"], ["84388.51", "0.107442"], ["84387.08", "0.003248"], ["84386.97", "0"], ["84386.93", "0.236958"], ["84384.38", "0.25087"], ["84382.24", "0.176533"], ["84381.68", "0"], ["84379.13", "0"], ["84378.82", "0.175966"], ["84378.5", "0"], ["84374.4", "0.284143"], ["84373.84", "0"], ["84371.29", "0"], ["84368.63", "0.283841"], ["84353.24", "0.355466"], ["84353.23", "0"], ["84351.29", "0"], ["84350.88", "0.023695"], ["84350.07", "0.023696"], ["84349.38", "0.023497"], ["84349.25", "0.001467"], ["84349.15", "0.0002"]], "a": [["84418.01", "0.066999"], ["84418.02", "0"], ["84418.53", "0.108059"], ["84419.09", "0.109107"], ["84420.05", "0"], ["84420.68", "0.11045"], ["84425.36", "0.169955"], ["84426.37", "0.177197"], ["84428.52", "0.168979"], ["84429", "0.178556"], ["84433.19", "0.315734"], ["84433.2", "0"], ["84434.21", "0.299577"], ["84436.36", "0.278585"], ["84439.19", "0"], ["84451.37", "0.001467"], ["84452.2", "0.000612"], ["84452.24", "0.369082"]], "u": 7510767, "seq": 66889410864}, "cts": 1742142249402, "record_time": 1742142248.508077}
{"topic": "orderbook.200.BTCUSDT", "ts": 1742142249610, "type": "delta", "data": {"s": "BTCUSDT", "b": [["84402.31", "0.011848"], ["84394.7", "0.04956"], ["84393.24", "0.155603"], ["84389.94", "0.117951"], ["84389.8", "0"], ["84389.65", "0.108268"], ["84389.52", "0"], ["84389.39", "0.203295"], ["84388.68", "0.105522"], ["84388.51", "0"], ["84387.15", "0.119643"], ["84382.41", "0.177876"], ["84382.24", "0"], ["84381.81", "0.181496"], ["84379.31", "0.165288"], ["84378.96", "0.172329"], ["84378.82", "0"], ["84376.51", "0.110399"], ["84374.57", "0.293438"], ["84374.4", "0"], ["84373.97", "0.280244"], ["84371.47", "0.28455"], ["84368.91", "0.023463"], ["84368.77", "0.27617"], ["84368.63", "0"], ["84368.35", "0"], ["84367.88", "0.237128"], ["84356.75", "0"], ["84356.74", "0.0002"], ["84356.65", "0.05"], ["84356.64", "0.049788"], ["84353.25", "0.355473"], ["84353.24", "0"], ["84350.92", "0"], ["84350.88", "0"], ["84350.07", "0"], ["84349.38", "0"], ["84349.25", "0"], ["84349.15", "0"]], "a": [["84407.36", "0"], ["84411.59", "0.0005"], ["84418.01", "0"], ["84418.15", "0.067627"], ["84418.16", "0.114769"], ["84418.53", "0"], ["84418.67", "0.106878"], ["84419.09", "0"], ["84419.26", "0.106822"], ["84420.68", "0"], ["84420.87", "0.114114"], ["84425.36", "0"], ["84425.53", "0.158634"], ["84426.21", "0.023501"], ["84426.37", "0"], ["84426.51", "0.15978"], ["84427", "0.000119"], ["84427.69", "0.248267"], ["84428.52", "0"], ["84428.71", "0.169408"], ["84429", "0"], ["84429.14", "0.169264"], ["84433.37", "0.289059"], ["84434.21", "0"], ["84434.35", "0.29563"], ["84436.36", "0"], ["84436.55", "0.292775"], ["84439.34", "0.29697"], ["84450.43", "0"], ["84451.2", "0"], ["84451.37", "0"], ["84452.2", "0"], ["84452.24", "0"]], "u": 7510768, "seq": 66889410999}, "cts": 1742142249607, "record_time": 1742142248.709069}
{"topic": "orderbook.200.BTCUSDT", "ts": 1742142249809, "type": "delta", "data": {"s": "BTCUSDT", "b": [["84400.88", "0.071094"], ["84398.4", "0"], ["84397.81", "0"], ["84393.24", "0.155477"], ["84390.71", "0.109335"], ["84390.43", "0.116264"], ["84389.94", "0"], ["84389.65", "0.0002"], ["84389.37", "0.107044"], ["84388.68", "0"], ["84387.99", "0.114848"], ["84387.15", "0.000337"], ["84387.08", "0.003"], ["84383.1", "0.179634"], ["84382.59", "0.177019"], ["84382.41", "0"], ["84381.81", "0"], ["84380.15", "0.171459"], ["84379.74", "0.163658"], ["84379.31", "0"], ["84378.96", "0"], ["84375.26", "0.277419"], ["84374.75", "0.289978"], ["84374.57", "0"], ["84373.97", "0"], ["84372.53", "0.243603"], ["84372.31", "0.275641"], ["84371.47", "0"], ["84369.54", "0.284515"], ["84368.77", "0"], ["84353.25", "0"], ["84353.23", "0.355464"], ["84350.96", "0"]], "a": [["84405.89", "0"], ["84408.36", "0.071088"], ["84409.89", "0"], ["84410.54", "0"], ["84418.15", "0"], ["84418.16", "0"], ["84418.67", "0"], ["84418.94", "0.119659"], ["84419.26", "0"], ["84419.44", "0.117476"], ["84419.95", "0.112579"], ["84420.87", "0"], ["84421.71", "0.117765"], ["84423.74", "0.052844"], ["84425.53", "0"], ["84426.23", "0.166375"], ["84426.51", "0"], ["84427.29", "0.168661"], ["84428.71", "0"], ["84429.14", "0"], ["84429.55", "0.158883"], ["84429.92", "0.171705"], ["84433.37", "0"], ["84434.07", "0.267701"], ["84434.35", "0"], ["84435.13", "0.29406"], ["84436.55", "0"], ["84437.39", "0.287324"], ["84439.34", "0"], ["84440.11", "0.284642"], ["84450.43", "0.0002"], ["84451.2", "0.000253"]], "u": 7510769, "seq": 66889411146}, "cts": 1742142249805, "record_time": 1742142248.908723}
{"topic": "orderbook.200.BTCUSDT", "ts": 1742142250010, "type": "delta", "data": {"s": "BTCUSDT", "b": [["84403.14", "0.10423"], ["84402.32", "0.014974"], ["84402.31", "0.00645"], ["84401.54", "0"], ["84400.88", "0"], ["84398.06", "0.000153"], ["84393.24", "0.100307"], ["84390.71", "0"], ["84390.43", "0"], ["84389.37", "0"], ["84388.04", "0.0001"], ["84387.99", "0"], ["84387.55", "0.003"], ["84386.93", "0"], ["84383.1", "0"], ["84382.59", "0"], ["84380.15", "0"], ["84379.91", "0.127839"], ["84379.74", "0"], ["84375.26", "0"], ["84374.75", "0"], ["84372.31", "0"], ["84369.54", "0"], ["84368.91", "0"], ["84367.88", "0"], ["84366.96", "0"], ["84356.95", "0.05"], ["84356.94", "0.049554"], ["84356.65", "0"], ["84356.64", "0.000234"], ["84353.23", "0"], ["84351.29", "0.355477"], ["84350.96", "0.001333"], ["84350.92", "0.000613"], ["84350.88", "0.023695"], ["84350.07", "0.023696"], ["84350.04", "0.0013"], ["84349.25", "0.001467"], ["84349.15", "0.0002"], ["84349.08", "0.000252"], ["84348.27", "0.059067"], ["84348.2", "0.24702"], ["84347.36", "0.000234"], ["84346.84", "0.000234"], ["84346.75", "0.001333"]], "a": [["84405.35", "0.0005"], ["84407.36", "0.011847"], ["84408.36", "0"], ["84409.89", "0.011846"], ["84410.54", "0.106791"], ["84417.26", "0.069598"], ["84418.94", "0"], ["84419.44", "0"], ["84419.95", "0"], ["84420.05", "0.162"], ["84421.58", "0"], ["84421.71", "0"], ["84422.91", "0.139764"], ["84424.57", "0"], ["84426.23", "0"], ["84427.29", "0"], ["84428.27", "0"], ["84429.55", "0"], ["84429.92", "0"], ["84432.33", "0.0008"], ["84434.07", "0"], ["84435.13", "0"], ["84437.39", "0"], ["84440.11", "0"], ["84443.35", "0.0012"], ["84451.37", "0.001467"], ["84452.2", "0.000612"], ["84452.24", "0.369082"], ["84452.96", "0.0002"], ["84453.6", "0.000235"], ["84453.62", "0.027942"], ["84454.13", "0.000235"]], "u": 7510770, "seq": 66889411415}, "cts": 1742142250004, "record_time": 1742142249.109362}
{"topic": "orderbook.200.BTCUSDT", "ts": 1742142250210, "type": "delta", "data": {"s": "BTCUSDT", "b": [["84403.14", "0.014143"], ["84402.32", "0"], ["84402.31", "0"], ["84402.3", "0"], ["84398.93", "0"], ["84398.06", "0"], ["84397.38", "0"], ["84395.47", "0"], ["84393.24", "0.000234"], ["84390.53", "0"], ["84390.52", "0"], ["84389.39", "0.083536"], ["84388.01", "0.071105"], ["84387.48", "0"], ["84387.15", "0.000089"], ["84386.3", "0"], ["84385.69", "0.003248"], ["84384.38", "0.165454"], ["84384.16", "0"], ["84382.71", "0"], ["84379.91", "0"], ["84379.51", "0.118479"], ["84378.87", "0.011848"], ["84378.5", "0.236958"], ["84378.3", "0.008453"], ["84376.51", "0"], ["84372.53", "0.109097"], ["84368.33", "0"], ["84366.94", "0.024122"], ["84364.1", "0"], ["84364.09", "0.005923"], ["84361.42", "0"], ["84361.41", "0"], ["84359.72", "0.017773"], ["84356.95", "0"], ["84356.94", "0"], ["84356.75", "0.05"], ["84356.74", "0.049754"], ["84356.13", "0"], ["84356", "0"], ["84352.54", "0"], ["84351.29", "0"], ["84348.42", "0.071139"], ["84346.7", "0.000613"], ["84346.62", "0.0002"], ["84346.35", "0.000335"], ["84345.96", "0.237128"], ["84345.06", "0.023696"], ["84344.9", "0.000089"], ["84344.76", "0.0237"], ["84344.61", "0.001467"], ["84344.44", "0.000252"], ["84344.09", "0.0002"], ["84343.32", "0.014085"], ["84343.2", "0.001243"], ["84342.81", "0.059948"], ["84342.72", "0.000234"], ["84342.53", "0.001333"]], "a": [["84403.15", "0.2022"], ["84403.98", "0.011847"], ["84405.18", "0.089922"], ["84407.16", "0.024614"], ["84410", "0.011848"], ["84414.77", "0.11798"], ["84415.25", "0"], ["84416.86", "0.089922"], ["84417.26", "0"], ["84418.4", "0.044"], ["84420.22", "0.03181"], ["84421", "0.068395"], ["84423.87", "0.099989"], ["84425.4", "0"], ["84427.69", "0.08915"], ["84428.8", "0"], ["84429.16", "0.017773"], ["84430.25", "0.023012"], ["84430.39", "0.005844"], ["84431.2", "0.089922"], ["84431.46", "0.071069"], ["84432.31", "0.118479"], ["84433.19", "0"], ["84434.16", "0"], ["84434.57", "0"], ["84436.03", "0"], ["84437.49", "0"], ["84438.81", "0.027942"], ["84439.69", "0.355518"], ["84444.78", "0.017796"], ["84448.5", "0"], ["84451.2", "0"], ["84451.37", "0"], ["84452.2", "0"], ["84452.24", "0"], ["84452.96", "0"], ["84453.6", "0"], ["84453.62", "0"], ["84454.13", "0"]], "u": 7510771, "seq": 66889412112}, "cts": 1742142250208, "record_time": 1742142249.309624}
{"topic": "orderbook.200.BTCUSDT", "ts": 1742142250409, "type": "delta", "data": {"s": "BTCUSDT", "b": [["84403.14", "0.001822"], ["84398.42", "0.0193"], ["84397.39", "0.024282"], ["84396.4", "0"], ["84393.24", "0.032566"], ["84389.39", "0"], ["84388.01", "0"], ["84386", "0.000296"], ["84385.69", "0"], ["84385.49", "0"], ["84385.29", "0"], ["84384.67", "0.00086"], ["84384.61", "0.000296"], ["84384.38", "0"], ["84384.14", "0.114839"], ["84383.79", "0.076206"], ["84377.85", "0.168558"], ["84374.29", "0.236958"], ["84371.79", "0"], ["84371.62", "0"], ["84369.99", "0.28788"], ["84369.92", "0.059948"], ["84368.34", "0.53212"], ["84368.17", "0"], ["84367.97", "0"], ["84356.76", "0.236958"], ["84356.75", "0"], ["84356.73", "0.049554"], ["84355.81", "0.071132"], ["84352.54", "0.236958"], ["84345.97", "0.355503"], ["84344.04", "0.162"], ["84343.4", "0.059458"], ["84342.81", "0"], ["84342.72", "0"], ["84342.53", "0"]], "a": [["84405.18", "0"], ["84413.4", "0.005923"], ["84414.77", "0.043424"], ["84414.8", "0.112016"], ["84416.7", "0.04"], ["84417", "0.06"], ["84420.8", "0.04"], ["84421.09", "0.158625"], ["84422.1", "0.056"], ["84422.5", "0"], ["84423.5", "0.048"], ["84423.8", "0.048"], ["84423.9", "0"], ["84427.69", "0.185414"], ["84427.7", "0"], ["84428.95", "0.273278"], ["84429.06", "0.236958"], ["84430.4", "0"], ["84430.6", "0"], ["84432.04", "0.236958"], ["84432.72", "0.236958"], ["84436.25", "0.236958"], ["84439.69", "0"], ["84440.47", "0"], ["84441.16", "0"], ["84444.29", "0.355503"], ["84445.34", "0.47368"], ["84448.96", "0"], ["84449.48", "0"], ["84449.62", "0"], ["84450", "0"], ["84450.13", "0"], ["84450.43", "0"]], "u": 7510772, "seq": 66889412494}, "cts": 1742142250408, "record_time": 1742142249.508522}
{"topic": "orderbook.200.BTCUSDT", "ts": 1742142250610, "type": "delta", "data": {"s": "BTCUSDT", "b": [["84403.14", "0"], ["84401.53", "0"], ["84399.78", "0"], ["84399.75", "0"], ["84399.57", "0"], ["84398.42", "0"], ["84398.41", "0"], ["84397.88", "0"], ["84397.39", "0"], ["84397.37", "0"], ["84397.32", "0"], ["84397.24", "0"], ["84395.65", "0"], ["84395.48", "0"], ["84394.73", "0"], ["84394.71", "0"], ["84394.7", "0"], ["84393.76", "0"], ["84393.75", "0"], ["84393.24", "0"], ["84393.23", "0"], ["84393.15", "0"], ["84393.11", "0"], ["84392.18", "0"], ["84391.01", "0"], ["84391", "0"], ["84390.84", "0"], ["84389.65", "0"], ["84389.12", "0"], ["84388.93", "0"], ["84388.89", "0"], ["84388.04", "0"], ["84387.55", "0"], ["84387.28", "0"], ["84387.15", "0"], ["84387.08", "0"], ["84386.37", "0.002747"], ["84386.36", "0"], ["84386", "0"], ["84385.32", "0.0005"], ["84384.67", "0.000612"], ["84384.61", "0"], ["84384.14", "0"], ["84383.8", "0"], ["84383.79", "0"], ["84383.78", "0"], ["84383.3", "0"], ["84383.15", "0"], ["84382", "0"], ["84381.6", "0"], ["84381.26", "0"], ["84380.96", "0"], ["84380.3", "0"], ["84379.9", "0"], ["84379.51", "0"], ["84378.87", "0"], ["84378.7", "0"], ["84378.5", "0"], ["84378.3", "0"], ["84378.2", "0"], ["84377.92", "0"], ["84377.85", "0"], ["84376.98", "0"], ["84376.8", "0"], ["84376.66", "0"], ["84376.5", "0"], ["84375.34", "0.005"], ["84374.91", "0.012296"], ["84374.29", "0"], ["84372.53", "0"], ["84370.25", "0"], ["84370.04", "0.000234"], ["84369.99", "0"], ["84369.92", "0"], ["84369.48", "0"], ["84368.34", "0"], ["84367.87", "0"], ["84367.07", "0.02"], ["84366.94", "0"], ["84366.8", "0"], ["84366.69", "0.000797"], ["84366.57", "0"], ["84366.1", "0.118499"], ["84365.6", "0.11136"], ["84364.09", "0"], ["84362.81", "0.011851"], ["84360.97", "0.070165"], ["84360.93", "0"], ["84360.26", "0.068395"], ["84359.76", "0"], ["84359.72", "0"], ["84358.42", "0"], ["84357.91", "0.009898"], ["84356.93", "0.167194"], ["84356.92", "0"], ["84356.86", "0"], ["84356.85", "0"], ["84356.76", "0"], ["84356.74", "0.0002"], ["84356.73", "0"], ["84355.81", "0"], ["84354.74", "0.017796"], ["84354.56", "0"], ["84353.22", "0"], ["84352.55", "0"], ["84352.54", "0"], ["84351.28", "0"], ["84350.88", "0"], ["84350.07", "0"], ["84349.89", "0.005924"], ["84348.42", "0"], ["84348.27", "0"], ["84348.2", "0"], ["84345.97", "0"], ["84345.96", "0"], ["84345.45", "0.05"], ["84345.06", "0"], ["84344.65", "0.05"], ["84343.94", "0.017776"], ["84343.91", "0.023702"], ["84343.32", "0"], ["84342.81", "0.059948"], ["84342.72", "0.000234"], ["84342.53", "0.001333"], ["84342.52", "0.162"], ["84342.49", "0.000613"], ["84342.2", "0.003589"], ["84341.56", "0.0002"], ["84341", "0.000119"], ["84340.37", "0.00466"], ["84340", "0.0006"], ["84339.97", "0.025167"], ["84339.8", "0.000252"], ["84339.15", "0.390262"], ["84339.03", "0.0002"], ["84338.31", "0.001333"], ["84338.27", "0.000613"], ["84338.08", "0.000234"], ["84337.68", "0.005925"], ["84337.56", "0.000234"], ["84336.52", "0.071149"], ["84336.45", "0.000089"], ["84335.33", "0.001467"], ["84335.16", "0.000252"], ["84334.2", "0.24702"], ["84334.1", "0.001333"], ["84334.05", "0.000613"], ["84334", "0.0237"], ["84333.45", "0.000234"], ["84333.19", "0.0237"], ["84333.14", "0.0025"], ["84332.92", "0.000234"], ["84332.8", "0.001335"], ["84332.38", "0.015"], ["84332.3", "0.001243"], ["84332.18", "0.005924"], ["84332.16", "0.237128"], ["84330.69", "0.001467"], ["84330.65", "0.089922"], ["84330.53", "0.000252"], ["84330.39", "0.059948"], ["84329.88", "0.001333"], ["84329.85", "1.777306"], ["84329.84", "0.000613"], ["84328.82", "0.000089"], ["84328.81", "0.000233"], ["84328.77", "0.009491"], ["84328.28", "0.000233"], ["84328.19", "0.0237"], ["84328", "0.000089"], ["84327.89", "0.023703"], ["84326.85", "0.01404"], ["84326.07", "0.068395"], ["84326.06", "0.001467"], ["84325.89", "0.000252"], ["84325.66", "0.001333"], ["84325.62", "0.000613"], ["84325.51", "0.237128"], ["84324.52", "0.000357"], ["84324.24", "0.000335"], ["84324.17", "0.000233"], ["84323.65", "0.000233"], ["84323.42", "0.236999"], ["84321.45", "0.001333"], ["84321.42", "0.001467"], ["84321.4", "0.001856"], ["84321.25", "0.000252"], ["84321.19", "0.04"], ["84321.18", "0.039645"], ["84321.06", "0.646659"], ["84319.56", "0.237128"], ["84319.55", "0.000089"], ["84319.54", "0.059948"], ["84319.53", "0.000233"], ["84319.2", "0.236999"], ["84319.01", "0.000233"], ["84318.5", "0.089922"], ["84318.47", "0.015"], ["84317.23", "0.001333"], ["84317.19", "0.000613"], ["84317.02", "0.035976"], ["84316.97", "0.005"], ["84316.78", "0.001467"]], "a": [["84388.61", "0.10358"], ["84388.94", "0.023216"], ["84389.12", "0.201403"], ["84389.13", "0.060874"], ["84389.66", "0.028507"], ["84391.01", "0.05"], ["84391.29", "0.359689"], ["84391.89", "0.005"], ["84392.18", "0.0002"], ["84392.34", "0.011851"], ["84393.11", "0.000613"], ["84393.15", "0.001333"], ["84393.16", "0.030234"], ["84393.76", "0.260645"], ["84394.22", "0.002276"], ["84394.71", "0.0002"], ["84394.74", "0.112357"], ["84394.97", "0.339769"], ["84395.48", "0.000252"], ["84395.49", "0.06"], ["84395.65", "0.001467"], ["84395.66", "0.247128"], ["84396.32", "0.005"], ["84396.73", "0.107226"], ["84397.32", "0.000613"], ["84397.37", "0.016471"], ["84397.38", "0.0006"], ["84397.88", "0.000234"], ["84397.89", "0.156173"], ["84398.41", "0.000234"], ["84398.56", "0.000089"], ["84398.75", "0.023698"], ["84399.78", "0.0006"], ["84400.13", "0.000252"], ["84400.29", "0.001467"], ["84400.34", "0.03181"], ["84400.62", "0.011848"], ["84401", "0.0006"], ["84401.51", "0.059948"], ["84401.52", "0.237128"], ["84401.54", "0.000613"], ["84401.59", "0.001333"], ["84402.2", "0.117229"], ["84402.21", "0.162"], ["84402.31", "0.165442"], ["84402.52", "0.000234"], ["84402.61", "0.168901"], ["84402.65", "0.068395"], ["84403.05", "0.000234"], ["84403.15", "0.036778"], ["84403.99", "0.024781"], ["84406.11", "0.005924"], ["84407.07", "0.000089"], ["84407.16", "0"], ["84407.36", "0.006512"], ["84407.58", "0.017022"], ["84408", "0.06"], ["84408.5", "0.020084"], ["84408.62", "0.237128"], ["84409.89", "0"], ["84409.98", "0.0005"], ["84410", "0"], ["84410.49", "0.269689"], ["84411.24", "0.023702"], ["84411.52", "0"], ["84411.59", "0"], ["84411.6", "0.162"], ["84411.81", "0.002581"], ["84412.32", "0.059488"], ["84413.23", "0.00951"], ["84413.85", "0.004666"], ["84413.91", "0.059948"], ["84414.77", "0.083601"], ["84414.8", "0"], ["84415.17", "0.027942"], ["84416.12", "0.005924"], ["84417.5", "0.0482"], ["84418.4", "0.162499"], ["84418.97", "0.355589"], ["84419.02", "0.0008"], ["84419.82", "0.023698"], ["84420", "0.06"], ["84420.22", "0"], ["84420.7", "0.068"], ["84421", "0"], ["84421.09", "0.000235"], ["84423.5", "0"], ["84424.15", "0.071075"], ["84424.83", "0.023699"], ["84425.23", "0.023699"], ["84426.21", "0"], ["84426.81", "0"], ["84427.14", "0.068395"], ["84427.4", "0"], ["84427.69", "0.285651"], ["84427.8", "0"], ["84428.21", "0.013997"], ["84428.24", "0.023699"], ["84428.95", "0"], ["84429.06", "0"], ["84429.16", "0"], ["84430.25", "0"], ["84430.79", "0.47368"], ["84430.86", "0"], ["84430.96", "0.005924"], ["84431.46", "0"], ["84431.81", "0.368082"], ["84432.04", "0"], ["84432.1", "0"], ["84432.31", "0"], ["84432.33", "0"], ["84432.47", "0.322897"], ["84432.48", "0"], ["84432.63", "0.427337"], ["84432.72", "0"], ["84433.27", "0"], ["84434.83", "0"], ["84435.36", "0"], ["84435.55", "0"], ["84436.25", "0"], ["84436.71", "0"], ["84436.88", "0"], ["84436.94", "0"], ["84437.27", "0"], ["84437.33", "0"], ["84437.44", "0"], ["84437.46", "0"], ["84437.76", "0"], ["84438.81", "0"], ["84438.9", "0"], ["84439.48", "0"], ["84439.53", "0"], ["84439.58", "0"], ["84439.67", "0"], ["84439.7", "0"], ["84440.19", "0"], ["84440.29", "0"], ["84440.3", "0"], ["84440.98", "0"], ["84441.11", "0"], ["84441.2", "0"], ["84441.72", "0"], ["84441.74", "0"], ["84441.91", "0"], ["84442.08", "0"], ["84442.24", "0"], ["84442.38", "0"], ["84442.83", "0"], ["84443.35", "0"], ["84443.76", "0"], ["84443.8", "0"], ["84443.9", "0"], ["84444.29", "0"], ["84444.3", "0"], ["84444.31", "0"], ["84444.78", "0"], ["84444.84", "0"], ["84445.13", "0"], ["84445.25", "0"], ["84445.34", "0"], ["84445.36", "0"], ["84445.91", "0"], ["84446.43", "0"], ["84446.44", "0"], ["84446.51", "0"], ["84446.56", "0"], ["84446.72", "0"], ["84447.85", "0"], ["84447.9", "0"], ["84447.98", "0"], ["84448.02", "0"]], "u": 7510773, "seq": 66889415133}, "cts": 1742142250607, "record_time": 1742142249.70983}
{"topic": "orderbook.200.BTCUSDT", "ts": 1742142250809, "type": "delta", "data": {"s": "BTCUSDT", "b": [["84388.6", "0"], ["84387.12", "0"], ["84386.37", "0"], ["84386.2", "0"], ["84385.32", "0"], ["84384.71", "0"], ["84384.67", "0"], ["84384.59", "0"], ["84384.48", "0"], ["84383.96", "0"], ["84376.31", "0.013157"], ["84375.34", "0"], ["84374.91", "0"], ["84374.9", "0"], ["84374.51", "0.015731"], ["84373.61", "0.0005"], ["84373.1", "0.04"], ["84372.41", "0.047914"], ["84372.4", "0.062927"], ["84370.25", "0.000089"], ["84370.21", "0.000554"], ["84369.98", "0"], ["84367.3", "0.04"], ["84367.07", "0"], ["84366.35", "0.005"], ["84366.12", "0.000296"], ["84366.1", "0"], ["84365.6", "0"], ["84365.01", "0.000296"], ["84364.2", "0.04"], ["84362.81", "0"], ["84362.25", "0.117388"], ["84360.97", "0.042084"], ["84360.94", "0"], ["84360.26", "0"], ["84358.58", "0.011851"], ["84357.4", "0.118509"], ["84356.93", "0"], ["84356.39", "0.008453"], ["84356.14", "0.068395"], ["84354.74", "0"], ["84352.79", "0"], ["84352.6", "0.019095"], ["84352.3", "0.139761"], ["84346.32", "1.466727"], ["84345.45", "0"], ["84344.65", "0"], ["84343.94", "0"], ["84342.53", "0.177632"], ["84339.76", "0.05"], ["84339.75", "0.04956"], ["84339.15", "0"], ["84338.79", "0.017777"], ["84338.47", "0.059028"], ["84336.52", "0"], ["84336.5", "0.0002"], ["84335.6", "0.162"], ["84334.32", "0.000988"], ["84333.97", "0.0002"], ["84328.77", "0"], ["84327.16", "0.162"], ["84324.71", "0.071159"], ["84323.42", "0"], ["84320.7", "0.071162"], ["84319.21", "0.355621"], ["84319.2", "0"], ["84318.72", "0.162"], ["84317.02", "0"], ["84316.97", "0"], ["84316.78", "0"]], "a": [["84382.06", "0.133623"], ["84382.14", "0.005"], ["84382.31", "0.113933"], ["84382.32", "0.359689"], ["84384.72", "0.003555"], ["84386.37", "0.217433"], ["84386.38", "0.359689"], ["84387.12", "0.0052"], ["84387.21", "0.01185"], ["84388.01", "0.011851"], ["84388.6", "0.000234"], ["84388.61", "0"], ["84388.89", "0.000613"], ["84388.93", "0.001333"], ["84388.94", "0"], ["84389.11", "0.237128"], ["84389.12", "0.000234"], ["84389.13", "0.04"], ["84389.65", "0.0002"], ["84389.66", "0"], ["84390.59", "0.011849"], ["84390.84", "0.000252"], ["84391", "0.112237"], ["84391.01", "0.001467"], ["84391.29", "0"], ["84391.89", "0"], ["84392.18", "0.000299"], ["84392.34", "0"], ["84392.97", "0.119465"], ["84393.16", "0"], ["84393.24", "0.000234"], ["84393.48", "0.162"], ["84393.75", "0.110528"], ["84393.76", "0.000234"], ["84394.74", "0"], ["84394.97", "0"], ["84395.19", "0.068395"], ["84395.66", "0.237128"], ["84396.32", "0"], ["84396.73", "0"], ["84397.24", "0.0002"], ["84397.37", "0.001333"], ["84397.38", "0"], ["84397.89", "0.110886"], ["84399.3", "0.020084"], ["84399.78", "0.0002"], ["84399.91", "0.008453"], ["84400.13", "0.0005"], ["84400.21", "0.13976"], ["84400.61", "0.037779"], ["84400.62", "0"], ["84402.2", "0.136125"], ["84402.31", "0.0002"], ["84402.61", "0"], ["84402.65", "0"], ["84403.51", "0.080337"], ["84403.6", "0.06"], ["84403.98", "0"], ["84403.99", "0.024533"], ["84404.33", "0.023174"], ["84405.64", "0.0008"], ["84406.81", "0.017777"], ["84407.36", "0"], ["84408.1", "0.044"], ["84408.14", "0.019104"], ["84408.36", "0.000988"], ["84408.5", "0"], ["84408.67", "0.071088"], ["84410.49", "0"], ["84410.55", "0"], ["84411.6", "0.218"], ["84412.19", "0.368082"], ["84413.9", "0.355617"], ["84415.17", "0"], ["84416.5", "0.071081"], ["84417", "0"], ["84418.4", "0.044"], ["84418.97", "0"], ["84419.02", "0"], ["84422.1", "0"], ["84422.91", "0"], ["84424.15", "0"], ["84424.24", "0.47368"], ["84425.23", "0"], ["84425.35", "0.0237"], ["84425.99", "0.027942"], ["84426.08", "0"], ["84426.16", "0"], ["84426.77", "0"], ["84429.8", "0"], ["84430.79", "0"], ["84431.81", "0"], ["84432.79", "0"], ["84433.14", "0"], ["84433.18", "0"], ["84433.71", "0"], ["84434.18", "0"], ["84434.2", "0"], ["84435.02", "0"], ["84435.23", "0"], ["84435.31", "0"]], "u": 7510774, "seq": 66889416601}, "cts": 1742142250807, "record_time": 1742142249.909495}
{"topic": "orderbook.200.BTCUSDT", "ts": 1742142251009, "type": "delta", "data": {"s": "BTCUSDT", "b": [["84382.05", "0"], ["84378.48", "0.000099"], ["84376.34", "0.000296"], ["84376.33", "0.027523"], ["84376.32", "0.028696"], ["84376.31", "0"], ["84373.61", "0"], ["84373.3", "0.04906"], ["84373.29", "0.0005"], ["84373.1", "0"], ["84372.41", "0.044517"], ["84369.07", "0.003"], ["84368.87", "0.003"], ["84368.78", "0.089792"], ["84368.67", "0.003"], ["84367.39", "0.001"], ["84367.31", "0.026904"], ["84367.3", "0"], ["84365.8", "0.048"], ["84365.7", "0.04"], ["84365.6", "0.04"], ["84365.01", "0"], ["84364", "0.04"], ["84363.78", "0.071126"], ["84363.7", "0.04"], ["84363.19", "0.108602"], ["84362.67", "0.116405"], ["84362.26", "0.054328"], ["84362.25", "0"], ["84360.97", "0"], ["84360.3", "0.04"], ["84359.3", "0.04"], ["84358.9", "0.04"], ["84356.76", "0.237018"], ["84356.37", "0.175663"], ["84352.54", "0.237018"], ["84352.17", "0.179353"], ["84348.49", "0.293287"], ["84346.68", "0.00351"], ["84343.4", "0"], ["84342.53", "0.001333"], ["84342.2", "0.000234"], ["84341.93", "0.266065"], ["84339.76", "0"], ["84339.75", "0"], ["84338.46", "0.05"], ["84338.45", "0.049551"], ["84334.2", "0"], ["84331.77", "0.071153"], ["84331.44", "0.0002"], ["84324.52", "0"], ["84324.24", "0"], ["84324.17", "0"], ["84323.65", "0"], ["84321.45", "0"], ["84321.42", "0"], ["84321.4", "0"], ["84321.25", "0"], ["84321.19", "0"], ["84321.18", "0"], ["84321.06", "0"], ["84320.7", "0"], ["84319.56", "0"], ["84319.55", "0"], ["84319.54", "0"], ["84319.53", "0"], ["84319.21", "0"], ["84319.01", "0"], ["84318.72", "0"], ["84318.5", "0"], ["84318.47", "0"], ["84317.23", "0"], ["84317.19", "0"]], "a": [["84381.74", "0.051834"], ["84382.06", "0.07111"], ["84384.22", "0.01185"], ["84384.59", "0.0002"], ["84384.72", "0"], ["84388.48", "0.011849"], ["84390.59", "0"], ["84391", "0.07781"], ["84391.55", "0.106591"], ["84392.18", "0.0002"], ["84392.97", "0"], ["84397.89", "0.215465"], ["84398.22", "0.059254"], ["84399.3", "0.020332"], ["84399.8", "0.04"], ["84400.13", "0.000252"], ["84400.2", "0.06"], ["84402.57", "0.179288"], ["84405.3", "0.056"], ["84406.6", "0.048"], ["84406.9", "0.048"], ["84407.56", "0.295783"], ["84407.58", "0.137628"], ["84407.79", "0.118509"], ["84408", "0"], ["84408.3", "0.04"], ["84410.54", "0.395348"], ["84410.95", "0.237017"], ["84411.62", "0.237018"], ["84412.32", "0"], ["84412.81", "0.280982"], ["84413.9", "0"], ["84415.17", "0.237017"], ["84415.84", "0.237018"], ["84416.7", "0"], ["84417.49", "0.355607"], ["84417.5", "0.0002"], ["84418.4", "0"], ["84420", "0"], ["84423.8", "0"], ["84423.92", "0.47368"], ["84424.24", "0"], ["84427.69", "0"], ["84431.13", "0"], ["84431.2", "0"], ["84432.38", "0"], ["84432.46", "0"], ["84432.47", "0"], ["84432.58", "0"], ["84432.6", "0"], ["84432.62", "0"], ["84432.63", "0"], ["84432.7", "0"]], "u": 7510775, "seq": 66889417031}, "cts": 1742142251007, "record_time": 1742142250.109086}
{"topic": "orderbook.200.BTCUSDT", "ts": 1742142251209, "type": "delta", "data": {"s": "BTCUSDT", "b": [["84394.21", "0.054158"], ["84393.1", "0.06"], ["84389.1", "0.087027"], ["84387.2", "0.000153"], ["84386.5", "0.000959"], ["84386.36", "0.054158"], ["84385.95", "0.07066"], ["84384.21", "0.027079"], ["84382.13", "0.027079"], ["84382.05", "0.081237"], ["84381.74", "0.009853"], ["84381.73", "0.056386"], ["84379.95", "0.089922"], ["84379.52", "0.0052"], ["84376.35", "0.027298"], ["84376.32", "0"], ["84374.99", "0.000248"], ["84374.53", "0.028547"], ["84374.52", "0.089922"], ["84374.51", "0"], ["84373.29", "0.1625"], ["84372.46", "0.059948"], ["84372.41", "0.020091"], ["84372.4", "0"], ["84368.78", "0"], ["84367.31", "0.051352"], ["84367.18", "0.120344"], ["84366.35", "0"], ["84365.8", "0"], ["84364.85", "0.162"], ["84364.2", "0"], ["84364.07", "0.116078"], ["84364", "0"], ["84363.78", "0"], ["84363.19", "0"], ["84362.67", "0"], ["84362.26", "0"], ["84361.53", "0.089922"], ["84361.2", "0.04"], ["84359.3", "0.08"], ["84358.58", "0"], ["84357.53", "0.023698"], ["84357.4", "0"], ["84356.76", "0"], ["84356.39", "0"], ["84356.37", "0"], ["84356.14", "0"], ["84356.02", "0.17563"], ["84355.92", "0.169391"], ["84355.9", "0.118509"], ["84353.63", "0.175419"], ["84352.61", "0.237018"], ["84352.54", "0"], ["84352.17", "0"], ["84351.72", "0.300178"], ["84351.3", "0.003527"], ["84350.94", "0.008787"], ["84348.49", "0"], ["84348.33", "0.017796"], ["84347.98", "0.292265"], ["84347.7", "0.005815"], ["84347.36", "0.220793"], ["84346.68", "0"], ["84346.33", "0.237018"], ["84345.47", "0.292751"], ["84341.93", "0"], ["84340.31", "0.39059"], ["84339.54", "0.024011"], ["84338.89", "0.071147"], ["84338.79", "0"], ["84338.46", "0"], ["84338.45", "0"], ["84337.96", "0.05"], ["84337.95", "0.040667"], ["84335.61", "0.355548"], ["84331.77", "0"], ["84329.85", "0"], ["84328.81", "0"], ["84328.28", "0"], ["84328.19", "0"], ["84328", "0"], ["84327.89", "0"], ["84327.16", "0"], ["84326.85", "0"], ["84326.07", "0"], ["84326.06", "0"], ["84325.89", "0"], ["84325.66", "0"], ["84325.62", "0"], ["84325.51", "0"], ["84324.71", "0"]], "a": [["84381.74", "0"], ["84382.06", "0"], ["84382.14", "0"], ["84382.31", "0"], ["84382.32", "0"], ["84384.22", "0"], ["84384.59", "0"], ["84386.37", "0"], ["84386.38", "0"], ["84387.12", "0"], ["84387.21", "0"], ["84388.01", "0"], ["84388.48", "0"], ["84388.6", "0"], ["84388.89", "0"], ["84388.93", "0"], ["84389.11", "0"], ["84389.12", "0"], ["84389.13", "0"], ["84389.65", "0"], ["84390.84", "0"], ["84391", "0"], ["84391.01", "0"], ["84391.55", "0"], ["84392.18", "0"], ["84393.11", "0"], ["84393.15", "0"], ["84393.24", "0"], ["84393.48", "0"], ["84393.75", "0"], ["84393.76", "0"], ["84395.19", "0"], ["84395.49", "0"], ["84395.66", "0"], ["84396.08", "0.005"], ["84396.14", "0.113446"], ["84397.89", "0"], ["84398.22", "0"], ["84398.56", "0"], ["84398.66", "0.111469"], ["84399.3", "0"], ["84399.8", "0"], ["84399.91", "0"], ["84400.2", "0"], ["84400.21", "0"], ["84400.34", "0"], ["84400.61", "0.097033"], ["84401.03", "0.001"], ["84401.51", "0"], ["84401.52", "0"], ["84402.2", "0"], ["84402.21", "0"], ["84402.57", "0"], ["84403.51", "0"], ["84403.6", "0"], ["84404.7", "0.068"], ["84405.3", "0"], ["84405.64", "0"], ["84406.6", "0"], ["84406.7", "0.179832"], ["84406.81", "0"], ["84406.9", "0"], ["84407.41", "0.171456"], ["84407.55", "0.258044"], ["84407.56", "0"], ["84407.58", "0"], ["84407.79", "0"], ["84408.14", "0"], ["84408.3", "0"], ["84408.62", "0"], ["84408.67", "0"], ["84410.95", "0"], ["84411.6", "0"], ["84411.62", "0"], ["84412.19", "0"], ["84412.81", "0"], ["84412.95", "0.005"], ["84413.91", "0"], ["84413.92", "0"], ["84414.75", "0.269514"], ["84415.17", "0"], ["84415.84", "0"], ["84416.5", "0"], ["84416.86", "0"], ["84417.49", "0"], ["84417.86", "0.301048"], ["84418.98", "0.105026"], ["84418.99", "0"], ["84419.81", "0.023698"], ["84420.7", "0"], ["84420.8", "0"], ["84423.62", "0.0008"], ["84423.74", "0"], ["84423.88", "0"], ["84425.99", "0"], ["84427", "0"], ["84427.14", "0"], ["84431.13", "0.001333"], ["84431.2", "0.089922"], ["84432.38", "0.015"], ["84432.47", "0.322897"], ["84432.58", "0.000357"], ["84432.6", "0.000089"], ["84432.62", "0.000253"], ["84432.63", "0.427337"], ["84432.7", "0.0002"], ["84432.79", "0.001467"], ["84433.14", "0.0025"], ["84433.18", "0.059948"], ["84433.71", "0.023696"], ["84434.18", "0.11863"], ["84434.2", "0.068"], ["84435.02", "0.000235"], ["84435.09", "0.020401"], ["84435.23", "0.0002"], ["84435.31", "0.000612"], ["84435.36", "0.001333"], ["84435.55", "0.000235"], ["84435.7", "0.009"], ["84435.9", "0.009"], ["84436.71", "0.023695"], ["84437.27", "0.000253"], ["84437.44", "0.001467"], ["84437.46", "0.001"], ["84437.76", "0.0002"], ["84438.9", "0.0045"], ["84439.48", "0.002062"], ["84439.53", "0.000612"], ["84439.58", "0.001333"], ["84439.67", "0.000235"], ["84439.7", "0.246059"], ["84440.19", "0.000235"], ["84440.3", "0.0002"], ["84440.98", "0.024533"], ["84441.11", "0.000089"], ["84441.72", "0.023695"], ["84441.74", "0.059948"], ["84441.91", "0.000253"], ["84441.99", "0.368082"], ["84442.08", "0.001467"], ["84442.24", "0.023695"], ["84442.38", "0.000158"], ["84442.83", "0.0002"], ["84443.35", "0.0012"], ["84443.76", "0.000612"], ["84443.8", "0.001333"], ["84443.9", "0.002703"], ["84444.3", "0.11863"], ["84444.31", "0.000235"], ["84444.78", "0.017796"], ["84444.84", "0.000235"], ["84445.13", "0.023695"], ["84445.16", "0.0237"], ["84445.36", "0.0002"], ["84446.43", "0.04"], ["84446.44", "0.04"], ["84446.51", "0.000335"], ["84446.56", "0.000253"], ["84446.72", "0.001467"], ["84447.85", "0.005923"], ["84447.98", "0.000612"], ["84448.02", "0.001333"], ["84448.96", "0.000235"], ["84449.48", "0.000235"], ["84449.62", "0.000089"], ["84450", "0.000065"]], "u": 7510776, "seq": 66889417669}, "cts": 1742142251207, "record_time": 1742142250.309968}
{"topic": "orderbook.200.BTCUSDT", "ts": 1742142251409, "type": "delta", "data": {"s": "BTCUSDT", "b": [["84395.47", "0.016327"], ["84394.64", "0.008658"], ["84394.25", "0.027392"], ["84394.24", "0.024676"], ["84394.21", "0.07566"], ["84393.1", "0"], ["84392.72", "0.001394"], ["84392.18", "0.0002"], ["84391.26", "0.011849"], ["84389.99", "0.005"], ["84389.1", "0"], ["84388.73", "0.011849"], ["84387.2", "0"], ["84387.05", "0.015156"], ["84387.04", "0.04906"], ["84387.03", "0.0005"], ["84386.36", "0"], ["84385.95", "0"], ["84384.21", "0"], ["84382.13", "0"], ["84382.05", "0"], ["84381.74", "0.0004"], ["84381.73", "0.008814"], ["84381.64", "0.003"], ["84381.44", "0.003"], ["84381.24", "0.003"], ["84379.95", "0"], ["84379.52", "0.0002"], ["84378.7", "0.000089"], ["84378.48", "0"], ["84376.4", "0.000296"], ["84376.39", "0.01174"], ["84376.35", "0"], ["84376.33", "0.135194"], ["84376.3", "0.04"], ["84376.02", "0.163518"], ["84375.56", "0.008453"], ["84374.99", "0"], ["84374.53", "0"], ["84374.52", "0"], ["84374.5", "0.04"], ["84373.73", "0.175419"], ["84373.3", "0"], ["84373.29", "0.162"], ["84372.9", "0.04"], ["84372.47", "0.0399"], ["84372.41", "0"], ["84372.3", "0.04"], ["84371.93", "0.000448"], ["84371.82", "0.019095"], ["84370.5", "0.04"], ["84370.21", "0"], ["84369.42", "0.23698"], ["84368.78", "0.089548"], ["84368.1", "0.048"], ["84367.18", "0"], ["84366.12", "0"], ["84365.6", "0"], ["84365.2", "0.23698"], ["84364.07", "0"], ["84363.7", "0"], ["84360.3", "0"], ["84359.55", "0.014928"], ["84359.41", "0.023451"], ["84356.73", "0.023699"], ["84356.02", "0"], ["84355.92", "0"], ["84355.9", "0"], ["84353.84", "0.323198"], ["84353.63", "0"], ["84352.62", "0.28086"], ["84352.61", "0"], ["84352.6", "0"], ["84351.73", "0.237018"], ["84351.72", "0"], ["84347.98", "0"], ["84347.18", "0.07114"], ["84345.47", "0"], ["84344.59", "0.071142"], ["84344.05", "0.355514"], ["84343.91", "0"], ["84343.89", "0.000987"], ["84340.32", "0.237018"], ["84339.54", "0"], ["84339.5", "0.24702"], ["84338.89", "0"], ["84337.68", "0.181344"], ["84335.61", "0"], ["84334.32", "0"], ["84331.86", "0.23698"], ["84331.44", "0"], ["84330.69", "0"], ["84330.65", "0"], ["84330.53", "0"], ["84330.39", "0"], ["84329.88", "0"], ["84329.84", "0"], ["84328.82", "0"]], "a": [["84394.22", "0"], ["84394.71", "0"], ["84395.48", "0.013433"], ["84396.08", "0"], ["84396.14", "0"], ["84397.79", "0.00011"], ["84398.66", "0"], ["84398.75", "0"], ["84400.61", "0"], ["84401", "0.010988"], ["84401.59", "0.013181"], ["84402.66", "0.0005"], ["84403.05", "0.017379"], ["84403.14", "0.022431"], ["84404.33", "0"], ["84404.7", "0"], ["84406.11", "0"], ["84406.7", "0"], ["84406.77", "0.01174"], ["84407.37", "0.029647"], ["84407.39", "0.094219"], ["84407.4", "0.237018"], ["84407.41", "0"], ["84407.55", "0"], ["84408.36", "0"], ["84409.98", "0"], ["84410.1", "0.04"], ["84410.54", "0"], ["84411.24", "0"], ["84412.95", "0"], ["84413.88", "0.237018"], ["84414", "0.06"], ["84414.74", "0.236141"], ["84414.75", "0"], ["84414.77", "0"], ["84415.42", "0.139757"], ["84415.7", "0.056"], ["84416.12", "0"], ["84417.83", "0.000987"], ["84417.86", "0"], ["84418.98", "0"], ["84418.99", "0.237018"], ["84419.81", "0.056554"], ["84423.6", "0"], ["84423.86", "0.059948"], ["84423.92", "0"], ["84424.09", "0.023787"], ["84424.31", "0.118492"], ["84424.78", "0.175419"], ["84425.26", "0.017611"], ["84425.35", "0"], ["84427.61", "0.019104"], ["84427.76", "0.071072"], ["84429.01", "0.084887"], ["84430.02", "0.008453"], ["84432.47", "0"], ["84435.09", "0"], ["84435.24", "0.071066"], ["84437.46", "0.163"], ["84438.27", "0.005"], ["84439.69", "0.355509"], ["84445.9", "0.162"], ["84448.65", "0.0045"], ["84448.66", "0.0045"], ["84448.85", "0.0045"], ["84448.86", "0.0045"], ["84449.62", "0"], ["84450", "0"]], "u": 7510777, "seq": 66889418736}, "cts": 1742142251408, "record_time": 1742142250.509074}
{"topic": "orderbook.200.BTCUSDT", "ts": 1742142251609, "type": "delta", "data": {"s": "BTCUSDT", "b": [["84395.47", "0.114124"], ["84394.25", "0"], ["84394.24", "0"], ["84394.22", "0.01534"], ["84394.21", "0.005"], ["84391.9", "0.000099"], ["84390", "0.027392"], ["84389.65", "0.0002"], ["84387.12", "0.0002"], ["84387.06", "0.03819"], ["84384.59", "0.0002"], ["84382.35", "0.000296"], ["84382.05", "0.0002"], ["84381.78", "0.027143"], ["84381.77", "0.028003"], ["84381.76", "0.059948"], ["84381.73", "0.008014"], ["84381.05", "0.015728"], ["84378.95", "0.019477"], ["84378.94", "0.062915"], ["84378.5", "0.04"], ["84378", "0.04"], ["84376.81", "0.144603"], ["84376.34", "0"], ["84376.33", "0"], ["84376.23", "0.000859"], ["84376.02", "0"], ["84373", "0.04"], ["84372.3", "0"], ["84371.93", "0.0002"], ["84371.6", "0.04"], ["84371.2", "0.04"], ["84369.42", "0"], ["84368.78", "0"], ["84365.7", "0"], ["84365.2", "0"], ["84361.78", "0.071127"], ["84361.2", "0"], ["84359.41", "0"], ["84359.3", "0"], ["84356.85", "0.023697"], ["84354.56", "0.005924"], ["84354.38", "0.071134"], ["84353.85", "0.28214"], ["84352.63", "0.355491"], ["84352.62", "0"], ["84350.88", "0.023697"], ["84350.07", "0.023697"], ["84348.33", "0"], ["84347.18", "0"], ["84345.06", "0.023697"], ["84344.59", "0"], ["84344.05", "0"], ["84336.08", "0.23698"], ["84334.05", "0"], ["84334", "0"], ["84333.97", "0"], ["84333.45", "0"], ["84333.19", "0"], ["84333.14", "0"], ["84332.92", "0"], ["84332.8", "0"], ["84332.38", "0"], ["84332.3", "0"], ["84332.18", "0"], ["84332.16", "0"], ["84331.86", "0"]], "a": [["84395.48", "0.016249"], ["84397.79", "0"], ["84401", "0.0006"], ["84401.59", "0.001333"], ["84403.05", "0.000234"], ["84403.14", "0"], ["84406.33", "0.020085"], ["84406.77", "0"], ["84407.37", "0.0002"], ["84408.1", "0"], ["84408.44", "0.080339"], ["84410.1", "0"], ["84412.15", "0.009716"], ["84413.23", "0"], ["84413.87", "0.091721"], ["84414", "0"], ["84414.2", "0.04"], ["84414.74", "0"], ["84415.7", "0.068"], ["84419.82", "0"], ["84420.34", "0.017796"], ["84424.83", "0"], ["84425.26", "0"], ["84427.76", "0"], ["84428.24", "0"], ["84430.43", "0.014575"], ["84430.75", "0.02024"], ["84438.27", "0"], ["84438.84", "0.071063"], ["84439.69", "0"], ["84443.13", "0.005"], ["84444.29", "0.355491"], ["84449.62", "0.000089"], ["84450", "0.000065"], ["84450.13", "0.000199"], ["84451.2", "0.000253"]], "u": 7510778, "seq": 66889419859}, "cts": 1742142251607, "record_time": 1742142250.707813}
{"topic": "orderbook.200.BTCUSDT", "ts": 1742142251809, "type": "delta", "data": {"s": "BTCUSDT", "b": [["84397.36", "0.514999"], ["84397.31", "0.000153"], ["84396.53", "0.011848"], ["84395.87", "0.025487"], ["84395.86", "0.071099"], ["84395.47", "0"], ["84394.71", "0.0002"], ["84394.22", "0"], ["84393.11", "0.000613"], ["84391.01", "0.001467"], ["84390.84", "0.000252"], ["84390", "0"], ["84389.12", "0.000234"], ["84388.93", "0.001333"], ["84388.92", "0.0005"], ["84388.89", "0.000613"], ["84388.73", "0"], ["84388.6", "0.000234"], ["84388.47", "0.11894"], ["84388.17", "0.116443"], ["84387.15", "0.000089"], ["84387.06", "0"], ["84387.05", "0.081767"], ["84387.03", "0"], ["84386.37", "0.001467"], ["84386.2", "0.000252"], ["84384.71", "0.001333"], ["84384.67", "0.000613"], ["84384.61", "0.093544"], ["84384.6", "0.059429"], ["84384.48", "0.000234"], ["84383.96", "0.000234"], ["84383.84", "0.015727"], ["84382.53", "0.175419"], ["84382.07", "0.009761"], ["84381.78", "0"], ["84381.77", "0"], ["84381.74", "0"], ["84381.73", "0.001467"], ["84381.05", "0"], ["84380.57", "0.001045"], ["84380.06", "0.172743"], ["84378.96", "0.000296"], ["84378.95", "0.041042"], ["84377.11", "0.161471"], ["84376.7", "0.04"], ["84376.64", "0.009898"], ["84376.4", "0"], ["84376.39", "0"], ["84376.23", "0.000611"], ["84375", "0.048"], ["84373.73", "0"], ["84373.64", "0.236975"], ["84372.47", "0.058912"], ["84371.95", "0.27932"], ["84370.73", "0.017796"], ["84369.42", "0.236975"], ["84366.69", "0"], ["84366.57", "0.293122"], ["84363.87", "0.014642"], ["84361.79", "0.06734"], ["84359.55", "0"], ["84359.36", "0.02469"], ["84358.91", "0.392809"], ["84358.9", "0"], ["84357.91", "0"], ["84357.53", "0"], ["84356.86", "0.237018"], ["84353.99", "0.004637"], ["84352.63", "0"], ["84352.54", "0.177731"], ["84350.96", "0.051333"], ["84350.95", "0.035189"], ["84350", "0.2"], ["84349.89", "0"], ["84347.04", "0.000987"], ["84343.89", "0"], ["84342.52", "0"], ["84342.49", "0"], ["84342.2", "0"], ["84341.56", "0"], ["84341", "0"], ["84340.37", "0"], ["84340.32", "0"], ["84340.31", "0"], ["84340", "0"], ["84339.97", "0"], ["84339.8", "0"], ["84339.5", "0"], ["84339.03", "0"], ["84338.47", "0"], ["84338.31", "0"], ["84338.27", "0"], ["84338.08", "0"], ["84337.96", "0"], ["84337.95", "0"], ["84337.68", "0"], ["84337.56", "0"], ["84336.5", "0"], ["84336.45", "0"], ["84336.08", "0"], ["84335.6", "0"], ["84335.33", "0"], ["84335.16", "0"], ["84334.1", "0"]], "a": [["84395.48", "0"], ["84395.65", "0"], ["84397.24", "0"], ["84397.32", "0"], ["84397.37", "0.014514"], ["84399.1", "0.00011"], ["84406.33", "0"], ["84407.39", "0"], ["84407.4", "0"], ["84409.1", "0.020085"], ["84413.85", "0"], ["84414.2", "0"], ["84415.41", "0.06551"], ["84415.7", "0"], ["84417.65", "0.110599"], ["84417.83", "0"], ["84418", "0.044"], ["84418.17", "0.119344"], ["84418.98", "0.125889"], ["84419.81", "0"], ["84420.1", "0.06"], ["84420.2", "0.06"], ["84420.98", "0.000987"], ["84421.5", "0.068"], ["84424.31", "0"], ["84424.7", "0.048"], ["84425.1", "0.0482"], ["84425.53", "0.023697"], ["84426.28", "0.165087"], ["84427.72", "0.00951"], ["84427.91", "0.004667"], ["84428.21", "0"], ["84429.01", "0.26199"], ["84430.01", "0.118487"], ["84430.96", "0"], ["84431.79", "0.022919"], ["84434.39", "0.263569"], ["84435.24", "0"], ["84439.55", "0.291761"], ["84441.21", "0.037595"], ["84442.33", "0.014002"], ["84444.29", "0"], ["84445.46", "0.03181"], ["84446.4", "0.071056"], ["84447.56", "0.005"], ["84447.9", "0.0002"], ["84448.66", "0"], ["84448.85", "0"], ["84448.86", "0"], ["84448.96", "0"], ["84449.48", "0"], ["84449.62", "0"], ["84450", "0"], ["84450.13", "0"], ["84451.2", "0"]], "u": 7510779, "seq": 66889421236}, "cts": 1742142251806, "record_time": 1742142250.909066}
{"topic": "orderbook.200.BTCUSDT", "ts": 1742142252010, "type": "delta", "data": {"s": "BTCUSDT", "b": [["84397.36", "0.444339"], ["84395.86", "0"], ["84391.9", "0"], ["84389.41", "0.236997"], ["84388.48", "0.203821"], ["84388.47", "0"], ["84388.17", "0"], ["84387.96", "0.0001"], ["84387.47", "0.118806"], ["84387.17", "0.107773"], ["84387.05", "0"], ["84386.04", "0.237006"], ["84385.42", "0.116809"], ["84385.34", "0.106782"], ["84385.22", "0.003"], ["84385.02", "0.003"], ["84384.82", "0.003"], ["84384.61", "0.09965"], ["84381.76", "0.060196"], ["84381.43", "0.236974"], ["84380.57", "0.000797"], ["84380.07", "0.14403"], ["84380.06", "0"], ["84379.06", "0.163903"], ["84378.95", "0"], ["84378.85", "0.172607"], ["84377.86", "0.236974"], ["84377.32", "0.165683"], ["84377.22", "0.236974"], ["84377.11", "0"], ["84376.12", "0.16127"], ["84374.95", "0.008907"], ["84372.47", "0.216763"], ["84371.95", "0"], ["84370.96", "0.293433"], ["84370.75", "0.281592"], ["84370.5", "0"], ["84369.42", "0"], ["84369.21", "0.266478"], ["84368.1", "0"], ["84367.31", "0.131105"], ["84366.57", "0"], ["84365.58", "0.293186"], ["84361.93", "0.237018"], ["84358.91", "0.037341"], ["84352.96", "0.05"], ["84352.95", "0.028367"], ["84351.78", "0.355483"], ["84350.96", "0.001333"], ["84350.95", "0"], ["84350.94", "0"], ["84350.04", "0"], ["84350", "0"], ["84349.96", "0.0013"], ["84348.74", "0.236974"], ["84347.22", "0.237115"], ["84346.35", "0"], ["84346.33", "0"], ["84346.32", "0"], ["84345.06", "0"], ["84344.9", "0"], ["84344.76", "0"], ["84344.61", "0"], ["84344.44", "0"], ["84344.09", "0"], ["84344.04", "0"], ["84343.2", "0"], ["84342.81", "0"], ["84342.72", "0"], ["84342.53", "0"]], "a": [["84399.1", "0"], ["84401.37", "0.0003"], ["84405.35", "0"], ["84407.07", "0"], ["84415.41", "0.118808"], ["84415.42", "0"], ["84416.66", "0.10971"], ["84416.96", "0.118172"], ["84417.17", "0.111639"], ["84417.65", "0"], ["84418.17", "0"], ["84419.7", "0.04"], ["84420.29", "0.111297"], ["84422.96", "0.023188"], ["84423.45", "0.176572"], ["84423.87", "0.1702"], ["84425.2", "0.056"], ["84425.28", "0.173959"], ["84426.28", "0"], ["84428.01", "0.168747"], ["84428.4", "0.172611"], ["84429", "0.184767"], ["84429.01", "0"], ["84431.56", "0.293661"], ["84433.39", "0.29367"], ["84434.39", "0"], ["84436.5", "0.286035"], ["84436.94", "0.236974"], ["84438.55", "0.273144"], ["84439.37", "0.0013"], ["84439.55", "0"], ["84441.16", "0.236974"], ["84443.35", "0"], ["84446.51", "0"], ["84446.56", "0"], ["84446.72", "0"], ["84447.56", "0"], ["84447.85", "0"], ["84447.9", "0"], ["84447.98", "0"], ["84448.02", "0"], ["84448.65", "0"]], "u": 7510780, "seq": 66889421470}, "cts": 1742142252007, "record_time": 1742142251.108984}
{"topic": "orderbook.200.BTCUSDT", "ts": 1742142252209, "type": "delta", "data": {"s": "BTCUSDT", "b": [["84397.36", "0.016174"], ["84397.31", "0"], ["84395.87", "0"], ["84393.74", "0.000099"], ["84393.05", "0.030527"], ["84393.04", "0.027439"], ["84393.03", "0.071101"], ["84392.45", "0.000153"], ["84389.43", "0.000296"], ["84389.42", "0.189426"], ["84388.48", "0"], ["84387.73", "0.102224"], ["84387.47", "0"], ["84387.17", "0"], ["84385.42", "0"], ["84385.34", "0"], ["84384.61", "0.220752"], ["84383.46", "0.109389"], ["84383.16", "0.119665"], ["84382.05", "0.000448"], ["84381.76", "0.059948"], ["84381.43", "0"], ["84381.17", "0.116313"], ["84379.06", "0"], ["84378.96", "0"], ["84378.85", "0"], ["84377.86", "0"], ["84377.32", "0"], ["84377.22", "0"], ["84376.12", "0"], ["84375.05", "0.167628"], ["84374.41", "0.02"], ["84374.06", "0.236974"], ["84373.64", "0"], ["84373.22", "0.02"], ["84373.06", "0.160927"], ["84372.11", "0.16481"], ["84370.96", "0"], ["84370.75", "0"], ["84369.84", "0.236974"], ["84369.21", "0"], ["84366.94", "0.276015"], ["84365.58", "0"], ["84365.2", "0.236974"], ["84364.95", "0.300256"], ["84361.78", "0"], ["84361.56", "0.28253"], ["84361.05", "1.494749"], ["84360.98", "0.236974"], ["84353.16", "0.05"], ["84353.15", "0.034297"], ["84352.96", "0"], ["84352.95", "0"], ["84351.78", "0"], ["84350.46", "0.071137"], ["84348.74", "0"], ["84347.37", "0.355493"], ["84346.75", "0"], ["84346.7", "0"], ["84346.62", "0"]], "a": [["84397.88", "0.009439"], ["84398.33", "0.071097"], ["84400.99", "0.00011"], ["84402.66", "0"], ["84405.81", "0.001833"], ["84407.37", "0.030477"], ["84407.58", "0.040041"], ["84412.65", "0.106058"], ["84412.92", "0.078056"], ["84413.16", "0.118693"], ["84413.87", "0"], ["84415.4", "0.059948"], ["84416.03", "0.112116"], ["84416.66", "0"], ["84416.96", "0"], ["84417.17", "0"], ["84418.98", "0.219194"], ["84419.11", "0.139753"], ["84420.1", "0.1"], ["84420.29", "0"], ["84421.27", "0.16906"], ["84423.45", "0"], ["84424", "0.173986"], ["84424.14", "0.1732"], ["84424.61", "0.03181"], ["84425.28", "0"], ["84428.01", "0"], ["84428.07", "0.264016"], ["84428.4", "0"], ["84428.93", "0.236974"], ["84429", "0"], ["84429.38", "0.291727"], ["84431.56", "0"], ["84431.57", "0.071069"], ["84432.25", "0.27774"], ["84432.72", "0.236974"], ["84433.15", "0.236974"], ["84433.39", "0"], ["84434.54", "0.284483"], ["84436.5", "0"], ["84438.55", "0"], ["84441.16", "0"], ["84445.46", "0"], ["84445.9", "0"], ["84446.4", "0"], ["84446.43", "0"], ["84446.44", "0"]], "u": 7510781, "seq": 66889421913}, "cts": 1742142252205, "record_time": 1742142251.308014}
{"topic": "orderbook.200.BTCUSDT", "ts": 1742142252409, "type": "delta", "data": {"s": "BTCUSDT", "b": [["84393.05", "0.030596"], ["84384.61", "0.189244"], ["84384.01", "0.003"], ["84383.81", "0.003"], ["84383.46", "0"], ["84383.16", "0"], ["84382.35", "0.000544"], ["84382.05", "0.0002"], ["84381.64", "0"], ["84381.44", "0"], ["84381.24", "0"], ["84381.17", "0"], ["84380.07", "0.043677"], ["84376.81", "0.295917"], ["84375.05", "0"], ["84374.82", "0.02"], ["84374.16", "0.02"], ["84373.52", "0.02"], ["84373.44", "0.162118"], ["84373.22", "0"], ["84373.06", "0"], ["84372.11", "0"], ["84369.07", "0"], ["84368.87", "0"], ["84368.67", "0"], ["84366.94", "0"], ["84365.2", "0"], ["84364.95", "0"], ["84361.56", "0"], ["84360.98", "0"], ["84347.37", "0"], ["84346.75", "0.001333"], ["84346.7", "0.000613"], ["84346.62", "0.0002"], ["84346.35", "0.000335"], ["84346.33", "0.237018"], ["84345.06", "0.023697"], ["84344.9", "0.000089"], ["84344.76", "0.0237"], ["84344.61", "0.001467"], ["84344.44", "0.000252"], ["84344.09", "0.0002"], ["84343.9", "0.24702"], ["84343.2", "0.001243"]], "a": [["84397.37", "0.022114"], ["84404.11", "0.000871"], ["84412.22", "0.116798"], ["84412.64", "0.137115"], ["84412.65", "0"], ["84412.92", "0"], ["84413.16", "0"], ["84415.41", "0.06551"], ["84416.03", "0"], ["84421.27", "0"], ["84423.87", "0.242397"], ["84424", "0"], ["84424.14", "0"], ["84427", "0.000119"], ["84428.06", "0.369891"], ["84428.07", "0"], ["84429.38", "0"], ["84432.04", "0.074066"], ["84432.25", "0"], ["84434.54", "0"], ["84435.9", "0.0045"], ["84438.9", "0"], ["84446.43", "0.04"], ["84446.44", "0.04"], ["84446.51", "0.000335"], ["84446.56", "0.000253"], ["84446.72", "0.001467"], ["84447.56", "1.450601"]], "u": 7510782, "seq": 66889422096}, "cts": 1742142252404, "record_time": 1742142251.508975}
{"topic": "orderbook.200.BTCUSDT", "ts": 1742142252609, "type": "delta", "data": {"s": "BTCUSDT", "b": [["84400.28", "0.112947"], ["84397.37", "0.01562"], ["84397.36", "0.071347"], ["84397.24", "0.0002"], ["84395.48", "0.000252"], ["84395.42", "0.071099"], ["84394.12", "0.000153"], ["84393.76", "0.000234"], ["84393.24", "0.000234"], ["84393.15", "0.001333"], ["84393.06", "0.015287"], ["84393.05", "0.000069"], ["84393.04", "0"], ["84393.03", "0"], ["84392.45", "0"], ["84391.84", "0.0005"], ["84389.99", "0"], ["84388.92", "0"], ["84387.04", "0.008745"], ["84384.61", "0.098825"], ["84382.53", "0.175667"], ["84382.35", "0.000296"], ["84381.82", "0.062909"], ["84378.94", "0"], ["84374.82", "0"], ["84374.41", "0"], ["84374.16", "0"], ["84373.64", "0.236974"], ["84373.52", "0"], ["84373.44", "0"], ["84372.47", "0"], ["84371.61", "0.2671"], ["84369.42", "0.236974"], ["84367.31", "0"], ["84361.67", "0.071128"], ["84350.46", "0"], ["84348.74", "0.177731"], ["84347.37", "0.355496"], ["84344.44", "0"], ["84344.09", "0"], ["84343.9", "0"], ["84343.2", "0"]], "a": [["84397.37", "0"], ["84397.88", "0"], ["84398.33", "0"], ["84398.41", "0"], ["84399.78", "0"], ["84400.13", "0"], ["84404.11", "0"], ["84407.37", "0.0002"], ["84407.58", "0"], ["84412.22", "0"], ["84412.64", "0.078056"], ["84415.39", "0.034072"], ["84415.4", "0"], ["84415.41", "0"], ["84420.05", "0"], ["84423.87", "0"], ["84425.6", "1.475359"], ["84428.06", "0"], ["84431.57", "0"], ["84432.04", "0"], ["84432.72", "0"], ["84442.83", "0.071259"], ["84445.9", "0.162"], ["84446.42", "0.355495"], ["84447.56", "0.005"], ["84447.85", "0.005923"], ["84447.9", "0.0002"], ["84447.98", "0.000612"], ["84448.02", "0.001333"], ["84448.66", "0.0045"], ["84448.69", "0.000889"], ["84448.86", "0.0045"], ["84448.96", "0.000235"], ["84449.48", "0.000235"], ["84449.62", "0.000089"], ["84450", "0.000065"], ["84450.13", "0.000199"], ["84450.34", "0.0045"]], "u": 7510783, "seq": 66889422514}, "cts": 1742142252608, "record_time": 1742142251.707826}
{"topic": "orderbook.200.BTCUSDT", "ts": 1742142252810, "type": "delta", "data": {"s": "BTCUSDT", "b": [["84400.28", "0.190496"], ["84399.45", "0.011848"], ["84398.71", "0.021329"], ["84398.7", "0.071096"], ["84397.37", "0"], ["84397.36", "0"], ["84395.42", "0.000069"], ["84394.12", "0"], ["84393.74", "0"], ["84393.06", "0"], ["84393.05", "0"], ["84391.85", "0.079931"], ["84391.84", "0.04956"], ["84391.26", "0"], ["84390.37", "0.105997"], ["84390.08", "0.114734"], ["84389", "0.109459"], ["84387.04", "0"], ["84386.79", "0.015726"], ["84384.59", "0.000448"], ["84383.9", "0.04"], ["84383.84", "0"], ["84383.38", "0.162"], ["84382.65", "0.160539"], ["84382.53", "0.175419"], ["84382.14", "0.167353"], ["84381.9", "0.04"], ["84380.07", "0"], ["84379.25", "0.165978"], ["84376.5", "0.02"], ["84374.71", "0.28566"], ["84374.2", "0.285465"], ["84371.62", "0.251981"], ["84371.61", "0"], ["84369.14", "0.023697"], ["84368.93", "0.278702"], ["84364.86", "0.04866"], ["84364.03", "0.323159"], ["84361.79", "0.507347"], ["84355.36", "0.05"], ["84355.35", "0.040353"], ["84353.84", "0"], ["84353.16", "0"], ["84353.15", "0"], ["84349.97", "0.04"], ["84349.96", "0.040947"], ["84349.9", "0.000987"], ["84348.75", "0.355489"], ["84347.37", "0"], ["84347.22", "0"], ["84347.04", "0"], ["84346.84", "0"], ["84346.75", "0"], ["84346.7", "0"], ["84346.62", "0"], ["84346.35", "0"], ["84346.33", "0"], ["84345.06", "0"], ["84344.9", "0"], ["84344.76", "0"], ["84344.61", "0"]], "a": [["84400.29", "0.004148"], ["84400.99", "0"], ["84408.44", "0"], ["84409.1", "0"], ["84411.99", "0.020084"], ["84414.1", "0.080337"], ["84415.39", "0.016087"], ["84418.95", "0.106654"], ["84419.46", "0.119243"], ["84419.48", "0.537414"], ["84419.97", "0.117554"], ["84420.98", "0"], ["84421.24", "0.118285"], ["84422.96", "0"], ["84423.92", "0.000987"], ["84424.61", "0"], ["84424.77", "0.535391"], ["84425.53", "0"], ["84426.32", "0.175443"], ["84427.4", "0.159474"], ["84428.92", "0.202728"], ["84430.07", "0.178623"], ["84432.62", "0.285363"], ["84434.26", "0.286389"], ["84435.34", "0.297588"], ["84435.35", "0.03181"], ["84436.94", "0"], ["84437.37", "0.236966"], ["84440.39", "0.275064"], ["84441.21", "0"], ["84442.73", "0.04"], ["84442.74", "0.04"], ["84445.89", "0.355491"], ["84446.42", "0"], ["84446.43", "0"], ["84446.44", "0"], ["84446.56", "0.038126"], ["84448.66", "0"], ["84448.69", "0"], ["84448.86", "0"], ["84448.96", "0"], ["84449.48", "0"], ["84449.62", "0"], ["84450", "0"], ["84450.13", "0"], ["84450.34", "0"]], "u": 7510784, "seq": 66889423108}, "cts": 1742142252803, "record_time": 1742142251.909078}
{"topic": "orderbook.200.BTCUSDT", "ts": 1742142253010, "type": "delta", "data": {"s": "BTCUSDT", "b": [["84400.28", "0.026726"], ["84398.8", "0.000153"], ["84398.71", "0"], ["84398.7", "0"], ["84396.66", "0.000099"], ["84396.54", "0.016628"], ["84395.65", "0.001467"], ["84395.42", "0"], ["84394.72", "0.027769"], ["84391.87", "0.023825"], ["84391.86", "0.027869"], ["84391.85", "0.000069"], ["84390.37", "0"], ["84390.08", "0"], ["84389", "0"], ["84387.2", "0.003"], ["84387", "0.003"], ["84386.8", "0.003"], ["84384.71", "0.001581"], ["84384.61", "0.271594"], ["84384.59", "0.0002"], ["84383.6", "0.04"], ["84383.38", "0"], ["84382.65", "0"], ["84382.2", "0.04"], ["84382.14", "0"], ["84380.4", "0.048"], ["84380.2", "0.04"], ["84379.25", "0"], ["84378.6", "0.04"], ["84377.3", "0.04"], ["84377.22", "0.221999"], ["84376.8", "0.04"], ["84376.5", "0"], ["84376.4", "0.02"], ["84376.3", "0"], ["84374.71", "0"], ["84374.5", "0"], ["84374.2", "0"], ["84373", "0"], ["84372.9", "0"], ["84371.6", "0"], ["84368.93", "0"], ["84361.67", "0"], ["84353.42", "0.11"], ["84350.54", "0.071137"], ["84348.75", "0"], ["84348.55", "0.2"], ["84347.36", "0"]], "a": [["84400.29", "0.002681"], ["84403.91", "0.00011"], ["84405.81", "0.001333"], ["84407.02", "0.013402"], ["84407.03", "0.010691"], ["84408.73", "0.0005"], ["84411.81", "0.025117"], ["84417.19", "0.162"], ["84418.95", "0"], ["84418.98", "0.439964"], ["84419.46", "0"], ["84419.97", "0"], ["84421.24", "0"], ["84425.39", "0.023373"], ["84426.32", "0"], ["84427.4", "0"], ["84430.07", "0"], ["84432.72", "0.236966"], ["84434.26", "0"], ["84435.34", "0"], ["84435.7", "0.0045"], ["84435.9", "0"], ["84436.94", "0.236966"], ["84437.37", "0"], ["84440.39", "0"], ["84444.29", "0.355506"], ["84445.89", "0"], ["84448.69", "0.000889"], ["84448.96", "0.000235"], ["84449.48", "0.000235"], ["84449.62", "0.000089"]], "u": 7510785, "seq": 66889423547}, "cts": 1742142253008, "record_time": 1742142252.10843}
{"topic": "orderbook.200.BTCUSDT", "ts": 1742142253210, "type": "delta", "data": {"s": "BTCUSDT", "b": [["84400.28", "0.071511"], ["84399.16", "0.000153"], ["84398.8", "0"], ["84396.54", "0.035901"], ["84394.72", "0"], ["84393.89", "0.071169"], ["84391.87", "0.015444"], ["84391.86", "0"], ["84391.85", "0"], ["84389.42", "0.261567"], ["84386.73", "0.113569"], ["84386.44", "0.118852"], ["84385.25", "0.111962"], ["84384.71", "0.001333"], ["84384.67", "0.000861"], ["84384.61", "0.148552"], ["84384.11", "0.109533"], ["84378.93", "0.168536"], ["84378.54", "0.166213"], ["84378", "0"], ["84376.7", "0"], ["84376.6", "0.02"], ["84376.4", "0"], ["84376.22", "0.174343"], ["84375.67", "0.160319"], ["84375", "0"], ["84371.62", "0"], ["84371.2", "0"], ["84371.04", "0.289854"], ["84370.64", "0.30014"], ["84368.32", "0.28309"], ["84365.4", "0.299919"], ["84355.36", "0"], ["84355.35", "0"], ["84354.86", "0.05"], ["84354.85", "0.036178"], ["84353.42", "0"], ["84348.74", "0"], ["84348.55", "0"], ["84347.7", "0"]], "a": [["84400.54", "0.071095"], ["84415.16", "0.118758"], ["84415.39", "0.062676"], ["84415.67", "0.11875"], ["84416.06", "0.109323"], ["84418.08", "0.118409"], ["84422.38", "0.171673"], ["84423.56", "0.163662"], ["84425.98", "0.176534"], ["84426.22", "0.16996"], ["84430.28", "0.274261"], ["84431.46", "0.29103"], ["84433.88", "0.277432"], ["84436.49", "0.278825"], ["84442.73", "0"], ["84442.74", "0"], ["84443.03", "0.04"], ["84443.04", "0.04"], ["84444.29", "0"], ["84446.51", "0"], ["84446.56", "0"], ["84446.72", "0"], ["84447.56", "0"], ["84447.85", "0"], ["84447.9", "0"], ["84447.98", "0"], ["84448.02", "0"], ["84448.69", "0"], ["84448.96", "0"], ["84449.48", "0"], ["84449.62", "0"]], "u": 7510786, "seq": 66889423780}, "cts": 1742142253206, "record_time": 1742142252.307806}
{"topic": "orderbook.200.BTCUSDT", "ts": 1742142253410, "type": "delta", "data": {"s": "BTCUSDT", "b": [["84400.28", "0.071198"], ["84399.16", "0"], ["84387.39", "0.003"], ["84386.73", "0"], ["84386.72", "0.109543"], ["84386.44", "0"], ["84386.43", "0.118724"], ["84385.25", "0"], ["84385.24", "0.113483"], ["84384.11", "0.110665"], ["84378.93", "0"], ["84378.92", "0.176868"], ["84378.54", "0"], ["84378.53", "0.15979"], ["84376.22", "0"], ["84376.21", "0.158363"], ["84375.67", "0"], ["84375.66", "0.179713"], ["84371.05", "0.331958"], ["84371.04", "0"], ["84371.02", "0.294129"], ["84370.64", "0"], ["84370.63", "0.264939"], ["84368.32", "0"], ["84368.31", "0.26822"], ["84365.4", "0.000234"], ["84365.39", "0.278117"], ["84355.66", "0.05"], ["84355.65", "0.036177"], ["84354.86", "0"], ["84354.85", "0"], ["84352.58", "0.04"], ["84352.57", "0.039644"], ["84349.97", "0"], ["84349.96", "0.0013"], ["84349.25", "0"], ["84349.15", "0"], ["84349.08", "0"]], "a": [["84400.29", "0.002991"], ["84415.15", "0.117325"], ["84415.16", "0"], ["84415.39", "0.160797"], ["84415.65", "0.11"], ["84415.67", "0"], ["84416.05", "0.105479"], ["84416.06", "0"], ["84418.07", "0.113698"], ["84418.08", "0"], ["84419.11", "0"], ["84422.36", "0.177228"], ["84422.38", "0"], ["84423.55", "0.171639"], ["84423.56", "0"], ["84424.81", "0.009011"], ["84425.97", "0.161031"], ["84425.98", "0"], ["84426.21", "0.175699"], ["84426.22", "0"], ["84430.26", "0.275893"], ["84430.28", "0"], ["84431.45", "0.288128"], ["84431.46", "0"], ["84433.87", "0.267743"], ["84433.88", "0"], ["84436.48", "0.264074"], ["84436.49", "0"], ["84436.94", "0"], ["84442.48", "0.473696"], ["84442.63", "0.04"], ["84442.64", "0.04"], ["84443.03", "0"], ["84443.04", "0"], ["84445.89", "0.355502"], ["84445.9", "0"]], "u": 7510787, "seq": 66889423912}, "cts": 1742142253403, "record_time": 1742142252.509047}
{"topic": "orderbook.200.BTCUSDT", "ts": 1742142253610, "type": "delta", "data": {"s": "BTCUSDT", "b": [["84409.57", "0.158636"], ["84407.69", "0.000234"], ["84407.37", "0.0002"], ["84407.17", "0.000234"], ["84405.81", "0.001333"], ["84405.76", "0.000613"], ["84404.93", "0.001467"], ["84404.77", "0.000252"], ["84403.16", "0.035322"], ["84403.14", "0.002119"], ["84403.05", "0.000234"], ["84403.04", "0.054399"], ["84402.89", "0.110983"], ["84402.69", "0.008453"], ["84402.61", "0.11308"], ["84402.52", "0.000234"], ["84402.31", "0.0002"], ["84402.15", "0.113169"], ["84401.59", "0.001333"], ["84401.54", "0.000613"], ["84401.13", "0.04906"], ["84400.29", "0.001867"], ["84400.28", "0"], ["84400.13", "0.000252"], ["84399.78", "0.0002"], ["84399.75", "0.108452"], ["84399.45", "0"], ["84398.41", "0.000234"], ["84397.88", "0.000234"], ["84397.37", "0.001333"], ["84397.32", "0.000613"], ["84396.57", "0.06019"], ["84396.55", "0.059948"], ["84396.54", "0"], ["84396.53", "0"], ["84395.95", "0.175449"], ["84395.69", "0.010405"], ["84395.6", "0.000089"], ["84395.1", "0.04"], ["84394.86", "0.181343"], ["84394.72", "0.059506"], ["84394.7", "0.0005"], ["84394.64", "0"], ["84394.21", "0"], ["84393.89", "0"], ["84392.68", "0.118674"], ["84392.67", "0.162"], ["84392.5", "0.015795"], ["84392.07", "0.175419"], ["84392.03", "0.159763"], ["84391.99", "0.177531"], ["84391.87", "0"], ["84391.84", "0"], ["84391.7", "0.04"], ["84391.01", "0.001715"], ["84389.94", "0.062902"], ["84389.6", "0.04"], ["84389.42", "0.261677"], ["84389.41", "0"], ["84388.3", "0.04"], ["84387.73", "0"], ["84387.1", "0.315218"], ["84386.79", "0"], ["84386.72", "0"], ["84386.5", "0"], ["84386.43", "0"], ["84386.3", "0.04"], ["84386.04", "0"], ["84385.24", "0"], ["84384.67", "0.000613"], ["84384.6", "0"], ["84384.23", "0.271384"], ["84384.11", "0"], ["84383.38", "0.162"], ["84382.53", "0"], ["84382.07", "0"], ["84381.95", "0.292037"], ["84381.82", "0"], ["84381.77", "0.089922"], ["84381.11", "0.118483"], ["84380.2", "0"], ["84378.93", "0.2042"], ["84378.92", "0"], ["84378.62", "0.139719"], ["84378.6", "0"], ["84378.55", "0.015608"], ["84378.53", "0"], ["84378.09", "0.023694"], ["84377.22", "0"], ["84376.6", "0"], ["84376.21", "0"], ["84375.66", "0"], ["84375.56", "0"], ["84374.34", "0.071117"], ["84374.25", "0.323119"], ["84374.06", "0"], ["84373.65", "0.237018"], ["84373.64", "0"], ["84373.22", "0.005924"], ["84373.21", "0.020784"], ["84371.02", "0"], ["84370.63", "0"], ["84369.99", "0.071121"], ["84369.84", "0"], ["84369.42", "0"], ["84369.14", "0"], ["84368.33", "0.225819"], ["84368.31", "0"], ["84367.85", "0.004574"], ["84365.4", "0.355659"], ["84365.39", "0"], ["84364.86", "0"], ["84364.03", "0"], ["84363.87", "0"], ["84362.52", "0.005923"], ["84361.64", "0.023693"], ["84359.3", "0.24702"], ["84356.73", "0"], ["84354.38", "0"], ["84354.21", "0"], ["84353.99", "0"], ["84353.89", "0"], ["84353.85", "0"], ["84353.72", "0"], ["84353.35", "0"], ["84352.58", "0"], ["84352.57", "0"], ["84352.54", "0"], ["84352.49", "0"], ["84352.3", "0"], ["84352", "0"], ["84351.77", "0"], ["84351.73", "0"], ["84351.68", "0"], ["84351.63", "0"], ["84351.48", "0"], ["84351.3", "0"], ["84350.96", "0"], ["84350.92", "0"], ["84350.88", "0"], ["84350.54", "0"], ["84350.07", "0"], ["84349.96", "0"], ["84349.9", "0"]], "a": [["84400.29", "0"], ["84400.54", "0"], ["84401", "0"], ["84401.03", "0"], ["84401.37", "0"], ["84401.54", "0"], ["84401.59", "0"], ["84402.31", "0"], ["84402.52", "0"], ["84403.05", "0"], ["84403.15", "0"], ["84403.91", "0"], ["84403.99", "0"], ["84404.77", "0"], ["84404.8", "0"], ["84404.84", "0"], ["84404.93", "0"], ["84405.77", "0"], ["84405.81", "0"], ["84406.3", "0"], ["84406.44", "0"], ["84407.02", "0"], ["84407.03", "0"], ["84407.17", "0"], ["84407.37", "0"], ["84407.59", "0"], ["84407.69", "0"], ["84408.73", "0"], ["84409.41", "0"], ["84409.58", "0.002681"], ["84409.9", "0"], ["84409.96", "0"], ["84409.99", "0"], ["84410.03", "0"], ["84411.81", "0"], ["84411.99", "0"], ["84412.15", "0"], ["84412.33", "0"], ["84412.44", "0"], ["84412.64", "0"], ["84413", "0"], ["84413.4", "0"], ["84413.88", "0"], ["84414.1", "0"], ["84415.03", "0"], ["84415.15", "0"], ["84415.39", "0"], ["84415.58", "0"], ["84415.65", "0"], ["84416.05", "0"], ["84416.98", "0.000235"], ["84417.17", "0.0005"], ["84417.19", "0"], ["84418", "0"], ["84418.07", "0"], ["84418.98", "0"], ["84418.99", "0"], ["84419.48", "0"], ["84419.7", "0"], ["84420.1", "0"], ["84420.2", "0"], ["84420.34", "0"], ["84421.5", "0"], ["84422.36", "0"], ["84423.44", "0"], ["84423.55", "0"], ["84423.62", "0"], ["84423.64", "0"], ["84423.86", "0"], ["84424.06", "0"], ["84424.09", "0"], ["84424.7", "0"], ["84424.77", "0"], ["84424.78", "0"], ["84424.81", "0"], ["84425.1", "0.0002"], ["84425.2", "0"], ["84425.39", "0"], ["84425.6", "0"], ["84425.66", "0.010405"], ["84425.97", "0"], ["84426.21", "0"], ["84426.47", "0"], ["84427", "0"], ["84427.61", "0"], ["84427.91", "0"], ["84428.33", "0.13972"], ["84428.91", "0.237018"], ["84428.92", "0.144246"], ["84428.93", "0"], ["84429.02", "0"], ["84430.01", "0"], ["84430.02", "0"], ["84430.26", "0"], ["84430.39", "0"], ["84430.4", "0.06"], ["84430.43", "0"], ["84430.81", "0.107245"], ["84431.2", "0"], ["84431.31", "0.11614"], ["84431.45", "0"], ["84431.7", "0.044"], ["84431.79", "0"], ["84432.4", "0.107217"], ["84432.62", "0.40933"], ["84432.63", "0"], ["84432.72", "0"], ["84433.1", "0.114262"], ["84433.13", "0.059948"], ["84433.15", "0"], ["84433.18", "0"], ["84433.71", "0"], ["84433.8", "0.06"], ["84433.87", "0"], ["84434", "0.04"], ["84435.35", "0"], ["84435.5", "0.068"], ["84436.3", "0.048"], ["84436.48", "0"], ["84437.1", "0.048"], ["84437.46", "0.162"], ["84437.56", "0.020784"], ["84438.36", "0.008453"], ["84438.47", "0.003343"], ["84438.6", "0.163052"], ["84438.84", "0"], ["84439.07", "0.174136"], ["84439.7", "0"], ["84439.99", "0.017796"], ["84440.06", "0.023694"], ["84440.85", "0.171532"], ["84440.98", "0"], ["84441.52", "0.004647"], ["84441.67", "0.162886"], ["84442.24", "0"], ["84442.3", "0.0008"], ["84442.48", "0"], ["84442.63", "0"], ["84442.64", "0"], ["84442.8", "0.015608"], ["84442.83", "0.0002"], ["84442.85", "0.175419"], ["84443.13", "0"], ["84444.89", "0.019104"], ["84445.16", "0"], ["84445.89", "0"], ["84446.26", "0.024442"], ["84446.51", "0.000335"], ["84446.56", "0.000253"], ["84446.72", "0.001467"], ["84446.82", "0.293959"], ["84446.9", "1.447343"], ["84447.17", "0.023693"], ["84447.5", "0.00474"], ["84447.85", "0.005923"], ["84447.9", "0.0002"], ["84447.98", "0.000612"], ["84448.02", "0.001333"], ["84448.61", "0.277825"], ["84448.96", "0.000235"], ["84449.48", "0.000235"], ["84449.62", "0.000089"], ["84450", "0.000065"], ["84450.13", "0.000199"], ["84450.34", "0.0045"], ["84450.43", "0.0002"], ["84450.54", "0.0045"], ["84451.2", "0.000253"], ["84451.37", "0.001467"], ["84452.2", "0.000612"], ["84452.24", "0.001333"], ["84452.43", "0.04"], ["84452.44", "0.04"], ["84452.96", "0.0002"], ["84453.1", "0.0045"], ["84453.11", "0.0045"], ["84453.15", "0.023693"], ["84453.3", "0.0045"], ["84453.31", "0.0045"], ["84453.6", "0.000235"], ["84454.13", "0.000235"], ["84454.34", "0.071049"], ["84454.42", "0.11863"], ["84455.3", "0.003"], ["84455.5", "0.0002"], ["84455.85", "0.000253"], ["84456.01", "0.001467"], ["84456.42", "0.000612"], ["84456.47", "0.001333"], ["84456.59", "0.001"], ["84456.78", "0.031731"], ["84458.03", "0.0002"], ["84458.13", "0.000089"], ["84458.25", "0.000235"], ["84458.46", "0.000089"], ["84458.6", "0.059948"], ["84458.77", "0.000235"], ["84458.88", "0.000823"], ["84459.74", "0.005"], ["84460.49", "0.000253"], ["84460.57", "0.0002"], ["84460.65", "0.000612"], ["84460.66", "0.001467"], ["84460.69", "0.001333"], ["84462.2", "0.246659"], ["84462.26", "0.071043"], ["84462.89", "0.000235"], ["84462.9", "0.000085"], ["84463.1", "0.0002"], ["84463.42", "0.000235"], ["84463.97", "0.352234"], ["84464.54", "0.11863"], ["84464.87", "0.000612"], ["84464.91", "0.001333"], ["84465.14", "0.000253"], ["84465.3", "0.001467"], ["84466.64", "0.000089"], ["84466.97", "0.005"], ["84467.43", "0.023697"], ["84467.54", "0.000235"], ["84467.82", "1.777245"], ["84468.06", "0.000235"], ["84468.4", "0.427229"], ["84468.62", "0.000335"], ["84469.09", "0.000612"]], "u": 7510788, "seq": 66889425750}, "cts": 1742142253606, "record_time": 1742142252.709928}
{"topic": "orderbook.200.BTCUSDT", "ts": 1742142253809, "type": "delta", "data": {"s": "BTCUSDT", "b": [["84414.21", "0.114056"], ["84414.2", "0.009287"], ["84414.04", "0.000153"], ["84412.5", "0.022826"], ["84412.49", "0.071085"], ["84411.81", "0.005"], ["84409.99", "0.000612"], ["84409.57", "0.0002"], ["84409.41", "0.000252"], ["84408.74", "0.011847"], ["84404.84", "0.0002"], ["84404.29", "0.019588"], ["84404.05", "0.000089"], ["84403.16", "0"], ["84403.14", "0.001919"], ["84402.89", "0"], ["84402.61", "0"], ["84402.15", "0"], ["84401.14", "0.036174"], ["84401.13", "0"], ["84400.56", "0.01049"], ["84400.29", "0.001467"], ["84400.19", "0.089922"], ["84399.75", "0"], ["84398.26", "0.015722"], ["84396.78", "0.000797"], ["84396.66", "0"], ["84396.15", "0.062893"], ["84395.95", "0"], ["84395.69", "0"], ["84395.4", "0.04"], ["84395.1", "0.040248"], ["84394.86", "0"], ["84393.7", "0.04"], ["84392.68", "0"], ["84392.5", "0"], ["84392.33", "0.019095"], ["84392.03", "0"], ["84391.99", "0"], ["84391.01", "0.001467"], ["84390.4", "0.04"], ["84390.17", "0.279699"], ["84389.94", "0"], ["84389.42", "0.072251"], ["84387.1", "0.04"], ["84386.3", "0.27694"], ["84386.23", "0.021054"], ["84385.65", "0.23694"], ["84384.23", "0"], ["84383.9", "0"], ["84383.6", "0"], ["84383.53", "0.015736"], ["84382.2", "0"], ["84382.08", "0.23694"], ["84381.95", "0"], ["84381.9", "0"], ["84381.55", "0.071111"], ["84381.43", "0.097806"], ["84381.11", "0"], ["84380.57", "0"], ["84378.94", "0.237018"], ["84378.93", "0"], ["84378.55", "0"], ["84378.5", "0"], ["84378.09", "0"], ["84377.3", "0"], ["84376.8", "0"], ["84374.99", "0.02374"], ["84373.21", "0"], ["84372.47", "0.355401"], ["84371.82", "0"], ["84371.05", "0"], ["84370.3", "0.000089"], ["84369.99", "0"], ["84368.33", "0"], ["84365.4", "0.000234"], ["84363.83", "0.000987"], ["84359.36", "0.000613"], ["84356.4", "0.162"], ["84354.56", "0"]], "a": [["84409.58", "0"], ["84414.05", "0"], ["84414.21", "0"], ["84414.22", "0.002651"], ["84422.65", "0.009018"], ["84423.46", "0.020084"], ["84423.92", "0"], ["84425.09", "0.028006"], ["84425.57", "0.080334"], ["84425.66", "0"], ["84426.78", "0.071073"], ["84427.72", "0"], ["84428.33", "0"], ["84428.85", "0.237018"], ["84428.86", "0.116104"], ["84428.91", "0"], ["84428.92", "0"], ["84430", "0.04"], ["84430.33", "0.01049"], ["84430.75", "0.139718"], ["84430.81", "0"], ["84431.31", "0"], ["84432.39", "0.194411"], ["84432.4", "0"], ["84432.58", "0"], ["84432.62", "0.000253"], ["84433.1", "0"], ["84433.13", "0"], ["84435.1", "0.056"], ["84437.45", "0.161253"], ["84437.46", "0"], ["84437.85", "0.000987"], ["84438.55", "0.023617"], ["84438.6", "0"], ["84439.07", "0"], ["84439.48", "0"], ["84440.06", "0"], ["84440.85", "0"], ["84441.67", "0"], ["84441.76", "0.00951"], ["84442.33", "0"], ["84442.8", "0"], ["84445.72", "0.11847"], ["84445.91", "0.162"], ["84446.82", "0"], ["84447.36", "0.015736"], ["84447.5", "0"], ["84448.31", "0.004739"], ["84448.34", "0.30011"], ["84448.61", "0"], ["84448.9", "0.23694"], ["84449.6", "0.23694"], ["84452.43", "0"], ["84452.44", "0"], ["84453.12", "0.23694"], ["84454.34", "0"], ["84454.36", "0.162"], ["84456.4", "0.014051"], ["84457.74", "0.04"], ["84457.75", "0.04"], ["84459.07", "0.071046"], ["84462.26", "0"], ["84462.81", "0.162"], ["84465.8", "0.07104"], ["84467.56", "0.000357"], ["84467.81", "0.355405"]], "u": 7510789, "seq": 66889426709}, "cts": 1742142253807, "record_time": 1742142252.909097}
{"topic": "orderbook.200.BTCUSDT", "ts": 1742142254010, "type": "delta", "data": {"s": "BTCUSDT", "b": [["84413.38", "0.011846"], ["84410.59", "0.000099"], ["84409.9", "0.0002"], ["84409.57", "0"], ["84407.47", "0.011847"], ["84405.78", "0.058718"], ["84405.77", "0.04906"], ["84404.65", "0.01572"], ["84404.49", "0.118629"], ["84404.29", "0"], ["84404.21", "0.11751"], ["84403.67", "0.112966"], ["84402.54", "0.062885"], ["84401.31", "0.116611"], ["84401.14", "0.036456"], ["84400.27", "0.003"], ["84398.26", "0"], ["84397.26", "0.142976"], ["84396.57", "0"], ["84396.55", "0.060196"], ["84396.45", "0.17328"], ["84396.15", "0.00007"], ["84395.1", "0.04"], ["84393.55", "0.170303"], ["84393.4", "0.048"], ["84390.17", "0"], ["84388.7", "0.283828"], ["84385.69", "0.023693"], ["84372.58", "1.492147"], ["84372.47", "0"], ["84364.86", "0.355406"], ["84362.1", "0.24702"], ["84361.05", "0"], ["84359.3", "0"], ["84358.91", "0"], ["84358.78", "0"], ["84358.53", "0"], ["84358.36", "0"], ["84356.86", "0"], ["84356.85", "0"], ["84356.74", "0"], ["84356.64", "0"], ["84356.4", "0"], ["84356.12", "0"], ["84355.66", "0"], ["84355.65", "0"], ["84355.18", "0"], ["84355.14", "0"]], "a": [["84414.22", "0.004148"], ["84421.04", "0.02"], ["84421.09", "0.016272"], ["84421.25", "0.071077"], ["84422.65", "0.000612"], ["84423.46", "0"], ["84425.09", "0"], ["84425.57", "0"], ["84426.78", "0"], ["84428.15", "0.031191"], ["84428.84", "0.151947"], ["84428.86", "0"], ["84429.86", "0.023233"], ["84431.97", "0.080332"], ["84432.39", "0"], ["84432.41", "0.109034"], ["84432.91", "0.111989"], ["84433.79", "0.125324"], ["84433.91", "0.110821"], ["84434.66", "0.119341"], ["84437.45", "0"], ["84440.12", "0.164432"], ["84440.66", "0.162366"], ["84442.42", "0.165376"], ["84443.27", "0.180547"], ["84445.38", "0.236927"], ["84447.66", "0.023693"], ["84448.31", "0"], ["84448.34", "0"], ["84448.42", "0.295668"], ["84450.57", "0.022"], ["84457.74", "0"], ["84457.75", "0"], ["84459.53", "0.04"], ["84459.54", "0.04"], ["84464.53", "0.355411"], ["84466.89", "0.009"], ["84466.97", "0"], ["84467.43", "0"], ["84467.54", "0"], ["84467.56", "0"], ["84467.81", "0"], ["84467.82", "0"], ["84468.06", "0"], ["84468.4", "0"], ["84468.62", "0"], ["84469.09", "0"]], "u": 7510790, "seq": 66889427244}, "cts": 1742142254004, "record_time": 1742142253.108628}
{"topic": "orderbook.200.BTCUSDT", "ts": 1742142254210, "type": "delta", "data": {"s": "BTCUSDT", "b": [["84405.78", "0.149078"], ["84404.49", "0"], ["84404.21", "0"], ["84403.67", "0"], ["84401.31", "0"], ["84401.14", "0"], ["84401.09", "0.039195"], ["84400.19", "0"], ["84397.26", "0"], ["84396.78", "0.001045"], ["84396.55", "0.059948"], ["84396.46", "0.106679"], ["84396.45", "0"], ["84396.36", "0.00007"], ["84396.15", "0"], ["84396", "0.04"], ["84394.5", "0.04"], ["84393.55", "0"], ["84392.6", "0.04"], ["84391.4", "0.04"], ["84391.1", "0.04"], ["84389.6", "0"], ["84388.7", "0"], ["84386.73", "0.236927"], ["84382.51", "0.236927"], ["84381.55", "0"], ["84380.4", "0"], ["84378.94", "0"], ["84369.7", "0.071121"], ["84361.79", "0.06734"], ["84358.78", "0.00109"], ["84358.53", "0.001467"], ["84358.36", "0.000252"], ["84356.86", "0.237018"]], "a": [["84418.8", "0.071079"], ["84419.64", "0.011846"], ["84419.65", "0.011846"], ["84419.66", "0.011842"], ["84421.09", "0.000235"], ["84421.25", "0"], ["84432.41", "0"], ["84432.9", "0.059948"], ["84432.91", "0"], ["84433.79", "0.178707"], ["84433.91", "0"], ["84434.66", "0"], ["84440.12", "0"], ["84440.66", "0"], ["84441.57", "0.009051"], ["84442.42", "0"], ["84443.27", "0"], ["84445.81", "0.236927"], ["84448.42", "0"], ["84450.04", "0.236927"], ["84453.12", "0"], ["84463.96", "0.35542"], ["84464.37", "0.037649"], ["84464.53", "0"], ["84466.97", "0.005"], ["84467.09", "0.009"]], "u": 7510791, "seq": 66889427582}, "cts": 1742142254196, "record_time": 1742142253.311179}
{"topic": "orderbook.200.BTCUSDT", "ts": 1742142254410, "type": "delta", "data": {"s": "BTCUSDT", "b": [["84448.88", "0.080877"], ["84443.47", "0.026981"], ["84441.67", "0.059948"], ["84441.04", "0.026959"], ["84438.07", "0.026981"], ["84435.56", "0.229352"], ["84435.18", "0.200902"], ["84433.22", "0.059948"], ["84431.7", "0.001705"], ["84431.69", "0.079715"], ["84430.96", "0.017796"], ["84430.69", "0.162"], ["84430.68", "0.17403"], ["84430.67", "0.325296"], ["84430.24", "0.016392"], ["84429.85", "0.131293"], ["84429.41", "0.005"], ["84429.4", "0.000089"], ["84427.98", "0.000252"], ["84426.91", "0.001333"], ["84426.87", "0.000613"], ["84426.26", "0.000234"], ["84425.71", "0.175419"], ["84423.34", "0.000252"], ["84423.05", "0.059948"], ["84423.04", "0.009898"], ["84420.95", "0.000089"], ["84420.74", "0.065581"], ["84419.85", "0.026981"], ["84419.63", "0.026959"], ["84418.79", "0.003559"], ["84418.69", "0.000252"], ["84417.82", "0.000797"], ["84417.2", "0.003"], ["84417", "0.003"], ["84416.8", "0.003"], ["84414.22", "0.00414"], ["84414.21", "0.364715"], ["84414.2", "0"], ["84414.05", "0.000252"], ["84414.04", "0"], ["84413.41", "0.02728"], ["84413.4", "0.034593"], ["84412.5", "0.000089"], ["84412.49", "0"], ["84412.44", "0.0002"], ["84412.33", "0.000234"], ["84411.81", "0.000234"], ["84410.03", "0.001333"], ["84409.58", "0.001467"], ["84408.77", "0.139714"], ["84406.92", "0.000357"], ["84405.78", "0"], ["84405.77", "0.0005"], ["84405.76", "0.162613"], ["84405.45", "0.017765"], ["84405.12", "0.059948"], ["84404.65", "0"], ["84403.04", "0"], ["84402.69", "0"], ["84402.54", "0"], ["84401.09", "0"], ["84400.56", "0"], ["84397.7", "0.001243"], ["84396.78", "0"], ["84396.75", "0.176903"], ["84396.46", "0"], ["84396.36", "0"], ["84396.01", "0.08121"], ["84396", "0.040071"], ["84394.7", "0"], ["84392.68", "0.355334"], ["84392.33", "0"], ["84392.07", "0"], ["84391.7", "0"], ["84389.65", "0.006121"], ["84389.42", "0.258591"], ["84388.94", "0.269403"], ["84388.3", "0"], ["84387.1", "0"], ["84386.73", "0"], ["84386.3", "0"], ["84386.23", "0"], ["84385.69", "0"], ["84385.65", "0"], ["84385.57", "0.281125"], ["84383.53", "0"], ["84382.51", "0"], ["84382.08", "0"], ["84381.77", "0"], ["84381.43", "0"], ["84378.62", "0"], ["84378.52", "0.023686"], ["84376.64", "0"], ["84374.95", "0"], ["84374.62", "0.391366"], ["84374.34", "0"], ["84374.3", "0.24702"], ["84371.44", "0.005922"], ["84370.73", "0"], ["84369.7", "0"], ["84369.55", "0.05"], ["84369.54", "0.047173"], ["84367.76", "0.023692"], ["84367.4", "0.452299"], ["84366.95", "0.023692"], ["84365", "0"], ["84364.86", "0"], ["84364.85", "0"], ["84364.34", "0"], ["84363.83", "0"], ["84363.62", "0"], ["84363.57", "0"], ["84363.17", "0"], ["84363", "0"], ["84362.52", "0"], ["84362.1", "0"], ["84361.93", "0"], ["84361.81", "0"], ["84361.8", "0"], ["84361.79", "0"], ["84361.64", "0"], ["84361.53", "0"], ["84361.28", "0"], ["84360.96", "0"], ["84360.95", "0"], ["84360.76", "0"], ["84359.4", "0"], ["84359.36", "0"], ["84359.27", "0"], ["84358.78", "0"], ["84358.53", "0"], ["84358.36", "0"], ["84356.86", "0"]], "a": [["84414.22", "0"], ["84414.25", "0"], ["84414.32", "0"], ["84414.48", "0"], ["84414.97", "0"], ["84416.45", "0"], ["84416.97", "0"], ["84416.98", "0"], ["84417.17", "0"], ["84417.5", "0"], ["84418.43", "0"], ["84418.47", "0"], ["84418.69", "0"], ["84418.79", "0"], ["84418.8", "0"], ["84418.86", "0"], ["84419.64", "0"], ["84419.65", "0"], ["84419.66", "0"], ["84420.03", "0"], ["84421.04", "0"], ["84421.09", "0"], ["84421.62", "0"], ["84422.57", "0"], ["84422.65", "0"], ["84422.69", "0"], ["84423.34", "0"], ["84423.51", "0"], ["84424.4", "0"], ["84425.1", "0"], ["84425.74", "0"], ["84426.26", "0"], ["84426.87", "0"], ["84426.91", "0"], ["84427.63", "0"], ["84427.98", "0"], ["84428.15", "0"], ["84428.84", "0"], ["84428.85", "0"], ["84429.86", "0"], ["84430", "0"], ["84430.17", "0"], ["84430.33", "0"], ["84430.38", "0"], ["84430.4", "0"], ["84430.45", "0"], ["84430.65", "0"], ["84430.75", "0"], ["84430.91", "0"], ["84431.09", "0"], ["84431.13", "0"], ["84431.7", "0"], ["84431.97", "0"], ["84432.38", "0"], ["84432.6", "0"], ["84432.62", "0"], ["84432.7", "0"], ["84432.79", "0"], ["84432.9", "0"], ["84433.14", "0"], ["84433.79", "0"], ["84433.8", "0"], ["84434", "0"], ["84434.18", "0"], ["84434.2", "0"], ["84435.02", "0"], ["84435.1", "0"], ["84435.23", "0"], ["84435.31", "0"], ["84435.36", "0"], ["84435.5", "0"], ["84435.55", "0"], ["84435.7", "0"], ["84436.3", "0"], ["84436.71", "0"], ["84437.1", "0"], ["84437.27", "0"], ["84437.44", "0"], ["84437.56", "0"], ["84437.76", "0"], ["84437.85", "0"], ["84438.36", "0"], ["84438.47", "0"], ["84438.55", "0"], ["84439.37", "0"], ["84439.53", "0"], ["84439.58", "0"], ["84439.67", "0"], ["84439.99", "0"], ["84440.19", "0"], ["84440.3", "0"], ["84441.11", "0"], ["84441.52", "0"], ["84441.57", "0"], ["84441.72", "0"], ["84441.74", "0"], ["84441.76", "0"], ["84441.91", "0"], ["84441.99", "0"], ["84442.08", "0"], ["84442.3", "0"], ["84442.38", "0"], ["84442.83", "0"], ["84442.85", "0"], ["84443.76", "0"], ["84443.8", "0"], ["84443.9", "0"], ["84444.3", "0"], ["84444.31", "0"], ["84444.78", "0"], ["84444.84", "0"], ["84444.89", "0"], ["84445.13", "0"], ["84445.36", "0"], ["84445.38", "0"], ["84445.72", "0"], ["84445.81", "0"], ["84445.91", "0"], ["84446.26", "0"], ["84446.51", "0"], ["84446.56", "0"], ["84446.72", "0"], ["84446.9", "0"], ["84447.17", "0"], ["84447.36", "0"], ["84447.66", "0"], ["84447.85", "0"], ["84447.9", "0"], ["84447.98", "0"], ["84448.02", "0"], ["84448.89", "0.060986"], ["84448.9", "0"], ["84448.96", "0"], ["84449.48", "0"], ["84449.6", "0"], ["84449.62", "0"], ["84450", "0"], ["84450.04", "0"], ["84450.34", "0"], ["84450.54", "0"], ["84450.57", "0"], ["84450.63", "0.059213"], ["84453.1", "0"], ["84453.11", "0"], ["84453.15", "0"], ["84453.3", "0"], ["84453.31", "0"], ["84454.36", "0"], ["84454.42", "0"], ["84455.3", "0"], ["84456.28", "0.005921"], ["84456.47", "0.060546"], ["84456.78", "0"], ["84457.34", "0.0005"], ["84457.51", "0.059213"], ["84458.6", "0"], ["84459.07", "0"], ["84459.53", "0"], ["84459.54", "0"], ["84459.74", "0"], ["84462.2", "0.0006"], ["84462.81", "0"], ["84463.96", "0"], ["84463.97", "0"], ["84464.12", "0.005"], ["84464.54", "0"], ["84465.63", "0.0002"], ["84465.8", "0"], ["84466.89", "0.0045"], ["84467.08", "0.237018"], ["84467.09", "0.0045"], ["84467.54", "0.000235"], ["84468.06", "0.000235"], ["84468.62", "0.000335"], ["84469.09", "0.000612"], ["84469.14", "0.001333"], ["84469.48", "0.005"], ["84469.56", "0.000111"], ["84469.67", "0.002853"], ["84469.78", "0.000253"], ["84469.95", "0.001467"], ["84471.26", "0.023683"], ["84472.18", "0.000235"], ["84472.64", "0.000935"], ["84472.71", "0.000235"], ["84473.32", "0.000612"], ["84473.36", "0.001333"], ["84474.43", "0.000253"], ["84474.6", "0.001467"], ["84475.15", "0.000089"], ["84475.54", "0.04"], ["84475.55", "0.04"], ["84476.83", "0.000235"], ["84477.05", "0.030367"], ["84477.21", "0.237018"], ["84477.22", "0.023687"], ["84477.35", "0.000235"], ["84477.54", "0.000612"], ["84477.58", "0.001333"], ["84478", "0.000042"], ["84478.71", "0.023686"], ["84479.01", "0.005"], ["84479.07", "0.000253"], ["84479.24", "0.001467"], ["84479.5", "0.020401"], ["84480.32", "0.322714"], ["84480.48", "0.0008"], ["84481.47", "0.000235"], ["84481.72", "0.000889"], ["84481.76", "0.000612"], ["84481.81", "0.001333"], ["84482", "0.000235"], ["84482.38", "0.015"], ["84482.43", "0.285255"], ["84483.14", "0.0025"], ["84483.66", "0.000089"], ["84483.72", "0.000253"], ["84483.89", "0.001467"], ["84484.79", "0.118574"], ["84485.02", "0.00315"], ["84485.3", "0.246059"], ["84485.99", "0.000612"], ["84486.03", "0.001333"], ["84486.12", "0.000235"], ["84486.65", "0.000235"], ["84487.74", "0.017796"], ["84488.23", "0.027843"], ["84488.37", "0.000253"], ["84488.53", "0.001467"], ["84490.21", "0.000612"], ["84490.25", "0.001333"], ["84490.73", "0.000335"], ["84490.77", "0.000235"], ["84490.82", "0.140922"], ["84490.96", "0.001"], ["84491.05", "0.002421"], ["84491.29", "0.000235"], ["84492.17", "0.000089"], ["84493.01", "0.000253"], ["84493.13", "0.000158"], ["84493.18", "0.001467"], ["84493.26", "0.059948"], ["84494.44", "0.000612"], ["84494.48", "0.001333"], ["84494.92", "0.118574"], ["84495.41", "0.000235"], ["84495.94", "0.000235"], ["84497.66", "0.000253"], ["84497.83", "0.001467"], ["84498.1", "0.023686"], ["84498.2", "0.06"], ["84498.66", "0.000612"], ["84498.7", "0.001333"], ["84499.57", "0.0045"], ["84499.77", "0.0045"], ["84499.85", "0.000357"], ["84499.94", "0.000089"], ["84500", "1.076043"], ["84500.06", "0.000235"], ["84500.23", "0.177705"], ["84500.59", "0.000235"], ["84500.68", "0.000089"], ["84500.7", "0.048"], ["84501.24", "0.000059"], ["84501.84", "0.059948"], ["84502.31", "0.000253"], ["84502.48", "0.001467"], ["84502.89", "0.000612"], ["84502.9", "0.044"], ["84502.93", "0.001333"], ["84503.44", "0.002"], ["84504.71", "0.000235"], ["84504.88", "0.12"], ["84505.05", "0.237128"], ["84505.24", "0.000235"], ["84506.48", "0.12"], ["84506.96", "0.000253"], ["84507.1", "0.002456"], ["84507.11", "0.000612"], ["84507.12", "0.001467"], ["84507.15", "0.001333"], ["84508.43", "0.02007"], ["84509.19", "0.000089"], ["84509.36", "0.000235"], ["84509.39", "0.004842"], ["84509.88", "0.000235"], ["84510.5", "0.059948"], ["84511.34", "0.000612"], ["84511.38", "0.001333"], ["84511.6", "0.000253"], ["84511.77", "0.001467"], ["84512.84", "0.000335"], ["84513", "0.044"], ["84514.01", "0.000235"], ["84514.09", "0.322585"], ["84514.3", "0.04"], ["84514.53", "0.000235"], ["84515.18", "0.237128"], ["84515.56", "0.000612"], ["84515.59", "0.05763"], ["84515.61", "0.001333"], ["84515.84", "0.000085"], ["84516", "0.06"], ["84516.25", "0.000253"], ["84516.42", "0.001467"], ["84516.97", "0.005"], ["84517.7", "0.000089"], ["84518.01", "0.105686"], ["84518.2", "0.048"], ["84518.56", "0.000199"], ["84518.65", "0.000235"], ["84519.18", "0.000235"], ["84519.57", "0.078403"], ["84519.79", "0.000612"], ["84519.83", "0.001333"], ["84519.87", "0.318117"], ["84519.9", "0.493079"], ["84520.33", "0.000111"], ["84520.56", "0.017041"], ["84520.9", "0.000253"], ["84521.07", "0.001467"], ["84521.4", "0.068"]], "u": 7510792, "seq": 66889429213}, "cts": 1742142254403, "record_time": 1742142253.512662}
{"topic": "orderbook.200.BTCUSDT", "ts": 1742142254610, "type": "delta", "data": {"s": "BTCUSDT", "b": [["84448.88", "0"], ["84443.47", "0"], ["84441.67", "0"], ["84441.04", "0"], ["84438.07", "0"], ["84437.85", "0.035247"], ["84436.22", "0.01386"], ["84435.56", "0"], ["84435.18", "0"], ["84433.22", "0"], ["84431.71", "0.030663"], ["84431.7", "0"], ["84431.69", "0"], ["84430.96", "0"], ["84430.71", "0.027426"], ["84430.7", "0.059078"], ["84430.68", "0"], ["84430.67", "0.014078"], ["84430.17", "0.0002"], ["84429.85", "0"], ["84429.41", "0"], ["84428.27", "0.065572"], ["84425.72", "0.052701"], ["84425.1", "0.0002"], ["84423.06", "0.070634"], ["84423.05", "0.059531"], ["84422.63", "0.005733"], ["84422.6", "0.04"], ["84422.57", "0.0002"], ["84422.3", "0.044"], ["84420.9", "0.04"], ["84420.74", "0"], ["84420.03", "0.0002"], ["84419.85", "0"], ["84419.63", "0"], ["84417.4", "0.04"], ["84415.14", "0.02"], ["84414.31", "0.09634"], ["84414.3", "0.04"], ["84414.22", "0"], ["84414.21", "0.094454"], ["84414", "0.04"], ["84413.41", "0"], ["84413.4", "0"], ["84413.38", "0"], ["84411.5", "0.048"], ["84410.59", "0"], ["84410.41", "0.011383"], ["84408.78", "0.04933"], ["84408.74", "0"], ["84408.1", "0.04"], ["84407.47", "0"], ["84406.11", "0.008599"], ["84405.45", "0"], ["84403.95", "0.323006"], ["84402.82", "0.023684"], ["84399.56", "0.005"], ["84396.75", "0"], ["84396.36", "0.000071"], ["84396", "0.04"], ["84395.5", "0.399592"], ["84395.4", "0"], ["84395.1", "0"], ["84394.83", "0.023684"], ["84394.72", "0"], ["84392.68", "0"], ["84392.6", "0"], ["84389.43", "0"], ["84389.42", "0.072251"], ["84388.95", "0.237018"], ["84388.94", "0"], ["84388.33", "0.005921"], ["84387", "0"], ["84386.8", "0"], ["84386.27", "0.005503"], ["84385.71", "0.004682"], ["84385.58", "0.355343"], ["84385.57", "0"], ["84385.22", "0"], ["84385.02", "0"], ["84384.82", "0"], ["84384.64", "0.023684"], ["84384.61", "0"], ["84384.01", "0"], ["84383.83", "0.023684"], ["84383.81", "0"], ["84383.14", "0.0025"], ["84382.38", "0.015"], ["84382.35", "0"], ["84382.05", "0"], ["84379.52", "0"], ["84379.3", "0.237018"], ["84378.52", "0"], ["84376.99", "0"], ["84375.1", "0.24702"], ["84374.62", "0"], ["84374.46", "0"], ["84374.3", "0"], ["84374.25", "0"], ["84373.73", "0.02369"], ["84372.82", "0.013729"], ["84371.93", "0"], ["84370.17", "0.646282"], ["84369.7", "0.059087"], ["84369.4", "0"], ["84367.85", "0"], ["84367.76", "0"], ["84367.41", "0.237018"], ["84366.95", "0"], ["84366.87", "0"], ["84365", "0.001243"], ["84363.83", "0.000987"], ["84363.62", "0.001333"], ["84363.57", "0.000613"], ["84363.17", "0.001467"], ["84363", "0.000252"], ["84361.93", "0.237018"], ["84361.8", "0.000089"], ["84361.28", "0.000234"]], "a": [["84437.86", "0.087704"], ["84442.08", "0.005"], ["84444.66", "0.0004"], ["84446.14", "0.0537"], ["84446.3", "0.0005"], ["84448.87", "0.237018"], ["84448.89", "0.082898"], ["84450.32", "0.023685"], ["84450.63", "0"], ["84454.57", "0.103358"], ["84454.58", "0.237018"], ["84455.9", "0.019248"], ["84456.1", "0.04"], ["84456.28", "0"], ["84456.4", "0"], ["84456.47", "0.001333"], ["84456.76", "0.059948"], ["84457.33", "0.067699"], ["84457.34", "0.162"], ["84457.51", "0"], ["84458.01", "0.076993"], ["84459.49", "0.002128"], ["84460", "0.056"], ["84461.2", "0.052"], ["84461.32", "0.086673"], ["84461.33", "0.237018"], ["84461.54", "0.005691"], ["84461.92", "0.029603"], ["84463.41", "0.019921"], ["84463.8", "0.04"], ["84464.12", "0"], ["84464.32", "0.059207"], ["84465.4", "0.06"], ["84465.78", "0.059948"], ["84465.79", "0.162"], ["84466.4", "0.044"], ["84466.6", "0.175419"], ["84466.8", "0.04"], ["84467.31", "0.019104"], ["84468.17", "0.0002"], ["84469.48", "0"], ["84470.7", "0.0002"], ["84471.26", "0"], ["84473.02", "0.004637"], ["84473.24", "0.0002"], ["84473.81", "0.071033"], ["84474.24", "0.162"], ["84474.5", "0.013718"], ["84475.53", "0.059948"], ["84475.54", "0"], ["84475.55", "0"], ["84475.77", "0.0002"], ["84477.2", "0.355343"], ["84477.38", "0.139714"], ["84478.16", "0.01992"], ["84478.3", "0.0002"], ["84478.5", "0.023684"], ["84478.71", "0"], ["84478.78", "0.089922"], ["84479.01", "0"], ["84479.22", "0.023684"], ["84479.5", "0"], ["84480.32", "0"], ["84480.48", "0"], ["84480.84", "0.0002"], ["84481.63", "0.023684"], ["84482.02", "0.071026"], ["84482.32", "0.027942"], ["84482.43", "0"], ["84482.69", "0.162"], ["84483.37", "0.0002"], ["84484.78", "0.059948"], ["84485.91", "0.0002"], ["84487.64", "0.04"], ["84487.65", "0.04"], ["84488.23", "0"], ["84488.28", "0.11"], ["84488.44", "0.0002"], ["84489.5", "0.427229"], ["84490.14", "0.023682"], ["84490.82", "0"], ["84490.98", "0.0002"], ["84491.14", "0.162"], ["84492.52", "0.00592"], ["84493.51", "0.0002"], ["84494.02", "0.204662"], ["84495.79", "0.405903"], ["84496.05", "0.0002"], ["84498.58", "0.0002"], ["84499.59", "0.162"], ["84500.23", "0"], ["84502.9", "0"], ["84504.71", "0"], ["84504.88", "0"], ["84505.05", "0"], ["84505.24", "0"], ["84506.48", "0"], ["84506.96", "0"], ["84507.1", "0"], ["84507.11", "0"], ["84507.12", "0"], ["84507.15", "0"], ["84508.43", "0"], ["84509.19", "0"], ["84509.36", "0"], ["84509.39", "0"], ["84509.88", "0"], ["84510.5", "0"], ["84511.34", "0"], ["84511.38", "0"], ["84511.6", "0"], ["84511.77", "0"], ["84512.84", "0"], ["84513", "0"], ["84514.01", "0"], ["84514.09", "0"], ["84514.3", "0"], ["84514.53", "0"], ["84515.18", "0"], ["84515.56", "0"], ["84515.59", "0"], ["84515.61", "0"], ["84515.84", "0"], ["84516", "0"], ["84516.25", "0"], ["84516.42", "0"], ["84516.97", "0"], ["84517.7", "0"], ["84518.01", "0"], ["84518.2", "0"], ["84518.56", "0"], ["84518.65", "0"], ["84519.18", "0"], ["84519.57", "0"], ["84519.79", "0"], ["84519.83", "0"], ["84519.87", "0"], ["84519.9", "0"], ["84520.33", "0"], ["84520.56", "0"], ["84520.9", "0"], ["84521.07", "0"], ["84521.4", "0"]], "u": 7510793, "seq": 66889431207}, "cts": 1742142254607, "record_time": 1742142253.709142}
{"topic": "orderbook.200.BTCUSDT", "ts": 1742142254809, "type": "delta", "data": {"s": "BTCUSDT", "b": [["84437.85", "0.036431"], ["84436.22", "0"], ["84434.23", "0.000099"], ["84433.64", "0.011843"], ["84431.1", "0.011843"], ["84430.71", "0.000296"], ["84427.63", "0.0002"], ["84426.79", "0.021528"], ["84426.78", "0.071073"], ["84425.72", "0"], ["84425.71", "0"], ["84422.63", "0"], ["84420.3", "0.04"], ["84419", "0.04"], ["84418.11", "0.005738"], ["84417.5", "0.0002"], ["84417.41", "0.064798"], ["84417.4", "0.08"], ["84417.22", "0.175419"], ["84415.14", "0"], ["84414.97", "0.0002"], ["84414.31", "0.059758"], ["84414.22", "0.003774"], ["84414.21", "0.093854"], ["84412.68", "0.000335"], ["84412.41", "0.11843"], ["84412.28", "0.008453"], ["84406.11", "0"], ["84401.63", "0.008607"], ["84401.49", "0.000987"], ["84398.06", "1.526496"], ["84396.36", "0"], ["84394.5", "0"], ["84393.7", "0"], ["84393.4", "0"], ["84392.68", "0.237018"], ["84391.4", "0"], ["84391.1", "0"], ["84390.57", "0.000335"], ["84390.4", "0"], ["84388.95", "0"], ["84387.4", "0.071106"], ["84385.59", "0.592363"], ["84385.58", "0"], ["84377.91", "0.071114"], ["84376.81", "0.144603"], ["84374.99", "0"], ["84373.64", "0.177645"], ["84372.58", "0"], ["84365", "0"], ["84363.83", "0"], ["84363.62", "0"], ["84363.57", "0"], ["84363.17", "0"], ["84363", "0"], ["84361.93", "0"], ["84361.8", "0"], ["84361.28", "0"]], "a": [["84437.86", "0.095045"], ["84438.69", "0.000971"], ["84440.25", "0.026371"], ["84440.26", "0.071061"], ["84442.07", "0.011842"], ["84444.61", "0.011842"], ["84444.66", "0"], ["84446.13", "0.01626"], ["84448.86", "0.1043"], ["84449.62", "0.000089"], ["84456.44", "0.005738"], ["84457.33", "0.097935"], ["84457.7", "0.04"], ["84459.2", "0.052"], ["84461.54", "0"], ["84464.37", "0"], ["84464.64", "0.11843"], ["84465.56", "0.0008"], ["84466.48", "0.236861"], ["84469.99", "0.236861"], ["84470.7", "0.237061"], ["84472.95", "0.008607"], ["84473.81", "0"], ["84475.59", "0.000987"], ["84477.2", "0"], ["84478.16", "0.011383"], ["84482.01", "0.355342"], ["84486.27", "0.071023"], ["84487.83", "0.029772"], ["84488.77", "0.037886"], ["84489.22", "1.556257"], ["84491.05", "0"], ["84495.06", "0.078372"], ["84495.93", "0.285168"], ["84498.2", "0"], ["84499.57", "0"], ["84499.59", "0"], ["84499.77", "0"], ["84499.85", "0"], ["84499.94", "0"], ["84500", "0"], ["84500.06", "0"], ["84500.59", "0"], ["84500.68", "0"], ["84500.7", "0"], ["84501.24", "0"], ["84501.84", "0"], ["84502.31", "0"], ["84502.48", "0"], ["84502.89", "0"], ["84502.93", "0"], ["84503.44", "0"]], "u": 7510794, "seq": 66889431503}, "cts": 1742142254807, "record_time": 1742142253.907659}
{"topic": "orderbook.200.BTCUSDT", "ts": 1742142255010, "type": "delta", "data": {"s": "BTCUSDT", "b": [["84437.85", "0.102573"], ["84437.76", "0.0002"], ["84437.44", "0.001467"], ["84437.27", "0.000252"], ["84435.55", "0.000234"], ["84435.36", "0.001333"], ["84435.31", "0.000613"], ["84435.23", "0.0002"], ["84435.02", "0.000234"], ["84432.79", "0.001467"], ["84432.7", "0.0002"], ["84432.62", "0.000252"], ["84431.13", "0.001333"], ["84431.09", "0.000613"], ["84430.9", "0.000234"], ["84430.69", "0"], ["84430.67", "0"], ["84430.38", "0.000234"], ["84429.44", "0.07107"], ["84429.41", "0.04895"], ["84428.15", "0.001467"], ["84426.79", "0"], ["84426.78", "0"], ["84425.75", "0.003"], ["84425.74", "0.000234"], ["84425.55", "0.003"], ["84425.35", "0.003"], ["84423.51", "0.001467"], ["84423.07", "0.059948"], ["84422.69", "0.001333"], ["84422.65", "0.000613"], ["84421.62", "0.000234"], ["84421.09", "0.000234"], ["84419.1", "0.052"], ["84418.86", "0.001467"], ["84418.47", "0.001333"], ["84418.43", "0.000613"], ["84416.98", "0.000234"], ["84416.45", "0.000234"], ["84414.31", "0.098758"], ["84414.25", "0.001333"], ["84414.22", "0.005241"], ["84414.21", "0.079656"], ["84411.62", "0.236861"], ["84411.5", "0"], ["84408.1", "0"], ["84407.4", "0.236861"], ["84398.07", "0.458019"], ["84396", "0"], ["84395.85", "0.017796"], ["84392.68", "0"], ["84385.6", "0.355342"], ["84385.59", "0.237018"], ["84380.32", "0.017765"], ["84375.1", "0"], ["84374.68", "0"], ["84373.73", "0"], ["84373.65", "0"], ["84373.64", "0"], ["84373.29", "0"], ["84373.22", "0"], ["84372.82", "0"], ["84372.46", "0"], ["84372.45", "0"], ["84372.28", "0"], ["84372.05", "0"], ["84372.01", "0"], ["84371.44", "0"], ["84370.56", "0"], ["84370.3", "0"], ["84370.25", "0"], ["84370.17", "0"], ["84370.04", "0"], ["84369.7", "0"], ["84369.55", "0"], ["84369.54", "0"], ["84368.46", "0"], ["84367.84", "0"], ["84367.81", "0"], ["84367.79", "0"], ["84367.64", "0"], ["84367.41", "0"], ["84367.4", "0"], ["84367.39", "0"], ["84366.84", "0"], ["84365.92", "0"], ["84365.4", "0"]], "a": [["84438.69", "0"], ["84459.4", "0.04"], ["84463.8", "0"], ["84465.78", "0.33938"], ["84482", "0.355577"], ["84482.01", "0"], ["84483.07", "0.017796"], ["84488.28", "0"], ["84490.01", "0.0045"], ["84490.15", "0.0045"], ["84490.21", "0.005112"], ["84490.35", "0.0045"], ["84495.06", "0"], ["84497.78", "0.078372"], ["84498.7", "0"]], "u": 7510795, "seq": 66889431652}, "cts": 1742142255004, "record_time": 1742142254.109462}
{"topic": "orderbook.200.BTCUSDT", "ts": 1742142255210, "type": "delta", "data": {"s": "BTCUSDT", "b": [["84437.85", "0.173233"], ["84437.02", "0.005716"], ["84435.12", "0.071066"], ["84433.65", "0.013328"], ["84431.71", "0"], ["84430.71", "0"], ["84429.44", "0"], ["84429.41", "0.04945"], ["84423.51", "0.002467"], ["84420.95", "0.162089"], ["84416.62", "0.000071"], ["84414.31", "0.098687"], ["84413.26", "0.11843"], ["84405.77", "0.172154"], ["84403.14", "0"], ["84397.52", "0.071097"], ["84394.74", "0.073831"], ["84393.05", "0.05"], ["84393.04", "0.049552"], ["84389.43", "0.35533"], ["84386.73", "0.236861"], ["84385.6", "0"], ["84384.69", "0.11"], ["84382.51", "0.236861"], ["84378.79", "0.089922"], ["84378.7", "0"], ["84377.91", "0"], ["84377.09", "0"], ["84376.92", "0"], ["84376.81", "0"], ["84376.27", "0"], ["84376.23", "0"], ["84375.9", "0"], ["84375.2", "0"]], "a": [["84437.86", "0.074195"], ["84440.25", "0"], ["84440.26", "0"], ["84442.07", "0"], ["84444.23", "0.04113"], ["84444.61", "0"], ["84446.13", "0"], ["84448.86", "0.1073"], ["84460.21", "0.001"], ["84461", "0.06"], ["84464.32", "0"], ["84474.23", "0.201559"], ["84482", "0.000235"], ["84485.29", "0.355324"], ["84490.02", "0.003"]], "u": 7510796, "seq": 66889431813}, "cts": 1742142255207, "record_time": 1742142254.309766}
{"topic": "orderbook.200.BTCUSDT", "ts": 1742142255409, "type": "delta", "data": {"s": "BTCUSDT", "b": [["84442.07", "0.151537"], ["84437.85", "0.117563"], ["84437.02", "0.011843"], ["84435.12", "0"], ["84433.65", "0"], ["84431.48", "0.003"], ["84430.7", "0.040157"], ["84427.04", "0.005894"], ["84426.88", "0.005"], ["84423.63", "0.071886"], ["84423.06", "0.13827"], ["84423.05", "0"], ["84418.11", "0"], ["84417.3", "0.236918"], ["84411.62", "0"], ["84410.95", "0.008841"], ["84410.75", "0.008913"], ["84410.53", "0.089922"], ["84405.97", "0.005812"], ["84401.63", "0"], ["84399.56", "0"], ["84399.38", "0.024094"], ["84395.82", "0.171392"], ["84393.06", "0.355313"], ["84389.43", "0"], ["84387.4", "0"], ["84386.73", "0"], ["84382.51", "0"], ["84381.72", "0.015"], ["84379.32", "0"], ["84379.3", "0"], ["84378.79", "0"]], "a": [["84437.86", "0"], ["84442.08", "0.006184"], ["84444.23", "0"], ["84455.7", "0.056"], ["84455.9", "0"], ["84456.44", "0"], ["84456.76", "0"], ["84457.33", "0.136455"], ["84457.34", "0"], ["84461.58", "0.005894"], ["84461.92", "0"], ["84462.12", "0.139679"], ["84462.2", "0.0446"], ["84462.5", "0.04"], ["84463.41", "0"], ["84463.6", "0.023802"], ["84464.64", "0"], ["84465.4", "0"], ["84465.79", "0"], ["84466.48", "0"], ["84469.99", "0"], ["84470.7", "0.0002"], ["84472.95", "0"], ["84474.99", "0.008453"], ["84477.38", "0"], ["84477.68", "0.008841"], ["84482.02", "0"], ["84485.29", "0"], ["84486.27", "0"], ["84488.76", "0.355313"], ["84492.63", "0.0045"], ["84492.83", "0.0045"], ["84497.78", "0"], ["84498.7", "0.001333"], ["84499.57", "0.0045"], ["84499.77", "0.0045"], ["84499.85", "0.000357"], ["84499.93", "0.285196"], ["84499.94", "0.000089"], ["84499.97", "0.0045"], ["84500", "1.076043"], ["84500.06", "0.000235"]], "u": 7510797, "seq": 66889432158}, "cts": 1742142255407, "record_time": 1742142254.508047}
{"topic": "orderbook.200.BTCUSDT", "ts": 1742142255610, "type": "delta", "data": {"s": "BTCUSDT", "b": [["84442.07", "0.147433"], ["84441.91", "0.000252"], ["84441.24", "0.011842"], ["84440.3", "0.0002"], ["84440.19", "0.000234"], ["84439.67", "0.000234"], ["84439.58", "0.001333"], ["84439.53", "0.000613"], ["84437.86", "0.024286"], ["84437.85", "0.060043"], ["84435.1", "0.001418"], ["84434.23", "0"], ["84431.67", "0.005"], ["84431.1", "0"], ["84430.7", "0.154803"], ["84428.5", "0.236887"], ["84428.3", "0.044"], ["84426.41", "0.037282"], ["84426.4", "0.04"], ["84425.74", "0.000482"], ["84425.12", "0.236896"], ["84424.7", "0.04"], ["84423.63", "0"], ["84423.1", "0.04"], ["84422.3", "0"], ["84420.9", "0"], ["84420.06", "0.236849"], ["84419.95", "0.118424"], ["84418.18", "0.02"], ["84417.4", "0.04"], ["84417.3", "0"], ["84416.27", "0.236855"], ["84415.84", "0.236849"], ["84414.31", "0.143833"], ["84414.21", "0.08011"], ["84413.26", "0"], ["84412.41", "0"], ["84407.4", "0"], ["84405.44", "0.071091"], ["84401.69", "0.004696"], ["84395.31", "0.05909"], ["84393.06", "0"], ["84390.95", "0.177637"], ["84390.62", "0.023684"], ["84389.43", "0.355312"], ["84389", "0.000119"], ["84388.81", "0.014087"], ["84386.28", "0.237005"], ["84385.71", "0"], ["84385.59", "0"], ["84384.71", "0"], ["84384.69", "0"], ["84384.67", "0"], ["84384.64", "0"], ["84384.59", "0"], ["84384.48", "0"], ["84383.96", "0"], ["84383.83", "0"], ["84383.38", "0"], ["84383.14", "0"], ["84382.38", "0"], ["84381.76", "0"], ["84381.73", "0"], ["84381.72", "0"], ["84381.56", "0"], ["84380.49", "0"], ["84380.45", "0"], ["84380.32", "0"], ["84379.84", "0"]], "a": [["84442.08", "0.018287"], ["84446.13", "0.01761"], ["84446.3", "0.005"], ["84448.83", "0.002517"], ["84448.86", "0.108117"], ["84448.89", "0.085034"], ["84449.77", "0.071053"], ["84450.52", "0.0005"], ["84453.47", "0.019249"], ["84457.33", "0.100097"], ["84460", "0"], ["84461.32", "0.13735"], ["84463.6", "0"], ["84465.64", "0.006046"], ["84465.78", "0.059948"], ["84466.4", "0"], ["84466.59", "0.146574"], ["84466.8", "0"], ["84467.6", "0.02356"], ["84474.5", "0"], ["84474.51", "0.118424"], ["84474.92", "0.236849"], ["84474.99", "0"], ["84478", "0.000161"], ["84479.13", "0.236849"], ["84479.58", "0.236855"], ["84482.32", "0"], ["84483.8", "0.236855"], ["84484.16", "0.008453"], ["84484.29", "0.473461"], ["84486.37", "0.071023"], ["84487.63", "0.35531"], ["84488.76", "0"], ["84491.38", "0.013714"], ["84491.96", "0.020078"], ["84494.67", "0.071016"], ["84495.93", "0"], ["84496.46", "0.177637"], ["84498.1", "0"], ["84498.58", "0"], ["84498.66", "0"], ["84498.7", "0"], ["84499.57", "0"], ["84499.77", "0"], ["84499.85", "0"], ["84499.93", "0"], ["84499.94", "0"], ["84499.97", "0"], ["84500", "0"], ["84500.06", "0"]], "u": 7510798, "seq": 66889432674}, "cts": 1742142255602, "record_time": 1742142254.709715}
{"topic": "orderbook.200.BTCUSDT", "ts": 1742142255810, "type": "delta", "data": {"s": "BTCUSDT", "b": [["84442.07", "0.049414"], ["84441.24", "0"], ["84438.45", "0.000099"], ["84437.86", "0"], ["84437.02", "0"], ["84428.1", "0.04"], ["84426.6", "0.04"], ["84426.41", "0.094199"], ["84424.4", "0.052"], ["84422.6", "0"], ["84422.5", "0.04"], ["84421.7", "0.04"], ["84421.46", "0.017796"], ["84421.3", "0.04"], ["84420.49", "0.236849"], ["84420.3", "0"], ["84420.18", "0.02"], ["84419", "0"], ["84418.99", "0.02"], ["84418.34", "0.02"], ["84418.18", "0"], ["84414.31", "0"], ["84405.62", "0.000987"], ["84405.44", "0"], ["84404.94", "1.592471"], ["84401.49", "0"], ["84398.06", "0"], ["84395.85", "0"], ["84391.89", "0.071102"], ["84389.43", "0"], ["84386.29", "0.355325"], ["84386.28", "0"], ["84386.27", "0"], ["84386.2", "0"]], "a": [["84442.08", "0.063868"], ["84444.12", "0.05114"], ["84444.13", "0.071058"], ["84446.13", "0"], ["84446.29", "0.007453"], ["84448.83", "0.011841"], ["84449.77", "0"], ["84451.24", "0.000153"], ["84457.32", "0.059948"], ["84458.98", "0.162"], ["84474.2", "0.00062"], ["84475.59", "0"], ["84478.43", "0.071029"], ["84479.12", "0.157813"], ["84479.92", "0.000987"], ["84483.79", "0.355329"], ["84487.63", "0"], ["84489.22", "0"], ["84490.84", "0.027942"], ["84494.67", "0"], ["84495.79", "0"], ["84495.94", "0"], ["84496.05", "0"], ["84496.46", "0"], ["84497.66", "0"], ["84497.83", "0"]], "u": 7510799, "seq": 66889432942}, "cts": 1742142255804, "record_time": 1742142254.909147}
{"topic": "orderbook.200.BTCUSDT", "ts": 1742142256009, "type": "delta", "data": {"s": "BTCUSDT", "b": [["84442.07", "0.049723"], ["84437.88", "0.040207"], ["84437.87", "0.032355"], ["84437.86", "0.011843"], ["84437.85", "0.024043"], ["84437.27", "0.071316"], ["84435.97", "0.0001"], ["84433.63", "0.0005"], ["84430.71", "0.000296"], ["84429.41", "0.04895"], ["84426.87", "0.000861"], ["84425.74", "0.000234"], ["84423.06", "0.281732"], ["84419.39", "0.222"], ["84419.1", "0"], ["84417.4", "0"], ["84414.3", "0"], ["84414", "0"], ["84398.3", "0.177637"], ["84398.07", "0"], ["84397.97", "0.0013"], ["84387.96", "0"], ["84387.12", "0"], ["84386.37", "0"], ["84386.29", "0"]], "a": [["84442.08", "0.018287"], ["84442.91", "0.001873"], ["84444.12", "0"], ["84444.13", "0"], ["84444.88", "0.033697"], ["84446.13", "0.042479"], ["84446.29", "0.011841"], ["84446.71", "0.071056"], ["84449", "0.000153"], ["84451.24", "0"], ["84462.12", "0"], ["84466.61", "0.139676"], ["84467.04", "0.008688"], ["84482.88", "0.0012"], ["84483.79", "0"], ["84486.36", "0.355325"], ["84493.55", "0.322663"], ["84494.02", "0"], ["84494.44", "0"], ["84494.48", "0"], ["84494.92", "0"], ["84495.41", "0"]], "u": 7510800, "seq": 66889433156}, "cts": 1742142256003, "record_time": 1742142255.108072}
{"topic": "orderbook.200.BTCUSDT", "ts": 1742142256209, "type": "delta", "data": {"s": "BTCUSDT", "b": [["84442.07", "0"], ["84441.91", "0"], ["84440.3", "0"], ["84440.19", "0"], ["84439.67", "0"], ["84439.58", "0"], ["84439.53", "0"], ["84438.45", "0"], ["84437.88", "0"], ["84437.87", "0"], ["84437.86", "0"], ["84437.85", "0"], ["84437.76", "0"], ["84437.44", "0"], ["84437.27", "0"], ["84435.97", "0"], ["84435.55", "0"], ["84435.36", "0"], ["84435.31", "0"], ["84435.23", "0"], ["84435.1", "0"], ["84435.02", "0"], ["84433.64", "0"], ["84433.63", "0"], ["84432.79", "0.002651"], ["84431.67", "0"], ["84431.49", "0.059073"], ["84431.48", "0"], ["84430.7", "0"], ["84430.24", "0"], ["84429.52", "0.000959"], ["84429.41", "0"], ["84429.4", "0"], ["84428.5", "0"], ["84428.3", "0"], ["84428.27", "0"], ["84428.1", "0"], ["84427.04", "0"], ["84426.88", "0"], ["84426.87", "0.000613"], ["84426.6", "0"], ["84426.41", "0"], ["84426.4", "0"], ["84425.75", "0"], ["84425.55", "0"], ["84425.35", "0"], ["84425.12", "0"], ["84424.7", "0"], ["84424.52", "0.00144"], ["84424.4", "0"], ["84424.35", "0.0005"], ["84423.1", "0"], ["84423.07", "0"], ["84423.06", "0"], ["84423.04", "0"], ["84422.5", "0"], ["84421.7", "0"], ["84421.46", "0"], ["84421.41", "0.06558"], ["84421.3", "0"], ["84420.95", "0.000089"], ["84420.49", "0"], ["84420.18", "0"], ["84420.06", "0"], ["84419.95", "0"], ["84419.39", "0"], ["84418.99", "0"], ["84418.79", "0"], ["84418.34", "0"], ["84417.82", "0"], ["84417.42", "0.000296"], ["84417.41", "0"], ["84417.22", "0"], ["84416.27", "0"], ["84415.84", "0"], ["84415.71", "0.005"], ["84414.23", "0.036002"], ["84414.22", "0.001467"], ["84414.21", "0.001067"], ["84412.28", "0"], ["84410.95", "0"], ["84410.75", "0"], ["84410.53", "0"], ["84410.41", "0"], ["84410.17", "0.009898"], ["84409.5", "0.04"], ["84408.77", "0"], ["84408.11", "0.006057"], ["84406.92", "0"], ["84405.97", "0"], ["84405.77", "0.628096"], ["84405.42", "0.017796"], ["84405.12", "0"], ["84404.94", "0"], ["84403.95", "0"], ["84402.82", "0"], ["84402.2", "0.000797"], ["84399.38", "0"], ["84399.31", "0.019095"], ["84398.31", "0.053751"], ["84398.3", "0"], ["84397.52", "0"], ["84396.55", "0"], ["84396.23", "0.012111"], ["84396.02", "0.059948"], ["84395.82", "0"], ["84395.5", "0"], ["84395.31", "0"], ["84394.83", "0"], ["84394.74", "0"], ["84393.05", "0"], ["84393.04", "0"], ["84392.44", "0.009086"], ["84391.89", "0"], ["84390.95", "0"], ["84389.65", "0.0002"], ["84389.42", "0"], ["84389", "0"], ["84388.97", "0.023684"], ["84387.88", "0.05"], ["84387.87", "0.049563"], ["84387.16", "0.059948"], ["84387.12", "0.0002"], ["84386.37", "0.001467"], ["84386.27", "0.005503"], ["84386.2", "0.000252"], ["84384.71", "0.001333"], ["84384.67", "0.000613"], ["84384.64", "0.023684"], ["84384.59", "0.0002"], ["84384.48", "0.000234"], ["84383.96", "0.000234"], ["84383.94", "0.005921"], ["84383.83", "0.023684"], ["84383.14", "0.0025"], ["84382.38", "0.015"], ["84381.73", "0.001467"], ["84381.56", "0.000252"], ["84380.99", "0.023684"], ["84380.97", "0.071111"], ["84380.49", "0.001333"], ["84380.45", "0.000611"], ["84380.32", "0.017765"], ["84379.84", "0.000234"], ["84379.32", "0.000234"], ["84378.79", "0.089922"], ["84378.7", "0.000089"], ["84377.09", "0.001467"], ["84376.92", "0.000252"], ["84376.4", "0.000357"], ["84376.27", "0.001333"], ["84376.23", "0.000611"], ["84375.9", "0.001243"], ["84375.45", "0.39838"], ["84375.2", "0.000234"], ["84375.1", "0.24702"], ["84374.68", "0.000234"], ["84373.73", "0.02369"], ["84373.64", "0.177656"], ["84373.22", "0.005924"], ["84372.46", "0.059948"], ["84372.45", "0.001467"], ["84372.28", "0.000252"], ["84372.05", "0.001333"], ["84372.01", "0.000612"], ["84371.44", "0.005922"], ["84370.56", "0.000234"], ["84370.3", "0.000089"], ["84370.25", "0.000089"], ["84370.17", "0.646282"], ["84370.04", "0.000234"], ["84369.7", "0.059087"], ["84368.46", "0.000335"], ["84367.84", "0.001333"], ["84367.81", "0.001467"], ["84367.79", "0.000612"], ["84367.64", "0.000252"], ["84367.41", "0.237018"], ["84366.97", "0.005"], ["84366.84", "0.00118"], ["84366.25", "0.000158"], ["84365.92", "0.000234"], ["84365.4", "0.000234"], ["84365", "0.001243"], ["84363.62", "0.001333"], ["84363.57", "0.000613"], ["84363.17", "0.001467"], ["84363", "0.000252"], ["84361.93", "0.237018"], ["84361.8", "0.000089"], ["84361.7", "0.183749"], ["84361.28", "0.000234"], ["84360.96", "0.059948"]], "a": [["84432.8", "0.225993"], ["84433.64", "0.210437"], ["84433.8", "0.359689"], ["84435.37", "0.059948"], ["84435.56", "0.237018"], ["84437.27", "0.05216"], ["84437.28", "0.038816"], ["84437.4", "0.005"], ["84437.76", "0.0002"], ["84438.45", "0.0004"], ["84438.46", "0.0004"], ["84438.51", "0.089922"], ["84439.53", "0.000611"], ["84439.58", "0.001333"], ["84439.67", "0.000234"], ["84440.19", "0.000234"], ["84440.3", "0.0002"], ["84441.91", "0.121107"], ["84441.92", "0.237018"], ["84441.94", "0.006057"], ["84442", "0.005"], ["84442.08", "0.025151"], ["84442.12", "0.035529"], ["84442.83", "0.0002"], ["84442.91", "0.001592"], ["84443.6", "0.035529"], ["84443.76", "0.000611"], ["84443.8", "0.001333"], ["84444.31", "0.000234"], ["84444.58", "0.005921"], ["84444.66", "0.051304"], ["84444.84", "0.000234"], ["84444.87", "0.059948"], ["84444.88", "0.0002"], ["84445.36", "0.0002"], ["84446.13", "0"], ["84446.3", "0"], ["84446.31", "0.0005"], ["84446.56", "0.000252"], ["84446.71", "0"], ["84446.72", "0.001467"], ["84447.9", "0.0002"], ["84447.98", "0.000611"], ["84448.02", "0.001333"], ["84448.83", "0"], ["84448.95", "0.019249"], ["84448.96", "0.000482"], ["84449", "0"], ["84449.46", "0.175419"], ["84449.48", "0.000234"], ["84449.7", "0.162"], ["84450.52", "0"], ["84451.06", "0.076996"], ["84453.12", "0.089922"], ["84453.47", "0"], ["84457.45", "0.017796"], ["84457.62", "0.009086"], ["84458.01", "0"], ["84458.97", "0.355423"], ["84461.32", "0.086673"], ["84461.58", "0"], ["84461.89", "0.071043"], ["84465.45", "0.012106"], ["84466.6", "0"], ["84466.61", "0.25811"], ["84469.46", "0.029772"], ["84471.07", "0.027942"], ["84473.7", "0.023687"], ["84474.2", "0"], ["84474.51", "0"], ["84474.92", "0"], ["84475.01", "0.473461"], ["84476.15", "1.595453"], ["84477.68", "0"], ["84478", "0.322884"], ["84478.16", "0"], ["84478.43", "0"], ["84479.13", "0.177656"], ["84479.58", "0"], ["84483.07", "0"], ["84483.8", "0"], ["84484.29", "0"], ["84486.36", "0"], ["84486.37", "0"], ["84487.74", "0"], ["84487.83", "0"], ["84488.37", "0"], ["84488.44", "0"], ["84488.53", "0"], ["84488.77", "0"], ["84489.5", "0"], ["84490.01", "0"], ["84490.02", "0"], ["84490.14", "0"], ["84490.15", "0"], ["84490.21", "0"], ["84490.25", "0"], ["84490.35", "0"], ["84490.73", "0"], ["84490.77", "0"], ["84490.84", "0"], ["84490.96", "0"], ["84490.98", "0"], ["84491.14", "0"], ["84491.29", "0"], ["84491.38", "0"], ["84491.96", "0"], ["84492.17", "0"], ["84492.52", "0"], ["84492.63", "0"], ["84492.83", "0"], ["84493.01", "0"], ["84493.13", "0"], ["84493.18", "0"], ["84493.26", "0"], ["84493.51", "0"], ["84493.55", "0"]], "u": 7510801, "seq": 66889435206}, "cts": 1742142256208, "record_time": 1742142255.30973}
{"topic": "orderbook.200.BTCUSDT", "ts": 1742142256410, "type": "delta", "data": {"s": "BTCUSDT", "b": [["84432.79", "0"], ["84432.7", "0"], ["84432.62", "0"], ["84431.49", "0"], ["84431.13", "0.03383"], ["84430.71", "0"], ["84430.66", "0.010582"], ["84429.17", "0.000099"], ["84426.07", "0.025294"], ["84426.06", "0.026997"], ["84426.05", "0.011844"], ["84424.75", "0.011844"], ["84423.45", "0.016395"], ["84422.7", "0.043418"], ["84422.69", "0.050283"], ["84420.4", "0.003"], ["84420.2", "0.003"], ["84420", "0.003"], ["84417.42", "0"], ["84416.62", "0"], ["84415.1", "0.120738"], ["84415.08", "0.111814"], ["84414.38", "0.119739"], ["84414.26", "0.000296"], ["84414.24", "0.011964"], ["84414.23", "0.162072"], ["84413.36", "0.006099"], ["84413.2", "0.044"], ["84413", "0.04"], ["84411.5", "0.04"], ["84411.3", "0.04"], ["84409.59", "0.014533"], ["84409.4", "0.052"], ["84408.78", "0"], ["84408.11", "0"], ["84407.9", "0.04"], ["84407.86", "0.177406"], ["84407.7", "0.04"], ["84406.92", "0.167803"], ["84406.6", "0.04"], ["84406.2", "0.04"], ["84405.82", "0.059948"], ["84405.77", "0.055461"], ["84405.62", "0"], ["84403.68", "0.163395"], ["84403.18", "0.236878"], ["84402.52", "0.237109"], ["84402.31", "0.008959"], ["84401.69", "0"], ["84400.27", "0"], ["84399.95", "0.175419"], ["84399.7", "0.297427"], ["84398.96", "0.236878"], ["84398.89", "0.139674"], ["84398.76", "0.270986"], ["84398.31", "0"], ["84398.3", "0.236875"], ["84396.7", "0.009139"], ["84396.36", "0.000987"], ["84396.01", "0"], ["84395.32", "0.008453"], ["84394.65", "1.555234"], ["84393.08", "0.28652"], ["84392.72", "0.072495"], ["84392.68", "0.059167"], ["84392.44", "0"], ["84388.81", "0"], ["84388.34", "0.053683"], ["84387.88", "0"], ["84387.87", "0"], ["84387.39", "0"], ["84387.2", "0"], ["84385.78", "0.05"], ["84385.77", "0.049553"], ["84385.46", "0.071107"], ["84384.22", "0.162"], ["84382.05", "0.0002"], ["84381", "0.237018"], ["84380.98", "0.355379"], ["84380.97", "0"], ["84378.85", "0.004628"], ["84375.77", "0.162"], ["84375.1", "0"], ["84375", "0.24702"], ["84373.65", "0.237018"], ["84373.22", "0"], ["84372.46", "0"], ["84372.45", "0"], ["84372.28", "0"], ["84372.05", "0"], ["84372.01", "0"], ["84371.44", "0"], ["84370.56", "0"], ["84370.3", "0"], ["84370.25", "0"], ["84370.17", "0"], ["84370.04", "0"], ["84369.7", "0"], ["84368.46", "0"], ["84367.84", "0"], ["84367.81", "0"], ["84367.79", "0"], ["84367.64", "0"], ["84367.41", "0"], ["84366.97", "0"], ["84366.84", "0"], ["84366.25", "0"], ["84365.92", "0"], ["84365.4", "0"], ["84365", "0"], ["84363.62", "0"], ["84363.57", "0"], ["84363.17", "0"], ["84363", "0"], ["84361.93", "0"], ["84361.8", "0"], ["84361.7", "0"], ["84361.28", "0"], ["84360.96", "0"]], "a": [["84431.14", "0.031568"], ["84431.5", "0.000153"], ["84432.8", "0.035"], ["84433.64", "0.01"], ["84433.8", "0"], ["84435.23", "0.0002"], ["84435.37", "0"], ["84435.55", "0.071105"], ["84436.42", "0.000099"], ["84437.01", "0.011843"], ["84437.27", "0.018343"], ["84437.44", "0.001467"], ["84438.51", "0"], ["84441.11", "0.000089"], ["84441.91", "0.082072"], ["84441.94", "0"], ["84442", "0"], ["84442.08", "0.036993"], ["84442.12", "0"], ["84442.91", "0"], ["84443.6", "0"], ["84444.47", "0.112573"], ["84444.66", "0.035594"], ["84445.26", "0.116792"], ["84445.35", "0.037781"], ["84446.2", "0.118897"], ["84446.29", "0"], ["84446.93", "0.006099"], ["84448.86", "0.225141"], ["84448.95", "0.019497"], ["84448.96", "0.000234"], ["84449", "0.04"], ["84449.2", "0.056"], ["84452.72", "0.171176"], ["84453.12", "0"], ["84453.42", "0.160166"], ["84453.5", "0.04"], ["84454.2", "0.052"], ["84454.24", "0.00462"], ["84455.5", "0.0442"], ["84455.7", "0"], ["84455.89", "0.163314"], ["84455.9", "0.04"], ["84456.1", "0"], ["84457.33", "0.210979"], ["84457.34", "0.236875"], ["84457.62", "0"], ["84458.97", "0"], ["84460.88", "0.264344"], ["84461.55", "0.236875"], ["84461.57", "0.298502"], ["84461.89", "0"], ["84462.51", "0.009148"], ["84466.49", "0.278028"], ["84466.63", "0.071039"], ["84467.56", "0.01936"], ["84468.42", "0.014078"], ["84469.59", "0.004739"], ["84470.62", "0.000987"], ["84471.07", "0"], ["84473.01", "0.071034"], ["84473.02", "0"], ["84473.35", "0.473461"], ["84475.01", "0"], ["84477.36", "0.021323"], ["84477.99", "0.355362"], ["84479.12", "0"], ["84479.92", "0"], ["84481.65", "0.027942"], ["84482.88", "0"], ["84483.14", "0"], ["84483.37", "0"], ["84483.66", "0"], ["84483.72", "0"], ["84483.89", "0"], ["84484.16", "0"], ["84484.78", "0"], ["84484.79", "0"], ["84485.02", "0"], ["84485.3", "0"], ["84485.91", "0"], ["84485.99", "0"], ["84486.03", "0"], ["84486.12", "0"], ["84486.65", "0"], ["84487.64", "0"], ["84487.65", "0"]], "u": 7510802, "seq": 66889435821}, "cts": 1742142256407, "record_time": 1742142255.50972}
{"topic": "orderbook.200.BTCUSDT", "ts": 1742142256610, "type": "delta", "data": {"s": "BTCUSDT", "b": [["84431.13", "0.062256"], ["84429.17", "0"], ["84426.07", "0.013553"], ["84426.06", "0"], ["84415.11", "0.000296"], ["84415.1", "0.000072"], ["84415.08", "0"], ["84414.62", "0.000296"], ["84414.38", "0"], ["84414.26", "0"], ["84414.24", "0"], ["84414.23", "0.162"], ["84409.45", "0.175419"], ["84408.25", "0.11844"], ["84407.86", "0"], ["84407.18", "0.02"], ["84406.92", "0"], ["84403.68", "0"], ["84401", "0.009179"], ["84400.32", "0.290927"], ["84399.95", "0"], ["84399.7", "0"], ["84398.76", "0"], ["84398.3", "0"], ["84396.7", "0"], ["84394.66", "0.46664"], ["84393.08", "0"], ["84392.55", "0.005951"], ["84391.4", "0.023257"], ["84381.01", "0.35535"], ["84380.98", "0"], ["84373.22", "0.005924"], ["84372.46", "0.059948"], ["84372.45", "0.001467"], ["84372.28", "0.000252"], ["84372.05", "0.001333"]], "a": [["84431.14", "0.030009"], ["84431.5", "0"], ["84432.8", "0"], ["84433.64", "0"], ["84435.23", "0.032137"], ["84435.55", "0"], ["84435.56", "0"], ["84436.36", "0.09771"], ["84436.37", "0.237018"], ["84436.42", "0"], ["84437.01", "0"], ["84437.27", "0.000252"], ["84437.88", "0.000264"], ["84441.86", "0.000153"], ["84444.47", "0"], ["84444.66", "0.1134"], ["84445.26", "0"], ["84446.2", "0"], ["84448.95", "0.019249"], ["84449.2", "0.056248"], ["84449.46", "0"], ["84449.7", "0"], ["84452.72", "0"], ["84453.41", "0.223936"], ["84453.42", "0"], ["84454.3", "0.052"], ["84454.57", "0"], ["84455.89", "0"], ["84457.34", "0"], ["84457.7", "0"], ["84458.53", "0.175419"], ["84459.2", "0"], ["84460.88", "0"], ["84461.2", "0"], ["84461.32", "0.249895"], ["84461.46", "0.283457"], ["84461.55", "0"], ["84461.57", "0"], ["84462.2", "0.0006"], ["84462.5", "0"], ["84466.49", "0"], ["84466.61", "0.139676"], ["84466.63", "0"], ["84469.46", "0"], ["84469.59", "0"], ["84476.59", "0.029772"], ["84477.61", "0.07103"], ["84477.99", "0"], ["84479.13", "0"], ["84481.65", "0"], ["84482.68", "0.355351"], ["84482.88", "0.0012"], ["84483.04", "0.0045"], ["84483.14", "0.0025"], ["84483.25", "0.0045"], ["84483.29", "0.0045"], ["84483.37", "0.0002"], ["84483.45", "0.0045"], ["84483.49", "0.0045"], ["84483.66", "0.000089"], ["84483.72", "0.000253"], ["84483.89", "0.001467"], ["84484.16", "0.008453"], ["84484.78", "0.059948"], ["84484.79", "0.118574"], ["84485.02", "0.00315"], ["84485.3", "0.246059"], ["84485.91", "0.0002"], ["84485.99", "0.000612"], ["84486.03", "0.001333"], ["84486.12", "0.000235"]], "u": 7510803, "seq": 66889436508}, "cts": 1742142256601, "record_time": 1742142255.709025}
{"topic": "orderbook.200.BTCUSDT", "ts": 1742142256810, "type": "delta", "data": {"s": "BTCUSDT", "b": [["84431.13", "0.132916"], ["84427.36", "0.000099"], ["84418.4", "0.000296"], ["84416.62", "0.107054"], ["84416.59", "0.10607"], ["84415.11", "0"], ["84415.1", "0"], ["84414.97", "0.000496"], ["84414.62", "0"], ["84414.39", "0.101193"], ["84409.98", "0.02"], ["84408.8", "0.02"], ["84408.44", "0.181296"], ["84407.6", "0.02"], ["84407.18", "0"], ["84406.73", "0.067675"], ["84405.21", "0.173098"], ["84400.32", "0"], ["84400.29", "0.287978"], ["84396.36", "0"], ["84394.7", "0.000987"], ["84394.61", "0.28985"], ["84389.78", "0.05"], ["84389.77", "0.049548"], ["84385.78", "0"], ["84385.77", "0"], ["84381.02", "0.355363"], ["84381.01", "0"], ["84373.65", "0"], ["84373.64", "0"], ["84373.22", "0"], ["84372.46", "0"], ["84372.45", "0"], ["84372.28", "0"], ["84372.05", "0"]], "a": [["84434.91", "0.000099"], ["84435.35", "0.000118"], ["84436.36", "0.088452"], ["84437.88", "0.009509"], ["84438.45", "0"], ["84438.46", "0"], ["84441.86", "0"], ["84441.91", "0.081672"], ["84444.66", "0.08019"], ["84445.96", "0.118567"], ["84446.75", "0.108177"], ["84448.86", "0.152716"], ["84449.2", "0.056"], ["84449.62", "0.000337"], ["84453.41", "0"], ["84454.5", "0.06"], ["84454.9", "0.176776"], ["84457.33", "0.100097"], ["84457.37", "0.165715"], ["84461", "0"], ["84461.32", "0.086673"], ["84461.46", "0"], ["84461.55", "0.236879"], ["84463.05", "0.287658"], ["84465.77", "0.236879"], ["84467.97", "0.294427"], ["84468.96", "0.000987"], ["84470.62", "0"], ["84471.26", "0.032137"], ["84478.77", "0.355359"], ["84479.13", "0.17766"], ["84482.68", "0"], ["84484.79", "0"], ["84485.02", "0"], ["84485.3", "0"], ["84485.91", "0"], ["84485.99", "0"], ["84486.03", "0"], ["84486.12", "0"]], "u": 7510804, "seq": 66889436702}, "cts": 1742142256808, "record_time": 1742142255.908837}
{"topic": "orderbook.200.BTCUSDT", "ts": 1742142257010, "type": "delta", "data": {"s": "BTCUSDT", "b": [["84430.51", "0.022344"], ["84430.5", "0.07107"], ["84424.44", "0.005"], ["84424.35", "0"], ["84423.57", "0.003"], ["84423.37", "0.003"], ["84423.17", "0.003"], ["84422.7", "0.132833"], ["84422.69", "0.050783"], ["84421.9", "0.044"], ["84420.5", "0.236909"], ["84420.2", "0.043"], ["84419.23", "0.118288"], ["84419.2", "0.108525"], ["84418.34", "0.105782"], ["84417.77", "0.068486"], ["84416.81", "0.23692"], ["84416.8", "0.043"], ["84416.62", "0.000072"], ["84416.59", "0"], ["84416.03", "0.109835"], ["84414.98", "0.000296"], ["84414.97", "0.0002"], ["84414.4", "0.052"], ["84413.12", "0.23693"], ["84412.05", "0.236879"], ["84411.82", "0.168867"], ["84411.58", "0.02"], ["84411.05", "0.180028"], ["84409.98", "0"], ["84409.59", "0.237348"], ["84409.29", "0.02"], ["84408.8", "0"], ["84408.64", "0.02"], ["84408.44", "0"], ["84408.1", "0.02"], ["84407.88", "0.179787"], ["84407.83", "0.236879"], ["84407.82", "0.164257"], ["84407.6", "0"], ["84406.73", "0"], ["84406.21", "0.237018"], ["84405.21", "0"], ["84403.67", "0.28012"], ["84403.18", "0"], ["84402.9", "0.28196"], ["84402.52", "0.000234"], ["84400.3", "0.237018"], ["84400.29", "0.001467"], ["84399.73", "0.264198"], ["84397.22", "0.271959"], ["84394.67", "0.237018"], ["84394.61", "0"], ["84390.58", "0.05"], ["84390.57", "0.049882"], ["84389.78", "0"], ["84389.77", "0"], ["84385.47", "0.355342"], ["84381.56", "0"], ["84381.02", "0"], ["84381", "0"], ["84380.99", "0"], ["84380.49", "0"], ["84380.45", "0"], ["84380.32", "0"], ["84379.84", "0"], ["84379.32", "0"], ["84378.85", "0"], ["84378.79", "0"], ["84378.7", "0"], ["84377.09", "0"], ["84376.92", "0"], ["84376.4", "0"], ["84376.27", "0"], ["84376.23", "0"], ["84375.9", "0"], ["84375.77", "0"], ["84375.45", "0"], ["84375.2", "0"], ["84375", "0"], ["84374.68", "0"], ["84373.73", "0"]], "a": [["84431.83", "0.024425"], ["84435.23", "0.0002"], ["84435.35", "0"], ["84436.36", "0"], ["84436.37", "0"], ["84437.27", "0.032282"], ["84437.28", "0"], ["84437.76", "0.029252"], ["84437.88", "0"], ["84438.62", "0.071063"], ["84439.58", "0.001833"], ["84441.92", "0"], ["84444.65", "0.048758"], ["84444.66", "0"], ["84445.96", "0"], ["84446.31", "0"], ["84446.75", "0"], ["84448.57", "0.115781"], ["84448.86", "0.217454"], ["84448.87", "0"], ["84449.36", "0.120243"], ["84449.62", "0.000089"], ["84450.13", "0.118242"], ["84451.08", "0.120137"], ["84451.2", "0.000501"], ["84454.29", "0.184398"], ["84454.58", "0"], ["84454.9", "0"], ["84456.65", "0.169776"], ["84457.37", "0"], ["84457.51", "0.168046"], ["84459.23", "0.159807"], ["84459.98", "0.164743"], ["84461.55", "0"], ["84463.05", "0"], ["84464.8", "0.280286"], ["84465.66", "0.278829"], ["84467.38", "0.300675"], ["84467.97", "0"], ["84469.99", "0.236879"], ["84470.58", "0.294566"], ["84471.26", "0"], ["84475.36", "0.236879"], ["84476.59", "0"], ["84478.57", "0.003422"], ["84478.77", "0"], ["84479.13", "0"], ["84479.58", "0.236879"], ["84479.66", "0.029772"], ["84482.64", "0.17766"], ["84482.92", "0.0045"], ["84483.49", "0"], ["84484.77", "0.355342"], ["84484.78", "0"]], "u": 7510805, "seq": 66889437410}, "cts": 1742142257007, "record_time": 1742142256.108919}
{"topic": "orderbook.200.BTCUSDT", "ts": 1742142257210, "type": "delta", "data": {"s": "BTCUSDT", "b": [["84431.13", "0.03583"], ["84430.67", "0.031508"], ["84424.44", "0"], ["84422.7", "0.134353"], ["84421.9", "0"], ["84420.2", "0.003"], ["84419.23", "0"], ["84419.2", "0"], ["84418.6", "0.04"], ["84418.47", "0.107885"], ["84418.34", "0"], ["84417.77", "0.112037"], ["84416.8", "0.003"], ["84416.03", "0"], ["84412.68", "0.020335"], ["84412.1", "0.04"], ["84411.82", "0"], ["84411.8", "0.04"], ["84411.58", "0"], ["84411.39", "0.02"], ["84411.05", "0"], ["84410.84", "0.02"], ["84410.42", "0.175392"], ["84410.19", "0.02"], ["84409.4", "0"], ["84409.29", "0"], ["84409.14", "0.02"], ["84408.64", "0"], ["84408.1", "0"], ["84407.88", "0"], ["84407.82", "0"], ["84407.7", "0.206924"], ["84406.21", "0"], ["84403.67", "0"], ["84402.9", "0"], ["84402.27", "0.264753"], ["84399.73", "0"], ["84398.96", "0"], ["84397.22", "0"], ["84391.28", "0.049546"], ["84391.27", "0.049546"], ["84390.95", "0.17766"], ["84390.58", "0"], ["84390.57", "0.000335"], ["84389", "0.000119"], ["84388.3", "0.04"], ["84388.29", "0.03964"], ["84385.47", "0"], ["84381.56", "0.000252"], ["84381", "0.237018"], ["84380.99", "0.023684"], ["84380.49", "0.001333"], ["84380.45", "0.000611"], ["84380.32", "0.017765"], ["84379.84", "0.000234"]], "a": [["84431.14", "0.032009"], ["84435.23", "0.032178"], ["84436.25", "0.025099"], ["84436.26", "0.071065"], ["84437.27", "0.000252"], ["84437.76", "0.0002"], ["84438.61", "0.003"], ["84438.62", "0"], ["84441.91", "0.000252"], ["84444.65", "0.075203"], ["84448.57", "0"], ["84448.86", "0.09175"], ["84449.36", "0"], ["84450.13", "0.000199"], ["84450.32", "0.023933"], ["84451.08", "0"], ["84451.2", "0.000253"], ["84454.29", "0"], ["84456.65", "0"], ["84457.51", "0"], ["84459.22", "0.179743"], ["84459.23", "0"], ["84459.98", "0"], ["84463.41", "0.265229"], ["84464.8", "0"], ["84465.66", "0"], ["84465.77", "0"], ["84467.38", "0"], ["84469.82", "0.301323"], ["84469.99", "0"], ["84470.58", "0"], ["84471.14", "0.236879"], ["84471.4", "0.030009"], ["84477.36", "0.061323"], ["84477.37", "0.04"], ["84477.6", "0.355364"], ["84479.58", "0"], ["84482.64", "0"], ["84484.77", "0"], ["84484.78", "0.059948"], ["84484.79", "0.118574"], ["84485.02", "0.00315"], ["84485.3", "0.246059"], ["84485.91", "0.0002"], ["84485.99", "0.000612"], ["84486.03", "0.001333"], ["84486.12", "0.000235"]], "u": 7510806, "seq": 66889437946}, "cts": 1742142257205, "record_time": 1742142256.309091}
{"topic": "orderbook.200.BTCUSDT", "ts": 1742142257409, "type": "delta", "data": {"s": "BTCUSDT", "b": [["84431.13", "0.10649"], ["84430.68", "0.025519"], ["84430.67", "0"], ["84430.51", "0"], ["84425.54", "0.003"], ["84418.88", "0.117684"], ["84418.7", "0.044"], ["84418.48", "0.076319"], ["84418.47", "0.001333"], ["84418.08", "0.107908"], ["84417.77", "0"], ["84417.7", "0.006314"], ["84416.9", "0.04"], ["84416.67", "0.112523"], ["84415.2", "0.04"], ["84413.5", "0.04"], ["84413.48", "0.02"], ["84413.36", "0"], ["84413.2", "0"], ["84412.68", "0.000335"], ["84412.19", "0.02"], ["84411.56", "0.175414"], ["84411.39", "0"], ["84411.3", "0"], ["84410.89", "0.02"], ["84410.7", "0.170552"], ["84410.42", "0"], ["84410.19", "0"], ["84408.52", "0.161887"], ["84407.9", "0"], ["84407.84", "0.237018"], ["84407.7", "0"], ["84407.47", "0.179605"], ["84407.4", "0.236879"], ["84406.73", "0.236879"], ["84406.6", "0"], ["84406.2", "0"], ["84403.41", "0.267762"], ["84403.18", "0.236879"], ["84402.52", "0.237113"], ["84402.27", "0"], ["84400.37", "0.281812"], ["84396.87", "0.2785"], ["84391.29", "0.05"], ["84391.27", "0"], ["84383.14", "0"], ["84382.38", "0"], ["84382.05", "0"], ["84381.73", "0"], ["84381.56", "0"], ["84381", "0"], ["84380.99", "0"], ["84380.49", "0"], ["84380.45", "0"], ["84380.32", "0"], ["84379.84", "0"]], "a": [["84431.14", "0.020986"], ["84435.23", "0.0002"], ["84436.25", "0"], ["84440.58", "0.000153"], ["84444.65", "0.076947"], ["84448.55", "0.09175"], ["84448.86", "0"], ["84449.01", "0.112866"], ["84449.87", "0.114073"], ["84450.32", "0.023685"], ["84451.2", "0.000501"], ["84451.72", "0.116557"], ["84454.19", "0.077246"], ["84456.39", "0.157693"], ["84459.22", "0"], ["84459.63", "0.1597"], ["84459.87", "0.171543"], ["84463.41", "0"], ["84464.54", "0.29631"], ["84465.31", "0.272123"], ["84467.67", "0.00951"], ["84468.02", "0.273025"], ["84469.82", "0"], ["84470.23", "0.286327"], ["84477.6", "0"], ["84478.77", "0.355358"], ["84483.04", "0"], ["84484.78", "0"], ["84484.79", "0"], ["84485.02", "0"], ["84485.3", "0"], ["84485.91", "0"], ["84485.99", "0"], ["84486.03", "0"], ["84486.12", "0"]], "u": 7510807, "seq": 66889438336}, "cts": 1742142257408, "record_time": 1742142256.507917}
{"topic": "orderbook.200.BTCUSDT", "ts": 1742142257609, "type": "delta", "data": {"s": "BTCUSDT", "b": [["84419.88", "0.106934"], ["84419.86", "0.108394"], ["84419", "0.04"], ["84418.89", "0.170951"], ["84418.88", "0"], ["84418.6", "0.146305"], ["84418.48", "0"], ["84418.08", "0"], ["84417.28", "0.10552"], ["84416.67", "0"], ["84414.39", "0.367447"], ["84413.48", "0"], ["84413.38", "0.02"], ["84412.08", "0.177139"], ["84411.71", "0.164592"], ["84411.56", "0"], ["84411.54", "0.02"], ["84410.84", "0"], ["84410.7", "0"], ["84409.84", "0.02"], ["84409.59", "0.463949"], ["84409.5", "0"], ["84409.14", "0"], ["84409.13", "0.167584"], ["84408.52", "0"], ["84408.47", "0.174723"], ["84407.47", "0"], ["84403.93", "0.290554"], ["84403.55", "0.301597"], ["84403.41", "0"], ["84402.52", "0.000234"], ["84400.97", "0.296806"], ["84400.37", "0"], ["84397.87", "0.267573"], ["84396.87", "0"], ["84392.29", "0.004643"], ["84391.29", "0"], ["84391.28", "0"], ["84390.88", "0.049547"], ["84390.39", "0.05"], ["84388.3", "0"], ["84388.29", "0"], ["84388.02", "0.04"], ["84388.01", "0.03964"], ["84383.94", "0"], ["84383.83", "0"]], "a": [["84431.14", "0.034009"], ["84440.58", "0"], ["84444.65", "0.035444"], ["84445.35", "0"], ["84446.93", "0"], ["84448.55", "0.2127"], ["84449.01", "0"], ["84449.22", "0.120181"], ["84449.87", "0"], ["84450.01", "0.110356"], ["84450.39", "0.117396"], ["84451.51", "0.006342"], ["84451.72", "0"], ["84452.33", "0.113544"], ["84454.19", "0.114898"], ["84456.39", "0"], ["84456.91", "0.159834"], ["84457.33", "0.208024"], ["84458.17", "0.171331"], ["84459.63", "0"], ["84459.87", "0"], ["84460.48", "0.163801"], ["84460.64", "0.16669"], ["84464.54", "0"], ["84465.06", "0.295879"], ["84468.02", "0"], ["84468.63", "0.280156"], ["84470.23", "0"], ["84470.7", "0.237079"], ["84471.23", "0.295656"], ["84471.4", "0"], ["84471.43", "0.034009"], ["84477.36", "0.021323"], ["84477.37", "0"], ["84477.67", "0.04"], ["84477.68", "0.04"], ["84478.77", "0"], ["84482.68", "0.355355"], ["84484.16", "0"]], "u": 7510808, "seq": 66889438609}, "cts": 1742142257608, "record_time": 1742142256.707821}
{"topic": "orderbook.200.BTCUSDT", "ts": 1742142257809, "type": "delta", "data": {"s": "BTCUSDT", "b": [["84437.39", "0.211603"], ["84436.56", "0.011843"], ["84434.91", "0.0004"], ["84434.9", "0.03"], ["84432.7", "0.0002"], ["84432.62", "0.000252"], ["84431.14", "0.0004"], ["84431.13", "0.001333"], ["84430.68", "0"], ["84430.5", "0"], ["84429.04", "0.005"], ["84428.95", "0.04945"], ["84427.84", "0.006385"], ["84427.33", "0.237282"], ["84427.32", "0.23689"], ["84426.07", "0"], ["84426.05", "0"], ["84425.63", "0.236895"], ["84425.6", "0.106"], ["84425.1", "0.115155"], ["84424.76", "0.000296"], ["84424.75", "0"], ["84424.25", "0.005"], ["84423.7", "0.04"], ["84422.71", "0.059351"], ["84422.7", "0.203874"], ["84422.69", "0.001333"], ["84422.68", "0.162"], ["84420.5", "0"], ["84420.49", "0.236862"], ["84419.88", "0"], ["84419.86", "0"], ["84418.97", "0.008453"], ["84418.69", "0.175671"], ["84418.6", "0.202237"], ["84418.4", "0"], ["84417.7", "0"], ["84417.64", "0.019095"], ["84417.3", "0.04"], ["84417.28", "0"], ["84416.9", "0.08"], ["84416.81", "0"], ["84416.46", "0.000797"], ["84416.27", "0.236862"], ["84415.84", "0.236862"], ["84415.71", "0"], ["84415.68", "0.02"], ["84414.41", "0.059948"], ["84414.39", "0.387447"], ["84414.22", "0.163249"], ["84413.54", "0.02"], ["84413.51", "0.237018"], ["84413.38", "0"], ["84413.12", "0"], ["84412.93", "0.009578"], ["84412.19", "0"], ["84412.08", "0"], ["84412.05", "0"], ["84411.71", "0"], ["84411.62", "0.236862"], ["84411.54", "0"], ["84411.5", "0"], ["84410.89", "0"], ["84410.47", "0.301379"], ["84409.84", "0"], ["84409.45", "0"], ["84409.41", "0.013012"], ["84409.13", "0"], ["84408.47", "0"], ["84408.25", "0"], ["84407.83", "0"], ["84407.46", "0.023686"], ["84407.4", "0"], ["84407.06", "0.071089"], ["84406.73", "0"], ["84406.63", "0.089922"], ["84406.07", "0.280113"], ["84405.22", "0.005921"], ["84403.93", "0"], ["84403.65", "0.294986"], ["84403.55", "0"], ["84403.18", "0"], ["84402.2", "0"], ["84401", "0"], ["84400.97", "0"], ["84400.93", "0.000987"], ["84399.8", "0.071095"], ["84399.5", "0.323023"], ["84399.31", "0"], ["84397.87", "0"], ["84396.23", "0"], ["84395.32", "0"], ["84394.74", "0.177646"], ["84394.7", "0"], ["84392.72", "0.001394"], ["84390.96", "0.355306"], ["84390.88", "0"], ["84390.78", "0.049547"], ["84388.02", "0"], ["84388.01", "0"], ["84387.92", "0.04"], ["84387.91", "0.03964"], ["84385.46", "0"], ["84384.22", "0"], ["84383.96", "0"]], "a": [["84431.14", "0"], ["84431.83", "0"], ["84434.91", "0"], ["84435.23", "0"], ["84436.26", "0"], ["84437.27", "0"], ["84437.4", "0.01331"], ["84438.61", "0"], ["84439.58", "0.001333"], ["84441.11", "0"], ["84441.91", "0.028635"], ["84444.65", "0"], ["84444.87", "0"], ["84445.84", "0.032127"], ["84445.97", "0.005"], ["84447.43", "0.071055"], ["84448.55", "0"], ["84448.88", "0.062876"], ["84449", "0"], ["84449.2", "0"], ["84449.22", "0"], ["84450.01", "0"], ["84450.39", "0"], ["84451.2", "0.000253"], ["84451.51", "0"], ["84452.33", "0"], ["84453.5", "0"], ["84454.19", "0"], ["84454.2", "0"], ["84454.24", "0"], ["84454.3", "0"], ["84454.5", "0"], ["84455.18", "0.070916"], ["84455.5", "0.0002"], ["84455.9", "0"], ["84456.91", "0"], ["84458.05", "0.139665"], ["84458.17", "0"], ["84458.4", "0.056"], ["84458.53", "0"], ["84458.98", "0"], ["84460", "0.04"], ["84460.48", "0"], ["84460.52", "0.006385"], ["84460.64", "0"], ["84461.33", "0"], ["84461.7", "0.052"], ["84462.51", "0"], ["84462.75", "0.162"], ["84463.32", "0.158967"], ["84464.7", "0.044"], ["84465.06", "0"], ["84465.1", "0.04"], ["84465.3", "0.337587"], ["84466.25", "0.161847"], ["84466.59", "0"], ["84466.61", "0"], ["84467.04", "0"], ["84467.08", "0"], ["84467.42", "0.008748"], ["84467.52", "0.175419"], ["84468.42", "0"], ["84468.63", "0"], ["84468.96", "0"], ["84470.69", "0.237018"], ["84470.7", "0.237062"], ["84471.14", "0"], ["84471.23", "0"], ["84471.43", "0"], ["84471.45", "0.283121"], ["84473.01", "0"], ["84473.22", "0.004675"], ["84473.35", "0"], ["84473.7", "0"], ["84474.2", "0.236862"], ["84474.92", "0.236862"], ["84475.24", "0.000987"], ["84475.36", "0"], ["84475.43", "0.009578"], ["84476.82", "0.287641"], ["84477.36", "0"], ["84477.61", "0"], ["84477.67", "0"], ["84477.68", "0"], ["84478", "0.000161"], ["84478.42", "0.236862"], ["84479.58", "0.236862"], ["84479.66", "0"], ["84482.67", "0.04"], ["84482.68", "0.04"], ["84483.8", "0.236862"], ["84484.16", "0.008453"], ["84484.2", "0.037662"], ["84484.63", "0.071024"], ["84484.78", "0.059948"], ["84484.79", "0.118574"], ["84485.02", "0.00315"], ["84485.3", "0.246059"], ["84485.91", "0.0002"], ["84485.99", "0.000612"], ["84486.03", "0.001333"], ["84486.12", "0.000235"], ["84486.65", "0.000235"], ["84487.37", "0.014025"], ["84487.74", "0.017796"], ["84488.37", "0.000253"], ["84488.44", "0.0002"], ["84488.53", "0.001467"], ["84489.18", "0.07102"], ["84489.5", "0.427229"], ["84490", "0.002053"], ["84490.01", "0.0045"], ["84490.02", "0.003"], ["84490.14", "0.023682"], ["84490.21", "0.005112"]], "u": 7510809, "seq": 66889440082}, "cts": 1742142257807, "record_time": 1742142256.909359}
{"topic": "orderbook.200.BTCUSDT", "ts": 1742142258010, "type": "delta", "data": {"s": "BTCUSDT", "b": [["84436.57", "0.012809"], ["84433.18", "0.011843"], ["84432.99", "0.0001"], ["84429.05", "0.018856"], ["84427.36", "0"], ["84427.34", "0.000296"], ["84425.6", "0"], ["84425.1", "0.0002"], ["84423.8", "0.044"], ["84422.73", "0.114545"], ["84422.7", "0.134353"], ["84422.68", "0"], ["84422", "0.04"], ["84420.3", "0.04"], ["84419.7", "0.052"], ["84418.7", "0"], ["84418.6", "0.04"], ["84417.9", "0.04"], ["84417.78", "0.02"], ["84416.9", "0.04"], ["84416.49", "0.02"], ["84415.68", "0"], ["84415.39", "0.02"], ["84414.98", "0"], ["84414.6", "0.168271"], ["84414.4", "0"], ["84414.39", "0.367447"], ["84414.24", "0.02"], ["84414.22", "0.001467"], ["84413.84", "0.02"], ["84413.54", "0"], ["84413.51", "0"], ["84413.5", "0"], ["84413", "0"], ["84412.1", "0"], ["84411.8", "0"], ["84410.47", "0"], ["84409.68", "0.293636"], ["84409.59", "0"], ["84407.06", "0"], ["84406.47", "0.263296"], ["84406.07", "0"], ["84403.65", "0"], ["84398.3", "0.177646"], ["84397.97", "0"], ["84395.84", "0.071099"], ["84394.99", "0.0013"], ["84394.65", "0"], ["84391.4", "0"], ["84390.96", "0"]], "a": [["84444.4", "0.0003"], ["84444.5", "0.071058"], ["84444.88", "0"], ["84445.84", "0.0005"], ["84446.21", "0.000153"], ["84447.43", "0"], ["84452.96", "0.023563"], ["84454.96", "0.066549"], ["84455.18", "0"], ["84457.31", "0.237018"], ["84457.33", "0.100097"], ["84457.69", "0.118711"], ["84458.4", "0.096"], ["84461.32", "0.127322"], ["84462.74", "0.237018"], ["84463.32", "0"], ["84463.4", "0.052"], ["84464.5", "0.06"], ["84465.3", "0.001467"], ["84465.82", "0.161316"], ["84466.25", "0"], ["84471.45", "0"], ["84473.95", "0.288555"], ["84476.38", "0.01331"], ["84476.82", "0"], ["84477.64", "0.07103"], ["84482.4", "0.0012"], ["84482.67", "0"], ["84482.68", "0"], ["84482.88", "0"], ["84483.67", "0.04"], ["84483.68", "0.04"], ["84487.42", "0.029772"], ["84489.18", "0"], ["84489.5", "0"], ["84490", "0"], ["84490.01", "0"], ["84490.02", "0"], ["84490.14", "0"], ["84490.21", "0"]], "u": 7510810, "seq": 66889440391}, "cts": 1742142258006, "record_time": 1742142257.109745}
{"topic": "orderbook.200.BTCUSDT", "ts": 1742142258210, "type": "delta", "data": {"s": "BTCUSDT", "b": [["84433.62", "0.000099"], ["84425.93", "0.112705"], ["84425.91", "0.110724"], ["84424.95", "0.119644"], ["84422.73", "0"], ["84422.69", "0.110825"], ["84418.89", "0.261423"], ["84418.45", "0.158499"], ["84417.99", "0.02"], ["84417.78", "0.184196"], ["84416.79", "0.02"], ["84416.49", "0"], ["84415.94", "0.02"], ["84415.39", "0"], ["84415.2", "0"], ["84414.6", "0"], ["84414.56", "0.163129"], ["84414.55", "0.158503"], ["84414.39", "0.101193"], ["84413.84", "0"], ["84410.32", "0.26393"], ["84409.68", "0"], ["84409.65", "0.267586"], ["84406.47", "0"], ["84406.43", "0.29657"], ["84403.98", "0.29955"], ["84394.66", "0"], ["84384.71", "0"], ["84384.67", "0"], ["84384.64", "0"], ["84384.59", "0"], ["84384.48", "0"]], "a": [["84444.14", "0.005294"], ["84445.71", "0.000153"], ["84446.21", "0"], ["84452.96", "0.0002"], ["84454.96", "0"], ["84455.2", "0.113553"], ["84455.99", "0.109061"], ["84456.66", "0.112417"], ["84457.3", "0.229256"], ["84457.33", "0"], ["84457.65", "0.11664"], ["84457.69", "0"], ["84463.17", "0.16906"], ["84464.12", "0.165847"], ["84465.78", "0.230174"], ["84465.82", "0"], ["84466.58", "0.172087"], ["84471.3", "0.274393"], ["84473.91", "0.285253"], ["84473.95", "0"], ["84476.38", "0"], ["84476.42", "0.01331"], ["84477.15", "0.284065"], ["84484.62", "0.355332"], ["84486.12", "0"], ["84486.65", "0"], ["84487.37", "0"], ["84487.42", "0"], ["84487.74", "0"], ["84488.37", "0"], ["84488.44", "0"], ["84488.53", "0"]], "u": 7510811, "seq": 66889440550}, "cts": 1742142258207, "record_time": 1742142257.308204}
{"topic": "orderbook.200.BTCUSDT", "ts": 1742142258410, "type": "delta", "data": {"s": "BTCUSDT", "b": [["84434.91", "0"], ["84429.31", "0.003"], ["84429.11", "0.003"], ["84428.91", "0.003"], ["84425.97", "0.11774"], ["84425.94", "0.115483"], ["84425.93", "0"], ["84425.91", "0"], ["84425", "0.108461"], ["84424.95", "0"], ["84423.17", "0"], ["84422.73", "0.10788"], ["84422.69", "0.001333"], ["84420.4", "0"], ["84420.2", "0"], ["84420", "0"], ["84419.28", "0.02"], ["84418.5", "0.178084"], ["84418.45", "0"], ["84417.81", "0.179823"], ["84417.78", "0"], ["84417.34", "0.02"], ["84417.2", "0"], ["84417", "0"], ["84416.8", "0"], ["84415.94", "0"], ["84415.74", "0.02"], ["84414.6", "0.176009"], ["84414.58", "0.178326"], ["84414.56", "0"], ["84414.55", "0"], ["84414.24", "0"], ["84410.37", "0.282497"], ["84410.32", "0"], ["84409.68", "0.275646"], ["84409.65", "0"], ["84407.27", "0.023798"], ["84406.47", "0.290731"], ["84406.43", "0"], ["84405.85", "1.545652"], ["84403.98", "0"], ["84389.07", "0.2"], ["84388.35", "0.355322"], ["84386.21", "0.237018"], ["84386.2", "0"]], "a": [["84444.14", "0"], ["84445.71", "0"], ["84447.51", "0.000153"], ["84455.19", "0.068758"], ["84455.2", "0"], ["84455.24", "0.111912"], ["84455.99", "0"], ["84456.03", "0.106573"], ["84456.66", "0"], ["84457.16", "0.022593"], ["84457.45", "0"], ["84457.65", "0"], ["84457.69", "0.114637"], ["84461.32", "0.279728"], ["84463.17", "0"], ["84463.22", "0.173131"], ["84464.12", "0"], ["84464.16", "0.171634"], ["84465.78", "0.059948"], ["84465.82", "0.178481"], ["84466.58", "0"], ["84466.62", "0.176871"], ["84469.57", "0.017796"], ["84471.3", "0"], ["84471.35", "0.298915"], ["84473.91", "0"], ["84476.37", "0.01331"], ["84476.42", "0"], ["84477.15", "0"], ["84477.19", "0.282554"], ["84484.62", "0"], ["84486.12", "0.000235"]], "u": 7510812, "seq": 66889440687}, "cts": 1742142258407, "record_time": 1742142257.508997}
