{"topic": "orderbook.200.BTCUSDT", "ts": 1742585762320, "type": "snapshot", "data": {"s": "BTCUSDT", "b": [["83938.8", "0.124038"], ["83935.2", "0.006823"], ["83934.7", "0.005476"], ["83932.9", "0.002263"], ["83932.3", "0.090672"], ["83932.2", "0.087293"], ["83931.6", "0.001333"], ["83931.3", "0.09504"], ["83930.8", "0.001466"], ["83930.5", "0.005475"], ["83930.4", "0.06"], ["83930", "0.000524"], ["83929.7", "0.001"], ["83929.6", "0.048"], ["83929.5", "0.001"], ["83928.9", "0.071523"], ["83928.1", "0.000333"], ["83928", "0.216788"], ["83927.9", "0.06"], ["83927.4", "0.065333"], ["83927.3", "0.05019"], ["83926.5", "0.02"], ["83926.3", "0.005475"], ["83926.1", "0.001466"], ["83925.8", "0.084"], ["83925.5", "0.003"], ["83925.4", "0.000524"], ["83925.1", "0.059999"], ["83925", "0.191"], ["83924.7", "0.051392"], ["83924.6", "0.056"], ["83924.4", "0.131337"], ["83924.3", "0.067906"], ["83924.2", "0.00448"], ["83924.1", "0.06"], ["83924", "0.000333"], ["83923.4", "0.019686"], ["83923.2", "0.010719"], ["83922.9", "0.056"], ["83922.4", "0.056"], ["83922.1", "0.005465"], ["83921.5", "0.001466"], ["83921.2", "0.112232"], ["83920.7", "0.052528"], ["83920", "0.026049"], ["83919.9", "0.0001"], ["83919.8", "0.000333"], ["83919", "0.001333"], ["83918.9", "0.00166"], ["83918", "0.064763"], ["83917.9", "0.005465"], ["83917.7", "0.118539"], ["83917.3", "0.030388"], ["83916.9", "0.001466"], ["83916.6", "0.059399"], ["83916.1", "0.000528"], ["83916", "0.00009"], ["83915.6", "0.000333"], ["83915.5", "0.000358"], ["83915", "0.000807"], ["83914.9", "0.001333"], ["83914.7", "0.035748"], ["83914.4", "0.003575"], ["83914.2", "0.055423"], ["83914.1", "0.178702"], ["83913.7", "0.005465"], ["83913.3", "0.178702"], ["83913.2", "0.00039"], ["83913", "0.000464"], ["83912.3", "0.001466"], ["83912.2", "0.171"], ["83911.9", "0.005957"], ["83911.5", "0.000528"], ["83911.4", "0.000333"], ["83911.2", "0.118539"], ["83910.7", "0.001686"], ["83910.4", "0.023827"], ["83909.5", "0.005465"], ["83909.1", "0.178702"], ["83909", "0.000376"], ["83908.9", "0.05391"], ["83908.6", "0.00211"], ["83907.7", "0.001466"], ["83907.6", "0.440781"], ["83907.4", "0.007557"], ["83907.3", "0.059399"], ["83907.2", "0.000333"], ["83906.9", "0.000528"], ["83906.5", "0.001333"], ["83906", "0.004704"], ["83905.4", "0.011087"], ["83905.3", "0.601452"], ["83905", "0.118539"], ["83904.8", "0.003575"], ["83904.7", "0.551828"], ["83904", "0.000701"], ["83903.8", "0.171"], ["83903.1", "0.001466"], ["83903", "0.000333"], ["83902.3", "0.025687"], ["83901.2", "0.005465"], ["83900.8", "0.039635"], ["83900.7", "0.039636"], ["83900.6", "0.023826"], ["83900.2", "0.000777"], ["83900.1", "0.00006"], ["83900", "0.004538"], ["83899.7", "0.013093"], ["83899.6", "0.012882"], ["83899.2", "0.00009"], ["83898.9", "0.01192"], ["83898.8", "0.000333"], ["83898.5", "0.001466"], ["83898.1", "0.001333"], ["83897.9", "0.173938"], ["83897.8", "0.168087"], ["83897.7", "0.000528"], ["83897.6", "0.12558"], ["83897.5", "0.023826"], ["83897", "0.005465"], ["83896.8", "0.02971"], ["83896.5", "0.023826"], ["83895.4", "0.173501"], ["83895.2", "0.059399"], ["83894.7", "0.00042"], ["83894.6", "0.00126"], ["83894.2", "0.00009"], ["83893.9", "0.001333"], ["83893.8", "0.001466"], ["83893.4", "0.000358"], ["83893", "0.006484"], ["83892.8", "0.005465"], ["83891.5", "0.023826"], ["83890.8", "0.052002"], ["83890.6", "0.125091"], ["83890.4", "0.096888"], ["83890.2", "0.00253"], ["83889.7", "0.001333"], ["83889.3", "0.357585"], ["83889.2", "0.001466"], ["83889", "0.100204"], ["83888.8", "0.001025"], ["83888.7", "0.003614"], ["83888.6", "0.037636"], ["83888.5", "0.000251"], ["83888.4", "0.000528"], ["83888.3", "0.004037"], ["83888", "0.000569"], ["83887.7", "0.118539"], ["83887.6", "0.342243"], ["83887.3", "0.023827"], ["83887.2", "0.048078"], ["83887", "0.171"], ["83886.7", "0.059399"], ["83886.6", "5.244234"], ["83886.2", "0.000333"], ["83885.7", "0.009225"], ["83885.5", "0.085163"], ["83885.4", "0.000149"], ["83885", "0.000333"], ["83884.6", "0.001466"], ["83884.4", "0.005465"], ["83884", "0.000118"], ["83883.9", "0.089351"], ["83883.8", "0.024358"], ["83883.4", "3.736288"], ["83883.2", "0.064"], ["83883", "0.000435"], ["83882.4", "0.00018"], ["83882.2", "0.023239"], ["83882", "0.000333"], ["83881.8", "0.00588"], ["83881.6", "0.000036"], ["83881.4", "0.118539"], ["83881.3", "0.018123"], ["83880.7", "0.02383"], ["83880.2", "0.005465"], ["83880", "0.006642"], ["83879.7", "0.02383"], ["83879.2", "0.000528"], ["83879", "0.003575"], ["83878.6", "0.171"], ["83878.3", "0.000572"], ["83878.1", "0.005956"], ["83878", "0.109881"], ["83877.8", "0.000333"], ["83877.1", "0.001333"], ["83876.8", "0.000094"], ["83876.2", "0.005957"], ["83876", "0.005657"], ["83875.9", "0.000067"], ["83875.8", "0.000302"], ["83875.7", "0.02016"], ["83875.4", "0.013466"], ["83875.3", "0.0015"], ["83875", "0.000436"], ["83874.7", "0.02383"], ["83874.6", "0.000528"], ["83874.1", "0.059399"], ["83874", "0.00009"]], "a": [["83938.9", "0.45795"], ["83939.2", "0.000524"], ["83939.4", "0.022466"], ["83939.5", "0.071514"], ["83940", "0.003039"], ["83940.7", "0.000333"], ["83941.4", "0.00108"], ["83941.9", "0.002"], ["83942.5", "0.0052"], ["83943.1", "0.00549"], ["83943.4", "0.063612"], ["83943.5", "0.026566"], ["83943.8", "0.079944"], ["83944.2", "0.001333"], ["83944.5", "0.004037"], ["83944.6", "0.001466"], ["83944.9", "0.000633"], ["83945", "0.071509"], ["83945.5", "0.0208"], ["83945.6", "0.009225"], ["83947.1", "0.171731"], ["83947.2", "0.260785"], ["83947.3", "0.236491"], ["83948.4", "0.001857"], ["83948.9", "0.073506"], ["83949.1", "0.000333"], ["83949.2", "0.004466"], ["83949.4", "0.051392"], ["83949.6", "0.140783"], ["83949.7", "0.031199"], ["83950.5", "0.0018"], ["83951.1", "0.178702"], ["83951.5", "0.004628"], ["83952.6", "0.001333"], ["83953.1", "0.025975"], ["83953.3", "0.000333"], ["83953.5", "0.04"], ["83953.6", "0.17867"], ["83953.8", "0.041466"], ["83954", "0.004418"], ["83955.1", "0.277562"], ["83955.2", "0.04009"], ["83955.3", "0.178702"], ["83955.5", "0.04"], ["83955.7", "0.00537"], ["83956.7", "0.04"], ["83956.8", "0.001333"], ["83956.9", "0.178702"], ["83957.1", "0.04"], ["83957.5", "0.000333"], ["83957.7", "0.179187"], ["83958", "0.059399"], ["83958.1", "0.137576"], ["83958.3", "0.04"], ["83958.4", "0.019384"], ["83958.5", "0.001466"], ["83958.8", "0.04"], ["83958.9", "0.000298"], ["83959.4", "0.178658"], ["83959.9", "0.015307"], ["83960", "0.00024"], ["83960.3", "0.04"], ["83960.5", "0.04"], ["83960.7", "0.171"], ["83961", "0.001333"], ["83961.7", "0.000333"], ["83962.3", "0.000526"], ["83963.1", "0.001466"], ["83963.4", "0.005957"], ["83963.6", "0.00009"], ["83964.1", "0.00537"], ["83965.2", "0.001333"], ["83965.3", "0.045887"], ["83965.4", "0.123682"], ["83965.9", "0.000333"], ["83966.2", "0.023941"], ["83966.4", "0.051392"], ["83966.8", "0.059399"], ["83966.9", "0.002585"], ["83967.2", "0.035747"], ["83967.5", "0.228841"], ["83967.6", "0.553113"], ["83967.7", "0.001466"], ["83967.9", "0.089351"], ["83968.3", "0.00537"], ["83969.1", "0.171"], ["83969.4", "0.001333"], ["83969.5", "0.000405"], ["83969.6", "0.023827"], ["83970.1", "0.000333"], ["83971.1", "0.118539"], ["83971.2", "0.308501"], ["83971.3", "0.594275"], ["83971.4", "0.000358"], ["83971.5", "0.000526"], ["83972", "0.00018"], ["83972.3", "0.001466"], ["83972.4", "0.341898"], ["83972.5", "0.00537"], ["83972.6", "0.03"], ["83973.6", "0.001333"], ["83974.3", "0.000633"], ["83974.5", "0.129732"], ["83976.1", "0.000526"], ["83976.7", "0.00537"], ["83976.9", "0.001466"], ["83977", "0.015"], ["83977.3", "0.04"], ["83977.4", "0.04"], ["83977.6", "0.127459"], ["83977.8", "0.001333"], ["83978.1", "0.022341"], ["83978.2", "0.011918"], ["83978.5", "0.118872"], ["83978.6", "0.171"], ["83978.8", "0.059399"], ["83979.3", "0.001787"], ["83980", "0.00024"], ["83980.4", "0.00009"], ["83980.5", "0.005956"], ["83980.6", "2.561884"], ["83980.7", "0.455618"], ["83980.8", "1.429426"], ["83980.9", "0.005372"], ["83981.6", "0.001466"], ["83981.8", "0.000795"], ["83982", "0.001333"], ["83982.3", "0.05148"], ["83982.7", "0.000333"], ["83984.8", "0.023825"], ["83985.1", "0.005372"], ["83985.4", "0.119065"], ["83986.2", "0.008755"], ["83986.4", "0.013922"], ["83986.9", "0.021213"], ["83987", "0.171"], ["83988", "0.000118"], ["83988.8", "0.357675"], ["83988.9", "0.089351"], ["83989.3", "0.005374"], ["83989.7", "0.023825"], ["83990", "0.000526"], ["83990.4", "0.001333"], ["83990.7", "0.023825"], ["83990.8", "0.001466"], ["83991.1", "0.000333"], ["83991.3", "0.059399"], ["83991.6", "0.051392"], ["83993.2", "0.147382"], ["83993.3", "0.118539"], ["83993.5", "0.005738"], ["83993.8", "0.023824"], ["83994.6", "0.001859"], ["83995", "0.005953"], ["83995.3", "0.001833"], ["83995.4", "0.013466"], ["83995.5", "0.319915"], ["83995.7", "0.000145"], ["83995.8", "1.063113"], ["83995.9", "3.493672"], ["83997.2", "0.00009"], ["83997.7", "0.00538"], ["83998.8", "0.001333"], ["83999.2", "0.000526"], ["83999.5", "0.000333"], ["83999.6", "0.003575"], ["84000", "0.001706"], ["84000.2", "1.787141"], ["84000.4", "0.000358"], ["84000.7", "0.013095"], ["84001.9", "0.005387"], ["84002.6", "0.04"], ["84003", "0.001333"], ["84003.2", "0.178565"], ["84003.4", "0.118539"], ["84003.7", "0.000633"], ["84003.9", "0.171526"], ["84004.5", "0.059399"], ["84004.7", "0.001466"], ["84005.4", "0.0006"], ["84005.6", "0.04009"], ["84006.1", "0.005387"], ["84006.9", "0.354"], ["84007.2", "0.001333"], ["84007.6", "0.04"], ["84007.9", "0.059864"], ["84008.5", "0.119065"], ["84009.3", "0.001466"], ["84010.3", "0.005399"], ["84010.4", "1.028445"], ["84011.4", "0.001333"], ["84012", "0.000333"], ["84012.1", "0.000333"], ["84012.3", "0.171"], ["84013.1", "0.000528"], ["84013.3", "0.027502"], ["84013.8", "0.059399"], ["84013.9", "0.120005"], ["84014", "0.00018"], ["84014.2", "0.04"]], "u": 172277, "seq": 67577758014}, "cts": 1742585762317, "record_time": 1742585763.867153, "EXCHANGE": "BYBIT"}
{"topic": "orderbook.200.BTCUSDT", "ts": 1742585762519, "type": "delta", "data": {"s": "BTCUSDT", "b": [["83938.8", "0.121095"], ["83901.4", "0.04"], ["83901.3", "0.039635"], ["83900.8", "0"], ["83900.7", "0"], ["83892.7", "0.013872"], ["83889.4", "0.357583"], ["83889.3", "0"], ["83874", "0"]], "a": [["83974.7", "0.04"], ["83974.8", "0.04"], ["83977.3", "0"], ["83977.4", "0"], ["83988.8", "0.357677"]], "u": 172278, "seq": 67577758043}, "cts": 1742585762514, "record_time": 1742585763.869153, "EXCHANGE": "BYBIT"}
{"topic": "orderbook.200.BTCUSDT", "ts": 1742585762719, "type": "delta", "data": {"s": "BTCUSDT", "b": [["83938.8", "0.193409"], ["83933.8", "0.022135"], ["83933.7", "0.071519"], ["83928.9", "0"], ["83889.5", "0.357583"], ["83889.4", "0"], ["83874.1", "0"]], "a": [["83938.9", "0.28695"], ["83988.8", "0.357673"]], "u": 172279, "seq": 67577758108}, "cts": 1742585762702, "record_time": 1742585763.870154, "EXCHANGE": "BYBIT"}
{"topic": "orderbook.200.BTCUSDT", "ts": 1742585762920, "type": "delta", "data": {"s": "BTCUSDT", "b": [["83911.3", "0.115851"], ["83901.6", "0.04"], ["83901.5", "0.039635"], ["83901.4", "0"], ["83901.3", "0"], ["83899.9", "0.013"], ["83899.8", "0.012881"], ["83899.7", "0.000093"], ["83899.6", "0"], ["83898.1", "0.051333"], ["83898", "0.049548"], ["83897.9", "0.123938"], ["83897.8", "0.118539"], ["83890.7", "0.35758"], ["83889.5", "0"], ["83885.4", "0"], ["83882.9", "0.000149"], ["83875", "0"], ["83874.7", "0"], ["83874.6", "0"]], "a": [["83988.8", "0.00009"], ["83991.2", "0.357576"], ["83993.2", "0.147527"], ["83995.7", "0"]], "u": 172280, "seq": 67577758148}, "cts": 1742585762916, "record_time": 1742585763.871703, "EXCHANGE": "BYBIT"}
{"topic": "orderbook.200.BTCUSDT", "ts": 1742585763119, "type": "delta", "data": {"s": "BTCUSDT", "b": [["83938.8", "0.363392"], ["83928.2", "0.000153"], ["83890.7", "0"], ["83889.1", "0.357581"], ["83875.3", "0"]], "a": [["83988.8", "0.357671"], ["83991.2", "0"], ["84014.5", "0.005702"]], "u": 172281, "seq": 67577758201}, "cts": 1742585763116, "record_time": 1742585763.872707, "EXCHANGE": "BYBIT"}
{"topic": "orderbook.200.BTCUSDT", "ts": 1742585763319, "type": "delta", "data": {"s": "BTCUSDT", "b": [["83912.8", "0.001135"], ["83901.6", "0.039635"], ["83898.2", "0.05"], ["83898.1", "0.050881"], ["83898", "0"], ["83890.9", "0.357574"], ["83889.1", "0"], ["83875.4", "0"]], "a": [["83967.2", "0"], ["83974.7", "0"], ["83974.9", "0.04"], ["83980.5", "1.221583"], ["83980.7", "0"], ["83988.8", "0.00009"], ["83991.2", "0.357576"], ["84015.4", "3.960015"]], "u": 172282, "seq": 67577758249}, "cts": 1742585763317, "record_time": 1742585763.873707, "EXCHANGE": "BYBIT"}
{"topic": "orderbook.200.BTCUSDT", "ts": 1742585763519, "type": "delta", "data": {"s": "BTCUSDT", "b": [["83931.3", "0.10574"], ["83928.2", "0"], ["83920.9", "0.02358"], ["83916", "0.551918"], ["83907.4", "0.005957"], ["83904.7", "0"], ["83902.6", "0.0016"], ["83899.9", "0.012881"]], "a": [["83965.2", "0.03708"]], "u": 172283, "seq": 67577758295}, "cts": 1742585763508, "record_time": 1742585763.874707, "EXCHANGE": "BYBIT"}
{"topic": "orderbook.200.BTCUSDT", "ts": 1742585763719, "type": "delta", "data": {"s": "BTCUSDT", "b": [["83918", "0.222216"], ["83907.6", "0.151447"], ["83898.2", "0"], ["83898", "0.049548"], ["83891", "0.357578"], ["83890.9", "0"]], "a": [["83939.4", "0"], ["83941.4", "0"], ["83948.9", "0.071506"], ["83949.4", "0"], ["83955.2", "0.091482"], ["83958", "0"], ["83966.4", "0"], ["83974.8", "0"], ["83975", "0.04"], ["83980.6", "0"], ["83983.2", "2.561884"], ["83991.2", "0"], ["83993.1", "0.35757"], ["84015.6", "0.001691"], ["84016.3", "0.000333"], ["84016.8", "0.051392"], ["84017.5", "0.080319"], ["84017.6", "0.683428"]], "u": 172284, "seq": 67577758377}, "cts": 1742585763716, "record_time": 1742585763.876709, "EXCHANGE": "BYBIT"}
{"topic": "orderbook.200.BTCUSDT", "ts": 1742585763919, "type": "delta", "data": {"s": "BTCUSDT", "b": [["83931.9", "0.07152"], ["83901.7", "0.04"], ["83901.5", "0"], ["83900", "0.017538"], ["83899.8", "0"], ["83898.2", "0.05"], ["83898", "0"], ["83891.1", "0.357572"], ["83891", "0"], ["83889.4", "5.189788"], ["83886.6", "0.021653"], ["83875.7", "0"]], "a": [["83946.3", "0.002"], ["83974.9", "0"], ["83975.1", "0.04"], ["83983.2", "0"], ["83985.9", "2.561884"], ["83991.2", "0.357572"], ["83993.1", "0"], ["84017.6", "0"]], "u": 172285, "seq": 67577758458}, "cts": 1742585763916, "record_time": 1742585764.010528, "EXCHANGE": "BYBIT"}
{"topic": "orderbook.200.BTCUSDT", "ts": 1742585764120, "type": "delta", "data": {"s": "BTCUSDT", "b": [["83938.8", "0.359993"], ["83907.6", "0.274753"], ["83891.1", "0"], ["83890.7", "0.357578"]], "a": [["83939.4", "0.022466"], ["83946.1", "0.002"], ["83980.5", "0.005956"], ["84016.8", "0"], ["84017.5", "0"]], "u": 172286, "seq": 67577758504}, "cts": 1742585764116, "record_time": 1742585764.211477, "EXCHANGE": "BYBIT"}
{"topic": "orderbook.200.BTCUSDT", "ts": 1742585764319, "type": "delta", "data": {"s": "BTCUSDT", "b": [["83938.8", "0.358803"], ["83929.2", "0.000153"], ["83900.6", "0.026826"], ["83890.9", "0.357577"], ["83890.7", "0"], ["83886.3", "0.024869"], ["83882.2", "0"], ["83875.8", "0"]], "a": [["83939.4", "0"], ["83949.2", "0.001466"], ["83965.3", "0.046749"], ["83983.2", "2.561884"], ["83985.8", "0.833032"], ["83985.9", "0"]], "u": 172287, "seq": 67577758572}, "cts": 1742585764301, "record_time": 1742585764.41062, "EXCHANGE": "BYBIT"}
{"topic": "orderbook.200.BTCUSDT", "ts": 1742585764520, "type": "delta", "data": {"s": "BTCUSDT", "b": [["83938.8", "0.358217"], ["83929.7", "0"], ["83929.2", "0"], ["83901.7", "0"], ["83901.6", "0"], ["83901.5", "0.039635"], ["83901.4", "0.039635"], ["83900", "0.004538"], ["83899.9", "0"], ["83899.8", "0.012881"], ["83899.7", "0.012975"], ["83898.2", "0"], ["83898.1", "0.001333"], ["83898", "0.049548"], ["83897.9", "0.173486"], ["83875.8", "0.000302"], ["83875.7", "0.02016"]], "a": [["83947", "0.001"], ["83957", "0.003518"], ["83965.3", "0.045887"], ["83975", "0"], ["83975.1", "0"], ["83975.6", "0.04"], ["83975.7", "0.04"], ["83985.8", "0"], ["83991.1", "0.357905"], ["83991.2", "0"]], "u": 172288, "seq": 67577758648}, "cts": 1742585764508, "record_time": 1742585764.611011, "EXCHANGE": "BYBIT"}
{"topic": "orderbook.200.BTCUSDT", "ts": 1742585764720, "type": "delta", "data": {"s": "BTCUSDT", "b": [["83938.8", "0.168618"], ["83900", "0.017538"], ["83899.9", "0.012881"], ["83899.8", "0"], ["83899.7", "0.000093"], ["83898.2", "0.05"], ["83898.1", "0.050881"], ["83898", "0"], ["83897.9", "0.123938"], ["83890.9", "0"], ["83885.6", "0.357584"], ["83881.5", "0.353962"], ["83875.7", "0"]], "a": [["83939.4", "0.022466"], ["83945.8", "0.071509"], ["83948.9", "0"], ["83966.2", "0"], ["83970.5", "0.024983"], ["83988.8", "0.357669"], ["83991.1", "0.000333"], ["84016.3", "0"]], "u": 172289, "seq": 67577758760}, "cts": 1742585764717, "record_time": 1742585764.811208, "EXCHANGE": "BYBIT"}
{"topic": "orderbook.200.BTCUSDT", "ts": 1742585764920, "type": "delta", "data": {"s": "BTCUSDT", "b": [["83933.9", "0.022135"], ["83933.8", "0.071519"], ["83933.7", "0"], ["83932.3", "0.124903"], ["83929.5", "0"], ["83925.1", "0.0006"], ["83924.7", "0.164565"], ["83914.9", "0.18249"], ["83905.8", "0.29389"], ["83900.1", "0.01306"], ["83900", "0.017419"], ["83899.9", "0"], ["83898.3", "0.05"], ["83898.2", "0.049547"], ["83898.1", "0.001333"], ["83889.4", "0"], ["83885.7", "0.366808"], ["83885.6", "0"], ["83883.8", "5.25242"], ["83875.7", "0.02016"], ["83875.4", "0.013466"]], "a": [["83938.9", "0.45795"], ["83949.9", "0.121231"], ["83955", "0.178667"], ["83956.6", "0.059399"], ["83957.7", "0.000526"], ["83959.7", "0.17325"], ["83968.8", "0.288939"], ["83980.6", "2.561884"], ["83983.2", "0"], ["83988.7", "0.357583"], ["83988.8", "0.00009"], ["84013.9", "0"], ["84014", "0"], ["84014.2", "0"], ["84014.5", "0"], ["84015.4", "0"], ["84015.6", "0"]], "u": 172290, "seq": 67577758864}, "cts": 1742585764909, "record_time": 1742585765.011702, "EXCHANGE": "BYBIT"}
{"topic": "orderbook.200.BTCUSDT", "ts": 1742585765119, "type": "delta", "data": {"s": "BTCUSDT", "b": [["83938.8", "0.202812"], ["83924.7", "0.051392"], ["83914.9", "0.001333"], ["83914.2", "0.156056"], ["83905.8", "0"], ["83901.8", "0.04"], ["83901.7", "0.039635"], ["83901.5", "0"], ["83901.4", "0"], ["83889.1", "0.357581"], ["83885.7", "0.009225"]], "a": [["83949.9", "0"], ["83955.1", "0.19181"], ["83959.7", "0"], ["83968.8", "0"], ["83974.9", "0.04"], ["83975", "0.04"], ["83975.6", "0"], ["83975.7", "0"], ["83988.6", "0.357581"], ["83988.7", "0"], ["84013.9", "0.120005"], ["84014", "0.00018"], ["84014.2", "0.04"]], "u": 172291, "seq": 67577758956}, "cts": 1742585765117, "record_time": 1742585765.210088, "EXCHANGE": "BYBIT"}
{"topic": "orderbook.200.BTCUSDT", "ts": 1742585765319, "type": "delta", "data": {"s": "BTCUSDT", "b": [["83916.6", "0.238101"], ["83914.1", "0"], ["83901.8", "0"], ["83901.7", "0"], ["83901.6", "0.039635"], ["83901.5", "0.039635"], ["83900.1", "0.00006"], ["83900", "0.017538"], ["83899.9", "0.012881"], ["83898.3", "0"], ["83898.2", "0.05"], ["83898.1", "0.050881"], ["83889.2", "0.359048"], ["83889.1", "0"], ["83875.3", "0.0015"], ["83875", "0.000436"]], "a": [["83941.9", "0"], ["83943.4", "0.111524"], ["83945", "0"], ["83954.4", "0.178702"], ["83954.9", "0.24541"], ["83955.1", "0"], ["83956.9", "0"], ["83988.5", "0.357582"], ["83988.6", "0"], ["83988.8", "0.025357"], ["83989.3", "0.030793"], ["84014.5", "0.005702"], ["84015.4", "3.960015"]], "u": 172292, "seq": 67577759051}, "cts": 1742585765310, "record_time": 1742585765.411015, "EXCHANGE": "BYBIT"}
{"topic": "orderbook.200.BTCUSDT", "ts": 1742585765520, "type": "delta", "data": {"s": "BTCUSDT", "b": [["83938.8", "0.047393"], ["83935.3", "0.055669"], ["83935.2", "0.177823"], ["83933.9", "0"], ["83933.8", "0"], ["83932.4", "0.000298"], ["83930.4", "0"], ["83929.3", "0.071523"], ["83926.8", "0.06"], ["83914.2", "0.055423"], ["83901.6", "0.04"], ["83900", "0.004538"], ["83899.9", "0.013"], ["83899.8", "0.012881"], ["83898.2", "0"], ["83898", "0.049548"], ["83889.3", "0.357581"], ["83889.2", "0.001466"], ["83875.4", "0"], ["83875.3", "0"], ["83875", "0"]], "a": [["83938.9", "0.517355"], ["83939", "0.000258"], ["83939.4", "0"], ["83939.5", "0"], ["83942.5", "0"], ["83945.5", "0"], ["83945.6", "0.080734"], ["83945.8", "0"], ["83946.8", "0.00009"], ["83949.7", "0"], ["83979", "1.4289"], ["83980.5", "1.221583"], ["83980.8", "0.000526"], ["83982.3", "0.051481"], ["83988.4", "0.357581"], ["83988.5", "0"], ["84015.6", "0.001691"], ["84016.3", "0.000333"], ["84016.8", "0.051392"]], "u": 172293, "seq": 67577759211}, "cts": 1742585765508, "record_time": 1742585765.611152, "EXCHANGE": "BYBIT"}
{"topic": "orderbook.200.BTCUSDT", "ts": 1742585765720, "type": "delta", "data": {"s": "BTCUSDT", "b": [["83938.8", "0.077177"], ["83919.8", "0.055999"], ["83912.8", "0.055748"], ["83911.6", "0.125091"], ["83905.8", "0.119592"], ["83889.4", "0.357579"], ["83889.3", "0"], ["83875.8", "0"], ["83875.7", "0"]], "a": [["83938.9", "0.547141"], ["83942.5", "0.0052"], ["83945.5", "0.0208"], ["83946", "0.002"], ["83949.7", "0.031199"], ["83954.8", "0.059787"], ["83961.8", "0.061582"], ["83968.8", "0.108515"], ["83980.5", "0.005956"], ["83980.6", "0"], ["83983.2", "2.561882"], ["83988.4", "0"], ["83991.2", "0.357579"], ["84014", "0"], ["84014.2", "0"], ["84014.5", "0"], ["84015.4", "0"], ["84015.6", "0"], ["84016.3", "0"], ["84016.8", "0"]], "u": 172294, "seq": 67577759287}, "cts": 1742585765714, "record_time": 1742585765.810582, "EXCHANGE": "BYBIT"}
{"topic": "orderbook.200.BTCUSDT", "ts": 1742585765919, "type": "delta", "data": {"s": "BTCUSDT", "b": [["83935.3", "0"], ["83935.2", "0.006823"], ["83931.9", "0"], ["83927.2", "0.071524"], ["83923.3", "0.010781"], ["83919.8", "0.000333"], ["83917.7", "0"], ["83916.7", "0.118539"], ["83912.8", "0.001135"], ["83905.8", "0"], ["83901.6", "0"], ["83901.4", "0.039635"], ["83899.9", "0"], ["83899.7", "0.012975"], ["83898.1", "0.001333"], ["83897.9", "0.173486"], ["83889.4", "0"], ["83887.8", "0.357584"], ["83883.8", "5.303978"], ["83875.8", "0.000302"], ["83875.7", "0.02016"]], "a": [["83938.9", "0.618655"], ["83949.6", "0.139029"], ["83951.3", "0.178675"], ["83953.6", "0"], ["83954.7", "0.178668"], ["83954.8", "0"], ["83959.4", "0"], ["83961.8", "0.003575"], ["83968.8", "0"], ["83986.9", "0.378798"], ["83991.2", "0"], ["84014", "0.00018"], ["84014.2", "0.04"], ["84014.5", "0.005702"]], "u": 172295, "seq": 67577759376}, "cts": 1742585765916, "record_time": 1742585766.010227, "EXCHANGE": "BYBIT"}
{"topic": "orderbook.200.BTCUSDT", "ts": 1742585766119, "type": "delta", "data": {"s": "BTCUSDT", "b": [["83938.8", "0.133282"], ["83933", "0.022135"], ["83932.9", "0.073782"], ["83930.5", "0.005628"], ["83927.2", "0"], ["83925.1", "0.059999"], ["83924.3", "0.185417"], ["83916.6", "0.059399"], ["83914.5", "0.163752"], ["83914.2", "0.102446"], ["83913.3", "0"], ["83911.6", "0"], ["83905.4", "0.299349"], ["83901.6", "0.04"], ["83901.4", "0"], ["83899.9", "0.013"], ["83899.7", "0.000093"], ["83898.1", "0.051333"], ["83897.9", "0.123938"], ["83890.9", "0.357576"], ["83887.8", "0"], ["83886.6", "5.301273"], ["83883.8", "0.024358"]], "a": [["83938.9", "0.447894"], ["83949.5", "0.124412"], ["83949.6", "0.097631"], ["83951.3", "0"], ["83954.7", "0"], ["83954.9", "0.138199"], ["83955", "0"], ["83959.3", "0.18254"], ["83968.4", "0.287823"], ["83986.9", "0.021213"], ["83991.2", "0.357574"], ["84003.2", "0"]], "u": 172296, "seq": 67577759539}, "cts": 1742585766117, "record_time": 1742585766.211007, "EXCHANGE": "BYBIT"}
{"topic": "orderbook.200.BTCUSDT", "ts": 1742585766320, "type": "delta", "data": {"s": "BTCUSDT", "b": [["83930.4", "0.06"], ["83926.8", "0"], ["83925.5", "0"], ["83914.6", "0.105961"], ["83914.2", "0"], ["83909.1", "0"], ["83909", "0.179078"], ["83908.8", "0.119134"], ["83904.9", "0.178702"], ["83900.7", "0.178702"], ["83900.6", "0.023826"], ["83890.9", "0"], ["83889.1", "0.357581"], ["83875.7", "0"]], "a": [["83938.9", "0.450255"], ["83959.6", "0.119134"], ["83961.8", "0"], ["83965.5", "0.001098"], ["83988.8", "0.382941"], ["83991.2", "0"]], "u": 172297, "seq": 67577759638}, "cts": 1742585766315, "record_time": 1742585766.410733, "EXCHANGE": "BYBIT"}
{"topic": "orderbook.200.BTCUSDT", "ts": 1742585766520, "type": "delta", "data": {"s": "BTCUSDT", "b": [["83938.8", "0.077777"], ["83937.5", "0.071516"], ["83933", "0"], ["83932.9", "0.002263"], ["83931.2", "0.071521"], ["83930.5", "0.005475"], ["83924.3", "0.067906"], ["83914.5", "0"], ["83906.5", "0.180035"], ["83905.4", "0.011087"], ["83904.9", "0"], ["83900.7", "0"], ["83892.3", "0.178702"], ["83889.1", "0"], ["83888.1", "0.178702"], ["83887.8", "0.357586"], ["83886.6", "0.021653"], ["83883.9", "0"], ["83883.8", "5.303978"], ["83875.7", "0.02016"]], "a": [["83938.9", "0.631655"], ["83949.5", "0"], ["83954.3", "0.210472"], ["83954.9", "0"], ["83958.8", "0.0406"], ["83959.3", "0"], ["83965.5", "0"], ["83968.4", "0"], ["83986.9", "0.378799"], ["83988.8", "0.025357"], ["84015.4", "3.960015"], ["84015.6", "0.001691"], ["84016.3", "0.000333"], ["84016.8", "0.051392"]], "u": 172298, "seq": 67577759774}, "cts": 1742585766501, "record_time": 1742585766.610383, "EXCHANGE": "BYBIT"}
{"topic": "orderbook.200.BTCUSDT", "ts": 1742585766719, "type": "delta", "data": {"s": "BTCUSDT", "b": [["83938.4", "0.071515"], ["83937.5", "0"], ["83914.6", "0.056836"], ["83901.6", "0.039635"], ["83899.9", "0.012881"], ["83898.1", "0.050881"], ["83892.3", "0"], ["83888.7", "0.361198"], ["83888.1", "0"], ["83887.8", "0"], ["83875.4", "0.013466"], ["83875.3", "0.0015"], ["83875", "0.000436"]], "a": [["83949.6", "0.192631"], ["83950.8", "0.178676"], ["83952.5", "0.178672"], ["83954.2", "0.178669"], ["83977.6", "0.528197"], ["83992.8", "0.178587"], ["84015.4", "0"], ["84015.6", "0"], ["84016.3", "0"], ["84016.8", "0"]], "u": 172299, "seq": 67577759861}, "cts": 1742585766696, "record_time": 1742585766.809658, "EXCHANGE": "BYBIT"}
{"topic": "orderbook.200.BTCUSDT", "ts": 1742585766920, "type": "delta", "data": {"s": "BTCUSDT", "b": [["83938.8", "0.078577"], ["83932.7", "0.07152"], ["83931.2", "0"], ["83889.1", "0.357581"], ["83888.7", "0.003614"], ["83883.8", "5.200655"], ["83875", "0"]], "a": [["83938.9", "0.460655"], ["83986.9", "0.021213"], ["83988.8", "0.38294"]], "u": 172300, "seq": 67577759930}, "cts": 1742585766896, "record_time": 1742585767.010715, "EXCHANGE": "BYBIT"}
{"topic": "orderbook.200.BTCUSDT", "ts": 1742585767119, "type": "delta", "data": {"s": "BTCUSDT", "b": [["83938.8", "0"], ["83938.4", "0"], ["83932.7", "0"], ["83932.3", "0.000333"], ["83932.2", "0.027293"], ["83931.3", "0.09504"], ["83929.3", "0"], ["83928", "0.040942"], ["83927.4", "0.001333"], ["83927.3", "0"], ["83926.5", "0"], ["83925.8", "0"], ["83925.1", "0.0006"], ["83925", "0.171"], ["83924.3", "0.064"], ["83924.2", "0"], ["83923.4", "0"], ["83923.3", "0"], ["83923.2", "0.001333"], ["83922.9", "0"], ["83922.4", "0"], ["83921.2", "0.000555"], ["83920.7", "0.000528"], ["83917.1", "0.042909"], ["83916.7", "0"], ["83916.6", "0"], ["83914.7", "0"], ["83911.6", "0.125091"], ["83911.2", "0"], ["83910.4", "0"], ["83910.1", "0.0502"], ["83909", "0.000376"], ["83908.8", "0"], ["83907.3", "0"], ["83906.5", "0.001333"], ["83901.6", "0"], ["83901.5", "0"], ["83899.9", "0"], ["83899.8", "0"], ["83898.1", "0.001333"], ["83898", "0"], ["83897.6", "0"], ["83892.3", "0.04"], ["83892.2", "0.039644"], ["83890.9", "0.357574"], ["83889.7", "0.014333"], ["83889.6", "0.012885"], ["83889.1", "0.125606"], ["83887.9", "0.05"], ["83887.8", "0.04956"], ["83887.3", "0"], ["83886.3", "0"], ["83884", "0"], ["83883.9", "0.089351"], ["83883.8", "0.024358"], ["83875", "0.000436"], ["83874.7", "0.02383"], ["83874.6", "0.000528"], ["83874.1", "0.059399"], ["83874", "0.00009"], ["83873.7", "0.118539"], ["83873.6", "0.000333"], ["83872.9", "0.001333"], ["83872.8", "0.000043"], ["83871.8", "0.005465"], ["83871.5", "0.000083"], ["83871.3", "0.001739"], ["83870.8", "0.001466"], ["83870", "0.000528"], ["83869.9", "0.06"], ["83869.7", "0.064"], ["83869.4", "0.000333"], ["83868.7", "0.0027"]], "a": [["83935.3", "1.9687"], ["83938.5", "0.025454"], ["83938.8", "0.0528"], ["83938.9", "0.667233"], ["83941.7", "0.009516"], ["83943", "0.023826"], ["83943.3", "0.059399"], ["83943.5", "0.086133"], ["83944.5", "0"], ["83945.6", "0.009225"], ["83949.8", "0.059567"], ["83952.4", "0.059399"], ["83953.1", "0.000526"], ["83956.6", "0"], ["83958.4", "0"], ["83958.8", "0.0412"], ["83959.6", "0"], ["83959.9", "0.00537"], ["83969.6", "0"], ["83970.5", "0"], ["83974.9", "0"], ["83975", "0"], ["83976.2", "0.04"], ["83976.3", "0.04"], ["83988.8", "0.025357"], ["83991.2", "0.357574"], ["84014", "0"], ["84014.2", "0"], ["84014.5", "0"]], "u": 172301, "seq": 67577760187}, "cts": 1742585767117, "record_time": 1742585767.21083, "EXCHANGE": "BYBIT"}
{"topic": "orderbook.200.BTCUSDT", "ts": 1742585767319, "type": "delta", "data": {"s": "BTCUSDT", "b": [["83935.2", "0"], ["83934.7", "0"], ["83932.9", "0"], ["83932.4", "0"], ["83932.3", "0"], ["83932.2", "0"], ["83931.6", "0"], ["83931.3", "0.02"], ["83930.4", "0"], ["83929.6", "0"], ["83928", "0"], ["83927.9", "0"], ["83926.8", "0.06"], ["83925", "0"], ["83924.7", "0"], ["83924.6", "0"], ["83924.4", "0.000083"], ["83924.3", "0"], ["83924.1", "0"], ["83923", "0.053704"], ["83922.9", "0.171"], ["83920.9", "0"], ["83920.1", "0.020224"], ["83919.2", "0.001"], ["83918", "0"], ["83917.1", "0"], ["83916", "0.00009"], ["83915.8", "0.071534"], ["83914.4", "0"], ["83912.8", "0"], ["83912", "0.051392"], ["83911.6", "0"], ["83911.3", "0.120927"], ["83911.2", "0.084"], ["83910.9", "0.003788"], ["83910.5", "0.019686"], ["83910.3", "0.009994"], ["83909.8", "0.111669"], ["83909.5", "0.069465"], ["83909.1", "0.059399"], ["83906.3", "0.056"], ["83904.9", "0.178717"], ["83902.7", "0.02"], ["83902.3", "0.001861"], ["83902.2", "0.551828"], ["83901.6", "0.119139"], ["83900.7", "0.178717"], ["83900.6", "0"], ["83897.5", "0"], ["83896.5", "0"], ["83892.3", "0"], ["83892.2", "0"], ["83891.5", "0"], ["83890.9", "0"], ["83890.6", "0"], ["83890.4", "0.000333"], ["83889.7", "0.001333"], ["83889.6", "0"], ["83889.2", "0.341649"], ["83889.1", "0"], ["83887.9", "0"], ["83887.8", "0"], ["83885.5", "0.025163"], ["83884.4", "0.084753"], ["83883.9", "0"], ["83882.8", "0.013"], ["83882.7", "0.012884"], ["83881.1", "0.049559"], ["83881", "0.05"], ["83878.1", "0"], ["83875.7", "0"], ["83875.4", "0.037277"], ["83874.2", "0.357634"], ["83870.2", "0.171"], ["83868.1", "0.084"], ["83867.6", "0.005465"], ["83866.5", "0.000468"], ["83866.4", "0.06"], ["83866.2", "1.549518"], ["83865.7", "1.787141"], ["83865.6", "0.051482"], ["83865.4", "0.000528"], ["83865.2", "0.000333"], ["83864.9", "0.06"], ["83864.5", "0.001333"], ["83863.6", "4.066868"]], "a": [["83931.4", "0.498961"], ["83932.7", "0.023829"], ["83935.1", "0.075159"], ["83935.3", "0.221"], ["83935.8", "0.001333"], ["83936.2", "0.004037"], ["83936.5", "0.000333"], ["83937.2", "0.003575"], ["83937.3", "0.059569"], ["83937.7", "0.023827"], ["83938.5", "0.204171"], ["83938.8", "0.141246"], ["83938.9", "0.359186"], ["83939.1", "0.059569"], ["83939.3", "0.005956"], ["83941", "0.005956"], ["83941.2", "0.036"], ["83941.8", "0.160119"], ["83941.9", "0.020801"], ["83942.5", "0"], ["83942.7", "0.178717"], ["83942.8", "0.01056"], ["83943.1", "0.056882"], ["83943.3", "0.04"], ["83943.4", "0"], ["83943.5", "0.083393"], ["83943.7", "0.06"], ["83945.5", "0.04"], ["83945.6", "0"], ["83946", "0.115573"], ["83946.1", "0.092769"], ["83947.1", "0.059569"], ["83947.2", "0.003"], ["83947.3", "0.176491"], ["83949.3", "0.04"], ["83949.6", "0"], ["83949.7", "0.064502"], ["83950.7", "0.04"], ["83950.8", "0"], ["83951.1", "0"], ["83951.5", "0.010584"], ["83952.5", "0.119139"], ["83954", "0"], ["83954.2", "0"], ["83954.4", "0"], ["83954.7", "0.553113"], ["83955.2", "0.00009"], ["83955.3", "0"], ["83958", "0.595594"], ["83958.1", "0"], ["83959.9", "0.030789"], ["83964.4", "0.023776"], ["83965", "0.118539"], ["83966.4", "0.051392"], ["83967", "0.178717"], ["83967.6", "0"], ["83967.9", "0"], ["83968", "0.023828"], ["83968.7", "0.025267"], ["83969.4", "0.00729"], ["83969.8", "0.011919"], ["83971.3", "0"], ["83972.3", "0.3591"], ["83972.8", "0.01411"], ["83972.9", "0.023828"], ["83973.3", "1.4289"], ["83973.9", "0.023828"], ["83974.5", "0"], ["83977", "0.038828"], ["83978.7", "0.023828"], ["83979", "0"], ["83979.5", "0.051481"], ["83982.3", "0"], ["83983.2", "0"], ["83986.4", "0"], ["83986.9", "0.000333"], ["83988.8", "0.00009"], ["83989.3", "0.005374"], ["83991.2", "0"], ["83992.8", "0"], ["84007.6", "0"], ["84007.9", "0"], ["84008.5", "0"], ["84009.3", "0"], ["84010.3", "0"], ["84010.4", "0"], ["84011.4", "0"], ["84012", "0"], ["84012.1", "0"], ["84012.3", "0"], ["84013.1", "0"], ["84013.3", "0"], ["84013.8", "0"], ["84013.9", "0"]], "u": 172302, "seq": 67577761267}, "cts": 1742585767317, "record_time": 1742585767.411273, "EXCHANGE": "BYBIT"}
{"topic": "orderbook.200.BTCUSDT", "ts": 1742585767520, "type": "delta", "data": {"s": "BTCUSDT", "b": [["83931.3", "0.022978"], ["83927.7", "0.006816"], ["83925.6", "0.071526"], ["83924.7", "0.027265"], ["83923.8", "0.07898"], ["83920.5", "0.040899"], ["83920.1", "0.058511"], ["83919.2", "0.072531"], ["83917.3", "0.101921"], ["83915.9", "0.09315"], ["83915.8", "0"], ["83914.6", "0"], ["83913", "0.048464"], ["83912.9", "0.064"], ["83911.3", "0.192736"], ["83909.5", "0.129465"], ["83907.9", "0.056"], ["83907.8", "0.056"], ["83906.2", "0.052"], ["83902.7", "0"], ["83887.2", "0.000078"], ["83886.2", "0.12595"], ["83883.9", "0.089359"], ["83883.2", "0"], ["83875.5", "0.35763"], ["83874.2", "0"], ["83872.8", "5.17634"], ["83865.7", "0"], ["83865.6", "0"], ["83865.4", "0"], ["83865.2", "0"], ["83864.9", "0"], ["83864.5", "0"], ["83863.6", "0"]], "a": [["83931.4", "0.574658"], ["83935", "0.005206"], ["83938", "0.020825"], ["83938.8", "0.201016"], ["83938.9", "0.370046"], ["83939.7", "0.257785"], ["83941.6", "0.04"], ["83941.9", "0"], ["83942.2", "0.031237"], ["83942.8", "0"], ["83944.7", "0.04"], ["83944.9", "0.040633"], ["83946.1", "0.061569"], ["83946.6", "0.08"], ["83948.3", "0.04"], ["83949.7", "0.104181"], ["83952.4", "0.088823"], ["83953.5", "0"], ["83953.8", "0.001466"], ["83955.5", "0"], ["83956.7", "0"], ["83957.1", "0"], ["83957.9", "0.118539"], ["83958.8", "0.0012"], ["83959.4", "0.004687"], ["83959.9", "0.00537"], ["83960.3", "0"], ["83960.5", "0"], ["83966.9", "0.000526"], ["83967.5", "0"], ["83967.9", "0.089359"], ["83969.4", "2.56907"], ["83971.8", "0.025419"], ["83972.3", "0.001466"], ["83976.1", "0.358156"], ["83977.6", "0.127459"], ["83993.8", "0.051242"], ["84006.1", "0"], ["84006.9", "0"], ["84007.2", "0"]], "u": 172303, "seq": 67577761492}, "cts": 1742585767518, "record_time": 1742585767.610638, "EXCHANGE": "BYBIT"}
{"topic": "orderbook.200.BTCUSDT", "ts": 1742585767720, "type": "delta", "data": {"s": "BTCUSDT", "b": [["83931.3", "0.021913"], ["83925.6", "0"], ["83923.9", "0.090068"], ["83923", "0"], ["83921.6", "0.071529"], ["83920.1", "0.042029"], ["83918.2", "0.001"], ["83917.3", "0.030388"], ["83916.1", "0.000681"], ["83915", "0.005125"], ["83910.2", "0.118539"], ["83902.3", "0.024627"], ["83883.4", "3.680288"], ["83875.5", "5.533927"], ["83872.8", "0.000043"], ["83866.4", "0"], ["83866.2", "0"]], "a": [["83931.4", "0.279587"], ["83932.7", "0"], ["83933.6", "0.023829"], ["83935.3", "0.272517"], ["83938.4", "0.309867"], ["83938.8", "0"], ["83938.9", "0.350046"], ["83944.9", "0.080633"], ["83949.3", "0"], ["83950.6", "0.029424"], ["83952.4", "0.059399"], ["83957.9", "0"], ["83958.3", "0"], ["83963.2", "0.022341"], ["83969.3", "0.774518"], ["83974.5", "0.125102"], ["83976.1", "0.000526"], ["83978.1", "0"], ["83978.4", "0.357624"], ["84005.6", "0"]], "u": 172304, "seq": 67577761736}, "cts": 1742585767715, "record_time": 1742585767.81102, "EXCHANGE": "BYBIT"}
{"topic": "orderbook.200.BTCUSDT", "ts": 1742585767920, "type": "delta", "data": {"s": "BTCUSDT", "b": [["83916.3", "0.000153"], ["83916.1", "0.000528"], ["83911.3", "0.270921"], ["83909", "0.179093"], ["83889.1", "0.125631"], ["83886.2", "0.000333"], ["83878.7", "0.357611"], ["83878.3", "5.176869"], ["83875.5", "0"], ["83867.6", "0"], ["83866.5", "0"]], "a": [["83933.6", "0"], ["83938.5", "0.025454"], ["83939.1", "0.23827"], ["83940.8", "0.178697"], ["83941.8", "0.41554"], ["83942.5", "0.178694"], ["83946", "0.169631"], ["83946.3", "0"], ["83967", "0"], ["83969.4", "2.569069"], ["83973.8", "0.051481"], ["83978.4", "0"], ["83979.5", "0"], ["83981.1", "0.178612"], ["83985.3", "0.357611"], ["83995.5", "0.194824"]], "u": 172305, "seq": 67577761841}, "cts": 1742585767910, "record_time": 1742585768.01165, "EXCHANGE": "BYBIT"}
{"topic": "orderbook.200.BTCUSDT", "ts": 1742585768119, "type": "delta", "data": {"s": "BTCUSDT", "b": [["83931.3", "0.212913"], ["83929.7", "0.071522"], ["83926.8", "0"], ["83923.9", "0.139726"], ["83923.7", "0.071527"], ["83922.9", "0.231"], ["83920.1", "0.02087"], ["83919.2", "0.001"], ["83916.8", "0.000153"], ["83916.3", "0"], ["83916", "0.139978"], ["83915.9", "0"], ["83910.2", "0"], ["83905", "0"], ["83891.9", "0.125631"], ["83890.6", "0.125102"], ["83889.1", "0"], ["83882.1", "0.049558"], ["83882", "0.049891"], ["83881.1", "0"], ["83881", "0"], ["83878.8", "0.357615"], ["83878.7", "0"], ["83869.6", "0.125102"], ["83867.6", "0.005465"]], "a": [["83935.3", "0.242517"], ["83939.1", "0.059569"], ["83939.8", "0.06"], ["83941.8", "0.236823"], ["83943.7", "0"], ["83946.1", "0.059569"], ["83953.5", "0.125102"], ["83957.9", "0.118539"], ["83959.6", "0.023759"], ["83964.4", "0"], ["83971.8", "0"], ["83985.2", "0.357611"], ["83985.3", "0"], ["84000.2", "0"]], "u": 172306, "seq": 67577761963}, "cts": 1742585768117, "record_time": 1742585768.210249, "EXCHANGE": "BYBIT"}
{"topic": "orderbook.200.BTCUSDT", "ts": 1742585768320, "type": "delta", "data": {"s": "BTCUSDT", "b": [["83931.3", "0.221352"], ["83931.2", "0.071521"], ["83929.7", "0"], ["83925.3", "0.029842"], ["83925.2", "0.071526"], ["83924.7", "0.030265"], ["83923.7", "0"], ["83922.7", "0.071528"], ["83921.6", "0"], ["83916.9", "0.010877"], ["83916.8", "0"], ["83911.1", "0.003"], ["83909.2", "0.023681"], ["83884.5", "0.357601"], ["83884", "0.000118"], ["83882.1", "0.05"], ["83881.1", "5.152839"], ["83878.8", "0"], ["83878.3", "0.000572"], ["83869.4", "0"], ["83868.7", "0"], ["83868.1", "0"], ["83867.6", "0"]], "a": [["83935.1", "0.023166"], ["83935.3", "0.071517"], ["83937.2", "0"], ["83937.3", "0"], ["83937.7", "0"], ["83938.4", "0"], ["83938.8", "0.203396"], ["83938.9", "0.320046"], ["83939.1", "0"], ["83939.3", "0"], ["83940.8", "0"], ["83941", "0"], ["83942.5", "0"], ["83942.6", "0.178694"], ["83942.7", "0"], ["83943", "0"], ["83944.3", "0.17869"], ["83945.8", "0.199092"], ["83945.9", "0.178687"], ["83946", "0.002"], ["83946.1", "0"], ["83946.8", "0.178807"], ["83947.1", "0"], ["83951.1", "0.178717"], ["83955.3", "0.178717"], ["83968.7", "0"], ["83976.9", "0.004466"], ["83979.3", "0.027054"], ["83985.1", "0.362972"], ["83985.2", "0"], ["84005.6", "0.04009"], ["84006.1", "0.005387"], ["84006.9", "0.354"], ["84007.2", "0.001333"], ["84007.6", "0.04"], ["84007.9", "0.059864"], ["84008.5", "0.119065"], ["84009.3", "0.001466"]], "u": 172307, "seq": 67577762088}, "cts": 1742585768317, "record_time": 1742585768.41139, "EXCHANGE": "BYBIT"}
{"success": true, "ret_msg": "subscribe", "conn_id": "715e41eb-1d55-4682-b7f5-361425dd1be0", "op": "subscribe", "record_time": 1742586286.37289, "EXCHANGE": "BYBIT"}
{"topic": "orderbook.200.BTCUSDT", "ts": 1742586284320, "type": "snapshot", "data": {"s": "BTCUSDT", "b": [["83872.7", "0.515201"], ["83872.6", "0.023673"], ["83872.5", "0.071571"], ["83871.8", "0.005348"], ["83870.8", "0.001466"], ["83870", "0.000524"], ["83869.4", "0.000333"], ["83869.3", "0.080439"], ["83869.2", "0.006801"], ["83869.1", "0.003"], ["83868.7", "0.001333"], ["83868.3", "0.027206"], ["83868.2", "0.071575"], ["83868", "0.000153"], ["83867.6", "0.005348"], ["83867.5", "0.056196"], ["83867.3", "0.008195"], ["83866.2", "0.001466"], ["83866.1", "0.00528"], ["83866", "0.071577"], ["83865.4", "0.000524"], ["83865.3", "0.06402"], ["83865.2", "0.010893"], ["83864.5", "0.173799"], ["83864.4", "0.10175"], ["83864.3", "0.06"], ["83864.1", "0.040811"], ["83863.5", "0.026565"], ["83863.4", "0.005348"], ["83862", "0.064"], ["83861.8", "0.048"], ["83861.5", "0.222114"], ["83861.2", "0.023687"], ["83861.1", "0.000635"], ["83861", "0.000333"], ["83860.8", "0.000522"], ["83860.7", "0.137465"], ["83860.6", "0.049875"], ["83860.3", "0.007893"], ["83860.1", "0.06"], ["83860", "0.08418"], ["83859.7", "0.002386"], ["83859.5", "0.037798"], ["83859.2", "0.00529"], ["83859", "0.009786"], ["83858.7", "0.06"], ["83858.5", "0.064"], ["83857.2", "0.118629"], ["83857.1", "0.220802"], ["83857", "0.1056"], ["83856.9", "0.001466"], ["83856.8", "0.270983"], ["83856.1", "0.001855"], ["83855.8", "0.111564"], ["83855.1", "0.23488"], ["83855", "0.057235"], ["83854.6", "0.000994"], ["83853.7", "0.004657"], ["83852.6", "0.000333"], ["83852.3", "0.001466"], ["83852.2", "0.019042"], ["83851.9", "0.509759"], ["83851.8", "0.118539"], ["83851.5", "0.000522"], ["83850.8", "0.005235"], ["83850.6", "0.17889"], ["83850.3", "0.171"], ["83850", "0.527773"], ["83849.2", "0.000358"], ["83849.1", "0.592819"], ["83848.8", "0.033946"], ["83848.5", "0.000333"], ["83848.4", "0.178842"], ["83848.2", "0.009225"], ["83847.7", "0.002799"], ["83847.5", "0.003575"], ["83847.2", "0.059399"], ["83846.9", "0.000522"], ["83846.6", "0.005835"], ["83845.9", "0.118539"], ["83845.4", "0.012"], ["83845.3", "0.0015"], ["83845.2", "0.001859"], ["83844.9", "0.005961"], ["83844.3", "0.000333"], ["83843.6", "0.001333"], ["83843.1", "0.001466"], ["83842.9", "0.000936"], ["83842.4", "0.005225"], ["83842.3", "0.000522"], ["83841.8", "0.178831"], ["83841.2", "0.000298"], ["83840.4", "0.02018"], ["83840.1", "0.000333"], ["83840", "0.00006"], ["83839.9", "0.02"], ["83839.7", "0.002145"], ["83839.5", "0.118539"], ["83839.4", "0.001333"], ["83839.3", "0.191"], ["83839.1", "0.011928"], ["83838.5", "0.001466"], ["83838.2", "0.005224"], ["83838.1", "0.02"], ["83837.7", "0.000522"], ["83837.6", "0.238831"], ["83837.5", "0.039633"], ["83836.6", "0.023843"], ["83836.1", "0.003575"], ["83835.9", "0.000333"], ["83835.6", "0.026968"], ["83835.5", "0.012881"], ["83835.2", "0.001333"], ["83835.1", "0.0001"], ["83834.9", "0.023844"], ["83834.8", "0.357807"], ["83834.7", "0.059399"], ["83834.2", "0.05"], ["83834.1", "0.054751"], ["83834", "0.02"], ["83833.9", "0.001466"], ["83833.1", "0.000522"], ["83832.7", "0.166539"], ["83832.5", "0.126041"], ["83832", "0.033946"], ["83831.8", "0.023844"], ["83831.7", "0.000333"], ["83831.3", "0.208707"], ["83831.2", "0.354184"], ["83831", "0.001333"], ["83830.9", "0.171"], ["83830.7", "0.01193"], ["83830.2", "0.023035"], ["83829.9", "0.029048"], ["83829.3", "0.001466"], ["83829.2", "0.00018"], ["83828.9", "0.087844"], ["83828.5", "0.000522"], ["83828.3", "0.015"], ["83828", "0.000149"], ["83827.5", "0.000333"], ["83827.3", "0.144"], ["83827.1", "0.118897"], ["83826.8", "0.001333"], ["83825.7", "0.069203"], ["83825.6", "0.056"], ["83825.5", "0.06"], ["83825.4", "0.059399"], ["83825.3", "0.005961"], ["83825", "0.000118"], ["83824.9", "0.125179"], ["83824.7", "0.001466"], ["83824", "0.080108"], ["83823.9", "0.000522"], ["83823.8", "0.056"], ["83823.6", "0.00009"], ["83823.5", "0.023844"], ["83823.3", "0.000333"], ["83823.2", "0.059608"], ["83822.8", "0.041799"], ["83822.6", "0.001333"], ["83822.2", "0.052"], ["83821.5", "0.176803"], ["83820", "0.001526"], ["83819.8", "0.023848"], ["83819.4", "0.118539"], ["83819.2", "0.000522"], ["83819.1", "0.000333"], ["83818.4", "0.001333"], ["83818.1", "0.023848"], ["83817.5", "9.056428"], ["83817.3", "0.005189"], ["83817.1", "0.00067"], ["83816.6", "0.089416"], ["83815.7", "1.788206"], ["83815.4", "0.013466"], ["83815.3", "0.0015"], ["83815.2", "0.00009"], ["83815", "0.023848"], ["83814.9", "0.000333"], ["83814.8", "0.178966"], ["83814.7", "0.059399"], ["83814.6", "0.000522"], ["83814.3", "0.118539"], ["83814.2", "0.001333"], ["83813.3", "0.015"], ["83813.1", "0.176189"], ["83812.5", "1.272113"], ["83812.1", "0.023848"], ["83811.1", "0.000358"], ["83810.8", "3.977808"], ["83810.7", "0.000333"], ["83810", "0.031565"], ["83809.3", "3.548584"], ["83808.9", "0.005189"], ["83808.5", "0.005962"], ["83806.8", "0.00009"], ["83806.7", "0.023848"], ["83806.6", "0.118539"], ["83806.5", "0.000333"]], "a": [["83872.8", "0.16726"], ["83873", "0.031689"], ["83873.1", "0.071571"], ["83873.8", "0.023544"], ["83874.1", "0.001523"], ["83874.8", "0.0021"], ["83876.5", "0.005225"], ["83877.1", "0.001333"], ["83877.8", "0.000333"], ["83878.7", "0.001012"], ["83879.2", "0.000524"], ["83879.5", "0.020899"], ["83879.9", "0.071565"], ["83880", "0.110882"], ["83880.1", "0.171"], ["83880.2", "0.005344"], ["83880.3", "0.03696"], ["83881.2", "0.06"], ["83881.3", "0.001333"], ["83882", "0.016228"], ["83882.3", "0.04"], ["83882.9", "0.102818"], ["83883", "0.006282"], ["83883.4", "0.04"], ["83883.6", "0.023844"], ["83883.7", "0.102908"], ["83883.8", "0.000524"], ["83884", "0.04"], ["83884.2", "0.04"], ["83884.3", "0.0006"], ["83884.4", "0.005429"], ["83884.6", "0.001466"], ["83885", "0.019685"], ["83885.5", "0.001333"], ["83885.6", "0.04"], ["83886.1", "0.007009"], ["83886.2", "0.025983"], ["83886.4", "0.033856"], ["83886.6", "0.009225"], ["83886.8", "0.04"], ["83887.1", "0.0006"], ["83887.6", "0.361478"], ["83887.7", "0.17881"], ["83887.9", "0.178842"], ["83888", "0.00009"], ["83888.4", "0.000524"], ["83888.6", "0.005429"], ["83888.7", "0.178831"], ["83889", "0.04"], ["83889.2", "0.001466"], ["83889.4", "0.178807"], ["83889.5", "0.009227"], ["83889.7", "0.001333"], ["83889.8", "0.099399"], ["83890", "0.04"], ["83890.4", "0.171333"], ["83890.6", "0.08004"], ["83890.8", "0.097739"], ["83891.2", "0.178842"], ["83891.6", "0.006309"], ["83891.7", "0.04"], ["83892.1", "0.178842"], ["83892.2", "0.111564"], ["83892.8", "0.005429"], ["83893", "0.000524"], ["83893.8", "0.001466"], ["83893.9", "0.001333"], ["83894.6", "0.000333"], ["83895.3", "0.0012"], ["83895.4", "0.001468"], ["83896.4", "0.00009"], ["83897", "0.005432"], ["83897.7", "0.000524"], ["83898.1", "0.001333"], ["83898.5", "0.001466"], ["83898.8", "0.000333"], ["83899.2", "0.093255"], ["83899.3", "0.406777"], ["83899.5", "0.000083"], ["83899.7", "0.006287"], ["83899.8", "0.005961"], ["83900", "0.029805"], ["83900.7", "0.023844"], ["83900.9", "0.0012"], ["83901", "0.171"], ["83901.2", "0.005432"], ["83901.5", "0.0006"], ["83902.1", "0.611406"], ["83902.3", "0.001857"], ["83902.5", "0.540713"], ["83902.9", "0.0024"], ["83903", "0.000333"], ["83903.1", "0.001466"], ["83903.5", "0.0016"], ["83904.8", "0.00009"], ["83905.1", "0.000358"], ["83905.3", "0.006945"], ["83905.4", "0.012"], ["83906.5", "0.001333"], ["83906.8", "0.00018"], ["83906.9", "0.000524"], ["83907.2", "0.000333"], ["83907.3", "0.035775"], ["83907.7", "0.001466"], ["83908.5", "0.00596"], ["83908.6", "0.121582"], ["83908.7", "0.059399"], ["83908.8", "0.125179"], ["83909.3", "0.004601"], ["83909.4", "0.17415"], ["83909.5", "0.005457"], ["83910", "0.000118"], ["83910.4", "0.000333"], ["83910.5", "0.011928"], ["83910.7", "0.001333"], ["83911.4", "0.000333"], ["83911.5", "0.000524"], ["83912", "0.04"], ["83912.1", "0.04"], ["83912.2", "0.118539"], ["83912.3", "0.001466"], ["83913.1", "0.117337"], ["83913.2", "0.00009"], ["83913.3", "0.00273"], ["83913.5", "0.08941"], ["83913.7", "0.005457"], ["83914.2", "0.024184"], ["83914.3", "0.317633"], ["83914.4", "0.051496"], ["83914.6", "1.429887"], ["83914.9", "0.001333"], ["83915.6", "0.000333"], ["83915.8", "0.029852"], ["83916", "0.033856"], ["83916.1", "0.000524"], ["83916.2", "0.022341"], ["83916.9", "0.041466"], ["83917.3", "0.005961"], ["83917.4", "0.02376"], ["83917.6", "0.118539"], ["83917.8", "0.171358"], ["83917.9", "0.005457"], ["83918.6", "0.04"], ["83918.8", "0.04"], ["83919", "0.001333"], ["83919.5", "0.059399"], ["83919.8", "0.000333"], ["83920.7", "0.024369"], ["83921.1", "0.013912"], ["83921.2", "0.0006"], ["83921.5", "0.001466"], ["83921.6", "0.00009"], ["83921.8", "0.023844"], ["83922.1", "0.005457"], ["83922.3", "0.000024"], ["83923", "0.000204"], ["83923.2", "0.001333"], ["83923.6", "0.04"], ["83924", "0.000333"], ["83924.2", "0.118539"], ["83924.9", "0.023844"], ["83925.1", "2.56168"], ["83925.3", "0.000263"], ["83925.4", "0.000263"], ["83925.6", "0.001788"], ["83926.1", "0.08244"], ["83926.2", "0.171"], ["83926.3", "0.005457"], ["83926.5", "0.038843"], ["83927", "0.059502"], ["83927.2", "0.000358"], ["83927.4", "0.001333"], ["83928.1", "0.000333"], ["83929.2", "0.059399"], ["83929.3", "0.118539"], ["83929.8", "0.125179"], ["83930", "0.000616"], ["83930.5", "0.005457"], ["83930.8", "0.001466"], ["83931.6", "0.001333"], ["83932.3", "0.000333"], ["83932.6", "0.114"], ["83934.5", "0.08941"], ["83934.6", "0.171526"], ["83934.7", "0.045457"], ["83934.9", "0.0006"], ["83935.3", "0.120039"], ["83935.4", "0.013466"], ["83935.7", "0.04"], ["83935.8", "0.001333"], ["83936.5", "0.000478"], ["83938.4", "0.00009"], ["83938.9", "0.005457"], ["83939.2", "0.000526"], ["83940", "0.002799"], ["83940.3", "0.357804"], ["83940.4", "0.177938"], ["83940.7", "0.000333"], ["83943", "0.171"], ["83943.1", "0.005457"]], "u": 174881, "seq": 67578156460}, "cts": 1742586284305, "record_time": 1742586286.377397, "EXCHANGE": "BYBIT"}
{"topic": "orderbook.200.BTCUSDT", "ts": 1742586284520, "type": "delta", "data": {"s": "BTCUSDT", "b": [["83872.7", "0.344801"], ["83872.6", "0"], ["83868", "0"], ["83836", "0.013"], ["83835.9", "0.013214"], ["83835.6", "0.013968"], ["83835.5", "0"], ["83834.8", "0.357804"], ["83824", "0.056"], ["83806.4", "0.0016"], ["83806.2", "0.001466"]], "a": [["83872.8", "0.241941"], ["83873.8", "0.026544"], ["83878.3", "0.071566"], ["83883.7", "0.031347"], ["83886.1", "0.004009"], ["83890.8", "0.145175"], ["83895.4", "0.0006"], ["83922", "0.023665"], ["83922.3", "2.561704"], ["83925.1", "0"], ["83934.4", "0.357808"], ["83940.3", "0"], ["83943.1", "0"]], "u": 174882, "seq": 67578156520}, "cts": 1742586284510, "record_time": 1742586286.379902, "EXCHANGE": "BYBIT"}
{"topic": "orderbook.200.BTCUSDT", "ts": 1742586284719, "type": "delta", "data": {"s": "BTCUSDT", "b": [["83872.7", "0.34388"], ["83834.8", "0"], ["83829", "0.357828"]], "a": [["83872.8", "0.243297"], ["83883", "0.009351"], ["83895.8", "0.003576"], ["83908.5", "2.56764"], ["83922.3", "0.000024"], ["83929.7", "0.357828"], ["83934.4", "0"], ["83943", "0"]], "u": 174883, "seq": 67578156577}, "cts": 1742586284712, "record_time": 1742586286.380907, "EXCHANGE": "BYBIT"}
{"topic": "orderbook.200.BTCUSDT", "ts": 1742586284919, "type": "delta", "data": {"s": "BTCUSDT", "b": [["83867.7", "0.000153"], ["83806.2", "0"]], "a": [["83872.8", "0.244097"], ["83880.1", "0.178001"], ["83895.4", "0.001463"], ["83929.1", "0.357833"], ["83929.7", "0"]], "u": 174884, "seq": 67578156629}, "cts": 1742586284917, "record_time": 1742586286.382907, "EXCHANGE": "BYBIT"}
{"topic": "orderbook.200.BTCUSDT", "ts": 1742586285120, "type": "delta", "data": {"s": "BTCUSDT", "b": [["83864.5", "0.176799"], ["83839.6", "0.195696"], ["83833.9", "0.319404"], ["83829.1", "0.357833"], ["83829", "0"], ["83806.4", "0"]], "a": [["83872.8", "0.242741"], ["83895.4", "0.0006"], ["83908.4", "0.885299"], ["83908.5", "0.00596"], ["83908.6", "0"], ["83914", "2.56168"], ["83940.7", "0"]], "u": 174885, "seq": 67578156673}, "cts": 1742586285105, "record_time": 1742586286.384906, "EXCHANGE": "BYBIT"}
{"topic": "orderbook.200.BTCUSDT", "ts": 1742586285319, "type": "delta", "data": {"s": "BTCUSDT", "b": [["83867.7", "0"], ["83864.3", "0.060999"], ["83829.2", "0.358013"], ["83829.1", "0"], ["83806.4", "0.0016"], ["83806.2", "0.001466"]], "a": [["83872.8", "0.244097"], ["83908.4", "0"], ["83940.7", "0.000333"]], "u": 174886, "seq": 67578156715}, "cts": 1742586285307, "record_time": 1742586286.38641, "EXCHANGE": "BYBIT"}
{"topic": "orderbook.200.BTCUSDT", "ts": 1742586285519, "type": "delta", "data": {"s": "BTCUSDT", "b": [["83829.2", "0.00018"], ["83827.4", "0.357834"], ["83806.2", "0"]], "a": [["83872.8", "0.242741"], ["83892.2", "0"], ["83941.8", "1.788424"]], "u": 174887, "seq": 67578156736}, "cts": 1742586285518, "record_time": 1742586286.387415, "EXCHANGE": "BYBIT"}
{"topic": "orderbook.200.BTCUSDT", "ts": 1742586285720, "type": "delta", "data": {"s": "BTCUSDT", "b": [["83829", "0.357831"], ["83827.4", "0"]], "a": [["83892.7", "0.111565"], ["83941.8", "0"]], "u": 174888, "seq": 67578156757}, "cts": 1742586285707, "record_time": 1742586286.388416, "EXCHANGE": "BYBIT"}
{"topic": "orderbook.200.BTCUSDT", "ts": 1742586285919, "type": "delta", "data": {"s": "BTCUSDT", "b": [["83868.1", "0.000153"], ["83806.4", "0"]], "a": [["83872.8", "0.244097"], ["83929", "0.357831"], ["83929.1", "0"]], "u": 174889, "seq": 67578156776}, "cts": 1742586285911, "record_time": 1742586286.389919, "EXCHANGE": "BYBIT"}
{"topic": "orderbook.200.BTCUSDT", "ts": 1742586286120, "type": "delta", "data": {"s": "BTCUSDT", "b": [["83869.1", "0"], ["83834.2", "0.266361"], ["83832.5", "0.12604"], ["83806.4", "0.0016"]], "a": [["83913.9", "1.335076"], ["83928.9", "0.357829"], ["83929", "0"], ["83940.7", "0"]], "u": 174890, "seq": 67578156822}, "cts": 1742586286113, "record_time": 1742586286.391924, "EXCHANGE": "BYBIT"}
{"topic": "orderbook.200.BTCUSDT", "ts": 1742586286320, "type": "delta", "data": {"s": "BTCUSDT", "b": [["83868.1", "0"], ["83864.4", "0.10475"], ["83829", "0.357825"], ["83806.2", "0.001466"]], "a": [["83872.8", "0.242741"], ["83928.9", "0"], ["83932.5", "0.357827"]], "u": 174891, "seq": 67578156848}, "cts": 1742586286304, "record_time": 1742586286.408844, "EXCHANGE": "BYBIT"}
{"topic": "orderbook.200.BTCUSDT", "ts": 1742586286519, "type": "delta", "data": {"s": "BTCUSDT", "b": [["83868.3", "0.027359"], ["83832.5", "0"], ["83805.8", "0.001989"]], "a": [["83932.4", "0.357827"], ["83932.5", "0"]], "u": 174892, "seq": 67578156864}, "cts": 1742586286511, "record_time": 1742586286.60778, "EXCHANGE": "BYBIT"}
{"topic": "orderbook.200.BTCUSDT", "ts": 1742586286720, "type": "delta", "data": {"s": "BTCUSDT", "b": [["83832.5", "0.126028"], ["83805.8", "0"]], "a": [["83895.8", "0"], ["83932.3", "0.358161"], ["83932.4", "0"], ["83940.7", "0.000333"], ["83941.8", "1.788424"]], "u": 174893, "seq": 67578156889}, "cts": 1742586286711, "record_time": 1742586286.809095, "EXCHANGE": "BYBIT"}
{"topic": "orderbook.200.BTCUSDT", "ts": 1742586286920, "type": "delta", "data": {"s": "BTCUSDT", "b": [["83869.3", "0.077439"], ["83868.3", "0.027206"], ["83867.9", "0.000153"], ["83806.2", "0"]], "a": [["83872.8", "0.244097"], ["83879.7", "0.001259"], ["83929.7", "0.357828"], ["83932.3", "0.000333"], ["83940.7", "0"], ["83941.8", "0"]], "u": 174894, "seq": 67578156914}, "cts": 1742586286914, "record_time": 1742586287.009801, "EXCHANGE": "BYBIT"}
{"topic": "orderbook.200.BTCUSDT", "ts": 1742586287120, "type": "delta", "data": {"s": "BTCUSDT", "b": [["83867.9", "0"], ["83864.6", "0.003"], ["83848.5", "0.12035"]], "a": [["83872.8", "0.248741"], ["83873.8", "0.003"], ["83908.7", "0.156586"], ["83929.1", "0.357831"], ["83929.7", "0"]], "u": 174895, "seq": 67578156949}, "cts": 1742586287103, "record_time": 1742586287.20758, "EXCHANGE": "BYBIT"}
{"topic": "orderbook.200.BTCUSDT", "ts": 1742586287320, "type": "delta", "data": {"s": "BTCUSDT", "b": [["83868.2", "0.071728"], ["83861.2", "0"], ["83860.9", "0.023854"], ["83855.6", "0.061039"], ["83848.6", "0.061007"], ["83841.6", "0.111618"], ["83806.6", "0"], ["83806.5", "0"], ["83806.4", "0"]], "a": [["83872.8", "0.18006"], ["83873.8", "0"], ["83874.2", "0.024366"], ["83890.6", "0.140788"], ["83897.6", "0.060069"], ["83904.6", "0.108846"], ["83910", "0"], ["83929.1", "0"], ["83932.5", "0.357827"], ["83940.4", "0"]], "u": 174896, "seq": 67578157001}, "cts": 1742586287305, "record_time": 1742586287.408313, "EXCHANGE": "BYBIT"}
{"topic": "orderbook.200.BTCUSDT", "ts": 1742586287519, "type": "delta", "data": {"s": "BTCUSDT", "b": [["83855.6", "0"], ["83848.6", "0"], ["83841.6", "0"], ["83831.4", "0.357823"], ["83829", "0"], ["83806.6", "0.118539"], ["83806.5", "0.000333"], ["83806.4", "0.0016"]], "a": [["83890.6", "0.08004"], ["83897.6", "0"], ["83904.6", "0"], ["83932.4", "0.357826"], ["83932.5", "0"], ["83940.4", "0.177938"], ["83940.7", "0.000333"]], "u": 174897, "seq": 67578157039}, "cts": 1742586287504, "record_time": 1742586287.608867, "EXCHANGE": "BYBIT"}
{"topic": "orderbook.200.BTCUSDT", "ts": 1742586287720, "type": "delta", "data": {"s": "BTCUSDT", "b": [["83872.6", "0.023673"], ["83868.3", "0.027359"], ["83868.2", "0.071575"], ["83806.4", "0"]], "a": [["83932.3", "0.358153"], ["83932.4", "0"], ["83941.8", "1.788424"]], "u": 174898, "seq": 67578157065}, "cts": 1742586287713, "record_time": 1742586287.808952, "EXCHANGE": "BYBIT"}
{"topic": "orderbook.200.BTCUSDT", "ts": 1742586287920, "type": "delta", "data": {"s": "BTCUSDT", "b": [["83872.7", "0.51488"], ["83863.5", "0.031845"], ["83846.3", "0.119228"], ["83832.8", "0.357817"], ["83831.4", "0"], ["83817.5", "8.969312"], ["83806.5", "0"]], "a": [["83872.8", "0.18606"], ["83892.9", "0.119228"], ["83932.3", "0.000333"], ["83932.5", "0.357817"], ["83940.7", "0"], ["83941.8", "0"]], "u": 174899, "seq": 67578157121}, "cts": 1742586287917, "record_time": 1742586288.007946, "EXCHANGE": "BYBIT"}
{"topic": "orderbook.200.BTCUSDT", "ts": 1742586288120, "type": "delta", "data": {"s": "BTCUSDT", "b": [["83868.4", "0.000153"], ["83868.3", "0.027206"], ["83841.9", "0.059793"], ["83837.6", "0.198831"], ["83837.5", "0"], ["83837.1", "0.039633"], ["83837", "0.039633"], ["83836", "0"], ["83835.9", "0.000333"], ["83835.5", "0.012881"], ["83835.4", "0.012881"], ["83834.8", "0.357811"], ["83834.2", "0.216361"], ["83834.1", "0.005206"], ["83833.8", "0.05"], ["83833.7", "0.049546"], ["83832.8", "0"], ["83824.1", "0.024108"], ["83820.1", "8.937076"], ["83817.5", "0"], ["83810", "0"], ["83809.3", "0"], ["83808.9", "0"], ["83808.5", "0"], ["83806.8", "0"], ["83806.7", "0"], ["83806.6", "0"]], "a": [["83872.8", "0.19206"], ["83887.9", "0"], ["83896.3", "0.178842"], ["83899.1", "0.027977"], ["83899.6", "0.0093"], ["83899.7", "0"], ["83912", "0"], ["83912.1", "0"], ["83912.9", "0.04"], ["83913", "0.04"], ["83922", "0"], ["83932.5", "0"], ["83935.2", "0.357806"]], "u": 174900, "seq": 67578157179}, "cts": 1742586288109, "record_time": 1742586288.209301, "EXCHANGE": "BYBIT"}
{"topic": "orderbook.200.BTCUSDT", "ts": 1742586288320, "type": "delta", "data": {"s": "BTCUSDT", "b": [["83868.4", "0"], ["83837.5", "0.039633"], ["83837.4", "0.039633"], ["83837.1", "0"], ["83837", "0"], ["83835.9", "0.013214"], ["83835.8", "0.012881"], ["83835.5", "0"], ["83835.4", "0"], ["83834.8", "0.35781"], ["83834.2", "0.266361"], ["83834.1", "0.054751"], ["83833.8", "0"], ["83833.7", "0"], ["83820.1", "0"], ["83817.5", "8.937076"], ["83810", "0.031565"], ["83809.3", "3.548584"], ["83808.9", "0.005189"], ["83808.5", "0.005962"]], "a": [["83883.6", "0"], ["83892.7", "0"], ["83912.1", "0.04"], ["83912.2", "0.158539"], ["83912.9", "0"], ["83913", "0"], ["83934.4", "0.35781"], ["83935.2", "0"], ["83940.7", "0.000333"], ["83941.8", "1.788424"], ["83943.1", "0.005457"]], "u": 174901, "seq": 67578157231}, "cts": 1742586288316, "record_time": 1742586288.408734, "EXCHANGE": "BYBIT"}
{"topic": "orderbook.200.BTCUSDT", "ts": 1742586288519, "type": "delta", "data": {"s": "BTCUSDT", "b": [["83872.7", "0.341017"], ["83837.6", "0.238831"], ["83837.4", "0"], ["83836", "0.013"], ["83835.8", "0"], ["83832.5", "0"], ["83829.6", "0.126028"], ["83826.4", "0.096629"], ["83824.1", "0"], ["83806.8", "0.00009"]], "a": [["83872.8", "0.193416"], ["83887.9", "0.178842"], ["83893.9", "0.112898"], ["83896.3", "0"], ["83910", "0.000118"], ["83912", "0.04"], ["83912.2", "0.118539"], ["83934.3", "0.35781"], ["83934.4", "0"], ["83941.8", "0"], ["83943.1", "0"]], "u": 174902, "seq": 67578157283}, "cts": 1742586288513, "record_time": 1742586288.607894, "EXCHANGE": "BYBIT"}
{"topic": "orderbook.200.BTCUSDT", "ts": 1742586288719, "type": "delta", "data": {"s": "BTCUSDT", "b": [["83872.7", "0.341617"], ["83845.9", "0.142385"], ["83834.8", "0"], ["83834.3", "0.357811"], ["83829.6", "0.12602"], ["83820.1", "8.937076"], ["83817.5", "0"]], "a": [["83872.8", "0.19206"], ["83934.2", "0.357812"], ["83934.3", "0"]], "u": 174903, "seq": 67578157341}, "cts": 1742586288709, "record_time": 1742586288.80845, "EXCHANGE": "BYBIT"}
{"topic": "orderbook.200.BTCUSDT", "ts": 1742586288919, "type": "delta", "data": {"s": "BTCUSDT", "b": [["83872.7", "0.454343"], ["83837.7", "0.040522"], ["83837.6", "0.238464"], ["83837.5", "0"], ["83836.1", "0.016575"], ["83836", "0.012881"], ["83835.9", "0.000333"], ["83834.4", "0.357811"], ["83834.3", "0.05"], ["83834.2", "0.265906"], ["83834.1", "0.005206"]], "a": [["83872.8", "0.195279"], ["83878.3", "0"], ["83882.6", "0.071562"], ["83911.9", "0.04"], ["83912.1", "0"], ["83934.1", "0.357813"], ["83934.2", "0"]], "u": 174904, "seq": 67578157438}, "cts": 1742586288914, "record_time": 1742586289.008465, "EXCHANGE": "BYBIT"}
{"topic": "orderbook.200.BTCUSDT", "ts": 1742586289120, "type": "delta", "data": {"s": "BTCUSDT", "b": [["83872.7", "0.216131"], ["83864.5", "0.173799"], ["83837.7", "0.000522"], ["83837.6", "0.198831"], ["83837.2", "0.04"], ["83837.1", "0.039633"], ["83836.1", "0.003575"], ["83836", "0"], ["83835.6", "0.026968"], ["83835.5", "0.012881"], ["83834.8", "0.357811"], ["83834.4", "0"], ["83834.3", "0"], ["83834.2", "0.216361"], ["83833.8", "0.05"], ["83833.7", "0.049546"], ["83808.9", "0"], ["83808.5", "0"], ["83806.8", "0"]], "a": [["83872.8", "0.273691"], ["83873", "0.049444"], ["83878", "0.071566"], ["83882.6", "0"], ["83911.9", "0"], ["83912", "0"], ["83912.8", "0.04"], ["83912.9", "0.04"], ["83934.1", "0"], ["83935.2", "0.357807"]], "u": 174905, "seq": 67578157504}, "cts": 1742586289117, "record_time": 1742586289.210237, "EXCHANGE": "BYBIT"}
{"topic": "orderbook.200.BTCUSDT", "ts": 1742586289319, "type": "delta", "data": {"s": "BTCUSDT", "b": [["83872.7", "0.216191"], ["83872.6", "0"], ["83864.3", "0.06"], ["83859.7", "0"], ["83856", "0.109884"], ["83849", "0.175241"], ["83842", "0.287593"], ["83837.7", "0.040522"], ["83837.6", "0.238464"], ["83837.2", "0"], ["83837.1", "0"], ["83836.1", "0.016575"], ["83836", "0.012881"], ["83835.6", "0.013968"], ["83835.5", "0"], ["83834.8", "0"], ["83834.1", "0.055206"], ["83834", "0.069545"], ["83833.8", "0"], ["83833.7", "0"], ["83832.5", "0.12602"], ["83831.4", "0.357818"], ["83829.6", "0"], ["83808.9", "0.005189"], ["83808.5", "0.005962"], ["83806.8", "0.00009"]], "a": [["83872.8", "0.279691"], ["83888.9", "0.124336"], ["83895.9", "0.177901"], ["83900.5", "0.089421"], ["83902.9", "0.300881"], ["83905.3", "0.021989"], ["83911.9", "0.04"], ["83912", "0.04"], ["83912.8", "0"], ["83912.9", "0"], ["83923.1", "0.023665"], ["83932.5", "0.357817"], ["83935.2", "0"], ["83939.2", "0"], ["83940", "0"], ["83940.4", "0"], ["83940.7", "0"]], "u": 174906, "seq": 67578157589}, "cts": 1742586289303, "record_time": 1742586289.408878, "EXCHANGE": "BYBIT"}
{"topic": "orderbook.200.BTCUSDT", "ts": 1742586289520, "type": "delta", "data": {"s": "BTCUSDT", "b": [["83842.1", "0.146071"], ["83841.9", "0"], ["83834.3", "0.05"], ["83834.2", "0.265906"], ["83834.1", "0.005206"], ["83834", "0.02"], ["83831.4", "0"], ["83831", "0.359154"]], "a": [["83932.4", "0.35782"], ["83932.5", "0"]], "u": 174907, "seq": 67578157631}, "cts": 1742586289517, "record_time": 1742586289.609398, "EXCHANGE": "BYBIT"}
{"topic": "orderbook.200.BTCUSDT", "ts": 1742586289719, "type": "delta", "data": {"s": "BTCUSDT", "b": [["83868.6", "0.000153"], ["83831", "0.001333"], ["83829", "0.357822"], ["83808.5", "0"], ["83806.8", "0"]], "a": [["83932.3", "0.358158"], ["83932.4", "0"], ["83939.2", "0.000526"]], "u": 174908, "seq": 67578157655}, "cts": 1742586289716, "record_time": 1742586289.808079, "EXCHANGE": "BYBIT"}
{"topic": "orderbook.200.BTCUSDT", "ts": 1742586289920, "type": "delta", "data": {"s": "BTCUSDT", "b": [["83859.8", "0.122054"], ["83856", "0"], ["83850", "0.711372"], ["83849", "0"], ["83842", "0"], ["83840.9", "0.294861"], ["83837.7", "0.000522"], ["83837.5", "0.039633"], ["83836.1", "0.003575"], ["83835.9", "0.013214"], ["83834.3", "0"], ["83834.1", "0.054751"], ["83808.5", "0.005962"]], "a": [["83872.8", "0.285691"], ["83885", "0.138666"], ["83888.9", "0"], ["83894.8", "0.167802"], ["83895.9", "0"], ["83902.9", "0.0024"], ["83903.9", "0.278713"], ["83911.9", "0"], ["83912.1", "0.04"], ["83932.2", "0.357826"], ["83932.3", "0.000333"], ["83939.2", "0"]], "u": 174909, "seq": 67578157697}, "cts": 1742586289884, "record_time": 1742586290.008576, "EXCHANGE": "BYBIT"}
{"topic": "orderbook.200.BTCUSDT", "ts": 1742586290120, "type": "delta", "data": {"s": "BTCUSDT", "b": [["83872.7", "0.216853"], ["83868.7", "0.001486"], ["83868.6", "0"], ["83859.8", "0"], ["83856", "0.11723"], ["83850", "0.527773"], ["83849", "0.175621"], ["83842", "0.295853"], ["83840.9", "0"], ["83829.1", "0.357826"], ["83829", "0"]], "a": [["83883", "0.006282"], ["83885", "0.019685"], ["83888.9", "0.114367"], ["83890.8", "0.225355"], ["83894.8", "0"], ["83895.9", "0.166655"], ["83902.9", "0.310228"], ["83903.9", "0"], ["83932.1", "0.357826"], ["83932.2", "0"]], "u": 174910, "seq": 67578157748}, "cts": 1742586290117, "record_time": 1742586290.223796, "EXCHANGE": "BYBIT"}
{"topic": "orderbook.200.BTCUSDT", "ts": 1742586290320, "type": "delta", "data": {"s": "BTCUSDT", "b": [["83872.7", "0.207539"], ["83868.7", "0.001333"], ["83864.4", "0.10175"], ["83856", "0"], ["83849", "0"], ["83842", "0"], ["83831.4", "0.357822"], ["83829.1", "0"], ["83806.8", "0.00009"], ["83806.7", "0.023848"], ["83806.6", "0.118539"]], "a": [["83872.8", "0.291691"], ["83888.9", "0"], ["83895.9", "0"], ["83902.9", "0.0024"], ["83932", "0.357822"], ["83932.1", "0"], ["83939.2", "0.000526"], ["83940", "0.002799"]], "u": 174911, "seq": 67578157789}, "cts": 1742586290308, "record_time": 1742586290.409346, "EXCHANGE": "BYBIT"}
{"topic": "orderbook.200.BTCUSDT", "ts": 1742586290520, "type": "delta", "data": {"s": "BTCUSDT", "b": [["83872.7", "0.252528"], ["83868.4", "0.000153"], ["83842.1", "0"], ["83831.4", "0.35782"]], "a": [["83872.8", "0.297691"], ["83932", "0"], ["83932.5", "0.35782"]], "u": 174912, "seq": 67578157838}, "cts": 1742586290517, "record_time": 1742586290.608277, "EXCHANGE": "BYBIT"}
{"topic": "orderbook.200.BTCUSDT", "ts": 1742586290720, "type": "delta", "data": {"s": "BTCUSDT", "b": [["83872.7", "0.249492"], ["83872.6", "0.023673"], ["83832.8", "0.357816"], ["83831.4", "0"], ["83828", "0"], ["83821.8", "0.000149"], ["83806.6", "0"]], "a": [["83872.8", "0.300279"], ["83876.5", "0.076793"], ["83878", "0"], ["83925.6", "0"], ["83930", "0.000761"], ["83932.5", "0.357818"], ["83936.5", "0.000333"], ["83940.4", "0.177938"], ["83940.7", "0.000333"]], "u": 174913, "seq": 67578157883}, "cts": 1742586290716, "record_time": 1742586290.808905, "EXCHANGE": "BYBIT"}
{"topic": "orderbook.200.BTCUSDT", "ts": 1742586290920, "type": "delta", "data": {"s": "BTCUSDT", "b": [["83872.7", "0.47044"], ["83864.6", "0.006"], ["83837.6", "0.198831"], ["83837.5", "0"], ["83837.3", "0.04"], ["83837.2", "0.039633"], ["83836", "0"], ["83835.9", "0.000333"], ["83835.7", "0.013"], ["83835.6", "0.026849"], ["83834.8", "0.357811"], ["83834.2", "0.216361"], ["83834.1", "0.005206"], ["83833.9", "0.369404"], ["83833.8", "0.049545"], ["83832.8", "0"], ["83806.8", "0"], ["83806.7", "0"]], "a": [["83872.8", "0.287291"], ["83876.5", "0.005225"], ["83877.1", "0.0729"], ["83912", "0"], ["83912.1", "0"], ["83912.7", "0.04"], ["83912.8", "0.04"], ["83914", "0"], ["83916", "0.035644"], ["83925.1", "2.561565"], ["83932.5", "0"], ["83934.4", "0.357817"]], "u": 174914, "seq": 67578157964}, "cts": 1742586290916, "record_time": 1742586291.009262, "EXCHANGE": "BYBIT"}
{"topic": "orderbook.200.BTCUSDT", "ts": 1742586291119, "type": "delta", "data": {"s": "BTCUSDT", "b": [["83864.6", "0.003"], ["83837.6", "0.238831"], ["83837.5", "0.039633"], ["83837.3", "0"], ["83837.2", "0"], ["83836", "0.013"], ["83835.9", "0.013214"], ["83835.7", "0"], ["83835.6", "0.013968"], ["83834.2", "0.266361"], ["83834.1", "0.054751"], ["83833.9", "0.319404"], ["83833.8", "0"], ["83822.8", "0.065907"], ["83806.8", "0.00009"], ["83806.7", "0.023848"]], "a": [["83872.8", "0.293291"], ["83883", "0.000669"], ["83911.8", "0.04"], ["83911.9", "0.04"], ["83912.7", "0"], ["83912.8", "0"], ["83913.9", "0.567109"], ["83934.4", "0"], ["83940.3", "0.357806"]], "u": 174915, "seq": 67578158020}, "cts": 1742586291104, "record_time": 1742586291.207758, "EXCHANGE": "BYBIT"}
{"topic": "orderbook.200.BTCUSDT", "ts": 1742586291319, "type": "delta", "data": {"s": "BTCUSDT", "b": [["83834.9", "0.380362"], ["83834.8", "0.357801"], ["83834.2", "0.05"], ["83820.2", "8.704322"], ["83820.1", "0"]], "a": [["83872.8", "0.299291"], ["83914", "2.561565"], ["83923.1", "0"], ["83925.1", "0"], ["83941.8", "1.788424"]], "u": 174916, "seq": 67578158118}, "cts": 1742586291316, "record_time": 1742586291.408676, "EXCHANGE": "BYBIT"}
{"topic": "orderbook.200.BTCUSDT", "ts": 1742586291520, "type": "delta", "data": {"s": "BTCUSDT", "b": [["83872.7", "0.301926"], ["83868.6", "0.000153"], ["83868.4", "0"], ["83864.5", "0.207655"], ["83859.5", "0.003942"], ["83839.7", "0.359937"], ["83837.6", "0.198831"], ["83837.5", "0"], ["83837.2", "0.04"], ["83837.1", "0.039633"], ["83836", "0"], ["83835.9", "0.000333"], ["83835.6", "0.026968"], ["83835.5", "0.012881"], ["83834.8", "0"], ["83834.2", "0"], ["83834.1", "0.005206"], ["83833.8", "0.05"], ["83833.7", "0.049546"], ["83806.7", "0"]], "a": [["83872.8", "0.305291"], ["83873", "0"], ["83886.6", "0"], ["83890", "0.049225"], ["83900", "0"], ["83911.8", "0"], ["83911.9", "0"], ["83912.6", "0.04"], ["83912.7", "0.04"], ["83943.1", "0.005457"], ["83943.8", "0.000526"], ["83944.2", "0.001333"]], "u": 174917, "seq": 67578158249}, "cts": 1742586291517, "record_time": 1742586291.609232, "EXCHANGE": "BYBIT"}
{"topic": "orderbook.200.BTCUSDT", "ts": 1742586291720, "type": "delta", "data": {"s": "BTCUSDT", "b": [["83872.7", "0.246014"], ["83868.6", "0"], ["83839.7", "0.002145"], ["83837.7", "0.358319"], ["83837.2", "0.039633"], ["83834.9", "0.023844"], ["83833.8", "0.049545"], ["83806.7", "0.023848"]], "a": [["83943", "0.171"], ["83944.2", "0"]], "u": 174918, "seq": 67578158303}, "cts": 1742586291712, "record_time": 1742586291.808752, "EXCHANGE": "BYBIT"}
{"topic": "orderbook.200.BTCUSDT", "ts": 1742586291920, "type": "delta", "data": {"s": "BTCUSDT", "b": [["83872.7", "0.302426"], ["83868.5", "0.000153"], ["83837.7", "0.000522"], ["83834.8", "0.357808"], ["83832.5", "0"], ["83829.6", "0.126028"], ["83822.8", "8.770229"], ["83820.2", "0"], ["83806.7", "0"]], "a": [["83935.2", "0.357808"], ["83940.3", "0"]], "u": 174919, "seq": 67578158328}, "cts": 1742586291859, "record_time": 1742586292.008716, "EXCHANGE": "BYBIT"}
{"topic": "orderbook.200.BTCUSDT", "ts": 1742586292120, "type": "delta", "data": {"s": "BTCUSDT", "b": [["83872.7", "0.473426"], ["83869.6", "0.071573"], ["83869.3", "0.055066"], ["83869", "0.000153"], ["83868.5", "0"], ["83866", "0"], ["83860.1", "0.171804"], ["83850.3", "0.345168"], ["83841.2", "0.289433"], ["83829.6", "0.126027"]], "a": [["83885.3", "0.118616"], ["83895.1", "0.16421"], ["83904.2", "0.293965"], ["83935.2", "0"], ["83935.6", "0.357806"], ["83943", "0"], ["83943.1", "0"], ["83943.8", "0"]], "u": 174920, "seq": 67578158368}, "cts": 1742586292116, "record_time": 1742586292.20874, "EXCHANGE": "BYBIT"}
{"topic": "orderbook.200.BTCUSDT", "ts": 1742586292319, "type": "delta", "data": {"s": "BTCUSDT", "b": [["83837.2", "0"], ["83837", "0.039633"], ["83835.6", "0.013968"], ["83835.4", "0.012881"], ["83834.9", "0.700224"], ["83834.8", "0"], ["83833.8", "0"], ["83833.6", "0.049546"]], "a": [["83912.6", "0"], ["83912.8", "0.04"], ["83935.6", "0"], ["83940.3", "0.357801"]], "u": 174921, "seq": 67578158408}, "cts": 1742586292312, "record_time": 1742586292.408207, "EXCHANGE": "BYBIT"}
{"topic": "orderbook.200.BTCUSDT", "ts": 1742586292520, "type": "delta", "data": {"s": "BTCUSDT", "b": [["83872.7", "0.302426"], ["83869", "0"], ["83868.2", "0.071728"], ["83860.1", "0.06"], ["83850.3", "0.171"], ["83841.2", "0.000298"], ["83837.2", "0.04"], ["83837", "0"], ["83835.6", "0.026968"], ["83835.4", "0"], ["83835", "0.357805"], ["83834.9", "0.023844"], ["83833.8", "0.05"], ["83833.6", "0"], ["83822.8", "8.746121"], ["83806.7", "0.023848"]], "a": [["83873", "0.053405"], ["83877.1", "0.0759"], ["83879.7", "0"], ["83885.3", "0"], ["83895.1", "0"], ["83904.2", "0"], ["83912.6", "0.04"], ["83912.8", "0"], ["83935.6", "0.357806"], ["83940.3", "0"], ["83943.1", "0.005457"], ["83943.8", "0.000526"], ["83944.2", "0.001333"]], "u": 174922, "seq": 67578158498}, "cts": 1742586292514, "record_time": 1742586292.609258, "EXCHANGE": "BYBIT"}
{"topic": "orderbook.200.BTCUSDT", "ts": 1742586292720, "type": "delta", "data": {"s": "BTCUSDT", "b": [["83872.7", "0.303026"], ["83835.1", "0.35791"], ["83835", "0"], ["83832.5", "0.126027"], ["83829.6", "0"], ["83806.6", "0.118539"]], "a": [["83872.8", "0.317291"], ["83873", "0"], ["83913.9", "1.264689"], ["83934.4", "0.35781"], ["83935.6", "0"], ["83943", "0.171"]], "u": 174923, "seq": 67578158529}, "cts": 1742586292713, "record_time": 1742586292.80926, "EXCHANGE": "BYBIT"}
{"topic": "orderbook.200.BTCUSDT", "ts": 1742586292920, "type": "delta", "data": {"s": "BTCUSDT", "b": [["83835.2", "0.359141"], ["83835.1", "0.0001"], ["83822.8", "0.041799"], ["83820.2", "8.481155"], ["83806.6", "0"]], "a": [["83934.4", "0"], ["83935.6", "0.357808"]], "u": 174924, "seq": 67578158561}, "cts": 1742586292914, "record_time": 1742586293.008631, "EXCHANGE": "BYBIT"}
{"topic": "orderbook.200.BTCUSDT", "ts": 1742586293120, "type": "delta", "data": {"s": "BTCUSDT", "b": [["83872.7", "0.303795"], ["83872.6", "0"], ["83869.7", "0.076592"], ["83869.3", "0"], ["83868.2", "0.071575"], ["83837.5", "0.04"], ["83837.4", "0.039633"], ["83837.2", "0"], ["83837.1", "0"], ["83835.2", "0.001333"], ["83834.1", "0.055206"], ["83834", "0.069545"], ["83833.8", "0"], ["83833.7", "0"], ["83831.4", "0.357822"], ["83820.2", "0"], ["83809", "8.481155"], ["83806.6", "0.118539"], ["83806.5", "0.000333"]], "a": [["83872.8", "0.323291"], ["83873", "0.054305"], ["83875.8", "0.071568"], ["83879.9", "0"], ["83897.7", "0.0041"], ["83911.9", "0.04"], ["83912", "0.04"], ["83912.6", "0"], ["83912.7", "0"], ["83914", "0"], ["83919.5", "0.081934"], ["83921.9", "0.023665"], ["83925.1", "2.561565"], ["83932.5", "0.357822"], ["83935.6", "0"], ["83943.8", "0"], ["83944.2", "0"]], "u": 174925, "seq": 67578158658}, "cts": 1742586293116, "record_time": 1742586293.209242, "EXCHANGE": "BYBIT"}
{"topic": "orderbook.200.BTCUSDT", "ts": 1742586293320, "type": "delta", "data": {"s": "BTCUSDT", "b": [["83872.6", "0.023673"], ["83837.6", "0.238831"], ["83837.5", "0.039633"], ["83837.4", "0"], ["83836", "0.013"], ["83835.9", "0.013214"], ["83835.6", "0.013968"], ["83835.5", "0"], ["83834.2", "0.05"], ["83834.1", "0.054751"], ["83834", "0.02"], ["83832.8", "0.357819"], ["83831.4", "0"], ["83809.2", "8.481155"], ["83809", "0"], ["83806.5", "0"]], "a": [["83875.8", "0"], ["83875.9", "0.071568"], ["83877.1", "0.004333"], ["83879.3", "0.071565"], ["83895.7", "0.001094"], ["83911.8", "0.04"], ["83912", "0"], ["83913.9", "0.567109"], ["83919.5", "0.059399"], ["83922.3", "2.561589"], ["83925.1", "0"], ["83932.5", "0.357819"], ["83943.1", "0"]], "u": 174926, "seq": 67578158713}, "cts": 1742586293299, "record_time": 1742586293.409499, "EXCHANGE": "BYBIT"}
{"topic": "orderbook.200.BTCUSDT", "ts": 1742586293520, "type": "delta", "data": {"s": "BTCUSDT", "b": [["83872.7", "0.314523"], ["83860.1", "0.076093"], ["83834.1", "0.362028"], ["83820.1", "8.481155"], ["83809.2", "0"]], "a": [["83895.7", "0"], ["83919.6", "2.561565"], ["83922.3", "0.000024"], ["83932.5", "0"], ["83934.4", "0.357815"]], "u": 174927, "seq": 67578158762}, "cts": 1742586293516, "record_time": 1742586293.608556, "EXCHANGE": "BYBIT"}
{"topic": "orderbook.200.BTCUSDT", "ts": 1742586293721, "type": "delta", "data": {"s": "BTCUSDT", "b": [["83872.7", "0.303795"], ["83860.1", "0.06"]], "a": [["83932.5", "0.357819"], ["83934.4", "0"]], "u": 174928, "seq": 67578158806}, "cts": 1742586293640, "record_time": 1742586293.80947, "EXCHANGE": "BYBIT"}
{"topic": "orderbook.200.BTCUSDT", "ts": 1742586293919, "type": "delta", "data": {"s": "BTCUSDT", "b": [["83865.5", "0.003"], ["83806.6", "0"]], "a": [["83897.7", "0.000524"], ["83914", "2.561565"], ["83919.6", "0"]], "u": 174929, "seq": 67578158824}, "cts": 1742586293895, "record_time": 1742586294.007611, "EXCHANGE": "BYBIT"}
{"topic": "orderbook.200.BTCUSDT", "ts": 1742586294120, "type": "delta", "data": {"s": "BTCUSDT", "b": [["83865.6", "0.003"], ["83820.2", "8.36801"], ["83820.1", "0"], ["83806.7", "0"]], "a": [["83895.8", "0.001229"], ["83913.9", "1.264689"], ["83932.5", "0"], ["83934.4", "0.357817"], ["83943", "0"]], "u": 174930, "seq": 67578158871}, "cts": 1742586294115, "record_time": 1742586294.208606, "EXCHANGE": "BYBIT"}
{"topic": "orderbook.200.BTCUSDT", "ts": 1742586294320, "type": "delta", "data": {"s": "BTCUSDT", "b": [["83834.3", "0.357814"], ["83832.8", "0"]], "a": [["83873", "0.050201"], ["83875.9", "0"], ["83877.2", "0.071567"], ["83895.8", "0"], ["83943.1", "0.005457"]], "u": 174931, "seq": 67578158934}, "cts": 1742586294307, "record_time": 1742586294.408471, "EXCHANGE": "BYBIT"}
{"topic": "orderbook.200.BTCUSDT", "ts": 1742586294520, "type": "delta", "data": {"s": "BTCUSDT", "b": [["83872.7", "0.030997"], ["83872.6", "0"], ["83869.7", "0.079592"], ["83864.9", "0.000999"], ["83837.6", "0.198831"], ["83837.4", "0.039633"], ["83836", "0"], ["83835.8", "0.012881"], ["83834.3", "0"], ["83834.2", "0"], ["83834.1", "0.054751"], ["83834", "0.069545"], ["83829", "0.357825"], ["83820.2", "0"], ["83817.5", "8.36801"]], "a": [["83872.8", "0.331079"], ["83875.7", "0.071568"], ["83877.2", "0"], ["83879.9", "0.059399"], ["83891.6", "0"], ["83897.2", "0.003576"], ["83911.8", "0"], ["83912", "0.04"], ["83916", "0.033856"], ["83932.5", "0.35782"], ["83934.4", "0"], ["83943.1", "0"]], "u": 174932, "seq": 67578159021}, "cts": 1742586294516, "record_time": 1742586294.608387, "EXCHANGE": "BYBIT"}
{"topic": "orderbook.200.BTCUSDT", "ts": 1742586294719, "type": "delta", "data": {"s": "BTCUSDT", "b": [["83872.7", "0.010655"], ["83863.2", "0.000153"], ["83860.1", "0.065188"], ["83858.7", "0.181461"], ["83848.9", "0.174056"], ["83839.8", "0.293393"], ["83834.2", "0.28122"], ["83834", "0.02"], ["83829", "0"], ["83827.4", "0.357834"], ["83809.3", "0"], ["83808.9", "0"], ["83808.5", "0"], ["83806.8", "0"]], "a": [["83872.8", "0.508079"], ["83883.9", "0.114179"], ["83893.7", "0.179144"], ["83902.8", "0.305803"], ["83929.1", "0.357833"], ["83932.5", "0"], ["83940.4", "0"], ["83940.7", "0"], ["83941.8", "0"]], "u": 174933, "seq": 67578159076}, "cts": 1742586294706, "record_time": 1742586294.808693, "EXCHANGE": "BYBIT"}
{"topic": "orderbook.200.BTCUSDT", "ts": 1742586294919, "type": "delta", "data": {"s": "BTCUSDT", "b": [["83864.6", "0"], ["83863.9", "0.000153"], ["83863.2", "0"], ["83858.7", "0.179916"], ["83848.9", "0.176656"], ["83839.8", "0.309836"], ["83836", "0.013"], ["83835.8", "0"], ["83809.3", "3.548584"]], "a": [["83883.9", "0.12408"], ["83893.7", "0.184094"], ["83902.8", "0.272718"], ["83929.1", "0.357835"]], "u": 174934, "seq": 67578159129}, "cts": 1742586294912, "record_time": 1742586295.00853, "EXCHANGE": "BYBIT"}
{"topic": "orderbook.200.BTCUSDT", "ts": 1742586295119, "type": "delta", "data": {"s": "BTCUSDT", "b": [["83872.7", "0.347329"], ["83872.6", "0.023673"], ["83868.9", "0.000153"], ["83865.5", "0.006"], ["83863.9", "0"], ["83858.7", "0.06"], ["83848.9", "0"], ["83839.8", "0"], ["83837.6", "0.238831"], ["83837.4", "0"], ["83831.4", "0.357823"], ["83827.4", "0"], ["83820.1", "8.36801"], ["83817.5", "0"], ["83808.9", "0.005189"], ["83808.5", "0.005962"]], "a": [["83872.8", "0.335291"], ["83873", "0.032835"], ["83873.1", "0"], ["83874.1", "0.073093"], ["83875.7", "0"], ["83877.6", "0.071567"], ["83879.9", "0"], ["83883.9", "0"], ["83893.7", "0"], ["83902.8", "0"], ["83911.8", "0.04"], ["83912", "0"], ["83917", "0.001788"], ["83929.1", "0"], ["83932.5", "0.357826"], ["83940.4", "0.177938"], ["83940.7", "0.000333"], ["83941.8", "1.788424"], ["83943.1", "0.005457"]], "u": 174935, "seq": 67578159240}, "cts": 1742586295112, "record_time": 1742586295.20834, "EXCHANGE": "BYBIT"}
{"topic": "orderbook.200.BTCUSDT", "ts": 1742586295320, "type": "delta", "data": {"s": "BTCUSDT", "b": [["83872.7", "0.256317"], ["83837.6", "0.198831"], ["83837.5", "0"], ["83837.2", "0.04"], ["83837.1", "0.039633"], ["83836", "0"], ["83835.9", "0.000333"], ["83835.6", "0.026968"], ["83835.5", "0.012881"], ["83834.3", "0.357814"], ["83834.2", "0.23122"], ["83834.1", "0.005206"], ["83833.8", "0.05"], ["83833.7", "0.049546"], ["83831.4", "0"], ["83820.2", "8.375235"], ["83820.1", "0"], ["83809.3", "0"], ["83808.9", "0"], ["83808.5", "0"]], "a": [["83873", "0"], ["83873.1", "0.054305"], ["83873.2", "0.07157"], ["83874.1", "0.001523"], ["83876.2", "0.071568"], ["83877.6", "0"], ["83897.2", "0"], ["83911.8", "0"], ["83911.9", "0"], ["83912.6", "0.04"], ["83912.7", "0.04"], ["83932.5", "0"], ["83934.4", "0.357818"], ["83942.7", "0.354209"], ["83943.1", "0"]], "u": 174936, "seq": 67578159320}, "cts": 1742586295317, "record_time": 1742586295.409248, "EXCHANGE": "BYBIT"}
{"topic": "orderbook.200.BTCUSDT", "ts": 1742586295520, "type": "delta", "data": {"s": "BTCUSDT", "b": [["83872.7", "0.109117"], ["83868.9", "0"], ["83867", "0.000153"], ["83854.6", "0.061634"], ["83847.6", "0.05536"], ["83840.6", "0.120182"], ["83835.9", "0.013333"], ["83835.8", "0.012881"], ["83835.6", "0.013968"], ["83835.5", "0"], ["83834.3", "0"], ["83834.2", "0.28122"], ["83834.1", "0.054751"], ["83833.8", "0"], ["83833.7", "0"], ["83832.8", "0.357815"], ["83820.2", "0"], ["83817.5", "8.375235"]], "a": [["83889.6", "0.058616"], ["83891.6", "0.006205"], ["83896.6", "0.062204"], ["83903.6", "0.120454"], ["83940.4", "0"], ["83940.7", "0"], ["83941.8", "0"], ["83942.7", "0"]], "u": 174937, "seq": 67578159401}, "cts": 1742586295502, "record_time": 1742586295.609344, "EXCHANGE": "BYBIT"}
{"topic": "orderbook.200.BTCUSDT", "ts": 1742586295720, "type": "delta", "data": {"s": "BTCUSDT", "b": [["83872.6", "0"], ["83855.8", "0"], ["83854.6", "0.000994"], ["83853.4", "0.111562"], ["83847.6", "0"], ["83841.9", "0.095847"], ["83840.6", "0"], ["83837.6", "0.238831"], ["83837.5", "0.039633"], ["83837.2", "0"], ["83837.1", "0"], ["83836", "0.013"], ["83835.9", "0.013214"], ["83835.8", "0"], ["83809.3", "3.548584"], ["83808.9", "0.005189"], ["83808.5", "0.005962"]], "a": [["83889.6", "0"], ["83896.6", "0"], ["83903.6", "0"], ["83911.8", "0.04"], ["83911.9", "0.04"], ["83912.6", "0"], ["83912.7", "0"], ["83932.5", "0.357819"], ["83934.4", "0"], ["83940.4", "0.177938"], ["83940.7", "0.000333"], ["83941.8", "1.788424"]], "u": 174938, "seq": 67578159437}, "cts": 1742586295716, "record_time": 1742586295.807539, "EXCHANGE": "BYBIT"}
{"topic": "orderbook.200.BTCUSDT", "ts": 1742586295920, "type": "delta", "data": {"s": "BTCUSDT", "b": [["83872.6", "0.023673"], ["83867", "0"], ["83854.6", "0.061936"], ["83847.6", "0.056572"], ["83841.9", "0"], ["83840.6", "0.116722"], ["83832.8", "0"], ["83831.4", "0.357823"], ["83808.5", "0"]], "a": [["83889.6", "0.060933"], ["83896.6", "0.062035"], ["83903.6", "0.121831"], ["83940.4", "0"], ["83940.7", "0"], ["83941.8", "0"]], "u": 174939, "seq": 67578159464}, "cts": 1742586295888, "record_time": 1742586296.008664, "EXCHANGE": "BYBIT"}
{"topic": "orderbook.200.BTCUSDT", "ts": 1742586296120, "type": "delta", "data": {"s": "BTCUSDT", "b": [["83866.4", "0.000153"], ["83808.9", "0"]], "a": [["83903.5", "0.055411"], ["83905.3", "0.006945"]], "u": 174940, "seq": 67578159491}, "cts": 1742586296116, "record_time": 1742586296.208003, "EXCHANGE": "BYBIT"}
{"topic": "orderbook.200.BTCUSDT", "ts": 1742586296520, "type": "delta", "data": {"s": "BTCUSDT", "b": [["83872.7", "0.085317"], ["83872.6", "0"], ["83864.5", "0.173799"], ["83859.3", "0.033856"], ["83854.6", "0.000994"], ["83847.6", "0"], ["83840.6", "0"], ["83831.4", "0"], ["83829", "0.357825"], ["83808.9", "0.005189"], ["83808.5", "0.005962"]], "a": [["83889.6", "0"], ["83896.6", "0"], ["83897.7", "0.0041"], ["83903.6", "0"], ["83914", "0"], ["83922.3", "2.561589"], ["83940.4", "0.177938"], ["83940.7", "0.000333"], ["83941.8", "1.788424"], ["83942.7", "0.354209"]], "u": 174941, "seq": 67578159555}, "cts": 1742586296508, "record_time": 1742586296.608438, "EXCHANGE": "BYBIT"}
{"topic": "orderbook.200.BTCUSDT", "ts": 1742586296720, "type": "delta", "data": {"s": "BTCUSDT", "b": [["83872.7", "0.084517"], ["83831.4", "0.357824"], ["83829", "0"]], "a": [["83903.5", "0.0016"], ["83913.9", "0.567109"], ["83914", "2.561565"], ["83922.3", "0.000024"], ["83942.7", "0"]], "u": 174942, "seq": 67578159612}, "cts": 1742586296705, "record_time": 1742586296.809524, "EXCHANGE": "BYBIT"}
{"topic": "orderbook.200.BTCUSDT", "ts": 1742586296919, "type": "delta", "data": {"s": "BTCUSDT", "b": [["83872.7", "0.085117"], ["83841.9", "0.059793"], ["83808.5", "0"]], "a": [], "u": 174943, "seq": 67578159642}, "cts": 1742586296913, "record_time": 1742586297.008644, "EXCHANGE": "BYBIT"}
{"topic": "orderbook.200.BTCUSDT", "ts": 1742586297120, "type": "delta", "data": {"s": "BTCUSDT", "b": [], "a": [["83897.7", "0.000524"]], "u": 174944, "seq": 67578159658}, "cts": 1742586297112, "record_time": 1742586297.208656, "EXCHANGE": "BYBIT"}
{"topic": "orderbook.200.BTCUSDT", "ts": 1742586297319, "type": "delta", "data": {"s": "BTCUSDT", "b": [], "a": [["83887.5", "0.003576"], ["83941.8", "0"]], "u": 174945, "seq": 67578159679}, "cts": 1742586297316, "record_time": 1742586297.42889, "EXCHANGE": "BYBIT"}
{"topic": "orderbook.200.BTCUSDT", "ts": 1742586297520, "type": "delta", "data": {"s": "BTCUSDT", "b": [["83866.4", "0"], ["83808.5", "0.005962"]], "a": [["83887.5", "0"], ["83897.2", "0.003538"], ["83913.9", "1.264153"]], "u": 174946, "seq": 67578159695}, "cts": 1742586297512, "record_time": 1742586297.609362, "EXCHANGE": "BYBIT"}
{"topic": "orderbook.200.BTCUSDT", "ts": 1742586297720, "type": "delta", "data": {"s": "BTCUSDT", "b": [["83831.4", "0"], ["83829", "0.357825"]], "a": [["83872.8", "0.337079"], ["83917", "0"], ["83941.8", "1.788424"]], "u": 174947, "seq": 67578159721}, "cts": 1742586297696, "record_time": 1742586297.808253, "EXCHANGE": "BYBIT"}
{"topic": "orderbook.200.BTCUSDT", "ts": 1742586297919, "type": "delta", "data": {"s": "BTCUSDT", "b": [["83872.7", "0.011255"], ["83869.7", "0.003"], ["83865.5", "0.003"], ["83864.9", "0.001152"], ["83856.8", "0.092107"], ["83855.1", "0.056"], ["83853.6", "0.055604"], ["83846.6", "0.063059"], ["83845.9", "0.321227"], ["83839.6", "0.3047"], ["83829", "0"], ["83827.2", "0.357841"], ["83808.5", "0"]], "a": [["83872.8", "0.508079"], ["83879.9", "0.059399"], ["83888.6", "0.061454"], ["83895.6", "0.060161"], ["83897.3", "0.003576"], ["83902.6", "0.115559"], ["83922.9", "0.022535"], ["83929.1", "0.357833"], ["83932.5", "0"], ["83939.2", "0"], ["83940", "0"], ["83940.4", "0"], ["83940.7", "0"], ["83941.8", "0"]], "u": 174948, "seq": 67578159787}, "cts": 1742586297908, "record_time": 1742586298.008245, "EXCHANGE": "BYBIT"}
{"topic": "orderbook.200.BTCUSDT", "ts": 1742586298120, "type": "delta", "data": {"s": "BTCUSDT", "b": [["83865.6", "0"], ["83857.1", "0.127749"], ["83848.5", "0.21909"], ["83829.9", "0.005205"], ["83827.2", "0"], ["83826.5", "0.357842"], ["83808.5", "0.005962"]], "a": [["83872.8", "0.506291"], ["83914.9", "0.003121"], ["83929", "0.357843"], ["83929.1", "0"]], "u": 174949, "seq": 67578159824}, "cts": 1742586298107, "record_time": 1742586298.20864, "EXCHANGE": "BYBIT"}
{"topic": "orderbook.200.BTCUSDT", "ts": 1742586298319, "type": "delta", "data": {"s": "BTCUSDT", "b": [["83864.9", "0.000999"], ["83827.4", "0.35784"], ["83826.5", "0"]], "a": [["83872.8", "0.508079"], ["83891.2", "0"], ["83914.9", "0.001333"], ["83928.9", "0.35784"], ["83929", "0"], ["83939.2", "0.000526"]], "u": 174950, "seq": 67578159847}, "cts": 1742586298306, "record_time": 1742586298.40844, "EXCHANGE": "BYBIT"}
{"topic": "orderbook.200.BTCUSDT", "ts": 1742586298519, "type": "delta", "data": {"s": "BTCUSDT", "b": [["83867.5", "0.05"], ["83864.9", "0"], ["83860.9", "0"], ["83857.2", "0.00009"], ["83853.6", "0"], ["83850.6", "0"], ["83848.4", "0"], ["83846.6", "0.005835"], ["83839.6", "0.195696"], ["83827.5", "0.358168"], ["83827.4", "0"], ["83817.5", "0"], ["83814.7", "8.417958"], ["83806.8", "0.00009"], ["83806.7", "0.023848"], ["83806.6", "0.118539"], ["83806.5", "0.000333"], ["83806.4", "0.0016"], ["83806.2", "0.001466"], ["83805.8", "0.001989"]], "a": [["83888.6", "0.005429"], ["83890.8", "0.139478"], ["83895.5", "0.050912"], ["83895.6", "0"], ["83899.1", "0"], ["83902.6", "0"], ["83928.8", "0.357835"], ["83928.9", "0"], ["83940", "0.002799"], ["83940.4", "0.177938"]], "u": 174951, "seq": 67578159902}, "cts": 1742586298513, "record_time": 1742586298.608339, "EXCHANGE": "BYBIT"}
{"topic": "orderbook.200.BTCUSDT", "ts": 1742586298720, "type": "delta", "data": {"s": "BTCUSDT", "b": [["83867", "0.000153"], ["83859", "0.033608"], ["83856.8", "0.056333"], ["83856.7", "0.035774"], ["83848.5", "0.12035"], ["83837.9", "0.04"], ["83837.8", "0.039633"], ["83837.6", "0.198831"], ["83837.5", "0"], ["83836.3", "0.013"], ["83836.2", "0.012881"], ["83836", "0"], ["83835.9", "0.000333"], ["83834.5", "0.05"], ["83834.4", "0.049545"], ["83834.2", "0.23122"], ["83834.1", "0.005206"], ["83827.6", "0.35784"], ["83827.5", "0.000333"], ["83817.3", "8.373814"], ["83814.7", "0.059399"], ["83806.8", "0"], ["83806.7", "0"], ["83806.6", "0"], ["83806.5", "0"], ["83806.4", "0"], ["83806.2", "0"], ["83805.8", "0"]], "a": [["83872.8", "0.506291"], ["83895.5", "0"], ["83911.3", "0.04"], ["83911.4", "0.040333"], ["83911.8", "0"], ["83911.9", "0"], ["83918.4", "0.001788"], ["83928.7", "0.35784"], ["83928.8", "0"], ["83940.7", "0.000333"]], "u": 174952, "seq": 67578159979}, "cts": 1742586298717, "record_time": 1742586298.809023, "EXCHANGE": "BYBIT"}
{"topic": "orderbook.200.BTCUSDT", "ts": 1742586298920, "type": "delta", "data": {"s": "BTCUSDT", "b": [["83857.2", "0.118629"], ["83827.7", "0.357836"], ["83827.6", "0"]], "a": [["83872.8", "0.335291"], ["83891.2", "0.178842"], ["83928.6", "0.357836"], ["83928.7", "0"], ["83940.7", "0"]], "u": 174953, "seq": 67578160020}, "cts": 1742586298916, "record_time": 1742586299.008262, "EXCHANGE": "BYBIT"}
{"topic": "orderbook.200.BTCUSDT", "ts": 1742586299119, "type": "delta", "data": {"s": "BTCUSDT", "b": [["83872.7", "0"], ["83872.5", "0"], ["83871.8", "0"], ["83870.8", "0.041041"], ["83869.7", "0"], ["83869.6", "0"], ["83869.2", "0"], ["83868.3", "0"], ["83867.3", "0.006801"], ["83867", "0"], ["83865.9", "0.071577"], ["83865.5", "0"], ["83864.5", "0.161558"], ["83864.3", "0.027207"], ["83864.1", "0"], ["83862.4", "0.06"], ["83860.2", "0.040813"], ["83860.1", "0.06"], ["83859", "0"], ["83858.2", "0.059748"], ["83856.7", "0"], ["83856.3", "0.120402"], ["83850.1", "0.008893"], ["83846.5", "0.176836"], ["83837.9", "0"], ["83837.8", "0"], ["83837.4", "0.328657"], ["83837.3", "0.039631"], ["83836.5", "0.011922"], ["83836.3", "0"], ["83836.2", "0"], ["83835.8", "0.013"], ["83835.7", "0.01288"], ["83834.5", "0"], ["83834.4", "0"], ["83834", "0.07"], ["83833.9", "0.368947"], ["83832.5", "0"], ["83827.7", "0"], ["83825.6", "0.413848"], ["83824", "0.182042"], ["83817.3", "0.005189"], ["83810", "0.03514"], ["83806.8", "0.00009"], ["83806.7", "0.023848"], ["83806.6", "0.118539"], ["83806.5", "0.000333"], ["83806.4", "8.370225"], ["83806.2", "0.001466"], ["83805.8", "0.001989"], ["83805.4", "0.00052"]], "a": [["83870.9", "0.732476"], ["83872.7", "0.067651"], ["83872.8", "0.1926"], ["83873.1", "0"], ["83873.2", "0"], ["83874.4", "0.005225"], ["83874.8", "0.048042"], ["83874.9", "0.071569"], ["83876", "0.005336"], ["83876.5", "0"], ["83879.3", "0.06"], ["83879.6", "0.00009"], ["83879.9", "0"], ["83880", "0.170281"], ["83881.2", "0"], ["83881.5", "0.143752"], ["83882.9", "0"], ["83883.7", "0"], ["83883.9", "0.063708"], ["83891.2", "0"], ["83891.3", "0.175893"], ["83892.1", "0"], ["83900.4", "0.289909"], ["83907.3", "0"], ["83911.3", "0"], ["83911.5", "0.040524"], ["83912.7", "1.429887"], ["83914.6", "0"], ["83926", "0.357847"], ["83928.6", "0"], ["83940.7", "0.000333"]], "u": 174954, "seq": 67578160385}, "cts": 1742586299116, "record_time": 1742586299.20879, "EXCHANGE": "BYBIT"}
{"topic": "orderbook.200.BTCUSDT", "ts": 1742586299319, "type": "delta", "data": {"s": "BTCUSDT", "b": [["83868.2", "0"], ["83867.6", "0.076923"], ["83865.9", "0"], ["83865", "0.006386"], ["83863.9", "0.071578"], ["83863.3", "0.008195"], ["83858.2", "0.083253"], ["83857.2", "0.00009"], ["83856.3", "0"], ["83856.1", "0.122398"], ["83854.8", "0.035775"], ["83850.4", "0.009076"], ["83848.8", "0.00009"], ["83848.5", "0.201321"], ["83846.5", "0"], ["83846.3", "0"], ["83841.8", "0"], ["83837.4", "0.04"], ["83830.2", "0"], ["83826.4", "0"], ["83825.8", "0.382049"], ["83825.6", "0.056"], ["83823.2", "0"], ["83815.2", "0.033946"], ["83805.1", "0.240615"], ["83805", "0.000358"], ["83804.7", "0.00517"]], "a": [["83872.7", "0.07106"], ["83881.1", "0.033856"], ["83881.3", "0.121609"], ["83881.5", "0.031348"], ["83883.6", "0.117519"], ["83883.7", "0.178846"], ["83883.9", "0"], ["83886.4", "0"], ["83891.3", "0"], ["83891.6", "0"], ["83892.9", "0"], ["83900.4", "0"], ["83902", "0.118539"], ["83905.3", "0.04272"], ["83909.8", "0.023571"], ["83913.9", "0.567109"], ["83914", "0"], ["83914.2", "0"], ["83926", "0"], ["83926.4", "0.357846"], ["83941.7", "2.561565"], ["83941.8", "1.788424"], ["83942.7", "0.354209"]], "u": 174955, "seq": 67578160512}, "cts": 1742586299317, "record_time": 1742586299.408639, "EXCHANGE": "BYBIT"}
{"topic": "orderbook.200.BTCUSDT", "ts": 1742586299519, "type": "delta", "data": {"s": "BTCUSDT", "b": [["83857.2", "0.118629"], ["83854.6", "0"], ["83852.7", "0.000994"], ["83848.5", "0.12035"], ["83846.3", "0.176611"], ["83843.4", "0.178846"], ["83841.9", "0"], ["83837.2", "0.30183"], ["83833.4", "0.178846"], ["83829.2", "0.179026"], ["83827.4", "0.357843"], ["83826.8", "0.127378"], ["83825.8", "0.024203"], ["83824", "0.056"], ["83817.3", "8.350972"], ["83806.4", "0.0016"], ["83805.4", "0"], ["83805.1", "0"], ["83805", "0"], ["83804.7", "0"]], "a": [["83870.9", "0.726515"], ["83872.2", "0.0019"], ["83874.8", "0.045942"], ["83890.8", "0"], ["83891.1", "0.164123"], ["83900.2", "0.308592"], ["83900.9", "0.0028"], ["83902", "0"], ["83903.5", "0"], ["83911.2", "0.04"], ["83911.3", "0.04"], ["83911.4", "0.000333"], ["83911.5", "0.000524"], ["83913.9", "0"], ["83914.4", "0.051497"], ["83926.4", "0"], ["83926.9", "0.357838"], ["83941.7", "2.561623"], ["83942.7", "0"]], "u": 174956, "seq": 67578160588}, "cts": 1742586299516, "record_time": 1742586299.608139, "EXCHANGE": "BYBIT"}
{"topic": "orderbook.200.BTCUSDT", "ts": 1742586299720, "type": "delta", "data": {"s": "BTCUSDT", "b": [["83870.8", "0.03831"], ["83856.1", "0.001855"], ["83848.5", "0.165485"], ["83846.3", "0"], ["83843.4", "0"], ["83841.8", "0.178846"], ["83837.2", "0"], ["83833.4", "0"], ["83829.3", "0.359297"], ["83829.2", "0.00018"], ["83827.4", "0"], ["83822.2", "0.148634"], ["83805.4", "0.00052"], ["83805.1", "0.240615"], ["83805", "0.000358"], ["83804.7", "0.00517"]], "a": [["83870.9", "0.726754"], ["83875.4", "0.001466"], ["83877.4", "0.020899"], ["83879.5", "0"], ["83881.3", "0.001333"], ["83890.9", "0.003576"], ["83891", "0.097432"], ["83891.1", "0"], ["83897.3", "0"], ["83899.8", "0.029807"], ["83900.2", "0"], ["83911.2", "0"], ["83911.3", "0"], ["83911.4", "0.040333"], ["83911.5", "0.040524"], ["83914", "2.561623"], ["83926.9", "0"], ["83929.1", "0.357837"], ["83941.7", "0"], ["83942.7", "0.354209"], ["83943.1", "0.005457"]], "u": 174957, "seq": 67578160671}, "cts": 1742586299716, "record_time": 1742586299.808515, "EXCHANGE": "BYBIT"}
{"topic": "orderbook.200.BTCUSDT", "ts": 1742586299920, "type": "delta", "data": {"s": "BTCUSDT", "b": [["83870.8", "0.020598"], ["83850.1", "0.0003"], ["83841.9", "0.059797"], ["83841.8", "0"], ["83829.4", "0.357834"], ["83829.3", "0.001466"], ["83817.3", "0.005189"], ["83814.7", "8.405182"], ["83804.7", "0"]], "a": [["83891", "0"], ["83929", "0.357835"], ["83929.1", "0"], ["83943", "0.171"]], "u": 174958, "seq": 67578160744}, "cts": 1742586299916, "record_time": 1742586300.008629, "EXCHANGE": "BYBIT"}
{"topic": "orderbook.200.BTCUSDT", "ts": 1742586300119, "type": "delta", "data": {"s": "BTCUSDT", "b": [["83870.8", "0.017379"], ["83867.5", "0"], ["83865", "0"], ["83864.5", "0.001333"], ["83857.2", "0.00009"], ["83847.2", "0"], ["83845.9", "0.142385"], ["83841.9", "0"], ["83831.2", "0"], ["83829.5", "0.357831"], ["83829.4", "0"], ["83823.5", "0.378058"], ["83814.8", "0"], ["83814.7", "0.059399"], ["83811.9", "8.337494"], ["83804.7", "0.00517"], ["83804.3", "0.028199"], ["83804.1", "0.089099"], ["83803.9", "0.125182"], ["83802.5", "0.011876"]], "a": [["83899.8", "0.005961"], ["83902", "0.118539"], ["83929", "0"], ["83929.7", "0.35783"], ["83943.1", "0"]], "u": 174959, "seq": 67578160832}, "cts": 1742586300117, "record_time": 1742586300.207641, "EXCHANGE": "BYBIT"}
{"topic": "orderbook.200.BTCUSDT", "ts": 1742586300319, "type": "delta", "data": {"s": "BTCUSDT", "b": [["83870.8", "0"], ["83870", "0.003504"], ["83867.6", "0.005348"], ["83865.4", "0.000822"], ["83863.9", "0"], ["83862.4", "0"], ["83862", "0"], ["83861.8", "0"], ["83861.6", "0.06"], ["83861.5", "0.051114"], ["83860.7", "0"], ["83860.6", "0"], ["83860.3", "0.001933"], ["83860.1", "0"], ["83860", "0.00018"], ["83859.5", "0"], ["83859.3", "0"], ["83858.7", "0"], ["83858.5", "0"], ["83858.2", "0"], ["83857.1", "0.048687"], ["83857", "0.0496"], ["83856.8", "0.000333"], ["83855.9", "0.049738"], ["83855.1", "0"], ["83855", "0.005235"], ["83854.8", "0"], ["83853.8", "0.064"], ["83853.7", "0"], ["83853.4", "0"], ["83852.3", "0.089495"], ["83852.2", "0.103042"], ["83851.9", "0.001333"], ["83851.8", "0"], ["83850.4", "0.069076"], ["83850.1", "0"], ["83850", "0"], ["83849.8", "0.004108"], ["83849.5", "0.033856"], ["83849.1", "0"], ["83848.8", "0.05609"], ["83848.5", "0.045468"], ["83848.2", "0"], ["83847.1", "0.052"], ["83846.6", "0.117395"], ["83845.9", "0.118539"], ["83844.2", "0.035789"], ["83843.5", "0.005961"], ["83842.9", "0"], ["83841.3", "0.009225"], ["83839.4", "0.533415"], ["83839.1", "0"], ["83838.3", "0.596123"], ["83837.6", "0.02"], ["83837.4", "0"], ["83837.3", "0"], ["83836.6", "0"], ["83835.8", "0"], ["83835.7", "0"], ["83834.9", "0"], ["83834", "0.02"], ["83833.9", "0.001466"], ["83833.4", "0.178848"], ["83831.8", "0"], ["83831.7", "0.039969"], ["83831.6", "0.039636"], ["83830.1", "0.012882"], ["83830", "0.012882"], ["83829.5", "0"], ["83829.2", "0.179028"], ["83828.9", "0.064"], ["83828.3", "0.064549"], ["83828.2", "0.049549"], ["83826.8", "0.001333"], ["83825.3", "0"], ["83823.8", "0"], ["83823.5", "0.354214"], ["83822.8", "0.01656"], ["83821.6", "0.357871"], ["83821.1", "0.126045"], ["83816.6", "0"], ["83812.5", "0"], ["83811.9", "0"], ["83806.4", "8.339094"], ["83804.7", "0.17617"], ["83802.3", "0.000333"], ["83802.2", "0.059399"], ["83801.6", "0.002799"], ["83800.8", "0.00052"], ["83800.5", "0.06482"], ["83800", "0.119443"], ["83798.7", "0.120826"], ["83798.4", "0.00018"], ["83798.2", "0.000333"], ["83797.7", "0.048"], ["83797.4", "0.001333"], ["83797", "0.001466"], ["83796.3", "0.005769"], ["83796.2", "0.00052"], ["83795.7", "0.02016"], ["83794.8", "0.013127"], ["83794", "0.000333"], ["83793.6", "0.4"], ["83793.3", "0.001333"], ["83793.1", "0.625932"]], "a": [["83870.1", "1.061183"], ["83870.6", "0.003576"], ["83870.7", "0.165502"], ["83870.8", "0.071573"], ["83870.9", "0.392"], ["83871.4", "0.006246"], ["83872.7", "0.003409"], ["83872.8", "0.0216"], ["83873.4", "0.095416"], ["83873.6", "0.119232"], ["83874.1", "0"], ["83874.8", "0.090377"], ["83875", "0.003759"], ["83875.3", "0.178848"], ["83875.4", "0.035322"], ["83876.2", "0"], ["83878.3", "0.049227"], ["83878.5", "0.06"], ["83879.3", "0"], ["83879.4", "0.256702"], ["83879.5", "0.286523"], ["83880", "0.060865"], ["83880.4", "0.059616"], ["83881.1", "0.005961"], ["83881.2", "0.178824"], ["83881.5", "0.057072"], ["83881.7", "0.04"], ["83883.4", "0.08"], ["83883.5", "0.099659"], ["83883.6", "0"], ["83883.7", "0"], ["83884.3", "0.179418"], ["83885", "0.059685"], ["83886.1", "0"], ["83886.2", "0.000333"], ["83886.9", "0.059616"], ["83887.7", "0"], ["83887.9", "0"], ["83888.7", "0"], ["83889.4", "0"], ["83889.5", "0"], ["83890", "0"], ["83890.6", "0"], ["83890.9", "0"], ["83891.6", "0.029808"], ["83895.6", "0.023846"], ["83899", "0.023846"], ["83900.5", "0.095382"], ["83900.7", "0"], ["83901.6", "0.023665"], ["83903.9", "0.023846"], ["83904.4", "0.317671"], ["83905", "0.023846"], ["83905.9", "0.051497"], ["83908.1", "0.023846"], ["83908.8", "0.147714"], ["83909.7", "0.023846"], ["83910.5", "0"], ["83911.9", "1.429887"], ["83912.7", "0"], ["83914", "0"], ["83914.3", "0"], ["83914.4", "0"], ["83921.9", "0"], ["83922.9", "0"], ["83923.5", "0.35787"], ["83929.7", "0"], ["83929.8", "0"], ["83932.6", "0"], ["83934.5", "0"], ["83940.7", "0"], ["83941.8", "0"], ["83942.7", "0"], ["83943", "0"]], "u": 174960, "seq": 67578162109}, "cts": 1742586300317, "record_time": 1742586300.408543, "EXCHANGE": "BYBIT"}
{"topic": "orderbook.200.BTCUSDT", "ts": 1742586300519, "type": "delta", "data": {"s": "BTCUSDT", "b": [["83870", "0"], ["83869.4", "0"], ["83868.7", "0"], ["83867.6", "0"], ["83867.3", "0"], ["83866.2", "0"], ["83866.1", "0"], ["83865.4", "0"], ["83865.3", "0"], ["83865.2", "0"], ["83864.5", "0"], ["83864.4", "0"], ["83864.3", "0"], ["83863.5", "0"], ["83863.4", "0"], ["83863.3", "0"], ["83861.6", "0.387796"], ["83861.1", "0"], ["83860.2", "0"], ["83857.2", "0"], ["83857.1", "0"], ["83857", "0"], ["83856", "0.017923"], ["83854.1", "0.01056"], ["83853.8", "0"], ["83852.4", "0.0264"], ["83852.3", "0.123448"], ["83852.2", "0"], ["83850.6", "0.064"], ["83850.4", "0"], ["83850.1", "0.0003"], ["83849.5", "0"], ["83849", "0.094186"], ["83848.9", "0.056"], ["83848.8", "0.00009"], ["83848.5", "0.000333"], ["83847.5", "0"], ["83847.1", "0"], ["83846.7", "0.009"], ["83846.6", "0.005835"], ["83845.9", "0"], ["83844.3", "0.098082"], ["83844.2", "0.181205"], ["83842.3", "0.056522"], ["83842.1", "0.019642"], ["83841.9", "0.009076"], ["83841.6", "0.05"], ["83841.5", "0.000635"], ["83841.3", "0"], ["83839.6", "0.425001"], ["83839.4", "0.561866"], ["83838.6", "0.017913"], ["83836.5", "0"], ["83835.7", "0.04874"], ["83835.6", "0"], ["83834.2", "0"], ["83834.1", "0.125602"], ["83833.4", "0.178866"], ["83831.7", "0.009558"], ["83831.6", "0"], ["83830.1", "0"], ["83830", "0"], ["83829.2", "0.179046"], ["83828.6", "0.039631"], ["83828.5", "0.040153"], ["83828.3", "0.015"], ["83828.2", "0"], ["83827.4", "0.214923"], ["83827.3", "0.06"], ["83827", "0.01288"], ["83826.9", "0.01288"], ["83826.4", "0.011924"], ["83825.8", "0"], ["83825.7", "0.005203"], ["83825.6", "0"], ["83825.2", "0.049543"], ["83825.1", "0.049543"], ["83824.9", "0"], ["83824", "0"], ["83823.6", "0.397847"], ["83822.2", "0.052"], ["83821.8", "0"], ["83821.6", "0"], ["83821.1", "0"], ["83819.5", "0.35788"], ["83818", "0.023671"], ["83817.1", "0"], ["83815.5", "0.126047"], ["83813.2", "0.178866"], ["83809.5", "0.000149"], ["83806.4", "0.0016"], ["83804.3", "0"], ["83798.7", "0"], ["83796.3", "0.176769"], ["83793.1", "0"], ["83792.8", "0.028207"], ["83792.7", "0.059399"], ["83792.6", "8.337494"], ["83792.4", "0.001466"], ["83792.2", "0.005164"], ["83791.6", "0.000528"], ["83791.4", "0.064"], ["83790.9", "0.118539"], ["83790.4", "0.05965"], ["83790", "0.06009"], ["83789.8", "0.084333"], ["83789.7", "0.000244"], ["83789.5", "0.000407"], ["83789.4", "0.000237"], ["83789.1", "0.001333"], ["83788.4", "0.001433"], ["83788.2", "0.064"], ["83788.1", "0.18"], ["83788", "0.006241"], ["83787.8", "0.0024"], ["83787", "0.000528"]], "a": [["83861.7", "0.518172"], ["83862.6", "0.071579"], ["83866.1", "0.014463"], ["83866.2", "0.174395"], ["83866.3", "0.171"], ["83867.4", "0.12"], ["83867.6", "0.005336"], ["83867.8", "0.071575"], ["83868.7", "0.001333"], ["83868.8", "0.08"], ["83869.2", "0.04224"], ["83869.4", "0.000333"], ["83869.5", "0.05298"], ["83869.6", "0.033856"], ["83869.8", "0.136265"], ["83870", "0.091439"], ["83870.1", "0.11"], ["83870.4", "0.071573"], ["83870.6", "0"], ["83870.7", "0.023846"], ["83870.8", "0.001466"], ["83870.9", "0.236895"], ["83871", "0.003576"], ["83871.2", "0.00009"], ["83871.4", "0"], ["83871.8", "0.005336"], ["83872.3", "0.005225"], ["83872.9", "0.001333"], ["83873.4", "0.023846"], ["83873.6", "0.119565"], ["83873.7", "0.019816"], ["83873.9", "0.0209"], ["83874.4", "0"], ["83874.6", "0.000524"], ["83874.8", "0.020908"], ["83874.9", "0"], ["83875.3", "0"], ["83875.4", "0.001466"], ["83876.8", "0.02611"], ["83877.1", "0.001333"], ["83877.4", "0"], ["83878", "0.031356"], ["83878.5", "0"], ["83879", "0.162462"], ["83879.4", "0"], ["83879.5", "0.178866"], ["83880.3", "0"], ["83881.2", "0"], ["83881.5", "0"], ["83882", "0.000333"], ["83882.2", "0.04"], ["83882.4", "0.033856"], ["83883.4", "0.04"], ["83883.5", "0.139659"], ["83883.7", "0.178866"], ["83884.3", "0.0006"], ["83885", "0.04"], ["83886.8", "0"], ["83887.6", "0.102524"], ["83888", "0.599567"], ["83888.5", "0.540713"], ["83889", "0"], ["83889.8", "0.059399"], ["83891.6", "0.078003"], ["83891.7", "0"], ["83895.6", "0"], ["83896.9", "0.038918"], ["83897.2", "0"], ["83900.5", "0.005961"], ["83901", "0.193341"], ["83902", "0.142852"], ["83902.1", "0.011929"], ["83902.5", "0"], ["83903.5", "1.429887"], ["83903.8", "0.178866"], ["83904.3", "0.135166"], ["83905.9", "0.051494"], ["83908.3", "0.01404"], ["83909.3", "0"], ["83909.8", "0"], ["83911.9", "0"], ["83916", "0"], ["83916.2", "0"], ["83916.8", "0.357891"], ["83917.8", "0.171503"], ["83921.1", "0"], ["83923.5", "0"], ["83930", "0.000616"], ["83932.3", "0"], ["83934.6", "0"], ["83934.7", "0"], ["83934.9", "0"], ["83935.3", "0"], ["83935.4", "0"], ["83935.7", "0"], ["83935.8", "0"], ["83936.5", "0"], ["83938.4", "0"], ["83938.9", "0"], ["83939.2", "0"], ["83940", "0"], ["83940.4", "0"]], "u": 174961, "seq": 67578163020}, "cts": 1742586300516, "record_time": 1742586300.609349, "EXCHANGE": "BYBIT"}
{"topic": "orderbook.200.BTCUSDT", "ts": 1742586300719, "type": "delta", "data": {"s": "BTCUSDT", "b": [["83861.6", "0.559188"], ["83861.1", "0.000635"], ["83858.1", "0.006762"], ["83857.2", "0.011929"], ["83855.1", "0.02705"], ["83852.3", "0.186693"], ["83850.9", "0.040577"], ["83850.2", "0.033856"], ["83849.1", "0.118539"], ["83849", "0.142186"], ["83848.9", "0.064"], ["83847.3", "0.036203"], ["83847.2", "0.084"], ["83846.2", "0.122949"], ["83845.5", "0.06"], ["83844.2", "0.147349"], ["83843.8", "0.056"], ["83842.2", "0.052"], ["83841.5", "0"], ["83839.2", "0.167135"], ["83832.7", "0.118539"], ["83832.2", "0.284481"], ["83828.9", "0"], ["83828.6", "0"], ["83828.5", "0.000522"], ["83828", "0.04"], ["83827.9", "0.039631"], ["83827.4", "0.133139"], ["83827", "0"], ["83826.9", "0"], ["83826.4", "0.024924"], ["83826.3", "0.01288"], ["83825.5", "0"], ["83825.4", "0.073347"], ["83825.3", "0.357857"], ["83825.2", "0"], ["83825.1", "0"], ["83824.6", "0.05"], ["83824.5", "0.049543"], ["83824", "0.126047"], ["83822.2", "0"], ["83819.5", "0"], ["83816.6", "0.089433"], ["83815.8", "0.58895"], ["83815.5", "0"], ["83811.6", "0.025239"], ["83811.3", "0.024108"], ["83806.4", "8.339094"], ["83795.6", "0.089433"], ["83792.6", "0"], ["83791.4", "0"], ["83790.9", "0"], ["83790.4", "0"], ["83790", "0"], ["83789.8", "0"], ["83789.7", "0"], ["83789.5", "0"], ["83789.4", "0"], ["83789.1", "0"], ["83788.4", "0"], ["83788.2", "0"], ["83788.1", "0"], ["83788", "0"], ["83787.8", "0"], ["83787", "0"]], "a": [["83861.7", "0.17968"], ["83862.6", "0"], ["83865.2", "0.005256"], ["83865.5", "0.021473"], ["83865.6", "0.071577"], ["83866.2", "0.084929"], ["83866.3", "0"], ["83867.4", "0.1"], ["83867.8", "0"], ["83868.2", "0.021026"], ["83868.8", "0.06"], ["83869.2", "0.0528"], ["83869.5", "0"], ["83869.6", "0"], ["83870", "0.139784"], ["83870.1", "0.06"], ["83870.4", "0"], ["83870.7", "0"], ["83870.9", "0.21874"], ["83871", "0"], ["83871.7", "0.071572"], ["83872.3", "0"], ["83872.4", "0.031537"], ["83872.8", "0.0016"], ["83873.9", "0.07157"], ["83874.1", "0.009225"], ["83874.6", "0.03438"], ["83874.8", "0.032888"], ["83875.5", "0.04"], ["83877.3", "0.04"], ["83878", "0"], ["83879.1", "0.119735"], ["83882.3", "0"], ["83882.4", "0"], ["83884.2", "0"], ["83886.1", "0.173789"], ["83887.6", "0.401114"], ["83888.4", "0.004757"], ["83893.1", "0.296338"], ["83895.6", "0.004693"], ["83899.3", "0"], ["83899.6", "0"], ["83900.5", "0.095394"], ["83900.9", "0.117963"], ["83901.6", "0"], ["83908.5", "2.567526"], ["83908.8", "0.125179"], ["83916", "0.033856"], ["83916.8", "0"], ["83923.5", "0.357863"], ["83929.8", "0.125206"], ["83932.3", "0.000333"]], "u": 174962, "seq": 67578163278}, "cts": 1742586300716, "record_time": 1742586300.808424, "EXCHANGE": "BYBIT"}
{"topic": "orderbook.200.BTCUSDT", "ts": 1742586300919, "type": "delta", "data": {"s": "BTCUSDT", "b": [["83861.6", "0.388188"], ["83855.8", "0.006192"], ["83850.6", "0"], ["83848.4", "0.06"], ["83847.3", "0.060411"], ["83846.9", "0.036301"], ["83846.2", "0"], ["83843.9", "0.178904"], ["83842.3", "0.235429"], ["83841.6", "0"], ["83840", "0.178972"], ["83839.2", "0"], ["83832.2", "0"], ["83831.3", "0"], ["83828", "0.039631"], ["83827.2", "0.357848"], ["83826.4", "0.024804"], ["83825.3", "0.05"], ["83825.2", "0.049543"], ["83824.6", "0"], ["83824.5", "0"], ["83824", "0"], ["83823.6", "0.208037"], ["83821.1", "0.126044"], ["83809", "8.337494"], ["83806.4", "0.0016"], ["83791.4", "0.064"], ["83790.9", "0.118539"]], "a": [["83861.7", "0.38048"], ["83865.5", "0"], ["83865.6", "0"], ["83869.8", "0.214436"], ["83870.2", "0.077535"], ["83871.7", "0"], ["83873.4", "0"], ["83873.6", "0.000333"], ["83874.5", "0.057815"], ["83874.8", "0"], ["83877.1", "0.041333"], ["83878.8", "0.006189"], ["83879.1", "0"], ["83882.6", "0.178821"], ["83886.1", "0"], ["83888", "0.00009"], ["83888.5", "0"], ["83891.6", "0.14888"], ["83893.1", "0"], ["83902.2", "0.544087"], ["83902.3", "0.602988"], ["83905.8", "2.561768"], ["83908.5", "0.00596"], ["83923.5", "0"], ["83926", "0.357851"], ["83929.8", "0"], ["83931.3", "0.027762"], ["83934.6", "0.000526"], ["83934.7", "0.045457"], ["83934.8", "0.013105"]], "u": 174963, "seq": 67578163417}, "cts": 1742586300915, "record_time": 1742586301.008077, "EXCHANGE": "BYBIT"}
{"topic": "orderbook.200.BTCUSDT", "ts": 1742586301120, "type": "delta", "data": {"s": "BTCUSDT", "b": [["83861.6", "0.34244"], ["83856.3", "0.000153"], ["83856", "0.045392"], ["83853.2", "0.06"], ["83846.7", "0.073"], ["83845", "0.056"], ["83844.3", "0.207973"], ["83835.8", "0.178866"], ["83831", "0.140362"], ["83827.3", "0"], ["83827.2", "0"], ["83823.7", "0.357857"], ["83821.1", "0.126008"], ["83813.2", "0"], ["83809", "0"], ["83806.4", "8.340403"], ["83790.9", "0"]], "a": [["83862.7", "0.023051"], ["83862.8", "0.071579"], ["83872.7", "0.07498"], ["83873.9", "0"], ["83878.8", "0.046189"], ["83880.9", "0.178825"], ["83882.5", "0.170412"], ["83883.5", "0.04"], ["83883.6", "0.178866"], ["83884", "0"], ["83884.2", "0.10789"], ["83887.6", "0"], ["83891.6", "0.078003"], ["83900.9", "0.440033"], ["83903.8", "0"], ["83905.9", "0.051499"], ["83923.5", "0.357857"], ["83926", "0"], ["83932.2", "1.029403"], ["83934.6", "0"], ["83934.7", "0"], ["83934.8", "0"]], "u": 174964, "seq": 67578163565}, "cts": 1742586301115, "record_time": 1742586301.211719, "EXCHANGE": "BYBIT"}
{"topic": "orderbook.200.BTCUSDT", "ts": 1742586301319, "type": "delta", "data": {"s": "BTCUSDT", "b": [["83861.6", "0.275216"], ["83856.3", "0"], ["83855.4", "0.000153"], ["83852.3", "0.313578"], ["83850.1", "0.535746"], ["83849.5", "0.023999"], ["83847.3", "0.093385"], ["83839.4", "0.029784"], ["83838.6", "0"], ["83835.9", "0.194428"], ["83834.1", "0.005206"], ["83827.4", "0.192176"], ["83824.9", "0.125206"], ["83823.7", "0"], ["83821.6", "0.357863"], ["83821.1", "0"], ["83818.3", "0.126008"], ["83811.3", "0"]], "a": [["83861.8", "0.023051"], ["83861.9", "0.07158"], ["83862.7", "0"], ["83862.8", "0"], ["83868.6", "0.071574"], ["83870.2", "0.005962"], ["83881.1", "0.184827"], ["83883.6", "0"], ["83885.6", "0"], ["83887.8", "0.125206"], ["83888.3", "0.073115"], ["83903.4", "1.339817"], ["83904.3", "0"], ["83923.4", "0.357861"], ["83923.5", "0"], ["83932.3", "0"]], "u": 174965, "seq": 67578163747}, "cts": 1742586301316, "record_time": 1742586301.408261, "EXCHANGE": "BYBIT"}
{"topic": "orderbook.200.BTCUSDT", "ts": 1742586301520, "type": "delta", "data": {"s": "BTCUSDT", "b": [["83861.6", "0.294963"], ["83839.6", "0.195696"], ["83828.2", "0.039631"], ["83828.1", "0.039631"], ["83828", "0"], ["83827.9", "0"], ["83827.4", "0.133139"], ["83825.5", "0.357853"], ["83825.3", "0"], ["83825.2", "0"], ["83824.8", "0.05"], ["83824.7", "0.051009"], ["83823.6", "0.289402"], ["83821.6", "0"], ["83821.1", "0.126008"], ["83818.3", "0"], ["83817.5", "0.024108"]], "a": [["83861.8", "0"], ["83861.9", "0"], ["83863", "0.0014"], ["83863.6", "0.023051"], ["83863.7", "0.071579"], ["83868.6", "0"], ["83870.4", "0.071573"], ["83872.2", "0"], ["83879", "0.258279"], ["83887.7", "0.110704"], ["83888.3", "0"], ["83891.7", "0.0016"], ["83900.9", "0.438433"], ["83903.8", "0.04"], ["83903.9", "0.063846"], ["83905.3", "0.006945"], ["83905.8", "0"], ["83908.5", "2.567728"], ["83911.4", "0.000333"], ["83911.5", "0.000524"], ["83923.4", "0"], ["83926", "0.357855"], ["83932.2", "0"]], "u": 174966, "seq": 67578163882}, "cts": 1742586301513, "record_time": 1742586301.610358, "EXCHANGE": "BYBIT"}
{"topic": "orderbook.200.BTCUSDT", "ts": 1742586301720, "type": "delta", "data": {"s": "BTCUSDT", "b": [["83843.9", "0"], ["83839.6", "0.270335"], ["83838.3", "0.774989"], ["83827.5", "0.358178"], ["83827.4", "0.229736"], ["83825.9", "0.05"], ["83825.8", "0.049542"], ["83825.5", "0"], ["83824.8", "0"], ["83824.7", "0.001466"], ["83790.9", "0.118539"]], "a": [["83861.7", "0.20948"], ["83863.6", "0"], ["83863.7", "0"], ["83863.8", "0.02305"], ["83863.9", "0.071578"], ["83868.7", "0.072907"], ["83870.4", "0"], ["83874.1", "0"], ["83883.6", "0.178866"], ["83897.3", "0.035778"], ["83903.4", "0.584554"], ["83908.5", "0.00596"], ["83917", "2.561768"], ["83926", "0"], ["83926.9", "0.357845"], ["83931.6", "0"]], "u": 174967, "seq": 67578163999}, "cts": 1742586301717, "record_time": 1742586301.808264, "EXCHANGE": "BYBIT"}
{"topic": "orderbook.200.BTCUSDT", "ts": 1742586301919, "type": "delta", "data": {"s": "BTCUSDT", "b": [["83861.6", "0.465963"], ["83857.8", "0.089099"], ["83857.2", "0"], ["83855.5", "0.033856"], ["83855.4", "0"], ["83852.9", "0.019642"], ["83852.7", "0.01007"], ["83850.2", "0"], ["83850.1", "0.0003"], ["83847.6", "0.056"], ["83847.3", "0.142933"], ["83847.1", "0.120441"], ["83846.5", "0.178898"], ["83845.7", "0.089099"], ["83842.3", "0.056522"], ["83842.1", "0"], ["83841.9", "0"], ["83840.1", "0.171853"], ["83840", "0.00006"], ["83838.3", "0.596123"], ["83836.4", "0.535446"], ["83835.8", "0"], ["83833.4", "0"], ["83833.1", "0.302119"], ["83832.9", "0.024108"], ["83830.9", "0.260099"], ["83829.6", "0.025239"], ["83829.3", "0.359302"], ["83829.2", "0.00018"], ["83827.6", "0.246476"], ["83827.5", "0.000333"], ["83827.4", "0"], ["83826.6", "0.01288"], ["83826.5", "0.01288"], ["83826.4", "0.011924"], ["83826.3", "0"], ["83825.9", "0"], ["83825.8", "0"], ["83825.5", "0.022989"], ["83824.8", "0.049543"], ["83824.7", "0.051009"], ["83824", "0.126015"], ["83821.1", "0"], ["83818", "0"], ["83817.5", "0"], ["83816.6", "0"], ["83811.6", "0"], ["83809.2", "8.456075"], ["83806.4", "0.0016"], ["83790.9", "0"]], "a": [["83861.7", "0.133684"], ["83863", "0"], ["83863.8", "0"], ["83863.9", "0"], ["83866.2", "0"], ["83868.7", "0.001333"], ["83868.8", "0"], ["83872.7", "0.003409"], ["83873.7", "0"], ["83874.6", "0.000524"], ["83877.9", "0.071566"], ["83878.3", "0.04"], ["83878.8", "0.04"], ["83879.5", "0"], ["83880", "0.204923"], ["83880.4", "0"], ["83880.9", "0"], ["83881.1", "0"], ["83882.2", "0.049225"], ["83882.6", "0"], ["83883.6", "0"], ["83883.7", "0"], ["83884.2", "0"], ["83886.3", "0.019816"], ["83886.9", "0"], ["83887", "0.167869"], ["83889.8", "0.603486"], ["83889.9", "0.601131"], ["83891.6", "0.048195"], ["83893.9", "0.001333"], ["83894", "0.283147"], ["83897.3", "0"], ["83900.5", "0.005961"], ["83902", "0.118539"], ["83902.2", "0"], ["83902.3", "0.001857"], ["83903.8", "0"], ["83903.9", "0.023846"], ["83905.5", "0.04"], ["83905.6", "0.04"], ["83905.9", "0"], ["83909.5", "0.029485"], ["83913.5", "0"], ["83914.4", "0.051499"], ["83917", "0"], ["83926.9", "0"], ["83929.1", "0.357836"], ["83931.6", "0.001333"], ["83932.3", "0.000333"], ["83934.6", "0.000526"], ["83934.7", "0.045457"], ["83934.8", "0.013105"], ["83934.9", "0.0006"], ["83935.3", "0.120039"], ["83935.4", "0.013466"], ["83935.7", "0.04"], ["83935.8", "0.001333"], ["83936.5", "0.000333"], ["83938.4", "0.00009"], ["83938.9", "2.567089"]], "u": 174968, "seq": 67578164575}, "cts": 1742586301917, "record_time": 1742586302.008371, "EXCHANGE": "BYBIT"}
{"topic": "orderbook.200.BTCUSDT", "ts": 1742586302120, "type": "delta", "data": {"s": "BTCUSDT", "b": [["83868.6", "2.270073"], ["83867.6", "0.066677"], ["83867.5", "0.222561"], ["83865.2", "0.147785"], ["83865.1", "0.05"], ["83863.4", "0.005327"], ["83861.6", "0.242166"], ["83861.4", "0.078334"], ["83861.3", "0.033856"], ["83858.6", "0.027048"], ["83858.1", "0"], ["83857.4", "0.048"], ["83857.2", "0.06409"], ["83856.8", "0.119392"], ["83856.7", "0.06"], ["83856", "0"], ["83855.6", "0.084"], ["83855.5", "0"], ["83855.1", "0"], ["83854.5", "0.176336"], ["83854.4", "0.040575"], ["83854.1", "0.535446"], ["83853.9", "0.06"], ["83853.6", "0.06"], ["83853.2", "0"], ["83852.8", "0.178885"], ["83852.4", "0"], ["83852.3", "0.339475"], ["83852.2", "0.056"], ["83850.9", "0.178889"], ["83850.5", "0.052"], ["83849.8", "0"], ["83849.2", "0.598129"], ["83849", "0.048"], ["83848.8", "0.033946"], ["83847.5", "0.054263"], ["83847.3", "0.127667"], ["83847.1", "0"], ["83846.5", "0"], ["83845.8", "0.059399"], ["83844.3", "0.098082"], ["83844.2", "0.11156"], ["83843.8", "0"], ["83843.7", "0.003576"], ["83842.7", "0.04872"], ["83842.3", "0.000522"], ["83841.8", "0.178851"], ["83840.5", "0.117446"], ["83840.2", "0.357794"], ["83840.1", "0.000333"], ["83839.6", "0.421639"], ["83839.4", "0.02518"], ["83838.3", "0"], ["83837.6", "0.198851"], ["83836.4", "0"], ["83833.6", "0.317939"], ["83833.1", "0.02437"], ["83829.6", "0.126015"], ["83829.3", "0.001466"], ["83827.6", "0"], ["83826.7", "0.147518"], ["83825.5", "0"], ["83825.4", "0.059399"], ["83824", "0"], ["83823.6", "0.208037"], ["83821", "0.000149"], ["83816.6", "0.089426"], ["83815.2", "0.00009"], ["83809.5", "0"], ["83809.2", "0"], ["83804.5", "0.059622"], ["83800", "1.391746"], ["83797", "0"], ["83796.3", "0"], ["83796.2", "0"], ["83795.7", "0"], ["83795.6", "0"], ["83794.8", "0"], ["83794", "0"], ["83793.6", "0"], ["83793.3", "0"], ["83792.8", "0"], ["83792.7", "0"], ["83792.4", "0"], ["83792.2", "0"], ["83791.6", "0"], ["83791.4", "0"]], "a": [["83861.7", "0"], ["83865.2", "0"], ["83866.1", "0"], ["83867.4", "0"], ["83867.6", "0"], ["83868.2", "0"], ["83868.7", "0.057432"], ["83869.2", "0"], ["83869.8", "0"], ["83870", "0.000524"], ["83870.1", "0"], ["83870.9", "0"], ["83871.2", "0"], ["83872.4", "0"], ["83874.5", "0"], ["83875", "0"], ["83875.5", "0"], ["83876.7", "0.047803"], ["83876.8", "0.097677"], ["83877.1", "0.061333"], ["83877.3", "0"], ["83877.9", "0.00528"], ["83879", "0.068127"], ["83880", "0.060865"], ["83882.2", "0"], ["83882.4", "0.04"], ["83882.5", "0.071044"], ["83885.7", "0.07156"], ["83886.1", "0.033856"], ["83887", "0"], ["83887.7", "0.440431"], ["83887.8", "0"], ["83888.7", "0.111559"], ["83889.1", "0.009225"], ["83889.5", "0.056197"], ["83889.8", "0.059399"], ["83889.9", "0"], ["83890", "0.009227"], ["83891.6", "0.082125"], ["83894", "0"], ["83895.6", "0"], ["83896.5", "0.061154"], ["83900.9", "0.116363"], ["83901", "0.171"], ["83902", "0"], ["83902.9", "0.546487"], ["83903", "0.601464"], ["83903.5", "0.117779"], ["83904.4", "0"], ["83905.5", "0"], ["83905.6", "0"], ["83908.3", "0"], ["83909.5", "0.005457"], ["83909.6", "0.04"], ["83909.7", "0.063846"], ["83912.1", "0.108748"], ["83914.4", "0"], ["83915.2", "0.04"], ["83915.4", "0.022341"], ["83917.2", "0.051499"], ["83917.8", "0.171358"], ["83918.6", "0.08"], ["83920.3", "0.04"], ["83921.9", "0.04"], ["83929.1", "0"], ["83929.3", "0.118684"], ["83930.8", "0.005041"], ["83931.3", "0"], ["83934.6", "0.171526"], ["83938.8", "0.357791"], ["83938.9", "0.005457"], ["83939.2", "0.000526"], ["83940", "0.002799"], ["83940.4", "0.177938"], ["83940.7", "0.000333"], ["83941.8", "1.788424"], ["83942.4", "0.203426"], ["83942.7", "0.354209"], ["83943.1", "0.005457"], ["83943.8", "0.000526"], ["83943.9", "1.029259"], ["83944.2", "0.001333"], ["83944.4", "0.003575"], ["83944.5", "2.561632"]], "u": 174969, "seq": 67578165285}, "cts": 1742586302117, "record_time": 1742586302.209222, "EXCHANGE": "BYBIT"}
{"topic": "orderbook.200.BTCUSDT", "ts": 1742586302320, "type": "delta", "data": {"s": "BTCUSDT", "b": [["83868.6", "2.270873"], ["83866.9", "0.033856"], ["83865.2", "0.100261"], ["83865", "0.006761"], ["83862.6", "0.004108"], ["83862.1", "0.027047"], ["83861.6", "0.235405"], ["83861.3", "0"], ["83861.1", "0.011195"], ["83859.4", "0.0264"], ["83858.6", "0"], ["83857.9", "0.040573"], ["83856.8", "0.309264"], ["83855.6", "0.148"], ["83854.5", "0.118539"], ["83854.4", "0"], ["83852.7", "0.06607"], ["83852.3", "0.395475"], ["83851.2", "0.004688"], ["83849.2", "0.777022"], ["83849", "0"], ["83848.9", "0"], ["83848.4", "0"], ["83847.6", "0"], ["83847.5", "0"], ["83847.2", "0"], ["83845.9", "0.178851"], ["83845.5", "0"], ["83845", "0"], ["83843.7", "0"], ["83842.2", "0"], ["83840.5", "0"], ["83840.2", "0"], ["83839.6", "0"], ["83839.4", "0.001333"], ["83837", "0.013784"], ["83836.4", "0.025239"], ["83836", "0.357802"], ["83829.6", "0"], ["83828.3", "0.065"], ["83828.2", "0.089178"], ["83826.8", "0.127348"], ["83826.7", "0"], ["83825.3", "0.09663"], ["83824.8", "0"], ["83824.7", "0.001466"], ["83814.7", "0.083246"], ["83810.6", "0.178975"], ["83797", "0.001466"], ["83796.3", "0.005769"], ["83796.2", "0.00052"], ["83795.7", "0.02016"], ["83795.6", "0.089433"], ["83794.8", "0.013127"]], "a": [["83868.7", "0.087472"], ["83872.3", "0.005256"], ["83874.1", "0.07157"], ["83875.2", "0.021024"], ["83876.2", "0.0528"], ["83876.6", "0.000297"], ["83876.7", "0.076457"], ["83876.8", "0.02611"], ["83877", "0.13926"], ["83877.9", "0.04774"], ["83878.8", "0"], ["83879", "0.102541"], ["83879.4", "0.031535"], ["83880", "0.001466"], ["83881.4", "0.071563"], ["83882.1", "0.04"], ["83883", "0.072231"], ["83885.7", "0"], ["83886.1", "0"], ["83887.2", "0.04"], ["83887.7", "0.110704"], ["83887.9", "0.003759"], ["83889.5", "0"], ["83891.2", "0.178851"], ["83891.6", "0"], ["83891.7", "0.035456"], ["83896.5", "0"], ["83899.2", "0.059399"], ["83900.9", "0.388875"], ["83903.4", "0"], ["83903.5", "0"], ["83904.2", "0.035775"], ["83908.8", "0.129747"], ["83909.6", "0"], ["83909.7", "0.023846"], ["83909.8", "0.04"], ["83909.9", "0.04"], ["83914.4", "0.051499"], ["83917.2", "0"], ["83920.5", "0.013704"], ["83927.9", "2.56145"], ["83929.8", "0.125196"], ["83932.8", "0.033856"], ["83934.5", "0.357802"], ["83938.8", "0"], ["83940.7", "0"], ["83941.8", "0"], ["83942.4", "0"], ["83942.7", "0"], ["83943.1", "0"], ["83943.8", "0"], ["83943.9", "0"], ["83944.2", "0"], ["83944.4", "0"], ["83944.5", "0"]], "u": 174970, "seq": 67578165596}, "cts": 1742586302316, "record_time": 1742586302.408892, "EXCHANGE": "BYBIT"}
{"topic": "orderbook.200.BTCUSDT", "ts": 1742586302519, "type": "delta", "data": {"s": "BTCUSDT", "b": [["83869.3", "0.659721"], ["83868.7", "0.025625"], ["83868.6", "0.221153"], ["83867.6", "0"], ["83867.5", "0.051561"], ["83864.5", "0.001333"], ["83857.8", "0"], ["83846.7", "0.009"], ["83844.2", "0.135407"], ["83839.6", "0.530584"], ["83836.1", "0.307559"], ["83836", "0"], ["83835.9", "0.000333"], ["83832.7", "0.13142"], ["83832.6", "0.012881"], ["83831.9", "0.023985"], ["83830.8", "0.05"], ["83830.7", "0.061475"], ["83829.6", "0.126028"], ["83828.3", "0.015"], ["83828.2", "0.039631"], ["83827.2", "0.171769"], ["83826.8", "0.001333"], ["83826.6", "0"], ["83826.5", "0"], ["83823", "8.456075"], ["83796.3", "0"], ["83796.2", "0"], ["83795.7", "0"], ["83795.6", "0"], ["83794.8", "0"]], "a": [["83868.7", "0"], ["83869.4", "0.030371"], ["83869.7", "0.009705"], ["83870.2", "0"], ["83874.1", "0"], ["83875.1", "0.000297"], ["83876.6", "0"], ["83876.7", "0"], ["83876.8", "0"], ["83877.1", "0.001333"], ["83877.2", "0.005962"], ["83877.8", "0.060333"], ["83880.5", "0.04"], ["83883", "0.000669"], ["83883.5", "0.066108"], ["83885.4", "0.07156"], ["83891.1", "0.067018"], ["83892.7", "0.003"], ["83896.9", "0"], ["83897.6", "0.023847"], ["83898.9", "0.024974"], ["83903.8", "0.031569"], ["83904.2", "0"], ["83905.5", "0.035775"], ["83909.8", "0"], ["83909.9", "0"], ["83910.9", "0.04"], ["83911", "0.04"], ["83914.4", "0.051493"], ["83915.8", "0.054668"], ["83919.7", "2.56145"], ["83927.9", "0"], ["83934.5", "0"], ["83940", "0"], ["83940.4", "0"]], "u": 174971, "seq": 67578165864}, "cts": 1742586302517, "record_time": 1742586302.630661, "EXCHANGE": "BYBIT"}
{"topic": "orderbook.200.BTCUSDT", "ts": 1742586302719, "type": "delta", "data": {"s": "BTCUSDT", "b": [["83869.3", "0.577751"], ["83868.7", "0.088722"], ["83868.6", "0.221"], ["83858.5", "0.06"], ["83854.4", "0.178881"], ["83852.8", "0"], ["83852.7", "0.244955"], ["83850.9", "0"], ["83849.2", "0.598129"], ["83848.4", "0.17885"], ["83845.9", "0"], ["83839.7", "0.334108"], ["83839.6", "0"], ["83836.2", "0.357806"], ["83836.1", "0.003575"], ["83835.7", "0"], ["83834.1", "0.175045"], ["83833", "0.013"], ["83832.9", "0.012881"], ["83832.7", "0.118539"], ["83832.6", "0"], ["83832.1", "0.05"], ["83832", "0.08349"], ["83830.8", "0"], ["83830.7", "0.01193"], ["83829.6", "0.126015"], ["83827.2", "0"], ["83823", "0"], ["83821.7", "0.024108"], ["83820.2", "8.456075"], ["83796.3", "0.005769"]], "a": [["83869.4", "0.078289"], ["83872.8", "0"], ["83874.1", "0.07157"], ["83876.1", "0.092228"], ["83879", "0.143709"], ["83879.8", "0.071565"], ["83882.5", "0.045051"], ["83883.8", "0.040524"], ["83885.4", "0"], ["83899.2", "0.093255"], ["83905.5", "0.030371"], ["83910.9", "0"], ["83911", "0"], ["83911.2", "0.04"], ["83911.3", "0.04"], ["83913.1", "0.296187"], ["83914.4", "0.051492"], ["83917.2", "0.17885"], ["83919.6", "2.56145"], ["83919.7", "0"], ["83932.8", "0"], ["83934.5", "0.357805"], ["83938.9", "0"], ["83939.2", "0"]], "u": 174972, "seq": 67578166037}, "cts": 1742586302716, "record_time": 1742586302.808292, "EXCHANGE": "BYBIT"}
{"topic": "orderbook.200.BTCUSDT", "ts": 1742586302920, "type": "delta", "data": {"s": "BTCUSDT", "b": [["83869.3", "0.292664"], ["83868.7", "0"], ["83868.6", "0"], ["83867.5", "0.001561"], ["83866.9", "0"], ["83865.1", "0.02"], ["83862.4", "0.022843"], ["83861", "0.034189"], ["83860.9", "0.06"], ["83856.7", "0"], ["83855.3", "0.17888"], ["83853.6", "0"], ["83848.5", "0.121114"], ["83847.3", "0"], ["83845.7", "0"], ["83836.4", "0"], ["83836.2", "0"], ["83834.2", "0.013"], ["83834.1", "0.187925"], ["83833.4", "0.17885"], ["83833", "0"], ["83832.9", "0"], ["83832.3", "0.05"], ["83832.2", "0.407366"], ["83832.1", "0"], ["83832", "0.033946"], ["83824.1", "0.025239"], ["83821.7", "0"], ["83820.2", "0"], ["83817.5", "8.456075"], ["83796.3", "0.176769"], ["83796.2", "0.00052"], ["83795.7", "0.02016"], ["83795.6", "0.089433"], ["83794.8", "0.013127"], ["83794", "0.000333"]], "a": [["83869.4", "0.332063"], ["83874.1", "0"], ["83875.1", "0"], ["83875.5", "0.071569"], ["83878.2", "0.071566"], ["83879.8", "0"], ["83881.4", "0"], ["83882.5", "0.069409"], ["83885.8", "0.033856"], ["83887.5", "0.006381"], ["83887.9", "0.182609"], ["83888", "0.1789"], ["83889.6", "0.178806"], ["83891.2", "0"], ["83891.7", "0.0016"], ["83892.1", "0.17885"], ["83912.1", "0.174954"], ["83913.1", "0.117337"], ["83914.4", "0.051493"], ["83917.2", "0"]], "u": 174973, "seq": 67578166167}, "cts": 1742586302907, "record_time": 1742586303.00887, "EXCHANGE": "BYBIT"}
{"topic": "orderbook.200.BTCUSDT", "ts": 1742586303119, "type": "delta", "data": {"s": "BTCUSDT", "b": [["83869.3", "0.292817"], ["83867.5", "0.001256"], ["83855.1", "0.035775"], ["83846.9", "0.000522"], ["83845.9", "0.17885"], ["83839.7", "0.167361"], ["83835.8", "0.039631"], ["83835.7", "0.039631"], ["83834.2", "0.01288"], ["83833.7", "0.35782"], ["83833.4", "0"], ["83832.3", "0.049543"], ["83832.2", "0.049543"], ["83829.6", "0.126023"], ["83828.2", "0"], ["83828.1", "0"], ["83820.2", "8.655286"], ["83817.5", "0"], ["83794.8", "0"], ["83794", "0"]], "a": [["83869.4", "0.260489"], ["83870", "0.006137"], ["83872.7", "0.002199"], ["83875.5", "0"], ["83880.4", "0.071564"], ["83887.7", "0.260375"], ["83887.9", "0.003759"], ["83891.2", "0.17885"], ["83892.1", "0"], ["83910.8", "0.04"], ["83910.9", "0.04"], ["83911.2", "0"], ["83911.3", "0"]], "u": 174974, "seq": 67578166245}, "cts": 1742586303111, "record_time": 1742586303.208531, "EXCHANGE": "BYBIT"}
{"topic": "orderbook.200.BTCUSDT", "ts": 1742586303320, "type": "delta", "data": {"s": "BTCUSDT", "b": [["83869.3", "0.463817"], ["83854.4", "0"], ["83852.7", "0.06607"], ["83834.8", "0.357817"], ["83834.1", "0.288806"], ["83833.7", "0"], ["83820.2", "0"], ["83817.5", "8.655286"], ["83806", "0.027636"]], "a": [["83869.4", "0.089489"], ["83874.4", "0.071569"], ["83878.2", "0"], ["83882.5", "0.140971"], ["83897.5", "0.043381"], ["83898.9", "0"], ["83908.9", "0.17885"], ["83938.4", "0"]], "u": 174975, "seq": 67578166308}, "cts": 1742586303313, "record_time": 1742586303.420536, "EXCHANGE": "BYBIT"}
{"topic": "orderbook.200.BTCUSDT", "ts": 1742586303520, "type": "delta", "data": {"s": "BTCUSDT", "b": [["83869.3", "0.307722"], ["83853", "0.178884"], ["83851.6", "0.178887"], ["83845.9", "0"], ["83835.9", "0.398145"], ["83835.7", "0"], ["83834.9", "0.319058"], ["83834.8", "0"], ["83834.3", "0.013"], ["83834.1", "0.005206"], ["83832.4", "0.05"], ["83832.2", "0"], ["83795.6", "0"]], "a": [["83869.4", "0.275395"], ["83872.4", "0.071571"], ["83874.1", "0.002"], ["83874.4", "0"], ["83878.6", "0.071566"], ["83880.4", "0"], ["83891.7", "0"], ["83902.8", "0.0016"], ["83904.7", "0.17885"], ["83908.7", "0.225658"], ["83919.6", "2.561497"], ["83935.8", "0"], ["83936.5", "0"]], "u": 174976, "seq": 67578166399}, "cts": 1742586303516, "record_time": 1742586303.608791, "EXCHANGE": "BYBIT"}
{"topic": "orderbook.200.BTCUSDT", "ts": 1742586303719, "type": "delta", "data": {"s": "BTCUSDT", "b": [["83869.3", "0.478885"], ["83848.5", "0.000333"], ["83836", "0.699899"], ["83835.9", "0.000333"], ["83835.8", "0"], ["83835.7", "0.04"], ["83835.6", "0.039631"], ["83834.9", "0"], ["83834.3", "0"], ["83834.2", "0"], ["83834.1", "0.018206"], ["83834", "0.03288"], ["83795.6", "0.089433"]], "a": [["83869.4", "0.104395"], ["83872.4", "0"], ["83874.9", "0.071569"], ["83878.6", "0"], ["83880.7", "0.071564"], ["83893.5", "0.000858"], ["83910.8", "0"], ["83910.9", "0"], ["83911.2", "0.04"], ["83911.3", "0.04"], ["83916.8", "2.561497"], ["83919.6", "0"], ["83921.4", "0.089425"], ["83935.4", "0"], ["83935.7", "0"]], "u": 174977, "seq": 67578166481}, "cts": 1742586303716, "record_time": 1742586303.808293, "EXCHANGE": "BYBIT"}
{"topic": "orderbook.200.BTCUSDT", "ts": 1742586303920, "type": "delta", "data": {"s": "BTCUSDT", "b": [["83869.3", "0.307885"], ["83865.1", "0"], ["83836", "0"], ["83835.7", "0"], ["83835.5", "0.039631"], ["83834.1", "0.005206"], ["83833.9", "0.014346"], ["83833.7", "0.357817"], ["83832.4", "0"], ["83832.3", "0"], ["83832.2", "0.05"], ["83832.1", "0.049543"], ["83829.6", "0.126008"], ["83794.8", "0.013127"]], "a": [["83869.4", "0.275395"], ["83874.9", "0"], ["83877.1", "0.0729"], ["83878.8", "0.071566"], ["83880", "0.060865"], ["83880.7", "0"], ["83882.5", "0.099189"], ["83893.5", "0"], ["83904.7", "0"], ["83908.9", "0"], ["83911.2", "0"], ["83911.4", "0.040333"], ["83916.8", "0"], ["83919.6", "2.561497"], ["83921.4", "0"], ["83935.4", "0.013466"], ["83935.7", "0.04"], ["83935.8", "0.001333"], ["83936.5", "0.000333"], ["83938.4", "0.00009"], ["83938.9", "0.005457"]], "u": 174978, "seq": 67578166611}, "cts": 1742586303903, "record_time": 1742586304.008553, "EXCHANGE": "BYBIT"}
{"topic": "orderbook.200.BTCUSDT", "ts": 1742586304119, "type": "delta", "data": {"s": "BTCUSDT", "b": [["83834.3", "0.01288"], ["83834.2", "0.01288"], ["83834", "0.02"], ["83833.9", "0.001466"], ["83833.7", "0.357822"], ["83832.4", "0.049543"], ["83832.3", "0.049543"], ["83832.2", "0"], ["83832.1", "0"], ["83795.6", "0"], ["83794.8", "0"]], "a": [["83870", "0.07771"], ["83876.9", "0.071567"], ["83877.1", "0.001333"], ["83887.9", "0.182609"], ["83888.7", "0.290409"], ["83891.2", "0"], ["83892.1", "0.17885"], ["83911.2", "1.430085"], ["83916.8", "2.561497"], ["83919.6", "0"], ["83938.4", "0"], ["83938.9", "0"]], "u": 174979, "seq": 67578166678}, "cts": 1742586304101, "record_time": 1742586304.20853, "EXCHANGE": "BYBIT"}
{"topic": "orderbook.200.BTCUSDT", "ts": 1742586304320, "type": "delta", "data": {"s": "BTCUSDT", "b": [["83869.3", "0.308685"], ["83868.6", "0.000153"], ["83862.4", "0.028843"], ["83856.5", "0.108768"], ["83846.7", "0.174627"], ["83845.9", "0.17885"], ["83837.6", "0.493437"], ["83835.9", "0.040333"], ["83835.8", "0.039631"], ["83835.6", "0"], ["83835.5", "0"], ["83833.7", "0"], ["83833.4", "0.17885"], ["83832.5", "0.357825"], ["83796.3", "0"], ["83796.2", "0"], ["83795.7", "0"]], "a": [["83869.4", "0.282157"], ["83881.7", "0.160445"], ["83891.5", "0.182158"], ["83893.6", "0.000942"], ["83900.5", "0.095386"], ["83900.6", "0.273919"], ["83910.8", "0.04"], ["83910.9", "0.04"], ["83911.3", "0"], ["83911.4", "0.000333"], ["83911.5", "0.052017"], ["83914.4", "0"], ["83916.8", "0"], ["83919.6", "2.561497"], ["83919.7", "0.023665"], ["83921.4", "0.089425"], ["83935.3", "0"], ["83935.4", "0"], ["83935.7", "0"], ["83935.8", "0"], ["83936.5", "0"]], "u": 174980, "seq": 67578166760}, "cts": 1742586304316, "record_time": 1742586304.408344, "EXCHANGE": "BYBIT"}
{"topic": "orderbook.200.BTCUSDT", "ts": 1742586304519, "type": "delta", "data": {"s": "BTCUSDT", "b": [["83868.6", "0"], ["83868.4", "0.000153"], ["83861.6", "0.215405"], ["83856.5", "0"], ["83846.7", "0.009"], ["83837.6", "0.198851"], ["83836", "0.04"], ["83835.9", "0.039964"], ["83835.8", "0"], ["83834.4", "0.013"], ["83834.2", "0"], ["83832.5", "0.05"], ["83832.3", "0"], ["83829.7", "0.357829"], ["83829.6", "0.126011"], ["83796.3", "0.005769"]], "a": [["83869.9", "0.02809"], ["83881.7", "0.04"], ["83891.5", "0"], ["83892.7", "0"], ["83893.6", "0.00095"], ["83900.6", "0"], ["83910.7", "0.041333"], ["83910.9", "0"], ["83912.1", "0.108748"], ["83914", "2.561497"], ["83919.6", "0"], ["83929.7", "0.357833"], ["83934.5", "0"], ["83935.3", "0.120039"], ["83935.4", "0.013466"], ["83935.7", "0.04"]], "u": 174981, "seq": 67578166846}, "cts": 1742586304516, "record_time": 1742586304.608159, "EXCHANGE": "BYBIT"}
{"topic": "orderbook.200.BTCUSDT", "ts": 1742586304720, "type": "delta", "data": {"s": "BTCUSDT", "b": [["83869.3", "0.314685"], ["83868.4", "0"], ["83856.6", "0.110213"], ["83846.8", "0.186858"], ["83837.7", "0.303524"], ["83836", "0"], ["83835.8", "0.039631"], ["83834.4", "0"], ["83834.2", "0.01288"], ["83834.1", "0.243602"], ["83832.5", "0"], ["83832.3", "0.049543"], ["83829.7", "0"], ["83827.2", "0.357836"], ["83805.1", "0"], ["83804.4", "0.240615"], ["83796.3", "0"]], "a": [["83869.4", "0.293269"], ["83869.9", "0"], ["83870", "0.006137"], ["83871.2", "0.025809"], ["83871.3", "0.071572"], ["83880", "0.001466"], ["83881.8", "0.117314"], ["83891.6", "0.174735"], ["83893.6", "0"], ["83900.7", "0.307291"], ["83908.7", "0.607842"], ["83929.1", "0.357836"], ["83929.7", "0"], ["83935.3", "0"], ["83935.4", "0"], ["83935.7", "0"]], "u": 174982, "seq": 67578166925}, "cts": 1742586304710, "record_time": 1742586304.808011, "EXCHANGE": "BYBIT"}
{"topic": "orderbook.200.BTCUSDT", "ts": 1742586304920, "type": "delta", "data": {"s": "BTCUSDT", "b": [["83869.3", "0.486469"], ["83869", "0.000153"], ["83861.4", "0.133274"], ["83856.6", "0"], ["83846.8", "0"], ["83845.9", "0"], ["83837.7", "0.000522"], ["83835.9", "0.000333"], ["83835.8", "0"], ["83835.6", "0.039631"], ["83835.5", "0.039631"], ["83834.8", "0.357816"], ["83834.3", "0"], ["83834.2", "0"], ["83834", "0.03288"], ["83833.9", "0.014346"], ["83833.4", "0"], ["83832.4", "0"], ["83832.3", "0"], ["83832.1", "0.049543"], ["83832", "0.08349"], ["83829.6", "0.126017"], ["83827.2", "0"], ["83819.1", "0.024441"], ["83796.3", "0.005769"], ["83796.2", "0.00052"], ["83795.7", "0.02016"], ["83795.6", "0.089433"], ["83794.8", "0.013127"]], "a": [["83869.4", "0.093195"], ["83871.2", "0"], ["83871.3", "0"], ["83874.5", "0.071569"], ["83876.9", "0"], ["83878.8", "0"], ["83881.6", "0.071563"], ["83881.8", "0"], ["83883.7", "0.071562"], ["83887.9", "0.003759"], ["83888.7", "0.111559"], ["83891.2", "0.17885"], ["83891.6", "0"], ["83892.1", "0"], ["83893.8", "0.002645"], ["83900.5", "0.005961"], ["83900.7", "0"], ["83910.7", "0.001333"], ["83910.8", "0"], ["83911.3", "0.04"], ["83911.4", "0.040333"], ["83914", "0"], ["83919.6", "2.561497"], ["83921.4", "0"], ["83929.1", "0"], ["83934.5", "0.35783"], ["83935.3", "0.120039"], ["83935.4", "0.013466"], ["83935.7", "0.04"], ["83935.8", "0.001333"], ["83936.5", "0.000333"]], "u": 174983, "seq": 67578167047}, "cts": 1742586304914, "record_time": 1742586305.008868, "EXCHANGE": "BYBIT"}
{"topic": "orderbook.200.BTCUSDT", "ts": 1742586305120, "type": "delta", "data": {"s": "BTCUSDT", "b": [["83869.3", "0.315469"], ["83869", "0"], ["83845.9", "0.17885"], ["83837.7", "0.358325"], ["83835.9", "0.040333"], ["83835.8", "0.039631"], ["83835.6", "0"], ["83835.5", "0"], ["83834.8", "0"], ["83834.3", "0.013"], ["83834.2", "0.01288"], ["83834", "0.02"], ["83833.9", "0.001466"], ["83832.4", "0.05"], ["83832.3", "0.049543"], ["83832.1", "0"], ["83832", "0.033946"], ["83796.3", "0.176769"], ["83794.8", "0"]], "a": [["83869.4", "0.264195"], ["83874.5", "0"], ["83879.9", "0.071565"], ["83881.6", "0"], ["83882.1", "0.111563"], ["83883.7", "0"], ["83893.7", "0.17885"], ["83893.8", "0.001466"], ["83910.8", "0.04"], ["83910.9", "0.04"], ["83911.3", "0"], ["83911.4", "0.000333"], ["83921.4", "0.17885"], ["83925.6", "0.17885"], ["83934.5", "0"], ["83936.5", "0"]], "u": 174984, "seq": 67578167175}, "cts": 1742586305115, "record_time": 1742586305.208414, "EXCHANGE": "BYBIT"}
{"topic": "orderbook.200.BTCUSDT", "ts": 1742586305319, "type": "delta", "data": {"s": "BTCUSDT", "b": [["83869.3", "0.308588"], ["83868.7", "0.021849"], ["83868.6", "0.071574"], ["83865", "0.078338"], ["83845.9", "0"], ["83837.7", "0.000522"], ["83836.2", "0.04"], ["83836.1", "0.043206"], ["83836", "0.357812"], ["83835.9", "0.000333"], ["83835.8", "0"], ["83834.6", "0.013"], ["83834.5", "0.01288"], ["83834.3", "0"], ["83834.2", "0"], ["83832.7", "0.168539"], ["83832.6", "0.049543"], ["83832.4", "0"], ["83832.3", "0"], ["83795.6", "0"]], "a": [["83869.4", "0.093195"], ["83875.1", "0.071569"], ["83879.9", "0"], ["83880.5", "0.111564"], ["83882.1", "0.04"], ["83884.3", "0.072161"], ["83891.1", "0.101658"], ["83893.7", "0"], ["83900.5", "0.184811"], ["83904.7", "0.17885"], ["83910.1", "0.04"], ["83910.2", "0.04"], ["83910.8", "0"], ["83910.9", "0"], ["83914", "0.317634"], ["83916.8", "2.561497"], ["83919.6", "0"], ["83921.4", "0.089425"], ["83925.6", "0"], ["83935.2", "0.357811"], ["83935.8", "0"]], "u": 174985, "seq": 67578167314}, "cts": 1742586305315, "record_time": 1742586305.408588, "EXCHANGE": "BYBIT"}
{"topic": "orderbook.200.BTCUSDT", "ts": 1742586305520, "type": "delta", "data": {"s": "BTCUSDT", "b": [["83863.2", "0.071579"], ["83861.1", "0.01056"], ["83836.2", "0"], ["83836", "0.039631"], ["83834.8", "0.357815"], ["83834.6", "0"], ["83834.4", "0.01288"], ["83832.7", "0.118539"], ["83832.5", "0.049543"], ["83819.1", "0.000333"], ["83796.2", "0"], ["83795.7", "0"]], "a": [["83869.4", "0.264195"], ["83872.6", "0.071571"], ["83875.1", "0"], ["83878.6", "0.071566"], ["83884.3", "0.0006"], ["83891.1", "0.067018"], ["83910.1", "0"], ["83910.3", "0.04"], ["83934.5", "0.357815"], ["83935.2", "0"], ["83935.7", "0"]], "u": 174986, "seq": 67578167397}, "cts": 1742586305516, "record_time": 1742586305.608309, "EXCHANGE": "BYBIT"}
{"topic": "orderbook.200.BTCUSDT", "ts": 1742586305719, "type": "delta", "data": {"s": "BTCUSDT", "b": [["83855.1", "0"], ["83836.2", "0.357813"], ["83834.8", "0"], ["83834.6", "0.013"], ["83834.4", "0"], ["83832.7", "0.168539"], ["83832.5", "0"], ["83829.6", "0.252034"], ["83796.2", "0.00052"], ["83795.7", "0.02016"]], "a": [["83869.4", "0.283257"], ["83900.5", "0.005961"], ["83904.7", "0"], ["83916.8", "0"], ["83919.6", "2.561497"], ["83934.4", "0.357818"], ["83934.5", "0"], ["83935.7", "0.04"]], "u": 174987, "seq": 67578167429}, "cts": 1742586305717, "record_time": 1742586305.808245, "EXCHANGE": "BYBIT"}
{"topic": "orderbook.200.BTCUSDT", "ts": 1742586305920, "type": "delta", "data": {"s": "BTCUSDT", "b": [["83869.3", "0.294288"], ["83862.3", "0.000999"], ["83855", "0.04101"], ["83845.9", "0.17885"], ["83839.7", "0.254053"], ["83836.2", "0"], ["83832.8", "0.357822"], ["83829.6", "0.126014"], ["83796.2", "0"], ["83795.7", "0"]], "a": [["83869.4", "0.325369"], ["83871.1", "0.025809"], ["83871.2", "0.071572"], ["83872.6", "0"], ["83876.7", "0.071567"], ["83878.6", "0"], ["83891.2", "0"], ["83892.1", "0.17885"], ["83916.8", "2.561497"], ["83919.6", "0"], ["83934.3", "0.357821"], ["83934.4", "0"], ["83935.7", "0"]], "u": 174988, "seq": 67578167525}, "cts": 1742586305917, "record_time": 1742586306.008771, "EXCHANGE": "BYBIT"}
{"topic": "orderbook.200.BTCUSDT", "ts": 1742586306120, "type": "delta", "data": {"s": "BTCUSDT", "b": [["83861.4", "0.130274"], ["83839.7", "0.167361"], ["83834.6", "0"], ["83834.4", "0.01288"], ["83832.9", "0.357823"], ["83832.8", "0"], ["83802.6", "0.172062"], ["83796.3", "0"]], "a": [["83887.9", "0.182609"], ["83888.7", "0.290409"], ["83910.2", "0"], ["83910.3", "0"], ["83910.4", "0.040333"], ["83910.5", "0.04"], ["83934.2", "0.357824"], ["83934.3", "0"], ["83935.7", "0.04"]], "u": 174989, "seq": 67578167577}, "cts": 1742586306117, "record_time": 1742586306.208479, "EXCHANGE": "BYBIT"}
{"success": true, "ret_msg": "pong", "conn_id": "715e41eb-1d55-4682-b7f5-361425dd1be0", "op": "ping", "record_time": 1742586306.361475, "EXCHANGE": "BYBIT"}
{"topic": "orderbook.200.BTCUSDT", "ts": 1742586306320, "type": "delta", "data": {"s": "BTCUSDT", "b": [["83869.3", "0.465441"], ["83862.4", "0.031843"], ["83859.1", "0.112098"], ["83848.6", "0.168488"], ["83845.9", "0"], ["83841.6", "0.300562"], ["83837.7", "0.358328"], ["83836.1", "0.003575"], ["83836", "0"], ["83835.1", "0.0401"], ["83835", "0.039632"], ["83834.5", "0"], ["83834.4", "0"], ["83833.5", "0.013"], ["83833.4", "0.012881"], ["83832.9", "0"], ["83832.7", "0.118539"], ["83832.6", "0"], ["83831.6", "0.05"], ["83831.5", "0.049544"], ["83819.1", "0.024441"], ["83797.4", "0"], ["83797", "0"]], "a": [["83869.4", "0.093195"], ["83871.1", "0"], ["83871.2", "0"], ["83876.2", "0.124368"], ["83876.7", "0"], ["83880.5", "0.04"], ["83881.9", "0.071563"], ["83883.6", "0.114064"], ["83885.3", "0.07156"], ["83887.5", "0"], ["83887.9", "0.003759"], ["83888.4", "0.010967"], ["83888.7", "0.111559"], ["83891.2", "0.17885"], ["83892.1", "0"], ["83894.1", "0.170283"], ["83901.1", "0.296999"], ["83904.7", "0.17885"], ["83908.9", "0.17885"], ["83910.4", "0.000333"], ["83910.5", "0"], ["83912.2", "0.158539"], ["83912.3", "0.041466"], ["83916.8", "0"], ["83919.7", "0"], ["83921.4", "0"], ["83922.3", "2.561521"], ["83934.2", "0"], ["83935.8", "0.001333"], ["83936.5", "0.000333"]], "u": 174990, "seq": 67578167755}, "cts": 1742586306316, "record_time": 1742586306.40864, "EXCHANGE": "BYBIT"}
{"topic": "orderbook.200.BTCUSDT", "ts": 1742586306520, "type": "delta", "data": {"s": "BTCUSDT", "b": [["83873.5", "0.646637"], ["83873.1", "0.648966"], ["83871.7", "0.255988"], ["83869.8", "0.090857"], ["83869.6", "0.024176"], ["83869.4", "0.001256"], ["83869.3", "0.163911"], ["83869.2", "0.071574"], ["83868.7", "0.001333"], ["83868.6", "0"], ["83867.6", "0.005334"], ["83867.5", "0"], ["83866.3", "0.027045"], ["83866.2", "0.001466"], ["83866.1", "0.006761"], ["83865.4", "0.000524"], ["83865.2", "0.217957"], ["83865", "0"], ["83864.9", "0.009076"], ["83863.6", "0.019642"], ["83863.2", "0"], ["83862.4", "0.120559"], ["83862.1", "0.04057"], ["83861.6", "0.333944"], ["83861.4", "0.089099"], ["83861.2", "0.06"], ["83861.1", "0.075181"], ["83861", "0.000333"], ["83860.9", "0"], ["83859.5", "0.049002"], ["83859.4", "0"], ["83859.1", "0"], ["83857.9", "0"], ["83855.9", "0.178841"], ["83855.3", "0"], ["83854.6", "0.059399"], ["83853.7", "0.024108"], ["83853", "0"], ["83852.9", "0"], ["83852.7", "0.056994"], ["83851.6", "0"], ["83850.5", "0.141099"], ["83850.1", "0"], ["83848.6", "0"], ["83845.9", "0.357766"], ["83845.3", "0.005075"], ["83845.1", "0.023846"], ["83844.2", "0.023847"], ["83841.8", "0"], ["83841.6", "0"], ["83839.1", "0.011928"], ["83837.7", "0.000522"], ["83837.6", "0.02"], ["83836.6", "0.023845"], ["83835.1", "0.0001"], ["83834.9", "0.063477"], ["83834.1", "0.005206"], ["83833.5", "0"], ["83833.3", "0.012881"], ["83832.5", "0.126014"], ["83831.8", "0.023845"], ["83831.7", "0.000333"], ["83831.6", "0"], ["83831.5", "0.05"], ["83831.4", "0.049544"], ["83829.6", "0"], ["83828.9", "0.023845"], ["83825.3", "0.005961"], ["83824.1", "0"], ["83823.5", "0.37806"], ["83819.1", "0.000333"], ["83818.9", "0.015877"], ["83817.5", "0"], ["83814.7", "0.059399"], ["83806.4", "9.567604"], ["83803.9", "0"], ["83801.6", "0"], ["83800.8", "0"], ["83800.5", "0"], ["83800", "0"], ["83798.4", "0"], ["83798.2", "0"], ["83797.7", "0"]], "a": [["83869.4", "0"], ["83869.7", "0"], ["83870", "0"], ["83870.8", "0"], ["83871.8", "0"], ["83872.3", "0"], ["83872.7", "0"], ["83872.9", "0"], ["83874.1", "0"], ["83874.2", "0"], ["83875.2", "0"], ["83876.1", "0"], ["83876.2", "0"], ["83877", "0"], ["83877.8", "0.000333"], ["83877.9", "0"], ["83878.3", "0.021024"], ["83879", "0"], ["83879.4", "0"], ["83879.6", "0"], ["83880.1", "0.007001"], ["83880.5", "0"], ["83881.7", "0"], ["83881.9", "0"], ["83882", "0.060333"], ["83882.1", "0"], ["83882.4", "0"], ["83882.5", "0.031534"], ["83883.4", "0"], ["83883.5", "0.026108"], ["83883.6", "0"], ["83883.8", "0.000524"], ["83885", "0"], ["83885.3", "0"], ["83885.8", "0"], ["83886.3", "0"], ["83887.2", "0"], ["83887.6", "0.000297"], ["83887.7", "0.110704"], ["83888", "0.00009"], ["83888.4", "0.004757"], ["83888.7", "0"], ["83889.1", "0"], ["83889.6", "0"], ["83889.8", "0"], ["83890", "0"], ["83891.1", "0"], ["83891.2", "0"], ["83892.7", "0.0024"], ["83894.1", "0"], ["83898.7", "0.009225"], ["83899", "0"], ["83899.2", "0.059399"], ["83900.5", "0"], ["83901.1", "0"], ["83901.2", "0.184273"], ["83902.1", "0"], ["83903.8", "0.079657"], ["83903.9", "0"], ["83904.7", "0"], ["83905", "0"], ["83905.5", "0"], ["83906.4", "0.035774"], ["83908.1", "0"], ["83908.9", "0"], ["83909.7", "0"], ["83911", "0.011928"], ["83911.2", "0"], ["83911.5", "0.000524"], ["83912.2", "0"], ["83912.3", "0.001466"], ["83917.6", "0"], ["83917.8", "0.211358"], ["83917.9", "0.045457"], ["83922.3", "0.000024"], ["83925.7", "0.051493"], ["83927", "0.029697"], ["83930.8", "0.001466"], ["83932.8", "0.033856"], ["83938.4", "0.00009"], ["83938.9", "2.566954"], ["83939.2", "0.000526"], ["83940", "0.002799"], ["83940.4", "0.177938"], ["83940.7", "0.000333"], ["83941.8", "1.788424"], ["83942.4", "0.203425"], ["83942.7", "0.354209"], ["83943.1", "0.005457"], ["83943.8", "0.000526"], ["83943.9", "0.027408"], ["83944.2", "0.001333"], ["83944.4", "0.003575"], ["83944.6", "0.001466"], ["83944.9", "3.581379"], ["83945.3", "3.956989"], ["83946.5", "0.02971"], ["83947.3", "0.005457"], ["83947.4", "0.635028"], ["83948.4", "0.001859"], ["83949.1", "0.015333"], ["83949.2", "0.001466"], ["83949.3", "0.000358"], ["83949.5", "0.059399"], ["83950.2", "1.794206"], ["83950.3", "0.625971"], ["83950.5", "0.130533"], ["83951.2", "0.05"], ["83951.5", "0.005457"], ["83951.8", "0.05961"], ["83952.4", "0.000083"], ["83952.6", "0.001333"], ["83953", "0.000263"], ["83953.1", "0.000263"], ["83953.3", "0.012327"], ["83953.8", "0.001466"], ["83954.5", "0.05"], ["83955", "0.011994"], ["83955.3", "0.011874"], ["83955.7", "0.005457"], ["83956.5", "0.05"], ["83956.8", "0.001333"], ["83957.2", "0.05"], ["83957.5", "0.012207"]], "u": 174991, "seq": 67578168998}, "cts": 1742586306517, "record_time": 1742586306.609173, "EXCHANGE": "BYBIT"}
{"topic": "orderbook.200.BTCUSDT", "ts": 1742586306720, "type": "delta", "data": {"s": "BTCUSDT", "b": [["83873.5", "0.656493"], ["83870", "0.006761"], ["83869.6", "0.02"], ["83869.3", "0.14869"], ["83867.4", "0.071575"], ["83866.4", "0.009"], ["83866.1", "0"], ["83866", "0.01056"], ["83865.2", "0.322778"], ["83864.8", "0.178859"], ["83864.3", "0.0264"], ["83864.1", "0.064"], ["83863.7", "0.048"], ["83863", "0.178863"], ["83862", "0.084"], ["83861.3", "0.178867"], ["83861.2", "0.344136"], ["83861.1", "0"], ["83860.7", "0.06"], ["83860.1", "0.597771"], ["83859.1", "0.056"], ["83858.6", "0.056"], ["83857.5", "0.056"], ["83857.4", "0.052"], ["83857.2", "0.00009"], ["83856.7", "0.009225"], ["83855.9", "0"], ["83855.6", "0.064"], ["83853.9", "0"], ["83853.7", "0"], ["83852.2", "0"], ["83851", "0.003575"], ["83850.5", "0.089099"], ["83850.1", "0.178841"], ["83849.2", "0.000358"], ["83848.4", "0"], ["83846.7", "0"], ["83846", "0.357765"], ["83845.9", "0.304029"], ["83844.3", "0.059946"], ["83844.1", "0.317899"], ["83843.2", "0.024108"], ["83843", "0.025239"], ["83841", "0.126014"], ["83839.7", "0.002145"], ["83837.6", "0.10942"], ["83835.3", "0.012881"], ["83835.2", "0.014214"], ["83833.6", "0"], ["83833.4", "0.049547"], ["83833.3", "0.049547"], ["83832.5", "0"], ["83831.5", "0"], ["83831.4", "0"], ["83831", "0.001333"], ["83806.2", "0"], ["83806", "0"], ["83805.8", "0"], ["83805.4", "0"], ["83805", "0"], ["83804.7", "0"], ["83804.5", "0"], ["83804.4", "0"], ["83804.1", "0"], ["83802.6", "0"], ["83802.5", "0"], ["83802.3", "0"], ["83802.2", "0"]], "a": [["83873.6", "0.030132"], ["83877.1", "0.006589"], ["83881", "0.000297"], ["83881.1", "0.0528"], ["83881.9", "0.13926"], ["83882", "0.231333"], ["83882.8", "0.04774"], ["83884.9", "0.07156"], ["83887.6", "0"], ["83887.7", "0.126276"], ["83890", "0.04"], ["83890.1", "0.099399"], ["83890.2", "0.04"], ["83890.8", "0.071555"], ["83891", "0.046378"], ["83891.9", "0.04"], ["83893.1", "0.071553"], ["83893.5", "0.04"], ["83895", "0.04"], ["83895.2", "0.04"], ["83896.7", "0.04"], ["83896.9", "0.04"], ["83897.5", "0.028838"], ["83900.3", "0.033856"], ["83900.5", "0.019816"], ["83902", "0.009227"], ["83902.9", "0.0024"], ["83903", "0.000333"], ["83903.8", "0"], ["83904.5", "0.111559"], ["83906.4", "0"], ["83908.7", "0.059399"], ["83914", "0"], ["83915", "0.544087"], ["83915.1", "0.601131"], ["83915.2", "0"], ["83916.9", "0.001466"], ["83917.7", "0.118539"], ["83917.8", "0.171358"], ["83917.9", "0.005457"], ["83918.3", "0.04"], ["83918.4", "0.041788"], ["83918.6", "0.04"], ["83918.8", "0"], ["83920.3", "0"], ["83921.4", "0.08942"], ["83921.9", "0"], ["83925.7", "0.051491"], ["83938.9", "0.005457"], ["83943", "0.171"], ["83944.5", "2.561497"], ["83949.4", "0.357765"], ["83949.5", "0"], ["83950.2", "0"], ["83950.3", "0"], ["83950.5", "0"], ["83951.2", "0"], ["83951.5", "0"], ["83951.8", "0"], ["83952.4", "0"], ["83952.6", "0"], ["83953", "0"], ["83953.1", "0"], ["83953.3", "0"], ["83953.8", "0"], ["83954.5", "0"], ["83955", "0"], ["83955.3", "0"], ["83955.7", "0"], ["83956.5", "0"], ["83956.8", "0"], ["83957.2", "0"], ["83957.5", "0"]], "u": 174992, "seq": 67578169401}, "cts": 1742586306716, "record_time": 1742586306.809662, "EXCHANGE": "BYBIT"}
{"topic": "orderbook.200.BTCUSDT", "ts": 1742586306920, "type": "delta", "data": {"s": "BTCUSDT", "b": [["83873.2", "0.273515"], ["83860.9", "0.064"], ["83855.9", "0.178841"], ["83852.7", "0.000994"], ["83852.3", "0.186693"], ["83846.1", "0.588745"], ["83846", "0"], ["83839.6", "9.566004"], ["83835.3", "0"], ["83835.1", "0.012981"], ["83833.4", "0"], ["83833.2", "0.049547"], ["83806.6", "0"], ["83806.5", "0"], ["83806.4", "0"]], "a": [["83873.6", "0.030371"], ["83877.2", "0"], ["83882.1", "0.005961"], ["83884.9", "0"], ["83887.9", "0"], ["83891", "0.067114"], ["83891.7", "0.04"], ["83896.6", "0.054468"], ["83896.7", "0.043759"], ["83897.5", "0"], ["83900.5", "0.198657"], ["83900.9", "0.116363"], ["83904.7", "0.178841"], ["83910", "0.03025"], ["83918.3", "0"], ["83918.4", "0.001788"], ["83918.5", "0.04"], ["83918.6", "0.08"], ["83922.8", "0.051491"], ["83923.6", "0"], ["83925.7", "0"], ["83933.4", "2.561497"], ["83944.4", "0.36134"], ["83944.5", "0"], ["83949.4", "0"], ["83949.5", "0.059399"], ["83950.2", "1.794206"]], "u": 174993, "seq": 67578169480}, "cts": 1742586306914, "record_time": 1742586307.008507, "EXCHANGE": "BYBIT"}
{"topic": "orderbook.200.BTCUSDT", "ts": 1742586307120, "type": "delta", "data": {"s": "BTCUSDT", "b": [["83875.9", "2.376086"], ["83873.7", "0.335887"], ["83873.5", "0.271"], ["83873.2", "0"], ["83873.1", "0.477966"], ["83871.8", "0.006761"], ["83870.8", "0.001466"], ["83870", "0.000524"], ["83869.4", "0.001589"], ["83868.8", "0.027044"], ["83867.4", "0"], ["83866.3", "0"], ["83865.6", "0.00009"], ["83864.6", "0.040569"], ["83862.1", "0"], ["83855.6", "0"], ["83851", "0"], ["83850", "0.04872"], ["83846.1", "0"], ["83844.4", "0.357765"], ["83839.6", "0"], ["83836.2", "0.012882"], ["83836.1", "0.016457"], ["83835.2", "0.001333"], ["83835.1", "0.0001"], ["83834.3", "0.049549"], ["83834.2", "0.049549"], ["83833.3", "0"], ["83833.2", "0"], ["83831.2", "9.846936"], ["83829.5", "0.096625"], ["83822.9", "0.056"], ["83809.3", "0"], ["83808.9", "0"], ["83808.5", "0"], ["83806.8", "0"], ["83806.7", "0"]], "a": [["83873.6", "0"], ["83874.6", "0"], ["83875.4", "0"], ["83876", "0.009748"], ["83877.1", "0.001333"], ["83878.3", "0"], ["83879.5", "0.005256"], ["83882", "0.171333"], ["83882.5", "0.021023"], ["83883.7", "0.002521"], ["83883.9", "0.071561"], ["83884.4", "0.065429"], ["83886.7", "0.031533"], ["83910", "0.009866"], ["83918.5", "0"], ["83918.6", "0"], ["83918.8", "0.04"], ["83918.9", "0.04"], ["83944.4", "0.003575"], ["83949.4", "0.357764"], ["83950.2", "0"]], "u": 174994, "seq": 67578169685}, "cts": 1742586307109, "record_time": 1742586307.209663, "EXCHANGE": "BYBIT"}
{"topic": "orderbook.200.BTCUSDT", "ts": 1742586307320, "type": "delta", "data": {"s": "BTCUSDT", "b": [["83875.9", "2.375933"], ["83873.8", "0.197193"], ["83873.7", "0"], ["83873.6", "0.010603"], ["83873.1", "0.12157"], ["83869.8", "0"], ["83869.3", "0.072978"], ["83867.5", "0.06"], ["83861.4", "0"], ["83861.2", "0.284136"], ["83852.7", "0.004569"], ["83849.5", "0"], ["83844.4", "0"], ["83843.2", "0"], ["83843", "0"], ["83841.1", "0.357779"], ["83841", "0.126016"], ["83836.2", "0"], ["83836.1", "0.003575"], ["83836", "0.012882"], ["83835.9", "0.013215"], ["83834.3", "0"], ["83834.2", "0"], ["83834.1", "0.054755"], ["83834", "0.069549"], ["83831.2", "0"], ["83830.4", "0.025239"], ["83811.9", "9.846936"], ["83809.3", "3.548584"], ["83808.9", "0.005189"], ["83808.5", "0.005962"], ["83806.8", "0.00009"]], "a": [["83876", "0.04427"], ["83881", "0.071861"], ["83882.7", "0.065485"], ["83883.9", "0"], ["83886.3", "0.071559"], ["83888.1", "0.071558"], ["83890.8", "0"], ["83893.1", "0"], ["83895.1", "0.033856"], ["83900.3", "0"], ["83904.7", "0"], ["83930.6", "2.561505"], ["83933.4", "0"], ["83941.7", "0.357779"], ["83949.4", "0"], ["83950.2", "1.794206"]], "u": 174995, "seq": 67578169817}, "cts": 1742586307314, "record_time": 1742586307.408767, "EXCHANGE": "BYBIT"}
{"topic": "orderbook.200.BTCUSDT", "ts": 1742586307520, "type": "delta", "data": {"s": "BTCUSDT", "b": [["83873.6", "0"], ["83855.8", "0"], ["83837.8", "0.04"], ["83837.7", "0.040158"], ["83836.2", "0.013"], ["83836.1", "0.016457"], ["83836", "0"], ["83835.9", "0.000333"], ["83835", "0"], ["83834.9", "0.023845"], ["83834.3", "0.05"], ["83834.2", "0.049549"], ["83834.1", "0.005206"], ["83834", "0.02"], ["83814.7", "9.906335"], ["83811.9", "0"], ["83806.7", "0.023848"]], "a": [["83878.7", "0"], ["83881.6", "0.0025"], ["83891", "0.073348"], ["83896.3", "0.178836"], ["83902.8", "0"], ["83910.3", "0.0016"], ["83918.1", "0.04"], ["83918.2", "0.04"], ["83918.8", "0"], ["83918.9", "0"], ["83927.9", "2.561432"], ["83930.6", "0"], ["83940.3", "0.357783"], ["83941.7", "0"], ["83950.2", "0"]], "u": 174996, "seq": 67578169878}, "cts": 1742586307517, "record_time": 1742586307.609304, "EXCHANGE": "BYBIT"}
{"topic": "orderbook.200.BTCUSDT", "ts": 1742586307720, "type": "delta", "data": {"s": "BTCUSDT", "b": [["83875.9", "2.382342"], ["83865", "0.06"], ["83864", "0.089099"], ["83860.1", "0.633544"], ["83855", "0.005235"], ["83852.7", "0.000994"], ["83846", "0.023845"], ["83844.2", "0.381619"], ["83842.7", "0"], ["83841.1", "0"], ["83839.8", "0.04"], ["83839.7", "0.041779"], ["83837.8", "0"], ["83837.7", "0.000522"], ["83831.2", "9.846936"], ["83814.7", "0.059399"], ["83806.8", "0"], ["83806.7", "0"]], "a": [["83876", "0.040097"], ["83881", "0.000297"], ["83882", "0.000333"], ["83882.7", "0.044017"], ["83886.3", "0"], ["83888.1", "0"], ["83890.4", "0.242889"], ["83891", "0.067114"], ["83896.2", "0.109273"], ["83896.6", "0"], ["83897.6", "0"], ["83910", "0.000118"], ["83927.9", "0"], ["83933.4", "2.561432"], ["83940.3", "0"], ["83944.8", "0.357775"], ["83950.2", "1.794206"], ["83950.5", "0.130533"], ["83951.5", "0.005457"]], "u": 174997, "seq": 67578169950}, "cts": 1742586307713, "record_time": 1742586307.8277, "EXCHANGE": "BYBIT"}
{"topic": "orderbook.200.BTCUSDT", "ts": 1742586307920, "type": "delta", "data": {"s": "BTCUSDT", "b": [["83877", "0.90636"], ["83876", "0.042166"], ["83875.9", "0.372592"], ["83873.8", "0.117494"], ["83873.5", "0.00676"], ["83871.8", "0.005339"], ["83869.3", "0.303465"], ["83867.1", "0.118539"], ["83867", "0.178855"], ["83866.9", "0.535446"], ["83865.9", "0.048997"], ["83865.6", "0.033946"], ["83865.5", "0.056"], ["83865.3", "0.178858"], ["83864.8", "0"], ["83864.3", "0.050533"], ["83863.9", "0.056"], ["83863", "0"], ["83862.6", "0"], ["83861.3", "0"], ["83859.5", "0"], ["83858.5", "0"], ["83855.9", "0"], ["83854.1", "0"], ["83850.6", "0.357748"], ["83844.3", "0.318102"], ["83844.2", "0"], ["83839", "0.013"], ["83838.9", "0.012881"], ["83837.8", "0.023646"], ["83837.6", "0.15942"], ["83837.5", "0.049546"], ["83836.2", "0"], ["83836.1", "0.003575"], ["83835.4", "3.570984"], ["83834.3", "0"], ["83834.2", "0"], ["83832.1", "0.000149"], ["83832", "0.00009"], ["83831.9", "0"], ["83831.6", "0.024108"], ["83831.2", "0"], ["83829.5", "0"], ["83826.4", "0"], ["83821", "0"]], "a": [["83876", "0"], ["83877.1", "0.001572"], ["83879.5", "0"], ["83880.6", "0.005255"], ["83881", "0"], ["83881.6", "0"], ["83881.8", "0.023925"], ["83882.1", "0"], ["83882.7", "0"], ["83883.5", "0"], ["83884.4", "0.005429"], ["83885.5", "0.061333"], ["83885.6", "0.005961"], ["83887.7", "0.080099"], ["83888.7", "0.026108"], ["83890.1", "0.04"], ["83890.2", "0"], ["83890.4", "0.171333"], ["83894.8", "0.071552"], ["83895.1", "0"], ["83896.3", "0"], ["83900.5", "0.019816"], ["83900.7", "0.033856"], ["83904.4", "0.039997"], ["83904.5", "0"], ["83905.3", "0.030789"], ["83913.4", "0.007975"], ["83915.4", "0"], ["83915.8", "0.029852"], ["83917.7", "0"], ["83918.1", "0"], ["83918.2", "0"], ["83920.3", "0.04"], ["83920.4", "0.04"], ["83921.4", "0.178833"], ["83921.8", "0.047121"], ["83922.8", "0"], ["83925.6", "0.178833"], ["83925.7", "0.051492"], ["83926.4", "0.022341"], ["83927.9", "0.04"], ["83929.3", "0.118539"], ["83931.3", "0.04"], ["83933.4", "0"], ["83934.5", "0.04"], ["83934.7", "0.085457"], ["83938.9", "2.566974"], ["83940.4", "0.178083"], ["83944.8", "0"], ["83951.4", "0.171"], ["83951.8", "0.05961"]], "u": 174998, "seq": 67578170296}, "cts": 1742586307918, "record_time": 1742586308.008294, "EXCHANGE": "BYBIT"}
{"topic": "orderbook.200.BTCUSDT", "ts": 1742586308119, "type": "delta", "data": {"s": "BTCUSDT", "b": [["83877.7", "2.461957"], ["83877.2", "0.058323"], ["83877", "0.307625"], ["83876", "0"], ["83875.9", "0.056256"], ["83873.7", "0.089099"], ["83872.9", "0.001333"], ["83872.1", "0.004108"], ["83871.2", "0.027044"], ["83871", "0.048"], ["83870.9", "0.064"], ["83869.3", "0.42905"], ["83868.8", "0.084"], ["83868.6", "0.06"], ["83867.9", "0.178853"], ["83867.2", "0.064"], ["83867", "0.219423"], ["83866", "0"], ["83865.8", "0.056"], ["83864.6", "0"], ["83863.5", "0.003575"], ["83861", "0.179166"], ["83859.1", "0"], ["83858.6", "0"], ["83857.5", "0"], ["83856.8", "0.000333"], ["83852.4", "0.357737"], ["83850.6", "0"], ["83846.1", "0.025239"], ["83845.9", "0.125188"], ["83844.3", "0.071868"], ["83842.9", "0.039632"], ["83842.8", "0.039632"], ["83841.1", "0.013"], ["83841", "0.138897"], ["83839.8", "0"], ["83839.7", "0.002145"], ["83839.3", "0.240544"], ["83839.2", "0.049544"], ["83839", "0"], ["83838.9", "0"], ["83837.6", "0.10942"], ["83837.5", "0"], ["83830.4", "0"], ["83828.5", "10.141339"], ["83817.6", "0.02753"], ["83811.1", "0"], ["83810.8", "0"], ["83810.7", "0"], ["83810.6", "0"], ["83810", "0"], ["83809.3", "0"], ["83808.9", "0"], ["83808.5", "0"]], "a": [["83877.1", "0"], ["83877.8", "0.000572"], ["83879.8", "0.007975"], ["83881.1", "0"], ["83881.8", "0"], ["83881.9", "0"], ["83885.5", "0.001333"], ["83886.2", "0.060333"], ["83887.7", "0"], ["83888", "0"], ["83888.6", "0.089501"], ["83891", "0"], ["83891.6", "0.051446"], ["83894.8", "0"], ["83896.2", "0.048468"], ["83896.6", "0.04"], ["83901.2", "0.005432"], ["83904.4", "0"], ["83905.2", "0.013548"], ["83906.2", "0.111558"], ["83913.4", "0"], ["83920.3", "0"], ["83920.4", "0"], ["83921.4", "0"], ["83922.7", "0.04"], ["83922.8", "0.04"], ["83927.8", "0.04"], ["83929.5", "0.04"], ["83929.6", "0.04"], ["83929.8", "0.304028"], ["83952.4", "0.000083"], ["83952.6", "0.001333"], ["83953", "0.000263"]], "u": 174999, "seq": 67578170658}, "cts": 1742586308117, "record_time": 1742586308.208453, "EXCHANGE": "BYBIT"}
{"topic": "orderbook.200.BTCUSDT", "ts": 1742586308320, "type": "delta", "data": {"s": "BTCUSDT", "b": [["83882.9", "0.994966"], ["83880", "0.00006"], ["83879.3", "0.104792"], ["83879.1", "0.335905"], ["83877.8", "0.08936"], ["83877.7", "0.186"], ["83877.2", "0"], ["83877.1", "0.001333"], ["83877", "0.05"], ["83876.9", "0.033856"], ["83876.4", "0.027065"], ["83876", "0.005339"], ["83875.6", "0.00676"], ["83875.4", "0.012026"], ["83874.6", "0.000524"], ["83874.3", "0.019642"], ["83874", "0.00009"], ["83873.9", "0.118539"], ["83873.8", "0.172883"], ["83873.7", "0.115499"], ["83873.6", "0.000333"], ["83873.5", "0"], ["83873.1", "0.05"], ["83872.2", "0.0406"], ["83871.7", "0.221"], ["83871.2", "0"], ["83870.3", "0.003081"], ["83869.3", "0.48905"], ["83869.2", "0"], ["83867.9", "0"], ["83867", "0.178855"], ["83864.3", "0.024133"], ["83864.1", "0.052"], ["83863.7", "0"], ["83863.6", "0"], ["83862.4", "0.114559"], ["83862", "0"], ["83860.9", "0"], ["83860.7", "0"], ["83857.5", "0.357717"], ["83857.4", "0"], ["83857", "0.04872"], ["83856.7", "0"], ["83855.6", "0.003575"], ["83854.7", "0.053381"], ["83852.5", "0.303445"], ["83852.4", "0"], ["83852.3", "0.001466"], ["83851.2", "0"], ["83846.1", "0.102391"], ["83846", "0"], ["83845.1", "0"], ["83844.9", "0"], ["83844.2", "0.175214"], ["83843.5", "0"], ["83839.6", "0.185939"], ["83837", "0"], ["83831.6", "0"], ["83828.5", "0.000522"], ["83814.3", "0"], ["83814.2", "0"], ["83813.3", "0"], ["83813.1", "0"], ["83812.1", "0"]], "a": [["83877.8", "0"], ["83879.2", "0"], ["83879.8", "0"], ["83880", "0"], ["83880.1", "0"], ["83880.2", "0"], ["83880.6", "0"], ["83881.3", "0"], ["83882", "0"], ["83882.5", "0"], ["83882.8", "0"], ["83886.2", "0.000333"], ["83886.7", "0"], ["83887.5", "0.01034"], ["83888.6", "0.005429"], ["83888.7", "0"], ["83890", "0"], ["83890.1", "0"], ["83890.3", "0.000297"], ["83890.5", "0.01056"], ["83891.2", "0.074822"], ["83891.3", "0.12892"], ["83891.4", "0.06"], ["83891.6", "0"], ["83891.7", "0"], ["83891.9", "0"], ["83892.2", "0.04774"], ["83893.5", "0"], ["83894.3", "0.071552"], ["83894.8", "0.026049"], ["83895", "0"], ["83895.2", "0"], ["83896.2", "0"], ["83896.5", "0.033674"], ["83896.7", "0.003759"], ["83896.9", "0"], ["83898.4", "0.04"], ["83898.7", "0"], ["83899.3", "0.071548"], ["83899.8", "0"], ["83900.7", "0"], ["83900.9", "0.058895"], ["83901.5", "0.0406"], ["83903.3", "0.071545"], ["83905.2", "0.045322"], ["83905.3", "0.006945"], ["83905.8", "0.033856"], ["83908.5", "0"], ["83908.7", "0.157056"], ["83908.8", "0.304"], ["83911.2", "0.009225"], ["83912.1", "0.390101"], ["83915.8", "0.023844"], ["83917.7", "0.0719"], ["83920.5", "0"], ["83921.7", "0.075903"], ["83922.7", "0"], ["83922.8", "0"], ["83924.6", "0.04"], ["83924.7", "0.04"], ["83925.5", "0.174346"], ["83925.6", "0"], ["83925.7", "0"], ["83926.1", "0.001466"], ["83929.8", "0.125196"], ["83931.3", "0.091492"], ["83935.6", "0.014051"], ["83938.9", "0.005457"], ["83942.4", "0.114"], ["83943.9", "0"], ["83944.5", "2.561389"], ["83950.7", "0.12518"], ["83951.8", "0"], ["83953.1", "0.000263"], ["83953.3", "0.012327"], ["83953.8", "0.001466"], ["83955", "0.011994"], ["83955.3", "0.011874"], ["83955.7", "0.005457"], ["83956.8", "0.001333"], ["83957.5", "0.012207"], ["83957.7", "0.000526"], ["83957.9", "0.059399"], ["83958.5", "0.01346"]], "u": 175000, "seq": 67578171834}, "cts": 1742586308316, "record_time": 1742586308.409, "EXCHANGE": "BYBIT"}
{"topic": "orderbook.200.BTCUSDT", "ts": 1742586308520, "type": "delta", "data": {"s": "BTCUSDT", "b": [["83882.9", "1.009871"], ["83880.6", "0.003"], ["83879.4", "0.006766"], ["83879.1", "0.321"], ["83875.6", "0"], ["83873.8", "0.287262"], ["83870.3", "0.405339"], ["83866", "0.064044"], ["83865.2", "0.217957"], ["83865", "0"], ["83858.5", "0.178821"], ["83857.6", "0.357711"], ["83857.5", "0"], ["83854.3", "0.178821"], ["83852.9", "0.331654"], ["83852.5", "0.194718"], ["83850.5", "0.113207"], ["83850.1", "0"], ["83849.4", "0.125998"], ["83844.1", "0"], ["83841", "0.012881"], ["83833.6", "0.015877"], ["83819.3", "1.27201"], ["83818.9", "0"], ["83818.5", "0.172172"], ["83815.2", "0"], ["83815", "0"], ["83814.9", "0"], ["83814.7", "0"], ["83814.6", "0"]], "a": [["83883", "0.003649"], ["83886.5", "0.005251"], ["83888.8", "0.023825"], ["83889.5", "0.021003"], ["83890.4", "0.000333"], ["83890.5", "0.0528"], ["83891.2", "0"], ["83891.4", "0.231"], ["83893.7", "0.031503"], ["83894.3", "0"], ["83896.5", "0.057674"], ["83896.6", "0"], ["83897.7", "0.040524"], ["83897.8", "0.04"], ["83899.3", "0"], ["83899.5", "0.040083"], ["83900.9", "0.085146"], ["83901.1", "0.071547"], ["83901.2", "0.045432"], ["83902.8", "0.04"], ["83902.9", "0.0424"], ["83904.5", "0.04"], ["83906.2", "0"], ["83908.8", "0.178821"], ["83913", "0.111556"], ["83921.7", "0"], ["83924.2", "0"], ["83924.6", "0"], ["83924.7", "0"], ["83924.8", "1.429854"], ["83925.4", "0.040263"], ["83925.5", "0.04"], ["83931.3", "0.04"], ["83932", "0.317566"], ["83934.2", "0.051491"], ["83947.4", "0"], ["83957.9", "0"], ["83958.5", "0"]], "u": 175001, "seq": 67578172113}, "cts": 1742586308517, "record_time": 1742586308.608478, "EXCHANGE": "BYBIT"}
{"topic": "orderbook.200.BTCUSDT", "ts": 1742586308720, "type": "delta", "data": {"s": "BTCUSDT", "b": [["83882.9", "1.195888"], ["83882.5", "0.003"], ["83879.2", "0.118539"], ["83878.1", "0.009225"], ["83877.7", "0.171095"], ["83875.5", "0.009"], ["83873.7", "0.0264"], ["83869.1", "0.060615"], ["83867", "0"], ["83866.4", "0"], ["83865.3", "0"], ["83863.5", "0"], ["83862.7", "0.05"], ["83862.1", "0.061776"], ["83861", "0.000333"], ["83857.6", "0"], ["83855.1", "0.112762"], ["83854.8", "0.357723"], ["83854.7", "0.100355"], ["83850.5", "0.089099"], ["83850", "0"], ["83845.9", "0.023515"], ["83844.4", "0.061811"], ["83844.2", "0"], ["83843", "0.049547"], ["83842.9", "0.089179"], ["83839.6", "10.326756"], ["83839.3", "0.215108"], ["83839.2", "0"], ["83837.8", "0"], ["83837.6", "0.10941"], ["83825.7", "0.245818"], ["83815.4", "0"], ["83815.3", "0"]], "a": [["83883", "0.000908"], ["83883.7", "0"], ["83889.2", "0.002084"], ["83892.6", "0.071554"], ["83896.7", "0"], ["83898.4", "0"], ["83899.2", "0.130947"], ["83900.9", "0.139329"], ["83901.1", "0"], ["83901.5", "0.0006"], ["83904.1", "0.059787"], ["83904.4", "0.028686"], ["83905.2", "0.04"], ["83908.8", "0"], ["83911.1", "0.059379"], ["83913", "0"], ["83915.7", "0.111555"], ["83918.1", "0.111536"], ["83921.4", "0.08941"], ["83921.8", "0.023844"], ["83926.5", "0.043502"], ["83929.8", "0"], ["83929.9", "0.022928"], ["83934.8", "0"], ["83942.4", "0.382231"], ["83944.5", "0"], ["83946.6", "0.178821"], ["83950", "2.561389"], ["83956.1", "0.013102"], ["83957.5", "0"], ["83957.7", "0"]], "u": 175002, "seq": 67578172309}, "cts": 1742586308717, "record_time": 1742586308.809459, "EXCHANGE": "BYBIT"}
{"topic": "orderbook.200.BTCUSDT", "ts": 1742586308919, "type": "delta", "data": {"s": "BTCUSDT", "b": [["83882.9", "0.985744"], ["83879.2", "0"], ["83879.1", "0.301"], ["83877.7", "0.05"], ["83874.5", "0.06"], ["83869.1", "0"], ["83869", "0.056342"], ["83868.6", "0"], ["83866", "0.004645"], ["83862.1", "0"], ["83862", "0.060757"], ["83855.1", "0"], ["83855", "0.124859"], ["83854.9", "0.214345"], ["83854.8", "0"], ["83854.7", "0"], ["83850.6", "0.357741"], ["83849.4", "0.126022"], ["83846.2", "0.038126"], ["83846.1", "0.025239"], ["83843.6", "0.050879"], ["83843.5", "0.049546"], ["83843", "0"], ["83842.9", "0.039632"], ["83839.6", "10.426401"], ["83835.8", "0.178821"]], "a": [["83883", "0.003888"], ["83883.7", "0.002521"], ["83890.1", "0.000297"], ["83890.3", "0"], ["83891.2", "0.164476"], ["83892.6", "0"], ["83896.5", "0.080266"], ["83896.9", "0.07155"], ["83903.3", "0"], ["83904", "0.106964"], ["83904.1", "0"], ["83904.4", "0"], ["83904.7", "0.178821"], ["83905.8", "0.037615"], ["83908.5", "0.04"], ["83908.9", "0.178821"], ["83911", "0.066235"], ["83911.1", "0"], ["83918", "0.124469"], ["83918.1", "0"], ["83920.5", "0.004769"], ["83924.7", "0.566913"], ["83925.4", "0.000263"], ["83925.5", "0"], ["83926.6", "0.04"], ["83926.7", "0.04"], ["83934.5", "0"], ["83939", "0.178821"], ["83942.4", "0.20341"], ["83944.5", "2.561445"], ["83946.6", "0"], ["83950", "0"], ["83955.3", "0"], ["83955.7", "0"], ["83956.1", "0"], ["83956.8", "0"]], "u": 175003, "seq": 67578172459}, "cts": 1742586308917, "record_time": 1742586309.008839, "EXCHANGE": "BYBIT"}
{"topic": "orderbook.200.BTCUSDT", "ts": 1742586309119, "type": "delta", "data": {"s": "BTCUSDT", "b": [["83882.9", "0.219989"], ["83879.3", "0.03"], ["83879.1", "0.1"], ["83878.1", "0"], ["83877.8", "0.000333"], ["83877.7", "0"], ["83877", "0"], ["83875.9", "0.006256"], ["83874.3", "0"], ["83873.9", "0"], ["83873.1", "0"], ["83871.7", "0.201"], ["83869.3", "0.363465"], ["83869", "0"], ["83865.6", "0.00009"], ["83864", "0"], ["83862", "0"], ["83855", "0.005235"], ["83854.9", "0"], ["83853", "0.371473"], ["83852.5", "0"], ["83850.6", "0"], ["83850.5", "0"], ["83849.4", "0"], ["83846.1", "0"], ["83845.9", "0"], ["83845.6", "0.012881"], ["83845.5", "0.012881"], ["83844.5", "0.35777"], ["83843.8", "0.12603"], ["83843.7", "0.05"], ["83843.5", "0"], ["83841.1", "0"], ["83841", "0"], ["83839.6", "0.185939"], ["83839.3", "0.191"], ["83835.8", "0"], ["83833.3", "0.178821"], ["83832", "0.033946"], ["83831.3", "10.240462"], ["83815.4", "0.013466"], ["83815.3", "0.0015"], ["83815.2", "0.00009"], ["83815", "0.023848"], ["83814.9", "0.000333"], ["83814.7", "0.059399"], ["83814.6", "0.000522"], ["83814.3", "0.118539"], ["83814.2", "0.001333"], ["83813.3", "0.015"], ["83813.1", "0.005189"], ["83812.1", "0.023848"]], "a": [["83883", "0.465162"], ["83883.8", "0.028104"], ["83883.9", "0.071561"], ["83888.5", "0.024984"], ["83888.8", "0"], ["83890.4", "0.059732"], ["83891.2", "0.236031"], ["83896.5", "0.057674"], ["83896.9", "0"], ["83899.2", "0.059399"], ["83900.4", "0.033856"], ["83900.9", "0.094895"], ["83903.4", "0.04"], ["83904", "0.046622"], ["83905.8", "0"], ["83907.4", "0.178768"], ["83911", "0.011928"], ["83918", "0"], ["83924.1", "0.118539"], ["83926.6", "0"], ["83926.7", "0"], ["83926.9", "0.04"], ["83927", "0.069697"], ["83929.5", "0"], ["83929.9", "0"], ["83931.3", "0.114026"], ["83932.1", "0.023665"], ["83934.2", "0"], ["83944.4", "0.361345"], ["83944.5", "0"], ["83955.3", "0.011874"], ["83955.7", "0.005457"]], "u": 175004, "seq": 67578172642}, "cts": 1742586309117, "record_time": 1742586309.210754, "EXCHANGE": "BYBIT"}
{"topic": "orderbook.200.BTCUSDT", "ts": 1742586309319, "type": "delta", "data": {"s": "BTCUSDT", "b": [["83882.9", "0.148984"], ["83879.3", "0"], ["83877", "0.03339"], ["83876.9", "0"], ["83875.5", "0"], ["83873.8", "0.133536"], ["83871.7", "0.171"], ["83871.1", "0.033856"], ["83870.3", "0"], ["83869.6", "0"], ["83869.3", "0.194705"], ["83866.9", "0"], ["83864.8", "0.178859"], ["83863.4", "0.024969"], ["83862.7", "0"], ["83862.6", "0.00596"], ["83862.4", "0.293423"], ["83861.7", "0.05"], ["83861", "0.009558"], ["83860.7", "0.178868"], ["83858.5", "0"], ["83857", "0.167934"], ["83855.8", "0.53463"], ["83855.7", "0.178821"], ["83854.3", "0"], ["83853", "0"], ["83845.9", "0.125174"], ["83845.6", "0"], ["83845.5", "0"], ["83844.6", "0.241932"], ["83844.5", "0.012881"], ["83844.4", "0"], ["83843.8", "0"], ["83843.7", "0"], ["83843.6", "0.001333"], ["83842.9", "0.089632"], ["83842.8", "0.089179"], ["83838.1", "0.14603"], ["83837.6", "0.02"], ["83837.2", "0.023345"], ["83835.5", "0.357809"], ["83833.3", "0"], ["83831.3", "0"], ["83828.5", "10.240984"], ["83813.1", "0.176189"], ["83811.1", "0.000358"], ["83810.8", "3.977808"], ["83810.7", "0.000333"], ["83810", "0.031565"], ["83808.9", "0.005189"]], "a": [["83888.5", "0.03968"], ["83888.9", "0.071557"], ["83889.4", "0.023758"], ["83890.4", "0.000333"], ["83891.9", "0.04"], ["83892", "0.04"], ["83893.6", "0.003759"], ["83894.9", "0.033856"], ["83895.4", "0.0406"], ["83896.5", "0.097674"], ["83897", "0.045432"], ["83897.8", "0"], ["83900.4", "0"], ["83901", "0.349821"], ["83901.2", "0.224214"], ["83902.9", "0.0024"], ["83903.2", "0.178777"], ["83904", "0.131978"], ["83904.7", "0"], ["83905.1", "0.119572"], ["83907.4", "0"], ["83907.6", "0.003575"], ["83908.8", "0.125174"], ["83908.9", "0"], ["83915", "0.662626"], ["83916.3", "0.022535"], ["83921.2", "0.024897"], ["83921.4", "0"], ["83928.5", "0.051491"], ["83929.8", "0.125174"], ["83931.3", "0.04"], ["83934.5", "0.357809"], ["83939", "0"], ["83944.4", "0.003575"], ["83947.1", "0.107283"], ["83950.7", "0"], ["83953.1", "0"], ["83953.3", "0"], ["83953.8", "0"], ["83955", "0"], ["83955.3", "0"], ["83955.7", "0"]], "u": 175005, "seq": 67578172948}, "cts": 1742586309317, "record_time": 1742586309.408739, "EXCHANGE": "BYBIT"}
{"topic": "orderbook.200.BTCUSDT", "ts": 1742586309520, "type": "delta", "data": {"s": "BTCUSDT", "b": [["83882.9", "0.158521"], ["83869.3", "0.159144"], ["83867.1", "0"], ["83864.8", "0"], ["83862.4", "0.114559"], ["83861.7", "0"], ["83861.6", "0.51281"], ["83860.7", "0"], ["83859.9", "0.17887"], ["83855.9", "0.27006"], ["83852.9", "0.013788"], ["83850.1", "0.178821"], ["83846.4", "0.04"], ["83846.3", "0.039634"], ["83845.9", "0.303995"], ["83844.8", "0.013"], ["83844.7", "0.012881"], ["83844.6", "0"], ["83844.5", "0"], ["83842.9", "0.05"], ["83842.8", "0.049547"], ["83841", "0.126072"], ["83838.2", "0.363028"], ["83838.1", "0.02"], ["83835.5", "0"], ["83831.2", "0.096623"], ["83810", "0"], ["83808.9", "0"]], "a": [["83885.4", "0.009225"], ["83885.5", "0.004033"], ["83896.5", "0.142973"], ["83897.7", "0.000524"], ["83898.5", "0.180253"], ["83898.6", "0.04"], ["83898.7", "0.04"], ["83899.4", "0.006204"], ["83900.2", "0.178784"], ["83900.5", "0.198637"], ["83900.9", "0.244097"], ["83901.2", "0.005432"], ["83903.2", "0"], ["83903.3", "0.11924"], ["83903.4", "0"], ["83904", "0.046622"], ["83904.5", "0"], ["83910.3", "0"], ["83911.2", "0"], ["83914.2", "0.0016"], ["83916.3", "0"], ["83923", "0.317804"], ["83925.7", "0.04"], ["83925.8", "0.04"], ["83926.9", "0"], ["83927", "0.029697"], ["83927.1", "0.022535"], ["83932", "0"], ["83934.5", "0"], ["83935.6", "0.371856"], ["83953", "0"]], "u": 175006, "seq": 67578173125}, "cts": 1742586309515, "record_time": 1742586309.608602, "EXCHANGE": "BYBIT"}
{"topic": "orderbook.200.BTCUSDT", "ts": 1742586309719, "type": "delta", "data": {"s": "BTCUSDT", "b": [["83882.9", "0.097684"], ["83879.1", "0"], ["83877", "0"], ["83872.1", "0"], ["83871.1", "0"], ["83866", "0"], ["83865.6", "0.033946"], ["83862.4", "0.003"], ["83861.6", "0.333944"], ["83861.4", "0.004108"], ["83859.9", "0"], ["83855.7", "0"], ["83853.2", "0.004622"], ["83852.9", "0"], ["83850.4", "0.150799"], ["83850.1", "0"], ["83846.4", "0.039634"], ["83845.9", "0.125174"], ["83844.8", "0.012881"], ["83842.9", "0.049547"], ["83841", "0"], ["83838.2", "0.005224"], ["83838.1", "0.146048"], ["83837.2", "0"], ["83836.3", "0.048"], ["83836.2", "0.064"], ["83833.6", "0"], ["83832.8", "0.06"], ["83832", "0.058447"], ["83831.2", "0.152623"], ["83829.5", "0.052"], ["83828.6", "0.357827"], ["83828.5", "0.000522"], ["83825.8", "10.240462"], ["83825", "0.178939"], ["83820.8", "0.178821"], ["83816.6", "0"], ["83810", "0.031565"], ["83808.9", "0.005189"], ["83808.5", "0.005962"]], "a": [["83883", "0.51928"], ["83885.4", "0"], ["83888.5", "0.066438"], ["83889.2", "0.0219"], ["83889.4", "0.057614"], ["83890.4", "0.059732"], ["83893.7", "0.071503"], ["83894.9", "0"], ["83895.3", "0.0412"], ["83896.2", "0.122219"], ["83896.3", "0.178821"], ["83896.5", "0.04"], ["83896.6", "0.119073"], ["83898.5", "0.001466"], ["83899.2", "0.093255"], ["83899.5", "0.000083"], ["83899.9", "0.119073"], ["83900.1", "0.272699"], ["83900.5", "0.178821"], ["83900.9", "0.0012"], ["83901", "0.171"], ["83903.3", "0"], ["83905.1", "0.000358"], ["83905.2", "0"], ["83908.5", "0"], ["83915.9", "0.023516"], ["83917.1", "0.023665"], ["83921.2", "0.0006"], ["83922.8", "0.051491"], ["83926.5", "0.038843"], ["83928.5", "0"], ["83929.7", "0.357827"], ["83932.1", "0"], ["83932.8", "0"], ["83935.6", "0.014051"], ["83952.6", "0"]], "u": 175007, "seq": 67578173335}, "cts": 1742586309717, "record_time": 1742586309.808242, "EXCHANGE": "BYBIT"}
{"topic": "orderbook.200.BTCUSDT", "ts": 1742586309920, "type": "delta", "data": {"s": "BTCUSDT", "b": [["83882.9", "0.129595"], ["83874", "0"], ["83873.8", "0"], ["83871.9", "0.087099"], ["83869.3", "0.223575"], ["83865.8", "0.167555"], ["83862.3", "0"], ["83861.2", "0.195335"], ["83853.2", "0.183443"], ["83850.4", "0"], ["83846.4", "0"], ["83846.3", "0"], ["83844.8", "0"], ["83844.7", "0.039636"], ["83844.6", "0.039636"], ["83843.1", "0.014348"], ["83843", "0.012882"], ["83842.9", "0"], ["83842.8", "0"], ["83841.2", "0.049847"], ["83841.1", "0.049549"], ["83835.5", "1.183151"], ["83833.5", "0.144"], ["83832.9", "0.357818"], ["83831.9", "0.064"], ["83830.2", "0.056"], ["83828.6", "0"], ["83806.8", "0.00009"]], "a": [["83883", "0.544958"], ["83890.4", "0.000333"], ["83893.1", "0.009225"], ["83896.9", "0.04"], ["83898.5", "0.180287"], ["83900.1", "0.176976"], ["83902.8", "0"], ["83904", "0"], ["83921.4", "0.08941"], ["83922.7", "0.14685"], ["83929.7", "0"], ["83934.5", "0.357818"], ["83938.9", "2.566973"], ["83951.5", "0"], ["83952.4", "0"]], "u": 175008, "seq": 67578173494}, "cts": 1742586309916, "record_time": 1742586310.008455, "EXCHANGE": "BYBIT"}
{"topic": "orderbook.200.BTCUSDT", "ts": 1742586310119, "type": "delta", "data": {"s": "BTCUSDT", "b": [["83882.9", "0.129853"], ["83863.8", "0.112459"], ["83861.6", "0.51281"], ["83860", "0.17905"], ["83858.3", "0.178873"], ["83856.8", "0.179595"], ["83855.7", "0.178821"], ["83853.2", "0.004622"], ["83850.4", "0.097153"], ["83849.8", "0.301472"], ["83844.8", "0.04"], ["83844.6", "0"], ["83841.3", "0.049549"], ["83841.1", "0"], ["83841", "0.126005"], ["83840.7", "0.013715"], ["83838.1", "0.02"], ["83832.9", "0"], ["83831", "0.359155"], ["83810.8", "0"], ["83810.7", "0"], ["83810", "0"], ["83808.9", "0"], ["83808.5", "0"], ["83806.8", "0"]], "a": [["83896.2", "0.218467"], ["83896.7", "0.113051"], ["83903.7", "0.172382"], ["83910.7", "0.293515"], ["83914.5", "0.004608"], ["83922.3", "2.56154"], ["83923.5", "0.04"], ["83923.6", "0.04"], ["83925.7", "0"], ["83925.8", "0"], ["83931.2", "0.357823"], ["83934.5", "0"], ["83938.9", "0.005457"], ["83950.2", "0"], ["83950.5", "0"], ["83951.4", "0"]], "u": 175009, "seq": 67578173561}, "cts": 1742586310105, "record_time": 1742586310.207459, "EXCHANGE": "BYBIT"}
{"topic": "orderbook.200.BTCUSDT", "ts": 1742586310319, "type": "delta", "data": {"s": "BTCUSDT", "b": [["83882.9", "0.120844"], ["83875.9", "0"], ["83871.7", "0"], ["83869.4", "0.000333"], ["83867.5", "0.060153"], ["83863.8", "0"], ["83862.4", "0"], ["83861.6", "0.333944"], ["83861.2", "0.278241"], ["83861", "0.000333"], ["83860", "0.00018"], ["83859", "0.178872"], ["83858.3", "0"], ["83856.8", "0.000333"], ["83855.7", "0"], ["83854.3", "0.00596"], ["83849.8", "0"], ["83844.8", "0.039636"], ["83841", "0"], ["83838.1", "0.146005"], ["83831", "0.001333"], ["83825", "0.000118"], ["83823", "0.357838"], ["83820.3", "0.178954"], ["83810.8", "3.977808"], ["83810.7", "0.000333"], ["83810", "0.031565"], ["83808.9", "0.005189"]], "a": [["83883", "0.559183"], ["83888", "0.023842"], ["83893.1", "0"], ["83896.7", "0"], ["83900.2", "0"], ["83903.7", "0"], ["83907.6", "0"], ["83909.8", "0.00596"], ["83910.3", "0.022535"], ["83910.7", "0.001333"], ["83922.2", "0.939312"], ["83922.7", "0"], ["83927.1", "0"], ["83929.1", "0.357838"], ["83931.2", "0"], ["83950.2", "1.794206"], ["83950.5", "0.130533"], ["83951.5", "0.005457"]], "u": 175010, "seq": 67578173928}, "cts": 1742586310317, "record_time": 1742586310.407401, "EXCHANGE": "BYBIT"}
{"topic": "orderbook.200.BTCUSDT", "ts": 1742586310520, "type": "delta", "data": {"s": "BTCUSDT", "b": [["83882.9", "0.093643"], ["83871.9", "0.035799"], ["83867.5", "0.06"], ["83854.5", "0.127764"], ["83850.7", "0.178821"], ["83846.6", "0.045835"], ["83846.5", "0.039634"], ["83845", "0.013"], ["83844.9", "0.012881"], ["83844.8", "0"], ["83844.7", "0"], ["83844.4", "0.071841"], ["83844.3", "0.012255"], ["83843.1", "0.051466"], ["83843", "0.049547"], ["83841.3", "0"], ["83841.2", "0.000298"], ["83838.1", "0.146012"], ["83827.2", "0.35783"], ["83825.8", "0"], ["83825", "0.178939"], ["83823", "0"], ["83820.2", "10.426524"], ["83810", "0"], ["83808.9", "0"]], "a": [["83883", "0.661419"], ["83883.8", "0.014599"], ["83883.9", "0"], ["83885.5", "0.027875"], ["83888.3", "0.106871"], ["83888.4", "0.123969"], ["83888.5", "0"], ["83890.8", "0.009225"], ["83891.2", "0.321104"], ["83892.1", "0.178821"], ["83895.2", "0.059606"], ["83895.3", "0.377759"], ["83896", "0.178821"], ["83896.2", "0"], ["83898.5", "0.001466"], ["83900.1", "0.111701"], ["83900.5", "0"], ["83914", "2.561516"], ["83919.5", "0.099399"], ["83919.6", "0.04"], ["83922.3", "0.000024"], ["83923.5", "0"], ["83923.6", "0"], ["83929.1", "0"], ["83934.5", "0.35783"], ["83951.5", "0"]], "u": 175011, "seq": 67578174175}, "cts": 1742586310517, "record_time": 1742586310.608647, "EXCHANGE": "BYBIT"}
{"topic": "orderbook.200.BTCUSDT", "ts": 1742586310720, "type": "delta", "data": {"s": "BTCUSDT", "b": [["83882.9", "0.096066"], ["83874.5", "0.231"], ["83869.3", "0.15836"], ["83867.7", "0.008"], ["83865.8", "0.056"], ["83862.6", "0.066648"], ["83855.6", "0.06259"], ["83850.7", "0"], ["83850.1", "0.178821"], ["83848.6", "0.11714"], ["83846.6", "0.005835"], ["83846.5", "0"], ["83846.2", "0.07776"], ["83846.1", "0.039634"], ["83845.9", "0.303995"], ["83845", "0"], ["83844.9", "0"], ["83844.6", "0.012881"], ["83844.5", "0.012881"], ["83844.4", "0"], ["83843.1", "0.001466"], ["83843", "0"], ["83842.7", "0.049547"], ["83842.6", "0.049547"], ["83838.1", "0.146021"], ["83832.1", "0.357965"], ["83827.2", "0"], ["83825.8", "10.426524"], ["83825", "0.000118"], ["83820.8", "0"], ["83820.2", "0"]], "a": [["83883", "0.652644"], ["83890.8", "0"], ["83895.3", "0.287124"], ["83897.6", "0.058559"], ["83900.1", "0"], ["83904.6", "0.056742"], ["83910.3", "0"], ["83911.6", "0.119424"], ["83920", "0.051491"], ["83922.2", "0"], ["83922.8", "0"], ["83923.6", "0.022535"]], "u": 175012, "seq": 67578174307}, "cts": 1742586310716, "record_time": 1742586310.808248, "EXCHANGE": "BYBIT"}
{"topic": "orderbook.200.BTCUSDT", "ts": 1742586310920, "type": "delta", "data": {"s": "BTCUSDT", "b": [["83874.6", "0.000822"], ["83867.7", "0.008153"], ["83863.2", "0.111554"], ["83862.6", "0.067364"], ["83855.6", "0.060017"], ["83853.2", "0.183443"], ["83848.6", "0.109106"], ["83846.2", "0.165321"], ["83842.8", "0.04171"], ["83832.1", "0.000149"], ["83831", "0.359154"], ["83816.6", "0.08941"], ["83811.1", "0"], ["83810.8", "0"], ["83810.7", "0"]], "a": [["83883", "0.6433"], ["83893.6", "0.012984"], ["83897.6", "0.056305"], ["83899.8", "0.093776"], ["83902.9", "0.003"], ["83904.6", "0.055982"], ["83911.6", "0.119737"], ["83912.1", "1.197137"], ["83923.6", "0"], ["83934.4", "0.357817"], ["83934.5", "0"]], "u": 175013, "seq": 67578174380}, "cts": 1742586310909, "record_time": 1742586311.009225, "EXCHANGE": "BYBIT"}
{"topic": "orderbook.200.BTCUSDT", "ts": 1742586311120, "type": "delta", "data": {"s": "BTCUSDT", "b": [["83874.6", "0.000524"], ["83862.6", "0.062921"], ["83855.6", "0.06017"], ["83850.4", "0.138655"], ["83848.6", "0.124274"], ["83838.1", "0.146006"], ["83836.8", "0.02503"], ["83832", "0.033946"], ["83831", "0.001333"], ["83830.3", "0.357823"], ["83813.1", "0"], ["83812.1", "0"]], "a": [["83897.6", "0.056306"], ["83904.6", "0.056978"], ["83911.6", "0.112716"], ["83915.9", "0"], ["83920.8", "0.024212"], ["83921.3", "0.16749"], ["83934.3", "0.357823"], ["83934.4", "0"], ["83950.5", "0"]], "u": 175014, "seq": 67578174453}, "cts": 1742586311113, "record_time": 1742586311.207661, "EXCHANGE": "BYBIT"}
{"topic": "orderbook.200.BTCUSDT", "ts": 1742586311320, "type": "delta", "data": {"s": "BTCUSDT", "b": [["83830.3", "0"], ["83827.2", "0.357826"]], "a": [["83883", "0.6493"], ["83883.7", "0.00252"], ["83914", "0"], ["83916.8", "2.561516"], ["83917.7", "0.10236"], ["83934.2", "0.357826"], ["83934.3", "0"]], "u": 175015, "seq": 67578174510}, "cts": 1742586311310, "record_time": 1742586311.409924, "EXCHANGE": "BYBIT"}
{"topic": "orderbook.200.BTCUSDT", "ts": 1742586311519, "type": "delta", "data": {"s": "BTCUSDT", "b": [["83867.7", "0.008"], ["83862.6", "0.060596"], ["83855.6", "0.061827"], ["83848.6", "0.116167"], ["83841.8", "0.178821"], ["83838.1", "0.146004"], ["83835.1", "0"], ["83834.7", "0.059499"], ["83829.6", "0.357825"], ["83827.2", "0"]], "a": [["83883", "0.651088"], ["83884.3", "0.0032"], ["83885.5", "0.025175"], ["83897.6", "0.056497"], ["83904.6", "0.054592"], ["83911.6", "0.124269"], ["83912.1", "0"], ["83913", "0.0016"], ["83914.2", "0"], ["83918.4", "0"], ["83934.1", "0.357829"], ["83934.2", "0"], ["83950.5", "0.130533"], ["83951.5", "0.005457"]], "u": 175016, "seq": 67578174598}, "cts": 1742586311505, "record_time": 1742586311.612441, "EXCHANGE": "BYBIT"}
{"success": true, "ret_msg": "subscribe", "conn_id": "be23e606-2b32-4149-8f1c-1c4e60bc8df1", "op": "subscribe", "record_time": 1742586504.577576, "EXCHANGE": "BYBIT"}
