{"topic": "orderbook.200.BTCUSDT", "ts": 1741868504209, "type": "snapshot", "data": {"s": "BTCUSDT", "b": [["83049.99", "0.17625"], ["83047.41", "0.000099"], ["83046.28", "0.00009"], ["83045.77", "0.016862"], ["83045.75", "0.00011"], ["83045.74", "0.01439"], ["83045.14", "0.000238"], ["83044.47", "0.001467"], ["83044.46", "0.04"], ["83043.79", "0.00009"], ["83043.25", "0.00011"], ["83042.2", "0.135092"], ["83042.19", "0.06"], ["83041.98", "0.028621"], ["83041.69", "0.115495"], ["83041.68", "0.162"], ["83041.3", "0.00009"], ["83040.99", "0.000238"], ["83040.91", "0.028622"], ["83040.8", "0.04"], ["83040.76", "0.00011"], ["83040.66", "0.008045"], ["83040.6", "0.04"], ["83039.9", "0.001467"], ["83039.1", "0.04"], ["83039.01", "0.036904"], ["83039", "0.04"], ["83038.81", "0.00009"], ["83038.4", "0.001003"], ["83038.36", "0.00015"], ["83038.27", "0.00011"], ["83038.05", "0.001333"], ["83037.5", "0.04"], ["83037.3", "0.04"], ["83036.84", "0.000238"], ["83036.32", "0.00009"], ["83035.9", "0.04"], ["83035.87", "0.028"], ["83035.86", "0.006164"], ["83035.83", "0.1157"], ["83035.78", "0.32751"], ["83035.71", "0.11117"], ["83035.6", "0.04"], ["83035.44", "0.023678"], ["83035.34", "0.001467"], ["83034.81", "0.117673"], ["83034.67", "0.000091"], ["83034.2", "0.04"], ["83034.14", "0.11876"], ["83034.02", "0.240865"], ["83034", "0.04"], ["83033.9", "0.001333"], ["83033.83", "0.00009"], ["83033.29", "0.00011"], ["83033.2", "0.115043"], ["83032.78", "0.192682"], ["83032.69", "0.000238"], ["83032.36", "0.24087"], ["83031.78", "0.05212"], ["83031.67", "0.036129"], ["83031.61", "0.400061"], ["83031.6", "0.883378"], ["83031.34", "0.00009"], ["83031.3", "0.0006"], ["83030.83", "0.001522"], ["83030.8", "0.00011"], ["83030.77", "0.001467"], ["83030.11", "0.159399"], ["83029.75", "0.001333"], ["83029.39", "0.018068"], ["83029.07", "0.003497"], ["83028.85", "0.00009"], ["83028.67", "0.162"], ["83028.54", "0.000239"], ["83028.31", "0.00011"], ["83027.98", "0.024082"], ["83027.71", "0.072278"], ["83027.55", "0.110709"], ["83027.14", "0.240885"], ["83026.85", "0.024525"], ["83026.54", "0.012042"], ["83026.48", "0.000091"], ["83026.36", "0.00009"], ["83026.29", "0.019025"], ["83026.2", "0.180962"], ["83026.03", "0.167331"], ["83025.82", "0.00011"], ["83025.81", "0.001"], ["83025.59", "0.001333"], ["83025.01", "0.161092"], ["83024.39", "0.000239"], ["83023.86", "0.00009"], ["83023.33", "0.00011"], ["83023.13", "0.000408"], ["83023.11", "0.28032"], ["83023.02", "0.43642"], ["83023.01", "1.396183"], ["83022.59", "0.018063"], ["83022.01", "0.00379"], ["83021.82", "0.009375"], ["83021.64", "0.001467"], ["83021.44", "0.001333"], ["83021.37", "0.00009"], ["83020.85", "0.024083"], ["83020.84", "0.00011"], ["83020.23", "0.000239"], ["83019.2", "0.271465"], ["83018.88", "0.00009"], ["83018.85", "0.240819"], ["83018.64", "0.162172"], ["83018.6", "0.0024"], ["83018.51", "0.006021"], ["83018.35", "0.00011"], ["83018.29", "0.000091"], ["83017.83", "0.240819"], ["83017.29", "0.001333"], ["83017.07", "0.001467"], ["83016.93", "0.273701"], ["83016.41", "0.009"], ["83016.39", "0.00009"], ["83016.08", "0.000239"], ["83015.89", "0.006021"], ["83015.85", "0.00011"], ["83014.7", "0.240819"], ["83014.51", "0.278175"], ["83013.9", "0.00009"], ["83013.63", "0.003"], ["83013.36", "0.00011"], ["83013.21", "0.05212"], ["83013.14", "0.001333"], ["83012.8", "0.240819"], ["83012.5", "0.001467"], ["83011.93", "0.000239"], ["83011.41", "0.00009"], ["83010.87", "0.00011"], ["83010.55", "0.289637"], ["83010.33", "0.162"], ["83010.15", "0.36522"], ["83010.1", "0.000091"], ["83009.38", "0.473172"], ["83009.14", "0.011371"], ["83008.99", "0.001333"], ["83008.92", "0.00009"], ["83008.38", "0.00011"], ["83007.94", "0.001467"], ["83007.78", "0.000239"], ["83007.67", "0.11"], ["83006.58", "0.357743"], ["83006.43", "0.00009"], ["83005.89", "0.00011"], ["83005.32", "0.00158"], ["83004.88", "0.000602"], ["83004.84", "0.001333"], ["83003.94", "0.00009"], ["83003.63", "0.000239"], ["83003.4", "0.00011"], ["83003.37", "0.001467"], ["83003.24", "0.024084"], ["83002.3", "0.018068"], ["83001.91", "0.000091"], ["83001.45", "0.00009"], ["83001.38", "0.016397"], ["83000.91", "0.00011"], ["83000.69", "0.001333"], ["82999.6", "0.0006"], ["82999.51", "0.024084"], ["82999.48", "0.000239"], ["82999.24", "0.02016"], ["82999.1", "0.024084"], ["82999.01", "0.024084"], ["82998.96", "0.00009"], ["82998.81", "0.001467"], ["82998.42", "0.00011"], ["82998.07", "0.024082"], ["82997.44", "0.015"], ["82997.11", "0.361281"], ["82997.1", "0.650626"], ["82996.86", "0.0015"], ["82996.85", "0.162"], ["82996.54", "0.001333"], ["82996.47", "0.00009"], ["82995.93", "0.00011"], ["82995.33", "0.000239"], ["82994.24", "0.001467"], ["82993.98", "0.00009"], ["82993.94", "0.180614"], ["82993.72", "0.000091"], ["82993.44", "0.00011"], ["82993.39", "0.006021"], ["82992.96", "0.001"], ["82992.87", "0.060013"], ["82992.39", "0.001333"], ["82992.26", "0.001"], ["82991.49", "0.00009"], ["82991.45", "0.000366"], ["82991.18", "0.000239"], ["82990.95", "0.00011"], ["82990.55", "0.001649"], ["82989.68", "0.001467"], ["82989", "0.00009"]], "a": [["83050", "4.945933"], ["83050.25", "0.001664"], ["83050.51", "0.001333"], ["83050.73", "0.00011"], ["83050.86", "0.00315"], ["83051.27", "0.00009"], ["83053.22", "0.00011"], ["83053.3", "0.001"], ["83053.45", "0.000238"], ["83053.61", "0.001467"], ["83053.76", "0.00009"], ["83054.66", "0.001333"], ["83055.19", "0.000676"], ["83055.71", "0.00011"], ["83055.86", "0.002199"], ["83056.25", "0.00009"], ["83056.86", "0.0015"], ["83057.3", "0.0028"], ["83057.6", "0.000238"], ["83058.17", "0.001467"], ["83058.2", "0.00011"], ["83058.3", "0.166366"], ["83058.31", "0.162"], ["83058.74", "0.00009"], ["83058.81", "0.001333"], ["83059.31", "0.001003"], ["83059.35", "0.240819"], ["83060.12", "0.072249"], ["83060.7", "0.00011"], ["83060.71", "0.108382"], ["83060.84", "0.00061"], ["83061.03", "0.116404"], ["83061.23", "0.00009"], ["83061.33", "0.183784"], ["83061.58", "0.045585"], ["83061.75", "0.000238"], ["83061.82", "0.000091"], ["83062.12", "0.009582"], ["83062.31", "0.002791"], ["83062.74", "0.001467"], ["83062.96", "0.001333"], ["83063.01", "0.113384"], ["83063.19", "0.00011"], ["83063.3", "0.107032"], ["83063.5", "0.00301"], ["83063.51", "0.240819"], ["83063.55", "0.045586"], ["83063.73", "0.00009"], ["83064.16", "0.000153"], ["83064.94", "0.01951"], ["83064.97", "0.002261"], ["83065.43", "0.348384"], ["83065.44", "0.240774"], ["83065.68", "0.00011"], ["83065.91", "0.000238"], ["83065.99", "0.000673"], ["83066.19", "0.05212"], ["83066.22", "0.00009"], ["83067.1", "0.240769"], ["83067.12", "0.001333"], ["83067.31", "0.001467"], ["83067.7", "0.068"], ["83067.91", "0.162"], ["83068.1", "0.064"], ["83068.17", "0.00011"], ["83068.61", "0.178648"], ["83068.65", "0.240819"], ["83068.71", "0.00009"], ["83068.76", "0.144353"], ["83068.96", "0.002"], ["83069.5", "0.068"], ["83069.59", "0.184267"], ["83069.6", "0.064"], ["83070.01", "0.000091"], ["83070.06", "0.000238"], ["83070.3", "0.172388"], ["83070.36", "0.03797"], ["83070.51", "0.171006"], ["83070.66", "0.00011"], ["83070.83", "0.159052"], ["83071", "0.056"], ["83071.2", "0.00009"], ["83071.27", "0.001333"], ["83071.4", "0.048"], ["83071.88", "0.001467"], ["83071.91", "0.00619"], ["83072.03", "0.030465"], ["83072.13", "0.000123"], ["83072.44", "0.024206"], ["83072.7", "0.04"], ["83072.8", "0.06"], ["83072.81", "0.240819"], ["83073.15", "0.00011"], ["83073.29", "0.001"], ["83073.63", "0.003"], ["83073.69", "0.00009"], ["83074.21", "0.000238"], ["83074.4", "0.232614"], ["83074.6", "0.04"], ["83075.34", "0.118597"], ["83075.42", "0.001333"], ["83075.61", "0.284633"], ["83075.65", "0.00011"], ["83075.69", "0.000366"], ["83076.19", "0.00009"], ["83076.22", "0.162"], ["83076.41", "0.009"], ["83076.45", "0.001467"], ["83076.81", "0.000708"], ["83077.3", "0.298514"], ["83077.8", "0.030367"], ["83078", "0.000117"], ["83078.14", "0.00011"], ["83078.2", "0.000091"], ["83078.37", "0.000238"], ["83078.47", "0.024084"], ["83078.63", "0.006021"], ["83078.68", "0.00009"], ["83079.58", "0.001333"], ["83079.93", "0.274046"], ["83080", "0.013821"], ["83080.47", "0.012041"], ["83080.63", "0.00011"], ["83080.64", "0.003789"], ["83081.01", "0.27999"], ["83081.02", "0.001467"], ["83081.17", "0.00009"], ["83081.53", "0.000199"], ["83081.73", "0.024082"], ["83082.52", "0.000238"], ["83082.58", "0.003426"], ["83083.12", "0.00011"], ["83083.27", "0.0176"], ["83083.33", "0.000556"], ["83083.66", "0.00009"], ["83083.73", "0.007354"], ["83083.78", "0.466293"], ["83083.79", "1.348406"], ["83084", "0.024086"], ["83084.35", "0.000085"], ["83084.53", "0.162"], ["83084.62", "0.018068"], ["83084.73", "0.000088"], ["83085.59", "0.001467"], ["83085.62", "0.00011"], ["83085.88", "0.012042"], ["83086.06", "0.072227"], ["83086.16", "0.00009"], ["83086.39", "0.000091"], ["83086.53", "0.024084"], ["83086.67", "0.018063"], ["83086.68", "0.000238"], ["83086.86", "0.0015"], ["83087.03", "0.024084"], ["83087.65", "0.0003"], ["83087.66", "0.0001"], ["83087.89", "0.001333"], ["83087.94", "0.000602"], ["83088.11", "0.00011"], ["83088.65", "0.00009"], ["83089.18", "0.001"], ["83089.42", "0.024084"], ["83089.92", "0.00285"], ["83090.16", "0.001467"], ["83090.5", "0.072223"], ["83090.6", "0.00011"], ["83090.77", "0.024084"], ["83090.83", "0.018306"], ["83091.14", "0.00009"], ["83091.36", "0.008045"], ["83091.51", "0.481397"], ["83091.88", "0.240697"], ["83092.04", "0.001333"], ["83092.1", "0.000054"], ["83092.84", "0.162"], ["83093.09", "0.00011"], ["83093.27", "0.011367"], ["83093.4", "0.002636"], ["83093.63", "0.00009"], ["83093.98", "0.000091"], ["83094.54", "0.0055"], ["83094.58", "0.000091"], ["83094.73", "0.001467"], ["83095.17", "0.180614"], ["83095.3", "0.0013"], ["83095.32", "0.05212"], ["83095.45", "0.000904"], ["83095.55", "0.000125"], ["83095.59", "0.00011"], ["83096.13", "0.00009"], ["83096.19", "0.001333"], ["83096.57", "0.02706"], ["83096.79", "0.463347"], ["83097.71", "0.180614"], ["83097.8", "0.000366"], ["83097.86", "0.364834"], ["83098.08", "0.00011"], ["83098.33", "0.021836"], ["83098.51", "0.036127"], ["83098.62", "0.00009"]], "u": 6144237, "seq": 66431544210}, "cts": 1741868504206, "record_time": 1741868506.093408}
{"topic": "orderbook.200.BTCUSDT", "ts": 1741868504410, "type": "delta", "data": {"s": "BTCUSDT", "b": [["83007.67", "0"], ["82994.74", "0.2"]], "a": [["83050.22", "0.001664"], ["83050.25", "0"], ["83064.16", "0"], ["83064.52", "0.000153"], ["83075.34", "0"], ["83080.82", "0.012042"], ["83085.88", "0"], ["83098.77", "0.000111"]], "u": 6144238, "seq": 66431544253}, "cts": 1741868504401, "record_time": 1741868506.094408}
{"topic": "orderbook.200.BTCUSDT", "ts": 1741868504609, "type": "delta", "data": {"s": "BTCUSDT", "b": [["82994.74", "0"], ["82988.94", "0.240996"]], "a": [["83064.52", "0"], ["83065.14", "0.000153"], ["83074.39", "0.309251"], ["83075.75", "0.118568"], ["83098.62", "0"], ["83098.77", "0"]], "u": 6144239, "seq": 66431544290}, "cts": 1741868504605, "record_time": 1741868506.095408}
{"topic": "orderbook.200.BTCUSDT", "ts": 1741868504810, "type": "delta", "data": {"s": "BTCUSDT", "b": [["83039.14", "0.00015"], ["83038.36", "0"], ["83031.14", "0.01"], ["82988.94", "0"]], "a": [["83096.17", "0.11"], ["83098.51", "0"]], "u": 6144240, "seq": 66431544299}, "cts": 1741868504805, "record_time": 1741868506.095408}
{"topic": "orderbook.200.BTCUSDT", "ts": 1741868505010, "type": "delta", "data": {"s": "BTCUSDT", "b": [["83035.83", "0.117885"], ["83035.71", "0.111752"], ["83034.81", "0.11472"], ["83034.02", "0"], ["83033.2", "0.113576"], ["83032.36", "0"], ["83030.11", "0.180647"], ["83029.48", "0.240878"], ["83027.82", "0.240883"], ["83026.2", "0.179136"], ["83026.03", "0.174142"], ["83025.01", "0.175901"], ["83023.11", "0.298357"], ["83019.21", "0.364784"], ["83019.2", "0.280612"], ["83016.93", "0.274488"], ["83014.51", "0.275424"], ["82997.11", "0"], ["82994.22", "0.001"], ["82993.95", "0.361323"], ["82992.96", "0"], ["82989", "0"]], "a": [["83050", "4.947597"], ["83050.22", "0"], ["83058.16", "0.072251"], ["83059.34", "0.00301"], ["83060.12", "0"], ["83060.71", "0.107849"], ["83061.03", "0.114846"], ["83061.33", "0.167628"], ["83063.01", "0.120523"], ["83063.3", "0.115773"], ["83063.5", "0"], ["83068.61", "0.176408"], ["83070.3", "0.170979"], ["83070.51", "0.166515"], ["83070.83", "0.176559"], ["83075.61", "0.263583"], ["83077.3", "0.271416"], ["83079.93", "0.273104"], ["83081.01", "0.283521"], ["83081.07", "0.072231"], ["83087.65", "0"], ["83087.66", "0"], ["83087.75", "0.0003"], ["83087.76", "0.0001"], ["83090.5", "0"], ["83097.7", "0.361322"]], "u": 6144241, "seq": 66431544651}, "cts": 1741868505001, "record_time": 1741868506.096538}
{"topic": "orderbook.200.BTCUSDT", "ts": 1741868505209, "type": "delta", "data": {"s": "BTCUSDT", "b": [["83049.99", "0.166412"], ["83045.77", "0"], ["83042.2", "0.080686"], ["83041.68", "0"], ["83040.66", "0"], ["83036.63", "0.008045"], ["83035.83", "0"], ["83035.78", "0.239659"], ["83035.71", "0"], ["83034.81", "0"], ["83033.2", "0"], ["83032.78", "0.120409"], ["83030.11", "0"], ["83029.48", "0"], ["83027.82", "0"], ["83027.14", "0"], ["83027.07", "0.240885"], ["83026.2", "0.001467"], ["83026.03", "0"], ["83025.41", "0.24089"], ["83025.01", "0"], ["83024.1", "0.072281"], ["83023.11", "0"], ["83019.2", "0"], ["83018.85", "0"], ["83017.83", "0"], ["83016.93", "0"], ["83014.7", "0"], ["83014.51", "0"], ["83012.8", "0"], ["83007.35", "0.001444"], ["82997.11", "0.361313"], ["82993.95", "0"], ["82989", "0.00009"], ["82988.94", "0.240996"], ["82988.46", "0.00011"], ["82988.24", "0.001333"], ["82988.14", "0.024084"], ["82988", "0.000117"], ["82987.3", "0.0006"], ["82987.23", "0.650703"], ["82987.03", "0.000239"], ["82986.63", "0.024087"], ["82986.51", "0.00009"], ["82986.41", "0.009"], ["82985.97", "0.00011"], ["82985.84", "0.05212"], ["82985.53", "0.000091"], ["82985.12", "0.001467"]], "a": [["83050", "5.051057"], ["83052.83", "0.000153"], ["83056.38", "0.021676"], ["83056.39", "0.072253"], ["83058.16", "0"], ["83059.34", "0"], ["83060.71", "0"], ["83061.03", "0"], ["83061.57", "0.00301"], ["83063.01", "0"], ["83063.3", "0"], ["83065.14", "0"], ["83068.61", "0"], ["83070.3", "0"], ["83070.51", "0"], ["83070.83", "0"], ["83073.84", "0.01"], ["83075.61", "0"], ["83077.3", "0.003619"], ["83079.93", "0"], ["83081.01", "0"], ["83087.57", "0.0003"], ["83087.58", "0.0001"], ["83087.75", "0"], ["83087.76", "0"], ["83097.7", "0"], ["83098.51", "0.036127"], ["83098.62", "0.00009"], ["83098.77", "0.000111"], ["83099.1", "0.021895"], ["83099.3", "0.001467"], ["83099.82", "0.495033"], ["83100", "0.003135"], ["83100.35", "0.001333"], ["83100.43", "0.12"], ["83100.57", "0.00011"]], "u": 6144242, "seq": 66431544869}, "cts": 1741868505207, "record_time": 1741868506.097538}
{"topic": "orderbook.200.BTCUSDT", "ts": 1741868505409, "type": "delta", "data": {"s": "BTCUSDT", "b": [["83049.99", "0.139298"], ["83036.63", "0"], ["83035.88", "0.178235"], ["83035.86", "0"], ["83035.78", "0.00011"], ["83035.44", "0"], ["83034.39", "0.122632"], ["83034.14", "0"], ["83034.03", "0.118511"], ["83033.14", "0.008045"], ["83032.76", "0.119219"], ["83027.55", "0.170382"], ["83027.07", "0"], ["83025.76", "0.177394"], ["83025.41", "0"], ["83024.59", "0.176646"], ["83022.59", "0"], ["83022.48", "0.018064"], ["83019.21", "0"], ["83018.76", "0.277444"], ["83014.09", "0.282457"], ["82997.12", "0.361318"], ["82997.11", "0"], ["82993.94", "0"], ["82988.94", "0"], ["82988.54", "0.162"], ["82985.12", "0"]], "a": [["83050", "4.947597"], ["83052.83", "0"], ["83053.89", "0.022999"], ["83056.3", "0.072253"], ["83056.38", "0"], ["83056.39", "0"], ["83059.34", "0.00301"], ["83059.93", "0.05212"], ["83060.29", "0.114278"], ["83061.33", "0.130574"], ["83061.57", "0"], ["83062.86", "0.114644"], ["83064.25", "0.000153"], ["83066.19", "0"], ["83069.86", "0.159253"], ["83070.09", "0.170082"], ["83072.81", "0"], ["83073.61", "0.003624"], ["83074.39", "0"], ["83075.57", "0.012043"], ["83076.86", "0.274806"], ["83078.13", "0.003513"], ["83078.54", "0.02706"], ["83080.59", "0.281184"], ["83080.82", "0"], ["83081.01", "0.021895"], ["83081.35", "0.018064"], ["83082.58", "0"], ["83086.27", "0.0003"], ["83086.28", "0.0001"], ["83086.67", "0"], ["83087.57", "0"], ["83087.58", "0"], ["83096.57", "0"], ["83096.78", "0.361321"], ["83099.1", "0"], ["83099.3", "0"], ["83099.82", "0"], ["83100", "0"], ["83100.35", "0"], ["83100.43", "0"], ["83100.57", "0"]], "u": 6144243, "seq": 66431545452}, "cts": 1741868505406, "record_time": 1741868506.097538}
{"topic": "orderbook.200.BTCUSDT", "ts": 1741868505610, "type": "delta", "data": {"s": "BTCUSDT", "b": [["83045.75", "0.016939"], ["83035.88", "0.217002"], ["83035.67", "0.006202"], ["83035.34", "0.024974"], ["83034.39", "0"], ["83032.78", "0"], ["83032.76", "0"], ["83026.85", "0"], ["83025.76", "0"], ["83024.59", "0"], ["83019.55", "0.023925"], ["83018.76", "0"], ["83014.7", "0.240819"], ["83014.09", "0"], ["83013.67", "0.240819"], ["83009.52", "0.240819"], ["82997.13", "0.361316"], ["82997.12", "0"], ["82997.1", "0"], ["82993.94", "0.180614"], ["82992.87", "0"], ["82991.35", "0.180614"], ["82987.23", "0"], ["82985.12", "0.001467"], ["82984.79", "0.00602"], ["82984.09", "0.001333"], ["82984.02", "0.00009"]], "a": [["83060.29", "0"], ["83061.33", "0.234177"], ["83062.86", "0"], ["83064.5", "0.240819"], ["83069.86", "0"], ["83070.09", "0"], ["83073.59", "0.120409"], ["83076.86", "0"], ["83080.59", "0"], ["83081.01", "0"], ["83091.41", "0.021895"], ["83096.78", "0"], ["83099.3", "0.001467"], ["83099.82", "0.495033"], ["83100", "0.003135"], ["83100.35", "0.001333"], ["83100.43", "0.12"]], "u": 6144244, "seq": 66431545754}, "cts": 1741868505601, "record_time": 1741868506.098538}
{"topic": "orderbook.200.BTCUSDT", "ts": 1741868505809, "type": "delta", "data": {"s": "BTCUSDT", "b": [["83049.99", "0.242758"], ["83042.2", "0.135092"], ["83041.68", "0.162"], ["83039.01", "0.09712"], ["83036.57", "0.10757"], ["83036.38", "0.108675"], ["83035.88", "0.116054"], ["83035.35", "0.119159"], ["83033.82", "0.240866"], ["83033.78", "0.119531"], ["83032.88", "0.072273"], ["83032.16", "0.240871"], ["83030.78", "0.160491"], ["83030.62", "0.240875"], ["83027.55", "0"], ["83026.78", "0.165262"], ["83026.77", "0.172893"], ["83025.55", "0.182465"], ["83024.1", "0"], ["83023.78", "0.266686"], ["83019.78", "0.30169"], ["83018.85", "0.240819"], ["83017.67", "0.288048"], ["83015.05", "0.271176"], ["83000.25", "0.026014"], ["82997.14", "0.361305"], ["82997.13", "0"], ["82992.66", "0.65066"], ["82989", "0"], ["82988.54", "0"], ["82988.46", "0"], ["82988.24", "0"], ["82988.14", "0"], ["82988", "0"], ["82987.3", "0"], ["82987.03", "0"], ["82986.63", "0"], ["82986.51", "0"], ["82986.41", "0"], ["82985.97", "0"], ["82985.84", "0"], ["82985.53", "0"], ["82985.12", "0"], ["82984.79", "0"], ["82984.09", "0"], ["82984.02", "0"]], "a": [["83053.89", "0"], ["83056.3", "0"], ["83059.34", "0"], ["83061.25", "0.118723"], ["83061.77", "0.113727"], ["83063.5", "0.00301"], ["83063.68", "0.106632"], ["83063.88", "0.113604"], ["83069.28", "0.166495"], ["83069.59", "0"], ["83070.88", "0.182163"], ["83071.05", "0.167438"], ["83071.57", "0.159654"], ["83073.61", "0"], ["83074.39", "0.174575"], ["83075.57", "0"], ["83076.28", "0.278652"], ["83077.88", "0.294633"], ["83078.54", "0"], ["83080.26", "0.012042"], ["83080.67", "0.268242"], ["83081.07", "0"], ["83081.55", "0.283476"], ["83086.17", "0.0003"], ["83086.18", "0.0001"], ["83086.27", "0"], ["83086.28", "0"], ["83089.53", "0.072224"], ["83091.41", "0"], ["83096.23", "0.02706"], ["83098.51", "0"], ["83098.62", "0"], ["83098.77", "0"], ["83099.3", "0"], ["83099.82", "0"], ["83100", "0"], ["83100.35", "0"], ["83100.43", "0"]], "u": 6144245, "seq": 66431545911}, "cts": 1741868505806, "record_time": 1741868506.099538}
{"topic": "orderbook.200.BTCUSDT", "ts": 1741868506010, "type": "delta", "data": {"s": "BTCUSDT", "b": [["83035.88", "0.315614"], ["83026.79", "0.246838"], ["82997.15", "0.361301"], ["82997.14", "0"], ["82989.68", "0"]], "a": [["83058.74", "0.072341"]], "u": 6144246, "seq": 66431545939}, "cts": 1741868506006, "record_time": 1741868506.099538}
{"topic": "orderbook.200.BTCUSDT", "ts": 1741868506210, "type": "delta", "data": {"s": "BTCUSDT", "b": [["83049.99", "0.242885"], ["83038.01", "0.05212"], ["83031.78", "0"], ["83031.29", "0.012042"], ["83029.3", "0.120409"], ["83027.05", "0.018063"], ["83026.54", "0"], ["83026.47", "0.023513"], ["83022.48", "0"], ["83019.55", "0"], ["83006.59", "0.36127"], ["82997.15", "0"], ["82992.66", "0"]], "a": [["83058.74", "0.00009"], ["83059.93", "0"], ["83063.5", "0"], ["83066.34", "0.072244"], ["83070.46", "0.05212"], ["83071.04", "0.00301"], ["83073.59", "0"], ["83073.84", "0"], ["83080.26", "0"], ["83081.35", "0"], ["83085.49", "0.012041"], ["83085.76", "0.018063"], ["83086.06", "0"], ["83086.17", "0"], ["83086.18", "0"], ["83087.37", "0.0003"], ["83087.38", "0.0001"], ["83094.75", "0.072219"], ["83096.17", "0"], ["83098.51", "0.036127"], ["83098.62", "0.00009"]], "u": 6144247, "seq": 66431546123}, "cts": 1741868506205, "record_time": 1741868506.100538}
{"topic": "orderbook.200.BTCUSDT", "ts": 1741868506409, "type": "delta", "data": {"s": "BTCUSDT", "b": [["83049.99", "0.252374"], ["83039.01", "0.12403"], ["83036.68", "0.11531"], ["83036.63", "0.012041"], ["83036.57", "0"], ["83036.44", "0.109386"], ["83036.38", "0"], ["83036.31", "0.034891"], ["83035.42", "0.117992"], ["83035.35", "0"], ["83033.86", "0.114967"], ["83033.82", "0"], ["83033.78", "0"], ["83033.14", "0"], ["83032.4", "0.018062"], ["83031.29", "0"], ["83030.84", "0.175036"], ["83030.78", "0"], ["83027.05", "0"], ["83026.88", "0.17078"], ["83026.86", "0.168859"], ["83026.78", "0"], ["83026.77", "0"], ["83025.62", "0.181251"], ["83025.55", "0"], ["83023.84", "0.26304"], ["83023.78", "0"], ["83019.86", "0.293074"], ["83019.78", "0"], ["83017.78", "0.276009"], ["83017.67", "0"], ["83015.16", "0.026014"], ["83015.12", "0.3064"], ["83015.05", "0"], ["83014.07", "0.060115"], ["83013.67", "0"], ["83010.56", "0.361252"], ["83009.52", "0"], ["83007.35", "0"], ["83006.59", "0"], ["83000.56", "0.020732"], ["83000.25", "0"], ["82997.68", "0.650621"], ["82991.35", "0"], ["82989.68", "0.001467"], ["82989", "0.00009"]], "a": [["83050", "4.945933"], ["83050.08", "0.001664"], ["83058.3", "0.117481"], ["83061.25", "0"], ["83061.32", "0.111458"], ["83061.77", "0"], ["83061.88", "0.116134"], ["83063.68", "0"], ["83063.74", "0.115813"], ["83063.88", "0"], ["83063.96", "0.111804"], ["83065.08", "0.072245"], ["83066.34", "0"], ["83069.28", "0"], ["83069.34", "0.159193"], ["83069.49", "0.300833"], ["83070.46", "0"], ["83070.88", "0"], ["83070.96", "0.168344"], ["83071.04", "0"], ["83071.05", "0"], ["83071.12", "0.175706"], ["83071.57", "0"], ["83071.68", "0.164202"], ["83072.81", "0.240819"], ["83075.02", "0.05212"], ["83075.74", "0.00301"], ["83076.28", "0"], ["83076.34", "0.294933"], ["83077.88", "0"], ["83077.96", "0.272437"], ["83080.67", "0"], ["83080.78", "0.266431"], ["83081.55", "0"], ["83081.62", "0.301513"], ["83085.76", "0"], ["83087.37", "0"], ["83087.38", "0"], ["83087.57", "0.0003"], ["83087.58", "0.0001"], ["83089.37", "0.072224"], ["83089.53", "0"], ["83090.95", "0.018062"], ["83091.36", "0"], ["83096.23", "0"], ["83098.62", "0"]], "u": 6144248, "seq": 66431546461}, "cts": 1741868506407, "record_time": 1741868506.21034}
{"topic": "orderbook.200.BTCUSDT", "ts": 1741868506610, "type": "delta", "data": {"s": "BTCUSDT", "b": [["83049.99", "0.144481"], ["83039.62", "0.008045"], ["83039.01", "0.061962"], ["83036.68", "0"], ["83036.44", "0"], ["83035.88", "0.209243"], ["83035.48", "0.11529"], ["83035.42", "0"], ["83035.21", "0.111081"], ["83034.55", "0.10713"], ["83033.86", "0"], ["83032.92", "0.121045"], ["83030.84", "0"], ["83029.61", "0.162757"], ["83026.88", "0"], ["83026.86", "0"], ["83026.79", "0"], ["83025.92", "0.159581"], ["83025.68", "0.170432"], ["83025.62", "0"], ["83024.75", "0.18201"], ["83023.84", "0"], ["83022.61", "0.286093"], ["83019.86", "0"], ["83018.92", "0.291917"], ["83017.83", "0.240819"], ["83017.78", "0"], ["83016.58", "0.281006"], ["83015.12", "0"], ["83014.25", "0.304345"], ["83013.67", "0.240819"], ["83000.56", "0"], ["82996.91", "0.2"], ["82991.35", "0.180614"], ["82990.55", "0"], ["82989.68", "0"], ["82989", "0"]], "a": [["83050.02", "0.001664"], ["83050.08", "0"], ["83058.3", "0.126607"], ["83060.45", "0.109321"], ["83060.68", "0.113679"], ["83061.32", "0"], ["83061.88", "0"], ["83062.51", "0.10648"], ["83063.02", "0.120435"], ["83063.74", "0"], ["83063.96", "0"], ["83064.25", "0"], ["83065.27", "0.000153"], ["83068.11", "0.158041"], ["83068.72", "0.05212"], ["83069.34", "0"], ["83070.02", "0.180349"], ["83070.25", "0.17731"], ["83070.48", "0.163782"], ["83070.96", "0"], ["83071.12", "0"], ["83071.68", "0"], ["83072.43", "0.00301"], ["83075.02", "0"], ["83075.11", "0.283834"], ["83075.74", "0"], ["83076.34", "0"], ["83077.02", "0.278021"], ["83077.96", "0"], ["83079.58", "0.293376"], ["83080.75", "0.302522"], ["83080.78", "0"], ["83081.62", "0"], ["83098.62", "0.00009"]], "u": 6144249, "seq": 66431546666}, "cts": 1741868506607, "record_time": 1741868506.410063}
{"topic": "orderbook.200.BTCUSDT", "ts": 1741868506810, "type": "delta", "data": {"s": "BTCUSDT", "b": [["83049.99", "0.143481"], ["83046.66", "0.008045"], ["83039.62", "0"], ["83036.63", "0"], ["83035.88", "0.297645"], ["83035.52", "0.10786"], ["83035.48", "0"], ["83035.27", "0.115577"], ["83035.21", "0"], ["83034.58", "0.118456"], ["83034.55", "0"], ["83032.95", "0.116074"], ["83032.92", "0"], ["83032.43", "0.012042"], ["83031.14", "0"], ["83029.67", "0.174098"], ["83029.61", "0"], ["83025.95", "0.161386"], ["83025.92", "0"], ["83025.72", "0.158329"], ["83025.68", "0"], ["83024.78", "0.170924"], ["83024.75", "0"], ["83022.67", "0.281879"], ["83022.61", "0"], ["83018.95", "0.267619"], ["83018.92", "0"], ["83016.62", "0.282065"], ["83016.58", "0"], ["83014.28", "0.292154"], ["83014.25", "0"], ["83010.56", "0"], ["82997.69", "0.361277"], ["82996.91", "0"], ["82990.55", "0.001649"], ["82989.68", "0.001467"]], "a": [["83050", "4.947597"], ["83050.02", "0"], ["83058.3", "0.179683"], ["83060.45", "0"], ["83060.48", "0.120821"], ["83060.68", "0"], ["83060.72", "0.106771"], ["83061.55", "0.072248"], ["83062.51", "0"], ["83062.57", "0.108082"], ["83063.02", "0"], ["83063.05", "0.118966"], ["83065.08", "0"], ["83065.27", "0"], ["83065.31", "0.000153"], ["83068.11", "0"], ["83068.17", "0.168893"], ["83069.48", "0.00301"], ["83070.02", "0"], ["83070.05", "0.179693"], ["83070.25", "0"], ["83070.28", "0.181447"], ["83070.48", "0"], ["83070.52", "0.173203"], ["83072.43", "0"], ["83075.11", "0"], ["83075.17", "0.278586"], ["83077.02", "0"], ["83077.05", "0.264841"], ["83079.57", "0.188165"], ["83079.58", "0.001333"], ["83079.62", "0.267872"], ["83080.75", "0"], ["83080.78", "0.267426"], ["83086.02", "0.018063"], ["83087.57", "0"], ["83087.58", "0"], ["83087.67", "0.0003"], ["83087.68", "0.0001"], ["83090.65", "0.008045"], ["83090.95", "0"], ["83098.62", "0"]], "u": 6144250, "seq": 66431546914}, "cts": 1741868506807, "record_time": 1741868506.611358}
{"topic": "orderbook.200.BTCUSDT", "ts": 1741868507010, "type": "delta", "data": {"s": "BTCUSDT", "b": [["83049.99", "0.139869"], ["83039.01", "0.120904"], ["83036.63", "0.109797"], ["83036.4", "0.109159"], ["83035.52", "0"], ["83035.39", "0.119691"], ["83035.27", "0"], ["83034.58", "0"], ["83033.82", "0.120709"], ["83032.95", "0"], ["83030.8", "0.173467"], ["83029.67", "0"], ["83026.83", "0.166241"], ["83026.82", "0.170031"], ["83025.95", "0"], ["83025.72", "0"], ["83025.59", "0.162171"], ["83024.78", "0"], ["83023.8", "0.300046"], ["83023.01", "0"], ["83022.67", "0"], ["83019.82", "0.299312"], ["83018.96", "0.36614"], ["83018.95", "0"], ["83017.73", "0.277446"], ["83016.62", "0"], ["83015.09", "0.278987"], ["83014.28", "0"], ["82997.73", "0.001"], ["82994.22", "0"], ["82989", "0.00009"], ["82988.46", "0.00011"]], "a": [["83058.3", "0.126607"], ["83060.48", "0"], ["83060.72", "0"], ["83061.29", "0.121593"], ["83061.83", "0.119373"], ["83062.57", "0"], ["83063.05", "0"], ["83063.7", "0.112824"], ["83063.92", "0.109727"], ["83067.09", "0.00301"], ["83068.17", "0.00011"], ["83069.3", "0.176221"], ["83069.48", "0"], ["83070.05", "0"], ["83070.28", "0"], ["83070.52", "0"], ["83070.92", "0.167707"], ["83071.09", "0.169881"], ["83071.63", "0.158362"], ["83075.17", "0"], ["83076.3", "0.273878"], ["83077.05", "0"], ["83077.92", "0.277384"], ["83079.62", "0"], ["83080.73", "0.277261"], ["83080.78", "0"], ["83081.59", "0.281283"], ["83083.79", "0"], ["83087.47", "0.0003"], ["83087.48", "0.0001"], ["83087.67", "0"], ["83087.68", "0"]], "u": 6144251, "seq": 66431547082}, "cts": 1741868507005, "record_time": 1741868506.811079}
{"topic": "orderbook.200.BTCUSDT", "ts": 1741868507210, "type": "delta", "data": {"s": "BTCUSDT", "b": [["83049.99", "0.249153"], ["83039.01", "0.124202"], ["83036.63", "0"], ["83036.4", "0"], ["83035.39", "0"], ["83033.82", "0"], ["83030.8", "0.00011"], ["83029.64", "1.353409"], ["83026.83", "0"], ["83026.82", "0"], ["83025.59", "0.001333"], ["83023.8", "0"], ["83023.02", "0"], ["83019.82", "0"], ["83017.73", "0"], ["83015.09", "0"], ["83006.59", "0.361271"], ["82997.69", "0"], ["82988.54", "0.162"], ["82988.24", "0.001333"], ["82988.14", "0.024084"], ["82988", "0.000117"], ["82987.77", "0.650699"], ["82987.3", "0.0006"], ["82987.03", "0.000239"], ["82986.63", "0.024087"], ["82986.51", "0.00009"], ["82986.41", "0.009"]], "a": [["83061.29", "0"], ["83061.55", "0"], ["83061.83", "0"], ["83063.7", "0"], ["83063.92", "0"], ["83064.53", "0.072246"], ["83067.09", "0"], ["83069.3", "0"], ["83070.35", "0.00301"], ["83070.92", "0"], ["83071.09", "0"], ["83071.63", "0"], ["83076.3", "0"], ["83077.92", "0"], ["83079.57", "0"], ["83080.73", "0"], ["83081.59", "0"], ["83082.66", "1.397154"], ["83083.78", "0"], ["83098.62", "0.00009"], ["83098.77", "0.000111"], ["83099.3", "0.001467"], ["83099.82", "0.495033"], ["83100", "0.003135"], ["83100.35", "0.001333"], ["83100.43", "0.12"], ["83100.57", "0.00011"], ["83101.11", "0.00009"], ["83101.29", "0.002167"], ["83101.37", "0.001"], ["83102.09", "0.000366"], ["83102.77", "0.000091"]], "u": 6144252, "seq": 66431547371}, "cts": 1741868507206, "record_time": 1741868507.011721}
{"topic": "orderbook.200.BTCUSDT", "ts": 1741868507410, "type": "delta", "data": {"s": "BTCUSDT", "b": [["83049.99", "0.145693"], ["83039.01", "0.061962"], ["83035.88", "0.209243"], ["83035.54", "0.106282"], ["83035.3", "0.115056"], ["83034.6", "0.108527"], ["83032.97", "0.108131"], ["83031.61", "0.815059"], ["83029.7", "0.168274"], ["83025.97", "0.171173"], ["83025.74", "0.158713"], ["83024.8", "0.178528"], ["83022.7", "0.26327"], ["83018.97", "0.271185"], ["83018.96", "0"], ["83016.81", "0.11"], ["83016.64", "0.273813"], ["83014.3", "0.272714"], ["83009.39", "0.361269"], ["83006.59", "0"], ["82989", "0"], ["82988.54", "0"], ["82988.46", "0"], ["82988.24", "0"], ["82988.14", "0"], ["82988", "0"], ["82987.77", "0"], ["82987.3", "0"], ["82987.03", "0"], ["82986.63", "0"], ["82986.51", "0"], ["82986.41", "0"]], "a": [["83058.3", "0.174947"], ["83060.5", "0.106907"], ["83060.74", "0.104899"], ["83062.53", "0.072247"], ["83062.6", "0.120468"], ["83063.07", "0.113068"], ["83064.53", "0"], ["83068.2", "0.161182"], ["83069.49", "0.204667"], ["83070.07", "0.165211"], ["83070.3", "0.160672"], ["83070.35", "0"], ["83070.54", "0.177512"], ["83071.39", "0.00301"], ["83075.2", "0.286308"], ["83077.07", "0.271315"], ["83079.64", "0.267051"], ["83080.8", "0.274261"], ["83098.77", "0"], ["83099.3", "0"], ["83099.82", "0"], ["83100", "0"], ["83100.35", "0"], ["83100.43", "0"], ["83100.57", "0"], ["83101.11", "0"], ["83101.29", "0"], ["83101.37", "0"], ["83102.09", "0"], ["83102.77", "0"]], "u": 6144253, "seq": 66431547492}, "cts": 1741868507405, "record_time": 1741868507.210574}
{"topic": "orderbook.200.BTCUSDT", "ts": 1741868507610, "type": "delta", "data": {"s": "BTCUSDT", "b": [["83035.88", "0.298116"], ["83016.81", "0"], ["83009.4", "0.361265"], ["83009.39", "0"], ["82989", "0.00009"]], "a": [["83065.13", "0.000153"], ["83065.31", "0"], ["83069.49", "0.330102"]], "u": 6144254, "seq": 66431547538}, "cts": 1741868507605, "record_time": 1741868507.410101}
{"topic": "orderbook.200.BTCUSDT", "ts": 1741868507809, "type": "delta", "data": {"s": "BTCUSDT", "b": [["83009.4", "0"], ["83006.59", "0.361268"], ["83003.63", "0.200239"]], "a": [["83052.64", "0.000153"], ["83065.13", "0"]], "u": 6144255, "seq": 66431547561}, "cts": 1741868507806, "record_time": 1741868507.610108}
{"topic": "orderbook.200.BTCUSDT", "ts": 1741868508010, "type": "delta", "data": {"s": "BTCUSDT", "b": [["83049.99", "0.146763"], ["83035.55", "0.110109"], ["83035.54", "0"], ["83035.32", "0.119272"], ["83035.3", "0"], ["83034.61", "0.118809"], ["83034.6", "0"], ["83032.98", "0.11803"], ["83032.97", "0"], ["83029.72", "0.177708"], ["83029.7", "0"], ["83025.98", "0.159318"], ["83025.97", "0"], ["83025.75", "0.160858"], ["83025.74", "0"], ["83024.81", "0.174558"], ["83024.8", "0"], ["83022.72", "0.292978"], ["83022.7", "0"], ["83018.98", "0.648362"], ["83018.97", "0"], ["83016.65", "0.293146"], ["83016.64", "0"], ["83015.16", "0"], ["83014.31", "0.295565"], ["83014.3", "0"], ["83004.71", "0.026014"]], "a": [["83058.3", "0.180631"], ["83060.5", "0"], ["83060.51", "0.121978"], ["83060.74", "0"], ["83060.75", "0.108772"], ["83062.6", "0"], ["83062.62", "0.110454"], ["83063.07", "0"], ["83063.08", "0.113088"], ["83068.2", "0"], ["83068.22", "0.177207"], ["83070.07", "0"], ["83070.08", "0.181603"], ["83070.3", "0"], ["83070.31", "0.169725"], ["83070.54", "0"], ["83070.55", "0.158568"], ["83075.2", "0"], ["83075.22", "0.266467"], ["83077.07", "0"], ["83077.08", "0.302028"], ["83079.63", "0.171789"], ["83079.64", "0"], ["83079.65", "0.293362"], ["83080.8", "0"], ["83080.81", "0.281832"], ["83084.16", "0.072228"], ["83094.75", "0"], ["83098.62", "0"]], "u": 6144256, "seq": 66431547640}, "cts": 1741868508001, "record_time": 1741868507.810296}
{"topic": "orderbook.200.BTCUSDT", "ts": 1741868508209, "type": "delta", "data": {"s": "BTCUSDT", "b": [["83006.59", "0.361265"], ["83003.63", "0.000239"]], "a": [["83060.82", "0.072249"], ["83062.53", "0"], ["83069.59", "0.00301"], ["83071.39", "0"], ["83087.47", "0"], ["83087.48", "0"], ["83087.57", "0.0003"], ["83087.58", "0.0001"]], "u": 6144257, "seq": 66431547660}, "cts": 1741868508205, "record_time": 1741868508.010397}
{"topic": "orderbook.200.BTCUSDT", "ts": 1741868508410, "type": "delta", "data": {"s": "BTCUSDT", "b": [["83032.4", "0"], ["83027.54", "0.018063"], ["83006.59", "0"], ["82997.69", "0.36128"]], "a": [["83052.64", "0"], ["83052.79", "0.000153"], ["83062.31", "0"], ["83063.89", "0.00301"], ["83063.9", "0.064"], ["83069.59", "0"], ["83078.74", "0.01"], ["83080.67", "0.012042"], ["83085.49", "0"], ["83087.57", "0.0001"], ["83098.51", "0"]], "u": 6144258, "seq": 66431547705}, "cts": 1741868508406, "record_time": 1741868508.211018}
{"topic": "orderbook.200.BTCUSDT", "ts": 1741868508610, "type": "delta", "data": {"s": "BTCUSDT", "b": [["83049.99", "0.246611"], ["83036.67", "0.116113"], ["83036.42", "0.106922"], ["83035.88", "0.209243"], ["83035.55", "0"], ["83035.42", "0.110387"], ["83035.32", "0"], ["83034.61", "0"], ["83033.85", "0.120231"], ["83032.98", "0"], ["83030.82", "0.167251"], ["83029.72", "0"], ["83026.87", "0.166497"], ["83026.85", "0.171389"], ["83025.98", "0"], ["83025.75", "0"], ["83025.62", "0.166513"], ["83024.81", "0"], ["83023.82", "0.296145"], ["83022.72", "0"], ["83019.85", "0.301401"], ["83018.98", "0.364734"], ["83017.77", "0.294358"], ["83016.65", "0"], ["83015.12", "0.29426"], ["83014.31", "0"], ["83005.61", "0.11"], ["82989.68", "0"], ["82989", "0"]], "a": [["83052.79", "0"], ["83060.51", "0"], ["83060.75", "0"], ["83061.32", "0.121374"], ["83061.87", "0.113808"], ["83062.62", "0"], ["83063.08", "0"], ["83063.67", "0.000153"], ["83063.72", "0.120552"], ["83063.89", "0"], ["83063.95", "0.106831"], ["83064.93", "0.00301"], ["83068.1", "0"], ["83068.22", "0"], ["83069.32", "0.178145"], ["83070.08", "0"], ["83070.31", "0"], ["83070.55", "0"], ["83070.95", "0.170714"], ["83071.12", "0.174694"], ["83071.67", "0.16832"], ["83075.22", "0"], ["83076.32", "0.287716"], ["83077.08", "0"], ["83077.95", "0.280509"], ["83079.65", "0"], ["83080.77", "0.300046"], ["83080.81", "0"], ["83081.62", "0.287927"], ["83087.46", "0.0003"], ["83087.47", "0.0001"], ["83087.57", "0"], ["83087.58", "0"], ["83098.51", "0.036127"]], "u": 6144259, "seq": 66431547845}, "cts": 1741868508601, "record_time": 1741868508.411158}
{"topic": "orderbook.200.BTCUSDT", "ts": 1741868508810, "type": "delta", "data": {"s": "BTCUSDT", "b": [["83049.99", "0.253835"], ["83039.01", "0.122128"], ["83036.67", "0"], ["83036.42", "0"], ["83035.42", "0"], ["83033.85", "0"], ["83030.82", "0"], ["83026.87", "0"], ["83026.85", "0"], ["83025.62", "0"], ["83023.82", "0"], ["83019.85", "0"], ["83017.77", "0"], ["83015.12", "0"], ["82989.68", "0.001467"], ["82989", "0.00009"], ["82988.46", "0.00011"], ["82988.24", "0.001333"], ["82988.14", "0.024084"], ["82988", "0.000117"], ["82987.77", "0.650699"], ["82987.3", "0.0006"], ["82987.03", "0.000239"], ["82986.63", "0.024087"], ["82986.51", "0.00009"], ["82986.41", "0.009"]], "a": [["83058.3", "0.126607"], ["83060.82", "0"], ["83061.32", "0"], ["83061.87", "0"], ["83063.49", "0.072246"], ["83063.72", "0"], ["83063.95", "0"], ["83069.32", "0"], ["83070.95", "0"], ["83071.12", "0"], ["83071.67", "0"], ["83076.32", "0"], ["83077.95", "0"], ["83079.63", "0"], ["83080.77", "0"], ["83081.62", "0"], ["83087.46", "0"], ["83087.47", "0"], ["83087.56", "0.0003"], ["83087.57", "0.0001"], ["83098.62", "0.00009"], ["83098.77", "0.110111"], ["83099.3", "0.001467"], ["83099.32", "0.02706"], ["83099.82", "0.495033"], ["83100", "0.003135"], ["83100.35", "0.001333"], ["83100.43", "0.12"], ["83100.57", "0.00011"], ["83101.11", "0.00009"], ["83101.29", "0.002167"], ["83101.37", "0.001"], ["83102.09", "0.000366"]], "u": 6144260, "seq": 66431547893}, "cts": 1741868508797, "record_time": 1741868508.613001}
{"topic": "orderbook.200.BTCUSDT", "ts": 1741868509010, "type": "delta", "data": {"s": "BTCUSDT", "b": [["83039.01", "0.121817"], ["83036.75", "0.112418"], ["83036.44", "0.109581"], ["83035.47", "0.115121"], ["83033.91", "0.10931"], ["83032.96", "0.01"], ["83030.84", "0.158379"], ["83026.95", "0.157138"], ["83026.91", "0.176685"], ["83025.67", "0.180182"], ["83023.84", "0.281144"], ["83019.91", "0.294886"], ["83018.98", "0"], ["83018.86", "0.201208"], ["83017.85", "0.287544"], ["83015.17", "0.297283"], ["83005.61", "0"], ["83004.07", "0.001"], ["82997.73", "0"], ["82989.68", "0"], ["82989", "0"], ["82988.46", "0"], ["82988.24", "0"], ["82988.14", "0"], ["82988", "0"], ["82987.77", "0"], ["82987.3", "0"], ["82987.03", "0"], ["82986.63", "0"], ["82986.51", "0"], ["82986.41", "0"]], "a": [["83061.33", "0.33025"], ["83061.37", "0.118288"], ["83061.95", "0.114737"], ["83063.48", "0.00301"], ["83063.74", "0.113584"], ["83064.01", "0.107158"], ["83064.93", "0"], ["83069.34", "0.165767"], ["83069.49", "0.204667"], ["83071.01", "0.169578"], ["83071.17", "0.180237"], ["83071.75", "0.168531"], ["83073.29", "0"], ["83076.34", "0.281438"], ["83078.01", "0.276969"], ["83080.85", "0.277302"], ["83081.67", "0.26902"], ["83082.65", "0.510299"], ["83090.12", "0.001"], ["83098.62", "0"], ["83098.77", "0"], ["83099.3", "0"], ["83099.32", "0"], ["83099.82", "0"], ["83100", "0"], ["83100.35", "0"], ["83100.43", "0"], ["83100.57", "0"], ["83101.11", "0"], ["83101.29", "0"], ["83101.37", "0"], ["83102.09", "0"]], "u": 6144261, "seq": 66431547959}, "cts": 1741868509007, "record_time": 1741868508.811785}
{"topic": "orderbook.200.BTCUSDT", "ts": 1741868509210, "type": "delta", "data": {"s": "BTCUSDT", "b": [["83046.66", "0"], ["83036.75", "0"], ["83036.69", "0.111015"], ["83035.47", "0"], ["83035.44", "0.110238"], ["83033.91", "0"], ["83033.87", "0.115708"], ["83026.95", "0"], ["83026.91", "0"], ["83026.89", "0.166609"], ["83026.87", "0.168791"], ["83025.67", "0"], ["83025.64", "0.163855"], ["83019.91", "0"], ["83019.87", "0.292096"], ["83017.85", "0"], ["83017.79", "0.270131"], ["83015.17", "0"], ["83015.14", "0.267571"], ["82997.45", "0.2"], ["82991.45", "0"], ["82989.68", "0.001467"]], "a": [["83061.34", "0.111088"], ["83061.37", "0"], ["83061.89", "0.119895"], ["83061.95", "0"], ["83063.48", "0"], ["83063.97", "0.116387"], ["83064.01", "0"], ["83065.42", "0.00301"], ["83069.49", "0.333684"], ["83070.97", "0.17261"], ["83071.01", "0"], ["83071.14", "0.170669"], ["83071.17", "0"], ["83071.69", "0.173599"], ["83071.75", "0"], ["83077.97", "0.277705"], ["83078.01", "0"], ["83080.79", "0.287364"], ["83080.85", "0"], ["83081.64", "0.274616"], ["83081.67", "0"], ["83087.46", "0.0003"], ["83087.47", "0.0001"], ["83087.56", "0"], ["83087.57", "0"], ["83090.65", "0"], ["83098.62", "0.00009"]], "u": 6144262, "seq": 66431548032}, "cts": 1741868509206, "record_time": 1741868509.01191}
{"topic": "orderbook.200.BTCUSDT", "ts": 1741868509410, "type": "delta", "data": {"s": "BTCUSDT", "b": [["82997.45", "0"], ["82989", "0.00009"]], "a": [["83061.67", "0.072248"], ["83063.49", "0"], ["83064.93", "0.00301"], ["83065.42", "0"]], "u": 6144263, "seq": 66431548055}, "cts": 1741868509406, "record_time": 1741868509.212508}
{"topic": "orderbook.200.BTCUSDT", "ts": 1741868509610, "type": "delta", "data": {"s": "BTCUSDT", "b": [["83049.99", "0.150375"], ["83039.01", "0.061962"], ["83036.69", "0"], ["83036.44", "0"], ["83035.88", "0.300037"], ["83035.54", "0.105854"], ["83035.44", "0"], ["83035.3", "0.113204"], ["83034.6", "0.117697"], ["83033.87", "0"], ["83032.97", "0.106767"], ["83030.84", "0"], ["83029.7", "0.177585"], ["83026.89", "0"], ["83026.87", "0"], ["83025.97", "0.165972"], ["83025.74", "0.167977"], ["83025.64", "0"], ["83024.8", "0.164378"], ["83023.84", "0"], ["83022.7", "0.265294"], ["83019.87", "0"], ["83018.97", "0.301881"], ["83017.79", "0"], ["83016.64", "0.264945"], ["83015.14", "0"], ["83014.3", "0.292388"]], "a": [["83058.3", "0.18302"], ["83060.5", "0.119903"], ["83060.74", "0.118811"], ["83061.33", "0.234177"], ["83061.34", "0"], ["83061.89", "0"], ["83062.6", "0.117619"], ["83063.07", "0.105878"], ["83063.74", "0"], ["83063.97", "0"], ["83068.2", "0.168442"], ["83069.34", "0"], ["83070.07", "0.158664"], ["83070.3", "0.165105"], ["83070.54", "0.164572"], ["83070.97", "0"], ["83071.14", "0"], ["83071.69", "0"], ["83072.44", "0"], ["83075.2", "0.301111"], ["83076.34", "0"], ["83077.07", "0.282454"], ["83077.97", "0"], ["83079.64", "0.279284"], ["83080.79", "0"], ["83080.8", "0.30058"], ["83081.64", "0"], ["83098.77", "0.110111"]], "u": 6144264, "seq": 66431548127}, "cts": 1741868509601, "record_time": 1741868509.411302}
{"topic": "orderbook.200.BTCUSDT", "ts": 1741868509810, "type": "delta", "data": {"s": "BTCUSDT", "b": [["83049.99", "0.149175"]], "a": [], "u": 6144265, "seq": 66431548142}, "cts": 1741868509804, "record_time": 1741868509.611079}
{"topic": "orderbook.200.BTCUSDT", "ts": 1741868510010, "type": "delta", "data": {"s": "BTCUSDT", "b": [["83041.98", "0"], ["83039.25", "0.028622"], ["83035.88", "0.297225"], ["83035.54", "0"], ["83035.53", "0.107733"], ["83035.3", "0"], ["83035.28", "0.115552"], ["83034.6", "0"], ["83034.58", "0.113037"], ["83032.97", "0"], ["83032.95", "0.107135"], ["83029.7", "0"], ["83029.68", "0.17978"], ["83025.97", "0"], ["83025.95", "0.180285"], ["83025.74", "0"], ["83025.73", "0.168474"], ["83024.8", "0"], ["83024.78", "0.173111"], ["83022.7", "0"], ["83022.68", "0.30174"], ["83018.98", "0.371282"], ["83018.97", "0"], ["83018.95", "0.282553"], ["83018.86", "0"], ["83016.64", "0"], ["83016.63", "0.296481"], ["83014.3", "0"], ["83014.28", "0.288509"], ["83005.71", "0.11"], ["82989", "0"]], "a": [["83050", "4.94737"], ["83060.48", "0.111709"], ["83060.5", "0"], ["83060.73", "0.119026"], ["83060.74", "0.045587"], ["83062.58", "0.116756"], ["83062.6", "0"], ["83063.05", "0.111364"], ["83063.07", "0"], ["83063.55", "0"], ["83064.93", "0"], ["83065.3", "0.068"], ["83067.09", "0.00301"], ["83067.1", "0.288769"], ["83068.18", "0.177937"], ["83068.2", "0"], ["83069.5", "0"], ["83070.05", "0.168677"], ["83070.07", "0"], ["83070.28", "0.182278"], ["83070.3", "0"], ["83070.53", "0.179205"], ["83070.54", "0"], ["83071.4", "0"], ["83075.18", "0.26324"], ["83075.2", "0"], ["83077.05", "0.298125"], ["83077.07", "0"], ["83079.63", "0.452828"], ["83079.64", "0"], ["83080.78", "0.267836"], ["83080.8", "0"], ["83099.3", "0.001467"]], "u": 6144266, "seq": 66431548231}, "cts": 1741868510007, "record_time": 1741868509.810073}
{"topic": "orderbook.200.BTCUSDT", "ts": 1741868510209, "type": "delta", "data": {"s": "BTCUSDT", "b": [["83029.64", "0"], ["83005.71", "0"], ["82989", "0.00009"], ["82988.46", "0.00011"]], "a": [["83064.93", "0.00301"], ["83065.4", "0.064"], ["83067.09", "0"], ["83070.4", "0.04"], ["83079.63", "0.265861"], ["83098.77", "0"], ["83099.3", "0"]], "u": 6144267, "seq": 66431548255}, "cts": 1741868510205, "record_time": 1741868510.010121}
{"topic": "orderbook.200.BTCUSDT", "ts": 1741868510410, "type": "delta", "data": {"s": "BTCUSDT", "b": [["83049.99", "0.252635"], ["83036.68", "0.111"], ["83036.44", "0.115739"], ["83035.88", "0.209243"], ["83035.53", "0"], ["83035.43", "0.118982"], ["83035.28", "0"], ["83034.58", "0"], ["83033.86", "0.119687"], ["83032.95", "0"], ["83031.61", "0.400061"], ["83030.84", "0.163864"], ["83029.68", "0"], ["83029.63", "1.34505"], ["83026.88", "0.173122"], ["83026.86", "0.162396"], ["83025.95", "0"], ["83025.73", "0"], ["83025.63", "0.173867"], ["83024.78", "0"], ["83023.84", "0.270463"], ["83022.68", "0"], ["83019.86", "0.276721"], ["83018.95", "0"], ["83017.78", "0.293877"], ["83016.63", "0"], ["83015.13", "0.279474"], ["83014.28", "0"], ["82997.2", "0.2"], ["82989", "0"], ["82988.46", "0"]], "a": [["83060.48", "0"], ["83060.73", "0"], ["83061.33", "0.350179"], ["83061.88", "0.116412"], ["83062.58", "0"], ["83063.05", "0"], ["83063.74", "0.106834"], ["83063.96", "0.110499"], ["83064.93", "0"], ["83067.09", "0.00301"], ["83068.18", "0"], ["83069.34", "0.172868"], ["83069.6", "0"], ["83070.05", "0"], ["83070.28", "0"], ["83070.53", "0"], ["83070.96", "0.167564"], ["83071.13", "0.171069"], ["83071.68", "0.168949"], ["83074.6", "0"], ["83075.18", "0"], ["83076.34", "0.294774"], ["83077.05", "0"], ["83077.96", "0.296952"], ["83079.63", "0"], ["83080.78", "0.274636"], ["83081.63", "0.274369"], ["83082.66", "0"], ["83087.46", "0"], ["83087.47", "0"], ["83087.66", "0.0003"], ["83087.67", "0.0001"], ["83098.77", "0.110111"], ["83099.3", "0.001467"], ["83099.32", "0.02706"], ["83099.82", "0.495033"]], "u": 6144268, "seq": 66431548335}, "cts": 1741868510401, "record_time": 1741868510.211305}
{"topic": "orderbook.200.BTCUSDT", "ts": 1741868510610, "type": "delta", "data": {"s": "BTCUSDT", "b": [["83049.99", "0.245411"], ["83036.68", "0"], ["83036.6", "0.115699"], ["83036.44", "0"], ["83036.4", "0.105456"], ["83035.43", "0"], ["83035.37", "0.115614"], ["83033.86", "0"], ["83033.8", "0.11935"], ["83031.61", "0.861711"], ["83030.84", "0"], ["83030.8", "0.178097"], ["83026.88", "0"], ["83026.86", "0"], ["83026.8", "0.326438"], ["83025.63", "0"], ["83025.57", "0.180145"], ["83023.84", "0"], ["83023.8", "0.263413"], ["83019.86", "0"], ["83019.8", "0.268033"], ["83017.78", "0"], ["83017.7", "0.289985"], ["83015.13", "0"], ["83015.07", "0.299002"], ["82997.2", "0"], ["82989", "0.00009"], ["82988.46", "0.00011"], ["82988.24", "0.001333"]], "a": [["83061.27", "0.11524"], ["83061.33", "0.234177"], ["83061.8", "0.107442"], ["83061.88", "0"], ["83063.7", "0.105151"], ["83063.74", "0"], ["83063.9", "0.173055"], ["83063.96", "0"], ["83064.93", "0.00301"], ["83067.09", "0"], ["83069.3", "0.164254"], ["83069.34", "0"], ["83070.9", "0.165069"], ["83070.96", "0"], ["83071.07", "0.183129"], ["83071.13", "0"], ["83071.6", "0.179887"], ["83071.68", "0"], ["83071.71", "0.023505"], ["83076.3", "0.274645"], ["83076.34", "0"], ["83077.9", "0.277812"], ["83077.96", "0"], ["83078.74", "0"], ["83080.7", "0.295583"], ["83080.78", "0"], ["83081.54", "1.355316"], ["83081.57", "0.287097"], ["83081.63", "0"], ["83082.65", "0"]], "u": 6144269, "seq": 66431548411}, "cts": 1741868510606, "record_time": 1741868510.410369}
{"topic": "orderbook.200.BTCUSDT", "ts": 1741868510809, "type": "delta", "data": {"s": "BTCUSDT", "b": [["83049.99", "0"], ["83047.41", "0"], ["83046.28", "0"], ["83045.75", "0"], ["83045.74", "0"], ["83045.14", "0"], ["83044.47", "0"], ["83044.46", "0"], ["83043.79", "0"], ["83043.25", "0"], ["83042.2", "0"], ["83042.19", "0"], ["83041.69", "0.022081"], ["83041.68", "0"], ["83040.92", "0.036506"], ["83040.85", "0.028625"], ["83040.8", "0"], ["83040.6", "0"], ["83039.25", "0"], ["83039.14", "0"], ["83039.1", "0"], ["83039.01", "0"], ["83039", "0"], ["83038.01", "0"], ["83037.5", "0"], ["83037.3", "0"], ["83036.6", "0"], ["83036.4", "0"], ["83036.31", "0"], ["83035.9", "0"], ["83035.88", "0"], ["83035.87", "0"], ["83035.67", "0"], ["83035.6", "0"], ["83035.55", "0.000501"], ["83035.37", "0"], ["83035.35", "0.024551"], ["83034.2", "0"], ["83034.03", "0"], ["83034", "0"], ["83033.8", "0"], ["83033.39", "0.005"], ["83032.88", "0"], ["83032.43", "0"], ["83032.16", "0"], ["83031.61", "0"], ["83031.6", "0"], ["83030.8", "0.00011"], ["83030.79", "0.00015"], ["83030.62", "0"], ["83029.63", "0"], ["83029.39", "0"], ["83029.3", "0"], ["83027.54", "0"], ["83027.23", "0.106124"], ["83027.17", "0.119558"], ["83026.8", "0"], ["83026.57", "0.109723"], ["83026.47", "0"], ["83025.57", "0"], ["83025.25", "0.12122"], ["83023.81", "0.072281"], ["83023.8", "0"], ["83021.79", "0.023138"], ["83021.49", "0.018068"], ["83021.48", "0.012043"], ["83021.42", "0.05212"], ["83020.97", "0.167191"], ["83019.81", "0.08041"], ["83019.8", "0"], ["83018.85", "0"], ["83018.25", "0.178316"], ["83017.83", "0"], ["83017.7", "0"], ["83017.43", "0.170393"], ["83017.37", "0.178382"], ["83017.33", "0.018065"], ["83015.07", "0"], ["83014.7", "0"], ["83014.07", "0"], ["83013.97", "0.269892"], ["83013.67", "0"], ["83013.21", "0"], ["83011.25", "0.276177"], ["83008.33", "0.28311"], ["83006.87", "0.302594"], ["83004.71", "0"], ["82997.69", "0"], ["82997.68", "0"], ["82993.94", "0"], ["82991.36", "0.361335"], ["82991.35", "0"], ["82988.54", "0.162"], ["82988.14", "0.024084"], ["82987.3", "0.0006"], ["82987.03", "0.000239"], ["82986.63", "0.024087"], ["82986.51", "0.00009"], ["82986.41", "0.009"], ["82985.97", "0.00011"], ["82985.84", "0.05212"], ["82985.53", "0.000091"], ["82985.12", "0.001467"], ["82984.79", "0.00602"], ["82984.09", "0.001333"], ["82984.02", "0.00009"], ["82983.63", "0.003"], ["82983.55", "1.806141"], ["82983.49", "0.00011"], ["82983.42", "0.518409"], ["82982.9", "0.024087"], ["82982.49", "0.024087"], ["82982.4", "0.024087"], ["82981.53", "0.00009"], ["82981", "0.00011"], ["82980.55", "0.001467"], ["82979.94", "0.001333"], ["82979.23", "0.000812"], ["82979.04", "0.00009"], ["82978.74", "0.022742"], ["82978.51", "0.00011"], ["82977.34", "0.000091"], ["82976.79", "0.006021"], ["82976.56", "0.00009"], ["82976.02", "0.00011"], ["82975.99", "0.001467"], ["82975.79", "0.001333"], ["82974.67", "0.069799"], ["82974.07", "0.00009"], ["82973.53", "0.00011"]], "a": [["83041.7", "0.33188"], ["83045.75", "0.018046"], ["83045.76", "0.06"], ["83049.99", "1.539496"], ["83050", "5.121816"], ["83050.14", "0.000153"], ["83050.51", "0.006333"], ["83052.43", "0.110253"], ["83052.82", "0.153141"], ["83053.07", "0.109439"], ["83053.63", "0.000091"], ["83053.87", "0.110861"], ["83055.35", "0.116849"], ["83056.68", "0.05212"], ["83058.29", "0.003011"], ["83058.3", "0.121607"], ["83059.35", "0"], ["83059.47", "0.180633"], ["83060.74", "0"], ["83061.27", "0"], ["83061.67", "0"], ["83061.8", "0"], ["83061.82", "0.045673"], ["83062.23", "0.180163"], ["83062.35", "0.169451"], ["83062.87", "0.169505"], ["83063.51", "0"], ["83063.67", "0"], ["83063.7", "0"], ["83063.9", "0.064"], ["83064.5", "0"], ["83064.93", "0"], ["83064.94", "0"], ["83065.44", "0"], ["83066.47", "0.262866"], ["83067.1", "0.048"], ["83067.95", "0.05212"], ["83068.65", "0"], ["83068.72", "0"], ["83068.76", "0"], ["83068.94", "0.003619"], ["83069.3", "0"], ["83069.35", "0.295703"], ["83069.92", "0.012043"], ["83070.9", "0"], ["83071.07", "0"], ["83071.33", "0.262465"], ["83071.6", "0"], ["83072.81", "0"], ["83073.1", "0.021895"], ["83073.37", "0.280523"], ["83074.07", "0.018065"], ["83074.4", "0.052"], ["83076.3", "0"], ["83077.9", "0"], ["83078.49", "0.120409"], ["83079.2", "0.02706"], ["83079.5", "0.072232"], ["83080.67", "0"], ["83080.7", "0"], ["83081.57", "0"], ["83083.21", "0.481397"], ["83084.16", "0"], ["83086.02", "0"], ["83086.96", "0.0003"], ["83086.97", "0.0001"], ["83087.66", "0"], ["83087.67", "0"], ["83089.37", "0"], ["83091.51", "0"], ["83091.88", "0"], ["83095.16", "0.361335"], ["83097.71", "0"], ["83099.32", "0"], ["83100", "0.003135"]], "u": 6144270, "seq": 66431549301}, "cts": 1741868510807, "record_time": 1741868510.611038}
{"topic": "orderbook.200.BTCUSDT", "ts": 1741868511009, "type": "delta", "data": {"s": "BTCUSDT", "b": [["83049.99", "0.941357"], ["83041.7", "0.148585"], ["83041.69", "0.34093"], ["83040.92", "0"], ["83039.17", "0.000099"], ["83037.48", "0.098114"], ["83037.47", "0.105602"], ["83037.15", "0.112082"], ["83036.79", "0.001"], ["83036.44", "0.109034"], ["83036.1", "0.04"], ["83035.55", "0"], ["83035.35", "0.081328"], ["83035.34", "0.138744"], ["83035.32", "0.072271"], ["83035.16", "0.05212"], ["83034.62", "0.006327"], ["83032.96", "0"], ["83031.67", "0"], ["83031.6", "0.04"], ["83031.2", "0.04"], ["83030.91", "0.036129"], ["83030.84", "0.158001"], ["83029.83", "0.147472"], ["83029.82", "0.118415"], ["83029.63", "0.001"], ["83028.68", "0.000301"], ["83028.34", "0.158854"], ["83028.2", "0.120421"], ["83027.67", "0.157274"], ["83027.35", "0.167349"], ["83027.26", "0.065084"], ["83027.23", "0"], ["83027.17", "0"], ["83026.57", "0"], ["83025.81", "0"], ["83025.25", "0"], ["83023.84", "0.268306"], ["83023.81", "0"], ["83021.48", "0"], ["83021.42", "0"], ["83021.34", "0.293824"], ["83020.97", "0"], ["83019.81", "0"], ["83018.98", "0"], ["83018.65", "0.220263"], ["83018.57", "0.274919"], ["83018.25", "0"], ["83017.43", "0"], ["83017.37", "0"], ["83017.33", "0"], ["83016.85", "0.283318"], ["83013.97", "0"], ["83013.21", "0.05212"], ["83011.25", "0"], ["83010.15", "0"], ["83008.33", "0"], ["83007.34", "0.026014"], ["83006.87", "0"], ["83004.07", "0"], ["82996.86", "0.362791"], ["82991.36", "0"], ["82981.93", "0.06038"], ["82980.79", "0.24102"], ["82980.23", "0.162"], ["82977.34", "0"], ["82976.79", "0"], ["82976.56", "0"], ["82976.02", "0"], ["82975.99", "0"], ["82975.79", "0"], ["82974.67", "0"], ["82974.07", "0"], ["82973.53", "0"]], "a": [["83041.7", "0"], ["83045.75", "0"], ["83045.76", "0"], ["83049.99", "0"], ["83050", "4.962872"], ["83050.14", "0"], ["83052.43", "0"], ["83052.82", "0"], ["83053.07", "0"], ["83053.87", "0"], ["83055.35", "0"], ["83056.68", "0"], ["83056.72", "0.240799"], ["83058.29", "0"], ["83058.3", "0.049361"], ["83059.47", "0"], ["83061.28", "0.000153"], ["83061.33", "0"], ["83062.23", "0"], ["83062.35", "0"], ["83062.66", "0.122709"], ["83062.67", "0.110859"], ["83062.87", "0"], ["83063.05", "0.110535"], ["83063.74", "0.110636"], ["83063.87", "0.01"], ["83065.43", "0.214237"], ["83065.44", "0.111406"], ["83065.73", "0.05212"], ["83066.47", "0"], ["83067.95", "0"], ["83069.34", "0.175284"], ["83069.35", "0"], ["83069.49", "0.204667"], ["83069.92", "0"], ["83071.33", "0"], ["83072.44", "0.165231"], ["83072.47", "0.177136"], ["83072.85", "0.176799"], ["83073.1", "0"], ["83073.36", "0.195353"], ["83073.37", "0"], ["83073.75", "0.001"], ["83074.07", "0"], ["83074.39", "0"], ["83075.75", "0"], ["83076.34", "0.29097"], ["83078.49", "0"], ["83079.2", "0"], ["83079.44", "0.276202"], ["83081.54", "0"], ["83081.57", "0.280482"], ["83082.26", "0.364903"], ["83083.02", "0.001"], ["83083.21", "0"], ["83083.35", "0.27971"], ["83084.49", "0.072228"], ["83085.96", "0.0003"], ["83085.97", "0.0001"], ["83086.8", "0.060199"], ["83086.96", "0"], ["83086.97", "0"], ["83090.12", "0"], ["83091.51", "0.481397"], ["83095.16", "0"], ["83095.17", "0"], ["83097.86", "0"], ["83098.77", "0.000111"], ["83100.35", "0.001333"], ["83100.43", "0.12"], ["83100.57", "0.00011"], ["83101.11", "0.00009"], ["83101.29", "0.002167"], ["83102.77", "0.000091"], ["83103.07", "0.00011"], ["83103.47", "0.003619"], ["83103.6", "0.00009"], ["83103.63", "0.003"], ["83103.87", "0.001467"]], "u": 6144271, "seq": 66431549990}, "cts": 1741868511007, "record_time": 1741868510.810117}
{"topic": "orderbook.200.BTCUSDT", "ts": 1741868511209, "type": "delta", "data": {"s": "BTCUSDT", "b": [["83041.7", "0.120585"], ["83039.17", "0"], ["83037.9", "0.04"], ["83037.8", "0.04"], ["83036.3", "0.04"], ["83035.35", "0.112344"], ["83034.7", "0.04"], ["83034.5", "0.04"], ["83033.18", "0.012042"], ["83032.8", "0.04"], ["83031.5", "0.04"], ["83030.85", "0.247251"], ["83029.83", "0.000301"], ["83029.03", "0.018063"], ["83021.67", "1.338982"], ["83014.21", "0.11"], ["83010.55", "0"], ["82997.18", "0.650625"], ["82987.22", "0.650703"], ["82982.4", "0"], ["82981.93", "0"], ["82981.53", "0"], ["82981", "0"], ["82980.79", "0"], ["82980.55", "0"], ["82980.23", "0"], ["82979.94", "0"], ["82979.23", "0"], ["82979.04", "0"], ["82978.74", "0"], ["82978.51", "0"]], "a": [["83050", "4.963826"], ["83056.71", "0.051195"], ["83058.3", "0"], ["83060.8", "0.019866"], ["83063.6", "0.068"], ["83065.43", "0.135377"], ["83067.7", "0"], ["83071.91", "0.124583"], ["83081.56", "0.012042"], ["83085.72", "0.018063"], ["83085.86", "0.0003"], ["83085.87", "0.0001"], ["83085.96", "0"], ["83085.97", "0"], ["83101.15", "0.162"], ["83103.47", "0"], ["83103.6", "0"], ["83103.63", "0"], ["83103.87", "0"]], "u": 6144272, "seq": 66431550114}, "cts": 1741868511203, "record_time": 1741868511.010385}
{"topic": "orderbook.200.BTCUSDT", "ts": 1741868511410, "type": "delta", "data": {"s": "BTCUSDT", "b": [["83047.47", "0.000099"], ["83013.67", "0.240819"], ["83009.52", "0.240819"], ["83006.59", "0.361282"], ["82996.86", "0.0015"], ["82985.64", "0.240819"], ["82983.55", "0"], ["82983.49", "0"], ["82983.42", "0"], ["82982.9", "0"], ["82982.49", "0"]], "a": [["83050", "4.962162"], ["83050.04", "0.001664"], ["83052.52", "0.000099"], ["83053.3", "0"], ["83056.72", "0"], ["83068.7", "0.06"], ["83070.2", "0.052"], ["83073.57", "0.228671"], ["83079.02", "1.391399"], ["83085.86", "0"], ["83085.87", "0"], ["83085.96", "0.0003"], ["83085.97", "0.0001"], ["83086.8", "0"], ["83101.29", "0"], ["83102.77", "0"], ["83103.07", "0"]], "u": 6144273, "seq": 66431550189}, "cts": 1741868511406, "record_time": 1741868511.210468}
