{"topic": "orderbook.200.BTCUSDT", "ts": 1742142232609, "type": "delta", "data": {"s": "BTCUSDT", "b": [["84293.58", "0.181755"], ["84293.44", "0.063654"], ["84293.42", "0.00096"], ["84291.4", "0.089922"], ["84290.97", "0.0002"], ["84290.96", "0.059948"], ["84288.79", "0.000252"], ["84283.43", "0.106126"], ["84283.11", "0.117262"], ["84282.8", "0.078933"], ["84282.79", "0.168679"], ["84282.44", "0.000233"], ["84281.92", "0.059948"], ["84281.91", "0.000233"], ["84281.55", "0.114575"], ["84280.86", "0.0002"], ["84280.36", "0.000817"], ["84279.69", "0.001467"], ["84279.68", "0.07078"], ["84279.52", "0.000252"], ["84279.3", "0.001333"], ["84279.25", "0.000614"], ["84278.85", "0"], ["84278.59", "0"], ["84278.39", "0.015081"], ["84278.33", "0.0002"], ["84278.14", "0.009407"], ["84277.8", "0.000233"], ["84277.3", "0.000089"], ["84277.28", "0.000233"], ["84276.29", "0.060329"], ["84275.98", "0.068395"], ["84275.8", "0.0002"], ["84275.61", "0.089922"], ["84275.48", "0"], ["84275.05", "0.001867"], ["84275.04", "0.000614"], ["84274.56", "0.174394"], ["84274.51", "0.008453"], ["84274.37", "0.100664"], ["84274.36", "0.162"], ["84273.52", "0.019233"], ["84271.7", "0.11863"], ["84271.35", "0.000357"], ["84271.26", "0"], ["84270.41", "0"], ["84269.76", "0"], ["84269.54", "0"], ["84269.13", "0"], ["84268.78", "0"], ["84268.25", "0"], ["84268.01", "0.000482"], ["84267.63", "0"], ["84267.58", "0"], ["84267.23", "0"], ["84267.2", "0.04"], ["84266.67", "0"], ["84265.77", "0"], ["84265.49", "0.014111"], ["84264.77", "0.11863"], ["84264.74", "0"], ["84264.16", "0.018803"], ["84264.1", "0.04"], ["84263.8", "0.04"], ["84263.35", "0.059948"], ["84261.45", "0"], ["84261.23", "0"], ["84261.2", "0.04"], ["84260.8", "0.04"], ["84260.75", "0"], ["84260.4", "0.040089"], ["84259.28", "0.11863"], ["84259.27", "0"], ["84259.11", "0.355889"], ["84259.1", "0"], ["84258.92", "0"], ["84258.69", "0.068395"], ["84258.66", "0"], ["84258.6", "0.087289"], ["84258.24", "0"], ["84257.9", "0.071215"], ["84257.02", "0"], ["84256.64", "0"], ["84256.27", "0"], ["84255.64", "0.023726"], ["84255.5", "0.04"], ["84255.31", "0.139995"], ["84254.93", "0.237266"], ["84254.9", "0.107948"], ["84253.35", "0.005931"], ["84253.03", "0.023727"], ["84252.35", "0.024188"], ["84251.5", "0"], ["84251.3", "0.071221"], ["84251.2", "0"], ["84251.04", "0"], ["84250.71", "0.237266"], ["84249.67", "0.023726"], ["84249.51", "0.11863"], ["84249.5", "0"], ["84249.38", "0"], ["84249", "0"], ["84248.86", "0.023726"], ["84248.75", "0"], ["84247.88", "0"], ["84247.6", "0"], ["84247.3", "0"], ["84246.8", "0"], ["84245.86", "0.000089"], ["84245.37", "0"], ["84245.1", "0.001243"], ["84243.87", "0.023726"], ["84243.57", "0.023729"], ["84243.4", "0"], ["84241.59", "0"], ["84241.37", "0.057651"], ["84236.56", "0"], ["84236.48", "0"], ["84233.1", "0.24702"], ["84232.79", "0"], ["84228.55", "0"], ["84228.43", "0"], ["84227.78", "0"], ["84227.43", "0"], ["84227.35", "0"], ["84227.02", "0"], ["84226.83", "0"], ["84226.82", "0"], ["84226.8", "0"], ["84226.72", "0"], ["84226.6", "0"], ["84226.31", "0"], ["84225.75", "0"], ["84225.25", "0"], ["84225", "0"], ["84224.9", "0"], ["84224.72", "0"], ["84224.53", "0"], ["84224.49", "0"], ["84224.08", "0"], ["84223.91", "0"], ["84223.3", "0"]], "a": [["84279.69", "0"], ["84280.86", "0"], ["84281.91", "0"], ["84281.94", "0"], ["84282.44", "0"], ["84282.8", "0"], ["84283.25", "0"], ["84283.39", "0"], ["84283.47", "0"], ["84283.51", "0"], ["84284.16", "0"], ["84284.32", "0"], ["84285.34", "0"], ["84285.92", "0"], ["84286.23", "0"], ["84286.55", "0"], ["84286.56", "0"], ["84286.6", "0"], ["84287.07", "0"], ["84287.68", "0"], ["84287.72", "0"], ["84288.11", "0"], ["84288.12", "0"], ["84288.44", "0"], ["84288.79", "0"], ["84288.96", "0"], ["84289.2", "0"], ["84290.97", "0"], ["84291.19", "0"], ["84291.7", "0"], ["84291.71", "0"], ["84291.74", "0"], ["84291.9", "0"], ["84291.94", "0"], ["84292.52", "0"], ["84292.54", "0"], ["84293.43", "0"], ["84293.49", "0"], ["84293.5", "0"], ["84293.83", "0"], ["84294.3", "0.0006"], ["84294.98", "0"], ["84294.99", "0"], ["84295", "0"], ["84295.17", "0"], ["84295.9", "0"], ["84295.94", "0"], ["84296.44", "0"], ["84297.02", "0"], ["84297.69", "0"], ["84297.7", "0"], ["84298.3", "0"], ["84299.68", "0"], ["84299.99", "0"], ["84300.11", "0"], ["84300.16", "0.005118"], ["84300.43", "0"], ["84300.52", "0"], ["84300.67", "0"], ["84301.09", "0.0002"], ["84301.35", "0"], ["84301.55", "0"], ["84301.58", "0"], ["84301.6", "0"], ["84301.78", "0"], ["84301.98", "0"], ["84302.02", "0.0005"], ["84302.2", "0.068"], ["84302.43", "0"], ["84303.49", "0.020997"], ["84303.73", "0.004866"], ["84303.81", "0"], ["84304", "0"], ["84304.01", "0"], ["84304.78", "0"], ["84304.95", "0"], ["84304.98", "0"], ["84305.53", "0"], ["84305.54", "0"], ["84305.6", "0.083987"], ["84306.87", "0.009407"], ["84307.32", "0"], ["84307.81", "0"], ["84308.83", "0"], ["84308.95", "0.000296"], ["84309.46", "0"], ["84309.56", "0"], ["84309.61", "0"], ["84309.8", "0"], ["84310.1", "0.06"], ["84310.22", "0"], ["84310.24", "0"], ["84310.6", "0.044"], ["84310.78", "0"], ["84311.08", "0"], ["84312.04", "0"], ["84312.14", "0.001467"], ["84312.78", "0"], ["84313.51", "0"], ["84314.15", "0.018786"], ["84314.21", "0.10807"], ["84314.74", "0.118737"], ["84314.89", "0.12036"], ["84315.36", "0"], ["84315.62", "0.31554"], ["84315.63", "0"], ["84315.68", "0"], ["84315.93", "0"], ["84316.56", "0"], ["84317.14", "0"], ["84317.5", "0"], ["84317.61", "0.004747"], ["84317.93", "0"], ["84317.96", "0"], ["84318.04", "0"], ["84319.16", "0.003334"], ["84319.52", "0.014111"], ["84320.24", "0"], ["84321.11", "0"], ["84321.12", "0"], ["84321.31", "0"], ["84321.33", "0"], ["84321.67", "0"], ["84321.73", "0.174766"], ["84322.92", "0.023728"], ["84323.29", "0.161744"], ["84323.83", "0"], ["84325.29", "0"], ["84325.3", "0"], ["84325.51", "0"], ["84326.07", "0"], ["84326.18", "0.180663"], ["84326.47", "0.162"], ["84327.92", "0.023729"], ["84328.04", "0"], ["84328.72", "0.023728"], ["84329.61", "0"], ["84329.86", "0.008453"], ["84329.99", "0"], ["84330", "0.19987"], ["84330.48", "0.000089"], ["84330.53", "0.000253"], ["84330.69", "0.001467"], ["84330.81", "0.009462"], ["84331.33", "0.023728"], ["84331.43", "0.001614"], ["84331.44", "0.0002"], ["84332.38", "0.015"], ["84332.92", "0.000235"], ["84333.14", "0.0025"], ["84333.45", "0.000235"], ["84333.6", "0.005932"], ["84333.97", "0.0002"], ["84334.02", "0.009089"], ["84334.05", "0.000612"], ["84334.1", "0.001333"], ["84334.15", "0.0013"], ["84334.22", "0.0045"], ["84334.27", "0.019075"], ["84334.38", "0.022"], ["84334.41", "0.000789"], ["84334.69", "0.023728"], ["84335.16", "0.000253"], ["84335.33", "0.001467"], ["84335.96", "0.000335"], ["84336.5", "0.0002"], ["84337.3", "0.246059"], ["84337.34", "0.11863"], ["84337.56", "0.000235"], ["84338.08", "0.000235"], ["84338.27", "0.000612"], ["84338.31", "0.001333"], ["84338.59", "0.354608"], ["84338.99", "0.000089"], ["84339.03", "0.0002"], ["84339.8", "0.040253"], ["84339.97", "0.001467"], ["84340.01", "0.04"], ["84340.88", "0.000158"], ["84341.56", "0.0002"], ["84342.2", "0.000235"], ["84342.46", "0.237306"], ["84342.49", "0.000612"], ["84342.53", "0.001333"], ["84342.72", "0.000235"], ["84343.29", "0.024741"], ["84343.72", "0.089922"], ["84344.09", "0.0002"], ["84344.44", "0.000253"], ["84344.61", "0.001467"], ["84345.69", "0.00089"], ["84345.81", "0.027637"], ["84346.23", "0.06093"], ["84346.7", "0.000612"], ["84346.75", "0.001333"], ["84346.84", "0.002519"], ["84347.03", "0.001"], ["84347.36", "0.000235"], ["84347.5", "0.000089"], ["84348.18", "0.237306"], ["84349.08", "0.000253"], ["84349.25", "0.001467"], ["84350", "0.021512"], ["84350.19", "0.059948"], ["84350.86", "0.428903"], ["84350.92", "0.000612"], ["84350.96", "0.001333"], ["84351.48", "0.000235"], ["84352", "0.000235"], ["84353.24", "0.118791"], ["84353.72", "0.000253"], ["84353.89", "0.001467"], ["84354", "0.352467"], ["84354.92", "0.00109"], ["84355.14", "0.000612"], ["84355.15", "0.000357"], ["84355.18", "0.001333"], ["84355.5", "0.12"], ["84355.81", "0.05904"], ["84356.01", "0.00009"], ["84356.12", "0.000235"], ["84356.64", "0.000235"], ["84357.02", "0.000085"], ["84358.07", "0.000335"], ["84358.36", "0.000253"]], "u": 7510683, "seq": 66889351858}, "cts": 1742142232608, "record_time": 1742142231.710067}
{"topic": "orderbook.200.BTCUSDT", "ts": 1742142232809, "type": "delta", "data": {"s": "BTCUSDT", "b": [["84293.58", "0.177124"], ["84293.44", "0.037436"], ["84292", "0.071186"], ["84291.4", "0"], ["84289.96", "0.000099"], ["84288.44", "0.0002"], ["84286.85", "0.01508"], ["84285.92", "0.0002"], ["84285.17", "0.045688"], ["84285.16", "0.049115"], ["84285.15", "0.0005"], ["84284.73", "0.060323"], ["84284.54", "0.118867"], ["84283.43", "0"], ["84283.39", "0.0002"], ["84283.22", "0.009427"], ["84283.11", "0"], ["84282.8", "0"], ["84282.79", "0.168079"], ["84281.55", "0"], ["84281.18", "0.008453"], ["84279.68", "0.07066"], ["84278.39", "0"], ["84278.14", "0"], ["84276.29", "0"], ["84275.5", "0.04"], ["84274.57", "0.02"], ["84274.56", "0"], ["84274.51", "0"], ["84274.37", "0.090159"], ["84274.11", "0.02"], ["84273.44", "0.02"], ["84273.4", "0.04"], ["84272.9", "0.04"], ["84272.31", "0.02"], ["84270.58", "0.014141"], ["84270.24", "0.02"], ["84269.8", "0.04"], ["84268.74", "0.024321"], ["84268.28", "0.008717"], ["84268.01", "0.000233"], ["84267.9", "0.04"], ["84266.39", "0.00591"], ["84265.49", "0"], ["84264.82", "0.071209"], ["84264.76", "0"], ["84262.4", "0.048614"], ["84259.51", "0.323559"], ["84259.29", "0.355887"], ["84259.11", "0"], ["84258.4", "0"], ["84257.91", "0.000335"], ["84256.4", "0"], ["84255.8", "0"], ["84254.93", "0"], ["84253.03", "0"], ["84252.71", "0.162"], ["84252.35", "0"], ["84251.3", "0"], ["84250.72", "1.372996"], ["84250.71", "0.177949"], ["84250.7", "0"], ["84250.24", "0"], ["84248.31", "0.004581"], ["84245.41", "0"], ["84243.54", "0.000989"], ["84242.95", "0"], ["84236.7", "0.24702"], ["84235.24", "0.237266"], ["84234.2", "0.015586"], ["84233.37", "0"], ["84233.1", "0"], ["84232.93", "0.162"], ["84232.41", "0"], ["84232.38", "0"], ["84232.01", "0"], ["84231.67", "0"], ["84231.46", "0"], ["84230.94", "0"], ["84230.83", "0"], ["84230.31", "0"], ["84228.74", "0"], ["84228.71", "0"], ["84228.7", "0"]], "a": [["84293.59", "0.003466"], ["84296.71", "0"], ["84297.21", "0.00011"], ["84298.63", "0.000623"], ["84299.24", "0"], ["84300.16", "0"], ["84302.02", "0.021612"], ["84302.2", "0"], ["84303.49", "0"], ["84305.6", "0"], ["84306.87", "0"], ["84308.95", "0"], ["84309.73", "0.029202"], ["84310.08", "0.000296"], ["84310.1", "0"], ["84310.59", "0.052542"], ["84311.95", "0.009427"], ["84312.05", "0.020995"], ["84312.77", "0"], ["84312.9", "0.068"], ["84312.97", "0.000612"], ["84313.89", "0.004623"], ["84314.15", "0.102764"], ["84314.2", "0.127349"], ["84314.21", "0"], ["84314.74", "0"], ["84314.89", "0"], ["84315.03", "0"], ["84315.62", "0"], ["84316.1", "0.044"], ["84316.2", "0.056"], ["84316.22", "0"], ["84317.13", "0.000989"], ["84317.61", "0"], ["84317.88", "0.112675"], ["84317.9", "0.06"], ["84318", "0.04"], ["84319.16", "0"], ["84319.52", "0"], ["84319.6", "0.068"], ["84320.25", "0.139994"], ["84321.2", "0.048"], ["84321.73", "0"], ["84322.39", "0.017796"], ["84322.91", "0.068395"], ["84323.29", "0"], ["84324.59", "0.014141"], ["84324.72", "0.167498"], ["84325.1", "0.003333"], ["84326.18", "0"], ["84328.85", "0.023727"], ["84329.86", "0"], ["84329.99", "0.11863"], ["84331.32", "0.00126"], ["84333.74", "1.395646"], ["84333.87", "0.014046"], ["84334.9", "0.162"], ["84338.58", "0.059948"], ["84339.8", "0.000253"], ["84340.01", "0"], ["84343.29", "0"], ["84343.33", "0.162"], ["84343.4", "0.04"], ["84343.41", "0.04"], ["84343.9", "0.03181"], ["84344.27", "0.017796"], ["84345.35", "0.32323"], ["84345.81", "0"], ["84350.18", "0.355887"], ["84351.76", "0.162"], ["84352.62", "0.015"], ["84354", "0"], ["84354.92", "0"], ["84355.14", "0"], ["84355.15", "0"], ["84355.18", "0"], ["84355.5", "0"], ["84355.81", "0"], ["84356.01", "0"], ["84356.12", "0"], ["84356.64", "0"], ["84357.02", "0"], ["84358.07", "0"], ["84358.36", "0"]], "u": 7510684, "seq": 66889352629}, "cts": 1742142232807, "record_time": 1742142231.909619}
{"topic": "orderbook.200.BTCUSDT", "ts": 1742142233009, "type": "delta", "data": {"s": "BTCUSDT", "b": [["84293.58", "0.259784"], ["84292.75", "0.011863"], ["84292.74", "0.0389"], ["84285.17", "0.063398"], ["84284.64", "0.11513"], ["84284.54", "0"], ["84282.8", "0.071389"], ["84281.8", "0.04"], ["84280.1", "0.04"], ["84279.68", "0"], ["84277.82", "0.106625"], ["84277.8", "0.176471"], ["84277.67", "0.003"], ["84277.47", "0.003"], ["84277.27", "0.003"], ["84276.8", "0.04"], ["84275.95", "0.237266"], ["84275.51", "0.163379"], ["84275.1", "0.04"], ["84275.05", "0.001467"], ["84274.37", "0"], ["84271.84", "0.02"], ["84271.74", "0.237266"], ["84271.7", "0"], ["84270.42", "0.001467"], ["84270.24", "0"], ["84269.26", "0.295995"], ["84267.2", "0"], ["84263.8", "0"], ["84261.2", "0"], ["84260.8", "0"], ["84260.4", "0.000089"], ["84259.29", "0"], ["84259.1", "0.177949"], ["84255.51", "0.355892"], ["84255.5", "0"], ["84254.9", "0.059948"], ["84250.72", "0"], ["84247.95", "0.2"], ["84240.2", "0.247253"], ["84238.04", "0.177949"], ["84236.7", "0"], ["84233.54", "0"], ["84233.14", "0"], ["84232.95", "0"], ["84232.93", "0"], ["84232.91", "0"], ["84232.83", "0"], ["84232.81", "0"], ["84232.8", "0"]], "a": [["84293.59", "0.00489"], ["84309.72", "0.000296"], ["84310.08", "0"], ["84314.2", "0.070306"], ["84314.7", "0.06"], ["84317.87", "0.11863"], ["84317.88", "0"], ["84317.99", "0.107662"], ["84318.82", "0.005984"], ["84320.48", "0"], ["84321.4", "0.048612"], ["84324.58", "0.11863"], ["84324.72", "0"], ["84324.83", "0.172467"], ["84325.9", "0.024679"], ["84330.47", "0.00126"], ["84331.32", "0"], ["84332.24", "0.004746"], ["84333.38", "0.290657"], ["84334.02", "0.004589"], ["84335.72", "0.008453"], ["84343.4", "0"], ["84343.41", "0"], ["84343.5", "0.04"], ["84343.51", "0.04"], ["84348.04", "0.009"], ["84348.24", "0.0045"], ["84348.25", "0.0045"], ["84350.17", "0.355892"], ["84350.18", "0"], ["84350.86", "0"], ["84350.92", "0"], ["84350.96", "0"], ["84351.48", "0"], ["84351.76", "0"], ["84352", "0"], ["84352.62", "0"], ["84353.24", "0"], ["84353.72", "0"], ["84353.89", "0"]], "u": 7510685, "seq": 66889353051}, "cts": 1742142233008, "record_time": 1742142232.108757}
{"topic": "orderbook.200.BTCUSDT", "ts": 1742142233209, "type": "delta", "data": {"s": "BTCUSDT", "b": [["84302.86", "0.254928"], ["84302.02", "0.0385"], ["84300.98", "0.060427"], ["84300.97", "0.131179"], ["84300.32", "0.059948"], ["84298.62", "0.03"], ["84298.56", "0.0002"], ["84298.55", "0.009748"], ["84298.06", "0.000252"], ["84298.05", "0.032822"], ["84296.35", "0.000233"], ["84296.15", "0.001333"], ["84296.11", "0.000614"], ["84295.82", "0.000233"], ["84295.81", "0.04"], ["84294.43", "0.049115"], ["84294.23", "0.117634"], ["84294.2", "0.000089"], ["84294", "0.05366"], ["84293.91", "0.105634"], ["84293.59", "0.0004"], ["84293.58", "0.213399"], ["84293.5", "0.0002"], ["84293.44", "0"], ["84293.43", "0.000252"], ["84292.75", "0"], ["84292.74", "0"], ["84292.39", "0.117585"], ["84292", "0"], ["84291.94", "0.001333"], ["84291.9", "0.000614"], ["84291.71", "0.000233"], ["84291.19", "0.000233"], ["84290.97", "0.02179"], ["84288.96", "0.001467"], ["84288.8", "0.04"], ["84288.4", "0.04"], ["84288.36", "0.009547"], ["84287.72", "0.001333"], ["84287.68", "0.000614"], ["84287.07", "0.000233"], ["84286.85", "0"], ["84286.55", "0.000233"], ["84286.04", "0.104032"], ["84286.03", "0.089922"], ["84285.75", "0.000089"], ["84285.55", "0.159594"], ["84285.36", "0.163041"], ["84285.17", "0"], ["84285.16", "0"], ["84285.15", "0.1625"], ["84284.64", "0"], ["84284.32", "0.001467"], ["84284.15", "0.000252"], ["84284.11", "0.068395"], ["84283.77", "0.00979"], ["84283.51", "0.001333"], ["84283.47", "0.000614"], ["84283.22", "0"], ["84282.8", "0.098465"], ["84282.79", "0.162"], ["84282.26", "0.176328"], ["84282.07", "0.02"], ["84282", "0.04"], ["84281.7", "0.04"], ["84281.61", "0.02"], ["84281.18", "0"], ["84280.94", "0.02"], ["84280.5", "0.04"], ["84280.16", "0.23724"], ["84279.81", "0.02"], ["84279.12", "0.005931"], ["84278.4", "0.04"], ["84278.1", "0.019104"], ["84277.8", "0.000233"], ["84277.19", "0.017796"], ["84277", "0.263994"], ["84276.81", "0.296761"], ["84275.98", "0"], ["84275.95", "0.23724"], ["84275.72", "0.014321"], ["84275.5", "0"], ["84275.1", "0"], ["84274.57", "0"], ["84274.11", "0"], ["84274.08", "0.023725"], ["84273.44", "0"], ["84273.4", "0"], ["84272.9", "0"], ["84272.69", "0.003"], ["84272.31", "0"], ["84271.85", "0.178578"], ["84271.84", "0"], ["84271.74", "0"], ["84271.49", "0.071204"], ["84271.14", "0.293664"], ["84270.58", "0"], ["84270.2", "0.04"], ["84269.8", "0"], ["84269.27", "0.110936"], ["84269.26", "0"], ["84267.9", "0"], ["84267.51", "0.323529"], ["84264.88", "0.017765"], ["84264.83", "0.092777"], ["84264.16", "0"], ["84263.86", "1.439213"], ["84262.41", "0.355865"], ["84261.99", "0.231684"], ["84260.83", "0"], ["84259.51", "0"], ["84259.1", "0"], ["84258.6", "0.187751"], ["84257.9", "0"], ["84255.51", "0"], ["84255.31", "0"], ["84248.36", "0"], ["84247.95", "0"], ["84247.9", "0.24702"], ["84245.59", "0"], ["84245.55", "0"], ["84245.47", "0"], ["84245.36", "0"], ["84245.1", "0"], ["84244.84", "0"], ["84244.68", "0"], ["84243.87", "0"], ["84243.57", "0"], ["84243.54", "0"], ["84243.5", "0"], ["84242.94", "0"], ["84242.61", "0"], ["84242.44", "0"], ["84242.42", "0"], ["84241.39", "0"], ["84241.38", "0"], ["84241.37", "0"], ["84241.36", "0"], ["84241.34", "0"], ["84240.73", "0"], ["84240.41", "0"], ["84240.2", "0"], ["84239.01", "0"], ["84238.78", "0"], ["84238.04", "0"], ["84237.98", "0"], ["84237.89", "0"], ["84237.82", "0"], ["84237.81", "0"], ["84237.17", "0"], ["84237.12", "0"], ["84236.49", "0"], ["84236.1", "0"], ["84235.8", "0"], ["84235.57", "0"], ["84235.36", "0"], ["84235.24", "0"], ["84235.05", "0"], ["84234.2", "0"], ["84233.35", "0"], ["84233.18", "0"]], "a": [["84293.59", "0"], ["84294.15", "0"], ["84294.3", "0"], ["84295.82", "0"], ["84296.03", "0"], ["84296.11", "0"], ["84296.15", "0"], ["84296.35", "0"], ["84297.21", "0"], ["84298.06", "0"], ["84298.23", "0"], ["84298.56", "0"], ["84298.63", "0"], ["84300.33", "0"], ["84300.37", "0"], ["84300.46", "0"], ["84300.98", "0"], ["84301.09", "0"], ["84302.02", "0"], ["84302.7", "0"], ["84302.87", "0.005276"], ["84308.66", "0.004808"], ["84309.72", "0"], ["84309.73", "0.000235"], ["84310.59", "0"], ["84310.6", "0"], ["84311.3", "0.0005"], ["84311.95", "0"], ["84312.05", "0"], ["84312.9", "0"], ["84313.84", "0.000296"], ["84313.85", "0.021922"], ["84313.89", "0"], ["84314.15", "0.083978"], ["84314.2", "0"], ["84314.7", "0"], ["84315.51", "0"], ["84315.71", "0"], ["84316.1", "0"], ["84316.2", "0"], ["84316.5", "0.003"], ["84317.06", "0.009548"], ["84317.87", "0"], ["84317.9", "0"], ["84317.99", "0"], ["84318", "0"], ["84318.82", "0"], ["84319.59", "0.093948"], ["84319.6", "0"], ["84320.28", "0"], ["84321.2", "0"], ["84321.4", "0.000612"], ["84321.6", "0.044"], ["84321.9", "0.06"], ["84322.91", "0.176789"], ["84322.92", "0"], ["84324.59", "0"], ["84324.83", "0"], ["84324.97", "0.023207"], ["84325.01", "0.109444"], ["84325.1", "0"], ["84325.55", "0.118117"], ["84325.74", "0.105721"], ["84325.9", "0"], ["84326.46", "0.166874"], ["84326.47", "0"], ["84327.51", "0.019095"], ["84327.92", "0"], ["84328.27", "0.00126"], ["84328.4", "0.048"], ["84328.6", "0.048"], ["84328.72", "0"], ["84328.85", "0"], ["84329.43", "0.004571"], ["84329.7", "0.014323"], ["84330.47", "0"], ["84331.26", "0.006034"], ["84331.33", "0"], ["84332.24", "0"], ["84332.58", "0.164346"], ["84333.38", "0"], ["84333.48", "0.023726"], ["84333.6", "0"], ["84333.73", "0.446345"], ["84334.1", "0.159338"], ["84334.69", "0"], ["84334.96", "0.005931"], ["84335.72", "0"], ["84336.99", "0.162077"], ["84338.12", "0.004746"], ["84338.48", "0.023726"], ["84339.28", "0.023726"], ["84341.13", "0.26314"], ["84341.89", "0.023726"], ["84342.65", "0.271218"], ["84343.23", "0.003"], ["84343.5", "0"], ["84343.51", "0"], ["84343.9", "0"], ["84344.16", "0.037741"], ["84345.25", "0.023726"], ["84345.35", "0"], ["84345.69", "0"], ["84346.62", "0.0002"], ["84348.1", "0.299829"], ["84348.6", "0.04"], ["84348.61", "0.04"], ["84349.15", "0.0002"], ["84350.17", "0"], ["84350.86", "0.428903"], ["84350.92", "0.000612"], ["84350.96", "0.001333"], ["84351.36", "0.000439"], ["84351.48", "0.000235"], ["84351.68", "0.0002"], ["84352", "0.000235"], ["84352.62", "0.015"], ["84353.24", "0.118791"], ["84353.72", "0.000253"], ["84353.89", "0.001467"], ["84354", "0.352467"], ["84354.59", "0.023727"], ["84354.92", "0.00109"], ["84355.14", "0.000612"], ["84355.15", "0.000357"], ["84355.18", "0.001333"], ["84356", "0.23724"], ["84356.01", "0.00009"], ["84356.12", "0.000235"], ["84356.13", "0.237266"], ["84356.64", "0.000235"], ["84357.02", "0.000085"], ["84358.07", "0.000335"]], "u": 7510686, "seq": 66889354597}, "cts": 1742142233207, "record_time": 1742142232.310081}
{"topic": "orderbook.200.BTCUSDT", "ts": 1742142233409, "type": "delta", "data": {"s": "BTCUSDT", "b": [["84302.86", "0.257048"], ["84302.03", "0.011862"], ["84300.98", "0.04345"], ["84300.97", "0.071179"], ["84298.65", "0.011862"], ["84296.13", "0.011862"], ["84296.03", "0.0002"], ["84295.82", "0.077095"], ["84295.81", "0"], ["84295.47", "0.008453"], ["84294.23", "0"], ["84294", "0"], ["84293.91", "0"], ["84293.58", "0.001867"], ["84292.39", "0"], ["84292.32", "0.071032"], ["84290.97", "0.0032"], ["84289.96", "0"], ["84289.93", "0.015078"], ["84287.1", "0.04"], ["84286.7", "0.04"], ["84286.04", "0.178386"], ["84285.55", "0"], ["84285.36", "0"], ["84285.1", "0.04"], ["84284.12", "0.003"], ["84283.92", "0.003"], ["84283.77", "0.009541"], ["84283.72", "0.003"], ["84283.4", "0.04"], ["84282.26", "0"], ["84281.8", "0"], ["84280.1", "0"], ["84279.34", "0.02"], ["84279.1", "0.048"], ["84277.8", "0.001476"], ["84277.4", "0.04"], ["84277", "0"], ["84276.81", "0"], ["84276.8", "0"], ["84275.51", "0"], ["84274.59", "0.13999"], ["84271.14", "0"], ["84270.98", "0.280248"], ["84266.9", "0.001243"], ["84265.14", "0.11"], ["84264.1", "0"], ["84262.41", "0"], ["84261.99", "0.082311"], ["84260.7", "0"], ["84259.29", "0.355869"], ["84258.6", "0"], ["84252.65", "0.000988"], ["84247.24", "0"], ["84247.08", "0"], ["84245.86", "0"]], "a": [["84308.66", "0"], ["84308.68", "0.007215"], ["84313.2", "0.000153"], ["84315.11", "0.020996"], ["84317.13", "0"], ["84323.3", "0.044"], ["84323.6", "0.068"], ["84324.85", "0.116965"], ["84325.01", "0"], ["84325.2", "0.04"], ["84325.3", "0.06"], ["84325.55", "0"], ["84325.74", "0"], ["84326.46", "0.167862"], ["84326.87", "0.17248"], ["84326.9", "0.068"], ["84327", "0.056"], ["84332.58", "0"], ["84333.88", "0.024267"], ["84334.1", "0.001333"], ["84336.82", "0.158454"], ["84336.98", "0.291663"], ["84336.99", "0"], ["84338.12", "0"], ["84341.13", "0"], ["84342.65", "0"], ["84348.1", "0"], ["84351.77", "0.162"], ["84356.64", "0"], ["84357.02", "0"], ["84358.07", "0"]], "u": 7510687, "seq": 66889354860}, "cts": 1742142233407, "record_time": 1742142232.509079}
{"topic": "orderbook.200.BTCUSDT", "ts": 1742142233609, "type": "delta", "data": {"s": "BTCUSDT", "b": [["84299.24", "0.000099"], ["84298.13", "0.237253"], ["84295.82", "0.083394"], ["84294.43", "0.049615"], ["84294.18", "0.107797"], ["84293.87", "0.105555"], ["84292.83", "0.009683"], ["84292.32", "0.072905"], ["84292.31", "0.12046"], ["84288.36", "0"], ["84286.55", "0.000482"], ["84286.04", "0.104032"], ["84285.47", "0.173369"], ["84285.31", "0.160544"], ["84285.15", "0.162"], ["84284.97", "0.02"], ["84284.51", "0.02"], ["84283.84", "0.02"], ["84282.71", "0.02"], ["84282.21", "0.172242"], ["84282.07", "0"], ["84281.61", "0"], ["84281.59", "0.23724"], ["84280.94", "0"], ["84280.5", "0"], ["84280.18", "0.014524"], ["84279.81", "0"], ["84278.4", "0"], ["84277.38", "0.23724"], ["84276.92", "0.270476"], ["84276.76", "0.272553"], ["84275.72", "0"], ["84271.1", "0.263866"], ["84270.98", "0"], ["84270.2", "0"], ["84265.14", "0"], ["84262.4", "0.000614"], ["84259.29", "0.355866"], ["84255.98", "0.237372"], ["84251", "0.000119"], ["84249.8", "0"], ["84249.76", "0"], ["84249.67", "0"], ["84249.51", "0"], ["84249.47", "0"], ["84249.43", "0"], ["84248.86", "0"], ["84248.31", "0"], ["84248", "0"], ["84247.9", "0"]], "a": [["84308.68", "0.0002"], ["84313.2", "0"], ["84321.6", "0"], ["84321.9", "0"], ["84322.39", "0"], ["84323.3", "0"], ["84323.6", "0"], ["84324.85", "0"], ["84324.97", "0.138646"], ["84325.3", "0"], ["84325.5", "0.108194"], ["84325.66", "0.115616"], ["84326.9", "0"], ["84327", "0"], ["84327.5", "0.00126"], ["84328", "0.068"], ["84328.27", "0"], ["84328.4", "0"], ["84328.6", "0"], ["84331.26", "0"], ["84331.27", "0.006065"], ["84331.3", "0.056"], ["84332.5", "0.179623"], ["84333.88", "0"], ["84334.05", "0.177805"], ["84335.18", "0.005"], ["84336.37", "0.23724"], ["84336.82", "0"], ["84336.94", "0.174091"], ["84337.3", "0"], ["84337.59", "0.017796"], ["84338.58", "0"], ["84340.58", "0.23724"], ["84341.05", "0.268532"], ["84342.61", "0.274556"], ["84344.94", "0.008453"], ["84348.06", "0.28664"], ["84348.6", "0"], ["84348.61", "0"], ["84349.6", "0.04"], ["84349.61", "0.04"], ["84356.64", "0.000235"], ["84357.02", "0.000085"], ["84357.1", "0.009"]], "u": 7510688, "seq": 66889355274}, "cts": 1742142233606, "record_time": 1742142232.708694}
{"topic": "orderbook.200.BTCUSDT", "ts": 1742142233809, "type": "delta", "data": {"s": "BTCUSDT", "b": [["84300.98", "0.130578"], ["84296.46", "0.155335"], ["84296.45", "0.237258"], ["84295.82", "0.000233"], ["84294.42", "0.162"], ["84294.18", "0"], ["84293.87", "0"], ["84292.35", "0.069358"], ["84292.32", "0"], ["84292.31", "0"], ["84287.68", "0.000863"], ["84286.55", "0.000233"], ["84286.04", "0.20537"], ["84285.5", "0.048"], ["84285.47", "0"], ["84285.31", "0"], ["84283.8", "0.04"], ["84282.24", "0.02"], ["84282.21", "0"], ["84279.34", "0"], ["84279.1", "0"], ["84276.93", "0.11863"], ["84276.92", "0"], ["84276.76", "0"], ["84271.1", "0"], ["84255.4", "0.24702"], ["84249.8", "0.001333"], ["84249.76", "0.000614"], ["84249.67", "0.023726"]], "a": [["84317.06", "0"], ["84319.59", "0.043398"], ["84321.65", "0.009783"], ["84324.97", "0"], ["84325.2", "0"], ["84325.5", "0"], ["84325.66", "0.001333"], ["84325.8", "0.044"], ["84326.2", "0.06"], ["84326.87", "0"], ["84327.5", "0.04526"], ["84329.6", "0.06"], ["84329.7", "0"], ["84331.2", "0.068"], ["84332.5", "0"], ["84332.8", "0.048"], ["84333", "0.048"], ["84333.87", "0"], ["84334.05", "0.000612"], ["84334.29", "0.014674"], ["84336", "0.000119"], ["84336.94", "0"], ["84336.98", "0"], ["84341.04", "0.059948"], ["84341.05", "0"], ["84342.61", "0"], ["84347.7", "0.013766"], ["84348.06", "0"], ["84349.6", "0"], ["84349.61", "0"], ["84349.7", "0.04"], ["84349.71", "0.04"], ["84357.3", "0.009"], ["84358.07", "0.000335"]], "u": 7510689, "seq": 66889355487}, "cts": 1742142233807, "record_time": 1742142232.908824}
{"topic": "orderbook.200.BTCUSDT", "ts": 1742142234010, "type": "delta", "data": {"s": "BTCUSDT", "b": [["84307.5", "0.555829"], ["84307.35", "0.044902"], ["84307.33", "0.111173"], ["84306.67", "0.011861"], ["84306.66", "0.0385"], ["84304.54", "0.023727"], ["84304.53", "0.065066"], ["84304.18", "0.001309"], ["84302.87", "0.0004"], ["84302.86", "0.00032"], ["84302.7", "0.000252"], ["84302.02", "0"], ["84301.09", "0.0002"], ["84300.98", "0.130102"], ["84300.97", "0"], ["84300.77", "0.011862"], ["84300.46", "0.000233"], ["84300.37", "0.001333"], ["84300.33", "0.000613"], ["84299.07", "0.049115"], ["84298.65", "0"], ["84298.23", "0.001467"], ["84298.18", "0.009813"], ["84296.41", "0.111018"], ["84296.13", "0"], ["84294.43", "0.0005"], ["84293.59", "0.001467"], ["84293.58", "0"], ["84292.83", "0"], ["84292.8", "0.015077"], ["84292.41", "0.070848"], ["84292.35", "0"], ["84292.33", "0.06031"], ["84291.19", "0.000482"], ["84289.93", "0"], ["84289.57", "0.175216"], ["84288.78", "0.003"], ["84288.67", "0.237227"], ["84288.59", "0.237227"], ["84288.58", "0.003"], ["84288.38", "0.003"], ["84287.68", "0.000614"], ["84286.04", "0.104032"], ["84285.77", "0.02"], ["84285.54", "0.014719"], ["84285.31", "0.02"], ["84284.97", "0"], ["84284.74", "0.02"], ["84284.73", "0"], ["84284.51", "0"], ["84284.45", "0.16715"], ["84284.38", "0.237227"], ["84283.84", "0"], ["84283.51", "0.021333"], ["84282.8", "0.237422"], ["84282.71", "0"], ["84282.24", "0"], ["84281.02", "0.296276"], ["84280.36", "0"], ["84280.18", "0"], ["84280.16", "0"], ["84278.57", "0.071198"], ["84277.82", "0.185243"], ["84277.4", "0"], ["84275.95", "0"], ["84274.6", "0.158158"], ["84274.08", "0"], ["84268.95", "0.17792"], ["84264.82", "0"], ["84262", "0.355859"], ["84261.9", "0.004576"], ["84260.43", "0.023722"], ["84259.29", "0"], ["84259.1", "0.177763"], ["84255.6", "0.24702"], ["84255.4", "0"], ["84254.63", "0"], ["84254.1", "0"], ["84254.01", "0"], ["84253.97", "0"], ["84253.35", "0"], ["84253.05", "0"], ["84252.72", "0"], ["84252.71", "0"], ["84252.65", "0"], ["84251.95", "0"], ["84251.88", "0"], ["84251.71", "0"], ["84251.7", "0"], ["84251", "0"], ["84250.71", "0"], ["84250.52", "0"], ["84250", "0"], ["84249.8", "0"], ["84249.76", "0"], ["84249.67", "0"]], "a": [["84302.87", "0"], ["84303.62", "0"], ["84303.73", "0"], ["84304.54", "0"], ["84304.58", "0"], ["84305.05", "0"], ["84305.1", "0"], ["84305.62", "0"], ["84306.15", "0"], ["84307.34", "0"], ["84307.51", "0.003881"], ["84311.3", "0"], ["84312.97", "0.007558"], ["84313.46", "0"], ["84313.84", "0"], ["84313.85", "0.000335"], ["84314.15", "0"], ["84315.11", "0"], ["84315.37", "0"], ["84315.94", "0.0005"], ["84316.49", "0.000296"], ["84316.61", "0.014072"], ["84318", "0.020996"], ["84318.46", "0.000296"], ["84318.47", "0.083984"], ["84319.59", "0"], ["84322.91", "0.032501"], ["84324.58", "0"], ["84327.42", "0.023186"], ["84329.76", "0.120432"], ["84331.27", "0"], ["84331.58", "0.068395"], ["84333.2", "0.04"], ["84333.48", "0"], ["84334.9", "0"], ["84336.36", "0.226385"], ["84336.37", "0"], ["84336.6", "0.165567"], ["84338.48", "0"], ["84339.18", "0.023933"], ["84339.28", "0"], ["84340.57", "0.168298"], ["84341.04", "0"], ["84341.89", "0"], ["84343.29", "0.023722"], ["84343.36", "0.237227"], ["84344.16", "0.03181"], ["84345.15", "0.295401"], ["84345.25", "0"], ["84347.57", "0.237227"], ["84348.29", "0.023722"], ["84349.09", "0.023722"], ["84349.65", "0.474217"], ["84349.7", "0"], ["84349.71", "0"], ["84351.69", "0.023722"], ["84351.89", "0.04"], ["84351.9", "0.04"], ["84353.97", "0.00593"], ["84354.21", "0.0002"], ["84354.59", "0"], ["84356", "0"], ["84356.13", "0"], ["84356.16", "0.023722"], ["84356.74", "0.0002"], ["84358.36", "0.000253"], ["84358.53", "0.001467"], ["84359.29", "0.002853"], ["84359.3", "0.246059"], ["84359.36", "0.000612"]], "u": 7510690, "seq": 66889356820}, "cts": 1742142234006, "record_time": 1742142233.109098}
{"topic": "orderbook.200.BTCUSDT", "ts": 1742142234210, "type": "delta", "data": {"s": "BTCUSDT", "b": [["84307.5", "0.556078"], ["84307.33", "0.071173"], ["84304.54", "0"], ["84304.53", "0"], ["84303.62", "0.0002"], ["84302.86", "0.00012"], ["84300.98", "0.066978"], ["84299.24", "0"], ["84298.18", "0.024889"], ["84298.13", "0"], ["84297.76", "0.106173"], ["84297.44", "0.106184"], ["84296.46", "0.058429"], ["84296.45", "0"], ["84296.41", "0"], ["84295.93", "0.117776"], ["84292.8", "0"], ["84292.41", "0.238257"], ["84292.34", "0.000817"], ["84291.19", "0.000233"], ["84289.57", "0"], ["84289.09", "0.168542"], ["84288.89", "0.178687"], ["84286.04", "0.233228"], ["84285.78", "0.165764"], ["84285.41", "0.02"], ["84285.31", "0"], ["84283.61", "0.02"], ["84283.51", "0.001333"], ["84282.35", "0.023723"], ["84281.02", "0"], ["84280.33", "0.289808"], ["84278.57", "0"], ["84277.82", "0.106625"], ["84274.67", "0.270909"], ["84267.35", "0.071207"], ["84262.01", "0.355854"], ["84262", "0"], ["84255.6", "0"], ["84255.58", "0"], ["84254.9", "0"]], "a": [["84310.88", "0.011861"], ["84310.89", "0.011857"], ["84310.9", "0.011858"], ["84310.95", "0.011861"], ["84312.97", "0.000612"], ["84316.49", "0"], ["84317.99", "0.000296"], ["84318", "0"], ["84318.46", "0"], ["84318.47", "0"], ["84320", "0.034238"], ["84320.24", "0.046299"], ["84323.38", "0.020995"], ["84325.49", "0.08398"], ["84328.54", "0.116779"], ["84329.08", "0.105496"], ["84329.76", "0"], ["84332.83", "0.162"], ["84335.1", "0.006076"], ["84336.6", "0"], ["84337.63", "0.164338"], ["84340.18", "0.023723"], ["84340.51", "0.166375"], ["84344.79", "0.237227"], ["84345.15", "0"], ["84346.18", "0.292478"], ["84351.63", "0.279802"], ["84351.89", "0"], ["84351.9", "0"], ["84354", "0.392467"], ["84354.01", "0.04"], ["84356.74", "0"], ["84357.02", "0"], ["84357.1", "0"], ["84357.3", "0"], ["84358.07", "0"], ["84358.36", "0"], ["84358.53", "0"], ["84359.29", "0"], ["84359.3", "0"], ["84359.36", "0"]], "u": 7510691, "seq": 66889357108}, "cts": 1742142234205, "record_time": 1742142233.309059}
{"topic": "orderbook.200.BTCUSDT", "ts": 1742142234410, "type": "delta", "data": {"s": "BTCUSDT", "b": [["84307.5", "0.528839"], ["84303.88", "0.000099"], ["84302.4", "0.074791"], ["84302.39", "0.237241"], ["84300.98", "0.269761"], ["84299.62", "0.237249"], ["84299.07", "0.049615"], ["84297.93", "0.237254"], ["84297.76", "0"], ["84297.44", "0"], ["84297", "0.04"], ["84296.7", "0.04"], ["84296.46", "0.115306"], ["84295.93", "0"], ["84295.3", "0.04"], ["84294.43", "0"], ["84293.82", "0.003"], ["84293.8", "0.048"], ["84293.62", "0.003"], ["84293.42", "0.00396"], ["84293.3", "0.04"], ["84292.1", "0.04"], ["84290.3", "0.04"], ["84290", "0.04"], ["84289.09", "0"], ["84288.89", "0"], ["84288.7", "0.001243"], ["84287.87", "0.02"], ["84287.4", "0.02"], ["84287.1", "0"], ["84286.84", "0.02"], ["84285.8", "0.237227"], ["84285.78", "0"], ["84285.77", "0"], ["84285.71", "0.02"], ["84285.5", "0"], ["84285.41", "0"], ["84285.1", "0"], ["84284.74", "0"], ["84283.61", "0"], ["84282", "0"], ["84281.7", "0"], ["84280.33", "0"], ["84277.38", "0"], ["84274.67", "0"], ["84263.86", "0"], ["84262.01", "0"], ["84257.26", "0.000988"], ["84255.99", "0.355868"], ["84255.98", "0"], ["84255.64", "0"]], "a": [["84310.26", "0.014901"], ["84317.99", "0"], ["84319.99", "0.000296"], ["84322.91", "0.05993"], ["84326.46", "0.166874"], ["84327.42", "0"], ["84328.54", "0"], ["84329.08", "0"], ["84331.12", "0.000988"], ["84333.74", "0"], ["84337.63", "0"], ["84340.51", "0"], ["84342.6", "1.444009"], ["84344.79", "0"], ["84345.94", "0.004745"], ["84346.18", "0"], ["84348.25", "0"], ["84351.63", "0"], ["84353.22", "0.17792"], ["84354", "0.352467"], ["84354.01", "0"], ["84354.2", "0.04"], ["84354.21", "0.0402"], ["84354.77", "0.027942"], ["84356.74", "0.0002"], ["84357.02", "0.000085"], ["84357.1", "0.0045"], ["84357.3", "0.0045"], ["84358.07", "0.000335"]], "u": 7510692, "seq": 66889357357}, "cts": 1742142234407, "record_time": 1742142233.508951}
{"topic": "orderbook.200.BTCUSDT", "ts": 1742142234610, "type": "delta", "data": {"s": "BTCUSDT", "b": [["84308.79", "0.801117"], ["84307.95", "0.0385"], ["84307.52", "0.02497"], ["84307.5", "0"], ["84307.35", "0"], ["84306.66", "0"], ["84306.15", "0.0002"], ["84304.54", "0.000613"], ["84302.87", "0.001867"], ["84302.4", "0"], ["84302.39", "0"], ["84300.98", "0.146744"], ["84300.77", "0"], ["84299.62", "0"], ["84299.08", "0.237251"], ["84297.94", "0.115979"], ["84297.93", "0"], ["84297.62", "0.119368"], ["84296.64", "0.060305"], ["84296.46", "0.227747"], ["84296.08", "0.106189"], ["84295.55", "0.105346"], ["84295.54", "0.23726"], ["84294.9", "0.04"], ["84292.33", "0"], ["84291.6", "0.04"], ["84289.21", "0.159305"], ["84289.03", "0.176333"], ["84288.8", "0"], ["84288.4", "0"], ["84286.96", "0.173887"], ["84286.84", "0"], ["84286.74", "0.02"], ["84286.7", "0"], ["84285.92", "0.159045"], ["84285.8", "0"], ["84285.14", "0.02"], ["84284.12", "0"], ["84283.92", "0"], ["84283.8", "0"], ["84283.72", "0"], ["84283.4", "0"], ["84282.8", "0.145073"], ["84280.62", "0.300198"], ["84280.44", "0.282283"], ["84278.37", "0.273186"], ["84277.85", "1.417054"], ["84277.82", "0"], ["84277.67", "0"], ["84277.48", "0.042884"], ["84277.47", "0"], ["84277.38", "0.237223"], ["84277.27", "0"], ["84274.75", "0.283022"], ["84264.83", "0"], ["84258.22", "0"], ["84256", "0.357122"], ["84255.99", "0"]], "a": [["84307.51", "0"], ["84308.68", "0"], ["84308.76", "0"], ["84308.8", "0.002519"], ["84310.26", "0.022181"], ["84314.89", "0.005155"], ["84315.94", "0"], ["84317.23", "0.001833"], ["84328.87", "0.118868"], ["84329.4", "0.110434"], ["84329.58", "0.112049"], ["84331.29", "0.153375"], ["84332.49", "0.120352"], ["84333.73", "0"], ["84336.36", "0"], ["84336.37", "0.237223"], ["84336.45", "0.16693"], ["84337.33", "0.148035"], ["84337.99", "0.172872"], ["84340.57", "0.555361"], ["84340.89", "0.162101"], ["84341.07", "0.172244"], ["84345.04", "0.29306"], ["84345.94", "0"], ["84346.58", "0.26378"], ["84349.66", "0.293414"], ["84352.06", "0.265825"], ["84356.01", "0"], ["84356.12", "0"], ["84356.16", "0"], ["84356.64", "0"], ["84356.74", "0"], ["84357.02", "0"], ["84357.1", "0"], ["84357.3", "0"], ["84358.07", "0"]], "u": 7510693, "seq": 66889357813}, "cts": 1742142234606, "record_time": 1742142233.708228}
{"topic": "orderbook.200.BTCUSDT", "ts": 1742142234809, "type": "delta", "data": {"s": "BTCUSDT", "b": [["84308.79", "0.035769"], ["84307.96", "0.015168"], ["84307.52", "0"], ["84307.33", "0"], ["84306.67", "0"], ["84304.58", "0.011861"], ["84303.88", "0"], ["84302.87", "0.001467"], ["84302.86", "0"], ["84299.08", "0"], ["84298.18", "0.015076"], ["84297.94", "0"], ["84297.62", "0"], ["84296.46", "0"], ["84296.08", "0"], ["84295.55", "0"], ["84295.54", "0"], ["84295.47", "0"], ["84295.22", "0.237261"], ["84294.42", "0"], ["84294.29", "0.1135"], ["84293.02", "0.10628"], ["84292.37", "0.010114"], ["84291.67", "0.1186"], ["84289.67", "0.02"], ["84289.21", "0"], ["84289.03", "0"], ["84288.75", "0.02"], ["84288.67", "0"], ["84288.64", "0.02"], ["84288.59", "0"], ["84287.87", "0"], ["84287.4", "0"], ["84287.04", "0.02"], ["84286.96", "0"], ["84286.95", "0.02"], ["84286.74", "0"], ["84286.23", "0.008453"], ["84286.15", "0.168543"], ["84286.03", "0"], ["84285.92", "0.0002"], ["84285.71", "0"], ["84285.7", "0.180568"], ["84285.54", "0"], ["84285.14", "0"], ["84284.45", "0"], ["84284.38", "0"], ["84283.08", "0.157666"], ["84280.62", "0"], ["84280.44", "0"], ["84279.72", "0.015172"], ["84278.37", "0"], ["84277.86", "0.53781"], ["84277.48", "0"], ["84277.11", "0.27786"], ["84276.93", "0"], ["84274.75", "0"], ["84274.49", "0.293575"], ["84271.85", "0.059948"], ["84271.49", "0"], ["84269.28", "0.015"], ["84260.29", "0.071213"], ["84259.1", "0"], ["84258.55", "0.000988"], ["84257.26", "0"], ["84256", "0.001243"], ["84255.98", "0.237372"], ["84255.64", "0.023726"], ["84255.6", "0.24702"], ["84255.58", "0.0002"], ["84254.9", "0.059948"], ["84254.63", "0.000233"], ["84254.1", "0.000233"], ["84254.01", "0.001333"], ["84253.97", "0.000614"], ["84253.35", "0.005931"], ["84253.09", "0.001"], ["84253.05", "0.0002"], ["84251.95", "0.00009"], ["84251.88", "0.001467"]], "a": [["84308.8", "0.075588"], ["84313.01", "0.002927"], ["84314.89", "0.0103"], ["84316.98", "0.010121"], ["84321.65", "0"], ["84322.89", "0.099582"], ["84322.9", "0.11863"], ["84322.91", "0"], ["84325.11", "0.03181"], ["84326.07", "0.107323"], ["84326.46", "0.237165"], ["84326.52", "0.12044"], ["84326.68", "0.089922"], ["84327.92", "0.024202"], ["84328.61", "0.119045"], ["84328.87", "0"], ["84329.4", "0"], ["84329.58", "0"], ["84329.63", "0.015182"], ["84331.12", "0"], ["84332.4", "0.000988"], ["84332.49", "0"], ["84333.39", "0.176857"], ["84334.29", "0"], ["84334.66", "0.181286"], ["84336.45", "0"], ["84337.2", "0.158579"], ["84337.63", "0.027942"], ["84337.99", "0"], ["84340.56", "0.059948"], ["84340.89", "0"], ["84341.07", "0"], ["84341.98", "0.295423"], ["84344.16", "0"], ["84345.04", "0"], ["84345.79", "0.263025"], ["84346.58", "0"], ["84346.67", "0.022181"], ["84349.66", "0"], ["84352.06", "0"], ["84353.21", "0.355891"], ["84354.77", "0"], ["84355.14", "0"], ["84355.15", "0"], ["84355.18", "0"]], "u": 7510694, "seq": 66889358195}, "cts": 1742142234808, "record_time": 1742142233.908724}
{"topic": "orderbook.200.BTCUSDT", "ts": 1742142235009, "type": "delta", "data": {"s": "BTCUSDT", "b": [["84308.79", "0.023568"], ["84307.96", "0"], ["84307.95", "0"], ["84305.17", "0.000099"], ["84304.58", "0"], ["84302.03", "0"], ["84300.98", "0.000233"], ["84300.32", "0"], ["84299.08", "0.041754"], ["84297", "0"], ["84296.7", "0"], ["84296.65", "0.019766"], ["84295.3", "0"], ["84295.22", "0"], ["84294.9", "0"], ["84294.29", "0"], ["84293.82", "0"], ["84293.8", "0"], ["84293.62", "0"], ["84293.42", "0.00096"], ["84293.3", "0"], ["84293.02", "0"], ["84292.42", "0.059948"], ["84292.41", "0"], ["84292.37", "0"], ["84292.34", "0"], ["84292.1", "0"], ["84291.67", "0"], ["84291.6", "0"], ["84290.96", "0"], ["84290.5", "0.04"], ["84290.3", "0"], ["84290", "0"], ["84289.67", "0"], ["84288.75", "0"], ["84288.64", "0"], ["84288.59", "0.000297"], ["84288.2", "0.04"], ["84287.72", "0.001582"], ["84287.61", "0.010181"], ["84287.04", "0"], ["84286.95", "0"], ["84286.84", "0.02"], ["84286.27", "0.02"], ["84286.23", "0"], ["84286.15", "0"], ["84286.04", "0.104032"], ["84285.81", "0.02"], ["84285.7", "0"], ["84285.24", "0.02"], ["84285.15", "0"], ["84284.11", "0"], ["84283.77", "0"], ["84283.47", "0.162614"], ["84283.08", "0"], ["84281.92", "0"], ["84281.59", "0"], ["84279.72", "0"], ["84279.12", "0"], ["84278.57", "0.068395"], ["84277.87", "0.059948"], ["84277.38", "0"], ["84277.11", "0"], ["84276.33", "0.00593"], ["84276.27", "0.009541"], ["84275.95", "0.237223"], ["84275.61", "0"], ["84275.22", "0.008453"], ["84274.97", "0.015272"], ["84274.49", "0"], ["84271.85", "0"], ["84271.74", "0.237223"], ["84271.35", "0"], ["84269.28", "0"], ["84268.95", "0"], ["84267.4", "0.288198"], ["84267.35", "0"], ["84266.9", "0.00206"], ["84264.77", "0"], ["84259.28", "0"], ["84259.1", "0.177917"], ["84255.98", "0"], ["84255.87", "0.071217"], ["84253.54", "0.162"], ["84251.71", "0.000252"], ["84251.7", "0.003"], ["84250.52", "0.0002"], ["84250", "0.000233"], ["84249.92", "0.000357"], ["84249.8", "0.001333"], ["84249.76", "0.000614"], ["84249.67", "0.023726"], ["84249.51", "0.11863"], ["84249.47", "0.000233"], ["84249.43", "0.089922"], ["84248.86", "0.023726"], ["84248", "0.001653"], ["84247.69", "0.013727"], ["84247.24", "0.001467"], ["84247.08", "0.000252"], ["84245.86", "0.000089"], ["84245.59", "0.001333"], ["84245.55", "0.000614"], ["84245.47", "0.0002"], ["84245.36", "0.000233"], ["84245.1", "0.001243"], ["84244.84", "0.000233"], ["84244.68", "0.059948"], ["84243.87", "0.023726"], ["84243.57", "0.023729"], ["84243.5", "0.00009"], ["84242.61", "0.001467"], ["84242.44", "0.000252"]], "a": [["84308.8", "0.21909"], ["84310.25", "0.025663"], ["84310.26", "0.000235"], ["84311.86", "0.010183"], ["84313.01", "0.01186"], ["84313.85", "0.070247"], ["84313.86", "0.11863"], ["84316.61", "0.000253"], ["84316.62", "0.089922"], ["84316.98", "0"], ["84319.55", "0.008453"], ["84320", "0.000113"], ["84320.67", "0.000789"], ["84322.89", "0.149393"], ["84323.17", "0.068395"], ["84324.5", "0.015274"], ["84325.11", "0"], ["84326.07", "0"], ["84326.52", "0"], ["84328.61", "0"], ["84329.63", "0"], ["84330.72", "0.237223"], ["84331.57", "0.059948"], ["84331.58", "0"], ["84332.35", "0.02466"], ["84332.76", "0.552449"], ["84333.39", "0"], ["84334.41", "0"], ["84334.66", "0"], ["84334.93", "0.237223"], ["84335.18", "0"], ["84336.36", "0.275218"], ["84336.37", "0"], ["84337.2", "0"], ["84337.24", "0.27859"], ["84337.33", "0"], ["84337.49", "0.118612"], ["84337.63", "0"], ["84339.18", "0"], ["84339.33", "0.023722"], ["84340.58", "0"], ["84341.98", "0"], ["84342.1", "0.027942"], ["84343.36", "0"], ["84344.94", "0"], ["84345.79", "0"], ["84346.22", "0.355913"], ["84347.57", "0"], ["84353.21", "0"], ["84353.22", "0"], ["84355.14", "0.000612"], ["84355.15", "0.000357"], ["84355.18", "0.001333"], ["84356.01", "0.00009"], ["84356.12", "0.000235"]], "u": 7510695, "seq": 66889359458}, "cts": 1742142235008, "record_time": 1742142234.10885}
{"topic": "orderbook.200.BTCUSDT", "ts": 1742142235210, "type": "delta", "data": {"s": "BTCUSDT", "b": [["84308.79", "0.030327"], ["84302.07", "0.0194"], ["84302.06", "0.002067"], ["84300.36", "0.0005"], ["84299.1", "0.000297"], ["84299.09", "0.031104"], ["84299.07", "0.049115"], ["84296.65", "0.03865"], ["84295.25", "0.071184"], ["84292.43", "0.095948"], ["84290.97", "0.0002"], ["84289.91", "0.106137"], ["84289.61", "0.112393"], ["84288.96", "0.001716"], ["84288.72", "0.114974"], ["84288.21", "0.04038"], ["84287.72", "0.001333"], ["84286.99", "0.105964"], ["84286.84", "0"], ["84286.5", "0.04"], ["84286.1", "0.04"], ["84286.04", "0"], ["84285.91", "0.02"], ["84285.81", "0"], ["84285.1", "0.048"], ["84284.5", "0.04"], ["84283.48", "0.104761"], ["84283.3", "0.04"], ["84282.8", "0.04"], ["84282.21", "0.164211"], ["84281.47", "0.176953"], ["84278.85", "0.168965"], ["84278.52", "0.17699"], ["84278.42", "0.000817"], ["84274.08", "0.289262"], ["84273.34", "0.292589"], ["84270.72", "0.272259"], ["84267.94", "0.285472"], ["84267.4", "0"], ["84266.9", "0.001243"], ["84251.7", "0"], ["84249.76", "0"], ["84249.67", "0"], ["84249.51", "0"], ["84249.47", "0"], ["84249.43", "0"], ["84248.86", "0"], ["84248", "0"], ["84247.69", "0"], ["84247.24", "0"], ["84247.08", "0"], ["84245.86", "0"], ["84245.59", "0"], ["84245.55", "0"], ["84245.47", "0"], ["84245.36", "0"], ["84245.1", "0"], ["84244.84", "0"], ["84244.68", "0"], ["84243.87", "0"], ["84243.57", "0"], ["84243.5", "0"], ["84242.61", "0"], ["84242.44", "0"]], "a": [["84309.63", "0.011861"], ["84319.06", "0.141169"], ["84319.19", "0.11448"], ["84319.55", "0"], ["84319.71", "0.114778"], ["84320.24", "0"], ["84320.45", "0.115627"], ["84321.97", "0.111721"], ["84326.3", "0.008453"], ["84326.87", "0.03181"], ["84326.96", "0.162968"], ["84327.3", "0.04"], ["84327.84", "0.177121"], ["84330.1", "0.177136"], ["84330.58", "0.176087"], ["84331.29", "0.30046"], ["84335.09", "0.27114"], ["84335.98", "0.27376"], ["84337.24", "0"], ["84338.24", "0.294971"], ["84339.27", "0.237223"], ["84341.16", "0.286209"], ["84346.22", "0"], ["84348.17", "0.355913"], ["84351.92", "0.237223"], ["84352", "0"], ["84352.62", "0"], ["84353.24", "0"], ["84353.72", "0"], ["84353.89", "0"], ["84353.97", "0"], ["84354", "0"], ["84354.2", "0"], ["84354.21", "0"], ["84354.92", "0"], ["84355.14", "0"], ["84355.15", "0"], ["84355.18", "0"], ["84356.01", "0"], ["84356.12", "0"]], "u": 7510696, "seq": 66889359983}, "cts": 1742142235204, "record_time": 1742142234.308667}
{"topic": "orderbook.200.BTCUSDT", "ts": 1742142235409, "type": "delta", "data": {"s": "BTCUSDT", "b": [["84308.79", "0.011186"], ["84302.06", "0"], ["84299.11", "0.031104"], ["84299.09", "0.000297"], ["84298.18", "0"], ["84296.65", "0.019766"], ["84296.64", "0"], ["84295.25", "0"], ["84292.99", "0.071185"], ["84292.43", "0.064956"], ["84291.67", "0.015077"], ["84289.91", "0"], ["84289.61", "0"], ["84289.07", "0.109836"], ["84288.96", "0.001467"], ["84288.95", "0.06031"], ["84288.79", "0.000501"], ["84288.77", "0.116312"], ["84288.72", "0"], ["84288.59", "0"], ["84288.36", "0.110037"], ["84288.21", "0.111447"], ["84287.61", "0"], ["84286.99", "0"], ["84286.47", "0.02"], ["84286.27", "0"], ["84286.1", "0.150154"], ["84286", "0.02"], ["84285.91", "0"], ["84285.44", "0.02"], ["84285.24", "0"], ["84284.6", "0.003"], ["84284.4", "0.003"], ["84283.37", "0.010305"], ["84282.35", "0"], ["84282.21", "0"], ["84281.86", "0.160851"], ["84281.47", "0"], ["84281.4", "0.04"], ["84281.1", "0.04"], ["84280.64", "0.180444"], ["84278.85", "0"], ["84278.52", "0"], ["84277.96", "0.168351"], ["84277.85", "0"], ["84277.68", "0.166213"], ["84275.95", "0"], ["84274.97", "0"], ["84274.08", "0"], ["84273.72", "0.294503"], ["84273.34", "0"], ["84272.5", "0.274771"], ["84271.74", "0"], ["84270.73", "0.015458"], ["84270.72", "0"], ["84268.74", "0"], ["84267.94", "0"], ["84267.51", "0"], ["84267.11", "0.281087"], ["84259.1", "0"], ["84249.76", "0.000614"], ["84249.67", "0.023726"], ["84249.51", "0.11863"], ["84249.47", "0.000233"], ["84249.43", "0.089922"], ["84248.86", "0.023726"]], "a": [["84308.8", "0.293206"], ["84313.85", "0.099713"], ["84314.87", "0.068395"], ["84314.88", "0.037958"], ["84316.8", "0.020997"], ["84318.28", "0.103556"], ["84318.29", "0.083988"], ["84318.36", "0.106541"], ["84318.87", "0.115492"], ["84319.06", "0"], ["84319.19", "0"], ["84319.71", "0"], ["84320.09", "0.112892"], ["84320.45", "0"], ["84321.08", "0.119475"], ["84321.97", "0.000089"], ["84323.17", "0"], ["84323.38", "0"], ["84325.49", "0"], ["84326.46", "0.336921"], ["84326.6", "0.163111"], ["84326.96", "0"], ["84327.01", "0.169892"], ["84327.84", "0"], ["84329.21", "0.159589"], ["84329.75", "0.175191"], ["84330.1", "0"], ["84330.58", "0"], ["84332.76", "0"], ["84333.2", "0"], ["84334.73", "0.287376"], ["84335.09", "0"], ["84335.14", "0.295245"], ["84335.98", "0"], ["84338.24", "0"], ["84338.48", "0.023722"], ["84338.6", "0.003358"], ["84340.32", "0.285114"], ["84341.16", "0"], ["84346.22", "0.355925"], ["84348.17", "0"], ["84349.82", "0.323213"], ["84351.77", "0"], ["84351.92", "0"]], "u": 7510697, "seq": 66889360556}, "cts": 1742142235407, "record_time": 1742142234.508073}
{"topic": "orderbook.200.BTCUSDT", "ts": 1742142235609, "type": "delta", "data": {"s": "BTCUSDT", "b": [["84308.79", "0.111186"], ["84304.58", "0.007885"], ["84302.06", "0.011862"], ["84299.11", "0"], ["84299.1", "0"], ["84299.09", "0"], ["84296.65", "0"], ["84293.14", "0.071329"], ["84293.08", "0.000297"], ["84292.99", "0"], ["84292.33", "0.112936"], ["84292.03", "0.1123"], ["84291.67", "0.123151"], ["84289.07", "0"], ["84288.96", "0.001716"], ["84288.91", "0.111769"], ["84288.79", "0.000252"], ["84288.77", "0"], ["84288.44", "0.01056"], ["84288.36", "0"], ["84287.8", "0.02"], ["84287.14", "0.02"], ["84286.57", "0.02"], ["84286.47", "0"], ["84286.1", "0.04"], ["84286", "0"], ["84285.91", "0.02"], ["84285.44", "0"], ["84285.11", "0.172958"], ["84283.83", "0.171755"], ["84283.37", "0"], ["84281.86", "0"], ["84280.85", "0.175567"], ["84280.71", "0.171777"], ["84280.64", "0"], ["84277.96", "0"], ["84277.86", "0"], ["84277.68", "0"], ["84277.38", "0.237223"], ["84275.8", "0.01574"], ["84275.63", "0.277553"], ["84273.72", "0"], ["84273.16", "0.237223"], ["84272.51", "0.280326"], ["84272.5", "0"], ["84270.73", "0"], ["84269.27", "0"], ["84268.29", "0.023924"], ["84267.14", "0.071207"], ["84267.11", "0"], ["84265.55", "1.421806"], ["84256.59", "0.015"], ["84255.88", "0.474514"], ["84255.87", "0"], ["84248.86", "0"]], "a": [["84308.8", "0.092725"], ["84309.63", "0.005885"], ["84310.25", "0"], ["84313.85", "0.060057"], ["84314.87", "0"], ["84316.5", "0"], ["84316.62", "0"], ["84318.28", "0.070066"], ["84318.36", "0"], ["84318.87", "0"], ["84319.1", "0.06"], ["84320.09", "0"], ["84320.3", "0.044"], ["84321.08", "0"], ["84321.84", "0.113935"], ["84322.3", "0.04"], ["84322.36", "0.108046"], ["84322.4", "0.06"], ["84322.77", "0.068395"], ["84322.89", "0.099582"], ["84323.65", "0.108871"], ["84324", "0.068"], ["84324.16", "0.116402"], ["84325.29", "0.03181"], ["84325.6", "0.048"], ["84325.8", "0.092"], ["84326.3", "0"], ["84326.6", "0"], ["84326.68", "0"], ["84326.87", "0"], ["84327.01", "0"], ["84327.3", "0"], ["84327.5", "0.00126"], ["84329.21", "0"], ["84329.6", "0"], ["84329.75", "0"], ["84330.2", "0.166876"], ["84330.56", "0.169775"], ["84330.71", "0.236302"], ["84330.72", "0"], ["84331.29", "0"], ["84331.57", "0"], ["84332.15", "0.237223"], ["84332.36", "0.180288"], ["84332.8", "0"], ["84332.88", "0.008453"], ["84333", "0"], ["84333.32", "0.174225"], ["84334.73", "0"], ["84334.93", "0"], ["84335.14", "0"], ["84336.36", "0"], ["84336.37", "0.237223"], ["84338.4", "0.264127"], ["84338.76", "0.288783"], ["84339.27", "0"], ["84340.32", "0"], ["84340.56", "0.335395"], ["84342.1", "0"], ["84342.6", "0"], ["84343.98", "0.300613"], ["84346.22", "0"], ["84351.92", "0.237223"], ["84352", "0.000235"], ["84352.62", "0.015"], ["84352.87", "0.027942"], ["84353.24", "0.118791"], ["84353.72", "0.000253"], ["84353.89", "0.001467"], ["84353.97", "0.00593"], ["84354", "0.352467"]], "u": 7510698, "seq": 66889361185}, "cts": 1742142235606, "record_time": 1742142234.70903}
{"topic": "orderbook.200.BTCUSDT", "ts": 1742142235810, "type": "delta", "data": {"s": "BTCUSDT", "b": [["84308.79", "0.011186"], ["84304.58", "0.001823"], ["84299.1", "0.000297"], ["84299.09", "0.032604"], ["84298.42", "0.071181"], ["84293.14", "0.000297"], ["84292.43", "0.06222"], ["84292.33", "0"], ["84292.03", "0"], ["84291.67", "0.015077"], ["84290.04", "0.105817"], ["84289.74", "0.116936"], ["84289.37", "0.110103"], ["84288.96", "0.001467"], ["84288.91", "0"], ["84288.79", "0.000501"], ["84288.27", "0.02"], ["84287.8", "0"], ["84287.7", "0.02"], ["84286.92", "0.10985"], ["84286.57", "0"], ["84285.54", "0.02"], ["84285.11", "0"], ["84283.83", "0"], ["84283.48", "0.236752"], ["84282.81", "0.169064"], ["84281.54", "0.179424"], ["84280.85", "0"], ["84280.71", "0"], ["84278.72", "0.16576"], ["84278.56", "0.175035"], ["84277.38", "0"], ["84275.63", "0"], ["84274.61", "0.27917"], ["84273.34", "0.293848"], ["84273.16", "0"], ["84272.51", "0"], ["84270.52", "0.284907"], ["84267.91", "0.286112"], ["84255.88", "0"], ["84255.37", "0.323575"], ["84253.55", "0.355892"], ["84249.8", "0"], ["84249.76", "0"], ["84249.67", "0"], ["84249.51", "0"], ["84249.47", "0"], ["84249.43", "0"]], "a": [["84308.8", "0.24399"], ["84309.63", "0.011861"], ["84310.87", "0.022063"], ["84315.22", "0.089922"], ["84318.28", "0.126688"], ["84319.56", "0.107696"], ["84320.08", "0.118731"], ["84321.34", "0.116703"], ["84321.84", "0"], ["84322.17", "0.120092"], ["84322.36", "0"], ["84322.89", "0.186478"], ["84323.65", "0.000235"], ["84324.16", "0"], ["84326.2", "0"], ["84326.46", "0"], ["84326.77", "0.66619"], ["84326.86", "0.089922"], ["84327.9", "0.161325"], ["84328.27", "0.176154"], ["84330.2", "0"], ["84330.37", "0.172895"], ["84330.56", "0"], ["84330.7", "1.482159"], ["84331.04", "0.171771"], ["84331.2", "0"], ["84332.36", "0"], ["84333.32", "0"], ["84334.93", "0.237223"], ["84336.1", "0.293834"], ["84336.47", "0.267275"], ["84338.4", "0"], ["84338.57", "0.269917"], ["84338.76", "0"], ["84339.15", "0.237223"], ["84340.56", "0.059948"], ["84340.57", "0"], ["84341.69", "0.276826"], ["84343.98", "0"], ["84351.77", "0.162"], ["84351.91", "0.355893"], ["84352.62", "0"], ["84352.87", "0"], ["84353.24", "0"], ["84353.72", "0"], ["84353.89", "0"], ["84353.97", "0"], ["84354", "0"]], "u": 7510699, "seq": 66889361702}, "cts": 1742142235808, "record_time": 1742142234.908612}
{"topic": "orderbook.200.BTCUSDT", "ts": 1742142236010, "type": "delta", "data": {"s": "BTCUSDT", "b": [["84304.58", "0"], ["84302.9", "0.029472"], ["84302.89", "0.018826"], ["84299.09", "0"], ["84293.14", "0"], ["84292.43", "0.118702"], ["84291.99", "0.0001"], ["84290.97", "0.000449"], ["84290.04", "0"], ["84289.74", "0"], ["84289.47", "0.02"], ["84289.37", "0"], ["84289", "0.02"], ["84288.79", "0.000252"], ["84288.59", "0.237223"], ["84288.44", "0.03056"], ["84288.27", "0"], ["84287.7", "0"], ["84287.14", "0"], ["84287.1", "0.02"], ["84286.92", "0"], ["84286.86", "0.003"], ["84286.84", "0.02"], ["84286.66", "0.003"], ["84285.91", "0"], ["84285.54", "0"], ["84284.38", "0.237223"], ["84282.81", "0"], ["84281.59", "0.237223"], ["84281.54", "0"], ["84278.72", "0"], ["84278.56", "0"], ["84277.38", "0.237223"], ["84274.62", "0.269372"], ["84274.61", "0"], ["84274.6", "0"], ["84273.34", "0"], ["84270.52", "0"], ["84268.95", "0.177917"], ["84267.91", "0"], ["84259.1", "0.177917"], ["84258.74", "0.000233"], ["84255.38", "0.11863"], ["84253.99", "0.0013"], ["84253.55", "0"], ["84249.8", "0.001333"], ["84249.76", "0.000614"], ["84249.67", "0.023726"], ["84249.51", "0.11863"]], "a": [["84310.8", "0.0005"], ["84315.14", "0.00593"], ["84318.28", "0.225387"], ["84318.8", "0.044"], ["84319.56", "0"], ["84320.08", "0"], ["84320.9", "0.068"], ["84321.34", "0"], ["84322.17", "0"], ["84322.29", "0.163933"], ["84322.89", "0"], ["84324.2", "0.056"], ["84325.11", "0.00593"], ["84327.9", "0"], ["84328.27", "0"], ["84330.37", "0"], ["84331.04", "0"], ["84334.15", "0"], ["84336.1", "0"], ["84336.47", "0"], ["84338.57", "0"], ["84339.27", "0.222022"], ["84341.69", "0"], ["84348.8", "0.0013"], ["84350.85", "0.355902"], ["84351.91", "0"], ["84352.62", "0.015"], ["84352.87", "0.027942"], ["84353.22", "0.177917"], ["84353.24", "0.118791"], ["84353.72", "0.000253"]], "u": 7510700, "seq": 66889362097}, "cts": 1742142236007, "record_time": 1742142235.109032}
{"topic": "orderbook.200.BTCUSDT", "ts": 1742142236210, "type": "delta", "data": {"s": "BTCUSDT", "b": [["84302.92", "0.029372"], ["84302.91", "0.018796"], ["84302.89", "0"], ["84299.1", "0"], ["84292.44", "0.000297"], ["84292.43", "0.165147"], ["84290.97", "0.0002"], ["84290.5", "0.040249"], ["84290.25", "0.106563"], ["84290.07", "0.02"], ["84289.95", "0.107837"], ["84289.7", "0.02"], ["84289.47", "0"], ["84289.04", "0.02"], ["84289.03", "0.11324"], ["84289", "0"], ["84288.44", "0.01056"], ["84287.8", "0.02"], ["84287.1", "0"], ["84287.07", "0.117894"], ["84285.8", "0.237223"], ["84282.48", "0.175187"], ["84281.75", "0.179201"], ["84278.87", "0.17878"], ["84278.77", "0.161692"], ["84278.11", "0.110124"], ["84277.38", "0"], ["84274.62", "0"], ["84274.28", "0.272276"], ["84273.55", "0.268413"], ["84270.67", "0.292354"], ["84268.11", "0.282972"], ["84260.34", "0.04"], ["84260.33", "0.039645"], ["84253.97", "0"], ["84253.54", "0"], ["84253.35", "0"], ["84253.09", "0"], ["84253.05", "0"], ["84251.95", "0"], ["84251.88", "0"], ["84251.71", "0"], ["84250.52", "0"], ["84250", "0"], ["84249.92", "0"], ["84249.8", "0"], ["84249.76", "0"], ["84249.67", "0"], ["84249.51", "0"]], "a": [["84318.28", "0.192414"], ["84319.77", "0.111774"], ["84320.28", "0.112445"], ["84321.01", "0.114797"], ["84322.32", "0.109375"], ["84325.8", "0.048"], ["84326.76", "0.358513"], ["84327.57", "0.171336"], ["84328", "0"], ["84328.48", "0.166326"], ["84330.52", "0.166525"], ["84330.71", "0"], ["84331.24", "0.168946"], ["84331.3", "0"], ["84335.77", "0.276647"], ["84336.68", "0.265582"], ["84338.72", "0.293245"], ["84341.9", "0.275861"], ["84345.59", "0.04"], ["84345.6", "0.04"], ["84350.84", "0.355899"], ["84350.85", "0"], ["84351.36", "0"], ["84351.48", "0"], ["84351.68", "0"], ["84351.69", "0"], ["84351.77", "0"], ["84351.92", "0"], ["84352", "0"], ["84352.62", "0"], ["84352.87", "0"], ["84353.22", "0"], ["84353.24", "0"], ["84353.72", "0"]], "u": 7510701, "seq": 66889362294}, "cts": 1742142236204, "record_time": 1742142235.310034}
{"topic": "orderbook.200.BTCUSDT", "ts": 1742142236410, "type": "delta", "data": {"s": "BTCUSDT", "b": [["84308.79", "0.183846"], ["84307.96", "0.004595"], ["84305.18", "0.0194"], ["84302.92", "0"], ["84302.91", "0"], ["84302.9", "0"], ["84302.89", "0.013006"], ["84302.88", "0.029572"], ["84302.07", "0"], ["84299.09", "0.032569"], ["84298.42", "0"], ["84292.9", "0.000297"], ["84292.44", "0"], ["84292.43", "0.291665"], ["84291.91", "0.162"], ["84290.97", "0.000449"], ["84290.5", "0.04"], ["84290.25", "0"], ["84290.17", "0.02"], ["84290.07", "0"], ["84289.95", "0"], ["84289.03", "0"], ["84288.59", "0"], ["84288.21", "0.242952"], ["84287.44", "0.02"], ["84287.07", "0.000233"], ["84286.89", "0.003"], ["84286.86", "0"], ["84286.84", "0"], ["84286.69", "0.003"], ["84286.66", "0"], ["84284.6", "0"], ["84284.4", "0"], ["84284.38", "0"], ["84282.92", "0.118612"], ["84282.53", "0.160761"], ["84282.48", "0"], ["84281.75", "0"], ["84278.87", "0"], ["84278.77", "0"], ["84278.11", "0"], ["84274.28", "0"], ["84273.55", "0"], ["84270.67", "0"], ["84268.11", "0"], ["84262", "0.355859"], ["84260.29", "0"], ["84259.1", "0"], ["84253.97", "0.000614"], ["84253.35", "0.005931"], ["84253.09", "0.001"], ["84253.05", "0.0002"], ["84251.95", "0.00009"], ["84251.88", "0.001467"], ["84251.71", "0.000252"], ["84251", "0.000119"], ["84250.52", "0.0002"], ["84250", "0.000233"], ["84249.92", "0.000357"], ["84249.8", "0.001333"], ["84249.76", "0.000614"], ["84249.67", "0.023726"]], "a": [["84308.8", "0.075449"], ["84309.63", "0.005645"], ["84310.87", "0"], ["84311.86", "0"], ["84313.01", "0"], ["84313.85", "0.000335"], ["84313.86", "0"], ["84315.14", "0"], ["84315.22", "0"], ["84316.44", "0.010668"], ["84318.28", "0.101266"], ["84318.8", "0"], ["84319.1", "0"], ["84319.77", "0"], ["84320.28", "0"], ["84320.3", "0"], ["84320.67", "0"], ["84320.9", "0"], ["84321.01", "0"], ["84322.3", "0"], ["84322.32", "0"], ["84322.4", "0"], ["84324", "0"], ["84324.2", "0"], ["84324.5", "0"], ["84325.11", "0"], ["84325.29", "0"], ["84325.6", "0"], ["84325.8", "0"], ["84326.86", "0"], ["84327.57", "0"], ["84328.48", "0"], ["84329.09", "0.016002"], ["84330.52", "0"], ["84330.69", "0.651262"], ["84330.7", "1.422211"], ["84331.24", "0"], ["84332.15", "0"], ["84332.35", "0"], ["84334.93", "0"], ["84335.77", "0"], ["84336.68", "0"], ["84336.92", "0.024331"], ["84337.49", "0"], ["84338.72", "0"], ["84339.15", "0"], ["84339.27", "0"], ["84340.58", "0.237223"], ["84341.9", "0"], ["84345.59", "0"], ["84345.6", "0"], ["84347.79", "0.04"], ["84347.8", "0.04"], ["84350.84", "0"], ["84351.36", "0.000439"], ["84351.48", "0.000235"], ["84351.68", "0.0002"], ["84351.69", "0.023722"], ["84352", "0.000235"], ["84352.62", "0.015"], ["84353.22", "0.177917"], ["84353.24", "0.118791"], ["84353.72", "0.000253"], ["84353.89", "0.001467"], ["84353.97", "0.00593"], ["84354", "0.352467"], ["84354.21", "0.0002"], ["84354.72", "0.03181"], ["84354.92", "0.00109"], ["84355.14", "0.000612"], ["84355.15", "0.000357"], ["84355.18", "0.001333"], ["84356.01", "0.00009"], ["84356.12", "0.000235"], ["84356.16", "0.023722"], ["84356.64", "0.000235"], ["84356.74", "0.0002"], ["84357.02", "0.000085"], ["84357.1", "0.0045"], ["84358.07", "0.000335"], ["84358.36", "0.000253"], ["84358.53", "0.001467"], ["84359.13", "0.024741"], ["84359.27", "0.0002"], ["84359.29", "0.002853"], ["84359.3", "0.246059"], ["84359.36", "0.000612"], ["84359.4", "0.001333"], ["84359.55", "0.001243"], ["84359.61", "0.059948"]], "u": 7510702, "seq": 66889362736}, "cts": 1742142236407, "record_time": 1742142235.509033}
{"topic": "orderbook.200.BTCUSDT", "ts": 1742142236609, "type": "delta", "data": {"s": "BTCUSDT", "b": [["84308.79", "0.113186"], ["84307.96", "0.011861"], ["84306.75", "0.021412"], ["84306.74", "0.071174"], ["84305.19", "0.014179"], ["84304.58", "0.011861"], ["84302.89", "0"], ["84302.88", "0"], ["84299.09", "0"], ["84299.08", "0.166544"], ["84298.49", "0.237252"], ["84297.1", "0.113812"], ["84297.02", "0.237223"], ["84296.82", "0.153406"], ["84296.81", "0.237257"], ["84296.8", "0.117189"], ["84295.83", "0.107612"], ["84293.67", "0.11491"], ["84293.37", "0.02"], ["84293.03", "0.010697"], ["84292.9", "0.020297"], ["84292.8", "0.237223"], ["84292.43", "0.165147"], ["84292.42", "0.060197"], ["84292.23", "0.02"], ["84291.05", "0.000817"], ["84291", "0.02"], ["84290.97", "0.0002"], ["84290.17", "0"], ["84289.7", "0"], ["84289.26", "0.163875"], ["84289.04", "0"], ["84288.6", "0.164852"], ["84288.44", "0.0002"], ["84288.21", "0.148618"], ["84287.84", "0.02"], ["84287.8", "0"], ["84287.44", "0"], ["84286.07", "0.068395"], ["84285.62", "0.168792"], ["84285.46", "0.173155"], ["84282.53", "0"], ["84281.59", "0"], ["84281.06", "0.295979"], ["84280.39", "0.268609"], ["84280.38", "0.016046"], ["84278.57", "0"], ["84278.42", "0"], ["84277.26", "0.278669"], ["84275.8", "0.0002"], ["84274.95", "0.286584"], ["84274.59", "0"], ["84274.13", "0.071201"], ["84262.85", "0.11"], ["84262.01", "0.11863"], ["84262", "0"], ["84260.35", "0.355865"], ["84260.34", "0"], ["84260.33", "0"], ["84260.24", "0.04"], ["84260.23", "0.039645"], ["84259.1", "0.177917"], ["84256.79", "0.23737"], ["84255.38", "0"], ["84255.37", "0"], ["84254.9", "0"], ["84254.63", "0"], ["84254.1", "0"], ["84254.01", "0"], ["84253.99", "0"], ["84253.97", "0"], ["84253.35", "0"], ["84253.09", "0"], ["84253.05", "0"], ["84251.95", "0"], ["84251.88", "0"], ["84251.71", "0"], ["84251", "0"], ["84250.52", "0"], ["84250", "0"], ["84249.92", "0"], ["84249.8", "0"], ["84249.76", "0"], ["84249.67", "0"]], "a": [["84308.8", "0.023439"], ["84309.63", "0"], ["84314.88", "0"], ["84314.89", "0"], ["84316.44", "0"], ["84317.53", "0.000296"], ["84317.54", "0.11863"], ["84318.28", "0.06983"], ["84319.53", "0.000388"], ["84319.99", "0"], ["84320.88", "0.010726"], ["84322.29", "0.057408"], ["84325.1", "0.044"], ["84325.4", "0.06"], ["84326.64", "0.109421"], ["84327.16", "0.107541"], ["84327.83", "0.109408"], ["84327.92", "0"], ["84328.95", "0.113847"], ["84329.09", "0"], ["84329.3", "0.068"], ["84331.9", "0.048"], ["84332.1", "0.048"], ["84332.6", "0.056"], ["84333.53", "0.01609"], ["84334.4", "0.171621"], ["84335.37", "0.173264"], ["84337.16", "0.172879"], ["84337.83", "0.000789"], ["84338.13", "0.160587"], ["84338.6", "0.003484"], ["84342.6", "0.287126"], ["84343.57", "0.293971"], ["84345.36", "0.285218"], ["84347.79", "0"], ["84347.8", "0"], ["84348.49", "0.04"], ["84348.5", "0.04"], ["84348.8", "0.265942"], ["84351.77", "0.162"], ["84356.16", "0"], ["84356.64", "0"], ["84356.74", "0"], ["84357.02", "0"], ["84357.1", "0"], ["84358.07", "0"], ["84358.36", "0"], ["84358.53", "0"], ["84359.13", "0"], ["84359.27", "0"], ["84359.29", "0"], ["84359.3", "0"], ["84359.36", "0"], ["84359.4", "0"], ["84359.55", "0"], ["84359.61", "0"]], "u": 7510703, "seq": 66889363460}, "cts": 1742142236608, "record_time": 1742142235.708747}
{"topic": "orderbook.200.BTCUSDT", "ts": 1742142236810, "type": "delta", "data": {"s": "BTCUSDT", "b": [["84308.79", "0.113137"], ["84307.95", "0.0192"], ["84306.75", "0"], ["84306.74", "0"], ["84305.19", "0"], ["84305.18", "0"], ["84304.46", "0.02594"], ["84304.45", "0.071176"], ["84299.09", "0.000297"], ["84299.08", "0.037081"], ["84298.49", "0"], ["84297.1", "0"], ["84297.02", "0"], ["84296.82", "0"], ["84296.81", "0"], ["84296.8", "0"], ["84295.83", "0"], ["84295.39", "0.082284"], ["84295.2", "0.02"], ["84294.58", "0.117736"], ["84294.53", "0.02"], ["84293.67", "0"], ["84293.3", "0.02"], ["84293.08", "0"], ["84292.9", "0.000297"], ["84292.8", "0"], ["84292.42", "0.059948"], ["84292.23", "0"], ["84292.01", "0.12019"], ["84291.94", "0.001582"], ["84291", "0"], ["84290.63", "0.02"], ["84290.02", "0.237223"], ["84289.26", "0"], ["84288.6", "0"], ["84287.84", "0"], ["84285.62", "0"], ["84285.46", "0"], ["84283.78", "0.170505"], ["84282.92", "0"], ["84281.06", "0"], ["84280.39", "0"], ["84279.77", "0.288171"], ["84278.16", "0.139957"], ["84277.26", "0"], ["84275.56", "0.263125"], ["84274.95", "0"], ["84273.13", "0.28888"], ["84263.31", "0.237223"], ["84262.85", "0"], ["84260.35", "0"], ["84259.1", "0.237223"], ["84256.8", "0.355872"], ["84255.38", "0.11863"], ["84255.37", "0.323575"], ["84254.93", "0.044372"], ["84254.9", "0.059948"], ["84254.63", "0.000233"], ["84254.1", "0.000233"], ["84254.01", "0.001333"], ["84253.99", "0.0013"], ["84253.97", "0.000614"]], "a": [["84310.8", "0.027911"], ["84315.53", "0.01186"], ["84316.77", "0.000296"], ["84316.78", "0.029591"], ["84317.18", "0.036445"], ["84317.53", "0"], ["84322.29", "0.081432"], ["84326.64", "0"], ["84326.77", "0"], ["84327.16", "0"], ["84327.39", "0.119925"], ["84327.83", "0"], ["84328.8", "0.044"], ["84328.95", "0"], ["84330.6", "0.04"], ["84330.9", "0.06"], ["84332.3", "0.068"], ["84334.4", "0"], ["84335.37", "0"], ["84335.61", "0.177203"], ["84336.44", "0.005"], ["84336.47", "0.17795"], ["84337.16", "0"], ["84338.13", "0"], ["84339.05", "0.118612"], ["84339.15", "0.237223"], ["84339.92", "0.03181"], ["84341.47", "0.27759"], ["84342.6", "0"], ["84343.36", "0.237223"], ["84343.48", "0.22308"], ["84343.57", "0"], ["84343.84", "0.281551"], ["84345.36", "0"], ["84347.17", "0.276303"], ["84348.8", "0.0013"], ["84353.37", "0.038007"], ["84354.72", "0"], ["84354.92", "0"], ["84355.14", "0"], ["84355.15", "0"], ["84355.18", "0"], ["84356.01", "0"], ["84356.12", "0"]], "u": 7510704, "seq": 66889363927}, "cts": 1742142236807, "record_time": 1742142235.90969}
{"topic": "orderbook.200.BTCUSDT", "ts": 1742142237010, "type": "delta", "data": {"s": "BTCUSDT", "b": [["84307.96", "0"], ["84299.09", "0"], ["84295.67", "0.02"], ["84295.39", "0.123378"], ["84294.71", "0.106608"], ["84294.58", "0"], ["84294.41", "0.115851"], ["84293.84", "0.109083"], ["84293.37", "0"], ["84292.93", "0.02"], ["84292.42", "0.060197"], ["84292.01", "0"], ["84291.94", "0.001333"], ["84291.46", "0.105"], ["84290.63", "0"], ["84287.25", "0.16892"], ["84286.18", "0.162297"], ["84283.78", "0"], ["84283.48", "0.104761"], ["84283.24", "0.180802"], ["84283.2", "0.159453"], ["84281.59", "0.237223"], ["84279.77", "0"], ["84279.03", "0.264671"], ["84277.96", "0.289016"], ["84275.57", "0.246067"], ["84275.56", "0"], ["84275.01", "0.295506"], ["84273.13", "0"], ["84272.5", "0.292924"], ["84263.31", "0"], ["84259.1", "0"], ["84256.8", "0"], ["84254.93", "0"], ["84253.99", "0"], ["84253.97", "0"]], "a": [["84308.8", "0.054489"], ["84310.8", "0.026836"], ["84313.01", "0.01186"], ["84324.33", "0.117163"], ["84324.85", "0.10563"], ["84325.92", "0.114326"], ["84326.76", "0.173597"], ["84326.84", "0.117399"], ["84327.39", "0"], ["84330.98", "0.024112"], ["84332.15", "0.237223"], ["84332.5", "0.171473"], ["84333.08", "0.169251"], ["84335.06", "0.168093"], ["84335.61", "0"], ["84335.85", "0.168971"], ["84336.47", "0"], ["84340.58", "0"], ["84340.73", "0.295071"], ["84341.3", "0.27733"], ["84341.47", "0"], ["84343.29", "0.316163"], ["84343.84", "0"], ["84346.54", "0.293315"], ["84347.17", "0"], ["84351.76", "0.355895"], ["84353.22", "0"], ["84353.24", "0"], ["84353.37", "0"], ["84353.72", "0"], ["84353.89", "0"], ["84353.97", "0"], ["84354", "0"], ["84354.21", "0"]], "u": 7510705, "seq": 66889364221}, "cts": 1742142237004, "record_time": 1742142236.109073}
{"topic": "orderbook.200.BTCUSDT", "ts": 1742142237210, "type": "delta", "data": {"s": "BTCUSDT", "b": [["84304.45", "0.074176"], ["84296.47", "0.02"], ["84296.1", "0.02"], ["84295.68", "0.117515"], ["84295.67", "0"], ["84295.43", "0.02"], ["84295.39", "0"], ["84295.2", "0"], ["84295.12", "0.111392"], ["84294.82", "0.109289"], ["84294.71", "0"], ["84294.53", "0"], ["84294.41", "0"], ["84294.35", "0.108818"], ["84294.2", "0.020089"], ["84293.84", "0"], ["84293.83", "0.02"], ["84293.3", "0"], ["84292.93", "0"], ["84292.42", "0.059948"], ["84291.99", "0.000349"], ["84291.83", "0.107302"], ["84291.46", "0"], ["84287.77", "0.160873"], ["84287.25", "0"], ["84286.59", "0.173956"], ["84286.18", "0"], ["84283.6", "0.340194"], ["84283.24", "0"], ["84283.2", "0"], ["84281.59", "0"], ["84279.54", "0.282096"], ["84279.03", "0"], ["84278.36", "0.277482"], ["84277.96", "0"], ["84275.38", "0.296055"], ["84275.01", "0"], ["84272.91", "0.27422"], ["84272.5", "0"], ["84256.8", "0.355876"], ["84253.99", "0.0013"], ["84253.97", "0.000614"]], "a": [["84308.8", "0.023439"], ["84308.84", "0.000153"], ["84310.8", "0.029836"], ["84315.77", "0.01093"], ["84316.78", "0.001467"], ["84319.53", "0.000235"], ["84320.88", "0"], ["84322.29", "0.179565"], ["84324.33", "0"], ["84324.74", "0.108851"], ["84324.85", "0"], ["84325.26", "0.115441"], ["84325.92", "0"], ["84326.44", "0.119428"], ["84326.84", "0"], ["84327.21", "0.112881"], ["84328.42", "0.016395"], ["84332.15", "0"], ["84332.5", "0"], ["84333.02", "0.169925"], ["84333.08", "0"], ["84333.48", "0.167045"], ["84333.53", "0"], ["84335.06", "0"], ["84335.43", "0.162273"], ["84335.85", "0"], ["84336.26", "0.174478"], ["84340.58", "0.237223"], ["84340.73", "0"], ["84341.24", "0.273814"], ["84341.3", "0"], ["84341.71", "0.271703"], ["84343.29", "0.023722"], ["84343.66", "0.297582"], ["84346.54", "0"], ["84346.95", "0.28746"], ["84351.76", "0"], ["84352.62", "0"]], "u": 7510706, "seq": 66889364526}, "cts": 1742142237204, "record_time": 1742142236.309671}
{"topic": "orderbook.200.BTCUSDT", "ts": 1742142237410, "type": "delta", "data": {"s": "BTCUSDT", "b": [["84307.95", "0"], ["84304.59", "0.013837"], ["84304.58", "0.010919"], ["84304.46", "0"], ["84304.45", "0"], ["84303.63", "0.0193"], ["84299.09", "0.000297"], ["84296.76", "0.09896"], ["84296.47", "0"], ["84296.1", "0"], ["84295.77", "0.02"], ["84295.68", "0"], ["84295.43", "0"], ["84295.3", "0.02"], ["84295.12", "0"], ["84294.82", "0"], ["84294.63", "0.02"], ["84294.35", "0"], ["84294.2", "0.000089"], ["84293.83", "0"], ["84293.67", "0.120974"], ["84293.4", "0.02"], ["84293.03", "0.02"], ["84292.8", "0.237223"], ["84291.99", "0.0001"], ["84291.91", "0"], ["84291.9", "0.000863"], ["84291.83", "0"], ["84290.02", "0"], ["84288.59", "0.237223"], ["84288", "0.010969"], ["84287.77", "0"], ["84286.59", "0"], ["84285.45", "0.164768"], ["84284.62", "0.118612"], ["84283.6", "0"], ["84281.59", "0.237223"], ["84280.38", "0"], ["84280.23", "0.237223"], ["84279.54", "0"], ["84278.36", "0"], ["84277.22", "0.291093"], ["84275.38", "0"], ["84275.36", "0.016454"], ["84274.13", "0"], ["84272.91", "0"], ["84263.52", "0.07121"], ["84260.24", "0"], ["84260.23", "0"], ["84260.04", "0.04"], ["84260.03", "0.039645"], ["84258.41", "0.00344"], ["84256.8", "0"], ["84256.79", "0"], ["84253.35", "0.005931"], ["84253.09", "0.001"], ["84253.05", "0.0002"], ["84251.95", "0.00009"], ["84251.88", "0.001467"]], "a": [["84308.8", "0.031289"], ["84309.63", "0.00245"], ["84310.8", "0.028324"], ["84314.9", "0.028359"], ["84323.59", "0.114518"], ["84324.11", "0.119623"], ["84324.74", "0"], ["84325.1", "0.157517"], ["84325.26", "0"], ["84326.44", "0"], ["84327.21", "0"], ["84331.89", "0.059948"], ["84332.11", "0.024503"], ["84332.34", "0.167683"], ["84333.02", "0"], ["84333.48", "0"], ["84335.43", "0"], ["84336.25", "0.288803"], ["84336.26", "0"], ["84336.44", "0"], ["84336.92", "0"], ["84339.05", "0"], ["84340.57", "0.270911"], ["84341.24", "0"], ["84341.71", "0"], ["84343.66", "0"], ["84346.95", "0"], ["84352.62", "0.015"], ["84353.22", "0.177917"], ["84353.24", "0.118791"], ["84353.37", "0.038007"], ["84353.72", "0.000253"], ["84353.89", "0.001467"], ["84353.97", "0.00593"]], "u": 7510707, "seq": 66889365103}, "cts": 1742142237407, "record_time": 1742142236.508696}
{"topic": "orderbook.200.BTCUSDT", "ts": 1742142237610, "type": "delta", "data": {"s": "BTCUSDT", "b": [["84307.96", "0.011861"], ["84306.46", "0.071174"], ["84304.59", "0"], ["84303.63", "0"], ["84302.88", "0.02947"], ["84299.1", "0.030416"], ["84296.76", "0.195523"], ["84296.07", "0.02"], ["84295.77", "0"], ["84295.6", "0.02"], ["84295.3", "0"], ["84294.93", "0.02"], ["84294.63", "0"], ["84294.31", "0.117979"], ["84294.01", "0.105714"], ["84293.7", "0.02"], ["84293.67", "0"], ["84293.42", "0.116093"], ["84293.4", "0"], ["84293.33", "0.02"], ["84293.16", "0.011048"], ["84293.03", "0"], ["84292.9", "0"], ["84291.94", "0.001582"], ["84291.91", "0.162"], ["84291.9", "0.000614"], ["84291.08", "0.111613"], ["84288", "0"], ["84286.84", "0.169295"], ["84285.78", "0.1642"], ["84285.47", "0.118612"], ["84285.45", "0"], ["84282.86", "0.178096"], ["84282.8", "0.219028"], ["84281.59", "0"], ["84280.51", "0.016573"], ["84278.61", "0.275197"], ["84277.56", "0.268588"], ["84277.22", "0"], ["84275.57", "0"], ["84275.36", "0"], ["84274.63", "0.276822"], ["84273.77", "0.071202"], ["84272.1", "0.263847"], ["84263.52", "0"], ["84259.1", "0.177917"], ["84258.7", "0.355872"], ["84258.41", "0"], ["84254.1", "0"], ["84254.01", "0"], ["84253.99", "0"], ["84253.97", "0"], ["84253.35", "0"], ["84253.09", "0"], ["84253.05", "0"], ["84251.95", "0"], ["84251.88", "0"]], "a": [["84308.8", "0.023439"], ["84308.84", "0"], ["84309.63", "0"], ["84310.8", "0.0005"], ["84313.01", "0"], ["84313.22", "0.071168"], ["84314.9", "0.000235"], ["84317.69", "0.000153"], ["84323.59", "0"], ["84323.93", "0.11894"], ["84324.11", "0"], ["84324.45", "0.116897"], ["84325.1", "0.044"], ["84325.51", "0.118736"], ["84326.46", "0.115317"], ["84330.98", "0"], ["84331.89", "0"], ["84332.09", "0.171602"], ["84332.11", "0"], ["84332.34", "0"], ["84332.68", "0.163967"], ["84334.69", "0.162072"], ["84335.18", "0.005"], ["84335.45", "0.176542"], ["84336.35", "0.118612"], ["84340.31", "0.286178"], ["84340.57", "0"], ["84340.9", "0.285377"], ["84342.91", "0.288758"], ["84346.14", "0.28644"], ["84346.27", "0.071141"], ["84348.49", "0"], ["84348.5", "0"], ["84348.79", "0.04"], ["84348.8", "0.0413"], ["84353.22", "0"], ["84353.24", "0"], ["84353.37", "0"], ["84353.72", "0"], ["84353.89", "0"], ["84353.97", "0"]], "u": 7510708, "seq": 66889365551}, "cts": 1742142237607, "record_time": 1742142236.709243}
{"topic": "orderbook.200.BTCUSDT", "ts": 1742142237809, "type": "delta", "data": {"s": "BTCUSDT", "b": [["84310.87", "0.181449"], ["84308.79", "0"], ["84306.46", "0"], ["84305.62", "0.000233"], ["84305.1", "0.000233"], ["84304.59", "0.001333"], ["84302.88", "0"], ["84302.06", "0"], ["84301.82", "0.0005"], ["84300.36", "0"], ["84300.22", "0.143389"], ["84299.11", "0.000297"], ["84299.1", "0"], ["84299.08", "0"], ["84297.69", "0.1186"], ["84297.39", "0.120756"], ["84296.76", "0.182654"], ["84296.64", "0.10714"], ["84296.03", "0.060505"], ["84295.6", "0"], ["84295.4", "0.02"], ["84294.93", "0"], ["84294.9", "0.04"], ["84294.83", "0.02"], ["84294.51", "0.10548"], ["84294.45", "0.015076"], ["84294.31", "0"], ["84294.01", "0"], ["84293.7", "0"], ["84293.5", "0.020449"], ["84293.43", "0.020252"], ["84293.42", "0.00096"], ["84293.33", "0"], ["84293.16", "0"], ["84292.8", "0"], ["84292.4", "0.008453"], ["84291.94", "0.001333"], ["84291.9", "0.011786"], ["84291.67", "0"], ["84291.6", "0.04"], ["84291.08", "0"], ["84290.12", "0.118609"], ["84290.02", "0.237223"], ["84289.16", "0.17421"], ["84288.95", "0"], ["84288.59", "0"], ["84286.84", "0"], ["84286.28", "0.165034"], ["84286.17", "0.173006"], ["84285.8", "0"], ["84285.78", "0"], ["84285.47", "0"], ["84284.62", "0"], ["84282.86", "0"], ["84282.8", "0.04"], ["84280.93", "0.269204"], ["84280.51", "0"], ["84280.23", "0.237217"], ["84279.26", "0.016759"], ["84278.61", "0"], ["84277.56", "0"], ["84276.02", "0.237217"], ["84275.66", "0.023722"], ["84275.22", "0"], ["84274.63", "0"], ["84273.77", "0"], ["84272.5", "0.023722"], ["84272.1", "0"], ["84271.96", "0.323512"], ["84271.65", "1.478689"], ["84270.21", "0.00593"], ["84270.05", "0.071205"], ["84267.74", "0.11"], ["84267.14", "0"], ["84266.53", "0.023722"], ["84265.72", "0.023722"], ["84265.55", "0"], ["84265.1", "0.160473"], ["84264.84", "0.11"], ["84260.62", "0.000988"], ["84259.1", "0"], ["84258.7", "0"], ["84258.55", "0"], ["84258.1", "0.24702"], ["84255.61", "0.355879"], ["84255.6", "0"], ["84255.37", "0"]], "a": [["84308.8", "0"], ["84309.73", "0"], ["84310.26", "0"], ["84310.8", "0"], ["84310.88", "0.022091"], ["84311.14", "0.000153"], ["84312.92", "0.071169"], ["84313.22", "0"], ["84314.9", "0.028759"], ["84315.53", "0"], ["84315.77", "0"], ["84316.77", "0.048316"], ["84316.78", "0.032729"], ["84316.8", "0"], ["84316.99", "0.002638"], ["84317.18", "0"], ["84317.23", "0.001333"], ["84317.37", "0.11863"], ["84317.54", "0"], ["84317.69", "0"], ["84318.28", "0"], ["84318.29", "0"], ["84319.31", "0.0005"], ["84320.24", "0.046698"], ["84321.3", "0.011112"], ["84322.29", "0"], ["84322.77", "0"], ["84322.89", "0.062084"], ["84323.93", "0"], ["84324.45", "0"], ["84325.1", "0"], ["84325.27", "0.083981"], ["84325.4", "0"], ["84325.51", "0"], ["84326.46", "0"], ["84327.31", "0.114437"], ["84327.83", "0.105843"], ["84328.42", "0"], ["84328.72", "0.10997"], ["84329.88", "0.115303"], ["84330.7", "0"], ["84331.34", "0.068395"], ["84331.89", "0.059948"], ["84331.9", "0"], ["84332.09", "0"], ["84332.1", "0"], ["84332.4", "0"], ["84332.68", "0"], ["84332.83", "0"], ["84332.88", "0"], ["84332.95", "0.024195"], ["84333.95", "0.016669"], ["84334.48", "0.000988"], ["84334.69", "0"], ["84335.1", "0"], ["84335.45", "0"], ["84335.81", "0.005901"], ["84336.05", "0.171958"], ["84336.35", "0"], ["84338.11", "0.165187"], ["84338.87", "0.008453"], ["84339.15", "0"], ["84339.2", "0.03181"], ["84339.43", "0.005"], ["84339.92", "0"], ["84340.18", "0"], ["84340.31", "0"], ["84340.45", "0.118609"], ["84340.52", "0.024709"], ["84340.9", "0"], ["84342.34", "1.417527"], ["84342.91", "0"], ["84343.1", "0.071143"], ["84343.36", "0"], ["84343.48", "0.237217"], ["84344.28", "0.291633"], ["84346.14", "0"], ["84346.27", "0"], ["84346.67", "0"], ["84347.68", "0.011861"], ["84348.79", "0"], ["84348.8", "0.0013"], ["84349.65", "0"], ["84349.82", "0"], ["84349.88", "0.071137"], ["84352.6", "0.04"], ["84352.61", "0.04"], ["84353.22", "0.177917"], ["84353.24", "0.118791"], ["84353.72", "0.000253"], ["84353.89", "0.001467"], ["84353.97", "0.00593"], ["84354", "0.352467"], ["84354.21", "0.0002"], ["84354.92", "0.00109"], ["84355.14", "0.000612"], ["84355.15", "0.000357"], ["84355.18", "0.001333"], ["84356.01", "0.00009"], ["84356.12", "0.000235"], ["84356.16", "0.023722"], ["84356.64", "0.000235"]], "u": 7510709, "seq": 66889366912}, "cts": 1742142237807, "record_time": 1742142236.908919}
{"topic": "orderbook.200.BTCUSDT", "ts": 1742142238009, "type": "delta", "data": {"s": "BTCUSDT", "b": [["84310.87", "0.013978"], ["84310.14", "0.000189"], ["84307.96", "0"], ["84305.17", "0"], ["84304.58", "0"], ["84300.39", "0.000297"], ["84300.38", "0.029818"], ["84300.22", "0.037259"], ["84299.11", "0"], ["84298.74", "0.015075"], ["84297.69", "0"], ["84297.39", "0"], ["84296.77", "0.02"], ["84296.76", "0.058166"], ["84296.64", "0"], ["84296.07", "0"], ["84295.8", "0.02"], ["84295.4", "0"], ["84295.13", "0.02"], ["84294.9", "0"], ["84294.83", "0"], ["84294.51", "0"], ["84294.45", "0"], ["84293.9", "0.02"], ["84293.7", "0.048"], ["84293.5", "0.0002"], ["84293.43", "0.000252"], ["84293.42", "0"], ["84292.73", "0.02"], ["84292.43", "0.238649"], ["84292.4", "0"], ["84291.94", "0.001582"], ["84291.91", "0"], ["84291.9", "0.000614"], ["84291.6", "0"], ["84290.23", "0.112504"], ["84290.12", "0"], ["84290.02", "0"], ["84289.33", "0.105343"], ["84289.16", "0"], ["84288.91", "0.003"], ["84286.8", "0.008453"], ["84286.5", "0"], ["84286.28", "0"], ["84286.17", "0"], ["84286.02", "0.011237"], ["84285.1", "0"], ["84284.5", "0"], ["84282.8", "0"], ["84282.72", "0.168182"], ["84280.93", "0"], ["84280.23", "0"], ["84279.26", "0"], ["84279.04", "0.164797"], ["84277.64", "0.003346"], ["84276.02", "0"], ["84273.38", "0.016856"], ["84270.05", "0"], ["84267.95", "0.289727"], ["84267.74", "0"], ["84264.84", "0"], ["84263.63", "0.07121"], ["84262.01", "0"], ["84258.9", "0.071214"], ["84255.61", "0"], ["84254.1", "0.000233"], ["84254.01", "0.001333"], ["84253.99", "0.0013"], ["84253.97", "0.000614"], ["84253.35", "0.005931"], ["84253.09", "0.001"], ["84253.05", "0.0002"], ["84251.95", "0.00009"], ["84251.88", "0.001467"], ["84251.71", "0.000252"], ["84251", "0.000119"], ["84250.52", "0.0002"], ["84250", "0.000233"]], "a": [["84310.88", "0.24219"], ["84310.94", "0.028027"], ["84311.14", "0"], ["84311.71", "0.01186"], ["84314.9", "0.000235"], ["84315.09", "0.01186"], ["84316.77", "0.071536"], ["84316.78", "0.001467"], ["84316.83", "0.023721"], ["84316.99", "0.011859"], ["84317.21", "0.089922"], ["84317.45", "0.00593"], ["84320.24", "0.101538"], ["84321.3", "0"], ["84323.67", "0.068395"], ["84323.76", "0.020996"], ["84323.96", "0.01686"], ["84325.3", "0.044"], ["84325.7", "0.06"], ["84326.41", "0"], ["84326.76", "0.249185"], ["84326.81", "0.089922"], ["84327.31", "0"], ["84327.43", "0.00593"], ["84327.76", "0.162"], ["84327.83", "0"], ["84328.72", "0"], ["84329.88", "0.001333"], ["84330.69", "0.001467"], ["84331.34", "0"], ["84331.45", "0.232444"], ["84332.2", "0.048"], ["84332.4", "0.048"], ["84333.95", "0"], ["84336.05", "0"], ["84336.37", "0.308372"], ["84338.11", "0"], ["84339.15", "0.237217"], ["84339.43", "0"], ["84340.45", "0"], ["84340.52", "0"], ["84342.23", "0.267517"], ["84343.36", "0.237217"], ["84344.28", "0"], ["84349.87", "0.355899"], ["84349.88", "0"], ["84355.15", "0"], ["84355.18", "0"], ["84356.01", "0"], ["84356.12", "0"], ["84356.16", "0"], ["84356.64", "0"]], "u": 7510710, "seq": 66889367908}, "cts": 1742142238006, "record_time": 1742142237.108548}
{"topic": "orderbook.200.BTCUSDT", "ts": 1742142238218, "type": "delta", "data": {"s": "BTCUSDT", "b": [["84310.87", "0.014154"], ["84310.14", "0"], ["84307.18", "0.000099"], ["84301.83", "0.0192"], ["84300.22", "0.053867"], ["84298.74", "0"], ["84297.88", "0.071181"], ["84296.77", "0"], ["84295.97", "0.02"], ["84295.8", "0"], ["84295.52", "0.02"], ["84295.41", "0.015076"], ["84295.13", "0"], ["84294.73", "0.02"], ["84293.9", "0"], ["84293.7", "0"], ["84293.6", "0.02"], ["84293.33", "0.02"], ["84292.73", "0"], ["84292.43", "0.073502"], ["84290.46", "0.118837"], ["84290.23", "0"], ["84290.15", "0.114607"], ["84289.56", "0.107521"], ["84289.33", "0"], ["84288.7", "0.041243"], ["84288.21", "0.053476"], ["84287.24", "0.118034"], ["84287.2", "0.048"], ["84286.7", "0.04"], ["84285.1", "0.04"], ["84284.38", "0.237217"], ["84282.95", "0.177075"], ["84282.72", "0"], ["84281.9", "0.166319"], ["84281.72", "0.118609"], ["84281.59", "0.237217"], ["84280.16", "0.237217"], ["84279.04", "0"], ["84278.98", "0.168445"], ["84278.9", "0.16796"], ["84277.38", "0.237217"], ["84276.02", "0.237217"], ["84275.66", "0"], ["84274.7", "0.268565"], ["84273.65", "0.29314"], ["84270.73", "0.293954"], ["84268.17", "0.265278"], ["84267.95", "0"], ["84259.1", "0.177913"], ["84255.58", "0"], ["84255.38", "0"], ["84254.9", "0"], ["84254.63", "0"], ["84254.1", "0"], ["84254.01", "0"], ["84253.99", "0"], ["84253.97", "0"], ["84253.35", "0"], ["84253.09", "0"], ["84253.05", "0"], ["84251.95", "0"], ["84251.88", "0"], ["84251.71", "0"], ["84251", "0"], ["84250.52", "0"], ["84250", "0"]], "a": [["84310.88", "0.060744"], ["84310.89", "0.040381"], ["84310.92", "0.092252"], ["84310.93", "0.11863"], ["84310.94", "0"], ["84311.08", "0.089922"], ["84320.17", "0.260749"], ["84320.24", "0"], ["84320.42", "0.020997"], ["84320.69", "0.116836"], ["84321.74", "0.106093"], ["84322.72", "0.118778"], ["84322.89", "0.117399"], ["84323.76", "0"], ["84326.41", "0.001348"], ["84327.09", "0.059304"], ["84328.34", "0.157825"], ["84328.94", "0.16017"], ["84329.36", "0.000789"], ["84330.98", "0.166099"], ["84331.72", "0.179044"], ["84332.04", "0.118609"], ["84332.15", "0.237217"], ["84334.93", "0.237217"], ["84336.6", "0.283196"], ["84336.73", "0.059304"], ["84337.19", "0.301589"], ["84337.63", "0.023722"], ["84337.83", "0"], ["84339.23", "0.298984"], ["84339.27", "0.237217"], ["84340.58", "0"], ["84342.23", "0"], ["84342.45", "0.301167"], ["84343.36", "0"], ["84346.35", "0.027942"], ["84349.86", "0.355905"], ["84349.87", "0"], ["84350.96", "0"], ["84351.36", "0"], ["84351.48", "0"], ["84351.68", "0"], ["84351.69", "0"], ["84351.77", "0"], ["84352", "0"], ["84352.6", "0"], ["84352.61", "0"], ["84352.62", "0"], ["84353.22", "0"], ["84353.24", "0"], ["84353.72", "0"], ["84353.89", "0"], ["84353.97", "0"], ["84354", "0"], ["84354.21", "0"], ["84354.92", "0"], ["84355.14", "0"]], "u": 7510711, "seq": 66889368629}, "cts": 1742142238204, "record_time": 1742142237.31773}
{"topic": "orderbook.200.BTCUSDT", "ts": 1742142238409, "type": "delta", "data": {"s": "BTCUSDT", "b": [["84310.5", "0.001243"], ["84305.14", "0.016179"], ["84305.13", "0.028624"], ["84299.98", "0.07118"], ["84297.88", "0"], ["84296.87", "0.02"], ["84296.2", "0.02"], ["84295.97", "0"], ["84295.52", "0"], ["84295.23", "0.02"], ["84294.73", "0"], ["84294.5", "0.02"], ["84293.6", "0"], ["84293.33", "0"], ["84293.13", "0.02"], ["84292.43", "0.140117"], ["84291.94", "0.001333"], ["84290.46", "0"], ["84290.15", "0"], ["84289.56", "0"], ["84288.38", "0"], ["84287.24", "0"], ["84287.14", "0.003"], ["84286.94", "0.003"], ["84286.89", "0"], ["84286.69", "0"], ["84285.8", "0.237217"], ["84282.95", "0"], ["84281.9", "0"], ["84278.98", "0"], ["84278.9", "0"], ["84277.38", "0"], ["84274.7", "0"], ["84273.65", "0"], ["84271.97", "0.54066"], ["84270.73", "0"], ["84269.93", "0.071205"], ["84268.17", "0"], ["84258.9", "0"], ["84255.58", "0.0002"], ["84255.38", "0.11863"], ["84254.9", "0.059948"], ["84254.63", "0.000233"], ["84254.1", "0.000233"], ["84254.01", "0.001333"], ["84253.99", "0.0013"], ["84253.97", "0.000614"], ["84253.35", "0.005931"]], "a": [["84310.88", "0.060897"], ["84320.16", "0.141165"], ["84320.17", "0"], ["84320.69", "0"], ["84321.74", "0"], ["84322.72", "0"], ["84328.34", "0"], ["84328.94", "0"], ["84330.98", "0"], ["84331.44", "0.182556"], ["84331.72", "0"], ["84332.34", "0.023218"], ["84336.6", "0"], ["84337.19", "0"], ["84339.23", "0"], ["84342.45", "0"], ["84349.86", "0"], ["84350.96", "0.001333"], ["84351.36", "0.000439"], ["84351.48", "0.000235"], ["84351.68", "0.0002"], ["84351.69", "0.023722"], ["84352", "0.000235"], ["84352.6", "0.04"], ["84352.61", "0.04"], ["84352.62", "0.015"], ["84353.22", "0.177917"], ["84353.24", "0.118791"]], "u": 7510712, "seq": 66889368962}, "cts": 1742142238408, "record_time": 1742142237.508849}
{"topic": "orderbook.200.BTCUSDT", "ts": 1742142238609, "type": "delta", "data": {"s": "BTCUSDT", "b": [["84310.87", "0.017673"], ["84305.14", "0"], ["84302.44", "0.0005"], ["84301.82", "0"], ["84299.98", "0"], ["84296.87", "0"], ["84296.76", "0.051"], ["84296.27", "0.02"], ["84296.2", "0"], ["84295.8", "0.02"], ["84295.71", "0.071183"], ["84294.5", "0"], ["84293.9", "0.02"], ["84293.63", "0.02"], ["84293.13", "0"], ["84292.43", "0.046692"], ["84292.42", "0.060197"], ["84291.16", "0.1122"], ["84290.85", "0.117126"], ["84287.84", "0.118297"], ["84285.8", "0"], ["84282.63", "0.178979"], ["84274.41", "0.267915"], ["84269.93", "0"], ["84259.15", "0.071214"], ["84253.99", "0"], ["84253.97", "0"], ["84253.35", "0"]], "a": [["84320.16", "0.108723"], ["84320.75", "0.120406"], ["84321.27", "0.113177"], ["84322.38", "0.119102"], ["84323.19", "0.111787"], ["84328.95", "0.175132"], ["84329.49", "0.172185"], ["84337.72", "0.299949"], ["84350.18", "0.355901"], ["84351.68", "0"], ["84351.69", "0"], ["84352", "0"], ["84352.6", "0"], ["84352.61", "0"], ["84352.62", "0"], ["84353.22", "0"], ["84353.24", "0"]], "u": 7510713, "seq": 66889369287}, "cts": 1742142238606, "record_time": 1742142237.708194}
{"topic": "orderbook.200.BTCUSDT", "ts": 1742142238810, "type": "delta", "data": {"s": "BTCUSDT", "b": [["84300.22", "0.037259"], ["84296.67", "0.02"], ["84296.27", "0"], ["84296.2", "0.02"], ["84295.8", "0"], ["84295.63", "0.02"], ["84295.23", "0"], ["84294.3", "0.02"], ["84294.03", "0.02"], ["84293.9", "0"], ["84293.63", "0"], ["84292.43", "0.109728"], ["84291.16", "0"], ["84290.85", "0"], ["84290.74", "0.110749"], ["84290.44", "0.108251"], ["84290.07", "0.117715"], ["84287.84", "0"], ["84287.45", "0.120485"], ["84283.5", "0.175717"], ["84282.63", "0"], ["84282.22", "0.171056"], ["84279.23", "0.333697"], ["84277.38", "0.237217"], ["84275.27", "0.268513"], ["84274.41", "0"], ["84274", "0.269856"], ["84271.01", "0.298671"], ["84268.54", "0.280722"], ["84255.64", "0"], ["84255.58", "0"], ["84255.38", "0"], ["84254.9", "0"], ["84254.63", "0"], ["84254.1", "0"], ["84254.01", "0"]], "a": [["84320.16", "0.049664"], ["84320.34", "0.11662"], ["84320.75", "0"], ["84320.86", "0.119073"], ["84321.27", "0"], ["84322.14", "0.113542"], ["84322.38", "0"], ["84322.8", "0.107549"], ["84323.19", "0"], ["84328.71", "0.178567"], ["84328.95", "0"], ["84329.08", "0.179855"], ["84329.49", "0"], ["84331.02", "0.178766"], ["84331.85", "0.168079"], ["84336.94", "0.289412"], ["84337.3", "0.26659"], ["84337.72", "0"], ["84339.24", "0.283116"], ["84342.54", "0.288562"], ["84350.17", "0.355906"], ["84350.18", "0"], ["84350.86", "0"], ["84350.92", "0"], ["84350.96", "0"], ["84351.36", "0"], ["84351.48", "0"]], "u": 7510714, "seq": 66889369511}, "cts": 1742142238806, "record_time": 1742142237.908699}
{"topic": "orderbook.200.BTCUSDT", "ts": 1742142239010, "type": "delta", "data": {"s": "BTCUSDT", "b": [["84310.87", "0.016813"], ["84300.22", "0.053867"], ["84297.79", "0.071181"], ["84296.76", "0.039"], ["84296.67", "0"], ["84296.2", "0"], ["84295.71", "0"], ["84295.63", "0"], ["84293.73", "0.02"], ["84292.42", "0.059948"], ["84292.4", "0.02"], ["84292.27", "0.020249"], ["84290.74", "0"], ["84290.44", "0"], ["84290.07", "0"], ["84288.21", "0.192502"], ["84287.45", "0"], ["84283.5", "0"], ["84282.22", "0"], ["84279.23", "0"], ["84278.16", "0"], ["84275.27", "0"], ["84274", "0"], ["84271.01", "0"], ["84268.54", "0"], ["84262.45", "0.04"], ["84262.44", "0.040978"], ["84260.04", "0"], ["84260.03", "0"], ["84255.64", "0.023726"], ["84255.58", "0.0002"], ["84255.38", "0.11863"], ["84254.9", "0.059948"], ["84254.63", "0.000233"], ["84254.1", "0.000233"], ["84254.01", "0.001333"], ["84253.99", "0.0013"], ["84253.97", "0.000614"], ["84253.35", "0.005931"], ["84253.09", "0.001"], ["84253.05", "0.0002"], ["84251.95", "0.00009"]], "a": [["84310.88", "0.140367"], ["84310.89", "0.011857"], ["84312.92", "0"], ["84320.16", "0.11263"], ["84320.34", "0"], ["84320.86", "0"], ["84322.14", "0"], ["84322.8", "0"], ["84328.71", "0"], ["84329.08", "0"], ["84331.02", "0"], ["84331.85", "0"], ["84336.94", "0"], ["84337.3", "0"], ["84338.87", "0"], ["84339.24", "0"], ["84342.54", "0"], ["84343.36", "0.237217"], ["84348.89", "0.04"], ["84348.9", "0.04"], ["84350.17", "0"], ["84350.86", "0.428903"], ["84350.92", "0.000612"], ["84350.96", "0.001333"], ["84351.36", "0.000439"], ["84351.48", "0.000235"], ["84351.68", "0.0002"], ["84351.69", "0.023722"], ["84352", "0.000235"], ["84352.62", "0.015"], ["84353.22", "0.177917"], ["84353.24", "0.118791"], ["84353.72", "0.000253"]], "u": 7510715, "seq": 66889369838}, "cts": 1742142239006, "record_time": 1742142238.10904}
{"topic": "orderbook.200.BTCUSDT", "ts": 1742142239209, "type": "delta", "data": {"s": "BTCUSDT", "b": [["84305.15", "0.028524"], ["84305.14", "0.003"], ["84294.77", "0.02"], ["84294.03", "0"], ["84292.43", "0.046692"], ["84292.42", "0.060197"], ["84292.27", "0"], ["84292.13", "0.02"], ["84285.8", "0.237217"], ["84277.38", "0"], ["84277.06", "0.139926"], ["84276.02", "0"], ["84262.45", "0"], ["84262.44", "0.001333"], ["84262.35", "0.04"], ["84262.34", "0.039645"], ["84253.54", "0.162"], ["84253.35", "0"], ["84253.09", "0"], ["84253.05", "0"], ["84251.95", "0"]], "a": [["84310.88", "0.131914"], ["84310.92", "0.095252"], ["84311.08", "0"], ["84319.55", "0.008453"], ["84320.16", "0.112208"], ["84348.89", "0"], ["84348.9", "0"], ["84348.99", "0.04"], ["84349", "0.04"], ["84350.18", "0.3559"], ["84351.77", "0.162"], ["84353.24", "0"], ["84353.72", "0"]], "u": 7510716, "seq": 66889370097}, "cts": 1742142239205, "record_time": 1742142238.309041}
{"topic": "orderbook.200.BTCUSDT", "ts": 1742142239410, "type": "delta", "data": {"s": "BTCUSDT", "b": [["84305.19", "0.028325"], ["84305.18", "0.01702"], ["84305.17", "0.028425"], ["84305.15", "0"], ["84305.13", "0"], ["84300.38", "0"], ["84293.73", "0"], ["84293.63", "0.02"], ["84291.3", "0.106719"], ["84291", "0.110954"], ["84290.59", "0.110231"], ["84288.59", "0.237217"], ["84288.53", "0.114889"], ["84283.99", "0.176955"], ["84282.74", "0.177783"], ["84280.28", "0.166493"], ["84280.16", "0"], ["84279.75", "0.180201"], ["84275.73", "0.298108"], ["84274.49", "0.278422"], ["84272.02", "0.292988"], ["84271.8", "0.044791"], ["84269.73", "0.071205"], ["84269.02", "0.30125"], ["84259.15", "0"], ["84256.51", "0"], ["84256.35", "0"], ["84256", "0"], ["84255.64", "0"], ["84255.58", "0"], ["84255.38", "0"], ["84254.9", "0"], ["84254.63", "0"], ["84254.1", "0"], ["84254.01", "0"], ["84253.99", "0"], ["84253.97", "0"], ["84253.54", "0"]], "a": [["84310.92", "0.043925"], ["84320.16", "0.109491"], ["84321.01", "0.109038"], ["84321.53", "0.111081"], ["84322.78", "0.109167"], ["84324.02", "0.117294"], ["84329.38", "0.16852"], ["84329.79", "0.174282"], ["84332.27", "0.175638"], ["84332.57", "0.177505"], ["84337.63", "0.294559"], ["84338.04", "0.270684"], ["84340.52", "0.270875"], ["84343.29", "0.305213"], ["84350.18", "0"], ["84350.85", "0.355898"], ["84350.92", "0"], ["84350.96", "0"], ["84351.36", "0"], ["84351.48", "0"], ["84351.68", "0"], ["84351.69", "0"], ["84351.77", "0"], ["84352", "0"], ["84352.62", "0"], ["84353.22", "0"]], "u": 7510717, "seq": 66889370400}, "cts": 1742142239408, "record_time": 1742142238.509701}
{"topic": "orderbook.200.BTCUSDT", "ts": 1742142239609, "type": "delta", "data": {"s": "BTCUSDT", "b": [["84305.2", "0.01699"], ["84305.18", "0"], ["84305.17", "0"], ["84295.97", "0.02"], ["84295.5", "0.02"], ["84294.93", "0.02"], ["84294.77", "0"], ["84294.3", "0"], ["84293.63", "0"], ["84293.5", "0.0202"], ["84292.43", "0.256933"], ["84292.42", "0.059948"], ["84292.4", "0"], ["84292.3", "0.000249"], ["84292.13", "0"], ["84292.03", "0.02"], ["84291.3", "0"], ["84291", "0"], ["84290.99", "0.105609"], ["84290.69", "0.116824"], ["84290.59", "0"], ["84290.2", "0.11176"], ["84288.53", "0"], ["84288.24", "0.112391"], ["84283.99", "0"], ["84283.6", "0.178573"], ["84282.74", "0"], ["84282.44", "0.163554"], ["84280.28", "0"], ["84279.75", "0"], ["84279.44", "0.179192"], ["84275.73", "0"], ["84275.35", "0.265019"], ["84274.49", "0"], ["84274.18", "0.285302"], ["84272.02", "0"], ["84271.73", "0.268606"], ["84269.02", "0"], ["84268.71", "0.299729"], ["84256.51", "0.001467"], ["84256.35", "0.000252"], ["84256", "0.001243"]], "a": [["84320.16", "0.111861"], ["84320.7", "0.116915"], ["84321.01", "0"], ["84321.22", "0.111104"], ["84321.53", "0"], ["84322.39", "0.120209"], ["84322.78", "0"], ["84323.73", "0.112792"], ["84324.02", "0"], ["84328.99", "0.164656"], ["84329.38", "0"], ["84329.48", "0.164903"], ["84329.79", "0"], ["84331.44", "0.379418"], ["84331.98", "0.166506"], ["84332.26", "0.161238"], ["84332.27", "0"], ["84332.57", "0"], ["84337.25", "0.29361"], ["84337.63", "0.023722"], ["84337.73", "0.298345"], ["84338.04", "0"], ["84340.23", "0.297061"], ["84340.52", "0"], ["84342.99", "0.264114"], ["84343.29", "0.023722"], ["84350.85", "0"], ["84350.86", "0"]], "u": 7510718, "seq": 66889370565}, "cts": 1742142239605, "record_time": 1742142238.708043}
{"topic": "orderbook.200.BTCUSDT", "ts": 1742142239809, "type": "delta", "data": {"s": "BTCUSDT", "b": [["84310.87", "0.108966"], ["84305.25", "0.028005"], ["84305.2", "0"], ["84305.19", "0"], ["84304.14", "0.011861"], ["84302.39", "0.071178"], ["84300.22", "0.037259"], ["84297.79", "0"], ["84296.76", "0.084074"], ["84295.97", "0"], ["84295.87", "0.02"], ["84295.5", "0"], ["84295.4", "0.02"], ["84294.93", "0"], ["84294.83", "0.02"], ["84293.5", "0.0002"], ["84293.4", "0.02"], ["84293.36", "0.120322"], ["84293.23", "0.02"], ["84292.76", "0.105026"], ["84292.43", "0.257182"], ["84292.3", "0"], ["84292.03", "0"], ["84290.99", "0"], ["84290.69", "0"], ["84290.48", "0.109213"], ["84290.22", "0.01188"], ["84290.2", "0"], ["84288.24", "0"], ["84285.22", "0.173281"], ["84283.6", "0"], ["84283.48", "0.276293"], ["84282.44", "0.000233"], ["84282.34", "0.180584"], ["84282.27", "0.178394"], ["84279.44", "0"], ["84277.09", "0.292834"], ["84275.35", "0"], ["84274.21", "0.280363"], ["84274.18", "0"], ["84271.73", "0"], ["84268.71", "0"], ["84262.36", "0.11863"], ["84262.35", "0"], ["84262.34", "0"], ["84262.24", "0.04"], ["84262.23", "0.039645"]], "a": [["84310.88", "0.172018"], ["84310.92", "0"], ["84310.93", "0"], ["84311.71", "0"], ["84316.83", "0"], ["84317.21", "0"], ["84317.45", "0"], ["84320.16", "0.049664"], ["84320.7", "0"], ["84321.22", "0"], ["84322.39", "0"], ["84322.94", "0.117752"], ["84323.46", "0.107719"], ["84323.73", "0"], ["84324.49", "0.116458"], ["84325.46", "0.109782"], ["84327.09", "0"], ["84327.43", "0"], ["84328.99", "0"], ["84329.48", "0"], ["84331", "0.178029"], ["84331.59", "0.159806"], ["84331.89", "0"], ["84331.98", "0"], ["84332.26", "0"], ["84333.6", "0.168511"], ["84334.33", "0.163827"], ["84334.93", "0"], ["84337.25", "0"], ["84337.73", "0"], ["84339.13", "0.264632"], ["84339.73", "0.281688"], ["84340.23", "0"], ["84341.73", "0.288713"], ["84342.99", "0"], ["84346.35", "0"], ["84350.86", "0.428903"], ["84350.92", "0.000612"], ["84350.96", "0.001333"], ["84351.36", "0.000439"], ["84351.48", "0.000235"], ["84351.68", "0.0002"], ["84351.69", "0.023722"], ["84352", "0.000235"], ["84352.62", "0.015"], ["84353.03", "0.474198"], ["84353.22", "0.177917"], ["84353.24", "0.118791"]], "u": 7510719, "seq": 66889371024}, "cts": 1742142239806, "record_time": 1742142238.909033}
{"topic": "orderbook.200.BTCUSDT", "ts": 1742142240010, "type": "delta", "data": {"s": "BTCUSDT", "b": [["84310.87", "0.011186"], ["84305.25", "0"], ["84305.15", "0.028502"], ["84304.14", "0.004611"], ["84302.39", "0"], ["84301.84", "0.027607"], ["84300.23", "0.000297"], ["84300.22", "0.059867"], ["84299.59", "0.07118"], ["84299.09", "0"], ["84296.97", "0.02"], ["84296.5", "0.02"], ["84295.87", "0"], ["84295.83", "0.02"], ["84295.4", "0"], ["84294.83", "0"], ["84294.5", "0.02"], ["84294.33", "0.02"], ["84293.43", "0.000501"], ["84293.4", "0"], ["84293.36", "0"], ["84293.23", "0"], ["84292.8", "0.237217"], ["84292.76", "0"], ["84292.43", "0.148349"], ["84291.99", "0"], ["84291.97", "0.0001"], ["84291.27", "0.118643"], ["84290.97", "0.109218"], ["84290.48", "0"], ["84290.43", "0.105945"], ["84287.98", "0.120448"], ["84286.8", "0"], ["84285.22", "0"], ["84284.38", "0"], ["84283.92", "0.164035"], ["84283.31", "0.008453"], ["84282.84", "0.166767"], ["84282.34", "0"], ["84282.27", "0"], ["84279.88", "0.162207"], ["84279.84", "0.172592"], ["84277.09", "0"], ["84275.79", "0.286098"], ["84274.7", "0.270113"], ["84274.21", "0"], ["84271.71", "0.28349"], ["84269.31", "0.29871"], ["84256.59", "0"], ["84256.51", "0"], ["84256.35", "0"], ["84256", "0"]], "a": [["84310.88", "0.602214"], ["84310.89", "0.02393"], ["84311.71", "0.01186"], ["84312.88", "0.0006"], ["84315.14", "0.00593"], ["84315.94", "0.023721"], ["84316.77", "0.048316"], ["84317.82", "0.089922"], ["84320.16", "0.10887"], ["84320.56", "0.105173"], ["84321.07", "0.112874"], ["84322.16", "0.120179"], ["84322.67", "0.28903"], ["84322.89", "0"], ["84322.94", "0"], ["84322.96", "0.116107"], ["84323.46", "0"], ["84324.49", "0"], ["84325.12", "0.00593"], ["84325.46", "0"], ["84325.53", "0.059304"], ["84328.67", "0.168702"], ["84329.21", "0.178578"], ["84331", "0"], ["84331.1", "0.163731"], ["84331.59", "0"], ["84331.95", "0.16421"], ["84332.03", "0.059948"], ["84333.6", "0"], ["84334.33", "0"], ["84336.8", "0.264248"], ["84337.34", "0.420904"], ["84339.13", "0"], ["84339.23", "0.271721"], ["84339.73", "0"], ["84341.73", "0"], ["84342.52", "0.279628"], ["84348.8", "0"], ["84350.18", "0.355907"], ["84350.88", "0.0012"], ["84351.36", "0"], ["84351.48", "0"], ["84351.68", "0"], ["84351.69", "0"], ["84352", "0"], ["84352.62", "0"], ["84353.03", "0"], ["84353.22", "0"], ["84353.24", "0"]], "u": 7510720, "seq": 66889371446}, "cts": 1742142240007, "record_time": 1742142239.10972}
{"topic": "orderbook.200.BTCUSDT", "ts": 1742142240210, "type": "delta", "data": {"s": "BTCUSDT", "b": [["84310.87", "0.11095"], ["84310.04", "0.01186"], ["84306.66", "0.010362"], ["84305.15", "0.036142"], ["84304.14", "0.011861"], ["84303.8", "0.071176"], ["84301.85", "0.059948"], ["84301.84", "0"], ["84300.22", "0.037259"], ["84299.59", "0"], ["84296.76", "0.225523"], ["84295.93", "0.02"], ["84295.83", "0"], ["84295.41", "0.252337"], ["84294.6", "0.02"], ["84294.5", "0"], ["84294.33", "0"], ["84294.23", "0.257264"], ["84294.2", "0.000338"], ["84293.99", "0.162"], ["84293.43", "0.000252"], ["84291.27", "0"], ["84291.1", "0.011861"], ["84290.97", "0.0002"], ["84290.43", "0"], ["84290.02", "0.237217"], ["84287.98", "0"], ["84286.02", "0"], ["84283.92", "0"], ["84282.84", "0"], ["84281.59", "0"], ["84279.88", "0"], ["84279.84", "0"], ["84278.45", "0.017792"], ["84275.88", "0.0712"], ["84275.79", "0"], ["84274.7", "0"], ["84273.38", "0"], ["84271.71", "0"], ["84269.31", "0"], ["84263.63", "0"], ["84262.24", "0"], ["84262.23", "0"], ["84262.15", "0.04"], ["84262.14", "0.039645"], ["84259.11", "0.355865"], ["84256.59", "0.015"], ["84256.51", "0.001467"], ["84256.35", "0.000252"], ["84256", "0.001243"], ["84255.64", "0.023726"], ["84255.58", "0.0002"], ["84255.38", "0.11863"]], "a": [["84310.88", "0.163862"], ["84310.89", "0.011857"], ["84311.71", "0"], ["84315.09", "0.006951"], ["84315.14", "0"], ["84315.92", "0.011861"], ["84315.94", "0"], ["84317.82", "0"], ["84320.16", "0.049664"], ["84320.56", "0"], ["84321.07", "0"], ["84322.16", "0"], ["84322.67", "0.173263"], ["84322.96", "0"], ["84323.96", "0"], ["84325.12", "0"], ["84325.53", "0"], ["84326.81", "0"], ["84328.57", "0.017792"], ["84328.67", "0"], ["84329.21", "0"], ["84331.1", "0"], ["84331.95", "0"], ["84332.03", "0"], ["84332.15", "0"], ["84335.83", "0.178652"], ["84336.73", "0"], ["84336.8", "0"], ["84337.34", "0.11863"], ["84339.23", "0"], ["84340.58", "0.237217"], ["84342.52", "0"], ["84348.98", "0.04"], ["84349", "0"], ["84350.18", "0"], ["84351.36", "0.000439"], ["84351.48", "0.000235"], ["84351.68", "0.0002"], ["84351.69", "0.023722"], ["84352", "0.000235"], ["84352.62", "0.015"], ["84353.03", "0.474198"], ["84353.22", "0.177917"], ["84353.24", "0.118791"], ["84353.72", "0.000253"], ["84353.89", "0.001467"], ["84353.97", "0.00593"], ["84354", "0.352467"], ["84354.21", "0.0002"], ["84354.92", "0.00109"], ["84355.14", "0.000612"], ["84355.15", "0.000357"], ["84355.18", "0.001333"], ["84356.01", "0.00009"]], "u": 7510721, "seq": 66889371896}, "cts": 1742142240207, "record_time": 1742142239.308684}
{"topic": "orderbook.200.BTCUSDT", "ts": 1742142240410, "type": "delta", "data": {"s": "BTCUSDT", "b": [["84310.04", "0"], ["84306.66", "0.004203"], ["84303.8", "0"], ["84301.55", "0.071178"], ["84296.76", "0.261598"], ["84294.51", "0.107613"], ["84294.33", "0.02"], ["84294.23", "0.237264"], ["84294.21", "0.120247"], ["84293.99", "0"], ["84293.24", "0.111939"], ["84287.14", "0"], ["84287.13", "0.003"], ["84286.94", "0"], ["84286.93", "0.003"], ["84286.69", "0.164343"], ["84286.02", "0.163585"], ["84283.48", "0.104761"], ["84283.28", "0.177056"], ["84283.04", "0.158831"], ["84278.5", "0.285981"], ["84277.82", "0.289668"], ["84275.09", "0.286188"], ["84272.39", "0.291154"], ["84262.15", "0"], ["84262.14", "0"], ["84261.95", "0.04"], ["84261.94", "0.039645"], ["84259.11", "0"], ["84258.1", "0"], ["84257.91", "0"], ["84256.59", "0"], ["84256.51", "0"], ["84256.35", "0"], ["84256", "0"], ["84255.64", "0"], ["84255.58", "0"], ["84255.38", "0"]], "a": [["84310.88", "0.164048"], ["84311.71", "0.009284"], ["84315.09", "0.01186"], ["84322.67", "0.113802"], ["84324", "0.108634"], ["84324.52", "0.107962"], ["84325.19", "0.114526"], ["84326.7", "0.113172"], ["84331.44", "0.182556"], ["84331.75", "0.171565"], ["84332.71", "0.179827"], ["84335.47", "0.167145"], ["84335.83", "0"], ["84339.94", "0.294345"], ["84343.09", "0.262963"], ["84346.12", "0.267772"], ["84348.98", "0"], ["84349", "0.04"], ["84351.77", "0.162"], ["84353.24", "0"], ["84353.72", "0"], ["84353.89", "0"], ["84353.97", "0"], ["84354", "0"], ["84354.21", "0"], ["84354.92", "0"], ["84355.14", "0"], ["84355.15", "0"], ["84355.18", "0"], ["84356.01", "0"]], "u": 7510722, "seq": 66889372245}, "cts": 1742142240407, "record_time": 1742142239.509553}
{"topic": "orderbook.200.BTCUSDT", "ts": 1742142240609, "type": "delta", "data": {"s": "BTCUSDT", "b": [["84310.87", "0.18161"], ["84310.04", "0.011188"], ["84306.66", "0.011469"], ["84305.15", "0"], ["84304.15", "0.022328"], ["84301.83", "0"], ["84301.55", "0"], ["84300.48", "0.061752"], ["84300.47", "0.059462"], ["84300.22", "0"], ["84298.55", "0"], ["84298.2", "0.116364"], ["84297.89", "0.107347"], ["84296.76", "0.365893"], ["84295.93", "0"], ["84295.85", "0.01186"], ["84295.83", "0.02"], ["84294.97", "0.109582"], ["84294.51", "0"], ["84294.21", "0"], ["84293.99", "0.162"], ["84293.24", "0"], ["84291.1", "0"], ["84290.84", "0.168205"], ["84289.7", "0.160766"], ["84286.77", "0.161264"], ["84286.69", "0"], ["84286.02", "0"], ["84283.28", "0"], ["84283.21", "0.017791"], ["84283.04", "0"], ["84282.64", "0.279375"], ["84282.31", "0.071195"], ["84281.72", "0"], ["84278.5", "0"], ["84278.45", "0"], ["84277.82", "0"], ["84276.08", "0.29625"], ["84275.09", "0"], ["84272.39", "0"], ["84269.73", "0"], ["84263.36", "0.355849"], ["84258.1", "0.24702"], ["84257.91", "0.000335"], ["84256.59", "0.015"]], "a": [["84310.88", "0.030274"], ["84311.71", "0"], ["84315.09", "0.00009"], ["84315.92", "0"], ["84316.77", "0"], ["84317.37", "0"], ["84319.55", "0"], ["84320.16", "0"], ["84320.34", "0.01186"], ["84323.34", "0.008453"], ["84323.67", "0"], ["84324", "0"], ["84324.52", "0"], ["84325.19", "0"], ["84326.7", "0"], ["84327.69", "0.117461"], ["84327.76", "0"], ["84328.21", "0.111548"], ["84328.57", "0"], ["84329.34", "0.119152"], ["84330.19", "0.110496"], ["84330.2", "0.068395"], ["84331.75", "0"], ["84332.04", "0"], ["84332.34", "0"], ["84332.71", "0"], ["84332.99", "0.017791"], ["84335.47", "0"], ["84335.9", "0.168914"], ["84336.37", "0.237223"], ["84336.4", "0.167989"], ["84338.39", "0.165606"], ["84339.15", "0"], ["84339.2", "0"], ["84339.27", "0"], ["84339.85", "0.118609"], ["84339.94", "0"], ["84341.35", "0.023937"], ["84343.09", "0"], ["84343.36", "0"], ["84343.48", "0"], ["84344.09", "0.295152"], ["84344.59", "0.273628"], ["84346.12", "0"], ["84346.52", "0.07114"], ["84346.58", "0.263727"], ["84348.99", "0"], ["84349", "0"], ["84349.89", "0.03181"], ["84350.09", "0.04"], ["84350.1", "0.04"], ["84353.24", "0.118791"], ["84353.72", "0.000253"], ["84353.89", "0.001467"], ["84353.97", "0.00593"], ["84354", "0.352467"], ["84354.21", "0.0002"], ["84354.92", "0.00109"], ["84355.14", "0.000612"], ["84355.15", "0.000357"]], "u": 7510723, "seq": 66889372794}, "cts": 1742142240608, "record_time": 1742142239.708837}
{"topic": "orderbook.200.BTCUSDT", "ts": 1742142240810, "type": "delta", "data": {"s": "BTCUSDT", "b": [["84316.77", "0.403814"], ["84315.95", "0.01478"], ["84315.08", "0.029765"], ["84314.9", "0.0193"], ["84313.73", "0.0002"], ["84312.02", "0.133393"], ["84311.98", "0.000252"], ["84311.04", "0.237217"], ["84310.93", "0.059948"], ["84310.88", "0.0004"], ["84310.87", "0.00156"], ["84310.26", "0.000233"], ["84309.73", "0.000233"], ["84309.36", "0.080523"], ["84309.35", "0.237222"], ["84308.8", "0.001333"], ["84308.76", "0.000613"], ["84308.68", "0.0002"], ["84308.34", "0.02629"], ["84307.51", "0.001467"], ["84307.34", "0.000252"], ["84307.29", "0.119445"], ["84306.99", "0.106109"], ["84306.66", "0"], ["84306.65", "0.0005"], ["84304.15", "0.153537"], ["84304.14", "0"], ["84302.66", "0.237201"], ["84302.65", "0.000089"], ["84302.44", "0"], ["84302.43", "0.162"], ["84301.74", "0.068395"], ["84301.2", "0.011859"], ["84300.48", "0.118222"], ["84300.47", "0.059711"], ["84299.26", "0.015074"], ["84299.07", "0"], ["84298.89", "0.169183"], ["84298.8", "0.161518"], ["84298.62", "0"], ["84298.47", "0.02"], ["84298.44", "0.237201"], ["84298.2", "0"], ["84298.1", "0.02"], ["84298.05", "0"], ["84297.89", "0"], ["84297.43", "0.02"], ["84297.1", "0.04"], ["84296.97", "0"], ["84296.5", "0"], ["84296.47", "0.170263"], ["84296.43", "0.009541"], ["84296.1", "0.02"], ["84295.85", "0"], ["84295.82", "0.16505"], ["84295.41", "0"], ["84295.1", "0.04"], ["84294.97", "0"], ["84294.6", "0"], ["84294.33", "0"], ["84294.23", "0"], ["84294.2", "0.000089"], ["84292.8", "0"], ["84292.57", "0.00897"], ["84292.43", "0.272734"], ["84292.35", "0.089922"], ["84291.8", "0.04"], ["84291.21", "0.019095"], ["84290.84", "0"], ["84290.83", "0.023719"], ["84290.02", "0"], ["84289.7", "0"], ["84288.82", "0.071189"], ["84288.6", "0.04"], ["84288.59", "0"], ["84288.55", "0.017789"], ["84288.28", "0.269602"], ["84287.1", "0.04"], ["84286.77", "0"], ["84286.7", "0.08"], ["84286.07", "0"], ["84285.8", "0"], ["84285.17", "0.290673"], ["84283.31", "0"], ["84283.3", "0"], ["84283.21", "0"], ["84282.64", "0"], ["84281.4", "0"], ["84281.1", "0"], ["84280.02", "0.000335"], ["84279.45", "0.023722"], ["84278.1", "0"], ["84277.07", "0.156914"], ["84276.27", "0"], ["84276.08", "0"], ["84275.88", "0"], ["84273.52", "0"], ["84271.98", "0.474442"], ["84271.8", "0"], ["84268.29", "0"], ["84268.28", "0"], ["84266.48", "0.000988"], ["84263.36", "0"], ["84261.15", "0"], ["84261", "0"], ["84260.98", "0"], ["84260.63", "0"], ["84260.62", "0"], ["84260.43", "0"], ["84260.4", "0"], ["84259.26", "0"], ["84259.1", "0"], ["84258.74", "0"], ["84258.69", "0"], ["84258.23", "0"], ["84258.18", "0"], ["84258.11", "0"], ["84258.1", "0"], ["84257.91", "0"], ["84256.59", "0"]], "a": [["84310.88", "0"], ["84310.89", "0"], ["84310.9", "0"], ["84310.95", "0"], ["84311.2", "0"], ["84311.98", "0"], ["84312.14", "0"], ["84312.88", "0"], ["84312.97", "0"], ["84313.02", "0"], ["84313.27", "0"], ["84313.73", "0"], ["84313.85", "0"], ["84314.37", "0"], ["84314.9", "0"], ["84315.09", "0"], ["84315.95", "0"], ["84316.26", "0"], ["84316.61", "0"], ["84316.78", "0.009997"], ["84316.99", "0"], ["84319.31", "0"], ["84320.25", "0"], ["84320.34", "0"], ["84320.42", "0"], ["84321.97", "0"], ["84322.67", "0"], ["84322.9", "0"], ["84323.34", "0"], ["84323.57", "0.020997"], ["84325.21", "0.0005"], ["84325.26", "0.029435"], ["84325.3", "0"], ["84325.7", "0"], ["84326.76", "0"], ["84327.51", "0"], ["84327.69", "0"], ["84328.21", "0"], ["84328.8", "0"], ["84329.3", "0"], ["84329.34", "0"], ["84329.36", "0"], ["84329.43", "0"], ["84329.98", "0.117219"], ["84330.19", "0"], ["84330.2", "0"], ["84330.57", "0.011859"], ["84330.6", "0"], ["84330.78", "0.000153"], ["84330.81", "0"], ["84330.9", "0"], ["84331.44", "0.117109"], ["84332.2", "0"], ["84332.3", "0"], ["84332.4", "0"], ["84332.6", "0"], ["84332.9", "0.044"], ["84332.92", "0.140138"], ["84332.95", "0"], ["84332.99", "0"], ["84334.27", "0"], ["84334.48", "0"], ["84334.82", "0.008453"], ["84334.9", "0.068"], ["84335.18", "0"], ["84335.9", "0"], ["84336", "0"], ["84336.37", "0"], ["84336.4", "0"], ["84337.3", "0.106324"], ["84337.59", "0"], ["84337.63", "0"], ["84338.2", "0.056"], ["84338.39", "0"], ["84338.59", "0"], ["84338.6", "0"], ["84339.33", "0"], ["84339.66", "0.005"], ["84339.85", "0"], ["84339.89", "0.109139"], ["84340.4", "0.000988"], ["84340.56", "0"], ["84340.57", "0.596971"], ["84340.89", "0.023719"], ["84341.35", "0"], ["84342.1", "0.162"], ["84342.89", "0.004589"], ["84343.1", "0"], ["84343.22", "0.017789"], ["84343.33", "0"], ["84343.72", "0"], ["84343.95", "0.160759"], ["84343.96", "0.068395"], ["84344.09", "0.0002"], ["84344.27", "0"], ["84344.59", "0"], ["84344.79", "0.237201"], ["84345.15", "0.1186"], ["84345.29", "0.009462"], ["84346.15", "0.003323"], ["84346.52", "0"], ["84346.58", "0"], ["84347.35", "0.000789"], ["84347.68", "0"], ["84348.26", "0.16334"], ["84348.57", "0.019104"], ["84349.01", "0.237201"], ["84349.89", "0"], ["84349.92", "0.009997"], ["84350.09", "0"], ["84350.1", "0"], ["84352.14", "0.293156"], ["84353.03", "0"], ["84353.69", "0.272132"], ["84355.18", "0.001333"], ["84356.01", "0.00009"], ["84356.12", "0.000235"], ["84356.16", "0.023722"], ["84356.28", "0.266382"], ["84356.46", "0.071132"], ["84356.64", "0.000235"], ["84356.74", "0.0002"], ["84357.02", "0.000085"], ["84357.1", "0.0045"], ["84358.07", "0.000335"], ["84358.36", "0.000253"], ["84358.53", "0.001467"], ["84358.69", "0.017796"], ["84359.27", "0.0002"], ["84359.29", "0.002853"], ["84359.3", "0.246059"], ["84359.36", "0.000612"], ["84359.4", "0.001333"], ["84359.41", "0.04"], ["84359.42", "0.04"], ["84359.55", "0.001243"], ["84359.61", "0.059948"], ["84360", "0.0006"], ["84360.38", "0.143808"], ["84360.74", "0.359725"], ["84360.76", "0.000235"], ["84360.87", "1.779498"], ["84361.28", "0.000235"], ["84361.81", "0.0002"], ["84363", "0.000253"], ["84363.06", "0.0045"], ["84363.08", "0.00089"], ["84363.17", "0.001467"], ["84363.26", "0.0045"], ["84363.35", "0.118791"], ["84363.57", "0.000612"], ["84363.62", "0.001333"], ["84364.34", "0.0002"], ["84364.52", "0.000089"], ["84365.12", "0.0045"], ["84365.17", "0.0045"], ["84365.32", "0.0045"], ["84365.37", "0.0045"], ["84365.4", "0.000235"], ["84365.92", "0.000235"]], "u": 7510724, "seq": 66889374276}, "cts": 1742142240807, "record_time": 1742142239.9096}
{"topic": "orderbook.200.BTCUSDT", "ts": 1742142241009, "type": "delta", "data": {"s": "BTCUSDT", "b": [["84325.65", "0.318321"], ["84325.61", "0.030235"], ["84325.24", "0.359689"], ["84324.16", "0.030435"], ["84323.64", "0.08165"], ["84321.42", "0.178625"], ["84321.41", "0.162"], ["84321.4", "0.000613"], ["84321.32", "0.0002"], ["84320.38", "0.089922"], ["84319.54", "0.059948"], ["84319.53", "0.000233"], ["84319.01", "0.000233"], ["84318.79", "0.0006"], ["84317.23", "0.001333"], ["84317.19", "0.000613"], ["84316.78", "0.001467"], ["84316.77", "0"], ["84316.61", "0.000252"], ["84316.26", "0.0002"], ["84315.95", "0"], ["84315.94", "0.01186"], ["84315.08", "0"], ["84314.9", "0.000233"], ["84314.37", "0.000233"], ["84313.02", "0.001333"], ["84312.97", "0.000613"], ["84312.56", "0.01186"], ["84312.14", "0.001467"], ["84312.02", "0.071117"], ["84311.2", "0.0002"], ["84311.16", "0.089922"], ["84311.1", "0.000089"], ["84311.09", "0.162"], ["84311.04", "0"], ["84310.88", "0"], ["84310.87", "0.00096"], ["84310.35", "0.022825"], ["84310.04", "0"], ["84309.96", "0.068395"], ["84309.63", "0.000817"], ["84309.36", "0.201871"], ["84309.35", "0"], ["84308.34", "0"], ["84307.29", "0"], ["84307.18", "0"], ["84306.99", "0"], ["84306.45", "0.011859"], ["84305.62", "0.000482"], ["84304.11", "0.015073"], ["84302.66", "0"], ["84302", "0.060294"], ["84301.74", "0"], ["84301.2", "0"], ["84300.48", "0.209436"], ["84300.47", "0.059462"], ["84299.47", "0.008453"], ["84299.26", "0"], ["84298.89", "0"], ["84298.8", "0"], ["84298.47", "0"], ["84298.44", "0"], ["84298.1", "0"], ["84297.43", "0"], ["84296.8", "0.04"], ["84296.76", "0.104295"], ["84296.47", "0"], ["84296.42", "0.118596"], ["84296.1", "0"], ["84296.03", "0.0002"], ["84295.83", "0"], ["84295.82", "0.000233"], ["84295.4", "0.04"], ["84294.13", "0.003"], ["84293.92", "0.003"], ["84293.8", "0.017788"], ["84293.72", "0.003"], ["84293.7", "0.048"], ["84293.4", "0.04"], ["84292.43", "0.148349"], ["84292.38", "0.068395"], ["84291.05", "0"], ["84290.12", "0.023779"], ["84288.7", "0.001243"], ["84288.55", "0"], ["84288.28", "0"], ["84288.2", "0"], ["84287.2", "0"], ["84286.7", "0.04"], ["84286.1", "0"], ["84285.17", "0"], ["84285.1", "0"], ["84280.84", "0.11"], ["84279.45", "0"], ["84277.88", "0.355795"], ["84277.29", "0.023718"], ["84277.08", "0.11863"], ["84277.07", "0"], ["84276.33", "0"], ["84271.98", "0.11863"], ["84268.95", "0"], ["84265.61", "0"], ["84265.1", "0"], ["84264.88", "0"], ["84263.9", "0"], ["84263.37", "0"], ["84263.35", "0"], ["84263.16", "0"], ["84262.44", "0"], ["84262.4", "0"], ["84262.36", "0"], ["84261.99", "0"], ["84261.98", "0"], ["84261.95", "0"], ["84261.94", "0"], ["84261.9", "0"]], "a": [["84316.78", "0"], ["84316.97", "0"], ["84317.19", "0"], ["84317.23", "0"], ["84317.25", "0"], ["84318.79", "0"], ["84319.01", "0"], ["84319.53", "0"], ["84319.54", "0"], ["84320", "0"], ["84321.25", "0"], ["84321.32", "0"], ["84321.4", "0"], ["84321.42", "0"], ["84321.45", "0"], ["84322", "0"], ["84323.57", "0"], ["84323.65", "0"], ["84323.85", "0"], ["84324.17", "0"], ["84325.21", "0"], ["84325.26", "0"], ["84325.27", "0"], ["84325.62", "0"], ["84325.66", "0.000715"], ["84327.97", "0.0005"], ["84328.25", "0.020996"], ["84329.97", "0.000296"], ["84329.98", "0"], ["84329.99", "0"], ["84330.36", "0.083985"], ["84330.48", "0"], ["84330.78", "0"], ["84331.44", "0.0002"], ["84331.45", "0"], ["84332.9", "0"], ["84332.92", "0.000235"], ["84334.02", "0.0045"], ["84334.38", "0"], ["84334.54", "0.07115"], ["84334.82", "0"], ["84334.9", "0"], ["84334.96", "0"], ["84336.25", "0"], ["84336.3", "0.04"], ["84337.3", "0"], ["84337.34", "0"], ["84337.9", "0.068"], ["84338.2", "0"], ["84338.48", "0"], ["84339.66", "0"], ["84339.7", "0.048"], ["84339.89", "0"], ["84340.58", "0"], ["84342.1", "0"], ["84342.34", "0"], ["84343.29", "0"], ["84343.94", "0.200113"], ["84343.95", "0"], ["84343.96", "0"], ["84344.43", "0.005"], ["84344.79", "0"], ["84347.25", "0.008453"], ["84348.17", "0.370498"], ["84348.26", "0"], ["84348.29", "0"], ["84349.01", "0"], ["84349.09", "0"], ["84349.13", "0.023583"], ["84349.92", "0"], ["84350.19", "0"], ["84350.58", "0.068395"], ["84351.69", "0"], ["84352.14", "0"], ["84352.62", "0"], ["84353.05", "0.02552"], ["84353.22", "0"], ["84353.69", "0"], ["84355.4", "0.023717"], ["84356.16", "0"], ["84356.28", "0"], ["84356.46", "0"], ["84359.41", "0"], ["84359.42", "0"], ["84360.21", "0.162"], ["84360.38", "0"], ["84360.45", "0.023717"], ["84361.2", "0.023717"], ["84363.06", "0"], ["84363.26", "0"], ["84363.8", "0.023717"], ["84365.12", "0"], ["84365.32", "0"], ["84366", "0.071124"], ["84366.35", "0.023722"], ["84366.41", "0.04"], ["84366.42", "0.04"], ["84366.87", "0.0002"], ["84366.97", "0.005"], ["84367.64", "0.000253"], ["84367.79", "0.000612"], ["84367.81", "0.001467"], ["84367.84", "0.001333"], ["84368.02", "0.071233"], ["84368.37", "0.023717"], ["84368.4", "0.059948"], ["84369.4", "0.0002"], ["84370.04", "0.000235"], ["84370.45", "0.001243"], ["84370.56", "0.000235"], ["84370.97", "0.0045"], ["84371.17", "0.0045"], ["84371.45", "0.0045"], ["84371.65", "0.0045"], ["84371.93", "0.0002"], ["84372.01", "0.000612"], ["84372.05", "0.001333"], ["84372.12", "0.024741"], ["84372.28", "0.000253"], ["84372.45", "0.001467"], ["84372.8", "0.059119"], ["84373", "0.0006"], ["84373.03", "0.000089"], ["84373.46", "0.118791"], ["84374.46", "0.0002"], ["84374.68", "0.000235"], ["84374.7", "0.00315"], ["84375.2", "0.000235"], ["84375.5", "0.000089"], ["84375.72", "0.017796"], ["84376.23", "0.001056"], ["84376.27", "0.001333"], ["84376.91", "0.091157"], ["84376.92", "0.000253"], ["84377.09", "0.001467"], ["84377.24", "0.28557"], ["84377.4", "0.027976"], ["84378.16", "2.362732"], ["84379.32", "0.000235"], ["84379.84", "0.000235"], ["84380", "0.007143"], ["84380.18", "0.000335"]], "u": 7510725, "seq": 66889375937}, "cts": 1742142241008, "record_time": 1742142240.109046}
{"topic": "orderbook.200.BTCUSDT", "ts": 1742142241209, "type": "delta", "data": {"s": "BTCUSDT", "b": [["84335.32", "0.223323"], ["84334.49", "0.011857"], ["84334.22", "0.019484"], ["84333.87", "0.005"], ["84332.85", "0.071152"], ["84331.12", "0.0195"], ["84331.11", "0.011858"], ["84330.53", "0.0602"], ["84329.49", "0.04067"], ["84328.91", "0.197504"], ["84328.9", "0.06047"], ["84328.58", "0.011858"], ["84328.27", "0.0105"], ["84327.5", "0.237149"], ["84327.49", "0.031348"], ["84326.89", "0.049115"], ["84326.06", "0.12766"], ["84326.05", "0.004479"], ["84325.89", "0.000252"], ["84325.68", "0.008453"], ["84325.66", "0.001333"], ["84325.65", "0"], ["84325.62", "0.000613"], ["84325.24", "0"], ["84324.17", "0.000233"], ["84324.16", "0"], ["84324", "0.106373"], ["84323.85", "0.0002"], ["84323.65", "0.000233"], ["84323.64", "0"], ["84322.6", "0.011856"], ["84321.96", "0.000099"], ["84321.45", "0.001333"], ["84321.43", "0.118574"], ["84321.42", "0.175472"], ["84321.25", "0.000252"], ["84319.55", "0.000089"], ["84318.79", "0.0002"], ["84318.54", "0.068395"], ["84318.08", "0.237149"], ["84315.94", "0"], ["84315.85", "0.173088"], ["84315.66", "0.009541"], ["84315.62", "0.019344"], ["84313.87", "0.237149"], ["84313.71", "0.006045"], ["84312.56", "0"], ["84312.03", "0.11863"], ["84312.02", "0.113245"], ["84310.87", "0"], ["84310.49", "0.281215"], ["84310.35", "0"], ["84309.96", "0"], ["84309.76", "0.017785"], ["84309.75", "0.075346"], ["84309.36", "0"], ["84307.5", "0.04"], ["84306.65", "0"], ["84306.45", "0"], ["84305.62", "0.000233"], ["84304.16", "0.114446"], ["84304.15", "0"], ["84304.14", "0.023715"], ["84304.11", "0"], ["84304", "0.278366"], ["84303.7", "0.04"], ["84303.6", "0.04"], ["84302.44", "0.11863"], ["84302", "0"], ["84301.31", "0.005929"], ["84301.08", "0.139901"], ["84300.48", "0"], ["84300.47", "0"], ["84299.47", "0"], ["84297", "0.023715"], ["84296.43", "0"], ["84296.42", "0"], ["84296.1", "0.04"], ["84295.81", "0.071183"], ["84295.1", "0"], ["84294.44", "0.323425"], ["84294", "0.474366"], ["84293.8", "0"], ["84292.54", "0.071186"], ["84291.8", "0"], ["84291.21", "0"], ["84290.83", "0"], ["84290.5", "0"], ["84290.02", "0.237149"], ["84288.82", "0"], ["84288.29", "0.11863"], ["84288.21", "0"], ["84287.34", "0.000089"], ["84287.33", "0.11"], ["84287.07", "0.006161"], ["84285.8", "0.237149"], ["84285.53", "1.429527"], ["84282.79", "0"], ["84282.58", "0.023714"], ["84282.31", "0"], ["84280.84", "0"], ["84277.88", "0"], ["84277.82", "0.004595"], ["84277.59", "0.023714"], ["84277.19", "0"], ["84277.06", "0"], ["84275.08", "0"], ["84275.05", "0"], ["84275.04", "0"], ["84274.88", "0"], ["84274.36", "0"], ["84273.27", "0"], ["84273.17", "0"], ["84272.69", "0"], ["84272.64", "0"], ["84272.5", "0"], ["84271.98", "0"], ["84271.97", "0"], ["84271.96", "0"], ["84271.65", "0"], ["84270.87", "0"], ["84270.82", "0"], ["84270.75", "0"], ["84270.42", "0"], ["84270.25", "0"], ["84270.21", "0"], ["84268.85", "0"], ["84268.53", "0"], ["84268.22", "0"], ["84268.01", "0"], ["84266.9", "0"], ["84266.65", "0"], ["84266.61", "0"], ["84266.53", "0"], ["84266.48", "0"], ["84266.39", "0"], ["84265.78", "0"], ["84265.72", "0"], ["84265.69", "0"]], "a": [["84325.66", "0"], ["84325.89", "0"], ["84326.06", "0"], ["84326.38", "0"], ["84326.41", "0"], ["84327.5", "0"], ["84327.97", "0"], ["84328.25", "0"], ["84328.28", "0"], ["84328.81", "0"], ["84328.91", "0"], ["84329.5", "0"], ["84329.84", "0"], ["84329.88", "0"], ["84329.97", "0"], ["84330", "0"], ["84330.36", "0"], ["84330.53", "0"], ["84330.57", "0"], ["84330.69", "0"], ["84331.43", "0"], ["84331.44", "0"], ["84332.38", "0"], ["84332.92", "0"], ["84333.14", "0"], ["84333.45", "0"], ["84333.97", "0"], ["84334.02", "0"], ["84334.05", "0"], ["84334.1", "0"], ["84334.22", "0"], ["84334.54", "0"], ["84335.16", "0"], ["84335.33", "0.023042"], ["84335.81", "0"], ["84336.3", "0"], ["84337.9", "0"], ["84338.99", "0"], ["84339.2", "0.0006"], ["84339.7", "0"], ["84340.57", "0"], ["84340.88", "0.018557"], ["84340.89", "0"], ["84341.56", "0.028734"], ["84342.07", "0.00614"], ["84342.46", "0"], ["84342.89", "0"], ["84343.22", "0"], ["84343.94", "0"], ["84344.43", "0"], ["84345.15", "0"], ["84345.29", "0"], ["84346.14", "0.020975"], ["84346.15", "0"], ["84347.25", "0"], ["84347.35", "0"], ["84347.7", "0"], ["84348.17", "0"], ["84348.18", "0"], ["84348.57", "0"], ["84349.13", "0"], ["84349.18", "0.020995"], ["84349.35", "0.011856"], ["84349.8", "0.000296"], ["84349.99", "0.020799"], ["84350.2", "0.044"], ["84350.58", "0"], ["84350.86", "0"], ["84351.28", "0.083979"], ["84351.76", "0.208192"], ["84351.77", "0"], ["84352.1", "0.1"], ["84353.05", "0"], ["84353.24", "0"], ["84353.97", "0"], ["84354", "0"], ["84354.52", "0.023715"], ["84355.15", "0"], ["84357.95", "0.005"], ["84358.69", "0"], ["84358.72", "0.004573"], ["84358.84", "0.008453"], ["84359.04", "0.115227"], ["84359.29", "0.095612"], ["84359.3", "0"], ["84359.61", "0"], ["84360.21", "0"], ["84360.73", "0.693202"], ["84360.74", "0"], ["84362.12", "0.023715"], ["84362.18", "0.017785"], ["84362.62", "0.068395"], ["84363.08", "0"], ["84363.35", "0"], ["84364.28", "0.165523"], ["84364.38", "0.013771"], ["84364.42", "0.237149"], ["84364.57", "0.237149"], ["84366", "0"], ["84366.35", "0"], ["84366.41", "0"], ["84366.42", "0"], ["84367.03", "0.004744"], ["84367.19", "0.163501"], ["84368.02", "0.000111"], ["84368.4", "0"], ["84368.64", "0.237149"], ["84368.65", "0.162"], ["84368.78", "0.237149"], ["84369.12", "0.009462"], ["84371.14", "0.005928"], ["84371.61", "0.279952"], ["84372.12", "0"], ["84372.65", "1.474578"], ["84372.8", "0"], ["84373.15", "0.019104"], ["84373.46", "0"], ["84373.96", "0.432012"], ["84374.17", "0.000789"], ["84376.9", "0.059948"], ["84376.99", "0.0002"], ["84377.09", "0.163467"], ["84377.24", "0"], ["84377.34", "0.278786"], ["84377.4", "0"], ["84378.15", "0.118574"], ["84378.16", "0"], ["84379.21", "0.04"], ["84379.22", "0.04"], ["84379.52", "0.0002"], ["84380.45", "0.000612"], ["84380.49", "0.001333"], ["84380.64", "0.359725"], ["84380.84", "0.071111"], ["84381.21", "0.03181"], ["84381.35", "0.001243"], ["84381.4", "0.246059"], ["84381.54", "0.000089"], ["84381.56", "0.000253"], ["84381.7", "0.000199"], ["84381.73", "0.001467"], ["84382.05", "0.0002"], ["84382.38", "0.015"], ["84382.6", "0.003779"], ["84383.14", "0.0025"], ["84383.58", "0.11863"], ["84383.96", "0.000235"], ["84384.48", "0.000235"], ["84384.59", "0.0002"], ["84384.67", "0.000612"], ["84384.71", "0.001333"], ["84385.55", "0.000357"], ["84386.2", "0.000253"], ["84386.37", "0.001467"], ["84387.68", "0.009491"], ["84388.6", "0.000235"], ["84388.87", "0.001"], ["84388.89", "0.000612"], ["84388.91", "0.071105"], ["84388.93", "0.001333"], ["84389.12", "0.000235"], ["84390.05", "0.000089"], ["84390.84", "0.000253"], ["84391", "0.027646"], ["84391.01", "0.001467"], ["84391.17", "0.059948"], ["84391.36", "0.35236"], ["84391.63", "0.000158"]], "u": 7510726, "seq": 66889378178}, "cts": 1742142241207, "record_time": 1742142240.310195}
{"topic": "orderbook.200.BTCUSDT", "ts": 1742142241409, "type": "delta", "data": {"s": "BTCUSDT", "b": [["84335.32", "0.291524"], ["84335.27", "0.032388"], ["84335.26", "0.07115"], ["84334.49", "0.001859"], ["84334.22", "0"], ["84332.85", "0"], ["84332.3", "0.001243"], ["84331.44", "0.0002"], ["84331.11", "0"], ["84330.53", "0.000252"], ["84329.49", "0"], ["84328.93", "0.069409"], ["84328.92", "0.059948"], ["84328.91", "0.0002"], ["84328.9", "0"], ["84327.5", "0"], ["84326.38", "0.0002"], ["84326.06", "0.005127"], ["84326.05", "0.003879"], ["84325.68", "0"], ["84324.39", "0.115546"], ["84324.08", "0.015066"], ["84324", "0"], ["84322.58", "0.107289"], ["84322.28", "0.114588"], ["84321.98", "0.060269"], ["84321.96", "0"], ["84321.42", "0.095592"], ["84321.4", "0.001856"], ["84320.38", "0"], ["84319.5", "0.04"], ["84319", "0.04"], ["84318.65", "0.068395"], ["84318.54", "0"], ["84317.3", "0.04"], ["84316.26", "0.000449"], ["84316.24", "0.179378"], ["84316.19", "0.003"], ["84316.06", "0.157738"], ["84315.99", "0.003"], ["84315.85", "0"], ["84315.62", "0.019095"], ["84314.13", "0.179268"], ["84314", "0.04"], ["84312.6", "0.04"], ["84312.3", "0.04"], ["84310.49", "0"], ["84309.63", "0"], ["84308.09", "0.283822"], ["84307.91", "0.267644"], ["84305.99", "0.282977"], ["84304", "0"], ["84300.2", "0.04"], ["84299.6", "0.001243"], ["84296.8", "0"], ["84295.4", "0"], ["84294", "0.11863"], ["84293.4", "0"], ["84290.12", "0"], ["84288.6", "0"], ["84287.1", "0"], ["84286.7", "0"], ["84285.53", "0"], ["84285.05", "0.000988"], ["84284.62", "0.059161"], ["84283.49", "0.355767"], ["84283.48", "0"], ["84283.14", "0.0025"], ["84282.38", "0.015"], ["84277.87", "0"], ["84277.82", "0"], ["84277.8", "0"], ["84277.64", "0"], ["84277.59", "0"], ["84277.3", "0"], ["84277.29", "0"], ["84277.28", "0"], ["84277.08", "0"], ["84275.8", "0"]], "a": [["84335.33", "0.023366"], ["84339.2", "0.025719"], ["84339.54", "0.011856"], ["84340.4", "0"], ["84340.87", "0.039812"], ["84342.07", "0.011856"], ["84342.19", "0.071144"], ["84349.8", "0"], ["84349.98", "0.000296"], ["84349.99", "0.071769"], ["84350.2", "0.088"], ["84350.6", "0.06"], ["84351.76", "0.045787"], ["84352.3", "0.068"], ["84353.7", "0.068"], ["84354.36", "0.10569"], ["84354.54", "0.115559"], ["84355.6", "0.056"], ["84356", "0.023345"], ["84357.1", "0.0525"], ["84357.3", "0.048"], ["84357.32", "0.111288"], ["84358.93", "0.000988"], ["84359.03", "0.03644"], ["84359.04", "0"], ["84359.29", "0.002853"], ["84360.88", "0.166185"], ["84362.53", "0.1399"], ["84362.69", "0.181323"], ["84363.62", "0.004851"], ["84364.27", "0.059948"], ["84364.28", "0"], ["84365.47", "0.171982"], ["84367.03", "0"], ["84367.19", "0"], ["84369.02", "0.276084"], ["84370.22", "0.023042"], ["84370.83", "0.277707"], ["84371.61", "0"], ["84372.64", "0.118574"], ["84373.62", "0.283656"], ["84377.09", "0.181263"], ["84377.34", "0"], ["84383.57", "0.355767"], ["84384.71", "0"], ["84385.55", "0"], ["84386.2", "0"], ["84386.37", "0"], ["84387.68", "0"], ["84388.6", "0"], ["84388.87", "0"], ["84388.89", "0"], ["84388.91", "0"], ["84388.93", "0"], ["84389.12", "0"], ["84390.05", "0"], ["84390.84", "0"], ["84391", "0"], ["84391.01", "0"], ["84391.17", "0"], ["84391.36", "0"], ["84391.63", "0"]], "u": 7510727, "seq": 66889378812}, "cts": 1742142241408, "record_time": 1742142240.509063}
{"topic": "orderbook.200.BTCUSDT", "ts": 1742142241609, "type": "delta", "data": {"s": "BTCUSDT", "b": [["84335.27", "0.04601"], ["84334.49", "0"], ["84331.63", "0.000099"], ["84331.13", "0.059421"], ["84328.93", "0.030906"], ["84328.92", "0"], ["84325.62", "0.146893"], ["84324.39", "0"], ["84322.58", "0"], ["84322.28", "0"], ["84321.42", "0.173188"], ["84318.31", "0.000817"], ["84318.08", "0.237398"], ["84317.7", "0.04"], ["84316.26", "0.0002"], ["84316.24", "0"], ["84316.06", "0"], ["84315.6", "0.04"], ["84314.48", "0.008453"], ["84314.4", "0.04"], ["84314.13", "0"], ["84313.71", "0"], ["84308.09", "0"], ["84307.91", "0"], ["84307.8", "0.048"], ["84307.58", "0.139898"], ["84306.72", "0.017796"], ["84305.99", "0"], ["84303.7", "0"], ["84303.6", "0"], ["84301.08", "0"], ["84297.1", "0"], ["84296.1", "0"], ["84295.25", "1.417877"], ["84287.33", "0"], ["84285.8", "0"], ["84283.5", "0.355768"], ["84283.49", "0"], ["84277.87", "0.059948"], ["84277.82", "0.004595"], ["84277.8", "0.001476"], ["84277.64", "0.003346"], ["84277.59", "0.023714"], ["84277.3", "0.000089"], ["84277.29", "0.023718"], ["84277.28", "0.000233"]], "a": [["84335.33", "0.033817"], ["84340.16", "0.071146"], ["84340.87", "0"], ["84340.88", "0.000158"], ["84341.56", "0.0002"], ["84342.19", "0"], ["84351.76", "0.164038"], ["84354.36", "0"], ["84354.54", "0"], ["84357.32", "0"], ["84358.84", "0"], ["84359.03", "0"], ["84360.88", "0"], ["84362.69", "0"], ["84363.8", "0.047467"], ["84365.47", "0"], ["84366.21", "0.03181"], ["84369.02", "0"], ["84370.22", "0"], ["84370.24", "0.023366"], ["84370.83", "0"], ["84372.65", "0"], ["84372.79", "1.448718"], ["84373.12", "0.071118"], ["84373.62", "0"], ["84381.21", "0"], ["84383.56", "0.355768"], ["84383.57", "0"], ["84384.71", "0.001333"], ["84385.49", "0.177861"], ["84385.55", "0.000357"], ["84385.8", "0.027942"], ["84385.88", "0.024741"], ["84386.2", "0.000253"], ["84386.37", "0.001467"], ["84387.68", "0.009491"], ["84387.78", "0.015"], ["84388.6", "0.000235"], ["84388.87", "0.001"]], "u": 7510728, "seq": 66889379274}, "cts": 1742142241604, "record_time": 1742142240.709048}
{"topic": "orderbook.200.BTCUSDT", "ts": 1742142241810, "type": "delta", "data": {"s": "BTCUSDT", "b": [["84335.32", "0.143454"], ["84335.27", "0"], ["84335.26", "0"], ["84332.67", "0.04556"], ["84332.66", "0.071152"], ["84329.88", "0.001333"], ["84329.84", "0.000613"], ["84328.81", "0.000233"], ["84328.28", "0.000233"], ["84326.06", "0.006594"], ["84326.05", "0"], ["84325.63", "0.080849"], ["84325.62", "0.000613"], ["84324.89", "0.237178"], ["84319", "0.040249"], ["84318.08", "0"], ["84316.25", "0.120271"], ["84311.76", "0.02"], ["84311.16", "0"], ["84311.09", "0.182"], ["84309.75", "0"], ["84307.5", "0"], ["84304.6", "0.024121"], ["84300.2", "0"], ["84293.7", "0"], ["84285.8", "0.237149"], ["84284.63", "0.355766"], ["84283.5", "0"], ["84277.3", "0"], ["84277.29", "0"], ["84277.28", "0"]], "a": [["84335.33", "0.025364"], ["84336.16", "0.011857"], ["84337.61", "0.071148"], ["84339.2", "0.0006"], ["84340.16", "0"], ["84344.15", "0.011857"], ["84344.96", "0.008453"], ["84349.35", "0"], ["84351.76", "0.097663"], ["84356.8", "0.017786"], ["84358", "0.000119"], ["84362.18", "0"], ["84368.32", "0.02376"], ["84370.24", "0"], ["84381.39", "0.355766"], ["84383.56", "0"], ["84385.53", "0.162"], ["84387.68", "0"], ["84387.78", "0"], ["84388.6", "0"], ["84388.87", "0"]], "u": 7510729, "seq": 66889379769}, "cts": 1742142241807, "record_time": 1742142240.908594}
{"topic": "orderbook.200.BTCUSDT", "ts": 1742142242010, "type": "delta", "data": {"s": "BTCUSDT", "b": [["84335.32", "0.285264"], ["84334.49", "0.004668"], ["84332.67", "0.02624"], ["84332.66", "0"], ["84331.11", "0.011858"], ["84325.63", "0.14679"], ["84324.89", "0"], ["84323.29", "0.237182"], ["84321.52", "0.254501"], ["84321.51", "0.237187"], ["84321.42", "0.001467"], ["84319.54", "0.060197"], ["84319.51", "0.237149"], ["84319", "0.04"], ["84318.08", "0.237149"], ["84316.1", "0.048"], ["84315.3", "0.237149"], ["84312.02", "0.071117"], ["84311.76", "0"], ["84311.66", "0.02"], ["84311.09", "0.162"], ["84311", "0.02"], ["84310.02", "0.0001"], ["84307.8", "0"], ["84302.88", "0.071177"], ["84292.54", "0"], ["84291.97", "0"], ["84290.02", "0.177861"], ["84286.32", "0.015"], ["84285.8", "0"], ["84284.63", "0"], ["84283.48", "0.355765"], ["84279.25", "0"], ["84278.33", "0"], ["84277.87", "0"], ["84277.82", "0"], ["84277.8", "0"], ["84277.64", "0"], ["84277.59", "0"]], "a": [["84336.16", "0"], ["84337.33", "0.0008"], ["84337.61", "0"], ["84339.54", "0"], ["84340.88", "0.01566"], ["84342.72", "0.028763"], ["84344.96", "0"], ["84348.7", "0.008453"], ["84350.88", "0"], ["84354.47", "0.068395"], ["84359.33", "0.005822"], ["84362.62", "0"], ["84364.41", "0.171636"], ["84365.86", "0.237149"], ["84370.07", "0.237149"], ["84373.12", "0"], ["84373.63", "0.071117"], ["84375.33", "0.0013"], ["84381.39", "0"], ["84383.57", "0.355765"], ["84386.2", "0"], ["84386.37", "0"]], "u": 7510730, "seq": 66889380240}, "cts": 1742142242008, "record_time": 1742142241.108156}
{"topic": "orderbook.200.BTCUSDT", "ts": 1742142242210, "type": "delta", "data": {"s": "BTCUSDT", "b": [["84335.32", "0.287264"], ["84334.49", "0"], ["84328.94", "0.059948"], ["84328.93", "0.098395"], ["84326.68", "0.237173"], ["84325.63", "0.179603"], ["84325.25", "0.106181"], ["84324.95", "0.119832"], ["84323.24", "0.113923"], ["84322.46", "0.108087"], ["84319.55", "0.000338"], ["84319.54", "0.059948"], ["84316.75", "0.164396"], ["84316.68", "0.176761"], ["84316.25", "0.190782"], ["84314.26", "0.166481"], ["84313.77", "0.178163"], ["84312.26", "0.02"], ["84311.66", "0"], ["84311.5", "0.02"], ["84311", "0"], ["84308.55", "0.289761"], ["84308.48", "0.265409"], ["84306.06", "0.277256"], ["84303.11", "0.283497"], ["84291", "0.04"], ["84290.99", "0.039641"], ["84284.63", "0.355756"], ["84284.32", "0"], ["84284.15", "0"], ["84283.51", "0"], ["84283.48", "0"], ["84283.47", "0"], ["84283.39", "0"], ["84283.14", "0"], ["84282.58", "0"], ["84282.44", "0"], ["84282.38", "0"], ["84281.91", "0"], ["84280.86", "0"], ["84280.02", "0"], ["84279.69", "0"], ["84279.52", "0"], ["84279.3", "0"]], "a": [["84335.33", "0.049939"], ["84339.52", "0.071146"], ["84339.54", "0.011856"], ["84354.77", "0.119018"], ["84355.22", "0.116155"], ["84355.29", "0.107575"], ["84356.79", "0.042951"], ["84357.73", "0.113242"], ["84361.78", "0.177067"], ["84363.49", "0.16288"], ["84365.93", "0.17168"], ["84366.25", "0.168704"], ["84369.98", "0.270951"], ["84370.45", "0.036822"], ["84371.69", "0.301155"], ["84373.63", "0"], ["84373.8", "0.071117"], ["84374.13", "0.270353"], ["84376.91", "0.391918"], ["84378.25", "0.04"], ["84378.26", "0.04"], ["84379.21", "0"], ["84379.22", "0"], ["84382.6", "0"], ["84383.14", "0"], ["84383.57", "0"], ["84383.58", "0"], ["84383.96", "0"], ["84384.48", "0"], ["84384.59", "0"], ["84384.67", "0"], ["84384.71", "0"], ["84385.49", "0"], ["84385.53", "0"], ["84385.55", "0"], ["84385.8", "0"], ["84385.88", "0"]], "u": 7510731, "seq": 66889380602}, "cts": 1742142242206, "record_time": 1742142241.309049}
{"topic": "orderbook.200.BTCUSDT", "ts": 1742142242410, "type": "delta", "data": {"s": "BTCUSDT", "b": [["84335.32", "0.145454"], ["84332.67", "0.045838"], ["84332.66", "0.071152"], ["84325.63", "0.144395"], ["84325.25", "0"], ["84324.95", "0"], ["84323.29", "0.349438"], ["84323.24", "0"], ["84322.99", "0.11032"], ["84322.46", "0"], ["84321.52", "0.397434"], ["84321.18", "0.108174"], ["84320.77", "0.118388"], ["84317.73", "0.003"], ["84317.53", "0.003"], ["84317.33", "0.003"], ["84316.75", "0"], ["84316.68", "0"], ["84316.25", "0.285361"], ["84314.79", "0.179387"], ["84314.62", "0.180509"], ["84314.26", "0"], ["84313.77", "0"], ["84312.57", "0.177816"], ["84312.26", "0"], ["84312.16", "0.02"], ["84311.81", "0.175631"], ["84308.55", "0"], ["84308.48", "0"], ["84306.59", "0.263341"], ["84306.42", "0.290029"], ["84306.06", "0"], ["84304.37", "0.275241"], ["84303.11", "0"], ["84302.88", "0"], ["84301.15", "0.29416"], ["84293.92", "0"], ["84293.72", "0"], ["84291.76", "0.071187"], ["84291", "0"], ["84290.99", "0"], ["84290.9", "0.04"], ["84290.89", "0.039641"], ["84288.91", "0"], ["84288.78", "0"], ["84288.58", "0"], ["84287.13", "0"], ["84286.93", "0"], ["84285.55", "0.162"], ["84284.63", "0"], ["84284.32", "0.001467"], ["84284.15", "0.000252"], ["84283.51", "0.001333"], ["84283.47", "0.000614"]], "a": [["84335.33", "0.061553"], ["84336.16", "0.001265"], ["84337.1", "0.071148"], ["84339.52", "0"], ["84340.88", "0.000158"], ["84342.72", "0.000235"], ["84351.76", "0.214522"], ["84352.81", "0.120096"], ["84353.16", "0.113229"], ["84353.33", "0.111815"], ["84354.77", "0"], ["84355.22", "0"], ["84355.29", "0"], ["84356.03", "0.110648"], ["84356.79", "0.071554"], ["84357.73", "0"], ["84359.72", "0.157664"], ["84361.53", "0.16024"], ["84361.78", "0"], ["84363.49", "0"], ["84364.23", "0.180387"], ["84364.29", "0.180325"], ["84365.93", "0"], ["84366.25", "0"], ["84367.92", "0.297695"], ["84369.73", "0.277362"], ["84369.98", "0"], ["84370.45", "0.001243"], ["84370.97", "0"], ["84371.17", "0"], ["84371.69", "0"], ["84372.43", "0.299738"], ["84374.13", "0"], ["84374.95", "0.273969"], ["84376.91", "0.091157"]], "u": 7510732, "seq": 66889381042}, "cts": 1742142242407, "record_time": 1742142241.508756}
{"topic": "orderbook.200.BTCUSDT", "ts": 1742142242609, "type": "delta", "data": {"s": "BTCUSDT", "b": [["84332.67", "0.02624"], ["84332.66", "0"], ["84331.11", "0"], ["84330.37", "0.053036"], ["84330.36", "0.071154"], ["84328.94", "0"], ["84328.93", "0"], ["84326.68", "0"], ["84325.63", "0.148776"], ["84324.86", "0.237178"], ["84323.29", "0.237182"], ["84322.99", "0"], ["84322.02", "0.105384"], ["84321.72", "0.115896"], ["84321.18", "0"], ["84320.77", "0"], ["84320.07", "0.116783"], ["84319.55", "0.000089"], ["84319.44", "0.115773"], ["84319.01", "0.000482"], ["84314.79", "0"], ["84314.62", "0"], ["84313.52", "0.17305"], ["84313.51", "0.16252"], ["84313.06", "0.02"], ["84312.57", "0"], ["84312.29", "0.02"], ["84312.16", "0"], ["84311.81", "0"], ["84311.73", "0.02"], ["84311.5", "0"], ["84311.24", "0.158027"], ["84310.54", "0.161964"], ["84306.59", "0"], ["84306.42", "0"], ["84305.32", "0.285595"], ["84305.31", "0.289875"], ["84304.38", "0.282942"], ["84304.37", "0"], ["84304.16", "0"], ["84303.04", "0.28656"], ["84301.23", "0.177861"], ["84301.15", "0"], ["84299.88", "0.271971"], ["84283.47", "0"]], "a": [["84335.33", "0.061552"], ["84336.16", "0.000962"], ["84351.54", "0.105836"], ["84352.06", "0.10842"], ["84352.21", "0.162"], ["84352.81", "0"], ["84353.16", "0"], ["84353.33", "0"], ["84354.71", "0.108028"], ["84356.02", "0.123645"], ["84356.03", "0"], ["84356.79", "0"], ["84359.72", "0"], ["84360.26", "0.164535"], ["84361.53", "0"], ["84362.91", "0.160117"], ["84363.02", "0.172822"], ["84363.54", "0.000147"], ["84364.23", "0"], ["84364.29", "0"], ["84367.92", "0"], ["84368.46", "0.296594"], ["84369.73", "0"], ["84371.11", "0.281576"], ["84372.43", "0"], ["84373.68", "0.279189"], ["84374.95", "0"], ["84382.6", "0.003779"]], "u": 7510733, "seq": 66889381363}, "cts": 1742142242608, "record_time": 1742142241.70905}
{"topic": "orderbook.200.BTCUSDT", "ts": 1742142242809, "type": "delta", "data": {"s": "BTCUSDT", "b": [["84334.49", "0.006905"], ["84331.11", "0.007738"], ["84330.37", "0.03169"], ["84330.36", "0"], ["84325.63", "0.211114"], ["84323.47", "0.109688"], ["84323.17", "0.105777"], ["84322.02", "0"], ["84321.8", "0.107677"], ["84321.72", "0"], ["84320.61", "0.118385"], ["84320.07", "0"], ["84319.5", "0.040249"], ["84319.44", "0"], ["84319.01", "0.000233"], ["84316.25", "0.205816"], ["84315.23", "0.161187"], ["84314.97", "0.175988"], ["84313.52", "0"], ["84313.51", "0"], ["84313.45", "0.02"], ["84313.06", "0"], ["84312.69", "0.02"], ["84312.41", "0.179003"], ["84312.29", "0"], ["84312.03", "0.13863"], ["84311.99", "0.168082"], ["84311.73", "0"], ["84311.24", "0"], ["84310.54", "0"], ["84307.76", "0.005965"], ["84307.03", "0.29116"], ["84306.77", "0.269181"], ["84305.32", "0"], ["84305.31", "0"], ["84304.6", "0"], ["84304.21", "0.293365"], ["84303.04", "0"], ["84301.33", "0.298911"], ["84299.88", "0"]], "a": [["84336.16", "0"], ["84337.1", "0"], ["84339.54", "0"], ["84339.97", "0.029001"], ["84340.87", "0.012664"], ["84340.88", "0.027741"], ["84344.08", "0.03267"], ["84344.09", "0.028728"], ["84346.14", "0"], ["84349.99", "0.099613"], ["84351.54", "0"], ["84352.06", "0"], ["84352.21", "0"], ["84352.99", "0.110942"], ["84353.51", "0.107651"], ["84353.78", "0.113532"], ["84354.71", "0"], ["84355.87", "0.110254"], ["84356", "0"], ["84356.02", "0"], ["84360.26", "0"], ["84360.34", "0.164095"], ["84361.71", "0.175372"], ["84362.91", "0"], ["84363.02", "0"], ["84364.07", "0.159971"], ["84364.47", "0.161616"], ["84368.46", "0"], ["84368.54", "0.279192"], ["84369.91", "0.264792"], ["84371.11", "0"], ["84372.27", "0.29577"], ["84373.68", "0"], ["84375.13", "0.27278"], ["84377.49", "0.474061"], ["84383.14", "0.0025"]], "u": 7510734, "seq": 66889381741}, "cts": 1742142242804, "record_time": 1742142241.908582}
{"topic": "orderbook.200.BTCUSDT", "ts": 1742142243009, "type": "delta", "data": {"s": "BTCUSDT", "b": [["84335.18", "0.050557"], ["84335.17", "0.07115"], ["84334.49", "0"], ["84333.88", "0.0193"], ["84332.67", "0"], ["84331.12", "0"], ["84331.11", "0.011858"], ["84330.38", "0.059948"], ["84330.37", "0.098785"], ["84327.89", "0.236854"], ["84325.63", "0.088685"], ["84324.86", "0"], ["84323.47", "0"], ["84323.17", "0"], ["84321.8", "0"], ["84321.43", "0"], ["84320.61", "0"], ["84319.55", "0.000338"], ["84319.5", "0.04"], ["84315.23", "0"], ["84314.97", "0"], ["84313.45", "0"], ["84313.36", "0.02"], ["84312.42", "0.23078"], ["84312.41", "0"], ["84312.02", "0"], ["84311.99", "0"], ["84307.03", "0"], ["84306.77", "0"], ["84304.21", "0"], ["84301.33", "0"], ["84285.56", "0.355754"], ["84283.47", "0.000614"], ["84283.39", "0.0002"], ["84283.14", "0.0025"], ["84282.58", "0.023714"], ["84282.44", "0.000233"], ["84282.38", "0.015"], ["84281.91", "0.000233"], ["84280.86", "0.0002"], ["84280.16", "0.177861"], ["84280.02", "0.000335"], ["84279.69", "0.001467"]], "a": [["84335.33", "0.061551"], ["84339.49", "0.071146"], ["84339.97", "0.001467"], ["84340.87", "0"], ["84340.88", "0.000158"], ["84344.08", "0"], ["84344.09", "0.0002"], ["84344.6", "0.020418"], ["84348.7", "0"], ["84352.35", "0.008453"], ["84352.99", "0"], ["84353.51", "0"], ["84353.78", "0"], ["84355.86", "0.076255"], ["84355.87", "0"], ["84360.34", "0"], ["84360.55", "0.105781"], ["84361.71", "0"], ["84364.07", "0"], ["84364.47", "0"], ["84368.54", "0"], ["84369.91", "0"], ["84370.41", "0.035579"], ["84371.45", "0"], ["84371.65", "0"], ["84372.27", "0"], ["84375.13", "0"], ["84383.58", "0.11863"], ["84383.96", "0.000235"], ["84384.48", "0.000235"], ["84384.59", "0.0002"], ["84384.67", "0.000612"], ["84384.71", "0.001333"], ["84385.02", "0.001235"], ["84385.49", "0.177861"], ["84385.55", "0.000357"], ["84385.8", "0.027942"], ["84385.88", "0.024741"]], "u": 7510735, "seq": 66889382158}, "cts": 1742142243002, "record_time": 1742142242.10893}
{"topic": "orderbook.200.BTCUSDT", "ts": 1742142243210, "type": "delta", "data": {"s": "BTCUSDT", "b": [["84335.32", "0.122045"], ["84335.18", "0"], ["84335.17", "0"], ["84333.88", "0"], ["84331.64", "0.0193"], ["84331.13", "0"], ["84331.11", "0"], ["84330.38", "0.027459"], ["84330.37", "0.03169"], ["84328.58", "0"], ["84327.89", "0"], ["84327.09", "0.071157"], ["84325.63", "0.014063"], ["84323.3", "0.000296"], ["84323.29", "0"], ["84322.6", "0"], ["84321.52", "0.254501"], ["84321.51", "0"], ["84321.41", "0"], ["84319.55", "0.000089"], ["84319.51", "0"], ["84318.09", "0.011857"], ["84317.7", "0.040249"], ["84314.06", "0.02"], ["84313.39", "0.02"], ["84313.36", "0"], ["84312.7", "0.118574"], ["84312.69", "0"], ["84312.42", "0"], ["84312.03", "0.02"], ["84311.5", "0.02"], ["84309.76", "0"], ["84307.76", "0"], ["84307.59", "0.118574"], ["84305.44", "0.017786"], ["84305.17", "0.006013"], ["84304.38", "0.16548"], ["84302.07", "0.023701"], ["84300.39", "0"], ["84295.81", "0"], ["84290.9", "0"], ["84290.89", "0"], ["84290.6", "0.04"], ["84290.59", "0.039642"], ["84285.56", "0"], ["84284.43", "0.071193"], ["84280.17", "0.355779"], ["84279.52", "0.000252"], ["84279.3", "0.001333"], ["84279.25", "0.000614"], ["84278.33", "0.0002"], ["84277.87", "0.059948"], ["84277.82", "0.004595"]], "a": [["84335.33", "0.061548"], ["84335.68", "0.071149"], ["84336.16", "0.011857"], ["84339.44", "0.011858"], ["84339.49", "0"], ["84339.54", "0.011856"], ["84344.15", "0"], ["84344.6", "0"], ["84346.22", "0.019978"], ["84348.22", "0.000296"], ["84349.29", "0.206015"], ["84349.7", "0.089922"], ["84349.98", "0"], ["84349.99", "0"], ["84351.76", "0.097663"], ["84352.09", "0.017787"], ["84352.21", "0.162"], ["84355.86", "0.043179"], ["84356.8", "0"], ["84358.28", "0.023447"], ["84360.49", "0.000789"], ["84366.57", "0.071123"], ["84370.07", "0"], ["84370.41", "0"], ["84371.2", "0.035579"], ["84374.17", "0"], ["84380.63", "0.355779"], ["84380.84", "0"], ["84385.02", "0"], ["84385.49", "0"], ["84385.55", "0"], ["84385.8", "0"], ["84385.88", "0"]], "u": 7510736, "seq": 66889382700}, "cts": 1742142243207, "record_time": 1742142242.309124}
{"topic": "orderbook.200.BTCUSDT", "ts": 1742142243409, "type": "delta", "data": {"s": "BTCUSDT", "b": [["84338.3", "1.088741"], ["84338.27", "0.071147"], ["84335.95", "0.001759"], ["84335.32", "0.00096"], ["84334.05", "0.000613"], ["84333.97", "0.0002"], ["84333.45", "0.000234"], ["84332.93", "0.0192"], ["84332.92", "0.000234"], ["84332.8", "0.001335"], ["84331.66", "0.027937"], ["84331.65", "0.059948"], ["84331.64", "0"], ["84331.11", "0.011858"], ["84330.69", "0.001467"], ["84330.38", "0"], ["84330.37", "0.056072"], ["84329.67", "0.119645"], ["84328.58", "0.011858"], ["84328", "0.000089"], ["84327.65", "0.119205"], ["84327.09", "0"], ["84326.06", "0.001467"], ["84323.14", "0.011856"], ["84321.52", "0"], ["84321.42", "0.163467"], ["84321.21", "0.161763"], ["84321.12", "0.172925"], ["84319.55", "0.137739"], ["84319.53", "0.000481"], ["84319.01", "0.118807"], ["84318.8", "0.003"], ["84318.6", "0.003"], ["84318.4", "0.003"], ["84318.24", "0.164499"], ["84318.09", "0"], ["84318.08", "0"], ["84317.7", "0.04"], ["84315.65", "0.02"], ["84315.58", "0.089922"], ["84315.3", "0"], ["84314.88", "0.02"], ["84314.06", "0"], ["84313.87", "0"], ["84313.39", "0"], ["84313.04", "0.274132"], ["84312.96", "0.276765"], ["84312.71", "0.139302"], ["84312.03", "0"], ["84311.5", "0"], ["84310.49", "0.017785"], ["84307.63", "0.299018"], ["84307.6", "0.088862"], ["84305.97", "0.071175"], ["84305.44", "0"], ["84301.23", "0"], ["84298.79", "0.071181"], ["84297.46", "0.017765"], ["84294.15", "0.023714"], ["84291.76", "0"], ["84291.07", "0.059047"], ["84290.61", "0.355736"], ["84290.02", "0"], ["84289.36", "0.023714"], ["84285.05", "0"], ["84284.62", "0"], ["84284.43", "0"], ["84284.32", "0"], ["84284.15", "0"], ["84283.51", "0"], ["84283.47", "0"], ["84283.39", "0"], ["84283.14", "0"], ["84282.58", "0"], ["84282.44", "0"], ["84282.38", "0"], ["84281.91", "0"], ["84280.86", "0"], ["84280.17", "0"], ["84280.16", "0"], ["84280.02", "0"], ["84279.69", "0"], ["84279.52", "0"], ["84279.3", "0"], ["84279.25", "0"], ["84278.33", "0"], ["84277.87", "0"], ["84277.82", "0"]], "a": [["84335.33", "0"], ["84335.68", "0"], ["84335.96", "0"], ["84336.16", "0"], ["84336.5", "0"], ["84337.33", "0"], ["84337.56", "0"], ["84338.08", "0"], ["84338.27", "0"], ["84338.31", "0.023651"], ["84339.44", "0"], ["84339.54", "0.002219"], ["84342.07", "0"], ["84343.23", "0"], ["84346.22", "0"], ["84348.04", "0"], ["84348.22", "0"], ["84348.24", "0"], ["84348.43", "0.071139"], ["84349.17", "0.011856"], ["84349.29", "0"], ["84349.7", "0"], ["84349.99", "0.032803"], ["84350.2", "0"], ["84350.6", "0"], ["84351.35", "0.001234"], ["84351.76", "0"], ["84352.09", "0"], ["84352.1", "0"], ["84352.21", "0"], ["84352.3", "0"], ["84352.35", "0"], ["84353.7", "0"], ["84354.47", "0"], ["84355.4", "0"], ["84355.6", "0"], ["84355.85", "0.000296"], ["84357.1", "0"], ["84357.3", "0"], ["84358", "0"], ["84358.28", "0"], ["84359.49", "0.109019"], ["84359.8", "0.06"], ["84360.45", "0"], ["84361.2", "0"], ["84361.82", "0.017785"], ["84363.8", "0.02375"], ["84364.27", "0"], ["84364.41", "0.242663"], ["84364.42", "0"], ["84364.5", "0.068"], ["84364.57", "0"], ["84365.86", "0"], ["84366.02", "0.169298"], ["84366.3", "0.048"], ["84366.5", "0.048"], ["84366.57", "0"], ["84368.37", "0"], ["84368.64", "0"], ["84368.78", "0"], ["84369.01", "0.005928"], ["84370.41", "0.023714"], ["84370.49", "0.162876"], ["84371.14", "0"], ["84371.2", "0"], ["84371.41", "0.008453"], ["84372.64", "0"], ["84372.78", "0.118574"], ["84373.8", "0"], ["84375.41", "0.023714"], ["84375.91", "0.292428"], ["84376.21", "0.023714"], ["84377.49", "0"], ["84378.25", "0"], ["84378.26", "0"], ["84379.05", "0.04"], ["84379.06", "0.04"], ["84380.34", "0.005928"], ["84380.63", "0"], ["84381.1", "0.290082"], ["84381.62", "0.023714"], ["84382.18", "0.023714"], ["84385.55", "0.000357"], ["84385.8", "0.027942"], ["84385.88", "0.024741"], ["84386.2", "0.000253"], ["84386.37", "0.001467"], ["84387.05", "0.071106"], ["84387.12", "0.0002"], ["84387.68", "0.009491"], ["84388.47", "0.059075"], ["84388.6", "0.000235"], ["84388.87", "0.001"], ["84388.89", "0.000612"], ["84388.93", "0.001333"], ["84389.12", "0.000235"], ["84389.42", "0.0045"], ["84389.45", "0.0045"], ["84389.62", "0.0045"], ["84389.65", "0.0045"], ["84390.05", "0.000089"], ["84390.84", "0.000253"], ["84391", "0.027646"], ["84391.01", "0.001467"], ["84391.17", "0.059948"], ["84391.36", "0.35236"], ["84391.63", "0.000158"], ["84392.38", "0.009"]], "u": 7510737, "seq": 66889384155}, "cts": 1742142243408, "record_time": 1742142242.50918}
{"topic": "orderbook.200.BTCUSDT", "ts": 1742142243609, "type": "delta", "data": {"s": "BTCUSDT", "b": [["84338.3", "0.025045"], ["84338.27", "0"], ["84332.93", "0.0195"], ["84331.66", "0"], ["84331.65", "0"], ["84331.63", "0"], ["84331.11", "0"], ["84330.39", "0.059948"], ["84330.38", "0.02958"], ["84330.37", "0.028159"], ["84329.67", "0"], ["84328.58", "0"], ["84327.65", "0"], ["84325.63", "0"], ["84325.62", "0.014492"], ["84323.54", "0.000296"], ["84323.14", "0"], ["84321.42", "0.001467"], ["84321.21", "0"], ["84321.12", "0"], ["84319.55", "0.146966"], ["84319.53", "0.000233"], ["84319.01", "0.000233"], ["84318.79", "0.000448"], ["84318.65", "0"], ["84318.24", "0"], ["84318.06", "0.10749"], ["84316.62", "0.011857"], ["84316.3", "0.107171"], ["84316.25", "0"], ["84315.65", "0"], ["84315.58", "0"], ["84314.88", "0"], ["84314.48", "0"], ["84313.04", "0"], ["84312.97", "0.119187"], ["84312.96", "0"], ["84312.7", "0"], ["84311.53", "0.068395"], ["84310.49", "0"], ["84308.76", "0.009066"], ["84307.72", "0.170603"], ["84307.63", "0"], ["84305.97", "0"], ["84305.17", "0.005806"], ["84304.38", "0"], ["84303.97", "0.017786"], ["84300.23", "0"], ["84298.79", "0"], ["84297", "0"], ["84294.82", "0.071184"], ["84290.61", "0"], ["84285.05", "0.000988"], ["84284.62", "0.059161"], ["84284.32", "0.001467"], ["84284.15", "0.000252"], ["84283.51", "0.001333"], ["84283.47", "0.000614"], ["84283.39", "0.023914"], ["84283.14", "0.0025"], ["84282.98", "0.003449"], ["84282.58", "0.023714"], ["84282.44", "0.000233"], ["84282.38", "0.015"], ["84281.91", "0.000233"], ["84281.77", "0.11"], ["84280.86", "0.0002"], ["84280.02", "0.000335"], ["84279.69", "0.001467"], ["84279.52", "0.000252"], ["84279.3", "0.001333"], ["84279.25", "0.000614"]], "a": [["84338.31", "0.099073"], ["84338.57", "0.089922"], ["84339.14", "0.011856"], ["84339.54", "0"], ["84342.52", "0.011856"], ["84343.92", "0.036107"], ["84343.93", "0.011857"], ["84345.05", "0.011856"], ["84348.42", "0.137825"], ["84348.43", "0"], ["84349.17", "0"], ["84349.9", "0.109095"], ["84349.99", "0"], ["84351.41", "0.111799"], ["84352.58", "0.03181"], ["84353.2", "0.044"], ["84355.1", "0.068395"], ["84355.19", "0.162"], ["84356.43", "0.175199"], ["84356.58", "0.017786"], ["84356.85", "0.089922"], ["84357.22", "0.159677"], ["84357.6", "0.06"], ["84357.73", "0.005"], ["84357.95", "0"], ["84359.4", "0.045333"], ["84359.49", "0"], ["84359.57", "0.160372"], ["84361.22", "0.023691"], ["84361.5", "0.068"], ["84361.82", "0"], ["84362.12", "0"], ["84362.26", "0.005"], ["84364.37", "0.178522"], ["84364.41", "0.071027"], ["84364.8", "0.056"], ["84366.02", "0"], ["84366.21", "0"], ["84367.74", "0.267797"], ["84370.49", "0"], ["84370.9", "0.027942"], ["84372.77", "0.355798"], ["84372.78", "0.798306"], ["84375.91", "0"], ["84377.22", "0.23714"], ["84378.88", "0.071113"], ["84379.05", "0"], ["84379.06", "0"], ["84379.85", "0.04"], ["84379.86", "0.04"], ["84381.1", "0"], ["84385.49", "0.177855"], ["84385.53", "0.162"], ["84385.8", "0"], ["84387.05", "0"], ["84388.6", "0"], ["84388.87", "0"], ["84388.89", "0"], ["84388.93", "0"], ["84389.12", "0"], ["84389.42", "0"], ["84389.45", "0"], ["84389.62", "0"], ["84389.65", "0"], ["84390.05", "0"], ["84390.84", "0"], ["84391", "0"], ["84391.01", "0"], ["84391.17", "0"], ["84391.36", "0"], ["84391.63", "0"], ["84392.38", "0"]], "u": 7510738, "seq": 66889385423}, "cts": 1742142243607, "record_time": 1742142242.709014}
{"topic": "orderbook.200.BTCUSDT", "ts": 1742142243810, "type": "delta", "data": {"s": "BTCUSDT", "b": [["84339.96", "0.251419"], ["84339.04", "0.084984"], ["84339.02", "0.0015"], ["84338.3", "0.005"], ["84338.21", "0.071147"], ["84337.47", "0.011857"], ["84336.5", "0.0002"], ["84335.17", "0.0192"], ["84335.16", "0.000252"], ["84334.66", "0.000099"], ["84334.1", "0.001333"], ["84334.09", "0.011857"], ["84332.93", "0"], ["84331.56", "0.005019"], ["84330.4", "0.17706"], ["84330.38", "0"], ["84330.37", "0"], ["84329.84", "0.117072"], ["84329.54", "0.109645"], ["84329.28", "0.015065"], ["84328.16", "0.113993"], ["84327.27", "0.119356"], ["84327.17", "0.060262"], ["84326.89", "0"], ["84326.33", "0.011856"], ["84325.62", "0.014581"], ["84324.08", "0"], ["84323.85", "0.000448"], ["84323.54", "0"], ["84322.29", "0.237138"], ["84321.98", "0"], ["84321.42", "0.163467"], ["84321.37", "0.164638"], ["84320.02", "0.068395"], ["84319.55", "0.000385"], ["84319.11", "0.174773"], ["84318.79", "0.0002"], ["84318.5", "0.089922"], ["84318.18", "0.132354"], ["84318.08", "0.237138"], ["84318.07", "0.118574"], ["84318.06", "0"], ["84316.62", "0"], ["84316.3", "0"], ["84313.68", "0.017784"], ["84311.53", "0"], ["84310.38", "0.023714"], ["84309.63", "0.071171"], ["84307.72", "0"], ["84303.97", "0"], ["84302.16", "0.071178"], ["84302.13", "0.000335"], ["84296.77", "0.355707"], ["84294.82", "0"], ["84294.23", "0.237138"], ["84291.07", "0"], ["84290.02", "0.237138"], ["84288.75", "0.000988"], ["84285.55", "0"], ["84285.05", "0"], ["84284.62", "0"], ["84284.32", "0"], ["84284.15", "0"], ["84283.51", "0"], ["84283.47", "0"], ["84283.39", "0"], ["84283.14", "0"], ["84282.98", "0"], ["84282.58", "0"], ["84282.44", "0"], ["84282.38", "0"], ["84281.91", "0"], ["84281.77", "0"], ["84280.86", "0"], ["84280.02", "0"], ["84279.69", "0"], ["84279.52", "0"], ["84279.3", "0"], ["84279.25", "0"]], "a": [["84338.31", "0"], ["84338.57", "0"], ["84339.03", "0"], ["84339.14", "0"], ["84339.2", "0"], ["84339.8", "0"], ["84339.97", "0.023108"], ["84342.52", "0"], ["84343.92", "0"], ["84343.93", "0"], ["84345.04", "0.000296"], ["84345.05", "0"], ["84348.42", "0"], ["84349.18", "0"], ["84349.9", "0"], ["84351.28", "0"], ["84351.41", "0"], ["84351.6", "0.044"], ["84351.9", "0.06"], ["84352.58", "0"], ["84353.19", "0.054201"], ["84353.69", "0.011856"], ["84354.25", "0.020995"], ["84354.8", "0.04"], ["84355.1", "0"], ["84355.19", "0"], ["84355.7", "0.068"], ["84355.85", "0"], ["84355.86", "0.232347"], ["84356.36", "0.083978"], ["84356.43", "0"], ["84356.58", "0"], ["84356.85", "0"], ["84356.9", "0.068"], ["84357.22", "0"], ["84357.73", "0"], ["84358.5", "0.048"], ["84358.7", "0.048"], ["84358.93", "0"], ["84358.99", "0.068395"], ["84359.23", "0.105803"], ["84359.33", "0"], ["84359.57", "0"], ["84359.74", "0.106015"], ["84359.8", "0"], ["84360", "0.118456"], ["84360.2", "0.056"], ["84362.38", "0.119865"], ["84362.63", "0.000988"], ["84364.37", "0"], ["84364.41", "0.150149"], ["84364.5", "0"], ["84366.3", "0"], ["84366.34", "0.017784"], ["84366.5", "0"], ["84367.74", "0"], ["84367.91", "0.171738"], ["84368.64", "0.072983"], ["84370.54", "0.166587"], ["84370.66", "0.170495"], ["84370.9", "0"], ["84371.14", "0.023714"], ["84372.77", "0"], ["84376.07", "0.265666"], ["84376.26", "0.03181"], ["84377.22", "0"], ["84378.88", "0"], ["84379.85", "0"], ["84379.86", "0"], ["84385.49", "0"], ["84385.94", "0.04"], ["84385.95", "0.04"], ["84387.67", "0.002028"], ["84387.9", "0.027942"], ["84388.47", "0"], ["84388.6", "0.000235"], ["84388.87", "0.001"], ["84388.89", "0.000612"], ["84388.93", "0.001333"], ["84389.12", "0.000235"], ["84389.42", "0.0045"], ["84389.45", "0.0045"], ["84389.62", "0.0045"], ["84389.65", "0.0047"], ["84390.05", "0.000089"], ["84390.63", "0.071103"]], "u": 7510739, "seq": 66889386571}, "cts": 1742142243807, "record_time": 1742142242.909116}
{"topic": "orderbook.200.BTCUSDT", "ts": 1742142244009, "type": "delta", "data": {"s": "BTCUSDT", "b": [["84342.52", "0.25917"], ["84342.48", "0.00237"], ["84341.98", "0.031111"], ["84341.96", "0.0315"], ["84340.87", "0.071145"], ["84339.97", "0.000857"], ["84339.96", "0"], ["84339.04", "0"], ["84339.03", "0.0002"], ["84339.02", "0"], ["84338.27", "0.000613"], ["84338.21", "0"], ["84337.56", "0.000234"], ["84336.29", "0.14362"], ["84336.28", "0.237146"], ["84335.33", "0.001467"], ["84335.17", "0"], ["84334.73", "0.23715"], ["84334.66", "0"], ["84333.53", "0.049115"], ["84333.05", "0.237155"], ["84332.26", "0.0002"], ["84331.56", "0"], ["84331.52", "0.162"], ["84331.14", "0.011855"], ["84330.72", "0.237128"], ["84330.53", "0.117966"], ["84330.4", "0.041453"], ["84330.13", "0.116635"], ["84329.84", "0.000613"], ["84329.54", "0"], ["84328.27", "0"], ["84328.16", "0"], ["84327.94", "0.237376"], ["84327.49", "0"], ["84327.27", "0"], ["84326.51", "0.237128"], ["84326.33", "0"], ["84325.62", "0.000613"], ["84325.61", "0"], ["84325.1", "0.04"], ["84324.14", "0.170584"], ["84323.85", "0.0002"], ["84323.72", "0.237128"], ["84322.29", "0"], ["84321.99", "0.159126"], ["84321.38", "0.341003"], ["84321.37", "0"], ["84320.8", "0.003"], ["84319.11", "0"], ["84318.7", "0.04"], ["84318.49", "0.017783"], ["84318.4", "0.043"], ["84318.18", "0"], ["84318.08", "0"], ["84317.45", "0.023712"], ["84315.41", "0.009062"], ["84313.97", "0.177852"], ["84313.85", "0.264625"], ["84313.68", "0"], ["84312.6", "0"], ["84312.3", "0"], ["84311.08", "0.177846"], ["84310.02", "0"], ["84304.14", "0"], ["84296.77", "0"], ["84294.26", "0.0012"], ["84294.23", "0"], ["84293.95", "0.237265"], ["84292.88", "0.045361"], ["84292.57", "0"], ["84292.44", "0.355725"], ["84290.02", "0.177846"], ["84288.75", "0"], ["84288.7", "0"], ["84288.44", "0"], ["84288.29", "0"], ["84287.72", "0"], ["84287.68", "0"], ["84287.34", "0"], ["84287.07", "0"], ["84286.55", "0"], ["84286.32", "0"], ["84285.92", "0"], ["84285.75", "0"]], "a": [["84339.97", "0"], ["84340.88", "0"], ["84341.56", "0"], ["84342.2", "0"], ["84342.49", "0"], ["84342.53", "0.002518"], ["84345.04", "0"], ["84348.79", "0.071138"], ["84351.35", "0"], ["84351.6", "0"], ["84351.9", "0"], ["84353.19", "0"], ["84353.2", "0"], ["84354.52", "0"], ["84354.8", "0"], ["84355.7", "0"], ["84355.85", "0.000296"], ["84355.86", "0.089433"], ["84356.9", "0"], ["84357.6", "0"], ["84358.5", "0"], ["84358.7", "0"], ["84359.23", "0"], ["84359.74", "0"], ["84360", "0.0006"], ["84360.12", "0.139862"], ["84360.2", "0"], ["84360.87", "0"], ["84360.9", "0.06"], ["84361.22", "0"], ["84362.38", "0"], ["84362.4", "0.117965"], ["84362.53", "0"], ["84363.62", "0.001333"], ["84363.8", "0"], ["84364.41", "0.071027"], ["84365.13", "0.105801"], ["84365.6", "0.068"], ["84367.36", "0.023712"], ["84367.4", "0.048"], ["84367.6", "0.048"], ["84367.9", "0.059948"], ["84367.91", "0"], ["84368.06", "0.023047"], ["84368.64", "0.163716"], ["84368.65", "0"], ["84370.54", "0"], ["84370.66", "0"], ["84372.77", "0.118574"], ["84372.78", "0.679732"], ["84373.27", "0.164347"], ["84373.28", "0.168974"], ["84373.32", "0.003492"], ["84374.29", "0.237128"], ["84375.33", "0"], ["84376.07", "0"], ["84377.06", "0.237128"], ["84377.22", "0.23713"], ["84378.5", "0.237128"], ["84379.97", "0.0013"], ["84381.28", "0.237128"], ["84381.41", "0.274236"], ["84381.43", "0.23713"], ["84382.45", "0.07111"], ["84385.94", "0"], ["84385.95", "0"], ["84386.73", "0.04"], ["84386.84", "0.04"], ["84390.3", "0.001235"], ["84390.84", "0.000253"], ["84391", "0.027646"], ["84391.01", "0.001467"], ["84391.17", "0.059948"], ["84391.36", "0.35236"], ["84391.63", "0.000158"]], "u": 7510740, "seq": 66889387821}, "cts": 1742142244006, "record_time": 1742142243.109031}
{"success": true, "ret_msg": "pong", "conn_id": "66eef079-b2bf-427b-aa45-7a2115dcff7c", "op": "ping", "record_time": 1742142243.170054}
{"topic": "orderbook.200.BTCUSDT", "ts": 1742142244210, "type": "delta", "data": {"s": "BTCUSDT", "b": [["84361.8", "0.171777"], ["84361.51", "0.045248"], ["84360.37", "0.005"], ["84358.98", "0.136904"], ["84356.64", "0.000234"], ["84356.12", "0.000234"], ["84354.11", "0.026977"], ["84354.1", "0.089922"], ["84353.37", "0.049115"], ["84353.35", "0.000089"], ["84350.67", "0.036255"], ["84350.66", "0.059948"], ["84349.45", "0.068395"], ["84348.08", "0.008453"], ["84346.91", "0.011853"], ["84344.9", "0.000089"], ["84343.6", "0.015741"], ["84343.24", "0.0486"], ["84343.23", "0.162"], ["84342.53", "0.162219"], ["84342.52", "0.317713"], ["84342.49", "0.000613"], ["84342.48", "0"], ["84342.2", "0.000234"], ["84341.99", "0.059948"], ["84341.98", "0"], ["84341.96", "0"], ["84341.56", "0.0002"], ["84341.5", "0.062965"], ["84341.1", "0.04"], ["84340.87", "0"], ["84340", "0.0006"], ["84339.97", "0.002324"], ["84339.8", "0.000252"], ["84339.1", "0.04"], ["84338.88", "0.000099"], ["84338.31", "0.001333"], ["84338.3", "0"], ["84338.08", "0.000234"], ["84337.47", "0"], ["84336.94", "0.009541"], ["84336.45", "0.000089"], ["84336.29", "0"], ["84336.28", "0"], ["84335.32", "0"], ["84335.1", "0.000817"], ["84334.73", "0"], ["84334.12", "0.01778"], ["84334.09", "0"], ["84333.87", "0"], ["84333.53", "0"], ["84333.07", "0.000248"], ["84333.05", "0"], ["84332.82", "0.019095"], ["84332.46", "0.000357"], ["84331.14", "0"], ["84330.72", "0.023708"], ["84330.65", "0.089922"], ["84330.58", "0.13986"], ["84330.53", "0.000252"], ["84330.4", "0.213613"], ["84330.13", "0"], ["84329.28", "0"], ["84328.63", "0.005926"], ["84327.95", "0.237128"], ["84327.94", "0"], ["84327.17", "0"], ["84326.51", "0"], ["84326.07", "0.068395"], ["84325.5", "0.04"], ["84324.14", "0"], ["84323.72", "0"], ["84323.4", "0.04"], ["84321.99", "0"], ["84321.38", "0"], ["84320.1", "0.04"], ["84320.02", "0"], ["84319.5", "0"], ["84319", "0"], ["84318.7", "0.057765"], ["84318.49", "0"], ["84318.31", "0"], ["84318.08", "0.355635"], ["84317.45", "0"], ["84317.3", "0"], ["84315.66", "0"], ["84315.62", "0"], ["84314", "0"], ["84313.97", "0"], ["84313.85", "0"], ["84312.39", "0.071169"], ["84311.08", "0"], ["84311.02", "0.023707"], ["84310.54", "0.071171"], ["84310.38", "0"], ["84309.63", "0"], ["84308.76", "0.000613"], ["84307.68", "0.004654"], ["84307.58", "0"], ["84306.72", "0"], ["84306.23", "0.02371"], ["84304.5", "0.24702"], ["84303.94", "0.005927"], ["84302.16", "0"], ["84302.07", "0"], ["84301.31", "0"], ["84300.26", "0.02371"], ["84299.45", "0.023707"], ["84297.46", "0"], ["84295.95", "0.352306"], ["84294.45", "0.023707"], ["84294.44", "0"], ["84294.14", "0.013963"], ["84293.95", "0"], ["84293.5", "0"], ["84292.88", "0"], ["84292.44", "0"], ["84292.38", "0"], ["84291.19", "0"], ["84290.97", "0"], ["84290.6", "0"], ["84290.59", "0"], ["84290.22", "0"], ["84290.02", "0"], ["84289.36", "0"], ["84288.96", "0"], ["84288.79", "0"]], "a": [["84342.53", "0"], ["84342.72", "0"], ["84344.09", "0"], ["84344.44", "0"], ["84344.61", "0"], ["84346.23", "0"], ["84346.62", "0"], ["84346.7", "0"], ["84346.75", "0"], ["84346.84", "0"], ["84347.03", "0"], ["84347.36", "0"], ["84347.5", "0"], ["84348.79", "0"], ["84349.08", "0"], ["84349.15", "0"], ["84349.25", "0"], ["84350", "0"], ["84350.92", "0"], ["84350.96", "0"], ["84351.36", "0"], ["84351.48", "0"], ["84351.68", "0"], ["84352", "0"], ["84353.69", "0"], ["84353.72", "0"], ["84353.89", "0"], ["84354.21", "0"], ["84354.25", "0"], ["84354.92", "0"], ["84355.14", "0"], ["84355.18", "0"], ["84355.85", "0"], ["84355.86", "0"], ["84356.01", "0"], ["84356.12", "0"], ["84356.36", "0"], ["84356.64", "0"], ["84356.74", "0"], ["84357.02", "0"], ["84358.07", "0"], ["84358.36", "0"], ["84358.53", "0"], ["84358.72", "0"], ["84358.99", "0"], ["84359.27", "0"], ["84359.29", "0"], ["84359.36", "0"], ["84359.4", "0"], ["84359.55", "0"], ["84360", "0"], ["84360.12", "0"], ["84360.49", "0"], ["84360.55", "0"], ["84360.73", "0"], ["84360.76", "0"], ["84360.9", "0"], ["84361.28", "0"], ["84361.5", "0"], ["84361.81", "0.037618"], ["84362.26", "0"], ["84362.4", "0"], ["84364.38", "0"], ["84364.41", "0"], ["84364.52", "0"], ["84364.8", "0"], ["84365.13", "0"], ["84365.17", "0"], ["84365.37", "0"], ["84365.6", "0"], ["84366.34", "0"], ["84367.36", "0"], ["84367.4", "0"], ["84367.6", "0"], ["84367.9", "0"], ["84368.06", "0"], ["84368.32", "0"], ["84368.64", "0"], ["84369.01", "0"], ["84369.12", "0"], ["84369.37", "0.012401"], ["84369.38", "0.011852"], ["84370.41", "0"], ["84371.14", "0"], ["84371.18", "0.011853"], ["84371.41", "0"], ["84372.77", "0"], ["84372.78", "0"], ["84372.79", "0"], ["84373.03", "0"], ["84373.15", "0"], ["84373.27", "0"], ["84373.28", "0"], ["84373.32", "0"], ["84373.96", "0"], ["84374.21", "0.022279"], ["84374.29", "0"], ["84375.41", "0"], ["84375.72", "0"], ["84376.21", "0"], ["84376.26", "0"], ["84376.8", "0.044"], ["84376.9", "0"], ["84376.91", "0"], ["84377.06", "0"], ["84377.09", "0.001467"], ["84377.22", "0"], ["84378.15", "0"], ["84378.4", "0.06"], ["84378.5", "0"], ["84380.34", "0"], ["84380.61", "0.023708"], ["84380.63", "0.107918"], ["84380.64", "0"], ["84381.28", "0"], ["84381.4", "0"], ["84381.41", "0"], ["84381.43", "0"], ["84381.62", "0"], ["84382.18", "0"], ["84382.33", "0.005"], ["84382.45", "0"], ["84382.75", "0.000789"], ["84383.58", "0"], ["84383.87", "0.023707"], ["84384.52", "0.01778"], ["84385.53", "0"], ["84385.55", "0"], ["84385.88", "0"], ["84386.27", "0.00459"], ["84386.73", "0"], ["84386.82", "0.162"], ["84386.84", "0"], ["84387.9", "0"], ["84388.04", "0.009462"], ["84388.72", "0.023707"], ["84389.87", "0.237074"], ["84390.33", "0.13986"], ["84390.37", "0.023707"], ["84390.63", "0"], ["84391.17", "0"], ["84391.36", "0"], ["84391.44", "0.068395"], ["84391.62", "0.297076"], ["84391.96", "0.019104"], ["84392.18", "0.0002"], ["84392.38", "0.009"], ["84392.58", "0.009"], ["84393.11", "0.000612"], ["84393.15", "0.001333"], ["84393.24", "0.000235"], ["84393.76", "0.000235"], ["84394", "0.009"], ["84394.08", "0.260781"], ["84394.2", "0.009"], ["84394.71", "0.0002"], ["84394.78", "0.001729"], ["84395.48", "0.000253"], ["84395.53", "0.013859"], ["84395.64", "0.023707"], ["84395.65", "0.001467"], ["84396.06", "0.005926"], ["84397.24", "0.0002"], ["84397.33", "0.000612"], ["84397.37", "0.001333"], ["84397.43", "0.323031"], ["84397.88", "0.000235"], ["84398.41", "0.000235"], ["84398.49", "0.237128"], ["84398.56", "0.000089"], ["84399.1", "0.071096"], ["84399.78", "0.0002"], ["84400", "0.003584"], ["84400.13", "0.000253"], ["84400.29", "0.001467"], ["84400.4", "0.246059"], ["84401.54", "0.000612"], ["84401.59", "0.001333"], ["84401.74", "0.04"], ["84401.75", "0.04"], ["84402.29", "0.000335"], ["84402.31", "0.0002"], ["84402.36", "0.008453"], ["84402.52", "0.000235"], ["84403.05", "0.000235"], ["84403.15", "0.001243"], ["84403.56", "0.237128"], ["84403.99", "0.024533"], ["84404.31", "0.074328"], ["84404.77", "0.000253"], ["84404.8", "0.006093"], ["84404.84", "0.0002"], ["84404.93", "0.001467"], ["84405.77", "0.000612"], ["84405.81", "0.001333"], ["84406.3", "0.0006"], ["84406.44", "0.00006"], ["84406.54", "0.059245"], ["84406.86", "0.071089"], ["84407.07", "0.000089"], ["84407.17", "0.000235"], ["84407.37", "0.0002"], ["84407.59", "0.028861"], ["84407.69", "0.000235"], ["84408.02", "0.059948"], ["84408.65", "0.237128"], ["84409.41", "0.000253"], ["84409.58", "0.001467"], ["84409.9", "0.0002"], ["84409.96", "0.000085"], ["84409.99", "0.000612"], ["84410.03", "0.001333"], ["84411.81", "0.000235"], ["84412.33", "0.000235"], ["84413", "0.008527"], ["84413.05", "0.00089"], ["84413.94", "0.11863"], ["84414.05", "0.000253"], ["84414.21", "0.000612"], ["84414.22", "0.001467"], ["84414.25", "0.001333"], ["84414.32", "0.002199"], ["84414.48", "0.002853"], ["84414.86", "0.015"], ["84415.58", "0.000089"], ["84416.45", "0.000235"], ["84416.97", "0.005"], ["84416.98", "0.000324"], ["84418.43", "0.000612"], ["84418.47", "0.001333"], ["84418.69", "0.000253"], ["84418.79", "0.000111"], ["84418.86", "0.001467"], ["84419.9", "0.088"], ["84420.2", "0.06"], ["84421.09", "0.000235"], ["84421.62", "0.000235"], ["84421.8", "0.04"], ["84421.86", "0.285419"], ["84422.65", "0.000612"], ["84422.69", "0.001333"], ["84423.34", "0.000253"], ["84423.51", "0.001467"], ["84423.7", "0.06"]], "u": 7510741, "seq": 66889389934}, "cts": 1742142244208, "record_time": 1742142243.310508}
{"topic": "orderbook.200.BTCUSDT", "ts": 1742142244409, "type": "delta", "data": {"s": "BTCUSDT", "b": [["84361.8", "0.111372"], ["84361.51", "0"], ["84358.99", "0.041212"], ["84358.78", "0.00109"], ["84356.74", "0.0002"], ["84355.06", "0.007807"], ["84354.21", "0.0002"], ["84354.11", "0.014821"], ["84354.1", "0"], ["84353.62", "0.000153"], ["84352.75", "0.071135"], ["84351.68", "0.0002"], ["84350.67", "0.059904"], ["84349.15", "0.0002"], ["84348.08", "0"], ["84346.91", "0"], ["84346.62", "0.0002"], ["84344.09", "0.0002"], ["84343.37", "0.119722"], ["84343.36", "0.237074"], ["84343.24", "0"], ["84343.2", "0.001243"], ["84342.8", "0.04"], ["84342.53", "0.267301"], ["84342.52", "0.186858"], ["84342.5", "0.04"], ["84341.23", "0.118537"], ["84341.12", "0.003"], ["84340.92", "0.003"], ["84340.9", "0.008453"], ["84340.8", "0.04"], ["84340.72", "0.003"], ["84339.15", "0.237074"], ["84338.88", "0"], ["84338.08", "0.000482"], ["84337.5", "0.04"], ["84336.1", "0.04"], ["84335.7", "0.04"], ["84334.12", "0"], ["84333.08", "0.237128"], ["84333.07", "0"], ["84331.53", "0.125223"], ["84330.72", "0.139859"], ["84330.58", "0"], ["84330.4", "0.041453"], ["84326.07", "0"], ["84325.1", "0"], ["84320.11", "0.231569"], ["84318.7", "0.017765"], ["84318.4", "0"], ["84318.08", "0"], ["84317.73", "0"], ["84317.7", "0"], ["84317.53", "0"], ["84317.33", "0"], ["84316.19", "0"], ["84315.99", "0"], ["84315.96", "0.039765"], ["84315.6", "0"], ["84315.41", "0"], ["84311.52", "0.000988"], ["84311.08", "0.237074"], ["84310.54", "0"], ["84308.2", "0.24702"], ["84308.15", "0.071173"], ["84307.6", "0"], ["84306.87", "0.237074"], ["84304.51", "0.355677"], ["84304.5", "0"], ["84295.25", "0"], ["84294.13", "0"], ["84294", "0"], ["84293.99", "0"], ["84293.59", "0"], ["84293.43", "0"], ["84292.43", "0"], ["84292.42", "0"], ["84292.35", "0"], ["84291.94", "0"], ["84291.9", "0"], ["84291.71", "0"]], "a": [["84361.81", "0.028611"], ["84362.63", "0"], ["84362.64", "0.011853"], ["84363.36", "0.071126"], ["84366.02", "0.011853"], ["84366.86", "0.01532"], ["84367.64", "0.008216"], ["84369.37", "0"], ["84369.96", "0.035359"], ["84369.97", "0.020086"], ["84372.08", "0.080345"], ["84373.03", "0.000089"], ["84374.21", "0"], ["84376.8", "0"], ["84378.1", "0.04"], ["84378.4", "0"], ["84379.47", "0.023366"], ["84379.7", "0.06"], ["84379.8", "0.068"], ["84379.9", "0.04"], ["84380.61", "0"], ["84380.63", "0"], ["84382.33", "0"], ["84382.81", "0.005"], ["84383.68", "0.068395"], ["84384.52", "0"], ["84385.3", "0.056"], ["84385.42", "0.000988"], ["84387.03", "0.005"], ["84388.5", "0.048"], ["84388.87", "0"], ["84388.89", "1.437687"], ["84389.2", "0.048"], ["84389.7", "0.237074"], ["84391.44", "0"], ["84392.58", "0.0045"], ["84393.91", "0.237074"], ["84394", "0.0045"], ["84394.2", "0.0045"], ["84395.26", "0.162"], ["84397.42", "0.355677"], ["84398.29", "0.039765"], ["84398.42", "0.02024"], ["84399.48", "0.002063"], ["84401.74", "0"], ["84401.75", "0"], ["84401.93", "0.366647"], ["84402.04", "0.04"], ["84402.05", "0.04"], ["84402.33", "0.008453"], ["84402.36", "0"], ["84403.7", "0.162"], ["84409.11", "0.430766"], ["84412.14", "0.162"], ["84412.28", "0.03181"], ["84414.86", "0"], ["84415.58", "0"], ["84416.45", "0"], ["84416.97", "0"], ["84416.98", "0"], ["84418.43", "0"], ["84418.47", "0"], ["84418.69", "0"], ["84418.79", "0"], ["84418.86", "0"], ["84419.9", "0"], ["84420.2", "0"], ["84421.09", "0"], ["84421.62", "0"], ["84421.8", "0"], ["84421.86", "0"], ["84422.65", "0"], ["84422.69", "0"], ["84423.34", "0"], ["84423.51", "0"], ["84423.7", "0"]], "u": 7510742, "seq": 66889390605}, "cts": 1742142244408, "record_time": 1742142243.50908}
{"topic": "orderbook.200.BTCUSDT", "ts": 1742142244609, "type": "delta", "data": {"s": "BTCUSDT", "b": [["84369.37", "0.255373"], ["84366.84", "0.00118"], ["84366.03", "0.021198"], ["84364.04", "0.00096"], ["84361.8", "0.004065"], ["84361.28", "0.000234"], ["84360.97", "0.011853"], ["84360.76", "0.000234"], ["84359.4", "0.001333"], ["84359.36", "0.000613"], ["84359.27", "0.0002"], ["84358.53", "0.001467"], ["84358.36", "0.000252"], ["84358.16", "0.000099"], ["84357.59", "0.011854"], ["84355.18", "0.001333"], ["84355.14", "0.000613"], ["84355.06", "0.011854"], ["84354.11", "0"], ["84353.89", "0.001467"], ["84353.72", "0.000252"], ["84353.62", "0"], ["84353.37", "0"], ["84353.36", "0.162"], ["84352.75", "0"], ["84352", "0.000234"], ["84351.48", "0.000234"], ["84351.15", "0.011495"], ["84350.96", "0.001333"], ["84350.92", "0.000613"], ["84350.75", "0.089922"], ["84350.67", "0.018044"], ["84350.66", "0"], ["84349.46", "0.068395"], ["84349.45", "0"], ["84349.25", "0.001467"], ["84349.08", "0.000252"], ["84347.36", "0.000234"], ["84346.84", "0.000234"], ["84346.75", "0.001333"], ["84346.7", "0.000613"], ["84345.88", "0.062959"], ["84344.61", "0.001467"], ["84344.44", "0.000252"], ["84343.6", "0"], ["84343.37", "0"], ["84343.36", "0"], ["84342.72", "0.000234"], ["84342.54", "0.000248"], ["84342.53", "0.268634"], ["84342.52", "0.162"], ["84341.99", "0"], ["84341.5", "0"], ["84341.23", "0"], ["84339.15", "0"], ["84338.08", "0.000234"], ["84337.26", "0.000817"], ["84336.83", "0.008676"], ["84335.48", "0.07115"], ["84335.1", "0"], ["84332.32", "0.023705"], ["84329.66", "0.017796"], ["84329.42", "0.023018"], ["84327.96", "0.355586"], ["84327.88", "0.071156"], ["84326.89", "0.023822"], ["84326.07", "0.068395"], ["84325.5", "0"], ["84323.4", "0"], ["84323.1", "0.023705"], ["84322.29", "0.17779"], ["84320.81", "0.005926"], ["84320.11", "0"], ["84320.1", "0"], ["84317.13", "0.023705"], ["84316.32", "0.023705"], ["84315.96", "0"], ["84312.39", "0"], ["84311.32", "0.023705"], ["84311.08", "0"], ["84308.2", "0"], ["84308.15", "0"], ["84306.87", "0"], ["84306.17", "0.059188"], ["84305.83", "1.436974"], ["84304.51", "0"], ["84302.87", "0"], ["84302.7", "0"], ["84302.65", "0"], ["84302.44", "0"], ["84302.43", "0"], ["84302.13", "0"], ["84301.85", "0"], ["84301.09", "0"], ["84300.98", "0"], ["84300.46", "0"], ["84300.37", "0"], ["84300.33", "0"], ["84300.26", "0"], ["84299.6", "0"], ["84299.45", "0"], ["84298.56", "0"], ["84298.23", "0"], ["84298.06", "0"], ["84296.76", "0"], ["84296.35", "0"], ["84296.15", "0"], ["84296.11", "0"], ["84296.03", "0"], ["84295.95", "0"], ["84295.82", "0"], ["84294.45", "0"], ["84294.26", "0"], ["84294.2", "0"], ["84294.15", "0"], ["84294.14", "0"]], "a": [["84361.81", "0"], ["84362.64", "0"], ["84363", "0"], ["84363.17", "0"], ["84363.36", "0"], ["84363.54", "0"], ["84363.57", "0"], ["84363.62", "0"], ["84364.34", "0"], ["84365.4", "0"], ["84365.92", "0"], ["84366.02", "0"], ["84366.86", "0"], ["84366.87", "0"], ["84366.97", "0"], ["84367.64", "0"], ["84367.79", "0"], ["84367.81", "0"], ["84367.84", "0"], ["84368.02", "0"], ["84369.38", "0.005"], ["84369.96", "0"], ["84369.97", "0"], ["84371.18", "0"], ["84372.08", "0"], ["84373.03", "0"], ["84375.5", "0"], ["84376.22", "0.059948"], ["84376.99", "0.008989"], ["84377.37", "0.080347"], ["84378.1", "0"], ["84379.47", "0"], ["84379.7", "0"], ["84379.8", "0"], ["84379.9", "0"], ["84382.81", "0"], ["84383.68", "0"], ["84383.79", "0.023739"], ["84383.87", "0"], ["84384.97", "0.005926"], ["84385.3", "0"], ["84385.69", "0.071107"], ["84386.26", "0.059948"], ["84386.54", "0.011495"], ["84386.82", "0"], ["84387.03", "0"], ["84388.5", "0"], ["84388.72", "0"], ["84388.88", "0.448877"], ["84389.69", "0.300187"], ["84389.7", "0"], ["84389.87", "0"], ["84390.3", "0"], ["84390.33", "0"], ["84390.37", "0"], ["84391.38", "0.068395"], ["84391.62", "0"], ["84392.09", "0.005"], ["84393.49", "0.118526"], ["84393.91", "0"], ["84394.07", "0.346583"], ["84394.08", "0"], ["84395.64", "0"], ["84396.06", "0"], ["84396.43", "0.017796"], ["84397.41", "0.297076"], ["84397.42", "0"], ["84398.29", "0.022723"], ["84398.49", "0"], ["84398.93", "0.059361"], ["84399.1", "0"], ["84399.48", "0.025768"], ["84400", "0.005294"], ["84400.53", "0.023705"], ["84402.04", "0"], ["84402.05", "0"], ["84402.33", "0"], ["84404.31", "0"], ["84405.54", "0.023705"], ["84405.86", "0.001237"], ["84406.54", "0"], ["84406.86", "0"], ["84408.94", "0.023705"], ["84411.92", "0.005926"], ["84412.26", "0.04"], ["84412.27", "0.04"], ["84412.28", "0"], ["84412.31", "0.023705"], ["84412.44", "0.0002"], ["84414.86", "0.015"], ["84414.97", "0.0002"], ["84415.03", "0.001"], ["84415.58", "0.000089"], ["84415.84", "0.009"], ["84416.04", "0.009"], ["84416.45", "0.000235"], ["84416.97", "0.005"], ["84416.98", "0.000324"], ["84417.5", "0.0002"], ["84418.43", "0.000612"], ["84418.47", "0.001333"], ["84418.69", "0.000253"], ["84418.79", "0.000111"], ["84418.86", "0.001467"], ["84419.77", "0.03181"], ["84420.98", "0.071078"], ["84421.09", "0.000235"], ["84421.62", "0.000235"], ["84422.65", "0.000612"], ["84422.69", "0.001333"], ["84423.34", "0.000253"], ["84423.51", "0.001467"], ["84423.7", "0.06"], ["84423.9", "0.352306"], ["84424.06", "0.11863"], ["84424.09", "0.000089"], ["84424.4", "0.000335"], ["84424.88", "0.059948"], ["84424.97", "0.017796"], ["84425.74", "0.000235"], ["84426.26", "0.000235"], ["84426.87", "0.000612"], ["84426.91", "0.001333"]], "u": 7510743, "seq": 66889392541}, "cts": 1742142244607, "record_time": 1742142243.709523}
{"topic": "orderbook.200.BTCUSDT", "ts": 1742142244809, "type": "delta", "data": {"s": "BTCUSDT", "b": [["84369.37", "0.031585"], ["84366.03", "0"], ["84361.84", "0.000296"], ["84361.83", "0.037713"], ["84361.82", "0.057204"], ["84361.81", "0.037813"], ["84361.22", "0.071128"], ["84360.97", "0"], ["84360.94", "0.04906"], ["84358.16", "0"], ["84357.59", "0"], ["84355.06", "0"], ["84353.36", "0"], ["84353", "0.015737"], ["84351.92", "0.112337"], ["84351.15", "0"], ["84350.91", "0.045164"], ["84350.9", "0.102953"], ["84350.75", "0"], ["84350.67", "0"], ["84349.22", "0.105587"], ["84349.2", "0.04"], ["84348.9", "0.04"], ["84347.57", "0.237053"], ["84347.2", "0.04"], ["84346.84", "0.000482"], ["84345.9", "0.000296"], ["84345.89", "0.080463"], ["84345.88", "0"], ["84345.79", "0.011559"], ["84345.6", "0.04"], ["84345.43", "0.118526"], ["84344.15", "0.000817"], ["84343.62", "0.163941"], ["84343.36", "0.237053"], ["84342.81", "0.059948"], ["84342.8", "0"], ["84342.54", "0"], ["84342.53", "0.106415"], ["84340.92", "0.181072"], ["84340.9", "0"], ["84340.8", "0"], ["84338.04", "0.008453"], ["84337.5", "0"], ["84337.26", "0"], ["84335.48", "0"], ["84335.31", "0.271888"], ["84333.08", "0"], ["84332.61", "0.27636"], ["84332.46", "0"], ["84331.59", "0.323283"], ["84327.96", "0"], ["84327.95", "0"], ["84327.88", "0"], ["84324.58", "0.017304"], ["84324.52", "0.000357"], ["84324.24", "0.000335"], ["84323.56", "0.07116"], ["84323.3", "0"], ["84323.08", "0.004655"], ["84322.29", "0"], ["84319.55", "0.000089"], ["84319.09", "0.000988"], ["84318.07", "0"], ["84316.97", "0.005"], ["84316.11", "0.355637"], ["84315.38", "0.071167"], ["84314.94", "0.059501"], ["84314.5", "0.24702"], ["84312.97", "0.000613"], ["84312.71", "0"], ["84311.52", "0"], ["84311.08", "0.237053"], ["84309.53", "0.013965"], ["84307.68", "0"], ["84306.23", "0"], ["84306.17", "0"], ["84306.15", "0"], ["84305.83", "0"], ["84305.62", "0"], ["84305.17", "0"], ["84305.14", "0"], ["84305.1", "0"], ["84304.59", "0"], ["84304.54", "0"], ["84304.18", "0"], ["84303.94", "0"], ["84303.62", "0"]], "a": [["84369.38", "0.076845"], ["84370.11", "0.07112"], ["84370.21", "0.011852"], ["84373.59", "0.011852"], ["84374.43", "0.077815"], ["84374.44", "0.237128"], ["84376.12", "0.008111"], ["84376.22", "0"], ["84376.99", "0.0002"], ["84377.36", "0.09522"], ["84378.19", "0.020086"], ["84379.58", "0.237128"], ["84381.03", "0.011559"], ["84382.64", "0.113609"], ["84382.75", "0"], ["84383.79", "0"], ["84384.93", "0.117634"], ["84385.42", "0"], ["84385.69", "0"], ["84386.2", "0.040253"], ["84386.26", "0.162"], ["84386.27", "0"], ["84386.54", "0"], ["84387.3", "0.044"], ["84388.87", "0.297076"], ["84388.89", "0.000612"], ["84389.4", "0.06"], ["84389.41", "0.02428"], ["84389.69", "0.076955"], ["84390.95", "0.165196"], ["84391.38", "0"], ["84391.7", "0.056"], ["84392.47", "0.139857"], ["84392.82", "0.000789"], ["84392.99", "0.000988"], ["84393.23", "0.178226"], ["84393.49", "0"], ["84393.91", "0.237053"], ["84394.06", "0.237128"], ["84394.07", "0"], ["84395.53", "0"], ["84396.45", "0.068395"], ["84397.41", "0.059948"], ["84397.43", "0"], ["84398.13", "0.237053"], ["84399.25", "0.274638"], ["84399.86", "0.004663"], ["84400.4", "0"], ["84400.57", "1.445486"], ["84401.53", "0.293343"], ["84404.74", "0.03181"], ["84404.81", "0.071091"], ["84405.86", "0.018541"], ["84411.19", "0.014018"], ["84412.13", "0.355641"], ["84412.22", "0.071085"], ["84412.26", "0"], ["84412.27", "0"], ["84413.06", "0.04"], ["84413.07", "0.04"], ["84415.02", "0.027942"], ["84418.47", "0"], ["84418.69", "0"], ["84418.79", "0"], ["84418.86", "0"], ["84419.77", "0"], ["84420.98", "0"], ["84421.09", "0"], ["84421.62", "0"], ["84422.65", "0"], ["84422.69", "0"], ["84423.34", "0"], ["84423.51", "0"], ["84423.7", "0"], ["84423.9", "0"], ["84424.06", "0"], ["84424.09", "0"], ["84424.4", "0"], ["84424.88", "0"], ["84424.97", "0"], ["84425.74", "0"], ["84426.26", "0"], ["84426.87", "0"], ["84426.91", "0"]], "u": 7510744, "seq": 66889393335}, "cts": 1742142244806, "record_time": 1742142243.909103}
{"topic": "orderbook.200.BTCUSDT", "ts": 1742142245009, "type": "delta", "data": {"s": "BTCUSDT", "b": [["84365.73", "0.000099"], ["84364.34", "0.0002"], ["84362.66", "0.033567"], ["84362.65", "0.037946"], ["84362.64", "0.033667"], ["84361.84", "0"], ["84361.83", "0"], ["84361.82", "0"], ["84361.81", "0.0002"], ["84361.8", "0.003665"], ["84361.22", "0"], ["84358.99", "0.058302"], ["84357.72", "0.071131"], ["84357.71", "0.000153"], ["84351.92", "0"], ["84351.03", "0.114111"], ["84350.92", "0.000909"], ["84350.91", "0.064661"], ["84350.6", "0.04"], ["84349.46", "0"], ["84349.22", "0"], ["84348.67", "0.003"], ["84348.47", "0.003"], ["84348.27", "0.003"], ["84347.57", "0"], ["84347.36", "0.000482"], ["84346.84", "0.000234"], ["84345.9", "0"], ["84345.79", "0"], ["84345.43", "0"], ["84343.9", "0.04"], ["84343.8", "0.04"], ["84343.62", "0"], ["84343.36", "0"], ["84342.72", "0.171442"], ["84342.5", "0"], ["84341.58", "0.068395"], ["84341.1", "0"], ["84340.92", "0.003"], ["84340.79", "0.011647"], ["84340.06", "0.170142"], ["84339.93", "0.118526"], ["84339.1", "0"], ["84336.1", "0"], ["84335.7", "0"], ["84335.31", "0"], ["84334.42", "0.302317"], ["84332.61", "0"], ["84326.07", "0"], ["84324.58", "0"], ["84324.02", "1.43126"], ["84320.32", "0.017417"], ["84316.11", "0"], ["84307.6", "0.355672"], ["84306.87", "0.237053"]], "a": [["84370.04", "0.029306"], ["84370.1", "0.026495"], ["84375.75", "0.011647"], ["84377.36", "0.141212"], ["84379.57", "0.059948"], ["84380.93", "0.089922"], ["84381.03", "0"], ["84381.04", "0.079354"], ["84381.75", "0.115755"], ["84382.64", "0"], ["84382.8", "0.04"], ["84384.07", "0.119324"], ["84384.8", "0.056"], ["84384.93", "0"], ["84385.55", "0.059263"], ["84386.1", "0.06"], ["84386.54", "0.03181"], ["84387.72", "0.005"], ["84388.01", "0.068395"], ["84388.15", "0.139855"], ["84388.88", "0"], ["84390.05", "0.162307"], ["84390.95", "0"], ["84392.47", "0"], ["84392.58", "0"], ["84392.8", "0.048"], ["84393.23", "0"], ["84394", "0"], ["84394.08", "0.237053"], ["84394.2", "0"], ["84396.45", "0"], ["84398.3", "0.169135"], ["84398.36", "0.267707"], ["84399.25", "0"], ["84399.75", "0.089922"], ["84401.05", "0.017417"], ["84401.53", "0"], ["84403.55", "0.355674"], ["84404.74", "0"], ["84405.86", "0.001237"], ["84410.85", "0.008453"], ["84412.13", "0"], ["84415.58", "0"], ["84415.84", "0"], ["84416.04", "0"], ["84416.45", "0"], ["84416.97", "0"], ["84416.98", "0"], ["84417.5", "0"], ["84418.43", "0"]], "u": 7510745, "seq": 66889393920}, "cts": 1742142245007, "record_time": 1742142244.108899}
{"topic": "orderbook.200.BTCUSDT", "ts": 1742142245210, "type": "delta", "data": {"s": "BTCUSDT", "b": [["84369.37", "0.078318"], ["84365.91", "0.071124"], ["84365.16", "0.006339"], ["84363.63", "0.028722"], ["84363.62", "0.001333"], ["84363.57", "0.000613"], ["84363.17", "0.001467"], ["84363", "0.000252"], ["84362.69", "0.020874"], ["84362.66", "0"], ["84362.65", "0"], ["84362.64", "0"], ["84362.63", "0.011853"], ["84361.8", "0"], ["84360.95", "0.003"], ["84358.99", "0.041212"], ["84357.72", "0"], ["84357.71", "0"], ["84353.29", "0.000296"], ["84353.28", "0.071436"], ["84352.99", "0.109086"], ["84352.49", "0.162"], ["84351.09", "0.000296"], ["84351.03", "0"], ["84350.91", "0.070306"], ["84350.6", "0.040248"], ["84347.36", "0.000234"], ["84345.4", "0.011689"], ["84344.62", "0.172491"], ["84342.72", "0.000234"], ["84340.79", "0"], ["84340.06", "0"], ["84339.97", "0.001467"], ["84339.93", "0"], ["84336.26", "0.291141"], ["84334.42", "0"], ["84331.36", "0.071153"], ["84327.13", "0.003"], ["84318.51", "0.355625"], ["84315.38", "0"], ["84309.53", "0"], ["84308.8", "0"], ["84308.76", "0"], ["84308.68", "0"], ["84307.6", "0"], ["84307.59", "0"], ["84307.51", "0"], ["84307.34", "0"], ["84306.87", "0"]], "a": [["84369.38", "0.018036"], ["84370.04", "0.000235"], ["84370.1", "0"], ["84370.11", "0"], ["84370.21", "0.009355"], ["84373", "0.008227"], ["84373.22", "0.071118"], ["84375.75", "0"], ["84377.36", "0.104686"], ["84379.57", "0"], ["84380.26", "0.011689"], ["84380.93", "0"], ["84381", "0.044"], ["84381.75", "0"], ["84383.1", "0.06"], ["84383.94", "0.120946"], ["84384.07", "0"], ["84384.4", "0.068"], ["84385.55", "0"], ["84385.86", "0.115792"], ["84386.25", "0.274344"], ["84386.26", "0"], ["84386.54", "0"], ["84387.3", "0"], ["84388.15", "0"], ["84390.05", "0.000089"], ["84391.7", "0"], ["84392.3", "0.171322"], ["84393.91", "0"], ["84394.08", "0"], ["84394.49", "0.118526"], ["84398.13", "0"], ["84398.3", "0.260812"], ["84398.36", "0"], ["84398.93", "0"], ["84400.66", "0.265562"], ["84402.52", "0.237288"], ["84403", "0.000119"], ["84403.55", "0"], ["84404.81", "0"], ["84405.86", "0.003"], ["84405.91", "0.03181"], ["84410.85", "0"], ["84411.34", "0.008453"], ["84415.02", "0"], ["84415.58", "0.000089"], ["84415.84", "0.0045"], ["84416.04", "0.0045"], ["84416.39", "0.071081"], ["84416.45", "0.000235"], ["84416.97", "0.005"], ["84416.98", "0.000324"], ["84417.5", "0.0002"]], "u": 7510746, "seq": 66889394380}, "cts": 1742142245203, "record_time": 1742142244.309058}
{"topic": "orderbook.200.BTCUSDT", "ts": 1742142245410, "type": "delta", "data": {"s": "BTCUSDT", "b": [["84369.37", "0.031585"], ["84366.46", "0.000153"], ["84365.91", "0"], ["84365.16", "0"], ["84364.35", "0.0193"], ["84363.63", "0"], ["84363.53", "0.042728"], ["84363.52", "0.071126"], ["84362.69", "0"], ["84362.63", "0"], ["84353.28", "0"], ["84352.99", "0"], ["84352.49", "0"], ["84352.2", "0.032022"], ["84351.09", "0"], ["84350.6", "0.04"], ["84349.3", "0.003"], ["84349.25", "0.001715"], ["84347.57", "0.237053"], ["84344.79", "0.237053"], ["84344.62", "0"], ["84343.36", "0.237053"], ["84342.53", "0.001333"], ["84340.58", "0.237053"], ["84336.27", "0.088386"], ["84336.26", "0"], ["84331.6", "0.236441"], ["84331.53", "0"], ["84331.36", "0"], ["84326.07", "0.068395"], ["84319.78", "0.071163"], ["84319", "0.000119"], ["84318.51", "0"], ["84311.1", "0.35574"], ["84311.08", "0"]], "a": [["84369.38", "0.047347"], ["84370.48", "0.07112"], ["84373.22", "0"], ["84383.94", "0"], ["84385.86", "0"], ["84386.25", "0.161044"], ["84386.26", "0.162"], ["84387.74", "0.139853"], ["84389.4", "0"], ["84389.82", "0.134055"], ["84392.3", "0"], ["84395.35", "0.237053"], ["84398.13", "0.237053"], ["84400.56", "0.629117"], ["84400.66", "0"], ["84402.34", "0.237053"], ["84404.95", "0.071091"], ["84408.01", "0.35565"], ["84411.55", "0.473869"], ["84416.39", "0"], ["84416.45", "0"], ["84416.97", "0"], ["84416.98", "0"], ["84417.5", "0"]], "u": 7510747, "seq": 66889394773}, "cts": 1742142245408, "record_time": 1742142244.509058}
{"topic": "orderbook.200.BTCUSDT", "ts": 1742142245610, "type": "delta", "data": {"s": "BTCUSDT", "b": [["84369.37", "0.154783"], ["84366.46", "0"], ["84364.37", "0.014467"], ["84363.52", "0"], ["84362.63", "0.011853"], ["84353.94", "0.110834"], ["84353.49", "0.120196"], ["84352.5", "0.173556"], ["84352.49", "0.162"], ["84352.2", "0"], ["84351.79", "0.237053"], ["84351.77", "0.059948"], ["84351.04", "0.117492"], ["84350.96", "0.001581"], ["84350.91", "0.133534"], ["84349.25", "0.001467"], ["84345.57", "0.158513"], ["84343.36", "0"], ["84342.67", "0.178132"], ["84337.21", "0.298238"], ["84336.27", "0"], ["84335.95", "0"], ["84330.72", "0"], ["84324.73", "0.017779"], ["84322.29", "0.17779"], ["84320.32", "0"], ["84319.78", "0"], ["84318.51", "0.355625"], ["84311.1", "0.000089"], ["84311.09", "0"], ["84311.02", "0"], ["84310.93", "0"], ["84310.5", "0"], ["84310.26", "0"], ["84309.73", "0"]], "a": [["84369.38", "0.044108"], ["84370.21", "0"], ["84370.48", "0"], ["84373", "0.0006"], ["84374.43", "0"], ["84381", "0"], ["84383.1", "0"], ["84384.4", "0"], ["84384.8", "0"], ["84384.89", "0.114057"], ["84386.11", "0.11081"], ["84386.26", "0"], ["84387", "0.114689"], ["84387.74", "0"], ["84392.8", "0.215342"], ["84393.25", "0.169876"], ["84394.05", "0.251474"], ["84395.37", "0.164856"], ["84398.13", "0"], ["84398.3", "0.023759"], ["84401.61", "0.278095"], ["84402.34", "0"], ["84402.52", "0.000235"], ["84408.01", "0"], ["84413.94", "0.119867"], ["84416.42", "0.17779"], ["84416.45", "0.000235"], ["84416.97", "0.005"], ["84416.98", "0.000324"], ["84417.5", "0.0002"]], "u": 7510748, "seq": 66889395224}, "cts": 1742142245607, "record_time": 1742142244.709058}
{"topic": "orderbook.200.BTCUSDT", "ts": 1742142245810, "type": "delta", "data": {"s": "BTCUSDT", "b": [["84369.37", "0.084123"], ["84368.7", "0.000153"], ["84365.74", "0.0193"], ["84365.16", "0.011853"], ["84364.37", "0"], ["84364.35", "0"], ["84363.53", "0.02139"], ["84359.39", "0.09964"], ["84358.99", "0.108089"], ["84357.71", "0.237086"], ["84354", "0.176471"], ["84353.94", "0"], ["84353.49", "0"], ["84353.36", "0.11281"], ["84353.22", "0.237053"], ["84352.5", "0"], ["84351.77", "0.060196"], ["84351.04", "0"], ["84350.96", "0.001333"], ["84350.51", "0.119541"], ["84350.46", "0.011852"], ["84349.75", "0.068395"], ["84349.01", "0.237053"], ["84346.36", "0.163292"], ["84345.7", "0.04"], ["84345.57", "0"], ["84345.4", "0"], ["84344.99", "0.16299"], ["84344.79", "0"], ["84343.8", "0.158526"], ["84342.7", "0.048"], ["84342.68", "0.197844"], ["84342.67", "0"], ["84342.15", "0.166738"], ["84341.58", "0"], ["84340.58", "0"], ["84338", "0.289644"], ["84337.21", "0"], ["84336.63", "0.263521"], ["84334.33", "0.139851"], ["84333.78", "0.271412"], ["84331.6", "0"], ["84331.47", "0.071153"], ["84331.08", "0.292479"], ["84322.09", "0.005575"], ["84321.59", "0.11"], ["84319.55", "0.355705"], ["84318.51", "0"], ["84314.5", "0"], ["84314.4", "0"], ["84314.37", "0"], ["84313.73", "0"], ["84313.02", "0"], ["84312.97", "0"], ["84312.14", "0"], ["84311.98", "0"], ["84311.32", "0"], ["84311.2", "0"], ["84311.1", "0"]], "a": [["84369.38", "0.041737"], ["84370.21", "0.006819"], ["84373.45", "0.071118"], ["84380.26", "0"], ["84381.04", "0"], ["84382.79", "0.049529"], ["84382.8", "0"], ["84384.3", "0.115529"], ["84384.71", "0.013185"], ["84384.89", "0"], ["84384.96", "0.13985"], ["84386.11", "0"], ["84386.48", "0.110738"], ["84387", "0"], ["84387.1", "0.044"], ["84387.72", "0"], ["84388.9", "0.04"], ["84389", "0.06"], ["84389.41", "0"], ["84390.9", "0.068"], ["84391.25", "0.006091"], ["84392.37", "0.159771"], ["84392.67", "0.180374"], ["84392.8", "0.048"], ["84393.25", "0"], ["84394.84", "0.171434"], ["84395.37", "0"], ["84395.49", "0.169366"], ["84399.57", "0.237053"], ["84400.73", "0.288779"], ["84401.03", "0.27367"], ["84401.05", "0"], ["84401.61", "0"], ["84402.34", "0.237053"], ["84403.21", "0.289935"], ["84403.78", "0.237053"], ["84404.95", "0"], ["84405.94", "0.017779"], ["84406.55", "0.237053"], ["84414.97", "0"], ["84415.03", "0"], ["84415.58", "0"], ["84415.84", "0"], ["84416.04", "0"], ["84416.42", "0"], ["84416.45", "0"], ["84416.97", "0"], ["84416.98", "0"], ["84417.5", "0"]], "u": 7510749, "seq": 66889395700}, "cts": 1742142245806, "record_time": 1742142244.908998}
