{"topic": "orderbook.200.BTCUSDT", "ts": 1742377116414, "type": "snapshot", "data": {"s": "BTCUSDT", "b": [["83552.87", "0.635385"], ["83552.25", "0.001333"], ["83552.06", "0.000243"], ["83551.53", "0.000243"], ["83551.32", "0.000333"], ["83551.11", "0.001109"], ["83550.73", "0.003"], ["83550.68", "0.021983"], ["83550.67", "0.071811"], ["83549.87", "0.001466"], ["83549.73", "0.02"], ["83549.16", "0.000277"], ["83548.97", "0.000099"], ["83548.07", "0.001333"], ["83548.03", "0.014174"], ["83547.46", "0.000243"], ["83547.15", "0.000333"], ["83546.94", "0.000243"], ["83546.93", "0.001109"], ["83546.03", "0.000252"], ["83545.92", "0.045068"], ["83545.28", "0.001466"], ["83545.25", "0.596716"], ["83545.24", "0.5"], ["83544.88", "0.000299"], ["83544.87", "0.000299"], ["83544.86", "0.926475"], ["83544.56", "0.006261"], ["83544.51", "0.00059"], ["83544.23", "0.000153"], ["83543.89", "0.001333"], ["83543.83", "0.045069"], ["83543.5", "0.009423"], ["83542.97", "0.000333"], ["83542.92", "0.019438"], ["83542.87", "0.000243"], ["83542.85", "0.021074"], ["83542.75", "0.001108"], ["83542.7", "0.056"], ["83542.64", "0.060553"], ["83542.63", "0.167035"], ["83542.6", "0.058"], ["83542.37", "0.170443"], ["83542.34", "0.000243"], ["83542.09", "0.178706"], ["83541.84", "0.003"], ["83541.7", "0.001"], ["83541.63", "0.024909"], ["83541.37", "0.003"], ["83541.27", "0.255892"], ["83541.19", "0.159905"], ["83541.17", "0.003"], ["83541", "0.064"], ["83540.9", "0.052"], ["83540.68", "0.001466"], ["83540.57", "0.170831"], ["83540.16", "0.001109"], ["83540", "0.00006"], ["83539.97", "0.000277"], ["83539.72", "0.001333"], ["83539.3", "0.076"], ["83539.2", "0.064"], ["83538.79", "0.000333"], ["83538.58", "0.00221"], ["83538.51", "0.003"], ["83538.27", "0.000243"], ["83538.08", "0.239369"], ["83537.87", "0.239369"], ["83537.75", "0.000243"], ["83537.7", "0.084"], ["83537.5", "0.068"], ["83537.22", "0.00241"], ["83536.59", "0.017962"], ["83536.33", "0.003954"], ["83536.19", "0.00009"], ["83536.15", "0.012911"], ["83536.13", "0.433396"], ["83536.12", "0.017962"], ["83536.09", "0.001466"], ["83536", "0.056"], ["83535.98", "0.014135"], ["83535.9", "0.064"], ["83535.54", "0.001333"], ["83535.38", "0.000277"], ["83534.79", "0.005961"], ["83534.62", "0.000333"], ["83534.57", "0.298612"], ["83534.4", "0.001106"], ["83533.9", "0.239424"], ["83533.7", "0.060553"], ["83533.69", "0.518884"], ["83533.68", "0.000242"], ["83533.37", "0.289282"], ["83533.16", "0.000242"], ["83532.7", "0.000078"], ["83532.34", "0.009224"], ["83532.23", "0.108072"], ["83532.02", "0.024275"], ["83531.89", "0.304876"], ["83531.71", "0.01869"], ["83531.5", "0.001466"], ["83531.37", "0.001333"], ["83530.99", "0.1665"], ["83530.78", "0.000277"], ["83530.44", "0.000333"], ["83530.22", "0.001106"], ["83529.08", "0.000242"], ["83528.77", "0.015"], ["83528.67", "0.112623"], ["83528.57", "0.446367"], ["83528.56", "0.000242"], ["83528.28", "0.00034"], ["83528.24", "0.07183"], ["83528.11", "0.00018"], ["83528.08", "0.003542"], ["83527.87", "0.00009"], ["83527.37", "0.432778"], ["83527.19", "0.001333"], ["83527.02", "0.00457"], ["83527", "0.000119"], ["83526.9", "0.001466"], ["83526.26", "0.000333"], ["83526.19", "0.000276"], ["83526.05", "0.001106"], ["83525.89", "0.92456"], ["83525.18", "0.000149"], ["83524.64", "0.005983"], ["83524.61", "0.440778"], ["83524.49", "0.000242"], ["83523.97", "0.000242"], ["83523.5", "0.071834"], ["83523.47", "0.060553"], ["83523.01", "0.001333"], ["83522.63", "0.1665"], ["83522.49", "0.011968"], ["83522.31", "0.001466"], ["83522.09", "0.000333"], ["83521.87", "0.001106"], ["83521.59", "0.000276"], ["83521.37", "0.167559"], ["83521.16", "0.119685"], ["83520.3", "0.02464"], ["83520", "0.00006"], ["83519.9", "0.000242"], ["83519.62", "0.00009"], ["83519.55", "0.00009"], ["83519.37", "0.000242"], ["83518.84", "0.001333"], ["83517.91", "0.000333"], ["83517.71", "0.001466"], ["83517.69", "0.001106"], ["83517", "0.000276"], ["83516.73", "0.003"], ["83516.48", "0.035914"], ["83515.94", "0.0091"], ["83515.53", "0.023938"], ["83515.3", "0.000842"], ["83515.18", "0.003663"], ["83514.98", "0.005984"], ["83514.78", "0.000242"], ["83514.74", "0.018279"], ["83514.67", "0.060553"], ["83514.66", "0.001333"], ["83514.27", "0.1665"], ["83514.13", "0.135395"], ["83513.73", "0.000333"], ["83513.52", "0.001106"], ["83513.43", "0.015"], ["83513.12", "0.001466"], ["83512.84", "0.11"], ["83512.82", "0.005"], ["83512.41", "0.000276"], ["83511.82", "0.008783"], ["83511.49", "0.013958"], ["83511.23", "0.00009"], ["83510.85", "0.023938"], ["83510.71", "0.000242"], ["83510.52", "0.511472"], ["83510.49", "0.001333"], ["83510.19", "0.000242"], ["83509.56", "0.000333"], ["83509.5", "0.005983"], ["83509.34", "0.001106"], ["83509.22", "0.0025"], ["83508.53", "0.001466"], ["83507.94", "0.023938"], ["83507.81", "0.000276"], ["83507.75", "0.022298"], ["83507.27", "0.000119"], ["83507.18", "0.023938"], ["83506.58", "0.119902"], ["83506.31", "0.001333"], ["83506.17", "0.00034"], ["83506.12", "0.000242"], ["83505.91", "0.1665"], ["83505.59", "0.000242"], ["83505.38", "0.000333"], ["83505.34", "0.04"], ["83505.33", "0.039645"], ["83505.17", "0.001123"]], "a": [["83552.88", "0.468"], ["83553.21", "0.030818"], ["83553.22", "0.071809"], ["83553.71", "0.011925"], ["83555.33", "0.005984"], ["83555.92", "0.003"], ["83555.93", "0.009866"], ["83556.78", "0.000099"], ["83557.05", "0.011967"], ["83558.35", "0.000277"], ["83559.07", "0.001466"], ["83559.15", "0.052284"], ["83559.46", "0.001109"], ["83559.55", "0.011967"], ["83559.68", "0.000333"], ["83560.34", "0.014628"], ["83560.53", "0.105532"], ["83560.61", "0.001333"], ["83560.73", "0.000243"], ["83560.74", "0.2265"], ["83561.24", "0.0005"], ["83561.25", "0.000243"], ["83561.26", "0.007181"], ["83561.36", "0.00375"], ["83561.55", "0.008783"], ["83561.57", "0.103241"], ["83562.95", "0.000277"], ["83563", "0.0002"], ["83563.3", "0.005984"], ["83563.37", "0.175128"], ["83563.64", "0.001109"], ["83563.66", "0.001466"], ["83563.69", "0.164634"], ["83563.86", "0.000333"], ["83563.92", "0.497755"], ["83564.58", "0.119902"], ["83564.59", "0.177735"], ["83564.78", "0.001333"], ["83565.17", "0.157309"], ["83565.32", "0.000243"], ["83565.36", "1"], ["83565.62", "0.019724"], ["83565.84", "0.000243"], ["83565.9", "0.00601"], ["83566.2", "0.04"], ["83566.25", "0.112522"], ["83566.99", "0.250002"], ["83567.14", "0.028602"], ["83567.54", "0.000277"], ["83567.8", "0.04"], ["83567.82", "0.00111"], ["83568.03", "0.000333"], ["83568.14", "0.239326"], ["83568.26", "0.001466"], ["83568.96", "0.001333"], ["83569.1", "0.04"], ["83569.2", "0.028602"], ["83569.26", "0.018392"], ["83569.48", "0.00009"], ["83569.81", "0.239321"], ["83569.92", "0.000243"], ["83570.36", "0.003359"], ["83570.4", "0.119902"], ["83570.43", "0.1665"], ["83570.44", "0.000243"], ["83571.01", "0.00726"], ["83571.17", "0.28335"], ["83571.37", "0.4591"], ["83571.48", "0.239316"], ["83571.5", "0.04"], ["83571.61", "0.005984"], ["83572", "0.001124"], ["83572.09", "0.279961"], ["83572.14", "0.000277"], ["83572.21", "0.000333"], ["83572.37", "0.302856"], ["83572.4", "0.08"], ["83572.53", "0.001"], ["83572.6", "0.071792"], ["83572.85", "0.004466"], ["83573.14", "0.001333"], ["83573.37", "0.000674"], ["83573.89", "0.283733"], ["83574.1", "0.08"], ["83574.2", "0.0006"], ["83574.3", "0.0042"], ["83574.51", "0.000243"], ["83575.04", "0.000243"], ["83575.22", "0.023813"], ["83575.28", "0.421749"], ["83575.7", "0.04"], ["83576.18", "0.001124"], ["83576.39", "0.000333"], ["83576.6", "0.04"], ["83576.74", "0.000277"], ["83577.12", "0.009228"], ["83577.17", "0.447547"], ["83577.32", "0.001333"], ["83577.45", "0.001466"], ["83577.51", "0.0036"], ["83577.8", "0.00009"], ["83577.81", "0.060553"], ["83577.82", "0.464966"], ["83578.08", "0.089922"], ["83578.2", "0.239369"], ["83578.3", "0.0024"], ["83578.37", "0.466985"], ["83578.74", "0.023741"], ["83579.09", "0.119902"], ["83579.11", "0.000243"], ["83579.41", "0.1665"], ["83579.63", "0.000243"], ["83579.67", "0.239369"], ["83579.82", "0.459412"], ["83579.83", "0.07817"], ["83579.89", "0.872401"], ["83580", "0.00024"], ["83580.13", "0.071785"], ["83580.36", "0.001124"], ["83580.57", "0.000333"], ["83580.91", "0.008918"], ["83581.32", "0.51903"], ["83581.33", "0.000277"], ["83581.5", "0.001333"], ["83582.05", "0.001466"], ["83582.48", "0.000939"], ["83583.2", "0.023937"], ["83583.71", "0.000243"], ["83583.84", "0.159893"], ["83583.85", "0.239369"], ["83584.05", "0.167559"], ["83584.16", "0.119902"], ["83584.22", "0.00034"], ["83584.23", "0.000243"], ["83584.53", "0.001124"], ["83584.75", "0.000333"], ["83585.68", "0.001333"], ["83585.93", "0.000277"], ["83586.12", "0.00009"], ["83586.64", "0.001466"], ["83586.65", "0.000939"], ["83587.47", "0.026746"], ["83587.75", "0.060553"], ["83587.77", "0.1665"], ["83587.82", "0.005"], ["83588.3", "0.000243"], ["83588.71", "0.001124"], ["83588.83", "0.000243"], ["83588.93", "0.000333"], ["83589.73", "0.205728"], ["83589.74", "0.089922"], ["83589.86", "0.001333"], ["83590.53", "0.000277"], ["83590.59", "0.004588"], ["83590.78", "0.00018"], ["83591.24", "0.001466"], ["83592.36", "0.119902"], ["83592.89", "0.001124"], ["83592.9", "0.000243"], ["83593.11", "0.000333"], ["83593.39", "0.023937"], ["83593.43", "0.000243"], ["83593.81", "0.018279"], ["83594.04", "0.001333"], ["83594.44", "0.00009"], ["83594.55", "0.013979"], ["83594.63", "0.003"], ["83594.64", "0.359057"], ["83594.65", "0.4784"], ["83595.12", "0.000277"], ["83595.84", "0.001466"], ["83596.06", "0.581368"], ["83596.12", "0.106813"], ["83596.13", "0.1665"], ["83596.75", "0.016388"], ["83597.07", "0.001124"], ["83597.08", "0.00049"], ["83597.13", "0.003929"], ["83597.29", "0.000333"], ["83597.5", "0.000243"], ["83597.7", "0.060553"], ["83597.86", "0.119902"], ["83598.02", "0.000243"], ["83598.22", "0.001333"], ["83598.73", "0.063137"], ["83599.05", "0.04"], ["83599.06", "0.04"], ["83599.72", "0.000277"], ["83600", "0.000045"], ["83600.34", "0.000207"], ["83600.44", "0.001466"], ["83600.99", "0.023338"], ["83601", "0.0021"], ["83601.25", "0.001124"], ["83601.26", "0.001"], ["83601.27", "0.017962"], ["83601.47", "0.000333"], ["83602.1", "0.000243"], ["83602.4", "0.001333"], ["83602.46", "0.00315"]], "u": 971900, "seq": 67263571120}, "cts": 1742377116407, "record_time": 1742377118.142899}
{"topic": "orderbook.200.BTCUSDT", "ts": 1742377116614, "type": "delta", "data": {"s": "BTCUSDT", "b": [["83552.87", "0.526342"], ["83550.73", "0"], ["83550.68", "0"], ["83550.67", "0"], ["83549.73", "0"], ["83548.03", "0"], ["83546.03", "0"], ["83545.92", "0"], ["83545.25", "0"], ["83545.24", "0"], ["83544.87", "0.439103"], ["83544.51", "0.0005"], ["83544.23", "0"], ["83543.83", "0"], ["83543.5", "0"], ["83542.92", "0"], ["83542.7", "0"], ["83542.64", "0"], ["83542.6", "0.006"], ["83541.69", "0.024907"], ["83541.63", "0"], ["83541.27", "0.127283"], ["83541", "0"], ["83540.9", "0"], ["83540.16", "0"], ["83539.3", "0"], ["83539.2", "0"], ["83538.93", "0.011969"], ["83538.08", "0"], ["83537.87", "0"], ["83537.7", "0"], ["83537.5", "0"], ["83536.59", "0"], ["83536.15", "0"], ["83536.12", "0"], ["83536", "0"], ["83535.98", "0"], ["83535.9", "0"], ["83534.85", "0.000153"], ["83534.83", "0.019438"], ["83533.91", "0.060553"], ["83533.9", "0"], ["83533.7", "0"], ["83533.69", "0.279515"], ["83533.18", "0.000252"], ["83533.03", "0.045075"], ["83532.8", "0.064"], ["83532.23", "0"], ["83532.03", "0.155729"], ["83531.71", "0"], ["83531.1", "0.068"], ["83530.94", "0.045076"], ["83530.27", "0.017954"], ["83528.67", "0"], ["83528.24", "0"], ["83528.08", "0"], ["83527", "0"], ["83524.75", "0.112531"], ["83524.61", "0"], ["83523.5", "0"], ["83522.53", "0.017962"], ["83521.66", "0.003492"], ["83521.44", "0.017962"], ["83521.16", "0"], ["83520.4", "1.333087"], ["83519.03", "0.071838"], ["83517.98", "0.02394"], ["83517.77", "0.023937"], ["83516.48", "0"], ["83515.9", "0.071841"], ["83514.13", "0"], ["83512.84", "0"], ["83511.61", "0.035916"], ["83510.82", "0.45884"], ["83506.58", "0"], ["83505.95", "0.135395"], ["83505.34", "0"], ["83505.33", "0"], ["83504.7", "0.060553"], ["83503.94", "0.001466"], ["83503.8", "0.056"], ["83503.7", "0.0021"], ["83503.5", "0.000157"], ["83503.22", "0.000277"], ["83502.91", "0.00009"], ["83502.5", "0.052"], ["83502.13", "0.001333"], ["83501.52", "0.000242"], ["83501.21", "0.000333"], ["83501.11", "0.119902"], ["83501.01", "0.179616"], ["83501", "0.000242"], ["83500.99", "0.001123"], ["83500.81", "0.023938"], ["83500.47", "0.167559"], ["83500", "0.00006"], ["83499.98", "0.002883"], ["83499.75", "0.296347"], ["83499.34", "0.001466"], ["83499.1", "0.064"], ["83498.63", "0.000277"], ["83497.96", "0.001333"]], "a": [["83552.88", "0.483964"], ["83553.21", "0.080069"], ["83554.22", "0.028607"], ["83554.46", "0.017954"], ["83554.94", "0.089922"], ["83556.3", "0.028606"], ["83556.65", "0.0036"], ["83560.34", "0"], ["83561.26", "0"], ["83561.55", "0"], ["83561.68", "0.089922"], ["83562.67", "0.00957"], ["83563.8", "0.04"], ["83565.5", "0.04"], ["83565.79", "0.539172"], ["83566.84", "1.347782"], ["83567.14", "0"], ["83567.4", "0.04"], ["83568.06", "0.071796"], ["83568.14", "0"], ["83569.2", "0"], ["83569.81", "0"], ["83571.48", "0"], ["83571.82", "0.001"], ["83577.12", "0"], ["83577.51", "0"], ["83579.31", "0.017962"], ["83579.67", "0"], ["83580.13", "0"], ["83581.05", "0.023338"], ["83581.32", "0"], ["83581.46", "0.02088"], ["83582.83", "0.017962"], ["83583.2", "0"], ["83583.85", "0"], ["83587.74", "0.359097"], ["83587.82", "0"], ["83592.25", "0.035914"], ["83593.39", "0"], ["83594.64", "0"], ["83597.13", "0"], ["83598.43", "0.003929"], ["83599.05", "0"], ["83599.06", "0"], ["83599.35", "0.04"], ["83599.36", "0.04"], ["83600.99", "0"], ["83601.27", "0"]], "u": 971901, "seq": 67263571614}, "cts": 1742377116610, "record_time": 1742377118.144369}
{"topic": "orderbook.200.BTCUSDT", "ts": 1742377116814, "type": "delta", "data": {"s": "BTCUSDT", "b": [["83552.87", "0.526778"], ["83549.53", "0.009619"], ["83541.69", "0"], ["83536.2", "0.056"], ["83536.13", "0.282532"], ["83536.1", "0.052"], ["83534.6", "0.064"], ["83534.5", "0.052"], ["83533.6", "0.239369"], ["83532.9", "0.076"], ["83531.3", "0.084"], ["83529.6", "0.056"], ["83529.52", "0.239369"], ["83529.5", "0.064"], ["83528.58", "0.544137"], ["83525.34", "0.239369"], ["83518.54", "0.5"], ["83511.61", "0"], ["83501.01", "0"], ["83501", "0"], ["83500.99", "0"], ["83500.81", "0"], ["83500.47", "0"], ["83500", "0"], ["83499.98", "0"], ["83499.75", "0"], ["83499.34", "0"], ["83499.1", "0"], ["83498.63", "0"], ["83497.96", "0"]], "a": [["83559.06", "0.016"], ["83560.3", "0.04"], ["83560.39", "0.16372"], ["83560.4", "0.04"], ["83560.53", "0"], ["83562", "0.04"], ["83562.1", "0.04"], ["83563.7", "0.04"], ["83565.5", "0.08"], ["83566.83", "0.555848"], ["83566.99", "0"], ["83567", "0.04"], ["83567.1", "0.04"], ["83569.1", "0"], ["83571.5", "0"], ["83574.1", "0.04"], ["83575.7", "0"], ["83576.6", "0"], ["83579.67", "0.239369"], ["83579.82", "0.205085"], ["83583.84", "0"], ["83583.85", "0.239369"], ["83587.74", "0.359095"], ["83598.73", "0.063131"], ["83601.26", "0"], ["83601.47", "0"], ["83602.1", "0"], ["83602.4", "0"], ["83602.46", "0"]], "u": 971902, "seq": 67263571798}, "cts": 1742377116811, "record_time": 1742377118.145354}
{"topic": "orderbook.200.BTCUSDT", "ts": 1742377117014, "type": "delta", "data": {"s": "BTCUSDT", "b": [["83549.54", "0.003"], ["83542.85", "0"], ["83535.12", "0.003"], ["83534.92", "0.003"], ["83532.03", "0.302976"], ["83518.64", "0.003"], ["83516.73", "0"], ["83511.47", "0.035916"], ["83501.52", "0"], ["83501.21", "0"], ["83501.11", "0"]], "a": [["83566.2", "0"], ["83567.4", "0"], ["83567.8", "0"], ["83571.16", "0.408878"], ["83571.37", "0"], ["83572.4", "0"], ["83574.1", "0"], ["83592.72", "0.003"], ["83594.63", "0"], ["83601.26", "0.001"], ["83601.47", "0.000333"], ["83602.1", "0.000243"], ["83602.4", "0.001333"], ["83602.46", "0.00315"]], "u": 971903, "seq": 67263571865}, "cts": 1742377117012, "record_time": 1742377118.146115}
{"topic": "orderbook.200.BTCUSDT", "ts": 1742377117214, "type": "delta", "data": {"s": "BTCUSDT", "b": [["83552.87", "0.546852"], ["83531.63", "0.23943"], ["83529.98", "0.239435"], ["83524.65", "0.137093"], ["83502.91", "0"], ["83502.5", "0"], ["83502.13", "0"]], "a": [["83561.23", "0.239345"], ["83562.9", "0.239341"], ["83563.69", "0.924793"], ["83563.92", "0"], ["83564.57", "0.239336"], ["83579.82", "0.282579"], ["83602.4", "0"], ["83602.46", "0"]], "u": 971904, "seq": 67263571971}, "cts": 1742377117205, "record_time": 1742377118.146809}
{"topic": "orderbook.200.BTCUSDT", "ts": 1742377117414, "type": "delta", "data": {"s": "BTCUSDT", "b": [["83549.53", "0"], ["83540.99", "0.071819"], ["83532.03", "0.42823"], ["83529.21", "0.001359"], ["83528.98", "0.001406"], ["83524.8", "0.001407"], ["83503.7", "0"], ["83503.5", "0"], ["83503.22", "0"]], "a": [["83552.88", "0.4854"], ["83559.05", "0.119902"], ["83560.29", "0.247092"], ["83560.39", "0"], ["83561.57", "0.101805"], ["83578.58", "0.004654"], ["83590.59", "0"], ["83602.1", "0"]], "u": 971905, "seq": 67263572203}, "cts": 1742377117411, "record_time": 1742377118.286467}
{"topic": "orderbook.200.BTCUSDT", "ts": 1742377117614, "type": "delta", "data": {"s": "BTCUSDT", "b": [["83539.36", "0.024909"], ["83533.69", "0.518884"], ["83531.33", "0.001058"], ["83530.69", "0.00113"], ["83529.21", "0"], ["83528.98", "0"], ["83527.16", "0.001058"], ["83527", "0.000119"], ["83526.51", "0.00113"], ["83525.34", "0"], ["83524.8", "0"], ["83518.54", "0"], ["83511.47", "0"], ["83511.43", "0.035916"], ["83507.11", "0.11"], ["83503.94", "0"], ["83503.8", "0"]], "a": [["83556.65", "0"], ["83566.31", "0.0036"], ["83575.22", "0"], ["83598.55", "0.11"]], "u": 971906, "seq": 67263572433}, "cts": 1742377117609, "record_time": 1742377118.487035}
{"topic": "orderbook.200.BTCUSDT", "ts": 1742377117815, "type": "delta", "data": {"s": "BTCUSDT", "b": [["83549.53", "0.000825"], ["83536.13", "0.448134"], ["83531.33", "0"], ["83530.69", "0"], ["83529.54", "0.001292"], ["83527.16", "0"], ["83526.86", "0.001086"], ["83526.51", "0"], ["83525.36", "0.001292"]], "a": [["83552.88", "0.485403"], ["83559.04", "0.016"], ["83559.06", "0"], ["83562.14", "0.023795"], ["83573.92", "0.024687"], ["83578.74", "0"], ["83595.11", "0.003929"], ["83598.43", "0"], ["83601.47", "0"]], "u": 971907, "seq": 67263572575}, "cts": 1742377117811, "record_time": 1742377118.687058}
{"topic": "orderbook.200.BTCUSDT", "ts": 1742377118014, "type": "delta", "data": {"s": "BTCUSDT", "b": [["83536.11", "0.239369"], ["83529.85", "0.001241"], ["83529.54", "0"], ["83526.86", "0"], ["83526.41", "0.001138"], ["83525.66", "0.001243"], ["83525.36", "0"], ["83504.7", "0"]], "a": [["83595.11", "0.003918"], ["83597.06", "0.04"], ["83597.07", "0.041124"], ["83599.35", "0"], ["83599.36", "0"], ["83601.47", "0.000333"]], "u": 971908, "seq": 67263572697}, "cts": 1742377118010, "record_time": 1742377118.886512}
{"topic": "orderbook.200.BTCUSDT", "ts": 1742377118215, "type": "delta", "data": {"s": "BTCUSDT", "b": [["83552.87", "0.547852"], ["83542.67", "0.071818"], ["83540.99", "0"], ["83539.07", "0.000153"], ["83536.11", "0"], ["83534.85", "0"], ["83533.6", "0"], ["83530.05", "0.00121"], ["83529.85", "0"], ["83529.56", "0.001288"], ["83526.41", "0"], ["83525.88", "0.00121"], ["83525.66", "0"], ["83504.7", "0.060553"], ["83503.94", "0.001466"]], "a": [["83562.14", "0"], ["83595.11", "0"], ["83595.14", "0.003918"], ["83602.1", "0.000243"]], "u": 971909, "seq": 67263572882}, "cts": 1742377118208, "record_time": 1742377119.08745}
{"topic": "orderbook.200.BTCUSDT", "ts": 1742377118414, "type": "delta", "data": {"s": "BTCUSDT", "b": [["83552.87", "0.547855"], ["83549.53", "0"], ["83536.11", "0.239369"], ["83535.32", "0.003"], ["83534.92", "0"], ["83530.05", "0"], ["83529.86", "0.00124"], ["83529.56", "0"], ["83529.12", "0.001369"], ["83525.88", "0"], ["83525.68", "0.00124"]], "a": [["83552.88", "0.464326"], ["83562.9", "0.260418"]], "u": 971910, "seq": 67263573053}, "cts": 1742377118410, "record_time": 1742377119.286582}
{"topic": "orderbook.200.BTCUSDT", "ts": 1742377118615, "type": "delta", "data": {"s": "BTCUSDT", "b": [["83542.85", "0.021077"], ["83529.86", "0"], ["83529.21", "0.001345"], ["83529.12", "0"], ["83528.87", "0.001414"], ["83525.68", "0"], ["83524.7", "0.001414"], ["83509.21", "0.11"], ["83504.7", "0"], ["83503.94", "0"]], "a": [["83566.31", "0"], ["83566.59", "0.0036"], ["83574.2", "0"], ["83574.3", "0"], ["83578.3", "0.0018"], ["83602.4", "0.001333"], ["83602.46", "0.00315"]], "u": 971911, "seq": 67263573139}, "cts": 1742377118609, "record_time": 1742377119.487316}
{"topic": "orderbook.200.BTCUSDT", "ts": 1742377118814, "type": "delta", "data": {"s": "BTCUSDT", "b": [["83542.85", "0"], ["83531.47", "0.001038"], ["83529.21", "0"], ["83528.93", "0.001403"], ["83528.87", "0"], ["83527.29", "0.001038"], ["83526.63", "0.001108"], ["83524.75", "0.113934"], ["83524.7", "0"]], "a": [["83563.08", "0.024281"], ["83566.16", "0.003384"], ["83566.59", "0"], ["83570.36", "0"], ["83595.12", "0.004195"], ["83595.14", "0"], ["83595.6", "0.0114"]], "u": 971912, "seq": 67263573234}, "cts": 1742377118810, "record_time": 1742377119.687215}
{"topic": "orderbook.200.BTCUSDT", "ts": 1742377119014, "type": "delta", "data": {"s": "BTCUSDT", "b": [["83552.87", "0.547675"], ["83534.5", "0.097074"], ["83533.03", "0"], ["83532.41", "0.045075"], ["83531.47", "0"], ["83530.94", "0"], ["83529.91", "0.001226"], ["83529.73", "0.001254"], ["83528.93", "0"], ["83527.29", "0"], ["83526.63", "0"], ["83525.74", "0.001226"], ["83524.75", "0.112531"], ["83521.76", "0.119685"], ["83520.61", "0.003"], ["83518.64", "0"], ["83507.11", "0"], ["83504.7", "0.060553"], ["83503.94", "0.001466"]], "a": [["83554.22", "0"], ["83555.67", "0.028606"], ["83556.3", "0"], ["83557.76", "0.028606"], ["83572.85", "0.001466"], ["83586.24", "0.003"], ["83592.72", "0"], ["83595.12", "0.000277"], ["83595.32", "0.003918"], ["83597.06", "0"], ["83597.07", "0.001124"], ["83597.25", "0.04"], ["83597.26", "0.04"], ["83599.99", "0.003"], ["83602.1", "0"], ["83602.4", "0"], ["83602.46", "0"]], "u": 971913, "seq": 67263573332}, "cts": 1742377119012, "record_time": 1742377119.88893}
{"topic": "orderbook.200.BTCUSDT", "ts": 1742377119215, "type": "delta", "data": {"s": "BTCUSDT", "b": [["83552.87", "0.547855"], ["83542.85", "0.021077"], ["83529.91", "0"], ["83529.73", "0"], ["83528.95", "0.001398"], ["83528.93", "0.001402"], ["83525.74", "0"], ["83525.23", "0.001309"], ["83503.94", "0"]], "a": [["83552.88", "0.485403"], ["83553.96", "0.0036"], ["83561.2", "0.002167"], ["83562.9", "0.239341"], ["83574.96", "0.005"], ["83595.02", "0.003918"], ["83595.32", "0"], ["83596.95", "0.04"], ["83596.96", "0.04"], ["83597.25", "0"], ["83597.26", "0"], ["83601.25", "0"], ["83601.26", "0"], ["83601.47", "0"]], "u": 971914, "seq": 67263573461}, "cts": 1742377119212, "record_time": 1742377120.087998}
{"topic": "orderbook.200.BTCUSDT", "ts": 1742377119414, "type": "delta", "data": {"s": "BTCUSDT", "b": [["83552.87", "0.526778"], ["83533.6", "0.239369"], ["83531.06", "0.001079"], ["83530.15", "0.001192"], ["83528.95", "0"], ["83528.93", "0"], ["83526.89", "0.001079"], ["83525.23", "0"], ["83504.7", "0"]], "a": [["83552.88", "0.483217"], ["83595.01", "0.003918"], ["83595.02", "0"]], "u": 971915, "seq": 67263573550}, "cts": 1742377119411, "record_time": 1742377120.287726}
{"topic": "orderbook.200.BTCUSDT", "ts": 1742377119614, "type": "delta", "data": {"s": "BTCUSDT", "b": [["83533.6", "0"], ["83531.06", "0"], ["83530.15", "0"], ["83528.94", "0.0014"], ["83528.85", "0.00142"], ["83526.89", "0"], ["83524.76", "0.0014"], ["83504.7", "0.060553"]], "a": [["83553.96", "0"], ["83587.74", "0.359086"], ["83592.25", "0"], ["83595.01", "0"], ["83595.21", "0.003918"], ["83596.95", "0"], ["83596.96", "0"], ["83597.15", "0.04"], ["83597.16", "0.04"], ["83601.25", "0.001124"], ["83601.26", "0.001"]], "u": 971916, "seq": 67263573660}, "cts": 1742377119612, "record_time": 1742377120.487115}
{"topic": "orderbook.200.BTCUSDT", "ts": 1742377119814, "type": "delta", "data": {"s": "BTCUSDT", "b": [["83529.84", "0.001237"], ["83529.5", "0.065293"], ["83528.94", "0"], ["83528.85", "0"], ["83525.32", "0.001293"], ["83524.76", "0"], ["83520.4", "0"], ["83515.06", "1.364106"], ["83503.94", "0.001466"]], "a": [["83566.44", "0.0036"], ["83566.84", "0"], ["83587.19", "0.035916"], ["83595.11", "0.003918"], ["83595.21", "0"], ["83597.05", "0.04"], ["83597.06", "0.04"], ["83597.15", "0"], ["83597.16", "0"], ["83598.1", "0.11"], ["83601.25", "0"], ["83601.26", "0"]], "u": 971917, "seq": 67263573731}, "cts": 1742377119805, "record_time": 1742377120.686663}
{"topic": "orderbook.200.BTCUSDT", "ts": 1742377120014, "type": "delta", "data": {"s": "BTCUSDT", "b": [["83552.87", "0.548041"], ["83542.85", "0"], ["83530.69", "0.001122"], ["83529.84", "0"], ["83529.5", "0.064"], ["83528.89", "0.001411"], ["83526.51", "0.001122"], ["83525.32", "0"]], "a": [["83552.88", "0.483403"], ["83562.78", "1.344242"], ["83562.79", "1.32754"], ["83563.69", "0.164634"], ["83566.83", "0.138506"], ["83569.7", "0.024507"], ["83573.92", "0"], ["83587.19", "0.035917"], ["83587.73", "0.359087"], ["83587.74", "0"], ["83595.11", "0"], ["83595.31", "0.003918"], ["83597.05", "0"], ["83597.06", "0"], ["83597.24", "0.04"], ["83597.25", "0.04"], ["83598.1", "0"], ["83601", "0"]], "u": 971918, "seq": 67263573841}, "cts": 1742377120012, "record_time": 1742377120.886903}
{"topic": "orderbook.200.BTCUSDT", "ts": 1742377120214, "type": "delta", "data": {"s": "BTCUSDT", "b": [["83534.5", "0.052"], ["83532.41", "0"], ["83530.69", "0"], ["83529.08", "0.001613"], ["83528.89", "0"], ["83528.82", "0.001425"], ["83526.51", "0"], ["83524.68", "0.001418"], ["83503.8", "0.056"], ["83503.7", "0.0021"]], "a": [["83555.67", "0"], ["83557.76", "0"], ["83563.46", "0.028604"], ["83565.55", "0.028603"], ["83587.19", "0"], ["83587.72", "0.359087"], ["83587.73", "0"], ["83601", "0.0021"]], "u": 971919, "seq": 67263573940}, "cts": 1742377120212, "record_time": 1742377121.086479}
{"topic": "orderbook.200.BTCUSDT", "ts": 1742377120414, "type": "delta", "data": {"s": "BTCUSDT", "b": [["83542.26", "0.000153"], ["83539.07", "0"], ["83535.58", "0.003"], ["83535.32", "0"], ["83535.12", "0.045074"], ["83533.03", "0.045075"], ["83529.82", "0.00124"], ["83529.68", "0.001262"], ["83529.08", "0.000242"], ["83528.82", "0"], ["83525.65", "0.00124"], ["83524.68", "0"], ["83503.8", "0"], ["83503.7", "0"]], "a": [["83556.29", "0.028606"], ["83558.42", "0.028605"], ["83563.46", "0"], ["83565.55", "0"], ["83566.44", "0"], ["83587.19", "0.035916"], ["83587.72", "0"], ["83589.72", "0.359085"], ["83595.3", "0.003918"], ["83595.31", "0"]], "u": 971920, "seq": 67263574067}, "cts": 1742377120410, "record_time": 1742377121.287164}
{"topic": "orderbook.200.BTCUSDT", "ts": 1742377120615, "type": "delta", "data": {"s": "BTCUSDT", "b": [["83549.54", "0"], ["83544.87", "0.000299"], ["83542.67", "0"], ["83541.7", "0"], ["83540.93", "0.071819"], ["83539.36", "0"], ["83536.12", "0.024909"], ["83536.11", "0"], ["83534.79", "0"], ["83533.69", "0.279515"], ["83530.93", "0.001051"], ["83530.06", "0.00115"], ["83529.95", "0.001164"], ["83529.82", "0"], ["83529.68", "0"], ["83529.52", "0"], ["83525.78", "0.001164"], ["83525.65", "0"], ["83524.75", "0"], ["83521.76", "0"], ["83521.66", "0"], ["83521.37", "0"], ["83511.43", "0"], ["83509.21", "0"], ["83503.8", "0.056"], ["83503.7", "0.0021"], ["83503.5", "0.000157"], ["83503.22", "0.000277"], ["83502.91", "0.00009"], ["83502.5", "0.052"], ["83502.13", "0.001333"], ["83501.52", "0.000242"], ["83501.21", "0.000333"], ["83501.11", "0.119902"]], "a": [["83552.88", "0.444954"], ["83562.9", "0.260604"], ["83583.84", "0.359112"], ["83589.72", "0"], ["83595.23", "0.003918"], ["83595.3", "0"], ["83596.06", "0"], ["83601.25", "0.001124"]], "u": 971921, "seq": 67263574306}, "cts": 1742377120610, "record_time": 1742377121.487459}
{"topic": "orderbook.200.BTCUSDT", "ts": 1742377120814, "type": "delta", "data": {"s": "BTCUSDT", "b": [["83534.29", "0.239369"], ["83533.6", "0.239369"], ["83533.17", "0.006126"], ["83532.02", "0"], ["83530.93", "0"], ["83530.12", "0.239369"], ["83530.06", "0"], ["83529.95", "0"], ["83529.28", "0.001263"], ["83528.39", "0.001432"], ["83525.78", "0"], ["83525.1", "0.001263"], ["83524.65", "0.086678"], ["83524.22", "0.001432"], ["83523.59", "0.112429"], ["83516.88", "0.003494"], ["83510.36", "0.035917"], ["83502.91", "0"], ["83502.5", "0"], ["83502.13", "0"], ["83501.52", "0"], ["83501.21", "0"], ["83501.11", "0"]], "a": [["83552.88", "0.481874"], ["83562.9", "0.239341"], ["83576.23", "0.121761"], ["83583.84", "0"], ["83587.18", "0.3591"], ["83590.12", "0.581409"], ["83601", "0"], ["83601.25", "0"]], "u": 971922, "seq": 67263574438}, "cts": 1742377120811, "record_time": 1742377121.686648}
{"topic": "orderbook.200.BTCUSDT", "ts": 1742377121014, "type": "delta", "data": {"s": "BTCUSDT", "b": [["83543.09", "0.071817"], ["83540.93", "0"], ["83531.84", "0.024475"], ["83531.63", "0"], ["83529.98", "0"], ["83529.56", "0.001219"], ["83529.28", "0"], ["83528.39", "0"], ["83526.91", "0.167559"], ["83525.98", "0.001138"], ["83525.38", "0.001219"], ["83525.1", "0"], ["83524.22", "0"], ["83522.27", "0.003"], ["83520.61", "0"], ["83502.91", "0.00009"]], "a": [["83583.42", "0.003"], ["83586.24", "0"], ["83595.01", "0.003917"], ["83595.23", "0"], ["83595.89", "0.003"], ["83597.02", "0.04"], ["83597.03", "0.04"], ["83597.24", "0"], ["83597.25", "0"], ["83599.99", "0"]], "u": 971923, "seq": 67263574547}, "cts": 1742377121010, "record_time": 1742377121.886999}
{"topic": "orderbook.200.BTCUSDT", "ts": 1742377121214, "type": "delta", "data": {"s": "BTCUSDT", "b": [["83532.03", "0.309345"], ["83510.36", "0"], ["83510.12", "0.035917"], ["83505.95", "0"], ["83502.5", "0.052"]], "a": [], "u": 971924, "seq": 67263574616}, "cts": 1742377121211, "record_time": 1742377122.087024}
{"topic": "orderbook.200.BTCUSDT", "ts": 1742377121414, "type": "delta", "data": {"s": "BTCUSDT", "b": [["83531.84", "0"], ["83530.7", "0.001075"], ["83529.56", "0"], ["83529.08", "0.001539"], ["83525.98", "0"], ["83525.38", "0"], ["83525.18", "0"], ["83524.9", "0.001297"], ["83522.47", "0.000149"], ["83505.95", "0.135403"], ["83502.13", "0.001333"]], "a": [["83583.84", "0.359102"], ["83587.18", "0"], ["83594.98", "0.003917"], ["83595.01", "0"]], "u": 971925, "seq": 67263574707}, "cts": 1742377121409, "record_time": 1742377122.286844}
{"topic": "orderbook.200.BTCUSDT", "ts": 1742377121615, "type": "delta", "data": {"s": "BTCUSDT", "b": [["83543.09", "0"], ["83542.63", "0.1665"], ["83541.25", "0.071819"], ["83536.12", "0"], ["83535.65", "0.024909"], ["83533.17", "0"], ["83530.7", "0"], ["83530.12", "0.263578"], ["83529.78", "0.001187"], ["83529.08", "0.000242"], ["83525.61", "0.001187"], ["83524.9", "0"], ["83505.71", "0.11"]], "a": [["83580.94", "0.023937"], ["83583.83", "0.359103"], ["83583.84", "0"], ["83583.85", "0"], ["83594.75", "0.003917"], ["83594.98", "0"], ["83596.81", "0.04"], ["83596.82", "0.04"], ["83597.02", "0"], ["83597.03", "0"]], "u": 971926, "seq": 67263574861}, "cts": 1742377121611, "record_time": 1742377122.487426}
{"topic": "orderbook.200.BTCUSDT", "ts": 1742377121814, "type": "delta", "data": {"s": "BTCUSDT", "b": [["83543.09", "0.071817"], ["83541.25", "0"], ["83530.66", "0.00108"], ["83530.01", "0.001156"], ["83529.78", "0"], ["83525.77", "0.001165"], ["83525.61", "0"], ["83502.13", "0"]], "a": [["83576.09", "0.149988"], ["83583.83", "0"], ["83587.18", "0.359097"], ["83600.44", "0"]], "u": 971927, "seq": 67263574949}, "cts": 1742377121805, "record_time": 1742377122.687016}
{"topic": "orderbook.200.BTCUSDT", "ts": 1742377122014, "type": "delta", "data": {"s": "BTCUSDT", "b": [["83552.87", "0.569304"], ["83530.66", "0"], ["83530.01", "0"], ["83529.63", "0.001209"], ["83529.04", "0.001303"], ["83528.53", "0.001402"], ["83525.77", "0"], ["83524.87", "0.001303"], ["83505.95", "0"]], "a": [["83552.88", "0.460611"], ["83562.9", "0.260604"], ["83575.28", "0.598902"], ["83584.04", "0.359102"], ["83587.18", "0"], ["83594.73", "0.003917"], ["83594.75", "0"], ["83598.73", "0"], ["83600.44", "0.001466"]], "u": 971928, "seq": 67263575067}, "cts": 1742377122010, "record_time": 1742377122.886651}
{"topic": "orderbook.200.BTCUSDT", "ts": 1742377122214, "type": "delta", "data": {"s": "BTCUSDT", "b": [["83552.87", "0.547041"], ["83544.87", "0.460233"], ["83544.42", "0.071816"], ["83543.09", "0"], ["83535.71", "0.02491"], ["83535.65", "0"], ["83533.17", "0.005931"], ["83530.86", "0.001058"], ["83529.63", "0"], ["83529.04", "0"], ["83528.53", "0"], ["83526.69", "0.001058"], ["83524.87", "0"], ["83523.76", "0.071834"], ["83515.9", "0"], ["83502.13", "0.001333"]], "a": [["83553.21", "0.044511"], ["83554.94", "0"], ["83584.04", "0"], ["83589.72", "0.359086"], ["83596.8", "0.04"], ["83596.82", "0"], ["83601", "0.0021"]], "u": 971929, "seq": 67263575240}, "cts": 1742377122210, "record_time": 1742377123.087377}
{"topic": "orderbook.200.BTCUSDT", "ts": 1742377122414, "type": "delta", "data": {"s": "BTCUSDT", "b": [["83552.87", "0.525778"], ["83542.85", "0.021263"], ["83535.78", "0.003"], ["83533.6", "0"], ["83530.86", "0"], ["83530.72", "0.001073"], ["83530.37", "0.001112"], ["83526.69", "0"], ["83526.54", "0.001073"], ["83526.19", "0.001388"], ["83524.65", "0.131167"], ["83518.61", "0.023937"], ["83506.16", "0.119902"], ["83503.22", "0"], ["83502.91", "0"], ["83502.5", "0"], ["83502.13", "0"]], "a": [["83552.88", "0.481874"], ["83562.9", "0.239341"], ["83570.92", "0.023937"], ["83594.72", "0.003917"], ["83594.73", "0"], ["83601", "0"]], "u": 971930, "seq": 67263575312}, "cts": 1742377122411, "record_time": 1742377123.28721}
{"topic": "orderbook.200.BTCUSDT", "ts": 1742377122614, "type": "delta", "data": {"s": "BTCUSDT", "b": [["83533.6", "0.239369"], ["83530.98", "0.001046"], ["83530.72", "0"], ["83530.37", "0"], ["83529.19", "0.001278"], ["83526.81", "0.001046"], ["83526.54", "0"], ["83526.19", "0.000276"], ["83525.01", "0.001278"], ["83503.7", "0"], ["83503.5", "0"]], "a": [["83589.71", "0.036361"], ["83589.73", "0"], ["83594.49", "0.003917"], ["83594.72", "0"], ["83596.58", "0.04"], ["83596.59", "0.04"], ["83596.8", "0"], ["83596.81", "0"]], "u": 971931, "seq": 67263575412}, "cts": 1742377122611, "record_time": 1742377123.488193}
{"topic": "orderbook.200.BTCUSDT", "ts": 1742377122815, "type": "delta", "data": {"s": "BTCUSDT", "b": [["83538.9", "0.0012"], ["83530.98", "0"], ["83529.19", "0"], ["83528.99", "0.001313"], ["83526.81", "0"], ["83525.01", "0"], ["83524.85", "0.001305"], ["83511.41", "0.11"]], "a": [["83589.7", "0.35908"], ["83589.72", "0"], ["83594.48", "0.003917"], ["83594.49", "0"], ["83598.73", "0.063131"], ["83600.44", "0"]], "u": 971932, "seq": 67263575486}, "cts": 1742377122811, "record_time": 1742377123.688377}
{"topic": "orderbook.200.BTCUSDT", "ts": 1742377123014, "type": "delta", "data": {"s": "BTCUSDT", "b": [["83552.87", "0.558584"], ["83544.25", "0.003"], ["83529.13", "0.001288"], ["83528.99", "0"], ["83524.95", "0.001288"], ["83524.85", "0"], ["83522.27", "0"]], "a": [["83552.88", "0.467168"], ["83563.08", "0"], ["83579.38", "0.003"], ["83583.42", "0"], ["83589.69", "0.036362"], ["83589.71", "0"], ["83590.02", "0.003"], ["83594.48", "0"], ["83594.68", "0.003917"], ["83595.89", "0"], ["83596.58", "0"], ["83596.59", "0"], ["83596.77", "0.04"], ["83596.78", "0.04"], ["83600.44", "0.001466"]], "u": 971933, "seq": 67263575627}, "cts": 1742377123011, "record_time": 1742377123.88716}
{"topic": "orderbook.200.BTCUSDT", "ts": 1742377123214, "type": "delta", "data": {"s": "BTCUSDT", "b": [["83552.87", "0.583031"], ["83542.85", "0"], ["83536.11", "0.239369"], ["83533.6", "0"], ["83529.13", "0"], ["83524.95", "0"], ["83515.06", "0"], ["83503.5", "0.000157"], ["83503.22", "0.000277"], ["83502.91", "0.00009"], ["83502.5", "0.052"]], "a": [["83562.78", "0.937616"], ["83562.79", "0"], ["83589.68", "0.35908"], ["83589.7", "0"], ["83596.77", "0"], ["83596.79", "0.04"], ["83601", "0.0021"]], "u": 971934, "seq": 67263575682}, "cts": 1742377123212, "record_time": 1742377124.086847}
{"topic": "orderbook.200.BTCUSDT", "ts": 1742377123415, "type": "delta", "data": {"s": "BTCUSDT", "b": [["83533.6", "0.239369"], ["83517.18", "1.399097"], ["83503.22", "0.135686"], ["83502.91", "0"], ["83502.5", "0"]], "a": [["83552.88", "0.463568"], ["83560.13", "0.660715"], ["83560.14", "1.376575"], ["83560.29", "0"], ["83561.91", "0.003492"], ["83566.16", "0"], ["83587.18", "0.007108"], ["83589.67", "0.359083"], ["83589.68", "0"], ["83589.69", "0"], ["83601", "0"]], "u": 971935, "seq": 67263575744}, "cts": 1742377123411, "record_time": 1742377124.287561}
{"topic": "orderbook.200.BTCUSDT", "ts": 1742377123614, "type": "delta", "data": {"s": "BTCUSDT", "b": [["83541.27", "0.100804"], ["83540.57", "0.173929"], ["83534.57", "0.27446"], ["83528.57", "0.452018"]], "a": [["83552.88", "0.463452"], ["83562.64", "0.0036"], ["83563.6", "0.024123"], ["83565.17", "0.173712"], ["83571.17", "0.287494"], ["83577.17", "0.459193"], ["83589.66", "0.359081"], ["83589.67", "0"], ["83600.34", "0"], ["83600.44", "0"]], "u": 971936, "seq": 67263575835}, "cts": 1742377123611, "record_time": 1742377124.486644}
{"topic": "orderbook.200.BTCUSDT", "ts": 1742377123815, "type": "delta", "data": {"s": "BTCUSDT", "b": [["83541.27", "0.099338"], ["83540.57", "0.169042"], ["83534.57", "0.280677"], ["83528.57", "0.450841"]], "a": [["83562.64", "0"], ["83565.17", "0.164215"], ["83571.17", "0.27718"], ["83577.17", "0.479081"], ["83589.66", "0"], ["83590.11", "0.359078"], ["83600.34", "0.000207"]], "u": 971937, "seq": 67263575911}, "cts": 1742377123808, "record_time": 1742377124.687421}
{"topic": "orderbook.200.BTCUSDT", "ts": 1742377124014, "type": "delta", "data": {"s": "BTCUSDT", "b": [["83541.27", "0.055572"], ["83540.57", "0.159484"], ["83534.57", "0.295273"], ["83528.57", "0.451934"]], "a": [["83565.17", "0.161711"], ["83571.17", "0.265785"], ["83577.17", "0.445246"], ["83589.73", "0.359078"], ["83590.11", "0"], ["83594.67", "0.003917"], ["83594.68", "0"], ["83596.77", "0.04"], ["83596.79", "0"], ["83598.1", "0.11"], ["83600.34", "0"]], "u": 971938, "seq": 67263575989}, "cts": 1742377124011, "record_time": 1742377124.886995}
{"topic": "orderbook.200.BTCUSDT", "ts": 1742377124214, "type": "delta", "data": {"s": "BTCUSDT", "b": [["83540.57", "0.162518"], ["83534.57", "0.286762"], ["83533.6", "0"], ["83528.57", "0.476135"], ["83502.91", "0.00009"]], "a": [["83565.17", "0.159937"], ["83571.17", "0.276261"], ["83577.17", "0.435719"]], "u": 971939, "seq": 67263576065}, "cts": 1742377124206, "record_time": 1742377125.087396}
{"topic": "orderbook.200.BTCUSDT", "ts": 1742377124414, "type": "delta", "data": {"s": "BTCUSDT", "b": [["83544.8", "0.000153"], ["83542.26", "0"], ["83541.27", "0.097949"], ["83540.57", "0"], ["83536.04", "0.003"], ["83535.84", "0.003"], ["83535.78", "0"], ["83535.58", "0"], ["83534.57", "0"], ["83528.57", "0"], ["83502.5", "0.052"], ["83502.13", "0.001333"], ["83501.52", "0.000242"]], "a": [["83565.17", "0"], ["83565.36", "0"], ["83571.17", "0"], ["83577.17", "0"], ["83585.87", "0.035917"], ["83587.19", "0"], ["83600.34", "0.000207"], ["83600.44", "0.001466"], ["83601", "0.0021"], ["83601.25", "0.001124"]], "u": 971940, "seq": 67263576143}, "cts": 1742377124411, "record_time": 1742377125.286819}
{"topic": "orderbook.200.BTCUSDT", "ts": 1742377124615, "type": "delta", "data": {"s": "BTCUSDT", "b": [["83544.87", "0.000299"], ["83544.8", "0"], ["83544.42", "0"], ["83543.8", "0.000153"], ["83541.27", "0"], ["83541.2", "0.102595"], ["83540.57", "0.168714"], ["83538.93", "0"], ["83536.11", "0"], ["83535.71", "0"], ["83534.57", "0.293898"], ["83534.29", "0"], ["83533.63", "0.01197"], ["83533.17", "0"], ["83531.09", "0.239369"], ["83530.27", "0"], ["83530.12", "0.239369"], ["83528.57", "0.438553"], ["83526.91", "0"], ["83525.94", "0.239369"], ["83525.07", "0.017956"], ["83523.76", "0"], ["83516.08", "0.071841"], ["83511.41", "0"], ["83510.12", "0"], ["83505.71", "0"], ["83501.21", "0.000333"], ["83501.11", "0.119902"], ["83501.01", "0.179616"], ["83501", "0.000242"]], "a": [["83552.88", "0.467052"], ["83553.21", "0.069776"], ["83554.08", "0.089922"], ["83561.23", "0"], ["83562.78", "0.596645"], ["83562.9", "0"], ["83564.57", "0"], ["83565.17", "0.167777"], ["83571.16", "0"], ["83571.17", "0.297752"], ["83576.09", "0.239369"], ["83576.23", "0.239369"], ["83577.17", "0.422521"], ["83578.2", "0"], ["83579.67", "0"], ["83580.27", "0.239369"], ["83582.48", "0"], ["83584.04", "0.359099"], ["83584.05", "0"], ["83585.87", "0"], ["83586.63", "0.007108"], ["83586.65", "0"], ["83586.91", "0.003"], ["83587.18", "0"], ["83589.73", "0"], ["83592.27", "0.003917"], ["83594.67", "0"], ["83598.1", "0"], ["83601.26", "0.001"], ["83601.47", "0.000333"], ["83602.1", "0.000243"], ["83602.4", "0.001333"], ["83602.46", "0.00315"]], "u": 971941, "seq": 67263576423}, "cts": 1742377124613, "record_time": 1742377125.487792}
{"topic": "orderbook.200.BTCUSDT", "ts": 1742377124814, "type": "delta", "data": {"s": "BTCUSDT", "b": [["83552.87", "0.561768"], ["83542.85", "0.021263"], ["83537.18", "0.02491"], ["83531.09", "0"], ["83530.12", "0"], ["83525.94", "0"], ["83510.07", "0.035917"]], "a": [["83552.88", "0.445789"], ["83562.9", "0.021263"], ["83571.16", "0.374858"], ["83576.09", "0"], ["83576.23", "0"], ["83580.27", "0"], ["83584.03", "0.359098"], ["83584.04", "0"], ["83585.83", "0.035917"], ["83586.62", "0.010298"], ["83586.63", "0"], ["83586.91", "0"], ["83592.26", "0.003917"], ["83592.27", "0"], ["83594.37", "0.04"], ["83594.38", "0.04"], ["83596.77", "0"], ["83596.78", "0"], ["83602.62", "0.000243"]], "u": 971942, "seq": 67263576519}, "cts": 1742377124808, "record_time": 1742377125.686882}
{"topic": "orderbook.200.BTCUSDT", "ts": 1742377125015, "type": "delta", "data": {"s": "BTCUSDT", "b": [["83542.85", "0"], ["83538.51", "0"], ["83537.16", "0.045073"], ["83535.12", "0"], ["83535.07", "0.045074"], ["83534.87", "0.003"], ["83533.6", "0.239369"], ["83533.03", "0"], ["83532.03", "0.22444"], ["83530.12", "0.239369"], ["83528.52", "0.023862"], ["83525.94", "0.239369"], ["83508.68", "0.135413"], ["83503.22", "0.000277"], ["83501.21", "0"], ["83501.11", "0"], ["83501.01", "0"], ["83501", "0"]], "a": [["83553.21", "0.358036"], ["83556.29", "0"], ["83557.47", "1"], ["83558.31", "0.028605"], ["83558.42", "0"], ["83560.4", "0.068605"], ["83562.9", "0.011066"], ["83571.81", "0.003"], ["83576.09", "0.239369"], ["83576.23", "0.239369"], ["83579.01", "0.003"], ["83579.38", "0"], ["83579.4", "0.003"], ["83580.27", "0.239369"], ["83584.03", "0"], ["83585.82", "0.359095"], ["83585.83", "0"], ["83590.02", "0"], ["83602.4", "0"], ["83602.46", "0"], ["83602.62", "0"]], "u": 971943, "seq": 67263576635}, "cts": 1742377125012, "record_time": 1742377125.88812}
{"topic": "orderbook.200.BTCUSDT", "ts": 1742377125214, "type": "delta", "data": {"s": "BTCUSDT", "b": [["83526.91", "0.167559"], ["83501.52", "0"]], "a": [["83585.81", "0.359097"], ["83585.82", "0"], ["83589.61", "0.167559"], ["83592.16", "0.003917"], ["83592.26", "0"], ["83594.36", "0.04"], ["83594.38", "0"], ["83596", "0.063131"], ["83598.73", "0"], ["83602.1", "0"]], "u": 971944, "seq": 67263576754}, "cts": 1742377125212, "record_time": 1742377126.087619}
{"topic": "orderbook.200.BTCUSDT", "ts": 1742377410414, "type": "snapshot", "data": {"s": "BTCUSDT", "b": [["83469.38", "0.097697"], ["83469.17", "0.65"], ["83468.86", "0.000242"], ["83468.74", "0.001333"], ["83468.11", "0.001"], ["83467.81", "0.000333"], ["83467.6", "0.001123"], ["83467.2", "0.001466"], ["83466.56", "0.003"], ["83466.54", "0.000477"], ["83466.49", "0.000276"], ["83465.35", "0.000099"], ["83464.79", "0.000242"], ["83464.57", "0.001333"], ["83464.56", "0.00315"], ["83464.27", "0.000242"], ["83464.11", "0.1665"], ["83463.64", "0.000333"], ["83463.43", "0.015"], ["83463.42", "0.001123"], ["83462.86", "0.071886"], ["83462.82", "0.005"], ["83462.61", "0.001466"], ["83462.12", "0.003"], ["83461.95", "0.00034"], ["83461.92", "0.003"], ["83461.9", "0.000276"], ["83461.65", "0.15973"], ["83461.64", "0.041863"], ["83461.03", "0.0005"], ["83460.39", "0.001333"], ["83460.2", "0.000242"], ["83460", "0.00006"], ["83459.81", "0.00256"], ["83459.68", "0.000242"], ["83459.55", "0.041864"], ["83459.54", "0.00599"], ["83459.51", "0.011981"], ["83459.47", "0.000333"], ["83459.27", "0.000252"], ["83459.25", "0.001123"], ["83459.22", "0.0025"], ["83458.79", "0.167044"], ["83458.51", "0.159999"], ["83458.4", "0.052"], ["83458.3", "0.044"], ["83458.02", "0.001466"], ["83457.9", "0.000199"], ["83457.63", "0.230672"], ["83457.61", "0.165647"], ["83457.31", "0.000276"], ["83456.99", "0.177869"], ["83456.78", "0.003"], ["83456.7", "0.052"], ["83456.6", "0.048"], ["83456.37", "0.000673"], ["83456.22", "0.001333"], ["83456.16", "0.000349"], ["83455.75", "0.1665"], ["83455.61", "0.000242"], ["83455.3", "0.000333"], ["83455.2", "0.005"], ["83455.09", "0.000242"], ["83455.08", "0.001123"], ["83455", "0.068"], ["83454.9", "0.056"], ["83453.43", "0.001466"], ["83453.4", "0.076"], ["83453.3", "0.06"], ["83453.11", "0.334569"], ["83453.1", "0.239609"], ["83452.99", "0.00009"], ["83452.75", "0.000157"], ["83452.72", "0.000276"], ["83452.47", "0.239609"], ["83452.05", "0.001333"], ["83451.89", "0.004021"], ["83451.8", "0.052"], ["83451.6", "0.056"], ["83451.45", "0.005096"], ["83451.12", "0.000333"], ["83451.02", "0.000242"], ["83450.99", "0.293914"], ["83450.91", "0.001123"], ["83450.87", "0.018361"], ["83450.69", "0.001647"], ["83450.5", "0.000242"], ["83450.27", "0.024338"], ["83450.11", "0.27191"], ["83449.97", "0.239609"], ["83449.8", "0.31583"], ["83449.79", "0.276193"], ["83449.76", "0.003"], ["83449.18", "0.018279"], ["83448.93", "0.239609"], ["83448.84", "0.001466"], ["83448.31", "0.266421"], ["83448.19", "0.017972"], ["83448.13", "0.000276"], ["83447.88", "0.001333"], ["83447.4", "0.1665"], ["83447.35", "0.023959"], ["83446.99", "0.009457"], ["83446.95", "0.000333"], ["83446.73", "0.001123"], ["83446.43", "0.000242"], ["83446", "0.000119"], ["83445.91", "0.000242"], ["83445", "0.667539"], ["83444.99", "0.466789"], ["83444.79", "0.002883"], ["83444.75", "0.239609"], ["83444.67", "0.00009"], ["83444.25", "0.001466"], ["83443.79", "0.426571"], ["83443.7", "0.001333"], ["83443.54", "0.000276"], ["83442.85", "0.111706"], ["83442.78", "0.000333"], ["83442.72", "0.001323"], ["83442.67", "0.00018"], ["83442.56", "0.001123"], ["83442.55", "0.015"], ["83442.31", "0.917239"], ["83442.15", "0.003"], ["83441.96", "0.017952"], ["83441.84", "0.000242"], ["83441.81", "0.017952"], ["83441.32", "0.000242"], ["83440.55", "0.035951"], ["83440", "0.00006"], ["83439.96", "0.071906"], ["83439.84", "0.00034"], ["83439.66", "0.001466"], ["83439.53", "0.001333"], ["83439.39", "0.00886"], ["83439.2", "0.000756"], ["83439.06", "0.119902"], ["83439.05", "0.1665"], ["83438.95", "0.000276"], ["83438.92", "0.4"], ["83438.61", "0.000333"], ["83438.54", "0.001323"], ["83438.39", "0.001123"], ["83438.05", "0.003663"], ["83437.25", "0.000242"], ["83437.22", "0.008783"], ["83436.73", "0.000242"], ["83436.55", "0.528955"], ["83436.5", "0.071909"], ["83436.4", "0.00009"], ["83436", "0.005989"], ["83435.99", "0.000395"], ["83435.88", "1.313696"], ["83435.36", "0.001333"], ["83435.24", "0.004617"], ["83435.07", "0.001466"], ["83434.71", "0.023959"], ["83434.43", "0.000333"], ["83434.36", "0.000276"], ["83434.22", "0.001123"], ["83432.66", "0.000242"], ["83432.64", "0.119902"], ["83432.43", "0.167726"], ["83432.22", "0.119804"], ["83432.14", "0.000242"], ["83431.83", "0.005989"], ["83431.71", "0.119804"], ["83431.19", "0.001333"], ["83431.16", "0.00599"], ["83430.7", "0.1665"], ["83430.48", "0.001466"], ["83430.35", "0.060553"], ["83430.26", "0.000333"], ["83430.04", "0.001123"], ["83430", "0.0001"], ["83429.98", "0.00003"], ["83429.82", "0.02396"], ["83429.77", "0.000276"], ["83429.52", "0.135792"], ["83428.98", "0.000085"], ["83428.77", "0.000111"], ["83428.68", "0.018279"], ["83428.07", "0.000242"], ["83428.03", "0.00009"], ["83427.98", "0.000568"], ["83427.59", "0.119902"], ["83427.55", "0.000242"], ["83427.02", "0.001333"], ["83426.93", "0.02396"], ["83426.37", "0.023959"], ["83426.09", "0.000333"], ["83425.89", "0.001466"], ["83425.87", "0.001123"], ["83425.53", "0.001917"], ["83425.22", "0.485193"], ["83425.18", "0.000276"], ["83424.17", "0.003663"], ["83424.08", "0.11"], ["83423.55", "0.001"]], "a": [["83469.39", "0.591278"], ["83470", "0.0036"], ["83472.91", "0.003"], ["83472.92", "0.16952"], ["83472.98", "0.000153"], ["83472.99", "0.000099"], ["83473.46", "0.000981"], ["83473.55", "0.011979"], ["83473.97", "0.000242"], ["83474.61", "0.009682"], ["83474.93", "0.097791"], ["83475.67", "0.000277"], ["83475.75", "0.011979"], ["83475.94", "0.001113"], ["83476.16", "0.000333"], ["83476.2", "0.089922"], ["83476.38", "0.001466"], ["83477.09", "0.001333"], ["83477.65", "0.011981"], ["83477.73", "1.052002"], ["83477.74", "0.0005"], ["83477.93", "0.023963"], ["83477.94", "0.468964"], ["83477.96", "0.00009"], ["83478.04", "0.000242"], ["83478.51", "0.00599"], ["83478.56", "0.000242"], ["83479.66", "0.001968"], ["83479.67", "0.004136"], ["83479.79", "0.163407"], ["83480", "0.00024"], ["83480.11", "0.165416"], ["83480.12", "0.001113"], ["83480.13", "0.239578"], ["83480.26", "0.000277"], ["83480.34", "0.000333"], ["83480.35", "0.251354"], ["83480.56", "1.319909"], ["83480.59", "0.001106"], ["83480.63", "0.003"], ["83480.95", "0.00599"], ["83480.97", "0.001466"], ["83481.01", "0.180148"], ["83481.26", "0.001333"], ["83481.49", "0.037732"], ["83481.59", "0.167802"], ["83481.8", "0.239573"], ["83482.63", "0.000242"], ["83482.87", "0.030855"], ["83483.16", "0.000242"], ["83483.5", "0.04"], ["83484.29", "0.001113"], ["83484.3", "0.04"], ["83484.51", "0.000333"], ["83484.85", "0.000277"], ["83484.86", "0.1665"], ["83484.96", "0.030854"], ["83485", "0.04"], ["83485.09", "0.003534"], ["83485.2", "0.04"], ["83485.44", "0.001333"], ["83485.53", "0.005173"], ["83485.57", "0.001466"], ["83486.06", "0.075324"], ["83486.11", "0.239561"], ["83486.28", "0.00009"], ["83486.48", "0.535503"], ["83486.6", "0.04"], ["83486.75", "0.071866"], ["83486.78", "0.089922"], ["83486.9", "0.04"], ["83487.22", "0.000242"], ["83487.59", "0.29011"], ["83487.74", "0.024"], ["83487.75", "0.000242"], ["83487.97", "0.075324"], ["83488.44", "0.00599"], ["83488.47", "0.001113"], ["83488.5", "0.04"], ["83488.51", "0.27923"], ["83488.68", "0.000333"], ["83488.79", "0.296674"], ["83489.3", "0.04"], ["83489.36", "0.060553"], ["83489.44", "0.000277"], ["83489.61", "0.001333"], ["83489.88", "0.059896"], ["83490.16", "0.001466"], ["83490.2", "0.04"], ["83490.31", "0.295319"], ["83490.55", "0.003"], ["83490.69", "0.239593"], ["83491", "0.04"], ["83491.3", "0.035951"], ["83491.82", "0.000242"], ["83492.34", "0.000242"], ["83492.56", "0.239609"], ["83492.63", "0.01936"], ["83492.64", "0.001113"], ["83492.86", "0.000333"], ["83492.98", "0.07186"], ["83493.29", "0.119902"], ["83493.59", "0.455018"], ["83493.77", "0.111715"], ["83493.78", "0.001333"], ["83493.97", "0.009115"], ["83494.04", "0.000277"], ["83494.09", "0.024317"], ["83494.6", "0.00009"], ["83494.75", "0.001466"], ["83494.79", "0.475695"], ["83494.86", "0.239593"], ["83495.07", "0.167726"], ["83495.19", "0.004688"], ["83496.13", "0.1665"], ["83496.24", "0.001124"], ["83496.31", "0.874268"], ["83496.41", "0.000242"], ["83496.82", "0.001113"], ["83496.93", "0.000242"], ["83497.03", "0.000333"], ["83497.11", "0.023623"], ["83497.35", "0.075244"], ["83497.46", "0.08302"], ["83497.96", "0.001333"], ["83498.63", "0.000277"], ["83498.71", "0.119902"], ["83499.34", "0.001466"], ["83500", "0.01736"], ["83500.07", "0.037732"], ["83500.22", "0.089922"], ["83500.41", "0.001124"], ["83500.99", "0.001113"], ["83501", "0.000242"], ["83501.01", "0.005"], ["83501.21", "0.000333"], ["83501.52", "0.000242"], ["83502.13", "0.001333"], ["83502.37", "0.000299"], ["83502.67", "0.02396"], ["83502.9", "0.0006"], ["83502.92", "0.00009"], ["83503.22", "0.000277"], ["83503.94", "0.001466"], ["83503.98", "0.359448"], ["83503.99", "0.060553"], ["83504.83", "0.119902"], ["83505.17", "0.001113"], ["83505.27", "0.00018"], ["83505.38", "0.000333"], ["83505.59", "0.000243"], ["83506.12", "0.000243"], ["83506.31", "0.001333"], ["83506.53", "0.017952"], ["83506.8", "0.029602"], ["83507.52", "0.581984"], ["83507.68", "0.014065"], ["83507.76", "0.003663"], ["83507.8", "0.0006"], ["83507.81", "0.000277"], ["83507.9", "0.0006"], ["83508.19", "0.1665"], ["83508.53", "0.001466"], ["83509.34", "0.001113"], ["83509.5", "0.015"], ["83509.56", "0.000333"], ["83509.91", "0.023959"], ["83510", "0.029924"], ["83510.19", "0.000243"], ["83510.27", "0.119902"], ["83510.49", "0.001333"], ["83510.68", "0.023959"], ["83510.71", "0.000243"], ["83511.11", "0.478931"], ["83511.42", "0.001714"], ["83511.48", "0.71128"], ["83512.41", "0.000277"], ["83512.44", "0.017952"], ["83512.67", "0.060553"], ["83513.12", "0.001466"], ["83513.52", "0.001114"], ["83513.58", "0.023959"], ["83513.73", "0.000333"], ["83513.78", "0.003682"], ["83514.11", "0.063133"], ["83514.66", "0.001333"], ["83514.78", "0.000243"], ["83514.8", "0.0006"], ["83514.88", "0.11"], ["83515.3", "0.000243"], ["83515.61", "0.119902"], ["83515.72", "0.00599"], ["83515.74", "0.119796"], ["83515.95", "0.167715"], ["83516", "0.000119"], ["83516.29", "0.04"], ["83516.3", "0.04"], ["83516.54", "0.1665"], ["83516.76", "0.037732"], ["83516.8", "0.24332"]], "u": 973369, "seq": 67263895040}, "cts": 1742377410401, "record_time": 1742377413.277276}
{"topic": "orderbook.200.BTCUSDT", "ts": 1742377410614, "type": "delta", "data": {"s": "BTCUSDT", "b": [["83443.2", "0.001241"], ["83442.72", "0"], ["83439.03", "0.001241"], ["83438.54", "0"]], "a": [["83470.21", "0.00488"], ["83472.98", "0"], ["83483.72", "0.023554"], ["83516.8", "0"]], "u": 973370, "seq": 67263895083}, "cts": 1742377410611, "record_time": 1742377413.278492}
{"topic": "orderbook.200.BTCUSDT", "ts": 1742377410815, "type": "delta", "data": {"s": "BTCUSDT", "b": [["83461.64", "0"], ["83458.77", "0.041866"], ["83444.54", "0.001069"], ["83443.2", "0"], ["83443.14", "0.00125"], ["83440.37", "0.001069"], ["83439.03", "0"], ["83438.97", "0.00125"], ["83429.52", "0.135796"], ["83424.08", "0"], ["83423.55", "0"]], "a": [["83469.39", "0.589973"], ["83471.64", "0.000153"], ["83480", "0.031094"], ["83482.87", "0"], ["83513.77", "0.003682"], ["83513.78", "0"]], "u": 973371, "seq": 67263895135}, "cts": 1742377410806, "record_time": 1742377413.279273}
{"topic": "orderbook.200.BTCUSDT", "ts": 1742377411014, "type": "delta", "data": {"s": "BTCUSDT", "b": [["83454.98", "0.239609"], ["83452.47", "0"], ["83449.97", "0"], ["83444.75", "0"], ["83444.54", "0"], ["83443.14", "0"], ["83442.76", "0.001315"], ["83440.37", "0"], ["83438.97", "0"], ["83438.59", "0.001314"], ["83424.08", "0.11"], ["83423.55", "0.001"], ["83423.49", "0.000242"], ["83423.19", "0.01656"]], "a": [["83469.39", "0.452273"], ["83470.21", "0"], ["83471.64", "0"], ["83472.92", "0.169673"], ["83476.2", "0"], ["83513.77", "0.003673"], ["83516.28", "0.04"], ["83516.3", "0"], ["83516.8", "0.24332"], ["83516.88", "0.11"], ["83516.97", "0.003663"]], "u": 973372, "seq": 67263895215}, "cts": 1742377411011, "record_time": 1742377413.280004}
{"topic": "orderbook.200.BTCUSDT", "ts": 1742377411214, "type": "delta", "data": {"s": "BTCUSDT", "b": [["83464.12", "0.078392"], ["83456.99", "0.159649"], ["83450.99", "0.289746"], ["83449.95", "0.003"], ["83449.76", "0"], ["83444.99", "0.444375"], ["83443.94", "0.001138"], ["83442.76", "0"], ["83442.41", "0.003"], ["83442.15", "0"], ["83439.81", "0.001133"], ["83438.59", "0"], ["83423.19", "0"]], "a": [["83472.04", "0.000153"], ["83472.92", "0.16952"], ["83481.59", "0.168822"], ["83487.59", "0.297316"], ["83490.44", "0.003"], ["83490.55", "0"], ["83493.59", "0.472327"], ["83516.97", "0"]], "u": 973373, "seq": 67263895307}, "cts": 1742377411206, "record_time": 1742377413.280775}
{"topic": "orderbook.200.BTCUSDT", "ts": 1742377411414, "type": "delta", "data": {"s": "BTCUSDT", "b": [["83456.99", "0.168258"], ["83450.99", "0.284243"], ["83444.99", "0.449515"], ["83444.72", "0.001051"], ["83443.94", "0"], ["83443.39", "0.001212"], ["83443.07", "0.001262"], ["83439.81", "0"], ["83439.22", "0.001212"], ["83423.55", "0"], ["83423.49", "0"]], "a": [["83469.39", "0.456138"], ["83481.59", "0.157915"], ["83487.59", "0.277334"], ["83493.59", "0.440668"]], "u": 973374, "seq": 67263895379}, "cts": 1742377411411, "record_time": 1742377413.281596}
{"topic": "orderbook.200.BTCUSDT", "ts": 1742377411615, "type": "delta", "data": {"s": "BTCUSDT", "b": [["83456.99", "0.162731"], ["83450.99", "0.278909"], ["83444.99", "0.438205"], ["83444.74", "0.001049"], ["83444.72", "0"], ["83443.39", "0"], ["83443.07", "0"], ["83440.56", "0.001049"], ["83439.22", "0"], ["83423.55", "0.001"], ["83423.49", "0.000242"]], "a": [["83469.39", "0.593838"], ["83470.21", "0.002094"], ["83481.59", "0.175736"], ["83487.59", "0.274233"], ["83493.59", "0.467604"], ["83516.88", "0"]], "u": 973375, "seq": 67263895473}, "cts": 1742377411610, "record_time": 1742377413.282324}
{"topic": "orderbook.200.BTCUSDT", "ts": 1742377411814, "type": "delta", "data": {"s": "BTCUSDT", "b": [["83469.38", "0.08137"], ["83461.65", "0.146306"], ["83458.79", "0"], ["83458.78", "0.170571"], ["83458.51", "0"], ["83458.5", "0.174627"], ["83450.11", "0"], ["83450.1", "0.274153"], ["83449.79", "0"], ["83449.78", "0.271664"], ["83444.74", "0"], ["83444.24", "0.071902"], ["83443.79", "0"], ["83443.78", "0.441846"], ["83442.31", "0.470434"], ["83442.3", "0.46534"], ["83440.56", "0"], ["83438.14", "0.001403"], ["83436.5", "0"]], "a": [["83469.39", "0.592838"], ["83470.21", "0.000701"], ["83472.04", "0"], ["83474.25", "0.000153"], ["83479.78", "0.168532"], ["83479.79", "0"], ["83480.1", "0.173623"], ["83480.11", "0"], ["83488.5", "0.332"], ["83488.51", "0"], ["83488.78", "0.279728"], ["83488.79", "0"], ["83494.78", "0.466164"], ["83494.79", "0"], ["83496.3", "0.467498"], ["83496.31", "0.450504"]], "u": 973376, "seq": 67263895563}, "cts": 1742377411811, "record_time": 1742377413.283044}
{"topic": "orderbook.200.BTCUSDT", "ts": 1742377412014, "type": "delta", "data": {"s": "BTCUSDT", "b": [["83442.62", "0.00134"], ["83442.31", "0.469031"], ["83438.45", "0.00134"], ["83438.14", "0"], ["83423.49", "0"]], "a": [["83470.21", "0.000209"], ["83475.45", "0.089922"], ["83514.88", "0"]], "u": 973377, "seq": 67263895627}, "cts": 1742377412010, "record_time": 1742377413.283764}
{"topic": "orderbook.200.BTCUSDT", "ts": 1742377412214, "type": "delta", "data": {"s": "BTCUSDT", "b": [["83469.38", "0.095288"], ["83458.78", "0"], ["83458.5", "0"], ["83452.47", "0.239609"], ["83450.1", "0"], ["83449.78", "0"], ["83444.32", "0.001093"], ["83443.78", "0"], ["83442.62", "0"], ["83442.3", "0"], ["83440.15", "0.001093"], ["83438.45", "0"], ["83435.88", "0"], ["83431.59", "1.340359"], ["83423.49", "0.000242"], ["83423.19", "0.01656"], ["83423.06", "0.195"], ["83422.96", "0.000242"], ["83422.84", "0.001333"]], "a": [["83479.78", "0"], ["83480.07", "1.318163"], ["83480.1", "0"], ["83480.56", "0"], ["83488.5", "0.04"], ["83488.78", "0"], ["83494.78", "0"], ["83496.3", "0"], ["83516.88", "0.11"], ["83516.97", "0.003663"], ["83517", "0.000277"], ["83517.69", "0.001114"], ["83517.71", "0.001466"]], "u": 973378, "seq": 67263895698}, "cts": 1742377412210, "record_time": 1742377413.284585}
{"topic": "orderbook.200.BTCUSDT", "ts": 1742377412414, "type": "delta", "data": {"s": "BTCUSDT", "b": [["83461.65", "0.144101"], ["83458.79", "0.166212"], ["83458.51", "0.171636"], ["83457.01", "0.003"], ["83456.99", "0"], ["83450.99", "0"], ["83450.11", "0.268632"], ["83449.8", "0.224199"], ["83449.79", "0.28569"], ["83445", "0"], ["83444.99", "0"], ["83444.32", "0"], ["83443.79", "0.442865"], ["83443", "0.001273"], ["83442.31", "0.952007"], ["83440.15", "0"], ["83438.83", "0.001273"], ["83438.18", "0.001394"], ["83429.52", "0.135797"], ["83423.06", "0"], ["83422.96", "0"], ["83422.84", "0"]], "a": [["83469.39", "0.455138"], ["83470.21", "0"], ["83473.08", "0.000153"], ["83474.25", "0"], ["83479.79", "0.160515"], ["83480.11", "0.171917"], ["83481.59", "0"], ["83487.59", "0"], ["83488.51", "0.264473"], ["83488.79", "0.28808"], ["83493.59", "0"], ["83494.79", "0.450502"], ["83496.31", "0.917974"], ["83517.71", "0"]], "u": 973379, "seq": 67263895814}, "cts": 1742377412409, "record_time": 1742377413.299129}
{"topic": "orderbook.200.BTCUSDT", "ts": 1742377412614, "type": "delta", "data": {"s": "BTCUSDT", "b": [["83444.7", "0.001053"], ["83443.8", "0.469573"], ["83443", "0"], ["83442.61", "0.001342"], ["83438.84", "0.001271"], ["83438.83", "0"], ["83438.18", "0"], ["83423.19", "0"]], "a": [["83513.77", "0"], ["83513.87", "0.003673"], ["83516.28", "0"], ["83516.29", "0"], ["83516.38", "0.04"], ["83516.39", "0.04"]], "u": 973380, "seq": 67263895899}, "cts": 1742377412610, "record_time": 1742377413.499764}
{"topic": "orderbook.200.BTCUSDT", "ts": 1742377412814, "type": "delta", "data": {"s": "BTCUSDT", "b": [["83457.04", "0.168033"], ["83451.04", "0.285075"], ["83445.04", "0.428249"], ["83444.7", "0"], ["83442.98", "0.001277"], ["83442.61", "0"], ["83438.84", "0"], ["83438.81", "0.001277"], ["83429.52", "0"], ["83423.49", "0"]], "a": [["83469.39", "0.433782"], ["83479.4", "0.021356"], ["83481.64", "0.172437"], ["83487.64", "0.293571"], ["83493.64", "0.47149"], ["83513.86", "0.003673"], ["83513.87", "0"], ["83516.88", "0"], ["83516.97", "0"], ["83517", "0"], ["83517.69", "0"]], "u": 973381, "seq": 67263895978}, "cts": 1742377412808, "record_time": 1742377413.698366}
{"topic": "orderbook.200.BTCUSDT", "ts": 1742377413015, "type": "delta", "data": {"s": "BTCUSDT", "b": [["83457.04", "0.174019"], ["83452.47", "0"], ["83451.04", "0.298614"], ["83445.04", "0.431877"], ["83442.98", "0"], ["83442.87", "0.001295"], ["83442.35", "0.001394"], ["83438.81", "0"], ["83438.18", "0.001394"]], "a": [["83481.64", "0.17367"], ["83487.64", "0.291406"], ["83493.64", "0.462184"], ["83514.88", "0.11"], ["83516.37", "0.04"], ["83516.39", "0"], ["83516.8", "0"]], "u": 973382, "seq": 67263896071}, "cts": 1742377413004, "record_time": 1742377413.900296}
{"topic": "orderbook.200.BTCUSDT", "ts": 1742377413214, "type": "delta", "data": {"s": "BTCUSDT", "b": [["83457.04", "0"], ["83451.04", "0"], ["83450.33", "0.003"], ["83449.95", "0"], ["83445.04", "0"], ["83443.78", "0.001158"], ["83442.97", "0.003"], ["83442.87", "0"], ["83442.41", "0"], ["83442.35", "0.001395"], ["83439.61", "0.001158"], ["83438.18", "0.001395"], ["83423.49", "0.000242"], ["83423.19", "0.01656"]], "a": [["83481.64", "0"], ["83487.64", "0"], ["83490.21", "0.003"], ["83490.44", "0"], ["83493.64", "0"], ["83511.73", "0.000149"], ["83516.8", "0.24332"], ["83516.88", "0.11"]], "u": 973383, "seq": 67263896166}, "cts": 1742377413209, "record_time": 1742377414.099014}
{"topic": "orderbook.200.BTCUSDT", "ts": 1742377413415, "type": "delta", "data": {"s": "BTCUSDT", "b": [["83456.99", "0.157481"], ["83453.11", "0.228173"], ["83450.99", "0.27118"], ["83444.99", "0.440267"], ["83443.78", "0"], ["83443.64", "0.001177"], ["83443.36", "0.001217"], ["83442.44", "0.001376"], ["83442.35", "0"], ["83439.61", "0"], ["83439.47", "0.001177"], ["83438.18", "0"], ["83423.55", "0"], ["83423.49", "0"], ["83423.19", "0"]], "a": [["83469.39", "0.432427"], ["83470.21", "0.00279"], ["83481.59", "0.178987"], ["83486.28", "0.071956"], ["83487.59", "0.280905"], ["83492.98", "0"], ["83493.59", "0.433648"], ["83514.88", "0"], ["83516.8", "0"], ["83516.88", "0"]], "u": 973384, "seq": 67263896237}, "cts": 1742377413411, "record_time": 1742377414.299332}
{"topic": "orderbook.200.BTCUSDT", "ts": 1742377413615, "type": "delta", "data": {"s": "BTCUSDT", "b": [["83456.99", "0.17513"], ["83454.98", "0"], ["83453.1", "0"], ["83451.45", "0"], ["83450.99", "0.287617"], ["83444.99", "0.474177"], ["83444.31", "0.001094"], ["83443.64", "0"], ["83443.36", "0"], ["83442.44", "0"], ["83440.55", "0"], ["83440.46", "0.035951"], ["83440.14", "0.001094"], ["83439.47", "0"], ["83423.55", "0.001"], ["83423.49", "0.000242"], ["83423.19", "0.01656"], ["83423.06", "0.195"], ["83422.96", "0.000242"]], "a": [["83469.39", "0.453783"], ["83478.22", "0.5"], ["83479.4", "0"], ["83481.59", "0.178496"], ["83487.59", "0.281661"], ["83493.59", "0.442521"]], "u": 973385, "seq": 67263896323}, "cts": 1742377413611, "record_time": 1742377414.499556}
{"topic": "orderbook.200.BTCUSDT", "ts": 1742377413814, "type": "delta", "data": {"s": "BTCUSDT", "b": [["83456.99", "0.166656"], ["83450.99", "0.267482"], ["83449.97", "0.239609"], ["83444.99", "0.42047"], ["83444.75", "0.239609"], ["83444.31", "0"], ["83440.14", "0"]], "a": [["83470.21", "0.006601"], ["83481.59", "0.177918"], ["83487.59", "0.279661"], ["83493.59", "0.438518"]], "u": 973386, "seq": 67263896395}, "cts": 1742377413811, "record_time": 1742377414.698466}
{"topic": "orderbook.200.BTCUSDT", "ts": 1742377414014, "type": "delta", "data": {"s": "BTCUSDT", "b": [["83469.17", "0"], ["83464.12", "0"], ["83461.65", "0.048854"], ["83458.79", "0"], ["83458.51", "0"], ["83457.63", "0.121821"], ["83457.61", "0"], ["83456.99", "0"], ["83456.87", "0.161932"], ["83456.59", "0.162044"], ["83456.11", "0.164033"], ["83454.65", "0.171357"], ["83450.99", "0"], ["83450.11", "0"], ["83449.79", "0"], ["83448.65", "0.297451"], ["83448.31", "0"], ["83448.19", "0.30286"], ["83447.87", "0.27475"], ["83446.81", "0.272407"], ["83444.99", "0"], ["83443.79", "0"], ["83442.65", "0.471313"], ["83442.31", "0"], ["83441.87", "0.446657"], ["83440.81", "0.430466"], ["83440.39", "0.475932"], ["83437.95", "0.003428"], ["83422.84", "0.001333"]], "a": [["83469.39", "0.610744"], ["83470.21", "0.01198"], ["83477.87", "0.171454"], ["83478.19", "0.173788"], ["83478.64", "0.111708"], ["83479.25", "0.177785"], ["83479.51", "0.172032"], ["83479.79", "0"], ["83480.11", "0"], ["83481.01", "0"], ["83481.59", "0"], ["83485.25", "0.299138"], ["83486.59", "0.277548"], ["83486.87", "0.301963"], ["83487.59", "0"], ["83488.51", "0"], ["83488.79", "0"], ["83488.81", "0.266461"], ["83490.31", "0"], ["83491.25", "0.447163"], ["83492.87", "0.430516"], ["83493.59", "0"], ["83493.77", "0"], ["83494.39", "0.481017"], ["83494.79", "0"], ["83494.81", "0.429692"], ["83496.31", "0"], ["83513.86", "0.003672"], ["83516.76", "0"]], "u": 973387, "seq": 67263896506}, "cts": 1742377414012, "record_time": 1742377414.898511}
{"topic": "orderbook.200.BTCUSDT", "ts": 1742377414214, "type": "delta", "data": {"s": "BTCUSDT", "b": [["83469.38", "0.094288"], ["83469.17", "0.52"], ["83461.65", "0.14381"], ["83458.79", "0.165417"], ["83458.51", "0.171458"], ["83457.63", "0.304403"], ["83457.61", "0.171083"], ["83456.99", "0.17486"], ["83456.87", "0"], ["83456.59", "0"], ["83456.11", "0"], ["83454.65", "0"], ["83453.11", "0"], ["83451.45", "0.005085"], ["83450.99", "0.271506"], ["83450.11", "0.298572"], ["83449.79", "0.304922"], ["83448.65", "0"], ["83448.31", "0.290036"], ["83448.19", "0.017972"], ["83447.87", "0"], ["83446.81", "0"], ["83444.99", "0.431039"], ["83443.8", "0"], ["83443.79", "0.445771"], ["83442.65", "0"], ["83442.31", "0.905984"], ["83441.87", "0"], ["83440.81", "0"], ["83440.39", "0"]], "a": [["83477.87", "0"], ["83478.19", "0"], ["83479.25", "0"], ["83479.51", "0"], ["83479.79", "0.181383"], ["83480.06", "0.141812"], ["83480.11", "0.158867"], ["83481.01", "0.178175"], ["83481.59", "0.157382"], ["83485.25", "0"], ["83486.59", "0"], ["83486.87", "0"], ["83487.59", "0.262406"], ["83488.51", "0.27463"], ["83488.79", "0.287689"], ["83488.81", "0"], ["83490.31", "0.266141"], ["83491.25", "0"], ["83492.87", "0"], ["83493.59", "0.419585"], ["83494.39", "0"], ["83494.79", "0.455821"], ["83494.81", "0"], ["83496.31", "0.915476"], ["83507.67", "0.023961"], ["83516.54", "0"]], "u": 973388, "seq": 67263896641}, "cts": 1742377414210, "record_time": 1742377415.098962}
{"topic": "orderbook.200.BTCUSDT", "ts": 1742377414414, "type": "delta", "data": {"s": "BTCUSDT", "b": [["83469.38", "0.094902"], ["83457.63", "0.210377"], ["83456.78", "0"], ["83422.58", "0.119902"]], "a": [["83514.88", "0.11"], ["83516.38", "0"]], "u": 973389, "seq": 67263896659}, "cts": 1742377414408, "record_time": 1742377415.299257}
{"topic": "orderbook.200.BTCUSDT", "ts": 1742377414614, "type": "delta", "data": {"s": "BTCUSDT", "b": [["83451.81", "0.219735"], ["83422.58", "0"]], "a": [], "u": 973390, "seq": 67263896682}, "cts": 1742377414607, "record_time": 1742377415.498681}
{"topic": "orderbook.200.BTCUSDT", "ts": 1742377414814, "type": "delta", "data": {"s": "BTCUSDT", "b": [["83444.76", "0.550176"], ["83422.84", "0"]], "a": [["83513.75", "0.003672"], ["83513.86", "0"]], "u": 973391, "seq": 67263896707}, "cts": 1742377414807, "record_time": 1742377415.698738}
{"topic": "orderbook.200.BTCUSDT", "ts": 1742377415014, "type": "delta", "data": {"s": "BTCUSDT", "b": [["83452.47", "0.239609"], ["83449.97", "0"], ["83444.14", "0.023961"], ["83422.96", "0"]], "a": [["83499.88", "0.023961"], ["83513.75", "0"], ["83513.85", "0.003672"], ["83516.37", "0"]], "u": 973392, "seq": 67263896738}, "cts": 1742377415012, "record_time": 1742377415.898482}
{"topic": "orderbook.200.BTCUSDT", "ts": 1742377415215, "type": "delta", "data": {"s": "BTCUSDT", "b": [["83469.38", "0.095902"], ["83450.33", "0"], ["83450.05", "0.003"], ["83442.97", "0"], ["83442.56", "0.004123"], ["83422.96", "0.000242"]], "a": [["83469.39", "0.589388"], ["83479.4", "0.021356"], ["83490.21", "0"], ["83490.38", "0.003"], ["83516", "0"]], "u": 973393, "seq": 67263896777}, "cts": 1742377415210, "record_time": 1742377416.099005}
{"topic": "orderbook.200.BTCUSDT", "ts": 1742377415414, "type": "delta", "data": {"s": "BTCUSDT", "b": [["83469.38", "0"], ["83462.86", "0"], ["83461.65", "0"], ["83461.05", "0.071888"], ["83458.8", "0.13028"], ["83458.79", "0"], ["83458.76", "0.183168"], ["83458.51", "0"], ["83458.48", "0.168965"], ["83457.63", "0"], ["83457.61", "0"], ["83457.58", "0.174509"], ["83456.99", "0"], ["83456.97", "0.168497"], ["83452.47", "0"], ["83451.45", "0"], ["83450.99", "0"], ["83450.97", "0.299484"], ["83450.11", "0"], ["83450.08", "0.298224"], ["83449.79", "0"], ["83449.76", "0.269152"], ["83448.93", "0"], ["83448.31", "0"], ["83448.28", "0.274589"], ["83444.99", "0"], ["83444.97", "0.471749"], ["83444.75", "0"], ["83444.24", "0"], ["83443.79", "0"], ["83443.76", "0.428289"], ["83442.31", "0"], ["83442.28", "0.901295"], ["83439.06", "0"], ["83436.7", "0.071909"], ["83436.08", "0.489925"], ["83432.43", "0"], ["83432.22", "0"], ["83431.59", "0"], ["83425.22", "0"], ["83424.08", "0"], ["83422.84", "0.001333"], ["83422.58", "0.119902"], ["83422.56", "0.013851"], ["83421.93", "0.060553"], ["83421.92", "0.000333"], ["83421.7", "0.001123"], ["83421.34", "0.13579"], ["83421.31", "0.001466"], ["83420.59", "0.000276"], ["83420.01", "0.023959"], ["83420", "0.05206"]], "a": [["83469.18", "0.119551"], ["83469.39", "0.914933"], ["83472.22", "0.000153"], ["83473.08", "0"], ["83477.72", "0.141812"], ["83479.4", "0"], ["83479.76", "0.180472"], ["83479.79", "0"], ["83480.07", "0"], ["83480.08", "0.172624"], ["83480.11", "0"], ["83480.98", "0.182765"], ["83481.01", "0"], ["83481.57", "0.162431"], ["83481.59", "0"], ["83487.57", "0.284206"], ["83487.59", "0"], ["83488.48", "0.289607"], ["83488.51", "0"], ["83488.76", "0.290346"], ["83488.79", "0"], ["83489.18", "0.029602"], ["83490.28", "0.301075"], ["83490.31", "0"], ["83493.57", "0.469679"], ["83493.59", "0"], ["83494.76", "0.483691"], ["83494.79", "0"], ["83496.24", "0"], ["83496.28", "0.868276"], ["83496.31", "0"], ["83498.7", "0.359457"], ["83503.98", "0"], ["83506.8", "0"], ["83516", "0.000119"]], "u": 973394, "seq": 67263897161}, "cts": 1742377415411, "record_time": 1742377416.298621}
{"topic": "orderbook.200.BTCUSDT", "ts": 1742377415614, "type": "delta", "data": {"s": "BTCUSDT", "b": [["83469.17", "0.524793"], ["83464.11", "0"], ["83461.03", "0"], ["83460.82", "0.0005"], ["83458.8", "0.07563"], ["83458.76", "0"], ["83458.65", "0.169967"], ["83458.48", "0"], ["83458.37", "0.175767"], ["83457.59", "0.225732"], ["83457.58", "0"], ["83457.47", "0.161787"], ["83456.97", "0"], ["83456.86", "0.175279"], ["83451.38", "0.005139"], ["83450.97", "0"], ["83450.86", "0.262573"], ["83450.08", "0"], ["83449.97", "0.295382"], ["83449.76", "0"], ["83449.65", "0.294145"], ["83448.93", "0.239609"], ["83448.28", "0"], ["83448.17", "0.275893"], ["83447.46", "0.239609"], ["83444.97", "0"], ["83444.86", "0.456193"], ["83444.75", "0.239609"], ["83443.76", "0"], ["83443.65", "0.438384"], ["83442.28", "0"], ["83442.17", "0.867184"], ["83439.06", "0.172597"], ["83435.92", "1.311099"], ["83432.43", "0.167727"], ["83422.35", "0.1665"], ["83421.93", "0"], ["83421.92", "0"], ["83421.7", "0"], ["83421.34", "0"], ["83421.31", "0"], ["83420.59", "0"], ["83420.01", "0"], ["83420", "0"]], "a": [["83469.18", "2.674121"], ["83469.19", "0.0036"], ["83469.39", "0.397804"], ["83471.45", "0.000153"], ["83472.22", "0"], ["83472.92", "0.1665"], ["83472.99", "0"], ["83477.53", "0.0005"], ["83477.74", "0"], ["83479.65", "0.164413"], ["83479.76", "0"], ["83479.97", "0.180613"], ["83480.05", "1.369543"], ["83480.08", "0"], ["83480.87", "0.167154"], ["83480.98", "0"], ["83481.46", "0.171474"], ["83481.57", "0"], ["83487.46", "0.266343"], ["83487.57", "0"], ["83488.37", "0.297547"], ["83488.48", "0"], ["83488.65", "0.276058"], ["83488.76", "0"], ["83490.06", "0.239609"], ["83490.17", "0.272587"], ["83490.28", "0"], ["83492.56", "0"], ["83493.46", "0.435874"], ["83493.57", "0"], ["83494.65", "0.46338"], ["83494.76", "0"], ["83496.17", "0.882123"], ["83496.28", "0"], ["83498.7", "0"], ["83500.06", "0.359459"], ["83510.9", "0.478931"], ["83511.11", "0"], ["83514.88", "0"]], "u": 973395, "seq": 67263897457}, "cts": 1742377415606, "record_time": 1742377416.49884}
{"topic": "orderbook.200.BTCUSDT", "ts": 1742377415814, "type": "delta", "data": {"s": "BTCUSDT", "b": [["83451.81", "0.127499"], ["83449.8", "0.359142"], ["83440.58", "0.239609"], ["83439.07", "0.119902"], ["83432.22", "0.119805"], ["83422.58", "0"], ["83422.56", "0"], ["83422.35", "0"]], "a": [["83469.18", "2.533214"], ["83469.39", "0.240843"], ["83472.78", "0.000099"], ["83500.06", "0"], ["83503.98", "0.359454"], ["83516", "0"]], "u": 973396, "seq": 67263897505}, "cts": 1742377415807, "record_time": 1742377416.699127}
{"topic": "orderbook.200.BTCUSDT", "ts": 1742377416014, "type": "delta", "data": {"s": "BTCUSDT", "b": [["83457.23", "0.003"], ["83429.52", "0.135788"], ["83422.96", "0"], ["83422.84", "0"]], "a": [["83469.18", "2.55457"], ["83500.06", "0.359455"], ["83503.98", "0"], ["83513.82", "0.003672"], ["83513.85", "0"]], "u": 973397, "seq": 67263897573}, "cts": 1742377416009, "record_time": 1742377416.898735}
{"topic": "orderbook.200.BTCUSDT", "ts": 1742377416214, "type": "delta", "data": {"s": "BTCUSDT", "b": [["83469.17", "0.537373"]], "a": [["83469.18", "2.512431"], ["83469.39", "0.240736"], ["83477.78", "0.008783"], ["83500.06", "0"], ["83503.98", "0.359454"], ["83515.95", "0"]], "u": 973398, "seq": 67263897636}, "cts": 1742377416210, "record_time": 1742377417.098387}
{"topic": "orderbook.200.BTCUSDT", "ts": 1742377416414, "type": "delta", "data": {"s": "BTCUSDT", "b": [["83457.01", "0"], ["83449.11", "0.239609"], ["83447.46", "0"], ["83440.58", "0"], ["83422.96", "0.000242"], ["83422.84", "0.001333"]], "a": [["83469.18", "2.521214"], ["83469.86", "0.089922"], ["83477.78", "0"], ["83479.19", "0.019255"], ["83491.7", "0.239609"], ["83500.06", "0.359457"], ["83503.98", "0"], ["83515.72", "0"], ["83515.74", "0"]], "u": 973399, "seq": 67263897669}, "cts": 1742377416408, "record_time": 1742377417.299146}
{"topic": "orderbook.200.BTCUSDT", "ts": 1742377416614, "type": "delta", "data": {"s": "BTCUSDT", "b": [["83469.17", "0.538373"], ["83461.16", "0.071888"], ["83461.05", "0"], ["83446.61", "0.239609"], ["83440.58", "0.239609"], ["83422.96", "0"], ["83422.84", "0"]], "a": [["83469.18", "2.369654"], ["83500.06", "0"], ["83503.98", "0.359453"], ["83513.72", "0.003672"], ["83513.82", "0"]], "u": 973400, "seq": 67263897739}, "cts": 1742377416602, "record_time": 1742377417.499214}
{"topic": "orderbook.200.BTCUSDT", "ts": 1742377416814, "type": "delta", "data": {"s": "BTCUSDT", "b": [["83469.17", "0.538442"]], "a": [["83479.19", "0"], ["83497.11", "0"], ["83503.97", "0.359454"], ["83503.98", "0"], ["83513.71", "0.003672"], ["83513.72", "0"], ["83515.72", "0.00599"], ["83515.74", "0.119796"]], "u": 973401, "seq": 67263897819}, "cts": 1742377416807, "record_time": 1742377417.69882}
{"topic": "orderbook.200.BTCUSDT", "ts": 1742377417014, "type": "delta", "data": {"s": "BTCUSDT", "b": [["83429.52", "0.13579"]], "a": [["83469.18", "2.388909"], ["83503.96", "0.359453"], ["83503.97", "0"]], "u": 973402, "seq": 67263897844}, "cts": 1742377417004, "record_time": 1742377417.899149}
{"topic": "orderbook.200.BTCUSDT", "ts": 1742377417214, "type": "delta", "data": {"s": "BTCUSDT", "b": [["83450.1", "0.003"], ["83450.05", "0"], ["83446.61", "0.198777"], ["83442.64", "0.003"], ["83442.56", "0.001123"], ["83423.06", "0"]], "a": [["83469.18", "2.369654"], ["83479.19", "0.019255"], ["83480.63", "0"], ["83489.37", "0.003"], ["83490.38", "0"], ["83496.83", "0.003"], ["83500.21", "0.359455"], ["83503.96", "0"], ["83515.74", "0"]], "u": 973403, "seq": 67263897876}, "cts": 1742377417210, "record_time": 1742377418.100199}
{"topic": "orderbook.200.BTCUSDT", "ts": 1742377417414, "type": "delta", "data": {"s": "BTCUSDT", "b": [["83442.09", "0.001407"], ["83439.07", "0"], ["83437.91", "0.00141"], ["83429.52", "0"]], "a": [["83469.18", "2.388909"], ["83479.19", "0"], ["83495.24", "0.00087"], ["83500.21", "0"], ["83503.98", "0.359454"]], "u": 973404, "seq": 67263897904}, "cts": 1742377417403, "record_time": 1742377418.298673}
{"topic": "orderbook.200.BTCUSDT", "ts": 1742377417614, "type": "delta", "data": {"s": "BTCUSDT", "b": [["83444.63", "0.00104"], ["83442.09", "0"], ["83440.46", "0.036991"], ["83437.91", "0"], ["83423.06", "0.195"]], "a": [["83469.26", "0.000153"], ["83471.45", "0"], ["83480.53", "0.003591"], ["83485.09", "0"], ["83503.98", "0.359453"], ["83513.71", "0"], ["83513.91", "0.003672"], ["83514.88", "0.11"], ["83515.72", "0"]], "u": 973405, "seq": 67263897986}, "cts": 1742377417609, "record_time": 1742377418.498166}
{"topic": "orderbook.200.BTCUSDT", "ts": 1742377417815, "type": "delta", "data": {"s": "BTCUSDT", "b": [["83461.16", "0"], ["83458.58", "0.07189"], ["83444.63", "0"], ["83442.75", "0.001282"], ["83442.58", "0.001311"], ["83440.46", "0.035951"], ["83438.01", "0.001389"], ["83423.19", "0"], ["83423.06", "0"]], "a": [["83469.18", "2.369654"], ["83500.21", "0.359455"], ["83503.98", "0"], ["83513.91", "0"], ["83514.11", "0.066805"], ["83515.72", "0.00599"]], "u": 973406, "seq": 67263898038}, "cts": 1742377417807, "record_time": 1742377418.699374}
{"topic": "orderbook.200.BTCUSDT", "ts": 1742377418014, "type": "delta", "data": {"s": "BTCUSDT", "b": [["83460.31", "0.071889"], ["83459.51", "0"], ["83458.58", "0"], ["83456.24", "0.003"], ["83456.04", "0.003"], ["83455.22", "0.011981"], ["83449.11", "0"], ["83448.93", "0"], ["83446.61", "0"], ["83444.75", "0"], ["83442.85", "0"], ["83442.75", "0"], ["83442.58", "0"], ["83442.26", "0.001373"], ["83440.58", "0"], ["83440.46", "0"], ["83440.04", "0.035951"], ["83438.08", "0.001373"], ["83438.01", "0"], ["83432.43", "0"], ["83432.22", "0"], ["83423.19", "0.01656"], ["83423.06", "0.195"], ["83422.96", "0.000242"], ["83422.84", "0.001333"], ["83422.58", "0.119902"], ["83422.56", "0.013851"], ["83421.93", "0.060553"]], "a": [["83469.18", "2.381635"], ["83477.65", "0"], ["83479.19", "0.019255"], ["83500.21", "0"], ["83503.98", "0.359453"], ["83514", "0.003672"], ["83514.11", "0.063133"], ["83515.72", "0"]], "u": 973407, "seq": 67263898313}, "cts": 1742377418006, "record_time": 1742377418.899231}
{"topic": "orderbook.200.BTCUSDT", "ts": 1742377418214, "type": "delta", "data": {"s": "BTCUSDT", "b": [["83469.17", "0.52725"], ["83466.56", "0"], ["83460.31", "0"], ["83460.21", "0.071889"], ["83451.38", "0"], ["83450.27", "0"], ["83449.8", "0.224199"], ["83443.97", "0.001099"], ["83442.26", "0"], ["83441.91", "0.001424"], ["83439.96", "0"], ["83439.8", "0.001099"], ["83438.08", "0"], ["83437.59", "0.111708"], ["83432.95", "0.071912"], ["83428.05", "0.239609"], ["83422.35", "0.1665"], ["83421.93", "0"]], "a": [["83469.18", "2.40089"], ["83475.78", "0.037732"], ["83479.19", "0"], ["83481.49", "0"], ["83500.21", "0.359455"], ["83503.98", "0"], ["83515.72", "0.00599"]], "u": 973408, "seq": 67263898591}, "cts": 1742377418208, "record_time": 1742377419.099548}
{"topic": "orderbook.200.BTCUSDT", "ts": 1742377418414, "type": "delta", "data": {"s": "BTCUSDT", "b": [["83469.17", "0.404499"], ["83462.84", "0.002725"], ["83460.21", "0"], ["83459.55", "0"], ["83459.27", "0"], ["83458.8", "0"], ["83458.77", "0"], ["83456.86", "0"], ["83456.38", "0.071892"], ["83456.24", "0"], ["83456.04", "0"], ["83455.27", "0.003"], ["83455.22", "0"], ["83455.2", "0"], ["83455.07", "0.003"], ["83453.94", "0.041869"], ["83453.27", "0.000252"], ["83451.85", "0.04187"], ["83450.87", "0"], ["83450.86", "0"], ["83450.68", "0.011982"], ["83448.19", "0"], ["83447.35", "0"], ["83444.86", "0"], ["83444.14", "0"], ["83443.97", "0"], ["83443.56", "0.018361"], ["83443.17", "0.017973"], ["83442.49", "0.001212"], ["83442.18", "0.00126"], ["83441.91", "0"], ["83440.04", "0"], ["83439.8", "0"], ["83439.39", "0"], ["83438.51", "0.001185"], ["83438.01", "0.00126"], ["83437.95", "0"], ["83436.7", "0"], ["83434.82", "0.023965"], ["83429.07", "0.071915"], ["83428.73", "0.239609"], ["83428.05", "0"], ["83424.55", "0.239609"], ["83421.93", "0.060553"], ["83421.92", "0.000333"], ["83421.7", "0.001123"], ["83421.34", "0.13579"], ["83421.31", "0.001466"], ["83421.1", "0.044"]], "a": [["83469.18", "2.520371"], ["83469.26", "0"], ["83474.93", "0.079819"], ["83475.13", "0.030856"], ["83475.93", "0.23959"], ["83477.22", "0.030855"], ["83477.6", "0.239585"], ["83479.2", "0.04"], ["83479.27", "0.23958"], ["83480", "0.00024"], ["83480.13", "0"], ["83481.46", "0"], ["83481.8", "0"], ["83484.96", "0"], ["83486", "0.04"], ["83486.11", "0"], ["83487.46", "0"], ["83491", "0"], ["83493.46", "0"], ["83498.71", "0.120869"], ["83499.88", "0"], ["83500.06", "0.359457"], ["83500.21", "0"], ["83500.41", "0"], ["83502.33", "0.003"], ["83506.83", "0.023961"], ["83511.48", "0"], ["83515.74", "0.119796"], ["83515.95", "0.167715"], ["83516", "0.000119"]], "u": 973409, "seq": 67263899114}, "cts": 1742377418410, "record_time": 1742377419.299035}
{"topic": "orderbook.200.BTCUSDT", "ts": 1742377418614, "type": "delta", "data": {"s": "BTCUSDT", "b": [["83456.59", "0.172722"], ["83453.41", "0.09317"], ["83451.81", "0"], ["83450.59", "0.298345"], ["83444.59", "0.439578"], ["83442.49", "0"], ["83442.18", "0"], ["83441.62", "0.00136"], ["83438.51", "0"], ["83438.01", "0"], ["83437.45", "0.00136"], ["83437.29", "0.035952"], ["83424.55", "0"], ["83421.1", "0"]], "a": [["83470", "0"], ["83481.19", "0.170567"], ["83484.2", "0.04"], ["83484.3", "0"], ["83487.19", "0.290864"], ["83489.3", "0"], ["83491.7", "0"], ["83493.19", "0.452716"], ["83500.06", "0"], ["83500.21", "0.359454"], ["83507.35", "0.711315"], ["83516", "0"]], "u": 973410, "seq": 67263899260}, "cts": 1742377418610, "record_time": 1742377419.498536}
{"topic": "orderbook.200.BTCUSDT", "ts": 1742377418814, "type": "delta", "data": {"s": "BTCUSDT", "b": [["83469.17", "0.678056"], ["83458.66", "0.06659"], ["83456.86", "0.173859"], ["83456.59", "0"], ["83456.38", "0"], ["83455.43", "0.011981"], ["83453.41", "0.171028"], ["83450.86", "0.262624"], ["83450.68", "0"], ["83450.59", "0"], ["83447.92", "0.017972"], ["83444.86", "0.465257"], ["83444.59", "0"], ["83443.72", "0.001061"], ["83443.17", "0"], ["83441.97", "0.001295"], ["83441.62", "0"], ["83439.55", "0.001061"], ["83439.07", "0.180455"], ["83437.8", "0.001295"], ["83437.45", "0"], ["83437.32", "0.071908"], ["83432.9", "0.239609"], ["83429.07", "0"], ["83421.92", "0"], ["83421.7", "0"], ["83421.34", "0"], ["83421.31", "0"]], "a": [["83469.18", "2.37097"], ["83469.39", "0.074236"], ["83469.86", "0"], ["83470.21", "0"], ["83474.93", "0.019266"], ["83475.45", "0"], ["83480.06", "0"], ["83480.35", "0"], ["83481.19", "0"], ["83481.46", "0.166703"], ["83487.19", "0"], ["83487.46", "0.300578"], ["83489.18", "0"], ["83493.19", "0"], ["83493.29", "0"], ["83493.46", "0.425612"], ["83495.52", "0.003"], ["83500.19", "0.029602"], ["83500.21", "0"], ["83501.01", "0"], ["83502.33", "0"], ["83503.98", "0.359454"], ["83511.33", "0.002156"], ["83516", "0.000119"], ["83516.54", "0.04"], ["83516.55", "0.04"], ["83516.76", "0.037732"], ["83516.8", "0.24332"], ["83516.97", "0.003663"]], "u": 973411, "seq": 67263899460}, "cts": 1742377418810, "record_time": 1742377419.699453}
{"topic": "orderbook.200.BTCUSDT", "ts": 1742377419015, "type": "delta", "data": {"s": "BTCUSDT", "b": [["83449.11", "0.239609"], ["83445.43", "0.239609"], ["83441.25", "0.239609"], ["83439.08", "0.259606"], ["83439.06", "0"], ["83438.64", "0.009188"], ["83435.92", "0"], ["83432.9", "0"], ["83430.42", "1.342515"], ["83428.73", "0"], ["83426.79", "0.135781"], ["83422.56", "0"], ["83422.35", "0"], ["83421.93", "0"]], "a": [["83469.18", "2.214015"], ["83475.78", "0"], ["83477.29", "0.060553"], ["83477.3", "1.35132"], ["83479.19", "0.019255"], ["83480.05", "0"], ["83481.24", "0.037732"], ["83489.88", "0"], ["83493.97", "0"], ["83503.97", "0.359434"], ["83503.98", "0"], ["83514.88", "0"], ["83516.54", "0.2065"], ["83517", "0.000277"]], "u": 973412, "seq": 67263899515}, "cts": 1742377419009, "record_time": 1742377419.90018}
{"topic": "orderbook.200.BTCUSDT", "ts": 1742377419214, "type": "delta", "data": {"s": "BTCUSDT", "b": [["83469.17", "0.677056"], ["83467.2", "0.004466"], ["83463.59", "0.003"], ["83458.3", "0.047"], ["83450.1", "0"], ["83449.98", "0.396711"], ["83449.8", "0"], ["83443.72", "0"], ["83443.47", "0.001087"], ["83442.64", "0"], ["83441.97", "0"], ["83439.55", "0"], ["83439.3", "0.001087"], ["83439.07", "0.119902"], ["83437.8", "0"], ["83437.42", "0.167727"], ["83424.08", "0.11"], ["83422.56", "0.013851"]], "a": [["83469.18", "2.236273"], ["83469.39", "0.071881"], ["83470.06", "0.000153"], ["83474.35", "1"], ["83477.72", "0"], ["83479.19", "0"], ["83488", "0.003"], ["83489.37", "0"], ["83494.84", "0.003"], ["83496.83", "0"], ["83503.96", "0.35944"], ["83503.97", "0"], ["83511.33", "0"], ["83517.69", "0.001114"]], "u": 973413, "seq": 67263899617}, "cts": 1742377419208, "record_time": 1742377420.098571}
{"topic": "orderbook.200.BTCUSDT", "ts": 1742377419414, "type": "delta", "data": {"s": "BTCUSDT", "b": [["83443.56", "0.041891"], ["83443.47", "0"], ["83443.37", "0.001099"], ["83442.05", "0.001282"], ["83439.3", "0"], ["83439.19", "0.001099"], ["83439.09", "0.060553"], ["83437.88", "0.001282"], ["83422.84", "0"], ["83422.58", "0"], ["83422.56", "0"]], "a": [["83476.32", "0.111709"], ["83478.64", "0"], ["83479.19", "0.019255"], ["83486.06", "0.275535"], ["83503.96", "0"], ["83503.98", "0.359439"], ["83517.69", "0"]], "u": 973414, "seq": 67263899698}, "cts": 1742377419401, "record_time": 1742377420.298862}
{"topic": "orderbook.200.BTCUSDT", "ts": 1742377419614, "type": "delta", "data": {"s": "BTCUSDT", "b": [["83449.11", "0"], ["83443.37", "0"], ["83442.05", "0"], ["83441.47", "0.001391"], ["83441.25", "0"], ["83439.19", "0"], ["83437.88", "0"], ["83437.3", "0.001391"], ["83429.52", "0.135796"], ["83426.79", "0"], ["83426.08", "0.11"], ["83422.84", "0.001333"], ["83422.58", "0.119902"], ["83422.56", "0.013851"]], "a": [["83479.19", "0"], ["83503.97", "0.35944"], ["83503.98", "0"], ["83509.5", "0.018672"], ["83514", "0"], ["83517.69", "0.001114"], ["83517.71", "0.001466"]], "u": 973415, "seq": 67263899731}, "cts": 1742377419612, "record_time": 1742377420.49903}
{"topic": "orderbook.200.BTCUSDT", "ts": 1742377419814, "type": "delta", "data": {"s": "BTCUSDT", "b": [["83469.17", "0.799807"], ["83461.78", "0.071887"], ["83451.62", "0.239609"], ["83449.6", "0.239609"], ["83445.43", "0"], ["83443.6", "0.001073"], ["83441.47", "0"], ["83441.26", "0.001435"], ["83439.43", "0.001073"], ["83437.3", "0"], ["83437.08", "0.119805"], ["83422.96", "0"], ["83422.84", "0"], ["83422.58", "0"], ["83422.56", "0"]], "a": [["83469.19", "0"], ["83473.55", "0"], ["83500.19", "0"], ["83503.97", "0"], ["83503.98", "0.359438"], ["83509.5", "0.015"], ["83509.89", "0.003672"], ["83510", "0"], ["83511.89", "0.029602"], ["83517.89", "0.00034"], ["83517.91", "0.000333"]], "u": 973416, "seq": 67263899819}, "cts": 1742377419803, "record_time": 1742377420.699052}
{"topic": "orderbook.200.BTCUSDT", "ts": 1742377420014, "type": "delta", "data": {"s": "BTCUSDT", "b": [["83469.17", "1.048117"], ["83465.29", "0.01198"], ["83464.44", "0.030232"], ["83464.43", "0.071885"], ["83461.78", "0"], ["83459.55", "0.070609"], ["83458.66", "0"], ["83458.65", "0.181162"], ["83458.37", "0.175271"], ["83457.78", "0.01797"], ["83456.97", "0.180162"], ["83456.86", "0"], ["83456.51", "0.003"], ["83456.31", "0.003"], ["83455.43", "0"], ["83453.99", "0.018361"], ["83453.78", "0.239609"], ["83451.89", "0"], ["83451.62", "0"], ["83450.97", "0.297606"], ["83450.86", "0"], ["83449.97", "0.28783"], ["83449.65", "0.269389"], ["83448.4", "0.023961"], ["83448.09", "0.004996"], ["83447.92", "0"], ["83444.97", "0.436336"], ["83444.86", "0"], ["83443.65", "0.433413"], ["83443.6", "0"], ["83443.56", "0.02353"], ["83442.23", "0.071904"], ["83442.17", "0.917602"], ["83441.66", "0.001352"], ["83441.26", "0"], ["83439.43", "0"], ["83437.49", "0.001352"], ["83435.31", "0.089922"], ["83434.82", "0"], ["83432.95", "0"], ["83429.52", "0.135804"], ["83424.93", "0.02092"], ["83424.08", "0"], ["83423.55", "0"], ["83423.49", "0"], ["83423.19", "0"], ["83423.06", "0"]], "a": [["83469.18", "0.361657"], ["83470.06", "0"], ["83472.91", "0"], ["83472.92", "0"], ["83474.08", "0.017971"], ["83474.35", "0"], ["83474.61", "0"], ["83474.93", "0"], ["83475.75", "0"], ["83475.85", "0.001068"], ["83477.22", "0.039638"], ["83477.3", "0"], ["83477.31", "1.310503"], ["83477.94", "0"], ["83479.65", "0.176166"], ["83479.97", "0.166219"], ["83480.53", "0"], ["83481.24", "0"], ["83481.46", "0"], ["83481.57", "0.164664"], ["83483.38", "0.000153"], ["83485.03", "0.009014"], ["83486.48", "0"], ["83486.78", "0"], ["83487.18", "0.003409"], ["83487.25", "0.019266"], ["83487.46", "0"], ["83487.57", "0.270886"], ["83488.37", "0.278476"], ["83488.46", "0.037732"], ["83488.65", "0.289932"], ["83488.82", "0.474971"], ["83490.06", "0"], ["83490.69", "0"], ["83493.46", "0"], ["83493.57", "0.480015"], ["83494.65", "0.487011"], ["83494.86", "0"], ["83495.07", "0"], ["83496.17", "0.906058"], ["83500.44", "0.536792"], ["83503.98", "0"], ["83507.34", "0.359415"], ["83509.89", "0"], ["83511.39", "0.003672"], ["83515.74", "0"], ["83515.95", "0"], ["83518.25", "0.023959"], ["83518.84", "0.001333"], ["83519.37", "0.024199"], ["83519.56", "0.00009"], ["83519.63", "0.00009"], ["83519.9", "0.000243"], ["83520", "0.00024"], ["83520.2", "0.089922"], ["83520.57", "0.239609"]], "u": 973417, "seq": 67263900371}, "cts": 1742377420010, "record_time": 1742377420.899161}
{"topic": "orderbook.200.BTCUSDT", "ts": 1742377420214, "type": "delta", "data": {"s": "BTCUSDT", "b": [["83469.17", "1.049117"], ["83462.25", "0.004021"], ["83459.55", "0.069945"], ["83458.66", "0.178948"], ["83458.65", "0"], ["83457.11", "0.171577"], ["83456.97", "0"], ["83454.12", "0.239609"], ["83451.11", "0.297242"], ["83450.97", "0"], ["83449.66", "0.298395"], ["83449.65", "0"], ["83445.11", "0.479688"], ["83444.97", "0"], ["83443.66", "0.466392"], ["83443.65", "0"], ["83443.17", "0.001122"], ["83441.66", "0"], ["83441.52", "0.001381"], ["83437.49", "0"], ["83437.34", "0.001381"], ["83425.18", "0"], ["83424.93", "0"], ["83424.17", "0"]], "a": [["83469.18", "0.340246"], ["83475.85", "0"], ["83479.19", "0.019255"], ["83479.65", "0"], ["83479.66", "0.178448"], ["83481.57", "0"], ["83481.71", "0.172782"], ["83486.06", "0.075324"], ["83486.28", "0.00009"], ["83487.57", "0"], ["83487.71", "0.279051"], ["83487.97", "0.200211"], ["83488.65", "0"], ["83488.66", "0.295163"], ["83493.57", "0"], ["83493.66", "0.07186"], ["83493.71", "0.469391"], ["83494.65", "0"], ["83494.66", "0.45629"], ["83511.39", "0"], ["83512.1", "0.002156"], ["83512.69", "0.003672"], ["83514.25", "0.239609"], ["83516.4", "0.239609"], ["83520", "0"], ["83520.2", "0"], ["83520.57", "0"]], "u": 973418, "seq": 67263900597}, "cts": 1742377420211, "record_time": 1742377421.098831}
{"topic": "orderbook.200.BTCUSDT", "ts": 1742377420414, "type": "delta", "data": {"s": "BTCUSDT", "b": [["83459.55", "0.066302"], ["83458.66", "0"], ["83458.65", "0.166803"], ["83457.11", "0"], ["83456.98", "0.159546"], ["83456.53", "0.003"], ["83456.51", "0"], ["83456.32", "0.003"], ["83456.31", "0"], ["83455.27", "0"], ["83455.07", "0"], ["83454.13", "0.338916"], ["83453.41", "0"], ["83451.11", "0"], ["83450.98", "0.267191"], ["83449.66", "0"], ["83449.65", "0.285497"], ["83445.11", "0"], ["83444.98", "0.427466"], ["83443.66", "0"], ["83443.65", "0.482892"], ["83443.17", "0"], ["83442.93", "0.001152"], ["83441.52", "0"], ["83438.76", "0.001152"], ["83437.34", "0"], ["83429.52", "0.135797"], ["83425.18", "0.000276"], ["83424.93", "0.02092"], ["83424.17", "0.003663"]], "a": [["83469.18", "0.359501"], ["83477.11", "0.547683"], ["83479.19", "0"], ["83479.65", "0.179786"], ["83479.66", "0.001968"], ["83481.58", "0.178473"], ["83481.71", "0"], ["83486.06", "0"], ["83487.58", "0.294869"], ["83487.71", "0"], ["83487.97", "0.275535"], ["83488.65", "0.289075"], ["83488.66", "0"], ["83493.58", "0.459622"], ["83493.71", "0"], ["83494.65", "0.4876"], ["83494.66", "0"], ["83495.52", "0"], ["83503.14", "0.003"], ["83507.33", "0.359421"], ["83507.34", "0"], ["83511.74", "0.239609"], ["83514.25", "0"]], "u": 973419, "seq": 67263900804}, "cts": 1742377420404, "record_time": 1742377421.299282}
{"topic": "orderbook.200.BTCUSDT", "ts": 1742377420614, "type": "delta", "data": {"s": "BTCUSDT", "b": [["83469.17", "0.882617"], ["83456.98", "0.174864"], ["83450.98", "0.30078"], ["83444.98", "0.452344"], ["83443.8", "0.001053"], ["83442.93", "0"], ["83441.85", "0.001317"], ["83439.62", "0.001053"], ["83438.76", "0"], ["83437.21", "0.001409"], ["83424.93", "0"], ["83424.17", "0"]], "a": [["83481.58", "0.173728"], ["83487.58", "0.294402"], ["83493.58", "0.479827"], ["83507.32", "0.359424"], ["83507.33", "0"], ["83511.74", "0"], ["83512.22", "0.239609"], ["83515.03", "0.04"], ["83515.04", "0.04"], ["83516.54", "0.1665"], ["83516.55", "0"], ["83519.9", "0"]], "u": 973420, "seq": 67263900933}, "cts": 1742377420611, "record_time": 1742377421.498845}
{"topic": "orderbook.200.BTCUSDT", "ts": 1742377420814, "type": "delta", "data": {"s": "BTCUSDT", "b": [["83469.17", "1.049117"], ["83459.55", "0.018584"], ["83458.65", "0.161643"], ["83456.98", "0"], ["83454.9", "0.0611"], ["83450.98", "0"], ["83449.65", "0.292622"], ["83444.98", "0"], ["83444.22", "0.642262"], ["83443.8", "0"], ["83443.76", "0.001057"], ["83443.65", "0.48788"], ["83441.85", "0"], ["83439.62", "0"], ["83439.59", "0.001057"], ["83437.21", "0"], ["83429.52", "0.135828"], ["83424.93", "0.02092"], ["83424.17", "0.003663"], ["83423.55", "0.001"], ["83423.49", "0.000242"]], "a": [["83469.18", "0.361657"], ["83479.65", "0.180453"], ["83481.58", "0"], ["83484.04", "0.0036"], ["83487.58", "0"], ["83488.65", "0.275123"], ["83493.58", "0"], ["83494.65", "0.469611"], ["83507.31", "0.359423"], ["83507.32", "0"], ["83512.1", "0"], ["83514.25", "0.239609"], ["83515.03", "0"], ["83515.04", "0"], ["83515.23", "0.04"], ["83515.24", "0.04"], ["83519.9", "0.000243"], ["83520", "0.00024"]], "u": 973421, "seq": 67263901094}, "cts": 1742377420808, "record_time": 1742377421.698794}
{"topic": "orderbook.200.BTCUSDT", "ts": 1742377421015, "type": "delta", "data": {"s": "BTCUSDT", "b": [["83459.55", "0.064754"], ["83456.88", "0.164547"], ["83454.13", "0.249744"], ["83450.88", "0.287971"], ["83444.88", "0.463065"], ["83443.76", "0"], ["83439.59", "0"], ["83438.04", "0.001255"], ["83423.55", "0"], ["83423.49", "0"]], "a": [["83469.18", "0.361658"], ["83481.48", "0.173999"], ["83484.04", "0"], ["83486.08", "0.0036"], ["83487.48", "0.265928"], ["83493.48", "0.425151"], ["83495.01", "0.005"], ["83504.82", "0.359428"], ["83507.31", "0"], ["83514.88", "0.11"], ["83519.37", "0"], ["83519.56", "0"], ["83519.63", "0"], ["83519.9", "0"], ["83520", "0"]], "u": 973422, "seq": 67263901273}, "cts": 1742377421007, "record_time": 1742377421.899741}
{"topic": "orderbook.200.BTCUSDT", "ts": 1742377421214, "type": "delta", "data": {"s": "BTCUSDT", "b": [["83469.17", "0.882617"], ["83456.88", "0"], ["83450.88", "0"], ["83444.88", "0"], ["83443.37", "0.001099"], ["83439.19", "0.001099"], ["83439.09", "0"], ["83438.04", "0"], ["83423.55", "0.001"], ["83423.49", "0.000242"], ["83423.19", "0.01656"]], "a": [["83469.18", "0.380914"], ["83475.92", "0.003"], ["83479.12", "0.003"], ["83481.48", "0"], ["83483.78", "0.003"], ["83486.08", "0"], ["83487.48", "0"], ["83488", "0"], ["83493.47", "0.119902"], ["83493.48", "0"], ["83494.84", "0"], ["83496.71", "0.239609"], ["83503.98", "0.359431"], ["83504.82", "0"], ["83512.22", "0"], ["83516.4", "0"], ["83519.37", "0.024199"], ["83519.56", "0.00009"], ["83519.63", "0.00009"]], "u": 973423, "seq": 67263901411}, "cts": 1742377421209, "record_time": 1742377422.09913}
{"topic": "orderbook.200.BTCUSDT", "ts": 1742377421414, "type": "delta", "data": {"s": "BTCUSDT", "b": [["83469.17", "0.800807"], ["83464.44", "0"], ["83464.43", "0"], ["83462.85", "0.071886"], ["83459.55", "0.018584"], ["83458.65", "0"], ["83456.86", "0.158625"], ["83450.86", "0.27783"], ["83449.65", "0"], ["83444.86", "0.481895"], ["83444.22", "0"], ["83443.65", "0"], ["83443.37", "0"], ["83443.12", "0.001128"], ["83443.05", "0.001137"], ["83442.87", "0.00116"], ["83439.19", "0"], ["83438.87", "0.001137"], ["83435.31", "0"], ["83426.08", "0"], ["83424.93", "0"], ["83423.06", "0.195"], ["83422.96", "0.000242"], ["83422.84", "0.001333"]], "a": [["83469.18", "0.508902"], ["83470.31", "0.089922"], ["83472.56", "0.000153"], ["83473.88", "0.00882"], ["83475.54", "0.089922"], ["83475.85", "0.011979"], ["83479.19", "0.015192"], ["83479.65", "0"], ["83481.46", "0.172781"], ["83483.38", "0"], ["83484.85", "0.143785"], ["83485.2", "0.129922"], ["83487.46", "0.277542"], ["83488.65", "0"], ["83489.86", "0.0036"], ["83493.46", "0.44695"], ["83494.65", "0"], ["83496.71", "0"], ["83514.25", "0"], ["83518.84", "0"], ["83519.37", "0"], ["83519.56", "0"], ["83519.63", "0"]], "u": 973424, "seq": 67263901625}, "cts": 1742377421410, "record_time": 1742377422.298882}
{"topic": "orderbook.200.BTCUSDT", "ts": 1742377421614, "type": "delta", "data": {"s": "BTCUSDT", "b": [["83463.44", "0.02916"], ["83459.55", "0.066991"], ["83458.65", "0.169101"], ["83449.65", "0.267676"], ["83444.76", "0"], ["83443.65", "0.469146"], ["83443.12", "0"], ["83443.05", "0"], ["83442.87", "0"], ["83442.6", "0.001197"], ["83442.07", "0.001279"], ["83438.87", "0"], ["83438.13", "0.00124"], ["83422.96", "0"], ["83422.84", "0"]], "a": [["83469.18", "0.524043"], ["83473.34", "0.003836"], ["83479.19", "0"], ["83479.65", "0.17185"], ["83484.85", "0.236085"], ["83488.65", "0.274976"], ["83491.35", "0.239609"], ["83491.7", "0.239609"], ["83494.65", "0.451785"], ["83495.53", "0.239609"], ["83500.05", "0.167727"], ["83512.49", "0.003672"], ["83512.69", "0"], ["83514.88", "0"], ["83517", "0"], ["83517.69", "0"], ["83517.71", "0"], ["83517.89", "0"], ["83517.91", "0"], ["83518.25", "0"]], "u": 973425, "seq": 67263901717}, "cts": 1742377421605, "record_time": 1742377422.498966}
{"topic": "orderbook.200.BTCUSDT", "ts": 1742377421814, "type": "delta", "data": {"s": "BTCUSDT", "b": [["83465.29", "0"], ["83460", "0.012041"], ["83457.78", "0"], ["83454.12", "0"], ["83453.78", "0"], ["83452.49", "0.017971"], ["83444.87", "0.607615"], ["83442.84", "0.001164"], ["83442.6", "0"], ["83442.07", "0"], ["83439.07", "0"], ["83439.06", "0.119902"], ["83438.13", "0"], ["83422.96", "0.000242"], ["83422.84", "0.001333"], ["83422.58", "0.119902"], ["83422.56", "0.013851"]], "a": [["83469.18", "0.532826"], ["83473.34", "0.005762"], ["83477.22", "0.030855"], ["83483.05", "0.037732"], ["83483.59", "0.003"], ["83488.46", "0"], ["83489.19", "0.239609"], ["83491.7", "0"], ["83512.49", "0"], ["83512.68", "0.003672"], ["83516.97", "0"]], "u": 973426, "seq": 67263901846}, "cts": 1742377421812, "record_time": 1742377422.698839}
{"topic": "orderbook.200.BTCUSDT", "ts": 1742377422014, "type": "delta", "data": {"s": "BTCUSDT", "b": [["83451.62", "0.239609"], ["83445.43", "0.239609"], ["83442.84", "0"], ["83422.56", "0"]], "a": [["83473.34", "0.009737"], ["83515.22", "0.04"], ["83515.24", "0"]], "u": 973427, "seq": 67263901880}, "cts": 1742377422008, "record_time": 1742377422.898937}
{"topic": "orderbook.200.BTCUSDT", "ts": 1742377422214, "type": "delta", "data": {"s": "BTCUSDT", "b": [], "a": [["83479.19", "0.015192"], ["83516.8", "0"]], "u": 973428, "seq": 67263901899}, "cts": 1742377422204, "record_time": 1742377423.099376}
{"topic": "orderbook.200.BTCUSDT", "ts": 1742377422414, "type": "delta", "data": {"s": "BTCUSDT", "b": [["83456.6", "0.051"], ["83456.53", "0"], ["83456.4", "0.003"], ["83456.32", "0"], ["83451.62", "0"], ["83430.42", "0"], ["83429.52", "0.135799"], ["83424.08", "0.11"], ["83422.56", "0.013851"], ["83421.93", "0.060553"]], "a": [["83469.18", "0.517634"], ["83512.68", "0"], ["83513.28", "0.003672"], ["83515.22", "0"], ["83515.23", "0"], ["83515.82", "0.04"], ["83515.83", "0.04"]], "u": 973429, "seq": 67263901962}, "cts": 1742377422411, "record_time": 1742377423.300308}
{"topic": "orderbook.200.BTCUSDT", "ts": 1742377422614, "type": "delta", "data": {"s": "BTCUSDT", "b": [["83449.11", "0.239609"], ["83441.25", "0.239609"], ["83431.46", "1.325459"], ["83425.91", "0.11"], ["83422.84", "0"], ["83422.58", "0"], ["83422.56", "0"], ["83421.93", "0"]], "a": [["83473.88", "0"], ["83477.31", "0"], ["83479.84", "1.375808"], ["83516.8", "0.24332"]], "u": 973430, "seq": 67263902002}, "cts": 1742377422609, "record_time": 1742377423.498982}
{"topic": "orderbook.200.BTCUSDT", "ts": 1742377422814, "type": "delta", "data": {"s": "BTCUSDT", "b": [["83455.2", "0.005"], ["83454.9", "0.056"], ["83449.11", "0"], ["83441.25", "0"], ["83425.91", "0"], ["83422.84", "0.001333"], ["83422.58", "0.119902"]], "a": [["83491.43", "0.023623"], ["83513.08", "0.003672"], ["83513.28", "0"], ["83514.88", "0.11"], ["83516.76", "0"], ["83516.8", "0"]], "u": 973431, "seq": 67263902054}, "cts": 1742377422811, "record_time": 1742377423.698872}
{"topic": "orderbook.200.BTCUSDT", "ts": 1742377423014, "type": "delta", "data": {"s": "BTCUSDT", "b": [["83445.01", "0.30503"], ["83429.52", "0.135792"], ["83422.58", "0"]], "a": [["83469.18", "0.532826"], ["83479.19", "0"], ["83513.08", "0"], ["83513.18", "0.003672"], ["83515.72", "0.04599"], ["83515.73", "0.04"], ["83515.82", "0"], ["83515.83", "0"], ["83516.76", "0.037732"], ["83516.8", "0.24332"]], "u": 973432, "seq": 67263902093}, "cts": 1742377423007, "record_time": 1742377423.898645}
{"topic": "orderbook.200.BTCUSDT", "ts": 1742377423214, "type": "delta", "data": {"s": "BTCUSDT", "b": [["83469.17", "0.767487"], ["83458.3", "0.044"], ["83458.28", "0.003"], ["83445.43", "0"]], "a": [["83470.31", "0"], ["83483.78", "0"], ["83484.43", "0.003"], ["83511.73", "0"], ["83511.85", "0.000149"], ["83513.06", "0.003678"], ["83513.18", "0"], ["83515.67", "0.04"], ["83515.68", "0.04"], ["83515.72", "0.00599"], ["83515.73", "0"]], "u": 973433, "seq": 67263902152}, "cts": 1742377423204, "record_time": 1742377424.09885}
{"topic": "orderbook.200.BTCUSDT", "ts": 1742377423414, "type": "delta", "data": {"s": "BTCUSDT", "b": [["83469.17", "0.800807"], ["83454.12", "0.239609"], ["83453.78", "0.239609"], ["83438.5", "0.023961"], ["83423.06", "0"], ["83422.96", "0"], ["83422.84", "0"]], "a": [["83473.34", "0"], ["83493.59", "0.023961"], ["83506.83", "0"], ["83507.67", "0"], ["83513.06", "0"], ["83513.26", "0.003678"], ["83515.67", "0"], ["83515.68", "0"], ["83515.77", "0.04"], ["83515.78", "0.04"], ["83516.88", "0.11"], ["83516.97", "0.003663"]], "u": 973434, "seq": 67263902188}, "cts": 1742377423411, "record_time": 1742377424.299546}
{"topic": "orderbook.200.BTCUSDT", "ts": 1742377423614, "type": "delta", "data": {"s": "BTCUSDT", "b": [], "a": [["83473.34", "0.004861"], ["83513.16", "0.003678"], ["83513.26", "0"], ["83515.67", "0.04"], ["83515.68", "0.04"], ["83515.77", "0"], ["83515.78", "0"], ["83516.97", "0"]], "u": 973435, "seq": 67263902217}, "cts": 1742377423607, "record_time": 1742377424.499072}
{"topic": "orderbook.200.BTCUSDT", "ts": 1742377423814, "type": "delta", "data": {"s": "BTCUSDT", "b": [["83429.52", "0.135785"]], "a": [["83473.34", "0.010147"], ["83513.05", "0.003678"], ["83513.16", "0"], ["83514.88", "0"], ["83516.97", "0.003663"]], "u": 973436, "seq": 67263902258}, "cts": 1742377423812, "record_time": 1742377424.698984}
{"topic": "orderbook.200.BTCUSDT", "ts": 1742377424014, "type": "delta", "data": {"s": "BTCUSDT", "b": [["83455.47", "0.041868"], ["83453.94", "0"], ["83453.38", "0.041869"], ["83451.85", "0"], ["83437.59", "0"], ["83423.06", "0.195"]], "a": [["83475.13", "0"], ["83476.64", "0.030855"], ["83477.22", "0"], ["83478.73", "0.030854"], ["83483.76", "0.003"], ["83515.56", "0.04"], ["83515.57", "0.04"], ["83515.67", "0"], ["83515.68", "0"], ["83516.97", "0"]], "u": 973437, "seq": 67263902303}, "cts": 1742377424008, "record_time": 1742377424.898703}
{"topic": "orderbook.200.BTCUSDT", "ts": 1742377424214, "type": "delta", "data": {"s": "BTCUSDT", "b": [["83469.17", "0.9795"], ["83456.87", "0.162056"], ["83456.86", "0"], ["83450.87", "0.281414"], ["83450.86", "0"], ["83444.87", "1.081667"], ["83444.86", "0"], ["83437.04", "0.11171"]], "a": [["83469.18", "0.412216"], ["83474.59", "0.008883"], ["83481.46", "0"], ["83481.47", "0.174594"], ["83483.78", "0.003"], ["83487.46", "0"], ["83487.47", "0.289112"], ["83489.86", "0"], ["83491.3", "0"], ["83493.46", "0"], ["83493.47", "0.55464"], ["83516.97", "0.003663"]], "u": 973438, "seq": 67263902369}, "cts": 1742377424210, "record_time": 1742377425.099271}
{"topic": "orderbook.200.BTCUSDT", "ts": 1742377424414, "type": "delta", "data": {"s": "BTCUSDT", "b": [["83456.87", "0.172313"], ["83456.6", "0.048"], ["83456.4", "0"], ["83450.87", "0.27941"], ["83444.87", "1.077892"], ["83437.29", "0"], ["83429.52", "0.135791"], ["83426.08", "0.11"], ["83422.96", "0.000242"]], "a": [["83474.59", "0"], ["83475.54", "0"], ["83481.47", "0.176772"], ["83487.47", "0.288371"], ["83488.68", "0.036284"], ["83493.47", "0.470188"], ["83517", "0.000277"], ["83517.69", "0.001114"]], "u": 973439, "seq": 67263902439}, "cts": 1742377424408, "record_time": 1742377425.299841}
{"topic": "orderbook.200.BTCUSDT", "ts": 1742377424614, "type": "delta", "data": {"s": "BTCUSDT", "b": [["83459.55", "0.018584"], ["83458.93", "0.164138"], ["83458.65", "0.181121"], ["83458.37", "0"], ["83457.83", "0.164658"], ["83457.59", "0.133482"], ["83457.47", "0.165704"], ["83456.87", "0"], ["83451.83", "0.290821"], ["83450.87", "0"], ["83450.25", "0.296766"], ["83449.97", "0"], ["83449.93", "0.302366"], ["83449.65", "0"], ["83448.17", "0.28992"], ["83445.83", "0.432578"], ["83444.87", "0.607615"], ["83443.93", "0.427646"], ["83443.65", "0"], ["83442.45", "0.439738"], ["83442.17", "0.468151"], ["83438.03", "0.035951"], ["83423.19", "0"], ["83423.06", "0"], ["83422.96", "0"]], "a": [["83469.18", "0.245716"], ["83472.56", "0"], ["83473.34", "0"], ["83473.69", "0.000153"], ["83475.85", "0"], ["83479.65", "0"], ["83479.93", "0.161123"], ["83479.97", "0"], ["83480.25", "0.159791"], ["83480.87", "0.163241"], ["83481.47", "0"], ["83482.43", "0.172618"], ["83487.47", "0"], ["83488.37", "0"], ["83488.43", "0.263734"], ["83488.65", "0.296013"], ["83488.93", "0.303404"], ["83490.17", "0.277499"], ["83493.47", "0"], ["83494.43", "0.461736"], ["83494.65", "0"], ["83494.93", "0.442634"], ["83496.17", "0.453537"], ["83496.45", "0.465646"], ["83512.75", "0.003678"], ["83513.05", "0"], ["83515.26", "0.04"], ["83515.27", "0.04"], ["83515.56", "0"], ["83515.57", "0"], ["83517.71", "0.001466"]], "u": 973440, "seq": 67263902594}, "cts": 1742377424607, "record_time": 1742377425.499475}
{"topic": "orderbook.200.BTCUSDT", "ts": 1742377424814, "type": "delta", "data": {"s": "BTCUSDT", "b": [["83458.93", "0.166489"], ["83458.65", "0.173989"], ["83457.84", "0.133482"], ["83457.83", "0.163394"], ["83457.59", "0"], ["83457.47", "0.181363"], ["83451.83", "0.275831"], ["83450.25", "0.289786"], ["83449.93", "0.287115"], ["83448.17", "0.293454"], ["83445.83", "0.439329"], ["83444.87", "0"], ["83443.93", "0.456267"], ["83442.45", "0"], ["83442.17", "0.449144"], ["83429.52", "0.135786"], ["83423.19", "0.01656"], ["83423.06", "0.195"]], "a": [["83475.85", "0.008607"], ["83479.93", "0.168044"], ["83480.25", "0.164487"], ["83480.87", "0.174602"], ["83482.43", "0.170421"], ["83484.85", "0.143785"], ["83488.43", "0.281208"], ["83488.65", "0.265433"], ["83488.93", "0.280476"], ["83490.17", "0.305862"], ["83491.7", "0.239609"], ["83494.43", "0.456106"], ["83494.93", "0.471921"], ["83496.17", "0.459674"], ["83496.45", "0.444984"], ["83503.98", "0"], ["83504.82", "0.359432"], ["83512.64", "0.003678"], ["83512.75", "0"], ["83517.69", "0"], ["83517.71", "0"]], "u": 973441, "seq": 67263902747}, "cts": 1742377424806, "record_time": 1742377425.69913}
{"topic": "orderbook.200.BTCUSDT", "ts": 1742377425014, "type": "delta", "data": {"s": "BTCUSDT", "b": [["83459.55", "0.06547"], ["83458.93", "0"], ["83458.65", "0.164029"], ["83458.37", "0.159759"], ["83457.84", "0.220224"], ["83457.83", "0"], ["83454.13", "0.381041"], ["83451.83", "0"], ["83451.62", "0.239609"], ["83450.25", "0"], ["83449.97", "0.271305"], ["83449.93", "0"], ["83449.65", "0.303444"], ["83445.83", "0"], ["83445.43", "0.239609"], ["83443.93", "0"], ["83443.65", "0.425809"], ["83442.17", "0.888383"], ["83422.96", "0.000242"]], "a": [["83469.18", "0.366326"], ["83479.65", "0.170835"], ["83479.93", "0"], ["83479.97", "0.176952"], ["83480.25", "0"], ["83482.43", "0"], ["83488.37", "0.295881"], ["83488.43", "0"], ["83488.65", "0.303499"], ["83488.93", "0"], ["83494.43", "0"], ["83494.65", "0.45724"], ["83494.93", "0"], ["83496.17", "0.881908"], ["83496.45", "0"], ["83504.81", "0.35943"], ["83504.82", "0"], ["83514.88", "0.11"], ["83515.16", "0.04"], ["83515.17", "0.04"], ["83515.26", "0"], ["83515.27", "0"], ["83517.69", "0.001114"], ["83517.71", "0.001466"], ["83517.89", "0.00034"]], "u": 973442, "seq": 67263902873}, "cts": 1742377425009, "record_time": 1742377425.898741}
{"topic": "orderbook.200.BTCUSDT", "ts": 1742377425215, "type": "delta", "data": {"s": "BTCUSDT", "b": [["83469.17", "0.973443"], ["83467.2", "0.001466"], ["83458.66", "0.003"], ["83458.28", "0"], ["83456.86", "0.160524"], ["83450.86", "0.271806"], ["83445.02", "0.532046"], ["83444.86", "0.45607"], ["83426.08", "0"], ["83423.19", "0"], ["83423.06", "0"], ["83422.96", "0"]], "a": [["83469.18", "0.532227"], ["83473.34", "0.004533"], ["83481.46", "0.178769"], ["83484.05", "0.003"], ["83484.43", "0"], ["83487.46", "0.268671"], ["83493.46", "0.438643"], ["83503.98", "0.359433"], ["83504.81", "0"], ["83512.64", "0"], ["83512.84", "0.003678"], ["83515.16", "0"], ["83515.17", "0"], ["83515.36", "0.04"], ["83515.37", "0.04"], ["83517", "0"], ["83517.69", "0"], ["83517.71", "0"], ["83517.89", "0"]], "u": 973443, "seq": 67263902942}, "cts": 1742377425210, "record_time": 1742377426.102317}
{"topic": "orderbook.200.BTCUSDT", "ts": 1742377425414, "type": "delta", "data": {"s": "BTCUSDT", "b": [["83456.67", "0.003"], ["83456.47", "0.003"], ["83423.55", "0"], ["83423.49", "0"]], "a": [["83479.19", "0.015192"], ["83484.85", "0.233424"], ["83491.7", "0"], ["83512.74", "0.003678"], ["83512.84", "0"], ["83515.26", "0.04"], ["83515.27", "0.04"], ["83515.36", "0"], ["83515.37", "0"]], "u": 973444, "seq": 67263902970}, "cts": 1742377425412, "record_time": 1742377426.299691}
{"topic": "orderbook.200.BTCUSDT", "ts": 1742377425614, "type": "delta", "data": {"s": "BTCUSDT", "b": [["83469.17", "0.978781"]], "a": [["83469.18", "0.516659"]], "u": 973445, "seq": 67263902999}, "cts": 1742377425606, "record_time": 1742377426.498698}
{"topic": "orderbook.200.BTCUSDT", "ts": 1742377425814, "type": "delta", "data": {"s": "BTCUSDT", "b": [["83451.62", "0"], ["83445.43", "0"], ["83431.46", "0"], ["83429.52", "0.135791"], ["83423.55", "0.001"], ["83423.49", "0.000242"], ["83423.19", "0.01656"]], "a": [["83491.7", "0.239609"], ["83493.45", "0.119902"], ["83516.88", "0"], ["83516.97", "0"]], "u": 973446, "seq": 67263903024}, "cts": 1742377425807, "record_time": 1742377426.698616}
{"topic": "orderbook.200.BTCUSDT", "ts": 1742377426015, "type": "delta", "data": {"s": "BTCUSDT", "b": [["83435.94", "1.36905"], ["83423.19", "0"]], "a": [["83469.18", "0.531851"], ["83479.19", "0"], ["83479.84", "0"], ["83483.59", "0"], ["83515.25", "0.04"], ["83515.27", "0"], ["83516.88", "0.11"], ["83516.97", "0.003663"], ["83517", "0.000277"]], "u": 973447, "seq": 67263903044}, "cts": 1742377426002, "record_time": 1742377426.89938}
{"topic": "orderbook.200.BTCUSDT", "ts": 1742377426214, "type": "delta", "data": {"s": "BTCUSDT", "b": [["83469.17", "0.979725"], ["83425.55", "0.11"], ["83423.49", "0"]], "a": [["83479.82", "1.384461"], ["83517", "0"]], "u": 973448, "seq": 67263903072}, "cts": 1742377426208, "record_time": 1742377427.102023}
{"topic": "orderbook.200.BTCUSDT", "ts": 1742377426414, "type": "delta", "data": {"s": "BTCUSDT", "b": [["83456.69", "0.003"], ["83456.67", "0"], ["83456.49", "0.003"], ["83456.47", "0"]], "a": [["83479.19", "0.015192"], ["83503.97", "0.359434"], ["83503.98", "0"], ["83514.88", "0"]], "u": 973449, "seq": 67263903099}, "cts": 1742377426409, "record_time": 1742377427.29945}
{"topic": "orderbook.200.BTCUSDT", "ts": 1742377426614, "type": "delta", "data": {"s": "BTCUSDT", "b": [["83469.17", "0.974439"], ["83425.55", "0"], ["83424.08", "0"], ["83423.49", "0.000242"], ["83423.19", "0.01656"]], "a": [["83469.18", "0.516659"], ["83479.19", "0"], ["83503.96", "0.359435"], ["83503.97", "0"], ["83517", "0.000277"]], "u": 973450, "seq": 67263903133}, "cts": 1742377426612, "record_time": 1742377427.499015}
{"topic": "orderbook.200.BTCUSDT", "ts": 1742377426815, "type": "delta", "data": {"s": "BTCUSDT", "b": [], "a": [["83469.18", "0.531851"], ["83488.68", "0.036285"], ["83503.95", "0.359435"], ["83503.96", "0"], ["83512.73", "0.003678"], ["83512.74", "0"]], "u": 973451, "seq": 67263903150}, "cts": 1742377426807, "record_time": 1742377427.700055}
{"topic": "orderbook.200.BTCUSDT", "ts": 1742377427014, "type": "delta", "data": {"s": "BTCUSDT", "b": [["83458.59", "0.041867"], ["83455.47", "0"], ["83429.52", "0.135797"]], "a": [["83469.18", "0.516659"], ["83476.64", "0"], ["83479.76", "0.030854"], ["83488.68", "0.000333"], ["83503.95", "0"], ["83503.98", "0.359437"]], "u": 973452, "seq": 67263903181}, "cts": 1742377427012, "record_time": 1742377427.899976}
{"topic": "orderbook.200.BTCUSDT", "ts": 1742377427215, "type": "delta", "data": {"s": "BTCUSDT", "b": [["83469.17", "0.978861"], ["83467.2", "0.004466"], ["83458.59", "0"], ["83456.08", "0.041868"]], "a": [["83469.18", "0.531851"], ["83473.34", "0.009983"], ["83477.24", "0.030855"], ["83479.76", "0"], ["83491.7", "0"], ["83503.97", "0.359436"], ["83503.98", "0"], ["83517.69", "0.001114"]], "u": 973453, "seq": 67263903214}, "cts": 1742377427209, "record_time": 1742377428.10043}
{"topic": "orderbook.200.BTCUSDT", "ts": 1742377427414, "type": "delta", "data": {"s": "BTCUSDT", "b": [], "a": [["83473.34", "0.010024"], ["83488.68", "0.036285"], ["83503.96", "0.359435"], ["83503.97", "0"]], "u": 973454, "seq": 67263903251}, "cts": 1742377427407, "record_time": 1742377428.299207}
{"topic": "orderbook.200.BTCUSDT", "ts": 1742377427614, "type": "delta", "data": {"s": "BTCUSDT", "b": [["83456.95", "0.157509"], ["83456.86", "0"], ["83450.95", "0.269355"], ["83450.86", "0"], ["83444.95", "0.427527"], ["83444.86", "0"], ["83442.8", "0.001169"], ["83438.63", "0.001169"], ["83438.08", "0.001249"], ["83425.59", "0.11"], ["83424.17", "0"], ["83423.55", "0"], ["83423.49", "0"], ["83423.19", "0"]], "a": [["83469.18", "0.365351"], ["83473.34", "0.004574"], ["83481.46", "0"], ["83481.55", "0.167086"], ["83487.46", "0"], ["83487.55", "0.278657"], ["83488.68", "0.000333"], ["83491.7", "0.239609"], ["83493.46", "0"], ["83493.55", "0.47691"], ["83503.95", "0.359434"], ["83503.96", "0"], ["83514.88", "0.11"], ["83517", "0"], ["83517.69", "0"]], "u": 973455, "seq": 67263903378}, "cts": 1742377427612, "record_time": 1742377428.498791}
{"topic": "orderbook.200.BTCUSDT", "ts": 1742377427814, "type": "delta", "data": {"s": "BTCUSDT", "b": [["83456.95", "0"], ["83456.86", "0.163713"], ["83450.95", "0"], ["83450.86", "0.268601"], ["83444.95", "0"], ["83444.86", "0.47868"], ["83442.8", "0"], ["83442.04", "0.001284"], ["83438.63", "0"], ["83438.08", "0"], ["83437.86", "0.001284"], ["83424.17", "0.003663"]], "a": [["83469.18", "0.531851"], ["83474.59", "0.009051"], ["83478.22", "0"], ["83481.46", "0.168414"], ["83481.55", "0"], ["83487.46", "0.291689"], ["83487.55", "0"], ["83493.46", "0.478373"], ["83493.55", "0"], ["83503.94", "0.360902"], ["83503.95", "0"], ["83514.88", "0"], ["83517", "0.000277"], ["83517.69", "0.001114"]], "u": 973456, "seq": 67263903459}, "cts": 1742377427808, "record_time": 1742377428.700089}
{"topic": "orderbook.200.BTCUSDT", "ts": 1742377428014, "type": "delta", "data": {"s": "BTCUSDT", "b": [["83451.62", "0.239609"], ["83445.43", "0.239609"], ["83443.61", "0.001072"], ["83442.05", "0.001281"], ["83442.04", "0"], ["83439.44", "0.001072"], ["83437.88", "0.001281"], ["83437.86", "0"], ["83429.52", "0.135802"], ["83425.59", "0"], ["83425.53", "0"], ["83425.18", "0"], ["83424.17", "0"]], "a": [["83473.34", "0.010024"], ["83479.8", "0.0036"], ["83488.68", "0.036285"], ["83503.93", "0.359436"], ["83503.94", "0.001466"], ["83515.24", "0.04"], ["83515.26", "0"], ["83517", "0"], ["83517.69", "0"]], "u": 973457, "seq": 67263903511}, "cts": 1742377428005, "record_time": 1742377428.900429}
{"topic": "orderbook.200.BTCUSDT", "ts": 1742377428214, "type": "delta", "data": {"s": "BTCUSDT", "b": [["83443.74", "0.001059"], ["83443.61", "0"], ["83442.66", "0.001188"], ["83442.05", "0"], ["83439.57", "0.001059"], ["83439.44", "0"], ["83438.49", "0.001188"], ["83437.88", "0"]], "a": [["83479.19", "0.015192"], ["83483.76", "0"], ["83488.68", "0.000333"], ["83503.93", "0"], ["83503.98", "0.359436"]], "u": 973458, "seq": 67263903560}, "cts": 1742377428203, "record_time": 1742377429.0997}
{"topic": "orderbook.200.BTCUSDT", "ts": 1742377428414, "type": "delta", "data": {"s": "BTCUSDT", "b": [["83469.17", "0.978839"], ["83456.71", "0.003"], ["83456.69", "0"], ["83456.51", "0.003"], ["83456.49", "0"], ["83443.74", "0"], ["83442.66", "0"], ["83442.52", "0.001208"], ["83442.4", "0.001225"], ["83441.5", "0.001384"], ["83439.57", "0"], ["83438.49", "0"], ["83438.23", "0.001225"]], "a": [["83479.19", "0"], ["83483.78", "0"], ["83502.08", "0.023961"], ["83503.97", "0.359437"], ["83503.98", "0"], ["83517", "0.000277"]], "u": 973459, "seq": 67263903615}, "cts": 1742377428410, "record_time": 1742377429.298919}
{"topic": "orderbook.200.BTCUSDT", "ts": 1742377428614, "type": "delta", "data": {"s": "BTCUSDT", "b": [["83442.52", "0"], ["83442.4", "0"], ["83441.84", "0.001561"], ["83441.5", "0"], ["83438.23", "0"], ["83437.67", "0.001319"], ["83425.53", "0.001917"], ["83425.18", "0.000276"], ["83424.17", "0.003663"]], "a": [["83488.68", "0.036285"], ["83503.96", "0.359436"], ["83503.97", "0"]], "u": 973460, "seq": 67263903662}, "cts": 1742377428607, "record_time": 1742377429.498907}
{"topic": "orderbook.200.BTCUSDT", "ts": 1742377428814, "type": "delta", "data": {"s": "BTCUSDT", "b": [["83469.17", "0.985391"], ["83463.44", "0"], ["83462.85", "0"], ["83456.95", "0.161776"], ["83456.86", "0"], ["83451.62", "0"], ["83450.95", "0.271682"], ["83450.86", "0"], ["83446.64", "0.0719"], ["83445.43", "0"], ["83444.95", "0.472424"], ["83444.86", "0"], ["83443.63", "0.00107"], ["83441.84", "0.000242"], ["83439.46", "0.00107"], ["83439.09", "0.060553"], ["83437.67", "0"], ["83437.32", "0"], ["83429.52", "0.135797"], ["83423.55", "0.001"], ["83423.49", "0.000242"]], "a": [["83469.18", "0.365351"], ["83473.34", "0"], ["83475.85", "0"], ["83479.8", "0"], ["83481.46", "0"], ["83481.55", "0.16293"], ["83485.2", "0.04"], ["83487.46", "0"], ["83487.55", "0.299965"], ["83488.68", "0.000333"], ["83493.45", "0"], ["83493.46", "0"], ["83493.55", "0.469784"], ["83503.96", "0"], ["83507.34", "0.359426"], ["83512.72", "0.003678"], ["83512.73", "0"], ["83516.88", "0"], ["83517.69", "0.001114"], ["83517.71", "0.001466"], ["83517.89", "0.00034"], ["83517.91", "0.000333"], ["83518.25", "0.023959"]], "u": 973461, "seq": 67263903823}, "cts": 1742377428808, "record_time": 1742377429.699504}
{"topic": "orderbook.200.BTCUSDT", "ts": 1742377429014, "type": "delta", "data": {"s": "BTCUSDT", "b": [["83469.17", "0.978861"], ["83464.94", "0.03165"], ["83464.93", "0.071885"], ["83456.99", "0.160353"], ["83456.95", "0"], ["83450.99", "0.297904"], ["83450.95", "0"], ["83446.64", "0"], ["83444.99", "0.464385"], ["83444.95", "0"], ["83443.63", "0"], ["83443.59", "0.001074"], ["83441.95", "0.001299"], ["83439.46", "0"], ["83439.42", "0.001074"], ["83439.09", "0"], ["83439.06", "0.191809"], ["83437.78", "0.001299"], ["83423.55", "0"], ["83423.49", "0"]], "a": [["83469.18", "0.356568"], ["83472.97", "0.008783"], ["83475.85", "0.011979"], ["83475.93", "0"], ["83477.6", "0"], ["83479.27", "0"], ["83479.6", "0.239579"], ["83481.27", "0.239575"], ["83481.55", "0"], ["83481.59", "0.174798"], ["83482.94", "0.23957"], ["83487.55", "0"], ["83487.59", "0.270915"], ["83493.55", "0"], ["83493.59", "0.496719"], ["83507.33", "0.359421"], ["83507.34", "0"], ["83518.25", "0"]], "u": 973462, "seq": 67263903960}, "cts": 1742377429005, "record_time": 1742377429.899387}
{"topic": "orderbook.200.BTCUSDT", "ts": 1742377429214, "type": "delta", "data": {"s": "BTCUSDT", "b": [["83469.17", "0.973439"], ["83459.55", "0.072088"], ["83458.65", "0.183091"], ["83456.99", "0.172819"], ["83450.99", "0.278558"], ["83449.65", "0.301496"], ["83444.99", "0.461519"], ["83443.75", "0.001058"], ["83443.65", "0.461085"], ["83443.59", "0"], ["83441.95", "0"], ["83439.58", "0.001058"], ["83439.42", "0"], ["83437.78", "0"], ["83435.94", "0"], ["83423.55", "0.001"], ["83423.49", "0.000242"], ["83423.19", "0.01656"]], "a": [["83479.12", "0"], ["83479.65", "0.175809"], ["83479.82", "0"], ["83481.59", "0.169945"], ["83484.05", "0"], ["83484.27", "0.003"], ["83484.85", "0.143785"], ["83487.59", "0.264629"], ["83488.05", "0.003"], ["83488.65", "0.282379"], ["83488.68", "0.036285"], ["83493.59", "0.49368"], ["83494.65", "0.465589"], ["83507.32", "0.359423"], ["83507.33", "0"], ["83518.25", "0.023959"]], "u": 973463, "seq": 67263904125}, "cts": 1742377429211, "record_time": 1742377430.099619}
{"topic": "orderbook.200.BTCUSDT", "ts": 1742377429414, "type": "delta", "data": {"s": "BTCUSDT", "b": [["83469.17", "0.974063"], ["83459.55", "0.071285"], ["83458.65", "0.180414"], ["83456.99", "0.167027"], ["83450.99", "0.277245"], ["83449.65", "0.278624"], ["83444.99", "0.453024"], ["83443.75", "0"], ["83443.65", "0.477562"], ["83442.42", "0.001222"], ["83441.85", "0.001316"], ["83441.68", "0.001349"], ["83439.58", "0"], ["83437.93", "0.001273"], ["83435.94", "1.374197"], ["83429.52", "0.135798"], ["83423.55", "0"], ["83423.49", "0"], ["83423.19", "0"]], "a": [["83475.85", "0"], ["83479.65", "0.169566"], ["83480.52", "1.32708"], ["83481.59", "0.160434"], ["83487.59", "0.269568"], ["83488.65", "0.293226"], ["83488.68", "0.000333"], ["83493.59", "0.444629"], ["83494.65", "0.426405"], ["83507.32", "0"], ["83508.18", "0.359418"]], "u": 973464, "seq": 67263904363}, "cts": 1742377429406, "record_time": 1742377430.29919}
{"topic": "orderbook.200.BTCUSDT", "ts": 1742377429614, "type": "delta", "data": {"s": "BTCUSDT", "b": [["83469.17", "1.158046"], ["83458.66", "0.165525"], ["83458.65", "0"], ["83457.07", "0.168135"], ["83456.99", "0"], ["83451.07", "0.26813"], ["83450.99", "0"], ["83449.66", "0.268308"], ["83449.65", "0"], ["83445.07", "0.425883"], ["83444.99", "0"], ["83443.66", "0.482054"], ["83443.65", "0"], ["83443.16", "0.001123"], ["83442.87", "0.001159"], ["83442.42", "0"], ["83441.85", "0"], ["83441.68", "0"], ["83438.99", "0.001123"], ["83437.93", "0"], ["83426.08", "0.11"], ["83423.55", "0.001"]], "a": [["83469.18", "0.341376"], ["83479.19", "0.015192"], ["83479.65", "0"], ["83479.66", "0.172289"], ["83481.59", "0"], ["83481.67", "0.15876"], ["83487.59", "0"], ["83487.67", "0.270087"], ["83488.65", "0"], ["83488.66", "0.288583"], ["83488.68", "0.036285"], ["83493.59", "0.023961"], ["83493.67", "0.449085"], ["83494.65", "0"], ["83494.66", "0.470123"], ["83508.18", "0"], ["83510.26", "0.359417"], ["83518.25", "0"]], "u": 973465, "seq": 67263904587}, "cts": 1742377429612, "record_time": 1742377430.498823}
{"topic": "orderbook.200.BTCUSDT", "ts": 1742377429814, "type": "delta", "data": {"s": "BTCUSDT", "b": [["83465.19", "0.01198"], ["83460", "0.00006"], ["83459.55", "0.065605"], ["83458.66", "0.003"], ["83458.65", "0.16148"], ["83457.68", "0.01797"], ["83457.07", "0"], ["83456.99", "0.178704"], ["83452.49", "0"], ["83451.07", "0"], ["83450.99", "0.290694"], ["83449.66", "0"], ["83449.65", "0.286672"], ["83445.07", "0"], ["83444.99", "0.479428"], ["83443.66", "0"], ["83443.65", "0.425924"], ["83443.16", "0"], ["83442.87", "0"], ["83441.68", "0.001348"], ["83441.51", "0.001383"], ["83438.99", "0"], ["83437.45", "0.001359"], ["83429.52", "0.135793"], ["83424.17", "0"], ["83423.55", "0"]], "a": [["83479.19", "0"], ["83479.65", "0.161374"], ["83479.66", "0.001968"], ["83481.59", "0.171103"], ["83481.67", "0"], ["83487.59", "0.271601"], ["83487.67", "0"], ["83488.65", "0.280075"], ["83488.66", "0"], ["83493.59", "0.492739"], ["83493.67", "0"], ["83494.65", "0.470057"], ["83494.66", "0"], ["83514.98", "0.11"], ["83517.08", "0.11"], ["83517.91", "0"]], "u": 973466, "seq": 67263904732}, "cts": 1742377429804, "record_time": 1742377430.6996}
{"topic": "orderbook.200.BTCUSDT", "ts": 1742377430015, "type": "delta", "data": {"s": "BTCUSDT", "b": [["83469.17", "0.991546"], ["83459.55", "0.068451"], ["83458.65", "0.170968"], ["83456.99", "0.15994"], ["83450.99", "0.289269"], ["83449.65", "0.267238"], ["83444.99", "0.462512"], ["83443.65", "0.454037"], ["83441.68", "0"], ["83441.51", "0"], ["83437.45", "0"], ["83429.52", "0.1358"], ["83424.17", "0.003663"], ["83423.55", "0.001"], ["83423.49", "0.000242"]], "a": [["83469.18", "0.356568"], ["83479.65", "0.170648"], ["83481.59", "0.177724"], ["83487.59", "0.285512"], ["83488.65", "0.270116"], ["83488.68", "0.000333"], ["83493.59", "0.489271"], ["83494.65", "0.468112"], ["83512.72", "0"], ["83512.92", "0.003678"], ["83514.98", "0"], ["83515.24", "0"], ["83515.25", "0"], ["83515.43", "0.04"], ["83515.44", "0.04"], ["83517.91", "0.000333"]], "u": 973467, "seq": 67263904895}, "cts": 1742377430011, "record_time": 1742377430.90097}
{"topic": "orderbook.200.BTCUSDT", "ts": 1742377430214, "type": "delta", "data": {"s": "BTCUSDT", "b": [["83469.17", "1.169026"], ["83459.55", "0.018584"], ["83458.65", "0"], ["83458.37", "0"], ["83458.3", "0.212263"], ["83457.84", "0.226378"], ["83457.49", "0.165038"], ["83457.47", "0"], ["83456.99", "0"], ["83452.3", "0.294582"], ["83450.99", "0"], ["83449.97", "0"], ["83449.65", "0"], ["83448.19", "0.298129"], ["83448.17", "0"], ["83446.3", "0.43142"], ["83444.99", "0"], ["83443.65", "0"], ["83443.63", "0.00107"], ["83442.19", "0.48639"], ["83442.17", "0"], ["83441.82", "0.001322"], ["83439.46", "0.00107"], ["83437.65", "0.001322"], ["83423.19", "0.01656"], ["83423.06", "0.195"]], "a": [["83469.18", "0.194667"], ["83472.97", "0"], ["83477.76", "0.008783"], ["83479.19", "0.015192"], ["83479.65", "0"], ["83479.97", "0"], ["83480.87", "0"], ["83480.89", "0.172151"], ["83481.59", "0"], ["83482.9", "0.171517"], ["83487.59", "0"], ["83488.37", "0"], ["83488.65", "0"], ["83488.68", "0.036285"], ["83488.9", "0.292752"], ["83490.17", "0"], ["83490.19", "0.266331"], ["83493.59", "0.023961"], ["83494.65", "0"], ["83494.9", "0.48139"], ["83496.17", "0"], ["83496.19", "0.447821"], ["83508.18", "0.359415"], ["83510.26", "0"], ["83518.25", "0.023959"], ["83518.75", "0.027431"], ["83518.84", "0.001333"]], "u": 973468, "seq": 67263905223}, "cts": 1742377430210, "record_time": 1742377431.09922}
{"topic": "orderbook.200.BTCUSDT", "ts": 1742377430414, "type": "delta", "data": {"s": "BTCUSDT", "b": [["83469.17", "1.002526"], ["83466.72", "0.035499"], ["83466.71", "0.071883"], ["83464.94", "0"], ["83464.93", "0"], ["83459.55", "0.115775"], ["83458.3", "0.044"], ["83458.17", "0.238968"], ["83457.84", "0"], ["83457.49", "0"], ["83456.72", "0.003"], ["83456.71", "0"], ["83456.52", "0.003"], ["83456.51", "0"], ["83452.3", "0"], ["83448.19", "0"], ["83446.57", "0.0719"], ["83446.3", "0"], ["83445.02", "0.284423"], ["83443.63", "0"], ["83443.18", "0.001121"], ["83442.35", "0.001233"], ["83442.19", "0"], ["83441.82", "0"], ["83439.46", "0"], ["83439.06", "0.119902"], ["83439.01", "0.001121"], ["83437.65", "0"], ["83429.52", "0.135794"], ["83422.96", "0.000242"], ["83422.84", "0.001333"], ["83422.58", "0.119902"], ["83422.56", "0.013851"], ["83421.93", "0.060553"]], "a": [["83480.89", "0"], ["83482.9", "0"], ["83488.9", "0"], ["83490.19", "0"], ["83494.9", "0"], ["83496.19", "0"], ["83508.17", "0.359415"], ["83508.18", "0"], ["83512.92", "0"], ["83515.43", "0"], ["83515.44", "0"], ["83519.37", "0.024199"], ["83519.56", "0.00009"], ["83519.63", "0.00009"], ["83519.9", "0.000243"], ["83520", "0.00024"], ["83520.2", "0.089922"], ["83520.57", "0.119805"], ["83520.62", "0.119902"], ["83520.93", "0.167727"]], "u": 973469, "seq": 67263905540}, "cts": 1742377430408, "record_time": 1742377431.298747}
{"topic": "orderbook.200.BTCUSDT", "ts": 1742377430615, "type": "delta", "data": {"s": "BTCUSDT", "b": [["83469.17", "1.184002"], ["83459.55", "0.121228"], ["83459.13", "0.174381"], ["83458.85", "0.172509"], ["83458.17", "0.142072"], ["83458.03", "0.178321"], ["83457.48", "0.181438"], ["83454.13", "0.249744"], ["83452.03", "0.272769"], ["83450.45", "0.30133"], ["83450.13", "0.270449"], ["83449.98", "0"], ["83448.18", "0.271101"], ["83446.03", "0.468338"], ["83445.02", "0"], ["83444.13", "0.454148"], ["83443.18", "0"], ["83442.65", "0.463627"], ["83442.35", "0"], ["83442.18", "0.451807"], ["83442.15", "0.001265"], ["83441.56", "0.001373"], ["83439.01", "0"], ["83437.38", "0.001373"], ["83424.17", "0"], ["83423.55", "0"], ["83423.49", "0"], ["83423.19", "0"], ["83423.06", "0"], ["83422.96", "0"], ["83422.84", "0"], ["83422.58", "0"], ["83422.56", "0"], ["83421.93", "0"]], "a": [["83469.18", "0.224836"], ["83475.85", "0.007009"], ["83479.19", "0"], ["83480.13", "0.176644"], ["83480.45", "0.1676"], ["83480.88", "0.18346"], ["83482.63", "0.170316"], ["83488.63", "0.263357"], ["83488.68", "0.000333"], ["83488.85", "0.283313"], ["83489.13", "0.27776"], ["83490.18", "0.268872"], ["83494.63", "0.469175"], ["83495.13", "0.445839"], ["83496.18", "0.485937"], ["83496.65", "0.474692"], ["83507.34", "0.359416"], ["83508.17", "0"], ["83518.75", "0"], ["83518.84", "0"], ["83519.37", "0"], ["83519.56", "0"], ["83519.63", "0"], ["83519.9", "0"], ["83520", "0"], ["83520.2", "0"], ["83520.57", "0"], ["83520.62", "0"], ["83520.93", "0"]], "u": 973470, "seq": 67263905801}, "cts": 1742377430612, "record_time": 1742377431.499994}
{"topic": "orderbook.200.BTCUSDT", "ts": 1742377430814, "type": "delta", "data": {"s": "BTCUSDT", "b": [["83459.55", "0.118744"], ["83459.28", "0.164365"], ["83459.13", "0"], ["83459", "0.174246"], ["83458.85", "0"], ["83458.17", "0.390679"], ["83458.03", "0"], ["83452.17", "0.264653"], ["83452.03", "0"], ["83451.62", "0.239609"], ["83450.6", "0.281047"], ["83450.45", "0"], ["83450.28", "0.300019"], ["83450.13", "0"], ["83446.17", "0.478687"], ["83446.03", "0"], ["83445.43", "0.239609"], ["83444.28", "0.459064"], ["83444.13", "0"], ["83442.8", "0.421992"], ["83442.65", "0"], ["83442.15", "0"], ["83441.56", "0"], ["83441.45", "0.001394"], ["83441.37", "0.001411"], ["83437.38", "0"], ["83437.2", "0.001411"], ["83425.18", "0"]], "a": [["83469.18", "0.209644"], ["83475.85", "0"], ["83480.13", "0"], ["83480.28", "0.165784"], ["83480.45", "0"], ["83480.6", "0.178583"], ["83482.63", "0.000242"], ["83482.77", "0.170177"], ["83488.63", "0"], ["83488.68", "0.036284"], ["83488.77", "0.27365"], ["83488.85", "0"], ["83489", "0.277898"], ["83489.13", "0"], ["83489.28", "0.272769"], ["83494.63", "0"], ["83494.77", "0.423907"], ["83495.13", "0"], ["83495.28", "0.485143"], ["83496.65", "0"], ["83496.8", "0.480165"], ["83507.34", "0"], ["83510.26", "0.359416"]], "u": 973471, "seq": 67263905975}, "cts": 1742377430806, "record_time": 1742377431.699089}
{"topic": "orderbook.200.BTCUSDT", "ts": 1742377431014, "type": "delta", "data": {"s": "BTCUSDT", "b": [["83459.55", "0.115277"], ["83459.28", "0"], ["83459", "0"], ["83458.17", "0.231341"], ["83454.13", "0.531563"], ["83452.17", "0"], ["83450.6", "0"], ["83450.28", "0"], ["83446.17", "0"], ["83444.28", "0"], ["83442.8", "0"], ["83441.97", "0.001296"], ["83441.45", "0"], ["83441.37", "0"], ["83437.79", "0.001296"], ["83437.2", "0"], ["83425.18", "0.000276"], ["83424.17", "0.003663"], ["83423.55", "0.001"], ["83423.49", "0.000242"], ["83423.19", "0.01656"], ["83423.06", "0.195"], ["83422.96", "0.000242"], ["83422.84", "0.001333"], ["83422.58", "0.119902"]], "a": [["83479.19", "0.015192"], ["83480.28", "0"], ["83480.6", "0"], ["83482.77", "0"], ["83488.68", "0.036285"], ["83488.77", "0"], ["83489", "0"], ["83489.28", "0"], ["83494.77", "0"], ["83495.28", "0"], ["83496.8", "0"], ["83518.75", "0.027431"], ["83518.84", "0.001333"], ["83519.37", "0.024199"], ["83519.56", "0.00009"], ["83519.63", "0.00009"], ["83519.9", "0.000243"], ["83520", "0.00024"], ["83520.2", "0.089922"]], "u": 973472, "seq": 67263906074}, "cts": 1742377431009, "record_time": 1742377431.899983}
{"topic": "orderbook.200.BTCUSDT", "ts": 1742377431214, "type": "delta", "data": {"s": "BTCUSDT", "b": [["83469.17", "1.015579"], ["83459.55", "0.124358"], ["83459.13", "0.178217"], ["83458.85", "0.179108"], ["83458.03", "0.164621"], ["83454.13", "0.249744"], ["83452.03", "0.294532"], ["83450.45", "0.266714"], ["83450.13", "0.30257"], ["83446.03", "0.429156"], ["83444.13", "0.483056"], ["83443.02", "0.00114"], ["83442.65", "0.470145"], ["83442.22", "0.001253"], ["83442", "0.00129"], ["83441.97", "0"], ["83438.85", "0.00114"], ["83437.79", "0"], ["83425.87", "0"], ["83425.53", "0"], ["83425.18", "0"], ["83424.17", "0"], ["83423.55", "0"], ["83423.49", "0"], ["83423.19", "0"], ["83423.06", "0"], ["83422.96", "0"], ["83422.84", "0"], ["83422.58", "0"]], "a": [["83479.19", "0.014915"], ["83480.13", "0.164719"], ["83480.45", "0.158158"], ["83482.63", "0.162919"], ["83488.63", "0.266028"], ["83488.68", "0.000333"], ["83488.85", "0.275474"], ["83489.13", "0.278392"], ["83494.63", "0.420973"], ["83495.13", "0.450701"], ["83496.65", "0.45437"], ["83507.34", "0.359416"], ["83510.26", "0"], ["83518.75", "0"], ["83518.84", "0"], ["83519.37", "0"], ["83519.56", "0"], ["83519.63", "0"], ["83519.9", "0"], ["83520", "0"], ["83520.2", "0"]], "u": 973473, "seq": 67263906197}, "cts": 1742377431210, "record_time": 1742377432.099481}
{"topic": "orderbook.200.BTCUSDT", "ts": 1742377431414, "type": "delta", "data": {"s": "BTCUSDT", "b": [["83459.55", "0.123427"], ["83459.13", "0.175554"], ["83458.85", "0.178665"], ["83458.04", "0.167517"], ["83458.03", "0"], ["83454.13", "0.536992"], ["83452.04", "0.284266"], ["83452.03", "0"], ["83450.45", "0.293162"], ["83450.13", "0.281653"], ["83446.04", "0.440363"], ["83446.03", "0"], ["83444.13", "0.450561"], ["83443.02", "0"], ["83442.65", "0.478053"], ["83442.24", "0.001251"], ["83442.22", "0"], ["83442", "0"], ["83441.44", "0.001397"], ["83438.85", "0"], ["83438.06", "0.001251"], ["83437.27", "0.001397"]], "a": [["83469.18", "0.224559"], ["83479.19", "0"], ["83480.13", "0.17354"], ["83480.45", "0.161901"], ["83482.63", "0.000242"], ["83482.64", "0.162791"], ["83488.63", "0"], ["83488.64", "0.300073"], ["83488.68", "0.036285"], ["83488.85", "0.269484"], ["83489.13", "0.303481"], ["83494.63", "0"], ["83494.64", "0.44064"], ["83495.13", "0.466201"], ["83496.65", "0.477959"], ["83507.34", "0"], ["83510.26", "0.359415"]], "u": 973474, "seq": 67263906344}, "cts": 1742377431410, "record_time": 1742377432.299383}
{"topic": "orderbook.200.BTCUSDT", "ts": 1742377431614, "type": "delta", "data": {"s": "BTCUSDT", "b": [["83469.17", "1.182079"], ["83466.71", "0"], ["83466.63", "0.071883"], ["83459.55", "0.121622"], ["83459.13", "0.169226"], ["83458.85", "0.178978"], ["83458.04", "0.176084"], ["83452.04", "0.294076"], ["83450.45", "0.288902"], ["83450.13", "0.273326"], ["83446.04", "0.428741"], ["83444.13", "0.452797"], ["83443.44", "0.001091"], ["83442.65", "0.449718"], ["83442.24", "0"], ["83441.44", "0"], ["83439.27", "0.001091"], ["83438.06", "0"], ["83437.27", "0"], ["83425.87", "0.001123"], ["83425.53", "0.001917"]], "a": [["83480.13", "0.17397"], ["83480.45", "0.169926"], ["83482.64", "0.165672"], ["83488.64", "0.270114"], ["83488.85", "0.26504"], ["83489.13", "0.267013"], ["83494.64", "0.438168"], ["83495.13", "0.476497"], ["83496.65", "0.477332"]], "u": 973475, "seq": 67263906503}, "cts": 1742377431606, "record_time": 1742377432.499407}
{"topic": "orderbook.200.BTCUSDT", "ts": 1742377431814, "type": "delta", "data": {"s": "BTCUSDT", "b": [["83469.17", "1.002519"], ["83459.55", "0.119526"], ["83459.13", "0"], ["83458.85", "0"], ["83458.17", "0.142072"], ["83458.04", "0"], ["83457.48", "0"], ["83452.04", "0"], ["83451.62", "0"], ["83450.45", "0"], ["83450.13", "0"], ["83448.18", "0"], ["83446.04", "0"], ["83445.43", "0"], ["83444.13", "0"], ["83443.44", "0"], ["83442.65", "0"], ["83442.18", "0"], ["83441.42", "0.001401"], ["83439.27", "0"], ["83437.25", "0.001643"], ["83425.18", "0.000276"], ["83424.17", "0.003663"], ["83423.55", "0.001"], ["83423.49", "0.000242"], ["83423.19", "0.01656"], ["83423.06", "0.195"], ["83422.96", "0.000242"], ["83422.84", "0.001333"], ["83422.58", "0.119902"], ["83422.56", "0.013851"], ["83421.93", "0.060553"], ["83421.92", "0.000333"], ["83421.7", "0.001123"], ["83421.31", "0.001466"], ["83421.1", "0.044"]], "a": [["83472.48", "0.000153"], ["83473.69", "0"], ["83475.85", "0.011979"], ["83480.13", "0"], ["83480.45", "0"], ["83480.88", "0"], ["83482.64", "0"], ["83488.64", "0"], ["83488.68", "0.000333"], ["83488.85", "0"], ["83489.13", "0"], ["83490.18", "0"], ["83494.64", "0"], ["83495.13", "0"], ["83496.18", "0"], ["83496.65", "0"], ["83508.18", "0.359417"], ["83510.26", "0"], ["83518.75", "0.027431"], ["83518.84", "0.001333"], ["83519.37", "0.024199"], ["83519.56", "0.00009"], ["83519.63", "0.00009"], ["83519.9", "0.000243"], ["83520", "0.00024"], ["83520.2", "0.089922"], ["83520.57", "0.119805"], ["83520.62", "0.119902"], ["83520.93", "0.167727"]], "u": 973476, "seq": 67263906756}, "cts": 1742377431811, "record_time": 1742377432.700735}
{"topic": "orderbook.200.BTCUSDT", "ts": 1742377432014, "type": "delta", "data": {"s": "BTCUSDT", "b": [["83459.55", "0.018584"], ["83459.12", "0.174391"], ["83458.84", "0.174039"], ["83458.02", "0.172799"], ["83457.48", "0.17498"], ["83454.13", "0.249744"], ["83452.02", "0.298746"], ["83450.44", "0.285884"], ["83450.12", "0.296933"], ["83449.61", "0.161951"], ["83448.18", "0.270435"], ["83446.02", "0.434258"], ["83444.12", "0.42862"], ["83442.64", "0.464952"], ["83442.18", "0.453541"], ["83441.48", "0.001389"], ["83441.42", "0"], ["83437.31", "0.001389"], ["83437.25", "0.000242"], ["83423.55", "0"], ["83423.49", "0"], ["83423.19", "0"], ["83423.06", "0"], ["83422.96", "0"], ["83422.84", "0"], ["83422.58", "0"], ["83422.56", "0"], ["83421.93", "0"], ["83421.92", "0"], ["83421.7", "0"], ["83421.31", "0"], ["83421.1", "0"]], "a": [["83479.19", "0.014915"], ["83480.12", "0.167235"], ["83480.44", "0.180872"], ["83480.88", "0.171493"], ["83482.62", "0.167388"], ["83488.62", "0.266471"], ["83488.68", "0.036285"], ["83488.84", "0.281403"], ["83489.12", "0.284604"], ["83489.89", "0.0036"], ["83490.18", "0.305505"], ["83494.62", "0.428043"], ["83495.12", "0.431361"], ["83496.18", "0.474588"], ["83496.64", "0.436774"], ["83504.82", "0.359422"], ["83508.18", "0"], ["83514.88", "0.11"], ["83517.89", "0"], ["83517.91", "0"], ["83518.25", "0"], ["83518.75", "0"], ["83518.84", "0"], ["83519.37", "0"], ["83519.56", "0"], ["83519.63", "0"], ["83519.9", "0"], ["83520", "0"], ["83520.2", "0"], ["83520.57", "0"], ["83520.62", "0"], ["83520.93", "0"]], "u": 973477, "seq": 67263906973}, "cts": 1742377432008, "record_time": 1742377432.899297}
{"topic": "orderbook.200.BTCUSDT", "ts": 1742377432214, "type": "delta", "data": {"s": "BTCUSDT", "b": [["83466.63", "0"], ["83464.46", "0.071885"], ["83459.55", "0.117858"], ["83459.28", "0.159968"], ["83459.12", "0"], ["83458.99", "0.17569"], ["83458.84", "0"], ["83458.17", "0.227307"], ["83458.15", "0.160504"], ["83458.02", "0.001466"], ["83452.15", "0.29445"], ["83452.02", "0"], ["83450.59", "0.283936"], ["83450.44", "0"], ["83450.28", "0.278998"], ["83450.12", "0"], ["83446.15", "0.440646"], ["83446.02", "0"], ["83444.28", "0.441899"], ["83444.12", "0"], ["83442.79", "0.438535"], ["83442.64", "0"], ["83441.48", "0"], ["83437.31", "0"], ["83426.08", "0"], ["83423.55", "0.001"], ["83423.49", "0.000242"]], "a": [["83469.18", "0.209644"], ["83474.59", "0"], ["83479.19", "0"], ["83480.12", "0.001113"], ["83480.28", "0.181511"], ["83480.44", "0"], ["83480.59", "0.175985"], ["83482.62", "0"], ["83482.75", "0.175777"], ["83488.62", "0"], ["83488.75", "0.292291"], ["83488.84", "0"], ["83488.99", "0.291319"], ["83489.12", "0"], ["83489.28", "0.267265"], ["83494.62", "0"], ["83494.75", "0.458748"], ["83495.12", "0"], ["83495.28", "0.430765"], ["83496.64", "0"], ["83496.79", "0.425743"], ["83504.82", "0"], ["83507.34", "0.359422"], ["83517.89", "0.00034"], ["83517.91", "0.000333"], ["83518.25", "0.023959"]], "u": 973478, "seq": 67263907064}, "cts": 1742377432207, "record_time": 1742377433.099217}
{"topic": "orderbook.200.BTCUSDT", "ts": 1742377432414, "type": "delta", "data": {"s": "BTCUSDT", "b": [["83469.17", "1.020439"], ["83459.55", "0.115828"], ["83459.28", "0"], ["83459.15", "0.164846"], ["83458.99", "0"], ["83458.87", "0.164045"], ["83458.15", "0"], ["83458.04", "0.179443"], ["83456.72", "0"], ["83456.52", "0"], ["83454.13", "0.46318"], ["83452.15", "0"], ["83452.04", "0.300167"], ["83450.59", "0"], ["83450.47", "0.27454"], ["83450.28", "0"], ["83450.15", "0.297693"], ["83446.15", "0"], ["83446.04", "0.438364"], ["83444.28", "0"], ["83444.15", "0.466405"], ["83442.79", "0"], ["83442.67", "0.463445"], ["83423.19", "0.01656"], ["83423.06", "0.195"], ["83422.96", "0.000242"]], "a": [["83469.18", "0.224559"], ["83480.15", "0.162281"], ["83480.28", "0"], ["83480.47", "0.163825"], ["83480.59", "0.001106"], ["83482.64", "0.179144"], ["83482.75", "0"], ["83488.64", "0.283291"], ["83488.68", "0.000333"], ["83488.75", "0"], ["83488.87", "0.295362"], ["83488.99", "0"], ["83489.15", "0.274825"], ["83489.28", "0"], ["83494.64", "0.427358"], ["83494.75", "0.001466"], ["83495.15", "0.44392"], ["83495.28", "0"], ["83496.67", "0.46047"], ["83496.79", "0"], ["83507.33", "0.359419"], ["83507.34", "0"], ["83514.88", "0"], ["83518.25", "0"]], "u": 973479, "seq": 67263907241}, "cts": 1742377432407, "record_time": 1742377433.299566}
{"topic": "orderbook.200.BTCUSDT", "ts": 1742377432614, "type": "delta", "data": {"s": "BTCUSDT", "b": [["83459.55", "0.018584"], ["83459.15", "0.164399"], ["83458.87", "0.1586"], ["83458.04", "0.157986"], ["83452.04", "0.294687"], ["83450.47", "0.295634"], ["83450.15", "0.270689"], ["83446.04", "0.460956"], ["83444.15", "0.427709"], ["83442.67", "0.423798"]], "a": [["83480.15", "0.175796"], ["83480.47", "0.174693"], ["83480.52", "0"], ["83482.64", "0.176072"], ["83488.64", "0.29951"], ["83488.68", "0.036285"], ["83488.87", "0.263036"], ["83489.15", "0.274035"], ["83489.89", "0"], ["83494.64", "0.471892"], ["83495.15", "0.46265"], ["83496.67", "0.453994"], ["83507.33", "0"], ["83510.26", "0.359417"], ["83518.25", "0.023959"], ["83518.75", "0.027431"]], "u": 973480, "seq": 67263907370}, "cts": 1742377432603, "record_time": 1742377433.499374}
{"topic": "orderbook.200.BTCUSDT", "ts": 1742377432814, "type": "delta", "data": {"s": "BTCUSDT", "b": [["83465.35", "0"], ["83459.55", "0.065185"], ["83459.15", "0"], ["83458.87", "0"], ["83458.65", "0.160082"], ["83458.37", "0.164043"], ["83458.17", "0.142072"], ["83458.04", "0"], ["83457.48", "0"], ["83457.47", "0.160262"], ["83457.09", "0.162736"], ["83452.04", "0"], ["83451.09", "0.290937"], ["83450.47", "0"], ["83450.15", "0"], ["83449.97", "0.292261"], ["83449.65", "0.295402"], ["83448.18", "0"], ["83448.17", "0.286548"], ["83446.04", "0"], ["83445.09", "0.46504"], ["83444.15", "0"], ["83443.65", "0.447918"], ["83442.67", "0.00018"], ["83442.18", "0"], ["83442.17", "0.908383"], ["83438.95", "1.327371"], ["83435.94", "0"], ["83429.52", "0.135797"], ["83422.84", "0.001333"], ["83422.58", "0.119902"]], "a": [["83469.18", "0.345169"], ["83472.78", "0"], ["83479.19", "0.014915"], ["83479.65", "0.177085"], ["83479.97", "0.169057"], ["83480.15", "0"], ["83480.47", "0"], ["83480.87", "0.178742"], ["83480.88", "0"], ["83481.69", "0.163498"], ["83482.64", "0"], ["83483.45", "1.355822"], ["83487.69", "0.28841"], ["83488.37", "0.264512"], ["83488.64", "0"], ["83488.65", "0.287397"], ["83488.68", "0.000333"], ["83488.87", "0"], ["83489.15", "0"], ["83490.17", "0.292515"], ["83490.18", "0"], ["83492.15", "0.0036"], ["83493.69", "0.464684"], ["83494.64", "0"], ["83494.65", "0.428172"], ["83495.15", "0"], ["83496.17", "0.908684"], ["83496.18", "0"], ["83496.67", "0"], ["83507.34", "0.35942"], ["83510.26", "0"], ["83518.75", "0"]], "u": 973481, "seq": 67263907477}, "cts": 1742377432810, "record_time": 1742377433.699368}
{"topic": "orderbook.200.BTCUSDT", "ts": 1742377433014, "type": "delta", "data": {"s": "BTCUSDT", "b": [["83469.17", "1.002519"], ["83466", "0.000099"], ["83459.55", "0"], ["83459.23", "0.079687"], ["83458.65", "0.178678"], ["83458.6", "0.041867"], ["83458.37", "0.179047"], ["83458.17", "0.218513"], ["83457.09", "0.160616"], ["83456.08", "0"], ["83454.13", "0.249744"], ["83451.09", "0.281025"], ["83449.97", "0.28949"], ["83449.65", "0.286334"], ["83445.09", "0.430115"], ["83443.65", "0.438764"], ["83442.17", "0.951998"], ["83422.58", "0"]], "a": [["83472.35", "0.000099"], ["83477.24", "0"], ["83479.19", "0"], ["83479.65", "0.180628"], ["83479.75", "0.030854"], ["83479.97", "0.177003"], ["83481.69", "0.174491"], ["83487.69", "0.271951"], ["83488.37", "0.298211"], ["83488.65", "0.293802"], ["83493.65", "0.119902"], ["83493.69", "0.481897"], ["83494.65", "0.4365"], ["83496.17", "0.911204"], ["83507.33", "0.35942"], ["83507.34", "0"], ["83518.25", "0"]], "u": 973482, "seq": 67263907641}, "cts": 1742377433006, "record_time": 1742377433.89916}
{"topic": "orderbook.200.BTCUSDT", "ts": 1742377433214, "type": "delta", "data": {"s": "BTCUSDT", "b": [["83469.17", "1.140219"], ["83459.23", "0.02981"], ["83458.65", "0.166061"], ["83458.37", "0.164778"], ["83457.09", "0.177455"], ["83454.12", "0"], ["83451.09", "0.294194"], ["83449.97", "0.282353"], ["83449.65", "0.284604"], ["83445.09", "0.438833"], ["83445.02", "0.555017"], ["83443.65", "0.458985"], ["83442.17", "0.932435"], ["83439.09", "0.060553"], ["83426.08", "0.11"], ["83424.82", "0.02092"], ["83423.06", "0"], ["83422.96", "0"], ["83422.84", "0"]], "a": [["83472.48", "0"], ["83476.36", "0.000153"], ["83479.65", "0.181223"], ["83479.97", "0.175464"], ["83481.69", "0.170691"], ["83487.69", "0.290608"], ["83488.37", "0.265401"], ["83488.65", "0.29009"], ["83488.75", "0.035952"], ["83489.19", "0"], ["83492.15", "0"], ["83493.65", "0"], ["83493.69", "0.452914"], ["83494.65", "0.473417"], ["83495.24", "0"], ["83496.17", "0.926335"], ["83498.71", "0.119902"], ["83503.14", "0"], ["83507.33", "0"], ["83509.91", "0.026959"], ["83510.26", "0.359417"], ["83511.85", "0"], ["83511.97", "0.000149"], ["83514.11", "0"], ["83518.25", "0.023959"], ["83518.75", "0.027431"], ["83518.84", "0.001333"], ["83519.37", "0.024199"], ["83519.56", "0.00009"]], "u": 973483, "seq": 67263908012}, "cts": 1742377433207, "record_time": 1742377434.099865}
{"topic": "orderbook.200.BTCUSDT", "ts": 1742377433414, "type": "delta", "data": {"s": "BTCUSDT", "b": [["83469.17", "1.306719"], ["83466.06", "0.071884"], ["83464.46", "0"], ["83459.23", "0.075902"], ["83456.73", "0.003"], ["83456.63", "0.239609"], ["83456.53", "0.003"], ["83448.09", "0"], ["83432.25", "0.135797"], ["83429.52", "0"], ["83423.49", "0"], ["83423.19", "0"]], "a": [["83475.85", "0"], ["83485.53", "0"], ["83488.74", "0.035951"], ["83488.75", "0"], ["83494.2", "0.239609"], ["83509.91", "0.023959"], ["83514.98", "0.11"], ["83516.83", "0.003"], ["83519.56", "0"]], "u": 973484, "seq": 67263908248}, "cts": 1742377433411, "record_time": 1742377434.29906}
{"topic": "orderbook.200.BTCUSDT", "ts": 1742377433614, "type": "delta", "data": {"s": "BTCUSDT", "b": [["83459.23", "0.129251"], ["83458.66", "0.181269"], ["83458.65", "0"], ["83458.38", "0.16562"], ["83458.37", "0"], ["83457.15", "0.167594"], ["83457.09", "0"], ["83451.15", "0.29496"], ["83451.09", "0"], ["83449.98", "0.264659"], ["83449.97", "0"], ["83449.66", "0.275533"], ["83449.65", "0"], ["83449.6", "0"], ["83445.15", "0.462541"], ["83445.09", "0"], ["83443.66", "0.487505"], ["83443.65", "0"], ["83442.18", "0.42257"], ["83442.17", "0.478049"], ["83432.25", "0.135792"], ["83423.49", "0.000242"]], "a": [["83469.18", "0.337981"], ["83479.65", "0"], ["83479.66", "0.176126"], ["83479.97", "0"], ["83479.98", "0.168183"], ["83481.69", "0"], ["83481.75", "0.173497"], ["83487.69", "0"], ["83487.75", "0.286268"], ["83488.37", "0"], ["83488.38", "0.295172"], ["83488.65", "0"], ["83488.66", "0.30051"], ["83493.69", "0"], ["83493.75", "0.439644"], ["83494.65", "0"], ["83494.66", "0.460732"], ["83496.17", "0.466449"], ["83496.18", "0.478303"], ["83513.32", "0.003677"], ["83515.83", "0.04"], ["83516.04", "0.04"], ["83516.84", "0.063127"], ["83518.75", "0"], ["83518.84", "0"], ["83519.37", "0"]], "u": 973485, "seq": 67263908529}, "cts": 1742377433612, "record_time": 1742377434.499478}
{"topic": "orderbook.200.BTCUSDT", "ts": 1742377433814, "type": "delta", "data": {"s": "BTCUSDT", "b": [["83458.17", "0.34342"], ["83457.95", "0.239609"], ["83457.15", "0.176458"], ["83451.15", "0.285341"], ["83445.15", "0.477877"], ["83426.08", "0"]], "a": [["83479.19", "0.014915"], ["83481.75", "0.17699"], ["83487.75", "0.262502"], ["83493.75", "0.43623"], ["83513.32", "0"], ["83513.41", "0.003677"], ["83515.83", "0"], ["83515.93", "0.04"], ["83515.94", "0.04"], ["83516.04", "0"], ["83517.08", "0"]], "u": 973486, "seq": 67263908656}, "cts": 1742377433806, "record_time": 1742377434.700171}
{"topic": "orderbook.200.BTCUSDT", "ts": 1742377434014, "type": "delta", "data": {"s": "BTCUSDT", "b": [["83469.17", "1.432296"], ["83457.27", "0.171726"], ["83457.15", "0"], ["83451.27", "0.289246"], ["83451.15", "0"], ["83445.27", "0.452919"], ["83445.15", "0"]], "a": [["83469.18", "0.323066"], ["83481.75", "0"], ["83481.87", "0.166046"], ["83487.75", "0.000242"], ["83487.87", "0.269217"], ["83493.65", "0.119902"], ["83493.75", "0"], ["83493.87", "0.421089"], ["83510.9", "0"], ["83513.41", "0"], ["83513.51", "0.003677"], ["83515.93", "0"], ["83515.94", "0"], ["83516.02", "0.04"], ["83516.03", "0.04"], ["83518.25", "0"]], "u": 973487, "seq": 67263908762}, "cts": 1742377434008, "record_time": 1742377434.899448}
{"topic": "orderbook.200.BTCUSDT", "ts": 1742377434214, "type": "delta", "data": {"s": "BTCUSDT", "b": [["83469.17", "1.431296"], ["83457.27", "0"], ["83451.27", "0"], ["83449.99", "0.336591"], ["83449.61", "0"], ["83445.27", "0"], ["83439.34", "0.023961"], ["83424.82", "0"], ["83423.19", "0.01656"], ["83423.06", "0.195"], ["83422.96", "0.000242"]], "a": [["83469.18", "0.337981"], ["83479.19", "0"], ["83481.87", "0"], ["83487.87", "0"], ["83493.87", "0"], ["83494.04", "0.003877"], ["83518.25", "0.023959"], ["83518.75", "0.027431"], ["83518.84", "0.001333"], ["83519.37", "0.024199"]], "u": 973488, "seq": 67263908891}, "cts": 1742377434209, "record_time": 1742377435.099819}
{"topic": "orderbook.200.BTCUSDT", "ts": 1742377434415, "type": "delta", "data": {"s": "BTCUSDT", "b": [["83469.17", "1.428896"], ["83457.15", "0.163804"], ["83454.13", "0.1653"], ["83451.15", "0.282309"], ["83445.15", "0.478253"], ["83432.25", "0.135791"], ["83423.19", "0"], ["83423.06", "0"], ["83422.96", "0"]], "a": [["83481.75", "0.166028"], ["83487.75", "0.29994"], ["83493.75", "0.437489"], ["83494.04", "0.000277"], ["83518.84", "0"], ["83519.37", "0"]], "u": 973489, "seq": 67263909074}, "cts": 1742377434407, "record_time": 1742377435.301605}
{"topic": "orderbook.200.BTCUSDT", "ts": 1742377434614, "type": "delta", "data": {"s": "BTCUSDT", "b": [["83469.17", "1.435413"], ["83457.15", "0"], ["83457.13", "0.157591"], ["83454.13", "0.22933"], ["83451.15", "0"], ["83451.13", "0.291247"], ["83445.15", "0"], ["83445.13", "0.470146"]], "a": [["83474", "0.000013"], ["83474.61", "0.009021"], ["83481.73", "0.168162"], ["83481.75", "0"], ["83487.73", "0.275159"], ["83487.75", "0.000242"], ["83493.73", "0.470636"], ["83493.75", "0"], ["83510.26", "0.359416"], ["83517.91", "0"], ["83518.25", "0"], ["83518.75", "0"]], "u": 973490, "seq": 67263909235}, "cts": 1742377434609, "record_time": 1742377435.499217}
{"topic": "orderbook.200.BTCUSDT", "ts": 1742377434814, "type": "delta", "data": {"s": "BTCUSDT", "b": [["83457.2", "0.174351"], ["83457.13", "0"], ["83451.2", "0.297006"], ["83451.13", "0"], ["83445.2", "0.467799"], ["83445.13", "0"], ["83432.25", "0.135795"], ["83426.08", "0.11"], ["83423.49", "0"]], "a": [["83474.08", "0"], ["83476.32", "0"], ["83478.54", "0.01797"], ["83479.43", "0.111711"], ["83481.73", "0"], ["83481.8", "0.180527"], ["83483.72", "0"], ["83487.68", "0.0036"], ["83487.73", "0"], ["83487.8", "0.29865"], ["83493.73", "0"], ["83493.8", "0.432021"], ["83510.26", "0.359413"], ["83513.5", "0.003677"], ["83513.51", "0"], ["83514.4", "0.11"], ["83517.89", "0"]], "u": 973491, "seq": 67263909397}, "cts": 1742377434807, "record_time": 1742377435.69913}
{"topic": "orderbook.200.BTCUSDT", "ts": 1742377435014, "type": "delta", "data": {"s": "BTCUSDT", "b": [["83457.2", "0"], ["83451.2", "0"], ["83445.2", "0"], ["83423.49", "0.000242"], ["83423.19", "0.01656"], ["83423.06", "0.195"]], "a": [["83474.61", "0"], ["83481.8", "0"], ["83487.8", "0"], ["83493.8", "0"], ["83517.89", "0.00034"], ["83517.91", "0.000333"], ["83518.25", "0.023959"], ["83518.75", "0.027431"]], "u": 973492, "seq": 67263909513}, "cts": 1742377435012, "record_time": 1742377435.899507}
{"topic": "orderbook.200.BTCUSDT", "ts": 1742377435214, "type": "delta", "data": {"s": "BTCUSDT", "b": [["83469.17", "1.268913"], ["83459.23", "0.080581"], ["83458.66", "0.003"], ["83458.65", "0.181657"], ["83458.38", "0"], ["83458.37", "0.170044"], ["83458.17", "0.248573"], ["83457.95", "0"], ["83457.16", "0.176112"], ["83456.63", "0"], ["83454.13", "0.1653"], ["83453.78", "0"], ["83451.62", "0.239609"], ["83451.16", "0.292438"], ["83449.98", "0"], ["83449.97", "0.278783"], ["83449.66", "0"], ["83449.65", "0.274936"], ["83449.6", "0.239609"], ["83445.43", "0.239609"], ["83445.16", "0.478672"], ["83443.66", "0"], ["83443.65", "0.451865"], ["83442.18", "0"], ["83442.17", "0.901863"], ["83423.49", "0"], ["83423.19", "0"], ["83423.06", "0"]], "a": [["83469.18", "0.345169"], ["83479.65", "0.1792"], ["83479.66", "0.001968"], ["83479.97", "0.180954"], ["83479.98", "0"], ["83481.76", "0.17522"], ["83487.76", "0.268687"], ["83488.37", "0.287663"], ["83488.38", "0"], ["83488.65", "0.305311"], ["83488.66", "0"], ["83493.76", "0.44777"], ["83494.65", "0.468119"], ["83494.66", "0"], ["83496.17", "0.911141"], ["83496.18", "0"], ["83510.25", "0.359411"], ["83510.26", "0"], ["83517.91", "0"], ["83518.25", "0"], ["83518.75", "0"]], "u": 973493, "seq": 67263909653}, "cts": 1742377435210, "record_time": 1742377436.099087}
{"topic": "orderbook.200.BTCUSDT", "ts": 1742377435414, "type": "delta", "data": {"s": "BTCUSDT", "b": [["83469.17", "0.619913"], ["83468.89", "0.197549"], ["83468.88", "0.65"], ["83459.23", "0.0774"], ["83458.65", "0.171055"], ["83458.37", "0.166483"], ["83457.16", "0.175582"], ["83454.13", "0.232369"], ["83451.16", "0.285365"], ["83449.97", "0.300883"], ["83449.65", "0.28766"], ["83445.16", "0.449236"], ["83443.65", "0.471264"], ["83442.17", "0.9439"], ["83424.17", "0"], ["83423.55", "0"]], "a": [["83479.65", "0.172488"], ["83479.97", "0.166428"], ["83481.76", "0.161508"], ["83485.2", "0.064178"], ["83487.76", "0.279582"], ["83488.37", "0.294399"], ["83488.65", "0.305519"], ["83493.76", "0.447588"], ["83494.65", "0.433556"], ["83496.17", "0.890623"], ["83510.24", "0.359415"], ["83510.25", "0"]], "u": 973494, "seq": 67263909857}, "cts": 1742377435409, "record_time": 1742377436.298818}
{"topic": "orderbook.200.BTCUSDT", "ts": 1742377435614, "type": "delta", "data": {"s": "BTCUSDT", "b": [["83469.17", "0.482213"], ["83457.16", "0.169124"], ["83451.16", "0.28784"], ["83445.16", "0.436204"]], "a": [["83479.6", "0"], ["83481.27", "0"], ["83481.76", "0.162887"], ["83487.68", "0"], ["83487.76", "0.263591"], ["83493.76", "0.431033"], ["83510.23", "0.359416"], ["83510.24", "0"], ["83517.91", "0.000333"], ["83518.25", "0.023959"], ["83518.75", "0.027431"]], "u": 973495, "seq": 67263909940}, "cts": 1742377435607, "record_time": 1742377436.498751}
{"topic": "orderbook.200.BTCUSDT", "ts": 1742377435815, "type": "delta", "data": {"s": "BTCUSDT", "b": [["83466.06", "0"], ["83464.1", "0.071885"], ["83459.23", "0.12987"], ["83458.65", "0"], ["83458.37", "0"], ["83457.16", "0"], ["83451.16", "0"], ["83449.97", "0"], ["83449.65", "0"], ["83445.16", "0"], ["83443.65", "0"], ["83442.17", "0.478049"], ["83439.09", "0"], ["83432.25", "0.135788"], ["83424.17", "0.003663"], ["83423.55", "0.001"], ["83423.49", "0.000242"], ["83423.19", "0.01656"], ["83423.06", "0.195"], ["83422.96", "0.000242"], ["83422.84", "0.001333"], ["83422.58", "0.119902"], ["83422.56", "0.013851"]], "a": [["83470.15", "0.000153"], ["83473.34", "0.006459"], ["83473.38", "0.017971"], ["83475.85", "0.011979"], ["83476.36", "0"], ["83476.63", "0.239588"], ["83478.3", "0.239583"], ["83478.54", "0"], ["83479.65", "0"], ["83479.97", "0"], ["83481.76", "0"], ["83483.77", "0.089922"], ["83487.76", "0"], ["83488.37", "0"], ["83488.65", "0"], ["83490.02", "0.0036"], ["83493.76", "0"], ["83494.65", "0"], ["83496.17", "0.466449"], ["83507.34", "0.359421"], ["83510.23", "0"], ["83518.84", "0.001333"], ["83519.37", "0.024199"]], "u": 973496, "seq": 67263910083}, "cts": 1742377435807, "record_time": 1742377436.700519}
{"topic": "orderbook.200.BTCUSDT", "ts": 1742377436014, "type": "delta", "data": {"s": "BTCUSDT", "b": [["83459.23", "0.131252"], ["83458.66", "0.177102"], ["83458.38", "0.17646"], ["83458.17", "0.17669"], ["83457.16", "0.166094"], ["83454.13", "0.1653"], ["83451.16", "0.269507"], ["83449.99", "0"], ["83449.98", "0.270637"], ["83449.66", "0.297596"], ["83445.16", "0.442288"], ["83445.02", "0"], ["83443.66", "0.428158"], ["83442.18", "0.43058"], ["83438.95", "0.000276"], ["83423.19", "0"], ["83423.06", "0"], ["83422.96", "0"], ["83422.84", "0"], ["83422.58", "0"], ["83422.56", "0"]], "a": [["83469.18", "0.330254"], ["83475.02", "0.008908"], ["83479.19", "0.014915"], ["83479.66", "0.161697"], ["83479.98", "0.15846"], ["83481.76", "0.158577"], ["83483.45", "0"], ["83487.76", "0.276219"], ["83488.38", "0.292527"], ["83488.66", "0.287087"], ["83493.76", "0.460321"], ["83494.66", "0.485229"], ["83496.18", "0.450906"], ["83510.9", "0.47898"], ["83513.5", "0.003676"], ["83516.01", "0.04"], ["83516.03", "0"], ["83516.97", "0"], ["83517", "0"], ["83517.69", "0"], ["83517.71", "0"], ["83517.89", "0"], ["83517.91", "0"], ["83518.25", "0"], ["83518.75", "0"], ["83518.84", "0"], ["83519.37", "0"]], "u": 973497, "seq": 67263910182}, "cts": 1742377436008, "record_time": 1742377436.899435}
{"topic": "orderbook.200.BTCUSDT", "ts": 1742377436214, "type": "delta", "data": {"s": "BTCUSDT", "b": [["83469.17", "0.483136"], ["83459.23", "0.080564"], ["83458.66", "0.003"], ["83458.65", "0.181601"], ["83458.38", "0"], ["83458.37", "0.17838"], ["83457.16", "0"], ["83456.86", "0.180353"], ["83451.16", "0"], ["83450.86", "0.284073"], ["83449.98", "0"], ["83449.97", "0.283291"], ["83449.66", "0"], ["83449.65", "0.280551"], ["83446.57", "0"], ["83445.17", "0.671511"], ["83445.16", "0"], ["83444.86", "0.446823"], ["83443.66", "0"], ["83443.65", "0.453181"], ["83442.18", "0"], ["83442.17", "0.914217"], ["83439.19", "0.071907"], ["83438.66", "1.334101"], ["83423.55", "0"], ["83423.49", "0"]], "a": [["83469.18", "0.530333"], ["83475.27", "0.089922"], ["83477.76", "0"], ["83479.19", "0"], ["83479.65", "0.167314"], ["83479.66", "0.001968"], ["83479.97", "0.175554"], ["83479.98", "0"], ["83480.49", "1.350912"], ["83481.46", "0.173121"], ["83481.76", "0"], ["83487.46", "0.299904"], ["83487.76", "0"], ["83488.37", "0.274251"], ["83488.38", "0"], ["83488.65", "0.270864"], ["83488.66", "0"], ["83493.46", "0.478688"], ["83493.76", "0"], ["83494.65", "0.469586"], ["83494.66", "0"], ["83496.17", "0.890687"], ["83496.18", "0"], ["83507.33", "0.359428"], ["83507.34", "0"], ["83514.4", "0"], ["83516.97", "0.003663"]], "u": 973498, "seq": 67263910279}, "cts": 1742377436208, "record_time": 1742377437.09903}
{"topic": "orderbook.200.BTCUSDT", "ts": 1742377436414, "type": "delta", "data": {"s": "BTCUSDT", "b": [["83456.81", "0.003"], ["83456.73", "0"], ["83456.61", "0.003"], ["83456.53", "0"], ["83454.13", "0.229859"], ["83432.25", "0.135796"]], "a": [["83469.18", "0.527022"], ["83507.32", "0.359426"], ["83507.33", "0"]], "u": 973499, "seq": 67263910321}, "cts": 1742377436410, "record_time": 1742377437.299061}
{"topic": "orderbook.200.BTCUSDT", "ts": 1742377436614, "type": "delta", "data": {"s": "BTCUSDT", "b": [["83469.17", "0.482387"]], "a": [["83469.18", "0.520211"], ["83484.85", "0.221519"], ["83507.31", "0.359426"], ["83507.32", "0"]], "u": 973500, "seq": 67263910342}, "cts": 1742377436612, "record_time": 1742377437.499032}
{"topic": "orderbook.200.BTCUSDT", "ts": 1742377436815, "type": "delta", "data": {"s": "BTCUSDT", "b": [["83469.17", "0.454673"], ["83468.89", "0"], ["83465.19", "0"], ["83460.52", "0.011981"], ["83457.68", "0"], ["83453.01", "0.017971"], ["83423.55", "0.001"]], "a": [["83469.18", "0.65466"], ["83504.82", "0.359433"], ["83507.31", "0"], ["83513.49", "0.003676"], ["83513.5", "0"]], "u": 973501, "seq": 67263910385}, "cts": 1742377436812, "record_time": 1742377437.699697}
{"topic": "orderbook.200.BTCUSDT", "ts": 1742377437014, "type": "delta", "data": {"s": "BTCUSDT", "b": [["83466.72", "0"], ["83464.11", "0.03016"], ["83451.62", "0"], ["83449.98", "0.393999"], ["83449.6", "0"], ["83445.43", "0"], ["83437.42", "0"], ["83437.08", "0.239609"], ["83432.9", "0.239609"], ["83426.08", "0"], ["83423.49", "0.000242"], ["83423.19", "0.01656"], ["83423.06", "0.195"]], "a": [["83469.18", "0.810485"], ["83470", "0.002543"], ["83470.15", "0"], ["83473.34", "0.011979"], ["83473.38", "0"], ["83479.19", "0.011604"], ["83479.6", "0.239579"], ["83482.94", "0"], ["83485.54", "0.003"], ["83486.92", "0.071866"], ["83493.66", "0"], ["83494.2", "0"], ["83503.98", "0.359436"], ["83504.82", "0"]], "u": 973502, "seq": 67263910468}, "cts": 1742377437006, "record_time": 1742377437.899248}
{"topic": "orderbook.200.BTCUSDT", "ts": 1742377437215, "type": "delta", "data": {"s": "BTCUSDT", "b": [["83469.17", "0.216636"], ["83459.23", "0.02981"], ["83458.65", "0"], ["83458.37", "0"], ["83457.47", "0"], ["83456.86", "0"], ["83456.79", "0.178344"], ["83450.86", "0"], ["83450.79", "0.286321"], ["83449.97", "0"], ["83449.65", "0"], ["83448.17", "0"], ["83444.86", "0"], ["83444.79", "0.428913"], ["83443.65", "0"], ["83442.17", "0"], ["83442.11", "0.481339"], ["83437.08", "0"], ["83432.9", "0"], ["83422.96", "0.000242"], ["83422.84", "0.001333"], ["83422.58", "0.119902"], ["83422.56", "0.013851"], ["83421.93", "0.060553"], ["83421.92", "0.000333"], ["83421.7", "0.001123"], ["83421.31", "0.001466"], ["83421.1", "0.044"], ["83420.59", "0.000276"]], "a": [["83470", "0.003526"], ["83477.69", "0.003"], ["83479.19", "0"], ["83479.65", "0"], ["83479.97", "0"], ["83480.48", "0.275535"], ["83480.87", "0"], ["83481.39", "0.159461"], ["83481.46", "0"], ["83487.39", "0.267353"], ["83487.46", "0"], ["83488.37", "0"], ["83488.65", "0"], ["83490.02", "0"], ["83490.17", "0"], ["83492.74", "0.029602"], ["83493.39", "0.481976"], ["83493.46", "0"], ["83494.65", "0"], ["83496.17", "0"], ["83499.67", "0.027431"], ["83511.89", "0"], ["83513.29", "0.003676"], ["83513.49", "0"], ["83514.88", "0.11"], ["83514.98", "0"], ["83515.8", "0.04"], ["83515.81", "0.04"], ["83516.01", "0"], ["83516.02", "0"], ["83517", "0.000277"], ["83517.69", "0.001114"], ["83517.71", "0.001466"], ["83517.89", "0.00034"], ["83517.91", "0.000333"], ["83518.25", "0.023959"], ["83518.84", "0.001333"]], "u": 973503, "seq": 67263910683}, "cts": 1742377437207, "record_time": 1742377438.100138}
{"topic": "orderbook.200.BTCUSDT", "ts": 1742377437415, "type": "delta", "data": {"s": "BTCUSDT", "b": [["83467.2", "0.001466"], ["83464.11", "0"], ["83464.1", "0"], ["83462.26", "0.071887"], ["83462.25", "0"], ["83460.52", "0"], ["83459.23", "0.078665"], ["83458.6", "0.217137"], ["83457.45", "0.16364"], ["83455.56", "0.011981"], ["83453.67", "0.004012"], ["83453.01", "0"], ["83449.98", "0.066999"], ["83449.6", "0.290433"], ["83448.15", "0.293838"], ["83448.05", "0.017972"], ["83445.17", "0"], ["83443.6", "0.454666"], ["83442.76", "0.001179"], ["83442.65", "0.001195"], ["83442.21", "0.001262"], ["83442.15", "0.463254"], ["83442.11", "0"], ["83438.59", "0.001179"], ["83438.03", "0.037213"], ["83432.25", "0"], ["83429.52", "0.135796"], ["83421.93", "0"], ["83421.92", "0"], ["83421.7", "0"], ["83421.31", "0"], ["83421.1", "0"], ["83420.59", "0"]], "a": [["83469.18", "0.965381"], ["83469.19", "0.0036"], ["83470", "0.009468"], ["83475.02", "0"], ["83479.19", "0.011604"], ["83479.6", "0.408795"], ["83479.79", "0.003"], ["83480.85", "0.174843"], ["83488.6", "0.288489"], ["83490.15", "0.288058"], ["83491.7", "0"], ["83494.6", "0.476707"], ["83495.04", "0.001074"], ["83496.15", "0.467292"], ["83499.21", "0.001074"], ["83500.04", "0.359448"], ["83503.98", "0"], ["83509.77", "0.003"], ["83514.11", "0.063127"], ["83516.83", "0"], ["83516.84", "0"], ["83517", "0"], ["83517.69", "0"], ["83517.71", "0"], ["83517.89", "0"], ["83517.91", "0"], ["83518.25", "0"], ["83518.84", "0"]], "u": 973504, "seq": 67263910811}, "cts": 1742377437409, "record_time": 1742377438.300493}
{"topic": "orderbook.200.BTCUSDT", "ts": 1742377437614, "type": "delta", "data": {"s": "BTCUSDT", "b": [["83469.17", "0.212519"], ["83458.31", "0.157881"], ["83449.98", "0.239297"], ["83449.91", "0.272882"], ["83449.11", "0.239609"], ["83445.43", "0.239609"], ["83442.87", "0.001164"], ["83442.76", "0"], ["83442.65", "0"], ["83442.21", "0"], ["83442.11", "0.42669"], ["83441.88", "0.001318"], ["83441.25", "0.239609"], ["83438.85", "0.001145"], ["83438.59", "0"], ["83438.03", "0"], ["83438.02", "0.035952"], ["83437.42", "0.167727"], ["83429.52", "0.135792"], ["83423.19", "0"], ["83423.06", "0"], ["83422.96", "0"], ["83422.84", "0"], ["83422.58", "0"], ["83422.56", "0"]], "a": [["83479.19", "0"], ["83479.3", "0.04"], ["83479.91", "0.168729"], ["83480.9", "0.04"], ["83481", "0.04"], ["83482.6", "0.04"], ["83483.5", "0"], ["83484.3", "0.04"], ["83486", "0.08"], ["83488.31", "0.283319"], ["83488.5", "0"], ["83489.19", "0.239609"], ["83490.2", "0"], ["83496.11", "0.42648"], ["83500.04", "0"], ["83502.73", "0.003"], ["83503.98", "0.359446"], ["83509.77", "0"], ["83514.5", "0.04"], ["83514.51", "0.04"], ["83515.8", "0"], ["83515.81", "0"], ["83516", "0"], ["83516.54", "0"], ["83516.76", "0"], ["83516.8", "0"], ["83516.97", "0"]], "u": 973505, "seq": 67263910910}, "cts": 1742377437607, "record_time": 1742377438.499066}
{"topic": "orderbook.200.BTCUSDT", "ts": 1742377437814, "type": "delta", "data": {"s": "BTCUSDT", "b": [["83449.98", "0.371507"], ["83442.87", "0"], ["83442.61", "0.0012"], ["83441.88", "0"], ["83439.06", "0"], ["83438.85", "0"], ["83438.44", "0.0012"], ["83423.19", "0.01656"], ["83423.06", "0.195"]], "a": [["83469.18", "0.68764"], ["83485", "0"], ["83485.2", "0.024178"], ["83486.9", "0"], ["83491.7", "0.239609"], ["83511.99", "0.003676"], ["83513.29", "0"], ["83516", "0.000119"]], "u": 973506, "seq": 67263910985}, "cts": 1742377437810, "record_time": 1742377439.776018}
{"topic": "orderbook.200.BTCUSDT", "ts": 1742377438014, "type": "delta", "data": {"s": "BTCUSDT", "b": [["83469.17", "0.21555"], ["83468.88", "0.291008"], ["83458.32", "0.172691"], ["83458.31", "0"], ["83449.92", "0.297681"], ["83449.91", "0"], ["83445.02", "0.66934"], ["83443.28", "0.001113"], ["83442.61", "0"], ["83442.12", "0.459221"], ["83442.11", "0"], ["83441.9", "0.001315"], ["83438.44", "0"], ["83424.08", "0.11"], ["83423.19", "0"], ["83423.06", "0"]], "a": [["83479.19", "0.011604"], ["83479.91", "0"], ["83479.92", "0.165899"], ["83488.31", "0"], ["83488.32", "0.276422"], ["83496.11", "0"], ["83496.12", "0.464366"], ["83516", "0"]], "u": 973507, "seq": 67263911050}, "cts": 1742377438004, "record_time": 1742377439.778616}
{"topic": "orderbook.200.BTCUSDT", "ts": 1742377438215, "type": "delta", "data": {"s": "BTCUSDT", "b": [["83469.17", "0.48205"], ["83468.88", "0.52"], ["83462.27", "0.102918"], ["83459.23", "0"], ["83458.65", "0.17659"], ["83458.6", "0.041867"], ["83458.37", "0.168296"], ["83458.32", "0"], ["83458.31", "0.244484"], ["83458.17", "0"], ["83457.47", "0.169884"], ["83457.45", "0"], ["83456.86", "0.170963"], ["83456.79", "0"], ["83450.86", "0.297031"], ["83450.79", "0"], ["83449.97", "0.292707"], ["83449.92", "0"], ["83449.65", "0.289205"], ["83449.6", "0"], ["83448.17", "0.266976"], ["83448.15", "0"], ["83444.86", "0.443415"], ["83444.79", "0.002883"], ["83443.65", "0.464854"], ["83443.6", "0"], ["83443.28", "0"], ["83442.17", "0.937983"], ["83442.15", "0"], ["83442.12", "0"], ["83441.9", "0"], ["83441.72", "0.001349"], ["83441.47", "0.001405"], ["83437.54", "0.001349"], ["83437.04", "0"], ["83423.49", "0"]], "a": [["83469.18", "0.686442"], ["83470", "0"], ["83475.27", "0"], ["83479.19", "0"], ["83479.6", "0.239579"], ["83479.65", "0.173958"], ["83479.92", "0"], ["83479.97", "0.158679"], ["83480.85", "0"], ["83480.87", "0.182272"], ["83481.39", "0"], ["83481.46", "0.175858"], ["83487.39", "0"], ["83487.46", "0.279969"], ["83488.32", "0"], ["83488.37", "0.286536"], ["83488.6", "0"], ["83488.65", "0.304939"], ["83490.15", "0"], ["83490.17", "0.273472"], ["83493.39", "0"], ["83493.46", "0.440229"], ["83494.6", "0.00009"], ["83494.65", "0.473292"], ["83496.12", "0"], ["83496.15", "0"], ["83496.17", "0.910841"], ["83516", "0.000119"], ["83516.76", "0.037732"]], "u": 973508, "seq": 67263911199}, "cts": 1742377438211, "record_time": 1742377439.780309}
{"topic": "orderbook.200.BTCUSDT", "ts": 1742377438414, "type": "delta", "data": {"s": "BTCUSDT", "b": [["83456.91", "0.003"], ["83456.81", "0"], ["83456.71", "0.003"], ["83456.61", "0"], ["83449.6", "0.239609"], ["83442.55", "0.016213"], ["83441.72", "0"], ["83441.47", "0"], ["83441.39", "0.001421"], ["83441.25", "0"], ["83437.54", "0"], ["83437.19", "0.111711"], ["83429.52", "0.135793"], ["83423.49", "0.000242"]], "a": [["83469.18", "0.686289"], ["83470", "0.002092"], ["83470.11", "0.000153"], ["83516", "0"], ["83516.76", "0"]], "u": 973509, "seq": 67263911291}, "cts": 1742377438411, "record_time": 1742377439.781825}
{"topic": "orderbook.200.BTCUSDT", "ts": 1742377438614, "type": "delta", "data": {"s": "BTCUSDT", "b": [["83442.55", "0.015"], ["83442.07", "0.00129"], ["83441.39", "0"], ["83437.9", "0.00129"], ["83423.49", "0"]], "a": [["83469.18", "0.565679"], ["83475.73", "0.009085"], ["83515.72", "0"]], "u": 973510, "seq": 67263911353}, "cts": 1742377438609, "record_time": 1742377439.783375}
{"topic": "orderbook.200.BTCUSDT", "ts": 1742377438814, "type": "delta", "data": {"s": "BTCUSDT", "b": [["83442.2", "0.001267"], ["83442.07", "0"], ["83441.77", "0.001345"], ["83438.03", "0.001267"], ["83437.9", "0"], ["83429.52", "0.13579"], ["83423.55", "0"]], "a": [["83469.18", "0.554075"], ["83479.19", "0.011604"], ["83511.98", "0.003676"], ["83511.99", "0"], ["83515.61", "0"]], "u": 973511, "seq": 67263911393}, "cts": 1742377438811, "record_time": 1742377439.784807}
