{"topic": "orderbook.200.BTCUSDT", "ts": 1742577163320, "type": "delta", "data": {"s": "BTCUSDT", "b": [["83930.2", "0.003"], ["83917.8", "0.000825"], ["83876", "0"], ["83875.9", "0"]], "a": [["83952.7", "0"], ["84019.1", "0.011993"]], "u": 129320, "seq": 67571364784}, "cts": 1742577163317, "record_time": 1742577163.50824, "EXCHANGE": "BYBIT"}
{"topic": "orderbook.200.BTCUSDT", "ts": 1742577163520, "type": "delta", "data": {"s": "BTCUSDT", "b": [["83940.7", "0.000145"], ["83926.6", "0.147507"], ["83926.5", "0"], ["83924.9", "0"], ["83912.2", "0.049965"], ["83912", "0.039634"], ["83909.7", "0"], ["83909.5", "0.012882"], ["83906.5", "0.001333"], ["83906.3", "0.04955"], ["83897.7", "0.000522"], ["83894.3", "0.357562"], ["83893.8", "0"], ["83892.1", "5.777189"], ["83885.3", "0"]], "a": [["83949.1", "0.59384"], ["83960.4", "0.0003"], ["83960.5", "0"], ["83966.7", "0"], ["83968.4", "0"], ["83987.2", "0"], ["83987.4", "0.04"], ["84004.7", "0.001466"], ["84019.8", "0.004483"], ["84020.5", "0.000333"]], "u": 129321, "seq": 67571364868}, "cts": 1742577163514, "record_time": 1742577163.707746, "EXCHANGE": "BYBIT"}
{"topic": "orderbook.200.BTCUSDT", "ts": 1742577163719, "type": "delta", "data": {"s": "BTCUSDT", "b": [["83948.9", "0.071506"], ["83947.1", "0"], ["83944.2", "0.07151"], ["83942.6", "0.000298"], ["83942.3", "0.044926"], ["83940.7", "0.108543"], ["83938.6", "0.001"], ["83912.1", "0"], ["83912", "0"], ["83911.9", "0.039635"], ["83911.8", "0.123687"], ["83909.6", "0.005977"], ["83909.5", "0"], ["83909.4", "0.012882"], ["83909.3", "0.033122"], ["83906.4", "0.019965"], ["83906.3", "0"], ["83906.2", "0.061469"], ["83906.1", "0.04955"], ["83901.6", "0.357546"], ["83894.9", "5.857585"], ["83894.3", "0"], ["83892.1", "0"], ["83876.3", "0"]], "a": [["83951.3", "0.000153"], ["83964.5", "0.001611"], ["83966.9", "0.236483"], ["83987.3", "0"], ["83987.4", "0"], ["83987.7", "0.165076"], ["83987.8", "0.0401"], ["83995.8", "0"], ["84002.9", "0.357546"], ["84019.8", "0.175483"]], "u": 129322, "seq": 67571364953}, "cts": 1742577163708, "record_time": 1742577163.916487, "EXCHANGE": "BYBIT"}
{"topic": "orderbook.200.BTCUSDT", "ts": 1742577163920, "type": "delta", "data": {"s": "BTCUSDT", "b": [["83949", "0.023235"], ["83901.7", "0.203558"], ["83901.6", "0"], ["83901.5", "0"], ["83899.1", "0.357549"], ["83897.7", "5.777711"], ["83894.9", "0.080396"]], "a": [["83949.1", "0.600021"], ["83958.3", "0.005335"], ["83964.5", "0"], ["83985.1", "0.055673"], ["83988", "0"], ["84020.7", "0.011865"]], "u": 129323, "seq": 67571364993}, "cts": 1742577163896, "record_time": 1742577164.107974, "EXCHANGE": "BYBIT"}
{"topic": "orderbook.200.BTCUSDT", "ts": 1742577164119, "type": "delta", "data": {"s": "BTCUSDT", "b": [["83948.9", "0"], ["83946.7", "0.071508"], ["83944.2", "0"], ["83942.6", "0"], ["83942.3", "0"], ["83942.2", "0"], ["83941.9", "0.071512"], ["83940.1", "0.072846"], ["83901.7", "0"], ["83897.7", "0.000522"], ["83892.1", "5.641387"], ["83876", "0.004263"], ["83875.9", "0.08934"], ["83875.4", "0.001466"]], "a": [["83952", "0.001642"], ["83960.9", "0.024998"], ["83999", "0.357554"], ["84002.9", "0"], ["84007.1", "0.178556"], ["84020.5", "0"], ["84020.7", "0"]], "u": 129324, "seq": 67571365068}, "cts": 1742577164114, "record_time": 1742577164.307711, "EXCHANGE": "BYBIT"}
{"topic": "orderbook.200.BTCUSDT", "ts": 1742577164319, "type": "delta", "data": {"s": "BTCUSDT", "b": [["83946.7", "0"], ["83942.6", "0.000298"], ["83940.7", "0.000145"], ["83912", "0.039634"], ["83911.8", "0.084052"], ["83906.3", "0.04955"], ["83906.1", "0"], ["83899.1", "0"], ["83895", "0.357566"], ["83894.9", "5.721783"], ["83892.1", "0"], ["83876.3", "0.171"], ["83875.4", "0"]], "a": [["83950.8", "0.001642"], ["83951.3", "0"], ["83960.9", "0.023503"], ["83987.4", "0.04"], ["83987.5", "0.04"], ["83987.7", "0.125076"], ["83987.8", "0.0001"], ["83994.5", "0.357565"], ["83999", "0"], ["84019.1", "0"], ["84019.8", "0"]], "u": 129325, "seq": 67571365151}, "cts": 1742577164311, "record_time": 1742577164.507538, "EXCHANGE": "BYBIT"}
{"topic": "orderbook.200.BTCUSDT", "ts": 1742577164519, "type": "delta", "data": {"s": "BTCUSDT", "b": [["83949", "0.043779"], ["83946.2", "0.071508"], ["83942.6", "0"], ["83941.9", "0"], ["83941.6", "0.113752"], ["83940.1", "0.001333"], ["83937.6", "0.071515"], ["83897", "0.357899"], ["83895", "0"], ["83875.4", "0.001466"]], "a": [["83950.9", "0.001642"], ["83951.5", "0.004556"], ["83987.4", "0"], ["83987.5", "0"], ["83987.6", "0.6843"], ["83987.7", "0.165076"], ["83991.8", "0.198057"], ["83993.7", "0"], ["83994.2", "2.611884"], ["83994.5", "0"], ["83995.8", "0.357565"], ["83997", "0"], ["84012.8", "0.353911"], ["84017.9", "0"], ["84019.1", "0.011993"], ["84019.8", "0.004483"]], "u": 129326, "seq": 67571365228}, "cts": 1742577164514, "record_time": 1742577164.707818, "EXCHANGE": "BYBIT"}
{"topic": "orderbook.200.BTCUSDT", "ts": 1742577164720, "type": "delta", "data": {"s": "BTCUSDT", "b": [["83949", "0.03942"], ["83946.2", "0"], ["83912.2", "0.089965"], ["83912.1", "0.039634"], ["83912", "0"], ["83911.9", "0"], ["83906.5", "0.051333"], ["83906.4", "0.069515"], ["83906.3", "0"], ["83906.2", "0.011919"], ["83897", "0.357895"], ["83875.3", "0.059594"], ["83874.7", "0.011995"], ["83874.6", "0.00302"]], "a": [["83949.1", "0.600334"], ["83951", "0.001642"], ["83959.9", "0.005717"], ["83960.4", "0"], ["83961.2", "0.0153"], ["83963", "0.001457"], ["83963.9", "0.001544"], ["83986.8", "0.04"], ["83986.9", "0.099732"], ["83987.6", "0.6443"], ["83987.7", "0.125076"], ["83995.8", "0"], ["83997.2", "0.381478"], ["84019.1", "0"], ["84019.8", "0"]], "u": 129327, "seq": 67571365319}, "cts": 1742577164713, "record_time": 1742577164.927363, "EXCHANGE": "BYBIT"}
{"topic": "orderbook.200.BTCUSDT", "ts": 1742577164920, "type": "delta", "data": {"s": "BTCUSDT", "b": [["83941.7", "0.000298"], ["83935.9", "0.050372"], ["83933", "0.122761"], ["83923.2", "0.171474"], ["83914.1", "0.274521"], ["83912.2", "0.049965"], ["83912", "0.039634"], ["83909.6", "0.018977"], ["83909.5", "0.012882"], ["83909.4", "0"], ["83909.3", "0.02024"], ["83908.1", "0.096535"], ["83906.5", "0.001333"], ["83906.3", "0.04955"], ["83903.9", "0"], ["83894.9", "0.080396"], ["83892.1", "5.49478"], ["83876.3", "0"], ["83876", "0"], ["83875.9", "0"], ["83875.4", "0"], ["83875.3", "0"], ["83874.7", "0"], ["83874.6", "0"]], "a": [["83949.1", "0.60391"], ["83951.3", "0.000153"], ["83951.5", "0.004403"], ["83958.2", "0.112771"], ["83960.4", "0.0003"], ["83961.2", "0.015"], ["83968", "0.170521"], ["83973.6", "0.001333"], ["83977.1", "0.309391"], ["83986.8", "0"], ["83986.9", "0.059732"], ["83987.1", "0.04"], ["83987.2", "0.04"], ["84017", "0"], ["84017.7", "0"], ["84018.4", "0"], ["84018.5", "0"], ["84018.7", "0"], ["84018.8", "0"]], "u": 129328, "seq": 67571365379}, "cts": 1742577164909, "record_time": 1742577165.108414, "EXCHANGE": "BYBIT"}
{"topic": "orderbook.200.BTCUSDT", "ts": 1742577165119, "type": "delta", "data": {"s": "BTCUSDT", "b": [["83941.7", "0"], ["83941.6", "0.04224"], ["83940.6", "0.02"], ["83939.3", "0.071514"], ["83937.6", "0"], ["83935.9", "0.014946"], ["83933", "0"], ["83932.1", "0"], ["83924.8", "0"], ["83924.3", "0.149614"], ["83923.2", "0"], ["83922.3", "0.17868"], ["83922.2", "0.004387"], ["83920.1", "0.113971"], ["83919.4", "0"], ["83917.9", "0"], ["83915.2", "0"], ["83914.1", "0"], ["83897", "0.357894"], ["83876", "0.004263"], ["83875.9", "0.08934"], ["83875.4", "0.001466"], ["83875.3", "0.059594"], ["83874.7", "0.011995"], ["83874.6", "0.00302"], ["83874", "0.011968"]], "a": [["83951.3", "0"], ["83958.2", "0"], ["83959.9", "0.004309"], ["83963", "0"], ["83963.9", "0"], ["83968", "0"], ["83977.1", "0"], ["83984.9", "0.024992"], ["83987.1", "0"], ["83987.2", "0"], ["83987.3", "0.04"], ["83987.4", "0.04"], ["83991.8", "0.194978"], ["83994.2", "0"], ["83997", "2.611884"], ["83997.2", "0.381477"], ["84017", "0.000145"], ["84017.7", "0.001124"], ["84018.4", "0.011865"], ["84018.5", "0.001466"], ["84018.7", "0.004334"]], "u": 129329, "seq": 67571365501}, "cts": 1742577165116, "record_time": 1742577165.307685, "EXCHANGE": "BYBIT"}
{"topic": "orderbook.200.BTCUSDT", "ts": 1742577165319, "type": "delta", "data": {"s": "BTCUSDT", "b": [["83945.6", "0.071509"], ["83941.3", "0"], ["83940.6", "0.091513"], ["83939.3", "0"], ["83937", "0.068696"], ["83936.9", "0.071516"], ["83935.9", "0.001333"], ["83930.2", "0"], ["83926.6", "0.076069"], ["83919.5", "0"], ["83913.7", "0"], ["83912.3", "0.608984"], ["83912.2", "0.089599"], ["83912.1", "0"], ["83912", "0"], ["83906.6", "0.05"], ["83906.5", "0.050883"], ["83906.4", "0.019965"], ["83906.3", "0"], ["83897", "0.000332"], ["83896.9", "0"], ["83895", "0.357575"], ["83876.3", "0.171"], ["83873.6", "0.012327"], ["83872.9", "0.001333"], ["83871.8", "0.004263"]], "a": [["83972.4", "0"], ["83986.4", "0.04"], ["83986.5", "0.04"], ["83987.3", "0"], ["83987.4", "0"], ["83991.8", "0.125502"], ["83994.2", "2.611884"], ["83994.5", "0.357575"], ["83997", "0"], ["83997.2", "0.023915"]], "u": 129330, "seq": 67571365623}, "cts": 1742577165316, "record_time": 1742577165.507657, "EXCHANGE": "BYBIT"}
{"topic": "orderbook.200.BTCUSDT", "ts": 1742577165520, "type": "delta", "data": {"s": "BTCUSDT", "b": [["83949", "0.019476"], ["83945.6", "0"], ["83941.7", "0.000298"], ["83940.6", "0.262513"], ["83937", "0.035867"], ["83919.4", "0.17868"], ["83917.9", "0.17868"], ["83915.2", "0.125076"], ["83913.7", "0.17868"], ["83910.1", "0.013"], ["83910", "0.012881"], ["83909.6", "0.005977"], ["83909.5", "0"], ["83906.9", "0.226292"], ["83906.8", "0.220549"], ["83906.6", "0"], ["83906.5", "0.001333"], ["83895", "0"], ["83894.3", "0.35758"], ["83874", "0"], ["83873.6", "0"], ["83872.9", "0"], ["83871.8", "0"]], "a": [["83949.1", "0.604063"], ["83949.7", "0.049114"], ["83972.1", "0"], ["83990.9", "0.357581"], ["83994.5", "0"], ["83998.4", "0.022831"]], "u": 129331, "seq": 67571365742}, "cts": 1742577165512, "record_time": 1742577165.707483, "EXCHANGE": "BYBIT"}
{"topic": "orderbook.200.BTCUSDT", "ts": 1742577165720, "type": "delta", "data": {"s": "BTCUSDT", "b": [["83949", "0.018676"], ["83946.7", "0.071508"], ["83942", "0.071512"], ["83941.7", "0"], ["83940.6", "0.091513"], ["83937", "0.014413"], ["83936.9", "0"], ["83919.5", "0.185977"], ["83912.4", "0.15863"], ["83912.2", "0.049965"], ["83910.1", "0"], ["83910", "0"], ["83909.9", "0.012882"], ["83909.8", "0.012882"], ["83906.9", "0.176292"], ["83906.8", "0.171"], ["83906.7", "0.049549"], ["83906.6", "0.04955"], ["83896.9", "0.08934"], ["83894.3", "0"], ["83893.8", "0.357579"], ["83875.4", "0"], ["83875.3", "0"], ["83874.7", "0"], ["83874.6", "0"]], "a": [["83949.1", "0.605663"], ["83949.2", "0.342322"], ["83972.4", "0.17868"], ["83985.7", "0.04"], ["83985.8", "0.158996"], ["83986.4", "0"], ["83986.5", "0"], ["83990.9", "0.357579"], ["84007.1", "0"], ["84018.8", "0.118996"]], "u": 129332, "seq": 67571365860}, "cts": 1742577165713, "record_time": 1742577165.907958, "EXCHANGE": "BYBIT"}
{"topic": "orderbook.200.BTCUSDT", "ts": 1742577165920, "type": "delta", "data": {"s": "BTCUSDT", "b": [["83949", "0.033034"], ["83946.7", "0"], ["83943.7", "0.07151"], ["83942", "0"], ["83940.6", "0.02"], ["83939.5", "0.071514"], ["83938.3", "0.034596"], ["83937", "0"], ["83919.4", "0"], ["83917.9", "0"], ["83915.2", "0"], ["83913.7", "0"], ["83912.4", "0.039634"], ["83906.1", "0.132884"], ["83906", "0"], ["83901.5", "0.096294"], ["83896.9", "0"], ["83893.8", "0"], ["83892.7", "0.17868"], ["83892.1", "5.364114"], ["83888.7", "0.357583"], ["83888.5", "0.1792"], ["83875.4", "0.001466"], ["83875.3", "0.059594"], ["83874.7", "0.011995"], ["83874.6", "0.00302"]], "a": [["83949.1", "0.60551"], ["83960.6", "0.118996"], ["83962.7", "0.11912"], ["83972.4", "0"], ["83985.4", "0.054484"], ["83985.5", "0.04"], ["83985.7", "0"], ["83985.8", "0.118996"], ["83988.9", "0.372703"], ["83990.9", "0"], ["83994.2", "0"], ["84008.1", "2.611884"]], "u": 129333, "seq": 67571365962}, "cts": 1742577165917, "record_time": 1742577166.108975, "EXCHANGE": "BYBIT"}
{"topic": "orderbook.200.BTCUSDT", "ts": 1742577166119, "type": "delta", "data": {"s": "BTCUSDT", "b": [["83949", "0.036011"], ["83943.7", "0"], ["83942.8", "0.071511"], ["83939.5", "0"], ["83937.9", "0.071515"], ["83935.9", "0.07285"], ["83932.9", "0.11293"], ["83930.3", "0"], ["83927.8", "0.009216"], ["83924.4", "0.04409"], ["83923.1", "0.172478"], ["83921.6", "0.001466"], ["83920.8", "0.034156"], ["83919.5", "0.078769"], ["83914", "0.30953"], ["83912.4", "0"], ["83912.2", "0.089599"], ["83909.9", "0"], ["83909.7", "0.012882"], ["83906.7", "0"], ["83906.5", "0.050883"], ["83906.1", "0"], ["83903.2", "0.132894"], ["83894.2", "0.303756"], ["83892.8", "0.361848"], ["83888.7", "0"], ["83874", "0.011968"]], "a": [["83949.1", "0.624861"], ["83958.1", "0.123615"], ["83960.2", "0.038758"], ["83962.2", "0.17868"], ["83964.7", "0"], ["83967.9", "0.183979"], ["83972.1", "0.054379"], ["83977", "0.301635"], ["83985.3", "0.04"], ["83985.5", "0"], ["83988.9", "0.372708"], ["84018.5", "0"], ["84018.7", "0"], ["84018.8", "0"]], "u": 129334, "seq": 67571366161}, "cts": 1742577166109, "record_time": 1742577166.307632, "EXCHANGE": "BYBIT"}
{"topic": "orderbook.200.BTCUSDT", "ts": 1742577166319, "type": "delta", "data": {"s": "BTCUSDT", "b": [["83949", "0"], ["83945.5", "0"], ["83944.3", "0"], ["83943.8", "0"], ["83943.1", "0"], ["83942.8", "0"], ["83942.5", "0"], ["83941.6", "0"], ["83940.9", "0"], ["83940.8", "0"], ["83940.7", "0"], ["83940.6", "0"], ["83940.1", "0"], ["83940", "0"], ["83939.9", "0"], ["83939.2", "0"], ["83938.9", "0"], ["83938.6", "0"], ["83938.3", "0"], ["83937.9", "0"], ["83937.1", "0.021"], ["83935.9", "0.001333"], ["83934.1", "0.009641"], ["83933.7", "0"], ["83932.9", "0"], ["83932.8", "0"], ["83932.6", "0.07152"], ["83930.9", "0"], ["83930.8", "0.001466"], ["83930.1", "0.071522"], ["83929.5", "0"], ["83929.2", "0"], ["83928.7", "0.032874"], ["83927.8", "0"], ["83927.6", "0"], ["83926.6", "0.056099"], ["83925.9", "0"], ["83925.4", "0.040522"], ["83924.3", "0"], ["83924.2", "0"], ["83924.1", "0.05"], ["83924", "0.021485"], ["83923.1", "0"], ["83922.3", "0.05"], ["83920.8", "0.001122"], ["83920.1", "0"], ["83920", "0.035806"], ["83918.8", "0.009216"], ["83917.8", "0"], ["83917.7", "0.01984"], ["83916.9", "0.007768"], ["83915", "0"], ["83914.5", "0"], ["83914", "0"], ["83912.3", "0.56935"], ["83912.2", "0.049965"], ["83909.8", "0"], ["83909.7", "0"], ["83908.1", "0"], ["83907", "0"], ["83906.6", "0"], ["83906.5", "0.001333"], ["83905.6", "0.039629"], ["83905.5", "0.039629"], ["83903.2", "0"], ["83903.1", "0.014466"], ["83903", "0.037038"], ["83899.9", "0.0506"], ["83899.8", "0.049544"], ["83894.7", "0.132894"], ["83894.2", "0"], ["83893.9", "0.002799"], ["83892.8", "0.004263"], ["83892.7", "0"], ["83892.1", "0"], ["83888.5", "0.00052"], ["83879.8", "0.357618"], ["83879.5", "0"], ["83878.3", "5.364114"], ["83877.7", "0.003575"], ["83876.4", "0.118996"], ["83875.9", "0"], ["83873.6", "0.012327"], ["83873.2", "0.125076"], ["83872.9", "0.001333"], ["83871.8", "0.004263"], ["83871.6", "0.011878"], ["83871.5", "0.000083"], ["83871.3", "0.012352"], ["83871.2", "0.011994"], ["83871.1", "0.011877"], ["83871", "0.011994"], ["83870.9", "0.118996"], ["83870.8", "0.001466"], ["83870.7", "3.798197"], ["83870.4", "0.000149"], ["83870", "0.00052"], ["83869.9", "0.224383"], ["83869.8", "0.011994"], ["83869.7", "3.531433"], ["83869.5", "0.023986"], ["83869.4", "0.133051"], ["83868.9", "0.005959"], ["83868.7", "0.0027"], ["83868.6", "0.059399"], ["83868.2", "1.182486"], ["83867.6", "0.016257"], ["83867.4", "0.000422"], ["83866.8", "0.027708"], ["83866.4", "0.089099"], ["83866.2", "0.001466"], ["83865.9", "0.011876"], ["83865.6", "0.000106"], ["83865.4", "0.05994"], ["83865.3", "0.000333"], ["83864.9", "0.118996"]], "a": [["83937.2", "0.75028"], ["83941.7", "0.121547"], ["83943.1", "0.004384"], ["83943.8", "0.000522"], ["83944.3", "0.001333"], ["83944.6", "0.001466"], ["83945", "0.000333"], ["83945.5", "0.291288"], ["83945.6", "0.133201"], ["83946.8", "0.00009"], ["83947.3", "0.004384"], ["83948.4", "0.001333"], ["83948.5", "0.000522"], ["83948.9", "0.059399"], ["83949.1", "0.051948"], ["83949.2", "0.177474"], ["83949.5", "0.04"], ["83949.7", "0.09324"], ["83949.8", "0"], ["83950.1", "0.02"], ["83952.1", "0.02461"], ["83952.8", "0.003"], ["83953.7", "0.17867"], ["83954.1", "0.169957"], ["83954.4", "0.038853"], ["83955.2", "0.00009"], ["83955.3", "0.118996"], ["83955.4", "0.178666"], ["83955.8", "0"], ["83956.3", "0.036913"], ["83956.7", "0"], ["83956.8", "0.001333"], ["83957", "0.178663"], ["83957.5", "0.04"], ["83958.1", "0"], ["83958.3", "0"], ["83959.1", "0.263963"], ["83959.7", "0.178687"], ["83959.8", "0.178687"], ["83960", "0.00024"], ["83960.2", "0"], ["83960.4", "0"], ["83962.2", "0"], ["83962.7", "0"], ["83965.5", "0"], ["83967.9", "0"], ["83969.1", "0.007756"], ["83972.8", "0"], ["83973.7", "0"], ["83977", "0.001466"], ["83979", "0.022831"], ["83979.1", "0.952482"], ["83980.7", "0.357617"], ["83987.5", "0.476241"], ["83988.9", "0.01512"], ["83989.5", "0.023824"], ["83991", "0"], ["83998.4", "0"], ["83998.5", "0.178575"], ["84008.1", "0"], ["84013.9", "0"], ["84014", "0"], ["84014.5", "0"], ["84014.9", "0"], ["84015.1", "0"], ["84015.6", "0"], ["84015.7", "0"], ["84016.2", "0"], ["84016.3", "0"], ["84016.5", "0"], ["84016.7", "0"], ["84016.9", "0"], ["84017", "0"], ["84017.7", "0"], ["84018.4", "0"]], "u": 129335, "seq": 67571367333}, "cts": 1742577166317, "record_time": 1742577166.508749, "EXCHANGE": "BYBIT"}
{"topic": "orderbook.200.BTCUSDT", "ts": 1742577166520, "type": "delta", "data": {"s": "BTCUSDT", "b": [["83937.1", "0.222478"], ["83936.9", "0.071516"], ["83935.4", "0.001466"], ["83934.1", "0.005956"], ["83933.5", "0.005761"], ["83931.1", "0"], ["83930.6", "0.027436"], ["83929.4", "0.004079"], ["83926.6", "0.083585"], ["83926.4", "0.038956"], ["83924.2", "0.11924"], ["83924", "0.000333"], ["83923.8", "0.048"], ["83923.7", "0.056"], ["83923", "0.024431"], ["83922.3", "0"], ["83922", "0.088"], ["83921", "0.17874"], ["83920.3", "0.048"], ["83920", "0.00006"], ["83919.9", "0.205767"], ["83919.5", "0"], ["83919.3", "0.233201"], ["83918.9", "0.044"], ["83918.7", "0.048"], ["83916.9", "0.180171"], ["83915.1", "0.561121"], ["83914.7", "0.021"], ["83912.3", "0.630243"], ["83908.8", "0.047652"], ["83907", "0.118996"], ["83905.6", "0"], ["83905.5", "0"], ["83905.3", "0.120815"], ["83904", "0.063456"], ["83903.9", "0.039631"], ["83903.1", "0.001466"], ["83903", "0.024158"], ["83901.5", "0.109294"], ["83901.4", "0.308381"], ["83899.9", "0.0006"], ["83899.8", "0"], ["83898.3", "0.05"], ["83898.2", "0.049545"], ["83896.9", "0.023827"], ["83894.2", "0.125094"], ["83888.7", "0.357607"], ["83886.6", "5.364114"], ["83879.8", "0"], ["83879", "0.178829"], ["83878.3", "0"], ["83873.4", "0.000239"], ["83869.7", "0"], ["83869.5", "0"], ["83869.4", "0"], ["83868.9", "0"], ["83868.7", "0"], ["83868.6", "0"], ["83868.2", "0"], ["83867.6", "0"], ["83867.4", "0"], ["83866.8", "0"], ["83866.4", "0"], ["83866.2", "0"], ["83865.9", "0"], ["83865.6", "0"], ["83865.4", "0"], ["83865.3", "0"], ["83864.9", "0"]], "a": [["83937.2", "0.681137"], ["83940.6", "0.000153"], ["83940.8", "0.006159"], ["83941.7", "0"], ["83942.6", "0.046678"], ["83942.7", "0.071511"], ["83943.7", "0.024635"], ["83944.6", "0.010691"], ["83944.7", "0.042185"], ["83945.5", "0.182723"], ["83945.6", "0.123201"], ["83946.4", "0.05819"], ["83947.9", "0.036952"], ["83949.2", "0.171322"], ["83949.3", "0.041824"], ["83949.7", "0.135521"], ["83950.1", "0"], ["83950.9", "0.041642"], ["83951.1", "0.04"], ["83952.1", "0"], ["83952.6", "0.041333"], ["83952.8", "0.043"], ["83953.9", "0.001466"], ["83954.2", "0"], ["83954.3", "0.058699"], ["83954.5", "0.04"], ["83955.6", "0"], ["83956", "0.04"], ["83956.1", "0.04"], ["83956.3", "0"], ["83957.3", "0"], ["83957.5", "0.218705"], ["83959.2", "0"], ["83959.7", "0"], ["83960.7", "0"], ["83960.9", "0"], ["83961.3", "0.057351"], ["83961.4", "0"], ["83962.6", "0.079303"], ["83964", "0.178705"], ["83966.8", "0.023827"], ["83967.3", "0"], ["83968.3", "0.118049"], ["83972.1", "0"], ["83979", "0"], ["83979.1", "1.428723"], ["83980.7", "0"], ["83985.1", "0.004321"], ["83986.8", "0.357598"], ["83987.5", "0"], ["83987.6", "0.085411"], ["83990.8", "0.052823"], ["84008.7", "0"], ["84013.9", "0.001466"], ["84014", "0.00018"]], "u": 129336, "seq": 67571367646}, "cts": 1742577166517, "record_time": 1742577166.708017, "EXCHANGE": "BYBIT"}
{"topic": "orderbook.200.BTCUSDT", "ts": 1742577166720, "type": "delta", "data": {"s": "BTCUSDT", "b": [["83937.1", "0.054417"], ["83929.6", "0.003685"], ["83925.5", "0.044"], ["83921", "0"], ["83919.3", "0"], ["83918.2", "0.178745"], ["83916.9", "0.001466"], ["83916.5", "0.178749"], ["83914.8", "0.178753"], ["83912.3", "0.56935"], ["83912.2", "0.22867"], ["83910.6", "0.053525"], ["83905.3", "0.178705"], ["83901.1", "0.178705"], ["83900.4", "0.13291"], ["83900.2", "0.096544"], ["83899.2", "0.05009"], ["83899.1", "0.049544"], ["83898.3", "0"], ["83898.2", "0"], ["83894.7", "0"], ["83889.4", "5.364114"], ["83886.6", "0"], ["83875.9", "0.089353"], ["83870.7", "0"], ["83870.4", "0"], ["83870", "0"], ["83869.9", "0"], ["83869.8", "0"]], "a": [["83937.2", "0.685105"], ["83941.2", "0.068131"], ["83941.3", "0.071512"], ["83941.9", "0.003576"], ["83942.6", "0"], ["83942.7", "0"], ["83945.2", "0.071509"], ["83945.6", "0.119233"], ["83946.2", "0.023538"], ["83954.1", "0.26937"], ["83954.3", "0.04"], ["83957.1", "0"], ["83957.5", "0.178705"], ["83959.1", "0.184411"], ["83961.3", "0"], ["83961.9", "0"], ["83964.1", "0.004314"], ["83968.3", "0.004314"], ["83982.3", "0.085596"], ["83983.2", "2.611993"], ["83986.1", "0.357599"], ["83986.7", "0.022831"], ["83986.8", "0"], ["83990.8", "0.001466"], ["83991.4", "0.04"], ["84013.7", "0"], ["84013.9", "0"], ["84014", "0"]], "u": 129337, "seq": 67571367767}, "cts": 1742577166717, "record_time": 1742577166.908218, "EXCHANGE": "BYBIT"}
{"topic": "orderbook.200.BTCUSDT", "ts": 1742577166920, "type": "delta", "data": {"s": "BTCUSDT", "b": [["83937.1", "0.225417"], ["83925", "0.007027"], ["83920.6", "0.17874"], ["83919.9", "0.189443"], ["83919.8", "0.179038"], ["83918.2", "0"], ["83912.2", "0.049965"], ["83905.3", "0"], ["83904.4", "0.04"], ["83904.3", "0.039631"], ["83904", "0.023825"], ["83903.9", "0"], ["83901.9", "0.013"], ["83901.8", "0.01288"], ["83901.5", "0.225569"], ["83901.4", "0.295501"], ["83901.1", "0"], ["83899.2", "0.00009"], ["83899.1", "0"], ["83898.6", "0.049545"], ["83898.5", "0.051011"], ["83888.7", "0"], ["83885.7", "0.446699"], ["83870.8", "0"]], "a": [["83937.2", "0.60763"], ["83938.5", "0.071515"], ["83940.4", "0.003576"], ["83940.6", "0"], ["83940.7", "0.005959"], ["83941.3", "0"], ["83941.9", "0"], ["83943.4", "0.071511"], ["83946.2", "0"], ["83955", "0.036348"], ["83959.7", "0.178705"], ["83962.5", "0"], ["83962.6", "0"], ["83966.9", "0.041083"], ["83978.4", "0.04"], ["83978.5", "0.040333"], ["83983.2", "2.612115"], ["83985.3", "0"], ["83985.4", "0.014484"], ["83986.1", "0"], ["83988.9", "0.372719"], ["83994.3", "0.04"], ["83996", "0.04"]], "u": 129338, "seq": 67571367884}, "cts": 1742577166916, "record_time": 1742577167.107511, "EXCHANGE": "BYBIT"}
{"topic": "orderbook.200.BTCUSDT", "ts": 1742577167119, "type": "delta", "data": {"s": "BTCUSDT", "b": [["83937.1", "0.235207"], ["83937", "0.031501"], ["83932.7", "0.064431"], ["83928.7", "0.052874"], ["83917.9", "0.178705"], ["83916.9", "0.23957"], ["83913.7", "0.178705"], ["83904.4", "0.03963"], ["83901.9", "0.01288"], ["83901.5", "0.096294"], ["83900.4", "0"], ["83898.7", "0.049545"], ["83898.5", "0.001466"], ["83897.6", "0.132903"], ["83892.1", "5.240883"], ["83889.5", "0.357596"], ["83889.4", "0"], ["83885.7", "0.089099"], ["83871.5", "0"], ["83871.3", "0"], ["83871.2", "0"], ["83871.1", "0"], ["83871", "0"], ["83870.9", "0"]], "a": [["83937.2", "0.43663"], ["83938.4", "0.026163"], ["83938.5", "0"], ["83939.5", "0.005959"], ["83939.6", "0.071714"], ["83940.5", "0.000153"], ["83940.7", "0"], ["83941.2", "0.046678"], ["83943.4", "0"], ["83945.6", "0.099198"], ["83947.4", "0.071507"], ["83948.9", "0"], ["83955.3", "0"], ["83966.9", "0.184666"], ["83980.4", "2.618161"], ["83983.2", "0"], ["83986.7", "0"], ["83988.9", "0.01512"], ["83991.3", "0.357592"], ["84013.7", "0.118996"]], "u": 129339, "seq": 67571368016}, "cts": 1742577167116, "record_time": 1742577167.307526, "EXCHANGE": "BYBIT"}
{"topic": "orderbook.200.BTCUSDT", "ts": 1742577167320, "type": "delta", "data": {"s": "BTCUSDT", "b": [["83919.9", "0.305717"], ["83917.2", "0.178705"], ["83898.8", "0.050333"], ["83898.6", "0"], ["83896.9", "0.11318"], ["83889.5", "0"], ["83885.8", "0.357594"]], "a": [["83938.6", "0.071515"], ["83939.5", "0"], ["83939.6", "0.0032"], ["83940.7", "0.005959"], ["83943.5", "0.07151"], ["83945.2", "0"], ["83945.5", "0.232572"], ["83949", "0.059399"], ["83952.8", "0.04"], ["83962.2", "0.178705"], ["83968.2", "0.178705"], ["83980.4", "0.006046"], ["83985.9", "2.612115"], ["83991.2", "0.381418"], ["83991.3", "0"], ["84012.1", "0"], ["84012.8", "0"], ["84013.1", "0"], ["84013.7", "0"]], "u": 129340, "seq": 67571368094}, "cts": 1742577167316, "record_time": 1742577167.507449, "EXCHANGE": "BYBIT"}
{"topic": "orderbook.200.BTCUSDT", "ts": 1742577167519, "type": "delta", "data": {"s": "BTCUSDT", "b": [["83937.1", "0.239167"], ["83931.9", "0.003"], ["83917.2", "0"], ["83909.6", "0.004377"], ["83904.5", "0.04"], ["83904.3", "0"], ["83903.2", "0.0016"], ["83888.7", "0.357587"], ["83885.8", "0"], ["83871.6", "0"]], "a": [["83940.4", "0.000153"], ["83940.5", "0"], ["83948.1", "0.0241"], ["83949.7", "0.071769"], ["83953.7", "0"], ["83955", "0.0006"], ["83955.4", "0"], ["83957", "0"], ["83978.3", "0.04"], ["83978.5", "0.000333"], ["83982.3", "0.085594"], ["83991.1", "0.357922"], ["83991.2", "0.023825"], ["84012.1", "0.000333"], ["84012.8", "0.353911"]], "u": 129341, "seq": 67571368166}, "cts": 1742577167512, "record_time": 1742577167.706917, "EXCHANGE": "BYBIT"}
{"topic": "orderbook.200.BTCUSDT", "ts": 1742577167720, "type": "delta", "data": {"s": "BTCUSDT", "b": [["83902", "0.013"], ["83901.8", "0"], ["83887", "0"], ["83871.6", "0.011878"]], "a": [["83937.2", "0.436443"], ["83954.1", "0.099413"], ["83955", "0.036348"], ["83991.1", "0.000333"], ["83991.7", "0.357584"], ["84012.8", "0"]], "u": 129342, "seq": 67571368218}, "cts": 1742577167696, "record_time": 1742577167.907525, "EXCHANGE": "BYBIT"}
{"topic": "orderbook.200.BTCUSDT", "ts": 1742577167920, "type": "delta", "data": {"s": "BTCUSDT", "b": [["83892.1", "5.219487"]], "a": [["83978.3", "0"], ["83978.4", "0"], ["83978.5", "0.040333"], ["83978.6", "0.04"], ["83991.6", "0.380301"], ["83991.7", "0"], ["84008.1", "1.028473"], ["84012.8", "0.353911"]], "u": 129343, "seq": 67571368243}, "cts": 1742577167913, "record_time": 1742577168.10828, "EXCHANGE": "BYBIT"}
{"success": true, "ret_msg": "subscribe", "conn_id": "db9a9825-b0cd-4231-ad46-55f33c5e50d2", "op": "subscribe", "record_time": 1742584881.398695, "EXCHANGE": "BYBIT"}
{"topic": "orderbook.200.BTCUSDT", "ts": 1742584880320, "type": "snapshot", "data": {"s": "BTCUSDT", "b": [["84069.4", "0.07968"], ["84069.1", "0.005327"], ["84068.6", "0.000528"], ["84067.3", "0.0282"], ["84067.2", "0.031498"], ["84066.7", "0.000333"], ["84066.5", "0.0041"], ["84066", "0.001333"], ["84065.6", "0.007116"], ["84064.9", "0.005327"], ["84064.7", "0.001466"], ["84063.9", "0.000528"], ["84063.3", "0.056418"], ["84062.7", "0.028467"], ["84062.5", "0.000333"], ["84062", "0.172284"], ["84061.9", "0.00528"], ["84061.8", "0.001333"], ["84061.5", "0.07141"], ["84061.2", "0.005946"], ["84061.1", "0.048"], ["84061", "0.173355"], ["84060.7", "0.005327"], ["84060.1", "0.001466"], ["84060", "0.00006"], ["84059.8", "0.064"], ["84059.7", "0.171"], ["84059.4", "0.006045"], ["84059.3", "0.000528"], ["84058.9", "0.071412"], ["84058.8", "0.00009"], ["84058.7", "0.165939"], ["84058.5", "0.042703"], ["84058.4", "0.064"], ["84058.3", "0.000333"], ["84058.2", "0.092"], ["84058.1", "0.035697"], ["84057.8", "0.065426"], ["84057.6", "0.001333"], ["84057.4", "0.06"], ["84056.5", "0.069326"], ["84055.8", "0.023693"], ["84055.5", "0.001466"], ["84055.4", "0.012"], ["84055.3", "0.0015"], ["84055", "0.03569"], ["84054.7", "0.060528"], ["84054.4", "0.051333"], ["84054.1", "0.009673"], ["84054", "0.000366"], ["84053.6", "0.200731"], ["84053.4", "0.001333"], ["84053.2", "0.06"], ["84053", "0.11"], ["84052.9", "0.111671"], ["84052.5", "0.018594"], ["84052.3", "0.005326"], ["84052.2", "0.02063"], ["84051.9", "0.05"], ["84051.2", "0.171"], ["84050.9", "0.001466"], ["84050.7", "0.004603"], ["84050.6", "0.178464"], ["84050.5", "0.168107"], ["84050.4", "0.00018"], ["84050.1", "0.000528"], ["84049.9", "0.000333"], ["84049.2", "0.001333"], ["84048.5", "0.114238"], ["84048.4", "0.178469"], ["84048.1", "0.005682"], ["84047.4", "0.00588"], ["84047.3", "0.009225"], ["84047.2", "0.178471"], ["84046.3", "0.001466"], ["84046.1", "0.059399"], ["84046", "0.299077"], ["84045.8", "0.181999"], ["84045.7", "0.000333"], ["84045.5", "0.526685"], ["84045", "0.001333"], ["84043.9", "0.005318"], ["84043.2", "0.178424"], ["84042.7", "0.171"], ["84042", "0.00009"], ["84041.6", "0.013366"], ["84041.5", "0.000333"], ["84040.8", "0.001859"], ["84040", "0.00006"], ["84039.7", "0.005313"], ["84038.8", "0.031025"], ["84038.7", "0.023787"], ["84038.5", "0.04"], ["84038.4", "0.039629"], ["84037.8", "0.0015"], ["84037.6", "0.365604"], ["84037.5", "0.593544"], ["84037.4", "0.000333"], ["84037.3", "0.000333"], ["84037.1", "0.003575"], ["84037", "0.039302"], ["84036.8", "0.013"], ["84036.7", "0.131419"], ["84036.6", "0.001333"], ["84036.2", "0.000526"], ["84035.8", "0.015"], ["84035.5", "0.005313"], ["84035.3", "0.001189"], ["84035", "0.05"], ["84034.9", "0.04954"], ["84034.6", "0.023038"], ["84034.2", "0.171"], ["84034", "0.059399"], ["84033.7", "0.023785"], ["84033.6", "0.00009"], ["84033.1", "0.000333"], ["84032.9", "0.023787"], ["84032.7", "0.000358"], ["84032.4", "0.002799"], ["84032.2", "0.11263"], ["84032.1", "0.096392"], ["84031.7", "0.005946"], ["84031.6", "0.000526"], ["84031.5", "0.118539"], ["84031.3", "0.005313"], ["84031.2", "0.124844"], ["84030.2", "0.000083"], ["84029.5", "0.023789"], ["84028.9", "0.000333"], ["84028.2", "0.001333"], ["84027.8", "0.091529"], ["84027.1", "0.005308"], ["84027", "0.000542"], ["84026.7", "0.056"], ["84026.6", "0.294787"], ["84026.3", "1.11842"], ["84026.2", "3.543118"], ["84026", "0.000358"], ["84025.7", "0.171"], ["84025.4", "0.012"], ["84025.3", "0.0015"], ["84025.2", "0.00009"], ["84025", "0.000204"], ["84024.7", "0.000333"], ["84024", "0.001333"], ["84023.6", "0.156131"], ["84023.5", "0.353279"], ["84023.4", "0.023789"], ["84023.1", "0.001466"], ["84022.9", "0.005238"], ["84022.5", "0.0176"], ["84022.3", "0.000526"], ["84021.9", "0.118539"], ["84020.5", "0.000333"], ["84020", "0.00006"], ["84019.8", "0.001333"], ["84018.7", "0.005238"], ["84018.5", "0.000324"], ["84017.7", "0.030236"], ["84017.3", "0.357023"], ["84017.2", "0.171"], ["84017.1", "0.059399"], ["84016.8", "0.051423"], ["84016.5", "0.320756"], ["84016.3", "0.125217"], ["84016", "0.04"], ["84015.8", "0.056"], ["84015.6", "0.001333"], ["84014.5", "0.005238"], ["84014.3", "0.06"], ["84014", "0.092"], ["84013.9", "0.001466"], ["84013.1", "0.000526"], ["84012.1", "0.000333"], ["84011.8", "0.118539"], ["84011.7", "0.000149"], ["84011.4", "4.020016"], ["84011.3", "0.003575"], ["84010.3", "0.183662"], ["84009.3", "0.001466"], ["84008.7", "0.171"], ["84008.5", "0.179079"], ["84008.4", "0.00018"], ["84007.9", "0.000333"], ["84007.2", "0.029164"], ["84007", "0.06"], ["84006.9", "0.003"], ["84006.1", "0.183662"], ["84005.2", "0.00595"], ["84004.7", "0.001466"], ["84003.9", "0.000884"], ["84003.7", "0.000333"], ["84003", "0.001333"], ["84001.9", "0.107782"], ["84001.7", "0.118539"], ["84001.4", "0.003"], ["84001.2", "0.00595"], ["84001", "0.064"], ["84000.5", "0.064"], ["84000.2", "0.230399"]], "a": [["84069.5", "0.629023"], ["84070.2", "0.154153"], ["84071.1", "0.120089"], ["84073.3", "0.00497"], ["84074.1", "0.221089"], ["84074.4", "0.001333"], ["84074.7", "0.071399"], ["84075", "0.001189"], ["84075.2", "0.000333"], ["84076", "0.001"], ["84076.2", "0.01988"], ["84077", "0.10032"], ["84077.3", "0.129627"], ["84077.5", "0.005465"], ["84077.6", "0.051132"], ["84077.8", "0.000528"], ["84077.9", "0.320199"], ["84078.6", "0.002799"], ["84078.7", "0.126074"], ["84079.4", "0.000333"], ["84079.6", "0.020089"], ["84080.1", "0.158692"], ["84080.4", "0.029819"], ["84081.2", "0.00009"], ["84081.6", "0.009225"], ["84081.7", "0.005465"], ["84081.8", "0.198513"], ["84082.2", "0.000999"], ["84082.4", "0.000528"], ["84082.5", "0.020089"], ["84082.9", "0.001333"], ["84083.2", "0.041466"], ["84083.4", "0.162724"], ["84083.6", "0.000333"], ["84084.5", "0.024088"], ["84084.8", "0.001"], ["84085", "0.04"], ["84085.1", "0.04"], ["84085.3", "0.173075"], ["84085.5", "0.171"], ["84085.7", "0.07139"], ["84085.9", "0.005436"], ["84086", "0.178424"], ["84086.4", "0.04"], ["84087", "0.022567"], ["84087.1", "0.001861"], ["84087.2", "0.03"], ["84087.8", "0.000333"], ["84087.9", "0.001466"], ["84088", "0.03"], ["84088.2", "0.08"], ["84088.5", "0.04"], ["84089.6", "0.00009"], ["84089.7", "0.095978"], ["84089.8", "0.099399"], ["84089.9", "0.04"], ["84090.1", "0.005436"], ["84090.8", "0.111671"], ["84091.3", "0.001333"], ["84091.7", "0.000528"], ["84092", "0.000333"], ["84092.3", "0.031783"], ["84092.5", "0.001466"], ["84092.9", "0.248258"], ["84093", "0.5935"], ["84094.4", "0.005437"], ["84094.5", "0.171"], ["84094.8", "0.006205"], ["84095.5", "0.001333"], ["84095.9", "0.04919"], ["84096.2", "0.000333"], ["84096.3", "0.000528"], ["84096.8", "0.009643"], ["84097.1", "0.001466"], ["84097.5", "0.079958"], ["84097.8", "0.0006"], ["84098", "0.00009"], ["84098.6", "0.005445"], ["84099.7", "0.001333"], ["84100.2", "0.023788"], ["84100.4", "0.118872"], ["84100.6", "0.059399"], ["84100.9", "0.00053"], ["84101.7", "0.001466"], ["84102", "0.939416"], ["84102.1", "3.156951"], ["84102.7", "0.005947"], ["84102.8", "0.005445"], ["84103.6", "0.003"], ["84103.9", "0.001333"], ["84104", "0.000358"], ["84104.6", "0.000333"], ["84104.7", "0.03"], ["84105.6", "0.154759"], ["84106.4", "0.001556"], ["84106.9", "0.11433"], ["84107", "0.094648"], ["84107.1", "0.03"], ["84108.1", "0.001333"], ["84108.2", "0.03"], ["84108.3", "0.005947"], ["84108.8", "0.000333"], ["84108.9", "0.201"], ["84109", "0.024284"], ["84109.4", "0.294497"], ["84109.6", "0.004666"], ["84109.8", "0.0119"], ["84110.2", "0.00053"], ["84110.5", "0.003086"], ["84110.6", "0.529151"], ["84110.7", "0.118539"], ["84110.9", "0.059399"], ["84111", "0.001466"], ["84111.1", "0.03"], ["84111.2", "0.005445"], ["84111.4", "1.425849"], ["84112.3", "0.001333"], ["84112.5", "0.051471"], ["84113", "0.000333"], ["84113.1", "0.03"], ["84113.4", "0.04"], ["84113.5", "0.04"], ["84114.1", "0.095015"], ["84114.2", "0.023779"], ["84114.3", "0.03"], ["84114.4", "0.0006"], ["84114.8", "0.00062"], ["84115.3", "0.0015"], ["84115.4", "0.017866"], ["84115.6", "0.021892"], ["84115.8", "0.118539"], ["84116.1", "0.024884"], ["84116.5", "0.001333"], ["84117.2", "0.000333"], ["84117.6", "0.051333"], ["84118.3", "0.011898"], ["84118.4", "0.171"], ["84119.4", "0.00053"], ["84119.6", "0.005452"], ["84120", "0.024019"], ["84120.2", "0.001466"], ["84120.7", "0.001333"], ["84120.8", "0.358825"], ["84120.9", "0.118539"], ["84121.4", "0.000333"], ["84122.1", "0.059399"], ["84122.7", "0.0012"], ["84123", "0.000118"], ["84123.2", "0.00009"], ["84123.7", "0.023783"], ["84123.8", "0.005452"], ["84124.1", "0.00053"], ["84124.9", "0.002799"], ["84125.2", "0.005945"], ["84125.4", "0.005945"], ["84125.6", "0.000478"], ["84126.1", "0.118897"], ["84126.9", "0.001142"], ["84127.4", "0.04"], ["84127.5", "0.041904"], ["84127.7", "0.000297"], ["84127.9", "0.089175"], ["84128", "0.176452"], ["84128.1", "0.014033"], ["84128.7", "0.00053"], ["84128.8", "0.023785"], ["84129.1", "0.001333"], ["84129.5", "0.001466"], ["84129.7", "0.059449"], ["84129.8", "0.024116"], ["84130.7", "0.04"], ["84131.2", "0.0006"], ["84131.6", "0.00009"], ["84131.7", "0.0006"], ["84132.2", "0.005472"], ["84132.3", "0.04"], ["84132.4", "0.04"], ["84132.5", "0.01584"], ["84132.7", "0.118539"], ["84132.8", "0.059399"], ["84132.9", "0.023785"], ["84133.1", "0.02206"], ["84133.2", "0.000556"], ["84133.3", "0.001863"], ["84133.9", "0.04"], ["84134", "1.027267"], ["84134.1", "0.041466"], ["84134.6", "0.023785"], ["84135.4", "0.0024"], ["84135.5", "0.059449"], ["84136.4", "0.006679"], ["84136.5", "0.171"], ["84137.4", "0.011846"], ["84137.5", "0.001333"], ["84138", "0.00053"], ["84138.2", "0.000333"], ["84138.8", "0.001466"], ["84140", "0.00042"], ["84140.2", "0.011845"], ["84140.3", "0.118539"]], "u": 167872, "seq": 67577174052}, "cts": 1742584880291, "record_time": 1742584881.400199, "EXCHANGE": "BYBIT"}
{"topic": "orderbook.200.BTCUSDT", "ts": 1742584880520, "type": "delta", "data": {"s": "BTCUSDT", "b": [["84043.2", "0"], ["84038.5", "0"], ["84038.3", "0.039629"], ["84036.8", "0"], ["84036.6", "0.014213"], ["84035", "0"], ["84034.8", "0.04954"], ["84022.9", "0.183662"], ["84018.7", "0.183662"], ["84017.3", "0.35703"], ["84010.3", "0.005238"], ["84006.1", "0.005238"], ["84000", "0.001556"], ["83999.7", "0.06"]], "a": [["84070.1", "0.003576"], ["84120.7", "0.358359"], ["84120.8", "0.0018"], ["84140.3", "0"]], "u": 167873, "seq": 67577174105}, "cts": 1742584880516, "record_time": 1742584881.402203, "EXCHANGE": "BYBIT"}
{"topic": "orderbook.200.BTCUSDT", "ts": 1742584880719, "type": "delta", "data": {"s": "BTCUSDT", "b": [["84018.8", "0.357024"], ["84017.3", "0"], ["84000", "16.101829"]], "a": [["84120.7", "0.001333"], ["84122", "0.357024"], ["84140.2", "0"]], "u": 167874, "seq": 67577174139}, "cts": 1742584880655, "record_time": 1742584881.402203, "EXCHANGE": "BYBIT"}
{"topic": "orderbook.200.BTCUSDT", "ts": 1742584880919, "type": "delta", "data": {"s": "BTCUSDT", "b": [["84069.4", "0"], ["84069.1", "0"], ["84068.6", "0"], ["84067.3", "0"], ["84067.2", "0"], ["84066.7", "0.039038"], ["84066.5", "0"], ["84065.6", "0"], ["84063.5", "0.007116"], ["84063.3", "0"], ["84062.7", "0"], ["84062", "0"], ["84061.5", "0"], ["84061.1", "0"], ["84061", "0.113355"], ["84060", "0.028528"], ["84059.8", "0"], ["84058.9", "0.06"], ["84058.8", "0"], ["84058.7", "0"], ["84058.5", "0"], ["84058.4", "0"], ["84058.2", "0"], ["84058.1", "0"], ["84057.8", "0"], ["84057.5", "0.057249"], ["84057.4", "0"], ["84056.5", "0.07674"], ["84055.8", "0.098596"], ["84055", "0"], ["84054.7", "0.000528"], ["84054.4", "0"], ["84054", "0.058703"], ["84053.6", "0.129002"], ["84053.2", "0"], ["84053", "0.005947"], ["84052.9", "0"], ["84052.5", "0"], ["84052.2", "0"], ["84051.9", "0"], ["84050.6", "0"], ["84050.4", "0.023983"], ["84049.8", "0.064"], ["84048.5", "0"], ["84048.4", "0"], ["84047.3", "0"], ["84047.2", "0"], ["84046.5", "0.058419"], ["84046.1", "0"], ["84046", "0.275289"], ["84045.8", "0.003575"], ["84039.5", "0.059763"], ["84039.3", "0.023791"], ["84038.4", "0"], ["84038.3", "0"], ["84037.1", "0.122524"], ["84036.7", "0"], ["84036.6", "0.010558"], ["84034.9", "0"], ["84034.8", "0"], ["84034.7", "0.04"], ["84034.6", "0.03963"], ["84033.7", "0"], ["84033.1", "0.012228"], ["84033", "0.013"], ["84032.9", "0.036667"], ["84032.5", "0.120773"], ["84032.1", "0"], ["84031.7", "0"], ["84031.2", "0.05"], ["84031.1", "0.049542"], ["84028.4", "0.024577"], ["84027.8", "0.001466"], ["84023.1", "0.179896"], ["84022.9", "0.005238"], ["84021.3", "0.005947"], ["84019.3", "0.090064"], ["84018.8", "0"], ["84018.7", "0.005238"], ["84014.1", "0.00107"], ["84008.5", "0.000526"], ["84007.1", "0.357061"], ["84001.9", "0.01857"], ["84000", "0.001556"], ["83999.5", "0.000333"], ["83999.2", "0.221992"], ["83998.8", "0.001333"], ["83998.4", "0.120539"], ["83997.7", "0.005238"], ["83997.4", "0.000563"], ["83997", "0.059483"], ["83996.7", "0.000119"], ["83996.2", "0.0001"], ["83995.4", "0.013466"], ["83995.3", "0.001833"], ["83994.7", "0.003"], ["83994.6", "0.001859"], ["83994.3", "0.06"], ["83993.5", "0.005238"], ["83993", "1.179622"], ["83992.2", "0.00588"], ["83991.6", "0.169962"], ["83991.1", "0.000333"], ["83990.8", "0.001466"], ["83990.4", "0.001333"], ["83990", "0.000526"], ["83989.3", "0.005238"], ["83987.5", "0.624483"], ["83986.9", "0.000333"], ["83986.6", "0.000333"], ["83986.2", "0.002799"], ["83985.4", "0.000526"]], "a": [["84066.8", "0.910123"], ["84067.2", "0.110239"], ["84067.4", "0.225265"], ["84069.4", "0.01714"], ["84069.5", "0.052587"], ["84070.1", "0"], ["84070.2", "0"], ["84071.2", "0.00497"], ["84073.2", "0.000528"], ["84073.3", "0.005461"], ["84073.5", "0.019881"], ["84073.7", "0.001"], ["84073.9", "0.085003"], ["84074", "0.001466"], ["84074.7", "0"], ["84075.2", "0.051666"], ["84075.8", "0.06"], ["84076.2", "0"], ["84076.6", "0.071397"], ["84076.8", "0.218266"], ["84076.9", "0.059399"], ["84077.3", "0"], ["84077.7", "0.02982"], ["84077.9", "0.260199"], ["84080.1", "0.023089"], ["84080.4", "0"], ["84081.1", "0.03956"], ["84081.2", "0.022873"], ["84081.5", "0.060369"], ["84081.8", "0"], ["84082.5", "0.04"], ["84083.4", "0.04"], ["84083.7", "0.009643"], ["84085.3", "0.224959"], ["84085.7", "0"], ["84086", "0"], ["84087", "0"], ["84088.5", "0.097345"], ["84092.4", "0.051333"], ["84092.8", "0.118539"], ["84093.6", "0.023791"], ["84095.5", "0.11363"], ["84096.8", "0"], ["84100.2", "0"], ["84102.1", "0.535731"], ["84106.8", "0.023789"], ["84107", "0.005445"], ["84108.7", "1.425849"], ["84110.4", "2.62122"], ["84111.4", "0"], ["84111.9", "0.023789"], ["84112.4", "0.357061"], ["84112.9", "0.023789"], ["84113.3", "0.04"], ["84113.5", "0"], ["84116", "0.023789"], ["84117.7", "0.023789"], ["84122", "0"], ["84125.4", "0"], ["84133.9", "0"], ["84134", "0"], ["84134.1", "0"], ["84134.6", "0"], ["84135.4", "0"], ["84135.5", "0"], ["84136.4", "0"], ["84136.5", "0"], ["84137.4", "0"], ["84137.5", "0"], ["84138", "0"], ["84138.2", "0"], ["84138.8", "0"], ["84140", "0"]], "u": 167875, "seq": 67577174805}, "cts": 1742584880916, "record_time": 1742584881.403707, "EXCHANGE": "BYBIT"}
{"topic": "orderbook.200.BTCUSDT", "ts": 1742584881120, "type": "delta", "data": {"s": "BTCUSDT", "b": [["84066.7", "0.072264"], ["84058.9", "0"], ["84058.3", "0.060333"], ["84053.6", "0.192423"], ["84053.2", "0.048"], ["84053.1", "0.064"], ["84051.6", "0.156"], ["84051", "0.05"], ["84050.7", "0"], ["84050.1", "0.021008"], ["84049.9", "0.100869"], ["84049.8", "0.178"], ["84048.1", "0.065682"], ["84046.6", "0.06"], ["84046.5", "0"], ["84046.4", "0.06"], ["84046.2", "0.111681"], ["84045.6", "0.059399"], ["84043.9", "0.056651"], ["84041.8", "0.018594"], ["84039.5", "0"], ["84038.8", "0"], ["84037.6", "0.484143"], ["84037", "0.025371"], ["84034.7", "0"], ["84034.6", "0"], ["84034.4", "0.03963"], ["84034.3", "0.03963"], ["84033", "0"], ["84032.9", "0.023787"], ["84032.7", "0.013238"], ["84032.6", "0.01288"], ["84032.5", "0"], ["84032.2", "0"], ["84031.2", "0"], ["84031.1", "0"], ["84030.9", "0.049542"], ["84030.8", "0.049542"], ["84021.5", "0.013881"], ["84015.9", "0.357038"], ["84010.3", "0.183668"], ["84007.2", "0.001333"], ["84007.1", "0"], ["84006.1", "0.183668"], ["83991.7", "0.171"], ["83986.9", "0"], ["83986.6", "0"], ["83986.2", "0"], ["83985.4", "0"]], "a": [["84066.8", "0.914299"], ["84067.4", "0.221089"], ["84069.4", "0"], ["84071", "0.003576"], ["84077.6", "0.229562"], ["84079.1", "0.04"], ["84080.7", "0.04"], ["84081.1", "0.096998"], ["84081.5", "0"], ["84081.8", "0.17843"], ["84083.4", "0"], ["84084.5", "0"], ["84085.1", "0"], ["84088.5", "0"], ["84094.8", "0"], ["84095.5", "0.001333"], ["84097.5", "0"], ["84102", "0.172753"], ["84109.7", "0.051473"], ["84110.6", "0"], ["84112.4", "0"], ["84112.5", "0"], ["84118.3", "0.368937"], ["84128.1", "0"], ["84133.9", "0.04"], ["84134", "0.000333"], ["84134.1", "0.041466"], ["84134.6", "0.023785"], ["84135.4", "0.0024"], ["84135.5", "0.059449"], ["84136.4", "0.006679"]], "u": 167876, "seq": 67577175014}, "cts": 1742584881114, "record_time": 1742584881.405711, "EXCHANGE": "BYBIT"}
{"topic": "orderbook.200.BTCUSDT", "ts": 1742584881320, "type": "delta", "data": {"s": "BTCUSDT", "b": [["84066.7", "0.105203"], ["84058.8", "0.097172"], ["84058.7", "0.071412"], ["84057.5", "0"], ["84054", "0.000366"], ["84052", "0.124702"], ["84051", "0"], ["84050.6", "0.05"], ["84049.9", "0.143687"], ["84049.8", "0.128"], ["84049.5", "0.05"], ["84049.2", "0.037026"], ["84048.2", "0.122107"], ["84048.1", "0.125682"], ["84042.2", "0.184742"], ["84041.9", "0.026581"], ["84041.2", "0.166748"], ["84034.2", "0.467858"], ["84033.1", "0.301561"], ["84026.7", "0"], ["84022.1", "0.090092"], ["84019.3", "0"], ["84017.3", "0.357032"], ["84015.9", "0"], ["83995.3", "0.126734"], ["83991.7", "16.270377"], ["83991.1", "0"], ["83990.8", "0"], ["83990.4", "0"], ["83990", "0"], ["83989.3", "0"], ["83987.5", "0"]], "a": [["84066.8", "0.784705"], ["84067.2", "0.068321"], ["84067.4", "0.020089"], ["84071", "0"], ["84073.1", "0.0714"], ["84077.2", "0.123762"], ["84081.1", "0.217122"], ["84087", "0.180833"], ["84088.1", "0.163508"], ["84095.1", "0.285863"], ["84096.1", "0.296233"], ["84106.9", "0.502966"], ["84107", "0.09466"], ["84107.6", "2.62122"], ["84110.4", "0"], ["84111.8", "0.014104"], ["84118.3", "0.011898"], ["84120.8", "0.358832"], ["84134", "0"], ["84134.1", "0"], ["84134.6", "0"], ["84135.4", "0"], ["84135.5", "0"], ["84136.4", "0"]], "u": 167877, "seq": 67577175133}, "cts": 1742584881316, "record_time": 1742584881.423245, "EXCHANGE": "BYBIT"}
{"topic": "orderbook.200.BTCUSDT", "ts": 1742584881520, "type": "delta", "data": {"s": "BTCUSDT", "b": [["84061.1", "0.097875"], ["84056.8", "0.000153"], ["84052", "0"], ["84050.7", "0.05"], ["84050.6", "0"], ["84050.1", "0.000528"], ["84049.9", "0.220803"], ["84049.2", "0.061199"], ["84048.2", "0"], ["84044", "0.17843"], ["84043.2", "0.17843"], ["84042.2", "0"], ["84041.9", "0.073283"], ["84041.2", "0"], ["84039.8", "0.17843"], ["84034.2", "0.171"], ["84033.2", "0.18048"], ["84033.1", "0.012228"], ["84031", "0.05"], ["84030.8", "0"], ["84023.1", "0.001466"], ["84022.1", "0.090119"], ["84017.3", "0.357022"], ["83995.3", "0.001833"], ["83991.7", "0"], ["83991.6", "0"]], "a": [["84069.5", "0.050089"], ["84073.1", "0"], ["84074.6", "0.071399"], ["84076.6", "0"], ["84076.9", "0"], ["84077.2", "0"], ["84078.7", "0.19747"], ["84081.1", "0.096998"], ["84082.9", "0.004909"], ["84085.3", "0.317029"], ["84086", "0.17843"], ["84087", "0"], ["84088.1", "0"], ["84095.1", "0"], ["84096.1", "0"], ["84107.6", "2.621168"], ["84109", "0"], ["84109.7", "0.051469"], ["84111.8", "0.016602"], ["84120.8", "0.0018"], ["84126", "0.357021"], ["84134", "0.000333"], ["84134.1", "0.041466"], ["84134.6", "0.023785"], ["84135.4", "0.0024"], ["84135.5", "0.059449"], ["84136.1", "0.027949"]], "u": 167878, "seq": 67577175243}, "cts": 1742584881516, "record_time": 1742584881.623567, "EXCHANGE": "BYBIT"}
{"topic": "orderbook.200.BTCUSDT", "ts": 1742584881719, "type": "delta", "data": {"s": "BTCUSDT", "b": [["84050.1", "0.051861"], ["84045.8", "0.182005"], ["84044", "0"], ["84043.9", "0.005318"], ["84043.2", "0"], ["84039.8", "0"], ["84033.2", "0"], ["84031", "0.049542"], ["84022.1", "0.090121"], ["84010.3", "0.005238"], ["84006.1", "0.005238"], ["84001.9", "0.107785"], ["83993.5", "0.032954"], ["83991.7", "16.099377"], ["83991.6", "0.169962"], ["83991.1", "0.000333"], ["83990.8", "0.001466"]], "a": [["84069.5", "0.020089"], ["84070.7", "0.024342"], ["84075.2", "0.111666"], ["84075.8", "0"], ["84078.4", "0.006016"], ["84080.1", "0.020089"], ["84136.1", "0"]], "u": 167879, "seq": 67577175321}, "cts": 1742584881710, "record_time": 1742584881.822234, "EXCHANGE": "BYBIT"}
{"topic": "orderbook.200.BTCUSDT", "ts": 1742584881920, "type": "delta", "data": {"s": "BTCUSDT", "b": [["84057.5", "0.000153"], ["84056.8", "0"], ["84049.2", "0.025506"], ["84041.9", "0.026581"], ["84037.4", "0.125234"], ["84032.8", "0.01288"], ["84032.6", "0"], ["84031.1", "0.05"], ["84030.9", "0"], ["84022.1", "0.09011"], ["83994.4", "16.100676"], ["83991.7", "0"]], "a": [["84066.8", "0.713299"], ["84067.1", "0.071405"], ["84074.6", "0"], ["84076.5", "0.071397"], ["84078.4", "0"], ["84078.7", "0.126074"], ["84080.3", "0.071394"], ["84084.8", "0"], ["84092.4", "0"], ["84102.1", "3.156899"], ["84105.1", "0.031498"], ["84107.6", "0"], ["84122", "0.35702"], ["84126", "0"], ["84136.1", "0.027949"]], "u": 167880, "seq": 67577175397}, "cts": 1742584881916, "record_time": 1742584882.023257, "EXCHANGE": "BYBIT"}
{"topic": "orderbook.200.BTCUSDT", "ts": 1742584882120, "type": "delta", "data": {"s": "BTCUSDT", "b": [["84057.5", "0"], ["84048.7", "0.035692"], ["84044", "0.17843"], ["84039.8", "0.17843"], ["84037.4", "0.129878"], ["84034.5", "0.03963"], ["84034.3", "0"], ["84031.1", "0"], ["84030.9", "0.049542"], ["83994.4", "0"], ["83991.7", "16.271489"], ["83991.1", "0"], ["83990.8", "0"]], "a": [["84102.1", "0.535731"], ["84107.6", "2.621168"], ["84110.2", "0.04053"], ["84110.3", "0.04"], ["84113.3", "0"], ["84113.4", "0"], ["84122", "0"], ["84126", "0.35702"]], "u": 167881, "seq": 67577175448}, "cts": 1742584882116, "record_time": 1742584882.223577, "EXCHANGE": "BYBIT"}
{"topic": "orderbook.200.BTCUSDT", "ts": 1742584882319, "type": "delta", "data": {"s": "BTCUSDT", "b": [["84044", "0"], ["84039.8", "0"], ["84032.9", "0.036787"], ["84032.7", "0.000358"], ["84031.1", "0.05"], ["84030.9", "0"], ["84027.6", "0.09011"], ["84022.1", "0"], ["84010.3", "0.183668"], ["84006.1", "0.183668"], ["84001.9", "0.01857"], ["83991.1", "0.000333"], ["83990.8", "0.001466"]], "a": [["84075.2", "0.060333"], ["84077.9", "0.259199"], ["84081.3", "0.051333"], ["84082.2", "0"], ["84082.9", "0.001333"], ["84091", "0.003576"], ["84104.9", "2.621033"], ["84107.6", "0"], ["84122", "0.35702"], ["84126", "0"], ["84136.1", "0"]], "u": 167882, "seq": 67577175539}, "cts": 1742584882317, "record_time": 1742584882.422158, "EXCHANGE": "BYBIT"}
{"topic": "orderbook.200.BTCUSDT", "ts": 1742584882520, "type": "delta", "data": {"s": "BTCUSDT", "b": [["84010.3", "0.005238"], ["84006.1", "0.005238"], ["83994.4", "16.101169"], ["83991.7", "0.171"], ["83990.8", "0"]], "a": [["84077.6", "0.051132"], ["84079.3", "0.006232"], ["84081.8", "0"], ["84122", "0.357024"], ["84132.7", "0.471873"]], "u": 167883, "seq": 67577175639}, "cts": 1742584882516, "record_time": 1742584882.62329, "EXCHANGE": "BYBIT"}
{"topic": "orderbook.200.BTCUSDT", "ts": 1742584882720, "type": "delta", "data": {"s": "BTCUSDT", "b": [["84066.7", "0.106003"], ["84032.9", "0.023787"], ["84032.7", "0.013238"], ["84032.5", "0.075177"], ["84031.1", "0"], ["84030.9", "0.049542"], ["84027.6", "0"], ["84022.1", "0.09011"], ["83991.1", "0"]], "a": [["84066.8", "0.884299"], ["84080.2", "0.088078"], ["84081.1", "0"], ["84081.6", "0"], ["84090.2", "0.17843"], ["84090.4", "0.009225"], ["84091", "0"], ["84102.1", "3.156764"], ["84104.9", "0"], ["84109.5", "0.04"], ["84109.6", "0.044666"], ["84110.2", "0.00053"], ["84110.3", "0"], ["84120.8", "0.358826"], ["84122", "0"], ["84127.9", "1.116183"], ["84136.1", "0.027949"], ["84136.4", "0.006679"]], "u": 167884, "seq": 67577175794}, "cts": 1742584882716, "record_time": 1742584882.824379, "EXCHANGE": "BYBIT"}
{"topic": "orderbook.200.BTCUSDT", "ts": 1742584882919, "type": "delta", "data": {"s": "BTCUSDT", "b": [["84031.3", "0.183743"], ["84027.1", "0.183738"], ["84001.9", "0.107785"], ["83994.4", "16.101879"]], "a": [["84066.8", "0.713299"], ["84087.6", "0.003576"], ["84094.4", "0.183867"], ["84102", "0.93936"], ["84109.4", "0.334497"], ["84109.6", "0.004666"], ["84136.4", "0"]], "u": 167885, "seq": 67577175855}, "cts": 1742584882901, "record_time": 1742584883.021877, "EXCHANGE": "BYBIT"}
{"topic": "orderbook.200.BTCUSDT", "ts": 1742584883120, "type": "delta", "data": {"s": "BTCUSDT", "b": [["84060.8", "0.071411"], ["84056.5", "0.005326"], ["84050.8", "0.05"], ["84050.7", "0"], ["84049.6", "0.05"], ["84049.5", "0"], ["84031.3", "0.005313"], ["84027.6", "0.090109"], ["84027.1", "0.005308"], ["84022.1", "0"], ["83991.6", "0"]], "a": [["84079.3", "0"], ["84102.1", "0.535731"], ["84104.9", "2.621033"], ["84109.4", "0.294497"], ["84109.5", "0"], ["84110.1", "0.04"], ["84110.2", "0.04053"], ["84120.8", "0.0018"], ["84126", "0.357019"], ["84136.1", "0"]], "u": 167886, "seq": 67577175916}, "cts": 1742584883115, "record_time": 1742584883.223427, "EXCHANGE": "BYBIT"}
{"topic": "orderbook.200.BTCUSDT", "ts": 1742584883319, "type": "delta", "data": {"s": "BTCUSDT", "b": [["84058.4", "0.000153"], ["84032.9", "0.036787"], ["84032.7", "0.000358"], ["84031.1", "0.05"], ["84030.9", "0"], ["84022.9", "0.094453"], ["83994.4", "16.101696"], ["83991.7", "0"]], "a": [["84079.3", "0.006291"], ["84110", "0.04"], ["84110.2", "0.00053"], ["84135.4", "0"], ["84135.5", "0"]], "u": 167887, "seq": 67577175973}, "cts": 1742584883315, "record_time": 1742584883.421952, "EXCHANGE": "BYBIT"}
{"topic": "orderbook.200.BTCUSDT", "ts": 1742584883520, "type": "delta", "data": {"s": "BTCUSDT", "b": [["84059.8", "0.0044"], ["84058.4", "0"], ["84037.8", "0"], ["84031.1", "0.0516"], ["84027.6", "0"], ["84022.1", "0.09011"], ["83991.6", "0.169962"]], "a": [["84076", "0"], ["84097", "0.001041"], ["84117.1", "0.024284"], ["84122", "0.357022"], ["84126", "0"], ["84134.6", "0"]], "u": 167888, "seq": 67577176108}, "cts": 1742584883516, "record_time": 1742584883.623286, "EXCHANGE": "BYBIT"}
{"topic": "orderbook.200.BTCUSDT", "ts": 1742584883720, "type": "delta", "data": {"s": "BTCUSDT", "b": [["84066.7", "0.106122"], ["84050.8", "0"], ["84050.7", "0.05"], ["84049.9", "0.220883"], ["84049.6", "0"], ["84049.5", "0.05"], ["84034.6", "0.04"], ["84034.4", "0"], ["84031.3", "0.183743"], ["84027.1", "0.183738"], ["84017.4", "0.191653"], ["83991.6", "0"]], "a": [["84066.8", "0.715699"], ["84071", "0.000333"], ["84071.1", "0.123089"], ["84077.6", "0.046332"], ["84097", "0"], ["84102.1", "3.156764"], ["84103.6", "0"], ["84104.9", "0"], ["84105.6", "0.119069"], ["84109.5", "0.04"], ["84109.6", "0.044666"], ["84110", "0"], ["84110.1", "0"], ["84121.9", "0.357026"], ["84122", "0"], ["84134.6", "0.023785"], ["84135.4", "0.0024"], ["84135.5", "0.059449"]], "u": 167889, "seq": 67577176245}, "cts": 1742584883708, "record_time": 1742584883.823589, "EXCHANGE": "BYBIT"}
{"topic": "orderbook.200.BTCUSDT", "ts": 1742584883920, "type": "delta", "data": {"s": "BTCUSDT", "b": [["84066.7", "0.103918"], ["84058.5", "0.002204"], ["84035.5", "0.183743"], ["84022.1", "0.090102"], ["84017.5", "0.357025"], ["84017.3", "0"], ["83992.2", "0"]], "a": [["84073.3", "0.076861"], ["84080.3", "0"], ["84087.6", "0"], ["84091.7", "0.003903"], ["84099.3", "0.035692"], ["84121.8", "0.357026"], ["84121.9", "0"], ["84136.1", "0.027949"]], "u": 167890, "seq": 67577176311}, "cts": 1742584883912, "record_time": 1742584884.024289, "EXCHANGE": "BYBIT"}
{"topic": "orderbook.200.BTCUSDT", "ts": 1742584884119, "type": "delta", "data": {"s": "BTCUSDT", "b": [["84058.5", "0.002158"], ["84054.9", "0.023802"], ["84050.8", "0.05"], ["84050.7", "0"], ["84050.4", "0.00018"], ["84049.9", "0.220374"], ["84049.6", "0.05"], ["84049.5", "0"], ["84017.4", "0"]], "a": [["84080.2", "0.063892"], ["84121.7", "0.357025"], ["84121.8", "0"]], "u": 167891, "seq": 67577176393}, "cts": 1742584884109, "record_time": 1742584884.223405, "EXCHANGE": "BYBIT"}
{"topic": "orderbook.200.BTCUSDT", "ts": 1742584884320, "type": "delta", "data": {"s": "BTCUSDT", "b": [["84034.6", "0"], ["84034.4", "0.03963"], ["84032.9", "0.023787"], ["84032.7", "0.013238"], ["84031.1", "0.0016"], ["84030.9", "0.049542"], ["84017.6", "0.357024"], ["84017.5", "0"], ["84003", "0.401333"], ["83994.4", "16.101406"], ["83993", "0"]], "a": [["84067.1", "0"], ["84070.3", "0.071403"], ["84073.3", "0.005461"], ["84080.8", "0.071394"], ["84089.7", "0.132457"], ["84109.4", "0.334497"], ["84109.6", "0.004666"], ["84121.6", "0.357024"], ["84121.7", "0"], ["84136.1", "0"]], "u": 167892, "seq": 67577176455}, "cts": 1742584884301, "record_time": 1742584884.423606, "EXCHANGE": "BYBIT"}
{"topic": "orderbook.200.BTCUSDT", "ts": 1742584884519, "type": "delta", "data": {"s": "BTCUSDT", "b": [["84059.2", "0.000153"], ["84034.6", "0.04"], ["84034.4", "0"], ["84032.9", "0.036787"], ["84032.7", "0.000358"], ["84031.1", "0.0516"], ["84030.9", "0"], ["84027.1", "0.005308"], ["84017.7", "0.387261"], ["84017.6", "0"], ["83993", "1.179622"]], "a": [["84109.4", "0.294497"], ["84109.6", "0.044666"], ["84121.5", "0.357025"], ["84121.6", "0"]], "u": 167893, "seq": 67577176496}, "cts": 1742584884504, "record_time": 1742584884.622534, "EXCHANGE": "BYBIT"}
{"topic": "orderbook.200.BTCUSDT", "ts": 1742584884720, "type": "delta", "data": {"s": "BTCUSDT", "b": [["84034.6", "0"], ["84034.4", "0.03963"], ["84032.9", "0.023787"], ["84032.7", "0.013238"], ["84032.5", "0.119789"], ["84031.1", "0.0016"], ["84030.9", "0.049542"], ["84025", "0.090308"], ["84022.9", "0.005238"], ["84022.1", "0"], ["84017.8", "0.357024"], ["84017.7", "0.030236"], ["83993", "0"]], "a": [["84079.7", "0.003576"], ["84102.1", "0.535731"], ["84107.6", "2.621033"], ["84109.5", "0"], ["84109.6", "0.004666"], ["84110", "0.04"], ["84110.1", "0.043086"], ["84110.5", "0"], ["84121.5", "0"], ["84126", "0.35702"], ["84135.4", "0"], ["84135.5", "0"]], "u": 167894, "seq": 67577176592}, "cts": 1742584884708, "record_time": 1742584884.823412, "EXCHANGE": "BYBIT"}
{"topic": "orderbook.200.BTCUSDT", "ts": 1742584884920, "type": "delta", "data": {"s": "BTCUSDT", "b": [["84066.7", "0.384535"], ["84060.3", "0.001"], ["84059.6", "0.000153"], ["84059.2", "0"], ["84044", "0.17843"], ["84039.8", "0.17843"], ["84035.5", "0.005313"], ["84031.3", "0.005313"], ["84022.9", "0.094453"], ["84022", "0.357009"], ["84017.8", "0"], ["84016.2", "0.023489"], ["84002.7", "16.101065"], ["83994.7", "0"], ["83994.6", "0"], ["83994.4", "0"], ["83994.3", "0"], ["83993.5", "0"]], "a": [["84066.8", "0.69561"], ["84067.2", "0.032491"], ["84067.4", "0"], ["84069.5", "0"], ["84070.3", "0"], ["84070.7", "0"], ["84071.1", "0.103"], ["84073.7", "0"], ["84074.1", "0.171"], ["84076.5", "0"], ["84077.9", "0.23911"], ["84078.7", "0.105985"], ["84079.3", "0"], ["84079.6", "0"], ["84079.7", "0"], ["84080.1", "0"], ["84080.2", "0.098741"], ["84083.7", "0.081034"], ["84085.3", "0.224959"], ["84086", "0"], ["84092.8", "0"], ["84102", "0.172753"], ["84107.6", "0"], ["84110", "0"], ["84110.1", "0.003086"], ["84110.2", "0.04053"], ["84110.3", "0.04"], ["84110.4", "2.621033"], ["84135.4", "0.0024"], ["84135.5", "0.059449"], ["84136.1", "0.027949"], ["84136.4", "0.006679"], ["84137.4", "0.011846"], ["84137.5", "0.001333"], ["84138", "0.00053"], ["84138.2", "0.000333"], ["84138.8", "0.001466"], ["84140", "0.00042"], ["84140.2", "0.011845"], ["84140.3", "0.118539"]], "u": 167895, "seq": 67577176745}, "cts": 1742584884916, "record_time": 1742584885.023363, "EXCHANGE": "BYBIT"}
{"topic": "orderbook.200.BTCUSDT", "ts": 1742584885119, "type": "delta", "data": {"s": "BTCUSDT", "b": [["84053.6", "0.284432"], ["84052.2", "0.178461"], ["84050.5", "0.346571"], ["84050", "0.020152"], ["84049.9", "0.200218"], ["84048.8", "0.178468"], ["84048.3", "0.17843"], ["84045.8", "0.003575"], ["84032.5", "0.075177"], ["84022.1", "0.35701"], ["84022", "0"], ["83996.7", "0"], ["83996.2", "0"], ["83995.4", "0"], ["83995.3", "0"]], "a": [["84072", "0.071401"], ["84079", "0.071395"], ["84083.7", "0.009643"], ["84136.5", "0.171"], ["84140", "0"], ["84140.2", "0"], ["84140.3", "0"]], "u": 167896, "seq": 67577176791}, "cts": 1742584885107, "record_time": 1742584885.222438, "EXCHANGE": "BYBIT"}
{"topic": "orderbook.200.BTCUSDT", "ts": 1742584885320, "type": "delta", "data": {"s": "BTCUSDT", "b": [["84066.7", "0.152778"], ["84062.7", "0.071409"], ["84059.6", "0"], ["84058.8", "0.062113"], ["84058.7", "0"], ["84047.9", "0.061062"], ["84040.9", "0.05672"], ["84033.9", "0.122664"], ["84028.1", "0.096397"], ["84022.1", "0"], ["84017.3", "0.357011"], ["84002.7", "0"], ["83997.4", "0"], ["83997", "0"]], "a": [["84066.8", "0.458784"], ["84067.2", "0"], ["84071", "0.0739"], ["84071.1", "0.174402"], ["84072", "0"], ["84077.4", "0.071397"], ["84079", "0.04"], ["84080", "0.006076"], ["84080.8", "0.111394"], ["84082.9", "0.056662"], ["84084", "0.04"], ["84085.2", "0.167714"], ["84085.3", "0.118949"], ["84085.5", "0.211"], ["84085.7", "0.04"], ["84089.9", "0.095314"], ["84091.1", "0.003576"], ["84096.9", "0.124577"], ["84137.4", "0"], ["84137.5", "0"], ["84138", "0"], ["84138.2", "0"], ["84138.8", "0"]], "u": 167897, "seq": 67577176898}, "cts": 1742584885317, "record_time": 1742584885.423427, "EXCHANGE": "BYBIT"}
{"topic": "orderbook.200.BTCUSDT", "ts": 1742584885519, "type": "delta", "data": {"s": "BTCUSDT", "b": [["84049.9", "0.281907"], ["84032.9", "0.036787"], ["84032.7", "0.000358"], ["84031.1", "0.0516"], ["84030.9", "0"], ["84010.2", "0.17855"]], "a": [["84083.2", "0.001466"], ["84085", "0"], ["84088.2", "0.04"], ["84089.8", "0.059399"], ["84089.9", "0.055314"], ["84091.1", "0"], ["84096.8", "0.104242"], ["84110", "0.04"], ["84110.1", "0.043086"], ["84110.2", "0.00053"], ["84110.3", "0"], ["84137.4", "0.011846"]], "u": 167898, "seq": 67577176962}, "cts": 1742584885517, "record_time": 1742584885.622619, "EXCHANGE": "BYBIT"}
{"topic": "orderbook.200.BTCUSDT", "ts": 1742584885720, "type": "delta", "data": {"s": "BTCUSDT", "b": [["84066.7", "0.153378"], ["84047.9", "0"], ["84041.9", "0.093353"], ["84040.9", "0"], ["84034.6", "0.04"], ["84034.4", "0"], ["84033.9", "0"], ["84027.8", "0.091571"], ["84025", "0.000204"], ["84002.7", "16.101406"], ["83997.4", "0.000563"], ["83997", "0.059483"]], "a": [["84082.9", "0.001333"], ["84089.9", "0"], ["84092.9", "0.366797"], ["84096.9", "0"], ["84109.7", "0.091469"], ["84109.8", "0.0519"], ["84110", "0"], ["84110.1", "0.003086"], ["84137.5", "0.001333"], ["84138", "0.00053"], ["84138.2", "0.000333"]], "u": 167899, "seq": 67577177010}, "cts": 1742584885696, "record_time": 1742584885.823577, "EXCHANGE": "BYBIT"}
{"topic": "orderbook.200.BTCUSDT", "ts": 1742584885919, "type": "delta", "data": {"s": "BTCUSDT", "b": [["84066.7", "0.133467"]], "a": [["84070", "0.061053"], ["84070.1", "0.071403"], ["84071", "0.024137"], ["84071.1", "0.103"], ["84075.8", "0.071398"], ["84080", "0"], ["84080.8", "0.04"], ["84085.2", "0.120029"], ["84085.3", "0"], ["84091.1", "0.003576"], ["84096.8", "0"], ["84107.6", "2.621033"], ["84110.4", "0"], ["84122", "0.357019"], ["84126", "0"], ["84138.2", "0"]], "u": 167900, "seq": 67577177100}, "cts": 1742584885912, "record_time": 1742584886.023358, "EXCHANGE": "BYBIT"}
{"topic": "orderbook.200.BTCUSDT", "ts": 1742584886120, "type": "delta", "data": {"s": "BTCUSDT", "b": [["84050.9", "0.051466"], ["84050.8", "0"], ["84049.7", "0.05"], ["84049.6", "0"], ["84045.8", "0.182005"], ["84034.6", "0.03963"], ["84013", "0.023791"]], "a": [["84077.4", "0"], ["84079.8", "0.071395"], ["84109.7", "0.051469"], ["84109.8", "0.0119"], ["84109.9", "0.04"], ["84110", "0.04"], ["84122", "0.357022"], ["84137.5", "0"], ["84138", "0"]], "u": 167901, "seq": 67577177182}, "cts": 1742584886105, "record_time": 1742584886.23061, "EXCHANGE": "BYBIT"}
{"topic": "orderbook.200.BTCUSDT", "ts": 1742584886319, "type": "delta", "data": {"s": "BTCUSDT", "b": [["84066.7", "0.133518"], ["84031.1", "0.051142"]], "a": [["84066.8", "0.460694"], ["84080", "0.006181"], ["84121.9", "0.35702"], ["84122", "0"], ["84137.4", "0"]], "u": 167902, "seq": 67577177272}, "cts": 1742584886316, "record_time": 1742584886.422489, "EXCHANGE": "BYBIT"}
{"topic": "orderbook.200.BTCUSDT", "ts": 1742584886520, "type": "delta", "data": {"s": "BTCUSDT", "b": [], "a": [["84066.8", "0.459504"], ["84082.2", "0.04"], ["84083.9", "0.04"], ["84088.2", "0"], ["84091.1", "0"], ["84121.8", "0.357019"], ["84121.9", "0"]], "u": 167903, "seq": 67577177336}, "cts": 1742584886514, "record_time": 1742584886.623407, "EXCHANGE": "BYBIT"}
{"topic": "orderbook.200.BTCUSDT", "ts": 1742584886720, "type": "delta", "data": {"s": "BTCUSDT", "b": [["84066.7", "0.134493"], ["84054", "0.001828"], ["84052.6", "0.114447"], ["84051", "0.05"], ["84050.9", "0.001466"], ["84050.1", "0.072767"], ["84050", "0"], ["84049.8", "0.178"], ["84049.7", "0"], ["84044", "0"], ["84042.8", "0.186762"], ["84033.7", "0.292325"], ["84032.9", "0.036667"], ["84031.2", "0.05"], ["84031", "0"], ["83997", "0"]], "a": [["84077.8", "0.123245"], ["84080", "0"], ["84086.4", "0"], ["84087.6", "0.182277"], ["84096.7", "0.292731"], ["84120.8", "0.358823"], ["84121.8", "0"], ["84137.4", "0.011846"]], "u": 167904, "seq": 67577177412}, "cts": 1742584886710, "record_time": 1742584886.823631, "EXCHANGE": "BYBIT"}
{"topic": "orderbook.200.BTCUSDT", "ts": 1742584886919, "type": "delta", "data": {"s": "BTCUSDT", "b": [["84066.7", "0.105493"], ["84052.6", "0"], ["84052.2", "0"], ["84050.5", "0.168107"], ["84048.8", "0"], ["84048.7", "0"], ["84048.5", "0.035693"], ["84048.3", "0"], ["84042.8", "0"], ["84039.8", "0"], ["84033.7", "0"], ["84031.2", "0"], ["84031", "0.049542"], ["84027.8", "0.001466"], ["84025", "0.090283"], ["84022.9", "0.005238"], ["84017.3", "0"], ["84016.2", "0"], ["84014.4", "0.357037"], ["84002.7", "0"], ["83997", "0.059483"], ["83996.7", "0.000119"], ["83996.2", "0.0001"], ["83995.4", "0.013466"], ["83995.3", "0.001833"], ["83994.7", "0.003"], ["83994.6", "0.001859"], ["83994.4", "16.101406"], ["83994.3", "0.06"]], "a": [["84066.8", "0.633002"], ["84068.9", "0.061053"], ["84069", "0.071404"], ["84070", "0"], ["84070.1", "0"], ["84077.8", "0.000528"], ["84080", "0.006302"], ["84087.6", "0"], ["84089.2", "0.003576"], ["84094.4", "0.005437"], ["84096.7", "0"], ["84109.3", "0.04"], ["84109.4", "0.334497"], ["84109.9", "0"], ["84110", "0"], ["84111.8", "0.014104"], ["84117.5", "0.357037"], ["84120.8", "0.0018"]], "u": 167905, "seq": 67577177546}, "cts": 1742584886915, "record_time": 1742584887.022115, "EXCHANGE": "BYBIT"}
{"topic": "orderbook.200.BTCUSDT", "ts": 1742584887119, "type": "delta", "data": {"s": "BTCUSDT", "b": [["84053.6", "0.201408"], ["84049.9", "0.200218"], ["84048.5", "0"], ["84041.9", "0.026581"], ["84022.9", "0.183668"], ["84017.3", "0.357028"], ["84014.4", "0"], ["84000", "16.102962"], ["83994.4", "0"], ["83993.5", "0.032954"], ["83993", "1.179622"]], "a": [["84066.8", "0.462002"], ["84068.9", "0.056099"], ["84069", "0"], ["84070", "0.071403"], ["84086", "0.17843"], ["84099.3", "0"], ["84117.5", "0"], ["84120.8", "0.358832"], ["84137.5", "0.001333"]], "u": 167906, "seq": 67577177613}, "cts": 1742584887108, "record_time": 1742584887.223197, "EXCHANGE": "BYBIT"}
{"topic": "orderbook.200.BTCUSDT", "ts": 1742584887320, "type": "delta", "data": {"s": "BTCUSDT", "b": [["84066.7", "0.200004"], ["84060.6", "0.000153"], ["84059.7", "0.172"], ["84054.9", "0"], ["84051.4", "0.178462"], ["84050.4", "0.05018"], ["84049.8", "0.128"], ["84049.5", "0.178466"], ["84044", "0.17843"], ["84039.8", "0.17843"], ["84034.6", "0"], ["84034.5", "0"], ["84034.4", "0.03963"], ["84034.3", "0.03963"], ["84032.9", "0.023787"], ["84032.8", "0"], ["84032.7", "0.013238"], ["84032.6", "0.01288"], ["84031.1", "0.0016"], ["84031", "0.05"], ["84030.9", "0.049542"], ["84027.8", "0.091547"], ["84026.7", "0.357"], ["84025", "0.000204"], ["84022.9", "0.094453"], ["84017.3", "0"], ["84016.8", "0.069215"], ["84002.7", "16.101402"], ["84000", "0.001556"], ["83995.3", "0"], ["83994.7", "0"], ["83994.6", "0"], ["83994.3", "0"], ["83993.5", "0"], ["83993", "0"]], "a": [["84066.8", "0.268412"], ["84068.9", "0"], ["84069.9", "0.038732"], ["84070", "0"], ["84071", "0.000333"], ["84071.1", "0.1"], ["84075.8", "0"], ["84079.8", "0"], ["84080", "0"], ["84080.5", "0.071394"], ["84086", "0"], ["84090.4", "0"], ["84092.9", "0.248258"], ["84094.4", "0.183867"], ["84106", "0.009225"], ["84107.6", "0"], ["84109.3", "0"], ["84109.4", "0.294497"], ["84109.7", "0.002498"], ["84110.4", "0.04"], ["84110.5", "0.04"], ["84115.3", "0.052969"], ["84120.8", "0.0018"], ["84126", "0.357"], ["84127", "2.621033"], ["84138", "0.00053"], ["84138.2", "0.000333"]], "u": 167907, "seq": 67577177784}, "cts": 1742584887306, "record_time": 1742584887.423636, "EXCHANGE": "BYBIT"}
{"topic": "orderbook.200.BTCUSDT", "ts": 1742584887520, "type": "delta", "data": {"s": "BTCUSDT", "b": [["84066.7", "0.200268"], ["84047.8", "0.17847"], ["84041.9", "0.076337"], ["84034.5", "0.04"], ["84034.3", "0"], ["84032.8", "0.013"], ["84032.6", "0"], ["84026.7", "0"], ["84017.3", "0.357009"], ["83995.4", "0"]], "a": [["84071.8", "0.024359"], ["84074.9", "0.071399"], ["84075", "0"], ["84084.5", "0.071391"], ["84100.3", "0.053481"], ["84107.6", "2.621033"], ["84109.7", "0.053967"], ["84109.8", "0.0519"], ["84109.9", "0.04"], ["84110.4", "0"], ["84110.5", "0"], ["84115.3", "0.0015"], ["84122", "0.35701"], ["84126", "0"], ["84127", "0"], ["84138", "0"], ["84138.2", "0"]], "u": 167908, "seq": 67577177870}, "cts": 1742584887503, "record_time": 1742584887.623912, "EXCHANGE": "BYBIT"}
{"topic": "orderbook.200.BTCUSDT", "ts": 1742584887720, "type": "delta", "data": {"s": "BTCUSDT", "b": [["84066.7", "0.180357"], ["84060.6", "0"], ["84049.6", "0.116779"], ["84043.6", "0.035693"], ["84042.6", "0.168476"], ["84035.6", "0.299689"], ["84034.5", "0.03963"], ["84032.8", "0.01288"], ["84031", "0.049542"], ["83997", "0"], ["83996.7", "0"], ["83996.2", "0"]], "a": [["84074.1", "0.174"], ["84080.2", "0.144629"], ["84082.5", "0.15887"], ["84089.2", "0"], ["84089.5", "0.177522"], ["84096.5", "0.303293"], ["84109.8", "0.0119"], ["84110", "0.04"], ["84121.9", "0.357018"], ["84122", "0"], ["84137.4", "0"], ["84137.5", "0"]], "u": 167909, "seq": 67577177950}, "cts": 1742584887717, "record_time": 1742584887.823587, "EXCHANGE": "BYBIT"}
{"topic": "orderbook.200.BTCUSDT", "ts": 1742584887920, "type": "delta", "data": {"s": "BTCUSDT", "b": [["84034.6", "0.04"], ["84034.4", "0"], ["84031.1", "0.0516"], ["84030.9", "0"], ["84002.7", "16.101363"], ["83997", "0.059483"]], "a": [["84103.9", "0.037025"], ["84121.9", "0"], ["84126", "0.357017"]], "u": 167910, "seq": 67577177984}, "cts": 1742584887895, "record_time": 1742584888.02334, "EXCHANGE": "BYBIT"}
{"topic": "orderbook.200.BTCUSDT", "ts": 1742584888119, "type": "delta", "data": {"s": "BTCUSDT", "b": [["84066.7", "0.105757"], ["84049.6", "0"], ["84045.6", "0"], ["84042.6", "0"], ["84035.6", "0"], ["84032.9", "0.036787"], ["84032.7", "0.000358"], ["83996.7", "0.000119"], ["83996.2", "0.0001"], ["83995.4", "0.013466"], ["83995.3", "0.001833"]], "a": [["84066.8", "0.435158"], ["84074.9", "0"], ["84078.9", "0.071395"], ["84082.5", "0.04"], ["84083.5", "0.006166"], ["84084.5", "0"], ["84089.5", "0"], ["84092.8", "0.118539"], ["84096.5", "0"], ["84137.4", "0.011846"]], "u": 167911, "seq": 67577178088}, "cts": 1742584888106, "record_time": 1742584888.223198, "EXCHANGE": "BYBIT"}
{"topic": "orderbook.200.BTCUSDT", "ts": 1742584888320, "type": "delta", "data": {"s": "BTCUSDT", "b": [["84050.1", "0.051861"], ["84049.6", "0.023488"], ["84045.9", "0.059399"], ["84011.7", "0"], ["84003.8", "0.000149"], ["84002.7", "16.101385"], ["83995.4", "0"], ["83995.3", "0"]], "a": [["84066.8", "0.264158"], ["84117.7", "0.023934"], ["84122", "0.35702"], ["84125.6", "0.000333"], ["84126", "0"]], "u": 167912, "seq": 67577178128}, "cts": 1742584888314, "record_time": 1742584888.423188, "EXCHANGE": "BYBIT"}
{"topic": "orderbook.200.BTCUSDT", "ts": 1742584888519, "type": "delta", "data": {"s": "BTCUSDT", "b": [], "a": [["84122", "0"], ["84126", "0.357017"]], "u": 167913, "seq": 67577178178}, "cts": 1742584888517, "record_time": 1742584888.621737, "EXCHANGE": "BYBIT"}
{"topic": "orderbook.200.BTCUSDT", "ts": 1742584888720, "type": "delta", "data": {"s": "BTCUSDT", "b": [["84066.7", "0.104957"]], "a": [["84106.9", "1.260176"], ["84122", "0.357017"], ["84126", "0"]], "u": 167914, "seq": 67577178221}, "cts": 1742584888710, "record_time": 1742584888.823331, "EXCHANGE": "BYBIT"}
{"topic": "orderbook.200.BTCUSDT", "ts": 1742584888920, "type": "delta", "data": {"s": "BTCUSDT", "b": [["84002.7", "16.101277"]], "a": [["84122", "0"], ["84126", "0.357016"]], "u": 167915, "seq": 67577178250}, "cts": 1742584888910, "record_time": 1742584889.023399, "EXCHANGE": "BYBIT"}
{"topic": "orderbook.200.BTCUSDT", "ts": 1742584889120, "type": "delta", "data": {"s": "BTCUSDT", "b": [["84061", "0.113508"], ["84060.3", "0"], ["84034.6", "0"], ["84034.5", "0"], ["84034.4", "0.03963"], ["84034.3", "0.03963"], ["84032.9", "0.023787"], ["84032.8", "0"], ["84032.7", "0.013238"], ["84032.6", "0.01288"], ["84031.1", "0.0016"], ["84031", "0"], ["84030.9", "0.049542"], ["84030.8", "0.049542"]], "a": [["84092.8", "0"], ["84092.9", "0.366797"], ["84109.9", "0"], ["84110", "0"], ["84110.3", "0.04"], ["84110.4", "0.04"], ["84137.5", "0.001333"]], "u": 167916, "seq": 67577178304}, "cts": 1742584889085, "record_time": 1742584889.222034, "EXCHANGE": "BYBIT"}
{"topic": "orderbook.200.BTCUSDT", "ts": 1742584889319, "type": "delta", "data": {"s": "BTCUSDT", "b": [["84034.5", "0.04"], ["84034.3", "0"], ["84032.8", "0.013"], ["84032.6", "0"], ["84002.7", "16.101339"]], "a": [["84109.8", "0.0519"], ["84109.9", "0.04"], ["84110.3", "0"], ["84110.4", "0"], ["84138", "0.00053"]], "u": 167917, "seq": 67577178355}, "cts": 1742584889316, "record_time": 1742584889.421993, "EXCHANGE": "BYBIT"}
{"topic": "orderbook.200.BTCUSDT", "ts": 1742584889520, "type": "delta", "data": {"s": "BTCUSDT", "b": [["84032.9", "0.036787"], ["84032.8", "0.01288"], ["84032.7", "0.000358"], ["84031.1", "0.0516"], ["84031", "0.049542"], ["84030.9", "0"], ["84030.8", "0"], ["83995.4", "0.013466"]], "a": [["84109.8", "0.0119"], ["84109.9", "0"], ["84110.2", "0.04053"], ["84110.3", "0.04"]], "u": 167918, "seq": 67577178391}, "cts": 1742584889516, "record_time": 1742584889.623568, "EXCHANGE": "BYBIT"}
{"topic": "orderbook.200.BTCUSDT", "ts": 1742584889720, "type": "delta", "data": {"s": "BTCUSDT", "b": [["84066.7", "0.076456"], ["84061", "0.113355"], ["84058.5", "0"], ["84051", "0"], ["84050.4", "0.00018"], ["84049.6", "0"], ["84034.5", "0"], ["84034.4", "0.04"], ["84034.3", "0.03963"], ["84032.9", "0.023787"], ["84032.8", "0"], ["84032.7", "0.013358"], ["84032.6", "0.01288"], ["84031.1", "0.0016"], ["84031", "0"], ["84030.9", "0.05"], ["84030.8", "0.049542"], ["83995.3", "0.001833"], ["83994.7", "0.003"]], "a": [["84107.6", "0"], ["84109.3", "0.227053"], ["84110.2", "0.00053"], ["84110.4", "2.661033"], ["84112.4", "0.003"], ["84137.5", "0"], ["84138", "0"]], "u": 167919, "seq": 67577178451}, "cts": 1742584889715, "record_time": 1742584889.823427, "EXCHANGE": "BYBIT"}
{"topic": "orderbook.200.BTCUSDT", "ts": 1742584889920, "type": "delta", "data": {"s": "BTCUSDT", "b": [["84066.7", "0.105757"], ["84058.5", "0.025305"], ["84051", "0.05"], ["84050.4", "0.05018"], ["84049.6", "0.023514"], ["84034.4", "0.03963"], ["84032.7", "0.013238"], ["84030.9", "0.049542"], ["84002.7", "16.101385"], ["83995.4", "0"], ["83995.3", "0"], ["83994.7", "0"]], "a": [["84073.3", "0.076861"], ["84106.9", "0"], ["84137.5", "0.001333"]], "u": 167920, "seq": 67577178536}, "cts": 1742584889914, "record_time": 1742584890.023278, "EXCHANGE": "BYBIT"}
{"topic": "orderbook.200.BTCUSDT", "ts": 1742584890120, "type": "delta", "data": {"s": "BTCUSDT", "b": [["84051.1", "0.05"], ["84051", "0"], ["84050.5", "0.218107"], ["84050.4", "0.00018"], ["84049.6", "0.023011"], ["84034.6", "0.04"], ["84034.5", "0.03963"], ["84034.4", "0"], ["84034.3", "0"], ["84032.9", "0.036787"], ["84032.8", "0.01288"], ["84032.7", "0.000358"], ["84032.6", "0"], ["84031.1", "0.0516"], ["84031", "0.049542"], ["84030.9", "0"], ["84030.8", "0"], ["84002.7", "0"], ["83997.2", "16.101385"], ["83995.4", "0.013466"]], "a": [["84077.6", "0.117728"], ["84078.9", "0"], ["84109.7", "0.093967"], ["84109.8", "0.0519"], ["84110.3", "0"], ["84110.4", "2.621033"], ["84122", "0.35702"], ["84126", "0"], ["84138", "0.00053"], ["84138.2", "0.000333"]], "u": 167921, "seq": 67577178605}, "cts": 1742584890114, "record_time": 1742584890.249494, "EXCHANGE": "BYBIT"}
{"topic": "orderbook.200.BTCUSDT", "ts": 1742584890320, "type": "delta", "data": {"s": "BTCUSDT", "b": [["84034.6", "0.03963"], ["84033", "0.013"], ["84032.9", "0.036667"], ["84032.8", "0"], ["84000", "16.102941"], ["83997.2", "0"], ["83995.3", "0.001833"]], "a": [["84089", "0.003576"], ["84109.7", "0.053967"], ["84109.9", "0.04"], ["84138", "0"], ["84138.2", "0"]], "u": 167922, "seq": 67577178630}, "cts": 1742584890311, "record_time": 1742584890.421843, "EXCHANGE": "BYBIT"}
{"topic": "orderbook.200.BTCUSDT", "ts": 1742584890519, "type": "delta", "data": {"s": "BTCUSDT", "b": [["84061.4", "0.000153"], ["84034.7", "0.04"], ["84034.5", "0"], ["84031.2", "0.05"], ["84031.1", "0.051142"], ["84031", "0"], ["84002.7", "16.101385"], ["84000", "0.001556"], ["83995.4", "0"], ["83995.3", "0"]], "a": [["84089", "0"], ["84122", "0"], ["84126", "0.357016"], ["84138", "0.00053"]], "u": 167923, "seq": 67577178651}, "cts": 1742584890497, "record_time": 1742584890.622306, "EXCHANGE": "BYBIT"}
{"topic": "orderbook.200.BTCUSDT", "ts": 1742584890720, "type": "delta", "data": {"s": "BTCUSDT", "b": [["84066.7", "0.180357"], ["84034.7", "0"], ["84034.5", "0.03963"], ["84033", "0"], ["84032.8", "0.01288"], ["84031.2", "0"], ["84031", "0.049542"], ["84002.7", "16.101368"]], "a": [["84072.4", "0.071401"], ["84073.3", "0.005461"], ["84109.7", "0.093967"], ["84109.9", "0"]], "u": 167924, "seq": 67577178691}, "cts": 1742584890713, "record_time": 1742584890.823403, "EXCHANGE": "BYBIT"}
{"topic": "orderbook.200.BTCUSDT", "ts": 1742584890919, "type": "delta", "data": {"s": "BTCUSDT", "b": [["84002.7", "16.101367"]], "a": [["84107.6", "2.621033"], ["84108.6", "0.488155"], ["84110.4", "0"], ["84138", "0"]], "u": 167925, "seq": 67577178717}, "cts": 1742584890865, "record_time": 1742584891.022197, "EXCHANGE": "BYBIT"}
{"topic": "orderbook.200.BTCUSDT", "ts": 1742584891120, "type": "delta", "data": {"s": "BTCUSDT", "b": [["84049.7", "0.023011"], ["84049.6", "0"]], "a": [["84084.3", "0.118953"], ["84107.6", "0"], ["84110.4", "2.621033"], ["84125.9", "0.357017"], ["84126", "0"], ["84137.5", "0"]], "u": 167926, "seq": 67577178754}, "cts": 1742584891052, "record_time": 1742584891.223294, "EXCHANGE": "BYBIT"}
{"topic": "orderbook.200.BTCUSDT", "ts": 1742584891319, "type": "delta", "data": {"s": "BTCUSDT", "b": [["84061.7", "0.000153"], ["84061.4", "0"], ["84059.7", "0.171"], ["84049.7", "0"], ["84049.5", "0.202503"], ["84044", "0"], ["84035.5", "0.183743"], ["84031.3", "0.183743"], ["83995.4", "0.013466"], ["83995.3", "0.001833"]], "a": [["84091.4", "0.003576"], ["84122", "0.357023"], ["84125.9", "0"], ["84137.4", "0"]], "u": 167927, "seq": 67577178835}, "cts": 1742584891315, "record_time": 1742584891.422554, "EXCHANGE": "BYBIT"}
{"topic": "orderbook.200.BTCUSDT", "ts": 1742584891519, "type": "delta", "data": {"s": "BTCUSDT", "b": [["84035.5", "0.005313"], ["84032.5", "0.119652"], ["84031.3", "0.005313"]], "a": [["84109.7", "0.053967"], ["84109.9", "0.04"], ["84122", "0"], ["84126", "0.357017"], ["84136.5", "0"]], "u": 167928, "seq": 67577178900}, "cts": 1742584891515, "record_time": 1742584891.621806, "EXCHANGE": "BYBIT"}
{"topic": "orderbook.200.BTCUSDT", "ts": 1742584891720, "type": "delta", "data": {"s": "BTCUSDT", "b": [["84061.7", "0"], ["84044", "0.17843"], ["84032.5", "0.075177"]], "a": [["84107.6", "2.621033"], ["84108.5", "0.003"], ["84109.7", "0.093967"], ["84109.9", "0"], ["84110.4", "0"], ["84112.4", "0"], ["84125.9", "0.357017"], ["84126", "0"], ["84137.4", "0.011846"]], "u": 167929, "seq": 67577178959}, "cts": 1742584891714, "record_time": 1742584891.823352, "EXCHANGE": "BYBIT"}
{"topic": "orderbook.200.BTCUSDT", "ts": 1742584891920, "type": "delta", "data": {"s": "BTCUSDT", "b": [], "a": [["84091.4", "0"], ["84122", "0.357018"], ["84125.9", "0"], ["84136.5", "0.171"]], "u": 167930, "seq": 67577179018}, "cts": 1742584891915, "record_time": 1742584892.021893, "EXCHANGE": "BYBIT"}
{"topic": "orderbook.200.BTCUSDT", "ts": 1742584892119, "type": "delta", "data": {"s": "BTCUSDT", "b": [["84050.6", "0.05"], ["84050.5", "0.168107"], ["83995.3", "0"]], "a": [["84107.5", "1.286549"], ["84108.6", "0"], ["84122", "0"], ["84126", "0.357017"]], "u": 167931, "seq": 67577179058}, "cts": 1742584892107, "record_time": 1742584892.222451, "EXCHANGE": "BYBIT"}
{"topic": "orderbook.200.BTCUSDT", "ts": 1742584892320, "type": "delta", "data": {"s": "BTCUSDT", "b": [["84034.7", "0.04"], ["84034.5", "0"], ["84033", "0.013"], ["84032.8", "0"], ["84031.2", "0.05"], ["84031", "0"]], "a": [["84066.8", "0.264049"], ["84109.4", "0.334497"], ["84109.5", "0.04"], ["84109.7", "0.053967"], ["84109.8", "0.0119"], ["84125.9", "0.357018"], ["84126", "0"], ["84137.4", "0"]], "u": 167932, "seq": 67577179099}, "cts": 1742584892286, "record_time": 1742584892.423346, "EXCHANGE": "BYBIT"}
{"topic": "orderbook.200.BTCUSDT", "ts": 1742584892520, "type": "delta", "data": {"s": "BTCUSDT", "b": [["84066.7", "0.546876"], ["84065.5", "0.009225"], ["84064.8", "0.029763"], ["84064.7", "0.090565"], ["84063.7", "0.001"], ["84061.1", "0.135113"], ["84058.8", "0.151212"], ["84057.6", "0.052666"], ["84055.3", "0.020094"], ["84053.6", "0.315007"], ["84053.4", "0.179791"], ["84052.1", "0.178461"], ["84051.6", "0.334462"], ["84051.4", "0"], ["84050.9", "0.05713"], ["84050.1", "0.000528"], ["84049.5", "0.024037"], ["84047.8", "0"], ["84046.7", "0.111699"], ["84046.2", "0"], ["84046", "0.364388"], ["84045.8", "0.003575"], ["84045.6", "0.118539"], ["84043.9", "0.065575"], ["84042", "0.051423"], ["84041.8", "0"], ["84038", "0.118953"], ["84036.9", "0.110163"], ["84036.6", "0.001333"], ["84034.7", "0"], ["84034.6", "0"], ["84034", "0.099029"], ["84033.9", "0.03963"], ["84033", "0"], ["84032.9", "0.048134"], ["84032.6", "0.356977"], ["84032.3", "0.01288"], ["84032.2", "0.01288"], ["84031.8", "0.320756"], ["84031.2", "0"], ["84031.1", "0.0016"], ["84030.5", "0.049542"], ["84030.4", "0.049542"], ["84028.4", "0"], ["84028.1", "0"], ["84027", "0.024031"], ["84023.9", "0.025713"], ["84017.3", "0"], ["83997.4", "0"], ["83997", "0"], ["83996.7", "0"], ["83996.2", "0"], ["83995.4", "0"]], "a": [["84066.8", "0.153118"], ["84069.9", "0"], ["84071.8", "0"], ["84072.4", "0"], ["84073.9", "0"], ["84074.1", "0.003"], ["84075.1", "0.0694"], ["84075.3", "0.171"], ["84077.6", "0.027275"], ["84077.9", "0.20911"], ["84080.2", "0"], ["84080.5", "0"], ["84080.7", "0.109599"], ["84081", "0.071394"], ["84081.3", "0"], ["84083.5", "0"], ["84083.7", "0"], ["84084.3", "0"], ["84085.9", "0.065633"], ["84086.9", "0.071389"], ["84087.1", "0.053194"], ["84092.9", "0.307849"], ["84099.9", "0.118218"], ["84100.4", "0.000333"], ["84103.9", "0.001333"], ["84105.5", "0.035691"], ["84107.6", "0"], ["84109.4", "0.294497"], ["84109.5", "0"], ["84109.7", "0.002498"], ["84112.1", "0.04"], ["84112.2", "0.04"], ["84117.1", "0"], ["84121", "0.051469"], ["84125.9", "0"], ["84127.9", "0.089175"], ["84129.8", "2.645149"], ["84133.1", "0"], ["84133.8", "0.356975"], ["84137.4", "0.011846"], ["84137.5", "0.001333"], ["84138", "0.00053"], ["84138.2", "0.000333"], ["84138.8", "0.001466"]], "u": 167933, "seq": 67577179393}, "cts": 1742584892514, "record_time": 1742584892.623204, "EXCHANGE": "BYBIT"}
{"topic": "orderbook.200.BTCUSDT", "ts": 1742584892720, "type": "delta", "data": {"s": "BTCUSDT", "b": [["84073.1", "0.147035"], ["84071", "0.099031"], ["84070.9", "0.882414"], ["84070.6", "0.356396"], ["84070.1", "0.003686"], ["84067.1", "0.007116"], ["84066.8", "0.194624"], ["84066.7", "0.485993"], ["84066.6", "0.009467"], ["84065.5", "0"], ["84064.8", "0"], ["84064.7", "0.001466"], ["84064.5", "0.051333"], ["84064.2", "0.028466"], ["84063.5", "0"], ["84062.7", "0"], ["84062.5", "0.060333"], ["84060.8", "0"], ["84060", "0.042762"], ["84059.9", "0.178444"], ["84058.8", "0.421819"], ["84058.3", "0.000333"], ["84058.2", "0.178448"], ["84057.6", "0.001333"], ["84056.7", "0.526457"], ["84056.6", "0.178451"], ["84055.8", "0.055892"], ["84054.1", "0.000333"], ["84054", "0.000366"], ["84053.4", "0.001333"], ["84052.7", "0.592101"], ["84052.1", "0"], ["84051.6", "0.156"], ["84050.9", "0.001466"], ["84049.3", "0.025713"], ["84048.3", "0.17843"], ["84046.8", "0.356928"], ["84046.7", "0.230646"], ["84046.2", "0.023489"], ["84045.5", "0.000526"], ["84045.3", "0.02379"], ["84043.9", "0.005318"], ["84043", "0.003576"], ["84039.3", "0"], ["84038", "0"], ["84037.5", "0"], ["84037.1", "0.003575"], ["84036.9", "0"], ["84034", "0.059399"], ["84033.9", "0"], ["84032.9", "0.023787"], ["84032.8", "0.04"], ["84032.7", "0.03999"], ["84032.6", "0"], ["84032.3", "0"], ["84032.2", "0"], ["84031.1", "0.0146"], ["84031", "0.01288"], ["84030.5", "0"], ["84030.4", "0"], ["84029.3", "0.05"], ["84029.2", "0.049544"], ["84027", "0.000542"], ["84023.9", "0"], ["84021.5", "0"], ["84017.1", "0.059548"], ["84003.8", "0"], ["84002.7", "0"], ["83999.5", "0"], ["83999.2", "0"], ["83998.8", "0"], ["83998.4", "0"], ["83997.7", "0"]], "a": [["84066.8", "0"], ["84071", "0"], ["84071.1", "0"], ["84071.2", "0"], ["84073.2", "0.040528"], ["84073.5", "0"], ["84074.1", "0"], ["84074.8", "0.00497"], ["84075.1", "0"], ["84075.2", "0.000333"], ["84075.3", "0"], ["84076.8", "0"], ["84077.6", "0"], ["84077.7", "0.01988"], ["84079", "0"], ["84079.4", "0.060333"], ["84080.4", "0.001"], ["84080.8", "0"], ["84081", "0"], ["84081.9", "0.029819"], ["84082.5", "0"], ["84084", "0"], ["84085.2", "0"], ["84085.4", "0.083746"], ["84085.5", "0.171"], ["84085.7", "0"], ["84085.9", "0.005436"], ["84086.9", "0"], ["84087.1", "0.020918"], ["84087.2", "0"], ["84088", "0"], ["84089.7", "0.084185"], ["84090.2", "0"], ["84090.8", "0"], ["84091.7", "0.000528"], ["84092.3", "0.103167"], ["84092.9", "0.140046"], ["84093", "0"], ["84093.3", "0.009236"], ["84093.6", "0"], ["84093.9", "0.051333"], ["84094.4", "0.005437"], ["84097.1", "0.072846"], ["84099.9", "0"], ["84100.3", "0"], ["84105.5", "0"], ["84105.6", "0.00053"], ["84106.6", "0.592052"], ["84107", "0.005445"], ["84107.5", "0"], ["84108.7", "0"], ["84112.1", "0"], ["84112.2", "0"], ["84116.1", "0"], ["84116.4", "0.04"], ["84116.5", "0.041333"], ["84117.7", "0.023789"], ["84121", "0"], ["84126.7", "0.051469"], ["84127.9", "0"], ["84129.8", "0.024116"], ["84131", "0.000145"], ["84133.8", "0"], ["84134.1", "1.825762"], ["84140", "0.00042"], ["84140.2", "0.011845"], ["84140.3", "0.118539"], ["84140.6", "0.005473"], ["84141", "3.569895"], ["84141.3", "0.071295"], ["84141.7", "0.060832"], ["84142.4", "0.000333"], ["84142.6", "0.00053"], ["84142.7", "0.011845"], ["84142.8", "0.051333"], ["84143", "0.588759"], ["84143.2", "0.011847"], ["84143.3", "0.011844"], ["84143.4", "0.001466"], ["84143.6", "2.621033"], ["84143.7", "0.0006"], ["84144.2", "0.0018"], ["84144.8", "0.005475"], ["84145.3", "0.0015"], ["84145.4", "0.012"], ["84145.6", "0.118539"], ["84145.9", "0.001333"], ["84146", "0.011846"], ["84146.3", "0.011844"]], "u": 167934, "seq": 67577179996}, "cts": 1742584892717, "record_time": 1742584892.823419, "EXCHANGE": "BYBIT"}
{"topic": "orderbook.200.BTCUSDT", "ts": 1742584892919, "type": "delta", "data": {"s": "BTCUSDT", "b": [["84073.1", "0.840192"], ["84072.6", "0.089099"], ["84071", "0"], ["84070.9", "0.392211"], ["84070.6", "0"], ["84070.1", "0"], ["84069.8", "0.001"], ["84069.4", "0.071403"], ["84069.3", "0.007116"], ["84068.6", "0.000528"], ["84067.1", "0"], ["84066.8", "0.141348"], ["84066.7", "0.314993"], ["84066.4", "0.028465"], ["84065.1", "0.025713"], ["84064.7", "0.061466"], ["84064.2", "0"], ["84062.9", "0.064"], ["84062.5", "0.294647"], ["84062.2", "0.042701"], ["84061.1", "0.248021"], ["84060.8", "0.178442"], ["84060.4", "0.025091"], ["84060.2", "0.055888"], ["84060", "0.00006"], ["84059.9", "0"], ["84058.4", "0.210629"], ["84058.2", "0"], ["84057.8", "0.06"], ["84056.8", "0.059399"], ["84056.3", "0.06"], ["84056.1", "0.06"], ["84055.9", "0.178416"], ["84055.8", "0"], ["84055", "0.05"], ["84054.6", "0.05"], ["84053.1", "0"], ["84052.4", "0.178416"], ["84052.2", "0.004685"], ["84052", "0.17037"], ["84051.6", "0.064"], ["84051.4", "0.183272"], ["84051.1", "0"], ["84050.7", "0.118539"], ["84050.6", "0"], ["84049.5", "0"], ["84049.3", "0"], ["84048.3", "0"], ["84048.2", "0.178416"], ["84048.1", "0.065682"], ["84046.8", "0"], ["84046.6", "0"], ["84046.4", "0"], ["84046", "0.089099"], ["84045", "0.300882"], ["84044.4", "0.300624"], ["84044", "0"], ["84041.8", "0.023789"], ["84039.9", "0.35694"], ["84039.8", "0"], ["84038.5", "0.294745"], ["84037.6", "0.118539"], ["84037.4", "0.125234"], ["84033.4", "0.090069"], ["84027.8", "0.001466"], ["84026.6", "0"], ["84003.7", "0"], ["84003", "0"], ["84001.9", "0"], ["84001.7", "0"], ["84001.4", "0"], ["84001.2", "0"], ["84001", "0"], ["84000.5", "0"], ["84000.2", "0"], ["84000", "0"], ["83999.7", "0"]], "a": [["84073.2", "0.057669"], ["84074.8", "0"], ["84076.6", "0.023228"], ["84077", "0.10529"], ["84077.7", "0"], ["84079.1", "0"], ["84079.9", "0.01988"], ["84080.7", "0"], ["84081.2", "0.00009"], ["84081.9", "0"], ["84082.2", "0"], ["84083.9", "0"], ["84084.1", "0.029818"], ["84085.4", "0.059746"], ["84085.7", "0.022782"], ["84086.9", "0.04"], ["84087.1", "0.001861"], ["84087.4", "0.04"], ["84089.7", "0.032644"], ["84091.3", "0.120259"], ["84091.9", "0.04"], ["84092.3", "0.001783"], ["84092.9", "0"], ["84093.3", "0"], ["84093.5", "0.141463"], ["84093.6", "0.04"], ["84096", "0.019057"], ["84096.5", "0.111699"], ["84097", "0.042014"], ["84097.1", "0.001466"], ["84097.5", "0.18493"], ["84098.3", "0.183489"], ["84099.4", "0.071378"], ["84099.7", "0.025122"], ["84102.1", "0"], ["84102.2", "0.009236"], ["84104.5", "0.302988"], ["84105.3", "0.301034"], ["84106", "0"], ["84109.4", "0"], ["84111.2", "0.01467"], ["84111.8", "0"], ["84113.3", "0.005947"], ["84115.1", "0.536032"], ["84115.7", "0.04"], ["84116.4", "0"], ["84116.5", "0.001333"], ["84117.5", "0.04"], ["84118.6", "0.04"], ["84118.7", "0.04"], ["84121", "0.04"], ["84126.7", "0.051465"], ["84136.1", "0"], ["84140.2", "0.368778"], ["84140.8", "2.620957"], ["84143.4", "0"], ["84143.6", "0"], ["84143.7", "0"], ["84144.2", "0"], ["84144.8", "0"], ["84145.3", "0"], ["84145.4", "0"], ["84145.6", "0"], ["84145.9", "0"], ["84146", "0"], ["84146.3", "0"]], "u": 167935, "seq": 67577180621}, "cts": 1742584892915, "record_time": 1742584893.022578, "EXCHANGE": "BYBIT"}
{"topic": "orderbook.200.BTCUSDT", "ts": 1742584893119, "type": "delta", "data": {"s": "BTCUSDT", "b": [["84073.1", "0.891776"], ["84067.2", "0.05"], ["84066.7", "0.286792"], ["84063.6", "0.048"], ["84062.6", "0.323047"], ["84062.5", "0.178772"], ["84061.3", "0.064"], ["84061.1", "0"], ["84060.1", "0.129466"], ["84058.8", "0.471819"], ["84058.4", "0.152"], ["84057.5", "0.024791"], ["84055.8", "0.05"], ["84055", "0"], ["84054.6", "0"], ["84053.6", "0.474447"], ["84053.2", "0"], ["84052", "0"], ["84051.6", "0"], ["84051.4", "0"], ["84049.8", "0.064"], ["84049.2", "0.001333"], ["84045", "0.001333"], ["84044.4", "0"], ["84041.6", "0.036686"], ["84040.2", "0.014053"], ["84040", "0.357"], ["84039.9", "0"], ["84036.3", "0.139612"], ["84036.2", "0.050069"], ["84033.4", "0"], ["84029.3", "0"], ["84029.2", "0"], ["84024.8", "16.09787"], ["84003.7", "0.000333"], ["84003.1", "0.071661"], ["84003", "0.401333"]], "a": [["84073.2", "0.057907"], ["84076.6", "0"], ["84086.8", "0.04"], ["84088.5", "0.04"], ["84090.2", "0.04"], ["84090.3", "0.04"], ["84090.9", "0.071385"], ["84091.3", "0.001333"], ["84091.9", "0.08"], ["84097.5", "0"], ["84098.3", "0"], ["84098.6", "0.183861"], ["84102", "0"], ["84102.8", "0.183861"], ["84104.5", "0"], ["84105.2", "0.118539"], ["84105.3", "0"], ["84109.3", "0"], ["84128", "0.26566"], ["84129.8", "2.645073"], ["84140.8", "0"], ["84143.4", "0.001466"], ["84143.7", "0.0006"]], "u": 167936, "seq": 67577180810}, "cts": 1742584893116, "record_time": 1742584893.223508, "EXCHANGE": "BYBIT"}
{"topic": "orderbook.200.BTCUSDT", "ts": 1742584893319, "type": "delta", "data": {"s": "BTCUSDT", "b": [["84076.9", "0.425959"], ["84076.6", "0.356396"], ["84075.1", "0.0003"], ["84073.3", "0.312599"], ["84073.2", "0.331091"], ["84073.1", "0.13021"], ["84072.9", "0.023788"], ["84071", "0.210197"], ["84070.9", "0.220911"], ["84070.8", "0.05728"], ["84070.7", "0.059471"], ["84070.5", "0.178422"], ["84070.2", "0.029797"], ["84069.5", "0.065418"], ["84069.4", "0.072869"], ["84069.3", "0"], ["84069.2", "0.059471"], ["84069.1", "0.005458"], ["84068.7", "0.023788"], ["84067.6", "0.023688"], ["84067.4", "0.059471"], ["84067.1", "0.118943"], ["84066.8", "0.197267"], ["84066.7", "0.051108"], ["84066.5", "0.059471"], ["84066.4", "0"], ["84066", "0.044031"], ["84065.9", "0.059471"], ["84065.3", "0.118942"], ["84064.8", "0.06"], ["84064.7", "0.001466"], ["84064.5", "0"], ["84064", "0.12489"], ["84063", "0.055886"], ["84062.5", "0.000333"], ["84062.2", "0"], ["84061.2", "0.124889"], ["84061", "0"], ["84060.8", "0"], ["84060.5", "0.176105"], ["84060.4", "0"], ["84060.2", "0"], ["84059.6", "0.005947"], ["84059.4", "0.065517"], ["84058", "0.005947"], ["84056.8", "0.177938"], ["84056.6", "0"], ["84055.9", "0"], ["84055.3", "0.0015"], ["84055.2", "0.178416"], ["84054.8", "0.059472"], ["84049.9", "0.259689"], ["84049.8", "0"], ["84048.3", "0.35691"], ["84048.2", "0.237887"], ["84048.1", "0.005682"], ["84046.7", "0.111699"], ["84041.9", "0.217727"], ["84041.8", "0"], ["84040", "0.00006"], ["84036.3", "0.090069"], ["84036.2", "0.000526"], ["84036", "0.05"], ["84035.9", "0.049543"], ["84032.6", "0.017792"], ["84028.2", "0.179844"], ["84024.8", "0"], ["84019.2", "16.097379"], ["84016.8", "0.051423"], ["84016.3", "0.000333"], ["84013", "0.027722"], ["84012.1", "0"], ["84011.8", "0"], ["84011.4", "0"], ["84011.3", "0"], ["84010.3", "0"], ["84010.2", "0"], ["84009.3", "0"], ["84008.7", "0"], ["84008.5", "0"], ["84008.4", "0"], ["84007.9", "0"], ["84007.2", "0"], ["84007", "0"], ["84006.9", "0"], ["84006.1", "0"], ["84005.2", "0"], ["84004.7", "0"], ["84003.9", "0"], ["84003.7", "0"], ["84003.1", "0"], ["84003", "0"]], "a": [["84073.2", "0"], ["84073.3", "0"], ["84074", "0"], ["84074.4", "0"], ["84075.2", "0"], ["84077", "0.000238"], ["84077.8", "0.000825"], ["84077.9", "0"], ["84078.7", "0"], ["84079.9", "0"], ["84080.8", "0.00497"], ["84081.2", "0"], ["84081.4", "0.005947"], ["84083.7", "0.019879"], ["84084.1", "0"], ["84085.4", "0.033563"], ["84087.4", "0"], ["84087.9", "0.031283"], ["84089.7", "0.046209"], ["84089.8", "0"], ["84090.9", "0"], ["84092.3", "0"], ["84093.9", "0"], ["84096.5", "0"], ["84097", "0.097423"], ["84099.4", "0"], ["84099.8", "0.051333"], ["84100", "0.118944"], ["84103.5", "0.071374"], ["84105.2", "0"], ["84106.6", "0.071372"], ["84110.7", "0"], ["84115.6", "0.001466"], ["84118.6", "0"], ["84118.7", "0"], ["84121.7", "0.592052"], ["84122.6", "0.04"], ["84122.7", "0.0412"], ["84124.7", "0.022743"], ["84126.7", "0"], ["84129.5", "0.052931"], ["84129.8", "0.024116"], ["84130", "0.01379"], ["84132.5", "2.636797"], ["84134.1", "0.041466"], ["84137.4", "0"], ["84140.2", "0.011845"], ["84141.3", "0.059449"], ["84143.2", "0"], ["84144.2", "0.0018"], ["84144.8", "0.005475"], ["84145.3", "0.0015"], ["84145.4", "0.012"], ["84145.6", "0.118539"], ["84145.9", "0.001333"], ["84146", "0.011846"], ["84146.3", "0.011844"], ["84146.4", "0.015"], ["84146.5", "3.954851"], ["84146.6", "0.000333"], ["84146.9", "0.013072"], ["84147.2", "0.00053"], ["84148", "0.001466"]], "u": 167937, "seq": 67577181292}, "cts": 1742584893317, "record_time": 1742584893.423638, "EXCHANGE": "BYBIT"}
{"topic": "orderbook.200.BTCUSDT", "ts": 1742584893519, "type": "delta", "data": {"s": "BTCUSDT", "b": [["84080.3", "0.974262"], ["84080.2", "0.330332"], ["84080.1", "0.356396"], ["84080", "0.00006"], ["84078.5", "0.1003"], ["84078.3", "0.009467"], ["84077.4", "0.100311"], ["84077.3", "0.051333"], ["84076.9", "0.051944"], ["84076.5", "0.007115"], ["84076", "0.071398"], ["84075.6", "0.0035"], ["84075.2", "0.000333"], ["84075.1", "0"], ["84074.9", "0.001"], ["84074.4", "0.001333"], ["84074", "0.001466"], ["84073.6", "0.028463"], ["84073.4", "0.097204"], ["84073.3", "0.005458"], ["84073.2", "0.019122"], ["84073.1", "0.123095"], ["84072.8", "0.00528"], ["84072.7", "0.178417"], ["84072.6", "0"], ["84071.9", "0.1133"], ["84071", "0.470824"], ["84070.8", "0.005947"], ["84070.5", "0"], ["84070.2", "0.001333"], ["84069.4", "0.044162"], ["84069", "0.526457"], ["84068.9", "0.178425"], ["84068.6", "0.064528"], ["84068.5", "0.06"], ["84068", "0.178427"], ["84067.6", "0.06562"], ["84067.2", "0.05009"], ["84066.8", "0.227111"], ["84066.7", "0.050844"], ["84066.6", "0"], ["84066", "0.001333"], ["84065.5", "0.092"], ["84065.1", "0.617814"], ["84064.8", "0"], ["84064.7", "0.051466"], ["84063.7", "0.061"], ["84063.1", "0.118539"], ["84062.9", "0"], ["84062.6", "0.215181"], ["84062.1", "0.06"], ["84061.9", "0"], ["84060.5", "0"], ["84060.2", "0.007"], ["84059.8", "0"], ["84058.8", "0.421819"], ["84058.4", "0.184881"], ["84057.8", "0"], ["84056.7", "0"], ["84056.3", "0"], ["84055.8", "0"], ["84054.3", "0.003575"], ["84052.7", "0"], ["84051.5", "0.0264"], ["84050", "0.356897"], ["84048.8", "0.294709"], ["84048.3", "0.024406"], ["84048.2", "0.059471"], ["84046.9", "0.0016"], ["84043.3", "0.05"], ["84043.2", "0.049543"], ["84041.9", "0.090051"], ["84041.6", "0.013366"], ["84038.5", "0"], ["84036.3", "0"], ["84036", "0"], ["84035.9", "0"], ["84031.1", "0.013"], ["84019.2", "0"], ["84017.7", "0"], ["84017.2", "0"], ["84017.1", "0"], ["84016.8", "0"], ["84016.5", "0"], ["84016.3", "0"], ["84016", "0"], ["84015.8", "0"], ["84015.6", "0"], ["84014.5", "0"], ["84014.3", "0"], ["84014.1", "0"], ["84014", "0"], ["84013.9", "0"], ["84013.1", "0"], ["84013", "0"]], "a": [["84077", "0"], ["84077.5", "0"], ["84077.8", "0"], ["84078.6", "0"], ["84079.4", "0"], ["84080.8", "0"], ["84083.7", "0"], ["84084.2", "0.004969"], ["84085.4", "0"], ["84085.5", "0.000297"], ["84085.6", "0.10032"], ["84085.7", "0"], ["84086.8", "0"], ["84086.9", "0"], ["84087", "0.055"], ["84087.1", "0.021739"], ["84087.9", "0.001466"], ["84088.5", "0"], ["84088.8", "0.21411"], ["84089.6", "0.106075"], ["84089.7", "0"], ["84090.2", "0"], ["84090.3", "0"], ["84091.3", "0.031149"], ["84091.5", "0.022781"], ["84091.9", "0"], ["84093.5", "0.074063"], ["84093.6", "0"], ["84093.8", "0.04"], ["84094.8", "0.04"], ["84096", "0"], ["84097", "0.074616"], ["84098.6", "0.005445"], ["84099.5", "0.111378"], ["84099.6", "0.04"], ["84099.7", "0.041333"], ["84099.8", "0"], ["84100", "0"], ["84102.1", "0.047331"], ["84102.2", "0"], ["84102.8", "0.005445"], ["84103.4", "0.111699"], ["84103.5", "0"], ["84104.1", "0.019057"], ["84105.5", "0.09516"], ["84106.5", "0.111666"], ["84106.6", "0.118934"], ["84107.3", "0.071371"], ["84108.5", "0.054333"], ["84109.6", "0"], ["84111.2", "0.005445"], ["84115.8", "0"], ["84117.6", "0"], ["84118.3", "0.298855"], ["84119.6", "0.011399"], ["84119.7", "0.009225"], ["84121", "0"], ["84122.6", "0"], ["84122.7", "0.0012"], ["84124.7", "0"], ["84125.1", "0.044572"], ["84125.2", "0.045945"], ["84128", "0.265652"], ["84129.5", "0.316319"], ["84132.5", "0.01584"], ["84138", "0.051991"], ["84143", "0"], ["84145", "0.171"], ["84146", "0"], ["84148.2", "0.000358"], ["84148.4", "0.00009"], ["84148.6", "0.000358"], ["84148.7", "0.04"], ["84149", "0.016471"], ["84149.1", "0.0892"], ["84149.8", "0.0006"], ["84150.1", "0.001333"], ["84150.7", "0.011845"], ["84150.8", "0.158539"], ["84150.9", "0.011327"], ["84151.6", "0.059399"]], "u": 167938, "seq": 67577182271}, "cts": 1742584893517, "record_time": 1742584893.623405, "EXCHANGE": "BYBIT"}
{"topic": "orderbook.200.BTCUSDT", "ts": 1742584893720, "type": "delta", "data": {"s": "BTCUSDT", "b": [["84086.9", "0.58329"], ["84085.9", "0.009225"], ["84085.8", "0.496317"], ["84085.5", "0.02424"], ["84083.1", "0.007114"], ["84082.3", "0.071392"], ["84081.7", "0.005461"], ["84081.3", "0.049911"], ["84080.5", "0.001"], ["84080.4", "0.0015"], ["84080.3", "0.220911"], ["84080.2", "0.02846"], ["84079.4", "0.000333"], ["84078.6", "0.002799"], ["84078.5", "0"], ["84078.1", "0.023786"], ["84077.8", "0.071924"], ["84077.5", "0.005461"], ["84077.4", "0.31594"], ["84076.5", "0"], ["84076", "0.042693"], ["84075.6", "0.182001"], ["84075.3", "0.003"], ["84074", "0.146987"], ["84073.9", "0.178414"], ["84073.6", "0"], ["84073.4", "0"], ["84073.1", "0.051695"], ["84072.8", "0"], ["84072.7", "0"], ["84072.2", "0.178418"], ["84071.9", "0"], ["84070.7", "0.151471"], ["84070.5", "0.05"], ["84069.4", "0.001466"], ["84068.9", "0.048"], ["84068.7", "0"], ["84068.5", "0.288398"], ["84068", "0.05"], ["84067.9", "0.055882"], ["84067.8", "0.05"], ["84067.6", "0.023688"], ["84067.2", "0.115423"], ["84066.8", "0.411264"], ["84066.2", "0.111699"], ["84065.9", "0.084074"], ["84065.6", "0.059399"], ["84065.5", "0.152"], ["84065.4", "0.064"], ["84065.3", "0.182942"], ["84064.7", "0.001466"], ["84064.4", "0.023489"], ["84063.6", "0"], ["84063", "0"], ["84062.7", "0.003575"], ["84062.2", "0.118934"], ["84061.3", "0"], ["84060.1", "0.065466"], ["84059.4", "0.059472"], ["84058.8", "0.270726"], ["84057.5", "0"], ["84056.6", "0.178399"], ["84053.6", "0"], ["84052.2", "0"], ["84051.6", "0.035678"], ["84051.3", "0.356889"], ["84050", "0"], ["84046.7", "0"], ["84046.2", "0"], ["84045.9", "0.072399"], ["84045.8", "0.066455"], ["84045.7", "0.049875"], ["84044.8", "0.090051"], ["84043.3", "0"], ["84043.2", "0"], ["84041.9", "0"], ["84037.1", "0"], ["84033.1", "0.000333"], ["84031.1", "0"], ["84031", "0"], ["84022.3", "0"], ["84021.9", "0"], ["84021.3", "0"], ["84020.5", "0"], ["84020", "0"], ["84019.8", "0"], ["84018.7", "0"], ["84018.5", "0"]], "a": [["84080.4", "0"], ["84081.4", "0"], ["84081.7", "0"], ["84082.4", "0"], ["84082.9", "0"], ["84083.2", "0"], ["84083.6", "0"], ["84084.2", "0"], ["84085.5", "0"], ["84085.6", "0"], ["84085.9", "0"], ["84087.1", "0.001861"], ["84088.8", "0.005"], ["84089.6", "0"], ["84090.8", "0.004969"], ["84091.3", "0.001333"], ["84093.5", "0"], ["84093.7", "0.019877"], ["84094.2", "0.024209"], ["84094.4", "0.096152"], ["84096.6", "0.04"], ["84097.6", "0.04"], ["84097.8", "0.0406"], ["84097.9", "0.069814"], ["84098.2", "0.04"], ["84099.5", "0.04"], ["84102", "0.040934"], ["84102.1", "0"], ["84102.3", "0.083271"], ["84103.4", "0"], ["84105.5", "0.023787"], ["84107.3", "0"], ["84108.2", "0.10137"], ["84108.5", "0.051333"], ["84110.8", "0.05445"], ["84111.6", "0.071368"], ["84112", "0.009236"], ["84112.1", "0.111699"], ["84114.2", "0"], ["84115.7", "0"], ["84119.6", "0.005452"], ["84119.7", "0"], ["84121", "0.005465"], ["84124.4", "0.009225"], ["84125.1", "0.004572"], ["84125.2", "0.005945"], ["84128", "0.176452"], ["84128.9", "0.04"], ["84129", "0.04"], ["84132.1", "0.04"], ["84133.7", "0.024069"], ["84140.7", "0.178399"], ["84144.9", "0.178399"], ["84146.9", "0"], ["84149.1", "0"]], "u": 167939, "seq": 67577183265}, "cts": 1742584893717, "record_time": 1742584893.823348, "EXCHANGE": "BYBIT"}
{"topic": "orderbook.200.BTCUSDT", "ts": 1742584893919, "type": "delta", "data": {"s": "BTCUSDT", "b": [["84088.7", "0.651145"], ["84087", "0.342607"], ["84086.9", "0.60865"], ["84085.9", "0"], ["84085.8", "0"], ["84085.5", "0.019911"], ["84084.9", "0.007114"], ["84084.6", "0.005525"], ["84083.6", "0.000333"], ["84083.2", "0.002466"], ["84083.1", "0"], ["84082.9", "0.001333"], ["84082.4", "0.000528"], ["84081.7", "0.076854"], ["84081.4", "0.16193"], ["84079.4", "0.005613"], ["84078.5", "0.1133"], ["84077.8", "0.000528"], ["84077.4", "0.148302"], ["84076.9", "0.049911"], ["84076.6", "0"], ["84074.2", "0.006676"], ["84073.6", "0.05"], ["84072.5", "0.055877"], ["84070.3", "0.05"], ["84069.9", "0.05"], ["84069.8", "0.119925"], ["84068.7", "0.118539"], ["84068.5", "0.238398"], ["84068", "0"], ["84067.9", "0"], ["84067.8", "0"], ["84067", "0.004585"], ["84066.3", "0.024566"], ["84065.9", "0.059471"], ["84065.5", "0.06"], ["84065", "0.178387"], ["84064.4", "0.06"], ["84062.2", "0"], ["84060.8", "0.178387"], ["84060.1", "0.001466"], ["84056.6", "0"], ["84056.2", "0.356872"], ["84056.1", "0"], ["84053.4", "0.024822"], ["84053", "0"], ["84052.4", "0"], ["84051.6", "0.011892"], ["84051.3", "0"], ["84050.4", "0.090239"], ["84050.1", "0.012426"], ["84049.9", "0.059804"], ["84048.3", "0"], ["84047.1", "0.012882"], ["84047", "0.012882"], ["84046.4", "0.023784"], ["84045.9", "0.059399"], ["84045.8", "0.003575"], ["84045.7", "0.000333"], ["84045.4", "0.05"], ["84045.3", "0.073339"], ["84044.8", "0"], ["84040.3", "0.023784"], ["84040.2", "0"], ["84038.2", "0.005946"], ["84032.3", "0.023785"], ["84028.6", "0.000149"], ["84025.7", "0"], ["84025.4", "0"], ["84025.3", "0"], ["84025.2", "0"], ["84025", "0"], ["84024.7", "0"], ["84024", "0"], ["84023.6", "0"], ["84023.5", "0"], ["84023.4", "0"], ["84023.1", "0"], ["84022.9", "0"], ["84022.5", "0"]], "a": [["84087", "0"], ["84087.1", "0"], ["84087.8", "0"], ["84087.9", "0"], ["84090.8", "0"], ["84091.5", "0"], ["84092.6", "0.004969"], ["84093.8", "0"], ["84094.2", "0"], ["84094.4", "0.005437"], ["84094.5", "0.10032"], ["84094.8", "0"], ["84095.4", "0.26411"], ["84095.9", "0"], ["84096.2", "0.106318"], ["84096.6", "0"], ["84097", "0"], ["84097.6", "0"], ["84097.8", "0.0006"], ["84097.9", "0.029814"], ["84098.2", "0"], ["84098.7", "0.02278"], ["84099.5", "0"], ["84099.6", "0"], ["84099.7", "0.001333"], ["84100.6", "0"], ["84101.9", "0.059399"], ["84102", "0.022311"], ["84102.3", "0"], ["84102.7", "0"], ["84103.7", "0.04"], ["84104.1", "0"], ["84104.7", "0"], ["84105.5", "0"], ["84105.6", "0.04053"], ["84106.5", "0.077833"], ["84106.6", "0"], ["84106.8", "0"], ["84107.1", "0"], ["84108.2", "0"], ["84108.3", "0"], ["84110.8", "0.105335"], ["84111.2", "0.183832"], ["84111.6", "0"], ["84111.9", "0"], ["84112.1", "0"], ["84112.9", "0"], ["84113.3", "0"], ["84114", "0.071366"], ["84115.4", "0.196253"], ["84116", "0"], ["84116.4", "0.190288"], ["84117.5", "0"], ["84117.7", "0"], ["84120", "0.00024"], ["84120.9", "0"], ["84121", "0"], ["84128.9", "0"], ["84129", "0"], ["84130", "0"], ["84130.7", "0"], ["84131", "0"], ["84131.5", "0.04"], ["84131.6", "0.04009"], ["84133.7", "0"], ["84138", "0.00053"], ["84140.2", "0"], ["84140.7", "0"], ["84142.5", "0.000145"], ["84142.7", "0"], ["84143.6", "0.06553"], ["84144.9", "0"], ["84149", "0.005477"], ["84149.1", "2.620839"], ["84150.7", "0"], ["84151.8", "0.000528"], ["84152.1", "0.0006"], ["84152.2", "0.0012"], ["84152.5", "0.011594"], ["84152.6", "0.001466"], ["84153.2", "0.005184"], ["84154.2", "0.02971"], ["84154.3", "1.783868"], ["84154.4", "0.001333"], ["84155.1", "0.000333"], ["84155.5", "0.010994"], ["84156.4", "0.0012"], ["84156.5", "0.000528"], ["84156.8", "0.00009"], ["84157", "0.158539"], ["84157.3", "0.001466"], ["84157.4", "0.005184"], ["84158.2", "0.01872"], ["84158.6", "0.001333"], ["84159.2", "0.026"], ["84159.3", "0.000333"], ["84160", "0.0012"], ["84160.4", "0.059399"], ["84161.1", "0.000528"], ["84161.7", "0.005184"], ["84161.9", "0.001466"], ["84162.8", "0.012326"], ["84163.5", "0.118872"], ["84164", "0.000083"], ["84164.4", "0.000333"], ["84165.2", "0.00009"], ["84165.6", "0.04"], ["84165.7", "0.004198"], ["84165.9", "0.005184"], ["84166.5", "0.001466"], ["84166.9", "0.010992"], ["84167", "0.001333"]], "u": 167940, "seq": 67577184493}, "cts": 1742584893917, "record_time": 1742584894.023469, "EXCHANGE": "BYBIT"}
{"topic": "orderbook.200.BTCUSDT", "ts": 1742584894119, "type": "delta", "data": {"s": "BTCUSDT", "b": [["84091.2", "0.785566"], ["84091.1", "0.066273"], ["84088.7", "0.220911"], ["84087.1", "0.12717"], ["84087", "0"], ["84086.9", "0.40536"], ["84085.9", "0.07685"], ["84084.9", "0"], ["84084.6", "0"], ["84084.5", "0.051333"], ["84083.3", "0.028459"], ["84081.7", "0.005461"], ["84081.4", "0.22498"], ["84080.5", "0.1794"], ["84080.2", "0"], ["84079.9", "0.009225"], ["84079.4", "0.100333"], ["84079.1", "0.042691"], ["84079", "0.064"], ["84078.9", "0.184096"], ["84078.8", "0.178404"], ["84078.5", "0.052225"], ["84077.4", "0.141911"], ["84077.3", "0"], ["84077.1", "0.178408"], ["84076.3", "0.05"], ["84076", "0"], ["84075.9", "0.048"], ["84075.6", "0.00359"], ["84075.3", "0.053"], ["84074.9", "0.051"], ["84074.8", "0.115707"], ["84074.2", "0"], ["84074", "0.001466"], ["84073.9", "0.06"], ["84073.6", "0"], ["84072.4", "0.06"], ["84072.2", "0.06"], ["84070.8", "0"], ["84070.7", "0.059471"], ["84070.5", "0"], ["84070.3", "0.024653"], ["84069.9", "0"], ["84068.9", "0"], ["84068.6", "0.000528"], ["84068.5", "0.06"], ["84067.6", "0"], ["84066.3", "0"], ["84065.5", "0"], ["84065.1", "0.592101"], ["84063.7", "0.001"], ["84062.1", "0"], ["84060.1", "0.02525"], ["84058.8", "0.369892"], ["84058.5", "0"], ["84058.4", "0.124881"], ["84056.6", "0.294682"], ["84056.2", "0"], ["84056.1", "0.023262"], ["84055.3", "0.358372"], ["84053.9", "0.012881"], ["84053.8", "0.012881"], ["84052.1", "0.049546"], ["84052", "0.049546"], ["84051.3", "0.164805"], ["84048.8", "0"], ["84047.7", "0.017792"], ["84047.1", "0"], ["84047", "0"], ["84045.4", "0"], ["84045.3", "0.02379"], ["84044.4", "0.025713"], ["84044", "0.089189"], ["84034", "0.071243"], ["84032.6", "0"], ["84026.3", "0"], ["84026.2", "0"], ["84026", "0"]], "a": [["84088.8", "0"], ["84090.1", "0"], ["84091.3", "0.027026"], ["84092.6", "0"], ["84093.7", "0"], ["84094.5", "0"], ["84095.1", "0.004969"], ["84095.3", "0.024185"], ["84095.4", "0"], ["84097.3", "0.171"], ["84097.9", "0"], ["84098", "0.019966"], ["84099.7", "0.061333"], ["84101.9", "0"], ["84102", "0"], ["84102.2", "0.029813"], ["84102.7", "0.038241"], ["84104.1", "0.04"], ["84104.7", "0.04"], ["84104.8", "0.04"], ["84105.8", "0.04"], ["84106.6", "0.04"], ["84108.5", "0"], ["84108.9", "0.171"], ["84109.7", "0"], ["84109.8", "0.0519"], ["84110.6", "0.006017"], ["84111.4", "0.04"], ["84111.5", "0.04"], ["84112", "0"], ["84112.8", "0.019226"], ["84114", "0"], ["84114.1", "0.347016"], ["84115", "0.051333"], ["84115.1", "0"], ["84115.9", "0.023784"], ["84116", "0.111699"], ["84116.4", "0.118925"], ["84116.5", "0.072696"], ["84117.7", "0.04918"], ["84121.1", "0.009236"], ["84124.4", "0"], ["84127.4", "0.193256"], ["84128", "0.265641"], ["84129.3", "0.009225"], ["84129.5", "0.001466"], ["84131.5", "0"], ["84131.6", "0.00009"], ["84131.7", "0.536632"], ["84132.1", "0"], ["84132.3", "0.208535"], ["84132.4", "0"], ["84134.1", "0.001466"], ["84135.1", "0.04"], ["84135.2", "0.04"], ["84135.4", "0.074197"], ["84140.7", "0.020426"], ["84141", "0"], ["84149.1", "0.089189"], ["84151.9", "0.002497"], ["84153.5", "0.171"], ["84154.6", "2.620839"], ["84160.3", "0.356868"], ["84162", "0.171"], ["84164", "0"], ["84164.4", "0"], ["84165.2", "0"], ["84165.6", "0"], ["84165.7", "0"], ["84165.9", "0"], ["84166.5", "0"], ["84166.9", "0"], ["84167", "0"]], "u": 167941, "seq": 67577185010}, "cts": 1742584894116, "record_time": 1742584894.223269, "EXCHANGE": "BYBIT"}
{"topic": "orderbook.200.BTCUSDT", "ts": 1742584894319, "type": "delta", "data": {"s": "BTCUSDT", "b": [["84091.2", "0.786909"], ["84091.1", "0"], ["84088.8", "0.06248"], ["84088.3", "0.001"], ["84087.4", "0.007114"], ["84083.7", "0.00528"], ["84082.8", "0.1733"], ["84080.9", "0.024187"], ["84078.9", "0.293208"], ["84077.9", "0.055873"], ["84077.7", "0.064"], ["84077.3", "0.064"], ["84076.4", "0.061703"], ["84076.1", "0.06"], ["84075.6", "0.06759"], ["84073.7", "0.024611"], ["84073.5", "0.178378"], ["84072.5", "0"], ["84070.3", "0"], ["84069.4", "0.058033"], ["84068.5", "0"], ["84067.2", "0.051423"], ["84065.4", "0"], ["84062.4", "0.119657"], ["84060.1", "0.001466"], ["84057.2", "0.013859"], ["84055.4", "0.368869"], ["84055.3", "0.0015"], ["84054", "0.049909"], ["84053.9", "0.049543"], ["84053.7", "0.012881"], ["84052.1", "0"], ["84052", "0"], ["84047", "16.089852"], ["84041.6", "0.001466"], ["84031.5", "0"], ["84031.3", "0"], ["84030.2", "0"], ["84029.5", "0"], ["84028.9", "0"], ["84028.6", "0"], ["84028.2", "0"], ["84027.8", "0"], ["84027.1", "0"], ["84027", "0"]], "a": [["84091.3", "0.001333"], ["84096.1", "0.000297"], ["84097.2", "0.166695"], ["84098.7", "0"], ["84098.8", "0.10032"], ["84099.7", "0.270388"], ["84102.2", "0.1083"], ["84102.3", "0.071375"], ["84102.7", "0"], ["84104.1", "0.062779"], ["84109.8", "0.04"], ["84110.6", "0.071368"], ["84111.2", "0.005445"], ["84111.4", "0.102198"], ["84114", "0.258363"], ["84114.1", "0.071365"], ["84115.4", "0.017866"], ["84116.5", "0.001333"], ["84118.4", "0.232961"], ["84124.5", "0.005945"], ["84125", "0.001042"], ["84125.4", "0.124093"], ["84127.4", "0"], ["84128", "0.176452"], ["84135.1", "0"], ["84135.3", "0.04"], ["84139.7", "0.023456"], ["84149.1", "0"], ["84150.9", "0.000333"], ["84152.5", "0.0006"], ["84155.5", "0"], ["84160.2", "0.356872"], ["84160.3", "0"], ["84161.9", "0"], ["84162", "0"], ["84162.8", "0"], ["84163.5", "0"]], "u": 167942, "seq": 67577185399}, "cts": 1742584894315, "record_time": 1742584894.423232, "EXCHANGE": "BYBIT"}
{"topic": "orderbook.200.BTCUSDT", "ts": 1742584894519, "type": "delta", "data": {"s": "BTCUSDT", "b": [["84091.9", "0.641665"], ["84091.4", "0.145736"], ["84091.2", "0.554648"], ["84088.8", "0"], ["84088.7", "0.049911"], ["84087.1", "0.129031"], ["84082.2", "0.178397"], ["84080.5", "0.001"], ["84080.3", "0.221512"], ["84079.9", "0"], ["84079.2", "0.021304"], ["84078.5", "0"], ["84077.8", "0.057029"], ["84076.4", "0"], ["84070.8", "0.059857"], ["84069.4", "0.001466"], ["84069.2", "0.237849"], ["84065.3", "0.118942"], ["84064.4", "0"], ["84063.8", "0.116111"], ["84062.4", "0"], ["84061.7", "0.025713"], ["84060.8", "0"], ["84059.8", "0.356855"], ["84056.1", "0.113286"], ["84055.4", "0.012"], ["84054.9", "0.05"], ["84054.8", "0.109015"], ["84054", "0.000366"], ["84053.9", "0"], ["84050.4", "0.00018"], ["84049.7", "16.086792"], ["84047", "0"], ["84044.4", "0"], ["84035.9", "0.011844"], ["84031.6", "0"]], "a": [["84091.3", "0"], ["84091.7", "0"], ["84092", "0.003305"], ["84095.3", "0"], ["84096.1", "0"], ["84096.2", "0.000333"], ["84097.2", "0"], ["84097.3", "0"], ["84098", "0.019876"], ["84098.7", "0.000297"], ["84099.7", "0.210388"], ["84099.8", "0.171"], ["84100.4", "0.060333"], ["84102.2", "0.086887"], ["84102.3", "0"], ["84108.9", "0.24237"], ["84110.6", "0"], ["84110.8", "0.05445"], ["84111.1", "0"], ["84111.4", "0.04"], ["84112.8", "0.075879"], ["84114", "0.107838"], ["84114.1", "0"], ["84115.9", "0.095148"], ["84117.3", "0.006204"], ["84118.4", "0.171"], ["84119.6", "0.076813"], ["84119.8", "0.060491"], ["84125.1", "0"], ["84125.4", "0"], ["84126", "0.137579"], ["84126.8", "0.108774"], ["84129.7", "0"], ["84131.6", "0.347256"], ["84132.3", "0"], ["84135.2", "0"], ["84135.3", "0"], ["84135.5", "0"], ["84137.1", "0.04"], ["84137.2", "0.04"], ["84138.9", "0.004573"], ["84143.6", "0.014069"], ["84146.5", "4.006314"], ["84149.1", "0.178378"], ["84151.9", "2.623465"], ["84154.6", "0"], ["84160.2", "0"], ["84161.9", "0.001466"], ["84162.8", "0.012326"], ["84163.5", "0.118872"], ["84164", "0.000083"], ["84164.4", "0.000333"], ["84165.2", "0.00009"], ["84165.6", "0.04"], ["84165.7", "0.000528"], ["84165.9", "0.005184"]], "u": 167943, "seq": 67577185725}, "cts": 1742584894512, "record_time": 1742584894.622523, "EXCHANGE": "BYBIT"}
{"topic": "orderbook.200.BTCUSDT", "ts": 1742584894721, "type": "delta", "data": {"s": "BTCUSDT", "b": [["84100.3", "0.702063"], ["84100.1", "0.356396"], ["84097.8", "0.009522"], ["84097.7", "0.491898"], ["84097.4", "0.051333"], ["84097.3", "0.023781"], ["84097", "0.049911"], ["84096.1", "0.049911"], ["84095.5", "0.001333"], ["84095.2", "0.065399"], ["84094.4", "0.168764"], ["84094.3", "0.049911"], ["84094.2", "0.071382"], ["84094.1", "0.356396"], ["84093.8", "0.023782"], ["84093", "0.059455"], ["84092.5", "0.001466"], ["84092.4", "0.053305"], ["84092", "0.000333"], ["84091.9", "0.049911"], ["84091.7", "0.000528"], ["84091.4", "0"], ["84091.3", "0.163991"], ["84091.2", "0.220911"], ["84090.9", "0.130839"], ["84090.7", "0.009467"], ["84090.1", "0.005469"], ["84089.1", "0.11891"], ["84088.6", "0.007114"], ["84088.2", "0.059454"], ["84087.9", "0.001466"], ["84087.8", "0.000333"], ["84087.4", "0"], ["84087.3", "0.005945"], ["84087.1", "0.001861"], ["84087", "0.039136"], ["84086.9", "0.058018"], ["84086.2", "0.018516"], ["84085.9", "0.005461"], ["84085.7", "0.028458"], ["84085", "0.016942"], ["84084.5", "0"], ["84084", "0.437401"], ["84083.9", "0.526457"], ["84083.8", "0.05"], ["84083.7", "0"], ["84083.3", "0"], ["84083.2", "0.058335"], ["84083", "0.06"], ["84082.8", "0.06"], ["84082.3", "0"], ["84082.2", "0"], ["84081.5", "0.04269"], ["84081.4", "0"], ["84081.3", "0.097911"], ["84079.9", "0.592101"], ["84079.2", "0"], ["84079.1", "0"], ["84078.8", "0"], ["84078.7", "0.005945"], ["84078.3", "0"], ["84078.1", "0"], ["84077.9", "0"], ["84077.8", "0.000528"], ["84077.5", "0.183399"], ["84077.3", "0.089713"], ["84077.1", "0"], ["84076.9", "0.109911"], ["84076.3", "0"], ["84075.9", "0"], ["84075.4", "0.3568"], ["84075.3", "0.003"], ["84074.9", "0.001"], ["84073.9", "0"], ["84073.7", "0"], ["84073.5", "0"], ["84073.2", "0.004103"], ["84072.9", "0"], ["84072.4", "0"], ["84070.8", "0.023782"], ["84070.7", "0.011896"], ["84069.8", "0.001"], ["84069.5", "0"], ["84069.2", "0.059471"], ["84069", "0"], ["84068.9", "0.023489"], ["84067.4", "0"], ["84066.5", "0"], ["84065.1", "0"], ["84065", "0"], ["84064", "0"], ["84063.8", "0"], ["84061.7", "0"], ["84059.8", "0"], ["84058.9", "0.090016"], ["84056.1", "0"], ["84055.6", "0.023783"], ["84055.2", "0.228416"], ["84055.1", "0.049543"], ["84054.9", "0"], ["84054.8", "0.059472"], ["84053.9", "0.023782"], ["84053.4", "0.001333"], ["84051.2", "3.70612"], ["84050.1", "0.000528"], ["84049.8", "0.023783"], ["84049.7", "0"], ["84049.4", "0.178466"], ["84045.8", "0"], ["84043", "0"], ["84042.9", "3.949086"], ["84041", "0.000149"], ["84037.4", "0.000333"], ["84035.8", "0"], ["84035.5", "0"], ["84035.3", "0"], ["84034.2", "0"], ["84034", "0"], ["84033.6", "0"], ["84033.1", "0"], ["84032.9", "0"], ["84032.8", "0"], ["84032.7", "0"], ["84032.5", "0"], ["84032.4", "0"], ["84032.3", "0"], ["84031.8", "0"]], "a": [["84092", "0"], ["84092.5", "0"], ["84094.4", "0"], ["84095.1", "0"], ["84095.5", "0"], ["84096.2", "0"], ["84096.3", "0"], ["84097.1", "0"], ["84097.8", "0"], ["84098", "0"], ["84098.6", "0"], ["84098.7", "0"], ["84098.8", "0"], ["84099.7", "0"], ["84099.8", "0"], ["84100.4", "0.000333"], ["84102.2", "0"], ["84102.7", "0.000297"], ["84103.6", "0.09537"], ["84103.7", "0"], ["84104.1", "0"], ["84104.6", "0.023983"], ["84104.7", "0"], ["84104.8", "0"], ["84105.5", "0.01"], ["84105.6", "0.00053"], ["84105.8", "0"], ["84106.4", "0.001466"], ["84106.5", "0"], ["84106.6", "0"], ["84108.8", "0.050333"], ["84108.9", "0.171"], ["84109.8", "0"], ["84110.7", "0.022777"], ["84110.8", "0"], ["84110.9", "0"], ["84111.4", "0"], ["84111.5", "0"], ["84112.8", "0"], ["84113.1", "0"], ["84114", "0"], ["84114.3", "0"], ["84115", "0"], ["84115.3", "0.019799"], ["84115.9", "0"], ["84116", "0"], ["84116.4", "0"], ["84117.3", "0.04"], ["84117.4", "0.071363"], ["84118.3", "0.057417"], ["84119.6", "0.005452"], ["84119.8", "0"], ["84121.7", "0"], ["84122", "0.031991"], ["84123.7", "0"], ["84125", "0.023782"], ["84125.1", "0.006218"], ["84125.2", "0"], ["84126", "0.208934"], ["84126.1", "0.000358"], ["84126.8", "0"], ["84127.4", "0.051333"], ["84127.7", "0"], ["84128.2", "0.071353"], ["84128.8", "0"], ["84129.3", "0"], ["84129.8", "0.000333"], ["84131.7", "0.0006"], ["84132.7", "0.353334"], ["84132.8", "0.083181"], ["84132.9", "0"], ["84134.6", "0"], ["84137.1", "0"], ["84137.2", "0.005945"], ["84137.3", "0.005945"], ["84137.9", "0.023782"], ["84138.1", "0.011896"], ["84138.3", "0.009225"], ["84138.8", "0.025248"], ["84139.7", "1.4262"], ["84140.2", "0.095118"], ["84140.6", "0.597525"], ["84141.3", "0"], ["84142.5", "0"], ["84143.3", "0"], ["84143.7", "0.560414"], ["84144.9", "0.023781"], ["84146.2", "0.04"], ["84146.3", "0.04"], ["84146.4", "0"], ["84146.5", "0"], ["84148.1", "0.024275"], ["84149.1", "0"], ["84151.9", "0.002497"], ["84154.3", "0"], ["84154.9", "0.000145"], ["84155", "0.051459"], ["84162", "0.171"], ["84162.8", "0.001333"], ["84166.5", "0.001466"], ["84166.9", "0.010992"], ["84167", "0.001333"], ["84167.7", "0.000349"], ["84168", "0.051333"], ["84168.2", "0.013069"], ["84168.5", "2.620968"], ["84169.1", "0.177938"], ["84170", "0.002841"], ["84170.1", "0.005184"], ["84170.3", "0.040358"], ["84170.4", "0.002128"], ["84170.5", "3.589997"], ["84170.9", "0.028102"], ["84171.2", "0.002799"], ["84171.9", "0.000333"], ["84172.1", "0.04"], ["84172.3", "0.04"], ["84173", "0.001158"], ["84173.6", "0.00009"], ["84174.2", "0.12018"], ["84174.3", "0.005184"], ["84174.5", "0.04"], ["84174.6", "0.588538"], ["84175", "0.007671"], ["84175.2", "0.004125"], ["84175.3", "0.0015"], ["84175.4", "0.013333"], ["84175.8", "0.120005"], ["84176", "0.003668"], ["84176.1", "0.040333"], ["84176.2", "0.12"], ["84176.3", "0.04"], ["84177.8", "0.246684"]], "u": 167944, "seq": 67577187702}, "cts": 1742584894712, "record_time": 1742584894.828888, "EXCHANGE": "BYBIT"}
{"topic": "orderbook.200.BTCUSDT", "ts": 1742584894920, "type": "delta", "data": {"s": "BTCUSDT", "b": [["84100.8", "0.833268"], ["84100.3", "0.684747"], ["84100.1", "0"], ["84100", "0.00006"], ["84097.8", "0"], ["84097.7", "0.169911"], ["84097.4", "0.060558"], ["84097.3", "0"], ["84097", "0.057024"], ["84096.2", "0.000333"], ["84094.9", "0.343946"], ["84094.8", "0.17837"], ["84094.4", "0.005469"], ["84094.1", "0.384851"], ["84093.1", "0.178374"], ["84092.8", "0.00528"], ["84092.4", "0.053395"], ["84092.3", "0.260765"], ["84092.2", "0.178376"], ["84091.9", "0.163101"], ["84091.3", "0.001333"], ["84091", "0.064"], ["84090.1", "0.105469"], ["84089.8", "0.042685"], ["84089.6", "0.048"], ["84089.4", "0.092"], ["84088.6", "0"], ["84088.1", "0.193138"], ["84087.8", "0.056197"], ["84087.3", "0.069945"], ["84087", "0.05"], ["84086.9", "0.055985"], ["84086.1", "0.064"], ["84086", "0.05"], ["84085.9", "0.055461"], ["84085.7", "0"], ["84085.5", "0.083911"], ["84085", "0"], ["84084.4", "0.06"], ["84084.3", "0.085075"], ["84083.9", "0.586457"], ["84083.8", "0"], ["84083.2", "0.002466"], ["84081.8", "0.118906"], ["84081.5", "0"], ["84081.3", "0.049911"], ["84079.4", "0.000333"], ["84078.9", "0.184096"], ["84077.6", "0.178357"], ["84077.3", "0"], ["84076.7", "0.003575"], ["84075.6", "0.00359"], ["84075.5", "0.145556"], ["84075.4", "0"], ["84074.8", "0"], ["84073.4", "0.178357"], ["84071", "0.156122"], ["84070.8", "0"], ["84068.9", "0"], ["84067", "0"], ["84066.8", "0.184153"], ["84066.7", "0.34549"], ["84066.2", "0"], ["84065.7", "0.356827"], ["84065.2", "0.05"], ["84065.1", "0.049542"], ["84065", "0.025713"], ["84064.6", "0.090016"], ["84058.9", "0"], ["84056.6", "0"], ["84055.2", "0.178416"], ["84055.1", "0"], ["84052.8", "0.023489"], ["84040", "0"], ["84039.7", "0"], ["84038.7", "0"], ["84038.2", "0"], ["84037.6", "0"], ["84037.4", "0"], ["84037.3", "0"], ["84037", "0"], ["84036.6", "0"], ["84036.2", "0"], ["84035.9", "0"]], "a": [["84100.4", "0"], ["84100.9", "0.003502"], ["84102.7", "0"], ["84103.6", "0"], ["84104.6", "0.000333"], ["84104.7", "0.004968"], ["84104.9", "0.003668"], ["84105.5", "0"], ["84107.6", "0.000297"], ["84107.7", "0.019874"], ["84107.8", "0.15349"], ["84107.9", "0.10032"], ["84108.8", "0.209388"], ["84109.2", "0.065856"], ["84109.3", "0.06"], ["84110.1", "0.109071"], ["84111.9", "0.02981"], ["84114", "0.001"], ["84114.2", "0.04"], ["84115.3", "0.041512"], ["84115.8", "0.04"], ["84116.4", "0.04"], ["84117.1", "0.04"], ["84117.4", "0"], ["84118.2", "0.04"], ["84118.3", "0.097417"], ["84118.8", "0.04"], ["84121.1", "0"], ["84122", "0"], ["84123", "0.040118"], ["84123.1", "0.04"], ["84123.8", "0.183809"], ["84124.7", "0.019226"], ["84125", "0"], ["84125.1", "0"], ["84126", "0.137579"], ["84128", "0.354809"], ["84128.2", "0"], ["84128.3", "0.118906"], ["84130.9", "0.009236"], ["84131.6", "0.00009"], ["84132.5", "0"], ["84132.6", "0.118539"], ["84132.7", "0"], ["84133.9", "0"], ["84139.6", "0.682841"], ["84139.7", "0"], ["84140.2", "0"], ["84140.7", "0"], ["84143.6", "0"], ["84146.2", "0"], ["84146.3", "0"], ["84148.2", "0.040358"], ["84148.3", "0.04"], ["84150.7", "0.294352"], ["84151.4", "0.020426"], ["84165.5", "0.356824"], ["84165.7", "2.62151"], ["84168.5", "0"], ["84170.5", "3.760997"], ["84170.9", "0"], ["84171.5", "0.353364"], ["84175.8", "0"], ["84176", "0"], ["84176.1", "0"], ["84176.2", "0"], ["84176.3", "0"], ["84177.8", "0"]], "u": 167945, "seq": 67577188232}, "cts": 1742584894915, "record_time": 1742584895.023336, "EXCHANGE": "BYBIT"}
{"topic": "orderbook.200.BTCUSDT", "ts": 1742584895119, "type": "delta", "data": {"s": "BTCUSDT", "b": [["84100.8", "0.833421"], ["84100.4", "0.183098"], ["84100.3", "0.393083"], ["84095.2", "0.005945"], ["84092.4", "0.06009"], ["84092.3", "0.387309"], ["84091.4", "0.114697"], ["84088.1", "0.264683"], ["84086.3", "0.111699"], ["84086.1", "0.242357"], ["84084.3", "0.084976"], ["84082.8", "0"], ["84081.6", "0.173256"], ["84079.7", "0.004674"], ["84079.4", "0.125183"], ["84079", "0"], ["84077.7", "0"], ["84077.4", "0.049911"], ["84076.9", "0.049911"], ["84076.1", "0"], ["84075.5", "0"], ["84072.5", "0.280765"], ["84072.2", "0"], ["84067.1", "0.131943"], ["84067", "0.01288"], ["84066", "0.35816"], ["84065.7", "0"], ["84065.3", "0.168483"], ["84065.2", "0.049541"], ["84065.1", "0.096354"], ["84065", "0.114892"], ["84062.6", "0"], ["84058.8", "0.270726"], ["84058", "16.086465"], ["84053.8", "0"], ["84053.7", "0"], ["84040", "0.00006"], ["84039.7", "0.005313"], ["84038.7", "0.023787"]], "a": [["84100.9", "0.00374"], ["84112.6", "0.071367"], ["84114.1", "0.088525"], ["84115.3", "0.0015"], ["84116.6", "0.115316"], ["84118.1", "0.090646"], ["84118.3", "0.04"], ["84122", "0.099389"], ["84125.7", "0.071356"], ["84126.1", "0.006775"], ["84126.4", "0.174859"], ["84128.7", "0.112229"], ["84135.5", "0.280529"], ["84139.6", "0"], ["84141.2", "0.005445"], ["84148.7", "0"], ["84149.1", "0.089179"], ["84155", "0.051461"], ["84157.4", "2.626157"], ["84160.6", "0.01406"], ["84165.7", "0.000528"], ["84170.1", "0.094363"], ["84170.2", "1.026492"], ["84173", "0"], ["84173.6", "0"], ["84174.2", "0"], ["84174.3", "0"], ["84174.5", "0"], ["84174.6", "0"], ["84175", "0"], ["84175.2", "0"], ["84175.3", "0"], ["84175.4", "0"]], "u": 167946, "seq": 67577188420}, "cts": 1742584895117, "record_time": 1742584895.221794, "EXCHANGE": "BYBIT"}
{"topic": "orderbook.200.BTCUSDT", "ts": 1742584895320, "type": "delta", "data": {"s": "BTCUSDT", "b": [["84100.8", "0.632268"], ["84100.3", "0.363083"], ["84097.4", "0.051333"], ["84095.1", "0.02379"], ["84094.9", "0.073751"], ["84094.8", "0"], ["84094.1", "0.028455"], ["84093.8", "0.033007"], ["84093.1", "0"], ["84093", "0"], ["84092.2", "0"], ["84091.4", "0"], ["84090.9", "0.071385"], ["84090.4", "0.178379"], ["84088.8", "0.178383"], ["84088.1", "0.342727"], ["84086.1", "0.064"], ["84084.3", "0.084955"], ["84081.6", "0"], ["84080.4", "0"], ["84076.7", "0"], ["84072.5", "0"], ["84067.1", "0.131823"], ["84066", "0.051333"], ["84065.9", "0.109012"], ["84065.3", "0.118942"], ["84065.2", "0"], ["84065", "0.089179"], ["84063.2", "0.356836"], ["84058", "0.005947"], ["84055.3", "16.082018"], ["84054.2", "0.025713"], ["84038.2", "0.005946"], ["84037.6", "0.118539"], ["84037.4", "0.000333"], ["84037.3", "0.000333"], ["84037", "0.025371"]], "a": [["84106.8", "0.000297"], ["84106.9", "0.071372"], ["84112.6", "0"], ["84113.9", "0.001"], ["84116", "0.071364"], ["84116.6", "0"], ["84121.5", "0.051333"], ["84125.7", "0"], ["84126.4", "0"], ["84127.4", "0"], ["84132.2", "0.183829"], ["84135.5", "0"], ["84143.6", "0.268853"], ["84165.5", "0.356836"]], "u": 167947, "seq": 67577188531}, "cts": 1742584895315, "record_time": 1742584895.423281, "EXCHANGE": "BYBIT"}
{"topic": "orderbook.200.BTCUSDT", "ts": 1742584895519, "type": "delta", "data": {"s": "BTCUSDT", "b": [["84100.8", "0.803268"], ["84099.5", "0.0022"], ["84086.8", "0.178387"], ["84083.6", "0.17869"], ["84075.6", "0.00009"], ["84070.8", "0.0016"], ["84066.8", "0.410007"], ["84066", "0.001333"], ["84065.9", "0.059471"], ["84065.7", "0.05"], ["84065.6", "0.10894"], ["84063.2", "0"], ["84061.3", "0.356846"], ["84046.9", "0"], ["84037.4", "0"], ["84037.3", "0"], ["84037", "0"]], "a": [["84106.9", "0"], ["84107.8", "0.153193"], ["84108.3", "0.07137"], ["84113.9", "0.002"], ["84116", "0"], ["84118.2", "0.111362"], ["84120.9", "0.07136"], ["84140.5", "0.214799"], ["84161.9", "0.35831"], ["84165.5", "0"]], "u": 167948, "seq": 67577188595}, "cts": 1742584895517, "record_time": 1742584895.62236, "EXCHANGE": "BYBIT"}
{"topic": "orderbook.200.BTCUSDT", "ts": 1742584895720, "type": "delta", "data": {"s": "BTCUSDT", "b": [["84100.8", "0.632421"], ["84084", "0.605129"], ["84082.3", "0.005445"], ["84075.3", "0"], ["84067.6", "0.01288"], ["84067.5", "0.01288"], ["84067.1", "0.118943"], ["84067", "0"], ["84065.8", "0.049541"], ["84065.7", "0.049541"], ["84065.6", "0.059399"], ["84063.2", "0.356839"], ["84061.3", "0"], ["84058", "16.084245"], ["84055.3", "0.0015"], ["84043.6", "0"], ["84037.6", "0"]], "a": [["84118.1", "0.137532"], ["84161.9", "0.001466"], ["84165.5", "0.356836"], ["84172.3", "0"]], "u": 167949, "seq": 67577188646}, "cts": 1742584895699, "record_time": 1742584895.823227, "EXCHANGE": "BYBIT"}
{"topic": "orderbook.200.BTCUSDT", "ts": 1742584895919, "type": "delta", "data": {"s": "BTCUSDT", "b": [["84090.1", "0.055469"], ["84090", "0.05"], ["84084.3", "0.084939"], ["84069.2", "0.0991"], ["84069.1", "0.045087"], ["84067.6", "0"], ["84067.4", "0.01288"], ["84065.8", "0"], ["84065.6", "0.10894"], ["84063.2", "0"], ["84061.3", "0.496302"], ["84058", "0.005947"], ["84049.8", "16.102081"]], "a": [["84113.9", "0.002999"], ["84132.1", "0.11693"], ["84146.9", "0.04"], ["84147", "0.04"], ["84148.2", "0.000358"], ["84148.3", "0"], ["84163.4", "0.35684"], ["84165.5", "0"], ["84171.9", "0"], ["84172.1", "0"]], "u": 167950, "seq": 67577188697}, "cts": 1742584895916, "record_time": 1742584896.022413, "EXCHANGE": "BYBIT"}
{"topic": "orderbook.200.BTCUSDT", "ts": 1742584896120, "type": "delta", "data": {"s": "BTCUSDT", "b": [["84100.8", "0.632268"], ["84097.4", "0"], ["84091.4", "0.051333"], ["84066.9", "0.002129"], ["84061.4", "0.645193"], ["84061.3", "0"], ["84038.2", "0"]], "a": [], "u": 167951, "seq": 67577188733}, "cts": 1742584896116, "record_time": 1742584896.223289, "EXCHANGE": "BYBIT"}
{"topic": "orderbook.200.BTCUSDT", "ts": 1742584896319, "type": "delta", "data": {"s": "BTCUSDT", "b": [["84065.8", "0.05"], ["84065.6", "0.059399"], ["84061.5", "0.689861"], ["84061.4", "0"], ["84055.3", "16.076687"], ["84049.8", "0.023783"], ["84038.7", "0"]], "a": [], "u": 167952, "seq": 67577188785}, "cts": 1742584896307, "record_time": 1742584896.428479, "EXCHANGE": "BYBIT"}
{"topic": "orderbook.200.BTCUSDT", "ts": 1742584896520, "type": "delta", "data": {"s": "BTCUSDT", "b": [["84100.8", "0.803268"], ["84091.6", "0.124954"], ["84081.1", "0.168907"], ["84074.1", "0.297808"], ["84069.3", "0.04"], ["84069.1", "0.005458"], ["84067.6", "0.013"], ["84067.4", "0"], ["84063.7", "0"], ["84061.6", "0.703261"], ["84061.5", "0"], ["84050.8", "0.06"], ["84040.8", "0"], ["84040.3", "0"], ["84040", "0"], ["84039.7", "0"]], "a": [["84107.2", "0.000297"], ["84107.3", "0.071371"], ["84107.6", "0"], ["84108.3", "0"], ["84116.1", "0.120627"], ["84126.6", "0.178362"], ["84133.6", "0.275652"], ["84146.8", "0.04"], ["84147", "0"], ["84163.3", "0.356839"], ["84163.4", "0"], ["84170.5", "0"], ["84171.2", "0"], ["84171.5", "0"]], "u": 167953, "seq": 67577188842}, "cts": 1742584896460, "record_time": 1742584896.623696, "EXCHANGE": "BYBIT"}
{"topic": "orderbook.200.BTCUSDT", "ts": 1742584896720, "type": "delta", "data": {"s": "BTCUSDT", "b": [["84100.8", "0.543362"], ["84091.6", "0.110212"], ["84088.2", "0"], ["84087.3", "0.064"], ["84081.1", "0.182716"], ["84074.2", "0.161666"], ["84074.1", "0.287905"], ["84069.4", "0.041466"], ["84069.3", "0.039629"], ["84069.2", "0.059471"], ["84067.6", "0.01288"], ["84065.9", "0.109471"], ["84065.8", "0.049541"], ["84065.7", "0"], ["84063.2", "0.356837"], ["84061.6", "0"], ["84056.2", "0.00107"], ["84055.3", "0.0015"], ["84049.8", "16.09897"]], "a": [["84115.9", "0.071364"], ["84116.1", "0.114839"], ["84120.9", "0"], ["84126", "0.22798"], ["84126.6", "0.173774"], ["84133.6", "0.283335"], ["84146.7", "0.04"], ["84146.9", "0"], ["84154.6", "2.621114"], ["84157.4", "0.005184"], ["84163.3", "0"], ["84165.5", "0.356837"], ["84170.4", "0"]], "u": 167954, "seq": 67577188937}, "cts": 1742584896695, "record_time": 1742584896.823247, "EXCHANGE": "BYBIT"}
{"topic": "orderbook.200.BTCUSDT", "ts": 1742584896919, "type": "delta", "data": {"s": "BTCUSDT", "b": [["84069.8", "0"], ["84069.4", "0.001466"], ["84069.2", "0.0991"], ["84065.9", "0.059471"], ["84065.7", "0.049541"], ["84063.2", "0"], ["84061.3", "0.35684"], ["84052.5", "16.080852"], ["84049.8", "0.023783"], ["84041", "0"]], "a": [["84132.1", "0.187314"], ["84142.9", "1.426146"], ["84146.7", "0"], ["84146.9", "0.04"], ["84155", "0"], ["84163.4", "0.35684"], ["84165.5", "0"]], "u": 167955, "seq": 67577189000}, "cts": 1742584896904, "record_time": 1742584897.022368, "EXCHANGE": "BYBIT"}
{"topic": "orderbook.200.BTCUSDT", "ts": 1742584897120, "type": "delta", "data": {"s": "BTCUSDT", "b": [["84100.8", "0.714362"], ["84080.3", "0.220911"], ["84061.3", "0.356838"], ["84057.4", "0.064"], ["84041.5", "0"]], "a": [["84142.8", "0.772469"], ["84143.6", "0"], ["84146.7", "0.04"], ["84146.9", "0"], ["84155", "0.051461"], ["84163.4", "0"], ["84165.5", "0.356839"]], "u": 167956, "seq": 67577189069}, "cts": 1742584897116, "record_time": 1742584897.223417, "EXCHANGE": "BYBIT"}
{"topic": "orderbook.200.BTCUSDT", "ts": 1742584897319, "type": "delta", "data": {"s": "BTCUSDT", "b": [["84100.8", "0.543362"], ["84055.8", "0.092"], ["84052.5", "16.081678"], ["84050.6", "0.06"], ["84042", "0"], ["84041.6", "0"]], "a": [["84146.6", "0.040333"], ["84146.8", "0"], ["84152.1", "0.052061"], ["84155", "0"], ["84170.4", "0.002128"], ["84170.5", "3.589997"]], "u": 167957, "seq": 67577189114}, "cts": 1742584897315, "record_time": 1742584897.422257, "EXCHANGE": "BYBIT"}
{"topic": "orderbook.200.BTCUSDT", "ts": 1742584897520, "type": "delta", "data": {"s": "BTCUSDT", "b": [], "a": [["84154.6", "0"], ["84157.4", "2.626535"], ["84170.5", "3.760997"], ["84171.2", "0.002799"]], "u": 167958, "seq": 67577189143}, "cts": 1742584897454, "record_time": 1742584897.623601, "EXCHANGE": "BYBIT"}
{"topic": "orderbook.200.BTCUSDT", "ts": 1742584897720, "type": "delta", "data": {"s": "BTCUSDT", "b": [["84100.8", "0.714362"], ["84100.6", "0.000153"], ["84091.6", "0"], ["84087.8", "0.059197"], ["84087.5", "0.112688"], ["84081.1", "0"], ["84080.5", "0.178788"], ["84074.9", "0"], ["84074.1", "0"], ["84073.5", "0.274723"], ["84069.5", "0.003"], ["84063.2", "0.356835"], ["84061.3", "0"]], "a": [["84105.1", "0.034498"], ["84107.8", "0.129222"], ["84116.1", "0"], ["84117.6", "0.003"], ["84120.4", "0.115095"], ["84126.6", "0"], ["84127.4", "0.170033"], ["84133.6", "0"], ["84134.4", "0.305586"], ["84135.9", "0.003"], ["84170.5", "0"], ["84171.2", "0"]], "u": 167959, "seq": 67577189202}, "cts": 1742584897713, "record_time": 1742584897.823448, "EXCHANGE": "BYBIT"}
{"topic": "orderbook.200.BTCUSDT", "ts": 1742584897920, "type": "delta", "data": {"s": "BTCUSDT", "b": [["84100.8", "0.715432"], ["84083.2", "0.001466"], ["84063.2", "0"], ["84061.3", "0.356839"], ["84056.2", "0"], ["84052.5", "16.08188"], ["84042", "0.051423"]], "a": [], "u": 167960, "seq": 67577189224}, "cts": 1742584897890, "record_time": 1742584898.023409, "EXCHANGE": "BYBIT"}
{"topic": "orderbook.200.BTCUSDT", "ts": 1742584898120, "type": "delta", "data": {"s": "BTCUSDT", "b": [["84100.8", "0.544432"], ["84100.6", "0"], ["84077.6", "0"], ["84077.5", "0.06486"], ["84073.4", "0"], ["84065", "0"], ["84041.6", "0.001466"], ["84041.5", "0.000333"], ["84041", "0.000149"], ["84040.8", "0.001859"]], "a": [["84110.3", "0.023678"], ["84170.4", "0"]], "u": 167961, "seq": 67577189256}, "cts": 1742584898117, "record_time": 1742584898.223448, "EXCHANGE": "BYBIT"}
{"topic": "orderbook.200.BTCUSDT", "ts": 1742584898319, "type": "delta", "data": {"s": "BTCUSDT", "b": [["84100.8", "0.541877"], ["84078.9", "0"], ["84074.2", "0"], ["84066.8", "0.275765"], ["84052.5", "16.08168"], ["84040.3", "0.023784"], ["84040", "0.00006"]], "a": [["84146.6", "0.000333"], ["84146.7", "0"], ["84146.8", "0.04"], ["84146.9", "0.04"], ["84163.4", "0.356842"], ["84165.5", "0"], ["84170.3", "0"]], "u": 167962, "seq": 67577189321}, "cts": 1742584898305, "record_time": 1742584898.421669, "EXCHANGE": "BYBIT"}
{"topic": "orderbook.200.BTCUSDT", "ts": 1742584898520, "type": "delta", "data": {"s": "BTCUSDT", "b": [["84100.8", "0.712877"], ["84088.3", "0"], ["84063.2", "0.356838"], ["84061.3", "0"], ["84039.7", "0.005313"]], "a": [["84163.4", "0"], ["84165.5", "0.35684"]], "u": 167963, "seq": 67577189364}, "cts": 1742584898511, "record_time": 1742584898.623211, "EXCHANGE": "BYBIT"}
{"topic": "orderbook.200.BTCUSDT", "ts": 1742584898719, "type": "delta", "data": {"s": "BTCUSDT", "b": [["84100", "0.000213"], ["84077.6", "0.178357"], ["84073.4", "0.178357"], ["84069.4", "0.041466"], ["84069.2", "0.059471"], ["84067.7", "0.013"], ["84067.5", "0"], ["84065.9", "0.109471"], ["84065.7", "0"], ["84065", "0.089179"], ["84040", "0"], ["84039.7", "0"]], "a": [["84146.7", "0.04"], ["84146.9", "0"]], "u": 167964, "seq": 67577189403}, "cts": 1742584898696, "record_time": 1742584898.821932, "EXCHANGE": "BYBIT"}
{"topic": "orderbook.200.BTCUSDT", "ts": 1742584898919, "type": "delta", "data": {"s": "BTCUSDT", "b": [["84063.2", "0"], ["84061.3", "0.356839"]], "a": [["84110.3", "0"], ["84170.3", "0.040358"]], "u": 167965, "seq": 67577189436}, "cts": 1742584898864, "record_time": 1742584899.022108, "EXCHANGE": "BYBIT"}
{"topic": "orderbook.200.BTCUSDT", "ts": 1742584899120, "type": "delta", "data": {"s": "BTCUSDT", "b": [["84100", "0.00006"], ["84099.9", "0.000153"], ["84063.2", "0.356835"], ["84061.3", "0"], ["84040.3", "0"]], "a": [["84114", "0"], ["84170.4", "0.002128"]], "u": 167966, "seq": 67577189474}, "cts": 1742584899115, "record_time": 1742584899.221998, "EXCHANGE": "BYBIT"}
{"topic": "orderbook.200.BTCUSDT", "ts": 1742584899320, "type": "delta", "data": {"s": "BTCUSDT", "b": [["84100.8", "0.712077"], ["84073.8", "0.118539"], ["84063.3", "0.356835"], ["84063.2", "0"], ["84040.8", "0"]], "a": [["84110.6", "0.024377"], ["84170.4", "0"]], "u": 167967, "seq": 67577189538}, "cts": 1742584899315, "record_time": 1742584899.423515, "EXCHANGE": "BYBIT"}
{"topic": "orderbook.200.BTCUSDT", "ts": 1742584899519, "type": "delta", "data": {"s": "BTCUSDT", "b": [["84087.5", "0"], ["84080.5", "0"], ["84073.5", "0"], ["84063.4", "0.356835"], ["84063.3", "0"], ["84052.5", "16.081696"], ["84040.8", "0.001859"], ["84040.3", "0.023784"], ["84040", "0.00006"]], "a": [["84105.9", "0.071372"], ["84106.8", "0"], ["84107.3", "0"], ["84107.6", "0.000297"], ["84113.9", "0.001999"], ["84120.4", "0"], ["84127.4", "0"], ["84134.4", "0"], ["84165.5", "0.356833"], ["84170.4", "0.002128"], ["84170.5", "3.589997"], ["84171.2", "0.002799"]], "u": 167968, "seq": 67577189571}, "cts": 1742584899509, "record_time": 1742584899.622138, "EXCHANGE": "BYBIT"}
{"topic": "orderbook.200.BTCUSDT", "ts": 1742584899720, "type": "delta", "data": {"s": "BTCUSDT", "b": [["84100.8", "0.541077"], ["84099.9", "0"], ["84087.8", "0.056197"], ["84077.6", "0"], ["84069.4", "0.001466"], ["84069.2", "0.277457"], ["84067.7", "0"], ["84067.5", "0.01288"], ["84065.9", "0.059471"], ["84065.7", "0.049541"], ["84065", "0"], ["84063.4", "0"], ["84061.3", "0.35684"], ["84039.7", "0.005313"], ["84038.7", "0.023787"]], "a": [["84113.9", "0.000999"], ["84132.1", "0.11693"], ["84170.5", "3.760997"]], "u": 167969, "seq": 67577189594}, "cts": 1742584899701, "record_time": 1742584899.823547, "EXCHANGE": "BYBIT"}
{"topic": "orderbook.200.BTCUSDT", "ts": 1742584899919, "type": "delta", "data": {"s": "BTCUSDT", "b": [["84084.3", "0.084971"], ["84069.2", "0.0991"], ["84061.4", "0.356839"], ["84061.3", "0"], ["84052.5", "16.081694"], ["84047.6", "0.023781"], ["84038.7", "0"]], "a": [["84127.4", "0.118905"], ["84134.1", "0.004895"], ["84146.6", "0.040333"], ["84146.8", "0"], ["84165.4", "0.356839"], ["84165.5", "0"]], "u": 167970, "seq": 67577189653}, "cts": 1742584899912, "record_time": 1742584900.021856, "EXCHANGE": "BYBIT"}
{"topic": "orderbook.200.BTCUSDT", "ts": 1742584900120, "type": "delta", "data": {"s": "BTCUSDT", "b": [["84097.7", "0.139911"], ["84095.2", "0"], ["84093.8", "0.009225"], ["84073.1", "0.075476"], ["84061.4", "0"], ["84059.8", "0.356846"], ["84052.5", "0"], ["84047", "16.081694"], ["84038.7", "0.023787"]], "a": [["84105.9", "0"], ["84113.9", "0"], ["84115.9", "0"], ["84126.8", "0.003576"], ["84128", "0.37859"], ["84146.6", "0.000333"], ["84146.8", "0.04"], ["84161.9", "0.358312"], ["84165.4", "0"], ["84171.5", "0.353364"], ["84171.9", "0.000333"]], "u": 167971, "seq": 67577189704}, "cts": 1742584900117, "record_time": 1742584900.223444, "EXCHANGE": "BYBIT"}
{"topic": "orderbook.200.BTCUSDT", "ts": 1742584900320, "type": "delta", "data": {"s": "BTCUSDT", "b": [["84100.8", "0.540007"], ["84097", "0.027024"], ["84096.1", "0.019911"], ["84094.3", "0.019911"], ["84083.5", "0.003498"], ["84069.3", "0"], ["84069.2", "0.237828"], ["84068.6", "0.040158"], ["84068.5", "0.03963"], ["84067.6", "0"], ["84067.5", "0"], ["84066.9", "0.015009"], ["84066.8", "0.288645"], ["84065.8", "0"], ["84065.7", "0"], ["84065.1", "0.145896"], ["84065", "0.227899"], ["84059.9", "0.204895"], ["84057.7", "0.00107"], ["84049.8", "16.105477"], ["84047", "0"], ["84038.2", "0.005946"]], "a": [["84104.6", "0.00063"], ["84104.8", "0.022512"], ["84104.9", "0.075041"], ["84107.2", "0"], ["84113.7", "0.071366"], ["84126.8", "0"], ["84134.1", "0.001466"], ["84149.3", "0.051461"], ["84152.1", "0.0006"], ["84154.6", "2.621351"], ["84157.4", "0.005184"], ["84171.5", "0"], ["84171.9", "0"]], "u": 167972, "seq": 67577189769}, "cts": 1742584900317, "record_time": 1742584900.423284, "EXCHANGE": "BYBIT"}
{"topic": "orderbook.200.BTCUSDT", "ts": 1742584900520, "type": "delta", "data": {"s": "BTCUSDT", "b": [["84073.4", "0"], ["84060", "0.356908"], ["84059.8", "0"], ["84037.6", "0.118539"], ["84037.4", "0.000333"]], "a": [["84151.9", "2.623848"], ["84154.6", "0"], ["84171.5", "0.353364"]], "u": 167973, "seq": 67577189791}, "cts": 1742584900516, "record_time": 1742584900.623279, "EXCHANGE": "BYBIT"}
{"topic": "orderbook.200.BTCUSDT", "ts": 1742584900719, "type": "delta", "data": {"s": "BTCUSDT", "b": [["84068.7", "0.158539"], ["84068.5", "0"], ["84065.2", "0.05"], ["84065", "0.178357"], ["84061.3", "0.356846"], ["84060", "0.00006"], ["84059.9", "0"]], "a": [["84145.8", "0.04"], ["84145.9", "0.041333"], ["84146.7", "0"], ["84146.8", "0"], ["84161.9", "0.001466"], ["84163.4", "0.356846"]], "u": 167974, "seq": 67577189821}, "cts": 1742584900712, "record_time": 1742584900.821842, "EXCHANGE": "BYBIT"}
{"topic": "orderbook.200.BTCUSDT", "ts": 1742584900920, "type": "delta", "data": {"s": "BTCUSDT", "b": [["84067", "0.013"], ["84066.8", "0.275765"], ["84037.4", "0"]], "a": [["84100.9", "0.033146"], ["84163.4", "0.356845"]], "u": 167975, "seq": 67577189847}, "cts": 1742584900906, "record_time": 1742584901.023283, "EXCHANGE": "BYBIT"}
{"topic": "orderbook.200.BTCUSDT", "ts": 1742584901119, "type": "delta", "data": {"s": "BTCUSDT", "b": [["84100.8", "0.541877"], ["84099.3", "0.000153"], ["84073.4", "0.178357"], ["84065", "0"], ["84061.3", "0"], ["84059.8", "0.356846"], ["84057.7", "0"]], "a": [["84100.9", "0.00374"], ["84161.9", "0.358312"], ["84163.4", "0"], ["84171.9", "0.000333"]], "u": 167976, "seq": 67577189894}, "cts": 1742584901116, "record_time": 1742584901.222055, "EXCHANGE": "BYBIT"}
{"success": true, "ret_msg": "pong", "conn_id": "db9a9825-b0cd-4231-ad46-55f33c5e50d2", "op": "ping", "record_time": 1742584901.42119, "EXCHANGE": "BYBIT"}
{"topic": "orderbook.200.BTCUSDT", "ts": 1742584901320, "type": "delta", "data": {"s": "BTCUSDT", "b": [["84100.8", "0.522921"], ["84100.3", "0.192083"], ["84099.3", "0"], ["84093.8", "0"], ["84091.4", "0"], ["84090.4", "0"], ["84088.8", "0"], ["84086.8", "0"], ["84086.3", "0"], ["84083.6", "0.000333"], ["84081.8", "0.128131"], ["84079.4", "0.000333"], ["84077.5", "0.005461"], ["84073.4", "0"], ["84069.2", "0.059471"], ["84068.7", "0.118539"], ["84068.6", "0.000528"], ["84068.5", "0.03963"], ["84068.4", "0.03963"], ["84067", "0"], ["84066.9", "0.002129"], ["84066.8", "0.288645"], ["84066.7", "0.35837"], ["84065.2", "0"], ["84065.1", "0.096354"], ["84065", "0.049542"], ["84064.9", "0.054869"], ["84064.6", "0"], ["84063.2", "0.356837"], ["84059.9", "0.204895"], ["84059.8", "0"], ["84058.4", "0"], ["84056.1", "0.090024"], ["84050.5", "0.169177"], ["84049.8", "0.023783"], ["84049.4", "0"], ["84044", "0"], ["84037.4", "0.000333"], ["84037.3", "0.000333"], ["84037", "0.025371"], ["84036.6", "0.001333"], ["84036.2", "0.000526"], ["84035.9", "0.039551"], ["84035.8", "16.096696"], ["84035.5", "0.005313"], ["84035.3", "0.001189"]], "a": [["84104.8", "0"], ["84104.9", "0.003668"], ["84106.1", "0.071372"], ["84112.1", "0.019226"], ["84113.6", "0.059399"], ["84118.4", "0.180236"], ["84123.8", "0.005452"], ["84124.7", "0"], ["84128", "0.200233"], ["84130.9", "0"], ["84132.2", "0.005472"], ["84145.8", "0"], ["84145.9", "0.001333"], ["84146.2", "0.04"], ["84146.3", "0.04"], ["84149.1", "0"], ["84151.9", "0.002497"], ["84154.6", "2.621351"], ["84161.9", "0.001466"], ["84165.5", "0.35684"], ["84170.1", "0.005184"], ["84171.5", "0"], ["84171.9", "0"]], "u": 167977, "seq": 67577190204}, "cts": 1742584901316, "record_time": 1742584901.423191, "EXCHANGE": "BYBIT"}
{"topic": "orderbook.200.BTCUSDT", "ts": 1742584901519, "type": "delta", "data": {"s": "BTCUSDT", "b": [["84100.8", "0.47668"], ["84100.4", "0.108383"], ["84090", "0"], ["84088.8", "0.05"], ["84088.1", "0"], ["84087.4", "0.176639"], ["84087.3", "0.175677"], ["84087", "0"], ["84086", "0"], ["84085.9", "0.005461"], ["84085.8", "0.05"], ["84083.5", "0.053498"], ["84083.3", "0.05"], ["84082.3", "0"], ["84081.4", "0.032846"], ["84068.8", "0.04"], ["84068.7", "0.158169"], ["84068.5", "0"], ["84068.4", "0"], ["84067.1", "0.131943"], ["84067", "0.01288"], ["84066.8", "0.275765"], ["84066.7", "0.34549"], ["84065.3", "0.168942"], ["84065.2", "0.049541"], ["84065", "0"], ["84064.9", "0.005327"], ["84063.2", "0"], ["84061.3", "0.356843"], ["84059.9", "0"], ["84054.4", "0.048"], ["84052.7", "0.064"], ["84051", "0.128"], ["84049.3", "0.06"], ["84048.3", "0.178357"], ["84041.5", "16.082029"], ["84037.4", "0.125183"], ["84035.9", "0"], ["84035.8", "0"], ["84035.5", "0"], ["84035.3", "0"]], "a": [["84100.9", "0.033052"], ["84104.6", "0.000333"], ["84106.1", "0"], ["84107.1", "0.000297"], ["84107.8", "0.130222"], ["84113.7", "0"], ["84115.9", "0.071364"], ["84118.2", "0.04"], ["84122", "0.053166"], ["84132.1", "0.063423"], ["84145.5", "0.04"], ["84145.6", "0.158539"], ["84146.2", "0"], ["84146.3", "0"], ["84151.9", "2.623848"], ["84154.6", "0"], ["84163.4", "0.356839"], ["84165.5", "0"], ["84171.5", "0.353364"], ["84171.9", "0.000333"]], "u": 167978, "seq": 67577190375}, "cts": 1742584901515, "record_time": 1742584901.621974, "EXCHANGE": "BYBIT"}
{"topic": "orderbook.200.BTCUSDT", "ts": 1742584901720, "type": "delta", "data": {"s": "BTCUSDT", "b": [["84100.8", "0.478108"], ["84089.8", "0.094018"], ["84088.8", "0"], ["84087", "0.05"], ["84083.5", "0.003498"], ["84083.1", "0.05"], ["84069.5", "0"], ["84069.2", "0.237828"], ["84068.9", "0.04"], ["84068.8", "0.03963"], ["84068.7", "0.118539"], ["84067.2", "0.064423"], ["84067.1", "0.131823"], ["84067", "0"], ["84066.9", "0"], ["84065.4", "0.05"], ["84065.3", "0.168483"], ["84065.2", "0"], ["84065", "0.178357"], ["84061.4", "0.356844"], ["84061.3", "0"], ["84049.8", "16.105479"], ["84049.3", "0.12"], ["84044", "0.089179"], ["84041.5", "0.000333"], ["84036.2", "0"]], "a": [["84100.9", "0.039052"], ["84105.1", "0.031498"], ["84119.6", "0.183809"], ["84123.8", "0.183809"], ["84145.4", "0.052"], ["84145.6", "0.118539"], ["84149.1", "0.089179"], ["84161.9", "0.35831"], ["84163.4", "0"], ["84170.1", "0.094363"]], "u": 167979, "seq": 67577190473}, "cts": 1742584901714, "record_time": 1742584901.821834, "EXCHANGE": "BYBIT"}
{"topic": "orderbook.200.BTCUSDT", "ts": 1742584901920, "type": "delta", "data": {"s": "BTCUSDT", "b": [["84092.3", "0.260765"], ["84090.1", "0.005469"], ["84089.2", "0.178382"], ["84087.5", "0.178386"], ["84087", "0.1"], ["84085.9", "0.18385"], ["84084.3", "0.06"], ["84081.5", "0.024963"], ["84081.1", "0.178357"], ["84068.9", "0"], ["84068.8", "0"], ["84068.7", "0.158169"], ["84068.6", "0.040158"], ["84067.2", "0.051423"], ["84067.1", "0.131943"], ["84067", "0.01288"], ["84065.4", "0"], ["84065.3", "0.168942"], ["84065.2", "0.049541"], ["84061.4", "0"], ["84061.3", "0.356848"], ["84052.5", "15.450184"], ["84049.8", "0.023783"], ["84048.3", "0"], ["84047.2", "0.178471"], ["84037.4", "0"], ["84037.3", "0"], ["84037", "0"], ["84036.6", "0"]], "a": [["84145.4", "0.012"], ["84145.5", "0"], ["84145.8", "0.04"], ["84145.9", "0.041333"]], "u": 167980, "seq": 67577190542}, "cts": 1742584901916, "record_time": 1742584902.023159, "EXCHANGE": "BYBIT"}
{"topic": "orderbook.200.BTCUSDT", "ts": 1742584902120, "type": "delta", "data": {"s": "BTCUSDT", "b": [["84100.8", "0.47334"], ["84087.6", "0.309683"], ["84087.4", "0"], ["84081.5", "0"], ["84081.3", "0.074874"], ["84074.1", "0.059399"], ["84073.8", "0"], ["84068.8", "0.04"], ["84068.6", "0.000528"], ["84067.4", "0.013"], ["84067.3", "0.01288"], ["84067.1", "0.118943"], ["84067", "0"], ["84061.3", "0"], ["84059.8", "0.35685"], ["84058.4", "0.12485"], ["84038.2", "0"], ["84037.6", "0"]], "a": [["84117", "0.118539"], ["84125.9", "0.118539"], ["84145.5", "0.04"], ["84145.6", "0.158539"], ["84145.8", "0"], ["84145.9", "0.001333"], ["84171.5", "0"], ["84171.9", "0"]], "u": 167981, "seq": 67577190609}, "cts": 1742584902109, "record_time": 1742584902.223244, "EXCHANGE": "BYBIT"}
{"topic": "orderbook.200.BTCUSDT", "ts": 1742584902319, "type": "delta", "data": {"s": "BTCUSDT", "b": [["84100.8", "0.153048"], ["84100.4", "0"], ["84100.3", "0.000795"], ["84099.5", "0"], ["84097.7", "0"], ["84097", "0.007113"], ["84096.1", "0"], ["84095.1", "0"], ["84094.9", "0"], ["84094.3", "0"], ["84094.2", "0"], ["84091.9", "0.133101"], ["84091.2", "0.190911"], ["84090.9", "0"], ["84090.7", "0"], ["84089.8", "0.042685"], ["84089.2", "0"], ["84089.1", "0"], ["84088.8", "0.071387"], ["84088.7", "0.019911"], ["84087.6", "0"], ["84087.5", "0"], ["84087.3", "0.064"], ["84087.1", "0.145695"], ["84086.2", "0"], ["84085.9", "0.005461"], ["84083.9", "0.06"], ["84083.5", "0"], ["84083.4", "0.051333"], ["84083.3", "0"], ["84083.1", "0"], ["84082.9", "0.051333"], ["84082.5", "0.05"], ["84082", "0.05459"], ["84081.8", "0.009225"], ["84081.4", "0"], ["84081.1", "0"], ["84080.1", "0"], ["84079.9", "0"], ["84075", "0.054568"], ["84070.2", "0.527867"], ["84069.2", "0.059471"], ["84068.9", "0.04"], ["84068.8", "0.03963"], ["84068.7", "0"], ["84068", "0.124196"], ["84067.4", "0"], ["84067.3", "0"], ["84067.2", "0.01297"], ["84067.1", "0.131823"], ["84065.5", "0.049541"], ["84065.4", "0.049541"], ["84065.3", "0.118942"], ["84065.2", "0"], ["84065.1", "0"], ["84065", "0.766354"], ["84063.1", "0"], ["84060.8", "0.178357"], ["84059.8", "0"], ["84058.8", "0.181627"], ["84056.6", "0.178357"], ["84054.2", "0"], ["84052.8", "0"], ["84052.5", "0"], ["84051.2", "3.682076"], ["84047.2", "0"], ["84043", "0.356891"], ["84041.5", "15.450517"], ["84038.2", "0.005946"], ["84037.6", "0.118539"], ["84037.4", "0.125183"], ["84037.3", "0.000333"], ["84037", "0.025371"], ["84036.6", "0.001333"], ["84036.2", "0.000526"], ["84035.9", "0.039551"], ["84035.8", "0.015"], ["84035.5", "0.005313"], ["84035.3", "0.001189"], ["84034", "0.071243"], ["84033.6", "0.00009"], ["84033.5", "1.783573"], ["84033.1", "1.179392"], ["84032.9", "0.023787"], ["84032.7", "0.000358"], ["84032.4", "0.002799"], ["84031.8", "0.320756"], ["84031.6", "0.000526"], ["84031.5", "0.118539"]], "a": [["84100.9", "0.465549"], ["84109", "0.07137"], ["84109.2", "0.095789"], ["84109.9", "0.001"], ["84110", "0.071369"], ["84111.2", "0.183802"], ["84113.5", "0.142807"], ["84113.6", "0.110732"], ["84114.1", "0"], ["84115.9", "0"], ["84117", "0.177412"], ["84121.5", "0"], ["84123.8", "0.005452"], ["84124", "0.060087"], ["84127.4", "0"], ["84128.3", "0"], ["84130.6", "0.536105"], ["84131", "0.110468"], ["84133.3", "0.026147"], ["84141.2", "0.02979"], ["84143.6", "0.051461"], ["84143.7", "0.024382"], ["84145.2", "0.04"], ["84145.3", "0.0415"], ["84145.5", "0"], ["84145.6", "0.118539"], ["84148.1", "0"], ["84149", "0.362368"], ["84149.3", "0"], ["84150.6", "0.02206"], ["84151.9", "0.002497"], ["84161.9", "0.001466"], ["84168.2", "1.796642"], ["84170.2", "0"], ["84171.2", "0"]], "u": 167982, "seq": 67577190837}, "cts": 1742584902318, "record_time": 1742584902.423432, "EXCHANGE": "BYBIT"}
{"topic": "orderbook.200.BTCUSDT", "ts": 1742584902520, "type": "delta", "data": {"s": "BTCUSDT", "b": [["84100.8", "0.161494"], ["84100.3", "0"], ["84092.3", "0.179481"], ["84091.2", "0.262296"], ["84091", "0"], ["84089.4", "0"], ["84088.8", "0"], ["84087.5", "0.001"], ["84087.1", "0.227801"], ["84087", "0.05"], ["84086.5", "0.064"], ["84085.8", "0"], ["84085.7", "0.05"], ["84085", "0.092"], ["84084.4", "0"], ["84084.3", "0"], ["84084", "0.343717"], ["84083.6", "0.050333"], ["84082.5", "0"], ["84082", "0"], ["84081.8", "0.120901"], ["84081.7", "0.183859"], ["84080.8", "0.009467"], ["84080", "0.178462"], ["84079.9", "0.06"], ["84079.8", "0.06"], ["84077.5", "0.035435"], ["84077.4", "0.228318"], ["84076.8", "0.035678"], ["84076.2", "0.018516"], ["84076", "0.178357"], ["84075", "0"], ["84068.9", "0"], ["84068.8", "0"], ["84068.7", "0.03963"], ["84068.6", "0.040158"], ["84068", "0"], ["84067.2", "0.00009"], ["84067.1", "0"], ["84067", "0.01288"], ["84066.9", "0.01288"], ["84065.5", "0"], ["84065.4", "0"], ["84065.2", "0.049541"], ["84065.1", "0.168081"], ["84065", "0.587997"], ["84060.8", "0"], ["84056.6", "0"], ["84052.8", "0.356886"], ["84043", "0"], ["84038.7", "0.202276"], ["84035.9", "0.011844"], ["84034.2", "0.171"], ["84031.3", "0.005313"], ["84030.7", "0.120492"]], "a": [["84107.8", "0.18385"], ["84108.7", "0.08"], ["84110.5", "0.04"], ["84111.2", "0.005445"], ["84113.5", "0.221656"], ["84114", "0.04"], ["84114.2", "0"], ["84115.3", "0.0415"], ["84115.4", "0.236223"], ["84116.2", "0.003576"], ["84116.4", "0"], ["84117", "0.118539"], ["84118.2", "0"], ["84123", "0.000118"], ["84123.1", "0"], ["84124", "0"], ["84126", "0.137579"], ["84131", "0"], ["84133.3", "0.001863"], ["84138", "0.051991"], ["84139.3", "0.283779"], ["84141.2", "0.005445"], ["84143.6", "0"], ["84149", "0.005477"], ["84150.3", "0.024284"], ["84150.7", "0"], ["84151.5", "0.356885"], ["84160.6", "0"], ["84170.1", "0.005184"], ["84171.2", "0.002799"], ["84171.5", "0.353364"]], "u": 167983, "seq": 67577191068}, "cts": 1742584902516, "record_time": 1742584902.623236, "EXCHANGE": "BYBIT"}
{"topic": "orderbook.200.BTCUSDT", "ts": 1742584902719, "type": "delta", "data": {"s": "BTCUSDT", "b": [["84100.8", "0.232871"], ["84093.4", "0.071383"], ["84087.1", "0.156413"], ["84087", "0"], ["84086.4", "0.05"], ["84082.9", "0.001333"], ["84081.3", "0.049911"], ["84079", "0.024704"], ["84077.5", "0.154975"], ["84069.2", "0.237828"], ["84066.2", "0.04954"], ["84066.1", "0.04954"], ["84065.2", "0"], ["84065.1", "0.118539"], ["84065", "0.766354"], ["84052.9", "0.356883"], ["84052.8", "0"], ["84044.2", "15.450184"], ["84041.5", "0.000333"], ["84031.6", "0"], ["84031.5", "0"], ["84031.3", "0"], ["84030.7", "0"]], "a": [["84109.2", "0.169555"], ["84110", "0.189908"], ["84110.3", "0.04"], ["84111.2", "0.183802"], ["84112.1", "0.059226"], ["84115.8", "0"], ["84118.3", "0"], ["84118.8", "0"], ["84119.6", "0.005452"], ["84128", "0.289412"], ["84138", "2.673342"], ["84147.5", "0.013994"], ["84151.4", "0.37731"], ["84151.5", "0"], ["84171.9", "0.000333"], ["84172.1", "0.04"]], "u": 167984, "seq": 67577191171}, "cts": 1742584902714, "record_time": 1742584902.822602, "EXCHANGE": "BYBIT"}
{"topic": "orderbook.200.BTCUSDT", "ts": 1742584902919, "type": "delta", "data": {"s": "BTCUSDT", "b": [["84087.6", "0.001"], ["84079", "0"], ["84078.8", "0.024931"], ["84074.2", "0.043771"], ["84069.5", "0.04"], ["84069.4", "0.041095"], ["84068.7", "0"], ["84068.6", "0.000528"], ["84067.8", "0.013"], ["84067.7", "0.01288"], ["84067", "0"], ["84066.9", "0"], ["84066.2", "0"], ["84066.1", "0"], ["84066", "0.051333"], ["84065.9", "0.109012"], ["84053", "0.356883"], ["84052.9", "0"], ["84052.3", "0.031039"], ["84044.2", "14.822967"], ["84036.2", "0.024773"]], "a": [["84100.9", "0.471549"], ["84112.2", "0.04"], ["84117.1", "0"], ["84117.6", "0.075171"], ["84118.1", "0"], ["84136", "0.022836"], ["84138", "0.051991"], ["84142.1", "0.04"], ["84142.2", "0.04"], ["84145.2", "0"], ["84145.3", "0.0015"], ["84149.1", "2.71053"], ["84150.6", "0"], ["84151.4", "0.020426"], ["84153.4", "0.356882"], ["84159.2", "1.052626"], ["84172.1", "0"]], "u": 167985, "seq": 67577191264}, "cts": 1742584902917, "record_time": 1742584903.022396, "EXCHANGE": "BYBIT"}
{"topic": "orderbook.200.BTCUSDT", "ts": 1742584903119, "type": "delta", "data": {"s": "BTCUSDT", "b": [["84093.4", "0"], ["84088.5", "0.071387"], ["84087.7", "0.001"], ["84080.9", "0"], ["84073.5", "0.178357"], ["84069.6", "0.04"], ["84069.5", "0.039629"], ["84069.4", "0.001466"], ["84067.9", "0.013"], ["84067.8", "0.01288"], ["84067.7", "0"], ["84066.8", "0.438446"], ["84066.1", "0.05"], ["84066", "0.050874"], ["84065.9", "0.059471"], ["84053.1", "0.356882"], ["84053", "0"], ["84036.2", "0.000526"], ["84032.7", "0"], ["84032.4", "0"], ["84031.8", "0"]], "a": [["84110", "0.071369"], ["84141.7", "0.100832"], ["84141.8", "0.04"], ["84142.1", "0"], ["84142.2", "0"], ["84142.8", "0.051333"], ["84153.3", "0.356882"], ["84153.4", "0"], ["84172.1", "0.04"]], "u": 167986, "seq": 67577191369}, "cts": 1742584903116, "record_time": 1742584903.223339, "EXCHANGE": "BYBIT"}
{"topic": "orderbook.200.BTCUSDT", "ts": 1742584903320, "type": "delta", "data": {"s": "BTCUSDT", "b": [["84074.2", "0.091806"], ["84069.6", "0"], ["84069.4", "0.041095"], ["84067.9", "0"], ["84067.7", "0.01288"], ["84066.1", "0"], ["84066", "0.051333"], ["84065.9", "0.109012"], ["84053.1", "0"], ["84051.4", "0.356885"], ["84047.9", "0.023271"], ["84032.7", "0.000358"]], "a": [["84100.9", "0.473333"], ["84141.7", "0.060832"], ["84141.8", "0"], ["84141.9", "0.04"], ["84142", "0.04"], ["84153.2", "0.362069"], ["84153.3", "0"]], "u": 167987, "seq": 67577191434}, "cts": 1742584903311, "record_time": 1742584903.422149, "EXCHANGE": "BYBIT"}
{"topic": "orderbook.200.BTCUSDT", "ts": 1742584903519, "type": "delta", "data": {"s": "BTCUSDT", "b": [["84094.2", "0.050782"], ["84093.4", "0.071383"], ["84092.7", "0.0026"], ["84088.5", "0"], ["84070.8", "0"], ["84070.3", "0.118539"], ["84068.1", "0.013"], ["84068", "0.01288"], ["84067.8", "0"], ["84067.7", "0"], ["84066.3", "0.05"], ["84066.2", "0.04954"], ["84066", "0.001333"], ["84065.9", "0.059471"], ["84064", "0.0016"], ["84051.5", "0.383285"], ["84051.4", "0"], ["84033.5", "0"], ["84033.1", "0"], ["84032.9", "0"], ["84032.7", "0"]], "a": [["84100.9", "0.479333"], ["84113.5", "0.142807"], ["84117", "0"], ["84137.1", "0.035678"], ["84139.2", "0.359621"], ["84140.5", "0"], ["84141.2", "0"], ["84141.9", "0"], ["84142.1", "0.04"], ["84148.9", "0.04"], ["84153.1", "0.356882"], ["84153.2", "0.005184"], ["84172.1", "0"]], "u": 167988, "seq": 67577191510}, "cts": 1742584903510, "record_time": 1742584903.643204, "EXCHANGE": "BYBIT"}
{"topic": "orderbook.200.BTCUSDT", "ts": 1742584903720, "type": "delta", "data": {"s": "BTCUSDT", "b": [["84073.5", "0"], ["84068.1", "0"], ["84067.9", "0.01288"], ["84066.3", "0"], ["84066.1", "0.04954"], ["84055.3", "0.358374"], ["84051.5", "0.0264"], ["84047.9", "0"], ["84033.5", "1.783573"], ["84033.1", "1.179392"]], "a": [["84116.2", "0"], ["84117.6", "0.072171"], ["84120.8", "0.120339"], ["84124.3", "0.001091"], ["84153.1", "0"], ["84156.9", "0.356879"]], "u": 167989, "seq": 67577191589}, "cts": 1742584903716, "record_time": 1742584903.822599, "EXCHANGE": "BYBIT"}
{"topic": "orderbook.200.BTCUSDT", "ts": 1742584903919, "type": "delta", "data": {"s": "BTCUSDT", "b": [["84074.2", "0.043771"], ["84070.3", "0"], ["84069.7", "0.04"], ["84069.6", "0.039629"], ["84069.5", "0"], ["84069.4", "0.001466"], ["84056.3", "0.096364"], ["84056.1", "0"], ["84055.3", "0.0015"], ["84054.5", "0.356877"], ["84054.1", "0.025195"], ["84053.3", "0.090022"], ["84044.2", "14.735906"], ["84033.5", "0"], ["84033.1", "0"]], "a": [["84124.3", "0.001095"], ["84141.2", "0.04"], ["84141.3", "0.04"], ["84142", "0"], ["84142.1", "0"]], "u": 167990, "seq": 67577191625}, "cts": 1742584903908, "record_time": 1742584904.022593, "EXCHANGE": "BYBIT"}
{"topic": "orderbook.200.BTCUSDT", "ts": 1742584904120, "type": "delta", "data": {"s": "BTCUSDT", "b": [["84071", "0.314289"], ["84069.8", "0.04"], ["84069.7", "0.039629"], ["84069.6", "0"], ["84068.1", "0.013"], ["84067.9", "0"], ["84066.3", "0.05"], ["84066.1", "0"], ["84054.5", "0"], ["84053.4", "0.358213"], ["84033.5", "1.783573"]], "a": [["84121.5", "0.003576"], ["84124.3", "0"], ["84141.1", "0.04"], ["84141.3", "0"]], "u": 167991, "seq": 67577191660}, "cts": 1742584904115, "record_time": 1742584904.223235, "EXCHANGE": "BYBIT"}
{"topic": "orderbook.200.BTCUSDT", "ts": 1742584904320, "type": "delta", "data": {"s": "BTCUSDT", "b": [["84069.8", "0"], ["84069.7", "0"], ["84069.5", "0.04"], ["84069.4", "0.041095"], ["84068.1", "0"], ["84068", "0"], ["84067.8", "0.013"], ["84067.7", "0.01288"], ["84066.3", "0"], ["84066.2", "0"], ["84066", "0.051333"], ["84065.9", "0.109012"], ["84033.1", "1.179392"], ["84032.9", "0.023787"], ["84032.7", "0.000358"]], "a": [["84117.6", "0.099784"], ["84124.3", "0.001093"], ["84136", "0"], ["84140.3", "0.141408"], ["84141.1", "0"], ["84141.2", "0"], ["84142", "0.04"], ["84142.1", "0.04"], ["84153.4", "0.356881"], ["84156.9", "0"]], "u": 167992, "seq": 67577191709}, "cts": 1742584904316, "record_time": 1742584904.423366, "EXCHANGE": "BYBIT"}
{"topic": "orderbook.200.BTCUSDT", "ts": 1742584904519, "type": "delta", "data": {"s": "BTCUSDT", "b": [["84080.3", "0.244565"], ["84069.5", "0"], ["84069.3", "0.039629"], ["84067.8", "0"], ["84067.6", "0.01288"], ["84066.3", "0.05"], ["84066.2", "0.04954"], ["84066", "0.001333"], ["84065.9", "0.059471"], ["84054.5", "0.356879"], ["84053.4", "0.001333"], ["84033.1", "0"], ["84032.9", "0"], ["84032.7", "0"]], "a": [["84100.9", "0.459244"], ["84124.3", "0"], ["84142", "0"], ["84142.1", "0"], ["84142.3", "0.04"], ["84142.4", "0.040333"], ["84153.4", "0"], ["84156.9", "0.356881"], ["84172.1", "0.04"], ["84172.3", "0.04"]], "u": 167993, "seq": 67577191784}, "cts": 1742584904515, "record_time": 1742584904.621743, "EXCHANGE": "BYBIT"}
{"topic": "orderbook.200.BTCUSDT", "ts": 1742584904719, "type": "delta", "data": {"s": "BTCUSDT", "b": [["84100.8", "0.232071"], ["84091.9", "0.11319"], ["84069.8", "0.04"], ["84069.7", "0.039629"], ["84069.4", "0.001466"], ["84069.3", "0"], ["84068.1", "0.013"], ["84068", "0.01288"], ["84067.7", "0"], ["84067.6", "0"], ["84054.5", "0"], ["84053.4", "0.358214"], ["84041", "0"], ["84036.6", "0.001482"], ["84033.1", "1.179392"]], "a": [["84130.5", "0.224642"], ["84132.1", "0"], ["84140.9", "0.04"], ["84141", "0.04"], ["84142.3", "0"], ["84142.4", "0.000333"], ["84150.3", "0.024429"], ["84154.9", "0"], ["84156.8", "0.356971"], ["84156.9", "0"], ["84172.4", "0.027807"]], "u": 167994, "seq": 67577191847}, "cts": 1742584904717, "record_time": 1742584904.821869, "EXCHANGE": "BYBIT"}
{"topic": "orderbook.200.BTCUSDT", "ts": 1742584904920, "type": "delta", "data": {"s": "BTCUSDT", "b": [["84100.8", "0.121706"], ["84094.2", "0"], ["84093.4", "0"], ["84092.5", "0.001763"], ["84092.4", "0.06"], ["84092.3", "0.171"], ["84091.2", "0"], ["84090.2", "0.071386"], ["84088.7", "0"], ["84087.7", "0.072388"], ["84087.1", "0.109695"], ["84086.9", "0.006074"], ["84086.4", "0.002707"], ["84085.5", "0.064"], ["84084", "0.00009"], ["84083.4", "0"], ["84081.7", "0.005461"], ["84081.3", "0.019911"], ["84080.3", "0.214565"], ["84080", "0.00006"], ["84079.7", "0"], ["84077.4", "0.049911"], ["84076.8", "0.051333"], ["84076.7", "0.035679"], ["84076", "0"], ["84073.5", "0.178357"], ["84069.8", "0"], ["84069.7", "0"], ["84069.2", "0"], ["84068.1", "0"], ["84068", "0"], ["84066.3", "0"], ["84066.2", "0"], ["84065.2", "0.039633"], ["84065.1", "0.039633"], ["84065", "0.587997"], ["84063.5", "0.012881"], ["84063.4", "0.012881"], ["84061.7", "0.049546"], ["84061.6", "0.049546"], ["84058.6", "0.024066"], ["84054.1", "0.000333"], ["84053.4", "0.001333"], ["84053.3", "0"], ["84052.3", "0.005326"], ["84047.6", "0.1138"], ["84046.1", "0.356902"], ["84044.2", "0"], ["84033.2", "14.735906"], ["84032.9", "0.023787"], ["84032.7", "0.000358"], ["84032.4", "0.002799"], ["84031.8", "0.320756"], ["84031.6", "0.000526"]], "a": [["84100.9", "0.643062"], ["84103.9", "0.010558"], ["84107.1", "0.05163"], ["84107.5", "0.001"], ["84108.4", "0.02378"], ["84109.2", "0.187583"], ["84111.2", "0.005445"], ["84113.4", "0.118539"], ["84113.5", "0"], ["84113.6", "0.059399"], ["84119.6", "0.183809"], ["84121.5", "0"], ["84124.2", "0.000978"], ["84138", "2.673342"], ["84138.3", "0"], ["84140.9", "0"], ["84141", "0"], ["84141.3", "0.04"], ["84141.4", "0.04"], ["84145.2", "0.024284"], ["84148.7", "0.02206"], ["84148.8", "0.356907"], ["84149.1", "0.089179"], ["84150.3", "0.000145"], ["84156.8", "0.00009"], ["84171.9", "0"], ["84172.1", "0"], ["84172.3", "0"], ["84172.4", "0"]], "u": 167995, "seq": 67577192132}, "cts": 1742584904917, "record_time": 1742584905.023372, "EXCHANGE": "BYBIT"}
{"topic": "orderbook.200.BTCUSDT", "ts": 1742584905119, "type": "delta", "data": {"s": "BTCUSDT", "b": [["84100.8", "0.13657"], ["84078.8", "0"], ["84078.2", "0.178405"], ["84077.5", "0.035435"], ["84076.6", "0.178409"], ["84071", "0.156122"], ["84046.1", "0"], ["84044.1", "0.356911"], ["84035.9", "14.747927"], ["84033.2", "0"]], "a": [["84100.9", "0.664"], ["84113.9", "0.055115"], ["84115.4", "0.057866"], ["84117.6", "0.148767"], ["84119.6", "0.005452"], ["84132.5", "2.621351"], ["84138", "0.051991"], ["84141.3", "0"], ["84141.4", "0"], ["84141.5", "0.04"], ["84141.6", "0.04"], ["84151.9", "0"], ["84171.5", "0"]], "u": 167996, "seq": 67577192204}, "cts": 1742584905115, "record_time": 1742584905.221841, "EXCHANGE": "BYBIT"}
{"topic": "orderbook.200.BTCUSDT", "ts": 1742584905319, "type": "delta", "data": {"s": "BTCUSDT", "b": [["84100.8", "0.03118"], ["84098.4", "0.071379"], ["84092.3", "0"], ["84090.2", "0"], ["84084.8", "0.07139"], ["84071", "0.334479"], ["84066", "0.006008"], ["84065.2", "0"], ["84065.1", "0"], ["84064.7", "0.0411"], ["84064.6", "0.039634"], ["84063.5", "0"], ["84063.4", "0"], ["84063", "0.013"], ["84062.9", "0.012881"], ["84061.8", "0.051333"], ["84061.6", "0"], ["84056.6", "0.178357"], ["84044.1", "0"], ["84043", "0.356916"], ["84035.9", "0.011844"], ["84031.5", "0.118539"]], "a": [["84100.9", "0.701842"], ["84103.9", "0.001333"], ["84106.3", "0.071372"], ["84106.5", "0.000999"], ["84106.9", "0.274438"], ["84107", "0.183802"], ["84107.8", "0.001"], ["84110", "0"], ["84111.2", "0.183802"], ["84112.1", "0.04"], ["84113.5", "0.08763"], ["84113.9", "0"], ["84117.6", "0"], ["84124.2", "0"], ["84126.7", "0.024284"], ["84127.3", "0.587935"], ["84129.8", "2.621684"], ["84132.5", "0"], ["84140.6", "0.005473"], ["84145.2", "0"], ["84145.5", "0.356916"], ["84148.8", "0"]], "u": 167997, "seq": 67577192406}, "cts": 1742584905313, "record_time": 1742584905.422604, "EXCHANGE": "BYBIT"}
{"topic": "orderbook.200.BTCUSDT", "ts": 1742584905520, "type": "delta", "data": {"s": "BTCUSDT", "b": [["84100.8", "0.031081"], ["84092.7", "0"], ["84092.5", "0.004363"], ["84090.4", "0.071386"], ["84086.4", "0.002587"], ["84084.8", "0"], ["84064", "0"], ["84063.8", "0.0016"], ["84060.8", "0.178357"], ["84044.1", "0.356915"], ["84043", "0"], ["84033.2", "14.736083"], ["84031.5", "0"]], "a": [["84107.8", "0"], ["84118.3", "0.092979"], ["84124.3", "0.001093"], ["84139.2", "0"], ["84140.3", "0.118539"], ["84144.6", "0.02316"], ["84145.5", "0"], ["84148.8", "0.356915"], ["84171.2", "0"]], "u": 167998, "seq": 67577192504}, "cts": 1742584905516, "record_time": 1742584905.622559, "EXCHANGE": "BYBIT"}
{"topic": "orderbook.200.BTCUSDT", "ts": 1742584905719, "type": "delta", "data": {"s": "BTCUSDT", "b": [["84100.8", "0"], ["84100", "0"], ["84098.4", "0"], ["84097", "0"], ["84096.2", "0"], ["84095.8", "0.075316"], ["84094.1", "0"], ["84092.8", "0"], ["84092.5", "0.004066"], ["84092.4", "0"], ["84091.9", "0"], ["84090.4", "0"], ["84090.3", "0.028456"], ["84089.8", "0"], ["84088.6", "0.06"], ["84087.7", "0.001"], ["84086.4", "0.002354"], ["84086.1", "0.106687"], ["84085.4", "0.07139"], ["84083.1", "0.166756"], ["84078.3", "0.170473"], ["84077.5", "0.005461"], ["84074.2", "0.091806"], ["84065.3", "0"], ["84064.7", "0.001466"], ["84064.6", "0"], ["84064", "0.04"], ["84063.9", "0.040158"], ["84063", "0"], ["84062.9", "0"], ["84062.3", "0.013"], ["84062.2", "0.01288"], ["84061.8", "0.001333"], ["84061.7", "0"], ["84061.3", "0.166241"], ["84060.5", "0.05"], ["84060.4", "0.049541"], ["84048.2", "0"], ["84044.1", "0"], ["84038.8", "0.35693"], ["84031.5", "0.118539"], ["84031.3", "0.005313"], ["84030.7", "0.120492"], ["84030.2", "0.000083"], ["84029.5", "0.023789"]], "a": [["84095.9", "0.640734"], ["84096.2", "0.164"], ["84096.3", "0.271"], ["84097", "0.002497"], ["84097.1", "0.191089"], ["84100.1", "0.001784"], ["84100.4", "0.000333"], ["84100.8", "0.062825"], ["84100.9", "0.074813"], ["84103.3", "0.071375"], ["84103.8", "0.019875"], ["84104.3", "0.055"], ["84104.7", "0"], ["84105.5", "0.005"], ["84106.4", "0.001556"], ["84106.9", "0"], ["84107.7", "0"], ["84107.9", "0"], ["84108", "0.029811"], ["84108.8", "0.000333"], ["84109", "0"], ["84109.3", "0"], ["84110.1", "0.003086"], ["84111.9", "0"], ["84124.3", "0"], ["84126", "1.089252"], ["84126.1", "0.000538"], ["84137.8", "1.426146"], ["84141.4", "0.356931"], ["84142.9", "0"], ["84148.8", "0"], ["84170", "0"], ["84170.1", "0"], ["84170.3", "0"], ["84170.4", "0"], ["84170.5", "0"]], "u": 167999, "seq": 67577193067}, "cts": 1742584905717, "record_time": 1742584905.82188, "EXCHANGE": "BYBIT"}
{"topic": "orderbook.200.BTCUSDT", "ts": 1742584905920, "type": "delta", "data": {"s": "BTCUSDT", "b": [["84092", "0.007447"], ["84088", "0.071388"], ["84078.3", "0.116951"], ["84078.2", "0"], ["84077", "0.025025"], ["84076.7", "0"], ["84076.6", "0"], ["84075.8", "0.035679"], ["84073.5", "0"], ["84028.9", "0.000333"]], "a": [["84095.9", "0.719867"], ["84099.7", "0.004969"], ["84100.9", "0.069845"], ["84104.3", "0.06"], ["84105.5", "0"], ["84106.9", "0.162896"], ["84124.4", "0.001231"], ["84129.8", "2.62184"], ["84138", "0.051994"], ["84141.4", "0"], ["84144.9", "0.380708"], ["84169.1", "0"]], "u": 168000, "seq": 67577193167}, "cts": 1742584905916, "record_time": 1742584906.021984, "EXCHANGE": "BYBIT"}
{"topic": "orderbook.200.BTCUSDT", "ts": 1742584906119, "type": "delta", "data": {"s": "BTCUSDT", "b": [["84088.3", "0.00528"], ["84087.5", "0.167477"], ["84087.4", "0.113245"], ["84087.1", "0.001861"], ["84078.3", "0.070936"], ["84074.2", "0.043771"], ["84029.5", "0"], ["84028.9", "0"]], "a": [["84095.9", "0.722364"], ["84096.2", "0.118621"], ["84097", "0"], ["84100.8", "0.098292"], ["84103.4", "0.10032"], ["84104.3", "0.269055"], ["84105.1", "0.137483"], ["84144.8", "0.362398"], ["84144.9", "0.023781"]], "u": 168001, "seq": 67577193285}, "cts": 1742584906116, "record_time": 1742584906.222596, "EXCHANGE": "BYBIT"}
{"topic": "orderbook.200.BTCUSDT", "ts": 1742584906319, "type": "delta", "data": {"s": "BTCUSDT", "b": [["84095.8", "0"], ["84095.5", "0"], ["84094.4", "0"], ["84092.5", "0.001466"], ["84092", "0.000333"], ["84090.6", "0.007114"], ["84090.3", "0"], ["84089.6", "0"], ["84088.7", "0.000297"], ["84088", "0"], ["84087.8", "0.000333"], ["84087.7", "0.029457"], ["84087.5", "0.001"], ["84087.3", "0"], ["84086.5", "0"], ["84086.1", "0"], ["84085.5", "0"], ["84085.4", "0"], ["84085", "0"], ["84084", "0"], ["84083.9", "0"], ["84083.5", "0.042688"], ["84083.1", "0.118507"], ["84083", "0"], ["84082", "0.055869"], ["84081.8", "0"], ["84081.7", "0.011099"], ["84081.3", "0"], ["84080.3", "0"], ["84079.9", "0"], ["84079.8", "0"], ["84079.1", "0.092"], ["84078.7", "0.017843"], ["84078.3", "0.052936"], ["84078.1", "0.05"], ["84077.8", "0.050528"], ["84077.4", "0.019911"], ["84076.9", "0.019911"], ["84076.8", "0"], ["84076.2", "0"], ["84075.8", "0"], ["84074.1", "0"], ["84073.9", "0.06"], ["84073.1", "0.03092"], ["84071", "0.156122"], ["84070.9", "0.190911"], ["84070.7", "0"], ["84070.6", "0.051333"], ["84065.9", "0"], ["84064", "0"], ["84063.9", "0.000528"], ["84062.3", "0"], ["84062.2", "0.011897"], ["84061.2", "0.005946"], ["84061.1", "0.04"], ["84061", "0.039632"], ["84060.8", "0"], ["84060.5", "0"], ["84060.4", "0"], ["84059.6", "0"], ["84059.4", "0"], ["84059.2", "0.013"], ["84059", "0.013"], ["84057.2", "0.063859"], ["84057.1", "0.049543"], ["84056.8", "0.059399"], ["84056.6", "0"], ["84047.7", "0"], ["84047.6", "0.023781"], ["84046", "0"], ["84044.8", "0.090017"], ["84044", "0"], ["84038.8", "0"], ["84038.7", "0.023787"], ["84034.3", "0.356944"], ["84033.2", "0"], ["84029.5", "0.023789"], ["84028.9", "0.000333"], ["84028.2", "0.001333"], ["84027.8", "0.001466"], ["84027.1", "0.005308"], ["84027", "0.000542"], ["84026", "0.000358"], ["84025.4", "0.012"], ["84025.3", "0.0015"], ["84025.2", "0.00009"], ["84025", "0.000204"], ["84024.7", "0.000333"], ["84024", "0.014424"], ["84023.6", "0.028222"], ["84023.5", "0.353279"], ["84023.4", "0.023789"], ["84023.1", "0.001466"], ["84022.9", "0.005238"], ["84022.5", "0.0176"], ["84022.3", "0.000526"], ["84021.9", "0.118539"], ["84021.3", "0.005947"], ["84020.5", "0.000333"], ["84019.8", "0.001333"]], "a": [["84092.6", "0.429669"], ["84094.5", "0.928056"], ["84095.5", "0.009225"], ["84095.6", "0.207275"], ["84095.8", "0.01714"], ["84095.9", "0.050089"], ["84096.2", "0"], ["84096.3", "0"], ["84097.4", "0.001"], ["84098.3", "0.004969"], ["84098.6", "0.005475"], ["84099.7", "0.001333"], ["84100.1", "0"], ["84100.4", "0.051666"], ["84100.8", "0.151789"], ["84100.9", "0.050619"], ["84101.2", "0.019875"], ["84103.6", "0.04"], ["84103.8", "0"], ["84103.9", "0.060732"], ["84104", "0.060358"], ["84104.3", "0.209055"], ["84104.8", "0.04"], ["84105.4", "0.029812"], ["84106.3", "0"], ["84106.4", "0.010792"], ["84107", "0.005445"], ["84107.1", "0.000297"], ["84108", "0"], ["84109.8", "0.04"], ["84109.9", "0"], ["84117.6", "0.051333"], ["84118.4", "0.171"], ["84124.4", "0"], ["84128", "0.265631"], ["84129.6", "0.011897"], ["84129.8", "0.000333"], ["84135.6", "0.020426"], ["84136.4", "0.482061"], ["84137.5", "0.952097"], ["84137.8", "0"], ["84139.7", "0.023866"], ["84140.2", "0.35694"], ["84144.6", "0"], ["84144.8", "0.005475"], ["84151.4", "0"], ["84159.2", "0.026"], ["84165.9", "0"], ["84166.5", "0"], ["84166.9", "0"], ["84167", "0"], ["84167.7", "0"], ["84168", "0"], ["84168.2", "0"]], "u": 168002, "seq": 67577194298}, "cts": 1742584906318, "record_time": 1742584906.423215, "EXCHANGE": "BYBIT"}
{"topic": "orderbook.200.BTCUSDT", "ts": 1742584906520, "type": "delta", "data": {"s": "BTCUSDT", "b": [["84092.5", "0"], ["84092", "0"], ["84091.7", "0"], ["84091.3", "0"], ["84090.6", "0"], ["84090.1", "0"], ["84088.7", "0"], ["84088.6", "0"], ["84088.3", "0"], ["84087.9", "0.029815"], ["84087.7", "0.001"], ["84087.5", "0"], ["84087.4", "0"], ["84086.9", "0"], ["84084.1", "0.007114"], ["84083.6", "0.000333"], ["84083.5", "0"], ["84083.1", "0"], ["84082.6", "0.00528"], ["84082", "0"], ["84081.7", "0.178761"], ["84081.2", "0.02846"], ["84080.8", "0"], ["84079.4", "0.171333"], ["84079.1", "0"], ["84078.7", "0"], ["84078.3", "0"], ["84078.1", "0"], ["84077.4", "0"], ["84077", "0.067717"], ["84076.9", "0"], ["84076.8", "0.05"], ["84075.8", "0.06"], ["84075.2", "0.042857"], ["84074.2", "0"], ["84074", "0.081385"], ["84073.9", "0"], ["84073.7", "0.0714"], ["84073.2", "0.000528"], ["84073.1", "0.021695"], ["84072.7", "0.06"], ["84072.6", "0.124877"], ["84072.3", "0.055877"], ["84072.1", "0.064"], ["84071.7", "0.071401"], ["84071", "0.075669"], ["84070.6", "0"], ["84070.2", "0.001333"], ["84069.5", "0.009467"], ["84067.3", "0.111669"], ["84066.8", "0"], ["84066.7", "0.060069"], ["84066", "0.001333"], ["84065.6", "0"], ["84065", "0"], ["84064.9", "0.023843"], ["84064.4", "0.051333"], ["84062.2", "0"], ["84061.3", "0"], ["84061.1", "0"], ["84061", "0"], ["84060.9", "0.17838"], ["84059.2", "0"], ["84059", "0"], ["84058.6", "0"], ["84057.6", "0.527867"], ["84057.2", "0"], ["84057.1", "0"], ["84056.3", "0"], ["84055.6", "0"], ["84054.8", "0"], ["84053.9", "0"], ["84053.7", "0.011898"], ["84053.4", "0.026081"], ["84052.7", "0.104"], ["84052.6", "0.039635"], ["84052.5", "0.587997"], ["84051.2", "0.171"], ["84051", "0.077"], ["84050.9", "0.014347"], ["84050.8", "0"], ["84049.9", "0.000333"], ["84049.8", "0"], ["84049.3", "0.06"], ["84049.2", "0.051333"], ["84049.1", "0.049548"], ["84044.8", "0"], ["84042.9", "0"], ["84039.8", "0.17838"], ["84035.9", "0"], ["84035.5", "0.183693"], ["84034.3", "0"], ["84033.4", "0.09002"], ["84033.1", "0.000333"], ["84030.7", "0"], ["84026.8", "0.003575"], ["84025.7", "0.171"], ["84025", "3.511796"], ["84023.6", "0.356966"], ["84018.8", "0.05"], ["84018.7", "0.005238"], ["84018.5", "0.000324"], ["84017.7", "0.030236"], ["84017.1", "0.059399"], ["84016.8", "0.051423"], ["84016.5", "0.320756"], ["84016.3", "0.000333"], ["84016", "0.04"], ["84015.9", "0.064"], ["84015.8", "0.056"], ["84015.6", "0.001333"], ["84014.5", "0.005238"], ["84014.3", "0.06"], ["84014.2", "3.921767"], ["84014", "0.092"], ["84013.9", "0.001466"], ["84013.1", "0.000526"], ["84012.7", "0.06"], ["84012.1", "0.000333"], ["84011.8", "0.118539"], ["84011.4", "0.061333"], ["84010.3", "0.005238"], ["84009.3", "0.001466"], ["84008.5", "0.000526"]], "a": [["84088", "0.817681"], ["84090.1", "0.149615"], ["84090.2", "0.223586"], ["84090.7", "0.050089"], ["84091.2", "0.001"], ["84092.5", "0.145126"], ["84092.6", "0.193815"], ["84094.2", "0.122715"], ["84094.4", "0.005475"], ["84094.5", "0.060089"], ["84095.5", "0.001333"], ["84095.6", "0.02101"], ["84095.8", "0"], ["84096.2", "0.000333"], ["84096.3", "0.000528"], ["84096.4", "0.06"], ["84096.9", "0.07138"], ["84097", "0.199652"], ["84097.1", "0.192555"], ["84097.7", "0.10032"], ["84098", "0.00009"], ["84098.3", "0"], ["84098.6", "0.214585"], ["84098.7", "0.04"], ["84099.4", "0.105985"], ["84100.4", "0.000333"], ["84100.8", "0"], ["84100.9", "0.13535"], ["84101.2", "0"], ["84102.8", "0.011684"], ["84103", "0.04"], ["84103.3", "0"], ["84103.4", "0"], ["84104", "0.000358"], ["84104.3", "0"], ["84105.1", "0.031498"], ["84105.3", "0.167468"], ["84105.4", "0"], ["84106.3", "0.022778"], ["84106.9", "0"], ["84107", "0.196674"], ["84108", "0.04"], ["84108.1", "0.041333"], ["84108.3", "0.118539"], ["84108.5", "0.04"], ["84108.7", "0"], ["84109.3", "0.111669"], ["84110.1", "0"], ["84110.5", "0"], ["84110.6", "0"], ["84110.7", "0"], ["84111.2", "0.183825"], ["84112.1", "0"], ["84113.9", "0.536105"], ["84114", "0"], ["84115.3", "0.0015"], ["84115.4", "0.017866"], ["84116.4", "0.023784"], ["84116.7", "0.279263"], ["84117.8", "0.00018"], ["84120.1", "0.004567"], ["84123.9", "0.283831"], ["84126", "0.137579"], ["84126.1", "0.000358"], ["84126.7", "0.075754"], ["84128", "0.176452"], ["84128.7", "0.00053"], ["84129.9", "1.426146"], ["84130.3", "0.02088"], ["84130.6", "0"], ["84132.5", "0.356967"], ["84133.8", "0.02206"], ["84136.4", "0.006679"], ["84137.5", "0.001333"], ["84138", "0.00053"], ["84138.1", "0"], ["84138.9", "0"], ["84139.3", "0"], ["84140.2", "0"], ["84147.5", "0"], ["84148.7", "0"], ["84157.5", "0.567447"], ["84160.4", "0"], ["84161.1", "0"], ["84161.7", "0"], ["84161.9", "0"], ["84162", "0"], ["84162.8", "0"], ["84163.5", "0"], ["84164", "0"], ["84164.4", "0"], ["84165.2", "0"], ["84165.6", "0"], ["84165.7", "0"]], "u": 168003, "seq": 67577195614}, "cts": 1742584906517, "record_time": 1742584906.624303, "EXCHANGE": "BYBIT"}
{"topic": "orderbook.200.BTCUSDT", "ts": 1742584906720, "type": "delta", "data": {"s": "BTCUSDT", "b": [["84087.9", "0.004677"], ["84086.4", "0"], ["84084.2", "0.071391"], ["84083.9", "0.006141"], ["84077.2", "0.000632"], ["84077.1", "0.074162"], ["84076.8", "0"], ["84076", "0.071398"], ["84075.8", "0"], ["84075.6", "0.04809"], ["84075.2", "0.000333"], ["84075", "0.0003"], ["84074", "0.136218"], ["84073.9", "0.064"], ["84073.7", "0"], ["84073.2", "0.064528"], ["84073.1", "0.019911"], ["84072.7", "0"], ["84072.6", "0"], ["84072.2", "0.064"], ["84071.6", "0.092"], ["84071", "0.122345"], ["84070.2", "0.051333"], ["84068.9", "0.023785"], ["84068.2", "0.06"], ["84066.8", "0.042052"], ["84066.6", "0.06"], ["84066.5", "0.06"], ["84057.4", "0"], ["84055.8", "0"], ["84055.5", "0.025251"], ["84052.9", "0.004645"], ["84052.7", "0.064"], ["84052.6", "0"], ["84051.5", "0.066034"], ["84051.4", "0.039634"], ["84051", "0"], ["84050.9", "0.001466"], ["84050.6", "0"], ["84049.8", "0.013"], ["84049.7", "0.012881"], ["84049.2", "0.001333"], ["84049.1", "0"], ["84048", "0.049547"], ["84047.9", "0.049547"], ["84039.8", "0"], ["84039.1", "0.090034"], ["84038.6", "0.06"], ["84035.6", "0.356964"], ["84035.5", "0.005313"], ["84034", "0.059399"], ["84033.4", "0"], ["84023.6", "0"], ["84018.8", "0"], ["84017.2", "0.171"], ["84016.3", "0.125202"], ["84013.1", "0"], ["84012.7", "0"], ["84012.1", "0"], ["84011.8", "0"], ["84011.4", "0"], ["84010.3", "0"], ["84009.3", "0"], ["84008.5", "0"]], "a": [["84088", "0.894435"], ["84090", "0.076431"], ["84090.1", "0.027275"], ["84091.8", "0.004969"], ["84094.7", "0.019877"], ["84095.2", "0.04"], ["84095.3", "0.04"], ["84097.1", "0.232555"], ["84098.1", "0.04"], ["84098.5", "0.02278"], ["84098.9", "0.029814"], ["84100.3", "0.04"], ["84100.8", "0.114658"], ["84100.9", "0.050619"], ["84101.9", "0.04"], ["84102", "0.04"], ["84103", "0"], ["84104.8", "0"], ["84105.2", "0.012849"], ["84106.3", "0"], ["84107", "0.005445"], ["84108.5", "0"], ["84109.8", "0"], ["84111.2", "0.005445"], ["84112.2", "0"], ["84116.4", "0"], ["84116.7", "0"], ["84117.3", "0"], ["84118.7", "2.621396"], ["84126", "0.29741"], ["84126.7", "0.075756"], ["84132.5", "0"], ["84135.3", "0.356966"], ["84139.7", "0"], ["84156.7", "0.027621"], ["84158.2", "0"], ["84158.6", "0"], ["84159.2", "0"], ["84159.3", "0"], ["84160", "0"]], "u": 168004, "seq": 67577195843}, "cts": 1742584906717, "record_time": 1742584906.823285, "EXCHANGE": "BYBIT"}
{"topic": "orderbook.200.BTCUSDT", "ts": 1742584906919, "type": "delta", "data": {"s": "BTCUSDT", "b": [["84087.9", "0"], ["84087.8", "0.003544"], ["84087.6", "0"], ["84084.2", "0"], ["84083.9", "0"], ["84082.3", "0.071392"], ["84079.4", "0.000333"], ["84077.8", "0.000528"], ["84077.2", "0"], ["84077.1", "0.034742"], ["84077", "0.042692"], ["84076", "0"], ["84074.1", "0.071399"], ["84072.6", "0.000632"], ["84071.7", "0"], ["84070.3", "0.05"], ["84070.2", "0.001333"], ["84070.1", "0.071403"], ["84068.9", "0"], ["84068.4", "0.05"], ["84068.3", "0.024925"], ["84066.8", "0.072795"], ["84063.9", "0.005286"], ["84061", "0.109155"], ["84054.4", "0"], ["84052.7", "0"], ["84052.4", "0.178385"], ["84051.5", "0.0264"], ["84051.3", "0.204439"], ["84049.8", "0"], ["84049.6", "0.012881"], ["84049.3", "0"], ["84048.2", "0.178385"], ["84048", "0"], ["84047.8", "0.049547"], ["84038.6", "0.07371"], ["84035.7", "0.356966"], ["84035.6", "0"], ["84022.9", "0.09443"], ["84013.8", "14.887151"]], "a": [["84087.9", "0.585542"], ["84088", "0.667581"], ["84090", "0"], ["84090.2", "0.050089"], ["84092.5", "0.22142"], ["84094.1", "0.059399"], ["84094.4", "0.18386"], ["84096.3", "0.060528"], ["84096.4", "0"], ["84097", "0.289198"], ["84098.6", "0.39297"], ["84102.8", "0.005445"], ["84103.6", "0"], ["84105.3", "0.116519"], ["84108.1", "0.001333"], ["84109.2", "0"], ["84110.3", "0"], ["84126.7", "0.075753"], ["84128", "0.265644"], ["84129.8", "1.426479"], ["84129.9", "0"], ["84130.5", "0"], ["84130.8", "0.04"], ["84132.3", "0.04"], ["84134.6", "0.023152"], ["84135.3", "0"], ["84135.7", "0.04"], ["84136.4", "0.363639"], ["84158.2", "0.01872"], ["84158.6", "0.001333"]], "u": 168005, "seq": 67577196072}, "cts": 1742584906917, "record_time": 1742584907.022499, "EXCHANGE": "BYBIT"}
{"topic": "orderbook.200.BTCUSDT", "ts": 1742584907120, "type": "delta", "data": {"s": "BTCUSDT", "b": [["84087.8", "0"], ["84087.7", "0"], ["84087.1", "0"], ["84085.9", "0"], ["84085.7", "0"], ["84084.1", "0"], ["84083.6", "0.06336"], ["84082.6", "0"], ["84082.3", "0"], ["84081.7", "0.065461"], ["84081.2", "0"], ["84077.4", "0.028461"], ["84077.1", "0"], ["84077", "0"], ["84075.6", "0"], ["84075", "0"], ["84074.1", "0"], ["84074", "0.001466"], ["84073.9", "0"], ["84073.3", "0.123282"], ["84073.2", "0.157222"], ["84073.1", "0"], ["84072.1", "0"], ["84071", "0.135978"], ["84070.9", "0.243791"], ["84070.3", "0.071403"], ["84070.1", "0"], ["84068.7", "0.0003"], ["84068.4", "0"], ["84068.3", "0.06"], ["84067.3", "0"], ["84066.8", "0.042052"], ["84066.7", "0.020844"], ["84065.4", "0.005946"], ["84064.4", "0"], ["84063.9", "0.000528"], ["84061.8", "0.010558"], ["84061", "0.071041"], ["84060.9", "0.051333"], ["84058.8", "0.259823"], ["84058.4", "0"], ["84058", "0"], ["84055.2", "0"], ["84053.4", "0.001333"], ["84052.6", "0.404889"], ["84052.4", "0"], ["84051.4", "0"], ["84051.3", "0"], ["84050.7", "0"], ["84049.7", "0"], ["84049.6", "0"], ["84048.4", "0.04"], ["84048.3", "0.039633"], ["84048.2", "0"], ["84047.9", "0"], ["84047.8", "0"], ["84046.7", "0.013"], ["84046.6", "0.012881"], ["84046.4", "0"], ["84044.9", "0.05"], ["84044.8", "0.049548"], ["84040.3", "0"], ["84039.1", "0"], ["84036.6", "0.001333"], ["84035.7", "0"], ["84035.6", "0.064"], ["84034.3", "0.356971"], ["84033.4", "0.090028"], ["84024.5", "0.000149"], ["84022.9", "0.005238"], ["84013.8", "0"], ["84013.1", "0.000526"], ["84012.7", "0.06"], ["84012.1", "0.000333"], ["84011.8", "0.118539"], ["84011.4", "0.061333"], ["84010.3", "0.005238"], ["84009.3", "0.026641"], ["84009", "0.0279"], ["84008.5", "0.000526"], ["84008.4", "0.00018"], ["84008.2", "0.05"], ["84008", "0.05"], ["84007.9", "0.000333"], ["84007.2", "0.001333"], ["84007", "0.06"], ["84006.9", "0.003"], ["84006.1", "0.005238"], ["84005.8", "0.12"], ["84005.2", "0.00595"], ["84004.7", "0.001466"], ["84003.9", "0.000884"], ["84003.7", "0.000333"], ["84003", "0.401333"], ["84002.7", "14.834309"]], "a": [["84083.7", "0.554635"], ["84084.1", "0.50656"], ["84084.2", "0.020089"], ["84086", "0.223586"], ["84087.2", "0.137227"], ["84087.8", "0.01714"], ["84087.9", "0.072343"], ["84088", "0.221089"], ["84089.8", "0.004969"], ["84090.1", "0.09114"], ["84090.4", "0.019877"], ["84091.3", "0.001333"], ["84091.7", "0.000528"], ["84091.8", "0"], ["84092", "0.000333"], ["84092.2", "0.071384"], ["84092.6", "0.193415"], ["84094.2", "0"], ["84094.5", "0.050089"], ["84094.6", "0.029815"], ["84094.7", "0"], ["84095.6", "0.06"], ["84096.3", "0.000528"], ["84096.9", "0.118539"], ["84097.1", "0.212466"], ["84097.7", "0"], ["84098.6", "0.18386"], ["84098.9", "0"], ["84099.4", "0"], ["84100.2", "0.04"], ["84100.8", "0.091145"], ["84100.9", "0.03053"], ["84103.2", "0.118539"], ["84103.8", "0.118923"], ["84104.8", "0.012849"], ["84105.2", "0"], ["84106.6", "0.587935"], ["84108", "0"], ["84108.9", "0.17118"], ["84115.9", "0.023784"], ["84117.8", "0"], ["84118.7", "0"], ["84120.4", "0.005946"], ["84121", "0.075253"], ["84121.9", "0.023784"], ["84125.6", "0.951097"], ["84125.9", "0.593921"], ["84126.7", "0.024284"], ["84126.8", "0.023784"], ["84127.3", "0"], ["84128", "0.289428"], ["84128.9", "0.04"], ["84129.8", "0.000333"], ["84134", "0.040333"], ["84134.6", "0"], ["84135.3", "0.356971"], ["84136.4", "0.006679"], ["84137.2", "0"], ["84138.2", "0.000478"], ["84143.8", "3.572392"], ["84146.9", "3.917687"], ["84149.1", "0"], ["84150.3", "0"], ["84154.4", "0"], ["84155.1", "0"], ["84156.4", "0"], ["84156.5", "0"], ["84156.7", "0"], ["84156.8", "0"], ["84157", "0"], ["84157.3", "0"], ["84157.4", "0"], ["84157.5", "0"], ["84158.2", "0"], ["84158.6", "0"]], "u": 168006, "seq": 67577197274}, "cts": 1742584907117, "record_time": 1742584907.223544, "EXCHANGE": "BYBIT"}
{"topic": "orderbook.200.BTCUSDT", "ts": 1742584907319, "type": "delta", "data": {"s": "BTCUSDT", "b": [["84083.6", "0.027106"], ["84081.7", "0.005461"], ["84079.8", "0.01316"], ["84076.1", "0.00528"], ["84075.3", "0.128095"], ["84075.2", "0.173633"], ["84073.4", "0.000297"], ["84073.3", "0.005458"], ["84073.2", "0.107222"], ["84072.2", "0"], ["84070.9", "0.171"], ["84070.5", "0.048"], ["84070.2", "0.002333"], ["84068.7", "0"], ["84068.2", "0.11"], ["84067.2", "0.071958"], ["84067.1", "0.064"], ["84066.8", "0"], ["84065.9", "0.0003"], ["84062.8", "0.125198"], ["84062.7", "0.115242"], ["84062", "0.025175"], ["84061", "0"], ["84059.9", "0.027106"], ["84058.8", "0.181627"], ["84053.3", "0.178394"], ["84052.6", "0"], ["84044.8", "0.049545"], ["84034.4", "0.356973"], ["84034.3", "0"], ["84033.4", "0"], ["84031.3", "0.183707"], ["84030.6", "0.090028"], ["84027.1", "0.183702"], ["84010.9", "0.120521"], ["84009.3", "0.001466"], ["84008.7", "0.171"], ["84008.2", "0"], ["84008", "0"], ["84005.2", "0"], ["84004.7", "0"], ["84003.9", "0"], ["84003.7", "0"], ["84003", "0"], ["84002.7", "0"]], "a": [["84083.7", "0.549586"], ["84083.8", "0.003576"], ["84084", "0.17696"], ["84084.1", "0"], ["84087.5", "0.004969"], ["84087.7", "0.009225"], ["84087.8", "0"], ["84089.8", "0"], ["84090.1", "0.2043"], ["84090.7", "0.056189"], ["84091.2", "0.10132"], ["84092.1", "0.26911"], ["84092.5", "0.146592"], ["84092.8", "0.04"], ["84092.9", "0.105985"], ["84094.4", "0.005475"], ["84094.5", "0.090089"], ["84095.6", "0"], ["84097", "0.174559"], ["84098.1", "0"], ["84100.8", "0.12346"], ["84102.8", "0.183839"], ["84103.1", "0.012849"], ["84104.8", "0"], ["84104.9", "0"], ["84107", "0.183839"], ["84110.1", "0.0495"], ["84125.6", "1.426479"], ["84125.9", "0.118539"], ["84126", "0.137579"], ["84127.9", "0.024396"], ["84128.4", "0.013736"], ["84132.2", "0.36244"], ["84135.3", "0"], ["84149.1", "0.089197"], ["84152.6", "0"], ["84153.2", "0"], ["84153.5", "0"], ["84154.2", "0"]], "u": 168007, "seq": 67577197528}, "cts": 1742584907315, "record_time": 1742584907.422699, "EXCHANGE": "BYBIT"}
{"topic": "orderbook.200.BTCUSDT", "ts": 1742584907520, "type": "delta", "data": {"s": "BTCUSDT", "b": [["84083.6", "0.000333"], ["84079.8", "0.007115"], ["84076.1", "0.00878"], ["84075.4", "0.000297"], ["84075.3", "0"], ["84073.4", "0"], ["84073.2", "0.043222"], ["84071.6", "0"], ["84070.1", "0.001"], ["84068.8", "0.064"], ["84068.3", "0"], ["84068.2", "0.05"], ["84067", "0.064"], ["84066.6", "0"], ["84066.5", "0"], ["84065.9", "0"], ["84063.8", "0"], ["84062.2", "0.056575"], ["84062", "0.085175"], ["84055.2", "0.055918"], ["84053.7", "0"], ["84053.3", "0"], ["84052.4", "0.178394"], ["84048.2", "0.288561"], ["84047.4", "0.00748"], ["84043.6", "0.011899"], ["84038.2", "0"], ["84034.5", "0.356973"], ["84034.4", "0"], ["84033.4", "0.090033"], ["84031.3", "0.005313"], ["84030.6", "0"], ["84027.1", "0.005308"], ["84010.9", "14.95483"], ["84007.6", "0.0003"], ["84005.4", "0.05"]], "a": [["84083.7", "0.573676"], ["84084", "0.184269"], ["84087.2", "0.122362"], ["84087.7", "0"], ["84097.2", "0.056519"], ["84100.2", "0.052849"], ["84103.1", "0"], ["84104.2", "0.059469"], ["84107", "0.005445"], ["84111", "0.013365"], ["84111.2", "0.128242"], ["84113.2", "2.621533"], ["84113.3", "0.005946"], ["84126.5", "0.04"], ["84129.6", "0"], ["84152.2", "0"], ["84152.5", "0"]], "u": 168008, "seq": 67577198037}, "cts": 1742584907517, "record_time": 1742584907.623315, "EXCHANGE": "BYBIT"}
{"topic": "orderbook.200.BTCUSDT", "ts": 1742584907719, "type": "delta", "data": {"s": "BTCUSDT", "b": [["84083.6", "0.001133"], ["84077.4", "0.031461"], ["84070.3", "0"], ["84069.5", "0"], ["84068.7", "0.064"], ["84067.9", "0.071405"], ["84067.2", "0.163958"], ["84064.9", "0.005327"], ["84063.8", "0.06"], ["84063.7", "0.06"], ["84062.2", "0"], ["84062.1", "0.06"], ["84060.6", "0.023562"], ["84055.2", "0"], ["84053.3", "0.178394"], ["84052.4", "0"], ["84048.4", "0"], ["84048.3", "0"], ["84048.2", "0"], ["84046.8", "0.04"], ["84046.7", "0.039634"], ["84046.6", "0"], ["84045.1", "0.013"], ["84045", "0.014214"], ["84044.9", "0"], ["84044.8", "0"], ["84044", "0.02422"], ["84043.3", "0.05"], ["84043.2", "0.049547"], ["84038.6", "0.01371"], ["84034.5", "0"], ["84033.4", "0.090039"], ["84025.8", "0.356982"], ["84010.9", "0.120521"], ["84008.3", "14.834309"], ["84005.8", "0"], ["84005.4", "0"]], "a": [["84083.7", "0.817183"], ["84084.2", "0.09148"], ["84086", "0.221089"], ["84087.9", "0.051333"], ["84089.9", "0.071386"], ["84094.2", "0.009236"], ["84097.2", "0"], ["84098.6", "0.005475"], ["84098.9", "0.023785"], ["84099.6", "0.012849"], ["84100.2", "0.04"], ["84100.8", "0.186824"], ["84102.8", "0.005445"], ["84104.2", "0"], ["84106.4", "0.001556"], ["84108.5", "0.059464"], ["84111.2", "0.005445"], ["84113.2", "0"], ["84114.4", "0.060064"], ["84118.2", "0.051472"], ["84118.7", "2.621533"], ["84120.3", "0.059464"], ["84120.8", "0.140765"], ["84121", "0.023784"], ["84128.8", "0.356991"], ["84132.2", "0.005472"], ["84135.6", "0"], ["84135.9", "0"], ["84137.5", "0.012326"], ["84150.9", "0"], ["84151.6", "0"], ["84151.8", "0"], ["84152.1", "0"]], "u": 168009, "seq": 67577198357}, "cts": 1742584907717, "record_time": 1742584907.822464, "EXCHANGE": "BYBIT"}
{"topic": "orderbook.200.BTCUSDT", "ts": 1742584907919, "type": "delta", "data": {"s": "BTCUSDT", "b": [["84083.6", "0"], ["84079.2", "0.071395"], ["84076.1", "0.00528"], ["84075.5", "0.006025"], ["84075.4", "0"], ["84072.6", "0"], ["84072.4", "0.071401"], ["84072.3", "0"], ["84071", "0.093081"], ["84070.5", "0"], ["84070", "0.071403"], ["84068.8", "0"], ["84068.7", "0"], ["84068.2", "0"], ["84067.9", "0"], ["84067.6", "0.055881"], ["84067.2", "0.071958"], ["84067.1", "0"], ["84067", "0"], ["84064.8", "0.05"], ["84064.4", "0.05"], ["84063.8", "0"], ["84063.7", "0"], ["84062.7", "0.003575"], ["84062.1", "0"], ["84062", "0"], ["84061.8", "0.001333"], ["84060.6", "0.087562"], ["84060.4", "0.009467"], ["84059.9", "0"], ["84059", "0.06"], ["84058.8", "0.241627"], ["84057.5", "0.009225"], ["84055.9", "0.018516"], ["84053.3", "0"], ["84052.6", "0.292031"], ["84047.6", "0"], ["84046.8", "0"], ["84046.7", "0.118929"], ["84046.1", "0.04"], ["84046", "0.039635"], ["84045.1", "0"], ["84045", "0.001333"], ["84044.4", "0.013"], ["84044.3", "0.012881"], ["84044", "0"], ["84043.3", "0"], ["84043.2", "0"], ["84042.6", "0.05"], ["84042.5", "0.049548"], ["84037.4", "0.000333"], ["84035.6", "0"], ["84033.4", "0"], ["84027.8", "0.09149"], ["84024", "0.001333"], ["84008.3", "0"], ["84006.8", "0.025825"], ["84005.2", "0.00595"], ["84005.1", "0.05"], ["84004.8", "0.05"], ["84004.7", "0.001466"], ["84003.9", "0.000884"], ["84003.8", "0.624378"], ["84003.7", "0.000333"]], "a": [["84083.3", "0.782706"], ["84083.5", "0.198838"], ["84083.6", "0.01714"], ["84083.7", "0.221089"], ["84083.8", "0"], ["84084", "0"], ["84086", "0.050089"], ["84087.6", "0.003576"], ["84087.8", "0.000333"], ["84088.5", "0.04"], ["84088.6", "0.04"], ["84090.4", "0.059877"], ["84091.7", "0.060528"], ["84092.1", "0.20911"], ["84092.5", "0.201869"], ["84093.5", "0.04"], ["84093.7", "0.062781"], ["84095.2", "0.08"], ["84095.9", "0.03"], ["84097", "0.121833"], ["84097.1", "0.172466"], ["84097.3", "0.012849"], ["84098.5", "0"], ["84099.6", "0"], ["84100.2", "0"], ["84100.8", "0.12946"], ["84101.9", "0"], ["84102", "0"], ["84103.8", "0"], ["84107.7", "0.023786"], ["84118.2", "0.051466"], ["84118.3", "0.899302"], ["84121.1", "0.003531"], ["84121.8", "0.02456"], ["84125.2", "1.426146"], ["84125.6", "0.000333"], ["84127.9", "0"], ["84128.8", "0"], ["84130.7", "0.356989"], ["84137", "0.010993"], ["84148.9", "0"], ["84149", "0"], ["84149.1", "0"], ["84149.8", "0"], ["84150.1", "0"], ["84150.8", "0"]], "u": 168010, "seq": 67577198714}, "cts": 1742584907916, "record_time": 1742584908.023208, "EXCHANGE": "BYBIT"}
{"topic": "orderbook.200.BTCUSDT", "ts": 1742584908119, "type": "delta", "data": {"s": "BTCUSDT", "b": [["84083.2", "0"], ["84082.9", "0"], ["84082.4", "0"], ["84081.7", "0.008672"], ["84079.8", "0"], ["84079.2", "0"], ["84078.4", "0.007115"], ["84075.2", "0.113633"], ["84074.8", "0.06"], ["84070", "0"], ["84069.9", "0.071403"], ["84067.2", "0.040723"], ["84064.1", "0.048"], ["84062.3", "0.064"], ["84060.6", "0.064"], ["84060.5", "0.064"], ["84057.2", "0.06"], ["84056.8", "0.064158"], ["84055.7", "0.111667"], ["84051.6", "0"], ["84048.2", "0.178395"], ["84046.4", "0.011893"], ["84044.4", "0.012881"], ["84044", "0.178395"], ["84042.7", "0.221"], ["84042.6", "0.049547"], ["84042.5", "0"], ["84038", "0.023232"], ["84031.9", "0.356982"], ["84028.1", "0.178395"], ["84025.8", "0"], ["84005.1", "0"], ["84004.8", "0"], ["84003.9", "0"], ["84003.8", "0"], ["84003.7", "0"]], "a": [["84081.8", "0.467357"], ["84082.2", "0.04"], ["84082.3", "0.827394"], ["84082.5", "0.109944"], ["84083.2", "0.009225"], ["84083.3", "0.268432"], ["84083.5", "0"], ["84083.6", "0"], ["84083.7", "0.050089"], ["84084.2", "0.020089"], ["84086.3", "0.004969"], ["84087.1", "0.001861"], ["84087.5", "0"], ["84087.6", "0"], ["84087.7", "0.071388"], ["84087.9", "0.052799"], ["84090.7", "0.106189"], ["84091.7", "0.010528"], ["84092", "0.040333"], ["84092.2", "0"], ["84094.5", "0.07"], ["84095.2", "0.04"], ["84096.8", "0.012849"], ["84097", "0.090999"], ["84097.3", "0"], ["84098.7", "0"], ["84100.3", "0"], ["84100.8", "0.006"], ["84117.7", "0"], ["84118.7", "2.621124"], ["84130.7", "0"], ["84132.2", "0.362454"], ["84148.9", "0.04"]], "u": 168011, "seq": 67577199062}, "cts": 1742584908117, "record_time": 1742584908.223234, "EXCHANGE": "BYBIT"}
{"topic": "orderbook.200.BTCUSDT", "ts": 1742584908320, "type": "delta", "data": {"s": "BTCUSDT", "b": [["84079.4", "0.071728"], ["84077.4", "0.003"], ["84075.5", "0"], ["84075.3", "0.000297"], ["84075", "0.028462"], ["84073.2", "0.000528"], ["84070.8", "0.042696"], ["84067.2", "0.069244"], ["84064.4", "0"], ["84063.9", "0.064528"], ["84063.5", "0.05"], ["84062.8", "0.182788"], ["84062.3", "0.156"], ["84060.2", "0.031323"], ["84057.3", "0.06"], ["84056.8", "0.059399"], ["84056.4", "0.008672"], ["84046.1", "0.039633"], ["84046", "0.039633"], ["84042.7", "0.171"], ["84042.6", "0.049546"], ["84042.5", "0.049546"], ["84033.6", "0.791141"], ["84031.9", "0"], ["84028.2", "0.358316"], ["84022.9", "0.094437"], ["84006.8", "0"], ["84006.1", "0"], ["84005.2", "0"], ["84004.7", "0"]], "a": [["84081.8", "0.579781"], ["84082.1", "0.250008"], ["84082.2", "0"], ["84082.3", "0.121481"], ["84082.5", "0"], ["84083.3", "0.205091"], ["84090.2", "0.288487"], ["84090.7", "0.050089"], ["84091.7", "0.000528"], ["84092.6", "0.173326"], ["84094.4", "0.183873"], ["84096.2", "0.013182"], ["84096.8", "0.098706"], ["84097", "0"], ["84107", "0.094644"], ["84113.2", "2.621183"], ["84118.7", "0"], ["84121.5", "0.04"], ["84121.6", "0.04"], ["84123.7", "1.426146"], ["84125.2", "0"], ["84127.1", "0.04"], ["84130.7", "0.356983"], ["84132.2", "0.005472"], ["84141.5", "0"], ["84141.6", "0"]], "u": 168012, "seq": 67577199321}, "cts": 1742584908317, "record_time": 1742584908.423315, "EXCHANGE": "BYBIT"}
