{"topic": "orderbook.200.BTCUSDT", "ts": 1742142219610, "type": "delta", "data": {"s": "BTCUSDT", "b": [["84261.36", "0.024409"], ["84261.35", "0.071212"], ["84257.81", "0.004372"], ["84255.35", "0"], ["84255.34", "0"], ["84252.7", "0"], ["84251.15", "0.000297"], ["84251.14", "0.028547"], ["84251.13", "0.09369"], ["84251.12", "0.109705"], ["84251.1", "0.02"], ["84250.84", "0.118155"], ["84250.71", "0.084241"], ["84250.31", "0.116694"], ["84249.9", "0.04"], ["84249.6", "0.04"], ["84249.51", "0.000297"], ["84249.5", "0.001"], ["84249.49", "0.015092"], ["84249.4", "0.02"], ["84249.11", "0.237391"], ["84248.93", "0.089922"], ["84248.06", "0"], ["84248.03", "0"], ["84247.8", "0"], ["84247.77", "0"], ["84247.43", "0"], ["84247.33", "0.02"], ["84246.46", "0.237355"], ["84246.29", "0.347138"], ["84246.28", "0.237399"], ["84246.05", "0.068395"], ["84245.84", "0.011867"], ["84245.71", "0"], ["84244.65", "0"], ["84244.6", "0.237404"], ["84244.21", "0.019233"], ["84244.02", "0.177796"], ["84243", "0.04"], ["84242.97", "0.163902"], ["84242.51", "0"], ["84240.82", "0"], ["84240.11", "0.171066"], ["84239.91", "0"], ["84239.46", "0.237355"], ["84239.14", "0"], ["84238.17", "0"], ["84238.04", "0"], ["84237.12", "0.000613"], ["84237.05", "0"], ["84236.78", "0"], ["84236.65", "0.023734"], ["84236.15", "0.27804"], ["84235.11", "0.283121"], ["84233.49", "0.089922"], ["84233.2", "0.017801"], ["84233.05", "0.071236"], ["84232.05", "0.277797"], ["84232.04", "0"], ["84231.68", "0"], ["84231.03", "0"], ["84229.88", "0.271639"], ["84228.91", "0"], ["84228.19", "0"], ["84226.82", "0"], ["84226.63", "0"], ["84225", "0.068395"], ["84223.15", "0"], ["84221.71", "0.323705"], ["84221.08", "0"], ["84219.67", "0.11863"], ["84215.02", "0.356048"], ["84214.47", "0.11863"], ["84212.62", "0"], ["84212.41", "0"], ["84212.4", "0"], ["84211.93", "0"], ["84211.9", "0"], ["84211.85", "0"], ["84210.81", "0"], ["84210.2", "0"], ["84210.19", "0"], ["84210.18", "0"], ["84210.1", "0"], ["84210.02", "0"], ["84209.7", "0"], ["84208.56", "0"], ["84208.55", "0"], ["84208.3", "0"]], "a": [["84262.02", "0.025504"], ["84266.22", "0"], ["84267.41", "0"], ["84268.53", "0.000233"], ["84268.75", "0"], ["84269.37", "0.000297"], ["84271.32", "0"], ["84271.65", "0"], ["84272.13", "0"], ["84272.25", "0.011867"], ["84272.72", "0"], ["84272.76", "0"], ["84273.82", "0"], ["84273.83", "0"], ["84274.6", "0.020997"], ["84276.38", "0"], ["84276.61", "0.137166"], ["84276.88", "0"], ["84277.81", "0"], ["84278.2", "0"], ["84278.33", "0.0002"], ["84278.47", "0"], ["84278.55", "0"], ["84278.6", "0"], ["84279.44", "0.116439"], ["84279.59", "0"], ["84279.9", "0"], ["84279.94", "0.107169"], ["84280.3", "0"], ["84280.98", "0.110049"], ["84280.99", "0.119613"], ["84281.07", "0"], ["84281.73", "0"], ["84281.88", "0"], ["84281.89", "0"], ["84281.9", "0"], ["84282.7", "0.044"], ["84282.83", "0.008453"], ["84282.9", "0.06"], ["84283.12", "0"], ["84283.4", "0"], ["84283.6", "0"], ["84284.45", "0"], ["84284.75", "0"], ["84285", "0"], ["84285.3", "0.11863"], ["84285.37", "0"], ["84286.15", "0.0178"], ["84286.3", "0.06"], ["84286.34", "0"], ["84287.01", "0"], ["84287.03", "0.023872"], ["84287.22", "0.023734"], ["84287.28", "0.162907"], ["84287.39", "0"], ["84287.73", "0"], ["84287.81", "0.164057"], ["84287.86", "0.004598"], ["84288.7", "0.330698"], ["84289.3", "0.048"], ["84289.6", "0.048"], ["84290.02", "0"], ["84290.45", "0.166671"], ["84291.87", "0"], ["84292.03", "0.009462"], ["84292.61", "0"], ["84294.2", "0"], ["84295.15", "0.297219"], ["84295.24", "0.019075"], ["84295.45", "0.071183"], ["84295.68", "0.294849"], ["84297.62", "0"], ["84298.09", "0.071181"], ["84298.44", "0.237355"], ["84300.68", "0.27413"], ["84302.45", "0.013795"], ["84302.66", "0.237355"], ["84307.02", "0"], ["84307.03", "0"], ["84309.66", "0"], ["84309.72", "0.04"], ["84309.73", "0.040235"], ["84309.77", "0"], ["84310.3", "0.03181"], ["84313.85", "0.000335"], ["84313.87", "0.237355"], ["84313.97", "0.237355"], ["84314.2", "0.246059"], ["84314.37", "0.000235"], ["84314.44", "0.089922"], ["84314.9", "0.000235"], ["84315.93", "0.11863"], ["84315.95", "0.001243"], ["84316.26", "0.0002"], ["84316.48", "0.0045"], ["84316.61", "0.000253"], ["84316.68", "0.0045"]], "u": 7510618, "seq": 66889300173}, "cts": 1742142219608, "record_time": 1742142218.709602}
{"topic": "orderbook.200.BTCUSDT", "ts": 1742142219810, "type": "delta", "data": {"s": "BTCUSDT", "b": [["84262.01", "0.179336"], ["84261.36", "0"], ["84261.35", "0"], ["84261.26", "0.024409"], ["84261.25", "0.071212"], ["84251.66", "0.02"], ["84251.14", "0.000297"], ["84251.13", "0.025332"], ["84251.12", "0"], ["84250.84", "0"], ["84250.32", "0.249618"], ["84250.31", "0"], ["84250.04", "0.116942"], ["84249.96", "0"], ["84249.75", "0.1128"], ["84249.5", "0.021"], ["84249.41", "0.108838"], ["84249.4", "0"], ["84249.01", "0"], ["84248.93", "0.109922"], ["84248.2", "0.04"], ["84247.81", "0"], ["84247.8", "0.04"], ["84247.33", "0"], ["84246.83", "0.120153"], ["84245.7", "0"], ["84244.9", "0"], ["84244.5", "0.04"], ["84244.02", "0"], ["84243.5", "0.00009"], ["84243.12", "0.165229"], ["84242.97", "0"], ["84241.89", "0.172761"], ["84241.39", "0"], ["84240.11", "0"], ["84239.9", "0.04"], ["84239.03", "0.166428"], ["84238.96", "0.16377"], ["84238.5", "0"], ["84237.13", "0"], ["84236.15", "0"], ["84235.25", "0.294635"], ["84235.11", "0"], ["84234.02", "0.299393"], ["84232.05", "0"], ["84231.1", "0.291488"], ["84229.88", "0"], ["84228.8", "0.282042"], ["84223.14", "0"], ["84215.03", "0.356049"], ["84215.02", "0"], ["84212.62", "0.0002"], ["84212.41", "0.000233"], ["84212.4", "0.001243"], ["84211.93", "0.000989"]], "a": [["84262.02", "0.025027"], ["84264.98", "0.071209"], ["84267.32", "0"], ["84268.75", "0.00097"], ["84269.37", "0"], ["84276.61", "0.080096"], ["84278.36", "0.11122"], ["84278.86", "0.118028"], ["84279.44", "0"], ["84279.94", "0"], ["84280.09", "0.109271"], ["84280.65", "0.110691"], ["84280.98", "0.060825"], ["84280.99", "0"], ["84282.7", "0.044461"], ["84284.3", "0.044"], ["84284.44", "0.239155"], ["84284.7", "0.068"], ["84286.38", "0.158911"], ["84286.73", "0.160169"], ["84287.28", "0"], ["84287.81", "0"], ["84288", "0.056"], ["84288.3", "0.068"], ["84288.52", "0.164083"], ["84288.7", "0"], ["84289.37", "0.159923"], ["84290.45", "0"], ["84294.25", "0.289485"], ["84294.59", "0.281085"], ["84295.15", "0"], ["84295.68", "0"], ["84296.38", "0.274112"], ["84298.44", "0"], ["84299.18", "1.419018"], ["84299.6", "0.288339"], ["84300.68", "0"], ["84302.66", "0"], ["84309.72", "0"], ["84309.73", "0.000235"], ["84310.32", "0.04"], ["84310.33", "0.04"], ["84315.93", "0"], ["84315.95", "0"], ["84316.26", "0"], ["84316.48", "0"], ["84316.61", "0"], ["84316.68", "0"]], "u": 7510619, "seq": 66889300546}, "cts": 1742142219805, "record_time": 1742142218.908792}
{"topic": "orderbook.200.BTCUSDT", "ts": 1742142220009, "type": "delta", "data": {"s": "BTCUSDT", "b": [["84265.78", "0.326869"], ["84265.42", "0.056171"], ["84265.41", "0.071209"], ["84264.98", "0.0004"], ["84264.97", "0.115427"], ["84263.16", "0.0002"], ["84262.01", "0.0054"], ["84261.26", "0"], ["84261.25", "0"], ["84260.01", "0.0011"], ["84257.81", "0"], ["84257.35", "0.0005"], ["84255.01", "0"], ["84254.95", "0.112584"], ["84254.67", "0.119908"], ["84254.03", "0.133427"], ["84253.58", "0.162"], ["84253.56", "0.02"], ["84253.1", "0.02"], ["84252.74", "0.120196"], ["84252.4", "0.015091"], ["84251.66", "0"], ["84251.5", "0.02"], ["84251.13", "0"], ["84251.1", "0"], ["84250.52", "0.012066"], ["84250.43", "0.02"], ["84250.32", "0.360145"], ["84250.04", "0"], ["84249.75", "0"], ["84249.51", "0"], ["84249.5", "0.001"], ["84249.49", "0"], ["84249.41", "0"], ["84249.21", "0.009541"], ["84249.11", "0"], ["84248.93", "0.089922"], ["84246.84", "0.16715"], ["84246.83", "0"], ["84246.28", "0"], ["84245.84", "0"], ["84244.91", "0.157642"], ["84243.99", "0.158212"], ["84243.2", "0"], ["84243.12", "0"], ["84242.26", "0.059948"], ["84242.25", "0"], ["84241.9", "0.263629"], ["84241.89", "0"], ["84239.12", "0.071231"], ["84239.03", "0"], ["84239.01", "0.293758"], ["84238.96", "0"], ["84237.88", "0.0178"], ["84235.26", "0.251985"], ["84235.25", "0"], ["84234.45", "0.023735"], ["84234.02", "0"], ["84233.82", "0.263167"], ["84233.2", "0"], ["84231.1", "0"], ["84231.08", "0"], ["84228.8", "0"], ["84227.08", "0"], ["84224.02", "0.35602"], ["84222.01", "0.0013"], ["84217.01", "0"], ["84215.03", "0"], ["84211.9", "0.001333"]], "a": [["84262.02", "0"], ["84264.98", "0"], ["84265.65", "0"], ["84265.69", "0"], ["84265.79", "0.023053"], ["84268.75", "0"], ["84269.38", "0"], ["84270.43", "0"], ["84270.45", "0.0178"], ["84270.84", "0"], ["84270.91", "0"], ["84271.29", "0.071204"], ["84272.25", "0"], ["84274.08", "0.0005"], ["84274.6", "0"], ["84276.61", "0"], ["84276.78", "0.020997"], ["84276.84", "0.011866"], ["84278.36", "0"], ["84278.86", "0"], ["84280.08", "0.126612"], ["84280.09", "0"], ["84280.65", "0"], ["84280.98", "0"], ["84282.7", "0.044"], ["84283.13", "0.11058"], ["84283.63", "0.107011"], ["84283.87", "0"], ["84284.32", "0.001467"], ["84286.15", "0"], ["84286.38", "0"], ["84286.4", "0.10552"], ["84286.65", "0"], ["84286.73", "0"], ["84286.94", "0.035608"], ["84287.03", "0"], ["84288.52", "0"], ["84288.7", "0.245459"], ["84289.37", "0"], ["84290.36", "0.068395"], ["84290.98", "0.017799"], ["84291.46", "0.17313"], ["84292.75", "0.524628"], ["84292.76", "0"], ["84293.88", "0.008905"], ["84293.92", "0.005"], ["84294.09", "0.161866"], ["84294.23", "0.401106"], ["84294.25", "0"], ["84294.59", "0"], ["84295.45", "0"], ["84296.38", "0"], ["84296.48", "0"], ["84296.85", "0.023735"], ["84297.32", "0"], ["84299.19", "0.024389"], ["84299.29", "0.299281"], ["84299.6", "0"], ["84301.02", "0"], ["84302.05", "0.296968"], ["84304.14", "0"], ["84304.27", "0.274272"], ["84305.68", "0.071175"], ["84307.53", "0.005933"], ["84310.32", "0"], ["84310.33", "0"], ["84310.62", "0.04"], ["84310.63", "0.04"], ["84313.42", "0.029801"], ["84313.87", "0"], ["84313.97", "0"], ["84315.93", "0.11863"], ["84315.95", "0.001243"], ["84316.26", "0.0002"], ["84316.41", "0.009"], ["84316.48", "0.0045"], ["84316.61", "0.004753"], ["84316.68", "0.0045"], ["84316.78", "0.001467"], ["84316.88", "0.0045"], ["84316.97", "0.005"], ["84317.08", "0.0045"], ["84317.19", "0.000612"], ["84317.23", "0.001333"]], "u": 7510620, "seq": 66889301999}, "cts": 1742142220006, "record_time": 1742142219.109046}
{"topic": "orderbook.200.BTCUSDT", "ts": 1742142220210, "type": "delta", "data": {"s": "BTCUSDT", "b": [["84265.78", "0.29934"], ["84265.42", "0"], ["84265.41", "0"], ["84264.98", "0"], ["84264.97", "0"], ["84264.95", "0.011867"], ["84262.15", "0.026608"], ["84262.14", "0.071212"], ["84262.01", "0.005"], ["84254.95", "0"], ["84254.67", "0"], ["84254.14", "0.119942"], ["84254.03", "0.091625"], ["84253.85", "0.107732"], ["84253.58", "0"], ["84253.1", "0"], ["84253", "0.02"], ["84252.74", "0"], ["84252.36", "0.112433"], ["84251.5", "0"], ["84251.4", "0.02"], ["84250.93", "0.02"], ["84250.71", "0"], ["84250.43", "0"], ["84250.32", "0.218901"], ["84249.79", "0.237389"], ["84248.93", "0"], ["84248.6", "0.04"], ["84248.5", "0.048"], ["84248.11", "0.237394"], ["84246.84", "0"], ["84246.8", "0.04"], ["84246.46", "0"], ["84246.1", "0.159353"], ["84246.03", "0.163911"], ["84245.3", "0.04"], ["84244.91", "0"], ["84243.99", "0"], ["84243.18", "0.166764"], ["84242.27", "0.059948"], ["84242.26", "0"], ["84242", "0"], ["84239.9", "0"], ["84239.12", "0"], ["84239.01", "0.000237"], ["84238.97", "0.023402"], ["84238.27", "0.297946"], ["84238.2", "0.289599"], ["84235.8", "0.266385"], ["84235.26", "0"], ["84233.82", "0"], ["84233", "0.264121"], ["84229.63", "0.178008"], ["84229.22", "0.071239"], ["84224.02", "0"], ["84221.61", "0.04"], ["84221.6", "0.039641"], ["84215.76", "0.000989"], ["84215.02", "0.356052"], ["84215.01", "0"], ["84215", "0"], ["84212.4", "0"], ["84211.93", "0"], ["84211.9", "0"]], "a": [["84265.79", "0.094722"], ["84269.42", "0.000099"], ["84271.29", "0"], ["84272.52", "0.007037"], ["84275.11", "0.000153"], ["84276.61", "0.090001"], ["84280.08", "0.06211"], ["84282.32", "0.112574"], ["84282.82", "0.109653"], ["84282.89", "0.115584"], ["84283.13", "0"], ["84283.63", "0"], ["84284.59", "0"], ["84285.57", "0"], ["84286.4", "0"], ["84286.94", "0"], ["84287.04", "0.140035"], ["84287.22", "0.047905"], ["84289.15", "0.176997"], ["84289.32", "0.000989"], ["84290.07", "0.03181"], ["84290.65", "0.177704"], ["84291.08", "0.162"], ["84291.46", "0"], ["84292.75", "0.131403"], ["84292.95", "0.167098"], ["84293.28", "0.160542"], ["84294.09", "0"], ["84294.23", "0.237355"], ["84296.95", "0.619446"], ["84296.98", "0.288569"], ["84297.02", "0.237344"], ["84297.1", "0.237344"], ["84298.44", "0.237344"], ["84298.47", "0.2776"], ["84299.29", "0"], ["84300.77", "0.300044"], ["84301.23", "0.237344"], ["84301.32", "0.117194"], ["84302.05", "0"], ["84302.66", "0.237344"], ["84303.45", "0.293241"], ["84304.27", "0"], ["84310.3", "0"], ["84310.42", "0.04"], ["84310.43", "0.04"], ["84310.62", "0"], ["84310.63", "0"], ["84314.19", "0.356059"], ["84315.93", "0"], ["84315.95", "0"], ["84316.26", "0"], ["84316.41", "0"], ["84316.48", "0"], ["84316.61", "0"], ["84316.68", "0"], ["84316.78", "0"], ["84316.88", "0"], ["84316.97", "0"], ["84317.08", "0"], ["84317.19", "0"], ["84317.23", "0"]], "u": 7510621, "seq": 66889302410}, "cts": 1742142220207, "record_time": 1742142219.309988}
{"topic": "orderbook.200.BTCUSDT", "ts": 1742142220409, "type": "delta", "data": {"s": "BTCUSDT", "b": [["84265.78", "0.89234"], ["84264.2", "0.021423"], ["84264.19", "0.07121"], ["84262.15", "0.000099"], ["84262.14", "0"], ["84255.47", "0.012"], ["84255.46", "0.02"], ["84255", "0.02"], ["84254.3", "0.109022"], ["84254.14", "0"], ["84254.03", "0"], ["84253.85", "0"], ["84253.56", "0"], ["84253.4", "0.02"], ["84253", "0"], ["84252.36", "0"], ["84251.4", "0"], ["84249.79", "0"], ["84246.46", "0.237344"], ["84246.1", "0"], ["84246.03", "0"], ["84243.18", "0"], ["84242.25", "0.237344"], ["84241.5", "0"], ["84238.7", "0.300789"], ["84238.27", "0"], ["84238.2", "0"], ["84236.84", "0.269554"], ["84235.8", "0.000335"], ["84234.39", "1.44649"], ["84233.06", "0.277169"], ["84233", "0"], ["84226.82", "0.178008"], ["84219.66", "0"], ["84216.98", "0.356042"], ["84215.02", "0"], ["84212.4", "0.001243"], ["84211.9", "0.001333"], ["84211.85", "0.000613"], ["84210.81", "0.023733"]], "a": [["84265.79", "0.023514"], ["84268.82", "0.071206"], ["84272.52", "0"], ["84275.11", "0"], ["84276.61", "0"], ["84280.08", "0.105284"], ["84282.32", "0"], ["84282.7", "0"], ["84282.82", "0"], ["84282.89", "0"], ["84282.9", "0"], ["84284.3", "0"], ["84284.7", "0"], ["84286.3", "0"], ["84288", "0"], ["84289.15", "0"], ["84289.3", "0"], ["84289.59", "0.168048"], ["84289.6", "0"], ["84290.65", "0"], ["84290.9", "0.06"], ["84292.95", "0"], ["84293.28", "0"], ["84294.23", "0"], ["84296.98", "0"], ["84297.42", "0.263259"], ["84298.47", "0"], ["84299.18", "0"], ["84300.77", "0"], ["84301.73", "1.395803"], ["84301.82", "0.276666"], ["84303.45", "0"], ["84314.19", "0"], ["84315.93", "0.11863"], ["84315.95", "0.001243"], ["84316.26", "0.0002"], ["84316.41", "0.009"], ["84316.61", "0.004753"], ["84316.68", "0.0045"], ["84316.78", "0.001467"], ["84316.88", "0.0045"], ["84316.97", "0.005"], ["84317.19", "0.000612"], ["84317.23", "0.001333"], ["84317.25", "0.000111"], ["84317.88", "0.003"], ["84318.79", "0.0002"], ["84319.01", "0.000235"], ["84319.53", "0.000235"], ["84319.54", "0.00315"], ["84320", "0.000113"], ["84320.25", "0.0045"]], "u": 7510622, "seq": 66889303174}, "cts": 1742142220408, "record_time": 1742142219.520033}
{"topic": "orderbook.200.BTCUSDT", "ts": 1742142220609, "type": "delta", "data": {"s": "BTCUSDT", "b": [["84265.78", "1.24634"], ["84255.67", "0.01206"], ["84255.66", "0.02"], ["84255.55", "0.114569"], ["84255.47", "0"], ["84255.46", "0"], ["84255.26", "0.109853"], ["84255.1", "0.02"], ["84255", "0"], ["84254.3", "0.090099"], ["84253.6", "0.02"], ["84253.44", "0.119524"], ["84253.4", "0"], ["84253.03", "0.02"], ["84252.2", "0.237383"], ["84250.93", "0"], ["84247.43", "0.180551"], ["84245.67", "0.17252"], ["84244.59", "0.178803"], ["84243.67", "0.237344"], ["84241.9", "0"], ["84240.69", "0.715935"], ["84238.7", "0"], ["84236.84", "0"], ["84235.24", "0"], ["84234.41", "0.293262"], ["84233.06", "0"], ["84221.71", "0.363705"], ["84221.7", "0.039641"], ["84221.61", "0"], ["84221.6", "0"], ["84218.69", "0.356038"], ["84216.98", "0"], ["84212.4", "0"], ["84211.9", "0"], ["84211.85", "0"], ["84210.81", "0"]], "a": [["84268.74", "0.071206"], ["84268.82", "0"], ["84272.64", "0.000233"], ["84280.08", "0"], ["84282.83", "0"], ["84283.73", "0.117132"], ["84283.97", "0.118612"], ["84284.23", "0.111014"], ["84284.44", "0.130799"], ["84286.95", "0.008453"], ["84287.16", "0.105367"], ["84287.69", "0.023514"], ["84288.2", "0.044"], ["84288.3", "0.06"], ["84289.59", "0"], ["84289.65", "0"], ["84290", "0.068"], ["84290.07", "0"], ["84290.23", "0.175491"], ["84293.3", "0.056"], ["84293.88", "0"], ["84294.3", "0.048"], ["84294.7", "0.048"], ["84295.71", "0.008859"], ["84296.95", "0.13445"], ["84297.02", "0"], ["84297.1", "0"], ["84297.42", "0"], ["84299.88", "0.268013"], ["84301.23", "0"], ["84301.32", "0"], ["84301.82", "0"], ["84304.44", "0.03181"], ["84304.86", "0.276469"], ["84319.53", "0"], ["84319.54", "0"], ["84320", "0"], ["84320.25", "0"]], "u": 7510623, "seq": 66889303785}, "cts": 1742142220607, "record_time": 1742142219.708989}
{"topic": "orderbook.200.BTCUSDT", "ts": 1742142220809, "type": "delta", "data": {"s": "BTCUSDT", "b": [["84266.64", "1.211105"], ["84266.61", "0.034719"], ["84266.6", "0.103262"], ["84265.79", "0.0004"], ["84265.78", "0"], ["84264.2", "0"], ["84264.19", "0"], ["84262.44", "0.001333"], ["84262.4", "0.000613"], ["84259.96", "0.02"], ["84259.5", "0.02"], ["84259.35", "0.027047"], ["84259.34", "0.089922"], ["84258.21", "0.0005"], ["84258.07", "0.11773"], ["84258.06", "0.120213"], ["84257.8", "0.02"], ["84257.78", "0.106264"], ["84257.35", "0"], ["84256.4", "0.116118"], ["84256.01", "0.121382"], ["84255.67", "0"], ["84255.66", "0"], ["84255.55", "0"], ["84255.26", "0"], ["84255.23", "0.02"], ["84255.1", "0"], ["84254.3", "0"], ["84253.6", "0"], ["84253.44", "0"], ["84253.03", "0"], ["84252.2", "0"], ["84251.15", "0.000546"], ["84250.63", "0.089922"], ["84250.52", "0.0002"], ["84250.14", "0.175799"], ["84250.03", "0.237389"], ["84249.95", "0.167596"], ["84248.18", "0.167657"], ["84248.11", "0"], ["84247.43", "0"], ["84247.11", "0.17629"], ["84246.46", "0"], ["84245.67", "0"], ["84245.47", "0.0002"], ["84244.6", "0"], ["84244.59", "0"], ["84243.37", "0.017799"], ["84242.31", "0.2754"], ["84242.25", "0"], ["84242.13", "0.293422"], ["84240.35", "0.288374"], ["84239.46", "0"], ["84238.97", "0.094633"], ["84237.88", "0"], ["84236.93", "0.301851"], ["84234.41", "0"], ["84231.02", "0.023734"], ["84229.94", "0.005933"], ["84229.22", "0"], ["84227.66", "0.023734"], ["84225.06", "0.023734"], ["84224.26", "0.023734"], ["84219.68", "0.356027"], ["84219.26", "0.023734"], ["84219.2", "0.24702"], ["84218.69", "0"], ["84216.62", "0.000989"], ["84215.76", "0"], ["84214.65", "0"], ["84214.59", "0"], ["84214.47", "0"], ["84214.46", "0"], ["84214.17", "0"], ["84214", "0"], ["84213.69", "0"], ["84213.09", "0"], ["84212.93", "0"], ["84212.62", "0"], ["84212.41", "0"]], "a": [["84265.79", "0"], ["84266.61", "0"], ["84266.65", "0.010186"], ["84268.74", "0"], ["84270.44", "0"], ["84274.08", "0"], ["84275.07", "0.03498"], ["84275.08", "0.001833"], ["84276.6", "0.000296"], ["84276.61", "0.028642"], ["84276.84", "0"], ["84278.32", "0"], ["84279.68", "0.059948"], ["84282.18", "0.011866"], ["84283.73", "0"], ["84283.97", "0"], ["84284.16", "0.000252"], ["84284.23", "0"], ["84284.44", "0.231429"], ["84286.25", "0.112124"], ["84286.75", "0.120725"], ["84286.93", "0.110067"], ["84287.16", "0"], ["84287.69", "0"], ["84288.2", "0"], ["84288.3", "0"], ["84288.71", "0"], ["84289.32", "0"], ["84289.67", "0.104977"], ["84290", "0"], ["84290.18", "0.000989"], ["84290.23", "0"], ["84290.9", "0"], ["84291.08", "0"], ["84293", "0.044"], ["84293.2", "0.223848"], ["84293.3", "0"], ["84293.92", "0"], ["84294.3", "0"], ["84294.54", "0"], ["84294.57", "0.161319"], ["84294.7", "0"], ["84295.4", "0.005"], ["84295.71", "0"], ["84296.47", "0"], ["84296.75", "0.017796"], ["84296.85", "0"], ["84297.21", "0.16301"], ["84297.5", "0.162399"], ["84299.19", "0"], ["84299.56", "0"], ["84299.6", "0.048"], ["84299.88", "0"], ["84300.21", "0"], ["84301.02", "0.270296"], ["84302.4", "0.291898"], ["84303.67", "0.023537"], ["84304.44", "0"], ["84304.86", "0"], ["84305.32", "0.270143"], ["84305.56", "0.023734"], ["84307.38", "0.286408"], ["84307.53", "0"], ["84310.42", "0"], ["84310.43", "0"], ["84312.12", "0.04"], ["84312.13", "0.04"], ["84313.42", "0"], ["84315.71", "0.03181"], ["84316.24", "0.005933"], ["84319.41", "0.356277"], ["84319.53", "0.000235"], ["84319.54", "0.00315"], ["84320", "0.000113"], ["84320.25", "0.0045"], ["84320.31", "0.059309"], ["84320.33", "0.0045"], ["84320.45", "0.0045"], ["84320.48", "0.00593"], ["84320.54", "0.0045"]], "u": 7510624, "seq": 66889305322}, "cts": 1742142220807, "record_time": 1742142219.908989}
{"topic": "orderbook.200.BTCUSDT", "ts": 1742142221010, "type": "delta", "data": {"s": "BTCUSDT", "b": [["84266.64", "0.263731"], ["84266.61", "0"], ["84266.6", "0.030468"], ["84265.79", "0"], ["84262.44", "0.005704"], ["84262.15", "0"], ["84261.79", "0.022489"], ["84261.78", "0.071212"], ["84261.18", "0"], ["84259.96", "0"], ["84259.5", "0"], ["84259.35", "0"], ["84259.34", "0"], ["84258.37", "0.026534"], ["84258.36", "0.02"], ["84258.07", "0"], ["84258.06", "0"], ["84257.78", "0"], ["84256.4", "0"], ["84256.1", "0.02"], ["84256.01", "0"], ["84255.92", "0.115788"], ["84255.73", "0.02"], ["84255.64", "0.108482"], ["84255.23", "0"], ["84254.63", "0.00105"], ["84254.35", "0.10603"], ["84254.32", "0.077237"], ["84253.22", "0.116602"], ["84251.93", "0.237383"], ["84251.15", "0.000297"], ["84250.63", "0"], ["84250.5", "0.011866"], ["84250.17", "0.237637"], ["84250.14", "0"], ["84250.03", "0"], ["84249.95", "0"], ["84248.18", "0"], ["84248.08", "0.157613"], ["84247.81", "0.168654"], ["84247.11", "0"], ["84245.39", "0.162084"], ["84244.96", "0.17645"], ["84243.67", "0"], ["84243.37", "0"], ["84242.32", "0.059948"], ["84242.31", "0"], ["84242.27", "0"], ["84242.13", "0"], ["84240.35", "0"], ["84240.26", "0.296538"], ["84239.98", "0.271209"], ["84238.97", "0.023402"], ["84237.87", "0.0178"], ["84236.93", "0"], ["84234.79", "0.274961"], ["84233.43", "0.071236"], ["84233.05", "0"], ["84229.63", "0"], ["84227", "0.071241"], ["84221.71", "0.323705"], ["84221.7", "0"], ["84221.52", "0.04"], ["84221.51", "0.039642"], ["84219.69", "0.11863"], ["84219.68", "0"], ["84219.67", "0"], ["84216.97", "0.005"], ["84214.65", "0.000252"], ["84214.59", "0.004586"], ["84214.47", "0.11863"], ["84214.17", "0.023733"]], "a": [["84266.65", "0.081394"], ["84267.83", "0.000153"], ["84269.42", "0"], ["84275.04", "0.029255"], ["84275.07", "0.04906"], ["84276.61", "0.089955"], ["84277.94", "0.011866"], ["84282.18", "0"], ["84284.1", "0.113634"], ["84284.44", "0.265475"], ["84284.6", "0.119221"], ["84284.88", "0.106669"], ["84285.58", "0.008453"], ["84286.25", "0"], ["84286.75", "0"], ["84286.88", "0.10928"], ["84286.93", "0"], ["84286.95", "0"], ["84287.3", "0.044"], ["84288.7", "0.117754"], ["84289.2", "0.0606"], ["84289.3", "0.068"], ["84289.67", "0"], ["84290", "0.010186"], ["84290.8", "0.068"], ["84290.9", "0.056"], ["84291.14", "0.16958"], ["84291.44", "0.089922"], ["84291.94", "0.163333"], ["84292.14", "0.071186"], ["84292.15", "0.03181"], ["84292.43", "0.162848"], ["84293.2", "0.06"], ["84294.57", "0"], ["84294.71", "0.163379"], ["84295.06", "0.159008"], ["84297.21", "0"], ["84297.5", "0"], ["84298.97", "0.27942"], ["84299.78", "0.008839"], ["84300.26", "0.273822"], ["84301.02", "0"], ["84302.4", "0"], ["84303.48", "0.029801"], ["84305.24", "0.265439"], ["84305.32", "0"], ["84305.68", "0"], ["84307.38", "0"], ["84312.12", "0"], ["84312.13", "0"], ["84312.31", "0.04"], ["84312.32", "0.04"], ["84314.19", "0.356055"], ["84315.71", "0"], ["84319.53", "0"], ["84319.54", "0"], ["84320", "0"], ["84320.25", "0"], ["84320.31", "0"], ["84320.33", "0"], ["84320.45", "0"], ["84320.48", "0"], ["84320.54", "0"]], "u": 7510625, "seq": 66889306215}, "cts": 1742142221006, "record_time": 1742142220.108989}
{"topic": "orderbook.200.BTCUSDT", "ts": 1742142221210, "type": "delta", "data": {"s": "BTCUSDT", "b": [["84266.61", "0.012761"], ["84264.3", "0.07121"], ["84263.01", "0.000099"], ["84261.79", "0.025489"], ["84261.78", "0"], ["84260.56", "0.02"], ["84259.49", "0.02"], ["84258.4", "0.02"], ["84258.37", "0.088791"], ["84258.36", "0"], ["84257.83", "0.02"], ["84257.8", "0"], ["84256.1", "0"], ["84255.92", "0"], ["84255.73", "0"], ["84255.64", "0"], ["84254.35", "0"], ["84254.32", "0.133534"], ["84253.22", "0"], ["84253.04", "0.118575"], ["84251.14", "0.000546"], ["84250.67", "0.237342"], ["84250.17", "0.237388"], ["84249.7", "0.23739"], ["84248.08", "0"], ["84247.81", "0"], ["84246.46", "0.237342"], ["84246.29", "0"], ["84245.39", "0"], ["84245.18", "0.158713"], ["84244.96", "0"], ["84243.67", "0.237342"], ["84240.26", "0"], ["84239.98", "0"], ["84239.46", "0.237342"], ["84237.31", "0.295504"], ["84234.79", "0"], ["84222.9", "0.356023"], ["84214.46", "0.162"]], "a": [["84270.28", "0.000099"], ["84276.61", "0"], ["84284.02", "0.033004"], ["84284.1", "0"], ["84284.43", "0.199322"], ["84284.44", "0"], ["84284.6", "0"], ["84284.88", "0"], ["84285.7", "0.044"], ["84285.9", "0.06"], ["84286.88", "0.116871"], ["84291.14", "0"], ["84292.14", "0"], ["84292.3", "0.048"], ["84292.43", "0"], ["84292.6", "0.048"], ["84293", "0"], ["84294.71", "0"], ["84294.75", "0.176956"], ["84295.06", "0"], ["84298.97", "0"], ["84299.15", "0.023923"], ["84299.6", "0"], ["84300.26", "0"], ["84301.63", "0.071178"], ["84302.61", "0.273237"], ["84303.67", "0"], ["84305.24", "0"], ["84314.19", "0"], ["84316.78", "0.00482"], ["84317.88", "0"], ["84318.08", "0.237342"], ["84319.53", "0.000235"], ["84319.54", "0.00315"], ["84320", "0.000113"], ["84320.25", "0.0045"], ["84320.31", "0.059309"], ["84320.33", "0.0045"]], "u": 7510626, "seq": 66889306451}, "cts": 1742142221207, "record_time": 1742142220.309076}
{"topic": "orderbook.200.BTCUSDT", "ts": 1742142221410, "type": "delta", "data": {"s": "BTCUSDT", "b": [["84275.04", "0.24508"], ["84275.03", "0.001186"], ["84273.34", "0.070874"], ["84273.33", "0.089922"], ["84273.16", "0.071202"], ["84270.82", "0.000613"], ["84270.75", "0.0002"], ["84270.42", "0.0004"], ["84270.25", "0.000252"], ["84268.53", "0.000633"], ["84268.52", "0.03"], ["84268.22", "0.0002"], ["84268.01", "0.000233"], ["84266.65", "0.091877"], ["84266.64", "0.126191"], ["84266.61", "0.001113"], ["84265.78", "0.001467"], ["84265.69", "0.0002"], ["84265.61", "0.000252"], ["84264.95", "0"], ["84264.3", "0"], ["84263.9", "0.000233"], ["84263.37", "0.000233"], ["84262.44", "0.001333"], ["84262.01", "0"], ["84261.8", "0.22341"], ["84261.79", "0.003"], ["84261.4", "0.02"], ["84261.04", "0.011865"], ["84260.65", "0.089922"], ["84260.56", "0"], ["84260.4", "0.000089"], ["84259.8", "0.02"], ["84259.49", "0"], ["84259.46", "0.02"], ["84259.4", "0.04"], ["84259.15", "0.177559"], ["84259.1", "0.237331"], ["84258.4", "0"], ["84258.37", "0"], ["84258.33", "0.000249"], ["84258.21", "0"], ["84257.83", "0"], ["84256.83", "0.02"], ["84256.5", "0.23737"], ["84256.3", "0.162"], ["84254.93", "0.015089"], ["84254.15", "0.237377"], ["84253.59", "0.068395"], ["84253.04", "0"], ["84252.9", "0.04"], ["84252.82", "0.060361"], ["84252.6", "0.04"], ["84252.4", "0"], ["84251.93", "0"], ["84251.79", "0.089922"], ["84251.14", "0.000297"], ["84250.67", "0"], ["84250.5", "0"], ["84250.17", "0"], ["84248.4", "0.017798"], ["84247.34", "0"], ["84246.46", "0"], ["84246.07", "0.071225"], ["84246.05", "0"], ["84245.18", "0"], ["84241.53", "0.140028"], ["84239.9", "0.07123"], ["84238.04", "0.177998"], ["84237.87", "0"], ["84237.32", "0.355969"], ["84237.31", "0"], ["84234.46", "0.44361"], ["84234.45", "0"], ["84233.43", "0"], ["84227", "0"], ["84225.07", "0.11863"], ["84222.9", "0"], ["84219.28", "0"], ["84219.26", "0"], ["84219.2", "0"], ["84218.68", "0"], ["84218.63", "0"], ["84218.15", "0"], ["84217.71", "0"], ["84217.67", "0"], ["84217.56", "0"], ["84217.45", "0"], ["84217.16", "0"], ["84217.04", "0"], ["84216.97", "0"], ["84216.62", "0"], ["84216.11", "0"], ["84216.07", "0"], ["84215.14", "0"], ["84214.81", "0"], ["84214.65", "0"], ["84214.59", "0"], ["84214.47", "0"], ["84214.46", "0"], ["84214.17", "0"]], "a": [["84266.65", "0"], ["84267.83", "0"], ["84268.01", "0"], ["84268.22", "0"], ["84268.53", "0"], ["84270.25", "0"], ["84270.28", "0"], ["84270.42", "0"], ["84270.45", "0"], ["84270.75", "0"], ["84270.82", "0"], ["84270.87", "0"], ["84272.64", "0"], ["84273.17", "0"], ["84273.27", "0"], ["84274.88", "0"], ["84275.04", "0"], ["84275.05", "0.002653"], ["84275.07", "0"], ["84276.6", "0"], ["84276.62", "0"], ["84276.78", "0"], ["84277.94", "0"], ["84279.09", "0.071197"], ["84279.42", "0"], ["84279.68", "0"], ["84279.7", "0"], ["84282.88", "0.011865"], ["84284.02", "0"], ["84284.42", "0.000296"], ["84284.43", "0"], ["84285.29", "0.000296"], ["84285.58", "0"], ["84285.7", "0"], ["84285.9", "0"], ["84286.88", "0"], ["84287.04", "0"], ["84287.3", "0"], ["84289.11", "0.008453"], ["84289.2", "0.0006"], ["84289.3", "0"], ["84290", "0"], ["84290.36", "0"], ["84290.8", "0"], ["84290.9", "0"], ["84290.98", "0"], ["84291.44", "0"], ["84291.94", "0.001333"], ["84292.03", "0"], ["84292.15", "0"], ["84292.3", "0"], ["84292.6", "0"], ["84292.75", "0"], ["84293.19", "0.085805"], ["84293.2", "0"], ["84293.9", "0.06"], ["84294.4", "0.06"], ["84294.75", "0"], ["84295.4", "0"], ["84295.52", "0.017798"], ["84298.02", "0.068395"], ["84298.09", "0"], ["84298.2", "0.048"], ["84298.44", "0"], ["84299.15", "0"], ["84299.78", "0"], ["84300.8", "0.048"], ["84301.1", "0.698392"], ["84301.63", "0"], ["84302.61", "0"], ["84302.66", "0"], ["84303.48", "0"], ["84307.01", "0"], ["84307.69", "0.071173"], ["84311.08", "0"], ["84311.47", "0.07117"], ["84312.31", "0"], ["84312.32", "0"], ["84315.77", "0.001281"], ["84317.46", "0.03181"], ["84317.75", "0.026414"], ["84318.08", "0"], ["84320.28", "0.162"], ["84320.45", "0.0045"], ["84320.48", "0.00593"], ["84320.59", "0.059079"], ["84320.71", "0.04"], ["84320.72", "0.04"], ["84321.15", "0.009"], ["84321.25", "0.000253"], ["84321.31", "0.059948"], ["84321.32", "0.0002"], ["84321.35", "0.009"], ["84321.4", "0.000612"], ["84321.42", "0.001467"], ["84321.45", "0.001333"], ["84321.67", "0.11863"], ["84321.97", "0.000089"], ["84322", "0.0006"], ["84322.56", "0.003"], ["84323.14", "0.023733"], ["84323.31", "0.023728"], ["84323.65", "0.000235"], ["84323.71", "0.023728"], ["84323.85", "0.0002"], ["84324.17", "0.000235"], ["84325.29", "0.431384"], ["84325.51", "0.089922"], ["84325.56", "0.029801"], ["84325.62", "0.000612"], ["84325.66", "0.001333"], ["84325.89", "0.000253"], ["84325.92", "0.023728"], ["84326", "0.000119"], ["84326.06", "0.001467"], ["84326.07", "0.068395"], ["84326.38", "0.0002"], ["84326.41", "0.001347"], ["84328.04", "0.237306"], ["84328.28", "0.000235"], ["84328.81", "0.000235"], ["84329.28", "0.023728"], ["84329.43", "1.780162"], ["84329.5", "0.0006"], ["84329.55", "0.009"], ["84329.75", "0.009"]], "u": 7510627, "seq": 66889308120}, "cts": 1742142221407, "record_time": 1742142220.509998}
{"topic": "orderbook.200.BTCUSDT", "ts": 1742142221609, "type": "delta", "data": {"s": "BTCUSDT", "b": [["84281.77", "0.298858"], ["84278.33", "0.0002"], ["84277.86", "0.011865"], ["84275.8", "0.004992"], ["84275.79", "0.0052"], ["84275.08", "0.001333"], ["84275.05", "0.001467"], ["84275.04", "0.000613"], ["84275.03", "0"], ["84274.88", "0.000252"], ["84274.49", "0.004371"], ["84273.34", "0.0005"], ["84273.33", "0"], ["84273.27", "0.0002"], ["84273.17", "0.000233"], ["84273.16", "0"], ["84272.64", "0.000233"], ["84270.87", "0.001333"], ["84270.47", "0.10233"], ["84270.42", "0.001867"], ["84268.85", "0.000089"], ["84268.52", "0"], ["84268.49", "0.108173"], ["84267.53", "0.237299"], ["84266.66", "0.084563"], ["84266.65", "0.001733"], ["84266.61", "0.162613"], ["84265.54", "0.011864"], ["84265.32", "0.005932"], ["84265.04", "0.237346"], ["84264.76", "0.02"], ["84264.7", "0.02"], ["84264.13", "0.02"], ["84263.35", "0.237351"], ["84263.31", "0.237299"], ["84263.1", "0.02"], ["84263.01", "0"], ["84262.2", "0.157938"], ["84262.18", "0.019233"], ["84262.13", "0.02"], ["84261.8", "0.223659"], ["84261.73", "0"], ["84261.4", "0"], ["84261.04", "0"], ["84259.8", "0.04"], ["84259.73", "0.015087"], ["84259.46", "0"], ["84259.27", "0.169915"], ["84259.15", "0"], ["84259.1", "0"], ["84258.33", "0"], ["84258.1", "0.04"], ["84257.72", "0"], ["84257.62", "0.06035"], ["84257.6", "0.04"], ["84257", "0.237369"], ["84256.83", "0"], ["84256.51", "0.126313"], ["84256.5", "0"], ["84256.31", "0.237299"], ["84256", "0.041243"], ["84254.93", "0"], ["84254.33", "0.059948"], ["84254.3", "0.08"], ["84254.15", "0"], ["84252.9", "0.057797"], ["84252.82", "0"], ["84252.1", "0.237299"], ["84251.03", "0.297925"], ["84249.7", "0"], ["84249.6", "0"], ["84249.42", "0.02373"], ["84248.4", "0"], ["84248.2", "0"], ["84247.8", "0"], ["84245.3", "0"], ["84244.5", "0"], ["84244.21", "0"], ["84243.67", "0"], ["84243", "0"], ["84239.46", "0"], ["84239.29", "0"], ["84237.32", "0"], ["84236.65", "0"], ["84234.47", "0.474608"], ["84230.1", "0.004573"], ["84223.3", "0.248263"], ["84222.2", "0"], ["84222.01", "0"], ["84221.71", "0"], ["84221.67", "0"], ["84221.52", "0"], ["84221.51", "0"], ["84220.71", "0"], ["84220.32", "0"], ["84220.28", "0"], ["84220.2", "0"], ["84219.69", "0"], ["84219.45", "0"]], "a": [["84275.05", "0"], ["84275.08", "0"], ["84275.8", "0"], ["84277.28", "0"], ["84277.8", "0"], ["84278.33", "0"], ["84279.09", "0"], ["84279.25", "0"], ["84279.3", "0"], ["84279.52", "0"], ["84279.69", "0"], ["84280.34", "0"], ["84280.86", "0"], ["84282.88", "0"], ["84283.48", "0.0005"], ["84283.53", "0.020999"], ["84284.22", "0.04906"], ["84284.42", "0"], ["84285.29", "0"], ["84285.3", "0"], ["84285.64", "0.083995"], ["84287.22", "0"], ["84287.86", "0"], ["84287.93", "0"], ["84288.05", "0.011865"], ["84288.7", "0"], ["84288.97", "0"], ["84289.11", "0"], ["84290.39", "0.001477"], ["84290.52", "0"], ["84291.06", "0.054477"], ["84293.19", "0"], ["84293.9", "0"], ["84293.95", "0.008453"], ["84294.4", "0"], ["84295.24", "0"], ["84295.52", "0"], ["84296.95", "0"], ["84297.03", "0.004747"], ["84297.69", "0.093325"], ["84298.2", "0"], ["84298.5", "0.044"], ["84298.7", "0.068"], ["84299.12", "0"], ["84299.18", "0.112215"], ["84300.69", "0.041527"], ["84300.8", "0"], ["84301.69", "0.023767"], ["84301.96", "0.004584"], ["84302", "0.056"], ["84302.1", "0.06"], ["84302.45", "0"], ["84302.8", "0.068"], ["84303.42", "0"], ["84305.48", "0.173991"], ["84305.56", "0"], ["84306.45", "0"], ["84306.85", "0"], ["84306.93", "0.009462"], ["84307.69", "0"], ["84308.26", "0.000789"], ["84309.06", "0"], ["84310.31", "0.019075"], ["84310.87", "0"], ["84311.08", "0.237299"], ["84312.42", "0"], ["84313.34", "0.280612"], ["84315.07", "0.023729"], ["84315.3", "0.237299"], ["84316.24", "0"], ["84316.34", "0.29656"], ["84316.51", "0.013753"], ["84317.39", "0.071165"], ["84319.85", "0.275406"], ["84320.71", "0"], ["84320.72", "0"], ["84322.02", "0.04"], ["84322.03", "0.04"], ["84325.74", "0.005932"], ["84328.71", "0.162"], ["84328.91", "0.0002"], ["84329.84", "0.000612"], ["84329.88", "0.001333"], ["84329.99", "0.059948"], ["84330", "0.19987"], ["84330.48", "0.000089"], ["84330.53", "0.000253"], ["84330.69", "0.001467"], ["84331.43", "0.001614"], ["84331.44", "0.0002"]], "u": 7510628, "seq": 66889309910}, "cts": 1742142221607, "record_time": 1742142220.709172}
{"topic": "orderbook.200.BTCUSDT", "ts": 1742142221809, "type": "delta", "data": {"s": "BTCUSDT", "b": [["84283.5", "0.275999"], ["84283.47", "0.003556"], ["84283.36", "0.08215"], ["84283.35", "0.260808"], ["84281.77", "0.000961"], ["84281.07", "0.011865"], ["84280.86", "0.0002"], ["84279.25", "0.000613"], ["84278.56", "0.030124"], ["84278.55", "0.089922"], ["84278.25", "0.000099"], ["84277.86", "0"], ["84277.8", "0.000233"], ["84277.7", "0.00437"], ["84277.28", "0.000233"], ["84275.8", "0.0002"], ["84275.79", "0.005"], ["84274.49", "0"], ["84274.14", "0.113304"], ["84273.47", "0.0005"], ["84273.34", "0"], ["84272.3", "0.108115"], ["84270.47", "0"], ["84270.32", "0.011864"], ["84270.12", "0.02"], ["84269.21", "0.041117"], ["84269.2", "0.04"], ["84269.18", "0.015085"], ["84269.1", "0.02"], ["84268.86", "0.02"], ["84268.8", "0.04"], ["84268.49", "0"], ["84268.4", "0.02"], ["84267.83", "0.000817"], ["84267.59", "0.009541"], ["84267.53", "0"], ["84267.1", "0.04"], ["84267.07", "0.060592"], ["84266.66", "0"], ["84266.62", "0.295637"], ["84266.23", "0.02"], ["84266.15", "0.164566"], ["84265.54", "0"], ["84265.04", "0"], ["84264.76", "0"], ["84264.7", "0"], ["84264.31", "0.160347"], ["84264.13", "0"], ["84263.8", "0.04"], ["84263.35", "0"], ["84263.31", "0"], ["84263.1", "0"], ["84262.4", "0.040613"], ["84262.2", "0"], ["84262.13", "0"], ["84262.1", "0.04"], ["84261.8", "0"], ["84261.77", "0.068395"], ["84259.73", "0"], ["84259.27", "0"], ["84258.16", "0.284319"], ["84257.67", "0.017796"], ["84257.64", "0.00882"], ["84257.62", "0"], ["84257", "0"], ["84256.32", "0.265616"], ["84256.31", "0"], ["84256", "0.089243"], ["84255.91", "0.017796"], ["84254.63", "0.000233"], ["84254.3", "0.04"], ["84253.59", "0"], ["84252.9", "0"], ["84252.6", "0"], ["84252.22", "0.07122"], ["84252.1", "0"], ["84251.03", "0"], ["84250.32", "0"], ["84249.9", "0"], ["84249.21", "0"], ["84248.6", "0"], ["84248.5", "0"], ["84246.8", "0"], ["84246.07", "0"], ["84244.48", "0.02373"], ["84240.7", "0.11863"], ["84240.69", "0"], ["84240.53", "0.323632"], ["84239.91", "0.35596"], ["84239.9", "0"], ["84238.97", "0"], ["84238.04", "0"], ["84234.47", "0.11863"], ["84234.39", "0"], ["84234.2", "0.001843"], ["84231.88", "0.000989"], ["84228.97", "0"], ["84226.82", "0"], ["84226.3", "0.24702"], ["84223.91", "0"], ["84223.3", "0"], ["84223.08", "0"], ["84223", "0"], ["84222.89", "0"], ["84222.72", "0"]], "a": [["84281.91", "0"], ["84282.44", "0"], ["84283.25", "0"], ["84283.39", "0"], ["84283.47", "0"], ["84283.48", "0"], ["84283.51", "0.002519"], ["84283.53", "0"], ["84284.22", "0"], ["84285.43", "0.000099"], ["84285.64", "0"], ["84286.55", "0.000233"], ["84288.05", "0"], ["84288.51", "0.002292"], ["84290.18", "0"], ["84290.33", "0.04906"], ["84290.34", "0.0005"], ["84291.06", "0"], ["84291.07", "0"], ["84292.32", "0"], ["84293.95", "0"], ["84294.22", "0.020996"], ["84296.31", "0.000296"], ["84296.32", "0.083985"], ["84296.75", "0"], ["84297.03", "0"], ["84297.69", "0"], ["84298.02", "0"], ["84298.11", "0.011863"], ["84298.5", "0"], ["84298.7", "0"], ["84299.18", "0"], ["84300.05", "0"], ["84300.47", "0.140027"], ["84300.69", "0.02373"], ["84301.69", "0"], ["84301.73", "0"], ["84302", "0"], ["84302.1", "0"], ["84302.8", "0"], ["84303.2", "0.117494"], ["84303.63", "0.114619"], ["84303.65", "0.008453"], ["84303.71", "0.105364"], ["84305.45", "0.000989"], ["84305.47", "0.056563"], ["84305.48", "0"], ["84306.34", "0.068395"], ["84306.66", "0.108653"], ["84306.93", "0"], ["84308.7", "0.068"], ["84309.05", "0.017796"], ["84310.3", "0.232293"], ["84310.75", "0.017795"], ["84311.08", "0"], ["84311.47", "0"], ["84311.64", "0.02373"], ["84311.7", "0.175527"], ["84311.85", "0"], ["84312", "0.056"], ["84312.7", "0.022698"], ["84313.34", "0"], ["84314.44", "0"], ["84314.65", "0.174252"], ["84315.3", "0"], ["84316.34", "0"], ["84317.39", "0"], ["84317.46", "0"], ["84319.69", "0.283745"], ["84319.85", "0"], ["84320.31", "0"], ["84321.57", "0.005932"], ["84322.02", "0"], ["84322.03", "0"], ["84322.37", "0.071161"], ["84322.64", "0.292902"], ["84325.56", "0"], ["84326.23", "0.017796"], ["84328.43", "0.323295"], ["84330.41", "0.03181"], ["84331.72", "0.04"], ["84331.73", "0.04"], ["84332.38", "0.015"], ["84332.92", "0.000235"], ["84333.14", "0.0025"], ["84333.45", "0.000235"], ["84333.67", "0.029801"], ["84333.97", "0.0002"], ["84334.02", "0.000089"], ["84334.05", "0.000612"], ["84334.06", "0.237306"]], "u": 7510629, "seq": 66889311432}, "cts": 1742142221807, "record_time": 1742142220.909993}
{"topic": "orderbook.200.BTCUSDT", "ts": 1742142222010, "type": "delta", "data": {"s": "BTCUSDT", "b": [["84284.31", "0.324985"], ["84284.16", "0.030628"], ["84284.15", "0.03"], ["84283.51", "0.0004"], ["84283.5", "0"], ["84283.48", "0.011864"], ["84283.47", "0"], ["84283.36", "0"], ["84283.35", "0"], ["84282.31", "0.0003"], ["84281.07", "0"], ["84280.94", "0.071196"], ["84279.52", "0.000252"], ["84279.3", "0.001333"], ["84278.56", "0.072947"], ["84278.55", "0"], ["84278.25", "0"], ["84277.7", "0"], ["84276.91", "0.015083"], ["84276.02", "0.237292"], ["84274.8", "0.060336"], ["84274.7", "0.04"], ["84274.59", "0.153587"], ["84274.58", "0.117188"], ["84274.29", "0.111784"], ["84274.14", "0"], ["84272.48", "0.104956"], ["84272.3", "0"], ["84271.8", "0.057055"], ["84271.26", "0.02"], ["84270.7", "0.02"], ["84270.42", "0.001467"], ["84270.32", "0"], ["84270.13", "0.075412"], ["84270.12", "0.031864"], ["84269.54", "0.068395"], ["84269.21", "0"], ["84269.18", "0"], ["84268.86", "0"], ["84268.63", "0.02"], ["84268.53", "0.000233"], ["84268.4", "0"], ["84268.2", "0.04"], ["84267.9", "0.04"], ["84267.5", "0.04"], ["84267.07", "0"], ["84266.9", "0.04"], ["84266.65", "0.215144"], ["84266.62", "0"], ["84266.29", "0.165345"], ["84266.23", "0"], ["84266.15", "0"], ["84266.09", "0.173696"], ["84265.4", "0.048"], ["84264.31", "0"], ["84263.7", "0.04"], ["84263.39", "0.162909"], ["84262.55", "0.023726"], ["84261.77", "0"], ["84261.12", "0.023729"], ["84260.01", "0"], ["84259.8", "0"], ["84259.4", "0"], ["84258.3", "0.270682"], ["84258.16", "0"], ["84258.1", "0.288798"], ["84257.67", "0"], ["84257.6", "0"], ["84257.48", "0.017796"], ["84256.32", "0"], ["84256", "0.049243"], ["84254.32", "0.077237"], ["84254.3", "0"], ["84253", "0.267446"], ["84249.74", "0.323597"], ["84249.42", "0"], ["84248.93", "0.071223"], ["84246.33", "1.392588"], ["84244.48", "0"], ["84244.31", "0.0013"], ["84240.53", "0"], ["84239.91", "0"], ["84238.04", "0.177969"], ["84234.48", "0.355959"], ["84234.46", "0"], ["84232.8", "0.24702"], ["84231.03", "0.237292"], ["84226.31", "0"], ["84226.3", "0"], ["84225.25", "0"], ["84225.07", "0"], ["84225.06", "0"], ["84225", "0"], ["84224.53", "0"], ["84224.49", "0"], ["84224.26", "0"], ["84224.08", "0"], ["84224.01", "0"]], "a": [["84283.51", "0"], ["84284.16", "0"], ["84284.32", "0.002653"], ["84285.43", "0"], ["84286.55", "0.03062"], ["84288.51", "0"], ["84294.22", "0"], ["84295.82", "0.02799"], ["84296.31", "0"], ["84296.32", "0"], ["84296.44", "0.028049"], ["84297.69", "0.040743"], ["84300.47", "0"], ["84300.69", "0"], ["84301.1", "0.157799"], ["84301.99", "0.020995"], ["84303.2", "0"], ["84303.34", "0.106446"], ["84303.63", "0"], ["84303.65", "0.116829"], ["84303.71", "0"], ["84303.85", "0.117992"], ["84304.09", "0.08398"], ["84306.66", "0"], ["84307", "0.06"], ["84308.5", "0.044"], ["84309.61", "0.162"], ["84309.75", "0.03062"], ["84309.98", "0.023219"], ["84310.04", "0.172193"], ["84310.3", "0.155693"], ["84311.64", "0"], ["84311.7", "0"], ["84311.84", "0.175394"], ["84311.9", "0.068"], ["84313.4", "0.048"], ["84313.7", "0.048"], ["84313.74", "0.023726"], ["84314.19", "0.192198"], ["84314.2", "0"], ["84314.34", "0.03181"], ["84314.53", "0.172263"], ["84314.65", "0"], ["84315.77", "0"], ["84316.46", "0.071166"], ["84316.56", "1.381261"], ["84317.75", "0"], ["84318.03", "0.29268"], ["84318.4", "0.009462"], ["84319.69", "0"], ["84319.83", "0.300551"], ["84320.59", "0"], ["84322.64", "0"], ["84324.92", "0.285105"], ["84326.07", "0"], ["84326.45", "0.474348"], ["84328.43", "0"], ["84329.15", "0.026414"], ["84330.41", "0"], ["84331.72", "0"], ["84331.73", "0"], ["84334.05", "0.356577"]], "u": 7510630, "seq": 66889312246}, "cts": 1742142222006, "record_time": 1742142221.109992}
{"topic": "orderbook.200.BTCUSDT", "ts": 1742142222210, "type": "delta", "data": {"s": "BTCUSDT", "b": [["84284.31", "0.015239"], ["84284.16", "0"], ["84284.15", "0"], ["84283.51", "0"], ["84283.48", "0"], ["84280.94", "0"], ["84280.72", "0.000099"], ["84278.56", "0"], ["84276.02", "0"], ["84275.12", "0.028363"], ["84275.11", "0.000297"], ["84275.09", "0.03155"], ["84274.7", "0"], ["84274.59", "0"], ["84274.58", "0"], ["84274.29", "0"], ["84272.48", "0"], ["84272.16", "0.02"], ["84271.8", "0"], ["84271.56", "0.02"], ["84271.26", "0"], ["84271.12", "0.02"], ["84270.7", "0"], ["84270.13", "0"], ["84270.12", "0"], ["84269.92", "0.02"], ["84269.9", "0.04"], ["84269.54", "0"], ["84269.2", "0"], ["84269.1", "0"], ["84268.8", "0"], ["84268.63", "0"], ["84268.2", "0"], ["84267.9", "0"], ["84267.59", "0"], ["84266.66", "0.351865"], ["84266.65", "0.001333"], ["84266.64", "0"], ["84266.61", "0.000613"], ["84266.29", "0"], ["84266.09", "0"], ["84263.39", "0"], ["84262.55", "0"], ["84262.41", "0.065621"], ["84262.4", "0.000613"], ["84262.1", "0"], ["84261.93", "0.117916"], ["84261.73", "0.02"], ["84260.65", "0"], ["84258.3", "0"], ["84258.1", "0"], ["84257.48", "0"], ["84256.98", "0.170103"], ["84256.51", "0.001467"], ["84256", "0.001243"], ["84254.33", "0"], ["84253.94", "0.174736"], ["84253", "0"], ["84252.22", "0"], ["84251.79", "0"], ["84251.15", "0"], ["84249.71", "0.02373"], ["84248.99", "0.270941"], ["84248.93", "0"], ["84245.95", "0.265765"], ["84240.7", "0"], ["84238.04", "0"], ["84238", "0.071232"], ["84235.24", "0.237292"], ["84234.48", "0"], ["84234.47", "0"], ["84233.5", "0.11863"], ["84226.31", "0.000233"], ["84225.25", "0.0002"], ["84225.07", "0.11863"], ["84225.06", "0.023734"], ["84225", "0.068395"], ["84224.53", "0.001333"], ["84224.49", "0.000614"], ["84224.26", "0.023734"], ["84224.08", "0.001467"], ["84224.01", "0.059948"], ["84223.91", "0.000252"], ["84223.3", "0.001243"], ["84223.08", "0.000085"], ["84223", "0.000119"], ["84222.72", "0.0002"], ["84222.35", "0.352416"], ["84222.2", "0.000233"], ["84221.67", "0.000233"], ["84221.52", "0.04"], ["84221.51", "0.039642"], ["84220.71", "0.008453"], ["84220.32", "0.001333"], ["84220.28", "0.000613"], ["84220.2", "0.0002"]], "a": [["84284.32", "0.081187"], ["84285.15", "0.006293"], ["84285.34", "0.011865"], ["84285.92", "0.029404"], ["84286.05", "0.089922"], ["84286.14", "0.071191"], ["84286.32", "0.03181"], ["84286.53", "0.089994"], ["84286.54", "0.11863"], ["84286.55", "0.000233"], ["84287.91", "0.000099"], ["84288.21", "0.059948"], ["84288.52", "0.011864"], ["84290.32", "0.055423"], ["84291.05", "0.011863"], ["84292.54", "0.11863"], ["84294.54", "0.112773"], ["84295.82", "0.027989"], ["84296.25", "0.029801"], ["84296.44", "0.000089"], ["84297.69", "0.040447"], ["84298.11", "0"], ["84298.53", "0.068395"], ["84298.65", "0.089922"], ["84300.38", "0.02373"], ["84301.1", "0"], ["84301.18", "0.162"], ["84302.64", "0"], ["84303.27", "0.000296"], ["84303.28", "0.200442"], ["84303.34", "0"], ["84303.65", "0"], ["84303.72", "0.071176"], ["84303.85", "0"], ["84304.28", "0.164109"], ["84305.45", "0"], ["84306.34", "0"], ["84306.8", "0.044"], ["84307.88", "0.000989"], ["84309.29", "0.140024"], ["84309.75", "0"], ["84309.82", "0.03062"], ["84309.97", "0.235602"], ["84310.04", "0.005815"], ["84310.3", "0.06"], ["84310.52", "0.269791"], ["84310.75", "0"], ["84311.84", "0"], ["84312.27", "0.297354"], ["84313.39", "0.356036"], ["84313.74", "0"], ["84314.34", "0"], ["84314.53", "0"], ["84316.46", "0"], ["84318.03", "0"], ["84319.83", "0"], ["84322.37", "0"], ["84324.92", "0"], ["84326.07", "0.068395"], ["84330.53", "0"], ["84330.69", "0"], ["84331.43", "0"], ["84331.44", "0"], ["84332.38", "0"], ["84332.92", "0"], ["84333.14", "0"], ["84333.45", "0"], ["84333.67", "0"], ["84333.97", "0"], ["84334.02", "0"], ["84334.05", "0"], ["84334.06", "0"]], "u": 7510631, "seq": 66889312913}, "cts": 1742142222208, "record_time": 1742142221.310044}
{"topic": "orderbook.200.BTCUSDT", "ts": 1742142222409, "type": "delta", "data": {"s": "BTCUSDT", "b": [["84284.31", "0.01699"], ["84282.31", "0"], ["84278.34", "0.030225"], ["84276.91", "0"], ["84275.11", "0"], ["84275.09", "0"], ["84274.8", "0"], ["84272.16", "0"], ["84271.56", "0"], ["84271.12", "0"], ["84269.92", "0"], ["84269.9", "0"], ["84267.51", "0.000297"], ["84267.5", "0"], ["84267.1", "0"], ["84266.94", "0.028119"], ["84266.93", "0.000297"], ["84266.92", "0.028961"], ["84266.91", "0.062679"], ["84266.9", "0.001243"], ["84266.66", "0"], ["84265.4", "0"], ["84265.33", "0.071209"], ["84263.7", "0"], ["84263.37", "0.000482"], ["84262.23", "0.02"], ["84262.06", "0.02"], ["84261.93", "0"], ["84261.73", "0"], ["84261.7", "0.04"], ["84261.56", "0.060345"], ["84261.5", "0.02"], ["84261.12", "0"], ["84258.4", "0.04"], ["84257.64", "0"], ["84256.98", "0"], ["84255.91", "0"], ["84254.68", "0.009541"], ["84254.66", "0.011865"], ["84254.32", "0"], ["84253.94", "0"], ["84252.57", "0.068395"], ["84251.14", "0"], ["84249.74", "0"], ["84249.71", "0"], ["84248.99", "0"], ["84247.88", "0.237292"], ["84245.95", "0"], ["84243.67", "0.237292"], ["84238.85", "0.017798"], ["84238", "0"], ["84236.14", "0.023732"], ["84235.74", "0.017796"], ["84235.24", "0"], ["84234.2", "0.002832"], ["84233.5", "0"], ["84233.25", "0.071236"], ["84231.88", "0"], ["84231.68", "0.11863"], ["84231.03", "0"], ["84228.73", "0.07124"], ["84226.82", "0.177969"], ["84224.02", "0.356025"], ["84222.89", "0.162"], ["84219.69", "0.11863"], ["84219.45", "0.001467"], ["84219.28", "0.000252"], ["84219.26", "0.023734"], ["84218.68", "0.035611"], ["84218.15", "0.00009"]], "a": [["84285.15", "0.011864"], ["84286.32", "0"], ["84290.19", "0.005932"], ["84290.32", "0.105881"], ["84290.83", "0.083993"], ["84292.74", "0.082728"], ["84292.75", "0.162"], ["84294.54", "0"], ["84295.82", "0.000233"], ["84296.25", "0"], ["84297.69", "0.086447"], ["84297.7", "0.16263"], ["84299.4", "0.020996"], ["84299.7", "0.068"], ["84300.06", "0.03181"], ["84300.66", "0.059323"], ["84301.99", "0"], ["84302.68", "0.017798"], ["84303", "0.056"], ["84303.28", "0"], ["84304.09", "0"], ["84304.28", "0"], ["84305.44", "0.019981"], ["84306.87", "0.237292"], ["84308.2", "0.029801"], ["84309.05", "0"], ["84309.82", "0"], ["84310.09", "0.071171"], ["84310.52", "0"], ["84311.08", "0.237292"], ["84312", "0"], ["84312.27", "0"], ["84313.39", "0"], ["84313.87", "0.237292"], ["84313.97", "0.237292"], ["84318.08", "0.237292"], ["84318.18", "0.237292"], ["84319.4", "0.356025"], ["84320.25", "0"], ["84320.45", "0"], ["84321.15", "0.0045"], ["84321.35", "0.0045"], ["84322.6", "0.017796"], ["84323.14", "0"], ["84326.82", "0.323301"], ["84329.55", "0.0045"], ["84329.75", "0"], ["84329.84", "0"], ["84329.88", "0"], ["84329.99", "0"], ["84330", "0"], ["84330.48", "0"]], "u": 7510632, "seq": 66889313862}, "cts": 1742142222407, "record_time": 1742142221.508919}
{"topic": "orderbook.200.BTCUSDT", "ts": 1742142222610, "type": "delta", "data": {"s": "BTCUSDT", "b": [["84284.31", "0.021732"], ["84275.88", "0.0005"], ["84273.47", "0"], ["84267.87", "0.000297"], ["84267.51", "0"], ["84266.96", "0.028759"], ["84266.95", "0.000297"], ["84266.93", "0.052959"], ["84266.92", "0"], ["84266.91", "0"], ["84265.33", "0"], ["84265.04", "0.071209"], ["84263.75", "0.015335"], ["84263.4", "0.04"], ["84263.37", "0.000233"], ["84263.26", "0.02"], ["84262.8", "0.02"], ["84262.1", "0.04"], ["84262.06", "0"], ["84261.5", "0"], ["84261.2", "0.02"], ["84260.63", "0.0202"], ["84260", "0.088"], ["84258.3", "0.04"], ["84257", "0.04"], ["84256.7", "0.04"], ["84252.1", "0.237292"], ["84252.01", "0.173258"], ["84248.36", "0.279696"], ["84246.34", "0.417776"], ["84243.67", "0"], ["84241.58", "0.263706"], ["84240.16", "0.07123"], ["84228.73", "0"], ["84224.03", "0.356027"], ["84224.02", "0"], ["84221.52", "0"], ["84221.51", "0"], ["84220.71", "0"], ["84220.32", "0"], ["84220.28", "0"], ["84220.2", "0"], ["84219.69", "0"], ["84219.45", "0"], ["84219.28", "0"], ["84219.26", "0"], ["84218.68", "0"], ["84218.15", "0"]], "a": [["84284.32", "0.072184"], ["84288.79", "0.02125"], ["84290", "0.008453"], ["84290.34", "0"], ["84292.18", "0.001278"], ["84292.74", "0.050756"], ["84292.75", "0.1625"], ["84294.08", "0.111394"], ["84295.4", "0.06"], ["84297.6", "0.044"], ["84297.69", "0.147935"], ["84298.8", "0.06"], ["84299.4", "0"], ["84300.4", "0.068"], ["84301.8", "0.048"], ["84302.1", "0.048"], ["84303.34", "0.180301"], ["84306.8", "0"], ["84308.5", "0"], ["84308.7", "0"], ["84310.3", "0"], ["84311.9", "0"], ["84312.7", "0"], ["84313.76", "0.267334"], ["84318.08", "0"], ["84318.18", "0"], ["84319.39", "0.356027"], ["84319.4", "0"], ["84329.55", "0"]], "u": 7510633, "seq": 66889314540}, "cts": 1742142222603, "record_time": 1742142221.709017}
{"topic": "orderbook.200.BTCUSDT", "ts": 1742142222809, "type": "delta", "data": {"s": "BTCUSDT", "b": [["84284.31", "0.121732"], ["84278.34", "0"], ["84277.9", "0.000144"], ["84267.12", "0.000297"], ["84267.11", "0.028002"], ["84267.1", "0.000297"], ["84267.09", "0.166448"], ["84266.96", "0"], ["84266.95", "0"], ["84266.94", "0"], ["84266.93", "0"], ["84265.04", "0"], ["84263.8", "0.040249"], ["84263.75", "0.015086"], ["84263.36", "0.02"], ["84263.26", "0"], ["84262.9", "0.02"], ["84262.8", "0"], ["84261.28", "0.237357"], ["84260.73", "0.02"], ["84260.63", "0.0002"], ["84259.59", "0.237362"], ["84254.89", "0.237292"], ["84252.58", "0.059948"], ["84252.01", "0"], ["84250.67", "0.237292"], ["84248.36", "0"], ["84241.58", "0"], ["84238.38", "0.003369"], ["84232.83", "0.0002"], ["84226.83", "0.356251"], ["84224.03", "0"], ["84222.2", "0"], ["84221.67", "0"]], "a": [["84284.32", "0.130369"], ["84285.92", "0.0002"], ["84286.05", "0"], ["84286.56", "0.047452"], ["84290", "0"], ["84292.36", "0.008453"], ["84292.74", "0.020306"], ["84292.75", "0.0005"], ["84294.08", "0"], ["84297.9", "0.059323"], ["84300.38", "0.033192"], ["84303.34", "0"], ["84307", "0"], ["84308.39", "0.237224"], ["84308.44", "0.022597"], ["84309.66", "0.237292"], ["84309.97", "0"], ["84313.4", "0"], ["84313.7", "0"], ["84313.76", "0"], ["84318.4", "0"], ["84319.39", "0"], ["84325.28", "0.356012"], ["84329.55", "0.0045"], ["84329.75", "0.0045"], ["84329.84", "0.000612"], ["84329.88", "0.001333"], ["84329.99", "0.059948"]], "u": 7510634, "seq": 66889314999}, "cts": 1742142222806, "record_time": 1742142221.908362}
{"topic": "orderbook.200.BTCUSDT", "ts": 1742142223010, "type": "delta", "data": {"s": "BTCUSDT", "b": [["84267.87", "0"], ["84267.19", "0.027597"], ["84267.18", "0.000297"], ["84267.17", "0.027699"], ["84267.16", "0.000297"], ["84267.15", "0.0278"], ["84267.13", "0.027901"], ["84267.12", "0"], ["84267.1", "0"], ["84267.09", "0.141891"], ["84265.5", "0.112456"], ["84265.46", "0.119318"], ["84265.2", "0.115579"], ["84263.8", "0.04"], ["84262.41", "0.228243"], ["84259.04", "0.170676"], ["84254.27", "0.168358"], ["84251.02", "0.272517"], ["84249.17", "0.301581"], ["84243.84", "0.276609"], ["84238.04", "0.177969"], ["84224.53", "0"], ["84224.49", "0"], ["84224.26", "0"], ["84224.08", "0"], ["84224.01", "0"], ["84223.91", "0"], ["84223.3", "0"], ["84223.08", "0"], ["84223", "0"], ["84222.89", "0"], ["84222.72", "0"], ["84222.35", "0"]], "a": [["84284.32", "0.138669"], ["84292.36", "0"], ["84292.74", "0.388569"], ["84294.37", "0.111043"], ["84294.88", "0.107699"], ["84296.35", "0.900233"], ["84296.74", "0.106749"], ["84301.17", "0.179189"], ["84302.9", "0.162863"], ["84303.15", "0.167944"], ["84305.6", "0.158227"], ["84306.7", "0.237229"], ["84310.92", "0.290605"], ["84311.17", "0.279022"], ["84316.02", "0.283011"], ["84321.15", "0"], ["84321.35", "0"], ["84329.28", "0"], ["84329.43", "0"], ["84329.5", "0"], ["84329.55", "0"], ["84329.75", "0"], ["84329.84", "0"], ["84329.88", "0"], ["84329.99", "0"]], "u": 7510635, "seq": 66889315319}, "cts": 1742142223004, "record_time": 1742142222.109631}
{"topic": "orderbook.200.BTCUSDT", "ts": 1742142223210, "type": "delta", "data": {"s": "BTCUSDT", "b": [["84284.31", "0.021732"], ["84284.3", "0.0006"], ["84267.2", "0.000297"], ["84267.16", "0"], ["84267.11", "0"], ["84267.09", "0.075945"], ["84265.86", "0.02"], ["84265.5", "0"], ["84265.46", "0"], ["84265.3", "0.020249"], ["84265.2", "0"], ["84264.73", "0.02"], ["84263.7", "0.02"], ["84263.36", "0"], ["84263.23", "0.02"], ["84262.9", "0"], ["84262.23", "0"], ["84262.01", "0.108297"], ["84261.2", "0"], ["84260.73", "0"], ["84259.04", "0"], ["84255.59", "0.169935"], ["84254.89", "0"], ["84254.27", "0"], ["84251.02", "0"], ["84249.17", "0"], ["84247.57", "0.2796"], ["84245", "0.023751"], ["84243.84", "0"], ["84226.83", "0.000233"], ["84226.49", "0"], ["84224.53", "0.001333"], ["84224.49", "0.000614"], ["84224.26", "0.023734"], ["84224.08", "0.001467"], ["84224.01", "0.059948"], ["84223.91", "0.000252"]], "a": [["84284.32", "0.146396"], ["84286.53", "0.092994"], ["84289.57", "0.008453"], ["84292.74", "0.287768"], ["84293.28", "0.113872"], ["84294.37", "0"], ["84294.88", "0"], ["84296.74", "0"], ["84297.25", "0.140028"], ["84297.59", "0.224678"], ["84297.69", "0"], ["84299.7", "0.242953"], ["84301.17", "0.256033"], ["84301.19", "0.003"], ["84302.9", "0"], ["84303.15", "0"], ["84305.6", "0"], ["84307.72", "0.264131"], ["84309.29", "0"], ["84309.65", "0.404008"], ["84309.98", "0"], ["84310.92", "0"], ["84311.17", "0"], ["84311.27", "1.378641"], ["84316.02", "0"], ["84316.56", "0"], ["84321.3", "0.356025"], ["84325.28", "0"], ["84329.28", "0.023728"], ["84329.43", "1.780162"], ["84329.5", "0.0006"], ["84329.84", "0.000612"], ["84329.88", "0.001333"]], "u": 7510636, "seq": 66889315678}, "cts": 1742142223205, "record_time": 1742142222.30866}
{"topic": "orderbook.200.BTCUSDT", "ts": 1742142223410, "type": "delta", "data": {"s": "BTCUSDT", "b": [["84278.34", "0.030226"], ["84269.17", "0.02213"], ["84269.16", "0.071206"], ["84267.18", "0"], ["84267.17", "0"], ["84267.15", "0"], ["84267.13", "0"], ["84266.46", "0.02"], ["84266", "0.02"], ["84265.86", "0"], ["84265.33", "0.020249"], ["84265.3", "0"], ["84264.73", "0"], ["84264.3", "0.02"], ["84263.83", "0.02"], ["84263.7", "0.117644"], ["84263.4", "0.153624"], ["84263.23", "0"], ["84263", "0.115692"], ["84262.01", "0"], ["84256.58", "0.164164"], ["84255.59", "0"], ["84255.38", "0.177901"], ["84254.89", "0.237292"], ["84252.47", "0.159924"], ["84248.56", "0.27721"], ["84247.57", "0"], ["84247.36", "0.283191"], ["84242.04", "0.290355"], ["84226.42", "0.11"], ["84225.08", "0.356017"], ["84225", "0"], ["84224.53", "0"], ["84224.49", "0"], ["84224.26", "0"], ["84224.08", "0"], ["84224.01", "0"], ["84223.91", "0"]], "a": [["84284.32", "0.162366"], ["84287.48", "0.023729"], ["84289.57", "0"], ["84289.75", "0.023729"], ["84290.32", "0.116448"], ["84290.91", "0.118646"], ["84292.57", "0.117083"], ["84293.08", "0.112503"], ["84293.28", "0"], ["84294.28", "0.117337"], ["84296.35", "0.000233"], ["84296.71", "0.059323"], ["84299.7", "0.068"], ["84300.69", "0.176878"], ["84301.1", "0.166237"], ["84301.17", "0.179189"], ["84302.77", "0.23724"], ["84303.79", "0.172896"], ["84304.46", "0.237235"], ["84306.7", "0"], ["84307.72", "0"], ["84308.39", "0"], ["84308.71", "0.279992"], ["84309.11", "0.265974"], ["84314.19", "0"], ["84314.22", "0.263852"], ["84321.3", "0"], ["84322.29", "0.177969"], ["84325.28", "0.356019"], ["84328.28", "0"], ["84328.71", "0"], ["84328.81", "0"], ["84328.91", "0"], ["84329.15", "0"], ["84329.28", "0"], ["84329.43", "0"], ["84329.5", "0"], ["84329.84", "0"], ["84329.88", "0"]], "u": 7510637, "seq": 66889316043}, "cts": 1742142223405, "record_time": 1742142222.509681}
{"topic": "orderbook.200.BTCUSDT", "ts": 1742142223610, "type": "delta", "data": {"s": "BTCUSDT", "b": [["84269.18", "0.000297"], ["84267.2", "0"], ["84267.09", "0.13114"], ["84265.33", "0.02"], ["84265.32", "0.006181"], ["84263.74", "0.106728"], ["84263.7", "0"], ["84263.44", "0.118731"], ["84263.4", "0.04"], ["84260.53", "0.110392"], ["84255.42", "0.160655"], ["84255.38", "0"], ["84254.89", "0"], ["84252.51", "0.321643"], ["84252.47", "0"], ["84250.67", "0"], ["84248.57", "0.297108"], ["84248.56", "0"], ["84247.4", "0.263903"], ["84247.36", "0"], ["84244.49", "0.299875"], ["84242.08", "0.276"], ["84242.04", "0"], ["84238.04", "0"], ["84237.43", "0.021732"], ["84226.42", "0"], ["84225.08", "0"], ["84225", "0.068395"]], "a": [["84292.57", "0"], ["84292.61", "0.11711"], ["84292.74", "0.107055"], ["84293.08", "0"], ["84293.12", "0.1175"], ["84295.01", "0.11453"], ["84301.1", "0"], ["84301.14", "0.180269"], ["84303.03", "0.173932"], ["84303.79", "0"], ["84303.83", "0.174278"], ["84309.11", "0"], ["84309.15", "0.265657"], ["84311.05", "0.294172"], ["84314.22", "0"], ["84314.26", "0.279932"], ["84326.45", "0"], ["84326.82", "0"], ["84328.04", "0"]], "u": 7510638, "seq": 66889316179}, "cts": 1742142223601, "record_time": 1742142222.708996}
{"topic": "orderbook.200.BTCUSDT", "ts": 1742142223810, "type": "delta", "data": {"s": "BTCUSDT", "b": [["84284.31", "0.121732"], ["84277.58", "0.000326"], ["84271.24", "0.023171"], ["84271.23", "0.071204"], ["84269.17", "0.000297"], ["84269.16", "0"], ["84267.2", "0.000297"], ["84267.09", "0.194142"], ["84267", "0.02"], ["84266.82", "0.107606"], ["84266.33", "0.02"], ["84266", "0"], ["84265.78", "0.001716"], ["84265.33", "0"], ["84265.32", "0.005932"], ["84265.3", "0.02"], ["84264.3", "0"], ["84263.74", "0"], ["84263.44", "0"], ["84263", "0"], ["84260.53", "0"], ["84260.4", "0.165378"], ["84256.58", "0"], ["84255.42", "0"], ["84252.58", "0.24875"], ["84252.51", "0"], ["84252.38", "0.300935"], ["84250.71", "0.146639"], ["84250.67", "0.237292"], ["84248.57", "0"], ["84247.4", "0"], ["84246.33", "0"], ["84244.49", "0"], ["84242.08", "0"], ["84229.63", "0.146639"], ["84226.83", "0.356236"], ["84224.53", "0.001333"], ["84224.49", "0.000614"], ["84224.26", "0.023734"], ["84224.08", "0.001467"]], "a": [["84284.32", "0.0831"], ["84291.34", "0.008453"], ["84292.61", "0"], ["84292.74", "0.100306"], ["84293.12", "0"], ["84294.28", "0"], ["84295.01", "0"], ["84300.69", "0"], ["84301.14", "0"], ["84301.17", "0.404496"], ["84303.03", "0"], ["84303.83", "0"], ["84304.51", "0.167637"], ["84308.2", "0"], ["84308.71", "0"], ["84309.15", "0"], ["84311.05", "0"], ["84311.27", "0"], ["84312.53", "0.298431"], ["84314.26", "0"], ["84321.79", "0.029801"], ["84325.28", "0"], ["84326.45", "0.474348"], ["84326.82", "0.323301"], ["84328.04", "0.237306"], ["84328.28", "0.000235"], ["84328.81", "0.000235"], ["84328.91", "0.0002"], ["84329.15", "0.026414"], ["84329.28", "0.023728"], ["84329.43", "1.780162"], ["84329.5", "0.0006"], ["84329.84", "0.000612"]], "u": 7510639, "seq": 66889316371}, "cts": 1742142223796, "record_time": 1742142222.908997}
{"topic": "orderbook.200.BTCUSDT", "ts": 1742142224009, "type": "delta", "data": {"s": "BTCUSDT", "b": [["84280.11", "0.000751"], ["84278.34", "0"], ["84277.58", "0.008251"], ["84276.61", "0.0005"], ["84275.12", "0"], ["84272.65", "0.02885"], ["84271.24", "0"], ["84271.23", "0"], ["84269.18", "0"], ["84269.17", "0"], ["84267.49", "0.014965"], ["84267.48", "0.028596"], ["84267.47", "0.000297"], ["84267.46", "0.02"], ["84267.19", "0"], ["84267.09", "0"], ["84266.82", "0"], ["84266.76", "0.095241"], ["84266.75", "0.029002"], ["84266.46", "0"], ["84265.78", "0.001467"], ["84265.69", "0.000449"], ["84265.53", "0.112804"], ["84265.24", "0.119422"], ["84264.83", "0.02"], ["84263.83", "0"], ["84260.4", "0.000089"], ["84257.22", "0.17904"], ["84254.89", "0.237292"], ["84254.3", "0.16163"], ["84252.38", "0"], ["84251.13", "0.281987"], ["84249.2", "0.301403"], ["84246.34", "0"], ["84245.85", "0.071225"], ["84244.31", "0"], ["84243.88", "0.297545"], ["84241.7", "1.38371"], ["84238.61", "0.0013"], ["84238.04", "0.177969"], ["84233.25", "0"], ["84231.69", "0.355995"], ["84226.83", "0.000233"], ["84225.25", "0"], ["84225.07", "0"], ["84225.06", "0"], ["84225", "0"], ["84224.53", "0"], ["84224.49", "0"], ["84224.26", "0"], ["84224.08", "0"]], "a": [["84284.32", "0.151127"], ["84286.53", "0.089994"], ["84287.48", "0"], ["84289.75", "0"], ["84290.19", "0"], ["84290.32", "0.08339"], ["84290.91", "0"], ["84291.34", "0"], ["84292.74", "0.089173"], ["84294.4", "0.117949"], ["84294.91", "0.107357"], ["84296.12", "0.023511"], ["84296.71", "0"], ["84297.56", "0.9"], ["84297.59", "0"], ["84298.65", "0"], ["84299.36", "1.450037"], ["84300.06", "0"], ["84302.77", "0"], ["84302.93", "0.162896"], ["84304.46", "0"], ["84304.51", "0"], ["84305.63", "0.173479"], ["84308.63", "0.237224"], ["84309.66", "0"], ["84310.95", "0.286087"], ["84311.28", "0.265569"], ["84311.48", "0.03181"], ["84312.53", "0"], ["84316.06", "0.286181"], ["84322.29", "0"], ["84328.03", "0.355993"], ["84328.71", "0.162"], ["84329.88", "0.001333"], ["84329.99", "0.059948"]], "u": 7510640, "seq": 66889316750}, "cts": 1742142224007, "record_time": 1742142223.109033}
{"success": true, "ret_msg": "pong", "conn_id": "66eef079-b2bf-427b-aa45-7a2115dcff7c", "op": "ping", "record_time": 1742142223.164262}
{"topic": "orderbook.200.BTCUSDT", "ts": 1742142224210, "type": "delta", "data": {"s": "BTCUSDT", "b": [["84284.31", "0.021732"], ["84280.11", "0"], ["84278.34", "0.03032"], ["84277.58", "0.001141"], ["84268.07", "0.000297"], ["84268.06", "0.02"], ["84267.51", "0.014757"], ["84267.5", "0.02"], ["84267.49", "0.000297"], ["84267.47", "0"], ["84267.46", "0"], ["84267.2", "0"], ["84267", "0"], ["84266.93", "0.02"], ["84266.76", "0.12881"], ["84266.75", "0"], ["84266.33", "0"], ["84265.9", "0.02"], ["84265.78", "0.001716"], ["84265.69", "0.0002"], ["84265.53", "0"], ["84265.43", "0.02"], ["84265.3", "0"], ["84265.24", "0"], ["84264.83", "0"], ["84263.44", "0.10755"], ["84263.14", "0.118049"], ["84262.65", "0.114238"], ["84257.22", "0"], ["84255.13", "0.175738"], ["84254.3", "0"], ["84252.21", "0.17752"], ["84251.13", "0"], ["84249.2", "0"], ["84247.11", "0.284482"], ["84243.92", "0.003485"], ["84243.88", "0"], ["84241.78", "0.267317"], ["84238.38", "0"], ["84231.69", "0"], ["84225.25", "0.0002"], ["84225.07", "0.11863"]], "a": [["84284.32", "0.142521"], ["84291.16", "0.008453"], ["84292.31", "0.106103"], ["84292.74", "0.05964"], ["84292.82", "0.114582"], ["84293.92", "0.112833"], ["84294.22", "0.089922"], ["84294.4", "0"], ["84294.91", "0"], ["84296.12", "0.0001"], ["84297.55", "0.822909"], ["84298.8", "0.1"], ["84300.34", "0.160275"], ["84300.84", "0.15917"], ["84301.17", "0.179189"], ["84302.93", "0"], ["84303.54", "0.166416"], ["84305.47", "0.195931"], ["84305.63", "0"], ["84306.35", "0.089922"], ["84306.95", "0.237228"], ["84308.36", "0.283396"], ["84308.86", "0.283325"], ["84309.66", "0.237292"], ["84310.95", "0"], ["84311.28", "0"], ["84313.96", "0.264744"], ["84316.06", "0"], ["84325.28", "0.356009"], ["84328.03", "0"], ["84328.91", "0"], ["84329.15", "0"], ["84329.28", "0"], ["84329.43", "0"], ["84329.5", "0"], ["84329.84", "0"], ["84329.88", "0"], ["84329.99", "0"]], "u": 7510641, "seq": 66889317092}, "cts": 1742142224207, "record_time": 1742142223.309}
{"topic": "orderbook.200.BTCUSDT", "ts": 1742142224409, "type": "delta", "data": {"s": "BTCUSDT", "b": [["84277.58", "0"], ["84269.37", "0.027924"], ["84268.84", "0.033896"], ["84268.83", "0.071206"], ["84268.81", "0.000297"], ["84268.07", "0"], ["84268.06", "0"], ["84267.51", "0"], ["84267.5", "0"], ["84267.49", "0"], ["84267.48", "0"], ["84266.93", "0"], ["84266.76", "0.061304"], ["84265.9", "0"], ["84265.43", "0"], ["84263.44", "0"], ["84263.29", "0.110702"], ["84263.14", "0"], ["84263", "0.105609"], ["84262.75", "0.118419"], ["84262.65", "0"], ["84256.33", "0.175011"], ["84255.13", "0"], ["84254.98", "0.180636"], ["84254.89", "0"], ["84252.21", "0"], ["84252.06", "0.175731"], ["84250.71", "0"], ["84250.67", "0"], ["84247.11", "0"], ["84246.96", "0.290932"], ["84245.85", "0"], ["84241.78", "0"], ["84241.64", "0.284921"], ["84238.04", "0"], ["84236.63", "0.071233"], ["84232.57", "0.04"], ["84232.56", "0.039648"], ["84229.63", "0"], ["84225.06", "0.023734"], ["84225", "0.068395"], ["84224.53", "0.001333"], ["84224.49", "0.000614"], ["84224.26", "0.023734"], ["84224.08", "0.001467"], ["84224.01", "0.059948"], ["84223.91", "0.000252"]], "a": [["84284.32", "0.511478"], ["84290.39", "0"], ["84290.92", "0.005932"], ["84291.11", "0.008453"], ["84291.16", "0"], ["84292.16", "0.105744"], ["84292.31", "0"], ["84292.67", "0.108804"], ["84292.74", "0.129633"], ["84292.75", "0.1625"], ["84292.82", "0"], ["84293.92", "0"], ["84294.02", "0.115119"], ["84296.21", "0.024276"], ["84296.69", "0.03181"], ["84297.54", "1.247876"], ["84297.55", "0"], ["84300.34", "0"], ["84300.69", "0.165989"], ["84300.84", "0"], ["84303.39", "0.170333"], ["84303.54", "0"], ["84308.36", "0"], ["84308.71", "0.291022"], ["84308.86", "0"], ["84309.65", "0"], ["84311.48", "0"], ["84313.81", "0.297278"], ["84313.96", "0"], ["84320.67", "0.04"], ["84320.68", "0.04"], ["84325.27", "0.356026"], ["84325.28", "0"]], "u": 7510642, "seq": 66889317340}, "cts": 1742142224407, "record_time": 1742142223.508547}
{"topic": "orderbook.200.BTCUSDT", "ts": 1742142224609, "type": "delta", "data": {"s": "BTCUSDT", "b": [["84284.31", "0"], ["84284.3", "0.006585"], ["84278.34", "0.030263"], ["84275.88", "0"], ["84275.87", "0.0005"], ["84272.72", "0.02604"], ["84272.71", "0.02859"], ["84272.7", "0.000297"], ["84272.69", "0.028938"], ["84272.65", "0"], ["84269.83", "0.02"], ["84269.38", "0.018561"], ["84269.37", "0"], ["84269.36", "0.02"], ["84269.3", "0.02"], ["84268.84", "0"], ["84268.83", "0"], ["84268.81", "0"], ["84267.7", "0.02"], ["84266.73", "0.02"], ["84266.6", "0"], ["84264.47", "0.07121"], ["84263.29", "0"], ["84263", "0"], ["84262.75", "0"], ["84261.28", "0"], ["84259.59", "0"], ["84256.33", "0"], ["84256.3", "0"], ["84254.98", "0"], ["84252.06", "0"], ["84248.96", "0.003462"], ["84246.96", "0"], ["84243.92", "0"], ["84241.64", "0"], ["84240.16", "0"], ["84237.46", "0.011218"], ["84237.43", "0"], ["84232.57", "0"], ["84232.56", "0"], ["84232.37", "0.04"], ["84232.36", "0.039648"], ["84231.16", "0.071238"], ["84223.3", "0.001243"], ["84223.08", "0.000085"], ["84223", "0.000119"], ["84222.72", "0.0002"], ["84222.35", "0.352416"], ["84222.2", "0.000233"], ["84221.67", "0.000233"]], "a": [["84284.31", "0.2423"], ["84284.32", "0.326423"], ["84285.91", "0.001274"], ["84287.49", "0.023729"], ["84290.32", "0.141872"], ["84290.39", "0.001477"], ["84290.76", "0.023729"], ["84290.91", "0.118646"], ["84291.11", "0"], ["84291.59", "0.005932"], ["84292.16", "0"], ["84292.18", "0"], ["84292.67", "0"], ["84292.74", "0.130133"], ["84292.75", "0.162"], ["84294.02", "0"], ["84296.71", "0.059323"], ["84298.45", "0.017799"], ["84300.48", "0.005932"], ["84300.69", "0"], ["84302.07", "0.237242"], ["84302.68", "0"], ["84303.39", "0"], ["84303.75", "0.237237"], ["84306.95", "0"], ["84307.03", "0.029801"], ["84308.63", "0"], ["84308.71", "0"], ["84313.81", "0"], ["84313.99", "0.026414"], ["84321.3", "0.356029"], ["84321.79", "0"], ["84325.27", "0"], ["84326.44", "0.474348"], ["84326.45", "0"], ["84328.81", "0"]], "u": 7510643, "seq": 66889317812}, "cts": 1742142224603, "record_time": 1742142223.709079}
{"topic": "orderbook.200.BTCUSDT", "ts": 1742142224810, "type": "delta", "data": {"s": "BTCUSDT", "b": [["84284.3", "0.007772"], ["84272.73", "0.000297"], ["84272.72", "0.017417"], ["84272.7", "0"], ["84272.69", "0.028641"], ["84269.86", "0.02"], ["84269.83", "0"], ["84269.38", "0"], ["84269.36", "0"], ["84268.73", "0.02"], ["84267.71", "0.000297"], ["84267.23", "0.02"], ["84266.73", "0"], ["84265.78", "0.001467"], ["84265.61", "0.000501"], ["84262.41", "0.065621"], ["84252.58", "0.059948"], ["84237.46", "0"], ["84224.02", "0.356027"], ["84222.89", "0.162"], ["84221.67", "0"]], "a": [["84284.31", "0.371395"], ["84284.32", "0.32627"], ["84286.53", "0"], ["84290.64", "0.008453"], ["84297.54", "0.912289"], ["84301.17", "0.294695"], ["84303.07", "0.059323"], ["84305.47", "0.056563"], ["84314.22", "0.059323"], ["84320.27", "0.04"], ["84320.28", "0.202"], ["84320.67", "0"], ["84320.68", "0"], ["84321.3", "0"], ["84325.28", "0.356024"], ["84328.71", "0"]], "u": 7510644, "seq": 66889318167}, "cts": 1742142224804, "record_time": 1742142223.910076}
{"topic": "orderbook.200.BTCUSDT", "ts": 1742142225009, "type": "delta", "data": {"s": "BTCUSDT", "b": [["84284.3", "0.007172"], ["84272.8", "0.028134"], ["84272.79", "0.017131"], ["84272.78", "0.028532"], ["84272.76", "0.028337"], ["84272.73", "0"], ["84272.72", "0"], ["84272.71", "0"], ["84272.69", "0"], ["84269.87", "0.024561"], ["84266.85", "0.071208"], ["84265.69", "0.000449"], ["84265.61", "0.000252"], ["84264.47", "0"], ["84262.91", "0.112847"], ["84254.89", "0.162206"], ["84250.67", "0.237292"], ["84246.87", "0.300918"], ["84246.46", "0.237292"], ["84237.47", "0.007772"], ["84232.37", "0.039648"], ["84226.83", "0.356247"], ["84224.02", "0"], ["84223.08", "0"], ["84223", "0"], ["84222.89", "0"], ["84222.72", "0"], ["84222.35", "0"], ["84222.2", "0"]], "a": [["84284.31", "0.184573"], ["84286.13", "0.097038"], ["84290.64", "0"], ["84290.91", "0.059323"], ["84292.07", "0.119022"], ["84292.58", "0.108062"], ["84300.6", "0.162904"], ["84308.62", "0.298174"], ["84320.27", "0"], ["84320.28", "0.162"], ["84320.32", "0.04"], ["84320.33", "0.0445"], ["84322.29", "0.177969"], ["84325.28", "0"], ["84326.06", "0.357473"], ["84326.44", "0"], ["84326.82", "0"], ["84328.04", "0"], ["84328.28", "0"]], "u": 7510645, "seq": 66889318417}, "cts": 1742142225005, "record_time": 1742142224.109001}
{"topic": "orderbook.200.BTCUSDT", "ts": 1742142225210, "type": "delta", "data": {"s": "BTCUSDT", "b": [["84272.87", "0.000297"], ["84272.86", "0.02783"], ["84272.85", "0.016898"], ["84272.84", "0.027765"], ["84272.82", "0.028033"], ["84272.8", "0"], ["84272.79", "0"], ["84272.78", "0"], ["84272.76", "0"], ["84270.16", "0.02"], ["84269.86", "0"], ["84269.6", "0.02"], ["84269.3", "0"], ["84269.03", "0.02"], ["84268.73", "0"], ["84268", "0.02"], ["84267.7", "0"], ["84267.43", "0.02"], ["84267.23", "0"], ["84266.86", "0.053102"], ["84266.76", "0"], ["84266.61", "0.000862"], ["84265.69", "0.0002"], ["84263.41", "0.116665"], ["84263.11", "0.114661"], ["84262.92", "0.110284"], ["84262.91", "0"], ["84262.41", "0"], ["84255.09", "0.177268"], ["84254.89", "0"], ["84252.18", "0.162436"], ["84250.67", "0"], ["84247.07", "0.296783"], ["84246.87", "0"], ["84246.46", "0"], ["84241.75", "0.296918"], ["84226.83", "0.000233"], ["84225.08", "0.356017"], ["84224.01", "0"], ["84223.91", "0"], ["84223.3", "0"]], "a": [["84284.31", "0.17612"], ["84284.32", "0.32927"], ["84290.48", "0.008453"], ["84292.07", "0"], ["84292.28", "0.110157"], ["84292.58", "0"], ["84292.79", "0.106074"], ["84300.6", "0"], ["84300.81", "0.173141"], ["84303.51", "0.181051"], ["84308.62", "0"], ["84308.83", "0.299975"], ["84309.65", "0.226154"], ["84313.93", "0.265811"], ["84322.56", "0"], ["84325.28", "0.356011"], ["84326.06", "0.001467"], ["84326.07", "0"], ["84326.23", "0"], ["84326.38", "0"], ["84326.41", "0"]], "u": 7510646, "seq": 66889318666}, "cts": 1742142225204, "record_time": 1742142224.309002}
{"topic": "orderbook.200.BTCUSDT", "ts": 1742142225409, "type": "delta", "data": {"s": "BTCUSDT", "b": [["84284.3", "0"], ["84281.77", "0.002147"], ["84278.34", "0"], ["84275.87", "0"], ["84275.81", "0.030263"], ["84273.34", "0.0005"], ["84272.9", "0.027627"], ["84272.87", "0"], ["84272.86", "0"], ["84272.85", "0"], ["84272.84", "0"], ["84272.82", "0"], ["84270.51", "0.000297"], ["84270.5", "0.02"], ["84270.19", "0.040307"], ["84270.18", "0.032189"], ["84269.92", "0.02"], ["84269.87", "0"], ["84269.6", "0"], ["84269.03", "0"], ["84268.9", "0.02"], ["84268", "0"], ["84267.53", "0.02"], ["84267.43", "0"], ["84266.86", "0.081464"], ["84266.85", "0"], ["84266.61", "0.000613"], ["84264.9", "0.071458"], ["84263.41", "0"], ["84263.11", "0"], ["84262.92", "0"], ["84261.36", "0.111082"], ["84261.07", "0.116372"], ["84255.09", "0"], ["84253.04", "0.169974"], ["84252.18", "0"], ["84250.13", "0.172813"], ["84247.07", "0"], ["84245.02", "0.281356"], ["84241.75", "0"], ["84239.69", "0.277531"], ["84237.47", "0"], ["84232.93", "0.04"], ["84232.92", "0.039648"], ["84232.37", "0"], ["84232.36", "0"], ["84225.09", "0.356019"], ["84225.08", "0"], ["84224.01", "0.059948"], ["84223.91", "0.000252"], ["84223.3", "0.001243"], ["84223.08", "0.000085"], ["84223", "0.000119"]], "a": [["84281.78", "0.25742"], ["84284.29", "0.059369"], ["84284.3", "0.23595"], ["84284.31", "0.0004"], ["84284.32", "0.328084"], ["84286.13", "0"], ["84286.14", "0"], ["84290.21", "0.0005"], ["84290.26", "0.107617"], ["84290.48", "0"], ["84290.77", "0.110851"], ["84291.05", "0"], ["84292.28", "0"], ["84292.74", "0.129633"], ["84292.79", "0"], ["84298.8", "0.262238"], ["84300.81", "0"], ["84301.5", "0.172813"], ["84303.27", "0"], ["84303.51", "0"], ["84306.82", "0.283984"], ["84308.83", "0"], ["84311.93", "0.272643"], ["84313.93", "0"], ["84320.02", "0.04"], ["84320.03", "0.04"], ["84320.32", "0"], ["84320.33", "0.0045"], ["84323.91", "0.474348"], ["84325.28", "0.356023"]], "u": 7510647, "seq": 66889319187}, "cts": 1742142225406, "record_time": 1742142224.508729}
{"topic": "orderbook.200.BTCUSDT", "ts": 1742142225610, "type": "delta", "data": {"s": "BTCUSDT", "b": [["84281.77", "0"], ["84280.86", "0"], ["84280.72", "0"], ["84279.52", "0"], ["84279.3", "0"], ["84279.25", "0"], ["84278.33", "0"], ["84277.9", "0"], ["84277.8", "0"], ["84277.28", "0"], ["84276.61", "0"], ["84275.81", "0"], ["84275.8", "0"], ["84275.79", "0"], ["84275.08", "0"], ["84275.05", "0"], ["84275.04", "0"], ["84274.88", "0"], ["84273.34", "0"], ["84273.27", "0"], ["84273.17", "0"], ["84272.9", "0"], ["84272.64", "0"], ["84270.87", "0"], ["84270.82", "0"], ["84270.75", "0"], ["84270.51", "0"], ["84270.5", "0"], ["84270.42", "0"], ["84270.25", "0"], ["84270.19", "0"], ["84270.18", "0"], ["84270.16", "0"], ["84269.92", "0"], ["84268.9", "0"], ["84268.85", "0"], ["84268.53", "0"], ["84268.22", "0"], ["84268.01", "0"], ["84267.83", "0"], ["84267.71", "0"], ["84267.53", "0"], ["84266.9", "0"], ["84266.86", "0"], ["84266.65", "0"], ["84266.61", "0"], ["84265.78", "0"], ["84265.69", "0"], ["84265.61", "0"], ["84265.32", "0"], ["84264.9", "0"], ["84263.9", "0.000527"], ["84263.8", "0"], ["84263.75", "0"], ["84263.4", "0"], ["84262.18", "0"], ["84262.1", "0"], ["84261.79", "0"], ["84261.7", "0"], ["84261.56", "0"], ["84261.36", "0"], ["84261.07", "0"], ["84260.4", "0"], ["84260", "0"], ["84258.4", "0"], ["84258.3", "0"], ["84258.22", "0.0005"], ["84257", "0"], ["84256.7", "0"], ["84254.68", "0"], ["84254.66", "0"], ["84253.04", "0"], ["84252.78", "0.000817"], ["84252.58", "0"], ["84252.57", "0"], ["84252.28", "0.005"], ["84252.1", "0"], ["84250.13", "0"], ["84249.77", "0.000297"], ["84249.7", "0.04"], ["84248.96", "0"], ["84247.88", "0"], ["84247.26", "0.005933"], ["84245.6", "0.000297"], ["84245.16", "0.160062"], ["84245.15", "0"], ["84245.02", "0"], ["84245", "0"], ["84244.58", "0.019233"], ["84244.57", "0.118671"], ["84243.2", "0.04"], ["84242.32", "0"], ["84241.53", "0"], ["84239.69", "0"], ["84238.85", "0"], ["84238.02", "0.011868"], ["84237.36", "0.003424"], ["84236.63", "0"], ["84236.46", "0.009541"], ["84236.14", "0"], ["84235.74", "0"], ["84233.49", "0"], ["84233.35", "0.001467"], ["84233.03", "0.140014"], ["84232.93", "0"], ["84232.92", "0"], ["84232.8", "0"], ["84231.68", "0"], ["84231.16", "0"], ["84231.12", "0.068395"], ["84231.02", "0"], ["84230.1", "0"], ["84229.94", "0"], ["84228.95", "0.2"], ["84227.66", "0"], ["84226.82", "0"], ["84225.09", "0"], ["84225.07", "0"], ["84225.06", "0"], ["84225", "0"], ["84224.26", "0"], ["84223.57", "0.323697"], ["84222.88", "0.023736"], ["84222.84", "0.017796"], ["84222.72", "0.0002"], ["84222.35", "0.352416"], ["84222.2", "0.000233"], ["84221.67", "0.000233"], ["84221.63", "0.017802"], ["84220.71", "0.008453"], ["84220.32", "0.001333"], ["84220.28", "0.000613"], ["84220.2", "0.0002"], ["84219.74", "0.04"], ["84219.73", "0.039658"], ["84219.45", "0.001467"], ["84219.28", "0.000252"], ["84218.15", "0.00009"], ["84217.71", "0.015"], ["84217.67", "0.0002"], ["84217.56", "0.000233"], ["84217.45", "0.002853"], ["84217.16", "0.017765"], ["84217.04", "0.000233"], ["84216.97", "0.005"], ["84216.11", "0.001333"], ["84216.07", "0.000613"], ["84215.14", "0.0002"], ["84214.81", "0.001467"], ["84214.65", "0.000252"], ["84214.17", "0.023733"], ["84214.12", "0.004701"], ["84214", "0.000158"], ["84213.69", "0.000335"], ["84213.09", "0.005933"], ["84212.93", "0.000233"], ["84212.41", "0.000233"], ["84212.4", "0.001243"], ["84211.9", "0.248353"], ["84211.85", "0.000613"], ["84210.81", "0.023733"], ["84210.19", "0.059948"], ["84210.18", "0.001467"], ["84210.02", "0.000252"], ["84209.7", "0.00009"], ["84208.56", "0.11863"], ["84208.3", "0.000233"], ["84208.21", "0.023733"], ["84207.78", "0.000233"], ["84207.7", "0.0006"], ["84207.69", "0.001333"], ["84207.64", "0.000615"], ["84207.41", "0.023733"], ["84205.75", "0.178016"], ["84205.55", "0.001467"], ["84205.38", "0.000252"], ["84204.38", "0.00009"], ["84204.33", "0.237303"], ["84203.67", "0.000233"], ["84203.48", "0.001333"], ["84203.43", "0.000615"], ["84203.32", "0.118629"], ["84203.15", "0.000233"], ["84202.41", "0.023733"], ["84201.63", "0.059948"], ["84201.5", "0.001243"], ["84201.25", "0.00009"], ["84200.92", "0.001467"], ["84200.75", "0.000252"], ["84200.03", "0.014102"], ["84199.27", "0.001333"], ["84199.22", "0.000615"], ["84199.04", "0.000233"], ["84198.51", "0.000233"], ["84198.13", "0.118629"], ["84196.29", "0.001467"], ["84196.12", "0.000252"], ["84195.3", "0.382564"], ["84195.06", "0.001333"], ["84195.01", "0.000615"], ["84194.41", "0.000233"], ["84194.4", "0.167859"], ["84193.88", "0.000233"], ["84192.8", "0.00009"], ["84192.4", "0.04"], ["84192.33", "0.11863"]], "a": [["84263.91", "0.243648"], ["84264.18", "0.359689"], ["84265.38", "0.011868"], ["84265.62", "0.031316"], ["84265.79", "0.01"], ["84266.65", "0.228048"], ["84266.66", "0.074593"], ["84267.05", "0.359689"], ["84268.22", "0.0502"], ["84268.43", "0.184402"], ["84268.44", "0.11863"], ["84268.93", "0.005"], ["84269.92", "0.059948"], ["84270.42", "0.001467"], ["84270.75", "0.0002"], ["84270.82", "0.000613"], ["84270.87", "0.001333"], ["84272.33", "0.015895"], ["84272.64", "0.086162"], ["84273.17", "0.000233"], ["84273.27", "0.0002"], ["84273.28", "0.005"], ["84273.82", "0.11863"], ["84273.88", "0.068395"], ["84274.88", "0.000252"], ["84275.04", "0.000613"], ["84275.05", "0.001467"], ["84275.08", "0.006958"], ["84275.09", "0.2024"], ["84275.2", "0.02794"], ["84275.8", "0.0002"], ["84277.28", "0.000233"], ["84277.8", "0.000233"], ["84278.33", "0.10336"], ["84278.34", "0.1622"], ["84279.25", "0.000613"], ["84279.3", "0.061281"], ["84279.31", "0.11863"], ["84279.42", "0.00009"], ["84279.52", "0.000252"], ["84279.69", "0.001467"], ["84280.86", "0.0002"], ["84281.4", "0.06"], ["84281.77", "0.102697"], ["84281.78", "0.162"], ["84281.91", "0.000233"], ["84282.44", "0.000233"], ["84282.75", "0.009462"], ["84282.82", "0.017802"], ["84283.25", "0.001243"], ["84283.38", "0.001276"], ["84283.39", "0.0002"], ["84283.47", "0.000613"], ["84283.51", "0.001333"], ["84283.52", "0.162"], ["84284.03", "0.083985"], ["84284.16", "0.000252"], ["84284.29", "0.059073"], ["84284.3", "0"], ["84284.31", "0"], ["84284.32", "0.014956"], ["84284.85", "0.00461"], ["84285", "0.071192"], ["84285.15", "0"], ["84285.34", "0"], ["84285.91", "0"], ["84287.21", "0.023735"], ["84287.91", "0"], ["84287.93", "0.000089"], ["84288.05", "0.020996"], ["84288.1", "0.048"], ["84288.52", "0"], ["84288.79", "0.000252"], ["84288.93", "0.237279"], ["84289.63", "0.029801"], ["84290.26", "0"], ["84290.32", "0.08339"], ["84290.33", "0"], ["84290.39", "0"], ["84290.77", "0"], ["84290.83", "0"], ["84291.58", "0.071187"], ["84292.38", "0.068395"], ["84292.7", "0.06"], ["84293.23", "0.019075"], ["84293.47", "0.023734"], ["84294.85", "0.000789"], ["84295.08", "0.005933"], ["84295.2", "0.048"], ["84295.39", "0.356114"], ["84296.21", "0"], ["84296.69", "0"], ["84297.56", "0"], ["84297.6", "0.061796"], ["84298.21", "0.023733"], ["84298.45", "0"], ["84298.53", "0"], ["84298.8", "0.04"], ["84298.89", "0.022"], ["84299.31", "0.01383"], ["84300.38", "0"], ["84301.5", "0"], ["84301.96", "0"], ["84302.07", "0"], ["84303.72", "0"], ["84303.75", "0"], ["84305.44", "0.257284"], ["84306.01", "0.323381"], ["84306.44", "0.023732"], ["84306.82", "0"], ["84306.84", "0.023732"], ["84306.87", "0"], ["84307.03", "0"], ["84308.26", "0"], ["84308.44", "0"], ["84308.78", "0.474348"], ["84308.87", "0.005933"], ["84309.05", "0.023732"], ["84309.66", "0"], ["84310.09", "0"], ["84310.31", "0"], ["84311.08", "0"], ["84311.93", "0"], ["84312.41", "0.023733"], ["84313.87", "0"], ["84313.97", "0"], ["84316.51", "0"], ["84316.61", "0"], ["84316.68", "0"], ["84316.78", "0"], ["84316.88", "0"], ["84316.97", "0"], ["84317.19", "0"], ["84317.23", "0"], ["84317.25", "0"], ["84318.79", "0"], ["84319.01", "0"], ["84319.41", "0"], ["84319.53", "0"], ["84319.54", "0"], ["84320", "0"], ["84320.02", "0"], ["84320.03", "0"], ["84320.28", "0"], ["84320.33", "0"], ["84320.48", "0"], ["84321.25", "0"], ["84321.31", "0"], ["84321.32", "0"], ["84321.4", "0"], ["84321.42", "0"], ["84321.45", "0"], ["84321.57", "0"], ["84321.67", "0"], ["84321.97", "0"], ["84322", "0"], ["84322.29", "0"], ["84322.6", "0"], ["84323.31", "0"], ["84323.65", "0"], ["84323.71", "0"], ["84323.85", "0"], ["84323.91", "0"], ["84324.17", "0"], ["84325.28", "0"], ["84325.29", "0"], ["84325.51", "0"], ["84325.62", "0"], ["84325.66", "0"], ["84325.74", "0"], ["84325.89", "0"], ["84325.92", "0"], ["84326", "0"], ["84326.06", "0"]], "u": 7510648, "seq": 66889322186}, "cts": 1742142225608, "record_time": 1742142224.710078}
{"topic": "orderbook.200.BTCUSDT", "ts": 1742142225809, "type": "delta", "data": {"s": "BTCUSDT", "b": [["84263.9", "0"], ["84263.37", "0"], ["84263.16", "0"], ["84262.44", "0"], ["84262.4", "0"], ["84261.15", "0"], ["84260.98", "0"], ["84260.63", "0"], ["84259.26", "0"], ["84258.74", "0"], ["84258.23", "0"], ["84258.22", "0"], ["84258.18", "0"], ["84258.11", "0"], ["84257.91", "0"], ["84252.78", "0"], ["84252.28", "0"], ["84251.95", "0"], ["84249.84", "0.029452"], ["84249.8", "0.001833"], ["84249.77", "0"], ["84249.7", "0"], ["84249.5", "0"], ["84247.26", "0"], ["84245.61", "0.027627"], ["84245.16", "0"], ["84244.59", "0.030729"], ["84244.58", "0"], ["84244.57", "0"], ["84244.2", "0.060375"], ["84243.8", "0.04"], ["84243.2", "0"], ["84243.05", "0.005"], ["84242.45", "0.000297"], ["84242.3", "0.04"], ["84241.7", "0"], ["84239.81", "0.016522"], ["84239.8", "0.04"], ["84238.9", "0.04"], ["84238.23", "0.000817"], ["84238.02", "0"], ["84237.36", "0"], ["84236.87", "0.118682"], ["84236.56", "0"], ["84236.4", "0.105514"], ["84235.11", "0.071234"], ["84234.2", "0.001843"], ["84233.04", "0.184617"], ["84231.32", "0"], ["84231.12", "0"], ["84229.98", "0.167066"], ["84229.82", "0.003477"], ["84229.31", "0.019233"], ["84229.09", "0.009295"], ["84228.95", "0"], ["84226.65", "0.068395"], ["84223.58", "0.221268"], ["84223.57", "0"], ["84222.89", "0.162"], ["84222.84", "0"], ["84221.95", "0.292883"], ["84221.63", "0"], ["84219.74", "0"], ["84219.73", "0"], ["84219.71", "0.023797"], ["84217.16", "0"], ["84214.46", "0.162"], ["84212.62", "0.0002"], ["84212", "0.013987"], ["84211.9", "0.001333"], ["84210.09", "0.0002"], ["84208.7", "0.24702"], ["84208.64", "0.000989"], ["84208.56", "0"], ["84207.57", "0.0002"], ["84207.56", "0.071258"], ["84206.94", "0.001"], ["84206.03", "0.162"], ["84205.75", "0"], ["84204.33", "0"], ["84203.18", "0.071261"], ["84201.64", "0.356124"], ["84197.6", "0.162"], ["84192.32", "0.457444"], ["84192.17", "0.017765"], ["84191.66", "0.001467"], ["84191.58", "0.000335"]], "a": [["84257.58", "0.242807"], ["84257.92", "0.056112"], ["84258.23", "0.25603"], ["84258.24", "0.18929"], ["84258.28", "0.000153"], ["84258.75", "0.071214"], ["84258.96", "0.359689"], ["84259.33", "0.011868"], ["84259.83", "0.005"], ["84260.63", "0.059495"], ["84261.16", "0.040766"], ["84262.4", "0.000613"], ["84262.44", "0.001333"], ["84262.7", "0.011867"], ["84263.16", "0.0002"], ["84263.37", "0.158518"], ["84263.38", "0.11863"], ["84263.9", "0.000233"], ["84263.91", "0"], ["84264.56", "0.005"], ["84265.23", "0.011867"], ["84265.38", "0"], ["84265.61", "0.000252"], ["84265.62", "0.0302"], ["84265.69", "0.0002"], ["84265.78", "0.001467"], ["84265.79", "0"], ["84266.01", "0.162"], ["84266.61", "0.000613"], ["84266.65", "0.001333"], ["84266.66", "0"], ["84267.05", "0"], ["84267.49", "0.037896"], ["84267.5", "0.000099"], ["84267.71", "0.105245"], ["84268.01", "0.000233"], ["84268.21", "0.071217"], ["84268.22", "0.0002"], ["84268.43", "0"], ["84268.53", "0.000233"], ["84268.93", "0"], ["84270.25", "0.000252"], ["84270.91", "0.00009"], ["84271.48", "0.020997"], ["84272.33", "0"], ["84272.64", "0.000233"], ["84273.28", "0"], ["84273.57", "0.032637"], ["84273.59", "0.083987"], ["84274.13", "0.162357"], ["84275.08", "0.001733"], ["84275.09", "0.1624"], ["84275.2", "0"], ["84275.93", "0.032059"], ["84277.7", "0.068"], ["84278.21", "0.023403"], ["84278.33", "0.10356"], ["84278.34", "0.162"], ["84279.1", "0.06"], ["84279.24", "0.071197"], ["84279.97", "0.012424"], ["84280.8", "0.056"], ["84281.64", "0.000789"], ["84281.77", "0.132886"], ["84282.16", "0.26959"], ["84282.32", "0.000989"], ["84282.82", "0"], ["84283.3", "0.044"], ["84283.38", "0"], ["84284.03", "0"], ["84284.99", "0.124915"], ["84285.9", "0.044"], ["84285.95", "0.118683"], ["84287.21", "0"], ["84288.05", "0"], ["84288.1", "0.077801"], ["84288.93", "0"], ["84289.63", "0"], ["84291.58", "0"], ["84292.41", "0.356056"], ["84292.7", "0"], ["84293.1", "0.068"], ["84293.4", "0.04"], ["84293.47", "0"], ["84294.21", "0.356124"], ["84294.85", "0"], ["84295.39", "0"], ["84295.4", "0"], ["84296.02", "0.323419"], ["84296.39", "0.026414"], ["84297.54", "0"], ["84297.7", "0.11863"], ["84298.29", "0.431067"], ["84298.8", "0"], ["84299.7", "0"], ["84300.2", "0.474348"], ["84301.17", "0.179189"], ["84301.8", "0"], ["84302.1", "0"], ["84305.44", "0.019981"], ["84306.01", "0"], ["84307.88", "0"], ["84308.78", "0"], ["84308.87", "0"], ["84309.05", "0"], ["84309.61", "0"], ["84309.65", "0"], ["84309.73", "0"], ["84310.04", "0"], ["84310.22", "0"], ["84310.24", "0"], ["84310.26", "0"], ["84311.2", "0"], ["84311.98", "0"], ["84312.14", "0"], ["84312.41", "0"], ["84312.97", "0"], ["84313.02", "0"], ["84313.27", "0"], ["84313.46", "0"], ["84313.73", "0"], ["84313.85", "0"], ["84313.99", "0"], ["84314.22", "0"], ["84314.37", "0"], ["84314.9", "0"], ["84315.07", "0"], ["84315.93", "0"], ["84315.95", "0"], ["84316.26", "0"], ["84316.41", "0"]], "u": 7510649, "seq": 66889323738}, "cts": 1742142225807, "record_time": 1742142224.909772}
{"topic": "orderbook.200.BTCUSDT", "ts": 1742142226010, "type": "delta", "data": {"s": "BTCUSDT", "b": [["84257.57", "0.003029"], ["84257.17", "0.000555"], ["84253.98", "0.000099"], ["84251.92", "0.023852"], ["84251.91", "0.028742"], ["84251.89", "0.028844"], ["84250.84", "0.001905"], ["84250.72", "0.02"], ["84250.36", "0.022285"], ["84249.84", "0"], ["84249.8", "0.001333"], ["84249.14", "0.0005"], ["84248.92", "0.02"], ["84248.55", "0.02"], ["84245.62", "0.000297"], ["84245.61", "0"], ["84245.6", "0"], ["84244.6", "0.000297"], ["84244.59", "0.044902"], ["84243.01", "0.015094"], ["84242.45", "0"], ["84242.42", "0.001"], ["84241.8", "0.04"], ["84241.6", "0.048"], ["84241.41", "0.02599"], ["84241.4", "0.04"], ["84239.81", "0"], ["84236.88", "0.094194"], ["84236.4", "0"], ["84235.11", "0"], ["84235", "0.04"], ["84234.7", "0.04"], ["84233.03", "0"], ["84232.28", "0.162"], ["84229.98", "0"], ["84228.77", "1.446616"], ["84222.07", "0.140012"], ["84221.95", "0"], ["84221.84", "0.017796"], ["84214.47", "0.11863"], ["84214.12", "0"], ["84213.04", "0.071253"], ["84211.04", "0.04"], ["84211.03", "0.039644"], ["84208.71", "0.11863"], ["84203.33", "0.356118"], ["84203.18", "0"], ["84201.64", "0"], ["84200.81", "0.004566"], ["84200.03", "0"], ["84199.04", "0"], ["84198.51", "0"], ["84198.13", "0"], ["84197.6", "0"], ["84196.29", "0"], ["84196.12", "0"], ["84195.3", "0"], ["84195.06", "0"], ["84195.01", "0"], ["84194.41", "0"], ["84194.4", "0"], ["84193.88", "0"], ["84192.8", "0"], ["84192.4", "0"], ["84192.33", "0"], ["84192.32", "0"], ["84192.17", "0"], ["84191.66", "0"], ["84191.58", "0"]], "a": [["84257.58", "0.159694"], ["84257.92", "0"], ["84258.23", "0.246577"], ["84258.24", "0.07066"], ["84258.96", "0"], ["84263.37", "0.255722"], ["84263.38", "0"], ["84265.22", "0.059244"], ["84265.44", "0.068395"], ["84266", "0.04906"], ["84266.01", "0"], ["84267.19", "0.008453"], ["84267.5", "0"], ["84267.71", "0"], ["84267.76", "0.128406"], ["84268.2", "0.020997"], ["84268.21", "0"], ["84271.32", "0.004702"], ["84271.48", "0"], ["84273.1", "0.044"], ["84273.3", "0.06"], ["84273.81", "0.154754"], ["84273.88", "0"], ["84274.13", "0"], ["84274.43", "0.140012"], ["84275.08", "0.001333"], ["84275.93", "0.03181"], ["84276.62", "0.019075"], ["84279.8", "0.048"], ["84280", "0.048"], ["84282.16", "0"], ["84284.17", "0.024287"], ["84284.29", "0"], ["84284.85", "0"], ["84285.79", "0.014107"], ["84287.2", "0.04"], ["84288.1", "0.029801"], ["84288.59", "0.237367"], ["84288.67", "0.236527"], ["84291.24", "0.017796"], ["84291.74", "0.000335"], ["84292.8", "0.237367"], ["84293.23", "0"], ["84294.21", "0"], ["84295.2", "0"], ["84297.25", "0"], ["84297.6", "0.017796"], ["84299.31", "0"], ["84299.7", "0.474348"], ["84300.2", "0"], ["84300.4", "0"], ["84301.16", "0.356111"], ["84301.23", "0.178026"], ["84303", "0"], ["84305.54", "0.352414"], ["84307.34", "0"], ["84307.51", "0"], ["84308.68", "0"], ["84308.76", "0"], ["84308.8", "0"]], "u": 7510650, "seq": 66889324344}, "cts": 1742142226007, "record_time": 1742142225.109004}
{"topic": "orderbook.200.BTCUSDT", "ts": 1742142226210, "type": "delta", "data": {"s": "BTCUSDT", "b": [["84251.98", "0.025398"], ["84251.97", "0.028438"], ["84251.92", "0"], ["84251.91", "0"], ["84251.89", "0"], ["84250.84", "0.005763"], ["84250.36", "0.01345"], ["84245.62", "0"], ["84242.3", "0"], ["84241.61", "0.05239"], ["84241.41", "0"], ["84240.1", "0.04"], ["84237.9", "0.04"], ["84236.88", "0"], ["84235.73", "0.008997"], ["84233.48", "0.2639"], ["84233.04", "0"], ["84211.04", "0"], ["84211.03", "0"], ["84206.04", "0.356103"], ["84204.93", "0.079298"], ["84203.33", "0"], ["84199.04", "0.000233"], ["84198.51", "0.000233"]], "a": [["84257.58", "0.100682"], ["84258.22", "0.060722"], ["84258.23", "0"], ["84258.28", "0"], ["84261.17", "0.000099"], ["84263.37", "0.158518"], ["84266.01", "0.0005"], ["84266.95", "0.008453"], ["84267.19", "0"], ["84267.47", "0.074038"], ["84267.76", "0"], ["84274.3", "0.001"], ["84274.8", "0.044"], ["84275.09", "0.162"], ["84278.33", "0.148066"], ["84281.4", "0"], ["84281.77", "0.132486"], ["84283.2", "0.068"], ["84285.9", "0"], ["84290.21", "0"], ["84293.1", "0"], ["84293.4", "0"], ["84301.16", "0"], ["84303.06", "0.356106"], ["84307.34", "0.000253"]], "u": 7510651, "seq": 66889324813}, "cts": 1742142226207, "record_time": 1742142225.308962}
{"topic": "orderbook.200.BTCUSDT", "ts": 1742142226409, "type": "delta", "data": {"s": "BTCUSDT", "b": [["84251.98", "0"], ["84251.97", "0"], ["84250.92", "0.02"], ["84250.84", "0.002346"], ["84250.72", "0"], ["84249.65", "0.02"], ["84249.22", "0.02"], ["84248.92", "0"], ["84248.55", "0"], ["84244.59", "0.025043"], ["84243.8", "0"], ["84243.05", "0"], ["84241.8", "0"], ["84241.6", "0"], ["84241.4", "0"], ["84240.22", "0.000297"], ["84240.21", "0.000297"], ["84240.1", "0"], ["84239.8", "0"], ["84238.9", "0"], ["84238.82", "0.005"], ["84237.9", "0"], ["84236.88", "0.067869"], ["84236.87", "0"], ["84236.46", "0"], ["84235.73", "0"], ["84235.43", "0.11509"], ["84235.2", "0.04"], ["84235", "0"], ["84234.8", "0.04"], ["84234.7", "0"], ["84234.69", "0.005934"], ["84233.48", "0"], ["84233.2", "0.04"], ["84232.28", "0"], ["84232.1", "0.04"], ["84231.6", "0.04"], ["84229.09", "0"], ["84228.68", "0.15997"], ["84224.76", "0.009472"], ["84223.47", "0.009541"], ["84222.88", "0"], ["84222.07", "0"], ["84220.77", "0.14001"], ["84220.25", "0.280967"], ["84219.71", "0"], ["84219.58", "0.024245"], ["84214.47", "0"], ["84209.95", "0.018944"], ["84208.64", "0"], ["84207.57", "0.001189"], ["84206.04", "0"], ["84205.75", "0.178026"], ["84198.13", "0.118629"], ["84196.29", "0.001467"], ["84196.12", "0.000252"], ["84195.91", "0.178026"], ["84195.3", "0.382564"], ["84195.06", "0.001333"]], "a": [["84257.58", "0.291703"], ["84258.22", "0.092269"], ["84258.24", "0"], ["84260.62", "0.059948"], ["84263.3", "0.005934"], ["84263.36", "0.11863"], ["84266.01", "0.1625"], ["84266.3", "0.008453"], ["84266.95", "0"], ["84267.49", "0"], ["84268.31", "0.110475"], ["84272.2", "0.068"], ["84273.8", "0.06"], ["84275", "0.068"], ["84275.06", "0.162886"], ["84275.5", "0.056"], ["84276.7", "0.04"], ["84277.7", "0"], ["84278.89", "0.237307"], ["84279.1", "0"], ["84281.1", "0.000989"], ["84282.26", "0.237298"], ["84282.32", "0"], ["84283.27", "0.059341"], ["84283.3", "0"], ["84283.49", "0.296038"], ["84283.95", "0.029801"], ["84284.17", "0"], ["84284.38", "0.237367"], ["84285.95", "0"], ["84287.2", "0"], ["84288.1", "0"], ["84288.58", "0.340666"], ["84289.58", "0.023736"], ["84289.98", "0.023736"], ["84290.32", "0"], ["84290.92", "0"], ["84292.19", "0.023736"], ["84292.8", "0"], ["84295.55", "0.023736"], ["84296.01", "0.356126"], ["84303.06", "0"], ["84305.44", "0"], ["84305.47", "0"], ["84305.54", "0"], ["84305.62", "0"], ["84306.15", "0"], ["84306.35", "0"], ["84306.44", "0"], ["84306.84", "0"], ["84307.34", "0"]], "u": 7510652, "seq": 66889325775}, "cts": 1742142226406, "record_time": 1742142225.508995}
{"topic": "orderbook.200.BTCUSDT", "ts": 1742142226609, "type": "delta", "data": {"s": "BTCUSDT", "b": [["84257.57", "0.004529"], ["84251.91", "0.028742"], ["84250.84", "0.000859"], ["84249.65", "0"], ["84249.22", "0"], ["84249.12", "0.02"], ["84248.85", "0.02"], ["84241.61", "0"], ["84241.35", "0.000297"], ["84240.74", "0.000297"], ["84240.22", "0"], ["84240.21", "0"], ["84236.9", "0.04"], ["84236.6", "0.04"], ["84235.43", "0"], ["84233.8", "0.054075"], ["84232.11", "0.093393"], ["84230.2", "0.04"], ["84229.9", "0.04"], ["84229.33", "0.009543"], ["84228.68", "0"], ["84224.76", "0"], ["84223.58", "0"], ["84222.6", "0.237367"], ["84220.25", "0"], ["84198.14", "0.356123"], ["84197.6", "0.162"], ["84196.12", "0"], ["84195.91", "0"], ["84195.3", "0"], ["84195.06", "0"]], "a": [["84257.58", "0.179795"], ["84266.01", "0.0005"], ["84266.3", "0"], ["84268.31", "0"], ["84273.58", "0.270054"], ["84273.81", "0"], ["84275.06", "0"], ["84279.07", "0.024324"], ["84280.8", "0"], ["84281.59", "0.237367"], ["84283.2", "0"], ["84283.49", "0"], ["84285.8", "0.237367"], ["84296.01", "0"], ["84297.69", "0.356123"], ["84305.44", "0.019981"], ["84305.54", "0.352414"], ["84305.62", "0.000235"]], "u": 7510653, "seq": 66889326142}, "cts": 1742142226607, "record_time": 1742142225.708026}
{"topic": "orderbook.200.BTCUSDT", "ts": 1742142226809, "type": "delta", "data": {"s": "BTCUSDT", "b": [["84257.57", "0.104029"], ["84255.24", "0.001215"], ["84252.72", "0.02"], ["84251.93", "0.028601"], ["84251.91", "0"], ["84250.92", "0"], ["84250.84", "0.011869"], ["84250.82", "0.02"], ["84250.36", "0"], ["84249.12", "0"], ["84244.6", "0.028652"], ["84241.35", "0"], ["84240.43", "0.000297"], ["84240.42", "0.000297"], ["84239.39", "0.116799"], ["84239.21", "0.116465"], ["84239.08", "0.116558"], ["84236.91", "0.027892"], ["84232.41", "0.178536"], ["84232.28", "0.162"], ["84230.58", "0.177861"], ["84227.5", "0.172791"], ["84225.4", "0.237367"], ["84223.92", "0.267636"], ["84222.09", "0.280272"], ["84221.18", "0.237367"], ["84218.68", "0.071248"], ["84216.46", "0.291632"], ["84214.47", "0.11863"], ["84207.56", "0"], ["84203.33", "0.356113"], ["84203.15", "0"], ["84202.41", "0"], ["84201.63", "0"], ["84201.5", "0"], ["84201.25", "0"], ["84200.92", "0"], ["84200.81", "0"], ["84200.75", "0"], ["84199.27", "0"], ["84199.22", "0"], ["84199.04", "0"], ["84198.51", "0"], ["84198.14", "0"], ["84198.13", "0"], ["84197.6", "0"], ["84196.29", "0"]], "a": [["84257.58", "0.128797"], ["84260.62", "0"], ["84263.36", "0"], ["84264.18", "0"], ["84265.64", "0.105854"], ["84269.98", "0.105549"], ["84270.51", "0.105764"], ["84272.34", "0.112975"], ["84279", "0.166246"], ["84279.14", "0.178928"], ["84280.16", "0.237367"], ["84281.87", "0.164726"], ["84287.5", "0.294792"], ["84287.63", "0.279782"], ["84288.59", "0"], ["84292.91", "0.282149"], ["84297.69", "0"], ["84299.36", "0"], ["84301.16", "0.356113"], ["84304", "0.000119"], ["84304.58", "0"], ["84304.95", "0"], ["84305.05", "0"], ["84305.1", "0"], ["84305.44", "0"], ["84305.54", "0"], ["84305.62", "0"]], "u": 7510654, "seq": 66889326438}, "cts": 1742142226808, "record_time": 1742142225.909096}
{"topic": "orderbook.200.BTCUSDT", "ts": 1742142227009, "type": "delta", "data": {"s": "BTCUSDT", "b": [["84256.74", "0.007843"], ["84255.24", "0.0005"], ["84253.37", "0.008397"], ["84252.72", "0"], ["84251.93", "0"], ["84250.84", "0"], ["84250.82", "0"], ["84248.85", "0"], ["84248.18", "0.015323"], ["84248.17", "0.029158"], ["84248.02", "0.02"], ["84246.22", "0.02"], ["84245.85", "0.02"], ["84245.42", "0.071226"], ["84244.6", "0"], ["84241.35", "0.000297"], ["84240.43", "0"], ["84240.42", "0"], ["84240.39", "0.115046"], ["84240.08", "0.11226"], ["84239.55", "0.112748"], ["84239.4", "0.107653"], ["84239.39", "0"], ["84239.21", "0"], ["84239.08", "0"], ["84236.91", "0"], ["84233.74", "0.009679"], ["84232.41", "0"], ["84231.58", "0.178493"], ["84230.83", "0.008833"], ["84230.58", "0"], ["84230.17", "0.118684"], ["84229.33", "0"], ["84228.5", "0.173243"], ["84227.5", "0"], ["84226.82", "0.237367"], ["84225.41", "0.237367"], ["84224.26", "0.296998"], ["84223.92", "0"], ["84223.09", "0.274183"], ["84222.09", "0"], ["84217.46", "0.29719"], ["84216.46", "0"], ["84216.24", "0.014495"], ["84212.76", "0.206482"], ["84212", "0"], ["84206.04", "0.356092"], ["84204.38", "0"], ["84203.67", "0"], ["84203.48", "0"], ["84203.43", "0"], ["84203.33", "0"], ["84203.32", "0"]], "a": [["84257.58", "0.049684"], ["84258.22", "0"], ["84259.33", "0"], ["84261.78", "0.005596"], ["84262.7", "0"], ["84263.3", "0"], ["84263.37", "0.05076"], ["84264.31", "0.008453"], ["84265.21", "0.11863"], ["84265.22", "0"], ["84265.44", "0"], ["84265.64", "0"], ["84267.47", "0.02708"], ["84268.44", "0"], ["84269.98", "0"], ["84270.51", "0"], ["84270.97", "0.117605"], ["84271.51", "0.119583"], ["84272.34", "0"], ["84272.68", "0.115342"], ["84273.28", "0.068395"], ["84273.57", "0.01865"], ["84274.44", "0.162"], ["84275.09", "0"], ["84275.93", "0"], ["84277.84", "0.014514"], ["84278.13", "1.449693"], ["84278.89", "0"], ["84279", "0"], ["84279.07", "0"], ["84279.14", "0"], ["84279.48", "0.169091"], ["84279.94", "0.118684"], ["84280", "0.222892"], ["84280.16", "0"], ["84281.59", "0"], ["84281.87", "0"], ["84282.26", "0"], ["84283.27", "0"], ["84283.95", "0"], ["84284.29", "0.024082"], ["84284.38", "0"], ["84287.5", "0"], ["84287.63", "0"], ["84287.97", "0.281531"], ["84288.22", "0.03181"], ["84288.5", "0.283656"], ["84288.67", "0"], ["84290.02", "0.237367"], ["84292.91", "0"], ["84293.91", "0.290422"], ["84298.67", "0.029801"], ["84301.16", "0"], ["84301.23", "0"], ["84301.32", "0.237367"], ["84304.58", "0.001315"], ["84304.95", "0.000089"], ["84304.97", "0.037807"], ["84305.05", "0.003748"], ["84305.1", "0.000786"], ["84305.44", "0.019981"], ["84305.54", "0.352414"], ["84305.62", "0.000235"], ["84306.15", "0.0002"], ["84306.35", "0.089922"]], "u": 7510655, "seq": 66889326991}, "cts": 1742142227006, "record_time": 1742142226.108379}
{"topic": "orderbook.200.BTCUSDT", "ts": 1742142227210, "type": "delta", "data": {"s": "BTCUSDT", "b": [["84257.57", "0"], ["84257.17", "0"], ["84256.74", "0"], ["84256.51", "0"], ["84256.35", "0"], ["84256", "0.002429"], ["84255.24", "0"], ["84253.37", "0"], ["84249.14", "0"], ["84248.84", "0.000297"], ["84248.18", "0"], ["84248.17", "0"], ["84248.02", "0"], ["84247.92", "0.0005"], ["84246.22", "0"], ["84245.85", "0"], ["84245.42", "0"], ["84245.11", "0.028753"], ["84245.1", "0.041673"], ["84244.59", "0"], ["84244.21", "0.029512"], ["84240.74", "0"], ["84240.39", "0"], ["84240.08", "0"], ["84239.55", "0"], ["84239.4", "0"], ["84233.74", "0"], ["84232.28", "0"], ["84232.11", "0.197522"], ["84231.58", "0"], ["84228.78", "0.721433"], ["84228.77", "0"], ["84228.5", "0"], ["84228.45", "0.009756"], ["84226.82", "0"], ["84225.41", "0"], ["84225.4", "0"], ["84224.26", "0"], ["84223.09", "0"], ["84222.6", "0"], ["84221.18", "0"], ["84218.68", "0"], ["84217.46", "0"], ["84216.24", "0"], ["84214.47", "0"], ["84214.18", "0.237367"], ["84213.04", "0"], ["84212.76", "0"], ["84211.25", "0.014641"], ["84207.32", "0.071258"], ["84206.04", "0"], ["84205.75", "0"], ["84204.38", "0.00009"], ["84203.67", "0.000233"], ["84203.48", "0.001333"], ["84203.43", "0.000615"], ["84203.32", "0.118629"], ["84203.15", "0.000233"], ["84202.41", "0.023733"], ["84201.63", "0.059948"], ["84201.5", "0.001243"], ["84201.25", "0.00009"], ["84200.92", "0.001467"], ["84200.81", "0.004566"], ["84200.75", "0.000252"], ["84199.27", "0.001333"], ["84199.22", "0.000615"], ["84199.04", "0.000233"], ["84198.51", "0.000233"], ["84198.13", "0.118629"], ["84196.29", "0.001467"], ["84196.12", "0.000252"], ["84195.3", "0.382564"], ["84195.06", "0.001333"], ["84195.01", "0.000615"], ["84194.41", "0.000233"], ["84194.4", "0.167859"], ["84193.88", "0.000233"], ["84192.8", "0.00009"], ["84192.33", "0.11863"], ["84192.32", "0.457444"], ["84192.17", "0.017765"], ["84191.66", "0.001467"]], "a": [["84256.01", "0.230462"], ["84256.36", "0.152552"], ["84256.47", "0.359689"], ["84256.52", "0.101216"], ["84257.58", "0"], ["84258.41", "0.011868"], ["84258.74", "0.003"], ["84258.75", "0"], ["84259.75", "0.023736"], ["84259.88", "0.002268"], ["84260.13", "0.11863"], ["84260.14", "0.07694"], ["84260.15", "0.089922"], ["84260.63", "0.0502"], ["84260.98", "0.000252"], ["84261.15", "0.061415"], ["84261.78", "0.011867"], ["84263.37", "0.11264"], ["84263.94", "0.005934"], ["84264.31", "0"], ["84264.79", "0.0005"], ["84266.01", "0.162"], ["84266.21", "0.03181"], ["84267.47", "0.132925"], ["84267.85", "0.089922"], ["84270.74", "0.059228"], ["84270.97", "0"], ["84271.51", "0"], ["84272.68", "0"], ["84273.3", "0.074634"], ["84275.83", "0.003"], ["84277.38", "0.237367"], ["84277.84", "0"], ["84278.12", "0.671108"], ["84278.33", "0.0002"], ["84278.53", "0.029801"], ["84279.09", "0.118684"], ["84279.48", "0"], ["84280", "0.048"], ["84281.59", "0.237367"], ["84284.32", "0.011956"], ["84287.97", "0"], ["84288.22", "0"], ["84288.5", "0"], ["84290.76", "0"], ["84292.37", "0.356144"], ["84293.91", "0"], ["84298.13", "0.474348"], ["84298.67", "0"], ["84299.7", "0"], ["84300.82", "0.003"], ["84301.19", "0"], ["84301.32", "0"], ["84304.58", "0"], ["84304.95", "0"], ["84304.97", "0"], ["84305.05", "0"], ["84305.1", "0"], ["84305.44", "0"], ["84305.54", "0"], ["84305.62", "0"], ["84306.15", "0"], ["84306.35", "0"]], "u": 7510656, "seq": 66889327922}, "cts": 1742142227206, "record_time": 1742142226.309007}
{"topic": "orderbook.200.BTCUSDT", "ts": 1742142227409, "type": "delta", "data": {"s": "BTCUSDT", "b": [["84256", "0.002984"], ["84255.24", "0.0005"], ["84253.98", "0"], ["84250.53", "0.027741"], ["84248.84", "0"], ["84247.92", "0"], ["84247.57", "0.0005"], ["84246.13", "0.000297"], ["84246.12", "0.02"], ["84245.12", "0.000297"], ["84245.11", "0.028822"], ["84244.32", "0.02"], ["84244.21", "0"], ["84243.95", "0.02"], ["84241.35", "0"], ["84234.45", "0.11999"], ["84228.78", "0"], ["84227.67", "0.170516"], ["84221.18", "0.237372"], ["84219.89", "1.397233"], ["84219.58", "0"], ["84219.2", "0.264687"], ["84217.36", "0.024115"], ["84214.47", "0.11863"], ["84213.41", "0.071253"], ["84207.57", "0.0002"], ["84206.01", "0.000989"], ["84205.75", "0.178029"], ["84201.64", "0.356123"], ["84197.6", "0.162"], ["84196.29", "0"], ["84196.12", "0"], ["84195.3", "0"], ["84195.06", "0"], ["84195.01", "0"], ["84194.41", "0"], ["84194.4", "0"], ["84193.88", "0"], ["84192.8", "0"], ["84192.33", "0"], ["84192.32", "0"], ["84192.17", "0"], ["84191.66", "0"]], "a": [["84256.01", "0.159022"], ["84256.35", "0.025825"], ["84256.36", "0.019766"], ["84256.47", "0"], ["84256.52", "0.071216"], ["84259.75", "0"], ["84260.13", "0"], ["84260.14", "0.05603"], ["84260.15", "0"], ["84261.17", "0"], ["84262.74", "0.011867"], ["84262.76", "0.008453"], ["84262.82", "0.023737"], ["84263.37", "0.05076"], ["84263.94", "0"], ["84265.23", "0"], ["84266.01", "0"], ["84266.21", "0"], ["84267.47", "0.080457"], ["84267.51", "0.115766"], ["84274.29", "0.170464"], ["84278.13", "0"], ["84278.22", "0.03181"], ["84278.53", "0"], ["84279.54", "0.000989"], ["84280.16", "0.237372"], ["84280.23", "0.237372"], ["84280.36", "0.237303"], ["84281.1", "0"], ["84282.77", "0.294145"], ["84284.38", "0.237372"], ["84284.45", "0.072905"], ["84285.8", "0"], ["84289.79", "0.029801"], ["84290.02", "0"], ["84292.37", "0"], ["84300.65", "0.356121"], ["84301.17", "0"], ["84301.23", "0.178029"], ["84304.54", "0"]], "u": 7510657, "seq": 66889328298}, "cts": 1742142227408, "record_time": 1742142226.508986}
{"topic": "orderbook.200.BTCUSDT", "ts": 1742142227610, "type": "delta", "data": {"s": "BTCUSDT", "b": [["84256", "0.102984"], ["84252.44", "0.000099"], ["84250.53", "0.02781"], ["84249.27", "0.002157"], ["84247.74", "0.015307"], ["84247.73", "0.028804"], ["84247.72", "0.02"], ["84246.13", "0"], ["84246.12", "0"], ["84245.92", "0.02"], ["84245.56", "0.039915"], ["84245.55", "0.020614"], ["84245.12", "0"], ["84245.11", "0"], ["84245.1", "0.001243"], ["84244.32", "0"], ["84243.95", "0"], ["84243.35", "0.071227"], ["84238.62", "0.000297"], ["84238.42", "0.118127"], ["84238.11", "0.1134"], ["84234.45", "0"], ["84229.63", "0.161636"], ["84227.67", "0"], ["84226.82", "0.237372"], ["84226.56", "0.178141"], ["84225.4", "0.237372"], ["84222.6", "0.237372"], ["84221.15", "0.297689"], ["84219.24", "0.071248"], ["84219.2", "0"], ["84216.59", "0.014854"], ["84215.54", "0.290257"], ["84214.18", "0"], ["84211.25", "0"], ["84209.35", "0.11"], ["84207.32", "0"], ["84203.38", "0.11"], ["84201.64", "0"], ["84200.92", "0"], ["84200.81", "0"], ["84200.75", "0"], ["84199.27", "0"], ["84199.22", "0"], ["84199.04", "0"], ["84198.51", "0"], ["84198.13", "0"], ["84197.6", "0"]], "a": [["84256.01", "0.05336"], ["84256.36", "0.01"], ["84259.24", "0.092338"], ["84259.25", "0.089922"], ["84259.57", "0.000099"], ["84260.14", "0"], ["84260.91", "0.009903"], ["84267.51", "0"], ["84267.79", "0.005974"], ["84268.94", "0.11547"], ["84269.47", "0.115415"], ["84274.29", "0"], ["84277.11", "0.9"], ["84277.94", "0.174326"], ["84278.12", "0"], ["84280.22", "0.403512"], ["84280.8", "0.179736"], ["84281.77", "1.387074"], ["84282.77", "0"], ["84285.8", "0.237372"], ["84286.42", "0.269735"], ["84288.58", "0"], ["84291.82", "0.271347"], ["84294.21", "0.356134"], ["84300.65", "0"], ["84301.23", "0"], ["84301.35", "0"], ["84302.7", "0"], ["84302.87", "0"], ["84303.07", "0"], ["84303.62", "0"], ["84303.73", "0"], ["84304", "0"]], "u": 7510658, "seq": 66889328521}, "cts": 1742142227608, "record_time": 1742142226.709196}
{"topic": "orderbook.200.BTCUSDT", "ts": 1742142227809, "type": "delta", "data": {"s": "BTCUSDT", "b": [["84256", "0.002984"], ["84250.53", "0.000069"], ["84249.27", "0"], ["84247.74", "0.000297"], ["84247.73", "0.028753"], ["84247.72", "0"], ["84247.62", "0.02"], ["84245.92", "0"], ["84245.82", "0.02"], ["84243.35", "0"], ["84238.83", "0.000297"], ["84238.62", "0"], ["84238.43", "0.070203"], ["84238.42", "0"], ["84238.11", "0"], ["84229.63", "0"], ["84226.82", "0"], ["84226.56", "0"], ["84225.4", "0"], ["84221.18", "0"], ["84221.15", "0"], ["84219.24", "0"], ["84215.54", "0"], ["84214.47", "0"], ["84209.73", "0.071256"], ["84209.35", "0"], ["84203.38", "0"], ["84200.92", "0.001467"], ["84200.81", "0.004566"], ["84200.75", "0.000252"], ["84199.27", "0.001333"], ["84199.22", "0.000615"], ["84199.04", "0.000233"], ["84198.51", "0.000233"], ["84198.13", "0.118629"], ["84196.29", "0.001467"], ["84196.12", "0.000252"], ["84195.91", "0.237372"], ["84195.3", "0.382564"], ["84195.06", "0.001333"]], "a": [["84256.01", "0.084064"], ["84256.35", "0.055034"], ["84261.2", "0.005934"], ["84262.76", "0"], ["84264.44", "0.162"], ["84268.94", "0"], ["84269.47", "0"], ["84277.94", "0"], ["84280.8", "0"], ["84286.42", "0"], ["84291.82", "0"], ["84294.2", "0.35614"], ["84294.21", "0"], ["84301.23", "0.178029"], ["84301.35", "0.059948"], ["84302.7", "0.000252"], ["84302.87", "0.001467"], ["84303.07", "0.059323"]], "u": 7510659, "seq": 66889328875}, "cts": 1742142227806, "record_time": 1742142226.909008}
{"topic": "orderbook.200.BTCUSDT", "ts": 1742142228009, "type": "delta", "data": {"s": "BTCUSDT", "b": [["84256", "0.024952"], ["84250.54", "0.000297"], ["84250.53", "0.02769"], ["84249.27", "0.0096"], ["84248.32", "0.02"], ["84247.74", "0.015589"], ["84247.62", "0"], ["84246.8", "0.0015"], ["84246.52", "0.02"], ["84245.82", "0"], ["84245.55", "0.000614"], ["84245.45", "0.02"], ["84244.69", "0.071226"], ["84239.02", "0.000297"], ["84238.83", "0"], ["84238.61", "0"], ["84238.43", "0"], ["84236.81", "0.118388"], ["84236.5", "0.118564"], ["84235.61", "0.119929"], ["84231.03", "0.237372"], ["84228.83", "0.163796"], ["84228.75", "0.024772"], ["84228.03", "0.161007"], ["84226.82", "0.237372"], ["84224.95", "0.159542"], ["84222.6", "0"], ["84220.36", "0.292246"], ["84219.56", "0.290881"], ["84218.97", "0.071248"], ["84216.97", "0.183029"], ["84213.94", "0.266264"], ["84209.73", "0"], ["84208.8", "0.0013"], ["84201.64", "0.356121"], ["84201.63", "0"], ["84201.5", "0"], ["84201.25", "0"], ["84200.92", "0"], ["84200.81", "0"], ["84200.75", "0"], ["84199.27", "0"], ["84199.22", "0"], ["84199.04", "0"], ["84198.51", "0"], ["84198.13", "0"], ["84196.29", "0"], ["84196.12", "0"], ["84195.91", "0"], ["84195.3", "0"], ["84195.06", "0"]], "a": [["84256.01", "0.075458"], ["84256.35", "0.025825"], ["84261.2", "0"], ["84261.26", "0.008453"], ["84262.82", "0"], ["84264.44", "0.0005"], ["84264.79", "0"], ["84267.31", "0.111199"], ["84267.79", "0"], ["84267.84", "0.109042"], ["84268.65", "0.114876"], ["84275.42", "0.177193"], ["84276.31", "0.161013"], ["84279.17", "0.166917"], ["84280.36", "0"], ["84283.89", "0.270477"], ["84284.78", "0.300645"], ["84290.18", "0.285998"], ["84294.2", "0"], ["84296.11", "0.000713"], ["84296.12", "0"], ["84300.65", "0.356121"], ["84301.35", "0"], ["84302.7", "0"], ["84302.87", "0"], ["84303.07", "0"]], "u": 7510660, "seq": 66889329168}, "cts": 1742142228006, "record_time": 1742142227.109024}
{"topic": "orderbook.200.BTCUSDT", "ts": 1742142228210, "type": "delta", "data": {"s": "BTCUSDT", "b": [["84256", "0.026952"], ["84250.55", "0.027651"], ["84250.54", "0"], ["84250.53", "0"], ["84249.27", "0.011869"], ["84248.33", "0.013176"], ["84247.74", "0"], ["84247.73", "0"], ["84246.15", "0.02"], ["84245.45", "0"], ["84244.69", "0"], ["84242.42", "0.072228"], ["84240.74", "0.000297"], ["84240.21", "0.000297"], ["84239.02", "0"], ["84236.88", "0.153464"], ["84236.81", "0"], ["84236.54", "0.11033"], ["84236.5", "0"], ["84235.61", "0"], ["84235.24", "0.237372"], ["84229.77", "0.168354"], ["84228.83", "0"], ["84228.03", "0"], ["84226.82", "0"], ["84224.95", "0"], ["84221.29", "0.292534"], ["84220.36", "0"], ["84219.56", "0"], ["84218.97", "0"], ["84216.97", "0.005"], ["84213.94", "0"], ["84201.64", "0"], ["84201.63", "0.059948"], ["84201.5", "0.001243"], ["84201.25", "0.00009"], ["84200.92", "0.001467"], ["84200.81", "0.004566"], ["84200.75", "0.000252"], ["84199.27", "0.001333"], ["84199.22", "0.000615"], ["84199.04", "0.000233"], ["84198.51", "0.000233"]], "a": [["84256.01", "0.075611"], ["84261.26", "0"], ["84264.44", "0.1625"], ["84266.24", "0.008453"], ["84267.31", "0"], ["84267.84", "0"], ["84268.65", "0"], ["84269.58", "0.112007"], ["84275.42", "0"], ["84276.31", "0"], ["84276.36", "0.179898"], ["84279.17", "0"], ["84283.89", "0"], ["84284.78", "0"], ["84290.18", "0"], ["84301.35", "0.059948"], ["84302.7", "0.000252"], ["84302.87", "0.001467"], ["84303.07", "0.059323"], ["84303.62", "0.0002"], ["84303.73", "0.11863"], ["84304", "0.000119"]], "u": 7510661, "seq": 66889329496}, "cts": 1742142228207, "record_time": 1742142227.308975}
{"topic": "orderbook.200.BTCUSDT", "ts": 1742142228410, "type": "delta", "data": {"s": "BTCUSDT", "b": [["84256", "0"], ["84255.58", "0"], ["84255.24", "0"], ["84254.63", "0"], ["84254.1", "0"], ["84254.02", "0.003574"], ["84250.55", "0"], ["84249.27", "0"], ["84248.33", "0"], ["84248.32", "0"], ["84248.02", "0.016172"], ["84248.01", "0.030487"], ["84247.57", "0"], ["84246.72", "0.02"], ["84246.52", "0"], ["84246.15", "0"], ["84245.6", "0.028158"], ["84245.59", "0.001833"], ["84245.56", "0.0252"], ["84244.92", "0.02"], ["84244.55", "0.02"], ["84242.42", "0.001"], ["84240.74", "0"], ["84240.21", "0"], ["84239.02", "0.000297"], ["84237.49", "0.000297"], ["84237.48", "0.071232"], ["84236.54", "0"], ["84235.24", "0"], ["84233.23", "0.108845"], ["84231.03", "0"], ["84229.77", "0"], ["84226.45", "0.179214"], ["84222.35", "0"], ["84221.29", "0"], ["84219.9", "0.434003"], ["84216.59", "0"], ["84213.41", "0"], ["84212.08", "0.015188"], ["84209.67", "0.071256"], ["84205.04", "0.0002"], ["84204.38", "0.07135"], ["84204.33", "0.177388"], ["84200.12", "0.237377"], ["84198.13", "0.118629"], ["84196.29", "0.001467"], ["84196.12", "0.000252"], ["84195.91", "0.237377"], ["84195.3", "0.382564"]], "a": [["84254.03", "0.244144"], ["84254.11", "0.012888"], ["84254.76", "0.118774"], ["84254.77", "0.359689"], ["84256", "0.0004"], ["84256.01", "0.010522"], ["84256.35", "0"], ["84256.52", "0"], ["84258.11", "0.0002"], ["84258.74", "0.003233"], ["84259.23", "0.11863"], ["84259.26", "0.000233"], ["84260.91", "0"], ["84261.78", "0"], ["84262.11", "0.005934"], ["84262.6", "0.023737"], ["84262.74", "0"], ["84263.36", "0.037737"], ["84263.37", "0.107299"], ["84264.56", "0"], ["84266.24", "0"], ["84267.47", "0.055902"], ["84267.79", "0.0059"], ["84268.2", "0.036252"], ["84269.58", "0"], ["84270.74", "0"], ["84270.82", "0.000862"], ["84272.35", "0.001243"], ["84273.11", "0.071202"], ["84273.3", "0.06"], ["84276.36", "0"], ["84276.84", "0.180405"], ["84277.38", "0"], ["84281.54", "0.263053"], ["84285", "0"], ["84285.8", "0"], ["84292.37", "0.356151"], ["84296.15", "0.475681"], ["84298.13", "0"], ["84300.65", "0"], ["84303.73", "0"], ["84304", "0"]], "u": 7510662, "seq": 66889330073}, "cts": 1742142228407, "record_time": 1742142227.50956}
{"topic": "orderbook.200.BTCUSDT", "ts": 1742142228609, "type": "delta", "data": {"s": "BTCUSDT", "b": [["84254.02", "0.003019"], ["84252.44", "0"], ["84248.09", "0.030082"], ["84248.08", "0.025166"], ["84248.02", "0"], ["84248.01", "0"], ["84247.18", "0.02"], ["84246.82", "0.02"], ["84246.72", "0"], ["84245.6", "0"], ["84244.65", "0.02"], ["84244.55", "0"], ["84237.49", "0"], ["84236.88", "0.067869"], ["84234.3", "0.110349"], ["84233.98", "0.119939"], ["84233.81", "0.105228"], ["84233.23", "0"], ["84227.03", "0.174466"], ["84226.45", "0"], ["84225.51", "0.163211"], ["84222.6", "0.237377"], ["84222.43", "0.176912"], ["84218.56", "0.298928"], ["84218.39", "0.237377"], ["84217.03", "0.300277"], ["84211.41", "0.281944"], ["84208.7", "0"], ["84204.33", "0.414765"], ["84198.51", "0"], ["84198.13", "0"], ["84196.29", "0"], ["84196.12", "0"], ["84195.91", "0"], ["84195.3", "0"]], "a": [["84254.03", "0.241844"], ["84254.86", "0.011868"], ["84259.57", "0"], ["84260.14", "0.008453"], ["84260.76", "0.011867"], ["84263.37", "0.217322"], ["84264.81", "0.112656"], ["84264.93", "0.068395"], ["84265.34", "0.116107"], ["84266.87", "0.116093"], ["84268.22", "0.000449"], ["84268.61", "0.083989"], ["84270.82", "0.000613"], ["84273.28", "0"], ["84273.59", "0"], ["84273.65", "0.173596"], ["84273.81", "0.174306"], ["84276.67", "0.176368"], ["84277.1", "0.501057"], ["84277.38", "0.237377"], ["84281.54", "0"], ["84282.12", "0.285391"], ["84282.29", "0.285903"], ["84284.32", "0.008281"], ["84284.99", "0"], ["84287.69", "0.296315"], ["84290.9", "0.356154"], ["84292.37", "0"], ["84300.66", "0"], ["84300.82", "0"], ["84300.98", "0"], ["84301.09", "0"], ["84301.18", "0"], ["84301.23", "0"], ["84301.35", "0"], ["84302.7", "0"], ["84302.87", "0"], ["84303.07", "0"], ["84303.62", "0"]], "u": 7510663, "seq": 66889330381}, "cts": 1742142228608, "record_time": 1742142227.711956}
{"topic": "orderbook.200.BTCUSDT", "ts": 1742142228810, "type": "delta", "data": {"s": "BTCUSDT", "b": [["84250.46", "0.000099"], ["84248.17", "0.029677"], ["84248.16", "0.022137"], ["84248.15", "0.029778"], ["84248.09", "0"], ["84248.08", "0"], ["84247.98", "0.02"], ["84247.62", "0.02"], ["84247.18", "0"], ["84246.82", "0"], ["84245.72", "0.02"], ["84245.45", "0.02"], ["84244.92", "0"], ["84244.65", "0"], ["84239.4", "0.023775"], ["84239.39", "0.071231"], ["84237.48", "0"], ["84236.88", "0.147054"], ["84234.3", "0"], ["84233.98", "0"], ["84233.81", "0"], ["84233.8", "0.048"], ["84230.83", "0"], ["84227.03", "0"], ["84225.51", "0"], ["84222.43", "0"], ["84220.77", "0"], ["84218.56", "0"], ["84217.03", "0"], ["84211.41", "0"], ["84206.01", "0"], ["84204.03", "0.000989"], ["84198.51", "0.000233"], ["84198.13", "0.118629"], ["84196.29", "0.001467"], ["84196.12", "0.000252"], ["84195.3", "0.382564"], ["84195.06", "0.001333"], ["84195.01", "0.000615"], ["84195", "0.24702"]], "a": [["84254.03", "0.255972"], ["84257.59", "0.000099"], ["84260.14", "0"], ["84262.46", "0.0005"], ["84263.37", "0.21409"], ["84264.44", "0.162"], ["84264.81", "0"], ["84265.34", "0"], ["84266.87", "0"], ["84267.47", "0.078687"], ["84273.65", "0"], ["84273.81", "0"], ["84276.67", "0"], ["84277.11", "0"], ["84277.55", "0.000989"], ["84279.54", "0"], ["84282.12", "0"], ["84282.29", "0"], ["84287.69", "0"], ["84290.9", "0"], ["84294.21", "0.356149"], ["84300.66", "0.059323"], ["84300.82", "0.003"], ["84300.98", "0.000233"], ["84301.09", "0.0002"], ["84301.23", "0.178029"], ["84301.35", "0.059948"], ["84302.7", "0.000252"], ["84302.87", "0.001467"], ["84303.07", "0.059323"]], "u": 7510664, "seq": 66889330690}, "cts": 1742142228805, "record_time": 1742142227.909514}
{"topic": "orderbook.200.BTCUSDT", "ts": 1742142229010, "type": "delta", "data": {"s": "BTCUSDT", "b": [["84254.02", "0"], ["84253.97", "0"], ["84253.05", "0"], ["84251.88", "0"], ["84251.71", "0"], ["84250.52", "0"], ["84250.46", "0"], ["84250", "0"], ["84249.8", "0"], ["84249.76", "0"], ["84249.47", "0"], ["84248.17", "0"], ["84248.16", "0"], ["84248.15", "0"], ["84248", "0"], ["84247.98", "0"], ["84247.62", "0"], ["84247.24", "0.003153"], ["84247.18", "0.000555"], ["84246.8", "0"], ["84245.86", "0"], ["84245.72", "0"], ["84245.59", "0.001333"], ["84245.56", "0"], ["84245.45", "0"], ["84245.09", "0"], ["84244.2", "0"], ["84243.5", "0"], ["84243.01", "0"], ["84242.8", "0.02"], ["84241.39", "0.029679"], ["84241.35", "0.02"], ["84240.83", "0.02"], ["84239.41", "0.015096"], ["84239.4", "0"], ["84239.39", "0"], ["84238.82", "0.0005"], ["84238.23", "0"], ["84237.34", "0.000296"], ["84237.33", "0.028058"], ["84237.32", "0.028259"], ["84237.31", "0.060386"], ["84236.9", "0"], ["84236.88", "0"], ["84236.6", "0"], ["84235.2", "0"], ["84234.8", "0"], ["84234.69", "0"], ["84233.8", "0"], ["84233.2", "0"], ["84232.1", "0"], ["84231.6", "0"], ["84231.5", "0.04"], ["84231.49", "0.005"], ["84230.9", "0.04"], ["84230.2", "0"], ["84230.17", "0"], ["84229.9", "0"], ["84229.82", "0"], ["84229.31", "0"], ["84228.45", "0"], ["84228.44", "0.07124"], ["84226.65", "0"], ["84226.4", "0.04"], ["84225.73", "0.118491"], ["84224.01", "0"], ["84223.19", "0.111169"], ["84223", "0.040119"], ["84222.9", "0.125352"], ["84222.89", "0"], ["84222.6", "0"], ["84220.99", "0.000817"], ["84220.86", "0.008731"], ["84219.43", "0.003551"], ["84219.3", "0.010354"], ["84217.36", "0"], ["84215.43", "0.068395"], ["84214.74", "0.169205"], ["84214.47", "0.057718"], ["84214.17", "0"], ["84213.09", "0"], ["84212.08", "0"], ["84210.81", "0"], ["84209.67", "0"], ["84208.71", "0"], ["84208.21", "0"], ["84207.41", "0"], ["84207.38", "0.015505"], ["84205.08", "0.023738"], ["84204.93", "0"], ["84204.38", "0.00009"], ["84204.33", "0"], ["84203.69", "0.298541"], ["84203.32", "0"], ["84202.79", "0.005934"], ["84202.51", "0.0002"], ["84202.41", "0"], ["84201.71", "0.023738"], ["84201.06", "0.04"], ["84201.05", "0.039649"], ["84200.12", "0"], ["84199.99", "0.0002"], ["84199.76", "0.071264"], ["84199.11", "0.023738"], ["84198.31", "0.023738"], ["84197.6", "0.162"], ["84197.46", "0.0002"], ["84195.3", "0"], ["84195", "0"], ["84194.79", "0.071269"], ["84194.41", "0.000233"], ["84194.4", "0.167859"], ["84193.88", "0.000233"], ["84193.32", "0.023738"], ["84192.8", "0.00009"], ["84192.33", "0.11863"], ["84192.17", "0.017765"], ["84191.66", "0.001467"], ["84191.58", "0.000335"], ["84191.49", "0.000252"], ["84191.32", "0.059948"], ["84191.31", "0.068395"], ["84190.85", "0.001333"], ["84190.8", "0.000615"], ["84190.6", "0.001243"], ["84190.32", "0.000111"], ["84189.78", "0.000233"], ["84189.25", "0.000233"], ["84188.32", "0.000357"], ["84187.03", "0.001467"], ["84187.01", "0.118791"], ["84186.86", "0.000252"], ["84186.72", "0.013697"], ["84186.64", "0.001333"], ["84186.59", "0.000615"]], "a": [["84247.25", "0.218335"], ["84248.34", "0.157458"], ["84248.35", "0.359689"], ["84249.75", "0.005"], ["84249.84", "0.059948"], ["84250", "0.010336"], ["84250.01", "0.030226"], ["84250.52", "0.059662"], ["84250.53", "0.093246"], ["84251.93", "0.237993"], ["84251.94", "0.359689"], ["84253.98", "0.11863"], ["84254.03", "0.180822"], ["84254.11", "0.000233"], ["84254.63", "0.000233"], ["84254.76", "0.109014"], ["84254.77", "0"], ["84255.57", "0.03789"], ["84255.58", "0.0002"], ["84255.67", "0.04906"], ["84255.68", "0.162"], ["84256", "0"], ["84256.01", "0"], ["84256.35", "0.000252"], ["84256.51", "0.001467"], ["84256.85", "0.068395"], ["84256.9", "0.116789"], ["84258.18", "0.000614"], ["84258.23", "0.001333"], ["84258.41", "0"], ["84258.67", "0.108273"], ["84258.94", "0.112255"], ["84259.24", "0"], ["84259.25", "0"], ["84259.51", "0.109521"], ["84259.83", "0"], ["84260.63", "0.0002"], ["84260.76", "0"], ["84260.78", "0.020684"], ["84261.16", "0"], ["84262", "0.03181"], ["84262.4", "0.000703"], ["84263.36", "0"], ["84263.37", "0.130098"], ["84263.76", "0.015754"], ["84264.15", "0.020997"], ["84264.84", "0.009462"], ["84264.93", "0"], ["84265.3", "0.044"], ["84265.42", "0.176627"], ["84265.6", "0.06"], ["84265.62", "0"], ["84266", "0"], ["84266.65", "0.072541"], ["84267.4", "0.068"], ["84267.95", "0.161436"], ["84268.17", "0.237338"], ["84268.2", "0"], ["84268.22", "0.0002"], ["84268.74", "0.000789"], ["84268.95", "0.237396"], ["84269.32", "0.017796"], ["84270.1", "0.04"], ["84270.21", "0.237332"], ["84270.7", "0.056"], ["84272.1", "0.048"], ["84273.16", "0.237396"], ["84273.57", "0"], ["84273.58", "0.195992"], ["84273.87", "0.272245"], ["84274.42", "0.029801"], ["84276.4", "0.269561"], ["84276.84", "0"], ["84277.1", "0"], ["84277.38", "0"], ["84278.21", "0"], ["84278.22", "0"], ["84278.74", "0.024519"], ["84279.09", "0"], ["84279.24", "0"], ["84279.7", "0.272837"], ["84279.8", "0"], ["84279.94", "0"], ["84280.16", "0"], ["84280.23", "0"], ["84281.35", "0.023738"], ["84281.59", "0"], ["84281.64", "0"], ["84281.78", "0"], ["84282.75", "0"], ["84284.29", "0"], ["84284.38", "0"], ["84284.45", "0"], ["84284.81", "0.023738"], ["84286.53", "0.356175"], ["84289.36", "0.474348"], ["84289.79", "0"], ["84292.01", "0.005934"], ["84292.54", "0.11872"], ["84294.21", "0"], ["84295.08", "0"], ["84296.09", "0.11"], ["84296.15", "0.001333"], ["84297.6", "0"], ["84297.9", "0.305382"], ["84298.06", "0"], ["84298.21", "0"], ["84298.23", "0"], ["84298.29", "0"], ["84298.56", "0"], ["84298.89", "0"], ["84300.33", "0"], ["84300.37", "0"], ["84300.46", "0"], ["84300.48", "0"], ["84300.66", "0"], ["84300.82", "0"], ["84300.98", "0"], ["84301.09", "0"], ["84301.23", "0"], ["84301.35", "0"], ["84302.7", "0"], ["84302.87", "0"], ["84303.07", "0"]], "u": 7510665, "seq": 66889332552}, "cts": 1742142229007, "record_time": 1742142228.110012}
{"topic": "orderbook.200.BTCUSDT", "ts": 1742142229209, "type": "delta", "data": {"s": "BTCUSDT", "b": [["84247.24", "0"], ["84247.18", "0"], ["84247.08", "0"], ["84245.59", "0"], ["84245.55", "0"], ["84245.47", "0"], ["84245.36", "0"], ["84245.1", "0"], ["84244.84", "0"], ["84242.94", "0"], ["84242.8", "0"], ["84242.61", "0.109115"], ["84241.39", "0"], ["84241.35", "0"], ["84240.83", "0"], ["84239.41", "0"], ["84239.02", "0"], ["84238.82", "0"], ["84237.34", "0"], ["84237.33", "0"], ["84237.32", "0"], ["84237.31", "0"], ["84237.19", "0.012548"], ["84237.18", "0.027805"], ["84235.88", "0.008642"], ["84234.19", "0.0005"], ["84233.37", "0.000296"], ["84233.36", "0.028666"], ["84232.49", "0.000543"], ["84232.4", "0.02821"], ["84232.39", "0.000297"], ["84232.11", "0.09385"], ["84231.5", "0"], ["84231.49", "0"], ["84230.9", "0"], ["84230.47", "0.015098"], ["84228.75", "0.073271"], ["84228.44", "0"], ["84228.37", "0.060396"], ["84227.04", "0.02"], ["84226.8", "0.04"], ["84226.22", "0.02"], ["84225.74", "0.112854"], ["84225.73", "0"], ["84225.43", "0.117749"], ["84225.1", "0.04"], ["84225.07", "0.02"], ["84224.7", "0.04"], ["84224.69", "0.119608"], ["84223.2", "0.050951"], ["84223.19", "0"], ["84223", "0.04"], ["84222.9", "0"], ["84222.58", "0.109238"], ["84222.3", "0.003"], ["84220.86", "0"], ["84219.3", "0"], ["84219.1", "0.04"], ["84218.8", "0.04"], ["84218.56", "0.005953"], ["84218.39", "0"], ["84217.93", "0.166399"], ["84217.9", "0.010433"], ["84217.32", "0.162"], ["84216.98", "0.168656"], ["84214.75", "0.099655"], ["84214.74", "0"], ["84214.47", "0"], ["84214.46", "0"], ["84214.13", "0.17763"], ["84213.92", "0.160196"], ["84213.85", "0.019233"], ["84210.2", "0.02466"], ["84209.76", "0.140003"], ["84209.48", "0.291682"], ["84208.53", "0.29848"], ["84207.38", "0"], ["84206.04", "0.109733"], ["84205.75", "0"], ["84205.69", "0.29961"], ["84204.72", "0.024051"], ["84203.69", "0"], ["84202.94", "0.267487"], ["84201.92", "0.015587"], ["84201.71", "0"], ["84201.36", "0.071263"], ["84201.06", "0"], ["84201.05", "0"], ["84200.81", "0"], ["84199.76", "0"], ["84198.14", "0.11863"], ["84198.13", "0"], ["84196.39", "0.323802"], ["84194.94", "0.0002"], ["84194.46", "0.04"], ["84194.45", "0.039645"], ["84193.79", "0.003"], ["84193.02", "0.02374"], ["84192.41", "0.0002"], ["84189.78", "0"], ["84189.25", "0"], ["84188.32", "0"], ["84187.03", "0"], ["84187.01", "0"], ["84186.86", "0"], ["84186.72", "0"], ["84186.64", "0"], ["84186.59", "0"]], "a": [["84242.62", "0.172388"], ["84244.23", "0.000153"], ["84245.23", "0.005"], ["84245.47", "0.0002"], ["84245.59", "0.010392"], ["84245.6", "0.011869"], ["84247.25", "0"], ["84248", "0.0002"], ["84248.08", "0.011869"], ["84248.32", "0.181533"], ["84248.33", "0.11863"], ["84248.34", "0"], ["84248.85", "0.02374"], ["84249.47", "0.000233"], ["84249.76", "0.000614"], ["84249.8", "0.001333"], ["84250", "0.000233"], ["84250.01", "0"], ["84250.52", "0.17212"], ["84251.71", "0.000252"], ["84251.88", "0.001467"], ["84251.93", "0"], ["84251.94", "0"], ["84253.05", "0.0002"], ["84253.89", "0.00009"], ["84254.03", "0.175622"], ["84254.76", "0.114929"], ["84254.86", "0"], ["84255.48", "0.020997"], ["84255.67", "0"], ["84256.15", "0.105468"], ["84256.68", "0.111227"], ["84256.9", "0"], ["84257.59", "0"], ["84257.63", "0.11533"], ["84258.04", "0.015587"], ["84258.67", "0"], ["84258.89", "0.119498"], ["84258.94", "0.08031"], ["84259.09", "0.008453"], ["84259.51", "0"], ["84261.17", "0.083989"], ["84261.2", "0.023182"], ["84261.45", "0.001243"], ["84262", "0"], ["84262.2", "0.06"], ["84262.44", "0.007267"], ["84262.6", "0"], ["84262.7", "0.044"], ["84262.97", "0.237352"], ["84263.37", "0.188833"], ["84263.76", "0"], ["84264.1", "0.048"], ["84264.15", "0"], ["84264.38", "0.159493"], ["84264.4", "0.048"], ["84265.12", "0.16448"], ["84265.42", "0"], ["84265.85", "0.121262"], ["84266.34", "0.237343"], ["84267.34", "0.171934"], ["84267.47", "0.361315"], ["84267.95", "0"], ["84267.97", "0.170966"], ["84268.17", "0"], ["84268.61", "0"], ["84270.21", "0"], ["84270.4", "0.068"], ["84271.74", "0.23741"], ["84271.8", "0.237396"], ["84272.2", "0"], ["84272.83", "0.279914"], ["84273.1", "0"], ["84273.15", "0.397955"], ["84273.16", "0"], ["84273.3", "0"], ["84273.57", "0.271308"], ["84273.58", "0"], ["84273.8", "0"], ["84273.87", "0"], ["84274.23", "0.03181"], ["84274.42", "0"], ["84275", "0"], ["84275.5", "0"], ["84275.79", "0.294233"], ["84275.83", "0"], ["84275.95", "0.23741"], ["84276.02", "0.237396"], ["84276.39", "0.295321"], ["84276.4", "0"], ["84276.7", "0"], ["84278.95", "0.26768"], ["84279.7", "0"], ["84281.2", "0.026414"], ["84283.51", "0.357518"], ["84284.73", "0.474348"], ["84284.81", "0"], ["84285.29", "0.32346"], ["84286.53", "0"], ["84289.19", "0.029801"], ["84289.36", "0"], ["84293.49", "0"], ["84293.5", "0"], ["84293.59", "0"], ["84294.15", "0"], ["84294.22", "0"], ["84295.55", "0"], ["84295.82", "0"], ["84296.02", "0"], ["84296.03", "0"], ["84296.09", "0"], ["84296.11", "0"], ["84296.15", "0"], ["84296.35", "0"], ["84296.39", "0"], ["84296.44", "0"], ["84296.71", "0"], ["84297.7", "0"], ["84297.9", "0"]], "u": 7510666, "seq": 66889334220}, "cts": 1742142229207, "record_time": 1742142228.309013}
{"topic": "orderbook.200.BTCUSDT", "ts": 1742142229409, "type": "delta", "data": {"s": "BTCUSDT", "b": [["84238.41", "0.001174"], ["84235.88", "0"], ["84228.75", "0.115467"], ["84227.73", "0.02"], ["84227.04", "0"], ["84226.41", "0.117379"], ["84226.22", "0.001487"], ["84226.09", "0.115879"], ["84226", "0.04"], ["84225.75", "0.162"], ["84225.74", "0"], ["84225.73", "0.02"], ["84225.6", "0.04"], ["84225.48", "0.010514"], ["84225.43", "0"], ["84225.07", "0"], ["84224.69", "0"], ["84224.04", "0.33304"], ["84223.34", "0.113945"], ["84223", "0.088"], ["84222.58", "0"], ["84219.9", "0.493951"], ["84219.5", "0.00909"], ["84218.56", "0"], ["84218.39", "0.23741"], ["84217.93", "0"], ["84217.9", "0"], ["84217.65", "0.165779"], ["84216.98", "0"], ["84216.97", "0.24241"], ["84214.89", "0.161904"], ["84214.58", "0.161113"], ["84214.18", "0.23741"], ["84214.13", "0"], ["84213.92", "0"], ["84212.15", "0.015771"], ["84210.19", "0.344719"], ["84209.48", "0"], ["84209.2", "0.283864"], ["84208.53", "0"], ["84206.45", "0.298883"], ["84206.05", "0.11863"], ["84205.75", "0.178057"], ["84205.69", "0"], ["84204.03", "0"], ["84202.94", "0"], ["84201.92", "0"], ["84194.79", "0"], ["84192.65", "0.000989"], ["84191.33", "0.356157"], ["84190.85", "0"], ["84190.8", "0"], ["84190.6", "0"], ["84190.32", "0"]], "a": [["84242.62", "0.086467"], ["84244.23", "0"], ["84245.59", "0"], ["84246.18", "0.000099"], ["84248.08", "0"], ["84248.32", "0"], ["84248.33", "0"], ["84248.35", "0"], ["84248.85", "0"], ["84249.35", "0.011869"], ["84249.84", "0"], ["84250.52", "0.059662"], ["84251.04", "0.045595"], ["84253.97", "0.000614"], ["84253.98", "0"], ["84254.02", "0.001333"], ["84254.03", "0.011675"], ["84254.39", "0.010514"], ["84254.76", "0"], ["84255.68", "0"], ["84256.15", "0"], ["84256.68", "0"], ["84256.81", "0.11498"], ["84257.3", "0.044"], ["84257.34", "0.10764"], ["84257.6", "0.06"], ["84257.63", "0"], ["84258.04", "0"], ["84258.87", "0.11863"], ["84258.89", "0"], ["84258.94", "0.192853"], ["84259.23", "0"], ["84259.4", "0.068"], ["84259.66", "0.107753"], ["84260.8", "0.04"], ["84262.7", "0.1"], ["84262.97", "0"], ["84264.38", "0"], ["84264.44", "0"], ["84265.12", "0"], ["84265.3", "0"], ["84265.6", "0"], ["84265.79", "0.159953"], ["84265.85", "0"], ["84266.13", "0.000989"], ["84266.2", "0.237343"], ["84266.34", "0"], ["84266.65", "0.001333"], ["84267.34", "0"], ["84267.38", "0.23734"], ["84267.47", "0"], ["84267.72", "0.015771"], ["84267.97", "0"], ["84268.1", "0.176347"], ["84271.74", "0"], ["84271.8", "0"], ["84272.1", "0"], ["84272.83", "0"], ["84273.15", "0.022"], ["84273.16", "0.23741"], ["84273.57", "0"], ["84274.23", "0.319431"], ["84274.8", "0"], ["84275.79", "0"], ["84275.95", "0"], ["84276.02", "0"], ["84276.39", "0"], ["84276.55", "0.271453"], ["84277.55", "0"], ["84278.95", "0"], ["84279.62", "0.290525"], ["84280", "0"], ["84281.77", "0.000296"], ["84283.51", "0.001333"], ["84290.02", "0.178057"], ["84292.37", "0.356157"], ["84292.74", "0.05964"], ["84293.49", "0.001225"], ["84293.5", "0.0002"], ["84293.59", "0.001467"], ["84294.15", "0.001243"], ["84294.22", "0.089922"], ["84295.55", "0.023736"], ["84295.82", "0.000233"], ["84296.03", "0.0002"], ["84296.11", "0.000713"], ["84296.15", "0.001333"], ["84296.35", "0.000233"], ["84296.44", "0.000089"], ["84296.71", "0.059323"], ["84297.7", "0.11863"], ["84297.9", "0.305382"], ["84298.06", "0.000252"]], "u": 7510667, "seq": 66889334804}, "cts": 1742142229407, "record_time": 1742142228.509226}
{"topic": "orderbook.200.BTCUSDT", "ts": 1742142229610, "type": "delta", "data": {"s": "BTCUSDT", "b": [["84249.74", "0.336318"], ["84247.99", "0.01"], ["84246.18", "0.039607"], ["84246.17", "0.09929"], ["84245.47", "0.0002"], ["84245.23", "0.0004"], ["84245.22", "0.0004"], ["84244.84", "0.000233"], ["84242.94", "0.0002"], ["84242.61", "0.002428"], ["84241.32", "0.0005"], ["84240.65", "0.11112"], ["84240.35", "0.005"], ["84240.34", "0.11612"], ["84238.68", "0.039789"], ["84238.66", "0.110918"], ["84238.44", "0.015096"], ["84238.41", "0"], ["84237.93", "0.105457"], ["84237.19", "0"], ["84237.18", "0"], ["84236.91", "0.100892"], ["84236.9", "0.237426"], ["84236.33", "0.060386"], ["84236.08", "0.01056"], ["84236.06", "0.005"], ["84234.8", "0.04"], ["84234.78", "0.000543"], ["84234.72", "0.02"], ["84234.53", "0.231632"], ["84234.19", "0"], ["84233.82", "0.237389"], ["84233.36", "0"], ["84232.83", "0.0202"], ["84232.49", "0"], ["84232.41", "0.000297"], ["84232.4", "0"], ["84232.39", "0"], ["84232.38", "0.015249"], ["84232.15", "0.001487"], ["84232.12", "0.101035"], ["84232.11", "0"], ["84231.92", "0.181431"], ["84231.5", "0.04"], ["84231.03", "0.237402"], ["84230.92", "0.019233"], ["84230.71", "0.005935"], ["84230.47", "0"], ["84229.61", "0.237389"], ["84229.51", "0.169392"], ["84228.87", "0.162428"], ["84228.75", "0.18719"], ["84228.37", "0"], ["84227.73", "0"], ["84226.41", "0"], ["84226.22", "0"], ["84226.09", "0"], ["84225.73", "0"], ["84225.48", "0"], ["84225.44", "0.068395"], ["84223.51", "0.282526"], ["84223.34", "0"], ["84223.2", "0"], ["84222.81", "0.015841"], ["84222.8", "0.021121"], ["84221.09", "0.282575"], ["84220.99", "0"], ["84220.76", "0.071247"], ["84219.9", "0.701038"], ["84219.89", "0"], ["84219.8", "0.089922"], ["84218.39", "0"], ["84217.99", "0.005997"], ["84217.93", "0.267965"], ["84217.65", "0"], ["84216.97", "0.005"], ["84215.43", "0"], ["84215.36", "0.023739"], ["84214.9", "0.174632"], ["84214.89", "0"], ["84214.75", "0"], ["84214.63", "0.071252"], ["84214.58", "0"], ["84214.18", "0"], ["84213.85", "0"], ["84212.15", "0"], ["84211.56", "0.323744"], ["84210.2", "0.234169"], ["84210.19", "0.059948"], ["84209.95", "0"], ["84209.2", "0"], ["84206.46", "0.35609"], ["84206.45", "0"], ["84206.06", "0.004611"], ["84205.9", "1.439919"], ["84205.26", "0.10803"], ["84201.36", "0"], ["84196.39", "0"], ["84195.6", "0.24702"], ["84195.01", "0"], ["84194.94", "0"], ["84194.46", "0"], ["84194.45", "0"], ["84194.41", "0"], ["84194.4", "0"], ["84193.88", "0"], ["84193.79", "0"], ["84193.32", "0"], ["84193.02", "0"], ["84192.8", "0"], ["84192.65", "0"], ["84192.41", "0"], ["84192.33", "0"], ["84192.17", "0"], ["84191.66", "0"], ["84191.58", "0"], ["84191.49", "0"], ["84191.33", "0"], ["84191.32", "0"], ["84191.31", "0"]], "a": [["84242.62", "0"], ["84245.23", "0"], ["84245.47", "0"], ["84245.6", "0"], ["84246.18", "0"], ["84248", "0"], ["84249.35", "0"], ["84249.47", "0"], ["84249.75", "0.02526"], ["84250.52", "0.0002"], ["84250.53", "0"], ["84251.04", "0"], ["84253.89", "0"], ["84254.07", "0.005"], ["84254.39", "0"], ["84255.48", "0"], ["84255.57", "0"], ["84256.36", "0"], ["84256.48", "0.000629"], ["84256.81", "0"], ["84256.85", "0"], ["84257.3", "0"], ["84257.34", "0"], ["84257.6", "0"], ["84258.87", "0"], ["84258.94", "0"], ["84259.09", "0"], ["84259.4", "0"], ["84259.66", "0"], ["84260.78", "0"], ["84260.8", "0"], ["84260.98", "0.011049"], ["84261.14", "0.000297"], ["84261.17", "0"], ["84262.11", "0"], ["84262.2", "0"], ["84262.44", "0.001333"], ["84262.7", "0"], ["84263.37", "0.000233"], ["84263.49", "0.020997"], ["84264.1", "0"], ["84264.4", "0"], ["84264.5", "0.044"], ["84264.7", "0.06"], ["84264.84", "0"], ["84264.89", "0.01056"], ["84265.21", "0"], ["84265.79", "0"], ["84266.2", "0"], ["84266.99", "0.140001"], ["84267.37", "0.11863"], ["84267.38", "0"], ["84267.39", "0.242368"], ["84267.72", "0"], ["84267.85", "0"], ["84267.97", "0.068395"], ["84268.1", "0"], ["84268.43", "0.008453"], ["84268.95", "0"], ["84269.1", "0.04"], ["84270.1", "0"], ["84270.7", "0"], ["84270.96", "0.117204"], ["84271.49", "0.226515"], ["84273.1", "0.056"], ["84273.11", "0"], ["84273.14", "1.409365"], ["84273.15", "0.316774"], ["84273.16", "0"], ["84273.99", "0.021106"], ["84274.12", "0.117037"], ["84274.23", "0"], ["84274.43", "0"], ["84274.44", "0"], ["84275.04", "0.162613"], ["84276.54", "0.288899"], ["84276.55", "0"], ["84278.16", "0.015841"], ["84278.23", "0.171263"], ["84278.74", "0"], ["84279.62", "0"], ["84279.91", "0.162489"], ["84279.97", "0"], ["84280.22", "0"], ["84281.2", "0"], ["84281.34", "0.057042"], ["84281.59", "0.237402"], ["84282.54", "0.164943"], ["84282.75", "0.171004"], ["84283.39", "0.071394"], ["84283.84", "0.024527"], ["84284.73", "0"], ["84285.29", "0"], ["84285.8", "0.237402"], ["84287.78", "0.07119"], ["84288.33", "0.278474"], ["84289.19", "0"], ["84290.02", "0"], ["84290.96", "0.289052"], ["84292.19", "0.05015"], ["84292.37", "0"], ["84293.69", "0.28121"], ["84297.02", "0.237389"], ["84298.21", "0.023733"], ["84298.23", "0.001467"], ["84298.29", "0.431067"], ["84298.56", "0.0002"], ["84298.89", "0.022"], ["84300.12", "0.003495"], ["84300.33", "0.000613"], ["84300.37", "0.001333"], ["84300.46", "0.000233"], ["84300.48", "0.005932"], ["84300.66", "0.059323"], ["84300.98", "0.000233"], ["84301.09", "0.0002"], ["84301.23", "0.237389"], ["84301.32", "0.237389"], ["84301.35", "0.059948"], ["84301.55", "0.0045"], ["84301.58", "0.0045"], ["84301.78", "0.0045"], ["84301.98", "0.0045"], ["84302.7", "0.000252"], ["84302.87", "0.001467"], ["84303.07", "0.059323"], ["84303.62", "0.0002"], ["84303.73", "0.11863"], ["84303.81", "0.0045"]], "u": 7510668, "seq": 66889336627}, "cts": 1742142229606, "record_time": 1742142228.710016}
{"topic": "orderbook.200.BTCUSDT", "ts": 1742142229809, "type": "delta", "data": {"s": "BTCUSDT", "b": [["84249.74", "0.308947"], ["84248.91", "0.000422"], ["84246.18", "0.039706"], ["84245.54", "0.01187"], ["84243.01", "0.00395"], ["84240.65", "0"], ["84240.34", "0"], ["84238.71", "0.119587"], ["84238.68", "0"], ["84238.66", "0"], ["84238.4", "0.114392"], ["84237.93", "0"], ["84237.03", "0.116627"], ["84236.98", "0.02"], ["84236.91", "0.218323"], ["84236.9", "0"], ["84236.62", "0.02"], ["84236.12", "0.000817"], ["84236.08", "0"], ["84235.71", "0.120385"], ["84235.4", "0.04"], ["84235.24", "0.237389"], ["84234.78", "0"], ["84234.72", "0"], ["84234.65", "0.237432"], ["84234.62", "0.02"], ["84234.53", "0"], ["84234.35", "0.02"], ["84233.28", "0.068395"], ["84233.2", "0.04"], ["84232.97", "0.237437"], ["84232.83", "0.0002"], ["84232.38", "0.015"], ["84232.15", "0"], ["84232.12", "0.322955"], ["84231.92", "0"], ["84231.83", "0.010617"], ["84231.34", "0.237441"], ["84230.29", "0.161291"], ["84230", "0.04"], ["84229.98", "0.177032"], ["84229.8", "0.04"], ["84229.51", "0"], ["84228.87", "0"], ["84228.75", "0"], ["84227.3", "0.15903"], ["84226.92", "0.180341"], ["84226.4", "0"], ["84225.44", "0"], ["84224.04", "0"], ["84223.51", "0"], ["84223", "0.048"], ["84221.87", "0.287697"], ["84221.56", "0.299438"], ["84221.09", "0"], ["84220.76", "0"], ["84219.9", "0.267035"], ["84219.8", "0"], ["84218.88", "0.267909"], ["84217.93", "0"], ["84215.98", "0.291439"], ["84214.9", "0"], ["84211.57", "0.11863"], ["84211.09", "0.071255"], ["84210.2", "0.02466"], ["84208.55", "0.178042"], ["84206.46", "0"], ["84199.78", "0.000989"], ["84198.51", "0"], ["84198.31", "0"], ["84198.14", "0"], ["84197.6", "0"], ["84197.46", "0"], ["84196.29", "0"], ["84196.12", "0"], ["84195.6", "0"], ["84195.06", "0"]], "a": [["84253.31", "0.000099"], ["84253.95", "0.011868"], ["84256.48", "0.011868"], ["84258.1", "0.024931"], ["84258.11", "0.028362"], ["84258.17", "0.04956"], ["84260.55", "0.010617"], ["84260.94", "0.000297"], ["84260.95", "0.065445"], ["84260.96", "0.11863"], ["84260.98", "0.000252"], ["84262.46", "0"], ["84264.69", "0.089821"], ["84264.89", "0"], ["84265.59", "0.083987"], ["84266.13", "0"], ["84267.06", "0.089922"], ["84267.7", "0.044"], ["84269.02", "0.113417"], ["84269.54", "0.116681"], ["84269.86", "0.119343"], ["84270.96", "0"], ["84271.4", "0.06"], ["84271.49", "0"], ["84271.91", "0.116487"], ["84273.13", "0.556571"], ["84273.15", "0"], ["84273.26", "0.000989"], ["84273.76", "0.015925"], ["84274.12", "0"], ["84274.4", "0.048"], ["84274.7", "0.048"], ["84274.79", "0.485792"], ["84276.54", "0"], ["84276.59", "0.170922"], ["84277.47", "0.071199"], ["84277.68", "0.009462"], ["84277.96", "0.170113"], ["84278.16", "0"], ["84278.23", "0"], ["84279.91", "0"], ["84280.23", "0.237389"], ["84280.33", "0.178109"], ["84280.8", "0.165801"], ["84281.77", "0"], ["84282.54", "0"], ["84282.75", "0"], ["84284.35", "0.03181"], ["84284.45", "0.194082"], ["84285.01", "0.28408"], ["84286.38", "0.293886"], ["84287.78", "0"], ["84288.33", "0"], ["84288.75", "0.295749"], ["84290.96", "0"], ["84291.74", "0.267237"], ["84293.69", "0"], ["84296.66", "0.059553"], ["84297.02", "0"], ["84300.03", "0.029801"], ["84300.46", "0"], ["84300.48", "0"], ["84300.66", "0"], ["84300.98", "0"], ["84301.09", "0"], ["84301.23", "0"], ["84301.32", "0"], ["84301.35", "0"], ["84301.55", "0"], ["84301.58", "0"], ["84301.78", "0"], ["84301.98", "0"], ["84302.7", "0"], ["84302.87", "0"], ["84303.07", "0"], ["84303.62", "0"], ["84303.73", "0"], ["84303.81", "0"]], "u": 7510669, "seq": 66889337092}, "cts": 1742142229807, "record_time": 1742142228.909016}
{"topic": "orderbook.200.BTCUSDT", "ts": 1742142230010, "type": "delta", "data": {"s": "BTCUSDT", "b": [["84249.74", "0.308447"], ["84245.95", "0.071225"], ["84245.54", "0"], ["84245.22", "0"], ["84243.01", "0"], ["84238.71", "0"], ["84238.52", "0.080493"], ["84238.51", "0.112457"], ["84238.4", "0"], ["84238.2", "0.119089"], ["84238.12", "0.02"], ["84237.45", "0.02"], ["84237.03", "0"], ["84237", "0.04"], ["84236.98", "0"], ["84236.91", "0.308964"], ["84236.88", "0.02"], ["84236.62", "0"], ["84236.6", "0.04"], ["84236.33", "0.180177"], ["84236.12", "0.020817"], ["84235.96", "0.119964"], ["84235.71", "0"], ["84234.62", "0"], ["84234.35", "0"], ["84234.15", "0.02"], ["84233.7", "0.048"], ["84230.29", "0"], ["84229.98", "0"], ["84229.78", "0.161896"], ["84229.59", "0.180845"], ["84227.54", "0.170007"], ["84227.3", "0"], ["84226.92", "0"], ["84226.8", "0"], ["84226.73", "0.165397"], ["84225.6", "0"], ["84224.7", "0"], ["84222.82", "0.193668"], ["84221.87", "0"], ["84221.56", "0"], ["84221.36", "0.29965"], ["84221.17", "0.272227"], ["84219.13", "0.263832"], ["84219.1", "0"], ["84218.88", "0"], ["84218.8", "0"], ["84216.97", "0.183042"], ["84215.98", "0"], ["84215.78", "0.298905"], ["84206.06", "0.360707"], ["84205.9", "0"], ["84204.72", "0"], ["84198.51", "0.000233"], ["84198.31", "0.023738"], ["84198.14", "0.11863"], ["84197.46", "0.0002"], ["84197.2", "0.24702"]], "a": [["84251.69", "0.07122"], ["84253.95", "0"], ["84258.1", "0"], ["84258.11", "0.0002"], ["84260.95", "0"], ["84260.96", "0"], ["84261.14", "0.019408"], ["84261.2", "0"], ["84264.49", "0.000297"], ["84268.82", "0.113895"], ["84269.02", "0"], ["84269.16", "0.116434"], ["84269.32", "0"], ["84269.35", "0.11554"], ["84269.54", "0"], ["84269.86", "0"], ["84271.91", "0"], ["84272.16", "0.119004"], ["84275.89", "0.163089"], ["84276.59", "0"], ["84277.38", "0.237389"], ["84277.47", "0"], ["84277.77", "0.171062"], ["84277.96", "0"], ["84278.68", "0.017796"], ["84280.22", "0.33134"], ["84280.23", "0"], ["84280.33", "0"], ["84280.58", "0.171123"], ["84280.6", "0.173003"], ["84280.8", "0"], ["84281.34", "0"], ["84284.31", "0.276293"], ["84284.45", "0"], ["84285.01", "0"], ["84285.8", "0"], ["84286.18", "0.264001"], ["84286.38", "0"], ["84287.69", "0.07119"], ["84288.75", "0"], ["84289", "0.276493"], ["84291.55", "0.263377"], ["84291.74", "0.000335"], ["84300.46", "0.000233"], ["84300.48", "0.005932"], ["84300.66", "0.059323"], ["84300.98", "0.000233"]], "u": 7510670, "seq": 66889337387}, "cts": 1742142230005, "record_time": 1742142229.109092}
{"topic": "orderbook.200.BTCUSDT", "ts": 1742142230209, "type": "delta", "data": {"s": "BTCUSDT", "b": [["84256.34", "0.107252"], ["84254.02", "0.055232"], ["84253.04", "0.041467"], ["84251.87", "0.06"], ["84251.7", "0.0704"], ["84250.51", "0.1"], ["84249.79", "0.394188"], ["84249.77", "0.024733"], ["84249.76", "0.0004"], ["84249.75", "0.0004"], ["84249.74", "0.001186"], ["84249.59", "0.071222"], ["84248.91", "0.011869"], ["84246.18", "0.000099"], ["84246.17", "0"], ["84245.95", "0"], ["84245.55", "0.000614"], ["84245.23", "0"], ["84244.77", "0.005"], ["84241.37", "0.0005"], ["84241.36", "0.162"], ["84241.32", "0"], ["84240.57", "0.082227"], ["84240.56", "0.015095"], ["84239.78", "0.02"], ["84239.48", "0.111767"], ["84239.17", "0.120502"], ["84238.75", "0.02"], ["84238.52", "0"], ["84238.51", "0"], ["84238.44", "0"], ["84238.2", "0"], ["84237.45", "0"], ["84237.23", "0.108605"], ["84237.04", "0.114739"], ["84236.99", "0.237425"], ["84236.88", "0"], ["84236.87", "0.01074"], ["84236.33", "0.060386"], ["84236.22", "0.02"], ["84236.12", "0.000817"], ["84236.06", "0"], ["84235.96", "0"], ["84235.95", "0.02"], ["84234.65", "0"], ["84234.15", "0"], ["84233.82", "0"], ["84232.97", "0"], ["84232.83", "0.090122"], ["84232", "0.04"], ["84231.83", "0"], ["84231.34", "0"], ["84231.03", "0"], ["84230.75", "0.172409"], ["84230.31", "0.15933"], ["84229.81", "0.059948"], ["84229.78", "0"], ["84229.61", "0"], ["84229.59", "0"], ["84228.82", "0.168019"], ["84227.72", "0.016151"], ["84227.7", "0.17817"], ["84227.55", "0.161388"], ["84227.54", "0"], ["84226.73", "0"], ["84226", "0"], ["84225.1", "0"], ["84224.81", "0.265027"], ["84223", "0"], ["84222.81", "0"], ["84222.34", "0.283041"], ["84221.64", "0.071246"], ["84221.36", "0"], ["84221.17", "0"], ["84220.4", "0.289082"], ["84220.27", "0.023885"], ["84219.13", "0"], ["84217.33", "0.11863"], ["84217.2", "1.43046"], ["84216.97", "0.005"], ["84216.76", "0.291349"], ["84215.78", "0"], ["84215.36", "0"], ["84211.09", "0"], ["84210.2", "0.380737"], ["84209.87", "0.023738"], ["84206.06", "0.004611"], ["84203", "0.24702"], ["84200", "0.000119"], ["84199.99", "0"], ["84199.78", "0"], ["84199.27", "0"], ["84199.22", "0"], ["84199.11", "0"], ["84199.04", "0"], ["84198.51", "0"], ["84198.31", "0"], ["84198.14", "0"], ["84197.46", "0"], ["84197.2", "0"]], "a": [["84249.75", "0"], ["84249.76", "0"], ["84249.8", "0"], ["84250", "0"], ["84250.52", "0"], ["84251.69", "0"], ["84251.71", "0"], ["84251.88", "0"], ["84253.05", "0"], ["84253.31", "0"], ["84253.97", "0"], ["84254.02", "0"], ["84254.03", "0"], ["84254.07", "0"], ["84254.11", "0"], ["84254.63", "0"], ["84255.58", "0"], ["84256.35", "0.125252"], ["84256.48", "0"], ["84258.43", "0.005"], ["84260.55", "0"], ["84260.94", "0"], ["84261.14", "0"], ["84261.15", "0.001467"], ["84262.4", "0.000613"], ["84263.49", "0"], ["84264.5", "0"], ["84264.68", "0.000297"], ["84264.69", "0"], ["84264.7", "0"], ["84265.37", "0.01074"], ["84265.63", "0.020996"], ["84267.06", "0"], ["84267.37", "0"], ["84267.39", "0"], ["84267.4", "0"], ["84267.69", "0.11863"], ["84267.7", "0"], ["84267.79", "0"], ["84267.97", "0"], ["84268.43", "0"], ["84268.74", "0"], ["84268.82", "0"], ["84269.16", "0"], ["84269.35", "0"], ["84269.77", "0.110098"], ["84269.85", "0.109318"], ["84270.3", "0.119144"], ["84270.4", "0"], ["84271.4", "0"], ["84272.16", "0"], ["84273.06", "0.008453"], ["84273.1", "0"], ["84273.14", "0"], ["84273.41", "0.109461"], ["84273.76", "0"], ["84273.9", "0.06"], ["84274.4", "0"], ["84274.7", "0"], ["84274.79", "0"], ["84275.04", "0.000613"], ["84275.6", "0.068"], ["84275.62", "0.068395"], ["84275.89", "0"], ["84276.58", "0.161251"], ["84277.37", "0.234143"], ["84277.38", "0"], ["84277.77", "0"], ["84278.42", "0.01611"], ["84278.71", "0.179376"], ["84280.58", "0"], ["84280.6", "0"], ["84281.55", "0.169326"], ["84281.82", "0.174571"], ["84282.17", "0.023739"], ["84283.39", "0.0002"], ["84283.84", "0"], ["84284.31", "0"], ["84284.35", "0"], ["84284.64", "0.000789"], ["84285", "0.270357"], ["84286.18", "0"], ["84287.12", "0.273768"], ["84289", "0"], ["84289.85", "0.023128"], ["84290.14", "0.005934"], ["84290.23", "0.296036"], ["84291.55", "0"], ["84292.38", "0"], ["84292.48", "0.274279"], ["84292.77", "0.071186"], ["84300.03", "0"], ["84301.09", "0.0002"], ["84301.35", "0.059948"], ["84301.55", "0.0045"], ["84301.58", "0.0045"], ["84301.78", "0.0045"], ["84301.98", "0.0045"], ["84302.7", "0.000252"], ["84302.87", "0.001467"], ["84303.07", "0.059323"], ["84303.6", "0.015"], ["84303.62", "0.0002"], ["84303.73", "0.11863"], ["84303.81", "0.0045"], ["84304", "0.000119"], ["84304.01", "0.0045"], ["84304.21", "0.0045"], ["84304.28", "0.0045"], ["84304.48", "0.0045"], ["84304.54", "0.003863"], ["84304.58", "0.001315"], ["84304.95", "0.000089"], ["84305.05", "0.003748"], ["84305.1", "0.000786"], ["84305.44", "0.019981"], ["84305.54", "0.352414"], ["84305.62", "0.000235"], ["84306.15", "0.0002"], ["84306.35", "0.089922"], ["84306.44", "0.023732"], ["84306.84", "0.023732"], ["84307.34", "0.000253"]], "u": 7510671, "seq": 66889339218}, "cts": 1742142230207, "record_time": 1742142229.309254}
{"topic": "orderbook.200.BTCUSDT", "ts": 1742142230409, "type": "delta", "data": {"s": "BTCUSDT", "b": [["84258.22", "0.238019"], ["84258.18", "0.034498"], ["84258.11", "0.05"], ["84256.69", "0.071216"], ["84256.34", "0"], ["84255.58", "0.0002"], ["84254.02", "0"], ["84253.97", "0.000614"], ["84253.04", "0"], ["84251.88", "0.001467"], ["84251.87", "0"], ["84251.71", "0.000252"], ["84251.7", "0.0302"], ["84250.51", "0"], ["84249.79", "0.002366"], ["84249.77", "0"], ["84249.76", "0.001014"], ["84249.74", "0"], ["84249.59", "0"], ["84249.47", "0.000233"], ["84249.11", "0.005"], ["84248.91", "0"], ["84248", "0.0002"], ["84247.91", "0.0005"], ["84247.24", "0.001467"], ["84247.08", "0.000252"], ["84246.88", "0.015093"], ["84246.18", "0"], ["84245.59", "0.001333"], ["84245.36", "0.000233"], ["84244.28", "0.02"], ["84243.82", "0.02"], ["84243.68", "0.112265"], ["84243.67", "0.237371"], ["84243.5", "0.00009"], ["84243.25", "0.02"], ["84241.93", "0.010802"], ["84241.92", "0.02"], ["84241.65", "0.02"], ["84241.51", "0.265565"], ["84241.37", "0"], ["84240.71", "0.158638"], ["84240.57", "0"], ["84240.56", "0"], ["84240.35", "0"], ["84239.78", "0"], ["84239.48", "0"], ["84239.46", "0.237371"], ["84239.17", "0"], ["84238.75", "0"], ["84238.6", "0.04"], ["84238.58", "0.06038"], ["84238.4", "0.04"], ["84238.12", "0"], ["84238.04", "0.237366"], ["84237.23", "0"], ["84237.05", "0.273729"], ["84237.04", "0"], ["84236.99", "0"], ["84236.91", "0"], ["84236.87", "0"], ["84236.33", "0"], ["84236.22", "0"], ["84235.95", "0"], ["84232.62", "0.01629"], ["84232.29", "0.280071"], ["84232.12", "0.101035"], ["84230.75", "0"], ["84230.31", "0.0002"], ["84228.82", "0"], ["84227.72", "0"], ["84227.7", "0"], ["84227.58", "0.071241"], ["84227.55", "0"], ["84226.82", "0.178024"], ["84226.49", "0.28373"], ["84225.54", "0.023737"], ["84224.12", "0.071244"], ["84222.83", "0.11863"], ["84222.82", "0"], ["84222.34", "0"], ["84221.64", "0"], ["84220.4", "0"], ["84216.76", "0"], ["84214.63", "0"], ["84210.2", "0.02466"], ["84207.5", "0.24702"], ["84206.06", "0.360693"], ["84203", "0"], ["84201.25", "0"], ["84200.92", "0"], ["84200.75", "0"], ["84200", "0"]], "a": [["84256.35", "0"], ["84256.51", "0"], ["84258.11", "0"], ["84258.17", "0"], ["84258.18", "0"], ["84258.23", "0.002519"], ["84258.43", "0"], ["84258.74", "0.000233"], ["84259.91", "0.000099"], ["84262.93", "0.005"], ["84264.49", "0"], ["84264.68", "0"], ["84265.37", "0"], ["84265.59", "0"], ["84265.63", "0"], ["84266.6", "0.0005"], ["84266.65", "0.050393"], ["84266.99", "0"], ["84267.58", "0.005"], ["84267.69", "0"], ["84268.53", "0.010091"], ["84269.1", "0"], ["84269.77", "0"], ["84269.85", "0"], ["84269.91", "0.023822"], ["84270.3", "0.010802"], ["84271.93", "0.020997"], ["84273.05", "0.000297"], ["84273.13", "0.133743"], ["84273.41", "0"], ["84273.8", "0.11863"], ["84273.82", "0"], ["84273.9", "0"], ["84273.99", "0"], ["84274.04", "0.083986"], ["84274.63", "0.139997"], ["84275.6", "0"], ["84275.62", "0"], ["84276.57", "0.224421"], ["84276.58", "0"], ["84276.62", "0"], ["84277", "0.044"], ["84277.37", "0"], ["84278.42", "0"], ["84278.71", "0"], ["84278.8", "0.06"], ["84280.22", "0"], ["84280.6", "0.068"], ["84281.02", "0.005932"], ["84281.54", "0.231344"], ["84281.55", "0"], ["84281.59", "0"], ["84281.75", "0.023614"], ["84281.82", "0"], ["84282.17", "0"], ["84282.27", "0.068395"], ["84283.28", "0.016203"], ["84284.99", "0.264565"], ["84285", "0"], ["84285.3", "0.048"], ["84285.7", "0.048"], ["84286.69", "0.02172"], ["84286.98", "0.177077"], ["84287.12", "0"], ["84287.49", "0"], ["84287.69", "0"], ["84289.14", "1.405245"], ["84290.02", "0.237371"], ["84290.22", "0.356332"], ["84290.23", "0"], ["84290.61", "0.071188"], ["84290.91", "0"], ["84292.48", "0"], ["84292.77", "0"], ["84295.39", "0.285823"], ["84295.79", "0.003531"], ["84296.66", "0"], ["84297.12", "0.071182"], ["84300.12", "0"], ["84301.18", "0.162"], ["84304.21", "0"], ["84305.53", "0.356082"], ["84306.83", "0.03181"], ["84307.05", "0.029801"], ["84307.51", "0.001467"], ["84308.4", "0.0045"], ["84308.6", "0.0045"], ["84308.68", "0.0002"], ["84308.76", "0.000612"], ["84308.8", "0.005833"], ["84308.87", "0.005933"], ["84309.05", "0.023732"]], "u": 7510672, "seq": 66889340878}, "cts": 1742142230408, "record_time": 1742142229.510252}
{"topic": "orderbook.200.BTCUSDT", "ts": 1742142230610, "type": "delta", "data": {"s": "BTCUSDT", "b": [["84258.22", "0.118425"], ["84258.18", "0"], ["84256.69", "0"], ["84254.66", "0.000099"], ["84253.05", "0.0002"], ["84250.52", "0.0002"], ["84249.79", "0.001966"], ["84249.11", "0"], ["84244.76", "0.051703"], ["84244.75", "0.060374"], ["84243.92", "0.02"], ["84243.82", "0"], ["84243.68", "0"], ["84243.67", "0"], ["84242.8", "0.04"], ["84242.1", "0.048"], ["84241.93", "0.231594"], ["84241.51", "0"], ["84241.36", "0"], ["84240.71", "0"], ["84240.6", "0.04"], ["84240.55", "0.005"], ["84240.4", "0.116202"], ["84240.2", "0.117192"], ["84239.89", "0.117747"], ["84239.46", "0"], ["84238.6", "0"], ["84238.58", "0"], ["84238.4", "0"], ["84238.04", "0"], ["84237.05", "0.010915"], ["84236.6", "0"], ["84236.43", "0.109417"], ["84235.24", "0"], ["84233.67", "0.160887"], ["84232.83", "0.0002"], ["84232.62", "0"], ["84232.29", "0"], ["84231.48", "0.165864"], ["84229.81", "0"], ["84228.42", "0.159092"], ["84228.01", "0.164551"], ["84227.58", "0"], ["84226.82", "0"], ["84226.49", "0"], ["84225.25", "0.285306"], ["84224.81", "0"], ["84224.12", "0"], ["84223.06", "0.291537"], ["84222.96", "0.016373"], ["84222.83", "0"], ["84219.6", "0.300422"], ["84218.02", "0.071249"], ["84217.49", "0.271311"], ["84217.33", "0"], ["84217.21", "0.11863"], ["84217.2", "0"], ["84216.98", "0.237366"], ["84212.76", "0.237366"], ["84211.35", "0.071255"], ["84208.55", "0"], ["84207.5", "0"], ["84206.06", "0.004611"], ["84205.75", "0"], ["84201.64", "0.356106"], ["84201.25", "0.00009"], ["84200.92", "0.001467"], ["84200.75", "0.000252"]], "a": [["84258.23", "0.348527"], ["84258.8", "0.000153"], ["84258.85", "0.071214"], ["84259.06", "0.011868"], ["84259.91", "0"], ["84262.43", "0.011867"], ["84262.62", "0.089922"], ["84264.96", "0.008081"], ["84265.22", "0.010915"], ["84266.58", "0.051041"], ["84266.59", "0.11863"], ["84267.58", "0"], ["84268.53", "0.000233"], ["84269.9", "0.000297"], ["84269.91", "0.081653"], ["84270.3", "0"], ["84270.49", "0.106132"], ["84271.02", "0.112069"], ["84271.32", "0"], ["84272.6", "0.117409"], ["84273.21", "0.118405"], ["84274.15", "0.068395"], ["84275.09", "0.162"], ["84275.59", "0.161812"], ["84276.57", "0.142877"], ["84278.06", "0.016373"], ["84278.8", "0.104"], ["84279", "0.06"], ["84279.43", "0.165468"], ["84279.94", "0.177535"], ["84280.6", "0.108"], ["84280.7", "0.068"], ["84281.02", "0.173838"], ["84281.54", "0"], ["84281.75", "0"], ["84282.27", "0.17592"], ["84283.28", "0"], ["84284", "0.056"], ["84284.49", "0.071193"], ["84284.81", "0.004629"], ["84284.99", "0"], ["84286.98", "0"], ["84287.85", "0.26842"], ["84288.35", "0.29353"], ["84288.67", "0.237366"], ["84289.01", "0.003391"], ["84289.43", "0.289445"], ["84289.85", "0"], ["84290.02", "0"], ["84290.22", "0"], ["84291.47", "0.019075"], ["84291.85", "0.03181"], ["84292.38", "0.068395"], ["84292.88", "0.237366"], ["84293.21", "0.284506"], ["84295.39", "0"], ["84295.79", "0"], ["84297.12", "0"], ["84300.65", "0.356106"], ["84303.73", "0.123496"], ["84305.05", "0"], ["84305.1", "0"], ["84305.44", "0"], ["84305.53", "0"], ["84305.54", "0"], ["84305.62", "0"], ["84306.15", "0"], ["84306.35", "0"], ["84306.44", "0"], ["84306.83", "0"], ["84306.84", "0"], ["84307.05", "0"], ["84307.34", "0"], ["84307.51", "0"], ["84308.4", "0"], ["84308.6", "0"], ["84308.68", "0"], ["84308.76", "0"], ["84308.8", "0"], ["84308.87", "0"], ["84309.05", "0"]], "u": 7510673, "seq": 66889341561}, "cts": 1742142230605, "record_time": 1742142229.709045}
{"topic": "orderbook.200.BTCUSDT", "ts": 1742142230810, "type": "delta", "data": {"s": "BTCUSDT", "b": [["84258.22", "0.189057"], ["84258.12", "0.01506"], ["84247", "0.118777"], ["84246.69", "0.118053"], ["84245.83", "0.111684"], ["84245.78", "0.02"], ["84245.42", "0.02"], ["84244.76", "0.096888"], ["84244.75", "0.080374"], ["84244.5", "0.04"], ["84244.28", "0"], ["84244", "0.04"], ["84243.92", "0"], ["84243.42", "0.02"], ["84243.25", "0"], ["84242.2", "0.04"], ["84242.1", "0"], ["84241.93", "0"], ["84241.92", "0"], ["84241.37", "0.15603"], ["84241.36", "0.162"], ["84240.4", "0.04"], ["84240.2", "0.000233"], ["84239.89", "0"], ["84239.15", "0.164336"], ["84238.34", "0.179984"], ["84237.82", "0.000296"], ["84237.4", "0.04"], ["84237.2", "0.04"], ["84236.43", "0"], ["84235.4", "0"], ["84235.3", "0.167016"], ["84233.7", "0"], ["84233.67", "0"], ["84233.37", "0"], ["84233.2", "0"], ["84232", "0"], ["84231.48", "0"], ["84230.79", "0.296676"], ["84230", "0"], ["84229.98", "0.285314"], ["84229.8", "0"], ["84229.63", "0.178024"], ["84228.43", "0.059948"], ["84228.42", "0"], ["84228.01", "0"], ["84225.25", "0.0002"], ["84224.44", "0.279575"], ["84223.92", "0.071244"], ["84223.06", "0"], ["84219.6", "0"], ["84218.74", "0.11"], ["84217.49", "0"], ["84216.98", "0"], ["84212.77", "0.356067"], ["84212.76", "0"], ["84211.35", "0"], ["84210.62", "0.2"], ["84208.55", "0.178024"], ["84208.25", "0.000989"], ["84201.64", "0"], ["84201.53", "0.237366"], ["84201.5", "0"], ["84201.25", "0"], ["84200.92", "0"], ["84200.75", "0"]], "a": [["84258.23", "0.002519"], ["84258.8", "0"], ["84258.85", "0"], ["84259.06", "0"], ["84259.76", "0.000153"], ["84260.86", "0.071213"], ["84261.79", "0.000099"], ["84262.43", "0"], ["84262.62", "0"], ["84264.96", "0"], ["84266.58", "0"], ["84266.59", "0"], ["84269.91", "0.023822"], ["84270.49", "0"], ["84271.02", "0"], ["84272.6", "0"], ["84273.21", "0"], ["84273.26", "0"], ["84274.63", "0"], ["84275.09", "0"], ["84275.59", "0"], ["84276.07", "0.139994"], ["84277.08", "0.119666"], ["84277.61", "0.115564"], ["84278.42", "0.105978"], ["84279.43", "0"], ["84279.94", "0"], ["84281.02", "0.005832"], ["84281.75", "0.000989"], ["84282.27", "0"], ["84284.49", "0"], ["84285.11", "0.174967"], ["84285.97", "0.179024"], ["84287.44", "0.023868"], ["84287.85", "0"], ["84288.35", "0"], ["84288.67", "0"], ["84288.78", "0.16622"], ["84289.43", "0"], ["84292.88", "0"], ["84293.21", "0"], ["84293.46", "0.28717"], ["84294.32", "0.263694"], ["84295.23", "0.071184"], ["84299.65", "0.300988"], ["84300.65", "0"], ["84305.05", "0.003748"], ["84305.1", "0.000786"], ["84305.44", "0.019981"], ["84305.54", "0.352414"], ["84305.62", "0.000235"], ["84306.15", "0.0002"], ["84306.35", "0.089922"], ["84306.44", "0.023732"], ["84306.84", "0.023732"], ["84307.05", "0.029801"], ["84307.34", "0.000253"]], "u": 7510674, "seq": 66889342148}, "cts": 1742142230807, "record_time": 1742142229.908545}
{"topic": "orderbook.200.BTCUSDT", "ts": 1742142231009, "type": "delta", "data": {"s": "BTCUSDT", "b": [["84257.39", "0.011868"], ["84254.02", "0.004372"], ["84249.79", "0.001566"], ["84247.07", "0.106948"], ["84247.06", "0.14256"], ["84247", "0"], ["84246.76", "0.108103"], ["84246.74", "0.008453"], ["84246.69", "0"], ["84246.46", "0.237366"], ["84245.88", "0.02"], ["84245.84", "0.280256"], ["84245.83", "0"], ["84245.78", "0"], ["84244.76", "0"], ["84243.77", "0.109574"], ["84243.15", "0.02"], ["84242.25", "0.237366"], ["84242.16", "0.011067"], ["84241.65", "0"], ["84240.4", "0"], ["84239.5", "0.04"], ["84239.15", "0.173839"], ["84238.9", "0.04"], ["84238.4", "0.159015"], ["84238.34", "0"], ["84237.05", "0"], ["84237", "0"], ["84235.42", "0.161376"], ["84235.37", "0.16326"], ["84235.3", "0"], ["84234.8", "0"], ["84232.12", "0.303275"], ["84231.5", "0"], ["84230.8", "0.282138"], ["84230.79", "0"], ["84230.05", "0.265433"], ["84229.98", "0"], ["84227.25", "0.01653"], ["84227.06", "0.281831"], ["84224.51", "0.27825"], ["84224.44", "0"], ["84222.96", "0"], ["84220.71", "0"], ["84219.9", "0.059948"], ["84216.97", "0.183024"], ["84213.85", "0.04"], ["84213.84", "0.039641"], ["84212.78", "0.356066"], ["84212.77", "0"], ["84210.62", "0"], ["84209.96", "0.237366"], ["84205.75", "0.237366"], ["84203.67", "0"], ["84203.48", "0"], ["84203.43", "0"], ["84203.15", "0"], ["84202.79", "0"], ["84202.51", "0"], ["84201.63", "0"], ["84201.53", "0"]], "a": [["84259.76", "0"], ["84261.69", "0.000153"], ["84264.96", "0.007014"], ["84265.22", "0"], ["84270.06", "0.011067"], ["84273.06", "0"], ["84273.13", "0.082833"], ["84277.08", "0"], ["84277.15", "0.110865"], ["84277.61", "0"], ["84277.68", "0.117319"], ["84278.06", "0"], ["84278.08", "0.008453"], ["84278.42", "0"], ["84278.43", "0.108552"], ["84281.55", "0.024091"], ["84282.73", "0.0166"], ["84285.11", "0.176741"], ["84285.97", "0"], ["84286.04", "0.174884"], ["84288.06", "0.164107"], ["84288.78", "0"], ["84288.85", "0.162643"], ["84289.14", "0"], ["84292.38", "0"], ["84293.46", "0"], ["84293.47", "0.265598"], ["84294.32", "0"], ["84294.39", "0.295355"], ["84296.42", "0.297677"], ["84299.65", "0"], ["84299.72", "0.263573"], ["84302.69", "0.04"], ["84302.7", "0.040252"], ["84304.28", "0"], ["84304.48", "0"]], "u": 7510675, "seq": 66889342572}, "cts": 1742142231007, "record_time": 1742142230.109203}
{"topic": "orderbook.200.BTCUSDT", "ts": 1742142231209, "type": "delta", "data": {"s": "BTCUSDT", "b": [["84261.14", "0.293167"], ["84260.98", "0.01287"], ["84260.63", "0.0004"], ["84260.62", "0.042501"], ["84258.75", "0.071214"], ["84258.22", "0.005787"], ["84258.12", "0.01868"], ["84258.11", "0.0502"], ["84257.39", "0"], ["84256.35", "0.000252"], ["84254.63", "0.000233"], ["84254.1", "0.000233"], ["84254.02", "0"], ["84254.01", "0.001333"], ["84253.57", "0.015091"], ["84252.2", "0.132617"], ["84252.1", "0.118946"], ["84251.95", "0.00009"], ["84251.7", "0.0332"], ["84251.46", "0.060368"], ["84250.67", "0.237357"], ["84250.24", "0.132087"], ["84250", "0.000233"], ["84249.8", "0.001333"], ["84249.79", "0.0005"], ["84249.76", "0.000614"], ["84249.75", "0"], ["84249.51", "0.106563"], ["84249.13", "0.005"], ["84248", "0.001653"], ["84247.99", "0"], ["84247.91", "0"], ["84247.88", "0.02"], ["84247.81", "0.011119"], ["84247.42", "0.02"], ["84247.07", "0"], ["84247.06", "0"], ["84246.88", "0"], ["84246.85", "0.02"], ["84246.76", "0"], ["84246.74", "0"], ["84245.88", "0"], ["84245.84", "0.166478"], ["84245.52", "0.02"], ["84245.42", "0"], ["84245.25", "0.02"], ["84245.1", "0.04"], ["84244.75", "0"], ["84244.34", "0.008453"], ["84243.77", "0"], ["84243.42", "0"], ["84243.22", "0.178026"], ["84243.15", "0"], ["84242.61", "0.001467"], ["84242.32", "0.009541"], ["84242.25", "0"], ["84242.23", "0.068395"], ["84242.16", "0"], ["84242.1", "0.048"], ["84241.15", "0.171754"], ["84240.55", "0"], ["84239.15", "0"], ["84238.4", "0"], ["84236.21", "0.038924"], ["84236.12", "0"], ["84235.42", "0"], ["84235.37", "0"], ["84235.08", "0.296591"], ["84234.86", "0.276392"], ["84233.28", "0"], ["84232.8", "0.268968"], ["84230.8", "0"], ["84230.05", "0"], ["84229.85", "0.071239"], ["84229.63", "0"], ["84227.34", "0.323683"], ["84227.25", "0"], ["84227.07", "0.140437"], ["84227.06", "0"], ["84226.24", "0.071242"], ["84225.54", "0"], ["84225", "0.068395"], ["84224.89", "1.412508"], ["84224.51", "0"], ["84223.92", "0"], ["84223.47", "0"], ["84222.8", "0"], ["84219.91", "0.35604"], ["84219.5", "0"], ["84218.74", "0"], ["84218.02", "0"], ["84212.78", "0"], ["84211.56", "0"], ["84206.9", "0.24702"], ["84205.75", "0"], ["84205.26", "0"], ["84205.08", "0"], ["84205.04", "0"], ["84204.38", "0"]], "a": [["84258.23", "0"], ["84258.74", "0"], ["84259.26", "0"], ["84259.88", "0"], ["84260.63", "0"], ["84260.86", "0"], ["84260.98", "0"], ["84261.15", "0.002653"], ["84261.48", "0.071212"], ["84261.69", "0"], ["84262.93", "0"], ["84264.96", "0"], ["84266.6", "0"], ["84266.61", "0.013909"], ["84266.66", "0.0005"], ["84267.54", "0.005939"], ["84267.62", "0.005"], ["84269.9", "0"], ["84269.91", "0"], ["84269.92", "0"], ["84270.06", "0"], ["84270.81", "0.059948"], ["84270.82", "0.029076"], ["84271.93", "0"], ["84272.34", "0.020814"], ["84272.35", "0.023718"], ["84273.05", "0"], ["84273.12", "0.000297"], ["84273.13", "0"], ["84273.27", "0.028818"], ["84273.8", "0"], ["84274.04", "0"], ["84274.15", "0"], ["84275.66", "0.011119"], ["84276.07", "0"], ["84276.56", "0.000297"], ["84276.57", "0.091439"], ["84277", "0"], ["84277.15", "0"], ["84277.68", "0"], ["84278.08", "0"], ["84278.34", "0"], ["84278.43", "0"], ["84278.62", "0.020996"], ["84278.8", "0.044"], ["84280.59", "0.140867"], ["84280.6", "0"], ["84280.72", "0.083982"], ["84281.02", "0"], ["84281.18", "0.005902"], ["84281.31", "0.003"], ["84281.35", "0"], ["84281.55", "0"], ["84282.18", "0.114962"], ["84282.49", "0.106606"], ["84282.73", "0"], ["84283.52", "0"], ["84284.7", "0.06"], ["84285.1", "0.270047"], ["84285.11", "0"], ["84285.33", "0.008453"], ["84285.79", "0"], ["84286.04", "0"], ["84287.44", "0"], ["84288.06", "0"], ["84288.3", "0.016678"], ["84288.85", "0"], ["84289.02", "0.071189"], ["84289.13", "1.435579"], ["84289.18", "0.178237"], ["84289.57", "0.220084"], ["84289.58", "0"], ["84289.99", "0.009462"], ["84290.14", "0"], ["84290.4", "0.03181"], ["84290.61", "0"], ["84291.85", "0"], ["84292.01", "0"], ["84292.19", "0"], ["84292.95", "0.024359"], ["84293.47", "0"], ["84293.8", "0.170021"], ["84293.88", "0.180139"], ["84294.39", "0"], ["84295.19", "0.023736"], ["84295.55", "0"], ["84296.42", "0"], ["84297.53", "0.291936"], ["84297.9", "0.246059"], ["84299.72", "0"], ["84300.66", "0"], ["84301.43", "0.013961"], ["84302.16", "0.289032"], ["84302.69", "0"], ["84302.7", "0.000252"], ["84303.26", "0.026414"], ["84305.44", "0.257338"], ["84307.51", "0.001467"], ["84308.68", "0.0002"], ["84308.76", "0.000612"], ["84308.8", "0.001333"], ["84308.87", "0.005933"], ["84309.05", "0.023732"], ["84309.66", "0.237357"], ["84309.69", "0.04"], ["84309.7", "0.04"], ["84309.73", "0.000235"], ["84310.22", "0.059948"], ["84310.24", "0.11863"], ["84310.26", "0.000235"], ["84310.78", "0.003"], ["84311.2", "0.0002"], ["84311.98", "0.000253"], ["84312.14", "0.001467"], ["84312.41", "0.023733"], ["84312.72", "0.323355"]], "u": 7510676, "seq": 66889343826}, "cts": 1742142231207, "record_time": 1742142230.308537}
{"topic": "orderbook.200.BTCUSDT", "ts": 1742142231409, "type": "delta", "data": {"s": "BTCUSDT", "b": [["84260.31", "0.011867"], ["84258.76", "0.038296"], ["84258.12", "0"], ["84256.94", "0.004372"], ["84254.66", "0"], ["84252.21", "0.028673"], ["84252.2", "0"], ["84252.1", "0"], ["84250.67", "0"], ["84250.24", "0.286835"], ["84249.51", "0"], ["84249", "0.04"], ["84248.58", "0.02"], ["84248.5", "0.04"], ["84248.12", "0.02"], ["84248.04", "0.237394"], ["84247.88", "0"], ["84247.57", "0.000817"], ["84247.45", "0.02"], ["84247.42", "0"], ["84247.3", "0.04"], ["84246.85", "0"], ["84246.8", "0.04"], ["84246.46", "0"], ["84246.35", "0.237399"], ["84246.12", "0.02"], ["84245.85", "0.02"], ["84245.52", "0"], ["84245.25", "0"], ["84244.67", "0.237404"], ["84244.1", "0.04"], ["84243.84", "0.008723"], ["84243.22", "0"], ["84242.8", "0"], ["84242.1", "0.088"], ["84241.8", "0.04"], ["84241.15", "0"], ["84240.6", "0"], ["84237.4", "0"], ["84237.2", "0"], ["84235.08", "0"], ["84234.86", "0"], ["84233.82", "0.237357"], ["84232.8", "0"], ["84232.79", "0.139991"], ["84232.12", "0.101035"], ["84229.61", "0.237357"], ["84227.07", "0"], ["84226.82", "0.178018"], ["84224.9", "0.550319"], ["84219.91", "0"], ["84211.14", "0.000989"], ["84210.2", "0.380737"], ["84209.96", "0"], ["84209.76", "0"], ["84208.55", "0"], ["84208.25", "0"], ["84206.04", "0"], ["84205.75", "0.178018"], ["84205.26", "0.10803"]], "a": [["84261.79", "0"], ["84265.35", "0.000169"], ["84267.54", "0.011866"], ["84269.53", "0.000153"], ["84270.8", "0.018595"], ["84270.82", "0.000613"], ["84272.34", "0"], ["84272.35", "0.001243"], ["84273.12", "0"], ["84273.27", "0.0002"], ["84276.57", "0.128305"], ["84277.58", "0.109884"], ["84278.22", "0.139991"], ["84278.61", "0.000297"], ["84281.75", "0"], ["84282.18", "0"], ["84282.49", "0"], ["84282.9", "0.044"], ["84283.74", "0.068395"], ["84284.68", "0.000989"], ["84285.1", "0"], ["84285.65", "0.024015"], ["84289.12", "0.660165"], ["84289.18", "0"], ["84289.57", "0"], ["84293.8", "0"], ["84293.88", "0"], ["84297.02", "0.237357"], ["84297.53", "0"], ["84301.23", "0.237357"], ["84302.16", "0"], ["84305.44", "0.019981"], ["84309.61", "0.162"], ["84309.65", "0.356072"], ["84309.66", "0"], ["84309.69", "0"], ["84309.7", "0"], ["84309.79", "0.04"], ["84309.8", "0.04"], ["84311.08", "0.178018"], ["84312.41", "0"], ["84312.72", "0"]], "u": 7510677, "seq": 66889344139}, "cts": 1742142231407, "record_time": 1742142230.508966}
{"topic": "orderbook.200.BTCUSDT", "ts": 1742142231610, "type": "delta", "data": {"s": "BTCUSDT", "b": [["84261.14", "0.293287"], ["84261", "0.0006"], ["84260.63", "0"], ["84257.58", "0.000099"], ["84256.94", "0.006749"], ["84250.47", "0.116384"], ["84250.17", "0.119855"], ["84248.15", "0.108906"], ["84247.88", "0.237357"], ["84247.84", "0.117267"], ["84247.55", "0.02"], ["84247.45", "0"], ["84246.22", "0.02"], ["84246.12", "0"], ["84245.95", "0.02"], ["84245.85", "0"], ["84244.5", "0"], ["84244", "0"], ["84243.84", "0"], ["84243.67", "0.237357"], ["84243.4", "0.04"], ["84242.2", "0"], ["84241.85", "0.168827"], ["84241.37", "0.057651"], ["84241.18", "0.167933"], ["84239.84", "0.166843"], ["84239.5", "0"], ["84238.9", "0"], ["84238.83", "0.160354"], ["84233.82", "0"], ["84233.53", "0.292065"], ["84232.87", "0.270225"], ["84231.52", "0.278067"], ["84229.61", "0"], ["84228.02", "0.277434"], ["84227.35", "0.22065"], ["84210.2", "0.02466"], ["84206.94", "0"], ["84206.9", "0"], ["84206.06", "0"], ["84206.05", "0"], ["84206.03", "0"], ["84205.75", "0"], ["84205.55", "0"], ["84205.38", "0"], ["84205.26", "0"]], "a": [["84264.71", "0.000099"], ["84265.35", "0.003947"], ["84267.54", "0"], ["84267.88", "0.011866"], ["84269.22", "0.000153"], ["84269.53", "0"], ["84280.27", "0.106155"], ["84280.41", "0.119228"], ["84280.59", "0.100076"], ["84280.94", "0.107731"], ["84281.18", "0"], ["84283.91", "0.119952"], ["84284.8", "0.04"], ["84286.4", "0.068"], ["84286.92", "0.167381"], ["84289.25", "0.173319"], ["84292.05", "0.173607"], ["84292.23", "0.157921"], ["84294.23", "0.237357"], ["84295.24", "0.287744"], ["84297.57", "0.272052"], ["84298.44", "0.237357"], ["84300.54", "0.293013"], ["84302.87", "0.264267"], ["84303.27", "0.474478"], ["84308.8", "0"], ["84308.87", "0"], ["84309.05", "0"], ["84309.61", "0"], ["84309.65", "0"], ["84309.73", "0"], ["84309.79", "0"], ["84309.8", "0"], ["84310.22", "0"], ["84310.24", "0"], ["84310.26", "0"], ["84310.78", "0"], ["84311.08", "0"], ["84311.2", "0"], ["84311.98", "0"], ["84312.14", "0"]], "u": 7510678, "seq": 66889344409}, "cts": 1742142231607, "record_time": 1742142230.70986}
{"topic": "orderbook.200.BTCUSDT", "ts": 1742142231809, "type": "delta", "data": {"s": "BTCUSDT", "b": [["84260.98", "0"], ["84260.62", "0"], ["84259.31", "0.071214"], ["84258.76", "0.018986"], ["84258.75", "0"], ["84250.47", "0"], ["84250.17", "0"], ["84249.88", "0.02"], ["84249.42", "0.02"], ["84248.85", "0.02"], ["84248.58", "0"], ["84248.15", "0"], ["84248.12", "0"], ["84247.84", "0"], ["84247.55", "0"], ["84247.52", "0.02"], ["84247.25", "0.02"], ["84246.22", "0"], ["84245.95", "0"], ["84241.85", "0"], ["84241.59", "0.009082"], ["84241.18", "0"], ["84239.84", "0"], ["84238.83", "0"], ["84238.04", "0.237357"], ["84233.82", "0.237357"], ["84233.54", "0.397875"], ["84233.53", "0"], ["84232.87", "0"], ["84232.12", "0"], ["84231.52", "0"], ["84228.02", "0"], ["84219.55", "0.04"], ["84219.54", "0.039639"], ["84213.85", "0"], ["84213.84", "0"], ["84211.58", "0.356061"], ["84208.89", "0.162"], ["84206.94", "0.001"], ["84206.9", "0.24702"], ["84206.06", "0.004611"], ["84206.05", "0.11863"], ["84205.75", "0.178018"], ["84205.55", "0.001467"], ["84205.41", "0.237514"], ["84205.38", "0.000252"], ["84205.26", "0.10803"]], "a": [["84261.48", "0"], ["84264.71", "0"], ["84265.35", "0"], ["84266.61", "0.000613"], ["84267.88", "0"], ["84269.22", "0"], ["84270.8", "0"], ["84278.22", "0"], ["84280.27", "0"], ["84280.41", "0"], ["84280.59", "0.154101"], ["84280.94", "0"], ["84283.91", "0"], ["84286.92", "0"], ["84289.02", "0"], ["84289.25", "0"], ["84292.05", "0"], ["84292.23", "0"], ["84295.24", "0"], ["84297.02", "0"], ["84297.57", "0"], ["84298.51", "0.071181"], ["84300.54", "0"], ["84301.23", "0"], ["84302.87", "0.001467"], ["84308.8", "0.001333"], ["84308.87", "0.005933"], ["84309.05", "0.023732"], ["84309.19", "0.04"], ["84309.2", "0.04"], ["84309.73", "0.000235"], ["84310.22", "0.059948"], ["84310.24", "0.11863"], ["84310.26", "0.000235"], ["84310.78", "0.003"], ["84311.08", "0.178018"], ["84311.2", "0.0002"], ["84311.98", "0.000253"], ["84312.14", "0.001467"], ["84312.41", "0.023733"], ["84312.72", "0.323355"], ["84312.73", "0.0045"], ["84312.77", "0.0045"], ["84312.93", "0.0045"], ["84312.97", "0.005112"]], "u": 7510679, "seq": 66889344737}, "cts": 1742142231807, "record_time": 1742142230.909591}
{"topic": "orderbook.200.BTCUSDT", "ts": 1742142232010, "type": "delta", "data": {"s": "BTCUSDT", "b": [["84270.41", "0.255148"], ["84268.54", "0.013584"], ["84267.61", "0.04528"], ["84266.61", "0.018468"], ["84266.6", "0.06"], ["84265.77", "0.000961"], ["84265.69", "0.0002"], ["84265.61", "0.000252"], ["84263.9", "0.000633"], ["84263.37", "0.000233"], ["84263.16", "0.0002"], ["84262.44", "0.001333"], ["84262.4", "0.018524"], ["84262.39", "0.033896"], ["84261.44", "0.012653"], ["84261.15", "0.001467"], ["84261.14", "0.00012"], ["84260.98", "0.000252"], ["84260.63", "0.0002"], ["84260.4", "0.000089"], ["84260.31", "0"], ["84259.77", "0.105103"], ["84259.46", "0.116441"], ["84259.31", "0"], ["84259.26", "0.000233"], ["84258.76", "0"], ["84258.74", "0.001333"], ["84258.23", "0.001333"], ["84258.18", "0.000614"], ["84256.94", "0"], ["84256.51", "0.001467"], ["84252.72", "0.071791"], ["84252.71", "0.173926"], ["84252.21", "0"], ["84251.88", "0.021467"], ["84251.7", "0.003"], ["84251.42", "0.02"], ["84251.15", "0.168776"], ["84250.85", "0.02"], ["84250.84", "0.231908"], ["84249.92", "0.068395"], ["84249.88", "0"], ["84249.79", "0"], ["84249.52", "0.02"], ["84249.43", "0.089922"], ["84249.42", "0"], ["84249.13", "0"], ["84248.85", "0"], ["84248.04", "0"], ["84247.81", "0"], ["84247.6", "0.019233"], ["84247.52", "0"], ["84246.35", "0"], ["84244.77", "0"], ["84244.68", "0.059948"], ["84244.67", "0"], ["84243.67", "0"], ["84242.23", "0"], ["84241.37", "0.113556"], ["84241.23", "0.017145"], ["84238.04", "0"], ["84236.47", "0.071233"], ["84236.21", "0.022242"], ["84233.83", "0.071207"], ["84233.82", "0"], ["84233.54", "0.145768"], ["84230.92", "0"], ["84230.83", "0.089922"], ["84230.71", "0"], ["84226.24", "0"], ["84221.93", "0.023734"], ["84220.74", "0.0013"], ["84220", "0.004653"], ["84219.91", "0.356024"], ["84219.64", "0.005933"], ["84215.96", "0.023734"], ["84215.16", "0.023734"], ["84213.4", "0.24702"], ["84211.58", "0"], ["84211.14", "0"], ["84210.2", "0"], ["84210.19", "0"], ["84210.18", "0"], ["84210.09", "0"], ["84210.02", "0"], ["84209.87", "0"], ["84209.7", "0"], ["84208.89", "0"], ["84208.8", "0"], ["84208.3", "0"], ["84207.78", "0"], ["84207.7", "0"], ["84207.69", "0"], ["84207.64", "0"], ["84207.57", "0"], ["84206.94", "0"], ["84206.9", "0"], ["84206.06", "0"], ["84206.05", "0"], ["84205.75", "0"], ["84205.55", "0"], ["84205.41", "0"], ["84205.38", "0"], ["84205.26", "0"]], "a": [["84261.15", "0"], ["84261.45", "0"], ["84262.4", "0"], ["84262.44", "0"], ["84263.16", "0"], ["84263.37", "0"], ["84263.9", "0"], ["84265.61", "0"], ["84265.69", "0"], ["84265.78", "0"], ["84266.61", "0"], ["84266.65", "0"], ["84266.66", "0"], ["84267.62", "0"], ["84268.01", "0"], ["84268.22", "0"], ["84268.53", "0"], ["84270.25", "0"], ["84270.42", "0.002653"], ["84270.81", "0"], ["84270.91", "0"], ["84272.13", "0.005"], ["84274.35", "0.000498"], ["84275.66", "0"], ["84276.56", "0.022165"], ["84276.57", "0"], ["84277.58", "0"], ["84278.6", "0.000296"], ["84278.61", "0.014808"], ["84278.68", "0"], ["84278.8", "0"], ["84278.85", "0.0005"], ["84279", "0"], ["84279.31", "0"], ["84280.23", "0.011426"], ["84280.59", "0"], ["84280.7", "0.11863"], ["84280.71", "0.103105"], ["84282.9", "0"], ["84283.06", "0.139998"], ["84284", "0"], ["84284.7", "0"], ["84284.8", "0"], ["84285.3", "0"], ["84285.33", "0"], ["84285.65", "0"], ["84285.7", "0"], ["84286.4", "0"], ["84286.53", "0.080079"], ["84287.9", "0.068"], ["84288.3", "0"], ["84289.01", "0"], ["84289.31", "0.008453"], ["84289.69", "0.109639"], ["84289.98", "0"], ["84290.21", "0.117106"], ["84290.31", "0.017796"], ["84290.4", "0"], ["84291.02", "0.108282"], ["84291.59", "0"], ["84292.2", "0.112565"], ["84292.41", "0"], ["84292.74", "0.195066"], ["84292.75", "0"], ["84292.87", "0.017139"], ["84292.95", "0"], ["84294.22", "0"], ["84295.23", "0"], ["84296.11", "0.000613"], ["84296.15", "0.001433"], ["84296.71", "0"], ["84297.89", "0.312498"], ["84297.9", "0"], ["84298.53", "0.169198"], ["84300.48", "0"], ["84300.51", "0.161533"], ["84302.79", "0.03181"], ["84303.07", "0"], ["84303.27", "0"], ["84304.36", "0.071176"], ["84307.05", "0"], ["84309.19", "0"], ["84309.2", "0"], ["84309.61", "0.162"], ["84311.09", "0.04"], ["84311.1", "0.04"], ["84312.13", "0.267494"], ["84312.78", "0.354608"], ["84313.02", "0.001333"], ["84313.27", "0.000199"], ["84313.46", "0.000089"], ["84313.73", "0.0002"], ["84313.85", "0.000335"], ["84314.22", "0.059323"], ["84314.37", "0.000235"], ["84314.9", "0.000235"], ["84315.37", "0.001"], ["84315.51", "0.009"], ["84315.71", "0.009"], ["84315.93", "0.11863"], ["84315.95", "0.001243"], ["84316.26", "0.0002"], ["84316.61", "0.000253"], ["84316.78", "0.001467"], ["84316.9", "0.0045"], ["84316.97", "0.005"], ["84317.1", "0.0045"], ["84317.19", "0.000612"], ["84317.23", "0.001333"], ["84317.25", "0.000111"], ["84317.5", "0.246059"], ["84318.79", "0.0002"], ["84319.01", "0.000235"], ["84319.53", "0.000235"], ["84319.54", "0.00315"], ["84319.62", "0.029801"], ["84320", "0.000113"]], "u": 7510680, "seq": 66889346525}, "cts": 1742142232007, "record_time": 1742142231.109126}
{"topic": "orderbook.200.BTCUSDT", "ts": 1742142232209, "type": "delta", "data": {"s": "BTCUSDT", "b": [["84273.16", "0.04"], ["84272.63", "0.267308"], ["84272.34", "0.094027"], ["84272.12", "0.220037"], ["84270.42", "0.015595"], ["84270.41", "0.108158"], ["84269.58", "0.011866"], ["84268.54", "0"], ["84268.22", "0.0002"], ["84267.61", "0"], ["84266.65", "0.001333"], ["84266.61", "0.000614"], ["84266.6", "0"], ["84265.78", "0.001467"], ["84263.9", "0.000233"], ["84262.4", "0.084392"], ["84262.34", "0.111372"], ["84262.03", "0.116272"], ["84261.98", "0.162"], ["84261.64", "0.005"], ["84261.44", "0"], ["84261.23", "0.089922"], ["84261.14", "0"], ["84260.67", "0.106231"], ["84259.77", "0"], ["84259.46", "0"], ["84259.1", "0.237331"], ["84258.81", "0.113676"], ["84258.6", "0.087289"], ["84257.58", "0"], ["84257.07", "0.015089"], ["84256.52", "0.060358"], ["84256.27", "0.005933"], ["84255.27", "0.02"], ["84254.9", "0.059948"], ["84254.89", "0.237331"], ["84254.82", "0.02"], ["84253.72", "0.17409"], ["84253.57", "0"], ["84252.92", "0.02"], ["84252.71", "0.1625"], ["84252.05", "0.02"], ["84251.88", "0.001467"], ["84251.5", "0.04"], ["84251.46", "0"], ["84251.42", "0"], ["84251.2", "0.04"], ["84251.15", "0"], ["84250.85", "0"], ["84250.84", "0"], ["84250.7", "0.214525"], ["84250.45", "0.02"], ["84250.24", "0.132087"], ["84249.52", "0"], ["84249.5", "0.048"], ["84249.38", "0.023087"], ["84248.36", "0.017796"], ["84247.88", "0"], ["84247.25", "0"], ["84246.02", "0.017306"], ["84245.84", "0"], ["84245.4", "0.288376"], ["84242.92", "0.071228"], ["84242.1", "0.04"], ["84241.37", "0.057651"], ["84241.23", "0"], ["84239.89", "0.295998"], ["84237.48", "0.024276"], ["84236.21", "0"], ["84233.83", "0"], ["84232.8", "0.11863"], ["84229.85", "0"], ["84228.44", "0.35601"], ["84227.43", "0.017765"], ["84226.72", "0.023733"], ["84224.89", "0"], ["84221.84", "0"], ["84221.6", "0.24702"], ["84220.27", "0"], ["84219.91", "0"], ["84217.04", "0"], ["84216.97", "0"], ["84216.11", "0"], ["84216.07", "0"], ["84215.96", "0"], ["84215.16", "0"], ["84215.14", "0"], ["84214.81", "0"], ["84214.65", "0"], ["84214", "0"], ["84213.69", "0"], ["84213.4", "0"], ["84212.93", "0"], ["84212.62", "0"], ["84212.41", "0"], ["84212.4", "0"], ["84211.9", "0"], ["84211.85", "0"], ["84211.57", "0"]], "a": [["84270.42", "0"], ["84270.75", "0"], ["84270.82", "0"], ["84270.87", "0"], ["84272.13", "0"], ["84272.35", "0"], ["84272.64", "0"], ["84274.04", "0.000099"], ["84274.35", "0"], ["84276.56", "0"], ["84278.61", "0"], ["84278.62", "0"], ["84278.84", "0.04906"], ["84278.85", "0"], ["84279.3", "0.001333"], ["84279.42", "0"], ["84280.23", "0"], ["84280.69", "0.000297"], ["84280.7", "0"], ["84280.71", "0"], ["84280.72", "0"], ["84280.78", "0.0005"], ["84281.02", "0.005"], ["84283.06", "0"], ["84283.74", "0"], ["84284.64", "0"], ["84285.78", "0.121028"], ["84286.53", "0"], ["84286.54", "0"], ["84286.69", "0"], ["84287.9", "0"], ["84288.21", "0"], ["84289.13", "0"], ["84289.31", "0"], ["84289.69", "0"], ["84289.99", "0"], ["84290.21", "0"], ["84291.02", "0"], ["84291.24", "0"], ["84291.47", "0"], ["84292.05", "0.068395"], ["84292.2", "0"], ["84292.26", "0.118664"], ["84292.74", "0.05964"], ["84292.78", "0.113781"], ["84292.87", "0"], ["84293.09", "0.119532"], ["84293.43", "0.006213"], ["84293.83", "0.008453"], ["84294.23", "0"], ["84294.55", "0.115968"], ["84295.19", "0"], ["84295.9", "0.068"], ["84297.5", "0.048"], ["84298.29", "0"], ["84298.51", "0"], ["84298.53", "0"], ["84298.6", "0.048"], ["84298.76", "0.03181"], ["84300.11", "0.023078"], ["84300.43", "0.000789"], ["84300.51", "0"], ["84301.1", "0.177918"], ["84301.17", "0.162793"], ["84301.18", "0"], ["84302.79", "0"], ["84302.86", "0.179125"], ["84303.26", "0"], ["84303.6", "0"], ["84303.9", "0.165481"], ["84305.44", "0"], ["84306.35", "0"], ["84308.44", "0.071172"], ["84309.41", "0.301858"], ["84311.09", "0"], ["84311.1", "0"], ["84312.13", "0"], ["84314.08", "0.026414"], ["84314.22", "0"], ["84314.7", "0.292101"], ["84315.68", "0.017796"], ["84316.22", "0.037894"], ["84317.09", "0.04"], ["84317.1", "0.0445"], ["84318.04", "0.162"], ["84320.28", "0.0045"], ["84320.48", "0.0045"], ["84321.11", "0.023736"], ["84321.25", "0.000253"], ["84321.31", "0.059948"], ["84321.32", "0.0002"], ["84321.4", "0.000612"], ["84321.42", "0.001467"], ["84321.45", "0.001333"], ["84321.67", "0.11863"], ["84321.97", "0.000089"], ["84322", "0.0006"], ["84323.65", "0.000235"], ["84323.83", "0.428903"], ["84324.17", "0.000235"], ["84324.39", "0.023739"], ["84325.51", "0.089922"], ["84325.62", "0.000612"], ["84325.66", "0.001333"], ["84325.89", "0.000253"], ["84326.06", "0.001467"]], "u": 7510681, "seq": 66889347808}, "cts": 1742142232207, "record_time": 1742142231.309276}
{"topic": "orderbook.200.BTCUSDT", "ts": 1742142232409, "type": "delta", "data": {"s": "BTCUSDT", "b": [["84279.68", "0.18471"], ["84279.3", "0.025879"], ["84278.85", "0.011865"], ["84278.59", "0.01"], ["84275.48", "0.004371"], ["84275.08", "0.001333"], ["84275.05", "0.0004"], ["84275.04", "0.000814"], ["84274.88", "0.000252"], ["84273.27", "0.0002"], ["84273.17", "0.000233"], ["84273.16", "0"], ["84272.64", "0.000233"], ["84272.63", "0"], ["84272.34", "0"], ["84272.12", "0"], ["84271.26", "0.166671"], ["84270.87", "0.001333"], ["84270.82", "0.000614"], ["84270.75", "0.0002"], ["84270.42", "0.001867"], ["84270.41", "0.00012"], ["84270.25", "0.000252"], ["84269.76", "0.112177"], ["84269.58", "0"], ["84269.54", "0.000099"], ["84269.13", "0.237335"], ["84268.85", "0.000089"], ["84268.78", "0.015085"], ["84268.53", "0.000233"], ["84268.25", "0.107956"], ["84268.01", "0.000233"], ["84267.63", "0.00934"], ["84267.58", "0.003969"], ["84267.23", "0.008453"], ["84266.67", "0.060345"], ["84264.76", "0.071392"], ["84264.74", "0.237307"], ["84262.4", "0.000614"], ["84262.39", "0"], ["84262.34", "0"], ["84262.03", "0"], ["84261.99", "0.149373"], ["84261.64", "0"], ["84261.45", "0.177344"], ["84260.83", "0.009541"], ["84260.75", "0.000817"], ["84260.7", "0.04"], ["84260.67", "0"], ["84259.27", "0.02"], ["84258.92", "0.02"], ["84258.81", "0"], ["84258.66", "0.068395"], ["84258.6", "0.132642"], ["84258.4", "0.04"], ["84258.24", "0.02"], ["84258.11", "0.0002"], ["84257.07", "0"], ["84257.02", "0.02"], ["84256.64", "0.02"], ["84256.52", "0"], ["84256.4", "0.04"], ["84256", "0.001243"], ["84255.8", "0.04"], ["84255.27", "0"], ["84254.89", "0"], ["84254.82", "0"], ["84253.72", "0"], ["84252.92", "0"], ["84252.05", "0"], ["84251.04", "0.017339"], ["84250.7", "0.04"], ["84250.45", "0"], ["84249.92", "0"], ["84248.75", "0.071223"], ["84248.5", "0"], ["84247.88", "0.177979"], ["84247.57", "0"], ["84246.02", "0"], ["84245.41", "0.180306"], ["84245.4", "0"], ["84245.37", "0.071226"], ["84245.1", "0.041243"], ["84244.34", "0"], ["84244.1", "0"], ["84242.95", "0.323623"], ["84242.92", "0"], ["84242.32", "0"], ["84242.1", "0"], ["84241.8", "0"], ["84241.39", "0.11863"], ["84241.37", "0.131148"], ["84239.89", "0"], ["84238.78", "0.02373"], ["84237.48", "0"], ["84236.56", "1.436818"], ["84236.49", "0.005932"], ["84236.48", "0.355968"], ["84236.47", "0"], ["84233.37", "0.004699"], ["84232.81", "0.02373"], ["84232.01", "0.02373"], ["84228.44", "0"], ["84227.34", "0"], ["84227.02", "0.02373"], ["84226.8", "0.24702"], ["84224.9", "0.11863"], ["84224.72", "0.23746"], ["84223.08", "0"], ["84222.72", "0"], ["84222.3", "0"], ["84222.2", "0"], ["84221.93", "0"], ["84221.67", "0"], ["84221.6", "0"], ["84220.74", "0"], ["84220.32", "0"], ["84220.28", "0"], ["84220.2", "0"], ["84220", "0"], ["84219.9", "0"], ["84219.64", "0"], ["84219.55", "0"], ["84219.54", "0"], ["84219.45", "0"], ["84219.43", "0"], ["84219.28", "0"], ["84218.15", "0"], ["84217.99", "0"], ["84217.71", "0"], ["84217.67", "0"], ["84217.56", "0"], ["84217.45", "0"], ["84217.32", "0"], ["84217.21", "0"]], "a": [["84273.17", "0"], ["84273.27", "0"], ["84274.04", "0"], ["84274.3", "0"], ["84274.88", "0"], ["84275.04", "0"], ["84275.05", "0"], ["84275.08", "0"], ["84275.8", "0"], ["84277.28", "0"], ["84277.8", "0"], ["84278.33", "0"], ["84278.6", "0"], ["84278.84", "0"], ["84279.25", "0"], ["84279.3", "0"], ["84279.52", "0"], ["84279.69", "0.002653"], ["84280.69", "0"], ["84280.78", "0"], ["84281.02", "0"], ["84281.31", "0"], ["84281.94", "0.071195"], ["84282.8", "0.001499"], ["84284.68", "0"], ["84284.81", "0"], ["84285.34", "0.033213"], ["84285.78", "0"], ["84286.23", "0.000146"], ["84286.55", "0.028346"], ["84286.6", "0.0005"], ["84287.93", "0"], ["84288.11", "0.012925"], ["84288.12", "0.0005"], ["84289.12", "0"], ["84290.31", "0"], ["84291.7", "0.000296"], ["84291.9", "0.028527"], ["84292.05", "0"], ["84292.26", "0"], ["84292.52", "0.000297"], ["84292.54", "0.00009"], ["84292.74", "0"], ["84292.78", "0"], ["84293.09", "0"], ["84293.43", "0.000252"], ["84293.83", "0.020996"], ["84294.55", "0"], ["84294.98", "0.000296"], ["84294.99", "0.057799"], ["84295", "0.044"], ["84295.17", "0.009544"], ["84295.94", "0.083984"], ["84296.71", "0.000989"], ["84297.02", "0.008453"], ["84297.5", "0"], ["84297.69", "0.152918"], ["84297.89", "0"], ["84298.21", "0"], ["84298.3", "0.068"], ["84298.44", "0"], ["84298.6", "0"], ["84298.76", "0"], ["84298.89", "0"], ["84299.24", "0.004642"], ["84299.68", "0.139996"], ["84299.99", "0.11386"], ["84300.52", "0.117203"], ["84300.67", "0.118819"], ["84301.09", "0.249183"], ["84301.1", "0"], ["84301.17", "0"], ["84301.43", "0"], ["84301.6", "0.056"], ["84302.43", "1.411511"], ["84302.86", "0"], ["84303.9", "0"], ["84304.36", "0"], ["84304.78", "0.068395"], ["84304.98", "0.162"], ["84305.53", "0.242062"], ["84305.6", "0.009462"], ["84306.44", "0"], ["84306.84", "0"], ["84306.87", "0.237307"], ["84307.32", "0.176099"], ["84307.81", "0.014316"], ["84308.44", "0"], ["84308.83", "0.166339"], ["84308.87", "0"], ["84309.05", "0"], ["84309.41", "0"], ["84309.46", "0.019075"], ["84309.56", "0.023731"], ["84309.61", "0.017796"], ["84309.8", "0.003529"], ["84311.08", "0.237307"], ["84312.04", "0.071169"], ["84312.14", "0.007399"], ["84312.41", "0"], ["84312.72", "0"], ["84312.73", "0"], ["84312.93", "0"], ["84313.51", "0.024462"], ["84314.08", "0"], ["84314.7", "0"], ["84315.03", "0.013998"], ["84315.36", "0.023731"], ["84315.51", "0.0045"], ["84315.63", "0.300206"], ["84315.71", "0.0045"], ["84316.56", "0.02373"], ["84316.9", "0"], ["84317.09", "0"], ["84317.1", "0"], ["84317.14", "0.292767"], ["84317.93", "0.071164"], ["84317.96", "0.023731"], ["84319.62", "0"], ["84320.24", "0.005932"], ["84321.12", "0.03181"], ["84321.33", "0.023731"], ["84323.85", "0.0002"], ["84324.39", "0"], ["84325.29", "0.04"], ["84325.3", "0.04"], ["84326.07", "0.068395"], ["84326.38", "0.0002"], ["84326.41", "0.001347"], ["84328.04", "0.237306"], ["84328.28", "0.000235"], ["84328.81", "0.000235"], ["84328.91", "0.0002"], ["84329.5", "0.0006"], ["84329.61", "0.029801"], ["84329.84", "0.000612"], ["84329.88", "0.001333"], ["84329.99", "0.059948"]], "u": 7510682, "seq": 66889349738}, "cts": 1742142232407, "record_time": 1742142231.509976}
