{"topic": "orderbook.200.BTCUSDT", "ts": 1742577052920, "type": "delta", "data": {"s": "BTCUSDT", "b": [["83982.2", "0.089853"], ["83949.7", "0"], ["83949.5", "0.03963"], ["83948.5", "0.000524"], ["83947.3", "0.004396"], ["83947.1", "0.01288"], ["83945.7", "0.132873"], ["83944", "0"], ["83943.8", "0.050068"], ["83939.9", "0.001785"], ["83933.6", "0.014084"], ["83915.6", "0"], ["83915.5", "0"]], "a": [["83982.3", "0.381166"], ["83985.1", "0.071475"], ["83986", "0.005956"], ["83986.9", "0.000333"], ["83988.5", "0"], ["83992.8", "0.071469"], ["83999.5", "0.000333"], ["84023.9", "0.118996"], ["84026.4", "0"], ["84026.6", "0.04"], ["84037.5", "0.357388"], ["84044.1", "0"], ["84056.2", "0"], ["84056.5", "0"], ["84056.6", "0"]], "u": 128769, "seq": 67571263494}, "cts": 1742577052916, "record_time": 1742577053.108468, "EXCHANGE": "BYBIT"}
{"topic": "orderbook.200.BTCUSDT", "ts": 1742577053119, "type": "delta", "data": {"s": "BTCUSDT", "b": [["83982.2", "0.018378"], ["83980.9", "0.004415"], ["83977.2", "0"], ["83976.1", "0"], ["83974.1", "0.070114"], ["83972.1", "0"], ["83971.6", "0.000524"], ["83971.5", "0.071487"], ["83971.1", "0"], ["83970", "0.099266"], ["83967.8", "0.056"], ["83966.2", "0.161451"], ["83966.1", "0.044"], ["83965.7", "0"], ["83965.5", "0"], ["83964.6", "0"], ["83963.8", "0"], ["83961.3", "0.198666"], ["83961.2", "0.015"], ["83960.4", "0"], ["83960.2", "0"], ["83959.3", "0"], ["83959.2", "0"], ["83956", "0"], ["83953.1", "0.520791"], ["83952.6", "0.001333"], ["83949.6", "0.00009"], ["83949.4", "0.03963"], ["83947.2", "0"], ["83947", "0.01288"], ["83946.6", "0"], ["83945.7", "0"], ["83945.3", "0"], ["83944.9", "0"], ["83943.9", "0.22086"], ["83943.7", "0.220545"], ["83943.5", "0.563881"], ["83943.4", "0.024869"], ["83936", "0"], ["83925.3", "7.906183"], ["83924.6", "0.359928"], ["83922.4", "0"], ["83915.6", "0.000333"], ["83915.5", "0.00036"], ["83915", "1.798086"], ["83914.9", "0.001333"], ["83914.6", "0.012143"], ["83914.1", "0.224383"], ["83913.8", "0.016124"], ["83913.5", "0.118835"], ["83912.6", "0.035555"], ["83912.3", "0.001466"], ["83911.5", "0.059942"], ["83911.4", "0.000333"], ["83911.3", "0.048"], ["83911.2", "0.015"], ["83911.1", "0.011994"]], "a": [["83982.3", "0.3965"], ["83982.9", "0.071477"], ["83985.1", "0"], ["83986", "0"], ["83990.3", "0.071471"], ["83991", "0.003899"], ["83991.1", "0.019671"], ["83993.9", "0.009462"], ["83996", "0.095294"], ["83996.9", "0"], ["84002.8", "0"], ["84003.2", "0"], ["84003.8", "0.050035"], ["84005.6", "0.119163"], ["84005.8", "0"], ["84006.5", "0.119073"], ["84010.6", "0"], ["84023.8", "0.357428"], ["84026.6", "0.062921"], ["84027.4", "0.089305"], ["84031.9", "0.022831"], ["84033.6", "0"], ["84037.5", "0"], ["84044", "2.612421"], ["84056.5", "0.004156"], ["84056.6", "0.000366"]], "u": 128770, "seq": 67571263717}, "cts": 1742577053116, "record_time": 1742577053.30927, "EXCHANGE": "BYBIT"}
{"topic": "orderbook.200.BTCUSDT", "ts": 1742577053320, "type": "delta", "data": {"s": "BTCUSDT", "b": [["83982.2", "0.089856"], ["83975.9", "0.071483"], ["83974.1", "0"], ["83974", "0"], ["83972.9", "0.043526"], ["83961.4", "0.153399"], ["83960.6", "0.114057"], ["83958.2", "0.00101"], ["83957.1", "0"], ["83955.8", "0.016053"], ["83954.2", "0.196987"], ["83954", "0"], ["83940.2", "0.0128"], ["83940", "0.134401"], ["83930.8", "0.180075"], ["83930.2", "0.178609"], ["83929.7", "0.357419"], ["83926.6", "0.238008"], ["83925.3", "0"], ["83924.6", "0.0025"], ["83919.8", "7.906516"], ["83911.3", "0"], ["83911.2", "0"], ["83911.1", "0"]], "a": [["83988.5", "0.071472"], ["83990.3", "0"], ["83991.6", "0.130853"], ["83992.1", "0.000999"], ["84000.1", "0.186432"], ["84000.8", "0.178609"], ["84002.2", "0.218609"], ["84003.3", "0"], ["84006.3", "0.003576"], ["84010.5", "0.038008"], ["84012.9", "0.004606"], ["84018.8", "0.118996"], ["84023.8", "0"], ["84025.7", "0"], ["84025.9", "0.013795"], ["84026.3", "0"], ["84031.7", "0.357411"], ["84039.8", "0"], ["84050.5", "0.027698"], ["84056", "0"], ["84056.5", "0"], ["84056.6", "0"]], "u": 128771, "seq": 67571263915}, "cts": 1742577053314, "record_time": 1742577053.509114, "EXCHANGE": "BYBIT"}
{"topic": "orderbook.200.BTCUSDT", "ts": 1742577053520, "type": "delta", "data": {"s": "BTCUSDT", "b": [["83982.2", "0.089056"], ["83967.4", "0.113539"], ["83963.3", "0.120053"], ["83958.2", "0"], ["83957.3", "0.001146"], ["83956.9", "0.177306"], ["83956.3", "0.18316"], ["83955.8", "0.062423"], ["83949.9", "0.315595"], ["83949.3", "0.31244"], ["83943.9", "0.270405"], ["83943.7", "0.171"], ["83940", "0.134399"], ["83930.9", "0.357411"], ["83930.8", "0.001466"], ["83929.7", "0"], ["83928.1", "7.906183"], ["83919.8", "0.000333"], ["83913.5", "0"], ["83912.6", "0"], ["83912.3", "0"], ["83911.5", "0"], ["83911.4", "0"]], "a": [["83991.9", "0.11192"], ["83996", "0.144215"], ["83996.2", "0.115491"], ["83998", "0.178609"], ["84002.4", "0.165245"], ["84003.2", "0.179362"], ["84009.4", "0.29732"], ["84010.2", "0.295323"], ["84024.7", "2.618707"], ["84044", "0"], ["84054.7", "0"], ["84054.8", "0"], ["84055.5", "0"], ["84055.6", "0"], ["84055.8", "0"], ["84055.9", "0"]], "u": 128772, "seq": 67571264061}, "cts": 1742577053512, "record_time": 1742577053.708994, "EXCHANGE": "BYBIT"}
{"topic": "orderbook.200.BTCUSDT", "ts": 1742577053719, "type": "delta", "data": {"s": "BTCUSDT", "b": [["83957", "0.175542"], ["83956.4", "0.059399"], ["83955.8", "0"], ["83931", "0.357413"], ["83930.9", "0"], ["83930.8", "0.180075"], ["83913.8", "0"]], "a": [["84000.1", "0.28087"]], "u": 128773, "seq": 67571264179}, "cts": 1742577053717, "record_time": 1742577053.936703, "EXCHANGE": "BYBIT"}
{"topic": "orderbook.200.BTCUSDT", "ts": 1742577053920, "type": "delta", "data": {"s": "BTCUSDT", "b": [["83949.4", "0.355812"], ["83947.5", "0"], ["83944.1", "0.05"], ["83944", "0.049545"], ["83943.9", "0.22086"], ["83943.8", "0.000523"], ["83940", "0.134382"], ["83931.1", "0.357413"], ["83931", "0"], ["83914.1", "0"]], "a": [["83982.3", "0.396347"], ["83988.5", "0"], ["83990.9", "0.07147"], ["84024.8", "0.051355"], ["84027.6", "0"], ["84031.6", "0.369849"], ["84031.7", "0"], ["84049.8", "1.027962"]], "u": 128774, "seq": 67571264236}, "cts": 1742577053911, "record_time": 1742577054.109077, "EXCHANGE": "BYBIT"}
{"topic": "orderbook.200.BTCUSDT", "ts": 1742577054119, "type": "delta", "data": {"s": "BTCUSDT", "b": [["83960.6", "0"], ["83959.9", "0.118459"], ["83949.7", "0.03963"], ["83949.6", "0.03972"], ["83949.5", "0"], ["83949.4", "0.316182"], ["83947.3", "0.017276"], ["83947.2", "0.01288"], ["83947.1", "0"], ["83947", "0"], ["83944.1", "0"], ["83943.9", "0.270405"], ["83931.1", "0"], ["83930.9", "0.357415"], ["83914.1", "0.224383"], ["83913.8", "0.016124"], ["83913.5", "0.118835"]], "a": [["83982.3", "0.3965"], ["83982.9", "0"], ["83984", "0.071476"], ["84023.5", "0.04"], ["84023.6", "0.04"], ["84026.5", "0"], ["84026.6", "0.022921"], ["84031.5", "0.357415"], ["84031.6", "0.012435"], ["84053.5", "0"], ["84054.2", "0"]], "u": 128775, "seq": 67571264308}, "cts": 1742577054117, "record_time": 1742577054.308329, "EXCHANGE": "BYBIT"}
{"topic": "orderbook.200.BTCUSDT", "ts": 1742577054320, "type": "delta", "data": {"s": "BTCUSDT", "b": [["83969.5", "0.045629"], ["83944.1", "0.05"], ["83943.9", "0.22086"], ["83938.2", "0.0965"], ["83913.8", "0"], ["83913.5", "0"]], "a": [["83982.3", "0.396347"], ["84004.4", "0"], ["84031.4", "0.357414"], ["84031.5", "0"], ["84048.4", "0.101146"], ["84053.5", "1.787425"]], "u": 128776, "seq": 67571264420}, "cts": 1742577054288, "record_time": 1742577054.509602, "EXCHANGE": "BYBIT"}
{"topic": "orderbook.200.BTCUSDT", "ts": 1742577054520, "type": "delta", "data": {"s": "BTCUSDT", "b": [["83982.2", "0.089856"], ["83967.4", "0"], ["83963.3", "0"], ["83956.9", "0"], ["83956.3", "0"], ["83954.2", "0.018378"], ["83949.9", "0.023811"], ["83949.8", "0.04"], ["83949.6", "0.00009"], ["83949.3", "0.001466"], ["83947.4", "0.131835"], ["83947.2", "0"], ["83913.8", "0.016124"], ["83913.5", "0.118835"], ["83912.6", "0.035555"], ["83912.3", "0.001466"]], "a": [["83982.3", "0.417923"], ["83985.4", "0.005639"], ["83991.9", "0"], ["83993.8", "0.009225"], ["83996", "0.095294"], ["83996.2", "0"], ["83998", "0"], ["84002.4", "0.001446"], ["84003.2", "0"], ["84009.4", "0"], ["84010.2", "0"], ["84023.5", "0"], ["84023.6", "0"], ["84023.9", "0.158996"], ["84024", "0.041333"], ["84024.1", "1.181814"], ["84031.3", "0.367805"], ["84031.4", "0"], ["84054.2", "0.000333"], ["84054.7", "0.000524"], ["84054.8", "0.118996"], ["84055.5", "0.001466"], ["84055.6", "0.024163"], ["84055.8", "0.589917"], ["84055.9", "0.005"]], "u": 128777, "seq": 67571264563}, "cts": 1742577054515, "record_time": 1742577054.709333, "EXCHANGE": "BYBIT"}
{"topic": "orderbook.200.BTCUSDT", "ts": 1742577054719, "type": "delta", "data": {"s": "BTCUSDT", "b": [["83982.2", "0.07082"], ["83974.7", "0.05256"], ["83974.6", "0.073984"], ["83972.9", "0"], ["83971.5", "0"], ["83961.8", "0.178942"], ["83957", "0.03164"], ["83949.8", "0"], ["83949.7", "0"], ["83949.6", "0.03972"], ["83949.5", "0.03963"], ["83949.4", "0"], ["83947.4", "0.118835"], ["83947.3", "0.004396"], ["83947.2", "0.01288"], ["83947.1", "0.01288"], ["83944.1", "0"], ["83944", "0"], ["83943.9", "0.270405"], ["83943.8", "0.050068"], ["83943.4", "0.114174"], ["83940", "0.134362"], ["83935.3", "0.3574"], ["83930.9", "0"], ["83930.8", "7.907363"], ["83930.2", "0"], ["83928.1", "0"], ["83926.6", "0.059399"], ["83922.4", "0.089305"], ["83911.5", "0.059942"], ["83911.4", "0.000333"], ["83911.3", "0.048"], ["83911.2", "0.015"]], "a": [["83982.3", "0.426957"], ["83984", "0"], ["83985.3", "0.005956"], ["83985.4", "0.071475"], ["83990.9", "0"], ["83995.5", "0.071466"], ["83997.6", "0.04"], ["84000.1", "0.201043"], ["84002.2", "0.219209"], ["84002.4", "0"], ["84006.3", "0"], ["84023.9", "0.118996"], ["84024", "0.001333"], ["84024.5", "0.04"], ["84024.6", "0.04"], ["84024.7", "0.006286"], ["84031.3", "0.01039"], ["84031.9", "0"], ["84034.9", "0.357406"], ["84035.7", "2.612421"], ["84055.8", "0"], ["84055.9", "0"]], "u": 128778, "seq": 67571264772}, "cts": 1742577054717, "record_time": 1742577054.908983, "EXCHANGE": "BYBIT"}
{"topic": "orderbook.200.BTCUSDT", "ts": 1742577054920, "type": "delta", "data": {"s": "BTCUSDT", "b": [["83982.2", "0.070805"], ["83977.8", "0.072814"], ["83974.7", "0.031115"], ["83974.6", "0.0025"], ["83967.7", "0.116545"], ["83961.9", "0.251728"], ["83961.8", "0.000333"], ["83961.4", "0"], ["83960.4", "0.178609"], ["83960.2", "0.178609"], ["83957.2", "0.18181"], ["83956", "0.178609"], ["83950.2", "0.29898"], ["83935.4", "0.358867"], ["83935.3", "0"], ["83930.8", "7.890363"], ["83914.1", "0"], ["83911.4", "0"], ["83911.3", "0"], ["83911.2", "0"]], "a": [["83982.3", "0.432913"], ["83984.5", "0.071476"], ["83985.3", "0"], ["83985.4", "0"], ["83990.6", "0.14968"], ["83992.2", "0.113243"], ["83995.5", "0"], ["84002.2", "0.179209"], ["84002.7", "0.186354"], ["84003.3", "0.178609"], ["84009.7", "0.310804"], ["84024.1", "0.43735"], ["84024.3", "0.04"], ["84024.4", "0.04"], ["84024.5", "0"], ["84024.6", "0"], ["84024.7", "2.618707"], ["84026.6", "0"], ["84031", "0.02391"], ["84035.7", "0"], ["84055.6", "0"]], "u": 128779, "seq": 67571264886}, "cts": 1742577054916, "record_time": 1742577055.110448, "EXCHANGE": "BYBIT"}
{"topic": "orderbook.200.BTCUSDT", "ts": 1742577055120, "type": "delta", "data": {"s": "BTCUSDT", "b": [["83960.4", "0"], ["83960.2", "0"], ["83956", "0"], ["83953.6", "0.462622"], ["83949.6", "0.00009"], ["83949.4", "0.03963"], ["83947.3", "0.017396"], ["83947.1", "0"], ["83944", "0.05"], ["83943.8", "0.000523"], ["83943.4", "0.024869"], ["83940", "0.134383"], ["83935.4", "0.001466"], ["83930.9", "0.357402"], ["83922.4", "0"], ["83911.4", "0.000333"], ["83911.3", "0.048"]], "a": [["83989.6", "0.005589"], ["84024.3", "0"], ["84024.4", "0"], ["84024.6", "0.04"], ["84024.7", "2.658707"], ["84034.9", "0.3574"]], "u": 128780, "seq": 67571265016}, "cts": 1742577055116, "record_time": 1742577055.308685, "EXCHANGE": "BYBIT"}
{"topic": "orderbook.200.BTCUSDT", "ts": 1742577055319, "type": "delta", "data": {"s": "BTCUSDT", "b": [["83956.8", "0.179942"], ["83949.7", "0.04"], ["83949.6", "0.03972"], ["83949.5", "0"], ["83949.4", "0"], ["83947.6", "0.024337"], ["83943.4", "0"], ["83930.8", "8.068972"], ["83930.2", "0.178609"], ["83926.6", "0.238008"]], "a": [["83983.6", "0.071476"], ["83984.5", "0"], ["84023.8", "0.04"], ["84023.9", "0.158996"], ["84024.6", "0"], ["84024.7", "2.618707"], ["84031.7", "0.357413"], ["84034.9", "0"]], "u": 128781, "seq": 67571265183}, "cts": 1742577055309, "record_time": 1742577055.508421, "EXCHANGE": "BYBIT"}
{"topic": "orderbook.200.BTCUSDT", "ts": 1742577055519, "type": "delta", "data": {"s": "BTCUSDT", "b": [["83975.7", "0.0006"], ["83952.2", "0.171"], ["83947", "0.0016"], ["83940", "0.134382"], ["83911.4", "0"], ["83911.3", "0"]], "a": [["84024.1", "1.181814"], ["84031.7", "0"], ["84032.5", "0.357411"]], "u": 128782, "seq": 67571265263}, "cts": 1742577055515, "record_time": 1742577055.709586, "EXCHANGE": "BYBIT"}
{"topic": "orderbook.200.BTCUSDT", "ts": 1742577055719, "type": "delta", "data": {"s": "BTCUSDT", "b": [["83957.3", "0.140911"], ["83957", "0"], ["83928.6", "0.023815"]], "a": [["83983.6", "0"], ["84003.3", "0"], ["84008.3", "0.128542"], ["84032.5", "0"], ["84034.9", "0.357409"], ["84037.9", "0.04"], ["84055.6", "0.024163"]], "u": 128783, "seq": 67571265373}, "cts": 1742577055716, "record_time": 1742577055.908418, "EXCHANGE": "BYBIT"}
{"topic": "orderbook.200.BTCUSDT", "ts": 1742577055919, "type": "delta", "data": {"s": "BTCUSDT", "b": [["83956.8", "0.001333"], ["83954.2", "0"], ["83953.6", "0.498351"], ["83931", "0.357402"], ["83930.9", "0"], ["83930.8", "7.969575"], ["83930.2", "0"], ["83926.6", "0.059399"], ["83911.4", "0.000333"], ["83911.3", "0.048"]], "a": [["83982.3", "0.43289"], ["83983.3", "0.000153"], ["83984.3", "0.071476"], ["83990.6", "0.07821"], ["83991", "0.075369"], ["83992.8", "0"], ["83995", "0.071467"], ["84055.5", "0"], ["84055.6", "0"]], "u": 128784, "seq": 67571265513}, "cts": 1742577055916, "record_time": 1742577056.10898, "EXCHANGE": "BYBIT"}
{"topic": "orderbook.200.BTCUSDT", "ts": 1742577056120, "type": "delta", "data": {"s": "BTCUSDT", "b": [["83982.2", "0.071129"], ["83967.7", "0.001466"], ["83957.3", "0.001146"], ["83957.2", "0"], ["83956.8", "0.179942"], ["83950.2", "0"], ["83931.1", "0.357406"], ["83931", "0"], ["83930.8", "8.148184"], ["83930.2", "0.178609"], ["83926.6", "0.238008"], ["83911.2", "0.015"]], "a": [["83983.3", "0"], ["83992.2", "0"], ["84002.7", "0"], ["84009.7", "0"], ["84055.5", "0.001466"], ["84055.6", "0.024163"], ["84055.8", "0.589917"], ["84055.9", "0.005"]], "u": 128785, "seq": 67571265581}, "cts": 1742577056099, "record_time": 1742577056.309613, "EXCHANGE": "BYBIT"}
{"topic": "orderbook.200.BTCUSDT", "ts": 1742577056320, "type": "delta", "data": {"s": "BTCUSDT", "b": [["83947.7", "0.18496"], ["83931.2", "0.357407"], ["83931.1", "0"], ["83911.2", "0"]], "a": [["84034.9", "0.357407"]], "u": 128786, "seq": 67571265716}, "cts": 1742577056315, "record_time": 1742577056.514086, "EXCHANGE": "BYBIT"}
{"topic": "orderbook.200.BTCUSDT", "ts": 1742577056520, "type": "delta", "data": {"s": "BTCUSDT", "b": [["83982.2", "0.072129"], ["83976.3", "0"], ["83973.2", "0"], ["83969.5", "0.04"], ["83967.7", "0.123114"], ["83961.7", "0.019765"], ["83959.9", "0.004403"], ["83959.1", "0.114057"], ["83957.7", "0.006477"], ["83957.3", "0"], ["83957.2", "0.165298"], ["83956.9", "0.079709"], ["83953.6", "0.462622"], ["83953.5", "0.089207"], ["83950.2", "0.297473"], ["83949.8", "0.04"], ["83949.7", "0.03963"], ["83949.6", "0.00009"], ["83947.4", "0.131835"], ["83947.3", "0.017276"], ["83947.2", "0"], ["83944.1", "0.05"], ["83944", "0.049545"], ["83943.9", "0.22086"], ["83931.3", "0.35741"], ["83931.2", "0"], ["83930.8", "0.001466"], ["83930.2", "0"], ["83926.6", "0.059399"], ["83925.3", "7.968109"], ["83915", "1.786092"], ["83911.4", "0"], ["83911.3", "0"]], "a": [["83982.4", "0.000153"], ["83983.3", "0.071477"], ["83984.3", "0"], ["83986.2", "0.000999"], ["83989.2", "0.071472"], ["83991.6", "0.113136"], ["83992.2", "0.122264"], ["83995", "0"], ["84000.8", "0"], ["84002.7", "0.172146"], ["84005.1", "0.003576"], ["84006.4", "0"], ["84009.7", "0.28866"], ["84015", "0.005953"], ["84023.7", "0.04"], ["84023.9", "0.118996"], ["84025.7", "0.295947"], ["84032.5", "0.35741"], ["84034.9", "0"], ["84036.3", "0.011993"], ["84047.4", "0.011993"], ["84052.3", "0"], ["84053.5", "0"], ["84054.2", "0"], ["84054.7", "0"], ["84054.8", "0"], ["84055.5", "0"], ["84055.6", "0"], ["84055.8", "0"], ["84055.9", "0"]], "u": 128787, "seq": 67571266249}, "cts": 1742577056517, "record_time": 1742577056.709001, "EXCHANGE": "BYBIT"}
{"topic": "orderbook.200.BTCUSDT", "ts": 1742577056720, "type": "delta", "data": {"s": "BTCUSDT", "b": [["83957.3", "0.129298"], ["83956.9", "0"], ["83952.9", "0.178609"], ["83951.8", "0.178609"], ["83947.6", "0.202946"], ["83945.3", "0.125026"], ["83931.4", "0.358013"], ["83931.3", "0"], ["83928.1", "7.968109"], ["83925.3", "0"], ["83912.3", "0"], ["83911.5", "0"]], "a": [["83985.6", "0.000999"], ["83996", "0.209797"], ["83998", "0.178609"], ["83998.3", "0.218609"], ["84032.4", "0.360212"], ["84032.5", "0"], ["84051", "0"]], "u": 128788, "seq": 67571266358}, "cts": 1742577056696, "record_time": 1742577056.909336, "EXCHANGE": "BYBIT"}
{"topic": "orderbook.200.BTCUSDT", "ts": 1742577056920, "type": "delta", "data": {"s": "BTCUSDT", "b": [["83931.4", "0.0006"], ["83929.7", "0.357414"], ["83922.4", "0.089305"], ["83913.5", "0"], ["83912.6", "0"]], "a": [["84005.1", "0"], ["84007.1", "0"], ["84031.7", "0.357414"], ["84032.4", "0.002799"], ["84051", "0.023808"]], "u": 128789, "seq": 67571266418}, "cts": 1742577056916, "record_time": 1742577057.109614, "EXCHANGE": "BYBIT"}
{"topic": "orderbook.200.BTCUSDT", "ts": 1742577057120, "type": "delta", "data": {"s": "BTCUSDT", "b": [["83982.2", "0.072032"], ["83976.4", "0.003"], ["83974.7", "0"], ["83973.9", "0.02848"], ["83967.7", "0.001466"], ["83957.2", "0"], ["83952.9", "0"], ["83951.8", "0"], ["83950.2", "0"], ["83949.8", "0"], ["83949.6", "0.03972"], ["83947.6", "0.024337"], ["83947.4", "0.118835"], ["83947.2", "0.01288"], ["83945.3", "0"], ["83944.1", "0"], ["83943.9", "0.270405"], ["83940", "0.134381"], ["83922.4", "0"], ["83913.5", "0.118835"], ["83912.6", "0.035555"], ["83912.3", "0.001466"], ["83911.5", "0.059942"], ["83911.4", "0.000333"], ["83911.3", "0.048"]], "a": [["83992.2", "0"], ["84002.7", "0"], ["84004", "0.035729"], ["84009.7", "0"], ["84023.7", "0"], ["84023.9", "0.158996"], ["84030.3", "0.003"], ["84052.3", "0.004156"], ["84053.5", "1.787425"]], "u": 128790, "seq": 67571266532}, "cts": 1742577057107, "record_time": 1742577057.311825, "EXCHANGE": "BYBIT"}
{"topic": "orderbook.200.BTCUSDT", "ts": 1742577057320, "type": "delta", "data": {"s": "BTCUSDT", "b": [["83957.3", "0.079709"], ["83953.5", "0.053478"], ["83952.9", "0.178609"], ["83951.8", "0.178609"], ["83947.6", "0.202946"], ["83945.3", "0.125026"], ["83922.4", "0.089305"], ["83912.3", "0"], ["83911.5", "0"], ["83911.4", "0"], ["83911.3", "0"]], "a": [["83982.4", "0"], ["83983.3", "0"], ["83984.4", "0.071476"], ["84000.1", "0.145925"], ["84019.1", "0.584252"], ["84024.8", "0"], ["84054.2", "0.000333"], ["84054.7", "0.000524"]], "u": 128791, "seq": 67571266625}, "cts": 1742577057289, "record_time": 1742577057.509484, "EXCHANGE": "BYBIT"}
{"topic": "orderbook.200.BTCUSDT", "ts": 1742577057520, "type": "delta", "data": {"s": "BTCUSDT", "b": [["83969.3", "0.0057"], ["83953.4", "0.036062"], ["83947.4", "0.131835"], ["83947.2", "0"], ["83944.1", "0.05"], ["83943.9", "0.327546"], ["83912.6", "0"]], "a": [["83989.2", "0"], ["83989.5", "0.071471"], ["83991", "0.003899"], ["83992.1", "0"], ["83993.1", "0.071468"]], "u": 128792, "seq": 67571266728}, "cts": 1742577057503, "record_time": 1742577057.709937, "EXCHANGE": "BYBIT"}
{"topic": "orderbook.200.BTCUSDT", "ts": 1742577057720, "type": "delta", "data": {"s": "BTCUSDT", "b": [["83959.7", "0.000358"]], "a": [["83982.3", "0.432875"], ["84031.6", "0.369848"], ["84031.7", "0"], ["84054.8", "0.118996"]], "u": 128793, "seq": 67571266795}, "cts": 1742577057715, "record_time": 1742577057.90879, "EXCHANGE": "BYBIT"}
{"topic": "orderbook.200.BTCUSDT", "ts": 1742577057920, "type": "delta", "data": {"s": "BTCUSDT", "b": [["83949.7", "0"], ["83949.5", "0.03963"], ["83947.4", "0.118835"], ["83947.3", "0.017396"], ["83947.2", "0.01288"], ["83944.1", "0"], ["83944", "0.05"], ["83943.9", "0.377091"], ["83940", "0.134362"], ["83915", "0"], ["83912.6", "0.035555"]], "a": [["83982.4", "0.000153"], ["84008.3", "0.125026"], ["84023.8", "0"], ["84023.9", "0.118996"], ["84024", "0.041333"], ["84024.1", "1.221814"], ["84031.6", "0.012435"], ["84032.5", "0.357412"], ["84053.5", "0.001333"], ["84054.8", "0"]], "u": 128794, "seq": 67571266837}, "cts": 1742577057899, "record_time": 1742577058.109077, "EXCHANGE": "BYBIT"}
{"topic": "orderbook.200.BTCUSDT", "ts": 1742577058120, "type": "delta", "data": {"s": "BTCUSDT", "b": [["83952.9", "0"], ["83952.3", "0.119073"], ["83951.8", "0"], ["83947.3", "0.004396"], ["83947.1", "0.01288"], ["83944", "0"], ["83943.8", "0.050068"], ["83928.1", "0"], ["83925.3", "7.964313"], ["83912.3", "0.001466"]], "a": [["83982.4", "0"], ["83982.7", "0.000153"], ["84005.6", "0.00009"], ["84006.5", "0"], ["84023.9", "0.158996"], ["84024.1", "1.181814"], ["84031.7", "0.357413"], ["84032.5", "0"], ["84054.8", "0.118996"]], "u": 128795, "seq": 67571266905}, "cts": 1742577058116, "record_time": 1742577058.309856, "EXCHANGE": "BYBIT"}
{"topic": "orderbook.200.BTCUSDT", "ts": 1742577058320, "type": "delta", "data": {"s": "BTCUSDT", "b": [["83952.9", "0.178609"], ["83951.8", "0.178609"], ["83929.8", "0.357418"], ["83929.7", "0"], ["83912.6", "0"], ["83912.3", "0"]], "a": [["83983.6", "0.071476"], ["83984.4", "0"], ["84004.1", "0.003576"], ["84004.8", "0.15768"], ["84023.7", "0.04"], ["84023.8", "0.04"], ["84023.9", "0.118996"], ["84024", "0.001333"], ["84031.6", "0.369853"], ["84031.7", "0"], ["84054.7", "0"], ["84054.8", "0"]], "u": 128796, "seq": 67571267001}, "cts": 1742577058316, "record_time": 1742577058.508812, "EXCHANGE": "BYBIT"}
{"topic": "orderbook.200.BTCUSDT", "ts": 1742577058519, "type": "delta", "data": {"s": "BTCUSDT", "b": [["83982.2", "0.08629"], ["83949.6", "0.00009"], ["83949.4", "0.03963"], ["83947.2", "0"], ["83947", "0.01448"], ["83945.5", "0"], ["83943.9", "0.327546"], ["83943.7", "0.220545"], ["83940.1", "0.082113"], ["83932.8", "0.35382"], ["83929.9", "0.357416"], ["83929.8", "0"], ["83928.1", "7.964313"], ["83925.3", "0"], ["83912.6", "0.035555"]], "a": [["83982.7", "0"], ["83983.6", "0"], ["83984.5", "0.071476"], ["84023.7", "0"], ["84023.9", "0.158996"], ["84024.7", "0.006286"], ["84031.5", "0.357416"], ["84031.6", "0.012435"], ["84054.7", "0.000524"]], "u": 128797, "seq": 67571267085}, "cts": 1742577058518, "record_time": 1742577058.708819, "EXCHANGE": "BYBIT"}
{"topic": "orderbook.200.BTCUSDT", "ts": 1742577058719, "type": "delta", "data": {"s": "BTCUSDT", "b": [["83969.3", "0"], ["83947.7", "0"], ["83947.2", "0.013"], ["83947", "0.0016"], ["83943.9", "0.377546"], ["83943.7", "0.171"], ["83930", "0.357935"], ["83929.9", "0"], ["83912.3", "0.001466"], ["83911.5", "0.059942"]], "a": [["83983", "0.07163"], ["83983.9", "0.000153"], ["83984.5", "0"], ["83988", "0.071473"], ["83993.1", "0"], ["84024.1", "0.43735"], ["84024.7", "2.618707"], ["84031.4", "0.357413"], ["84031.5", "0"], ["84054.7", "0"]], "u": 128798, "seq": 67571267194}, "cts": 1742577058717, "record_time": 1742577058.917327, "EXCHANGE": "BYBIT"}
{"topic": "orderbook.200.BTCUSDT", "ts": 1742577058920, "type": "delta", "data": {"s": "BTCUSDT", "b": [["83982.2", "0.08549"], ["83962.7", "0.108211"], ["83955.7", "0.066437"], ["83949.6", "0.04009"], ["83949.4", "0"], ["83948.7", "0.118109"], ["83930.1", "0.357416"], ["83930", "0.000522"], ["83911.5", "0"]], "a": [["83983", "0.071477"], ["83983.4", "0.000153"], ["83983.9", "0"], ["83988", "0"], ["83992", "0.071469"], ["83997.7", "0.060239"], ["84004.7", "0.055882"], ["84011.7", "0.119045"], ["84023.7", "0.04"], ["84023.9", "0.118996"], ["84031.3", "0.367807"], ["84031.4", "0"], ["84054.2", "0"]], "u": 128799, "seq": 67571267281}, "cts": 1742577058913, "record_time": 1742577059.109352, "EXCHANGE": "BYBIT"}
{"topic": "orderbook.200.BTCUSDT", "ts": 1742577059120, "type": "delta", "data": {"s": "BTCUSDT", "b": [["83940", "0.13436"], ["83930.2", "0.357414"], ["83930.1", "0"]], "a": [["83983", "0"], ["83983.4", "0"], ["83984.4", "0.071476"], ["84004.1", "0"], ["84030.3", "0"], ["84031.2", "0.357414"], ["84031.3", "0.01039"], ["84036.4", "0.116406"], ["84054.2", "0.000333"], ["84054.7", "0.000524"]], "u": 128800, "seq": 67571267368}, "cts": 1742577059116, "record_time": 1742577059.309555, "EXCHANGE": "BYBIT"}
{"topic": "orderbook.200.BTCUSDT", "ts": 1742577059319, "type": "delta", "data": {"s": "BTCUSDT", "b": [["83949.6", "0.00009"], ["83949.4", "0.03963"], ["83943.9", "0.327546"], ["83943.7", "0.220545"], ["83940", "0.001526"], ["83930.3", "0.357412"], ["83930.2", "0"], ["83912.3", "0"]], "a": [["83984.1", "0.000153"], ["83984.4", "0"], ["83984.7", "0.071475"], ["83989.5", "0"], ["83989.9", "0.071471"], ["84005.9", "0.003576"], ["84019.1", "0.532897"], ["84031.2", "0"], ["84031.7", "0.357412"], ["84054.2", "0"], ["84054.7", "0"]], "u": 128801, "seq": 67571267477}, "cts": 1742577059318, "record_time": 1742577059.508434, "EXCHANGE": "BYBIT"}
{"topic": "orderbook.200.BTCUSDT", "ts": 1742577059520, "type": "delta", "data": {"s": "BTCUSDT", "b": [["83949.6", "0.04009"], ["83949.4", "0"], ["83948.8", "0.229756"], ["83943.9", "0.377546"], ["83943.7", "0.171"], ["83940.1", "0.001333"], ["83940", "0.13436"], ["83930.4", "0.357416"], ["83930.3", "0"], ["83912.3", "0.001466"]], "a": [["83984.7", "0"], ["83985", "0.071475"], ["83989.9", "0"], ["83990.2", "0.071471"], ["84019.1", "0.584252"], ["84024.1", "1.166407"], ["84031.6", "0.369851"], ["84031.7", "0"], ["84054.2", "0.000333"]], "u": 128802, "seq": 67571267541}, "cts": 1742577059511, "record_time": 1742577059.709607, "EXCHANGE": "BYBIT"}
{"topic": "orderbook.200.BTCUSDT", "ts": 1742577059719, "type": "delta", "data": {"s": "BTCUSDT", "b": [["83982.2", "0.085312"], ["83949.6", "0.00009"], ["83949.4", "0.03963"], ["83947.2", "0"], ["83947", "0.01448"], ["83930.5", "0.357416"], ["83930.4", "0"]], "a": [["83984.1", "0"], ["83985.4", "0.002031"], ["84024.7", "0.006286"], ["84031.5", "0.357416"], ["84031.6", "0.012435"], ["84054.2", "0"]], "u": 128803, "seq": 67571267619}, "cts": 1742577059717, "record_time": 1742577059.908772, "EXCHANGE": "BYBIT"}
{"topic": "orderbook.200.BTCUSDT", "ts": 1742577059920, "type": "delta", "data": {"s": "BTCUSDT", "b": [["83969.2", "0.176607"], ["83954.1", "0.003426"], ["83943.9", "0.327546"], ["83943.7", "0.220545"], ["83930.6", "0.361755"], ["83930.5", "0"]], "a": [["83982.8", "0.000685"], ["83984.6", "0.000153"], ["84024.1", "0.43735"], ["84024.7", "2.618707"], ["84029", "0.476413"], ["84031.5", "0"], ["84053.5", "0"]], "u": 128804, "seq": 67571267670}, "cts": 1742577059916, "record_time": 1742577060.108081, "EXCHANGE": "BYBIT"}
{"topic": "orderbook.200.BTCUSDT", "ts": 1742577060120, "type": "delta", "data": {"s": "BTCUSDT", "b": [["83940", "0.134359"], ["83930.7", "0.357416"], ["83930.6", "0.004339"], ["83912.3", "0"]], "a": [["84005.9", "0"], ["84023.6", "0.04"], ["84023.8", "0"], ["84029", "0.118996"], ["84031.7", "0.357416"]], "u": 128805, "seq": 67571267720}, "cts": 1742577060116, "record_time": 1742577060.308903, "EXCHANGE": "BYBIT"}
{"topic": "orderbook.200.BTCUSDT", "ts": 1742577060320, "type": "delta", "data": {"s": "BTCUSDT", "b": [["83954.1", "0"], ["83930.8", "0.358882"], ["83930.7", "0"], ["83912.3", "0.001466"], ["83911.5", "0.059942"]], "a": [["83995.2", "0.003576"], ["84052.3", "0"]], "u": 128806, "seq": 67571267788}, "cts": 1742577060317, "record_time": 1742577060.508822, "EXCHANGE": "BYBIT"}
{"topic": "orderbook.200.BTCUSDT", "ts": 1742577060519, "type": "delta", "data": {"s": "BTCUSDT", "b": [["83982.2", "0"], ["83982", "0"], ["83981.9", "0"], ["83981.8", "0"], ["83981.6", "0"], ["83980.9", "0"], ["83980.8", "0"], ["83977.8", "0.001333"], ["83975.9", "0"], ["83975.7", "0"], ["83974.8", "0"], ["83973.9", "0"], ["83969.2", "0"], ["83966.7", "0.123791"], ["83962.7", "0.048"], ["83962.6", "0.118171"], ["83956.4", "0"], ["83956.2", "0.178272"], ["83955.7", "0.004402"], ["83955.6", "0.167055"], ["83953", "0"], ["83952.9", "0"], ["83951.8", "0"], ["83949.5", "0"], ["83949.3", "0.041097"], ["83949.2", "0.277321"], ["83948.7", "0"], ["83948.6", "0.431943"], ["83947.6", "0.024337"], ["83947.1", "0"], ["83946.9", "0.01288"], ["83945.3", "0"], ["83943.8", "0.000523"], ["83943.6", "0.049545"], ["83940.1", "0.082112"], ["83940", "0.001526"], ["83934.6", "0.000522"], ["83934.4", "0.132833"], ["83930.8", "0.001466"], ["83928.1", "0"], ["83922.6", "0"], ["83922.4", "0"], ["83918.9", "0.35744"], ["83911.4", "0.000333"], ["83911.3", "0.048"], ["83911.2", "0.015"], ["83911.1", "0.011994"], ["83910.7", "0.001333"], ["83910.4", "0.011859"], ["83909.6", "0.031122"], ["83909.1", "0.120667"], ["83908.7", "7.848831"], ["83908.6", "1.181916"], ["83908.3", "0.011994"], ["83907.9", "0.011994"], ["83907.8", "0.035716"], ["83907.7", "0.001466"], ["83907.6", "0.0047"]], "a": [["83980.1", "0.146575"], ["83981", "0.005952"], ["83981.7", "0.009406"], ["83982.1", "0.1"], ["83982.2", "0.015181"], ["83982.3", "0.401828"], ["83984.6", "0"], ["83985", "0"], ["83986.1", "0"], ["83986.2", "0"], ["83986.9", "0.059732"], ["83987", "0"], ["83987.1", "0.174"], ["83990.2", "0"], ["83990.5", "0"], ["83991.2", "0.113667"], ["83992", "0"], ["83992.2", "0.003576"], ["83993.8", "0"], ["83994.7", "0"], ["83995.2", "0"], ["83995.5", "0.123584"], ["83997.7", "0.004331"], ["83999.9", "0.119073"], ["84001.7", "0.165428"], ["84001.9", "0.004932"], ["84002.5", "0.1661"], ["84004.7", "0.001466"], ["84008.7", "0.280996"], ["84009.1", "0"], ["84009.5", "0.277085"], ["84011.7", "0"], ["84023.5", "0.35744"], ["84024.1", "1.166407"], ["84024.7", "0.006286"], ["84027.8", "0.003609"], ["84031.7", "0"]], "u": 128807, "seq": 67571268131}, "cts": 1742577060517, "record_time": 1742577060.70871, "EXCHANGE": "BYBIT"}
{"topic": "orderbook.200.BTCUSDT", "ts": 1742577060720, "type": "delta", "data": {"s": "BTCUSDT", "b": [["83980", "0"], ["83978.5", "0"], ["83978.4", "0"], ["83977.8", "0"], ["83977", "0"], ["83976.8", "0"], ["83976.7", "0"], ["83976.4", "0"], ["83976.2", "0"], ["83974.6", "0"], ["83974.3", "0"], ["83973.8", "0"], ["83973.6", "0"], ["83972.8", "0"], ["83972.5", "0"], ["83972.3", "0"], ["83971.6", "0"], ["83970.8", "0"], ["83970.2", "0"], ["83970", "0"], ["83969.7", "0.009584"], ["83969.5", "0"], ["83968.5", "0"], ["83968", "0"], ["83967.8", "0"], ["83966.7", "0"], ["83966.4", "0"], ["83966.2", "0"], ["83966.1", "0"], ["83965.8", "0"], ["83965.3", "0.00178"], ["83964.5", "0.024276"], ["83964.4", "0"], ["83962.9", "0"], ["83962.8", "0"], ["83962.7", "0"], ["83962.6", "0"], ["83961.9", "0"], ["83961.7", "0"], ["83961.3", "0.02"], ["83960.7", "0"], ["83959.6", "0.0003"], ["83959.1", "0"], ["83958.9", "0.035103"], ["83958.8", "0.003768"], ["83958.5", "0.001466"], ["83958.4", "0.005954"], ["83958", "0.00009"], ["83957.4", "0.02046"], ["83957.3", "0"], ["83956.9", "0.056"], ["83956.8", "0.001333"], ["83956.2", "0"], ["83956.1", "0"], ["83955.9", "0.0765"], ["83955.6", "0"], ["83953.8", "0.001113"], ["83953.6", "0"], ["83953.4", "0.000333"], ["83953.3", "0.237218"], ["83953.2", "0.128499"], ["83953.1", "0.000524"], ["83952.9", "0.044"], ["83952.3", "0"], ["83951.9", "0.048"], ["83950.9", "0"], ["83949.9", "0"], ["83949.4", "0"], ["83949.3", "0.001466"], ["83949.2", "0.000333"], ["83948.8", "0.205943"], ["83948.6", "0"], ["83947.6", "0"], ["83947", "0.0016"], ["83946.9", "0"], ["83946.8", "0.004625"], ["83946.5", "0"], ["83943.7", "0.171"], ["83943.6", "0"], ["83943.5", "0"], ["83943", "0"], ["83942.3", "0.295357"], ["83941.2", "0.238016"], ["83940.2", "0.003575"], ["83940.1", "0.001333"], ["83938.6", "0.023816"], ["83938.5", "0"], ["83938.3", "0.037993"], ["83938.2", "0"], ["83938", "0"], ["83937.4", "0.03963"], ["83937.3", "0.03963"], ["83936.3", "0.011915"], ["83935.3", "0.238799"], ["83935", "0.013394"], ["83934.9", "0.01288"], ["83934.5", "0.522003"], ["83934.4", "0"], ["83932.8", "0.00009"], ["83932", "0.023816"], ["83931.7", "0.050877"], ["83931.6", "0.049544"], ["83931.3", "0.023817"], ["83929.5", "1.030323"], ["83929.4", "0"], ["83928.2", "0.565467"], ["83927.7", "0"], ["83927.5", "0.007287"], ["83927.3", "0.023817"], ["83926.3", "0"], ["83925.6", "0"], ["83924.3", "0"], ["83922.3", "0"], ["83920", "0.00006"], ["83919.3", "0"], ["83919", "0"], ["83918.9", "0"], ["83916.2", "0"], ["83914.6", "0"], ["83912.2", "0.003575"], ["83911.6", "0.357486"], ["83911.1", "0"], ["83909.9", "0.171"], ["83909.6", "0.019263"], ["83909.1", "0"], ["83908.7", "0"], ["83907.9", "0"], ["83907.8", "0.023857"], ["83907.5", "0.011859"], ["83907.2", "0.000333"], ["83906.9", "0.119357"], ["83906.8", "0.059399"], ["83906.5", "3.762461"], ["83906", "0.023728"], ["83905.9", "0.005"], ["83905.8", "0.00595"], ["83905.4", "0.004263"], ["83903.7", "0.044"], ["83903.1", "0.001466"], ["83903", "0.013443"], ["83902.3", "0.001853"], ["83902", "0.048"], ["83901.9", "0.056"], ["83901.8", "0.118835"], ["83901.4", "0.089305"], ["83901.3", "0.12"], ["83901.2", "0.004263"], ["83900.7", "0.320756"], ["83900", "0.001844"], ["83899.9", "0.224383"], ["83899.6", "0.000149"], ["83899.5", "3.481478"], ["83899.2", "0.00009"], ["83899", "0.000358"], ["83898.8", "0.000333"], ["83898.5", "0.001466"], ["83898.1", "0.001333"], ["83897.7", "0.00052"], ["83897", "0.048263"], ["83896.8", "0.059564"], ["83894.6", "0.000333"], ["83893.9", "0.002799"], ["83893.4", "0.00036"], ["83893.2", "0.044"], ["83893.1", "0.00052"], ["83892.8", "0.004263"], ["83891.7", "0.118996"], ["83891.5", "0.044"], ["83891.4", "0.12"], ["83891", "0.04"], ["83890.8", "0.00009"], ["83890.4", "0.000333"], ["83890", "0.05"], ["83889.9", "0.059399"]], "a": [["83969.8", "0.738765"], ["83970.6", "0.000999"], ["83972.5", "0.194506"], ["83972.6", "0.441035"], ["83974.3", "0.000333"], ["83976.1", "0.099641"], ["83976.2", "0.000524"], ["83976.3", "0.050035"], ["83976.7", "0.00432"], ["83976.8", "0.03"], ["83976.9", "0.191035"], ["83977", "0.001466"], ["83977.3", "0.05819"], ["83977.8", "0.001333"], ["83977.9", "0.003899"], ["83978.1", "0.07821"], ["83978.5", "0.000333"], ["83979", "0.074195"], ["83980", "0.079038"], ["83980.1", "0.125033"], ["83980.4", "0.00009"], ["83980.8", "0.001523"], ["83980.9", "0.00432"], ["83981", "0"], ["83981.1", "0.009493"], ["83981.6", "0.001466"], ["83981.7", "0"], ["83982", "0.001333"], ["83982.1", "0"], ["83982.2", "0"], ["83982.3", "0.070973"], ["83982.7", "0.000333"], ["83983.5", "0.04"], ["83984.6", "0.006166"], ["83985.1", "0.004321"], ["83985.3", "0.178904"], ["83985.4", "0.181185"], ["83985.6", "0"], ["83985.7", "0.17863"], ["83986.2", "0.002799"], ["83987.6", "0.024665"], ["83988.1", "0.0401"], ["83988.3", "0.299428"], ["83988.4", "0.153055"], ["83988.5", "0.02"], ["83988.8", "0.00009"], ["83989.4", "0.159091"], ["83989.6", "0.17863"], ["83989.8", "0"], ["83990.3", "0.119087"], ["83990.6", "0"], ["83990.7", "0"], ["83991", "0"], ["83991.1", "0.000333"], ["83991.2", "0"], ["83991.5", "0"], ["83991.6", "0"], ["83991.8", "0.036996"], ["83992.2", "0"], ["83992.9", "0.102953"], ["83993", "0.04"], ["83993.2", "0.04"], ["83993.6", "0"], ["83993.9", "0"], ["83994.3", "0"], ["83994.6", "0.041857"], ["83995.5", "0"], ["83997", "0"], ["83997.4", "0.534598"], ["83998", "0"], ["83998.3", "0"], ["83999.1", "0.04105"], ["83999.9", "0"], ["84000.1", "0.227506"], ["84000.7", "0"], ["84001.4", "0.118996"], ["84001.7", "0"], ["84002.2", "0.0006"], ["84002.5", "0"], ["84003.6", "0.005954"], ["84004.2", "0.011915"], ["84007.5", "0.118996"], ["84007.8", "0.057309"], ["84008.3", "0.148842"], ["84008.6", "0.207171"], ["84008.7", "0"], ["84009.5", "0"], ["84010.5", "0"], ["84011.4", "0.02515"], ["84011.5", "0.357488"], ["84011.6", "0"], ["84011.7", "1.427733"], ["84012.6", "0.011913"], ["84012.9", "0"], ["84013.5", "0"], ["84013.7", "0.118996"], ["84014", "0.00018"], ["84014.7", "0.022831"], ["84015.4", "0.573623"], ["84015.6", "0.001691"], ["84017.2", "0.023817"], ["84019.1", "0"], ["84020.5", "0.02344"], ["84021.8", "0.023816"], ["84023.5", "0"], ["84024.1", "0.43735"], ["84024.2", "0"], ["84025.9", "0"], ["84027.9", "0"], ["84029.2", "0.171"], ["84031", "0"], ["84031.6", "0.000524"], ["84031.8", "0"], ["84035.5", "0.004437"], ["84045.2", "0.04"], ["84045.5", "0"], ["84045.8", "0"], ["84046.2", "0"], ["84046.3", "0"], ["84047.4", "0"], ["84047.5", "0"], ["84047.6", "0"], ["84047.8", "0"], ["84048.1", "0"], ["84048.3", "0"], ["84048.4", "0"], ["84049.2", "0"], ["84049.4", "0"], ["84049.8", "0"], ["84050", "0"], ["84050.1", "0"], ["84050.5", "0"], ["84050.9", "0"], ["84051", "0"]], "u": 128808, "seq": 67571270810}, "cts": 1742577060716, "record_time": 1742577060.910292, "EXCHANGE": "BYBIT"}
{"topic": "orderbook.200.BTCUSDT", "ts": 1742577060919, "type": "delta", "data": {"s": "BTCUSDT", "b": [["83969.7", "0"], ["83966.8", "0.0003"], ["83965.9", "0.005749"], ["83965.6", "0.00178"], ["83965.5", "0.071492"], ["83965.3", "0"], ["83964.5", "0"], ["83963", "0.022997"], ["83961.3", "0"], ["83961", "0.021333"], ["83959.6", "0"], ["83959.1", "0.071497"], ["83958.8", "0.034498"], ["83957.9", "0.032727"], ["83957.7", "0.066778"], ["83957.4", "0"], ["83956.9", "0"], ["83956.3", "0.048"], ["83955.9", "0.005"], ["83955.4", "0.0715"], ["83954.3", "0.04"], ["83954", "0.044"], ["83953.8", "0"], ["83953.3", "0.124386"], ["83953.2", "0.118835"], ["83952.9", "0"], ["83952", "0"], ["83951.9", "0"], ["83951.1", "0.003768"], ["83950.9", "0.044"], ["83949.4", "0.101717"], ["83949.2", "0.048333"], ["83948.8", "0"], ["83947.7", "0.044"], ["83946.8", "0"], ["83944.9", "0.114054"], ["83943.9", "0.22086"], ["83943.7", "0.180664"], ["83942.3", "0"], ["83941.5", "0.019765"], ["83941.2", "0.118925"], ["83938.3", "0"], ["83937.4", "0"], ["83937.3", "0"], ["83935", "0.000514"], ["83934.9", "0"], ["83934.7", "0.044023"], ["83934.6", "0.040155"], ["83933.6", "0"], ["83932.3", "0.013"], ["83932.2", "0.012881"], ["83931.7", "0.001333"], ["83931.6", "0"], ["83929.5", "0.023816"], ["83929", "0.049548"], ["83928.9", "0.049548"], ["83928.8", "0.009225"], ["83925", "0.047638"], ["83922.5", "0.01848"], ["83920.2", "0.132837"], ["83919.8", "0.354066"], ["83918.3", "0.184723"], ["83916", "0.357566"], ["83911.6", "0"], ["83908.6", "0"], ["83903.3", "0.125045"], ["83901.5", "0.171"], ["83901.3", "0"], ["83893.1", "0.17152"], ["83890.4", "0"], ["83890", "0"], ["83889.9", "0"]], "a": [["83969.5", "0.499787"], ["83969.7", "0.39472"], ["83969.8", "0.312014"], ["83972.5", "0"], ["83972.6", "0.170035"], ["83972.9", "0.005729"], ["83973.6", "0.006167"], ["83974.2", "0.071484"], ["83976.1", "0.164294"], ["83976.5", "0.024667"], ["83976.9", "0.262517"], ["83978", "0.010505"], ["83980", "0.077703"], ["83980.7", "0.036999"], ["83981.4", "0.04"], ["83981.9", "0.009225"], ["83982.3", "0.051635"], ["83984", "0.039"], ["83984.4", "0.04"], ["83984.6", "0"], ["83984.7", "0.04"], ["83986.4", "0.04"], ["83986.8", "0.04"], ["83987.6", "0"], ["83988.3", "0.19138"], ["83988.4", "0.114054"], ["83989.4", "0.04"], ["83989.8", "0.04"], ["83990.3", "0"], ["83991.8", "0"], ["83992.9", "0.053235"], ["83993", "0"], ["83994.6", "0.001857"], ["83994.8", "0"], ["83994.9", "0.08"], ["83996.5", "0"], ["83996.6", "0"], ["83997.6", "0"], ["84000.1", "0.145925"], ["84001.2", "0"], ["84001.5", "0"], ["84001.6", "0"], ["84006.4", "0.089318"], ["84007.8", "0.057317"], ["84008.6", "0.522628"], ["84008.8", "0.013878"], ["84009.4", "0.295121"], ["84011.5", "1.427733"], ["84011.7", "0"], ["84013.6", "0.357485"], ["84014.7", "0"], ["84014.8", "0.235679"], ["84019", "0"], ["84024.1", "0"], ["84024.6", "0.0025"], ["84025.8", "0"], ["84035", "0"], ["84043.9", "0.016017"], ["84045", "0"], ["84045.2", "0"]], "u": 128809, "seq": 67571271324}, "cts": 1742577060917, "record_time": 1742577061.109087, "EXCHANGE": "BYBIT"}
{"topic": "orderbook.200.BTCUSDT", "ts": 1742577061120, "type": "delta", "data": {"s": "BTCUSDT", "b": [["83969.4", "0"], ["83968.3", "0"], ["83967.7", "0"], ["83966.9", "0"], ["83966.8", "0"], ["83966.3", "0.106896"], ["83965.9", "0"], ["83965.6", "0"], ["83965.5", "0.00178"], ["83963", "0"], ["83962.5", "0.005749"], ["83961.2", "0.086495"], ["83961", "0.172333"], ["83959.6", "0.022998"], ["83958.9", "0"], ["83958.8", "0"], ["83957.9", "0.052727"], ["83957.7", "0.076794"], ["83955.4", "0.034499"], ["83954.8", "0.044"], ["83954.5", "0.044"], ["83952.6", "0.057333"], ["83952.1", "0.023358"], ["83949.6", "0.080636"], ["83949.4", "0"], ["83947.6", "0.048"], ["83945", "0.13267"], ["83943.9", "0"], ["83934.7", "0.00439"], ["83934.6", "0.000522"], ["83934.2", "0.03963"], ["83934.1", "0.03963"], ["83934", "0.02268"], ["83932.3", "0"], ["83932.2", "0"], ["83931.8", "0.013"], ["83931.7", "0.014213"], ["83930.9", "0.004585"], ["83929", "0"], ["83928.9", "0"], ["83928.5", "0.05"], ["83928.4", "0.049544"], ["83923", "0.132838"], ["83920.2", "0"], ["83919.9", "0.306851"], ["83916", "0.357573"], ["83911.5", "7.8576"], ["83906.4", "0.178643"]], "a": [["83966.4", "0.817735"], ["83966.8", "0.105952"], ["83968.4", "0.005957"], ["83968.5", "0.071489"], ["83969.5", "0.274576"], ["83969.7", "0"], ["83969.8", "0.069373"], ["83970.7", "0.006167"], ["83971.6", "0.000524"], ["83972.3", "0.001466"], ["83972.5", "0.086395"], ["83973.6", "0.026001"], ["83976.5", "0"], ["83977.8", "0.078334"], ["83979.5", "0.04"], ["83980.1", "0.110836"], ["83980.7", "0"], ["83984.5", "0.04"], ["83985.3", "0.218904"], ["83988.3", "0.120226"], ["83989.4", "0"], ["83992.9", "0"], ["83993.1", "0.038396"], ["83994.9", "0.04"], ["83995.9", "0.064013"], ["84000.1", "0.001466"], ["84001.3", "0.084116"], ["84007.8", "0.057313"], ["84008.1", "2.612585"], ["84008.3", "1.576575"], ["84011.5", "0"], ["84013.5", "0.357487"], ["84013.6", "0"], ["84014.1", "0.015"], ["84018.1", "0.023644"], ["84025.7", "0"], ["84026.8", "0.011993"], ["84033.2", "0.02803"], ["84036.2", "0.012517"], ["84036.4", "0.113406"], ["84040.8", "0"], ["84040.9", "0"], ["84041.6", "0"], ["84041.7", "0"], ["84041.8", "0"], ["84042.1", "0"], ["84043.9", "0"], ["84044.3", "0"], ["84044.7", "0"]], "u": 128810, "seq": 67571271778}, "cts": 1742577061116, "record_time": 1742577061.309673, "EXCHANGE": "BYBIT"}
{"topic": "orderbook.200.BTCUSDT", "ts": 1742577061319, "type": "delta", "data": {"s": "BTCUSDT", "b": [["83955.9", "0.010544"], ["83938.3", "0.035735"], ["83928.3", "0.300756"], ["83916", "0.00009"], ["83913.6", "0.357488"], ["83906.4", "0"], ["83891", "0"], ["83890.8", "0"]], "a": [["83966.4", "0.883342"], ["83966.8", "0.071873"], ["83968.4", "0"], ["83968.5", "0"], ["83969", "0.000153"], ["83969.7", "0.071488"], ["83972.5", "0.063231"], ["83972.9", "0"], ["83974.2", "0"], ["83975.3", "0.071483"], ["83976", "0.059399"], ["83976.9", "0.191035"], ["83978.9", "0.07148"], ["83980.9", "0.090285"], ["83986.8", "0"], ["83989.8", "0"], ["83993.1", "0"], ["83993.2", "0"], ["83994.9", "0"], ["84004.8", "1.402683"], ["84008.6", "0"], ["84013.4", "0.35749"], ["84013.5", "0"], ["84032.6", "0"], ["84040.8", "0.001333"], ["84040.9", "0.000524"], ["84041.5", "0.011993"], ["84041.6", "0.018278"], ["84041.7", "0.001466"], ["84041.8", "0.011994"]], "u": 128811, "seq": 67571271904}, "cts": 1742577061308, "record_time": 1742577061.508537, "EXCHANGE": "BYBIT"}
{"topic": "orderbook.200.BTCUSDT", "ts": 1742577061520, "type": "delta", "data": {"s": "BTCUSDT", "b": [["83941.6", "0.178643"], ["83931.4", "0.063726"], ["83928.6", "0.073815"], ["83928.5", "0.049544"], ["83928.4", "0"], ["83923.2", "0.12505"], ["83923.1", "0.04729"], ["83923", "0.132843"], ["83920", "0.357532"], ["83919.9", "0"], ["83915.1", "0.178643"], ["83914", "0.178643"], ["83913.6", "0"], ["83909.8", "0.178643"], ["83902.2", "0.12505"], ["83892.8", "0"], ["83891.7", "0"], ["83891.5", "0"], ["83891.4", "0"]], "a": [["83966.4", "0.877385"], ["83966.8", "0.115993"], ["83969.4", "0.005957"], ["83969.5", "0.271"], ["83969.7", "0"], ["83970.9", "0.071487"], ["83974.8", "0.02"], ["83975.3", "0"], ["83976.2", "0.024828"], ["83977.1", "0.071482"], ["83984.4", "0.321793"], ["83984.5", "0.218643"], ["83985.3", "0.04"], ["83988.5", "0"], ["84007.8", "0.057315"], ["84008.1", "0"], ["84010.8", "2.612611"], ["84013.3", "0.393734"], ["84013.4", "0"], ["84014.8", "0"], ["84018.7", "0.361809"], ["84029.7", "0"], ["84042.1", "0.023805"]], "u": 128812, "seq": 67571272012}, "cts": 1742577061505, "record_time": 1742577061.708625, "EXCHANGE": "BYBIT"}
{"topic": "orderbook.200.BTCUSDT", "ts": 1742577061720, "type": "delta", "data": {"s": "BTCUSDT", "b": [["83966.3", "0.106881"], ["83934", "0.022798"], ["83928.6", "0.023815"], ["83928.4", "0.049544"], ["83923.3", "0.086139"], ["83923.1", "0"], ["83920", "0.00006"], ["83917.6", "0.178643"], ["83916", "0.357569"], ["83915.1", "0"]], "a": [["83966.4", "0.883342"], ["83969.4", "0"], ["83980.1", "0.080035"], ["83985.3", "0.043576"], ["84004", "0"], ["84004.8", "0.618908"], ["84013.3", "0"], ["84015.3", "0.357485"], ["84018.7", "0.004334"], ["84035.8", "1.028134"], ["84043.9", "0.016017"]], "u": 128813, "seq": 67571272119}, "cts": 1742577061715, "record_time": 1742577061.909253, "EXCHANGE": "BYBIT"}
{"topic": "orderbook.200.BTCUSDT", "ts": 1742577061919, "type": "delta", "data": {"s": "BTCUSDT", "b": [["83966.3", "0.107448"], ["83961", "0.001333"], ["83955.9", "0.005"], ["83952.1", "0"], ["83951.8", "0.117757"], ["83941.3", "0.178495"], ["83938.7", "0.019765"], ["83934.3", "0.304985"], ["83931.8", "0.01288"], ["83928.6", "0.073815"], ["83928.4", "0"], ["83923", "0.13285"], ["83916", "0.00009"], ["83914.1", "0.35749"], ["83911.5", "0.059942"], ["83893.4", "0"], ["83893.2", "0"], ["83893.1", "0"]], "a": [["83968.4", "0.000153"], ["83969", "0"], ["83969.8", "0.140861"], ["83970.9", "0"], ["83973.5", "0.005649"], ["83975.5", "0.071483"], ["83976.3", "0.166492"], ["83977.1", "0"], ["83986.8", "0.184893"], ["83988.8", "0.035826"], ["83993.8", "0.280969"], ["84010.7", "0.795002"], ["84013.6", "0.357489"], ["84015.3", "0"], ["84041.8", "0"], ["84042.1", "0"], ["84043.9", "0"]], "u": 128814, "seq": 67571272219}, "cts": 1742577061917, "record_time": 1742577062.134064, "EXCHANGE": "BYBIT"}
{"topic": "orderbook.200.BTCUSDT", "ts": 1742577062120, "type": "delta", "data": {"s": "BTCUSDT", "b": [["83945", "0.223269"], ["83939.1", "0.178643"], ["83928.6", "0.023815"], ["83928.4", "0.049544"], ["83923", "0.132847"], ["83916", "0.357573"], ["83914.1", "0"], ["83908.7", "7.854058"], ["83894.6", "0"], ["83893.9", "0"]], "a": [["83968.9", "0.071489"], ["83969.8", "0.069373"], ["83993.7", "0.085388"], ["84010.6", "0.04"], ["84010.7", "0.835002"], ["84013.6", "0"], ["84016.6", "0.357483"], ["84023.6", "0"], ["84023.7", "0"], ["84041.7", "0"]], "u": 128815, "seq": 67571272297}, "cts": 1742577062116, "record_time": 1742577062.311695, "EXCHANGE": "BYBIT"}
{"topic": "orderbook.200.BTCUSDT", "ts": 1742577062320, "type": "delta", "data": {"s": "BTCUSDT", "b": [["83939.2", "0.075558"], ["83938.7", "0"], ["83916", "0.00009"], ["83914.1", "0.357486"]], "a": [["84010.5", "0.04"], ["84010.7", "0.795002"], ["84015.3", "0.689619"], ["84016.6", "0"], ["84041.6", "0"]], "u": 128816, "seq": 67571272354}, "cts": 1742577062316, "record_time": 1742577062.508648, "EXCHANGE": "BYBIT"}
{"topic": "orderbook.200.BTCUSDT", "ts": 1742577062520, "type": "delta", "data": {"s": "BTCUSDT", "b": [["83966.3", "0"], ["83966", "0"], ["83965.5", "0"], ["83965.2", "0.011717"], ["83962.5", "0"], ["83961.4", "0.005749"], ["83961.2", "0.015"], ["83959.1", "0"], ["83958.3", "0.071498"], ["83957.9", "0.032727"], ["83957.7", "0.006477"], ["83956.8", "0.021333"], ["83956.4", "0.10106"], ["83956.2", "0.0715"], ["83954.5", "0.04965"], ["83951.8", "0"], ["83949.6", "0.104902"], ["83941.6", "0"], ["83941.3", "0"], ["83938.6", "0"], ["83938.3", "0"], ["83935.3", "0.337469"], ["83934.3", "0"], ["83934.2", "0"], ["83934.1", "0"], ["83933.3", "0.03963"], ["83933.2", "0.03963"], ["83931.8", "0"], ["83931.7", "0.001333"], ["83930.9", "0.017465"], ["83930.8", "0.014346"], ["83929.5", "0"], ["83929.3", "0.023819"], ["83928.5", "0"], ["83928.4", "0"], ["83927.6", "0.049544"], ["83927.5", "0.056831"], ["83923", "0.132848"], ["83920.2", "0.023819"], ["83919.9", "0.253202"], ["83917.6", "0"], ["83914.1", "0.357485"], ["83912.5", "0.178645"], ["83899.9", "0"], ["83894.6", "0.000333"], ["83893.9", "0.002799"], ["83893.4", "0.00036"], ["83893.2", "0.044"], ["83893.1", "0.00052"], ["83892.8", "0.004263"], ["83891.7", "0.118996"], ["83891.6", "0.224383"]], "a": [["83965.3", "0.576348"], ["83965.5", "0.131634"], ["83965.7", "0.264882"], ["83966.4", "0.230024"], ["83966.8", "0"], ["83968.4", "0"], ["83968.9", "0"], ["83969.5", "0.006167"], ["83970.2", "0.000333"], ["83970.7", "0"], ["83973.8", "0.071485"], ["83974.1", "0.02"], ["83974.8", "0"], ["83976.3", "0.050035"], ["83977.3", "0"], ["83978", "0"], ["83978.1", "0"], ["83978.9", "0"], ["83979.2", "0.04"], ["83979.7", "0.039001"], ["83980.8", "0.005099"], ["83981", "0.04"], ["83981.9", "0"], ["83984", "0"], ["83985.3", "0.04"], ["83986.8", "0"], ["83993.8", "0"], ["84007.2", "1.429066"], ["84008.1", "2.612611"], ["84008.3", "0.148842"], ["84010.8", "0"], ["84012.4", "0.023819"], ["84013.6", "0.357492"], ["84015.2", "0.431774"], ["84015.3", "0"], ["84041.6", "0.012326"], ["84041.7", "0.001466"]], "u": 128817, "seq": 67571272938}, "cts": 1742577062516, "record_time": 1742577062.707675, "EXCHANGE": "BYBIT"}
{"success": true, "ret_msg": "pong", "conn_id": "a40f0371-7187-42e8-8ca7-9acd5f2ba35c", "op": "ping", "record_time": 1742577062.818109, "EXCHANGE": "BYBIT"}
{"topic": "orderbook.200.BTCUSDT", "ts": 1742577062720, "type": "delta", "data": {"s": "BTCUSDT", "b": [["83965.2", "0"], ["83964.1", "0"], ["83963.1", "0"], ["83962.3", "0"], ["83961.8", "0"], ["83961.4", "0"], ["83959.6", "0"], ["83958.3", "0"], ["83958", "0"], ["83956.8", "0.001333"], ["83956.4", "0.022999"], ["83956.3", "0"], ["83956.2", "0"], ["83955.5", "0.0715"], ["83955.4", "0"], ["83954.8", "0"], ["83954.7", "0.005"], ["83954.5", "0.00565"], ["83954.3", "0"], ["83954", "0"], ["83953.6", "0.071502"], ["83953.2", "0"], ["83952.8", "0.015"], ["83952.7", "0.118996"], ["83952.6", "0.001333"], ["83952.2", "0.205501"], ["83950.9", "0"], ["83949.8", "0.011525"], ["83949.6", "0.062902"], ["83949.2", "0.000333"], ["83947.7", "0"], ["83947.6", "0"], ["83946.3", "0.044"], ["83945", "0.098454"], ["83944.9", "0"], ["83944.6", "0.049466"], ["83943.5", "0.02305"], ["83943", "0.044"], ["83936.6", "0.178978"], ["83934", "0.000118"], ["83933.3", "0"], ["83933.2", "0"], ["83931.2", "0.04"], ["83931.1", "0.039628"], ["83930.9", "0.004585"], ["83930.8", "0.001466"], ["83929.6", "0.143504"], ["83928.8", "0.022225"], ["83928.7", "0.012879"], ["83927.6", "0"], ["83927.5", "0.007287"], ["83925.5", "0.05"], ["83925.4", "0.050064"], ["83923", "0.132845"], ["83916", "0.357572"], ["83914.1", "0"], ["83908.7", "0"], ["83903.2", "7.854058"], ["83898", "1.786453"], ["83893.1", "0.17152"], ["83891.6", "0"], ["83891.5", "0.044"], ["83891.4", "0.12"], ["83891", "0.04"], ["83890.8", "0.00009"], ["83890.4", "0.000333"], ["83889.9", "0.059399"], ["83889.7", "0.001333"], ["83889.3", "0.001466"], ["83889", "0.000204"], ["83888.6", "0.004263"], ["83888.5", "0.224903"]], "a": [["83961.3", "0.667309"], ["83961.8", "0.003576"], ["83963", "0.005958"], ["83963.1", "0.184358"], ["83963.2", "0.171"], ["83965.2", "0.026365"], ["83965.3", "0.189803"], ["83965.5", "0"], ["83965.7", "0.034232"], ["83966", "0.000333"], ["83966.4", "0.221035"], ["83966.9", "0.000523"], ["83967.7", "0.001466"], ["83968", "0.006167"], ["83968.3", "0.004314"], ["83969.4", "0.001333"], ["83969.5", "0"], ["83969.6", "0.042658"], ["83969.7", "0.071488"], ["83970.9", "0.024669"], ["83971.8", "0.071486"], ["83972", "0.00009"], ["83972.5", "0.101297"], ["83973.6", "0.079543"], ["83973.8", "0"], ["83975.1", "0.037001"], ["83975.5", "0"], ["83976.1", "0.099641"], ["83977.8", "0.041333"], ["83979", "0"], ["83980.8", "0.001523"], ["83983.5", "0"], ["83985.3", "0"], ["83991.8", "0.04102"], ["83993.7", "0"], ["84003.2", "1.427733"], ["84004.8", "1.345038"], ["84007.2", "0.001333"], ["84009.3", "0.133666"], ["84010.7", "0"], ["84013.5", "0.393734"], ["84013.6", "0.024986"], ["84014.8", "0.357486"], ["84015.2", "0"], ["84018.1", "0"], ["84032.5", "1.786453"], ["84035.8", "0"], ["84039.1", "0"], ["84039.2", "0"], ["84039.3", "0"], ["84039.4", "0"], ["84039.7", "0"], ["84040", "0"], ["84040.8", "0"], ["84040.9", "0"], ["84041.5", "0"], ["84041.6", "0"], ["84041.7", "0"]], "u": 128818, "seq": 67571273597}, "cts": 1742577062716, "record_time": 1742577062.909806, "EXCHANGE": "BYBIT"}
{"topic": "orderbook.200.BTCUSDT", "ts": 1742577062919, "type": "delta", "data": {"s": "BTCUSDT", "b": [["83961.2", "0"], ["83959", "0.071497"], ["83958.4", "0"], ["83957.9", "0"], ["83957.4", "0.005749"], ["83955.5", "0"], ["83954.7", "0"], ["83953.6", "0"], ["83953.3", "0"], ["83952.8", "0.02"], ["83952.7", "0"], ["83950.9", "0.071504"], ["83950.1", "0.032733"], ["83950", "0.044"], ["83949.8", "0"], ["83949.7", "0.04"], ["83949.6", "0.063818"], ["83948.3", "0.048"], ["83948", "0.056"], ["83946.9", "0.044"], ["83945.2", "0.044"], ["83945", "0.188104"], ["83942.9", "0.048"], ["83941", "0.001115"], ["83939.1", "0"], ["83937.8", "0.178704"], ["83935.9", "0.001333"], ["83935.6", "0.035736"], ["83935.3", "0.238799"], ["83931.4", "0.094889"], ["83931.2", "0"], ["83931.1", "0"], ["83928.8", "0"], ["83928.7", "0.03963"], ["83928.6", "0.063445"], ["83927.5", "0.001333"], ["83926.3", "0.01288"], ["83926.2", "0.014346"], ["83925.5", "0"], ["83925.4", "0.000522"], ["83925", "0.02382"], ["83923", "0.049545"], ["83922.9", "0.049545"], ["83919.9", "0.262427"], ["83917.4", "0.132845"], ["83916", "0.00009"], ["83915.8", "0.095054"], ["83914", "0"], ["83913.8", "0.004265"], ["83912.6", "0.393054"], ["83912.5", "0"], ["83910.4", "0"], ["83909.8", "0"], ["83908.3", "0"], ["83907.5", "0"], ["83903.2", "0"], ["83901.4", "0"], ["83897.7", "7.922719"], ["83888.1", "0.04"], ["83886.2", "0.000333"], ["83886", "0.027854"], ["83885.5", "0.001333"], ["83885", "0.000333"]], "a": [["83961.1", "0.221297"], ["83961.3", "0.752177"], ["83961.8", "0"], ["83963", "0"], ["83963.1", "0"], ["83965.1", "0.006167"], ["83965.2", "0"], ["83965.3", "0.13"], ["83967.8", "0.000999"], ["83968", "0.024669"], ["83968.8", "0.05819"], ["83969.6", "0.059584"], ["83969.7", "0"], ["83969.9", "0.071488"], ["83970.5", "0.074195"], ["83970.9", "0"], ["83972.2", "0.037002"], ["83973.5", "0.045649"], ["83975.1", "0"], ["83980.1", "0.020035"], ["83980.9", "0.00432"], ["83981.1", "0.013069"], ["83995.9", "0.183009"], ["83999.1", "0"], ["84001.3", "0.491203"], ["84004.8", "0.618908"], ["84005.3", "2.612611"], ["84008.1", "0"], ["84010.3", "0.027162"], ["84013.4", "0.357499"], ["84014.8", "0"], ["84037.6", "0.232638"], ["84039.2", "0.059489"]], "u": 128819, "seq": 67571274257}, "cts": 1742577062917, "record_time": 1742577063.109561, "EXCHANGE": "BYBIT"}
{"topic": "orderbook.200.BTCUSDT", "ts": 1742577063120, "type": "delta", "data": {"s": "BTCUSDT", "b": [["83961", "0"], ["83960", "0"], ["83959.9", "0"], ["83959.7", "0"], ["83959", "0"], ["83958.5", "0"], ["83957.7", "0.113593"], ["83957.4", "0"], ["83956.4", "0"], ["83954.5", "0"], ["83953.9", "0.007216"], ["83952.8", "0"], ["83952.3", "0.023001"], ["83952.2", "0.174"], ["83951.5", "0.075901"], ["83950.9", "0"], ["83949.6", "0.125116"], ["83949.3", "0.021466"], ["83948.9", "0.071506"], ["83948.1", "0.034503"], ["83947.4", "0"], ["83943.7", "0.171"], ["83941", "0"], ["83937.8", "0"], ["83937.6", "0.001487"], ["83936.6", "0.000333"], ["83935.6", "0"], ["83932", "0"], ["83929", "0.178661"], ["83928.7", "0"], ["83928.6", "0.023815"], ["83926.3", "0"], ["83926.2", "0.001466"], ["83925.8", "0.04"], ["83925.7", "0.03963"], ["83923.4", "0.013"], ["83923.3", "0.099019"], ["83923", "0"], ["83922.9", "0"], ["83920.1", "0.05"], ["83920", "0.049604"], ["83919.2", "0.02382"], ["83917.4", "0"], ["83915.9", "0.244882"], ["83912.6", "0.035555"], ["83911.7", "0.132852"], ["83903.8", "0.357524"], ["83903.3", "0"], ["83903", "0.000333"], ["83901.4", "0.17866"], ["83900", "0.001904"], ["83897.7", "0.00052"], ["83892.1", "7.922199"], ["83891.4", "0"], ["83885.1", "0.118996"], ["83884.9", "0.206497"], ["83884.6", "0.001466"], ["83884.4", "0.004263"], ["83883.8", "0.00052"], ["83882.4", "0.00018"], ["83882.3", "0.125058"], ["83882", "0.000333"], ["83881.8", "0.005885"], ["83881.4", "0.05"]], "a": [["83957.8", "0.787506"], ["83958.3", "0.003576"], ["83958.4", "0.130843"], ["83958.6", "0.324035"], ["83959.1", "0.020035"], ["83959.7", "0.000153"], ["83960.8", "0.071496"], ["83961.1", "0.014197"], ["83961.3", "0.050035"], ["83961.6", "0.006167"], ["83962.3", "0.000522"], ["83963.1", "0.001466"], ["83963.2", "0"], ["83964.1", "0.004314"], ["83964.5", "0.02467"], ["83965.1", "0"], ["83965.2", "0.001333"], ["83965.3", "0.03"], ["83965.4", "0.113704"], ["83965.5", "0.059399"], ["83965.7", "0.020035"], ["83966.1", "0.07821"], ["83968", "0.084068"], ["83968.1", "0.07149"], ["83968.7", "0.046496"], ["83969.6", "0"], ["83969.9", "0"], ["83971.2", "0.071487"], ["83971.8", "0"], ["83972.1", "0.136041"], ["83972.2", "0"], ["83972.5", "0.00432"], ["83973.6", "0.001333"], ["83973.8", "0.08"], ["83974.4", "0.125081"], ["83975.4", "0.079001"], ["83976.9", "0.231035"], ["83977.1", "0.04"], ["83979.7", "0"], ["83980", "0.055501"], ["83980.6", "0.178659"], ["83981.1", "0"], ["83981.2", "0.17866"], ["83981.4", "0"], ["83984.3", "0.04103"], ["83984.5", "0.04"], ["83984.7", "0"], ["83985.7", "0"], ["83986.1", "0.125061"], ["83987.1", "0.171"], ["83989.6", "0"], ["83991.7", "0.014702"], ["83993.5", "0.004689"], ["83997.1", "0.573623"], ["83999.7", "1.427733"], ["84002.1", "0.051358"], ["84003.1", "0.357524"], ["84003.2", "0"], ["84004.8", "0.916718"], ["84005.3", "0"], ["84007.1", "0.125061"], ["84007.8", "0.005954"], ["84011.2", "0.015"], ["84013.4", "0"], ["84013.5", "0"], ["84015.4", "0"], ["84016.4", "2.61277"], ["84029.4", "0"], ["84031.6", "0"], ["84032.4", "0"], ["84032.5", "0"], ["84033.2", "0"], ["84034.1", "0"], ["84035.5", "0"], ["84036.2", "0"], ["84036.3", "0"], ["84036.4", "0"], ["84036.6", "0"], ["84037", "0"], ["84037.4", "0"], ["84037.6", "0"], ["84037.7", "0"], ["84037.9", "0"], ["84038.7", "0"], ["84039", "0"], ["84039.2", "0"]], "u": 128820, "seq": 67571275246}, "cts": 1742577063116, "record_time": 1742577063.310002, "EXCHANGE": "BYBIT"}
{"topic": "orderbook.200.BTCUSDT", "ts": 1742577063320, "type": "delta", "data": {"s": "BTCUSDT", "b": [["83951.1", "0"], ["83943.2", "0.003768"], ["83940.2", "0"], ["83939.2", "0.000522"], ["83937.6", "0.001474"], ["83937.1", "0.114059"], ["83936.5", "0.009664"], ["83935.4", "0.060865"], ["83931.7", "0.004908"], ["83931", "0.035738"], ["83923.3", "0.014213"], ["83915.9", "0.137632"], ["83914.6", "0.132852"], ["83911.7", "0"], ["83907", "0.357513"], ["83903.8", "0"], ["83902.5", "0.178661"], ["83900.4", "7.922199"], ["83897.2", "0.178661"], ["83892.1", "0"], ["83884.7", "0.171"], ["83882.4", "0"], ["83882.3", "0"], ["83882", "0"], ["83881.8", "0"], ["83881.4", "0"]], "a": [["83957.8", "0.758246"], ["83958.3", "0"], ["83958.6", "0.294035"], ["83959.1", "0.020188"], ["83959.7", "0"], ["83960.8", "0"], ["83961.8", "0.071495"], ["83966.2", "0.02"], ["83968.1", "0"], ["83968.8", "0.067415"], ["83970.3", "0.04"], ["83972", "0.186555"], ["83972.1", "0.04"], ["83973.1", "0.071485"], ["83974.1", "0"], ["83975.6", "0.04"], ["83977.8", "0.001333"], ["83979.2", "0"], ["83979.5", "0"], ["83981", "0"], ["83984.4", "0"], ["83984.5", "0"], ["83986.4", "0"], ["83988.1", "0.0001"], ["83988.3", "0"], ["83996", "0.793855"], ["83998.8", "0.212528"], ["84001.3", "0.084116"], ["84003.1", "0"], ["84004.8", "0.29781"], ["84006.3", "0.357517"], ["84010.8", "2.612434"], ["84016.4", "0"], ["84031.6", "0.000524"], ["84032.4", "0.014793"], ["84032.5", "1.786453"], ["84033.1", "0.011994"], ["84033.2", "0.02803"], ["84034.1", "0.023813"], ["84035.5", "0.004437"]], "u": 128821, "seq": 67571275463}, "cts": 1742577063317, "record_time": 1742577063.510147, "EXCHANGE": "BYBIT"}
{"topic": "orderbook.200.BTCUSDT", "ts": 1742577063519, "type": "delta", "data": {"s": "BTCUSDT", "b": [["83957.7", "0.384193"], ["83952.9", "0.0018"], ["83952.3", "0.133018"], ["83949.8", "0.118996"], ["83947.3", "0.009952"], ["83947", "0.009225"], ["83941.3", "0.023842"], ["83937.6", "0.180178"], ["83937.2", "0.035983"], ["83935.2", "0.468496"], ["83935", "0.179175"], ["83930.8", "0.180127"], ["83929", "0"], ["83924.2", "0.0016"], ["83923.3", "0.066312"], ["83920.5", "0.05"], ["83920.4", "0.049544"], ["83920.1", "0"], ["83920", "0.00006"], ["83919.9", "0.253202"], ["83911.6", "0.357503"], ["83907", "0"], ["83903.2", "7.922199"], ["83901.4", "0"], ["83900.4", "0"], ["83897.2", "0"], ["83885.6", "0.550578"], ["83884.7", "0"], ["83884.6", "0"], ["83884.4", "0"], ["83883.8", "0"]], "a": [["83957.8", "0.247327"], ["83958.4", "0.03185"], ["83958.6", "0.1"], ["83959.1", "0"], ["83961.1", "0"], ["83961.3", "0"], ["83961.4", "0.005957"], ["83961.8", "0"], ["83965.3", "0"], ["83965.4", "0.080863"], ["83965.5", "0"], ["83965.7", "0"], ["83966.4", "0.171"], ["83969.8", "0.019338"], ["83971.2", "0"], ["83973.1", "0"], ["83974.4", "0"], ["83975.6", "0.112902"], ["83985.3", "0.161933"], ["83987.3", "0.125063"], ["83995.9", "0.064013"], ["84002.5", "2.612434"], ["84006.3", "0"], ["84009.2", "0.357503"], ["84010.3", "0.004331"], ["84010.8", "0"], ["84036.2", "0.012517"], ["84036.3", "0.011993"], ["84036.4", "0.113406"], ["84036.6", "0.001333"], ["84037", "0.001466"], ["84037.4", "0.000333"], ["84037.6", "0.061638"]], "u": 128822, "seq": 67571275634}, "cts": 1742577063517, "record_time": 1742577063.709325, "EXCHANGE": "BYBIT"}
{"topic": "orderbook.200.BTCUSDT", "ts": 1742577063719, "type": "delta", "data": {"s": "BTCUSDT", "b": [["83957.7", "0.230949"], ["83941.6", "0.178696"], ["83940", "0.136014"], ["83939.9", "0.180484"], ["83939.1", "0.178661"], ["83937.2", "0"], ["83923.3", "0.089663"], ["83920.7", "0.05"], ["83920.6", "0.049543"], ["83920.5", "0"], ["83920.4", "0"], ["83920.2", "0.15668"], ["83914.6", "0"], ["83913.6", "0.357491"], ["83911.7", "0.210719"], ["83911.6", "0"], ["83908.7", "7.922199"], ["83903.2", "0"], ["83902.5", "0"], ["83899.5", "3.660263"], ["83886.3", "0.550538"], ["83885.6", "0"]], "a": [["83957.8", "0.32993"], ["83958.4", "0"], ["83958.5", "0.03185"], ["83961.4", "0"], ["83961.5", "0.005957"], ["83968.7", "0.037003"], ["83968.8", "0.05819"], ["83972", "0.143031"], ["83972.4", "0.009225"], ["83972.6", "0.140035"], ["83973.7", "0.071485"], ["83975.5", "0.167865"], ["83975.6", "0.04"], ["83975.8", "0.071483"], ["83976.1", "0.009493"], ["83980", "0.124684"], ["83981.9", "0.178661"], ["84009.2", "0"], ["84013.6", "0.382477"], ["84020.5", "0.000333"], ["84036.6", "0"], ["84037", "0"], ["84037.4", "0"], ["84037.6", "0"]], "u": 128823, "seq": 67571275845}, "cts": 1742577063718, "record_time": 1742577063.908766, "EXCHANGE": "BYBIT"}
{"topic": "orderbook.200.BTCUSDT", "ts": 1742577063920, "type": "delta", "data": {"s": "BTCUSDT", "b": [["83957.7", "0.187868"], ["83952.2", "0.171"], ["83945.8", "0.0003"], ["83944.5", "0.035108"], ["83939.1", "0"], ["83936.3", "0"], ["83935.2", "0.289835"], ["83935", "0.000514"], ["83934.1", "0.178661"], ["83930.8", "0.001466"], ["83927.6", "0.011916"], ["83927.3", "0"], ["83923.3", "0.126602"], ["83920.7", "0"], ["83920.6", "0.295434"], ["83920.4", "0.049544"], ["83920.3", "0.049544"], ["83920.2", "0"], ["83917.4", "0.132861"], ["83916.8", "0.023821"], ["83913.6", "0"], ["83911.8", "0.381314"], ["83908.7", "0"], ["83903.3", "0.125063"], ["83900.4", "8.246834"], ["83887", "1.182221"], ["83886", "0"], ["83885.5", "0"], ["83885.1", "0"], ["83885", "0"], ["83884.9", "0"]], "a": [["83958.4", "0.005957"], ["83960.4", "0.000153"], ["83961", "0.000999"], ["83961.5", "0"], ["83964.9", "0.071492"], ["83971.9", "0.071486"], ["83973.7", "0"], ["83988.3", "0.047358"], ["83991.8", "0"], ["83995.9", "0.183009"], ["84004.9", "0.023821"], ["84006", "0.000118"], ["84012.6", "0"], ["84028", "0"], ["84028.1", "1.028228"], ["84035.5", "0"], ["84036.2", "0"], ["84036.3", "0"], ["84036.4", "0"]], "u": 128824, "seq": 67571276080}, "cts": 1742577063916, "record_time": 1742577064.109948, "EXCHANGE": "BYBIT"}
{"topic": "orderbook.200.BTCUSDT", "ts": 1742577064120, "type": "delta", "data": {"s": "BTCUSDT", "b": [["83957.7", "0.206353"], ["83947", "0"], ["83945.8", "0"], ["83944.5", "0"], ["83943.7", "0.180225"], ["83939.3", "0.061822"], ["83932.3", "0.057066"], ["83925.3", "0.115197"], ["83920.4", "0"], ["83920.2", "0.049544"], ["83915.9", "0.242247"], ["83911.8", "0.023821"], ["83911.7", "0"], ["83907.5", "0.178661"], ["83907", "0.35751"], ["83905.6", "0.178661"], ["83903.2", "8.246834"], ["83901.4", "0.178661"], ["83900.4", "0"], ["83887", "0"], ["83886.3", "0"], ["83886.2", "0"]], "a": [["83957.8", "0.506887"], ["83958.4", "0"], ["83960.4", "0"], ["83960.5", "0.000153"], ["83964", "0.071493"], ["83964.9", "0"], ["83974.3", "0.059466"], ["83975.8", "0.073043"], ["83981.3", "0.061444"], ["83988.3", "0.171758"], ["83991.7", "0"], ["84001.3", "0.86202"], ["84009.2", "0.35751"], ["84013.6", "0.024986"]], "u": 128825, "seq": 67571276154}, "cts": 1742577064112, "record_time": 1742577064.30936, "EXCHANGE": "BYBIT"}
{"topic": "orderbook.200.BTCUSDT", "ts": 1742577064320, "type": "delta", "data": {"s": "BTCUSDT", "b": [["83957.7", "0.206592"], ["83941.6", "0"], ["83940", "0.093959"], ["83939.9", "0.001785"], ["83939.3", "0"], ["83938.5", "0.178702"], ["83936.8", "0.178706"], ["83935.2", "0.468496"], ["83935", "0.179175"], ["83934.1", "0"], ["83932.3", "0"], ["83930.8", "0.180127"], ["83926", "0.04"], ["83925.9", "0.03963"], ["83925.8", "0"], ["83925.7", "0"], ["83925.3", "0"], ["83923.6", "0.013"], ["83923.5", "0.01288"], ["83923.4", "0"], ["83923.3", "0.113722"], ["83915.9", "0.137632"], ["83911.6", "0.357496"], ["83907.5", "0"], ["83907", "0"], ["83906", "8.270562"], ["83905.6", "0"], ["83903.2", "0"], ["83901.4", "0"], ["83887", "1.182221"], ["83886.2", "0.000333"], ["83886", "0.027854"], ["83885.5", "0.001333"], ["83885.1", "0.118996"], ["83885", "0.000333"]], "a": [["83957.8", "0.33233"], ["83958.4", "0.005958"], ["83960.5", "0"], ["83960.6", "0.000153"], ["83971.5", "0.001235"], ["83974.3", "0.000333"], ["83975.8", "0.071483"], ["83980", "0.188068"], ["83981.3", "0"], ["83982.3", "0.050035"], ["83988.3", "0.047358"], ["84004.1", "0.04"], ["84004.2", "0.051915"], ["84009.2", "0"], ["84010.5", "0"], ["84010.6", "0"], ["84013.6", "0.382489"], ["84035.5", "0.004437"]], "u": 128826, "seq": 67571276241}, "cts": 1742577064312, "record_time": 1742577064.509094, "EXCHANGE": "BYBIT"}
{"topic": "orderbook.200.BTCUSDT", "ts": 1742577064520, "type": "delta", "data": {"s": "BTCUSDT", "b": [["83957.7", "0.172284"], ["83944.1", "0.05"], ["83943.9", "0.109334"], ["83940", "0.136015"], ["83939.1", "0.178661"], ["83937.6", "0.180173"], ["83934.1", "0.167271"], ["83926.1", "0.04"], ["83926", "0.039629"], ["83925.9", "0"], ["83925", "0.325379"], ["83924.3", "0.125063"], ["83923.7", "0.013"], ["83923.6", "0.01288"], ["83923.5", "0"], ["83920.4", "0.05"], ["83920.2", "0"], ["83913.6", "0.357491"], ["83911.6", "0"], ["83901.4", "0.089331"], ["83887", "0"], ["83886.2", "0"], ["83886", "0"], ["83885.5", "0"], ["83885.1", "0"], ["83885", "0"]], "a": [["83957.8", "0.333115"], ["83958.4", "0"], ["83961.5", "0.005958"], ["83964", "0"], ["83965.6", "0.071492"], ["83969.1", "0.112078"], ["83971.5", "0"], ["83971.9", "0"], ["83973.2", "0.001337"], ["83973.9", "0.071485"], ["83978.9", "0.186063"], ["83988", "0.280687"], ["84004.1", "0"], ["84004.2", "0.011915"], ["84004.4", "0.04"], ["84004.5", "0.04"], ["84013.6", "0.382477"], ["84027.7", "0.353757"], ["84032.5", "0"], ["84033.1", "0"], ["84033.2", "0"], ["84034.1", "0"], ["84035.5", "0"]], "u": 128827, "seq": 67571276296}, "cts": 1742577064510, "record_time": 1742577064.708832, "EXCHANGE": "BYBIT"}
{"topic": "orderbook.200.BTCUSDT", "ts": 1742577064719, "type": "delta", "data": {"s": "BTCUSDT", "b": [["83923.8", "0.184611"], ["83923.7", "0.01288"], ["83923.6", "0"], ["83923.3", "0.001333"], ["83913.6", "0"], ["83911.6", "0.357496"], ["83906", "0.023728"], ["83903.2", "8.246834"], ["83888.1", "0"]], "a": [["83959.9", "0.000153"], ["83960.6", "0"], ["83965.4", "0.152355"], ["83965.6", "0"], ["83970.6", "0"], ["83973.2", "0"], ["83980.8", "0.000524"], ["83987.9", "0.131594"], ["83988.3", "0"], ["84032.5", "1.786453"], ["84033.1", "0.011994"], ["84033.2", "0.02803"]], "u": 128828, "seq": 67571276344}, "cts": 1742577064718, "record_time": 1742577064.908451, "EXCHANGE": "BYBIT"}
{"success": true, "ret_msg": "subscribe", "conn_id": "cfa0e6f6-b68f-47fa-88c0-833d35eb70cc", "op": "subscribe", "record_time": 1742577141.87774, "EXCHANGE": "BYBIT"}
{"topic": "orderbook.200.BTCUSDT", "ts": 1742577140320, "type": "snapshot", "data": {"s": "BTCUSDT", "b": [["83943", "0.153272"], ["83942.4", "0.071511"], ["83942.3", "0.0006"], ["83940.6", "0.0002"], ["83940", "0.00006"], ["83938.6", "0.005736"], ["83936.6", "0.000333"], ["83935.9", "0.001333"], ["83935.7", "0.001"], ["83935.6", "0.022946"], ["83935.4", "0.001466"], ["83935.3", "0.004079"], ["83935.2", "0.071816"], ["83935.1", "0.140506"], ["83934.7", "0.046632"], ["83934.6", "0.191522"], ["83934.5", "0.12"], ["83933.9", "0.057255"], ["83933", "0.052855"], ["83932.8", "0.00009"], ["83932.4", "0.071853"], ["83932.3", "0.000595"], ["83931.7", "0.001333"], ["83931.6", "0.086201"], ["83931.4", "0.034421"], ["83930.8", "0.001466"], ["83930.6", "0.004391"], ["83930.5", "0.026886"], ["83930.3", "0.056"], ["83930", "0.000522"], ["83929.9", "0.019965"], ["83929.4", "0.023634"], ["83929.3", "0.019965"], ["83929.2", "0.044361"], ["83929", "0.166744"], ["83928.6", "0.043803"], ["83928.3", "0.044"], ["83928.2", "0.000333"], ["83928", "0.04"], ["83927.5", "0.001333"], ["83926.7", "0.147627"], ["83926.6", "0.162037"], ["83926.4", "0.004387"], ["83926.2", "0.001466"], ["83926.1", "0.220965"], ["83925.4", "0.000522"], ["83925.3", "0.048"], ["83925.2", "0.009623"], ["83925.1", "0.001"], ["83924.8", "0.178731"], ["83924.6", "0.044"], ["83924.4", "0.00009"], ["83924", "0.274434"], ["83923.9", "0.049965"], ["83923.3", "0.045333"], ["83922.9", "0.06797"], ["83922.8", "0.178736"], ["83922.3", "0.214438"], ["83922.2", "0.004387"], ["83922.1", "0.049965"], ["83921.6", "0.001466"], ["83921.5", "0.093965"], ["83921.1", "0.357432"], ["83920.8", "0.001122"], ["83920", "0.00006"], ["83919.8", "0.000333"], ["83919.5", "0.376452"], ["83919.4", "0.178693"], ["83919.2", "0.173181"], ["83919.1", "0.001333"], ["83918", "0.004387"], ["83917.5", "0.062974"], ["83917.4", "0.569453"], ["83916.9", "0.180159"], ["83916.8", "0.190965"], ["83916.1", "0.000522"], ["83916", "0.294238"], ["83915.9", "0.52949"], ["83915.7", "0.003"], ["83915.6", "0.000333"], ["83915.3", "0.059577"], ["83915.2", "0.250195"], ["83914.9", "0.001333"], ["83913.8", "0.004377"], ["83913.1", "0.039628"], ["83913", "0.041128"], ["83912.3", "0.001466"], ["83912.2", "0.049965"], ["83911.8", "0.261754"], ["83911.5", "0.000522"], ["83911.4", "0.000333"], ["83911.1", "0.295467"], ["83910.7", "0.001333"], ["83910.6", "0.062844"], ["83910.5", "0.012879"], ["83910.4", "0.059577"], ["83910.1", "0.298893"], ["83909.6", "0.004377"], ["83909.1", "0.019965"], ["83908.8", "0.0264"], ["83908.5", "0.019965"], ["83908.1", "0.072191"], ["83908", "0.10894"], ["83907.9", "0.118996"], ["83907.7", "0.001466"], ["83907.6", "0.020055"], ["83907.5", "0.009533"], ["83907.2", "0.000333"], ["83907.1", "0.019965"], ["83906.9", "0.000522"], ["83906.8", "0.171"], ["83906.5", "0.001333"], ["83906.4", "0.019965"], ["83906.2", "0.011919"], ["83906.1", "0.132859"], ["83905.4", "0.004376"], ["83904.4", "0.089346"], ["83903.8", "0.125103"], ["83903.6", "0.03"], ["83903.1", "0.001466"], ["83903", "0.000333"], ["83902.3", "0.001855"], ["83901.2", "0.004376"], ["83900", "0.00006"], ["83899.9", "0.002386"], ["83899.2", "0.009315"], ["83899", "0.118996"], ["83898.8", "0.000333"], ["83898.5", "0.001466"], ["83898.1", "0.175908"], ["83897.8", "0.01192"], ["83897.7", "0.000522"], ["83897", "0.000332"], ["83896.9", "0.014086"], ["83896.6", "0.125118"], ["83894.9", "0.080396"], ["83894.8", "0.059399"], ["83894.6", "0.000333"], ["83893.9", "0.002799"], ["83893.4", "0.000358"], ["83893.2", "0.357566"], ["83893.1", "0.119516"], ["83892.8", "0.004263"], ["83892.1", "5.551497"], ["83892", "0.023831"], ["83890.8", "0.00009"], ["83890.4", "0.000333"], ["83890.3", "0.023831"], ["83889.7", "0.001333"], ["83889.3", "0.001466"], ["83889", "0.02403"], ["83888.6", "0.060263"], ["83888.5", "0.00052"], ["83887.7", "0.118996"], ["83887.3", "0.044"], ["83887.2", "0.023831"], ["83887", "0.000118"], ["83886.2", "0.024164"], ["83885.7", "0.089099"], ["83885.6", "0.059399"], ["83885.5", "0.001333"], ["83885", "0.000333"], ["83884.8", "0.048"], ["83884.7", "0.171"], ["83884.6", "0.001466"], ["83884.4", "0.004263"], ["83883.8", "0.00052"], ["83883.5", "0.048"], ["83883.4", "0.089369"], ["83882.9", "0.125144"], ["83882.7", "0.049957"], ["83882.6", "0.118996"], ["83882.5", "0.01936"], ["83882.4", "0.00018"], ["83882", "0.000333"], ["83881.8", "0.005885"], ["83881.3", "0.001333"], ["83881.2", "0.023831"], ["83881", "0.048"], ["83880.2", "0.004263"], ["83880", "0.155893"], ["83879.7", "0.044"], ["83879.2", "0.00052"], ["83877.8", "0.012328"], ["83877.7", "0.023837"], ["83877.1", "0.060732"], ["83877", "0.044"], ["83876.5", "0.04"], ["83876.4", "0.118996"], ["83876.3", "0.171"], ["83876.1", "0.027396"], ["83876", "0.004263"], ["83875.8", "0.000149"], ["83875.6", "0.125144"], ["83875.4", "0.001466"], ["83875.3", "0.059594"], ["83875.2", "0.023837"], ["83874.7", "0.011995"], ["83874.6", "0.00302"], ["83874", "0.011968"]], "a": [["83943.1", "0.388309"], ["83943.8", "0.001805"], ["83944.3", "0.001333"], ["83944.6", "0.023019"], ["83944.7", "0.07151"], ["83945", "0.000333"], ["83945.8", "0.005958"], ["83945.9", "0.006185"], ["83947.3", "0.004403"], ["83948.4", "0.001333"], ["83948.5", "0.000522"], ["83948.9", "0.024739"], ["83949.2", "0.000333"], ["83949.3", "0.001824"], ["83949.8", "0.005225"], ["83950.3", "0.103346"], ["83950.4", "0.035555"], ["83951.4", "0.0006"], ["83951.5", "0.024403"], ["83951.6", "0.171"], ["83951.7", "0.003"], ["83952.6", "0.001333"], ["83953.1", "0.037628"], ["83953.4", "0.000333"], ["83953.5", "0.0003"], ["83953.8", "0.084175"], ["83953.9", "0.001466"], ["83954.2", "0.1186"], ["83954.3", "0.02413"], ["83955", "0.039963"], ["83955.2", "0.00009"], ["83955.5", "0.0715"], ["83955.7", "0.004405"], ["83955.9", "0.005"], ["83956.8", "0.001333"], ["83957.5", "0.04"], ["83957.6", "0.111831"], ["83957.7", "0.000522"], ["83958.5", "0.001466"], ["83958.7", "0.162101"], ["83958.8", "0.059399"], ["83958.9", "0.0012"], ["83959.1", "0.04"], ["83959.3", "0.04"], ["83959.4", "0.007116"], ["83959.9", "0.004309"], ["83960", "0.00024"], ["83960.8", "0.04"], ["83960.9", "0.04"], ["83961", "0.172333"], ["83961.2", "0.018849"], ["83961.8", "0.000333"], ["83961.9", "0.018984"], ["83962.2", "0.178693"], ["83962.3", "0.000522"], ["83962.4", "0.187087"], ["83962.5", "0.292738"], ["83962.6", "0.04"], ["83963.1", "0.180159"], ["83963.6", "0.00009"], ["83964", "0.22289"], ["83964.1", "0.004314"], ["83964.3", "0.04"], ["83964.7", "0.009461"], ["83964.9", "0.005957"], ["83965.1", "0.035744"], ["83965.2", "0.001333"], ["83966", "0.000333"], ["83966.9", "0.041083"], ["83967.1", "0.165632"], ["83967.3", "0.178693"], ["83967.7", "0.001466"], ["83968.1", "0.059399"], ["83968.3", "0.004314"], ["83969.1", "0.118996"], ["83969.4", "0.172333"], ["83970.2", "0.000333"], ["83970.4", "0.004653"], ["83971.4", "0.000358"], ["83971.6", "0.000524"], ["83971.7", "0.763874"], ["83971.8", "1.787795"], ["83972", "0.00018"], ["83972.3", "0.001466"], ["83972.5", "0.00432"], ["83973.1", "0.277531"], ["83973.5", "0.011919"], ["83973.6", "0.001333"], ["83974.3", "0.000333"], ["83974.6", "0.0025"], ["83974.8", "0.118996"], ["83976.2", "0.000524"], ["83976.7", "0.00432"], ["83976.8", "0.059399"], ["83977", "0.001466"], ["83977.8", "0.172333"], ["83978.1", "0.131041"], ["83978.5", "0.000333"], ["83979.2", "0.000358"], ["83979.8", "0.003671"], ["83979.9", "0.118996"], ["83980.1", "0.568244"], ["83980.2", "1.787882"], ["83980.4", "0.00009"], ["83980.8", "0.000524"], ["83980.9", "0.00432"], ["83981", "0.023825"], ["83981.2", "0.539115"], ["83981.6", "0.025293"], ["83982", "0.001451"], ["83982.2", "0.011923"], ["83982.3", "0.034239"], ["83982.7", "0.000333"], ["83982.8", "0.000685"], ["83984.4", "0.013867"], ["83985", "1.428828"], ["83985.1", "0.055675"], ["83985.2", "0.002144"], ["83985.4", "0.000524"], ["83985.7", "0.105758"], ["83985.8", "0.118996"], ["83986.2", "0.173799"], ["83986.9", "0.059732"], ["83987", "0.023825"], ["83987.1", "0.04"], ["83987.2", "0.04"], ["83987.4", "0.023827"], ["83987.7", "0.125123"], ["83988.1", "0.0001"], ["83988.2", "0.244829"], ["83988.3", "0.089346"], ["83988.8", "0.00009"], ["83988.9", "0.01512"], ["83989.3", "0.004323"], ["83989.9", "0.577965"], ["83990", "0.000524"], ["83990.1", "0.023825"], ["83990.4", "0.001333"], ["83990.5", "0.023107"], ["83990.8", "0.001466"], ["83991.1", "0.000333"], ["83991.3", "0.295185"], ["83991.8", "0.125502"], ["83991.9", "0.133996"], ["83992.6", "0.04"], ["83993.5", "0.004689"], ["83994.6", "0.172857"], ["83995.3", "0.000333"], ["83995.4", "0.001466"], ["83995.6", "0.357568"], ["83995.8", "0.04"], ["83995.9", "0.059399"], ["83997", "2.611932"], ["83997.2", "0.00009"], ["83997.3", "0.118996"], ["83997.4", "0.04"], ["83997.6", "0.04"], ["83997.7", "0.004331"], ["83997.9", "0.04"], ["83998.8", "0.001333"], ["83999.1", "0.125116"], ["83999.3", "0.000524"], ["83999.5", "0.000333"], ["84000", "0.006718"], ["84000.1", "0.001466"], ["84000.6", "0.015"], ["84001.9", "0.004932"], ["84002.2", "0.0006"], ["84002.9", "0.04"], ["84003", "0.172333"], ["84003.7", "0.000333"], ["84003.9", "0.000524"], ["84004.4", "0.013094"], ["84004.7", "0.001466"], ["84005", "0.059399"], ["84005.3", "0.000083"], ["84005.6", "0.00009"], ["84005.9", "0.005"], ["84006.1", "0.004332"], ["84006.7", "0.354039"], ["84006.8", "0.118996"], ["84007.2", "0.001333"], ["84007.9", "0.000333"], ["84008.5", "0.000524"], ["84008.8", "0.12"], ["84009.2", "0.089346"], ["84009.3", "0.001466"], ["84009.6", "3.830445"], ["84010.3", "0.004331"], ["84010.6", "0.12"], ["84011.2", "0.015"], ["84011.4", "0.172333"], ["84011.8", "1.028428"], ["84012", "0.000333"], ["84012.1", "0.000333"], ["84013.1", "0.000524"], ["84013.7", "0.118996"], ["84013.9", "0.001466"], ["84014", "0.00018"], ["84014.4", "0.011866"]], "u": 129205, "seq": 67571351078}, "cts": 1742577140316, "record_time": 1742577141.878741, "EXCHANGE": "BYBIT"}
{"topic": "orderbook.200.BTCUSDT", "ts": 1742577140519, "type": "delta", "data": {"s": "BTCUSDT", "b": [["83929.4", "0"], ["83929", "0.044"], ["83922.3", "0.178693"], ["83922.2", "0.040132"], ["83919.2", "0"], ["83911.5", "0.013522"], ["83911.4", "0.013212"], ["83910.6", "0.049965"], ["83910.5", "0"], ["83910.1", "0.004695"], ["83908.2", "0.049541"], ["83908", "0.059399"], ["83895", "0.357567"], ["83893.7", "0.354014"], ["83893.2", "0"], ["83873.6", "0.000333"]], "a": [["83944.5", "0.005958"], ["83945.8", "0"], ["83953.4", "0.000633"], ["83953.5", "0"], ["83954.2", "0"], ["83962.2", "0"], ["83962.4", "0.27152"], ["83964", "0.04"], ["83973.1", "0"], ["83995.5", "0.357567"], ["83995.6", "0"], ["84014.5", "0.004334"], ["84014.9", "0.059399"], ["84015.1", "0.04"], ["84015.3", "0.027605"]], "u": 129206, "seq": 67571351173}, "cts": 1742577140516, "record_time": 1742577141.88074, "EXCHANGE": "BYBIT"}
{"topic": "orderbook.200.BTCUSDT", "ts": 1742577140720, "type": "delta", "data": {"s": "BTCUSDT", "b": [["83943", "0.156163"], ["83940.6", "0"], ["83908.3", "0.05"], ["83908.1", "0.02265"], ["83906.9", "0.176292"], ["83898.2", "0.205636"], ["83873.6", "0"]], "a": [["83964.7", "0.188154"], ["83967.1", "0.162056"], ["83971.5", "0.178693"], ["83977.7", "0.091112"], ["83984.9", "0.590205"], ["83985.7", "0"], ["83994.2", "2.611932"], ["83995.4", "0.359032"], ["83995.5", "0"], ["83997", "0"], ["84015.3", "0"]], "u": 129207, "seq": 67571351245}, "cts": 1742577140716, "record_time": 1742577141.88174, "EXCHANGE": "BYBIT"}
{"topic": "orderbook.200.BTCUSDT", "ts": 1742577140920, "type": "delta", "data": {"s": "BTCUSDT", "b": [["83913.8", "0.044377"], ["83913.7", "0.039627"], ["83913.1", "0"], ["83913", "0.0015"], ["83911.5", "0.000522"], ["83911.4", "0.000333"], ["83911.3", "0.012879"], ["83911.2", "0.012879"], ["83908.3", "0"], ["83908.2", "0"], ["83908.1", "0.072191"], ["83908", "0.10894"], ["83895", "0"], ["83894.9", "0.437963"], ["83892.1", "5.533421"], ["83873.6", "0.000333"]], "a": [["83985.4", "0.040524"], ["83985.5", "0.04"], ["83987.1", "0"], ["83987.2", "0"], ["83994", "0.022797"], ["83994.2", "0"], ["83995.4", "0.001466"], ["83997", "2.611932"], ["83997.2", "0.357657"]], "u": 129208, "seq": 67571351297}, "cts": 1742577140915, "record_time": 1742577141.88274, "EXCHANGE": "BYBIT"}
{"topic": "orderbook.200.BTCUSDT", "ts": 1742577141120, "type": "delta", "data": {"s": "BTCUSDT", "b": [["83943", "0"], ["83942.4", "0"], ["83942.3", "0"], ["83940", "0"], ["83938.6", "0.084676"], ["83935.6", "0"], ["83935.3", "0"], ["83935.2", "0"], ["83935.1", "0"], ["83935", "0.005736"], ["83934.6", "0.000522"], ["83934.5", "0"], ["83932.4", "0.000333"], ["83932.1", "0.018772"], ["83932", "0.022947"], ["83931.6", "0"], ["83931.4", "0"], ["83930.5", "0"], ["83930.3", "0"], ["83930.2", "0.02"], ["83929.9", "0"], ["83929.3", "0"], ["83929.2", "0.018847"], ["83929", "0"], ["83928.6", "0"], ["83927.8", "0.034423"], ["83927.3", "0.0003"], ["83926.7", "0.095573"], ["83926.6", "0.048"], ["83926.3", "0.02442"], ["83926.1", "0.171"], ["83925.3", "0"], ["83925.2", "0"], ["83924.8", "0"], ["83924.7", "0.005956"], ["83924.5", "0.032532"], ["83924.2", "0.004079"], ["83924.1", "0.06485"], ["83924", "0.07186"], ["83923.9", "0"], ["83922.9", "0.048"], ["83922.8", "0"], ["83922.5", "0.044"], ["83922.3", "0"], ["83922.2", "0.004387"], ["83922.1", "0"], ["83921.5", "0.044"], ["83921.1", "0"], ["83919.4", "0"], ["83918.9", "0.0585"], ["83917.5", "0.003575"], ["83917.4", "0"], ["83916.9", "0.001466"], ["83916", "0.303861"], ["83915.9", "0"], ["83915.5", "0.035748"], ["83915.3", "0"], ["83915.2", "0"], ["83914.9", "0.135326"], ["83914.4", "0.178702"], ["83913.8", "0.004377"], ["83913.7", "0"], ["83912.7", "0.178702"], ["83911.9", "0.057896"], ["83911.3", "0"], ["83911.2", "0"], ["83911.1", "0"], ["83910.4", "0"], ["83908.8", "0"], ["83908.5", "0.198667"], ["83908.1", "0"], ["83908", "0.059399"], ["83907.9", "0"], ["83906.4", "0.1391"], ["83906.1", "0"], ["83904.9", "0.152283"], ["83904.8", "0.039631"], ["83904.4", "0"], ["83903.8", "0.1501"], ["83902.4", "0.012881"], ["83902.3", "0.014736"], ["83901", "0.521539"], ["83899.3", "0.049546"], ["83899.2", "0.049636"], ["83898.2", "0.098366"], ["83898.1", "0.743792"], ["83896.6", "0"], ["83894.9", "0.080396"], ["83892.1", "0"], ["83889.1", "0.132901"], ["83887", "0"], ["83883.6", "0.357601"], ["83883.4", "0"], ["83880", "0.001526"], ["83876.1", "0"], ["83873.5", "0.023837"], ["83872.9", "0.001333"], ["83872.3", "0.000352"], ["83871.8", "0.004263"], ["83871.6", "0.011878"], ["83871.5", "0.000083"], ["83871.3", "0.012352"], ["83871.2", "0.011994"], ["83871.1", "0.011877"], ["83871", "0.011994"], ["83870.9", "0.118996"], ["83870.8", "0.001466"], ["83870.7", "3.798197"], ["83870.5", "0.224383"], ["83870.4", "0.023837"], ["83870", "0.00052"], ["83869.8", "0.011994"], ["83869.7", "3.531433"], ["83869.5", "0.023986"], ["83869.4", "0.144894"], ["83868.9", "0.005959"]], "a": [["83938.7", "0.566525"], ["83942.3", "0.187524"], ["83942.5", "0.1"], ["83942.6", "0.001642"], ["83943.1", "0.37632"], ["83944.5", "0"], ["83944.6", "0.001466"], ["83944.7", "0"], ["83945.3", "0.096248"], ["83945.9", "0"], ["83947", "0.020811"], ["83947.1", "0.02"], ["83948", "0.003849"], ["83948.5", "0.040522"], ["83948.7", "0.04"], ["83948.9", "0"], ["83949.5", "0.037107"], ["83950.2", "0.059399"], ["83950.3", "0.178433"], ["83950.5", "0.018984"], ["83951.5", "0.013864"], ["83952", "0.04"], ["83952.1", "0.178702"], ["83953.1", "0.000522"], ["83953.4", "0.000333"], ["83953.8", "0.14523"], ["83953.9", "0.058857"], ["83954.7", "0.178702"], ["83955", "0.0006"], ["83955.5", "0"], ["83957", "0.118996"], ["83957.1", "0.149782"], ["83957.6", "0.040333"], ["83958.9", "0.179902"], ["83959.4", "0"], ["83960.8", "0"], ["83960.9", "0.101438"], ["83961.2", "0.015"], ["83961.8", "0.003909"], ["83961.9", "0"], ["83962.3", "0.001122"], ["83962.5", "0"], ["83963", "0.118996"], ["83963.1", "0.001466"], ["83964.7", "0"], ["83967.3", "0"], ["83967.9", "0.124096"], ["83970.2", "0.023164"], ["83971.5", "0"], ["83971.6", "0.576911"], ["83980.6", "1.428828"], ["83982", "0.296669"], ["83982.3", "0.085595"], ["83983.4", "0.023107"], ["83985", "0"], ["83985.1", "0.004321"], ["83985.4", "0.000524"], ["83985.5", "0"], ["83985.8", "0.158996"], ["83985.9", "0.04"], ["83987.6", "0.357601"], ["83989.9", "0"], ["83990.5", "0"], ["83991.3", "0"], ["83994", "0"], ["83994.2", "2.611932"], ["83997", "0"], ["83997.2", "0.00009"], ["84011.8", "0"], ["84014.4", "0"], ["84014.5", "0"], ["84014.9", "0"], ["84015.1", "0"]], "u": 129209, "seq": 67571351986}, "cts": 1742577141117, "record_time": 1742577141.88374, "EXCHANGE": "BYBIT"}
{"topic": "orderbook.200.BTCUSDT", "ts": 1742577141320, "type": "delta", "data": {"s": "BTCUSDT", "b": [["83938.6", "0.102546"], ["83937.8", "0.071515"], ["83932.1", "0.037882"], ["83929.4", "0.071522"], ["83929.2", "0.011914"], ["83926.9", "0.071525"], ["83926.3", "0"], ["83924.7", "0.119902"], ["83924.1", "0.106204"], ["83924", "0.000333"], ["83923.2", "0.024089"], ["83922.3", "0.056"], ["83919.8", "0.179035"], ["83919.5", "0.081138"], ["83918.9", "0"], ["83917.3", "0.048"], ["83916", "0.009713"], ["83915.5", "0"], ["83915.4", "0.035748"], ["83914.9", "0.305699"], ["83911.9", "0"], ["83911.8", "0.084052"], ["83907", "0.118996"], ["83905.8", "0.307932"], ["83904.9", "0.039631"], ["83896.7", "0.009225"], ["83891.1", "0.003"], ["83889.2", "0.357593"], ["83883.6", "0"], ["83883.4", "0.089351"], ["83870.5", "0"], ["83870.4", "0"], ["83870", "0"], ["83869.8", "0"], ["83869.7", "0"], ["83869.5", "0"], ["83869.4", "0"], ["83868.9", "0"]], "a": [["83938.7", "0.63169"], ["83938.8", "0.021454"], ["83938.9", "0.071514"], ["83943.2", "0.009225"], ["83947", "0.060987"], ["83948.3", "0.071506"], ["83949.9", "0.114764"], ["83950.2", "0.099399"], ["83950.3", "0.184417"], ["83950.4", "0.075555"], ["83952", "0.08"], ["83952.1", "0"], ["83953.5", "0.04"], ["83953.7", "0.04"], ["83953.9", "0.001466"], ["83954.7", "0"], ["83955", "0.179302"], ["83955.2", "0.04009"], ["83955.4", "0.04"], ["83957", "0"], ["83957.5", "0"], ["83957.6", "0.000333"], ["83959.1", "0"], ["83959.7", "0.342927"], ["83960.9", "0"], ["83962.4", "0.04"], ["83962.6", "0"], ["83967.9", "0"], ["83968.8", "0.288531"], ["83970.2", "0.000333"], ["83984.9", "0"], ["83987.6", "0"], ["83988.2", "0"], ["83991.7", "0.357593"], ["83994.2", "0"], ["83999.8", "2.61216"], ["84002.8", "0.027727"], ["84014", "0"]], "u": 129210, "seq": 67571352200}, "cts": 1742577141306, "record_time": 1742577141.885243, "EXCHANGE": "BYBIT"}
{"topic": "orderbook.200.BTCUSDT", "ts": 1742577141520, "type": "delta", "data": {"s": "BTCUSDT", "b": [["83938.6", "0.102785"], ["83932.1", "0.057849"], ["83931.7", "0.072853"], ["83931.6", "0.003"], ["83928.2", "0.007266"], ["83927", "0.148327"], ["83926.9", "0"], ["83926.7", "0"], ["83925.1", "0"], ["83913", "0"], ["83902.9", "0.0016"], ["83899.8", "0.05"], ["83899.7", "0.049545"], ["83899.3", "0"], ["83899.2", "0.00009"], ["83897.6", "0.132901"], ["83894.2", "0.125091"], ["83889.1", "0"], ["83886.6", "5.533421"], ["83870.8", "0"], ["83870.7", "0"]], "a": [["83938.7", "0.641068"], ["83943.2", "0"], ["83943.4", "0.006962"], ["83945.3", "0.024739"], ["83946", "0.071897"], ["83946.1", "0.071508"], ["83947", "0"], ["83948.3", "0"], ["83950.1", "0.221502"], ["83950.3", "0.039265"], ["83950.5", "0.090489"], ["83958.7", "0.225143"], ["83959.3", "0"], ["83962.4", "0"], ["83963.1", "0.180168"], ["83964", "0"], ["83964.3", "0"], ["83967.3", "0.178702"], ["83982.2", "0.000956"], ["83982.3", "0.085597"], ["83987.7", "0.148244"], ["83988.7", "2.61216"], ["83991.9", "0.173996"], ["83999.8", "0"], ["84014", "0.00018"], ["84014.4", "0.011866"]], "u": 129211, "seq": 67571352329}, "cts": 1742577141512, "record_time": 1742577141.887247, "EXCHANGE": "BYBIT"}
{"topic": "orderbook.200.BTCUSDT", "ts": 1742577141720, "type": "delta", "data": {"s": "BTCUSDT", "b": [["83938.6", "0.424281"], ["83937.9", "0.071621"], ["83927", "0.092386"], ["83924.7", "0.005956"], ["83919.9", "0.131699"], ["83919.8", "0.357777"], ["83919.5", "0"], ["83918.2", "0.178745"], ["83916.9", "0.060865"], ["83915.4", "0"], ["83915.2", "0.035748"], ["83914.9", "0.135326"], ["83905.8", "0"], ["83889.3", "0.359054"], ["83889.2", "0"], ["83889", "0.048696"]], "a": [["83938.7", "0.463556"], ["83938.8", "0"], ["83938.9", "0"], ["83943", "0.005959"], ["83943.1", "0.34632"], ["83943.4", "0"], ["83946", "0.044811"], ["83946.1", "0"], ["83949.9", "0"], ["83950.4", "0.04"], ["83950.5", "0.018984"], ["83951.9", "0.071503"], ["83953.8", "0.074402"], ["83955", "0.0006"], ["83959.7", "0.178702"], ["83961.8", "0.000333"], ["83962.9", "0.104081"], ["83968.8", "0"], ["83983.4", "0"], ["83988.7", "0"], ["83991.7", "0"], ["83992.5", "0.357585"], ["83994.2", "2.61216"], ["84014.5", "0.004334"], ["84014.9", "0.059399"], ["84015.1", "0.04"], ["84015.2", "0.0003"]], "u": 129212, "seq": 67571352451}, "cts": 1742577141717, "record_time": 1742577141.908324, "EXCHANGE": "BYBIT"}
{"topic": "orderbook.200.BTCUSDT", "ts": 1742577141919, "type": "delta", "data": {"s": "BTCUSDT", "b": [["83919.9", "0.240302"], ["83916.5", "0.178749"], ["83905.5", "0.039631"], ["83905.4", "0.044007"], ["83904.9", "0"], ["83904.8", "0"], ["83903.2", "0.132889"], ["83899.8", "0"], ["83899.6", "0.049546"], ["83897.6", "0"], ["83894.3", "0.357575"], ["83889.3", "0.001466"], ["83888.3", "0.024942"], ["83871", "0"], ["83870.9", "0"]], "a": [["83938.7", "0.388681"], ["83941.9", "0.005959"], ["83942", "0.071512"], ["83942.3", "0.196749"], ["83943", "0"], ["83954.9", "0.071501"], ["83957.8", "0.178661"], ["83959.4", "0.178658"], ["83962.5", "0.178702"], ["83966.7", "0.125091"], ["83979.8", "0.043671"], ["83979.9", "0.158996"], ["83985.8", "0.118996"], ["83985.9", "0"], ["83987.6", "0.085411"], ["83992.5", "0"], ["83994.5", "0.357575"], ["84014", "0"], ["84014.4", "0"], ["84014.5", "0"], ["84014.9", "0"], ["84015.1", "0"], ["84015.2", "0"]], "u": 129213, "seq": 67571352542}, "cts": 1742577141911, "record_time": 1742577142.107659, "EXCHANGE": "BYBIT"}
{"topic": "orderbook.200.BTCUSDT", "ts": 1742577142120, "type": "delta", "data": {"s": "BTCUSDT", "b": [["83938.6", "0.425081"], ["83927", "0.093386"], ["83915.2", "0"], ["83903.2", "0.132885"], ["83903", "0.013213"], ["83902.9", "0.01448"], ["83902.4", "0.192683"], ["83902.3", "0.001855"], ["83899.8", "0.049545"], ["83899.6", "0"], ["83894.3", "0"], ["83893.2", "0.357578"], ["83887", "0.000118"], ["83877.9", "0.178831"], ["83871.1", "0"]], "a": [["83938.7", "0.393943"], ["83941.9", "0"], ["83942", "0"], ["83942.4", "0.005959"], ["83943.1", "0.417831"], ["83953.8", "0.146047"], ["83962.2", "0.178702"], ["83979.7", "0.04"], ["83979.9", "0.118996"], ["83994.1", "0.357576"], ["83994.5", "0"], ["84013.9", "0"]], "u": 129214, "seq": 67571352634}, "cts": 1742577142105, "record_time": 1742577142.307822, "EXCHANGE": "BYBIT"}
{"topic": "orderbook.200.BTCUSDT", "ts": 1742577142320, "type": "delta", "data": {"s": "BTCUSDT", "b": [["83938.6", "0.254081"], ["83938.4", "0.000135"], ["83915.1", "0.035748"], ["83893.2", "0"], ["83889.1", "0.357579"], ["83871.3", "0"], ["83871.2", "0"]], "a": [["83938.7", "0.391826"], ["83940.8", "0.071513"], ["83942.2", "0.005959"], ["83942.4", "0"], ["83943.1", "0.34632"], ["83949.8", "0.07673"], ["83954.9", "0"], ["83979.7", "0"], ["83979.9", "0.158996"], ["83994.1", "0.35758"], ["84013.9", "0.001466"]], "u": 129215, "seq": 67571352698}, "cts": 1742577142316, "record_time": 1742577142.508798, "EXCHANGE": "BYBIT"}
{"topic": "orderbook.200.BTCUSDT", "ts": 1742577142519, "type": "delta", "data": {"s": "BTCUSDT", "b": [["83905.6", "0.04"], ["83905.4", "0.004376"], ["83903.1", "0.014466"], ["83902.9", "0.0016"], ["83899.9", "0.052386"], ["83899.7", "0"], ["83893.2", "0.357579"], ["83889.1", "0"]], "a": [["83938.7", "0.425481"], ["83940.7", "0.021454"], ["83962.2", "0"]], "u": 129216, "seq": 67571352768}, "cts": 1742577142517, "record_time": 1742577142.707724, "EXCHANGE": "BYBIT"}
{"topic": "orderbook.200.BTCUSDT", "ts": 1742577142719, "type": "delta", "data": {"s": "BTCUSDT", "b": [["83938.6", "0.73799"], ["83929.5", "0.023826"], ["83928.4", "0.167535"], ["83928.3", "0.133099"], ["83928", "0.041"], ["83927.3", "0.02027"], ["83927", "0.001"], ["83920.5", "0.178741"], ["83919.8", "0.179035"], ["83918.2", "0"], ["83916.5", "0"], ["83916", "0.00009"], ["83915.2", "0.521539"], ["83915", "0.118996"], ["83914.9", "0.001333"], ["83912.7", "0.267801"], ["83912.3", "0.56935"], ["83909.8", "0.047616"], ["83906.4", "0.019965"], ["83905.6", "0"], ["83905.5", "0"], ["83905.4", "0.044376"], ["83905.3", "0.039631"], ["83903.8", "0.125103"], ["83903.4", "0.024942"], ["83903.3", "0.357541"], ["83903.2", "0"], ["83903.1", "0.001466"], ["83903", "0.000333"], ["83902.9", "0.0146"], ["83902.8", "0.01288"], ["83901", "0"], ["83900.4", "0.132885"], ["83899.9", "0.002386"], ["83899.8", "0"], ["83899.7", "0.05"], ["83899.6", "0.049546"], ["83898.1", "0.175908"], ["83893.2", "0"], ["83889", "0.02403"], ["83888.3", "0"], ["83886.6", "0"], ["83871.8", "0"], ["83871.6", "0"], ["83871.5", "0"]], "a": [["83938.7", "0.214758"], ["83940.7", "0"], ["83940.8", "0"], ["83942.2", "0"], ["83942.3", "0.006185"], ["83942.5", "0"], ["83943.1", "0.17532"], ["83946", "0"], ["83947.9", "0.024336"], ["83948", "0"], ["83948.7", "0"], ["83949.8", "0.005225"], ["83950.1", "0"], ["83950.2", "0.142137"], ["83950.4", "0"], ["83950.5", "0"], ["83951.5", "0.004403"], ["83951.9", "0"], ["83952", "0.04"], ["83953.4", "0.006291"], ["83953.7", "0"], ["83953.8", "0"], ["83955.2", "0.00009"], ["83955.4", "0"], ["83955.8", "0.037101"], ["83956.8", "0.010558"], ["83957.1", "0.035759"], ["83957.3", "0.071499"], ["83957.8", "0"], ["83958.1", "0.003849"], ["83958.7", "0"], ["83958.9", "0.0012"], ["83959.4", "0"], ["83959.7", "0"], ["83962.4", "0.157691"], ["83962.5", "0"], ["83962.9", "0"], ["83963", "0"], ["83963.1", "0.001466"], ["83964.2", "0.119135"], ["83966.7", "0"], ["83967.3", "0"], ["83969.1", "0"], ["83971.6", "0.000524"], ["83972.6", "0.178702"], ["83978.1", "0.005956"], ["83979.8", "0.003671"], ["83979.9", "0.118996"], ["83982.3", "0.034239"], ["83983.6", "0.04"], ["83983.7", "0.04"], ["83987.7", "0.125123"], ["83988.3", "0"], ["83989", "0.576387"], ["83993.9", "0.022886"], ["83994.1", "0"], ["83994.2", "0"], ["83996.4", "0.051358"], ["83996.6", "0.178702"], ["84000.8", "0.178702"], ["84002.8", "0.385268"], ["84014", "0.00018"], ["84014.4", "0.011866"], ["84014.5", "0.004334"], ["84014.9", "0.059399"], ["84015.1", "0.04"], ["84015.2", "0.0003"], ["84015.6", "0.59189"], ["84015.7", "0.065422"], ["84016.2", "0.00138"], ["84016.3", "0.040333"], ["84016.7", "0.04"], ["84016.8", "0.0016"], ["84016.9", "0.011865"]], "u": 129217, "seq": 67571353080}, "cts": 1742577142717, "record_time": 1742577142.908471, "EXCHANGE": "BYBIT"}
{"topic": "orderbook.200.BTCUSDT", "ts": 1742577142920, "type": "delta", "data": {"s": "BTCUSDT", "b": [["83938.6", "0.616834"], ["83934.5", "0.004079"], ["83928.4", "0.298144"], ["83927.1", "0.178727"], ["83926.8", "0.123733"], ["83925.5", "0.17873"], ["83924.2", "0"], ["83919.9", "0.131699"], ["83919.7", "0.114021"], ["83917", "0.170579"], ["83909.8", "0.024666"], ["83909.3", "0.02024"], ["83907.9", "0.307154"], ["83903.3", "0"], ["83902.4", "0"], ["83900.3", "0.049545"], ["83900.2", "0.049545"], ["83899.7", "0"], ["83899.6", "0"], ["83899.1", "0.357555"], ["83898.2", "0"], ["83874", "0"], ["83873.6", "0"], ["83873.5", "0"], ["83872.9", "0"], ["83872.3", "0"]], "a": [["83938.7", "0.218536"], ["83943.2", "0.071511"], ["83946.1", "0.021444"], ["83947.9", "0"], ["83948.5", "0.000522"], ["83949.4", "0.005958"], ["83950.1", "0.059399"], ["83950.2", "0.102137"], ["83950.7", "0.001642"], ["83952", "0.111658"], ["83952.2", "0.071503"], ["83953.4", "0.000333"], ["83953.5", "0"], ["83954.3", "0.06413"], ["83954.5", "0.04"], ["83954.7", "0.05063"], ["83954.8", "0.071501"], ["83955.8", "0"], ["83956.2", "0.04"], ["83957.3", "0"], ["83957.7", "0.040522"], ["83958.7", "0.075844"], ["83961.2", "0.055"], ["83961.3", "0.018984"], ["83961.5", "0.114021"], ["83961.8", "0.174527"], ["83962.4", "0"], ["83963", "0.17865"], ["83964.1", "0.062526"], ["83967.1", "0"], ["83970.9", "0.308705"], ["83972.6", "0"], ["83977.7", "0"], ["83983.6", "0"], ["83983.7", "0"], ["83984.3", "0.04"], ["83984.4", "0.053867"], ["83993.6", "0.051358"], ["83993.9", "0"], ["83994.9", "0.178702"], ["83996.4", "0"], ["83999", "0.357554"], ["84002.8", "0.027727"], ["84015.6", "0"], ["84015.7", "0"], ["84016.2", "0"], ["84016.3", "0"], ["84016.7", "0"], ["84016.8", "0"], ["84016.9", "0"]], "u": 129218, "seq": 67571353282}, "cts": 1742577142916, "record_time": 1742577143.107809, "EXCHANGE": "BYBIT"}
{"topic": "orderbook.200.BTCUSDT", "ts": 1742577143120, "type": "delta", "data": {"s": "BTCUSDT", "b": [["83938.6", "0.619699"], ["83935.7", "0"], ["83928.3", "0.044"], ["83926.8", "0.112085"], ["83919.9", "0.215549"], ["83919.8", "0.000333"], ["83917", "0.18514"], ["83916.9", "0.239567"], ["83914.4", "0"], ["83908.5", "0.019965"], ["83907.9", "0.308272"], ["83903.5", "0.01288"], ["83903.4", "0.037822"], ["83903.2", "0.132863"], ["83902.9", "0.0016"], ["83902.8", "0"], ["83900.4", "0"], ["83899.2", "0.357644"], ["83899.1", "0"], ["83894.9", "5.646312"], ["83881.3", "0.045333"], ["83874", "0.011968"], ["83873.6", "0.000333"], ["83873.5", "0.023837"]], "a": [["83938.7", "0.218297"], ["83943.2", "0"], ["83943.3", "0.071511"], ["83950.2", "0.109143"], ["83950.4", "0.001642"], ["83952", "0.114366"], ["83954.2", "0.093869"], ["83954.7", "0"], ["83955.9", "0.045"], ["83957.9", "0.04"], ["83958.7", "0.170523"], ["83959.4", "0.04"], ["83959.6", "0.04"], ["83961", "0.212333"], ["83961.8", "0.173632"], ["83964.7", "0.178702"], ["83967.6", "0.178702"], ["83969.3", "0.118996"], ["83970.9", "0.305402"], ["83988", "0.051358"], ["83993.6", "0"], ["83994.9", "0"], ["83996.6", "0"], ["83998.9", "0.357556"], ["83999", "0"], ["83999.8", "2.61216"], ["84000.8", "0"], ["84014.4", "0"], ["84014.5", "0"], ["84014.9", "0"], ["84015.1", "0"], ["84015.2", "0"]], "u": 129219, "seq": 67571353535}, "cts": 1742577143116, "record_time": 1742577143.308917, "EXCHANGE": "BYBIT"}
{"topic": "orderbook.200.BTCUSDT", "ts": 1742577143320, "type": "delta", "data": {"s": "BTCUSDT", "b": [["83930.7", "0.003"], ["83922.3", "0.234702"], ["83916.9", "0.418269"], ["83915.3", "0.470733"], ["83915.1", "0.036793"], ["83914.3", "0.024009"], ["83903.5", "0"], ["83903.3", "0.01288"], ["83900.3", "0"], ["83900.2", "0.05"], ["83900.1", "0.049545"], ["83899.3", "0.357552"], ["83899.2", "0.00009"], ["83891.1", "0"], ["83874", "0"], ["83873.6", "0"], ["83873.5", "0"]], "a": [["83938.7", "0.218536"], ["83956.9", "0.001385"], ["83962.9", "0.160556"], ["83964.1", "0.013775"], ["83967.3", "0.178702"], ["83971.5", "0.178702"], ["83984.3", "0"], ["83984.4", "0.013867"], ["83984.5", "0.04"], ["83984.6", "0.04"], ["83988.3", "0.089351"], ["83998.4", "0.024703"], ["83998.9", "0"], ["83999.7", "0.357552"], ["84011.4", "0"], ["84012", "0"], ["84012.1", "0"], ["84013.1", "0"], ["84013.7", "0"], ["84013.9", "0"], ["84014", "0"]], "u": 129220, "seq": 67571353670}, "cts": 1742577143315, "record_time": 1742577143.509008, "EXCHANGE": "BYBIT"}
{"topic": "orderbook.200.BTCUSDT", "ts": 1742577143519, "type": "delta", "data": {"s": "BTCUSDT", "b": [["83942.2", "0.627181"], ["83940", "0.00006"], ["83938.7", "0.250825"], ["83938.6", "0.401566"], ["83937.9", "0"], ["83937.3", "0.092799"], ["83935.6", "0.022946"], ["83935", "0"], ["83934.8", "0.04843"], ["83933.8", "0.02"], ["83933", "0.171634"], ["83932.1", "0.117898"], ["83932", "0"], ["83931.6", "0"], ["83931.4", "0.034421"], ["83930.2", "0"], ["83929.9", "0.059567"], ["83929.8", "0.214188"], ["83929.4", "0"], ["83927.8", "0"], ["83927.3", "0.01997"], ["83926.8", "0"], ["83925.1", "0.059567"], ["83924.8", "0.178702"], ["83924.1", "0.174576"], ["83922.5", "0.231697"], ["83922.3", "0.056"], ["83921.1", "0.178702"], ["83919.4", "0.178702"], ["83917.3", "0.048981"], ["83917", "0"], ["83916.9", "0.239567"], ["83915.2", "0.64663"], ["83915.1", "0.035748"], ["83912.7", "0.089099"], ["83908.6", "0.0016"], ["83907.9", "0"], ["83906.1", "0.132863"], ["83903.3", "0.370414"], ["83903.2", "0"], ["83902.9", "0"], ["83901.3", "0.05"], ["83901.2", "0.053924"], ["83900.2", "0"], ["83900.1", "0"], ["83899.3", "0"], ["83874.7", "0"], ["83874.6", "0"]], "a": [["83938.7", "0"], ["83942.3", "0.002978"], ["83943.1", "0.00432"], ["83943.3", "0"], ["83944.7", "0.071509"], ["83945.3", "0"], ["83945.9", "0.006185"], ["83946.1", "0"], ["83947.1", "0"], ["83948.9", "0.024739"], ["83949.4", "0.000298"], ["83949.5", "0"], ["83950.1", "0"], ["83950.2", "0.068909"], ["83950.6", "0.005958"], ["83950.7", "0.021642"], ["83952", "0"], ["83952.2", "0"], ["83953.1", "0.037628"], ["83956.9", "0"], ["83957.2", "0.071499"], ["83957.5", "0.119151"], ["83958.4", "0.001315"], ["83961.8", "0.000333"], ["83963", "0"], ["83964.7", "0"], ["83967.3", "0"], ["83967.6", "0"], ["83969.2", "0.118996"], ["83969.3", "0"], ["83970.1", "0.178702"], ["83970.9", "0"], ["83971.5", "0"], ["83980.1", "1.171797"], ["83980.4", "0.006046"], ["83980.6", "0"], ["83984.5", "0"], ["83984.6", "0"], ["83984.7", "0.04"], ["83984.8", "0.04"], ["83988", "0.051355"], ["83988.3", "0"], ["83996.6", "0.178702"], ["83999.7", "0"], ["83999.8", "0"], ["84000.8", "0.178702"], ["84004.9", "0.357533"], ["84005.3", "2.612243"], ["84011.4", "0.001333"], ["84012", "0.000333"], ["84012.1", "0.000333"], ["84013.1", "0.000524"], ["84013.7", "0.118996"], ["84013.9", "0.001466"], ["84014", "0.00018"], ["84014.4", "0.011866"], ["84014.5", "0.004334"]], "u": 129221, "seq": 67571354051}, "cts": 1742577143518, "record_time": 1742577143.707616, "EXCHANGE": "BYBIT"}
{"topic": "orderbook.200.BTCUSDT", "ts": 1742577143720, "type": "delta", "data": {"s": "BTCUSDT", "b": [["83938.7", "0.169805"], ["83933", "0.052855"], ["83927.3", "0.02027"], ["83922.5", "0.044"], ["83912.6", "0.035555"], ["83907", "0.158996"], ["83906.9", "0.215925"], ["83905.4", "0.004376"], ["83905.3", "0"], ["83904.5", "0.013"], ["83904.4", "0.102228"], ["83903.4", "0.024942"], ["83903.3", "0"], ["83899.1", "0.357544"], ["83897.7", "5.566438"], ["83894.9", "0.080396"], ["83875.3", "0"], ["83875.2", "0"]], "a": [["83942.3", "0.004977"], ["83950.1", "0.005958"], ["83950.6", "0"], ["83953.5", "0.0003"], ["83954.2", "0.163331"], ["83957.5", "0"], ["83958.4", "0"], ["83959.5", "0.001232"], ["83962.9", "0"], ["83964.1", "0.062526"], ["83967.2", "0.178694"], ["83967.3", "0.178694"], ["83971.5", "0.178694"], ["83980.1", "0.568244"], ["83984.2", "0.04"], ["83984.3", "0.04"], ["83984.7", "0"], ["83984.8", "0"], ["83988", "0.051353"], ["83988.3", "0.089347"], ["83996.6", "0"], ["83999", "0.357549"], ["83999.8", "2.61216"], ["84000.8", "0"], ["84004.9", "0"], ["84005.3", "0.000083"], ["84011.4", "0.172333"], ["84014.4", "0"], ["84014.5", "0"]], "u": 129222, "seq": 67571354170}, "cts": 1742577143717, "record_time": 1742577143.908915, "EXCHANGE": "BYBIT"}
{"topic": "orderbook.200.BTCUSDT", "ts": 1742577143920, "type": "delta", "data": {"s": "BTCUSDT", "b": [["83899.1", "0.357542"]], "a": [["83950.1", "0"], ["83950.6", "0.005958"], ["83954.3", "0.04"], ["83959.3", "0.001377"], ["83959.5", "0"], ["83985.1", "0.055674"], ["83988", "0"], ["83999", "0"], ["83999.8", "2.611893"], ["84002.8", "0.385268"], ["84014.4", "0.011866"], ["84014.5", "0.004334"]], "u": 129223, "seq": 67571354231}, "cts": 1742577143916, "record_time": 1742577144.108001, "EXCHANGE": "BYBIT"}
{"topic": "orderbook.200.BTCUSDT", "ts": 1742577144120, "type": "delta", "data": {"s": "BTCUSDT", "b": [["83942.2", "0.456181"], ["83938.6", "0.398701"], ["83937.3", "0.0037"], ["83901.4", "0.295501"], ["83899.1", "0"], ["83894.3", "0.357557"], ["83875.4", "0"]], "a": [["83943.4", "0.071511"], ["83944.7", "0"], ["83950.1", "0.005958"], ["83950.2", "0.099014"], ["83950.6", "0"], ["83952.2", "0.071503"], ["83952.8", "0.000153"], ["83954.2", "0.100789"], ["83957.2", "0"], ["83957.4", "0.023655"], ["83978.1", "0.131042"], ["83997.2", "0.357647"], ["83998.4", "0"], ["83999.8", "0"], ["84002.5", "2.611893"], ["84002.8", "0.027727"], ["84014.5", "0"]], "u": 129224, "seq": 67571354279}, "cts": 1742577144115, "record_time": 1742577144.30921, "EXCHANGE": "BYBIT"}
{"topic": "orderbook.200.BTCUSDT", "ts": 1742577144319, "type": "delta", "data": {"s": "BTCUSDT", "b": [["83942.2", "0.627181"], ["83914.3", "0"], ["83909.8", "0.049321"], ["83901.5", "0.120588"], ["83897.8", "0.369475"], ["83894.3", "0"], ["83875.4", "0.001466"]], "a": [["83952.2", "0.071656"], ["83952.8", "0"], ["83959.3", "0"], ["83994.2", "0.024809"], ["83997.2", "0.357644"], ["84014.5", "0.004334"]], "u": 129225, "seq": 67571354319}, "cts": 1742577144309, "record_time": 1742577144.520164, "EXCHANGE": "BYBIT"}
{"topic": "orderbook.200.BTCUSDT", "ts": 1742577144520, "type": "delta", "data": {"s": "BTCUSDT", "b": [["83909.8", "0.024655"], ["83907", "0.118996"], ["83906.9", "0.176292"], ["83906.6", "0.039633"], ["83906.5", "0.040966"], ["83904.5", "0"], ["83904.4", "0.089347"], ["83904.1", "0.012881"], ["83904", "0.012881"], ["83901.6", "0.357538"], ["83901.3", "0"], ["83901.2", "0.004376"], ["83900.9", "0.049548"], ["83900.8", "0.049548"], ["83899.1", "0.024666"], ["83897.8", "0.01192"], ["83876.3", "0"], ["83876", "0"], ["83875.8", "0"], ["83875.6", "0"], ["83875.4", "0"]], "a": [["83943.4", "0"], ["83944", "0.07151"], ["83950.1", "0"], ["83951.5", "0.010361"], ["83952.2", "0.071503"], ["83954.2", "0.093869"], ["83969.2", "0"], ["83984.2", "0"], ["83984.3", "0"], ["83985.2", "0.042144"], ["83985.3", "0.04"], ["83997.2", "0.00009"], ["84002.4", "0.357538"], ["84014.9", "0.059399"], ["84015.1", "0.04"]], "u": 129226, "seq": 67571354392}, "cts": 1742577144513, "record_time": 1742577144.708865, "EXCHANGE": "BYBIT"}
{"topic": "orderbook.200.BTCUSDT", "ts": 1742577144719, "type": "delta", "data": {"s": "BTCUSDT", "b": [["83942.2", "0.630846"], ["83928.1", "0.055516"], ["83921.1", "0.235198"], ["83914.1", "0.123065"], ["83901.6", "0"], ["83900.9", "0.40709"], ["83876.4", "0"]], "a": [["83949.4", "0"], ["83950.2", "0"], ["83950.6", "0.005958"], ["83951.5", "0.004403"], ["83961.5", "0"], ["83963.1", "0.057488"], ["83967.1", "0.233576"], ["83969.3", "0.118996"], ["83970.1", "0.240337"], ["83977.1", "0.122542"], ["83985.1", "0.004321"], ["83985.2", "0.002144"], ["83985.4", "0.040524"], ["83988", "0.051353"], ["84002.5", "0"], ["84005.3", "2.611976"], ["84015.1", "0"]], "u": 129227, "seq": 67571354438}, "cts": 1742577144714, "record_time": 1742577144.907945, "EXCHANGE": "BYBIT"}
{"topic": "orderbook.200.BTCUSDT", "ts": 1742577144920, "type": "delta", "data": {"s": "BTCUSDT", "b": [["83929", "0.1214"], ["83928.1", "0"], ["83922", "0.169766"], ["83921.1", "0.178702"], ["83918.1", "0.003576"], ["83915", "0.414727"], ["83914.1", "0"], ["83901", "0.05"], ["83900.9", "0.049548"], ["83900.8", "0"], ["83899.1", "0.382207"], ["83876.5", "0"]], "a": [["83950.2", "0.005958"], ["83950.6", "0.093523"], ["83954.9", "0.006983"], ["83961.9", "0.123341"], ["83963.1", "0.001466"], ["83965.3", "0.114018"], ["83968.9", "0.170382"], ["83970.1", "0.178702"], ["83975.9", "0.281768"], ["83977.1", "0"], ["84002.3", "0.357544"], ["84002.4", "0"], ["84002.5", "2.611893"], ["84005.3", "0.000083"], ["84013.7", "0"], ["84013.9", "0"], ["84014", "0"], ["84014.4", "0"], ["84014.5", "0"], ["84014.9", "0"]], "u": 129228, "seq": 67571354497}, "cts": 1742577144910, "record_time": 1742577145.108946, "EXCHANGE": "BYBIT"}
{"topic": "orderbook.200.BTCUSDT", "ts": 1742577145119, "type": "delta", "data": {"s": "BTCUSDT", "b": [["83918.1", "0"], ["83906.7", "0.04"], ["83906.5", "0.001333"], ["83904.2", "0.013"], ["83904", "0"], ["83899.2", "0.357638"], ["83899.1", "0.024666"]], "a": [["83964.1", "0.090637"], ["83984.9", "0.04"], ["83985", "0.04"], ["83985.3", "0"], ["83985.4", "0.000524"], ["84002.2", "0.358148"], ["84002.3", "0"]], "u": 129229, "seq": 67571354524}, "cts": 1742577145117, "record_time": 1742577145.308277, "EXCHANGE": "BYBIT"}
{"topic": "orderbook.200.BTCUSDT", "ts": 1742577145320, "type": "delta", "data": {"s": "BTCUSDT", "b": [["83929", "0"], ["83928", "0.101758"], ["83922", "0"], ["83921", "0.060834"], ["83919.1", "0.004909"], ["83915", "0.118996"], ["83914", "0.119619"], ["83906.7", "0.039633"], ["83899.3", "0.357546"], ["83899.2", "0.00009"], ["83877", "0"]], "a": [["83942.6", "0"], ["83950.2", "0"], ["83950.5", "0.005958"], ["83953.5", "0.000453"], ["83961.9", "0"], ["83963", "0.059585"], ["83968.9", "0"], ["83970", "0.058337"], ["83975.9", "0"], ["83977", "0.12072"], ["83999.8", "2.611893"], ["84002.1", "0.357546"], ["84002.2", "0.0006"], ["84002.5", "0"], ["84013.7", "0.118996"]], "u": 129230, "seq": 67571354604}, "cts": 1742577145314, "record_time": 1742577145.508599, "EXCHANGE": "BYBIT"}
{"topic": "orderbook.200.BTCUSDT", "ts": 1742577145520, "type": "delta", "data": {"s": "BTCUSDT", "b": [["83940.7", "0.0025"], ["83937.3", "0.001"], ["83928", "0.041"], ["83921", "0"], ["83914", "0"], ["83912", "0.0016"], ["83908.6", "0"], ["83901.5", "0.212779"], ["83900", "0.000473"], ["83899.4", "0.357547"], ["83899.3", "0"], ["83877", "0.044"]], "a": [["83950.5", "0"], ["83950.6", "0.099481"], ["83953.5", "0.0003"], ["83963", "0"], ["83970", "0"], ["83977", "0.001466"], ["83985.1", "0.055674"], ["83988", "0"], ["84002", "0.357543"], ["84002.1", "0"], ["84013.9", "0.001466"], ["84014", "0.00018"], ["84014.4", "0.011866"], ["84014.5", "0.004334"]], "u": 129231, "seq": 67571354683}, "cts": 1742577145494, "record_time": 1742577145.708778, "EXCHANGE": "BYBIT"}
{"topic": "orderbook.200.BTCUSDT", "ts": 1742577145720, "type": "delta", "data": {"s": "BTCUSDT", "b": [["83942.2", "0.632632"], ["83920.4", "0.004977"], ["83919.1", "0.001333"], ["83915.1", "0"], ["83906.7", "0"], ["83906.5", "0.040966"], ["83904.2", "0"], ["83904", "0.012881"], ["83901", "0"], ["83900.8", "0.049548"], ["83899.9", "0.0006"], ["83899.5", "0.357544"], ["83899.4", "0"], ["83876.5", "0.04"]], "a": [["83944", "0"], ["83945.1", "0.071509"], ["83950.6", "0.093523"], ["83951.5", "0.010361"], ["83954.4", "0.000153"], ["83954.9", "0"], ["83955", "0.007709"], ["83959.7", "0.004977"], ["83965.1", "0"], ["83984.2", "1.428843"], ["83984.9", "0"], ["83985", "0.137556"], ["83985.4", "0.040524"], ["83985.5", "0.04"], ["84001.9", "0.362476"], ["84002", "0"]], "u": 129232, "seq": 67571354744}, "cts": 1742577145709, "record_time": 1742577145.908592, "EXCHANGE": "BYBIT"}
{"topic": "orderbook.200.BTCUSDT", "ts": 1742577145919, "type": "delta", "data": {"s": "BTCUSDT", "b": [["83935.3", "0.075885"], ["83935.2", "0.071517"], ["83934.8", "0"], ["83932.7", "0.112738"], ["83931.7", "0.001333"], ["83922.9", "0.21634"], ["83913.8", "0.284671"], ["83899.5", "0"], ["83899.1", "0.382214"], ["83876.5", "0"]], "a": [["83942.3", "0.004957"], ["83943.7", "0.07151"], ["83945.1", "0"], ["83950.2", "0.006256"], ["83950.4", "0.073147"], ["83951.5", "0.004403"], ["83952.2", "0"], ["83952.4", "0.000153"], ["83954.2", "0.140757"], ["83954.4", "0"], ["83957.9", "0.14877"], ["83967.7", "0.188024"], ["83976.8", "0.351012"], ["83999.8", "0"], ["84001.8", "0.357545"], ["84001.9", "0.004932"], ["84002.5", "2.611893"], ["84014.5", "0"]], "u": 129233, "seq": 67571354787}, "cts": 1742577145912, "record_time": 1742577146.108317, "EXCHANGE": "BYBIT"}
{"topic": "orderbook.200.BTCUSDT", "ts": 1742577146120, "type": "delta", "data": {"s": "BTCUSDT", "b": [["83941.8", "0.002817"], ["83932.7", "0"], ["83927", "0"], ["83922.9", "0.048"], ["83913.8", "0.004377"], ["83906.6", "0"], ["83906.5", "0.001333"], ["83906.4", "0.059598"], ["83906.3", "0.039633"], ["83904.1", "0"], ["83904", "0"], ["83903.9", "0.012881"], ["83903.8", "0.137984"], ["83901.6", "0.357538"], ["83901.5", "0.120588"], ["83900.9", "0"], ["83900.8", "0"], ["83900.7", "0.049549"], ["83900.6", "0.049549"], ["83899.1", "0.024666"], ["83876.5", "0.04"]], "a": [["83943.7", "0"], ["83945.3", "0.071509"], ["83950.2", "0.000298"], ["83950.4", "0.001642"], ["83951.5", "0.010361"], ["83952.2", "0.000153"], ["83952.4", "0"], ["83953", "0.071502"], ["83957.9", "0.04"], ["83967.7", "0.001466"], ["83976.8", "0.059399"], ["83985.4", "0.000524"], ["83985.5", "0"], ["83986", "0.04"], ["83986.1", "0.04"], ["84001.8", "0"], ["84004.9", "0.357538"], ["84014", "0"], ["84014.4", "0"]], "u": 129234, "seq": 67571354853}, "cts": 1742577146104, "record_time": 1742577146.30793, "EXCHANGE": "BYBIT"}
{"topic": "orderbook.200.BTCUSDT", "ts": 1742577146319, "type": "delta", "data": {"s": "BTCUSDT", "b": [["83949.1", "0.9501"], ["83948.9", "0.136919"], ["83948.8", "0.171506"], ["83945.9", "0.004079"], ["83943.8", "0.59402"], ["83943.7", "0.368116"], ["83943.1", "0.004381"], ["83943", "0.049965"], ["83942.5", "0.023063"], ["83942.2", "0.147802"], ["83941.8", "0.074329"], ["83941.1", "0.001"], ["83940.8", "0.000333"], ["83940.1", "0.007069"], ["83940", "0.001526"], ["83939.2", "0.000522"], ["83939", "0.01997"], ["83938.9", "0.004381"], ["83938.7", "0.115114"], ["83938.6", "0.221965"], ["83938.3", "0.034596"], ["83937.8", "0"], ["83937.4", "0.022"], ["83937.3", "0.090099"], ["83935.6", "0"], ["83935.4", "0.142694"], ["83935.2", "0"], ["83934.7", "0.004392"], ["83934.6", "0.020522"], ["83934.5", "0"], ["83934.4", "0.059563"], ["83934.1", "0.005956"], ["83933.9", "0"], ["83933.8", "0"], ["83933.6", "0.059564"], ["83933", "0"], ["83932.3", "0"], ["83932.1", "0.195712"], ["83931.4", "0"], ["83929.5", "0.175482"], ["83929.2", "0.044"], ["83928.9", "0.119128"], ["83928.6", "0.044"], ["83928.4", "0.332309"], ["83927.6", "0.048"], ["83927.4", "0.059399"], ["83927.3", "0"], ["83927.1", "0"], ["83925.5", "0"], ["83924.8", "0"], ["83924.5", "0"], ["83924.2", "0.178692"], ["83922.1", "0.11912"], ["83921.4", "0.120176"], ["83921.2", "0.119127"], ["83921.1", "0"], ["83920.6", "0.118996"], ["83920.5", "0"], ["83919.8", "0.059896"], ["83919.4", "0"], ["83918.8", "0.059563"], ["83918", "0.063951"], ["83917.3", "0.048"], ["83916.9", "0.060865"], ["83915.2", "0.521539"], ["83914.6", "0.157568"], ["83912.8", "0.357492"], ["83910.7", "0.00152"], ["83910.1", "0"], ["83908.8", "0.023825"], ["83907.5", "0.003575"], ["83907.1", "0.04379"], ["83906.1", "0"], ["83904.4", "0"], ["83904", "0.023825"], ["83903.8", "0.137957"], ["83903", "0.024158"], ["83901.6", "0"], ["83899.5", "0.005956"], ["83899.1", "0"], ["83898", "0.023825"], ["83897.8", "0"], ["83897.7", "0.000522"], ["83896.9", "0"], ["83894.2", "0"], ["83883.4", "0"], ["83880.2", "0"], ["83880", "0"], ["83879.7", "0"], ["83879.2", "0"], ["83877.9", "0"], ["83877.8", "0"], ["83877.7", "0"], ["83877.1", "0"], ["83877", "0"], ["83876.5", "0"]], "a": [["83942.3", "0"], ["83943.1", "0"], ["83943.8", "0"], ["83944.3", "0"], ["83944.6", "0"], ["83945", "0"], ["83945.3", "0"], ["83945.9", "0"], ["83947.3", "0"], ["83948.4", "0"], ["83948.5", "0"], ["83948.9", "0"], ["83949.8", "0"], ["83950.2", "0"], ["83950.3", "0"], ["83950.6", "0"], ["83950.7", "0.001642"], ["83951.5", "0.004403"], ["83951.6", "0"], ["83952.2", "0.02"], ["83953", "0"], ["83953.1", "0.000522"], ["83953.5", "0"], ["83954.2", "0"], ["83954.3", "0"], ["83954.5", "0"], ["83954.8", "0"], ["83955", "0.0006"], ["83955.2", "0"], ["83955.9", "0.005"], ["83956", "0.039264"], ["83956.2", "0"], ["83956.8", "0.001333"], ["83957.1", "0"], ["83957.4", "0"], ["83957.9", "0"], ["83958.1", "0"], ["83958.7", "0"], ["83958.8", "0"], ["83959", "0.092901"], ["83959.6", "0"], ["83959.7", "0"], ["83960", "0.037152"], ["83960.9", "0.005957"], ["83961", "0.172333"], ["83961.2", "0.015"], ["83961.3", "0"], ["83963", "0.071494"], ["83964.1", "0.004314"], ["83964.2", "0"], ["83964.9", "0"], ["83965.1", "0.021947"], ["83965.2", "0.072825"], ["83965.3", "0"], ["83966.8", "0.009225"], ["83967.1", "0"], ["83967.2", "0.04"], ["83967.3", "0"], ["83968", "0.110252"], ["83968.4", "0.003849"], ["83969.3", "0"], ["83970.1", "0"], ["83970.4", "0.05975"], ["83970.6", "0.003499"], ["83971.5", "0"], ["83973.5", "0"], ["83973.7", "0.023825"], ["83974.8", "0"], ["83977.4", "0.061348"], ["83978.1", "0"], ["83981", "0"], ["83981.6", "0.001466"], ["83983", "0.011917"], ["83984.2", "0"], ["83984.4", "0.13689"], ["83985.1", "0.004321"], ["83986", "0"], ["83986.1", "0"], ["83987", "0"], ["83987.4", "0"], ["83987.7", "0"], ["83988.3", "0"], ["83990.1", "0"], ["83990.3", "0.005956"], ["83991.2", "0.023825"], ["83993.5", "0.044689"], ["83993.6", "0.04"], ["83993.8", "0.023825"], ["83997.2", "0.023915"], ["83999.1", "0"], ["83999.6", "0.023825"], ["84000.3", "0.023825"], ["84000.6", "0"], ["84002.5", "0"], ["84002.8", "0"], ["84004.9", "0.051353"], ["84009.2", "0"], ["84009.6", "0"], ["84014", "0.00018"], ["84014.4", "0.011866"], ["84014.5", "0.004334"], ["84014.9", "0.059399"], ["84015.1", "0.04"], ["84015.6", "0.59189"], ["84015.7", "0.065422"], ["84016.2", "0.00138"], ["84016.3", "0.040333"], ["84016.7", "0.04"], ["84016.8", "0.0016"], ["84016.9", "0.011865"], ["84017.7", "0.001124"], ["84018.4", "0.011865"], ["84018.5", "0.001466"], ["84018.7", "0.004334"], ["84018.8", "0.130862"], ["84019.1", "0.011993"], ["84019.8", "0.004483"], ["84020.5", "0.000333"], ["84020.7", "0.011865"], ["84022.2", "0.011994"], ["84022.3", "0.011994"], ["84022.4", "0.000614"], ["84022.7", "0.000145"], ["84022.9", "0.004436"], ["84023.2", "0.001466"], ["84023.7", "0.002735"], ["84023.9", "0.118996"], ["84024", "0.001333"], ["84024.6", "0.0025"], ["84024.7", "0.000333"], ["84025.3", "0.0005"], ["84026.7", "3.592291"], ["84026.8", "0.011993"], ["84027", "0.000524"], ["84027.1", "0.004436"], ["84027.8", "0.001466"], ["84028.2", "0.001333"], ["84028.9", "0.000333"], ["84029", "0.118996"], ["84029.1", "0.059399"]], "u": 129235, "seq": 67571356408}, "cts": 1742577146318, "record_time": 1742577146.514729, "EXCHANGE": "BYBIT"}
{"topic": "orderbook.200.BTCUSDT", "ts": 1742577146519, "type": "delta", "data": {"s": "BTCUSDT", "b": [["83949.1", "0.954177"], ["83948.9", "0.052676"], ["83945.5", "0.005765"], ["83943.9", "0.23621"], ["83943.8", "0"], ["83943.7", "0.306116"], ["83941.6", "0.04224"], ["83941.2", "0.009216"], ["83941.1", "0.120245"], ["83940.8", "0.057588"], ["83940.1", "0.001333"], ["83939.9", "0.052855"], ["83938.4", "0"], ["83936.4", "0.044"], ["83936.2", "0.04"], ["83935.5", "0.087282"], ["83935.4", "0.084854"], ["83935.3", "0"], ["83934.6", "0.076522"], ["83933.7", "0.03295"], ["83930.6", "0.185694"], ["83930.3", "0.044"], ["83929.5", "0.592313"], ["83928.7", "0.521539"], ["83928.4", "0.157912"], ["83928.2", "0.000333"], ["83925.9", "0.003575"], ["83925.3", "0.17868"], ["83924.6", "0"], ["83923.6", "0.292357"], ["83922.9", "0"], ["83922.3", "0"], ["83921.5", "0"], ["83921.4", "0"], ["83917.4", "0.132902"], ["83917.3", "0"], ["83915.2", "0.125076"], ["83914.6", "0.024666"], ["83912.8", "0"], ["83909.7", "0.17868"], ["83909.1", "0.03386"], ["83908.1", "0.3575"], ["83898.1", "0.172333"], ["83894.2", "0.125076"], ["83882.6", "0"], ["83882.5", "0"], ["83882.4", "0"], ["83882", "0"], ["83881.8", "0"], ["83881.3", "0"], ["83881.2", "0"], ["83881", "0"]], "a": [["83949.2", "0.00507"], ["83952.2", "0"], ["83952.8", "0.006152"], ["83953.5", "0.0003"], ["83955.8", "0.024609"], ["83956.7", "0.005225"], ["83957.6", "0.020333"], ["83957.7", "0.000522"], ["83958.9", "0.001498"], ["83959.2", "0.005957"], ["83959.3", "0.059399"], ["83959.4", "0"], ["83960.5", "0.023438"], ["83960.9", "0"], ["83962.9", "0.133922"], ["83963", "0"], ["83963.1", "0.041466"], ["83964", "0.071493"], ["83964.8", "0.04"], ["83965.1", "0"], ["83965.2", "0.001333"], ["83965.6", "0.112727"], ["83965.7", "0.071492"], ["83966.2", "0.04"], ["83969.4", "0.286345"], ["83969.8", "0.04"], ["83970.4", "0"], ["83971.7", "0.546526"], ["83972.1", "0.018984"], ["83974.9", "0.009266"], ["83976.1", "0.183331"], ["83977.4", "0"], ["83981.2", "0"], ["83983.1", "0.282035"], ["83984.4", "0"], ["83993.5", "0.004689"], ["83993.6", "0"], ["83995.1", "0.04"], ["83995.2", "0.04"], ["83995.7", "0.531136"], ["83997.6", "0"], ["83997.9", "0"], ["84002.9", "0"], ["84004.9", "0.051351"], ["84005", "0.238079"], ["84008.8", "0"], ["84010.5", "0.357496"], ["84012.9", "0.113162"], ["84019.8", "0.175483"], ["84020.1", "0.125076"], ["84024.1", "0.028168"], ["84024.7", "0"], ["84025.3", "0"], ["84026.7", "0"], ["84026.8", "0"], ["84027", "0"], ["84027.1", "0"], ["84027.8", "0"], ["84028.2", "0"], ["84028.9", "0"], ["84029", "0"], ["84029.1", "0"]], "u": 129236, "seq": 67571356811}, "cts": 1742577146517, "record_time": 1742577146.70866, "EXCHANGE": "BYBIT"}
{"topic": "orderbook.200.BTCUSDT", "ts": 1742577146720, "type": "delta", "data": {"s": "BTCUSDT", "b": [["83949.1", "0.946395"], ["83943.9", "0.1441"], ["83943.7", "0.296116"], ["83942.2", "0.144937"], ["83941.1", "0.001"], ["83940.9", "0.187635"], ["83938.7", "0"], ["83934.7", "0.052392"], ["83932.2", "0.003575"], ["83932.1", "0.524761"], ["83930.6", "0.004391"], ["83928.3", "0"], ["83928", "0"], ["83926.6", "0"], ["83926.2", "0.120462"], ["83925", "0.004622"], ["83923.6", "0"], ["83923.3", "0.001333"], ["83922.5", "0"], ["83915.3", "0"], ["83908.8", "0.073825"], ["83908.7", "0.049547"], ["83908.1", "0.357505"], ["83906", "5.608717"], ["83900.7", "0"], ["83900.6", "0"], ["83882.6", "0.118996"], ["83882.5", "0.01936"], ["83882.4", "0.00018"], ["83882", "0.000333"]], "a": [["83949.2", "0.005309"], ["83954.9", "0.000298"], ["83955", "0.072101"], ["83962.2", "0.071495"], ["83962.8", "0.076709"], ["83962.9", "0.06053"], ["83964", "0"], ["83964.6", "0.04"], ["83965.6", "0"], ["83966.5", "0.04"], ["83967.3", "0.00507"], ["83968.1", "0.099399"], ["83976.1", "0"], ["83983.1", "0"], ["83987.3", "0.004657"], ["83991.9", "0.133996"], ["83992.6", "0"], ["83995.1", "0"], ["83995.2", "0"], ["83995.6", "0.04"], ["83995.7", "0.571136"], ["83995.8", "0"], ["83996.4", "0.051351"], ["84004.9", "0"], ["84005", "0.059399"], ["84010.4", "0.357504"], ["84010.5", "0"], ["84010.6", "0"], ["84010.8", "2.611942"], ["84011.4", "0.212333"]], "u": 129237, "seq": 67571356983}, "cts": 1742577146709, "record_time": 1742577146.910448, "EXCHANGE": "BYBIT"}
{"topic": "orderbook.200.BTCUSDT", "ts": 1742577146919, "type": "delta", "data": {"s": "BTCUSDT", "b": [["83948.4", "0.001"], ["83945.5", "0.012757"], ["83944.3", "0.001333"], ["83943.8", "0.000522"], ["83943.7", "0.294261"], ["83942.2", "0.049965"], ["83940.8", "0.179918"], ["83936.7", "0.117907"], ["83932.2", "0"], ["83930.3", "0.22466"], ["83929.7", "0.186982"], ["83926.4", "0.007962"], ["83924.1", "0"], ["83923.3", "0.294938"], ["83923.2", "0"], ["83922.7", "0.308826"], ["83915.1", "0.268482"], ["83909.8", "0.382159"], ["83909", "0.05"], ["83908.9", "0.049547"], ["83908.8", "0.023825"], ["83908.7", "0"], ["83908.1", "0"], ["83904.4", "0.08934"], ["83883.4", "0.08934"], ["83882.9", "0"], ["83882.7", "0"], ["83882.6", "0"], ["83882.5", "0"], ["83882.4", "0"], ["83882", "0"]], "a": [["83949.2", "0.00507"], ["83950.7", "0"], ["83954.9", "0"], ["83955", "0.0006"], ["83955.6", "0.000298"], ["83956.9", "0.071499"], ["83962.2", "0"], ["83964", "0.071493"], ["83965.3", "0.124572"], ["83965.7", "0"], ["83967.1", "0.16673"], ["83967.4", "0.07149"], ["83967.9", "0.04"], ["83968", "0"], ["83969.6", "0.112593"], ["83970.6", "0"], ["83975.7", "0.17868"], ["83975.8", "0.183168"], ["83976.6", "0.18096"], ["83976.7", "0.074379"], ["83979.9", "0.297676"], ["83982.8", "0.301518"], ["83983.6", "0.278663"], ["83997.4", "0"], ["84000", "0.020473"], ["84010.3", "0.361833"], ["84010.4", "0"], ["84010.8", "0"], ["84013.6", "2.611942"], ["84014.4", "0"], ["84018.8", "0.118996"], ["84024", "0"], ["84024.1", "0"], ["84024.6", "0"]], "u": 129238, "seq": 67571357106}, "cts": 1742577146907, "record_time": 1742577147.108255, "EXCHANGE": "BYBIT"}
{"topic": "orderbook.200.BTCUSDT", "ts": 1742577147120, "type": "delta", "data": {"s": "BTCUSDT", "b": [["83949.1", "0.94926"], ["83940.8", "0.057588"], ["83940.7", "0.0225"], ["83937", "0.178705"], ["83936.8", "0.272018"], ["83936.7", "0"], ["83935.5", "0"], ["83935.3", "0.178709"], ["83934.9", "0.17868"], ["83934.6", "0.056522"], ["83933.6", "0.238277"], ["83930.3", "0.044"], ["83929.7", "0"], ["83927.1", "0.003575"], ["83926.4", "0.004387"], ["83923.3", "0.001333"], ["83922.7", "0"], ["83909.8", "0.024655"], ["83909.7", "0"], ["83909.1", "0.391361"], ["83909", "0"], ["83908.9", "0"], ["83908.8", "0.073372"], ["83908.7", "0.049547"], ["83895", "0.178795"]], "a": [["83949.2", "0.005309"], ["83950.4", "0"], ["83962.8", "0.11765"], ["83962.9", "0.060529"], ["83965.3", "0"], ["83969.6", "0"], ["83975.6", "0.234355"], ["83975.8", "0"], ["83976.6", "0"], ["83976.7", "0.00432"], ["83977.3", "0.17868"], ["83982.8", "0.000685"], ["83983.6", "0"], ["83999.1", "0.125076"], ["84010.2", "0.357501"], ["84010.3", "0.004331"], ["84010.8", "2.611847"], ["84012.9", "0"], ["84013.6", "0"], ["84024", "0.001333"], ["84024.1", "0.028168"], ["84024.6", "0.0025"]], "u": 129239, "seq": 67571357170}, "cts": 1742577147117, "record_time": 1742577147.308876, "EXCHANGE": "BYBIT"}
{"topic": "orderbook.200.BTCUSDT", "ts": 1742577147320, "type": "delta", "data": {"s": "BTCUSDT", "b": [["83949.1", "0.950646"], ["83929.8", "0.217763"], ["83927.1", "0"], ["83924.8", "0.125076"], ["83910.7", "0.359017"], ["83909.1", "0.03386"], ["83908.8", "0.023825"], ["83908.6", "0.049547"], ["83883.4", "0"]], "a": [["83956.9", "0"], ["83958.1", "0.071498"], ["83959.2", "0"], ["83959.9", "0.010266"], ["83963.3", "0.006961"], ["83980.2", "1.966562"], ["83987.7", "0.125076"], ["83991.8", "0.276246"], ["83995.6", "0"], ["83995.7", "0.531136"], ["83996", "0.04"], ["83996.1", "0.04"], ["84008.7", "0.125076"], ["84009.2", "0.08934"], ["84010.2", "0"], ["84010.8", "0"], ["84013.6", "2.969344"], ["84024", "0"], ["84024.1", "0"], ["84024.6", "0"]], "u": 129240, "seq": 67571357236}, "cts": 1742577147312, "record_time": 1742577147.508014, "EXCHANGE": "BYBIT"}
{"topic": "orderbook.200.BTCUSDT", "ts": 1742577147519, "type": "delta", "data": {"s": "BTCUSDT", "b": [["83949.1", "0.952432"], ["83947.8", "0.0021"], ["83943.7", "0.292475"], ["83943.3", "0.023667"], ["83940.7", "0.02"], ["83937.3", "0.089099"], ["83934.9", "0"], ["83932", "0.17868"], ["83929.8", "0.214188"], ["83929.5", "0.234953"], ["83925.3", "0"], ["83919.1", "0.002933"], ["83914.6", "0.064666"], ["83914.5", "0.039632"], ["83912.1", "0.013"], ["83912", "0.012881"], ["83910.7", "0.00152"], ["83908.8", "0.381323"], ["83906.4", "0.019965"], ["83906.3", "0"], ["83903.9", "0"], ["83903.8", "0.125076"], ["83883.5", "0"]], "a": [["83949.2", "0.002093"], ["83956.9", "0.071499"], ["83958.1", "0"], ["83959.3", "0"], ["83959.9", "0.010419"], ["83975.7", "0"], ["83977.3", "0"], ["83979.9", "0.118996"], ["83995.6", "0.04"], ["83995.7", "0.571136"], ["83996", "0"], ["83996.1", "0"], ["83999.1", "0"], ["84009.2", "0"], ["84010", "0.17868"], ["84011.3", "0.357498"], ["84013.6", "2.611847"], ["84024", "0.001333"], ["84024.1", "0.028168"], ["84024.6", "0.0025"], ["84024.7", "0.000333"]], "u": 129241, "seq": 67571357449}, "cts": 1742577147507, "record_time": 1742577147.708171, "EXCHANGE": "BYBIT"}
{"topic": "orderbook.200.BTCUSDT", "ts": 1742577147720, "type": "delta", "data": {"s": "BTCUSDT", "b": [["83949.1", "0.956511"], ["83945.9", "0"], ["83940.6", "0.123183"], ["83935.9", "0.004909"], ["83934.9", "0.17868"], ["83930.8", "0.176224"], ["83929.5", "0.413633"], ["83925.3", "0.17868"], ["83921.7", "0.296832"], ["83908.9", "0.05"], ["83908.8", "0.430871"], ["83908.7", "0"], ["83908.6", "0"], ["83884.4", "0"], ["83883.8", "0"]], "a": [["83949.2", "0.00507"], ["83959.9", "0.010266"], ["83960.5", "0"], ["83965.8", "0.115294"], ["83967.3", "0"], ["83971.8", "0"], ["83975.6", "0.245434"], ["83984.7", "0.311762"], ["84009.2", "0.17868"], ["84009.9", "0.3575"], ["84010", "0"], ["84011.3", "0"], ["84013.4", "0.17868"]], "u": 129242, "seq": 67571357494}, "cts": 1742577147714, "record_time": 1742577147.908588, "EXCHANGE": "BYBIT"}
{"topic": "orderbook.200.BTCUSDT", "ts": 1742577147920, "type": "delta", "data": {"s": "BTCUSDT", "b": [["83945.4", "0.089099"], ["83940.7", "0.020145"], ["83940.6", "0"], ["83935.9", "0.001333"], ["83930.8", "0.001466"], ["83929.3", "0.003576"], ["83927.7", "0.023823"], ["83922.1", "0"], ["83921.7", "0"], ["83921.2", "0"], ["83917.2", "0.023356"], ["83914.6", "0.024666"], ["83914.5", "0"], ["83914.3", "0.039632"], ["83914.2", "0.039632"], ["83912.1", "0"], ["83912", "0"], ["83911.8", "0.096933"], ["83911.7", "0.012881"], ["83910.7", "0.359014"], ["83909.8", "0"], ["83908.9", "0"], ["83908.8", "0.023825"], ["83908.6", "0.049547"], ["83908.5", "0.069512"], ["83884.4", "0.004263"]], "a": [["83949.2", "0.002332"], ["83959.9", "0.004309"], ["83960.9", "0.005957"], ["83965.8", "0"], ["83967.2", "0"], ["83971.7", "0.015882"], ["83975.6", "0.071513"], ["83976.3", "0.11912"], ["83984.7", "0"], ["83994.2", "0"], ["83995.6", "0"], ["83995.7", "0.531136"], ["83995.9", "0.099399"], ["83996", "0.04"], ["84001.3", "0.023848"], ["84007.5", "0.17868"], ["84009.9", "0"], ["84011.3", "0.357494"]], "u": 129243, "seq": 67571357575}, "cts": 1742577147916, "record_time": 1742577148.108996, "EXCHANGE": "BYBIT"}
{"topic": "orderbook.200.BTCUSDT", "ts": 1742577148119, "type": "delta", "data": {"s": "BTCUSDT", "b": [["83949.1", "0.95658"], ["83945.4", "0"], ["83943.3", "0"], ["83929.3", "0"], ["83914.5", "0.04"], ["83914.4", "0.039632"], ["83914.3", "0"], ["83914.2", "0"], ["83910.7", "0.00152"], ["83908.8", "0.073825"], ["83908.7", "0.407047"], ["83908.6", "0"], ["83908.5", "0.019965"], ["83883.8", "0.00052"], ["83883.5", "0.048"], ["83883.4", "0.08934"]], "a": [["83949.2", "0.005309"], ["83955.5", "0.000298"], ["83955.6", "0.071798"], ["83956.9", "0"], ["83958.9", "0.0012"], ["83959.9", "0.010266"], ["83960.7", "0.000153"], ["83960.9", "0.023503"], ["83962.2", "0.071495"], ["83967.4", "0"], ["83971.8", "0.04"], ["83975.5", "0.123689"], ["83975.6", "0"], ["83982.2", "0.011923"], ["83995.7", "0.571136"], ["83995.8", "0.04"], ["83995.9", "0.059399"], ["83996", "0"], ["84007.5", "0"], ["84008.6", "0.3575"], ["84009.2", "0"], ["84011.3", "0"], ["84013.4", "0"], ["84025.3", "0.0005"]], "u": 129244, "seq": 67571357632}, "cts": 1742577148101, "record_time": 1742577148.308231, "EXCHANGE": "BYBIT"}
{"topic": "orderbook.200.BTCUSDT", "ts": 1742577148319, "type": "delta", "data": {"s": "BTCUSDT", "b": [["83949.1", "0.655173"], ["83945.5", "0.005765"], ["83943.7", "0.262475"], ["83937.3", "0"], ["83935.5", "0.06087"], ["83935.4", "0.025291"], ["83934.4", "0"], ["83929.5", "0.294506"], ["83928.5", "0.056897"], ["83927.4", "0"], ["83926.2", "0.001466"], ["83914.6", "0"], ["83912", "0.10953"], ["83911.9", "0.012881"], ["83911.8", "0.084052"], ["83911.7", "0"], ["83908.8", "0.431331"], ["83908.7", "0.049547"], ["83905.2", "0.001786"], ["83899.6", "0.024666"], ["83883.6", "0.000149"], ["83883.5", "0"], ["83883.4", "0"]], "a": [["83949.2", "0.176309"], ["83954", "0.071502"], ["83955.5", "0.052045"], ["83955.6", "0.000298"], ["83957.5", "0.005957"], ["83958.8", "0.059399"], ["83959.9", "0.004309"], ["83960.4", "0.071496"], ["83962.2", "0"], ["83968.5", "0.005309"], ["83970.5", "0.061284"], ["83977.3", "0.17868"], ["83977.5", "0.057681"], ["83979.9", "0.297676"], ["83980.2", "1.787882"], ["83984.1", "0.17868"], ["83991.1", "0.476574"], ["84008.5", "0.358027"], ["84008.6", "0"], ["84009.2", "0.08934"], ["84022.7", "0"], ["84023.7", "0"], ["84023.9", "0"], ["84024", "0"], ["84024.1", "0"], ["84024.6", "0"], ["84024.7", "0"], ["84025.3", "0"]], "u": 129245, "seq": 67571357727}, "cts": 1742577148317, "record_time": 1742577148.507997, "EXCHANGE": "BYBIT"}
{"topic": "orderbook.200.BTCUSDT", "ts": 1742577148520, "type": "delta", "data": {"s": "BTCUSDT", "b": [["83949.1", "0.593094"], ["83943.7", "0.091475"], ["83943.4", "0.011917"], ["83943", "0.019965"], ["83942.2", "0.019965"], ["83941.8", "0.071512"], ["83937.1", "0.023355"], ["83935.5", "0"], ["83935.4", "0.001466"], ["83929.8", "0.125089"], ["83928.5", "0"], ["83919.8", "0.000333"], ["83918.8", "0"], ["83914.5", "0"], ["83914.3", "0.039632"], ["83912", "0.09653"], ["83911.8", "0.096933"], ["83908.8", "0.023825"], ["83908.6", "0.049547"], ["83906", "0"], ["83903.4", "0"], ["83900.4", "5.664042"], ["83899.6", "0"], ["83898.2", "0.357538"], ["83883.5", "0.048"]], "a": [["83949.2", "0.192234"], ["83950.4", "0.028232"], ["83950.5", "0.071505"], ["83953.8", "0.005958"], ["83953.9", "0.049505"], ["83954", "0"], ["83955.5", "0"], ["83955.6", "0"], ["83956.5", "0.071499"], ["83957.5", "0"], ["83960.4", "0.071649"], ["83960.7", "0"], ["83962.8", "0.076709"], ["83964", "0"], ["83966.8", "0"], ["83970.5", "0"], ["83970.9", "0.178633"], ["83972.6", "0.083372"], ["83975.7", "0.17868"], ["83977.5", "0"], ["83984.1", "0"], ["83991.1", "1.429056"], ["83995.7", "0.531136"], ["83995.8", "0"], ["83996.2", "0.04"], ["83996.3", "0.04"], ["83997.1", "0.022831"], ["83998.3", "0.023107"], ["83999.1", "0.125076"], ["84002.9", "0.357528"], ["84008.5", "0.000524"], ["84010.8", "2.612013"], ["84013.6", "0"], ["84022.9", "0"], ["84023.2", "0"]], "u": 129246, "seq": 67571357889}, "cts": 1742577148515, "record_time": 1742577148.715429, "EXCHANGE": "BYBIT"}
{"topic": "orderbook.200.BTCUSDT", "ts": 1742577148720, "type": "delta", "data": {"s": "BTCUSDT", "b": [["83949.1", "0.501389"], ["83943.9", "0.088277"], ["83924.3", "0.093392"], ["83908.8", "0.073372"], ["83908.6", "0"], ["83903.9", "0.357526"], ["83898.2", "0"]], "a": [["83975.1", "0.17868"], ["83984.1", "0.17868"], ["83987.6", "0.6443"], ["83996.2", "0"], ["83996.3", "0"], ["83996.4", "0.091351"], ["83996.5", "0.04"], ["84002.9", "0"], ["84004.9", "0.357526"], ["84022.4", "0"]], "u": 129247, "seq": 67571357976}, "cts": 1742577148717, "record_time": 1742577148.907891, "EXCHANGE": "BYBIT"}
{"topic": "orderbook.200.BTCUSDT", "ts": 1742577148919, "type": "delta", "data": {"s": "BTCUSDT", "b": [["83949.1", "0.128446"], ["83948.9", "0"], ["83948.8", "0.1"], ["83947.8", "0"], ["83943.9", "0.021062"], ["83943.7", "0"], ["83943.4", "0"], ["83943", "0"], ["83942.2", "0"], ["83941.8", "0"], ["83941.2", "0"], ["83940.9", "0.117297"], ["83940.8", "0.129101"], ["83939.9", "0.059745"], ["83939.7", "0.004079"], ["83939", "0"], ["83938.6", "0.191965"], ["83937.1", "0"], ["83937", "0"], ["83936.8", "0"], ["83936.3", "0.057213"], ["83935.3", "0"], ["83934.9", "0"], ["83933.6", "0"], ["83932.1", "0.309644"], ["83932", "0"], ["83930.7", "0.181719"], ["83929.9", "0"], ["83929.8", "0"], ["83929.5", "0.092"], ["83929", "0.178722"], ["83928.9", "0"], ["83927.8", "0.009216"], ["83927.7", "0"], ["83927.3", "0.357406"], ["83926.6", "0.01997"], ["83925.4", "0.059921"], ["83925.3", "0"], ["83925.1", "0"], ["83924.2", "0"], ["83921.1", "0.17868"], ["83920.6", "0"], ["83919.4", "0.17868"], ["83918", "0.004387"], ["83917.4", "0"], ["83917.2", "0"], ["83916.9", "0.239545"], ["83912", "0"], ["83911.7", "0.132891"], ["83908.9", "0.024998"], ["83903.9", "0"], ["83901.6", "0.357543"], ["83900.4", "0"], ["83897.7", "5.664564"], ["83883.4", "0.08934"], ["83882.9", "0.125076"], ["83882.7", "0.049957"], ["83882.6", "0.118996"], ["83882.5", "0.01936"], ["83882.4", "0.00018"], ["83882", "0.000333"], ["83881.8", "0.005885"], ["83881.5", "0.027734"], ["83881.3", "0.045333"], ["83881.2", "0.023831"], ["83881", "0.048"], ["83880.2", "0.004263"], ["83880", "0.001526"], ["83879.7", "0.044"], ["83879.5", "0.011994"], ["83879.2", "0.00052"], ["83877.9", "0.224383"]], "a": [["83949.2", "0.496854"], ["83949.9", "0.000266"], ["83950.4", "0"], ["83950.5", "0"], ["83953.8", "0"], ["83953.9", "0.068748"], ["83954.4", "0.071501"], ["83960.2", "0.018984"], ["83960.4", "0"], ["83961.4", "0.009266"], ["83961.5", "0.001642"], ["83962.9", "0.060521"], ["83963.3", "0"], ["83970.9", "0"], ["83971.5", "0.17868"], ["83972.1", "0"], ["83972.3", "0.180146"], ["83974.2", "0.003576"], ["83974.9", "0"], ["83975.1", "0"], ["83976.3", "0"], ["83977.3", "0"], ["83979.9", "0.118996"], ["83984.1", "0"], ["83988.3", "0.08934"], ["83992.9", "0.023553"], ["83996.4", "0"], ["83996.6", "0.04"], ["84001.3", "0"], ["84002.9", "0.357547"], ["84004.9", "0.051354"], ["84010.8", "0"], ["84013.6", "2.612013"], ["84020.1", "0"], ["84022.4", "0.000614"], ["84022.9", "0.004436"], ["84023.2", "0.001466"], ["84023.7", "0.002735"]], "u": 129248, "seq": 67571358205}, "cts": 1742577148914, "record_time": 1742577149.108554, "EXCHANGE": "BYBIT"}
{"topic": "orderbook.200.BTCUSDT", "ts": 1742577149120, "type": "delta", "data": {"s": "BTCUSDT", "b": [["83949.1", "0.125561"], ["83948.8", "0"], ["83943.9", "0"], ["83940.8", "0.057588"], ["83939.9", "0.052855"], ["83939.5", "0.001"], ["83932.6", "0.178715"], ["83932.1", "0.195712"], ["83930.7", "0.003"], ["83929.4", "0.178722"], ["83929", "0"], ["83928.4", "0.223966"], ["83924.3", "0"], ["83921.9", "0.17868"], ["83919.7", "0"], ["83919.4", "0"], ["83908.8", "0.023825"], ["83908.6", "0.049547"], ["83901.6", "0.357539"], ["83877.8", "0.012328"]], "a": [["83949.2", "0.503811"], ["83971.4", "0.119354"], ["83972.6", "0.262052"], ["83973.3", "0.003576"], ["83974.2", "0"], ["83978.1", "0.125076"], ["84002.1", "0.051354"], ["84002.5", "2.612013"], ["84002.9", "0.357539"], ["84004.9", "0"], ["84013.6", "0"], ["84023.7", "0"]], "u": 129249, "seq": 67571358293}, "cts": 1742577149114, "record_time": 1742577149.308351, "EXCHANGE": "BYBIT"}
{"topic": "orderbook.200.BTCUSDT", "ts": 1742577149319, "type": "delta", "data": {"s": "BTCUSDT", "b": [["83949.1", "0.127347"], ["83946.7", "0.071508"], ["83942.6", "0.019591"], ["83939.1", "0.071514"], ["83937.3", "0.071516"], ["83932.1", "0.290229"], ["83929.3", "0.114004"], ["83924.4", "0.17877"], ["83922", "0.109478"], ["83919.9", "0.131699"], ["83909.5", "0.049546"], ["83909.4", "0.049546"], ["83908.7", "0"], ["83908.6", "0"], ["83901.7", "0.357537"], ["83901.6", "0"], ["83880", "0"], ["83879.7", "0"], ["83879.5", "0"], ["83879.2", "0"], ["83877.9", "0"], ["83877.8", "0"]], "a": [["83949.2", "0.487476"], ["83957.4", "0.009225"], ["83965.5", "0.002382"], ["83973.3", "0"], ["83979.9", "0.297676"], ["83996.4", "0.051354"], ["84002", "0.357537"], ["84002.1", "0"], ["84002.9", "0"], ["84023.2", "0"]], "u": 129250, "seq": 67571358370}, "cts": 1742577149316, "record_time": 1742577149.507213, "EXCHANGE": "BYBIT"}
{"topic": "orderbook.200.BTCUSDT", "ts": 1742577149519, "type": "delta", "data": {"s": "BTCUSDT", "b": [["83949.1", "0.298347"], ["83948.5", "0.071506"], ["83946.7", "0"], ["83943.4", "0.042359"], ["83943.3", "0.071511"], ["83942.6", "0"], ["83941", "0.071513"], ["83939.1", "0"], ["83937.7", "0.007035"], ["83937.3", "0"], ["83936.3", "0.082764"], ["83934.7", "0.231102"], ["83933.1", "0.178714"], ["83932.6", "0"], ["83932.3", "0.061855"], ["83931.4", "0.178717"], ["83930.2", "0.024216"], ["83929.4", "0"], ["83927.3", "0.17868"], ["83925.3", "0.059394"], ["83921.9", "0"], ["83918.3", "0.113038"], ["83916.9", "0.060865"], ["83914.7", "0.04"], ["83914.6", "0.039632"], ["83914.4", "0"], ["83914.3", "0"], ["83912.2", "0.062965"], ["83912.1", "0.012881"], ["83911.9", "0"], ["83911.8", "0.084052"], ["83909.5", "0"], ["83909.4", "0"], ["83909", "0.05"], ["83908.9", "0.074545"], ["83901.8", "0.357541"], ["83901.7", "0"], ["83900.4", "5.68799"], ["83897.7", "0.000522"], ["83882.9", "0"], ["83881.2", "0"], ["83881", "0"], ["83880.2", "0"]], "a": [["83949.2", "0.254856"], ["83949.9", "0"], ["83950.3", "0.071505"], ["83952.7", "0.005958"], ["83953.2", "0.007147"], ["83954.4", "0"], ["83957.4", "0"], ["83958.8", "0.130896"], ["83967.3", "0.054938"], ["83971.4", "0.000358"], ["83972", "0.003756"], ["83991.1", "1.469056"], ["83991.2", "0.063825"], ["83996.5", "0"], ["83996.6", "0"], ["84001.9", "0.362478"], ["84002", "0"], ["84023.2", "0.001466"], ["84023.7", "0.002735"]], "u": 129251, "seq": 67571358504}, "cts": 1742577149516, "record_time": 1742577149.707199, "EXCHANGE": "BYBIT"}
{"topic": "orderbook.200.BTCUSDT", "ts": 1742577149720, "type": "delta", "data": {"s": "BTCUSDT", "b": [["83936.3", "0.154094"], ["83932.3", "0"], ["83929.8", "0.17868"], ["83927.3", "0"], ["83925.3", "0.17868"], ["83922", "0"], ["83921.2", "0.17443"], ["83918.3", "0"], ["83914.5", "0.13292"], ["83911.7", "0"], ["83909.6", "0.054377"], ["83909.5", "0.049546"], ["83909", "0"], ["83908.9", "0.024998"], ["83904.5", "0.357531"], ["83901.8", "0"], ["83881.2", "0.023831"], ["83881", "0.048"]], "a": [["83950.3", "0"], ["83950.4", "0.030376"], ["83950.5", "0.071505"], ["83953.2", "0"], ["83953.9", "0.001466"], ["83955.7", "0.033291"], ["83956.5", "0"], ["83958.7", "0.158685"], ["83959", "0"], ["83961.1", "0.071496"], ["83967.3", "0"], ["83971.7", "0.153494"], ["83972", "0.00018"], ["83997.1", "0"], ["84001.9", "0.004932"], ["84004.9", "0.357531"], ["84023.9", "0.118996"]], "u": 129252, "seq": 67571358614}, "cts": 1742577149712, "record_time": 1742577149.90817, "EXCHANGE": "BYBIT"}
{"topic": "orderbook.200.BTCUSDT", "ts": 1742577149920, "type": "delta", "data": {"s": "BTCUSDT", "b": [["83949.1", "0.125561"], ["83943.4", "0.020905"], ["83943.3", "0"], ["83941", "0"], ["83938.8", "0.071514"], ["83938.6", "0.172"], ["83937.7", "0"], ["83921.1", "0"], ["83919.9", "0"], ["83914.5", "0"], ["83912.7", "0.102099"], ["83912.6", "0.048436"], ["83912.2", "0.049965"], ["83912.1", "0"], ["83911.7", "0.13292"], ["83909.6", "0.004377"], ["83909.4", "0.049546"], ["83904.5", "0"], ["83901.6", "0.357542"], ["83900.4", "5.63531"], ["83880.2", "0.004263"], ["83880", "0.001526"], ["83879.7", "0.044"], ["83879.5", "0.011994"]], "a": [["83949.2", "0.3901"], ["83949.5", "0.028232"], ["83949.6", "0.071505"], ["83950.4", "0"], ["83950.5", "0"], ["83952.7", "0"], ["83953.2", "0.007179"], ["83955.3", "0.073107"], ["83955.4", "0.0715"], ["83955.7", "0.004405"], ["83957.1", "0.071499"], ["83958.7", "0"], ["83958.8", "0.059399"], ["83959.9", "0.088266"], ["83961.1", "0"], ["83961.6", "0.001642"], ["83972.2", "0.118996"], ["83996.3", "0.11798"], ["84002.4", "0.357542"], ["84004.9", "0"], ["84022.9", "0"], ["84023.2", "0"], ["84023.7", "0"], ["84023.9", "0"]], "u": 129253, "seq": 67571358739}, "cts": 1742577149916, "record_time": 1742577150.108085, "EXCHANGE": "BYBIT"}
{"topic": "orderbook.200.BTCUSDT", "ts": 1742577150120, "type": "delta", "data": {"s": "BTCUSDT", "b": [["83949.1", "0.129287"], ["83943.4", "0.039745"], ["83942.7", "0.071511"], ["83921.2", "0"], ["83921.1", "0.17868"], ["83915.2", "0.164708"], ["83915.1", "0.308114"], ["83914.7", "0"], ["83914.6", "0"], ["83912.7", "0.10198"], ["83911.7", "0.132895"], ["83901.7", "0.357537"], ["83901.6", "0"], ["83879.2", "0.00052"]], "a": [["83949.2", "0.2191"], ["83955.2", "0.009225"], ["83955.3", "0.050336"], ["83955.4", "0"], ["83959.6", "0.071497"], ["83968.2", "0.003576"], ["83990.4", "0.041333"], ["83990.5", "0.04"], ["83991.1", "1.429056"], ["83991.2", "0.023825"], ["84002.3", "0.357537"], ["84002.4", "0"], ["84022.2", "0"], ["84022.3", "0"], ["84022.4", "0"]], "u": 129254, "seq": 67571358861}, "cts": 1742577150115, "record_time": 1742577150.308104, "EXCHANGE": "BYBIT"}
{"topic": "orderbook.200.BTCUSDT", "ts": 1742577150320, "type": "delta", "data": {"s": "BTCUSDT", "b": [["83949.1", "0.300287"], ["83944.5", "0.064368"], ["83944.4", "0.07151"], ["83943.4", "0"], ["83941.1", "0"], ["83938.8", "0"], ["83932.3", "0.17868"], ["83929.8", "0"], ["83915.2", "0.125076"], ["83915.1", "0.268482"], ["83914.8", "0.039632"], ["83914.7", "0.039632"], ["83912.7", "0.089099"], ["83912.6", "0.035555"], ["83912.3", "0.582231"], ["83912.2", "0.062846"], ["83909.5", "0"], ["83909.4", "0"], ["83909.1", "0.083407"], ["83909", "0.049547"], ["83904.5", "0.357523"], ["83901.7", "0"]], "a": [["83949.2", "0.271169"], ["83952.7", "0.005958"], ["83968.2", "0"], ["83990.4", "0.001333"], ["83990.5", "0"], ["83991", "0.04"], ["83991.1", "1.469056"], ["84002.3", "0"], ["84006.6", "0.357522"]], "u": 129255, "seq": 67571358957}, "cts": 1742577150317, "record_time": 1742577150.507818, "EXCHANGE": "BYBIT"}
{"topic": "orderbook.200.BTCUSDT", "ts": 1742577150519, "type": "delta", "data": {"s": "BTCUSDT", "b": [["83940.4", "0.001"], ["83937.7", "0.007006"], ["83936.5", "0.122813"], ["83932.3", "0"], ["83926.7", "0.175994"], ["83924.4", "0.00009"], ["83921.1", "0"], ["83917.6", "0.304584"], ["83914.8", "0"], ["83914.7", "0"], ["83914.5", "0.132895"], ["83914.2", "0.039632"], ["83914.1", "0.039633"], ["83912.3", "0.56935"], ["83912.2", "0.049965"], ["83911.7", "0.012881"], ["83911.6", "0.012881"], ["83909.1", "0.03386"], ["83909", "0"], ["83908.5", "0.069512"], ["83908.4", "0.049548"], ["83907.2", "0.357852"], ["83904.5", "0"], ["83880", "0"], ["83879.7", "0"], ["83879.5", "0"], ["83879.2", "0"]], "a": [["83949.2", "0.247437"], ["83953.2", "0"], ["83953.5", "0"], ["83959.5", "0.142734"], ["83959.9", "0.004309"], ["83960.6", "0.0003"], ["83961.7", "0.119818"], ["83962.9", "0.04"], ["83971.5", "0.364296"], ["83974.8", "0.17868"], ["83980.6", "0.289541"], ["83991", "0"], ["83991.1", "1.429056"], ["83992.2", "0.04"], ["83992.3", "0.04"], ["84002.5", "0"], ["84005.3", "2.612096"], ["84006.6", "0"], ["84008.6", "0.357518"], ["84019.8", "0"], ["84020.5", "0"], ["84020.7", "0"]], "u": 129256, "seq": 67571359090}, "cts": 1742577150517, "record_time": 1742577150.707559, "EXCHANGE": "BYBIT"}
{"topic": "orderbook.200.BTCUSDT", "ts": 1742577150720, "type": "delta", "data": {"s": "BTCUSDT", "b": [["83936.5", "0"], ["83932.3", "0.17868"], ["83932", "0.17868"], ["83928.7", "0"], ["83926.7", "0"], ["83917.6", "0"], ["83912.7", "0.610638"], ["83908.6", "0.05"], ["83908.4", "0"], ["83907.2", "0.000333"], ["83907.1", "0.40131"], ["83880", "0.001526"], ["83879.7", "0.044"]], "a": [["83949.2", "0.307087"], ["83959.5", "0.106788"], ["83961.7", "0"], ["83971.5", "0.17868"], ["83979.6", "0.531136"], ["83980.6", "0"], ["83992.2", "0"], ["83992.4", "0.04"], ["83995.7", "0"], ["84019", "1.028339"], ["84019.8", "0.004483"]], "u": 129257, "seq": 67571359182}, "cts": 1742577150714, "record_time": 1742577150.908561, "EXCHANGE": "BYBIT"}
{"topic": "orderbook.200.BTCUSDT", "ts": 1742577150919, "type": "delta", "data": {"s": "BTCUSDT", "b": [["83949.1", "0.129287"], ["83948.4", "0"], ["83944.5", "0"], ["83944.4", "0"], ["83944", "0.07151"], ["83942.7", "0"], ["83942.6", "0.019591"], ["83940.3", "0.071513"], ["83937.7", "0"], ["83932.3", "0"], ["83932.1", "0.195712"], ["83932", "0"], ["83929.8", "0.17868"], ["83925.4", "0.000522"], ["83925.3", "0"], ["83924.4", "0.17877"], ["83915.1", "0.447152"], ["83912.8", "0.013"], ["83912.7", "0.623519"], ["83911.7", "0"], ["83911.6", "0.015"], ["83909", "0.05"], ["83908.9", "0.074545"], ["83908.6", "0"], ["83908.5", "0.019965"], ["83907.1", "0.04379"], ["83901.6", "0.357536"], ["83900.4", "5.593408"], ["83879.5", "0.011994"], ["83879.2", "0.00052"], ["83877.9", "0.224383"]], "a": [["83949.2", "0.287975"], ["83952.7", "0"], ["83953.2", "0.006938"], ["83955.2", "0"], ["83955.5", "0.0715"], ["83956", "0"], ["83957.1", "0"], ["83959.5", "0.178285"], ["83959.6", "0"], ["83960.2", "0.057742"], ["83961.4", "0.010908"], ["83971.7", "0.224523"], ["83991.8", "0.125502"], ["83992.3", "0"], ["83992.5", "0.04"], ["84002.9", "0.357533"], ["84005.3", "0.000083"], ["84008.6", "0"], ["84010.8", "2.612013"], ["84019.8", "0.175483"], ["84020.5", "0.000333"], ["84020.7", "0.011865"]], "u": 129258, "seq": 67571359337}, "cts": 1742577150917, "record_time": 1742577151.108098, "EXCHANGE": "BYBIT"}
{"topic": "orderbook.200.BTCUSDT", "ts": 1742577151119, "type": "delta", "data": {"s": "BTCUSDT", "b": [["83949.1", "0.127501"], ["83944.1", "0.042515"], ["83942.6", "0"], ["83927.3", "0.17868"], ["83924.4", "0.00009"], ["83916.9", "0.239545"], ["83915.3", "0.04"], ["83915.2", "0.164708"], ["83914.2", "0"], ["83914.1", "0"], ["83909.6", "0.054377"], ["83909.5", "0.049546"], ["83909", "0"], ["83908.9", "0.024998"], ["83904.5", "0.357533"], ["83901.6", "0"]], "a": [["83949.2", "0.459128"], ["83971.5", "0"], ["83972.3", "0.001466"], ["83972.6", "0.440682"], ["83973.7", "0.027401"], ["83974.8", "0"], ["83990.1", "0.04"], ["83990.2", "0.04"], ["83992.4", "0"], ["83992.5", "0"], ["84002.5", "2.612013"], ["84010.8", "0"], ["84022.2", "0.011994"], ["84022.3", "0.011994"]], "u": 129259, "seq": 67571359437}, "cts": 1742577151108, "record_time": 1742577151.308381, "EXCHANGE": "BYBIT"}
{"topic": "orderbook.200.BTCUSDT", "ts": 1742577151319, "type": "delta", "data": {"s": "BTCUSDT", "b": [["83940.9", "0.120297"], ["83921.9", "0.17868"], ["83921.1", "0.17868"], ["83904.5", "0"], ["83901.6", "0.357536"], ["83879.2", "0"], ["83877.9", "0"]], "a": [["83974.8", "0.17868"], ["83979.8", "0.000671"], ["84002.4", "0.357536"], ["84002.9", "0"], ["84022.3", "0"]], "u": 129260, "seq": 67571359490}, "cts": 1742577151318, "record_time": 1742577151.506998, "EXCHANGE": "BYBIT"}
{"topic": "orderbook.200.BTCUSDT", "ts": 1742577151519, "type": "delta", "data": {"s": "BTCUSDT", "b": [["83949.1", "0.127347"], ["83944.4", "0.0023"], ["83920.4", "0"], ["83919.1", "0.001333"], ["83917.4", "0.132915"], ["83915.7", "0.0046"], ["83914.5", "0"], ["83889", "0.000204"]], "a": [["83949.2", "0.272792"], ["83949.5", "0.03419"], ["83954.5", "0.009225"], ["83960.5", "0.0003"], ["83960.6", "0"], ["83977.3", "0.17868"], ["84020.7", "0"], ["84022.2", "0"]], "u": 129261, "seq": 67571359598}, "cts": 1742577151518, "record_time": 1742577151.708161, "EXCHANGE": "BYBIT"}
{"topic": "orderbook.200.BTCUSDT", "ts": 1742577151720, "type": "delta", "data": {"s": "BTCUSDT", "b": [["83936.7", "0.00691"], ["83927.3", "0"], ["83925.7", "0.035743"], ["83921.9", "0"], ["83917", "0.023824"], ["83916.9", "0.060865"], ["83915.3", "0"], ["83915.2", "0.165076"], ["83915.1", "0.486784"], ["83912.8", "0"], ["83912.7", "0.623638"], ["83912.6", "0.048436"], ["83909.6", "0.004377"], ["83909.5", "0.05"], ["83909.4", "0.049546"], ["83903.9", "0.357533"], ["83901.6", "0"]], "a": [["83949.5", "0.028232"], ["83952.7", "0.005958"], ["83953.2", "0"], ["83977.3", "0"], ["83990.1", "0"], ["83990.3", "0.045956"], ["84002.4", "0"], ["84004.9", "0.357533"], ["84020.1", "0.125076"], ["84020.7", "0.011865"]], "u": 129262, "seq": 67571359695}, "cts": 1742577151714, "record_time": 1742577151.908206, "EXCHANGE": "BYBIT"}
{"topic": "orderbook.200.BTCUSDT", "ts": 1742577151919, "type": "delta", "data": {"s": "BTCUSDT", "b": [["83949.1", "0.126161"], ["83944.1", "0.021062"], ["83944", "0"], ["83936.7", "0"], ["83934.9", "0.109591"], ["83928.4", "0.157912"], ["83927.3", "0.17868"], ["83925.1", "0.179874"], ["83921.9", "0.17868"], ["83917.5", "0.126329"], ["83917.4", "0"], ["83916.9", "0.239545"], ["83916", "0.300433"], ["83915.2", "0.164708"], ["83912.7", "0.623519"], ["83911.7", "0.132912"], ["83909.5", "0.049546"], ["83903.9", "0"], ["83901.6", "0.357541"], ["83900.4", "0"], ["83879.5", "0"]], "a": [["83949.2", "0.458975"], ["83949.6", "0.071658"], ["83952.7", "0"], ["83953.2", "0.007009"], ["83954.5", "0"], ["83960.1", "0.124116"], ["83967", "0.118996"], ["83969.9", "0.172921"], ["83972.6", "0.17863"], ["83979", "0.301348"], ["83990.2", "0"], ["83990.4", "0.041333"], ["84002.4", "0.357541"], ["84004.9", "0"], ["84020.1", "0"], ["84020.7", "0"]], "u": 129263, "seq": 67571359810}, "cts": 1742577151916, "record_time": 1742577152.107767, "EXCHANGE": "BYBIT"}
{"topic": "orderbook.200.BTCUSDT", "ts": 1742577152120, "type": "delta", "data": {"s": "BTCUSDT", "b": [["83949.1", "0.12784"], ["83934.9", "0"], ["83928.4", "0.217214"], ["83925.1", "0"], ["83916", "0.00009"], ["83913.1", "0.024989"], ["83908.9", "0"], ["83901.6", "0"], ["83899.1", "0.357543"], ["83897.7", "5.562404"], ["83879.5", "0.011994"], ["83879.2", "0.00052"]], "a": [["83960.1", "0"], ["83969.9", "0"], ["83971.7", "0.166152"], ["83979", "0"], ["83990.2", "0.04"], ["83990.4", "0.001333"], ["84020.7", "0.011865"], ["84022.2", "0.011994"]], "u": 129264, "seq": 67571359869}, "cts": 1742577152098, "record_time": 1742577152.308429, "EXCHANGE": "BYBIT"}
{"topic": "orderbook.200.BTCUSDT", "ts": 1742577152320, "type": "delta", "data": {"s": "BTCUSDT", "b": [["83948.5", "0"], ["83944.1", "0"], ["83942.6", "0.041045"], ["83941.9", "0.071512"], ["83940.3", "0"], ["83938.6", "0.243515"], ["83936.3", "0.110826"], ["83933.1", "0"], ["83930.5", "0.178719"], ["83930.2", "0"], ["83929.4", "0.056448"], ["83922.4", "0.060046"], ["83915.4", "0.121443"], ["83915.2", "0.125076"], ["83915.1", "0.447152"], ["83915", "0.158996"], ["83914.9", "0.040965"], ["83912.7", "0.610638"], ["83912.6", "0.035555"], ["83912.5", "0.013"], ["83912.4", "0.012881"], ["83909.5", "0"], ["83909.4", "0"], ["83909.3", "0.07024"], ["83909.2", "0.049547"], ["83899.2", "0.357636"], ["83899.1", "0"], ["83879.2", "0"]], "a": [["83949.5", "0.046425"], ["83949.6", "0.071505"], ["83953.8", "0.071502"], ["83959.5", "0.106788"], ["83960", "0.038794"], ["83964.4", "0.061983"], ["83971.4", "0.056471"], ["83972.6", "0"], ["83978.4", "0.114596"], ["83990", "0.040524"], ["83990.1", "0.04"], ["83990.2", "0"], ["83990.3", "0.005956"], ["83992.9", "0"], ["83996.1", "0.022831"], ["83997", "2.612013"], ["83997.2", "0.048431"], ["84002.3", "0.357546"], ["84002.4", "0"], ["84002.5", "0"], ["84020.7", "0"], ["84022.2", "0"]], "u": 129265, "seq": 67571359967}, "cts": 1742577152312, "record_time": 1742577152.508205, "EXCHANGE": "BYBIT"}
{"topic": "orderbook.200.BTCUSDT", "ts": 1742577152520, "type": "delta", "data": {"s": "BTCUSDT", "b": [["83949.1", "0.197667"], ["83943.7", "0.07151"], ["83938.6", "0.172"], ["83935.7", "0.006979"], ["83935.5", "0.120415"], ["83929.4", "0"], ["83925", "0.188214"], ["83922.4", "0"], ["83918", "0.297253"], ["83915.4", "0"], ["83915.1", "0.487152"], ["83915", "0.158628"], ["83914.9", "0.001333"], ["83912.6", "0.048555"], ["83912.5", "0.012881"], ["83912.4", "0"], ["83909.4", "0.05"], ["83909.3", "0.069787"], ["83909.2", "0"], ["83901.6", "0.357541"], ["83900.4", "5.561882"], ["83899.2", "0.00009"], ["83897.7", "0.000522"], ["83879.5", "0"]], "a": [["83949.2", "0.443945"], ["83949.5", "0.03419"], ["83953.8", "0"], ["83956.1", "0.009225"], ["83957.9", "0.071498"], ["83960", "0.156509"], ["83964.4", "0"], ["83970.5", "0.175433"], ["83971.4", "0.000358"], ["83971.7", "0"], ["83973.7", "0.023825"], ["83977.5", "0.285234"], ["83978.4", "0"], ["83989.7", "0.04"], ["83989.8", "0.04"], ["83990", "0.000524"], ["83990.1", "0"], ["83996.1", "0"], ["83997", "0"], ["84002.3", "0"], ["84002.5", "2.612013"], ["84002.9", "0.357539"]], "u": 129266, "seq": 67571360057}, "cts": 1742577152516, "record_time": 1742577152.707965, "EXCHANGE": "BYBIT"}
{"topic": "orderbook.200.BTCUSDT", "ts": 1742577152719, "type": "delta", "data": {"s": "BTCUSDT", "b": [["83943.8", "0.064334"], ["83942.6", "0"], ["83935.5", "0"], ["83930.1", "0.02433"], ["83925", "0.004622"], ["83924.4", "0.17877"], ["83921.9", "0"], ["83918", "0.004387"], ["83901.6", "0"], ["83895.1", "0.357543"], ["83879.5", "0.011994"], ["83879.2", "0.00052"]], "a": [["83949.2", "0.449903"], ["83949.5", "0.028232"], ["83960", "0.038794"], ["83970.5", "0"], ["83977.3", "0.003449"], ["83977.5", "0"], ["84002.4", "0.357542"], ["84002.9", "0"], ["84020.1", "0.125076"]], "u": 129267, "seq": 67571360108}, "cts": 1742577152713, "record_time": 1742577152.907449, "EXCHANGE": "BYBIT"}
{"topic": "orderbook.200.BTCUSDT", "ts": 1742577152919, "type": "delta", "data": {"s": "BTCUSDT", "b": [["83921.2", "0.053941"], ["83915.1", "0.486784"], ["83912.7", "0.623638"], ["83912.6", "0.048436"], ["83912.5", "0"], ["83909.5", "0.05"], ["83909.4", "0.049546"], ["83909.3", "0.02024"], ["83900.4", "5.576512"], ["83879.5", "1.79879"], ["83879.2", "0"]], "a": [["83949.2", "0.44975"], ["83961.5", "0"], ["83999", "0.357549"], ["84002.4", "0"], ["84020.7", "0.011865"]], "u": 129268, "seq": 67571360150}, "cts": 1742577152913, "record_time": 1742577153.107062, "EXCHANGE": "BYBIT"}
{"topic": "orderbook.200.BTCUSDT", "ts": 1742577153120, "type": "delta", "data": {"s": "BTCUSDT", "b": [["83949.1", "0.198869"], ["83943.8", "0.059039"], ["83939.5", "0"], ["83915.2", "0.165076"], ["83915", "0.118996"], ["83914.5", "0.132912"], ["83911.7", "0"], ["83879.2", "0.00052"]], "a": [["83949.3", "0.001977"], ["83960.2", "0.059384"], ["83989.4", "0.04"], ["83989.5", "0.04"], ["83989.7", "0"], ["83989.8", "0"]], "u": 129269, "seq": 67571360219}, "cts": 1742577153117, "record_time": 1742577153.308322, "EXCHANGE": "BYBIT"}
{"topic": "orderbook.200.BTCUSDT", "ts": 1742577153320, "type": "delta", "data": {"s": "BTCUSDT", "b": [["83921.9", "0.17868"], ["83879.2", "0"]], "a": [["83949.3", "0.001824"], ["83950", "0.000153"], ["84020.1", "0"]], "u": 129270, "seq": 67571360256}, "cts": 1742577153296, "record_time": 1742577153.507686, "EXCHANGE": "BYBIT"}
{"topic": "orderbook.200.BTCUSDT", "ts": 1742577153520, "type": "delta", "data": {"s": "BTCUSDT", "b": [["83949.1", "0.198999"], ["83921.9", "0"], ["83908.2", "0.096535"]], "a": [["83949.2", "0.469355"], ["83949.6", "0"], ["83950", "0"], ["83950.7", "0.000153"], ["83950.8", "0.071504"], ["83955.5", "0"], ["83960", "0.11029"], ["83967", "0"], ["83977.3", "0"], ["83999", "0.35755"], ["84022.2", "0.011994"], ["84022.3", "0.011994"], ["84022.4", "0.000614"]], "u": 129271, "seq": 67571360307}, "cts": 1742577153511, "record_time": 1742577153.708642, "EXCHANGE": "BYBIT"}
{"topic": "orderbook.200.BTCUSDT", "ts": 1742577153720, "type": "delta", "data": {"s": "BTCUSDT", "b": [["83915.2", "0.125076"], ["83915.1", "0.447152"], ["83915", "0.158628"], ["83914.9", "0.040965"], ["83912.7", "0.610638"], ["83912.6", "0.035555"], ["83912.5", "0.012881"], ["83912.4", "0.012881"], ["83909.5", "0"], ["83909.4", "0"], ["83909.3", "0.069787"], ["83909.2", "0.049547"], ["83879.5", "0"]], "a": [["83949.2", "0.292397"], ["83949.4", "0.005958"], ["83950.7", "0"], ["83950.8", "0.071657"], ["83960.4", "0.0003"], ["83960.5", "0"], ["83969.4", "0.289734"], ["83989.4", "0"], ["83989.5", "0"], ["83990", "0.040524"], ["83990.1", "0.04"], ["83998.9", "0.357548"], ["83999", "0"], ["84020.1", "0.125076"]], "u": 129272, "seq": 67571360384}, "cts": 1742577153709, "record_time": 1742577153.908239, "EXCHANGE": "BYBIT"}
{"topic": "orderbook.200.BTCUSDT", "ts": 1742577153920, "type": "delta", "data": {"s": "BTCUSDT", "b": [["83949.1", "0.200785"], ["83935.7", "0.116003"], ["83925.2", "0.169289"], ["83919.3", "0.11912"], ["83918.2", "0.288889"], ["83912.6", "0.048555"], ["83912.4", "0"], ["83911.8", "0.12334"], ["83909.4", "0.05"], ["83909.2", "0"], ["83880", "0"], ["83879.7", "0"]], "a": [["83950.8", "0.071504"], ["83960.2", "0.180821"], ["83961.6", "0"], ["83966.4", "0.035744"], ["83968.5", "0"], ["83969.2", "0.11912"], ["83970.7", "0.17664"], ["83971.5", "0.001294"], ["83972.1", "0.099436"], ["83972.7", "0.001375"], ["83977.3", "0.17868"], ["83977.7", "0.300864"], ["83998.8", "0.358881"], ["83998.9", "0"], ["84020.5", "0"], ["84020.7", "0"], ["84022.2", "0"], ["84022.3", "0"], ["84022.4", "0"]], "u": 129273, "seq": 67571360431}, "cts": 1742577153906, "record_time": 1742577154.108668, "EXCHANGE": "BYBIT"}
{"topic": "orderbook.200.BTCUSDT", "ts": 1742577154120, "type": "delta", "data": {"s": "BTCUSDT", "b": [["83949.1", "0.199985"], ["83943.7", "0"], ["83939.5", "0.071514"], ["83935.7", "0.006979"], ["83927.3", "0"], ["83925.3", "0.17868"], ["83925.2", "0"], ["83924.4", "0.00009"], ["83918.2", "0"], ["83915.1", "0.487152"], ["83914.9", "0.001333"], ["83900.4", "5.586887"], ["83880", "0.001526"], ["83879.7", "0.044"]], "a": [["83949.2", "0.469355"], ["83949.4", "0"], ["83949.9", "0.071505"], ["83950.8", "0"], ["83951.3", "0.000153"], ["83955.9", "0.0765"], ["83960", "0.038794"], ["83960.2", "0.059384"], ["83970.7", "0"], ["83971.5", "0"], ["83972.7", "0"], ["83977.7", "0"], ["83989.7", "0.04"], ["83989.8", "0.04"], ["83990", "0.000524"], ["83990.1", "0"], ["83998.8", "0.001333"], ["84002.4", "0.357548"], ["84020.5", "0.000333"], ["84020.7", "0.011865"]], "u": 129274, "seq": 67571360499}, "cts": 1742577154116, "record_time": 1742577154.307891, "EXCHANGE": "BYBIT"}
{"topic": "orderbook.200.BTCUSDT", "ts": 1742577154319, "type": "delta", "data": {"s": "BTCUSDT", "b": [["83949.1", "0.198199"], ["83943.9", "0.063968"], ["83943.8", "0.072032"], ["83939.5", "0"], ["83927.3", "0.17868"], ["83924.4", "0.17877"], ["83916.9", "0.060865"], ["83879.7", "0"]], "a": [["83949.2", "0.292397"], ["83949.4", "0.005958"], ["83949.9", "0"], ["83951", "0.071504"], ["83953.2", "0"], ["83955.9", "0.005"], ["83960", "0.11029"], ["83989.7", "0"], ["83989.8", "0"], ["83989.9", "0.04"], ["83990", "0.040524"], ["83999", "0.357548"], ["84002.4", "0"], ["84022.2", "0.011994"]], "u": 129275, "seq": 67571360565}, "cts": 1742577154316, "record_time": 1742577154.507638, "EXCHANGE": "BYBIT"}
{"topic": "orderbook.200.BTCUSDT", "ts": 1742577154520, "type": "delta", "data": {"s": "BTCUSDT", "b": [["83949.1", "0.198768"], ["83940.4", "0"], ["83929.3", "0"], ["83926.1", "0.284988"], ["83925.7", "0"], ["83925.6", "0.035744"], ["83917.5", "0.003575"], ["83879.7", "0.044"], ["83879.5", "1.79879"]], "a": [["83949.2", "0.469355"], ["83949.4", "0"], ["83951.3", "0"], ["83951.6", "0.000153"], ["83956.4", "0.0715"], ["83957.9", "0"], ["83989.5", "0.04"], ["83989.6", "0.04"], ["83989.9", "0"], ["83990", "0.000524"], ["83999", "0"], ["84002.4", "0.357549"]], "u": 129276, "seq": 67571360653}, "cts": 1742577154512, "record_time": 1742577154.708359, "EXCHANGE": "BYBIT"}
{"topic": "orderbook.200.BTCUSDT", "ts": 1742577154719, "type": "delta", "data": {"s": "BTCUSDT", "b": [], "a": [["83949.7", "0.071505"], ["83950.5", "0.000153"], ["83951", "0"], ["83951.6", "0"], ["83953.2", "0.00696"], ["83971.2", "0.001458"], ["83977.3", "0"], ["83999", "0.35755"], ["84002.4", "0"], ["84022.2", "0"]], "u": 129277, "seq": 67571360706}, "cts": 1742577154710, "record_time": 1742577154.907363, "EXCHANGE": "BYBIT"}
{"topic": "orderbook.200.BTCUSDT", "ts": 1742577154920, "type": "delta", "data": {"s": "BTCUSDT", "b": [["83919.4", "0.121404"], ["83909.4", "0.049546"], ["83900.4", "5.601697"], ["83879.5", "0"]], "a": [["83949.7", "0"], ["83949.9", "0.071505"], ["83950.5", "0"], ["83951.7", "0.003153"], ["83953.2", "0"], ["83961.4", "0.009266"], ["83972.3", "0.180146"], ["83974.8", "0"], ["83989.5", "0"], ["83989.6", "0"], ["83989.7", "0.04"], ["83989.8", "0.04"], ["84006.7", "0"], ["84017.9", "0.353923"], ["84020.1", "0"], ["84022.2", "0.011994"], ["84022.3", "0.011994"], ["84022.4", "0.000614"], ["84022.9", "0.004436"]], "u": 129278, "seq": 67571360759}, "cts": 1742577154909, "record_time": 1742577155.108387, "EXCHANGE": "BYBIT"}
{"topic": "orderbook.200.BTCUSDT", "ts": 1742577155119, "type": "delta", "data": {"s": "BTCUSDT", "b": [["83949.1", "0.190086"]], "a": [["83949.2", "0.478535"], ["83949.5", "0.071505"], ["83949.9", "0"], ["83950.8", "0.0264"], ["83972.3", "0.001466"], ["83974.8", "0.17868"], ["84022.9", "0"]], "u": 129279, "seq": 67571360820}, "cts": 1742577155117, "record_time": 1742577155.307954, "EXCHANGE": "BYBIT"}
{"topic": "orderbook.200.BTCUSDT", "ts": 1742577155319, "type": "delta", "data": {"s": "BTCUSDT", "b": [["83926.2", "0.060865"]], "a": [["83949.2", "0.479365"], ["83949.4", "0.0264"], ["83950.8", "0"], ["83951.7", "0.003"], ["83953.2", "0.006949"], ["83954.9", "0.071501"], ["83960", "0.038794"], ["83971.2", "0"], ["83973.1", "0.003576"], ["83977.3", "0.17868"], ["84020.1", "0.125076"], ["84020.7", "0"], ["84022.2", "0"], ["84022.3", "0"], ["84022.4", "0"]], "u": 129280, "seq": 67571360851}, "cts": 1742577155312, "record_time": 1742577155.508287, "EXCHANGE": "BYBIT"}
{"topic": "orderbook.200.BTCUSDT", "ts": 1742577155520, "type": "delta", "data": {"s": "BTCUSDT", "b": [["83949.1", "0.406678"], ["83939.4", "0.001"], ["83928.4", "0.315063"], ["83924.4", "0.00009"], ["83921.1", "0"], ["83917.3", "0.132917"], ["83915.1", "0.447152"], ["83914.9", "0.040965"], ["83914.5", "0"], ["83912.6", "0.035555"], ["83912.4", "0.012881"], ["83909.4", "0"], ["83909.2", "0.049547"], ["83901.6", "0.35754"], ["83895.1", "0"], ["83879.7", "0"]], "a": [["83949.2", "0.362478"], ["83949.5", "0"], ["83950.6", "0.071504"], ["83952.7", "0.005958"], ["83953.2", "0"], ["83954.9", "0"], ["83958.8", "0"], ["83959.2", "0.071497"], ["83960.3", "0.0003"], ["83960.4", "0"], ["83973.1", "0"], ["83974.2", "0.003576"], ["83975.5", "0.200782"], ["83977.3", "0"], ["83987.8", "0.0001"], ["83988.1", "0"], ["83989.7", "0"], ["83989.9", "0.04"], ["83999", "0"], ["84002.4", "0.357546"], ["84016.5", "0.0016"], ["84016.8", "0"], ["84020.7", "0.011865"], ["84022.2", "0.011994"]], "u": 129281, "seq": 67571360967}, "cts": 1742577155501, "record_time": 1742577155.707936, "EXCHANGE": "BYBIT"}
{"topic": "orderbook.200.BTCUSDT", "ts": 1742577155720, "type": "delta", "data": {"s": "BTCUSDT", "b": [["83936.3", "0.15268"], ["83933.7", "0.211662"], ["83932.3", "0.17868"], ["83932", "0.17868"], ["83930.5", "0"], ["83929.8", "0"], ["83929.5", "0.27068"], ["83927.3", "0"], ["83921.2", "0"], ["83915", "0.118996"], ["83914.8", "0.039632"], ["83912.5", "0"], ["83912.3", "0.582231"], ["83909.3", "0.07024"], ["83879.7", "0.044"], ["83879.5", "1.79879"]], "a": [["83959.1", "0.059399"], ["83977.3", "0.17868"], ["83989.8", "0"], ["83989.9", "0"], ["83990.1", "0.04"], ["83990.2", "0.04"], ["84020.7", "0"], ["84022.2", "0"]], "u": 129282, "seq": 67571361022}, "cts": 1742577155713, "record_time": 1742577155.908242, "EXCHANGE": "BYBIT"}
{"topic": "orderbook.200.BTCUSDT", "ts": 1742577155920, "type": "delta", "data": {"s": "BTCUSDT", "b": [["83949.1", "0.210786"], ["83932", "0"], ["83928.4", "0"], ["83926.2", "0.252641"], ["83915", "0.158996"], ["83914.8", "0"], ["83912.5", "0.013"], ["83912.3", "0.56935"], ["83901.6", "0"], ["83900.4", "5.58282"], ["83895.1", "0.357545"], ["83879.2", "0.00052"], ["83877.8", "0.012328"]], "a": [["83949.4", "0"], ["83950.6", "0"], ["83953.8", "0.006892"], ["83974.2", "0"], ["83990", "0.040524"], ["83990.2", "0"], ["83999", "0.35755"], ["84002.4", "0"], ["84002.5", "0"], ["84005.3", "2.612096"], ["84020.1", "0"], ["84020.7", "0.011865"], ["84022.2", "0.011994"], ["84022.3", "0.011994"], ["84022.4", "0.000614"], ["84022.9", "0.004436"]], "u": 129283, "seq": 67571361113}, "cts": 1742577155915, "record_time": 1742577156.108908, "EXCHANGE": "BYBIT"}
{"topic": "orderbook.200.BTCUSDT", "ts": 1742577156119, "type": "delta", "data": {"s": "BTCUSDT", "b": [["83949.1", "0.2096"], ["83932", "0.17868"], ["83901.5", "1.751871"], ["83877.8", "0"]], "a": [["83949.2", "0.49343"], ["83952.7", "0"], ["83977.3", "0"], ["83999", "0"], ["84002.9", "0.357548"], ["84023.2", "0.001466"], ["84023.7", "0.002735"]], "u": 129284, "seq": 67571361194}, "cts": 1742577156117, "record_time": 1742577156.307372, "EXCHANGE": "BYBIT"}
{"topic": "orderbook.200.BTCUSDT", "ts": 1742577156320, "type": "delta", "data": {"s": "BTCUSDT", "b": [["83949.1", "0.207371"], ["83945.3", "0.065058"], ["83945.2", "0.071509"], ["83943.9", "0"], ["83943.8", "0.000522"], ["83935.7", "0.127107"], ["83925.9", "0.183899"], ["83916.8", "0.465556"], ["83915", "0.158628"], ["83912.5", "0.012881"], ["83909.3", "0.069787"], ["83879.2", "0"]], "a": [["83949.2", "0.32645"], ["83950.4", "0.028468"], ["83950.5", "0.071505"], ["83960", "0.037152"], ["83960.9", "0.137135"], ["83970.7", "0.173029"], ["83979.8", "0.293474"], ["84002.5", "2.612013"], ["84005.3", "0.000083"], ["84010", "0.001693"], ["84022.3", "0"], ["84022.4", "0"], ["84022.9", "0"], ["84023.2", "0"], ["84023.7", "0"]], "u": 129285, "seq": 67571361261}, "cts": 1742577156315, "record_time": 1742577156.508184, "EXCHANGE": "BYBIT"}
{"topic": "orderbook.200.BTCUSDT", "ts": 1742577156519, "type": "delta", "data": {"s": "BTCUSDT", "b": [["83949.1", "0.387363"], ["83935.7", "0.006979"], ["83925.9", "0.003575"], ["83916.8", "0.190965"], ["83893.9", "0.026623"]], "a": [["83949.2", "0.379432"], ["83950.3", "0.005958"], ["83960.9", "0.023503"], ["83970.7", "0"], ["83979.8", "0.000671"], ["83989.8", "0.04"], ["83989.9", "0.04"], ["83990", "0.000524"], ["83990.1", "0"], ["84002.4", "0.357548"], ["84002.9", "0"], ["84022.2", "0"]], "u": 129286, "seq": 67571361306}, "cts": 1742577156511, "record_time": 1742577156.71939, "EXCHANGE": "BYBIT"}
{"topic": "orderbook.200.BTCUSDT", "ts": 1742577156720, "type": "delta", "data": {"s": "BTCUSDT", "b": [["83909.4", "0.05"], ["83909.2", "0"]], "a": [["83952.3", "0.000153"], ["84020.7", "0"]], "u": 129287, "seq": 67571361337}, "cts": 1742577156713, "record_time": 1742577156.907901, "EXCHANGE": "BYBIT"}
{"topic": "orderbook.200.BTCUSDT", "ts": 1742577156920, "type": "delta", "data": {"s": "BTCUSDT", "b": [["83939.3", "0.001"], ["83900.4", "5.770897"], ["83895.2", "0.357542"], ["83895.1", "0"], ["83879.5", "0"]], "a": [["83950.3", "0"], ["83950.5", "0"], ["83951.5", "0.010361"], ["83951.6", "0.071504"], ["83952.3", "0"], ["83953.8", "0"], ["83977.3", "0.17868"], ["84020.1", "0.125076"], ["84020.7", "0.011865"]], "u": 129288, "seq": 67571361398}, "cts": 1742577156915, "record_time": 1742577157.107724, "EXCHANGE": "BYBIT"}
{"topic": "orderbook.200.BTCUSDT", "ts": 1742577157119, "type": "delta", "data": {"s": "BTCUSDT", "b": [["83949.1", "0.378528"], ["83910.7", "0.001333"], ["83909.4", "0"], ["83909.2", "0.049547"], ["83895.3", "0.357547"], ["83895.2", "0"]], "a": [["83949.2", "0.369704"], ["83950", "0.015147"], ["83950.4", "0"], ["83951.2", "0.071504"], ["83951.5", "0.004403"], ["83951.6", "0"], ["83952.7", "0.005958"], ["83960.2", "0.057742"], ["83977.3", "0"], ["84020.1", "0"], ["84022.2", "0.011994"]], "u": 129289, "seq": 67571361520}, "cts": 1742577157115, "record_time": 1742577157.30784, "EXCHANGE": "BYBIT"}
{"topic": "orderbook.200.BTCUSDT", "ts": 1742577157320, "type": "delta", "data": {"s": "BTCUSDT", "b": [["83949.1", "0.135865"], ["83945.3", "0.043605"], ["83945.2", "0"], ["83943.3", "0.071511"], ["83941.9", "0"], ["83939.7", "0.075593"], ["83895.3", "0"], ["83895.1", "0.357554"], ["83879.5", "1.79879"]], "a": [["83949.2", "0.54439"], ["83949.4", "0.028535"], ["83949.5", "0.071505"], ["83950", "0"], ["83951.1", "0.000153"], ["83951.2", "0"], ["83952.7", "0"], ["83953.8", "0.007116"], ["83954.8", "0.071501"], ["83959.2", "0"], ["83979.5", "0.003"], ["83999", "0.357549"], ["84002.4", "0"], ["84020.7", "0"], ["84022.2", "0"]], "u": 129290, "seq": 67571361625}, "cts": 1742577157315, "record_time": 1742577157.507501, "EXCHANGE": "BYBIT"}
{"topic": "orderbook.200.BTCUSDT", "ts": 1742577157519, "type": "delta", "data": {"s": "BTCUSDT", "b": [["83949.1", "0.053769"], ["83949", "0.011912"], ["83945.3", "0"], ["83944.4", "0"], ["83943.3", "0"], ["83941.1", "0.071512"], ["83940.9", "0"], ["83940.7", "0.191145"], ["83939.7", "0"], ["83938.6", "0.001"], ["83937.4", "0"], ["83936.3", "0"], ["83936.2", "0"], ["83935.7", "0"], ["83934.7", "0.052392"], ["83934.6", "0.000522"], ["83934.5", "0.071518"], ["83933.7", "0.03295"], ["83932.3", "0"], ["83932.1", "0"], ["83932", "0"], ["83931.4", "0"], ["83930.1", "0"], ["83929.5", "0.044"], ["83929.4", "0.004079"], ["83929.2", "0.1"], ["83928.6", "0"], ["83926.2", "0.001466"], ["83926.1", "0.171"], ["83925.6", "0"], ["83925.3", "0"], ["83925", "0"], ["83924.8", "0"], ["83922.3", "0.17868"], ["83919.3", "0"], ["83917.3", "0"], ["83917", "0"], ["83915.2", "0"], ["83915", "0"], ["83914.9", "0.001333"], ["83913.1", "0"], ["83912.7", "0.521539"], ["83912.5", "0"], ["83912.4", "0.118996"], ["83911.9", "0.04"], ["83911.8", "0.162975"], ["83909.4", "0.013"], ["83909.3", "0.033122"], ["83909.2", "0"], ["83908.2", "0"], ["83907.5", "0.02842"], ["83906.2", "0.061919"], ["83906.1", "0.04955"], ["83904.4", "0"], ["83903.1", "0.134387"], ["83900.4", "0"], ["83896", "0.17868"], ["83895.1", "0"], ["83895", "0"], ["83894.2", "0"], ["83891.8", "0.17868"], ["83887.8", "0.357583"], ["83883.4", "0"], ["83881.5", "0"], ["83879.2", "0.00052"], ["83877.8", "0.012328"], ["83877.1", "0.060732"], ["83877", "0.044"], ["83876.5", "0.04"], ["83876.4", "0.13099"], ["83876", "0.228646"], ["83875.4", "0.001466"], ["83875.3", "0.059594"], ["83874.7", "0.011995"], ["83874.6", "0.00302"], ["83874", "0.011968"], ["83873.6", "0.012327"], ["83872.9", "0.001333"], ["83871.8", "0.004263"], ["83871.6", "0.011878"], ["83871.5", "0.000083"], ["83871.3", "0.012352"], ["83871.2", "0.011994"], ["83871.1", "1.798896"], ["83871", "0.011994"], ["83870.9", "0.118996"], ["83870.8", "0.001466"], ["83870.7", "3.798197"]], "a": [["83949.2", "0.564935"], ["83949.4", "0"], ["83949.5", "0"], ["83949.8", "0.028982"], ["83949.9", "0.071505"], ["83951.1", "0"], ["83952.2", "0.001642"], ["83954.7", "0.003849"], ["83954.8", "0.042826"], ["83955", "0.072101"], ["83955.3", "0"], ["83956.1", "0"], ["83956.4", "0"], ["83957.1", "0.04"], ["83964", "0.024577"], ["83964.1", "0.044314"], ["83967", "0.118996"], ["83967.3", "0.17868"], ["83968.3", "0.123434"], ["83968.4", "0"], ["83970.6", "0.003576"], ["83971.5", "0.17868"], ["83972.8", "0.023824"], ["83974.8", "0"], ["83975.7", "0"], ["83978.1", "0"], ["83979.9", "0.118996"], ["83986.3", "0.005955"], ["83987.3", "0"], ["83988.3", "0"], ["83991", "0.357582"], ["83991.6", "0.022718"], ["83996.4", "0"], ["83997.2", "0.023915"], ["83998.3", "0"], ["83999", "0"], ["84000", "0.006718"], ["84002.1", "0.051354"], ["84002.5", "0"], ["84019", "0"], ["84020.7", "0.011865"], ["84022.2", "0.011994"]], "u": 129291, "seq": 67571362298}, "cts": 1742577157518, "record_time": 1742577157.726149, "EXCHANGE": "BYBIT"}
{"topic": "orderbook.200.BTCUSDT", "ts": 1742577157720, "type": "delta", "data": {"s": "BTCUSDT", "b": [["83949.1", "0.09248"], ["83942.6", "0.071511"], ["83941.1", "0"], ["83940.7", "0.020145"], ["83936.4", "0"], ["83934.7", "0.004392"], ["83934.5", "0"], ["83934.4", "0.071518"], ["83931.1", "0.044"], ["83930.8", "0.041466"], ["83929.4", "0.052079"], ["83928.7", "0.060367"], ["83924.3", "0.044"], ["83922.2", "0.118369"], ["83921.7", "0.054958"], ["83921.6", "0.037211"], ["83919.4", "0"], ["83912.4", "0"], ["83911.9", "0"], ["83911.8", "0.084052"], ["83911.2", "0.039635"], ["83911.1", "0.039635"], ["83909.4", "0"], ["83909.3", "0.02024"], ["83909.1", "0.019965"], ["83908.7", "0.013"], ["83908.6", "0.012882"], ["83906.2", "0.011919"], ["83906.1", "0"], ["83905.5", "0.049551"], ["83905.4", "0.053927"], ["83903.9", "0.09654"], ["83901.5", "0.120588"], ["83896", "0"], ["83893.8", "0.357577"], ["83891.8", "0"], ["83887.8", "0"], ["83876.3", "0.171"], ["83876", "0.004263"], ["83870.9", "0"], ["83870.8", "0"], ["83870.7", "0"]], "a": [["83949.2", "0.574835"], ["83949.8", "0.04681"], ["83952.9", "0.071502"], ["83953.9", "0.041466"], ["83954.1", "0.077213"], ["83954.2", "0.04"], ["83954.8", "0"], ["83955.6", "0.04"], ["83957.3", "0.04"], ["83957.5", "0.04"], ["83959.2", "0.04"], ["83960.7", "0.04"], ["83961.9", "0.04"], ["83962.6", "0.118137"], ["83962.7", "0.083551"], ["83962.8", "0"], ["83963.1", "0.001466"], ["83963.7", "0.061793"], ["83964", "0"], ["83964.1", "0.222962"], ["83964.8", "0"], ["83967.1", "0.247881"], ["83967.2", "0.17868"], ["83967.6", "0.17868"], ["83967.9", "0"], ["83969.8", "0"], ["83970.7", "0.058774"], ["83972.1", "0"], ["83972.5", "0.008987"], ["83975.5", "0.077093"], ["83977.7", "0.120476"], ["83985.4", "0.014484"], ["83990", "0.023631"], ["83991", "0"], ["83991.5", "0.022831"], ["83994.5", "0.357577"], ["84004.7", "0.085017"], ["84009.2", "0.117289"], ["84017.9", "0"], ["84018.4", "0"], ["84018.5", "0"], ["84018.7", "0"], ["84018.8", "0"], ["84019.1", "0"], ["84019.8", "0"], ["84020.5", "0"], ["84020.7", "0"], ["84022.2", "0"]], "u": 129292, "seq": 67571362522}, "cts": 1742577157716, "record_time": 1742577157.923779, "EXCHANGE": "BYBIT"}
{"topic": "orderbook.200.BTCUSDT", "ts": 1742577157920, "type": "delta", "data": {"s": "BTCUSDT", "b": [["83949.1", "0.092719"], ["83942.6", "0"], ["83940.7", "0.191145"], ["83934.4", "0"], ["83928.7", "0"], ["83927.8", "0.033058"], ["83924.2", "0.048"], ["83921.7", "0"], ["83921.6", "0.001466"], ["83912.4", "0.118996"], ["83910.3", "0.00461"], ["83906", "0.132922"], ["83903.1", "0.001466"], ["83895", "0.357575"], ["83893.8", "0"], ["83892.1", "5.806571"], ["83879.5", "0.011994"], ["83873.2", "0.125076"], ["83871.1", "0"], ["83871", "0"]], "a": [["83949.2", "0.544835"], ["83962.9", "0"], ["83963.7", "0"], ["83964", "0.17868"], ["83964.6", "0"], ["83966.2", "0"], ["83966.5", "0"], ["83967.6", "0"], ["83968.1", "0.059399"], ["83970.7", "0"], ["83971.4", "0.120552"], ["83971.8", "0"], ["83977.7", "0"], ["83978.1", "0.125076"], ["83980.2", "0"], ["83988", "0.051354"], ["83991.5", "0"], ["83994.2", "2.611941"], ["83994.4", "0.357575"], ["83994.5", "0"], ["84002.1", "0"], ["84017.9", "0.353923"], ["84018.4", "0.011865"], ["84018.5", "0.001466"], ["84018.7", "0.004334"], ["84018.8", "0.118996"], ["84019.1", "0.011993"], ["84019.8", "0.004483"], ["84020.5", "0.000333"]], "u": 129293, "seq": 67571362673}, "cts": 1742577157913, "record_time": 1742577158.107616, "EXCHANGE": "BYBIT"}
{"topic": "orderbook.200.BTCUSDT", "ts": 1742577158119, "type": "delta", "data": {"s": "BTCUSDT", "b": [["83949.1", "0.224017"], ["83944.5", "0.042915"], ["83944.4", "0.07151"], ["83940.9", "0.071513"], ["83940.8", "0.144395"], ["83939.9", "0.064773"], ["83932.1", "0.006989"], ["83930.9", "0.086837"], ["83926.6", "0.147507"], ["83926.5", "0.178728"], ["83926.2", "0.060865"], ["83924.9", "0.178731"], ["83924.8", "0.17868"], ["83922.3", "0"], ["83921.6", "0.037211"], ["83917.9", "0.17868"], ["83913.7", "0.17868"], ["83911.2", "0"], ["83911.1", "0"], ["83910.7", "0.040969"], ["83910.6", "0.089601"], ["83908.7", "0"], ["83908.6", "0"], ["83908.2", "0.012882"], ["83908.1", "0.012882"], ["83906", "5.939493"], ["83905.5", "0"], ["83905.4", "0.004376"], ["83905", "0.049552"], ["83904.9", "0.049552"], ["83902.5", "0.024666"], ["83901.6", "0.357547"], ["83900.1", "0.013985"], ["83896.9", "0.08934"], ["83895", "0"], ["83892.1", "0"], ["83882.9", "0.125076"], ["83875.9", "0.08934"], ["83875.3", "0"], ["83874.7", "0"], ["83874.6", "0"], ["83874", "0"], ["83873.6", "0"], ["83873.2", "0"], ["83872.9", "0"], ["83871.8", "0"], ["83871.6", "0"], ["83871.5", "0"], ["83871.3", "0"], ["83871.2", "0"]], "a": [["83949.2", "0.535456"], ["83949.8", "0"], ["83949.9", "0"], ["83951.7", "0"], ["83951.9", "0.029348"], ["83952", "0.071503"], ["83952.9", "0"], ["83953.3", "0.009225"], ["83953.9", "0.043108"], ["83955", "0.0006"], ["83957.3", "0.111499"], ["83959", "0.071497"], ["83959.1", "0"], ["83959.4", "0.059399"], ["83964.1", "0.044314"], ["83967.2", "0"], ["83968.4", "0.095072"], ["83980.1", "0"], ["83980.8", "0.089864"], ["83988", "0"], ["83990", "0.000524"], ["83993.6", "0.051353"], ["83994.2", "0"], ["83994.4", "0"], ["83997.4", "0.04"], ["84002.5", "2.611941"], ["84002.9", "0.357552"], ["84019.8", "0.175483"]], "u": 129294, "seq": 67571362813}, "cts": 1742577158111, "record_time": 1742577158.308154, "EXCHANGE": "BYBIT"}
{"topic": "orderbook.200.BTCUSDT", "ts": 1742577158320, "type": "delta", "data": {"s": "BTCUSDT", "b": [["83926.6", "0.238788"], ["83919.4", "0.17868"], ["83918", "0.123383"], ["83915.2", "0.125076"], ["83906.6", "0.05"], ["83906.5", "0.050883"], ["83906", "0.132922"], ["83905", "0"], ["83904.9", "0"], ["83903.2", "5.806571"], ["83901.6", "0"], ["83897", "0.357882"], ["83894.2", "0.125076"], ["83883.6", "0"], ["83875.4", "0"]], "a": [["83951.9", "0"], ["83952", "0"], ["83955.6", "0.1115"], ["83957.3", "0.04"], ["83958.2", "0.071498"], ["83959", "0"], ["83962.6", "0.079303"], ["83962.7", "0"], ["83964.7", "0.17868"], ["83966.7", "0.178642"], ["83970.6", "0"], ["83999", "0.35755"], ["84002.9", "0"], ["84017", "0.000145"], ["84020.7", "0.011865"]], "u": 129295, "seq": 67571362869}, "cts": 1742577158308, "record_time": 1742577158.508332, "EXCHANGE": "BYBIT"}
{"topic": "orderbook.200.BTCUSDT", "ts": 1742577158519, "type": "delta", "data": {"s": "BTCUSDT", "b": [["83949.1", "0.224817"], ["83919.5", "0.221428"], ["83906.8", "0.220549"], ["83906.7", "0.04955"], ["83906.6", "0"], ["83906.5", "0.001333"], ["83885.3", "0.178816"], ["83876", "0"], ["83875.9", "0"]], "a": [["83949.7", "0.0523"], ["83949.8", "0.071505"], ["83953.6", "0.071502"], ["83953.8", "0.008758"], ["83958.2", "0"], ["83962.6", "0.122994"], ["83970.1", "0.030288"], ["84019.8", "0"], ["84020.5", "0"], ["84020.7", "0"]], "u": 129296, "seq": 67571362920}, "cts": 1742577158515, "record_time": 1742577158.707528, "EXCHANGE": "BYBIT"}
{"topic": "orderbook.200.BTCUSDT", "ts": 1742577158720, "type": "delta", "data": {"s": "BTCUSDT", "b": [["83949.1", "0.153311"], ["83948.2", "0.071506"], ["83944.9", "0.042914"], ["83944.5", "0"], ["83944.4", "0"], ["83942.9", "0.071511"], ["83935.9", "0.049397"], ["83909.9", "0.012882"], ["83909.8", "0.012882"], ["83908.2", "0"], ["83908.1", "0"], ["83906.8", "0.171"], ["83906.6", "0.04955"], ["83876.4", "0"], ["83876.3", "0"]], "a": [["83949.2", "0.535609"], ["83949.7", "0.031342"], ["83953.6", "0"], ["83953.8", "0.001642"], ["83954.1", "0.113011"], ["83954.2", "0.111501"], ["83955.6", "0.04"], ["83958", "0.071498"]], "u": 129297, "seq": 67571363050}, "cts": 1742577158715, "record_time": 1742577158.907669, "EXCHANGE": "BYBIT"}
{"topic": "orderbook.200.BTCUSDT", "ts": 1742577158920, "type": "delta", "data": {"s": "BTCUSDT", "b": [["83935.9", "0.014946"], ["83912.4", "0.15863"], ["83912.3", "0.608984"], ["83910.7", "0.001333"], ["83910.6", "0.049965"], ["83906", "5.939493"], ["83903.2", "0"], ["83876.4", "0.13099"]], "a": [["83962.4", "0.035745"], ["83966.4", "0"], ["83979.5", "0.33548"], ["83987.6", "0.6843"], ["83987.7", "0.165076"], ["83989.8", "0"], ["83989.9", "0"], ["83990.8", "0.052819"], ["83993.6", "0"], ["84019.8", "0.004483"], ["84020.5", "0.000333"], ["84020.7", "0.011865"]], "u": 129298, "seq": 67571363076}, "cts": 1742577158914, "record_time": 1742577159.106865, "EXCHANGE": "BYBIT"}
{"topic": "orderbook.200.BTCUSDT", "ts": 1742577159120, "type": "delta", "data": {"s": "BTCUSDT", "b": [["83949.1", "0.093848"], ["83948.2", "0"], ["83944.9", "0"], ["83942.9", "0"], ["83940.8", "0.057588"], ["83940.7", "0.020145"], ["83939.9", "0.052855"], ["83938.4", "0.071515"], ["83926.2", "0.001466"], ["83918", "0.004387"], ["83912.5", "0.039634"], ["83912.3", "0.56935"], ["83910", "0.012882"], ["83909.8", "0"], ["83906.9", "0.226292"], ["83906.8", "0.220549"], ["83906.7", "0"], ["83906.6", "0"], ["83906", "0.132922"], ["83902.5", "0"], ["83897", "0.000332"], ["83894.3", "0.357559"], ["83892.1", "5.821708"], ["83876", "0.004263"], ["83875.9", "0.08934"]], "a": [["83949.2", "0.544834"], ["83949.7", "0.048811"], ["83952.7", "0.001642"], ["83952.8", "0.077655"], ["83953.3", "0"], ["83953.8", "0.008545"], ["83954.2", "0.04"], ["83955.3", "0.0715"], ["83958", "0"], ["83987.5", "0.04"], ["83987.7", "0.125076"], ["83994.2", "2.611941"], ["83996.2", "0.357558"], ["83999", "0.023107"], ["84002.5", "0"], ["84019.8", "0.175483"], ["84020.5", "0"], ["84020.7", "0"]], "u": 129299, "seq": 67571363192}, "cts": 1742577159116, "record_time": 1742577159.308625, "EXCHANGE": "BYBIT"}
{"topic": "orderbook.200.BTCUSDT", "ts": 1742577159319, "type": "delta", "data": {"s": "BTCUSDT", "b": [["83946.5", "0.071508"], ["83940.9", "0.074513"], ["83940.7", "0.191145"], ["83930.7", "0"], ["83929.5", "0.100579"], ["83924.3", "0.10591"], ["83922.5", "0.055235"], ["83915.5", "0.122667"], ["83912.5", "0"], ["83912.4", "0.118996"], ["83912.2", "0.089599"], ["83912.1", "0.039634"], ["83910", "0"], ["83909.9", "0"], ["83909.7", "0.012882"], ["83909.6", "0.017259"], ["83906.9", "0.176292"], ["83906.8", "0.171"], ["83906.5", "0.050883"], ["83906.4", "0.069515"], ["83899.1", "0.357553"], ["83894.9", "5.902104"], ["83894.3", "0"], ["83892.1", "0"], ["83876.3", "0.171"], ["83875.9", "0"]], "a": [["83952.8", "0.080655"], ["83960.8", "0.118996"], ["83964.5", "0.057803"], ["83970.1", "0"], ["83970.5", "0.003576"], ["83971.5", "0.059471"], ["83972.4", "0.17868"], ["83978.5", "0.122918"], ["83979.5", "0.33248"], ["83996.2", "0"], ["84002.9", "0.357551"], ["84018.8", "0"], ["84019.1", "0"], ["84019.8", "0"]], "u": 129300, "seq": 67571363308}, "cts": 1742577159308, "record_time": 1742577159.507139, "EXCHANGE": "BYBIT"}
{"topic": "orderbook.200.BTCUSDT", "ts": 1742577159520, "type": "delta", "data": {"s": "BTCUSDT", "b": [["83940.9", "0.200051"], ["83939.4", "0"], ["83938.3", "0.037196"], ["83915.7", "0.003"], ["83912.2", "0.089965"], ["83909.7", "0.013"], ["83909.6", "0.018859"], ["83906.5", "0.051333"], ["83899.1", "0"], ["83898.2", "0.357557"], ["83894.9", "0.080396"], ["83892.1", "5.821708"]], "a": [["83949.2", "0.544992"], ["83987", "0.04"], ["83987.1", "0.04"], ["83987.5", "0"], ["83987.6", "0.6443"], ["83994.2", "0"], ["83999", "0.380664"], ["84002.9", "0"], ["84018.8", "0.118996"]], "u": 129301, "seq": 67571363376}, "cts": 1742577159518, "record_time": 1742577159.707747, "EXCHANGE": "BYBIT"}
{"topic": "orderbook.200.BTCUSDT", "ts": 1742577159719, "type": "delta", "data": {"s": "BTCUSDT", "b": [["83947", "0.071507"], ["83946.5", "0"], ["83939", "0.071514"], ["83938.4", "0"], ["83935.9", "0.047688"], ["83934.4", "0.114813"], ["83929.5", "0.044"], ["83924.6", "0.184414"], ["83922.5", "0"], ["83915.5", "0.310635"], ["83912.2", "0.049965"], ["83912", "0.039635"], ["83909.7", "0.012882"], ["83906.5", "0.050883"], ["83899.1", "0.357548"], ["83898.2", "0"], ["83876.3", "0"], ["83876", "0"]], "a": [["83949.2", "0.535614"], ["83953.6", "0.009225"], ["83959.6", "0.117471"], ["83960.8", "0"], ["83964.5", "0"], ["83969.4", "0.470229"], ["83971.5", "0"], ["83978.5", "0.273251"], ["83987", "0"], ["83987.2", "0.04"], ["83988", "0.051353"], ["83990.8", "0.001466"], ["83999", "0.380657"], ["84005.3", "2.611964"]], "u": 129302, "seq": 67571363477}, "cts": 1742577159716, "record_time": 1742577159.908085, "EXCHANGE": "BYBIT"}
{"topic": "orderbook.200.BTCUSDT", "ts": 1742577159919, "type": "delta", "data": {"s": "BTCUSDT", "b": [["83949.1", "0.094969"], ["83934.7", "0.116971"], ["83934.4", "0"], ["83930.6", "0.12423"], ["83924.6", "0"], ["83924.2", "0.231748"], ["83923.6", "0.183626"], ["83917.2", "0.291199"], ["83916.6", "0.285643"], ["83915.5", "0"], ["83912.2", "0.089965"], ["83912", "0"], ["83899.1", "0"], ["83897", "0.35789"], ["83892.1", "5.848825"], ["83876", "0.004263"], ["83875.9", "0.08934"]], "a": [["83949.2", "0.545628"], ["83953.6", "0"], ["83959.1", "0.184411"], ["83959.2", "0.155365"], ["83959.5", "0"], ["83959.6", "0"], ["83963.5", "0.119876"], ["83969.1", "0.0018"], ["83969.4", "0.289734"], ["83969.7", "0.181218"], ["83970.5", "0.177118"], ["83975.5", "0.181274"], ["83976.7", "0.289122"], ["83977.5", "0.27451"], ["83978.5", "0.000333"], ["83987", "0.04"], ["83987.2", "0"], ["83997.2", "0.381474"], ["83999", "0.023107"], ["84018.7", "0"], ["84018.8", "0"]], "u": 129303, "seq": 67571363563}, "cts": 1742577159905, "record_time": 1742577160.107452, "EXCHANGE": "BYBIT"}
{"topic": "orderbook.200.BTCUSDT", "ts": 1742577160120, "type": "delta", "data": {"s": "BTCUSDT", "b": [["83924.3", "0.208384"], ["83897", "0.000332"], ["83895", "0.357561"], ["83876.3", "0.171"], ["83876", "0"], ["83875.9", "0"]], "a": [["83966.9", "0.444994"], ["83967.1", "0"], ["83997", "2.611881"], ["83997.1", "0.357561"], ["83997.2", "0.023915"], ["84005.3", "0.000083"], ["84018.5", "0"]], "u": 129304, "seq": 67571363609}, "cts": 1742577160116, "record_time": 1742577160.308036, "EXCHANGE": "BYBIT"}
{"topic": "orderbook.200.BTCUSDT", "ts": 1742577160320, "type": "delta", "data": {"s": "BTCUSDT", "b": [["83919.5", "0.331103"], ["83898.2", "0.357554"], ["83895", "0"]], "a": [["83949.8", "0.071658"], ["83988", "0.051352"], ["83997.1", "0"], ["84002.9", "0.357554"]], "u": 129305, "seq": 67571363681}, "cts": 1742577160313, "record_time": 1742577160.508586, "EXCHANGE": "BYBIT"}
{"topic": "orderbook.200.BTCUSDT", "ts": 1742577160519, "type": "delta", "data": {"s": "BTCUSDT", "b": [["83949.1", "0.095562"], ["83935.9", "0.014946"], ["83934.7", "0.004392"], ["83930.6", "0.004391"], ["83924.2", "0.048"], ["83923.6", "0"], ["83917.2", "0"], ["83916.6", "0"], ["83898.2", "0"], ["83897", "0.357888"], ["83876", "0.004263"], ["83875.9", "0.08934"], ["83875.4", "0.001466"], ["83875.3", "0.059594"]], "a": [["83959.2", "0.04"], ["83960.3", "0"], ["83960.5", "0.0003"], ["83963.5", "0"], ["83969.7", "0"], ["83970.5", "0"], ["83976.7", "0.00432"], ["83977.5", "0"], ["83999", "0.380665"], ["84002.9", "0"], ["84018.5", "0.001466"], ["84018.7", "0.004334"], ["84018.8", "0.118996"], ["84019.1", "0.011993"], ["84019.8", "0.004483"]], "u": 129306, "seq": 67571363760}, "cts": 1742577160516, "record_time": 1742577160.707393, "EXCHANGE": "BYBIT"}
{"topic": "orderbook.200.BTCUSDT", "ts": 1742577160720, "type": "delta", "data": {"s": "BTCUSDT", "b": [["83924.3", "0.10591"], ["83919.5", "0.221428"], ["83899.1", "0.357555"], ["83897", "0.000332"], ["83875.3", "0"]], "a": [["83949.2", "0.549596"], ["83966.9", "0.337493"], ["83975.5", "0.077093"], ["83999", "0.380662"], ["84019.8", "0.175483"]], "u": 129307, "seq": 67571363803}, "cts": 1742577160715, "record_time": 1742577160.90804, "EXCHANGE": "BYBIT"}
{"topic": "orderbook.200.BTCUSDT", "ts": 1742577160919, "type": "delta", "data": {"s": "BTCUSDT", "b": [["83949.1", "0.095068"], ["83947.8", "0.071507"], ["83947", "0"], ["83942.7", "0.071511"], ["83940.9", "0.128538"], ["83939.3", "0"], ["83935.9", "0.049991"], ["83934.7", "0.12688"], ["83930.6", "0.114676"], ["83924.2", "0.229795"], ["83923.6", "0.167642"], ["83917.2", "0.304213"], ["83916.6", "0.284315"], ["83912.2", "0.049965"], ["83912.1", "0"], ["83912", "0.039635"], ["83911.9", "0.039635"], ["83909.7", "0"], ["83909.6", "0.005977"], ["83909.5", "0.012882"], ["83909.4", "0.012882"], ["83906.5", "0.001333"], ["83906.4", "0.019965"], ["83906.3", "0.04955"], ["83906.2", "0.061469"], ["83899.2", "0.357644"], ["83899.1", "0"], ["83892.1", "5.87648"], ["83876.4", "0"], ["83876.3", "0"], ["83876", "0"], ["83875.9", "0"], ["83875.4", "0"]], "a": [["83949.2", "0.540371"], ["83949.8", "0.071505"], ["83952.9", "0.009225"], ["83959.2", "0.150304"], ["83963.5", "0.116656"], ["83969.7", "0.168348"], ["83970.5", "0.17498"], ["83976.7", "0.315921"], ["83977.5", "0.27423"], ["83987", "0"], ["83987.1", "0"], ["83987.4", "0.04"], ["83987.5", "0.04"], ["83997", "0"], ["83998.9", "0.357554"], ["83999", "0.023107"], ["84005.3", "2.611964"], ["84018.5", "0"], ["84018.7", "0"], ["84018.8", "0"], ["84019.1", "0"], ["84019.8", "0"]], "u": 129308, "seq": 67571363888}, "cts": 1742577160909, "record_time": 1742577161.108309, "EXCHANGE": "BYBIT"}
{"topic": "orderbook.200.BTCUSDT", "ts": 1742577161120, "type": "delta", "data": {"s": "BTCUSDT", "b": [["83947.8", "0"], ["83946.6", "0.071508"], ["83935.9", "0.014946"], ["83934.7", "0.004392"], ["83930.6", "0.004391"], ["83924.3", "0.203003"], ["83924.2", "0.048"], ["83923.6", "0"], ["83917.2", "0"], ["83916.6", "0"], ["83909.6", "0.018859"], ["83909.4", "0"], ["83906.4", "0.069515"], ["83906.2", "0.011919"], ["83899.2", "0.00009"], ["83897", "0.357892"], ["83876.4", "0.13099"], ["83876", "0.004263"], ["83875.9", "0.08934"], ["83875.4", "0.001466"]], "a": [["83949.2", "0.549596"], ["83952.9", "0"], ["83959.2", "0.04"], ["83963.5", "0"], ["83969.7", "0"], ["83970.5", "0"], ["83975.5", "0.275148"], ["83976.7", "0.00432"], ["83977.5", "0"], ["83997.2", "0.381475"], ["83998.9", "0"], ["84018.5", "0.001466"], ["84018.7", "0.004334"], ["84018.8", "0.118996"], ["84019.1", "0.011993"], ["84019.8", "0.004483"], ["84020.5", "0.000333"]], "u": 129309, "seq": 67571364010}, "cts": 1742577161116, "record_time": 1742577161.316271, "EXCHANGE": "BYBIT"}
{"topic": "orderbook.200.BTCUSDT", "ts": 1742577161320, "type": "delta", "data": {"s": "BTCUSDT", "b": [["83949.1", "0"], ["83949", "0.035128"], ["83940.9", "0.077418"], ["83940.7", "0.000145"], ["83940.6", "0.02"], ["83924.3", "0.10591"], ["83912.1", "0.039634"], ["83912", "0.039634"], ["83911.9", "0"], ["83876.3", "0.171"], ["83875.4", "0"]], "a": [["83949.1", "0.5956"], ["83949.2", "0.34328"], ["83957.5", "0.06"], ["83957.6", "0.000333"], ["83973.6", "0.004909"], ["83975.5", "0.077093"], ["83987.1", "0.04"], ["83987.2", "0.04"], ["83987.4", "0"], ["83987.5", "0"], ["83991", "1.428723"], ["83991.1", "0.000333"], ["83996.2", "0.35756"], ["83997", "2.611881"], ["83997.2", "0.023915"], ["84005.3", "0.000083"], ["84018.8", "0"], ["84019.1", "0"], ["84019.8", "0"], ["84020.5", "0"]], "u": 129310, "seq": 67571364172}, "cts": 1742577161316, "record_time": 1742577161.508195, "EXCHANGE": "BYBIT"}
{"topic": "orderbook.200.BTCUSDT", "ts": 1742577161519, "type": "delta", "data": {"s": "BTCUSDT", "b": [["83949", "0.035262"], ["83942.7", "0"], ["83940.9", "0.074513"], ["83919.4", "0"], ["83917.9", "0"], ["83915.2", "0"], ["83913.7", "0"], ["83912.1", "0"], ["83911.9", "0.039635"], ["83909.6", "0.005977"], ["83909.4", "0.012882"], ["83906.4", "0.019965"], ["83906.2", "0.061469"], ["83897.1", "0.357565"], ["83897", "0.000332"], ["83896.9", "0"], ["83875.4", "0.001466"], ["83875.3", "0.059594"], ["83874.7", "0.011995"], ["83874.6", "0.00302"]], "a": [["83949.1", "0.595753"], ["83952.2", "0"], ["83972.4", "0"], ["83987.1", "0"], ["83987.2", "0"], ["83987.4", "0.04"], ["83987.5", "0.04"], ["83995.8", "0.357565"], ["83996.2", "0"], ["84018.8", "0.118996"], ["84019.1", "0.011993"]], "u": 129311, "seq": 67571364271}, "cts": 1742577161516, "record_time": 1742577161.707228, "EXCHANGE": "BYBIT"}
{"topic": "orderbook.200.BTCUSDT", "ts": 1742577161719, "type": "delta", "data": {"s": "BTCUSDT", "b": [["83928.6", "0.056311"], ["83921.6", "0.092014"], ["83919.5", "0"], ["83919.4", "0.17868"], ["83917.9", "0.17868"], ["83914.6", "0.113664"], ["83913.7", "0.17868"], ["83897.2", "0.357565"], ["83897.1", "0"], ["83896.9", "0.08934"], ["83875.9", "0"], ["83875.4", "0"], ["83875.3", "0"], ["83874.7", "0"], ["83874.6", "0"]], "a": [["83949.1", "0.5956"], ["83963.6", "0.05959"], ["83970.6", "0.061604"], ["83971.4", "0.000358"], ["83977.6", "0.123975"], ["83987.4", "0"], ["83987.5", "0"], ["83987.6", "0.6843"], ["83987.7", "0.165076"], ["83994.2", "2.611884"], ["83995.7", "0.357564"], ["83995.8", "0"], ["83997", "0"]], "u": 129312, "seq": 67571364344}, "cts": 1742577161714, "record_time": 1742577161.907518, "EXCHANGE": "BYBIT"}
{"success": true, "ret_msg": "pong", "conn_id": "cfa0e6f6-b68f-47fa-88c0-833d35eb70cc", "op": "ping", "record_time": 1742577161.918137, "EXCHANGE": "BYBIT"}
{"topic": "orderbook.200.BTCUSDT", "ts": 1742577161920, "type": "delta", "data": {"s": "BTCUSDT", "b": [["83949", "0.035691"], ["83922.3", "0.17868"], ["83919.5", "0.185729"], ["83915.2", "0.125076"], ["83897.3", "0.357563"], ["83897.2", "0"], ["83892.1", "5.884101"], ["83876.4", "0"], ["83876.3", "0"], ["83876", "0"]], "a": [["83949.1", "0.595753"], ["83972.4", "0.17868"], ["83995.7", "0"], ["83997.2", "0.381479"]], "u": 129313, "seq": 67571364386}, "cts": 1742577161903, "record_time": 1742577162.107938, "EXCHANGE": "BYBIT"}
{"topic": "orderbook.200.BTCUSDT", "ts": 1742577162120, "type": "delta", "data": {"s": "BTCUSDT", "b": [["83924.3", "0.168217"], ["83897.3", "0"], ["83897", "0.357895"], ["83876.4", "0.13099"]], "a": [["83987.4", "0.04"], ["83987.5", "0.04"], ["83987.6", "0.6443"], ["83987.7", "0.125076"], ["84018.8", "0"], ["84019.1", "0"]], "u": 129314, "seq": 67571364410}, "cts": 1742577162112, "record_time": 1742577162.308579, "EXCHANGE": "BYBIT"}
{"topic": "orderbook.200.BTCUSDT", "ts": 1742577162320, "type": "delta", "data": {"s": "BTCUSDT", "b": [["83948.4", "0.071506"], ["83946.6", "0"], ["83943.5", "0.07151"], ["83940.9", "0.200231"], ["83940.6", "0.191"], ["83939", "0"], ["83928.6", "0"], ["83921.6", "0.037211"], ["83914.6", "0"], ["83899.1", "0.357556"], ["83897", "0.000332"], ["83876", "0.004263"]], "a": [["83949.1", "0.586375"], ["83949.2", "0.343122"], ["83952.5", "0.009225"], ["83953.9", "0.041466"], ["83963.6", "0.00009"], ["83970.6", "0"], ["83977.6", "0"], ["83987.4", "0"], ["83987.5", "0"], ["83987.6", "0.6843"], ["83987.7", "0.165076"], ["83994.2", "0"], ["83997.2", "0.023915"], ["83999", "0.380663"], ["84002.5", "2.611884"], ["84018.8", "0.118996"], ["84019.1", "0.011993"], ["84019.8", "0.004483"]], "u": 129315, "seq": 67571364497}, "cts": 1742577162317, "record_time": 1742577162.50846, "EXCHANGE": "BYBIT"}
{"topic": "orderbook.200.BTCUSDT", "ts": 1742577162520, "type": "delta", "data": {"s": "BTCUSDT", "b": [["83948.4", "0"], ["83947.2", "0.071507"], ["83935.4", "0.002466"], ["83922.3", "0"], ["83914.5", "0.11912"], ["83899.1", "0.357547"], ["83897.7", "5.884623"], ["83892.1", "0"], ["83876.3", "0.171"]], "a": [["83952.5", "0"], ["83955.6", "0.049225"], ["83968.3", "0.004314"], ["83969.2", "0"], ["83997", "2.611884"], ["83997.2", "0.38147"], ["83999", "0.023107"], ["84002.5", "0"], ["84019.8", "0.175483"], ["84020.5", "0.000333"], ["84020.7", "0.011865"]], "u": 129316, "seq": 67571364589}, "cts": 1742577162516, "record_time": 1742577162.708387, "EXCHANGE": "BYBIT"}
{"topic": "orderbook.200.BTCUSDT", "ts": 1742577162720, "type": "delta", "data": {"s": "BTCUSDT", "b": [["83949", "0.036491"], ["83941.3", "0.036"], ["83924.3", "0.10591"], ["83899.1", "0"], ["83898.2", "0.357556"], ["83876", "0"]], "a": [["83949.1", "0.59384"], ["83953.8", "0.006903"], ["83955.6", "0.04"], ["83956.8", "0.00307"], ["83969.4", "0.286345"], ["83985.1", "0.055673"], ["83987.4", "0.04"], ["83987.5", "0.04"], ["83987.6", "0.6443"], ["83987.7", "0.125076"], ["83988", "0"], ["83997.2", "0.023915"], ["83999", "0.380663"], ["84015.7", "1.093802"], ["84020.7", "0"]], "u": 129317, "seq": 67571364638}, "cts": 1742577162692, "record_time": 1742577162.908242, "EXCHANGE": "BYBIT"}
{"topic": "orderbook.200.BTCUSDT", "ts": 1742577162920, "type": "delta", "data": {"s": "BTCUSDT", "b": [["83949", "0.036771"], ["83947.2", "0"], ["83943.5", "0"], ["83940.9", "0.003"], ["83938.6", "0.072515"], ["83915", "0.023824"], ["83912.1", "0.04"], ["83911.9", "0"], ["83909.6", "0.018977"], ["83909.4", "0"], ["83906.4", "0.069965"], ["83906.2", "0.011919"], ["83898.2", "0"], ["83894.3", "0.357562"], ["83881.8", "1.792683"], ["83876", "0.004263"], ["83875.9", "0.08934"]], "a": [["83962.4", "0"], ["83962.5", "0.035745"], ["83987.3", "0.04"], ["83987.5", "0"], ["83995.8", "0.357562"], ["83999", "0"], ["84016.3", "1.827131"]], "u": 129318, "seq": 67571364720}, "cts": 1742577162915, "record_time": 1742577163.108303, "EXCHANGE": "BYBIT"}
{"topic": "orderbook.200.BTCUSDT", "ts": 1742577163120, "type": "delta", "data": {"s": "BTCUSDT", "b": [["83947.1", "0.071507"], ["83942.2", "0.071512"], ["83940.7", "0.098797"], ["83912.2", "0.089965"], ["83912.1", "0.039634"], ["83912", "0"], ["83909.7", "0.013"], ["83909.6", "0.018859"], ["83909.5", "0"], ["83906.5", "0.051333"], ["83906.4", "0.069515"], ["83906.3", "0"], ["83894.3", "0"], ["83893.8", "0.357563"]], "a": [["83949.1", "0.593993"], ["83972.1", "0.109056"], ["83985.1", "0.004321"], ["83987.2", "0.04"], ["83987.4", "0"], ["83988", "0.051352"], ["83993.7", "0.007489"], ["84019.1", "0"], ["84019.8", "0"], ["84020.5", "0"]], "u": 129319, "seq": 67571364763}, "cts": 1742577163056, "record_time": 1742577163.308702, "EXCHANGE": "BYBIT"}
