{"topic": "orderbook.200.BTCUSDT", "ts": 1742555168319, "type": "snapshot", "data": {"s": "BTCUSDT", "b": [["84078.7", "0.006915"], ["84078.5", "0.003182"], ["84078", "0.000516"], ["84076.4", "0.005942"], ["84075.3", "0.000333"], ["84074.6", "0.001333"], ["84074.3", "0.003181"], ["84074.2", "0.001466"], ["84073.7", "0.0025"], ["84073.4", "0.000516"], ["84071.3", "0.009"], ["84071.1", "0.000333"], ["84070.4", "0.001333"], ["84070.1", "0.003181"], ["84069.6", "0.171"], ["84069.5", "0.001466"], ["84068.9", "0.001757"], ["84068.7", "0.000516"], ["84066.9", "0.000333"], ["84066.2", "0.001333"], ["84065.9", "0.003181"], ["84064.9", "0.001466"], ["84064.1", "0.000516"], ["84063.8", "0.012159"], ["84063.7", "0.04"], ["84063.1", "0.000531"], ["84062.9", "0.196138"], ["84062.7", "0.000333"], ["84062.2", "0.048"], ["84062.1", "0.08"], ["84062", "0.001423"], ["84061.8", "0.00009"], ["84061.7", "0.003181"], ["84061.1", "0.171"], ["84060.5", "0.052"], ["84060.4", "0.278769"], ["84060.3", "0.001466"], ["84060.1", "0.0003"], ["84060", "0.00006"], ["84059.6", "0.005942"], ["84059.5", "0.000516"], ["84058.8", "0.056723"], ["84058.7", "0.044"], ["84058.5", "0.000333"], ["84057.8", "0.001333"], ["84057.7", "0.018972"], ["84057.5", "0.003181"], ["84057", "0.04"], ["84056.5", "0.0045"], ["84056.4", "0.004064"], ["84055.7", "0.001466"], ["84055.4", "0.04"], ["84055.3", "0.04"], ["84054.9", "0.000516"], ["84054.3", "0.000333"], ["84053.6", "0.001423"], ["84053.5", "0.009905"], ["84053.2", "0.003181"], ["84052.7", "0.051776"], ["84052.6", "0.171"], ["84051.2", "0.00012"], ["84051", "0.001466"], ["84050.2", "0.000516"], ["84050.1", "0.000333"], ["84050", "0.00086"], ["84049.4", "0.001333"], ["84049.1", "0.004759"], ["84049", "0.003181"], ["84047.4", "0.005943"], ["84046.4", "0.001466"], ["84046.1", "0.459256"], ["84046", "0.51683"], ["84045.9", "0.000333"], ["84045.6", "0.000516"], ["84045.2", "0.001423"], ["84045", "0.000594"], ["84044.8", "0.003181"], ["84044.7", "0.059399"], ["84044.2", "0.509666"], ["84044.1", "0.171"], ["84043.3", "0.114403"], ["84042.8", "0.005942"], ["84041.8", "0.001466"], ["84041.7", "0.000333"], ["84041.3", "0.013697"], ["84041", "0.001849"], ["84040.6", "0.003181"], ["84040.4", "0.024278"], ["84040", "0.00006"], ["84039.5", "0.003575"], ["84039.2", "0.003485"], ["84039.1", "0.013"], ["84039", "0.012882"], ["84038.8", "0.04"], ["84038.3", "0.0119"], ["84037.6", "0.021653"], ["84037.5", "0.000333"], ["84037.4", "0.000337"], ["84037.3", "0.184241"], ["84037.2", "0.041466"], ["84036.8", "0.001423"], ["84036.6", "0.178404"], ["84036.4", "0.003697"], ["84036", "0.000118"], ["84035.6", "0.171629"], ["84035.5", "0.04"], ["84034.2", "0.118804"], ["84033.8", "0.04"], ["84033.3", "0.000333"], ["84032.6", "0.001333"], ["84032.5", "0.025251"], ["84032.2", "0.043181"], ["84031.8", "0.040516"], ["84031", "0.001783"], ["84030.2", "0.000083"], ["84029.1", "0.000333"], ["84028.6", "0.118804"], ["84028.4", "0.001423"], ["84028", "0.023131"], ["84027.9", "0.001466"], ["84027.8", "0.059399"], ["84027.6", "0.135586"], ["84027.1", "0.171516"], ["84026.5", "0.0045"], ["84026", "1.042024"], ["84025.9", "3.453607"], ["84025.1", "0.023787"], ["84025", "0.000199"], ["84024.9", "0.000333"], ["84024.8", "0.0001"], ["84024.2", "0.001333"], ["84023.8", "0.003181"], ["84023.3", "0.025253"], ["84022.5", "0.000516"], ["84020.7", "0.000333"], ["84020.6", "0.048119"], ["84020.2", "0.4"], ["84020", "0.001483"], ["84019.7", "0.023877"], ["84019.6", "0.003181"], ["84019.2", "0.023787"], ["84018.7", "0.001466"], ["84018.6", "0.171"], ["84018.5", "0.118804"], ["84018.2", "0.059399"], ["84017.9", "0.000516"], ["84016.5", "0.000333"], ["84016.4", "0.0001"], ["84015.8", "0.001333"], ["84015.4", "0.003181"], ["84015.3", "0.0001"], ["84014.3", "0.044"], ["84014.1", "0.001466"], ["84013.3", "0.000516"], ["84012.7", "0.353193"], ["84012.3", "3.258656"], ["84011.7", "0.011992"], ["84011.6", "0.001423"], ["84011.4", "0.102258"], ["84011.3", "0.009"], ["84011.2", "0.003181"], ["84011.1", "0.04"], ["84010.5", "0.114"], ["84010.1", "0.171"], ["84010", "0.066146"], ["84009.7", "0.015"], ["84009.4", "0.001466"], ["84009.2", "0.005942"], ["84009.1", "0.024061"], ["84008.8", "0.013093"], ["84008.7", "0.004644"], ["84008.5", "0.011992"], ["84008.4", "0.118804"], ["84008.1", "0.000333"], ["84007.5", "0.011992"], ["84007.4", "0.001333"], ["84007", "0.003181"], ["84005.1", "0.011992"], ["84004.8", "0.001466"], ["84004", "0.000516"], ["84003.9", "0.000333"], ["84003.3", "12.349945"], ["84003.2", "0.001423"], ["84002.8", "0.003181"], ["84001.7", "0.011992"], ["84001.6", "0.171"], ["84001.3", "0.059399"], ["84000.2", "0.001466"], ["84000", "3.638751"], ["83999.7", "0.000333"], ["83999.4", "0.000516"], ["83999", "0.001333"], ["83998.9", "0.624414"], ["83998.8", "0.000106"], ["83998.6", "0.003181"], ["83998.3", "0.118804"], ["83998", "0.000532"], ["83997.7", "0.027691"], ["83996.5", "0.0045"], ["83995.6", "0.001466"]], "a": [["84078.8", "0.927535"], ["84078.9", "0.023787"], ["84079.1", "0.202195"], ["84079.2", "0.098441"], ["84082.3", "0.04"], ["84082.4", "0.044"], ["84083", "0.001333"], ["84083.4", "0.17987"], ["84083.7", "0.000333"], ["84083.8", "0.1735"], ["84084", "0.186008"], ["84085.7", "0.048"], ["84085.9", "0.04"], ["84086.4", "0.196604"], ["84086.5", "0.059399"], ["84086.8", "0.118804"], ["84086.9", "0.003234"], ["84087.2", "0.001851"], ["84087.3", "0.1726"], ["84087.4", "0.048"], ["84087.5", "0.04"], ["84087.6", "0.178404"], ["84087.9", "0.003433"], ["84088", "0.001466"], ["84089", "0.048"], ["84089.1", "0.052"], ["84089.6", "0.104145"], ["84090.1", "0.004107"], ["84090.5", "0.077594"], ["84091", "0.029734"], ["84091.1", "0.003234"], ["84091.3", "0.029732"], ["84091.4", "0.001333"], ["84091.9", "0.000518"], ["84092", "0.118804"], ["84092.1", "0.000333"], ["84092.2", "0.00009"], ["84092.7", "0.001466"], ["84092.9", "0.005942"], ["84093.2", "0.00596"], ["84093.8", "0.009139"], ["84094.7", "0.212233"], ["84094.8", "0.112793"], ["84095.3", "0.003236"], ["84095.6", "0.001333"], ["84096.3", "0.024117"], ["84096.5", "0.477965"], ["84096.7", "0.067742"], ["84097.3", "0.001466"], ["84097.5", "0.118804"], ["84098.3", "0.024972"], ["84098.9", "0.023574"], ["84099.5", "0.003236"], ["84099.8", "0.001333"], ["84100.5", "0.000333"], ["84100.6", "0.00009"], ["84101", "0.059399"], ["84101.1", "0.303178"], ["84101.2", "0.171"], ["84101.7", "0.089099"], ["84101.9", "0.001466"], ["84102.7", "0.004573"], ["84103", "0.059462"], ["84103.2", "0.059463"], ["84103.7", "0.003236"], ["84103.9", "0.529058"], ["84104", "0.001333"], ["84104.7", "0.000333"], ["84104.8", "0.156914"], ["84105.6", "0.0119"], ["84105.7", "0.000518"], ["84106.5", "0.001466"], ["84107.9", "0.003236"], ["84108.2", "0.001333"], ["84109", "0.000423"], ["84109.7", "0.005942"], ["84110", "0.837923"], ["84110.2", "0.118804"], ["84110.3", "0.059399"], ["84110.4", "0.000518"], ["84110.5", "0.17141"], ["84111.2", "0.049031"], ["84111.9", "0.023784"], ["84112.1", "0.003236"], ["84112.4", "0.001333"], ["84112.5", "0.06344"], ["84112.8", "0.005946"], ["84113.2", "0.000333"], ["84113.6", "0.013"], ["84113.7", "0.012864"], ["84114.5", "0.04"], ["84114.6", "0.04"], ["84114.8", "0.119663"], ["84115", "0.000518"], ["84115.4", "0.023784"], ["84115.8", "0.163626"], ["84116.2", "2.257004"], ["84116.3", "0.003237"], ["84116.5", "0.0045"], ["84116.6", "0.001333"], ["84116.9", "0.118804"], ["84117", "0.353289"], ["84117.2", "0.023784"], ["84117.4", "0.000423"], ["84117.7", "0.184691"], ["84118.1", "0.023784"], ["84118.6", "0.023781"], ["84119.6", "0.000518"], ["84120.4", "0.001466"], ["84120.5", "0.003237"], ["84120.7", "1.425978"], ["84120.8", "0.059453"], ["84120.9", "0.001333"], ["84121", "0.002069"], ["84121.1", "0.059448"], ["84121.3", "0.059448"], ["84121.6", "0.000333"], ["84121.7", "0.171"], ["84123.2", "0.059399"], ["84124.2", "0.000518"], ["84124.4", "0.059449"], ["84124.5", "0.059453"], ["84124.6", "0.023105"], ["84124.7", "0.003237"], ["84125", "0.001466"], ["84125.1", "0.001333"], ["84125.4", "0.118804"], ["84125.8", "0.059876"], ["84126.5", "0.005942"], ["84126.6", "0.1883"], ["84127.8", "0.059449"], ["84128.1", "0.083229"], ["84128.8", "0.02388"], ["84128.9", "0.003755"], ["84129.3", "0.001333"], ["84129.6", "0.005944"], ["84129.7", "0.09651"], ["84130", "0.000333"], ["84130.8", "0.174737"], ["84130.9", "0.148527"], ["84131", "0.001459"], ["84131.1", "0.171"], ["84131.2", "0.059449"], ["84131.3", "0.009"], ["84132", "0.0018"], ["84132.1", "0.059449"], ["84132.3", "0.02378"], ["84132.8", "0.059399"], ["84133.1", "0.003211"], ["84133.5", "0.001851"], ["84134", "0.0012"], ["84134.1", "0.02378"], ["84134.2", "0.000423"], ["84134.3", "0.001466"], ["84134.6", "0.0006"], ["84135", "0.02378"], ["84135.8", "0.0006"], ["84136.3", "0.022046"], ["84136.7", "0.178281"], ["84137.2", "0.029723"], ["84137.3", "0.003211"], ["84137.7", "0.001333"], ["84138.1", "0.000518"], ["84138.4", "0.000333"], ["84138.8", "0.035532"], ["84138.9", "0.001466"], ["84139", "0.275685"], ["84139.1", "0.011844"], ["84139.2", "0.178257"], ["84140", "0.00024"], ["84140.6", "3.182236"], ["84140.9", "0.059449"], ["84141.2", "0.000297"], ["84141.3", "0.059399"], ["84141.5", "0.003211"], ["84141.6", "0.171"], ["84141.9", "0.001333"], ["84142", "0.000118"], ["84142.3", "0.167015"], ["84142.4", "0.059447"], ["84142.6", "0.000423"], ["84142.7", "0.000518"], ["84142.8", "0.07253"], ["84143.3", "0.005942"], ["84143.4", "0.011992"], ["84143.5", "0.001466"], ["84143.8", "0.011992"], ["84143.9", "0.002042"], ["84144.2", "0.0006"], ["84144.6", "0.0006"], ["84144.9", "0.130796"], ["84145.1", "0.048"], ["84145.7", "0.011992"], ["84145.8", "0.003212"], ["84146.1", "0.001333"], ["84146.5", "0.0045"], ["84146.6", "0.0012"], ["84146.8", "0.000333"], ["84147", "0.048"], ["84147.1", "0.059449"]], "u": 19811, "seq": 67549920494}, "cts": 1742555168317, "record_time": 1742555170.057217, "EXCHANGE": "BYBIT"}
{"topic": "orderbook.200.BTCUSDT", "ts": 1742555168520, "type": "delta", "data": {"s": "BTCUSDT", "b": [["84078.7", "0.007384"], ["84071.1", "0.024569"], ["84039.1", "0"], ["84038.9", "0.012882"], ["84006.2", "12.349945"], ["84003.3", "0"]], "a": [["84088.4", "0.006915"], ["84098.3", "0"], ["84098.9", "0"], ["84110", "0.120814"], ["84113.6", "0"], ["84113.8", "0.012864"], ["84114.5", "0"], ["84114.7", "0.04"], ["84147.3", "0.023984"]], "u": 19812, "seq": 67549920520}, "cts": 1742555168517, "record_time": 1742555170.058282, "EXCHANGE": "BYBIT"}
{"topic": "orderbook.200.BTCUSDT", "ts": 1742555168719, "type": "delta", "data": {"s": "BTCUSDT", "b": [["84063.8", "0.026788"], ["84063.7", "0.093828"], ["84030.5", "0.135565"], ["84027.6", "0"], ["84009", "12.349945"], ["84006.2", "0"]], "a": [["84078.8", "0.933535"], ["84096.7", "0.037579"], ["84113.4", "2.257004"], ["84116.2", "0"]], "u": 19813, "seq": 67549920555}, "cts": 1742555168682, "record_time": 1742555170.058815, "EXCHANGE": "BYBIT"}
{"topic": "orderbook.200.BTCUSDT", "ts": 1742555169120, "type": "delta", "data": {"s": "BTCUSDT", "b": [["84071.1", "0.000333"], ["84032.3", "0.066338"], ["84009", "12.643361"], ["83995.6", "0"]], "a": [["84078.8", "0.935959"], ["84083.9", "0.024307"], ["84093.9", "0.003576"], ["84110", "0.837923"], ["84113.8", "0.01286"], ["84147.1", "0"], ["84147.3", "0"]], "u": 19814, "seq": 67549920589}, "cts": 1742555169082, "record_time": 1742555170.059519, "EXCHANGE": "BYBIT"}
{"topic": "orderbook.200.BTCUSDT", "ts": 1742555169320, "type": "delta", "data": {"s": "BTCUSDT", "b": [], "a": [["84113.4", "0"], ["84116.2", "2.257004"]], "u": 19815, "seq": 67549920622}, "cts": 1742555169309, "record_time": 1742555170.06042, "EXCHANGE": "BYBIT"}
{"topic": "orderbook.200.BTCUSDT", "ts": 1742555169520, "type": "delta", "data": {"s": "BTCUSDT", "b": [["84060.5", "0.0557"], ["84043.3", "0.112803"], ["84031.8", "0.042116"], ["84030.5", "0"], ["84027.6", "0.135579"]], "a": [["84110", "0.120814"]], "u": 19816, "seq": 67549920644}, "cts": 1742555169517, "record_time": 1742555170.061251, "EXCHANGE": "BYBIT"}
{"topic": "orderbook.200.BTCUSDT", "ts": 1742555169720, "type": "delta", "data": {"s": "BTCUSDT", "b": [["84039.1", "0.013"], ["84038.9", "0"], ["84032.3", "0"], ["83995.6", "0.001466"]], "a": [["84089.4", "0.065701"], ["84113.4", "2.257004"], ["84113.6", "0.01286"], ["84113.7", "0.01286"], ["84113.8", "0"], ["84114.5", "0.04"], ["84114.7", "0"], ["84116.2", "0"], ["84147", "0"]], "u": 19817, "seq": 67549920663}, "cts": 1742555169667, "record_time": 1742555170.061923, "EXCHANGE": "BYBIT"}
{"topic": "orderbook.200.BTCUSDT", "ts": 1742555169920, "type": "delta", "data": {"s": "BTCUSDT", "b": [["84065.2", "0.023662"], ["83995.6", "0"]], "a": [["84078.8", "0.941959"], ["84093.9", "0"], ["84147", "0.048"]], "u": 19818, "seq": 67549920673}, "cts": 1742555169909, "record_time": 1742555170.062468, "EXCHANGE": "BYBIT"}
{"topic": "orderbook.200.BTCUSDT", "ts": 1742555170120, "type": "delta", "data": {"s": "BTCUSDT", "b": [["84039.1", "0"], ["84039", "0"], ["84038.8", "0.053"], ["84038.7", "0.012882"], ["84032.6", "0.035057"], ["83995.6", "0.001466"]], "a": [["84110", "0.837923"], ["84113.6", "0"], ["84113.8", "0.01286"], ["84114.5", "0"], ["84114.7", "0.04"]], "u": 19819, "seq": 67549920691}, "cts": 1742555170113, "record_time": 1742555170.132845, "EXCHANGE": "BYBIT"}
{"topic": "orderbook.200.BTCUSDT", "ts": 1742555170319, "type": "delta", "data": {"s": "BTCUSDT", "b": [["84070.8", "0.0003"], ["84060.1", "0"], ["84038.8", "0.04"], ["84038.6", "0.012882"], ["84027.7", "0.135579"], ["84027.6", "0"], ["83999", "0.028711"], ["83995.6", "0"]], "a": [["84096.3", "0.027693"], ["84113.4", "2.269864"], ["84113.5", "0.01286"], ["84113.7", "0"], ["84113.8", "0"], ["84114.3", "0.04"], ["84114.4", "0.04"], ["84114.6", "0"], ["84114.7", "0"], ["84147.1", "0.059449"]], "u": 19820, "seq": 67549920741}, "cts": 1742555170292, "record_time": 1742555170.333168, "EXCHANGE": "BYBIT"}
{"topic": "orderbook.200.BTCUSDT", "ts": 1742555170520, "type": "delta", "data": {"s": "BTCUSDT", "b": [["84078.7", "0.006915"], ["84051", "0.004466"]], "a": [], "u": 19821, "seq": 67549920753}, "cts": 1742555170507, "record_time": 1742555170.53334, "EXCHANGE": "BYBIT"}
{"topic": "orderbook.200.BTCUSDT", "ts": 1742555170720, "type": "delta", "data": {"s": "BTCUSDT", "b": [["84027.7", "0"], ["83995.6", "0.001466"]], "a": [], "u": 19822, "seq": 67549920770}, "cts": 1742555170716, "record_time": 1742555170.732659, "EXCHANGE": "BYBIT"}
{"topic": "orderbook.200.BTCUSDT", "ts": 1742555170920, "type": "delta", "data": {"s": "BTCUSDT", "b": [["84055.9", "0.058598"], ["84048.9", "0.061039"], ["84041.9", "0.119664"], ["84027.7", "0.135573"], ["83998", "0"], ["83997.7", "0"], ["83996.5", "0"], ["83995.6", "0"]], "a": [["84078.8", "0.947959"], ["84090.9", "0.061884"], ["84097.9", "0.061397"], ["84104.9", "0.114629"], ["84146.8", "0"], ["84147", "0"], ["84147.1", "0"]], "u": 19823, "seq": 67549920782}, "cts": 1742555170860, "record_time": 1742555170.933435, "EXCHANGE": "BYBIT"}
{"topic": "orderbook.200.BTCUSDT", "ts": 1742555171120, "type": "delta", "data": {"s": "BTCUSDT", "b": [["84078.7", "0.007133"], ["84058.1", "0.006056"], ["84049", "0.023715"], ["84038.8", "0.053"], ["84038.6", "0"], ["83999", "0.001333"]], "a": [["84096.3", "0.024117"], ["84113.3", "0.013"], ["84113.5", "0"], ["84114.2", "0.04"], ["84114.4", "0"]], "u": 19824, "seq": 67549920799}, "cts": 1742555171115, "record_time": 1742555171.133837, "EXCHANGE": "BYBIT"}
{"topic": "orderbook.200.BTCUSDT", "ts": 1742555171320, "type": "delta", "data": {"s": "BTCUSDT", "b": [["84055.9", "0"], ["84049.1", "0"], ["84048.9", "0"], ["84042", "0.074776"], ["84041.9", "0"], ["84030.5", "0.135573"], ["84027.7", "0"], ["83998", "0.000532"], ["83997.7", "0.027691"], ["83996.5", "0.0045"]], "a": [["84079.2", "0"], ["84090.9", "0"], ["84097.9", "0"], ["84104.9", "0"], ["84117.7", "0.526468"], ["84146.8", "0.000333"], ["84147", "0.048"], ["84147.1", "0.059449"], ["84147.3", "0.023984"]], "u": 19825, "seq": 67549920834}, "cts": 1742555171314, "record_time": 1742555171.332993, "EXCHANGE": "BYBIT"}
{"topic": "orderbook.200.BTCUSDT", "ts": 1742555171519, "type": "delta", "data": {"s": "BTCUSDT", "b": [["84078.7", "0.007733"], ["84049", "0.003181"], ["84048.9", "0.007133"], ["84042", "0"], ["84013.3", "0.129068"]], "a": [], "u": 19826, "seq": 67549920850}, "cts": 1742555171446, "record_time": 1742555171.532264, "EXCHANGE": "BYBIT"}
{"topic": "orderbook.200.BTCUSDT", "ts": 1742555171720, "type": "delta", "data": {"s": "BTCUSDT", "b": [["84078.7", "0.006933"], ["84014.3", "0"], ["83995.6", "0.001466"]], "a": [["84078.8", "0.953959"], ["84087.3", "0.171"]], "u": 19827, "seq": 67549920864}, "cts": 1742555171712, "record_time": 1742555171.733448, "EXCHANGE": "BYBIT"}
{"topic": "orderbook.200.BTCUSDT", "ts": 1742555171920, "type": "delta", "data": {"s": "BTCUSDT", "b": [["84078.7", "0.006541"], ["84028.7", "0.044"], ["83995.6", "0"]], "a": [["84078.8", "1.052768"]], "u": 19828, "seq": 67549920884}, "cts": 1742555171913, "record_time": 1742555171.933571, "EXCHANGE": "BYBIT"}
{"topic": "orderbook.200.BTCUSDT", "ts": 1742555172120, "type": "delta", "data": {"s": "BTCUSDT", "b": [["84048.9", "0.006541"], ["84030.5", "0"], ["84027.7", "0.135573"]], "a": [["84092.5", "0.003576"], ["84147.3", "0"]], "u": 19829, "seq": 67549920898}, "cts": 1742555172103, "record_time": 1742555172.133678, "EXCHANGE": "BYBIT"}
{"topic": "orderbook.200.BTCUSDT", "ts": 1742555172320, "type": "delta", "data": {"s": "BTCUSDT", "b": [["84058.1", "0"], ["84043.3", "0"], ["84040.9", "0.112805"], ["84040.5", "0.032754"], ["84012.7", "0"], ["83996.9", "0.353314"]], "a": [["84078.8", "1.058768"], ["84112.9", "0.013"], ["84113", "0.01286"], ["84113.3", "0"], ["84113.4", "2.257004"], ["84114.8", "0.193032"], ["84147.1", "0"]], "u": 19830, "seq": 67549920919}, "cts": 1742555172308, "record_time": 1742555172.33395, "EXCHANGE": "BYBIT"}
{"topic": "orderbook.200.BTCUSDT", "ts": 1742555172520, "type": "delta", "data": {"s": "BTCUSDT", "b": [["84078.7", "0.006324"], ["84051", "0.001466"]], "a": [["84092.5", "0"], ["84102.7", "0.008149"], ["84112.9", "0"], ["84113", "0"], ["84113.3", "0.013"], ["84113.4", "2.269864"], ["84146", "1.123049"], ["84147.1", "0.059449"]], "u": 19831, "seq": 67549920939}, "cts": 1742555172506, "record_time": 1742555172.534018, "EXCHANGE": "BYBIT"}
{"topic": "orderbook.200.BTCUSDT", "ts": 1742555172720, "type": "delta", "data": {"s": "BTCUSDT", "b": [["84057.2", "0.005977"], ["84038.8", "0.052882"], ["83996.5", "0"]], "a": [["84112.9", "0.013"], ["84113", "0.01286"], ["84113.3", "0"], ["84113.4", "2.257004"], ["84113.8", "0.04"], ["84113.9", "0.04"], ["84114.2", "0"], ["84114.3", "0"], ["84147.1", "0"]], "u": 19832, "seq": 67549920950}, "cts": 1742555172696, "record_time": 1742555172.733216, "EXCHANGE": "BYBIT"}
{"topic": "orderbook.200.BTCUSDT", "ts": 1742555172920, "type": "delta", "data": {"s": "BTCUSDT", "b": [["84030.5", "0.13557"], ["84027.7", "0"]], "a": [], "u": 19833, "seq": 67549920954}, "cts": 1742555172823, "record_time": 1742555172.933199, "EXCHANGE": "BYBIT"}
{"topic": "orderbook.200.BTCUSDT", "ts": 1742555173119, "type": "delta", "data": {"s": "BTCUSDT", "b": [["84078.7", "0.002973"], ["84069.6", "0"], ["84065.2", "0"], ["84060.9", "0.117942"], ["84057.2", "0"], ["84050.4", "0.172561"], ["84043.4", "0.281504"], ["84036.6", "0"], ["84009", "0"], ["84003.3", "13.833897"], ["83996.5", "0.0045"]], "a": [["84078.8", "1.1154"], ["84079.1", "0.035679"], ["84085.4", "0.118537"], ["84095.9", "0.18612"], ["84102.9", "0.307846"], ["84146.6", "0"], ["84146.8", "0"], ["84147", "0"]], "u": 19834, "seq": 67549921035}, "cts": 1742555173117, "record_time": 1742555173.132993, "EXCHANGE": "BYBIT"}
{"topic": "orderbook.200.BTCUSDT", "ts": 1742555173320, "type": "delta", "data": {"s": "BTCUSDT", "b": [["84060.9", "0"], ["84050.4", "0"], ["84043.4", "0"], ["84039.2", "0"], ["84038.8", "0.04"], ["84038.7", "0"], ["84036.3", "0.012883"], ["84036.2", "0.012883"], ["83995.6", "0.001466"], ["83995.5", "0.000333"], ["83994.8", "0.001939"]], "a": [["84085.4", "0"], ["84095.9", "0"], ["84096.6", "0.001285"], ["84102.9", "0"], ["84112.9", "0.01286"], ["84113.7", "0.04"], ["84113.9", "0"], ["84124.3", "0.098017"], ["84146.6", "0.0012"]], "u": 19835, "seq": 67549921140}, "cts": 1742555173317, "record_time": 1742555173.333296, "EXCHANGE": "BYBIT"}
{"topic": "orderbook.200.BTCUSDT", "ts": 1742555173519, "type": "delta", "data": {"s": "BTCUSDT", "b": [["84040.5", "0"], ["84036.3", "0"], ["84036.2", "0"], ["84035.9", "0.013"], ["84035.8", "0.012883"], ["84006.2", "13.833897"], ["84003.3", "0"], ["83994.7", "0.089099"]], "a": [["84078.8", "1.118976"], ["84096.6", "0"], ["84102.7", "0.004573"], ["84146.8", "0.000333"]], "u": 19836, "seq": 67549921191}, "cts": 1742555173455, "record_time": 1742555173.533365, "EXCHANGE": "BYBIT"}
{"topic": "orderbook.200.BTCUSDT", "ts": 1742555173720, "type": "delta", "data": {"s": "BTCUSDT", "b": [["84041", "0.060589"]], "a": [["84078.8", "1.062344"], ["84083.3", "0.169205"], ["84113.4", "2.297004"], ["84113.5", "0.04"], ["84113.7", "0"], ["84113.8", "0"]], "u": 19837, "seq": 67549921217}, "cts": 1742555173707, "record_time": 1742555173.733385, "EXCHANGE": "BYBIT"}
{"topic": "orderbook.200.BTCUSDT", "ts": 1742555173920, "type": "delta", "data": {"s": "BTCUSDT", "b": [["84078.7", "0.002975"]], "a": [["84078.8", "1.118976"], ["84083.3", "0"], ["84113.1", "0.04"], ["84113.2", "0.040333"], ["84113.4", "2.257004"], ["84113.5", "0"], ["84147", "0.048"]], "u": 19838, "seq": 67549921239}, "cts": 1742555173914, "record_time": 1742555173.93333, "EXCHANGE": "BYBIT"}
{"topic": "orderbook.200.BTCUSDT", "ts": 1742555174119, "type": "delta", "data": {"s": "BTCUSDT", "b": [["84062.9", "0.220157"], ["84036.5", "0.013"], ["84036.4", "0.016579"], ["84035.9", "0"], ["84035.8", "0"], ["83994.5", "0.052"]], "a": [["84078.8", "1.118948"], ["84098.7", "0.0006"], ["84112.2", "0.013"], ["84112.3", "0.01286"], ["84112.9", "0"], ["84113", "0"], ["84147", "0"]], "u": 19839, "seq": 67549921256}, "cts": 1742555174076, "record_time": 1742555174.132796, "EXCHANGE": "BYBIT"}
{"topic": "orderbook.200.BTCUSDT", "ts": 1742555174320, "type": "delta", "data": {"s": "BTCUSDT", "b": [], "a": [["84078.8", "1.124948"], ["84126.5", "0.144762"]], "u": 19840, "seq": 67549921275}, "cts": 1742555174282, "record_time": 1742555174.332914, "EXCHANGE": "BYBIT"}
{"topic": "orderbook.200.BTCUSDT", "ts": 1742555174520, "type": "delta", "data": {"s": "BTCUSDT", "b": [["84078.7", "0.003042"], ["84030.5", "0"], ["84027.7", "0.135561"]], "a": [["84078.8", "1.068316"], ["84083.3", "0.169205"], ["84146.8", "0"]], "u": 19841, "seq": 67549921305}, "cts": 1742555174517, "record_time": 1742555174.534839, "EXCHANGE": "BYBIT"}
{"topic": "orderbook.200.BTCUSDT", "ts": 1742555174919, "type": "delta", "data": {"s": "BTCUSDT", "b": [["84078.7", "0.010276"], ["84070.8", "0"], ["84070.2", "0.171"], ["84060.9", "0.111227"], ["84057.1", "0.114653"], ["84050.1", "0.1872"], ["84043.1", "0.296947"], ["84025.2", "0.016411"], ["84001.8", "0.0003"], ["83995.6", "0"], ["83995.5", "0"], ["83994.8", "0"], ["83994.7", "0"], ["83994.5", "0"]], "a": [["84086.1", "0.123273"], ["84090", "0.109438"], ["84095.9", "0.18245"], ["84097", "0.168761"], ["84104", "0.31254"], ["84146", "0"], ["84146.1", "0"], ["84146.5", "0"], ["84146.6", "0"]], "u": 19842, "seq": 67549921338}, "cts": 1742555174917, "record_time": 1742555174.932631, "EXCHANGE": "BYBIT"}
{"topic": "orderbook.200.BTCUSDT", "ts": 1742555175120, "type": "delta", "data": {"s": "BTCUSDT", "b": [["84058.8", "0.086815"], ["84051.1", "0.183559"], ["84050.2", "0.062473"], ["84042", "0.295077"], ["83996.9", "0"], ["83996.5", "0"]], "a": [["84096.7", "0.08369"], ["84105", "0.311571"], ["84145.8", "0"]], "u": 19843, "seq": 67549921358}, "cts": 1742555175112, "record_time": 1742555175.133068, "EXCHANGE": "BYBIT"}
{"topic": "orderbook.200.BTCUSDT", "ts": 1742555175320, "type": "delta", "data": {"s": "BTCUSDT", "b": [["84052.7", "0.100372"], ["84032.1", "0.003462"], ["83997.7", "0"]], "a": [["84101.1", "0.4723"], ["84117.9", "0.048"], ["84145.7", "0"]], "u": 19844, "seq": 67549921371}, "cts": 1742555175306, "record_time": 1742555175.333119, "EXCHANGE": "BYBIT"}
{"topic": "orderbook.200.BTCUSDT", "ts": 1742555175520, "type": "delta", "data": {"s": "BTCUSDT", "b": [["84078.7", "0"], ["84078.5", "0"], ["84078", "0"], ["84076.4", "0.006742"], ["84073.7", "0"], ["84071.4", "0.0025"], ["84070.2", "0"], ["84067.2", "0.071405"], ["84063.8", "0.012159"], ["84063.7", "0.053828"], ["84062.1", "0.04"], ["84060.9", "0"], ["84058.8", "0.055363"], ["84057.1", "0"], ["84057", "0.0403"], ["84051.1", "0"], ["84050.1", "0.000333"], ["84048.9", "0"], ["84048.4", "0.009715"], ["84043.1", "0"], ["84042", "0"], ["84038.3", "0"], ["84036.5", "0"], ["84036.3", "0.012882"], ["84032.5", "0.001466"], ["84032.2", "0.003181"], ["84028.1", "0.011901"], ["84028", "0.017185"], ["84027.7", "0"], ["84022.1", "0.135558"], ["84021.9", "0.023787"], ["84017.4", "0.005946"], ["84011.7", "0"], ["84008.5", "0"], ["84007.5", "0"], ["84006.2", "0"], ["84005.1", "0"], ["84003.3", "14.587802"], ["84001.8", "0"], ["84001.7", "0"], ["83997.7", "0.027691"], ["83996.9", "0.353314"], ["83996.5", "0.0045"], ["83995.6", "0.001466"], ["83995.5", "0.000333"], ["83994.8", "0.001939"], ["83994.7", "0.089099"], ["83994.5", "0.052"], ["83994.4", "0.043181"], ["83994.1", "1.12508"], ["83993.1", "0.05"], ["83992.2", "0.005943"]], "a": [["84076.5", "1.494948"], ["84076.8", "0.035681"], ["84078.7", "0.103657"], ["84078.8", "0.440809"], ["84079.1", "0"], ["84081.5", "0.0025"], ["84082.6", "0.000518"], ["84082.7", "0.003225"], ["84083.3", "0.117155"], ["84083.8", "0"], ["84086.1", "0"], ["84090", "0"], ["84095.9", "0"], ["84097", "0"], ["84097.1", "0.011901"], ["84104", "0.001333"], ["84105", "0"], ["84110.6", "2.257004"], ["84111.4", "0.044"], ["84111.7", "0.013"], ["84111.8", "0.01286"], ["84112.2", "0"], ["84112.3", "0"], ["84112.5", "0"], ["84112.6", "0.04"], ["84112.7", "0.04"], ["84113.1", "0"], ["84113.2", "0.000333"], ["84113.4", "0"], ["84118.4", "1.425978"], ["84120.7", "0"], ["84145.1", "0"]], "u": 19845, "seq": 67549921945}, "cts": 1742555175518, "record_time": 1742555175.533785, "EXCHANGE": "BYBIT"}
{"topic": "orderbook.200.BTCUSDT", "ts": 1742555175719, "type": "delta", "data": {"s": "BTCUSDT", "b": [["84076.4", "0.009715"], ["84067.2", "0"], ["84058.8", "0.078486"], ["84058.4", "0.04"], ["84056.8", "0.04"], ["84056.2", "0.006022"], ["84052.7", "0.051776"], ["84050.2", "0.000516"], ["84048.4", "0"], ["84048.3", "0.006742"], ["84037.3", "0.132241"], ["84037.2", "0.001466"], ["84035.5", "0"], ["84032.6", "0.001333"], ["84024.4", "0.04"], ["84003.3", "15.077836"], ["83993.1", "0"], ["83992.2", "0"]], "a": [["84078.7", "0.179944"], ["84079.5", "0.178409"], ["84086.4", "0.134156"], ["84087.6", "0"], ["84096.7", "0.037579"], ["84097.4", "0.000099"], ["84101.1", "0.000518"], ["84109.7", "0.069383"], ["84110.6", "2.257065"], ["84113", "0.048"], ["84114.7", "0.048"], ["84118.1", "0.075784"], ["84126.6", "0.06343"], ["84142.8", "0"], ["84144.6", "0"], ["84144.9", "0"]], "u": 19846, "seq": 67549922176}, "cts": 1742555175716, "record_time": 1742555175.73323, "EXCHANGE": "BYBIT"}
{"topic": "orderbook.200.BTCUSDT", "ts": 1742555175920, "type": "delta", "data": {"s": "BTCUSDT", "b": [["84029.6", "0.052"], ["84009", "15.077836"], ["84003.3", "0"], ["83994.1", "0"]], "a": [["84079.9", "0.003576"], ["84112.9", "0.04"], ["84126.5", "0.005942"], ["84143.9", "0"], ["84144.2", "0"]], "u": 19847, "seq": 67549922253}, "cts": 1742555175895, "record_time": 1742555175.933511, "EXCHANGE": "BYBIT"}
{"topic": "orderbook.200.BTCUSDT", "ts": 1742555176119, "type": "delta", "data": {"s": "BTCUSDT", "b": [["84036.4", "0.003697"], ["84036.3", "0"], ["84036.2", "0.012882"], ["84036.1", "0.012882"], ["84025.2", "0.074163"], ["84022.1", "0.135554"], ["84009", "0"], ["84006.2", "15.077836"], ["83994.4", "0"]], "a": [["84111.7", "0"], ["84111.8", "0"], ["84112.5", "0.01286"], ["84112.6", "0.01286"], ["84112.7", "0"], ["84113.4", "0.04"], ["84113.5", "0.04"]], "u": 19848, "seq": 67549922369}, "cts": 1742555176116, "record_time": 1742555176.132657, "EXCHANGE": "BYBIT"}
{"topic": "orderbook.200.BTCUSDT", "ts": 1742555176320, "type": "delta", "data": {"s": "BTCUSDT", "b": [["84062.9", "0.196138"], ["84056.2", "0"], ["84024.9", "0.135887"], ["84022.1", "0"], ["83994.4", "0.043181"], ["83994.1", "1.12508"]], "a": [["84111.3", "0.04"], ["84143.8", "0"]], "u": 19849, "seq": 67549922461}, "cts": 1742555176313, "record_time": 1742555176.333359, "EXCHANGE": "BYBIT"}
{"topic": "orderbook.200.BTCUSDT", "ts": 1742555176520, "type": "delta", "data": {"s": "BTCUSDT", "b": [["84076.4", "0.015996"], ["84009", "15.077836"], ["84006.2", "0"]], "a": [["84076.5", "1.374938"], ["84078.8", "0.443809"], ["84101.1", "0.323299"], ["84110.6", "0"], ["84113", "0.088"], ["84113.1", "0.04"], ["84113.4", "2.257065"], ["84113.5", "0"], ["84119", "0.000118"], ["84142", "0"], ["84143.8", "0.011992"]], "u": 19850, "seq": 67549922499}, "cts": 1742555176514, "record_time": 1742555176.534424, "EXCHANGE": "BYBIT"}
{"topic": "orderbook.200.BTCUSDT", "ts": 1742555176720, "type": "delta", "data": {"s": "BTCUSDT", "b": [["84036.4", "0.016697"], ["84036.3", "0.012882"], ["84036.2", "0"], ["84036.1", "0"], ["83993.1", "0.05"]], "a": [["84112.1", "0.016236"], ["84112.2", "0.01286"], ["84112.5", "0"], ["84112.6", "0"], ["84113.4", "0"], ["84116.2", "2.257065"], ["84143.9", "0.002042"]], "u": 19851, "seq": 67549922523}, "cts": 1742555176697, "record_time": 1742555176.734045, "EXCHANGE": "BYBIT"}
{"topic": "orderbook.200.BTCUSDT", "ts": 1742555176919, "type": "delta", "data": {"s": "BTCUSDT", "b": [["84057", "0.04"], ["84036.4", "0.003697"], ["84036.2", "0.012882"], ["83999.1", "0.0003"], ["83994.1", "0"], ["83993.1", "0"]], "a": [["84076.5", "1.387738"], ["84078.8", "0.443009"], ["84109.7", "0.005942"], ["84110", "0.120814"], ["84112.1", "0.003236"], ["84112.3", "0.01286"], ["84113", "0.048"], ["84113.2", "0.040333"], ["84143.9", "0"]], "u": 19852, "seq": 67549922552}, "cts": 1742555176913, "record_time": 1742555176.932171, "EXCHANGE": "BYBIT"}
{"topic": "orderbook.200.BTCUSDT", "ts": 1742555177120, "type": "delta", "data": {"s": "BTCUSDT", "b": [["84062.8", "0.023334"], ["84009", "0"], ["84006.2", "15.283451"], ["83994.4", "0"]], "a": [["84079.9", "0"], ["84106.8", "0.063441"]], "u": 19853, "seq": 67549922581}, "cts": 1742555177116, "record_time": 1742555177.132837, "EXCHANGE": "BYBIT"}
{"topic": "orderbook.200.BTCUSDT", "ts": 1742555177319, "type": "delta", "data": {"s": "BTCUSDT", "b": [["84031.9", "0.028795"], ["84009", "15.283451"], ["84006.2", "0"], ["83994.5", "0"]], "a": [["84082.2", "0.003576"], ["84143.8", "0"]], "u": 19854, "seq": 67549922594}, "cts": 1742555177302, "record_time": 1742555177.332576, "EXCHANGE": "BYBIT"}
{"topic": "orderbook.200.BTCUSDT", "ts": 1742555177519, "type": "delta", "data": {"s": "BTCUSDT", "b": [["84048.3", "0.125681"], ["84048.1", "0.023788"], ["83994.7", "0"]], "a": [["84085.8", "0.28939"], ["84085.9", "0.517447"], ["84086.4", "0"], ["84093.5", "0.118939"], ["84096.5", "0.000518"], ["84114.8", "0.86098"], ["84143.5", "0"]], "u": 19855, "seq": 67549922621}, "cts": 1742555177509, "record_time": 1742555177.533196, "EXCHANGE": "BYBIT"}
{"topic": "orderbook.200.BTCUSDT", "ts": 1742555177720, "type": "delta", "data": {"s": "BTCUSDT", "b": [["84048.4", "0.047063"], ["84009", "0"], ["84006.2", "15.189084"], ["83994.8", "0"]], "a": [["84076.5", "1.393738"], ["84093.4", "0.081023"], ["84094.7", "0"], ["84100", "0.00669"], ["84143.4", "0"]], "u": 19856, "seq": 67549922647}, "cts": 1742555177715, "record_time": 1742555177.734108, "EXCHANGE": "BYBIT"}
{"topic": "orderbook.200.BTCUSDT", "ts": 1742555177920, "type": "delta", "data": {"s": "BTCUSDT", "b": [["84076.4", "0.009715"], ["84009", "15.189084"], ["84006.2", "0"]], "a": [["84076.5", "1.399738"]], "u": 19857, "seq": 67549922659}, "cts": 1742555177913, "record_time": 1742555177.933392, "EXCHANGE": "BYBIT"}
{"topic": "orderbook.200.BTCUSDT", "ts": 1742555178320, "type": "delta", "data": {"s": "BTCUSDT", "b": [], "a": [["84076.5", "1.403314"], ["84082.2", "0"], ["84088.4", "0"], ["84143.4", "0.011992"], ["84143.5", "0.001466"]], "u": 19858, "seq": 67549922675}, "cts": 1742555178302, "record_time": 1742555178.333459, "EXCHANGE": "BYBIT"}
{"topic": "orderbook.200.BTCUSDT", "ts": 1742555178520, "type": "delta", "data": {"s": "BTCUSDT", "b": [["84076.4", "0.014988"]], "a": [["84076.5", "1.415314"], ["84110", "0.225106"], ["84113", "0.088"], ["84113.2", "0.000333"], ["84113.4", "2.257065"], ["84116.2", "0"]], "u": 19859, "seq": 67549922720}, "cts": 1742555178517, "record_time": 1742555178.533665, "EXCHANGE": "BYBIT"}
{"topic": "orderbook.200.BTCUSDT", "ts": 1742555178719, "type": "delta", "data": {"s": "BTCUSDT", "b": [["84036.4", "0.016697"], ["84036.2", "0"], ["83994.8", "0.001939"]], "a": [["84087.8", "0.014988"], ["84106.8", "0"], ["84109.7", "0.069383"], ["84112.1", "0.016236"], ["84112.3", "0"], ["84113.4", "0"], ["84114.8", "0"], ["84116.2", "2.257065"], ["84143.8", "0.011992"], ["84143.9", "0.002042"]], "u": 19860, "seq": 67549922750}, "cts": 1742555178681, "record_time": 1742555178.733989, "EXCHANGE": "BYBIT"}
{"topic": "orderbook.200.BTCUSDT", "ts": 1742555178920, "type": "delta", "data": {"s": "BTCUSDT", "b": [["84076.4", "0.009715"], ["84009", "15.066881"]], "a": [], "u": 19861, "seq": 67549922773}, "cts": 1742555178896, "record_time": 1742555178.933161, "EXCHANGE": "BYBIT"}
{"topic": "orderbook.200.BTCUSDT", "ts": 1742555179119, "type": "delta", "data": {"s": "BTCUSDT", "b": [], "a": [["84076.5", "1.411738"]], "u": 19862, "seq": 67549922779}, "cts": 1742555179116, "record_time": 1742555179.132427, "EXCHANGE": "BYBIT"}
{"topic": "orderbook.200.BTCUSDT", "ts": 1742555179320, "type": "delta", "data": {"s": "BTCUSDT", "b": [], "a": [["84079.4", "0.003576"], ["84113.4", "2.257065"], ["84116.2", "0"], ["84143.9", "0"]], "u": 19863, "seq": 67549922797}, "cts": 1742555179309, "record_time": 1742555179.332955, "EXCHANGE": "BYBIT"}
{"topic": "orderbook.200.BTCUSDT", "ts": 1742555179520, "type": "delta", "data": {"s": "BTCUSDT", "b": [["84076.4", "0.00361"], ["84062.8", "0"], ["84036.4", "0.003697"], ["84036.2", "0.012882"], ["84034.2", "0"], ["84009", "0"], ["83994.7", "0.089099"], ["83994.5", "0.052"]], "a": [["84076.5", "1.267631"], ["84078.7", "0"], ["84079.4", "0"], ["84082.2", "0.176849"], ["84083.3", "0"], ["84092.7", "0.086059"], ["84093.4", "0"], ["84110", "0.889231"], ["84112.1", "0.003236"], ["84112.3", "0.01286"], ["84113", "0.048"], ["84113.2", "0.040333"], ["84143.9", "0.002042"], ["84144.2", "0.0006"]], "u": 19864, "seq": 67549922880}, "cts": 1742555179516, "record_time": 1742555179.533861, "EXCHANGE": "BYBIT"}
{"topic": "orderbook.200.BTCUSDT", "ts": 1742555179719, "type": "delta", "data": {"s": "BTCUSDT", "b": [["84056.2", "0.005795"], ["84038.8", "0"], ["84037.3", "0"], ["84036.3", "0"], ["84036.2", "0"], ["84036.1", "0.012882"], ["84036", "0.013"], ["84033.8", "0"], ["84031.4", "0.04"], ["84026.3", "0.04"], ["83994.4", "0.043181"]], "a": [["84105.6", "0.0269"], ["84112.2", "0"], ["84112.3", "0"], ["84112.8", "0.018806"], ["84112.9", "0.05286"], ["84113.1", "0"], ["84113.2", "0.000333"], ["84113.7", "0.04"], ["84113.8", "0.04"], ["84144.6", "0.0006"]], "u": 19865, "seq": 67549922924}, "cts": 1742555179716, "record_time": 1742555179.733097, "EXCHANGE": "BYBIT"}
{"topic": "orderbook.200.BTCUSDT", "ts": 1742555179920, "type": "delta", "data": {"s": "BTCUSDT", "b": [["84076.4", "0.002973"], ["84063.8", "0"], ["84041", "0.001849"], ["84036.1", "0"], ["84035.9", "0.012882"], ["84006.2", "15.066881"]], "a": [["84092.4", "0.085033"], ["84092.7", "0.001466"], ["84106.8", "0.063441"], ["84109.7", "0.005942"], ["84111.2", "0.02525"], ["84116.7", "0.04"], ["84143.9", "0"], ["84144.2", "0"], ["84144.6", "0"]], "u": 19866, "seq": 67549923066}, "cts": 1742555179916, "record_time": 1742555179.932755, "EXCHANGE": "BYBIT"}
{"topic": "orderbook.200.BTCUSDT", "ts": 1742555180119, "type": "delta", "data": {"s": "BTCUSDT", "b": [["84052.6", "0.228973"], ["84045.6", "0.059937"], ["84038.6", "0.122364"], ["84036", "0.000118"], ["84035.8", "0.012882"], ["84006.2", "15.112174"], ["83994.5", "0"], ["83994.4", "0"]], "a": [["84080.1", "0.011893"], ["84087.5", "0.063787"], ["84087.6", "0.06133"], ["84094.6", "0.056175"], ["84101.6", "0.11178"], ["84110.6", "2.25708"], ["84113.4", "0"], ["84115.1", "0.04"], ["84142.7", "0"], ["84143.3", "0"], ["84143.4", "0"], ["84143.5", "0"], ["84143.8", "0"]], "u": 19867, "seq": 67549923173}, "cts": 1742555180112, "record_time": 1742555180.133786, "EXCHANGE": "BYBIT"}
{"topic": "orderbook.200.BTCUSDT", "ts": 1742555180320, "type": "delta", "data": {"s": "BTCUSDT", "b": [["84061.2", "0.023987"], ["84052.6", "0.23073"], ["84045.6", "0.057245"], ["84038.6", "0.114931"], ["83994.7", "0"]], "a": [["84087.6", "0.055513"], ["84094.6", "0.058524"], ["84101.6", "0.110496"], ["84113.1", "0.04"], ["84113.2", "0.040333"], ["84113.7", "0"], ["84113.8", "0"], ["84142.7", "0.000518"]], "u": 19868, "seq": 67549923254}, "cts": 1742555180313, "record_time": 1742555180.333204, "EXCHANGE": "BYBIT"}
{"topic": "orderbook.200.BTCUSDT", "ts": 1742555180520, "type": "delta", "data": {"s": "BTCUSDT", "b": [["84076.4", "0.003773"], ["84070", "0.011429"], ["84052.6", "0.171"], ["84045.6", "0.000516"], ["84038.6", "0"]], "a": [["84087.6", "0"], ["84094.6", "0"], ["84101.6", "0"], ["84115.7", "0.212699"], ["84143.3", "0.005942"], ["84143.4", "0.011992"]], "u": 19869, "seq": 67549923367}, "cts": 1742555180514, "record_time": 1742555180.533452, "EXCHANGE": "BYBIT"}
{"topic": "orderbook.200.BTCUSDT", "ts": 1742555180720, "type": "delta", "data": {"s": "BTCUSDT", "b": [["84076.4", "0.002976"], ["84036.4", "0.016697"], ["84036.3", "0.012882"], ["84035.9", "0"], ["84035.8", "0"], ["83994.7", "0.089099"]], "a": [["84076.5", "1.273631"], ["84110.6", "2.257065"], ["84111.7", "0.013"], ["84111.8", "0.01286"], ["84112.6", "0.04"], ["84112.7", "0.04"], ["84112.8", "0.005946"], ["84112.9", "0.04"], ["84113.1", "0"], ["84113.2", "0.000333"], ["84142.7", "0"], ["84143.3", "0"], ["84143.4", "0"]], "u": 19870, "seq": 67549923438}, "cts": 1742555180709, "record_time": 1742555180.733919, "EXCHANGE": "BYBIT"}
{"topic": "orderbook.200.BTCUSDT", "ts": 1742555180920, "type": "delta", "data": {"s": "BTCUSDT", "b": [["84076.4", "0.002977"], ["84036.4", "0.003697"], ["84036.3", "0"], ["84036.2", "0.013"], ["84036.1", "0.012882"], ["83994.7", "0"]], "a": [["84076.5", "1.279631"], ["84082.9", "0.012377"], ["84142.6", "0"]], "u": 19871, "seq": 67549923507}, "cts": 1742555180914, "record_time": 1742555180.933122, "EXCHANGE": "BYBIT"}
{"topic": "orderbook.200.BTCUSDT", "ts": 1742555181119, "type": "delta", "data": {"s": "BTCUSDT", "b": [["84076.4", "0.002973"], ["83999", "0.041333"]], "a": [["84076.5", "1.285631"], ["84111.5", "0.013"], ["84111.6", "0.01286"], ["84111.7", "0"], ["84111.8", "0"], ["84112.4", "0.041333"], ["84112.5", "0.04"], ["84112.6", "0"], ["84112.7", "0"], ["84142.6", "0.000423"]], "u": 19872, "seq": 67549923575}, "cts": 1742555181113, "record_time": 1742555181.132748, "EXCHANGE": "BYBIT"}
{"topic": "orderbook.200.BTCUSDT", "ts": 1742555181720, "type": "delta", "data": {"s": "BTCUSDT", "b": [], "a": [["84110.6", "2.256908"]], "u": 19873, "seq": 67549923677}, "cts": 1742555181716, "record_time": 1742555181.733858, "EXCHANGE": "BYBIT"}
{"topic": "orderbook.200.BTCUSDT", "ts": 1742555181920, "type": "delta", "data": {"s": "BTCUSDT", "b": [["84076.4", "0.006694"], ["84063.8", "0.016308"], ["84036.2", "0.055389"], ["84036", "0.013"], ["83994.8", "0"]], "a": [["84078.7", "0.193562"], ["84105.5", "0.029195"], ["84111.5", "0"], ["84111.7", "0.01286"], ["84112.4", "0.001333"], ["84112.6", "0.04"], ["84142.3", "0"], ["84142.4", "0"], ["84142.6", "0"]], "u": 19874, "seq": 67549923749}, "cts": 1742555181900, "record_time": 1742555181.934463, "EXCHANGE": "BYBIT"}
{"topic": "orderbook.200.BTCUSDT", "ts": 1742555182120, "type": "delta", "data": {"s": "BTCUSDT", "b": [["84076.4", "0.002973"], ["84036.1", "0"], ["84035.9", "0.012882"], ["84024.9", "0.000333"], ["84022.1", "0.13551"], ["84006.2", "15.227644"], ["83995.5", "0"]], "a": [["84078.7", "0"], ["84107.8", "2.256908"], ["84110.6", "0"], ["84111.6", "0"], ["84111.7", "0"], ["84111.9", "0.036644"], ["84112", "0.01286"], ["84112.5", "0"], ["84112.6", "0"], ["84112.8", "0.045946"], ["84112.9", "0.08"], ["84142.3", "0.167015"], ["84142.4", "0.059447"], ["84142.6", "0.000423"], ["84142.7", "0.000518"]], "u": 19875, "seq": 67549923845}, "cts": 1742555182117, "record_time": 1742555182.133954, "EXCHANGE": "BYBIT"}
{"topic": "orderbook.200.BTCUSDT", "ts": 1742555182320, "type": "delta", "data": {"s": "BTCUSDT", "b": [["84065.8", "0.022859"], ["84048.3", "0.118939"], ["83995.6", "0"]], "a": [["84110", "0.023781"], ["84111.9", "0.023784"], ["84112.1", "0.016096"], ["84112.8", "0.005946"], ["84113", "0.088"]], "u": 19876, "seq": 67549923947}, "cts": 1742555182302, "record_time": 1742555182.333733, "EXCHANGE": "BYBIT"}
{"topic": "orderbook.200.BTCUSDT", "ts": 1742555182520, "type": "delta", "data": {"s": "BTCUSDT", "b": [["84048.3", "0"], ["84048.2", "0.004759"], ["84036.1", "0.013"], ["84035.9", "0"], ["84015.2", "0.023788"], ["83999.3", "0.0003"], ["83999.1", "0"], ["83996.5", "0"]], "a": [["84076.5", "1.291631"], ["84092.4", "0.049351"], ["84093.5", "0"], ["84111.8", "0.013"], ["84111.9", "0.036644"], ["84112", "0"], ["84112.1", "0.003236"], ["84112.7", "0.04"], ["84112.8", "0.045946"], ["84112.9", "0.04"], ["84113", "0.048"]], "u": 19877, "seq": 67549924011}, "cts": 1742555182517, "record_time": 1742555182.532896, "EXCHANGE": "BYBIT"}
{"topic": "orderbook.200.BTCUSDT", "ts": 1742555182720, "type": "delta", "data": {"s": "BTCUSDT", "b": [["84048.4", "0"], ["83996.5", "0.0045"]], "a": [["84121", "0"], ["84143.3", "0.005942"]], "u": 19878, "seq": 67549924068}, "cts": 1742555182713, "record_time": 1742555182.733775, "EXCHANGE": "BYBIT"}
{"topic": "orderbook.200.BTCUSDT", "ts": 1742555182920, "type": "delta", "data": {"s": "BTCUSDT", "b": [["84076.4", "0.00645"], ["84058.8", "0.109611"], ["84058.1", "0.113911"], ["84047.6", "0.184559"], ["84041", "0.045019"], ["84040.9", "0"], ["84040.6", "0.280574"], ["84037.7", "0.112799"], ["83996.9", "0"], ["83996.5", "0"]], "a": [["84078.7", "0.193562"], ["84082.6", "0.115025"], ["84092.4", "0.0968"], ["84093.1", "0.178726"], ["84100.1", "0.307695"], ["84105.5", "0.702618"], ["84142.6", "0"], ["84142.7", "0"], ["84143.3", "0"]], "u": 19879, "seq": 67549924159}, "cts": 1742555182916, "record_time": 1742555182.933054, "EXCHANGE": "BYBIT"}
{"topic": "orderbook.200.BTCUSDT", "ts": 1742555183120, "type": "delta", "data": {"s": "BTCUSDT", "b": [["84047.7", "0.05759"], ["83997.7", "0"]], "a": [["84087.1", "0.024753"], ["84142.4", "0"]], "u": 19880, "seq": 67549924202}, "cts": 1742555183103, "record_time": 1742555183.13456, "EXCHANGE": "BYBIT"}
{"topic": "orderbook.200.BTCUSDT", "ts": 1742555183320, "type": "delta", "data": {"s": "BTCUSDT", "b": [], "a": [["84076.5", "1.288055"], ["84095", "0.001276"], ["84142.3", "0"]], "u": 19881, "seq": 67549924269}, "cts": 1742555183313, "record_time": 1742555183.333231, "EXCHANGE": "BYBIT"}
{"topic": "orderbook.200.BTCUSDT", "ts": 1742555183520, "type": "delta", "data": {"s": "BTCUSDT", "b": [["84036.1", "0"], ["84035.9", "0.012882"]], "a": [["84094", "0.001011"], ["84095", "0"], ["84111.8", "0"], ["84112", "0.01286"]], "u": 19882, "seq": 67549924320}, "cts": 1742555183513, "record_time": 1742555183.533337, "EXCHANGE": "BYBIT"}
{"topic": "orderbook.200.BTCUSDT", "ts": 1742555183720, "type": "delta", "data": {"s": "BTCUSDT", "b": [["84076.4", "0.002973"], ["84058.1", "0"], ["84047.6", "0"], ["84040.6", "0.003181"], ["84036.1", "0.013"], ["84035.9", "0"], ["84024.9", "0.135835"], ["84022.1", "0"], ["84006.2", "0"], ["84000.5", "15.337786"], ["83997.7", "0.027691"], ["83996.9", "0.353314"], ["83996.5", "0.0045"]], "a": [["84078.7", "0"], ["84082.6", "0.000518"], ["84086.3", "0.003576"], ["84093.1", "0"], ["84094", "0"], ["84100.1", "0"], ["84111.8", "0.013"], ["84112", "0"], ["84142.3", "0.167015"], ["84142.4", "0.059447"], ["84142.6", "0.000423"]], "u": 19883, "seq": 67549924432}, "cts": 1742555183717, "record_time": 1742555183.732742, "EXCHANGE": "BYBIT"}
{"topic": "orderbook.200.BTCUSDT", "ts": 1742555183919, "type": "delta", "data": {"s": "BTCUSDT", "b": [["84076.4", "0.002976"], ["84061.2", "0"], ["84047.7", "0"], ["84041", "0.001849"], ["84036.1", "0"], ["84036", "0.000118"], ["84035.5", "0.013"], ["84035.4", "0.012882"], ["84024.9", "0.000333"], ["84022.1", "0.135502"], ["84000.5", "0"], ["83997.7", "15.365477"], ["83995.6", "0.001466"]], "a": [["84076.5", "1.297631"], ["84086.3", "0"], ["84092.4", "0.049351"], ["84110.1", "0.206362"]], "u": 19884, "seq": 67549924563}, "cts": 1742555183916, "record_time": 1742555183.934408, "EXCHANGE": "BYBIT"}
{"topic": "orderbook.200.BTCUSDT", "ts": 1742555184119, "type": "delta", "data": {"s": "BTCUSDT", "b": [["84076.4", "0.003576"], ["84063.8", "0"], ["84057.7", "0.13835"], ["84047.9", "0.177056"], ["84038.8", "0.285122"], ["84036.1", "0.012882"], ["84036", "0.013"], ["84035.5", "0"], ["84035.4", "0"], ["84024.9", "0.135835"], ["84022.1", "0"], ["84003.3", "15.337786"], ["83997.7", "0.027691"]], "a": [["84076.5", "1.309631"], ["84082.9", "0.135075"], ["84092.4", "0.099123"], ["84092.7", "0.187934"], ["84101.8", "0.290442"], ["84111.8", "0.01286"], ["84142.6", "0"]], "u": 19885, "seq": 67549924685}, "cts": 1742555184117, "record_time": 1742555184.132656, "EXCHANGE": "BYBIT"}
{"topic": "orderbook.200.BTCUSDT", "ts": 1742555184319, "type": "delta", "data": {"s": "BTCUSDT", "b": [["84076.4", "0"], ["84075.3", "0"], ["84074.6", "0"], ["84074.3", "0"], ["84074.2", "0"], ["84073.4", "0"], ["84071.4", "0"], ["84071.3", "0"], ["84071.1", "0"], ["84070.4", "0.005461"], ["84070", "0"], ["84065.8", "0"], ["84064", "0.01143"], ["84062.9", "0"], ["84062", "0.001333"], ["84061.9", "0.171"], ["84061.8", "0"], ["84061.1", "0"], ["84060.5", "0.052"], ["84059.8", "0.022862"], ["84058.8", "0"], ["84058.5", "0.072371"], ["84057.7", "0.018972"], ["84056.2", "0"], ["84054.7", "0.0003"], ["84054.3", "0.08986"], ["84052.7", "0"], ["84048.2", "0"], ["84048.1", "0"], ["84048", "0.05534"], ["84047.9", "0"], ["84044.7", "0"], ["84044.2", "0.02112"], ["84044.1", "0.175759"], ["84039.5", "0"], ["84038.9", "0.144936"], ["84038.8", "0"], ["84037.8", "0.101766"], ["84037.7", "0"], ["84036.5", "0.112798"], ["84036.2", "0"], ["84036.1", "0"], ["84036", "0.000118"], ["84032.7", "0.488546"], ["84032.1", "0"], ["84031.7", "0.012881"], ["84031.6", "0.012881"], ["84024.9", "0.000333"], ["84013.6", "0.135502"], ["84013.3", "0.000516"], ["84003.3", "0"], ["83999.3", "0"], ["83998.9", "0"], ["83997.9", "0.235392"], ["83995.5", "0.000333"], ["83994.8", "0.001939"], ["83994.7", "0.089099"], ["83994.5", "0.052"], ["83994.4", "0.043181"], ["83994.1", "1.12508"], ["83993.2", "0.04"], ["83992.2", "0.005943"], ["83991.3", "0.000333"], ["83991", "0.041466"], ["83990.8", "0.000166"], ["83990.7", "0.00005"], ["83990.6", "0.625764"], ["83990.5", "0.027639"], ["83990.2", "0.003697"], ["83989.6", "0.011845"], ["83989.4", "0.195"]], "a": [["84070.5", "0.459138"], ["84073.2", "0.001189"], ["84075.5", "0.0025"], ["84076.4", "0.221301"], ["84076.5", "0.178075"], ["84076.8", "0"], ["84076.9", "0.012377"], ["84078", "0.000516"], ["84078.5", "0.003225"], ["84078.7", "0.118804"], ["84078.8", "0.274808"], ["84079.5", "0.000333"], ["84080.1", "0"], ["84081.1", "0.024754"], ["84081.5", "0"], ["84082.2", "0.090384"], ["84082.9", "0"], ["84083.2", "0.009564"], ["84083.4", "0.001466"], ["84083.8", "0.00009"], ["84086.5", "0.118872"], ["84087.1", "0"], ["84089.1", "0.400474"], ["84089.6", "0"], ["84091", "0.566043"], ["84092.7", "0.001466"], ["84093.8", "0"], ["84096.5", "0.039128"], ["84101.8", "0"], ["84103.9", "0"], ["84112.4", "1.427311"], ["84117", "3.535062"], ["84117.3", "0.00009"], ["84118.4", "0"], ["84121.3", "0"], ["84136.7", "0"], ["84137.1", "0.011846"], ["84140.6", "0"]], "u": 19886, "seq": 67549925126}, "cts": 1742555184315, "record_time": 1742555184.333534, "EXCHANGE": "BYBIT"}
{"topic": "orderbook.200.BTCUSDT", "ts": 1742555184519, "type": "delta", "data": {"s": "BTCUSDT", "b": [["84070.4", "0.002488"], ["84063.7", "0"], ["84062.2", "0"], ["84062.1", "0"], ["84060.5", "0"], ["84060.4", "0.238769"], ["84058.7", "0"], ["84058.5", "0.017879"], ["84058.4", "0"], ["84057", "0"], ["84056.8", "0"], ["84055.4", "0.024155"], ["84055.3", "0"], ["84054.7", "0"], ["84054.4", "0.0003"], ["84054.3", "0.085867"], ["84053.7", "0.121406"], ["84051.8", "0.04"], ["84050.1", "0.040333"], ["84048", "0"], ["84046.1", "0.217709"], ["84044.1", "0.171"], ["84043.2", "0.170462"], ["84040.5", "0.050782"], ["84038.9", "0.059399"], ["84036.2", "0.297954"], ["84031.8", "0.002116"], ["84031.7", "0"], ["84031.6", "0"], ["84028.2", "0.053"], ["84028.1", "0.024783"], ["84025.2", "0.016411"], ["84020.3", "0.242838"], ["84007.7", "0.178422"], ["83997.7", "15.365477"], ["83993.1", "0.171"], ["83988.2", "0.118804"], ["83987.6", "0.05"], ["83987.1", "0.000333"]], "a": [["84070.5", "0.478328"], ["84073.2", "0"], ["84075.3", "0.000333"], ["84076.4", "0.310005"], ["84076.5", "0.177742"], ["84076.9", "0.125175"], ["84078.2", "0.109718"], ["84079.5", "0.182862"], ["84080.7", "0.04"], ["84080.8", "0.003"], ["84082.2", "0.135482"], ["84082.6", "0.048518"], ["84083.4", "0.179888"], ["84088.7", "0.183015"], ["84089.1", "0.312247"], ["84089.4", "0"], ["84090.1", "0"], ["84092.4", "0.049351"], ["84093.7", "0.000972"], ["84094.8", "0"], ["84095.7", "0.303888"], ["84097.4", "0"], ["84101.1", "0.000518"], ["84101.3", "0.009"], ["84110.1", "0.608318"], ["84115.7", "1.14067"], ["84117.7", "0"], ["84136.3", "0"], ["84142.4", "0"]], "u": 19887, "seq": 67549925318}, "cts": 1742555184517, "record_time": 1742555184.53274, "EXCHANGE": "BYBIT"}
{"topic": "orderbook.200.BTCUSDT", "ts": 1742555184719, "type": "delta", "data": {"s": "BTCUSDT", "b": [["84070.4", "0.005461"], ["84058.5", "0.000333"], ["84057.8", "0.030389"], ["84055.1", "0.088"], ["84053.7", "0"], ["84053.5", "0.101905"], ["84051.8", "0.08"], ["84050.2", "0.038459"], ["84048.5", "0.04"], ["84048.4", "0.04"], ["84046", "0"], ["84043.2", "0"], ["84041.3", "0.018457"], ["84040.5", "0.025121"], ["84037.8", "0.170702"], ["84036.2", "0"], ["84034.2", "0.52406"], ["84032.8", "0.177152"], ["84031.9", "0"], ["84031.4", "0"], ["84029.6", "0"], ["84028.6", "0"], ["84026.3", "0"], ["84026.1", "0.118804"], ["84024.4", "0"], ["84016.3", "0.135512"], ["84013.7", "0.040805"], ["84013.6", "0"], ["84000.5", "15.055545"], ["83997.7", "0.027691"], ["83986.6", "0.050337"], ["83986.4", "0.001423"]], "a": [["84070.5", "0.477526"], ["84077.5", "0.084"], ["84078.2", "0"], ["84079.1", "0.04"], ["84079.3", "0.048"], ["84080.9", "0.048"], ["84082.3", "0"], ["84082.4", "0"], ["84084", "0.098008"], ["84084.2", "0.048"], ["84084.3", "0.052"], ["84085.7", "0"], ["84085.9", "0.477447"], ["84087.4", "0"], ["84088.7", "0"], ["84089.1", "0.260247"], ["84092.4", "0.109644"], ["84093.7", "0"], ["84094.4", "0.000099"], ["84095.7", "0"], ["84101.1", "0.167282"], ["84104.8", "0.118804"], ["84107.8", "2.256866"], ["84118", "0.118941"], ["84127.9", "3.57375"], ["84142.3", "0"]], "u": 19888, "seq": 67549925457}, "cts": 1742555184718, "record_time": 1742555184.732518, "EXCHANGE": "BYBIT"}
{"topic": "orderbook.200.BTCUSDT", "ts": 1742555184919, "type": "delta", "data": {"s": "BTCUSDT", "b": [["84070.4", "0.004306"], ["84060.4", "0"], ["84058.3", "0.011901"], ["84051.1", "0.005899"], ["84050", "0.04486"], ["84046.1", "0.061233"], ["84028.7", "0"], ["84016.4", "0.049869"], ["84013.7", "0"], ["83986.3", "0.001466"]], "a": [["84082.4", "0.04"], ["84087.5", "0.023787"], ["84089", "0"], ["84092.4", "0.024384"], ["84093.2", "0"], ["84104.9", "0.04"], ["84105", "0.04"], ["84112.7", "0.048"], ["84112.8", "0.005946"], ["84139", "0.169029"], ["84141.4", "1.12311"], ["84141.6", "0"], ["84141.9", "0"]], "u": 19889, "seq": 67549925571}, "cts": 1742555184916, "record_time": 1742555184.93368, "EXCHANGE": "BYBIT"}
{"topic": "orderbook.200.BTCUSDT", "ts": 1742555185120, "type": "delta", "data": {"s": "BTCUSDT", "b": [["84070.4", "0.005106"], ["84050.2", "0.066906"], ["84032.8", "0.295956"], ["84025.9", "0"], ["83995.1", "3.495029"], ["83994.1", "0"], ["83985.6", "0.000516"]], "a": [["84070.5", "0.482504"], ["84074.9", "0.144084"], ["84075", "0.477447"], ["84078.6", "0.065704"], ["84085.8", "0.137231"], ["84085.9", "0"], ["84104.9", "0"], ["84105", "0"], ["84105.1", "0.04"], ["84105.2", "0.04"], ["84139.6", "0.171"], ["84141.3", "0"], ["84141.4", "0"], ["84141.5", "0"]], "u": 19890, "seq": 67549925680}, "cts": 1742555185113, "record_time": 1742555185.132771, "EXCHANGE": "BYBIT"}
{"topic": "orderbook.200.BTCUSDT", "ts": 1742555185320, "type": "delta", "data": {"s": "BTCUSDT", "b": [["84070.4", "0.005864"], ["84044.2", "0"], ["84040.4", "0"], ["84036", "0.025012"], ["84028.4", "0.014423"], ["84028.3", "0.012882"], ["84028.2", "0.04"], ["84028.1", "0.125545"], ["84026", "0.005942"], ["84025.9", "0.0264"], ["84008.2", "0.128559"], ["83985.6", "0"]], "a": [["84104.1", "0.012857"], ["84104.2", "0.012857"], ["84105", "0.04"], ["84105.2", "0"], ["84111.8", "0"], ["84111.9", "0.023784"], ["84120.2", "0.024914"], ["84123.6", "0.178309"], ["84124.6", "0"], ["84140.9", "0"], ["84141.2", "0"]], "u": 19891, "seq": 67549925758}, "cts": 1742555185304, "record_time": 1742555185.334217, "EXCHANGE": "BYBIT"}
{"topic": "orderbook.200.BTCUSDT", "ts": 1742555185520, "type": "delta", "data": {"s": "BTCUSDT", "b": [["84070.4", "0.002891"], ["84057.8", "0.042327"], ["84057", "0.0039"], ["84054.4", "0"], ["84054.3", "0.134535"], ["84051.1", "0.0003"], ["84048", "0.061564"], ["84041", "0.056152"], ["84040.5", "0.017838"], ["84037.8", "0.237385"], ["84034", "0.113801"], ["84031.8", "0.000516"], ["84028.3", "0.014482"], ["83986.4", "0"], ["83986.3", "0"]], "a": [["84070.5", "0.585556"], ["84070.8", "0.035684"], ["84076.4", "0.404945"], ["84083", "0.057579"], ["84090", "0.060177"], ["84097", "0.121207"], ["84139.2", "0"], ["84139.6", "0"], ["84140", "0"]], "u": 19892, "seq": 67549926168}, "cts": 1742555185513, "record_time": 1742555185.532628, "EXCHANGE": "BYBIT"}
{"topic": "orderbook.200.BTCUSDT", "ts": 1742555185720, "type": "delta", "data": {"s": "BTCUSDT", "b": [["84070.4", "0.005864"], ["84055.4", "0"], ["84054.4", "0.0003"], ["84053.2", "0.123098"], ["84051.1", "0"], ["84049.1", "0.118899"], ["84048", "0"], ["84042.7", "0.18513"], ["84042.1", "0.186123"], ["84041.1", "0.055643"], ["84041", "0.001849"], ["84040.5", "0"], ["84035.7", "0.299401"], ["84035.1", "0.312346"], ["84034", "0"], ["84032.8", "0.177152"], ["84028.4", "0.001423"], ["84028.2", "0.052882"], ["84007.7", "0"], ["83990.4", "0.036923"], ["83987.6", "0"], ["83987.1", "0.050333"], ["83986.6", "0"]], "a": [["84070.5", "0.623024"], ["84077.7", "0.120964"], ["84079.5", "0.00444"], ["84080.4", "0.005864"], ["84082", "0.124321"], ["84083", "0.001333"], ["84087.8", "0"], ["84088.2", "0.183159"], ["84089", "0.166957"], ["84090", "0"], ["84095.2", "0.291571"], ["84096", "0.278087"], ["84096.7", "0.075001"], ["84097", "0"], ["84138.8", "0"], ["84138.9", "0"], ["84139", "0"], ["84139.1", "0"]], "u": 19893, "seq": 67549926283}, "cts": 1742555185717, "record_time": 1742555185.732855, "EXCHANGE": "BYBIT"}
{"topic": "orderbook.200.BTCUSDT", "ts": 1742555185920, "type": "delta", "data": {"s": "BTCUSDT", "b": [["84070.4", "0.011012"], ["84055.3", "0.024177"], ["84053.2", "0.003181"], ["84049.1", "0"], ["84046.1", "0.158618"], ["84042.7", "0"], ["84042.1", "0"], ["84041.1", "0.019347"], ["84037.8", "0.412573"], ["84035.7", "0"], ["84035.1", "0"], ["83989.8", "1.125137"], ["83986.6", "0.000337"], ["83986.4", "0.001423"], ["83986.3", "0.001466"]], "a": [["84070.5", "0.5288"], ["84077.7", "0"], ["84082", "0"], ["84088.2", "0"], ["84089", "0"], ["84092.4", "0.190446"], ["84095.2", "0"], ["84096", "0"], ["84096.7", "0.037579"], ["84104.1", "0"], ["84104.2", "0"], ["84104.4", "0.013"], ["84104.5", "0.012857"], ["84105", "0"], ["84105.1", "0"], ["84105.3", "0.04"], ["84105.4", "0.04"], ["84138.8", "0.035532"], ["84138.9", "0.001466"], ["84139", "0.027757"], ["84139.1", "0.011844"], ["84139.2", "0.178257"], ["84140", "0.00024"]], "u": 19894, "seq": 67549926380}, "cts": 1742555185916, "record_time": 1742555185.933912, "EXCHANGE": "BYBIT"}
{"topic": "orderbook.200.BTCUSDT", "ts": 1742555186119, "type": "delta", "data": {"s": "BTCUSDT", "b": [["84046.1", "0.061233"], ["84037.8", "0.237385"]], "a": [["84070.5", "0.530584"], ["84092.4", "0.024384"], ["84139.6", "0.171"], ["84140", "0"]], "u": 19895, "seq": 67549926429}, "cts": 1742555186117, "record_time": 1742555186.133219, "EXCHANGE": "BYBIT"}
{"topic": "orderbook.200.BTCUSDT", "ts": 1742555186320, "type": "delta", "data": {"s": "BTCUSDT", "b": [["84070.4", "0.011395"], ["84041.3", "0.013697"], ["84036.5", "0"], ["84028.3", "0.0016"], ["84028.1", "0.138427"], ["84000.5", "0"], ["83997.7", "14.628413"], ["83986.1", "0.05"], ["83985.6", "0.000516"]], "a": [["84070.5", "0.628592"], ["84102.1", "2.256866"], ["84103.7", "0.016236"], ["84103.8", "0.012857"], ["84104.4", "0"], ["84104.5", "0"], ["84104.9", "0.04"], ["84105", "0.04"], ["84105.3", "0"], ["84105.4", "0"], ["84107.8", "0"], ["84140", "0.00024"]], "u": 19896, "seq": 67549926500}, "cts": 1742555186308, "record_time": 1742555186.33299, "EXCHANGE": "BYBIT"}
{"topic": "orderbook.200.BTCUSDT", "ts": 1742555186519, "type": "delta", "data": {"s": "BTCUSDT", "b": [["84070.4", "0.000005"], ["84061.9", "0"], ["84059.5", "0.003515"], ["84058.3", "0"], ["84057.8", "0.001333"], ["84057.7", "0"], ["84057", "0"], ["84055.3", "0"], ["84054.3", "0.000333"], ["84053.6", "0.001333"], ["84041.1", "0.030742"], ["84038.9", "0"], ["84036", "0.000118"], ["84028.2", "0.04"], ["84028.1", "0.125545"], ["84027", "0.013"], ["84026.9", "0.012883"], ["84026.1", "0"], ["84016.3", "0"], ["84008.8", "0"], ["84008.2", "0"], ["84007.8", "0.135502"], ["83997.7", "0.027691"], ["83990.6", "0.001333"], ["83987.2", "0.013097"], ["83985.2", "0.044"], ["83984.4", "0.059399"], ["83984.2", "0.04"], ["83982.3", "0.04"], ["83982.2", "0.001333"], ["83981.8", "0.000019"]], "a": [["84070.5", "0.614592"], ["84074.6", "0.001333"], ["84083.4", "0.001466"], ["84096.3", "0.000333"], ["84101.1", "0.84382"], ["84102.1", "0"], ["84103.7", "0.003236"], ["84103.9", "0.012857"], ["84105.5", "0.029195"], ["84116.2", "2.256866"], ["84120.2", "0"], ["84123.6", "0"], ["84126.6", "0.003983"]], "u": 19897, "seq": 67549926765}, "cts": 1742555186517, "record_time": 1742555186.532419, "EXCHANGE": "BYBIT"}
{"topic": "orderbook.200.BTCUSDT", "ts": 1742555186719, "type": "delta", "data": {"s": "BTCUSDT", "b": [["84070.4", "0"], ["84070.1", "0"], ["84069.5", "0"], ["84068.9", "0"], ["84068.7", "0"], ["84066.9", "0"], ["84066.2", "0"], ["84065.9", "0"], ["84064.9", "0"], ["84064.1", "0"], ["84064", "0"], ["84063.1", "0.176262"], ["84059.8", "0"], ["84057.6", "0.01142"], ["84054.4", "0"], ["84053.6", "0.11845"], ["84053.5", "0.092"], ["84053.4", "0.022841"], ["84050.6", "0.019783"], ["84048.4", "0.063796"], ["84043.6", "0.0003"], ["84043", "0.009969"], ["84041.3", "0.009"], ["84041.1", "0"], ["84037.9", "0.059399"], ["84034.2", "0"], ["84032.7", "0"], ["84028.1", "0.113644"], ["84028", "0.003181"], ["84027.8", "0.172194"], ["84027.5", "0.022726"], ["84027", "0"], ["84026.9", "0"], ["84025.1", "0"], ["84025", "0.01308"], ["84024.9", "0.013214"], ["84023.3", "0.001466"], ["84022.2", "0.525512"], ["84021.8", "0.04"], ["84019.7", "0.00009"], ["84019.6", "0.495725"], ["84019.2", "0"], ["84018.3", "0.011903"], ["84016.4", "0.0001"], ["84016.1", "0.04"], ["84012.4", "1.180674"], ["84012.3", "0.000333"], ["84011.4", "0"], ["84011.1", "0.063791"], ["84009.3", "0.023791"], ["84007.1", "0.023791"], ["84005.2", "0.023791"], ["83997.7", "0"], ["83990.5", "0"], ["83990.4", "0"], ["83989.8", "0"], ["83987.1", "0.000333"], ["83986.6", "0.040206"], ["83986.1", "0"], ["83986", "0.003181"], ["83985.8", "3.284949"], ["83984.6", "0.171"], ["83982.9", "0.000333"], ["83981.8", "0.0032"], ["83981.7", "0.001466"], ["83981.3", "0.020845"], ["83980.9", "0.000516"], ["83980", "0.132291"], ["83979.9", "0.05"], ["83978.7", "0.05"], ["83978.3", "0.011844"]], "a": [["84063.2", "0.532314"], ["84063.5", "0.035686"], ["84065.4", "0.001189"], ["84068.2", "0.0025"], ["84068.7", "0.095568"], ["84068.8", "0.183658"], ["84069.5", "0.001466"], ["84070.1", "0.003224"], ["84070.4", "0.001333"], ["84070.5", "0.020535"], ["84070.8", "0"], ["84071.1", "0.000333"], ["84072.1", "0.044"], ["84073.4", "0.000516"], ["84073.5", "0.04"], ["84074.2", "0.001466"], ["84074.3", "0.003224"], ["84075.4", "0.00009"], ["84075.5", "0"], ["84075.8", "0.023789"], ["84076.3", "0.413997"], ["84076.4", "0.597165"], ["84076.5", "0.006742"], ["84076.9", "0.112798"], ["84077.1", "0.048"], ["84078.8", "0.322808"], ["84078.9", "0.075787"], ["84080.6", "0.099801"], ["84081.1", "0"], ["84082.2", "0"], ["84082.6", "0.000518"], ["84084.4", "0.000999"], ["84085.7", "0.059473"], ["84088.9", "0.004584"], ["84089.2", "0.03874"], ["84090.5", "0.059468"], ["84091", "0.029734"], ["84092.4", "0.015461"], ["84094.3", "0.023791"], ["84095", "0.023791"], ["84095.9", "0.005947"], ["84098.5", "0.023791"], ["84100.3", "0.023791"], ["84101.1", "0.167282"], ["84101.2", "0.194791"], ["84102.4", "0.35335"], ["84102.7", "0"], ["84105.1", "1.425978"], ["84105.6", "0.015"], ["84111.7", "0.023606"], ["84112.4", "0.001333"], ["84115.7", "1.701734"], ["84115.8", "0.149923"], ["84116.2", "0"], ["84117", "3.181773"], ["84119.1", "2.256866"], ["84128.1", "0.059449"], ["84128.8", "0.0001"], ["84131.3", "0"], ["84132", "0"], ["84132.1", "0"], ["84132.3", "0"], ["84132.8", "0"], ["84133.1", "0"], ["84133.5", "0"], ["84134", "0"], ["84134.1", "0"], ["84134.2", "0"], ["84134.3", "0"], ["84134.6", "0"], ["84135", "0"], ["84135.8", "0"], ["84137.1", "0"], ["84137.2", "0"], ["84137.3", "0"], ["84137.7", "0"], ["84138.1", "0"], ["84138.4", "0"], ["84138.8", "0"], ["84138.9", "0"], ["84139", "0"], ["84139.1", "0"], ["84139.2", "0"], ["84139.6", "0"], ["84140", "0"]], "u": 19898, "seq": 67549927819}, "cts": 1742555186716, "record_time": 1742555186.733139, "EXCHANGE": "BYBIT"}
{"topic": "orderbook.200.BTCUSDT", "ts": 1742555186919, "type": "delta", "data": {"s": "BTCUSDT", "b": [["84063.1", "0.347262"], ["84056.5", "0.032714"], ["84049", "0.009109"], ["84040.7", "0.018792"], ["84037.8", "0"], ["84036.1", "0.035695"], ["84035.7", "0.051489"], ["84032.8", "0.525512"], ["84032.1", "0.004567"], ["84030.2", "0.492627"], ["84027.9", "0.12027"], ["84025.2", "0.184605"], ["84022.2", "0"], ["84020.3", "0.349545"], ["84019.6", "0.003181"], ["84017.5", "0.013878"], ["84016.3", "0.135541"], ["84012.4", "0.186775"], ["84007.8", "0"], ["83997.7", "14.433465"], ["83988.5", "0.027657"], ["83983.3", "0.62453"], ["83982.4", "0.19739"], ["83981.7", "0"], ["83981.3", "0"], ["83980.9", "0"], ["83980", "0"], ["83979.9", "0"], ["83978.7", "0"], ["83978.3", "0"]], "a": [["84063.2", "0.542553"], ["84068.7", "0.107623"], ["84068.8", "0.171516"], ["84069.4", "0.178437"], ["84070.5", "0.018751"], ["84072", "0.04"], ["84073.9", "0.048"], ["84075.6", "0.048"], ["84075.8", "0"], ["84076.5", "0.005942"], ["84076.9", "0.152798"], ["84077.5", "0"], ["84078.8", "0.224799"], ["84079.1", "0"], ["84079.3", "0"], ["84080.9", "0"], ["84084.2", "0"], ["84084.3", "0"], ["84086.5", "0.059399"], ["84089.1", "0"], ["84090.4", "0.072974"], ["84094.4", "0"], ["84098.3", "0.063444"], ["84101.1", "0.278488"], ["84103.1", "0.014002"], ["84105", "0.493419"], ["84105.5", "0"], ["84106.8", "0"], ["84107.8", "2.256866"], ["84110.1", "0.206362"], ["84113.7", "0.002141"], ["84115.7", "0"], ["84119.1", "0"], ["84130.8", "0"], ["84131.3", "0.009"], ["84132", "0.0018"], ["84132.1", "0.059449"], ["84132.8", "0.059399"], ["84133.1", "0.003211"]], "u": 19899, "seq": 67549928040}, "cts": 1742555186916, "record_time": 1742555186.934028, "EXCHANGE": "BYBIT"}
{"topic": "orderbook.200.BTCUSDT", "ts": 1742555187120, "type": "delta", "data": {"s": "BTCUSDT", "b": [["84063.1", "0.176262"], ["84054.4", "0.0003"], ["84053.6", "0.11854"], ["84051.8", "0.04"], ["84045.9", "0.027975"], ["84043.6", "0"], ["84032.9", "0.25615"], ["84027.8", "0.059399"], ["84025.2", "0.016411"], ["84020.3", "0.242838"], ["84016.4", "0.061878"], ["84000", "3.638878"], ["83999.3", "0.128573"], ["83997.7", "0"], ["83991", "0.001466"], ["83987.3", "0.04"], ["83986.6", "0.000337"], ["83986.4", "14.434888"], ["83982.6", "0.039733"], ["83982.3", "0"], ["83982.2", "0"], ["83981.8", "0"]], "a": [["84068.7", "0.107881"], ["84068.8", "0.171258"], ["84070.5", "0.018351"], ["84075.3", "0.040333"], ["84080.6", "0.073401"], ["84082.4", "0"], ["84083.4", "0.090685"], ["84096.7", "0.071946"], ["84102.2", "0.04"], ["84102.3", "0.04"], ["84104.9", "0"], ["84105", "1.054769"], ["84107.8", "2.257062"], ["84128.2", "0.02752"], ["84133.1", "0"]], "u": 19900, "seq": 67549928169}, "cts": 1742555187116, "record_time": 1742555187.134378, "EXCHANGE": "BYBIT"}
{"topic": "orderbook.200.BTCUSDT", "ts": 1742555187319, "type": "delta", "data": {"s": "BTCUSDT", "b": [["84063.1", "0.34736"], ["84047.7", "0.04"], ["84045.9", "0.000333"], ["84028.4", "0.114221"], ["84025.2", "0"], ["84025", "0.038159"], ["83989.2", "14.433465"], ["83986.4", "0.001423"], ["83982.7", "0.039733"], ["83982.6", "0"], ["83982.4", "0"]], "a": [["84068.7", "0.108139"], ["84068.8", "0.171"], ["84072.7", "0.251654"], ["84072.8", "0.178437"], ["84074.9", "0"], ["84080.7", "0"], ["84087.4", "0.003482"], ["84101.1", "0.449193"], ["84132.8", "0"]], "u": 19901, "seq": 67549928237}, "cts": 1742555187309, "record_time": 1742555187.333606, "EXCHANGE": "BYBIT"}
{"topic": "orderbook.200.BTCUSDT", "ts": 1742555187520, "type": "delta", "data": {"s": "BTCUSDT", "b": [["84063.1", "0.17636"], ["84036.1", "0"], ["84000.5", "14.433465"], ["83989.2", "0"], ["83982.4", "0.19739"]], "a": [["84073", "0.005948"], ["84080.4", "0"], ["84101.1", "0.000518"], ["84102.2", "0"], ["84102.4", "0.39335"], ["84113.7", "0.180471"], ["84132.8", "0.059399"]], "u": 19902, "seq": 67549928287}, "cts": 1742555187516, "record_time": 1742555187.534349, "EXCHANGE": "BYBIT"}
{"topic": "orderbook.200.BTCUSDT", "ts": 1742555187720, "type": "delta", "data": {"s": "BTCUSDT", "b": [["84053.3", "0.053706"], ["84031.2", "0.035696"], ["84028.5", "0.170927"], ["84028.1", "0"], ["84025.1", "0.013"], ["84024.9", "0.000333"], ["83997.9", "0"], ["83989.9", "0.235392"], ["83982.9", "0"], ["83982.7", "0"], ["83982.4", "0"]], "a": [["84081.3", "0.035695"], ["84096.5", "0.000518"], ["84101.4", "0.013"], ["84101.5", "0.012855"], ["84103.8", "0"], ["84103.9", "0"], ["84132.8", "0"]], "u": 19903, "seq": 67549928344}, "cts": 1742555187695, "record_time": 1742555187.732775, "EXCHANGE": "BYBIT"}
{"topic": "orderbook.200.BTCUSDT", "ts": 1742555187920, "type": "delta", "data": {"s": "BTCUSDT", "b": [["84063.1", "0.34816"]], "a": [["84063.2", "0.548553"], ["84101.1", "0.303576"], ["84101.4", "0"], ["84101.5", "0"], ["84101.6", "0.013"], ["84101.7", "0.101954"], ["84102.3", "0"], ["84102.4", "0.35335"], ["84102.5", "0.04"], ["84102.6", "0.04"]], "u": 19904, "seq": 67549928382}, "cts": 1742555187917, "record_time": 1742555187.933233, "EXCHANGE": "BYBIT"}
{"topic": "orderbook.200.BTCUSDT", "ts": 1742555188120, "type": "delta", "data": {"s": "BTCUSDT", "b": [["84025.1", "0"], ["84024.9", "0.013214"], ["83982.9", "0.000333"]], "a": [["84063.2", "0.554553"], ["84101.6", "0"], ["84101.7", "0.089099"], ["84102", "0.012855"], ["84102.1", "2.269917"], ["84102.5", "0"], ["84102.6", "0"], ["84102.8", "0.04"], ["84102.9", "0.04"], ["84107.8", "0"]], "u": 19905, "seq": 67549928409}, "cts": 1742555188105, "record_time": 1742555188.133547, "EXCHANGE": "BYBIT"}
{"topic": "orderbook.200.BTCUSDT", "ts": 1742555188320, "type": "delta", "data": {"s": "BTCUSDT", "b": [["84063.1", "0.348229"], ["84000.5", "0"], ["83997.7", "14.326879"]], "a": [["84081.3", "0"], ["84102.8", "0"], ["84103", "0.099462"], ["84105", "0.453419"], ["84132.8", "0.059399"], ["84133.1", "0.003211"]], "u": 19906, "seq": 67549928437}, "cts": 1742555188312, "record_time": 1742555188.333801, "EXCHANGE": "BYBIT"}
{"topic": "orderbook.200.BTCUSDT", "ts": 1742555188520, "type": "delta", "data": {"s": "BTCUSDT", "b": [["84063.1", "0.34594"], ["84054.4", "0"], ["83982.4", "0.19739"]], "a": [["84080.8", "0"], ["84101", "0.05993"], ["84133.5", "0.001851"]], "u": 19907, "seq": 67549928490}, "cts": 1742555188516, "record_time": 1742555188.534078, "EXCHANGE": "BYBIT"}
{"topic": "orderbook.200.BTCUSDT", "ts": 1742555188719, "type": "delta", "data": {"s": "BTCUSDT", "b": [["84063.1", "0.347698"], ["84054.4", "0.0003"], ["84000.5", "14.326879"], ["83997.7", "0"], ["83982.4", "0"]], "a": [["84063.2", "0.560553"], ["84081.3", "0.035695"], ["84102.7", "0.04"], ["84102.8", "0.04"], ["84102.9", "0"], ["84103", "0.059462"], ["84133.1", "0"], ["84133.5", "0"]], "u": 19908, "seq": 67549928515}, "cts": 1742555188708, "record_time": 1742555188.733665, "EXCHANGE": "BYBIT"}
{"topic": "orderbook.200.BTCUSDT", "ts": 1742555188920, "type": "delta", "data": {"s": "BTCUSDT", "b": [], "a": [["84063.2", "0.566553"], ["84101.8", "0.012855"], ["84101.9", "0.014321"], ["84102", "0"], ["84102.1", "2.257062"]], "u": 19909, "seq": 67549928523}, "cts": 1742555188858, "record_time": 1742555188.933805, "EXCHANGE": "BYBIT"}
{"topic": "orderbook.200.BTCUSDT", "ts": 1742555189119, "type": "delta", "data": {"s": "BTCUSDT", "b": [], "a": [["84063.2", "0.459541"], ["84081.3", "0"], ["84101.1", "0.942769"], ["84133.1", "0.003211"]], "u": 19910, "seq": 67549928545}, "cts": 1742555189112, "record_time": 1742555189.26067, "EXCHANGE": "BYBIT"}
{"topic": "orderbook.200.BTCUSDT", "ts": 1742555189320, "type": "delta", "data": {"s": "BTCUSDT", "b": [["84063.1", "0.335671"]], "a": [], "u": 19911, "seq": 67549928561}, "cts": 1742555189311, "record_time": 1742555189.334531, "EXCHANGE": "BYBIT"}
{"topic": "orderbook.200.BTCUSDT", "ts": 1742555189520, "type": "delta", "data": {"s": "BTCUSDT", "b": [["84049", "0.013409"], ["84028.3", "0"], ["84020.3", "0.244438"], ["83982.6", "0.039343"]], "a": [["84081.3", "0.035695"], ["84102.6", "0.04"], ["84102.8", "0"], ["84133.1", "0"]], "u": 19912, "seq": 67549928584}, "cts": 1742555189517, "record_time": 1742555189.533693, "EXCHANGE": "BYBIT"}
{"topic": "orderbook.200.BTCUSDT", "ts": 1742555189720, "type": "delta", "data": {"s": "BTCUSDT", "b": [], "a": [["84063.2", "0.465541"], ["84101.7", "0.101954"], ["84101.9", "0.001466"]], "u": 19913, "seq": 67549928595}, "cts": 1742555189716, "record_time": 1742555189.734059, "EXCHANGE": "BYBIT"}
{"topic": "orderbook.200.BTCUSDT", "ts": 1742555189920, "type": "delta", "data": {"s": "BTCUSDT", "b": [["84063.1", "0.343413"]], "a": [], "u": 19914, "seq": 67549928598}, "cts": 1742555189848, "record_time": 1742555189.933084, "EXCHANGE": "BYBIT"}
{"success": true, "ret_msg": "pong", "conn_id": "d254c3be-961e-4554-aae4-742fef071034", "op": "ping", "record_time": 1742555190.095658, "EXCHANGE": "BYBIT"}
{"topic": "orderbook.200.BTCUSDT", "ts": 1742555190120, "type": "delta", "data": {"s": "BTCUSDT", "b": [["84000.5", "0"], ["83997.7", "14.268423"]], "a": [["84102.1", "0"], ["84107.8", "2.257062"]], "u": 19915, "seq": 67549928636}, "cts": 1742555190112, "record_time": 1742555190.132739, "EXCHANGE": "BYBIT"}
{"topic": "orderbook.200.BTCUSDT", "ts": 1742555190319, "type": "delta", "data": {"s": "BTCUSDT", "b": [["84063.1", "0.331413"], ["84050.7", "0.108958"], ["84050.2", "0.104708"], ["84046.6", "0.123828"], ["84040.2", "0.167275"], ["84039.6", "0.183528"], ["84033.2", "0.28471"], ["84032.6", "0.295732"], ["84000.5", "14.268423"], ["83997.7", "0"], ["83984.4", "0"], ["83984.2", "0"], ["83983.3", "0"], ["83982.9", "0"], ["83982.6", "0"]], "a": [["84071.5", "0.005942"], ["84075.2", "0.117803"], ["84076.5", "0"], ["84079.5", "0.118151"], ["84085.7", "0.238954"], ["84086.5", "0.225414"], ["84088.3", "0.005942"], ["84092.7", "0.290823"], ["84092.9", "0"], ["84093.5", "0.2913"], ["84101.1", "0.303576"], ["84104.9", "2.257062"], ["84105", "1.054827"], ["84105.1", "1.43192"], ["84107.8", "0"], ["84109.7", "0"], ["84121.9", "0.005942"], ["84126.5", "0"], ["84132.8", "0"]], "u": 19916, "seq": 67549928742}, "cts": 1742555190302, "record_time": 1742555190.332759, "EXCHANGE": "BYBIT"}
{"topic": "orderbook.200.BTCUSDT", "ts": 1742555190520, "type": "delta", "data": {"s": "BTCUSDT", "b": [["84063.1", "0.332673"], ["84059.6", "0"], ["84059.5", "0.000516"], ["84055", "0.005942"], ["84050.7", "0"], ["84050.2", "0.066906"], ["84046.6", "0"], ["84042.8", "0"], ["84040.2", "0"], ["84039.6", "0"], ["84038.2", "0.005942"], ["84033.2", "0"], ["84032.9", "0.376305"], ["84032.6", "0.001333"], ["84026", "0"], ["84021.4", "0.005942"], ["84009.2", "0"], ["84004.6", "0.005942"], ["83984.4", "0.059399"], ["83984.2", "0.04"], ["83983.3", "0.62453"], ["83982.9", "0.000333"], ["83982.7", "0.039343"]], "a": [["84063.2", "0.470314"], ["84075.2", "0"], ["84079.5", "0.00444"], ["84081.3", "0.035696"], ["84085.7", "0.059473"], ["84086.5", "0.059399"], ["84092.7", "0.001466"], ["84093.5", "0"], ["84105", "0.453419"], ["84132.8", "0.059399"], ["84133.1", "0.003211"]], "u": 19917, "seq": 67549928797}, "cts": 1742555190503, "record_time": 1742555190.573748, "EXCHANGE": "BYBIT"}
{"topic": "orderbook.200.BTCUSDT", "ts": 1742555190720, "type": "delta", "data": {"s": "BTCUSDT", "b": [["84025", "0.025278"], ["84024.8", "0.012981"]], "a": [["84072.7", "0.110204"], ["84075", "0"], ["84076.3", "0.226042"], ["84076.4", "0.059399"], ["84086.8", "0.600254"], ["84093.3", "0.537766"], ["84101.8", "0.012851"]], "u": 19918, "seq": 67549928823}, "cts": 1742555190709, "record_time": 1742555190.763905, "EXCHANGE": "BYBIT"}
{"topic": "orderbook.200.BTCUSDT", "ts": 1742555190919, "type": "delta", "data": {"s": "BTCUSDT", "b": [["84063.1", "0.324931"], ["84054.4", "0"], ["84042.8", "0.0003"], ["84025", "0.038278"], ["84024.8", "0.0001"]], "a": [["84063.2", "0.482314"]], "u": 19919, "seq": 67549928832}, "cts": 1742555190913, "record_time": 1742555190.934131, "EXCHANGE": "BYBIT"}
{"topic": "orderbook.200.BTCUSDT", "ts": 1742555191119, "type": "delta", "data": {"s": "BTCUSDT", "b": [["84038.5", "0.003576"], ["83982.7", "0"]], "a": [["84102.1", "2.257062"], ["84104.9", "0"]], "u": 19920, "seq": 67549928839}, "cts": 1742555191082, "record_time": 1742555191.13436, "EXCHANGE": "BYBIT"}
{"topic": "orderbook.200.BTCUSDT", "ts": 1742555191320, "type": "delta", "data": {"s": "BTCUSDT", "b": [["84063.1", "0.29997"]], "a": [["84101.1", "0.942768"]], "u": 19921, "seq": 67549928857}, "cts": 1742555191296, "record_time": 1742555191.335009, "EXCHANGE": "BYBIT"}
{"topic": "orderbook.200.BTCUSDT", "ts": 1742555191520, "type": "delta", "data": {"s": "BTCUSDT", "b": [["84042.9", "0.0003"], ["84042.8", "0"], ["83996.9", "0"], ["83985.1", "0.353365"]], "a": [["84106", "0.010848"], ["84133.1", "0"]], "u": 19922, "seq": 67549928864}, "cts": 1742555191511, "record_time": 1742555191.622535, "EXCHANGE": "BYBIT"}
{"topic": "orderbook.200.BTCUSDT", "ts": 1742555191720, "type": "delta", "data": {"s": "BTCUSDT", "b": [["84038.5", "0"], ["83982.7", "0.039343"]], "a": [], "u": 19923, "seq": 67549928876}, "cts": 1742555191710, "record_time": 1742555191.812245, "EXCHANGE": "BYBIT"}
{"topic": "orderbook.200.BTCUSDT", "ts": 1742555191919, "type": "delta", "data": {"s": "BTCUSDT", "b": [["84063.1", "0.29917"]], "a": [["84063.2", "0.483114"], ["84102.1", "0"], ["84107.8", "2.257062"]], "u": 19924, "seq": 67549928909}, "cts": 1742555191917, "record_time": 1742555191.9339, "EXCHANGE": "BYBIT"}
{"topic": "orderbook.200.BTCUSDT", "ts": 1742555192120, "type": "delta", "data": {"s": "BTCUSDT", "b": [["84025", "0.038159"], ["83982.7", "0.038783"]], "a": [["84101.1", "0.303576"], ["84101.7", "0.089099"], ["84101.8", "0"], ["84101.9", "0.014317"], ["84102", "0.012851"], ["84102.6", "0"], ["84102.7", "0"], ["84102.8", "0.04"], ["84102.9", "0.04"], ["84104.9", "2.257062"], ["84107.8", "0"]], "u": 19925, "seq": 67549928934}, "cts": 1742555192001, "record_time": 1742555192.193518, "EXCHANGE": "BYBIT"}
{"topic": "orderbook.200.BTCUSDT", "ts": 1742555192319, "type": "delta", "data": {"s": "BTCUSDT", "b": [["84063.1", "0.291973"]], "a": [["84063.2", "0.489114"], ["84104.9", "0"], ["84107.8", "2.257062"]], "u": 19926, "seq": 67549928964}, "cts": 1742555192317, "record_time": 1742555192.401599, "EXCHANGE": "BYBIT"}
{"topic": "orderbook.200.BTCUSDT", "ts": 1742555192520, "type": "delta", "data": {"s": "BTCUSDT", "b": [["84063.1", "0.17706"], ["84049", "0.007481"], ["84000.5", "0"], ["83994.8", "14.042637"], ["83984.6", "0.201002"], ["83982.7", "0"], ["83982.4", "0.19739"], ["83982.3", "0.04"]], "a": [["84063.2", "0.491255"], ["84063.4", "0.037792"], ["84065.1", "0.089099"], ["84071.9", "0.089099"], ["84072.6", "0.181656"], ["84072.7", "0.118804"], ["84083.9", "0"], ["84092.4", "0.177522"], ["84104.9", "2.257062"], ["84107.8", "0"], ["84113.7", "0.17833"], ["84132", "0"], ["84132.1", "0"], ["84132.8", "0"]], "u": 19927, "seq": 67549929050}, "cts": 1742555192517, "record_time": 1742555192.534421, "EXCHANGE": "BYBIT"}
{"topic": "orderbook.200.BTCUSDT", "ts": 1742555192719, "type": "delta", "data": {"s": "BTCUSDT", "b": [["84063.1", "0.184343"], ["83994.8", "13.923752"], ["83984.6", "0.199683"]], "a": [], "u": 19928, "seq": 67549929099}, "cts": 1742555192717, "record_time": 1742555192.732963, "EXCHANGE": "BYBIT"}
{"topic": "orderbook.200.BTCUSDT", "ts": 1742555192920, "type": "delta", "data": {"s": "BTCUSDT", "b": [["84000.5", "13.921813"], ["83994.8", "0.001939"], ["83982.3", "0"]], "a": [["84102.1", "2.257062"], ["84104.9", "0"]], "u": 19929, "seq": 67549929112}, "cts": 1742555192833, "record_time": 1742555192.932916, "EXCHANGE": "BYBIT"}
{"topic": "orderbook.200.BTCUSDT", "ts": 1742555193120, "type": "delta", "data": {"s": "BTCUSDT", "b": [], "a": [["84063.2", "0.497255"], ["84063.4", "0"], ["84065.1", "0"], ["84132", "0.0018"], ["84132.1", "0.059449"]], "u": 19930, "seq": 67549929120}, "cts": 1742555193112, "record_time": 1742555193.194286, "EXCHANGE": "BYBIT"}
{"topic": "orderbook.200.BTCUSDT", "ts": 1742555193320, "type": "delta", "data": {"s": "BTCUSDT", "b": [["84063.1", "0.185143"]], "a": [["84072.6", "0.110204"], ["84072.7", "0"], ["84132.8", "0.059399"]], "u": 19931, "seq": 67549929134}, "cts": 1742555193282, "record_time": 1742555193.386604, "EXCHANGE": "BYBIT"}
{"topic": "orderbook.200.BTCUSDT", "ts": 1742555193520, "type": "delta", "data": {"s": "BTCUSDT", "b": [], "a": [["84069.8", "0.112799"], ["84076.9", "0.04"], ["84101.1", "0.942767"], ["84132.8", "0"]], "u": 19932, "seq": 67549929148}, "cts": 1742555193512, "record_time": 1742555193.542122, "EXCHANGE": "BYBIT"}
{"topic": "orderbook.200.BTCUSDT", "ts": 1742555193720, "type": "delta", "data": {"s": "BTCUSDT", "b": [["83984.9", "0.028683"], ["83984.6", "0.171"], ["83982.4", "0"]], "a": [["84063.2", "0.497234"]], "u": 19933, "seq": 67549929160}, "cts": 1742555193606, "record_time": 1742555193.733995, "EXCHANGE": "BYBIT"}
{"topic": "orderbook.200.BTCUSDT", "ts": 1742555193920, "type": "delta", "data": {"s": "BTCUSDT", "b": [["84063.1", "0.356143"], ["84048.8", "0.005796"], ["84025", "0.025278"], ["84024.8", "0.012981"], ["83982.9", "0"]], "a": [["84070.3", "0.024187"], ["84101.9", "0.001466"], ["84102.1", "2.269913"], ["84102.8", "0"], ["84103", "0.099462"]], "u": 19934, "seq": 67549929177}, "cts": 1742555193913, "record_time": 1742555193.954187, "EXCHANGE": "BYBIT"}
{"topic": "orderbook.200.BTCUSDT", "ts": 1742555194120, "type": "delta", "data": {"s": "BTCUSDT", "b": [["84024.9", "0.000333"], ["84024.7", "0.012881"], ["83983.3", "0"]], "a": [["84063.2", "0.495093"], ["84102", "0"], ["84102.1", "0"], ["84102.5", "0.012849"], ["84102.6", "0.012849"], ["84102.9", "0"], ["84103", "0.059462"], ["84103.4", "0.04"], ["84103.5", "0.04"], ["84105.8", "0.002141"], ["84107.8", "2.257062"], ["84131.3", "0"], ["84132", "0"], ["84132.1", "0"]], "u": 19935, "seq": 67549929255}, "cts": 1742555194110, "record_time": 1742555194.13348, "EXCHANGE": "BYBIT"}
{"topic": "orderbook.200.BTCUSDT", "ts": 1742555194320, "type": "delta", "data": {"s": "BTCUSDT", "b": [], "a": [["84071.9", "0"], ["84101.1", "0.303576"], ["84104.9", "2.257062"], ["84107.8", "0"], ["84131.3", "0.009"]], "u": 19936, "seq": 67549929278}, "cts": 1742555194313, "record_time": 1742555194.334075, "EXCHANGE": "BYBIT"}
{"topic": "orderbook.200.BTCUSDT", "ts": 1742555194520, "type": "delta", "data": {"s": "BTCUSDT", "b": [["84043", "0.015556"], ["84042.9", "0"], ["83984.9", "0"], ["83984.8", "0.029086"], ["83983.3", "0.62453"]], "a": [["84087.4", "0"], ["84132", "0.0018"]], "u": 19937, "seq": 67549929296}, "cts": 1742555194517, "record_time": 1742555194.533548, "EXCHANGE": "BYBIT"}
{"topic": "orderbook.200.BTCUSDT", "ts": 1742555194720, "type": "delta", "data": {"s": "BTCUSDT", "b": [["84063.1", "0.344397"]], "a": [["84091.6", "0.023792"], ["84101.1", "0.942765"], ["84132", "0"]], "u": 19938, "seq": 67549929311}, "cts": 1742555194646, "record_time": 1742555194.769645, "EXCHANGE": "BYBIT"}
{"topic": "orderbook.200.BTCUSDT", "ts": 1742555194920, "type": "delta", "data": {"s": "BTCUSDT", "b": [], "a": [["84063.2", "0.501093"], ["84104.9", "0"], ["84110.6", "2.257062"]], "u": 19939, "seq": 67549929352}, "cts": 1742555194916, "record_time": 1742555194.958555, "EXCHANGE": "BYBIT"}
{"topic": "orderbook.200.BTCUSDT", "ts": 1742555195120, "type": "delta", "data": {"s": "BTCUSDT", "b": [["84063.1", "0.345169"]], "a": [["84101.1", "0.303576"], ["84102.9", "0.04"], ["84103", "0.099462"], ["84103.4", "0"], ["84103.5", "0"], ["84110.6", "0"], ["84113.4", "2.257062"], ["84132", "0.0018"]], "u": 19940, "seq": 67549929371}, "cts": 1742555195113, "record_time": 1742555195.133215, "EXCHANGE": "BYBIT"}
{"topic": "orderbook.200.BTCUSDT", "ts": 1742555195319, "type": "delta", "data": {"s": "BTCUSDT", "b": [["84025.1", "0.013"], ["84025", "0.038159"], ["84024.8", "0.0001"], ["84024.7", "0"]], "a": [["84101.8", "0.013"], ["84101.9", "0.014315"], ["84102.1", "2.257062"], ["84102.5", "0"], ["84102.6", "0"], ["84102.7", "0.04"], ["84102.8", "0.04"], ["84102.9", "0"], ["84103", "0.059462"], ["84106", "0"], ["84113.4", "0"], ["84132.1", "0.059449"]], "u": 19941, "seq": 67549929401}, "cts": 1742555195299, "record_time": 1742555195.333231, "EXCHANGE": "BYBIT"}
{"topic": "orderbook.200.BTCUSDT", "ts": 1742555195520, "type": "delta", "data": {"s": "BTCUSDT", "b": [], "a": [["84070.3", "0"], ["84132.8", "0.059399"]], "u": 19942, "seq": 67549929420}, "cts": 1742555195491, "record_time": 1742555195.534738, "EXCHANGE": "BYBIT"}
{"topic": "orderbook.200.BTCUSDT", "ts": 1742555195720, "type": "delta", "data": {"s": "BTCUSDT", "b": [["84063.1", "0.174169"], ["84016.4", "0.19733"], ["84016.3", "0"], ["84000.5", "0"], ["83997.7", "14.547036"], ["83982.9", "0.000333"]], "a": [["84073.4", "0.023856"], ["84101.1", "0.942811"], ["84102.1", "0"], ["84104.9", "2.257062"]], "u": 19943, "seq": 67549929443}, "cts": 1742555195704, "record_time": 1742555195.814954, "EXCHANGE": "BYBIT"}
{"topic": "orderbook.200.BTCUSDT", "ts": 1742555195920, "type": "delta", "data": {"s": "BTCUSDT", "b": [["84016.5", "0.062114"], ["84016.4", "0.135552"], ["84000.5", "14.547036"], ["83997.7", "0"]], "a": [["84063.2", "0.507093"], ["84068.7", "0.159876"], ["84070.3", "0.089099"], ["84102.1", "2.257062"], ["84104.9", "0"], ["84132.8", "0"]], "u": 19944, "seq": 67549929460}, "cts": 1742555195851, "record_time": 1742555196.008134, "EXCHANGE": "BYBIT"}
{"topic": "orderbook.200.BTCUSDT", "ts": 1742555196120, "type": "delta", "data": {"s": "BTCUSDT", "b": [["84056.5", "0.052394"], ["84056.4", "0.075478"], ["84031.7", "0.02296"], ["84027.5", "0"]], "a": [["84101.8", "0.012849"]], "u": 19945, "seq": 67549929510}, "cts": 1742555196107, "record_time": 1742555196.133326, "EXCHANGE": "BYBIT"}
{"topic": "orderbook.200.BTCUSDT", "ts": 1742555196519, "type": "delta", "data": {"s": "BTCUSDT", "b": [["84063.1", "0.185846"], ["84056.5", "0.032714"], ["84056.4", "0.004064"], ["84037.9", "0"], ["84027.9", "0.001466"], ["84000.5", "0"], ["83989.2", "14.547036"], ["83982.4", "0.19739"]], "a": [["84063.2", "0.605101"]], "u": 19946, "seq": 67549929552}, "cts": 1742555196502, "record_time": 1742555196.532739, "EXCHANGE": "BYBIT"}
{"topic": "orderbook.200.BTCUSDT", "ts": 1742555196719, "type": "delta", "data": {"s": "BTCUSDT", "b": [["84063.1", "0.179163"], ["84056.5", "0.0045"], ["84040.7", "0"], ["84028.5", "0"], ["84025.1", "0"], ["84024.9", "0.013214"], ["84016.4", "0.135569"], ["83982.3", "0.04"], ["83982.2", "0.001333"], ["83982.1", "1.12524"]], "a": [["84063.2", "0.507093"], ["84073.8", "0.024781"], ["84085.8", "0.242173"], ["84101.8", "0"], ["84101.9", "0.001466"], ["84102.3", "0.013"], ["84102.4", "0.366199"], ["84102.7", "0"], ["84102.8", "0"], ["84103.2", "0.099463"], ["84103.3", "0.04"]], "u": 19947, "seq": 67549929582}, "cts": 1742555196702, "record_time": 1742555196.735367, "EXCHANGE": "BYBIT"}
{"topic": "orderbook.200.BTCUSDT", "ts": 1742555196920, "type": "delta", "data": {"s": "BTCUSDT", "b": [["84063.1", "0.349963"], ["84056.5", "0.034496"], ["84028.5", "0.118804"], ["84025", "0.025278"], ["84024.9", "0.000333"], ["84024.8", "0.012981"], ["84024.7", "0.012881"], ["84000.5", "14.769424"], ["83989.2", "0"], ["83982.2", "0"], ["83982.1", "0"]], "a": [["84063.2", "0.506293"], ["84070.3", "0"], ["84076.3", "0.156561"], ["84078.7", "0"], ["84081.3", "0"], ["84102.1", "0"], ["84105.7", "0.002659"], ["84105.8", "0"], ["84107.8", "2.257062"], ["84132.8", "0.059399"], ["84133.1", "0.003211"], ["84133.4", "1.123217"], ["84133.5", "0.001851"]], "u": 19948, "seq": 67549929680}, "cts": 1742555196913, "record_time": 1742555196.933159, "EXCHANGE": "BYBIT"}
{"topic": "orderbook.200.BTCUSDT", "ts": 1742555197120, "type": "delta", "data": {"s": "BTCUSDT", "b": [], "a": [["84081.3", "0.035695"], ["84101.1", "0.303576"], ["84133.5", "0"]], "u": 19949, "seq": 67549929719}, "cts": 1742555197084, "record_time": 1742555197.138515, "EXCHANGE": "BYBIT"}
{"topic": "orderbook.200.BTCUSDT", "ts": 1742555197320, "type": "delta", "data": {"s": "BTCUSDT", "b": [["84063.1", "0.354266"], ["84006.2", "14.769424"], ["84000.5", "0"]], "a": [["84081.6", "0.118804"], ["84133.4", "0"]], "u": 19950, "seq": 67549929752}, "cts": 1742555197317, "record_time": 1742555197.390052, "EXCHANGE": "BYBIT"}
{"topic": "orderbook.200.BTCUSDT", "ts": 1742555197520, "type": "delta", "data": {"s": "BTCUSDT", "b": [], "a": [["84063.4", "0.015612"], ["84065", "0.015164"], ["84080.6", "0.119505"], ["84132.8", "0"], ["84133.1", "0"]], "u": 19951, "seq": 67549929786}, "cts": 1742555197512, "record_time": 1742555197.586318, "EXCHANGE": "BYBIT"}
{"topic": "orderbook.200.BTCUSDT", "ts": 1742555197719, "type": "delta", "data": {"s": "BTCUSDT", "b": [["84025.1", "0.013"], ["84025", "0.038159"], ["84024.8", "0.0001"], ["84024.7", "0"], ["84006.2", "0"], ["84000.5", "14.935374"]], "a": [["84101.6", "0.012851"], ["84101.7", "0.10195"], ["84102.3", "0"], ["84102.4", "0.35335"], ["84102.5", "0.04"], ["84102.6", "0.04"], ["84103.2", "0.059463"], ["84103.3", "0"], ["84104.9", "2.257062"], ["84107.8", "0"], ["84132.1", "0"]], "u": 19952, "seq": 67549929817}, "cts": 1742555197709, "record_time": 1742555197.733747, "EXCHANGE": "BYBIT"}
{"topic": "orderbook.200.BTCUSDT", "ts": 1742555197920, "type": "delta", "data": {"s": "BTCUSDT", "b": [["84028.6", "0.161846"], ["84003.3", "14.935374"], ["84000.5", "0"], ["83982.3", "0"]], "a": [["84073.4", "0.000516"], ["84101.1", "0.942767"]], "u": 19953, "seq": 67549929850}, "cts": 1742555197913, "record_time": 1742555197.933094, "EXCHANGE": "BYBIT"}
{"topic": "orderbook.200.BTCUSDT", "ts": 1742555198119, "type": "delta", "data": {"s": "BTCUSDT", "b": [["84063.1", "0.355066"], ["84025.2", "0.013"], ["84025.1", "0.012881"], ["84025", "0.025278"], ["83982.4", "0"]], "a": [["84063.2", "0.512293"], ["84073.5", "0.063726"], ["84101.3", "0.022"], ["84101.4", "0.012852"], ["84101.6", "0"], ["84101.7", "0.089099"], ["84102.2", "0.04"], ["84102.3", "0.04"], ["84102.5", "0"], ["84102.6", "0"]], "u": 19954, "seq": 67549929889}, "cts": 1742555198116, "record_time": 1742555198.132975, "EXCHANGE": "BYBIT"}
{"topic": "orderbook.200.BTCUSDT", "ts": 1742555198320, "type": "delta", "data": {"s": "BTCUSDT", "b": [["84063.1", "0.356895"], ["84025.2", "0"], ["84025", "0.038159"], ["83982.4", "0.19739"]], "a": [["84101.3", "0.009"], ["84101.4", "0"], ["84101.6", "0.012852"], ["84101.7", "0.101951"], ["84102.2", "0"], ["84102.3", "0"], ["84102.5", "0.04"], ["84102.6", "0.04"]], "u": 19955, "seq": 67549929931}, "cts": 1742555198313, "record_time": 1742555198.449976, "EXCHANGE": "BYBIT"}
{"topic": "orderbook.200.BTCUSDT", "ts": 1742555198520, "type": "delta", "data": {"s": "BTCUSDT", "b": [["84043", "0.014372"]], "a": [], "u": 19956, "seq": 67549929969}, "cts": 1742555198511, "record_time": 1742555198.542889, "EXCHANGE": "BYBIT"}
{"topic": "orderbook.200.BTCUSDT", "ts": 1742555198719, "type": "delta", "data": {"s": "BTCUSDT", "b": [["84063.1", "0.356152"], ["84051.1", "0.003"], ["84043.1", "0.004693"], ["84043", "0.009969"], ["84003.3", "14.772864"], ["83984.8", "0.029744"], ["83982.9", "0"], ["83982.4", "0"]], "a": [], "u": 19957, "seq": 67549930018}, "cts": 1742555198715, "record_time": 1742555198.737665, "EXCHANGE": "BYBIT"}
{"topic": "orderbook.200.BTCUSDT", "ts": 1742555198920, "type": "delta", "data": {"s": "BTCUSDT", "b": [], "a": [["84087.5", "0"], ["84132.1", "0.059449"]], "u": 19958, "seq": 67549930036}, "cts": 1742555198889, "record_time": 1742555198.966873, "EXCHANGE": "BYBIT"}
{"topic": "orderbook.200.BTCUSDT", "ts": 1742555199120, "type": "delta", "data": {"s": "BTCUSDT", "b": [["84063.1", "0.348356"], ["84028.5", "0"], ["83982.9", "0.000333"]], "a": [["84063.2", "0.513553"], ["84101.6", "0"], ["84101.7", "0.089099"], ["84101.8", "0.012852"], ["84101.9", "0.014318"], ["84102.5", "0"], ["84102.6", "0"], ["84102.7", "0.04"], ["84102.8", "0.04"]], "u": 19959, "seq": 67549930084}, "cts": 1742555199116, "record_time": 1742555199.153081, "EXCHANGE": "BYBIT"}
{"topic": "orderbook.200.BTCUSDT", "ts": 1742555199320, "type": "delta", "data": {"s": "BTCUSDT", "b": [["84028.7", "0.118804"], ["84023.6", "0.118804"], ["83983.3", "0"], ["83982.9", "0"]], "a": [["84063.2", "0.519553"]], "u": 19960, "seq": 67549930101}, "cts": 1742555199308, "record_time": 1742555199.333859, "EXCHANGE": "BYBIT"}
{"topic": "orderbook.200.BTCUSDT", "ts": 1742555199520, "type": "delta", "data": {"s": "BTCUSDT", "b": [["84063.1", "0.348486"], ["84025", "0.068584"]], "a": [["84063.2", "0.519443"], ["84083.1", "0.0006"], ["84132.1", "0"]], "u": 19961, "seq": 67549930116}, "cts": 1742555199508, "record_time": 1742555199.534651, "EXCHANGE": "BYBIT"}
{"topic": "orderbook.200.BTCUSDT", "ts": 1742555199720, "type": "delta", "data": {"s": "BTCUSDT", "b": [["84003.3", "0"], ["83997.7", "14.612853"]], "a": [["84063.2", "0.533584"], ["84104.9", "0"], ["84105.7", "0.000518"], ["84107.8", "2.257062"]], "u": 19962, "seq": 67549930148}, "cts": 1742555199711, "record_time": 1742555199.738437, "EXCHANGE": "BYBIT"}
{"topic": "orderbook.200.BTCUSDT", "ts": 1742555199920, "type": "delta", "data": {"s": "BTCUSDT", "b": [["84063.1", "0.177486"], ["84028.7", "0"], ["84003.3", "14.612853"], ["83997.7", "0"], ["83983.3", "0.62453"]], "a": [["84071.7", "0.089099"], ["84076.2", "0.118804"], ["84101.1", "0.303576"], ["84105", "1.05661"], ["84131.3", "0"], ["84132", "0"]], "u": 19963, "seq": 67549930203}, "cts": 1742555199910, "record_time": 1742555200.015022, "EXCHANGE": "BYBIT"}
{"topic": "orderbook.200.BTCUSDT", "ts": 1742555200120, "type": "delta", "data": {"s": "BTCUSDT", "b": [["84063.1", "0.173827"], ["84025.1", "0"], ["84025", "0.055703"], ["84024.9", "0.013214"], ["84024.8", "0.012981"], ["84022.7", "0.178437"], ["84014.3", "0.124906"], ["83994.5", "0"]], "a": [["84063.4", "0.04039"], ["84063.6", "0.089099"], ["84101.8", "0"], ["84101.9", "0.001466"], ["84102.1", "2.257062"], ["84102.3", "0.012852"], ["84102.4", "0.36635"], ["84102.7", "0"], ["84102.8", "0"], ["84103.2", "0.099463"], ["84103.4", "0.04"], ["84107.8", "0"]], "u": 19964, "seq": 67549930292}, "cts": 1742555200115, "record_time": 1742555200.206893, "EXCHANGE": "BYBIT"}
{"topic": "orderbook.200.BTCUSDT", "ts": 1742555200320, "type": "delta", "data": {"s": "BTCUSDT", "b": [["84019.1", "0.052"], ["83984.8", "0.029857"], ["83983.3", "0"]], "a": [["84102.3", "0"], ["84102.4", "0.366202"], ["84102.5", "0.012852"], ["84103.2", "0.059463"], ["84103.3", "0.04"], ["84105", "0.453419"], ["84131.2", "0"]], "u": 19965, "seq": 67549930372}, "cts": 1742555200316, "record_time": 1742555200.333414, "EXCHANGE": "BYBIT"}
{"topic": "orderbook.200.BTCUSDT", "ts": 1742555200519, "type": "delta", "data": {"s": "BTCUSDT", "b": [["84024.9", "0.000333"], ["84024.7", "0.012881"], ["83984.2", "0"]], "a": [["84063.4", "0.015612"], ["84063.6", "0"], ["84102.4", "0.35335"], ["84102.6", "0.012852"], ["84103.3", "0"], ["84103.5", "0.04"]], "u": 19966, "seq": 67549930425}, "cts": 1742555200503, "record_time": 1742555200.542846, "EXCHANGE": "BYBIT"}
{"topic": "orderbook.200.BTCUSDT", "ts": 1742555200720, "type": "delta", "data": {"s": "BTCUSDT", "b": [["84028.7", "0.118804"], ["84003.3", "14.453939"], ["83984.4", "0"]], "a": [["84063.2", "0.531443"], ["84102.1", "0"], ["84104.9", "2.257062"], ["84105.5", "0.002141"], ["84131.1", "0"]], "u": 19967, "seq": 67549930464}, "cts": 1742555200704, "record_time": 1742555200.736162, "EXCHANGE": "BYBIT"}
{"topic": "orderbook.200.BTCUSDT", "ts": 1742555200920, "type": "delta", "data": {"s": "BTCUSDT", "b": [["84043.1", "0.000868"]], "a": [["84130.2", "0.171"], ["84131", "0"]], "u": 19968, "seq": 67549930507}, "cts": 1742555200914, "record_time": 1742555200.948177, "EXCHANGE": "BYBIT"}
{"topic": "orderbook.200.BTCUSDT", "ts": 1742555201119, "type": "delta", "data": {"s": "BTCUSDT", "b": [["84063.1", "0.174643"], ["84048.8", "0"], ["84043.1", "0"], ["84025", "0.113159"], ["84022.7", "0"], ["84014.3", "0"], ["84003.3", "0"], ["83994.8", "14.455878"], ["83984.8", "0"], ["83984.4", "0.059399"], ["83984.2", "0.04"], ["83983.3", "0.62453"], ["83982.9", "0.000333"], ["83982.4", "0.19739"], ["83982.3", "0.04"]], "a": [["84063.2", "0.533643"], ["84068.7", "0.093068"], ["84069.4", "0"], ["84083.1", "0.0012"], ["84101.1", "0.942767"], ["84103.3", "0.04"], ["84103.5", "0"], ["84105.5", "0"], ["84131", "0.001459"], ["84131.2", "0.059449"]], "u": 19969, "seq": 67549930613}, "cts": 1742555201113, "record_time": 1742555201.133014, "EXCHANGE": "BYBIT"}
{"topic": "orderbook.200.BTCUSDT", "ts": 1742555201320, "type": "delta", "data": {"s": "BTCUSDT", "b": [["84063.1", "0.176401"], ["84043", "0.011127"], ["84025", "0.000199"], ["84024.9", "0.013333"], ["84024.7", "0"], ["84022.7", "0.178437"], ["83997.7", "14.453939"], ["83994.8", "0.001939"], ["83984.6", "0.201818"], ["83982.3", "0"]], "a": [["84101.8", "0.013"], ["84101.9", "0.014318"], ["84102.5", "0"], ["84102.6", "0"], ["84102.7", "0.04"], ["84102.8", "0.04"], ["84103.3", "0"], ["84103.4", "0"], ["84131.3", "0.009"]], "u": 19970, "seq": 67549930656}, "cts": 1742555201297, "record_time": 1742555201.333098, "EXCHANGE": "BYBIT"}
{"topic": "orderbook.200.BTCUSDT", "ts": 1742555201519, "type": "delta", "data": {"s": "BTCUSDT", "b": [["84043", "0.010269"], ["84003.3", "14.453939"], ["83997.7", "0"], ["83984.6", "0.171"], ["83983.1", "0.038638"], ["83982.4", "0"]], "a": [], "u": 19971, "seq": 67549930680}, "cts": 1742555201517, "record_time": 1742555201.58659, "EXCHANGE": "BYBIT"}
{"topic": "orderbook.200.BTCUSDT", "ts": 1742555201720, "type": "delta", "data": {"s": "BTCUSDT", "b": [["84063.1", "0.180903"], ["84048.2", "0.005789"], ["84025.1", "0.013"], ["84025", "0.01308"], ["84024.9", "0.000333"], ["84024.8", "0.0001"], ["84014.3", "0.124906"], ["84003.3", "14.300576"], ["83983.3", "0"], ["83983.1", "0"], ["83982.9", "0"]], "a": [["84101.4", "0.013"], ["84101.5", "0.012852"], ["84101.8", "0"], ["84101.9", "0.001466"], ["84102.1", "2.257062"], ["84102.3", "0.04"], ["84102.4", "0.39335"], ["84102.7", "0"], ["84102.8", "0"], ["84104.9", "0"]], "u": 19972, "seq": 67549930748}, "cts": 1742555201716, "record_time": 1742555201.77588, "EXCHANGE": "BYBIT"}
{"topic": "orderbook.200.BTCUSDT", "ts": 1742555201920, "type": "delta", "data": {"s": "BTCUSDT", "b": [], "a": [["84063.2", "0.534443"], ["84071.7", "0"], ["84101.5", "0.012849"], ["84132", "0.0018"]], "u": 19973, "seq": 67549930789}, "cts": 1742555201904, "record_time": 1742555201.933445, "EXCHANGE": "BYBIT"}
{"topic": "orderbook.200.BTCUSDT", "ts": 1742555202119, "type": "delta", "data": {"s": "BTCUSDT", "b": [["84063.1", "0.181263"], ["84023.7", "0.110686"], ["83984.2", "0"]], "a": [["84063.2", "0.540087"]], "u": 19974, "seq": 67549930828}, "cts": 1742555202112, "record_time": 1742555202.132651, "EXCHANGE": "BYBIT"}
{"topic": "orderbook.200.BTCUSDT", "ts": 1742555202320, "type": "delta", "data": {"s": "BTCUSDT", "b": [["84063.1", "0.182763"]], "a": [["84063.2", "0.539388"], ["84072.6", "0.164504"], ["84075.1", "0.178412"], ["84132", "0"]], "u": 19975, "seq": 67549930872}, "cts": 1742555202317, "record_time": 1742555202.335531, "EXCHANGE": "BYBIT"}
{"topic": "orderbook.200.BTCUSDT", "ts": 1742555202719, "type": "delta", "data": {"s": "BTCUSDT", "b": [["84063.1", "0.353763"], ["84043.9", "0.062013"], ["84036.9", "0.059297"], ["84029.9", "0.114051"], ["84003.3", "14.135902"], ["83985.1", "0"], ["83984.6", "0"], ["83984.4", "0"]], "a": [["84078.9", "0.137195"], ["84082.1", "0.003464"], ["84085.9", "0.059284"], ["84092.9", "0.111708"], ["84131", "0"], ["84131.2", "0"], ["84131.3", "0"]], "u": 19976, "seq": 67549930927}, "cts": 1742555202717, "record_time": 1742555202.732971, "EXCHANGE": "BYBIT"}
{"topic": "orderbook.200.BTCUSDT", "ts": 1742555202919, "type": "delta", "data": {"s": "BTCUSDT", "b": [["84063.1", "0.182763"], ["84025.2", "0.013"], ["84025.1", "0.012881"], ["84025", "0.000199"], ["83985.2", "0"]], "a": [["84101.1", "0.955767"], ["84101.2", "0.20764"], ["84101.4", "0"], ["84101.5", "0"], ["84102", "0.04"], ["84102.1", "2.297062"], ["84102.3", "0"], ["84102.4", "0.35335"], ["84131", "0.001459"], ["84131.2", "0.059449"]], "u": 19977, "seq": 67549930954}, "cts": 1742555202916, "record_time": 1742555202.932319, "EXCHANGE": "BYBIT"}
{"topic": "orderbook.200.BTCUSDT", "ts": 1742555203120, "type": "delta", "data": {"s": "BTCUSDT", "b": [["84063.1", "0.178261"], ["84043.9", "0"], ["84036.9", "0"], ["84029.9", "0"], ["84028.7", "0"], ["84016.5", "0.091868"], ["83985.2", "0.044"], ["83985.1", "0.353365"], ["83984.4", "0.059399"], ["83984.2", "0.04"]], "a": [["84078.9", "0.075787"], ["84085.9", "0"], ["84092.9", "0"], ["84102", "0"], ["84102.2", "0.04"], ["84131.3", "0.009"], ["84132", "0.0018"]], "u": 19978, "seq": 67549931011}, "cts": 1742555203116, "record_time": 1742555203.156899, "EXCHANGE": "BYBIT"}
{"topic": "orderbook.200.BTCUSDT", "ts": 1742555203320, "type": "delta", "data": {"s": "BTCUSDT", "b": [["84025.2", "0"], ["84025", "0.01308"], ["83984.6", "0.171"]], "a": [["84101.1", "0.942767"], ["84101.3", "0.021849"]], "u": 19979, "seq": 67549931029}, "cts": 1742555203316, "record_time": 1742555203.349143, "EXCHANGE": "BYBIT"}
{"topic": "orderbook.200.BTCUSDT", "ts": 1742555203520, "type": "delta", "data": {"s": "BTCUSDT", "b": [["84063.1", "0.007381"], ["84048.2", "0"], ["84025.2", "0.013"], ["84025", "0.000199"]], "a": [["84063.2", "0.71027"], ["84101.1", "0.955767"], ["84101.3", "0.009"]], "u": 19980, "seq": 67549931089}, "cts": 1742555203517, "record_time": 1742555203.537114, "EXCHANGE": "BYBIT"}
{"topic": "orderbook.200.BTCUSDT", "ts": 1742555203720, "type": "delta", "data": {"s": "BTCUSDT", "b": [["84063.1", "0.011308"], ["84056.5", "0.0045"], ["84003.3", "0"], ["83997.7", "13.814723"]], "a": [["84063.2", "0.708129"], ["84072.1", "0.133099"], ["84080.6", "0.128027"], ["84085.6", "0.001305"], ["84105.5", "0.002141"], ["84131.3", "0"], ["84132", "0"]], "u": 19981, "seq": 67549931142}, "cts": 1742555203715, "record_time": 1742555203.732649, "EXCHANGE": "BYBIT"}
{"topic": "orderbook.200.BTCUSDT", "ts": 1742555203919, "type": "delta", "data": {"s": "BTCUSDT", "b": [["84023.1", "0.178437"], ["84018.9", "0.178437"], ["84000.5", "13.814723"], ["83997.7", "0"], ["83984.4", "0"], ["83984.2", "0"]], "a": [["84063.2", "0.712054"], ["84085.6", "0"], ["84102", "0.04"], ["84102.2", "0"], ["84105.5", "0"], ["84131.3", "0.009"], ["84132", "0.0018"]], "u": 19982, "seq": 67549931158}, "cts": 1742555203908, "record_time": 1742555203.932482, "EXCHANGE": "BYBIT"}
{"topic": "orderbook.200.BTCUSDT", "ts": 1742555204120, "type": "delta", "data": {"s": "BTCUSDT", "b": [["84063.1", "0.011864"], ["84025.2", "0"], ["84025", "0.01308"], ["83984.4", "0.059399"]], "a": [["84063.2", "0.53927"], ["84081.7", "0.000954"], ["84101.1", "0.942767"], ["84101.2", "0.194791"], ["84101.4", "0.013"], ["84101.5", "0.012849"], ["84102", "0"], ["84102.1", "2.257062"], ["84102.3", "0.04"], ["84102.4", "0.39335"], ["84131.2", "0"], ["84131.3", "0"], ["84132", "0"]], "u": 19983, "seq": 67549931181}, "cts": 1742555204089, "record_time": 1742555204.207745, "EXCHANGE": "BYBIT"}
{"topic": "orderbook.200.BTCUSDT", "ts": 1742555204320, "type": "delta", "data": {"s": "BTCUSDT", "b": [], "a": [["84081.7", "0"], ["84131.2", "0.059449"]], "u": 19984, "seq": 67549931192}, "cts": 1742555204282, "record_time": 1742555204.396602, "EXCHANGE": "BYBIT"}
{"topic": "orderbook.200.BTCUSDT", "ts": 1742555204519, "type": "delta", "data": {"s": "BTCUSDT", "b": [["84043.1", "0.0003"], ["84043", "0.009969"], ["83984.4", "0"]], "a": [["84063.2", "0.539246"], ["84069.8", "0"], ["84102", "0.04"], ["84102.1", "2.297062"], ["84102.3", "0"], ["84102.4", "0.35335"], ["84131.3", "0.009"]], "u": 19985, "seq": 67549931209}, "cts": 1742555204512, "record_time": 1742555204.535881, "EXCHANGE": "BYBIT"}
{"topic": "orderbook.200.BTCUSDT", "ts": 1742555204720, "type": "delta", "data": {"s": "BTCUSDT", "b": [["84051.1", "0"], ["83984.4", "0.059399"]], "a": [["84063.2", "0.710246"], ["84068.7", "0.085727"], ["84070.7", "0.112792"], ["84101.1", "0.955616"], ["84101.2", "0.20764"], ["84101.4", "0"], ["84101.5", "0"], ["84132", "0.0018"]], "u": 19986, "seq": 67549931227}, "cts": 1742555204641, "record_time": 1742555204.744269, "EXCHANGE": "BYBIT"}
{"topic": "orderbook.200.BTCUSDT", "ts": 1742555204920, "type": "delta", "data": {"s": "BTCUSDT", "b": [], "a": [["84063.2", "0.842185"], ["84101.1", "0.942767"], ["84101.2", "0.194791"], ["84101.4", "0.013"], ["84101.5", "0.012849"], ["84102", "0"], ["84102.1", "2.257062"], ["84102.3", "0.04"], ["84102.4", "0.39335"], ["84105.8", "0.002141"], ["84131.2", "0"], ["84131.3", "0"], ["84132", "0"]], "u": 19987, "seq": 67549931248}, "cts": 1742555204904, "record_time": 1742555204.945923, "EXCHANGE": "BYBIT"}
{"topic": "orderbook.200.BTCUSDT", "ts": 1742555205120, "type": "delta", "data": {"s": "BTCUSDT", "b": [["84063.1", "0.019549"], ["84056.5", "0.034496"], ["84050.2", "0.102172"], ["84046.7", "0.121305"], ["84036.2", "0.172155"], ["84029.2", "0.309216"], ["84025.1", "0"], ["84024.9", "0.013214"], ["83984.6", "0"], ["83984.4", "0"]], "a": [["84063.2", "0.544889"], ["84068.7", "0.119238"], ["84071.2", "0.122744"], ["84080.6", "0.170363"], ["84081.7", "0.187623"], ["84088.7", "0.279285"], ["84130.2", "0"], ["84130.9", "0"], ["84131", "0"]], "u": 19988, "seq": 67549931277}, "cts": 1742555205102, "record_time": 1742555205.138592, "EXCHANGE": "BYBIT"}
{"topic": "orderbook.200.BTCUSDT", "ts": 1742555205319, "type": "delta", "data": {"s": "BTCUSDT", "b": [["84063.1", "0"], ["84062.7", "0.003306"], ["84050.2", "0.099872"], ["84046.7", "0"], ["84046.4", "0.115102"], ["84043.1", "0"], ["84036.3", "0.16257"], ["84036.2", "0"], ["84035.9", "0.172488"], ["84035.7", "0"], ["84029.2", "0"], ["84028.9", "0.29317"], ["83984.4", "0.059399"], ["83984.2", "0.04"], ["83983.3", "0.62453"]], "a": [["84062.8", "0.971408"], ["84063.1", "0.06401"], ["84063.2", "0.161329"], ["84063.4", "0"], ["84067.8", "0.0025"], ["84068.2", "0"], ["84070.9", "0.110331"], ["84071.2", "0"], ["84080.6", "0.128027"], ["84081.4", "0.173741"], ["84081.7", "0"], ["84083.1", "0.0018"], ["84088.4", "0.27385"], ["84088.6", "0.176894"], ["84088.7", "0"], ["84090.4", "0"], ["84101.8", "0.04"], ["84101.9", "0.041466"], ["84102.3", "0"], ["84102.4", "0.35335"], ["84104.7", "1.426311"], ["84105.1", "0.005942"], ["84130", "0"]], "u": 19989, "seq": 67549931470}, "cts": 1742555205316, "record_time": 1742555205.359499, "EXCHANGE": "BYBIT"}
{"topic": "orderbook.200.BTCUSDT", "ts": 1742555205520, "type": "delta", "data": {"s": "BTCUSDT", "b": [["84062.7", "0.176064"], ["84050.2", "0.066906"], ["84046.4", "0.001466"], ["84043.2", "0.0003"], ["84035.9", "0"], ["84031.7", "0.027719"], ["84031.2", "0"], ["84028.9", "0"], ["83984.6", "0.171"], ["83983", "0.038687"]], "a": [["84062.8", "1.099409"], ["84063.2", "0.151328"], ["84070.9", "0"], ["84081.4", "0"], ["84088.4", "0"], ["84088.6", "0"], ["84100.9", "0.013"], ["84101", "0.072779"], ["84101.4", "0"], ["84101.5", "0"], ["84105", "0"], ["84130", "0.000333"], ["84130.9", "0.148527"], ["84131", "0.001459"], ["84131.2", "0.059449"], ["84131.3", "0.009"], ["84132", "0.0018"]], "u": 19990, "seq": 67549931505}, "cts": 1742555205511, "record_time": 1742555205.534832, "EXCHANGE": "BYBIT"}
{"topic": "orderbook.200.BTCUSDT", "ts": 1742555205720, "type": "delta", "data": {"s": "BTCUSDT", "b": [["84062.7", "0.18051"], ["84050.2", "0.101035"], ["84048.4", "0.18131"], ["84038.6", "0.186413"], ["84036.3", "0.110923"], ["84029.5", "0.303951"], ["83983.3", "0"], ["83983", "0"]], "a": [["84062.8", "1.105409"], ["84072", "0.29293"], ["84072.6", "0"], ["84073.6", "0.115734"], ["84083.4", "0.272191"], ["84092.5", "0.290201"], ["84100.9", "0.012849"], ["84130.2", "0.171"], ["84131.3", "0"], ["84132", "0"]], "u": 19991, "seq": 67549931537}, "cts": 1742555205675, "record_time": 1742555205.778129, "EXCHANGE": "BYBIT"}
{"topic": "orderbook.200.BTCUSDT", "ts": 1742555205920, "type": "delta", "data": {"s": "BTCUSDT", "b": [["84062.7", "0.178842"], ["84050.2", "0.066906"], ["84048.4", "0.063796"], ["84038.7", "0.057707"], ["84038.6", "0"], ["84029.5", "0"], ["84025.1", "0.013"], ["84024.9", "0.000333"], ["83986", "0.356579"], ["83985.1", "0"], ["83983.3", "0.62453"]], "a": [["84066.9", "0.000333"], ["84073.6", "0"], ["84083.4", "0.090685"], ["84092.5", "0"], ["84100.8", "0.013"], ["84101", "0.05993"], ["84101.7", "0.129099"], ["84101.9", "0.001466"]], "u": 19992, "seq": 67549931573}, "cts": 1742555205914, "record_time": 1742555205.967297, "EXCHANGE": "BYBIT"}
{"topic": "orderbook.200.BTCUSDT", "ts": 1742555206120, "type": "delta", "data": {"s": "BTCUSDT", "b": [["84062.7", "0.184826"], ["84038.7", "0"], ["83982.9", "0.000333"]], "a": [["84062.8", "1.111409"], ["84063.2", "0.149544"]], "u": 19993, "seq": 67549931584}, "cts": 1742555206096, "record_time": 1742555206.133793, "EXCHANGE": "BYBIT"}
{"topic": "orderbook.200.BTCUSDT", "ts": 1742555206319, "type": "delta", "data": {"s": "BTCUSDT", "b": [["84062.7", "0"], ["84062", "0"], ["84056.5", "0.0045"], ["84056.4", "0"], ["84055.1", "0"], ["84053.6", "0.083052"], ["84053.5", "0"], ["84051.8", "0"], ["84050.2", "0.02488"], ["84050.1", "0.000333"], ["84050", "0.00086"], ["84048.5", "0"], ["84048.4", "0.023796"], ["84045.2", "0.041423"], ["84043.2", "0"], ["84025.1", "0"], ["84024.9", "0.013214"], ["84023.1", "0"], ["84022.7", "0"], ["84021.9", "0"], ["84017.4", "0"], ["84016.4", "0.0001"], ["84010.7", "0.135504"], ["84008", "0.023791"], ["84003.5", "0.005947"], ["84000.5", "0"], ["83989.2", "13.169116"], ["83982.4", "0.19739"], ["83982.3", "0.04"], ["83982.2", "0.001333"], ["83982.1", "1.12524"], ["83981.8", "0.0032"], ["83981.7", "0.001466"], ["83981.3", "0.020845"], ["83980.9", "0.000516"], ["83980", "0.132291"], ["83978.7", "0.000333"]], "a": [["84061.8", "0.860381"], ["84062.1", "0.964974"], ["84062.8", "0.311144"], ["84063.1", "0"], ["84067.1", "0.0025"], ["84067.8", "0"], ["84071.1", "0.178753"], ["84072", "0.228371"], ["84072.3", "0.07895"], ["84075.1", "0"], ["84090.4", "0.080111"], ["84100.7", "0.013"], ["84100.8", "0.012849"], ["84100.9", "0"], ["84101.6", "0.04"], ["84101.8", "0"], ["84104", "1.427311"], ["84104.7", "0.000333"], ["84105.8", "0"], ["84129.7", "0.090565"], ["84131.2", "0"]], "u": 19994, "seq": 67549932023}, "cts": 1742555206317, "record_time": 1742555206.338634, "EXCHANGE": "BYBIT"}
{"topic": "orderbook.200.BTCUSDT", "ts": 1742555206519, "type": "delta", "data": {"s": "BTCUSDT", "b": [["84061.7", "0"], ["84060.3", "0"], ["84060", "0"], ["84059.5", "0"], ["84058.5", "0"], ["84057.8", "0"], ["84057.6", "0"], ["84057.5", "0"], ["84056.5", "0"], ["84055.7", "0"], ["84055", "0.017844"], ["84053.4", "0"], ["84050.2", "0.037454"], ["84048.6", "0.048"], ["84048.5", "0.04"], ["84046.8", "0.052"], ["84046.6", "0.004066"], ["84046.2", "0.005909"], ["84046.1", "0.085741"], ["84043.4", "0.04"], ["84043.3", "0.044"], ["84042.7", "0.0003"], ["84041.9", "0.018549"], ["84041.8", "0.041466"], ["84034.6", "0.039941"], ["84031.7", "0.02296"], ["84025", "0.000199"], ["84024.9", "0.000333"], ["84023.7", "0.050018"], ["84023.3", "0.014466"], ["84023.2", "0.01288"], ["84016.5", "0.062114"], ["84014.7", "0.178453"], ["84000", "3.638938"], ["83983.3", "0"], ["83982.5", "0.011992"], ["83978.7", "0"]], "a": [["84055.1", "0.282273"], ["84055.8", "0.461448"], ["84056.6", "0.69762"], ["84057.6", "0.107067"], ["84057.9", "0.097103"], ["84058.6", "0.010002"], ["84058.9", "0.035689"], ["84059.5", "0.211569"], ["84059.6", "0.181004"], ["84060.4", "0.171"], ["84060.8", "0.0025"], ["84061.8", "0.172784"], ["84062", "0.001333"], ["84062.1", "0.176276"], ["84062.7", "0.000333"], ["84062.8", "0.002141"], ["84063.2", "0.0068"], ["84063.5", "0"], ["84064.1", "0.000516"], ["84064.9", "0.001466"], ["84065.9", "0.003223"], ["84066.2", "0.001333"], ["84067", "0.00009"], ["84067.1", "0"], ["84070.5", "0.00596"], ["84072", "0.17484"], ["84072.8", "0"], ["84073.8", "0"], ["84082.6", "0.039368"], ["84098.1", "1.425978"], ["84100.7", "0"], ["84100.9", "0.012849"], ["84101.6", "0"], ["84101.8", "0.04"], ["84102.1", "0"], ["84104", "0.001333"], ["84104.9", "2.257073"], ["84125.8", "0"], ["84126.6", "0"], ["84127.8", "0"], ["84127.9", "0"], ["84128.1", "0"], ["84128.2", "0"], ["84128.8", "0"], ["84128.9", "0"], ["84129.3", "0"], ["84129.6", "0"], ["84129.7", "0"], ["84130", "0"], ["84130.2", "0"], ["84130.9", "0"], ["84131", "0"]], "u": 19995, "seq": 67549933097}, "cts": 1742555206517, "record_time": 1742555206.535234, "EXCHANGE": "BYBIT"}
{"topic": "orderbook.200.BTCUSDT", "ts": 1742555206720, "type": "delta", "data": {"s": "BTCUSDT", "b": [["84055", "0"], ["84054.9", "0"], ["84054.3", "0"], ["84053.6", "0"], ["84053.3", "0.073744"], ["84052.7", "0.057711"], ["84050.2", "0.065255"], ["84046.7", "0.04"], ["84041.7", "0.040333"], ["84036.4", "0.085023"], ["84036.3", "0.059399"], ["84036", "0"], ["84034.6", "0.089941"], ["84033.7", "0.05"], ["84023.3", "0.001466"], ["84023.2", "0"], ["84022.5", "0.013395"], ["84022.4", "0.012879"], ["84016.5", "0.104763"], ["84008.1", "0.025322"], ["84000.5", "13.007677"], ["83999.3", "0"], ["83989.2", "0"], ["83979.2", "0.011992"], ["83978.8", "0.011992"], ["83978.7", "0.000333"]], "a": [["84053.4", "0.278836"], ["84055.1", "0.005942"], ["84055.8", "0"], ["84056.6", "0.003"], ["84057.6", "0"], ["84057.8", "0.001333"], ["84057.9", "0"], ["84058.4", "0.0025"], ["84058.5", "0.000333"], ["84058.6", "0.003"], ["84058.9", "0"], ["84059.5", "0.146961"], ["84059.6", "0.171"], ["84060.3", "0.001466"], ["84060.8", "0"], ["84061.7", "0.003223"], ["84062.1", "0.010001"], ["84062.8", "0"], ["84076", "0.243925"], ["84076.3", "0"], ["84079.4", "0.0388"], ["84082.6", "0.000518"], ["84086.5", "0.063899"], ["84086.7", "0.000099"], ["84089.2", "0"], ["84095.3", "1.429214"], ["84096.7", "0.499299"], ["84098.1", "0"], ["84100.8", "0"], ["84100.9", "0"], ["84101.1", "0.955616"], ["84101.2", "0.20764"], ["84101.7", "0.089099"], ["84101.8", "0"], ["84101.9", "0.041466"], ["84102", "0.04"], ["84105", "0.002141"], ["84124.3", "0"], ["84125.8", "0.059876"], ["84126.6", "0.003983"]], "u": 19996, "seq": 67549933791}, "cts": 1742555206705, "record_time": 1742555206.735303, "EXCHANGE": "BYBIT"}
{"topic": "orderbook.200.BTCUSDT", "ts": 1742555206920, "type": "delta", "data": {"s": "BTCUSDT", "b": [["84053.3", "0.073046"], ["84046.9", "0.011345"], ["84042.7", "0.022991"], ["84036.3", "0"], ["84034.6", "0.039941"], ["84034.5", "0.05"], ["84029.4", "0.035696"], ["84028.2", "0"], ["84022.6", "0.013"], ["84022.4", "0"], ["83978.7", "0"]], "a": [["84053.4", "0.285636"], ["84055.8", "0.010001"], ["84059.5", "0.150096"], ["84059.8", "0.012476"], ["84062.1", "0"], ["84063.2", "0.006"], ["84071", "0.118804"], ["84086.7", "0"], ["84092.4", "0.585057"], ["84096.6", "0.20485"], ["84096.7", "0"], ["84101.1", "0.955767"], ["84101.9", "0.001466"], ["84102.1", "0.04"], ["84104.9", "2.25728"], ["84125.8", "0"], ["84126.6", "0"]], "u": 19997, "seq": 67549933857}, "cts": 1742555206900, "record_time": 1742555206.934374, "EXCHANGE": "BYBIT"}
{"topic": "orderbook.200.BTCUSDT", "ts": 1742555207120, "type": "delta", "data": {"s": "BTCUSDT", "b": [["84028.6", "0.114205"]], "a": [["84053.4", "0.295637"], ["84055.8", "0"], ["84090.4", "0.192358"], ["84095.5", "0.063444"], ["84096.6", "0.076644"], ["84098.3", "0"], ["84125.8", "0.059876"]], "u": 19998, "seq": 67549933895}, "cts": 1742555207112, "record_time": 1742555207.133146, "EXCHANGE": "BYBIT"}
{"topic": "orderbook.200.BTCUSDT", "ts": 1742555207320, "type": "delta", "data": {"s": "BTCUSDT", "b": [], "a": [["84090.4", "0.080111"]], "u": 19999, "seq": 67549933905}, "cts": 1742555207259, "record_time": 1742555207.349175, "EXCHANGE": "BYBIT"}
{"topic": "orderbook.200.BTCUSDT", "ts": 1742555207520, "type": "delta", "data": {"s": "BTCUSDT", "b": [["84053.3", "0.24583"], ["84041.9", "0.064044"], ["84041.3", "0.128379"], ["84037.3", "0.13142"], ["84037.2", "0.121377"], ["84036.4", "0.003697"], ["84034.6", "0.039204"], ["84030.8", "0.184719"], ["84030.2", "0.668693"], ["84023.8", "0.288277"], ["84023.2", "0.303782"], ["83980", "0"], ["83979.2", "0"], ["83978.8", "0"]], "a": [["84057.7", "0.005803"], ["84059.5", "0.108558"], ["84060.4", "0"], ["84061.8", "0.171"], ["84063.2", "0"], ["84063.9", "0.045546"], ["84064", "0.024953"], ["84065.8", "0.109587"], ["84068.7", "0.199222"], ["84070.1", "0.127673"], ["84070.5", "0"], ["84076.3", "0.173874"], ["84077.1", "0.234624"], ["84083.3", "0.288445"], ["84084.1", "0.290973"], ["84125", "0"], ["84125.1", "0"], ["84125.4", "0"], ["84125.8", "0"]], "u": 20000, "seq": 67549933938}, "cts": 1742555207517, "record_time": 1742555207.542305, "EXCHANGE": "BYBIT"}
{"topic": "orderbook.200.BTCUSDT", "ts": 1742555207720, "type": "delta", "data": {"s": "BTCUSDT", "b": [["84053.3", "0.083647"], ["84041.9", "0.018549"], ["84041.3", "0.009"], ["84037.3", "0.095226"], ["84037.2", "0.001466"], ["84034.6", "0"], ["84034.5", "0"], ["84034.1", "0.05"], ["84033.7", "0"], ["84033.3", "0.050333"], ["84033.2", "0.034117"], ["84030.8", "0"], ["84030.2", "0.492627"], ["84023.9", "0.2354"], ["84023.8", "0.003181"], ["84023.7", "0"], ["84023.2", "0"], ["84022.6", "0"], ["84022.4", "0.012879"], ["84014", "0.000118"], ["83993.1", "0.299582"], ["83980", "0.132291"], ["83979.2", "0.011992"]], "a": [["84063.9", "0.01448"], ["84065.8", "0"], ["84070.1", "0.003224"], ["84076.3", "0"], ["84077.1", "0.048"], ["84080.6", "0.20079"], ["84083.3", "0"], ["84084.1", "0"], ["84097", "0.000118"], ["84101.1", "0.942767"], ["84101.3", "0.021849"], ["84102", "0"], ["84102.2", "0.04"], ["84119", "0"], ["84125", "0.001466"], ["84125.1", "0.001333"], ["84125.4", "0.118804"], ["84125.8", "0.059876"]], "u": 20001, "seq": 67549933982}, "cts": 1742555207717, "record_time": 1742555207.734302, "EXCHANGE": "BYBIT"}
{"topic": "orderbook.200.BTCUSDT", "ts": 1742555207919, "type": "delta", "data": {"s": "BTCUSDT", "b": [["84053.3", "0.023525"], ["84037.3", "0.068465"], ["84023.9", "0.0587"], ["84000.5", "0"], ["83997.7", "12.929792"]], "a": [["84080.6", "0.128027"], ["84089.1", "0.003575"], ["84125.8", "0"]], "u": 20002, "seq": 67549934003}, "cts": 1742555207912, "record_time": 1742555207.932901, "EXCHANGE": "BYBIT"}
{"topic": "orderbook.200.BTCUSDT", "ts": 1742555208120, "type": "delta", "data": {"s": "BTCUSDT", "b": [["84053.3", "0.012924"], ["84022.6", "0.013"], ["84022.4", "0"], ["84000.4", "12.929792"], ["83997.7", "0"], ["83989.6", "0"], ["83981.3", "0.009"], ["83978.8", "0.011992"]], "a": [["84053.4", "0.307637"], ["84082.1", "0"], ["84100.9", "0.013"], ["84101", "0.072779"], ["84101.2", "0.194791"], ["84101.3", "0.009"], ["84101.8", "0.04"], ["84101.9", "0.041466"], ["84102.1", "2.257326"], ["84102.2", "0"], ["84104.9", "0"], ["84125.8", "0.059876"]], "u": 20003, "seq": 67549934047}, "cts": 1742555208112, "record_time": 1742555208.262506, "EXCHANGE": "BYBIT"}
{"topic": "orderbook.200.BTCUSDT", "ts": 1742555208320, "type": "delta", "data": {"s": "BTCUSDT", "b": [["84053.3", "0.060942"], ["84000.5", "12.929792"], ["84000.4", "0"]], "a": [["84053.4", "0.187627"], ["84059.5", "0.057465"], ["84061.8", "0"], ["84072", "0.140676"], ["84072.1", "0.044"], ["84102.1", "0"], ["84113.4", "2.257123"], ["84126.6", "0.003983"]], "u": 20004, "seq": 67549934078}, "cts": 1742555208300, "record_time": 1742555208.450307, "EXCHANGE": "BYBIT"}
{"topic": "orderbook.200.BTCUSDT", "ts": 1742555208519, "type": "delta", "data": {"s": "BTCUSDT", "b": [["84053.3", "0.061547"]], "a": [["84053.4", "0.187854"], ["84101.1", "0.303576"], ["84104.9", "2.257123"], ["84113.4", "0"]], "u": 20005, "seq": 67549934096}, "cts": 1742555208511, "record_time": 1742555208.588246, "EXCHANGE": "BYBIT"}
{"topic": "orderbook.200.BTCUSDT", "ts": 1742555208720, "type": "delta", "data": {"s": "BTCUSDT", "b": [["84053.3", "0.02042"], ["84041.9", "0.030549"], ["84034.2", "0.034117"], ["84033.2", "0"], ["84022.6", "0"], ["84022.4", "0.012879"]], "a": [["84058.6", "0"], ["84063.9", "0.03049"], ["84066.7", "0.059399"], ["84100.9", "0"], ["84101.1", "0.948566"], ["84101.8", "0"], ["84102", "0.04"], ["84127.8", "0.059449"]], "u": 20006, "seq": 67549934143}, "cts": 1742555208682, "record_time": 1742555208.735834, "EXCHANGE": "BYBIT"}
{"topic": "orderbook.200.BTCUSDT", "ts": 1742555208920, "type": "delta", "data": {"s": "BTCUSDT", "b": [["84053.3", "0.066972"]], "a": [["84053.4", "0.193854"]], "u": 20007, "seq": 67549934152}, "cts": 1742555208876, "record_time": 1742555208.933728, "EXCHANGE": "BYBIT"}
{"topic": "orderbook.200.BTCUSDT", "ts": 1742555209120, "type": "delta", "data": {"s": "BTCUSDT", "b": [], "a": [["84101.1", "0.948565"]], "u": 20008, "seq": 67549934163}, "cts": 1742555209112, "record_time": 1742555209.133923, "EXCHANGE": "BYBIT"}
{"topic": "orderbook.200.BTCUSDT", "ts": 1742555209319, "type": "delta", "data": {"s": "BTCUSDT", "b": [], "a": [["84102.1", "2.257123"], ["84104.9", "0"]], "u": 20009, "seq": 67549934170}, "cts": 1742555209259, "record_time": 1742555209.334665, "EXCHANGE": "BYBIT"}
{"topic": "orderbook.200.BTCUSDT", "ts": 1742555209519, "type": "delta", "data": {"s": "BTCUSDT", "b": [["84053.3", "0.04751"]], "a": [], "u": 20010, "seq": 67549934178}, "cts": 1742555209455, "record_time": 1742555209.534557, "EXCHANGE": "BYBIT"}
{"success": true, "ret_msg": "subscribe", "conn_id": "a7beb424-a566-41eb-baaf-debfaa516def", "op": "subscribe", "record_time": 1742555346.230373, "EXCHANGE": "BYBIT"}
{"topic": "orderbook.200.BTCUSDT", "ts": 1742555345319, "type": "snapshot", "data": {"s": "BTCUSDT", "b": [["84061.1", "0.216339"], ["84060", "0.00006"], ["84059.4", "0.000319"], ["84056.1", "0.0025"], ["84055.7", "0.005362"], ["84055.2", "0.0039"], ["84055", "0.000297"], ["84054.9", "0.055211"], ["84054.8", "0.171"], ["84054.7", "0.011317"], ["84054.3", "0.000333"], ["84053.6", "0.001333"], ["84053.3", "0.019358"], ["84053.2", "0.003213"], ["84052.8", "0.045826"], ["84052.7", "0.015"], ["84052.5", "0.001753"], ["84051.6", "0.023718"], ["84051.2", "0.048"], ["84051", "0.041466"], ["84050.5", "0.022636"], ["84050.3", "0.102025"], ["84050.2", "0.114851"], ["84050.1", "0.000333"], ["84050", "0.00086"], ["84049.9", "0.122034"], ["84049.5", "0.056"], ["84049.4", "0.041569"], ["84049", "0.003181"], ["84048.7", "0.005942"], ["84047.7", "0.08"], ["84047.4", "0.005943"], ["84047.2", "0.052512"], ["84046.4", "0.001466"], ["84046.1", "0.234192"], ["84046", "0.084"], ["84045.9", "0.000333"], ["84045.6", "0.000516"], ["84045.3", "0.003"], ["84045.2", "0.011059"], ["84045", "0.000594"], ["84044.8", "0.003181"], ["84044.7", "0.005959"], ["84044.4", "0.04"], ["84044.3", "0.04"], ["84044.1", "0.171"], ["84041.8", "0.001466"], ["84041.7", "0.000333"], ["84041.3", "0.009"], ["84041", "0.001849"], ["84040.6", "0.003181"], ["84040.1", "0.170042"], ["84040", "0.00006"], ["84039.8", "0.286414"], ["84039.7", "0.187489"], ["84039.1", "0.179727"], ["84038.1", "0.059399"], ["84037.9", "0.528097"], ["84037.7", "0.122482"], ["84037.6", "0.021653"], ["84037.5", "0.000333"], ["84037.4", "0.000337"], ["84037.3", "0.035695"], ["84037.2", "0.001466"], ["84036.8", "0.001423"], ["84036.4", "0.003697"], ["84035.6", "0.171629"], ["84034.8", "0.112631"], ["84034.3", "0.089099"], ["84033.4", "0.118804"], ["84033.3", "0.19568"], ["84032.7", "0.310207"], ["84032.6", "0.001333"], ["84032.5", "0.001466"], ["84032.2", "0.003181"], ["84032.1", "0.303378"], ["84031.9", "0.485906"], ["84031.8", "0.000516"], ["84031", "0.294372"], ["84030.2", "0.004768"], ["84029.1", "0.000333"], ["84028.6", "0.118217"], ["84028.4", "0.001423"], ["84028", "0.003181"], ["84027.9", "0.001466"], ["84027.6", "0.118804"], ["84027.3", "0.059399"], ["84027.1", "0.195621"], ["84026.5", "0.0061"], ["84025.9", "0.0264"], ["84025", "0.000199"], ["84024.9", "0.000333"], ["84024.8", "0.0001"], ["84024.3", "0.048729"], ["84024.2", "0.001333"], ["84023.8", "0.003181"], ["84023.6", "0.012881"], ["84023.5", "0.012881"], ["84023.3", "0.001466"], ["84022.7", "0.017619"], ["84022.5", "0.000516"], ["84021.6", "0.118804"], ["84020.7", "0.128873"], ["84020.6", "0.000119"], ["84020.5", "0.011902"], ["84020.3", "0.232559"], ["84020.2", "0.4"], ["84020", "0.001483"], ["84019.7", "0.00009"], ["84019.6", "0.003181"], ["84019.3", "0.135511"], ["84018.7", "0.001466"], ["84018.6", "0.171"], ["84018.2", "0.059399"], ["84017.9", "0.000516"], ["84016.5", "1.940534"], ["84016.4", "2.950057"], ["84016.2", "3.521913"], ["84016", "0.000118"], ["84015.8", "0.001333"], ["84015.4", "0.003181"], ["84015.3", "0.0001"], ["84015.1", "0.005942"], ["84014.1", "0.001466"], ["84013.3", "0.000516"], ["84012.3", "0.000333"], ["84012", "0.011903"], ["84011.6", "0.001423"], ["84011.3", "0.009"], ["84011.2", "0.003181"], ["84011", "0.00107"], ["84010.5", "0.327005"], ["84010.4", "0.213321"], ["84010.3", "0.04"], ["84010.1", "0.171"], ["84010", "0.066146"], ["84009.7", "0.015"], ["84009.4", "0.001466"], ["84009.1", "0.076061"], ["84009", "17.620531"], ["84008.7", "0.004644"], ["84008.5", "0.003575"], ["84008.4", "0.118804"], ["84008.1", "0.021264"], ["84008", "0.023791"], ["84007.4", "0.001333"], ["84007", "0.003181"], ["84005.6", "0.04"], ["84004.8", "0.001466"], ["84004", "0.000516"], ["84003.9", "0.000333"], ["84003.5", "0.005947"], ["84003.2", "0.001423"], ["84002.8", "0.026973"], ["84001.6", "0.171"], ["84001.3", "0.059399"], ["84001.1", "0.023792"], ["84000.8", "0.000014"], ["84000.2", "0.001466"], ["84000.1", "1.091681"], ["84000", "3.678938"], ["83999.7", "0.000333"], ["83999.6", "0.057829"], ["83999.4", "0.000516"], ["83999.3", "0.023792"], ["83999", "0.041333"], ["83998.8", "0.000106"], ["83998.6", "0.003181"], ["83998.3", "0.124746"], ["83998", "0.000532"], ["83996.5", "0.0045"], ["83996", "0.235392"], ["83995.7", "0.023792"], ["83995.6", "0.001466"], ["83995.5", "0.000333"], ["83995.2", "0.023792"], ["83994.8", "0.001939"], ["83994.7", "0.089099"], ["83994.4", "0.003181"], ["83993.2", "0.04"], ["83993.1", "0.171"], ["83992.2", "0.005943"], ["83991.4", "0.203256"], ["83991.3", "0.000333"], ["83991", "0.001466"], ["83990.8", "0.000166"], ["83990.7", "0.00005"], ["83990.6", "0.001333"], ["83990.2", "0.003697"], ["83989.4", "0.195"], ["83988.5", "0.353413"], ["83988.2", "0.118804"], ["83987.3", "0.04"], ["83987.2", "0.013097"], ["83987.1", "0.000333"], ["83986.9", "0.028076"], ["83986.6", "0.000337"], ["83986.4", "0.001423"], ["83986.3", "0.001466"], ["83986", "0.003181"]], "a": [["84061.2", "0.134848"], ["84061.7", "0.003213"], ["84062", "0.001333"], ["84062.1", "0.012222"], ["84062.7", "0.000333"], ["84063.5", "0.00119"], ["84064.1", "0.000516"], ["84064.9", "0.001466"], ["84065.2", "0.005942"], ["84065.9", "0.003213"], ["84066.2", "0.004034"], ["84066.9", "0.000333"], ["84067.3", "0.000153"], ["84067.5", "0.013774"], ["84067.6", "0.012503"], ["84068.7", "0.002483"], ["84069.5", "0.001466"], ["84069.6", "0.015"], ["84070", "0.00329"], ["84070.1", "0.003214"], ["84070.4", "0.001333"], ["84071.1", "0.000333"], ["84071.3", "0.005917"], ["84071.4", "0.000297"], ["84071.5", "0.04"], ["84071.6", "0.044"], ["84071.8", "0.025006"], ["84072.4", "0.223165"], ["84072.5", "0.067374"], ["84073.2", "0.059399"], ["84073.4", "0.000516"], ["84074.2", "0.001466"], ["84074.3", "0.003215"], ["84074.6", "0.001333"], ["84074.7", "0.302107"], ["84075", "0.088"], ["84075.1", "0.123027"], ["84075.2", "0.048"], ["84075.3", "0.000333"], ["84075.4", "0.17109"], ["84075.5", "0.04"], ["84075.6", "0.232094"], ["84076.1", "0.0012"], ["84076.2", "0.03899"], ["84076.3", "0.005948"], ["84076.6", "0.088"], ["84077.4", "0.178442"], ["84077.7", "0.112637"], ["84077.9", "0.035695"], ["84078", "0.000516"], ["84078.2", "0.048"], ["84078.5", "0.18162"], ["84078.6", "0.023627"], ["84078.8", "0.002799"], ["84079", "0.117871"], ["84079.5", "0.000333"], ["84079.8", "0.220942"], ["84080", "0.00024"], ["84080.1", "0.052"], ["84080.2", "0.178401"], ["84081.1", "0.0012"], ["84082", "0.005942"], ["84082.5", "0.059399"], ["84082.6", "0.000516"], ["84082.7", "0.003225"], ["84083", "0.001333"], ["84083.1", "0.011202"], ["84083.4", "0.001466"], ["84083.7", "0.000333"], ["84083.8", "0.00009"], ["84083.9", "0.459606"], ["84084.8", "0.126103"], ["84084.9", "0.168015"], ["84085.2", "0.176054"], ["84085.6", "0.018458"], ["84086", "0.187392"], ["84086.5", "0.0045"], ["84086.7", "0.003447"], ["84086.9", "0.122038"], ["84087.2", "0.013745"], ["84087.3", "0.171"], ["84087.9", "0.003433"], ["84088", "0.001466"], ["84088.9", "0.011902"], ["84090.7", "0.217219"], ["84090.8", "0.540353"], ["84091.1", "0.003234"], ["84091.4", "0.001333"], ["84091.9", "0.059917"], ["84092", "0.118804"], ["84092.1", "0.000333"], ["84092.2", "0.290599"], ["84092.7", "0.001466"], ["84093", "0.278513"], ["84094", "0.288472"], ["84094.2", "0.019638"], ["84094.3", "0.023789"], ["84094.5", "0.0006"], ["84095", "0.023789"], ["84095.3", "0.003236"], ["84095.6", "0.001333"], ["84095.9", "0.005947"], ["84096", "0.000118"], ["84096.2", "0.004597"], ["84096.3", "0.000333"], ["84096.4", "0.0012"], ["84096.5", "0.000518"], ["84097.3", "0.001466"], ["84097.4", "0.082549"], ["84097.5", "0.118804"], ["84097.8", "0.003575"], ["84098.5", "0.023789"], ["84098.7", "0.0006"], ["84098.8", "0.005942"], ["84099.1", "0.04"], ["84099.3", "0.044"], ["84099.5", "0.003236"], ["84099.6", "0.089221"], ["84099.7", "0.002141"], ["84099.8", "0.001333"], ["84100", "0.00693"], ["84100.3", "0.024389"], ["84100.5", "0.000333"], ["84100.6", "0.00009"], ["84101", "0.05993"], ["84101.1", "0.609174"], ["84101.2", "0.194789"], ["84101.3", "0.009"], ["84101.4", "0.012846"], ["84101.5", "0.012846"], ["84101.9", "0.001466"], ["84102.3", "0.04"], ["84102.4", "0.04"], ["84102.6", "0.048"], ["84103", "0.004201"], ["84103.1", "1.426821"], ["84103.7", "0.003236"], ["84104", "0.064766"], ["84104.3", "0.048"], ["84104.7", "0.000333"], ["84104.8", "0.118804"], ["84105.6", "0.015"], ["84105.7", "0.000518"], ["84105.9", "0.048"], ["84106.2", "0.138911"], ["84106.3", "0.353419"], ["84106.4", "0.089099"], ["84106.5", "0.001466"], ["84106.9", "0.014061"], ["84107.9", "0.003236"], ["84108.2", "0.001333"], ["84109", "0.000423"], ["84110.2", "0.118804"], ["84110.3", "0.059399"], ["84110.4", "0.000518"], ["84110.5", "0.17141"], ["84111.2", "0.02525"], ["84111.9", "0.023784"], ["84112.1", "0.003236"], ["84112.4", "0.001333"], ["84112.8", "0.028772"], ["84112.9", "0.04"], ["84113.2", "0.000333"], ["84113.3", "0.052"], ["84115", "0.000518"], ["84115.4", "0.023784"], ["84115.5", "3.062956"], ["84115.6", "0.005942"], ["84115.8", "0.001466"], ["84116.2", "2.257053"], ["84116.3", "0.003237"], ["84116.5", "0.0045"], ["84116.6", "0.001333"], ["84116.9", "0.118804"], ["84117.2", "0.023784"], ["84117.3", "0.00009"], ["84117.4", "0.000423"], ["84118.1", "0.023784"], ["84119.6", "0.000518"], ["84120", "0.00034"], ["84120.4", "0.001466"], ["84120.5", "0.003237"], ["84120.9", "0.001333"], ["84121.6", "0.051633"], ["84121.7", "0.171"], ["84123.2", "0.059399"], ["84124.2", "0.000518"], ["84124.7", "0.003237"], ["84125", "0.001466"], ["84125.1", "0.001333"], ["84125.4", "0.118804"], ["84125.8", "0.000423"], ["84126.6", "0.00234"], ["84128.1", "0.059449"], ["84128.3", "3.600751"], ["84128.5", "0.0001"], ["84128.9", "0.003755"], ["84129.3", "0.041333"], ["84129.7", "0.090565"], ["84130", "0.000333"]], "u": 20661, "seq": 67549987617}, "cts": 1742555345277, "record_time": 1742555346.232066, "EXCHANGE": "BYBIT"}
{"topic": "orderbook.200.BTCUSDT", "ts": 1742555345520, "type": "delta", "data": {"s": "BTCUSDT", "b": [["84052.2", "0.002999"], ["84033.3", "0.397453"], ["84023.6", "0.013"], ["83986", "0"]], "a": [["84084.8", "0.245102"], ["84090.6", "0.001278"], ["84130", "0"]], "u": 20662, "seq": 67549987642}, "cts": 1742555345499, "record_time": 1742555346.233038, "EXCHANGE": "BYBIT"}
{"topic": "orderbook.200.BTCUSDT", "ts": 1742555345720, "type": "delta", "data": {"s": "BTCUSDT", "b": [["84052.2", "0.005998"], ["84011.8", "17.620531"], ["84009", "0"]], "a": [["84090.5", "0.001246"], ["84090.6", "0"]], "u": 20663, "seq": 67549987658}, "cts": 1742555345702, "record_time": 1742555346.233854, "EXCHANGE": "BYBIT"}
{"topic": "orderbook.200.BTCUSDT", "ts": 1742555345919, "type": "delta", "data": {"s": "BTCUSDT", "b": [["84061.6", "0.348431"], ["84061.2", "0.097553"], ["84061.1", "0.172389"], ["84060.4", "0.089099"], ["84056.6", "0.0025"], ["84056.1", "0"], ["84055", "0"], ["84053.3", "0"], ["84053.2", "0.018213"], ["84052.8", "0.071301"], ["84052.7", "0"], ["84050.9", "0.089099"], ["84050.3", "0.072655"], ["84050.2", "0.000516"], ["84049.9", "0"], ["84046.1", "0.124062"], ["84040.1", "0"], ["84039.7", "0"], ["84039.1", "0"], ["84037.8", "0.003576"], ["84033.4", "0.141623"], ["84032.7", "0"], ["84032.1", "0"], ["84031", "0"], ["84027.1", "0.171516"], ["84020.7", "0.000333"], ["84011.8", "0"], ["83986.9", "0"], ["83986.4", "17.630738"], ["83986", "0.003181"], ["83985.6", "0.000516"], ["83984.4", "0.059399"], ["83984", "0.04"], ["83983.2", "0.160747"], ["83982.9", "0.000333"], ["83982.5", "0.011992"]], "a": [["84061.2", "0"], ["84061.7", "0.054962"], ["84066.2", "0.001534"], ["84066.7", "0.0025"], ["84067.3", "0"], ["84067.5", "0"], ["84069.6", "0.005"], ["84070.1", "0.013214"], ["84071.3", "0"], ["84071.5", "0"], ["84071.6", "0"], ["84071.7", "0.000297"], ["84072.4", "0.145346"], ["84073.2", "0"], ["84074.7", "0"], ["84075", "0.04"], ["84075.1", "0.003762"], ["84075.5", "0"], ["84075.6", "0.071432"], ["84076.6", "0.04"], ["84077.1", "0.008842"], ["84077.3", "0.04"], ["84077.4", "0"], ["84077.9", "0"], ["84078.2", "0"], ["84078.5", "0.003215"], ["84079", "0"], ["84079.8", "0.256636"], ["84080.2", "0"], ["84083.4", "0.01915"], ["84084.9", "0"], ["84085.2", "0"], ["84086", "0.023792"], ["84090.5", "0"], ["84092.2", "0.00009"], ["84093", "0"], ["84094", "0"], ["84099.6", "0"], ["84101.4", "0"], ["84101.5", "0"], ["84102.3", "0"], ["84102.4", "0"], ["84104", "0.001333"], ["84104.7", "0.013333"], ["84104.8", "0.13165"], ["84105.6", "0.055"], ["84105.7", "0.040518"], ["84106.8", "0.063433"], ["84112.8", "0.005946"], ["84116.2", "0"], ["84117.5", "0.024954"], ["84124.7", "2.26029"], ["84130", "0.000333"], ["84130.9", "0.118804"], ["84131", "0.001428"], ["84131.2", "0.059449"], ["84131.3", "0.009"], ["84132", "0.0018"], ["84132.1", "0.059449"], ["84132.2", "0.027508"], ["84132.4", "0.005942"], ["84132.8", "0.059399"], ["84133.1", "0.006786"], ["84133.5", "0.001851"], ["84134.2", "0.000423"], ["84134.3", "0.001466"], ["84137.1", "0.4"], ["84137.2", "0.029723"], ["84137.3", "0.003211"], ["84137.4", "0.013073"], ["84137.7", "0.001333"]], "u": 20664, "seq": 67549987955}, "cts": 1742555345917, "record_time": 1742555346.234986, "EXCHANGE": "BYBIT"}
{"topic": "orderbook.200.BTCUSDT", "ts": 1742555346120, "type": "delta", "data": {"s": "BTCUSDT", "b": [["84061.6", "0.378173"], ["84061.2", "0.05181"], ["84061.1", "0.17232"], ["84060.4", "0"], ["84039.8", "0"], ["84033.3", "0.000333"], ["83998.2", "0.028134"], ["83989.2", "17.629315"], ["83986.4", "0.001423"], ["83984.6", "0.171"], ["83982.5", "0"]], "a": [["84061.7", "0.084706"], ["84069.6", "0"], ["84070.1", "0.018214"], ["84071.3", "0.00586"], ["84072.4", "0.101127"], ["84074.5", "0.000153"], ["84077.4", "0.044"], ["84079.8", "0.220942"], ["84080", "0.035934"], ["84080.7", "0.048"], ["84082.4", "0.048"], ["84084", "0.048"], ["84084.8", "0.108564"], ["84099.1", "0"], ["84099.3", "0"], ["84099.6", "0.08922"], ["84102.6", "0"], ["84104.3", "0"], ["84104.7", "0.000333"], ["84104.9", "0.012846"], ["84105.6", "0.015"], ["84105.8", "0.04"], ["84119.2", "2.257053"], ["84124.7", "0.003237"], ["84130.2", "0.171"], ["84134.3", "0"], ["84137.1", "0"], ["84137.2", "0"], ["84137.3", "0"], ["84137.4", "0"], ["84137.7", "0"]], "u": 20665, "seq": 67549988021}, "cts": 1742555346117, "record_time": 1742555346.235866, "EXCHANGE": "BYBIT"}
{"topic": "orderbook.200.BTCUSDT", "ts": 1742555346319, "type": "delta", "data": {"s": "BTCUSDT", "b": [["84061.6", "0.378246"], ["84060", "0.089159"], ["84048.5", "0.060583"], ["84041.5", "0.055305"], ["84034.5", "0.120536"], ["84024.4", "0.013"], ["84024.3", "0.06161"], ["84023.6", "0"], ["84023.5", "0"], ["84017.5", "17.629315"], ["83989.2", "0"], ["83983.2", "0"], ["83982.9", "0"]], "a": [["84061.7", "0.037122"], ["84072.3", "0.059399"], ["84082.3", "0.04"], ["84083.5", "0.059708"], ["84090.5", "0.054484"], ["84097.5", "0.22801"], ["84099.6", "0"], ["84105.9", "0"], ["84119.2", "0"], ["84134.2", "0"]], "u": 20666, "seq": 67549988098}, "cts": 1742555346318, "record_time": 1742555346.339867, "EXCHANGE": "BYBIT"}
{"topic": "orderbook.200.BTCUSDT", "ts": 1742555346520, "type": "delta", "data": {"s": "BTCUSDT", "b": [["84061.2", "0.072663"], ["84048.5", "0"], ["84041.5", "0"], ["84034.5", "0"], ["84033.5", "0.191738"], ["84024.4", "0"], ["84024.3", "0.048729"], ["84024.1", "0.013"], ["84024", "0.012881"], ["84017.5", "0"], ["84006.2", "17.629315"], ["83983.2", "0.160747"]], "a": [["84061.7", "0.084706"], ["84071.3", "0"], ["84075.1", "0"], ["84077.7", "0"], ["84080.8", "0.112625"], ["84083.5", "0"], ["84090.5", "0"], ["84097.5", "0.118804"], ["84104.8", "0.118804"], ["84104.9", "0"], ["84105.7", "0.013518"], ["84105.8", "0.012845"], ["84106.6", "0.04"], ["84106.7", "0.04"], ["84119.1", "2.25704"], ["84134.2", "0.000423"], ["84134.3", "0.001466"]], "u": 20667, "seq": 67549988241}, "cts": 1742555346509, "record_time": 1742555346.54034, "EXCHANGE": "BYBIT"}
{"topic": "orderbook.200.BTCUSDT", "ts": 1742555346719, "type": "delta", "data": {"s": "BTCUSDT", "b": [["84061.9", "0.343837"], ["84061.7", "0.056085"], ["84061.6", "0.171"], ["84061.2", "0.0006"], ["84061.1", "0.00132"], ["84057.5", "0.003214"], ["84056.9", "0.0025"], ["84056.6", "0"], ["84053.5", "0.01"], ["84053.2", "0.008213"], ["84048.7", "0.065394"], ["84045.3", "0"], ["84041.7", "0.058199"], ["84034.7", "0.112482"], ["84024.2", "0.014333"], ["84024.1", "0.012881"], ["84024", "0"], ["83984.4", "0"], ["83984", "0"], ["83983.2", "0"]], "a": [["84061.7", "0"], ["84062", "0.026194"], ["84066.7", "0"], ["84067", "0.0025"], ["84070.1", "0.003214"], ["84070.4", "0.016333"], ["84079.9", "0.026194"], ["84080", "0.00024"], ["84083.7", "0.055152"], ["84084.9", "0.004043"], ["84090.7", "0.27181"], ["84097.4", "0.057349"], ["84097.7", "0.121131"], ["84105.6", "0.028"], ["84105.7", "0.013363"], ["84105.8", "0"], ["84134.3", "0"]], "u": 20668, "seq": 67549988403}, "cts": 1742555346705, "record_time": 1742555346.739802, "EXCHANGE": "BYBIT"}
{"topic": "orderbook.200.BTCUSDT", "ts": 1742555346919, "type": "delta", "data": {"s": "BTCUSDT", "b": [["84061.9", "0.343911"], ["84053.5", "0.015"], ["84053.2", "0.003213"], ["84017.5", "17.629315"], ["84006.2", "0"], ["83990.6", "1.126459"]], "a": [["84072.6", "0.00599"], ["84074.2", "0.005509"], ["84074.5", "0"], ["84084.9", "0"], ["84106.5", "0.041466"], ["84106.7", "0"], ["84134.3", "0.001466"], ["84137.1", "0.4"]], "u": 20669, "seq": 67549988428}, "cts": 1742555346914, "record_time": 1742555346.939515, "EXCHANGE": "BYBIT"}
{"topic": "orderbook.200.BTCUSDT", "ts": 1742555347320, "type": "delta", "data": {"s": "BTCUSDT", "b": [["84061.1", "0.0006"], ["84025", "0.128733"]], "a": [], "u": 20670, "seq": 67549988452}, "cts": 1742555347288, "record_time": 1742555347.355521, "EXCHANGE": "BYBIT"}
{"topic": "orderbook.200.BTCUSDT", "ts": 1742555347520, "type": "delta", "data": {"s": "BTCUSDT", "b": [["84061.9", "0.344711"], ["84060.5", "0.0037"], ["84055.2", "0"], ["84038.2", "0.177322"], ["84037.3", "0"], ["84031.8", "0.002016"], ["84026.5", "0.0045"]], "a": [["84105.7", "0.013362"]], "u": 20671, "seq": 67549988489}, "cts": 1742555347495, "record_time": 1742555347.542483, "EXCHANGE": "BYBIT"}
{"topic": "orderbook.200.BTCUSDT", "ts": 1742555347720, "type": "delta", "data": {"s": "BTCUSDT", "b": [["84039.9", "0.026194"], ["84001.3", "0.294791"], ["83996", "0"]], "a": [], "u": 20672, "seq": 67549988500}, "cts": 1742555347672, "record_time": 1742555347.740616, "EXCHANGE": "BYBIT"}
{"topic": "orderbook.200.BTCUSDT", "ts": 1742555347920, "type": "delta", "data": {"s": "BTCUSDT", "b": [["84061.9", "0.348279"], ["84061.7", "0.056285"], ["84060", "0.00006"], ["84053.9", "0.110429"], ["84053.8", "0.115882"], ["84052.8", "0"], ["84050.3", "0.100535"], ["84049.7", "0.117066"], ["84048.7", "0.005942"], ["84043.3", "0.174618"], ["84042.7", "0.176633"], ["84041.7", "0.000333"], ["84036.3", "0.277467"], ["84035.7", "0.290452"], ["84034.7", "0"], ["84024.2", "0.014214"], ["84011", "0"], ["83986.3", "0"], ["83986", "0"], ["83985.6", "0"], ["83984.6", "0"]], "a": [["84062", "0.029394"], ["84078.3", "0.124323"], ["84082.6", "0.109765"], ["84083.7", "0.000333"], ["84088.8", "0.171519"], ["84089.6", "0.175417"], ["84090.7", "0.217219"], ["84095.8", "0.298894"], ["84096.6", "0.279394"], ["84097.7", "0"], ["84106.4", "0.129099"], ["84106.6", "0"], ["84134.2", "0"], ["84134.3", "0"], ["84137.1", "0"]], "u": 20673, "seq": 67549988536}, "cts": 1742555347915, "record_time": 1742555347.940927, "EXCHANGE": "BYBIT"}
{"topic": "orderbook.200.BTCUSDT", "ts": 1742555348119, "type": "delta", "data": {"s": "BTCUSDT", "b": [["84061.9", "0.195664"], ["84061.7", "0.0002"], ["84061.6", "0"], ["84053.9", "0.048935"], ["84053.8", "0"], ["84050.9", "0"], ["84050.3", "0.072655"], ["84049.7", "0"], ["84043.3", "0"], ["84042.7", "0"], ["84037.8", "0"], ["84036.3", "0"], ["84035.7", "0"], ["84024.3", "0.061729"], ["84024.1", "0"], ["84016.8", "0.001784"], ["83986.3", "0.001466"], ["83986", "0.003181"], ["83985.6", "0.000516"], ["83984.4", "0.059399"], ["83984", "0.04"], ["83983.2", "0.160747"], ["83982.9", "0.000333"], ["83982.5", "0.011992"], ["83982.2", "0.001333"]], "a": [["84062", "0.200632"], ["84077.1", "0"], ["84078.3", "0"], ["84082.6", "0.000516"], ["84088.8", "0"], ["84089.6", "0"], ["84095.8", "0"], ["84096.6", "0"], ["84105.5", "0.013"], ["84105.6", "0.027844"], ["84105.7", "0.000518"], ["84119.1", "2.257032"], ["84134.2", "0.000423"], ["84134.3", "0.001466"], ["84137.1", "0.4"], ["84137.2", "0.029723"], ["84137.3", "0.003211"]], "u": 20674, "seq": 67549988593}, "cts": 1742555348088, "record_time": 1742555348.141822, "EXCHANGE": "BYBIT"}
{"topic": "orderbook.200.BTCUSDT", "ts": 1742555348319, "type": "delta", "data": {"s": "BTCUSDT", "b": [["84061.9", "0.17647"], ["84038.1", "0"], ["84038", "0.059399"], ["84033.4", "0"], ["84017.5", "0"], ["84009", "17.255012"], ["83984.6", "0.171"]], "a": [["84067.5", "0.011976"], ["84080.6", "0.118804"], ["84083.4", "0.001466"], ["84099.6", "0.08922"], ["84104", "0.064765"], ["84106.8", "0"], ["84116.2", "2.257032"], ["84119.1", "0"], ["84137.2", "0"], ["84137.3", "0"]], "u": 20675, "seq": 67549988652}, "cts": 1742555348310, "record_time": 1742555348.340382, "EXCHANGE": "BYBIT"}
{"topic": "orderbook.200.BTCUSDT", "ts": 1742555348520, "type": "delta", "data": {"s": "BTCUSDT", "b": [["84061.9", "0.098392"], ["84051.8", "0.019358"], ["84039.9", "0"], ["84039.6", "0.035694"], ["84029.1", "0.023024"], ["84025.1", "0.08939"], ["84024.3", "0"], ["84024.2", "0.001333"], ["84023.9", "0.013"], ["84023.8", "0.016062"], ["84010.5", "5.476883"], ["84009", "0"], ["84003.3", "17.255012"], ["83982.5", "0"], ["83982.2", "0"]], "a": [["84068.9", "0.000153"], ["84074.8", "0.107338"], ["84101", "0.062055"], ["84102", "0.012844"], ["84102.1", "0.012844"], ["84103", "0"], ["84104", "0.001333"], ["84105.5", "0"], ["84105.6", "0.015"], ["84106.8", "0.063432"], ["84113.2", "0.02468"], ["84116.2", "0"], ["84117.5", "0"], ["84124.9", "2.257032"], ["84134.3", "0"], ["84137.1", "0"]], "u": 20676, "seq": 67549988725}, "cts": 1742555348511, "record_time": 1742555348.541187, "EXCHANGE": "BYBIT"}
{"topic": "orderbook.200.BTCUSDT", "ts": 1742555348719, "type": "delta", "data": {"s": "BTCUSDT", "b": [["84023.9", "0"], ["84023.8", "0.003181"], ["84023.5", "0.013"], ["84023.4", "0.012881"], ["84010.5", "0.327005"], ["84009", "17.085633"], ["84003.3", "0"], ["83982.9", "0"]], "a": [["84100.5", "0.002458"], ["84101", "0.05993"], ["84102", "0"], ["84102.1", "0"], ["84102.7", "0.013"], ["84102.8", "0.012844"], ["84104", "0.064765"], ["84106.8", "0"], ["84124.7", "2.260269"], ["84124.9", "0"], ["84134.3", "0.001466"], ["84137.1", "0.4"]], "u": 20677, "seq": 67549988756}, "cts": 1742555348636, "record_time": 1742555348.744461, "EXCHANGE": "BYBIT"}
{"topic": "orderbook.200.BTCUSDT", "ts": 1742555348920, "type": "delta", "data": {"s": "BTCUSDT", "b": [["84023.8", "0.016062"], ["84023.7", "0.012881"], ["84023.5", "0"], ["84023.4", "0"], ["83982.9", "0.000333"]], "a": [["84099.4", "0.002125"], ["84100.5", "0.000333"], ["84101.9", "0.01431"], ["84102", "0.012844"], ["84102.7", "0"], ["84102.8", "0.04"], ["84102.9", "0.04"], ["84106.4", "0.089099"], ["84106.5", "0.001466"], ["84116.2", "2.257032"], ["84124.7", "0.003237"], ["84134.2", "0"], ["84134.3", "0"], ["84137.1", "0"]], "u": 20678, "seq": 67549988780}, "cts": 1742555348881, "record_time": 1742555348.939863, "EXCHANGE": "BYBIT"}
{"topic": "orderbook.200.BTCUSDT", "ts": 1742555349120, "type": "delta", "data": {"s": "BTCUSDT", "b": [["84061.9", "0.269392"], ["84049.4", "0.130668"], ["84023.8", "0.003181"], ["84023.7", "0"], ["84023.4", "0.013"], ["84023.3", "0.014347"]], "a": [["84062", "0.029632"], ["84101.9", "0.001466"], ["84102", "0"], ["84102.8", "0.012844"], ["84102.9", "0.012844"], ["84103.7", "0.043236"], ["84103.8", "0.04"]], "u": 20679, "seq": 67549988801}, "cts": 1742555349108, "record_time": 1742555349.140231, "EXCHANGE": "BYBIT"}
{"topic": "orderbook.200.BTCUSDT", "ts": 1742555349720, "type": "delta", "data": {"s": "BTCUSDT", "b": [["84061.9", "0.229392"]], "a": [["84062", "0.029495"]], "u": 20680, "seq": 67549988833}, "cts": 1742555349717, "record_time": 1742555349.741001, "EXCHANGE": "BYBIT"}
{"topic": "orderbook.200.BTCUSDT", "ts": 1742555349920, "type": "delta", "data": {"s": "BTCUSDT", "b": [["84061.9", "0.100176"], ["84061.7", "0"], ["84052.2", "0"], ["84010.5", "5.426069"], ["83994.5", "0.35341"], ["83988.5", "0"], ["83982.5", "0.011992"], ["83982.2", "0.001333"]], "a": [["84062", "0.200495"]], "u": 20681, "seq": 67549988855}, "cts": 1742555349915, "record_time": 1742555349.940403, "EXCHANGE": "BYBIT"}
{"topic": "orderbook.200.BTCUSDT", "ts": 1742555350120, "type": "delta", "data": {"s": "BTCUSDT", "b": [["84023.9", "0.013"], ["84023.8", "0.016062"], ["84023.4", "0"], ["84023.3", "0.001466"], ["84009", "0"], ["84006.2", "17.085633"]], "a": [["84101.9", "0.014313"], ["84102", "0.012847"], ["84102.8", "0.04"], ["84102.9", "0.04"], ["84103.7", "0.003236"], ["84103.8", "0"]], "u": 20682, "seq": 67549988873}, "cts": 1742555350117, "record_time": 1742555350.141094, "EXCHANGE": "BYBIT"}
{"topic": "orderbook.200.BTCUSDT", "ts": 1742555350319, "type": "delta", "data": {"s": "BTCUSDT", "b": [["84061.9", "0.103147"], ["84049.4", "0.041569"], ["84010.5", "0.327005"]], "a": [["84062", "0.204573"], ["84101.7", "0.013"], ["84101.8", "0.012847"], ["84101.9", "0.001466"], ["84102", "0"], ["84102.6", "0.04"], ["84102.7", "0.04"], ["84102.8", "0"], ["84102.9", "0"], ["84133.5", "0"]], "u": 20683, "seq": 67549988918}, "cts": 1742555350311, "record_time": 1742555350.34117, "EXCHANGE": "BYBIT"}
{"topic": "orderbook.200.BTCUSDT", "ts": 1742555350520, "type": "delta", "data": {"s": "BTCUSDT", "b": [["84023.9", "0"], ["84023.7", "0.012881"], ["83982.6", "0.04406"], ["83982.2", "0"]], "a": [["84101.7", "0"], ["84101.9", "0.014313"], ["84102.6", "0"], ["84102.8", "0.04"], ["84133.5", "0.001851"]], "u": 20684, "seq": 67549988965}, "cts": 1742555350502, "record_time": 1742555350.540682, "EXCHANGE": "BYBIT"}
{"topic": "orderbook.200.BTCUSDT", "ts": 1742555350720, "type": "delta", "data": {"s": "BTCUSDT", "b": [], "a": [["84062", "0.033098"], ["84101.8", "0.013"]], "u": 20685, "seq": 67549988986}, "cts": 1742555350701, "record_time": 1742555350.740331, "EXCHANGE": "BYBIT"}
{"topic": "orderbook.200.BTCUSDT", "ts": 1742555350920, "type": "delta", "data": {"s": "BTCUSDT", "b": [["84061.9", "0.274747"], ["84039.6", "0"], ["84039.5", "0.033098"]], "a": [["84072.4", "0.158303"], ["84101.8", "0.012847"]], "u": 20686, "seq": 67549989018}, "cts": 1742555350906, "record_time": 1742555350.941421, "EXCHANGE": "BYBIT"}
{"topic": "orderbook.200.BTCUSDT", "ts": 1742555351119, "type": "delta", "data": {"s": "BTCUSDT", "b": [["84023.8", "0.003181"], ["84023.7", "0"], ["84023.6", "0.013"], ["84023.5", "0.012881"], ["83982.5", "0"]], "a": [["84079.7", "0.112619"], ["84080.8", "0"], ["84101.8", "0"], ["84101.9", "0.001466"], ["84102.4", "0.013"], ["84102.5", "0.012847"], ["84102.7", "0"], ["84102.8", "0"], ["84103.3", "0.04"], ["84103.4", "0.04"], ["84133.5", "0"]], "u": 20687, "seq": 67549989037}, "cts": 1742555351054, "record_time": 1742555351.140625, "EXCHANGE": "BYBIT"}
{"topic": "orderbook.200.BTCUSDT", "ts": 1742555351320, "type": "delta", "data": {"s": "BTCUSDT", "b": [], "a": [["84078.6", "0"], ["84133.5", "0.001851"]], "u": 20688, "seq": 67549989049}, "cts": 1742555351280, "record_time": 1742555351.340469, "EXCHANGE": "BYBIT"}
{"topic": "orderbook.200.BTCUSDT", "ts": 1742555351520, "type": "delta", "data": {"s": "BTCUSDT", "b": [["84009", "16.570662"], ["84006.2", "0"]], "a": [["84080.4", "0.023812"], ["84098.4", "0.002125"], ["84099.4", "0"], ["84133.5", "0"]], "u": 20689, "seq": 67549989059}, "cts": 1742555351458, "record_time": 1742555351.539588, "EXCHANGE": "BYBIT"}
{"topic": "orderbook.200.BTCUSDT", "ts": 1742555351720, "type": "delta", "data": {"s": "BTCUSDT", "b": [["84061.9", "0.276531"], ["84010.5", "5.271578"]], "a": [], "u": 20690, "seq": 67549989072}, "cts": 1742555351667, "record_time": 1742555351.7401, "EXCHANGE": "BYBIT"}
{"topic": "orderbook.200.BTCUSDT", "ts": 1742555351920, "type": "delta", "data": {"s": "BTCUSDT", "b": [["84023.6", "0"], ["84023.4", "0.012881"], ["84009", "0"], ["84006.2", "16.570662"]], "a": [["84102.4", "0"], ["84102.5", "0"], ["84102.6", "0.012847"], ["84102.7", "0.012847"], ["84103.3", "0"], ["84103.4", "0"], ["84103.5", "0.04"], ["84103.6", "0.04"]], "u": 20691, "seq": 67549989085}, "cts": 1742555351850, "record_time": 1742555351.940138, "EXCHANGE": "BYBIT"}
{"topic": "orderbook.200.BTCUSDT", "ts": 1742555352120, "type": "delta", "data": {"s": "BTCUSDT", "b": [["84061.9", "0.105531"], ["84023.6", "0.013"], ["84023.4", "0"], ["84016.8", "0"], ["84010.5", "0.327005"], ["83982.5", "0.011992"]], "a": [["84062", "0.204098"], ["84068.9", "0"], ["84102.9", "0.04"], ["84103", "0.04"], ["84103.5", "0"], ["84103.6", "0"], ["84133.5", "0.001851"]], "u": 20692, "seq": 67549989140}, "cts": 1742555352098, "record_time": 1742555352.140627, "EXCHANGE": "BYBIT"}
{"topic": "orderbook.200.BTCUSDT", "ts": 1742555352320, "type": "delta", "data": {"s": "BTCUSDT", "b": [["84023.7", "0.012881"], ["84023.6", "0.012881"], ["84023.5", "0"], ["84009", "15.868419"], ["84006.2", "0"]], "a": [["84102.1", "0.012847"], ["84102.2", "0.012847"], ["84102.6", "0"], ["84102.7", "0"], ["84102.9", "0"], ["84103.1", "1.466821"], ["84134.2", "0.000423"]], "u": 20693, "seq": 67549989156}, "cts": 1742555352272, "record_time": 1742555352.340686, "EXCHANGE": "BYBIT"}
{"topic": "orderbook.200.BTCUSDT", "ts": 1742555352520, "type": "delta", "data": {"s": "BTCUSDT", "b": [["84061.9", "0.103747"], ["84023.8", "0.016062"], ["84023.6", "0"], ["84018.4", "0.001784"], ["84009", "0"], ["84006.2", "15.868419"]], "a": [["84097.2", "0.002125"], ["84098.4", "0"], ["84101.8", "0.012847"], ["84101.9", "0.014313"], ["84102.1", "0"], ["84102.2", "0"], ["84134.3", "0.001466"]], "u": 20694, "seq": 67549989176}, "cts": 1742555352470, "record_time": 1742555352.540098, "EXCHANGE": "BYBIT"}
{"topic": "orderbook.200.BTCUSDT", "ts": 1742555352720, "type": "delta", "data": {"s": "BTCUSDT", "b": [["84061.9", "0.100774"], ["84060.5", "0"], ["84051.6", "0"], ["84038", "0"], ["84034.3", "0"], ["84029.1", "0.000333"], ["84027.6", "0"], ["84025", "0.000199"], ["84023.8", "0.003181"], ["84023.7", "0"], ["84023.6", "0.012881"], ["84023.5", "0.012881"], ["84019.3", "0"], ["84013.6", "0.135511"], ["83990.6", "0.001333"], ["83982.2", "0.001333"], ["83981.8", "0.0032"], ["83981.7", "0.001466"], ["83981.5", "0.005942"]], "a": [["84062", "0.375098"], ["84069.2", "0.089099"], ["84085.5", "0.089099"], ["84094.1", "0.002125"], ["84097.2", "0"], ["84101.8", "0"], ["84101.9", "0.001466"], ["84102.3", "0.013"], ["84102.4", "0.012847"], ["84103", "0"], ["84103.1", "1.426821"], ["84103.2", "0.04"], ["84103.3", "0.04"], ["84113.2", "0.000333"], ["84116.2", "0"], ["84124.7", "2.260269"], ["84133.5", "0"], ["84134.2", "0"], ["84134.3", "0"]], "u": 20695, "seq": 67549989238}, "cts": 1742555352716, "record_time": 1742555352.740338, "EXCHANGE": "BYBIT"}
{"topic": "orderbook.200.BTCUSDT", "ts": 1742555352920, "type": "delta", "data": {"s": "BTCUSDT", "b": [["84061.9", "0.094057"], ["84055.7", "0.001466"], ["84050.3", "0.100751"], ["84045.8", "0.003896"], ["84039.5", "0"], ["84038", "0.059399"], ["84037.4", "0.036032"], ["84028.6", "0"], ["84027.4", "0.197349"], ["84025.1", "0"], ["84022.8", "0.024825"], ["84016.5", "2.07604"], ["84013.6", "0"], ["84006.2", "0"], ["84000.5", "15.324506"]], "a": [["84062", "0.213228"], ["84069.2", "0"], ["84075.6", "0.112018"], ["84086.2", "0.003576"], ["84107", "0.022631"], ["84133.1", "0"]], "u": 20696, "seq": 67549989351}, "cts": 1742555352905, "record_time": 1742555352.939961, "EXCHANGE": "BYBIT"}
{"topic": "orderbook.200.BTCUSDT", "ts": 1742555353120, "type": "delta", "data": {"s": "BTCUSDT", "b": [["84050.3", "0.072655"], ["84023.6", "0"], ["84023.4", "0.012881"], ["84006.2", "15.324506"], ["84000.5", "0"], ["83982.6", "0.043784"]], "a": [["84088.8", "0.002125"], ["84094.1", "0"], ["84107.9", "2.260268"], ["84124.7", "0.003237"]], "u": 20697, "seq": 67549989404}, "cts": 1742555353082, "record_time": 1742555353.140492, "EXCHANGE": "BYBIT"}
{"topic": "orderbook.200.BTCUSDT", "ts": 1742555353320, "type": "delta", "data": {"s": "BTCUSDT", "b": [["83982.6", "0"], ["83982.3", "0.043784"]], "a": [["84101.6", "0.04"], ["84101.7", "0.04"], ["84103.2", "0"], ["84103.3", "0"]], "u": 20698, "seq": 67549989419}, "cts": 1742555353315, "record_time": 1742555353.341413, "EXCHANGE": "BYBIT"}
{"topic": "orderbook.200.BTCUSDT", "ts": 1742555353520, "type": "delta", "data": {"s": "BTCUSDT", "b": [["84051.1", "0.023755"], ["84001.3", "0.059399"], ["83996", "0.235392"], ["83985.3", "1.125197"], ["83982.3", "0"], ["83981.7", "0"], ["83981.5", "0"]], "a": [["84086.2", "0"], ["84107.9", "0.003236"], ["84116.2", "2.257032"]], "u": 20699, "seq": 67549989453}, "cts": 1742555353502, "record_time": 1742555353.540247, "EXCHANGE": "BYBIT"}
{"topic": "orderbook.200.BTCUSDT", "ts": 1742555353720, "type": "delta", "data": {"s": "BTCUSDT", "b": [["84061.9", "0.093957"], ["84050.3", "0.100382"], ["84048.1", "0.116556"], ["84038.3", "0.178031"], ["84029.2", "0.30373"], ["83982.5", "0"], ["83982.2", "0"], ["83981.8", "0"]], "a": [["84062", "0.213328"], ["84073.3", "0.112239"], ["84083.1", "0.188725"], ["84092.2", "0.296091"], ["84101", "0.059399"], ["84101.6", "0"], ["84101.8", "0.04"], ["84132.8", "0"]], "u": 20700, "seq": 67549989488}, "cts": 1742555353710, "record_time": 1742555353.740543, "EXCHANGE": "BYBIT"}
{"topic": "orderbook.200.BTCUSDT", "ts": 1742555353920, "type": "delta", "data": {"s": "BTCUSDT", "b": [["84038", "0"], ["84034.8", "0"], ["83982.5", "0.011992"], ["83982.2", "0.001333"]], "a": [["84079.8", "0.310448"], ["84107.8", "2.257032"], ["84116.2", "0"]], "u": 20701, "seq": 67549989518}, "cts": 1742555353902, "record_time": 1742555353.945212, "EXCHANGE": "BYBIT"}
{"topic": "orderbook.200.BTCUSDT", "ts": 1742555354119, "type": "delta", "data": {"s": "BTCUSDT", "b": [["84038.4", "0.059399"], ["84037.7", "0"], ["84036.5", "0.112616"], ["84029.3", "0.207226"], ["84027.4", "0.118804"], ["84023.6", "0.012881"], ["84023.4", "0"], ["83982.5", "0"], ["83982.2", "0"]], "a": [["84100.7", "0.013"], ["84100.8", "0.012845"], ["84101.6", "0.04"], ["84101.8", "0"], ["84102.3", "0"], ["84102.4", "0"]], "u": 20702, "seq": 67549989548}, "cts": 1742555354091, "record_time": 1742555354.140174, "EXCHANGE": "BYBIT"}
{"topic": "orderbook.200.BTCUSDT", "ts": 1742555354320, "type": "delta", "data": {"s": "BTCUSDT", "b": [], "a": [["84091.4", "0.002485"], ["84097.4", "0.084699"], ["84100.7", "0.012845"], ["84107.8", "0"], ["84113.4", "2.257032"]], "u": 20703, "seq": 67549989565}, "cts": 1742555354309, "record_time": 1742555354.34086, "EXCHANGE": "BYBIT"}
{"topic": "orderbook.200.BTCUSDT", "ts": 1742555354519, "type": "delta", "data": {"s": "BTCUSDT", "b": [["84061.9", "0.076071"], ["84055", "0.000297"], ["84050.3", "0.072655"], ["84048.1", "0"], ["84038.3", "0"], ["84029.2", "0"], ["83982.5", "0.011992"], ["83982.2", "0.001333"]], "a": [["84062", "0.215329"], ["84073.3", "0"], ["84083.1", "0.011202"], ["84091.4", "0.001333"], ["84092.2", "0.00009"], ["84100.7", "0"], ["84100.9", "0.012845"], ["84110.6", "2.257032"], ["84113.4", "0"], ["84132.8", "0.059399"]], "u": 20704, "seq": 67549989608}, "cts": 1742555354516, "record_time": 1742555354.539942, "EXCHANGE": "BYBIT"}
{"topic": "orderbook.200.BTCUSDT", "ts": 1742555354719, "type": "delta", "data": {"s": "BTCUSDT", "b": [["84061.9", "0.090941"], ["84029.3", "0"], ["84023.8", "0.016181"], ["84023.7", "0.012881"], ["84023.6", "0"], ["84023.5", "0"], ["83994.5", "0"], ["83991.3", "0.353746"], ["83981.8", "0.0032"], ["83981.7", "0.001466"], ["83981.5", "0.005942"]], "a": [["84062", "0.2302"], ["84100.2", "0.012845"], ["84100.3", "0.037234"], ["84100.8", "0"], ["84100.9", "0"], ["84101.3", "0.049"], ["84101.4", "0.04"], ["84101.6", "0"], ["84101.7", "0"], ["84107.9", "2.260268"], ["84110.6", "0"], ["84133.1", "0.006786"], ["84133.5", "0.001851"], ["84134.2", "0.000423"]], "u": 20705, "seq": 67549989645}, "cts": 1742555354714, "record_time": 1742555354.740241, "EXCHANGE": "BYBIT"}
{"topic": "orderbook.200.BTCUSDT", "ts": 1742555354920, "type": "delta", "data": {"s": "BTCUSDT", "b": [], "a": [["84078", "0.036211"], ["84079.9", "0"], ["84101.1", "0.649174"], ["84101.2", "0.234789"], ["84101.3", "0.009"], ["84101.4", "0"], ["84134.3", "0.001466"], ["84136.7", "1.123173"]], "u": 20706, "seq": 67549989658}, "cts": 1742555354915, "record_time": 1742555354.940233, "EXCHANGE": "BYBIT"}
{"topic": "orderbook.200.BTCUSDT", "ts": 1742555355120, "type": "delta", "data": {"s": "BTCUSDT", "b": [["84061.9", "0.088154"], ["84050.3", "0.099934"], ["84048.1", "0.115064"], ["84044", "0.112513"], ["84037.6", "0.199236"], ["84037", "0.178077"], ["84030.6", "0.286619"], ["84030", "0.297432"], ["84027.5", "0.114186"], ["83982.9", "0"], ["83982.5", "0"], ["83982.2", "0"], ["83981.8", "0"], ["83981.7", "0"], ["83981.5", "0"]], "a": [["84072.6", "0.11762"], ["84076.9", "0.109763"], ["84083.1", "0.183556"], ["84083.9", "0.631837"], ["84090.1", "0.287217"], ["84090.9", "0.281298"], ["84134.2", "0"], ["84134.3", "0"], ["84136.7", "0"]], "u": 20707, "seq": 67549989698}, "cts": 1742555355098, "record_time": 1742555355.141526, "EXCHANGE": "BYBIT"}
{"topic": "orderbook.200.BTCUSDT", "ts": 1742555355320, "type": "delta", "data": {"s": "BTCUSDT", "b": [["84023.8", "0.016062"]], "a": [["84107.9", "0.003236"], ["84116.2", "2.257032"], ["84133.5", "0"]], "u": 20708, "seq": 67549989711}, "cts": 1742555355285, "record_time": 1742555355.341248, "EXCHANGE": "BYBIT"}
{"topic": "orderbook.200.BTCUSDT", "ts": 1742555355520, "type": "delta", "data": {"s": "BTCUSDT", "b": [["84061.9", "0.265938"], ["84055.2", "0.0039"], ["84050.3", "0.072655"], ["84048.1", "0"], ["84044", "0"], ["84037.6", "0.021653"], ["84037", "0"], ["84031.8", "0.000516"], ["84030.6", "0"], ["84030", "0"], ["84027", "0.022686"], ["84026.5", "0.0061"], ["84022.8", "0"], ["84018.4", "0"], ["83982.9", "0.000333"], ["83982.5", "0.011992"], ["83982.2", "0.001333"], ["83981.8", "0.0032"], ["83981.7", "0.001466"]], "a": [["84062", "0.0592"], ["84072.6", "0.00599"], ["84076.9", "0"], ["84080.6", "0"], ["84083.1", "0.011202"], ["84083.9", "0.459606"], ["84090.1", "0"], ["84090.8", "0.541363"], ["84090.9", "0"], ["84100.2", "0"], ["84100.3", "0.024389"], ["84100.4", "0.012845"], ["84100.5", "0.013178"], ["84101.1", "0.609174"], ["84101.2", "0.194789"], ["84101.3", "0.049"], ["84101.4", "0.04"], ["84107", "0"], ["84111.3", "0.024257"], ["84113.5", "2.257032"], ["84116.2", "0"], ["84133.5", "0.001851"], ["84134.2", "0.000423"], ["84134.3", "0.001466"]], "u": 20709, "seq": 67549989783}, "cts": 1742555355507, "record_time": 1742555355.541364, "EXCHANGE": "BYBIT"}
{"topic": "orderbook.200.BTCUSDT", "ts": 1742555355720, "type": "delta", "data": {"s": "BTCUSDT", "b": [["84023.8", "0.003181"], ["84023.7", "0"], ["84023.5", "0.012881"], ["84023.4", "0.012881"], ["84019.3", "0.135504"], ["84016.5", "1.940534"], ["84009", "14.237049"], ["84006.2", "0"], ["83981.8", "0"], ["83981.7", "0"]], "a": [["84079.7", "0.231423"], ["84085.5", "0"], ["84090.8", "0.540353"], ["84100.4", "0"], ["84100.5", "0.000333"], ["84101.1", "0.622019"], ["84101.2", "0.207634"], ["84101.3", "0.009"], ["84101.4", "0"], ["84102", "0.04"], ["84102.1", "0.04"], ["84110.7", "2.257032"], ["84113.5", "0"], ["84136.7", "1.123173"]], "u": 20710, "seq": 67549989825}, "cts": 1742555355715, "record_time": 1742555355.740734, "EXCHANGE": "BYBIT"}
{"topic": "orderbook.200.BTCUSDT", "ts": 1742555355919, "type": "delta", "data": {"s": "BTCUSDT", "b": [["84061.9", "0.265269"], ["84047.3", "0.056422"], ["84040.3", "0.057439"], ["84033.3", "0.109834"], ["84023.5", "0"], ["84023.3", "0.014347"], ["83982.2", "0"]], "a": [["84082.3", "0.101291"], ["84089.3", "0.061027"], ["84096.3", "0.122619"], ["84101.1", "0.609174"], ["84101.2", "0.194789"], ["84101.4", "0.012845"], ["84101.5", "0.012845"], ["84102", "0"], ["84102.1", "0"], ["84102.3", "0.04"], ["84102.4", "0.04"], ["84110.7", "0"], ["84134.3", "0"], ["84136.7", "0"]], "u": 20711, "seq": 67549989848}, "cts": 1742555355878, "record_time": 1742555355.940422, "EXCHANGE": "BYBIT"}
{"topic": "orderbook.200.BTCUSDT", "ts": 1742555356119, "type": "delta", "data": {"s": "BTCUSDT", "b": [], "a": [["84087.9", "0.004373"], ["84110.7", "2.257032"], ["84134.2", "0"]], "u": 20712, "seq": 67549989856}, "cts": 1742555356002, "record_time": 1742555356.139383, "EXCHANGE": "BYBIT"}
{"topic": "orderbook.200.BTCUSDT", "ts": 1742555356320, "type": "delta", "data": {"s": "BTCUSDT", "b": [["84036.6", "0.086383"], ["84010.5", "4.571494"], ["83982.5", "0"]], "a": [["84087.9", "0.003433"], ["84094.2", "0.053869"], ["84110.7", "0"], ["84113.5", "2.257032"]], "u": 20713, "seq": 67549989874}, "cts": 1742555356295, "record_time": 1742555356.340931, "EXCHANGE": "BYBIT"}
{"topic": "orderbook.200.BTCUSDT", "ts": 1742555356520, "type": "delta", "data": {"s": "BTCUSDT", "b": [["84023.6", "0.013"], ["84023.5", "0.012881"], ["84023.4", "0"], ["84023.3", "0.001466"], ["83982.9", "0"]], "a": [["84101", "0.072399"], ["84101.1", "0.622019"], ["84101.4", "0"], ["84101.5", "0"], ["84101.9", "0.041466"], ["84102", "0.04"], ["84102.3", "0"], ["84102.4", "0"], ["84134.2", "0.000423"], ["84134.3", "0.001466"], ["84136.7", "1.123173"]], "u": 20714, "seq": 67549989889}, "cts": 1742555356496, "record_time": 1742555356.541675, "EXCHANGE": "BYBIT"}
{"topic": "orderbook.200.BTCUSDT", "ts": 1742555356719, "type": "delta", "data": {"s": "BTCUSDT", "b": [["84033.6", "0.118804"], ["84023.6", "0"], ["84023.5", "0"], ["84023.4", "0.013"], ["84023.3", "0.014347"]], "a": [["84101", "0.059399"], ["84101.1", "0.609174"], ["84101.4", "0.013"], ["84101.5", "0.012845"], ["84101.9", "0.001466"], ["84102", "0"], ["84102.3", "0.04"], ["84102.4", "0.04"], ["84134.2", "0"], ["84134.3", "0"], ["84136.7", "0"]], "u": 20715, "seq": 67549989910}, "cts": 1742555356675, "record_time": 1742555356.740088, "EXCHANGE": "BYBIT"}
{"topic": "orderbook.200.BTCUSDT", "ts": 1742555356919, "type": "delta", "data": {"s": "BTCUSDT", "b": [["84023.4", "0.012881"]], "a": [["84101.4", "0.012845"], ["84102.2", "0.04"], ["84102.4", "0"], ["84113.4", "2.257032"], ["84113.5", "0"]], "u": 20716, "seq": 67549989925}, "cts": 1742555356906, "record_time": 1742555356.939809, "EXCHANGE": "BYBIT"}
{"topic": "orderbook.200.BTCUSDT", "ts": 1742555357120, "type": "delta", "data": {"s": "BTCUSDT", "b": [["84047.3", "0.05761"], ["84040.3", "0.055017"], ["84033.3", "0.117211"], ["84023.5", "0.013"], ["84023.3", "0.001466"], ["83983.2", "0"]], "a": [["84082.3", "0.099016"], ["84089.3", "0.061082"], ["84096.3", "0.114204"], ["84101.1", "0.622174"], ["84101.2", "0.207634"], ["84101.4", "0"], ["84101.5", "0"], ["84102", "0.04"], ["84102.1", "0.04"], ["84102.2", "0"], ["84102.3", "0"], ["84113.4", "0"], ["84113.5", "2.257032"], ["84134.2", "0.000423"], ["84134.3", "0.001466"]], "u": 20717, "seq": 67549989956}, "cts": 1742555357045, "record_time": 1742555357.140668, "EXCHANGE": "BYBIT"}
{"topic": "orderbook.200.BTCUSDT", "ts": 1742555357320, "type": "delta", "data": {"s": "BTCUSDT", "b": [["84022.8", "0.041082"], ["83984", "0"]], "a": [["84113.4", "2.257032"], ["84113.5", "0"]], "u": 20718, "seq": 67549989965}, "cts": 1742555357277, "record_time": 1742555357.344996, "EXCHANGE": "BYBIT"}
{"topic": "orderbook.200.BTCUSDT", "ts": 1742555357519, "type": "delta", "data": {"s": "BTCUSDT", "b": [["84061.9", "0.265639"], ["84057.8", "0.001333"], ["84047.3", "0"], ["84040.3", "0"], ["84033.3", "0.000333"], ["83984", "0.04"]], "a": [["84062", "0.058438"], ["84082.3", "0.04"], ["84089.3", "0"], ["84096.3", "0.000333"], ["84136.7", "1.123173"]], "u": 20719, "seq": 67549989978}, "cts": 1742555357511, "record_time": 1742555357.541059, "EXCHANGE": "BYBIT"}
{"topic": "orderbook.200.BTCUSDT", "ts": 1742555357719, "type": "delta", "data": {"s": "BTCUSDT", "b": [], "a": [["84094.2", "0.019638"]], "u": 20720, "seq": 67549989988}, "cts": 1742555357677, "record_time": 1742555357.739681, "EXCHANGE": "BYBIT"}
{"topic": "orderbook.200.BTCUSDT", "ts": 1742555357919, "type": "delta", "data": {"s": "BTCUSDT", "b": [["84061.9", "0.405954"], ["84057.3", "0.084029"], ["84057.2", "0.089099"], ["84055", "0"], ["84054.9", "0.000516"], ["84045.8", "0"], ["84044.1", "0.260099"], ["84043.4", "0.0885"], ["84032.7", "0.024855"], ["84030.1", "0.241751"], ["84027", "0"], ["84023.5", "0"], ["84023.4", "0"], ["84022.9", "0.013"], ["84022.8", "0.053963"], ["84011.8", "14.109492"], ["84009", "0"], ["83985.3", "0"]], "a": [["84062", "0.036157"], ["84067.5", "0"], ["84072.3", "0"], ["84072.4", "0.101127"], ["84072.6", "0"], ["84074.8", "0"], ["84079.7", "0.112619"], ["84089.3", "0.11896"], ["84101.1", "0.609174"], ["84101.2", "0.194789"], ["84102", "0"], ["84102.1", "0"], ["84103.9", "0.012847"], ["84104", "0.01418"], ["84104.8", "0.158804"], ["84104.9", "0.04"], ["84111.3", "0"], ["84113.4", "0"], ["84116.9", "0.142639"], ["84119.2", "2.257032"], ["84136.7", "0"], ["84137.1", "0.4"], ["84137.2", "0.029723"], ["84137.3", "0.003211"], ["84137.4", "0.013073"], ["84137.7", "0.001333"]], "u": 20721, "seq": 67549990088}, "cts": 1742555357917, "record_time": 1742555357.939853, "EXCHANGE": "BYBIT"}
{"topic": "orderbook.200.BTCUSDT", "ts": 1742555358120, "type": "delta", "data": {"s": "BTCUSDT", "b": [["84063.4", "0.077636"], ["84062.6", "0.328563"], ["84061.9", "0.313923"], ["84058.5", "0.000333"], ["84057.6", "0.0025"], ["84057.4", "0.003896"], ["84056.9", "0.009194"], ["84054.7", "0"], ["84054.2", "0.01"], ["84054", "0.047174"], ["84053.9", "0"], ["84053.6", "0.001423"], ["84053.5", "0.005"], ["84051.8", "0"], ["84050.5", "0"], ["84047.2", "0"], ["84046.1", "0.200347"], ["84045.2", "0.001423"], ["84044.7", "0"], ["84038", "0.003576"], ["84030.2", "0.000083"], ["84011.8", "0"], ["84010.5", "0.327005"], ["84009", "14.109492"], ["83984.4", "0"], ["83984", "0"]], "a": [["84062", "0"], ["84062.1", "0"], ["84062.7", "0"], ["84063.5", "0.000814"], ["84067", "0"], ["84067.7", "0.0025"], ["84070.4", "0.006333"], ["84071.1", "0.010333"], ["84072.3", "0.059399"], ["84072.5", "0"], ["84074.2", "0.001466"], ["84076.2", "0.0006"], ["84076.9", "0.067371"], ["84078", "0.000516"], ["84084", "0.052043"], ["84086", "0"], ["84092.6", "0.03725"], ["84099.6", "0"], ["84103.9", "0"], ["84104", "0.001333"], ["84104.8", "0.118804"], ["84104.9", "0"], ["84105.8", "0.013"], ["84105.9", "0.012847"], ["84106.7", "0.04"], ["84106.8", "0.04"], ["84119.2", "0"], ["84122", "2.257032"], ["84137.8", "0.04"]], "u": 20722, "seq": 67549990288}, "cts": 1742555358117, "record_time": 1742555358.140531, "EXCHANGE": "BYBIT"}
{"topic": "orderbook.200.BTCUSDT", "ts": 1742555358319, "type": "delta", "data": {"s": "BTCUSDT", "b": [["84064", "0.149676"], ["84063.4", "0.52102"], ["84062.6", "0.171"], ["84061.9", "0.142923"], ["84058.4", "0.0025"], ["84057.6", "0"], ["84055.3", "0.04"], ["84054.2", "0.015"], ["84054", "0.023883"], ["84053.5", "0"], ["84051", "0.001466"], ["84020.3", "0.234343"], ["84017.5", "14.109492"], ["84010.5", "4.533227"], ["84009", "0"], ["83984.6", "0"]], "a": [["84063.5", "0"], ["84067.6", "0"], ["84067.7", "0"], ["84068.5", "0.0025"], ["84070.4", "0.001333"], ["84071.1", "0.005333"], ["84071.4", "0"], ["84071.7", "0"], ["84071.8", "0"], ["84071.9", "0.01"], ["84072.2", "0.000297"], ["84072.4", "0"], ["84074.9", "0.000297"], ["84080.4", "0"], ["84086.7", "0"], ["84088.3", "0.000099"], ["84091.2", "0.178437"], ["84092.5", "0.031253"], ["84094.2", "0"], ["84095.4", "0.178437"], ["84097.4", "0.057349"], ["84103.1", "0"], ["84105.8", "0"], ["84105.9", "0"], ["84106.3", "0.366266"], ["84106.4", "0.101946"], ["84106.7", "0"], ["84106.8", "0.063432"], ["84107.2", "0.04"], ["84107.3", "0.04"], ["84119.1", "2.257083"], ["84122", "0"], ["84137.9", "0.044"], ["84138.1", "0.000518"], ["84138.4", "0.000333"], ["84138.9", "0.001466"]], "u": 20723, "seq": 67549990471}, "cts": 1742555358317, "record_time": 1742555358.340293, "EXCHANGE": "BYBIT"}
{"topic": "orderbook.200.BTCUSDT", "ts": 1742555358520, "type": "delta", "data": {"s": "BTCUSDT", "b": [["84064", "0.425913"], ["84063.5", "0.152508"], ["84063.4", "0.361358"], ["84063.1", "0.000531"], ["84062.6", "0"], ["84059", "0.0025"], ["84058.4", "0"], ["84057.3", "0.119229"], ["84056.5", "0.116036"], ["84056.2", "0.116126"], ["84055.4", "0.048"], ["84054", "0"], ["84053.8", "0.064683"], ["84053.7", "0.056"], ["84053.6", "0.041423"], ["84052.4", "0.120389"], ["84052.1", "0.04"], ["84049.4", "0.001569"], ["84048.5", "0.04"], ["84047.7", "0.04"], ["84046.4", "0.188565"], ["84046", "0.254361"], ["84045.4", "0.174699"], ["84044.7", "0.006006"], ["84044.3", "0"], ["84039", "0.295603"], ["84038.4", "0.350241"], ["84037.3", "0.280107"], ["84010.5", "0.327005"], ["83990.2", "0"], ["83989.4", "0"], ["83988.2", "0"], ["83987.3", "0"], ["83987.2", "0"], ["83987.1", "0"], ["83986.6", "0"], ["83986.4", "0"], ["83986.3", "0"], ["83986", "0"], ["83985.6", "0"]], "a": [["84064.1", "0.009489"], ["84068.5", "0"], ["84069.1", "0.0025"], ["84071.1", "0.000333"], ["84071.9", "0.005"], ["84072.5", "0.01"], ["84074.1", "0.000153"], ["84075.7", "0.006026"], ["84081", "0.120075"], ["84081.4", "0.123908"], ["84085.3", "0.10919"], ["84088.3", "0"], ["84091.2", "0.165035"], ["84091.5", "0.185407"], ["84092.3", "0.181943"], ["84098.5", "0.328617"], ["84099.3", "0.294665"], ["84099.6", "0.178435"], ["84100.3", "0.333067"], ["84101.1", "0.09207"], ["84106.3", "0.353419"], ["84106.4", "0.089099"], ["84106.6", "0.012847"], ["84106.7", "0.012847"], ["84107.2", "0"], ["84107.3", "0"], ["84107.5", "0.04"], ["84107.6", "0.04"], ["84134.3", "0"], ["84137.1", "0"], ["84137.2", "0"], ["84137.3", "0"], ["84137.4", "0"], ["84137.7", "0"], ["84137.8", "0"], ["84137.9", "0"], ["84138.1", "0"], ["84138.4", "0"], ["84138.9", "0"]], "u": 20724, "seq": 67549990610}, "cts": 1742555358515, "record_time": 1742555358.54082, "EXCHANGE": "BYBIT"}
{"topic": "orderbook.200.BTCUSDT", "ts": 1742555358720, "type": "delta", "data": {"s": "BTCUSDT", "b": [["84064", "0.351069"], ["84063.4", "0.364358"], ["84061.4", "0.003"], ["84056.5", "0"], ["84056.2", "0.117493"], ["84053.8", "0.043629"], ["84052.4", "0"], ["84051.2", "0"], ["84050.4", "0.044"], ["84050.3", "0.041943"], ["84050.2", "0.040516"], ["84049.5", "0"], ["84046.4", "0.166971"], ["84046", "0"], ["84045.4", "0"], ["84043.2", "0.004695"], ["84039.1", "0.353255"], ["84039", "0"], ["84038.4", "0.059399"], ["84038.2", "0"], ["84038", "0"], ["84037.3", "0.305129"], ["84018.9", "0.04"], ["83990.2", "0.003697"], ["83989.4", "0.195"], ["83988.2", "0.118804"], ["83987.3", "0.04"]], "a": [["84071.9", "0"], ["84072.5", "0.015"], ["84081", "0"], ["84081.4", "0.110685"], ["84085.3", "0"], ["84086.9", "0.003234"], ["84088.6", "0.000099"], ["84090", "0.178435"], ["84090.7", "0.349782"], ["84091.2", "0.182985"], ["84091.5", "0"], ["84092.3", "0"], ["84095.4", "0"], ["84098.5", "0.023789"], ["84099.3", "0"], ["84099.6", "0"], ["84100.3", "0.330305"], ["84106.6", "0"], ["84106.7", "0"], ["84107.4", "0.013"], ["84107.5", "0.012847"], ["84107.6", "0"], ["84108.3", "0.04"], ["84108.4", "0.04"], ["84119.1", "2.257034"], ["84134.3", "0.001466"], ["84137.1", "0.4"], ["84137.2", "0.029723"], ["84137.3", "0.003211"], ["84137.4", "0.013073"], ["84137.7", "0.001333"]], "u": 20725, "seq": 67549990713}, "cts": 1742555358708, "record_time": 1742555358.743621, "EXCHANGE": "BYBIT"}
{"topic": "orderbook.200.BTCUSDT", "ts": 1742555358920, "type": "delta", "data": {"s": "BTCUSDT", "b": [["84056.2", "0"], ["84055.6", "0.01"], ["84054.2", "0.005"], ["84051.2", "0.003575"], ["84050.3", "0.087294"], ["84046.4", "0.001466"], ["84046.1", "0.124062"], ["84039.1", "0"], ["84037.3", "0"], ["84022.2", "0.048"], ["84017.2", "0.044"], ["83987.3", "0"]], "a": [["84064.1", "0.021489"], ["84081.2", "0.009489"], ["84081.4", "0"], ["84084.8", "0.064751"], ["84091.2", "0"], ["84100.3", "0.024389"], ["84137.8", "0.04"]], "u": 20726, "seq": 67549990771}, "cts": 1742555358906, "record_time": 1742555358.941246, "EXCHANGE": "BYBIT"}
{"topic": "orderbook.200.BTCUSDT", "ts": 1742555359119, "type": "delta", "data": {"s": "BTCUSDT", "b": [["84055.6", "0.015"], ["84054.2", "0"], ["84050.3", "0.041943"], ["84001.4", "0.235392"], ["83996", "0"], ["83987.3", "0.04"]], "a": [["84072.2", "0"], ["84072.3", "0"], ["84074.1", "0"], ["84074.8", "0.000297"], ["84074.9", "0.078124"], ["84090.7", "0.217219"], ["84137.9", "0.044"], ["84138.1", "0.000518"]], "u": 20727, "seq": 67549990798}, "cts": 1742555359109, "record_time": 1742555359.139908, "EXCHANGE": "BYBIT"}
{"topic": "orderbook.200.BTCUSDT", "ts": 1742555359320, "type": "delta", "data": {"s": "BTCUSDT", "b": [["84064.8", "0.386731"], ["84064.1", "0.089689"], ["84064", "0.190358"], ["84063.5", "0.0006"], ["84063.4", "0.174"], ["84061.9", "0.00157"], ["84059.8", "0.0025"], ["84059.5", "0.000516"], ["84059", "0"], ["84053.8", "0.075369"], ["84053.4", "0.04"], ["84052.5", "0"], ["84052.4", "0.001753"], ["84051.2", "0"], ["84050.3", "0.066955"], ["84050.2", "0.141367"], ["84043.2", "0.062317"], ["84036.2", "0.124457"], ["84020.3", "4.462553"], ["84017.5", "0"], ["84006.2", "13.960352"], ["84002.8", "0.003181"], ["83990.2", "0"], ["83989.4", "0"], ["83988.2", "0"], ["83987.3", "0"]], "a": [["84064.1", "0"], ["84064.9", "0.134439"], ["84069.1", "0"], ["84069.9", "0.0025"], ["84072.5", "0"], ["84073.3", "0.015"], ["84073.7", "0.000153"], ["84074.9", "0.051724"], ["84075", "0"], ["84075.2", "0"], ["84075.6", "0.071432"], ["84076.6", "0"], ["84076.9", "0"], ["84079.8", "0.219779"], ["84080", "0.04824"], ["84080.1", "0"], ["84080.6", "0.0119"], ["84081.2", "0"], ["84081.6", "0.04"], ["84083.3", "0.005942"], ["84085.1", "0.052"], ["84085.2", "0.061352"], ["84086.7", "0.178387"], ["84090", "0"], ["84092.2", "0.061512"], ["84099.2", "0.118181"], ["84106.8", "0"], ["84107.4", "0"], ["84107.5", "0"], ["84108.2", "0.014333"], ["84108.3", "0.012847"], ["84108.4", "0"], ["84109.1", "0.04"], ["84109.2", "0.04"], ["84109.7", "0.063438"], ["84138.4", "0.000333"]], "u": 20728, "seq": 67549991086}, "cts": 1742555359306, "record_time": 1742555359.340716, "EXCHANGE": "BYBIT"}
{"topic": "orderbook.200.BTCUSDT", "ts": 1742555359519, "type": "delta", "data": {"s": "BTCUSDT", "b": [["84064", "0.191677"], ["84060.6", "0.0036"], ["84055.2", "0"], ["84047.7", "0"], ["84044.4", "0"], ["84042.3", "0.003575"], ["84035.6", "0.171"], ["84031.9", "0.487506"], ["84026.5", "0.0045"], ["84020.3", "0.234343"], ["84009", "13.960352"], ["84006.2", "0"], ["83990.2", "0.003697"]], "a": [["84079.9", "0.04"], ["84080.6", "0"], ["84084.8", "0.144179"], ["84086.6", "0.118804"], ["84088.6", "0"], ["84110.1", "0.150604"], ["84138.4", "0"]], "u": 20729, "seq": 67549991143}, "cts": 1742555359507, "record_time": 1742555359.53992, "EXCHANGE": "BYBIT"}
{"topic": "orderbook.200.BTCUSDT", "ts": 1742555359720, "type": "delta", "data": {"s": "BTCUSDT", "b": [["84056.4", "0.01"], ["84055.6", "0.005"], ["84032", "0.013"], ["84031.9", "0.500386"], ["84022.9", "0"], ["84022.8", "0.041082"], ["84020.3", "14.194695"], ["84009", "0"], ["83990.9", "1.125122"], ["83990.2", "0"]], "a": [["84089", "0.000099"], ["84138.1", "0"]], "u": 20730, "seq": 67549991161}, "cts": 1742555359702, "record_time": 1742555359.740771, "EXCHANGE": "BYBIT"}
{"topic": "orderbook.200.BTCUSDT", "ts": 1742555359920, "type": "delta", "data": {"s": "BTCUSDT", "b": [["84056.9", "0.061698"]], "a": [], "u": 20731, "seq": 67549991175}, "cts": 1742555359916, "record_time": 1742555359.941208, "EXCHANGE": "BYBIT"}
{"success": true, "ret_msg": "subscribe", "conn_id": "d59011eb-c49f-46ad-9bdd-f698ff66c36b", "op": "subscribe", "record_time": 1742556561.61106, "EXCHANGE": "BYBIT"}
