{"topic": "orderbook.200.BTCUSDT", "ts": 1742569768520, "type": "delta", "data": {"s": "BTCUSDT", "b": [["84053", "0"], ["84046.3", "0"], ["84046.2", "0"], ["84045.8", "0"], ["84045.7", "0.0204"], ["84045.6", "0"], ["84045.5", "0"], ["84044.7", "0.003649"], ["84044.6", "0"], ["84044", "0"], ["84043.9", "0"], ["84043.8", "0"], ["84042.7", "0"], ["84042.2", "0"], ["84042", "0"], ["84040.8", "0"], ["84040.6", "0"], ["84040.5", "0.003663"], ["84038.9", "0"], ["84038.8", "0"], ["84037.2", "0.171"], ["84037.1", "0.001466"], ["84036.8", "0"], ["84036.7", "0.016333"], ["84036.5", "0.005335"], ["84033.4", "0.004635"], ["84032", "0"], ["84030.3", "0.021431"], ["84029.7", "0.044"], ["84029.6", "0"], ["84029.5", "0.071437"], ["84028.7", "0.056075"], ["84028.3", "0.001333"], ["84028", "0"], ["84027.4", "0"], ["84026", "0.000361"], ["84024", "0.089303"], ["84023.1", "0.052"], ["84020.9", "0.220123"], ["84019.3", "0"], ["84019.2", "0"], ["84017.5", "0"], ["84017.4", "0"], ["84017.2", "0.51707"], ["84016.6", "0"], ["84015.3", "0.04106"], ["84013.9", "0"], ["84013.8", "0"], ["84012.2", "0.000333"], ["84011.2", "0.015"], ["84010.2", "0"], ["84009.6", "0.04"], ["84009.5", "0.039634"], ["84008", "0.000333"], ["84007.8", "0.013"], ["84007.7", "0.012881"], ["84004.2", "0.05"], ["84004.1", "0.049549"], ["84002", "0.044"], ["83998", "0"], ["83997", "0"], ["83996.8", "0.004596"], ["83993.8", "0.134766"], ["83991", "0.096077"], ["83989.7", "0.171"], ["83977", "0.001466"], ["83975.3", "0"], ["83974", "0"], ["83973.1", "0"], ["83972.7", "0.172774"], ["83972.1", "0.045026"], ["83970.1", "0"], ["83969.6", "0.025482"], ["83969.1", "3.754103"], ["83968.1", "0.044004"], ["83967.8", "0.001466"], ["83967.3", "0.118852"], ["83967", "0.00052"], ["83966.9", "0.01002"], ["83966.4", "0.00018"], ["83966.1", "0.104175"], ["83966", "0.059732"], ["83965.3", "0.001333"], ["83964.9", "0.003552"], ["83963.8", "0.124931"], ["83963.1", "0.001466"], ["83962.4", "0.00052"], ["83962.2", "0.048"], ["83961.8", "0.000333"], ["83961.5", "0.002201"], ["83961.2", "0.015"], ["83961.1", "0.001333"]], "a": [["84045.8", "0.642787"], ["84046.3", "0.139808"], ["84046.4", "0.311476"], ["84046.5", "0.055693"], ["84047", "0.098009"], ["84050", "0.000333"], ["84050.1", "0.000516"], ["84050.9", "0.001466"], ["84051.4", "0.071419"], ["84052.9", "0.187483"], ["84053", "0.06402"], ["84053.1", "0.322666"], ["84053.3", "0.042625"], ["84053.6", "0"], ["84054.2", "0.031683"], ["84054.7", "0.009377"], ["84054.8", "0.015516"], ["84055", "0.016005"], ["84056", "0.00009"], ["84060.1", "0.037142"], ["84060.6", "0"], ["84061.3", "0.018568"], ["84061.5", "0"], ["84062.3", "0"], ["84062.6", "0.040333"], ["84063.2", "0.229723"], ["84063.3", "0.183126"], ["84063.8", "0.023796"], ["84063.9", "0.0006"], ["84064.1", "0"], ["84064.6", "0.179034"], ["84064.7", "0.023796"], ["84065.4", "0.059399"], ["84066.2", "0.0006"], ["84067.7", "0.023796"], ["84068.5", "0"], ["84068.6", "0.024312"], ["84069", "0"], ["84069.4", "0.025262"], ["84072.2", "0.18435"], ["84072.9", "0.003575"], ["84073.7", "0"], ["84074", "0"], ["84074.9", "0.005949"], ["84075.3", "0.118852"], ["84075.6", "0"], ["84075.9", "0.116702"], ["84076", "0"], ["84076.1", "0.011905"], ["84077.5", "0"], ["84077.9", "0.000516"], ["84080.2", "0"], ["84082.6", "0.122522"], ["84086.7", "0.328302"], ["84087.4", "1.426959"], ["84092.7", "0"], ["84095", "0.000118"], ["84095.3", "0"], ["84095.4", "0"], ["84096.8", "0.105148"], ["84097.8", "0.00015"], ["84104", "0.063883"], ["84108.7", "0"], ["84108.9", "0.000333"], ["84118.2", "0"], ["84119.5", "0"], ["84120.3", "0"], ["84120.4", "0"], ["84120.8", "0"], ["84121.1", "0"], ["84121.5", "0"], ["84122.2", "0"], ["84123.2", "0"], ["84123.4", "0"]], "u": 92368, "seq": 67563894297}, "cts": 1742569768517, "record_time": 1742569768.788426, "EXCHANGE": "BYBIT"}
{"topic": "orderbook.200.BTCUSDT", "ts": 1742569768719, "type": "delta", "data": {"s": "BTCUSDT", "b": [["84045.7", "0.072396"], ["84037.3", "0.074515"], ["84036.7", "0.001333"], ["84033.4", "0.0006"], ["84031.5", "0.034631"], ["84031.4", "0.071436"], ["84030.3", "0"], ["84029.5", "0"], ["84028.7", "0"], ["84028.1", "0.052737"], ["84028", "0.084"], ["84026.3", "0.04"], ["84026.2", "0.044"], ["84024.5", "0.04"], ["84024", "0.148889"], ["84023.9", "0.175035"], ["84022.9", "0.048"], ["84021.8", "0.019443"], ["84021.1", "0.116387"], ["84017.8", "0.045699"], ["84012.9", "0.178474"], ["84012.5", "0.178474"], ["84009.6", "0"], ["84009.4", "0.039634"], ["84008.7", "0.178474"], ["84007.8", "0"], ["84007.6", "0.012881"], ["84007.4", "0"], ["84005.8", "0"], ["84004.2", "0"], ["84004", "0.049549"], ["84002.4", "0"], ["83993.8", "0.230857"], ["83991.9", "0.089237"], ["83991", "0"], ["83972.1", "0"], ["83968.1", "0"], ["83966.3", "0.045026"], ["83966.1", "0.059518"], ["83964.6", "0.044245"], ["83963.8", "0"], ["83963.1", "0"], ["83962.4", "0"], ["83962.2", "0"], ["83961.8", "0"], ["83961.5", "0"], ["83961.2", "0"], ["83961.1", "0"]], "a": [["84045.8", "0.687409"], ["84046.3", "0.098751"], ["84054.1", "0.003576"], ["84054.7", "0.116774"], ["84056.4", "0.04"], ["84056.5", "0.04"], ["84056.8", "0.022986"], ["84057.9", "0.233042"], ["84058.2", "0.04"], ["84059", "0.102839"], ["84059.1", "0.218474"], ["84060.1", "0"], ["84063.3", "0.540074"], ["84064.2", "0.04"], ["84066.6", "0.17843"], ["84067.4", "0.231"], ["84069.1", "0"], ["84072.2", "0"], ["84074.1", "0.001466"], ["84075.9", "0"], ["84076", "0.089237"], ["84076.2", "0.013977"], ["84092.7", "0.063524"], ["84094.9", "0"], ["84104", "0.000361"], ["84105.3", "0.109865"], ["84110.9", "0"], ["84115.8", "0"], ["84116.2", "0"], ["84116.5", "0"], ["84116.6", "0"], ["84117.3", "0"], ["84117.4", "0"], ["84118", "0"], ["84119.1", "0"]], "u": 92369, "seq": 67563894455}, "cts": 1742569768717, "record_time": 1742569768.98782, "EXCHANGE": "BYBIT"}
{"topic": "orderbook.200.BTCUSDT", "ts": 1742569768920, "type": "delta", "data": {"s": "BTCUSDT", "b": [["84045.7", "0"], ["84045.1", "0.024407"], ["84040.3", "0.071428"], ["84037.3", "0.059515"], ["84036.7", "0.016333"], ["84029.7", "0.084"], ["84029.3", "0.091973"], ["84029", "0.071771"], ["84028.1", "0"], ["84025.4", "0.123534"], ["84024.6", "0.0425"], ["84018.4", "0.183432"], ["84017.9", "0.116997"], ["84017.8", "0.009996"], ["84012.6", "0.173582"], ["84011.4", "0.277315"], ["84005.8", "0.124933"], ["84005.1", "0"], ["84002.2", "0.024223"], ["84002", "0"], ["83996.6", "0.09606"], ["83993.8", "0.134766"], ["83966.3", "0"], ["83966.1", "0"], ["83966", "0"], ["83965.3", "0"], ["83964.9", "0"], ["83964.6", "0"]], "a": [["84045.2", "0.345356"], ["84045.6", "0.241729"], ["84045.8", "0.457153"], ["84046.1", "0.00796"], ["84046.3", "0"], ["84046.4", "0.140476"], ["84052.8", "0.015"], ["84054.1", "0"], ["84054.6", "0.171521"], ["84054.7", "0.049377"], ["84054.8", "0.055516"], ["84058.3", "0.123037"], ["84059.9", "0.04"], ["84061.6", "0.043669"], ["84063.2", "0.318615"], ["84065.3", "0.169708"], ["84065.7", "0"], ["84066.7", "0.124932"], ["84067.4", "0.191"], ["84068.9", "0.124933"], ["84069.2", "0"], ["84070.8", "0"], ["84070.9", "0"], ["84072.3", "0.332832"], ["84075.7", "0.063524"], ["84084.6", "0.781877"], ["84086.3", "0.046966"], ["84087.1", "1.428808"], ["84087.3", "0"], ["84087.4", "0"], ["84092.7", "0"], ["84101.7", "0.028152"], ["84114.9", "0"], ["84115.7", "0"]], "u": 92370, "seq": 67563894696}, "cts": 1742569768912, "record_time": 1742569769.195234, "EXCHANGE": "BYBIT"}
{"topic": "orderbook.200.BTCUSDT", "ts": 1742569769119, "type": "delta", "data": {"s": "BTCUSDT", "b": [["84045.1", "0.015659"], ["84037.2", "0.174"], ["84025.4", "0"], ["84024.7", "0.001774"], ["84018.4", "0"], ["84017.9", "0.141404"], ["84011.4", "0"], ["84004.4", "0.05"], ["84004.3", "0.049548"], ["84004.1", "0"], ["84004", "0"], ["83998.2", "0.478506"], ["83981.8", "0.014118"], ["83972.7", "0.171"], ["83969.6", "0"], ["83967.3", "0.121852"], ["83966.2", "0.002082"], ["83966.1", "0.059518"], ["83966", "0.059732"]], "a": [["84045.6", "0.157642"], ["84045.8", "0.221153"], ["84049.3", "0.001333"], ["84054.9", "0.003576"], ["84058.3", "0"], ["84059.5", "0.04"], ["84064.2", "0"], ["84065.3", "0"], ["84066.1", "0.002325"], ["84072.3", "0"], ["84091.8", "0.046466"], ["84104.6", "0.059732"], ["84114.9", "0.000518"]], "u": 92371, "seq": 67563894784}, "cts": 1742569769104, "record_time": 1742569769.387631, "EXCHANGE": "BYBIT"}
{"topic": "orderbook.200.BTCUSDT", "ts": 1742569769320, "type": "delta", "data": {"s": "BTCUSDT", "b": [["84043.1", "0.071426"], ["84040.3", "0"], ["84031.5", "0.076935"], ["84029.7", "0.199445"], ["84029", "0.000333"], ["84019.2", "0.186138"], ["84016.5", "1.383513"], ["84012.2", "0.289211"], ["84004.5", "0.05"], ["84004.4", "0.049548"], ["84004.3", "0"], ["83996.6", "0.096061"], ["83966.1", "0"], ["83966", "0"]], "a": [["84045.8", "0.221"], ["84046.1", "0"], ["84052.4", "0.015"], ["84052.5", "0.003576"], ["84052.8", "0"], ["84053.6", "0.015"], ["84054.2", "0.145351"], ["84054.8", "0.040516"], ["84054.9", "0"], ["84064.7", "0.205825"], ["84071.7", "0.279244"], ["84095", "0.040118"], ["84114.9", "0"]], "u": 92372, "seq": 67563894852}, "cts": 1742569769316, "record_time": 1742569769.588936, "EXCHANGE": "BYBIT"}
{"topic": "orderbook.200.BTCUSDT", "ts": 1742569769519, "type": "delta", "data": {"s": "BTCUSDT", "b": [["84045.1", "0.017059"], ["84035.8", "0.0017"], ["84031.5", "0.034631"], ["84029.7", "0.084"], ["84022.6", "0"], ["84019.2", "0"], ["84012.2", "0.000333"], ["84006.7", "0.1726"], ["84004.5", "0"], ["84004.3", "0.049548"], ["83966.1", "0.059518"]], "a": [["84045.2", "0.345509"], ["84054.2", "0.031683"], ["84064.7", "0.023796"], ["84071.7", "0"], ["84079.9", "0"], ["84114.9", "0.000518"], ["84115.7", "0.001466"]], "u": 92373, "seq": 67563894915}, "cts": 1742569769512, "record_time": 1742569769.788212, "EXCHANGE": "BYBIT"}
{"topic": "orderbook.200.BTCUSDT", "ts": 1742569769719, "type": "delta", "data": {"s": "BTCUSDT", "b": [["84045.1", "0.041197"], ["84043.1", "0"], ["84030.2", "0.008182"], ["84029.4", "0.118852"], ["84009.9", "0.039633"], ["84009.8", "0.039633"], ["84009.5", "0"], ["84009.4", "0"], ["84008.1", "0.024785"], ["84008", "0.013214"], ["84007.7", "0"], ["84007.6", "0"], ["84004.5", "0.049547"], ["84004.3", "0"], ["83966", "0.059732"]], "a": [["84045.2", "0.154656"], ["84045.6", "0.106294"], ["84045.8", "0.02"], ["84052.5", "0"], ["84067.9", "0.035704"], ["84079.5", "0.003434"], ["84081.2", "0.04009"], ["84081.3", "0.04"], ["84094.5", "0"], ["84098.4", "0"], ["84098.5", "0.023787"]], "u": 92374, "seq": 67563894972}, "cts": 1742569769715, "record_time": 1742569769.988048, "EXCHANGE": "BYBIT"}
{"topic": "orderbook.200.BTCUSDT", "ts": 1742569769919, "type": "delta", "data": {"s": "BTCUSDT", "b": [["84045.1", "0.289497"], ["84037.6", "0.103884"], ["84037.5", "0.07143"], ["84037.3", "0"], ["84035.5", "0.071432"], ["84031.5", "0"], ["84031.4", "0"], ["84029.8", "0.060856"], ["84017.9", "0.024407"], ["84012.5", "0"], ["84009.9", "0"], ["84009.8", "0"], ["84009.5", "0.039633"], ["84009.4", "0.039633"], ["84008.1", "0.011904"], ["84008", "0.000333"], ["84007.7", "0.012881"], ["84007.6", "0.012881"], ["84004.5", "0"], ["84004.4", "0"], ["84004.1", "0.049548"], ["84004", "0.049548"], ["83982.6", "0.117014"], ["83966.2", "0"], ["83966.1", "0"], ["83966", "0"]], "a": [["84045.6", "0.029363"], ["84046.4", "0.02"], ["84047", "0"], ["84052.4", "0"], ["84052.9", "0.136255"], ["84053.1", "0.194657"], ["84054.6", "0.093103"], ["84057.9", "0.054568"], ["84059.1", "0.04"], ["84063.3", "0.004689"], ["84064.6", "0.0006"], ["84066.6", "0"], ["84066.7", "0"], ["84068.9", "0"], ["84075.3", "0"], ["84075.7", "0"], ["84076", "0"], ["84079.5", "0"], ["84080.7", "0.027226"], ["84081.2", "0.00009"], ["84081.3", "0"], ["84081.4", "0.063524"], ["84082.4", "0.04"], ["84082.5", "0.040516"], ["84089.9", "0"], ["84093.6", "0.04"], ["84097", "0"], ["84108.7", "0.124933"], ["84110.9", "0.124933"], ["84115.8", "0.085864"], ["84116.2", "0.028203"], ["84116.6", "0.001333"], ["84117.3", "0.000333"], ["84117.4", "0.118852"], ["84119.1", "0.195"], ["84119.5", "0.000518"]], "u": 92375, "seq": 67563895161}, "cts": 1742569769917, "record_time": 1742569770.18795, "EXCHANGE": "BYBIT"}
{"topic": "orderbook.200.BTCUSDT", "ts": 1742569770119, "type": "delta", "data": {"s": "BTCUSDT", "b": [["84045.1", "0.292202"], ["84044.8", "0.022522"], ["84044.7", "0.075073"], ["84039.7", "0.021429"], ["84039.6", "0.071429"], ["84038", "0.004035"], ["84037.6", "0.145964"], ["84037.5", "0"], ["84035.1", "0.00948"], ["84034.6", "0.044"], ["84034.2", "0.019443"], ["84032.9", "0.04"], ["84032.8", "0.101621"], ["84029.8", "0"], ["84029.5", "0.048"], ["84023.9", "0.171"], ["84021.8", "0"], ["84017.8", "0.089615"], ["84016.6", "0.71923"], ["84015.7", "0.001333"], ["84012.9", "0"], ["84012.6", "0"], ["84010.6", "0.14352"], ["84009.5", "0"], ["84009.4", "0"], ["84008.7", "0"], ["84008.5", "0.347618"], ["84008.4", "0.039814"], ["84007.7", "0"], ["84007.6", "0"], ["84006.7", "0.185481"], ["84006.6", "0.012881"], ["84004.1", "0"], ["84004", "0"], ["84003.6", "0"], ["84003.1", "0.050882"], ["84003", "0.049549"], ["84002.2", "0"], ["83998.2", "0.171"], ["83996.6", "0"], ["83991.9", "0"], ["83985.3", "0.09606"], ["83966.1", "0.059518"], ["83966", "0.059732"]], "a": [["84045.2", "0.074592"], ["84045.6", "0"], ["84045.8", "0"], ["84046.4", "0"], ["84051.4", "0"], ["84052.9", "0"], ["84053", "0.150644"], ["84053.7", "0"], ["84054.6", "0"], ["84054.7", "0.005335"], ["84054.8", "0.000516"], ["84054.9", "0.030135"], ["84056.4", "0"], ["84056.5", "0"], ["84058.2", "0"], ["84059", "0.072054"], ["84059.1", "0"], ["84059.9", "0"], ["84060.2", "0.001466"], ["84061.3", "0"], ["84061.6", "0.003669"], ["84063.2", "0.04"], ["84065.4", "0"], ["84066.5", "0.04"], ["84067.3", "0"], ["84067.8", "0.116385"], ["84067.9", "0"], ["84069.1", "0.018568"], ["84070.9", "0.035702"], ["84073.6", "0"], ["84080.3", "0"], ["84080.7", "0.023792"], ["84081.4", "0"], ["84082.4", "0"], ["84082.5", "0.000516"], ["84082.6", "0.00367"], ["84084.6", "0.900729"], ["84085", "0.003411"], ["84086.3", "0.023792"], ["84086.8", "0.04367"], ["84086.9", "0.04"], ["84087.7", "0"], ["84089.9", "0.063524"], ["84094.7", "0.024054"], ["84097.6", "0"], ["84098.5", "0"], ["84101.1", "0.178475"], ["84101.5", "0"], ["84102.4", "0"], ["84103.2", "0"], ["84105.3", "0"], ["84116.5", "0.171"], ["84120.3", "0.001466"], ["84120.4", "0.003564"], ["84120.8", "0.001333"], ["84121.1", "0.114"], ["84121.4", "0.026267"], ["84121.5", "0.044747"], ["84122.2", "0.039588"], ["84123.2", "0.00009"], ["84123.4", "0.118852"], ["84123.5", "0.059399"], ["84124.1", "0.000518"], ["84124.6", "0.006049"], ["84124.9", "0.001466"], ["84125", "0.001333"], ["84125.7", "0.000333"], ["84126.1", "0.000361"]], "u": 92376, "seq": 67563895783}, "cts": 1742569770116, "record_time": 1742569770.388523, "EXCHANGE": "BYBIT"}
{"topic": "orderbook.200.BTCUSDT", "ts": 1742569770319, "type": "delta", "data": {"s": "BTCUSDT", "b": [["84045.1", "0.117805"], ["84037.6", "0.103884"], ["84036.2", "0.04"], ["84034.6", "0.084"], ["84033.5", "0.008"], ["84032.8", "0.145621"], ["84031.2", "0.04"], ["84031.1", "0.04"], ["84029.7", "0.136"], ["84029.3", "0.032142"], ["84028", "0.04"], ["84026.3", "0"], ["84026.2", "0"], ["84024.5", "0"], ["84022.9", "0"], ["84022.6", "0.178475"], ["84021.3", "0.178475"], ["84017.1", "0.178475"], ["84004.6", "0.05"], ["84004.5", "0.049547"], ["84003.1", "0.001333"], ["84003", "0"], ["83991.9", "0.089238"], ["83985.3", "0"], ["83968.1", "0.178639"], ["83967", "0"], ["83966.9", "0"], ["83966.4", "0"], ["83966.1", "0"], ["83966", "0"]], "a": [["84045.2", "0.101304"], ["84046.4", "0.017363"], ["84055.4", "0.008338"], ["84059", "0.000153"], ["84059.1", "0.040996"], ["84059.5", "0"], ["84059.8", "0.04"], ["84061.4", "0.04"], ["84063.1", "0.094176"], ["84064.8", "0.041466"], ["84066.4", "0.059399"], ["84067.3", "0.132138"], ["84067.5", "0.178475"], ["84068", "0.178475"], ["84070.9", "0"], ["84071.3", "0.035702"], ["84071.7", "0.178475"], ["84085", "0"], ["84086", "0.003411"], ["84086.8", "0.00367"], ["84086.9", "0"], ["84087.7", "0.04"], ["84087.8", "0.040333"], ["84089.9", "0"], ["84097", "0.089238"], ["84101.1", "0"], ["84118", "0.089238"], ["84121.4", "0"], ["84121.5", "0.04463"], ["84123.2", "0"], ["84123.4", "0"], ["84123.5", "0"], ["84124.1", "0"], ["84124.6", "0"], ["84124.9", "0"], ["84125", "0"], ["84125.7", "0"], ["84126.1", "0"]], "u": 92377, "seq": 67563895924}, "cts": 1742569770317, "record_time": 1742569770.58813, "EXCHANGE": "BYBIT"}
{"topic": "orderbook.200.BTCUSDT", "ts": 1742569770519, "type": "delta", "data": {"s": "BTCUSDT", "b": [["84045.1", "0.312705"], ["84040.5", "0.015566"], ["84037.6", "0.146366"], ["84036.3", "0.04816"], ["84034.8", "0.118852"], ["84034.7", "0.059399"], ["84033.5", "0"], ["84029.7", "0.052"], ["84029.3", "0.020142"], ["84028", "0"], ["84024.6", "0.0025"], ["84023.1", "0"], ["84020.1", "0.178475"], ["84008.2", "0.013"], ["84008.1", "0.024785"], ["84006.7", "0.1726"], ["84006.6", "0"], ["84005.1", "0.096042"], ["84003.7", "0"], ["83968.1", "0"], ["83967", "0.00052"]], "a": [["84045.2", "0.077804"], ["84046.4", "0"], ["84059", "0"], ["84059.1", "0.059872"], ["84059.7", "0.04"], ["84061.5", "0.04"], ["84063.1", "0.117729"], ["84064.7", "0.063796"], ["84067.5", "0"], ["84068", "0"], ["84071.7", "0"], ["84084.2", "0.063524"], ["84084.8", "0.003411"], ["84086", "0"], ["84089.9", "0.124933"], ["84123.2", "0.00009"]], "u": 92378, "seq": 67563896016}, "cts": 1742569770511, "record_time": 1742569770.789816, "EXCHANGE": "BYBIT"}
{"topic": "orderbook.200.BTCUSDT", "ts": 1742569770720, "type": "delta", "data": {"s": "BTCUSDT", "b": [["84037.6", "0.28381"], ["84035.4", "0.178496"], ["84033.7", "0.1785"], ["84032", "0.178503"], ["84005.3", "0.297327"], ["83993.4", "0.178585"], ["83969.1", "0"], ["83967.8", "0"], ["83967.3", "0"], ["83967", "0"]], "a": [["84057.4", "0.000153"], ["84067.5", "0.178475"], ["84068", "0.178475"], ["84071.7", "0.178475"], ["84080", "0.23119"], ["84084.8", "0"], ["84085", "0.003411"], ["84093.6", "0.218475"], ["84121.1", "0"], ["84121.5", "0"], ["84122.2", "0"], ["84123.2", "0"]], "u": 92379, "seq": 67563896064}, "cts": 1742569770715, "record_time": 1742569770.989062, "EXCHANGE": "BYBIT"}
{"topic": "orderbook.200.BTCUSDT", "ts": 1742569770919, "type": "delta", "data": {"s": "BTCUSDT", "b": [["84045.1", "0"], ["84044.8", "0"], ["84044.7", "0"], ["84041.7", "0"], ["84041.6", "0"], ["84040.9", "0"], ["84040.5", "0"], ["84040", "0"], ["84039.7", "0"], ["84039.6", "0"], ["84038", "0"], ["84037.6", "0"], ["84037.4", "0"], ["84037.2", "0"], ["84037.1", "0"], ["84036.7", "0"], ["84036.5", "0"], ["84036.3", "0"], ["84036.2", "0"], ["84035.8", "0"], ["84035.5", "0.001197"], ["84035.4", "0"], ["84035.1", "0"], ["84034.8", "0"], ["84034.7", "0"], ["84034.6", "0"], ["84034.2", "0"], ["84033.7", "0"], ["84033.6", "0"], ["84032.8", "0"], ["84032", "0"], ["84031.2", "0"], ["84031.1", "0"], ["84030.2", "0"], ["84029.7", "0"], ["84029.5", "0"], ["84029.4", "0"], ["84029.3", "0"], ["84027.1", "0.051563"], ["84027", "0.171516"], ["84025.7", "0"], ["84025.2", "0"], ["84024", "0"], ["84023.9", "0"], ["84023", "0"], ["84022.9", "0.040018"], ["84022.8", "0.04"], ["84022.6", "0"], ["84021.5", "0.071444"], ["84021.3", "0"], ["84021.1", "0"], ["84020.9", "0"], ["84020.1", "0"], ["84017.9", "0.012182"], ["84017.8", "0.040516"], ["84017.2", "0"], ["84017.1", "0"], ["84016.9", "0"], ["84016.6", "0"], ["84016.5", "0"], ["84016.2", "0.052"], ["84015.6", "0"], ["84015.5", "0.118852"], ["84015.4", "0.059399"], ["84015.3", "0.055715"], ["84014.7", "0.019443"], ["84013.6", "0"], ["84010.7", "0.00948"], ["84010.6", "0"], ["84009.5", "0.035707"], ["84008.8", "0"], ["84008.5", "0.000516"], ["84008.4", "0.00018"], ["84008.2", "0"], ["84008.1", "0.049334"], ["84006.9", "0.314906"], ["84006.8", "0.178251"], ["84005.8", "0"], ["84005.3", "0"], ["84005.1", "0"], ["84005", "0"], ["84004.6", "0"], ["84004.5", "0"], ["84003.4", "0.116384"], ["84000.9", "0.04"], ["84000.8", "0.039632"], ["83999.1", "0.013"], ["83999", "0.012881"], ["83995.5", "0.051466"], ["83995.4", "0.04988"], ["83995.2", "0"], ["83994.5", "0"], ["83994", "0.059399"], ["83993.4", "0"], ["83992.3", "0.024302"], ["83991.9", "0"], ["83991.6", "0.00009"], ["83989.1", "0"], ["83988.9", "0"], ["83986.7", "0"], ["83986.6", "0.046282"], ["83985", "0"], ["83984.8", "0.124947"], ["83984.1", "0"], ["83983.8", "0.059399"], ["83983.1", "0.023799"], ["83982.9", "0"], ["83982.6", "0"], ["83981.3", "0"], ["83980.3", "0.023799"], ["83980", "0.00006"], ["83978.6", "0.000333"], ["83976.4", "0.023799"], ["83975.5", "0.023799"], ["83975.3", "0.059399"], ["83975.2", "0"], ["83971.4", "0.003564"], ["83970.9", "0"], ["83969.1", "0.003552"], ["83967.8", "0.001466"], ["83967.3", "0.121852"], ["83967", "0.00052"], ["83966.9", "0.01002"], ["83966.4", "0.00018"], ["83966.1", "0.059518"], ["83966", "0.059732"], ["83965.3", "0.001333"], ["83964.9", "0.003552"], ["83964.2", "0.00107"], ["83963.8", "0.124947"], ["83963.1", "0.001466"], ["83962.4", "0.00052"], ["83962.2", "0.048"], ["83961.8", "0.000333"], ["83961.6", "0.124947"], ["83961.5", "0.002201"], ["83961.2", "0.015"], ["83961.1", "0.001333"], ["83961", "0.03571"], ["83960.7", "0.063043"], ["83960.4", "0.044"], ["83959.7", "0.000361"], ["83959.1", "0.1"], ["83958.8", "0.044"], ["83958.7", "0.04"], ["83958.5", "0.121466"], ["83958.1", "0.023807"], ["83958", "0.00009"], ["83957.7", "0.00052"], ["83957.6", "0.000333"], ["83957.2", "0.118852"], ["83957.1", "0.04081"], ["83957", "0.129303"], ["83956.9", "0.001333"], ["83956.7", "0.01872"], ["83955.9", "0.057"], ["83955.6", "0.013102"], ["83955.4", "0.048"], ["83954.3", "0.05"], ["83954.2", "0.096042"], ["83953.9", "0.001466"], ["83953.8", "0.01185"], ["83953.4", "0.000333"], ["83953.3", "0.05"], ["83953.1", "0.012513"], ["83952.7", "0.001333"], ["83951.1", "0.002149"], ["83951", "0.03441"], ["83950.3", "0.01185"], ["83950.1", "0.011993"]], "a": [["84035.6", "0.421442"], ["84036.4", "0.098009"], ["84037.4", "0.09018"], ["84037.5", "0.171"], ["84037.7", "0.1296"], ["84038.7", "0.004042"], ["84040", "0.111454"], ["84040.1", "0.120826"], ["84041", "0.171"], ["84041.8", "0.079687"], ["84043.1", "0.1067"], ["84044", "0.03135"], ["84044.6", "0.019892"], ["84044.8", "0.02134"], ["84045.2", "0.073549"], ["84045.5", "0.000516"], ["84045.8", "0.000333"], ["84046.3", "0.001466"], ["84046.4", "0.062215"], ["84046.7", "0.009337"], ["84046.9", "0.003645"], ["84047.6", "0.00009"], ["84047.7", "0.054572"], ["84048.3", "0.04"], ["84049.1", "0.089099"], ["84053", "0.061532"], ["84053.3", "0"], ["84053.4", "0.04"], ["84053.6", "0"], ["84054.2", "0.000333"], ["84054.7", "0"], ["84054.9", "0.068735"], ["84055", "0"], ["84056.8", "0"], ["84057.4", "0"], ["84057.8", "0.059399"], ["84057.9", "0"], ["84059.8", "0"], ["84060.2", "0.550942"], ["84061.7", "0"], ["84062.2", "0.517466"], ["84063.1", "0.113687"], ["84064", "0.004091"], ["84065.1", "0.0006"], ["84066.8", "0.000333"], ["84067.3", "0.222706"], ["84067.5", "0"], ["84068", "0"], ["84068.4", "0.089099"], ["84068.9", "0.124947"], ["84069.1", "0"], ["84070", "0.067194"], ["84071.2", "0.118852"], ["84071.7", "0"], ["84075.5", "0.2883"], ["84076.5", "0.023154"], ["84077.5", "1.426959"], ["84077.6", "0.118852"], ["84082.7", "0"], ["84083.4", "0.098009"], ["84084.2", "0"], ["84084.7", "0"], ["84085.1", "0.059549"], ["84086.7", "0.06112"], ["84086.8", "0.04367"], ["84087.1", "0.001849"], ["84087.7", "0"], ["84087.8", "0.000333"], ["84088.5", "0.178496"], ["84089.9", "0.124947"], ["84093.6", "0.04"], ["84094.6", "0.01185"], ["84094.7", "0"], ["84095.7", "3.448027"], ["84097", "0"], ["84097.8", "0"], ["84100.7", "3.661411"], ["84102.5", "0.01305"], ["84104.6", "0.071724"], ["84109.1", "0"], ["84110.9", "0"], ["84112.5", "0.01185"], ["84113.1", "0"], ["84113.6", "0"], ["84114", "0"], ["84114.7", "0"], ["84114.8", "0"], ["84114.9", "0"], ["84115.7", "0"], ["84115.8", "0"], ["84116.2", "0"], ["84116.5", "0"], ["84116.6", "0"], ["84117.3", "0"], ["84117.4", "0"], ["84118", "0"], ["84119.1", "0"], ["84119.5", "0"], ["84120.3", "0"], ["84120.4", "0"], ["84120.8", "0"]], "u": 92380, "seq": 67563897469}, "cts": 1742569770912, "record_time": 1742569771.191676, "EXCHANGE": "BYBIT"}
{"topic": "orderbook.200.BTCUSDT", "ts": 1742569771119, "type": "delta", "data": {"s": "BTCUSDT", "b": [["84035.5", "0"], ["84033.4", "0"], ["84033.2", "0"], ["84032.9", "0"], ["84032.5", "0"], ["84032.4", "0"], ["84032.1", "0.006037"], ["84027.1", "0"], ["84027", "0.000516"], ["84026.1", "0.169345"], ["84023.2", "0.09651"], ["84023.1", "0.118852"], ["84023", "0.04"], ["84022.9", "0"], ["84021.2", "0.084"], ["84019.6", "0.028184"], ["84019.5", "0.04364"], ["84019.4", "0.044"], ["84018.7", "0.071446"], ["84017.9", "0.114866"], ["84017.7", "0.04"], ["84016.1", "0.048"], ["84010.6", "0.052356"], ["84009.5", "0"], ["84008.1", "0.03743"], ["84007.4", "0.178643"], ["84006.9", "0.003636"], ["84003.4", "0"], ["84000.9", "0.03963"], ["84000.4", "0.281079"], ["83997.6", "0.011906"], ["83985.7", "0"], ["83984.8", "0"], ["83984", "0"], ["83976.7", "0.0238"], ["83975", "0.0238"], ["83967.3", "0.118852"], ["83964.2", "0.17207"], ["83963.8", "0"], ["83959.1", "0"], ["83957", "0.225354"], ["83956.5", "0.003552"], ["83955.7", "0.171"], ["83954.3", "0"], ["83954.2", "0"], ["83953.3", "0"], ["83952.9", "0.05"], ["83952.3", "0.003552"], ["83952", "0.05"], ["83951", "0"], ["83950.8", "0.033502"], ["83950.3", "0"], ["83950.1", "0"]], "a": [["84032.2", "0.481258"], ["84033.4", "0.322516"], ["84033.5", "0.39563"], ["84034.6", "0.004042"], ["84035.6", "0.02"], ["84036.7", "0.001333"], ["84037.1", "0.001466"], ["84037.4", "0.000333"], ["84038.7", "0"], ["84040", "0.060254"], ["84041", "0"], ["84041.6", "0.000333"], ["84042.3", "0.108658"], ["84042.4", "0.109317"], ["84042.9", "0.116105"], ["84043.7", "0.005335"], ["84044.6", "0"], ["84045.2", "0.080514"], ["84046.4", "0.092609"], ["84048.2", "0.04"], ["84048.9", "0.003649"], ["84049.8", "0.04"], ["84050", "0.040333"], ["84051.4", "0.04"], ["84051.7", "0.04"], ["84052.9", "0.175293"], ["84053", "0.101532"], ["84053.4", "0.0406"], ["84055.1", "0.04"], ["84055.4", "0"], ["84059.7", "0"], ["84059.9", "0.292176"], ["84060.2", "0.554517"], ["84061.5", "0"], ["84062.6", "0.000333"], ["84063.2", "0"], ["84064.8", "0.001466"], ["84066.5", "0"], ["84068.9", "0"], ["84071.2", "0"], ["84075.4", "1.486358"], ["84077.5", "0"], ["84080", "0"], ["84083.7", "0"], ["84084.5", "0.015"], ["84084.6", "0.142644"], ["84086", "0.1785"], ["84088.5", "0"], ["84111.2", "0"], ["84112", "0"], ["84112.2", "0"], ["84112.3", "0"], ["84112.5", "0"], ["84112.6", "0"]], "u": 92381, "seq": 67563898268}, "cts": 1742569771117, "record_time": 1742569771.387922, "EXCHANGE": "BYBIT"}
{"topic": "orderbook.200.BTCUSDT", "ts": 1742569771320, "type": "delta", "data": {"s": "BTCUSDT", "b": [["84032.1", "0.009012"], ["84024.7", "0"], ["84021.5", "0"], ["84021.1", "0.02464"], ["84019.6", "0.068824"], ["84017.9", "0"], ["84016.3", "0.108897"], ["84016.2", "0.179275"], ["84015.8", "0.071449"], ["84015.3", "0.00364"], ["84012.6", "0.060699"], ["84012.5", "0.118027"], ["84010.6", "0.011941"], ["84010.3", "0.031738"], ["84007.4", "0"], ["84007.2", "0.006037"], ["84006.5", "0.167133"], ["84006.4", "0.119384"], ["84005.5", "0.17496"], ["84004.5", "0.178503"], ["84002.4", "0.178503"], ["84000.9", "0"], ["84000.8", "0"], ["84000.5", "0.0238"], ["84000.4", "0"], ["84000.3", "0.178503"], ["83999.9", "0.04"], ["83999.8", "0.03963"], ["83999.1", "0"], ["83999", "0"], ["83998.5", "0.283884"], ["83998.1", "0.013"], ["83998", "0.01288"], ["83997.4", "0.289501"], ["83996.8", "0"], ["83995.5", "0.001466"], ["83995.4", "0.000333"], ["83994.5", "0.05"], ["83994.4", "0.049544"], ["83992.9", "0.51707"], ["83988.9", "0.55974"], ["83982.5", "0.096051"], ["83970.9", "0.089252"], ["83957", "0.129303"], ["83955.9", "0"], ["83955.7", "0"], ["83955.6", "0"], ["83955.4", "0"], ["83953.9", "0"], ["83953.8", "0"], ["83953.4", "0"], ["83953.1", "0"], ["83952.9", "0"], ["83952.7", "0"], ["83952.3", "0"], ["83952", "0"], ["83951.1", "0"], ["83950.8", "0"]], "a": [["84032.2", "0.5599"], ["84033.4", "0.233037"], ["84033.5", "0.321"], ["84034.5", "0.007976"], ["84040.9", "0.001849"], ["84041.5", "0.114324"], ["84041.7", "0.001466"], ["84042.4", "0"], ["84043.2", "0.022989"], ["84045.1", "0.001333"], ["84045.2", "0.075866"], ["84045.4", "0.119959"], ["84046.4", "0.173637"], ["84047.8", "0.178503"], ["84050.6", "0.162102"], ["84050.7", "0.178503"], ["84051.3", "0.183431"], ["84052.4", "0.169782"], ["84052.9", "0"], ["84053", "0.04"], ["84054.9", "0.247238"], ["84059.4", "0.304634"], ["84059.9", "0"], ["84060.4", "0.307906"], ["84061.4", "0"], ["84062.9", "0.013963"], ["84063.1", "0.050134"], ["84063.3", "0"], ["84064.7", "0.023796"], ["84074.1", "1.428425"], ["84075.4", "0.059399"], ["84076", "0.089252"], ["84076.2", "0"], ["84087.8", "0.012326"], ["84097", "0.089252"], ["84107.8", "0"], ["84108", "0"], ["84108.1", "0"], ["84108.3", "0"], ["84108.7", "0"], ["84108.9", "0"], ["84109.9", "0"], ["84110.3", "0"], ["84111", "0"], ["84111.1", "0"]], "u": 92382, "seq": 67563898536}, "cts": 1742569771314, "record_time": 1742569771.590865, "EXCHANGE": "BYBIT"}
{"topic": "orderbook.200.BTCUSDT", "ts": 1742569771520, "type": "delta", "data": {"s": "BTCUSDT", "b": [["84027.8", "0.072905"], ["84020.7", "0.071445"], ["84016.7", "0.110564"], ["84016.3", "0"], ["84015.8", "0"], ["84012.6", "0.022688"], ["84012.5", "0"], ["84006.9", "0.302825"], ["84006.5", "0"], ["84006.2", "0.185478"], ["84005.5", "0"], ["83999.2", "0.298716"], ["83998.5", "0.003552"], ["83997.4", "0"], ["83984.8", "0.124952"], ["83982.4", "0.004615"], ["83963.8", "0.124952"], ["83961.6", "0"]], "a": [["84032.2", "0.560053"], ["84040", "0.089001"], ["84041.2", "0.11787"], ["84041.5", "0"], ["84045.4", "0"], ["84048.8", "0.023972"], ["84049.4", "0.004588"], ["84050.4", "0.178503"], ["84050.6", "0.247803"], ["84051.3", "0"], ["84051.7", "0.217355"], ["84052.4", "0"], ["84056.5", "0.178451"], ["84058.7", "0.298933"], ["84059.4", "0.000516"], ["84060.4", "0"], ["84063.1", "0"], ["84068.9", "0.124952"], ["84086", "0"], ["84086.2", "0.015549"], ["84089.6", "0.00009"], ["84096.8", "0.283514"], ["84107.5", "0"]], "u": 92383, "seq": 67563898615}, "cts": 1742569771517, "record_time": 1742569771.788093, "EXCHANGE": "BYBIT"}
{"topic": "orderbook.200.BTCUSDT", "ts": 1742569771719, "type": "delta", "data": {"s": "BTCUSDT", "b": [["84032.1", "0.006618"], ["84027.8", "0.001466"], ["84026.2", "0.050912"], ["84023", "0.111443"], ["84019.6", "0.050914"], ["84018.7", "0"], ["84016.7", "0"], ["84015.9", "0.008158"], ["84014.5", "0.178541"], ["84007.2", "0"], ["84006.5", "0.116383"], ["84006.4", "0.003"], ["84006.2", "0"], ["84003.4", "0.262942"], ["84000.5", "0"], ["83999.9", "0"], ["83999.8", "0"], ["83999.2", "0"], ["83998.6", "0.039631"], ["83998.5", "0.043183"], ["83998.1", "0"], ["83998", "0"], ["83996.8", "0.013"], ["83996.7", "0.01288"], ["83994.5", "0"], ["83994.4", "0"], ["83993.2", "0.049545"], ["83993.1", "0.049546"], ["83974.2", "0.178626"], ["83955.9", "0.057"]], "a": [["84032.2", "0.263963"], ["84033.4", "0.172735"], ["84033.5", "0.15"], ["84034.5", "0"], ["84040", "0.060254"], ["84041.2", "0"], ["84044.9", "0.04"], ["84046.4", "0.26018"], ["84046.5", "0.095693"], ["84046.7", "0.049337"], ["84048.1", "0.04"], ["84049.2", "0.116383"], ["84051.7", "0"], ["84053.2", "0.178503"], ["84054.8", "0.178971"], ["84058.7", "0"], ["84067.8", "0"], ["84074", "0.551223"], ["84081.1", "0.001527"], ["84086.2", "0"]], "u": 92384, "seq": 67563898742}, "cts": 1742569771712, "record_time": 1742569772.007733, "EXCHANGE": "BYBIT"}
{"topic": "orderbook.200.BTCUSDT", "ts": 1742569771919, "type": "delta", "data": {"s": "BTCUSDT", "b": [["84029.4", "0.071437"], ["84023", "0.04"], ["84020.8", "0.094299"], ["84019.6", "0"], ["84018.1", "0.071447"], ["84017.2", "0.119179"], ["84010.3", "0"], ["84010.1", "0.023891"], ["84006.9", "0.003636"], ["84006.7", "0.352025"], ["84006", "0.006618"], ["83999.7", "0.312167"], ["83999", "0.000118"], ["83993.4", "0.05"], ["83993.3", "0.049545"], ["83993.2", "0"], ["83993.1", "0"], ["83957.1", "0"], ["83957", "0"], ["83956.9", "0"], ["83956.7", "0"], ["83956.5", "0"], ["83955.9", "0"]], "a": [["84040", "0.091996"], ["84040.5", "0.003649"], ["84041.7", "0.125415"], ["84043.2", "0.062989"], ["84043.4", "0.04"], ["84044.7", "0.003649"], ["84045.1", "0.041333"], ["84045.2", "0.068568"], ["84048.3", "0"], ["84048.4", "0.04"], ["84049.8", "0"], ["84050", "0.080333"], ["84050.1", "0.040516"], ["84051.4", "0"], ["84052.2", "0.181995"], ["84053", "0"], ["84053.4", "0.0006"], ["84059.2", "0.280181"], ["84066.7", "0.124952"], ["84087.7", "0.124952"], ["84105.9", "0"], ["84106.3", "0"], ["84106.4", "0"], ["84107.3", "0"]], "u": 92385, "seq": 67563898808}, "cts": 1742569771917, "record_time": 1742569772.188115, "EXCHANGE": "BYBIT"}
{"topic": "orderbook.200.BTCUSDT", "ts": 1742569772119, "type": "delta", "data": {"s": "BTCUSDT", "b": [["84032.1", "0.007418"], ["84017.2", "0"], ["84006.7", "0.1726"], ["83999.7", "0"], ["83996.8", "0.01288"], ["83993.4", "0"], ["83993.2", "0.049545"], ["83957.1", "0.04081"], ["83957", "0.129303"]], "a": [["84032.2", "0.434963"], ["84040", "0.060254"], ["84041.7", "0.001466"], ["84048.2", "0"], ["84049", "0.059399"], ["84050", "0.040333"], ["84052.2", "0"], ["84054.9", "0.207238"], ["84055.1", "0"], ["84059.2", "0"], ["84067.2", "0.063524"], ["84070", "0.00367"], ["84104", "1.10191"], ["84105.7", "0.011993"], ["84105.9", "0.045"]], "u": 92386, "seq": 67563898857}, "cts": 1742569772116, "record_time": 1742569772.387358, "EXCHANGE": "BYBIT"}
{"topic": "orderbook.200.BTCUSDT", "ts": 1742569772320, "type": "delta", "data": {"s": "BTCUSDT", "b": [["84029.4", "0"], ["84023.2", "0.058813"], ["84023.1", "0"], ["84020.8", "0"], ["84020.7", "0"], ["84019.6", "0.050914"], ["84018.1", "0"], ["84018", "0.071447"], ["84016.2", "0.24081"], ["84015.9", "0.079607"], ["84014.4", "0.011941"], ["84012.6", "0"], ["84012.4", "0.057341"], ["84012.3", "0.123359"], ["84010.6", "0"], ["84010.1", "0.0003"], ["84006", "0"], ["84005.3", "0.184574"], ["84005.1", "0.004761"], ["83998.6", "0"], ["83998.5", "0.003552"], ["83998.3", "0.350046"], ["83996.8", "0"], ["83996.7", "0"], ["83996.5", "0.039633"], ["83996.4", "0.039633"], ["83996.1", "0.179378"], ["83994.7", "0.014734"], ["83994.6", "0.012881"], ["83993.3", "0"], ["83993.2", "0"], ["83991.1", "0.049548"], ["83991", "0.049548"], ["83981.8", "0.000361"], ["83969.2", "0.014076"]], "a": [["84034.6", "0"], ["84042.3", "0.181153"], ["84045.2", "0.179469"], ["84048.8", "0"], ["84050.4", "0"], ["84050.6", "0.162102"], ["84052.2", "0.181779"], ["84053.2", "0.356961"], ["84054.8", "0.000516"], ["84059.2", "0.30542"], ["84067.3", "0.132138"], ["84072.4", "0.118852"], ["84080.6", "0.004207"], ["84081.1", "0"], ["84089.7", "0.011852"], ["84105.9", "0"]], "u": 92387, "seq": 67563898992}, "cts": 1742569772302, "record_time": 1742569772.588445, "EXCHANGE": "BYBIT"}
{"topic": "orderbook.200.BTCUSDT", "ts": 1742569772519, "type": "delta", "data": {"s": "BTCUSDT", "b": [["84019.6", "0.085447"], ["84017.7", "0.104878"]], "a": [["84032.2", "0.439005"], ["84050.6", "0.255462"], ["84054", "0.007418"], ["84056.1", "0.178452"], ["84068.1", "0.003504"], ["84071.3", "0"], ["84076", "0.093459"], ["84080.6", "0"], ["84085", "0"], ["84105.9", "0.045"]], "u": 92388, "seq": 67563899020}, "cts": 1742569772501, "record_time": 1742569772.788236, "EXCHANGE": "BYBIT"}
{"topic": "orderbook.200.BTCUSDT", "ts": 1742569772720, "type": "delta", "data": {"s": "BTCUSDT", "b": [["84026.2", "0"], ["84025.8", "0.07144"], ["84015.9", "0.071449"], ["84012.4", "0"], ["84012.3", "0"], ["84005.3", "0"], ["83998.3", "0.068858"], ["83996.5", "0"], ["83996.3", "0.039633"], ["83994.7", "0.001853"], ["83994.5", "0.012881"], ["83991.1", "0"], ["83990.9", "0.051014"], ["83956.9", "0.001333"], ["83956.7", "0.01872"], ["83956.5", "0.003552"]], "a": [["84034.5", "0.00799"], ["84035", "0.023385"], ["84045.2", "0.068568"], ["84052.2", "0"], ["84059.2", "0"], ["84073.9", "0.004207"], ["84076", "0.089252"], ["84105.9", "0"]], "u": 92389, "seq": 67563899062}, "cts": 1742569772678, "record_time": 1742569772.989385, "EXCHANGE": "BYBIT"}
{"topic": "orderbook.200.BTCUSDT", "ts": 1742569772919, "type": "delta", "data": {"s": "BTCUSDT", "b": [["84027.5", "0.071439"], ["84026.1", "0.169414"], ["84025.8", "0"], ["84015.1", "0.008277"], ["84007.7", "0.004035"], ["84006.9", "0.201625"], ["83989.8", "0.211629"], ["83956.7", "0"], ["83956.5", "0"]], "a": [["84032.2", "0.438852"], ["84059.1", "0.320055"]], "u": 92390, "seq": 67563899090}, "cts": 1742569772907, "record_time": 1742569773.188362, "EXCHANGE": "BYBIT"}
{"topic": "orderbook.200.BTCUSDT", "ts": 1742569773119, "type": "delta", "data": {"s": "BTCUSDT", "b": [["84027.5", "0.071508"], ["84026.1", "0.169345"], ["83991.1", "0.049548"], ["83990.9", "0.001466"], ["83956.9", "0"]], "a": [["84032.2", "0.439005"]], "u": 92391, "seq": 67563899108}, "cts": 1742569773104, "record_time": 1742569773.388247, "EXCHANGE": "BYBIT"}
{"topic": "orderbook.200.BTCUSDT", "ts": 1742569773320, "type": "delta", "data": {"s": "BTCUSDT", "b": [["84032.1", "0.007487"], ["84027.5", "0"], ["84026.2", "0.050912"], ["84023.2", "0.108808"], ["84021.3", "0.118852"], ["84021.2", "0.155444"], ["84015.9", "0"], ["83996.5", "0.039633"], ["83996.3", "0"], ["83991.2", "0.049881"], ["83991", "0"], ["83956.9", "0.001333"]], "a": [["84032.2", "0.349753"], ["84033.5", "0.12"], ["84033.9", "0.000153"], ["84034.5", "0"], ["84036.4", "0"], ["84049", "0"], ["84049.7", "0.001216"], ["84069.6", "0.04"], ["84069.7", "0.04"], ["84086.7", "0.02112"], ["84086.8", "0.00367"], ["84105.7", "0"]], "u": 92392, "seq": 67563899162}, "cts": 1742569773316, "record_time": 1742569773.588362, "EXCHANGE": "BYBIT"}
{"topic": "orderbook.200.BTCUSDT", "ts": 1742569773520, "type": "delta", "data": {"s": "BTCUSDT", "b": [["84029", "0.071771"], ["84022.1", "0.0007"], ["84021.2", "0.084"], ["84016.7", "0.111141"], ["84015.9", "0.071449"], ["84014.4", "0"], ["84010.4", "0.05"], ["84006.9", "0.381159"], ["84006.7", "0.171"], ["83997.8", "0.296298"], ["83996.6", "0.039633"], ["83996.4", "0"], ["83994.9", "0.013"], ["83994.8", "0.012881"], ["83994.6", "0"], ["83994.5", "0"], ["83992.9", "0.51877"], ["83991.3", "0.05"], ["83991.1", "0"], ["83957.2", "0"], ["83957.1", "0"], ["83957", "0"], ["83956.9", "0"]], "a": [["84037.5", "0.1711"], ["84040", "0.092269"], ["84041.9", "0.124859"], ["84049", "0.059399"], ["84049.7", "0"], ["84051.7", "0.186932"], ["84060.8", "0.298674"], ["84066.7", "0.126552"], ["84067.5", "0.003392"], ["84068.1", "0"], ["84069.5", "0.04"], ["84069.7", "0"], ["84097.2", "0.001466"], ["84104.6", "0"], ["84104.9", "0"], ["84105.6", "0"]], "u": 92393, "seq": 67563899225}, "cts": 1742569773500, "record_time": 1742569773.788462, "EXCHANGE": "BYBIT"}
{"topic": "orderbook.200.BTCUSDT", "ts": 1742569773720, "type": "delta", "data": {"s": "BTCUSDT", "b": [["84029", "0.000333"], ["84027.6", "0.071439"], ["84016.7", "0"], ["84011.3", "0.024174"], ["84006.9", "0.201625"], ["83997.8", "0"], ["83994.9", "0"], ["83994.7", "0.014734"], ["83957.2", "0.118852"]], "a": [["84032.2", "0.421188"], ["84032.8", "0.000153"], ["84033.9", "0"], ["84034.5", "0.008013"], ["84039.1", "0.071429"], ["84040", "0.060254"], ["84041.9", "0"], ["84051.7", "0"], ["84060.8", "0"], ["84067.5", "0"], ["84067.7", "0.027188"], ["84104.6", "0.071724"], ["84104.9", "0.00067"]], "u": 92394, "seq": 67563899258}, "cts": 1742569773682, "record_time": 1742569773.988565, "EXCHANGE": "BYBIT"}
{"topic": "orderbook.200.BTCUSDT", "ts": 1742569773919, "type": "delta", "data": {"s": "BTCUSDT", "b": [["83996.6", "0"], ["83996.5", "0.04"], ["83996.4", "0.039633"], ["83994.8", "0"], ["83994.7", "0.014853"], ["83994.6", "0.012881"], ["83991.3", "0"], ["83991.2", "0.000333"], ["83991.1", "0.05"], ["83991", "0.049548"], ["83957.2", "0"]], "a": [["84054.9", "0.301869"], ["84069.4", "0.065262"], ["84069.6", "0"], ["84105.6", "0.000518"]], "u": 92395, "seq": 67563899278}, "cts": 1742569773917, "record_time": 1742569774.187675, "EXCHANGE": "BYBIT"}
{"topic": "orderbook.200.BTCUSDT", "ts": 1742569774120, "type": "delta", "data": {"s": "BTCUSDT", "b": [["84028.4", "0.071438"], ["84027.6", "0"], ["84021.1", "0.096084"], ["84015.9", "0"], ["83996.5", "0.039633"], ["83994.9", "0.013"], ["83994.8", "0.012881"], ["83994.7", "0.001853"], ["83994.6", "0"], ["83993.9", "0.344336"], ["83991.3", "0.05"], ["83991.2", "0.049881"], ["83991.1", "0"], ["83991", "0"], ["83957.2", "0.118852"]], "a": [["84032.8", "0"], ["84034.5", "0.000153"], ["84042.1", "0.071427"]], "u": 92396, "seq": 67563899309}, "cts": 1742569774112, "record_time": 1742569774.388061, "EXCHANGE": "BYBIT"}
{"topic": "orderbook.200.BTCUSDT", "ts": 1742569774320, "type": "delta", "data": {"s": "BTCUSDT", "b": [["84032.1", "0.006687"], ["84029.4", "0.071437"], ["84028.4", "0"], ["84012.4", "0.024674"], ["84011.9", "0.061106"], ["84011.3", "0"], ["84004.9", "0.056788"], ["83997.9", "0.110665"], ["83957.7", "0"], ["83957.6", "0"], ["83957.2", "0"]], "a": [["84032.2", "0.421988"], ["84046.9", "0.063113"], ["84053.9", "0.056167"], ["84060.9", "0.110095"], ["84104.9", "0"], ["84105.6", "0"]], "u": 92397, "seq": 67563899382}, "cts": 1742569774267, "record_time": 1742569774.589767, "EXCHANGE": "BYBIT"}
{"topic": "orderbook.200.BTCUSDT", "ts": 1742569774519, "type": "delta", "data": {"s": "BTCUSDT", "b": [["84012.4", "0.039922"], ["84006.5", "0"], ["84006.4", "0.119385"], ["83957.7", "0.00052"]], "a": [["84050.4", "0.178503"], ["84104.6", "0"]], "u": 92398, "seq": 67563899402}, "cts": 1742569774485, "record_time": 1742569774.788553, "EXCHANGE": "BYBIT"}
{"topic": "orderbook.200.BTCUSDT", "ts": 1742569774719, "type": "delta", "data": {"s": "BTCUSDT", "b": [["84032.1", "0.008018"], ["84019.6", "0.11762"], ["84011.9", "0"], ["84004.9", "0"], ["83997.9", "0"], ["83996.7", "0.04"], ["83996.6", "0.039633"], ["83996.5", "0"], ["83996.4", "0"], ["83957.6", "0.000333"], ["83957.2", "0.118852"], ["83957.1", "0.04081"]], "a": [["84032.2", "0.250988"], ["84046.9", "0.003645"], ["84048.7", "0.000971"], ["84049.8", "0.001244"], ["84053.9", "0"], ["84060.9", "0"]], "u": 92399, "seq": 67563899445}, "cts": 1742569774707, "record_time": 1742569774.98955, "EXCHANGE": "BYBIT"}
{"topic": "orderbook.200.BTCUSDT", "ts": 1742569774920, "type": "delta", "data": {"s": "BTCUSDT", "b": [["84012.4", "0.024674"]], "a": [["84036.2", "0.008224"], ["84048.7", "0"], ["84049.8", "0"], ["84050.4", "0"], ["84104.6", "0.071724"], ["84104.9", "0.00067"]], "u": 92400, "seq": 67563899458}, "cts": 1742569774902, "record_time": 1742569775.240728, "EXCHANGE": "BYBIT"}
{"topic": "orderbook.200.BTCUSDT", "ts": 1742569775119, "type": "delta", "data": {"s": "BTCUSDT", "b": [["84032.1", "0.179257"], ["84030.9", "0.071436"], ["84029.4", "0"], ["84023.1", "0.071443"], ["84018", "0"], ["84015.9", "0.178538"], ["84007", "0.116392"], ["84006.4", "0.003"], ["83998.3", "0.123968"], ["83996.7", "0"], ["83996.6", "0"], ["83996.5", "0.039633"], ["83996.4", "0.039633"], ["83994.9", "0"], ["83994.8", "0"], ["83994.7", "0.014734"], ["83994.6", "0.012881"], ["83991.3", "0"], ["83991.2", "0.000333"], ["83991.1", "0.049548"], ["83991", "0.049548"], ["83957.2", "0"], ["83957.1", "0"]], "a": [["84034.5", "0"], ["84036.2", "0"], ["84049", "0"], ["84052.3", "0.001237"], ["84066.3", "0.074942"], ["84067.7", "0.023796"], ["84068", "0.003392"], ["84069.4", "0.025262"], ["84069.5", "0"], ["84069.7", "0.04"], ["84069.8", "0.04"], ["84104.9", "0"]], "u": 92401, "seq": 67563899513}, "cts": 1742569775114, "record_time": 1742569775.38891, "EXCHANGE": "BYBIT"}
{"topic": "orderbook.200.BTCUSDT", "ts": 1742569775320, "type": "delta", "data": {"s": "BTCUSDT", "b": [["84030.9", "0"], ["84029.7", "0.021431"], ["84029.6", "0.071437"], ["84023.1", "0"], ["84019.6", "0.115916"], ["84019", "0.123143"], ["84018.3", "0.071447"], ["84012.6", "0.178545"], ["84008.5", "0.181142"], ["84005", "0.178503"], ["84002.4", "0"], ["84001.5", "0.298927"], ["83996.1", "0.000875"], ["83994.8", "0.012881"], ["83994.6", "0"], ["83991.2", "0.049881"], ["83991", "0"], ["83985.3", "0.096017"], ["83982.5", "0"], ["83958", "0"], ["83957.7", "0"], ["83957.6", "0"]], "a": [["84034.8", "0.000153"], ["84043.5", "0.11118"], ["84050.4", "0.178503"], ["84052.3", "0"], ["84054", "0.188311"], ["84061", "0.300823"], ["84104", "0"], ["84104.2", "0"], ["84104.6", "0"]], "u": 92402, "seq": 67563899601}, "cts": 1742569775310, "record_time": 1742569775.588133, "EXCHANGE": "BYBIT"}
{"topic": "orderbook.200.BTCUSDT", "ts": 1742569775520, "type": "delta", "data": {"s": "BTCUSDT", "b": [["84030.8", "0.021431"], ["84030.7", "0.071436"], ["84029.7", "0"], ["84029.6", "0"], ["84019", "0"], ["84016.2", "0.318844"], ["84008.5", "0.000516"], ["84001.5", "0"], ["83998.3", "0.068858"], ["83996.6", "0.04"], ["83996.4", "0"], ["83958", "0.00009"], ["83957.7", "0.00052"]], "a": [["84032.2", "0.230988"], ["84033.5", "0.1"], ["84034.8", "0"], ["84034.9", "0.000153"], ["84043.5", "0"], ["84054", "0.007418"], ["84061", "0"], ["84072.8", "0.023353"], ["84073.9", "0"], ["84104", "1.10191"], ["84104.2", "0.0006"], ["84104.6", "0.071724"]], "u": 92403, "seq": 67563899669}, "cts": 1742569775497, "record_time": 1742569775.787918, "EXCHANGE": "BYBIT"}
{"topic": "orderbook.200.BTCUSDT", "ts": 1742569775719, "type": "delta", "data": {"s": "BTCUSDT", "b": [["84032.1", "0.350257"], ["84032", "0.021765"], ["84031.9", "0.071435"], ["84030.8", "0"], ["84030.7", "0"], ["84023.5", "0.071442"], ["84021.2", "0.146422"], ["84019.6", "0.099033"], ["84019.5", "0.106062"], ["84018.3", "0"], ["84017.9", "0.062422"], ["84016.2", "0.052"], ["84015.9", "0"], ["84014.5", "0"], ["84012.6", "0"], ["83996.6", "0"], ["83996.5", "0"], ["83996.3", "0.04"], ["83996.2", "0.039633"], ["83994.8", "0"], ["83994.7", "0.001853"], ["83994.5", "0.013"], ["83994.4", "0.012881"], ["83991.2", "0.000333"], ["83991.1", "0"], ["83990.9", "0.051466"], ["83990.8", "0.049548"], ["83988.2", "0.096013"], ["83985.3", "0"], ["83957.6", "0.000333"]], "a": [["84032.2", "0.205512"], ["84033.4", "0"], ["84034.9", "0"], ["84035", "0.000153"], ["84035.6", "0"], ["84037.5", "0.0001"], ["84037.7", "0.02"], ["84040", "0.106111"], ["84040.7", "0.171"], ["84045.2", "0.038568"], ["84046.4", "0.147042"], ["84047.8", "0"], ["84049.1", "0"], ["84050.4", "0"], ["84050.6", "0"], ["84050.7", "0"], ["84053", "0.062337"], ["84053.2", "0"], ["84054.9", "0.123366"], ["84056.1", "0"], ["84056.6", "0.178451"], ["84060.2", "0.550942"], ["84067.2", "0"], ["84068", "0"], ["84068.9", "0"], ["84069.1", "0.003392"], ["84069.7", "0"], ["84069.8", "0"], ["84070", "0.067189"], ["84070.8", "0.04"], ["84070.9", "0.04"], ["84072.4", "0"], ["84076", "0"], ["84104.9", "0.00067"], ["84105.6", "0.000518"], ["84105.7", "0.011993"], ["84105.9", "0.045"], ["84106.3", "0.04"], ["84106.4", "0.001556"], ["84107.3", "0.04"], ["84107.5", "0.04"], ["84107.8", "0.003563"], ["84108.1", "0.001333"], ["84108.3", "0.24"]], "u": 92404, "seq": 67563899767}, "cts": 1742569775706, "record_time": 1742569775.988117, "EXCHANGE": "BYBIT"}
{"topic": "orderbook.200.BTCUSDT", "ts": 1742569775919, "type": "delta", "data": {"s": "BTCUSDT", "b": [["84032.1", "0.179257"], ["84021.3", "0"], ["84016.2", "0.181758"], ["84007.5", "0.116391"], ["84007", "0"], ["83996.3", "0"], ["83996.2", "0"], ["83996", "0.04"], ["83995.9", "0.039634"], ["83994.5", "0"], ["83994.4", "0"], ["83994.2", "0.013"], ["83994.1", "0.012881"], ["83990.9", "0.001466"], ["83990.8", "0"], ["83990.6", "0.05"], ["83990.5", "0.050882"], ["83957.2", "0.118852"]], "a": [["84033.4", "0.037016"], ["84034.4", "0.000153"], ["84035", "0"], ["84038.8", "0.007851"], ["84056.5", "0"], ["84058.2", "0.178503"], ["84063.3", "0.178503"], ["84066.3", "0"], ["84067.2", "0.063519"], ["84069.1", "0"], ["84069.8", "0.003392"], ["84070", "0.00367"], ["84070.8", "0"], ["84070.9", "0"], ["84071.5", "0.04"], ["84071.6", "0.04"], ["84107.8", "0"], ["84108.1", "0"], ["84108.3", "0"]], "u": 92405, "seq": 67563899827}, "cts": 1742569775917, "record_time": 1742569776.187656, "EXCHANGE": "BYBIT"}
{"topic": "orderbook.200.BTCUSDT", "ts": 1742569776120, "type": "delta", "data": {"s": "BTCUSDT", "b": [["84021.3", "0.118852"], ["83988.2", "0"], ["83985.3", "0.096007"], ["83984.9", "0.090988"], ["83957.6", "0"], ["83957.2", "0"]], "a": [["84032.2", "0.376512"], ["84034.4", "0"], ["84034.9", "0.000153"], ["84055.7", "0.178503"], ["84056.6", "0"], ["84058.2", "0"], ["84063.2", "0.147071"], ["84063.3", "0"], ["84068.9", "0.124952"]], "u": 92406, "seq": 67563899874}, "cts": 1742569776116, "record_time": 1742569776.388048, "EXCHANGE": "BYBIT"}
{"topic": "orderbook.200.BTCUSDT", "ts": 1742569776319, "type": "delta", "data": {"s": "BTCUSDT", "b": [["84032.1", "0.180057"], ["84010.6", "0.05"], ["84010.4", "0"], ["83994.7", "0.014853"], ["83994.6", "0.012881"], ["83994.2", "0"], ["83994.1", "0"], ["83991.1", "0.049548"], ["83991", "0.049548"], ["83990.6", "0"], ["83990.5", "0.001333"]], "a": [["84034.6", "0.000153"], ["84034.9", "0"], ["84037", "0.024252"], ["84054.9", "0.028735"], ["84055.7", "0"], ["84056.6", "0.178451"], ["84058.2", "0.178503"], ["84059.1", "0.498558"], ["84063.2", "0"], ["84069.3", "0.003392"], ["84069.8", "0"], ["84107.5", "0"]], "u": 92407, "seq": 67563899932}, "cts": 1742569776313, "record_time": 1742569776.588904, "EXCHANGE": "BYBIT"}
{"topic": "orderbook.200.BTCUSDT", "ts": 1742569776520, "type": "delta", "data": {"s": "BTCUSDT", "b": [["83996.5", "0.04"], ["83996.4", "0.039633"], ["83996", "0"], ["83995.9", "0"], ["83991.1", "0.05"], ["83985.3", "0.096005"]], "a": [["84032.2", "0.205512"], ["84057.2", "0.17845"], ["84057.9", "0.178503"], ["84058.8", "0.178503"], ["84059.1", "0.320055"], ["84069.3", "0"], ["84069.5", "0.003392"], ["84071.2", "0.04"], ["84071.3", "0.04"], ["84071.5", "0"], ["84071.6", "0"], ["84076", "0.089252"], ["84105.9", "0"], ["84106.3", "0"], ["84106.4", "0"], ["84107.3", "0"]], "u": 92408, "seq": 67563899993}, "cts": 1742569776517, "record_time": 1742569776.788183, "EXCHANGE": "BYBIT"}
{"success": true, "ret_msg": "pong", "conn_id": "42090351-68c6-491c-8113-6d4f7b405345", "op": "ping", "record_time": 1742569776.878633, "EXCHANGE": "BYBIT"}
{"topic": "orderbook.200.BTCUSDT", "ts": 1742569776719, "type": "delta", "data": {"s": "BTCUSDT", "b": [["83996.5", "0"], ["83996.3", "0.039633"], ["83994.7", "0.001853"], ["83994.5", "0.012881"], ["83957.7", "0"]], "a": [["84057.9", "0"], ["84063", "0.178503"], ["84067.2", "0.242022"], ["84069.5", "0"], ["84069.6", "0.003392"], ["84071.2", "0"], ["84071.4", "0.04"]], "u": 92409, "seq": 67563900045}, "cts": 1742569776717, "record_time": 1742569776.987978, "EXCHANGE": "BYBIT"}
{"topic": "orderbook.200.BTCUSDT", "ts": 1742569776920, "type": "delta", "data": {"s": "BTCUSDT", "b": [["83987.4", "0.089252"], ["83985.3", "0.095997"], ["83958", "0"]], "a": [["84032.2", "0.376512"], ["84060.4", "0.178503"], ["84069.4", "0.028654"], ["84069.6", "0"], ["84071.1", "0.04"], ["84071.2", "0.04"], ["84071.3", "0"], ["84071.4", "0"]], "u": 92410, "seq": 67563900083}, "cts": 1742569776916, "record_time": 1742569777.188056, "EXCHANGE": "BYBIT"}
{"topic": "orderbook.200.BTCUSDT", "ts": 1742569777119, "type": "delta", "data": {"s": "BTCUSDT", "b": [["84025.6", "0.071441"], ["84021.1", "0.02464"], ["83996.4", "0"], ["83996.3", "0.04"], ["83996.2", "0.039633"], ["83994.6", "0"], ["83994.4", "0.012881"], ["83991.1", "0"], ["83990.9", "0.051014"]], "a": [["84032.2", "0.205512"], ["84034.6", "0"], ["84035.6", "0.000153"], ["84037.7", "0"], ["84054.9", "0.230467"], ["84058.8", "0"], ["84060.4", "0"], ["84063", "0"], ["84067.2", "0.063519"], ["84068.9", "0"], ["84069.4", "0.025262"], ["84069.6", "0.003392"], ["84071.1", "0"], ["84071.2", "0"], ["84071.3", "0.04"], ["84071.4", "0.04"], ["84076", "0"], ["84105.9", "0.045"], ["84106.3", "0.04"], ["84106.4", "0.001556"], ["84107.3", "0.04"], ["84107.5", "0.04"]], "u": 92411, "seq": 67563900147}, "cts": 1742569777117, "record_time": 1742569777.388941, "EXCHANGE": "BYBIT"}
{"topic": "orderbook.200.BTCUSDT", "ts": 1742569777320, "type": "delta", "data": {"s": "BTCUSDT", "b": [["84032.1", "0.352841"], ["84025.6", "0"], ["84025.5", "0.071441"], ["84022.9", "0.178523"], ["84021.2", "0.084"], ["84020.7", "0.004035"], ["84007.7", "0"], ["84005", "0"], ["84003.4", "0.352041"], ["83996.4", "0.039633"], ["83996.3", "0.039633"], ["83996.2", "0"], ["83994.6", "0.012881"], ["83994.4", "0"], ["83991.2", "0.049881"], ["83991.1", "0.049548"], ["83991", "0.095997"], ["83990.9", "0.001466"], ["83985.3", "0"]], "a": [["84032.2", "0.191832"], ["84033.4", "0"], ["84033.5", "0"], ["84035.6", "0"], ["84040.1", "0.124868"], ["84045.2", "0.02"], ["84049.2", "0"], ["84054", "0"], ["84056.6", "0"], ["84057.2", "0"], ["84058.2", "0"], ["84067.2", "0"], ["84069.6", "0"], ["84071.3", "0"], ["84071.4", "0.003392"], ["84073.1", "0.04"], ["84073.2", "0.04"], ["84075.7", "0.063519"], ["84080", "0.105338"], ["84098.6", "0.353485"], ["84107.8", "0.003563"], ["84108.1", "0.001333"], ["84108.3", "0.24"], ["84108.9", "0.000333"], ["84109.9", "0.0006"], ["84110.3", "0.000518"]], "u": 92412, "seq": 67563900284}, "cts": 1742569777313, "record_time": 1742569777.589626, "EXCHANGE": "BYBIT"}
{"topic": "orderbook.200.BTCUSDT", "ts": 1742569777520, "type": "delta", "data": {"s": "BTCUSDT", "b": [["84040", "0.652146"], ["84036.7", "0.10352"], ["84036.6", "0.3409"], ["84035.5", "0.0096"], ["84033.8", "0.071434"], ["84033.2", "0.000333"], ["84032.5", "0.001333"], ["84032.4", "0.001466"], ["84032.2", "0.116843"], ["84032.1", "0.227758"], ["84032", "0"], ["84027.8", "0.020909"], ["84027.7", "0.0004"], ["84027.3", "0.04"], ["84026.5", "0.100464"], ["84026.4", "0.118852"], ["84026.3", "0.059399"], ["84026.2", "0"], ["84026.1", "0"], ["84025.5", "0"], ["84025.4", "0.178517"], ["84025.2", "0.00009"], ["84024.6", "0.01198"], ["84024.1", "0.045928"], ["84023.7", "0.064408"], ["84023.6", "0.204744"], ["84023.5", "0.178521"], ["84023.2", "0.002066"], ["84022.9", "0"], ["84022.8", "0"], ["84022.3", "0.04"], ["84022.1", "0"], ["84021.9", "0.178525"], ["84021.1", "0"], ["84020.8", "0.052"], ["84019.5", "0.04364"], ["84017.9", "0.089099"], ["84017.7", "0.04"], ["84016.7", "0.057981"], ["84015.1", "0"], ["84014.7", "0"], ["84012.6", "0.178486"], ["84012.5", "0.178486"], ["84010.7", "0"], ["84010.3", "0.51707"], ["84009.7", "0.123928"], ["84008.4", "0.178666"], ["84006.2", "0.55974"], ["84004.5", "0"], ["84000.6", "0.288557"], ["84000.3", "0"], ["83998.5", "0.005152"], ["83998.1", "0.024341"], ["83996.7", "0.004566"], ["83992.9", "0"], ["83992.3", "0"], ["83991.2", "0.000333"], ["83991", "0.049548"], ["83988.9", "0"], ["83988.2", "0.095997"], ["83982.4", "0"], ["83969.2", "0"], ["83967", "1.155223"], ["83961.8", "0"], ["83961.5", "0"], ["83961.2", "0"], ["83961.1", "0"], ["83961", "0"], ["83960.7", "0"], ["83960.4", "0"], ["83959.7", "0"], ["83958.8", "0"], ["83958.7", "0"], ["83958.5", "0"], ["83958.1", "0"]], "a": [["84032.2", "0"], ["84036.7", "0"], ["84037", "0"], ["84037.1", "0"], ["84037.4", "0"], ["84037.5", "0"], ["84038.8", "0"], ["84039.1", "0"], ["84040", "0"], ["84040.1", "0.121733"], ["84040.7", "0"], ["84041.8", "0"], ["84042.1", "0"], ["84042.3", "0"], ["84042.9", "0"], ["84043.1", "0.056151"], ["84043.2", "0.04"], ["84043.7", "0"], ["84044", "0"], ["84045.2", "0"], ["84046.4", "0.142522"], ["84046.5", "0.04"], ["84046.7", "0.04"], ["84047.6", "0.106735"], ["84048.5", "0.03135"], ["84049.3", "0.006668"], ["84049.4", "0"], ["84050", "0.111753"], ["84051.4", "0.0096"], ["84051.8", "0.071418"], ["84054.9", "0"], ["84055.4", "0.04497"], ["84055.5", "0.131389"], ["84057.6", "0.009337"], ["84057.8", "0"], ["84058.3", "0.018568"], ["84058.7", "0.061859"], ["84059.1", "0"], ["84060.2", "0.001466"], ["84062.1", "0.159529"], ["84062.2", "0"], ["84062.9", "0"], ["84063", "0.356972"], ["84063.7", "0.004572"], ["84065.7", "0.060013"], ["84065.8", "0.182155"], ["84066.7", "0.124952"], ["84067.2", "0.180086"], ["84068.4", "0"], ["84071.4", "0"], ["84072.7", "0.111349"], ["84073.1", "0"], ["84073.2", "0"], ["84074.1", "0.001466"], ["84075.5", "0"], ["84075.7", "0"], ["84075.8", "0.549476"], ["84076.5", "0"], ["84077.6", "0"], ["84077.8", "0.517466"], ["84078.5", "0.086911"], ["84080.2", "0.04"], ["84080.3", "0.04"], ["84082.2", "0.024253"], ["84089.7", "0"], ["84094.6", "0"], ["84096.8", "0.105148"], ["84097", "0"], ["84102.5", "0.0012"], ["84104", "0.000361"], ["84108", "0.171"], ["84108.7", "0.12494"], ["84110.9", "0.124952"], ["84111", "0.04"], ["84111.1", "0.001549"], ["84111.2", "0.015"], ["84112", "0.003563"], ["84112.2", "0.118852"], ["84112.3", "0.001333"], ["84112.6", "0.0006"], ["84112.7", "0.013077"], ["84113.1", "0.000333"], ["84113.4", "0.089252"], ["84113.6", "0.000333"], ["84114", "0.059399"]], "u": 92413, "seq": 67563901070}, "cts": 1742569777516, "record_time": 1742569777.788532, "EXCHANGE": "BYBIT"}
{"topic": "orderbook.200.BTCUSDT", "ts": 1742569777720, "type": "delta", "data": {"s": "BTCUSDT", "b": [["84040", "0.213158"], ["84036.7", "0.0724"], ["84036.6", "0.1399"], ["84035.5", "0"], ["84032.2", "0.084093"], ["84032.1", "0.207758"], ["84027.4", "0.04"], ["84025.7", "0.04"], ["84025.6", "0.044"], ["84024", "0.04"], ["84023.7", "0.003641"], ["84023", "0"], ["84022.4", "0.040516"], ["84021.2", "0.04"], ["84020.6", "0.048333"], ["84019.6", "0"], ["84019.5", "0.00364"], ["84019.4", "0"], ["84017.9", "0"], ["84017.8", "0.000516"], ["84016.7", "0"], ["84016.2", "0.129758"], ["84016.1", "0"], ["84012.4", "0.264591"], ["84009.7", "0"], ["84007.5", "0"], ["84005.8", "0.12494"], ["83999.8", "0.013"], ["83999.7", "0.012882"], ["83996.2", "0.05"], ["83996.1", "0.050426"], ["83994.6", "0"], ["83994.5", "0"], ["83993.9", "0.227696"], ["83993.8", "0.230754"], ["83991.1", "0"], ["83991", "0"], ["83989.8", "0.06374"], ["83988.2", "0"], ["83963.8", "0"], ["83961.8", "0.000333"], ["83961.5", "0.002201"], ["83961.2", "0.015"], ["83961.1", "0.001333"], ["83961", "0.03571"], ["83960.7", "0.063043"], ["83960.4", "0.044"]], "a": [["84040.1", "0.155008"], ["84041", "0.071428"], ["84045.8", "0.071756"], ["84047.9", "0.071422"], ["84050", "0.040333"], ["84051.1", "0.004042"], ["84051.4", "0"], ["84051.8", "0"], ["84051.9", "0.000153"], ["84055.4", "0.062792"], ["84058.7", "0"], ["84061.3", "0.035706"], ["84062.1", "0"], ["84062.9", "0.107092"], ["84065.3", "0.178433"], ["84065.7", "0"], ["84067.2", "0.0016"], ["84067.3", "0"], ["84068.9", "0.12494"], ["84072.7", "0"], ["84074", "0"], ["84075.7", "0.063515"], ["84077.4", "0.014097"], ["84078.5", "0.02"], ["84079", "0.003392"], ["84080.2", "0"], ["84080.3", "0"], ["84080.8", "0.04"], ["84080.9", "0.04"], ["84110.9", "0"], ["84113.6", "0"], ["84114", "0"]], "u": 92414, "seq": 67563901241}, "cts": 1742569777715, "record_time": 1742569777.989483, "EXCHANGE": "BYBIT"}
{"topic": "orderbook.200.BTCUSDT", "ts": 1742569777920, "type": "delta", "data": {"s": "BTCUSDT", "b": [["84040", "0.228632"], ["84033.1", "0.007645"], ["84032.3", "0.118852"], ["84031.6", "0.015"], ["84021.2", "0"], ["84017.7", "0"], ["84016.9", "0.116388"], ["84010.6", "0"], ["83999.8", "0"], ["83999.6", "0.013215"], ["83996.2", "0"], ["83996", "0.049551"], ["83984.1", "0.013721"], ["83960.4", "0"]], "a": [["84040.1", "0.169883"], ["84043.1", "0.029579"], ["84043.2", "0"], ["84043.4", "0"], ["84044.9", "0"], ["84045.1", "0.001333"], ["84045.6", "0.071424"], ["84045.8", "0.000333"], ["84046.4", "0.092618"], ["84046.5", "0"], ["84046.7", "0"], ["84048.1", "0"], ["84048.4", "0"], ["84048.5", "0.04635"], ["84048.9", "0.043649"], ["84050", "0.000333"], ["84050.1", "0.000516"], ["84050.7", "0.04"], ["84051.9", "0"], ["84052.4", "0.04"], ["84052.6", "0.000153"], ["84055.7", "0.04"], ["84055.8", "0.04"], ["84061.3", "0"], ["84062.5", "0.035706"], ["84063", "0.178486"], ["84065.8", "0.003669"], ["84079", "0"], ["84079.1", "0.003392"], ["84092.4", "0.089243"], ["84106.2", "0.178346"], ["84108.7", "0"], ["84113.6", "0.000333"]], "u": 92415, "seq": 67563901368}, "cts": 1742569777916, "record_time": 1742569778.188617, "EXCHANGE": "BYBIT"}
{"topic": "orderbook.200.BTCUSDT", "ts": 1742569778120, "type": "delta", "data": {"s": "BTCUSDT", "b": [["84024.6", "0.031699"], ["83996.6", "0.095989"], ["83993.8", "0.134766"], ["83960.7", "0"]], "a": [["84049", "0.04"], ["84050.5", "0.04"], ["84050.6", "0.09781"], ["84052.3", "0.04"], ["84053", "0"], ["84053.9", "0.04"], ["84054.1", "0.04"], ["84062.9", "0.053546"], ["84065.5", "0.178486"], ["84065.8", "0.182155"], ["84067.2", "0.180086"], ["84071.4", "0.178486"], ["84112.2", "0"], ["84112.3", "0"], ["84112.6", "0"], ["84112.7", "0"], ["84113.1", "0"], ["84113.4", "0"], ["84113.6", "0"]], "u": 92416, "seq": 67563901411}, "cts": 1742569778098, "record_time": 1742569778.389702, "EXCHANGE": "BYBIT"}
{"topic": "orderbook.200.BTCUSDT", "ts": 1742569778319, "type": "delta", "data": {"s": "BTCUSDT", "b": [["84040", "0.399632"], ["84027.9", "0.206439"], ["84027.8", "0.199421"], ["84026.5", "0"], ["84026.2", "0.178516"], ["84025.4", "0"], ["84023.6", "0"], ["84023.5", "0"], ["84021.9", "0"], ["83998.5", "0.0547"], ["83998.4", "0.049549"], ["83996.1", "0.000875"], ["83996", "0"], ["83960.7", "0.063043"], ["83960.4", "0.044"], ["83959.7", "0.000361"], ["83958.8", "0.094"]], "a": [["84040.1", "0.151483"], ["84041", "0"], ["84043.1", "0"], ["84045.6", "0"], ["84047.7", "0"], ["84047.9", "0"], ["84050.6", "0.142174"], ["84052.6", "0"], ["84052.8", "0.071418"], ["84054.7", "0.000153"], ["84055.4", "0.034439"], ["84055.5", "0"], ["84062.5", "0"], ["84063", "0"], ["84063.5", "0.035705"], ["84065.2", "0.27212"], ["84065.3", "0"], ["84065.5", "0"], ["84066.7", "0"], ["84067.2", "0.0016"], ["84068", "0.178486"], ["84068.3", "0.178486"], ["84068.9", "0"], ["84071.4", "0"], ["84075.7", "0.400672"], ["84079.1", "0"], ["84080.7", "0.027189"], ["84080.8", "0"], ["84080.9", "0"], ["84082.4", "0.04"], ["84082.5", "0.040516"], ["84112.2", "0.118852"], ["84112.3", "0.001333"], ["84112.6", "0.0006"], ["84112.7", "0.013077"], ["84113.1", "0.000333"], ["84113.4", "0.089252"], ["84113.6", "0.000333"], ["84114", "0.059399"], ["84114.7", "0.614161"], ["84114.8", "0.00009"]], "u": 92417, "seq": 67563901565}, "cts": 1742569778304, "record_time": 1742569778.587341, "EXCHANGE": "BYBIT"}
{"topic": "orderbook.200.BTCUSDT", "ts": 1742569778520, "type": "delta", "data": {"s": "BTCUSDT", "b": [["84040", "0.400432"], ["84032.2", "0.131633"], ["84031.2", "0.178505"], ["84024.6", "0.01198"], ["84024.2", "0.087301"], ["84003.6", "0.024575"], ["83999.9", "0.049547"], ["83999.8", "0.049547"], ["83998.5", "0.005152"], ["83998.4", "0"], ["83998.1", "0"], ["83990.6", "0.01584"], ["83960.7", "0"], ["83960.4", "0"], ["83959.7", "0"], ["83958.8", "0"]], "a": [["84041.8", "0.071427"], ["84048", "0.007749"], ["84048.3", "0.071421"], ["84050.6", "0.213593"], ["84052.8", "0"], ["84054.7", "0"], ["84054.8", "0.000669"], ["84060.8", "0.036518"], ["84060.9", "0.116392"], ["84062.9", "0.118991"], ["84063.5", "0"], ["84064.2", "0.178435"], ["84065.1", "0.036304"], ["84065.2", "0.074013"], ["84065.8", "0.003669"], ["84067.2", "0.180086"], ["84068", "0"], ["84071.4", "0.178486"], ["84075.7", "0.337157"], ["84078.5", "0.083515"], ["84080.7", "0.023792"], ["84081.3", "0.003397"], ["84082.2", "0"], ["84082.4", "0"], ["84082.5", "0.000516"], ["84083", "0.04"], ["84083.1", "0.04"], ["84084.4", "0.118852"], ["84084.6", "0.023792"], ["84087.7", "0.149352"], ["84095.7", "0"], ["84108.7", "0.12494"], ["84113.4", "0"], ["84113.6", "0"], ["84114", "0"], ["84114.7", "0"], ["84114.8", "0"]], "u": 92418, "seq": 67563901698}, "cts": 1742569778516, "record_time": 1742569778.788218, "EXCHANGE": "BYBIT"}
{"topic": "orderbook.200.BTCUSDT", "ts": 1742569778719, "type": "delta", "data": {"s": "BTCUSDT", "b": [["84031.3", "0.009988"], ["83999.9", "0"], ["83999.8", "0"], ["83999.7", "0.062882"], ["83999.6", "0.062762"], ["83996.6", "0.096009"], ["83960.7", "0.063043"]], "a": [["84053.8", "0.054568"], ["84060.8", "0.051587"], ["84064.2", "0"], ["84065.8", "0.182155"], ["84067.2", "0.0016"], ["84068.3", "0"], ["84071.4", "0"], ["84110.9", "0.12494"], ["84113.4", "0.089252"]], "u": 92419, "seq": 67563901744}, "cts": 1742569778708, "record_time": 1742569778.987634, "EXCHANGE": "BYBIT"}
{"topic": "orderbook.200.BTCUSDT", "ts": 1742569778920, "type": "delta", "data": {"s": "BTCUSDT", "b": [["84017.6", "0.178486"], ["84012.5", "0"], ["84008.4", "0.00018"], ["84005.3", "0.039632"], ["84005.2", "0.039632"], ["84003.5", "0.012881"], ["84003.4", "0.364922"], ["83999.9", "0.05"], ["83999.8", "0.049547"], ["83999.7", "0"], ["83999.6", "0.000333"], ["83996.4", "0"], ["83996.3", "0"], ["83961", "0"], ["83960.7", "0"]], "a": [["84045", "0.023261"], ["84064.4", "0.178525"], ["84078.1", "0.178486"], ["84079.8", "0.178486"], ["84081.1", "0.003397"], ["84081.3", "0"], ["84082.9", "0.041333"], ["84083.1", "0"], ["84084", "0.180984"], ["84113.1", "0"], ["84113.4", "0"]], "u": 92420, "seq": 67563901790}, "cts": 1742569778917, "record_time": 1742569779.188349, "EXCHANGE": "BYBIT"}
{"topic": "orderbook.200.BTCUSDT", "ts": 1742569779120, "type": "delta", "data": {"s": "BTCUSDT", "b": [["84016.8", "0.178576"], ["84012.4", "0.024674"], ["84006.4", "0"], ["84005.4", "0.04"], ["84005.2", "0"], ["84003.6", "0.037575"], ["84003.4", "0.352041"], ["84000", "0.067036"], ["83999.9", "0.049547"], ["83999.8", "0"], ["83996.6", "0.096015"], ["83961", "0.03571"], ["83960.7", "0.063043"]], "a": [["84041.8", "0.074427"], ["84081", "0.003397"], ["84081.1", "0"], ["84082.7", "0.04"], ["84082.8", "0.04"], ["84082.9", "0.001333"], ["84083", "0"], ["84085.2", "0.288267"], ["84112.6", "0"], ["84112.7", "0"]], "u": 92421, "seq": 67563901822}, "cts": 1742569779115, "record_time": 1742569779.407967, "EXCHANGE": "BYBIT"}
{"topic": "orderbook.200.BTCUSDT", "ts": 1742569779320, "type": "delta", "data": {"s": "BTCUSDT", "b": [["84040", "0.292208"], ["84033.1", "0"], ["84032.3", "0"], ["84032.2", "0.084093"], ["84032.1", "0.205974"], ["84031.3", "0"], ["84031.2", "0"], ["84027.9", "0.113"], ["84027.8", "0.020909"], ["84026.2", "0"], ["84025.9", "0.062417"], ["84024.2", "0.190618"], ["84023.3", "0.110292"], ["84022.5", "0.062417"], ["84017.6", "0"], ["84016.8", "0.00009"], ["84016.3", "0.1742"], ["84009.3", "0.27509"], ["84008.4", "0.178666"], ["84005.4", "0.039632"], ["84005.1", "0"], ["84003.6", "0.037456"], ["84000", "0.066583"], ["83960.4", "0.044"], ["83959.7", "0.000361"], ["83958.8", "0.094"]], "a": [["84040.1", "0.329583"], ["84040.2", "0.071428"], ["84041.7", "0.017496"], ["84041.8", "0.003"], ["84046.6", "0.071423"], ["84048.3", "0"], ["84048.5", "0.135449"], ["84051.9", "0.000153"], ["84054.8", "0.000516"], ["84055.4", "0.067032"], ["84056.2", "0.122994"], ["84058.8", "0.178486"], ["84060.8", "0.230073"], ["84062.2", "0.089099"], ["84063", "0.178486"], ["84063.2", "0.166812"], ["84065.8", "0.003669"], ["84070.2", "0.299147"], ["84108.7", "0"], ["84110.9", "0"], ["84111", "0"], ["84111.1", "0"], ["84111.2", "0"], ["84112", "0"], ["84112.2", "0"], ["84112.3", "0"]], "u": 92422, "seq": 67563901943}, "cts": 1742569779316, "record_time": 1742569779.588526, "EXCHANGE": "BYBIT"}
{"topic": "orderbook.200.BTCUSDT", "ts": 1742569779519, "type": "delta", "data": {"s": "BTCUSDT", "b": [["84040", "0.100462"], ["84036.7", "0"], ["84036.6", "0"], ["84033.8", "0"], ["84032.2", "0.057627"], ["84032.1", "0.004974"], ["84031.9", "0"], ["84031.5", "0.171"], ["84027.9", "0.003642"], ["84027.8", "0.001466"], ["84027.7", "0"], ["84026.4", "0"], ["84026.3", "0"], ["84026.1", "0.07144"], ["84025.9", "0"], ["84024.6", "0.0025"], ["84024.2", "0.128201"], ["84023.3", "0"], ["84022.5", "0"], ["84016.3", "0"], ["84009.3", "0.001466"], ["84005.6", "0.0016"], ["84005.4", "0"], ["84005.3", "0"], ["84005.2", "0.04"], ["84005.1", "0.039632"], ["84003.6", "0.024575"], ["84003.5", "0"], ["84003.4", "0.275942"], ["84003.3", "0.366226"], ["84000", "0.017036"], ["83999.9", "0"], ["83999.8", "0.05"], ["83999.7", "0.049547"], ["83998.5", "0.003552"], ["83996.6", "0"], ["83988.2", "0.096015"], ["83958.7", "0.04"], ["83958.5", "0.121466"], ["83958.1", "0.023807"], ["83958", "0.00009"], ["83957.7", "0.00052"], ["83957.6", "0.000333"], ["83957.2", "0.118852"], ["83957.1", "0.04081"]], "a": [["84040.1", "0.500583"], ["84040.8", "0.043474"], ["84040.9", "0.090948"], ["84041.4", "0.0002"], ["84041.7", "0.001466"], ["84047.5", "0.071422"], ["84050.6", "0.142174"], ["84051.9", "0"], ["84055.4", "0.116504"], ["84056.2", "0"], ["84057.8", "0.178449"], ["84057.9", "0.178486"], ["84061.6", "0.058859"], ["84062.9", "0"], ["84063.2", "0"], ["84064.4", "0.00009"], ["84065.2", "0"], ["84066.7", "0.12494"], ["84067.2", "0"], ["84070.2", "0"], ["84070.6", "0.0017"], ["84078", "0.118852"], ["84078.1", "0"], ["84078.5", "0.02"], ["84079.8", "0"], ["84081.4", "0.063518"], ["84082", "1.427181"], ["84084", "0.002498"], ["84110.3", "0"]], "u": 92423, "seq": 67563902112}, "cts": 1742569779517, "record_time": 1742569779.787512, "EXCHANGE": "BYBIT"}
{"topic": "orderbook.200.BTCUSDT", "ts": 1742569779719, "type": "delta", "data": {"s": "BTCUSDT", "b": [["84040", "0.103436"], ["84032.2", "0"], ["84028.2", "0.071438"], ["84027.4", "0.094236"], ["84026.1", "0"], ["84025.8", "0.07144"], ["84024.2", "0.087301"], ["84020.9", "0.068358"], ["84020.7", "0"], ["84014.7", "0.019443"], ["84012.4", "0.060379"], ["84010.7", "0.00948"], ["84010", "0.178486"], ["84005.2", "0"], ["84005.1", "0"], ["84004.1", "0.039633"], ["84004", "0.039633"], ["84003.6", "0"], ["84003.4", "0.262942"], ["84003.3", "0.353345"], ["84002.3", "0.012881"], ["84002.2", "0.012881"], ["83999.8", "0"], ["83999.7", "0"], ["83998.7", "0.049548"], ["83998.6", "0.049548"], ["83997.6", "0.036255"], ["83957.7", "0"], ["83957.6", "0"], ["83957.2", "0"], ["83957.1", "0"]], "a": [["84040.1", "0.504778"], ["84046.4", "0.134699"], ["84051.1", "0"], ["84055.4", "0.279573"], ["84055.9", "0.178453"], ["84057.5", "0.178449"], ["84057.7", "0.060732"], ["84057.8", "0"], ["84058.2", "0.178486"], ["84059.2", "0.178446"], ["84060.8", "0.051587"], ["84061.6", "0.003669"], ["84063", "0.182061"], ["84068.9", "0.12494"], ["84081.4", "0"], ["84081.7", "0.023262"], ["84084.2", "0.06352"], ["84087.7", "0.124952"], ["84108.1", "0"], ["84108.3", "0"], ["84108.9", "0"], ["84109.9", "0"]], "u": 92424, "seq": 67563902246}, "cts": 1742569779715, "record_time": 1742569779.987912, "EXCHANGE": "BYBIT"}
{"topic": "orderbook.200.BTCUSDT", "ts": 1742569779919, "type": "delta", "data": {"s": "BTCUSDT", "b": [["84040", "0"], ["84033.2", "0.201572"], ["84032.1", "0.003643"], ["84031.6", "0.0513"], ["84029.9", "0.071437"], ["84028.3", "0.088789"], ["84028.2", "0"], ["84027.5", "0.064866"], ["84027.4", "0.04"], ["84024.8", "0.015333"], ["84017.7", "0.178534"], ["84016.2", "0.203762"], ["84016", "0.178537"], ["84014.3", "0.179141"], ["84012.5", "0.178501"], ["84012.4", "0.024674"], ["84012.1", "0.004035"], ["84010.7", "0.045187"], ["84010.6", "0.00857"], ["84010.1", "0"], ["84010", "0"], ["84004.1", "0"], ["84004", "0"], ["84003", "0.039628"], ["84002.9", "0.039628"], ["84002.3", "0"], ["84002.2", "0"], ["84001.2", "0.012879"], ["84001.1", "0.012879"], ["83998.7", "0"], ["83998.6", "0"], ["83997.6", "0.085797"], ["83997.5", "0.049542"], ["83991", "0.096017"], ["83990.6", "0"], ["83989.8", "0.099287"], ["83988.2", "0"], ["83958", "0"]], "a": [["84033.3", "0.195601"], ["84037.5", "0.000153"], ["84040", "0.149598"], ["84040.1", "0.401735"], ["84040.8", "0"], ["84040.9", "0.001849"], ["84041.7", "0.016466"], ["84044.7", "0.017684"], ["84046.4", "0.092618"], ["84047.4", "0.015"], ["84047.5", "0"], ["84047.6", "0.00009"], ["84048.5", "0.089099"], ["84049.3", "0.001333"], ["84059.1", "0.171995"], ["84060.8", "0"], ["84067.3", "0.118904"], ["84075.2", "1.427514"], ["84075.7", "0.400677"], ["84082", "0"], ["84084.2", "0"], ["84108", "0"]], "u": 92425, "seq": 67563902479}, "cts": 1742569779906, "record_time": 1742569780.188714, "EXCHANGE": "BYBIT"}
{"topic": "orderbook.200.BTCUSDT", "ts": 1742569780120, "type": "delta", "data": {"s": "BTCUSDT", "b": [["84033.2", "0.095078"], ["84029.9", "0"], ["84027.8", "0.072905"], ["84021.4", "0.007832"], ["84020.9", "0.112163"], ["84010", "0.178501"], ["84003", "0"], ["84002.9", "0"], ["84002.8", "0.039628"], ["84002.7", "0.043264"], ["84001.2", "0"], ["84001.1", "0"], ["84001", "0.012879"], ["84000.9", "0.012879"], ["83997.6", "0.036255"], ["83997.5", "0"], ["83997.4", "0.049542"], ["83997.3", "0.049542"], ["83958.1", "0"]], "a": [["84033.3", "0.180065"], ["84035.8", "0.000153"], ["84037.4", "0.000333"], ["84037.5", "0"], ["84038.4", "0.07143"], ["84040.8", "0.1067"], ["84041.7", "0.047816"], ["84042.5", "0.005335"], ["84043.3", "0.01513"], ["84044.7", "0.003649"], ["84046.4", "0.060424"], ["84046.6", "0"], ["84106.4", "0"], ["84107.3", "0"], ["84107.5", "0"], ["84107.8", "0"]], "u": 92426, "seq": 67563902599}, "cts": 1742569780117, "record_time": 1742569780.388487, "EXCHANGE": "BYBIT"}
{"topic": "orderbook.200.BTCUSDT", "ts": 1742569780320, "type": "delta", "data": {"s": "BTCUSDT", "b": [["84021.4", "0"], ["84012.4", "0.283211"], ["84002.8", "0"], ["84002.6", "0.039628"], ["84001", "0"], ["84000.8", "0.012879"], ["83997.4", "0"], ["83997.2", "0.049542"], ["83958.1", "0.023807"]], "a": [["84035.8", "0"], ["84035.9", "0.000153"], ["84057.9", "0"], ["84106.4", "0.001556"]], "u": 92427, "seq": 67563902629}, "cts": 1742569780309, "record_time": 1742569780.588184, "EXCHANGE": "BYBIT"}
{"topic": "orderbook.200.BTCUSDT", "ts": 1742569780520, "type": "delta", "data": {"s": "BTCUSDT", "b": [["84033.2", "0.188484"], ["84021.4", "0.007849"], ["83997.4", "0.049542"], ["83997.2", "0"], ["83958.1", "0"]], "a": [["84035.9", "0"], ["84038.4", "0"], ["84040.1", "0.230735"], ["84043.3", "0.034666"], ["84043.5", "0.071425"], ["84046.2", "0.060864"], ["84046.4", "0"], ["84055.4", "0.458074"], ["84071.4", "0.08925"]], "u": 92428, "seq": 67563902696}, "cts": 1742569780514, "record_time": 1742569780.789022, "EXCHANGE": "BYBIT"}
{"topic": "orderbook.200.BTCUSDT", "ts": 1742569780720, "type": "delta", "data": {"s": "BTCUSDT", "b": [["84028.3", "0.139403"], ["84027.9", "0.122494"], ["83997.5", "0.05"], ["83997.3", "0"]], "a": [["84037.5", "0.000153"], ["84057.9", "0.178501"], ["84060.9", "0.152098"], ["84065.1", "0.0006"], ["84106.3", "0"], ["84106.4", "0"]], "u": 92429, "seq": 67563902711}, "cts": 1742569780703, "record_time": 1742569780.988491, "EXCHANGE": "BYBIT"}
{"topic": "orderbook.200.BTCUSDT", "ts": 1742569780920, "type": "delta", "data": {"s": "BTCUSDT", "b": [["84033.2", "0.359484"], ["84024.3", "0.059399"], ["84020.9", "0.164647"], ["84020.4", "0.062431"], ["84018.7", "0.062431"], ["84018", "0.178533"], ["84017.7", "0"], ["84016", "0"], ["84014.3", "0.0006"], ["84010", "0"], ["83997.5", "0"], ["83997.4", "0"], ["83997.3", "0.049542"], ["83997.2", "0.049542"], ["83996.6", "0.096004"], ["83991", "0"], ["83958.5", "0"]], "a": [["84033.3", "0.107262"], ["84035.5", "0.071432"], ["84036.7", "0.021575"], ["84037.5", "0"], ["84037.6", "0.000153"], ["84040.1", "0.059735"], ["84040.2", "0"], ["84041.8", "0.174"], ["84045.5", "0.07194"], ["84046.2", "0.051294"], ["84048.5", "0"], ["84055.9", "0"], ["84057.5", "0"], ["84059.2", "0"], ["84060.9", "0.116392"], ["84063", "0.178486"], ["84085.1", "0.059399"], ["84089.2", "0.00015"], ["84106.3", "0.04"], ["84106.4", "0.001556"]], "u": 92430, "seq": 67563902827}, "cts": 1742569780917, "record_time": 1742569781.188616, "EXCHANGE": "BYBIT"}
{"topic": "orderbook.200.BTCUSDT", "ts": 1742569781120, "type": "delta", "data": {"s": "BTCUSDT", "b": [["84033.2", "0.189284"], ["84024.3", "0"], ["84011", "0.05"], ["84010.6", "0.009167"], ["84002.7", "0.003636"], ["84002.6", "0"], ["84002.4", "0.039629"], ["84002.3", "0.039629"], ["84000.9", "0"], ["84000.8", "0"], ["84000.6", "0.301557"], ["84000.5", "0.01288"], ["83996.6", "0.096002"], ["83958.8", "0.044"]], "a": [["84035.5", "0"], ["84036.1", "0.000153"], ["84036.7", "0"], ["84037.6", "0"], ["84043.3", "0.036557"], ["84043.5", "0"], ["84046.2", "0.034134"], ["84059.1", "0"], ["84061", "0.035706"], ["84074.8", "0.003404"], ["84077", "0.003"], ["84081", "0"], ["84107.3", "0.04"], ["84107.5", "0.04"]], "u": 92431, "seq": 67563902962}, "cts": 1742569781089, "record_time": 1742569781.388786, "EXCHANGE": "BYBIT"}
{"topic": "orderbook.200.BTCUSDT", "ts": 1742569781320, "type": "delta", "data": {"s": "BTCUSDT", "b": [["84006.9", "0.291486"], ["83997.4", "0.049542"], ["83997.2", "0"]], "a": [["84036.1", "0"], ["84037.4", "0.000486"], ["84075.1", "0.446074"]], "u": 92432, "seq": 67563902999}, "cts": 1742569781311, "record_time": 1742569781.588208, "EXCHANGE": "BYBIT"}
{"topic": "orderbook.200.BTCUSDT", "ts": 1742569781519, "type": "delta", "data": {"s": "BTCUSDT", "b": [["84033.2", "0.144684"], ["84029.3", "0.0004"], ["84027.9", "0.003642"], ["84016.3", "0.118789"], ["84012.6", "0"], ["84012.5", "0"], ["84009.3", "0.183128"], ["84008.4", "0.00018"], ["84007.5", "0.178501"], ["84005.8", "0"], ["84005.6", "0"], ["84002.8", "0.039628"], ["84002.7", "0.043264"], ["84002.4", "0"], ["84002.3", "0.311339"], ["84001", "0.012879"], ["84000.9", "0.012879"], ["84000.6", "0.288557"], ["84000.5", "0"], ["84000.1", "0.122018"], ["83997.5", "0.05"], ["83997.3", "0"], ["83996.6", "0"], ["83991", "0.096002"], ["83987.4", "0.08925"], ["83984.8", "0"], ["83958.5", "0.121466"]], "a": [["84033.3", "0.278262"], ["84033.4", "0.071434"], ["84036.2", "0.000153"], ["84037.4", "0.000333"], ["84039.3", "0.0001"], ["84041.4", "0"], ["84041.7", "0.119243"], ["84046.2", "0.063072"], ["84049.2", "0.110682"], ["84055.9", "0.178453"], ["84056.2", "0.177438"], ["84057.5", "0.178449"], ["84057.9", "0"], ["84063.2", "0.307382"], ["84068.5", "0.0016"], ["84070.6", "0"], ["84074", "0.003403"], ["84074.8", "0"], ["84075.7", "0.440677"], ["84075.8", "0.589476"], ["84082.7", "0"], ["84082.8", "0"], ["84106.3", "0"], ["84106.4", "0"], ["84107.3", "0"], ["84107.5", "0"]], "u": 92433, "seq": 67563903151}, "cts": 1742569781512, "record_time": 1742569781.787173, "EXCHANGE": "BYBIT"}
{"topic": "orderbook.200.BTCUSDT", "ts": 1742569781720, "type": "delta", "data": {"s": "BTCUSDT", "b": [["84033.2", "0.164584"], ["84028.4", "0.118852"], ["84016.3", "0"], ["84016.2", "0.129758"], ["84010", "0.178501"], ["84009.3", "0.001466"], ["84008.4", "0.178681"], ["84007.5", "0"], ["84004.2", "0.178501"], ["84002.8", "0"], ["84002.7", "0.003636"], ["84002.5", "0.039628"], ["84002.4", "0.039629"], ["84002.3", "0"], ["84001", "0"], ["84000.9", "0"], ["84000.7", "0.012879"], ["84000.6", "0.301437"], ["83997.5", "0"], ["83997.4", "0.05"], ["83997.3", "0.049542"], ["83993.8", "0.230761"], ["83991", "0"], ["83984.9", "0"], ["83958.1", "0.023807"], ["83958", "0.00009"]], "a": [["84033.3", "0.119349"], ["84046.2", "0.034134"], ["84049.2", "0"], ["84056.2", "0"], ["84063.2", "0"], ["84074", "0"], ["84074.6", "0.003403"], ["84075.7", "0.400677"], ["84075.8", "0.549476"], ["84076.3", "0.04"], ["84076.4", "0.04"], ["84106.3", "0.04"]], "u": 92434, "seq": 67563903200}, "cts": 1742569781712, "record_time": 1742569781.988613, "EXCHANGE": "BYBIT"}
{"topic": "orderbook.200.BTCUSDT", "ts": 1742569781919, "type": "delta", "data": {"s": "BTCUSDT", "b": [["84005.8", "0.124951"], ["83997.4", "0"], ["83997.3", "0"], ["83997.1", "0.05"], ["83997", "0.049542"], ["83984.8", "0.124951"], ["83958.1", "0"], ["83958", "0"]], "a": [["84033.3", "0.278262"], ["84033.4", "0"], ["84034.3", "0.021576"], ["84034.4", "0.071433"], ["84036.2", "0"], ["84037.4", "0.000486"], ["84072.9", "0.0671"], ["84074.6", "0"], ["84074.7", "0.003403"], ["84075.7", "0.337157"], ["84076.3", "0"], ["84076.5", "0.04"]], "u": 92435, "seq": 67563903294}, "cts": 1742569781916, "record_time": 1742569782.187291, "EXCHANGE": "BYBIT"}
{"topic": "orderbook.200.BTCUSDT", "ts": 1742569782120, "type": "delta", "data": {"s": "BTCUSDT", "b": [["84033.2", "0.144684"], ["84028.4", "0"], ["84000.9", "0.013"], ["84000.8", "0.012879"], ["84000.7", "0"], ["84000.6", "0.288557"], ["83997.3", "0.049542"], ["83997.2", "0.049542"], ["83997.1", "0"], ["83997", "0"], ["83993.8", "0.134766"], ["83991", "0.095994"], ["83958.5", "0"]], "a": [["84033.3", "0.349696"], ["84034.3", "0"], ["84034.4", "0"], ["84036.4", "0.000153"], ["84037.4", "0.000333"], ["84039.4", "0.071429"], ["84043.3", "0.01513"], ["84045.5", "0.000516"], ["84074.3", "0.053404"], ["84074.7", "0"], ["84106.4", "0.001556"]], "u": 92436, "seq": 67563903385}, "cts": 1742569782102, "record_time": 1742569782.388827, "EXCHANGE": "BYBIT"}
{"topic": "orderbook.200.BTCUSDT", "ts": 1742569782320, "type": "delta", "data": {"s": "BTCUSDT", "b": [["84033.2", "0.046136"], ["84032.2", "0.071435"], ["84031.6", "0"], ["84031.5", "0"], ["84028.3", "0.001333"], ["84027.8", "0.001466"], ["84027.5", "0"], ["84027.4", "0"], ["84027.3", "0"], ["84025.8", "0"], ["84025.7", "0"], ["84025.6", "0"], ["84024.8", "0.126917"], ["84024.7", "0.171"], ["84024.2", "0"], ["84024.1", "0.001928"], ["84024", "0"], ["84023.3", "0.071443"], ["84022.4", "0.000516"], ["84022.3", "0"], ["84021.4", "0"], ["84020.9", "0.120708"], ["84020.8", "0"], ["84020.6", "0.071778"], ["84020.4", "0"], ["84018.7", "0"], ["84018", "0"], ["84017.8", "0.17905"], ["84016.2", "0.203778"], ["84016.1", "0.178537"], ["84014.4", "0.178541"], ["84010.7", "0.00948"], ["84010", "0"], ["84008.4", "0.00018"], ["84005.8", "0"], ["84004.2", "0"], ["84002.5", "0"], ["84002.4", "0"], ["84001", "0.03963"], ["84000.9", "0.03963"], ["84000.8", "0"], ["83999.4", "0.0238"], ["83999.2", "0.01288"], ["83999.1", "0.01288"], ["83997.3", "0"], ["83997.2", "0"], ["83995.6", "0.049544"], ["83995.5", "0.05101"], ["83987.4", "0"], ["83970.9", "0"], ["83963.8", "0.124951"], ["83958.5", "0.121466"], ["83958.1", "0.023807"], ["83958", "0.00009"], ["83957.7", "0.00052"], ["83957.6", "0.000333"], ["83957.2", "0.118852"], ["83957.1", "0.04081"], ["83957", "0.129303"], ["83956.9", "0.001333"], ["83956.7", "0.01872"], ["83956.5", "0.003552"], ["83955.9", "0.057"], ["83955.7", "0.004624"], ["83955.6", "0.013102"], ["83955.4", "0.092637"]], "a": [["84033.3", "0.520849"], ["84036.4", "0"], ["84043.3", "0.04834"], ["84043.6", "0.089099"], ["84044.3", "0.009337"], ["84045.4", "0.018568"], ["84053.8", "0"], ["84055.4", "0.279573"], ["84056.3", "0.003575"], ["84057.6", "0"], ["84058.2", "0"], ["84058.3", "0"], ["84058.8", "0"], ["84062.9", "0.020833"], ["84063", "0"], ["84070", "0.067195"], ["84072.8", "0.00009"], ["84072.9", "0.003575"], ["84107.3", "0.04"], ["84107.5", "0.04"]], "u": 92437, "seq": 67563903650}, "cts": 1742569782313, "record_time": 1742569782.588285, "EXCHANGE": "BYBIT"}
{"topic": "orderbook.200.BTCUSDT", "ts": 1742569782520, "type": "delta", "data": {"s": "BTCUSDT", "b": [["84033.2", "0.315684"], ["84032.2", "0"], ["84025.4", "0.021459"], ["84025.3", "0.071441"], ["84023.3", "0"], ["84020.7", "0.044"], ["84019", "0.04"], ["84015.6", "0.048"], ["84012.4", "0.180581"], ["84009.4", "0.035707"], ["84005", "0.178501"], ["84001", "0"], ["84000.9", "0"], ["84000.8", "0.04"], ["84000.7", "0.03963"], ["84000", "0.195537"], ["83999.2", "0"], ["83999.1", "0"], ["83999", "0.012998"], ["83998.9", "0.014213"], ["83989.8", "0.06374"], ["83987.4", "0.08925"], ["83966.4", "0.08943"], ["83955.9", "0"], ["83955.7", "0"], ["83955.6", "0"], ["83955.4", "0"]], "a": [["84033.3", "0.349696"], ["84034.1", "0.000153"], ["84046.2", "0.130808"], ["84048.4", "0.054568"], ["84050.4", "0.357002"], ["84054.6", "0.178501"], ["84055.4", "0"], ["84055.7", "0.218501"], ["84106.4", "0"], ["84107.3", "0"], ["84107.5", "0"]], "u": 92438, "seq": 67563903728}, "cts": 1742569782496, "record_time": 1742569782.788611, "EXCHANGE": "BYBIT"}
{"topic": "orderbook.200.BTCUSDT", "ts": 1742569782719, "type": "delta", "data": {"s": "BTCUSDT", "b": [["84033.2", "0.315982"], ["84027.4", "0.043154"], ["84027.3", "0.071439"], ["84025.4", "0"], ["84022.5", "0.04"], ["84022.4", "0.040516"], ["84020.9", "0.128425"], ["84020.7", "0.084"], ["84020.6", "0.000333"], ["84019", "0.084"], ["84017.4", "0.04"], ["84017.3", "0.04"], ["84015.8", "0.052"], ["84011.1", "0.053639"], ["84011", "0"], ["84010.6", "0"], ["84010.1", "0.02022"], ["84004.2", "0.178501"], ["83995.7", "0.05"], ["83995.5", "0.001466"], ["83991.1", "0.10938"], ["83989.8", "0"], ["83957.2", "0"], ["83957.1", "0"], ["83957", "0"], ["83956.9", "0"], ["83956.7", "0"], ["83956.5", "0"]], "a": [["84033.3", "0.178696"], ["84039.4", "0"], ["84043.3", "0.059146"], ["84043.6", "0"], ["84044.3", "0.080762"], ["84106.4", "0.001556"], ["84107.3", "0.04"]], "u": 92439, "seq": 67563903796}, "cts": 1742569782697, "record_time": 1742569782.987879, "EXCHANGE": "BYBIT"}
{"topic": "orderbook.200.BTCUSDT", "ts": 1742569782920, "type": "delta", "data": {"s": "BTCUSDT", "b": [["84033.2", "0.486982"], ["83995.7", "0"], ["83995.6", "0"], ["83995.4", "0.050333"], ["83995.3", "0.049544"], ["83957.2", "0.118852"]], "a": [["84034.1", "0"], ["84056.3", "0"], ["84070", "0.00367"], ["84072.9", "0.067098"], ["84073.9", "0.04"], ["84074", "0.04"], ["84076.4", "0"], ["84076.5", "0"], ["84107.5", "0.04"], ["84107.8", "0.003563"]], "u": 92440, "seq": 67563903852}, "cts": 1742569782916, "record_time": 1742569783.188398, "EXCHANGE": "BYBIT"}
{"topic": "orderbook.200.BTCUSDT", "ts": 1742569783119, "type": "delta", "data": {"s": "BTCUSDT", "b": [["84033.2", "0.315982"], ["84022.1", "0.064874"], ["84007.5", "0.095724"], ["84005", "0"], ["84000", "0.017036"], ["83999.1", "0.01288"], ["83998.9", "0.001333"], ["83995.5", "0.05101"], ["83995.4", "0.049877"], ["83995.3", "0"], ["83957.2", "0"]], "a": [["84033.3", "0.369696"], ["84034.9", "0.000153"], ["84070", "0.067193"], ["84071.9", "0.003404"], ["84072.9", "0.003575"], ["84073.9", "0"], ["84074", "0"], ["84074.1", "0.041466"], ["84074.2", "0.04367"], ["84074.3", "0.05"], ["84077", "0"], ["84108.1", "0.001333"]], "u": 92441, "seq": 67563903894}, "cts": 1742569783088, "record_time": 1742569783.388129, "EXCHANGE": "BYBIT"}
{"topic": "orderbook.200.BTCUSDT", "ts": 1742569783320, "type": "delta", "data": {"s": "BTCUSDT", "b": [["84005", "0.178501"], ["84000.8", "0.03963"], ["84000", "0.195537"], ["83999.1", "0"], ["83998.9", "0.014213"], ["83995.5", "0.001466"], ["83995.3", "0.049544"], ["83957.6", "0"]], "a": [["84055.6", "0.205534"], ["84071.9", "0"], ["84072", "0.003401"], ["84108", "0.171"], ["84108.1", "0"]], "u": 92442, "seq": 67563903922}, "cts": 1742569783309, "record_time": 1742569783.588173, "EXCHANGE": "BYBIT"}
{"topic": "orderbook.200.BTCUSDT", "ts": 1742569783519, "type": "delta", "data": {"s": "BTCUSDT", "b": [["84010.1", "0.019842"], ["84000.2", "0.0016"], ["84000.1", "0.120318"], ["83995.6", "0.05"], ["83995.5", "0.05101"], ["83995.4", "0.000333"], ["83995.3", "0"], ["83957.7", "0"]], "a": [["84068.4", "0.0016"], ["84068.5", "0"]], "u": 92443, "seq": 67563903969}, "cts": 1742569783507, "record_time": 1742569783.787226, "EXCHANGE": "BYBIT"}
{"topic": "orderbook.200.BTCUSDT", "ts": 1742569783720, "type": "delta", "data": {"s": "BTCUSDT", "b": [["83999.2", "0.013"], ["83999.1", "0.01288"], ["83999", "0.000118"], ["83998.9", "0.001333"], ["83958.1", "0"], ["83958", "0"]], "a": [["84039.6", "0.071429"], ["84043.3", "0.023501"], ["84044.3", "0.009337"], ["84052", "0.001233"], ["84052.1", "0.001268"], ["84071.8", "0.003401"], ["84072", "0"], ["84107.5", "0"], ["84107.8", "0"], ["84108", "0"]], "u": 92444, "seq": 67563903996}, "cts": 1742569783714, "record_time": 1742569783.988256, "EXCHANGE": "BYBIT"}
{"topic": "orderbook.200.BTCUSDT", "ts": 1742569783920, "type": "delta", "data": {"s": "BTCUSDT", "b": [["83999.2", "0"], ["83999.1", "0"], ["83999", "0.012998"], ["83998.9", "0.014213"], ["83995.6", "0"], ["83995.5", "0.001466"], ["83995.4", "0.049877"], ["83995.3", "0.049544"], ["83958.1", "0.023807"], ["83958", "0.00009"]], "a": [["84034.9", "0"], ["84035.8", "0.000153"], ["84039.6", "0"], ["84041.7", "0.047816"], ["84043.3", "0.041991"], ["84044.1", "0.071425"], ["84052", "0"], ["84052.1", "0"], ["84071.8", "0"], ["84072.1", "0.003401"], ["84107.5", "0.04"], ["84107.8", "0.003563"]], "u": 92445, "seq": 67563904025}, "cts": 1742569783917, "record_time": 1742569784.188829, "EXCHANGE": "BYBIT"}
{"topic": "orderbook.200.BTCUSDT", "ts": 1742569784120, "type": "delta", "data": {"s": "BTCUSDT", "b": [["84033.2", "0.096208"], ["84027.4", "0.021722"], ["84027.3", "0"], ["84022.5", "0.111443"], ["84020.9", "0.120708"], ["84007.5", "0"], ["84005", "0"], ["84004.2", "0"], ["83995.7", "0.05"], ["83995.6", "0.049544"], ["83995.4", "0.000333"], ["83995.3", "0"], ["83957.7", "0.00052"], ["83957.6", "0.000333"], ["83957.2", "0.118852"]], "a": [["84033.3", "0.540696"], ["84034.9", "0.000153"], ["84035.8", "0"], ["84039.7", "0.071429"], ["84048.1", "0.089099"], ["84107.5", "0"], ["84107.8", "0"]], "u": 92446, "seq": 67563904070}, "cts": 1742569784114, "record_time": 1742569784.387956, "EXCHANGE": "BYBIT"}
{"topic": "orderbook.200.BTCUSDT", "ts": 1742569784320, "type": "delta", "data": {"s": "BTCUSDT", "b": [["84033.2", "0.290438"], ["84027.5", "0.036725"], ["84027.4", "0.071439"], ["84022.5", "0.04"], ["84020.9", "0.128328"], ["84005", "0.178501"], ["84004.2", "0.178501"], ["84000.8", "0"], ["84000.6", "0.328187"], ["83999", "0.000118"], ["83998.9", "0.014333"], ["83998.8", "0.01288"], ["83995.7", "0"], ["83995.6", "0"], ["83995.3", "0.05"], ["83995.2", "0.049544"], ["83957.7", "0"], ["83957.6", "0"], ["83957.2", "0"]], "a": [["84033.3", "0.369696"], ["84034.9", "0"], ["84035", "0.000153"], ["84043.3", "0.044929"], ["84060.8", "0.08021"], ["84071.1", "0.003401"], ["84072.1", "0"], ["84107.3", "0"]], "u": 92447, "seq": 67563904155}, "cts": 1742569784307, "record_time": 1742569784.603138, "EXCHANGE": "BYBIT"}
{"topic": "orderbook.200.BTCUSDT", "ts": 1742569784520, "type": "delta", "data": {"s": "BTCUSDT", "b": [["84033.2", "0.119438"], ["84020.9", "0.194984"], ["84001.1", "0.03963"], ["84001", "0.03963"], ["84000.7", "0"], ["84000.6", "0.288557"], ["83999.3", "0.0134"], ["83999.2", "0.01288"], ["83998.9", "0.001333"], ["83998.8", "0"], ["83995.7", "0.049544"], ["83995.6", "0.049544"], ["83995.3", "0"], ["83995.2", "0"], ["83958", "0"]], "a": [["84035", "0"], ["84035.5", "0.000153"], ["84043.1", "0.044929"], ["84043.3", "0"], ["84050.6", "0.20777"], ["84054.1", "0.043575"], ["84070.9", "0.003401"], ["84071.1", "0"], ["84072.6", "0.04"], ["84072.7", "0.04"], ["84074.1", "0.001466"], ["84074.2", "0.00367"], ["84106.3", "0"], ["84106.4", "0"]], "u": 92448, "seq": 67563904218}, "cts": 1742569784516, "record_time": 1742569784.788089, "EXCHANGE": "BYBIT"}
{"topic": "orderbook.200.BTCUSDT", "ts": 1742569784720, "type": "delta", "data": {"s": "BTCUSDT", "b": [["84018.7", "0.11033"], ["84008.2", "0.172258"], ["84001.2", "0.304168"], ["83984.9", "0.095104"], ["83958.8", "0"], ["83958.7", "0"], ["83958.5", "0"], ["83958.1", "0"]], "a": [["84043.1", "0.072756"], ["84043.2", "0.11148"], ["84053.7", "0.183082"], ["84054.1", "0.04"], ["84060.7", "0.28759"], ["84105.7", "0"], ["84105.9", "0"], ["84106.2", "0"]], "u": 92449, "seq": 67563904250}, "cts": 1742569784717, "record_time": 1742569784.988364, "EXCHANGE": "BYBIT"}
{"topic": "orderbook.200.BTCUSDT", "ts": 1742569784920, "type": "delta", "data": {"s": "BTCUSDT", "b": [["84033.2", "0.290425"], ["84018.7", "0"], ["84008.2", "0"], ["84001.2", "0"], ["83958.8", "0.044"], ["83958.7", "0.04"], ["83958.5", "0.121466"]], "a": [["84042.1", "0.003575"], ["84043.1", "0.044929"], ["84043.2", "0"], ["84053.7", "0"], ["84060.7", "0"], ["84105.7", "0.011993"], ["84105.9", "0.045"]], "u": 92450, "seq": 67563904274}, "cts": 1742569784875, "record_time": 1742569785.187743, "EXCHANGE": "BYBIT"}
{"topic": "orderbook.200.BTCUSDT", "ts": 1742569785120, "type": "delta", "data": {"s": "BTCUSDT", "b": [["84033.2", "0.09536"], ["84027.5", "0.021722"], ["84027.4", "0"], ["84022.2", "0.071443"], ["84020.9", "0.187364"], ["84005", "0"], ["84004.2", "0"], ["84001.1", "0"], ["84001", "0"], ["84000.8", "0.04"], ["84000.7", "0.03963"], ["84000", "0.017036"], ["83999.3", "0.00052"], ["83999.2", "0"], ["83999.1", "0.013"], ["83999", "0.012998"], ["83995.7", "0"], ["83995.6", "0"], ["83995.5", "0.05101"], ["83995.4", "0.049877"], ["83987.4", "0"], ["83975.6", "0.003"], ["83958.1", "0.023807"], ["83958", "0.00009"], ["83957.7", "0.00052"], ["83957.6", "0.000333"]], "a": [["84033.3", "0.540696"], ["84035.7", "0.02683"], ["84035.8", "0.089099"], ["84042.1", "0"], ["84057.3", "0.007244"], ["84070.5", "0.0034"], ["84070.9", "0"], ["84105.9", "0"]], "u": 92451, "seq": 67563904351}, "cts": 1742569785103, "record_time": 1742569785.387962, "EXCHANGE": "BYBIT"}
{"topic": "orderbook.200.BTCUSDT", "ts": 1742569785319, "type": "delta", "data": {"s": "BTCUSDT", "b": [["84033.2", "0"], ["84032.5", "0"], ["84032.4", "0"], ["84032.1", "0.007938"], ["84030.2", "0.071437"], ["84029.3", "0"], ["84027.5", "0"], ["84025.3", "0"], ["84024.8", "0.111917"], ["84024.1", "0.016928"], ["84022.9", "0.071443"], ["84022.2", "0"], ["84021.3", "0"], ["84021.1", "0.118852"], ["84020.9", "0.120708"], ["84018.6", "0.072913"], ["84016.9", "0"], ["84009.4", "0"], ["84008.6", "0.116385"], ["84006.9", "0.312198"], ["84000.8", "0"], ["84000.7", "0"], ["83999.9", "0.03963"], ["83999.8", "0.03963"], ["83999.1", "0"], ["83999", "0.000118"], ["83998.1", "0.01288"], ["83998", "0.01288"], ["83997.6", "0.011906"], ["83996.7", "0"], ["83995.5", "0.001466"], ["83995.4", "0.000333"], ["83994.6", "0.049544"], ["83994.5", "0.049544"], ["83991", "0"], ["83990.6", "0.02264"], ["83988.2", "0.095979"], ["83984.8", "0"], ["83984.1", "0"], ["83966.4", "0.00018"], ["83957.2", "0.118852"], ["83957.1", "0.04081"], ["83957", "0.129303"], ["83956.9", "0.001333"], ["83956.7", "0.01872"]], "a": [["84032.2", "0.413963"], ["84032.3", "0.055693"], ["84032.5", "0.257255"], ["84032.6", "0.195165"], ["84033.2", "0.042048"], ["84033.3", "0.191"], ["84035.5", "0"], ["84035.7", "0"], ["84036.7", "0.001333"], ["84037.1", "0.001466"], ["84037.8", "0.07143"], ["84040", "0"], ["84040.1", "0.004042"], ["84040.7", "0.099209"], ["84041", "0.015"], ["84041.7", "0.032816"], ["84043.1", "0"], ["84044.1", "0"], ["84044.6", "0.0207"], ["84046.2", "0.185804"], ["84047.8", "0.178501"], ["84048", "0.067148"], ["84050.4", "0.178501"], ["84054.2", "0.178789"], ["84055.7", "0.04"], ["84055.9", "0"], ["84057.3", "0.185694"], ["84063.7", "0"], ["84064.6", "0.065828"], ["84070", "0.00367"], ["84070.5", "0"], ["84070.6", "0.0034"], ["84072.9", "0.185949"], ["84074.1", "1.428647"], ["84074.7", "0.022875"], ["84075.2", "0.000333"], ["84077.4", "0"], ["84081.7", "0"], ["84104.6", "0"], ["84104.9", "0"], ["84105.6", "0"], ["84105.7", "0"]], "u": 92452, "seq": 67563904727}, "cts": 1742569785318, "record_time": 1742569785.587572, "EXCHANGE": "BYBIT"}
