{"topic": "orderbook.200.BTCUSDT", "ts": 1742543250520, "type": "snapshot", "data": {"s": "BTCUSDT", "b": [["83876.8", "0.436696"], ["83874.8", "0.109832"], ["83874.63", "0.005963"], ["83874.35", "0.000525"], ["83873.51", "0.000099"], ["83873.5", "0.0012"], ["83872.62", "0.002098"], ["83872.61", "0.000591"], ["83872.34", "0.336365"], ["83872.03", "0.004484"], ["83871.98", "0.000189"], ["83871.22", "0.001799"], ["83869.86", "0.001996"], ["83869.34", "0.001333"], ["83869.1", "0.008968"], ["83868.74", "0.000255"], ["83868.57", "0.001008"], ["83868.21", "0.000255"], ["83867.79", "0.00019"], ["83867.53", "0.005961"], ["83867.24", "0.017891"], ["83867.19", "0.001996"], ["83867.03", "0.000333"], ["83866.97", "0.001996"], ["83866.76", "0.002982"], ["83866.61", "0.001466"], ["83866.06", "0.119407"], ["83866.05", "0.166336"], ["83865.99", "0.06919"], ["83865.57", "0.05874"], ["83865.48", "0.003"], ["83865.15", "0.23419"], ["83865.14", "0.001333"], ["83864.91", "0.017937"], ["83864.61", "0.023847"], ["83864.6", "0.0006"], ["83864.5", "0.003861"], ["83864.44", "0.120055"], ["83864.21", "0.116197"], ["83864.13", "0.000255"], ["83863.6", "0.000255"], ["83863.59", "0.00019"], ["83863.35", "0.022493"], ["83862.84", "0.000333"], ["83862.4", "0.04"], ["83862.3", "0.0006"], ["83862.28", "0.170602"], ["83862.27", "0.171"], ["83862", "0.002066"], ["83861.77", "0.00009"], ["83861", "0.04"], ["83860.95", "0.001333"], ["83860.7", "0.04"], ["83860.6", "0.117967"], ["83860.34", "0.046405"], ["83860", "0.04006"], ["83859.72", "0.119407"], ["83859.71", "0.009677"], ["83859.64", "0.06215"], ["83859.51", "0.000255"], ["83859.4", "0.000191"], ["83859", "0.04"], ["83858.99", "0.000255"], ["83858.64", "0.000333"], ["83858.51", "0.978174"], ["83858.01", "0.029256"], ["83857.78", "1"], ["83857.39", "0.001466"], ["83857.3", "0.04"], ["83857.18", "0.000084"], ["83856.97", "0.023398"], ["83856.76", "0.001333"], ["83856.56", "0.008805"], ["83856.54", "0.005961"], ["83856.53", "0.127277"], ["83856.45", "0.018093"], ["83856.3", "0.04"], ["83855.9", "0.04"], ["83855.75", "0.089922"], ["83855.6", "0.04"], ["83855.36", "0.017899"], ["83855.21", "0.000195"], ["83854.92", "0.114992"], ["83854.9", "0.000255"], ["83854.86", "0.012007"], ["83854.8", "0.000597"], ["83854.77", "1.345344"], ["83854.7", "0.04"], ["83854.66", "0.05962"], ["83854.45", "0.000333"], ["83854.41", "0.185827"], ["83854.39", "0.119407"], ["83854.38", "0.000255"], ["83853.6", "0.186481"], ["83853.42", "0.023848"], ["83853.34", "0.00009"], ["83852.99", "0.071588"], ["83852.77", "0.001466"], ["83852.64", "0.06066"], ["83852.57", "0.001333"], ["83851.02", "0.000195"], ["83851.01", "0.003374"], ["83850.97", "0.058414"], ["83850.9", "0.119222"], ["83850.29", "0.000255"], ["83850.26", "0.000333"], ["83850.06", "0.120354"], ["83849.76", "0.000255"], ["83849.5", "0.0006"], ["83849.49", "0.071591"], ["83849.41", "0.000298"], ["83849.23", "0.000298"], ["83848.81", "0.119407"], ["83848.79", "0.171"], ["83848.74", "0.003"], ["83848.37", "0.001333"], ["83848.16", "0.001466"], ["83847.54", "0.001127"], ["83846.82", "0.000195"], ["83846.6", "0.274544"], ["83846.52", "0.003"], ["83846.51", "0.0015"], ["83846.27", "0.04546"], ["83846.07", "0.000333"], ["83846.04", "0.310393"], ["83846.03", "0.811485"], ["83845.68", "0.000255"], ["83845.64", "0.119952"], ["83845.31", "0.301078"], ["83845.15", "0.000255"], ["83844.91", "0.00009"], ["83844.38", "0.023844"], ["83844.18", "0.001333"], ["83843.55", "0.001466"], ["83843.43", "0.017899"], ["83842.63", "0.000196"], ["83842.15", "0.058414"], ["83842.14", "0.119407"], ["83841.87", "0.000333"], ["83841.07", "0.000255"], ["83840.54", "0.000255"], ["83840.21", "0.089922"], ["83840", "0.00066"], ["83839.99", "0.001333"], ["83838.94", "0.001466"], ["83838.88", "0.11"], ["83838.44", "0.000196"], ["83838.03", "0.127279"], ["83837.91", "0.171"], ["83837.82", "0.00036"], ["83837.68", "0.000333"], ["83837.46", "0.046405"], ["83837.21", "0.035775"], ["83836.48", "0.00009"], ["83836.45", "0.000255"], ["83836.4", "0.0006"], ["83836.1", "0.066066"], ["83836.09", "0.119407"], ["83835.93", "0.000255"], ["83835.9", "0.0016"], ["83835.8", "0.001333"], ["83834.8", "0.000147"], ["83834.33", "0.001466"], ["83834.25", "0.000197"], ["83833.69", "0.058414"], ["83833.49", "0.000333"], ["83831.84", "0.000255"], ["83831.6", "0.001333"], ["83831.56", "0.023845"], ["83831.38", "0.024675"], ["83831.33", "0.009"], ["83831.32", "0.000255"], ["83831.11", "0.000619"], ["83830.15", "0.015"], ["83830.06", "0.000198"], ["83830", "0.007487"], ["83829.72", "0.001466"], ["83829.32", "0.357833"], ["83829.3", "0.000333"], ["83829.28", "0.171"], ["83829.12", "0.011929"], ["83828.86", "0.005962"], ["83828.05", "0.00009"], ["83827.81", "0.00875"], ["83827.5", "0.04"], ["83827.49", "0.039646"], ["83827.47", "0.013"], ["83827.46", "0.012885"], ["83827.41", "0.001333"], ["83827.23", "0.000255"], ["83826.71", "0.000255"], ["83826.02", "0.119407"], ["83825.88", "0.005961"], ["83825.86", "0.000198"], ["83825.4", "0.023845"], ["83825.11", "0.001799"], ["83824.94", "0.05"], ["83824.93", "0.049561"], ["83824", "0.000118"], ["83823.65", "0.089922"]], "a": [["83876.81", "0.256214"], ["83877.44", "0.000256"], ["83877.73", "0.001333"], ["83877.95", "0.012077"], ["83877.96", "0.000256"], ["83878.1", "0.0002"], ["83878.26", "0.00315"], ["83879.61", "0.000333"], ["83879.7", "0.0036"], ["83880.03", "0.071565"], ["83880.37", "0.000225"], ["83880.45", "0.002311"], ["83880.56", "0.000083"], ["83880.95", "0.009077"], ["83880.99", "0.011921"], ["83881.1", "0.0006"], ["83881.29", "0.007924"], ["83881.92", "0.15114"], ["83881.93", "0.171"], ["83882.05", "0.000256"], ["83882.48", "0.178822"], ["83882.58", "0.000256"], ["83883.42", "0.178834"], ["83883.51", "0.011921"], ["83883.6", "0.0006"], ["83883.8", "0.000333"], ["83884.13", "0.000226"], ["83884.14", "0.159847"], ["83884.15", "0.178818"], ["83884.22", "0.015849"], ["83884.56", "0.000225"], ["83884.78", "0.000153"], ["83884.86", "0.005963"], ["83885.06", "0.001466"], ["83885.1", "0.0006"], ["83885.83", "0.178814"], ["83886.11", "0.001333"], ["83886.66", "0.021894"], ["83887.03", "0.005961"], ["83887.12", "0.12147"], ["83887.19", "0.000256"], ["83888", "0.000333"], ["83888.42", "0.031696"], ["83888.5", "0.1"], ["83888.76", "0.000225"], ["83888.89", "0.472164"], ["83888.9", "0.108"], ["83888.94", "0.114783"], ["83889.06", "0.023724"], ["83889.22", "0.178834"], ["83889.41", "0.116057"], ["83889.44", "0.003503"], ["83889.46", "0.125188"], ["83889.68", "0.001466"], ["83889.85", "0.00009"], ["83889.88", "0.004701"], ["83890", "0.000243"], ["83890.31", "0.001333"], ["83890.32", "0.171"], ["83890.38", "0.003"], ["83890.5", "0.192"], ["83890.94", "0.00018"], ["83891.15", "0.01789"], ["83891.28", "0.000256"], ["83891.33", "0.009"], ["83891.52", "0.344122"], ["83891.8", "0.000256"], ["83891.83", "0.178834"], ["83892.1", "0.108"], ["83892.19", "0.000333"], ["83892.41", "0.397722"], ["83892.57", "0.125184"], ["83892.95", "0.000225"], ["83893", "0.104"], ["83893.27", "0.009982"], ["83893.5", "0.117559"], ["83893.76", "0.00036"], ["83893.79", "0.019147"], ["83893.8", "0.289603"], ["83893.9", "0.104"], ["83894", "0.003796"], ["83894.29", "0.001466"], ["83894.32", "0.046405"], ["83894.34", "0.013848"], ["83894.4", "0.116"], ["83894.5", "0.001333"], ["83894.64", "0.057208"], ["83895.07", "0.016394"], ["83895.12", "0.058414"], ["83895.4", "0.1"], ["83895.5", "0.112"], ["83895.89", "0.000256"], ["83895.94", "0.035775"], ["83895.97", "0.0008"], ["83896.02", "0.178834"], ["83896.39", "0.000333"], ["83896.42", "0.000256"], ["83897.12", "0.29647"], ["83897.13", "0.12433"], ["83897.15", "0.000225"], ["83897.25", "0.003576"], ["83897.49", "0.023845"], ["83897.59", "0.003541"], ["83897.67", "0.119227"], ["83897.86", "0.023845"], ["83898.28", "0.00009"], ["83898.3", "0.0006"], ["83898.7", "0.001333"], ["83898.71", "0.171"], ["83898.91", "0.001466"], ["83899.06", "0.003575"], ["83899.21", "0.186356"], ["83899.4", "0.0006"], ["83899.44", "0.178088"], ["83899.67", "0.022"], ["83900", "0.007442"], ["83900.5", "0.167628"], ["83900.51", "0.000256"], ["83900.58", "0.000333"], ["83900.9", "0.008805"], ["83901.03", "0.000256"], ["83901.34", "0.000225"], ["83901.64", "0.054667"], ["83902.35", "0.114757"], ["83902.69", "0.000199"], ["83902.89", "0.001333"], ["83902.98", "0.023845"], ["83903.52", "0.001466"], ["83903.8", "0.0006"], ["83903.9", "0.023845"], ["83904.27", "0.001"], ["83904.59", "0.691714"], ["83904.6", "2.305712"], ["83904.78", "0.000333"], ["83905.12", "0.000256"], ["83905.54", "0.000225"], ["83905.59", "0.005961"], ["83905.65", "0.000256"], ["83906", "0.071542"], ["83906.1", "1.314219"], ["83906.22", "0.217075"], ["83906.23", "0.482462"], ["83906.4", "0.017899"], ["83906.44", "0.295592"], ["83906.51", "0.0015"], ["83906.52", "0.003"], ["83906.71", "0.00009"], ["83906.8", "0.00169"], ["83907.09", "0.001333"], ["83907.1", "0.171"], ["83907.12", "0.003"], ["83907.21", "0.023845"], ["83907.34", "0.017899"], ["83907.5", "0.312289"], ["83908.13", "0.001466"], ["83908.31", "0.271715"], ["83908.64", "0.108453"], ["83908.97", "0.000333"], ["83909", "0.000118"], ["83909.73", "0.000225"], ["83909.74", "0.000256"], ["83910.25", "0.130624"], ["83910.26", "0.000256"], ["83910.41", "0.125199"], ["83910.75", "0.001173"], ["83911.09", "0.000111"], ["83911.27", "0.071538"], ["83911.28", "0.001333"], ["83911.88", "0.058414"], ["83912.75", "0.001466"], ["83913.17", "0.000333"], ["83913.48", "0.001071"], ["83913.49", "0.000354"], ["83913.53", "0.125188"], ["83913.62", "0.023845"], ["83913.93", "0.000225"], ["83914.35", "0.000256"], ["83914.88", "0.000256"], ["83915.14", "0.00009"], ["83915.26", "0.02365"], ["83915.48", "0.001333"], ["83915.49", "0.171"], ["83915.81", "0.005961"], ["83915.87", "0.00036"], ["83916.98", "0.089417"], ["83917.36", "0.001799"], ["83917.77", "0.00282"], ["83918.12", "0.000225"], ["83918.74", "0.953304"], ["83918.97", "0.000256"], ["83919.49", "0.000256"], ["83919.67", "0.001333"], ["83919.69", "0.005"], ["83920.1", "0.073666"], ["83920.32", "0.04"], ["83920.33", "0.04"], ["83920.44", "0.046405"], ["83920.92", "0.00143"], ["83921.28", "0.023108"], ["83921.33", "0.009"]], "u": 69219, "seq": 67537853882}, "cts": 1742543250517, "record_time": 1742543252.883602}
{"topic": "orderbook.200.BTCUSDT", "ts": 1742543250720, "type": "delta", "data": {"s": "BTCUSDT", "b": [["83866.05", "0.123613"], ["83864.61", "0"], ["83864.46", "0.112501"], ["83864.44", "0"], ["83864.22", "0.122768"], ["83864.21", "0"], ["83860.61", "0.11953"], ["83860.6", "0"], ["83859.65", "0.058254"], ["83859.64", "0"], ["83854.86", "0"], ["83854.42", "0.182425"], ["83854.41", "0"], ["83853.61", "0.170951"], ["83853.6", "0"], ["83852.65", "0.054786"], ["83852.64", "0"], ["83846.61", "0.297212"], ["83846.6", "0"], ["83845.65", "0.123334"], ["83845.64", "0"], ["83845.32", "0.295919"], ["83845.31", "0"], ["83838.88", "0"], ["83838.03", "0.127264"], ["83834.8", "0.000132"], ["83829.32", "0"], ["83828.18", "0.013"], ["83828.17", "0.012884"], ["83827.51", "0.357835"], ["83827.47", "0"], ["83827.46", "0"], ["83823.34", "0.004635"], ["83823.22", "0.001333"], ["83822.62", "0.000255"]], "a": [["83880.5", "0.0003"], ["83882.91", "0.000153"], ["83884.78", "0"], ["83886.7", "0.178834"], ["83887.64", "0.178834"], ["83888.94", "0"], ["83888.96", "0.123014"], ["83889.41", "0"], ["83889.42", "0.119929"], ["83893.5", "0"], ["83893.51", "0.110153"], ["83894.64", "0"], ["83894.65", "0.061772"], ["83895.94", "0"], ["83896.02", "0"], ["83899.21", "0"], ["83899.22", "0.184253"], ["83899.44", "0"], ["83899.46", "0.165018"], ["83900.5", "0"], ["83900.51", "0.166159"], ["83901.64", "0"], ["83901.65", "0.057437"], ["83903.75", "0.028239"], ["83906.44", "0"], ["83906.46", "0.308801"], ["83907.5", "0"], ["83907.51", "0.299834"], ["83908.31", "0"], ["83908.32", "0.284551"], ["83908.64", "0"], ["83908.65", "0.113045"], ["83913.47", "0.0004"], ["83913.48", "0.001025"], ["83913.49", "0"], ["83920.98", "0.013"], ["83921.28", "0"], ["83921.33", "0"]], "u": 69220, "seq": 67537854109}, "cts": 1742543250717, "record_time": 1742543252.884909}
{"topic": "orderbook.200.BTCUSDT", "ts": 1742543250919, "type": "delta", "data": {"s": "BTCUSDT", "b": [["83876.8", "0"], ["83874.8", "0"], ["83874.63", "0"], ["83874.35", "0"], ["83873.51", "0"], ["83873.5", "0"], ["83872.62", "0"], ["83872.61", "0"], ["83872.34", "0.389938"], ["83872.03", "0"], ["83869.1", "0"], ["83867.24", "0"], ["83866.76", "0"], ["83866.13", "0.008968"], ["83866.06", "0"], ["83866.05", "0"], ["83865.48", "0"], ["83864.91", "0"], ["83864.6", "0"], ["83864.5", "0"], ["83864.46", "0"], ["83864.22", "0"], ["83863.35", "0"], ["83862.4", "0"], ["83862.28", "0.007676"], ["83862.27", "0"], ["83861.95", "0.030037"], ["83861.94", "0.017938"], ["83861", "0"], ["83860.7", "0"], ["83860.61", "0"], ["83860.34", "0"], ["83859.72", "0"], ["83859.71", "0"], ["83859.65", "0"], ["83859.62", "0.1157"], ["83859.38", "0.110546"], ["83859", "0"], ["83858.51", "0"], ["83857.78", "0"], ["83857.3", "0"], ["83856.97", "0"], ["83856.56", "0"], ["83856.53", "0"], ["83856.45", "0"], ["83855.9", "0"], ["83855.75", "0"], ["83855.6", "0"], ["83855.36", "0"], ["83855.18", "0.005961"], ["83854.92", "0"], ["83854.81", "0.058376"], ["83854.77", "0"], ["83854.66", "0"], ["83854.43", "0.242283"], ["83854.42", "0"], ["83854.39", "0"], ["83853.61", "0"], ["83853.42", "0"], ["83853.32", "0.003861"], ["83852.99", "0"], ["83852.65", "0"], ["83851.01", "0"], ["83850.97", "0"], ["83850.9", "0"], ["83850.74", "0.023857"], ["83850.68", "0.013719"], ["83850.06", "0"], ["83849.58", "0.177359"], ["83849.5", "0.215666"], ["83849.49", "0"], ["83848.81", "0"], ["83847.81", "0.059574"], ["83847.54", "0"], ["83846.61", "0"], ["83846.03", "0"], ["83845.65", "0"], ["83845.32", "0.001124"], ["83844.38", "0"], ["83842.8", "0.001124"], ["83840.81", "0.10871"], ["83840.48", "0.285144"], ["83840.21", "0"], ["83838.03", "0"], ["83837.46", "0"], ["83837.21", "0"], ["83834.95", "0.003522"], ["83834.8", "0"], ["83831.38", "0"], ["83831.26", "0.008805"], ["83828.86", "0"], ["83828.33", "0.510203"], ["83828.18", "0"], ["83828.17", "0"], ["83827.51", "0"], ["83827.5", "0"], ["83827.49", "0"], ["83826.31", "0.000132"], ["83824.94", "0"], ["83824.93", "0"], ["83824", "0"], ["83823.65", "0"], ["83822.29", "0.023845"], ["83822.21", "0.354236"], ["83822.1", "0.000255"], ["83822.04", "0.001788"], ["83821.67", "0.000201"], ["83820.91", "0.000333"], ["83820.5", "0.001466"], ["83820.2", "0.058414"], ["83820", "0.000082"], ["83819.73", "0.00009"], ["83819.62", "0.00009"], ["83819.59", "0.013"], ["83819.58", "0.012886"], ["83819.53", "0.411536"], ["83819.03", "0.001333"], ["83819", "0.039654"], ["83818.91", "0.04"], ["83818.61", "0.119407"], ["83818.01", "0.000255"], ["83817.82", "0.023845"], ["83817.72", "0.013878"], ["83817.49", "0.000255"], ["83817.48", "0.000201"], ["83816.72", "0.000333"], ["83816.7", "0.0006"], ["83816.6", "0.018279"], ["83816.52", "0.003"], ["83816.51", "0.0015"], ["83816.35", "0.05"], ["83816.34", "0.049571"], ["83816.3", "0.059637"], ["83815.89", "0.001466"], ["83815.71", "0.00036"], ["83815.41", "0.023845"], ["83814.84", "0.001333"], ["83814.79", "0.023852"], ["83814.54", "0.023844"], ["83813.57", "0.119407"], ["83813.4", "0.000255"], ["83813.29", "0.000204"], ["83812.88", "0.000255"], ["83812.53", "0.012184"], ["83811.62", "0.058414"], ["83811.33", "0.023916"], ["83811.28", "0.001466"], ["83811.19", "0.00009"], ["83810.65", "0.001333"], ["83809.8", "0.046405"], ["83809.56", "0.011958"], ["83809.11", "0.005963"], ["83809.1", "0.000206"], ["83808.88", "0.000515"], ["83808.79", "0.000255"], ["83808.63", "0.023852"], ["83808.56", "0.226212"], ["83808.51", "0.011958"], ["83808.36", "0.119407"], ["83808.34", "0.000333"]], "a": [["83872.35", "0.803957"], ["83873.49", "0.24405"], ["83873.51", "0.342"], ["83873.75", "0.046405"], ["83874.38", "0.013719"], ["83875", "0.096222"], ["83876.79", "0.156051"], ["83876.8", "0.245265"], ["83876.81", "0.003289"], ["83877.16", "0.008805"], ["83877.64", "0.011922"], ["83877.95", "0.020002"], ["83879.61", "0.348065"], ["83879.85", "0.003796"], ["83880.02", "0.058414"], ["83880.03", "0"], ["83880.32", "0.130838"], ["83880.69", "0.001"], ["83880.87", "0.009048"], ["83880.89", "0.015849"], ["83880.97", "0.017899"], ["83881.29", "0"], ["83881.42", "0.00009"], ["83881.73", "0.019285"], ["83881.92", "0.001333"], ["83882.48", "0"], ["83882.91", "0"], ["83882.97", "0.002976"], ["83883.04", "0.121476"], ["83883.42", "0"], ["83884.12", "0.118841"], ["83884.14", "0"], ["83884.15", "0"], ["83884.22", "0"], ["83884.58", "0.120139"], ["83884.8", "0.142578"], ["83884.86", "0"], ["83885.08", "0.031697"], ["83885.83", "0"], ["83886.7", "0"], ["83887.12", "0"], ["83887.2", "0.104"], ["83887.64", "0"], ["83888.42", "0"], ["83888.96", "0"], ["83889.22", "0"], ["83889.42", "0"], ["83889.46", "0"], ["83889.81", "0.054413"], ["83889.88", "0"], ["83891.15", "0"], ["83891.52", "0"], ["83891.83", "0"], ["83892.35", "0.48537"], ["83892.57", "0"], ["83892.78", "0.046405"], ["83893.27", "0"], ["83893.5", "0.0012"], ["83893.51", "0"], ["83893.79", "0"], ["83893.9", "0"], ["83894", "0"], ["83894.32", "0"], ["83894.38", "0.180945"], ["83894.62", "0.176225"], ["83894.65", "0"], ["83895.07", "0"], ["83896.81", "0.056551"], ["83897.02", "0.023845"], ["83897.67", "0"], ["83898.6", "0.071549"], ["83899.22", "0"], ["83899.46", "0"], ["83900.51", "0.000256"], ["83900.9", "0"], ["83901.62", "0.285744"], ["83901.65", "0"], ["83903.48", "0.299559"], ["83903.75", "0"], ["83903.81", "0.113095"], ["83906", "0"], ["83906.21", "0.119407"], ["83906.23", "0"], ["83906.4", "0"], ["83906.46", "0"], ["83907.51", "0"], ["83908.17", "0.0004"], ["83908.18", "0.000354"], ["83908.31", "0.005961"], ["83908.32", "0"], ["83908.65", "0"], ["83910.24", "0.357923"], ["83911.27", "0"], ["83913.47", "0"], ["83913.48", "0.000671"], ["83913.53", "0"], ["83914.28", "0.953304"], ["83914.44", "0.073666"], ["83915.26", "0"], ["83916.53", "0.119407"], ["83916.98", "0"], ["83918.74", "0"], ["83920.1", "0"], ["83920.76", "1.061716"], ["83920.99", "0.013"], ["83921.28", "0.023108"], ["83921.33", "0.009"], ["83921.46", "0.000356"]], "u": 69221, "seq": 67537855302}, "cts": 1742543250918, "record_time": 1742543252.885554}
{"topic": "orderbook.200.BTCUSDT", "ts": 1742543251119, "type": "delta", "data": {"s": "BTCUSDT", "b": [["83872.34", "0"], ["83871.98", "0"], ["83871.22", "0"], ["83869.86", "0.101855"], ["83869.72", "0.176641"], ["83869.17", "0.000099"], ["83867.53", "0"], ["83866.13", "0"], ["83865.99", "0"], ["83865.42", "0.004484"], ["83863.62", "0.000591"], ["83862.48", "0.008969"], ["83861.95", "0"], ["83861.94", "0"], ["83861.77", "0"], ["83861.06", "0.06919"], ["83860.6", "0.005962"], ["83860", "0.00006"], ["83859.62", "0"], ["83859.38", "0"], ["83858.29", "0.017939"], ["83858.01", "0"], ["83856.3", "0"], ["83854.81", "0"], ["83854.7", "0"], ["83854.43", "0"], ["83853.35", "0.003096"], ["83852.21", "0.012135"], ["83852.2", "0.04"], ["83850.74", "0"], ["83850.68", "0"], ["83849.59", "0.258932"], ["83849.58", "0"], ["83849.5", "0.0006"], ["83849.4", "0.04"], ["83849.19", "1"], ["83848.9", "0.04"], ["83848.8", "0.002982"], ["83847.81", "0"], ["83846.04", "0"], ["83845.6", "0.04"], ["83845.32", "0"], ["83844.58", "0.009337"], ["83844.1", "0.04"], ["83843.35", "0.009685"], ["83842.8", "0"], ["83842.16", "0.053346"], ["83841.98", "0.019601"], ["83841.85", "0.114849"], ["83840.81", "0"], ["83840.48", "0"], ["83839.22", "0.000835"], ["83839.02", "0.046405"], ["83837.3", "0.001116"], ["83837.23", "0.013455"], ["83836.09", "1.505439"], ["83836.08", "0.071602"], ["83830.75", "0.071607"], ["83828.33", "0"], ["83826.31", "0"], ["83825.8", "0.03578"], ["83822.11", "0.00011"], ["83820.89", "0.171"], ["83819.59", "0"], ["83819.58", "0"], ["83819.45", "0.304273"], ["83819", "0"], ["83818.91", "0"], ["83817.72", "0"], ["83816.35", "0"], ["83816.34", "0"], ["83815.6", "0.013"], ["83815.59", "0.012886"], ["83814.91", "0.04"], ["83814.9", "0.039651"], ["83813.58", "0.357918"], ["83812.53", "0.000333"], ["83812.5", "0.171"], ["83812.36", "0.05"], ["83812.35", "0.049567"], ["83811.33", "0"], ["83809.56", "0"], ["83808.63", "0"], ["83808.56", "0"], ["83808.51", "0"], ["83808.36", "0"], ["83808.34", "0"]], "a": [["83869.87", "0.964796"], ["83870.63", "0.004094"], ["83870.7", "0.011923"], ["83871.81", "0.001"], ["83872.33", "0.003576"], ["83872.34", "0.153776"], ["83872.35", "0.247456"], ["83873.49", "0"], ["83873.51", "0.171"], ["83874.05", "0.011922"], ["83874.31", "0.007925"], ["83874.38", "0"], ["83875", "0"], ["83875.42", "0.000333"], ["83875.5", "0.088"], ["83875.53", "0.000099"], ["83875.84", "0.001466"], ["83876.04", "0.121479"], ["83876.17", "0.000188"], ["83876.79", "0.265561"], ["83876.81", "0.0004"], ["83877.16", "0"], ["83877.25", "0.015849"], ["83877.95", "0.497447"], ["83879.16", "0.178849"], ["83879.26", "0.178849"], ["83879.61", "0.000333"], ["83879.7", "0.1036"], ["83879.85", "0"], ["83880.01", "0.196475"], ["83880.11", "0.005962"], ["83880.3", "0.104"], ["83880.32", "0"], ["83880.4", "0.1"], ["83880.89", "0.008805"], ["83880.99", "0"], ["83881.44", "0.031697"], ["83882.95", "0.028239"], ["83883.04", "0"], ["83883.45", "0.178849"], ["83883.51", "0"], ["83884.11", "0.086339"], ["83884.12", "0"], ["83884.58", "0"], ["83884.8", "0"], ["83885.08", "0"], ["83885.3", "0.112"], ["83885.77", "0.026937"], ["83886.65", "0.023846"], ["83887.03", "0"], ["83887.36", "0.071558"], ["83888.17", "0.089922"], ["83888.89", "0.148503"], ["83889.06", "0"], ["83889.17", "0.035778"], ["83889.26", "0.0013"], ["83889.81", "0"], ["83890.5", "0.104"], ["83891.08", "1.356939"], ["83892.35", "0"], ["83892.57", "0.125194"], ["83893.3", "0.071553"], ["83894.38", "0"], ["83894.62", "0"], ["83895.5", "0"], ["83896.02", "0.089424"], ["83896.81", "0"], ["83897.02", "0"], ["83897.12", "0.151013"], ["83897.25", "0"], ["83897.86", "0"], ["83898.6", "0"], ["83901.62", "0"], ["83903.17", "0.0004"], ["83903.18", "0.000354"], ["83903.48", "0"], ["83903.81", "0"], ["83905.43", "0.303961"], ["83905.6", "0.023108"], ["83906.1", "0"], ["83906.22", "0"], ["83908.12", "0.133193"], ["83908.17", "0"], ["83908.18", "0"], ["83908.78", "0.073666"], ["83910.24", "0"], ["83910.25", "0"], ["83910.99", "3.23453"], ["83911.79", "0.953304"], ["83911.87", "0.357918"], ["83913.53", "0.125194"], ["83914.11", "0.027484"], ["83914.28", "0"], ["83914.44", "0"], ["83916.98", "0.089424"], ["83919.67", "0"], ["83919.69", "0"], ["83920.32", "0"], ["83920.33", "0"], ["83920.44", "0"], ["83920.76", "0"], ["83920.92", "0"], ["83920.98", "0"], ["83920.99", "0"], ["83921.28", "0"], ["83921.33", "0"], ["83921.46", "0"]], "u": 69222, "seq": 67537856401}, "cts": 1742543251117, "record_time": 1742543252.886278}
{"topic": "orderbook.200.BTCUSDT", "ts": 1742543251319, "type": "delta", "data": {"s": "BTCUSDT", "b": [["83869.86", "0"], ["83869.72", "0"], ["83869.34", "0"], ["83869.17", "0"], ["83868.74", "0"], ["83868.57", "0"], ["83868.21", "0.126969"], ["83865.57", "0"], ["83865.42", "0"], ["83865.15", "0"], ["83863.77", "0.004484"], ["83857.95", "0.027164"], ["83857.94", "0.071583"], ["83856.02", "0.00311"], ["83853.35", "0"], ["83852.21", "0.029235"], ["83850.7", "0.04"], ["83849.73", "0.009331"], ["83849.59", "0.495306"], ["83849.44", "0.029262"], ["83849.19", "0"], ["83848.6", "0.04"], ["83847.1", "0.04"], ["83846.9", "0.04"], ["83845.6", "0.08"], ["83844.58", "0"], ["83841.86", "0.101284"], ["83836.09", "0.119407"], ["83836.08", "0"], ["83827.34", "1.352339"], ["83827.26", "0.07161"], ["83825.8", "0"], ["83823.68", "0.035781"], ["83822.31", "0.000108"], ["83822.11", "0"], ["83821.05", "0.127265"], ["83814.92", "0.357905"], ["83813.58", "0"], ["83808.79", "0"]], "a": [["83868.22", "1.678502"], ["83868.58", "0.000153"], ["83869.58", "0.002889"], ["83869.86", "0.127528"], ["83869.87", "0.642727"], ["83872.33", "0"], ["83872.34", "0.192768"], ["83872.35", "0.076456"], ["83872.66", "0.007925"], ["83873.35", "0.000255"], ["83873.53", "0.001333"], ["83873.8", "0.108"], ["83874.04", "0.009"], ["83874.31", "0"], ["83874.36", "0.086727"], ["83874.8", "0.009331"], ["83875.5", "0.192"], ["83875.53", "0"], ["83876.79", "0.370638"], ["83877.1", "0.108"], ["83878.9", "0.104"], ["83880.02", "0"], ["83880.5", "0.1123"], ["83881.3", "0.104"], ["83883.4", "0.116"], ["83883.45", "0"], ["83885.3", "0"], ["83885.37", "0.001115"], ["83887.2", "0"], ["83887.89", "0.001115"], ["83888.5", "0"], ["83888.89", "0.55274"], ["83888.9", "0"], ["83889.26", "0"], ["83890.5", "0"], ["83892.1", "0"], ["83895.4", "0"], ["83897.12", "0.108091"], ["83902.37", "0.0004"], ["83902.38", "0.000354"], ["83903.17", "0"], ["83903.18", "0"], ["83906.06", "0.178849"], ["83910.14", "0.953304"], ["83911.79", "0"], ["83911.87", "0"], ["83915.48", "0.359239"], ["83917.77", "0"], ["83918.12", "0"], ["83918.97", "0"], ["83919.49", "0"]], "u": 69223, "seq": 67537857141}, "cts": 1742543251315, "record_time": 1742543252.887221}
{"topic": "orderbook.200.BTCUSDT", "ts": 1742543251520, "type": "delta", "data": {"s": "BTCUSDT", "b": [["83868.21", "0.113238"], ["83865.04", "0.000099"], ["83860.6", "0"], ["83860.25", "0.04807"], ["83859.83", "0.23419"], ["83858.94", "0.005962"], ["83853", "0.103245"], ["83852.98", "0.124682"], ["83852.84", "0.000298"], ["83852.74", "0.11687"], ["83852.7", "0.000298"], ["83852.21", "0.002982"], ["83849.59", "0.258932"], ["83849.41", "0"], ["83849.23", "0"], ["83848.8", "0"], ["83848.18", "0.055059"], ["83845.61", "0.104504"], ["83842.94", "0.17405"], ["83842.16", "0"], ["83841.18", "0.055337"], ["83835.28", "0.017899"], ["83834.18", "0.122193"], ["83833.84", "0.303571"], ["83823.68", "0"], ["83823.39", "0.035781"], ["83822.31", "0"], ["83822.21", "0.354344"], ["83816.51", "0.024989"], ["83814.93", "0.357904"], ["83814.92", "0"], ["83814.9", "0.03965"], ["83812.36", "0"], ["83812.35", "0"], ["83811.62", "0"], ["83811.28", "0"], ["83811.19", "0"], ["83810.65", "0"], ["83809.8", "0"], ["83809.11", "0"], ["83809.1", "0"], ["83808.88", "0"]], "a": [["83868.22", "1.765229"], ["83871.4", "0.000099"], ["83872.82", "0.000255"], ["83873.5", "0.1"], ["83874.13", "0.178852"], ["83874.36", "0"], ["83874.92", "0.011922"], ["83875.07", "0.178852"], ["83876.81", "0"], ["83877", "0.104"], ["83877.48", "0.122071"], ["83877.64", "0"], ["83877.94", "0.110571"], ["83878.44", "0.005962"], ["83879.16", "0"], ["83879.7", "0.0036"], ["83880.11", "0"], ["83880.3", "0"], ["83880.89", "0"], ["83882.07", "0.008805"], ["83883.18", "0.060471"], ["83884.11", "0.045171"], ["83885.37", "0"], ["83886.7", "0.001293"], ["83887.74", "0.183425"], ["83887.89", "0"], ["83887.98", "0.163741"], ["83890.18", "0.057819"], ["83892.41", "0.237964"], ["83893", "0"], ["83894.4", "0"], ["83894.98", "0.295007"], ["83896.84", "0.301572"], ["83897.18", "0.119865"], ["83900.37", "0.023745"], ["83902.27", "0.0004"], ["83902.28", "0.000354"], ["83902.37", "0"], ["83902.38", "0"], ["83914.88", "0"], ["83915.14", "0"], ["83915.48", "0"], ["83915.49", "0"], ["83915.81", "0"], ["83915.87", "0"], ["83916.53", "0"], ["83916.98", "0"], ["83917.36", "0"]], "u": 69224, "seq": 67537857433}, "cts": 1742543251517, "record_time": 1742543252.88788}
{"topic": "orderbook.200.BTCUSDT", "ts": 1742543251719, "type": "delta", "data": {"s": "BTCUSDT", "b": [["83863.78", "0.003"], ["83860.25", "0.05874"], ["83857.59", "0.003"], ["83853.17", "0.130522"], ["83853", "0.120361"], ["83852.98", "0"], ["83852.77", "0.123333"], ["83852.74", "0"], ["83852.21", "0"], ["83852.15", "0.02397"], ["83850.71", "0.002982"], ["83848.2", "0.056091"], ["83848.18", "0"], ["83843.48", "0.182375"], ["83842.97", "0.163486"], ["83842.94", "0"], ["83841.2", "0.057334"], ["83841.18", "0"], ["83834.2", "0.119517"], ["83834.18", "0"], ["83833.87", "0.29858"], ["83833.84", "0"], ["83822.21", "0.354341"], ["83815.6", "0"], ["83815.59", "0"], ["83815.5", "0.013"], ["83815.49", "0.012886"], ["83814.93", "0"], ["83814.91", "0"], ["83814.9", "0"], ["83814.81", "0.04"], ["83814.8", "0.03965"], ["83813.58", "0.357906"], ["83812.88", "0"], ["83812.53", "0"], ["83812.5", "0"]], "a": [["83868.22", "1.780134"], ["83869.86", "0.203715"], ["83869.87", "0.627822"], ["83870.44", "0.023533"], ["83874.13", "0"], ["83875.07", "0"], ["83876.05", "0.003"], ["83876.8", "0.004571"], ["83877.48", "0"], ["83877.5", "0.109807"], ["83877.94", "0"], ["83877.97", "0.117575"], ["83878.4", "0.116"], ["83879.26", "0.178852"], ["83880.84", "0.178825"], ["83881.3", "0"], ["83882.02", "0.178823"], ["83883.18", "0"], ["83883.2", "0.061437"], ["83883.4", "0"], ["83883.45", "0.178852"], ["83883.7", "0.178819"], ["83884.11", "0.143394"], ["83885.11", "0.003"], ["83886.42", "0.058414"], ["83886.7", "0"], ["83887.74", "0"], ["83887.77", "0.171873"], ["83887.98", "0"], ["83888", "0.176711"], ["83890.18", "0"], ["83890.2", "0.057352"], ["83890.38", "0"], ["83893.8", "0"], ["83894.98", "0"], ["83895", "0.284473"], ["83896.84", "0"], ["83896.87", "0.283843"], ["83897.18", "0"], ["83897.2", "0.115994"], ["83902.26", "0.0004"], ["83902.27", "0.000354"], ["83902.28", "0"], ["83906.06", "0"], ["83907.12", "0"], ["83910.14", "1.430005"], ["83914.63", "0.11"]], "u": 69225, "seq": 67537857681}, "cts": 1742543251716, "record_time": 1742543252.88834}
{"topic": "orderbook.200.BTCUSDT", "ts": 1742543251919, "type": "delta", "data": {"s": "BTCUSDT", "b": [["83868.21", "0"], ["83867.79", "0.00639"], ["83861.07", "0.000298"], ["83853.17", "0.026048"], ["83853", "0"], ["83852.77", "0.001466"], ["83851.51", "0.114315"], ["83851.27", "0.111815"], ["83848.2", "0"], ["83847.66", "0.112889"], ["83845.61", "0.195199"], ["83842.97", "0"], ["83841.47", "0.184926"], ["83841.2", "0"], ["83840.66", "0.178315"], ["83834.2", "0"], ["83833.87", "0"], ["83833.66", "0.298993"], ["83832.71", "0.120247"], ["83832.37", "0.295353"], ["83822.21", "0.354236"], ["83822.12", "0.00011"], ["83815.5", "0.012886"], ["83813.57", "0"], ["83813.4", "0"], ["83813.29", "0"]], "a": [["83867.8", "0.451453"], ["83868.2", "0.262775"], ["83868.22", "0.174576"], ["83869.86", "0.019918"], ["83869.87", "0.385249"], ["83876.01", "0.11027"], ["83876.47", "0.109392"], ["83877.5", "0"], ["83877.97", "0"], ["83879.16", "0.178852"], ["83879.53", "1"], ["83880.01", "0.363691"], ["83880.56", "0.11927"], ["83880.9", "0.178852"], ["83881.43", "0.008805"], ["83882.07", "0"], ["83883.2", "0"], ["83886.27", "0.166393"], ["83886.51", "0.168465"], ["83887.56", "0.186449"], ["83887.77", "0"], ["83888", "0.000333"], ["83890.2", "0"], ["83893.51", "0.299029"], ["83894.56", "0.278349"], ["83895", "0"], ["83895.37", "0.285026"], ["83896.87", "0"], ["83897.2", "0"], ["83902.17", "0.0004"], ["83902.18", "0.000354"], ["83902.26", "0"], ["83902.27", "0"], ["83909.11", "0.04"], ["83909.12", "0.04"], ["83909.72", "1.430005"], ["83910.14", "0"], ["83913.48", "0"], ["83913.53", "0"], ["83913.62", "0"], ["83913.93", "0"], ["83914.11", "0"], ["83914.35", "0"], ["83914.63", "0"]], "u": 69226, "seq": 67537858101}, "cts": 1742543251917, "record_time": 1742543252.888831}
{"topic": "orderbook.200.BTCUSDT", "ts": 1742543252120, "type": "delta", "data": {"s": "BTCUSDT", "b": [["83867.79", "0"], ["83867.19", "0.007957"], ["83863.78", "0"], ["83863.77", "0"], ["83862.76", "0.004484"], ["83862.48", "0"], ["83859.82", "0.008969"], ["83858.29", "0"], ["83857.95", "0"], ["83856.02", "0"], ["83855.63", "0.01794"], ["83853.32", "0"], ["83853.17", "0.093105"], ["83852.7", "0"], ["83852.15", "0"], ["83851.51", "0"], ["83851.27", "0"], ["83851.14", "0.111982"], ["83850.9", "0.117989"], ["83850.71", "0"], ["83849.81", "0.003216"], ["83849.73", "0"], ["83847.66", "0"], ["83847.3", "0.120688"], ["83847.11", "0.002982"], ["83846.34", "0.057201"], ["83844.57", "0.009622"], ["83841.86", "0.197596"], ["83841.47", "0"], ["83841.1", "0.166105"], ["83840.66", "0"], ["83840.3", "0.186449"], ["83839.34", "0.060074"], ["83839.22", "0"], ["83837.3", "0"], ["83833.66", "0"], ["83833.3", "0.298181"], ["83832.71", "0"], ["83832.37", "0"], ["83832.34", "0.118967"], ["83832", "0.284673"], ["83831.56", "0"], ["83825.88", "0"], ["83825.4", "0"], ["83824", "0.000118"], ["83823.39", "0"], ["83823.34", "0"], ["83822.29", "0"], ["83822.12", "0"], ["83819.62", "0.0002"], ["83815.5", "0"], ["83815.49", "0"], ["83815.41", "0"], ["83814.81", "0"], ["83814.8", "0"], ["83813.58", "0"], ["83813.57", "0.119407"], ["83813.4", "0.000255"], ["83813.29", "0.000204"], ["83813.01", "0.013"], ["83813", "0.012886"], ["83812.88", "0.000255"], ["83812.53", "0.000333"], ["83812.32", "0.04"], ["83812.31", "0.039652"], ["83811.62", "0.058414"], ["83811.41", "0.004655"], ["83811.28", "0.001466"], ["83811.19", "0.00009"], ["83810.65", "0.001333"], ["83809.8", "0.046405"], ["83809.77", "0.05"], ["83809.76", "0.049569"], ["83809.11", "0.005963"]], "a": [["83867.2", "1.655699"], ["83867.79", "0.264188"], ["83867.8", "0.171"], ["83868.2", "0"], ["83868.22", "0"], ["83868.63", "0.011923"], ["83869.1", "0.178854"], ["83869.5", "0.009622"], ["83869.62", "0.001"], ["83869.87", "0.366418"], ["83871.4", "0"], ["83871.63", "0.007925"], ["83871.98", "0.000188"], ["83872.66", "0"], ["83874.05", "0"], ["83874.57", "0.01585"], ["83874.8", "0"], ["83875.64", "0.120564"], ["83876.01", "0"], ["83876.1", "0.118024"], ["83876.47", "0"], ["83876.52", "0.000591"], ["83876.79", "0.649389"], ["83877.25", "0"], ["83877.68", "0.178832"], ["83877.94", "0.058414"], ["83878.39", "0.178853"], ["83878.76", "0.031698"], ["83879.16", "0"], ["83879.26", "0"], ["83879.36", "0.178828"], ["83880.2", "0.115004"], ["83880.5", "0.112"], ["83880.56", "0.000083"], ["83880.84", "0"], ["83880.9", "0"], ["83881.34", "0.055519"], ["83881.43", "0"], ["83881.44", "0"], ["83882.02", "0"], ["83883.45", "0"], ["83884.11", "0.201394"], ["83885.9", "0.179526"], ["83886.14", "0.174288"], ["83886.27", "0"], ["83886.51", "0"], ["83887.2", "0.183584"], ["83887.56", "0"], ["83888.34", "0.06125"], ["83893.14", "0.292431"], ["83893.51", "0"], ["83894.2", "0.306961"], ["83894.56", "0"], ["83895", "0.274535"], ["83895.34", "0.119917"], ["83895.37", "0"], ["83900.27", "0.0004"], ["83900.28", "0.000354"], ["83902.17", "0"], ["83902.18", "0"], ["83909.12", "1.470005"], ["83909.68", "0.013"], ["83909.69", "0.013"], ["83909.72", "0"], ["83911.09", "0"], ["83911.28", "0"], ["83911.88", "0"], ["83912.75", "0"], ["83913.17", "0"]], "u": 69227, "seq": 67537859042}, "cts": 1742543252117, "record_time": 1742543252.889274}
{"topic": "orderbook.200.BTCUSDT", "ts": 1742543252320, "type": "delta", "data": {"s": "BTCUSDT", "b": [["83867.19", "0"], ["83867.03", "0"], ["83866.97", "0"], ["83866.61", "0"], ["83865.14", "0"], ["83865.04", "0"], ["83864.13", "0"], ["83863.62", "0"], ["83863.6", "0"], ["83863.59", "0"], ["83862.84", "0"], ["83862.76", "0"], ["83862.3", "0"], ["83861.07", "0"], ["83861.06", "0"], ["83860.25", "0.005225"], ["83859.83", "0"], ["83859.82", "0"], ["83857.94", "0"], ["83857.87", "0.004485"], ["83857.59", "0"], ["83855.63", "0"], ["83855.18", "0"], ["83854.94", "0.008963"], ["83853.34", "0"], ["83853.17", "0"], ["83852.2", "0"], ["83851.14", "0"], ["83850.9", "0"], ["83850.75", "0.017928"], ["83850.7", "0"], ["83849.81", "0"], ["83849.59", "0"], ["83849.44", "0"], ["83849.4", "0"], ["83848.9", "0"], ["83848.79", "0"], ["83848.6", "0"], ["83847.3", "0"], ["83847.11", "0"], ["83847.1", "0"], ["83846.9", "0"], ["83846.34", "0"], ["83845.6", "0"], ["83844.98", "0.029212"], ["83844.62", "0.003953"], ["83844.57", "0"], ["83844.1", "0"], ["83843.51", "0.003241"], ["83843.48", "0"], ["83843.43", "0"], ["83843.35", "0"], ["83842.81", "0.123425"], ["83842.16", "0.058414"], ["83842.15", "0"], ["83841.98", "0"], ["83841.85", "0"], ["83841.1", "0"], ["83840.3", "0"], ["83839.41", "0.009714"], ["83839.35", "0.002982"], ["83839.34", "0"], ["83839.02", "0"], ["83834.95", "0"], ["83833.31", "0.245354"], ["83833.3", "0"], ["83833.01", "0.177036"], ["83832.34", "0"], ["83832", "0"], ["83831.26", "0"], ["83831.24", "0.060303"], ["83830.85", "0.046405"], ["83830.75", "0"], ["83827.81", "0"], ["83827.26", "0"], ["83825.77", "0.023849"], ["83825.2", "0.283406"], ["83824.24", "0.114803"], ["83823.91", "0.2773"], ["83822.15", "0.017899"], ["83821.9", "0.008805"], ["83821.13", "0.071615"], ["83821.05", "0"], ["83819.62", "0.00009"], ["83819.53", "0"], ["83817.82", "0"], ["83816.51", "0.0015"], ["83813.72", "0.000077"], ["83813.01", "0"], ["83813", "0"], ["83812.5", "0.171"], ["83812.32", "0"], ["83812.31", "0"], ["83811.06", "0.023868"], ["83809.77", "0"], ["83809.76", "0"], ["83809.1", "0.000206"], ["83808.88", "0.000515"], ["83808.79", "0.000255"], ["83808.63", "0.023852"], ["83808.36", "0.119407"], ["83808.34", "0.000333"], ["83808.27", "0.000255"], ["83807.11", "0.013"], ["83807.1", "0.012886"], ["83806.97", "0.001"], ["83806.9", "0.04"], ["83806.89", "0.127297"], ["83806.75", "0.008873"], ["83806.67", "0.001466"], ["83806.46", "0.001333"], ["83806.42", "0.04"], ["83806.41", "0.039652"], ["83805.57", "0.502638"], ["83805.52", "0.023852"], ["83804.96", "0.014067"], ["83804.91", "0.000206"], ["83804.52", "0.00073"], ["83804.18", "0.000255"], ["83804.15", "0.000333"], ["83803.87", "0.05"], ["83803.86", "0.049574"], ["83803.66", "0.000255"], ["83803.57", "1.788407"], ["83803.4", "0.04"], ["83802.89", "0.058414"], ["83802.76", "0.00009"], ["83802.27", "0.001333"], ["83802.06", "0.001466"], ["83801.33", "0.009"], ["83801.05", "0.023852"], ["83800.72", "0.000206"], ["83800.34", "0.029825"], ["83800.12", "0.119407"], ["83800", "0.003639"], ["83799.96", "0.000333"], ["83799.57", "0.000255"], ["83799.05", "0.000255"], ["83798.64", "0.023852"], ["83798.08", "0.001333"], ["83797.45", "0.001466"]], "a": [["83862.29", "1.718256"], ["83862.3", "0.12373"], ["83862.31", "0.539844"], ["83863.02", "0.009715"], ["83863.47", "0.023848"], ["83864.75", "0.004094"], ["83865.11", "0.046405"], ["83865.59", "0.059621"], ["83866.62", "0.011923"], ["83866.74", "0.007931"], ["83867.03", "0.000333"], ["83867.18", "0.225498"], ["83867.19", "0.0004"], ["83867.2", "0.014906"], ["83867.5", "0.009048"], ["83867.79", "0.000588"], ["83867.8", "0"], ["83868.01", "0.114637"], ["83868.21", "0.000255"], ["83868.58", "0"], ["83868.63", "0.012123"], ["83868.74", "0.000255"], ["83869.1", "0"], ["83869.34", "0.001333"], ["83869.5", "0"], ["83869.67", "0.015862"], ["83869.86", "0.003"], ["83869.87", "0.363306"], ["83870.38", "0.000099"], ["83870.48", "0.059618"], ["83870.63", "0"], ["83871.22", "0.001799"], ["83871.63", "0"], ["83872.29", "0.121697"], ["83872.44", "0.178843"], ["83872.99", "0.00009"], ["83873.75", "0"], ["83873.86", "0.031723"], ["83874.12", "0.178839"], ["83874.57", "0"], ["83875.4", "0.1"], ["83875.64", "0"], ["83875.8", "0.178836"], ["83876.04", "0"], ["83876.1", "0"], ["83877.68", "0"], ["83877.81", "0.185568"], ["83878.42", "0.00018"], ["83878.76", "0"], ["83879.16", "0.178865"], ["83879.36", "0"], ["83880.01", "0.196475"], ["83880.02", "0.071565"], ["83880.2", "0"], ["83880.43", "0.008805"], ["83880.87", "0"], ["83881.34", "0"], ["83881.63", "0.023849"], ["83881.89", "0.014013"], ["83882.3", "0.0006"], ["83882.95", "0.143114"], ["83883.7", "0"], ["83885.9", "0"], ["83886.1", "0.289697"], ["83886.14", "0"], ["83886.65", "0"], ["83886.91", "0.309296"], ["83887.2", "0"], ["83887.24", "0.121665"], ["83888.17", "0"], ["83888.34", "0"], ["83888.78", "0.017899"], ["83888.86", "0.003575"], ["83890.94", "0"], ["83893.14", "0"], ["83893.3", "0"], ["83894.2", "0"], ["83894.34", "0"], ["83894.93", "0.023363"], ["83895", "0"], ["83895.34", "0"], ["83896.21", "0.011929"], ["83899.57", "0.0004"], ["83899.58", "0.000354"], ["83900.27", "0"], ["83900.28", "0"], ["83900.37", "0"], ["83901", "0.119407"], ["83902.35", "0"], ["83903.12", "0.073668"], ["83904.21", "1.430005"], ["83904.58", "0.357955"], ["83907.34", "0"], ["83908.31", "0"], ["83908.78", "0"], ["83908.97", "0"], ["83909", "0"], ["83909.11", "0"], ["83909.12", "0"], ["83909.68", "0"], ["83909.69", "0"], ["83909.73", "0"], ["83909.74", "0"], ["83910.26", "0"], ["83910.41", "0"], ["83910.75", "0"], ["83910.99", "0"]], "u": 69228, "seq": 67537860405}, "cts": 1742543252316, "record_time": 1742543252.88976}
{"topic": "orderbook.200.BTCUSDT", "ts": 1742543252520, "type": "delta", "data": {"s": "BTCUSDT", "b": [["83862.28", "0.014438"], ["83860.25", "0"], ["83859.11", "0.000099"], ["83858.94", "0"], ["83854.33", "0.000298"], ["83854.32", "0.05874"], ["83853.9", "0.23419"], ["83853.48", "0.06919"], ["83853.01", "0.005962"], ["83852.84", "0"], ["83849.82", "0.07159"], ["83846.53", "0.000298"], ["83846.52", "0.017088"], ["83845.69", "0.120608"], ["83845.61", "0.127586"], ["83845.45", "0.110994"], ["83843.5", "0.04"], ["83842.81", "0"], ["83842.18", "0.024001"], ["83842.16", "0"], ["83842.14", "0"], ["83841.9", "0.04"], ["83841.86", "0.056466"], ["83841.84", "0.121276"], ["83841", "0.04"], ["83840.89", "0.05775"], ["83840.7", "0.04"], ["83839.42", "0.002982"], ["83839.35", "0"], ["83838.5", "0.04"], ["83836.8", "0.04"], ["83835.65", "0.168312"], ["83834.84", "0.17417"], ["83834.58", "0.114931"], ["83833.89", "0.058955"], ["83833.52", "0.009685"], ["83833.31", "0"], ["83833.02", "0.095807"], ["83833.01", "0"], ["83832.15", "0.019601"], ["83831.24", "0"], ["83827.84", "0.30162"], ["83826.89", "0.11549"], ["83826.55", "0.28304"], ["83825.2", "0"], ["83825.02", "0.003462"], ["83824.24", "0"], ["83823.91", "0"], ["83817.45", "0.008476"], ["83817.43", "0.071618"], ["83813.92", "0.000086"], ["83813.72", "0"], ["83807.11", "0"], ["83807.1", "0"], ["83807.01", "0.013"], ["83807", "0.012886"], ["83806.89", "0.127321"], ["83806.42", "0"], ["83806.41", "0"], ["83806.32", "0.04"], ["83806.31", "0.039652"], ["83804.96", "0"], ["83804.11", "0.171"], ["83803.88", "0.357951"], ["83803.87", "0"], ["83803.86", "0"], ["83803.66", "0"], ["83803.57", "0"], ["83803.4", "0"], ["83802.89", "0"], ["83802.76", "0"], ["83802.27", "0"], ["83802.06", "0"], ["83801.33", "0"], ["83801.05", "0"], ["83800.72", "0"], ["83800.34", "0"], ["83800.12", "0"], ["83800", "0"], ["83799.96", "0"], ["83799.57", "0"], ["83799.05", "0"], ["83798.64", "0"], ["83798.08", "0"], ["83797.45", "0"]], "a": [["83862.29", "1.805983"], ["83862.3", "0.215178"], ["83862.49", "0.178865"], ["83863.12", "0.011924"], ["83863.69", "0.004675"], ["83865.59", "0"], ["83865.81", "0.059621"], ["83866.47", "0.011923"], ["83866.68", "0.178865"], ["83867.18", "0.316894"], ["83867.19", "0"], ["83867.2", "0"], ["83867.6", "0.108"], ["83868.01", "0"], ["83869", "0.104"], ["83870.19", "0.121853"], ["83870.38", "0"], ["83870.65", "0.109996"], ["83870.7", "0"], ["83870.8", "0.108"], ["83870.84", "0.178865"], ["83870.9", "0.104"], ["83871.61", "0.125205"], ["83872.34", "0.266319"], ["83872.4", "0.116"], ["83872.5", "0.104"], ["83872.51", "0.005962"], ["83873.8", "0"], ["83874", "0.112"], ["83874.74", "0.109553"], ["83874.92", "0"], ["83875.89", "0.056513"], ["83876.8", "0"], ["83877.1", "0"], ["83877.81", "0"], ["83878.39", "0"], ["83878.44", "0"], ["83878.9", "0"], ["83879.16", "0"], ["83880.06", "0.125205"], ["83880.4", "0"], ["83880.43", "0"], ["83880.45", "0.178385"], ["83880.5", "0"], ["83880.69", "0.1887"], ["83881.74", "0.178266"], ["83882.89", "0.05641"], ["83886.1", "0"], ["83886.91", "0"], ["83887.24", "0"], ["83887.69", "0.309325"], ["83888.74", "0.298459"], ["83889.55", "0.28026"], ["83889.89", "0.123364"], ["83891.08", "0"], ["83892.41", "0"], ["83893.27", "0.0004"], ["83893.28", "0.000354"], ["83899.57", "0"], ["83899.58", "0"], ["83900.29", "0.073665"], ["83900.63", "0.005"], ["83903.12", "0"], ["83904.58", "0"], ["83906.2", "0.357947"], ["83907.09", "0"], ["83907.1", "0"], ["83907.21", "0"], ["83908.12", "0"], ["83908.13", "0"]], "u": 69229, "seq": 67537861008}, "cts": 1742543252516, "record_time": 1742543252.890269}
{"topic": "orderbook.200.BTCUSDT", "ts": 1742543252719, "type": "delta", "data": {"s": "BTCUSDT", "b": [["83862.28", "0"], ["83862", "0"], ["83860.95", "0.007534"], ["83857.87", "0"], ["83856.53", "0.004481"], ["83849.83", "0.038609"], ["83846.52", "0.003"], ["83845.69", "0.117481"], ["83845.61", "0"], ["83845.45", "0.119027"], ["83844.98", "0"], ["83844", "0.04"], ["83843.66", "0.000629"], ["83842.3", "0.04"], ["83841.91", "0.122389"], ["83841.84", "0"], ["83840.89", "0.060603"], ["83839.44", "0.029214"], ["83839.42", "0"], ["83835.65", "0.164272"], ["83834.84", "0"], ["83834.8", "0.04"], ["83833.89", "0.056896"], ["83833.02", "0"], ["83827.84", "0"], ["83827.34", "0"], ["83826.89", "0.10843"], ["83826.55", "0.297663"], ["83825.77", "0"], ["83817.45", "0"], ["83815.88", "0.008715"], ["83813.92", "0"], ["83811.93", "0.000086"], ["83809.72", "0.127321"], ["83807.01", "0"], ["83807", "0"], ["83806.9", "0"], ["83806.89", "0"], ["83806.32", "0"], ["83806.31", "0"], ["83805.12", "0.013"], ["83805.11", "0.012887"], ["83804.42", "0.04"], ["83804.41", "0.039654"], ["83804.12", "0.357946"], ["83803.88", "0"], ["83803.66", "0.000255"], ["83803.57", "1.788407"], ["83803.4", "0.04"], ["83802.89", "0.058414"], ["83802.76", "0.00009"]], "a": [["83860.96", "0.807179"], ["83862.28", "1.031333"], ["83862.29", "1.292693"], ["83862.3", "0.003976"], ["83862.31", "0.332502"], ["83864.07", "0.178865"], ["83865.39", "0.007931"], ["83865.47", "0.000099"], ["83865.61", "0.059621"], ["83866.74", "0"], ["83866.75", "0.121705"], ["83866.9", "0.1"], ["83867.28", "0.0002"], ["83867.79", "0.000188"], ["83868.63", "0.011923"], ["83869", "0.192"], ["83869.58", "0"], ["83870.19", "0.122544"], ["83870.65", "0.109526"], ["83872.29", "0"], ["83873.5", "0"], ["83873.93", "0.059621"], ["83874.74", "0"], ["83875.5", "0"], ["83875.89", "0.055827"], ["83877", "0"], ["83878.4", "0"], ["83879.53", "0"], ["83880.01", "0.336677"], ["83880.45", "0.171719"], ["83880.69", "0.166778"], ["83881.63", "0"], ["83881.74", "0"], ["83882", "0.0006"], ["83882.89", "0.060454"], ["83884.11", "0"], ["83887.69", "0.298717"], ["83888.74", "0"], ["83888.89", "0.148503"], ["83889.55", "0.307983"], ["83889.89", "0.111167"], ["83890.97", "0.0004"], ["83890.98", "0.000354"], ["83893.27", "0"], ["83893.28", "0"], ["83902.88", "0.476652"], ["83903.43", "0.11"], ["83904.21", "0.953353"], ["83906.2", "0"], ["83907.09", "0.001333"]], "u": 69230, "seq": 67537861363}, "cts": 1742543252718, "record_time": 1742543252.890782}
{"topic": "orderbook.200.BTCUSDT", "ts": 1742543252919, "type": "delta", "data": {"s": "BTCUSDT", "b": [["83860.95", "0.006201"], ["83859.11", "0"], ["83849.83", "0"], ["83846.27", "0"], ["83845.7", "0.117389"], ["83845.69", "0"], ["83845.45", "0"], ["83844.86", "0.115667"], ["83844.62", "0.121673"], ["83842.18", "0"], ["83841.91", "0.119407"], ["83841.86", "0.111459"], ["83841.01", "0.002982"], ["83840.89", "0"], ["83840.06", "0.056382"], ["83836.7", "0.04"], ["83836.1", "0.167648"], ["83835.65", "0"], ["83834.82", "0.165828"], ["83834.58", "0"], ["83834.4", "0.012503"], ["83833.89", "0"], ["83833.06", "0.057166"], ["83831.61", "0.024529"], ["83830.4", "0.04545"], ["83826.89", "0"], ["83826.55", "0"], ["83826.06", "0.121931"], ["83825.72", "0.291591"], ["83819.53", "1.341729"], ["83816.3", "0"], ["83815.88", "0"], ["83811.93", "0"], ["83809.72", "0.12727"], ["83805.58", "0.35795"], ["83805.12", "0"], ["83805.11", "0"], ["83804.42", "0"], ["83804.41", "0"], ["83804.32", "0.013"], ["83804.31", "0.012887"], ["83804.12", "0"], ["83803.62", "0.039654"], ["83803.61", "0.039654"], ["83802.27", "0.001333"], ["83802.06", "0.001466"]], "a": [["83860.96", "0.779353"], ["83861.56", "0.178868"], ["83862.28", "0.007033"], ["83862.29", "0.175039"], ["83864.07", "0"], ["83865.14", "0.001333"], ["83865.47", "0"], ["83865.6", "0.163637"], ["83866.61", "0.001466"], ["83869.36", "0.120024"], ["83869.82", "0.124432"], ["83870.19", "0"], ["83870.65", "0"], ["83873.09", "1.362127"], ["83873.99", "0.008805"], ["83874.04", "0"], ["83875.06", "0.054322"], ["83875.89", "0"], ["83876.79", "0.168471"], ["83879.62", "0.163136"], ["83879.86", "0.176182"], ["83880.45", "0.002311"], ["83880.69", "0.001"], ["83882.06", "0.05804"], ["83882.89", "0"], ["83886.86", "0.287415"], ["83887.69", "0"], ["83888.72", "0.286601"], ["83889.06", "0.123523"], ["83889.55", "0"], ["83889.89", "0"], ["83890.96", "0.0004"], ["83890.97", "0.000354"], ["83890.98", "0"], ["83900.29", "0.073664"], ["83902.88", "1.430005"], ["83903.42", "0.357947"], ["83904.21", "0"], ["83906.51", "0"], ["83906.52", "0"], ["83906.71", "0"], ["83906.8", "0"], ["83907.09", "0"]], "u": 69231, "seq": 67537861623}, "cts": 1742543252914, "record_time": 1742543252.915459}
{"topic": "orderbook.200.BTCUSDT", "ts": 1742543253120, "type": "delta", "data": {"s": "BTCUSDT", "b": [["83860.95", "0.005962"], ["83857.78", "0.000099"], ["83853.01", "0"], ["83852.3", "0.071588"], ["83851.68", "0.005962"], ["83849.82", "0"], ["83846.05", "0.003329"], ["83843.52", "0.002982"], ["83843.51", "0"], ["83842.31", "0.058414"], ["83841.01", "0"], ["83839.74", "0.023616"], ["83835.77", "0.114962"], ["83815.66", "0.005962"], ["83808.37", "0.357935"], ["83805.58", "0"], ["83804.32", "0"], ["83804.31", "0"], ["83804.02", "0.013"], ["83804.01", "0.012887"], ["83803.62", "0"], ["83803.61", "0"], ["83803.33", "0.04"], ["83802.89", "0"], ["83802.76", "0"], ["83802.27", "0"], ["83802.06", "0"]], "a": [["83860.96", "0.740024"], ["83861.31", "0.011924"], ["83861.56", "0"], ["83862.3", "0.0004"], ["83862.31", "0.24258"], ["83862.49", "0"], ["83863.12", "0"], ["83863.25", "0.000153"], ["83864.14", "0.000099"], ["83865.15", "0.000591"], ["83865.6", "0.109978"], ["83866.68", "0"], ["83868.63", "0"], ["83871.18", "0.005962"], ["83871.61", "0.178868"], ["83872.34", "0.735299"], ["83872.51", "0"], ["83873.09", "0"], ["83876.52", "0"], ["83880.01", "0.196475"], ["83885.77", "0"], ["83888.89", "0"], ["83890.73", "0.089922"], ["83890.96", "0"], ["83890.97", "0"], ["83891.66", "0.0004"], ["83891.67", "0.000354"], ["83896.12", "0.026937"], ["83901", "0"], ["83903.42", "0"], ["83906.2", "0.119407"], ["83906.21", "0"], ["83906.51", "0.0015"], ["83906.52", "0.003"], ["83906.71", "0.00009"], ["83906.8", "0.00169"], ["83907.09", "0.001333"]], "u": 69232, "seq": 67537861931}, "cts": 1742543253114, "record_time": 1742543253.1878}
{"topic": "orderbook.200.BTCUSDT", "ts": 1742543253320, "type": "delta", "data": {"s": "BTCUSDT", "b": [["83860.95", "0.006148"], ["83843.52", "0"], ["83842.32", "0.002982"], ["83842.31", "0"], ["83839.74", "0"], ["83830.92", "0.001114"], ["83828.4", "0.001114"], ["83808.37", "0"], ["83805.58", "0.357938"]], "a": [["83860.97", "0.003576"], ["83862.52", "0.000153"], ["83863.25", "0"], ["83867.66", "0.011923"], ["83870.84", "0"], ["83872.34", "0.358163"], ["83872.6", "1"], ["83873.36", "0.178868"], ["83873.7", "1.338838"], ["83874.13", "0.178868"], ["83875.07", "0.178868"], ["83876.95", "0.001098"], ["83888.71", "0.223627"], ["83890.86", "0.0004"], ["83890.87", "0.000354"], ["83891.66", "0"], ["83891.67", "0"], ["83905.6", "0"], ["83905.65", "0"], ["83906.2", "0"], ["83906.51", "0"], ["83906.52", "0"], ["83906.71", "0"], ["83906.8", "0"], ["83907.09", "0"]], "u": 69233, "seq": 67537862284}, "cts": 1742543253316, "record_time": 1742543253.28799}
{"topic": "orderbook.200.BTCUSDT", "ts": 1742543253519, "type": "delta", "data": {"s": "BTCUSDT", "b": [["83860.95", "0"], ["83857.14", "0.003166"], ["83856.53", "0"], ["83855.58", "0.004482"], ["83854.94", "0"], ["83852.65", "0.008964"], ["83850.75", "0"], ["83848.46", "0.017929"], ["83845.7", "0"], ["83844.89", "0.08699"], ["83844.86", "0"], ["83844.62", "0"], ["83844.31", "0.114728"], ["83844.07", "0.123648"], ["83841.1", "0.0019"], ["83840.06", "0"], ["83839.51", "0.058235"], ["83835.9", "0"], ["83834.82", "0"], ["83834.4", "0"], ["83834.27", "0.168342"], ["83833.06", "0"], ["83832.51", "0.061944"], ["83830.92", "0"], ["83828.4", "0"], ["83828.36", "0.000979"], ["83826.06", "0"], ["83825.84", "0.000979"], ["83825.72", "0"], ["83825.51", "0.112977"], ["83825.17", "0.311292"], ["83812.4", "0.0016"], ["83809.72", "0.127261"]], "a": [["83860.01", "0.648455"], ["83860.48", "0.003"], ["83860.94", "0.003"], ["83860.95", "0.110658"], ["83860.96", "0.198831"], ["83860.97", "0"], ["83862.29", "0.004039"], ["83862.31", "0.171"], ["83862.36", "0.000153"], ["83862.52", "0"], ["83864.43", "0.007931"], ["83865.39", "0"], ["83867.36", "0.015862"], ["83868.81", "0.112221"], ["83869.27", "0.116725"], ["83869.36", "0"], ["83869.67", "0"], ["83869.82", "0"], ["83871.56", "0.031723"], ["83871.61", "0.304077"], ["83872.34", "1.176025"], ["83873.86", "0"], ["83874.51", "0.054492"], ["83875.06", "0"], ["83876.18", "0.001352"], ["83876.24", "0.001363"], ["83876.95", "0"], ["83877.5", "0.0001"], ["83878.1", "0"], ["83878.7", "0.001352"], ["83878.75", "0.001363"], ["83879.07", "0.169709"], ["83879.26", "0.178868"], ["83879.31", "0.167676"], ["83879.62", "0"], ["83879.86", "0"], ["83880.71", "0.023849"], ["83881.51", "0.055153"], ["83882.06", "0"], ["83886.2", "0.023849"], ["83886.31", "0.311205"], ["83886.86", "0"], ["83887.12", "0.023849"], ["83888.17", "0.274409"], ["83888.51", "0.111179"], ["83888.72", "0"], ["83889.06", "0"], ["83890.36", "0.0004"], ["83890.37", "0.000354"], ["83890.43", "0.023849"], ["83890.86", "0"], ["83890.87", "0"], ["83896.84", "0.023849"], ["83901.93", "1.430005"], ["83902.88", "0"], ["83903.43", "0"], ["83903.52", "0"], ["83903.8", "0"], ["83903.9", "0"], ["83904.27", "0"], ["83904.59", "0"], ["83904.6", "0"], ["83904.78", "0"], ["83905.12", "0"], ["83905.43", "0"], ["83905.54", "0"], ["83905.59", "0"]], "u": 69234, "seq": 67537863269}, "cts": 1742543253516, "record_time": 1742543253.489315}
{"topic": "orderbook.200.BTCUSDT", "ts": 1742543253720, "type": "delta", "data": {"s": "BTCUSDT", "b": [["83860", "0.006022"], ["83857.78", "0"], ["83856.54", "0.008961"], ["83844.89", "0.145395"], ["83844.38", "0.122341"], ["83844.31", "0"], ["83844.14", "0.112543"], ["83844.07", "0"], ["83840.54", "0.115367"], ["83839.72", "0.024303"], ["83839.58", "0.06216"], ["83839.51", "0"], ["83835.31", "0.003953"], ["83834.42", "0.003"], ["83834.34", "0.178321"], ["83834.27", "0"], ["83833.54", "0.171686"], ["83832.58", "0.061399"], ["83832.52", "0.062704"], ["83832.51", "0"], ["83831.61", "0"], ["83826.54", "0.277403"], ["83825.58", "0.113279"], ["83825.51", "0"], ["83825.24", "0.283756"], ["83825.17", "0"], ["83815.66", "0"], ["83815.44", "0.004772"], ["83803.66", "0"], ["83803.57", "0"], ["83803.4", "0"], ["83803.33", "0"]], "a": [["83860.01", "0.760904"], ["83860.95", "0.083668"], ["83860.96", "0.183"], ["83862.29", "0.0008"], ["83862.36", "0"], ["83862.84", "0.000153"], ["83864.14", "0"], ["83864.19", "0.011924"], ["83866.47", "0"], ["83866.71", "0.011923"], ["83867.66", "0"], ["83868.81", "0"], ["83868.88", "0.119643"], ["83869.27", "0"], ["83869.34", "0.119194"], ["83871.61", "0.125209"], ["83873.44", "0.122659"], ["83874.13", "0"], ["83874.51", "0"], ["83874.58", "0.056182"], ["83875.07", "0"], ["83875.11", "0.001187"], ["83876.05", "0"], ["83876.1", "0.001338"], ["83876.18", "0"], ["83876.24", "0"], ["83876.79", "0.303072"], ["83877.62", "0.001187"], ["83878.62", "0.001338"], ["83878.7", "0"], ["83878.75", "0"], ["83879.07", "0"], ["83879.14", "0.175672"], ["83879.26", "0"], ["83879.31", "0"], ["83879.38", "0.172125"], ["83880.44", "0.178181"], ["83881.51", "0"], ["83881.58", "0.059732"], ["83884.18", "0.003"], ["83885.11", "0"], ["83886.31", "0"], ["83886.38", "0.301658"], ["83887.44", "0.286726"], ["83888.17", "0"], ["83888.24", "0.276797"], ["83888.51", "0"], ["83888.58", "0.119912"], ["83888.71", "0"], ["83890.36", "0"], ["83890.37", "0"], ["83890.45", "0.0004"], ["83890.46", "0.000354"], ["83897.46", "0.073664"], ["83900.29", "0"], ["83903.43", "0.11"], ["83903.52", "0.001466"], ["83903.8", "0.0006"], ["83903.9", "0.023845"]], "u": 69235, "seq": 67537863752}, "cts": 1742543253712, "record_time": 1742543253.712715}
{"topic": "orderbook.200.BTCUSDT", "ts": 1742543253920, "type": "delta", "data": {"s": "BTCUSDT", "b": [["83856.83", "0.000099"], ["83832.52", "0.044121"], ["83812.28", "0.11"], ["83809.72", "0.127307"], ["83805.58", "0.357942"], ["83804.02", "0"], ["83804.01", "0"]], "a": [["83860.01", "0.773483"], ["83860.96", "0.174"], ["83863.19", "0.000099"], ["83864.06", "0.238983"], ["83864.07", "0.17887"], ["83865.6", "0"], ["83866.68", "0.17887"], ["83870.87", "0.17887"], ["83873.7", "1.34486"], ["83874.74", "0.001141"], ["83875.11", "0"], ["83875.79", "0.001285"], ["83876.1", "0"], ["83877.62", "0"], ["83878.62", "0"], ["83889.17", "0"], ["83890.45", "0"], ["83890.46", "0"], ["83890.65", "0.0004"], ["83890.66", "0.000354"], ["83897.46", "0.073665"], ["83897.6", "0.04"], ["83897.61", "0.04"], ["83903.52", "0"], ["83903.8", "0"], ["83903.9", "0"]], "u": 69236, "seq": 67537863927}, "cts": 1742543253912, "record_time": 1742543253.887564}
{"topic": "orderbook.200.BTCUSDT", "ts": 1742543254120, "type": "delta", "data": {"s": "BTCUSDT", "b": [["83860", "0.005962"], ["83851.68", "0"], ["83850.73", "0.005962"], ["83840.54", "0.000255"], ["83840.53", "0.109116"], ["83835.77", "0"], ["83835.57", "1"], ["83834.99", "0.115278"], ["83833.54", "0"], ["83833.53", "0.164845"], ["83826.55", "0.238507"], ["83826.54", "0"], ["83826.53", "0.280702"], ["83812.28", "0"], ["83805.58", "0.357941"], ["83804.15", "0"], ["83804.11", "0"]], "a": [["83862.84", "0"], ["83863.01", "0.000153"], ["83870.23", "0.005962"], ["83871.18", "0"], ["83873.43", "0.122627"], ["83873.44", "0"], ["83873.7", "1.338838"], ["83873.97", "0.00106"], ["83874.65", "0.001131"], ["83874.74", "0"], ["83875.79", "0"], ["83876.49", "0.00106"], ["83877.17", "0.001131"], ["83880.43", "0.165093"], ["83880.44", "0"], ["83887.43", "0.310165"], ["83887.44", "0"], ["83890.65", "0"], ["83890.66", "0.0004"], ["83890.67", "0.000354"], ["83897.6", "0"], ["83897.61", "0"], ["83897.8", "0.04"], ["83897.81", "0.04"], ["83902.98", "0"], ["83903.43", "0"]], "u": 69237, "seq": 67537864170}, "cts": 1742543254109, "record_time": 1742543254.087057}
{"topic": "orderbook.200.BTCUSDT", "ts": 1742543254320, "type": "delta", "data": {"s": "BTCUSDT", "b": [["83860", "0.00603"], ["83856.54", "0.005961"], ["83844.38", "0"], ["83844.14", "0"], ["83840.53", "0"], ["83839.58", "0"], ["83836.1", "0.49326"], ["83834.34", "0"], ["83833.53", "0"], ["83833.52", "0.192539"], ["83832.58", "0"], ["83826.53", "0"], ["83826.52", "0.292309"], ["83825.58", "0"], ["83825.24", "0"], ["83822.21", "0"], ["83805.58", "0"], ["83804.53", "0.013"], ["83804.52", "0.013617"], ["83804.15", "0.000333"], ["83803.66", "0.000255"], ["83803.57", "1.788407"], ["83803.43", "0.04"], ["83803.42", "0.039653"], ["83803.4", "0.04"], ["83802.89", "0.058414"], ["83802.76", "0.00009"], ["83802.27", "0.001333"], ["83802.06", "0.001466"]], "a": [["83860.01", "0.857193"], ["83863.01", "0"], ["83864.07", "0"], ["83868.88", "0"], ["83869.33", "0.113294"], ["83869.34", "0.001333"], ["83870.84", "0.17887"], ["83870.87", "0"], ["83872.35", "0"], ["83873.36", "0"], ["83873.43", "0"], ["83873.69", "0.005962"], ["83873.97", "0"], ["83874.58", "0"], ["83874.65", "0"], ["83876.13", "0.001343"], ["83876.49", "0"], ["83877.17", "0"], ["83877.75", "0.001204"], ["83879.14", "0"], ["83879.38", "0"], ["83880.42", "0.185705"], ["83880.43", "0"], ["83881.58", "0"], ["83886.37", "0.236338"], ["83886.38", "0"], ["83887.42", "0.280404"], ["83887.43", "0"], ["83888.23", "0.285759"], ["83888.24", "0"], ["83888.58", "0"], ["83890.56", "0.0004"], ["83890.57", "0.000354"], ["83890.66", "0"], ["83890.67", "0"], ["83898.08", "0.013"], ["83898.09", "0.013"], ["83902.98", "0.023845"], ["83903.43", "0.11"], ["83903.52", "0.001466"], ["83903.8", "0.0006"], ["83903.9", "0.023845"], ["83904.27", "0.001"], ["83904.6", "2.305712"], ["83904.78", "0.000333"], ["83905.12", "0.000256"]], "u": 69238, "seq": 67537864543}, "cts": 1742543254310, "record_time": 1742543254.287785}
{"topic": "orderbook.200.BTCUSDT", "ts": 1742543254519, "type": "delta", "data": {"s": "BTCUSDT", "b": [["83860", "0.00683"], ["83844.89", "0.142786"], ["83844.37", "0.113871"], ["83844.14", "0.112645"], ["83844.01", "0.002982"], ["83842.32", "0"], ["83840.53", "0.120103"], ["83839.57", "0.056529"], ["83834.34", "0.17658"], ["83833.53", "0.164037"], ["83833.52", "0.009685"], ["83832.57", "0.058469"], ["83826.55", "0"], ["83826.53", "0.292063"], ["83826.52", "0"], ["83825.57", "0.123276"], ["83825.24", "0.273567"], ["83812.56", "0.127306"], ["83809.72", "0"], ["83805.58", "0.35794"], ["83804.53", "0"], ["83804.52", "0.00073"], ["83804.11", "0.171"], ["83803.66", "0"], ["83803.57", "0"], ["83803.43", "0"], ["83803.42", "0"], ["83803.4", "0"], ["83802.89", "0"], ["83802.76", "0"], ["83802.27", "0"], ["83802.06", "0"]], "a": [["83860.01", "0.774377"], ["83863.47", "0.024001"], ["83868.87", "0.11472"], ["83869.33", "0"], ["83869.34", "0.12466"], ["83873.43", "0.113574"], ["83873.69", "0"], ["83873.7", "1.345668"], ["83874.57", "0.059745"], ["83876.13", "0"], ["83876.79", "0.168471"], ["83877.75", "0"], ["83879.14", "0.168356"], ["83879.37", "0.169817"], ["83880.42", "0"], ["83880.43", "0.177804"], ["83881.57", "0.056547"], ["83886.37", "0.310462"], ["83887.42", "0"], ["83887.43", "0.27393"], ["83888.23", "0"], ["83888.24", "0.282737"], ["83888.57", "0.111218"], ["83890.56", "0"], ["83890.57", "0"], ["83891.36", "0.0004"], ["83891.37", "0.000354"], ["83893.21", "0.003554"], ["83897.59", "0"], ["83897.8", "0"], ["83897.81", "0"], ["83898.08", "0"], ["83898.09", "0"], ["83898.3", "0.0406"], ["83898.31", "0.04"], ["83898.98", "0.013"], ["83898.99", "0.013"], ["83900.63", "0"], ["83905.12", "0"]], "u": 69239, "seq": 67537864757}, "cts": 1742543254516, "record_time": 1742543254.500577}
{"topic": "orderbook.200.BTCUSDT", "ts": 1742543254719, "type": "delta", "data": {"s": "BTCUSDT", "b": [], "a": [["83860.01", "0.772101"], ["83866.59", "0.17887"], ["83867.18", "0.438332"], ["83870.87", "0.17887"], ["83873.36", "0.17887"], ["83873.7", "1.338838"], ["83875.12", "0.001189"], ["83876.79", "0.248834"], ["83878.96", "0.001403"], ["83890.56", "0.0004"], ["83890.57", "0.000354"], ["83891.36", "0"], ["83891.37", "0"], ["83903.8", "0"], ["83903.9", "0"], ["83904.27", "0"], ["83904.6", "0"], ["83904.78", "0"]], "u": 69240, "seq": 67537864943}, "cts": 1742543254716, "record_time": 1742543254.748747}
{"topic": "orderbook.200.BTCUSDT", "ts": 1742543254919, "type": "delta", "data": {"s": "BTCUSDT", "b": [["83860", "0.006923"], ["83844.01", "0"], ["83842.31", "0.002982"], ["83830.3", "0.012205"], ["83804.11", "0"]], "a": [["83860.37", "0.002003"], ["83863.47", "0.023848"], ["83864.07", "0.000153"], ["83873.36", "0"], ["83873.7", "1.345761"], ["83875.12", "0"], ["83877.14", "0.001128"], ["83877.27", "0.001143"], ["83878.96", "0"], ["83880.69", "0"], ["83890.56", "0"], ["83890.57", "0"], ["83890.95", "0.0004"], ["83890.96", "0.000354"]], "u": 69241, "seq": 67537865165}, "cts": 1742543254917, "record_time": 1742543254.886274}
{"topic": "orderbook.200.BTCUSDT", "ts": 1742543255120, "type": "delta", "data": {"s": "BTCUSDT", "b": [["83860", "0"], ["83859.51", "0"], ["83859.4", "0"], ["83858.99", "0"], ["83858.64", "0"], ["83857.39", "0"], ["83857.18", "0"], ["83857.14", "0"], ["83856.83", "0"], ["83856.76", "0"], ["83856.54", "0"], ["83855.58", "0"], ["83855.21", "0"], ["83854.9", "0"], ["83854.8", "0"], ["83854.45", "0"], ["83854.38", "0"], ["83854.33", "0"], ["83854.32", "0"], ["83853.9", "0"], ["83853.48", "0"], ["83852.65", "0"], ["83852.3", "0"], ["83851.62", "0.00528"], ["83848.46", "0"], ["83848.25", "0.008958"], ["83846.05", "0"], ["83844.91", "0"], ["83844.89", "0"], ["83844.06", "0.017917"], ["83844", "0"], ["83843.5", "0"], ["83842.31", "0"], ["83842.3", "0"], ["83841.91", "0"], ["83841.9", "0"], ["83841.57", "0.005962"], ["83841.1", "0"], ["83841", "0"], ["83840.7", "0"], ["83839.41", "0"], ["83838.5", "0"], ["83837.91", "0"], ["83837.23", "0"], ["83836.8", "0"], ["83836.09", "0"], ["83835.57", "0"], ["83835.28", "0"], ["83834.99", "0"], ["83833.69", "0"], ["83833.59", "0.010777"], ["83830.4", "0"], ["83830.3", "0"], ["83829.12", "0"], ["83827.16", "0.017899"], ["83825.02", "0"], ["83823.98", "0.01437"], ["83821.13", "0"], ["83819.53", "0"], ["83819.5", "0.023849"], ["83819.08", "0.011931"], ["83814.54", "0"], ["83812.56", "0"], ["83811.06", "0"], ["83805.58", "0"], ["83803.66", "0.000255"], ["83803.57", "1.788407"], ["83803.4", "0.04"], ["83802.89", "0.058414"], ["83802.76", "0.00009"], ["83802.53", "0.013"], ["83802.52", "0.012887"], ["83802.27", "0.001333"], ["83802.06", "0.001466"], ["83801.44", "0.04"], ["83801.43", "0.039655"], ["83801.33", "0.009"], ["83801.05", "0.023852"], ["83800.72", "0.000206"], ["83800.34", "0.029825"], ["83800.12", "0.119407"], ["83800", "0.003639"], ["83799.96", "0.000333"], ["83799.57", "0.000255"], ["83799.29", "0.05"], ["83799.08", "0.049571"], ["83799.05", "0.000255"], ["83798.64", "0.023852"], ["83798.4", "0.127325"], ["83798.08", "0.001333"], ["83797.45", "0.001466"], ["83797.4", "0.011961"], ["83796.8", "0.04"], ["83796.53", "0.000206"], ["83796.28", "0.354242"], ["83795.77", "0.000333"], ["83795.18", "1.788647"], ["83794.96", "0.000255"], ["83794.88", "0.419292"], ["83794.85", "0.119407"], ["83794.7", "0.04"], ["83794.44", "0.000255"], ["83794.33", "0.00009"], ["83793.89", "0.001333"], ["83793.66", "0.058414"], ["83793.6", "0.00036"], ["83793", "0.04"], ["83792.86", "0.014045"], ["83792.84", "0.001466"], ["83792.34", "0.000206"], ["83791.6", "0.0006"], ["83791.58", "0.000333"]], "a": [["83852.78", "0.274781"], ["83853.05", "0.089922"], ["83853.49", "0.022678"], ["83853.91", "0.000478"], ["83854.33", "0.022678"], ["83855.58", "0.006592"], ["83855.59", "0.112276"], ["83855.67", "0.010778"], ["83856.55", "0.1138"], ["83858.65", "0.99719"], ["83858.73", "0.007931"], ["83859", "0.058414"], ["83860", "0.448849"], ["83860.01", "0.384368"], ["83860.11", "0.015875"], ["83860.4", "0.002"], ["83860.5", "0.0002"], ["83860.94", "0"], ["83860.95", "0.007287"], ["83862", "0.001466"], ["83862.84", "0.000333"], ["83863.02", "0"], ["83863.59", "0.000188"], ["83863.6", "0.000255"], ["83863.66", "0.121921"], ["83864.07", "0"], ["83864.13", "0.000255"], ["83864.3", "0.031748"], ["83864.43", "0"], ["83864.56", "0.00009"], ["83866.59", "0"], ["83866.68", "0"], ["83866.75", "0"], ["83867.28", "0"], ["83867.36", "0"], ["83867.97", "0.03718"], ["83868.39", "0.042515"], ["83868.51", "0.014369"], ["83868.81", "0.010615"], ["83868.86", "0.058414"], ["83870.32", "0.00018"], ["83870.84", "0"], ["83870.87", "0"], ["83871.56", "0"], ["83871.61", "0"], ["83871.81", "0"], ["83872.44", "0"], ["83873.7", "1.338838"], ["83873.99", "0"], ["83874.12", "0"], ["83874.8", "0.026937"], ["83875.26", "0.119247"], ["83875.8", "0"], ["83876.62", "0.001439"], ["83877.14", "0"], ["83877.27", "0"], ["83877.72", "0.023849"], ["83878.42", "0"], ["83879.14", "0.169795"], ["83880.06", "0"], ["83881.73", "0"], ["83887.36", "0"], ["83888.81", "0.005962"], ["83889.77", "0.0004"], ["83889.78", "0.000352"], ["83890.73", "0"], ["83890.95", "0"], ["83890.96", "0"], ["83894.93", "0"], ["83895.53", "0.119407"], ["83896.02", "0"], ["83896.12", "0"], ["83898.29", "0.357972"], ["83900.58", "0"], ["83901.03", "0"], ["83901.34", "0"], ["83901.93", "0"], ["83902.69", "0"], ["83902.89", "0"], ["83902.98", "0"], ["83903.43", "0"], ["83903.52", "0"]], "u": 69242, "seq": 67537866107}, "cts": 1742543255117, "record_time": 1742543255.088119}
{"topic": "orderbook.200.BTCUSDT", "ts": 1742543255319, "type": "delta", "data": {"s": "BTCUSDT", "b": [["83852.77", "0.007428"], ["83851.66", "0.011017"], ["83851.62", "0"], ["83849.6", "0.000099"], ["83848.74", "0"], ["83848.37", "0.005812"], ["83848.25", "0"], ["83846.53", "0"], ["83845.44", "0.008958"], ["83845.17", "0.000926"], ["83844.37", "0"], ["83844.14", "0"], ["83844.06", "0"], ["83841.86", "0"], ["83841.25", "0.017918"], ["83840.53", "0"], ["83839.72", "0"], ["83839.65", "0.000298"], ["83839.57", "0"], ["83838.66", "0.0716"], ["83838.46", "0.003606"], ["83836.7", "0"], ["83836.1", "0"], ["83834.8", "0"], ["83834.43", "0.002983"], ["83834.34", "0"], ["83834.29", "0.005962"], ["83833.59", "0"], ["83833.53", "0"], ["83833.3", "0.04"], ["83832.7", "0.000298"], ["83832.58", "0.061263"], ["83832.57", "0"], ["83832.52", "0"], ["83832.1", "0.04"], ["83831.5", "0.04"], ["83831.32", "0.119662"], ["83830.85", "0"], ["83830.15", "0"], ["83829.55", "0.115245"], ["83829.29", "0.058414"], ["83829.19", "0.010783"], ["83828.36", "0"], ["83826.54", "0.242847"], ["83826.53", "0"], ["83826.3", "0.04"], ["83826", "0.04"], ["83825.84", "0"], ["83825.57", "0"], ["83825.24", "0"], ["83823.99", "0.013472"], ["83822.31", "0.046405"], ["83821.9", "0"], ["83820.9", "0.229279"], ["83820.25", "0.04551"], ["83819.86", "0.001121"], ["83819.45", "0"], ["83817.43", "0"], ["83817.34", "0.001121"], ["83816.14", "0.003552"], ["83815.44", "0"], ["83814.79", "0"], ["83812.93", "0.008805"], ["83811.79", "0.071623"], ["83811.41", "0"], ["83809.8", "0"], ["83809.11", "0"], ["83808.63", "0"], ["83808.12", "0.071626"], ["83805.52", "0"], ["83804.28", "0.023851"], ["83804.11", "0.171"], ["83802.53", "0"], ["83802.52", "0"], ["83801.95", "0.024634"], ["83801.44", "0"], ["83801.43", "0"], ["83801.05", "0"], ["83799.29", "0"], ["83799.08", "0"], ["83798.64", "0"], ["83798.54", "0.013"], ["83798.53", "0.012886"], ["83798.41", "0.357978"], ["83798.4", "0"], ["83798.15", "0.005962"], ["83797.87", "0.023851"], ["83797.84", "0.04"], ["83797.83", "0.039651"], ["83796.28", "0"], ["83795.72", "0.171"], ["83795.46", "0.004586"], ["83795.29", "0.05"], ["83795.28", "0.049567"], ["83794.56", "0.023851"], ["83791.64", "0.023851"], ["83791.58", "0"]], "a": [["83852.78", "0.930148"], ["83853.49", "0"], ["83853.55", "0.142116"], ["83853.56", "0.339919"], ["83853.61", "0.011925"], ["83853.91", "0"], ["83854.33", "0"], ["83855.58", "0"], ["83855.59", "0"], ["83855.65", "0.00907"], ["83856.2", "0.000153"], ["83856.24", "0.046405"], ["83856.96", "0.011925"], ["83857.18", "0.007937"], ["83858.65", "0"], ["83858.73", "0"], ["83859", "0"], ["83859.09", "0.0002"], ["83859.48", "0.011924"], ["83859.98", "0.296503"], ["83860", "0.00692"], ["83860.01", "0.27016"], ["83860.4", "0.102"], ["83860.5", "0"], ["83860.74", "0.01067"], ["83860.96", "0.003"], ["83861.16", "0.14344"], ["83861.31", "0"], ["83861.58", "0.03179"], ["83862.15", "0.010725"], ["83862.28", "0"], ["83862.5", "0.192"], ["83862.57", "0.00528"], ["83862.98", "0.01595"], ["83863.19", "0"], ["83863.65", "0.287366"], ["83864.06", "0"], ["83864.19", "0"], ["83864.24", "0.477767"], ["83865.11", "0"], ["83865.5", "0.116"], ["83866.71", "0"], ["83867.4", "0.1"], ["83867.5", "0.121048"], ["83867.53", "0.001326"], ["83867.93", "0.028239"], ["83867.97", "0"], ["83868.39", "0"], ["83868.81", "0"], ["83868.87", "0"], ["83869", "0.104"], ["83869.34", "0.001333"], ["83869.41", "0.013745"], ["83869.87", "0.015574"], ["83869.97", "0.001314"], ["83870.09", "0.006923"], ["83872.4", "0"], ["83872.65", "0.071571"], ["83872.95", "0.008805"], ["83873.43", "0"], ["83874.57", "0"], ["83876.62", "0"], ["83877.13", "2.265492"], ["83877.95", "0"], ["83879.14", "0"], ["83879.37", "0"], ["83879.66", "0.003575"], ["83880.43", "0"], ["83880.95", "0"], ["83881.57", "0"], ["83881.89", "0"], ["83882.95", "0.114875"], ["83886.37", "0.0004"], ["83886.38", "0.000352"], ["83887.32", "0.024732"], ["83887.43", "0"], ["83888.24", "0"], ["83888.52", "0.304022"], ["83888.57", "0"], ["83888.97", "0.073665"], ["83889.18", "0.023108"], ["83889.77", "0"], ["83889.78", "0"], ["83890.97", "0.178885"], ["83894.7", "1.430005"], ["83896.09", "0.02749"], ["83897.11", "0.357978"], ["83897.46", "0"], ["83898.29", "0"], ["83900", "0"], ["83900.51", "0"]], "u": 69243, "seq": 67537867581}, "cts": 1742543255317, "record_time": 1742543255.287046}
{"topic": "orderbook.200.BTCUSDT", "ts": 1742543255520, "type": "delta", "data": {"s": "BTCUSDT", "b": [["83850.73", "0"], ["83843.5", "0.005963"], ["83841.26", "0.016668"], ["83838.66", "0"], ["83835.32", "0.002983"], ["83834.43", "0"], ["83834.3", "0.000298"], ["83832.8", "0.04"], ["83832.7", "0"], ["83832.58", "0.098802"], ["83829.5", "0.04"], ["83829.4", "0.04"], ["83827.9", "0.04"], ["83827.8", "0.04"], ["83826.54", "0"], ["83820.9", "0"], ["83820.53", "1.321145"], ["83810.26", "0.011017"], ["83801.23", "0.127336"], ["83800.13", "0.357971"], ["83798.41", "0"], ["83793", "0"], ["83792.86", "0"], ["83792.84", "0"], ["83792.34", "0"], ["83791.64", "0"], ["83791.6", "0"]], "a": [["83852.78", "0.930082"], ["83853.05", "0"], ["83855.48", "0.000153"], ["83855.95", "0.000099"], ["83856.2", "0"], ["83858.64", "0.000333"], ["83859.04", "0.178885"], ["83860", "0"], ["83860.01", "0.269827"], ["83860.74", "0.047905"], ["83860.8", "0.108"], ["83861.16", "0.228525"], ["83861.58", "0.053075"], ["83863", "0.005963"], ["83863.8", "0.104"], ["83864.2", "0.108"], ["83865.7", "0.001083"], ["83865.9", "0.104"], ["83866.89", "0.001226"], ["83866.9", "0"], ["83867.18", "0.264623"], ["83867.53", "0"], ["83867.6", "0"], ["83868.22", "0.001083"], ["83869", "0"], ["83869.97", "0"], ["83870.23", "0"], ["83870.8", "0"], ["83873.87", "0.089922"], ["83874", "0"], ["83875.4", "0"], ["83880.01", "0"], ["83886.07", "0.0004"], ["83886.08", "0.000352"], ["83886.37", "0"], ["83886.38", "0"], ["83888.97", "0.073666"], ["83897.11", "0"], ["83898.6", "2.16016"]], "u": 69244, "seq": 67537867940}, "cts": 1742543255517, "record_time": 1742543255.486427}
{"topic": "orderbook.200.BTCUSDT", "ts": 1742543255720, "type": "delta", "data": {"s": "BTCUSDT", "b": [["83852.77", "0"], ["83852.57", "0"], ["83851.66", "0"], ["83851.02", "0.008542"], ["83848.37", "0.001333"], ["83846.61", "0.004479"], ["83845.06", "0.003"], ["83842.79", "0.071596"], ["83841.26", "0"], ["83839.65", "0"], ["83835.4", "0.003"], ["83834.43", "0.000298"], ["83834.42", "0"], ["83831.27", "0.0003"], ["83830", "1.007487"], ["83829.29", "0.20278"], ["83823.99", "0"], ["83823.23", "0.020441"], ["83804.06", "0.127336"], ["83803.4", "0"], ["83801.23", "0"], ["83795.99", "0.05"], ["83795.98", "0.049567"], ["83795.29", "0"], ["83795.28", "0"], ["83793", "0.04"]], "a": [["83851.03", "1.870008"], ["83851.73", "0.001193"], ["83852.77", "0.258525"], ["83852.78", "0.508713"], ["83853.55", "0.003"], ["83855.66", "0.023743"], ["83856.08", "0.007937"], ["83856.55", "0"], ["83856.76", "0.001333"], ["83857.18", "0"], ["83857.34", "0.0002"], ["83857.39", "0.001466"], ["83858.99", "0.000255"], ["83859.09", "0"], ["83859.4", "0.000188"], ["83859.51", "0.000255"], ["83860.01", "0.100005"], ["83860.95", "0.001333"], ["83862.3", "0"], ["83862.49", "0.178885"], ["83862.51", "0.089922"], ["83865.7", "0"], ["83866.68", "0.178885"], ["83866.89", "0"], ["83867.18", "0.166367"], ["83868.22", "0"], ["83869.86", "0"], ["83870.6", "0.001432"], ["83870.9", "0"], ["83871.61", "0.125219"], ["83872.5", "0"], ["83873.87", "0"], ["83875.07", "0.089442"], ["83876.79", "0.674851"], ["83877.23", "0.003"], ["83884.18", "0"], ["83885.65", "0.0004"], ["83885.66", "0.000352"], ["83886.07", "0"], ["83886.08", "0"], ["83892.95", "1.43023"], ["83894.7", "0"], ["83896.02", "0.089442"], ["83898.6", "0"], ["83898.98", "0"], ["83898.99", "0"], ["83899.06", "0"], ["83899.4", "0"], ["83899.67", "0"]], "u": 69245, "seq": 67537868374}, "cts": 1742543255716, "record_time": 1742543255.686585}
{"topic": "orderbook.200.BTCUSDT", "ts": 1742543255919, "type": "delta", "data": {"s": "BTCUSDT", "b": [["83849.6", "0"], ["83842.8", "0.000298"], ["83842.63", "0.171196"], ["83841.26", "0.016579"], ["83834.43", "0"], ["83834.21", "0.111259"], ["83833.97", "0.120291"], ["83830.36", "0.12282"], ["83829.4", "0.09723"], ["83824.17", "0.168536"], ["83823.36", "0.172408"], ["83822.4", "0.057254"], ["83820.44", "0.012152"], ["83816.36", "0.302831"], ["83815.4", "0.119144"], ["83815.07", "0.27949"], ["83810.26", "0"], ["83809.97", "0.008542"], ["83804.06", "0"], ["83801.23", "0.127329"], ["83800.13", "0"], ["83797.85", "0.357968"], ["83795.99", "0"], ["83795.98", "0"], ["83795.9", "0.05"], ["83795.89", "0.049567"], ["83794.88", "0"], ["83794.85", "0"], ["83794.7", "0"], ["83794.56", "0"], ["83794.44", "0"], ["83794.33", "0"], ["83793.89", "0"], ["83793.66", "0"], ["83793.6", "0"], ["83793", "0"]], "a": [["83851.86", "0.011925"], ["83852.78", "0.426182"], ["83855.48", "0"], ["83855.85", "0.000153"], ["83855.95", "0"], ["83858.71", "0.118178"], ["83859.17", "0.116817"], ["83859.48", "0"], ["83863.26", "0.111818"], ["83864.4", "0.055927"], ["83865.81", "0.23851"], ["83865.89", "0.178857"], ["83867.56", "0.178853"], ["83868.97", "0.170552"], ["83869.21", "0.181771"], ["83870.26", "0.181177"], ["83871.4", "0.055634"], ["83872.34", "0.358163"], ["83876.21", "0.311698"], ["83877.26", "0.295277"], ["83877.95", "0.012222"], ["83878.07", "0.30781"], ["83878.4", "0.113604"], ["83885.64", "0.0004"], ["83885.65", "0.000352"], ["83885.66", "0"], ["83888.97", "0.073667"], ["83890.97", "0"], ["83896.39", "0"], ["83896.42", "0"], ["83896.84", "0"], ["83897.12", "0"], ["83897.13", "0"], ["83897.15", "0"], ["83897.49", "0"], ["83898.28", "0"], ["83898.3", "0"], ["83898.31", "0"], ["83898.7", "0"], ["83898.71", "0"], ["83898.91", "0"]], "u": 69246, "seq": 67537868706}, "cts": 1742543255912, "record_time": 1742543255.886434}
{"topic": "orderbook.200.BTCUSDT", "ts": 1742543256119, "type": "delta", "data": {"s": "BTCUSDT", "b": [["83848.04", "0.000099"], ["83843.5", "0"], ["83842.8", "0.073136"], ["83841.75", "0.005963"], ["83838.47", "0.002983"], ["83835.32", "0"], ["83834.22", "0.072371"], ["83834.21", "0"], ["83834.19", "0.112313"], ["83833.97", "0"], ["83833.95", "0.121401"], ["83833.74", "0.011146"], ["83831.44", "0.023561"], ["83830.36", "0"], ["83830.35", "0.123838"], ["83829.4", "0.04"], ["83829.39", "0.060582"], ["83829.19", "0"], ["83824.17", "0"], ["83824.15", "0.179637"], ["83823.36", "0"], ["83823.35", "0.170468"], ["83822.4", "0"], ["83822.39", "0.062023"], ["83817.49", "0.071873"], ["83816.36", "0"], ["83816.35", "0.29497"], ["83815.4", "0"], ["83815.39", "0.12102"], ["83815.07", "0"], ["83815.05", "0.28058"], ["83808.12", "0"], ["83801.01", "0.11"], ["83800.13", "0.357962"], ["83798.75", "0.04"], ["83798.74", "0.039649"], ["83797.85", "0"], ["83797.84", "0"], ["83797.83", "0"], ["83795.89", "0.049565"], ["83795.72", "0"], ["83795.46", "0"], ["83795.18", "0"], ["83794.96", "0"]], "a": [["83851.03", "1.902245"], ["83854.01", "0.000099"], ["83855.22", "0.000591"], ["83858.69", "0.119679"], ["83858.71", "0"], ["83859.15", "0.114676"], ["83859.17", "0"], ["83861.25", "0.005963"], ["83862.51", "0"], ["83863", "0"], ["83863.25", "0.11591"], ["83863.26", "0"], ["83863.65", "0.504078"], ["83864.39", "0.061078"], ["83864.4", "0"], ["83865.14", "0.001357"], ["83865.15", "0"], ["83868.95", "0.167407"], ["83868.97", "0"], ["83869.19", "0.174395"], ["83869.21", "0"], ["83869.24", "0.17885"], ["83869.62", "0"], ["83870.25", "0.166096"], ["83870.26", "0"], ["83870.44", "0"], ["83871.39", "0.058269"], ["83871.4", "0"], ["83876.19", "0.304741"], ["83876.21", "0"], ["83877.25", "0.293356"], ["83877.26", "0"], ["83878.05", "0.28723"], ["83878.07", "0"], ["83878.39", "0.113881"], ["83878.4", "0"], ["83880.06", "0.125222"], ["83880.28", "0.003438"], ["83885.54", "0.0004"], ["83885.55", "0.000352"], ["83885.64", "0"], ["83885.65", "0"], ["83892.49", "0.04"], ["83892.5", "0.04"], ["83893.21", "0"], ["83896.09", "0"], ["83896.21", "0"]], "u": 69247, "seq": 67537868902}, "cts": 1742543256116, "record_time": 1742543256.088485}
{"topic": "orderbook.200.BTCUSDT", "ts": 1742543256320, "type": "delta", "data": {"s": "BTCUSDT", "b": [["83851.02", "0.015702"], ["83845.15", "0.071849"], ["83844.32", "0.001435"], ["83842.81", "0.000298"], ["83842.8", "0.051359"], ["83842.79", "0"], ["83841.06", "0.00375"], ["83838.46", "0"], ["83834.71", "0.15105"], ["83834.7", "0.121059"], ["83834.46", "0.119674"], ["83834.41", "0.000298"], ["83834.3", "0"], ["83834.22", "0"], ["83834.19", "0"], ["83833.95", "0"], ["83832.58", "0.480594"], ["83830.35", "0"], ["83829.9", "0.060867"], ["83829.39", "0"], ["83824.66", "0.165709"], ["83824.15", "0"], ["83823.35", "0"], ["83822.9", "0.055093"], ["83822.39", "0"], ["83820.54", "0.501012"], ["83820.53", "0"], ["83816.35", "0"], ["83815.9", "0.115882"], ["83815.56", "0.27874"], ["83815.39", "0"], ["83815.05", "0"], ["83809.8", "0.046405"], ["83804.52", "0"], ["83801.24", "0.357957"], ["83801.01", "0"], ["83800.13", "0"], ["83798.75", "0"], ["83798.74", "0"], ["83798.65", "0.04"], ["83798.64", "0.039649"], ["83796.11", "0.05"], ["83796.1", "0.049564"], ["83795.9", "0"], ["83795.89", "0"], ["83795.46", "0.004586"], ["83795.18", "1.788647"], ["83794.96", "0.000255"]], "a": [["83851.03", "1.797445"], ["83851.86", "0"], ["83852.78", "0.417182"], ["83853.55", "0"], ["83858.69", "0"], ["83859.15", "0"], ["83859.2", "0.123824"], ["83859.34", "0.456628"], ["83859.66", "0.118885"], ["83859.98", "0"], ["83861.56", "0.178889"], ["83863.25", "0"], ["83864.39", "0"], ["83864.9", "0.057944"], ["83867.18", "0.365896"], ["83867.93", "0"], ["83868.95", "0"], ["83869.19", "0"], ["83869.46", "0.182318"], ["83869.7", "0.164162"], ["83869.87", "0"], ["83870.25", "0"], ["83870.6", "0"], ["83871.39", "0"], ["83871.9", "0.057431"], ["83873.7", "0"], ["83874.8", "0"], ["83876.19", "0"], ["83876.7", "0.29746"], ["83877.25", "0"], ["83878.05", "0"], ["83878.39", "0"], ["83878.56", "0.271713"], ["83878.9", "0.119526"], ["83879.6", "0.028239"], ["83885.29", "0.026937"], ["83885.54", "0"], ["83885.55", "0"], ["83885.74", "0.0004"], ["83885.75", "0.000352"], ["83892.49", "0"], ["83892.5", "0"], ["83892.59", "0.04"], ["83892.6", "0.04"], ["83896.09", "0.02749"], ["83896.21", "0.011929"], ["83896.39", "0.000333"], ["83896.42", "0.000256"], ["83896.84", "0.023849"], ["83897.13", "0.12433"], ["83897.15", "0.000225"]], "u": 69248, "seq": 67537869243}, "cts": 1742543256310, "record_time": 1742543256.35891}
{"topic": "orderbook.200.BTCUSDT", "ts": 1742543256520, "type": "delta", "data": {"s": "BTCUSDT", "b": [["83851.02", "0.016502"], ["83844.32", "0.000662"], ["83838.47", "0"], ["83835.41", "0.002982"], ["83834.72", "0.000298"], ["83834.71", "0.193367"], ["83834.7", "0"], ["83834.47", "0.120318"], ["83834.46", "0"], ["83834.41", "0"], ["83830.87", "0.109489"], ["83829.91", "0.055137"], ["83829.9", "0"], ["83824.67", "0.174525"], ["83824.66", "0"], ["83823.87", "0.166548"], ["83822.91", "0.055382"], ["83822.9", "0"], ["83820.54", "0"], ["83816.87", "0.299913"], ["83815.91", "0.123525"], ["83815.9", "0"], ["83815.57", "0.305291"], ["83815.56", "0"], ["83815.43", "1.347191"], ["83806.89", "0.127329"], ["83801.23", "0"], ["83796.41", "0.05"], ["83796.4", "0.049564"], ["83796.11", "0"], ["83796.1", "0"], ["83795.72", "0.171"], ["83795.46", "0"], ["83795.18", "0"], ["83794.96", "0"]], "a": [["83851.86", "0.011925"], ["83858.83", "0.023272"], ["83859.2", "0"], ["83859.21", "0.110992"], ["83859.66", "0"], ["83859.67", "0.111403"], ["83861.56", "0"], ["83863.77", "0.121559"], ["83864.9", "0"], ["83864.91", "0.056659"], ["83865.61", "0"], ["83867.41", "1.38427"], ["83869.46", "0"], ["83869.47", "0.163508"], ["83869.7", "0"], ["83869.71", "0.177939"], ["83870.77", "0.187333"], ["83871.9", "0"], ["83871.91", "0.055417"], ["83876.7", "0"], ["83876.71", "0.292338"], ["83877.77", "0.276447"], ["83878.56", "0"], ["83878.57", "0.290453"], ["83878.9", "0"], ["83878.91", "0.121502"], ["83885.66", "0.0004"], ["83885.67", "0.000352"], ["83885.74", "0"], ["83885.75", "0"], ["83888.97", "0.073666"], ["83892.59", "0"], ["83892.6", "0"], ["83892.69", "0.04"], ["83892.7", "0.04"], ["83896.42", "0"], ["83896.84", "0"], ["83897.13", "0"], ["83897.15", "0"]], "u": 69249, "seq": 67537869441}, "cts": 1742543256511, "record_time": 1742543256.487554}
{"topic": "orderbook.200.BTCUSDT", "ts": 1742543256720, "type": "delta", "data": {"s": "BTCUSDT", "b": [["83851.02", "0.023172"], ["83844.32", "0"], ["83835.41", "0.002983"], ["83834.81", "0.044886"], ["83834.8", "0.120169"], ["83834.72", "0"], ["83834.71", "0"], ["83834.56", "0.119357"], ["83834.47", "0"], ["83830.95", "0.117398"], ["83830.87", "0"], ["83829.99", "0.05558"], ["83829.91", "0"], ["83824.76", "0.179297"], ["83824.67", "0"], ["83823.95", "0.171614"], ["83823.87", "0"], ["83822.99", "0.059524"], ["83822.91", "0"], ["83816.95", "0.28063"], ["83816.87", "0"], ["83815.99", "0.113013"], ["83815.91", "0"], ["83815.66", "0.312057"], ["83815.57", "0"], ["83806.89", "0"], ["83804.06", "0.127329"], ["83801.24", "0"], ["83798.66", "0.357963"], ["83796.51", "0.05"], ["83796.5", "0.049564"], ["83796.41", "0"], ["83796.4", "0"], ["83795.46", "0.004586"]], "a": [["83851.03", "1.911245"], ["83855.85", "0"], ["83856.88", "0.000153"], ["83859.21", "0"], ["83859.3", "0.116803"], ["83859.67", "0"], ["83859.76", "0.117698"], ["83863.77", "0"], ["83863.85", "0.112074"], ["83864.91", "0"], ["83864.99", "0.061027"], ["83867.18", "0.748927"], ["83869.47", "0"], ["83869.56", "0.1721"], ["83869.71", "0"], ["83869.8", "0.176222"], ["83870.77", "0"], ["83870.85", "0.170306"], ["83871.91", "0"], ["83871.99", "0.058747"], ["83876.71", "0"], ["83876.8", "0.297476"], ["83877.77", "0"], ["83877.85", "0.303397"], ["83878.57", "0"], ["83878.66", "0.293373"], ["83878.91", "0"], ["83878.99", "0.120028"], ["83885.45", "0.0004"], ["83885.46", "0.000352"], ["83885.66", "0"], ["83885.67", "0"], ["83893.66", "0.005"], ["83896.39", "0"]], "u": 69250, "seq": 67537869642}, "cts": 1742543256716, "record_time": 1742543256.688049}
{"topic": "orderbook.200.BTCUSDT", "ts": 1742543256920, "type": "delta", "data": {"s": "BTCUSDT", "b": [["83842.81", "0"], ["83834.82", "0.000298"], ["83834.81", "0.075119"], ["83804.06", "0"], ["83801.23", "0.127336"], ["83799.78", "0.013"], ["83799.77", "0.012885"], ["83798.67", "0.357963"], ["83798.66", "0"], ["83798.54", "0"], ["83798.53", "0"]], "a": [["83876.79", "0.938919"], ["83885.13", "0.089922"], ["83885.45", "0"], ["83885.46", "0"], ["83885.61", "0.0004"], ["83885.62", "0.000352"], ["83893.1", "0.013"], ["83893.11", "0.013"], ["83896.02", "0"], ["83896.09", "0"], ["83896.21", "0"]], "u": 69251, "seq": 67537869713}, "cts": 1742543256912, "record_time": 1742543256.886817}
{"topic": "orderbook.200.BTCUSDT", "ts": 1742543257120, "type": "delta", "data": {"s": "BTCUSDT", "b": [["83806.89", "0.127336"], ["83801.23", "0"], ["83799.09", "0.04"], ["83799.08", "0.039649"], ["83798.68", "0.357962"], ["83798.67", "0"], ["83798.65", "0"], ["83798.64", "0"], ["83796.53", "0.050206"], ["83796.52", "0.049564"], ["83796.51", "0"], ["83796.5", "0"], ["83795.18", "1.788647"]], "a": [["83851.03", "1.902245"], ["83873.07", "0.003365"], ["83880.28", "0"], ["83892.43", "0.04"], ["83892.44", "0.04"], ["83892.69", "0"], ["83892.7", "0"]], "u": 69252, "seq": 67537869768}, "cts": 1742543257104, "record_time": 1742543257.086166}
{"topic": "orderbook.200.BTCUSDT", "ts": 1742543257320, "type": "delta", "data": {"s": "BTCUSDT", "b": [["83847.05", "0.071593"], ["83845.15", "0.000255"], ["83844.32", "0.000703"], ["83843.31", "0.003888"], ["83841.06", "0"], ["83835", "0.11506"], ["83834.8", "0"], ["83834.76", "0.123655"], ["83834.56", "0"], ["83831.15", "0.10963"], ["83830.95", "0"], ["83830.2", "0.06084"], ["83829.99", "0"], ["83824.96", "0.169111"], ["83824.76", "0"], ["83824.15", "0.18661"], ["83823.95", "0"], ["83823.2", "0.061466"], ["83822.99", "0"], ["83820.9", "0.240158"], ["83817.15", "0.298211"], ["83816.95", "0"], ["83816.2", "0.114694"], ["83815.99", "0"], ["83815.86", "0.275882"], ["83815.66", "0"], ["83807.98", "0.11"], ["83800.13", "0.35796"], ["83799.78", "0"], ["83799.77", "0"], ["83799.68", "0.013"], ["83799.67", "0.012885"], ["83799.09", "0"], ["83799.08", "0"], ["83798.99", "0.04"], ["83798.98", "0.039649"], ["83798.68", "0"], ["83796.53", "0.000206"], ["83796.52", "0"], ["83796.44", "0.05"], ["83795.77", "0"], ["83795.72", "0"], ["83795.46", "0"], ["83795.18", "0"]], "a": [["83851.03", "1.788445"], ["83851.86", "0"], ["83855.67", "0"], ["83859.3", "0"], ["83859.5", "0.123812"], ["83859.76", "0"], ["83859.96", "0.113311"], ["83861", "0.011665"], ["83863.85", "0"], ["83864.05", "0.11743"], ["83864.99", "0"], ["83865.2", "0.061088"], ["83869.56", "0"], ["83869.76", "0.166621"], ["83869.8", "0"], ["83870", "0.165394"], ["83870.85", "0"], ["83871.05", "0.163278"], ["83871.99", "0"], ["83872.2", "0.056775"], ["83876.8", "0"], ["83877", "0.276526"], ["83877.85", "0"], ["83878.05", "0.274779"], ["83878.66", "0"], ["83878.86", "0.282217"], ["83878.99", "0"], ["83879.2", "0.108984"], ["83885.61", "0"], ["83885.62", "0"], ["83885.71", "0.0004"], ["83885.72", "0.000352"], ["83892.43", "0"], ["83892.44", "0"], ["83892.53", "0.04"], ["83892.54", "0.04"], ["83893.1", "0"], ["83893.11", "0"], ["83893.2", "0.013"], ["83893.21", "0.013"], ["83896.02", "0.089442"]], "u": 69253, "seq": 67537869866}, "cts": 1742543257308, "record_time": 1742543257.36967}
{"topic": "orderbook.200.BTCUSDT", "ts": 1742543257519, "type": "delta", "data": {"s": "BTCUSDT", "b": [["83847.06", "0.02423"], ["83844.32", "0"], ["83842.81", "0.000298"], ["83839.45", "0.002982"], ["83835.41", "0"], ["83835.15", "0.110255"], ["83835.1", "0.0022"], ["83835.03", "0.000298"], ["83835.01", "0.08033"], ["83835", "0"], ["83834.91", "0.114329"], ["83834.82", "0"], ["83834.81", "0"], ["83834.76", "0"], ["83831.31", "0.117862"], ["83831.15", "0"], ["83830.35", "0.057964"], ["83830.2", "0"], ["83825.11", "0.172171"], ["83824.96", "0"], ["83824.31", "0.168651"], ["83824.15", "0"], ["83823.35", "0.055096"], ["83823.2", "0"], ["83817.31", "0.30642"], ["83817.15", "0"], ["83816.35", "0.123407"], ["83816.2", "0"], ["83816.01", "0.303267"], ["83815.86", "0"], ["83812.4", "0"], ["83806.89", "0.127286"], ["83806.4", "0.0016"], ["83797.13", "0.05"], ["83797.12", "0.049563"], ["83796.8", "0"], ["83796.53", "0"], ["83796.44", "0"]], "a": [["83851.03", "1.693532"], ["83853.55", "0.009"], ["83858.83", "0"], ["83859.5", "0"], ["83859.65", "0.121323"], ["83859.96", "0"], ["83860.01", "0.02241"], ["83860.11", "0.139053"], ["83860.48", "0"], ["83864.05", "0"], ["83864.21", "0.114776"], ["83865.2", "0"], ["83865.35", "0.061987"], ["83869.76", "0"], ["83869.91", "0.178577"], ["83870", "0"], ["83870.15", "0.171067"], ["83871.05", "0"], ["83871.21", "0.173771"], ["83872.2", "0"], ["83872.35", "0.058505"], ["83877", "0"], ["83877.15", "0.301985"], ["83878.05", "0"], ["83878.21", "0.303933"], ["83878.86", "0"], ["83879.01", "0.290417"], ["83879.2", "0"], ["83879.35", "0.117801"], ["83885.21", "0.0004"], ["83885.22", "0.000352"], ["83885.29", "0"], ["83885.71", "0"], ["83885.72", "0"], ["83896.09", "0.054427"], ["83896.21", "0.011929"], ["83896.39", "0.000333"]], "u": 69254, "seq": 67537870041}, "cts": 1742543257517, "record_time": 1742543257.486783}
{"topic": "orderbook.200.BTCUSDT", "ts": 1742543257720, "type": "delta", "data": {"s": "BTCUSDT", "b": [["83844.32", "0.002098"], ["83835.17", "0.076661"], ["83835.15", "0"], ["83835.01", "0"], ["83834.91", "0"], ["83831.31", "0.109566"], ["83830.35", "0.055144"], ["83829.11", "0.046405"], ["83825.11", "0.001799"], ["83824.31", "0.175766"], ["83823.35", "0.060601"], ["83822.31", "0"], ["83817.31", "0.302752"], ["83816.35", "0.112881"], ["83816.01", "0"], ["83814.69", "0.003"], ["83800.14", "0.357958"], ["83800.13", "0"], ["83800.08", "0.013"], ["83800.07", "0.012885"], ["83799.68", "0"], ["83799.67", "0"], ["83797.13", "0"], ["83797.12", "0"], ["83796.84", "0.05"], ["83796.83", "0.049564"], ["83796.8", "0.04"]], "a": [["83851.03", "1.864532"], ["83851.86", "0.011925"], ["83852.78", "0.413588"], ["83855.04", "0.003943"], ["83855.66", "0"], ["83856.24", "0"], ["83859.04", "0"], ["83859.31", "0.023871"], ["83859.65", "0"], ["83860.11", "0.015875"], ["83862.26", "0.178889"], ["83862.29", "0"], ["83863.24", "0.046405"], ["83864.21", "0.11557"], ["83865.35", "0.054345"], ["83869.91", "0"], ["83870.15", "0"], ["83871.21", "0.166867"], ["83872.35", "0.060821"], ["83877.15", "0"], ["83877.23", "0"], ["83878.21", "0.290759"], ["83879.01", "0"], ["83879.35", "0.115707"], ["83885.21", "0"], ["83885.22", "0"], ["83885.51", "0.0004"], ["83885.52", "0.000352"], ["83893", "0.013"], ["83893.01", "0.013"], ["83893.2", "0"], ["83893.21", "0"], ["83896.03", "0.003"], ["83896.42", "0.000256"], ["83896.84", "0.023849"], ["83897.13", "0.12433"], ["83897.15", "0.000225"]], "u": 69255, "seq": 67537870251}, "cts": 1742543257714, "record_time": 1742543257.686896}
{"topic": "orderbook.200.BTCUSDT", "ts": 1742543257919, "type": "delta", "data": {"s": "BTCUSDT", "b": [["83851.02", "0.023159"], ["83835.17", "0"], ["83835.15", "0.123319"], ["83834.92", "0.120289"], ["83825.12", "0.164093"], ["83823.23", "0"], ["83816.02", "0.285921"], ["83806.89", "0.127291"], ["83800.15", "0.357955"], ["83800.14", "0"], ["83797.04", "0.05"], ["83796.84", "0"], ["83796.83", "0"], ["83796.8", "0"]], "a": [["83851.03", "1.865332"], ["83859.65", "0.118554"], ["83860.12", "0.114648"], ["83869.92", "0.179195"], ["83870.15", "0.181502"], ["83877.15", "0.305981"], ["83879.02", "0.300218"], ["83885.31", "0.0004"], ["83885.32", "0.000352"], ["83885.51", "0"], ["83885.52", "0"], ["83893", "0"], ["83893.01", "0"], ["83893.09", "0.013"], ["83893.1", "0.013"], ["83896.21", "0"], ["83896.39", "0"], ["83896.42", "0"], ["83896.84", "0"], ["83897.13", "0"], ["83897.15", "0"]], "u": 69256, "seq": 67537870353}, "cts": 1742543257911, "record_time": 1742543257.894396}
{"topic": "orderbook.200.BTCUSDT", "ts": 1742543258120, "type": "delta", "data": {"s": "BTCUSDT", "b": [["83839.45", "0"], ["83835.41", "0.002982"], ["83835.16", "0.082369"], ["83834.92", "0"], ["83825.12", "0"], ["83816.02", "0"], ["83800.16", "0.357958"], ["83800.15", "0"], ["83799.6", "0.04"], ["83799.59", "0.039648"], ["83798.99", "0"], ["83798.98", "0"], ["83797.03", "0.049563"], ["83796.8", "0.04"]], "a": [["83851.03", "1.979132"], ["83853.55", "0"], ["83860.12", "0"], ["83862.26", "0"], ["83869.92", "0"], ["83879.02", "0"], ["83892.13", "0.04"], ["83892.14", "0.04"], ["83892.53", "0"], ["83892.54", "0"], ["83896.21", "0.011929"], ["83896.39", "0.000333"], ["83896.42", "0.000256"], ["83896.84", "0.023849"], ["83897.13", "0.12433"]], "u": 69257, "seq": 67537870470}, "cts": 1742543258112, "record_time": 1742543258.090543}
{"topic": "orderbook.200.BTCUSDT", "ts": 1742543258320, "type": "delta", "data": {"s": "BTCUSDT", "b": [["83835.41", "0.002983"], ["83835.16", "0.046282"], ["83834.92", "0.119369"], ["83825.12", "0.170047"], ["83816.02", "0.304144"], ["83800.28", "0.013"], ["83800.27", "0.012885"], ["83800.17", "0.357959"], ["83800.16", "0"], ["83800.08", "0"], ["83800.07", "0"], ["83797.04", "0"], ["83797.03", "0"], ["83796.8", "0"]], "a": [["83851.03", "1.865266"], ["83859.75", "0.178889"], ["83860.12", "0.115747"], ["83869.92", "0.184875"], ["83879.02", "0.273423"], ["83885.31", "0"], ["83885.32", "0"], ["83885.51", "0.0004"], ["83885.52", "0.000352"], ["83892.13", "0"], ["83892.14", "0"], ["83892.33", "0.04"], ["83892.34", "0.04"], ["83893", "0.013"], ["83893.01", "0.013"], ["83893.09", "0"], ["83893.1", "0"], ["83896.39", "0"], ["83896.42", "0"], ["83896.84", "0"], ["83897.13", "0"]], "u": 69258, "seq": 67537870530}, "cts": 1742543258306, "record_time": 1742543258.287165}
{"topic": "orderbook.200.BTCUSDT", "ts": 1742543258520, "type": "delta", "data": {"s": "BTCUSDT", "b": [["83835.41", "0.002982"], ["83835.16", "0.076307"], ["83800.28", "0"], ["83800.27", "0"], ["83800.18", "0.370958"], ["83800.17", "0.012885"], ["83799.6", "0"], ["83799.59", "0"], ["83799.5", "0.04"], ["83799.49", "0.039648"], ["83796.94", "0.05"]], "a": [["83851.03", "1.979066"], ["83855.03", "0.009"], ["83868.67", "0.003418"], ["83873.07", "0"], ["83885.51", "0"], ["83885.52", "0"], ["83885.61", "0.0004"], ["83885.62", "0.000352"], ["83892.33", "0"], ["83892.34", "0"], ["83892.43", "0.04"], ["83892.44", "0.04"], ["83893", "0"], ["83893.01", "0"], ["83893.1", "0.013"], ["83893.11", "0.013"], ["83896.21", "0"]], "u": 69259, "seq": 67537870600}, "cts": 1742543258509, "record_time": 1742543258.487835}
{"topic": "orderbook.200.BTCUSDT", "ts": 1742543258720, "type": "delta", "data": {"s": "BTCUSDT", "b": [["83839.45", "0.002982"], ["83835.41", "0"], ["83825.13", "0.13333"], ["83806.89", "0.12726"], ["83800.19", "0.357958"], ["83800.18", "0"], ["83800.17", "0"], ["83799.89", "0.013"], ["83799.88", "0.012885"], ["83799.5", "0"], ["83799.49", "0"], ["83799.2", "0.04"], ["83799.19", "0.039648"], ["83797.4", "0"], ["83796.94", "0"]], "a": [["83851.03", "1.865266"], ["83885.61", "0"], ["83885.62", "0"], ["83886.33", "0.0004"], ["83886.34", "0.000352"], ["83892.43", "0"], ["83892.44", "0"], ["83893.1", "0"], ["83893.11", "0"], ["83893.13", "0.04"], ["83893.14", "0.04"], ["83893.8", "0.013"], ["83893.81", "0.013"]], "u": 69260, "seq": 67537870703}, "cts": 1742543258711, "record_time": 1742543258.687252}
{"topic": "orderbook.200.BTCUSDT", "ts": 1742543258919, "type": "delta", "data": {"s": "BTCUSDT", "b": [["83847.06", "0"], ["83835.17", "0.000298"], ["83835.15", "0"], ["83835.03", "0"], ["83835", "0.112785"], ["83834.92", "0"], ["83834.76", "0.109251"], ["83831.31", "0"], ["83830.35", "0"], ["83825.12", "0"], ["83824.96", "0.178758"], ["83824.31", "0"], ["83823.35", "0"], ["83817.31", "0"], ["83816.35", "0"], ["83816.02", "0"], ["83815.86", "0.277013"], ["83806.89", "0.127257"], ["83801.14", "0.000776"], ["83800.2", "0.357957"], ["83800.19", "0"], ["83799.89", "0"], ["83799.88", "0"], ["83799.79", "0.013"], ["83799.78", "0.012885"], ["83799.2", "0"], ["83799.19", "0"], ["83799.1", "0.04"], ["83799.09", "0.039649"], ["83797.4", "0.011961"], ["83796.8", "0.04"], ["83796.55", "0.05"], ["83796.54", "0.049564"], ["83796.53", "0.000206"], ["83795.77", "0.000333"]], "a": [["83859.5", "0.118474"], ["83859.65", "0"], ["83859.96", "0.118511"], ["83860.12", "0"], ["83860.37", "0"], ["83864.21", "0"], ["83865.35", "0"], ["83869.76", "0.183396"], ["83869.92", "0"], ["83870", "0.164404"], ["83870.15", "0"], ["83871.21", "0"], ["83872.35", "0"], ["83877", "0.299295"], ["83877.15", "0"], ["83878.21", "0"], ["83878.86", "0.27218"], ["83879.02", "0"], ["83879.35", "0"], ["83886.03", "0.0004"], ["83886.04", "0.000352"], ["83886.33", "0"], ["83886.34", "0"], ["83893.13", "0"], ["83893.14", "0"], ["83893.23", "0.04"], ["83893.24", "0.04"], ["83893.8", "0"], ["83893.81", "0"], ["83893.89", "0.013"], ["83893.9", "0.013"], ["83896.21", "0.011929"], ["83896.39", "0.000333"], ["83896.42", "0.000256"], ["83896.84", "0.023849"], ["83897.13", "0.12433"], ["83897.15", "0.000225"], ["83897.49", "0.023845"]], "u": 69261, "seq": 67537870867}, "cts": 1742543258916, "record_time": 1742543258.948139}
{"topic": "orderbook.200.BTCUSDT", "ts": 1742543259120, "type": "delta", "data": {"s": "BTCUSDT", "b": [["83847.06", "0.02423"], ["83835.18", "0.000298"], ["83835.17", "0"], ["83835.15", "0.123137"], ["83835", "0"], ["83834.92", "0.110129"], ["83834.76", "0"], ["83831.31", "0.115813"], ["83830.35", "0.059482"], ["83825.13", "0"], ["83825.12", "0.178729"], ["83824.96", "0"], ["83824.31", "0.177402"], ["83823.35", "0.054485"], ["83820.9", "0"], ["83817.31", "0.285441"], ["83816.35", "0.115182"], ["83816.02", "0.278252"], ["83815.86", "0"], ["83806.89", "0.127265"], ["83803.9", "0.304329"], ["83800.21", "0.357957"], ["83800.2", "0"], ["83797.4", "0"], ["83796.8", "0"], ["83796.55", "0"], ["83796.54", "0"], ["83796.53", "0"], ["83795.77", "0"]], "a": [["83851.03", "1.8652"], ["83859.5", "0"], ["83859.65", "0.112104"], ["83859.96", "0"], ["83860.12", "0.123043"], ["83864.21", "0.112994"], ["83865.35", "0.061922"], ["83869.76", "0"], ["83869.92", "0.172095"], ["83870", "0"], ["83870.15", "0.165023"], ["83871.21", "0.163831"], ["83872.35", "0.058371"], ["83877", "0"], ["83877.15", "0.289243"], ["83878.21", "0.301845"], ["83878.86", "0"], ["83879.02", "0.29987"], ["83879.35", "0.123135"], ["83880.05", "0.138932"], ["83885.83", "0.0004"], ["83885.84", "0.000352"], ["83886.03", "0"], ["83886.04", "0"], ["83896.21", "0"], ["83896.39", "0"], ["83896.42", "0"], ["83896.84", "0"], ["83897.13", "0"], ["83897.15", "0"], ["83897.49", "0"]], "u": 69262, "seq": 67537870997}, "cts": 1742543259106, "record_time": 1742543259.086874}
{"topic": "orderbook.200.BTCUSDT", "ts": 1742543259319, "type": "delta", "data": {"s": "BTCUSDT", "b": [["83851.02", "0.015999"], ["83839.45", "0"], ["83835.41", "0.002982"], ["83835.32", "0.000298"], ["83835.18", "0"], ["83835.15", "0"], ["83835.07", "0.12012"], ["83834.92", "0"], ["83834.83", "0.113329"], ["83831.31", "0"], ["83831.22", "0.115975"], ["83830.35", "0"], ["83830.27", "0.058446"], ["83825.12", "0"], ["83825.03", "0.177306"], ["83824.31", "0"], ["83824.22", "0.179776"], ["83823.35", "0"], ["83823.27", "0.060254"], ["83817.31", "0"], ["83817.22", "0.307451"], ["83816.35", "0"], ["83816.27", "0.113716"], ["83816.02", "0"], ["83815.93", "0.279704"], ["83800.22", "0.357959"], ["83800.21", "0"], ["83799.51", "0.04"], ["83799.5", "0.039648"], ["83799.1", "0"], ["83799.09", "0"]], "a": [["83859.57", "0.118187"], ["83859.65", "0"], ["83860.03", "0.110102"], ["83860.12", "0"], ["83860.4", "0.1"], ["83864.12", "0.115695"], ["83864.21", "0"], ["83865.27", "0.061774"], ["83865.35", "0"], ["83869.83", "0.18367"], ["83869.92", "0"], ["83870.07", "0.164862"], ["83870.15", "0"], ["83871.12", "0.181482"], ["83871.21", "0"], ["83872.27", "0.057164"], ["83872.35", "0"], ["83877.07", "0.292612"], ["83877.15", "0"], ["83878.12", "0.283016"], ["83878.21", "0"], ["83878.93", "0.290492"], ["83879.02", "0"], ["83879.27", "0.118461"], ["83879.35", "0"], ["83892.62", "0.04"], ["83892.63", "0.04"], ["83893.23", "0"], ["83893.24", "0"]], "u": 69263, "seq": 67537871106}, "cts": 1742543259311, "record_time": 1742543259.28606}
{"topic": "orderbook.200.BTCUSDT", "ts": 1742543259520, "type": "delta", "data": {"s": "BTCUSDT", "b": [["83851", "0.0006"], ["83846.84", "0.002098"], ["83844.32", "0"], ["83839.45", "0.002982"], ["83836.54", "0.118883"], ["83836.53", "0.119407"], ["83835.41", "0"], ["83835.33", "0.000298"], ["83835.32", "0"], ["83835.16", "0"], ["83835.08", "0.124233"], ["83835.07", "0"], ["83834.83", "0"], ["83831.24", "0.119434"], ["83831.22", "0"], ["83830.28", "0.056373"], ["83830.27", "0"], ["83825.03", "0"], ["83824.24", "0.174968"], ["83824.22", "0"], ["83823.28", "0.059343"], ["83823.27", "0"], ["83817.24", "0.304199"], ["83817.22", "0"], ["83816.28", "0.116409"], ["83816.27", "0"], ["83815.93", "0"], ["83800.59", "0.013"], ["83800.58", "0.012885"], ["83800.23", "0.357956"], ["83800.22", "0"], ["83799.79", "0"], ["83799.78", "0"], ["83797.4", "0.011961"]], "a": [["83851.03", "1.6942"], ["83851.86", "0"], ["83859.57", "0"], ["83859.58", "0.124891"], ["83860.03", "0"], ["83864.12", "0"], ["83864.14", "0.111806"], ["83865.27", "0"], ["83865.28", "0.060648"], ["83869.83", "0"], ["83870.07", "0"], ["83870.08", "0.186218"], ["83871.12", "0"], ["83871.14", "0.183453"], ["83872.27", "0"], ["83872.28", "0.058566"], ["83877.07", "0"], ["83877.08", "0.308455"], ["83878.12", "0"], ["83878.14", "0.302457"], ["83878.93", "0"], ["83879.27", "0"], ["83879.28", "0.115041"], ["83885.63", "0.0004"], ["83885.64", "0.000352"], ["83885.83", "0"], ["83885.84", "0"], ["83893.09", "0.013"], ["83893.1", "0.013"], ["83893.89", "0"], ["83893.9", "0"], ["83896.21", "0.011929"], ["83896.39", "0.000333"], ["83896.42", "0.000256"], ["83896.84", "0.023849"]], "u": 69264, "seq": 67537871251}, "cts": 1742543259516, "record_time": 1742543259.513877}
{"topic": "orderbook.200.BTCUSDT", "ts": 1742543259719, "type": "delta", "data": {"s": "BTCUSDT", "b": [["83851.02", "0.023159"], ["83846.84", "0"], ["83844.32", "0.002098"], ["83836.54", "0.085224"], ["83835.4", "0"], ["83835.08", "0.119957"], ["83834.84", "0.120679"], ["83831.24", "0"], ["83831.23", "0.124455"], ["83830.28", "0"], ["83830.27", "0.060981"], ["83825.04", "0.177285"], ["83824.24", "0"], ["83824.23", "0.183934"], ["83823.28", "0"], ["83823.27", "0.056363"], ["83817.26", "1.355766"], ["83817.24", "0"], ["83817.23", "0.295265"], ["83816.28", "0"], ["83816.27", "0.122592"], ["83815.94", "0.311926"], ["83815.43", "0"], ["83814.69", "0"], ["83804.03", "0.003"], ["83800.59", "0"], ["83800.58", "0"], ["83800.39", "0.013"], ["83800.38", "0.012885"], ["83800.24", "0.357954"], ["83800.23", "0"], ["83799.71", "0.04"], ["83799.7", "0.039648"], ["83799.51", "0"], ["83799.5", "0"], ["83797.45", "0"], ["83797.4", "0"]], "a": [["83851.03", "1.8652"], ["83851.86", "0.011925"], ["83859.58", "0.116652"], ["83860.04", "0.108992"], ["83862.26", "0.178889"], ["83864.13", "0.112472"], ["83864.14", "0"], ["83865.27", "0.057435"], ["83865.28", "0"], ["83867.41", "0"], ["83869.84", "0.179785"], ["83870.08", "0.177017"], ["83871.13", "0.176734"], ["83871.14", "0"], ["83872.27", "0.055008"], ["83872.28", "0"], ["83877.08", "0.306619"], ["83878.13", "0.298113"], ["83878.14", "0"], ["83878.94", "0.283889"], ["83879.27", "0.117414"], ["83879.28", "0"], ["83885.63", "0"], ["83885.64", "0"], ["83885.73", "0.0004"], ["83885.74", "0.000352"], ["83892.62", "0"], ["83892.63", "0"], ["83892.72", "0.04"], ["83892.73", "0.04"], ["83893.09", "0"], ["83893.1", "0"], ["83893.39", "0.013"], ["83893.4", "0.013"], ["83896.03", "0"], ["83896.42", "0"], ["83896.84", "0"]], "u": 69265, "seq": 67537871442}, "cts": 1742543259716, "record_time": 1742543259.688268}
{"topic": "orderbook.200.BTCUSDT", "ts": 1742543259920, "type": "delta", "data": {"s": "BTCUSDT", "b": [["83835.16", "0.122563"], ["83835.08", "0"], ["83834.92", "0.1145"], ["83834.84", "0"], ["83831.32", "0.230884"], ["83831.23", "0"], ["83830.36", "0.062093"], ["83830.27", "0"], ["83825.12", "0.182593"], ["83825.04", "0"], ["83824.32", "0.186075"], ["83824.23", "0"], ["83823.36", "0.057134"], ["83823.27", "0"], ["83818.62", "0.553166"], ["83817.32", "0.287974"], ["83817.23", "0"], ["83816.36", "0.108438"], ["83816.27", "0"], ["83816.02", "0.283211"], ["83815.94", "0"], ["83806.89", "0.127255"], ["83800.39", "0"], ["83800.38", "0"], ["83800.25", "0.357955"], ["83800.24", "0"], ["83800.2", "0.013"], ["83800.19", "0.012885"], ["83799.71", "0"], ["83799.7", "0"], ["83799.41", "0.04"], ["83799.4", "0.039648"]], "a": [["83859.58", "0"], ["83859.66", "0.114166"], ["83860.04", "0"], ["83860.12", "0.123758"], ["83864.13", "0.000255"], ["83864.22", "0.115128"], ["83865.27", "0"], ["83865.36", "0.054839"], ["83867.18", "0.381835"], ["83869.84", "0"], ["83869.92", "0.175993"], ["83870.08", "0"], ["83870.16", "0.179893"], ["83871.13", "0"], ["83871.22", "0.179549"], ["83872.27", "0"], ["83872.36", "0.0546"], ["83873.6", "1.358376"], ["83877.08", "0"], ["83877.16", "0.280038"], ["83878.13", "0"], ["83878.22", "0.28446"], ["83878.94", "0"], ["83879.02", "0.300713"], ["83879.27", "0"], ["83879.36", "0.109937"], ["83885.73", "0"], ["83885.74", "0"], ["83885.83", "0.0004"], ["83885.84", "0.000352"], ["83893.29", "0.013"], ["83893.3", "0.013"], ["83893.39", "0"], ["83893.4", "0"], ["83896.39", "0"]], "u": 69266, "seq": 67537871558}, "cts": 1742543259905, "record_time": 1742543259.887656}
{"topic": "orderbook.200.BTCUSDT", "ts": 1742543260119, "type": "delta", "data": {"s": "BTCUSDT", "b": [["83844.32", "0.001516"], ["83831.32", "0.230435"], ["83824.32", "0.181147"], ["83821.57", "0.119259"], ["83817.32", "0.288594"], ["83806.89", "0.127274"], ["83800.26", "0.357957"], ["83800.25", "0"], ["83800.2", "0"], ["83800.19", "0"], ["83800.1", "0.013"], ["83800.09", "0.012885"], ["83799.51", "0.04"], ["83799.5", "0.039648"], ["83799.41", "0"], ["83799.4", "0"], ["83797.87", "0"]], "a": [["83862.26", "0"], ["83864.22", "0.115368"], ["83871.22", "0.16914"], ["83872.34", "0.835708"], ["83875.26", "0"], ["83877.72", "0"], ["83878.22", "0.312337"], ["83892.62", "0.04"], ["83892.63", "0.04"], ["83892.72", "0"], ["83892.73", "0"], ["83893.29", "0"], ["83893.3", "0"], ["83893.39", "0.013"], ["83893.4", "0.013"], ["83896.39", "0.000333"], ["83896.42", "0.000256"], ["83896.84", "0.023849"]], "u": 69267, "seq": 67537871632}, "cts": 1742543260114, "record_time": 1742543260.089496}
{"topic": "orderbook.200.BTCUSDT", "ts": 1742543260319, "type": "delta", "data": {"s": "BTCUSDT", "b": [["83800.27", "0.357957"], ["83800.26", "0"], ["83799.51", "0"], ["83799.5", "0"], ["83799.41", "0.04"], ["83799.4", "0.039648"]], "a": [["83885.73", "0.0004"], ["83885.74", "0.000351"], ["83885.83", "0"], ["83885.84", "0"], ["83892.62", "0"], ["83892.63", "0"], ["83892.72", "0.04"], ["83892.73", "0.04"]], "u": 69268, "seq": 67537871697}, "cts": 1742543260316, "record_time": 1742543260.286819}
{"topic": "orderbook.200.BTCUSDT", "ts": 1742543260519, "type": "delta", "data": {"s": "BTCUSDT", "b": [["83851.02", "0.194159"], ["83850.14", "0.052332"], ["83850.13", "0.07159"], ["83849.28", "0.089922"], ["83847.06", "0"], ["83847.05", "0"], ["83844.32", "0"], ["83843.31", "0"], ["83842.82", "0.08727"], ["83842.81", "0.119705"], ["83842.8", "0"], ["83841.64", "0.001"], ["83839.45", "0"], ["83838.01", "0.108753"], ["83836.56", "0.017502"], ["83836.4", "0.090522"], ["83835.55", "0.046405"], ["83835.16", "0"], ["83834.92", "0"], ["83833.74", "0"], ["83833.45", "0.061542"], ["83831.32", "0.119662"], ["83830.36", "0"], ["83829.11", "0"], ["83828.21", "0.167003"], ["83826.45", "0.059091"], ["83825.12", "0"], ["83824.32", "0"], ["83823.98", "0"], ["83823.36", "0"], ["83822.9", "0.071613"], ["83820.4", "0.277821"], ["83819.86", "0"], ["83819.83", "0.089922"], ["83819.45", "0.123915"], ["83819.11", "0.306997"], ["83817.34", "0"], ["83817.32", "0"], ["83816.36", "0"], ["83816.02", "0"], ["83811.79", "0"], ["83806.9", "0.357936"], ["83804.91", "0.323926"], ["83800.5", "0.013"], ["83800.49", "0.012885"], ["83800.27", "0"], ["83800.1", "0"], ["83800.09", "0"], ["83799.81", "0.04"], ["83799.8", "0.039648"], ["83799.41", "0"], ["83799.4", "0"], ["83797.87", "0.023851"], ["83797.45", "0.001466"], ["83797.4", "0.011961"], ["83797.25", "0.05"], ["83797.24", "0.049563"]], "a": [["83851.03", "0.243208"], ["83851.73", "0"], ["83851.86", "0.013118"], ["83852.77", "0"], ["83852.78", "0.171"], ["83853.56", "0"], ["83853.61", "0"], ["83855.03", "0"], ["83855.04", "0"], ["83856.88", "0"], ["83859.31", "0"], ["83859.34", "0.319902"], ["83859.66", "0"], ["83859.75", "0"], ["83860.01", "0"], ["83860.12", "0"], ["83861", "0"], ["83862.49", "0"], ["83862.75", "0.123831"], ["83863.21", "0.12368"], ["83863.24", "0"], ["83863.8", "0.104153"], ["83864.22", "0"], ["83864.79", "0.341343"], ["83865.36", "0"], ["83865.81", "0.059621"], ["83865.89", "0"], ["83866.1", "0.013119"], ["83866.68", "0"], ["83867.56", "0"], ["83868.45", "0.055469"], ["83868.86", "0"], ["83869.23", "0.058414"], ["83869.24", "0"], ["83869.71", "0.046405"], ["83869.92", "0"], ["83870.16", "0"], ["83870.9", "0.115051"], ["83871.22", "0.001799"], ["83871.61", "0"], ["83872.36", "0"], ["83872.6", "0"], ["83872.65", "0"], ["83872.95", "0"], ["83873.01", "0.181677"], ["83873.6", "0"], ["83873.93", "0"], ["83875.07", "0"], ["83875.45", "0.057478"], ["83877.16", "0"], ["83878.22", "0"], ["83879.02", "0"], ["83879.36", "0"], ["83879.6", "0"], ["83880.06", "0"], ["83881.3", "0.29846"], ["83881.39", "0.008805"], ["83882.11", "0.298278"], ["83882.45", "0.117562"], ["83882.95", "0"], ["83884.16", "0.071561"], ["83885.13", "0"], ["83885.73", "0"], ["83885.74", "0"], ["83887.13", "0.0004"], ["83887.14", "0.000351"], ["83888.97", "0"], ["83892.57", "0"], ["83892.72", "0"], ["83892.73", "0"], ["83892.83", "0.028239"], ["83893.39", "0"], ["83893.4", "0"], ["83893.92", "0.04"], ["83893.93", "0.04"], ["83894.59", "0.013"], ["83894.6", "0.013"], ["83895.53", "0"], ["83896.02", "0"], ["83897.13", "0.12433"], ["83897.15", "0.000225"], ["83897.49", "0.023845"], ["83898.28", "0.00009"], ["83898.3", "0.0006"], ["83898.7", "0.001333"], ["83898.91", "0.001466"], ["83899.06", "0.003575"], ["83899.13", "0.11"], ["83899.4", "0.0006"], ["83899.67", "0.022"], ["83900", "0.007442"], ["83900.29", "0.073666"], ["83900.51", "0.000256"], ["83900.58", "0.000333"], ["83900.64", "0.119407"], ["83901.03", "0.125478"], ["83901.34", "0.000225"], ["83901.99", "0.003"], ["83902.69", "0.000199"], ["83902.89", "0.001333"], ["83902.98", "0.023845"], ["83903.52", "0.001466"], ["83903.8", "0.0006"], ["83903.9", "0.023845"], ["83904.27", "0.001"], ["83904.3", "0.1"], ["83904.78", "0.000333"]], "u": 69269, "seq": 67537872325}, "cts": 1742543260516, "record_time": 1742543260.523162}
{"topic": "orderbook.200.BTCUSDT", "ts": 1742543260720, "type": "delta", "data": {"s": "BTCUSDT", "b": [["83851.02", "0.198534"], ["83850.19", "0.002098"], ["83850.14", "0.025355"], ["83849.28", "0"], ["83844.94", "0.013127"], ["83842.83", "0.002982"], ["83842.81", "0.119407"], ["83841.26", "0.049975"], ["83838.01", "0"], ["83837.77", "0.121833"], ["83837.53", "0.121971"], ["83833.92", "0.112702"], ["83833.45", "0"], ["83832.97", "0.061199"], ["83828.21", "0"], ["83827.73", "0.165187"], ["83826.92", "0.174309"], ["83826.45", "0"], ["83825.97", "0.05932"], ["83820.4", "0"], ["83819.92", "0.311406"], ["83819.45", "0"], ["83819.11", "0"], ["83818.97", "0.113963"], ["83818.63", "0.299695"], ["83811.69", "0.11"], ["83806.9", "0"], ["83805.58", "0.357937"], ["83799.35", "0.05"], ["83799.34", "0.049561"], ["83799.05", "0"], ["83798.15", "0"], ["83798.08", "0"], ["83797.87", "0"], ["83797.45", "0"], ["83797.4", "0"], ["83797.25", "0"], ["83797.24", "0"]], "a": [["83851.03", "0.339726"], ["83851.73", "0.001193"], ["83851.86", "0"], ["83853.86", "0.071587"], ["83855.2", "0.013098"], ["83855.21", "0.010806"], ["83860.13", "0.00441"], ["83860.27", "0.024396"], ["83862.23", "0.009"], ["83862.27", "0.116291"], ["83862.73", "0.114617"], ["83862.75", "0"], ["83863.21", "0"], ["83863.65", "0.307229"], ["83864.24", "0"], ["83866.82", "0.116913"], ["83867.18", "0.179541"], ["83867.97", "0.055721"], ["83867.98", "0.018831"], ["83868.45", "0"], ["83872.34", "0"], ["83872.53", "0.164439"], ["83872.77", "0.171157"], ["83873.01", "0"], ["83873.82", "0.164974"], ["83874.97", "0.056972"], ["83875.45", "0"], ["83876.79", "0.674851"], ["83878.62", "0.477767"], ["83879.77", "0.275061"], ["83880.82", "0.281271"], ["83881.3", "0"], ["83881.63", "0.285193"], ["83881.97", "0.122025"], ["83882.11", "0"], ["83882.45", "0"], ["83887.13", "0"], ["83887.14", "0"], ["83887.72", "0.0004"], ["83887.73", "0.000351"], ["83893.92", "0"], ["83893.93", "0"], ["83894.59", "0"], ["83894.6", "0"], ["83894.62", "0.04"], ["83894.63", "0.04"], ["83895.29", "0.013"], ["83895.3", "0.013"], ["83896", "0.178889"], ["83896.02", "0.089444"], ["83898.71", "0.171"], ["83899.13", "0"], ["83901.03", "0"], ["83901.34", "0"], ["83901.99", "0"], ["83902.69", "0"], ["83902.89", "0"], ["83902.98", "0"], ["83903.52", "0"], ["83903.8", "0"], ["83903.9", "0"], ["83904.27", "0"], ["83904.3", "0"], ["83904.78", "0"]], "u": 69270, "seq": 67537872705}, "cts": 1742543260716, "record_time": 1742543260.719153}
{"topic": "orderbook.200.BTCUSDT", "ts": 1742543260920, "type": "delta", "data": {"s": "BTCUSDT", "b": [["83841.26", "0.093995"], ["83839", "0.04"], ["83837.77", "0"], ["83837.54", "0.160261"], ["83837.53", "0"], ["83837.3", "0.04"], ["83836.54", "0"], ["83835.8", "0.041333"], ["83834.1", "0.04"], ["83834", "0.04"], ["83833.92", "0"], ["83832.97", "0"], ["83832.8", "0"], ["83832.3", "0.04"], ["83827.73", "0"], ["83826.92", "0"], ["83825.97", "0"], ["83819.92", "0"], ["83818.97", "0"], ["83818.63", "0"], ["83806.89", "0.127304"], ["83805.58", "0.357939"], ["83799.46", "0.05"], ["83799.45", "0.04956"], ["83799.35", "0"], ["83799.34", "0"], ["83799.05", "0.000255"], ["83798.15", "0.005962"], ["83798.08", "0.001333"], ["83797.87", "0.023851"], ["83797.45", "0.001466"], ["83797.4", "0.011961"]], "a": [["83851.03", "0.336794"], ["83855.21", "0.00341"], ["83862.27", "0"], ["83862.73", "0"], ["83863.47", "0"], ["83866.82", "0"], ["83867.97", "0"], ["83872.53", "0"], ["83872.77", "0"], ["83873.82", "0"], ["83874.97", "0"], ["83878.5", "1.343922"], ["83879.77", "0"], ["83880.82", "0"], ["83881.63", "0"], ["83881.97", "0"], ["83894.6", "0.005962"], ["83894.63", "0.113666"], ["83896.02", "0"], ["83900.29", "0"], ["83901.03", "0.125478"], ["83901.34", "0.000225"], ["83901.99", "0.003"], ["83902.69", "0.000199"], ["83902.89", "0.001333"], ["83902.98", "0.023845"], ["83903.52", "0.001466"], ["83903.8", "0.0006"], ["83903.9", "0.023845"], ["83904.27", "0.001"], ["83904.3", "0.1"], ["83904.78", "0.000333"], ["83905.12", "0.000256"]], "u": 69271, "seq": 67537872946}, "cts": 1742543260916, "record_time": 1742543260.885844}
{"topic": "orderbook.200.BTCUSDT", "ts": 1742543261119, "type": "delta", "data": {"s": "BTCUSDT", "b": [["83843.66", "0"], ["83841.26", "0.071697"], ["83839.5", "0.04"], ["83837.77", "0.122927"], ["83837.7", "0.04"], ["83837.54", "0.273386"], ["83835.6", "0.04"], ["83833.93", "0.124868"], ["83833.3", "0"], ["83832.97", "0.057016"], ["83832.5", "0.04"], ["83832.1", "0"], ["83831.5", "0"], ["83829.5", "0"], ["83827.9", "0"], ["83827.8", "0"], ["83827.74", "0.178735"], ["83826.93", "0.171327"], ["83826", "0"], ["83825.97", "0.061182"], ["83822.91", "0.063381"], ["83819.93", "0.276587"], ["83818.97", "0.114548"], ["83818.64", "0.301211"], ["83811.69", "0"], ["83809.72", "0.127304"], ["83806.89", "0"], ["83805.59", "0.357939"], ["83805.58", "0"], ["83802.7", "0.013"], ["83802.69", "0.012884"], ["83802.02", "0.04"], ["83802.01", "0.039646"], ["83800.5", "0"], ["83800.49", "0"], ["83799.81", "0"], ["83799.8", "0"], ["83798.15", "0"], ["83798.08", "0"], ["83797.87", "0"], ["83797.45", "0"], ["83797.4", "0"]], "a": [["83854.01", "0"], ["83855.21", "0.005686"], ["83862.27", "0.119456"], ["83862.74", "0.111345"], ["83866.83", "0.119742"], ["83867.97", "0.060278"], ["83869.81", "0.178889"], ["83870.87", "0.178889"], ["83872.54", "0.185104"], ["83872.77", "0.176457"], ["83873.83", "0.169462"], ["83874.97", "0.057998"], ["83875.07", "0.178889"], ["83876.79", "1.164617"], ["83879.77", "0.281385"], ["83880.05", "0"], ["83880.83", "0.275691"], ["83881.64", "0.281777"], ["83881.97", "0.120883"], ["83894.52", "0.04"], ["83894.53", "0.04"], ["83894.62", "0"], ["83894.63", "0.073666"], ["83895.19", "0.013"], ["83895.2", "0.013"], ["83895.29", "0"], ["83895.3", "0"], ["83900.64", "0"], ["83901.03", "0"], ["83901.34", "0"], ["83901.99", "0"], ["83902.69", "0"], ["83902.89", "0"], ["83902.98", "0"], ["83903.52", "0"], ["83903.8", "0"], ["83903.9", "0"], ["83904.27", "0"], ["83904.3", "0"], ["83904.78", "0"], ["83905.12", "0"]], "u": 69272, "seq": 67537873063}, "cts": 1742543261115, "record_time": 1742543261.086361}
{"topic": "orderbook.200.BTCUSDT", "ts": 1742543261319, "type": "delta", "data": {"s": "BTCUSDT", "b": [["83841.26", "0.071473"], ["83837.77", "0"], ["83837.74", "0.12218"], ["83837.54", "0.160261"], ["83837.51", "0.12285"], ["83833.93", "0"], ["83833.9", "0.110029"], ["83832.97", "0"], ["83832.94", "0.059039"], ["83829.4", "0"], ["83827.74", "0"], ["83827.71", "0.168782"], ["83826.93", "0"], ["83826.9", "0.173558"], ["83826.3", "0"], ["83825.97", "0"], ["83825.94", "0.059341"], ["83819.93", "0"], ["83819.9", "0.287869"], ["83818.97", "0"], ["83818.94", "0.114848"], ["83818.64", "0"], ["83818.61", "0.425392"], ["83805.6", "0.357936"], ["83805.59", "0"], ["83798.15", "0.005962"], ["83798.08", "0.001333"]], "a": [["83851.03", "0.352512"], ["83854.18", "0.000099"], ["83855.2", "0"], ["83857.34", "0"], ["83862.24", "0.123662"], ["83862.27", "0"], ["83862.71", "0.120093"], ["83862.74", "0"], ["83866.8", "0.12312"], ["83866.83", "0"], ["83867.18", "0.271524"], ["83867.94", "0.059063"], ["83867.97", "0"], ["83868.7", "0.178851"], ["83869.81", "0"], ["83870.38", "0.178847"], ["83870.84", "0.178889"], ["83870.87", "0"], ["83872.06", "0.178844"], ["83872.51", "0.170641"], ["83872.54", "0"], ["83872.74", "0.172988"], ["83872.77", "0"], ["83873.8", "0.183944"], ["83873.83", "0"], ["83874.94", "0.055232"], ["83874.97", "0"], ["83879.26", "0.178889"], ["83879.74", "0.308331"], ["83879.77", "0"], ["83880.8", "0.302761"], ["83880.83", "0"], ["83881.61", "0.30514"], ["83881.64", "0"], ["83881.94", "0.116748"], ["83881.97", "0"], ["83889.93", "0.125222"], ["83896", "0"], ["83900.51", "0"], ["83900.58", "0"]], "u": 69273, "seq": 67537873179}, "cts": 1742543261316, "record_time": 1742543261.286677}
{"topic": "orderbook.200.BTCUSDT", "ts": 1742543261520, "type": "delta", "data": {"s": "BTCUSDT", "b": [["83841.26", "0.06948"], ["83837.83", "0.115538"], ["83837.74", "0"], ["83837.7", "0.0421"], ["83837.59", "0.118615"], ["83837.51", "0"], ["83835.1", "0"], ["83833.99", "0.114483"], ["83833.9", "0"], ["83833.03", "0.061586"], ["83832.94", "0"], ["83827.79", "0.185463"], ["83827.71", "0"], ["83826.99", "0.177984"], ["83826.9", "0"], ["83826.03", "0.055175"], ["83825.94", "0"], ["83822.62", "0.00367"], ["83822.41", "0.119259"], ["83819.99", "0.276247"], ["83819.9", "0"], ["83819.03", "0.122175"], ["83818.94", "0"], ["83818.69", "0.311788"], ["83818.61", "0.119407"], ["83816.14", "0"], ["83809.72", "0"], ["83809", "0.0016"], ["83806.74", "0.02381"], ["83806.4", "0"], ["83805.61", "0.357937"], ["83805.6", "0"], ["83804.06", "0.127306"], ["83802.9", "0.013"], ["83802.89", "0.071298"], ["83802.7", "0"], ["83802.69", "0"], ["83802.22", "0.04"], ["83802.21", "0.039646"], ["83802.02", "0"], ["83802.01", "0"], ["83801.95", "0"], ["83800.89", "0.2"], ["83799.66", "0.05"], ["83799.65", "0.04956"], ["83799.46", "0"], ["83799.45", "0"], ["83797.87", "0.023851"]], "a": [["83851.03", "0.314737"], ["83855.21", "0"], ["83860.27", "0"], ["83862.24", "0"], ["83862.33", "0.112544"], ["83862.71", "0"], ["83862.79", "0.108742"], ["83865.81", "0"], ["83866.8", "0"], ["83866.89", "0.11726"], ["83867.94", "0"], ["83868.03", "0.058647"], ["83870.65", "0.119259"], ["83872.5", "0.280488"], ["83872.51", "0"], ["83872.59", "0.169615"], ["83872.74", "0"], ["83872.83", "0.172911"], ["83873.8", "0"], ["83873.89", "0.175907"], ["83874.94", "0"], ["83875.03", "0.0556"], ["83875.07", "0"], ["83879.74", "0"], ["83879.83", "0.302046"], ["83880.8", "0"], ["83880.89", "0.305261"], ["83881.61", "0"], ["83881.69", "0.274605"], ["83881.94", "0"], ["83882.03", "0.11252"], ["83887.32", "0"], ["83887.72", "0"], ["83887.73", "0"], ["83888.12", "0.0004"], ["83888.13", "0.000351"], ["83892.11", "0.024801"], ["83894.52", "0"], ["83894.53", "0"], ["83894.92", "0.04"], ["83894.93", "0.04"], ["83895.19", "0"], ["83895.2", "0"], ["83895.59", "0.013"], ["83895.6", "0.013"], ["83900.51", "0.000256"], ["83900.58", "0.000333"]], "u": 69274, "seq": 67537873549}, "cts": 1742543261516, "record_time": 1742543261.568569}
{"topic": "orderbook.200.BTCUSDT", "ts": 1742543261719, "type": "delta", "data": {"s": "BTCUSDT", "b": [["83851.02", "0.66387"], ["83849.96", "0.013725"], ["83848.87", "0.023851"], ["83847.97", "0.000996"], ["83845.61", "0.089922"], ["83844.94", "0"], ["83842.83", "0"], ["83841.95", "0.046405"], ["83841.64", "0.11537"], ["83841.61", "0.05881"], ["83841.41", "0.114142"], ["83841.26", "0"], ["83837.83", "0"], ["83837.71", "0.058414"], ["83837.59", "0"], ["83835.55", "0"], ["83833.99", "0"], ["83833.03", "0"], ["83831.61", "0.165449"], ["83828.72", "0.071608"], ["83827.79", "0"], ["83826.99", "0"], ["83826.03", "0"], ["83822.92", "0.357875"], ["83822.41", "0"], ["83821.57", "0"], ["83819.99", "0"], ["83819.5", "0"], ["83819.03", "0.001333"], ["83818.69", "0"], ["83817.49", "0.000255"], ["83815.39", "0.127306"], ["83808.49", "0.020416"], ["83805.61", "0"], ["83804.06", "0"], ["83804.03", "0"], ["83803.73", "0.019264"], ["83802.9", "0"], ["83802.89", "0.058414"], ["83802.22", "0"], ["83802.21", "0"], ["83802.1", "0.013"], ["83802.09", "0.012885"], ["83801.42", "0.04"], ["83801.41", "0.039646"], ["83800.54", "0.003"], ["83799.66", "0"], ["83799.65", "0"], ["83798.86", "0.05"], ["83798.85", "0.049561"], ["83797.45", "0.001466"], ["83797.4", "0.011961"], ["83796.8", "0.04"]], "a": [["83851.03", "0.099155"], ["83851.73", "0"], ["83852.78", "0"], ["83853.86", "0"], ["83855.65", "0"], ["83856.96", "0"], ["83857.38", "0.000298"], ["83859.34", "0"], ["83860.13", "0"], ["83860.8", "0.109193"], ["83862.23", "0"], ["83862.33", "0"], ["83862.79", "0"], ["83863.8", "0.104"], ["83864.2", "0"], ["83866.1", "0"], ["83866.14", "0.112475"], ["83866.89", "0"], ["83867.4", "0"], ["83868.03", "0"], ["83868.51", "0"], ["83868.67", "0"], ["83869.23", "0"], ["83869.71", "0"], ["83870.22", "0.000153"], ["83870.37", "0.013706"], ["83870.48", "0"], ["83870.65", "0"], ["83870.9", "0"], ["83872.59", "0"], ["83872.83", "0"], ["83873.89", "0"], ["83875.03", "0"], ["83875.41", "0.046405"], ["83877.43", "0.023852"], ["83878.5", "0"], ["83879.26", "0"], ["83879.83", "0"], ["83880.02", "0"], ["83880.06", "0.125222"], ["83880.89", "0"], ["83881.69", "0"], ["83881.89", "0.0183"], ["83882.03", "0"], ["83883.64", "0.302129"], ["83884.16", "0"], ["83888.12", "0"], ["83888.13", "0"], ["83889.18", "0"], ["83889.93", "0"], ["83890.52", "0.0004"], ["83890.53", "0.000351"], ["83892.79", "0.071554"], ["83892.83", "0"], ["83893.7", "0.005962"], ["83894.63", "0"], ["83894.92", "0"], ["83894.93", "0"], ["83895.59", "0"], ["83895.6", "0"], ["83896.09", "0.02749"], ["83896.52", "0.04"], ["83896.53", "0.04"], ["83898.18", "0.013"], ["83898.19", "0.013"], ["83899.82", "0.023108"], ["83901.03", "0.125478"], ["83901.34", "0.000225"], ["83902.69", "0.000199"], ["83902.89", "0.001333"], ["83902.98", "0.023845"], ["83903.12", "0.073666"], ["83903.52", "0.001466"], ["83903.8", "0.0006"], ["83903.9", "0.023845"], ["83904.27", "0.001"], ["83904.3", "0.1"], ["83904.78", "0.000333"], ["83905.12", "0.000256"], ["83905.48", "0.003"], ["83905.54", "0.000225"], ["83905.59", "0.005961"], ["83905.65", "0.000256"], ["83905.94", "1.061904"], ["83906.2", "0.121007"], ["83906.51", "0.0015"], ["83906.52", "0.003"], ["83906.71", "0.00009"], ["83906.8", "0.00009"], ["83907.09", "0.001333"], ["83907.21", "0.023845"], ["83907.78", "0.354284"]], "u": 69275, "seq": 67537874466}, "cts": 1742543261717, "record_time": 1742543261.763308}
{"topic": "orderbook.200.BTCUSDT", "ts": 1742543261919, "type": "delta", "data": {"s": "BTCUSDT", "b": [["83851.02", "1.209502"], ["83850.14", "0.048865"], ["83848.96", "0.046405"], ["83846.76", "0.009685"], ["83845.62", "0.13286"], ["83845.38", "0.019601"], ["83842.82", "0"], ["83842.35", "0.059629"], ["83841.95", "0"], ["83841.64", "0.001"], ["83841.61", "0.065965"], ["83841.41", "0"], ["83841.33", "0.117216"], ["83841.09", "0.114055"], ["83841.08", "0.023851"], ["83837.49", "0.109527"], ["83836.53", "0.175591"], ["83835.31", "0"], ["83833.52", "0"], ["83832.15", "0"], ["83831.61", "0"], ["83831.44", "0"], ["83831.29", "0.174237"], ["83830.49", "0.163552"], ["83830", "0.007487"], ["83829.53", "0.056793"], ["83828.97", "0.119259"], ["83828.11", "0.059629"], ["83827.81", "0.009026"], ["83823.49", "0.293841"], ["83823.2", "0.023852"], ["83822.92", "0"], ["83822.91", "0"], ["83822.53", "0.123388"], ["83822.19", "0.289185"], ["83821.69", "0.502638"], ["83820.26", "0.357885"], ["83818.22", "0.127299"], ["83817.31", "0.30428"], ["83816.88", "0.02401"], ["83815.39", "0"], ["83813.51", "0.417837"], ["83809.45", "0.004625"], ["83806.74", "0"], ["83805.57", "0"], ["83803.9", "0"], ["83803.73", "0"], ["83803.57", "0"], ["83800.89", "0"], ["83800.84", "0.014894"], ["83799.57", "0"], ["83799.05", "0"], ["83798.86", "0"], ["83798.85", "0"], ["83798.15", "0"], ["83798.08", "0"], ["83797.87", "0"], ["83797.45", "0"], ["83797.4", "0"], ["83796.8", "0"]], "a": [["83851.03", "0.130732"], ["83857.38", "0"], ["83860.39", "0.000298"], ["83860.4", "0"], ["83860.8", "0"], ["83861.16", "0.229718"], ["83862.5", "0"], ["83863.65", "0"], ["83863.66", "0"], ["83863.8", "0"], ["83864.56", "0"], ["83864.75", "0"], ["83864.79", "0"], ["83865.83", "0.118419"], ["83865.9", "0"], ["83866", "0.1"], ["83866.14", "0"], ["83866.29", "0.119452"], ["83867.18", "0"], ["83867.28", "0.023768"], ["83867.5", "0"], ["83867.98", "0"], ["83868", "0.088"], ["83868.31", "0.071575"], ["83868.74", "0.122162"], ["83869.41", "0"], ["83870.09", "0"], ["83870.37", "0"], ["83870.39", "0.111643"], ["83871.53", "0.06104"], ["83872.27", "0.004597"], ["83872.5", "0"], ["83874.48", "0.004094"], ["83875.41", "0"], ["83875.98", "0.013735"], ["83876.02", "0.009048"], ["83876.09", "0.177708"], ["83876.33", "0.171595"], ["83876.79", "0.674851"], ["83876.84", "0.360945"], ["83877.13", "0"], ["83877.36", "0.178889"], ["83877.39", "0.174647"], ["83877.43", "0"], ["83877.45", "0.178889"], ["83878.53", "0.060854"], ["83878.62", "0"], ["83879.5", "0.1"], ["83879.95", "0.003392"], ["83880.09", "0.115184"], ["83880.97", "0"], ["83881.39", "0"], ["83881.64", "0.178889"], ["83881.87", "0.046405"], ["83882.65", "0.014054"], ["83883.33", "0.293693"], ["83883.64", "0"], ["83884.39", "0.295309"], ["83885.19", "0.285199"], ["83885.53", "0.117028"], ["83889.2", "0.008805"], ["83890.52", "0"], ["83890.53", "0"], ["83891.61", "0.477767"], ["83892.11", "0"], ["83892.78", "0"], ["83892.79", "0"], ["83895.37", "0.017899"], ["83896.09", "0"], ["83896.43", "0.0004"], ["83896.44", "0.000351"], ["83896.52", "0"], ["83896.53", "0"], ["83897.78", "0.071549"], ["83898.18", "0"], ["83898.19", "0"], ["83900.75", "0.023353"], ["83900.77", "0.028239"], ["83901.73", "0.071546"], ["83903.12", "0"], ["83903.2", "2.405549"], ["83903.79", "0.001549"], ["83903.91", "0.04"], ["83903.92", "0.04"], ["83904.58", "0.013"], ["83904.59", "0.013"], ["83905.94", "0"], ["83906.2", "0.0016"], ["83906.51", "0"], ["83906.52", "0"], ["83906.71", "0"], ["83906.8", "0"], ["83907.09", "0"], ["83907.21", "0"], ["83907.78", "0"]], "u": 69276, "seq": 67537875389}, "cts": 1742543261917, "record_time": 1742543261.888824}
{"topic": "orderbook.200.BTCUSDT", "ts": 1742543262120, "type": "delta", "data": {"s": "BTCUSDT", "b": [["83851.02", "1.310906"], ["83841.61", "0.132014"], ["83841.33", "0"], ["83841.09", "0"], ["83841.03", "0.122805"], ["83840.79", "0.124844"], ["83837.49", "0"], ["83837.19", "0.123264"], ["83836.53", "0.119407"], ["83836.23", "0.057765"], ["83832.58", "0"], ["83831.29", "0"], ["83830.99", "0.179387"], ["83830.49", "0"], ["83830.19", "0.182825"], ["83829.53", "0"], ["83829.23", "0.059713"], ["83827.87", "0.003576"], ["83823.49", "0"], ["83823.19", "0.292591"], ["83822.53", "0"], ["83822.23", "0.109653"], ["83822.19", "0"], ["83822.04", "0"], ["83821.89", "0.277119"], ["83820.26", "0"], ["83816.18", "0.11"], ["83813.58", "0.357893"], ["83799.96", "0"]], "a": [["83851.03", "0.151603"], ["83863.79", "0.071578"], ["83865.5", "0"], ["83865.53", "0.109389"], ["83865.83", "0"], ["83865.99", "0.123785"], ["83866", "0"], ["83866.29", "0"], ["83867.28", "0"], ["83868", "0"], ["83868.31", "0"], ["83868.7", "0"], ["83869.4", "0.104"], ["83870.09", "0.120697"], ["83870.38", "0"], ["83870.39", "0"], ["83871.23", "0.058579"], ["83871.53", "0"], ["83872.06", "0"], ["83872.9", "0.108"], ["83874.6", "0.104"], ["83875.06", "0.178837"], ["83875.79", "0.163971"], ["83876.03", "0.166626"], ["83876.09", "0"], ["83876.3", "0.108"], ["83876.33", "0"], ["83876.79", "0"], ["83877.09", "0.177303"], ["83877.26", "0.018831"], ["83877.39", "0"], ["83878", "0.104"], ["83878.23", "0.056414"], ["83878.53", "0"], ["83879.6", "0.112"], ["83881.05", "1.382228"], ["83883.03", "0.298909"], ["83883.33", "0"], ["83884.09", "0.272534"], ["83884.39", "0"], ["83884.89", "0.272122"], ["83885.19", "0"], ["83885.23", "0.122371"], ["83885.53", "0"], ["83892.2", "0.071554"], ["83896.14", "0.0004"], ["83896.15", "0.000351"], ["83896.43", "0"], ["83896.44", "0"], ["83899.82", "0"], ["83901.73", "0"], ["83905.95", "0.073668"], ["83906.2", "0"]], "u": 69277, "seq": 67537875776}, "cts": 1742543262112, "record_time": 1742543262.088357}
{"topic": "orderbook.200.BTCUSDT", "ts": 1742543262320, "type": "delta", "data": {"s": "BTCUSDT", "b": [["83848.39", "0.023563"], ["83844.97", "0.029163"], ["83841.61", "0.114339"], ["83841.03", "0.118829"], ["83840.86", "1"], ["83840.79", "0.117593"], ["83839.44", "0"], ["83837.19", "0.116924"], ["83836.23", "0.059278"], ["83831.33", "0.191157"], ["83830.99", "0.174211"], ["83830.19", "0.185637"], ["83829.23", "0.058876"], ["83823.2", "0"], ["83823.19", "0.298119"], ["83822.23", "0.109741"], ["83821.89", "0.297298"], ["83818.23", "0.35789"], ["83817.26", "0"], ["83813.58", "0"]], "a": [["83865.53", "0.117008"], ["83865.99", "0.118873"], ["83868.73", "0.167271"], ["83869.36", "0.17885"], ["83869.4", "0"], ["83870.09", "0.115146"], ["83871.07", "0.024248"], ["83871.23", "0.055842"], ["83871.9", "0.171895"], ["83872.5", "0.1"], ["83874.6", "0.192"], ["83875.79", "0.165336"], ["83876.03", "0.170197"], ["83877.09", "0.181259"], ["83878.23", "0.060589"], ["83882.21", "0.023852"], ["83883.03", "0.288634"], ["83884.09", "0.304134"], ["83884.89", "0.298441"], ["83885.23", "0.123223"], ["83889.93", "0.125222"], ["83896.14", "0"], ["83896.15", "0"], ["83896.64", "0.0004"], ["83896.65", "0.000351"], ["83904.3", "0"], ["83905.48", "0"], ["83905.54", "0"], ["83905.59", "0"], ["83905.65", "0"], ["83905.95", "0"]], "u": 69278, "seq": 67537876011}, "cts": 1742543262314, "record_time": 1742543262.288123}
{"topic": "orderbook.200.BTCUSDT", "ts": 1742543262520, "type": "delta", "data": {"s": "BTCUSDT", "b": [["83851.02", "1.231939"], ["83841.61", "0.422599"], ["83840.97", "0.078967"], ["83830.28", "1.330318"], ["83823.2", "0.39043"], ["83818.62", "0"], ["83818.23", "0"], ["83816.19", "0.35789"], ["83804.77", "0.05"], ["83804.76", "0.049554"], ["83800.54", "0"], ["83800.34", "0"], ["83800.12", "0"], ["83800", "0"]], "a": [["83871.07", "0"], ["83871.9", "0.260461"], ["83873.36", "0.178889"], ["83876", "0.104"], ["83876.29", "0.44384"], ["83876.62", "0.035783"], ["83877.3", "0.116"], ["83896.64", "0"], ["83896.65", "0"], ["83897.64", "0.0004"], ["83897.65", "0.000351"], ["83903.91", "0"], ["83903.92", "0"], ["83904.42", "0.04"], ["83904.43", "0.04"], ["83904.58", "0"], ["83904.59", "0"], ["83904.78", "0"], ["83905.12", "0"]], "u": 69279, "seq": 67537876070}, "cts": 1742543262515, "record_time": 1742543262.486968}
{"topic": "orderbook.200.BTCUSDT", "ts": 1742543262720, "type": "delta", "data": {"s": "BTCUSDT", "b": [["83851.02", "1.330507"], ["83845.38", "0"], ["83841.03", "0.118449"], ["83840.97", "0"], ["83840.79", "0.114183"], ["83837.19", "0"], ["83836.23", "0.061669"], ["83831.33", "0.566773"], ["83830.99", "0.174703"], ["83830.19", "0"], ["83829.23", "0.060955"], ["83823.19", "0"], ["83822.23", "0.122131"], ["83821.89", "0.287264"], ["83816.19", "0"], ["83813.58", "0.357892"], ["83804.97", "0.05"], ["83804.96", "0.049554"], ["83804.77", "0"], ["83804.76", "0"], ["83800.54", "0.003"], ["83800.34", "0.029825"], ["83800.12", "0.119407"], ["83800", "0.003639"], ["83799.96", "0.000333"]], "a": [["83851.03", "0.151842"], ["83863.72", "0.071578"], ["83863.79", "0"], ["83864.73", "0.009163"], ["83865.52", "0.092409"], ["83865.53", "0.121671"], ["83865.99", "0.111724"], ["83870.09", "0"], ["83871.05", "0.178846"], ["83871.08", "0.02405"], ["83871.23", "0.054213"], ["83875.79", "0.165758"], ["83876.03", "0.186135"], ["83876.62", "0"], ["83876.8", "0.035783"], ["83877.09", "0"], ["83878.23", "0.061971"], ["83881.04", "0.639302"], ["83883.03", "0.299744"], ["83884.09", "0"], ["83884.89", "0.281057"], ["83885.23", "0.118149"], ["83896.73", "0.0004"], ["83896.74", "0.000351"], ["83897.64", "0"], ["83897.65", "0"], ["83904.42", "0"], ["83904.43", "0"]], "u": 69280, "seq": 67537876367}, "cts": 1742543262715, "record_time": 1742543262.689706}
{"topic": "orderbook.200.BTCUSDT", "ts": 1742543262920, "type": "delta", "data": {"s": "BTCUSDT", "b": [["83851.02", "1.21819"], ["83848.39", "0"], ["83841.03", "0"], ["83841.01", "0.120708"], ["83840.79", "0"], ["83840.77", "0.11201"], ["83837.17", "0.1182"], ["83836.23", "0"], ["83836.21", "0.057794"], ["83830.99", "0"], ["83830.97", "0.168485"], ["83830.17", "0.171021"], ["83829.23", "0"], ["83829.21", "0.058452"], ["83827.87", "0"], ["83823.17", "0.297417"], ["83822.23", "0"], ["83822.21", "0.122212"], ["83821.89", "0"], ["83821.87", "0.296955"], ["83799.96", "0"]], "a": [["83851.03", "0.152885"], ["83860.96", "0.004193"], ["83861.16", "0.228525"], ["83864.73", "0"], ["83865.51", "0.109752"], ["83865.52", "0"], ["83865.53", "0"], ["83865.97", "0.118007"], ["83865.99", "0"], ["83868.73", "0.238551"], ["83870.07", "0.114039"], ["83871.08", "0"], ["83871.21", "0.059842"], ["83871.23", "0"], ["83873.36", "0"], ["83875.77", "0.168931"], ["83875.79", "0"], ["83876.01", "0.183267"], ["83876.03", "0"], ["83876.8", "0"], ["83877.07", "0.186448"], ["83877.36", "0"], ["83878.21", "0.054641"], ["83878.23", "0"], ["83883.01", "0.299752"], ["83883.03", "0"], ["83884.07", "0.288806"], ["83884.87", "0.284577"], ["83884.88", "0.15926"], ["83884.89", "0"], ["83885.21", "0.123056"], ["83885.23", "0"], ["83896.73", "0"], ["83896.74", "0"], ["83897.23", "0.0004"], ["83897.24", "0.000351"], ["83904.72", "0.04"], ["83904.73", "0.04"]], "u": 69281, "seq": 67537876660}, "cts": 1742543262910, "record_time": 1742543262.88813}
{"topic": "orderbook.200.BTCUSDT", "ts": 1742543263120, "type": "delta", "data": {"s": "BTCUSDT", "b": [["83851.02", "1.318569"], ["83841.01", "0"], ["83840.77", "0"], ["83837.17", "0"], ["83836.21", "0"], ["83830.97", "0"], ["83830.17", "0"], ["83829.21", "0"], ["83823.17", "0"], ["83822.21", "0"], ["83821.87", "0"], ["83816.19", "0.357891"], ["83813.58", "0"], ["83805.17", "0.05"], ["83805.16", "0.049554"], ["83804.97", "0"], ["83804.96", "0"], ["83799.96", "0.000333"], ["83799.57", "0.000255"], ["83799.05", "0.000255"], ["83798.15", "0.005962"], ["83798.08", "0.001333"], ["83797.87", "0.023851"], ["83797.45", "0.001466"], ["83797.4", "0.011961"], ["83796.8", "0.04"], ["83796.53", "0.000206"]], "a": [["83851.03", "0.082497"], ["83860.96", "0.003"], ["83861.16", "0.229718"], ["83865.51", "0"], ["83865.97", "0"], ["83870.07", "0"], ["83871.21", "0"], ["83874.84", "0.178889"], ["83875.77", "0"], ["83876.01", "0"], ["83877.07", "0"], ["83878.21", "0"], ["83881.05", "0"], ["83883.01", "0"], ["83884.07", "0"], ["83884.87", "0"], ["83884.88", "0"], ["83885.21", "0"], ["83892.78", "0.046405"], ["83904.78", "0.000333"], ["83905.12", "0.000256"], ["83905.38", "0.013"], ["83905.39", "0.013"], ["83905.48", "0.003"], ["83905.54", "0.000225"], ["83905.59", "0.005961"], ["83905.65", "0.000256"], ["83905.95", "0.073668"], ["83906.19", "0.119407"], ["83906.2", "0.0016"], ["83906.51", "0.0015"]], "u": 69282, "seq": 67537876940}, "cts": 1742543263107, "record_time": 1742543263.140436}
{"topic": "orderbook.200.BTCUSDT", "ts": 1742543263319, "type": "delta", "data": {"s": "BTCUSDT", "b": [["83845.27", "0.024398"], ["83842.04", "0.110187"], ["83841.81", "0.112073"], ["83838.2", "0.113289"], ["83837.24", "0.058322"], ["83832.01", "0.177094"], ["83831.2", "0.170852"], ["83830.28", "0"], ["83830.24", "0.054872"], ["83830.21", "1.379429"], ["83829.26", "0.001173"], ["83827.24", "0.023852"], ["83826.75", "0.001173"], ["83824.2", "0.286331"], ["83823.24", "0.119252"], ["83823.2", "0"], ["83822.91", "0.296676"], ["83800.34", "0"], ["83800.12", "0"], ["83800", "0"], ["83799.96", "0"], ["83799.57", "0"], ["83799.05", "0"], ["83798.15", "0"], ["83798.08", "0"], ["83797.87", "0"], ["83797.45", "0"], ["83797.4", "0"], ["83796.8", "0"], ["83796.53", "0"]], "a": [["83851.03", "0.075939"], ["83866.54", "0.122269"], ["83867.01", "0.121088"], ["83871.1", "0.116351"], ["83872.24", "0.06188"], ["83873.25", "0.023465"], ["83873.36", "0.178889"], ["83876.81", "0.171202"], ["83876.82", "0.035783"], ["83877.04", "0.175242"], ["83877.08", "0.001317"], ["83878.1", "0.184396"], ["83879.24", "0.059606"], ["83879.6", "0.113317"], ["83881.04", "0.138043"], ["83883.8", "1.320236"], ["83884.04", "0.298967"], ["83885.1", "0.286501"], ["83885.91", "0.280499"], ["83886.24", "0.122193"], ["83890.02", "0.089444"], ["83893.66", "0"], ["83897.23", "0"], ["83897.24", "0"], ["83897.63", "0.0004"], ["83897.64", "0.000352"], ["83904.27", "0"], ["83904.72", "0"], ["83904.73", "0"], ["83904.78", "0"], ["83905.12", "0"], ["83905.38", "0"], ["83905.39", "0"], ["83905.48", "0"], ["83905.54", "0"], ["83905.59", "0"], ["83905.65", "0"], ["83905.95", "0"], ["83906.19", "0"], ["83906.2", "0"], ["83906.51", "0"]], "u": 69283, "seq": 67537877265}, "cts": 1742543263315, "record_time": 1742543263.286438}
{"topic": "orderbook.200.BTCUSDT", "ts": 1742543263520, "type": "delta", "data": {"s": "BTCUSDT", "b": [["83847.2", "0.0016"], ["83842.04", "0.110349"], ["83841.81", "0"], ["83841.8", "0.120203"], ["83838.2", "0.119555"], ["83837.7", "0.04"], ["83837.24", "0.057546"], ["83832.01", "0"], ["83832", "0.18449"], ["83831.2", "0.174801"], ["83830.24", "0.056748"], ["83826.57", "0.003576"], ["83824.21", "0.389996"], ["83824.2", "0.292913"], ["83823.24", "0.112466"], ["83822.91", "0"], ["83822.9", "0.375275"], ["83818.5", "0.0016"], ["83816.19", "0"], ["83813.58", "0.357892"], ["83809", "0"], ["83808.71", "0.013"], ["83808.7", "0.012882"], ["83808.02", "0.04"], ["83808.01", "0.03964"], ["83805.47", "0.05"], ["83805.46", "0.049553"], ["83805.17", "0"], ["83805.16", "0"], ["83802.1", "0"], ["83802.09", "0"], ["83801.42", "0"], ["83801.41", "0"], ["83800.72", "0"], ["83800.54", "0"]], "a": [["83851.03", "0.081901"], ["83866.54", "0.119628"], ["83867", "0.121829"], ["83867.01", "0"], ["83871.1", "0.112977"], ["83872.24", "0.056625"], ["83873.25", "0"], ["83873.59", "0.0241"], ["83875.97", "0.001157"], ["83876.26", "0.001194"], ["83876.8", "0.170144"], ["83876.81", "0"], ["83876.82", "0"], ["83877.04", "0.17054"], ["83877.08", "0"], ["83878.1", "0.175699"], ["83878.49", "0.001157"], ["83878.78", "0.001194"], ["83879.24", "0.057561"], ["83879.6", "0.112"], ["83881.04", "0.516759"], ["83884.04", "0.273534"], ["83885.1", "0.291494"], ["83885.9", "0.301433"], ["83885.91", "0"], ["83886.24", "0.108893"], ["83897.53", "0.0004"], ["83897.54", "0.000352"], ["83897.63", "0"], ["83897.64", "0"], ["83903.8", "0"], ["83903.9", "0"]], "u": 69284, "seq": 67537877559}, "cts": 1742543263511, "record_time": 1742543263.487924}
{"topic": "orderbook.200.BTCUSDT", "ts": 1742543263719, "type": "delta", "data": {"s": "BTCUSDT", "b": [["83851", "0.0012"], ["83842.04", "0"], ["83841.8", "0"], ["83838.2", "0"], ["83832", "0"], ["83831.27", "0.005539"], ["83831.2", "0"], ["83826.57", "0"], ["83824.2", "0"], ["83822.9", "0.071613"], ["83813.59", "0.357894"], ["83813.58", "0"], ["83808.71", "0"], ["83808.69", "0.012883"], ["83808.12", "0.04"], ["83808.11", "0.03964"], ["83808.02", "0"], ["83808.01", "0"], ["83805.57", "0.05"], ["83805.56", "0.049553"], ["83805.47", "0"], ["83805.46", "0"], ["83800.72", "0.000206"], ["83800.34", "0.029825"], ["83800.2", "0.003"], ["83800.12", "0.119407"], ["83800", "0.003639"], ["83799.96", "0.000333"], ["83799.57", "0.000255"]], "a": [["83851.03", "0.078477"], ["83866.54", "0"], ["83867", "0"], ["83871.1", "0"], ["83875.97", "0"], ["83876.26", "0"], ["83876.8", "0"], ["83877.04", "0"], ["83877.06", "0.035783"], ["83878.1", "0"], ["83878.49", "0"], ["83878.78", "0"], ["83884.04", "0"], ["83885.1", "0.0006"], ["83885.9", "0"], ["83897.53", "0"], ["83897.54", "0"], ["83897.63", "0.0004"], ["83897.64", "0.000352"], ["83903.8", "0.0006"], ["83903.9", "0.023845"], ["83904.27", "0.001"], ["83904.41", "0.04"], ["83904.42", "0.04"], ["83904.78", "0.000333"], ["83905.08", "0.013"], ["83905.09", "0.013"], ["83905.12", "0.000256"], ["83905.54", "0.000225"], ["83905.59", "0.005961"]], "u": 69285, "seq": 67537877771}, "cts": 1742543263715, "record_time": 1742543263.687913}
{"topic": "orderbook.200.BTCUSDT", "ts": 1742543263920, "type": "delta", "data": {"s": "BTCUSDT", "b": [["83851.02", "1.240402"], ["83842.11", "0.116763"], ["83841.87", "0.124021"], ["83840.97", "0.078967"], ["83838.26", "0.116194"], ["83837.31", "0.058352"], ["83837.24", "0"], ["83832.07", "0.168752"], ["83831.26", "0.179116"], ["83830.31", "0.059919"], ["83830.24", "0"], ["83824.26", "0.27861"], ["83824.21", "0"], ["83823.31", "0.123182"], ["83823.24", "0"], ["83822.97", "0.279066"], ["83813.6", "0.357896"], ["83813.59", "0"], ["83809.73", "0.2"], ["83808.81", "0.013"], ["83808.8", "0.012882"], ["83808.7", "0"], ["83808.69", "0"], ["83808.13", "0.04"], ["83808.12", "0.03964"], ["83808.11", "0"], ["83800.72", "0"], ["83800.34", "0"], ["83800.2", "0"], ["83800.12", "0"], ["83800", "0"], ["83799.96", "0"], ["83799.57", "0"]], "a": [["83851.03", "0.077077"], ["83866.61", "0.120198"], ["83867.07", "0.117903"], ["83871.16", "0.112559"], ["83872.24", "0"], ["83872.31", "0.054275"], ["83876.31", "0.0012"], ["83876.87", "0.170201"], ["83877.11", "0.166341"], ["83877.31", "0.001358"], ["83878.16", "0.174052"], ["83878.82", "0.0012"], ["83879.24", "0"], ["83879.31", "0.062059"], ["83879.83", "0.001358"], ["83884.11", "0.307923"], ["83885.16", "0.273701"], ["83885.97", "0.28854"], ["83886.24", "0"], ["83886.31", "0.114318"], ["83903.79", "0"], ["83903.8", "0"], ["83903.9", "0"], ["83904.27", "0"], ["83904.41", "0"], ["83904.42", "0"], ["83904.78", "0"], ["83905.08", "0"], ["83905.09", "0"], ["83905.12", "0"], ["83905.54", "0"], ["83905.59", "0"]], "u": 69286, "seq": 67537877977}, "cts": 1742543263916, "record_time": 1742543263.88655}
{"topic": "orderbook.200.BTCUSDT", "ts": 1742543264120, "type": "delta", "data": {"s": "BTCUSDT", "b": [["83851.02", "1.327369"], ["83840.97", "0"], ["83815.5", "0.000068"], ["83813.61", "0.357896"], ["83813.6", "0"], ["83809.73", "0"], ["83800.72", "0.000206"]], "a": [["83876.31", "0"], ["83877.31", "0"], ["83877.55", "0.001403"], ["83878.82", "0"], ["83879.83", "0"], ["83880.06", "0.126625"], ["83880.09", "0"], ["83881.49", "0.115151"], ["83884.1", "0.334978"], ["83903.79", "0.001549"], ["83903.8", "0.0006"]], "u": 69287, "seq": 67537878130}, "cts": 1742543264110, "record_time": 1742543264.188715}
{"topic": "orderbook.200.BTCUSDT", "ts": 1742543264320, "type": "delta", "data": {"s": "BTCUSDT", "b": [["83842.11", "0"], ["83841.87", "0.000333"], ["83838.26", "0"], ["83837.31", "0"], ["83832.07", "0"], ["83831.26", "0"], ["83830.31", "0"], ["83828.97", "0"], ["83824.26", "0"], ["83823.31", "0"], ["83822.97", "0"], ["83820.26", "0.357874"], ["83815.5", "0"], ["83815.4", "0.000068"], ["83813.61", "0"], ["83808.81", "0"], ["83808.8", "0"], ["83808.71", "0.013"], ["83808.7", "0.012882"], ["83808.13", "0"], ["83808.12", "0"], ["83808.03", "0.04"], ["83808.02", "0.03964"], ["83807.98", "0"], ["83805.57", "0"], ["83805.56", "0"], ["83805.47", "0.05"], ["83805.46", "0.049553"], ["83800.34", "0.029825"], ["83800.2", "0.003"], ["83800.12", "0.119407"], ["83800", "0.003639"], ["83799.96", "0.000333"], ["83799.57", "0.000255"], ["83799.05", "0.000255"], ["83798.15", "0.005962"], ["83798.08", "0.001333"], ["83797.87", "0.023851"], ["83797.45", "0.001466"]], "a": [["83851.03", "0.070876"], ["83863.72", "0"], ["83865.92", "0.071577"], ["83866.61", "0.001466"], ["83867.07", "0"], ["83869.35", "0.058414"], ["83871.16", "0"], ["83872.31", "0"], ["83876.03", "0.001164"], ["83876.87", "0"], ["83877.11", "0"], ["83877.55", "0"], ["83878.16", "0"], ["83878.54", "0.001164"], ["83879.31", "0"], ["83880.06", "0.125222"], ["83882.26", "0.119259"], ["83884.11", "0"], ["83885.16", "0"], ["83885.97", "0"], ["83886.31", "0"], ["83897.63", "0"], ["83897.64", "0"], ["83897.73", "0.0004"], ["83897.74", "0.000352"], ["83903.9", "0.023845"], ["83904.27", "0.001"], ["83904.51", "0.04"], ["83904.52", "0.04"], ["83904.78", "0.000333"], ["83905.12", "0.000256"], ["83905.17", "0.013"], ["83905.18", "0.013"]], "u": 69288, "seq": 67537878372}, "cts": 1742543264317, "record_time": 1742543264.287614}
{"topic": "orderbook.200.BTCUSDT", "ts": 1742543264520, "type": "delta", "data": {"s": "BTCUSDT", "b": [["83851.02", "1.093584"], ["83848.87", "0"], ["83845.89", "0.023851"], ["83845.62", "0.207721"], ["83845.61", "0"], ["83842.11", "0.118111"], ["83841.87", "0.122866"], ["83841.64", "0"], ["83838.26", "0.11636"], ["83837.31", "0.054332"], ["83832.07", "0.173085"], ["83831.26", "0.166461"], ["83830.31", "0.055085"], ["83824.26", "0.309606"], ["83823.31", "0.120971"], ["83822.97", "0.272048"], ["83820.27", "0.342766"], ["83820.26", "0"], ["83816.18", "0"], ["83815.5", "0.000068"], ["83815.4", "0"], ["83813.58", "0.357897"], ["83808.49", "0"], ["83808.13", "0.04"], ["83808.12", "0.03964"], ["83808.03", "0"], ["83808.02", "0"], ["83805.57", "0.05"], ["83805.56", "0.049553"], ["83805.47", "0"], ["83805.46", "0"], ["83799.57", "0"], ["83799.05", "0"], ["83798.15", "0"], ["83798.08", "0"], ["83797.87", "0"], ["83797.45", "0"]], "a": [["83851.03", "0.077077"], ["83863.95", "0.074034"], ["83863.96", "0.071578"], ["83865.92", "0"], ["83866.46", "0.008934"], ["83866.61", "0.120652"], ["83867.07", "0.123031"], ["83869.55", "0.005059"], ["83871.16", "0.117938"], ["83872.27", "0"], ["83872.31", "0.059025"], ["83872.33", "0.178889"], ["83874.84", "0"], ["83876.03", "0"], ["83876.87", "0.176886"], ["83877.11", "0.175167"], ["83878.16", "0.18194"], ["83878.54", "0"], ["83879.31", "0.056542"], ["83881.64", "0"], ["83884.1", "0"], ["83884.11", "0.29671"], ["83885.16", "0.302833"], ["83885.97", "0.280914"], ["83886.31", "0.120376"], ["83897.63", "0.0004"], ["83897.64", "0.000352"], ["83897.73", "0"], ["83897.74", "0"], ["83903.12", "0.073673"], ["83903.79", "0"], ["83903.8", "0"], ["83903.9", "0"], ["83904.27", "0"], ["83904.51", "0"], ["83904.52", "0"], ["83904.78", "0"], ["83905.12", "0"], ["83905.17", "0"], ["83905.18", "0"]], "u": 69289, "seq": 67537878760}, "cts": 1742543264516, "record_time": 1742543264.486973}
{"topic": "orderbook.200.BTCUSDT", "ts": 1742543264719, "type": "delta", "data": {"s": "BTCUSDT", "b": [["83851.02", "0.922584"], ["83850.14", "0.025355"], ["83848.96", "0"], ["83842.47", "0.046405"], ["83840.97", "0.078962"], ["83840.47", "0.019601"], ["83820.27", "0"], ["83815.5", "0"], ["83815.4", "0.000068"], ["83813.58", "0"], ["83811.63", "0.357908"], ["83808.13", "0"], ["83808.12", "0"], ["83808.03", "0.04"], ["83808.02", "0.03964"], ["83805.57", "0"], ["83805.56", "0"], ["83805.47", "0.05"], ["83805.46", "0.049553"], ["83800.7", "0.354288"], ["83800", "0"], ["83799.96", "0"]], "a": [["83851.03", "0.077066"], ["83861.15", "0.144461"], ["83861.16", "0.228525"], ["83866.46", "0"], ["83873.25", "0.178889"], ["83875.03", "0.046405"], ["83881.87", "0"], ["83897.63", "0"], ["83897.64", "0"], ["83897.72", "0.0004"], ["83897.73", "0.000352"], ["83903.52", "0"]], "u": 69290, "seq": 67537879088}, "cts": 1742543264707, "record_time": 1742543264.725974}
{"topic": "orderbook.200.BTCUSDT", "ts": 1742543264919, "type": "delta", "data": {"s": "BTCUSDT", "b": [["83855.21", "1.129006"], ["83854.83", "0.119407"], ["83854.81", "0.240406"], ["83854.8", "0.359689"], ["83851.02", "0.512852"], ["83850.37", "0.001"], ["83850.14", "0.038175"], ["83850.13", "0"], ["83849.96", "0"], ["83849.87", "0.004479"], ["83847.98", "0.008958"], ["83847.19", "0.089922"], ["83846.61", "0"], ["83845.44", "0"], ["83844.91", "0.00009"], ["83843.79", "0.017917"], ["83842.35", "0"], ["83842.11", "0"], ["83841.87", "0.000333"], ["83841.25", "0"], ["83840.97", "0.077017"], ["83838.26", "0"], ["83837.31", "0"], ["83836.88", "0.071601"], ["83832.07", "0"], ["83831.27", "0"], ["83831.26", "0"], ["83830.31", "0"], ["83827.97", "0.04559"], ["83824.26", "0"], ["83823.31", "0"], ["83822.97", "0"], ["83822.9", "0"], ["83817.32", "0.357888"], ["83816.9", "0.000068"], ["83815.4", "0"], ["83811.63", "0"], ["83808.81", "0.013"], ["83808.8", "0.012882"], ["83808.71", "0"], ["83808.7", "0"], ["83808.13", "0.04"], ["83808.12", "0.03964"], ["83808.03", "0"], ["83808.02", "0"], ["83806.98", "0.05"], ["83806.97", "0.050552"], ["83805.47", "0"], ["83805.46", "0"], ["83800", "0.003639"], ["83799.96", "0.000333"], ["83799.57", "0.000255"], ["83799.05", "0.000255"], ["83798.15", "0.005962"], ["83798.08", "0.001333"]], "a": [["83851.03", "0"], ["83854.18", "0"], ["83855.22", "0.04083"], ["83856.08", "0"], ["83859.52", "0.007937"], ["83860.11", "0"], ["83861.15", "0"], ["83861.16", "0.229718"], ["83862.45", "0.015874"], ["83863.95", "0"], ["83863.96", "0"], ["83864.3", "0"], ["83865.76", "0.000153"], ["83866.61", "0.03614"], ["83866.64", "0.031748"], ["83866.85", "0.071576"], ["83867.06", "0.110066"], ["83867.07", "0"], ["83868.73", "0"], ["83869.35", "0"], ["83869.36", "0"], ["83869.55", "0"], ["83870.22", "0"], ["83870.84", "0"], ["83871.05", "0"], ["83871.16", "0"], ["83871.9", "0.394217"], ["83872.31", "0"], ["83872.33", "0"], ["83872.89", "0.005143"], ["83873.25", "0"], ["83873.36", "0"], ["83875.06", "0"], ["83875.13", "0.001066"], ["83876.87", "0"], ["83877.11", "0"], ["83877.45", "0"], ["83877.65", "0.001066"], ["83878.16", "0"], ["83879.31", "0"], ["83880.06", "0"], ["83884.11", "0"], ["83885.16", "0"], ["83885.97", "0"], ["83886.31", "0"], ["83889.93", "0"], ["83890.02", "0"], ["83892.95", "0.000225"], ["83897.22", "0.0004"], ["83897.23", "0.000352"], ["83897.72", "0"], ["83897.73", "0"], ["83903.12", "0"], ["83903.52", "0.001466"], ["83903.79", "0.001549"], ["83903.8", "0.0006"], ["83903.9", "0.023845"], ["83904.27", "0.001"], ["83904.4", "0.04"], ["83904.41", "0.04"], ["83904.78", "0.000333"], ["83905.07", "0.013"], ["83905.08", "0.013"], ["83905.12", "0.000256"], ["83905.54", "0.000225"], ["83905.59", "0.005961"], ["83905.65", "0.000256"], ["83905.82", "0.003"], ["83906.19", "0.119407"], ["83906.2", "0.0016"], ["83906.51", "0.0015"], ["83906.52", "0.003"], ["83906.71", "0.00009"], ["83906.8", "0.00009"], ["83907.09", "0.001333"], ["83907.21", "0.023845"], ["83907.78", "0.354284"], ["83908.13", "0.001466"], ["83908.78", "0.073673"]], "u": 69291, "seq": 67537879551}, "cts": 1742543264915, "record_time": 1742543264.886912}
{"topic": "orderbook.200.BTCUSDT", "ts": 1742543265120, "type": "delta", "data": {"s": "BTCUSDT", "b": [["83855.21", "1.133776"], ["83854.38", "0.002098"], ["83851.03", "0.008"], ["83851.02", "0.423065"], ["83850.91", "0.004479"], ["83850.19", "0"], ["83849.87", "0"], ["83848.52", "0.033576"], ["83848.04", "0"], ["83845.94", "0.005963"], ["83845.62", "0.13286"], ["83842.49", "0.121205"], ["83842.25", "0.122231"], ["83841.75", "0"], ["83840.97", "0"], ["83838.64", "0.115568"], ["83837.68", "0.055844"], ["83832.45", "0.18676"], ["83831.64", "0.180996"], ["83830.68", "0.059463"], ["83824.64", "0.29432"], ["83823.68", "0.118338"], ["83823.35", "0.28769"], ["83817.32", "0"], ["83816.9", "0.000063"], ["83813.58", "0.357889"], ["83810.21", "0.013"], ["83810.2", "0.012883"], ["83809.53", "0.04"], ["83809.52", "0.039643"], ["83808.81", "0"], ["83808.8", "0"], ["83808.13", "0"], ["83808.12", "0"], ["83806.97", "0.050556"], ["83800.34", "0"], ["83800.2", "0"], ["83800.12", "0"], ["83800", "0"], ["83799.96", "0"], ["83799.57", "0"], ["83799.05", "0"], ["83798.15", "0"], ["83798.08", "0"]], "a": [["83855.22", "0.404552"], ["83858.37", "0.000099"], ["83860.03", "0.001193"], ["83860.39", "0"], ["83861.16", "0.228525"], ["83861.25", "0"], ["83865.44", "0.005963"], ["83866.61", "0.067121"], ["83866.99", "0.117716"], ["83867.06", "0.073063"], ["83867.3", "0.009055"], ["83867.45", "0.119146"], ["83870.47", "0.005164"], ["83871.54", "0.10906"], ["83871.9", "0"], ["83872.49", "0.196222"], ["83872.68", "0.060607"], ["83872.89", "0"], ["83875.13", "0"], ["83876.29", "0"], ["83877.25", "0.174516"], ["83877.49", "0.165849"], ["83877.65", "0"], ["83878.54", "0.175207"], ["83879.68", "0.05569"], ["83884.49", "0.304424"], ["83885.54", "0.295811"], ["83886.35", "0.304679"], ["83886.68", "0.120542"], ["83898.51", "0.17888"], ["83904", "0.04"], ["83904.01", "0.04"], ["83904.4", "0"], ["83904.41", "0"], ["83904.67", "0.013"], ["83904.68", "0.013"], ["83905.07", "0"], ["83905.08", "0"], ["83905.82", "0"], ["83906.19", "0"], ["83906.2", "0"], ["83906.51", "0"], ["83906.52", "0"], ["83906.71", "0"], ["83906.8", "0"], ["83907.09", "0"], ["83907.21", "0"], ["83907.78", "0"], ["83908.13", "0"], ["83908.78", "0"]], "u": 69292, "seq": 67537879764}, "cts": 1742543265117, "record_time": 1742543265.436105}
{"topic": "orderbook.200.BTCUSDT", "ts": 1742543265320, "type": "delta", "data": {"s": "BTCUSDT", "b": [["83855.21", "1.007869"], ["83852.06", "0.000099"], ["83851.02", "0.415905"], ["83845.62", "0.204195"], ["83845.16", "0.077017"], ["83800.72", "0"], ["83800.7", "0"]], "a": [["83867.3", "0"], ["83874.84", "0.17888"], ["83876.27", "0.001195"], ["83876.83", "0.431759"], ["83877.14", "0.001327"], ["83877.45", "0.17888"], ["83878.79", "0.001195"], ["83879.66", "0.004902"], ["83881.64", "0.17888"], ["83889.93", "0.125216"], ["83903.12", "0.073673"], ["83904.27", "0"], ["83904.67", "0"], ["83904.68", "0"], ["83904.78", "0"], ["83905.12", "0"], ["83905.54", "0"], ["83905.59", "0"], ["83905.65", "0"]], "u": 69293, "seq": 67537879846}, "cts": 1742543265312, "record_time": 1742543265.439581}
{"topic": "orderbook.200.BTCUSDT", "ts": 1742543265520, "type": "delta", "data": {"s": "BTCUSDT", "b": [["83855.21", "0.946905"], ["83852.07", "0.008"], ["83851.04", "0.002982"], ["83851.03", "0"], ["83848.9", "0.0015"], ["83847.2", "0"], ["83845.16", "0"], ["83824.65", "0.367939"], ["83822.78", "0.11"], ["83820.25", "0"], ["83820.2", "0.060014"], ["83818.5", "0"]], "a": [["83855.22", "0.423893"], ["83876.27", "0"], ["83877.14", "0"], ["83878.79", "0"], ["83879.66", "0.003575"], ["83884.48", "0.347203"], ["83896", "0.17888"], ["83898.51", "0"], ["83901.97", "0.005"], ["83903.12", "0.073669"], ["83904.27", "0.001"]], "u": 69294, "seq": 67537879936}, "cts": 1742543265510, "record_time": 1742543265.489335}
