{"topic": "orderbook.200.BTCUSDT", "ts": 1742561258319, "type": "snapshot", "data": {"s": "BTCUSDT", "b": [["83870.8", "0.481478"], ["83870.7", "0.001928"], ["83870.2", "0.023557"], ["83870.1", "0.072173"], ["83867.1", "0.005749"], ["83866", "0.0006"], ["83865.5", "0.000512"], ["83865.4", "0.000333"], ["83865", "0.071577"], ["83864.7", "0.001333"], ["83864.3", "0.003187"], ["83864.2", "0.003679"], ["83862.9", "0.092145"], ["83862.8", "0.071579"], ["83862.4", "0.186"], ["83861.7", "0.08875"], ["83861.2", "0.000333"], ["83860.9", "0.000512"], ["83860.6", "0.045674"], ["83860.5", "0.142515"], ["83860.4", "0.00009"], ["83860.1", "0.003187"], ["83860", "0.00006"], ["83858.6", "0.000994"], ["83858.5", "0.0054"], ["83857.1", "0.001466"], ["83857", "0.000333"], ["83856.7", "0.000298"], ["83856.3", "0.059919"], ["83855.9", "0.003184"], ["83855.3", "0.054463"], ["83854.9", "0.04"], ["83854.5", "0.04"], ["83853.8", "0.003938"], ["83853.2", "0.052"], ["83852.9", "0.04"], ["83852.8", "0.000333"], ["83852.5", "0.001466"], ["83852.4", "0.119299"], ["83852.2", "0.114758"], ["83852.1", "0.045333"], ["83852", "0.00009"], ["83851.7", "0.003694"], ["83851.6", "0.171"], ["83851.5", "0.052"], ["83851.2", "0.044"], ["83849.7", "0.018136"], ["83848.8", "0.052"], ["83848.6", "0.000333"], ["83847.9", "0.050799"], ["83847.6", "0.003181"], ["83847.1", "0.00051"], ["83847", "0.009005"], ["83846.8", "0.066989"], ["83846.7", "0.119299"], ["83846.6", "0.044"], ["83846", "0.059399"], ["83845.1", "0.023373"], ["83844.8", "0.0006"], ["83844.4", "0.000333"], ["83844.2", "0.016394"], ["83844.1", "0.090518"], ["83843.7", "0.001333"], ["83843.6", "0.00009"], ["83843.4", "0.003181"], ["83843.2", "0.001466"], ["83843.1", "0.004654"], ["83842.6", "0.025393"], ["83842.5", "0.00051"], ["83842.4", "0.001197"], ["83841.6", "0.119299"], ["83840.4", "0.171"], ["83840.2", "0.000333"], ["83840", "0.000483"], ["83839.5", "0.432255"], ["83839.4", "0.552682"], ["83839.2", "0.00318"], ["83838.6", "0.001466"], ["83837.8", "0.00051"], ["83837.6", "0.0002"], ["83836.5", "0.507615"], ["83836.3", "0.059399"], ["83836", "0.000333"], ["83835.9", "0.073541"], ["83835.8", "0.119299"], ["83835.6", "0.035779"], ["83835.3", "0.001333"], ["83835.2", "0.00009"], ["83835", "0.003173"], ["83834", "0.001466"], ["83833.9", "0.059633"], ["83833.2", "0.00051"], ["83832.5", "0.023853"], ["83831.8", "0.000333"], ["83831.3", "0.009"], ["83831.1", "0.0861"], ["83831", "0.02268"], ["83830.9", "0.089099"], ["83830.8", "0.003173"], ["83829.8", "0.0016"], ["83829.4", "0.180312"], ["83828.6", "0.00051"], ["83827.8", "0.126037"], ["83827.7", "0.119299"], ["83827.6", "0.000333"], ["83827.5", "0.171"], ["83827.1", "0.013241"], ["83827", "0.012883"], ["83826.9", "0.001333"], ["83826.8", "0.00009"], ["83826.6", "0.003173"], ["83826.3", "0.01193"], ["83824.8", "0.001466"], ["83824.5", "0.013957"], ["83824.3", "0.005961"], ["83824", "0.100304"], ["83823.6", "0.002503"], ["83823.5", "1.102163"], ["83823.4", "0.059399"], ["83822.7", "0.001333"], ["83822.5", "0.119299"], ["83822.4", "3.535394"], ["83821.4", "0.023848"], ["83820.5", "0.023848"], ["83820.2", "0.001466"], ["83820", "0.00006"], ["83819.4", "0.000508"], ["83819.3", "0.000333"], ["83818.5", "0.060966"], ["83818.4", "0.00009"], ["83818.2", "0.003173"], ["83817.9", "0.11504"], ["83817.8", "0.171"], ["83817.4", "0.059633"], ["83816.5", "0.0225"], ["83816", "0.023846"], ["83815.6", "0.025312"], ["83815.3", "0.089099"], ["83815.1", "0.000333"], ["83814.8", "0.000508"], ["83814.4", "0.001333"], ["83814.2", "1.171932"], ["83814.1", "3.697219"], ["83814", "0.003173"], ["83813.8", "0.128858"], ["83812.4", "0.119299"], ["83812", "0.000118"], ["83811.2", "0.413682"], ["83811", "0.001466"], ["83810.9", "0.000333"], ["83810.8", "0.0006"], ["83810.2", "0.001841"], ["83810", "0.011974"], ["83809.9", "0.061228"], ["83809.8", "0.027042"], ["83809.2", "0.00009"], ["83808.5", "0.04"], ["83808.4", "0.171"], ["83807.5", "0.005962"], ["83807.2", "0.000149"], ["83806.9", "0.044"], ["83806.8", "0.05624"], ["83806.7", "0.119632"], ["83806.5", "0.044"], ["83806.4", "0.001466"], ["83806", "0.001333"], ["83805.9", "0.015"], ["83805.6", "0.003679"], ["83805", "0.000358"], ["83804.6", "0.02385"], ["83803.7", "1.812314"], ["83802.7", "0.059399"], ["83802.5", "0.000333"], ["83802.2", "0.005963"], ["83801.8", "0.002799"], ["83801.6", "0.00009"], ["83801.5", "0.178313"], ["83801.4", "0.282574"], ["83801.3", "0.009"], ["83801", "0.000508"], ["83800.1", "0.119299"], ["83800", "0.172157"], ["83799.2", "0.02385"], ["83798.8", "0.02385"], ["83798.7", "3.38725"], ["83798.5", "0.235392"], ["83798.3", "0.000333"], ["83797.7", "0.059633"], ["83797.6", "0.001333"], ["83797.3", "0.003167"], ["83797.1", "0.001466"], ["83796.4", "0.000508"], ["83796.1", "0.02764"], ["83796", "0.04"], ["83794.3", "0.119299"], ["83794.1", "0.000333"], ["83793.7", "0.089099"], ["83793.4", "0.001333"], ["83793.3", "0.029816"], ["83793.2", "0.011974"]], "a": [["83870.9", "0.516378"], ["83871.1", "0.021471"], ["83872.7", "0.003244"], ["83873", "0.001333"], ["83873.8", "0.000333"], ["83874.6", "0.006181"], ["83874.7", "0.000512"], ["83875.1", "0.020867"], ["83875.2", "0.02147"], ["83875.4", "0.003857"], ["83875.5", "0.001466"], ["83876.5", "0.0045"], ["83876.9", "0.003244"], ["83877.2", "0.001333"], ["83877.3", "0.011884"], ["83877.4", "0.02147"], ["83878", "0.000333"], ["83878.4", "0.09756"], ["83878.8", "0.009664"], ["83879.3", "0.015"], ["83879.4", "0.000512"], ["83880.1", "0.019683"], ["83880.2", "0.02646"], ["83880.7", "0.0002"], ["83881.1", "0.003244"], ["83881.2", "0.023705"], ["83881.3", "0.178824"], ["83881.4", "0.001333"], ["83881.9", "0.065257"], ["83882.1", "0.000333"], ["83882.2", "0.00009"], ["83882.7", "0.207163"], ["83883", "0.000358"], ["83883.1", "0.17882"], ["83884", "0.000512"], ["83884.6", "0.178817"], ["83884.8", "0.001466"], ["83885.1", "0.003548"], ["83885.2", "0.04"], ["83885.3", "0.043244"], ["83885.4", "0.020911"], ["83885.6", "0.001333"], ["83886.3", "0.000333"], ["83886.6", "0.373072"], ["83886.7", "0.021638"], ["83886.9", "0.04"], ["83887", "0.044"], ["83888", "0.0424"], ["83888.5", "0.04"], ["83888.6", "0.000512"], ["83888.7", "0.04"], ["83888.9", "0.00926"], ["83889.4", "0.001466"], ["83889.5", "0.003244"], ["83889.8", "0.001333"], ["83889.9", "0.059399"], ["83890", "0.19984"], ["83890.2", "0.04"], ["83890.3", "0.002528"], ["83890.4", "0.04"], ["83890.5", "0.000333"], ["83890.6", "0.00009"], ["83891.3", "0.009"], ["83891.7", "0.082908"], ["83891.9", "0.04"], ["83892", "0.04"], ["83893.2", "0.000512"], ["83893.3", "0.02464"], ["83893.4", "0.002261"], ["83893.5", "0.000057"], ["83893.7", "0.003244"], ["83894", "0.002799"], ["83894.1", "0.011884"], ["83894.2", "0.01193"], ["83894.7", "0.000333"], ["83895", "0.171"], ["83895.4", "0.035779"], ["83896.3", "0.152672"], ["83896.4", "0.495252"], ["83897", "0.000118"], ["83897.8", "0.000512"], ["83897.9", "0.003244"], ["83898.1", "0.001789"], ["83898.2", "0.001333"], ["83898.6", "0.001466"], ["83898.9", "0.000333"], ["83899", "0.00009"], ["83899.5", "0.000083"], ["83900", "0.32736"], ["83900.1", "0.059399"], ["83901.4", "0.04"], ["83901.5", "0.052723"], ["83901.6", "0.012723"], ["83902.1", "0.003244"], ["83902.4", "0.001845"], ["83902.9", "0.559701"], ["83903.1", "0.000333"], ["83903.2", "0.001466"], ["83903.4", "0.171"], ["83903.6", "0.065548"], ["83903.7", "0.023848"], ["83904.4", "0.023846"], ["83904.8", "0.023846"], ["83905", "0.004622"], ["83905.1", "0.000358"], ["83905.2", "0.023848"], ["83905.9", "0.063474"], ["83906.1", "0.023848"], ["83906.3", "0.003244"], ["83906.5", "0.0045"], ["83906.6", "0.001333"], ["83906.8", "0.00009"], ["83906.9", "0.003564"], ["83907", "0.000512"], ["83907.3", "0.000333"], ["83907.4", "0.0007"], ["83907.8", "0.001466"], ["83908", "0.162341"], ["83908.1", "0.14095"], ["83908.5", "0.089099"], ["83909.4", "0.00315"], ["83910.4", "0.000332"], ["83910.5", "0.003244"], ["83910.8", "0.001333"], ["83910.9", "0.011884"], ["83911.5", "0.000333"], ["83911.7", "0.119811"], ["83911.8", "0.171"], ["83912.3", "0.440841"], ["83912.4", "1.431524"], ["83912.6", "2.606292"], ["83912.8", "0.003"], ["83913.1", "0.005961"], ["83913.3", "0.002721"], ["83914.7", "0.003244"], ["83914.9", "0.024265"], ["83915", "0.001333"], ["83915.7", "0.000333"], ["83915.8", "0.00009"], ["83916.3", "0.000512"], ["83916.8", "0.119299"], ["83916.9", "0.059399"], ["83917.1", "0.001466"], ["83918.3", "0.013832"], ["83918.9", "0.009194"], ["83919.2", "0.001333"], ["83919.9", "0.000333"], ["83920.2", "0.171"], ["83920.9", "0.000512"], ["83921.3", "0.009"], ["83921.7", "0.001466"], ["83922", "0.119299"], ["83922.4", "3.320659"], ["83923", "0.003447"], ["83923.1", "0.178735"], ["83923.4", "0.001333"], ["83924", "0.10466"], ["83924.1", "0.000333"], ["83924.2", "0.00009"], ["83925.3", "0.003564"], ["83925.5", "0.000512"], ["83925.9", "0.015"], ["83926.3", "0.001466"], ["83927.2", "0.003602"], ["83927.6", "0.001333"], ["83927.7", "0.011884"], ["83927.9", "0.004765"], ["83928.3", "0.354728"], ["83928.6", "0.171"], ["83929.6", "0.003779"], ["83930.1", "0.000512"], ["83930.8", "0.04"], ["83930.9", "0.001466"], ["83931.4", "0.003244"], ["83931.8", "0.001333"], ["83932.1", "0.366511"], ["83932.2", "1.125909"], ["83932.5", "0.000333"], ["83932.6", "0.00009"], ["83933.7", "0.059399"], ["83934.7", "0.000512"], ["83935.5", "0.001466"], ["83935.6", "0.003244"], ["83935.9", "0.04"], ["83936", "0.001333"], ["83936.5", "0.0045"], ["83936.7", "0.000333"], ["83937", "0.171"], ["83937.1", "0.011992"], ["83938", "1.788464"], ["83939.4", "0.000512"], ["83939.8", "0.015236"], ["83940.1", "0.001466"], ["83940.2", "0.001333"], ["83940.9", "0.000333"], ["83941", "0.002905"], ["83941.5", "0.08019"], ["83942.1", "0.059399"], ["83942.2", "0.239299"], ["83942.9", "0.04"]], "u": 49863, "seq": 67553422699}, "cts": 1742561258295, "record_time": 1742561258.898097, "EXCHANGE": "BYBIT"}
{"topic": "orderbook.200.BTCUSDT", "ts": 1742561258519, "type": "delta", "data": {"s": "BTCUSDT", "b": [["83870.8", "0.477307"], ["83865", "0"], ["83864.7", "0.072911"], ["83862.8", "0"], ["83860.5", "0.214096"], ["83822.4", "0.003173"], ["83811.1", "3.54833"], ["83793.1", "0.004367"]], "a": [["83909.8", "2.606292"], ["83912.3", "1.168524"], ["83912.6", "0"]], "u": 49864, "seq": 67553422759}, "cts": 1742561258516, "record_time": 1742561258.899135, "EXCHANGE": "BYBIT"}
{"topic": "orderbook.200.BTCUSDT", "ts": 1742561258720, "type": "delta", "data": {"s": "BTCUSDT", "b": [["83861.7", "0.068722"], ["83827.1", "0.000358"], ["83827", "0.013"], ["83826.9", "0.014216"], ["83823.5", "0.055904"]], "a": [["83900.5", "0.013"], ["83900.6", "0.012723"], ["83901.5", "0.04"], ["83901.6", "0"], ["83912.3", "0.440841"], ["83942.9", "0"]], "u": 49865, "seq": 67553422783}, "cts": 1742561258662, "record_time": 1742561258.899884, "EXCHANGE": "BYBIT"}
{"topic": "orderbook.200.BTCUSDT", "ts": 1742561258920, "type": "delta", "data": {"s": "BTCUSDT", "b": [["83870.8", "0.491168"], ["83830.8", "3.518904"], ["83827.4", "0.012883"], ["83827.3", "0.012883"], ["83827", "0"], ["83826.9", "0.001333"], ["83811.1", "0"]], "a": [["83875.4", "0"], ["83880.1", "0.001466"], ["83900.5", "0"], ["83900.6", "0"], ["83900.7", "0.013"], ["83900.8", "0.012723"], ["83901.1", "0.04"], ["83901.2", "0.04"], ["83901.4", "0"], ["83901.5", "0"], ["83909.8", "0"], ["83921.1", "2.606292"], ["83942.9", "0.04"]], "u": 49866, "seq": 67553422853}, "cts": 1742561258897, "record_time": 1742561258.937233, "EXCHANGE": "BYBIT"}
{"topic": "orderbook.200.BTCUSDT", "ts": 1742561259119, "type": "delta", "data": {"s": "BTCUSDT", "b": [["83870.8", "0.480907"], ["83860.6", "0.068339"], ["83860", "0.02306"], ["83831.1", "1.134669"]], "a": [["83870.9", "0.345378"], ["83881.7", "0.024722"], ["83885.2", "0.043976"], ["83888.7", "0.058217"], ["83900.7", "0"], ["83900.8", "0"], ["83900.9", "0.013"], ["83901", "0.012723"], ["83901.1", "0"], ["83901.2", "0"], ["83901.3", "0.04"], ["83901.4", "0.04"], ["83942.9", "0"]], "u": 49867, "seq": 67553422924}, "cts": 1742561259116, "record_time": 1742561259.138171, "EXCHANGE": "BYBIT"}
{"topic": "orderbook.200.BTCUSDT", "ts": 1742561259319, "type": "delta", "data": {"s": "BTCUSDT", "b": [["83844.2", "0"], ["83828", "0.013"], ["83827.9", "0.012883"], ["83827.4", "0"], ["83827.3", "0"], ["83807.2", "0"], ["83794.9", "0.000149"], ["83793", "0.023854"]], "a": [["83875.1", "0.013269"], ["83875.2", "0"], ["83880.9", "0.021469"], ["83895.4", "0.035778"], ["83900.9", "0"], ["83901", "0"], ["83901.3", "0"], ["83901.4", "0"], ["83901.7", "0.013"], ["83901.8", "0.012723"], ["83902.1", "0.043244"], ["83902.2", "0.04"], ["83942.9", "0.04"]], "u": 49868, "seq": 67553423038}, "cts": 1742561259312, "record_time": 1742561259.337828, "EXCHANGE": "BYBIT"}
{"topic": "orderbook.200.BTCUSDT", "ts": 1742561259520, "type": "delta", "data": {"s": "BTCUSDT", "b": [["83870.8", "0.522751"], ["83835.5", "0.178846"], ["83828", "0"], ["83827.9", "0"], ["83827.7", "0.132182"], ["83827.6", "0.013216"], ["83792.7", "0.059399"]], "a": [["83870.9", "0.516378"], ["83895.4", "0"], ["83901.7", "0"], ["83901.9", "0.012723"], ["83921.1", "0"], ["83924", "2.710952"], ["83944", "0.003756"], ["83944.3", "0.011993"]], "u": 49869, "seq": 67553423158}, "cts": 1742561259512, "record_time": 1742561259.537736, "EXCHANGE": "BYBIT"}
{"topic": "orderbook.200.BTCUSDT", "ts": 1742561259720, "type": "delta", "data": {"s": "BTCUSDT", "b": [["83870.8", "0.522916"], ["83830.8", "3.511181"], ["83829.4", "0.001466"], ["83827.9", "0.013"], ["83827.8", "0.13892"], ["83827.7", "0.119299"], ["83827.6", "0.000333"], ["83813.8", "0"]], "a": [["83878.8", "0"], ["83895.5", "0.035778"], ["83901.4", "0.013"], ["83901.5", "0.012723"], ["83901.8", "0.04"], ["83901.9", "0.04"], ["83902.1", "0.003244"], ["83902.2", "0"], ["83921.1", "2.606292"], ["83924", "0.10466"], ["83944", "0"], ["83944.3", "0"]], "u": 49870, "seq": 67553423229}, "cts": 1742561259715, "record_time": 1742561259.738214, "EXCHANGE": "BYBIT"}
{"topic": "orderbook.200.BTCUSDT", "ts": 1742561259919, "type": "delta", "data": {"s": "BTCUSDT", "b": [["83870.8", "0.281855"], ["83870.2", "0"], ["83870.1", "0.0006"], ["83864.7", "0.001333"], ["83862.9", "0"], ["83862.5", "0.076417"], ["83861.3", "0.07158"], ["83860.6", "0"], ["83860.5", "0.142515"], ["83857.9", "0.071583"], ["83846", "0"], ["83835.5", "0"], ["83830.8", "0.003173"], ["83827.9", "0.012883"], ["83824", "0.000509"], ["83807", "0.099771"], ["83792.5", "0.001466"]], "a": [["83870.9", "0.737468"], ["83878.2", "0.072957"], ["83878.3", "0.059399"], ["83878.4", "0"], ["83879", "0.089099"], ["83881.3", "0"], ["83882.7", "0"], ["83883.1", "0"], ["83884.6", "0"], ["83885.2", "0.115022"], ["83889.5", "0.092343"], ["83892", "0.043576"], ["83901.3", "0.04"], ["83901.4", "0.053"], ["83901.8", "0"], ["83901.9", "0"], ["83902.8", "0.119299"], ["83907", "2.606804"], ["83921.1", "0"], ["83923.1", "0"], ["83944", "0.003756"], ["83944.3", "0.011993"], ["83944.4", "0.001333"], ["83944.5", "0.011884"]], "u": 49871, "seq": 67553423405}, "cts": 1742561259916, "record_time": 1742561259.936886, "EXCHANGE": "BYBIT"}
{"topic": "orderbook.200.BTCUSDT", "ts": 1742561260120, "type": "delta", "data": {"s": "BTCUSDT", "b": [["83870.8", "0.284528"], ["83862.4", "0.189"], ["83861.4", "0.095776"], ["83856.3", "0.090055"], ["83853.7", "0.124652"], ["83851.8", "0.006432"], ["83846.7", "0.290351"], ["83839.7", "0.29922"], ["83831.1", "0.001333"], ["83829.4", "0.180312"], ["83827.9", "0"], ["83827.8", "0.126037"], ["83827.1", "0.013358"], ["83827", "0.012883"], ["83824", "0.100282"], ["83807", "0"], ["83793", "0"], ["83792.7", "0"], ["83792.5", "0"]], "a": [["83870.9", "0.737104"], ["83878.2", "0.115767"], ["83880.5", "0.04"], ["83882.4", "0.044"], ["83883.8", "0.04"], ["83884.1", "0.04"], ["83885.2", "0.102136"], ["83885.8", "0.04"], ["83886.6", "0.493054"], ["83887", "0"], ["83887.2", "0.04"], ["83888.5", "0"], ["83893.6", "0.168161"], ["83900.6", "0.289631"], ["83900.9", "0.012723"], ["83901", "0.012723"], ["83901.4", "0.04"], ["83901.5", "0"], ["83903.6", "0.834284"], ["83907", "0.000512"], ["83909.6", "0.178846"], ["83909.8", "2.606292"], ["83912.8", "0"], ["83941.5", "0"], ["83942.1", "0"], ["83942.2", "0"], ["83942.9", "0"], ["83944", "0"], ["83944.3", "0"], ["83944.4", "0"], ["83944.5", "0"]], "u": 49872, "seq": 67553423486}, "cts": 1742561260116, "record_time": 1742561260.167737, "EXCHANGE": "BYBIT"}
{"topic": "orderbook.200.BTCUSDT", "ts": 1742561260320, "type": "delta", "data": {"s": "BTCUSDT", "b": [["83870.8", "0.314468"], ["83864.2", "0.015178"], ["83856.4", "0.059399"], ["83856.3", "0.059919"], ["83853.7", "0"], ["83851.8", "0"], ["83846.9", "0.059399"], ["83846.8", "0.099124"], ["83846.7", "0.119299"], ["83839.7", "0"], ["83830.8", "3.511181"], ["83829.4", "0.001466"], ["83827.8", "0.139037"], ["83827.7", "0.132182"], ["83827.1", "0.000358"], ["83827", "0"], ["83793", "0.023854"], ["83792.7", "0.059399"]], "a": [["83877.5", "0.012361"], ["83878.3", "0"], ["83880.7", "0.0402"], ["83882.2", "0.04009"], ["83885.2", "0.075022"], ["83885.3", "0.003244"], ["83885.5", "0.04"], ["83886.6", "0.373072"], ["83886.9", "0"], ["83887.4", "0.04"], ["83888.7", "0.018217"], ["83889.9", "0"], ["83890.4", "0"], ["83891.9", "0"], ["83892", "0.003576"], ["83893.6", "0"], ["83900.6", "0"], ["83900.7", "0.013"], ["83900.8", "0.012723"], ["83900.9", "0"], ["83901", "0"], ["83901.2", "0.04"], ["83901.4", "0"], ["83903.6", "0.065548"], ["83929.5", "0.001"], ["83931.4", "0.128436"], ["83941.5", "0.08019"], ["83942.1", "0.059399"], ["83942.2", "0.239299"]], "u": 49873, "seq": 67553423572}, "cts": 1742561260314, "record_time": 1742561260.339014, "EXCHANGE": "BYBIT"}
{"topic": "orderbook.200.BTCUSDT", "ts": 1742561260520, "type": "delta", "data": {"s": "BTCUSDT", "b": [["83846.8", "0.066989"], ["83830.9", "1.147426"], ["83829.4", "0.180312"], ["83827.8", "0.126037"], ["83827.7", "0.119299"], ["83827.5", "0.184"], ["83827.4", "0.012883"], ["83792.7", "0"]], "a": [["83882.7", "0.163651"], ["83882.8", "0.178821"], ["83885.2", "0.003976"], ["83890.2", "0"], ["83900.7", "0"], ["83900.9", "0.012723"], ["83909.6", "0"], ["83931.4", "0.003244"]], "u": 49874, "seq": 67553423631}, "cts": 1742561260508, "record_time": 1742561260.537895, "EXCHANGE": "BYBIT"}
{"topic": "orderbook.200.BTCUSDT", "ts": 1742561260719, "type": "delta", "data": {"s": "BTCUSDT", "b": [["83869.2", "0.071574"], ["83858.1", "0.120275"], ["83856.3", "0.086015"], ["83854.3", "0.111186"], ["83848.3", "0.178147"], ["83847.3", "0.167354"], ["83840.3", "0.278305"], ["83839.2", "0.280153"], ["83830.8", "3.45738"], ["83827.8", "0.13892"], ["83827.7", "0.132182"], ["83827.5", "0.171"], ["83827.4", "0"], ["83793.4", "0"], ["83793.3", "0"], ["83793.2", "0"], ["83793.1", "0"], ["83793", "0"]], "a": [["83883.3", "0.109153"], ["83886.6", "0.311988"], ["83887.2", "0.154245"], ["83893.1", "0.183057"], ["83894.2", "0.181377"], ["83900.7", "0.013"], ["83900.9", "0"], ["83901.1", "0.04"], ["83901.2", "0.348579"], ["83901.3", "0"], ["83902.2", "0.280854"], ["83941.5", "0"], ["83942.1", "0"], ["83942.2", "0"]], "u": 49875, "seq": 67553423698}, "cts": 1742561260717, "record_time": 1742561260.740265, "EXCHANGE": "BYBIT"}
{"topic": "orderbook.200.BTCUSDT", "ts": 1742561260919, "type": "delta", "data": {"s": "BTCUSDT", "b": [["83870.8", "0.284528"], ["83869.2", "0"], ["83848.4", "0.1967"], ["83846.8", "0"], ["83803.7", "0.02385"], ["83793.4", "0.001333"]], "a": [["83907.9", "0.125192"], ["83938", "0"]], "u": 49876, "seq": 67553423747}, "cts": 1742561260916, "record_time": 1742561260.9372, "EXCHANGE": "BYBIT"}
{"topic": "orderbook.200.BTCUSDT", "ts": 1742561261119, "type": "delta", "data": {"s": "BTCUSDT", "b": [["83870.8", "0.284989"], ["83870.2", "0.071573"], ["83858.1", "0"], ["83856.3", "0.059919"], ["83854.3", "0"], ["83848.3", "0"], ["83847.3", "0"], ["83840.3", "0"], ["83839.2", "0.00318"], ["83793.3", "0.029816"], ["83793.2", "0.011974"], ["83793.1", "0.004367"], ["83793", "0.023854"]], "a": [["83883.3", "0"], ["83887.2", "0.04"], ["83893.1", "0"], ["83894.2", "0.01193"], ["83901.2", "0.04"], ["83902.2", "0"], ["83941.5", "0.08019"], ["83942.1", "0.059399"], ["83942.2", "0.239299"]], "u": 49877, "seq": 67553423820}, "cts": 1742561261110, "record_time": 1742561261.216784, "EXCHANGE": "BYBIT"}
{"topic": "orderbook.200.BTCUSDT", "ts": 1742561261320, "type": "delta", "data": {"s": "BTCUSDT", "b": [["83870.8", "0.284189"], ["83861.7", "0.067625"], ["83848.4", "0.09305"], ["83827.8", "0.126037"], ["83827.6", "0.013216"]], "a": [["83875.1", "0.031661"], ["83878.2", "0.170243"], ["83881.2", "0.202529"], ["83884.5", "0.178817"], ["83900.7", "0"], ["83900.9", "0.012727"], ["83901.1", "0"], ["83901.3", "0.04"], ["83942.2", "0"]], "u": 49878, "seq": 67553423861}, "cts": 1742561261314, "record_time": 1742561261.339043, "EXCHANGE": "BYBIT"}
{"topic": "orderbook.200.BTCUSDT", "ts": 1742561261520, "type": "delta", "data": {"s": "BTCUSDT", "b": [["83870.8", "0.283728"], ["83870.2", "0"], ["83869.2", "0.071574"], ["83858.6", "0.006394"], ["83858.5", "0"], ["83829.9", "0.0016"], ["83829.8", "0"], ["83827.7", "0.119299"], ["83827.6", "0.000333"], ["83827.3", "0.012883"], ["83827.2", "0.012883"], ["83793", "0"]], "a": [["83870.9", "0.707014"], ["83879", "0"], ["83942.2", "0.239299"]], "u": 49879, "seq": 67553423919}, "cts": 1742561261502, "record_time": 1742561261.547849, "EXCHANGE": "BYBIT"}
{"topic": "orderbook.200.BTCUSDT", "ts": 1742561261720, "type": "delta", "data": {"s": "BTCUSDT", "b": [["83870.8", "0.295767"], ["83869.8", "0.071573"], ["83869.2", "0"], ["83859", "0.071583"], ["83858.1", "0.11821"], ["83857.9", "0"], ["83854.3", "0.109692"], ["83848.3", "0.180976"], ["83847.3", "0.165728"], ["83840.3", "0.293981"], ["83839.2", "0.275039"], ["83830.8", "3.501657"], ["83793.7", "0"], ["83793.4", "0"], ["83793.3", "0"], ["83793.2", "0"], ["83793.1", "0"]], "a": [["83883.3", "0.112788"], ["83887.2", "0.154951"], ["83893.1", "0.187098"], ["83894.2", "0.190264"], ["83900.8", "0"], ["83900.9", "0"], ["83901", "0.012727"], ["83901.1", "0.012727"], ["83901.2", "0.292522"], ["83901.3", "0"], ["83901.4", "0.04"], ["83901.5", "0.04"], ["83902.2", "0.305582"], ["83902.8", "0"], ["83941.5", "0"], ["83942.1", "0"], ["83942.2", "0"]], "u": 49880, "seq": 67553424041}, "cts": 1742561261716, "record_time": 1742561261.738953, "EXCHANGE": "BYBIT"}
{"topic": "orderbook.200.BTCUSDT", "ts": 1742561261920, "type": "delta", "data": {"s": "BTCUSDT", "b": [["83856.3", "0.085567"], ["83848.4", "0.18543"]], "a": [["83875.1", "0.013269"], ["83882.7", "0.230676"], ["83908", "0.923936"], ["83909.8", "0"], ["83921.1", "2.606292"]], "u": 49881, "seq": 67553424087}, "cts": 1742561261915, "record_time": 1742561261.940902, "EXCHANGE": "BYBIT"}
{"topic": "orderbook.200.BTCUSDT", "ts": 1742561262119, "type": "delta", "data": {"s": "BTCUSDT", "b": [["83870.8", "0.29595"], ["83827.8", "0.139037"], ["83827.7", "0.132182"], ["83827.3", "0"], ["83827.2", "0"], ["83793.7", "0.089099"], ["83793.4", "0.001333"]], "a": [["83908", "0.162341"], ["83909.8", "2.606292"], ["83921.1", "0"]], "u": 49882, "seq": 67553424134}, "cts": 1742561262097, "record_time": 1742561262.137342, "EXCHANGE": "BYBIT"}
{"topic": "orderbook.200.BTCUSDT", "ts": 1742561262320, "type": "delta", "data": {"s": "BTCUSDT", "b": [], "a": [["83900.9", "0.013"], ["83901.1", "0"]], "u": 49883, "seq": 67553424172}, "cts": 1742561262314, "record_time": 1742561262.338435, "EXCHANGE": "BYBIT"}
{"topic": "orderbook.200.BTCUSDT", "ts": 1742561262519, "type": "delta", "data": {"s": "BTCUSDT", "b": [["83870.8", "0.284711"], ["83869.8", "0"], ["83861.3", "0"], ["83858.1", "0"], ["83856.3", "0.059919"], ["83856.1", "0.071585"], ["83854.3", "0"], ["83848.3", "0"], ["83847.3", "0"], ["83840.3", "0"], ["83839.2", "0.00318"], ["83827.8", "0.126037"], ["83827.7", "0.119299"], ["83827.2", "0.013"], ["83827.1", "0.013241"], ["83793.3", "0.029816"], ["83793.2", "0.011974"], ["83793.1", "0.004367"], ["83793", "0.023854"], ["83792.7", "0.059399"]], "a": [["83883.3", "0"], ["83887.2", "0.04"], ["83893.1", "0"], ["83894.2", "0.01193"], ["83900.9", "0"], ["83901", "0"], ["83901.1", "0.012727"], ["83901.2", "0.012727"], ["83901.4", "0"], ["83901.6", "0.04"], ["83902.2", "0"], ["83902.8", "0.119299"], ["83941.5", "0.08019"], ["83942.1", "0.059399"], ["83942.2", "0.239299"]], "u": 49884, "seq": 67553424264}, "cts": 1742561262513, "record_time": 1742561262.539967, "EXCHANGE": "BYBIT"}
{"topic": "orderbook.200.BTCUSDT", "ts": 1742561262720, "type": "delta", "data": {"s": "BTCUSDT", "b": [["83870.8", "0.284403"], ["83868.8", "0.071574"], ["83861.3", "0.071581"], ["83858.3", "0.113132"], ["83856.3", "0.08914"], ["83856.1", "0"], ["83854.2", "0.121604"], ["83848.4", "0.09305"], ["83847.8", "0.186322"], ["83847.2", "0.184643"], ["83840.8", "0.294998"], ["83840.2", "0.275916"], ["83830.8", "3.547344"], ["83828", "0.012883"], ["83827.9", "0.012883"], ["83827.2", "0"], ["83827.1", "0.000358"], ["83793.7", "0"], ["83793.4", "0"], ["83793.3", "0"], ["83793.2", "0"], ["83793.1", "0"], ["83793", "0"], ["83792.7", "0"]], "a": [["83882.8", "0.301013"], ["83887.1", "0.12146"], ["83893.3", "0.199516"], ["83894.1", "0.18844"], ["83900.3", "0.283225"], ["83900.8", "0.012727"], ["83900.9", "0.012727"], ["83901.1", "0.285105"], ["83901.2", "0"], ["83909.8", "0"], ["83921.1", "2.606292"], ["83941.5", "0"], ["83942.1", "0"], ["83942.2", "0"]], "u": 49885, "seq": 67553424340}, "cts": 1742561262701, "record_time": 1742561262.790192, "EXCHANGE": "BYBIT"}
{"topic": "orderbook.200.BTCUSDT", "ts": 1742561262920, "type": "delta", "data": {"s": "BTCUSDT", "b": [["83868.8", "0"], ["83861.6", "0.07158"], ["83861.3", "0"], ["83858.3", "0"], ["83856.7", "0.098222"], ["83856.3", "0.001843"], ["83854.2", "0"], ["83848.4", "0.192708"], ["83847.8", "0"], ["83847.2", "0"], ["83840.8", "0"], ["83840.2", "0.000333"], ["83793.7", "0.089099"], ["83793.4", "0.001333"], ["83793.3", "0.029816"], ["83793.2", "0.011974"], ["83793.1", "0.004367"], ["83793", "0.023854"]], "a": [["83882.8", "0.178821"], ["83887.1", "0"], ["83892", "0"], ["83893.3", "0.02464"], ["83894.1", "0.011884"], ["83900.3", "0"], ["83901.1", "0"], ["83929.5", "0"], ["83941.5", "0.08019"], ["83942.1", "0.059399"], ["83942.2", "0.239299"], ["83942.9", "0.04"], ["83944", "0.003756"]], "u": 49886, "seq": 67553424433}, "cts": 1742561262902, "record_time": 1742561262.938682, "EXCHANGE": "BYBIT"}
{"topic": "orderbook.200.BTCUSDT", "ts": 1742561263120, "type": "delta", "data": {"s": "BTCUSDT", "b": [["83848.4", "0.09305"], ["83828.1", "0.013"], ["83827.9", "0"], ["83818.8", "0.12885"], ["83793", "0"]], "a": [["83918.3", "2.620124"], ["83921.1", "0"], ["83944.3", "0.011993"]], "u": 49887, "seq": 67553424475}, "cts": 1742561263104, "record_time": 1742561263.137115, "EXCHANGE": "BYBIT"}
{"topic": "orderbook.200.BTCUSDT", "ts": 1742561263319, "type": "delta", "data": {"s": "BTCUSDT", "b": [["83828.1", "0"], ["83827.9", "0.012883"], ["83818.9", "0.17892"], ["83817.9", "0.011931"], ["83793.1", "0"]], "a": [["83895.2", "0.003576"], ["83895.6", "0.001036"], ["83901.2", "0.04"], ["83901.3", "0.04"], ["83901.5", "0"], ["83901.6", "0"], ["83944", "0"], ["83944.3", "0"]], "u": 49888, "seq": 67553424516}, "cts": 1742561263317, "record_time": 1742561263.336901, "EXCHANGE": "BYBIT"}
{"topic": "orderbook.200.BTCUSDT", "ts": 1742561263519, "type": "delta", "data": {"s": "BTCUSDT", "b": [["83828", "0.013"]], "a": [["83895.6", "0"], ["83900.7", "0.013"], ["83900.9", "0"], ["83901.1", "0.04"], ["83901.3", "0"], ["83944", "0.003756"]], "u": 49889, "seq": 67553424536}, "cts": 1742561263516, "record_time": 1742561263.54192, "EXCHANGE": "BYBIT"}
{"topic": "orderbook.200.BTCUSDT", "ts": 1742561263720, "type": "delta", "data": {"s": "BTCUSDT", "b": [["83830.8", "0.003173"], ["83828", "0"], ["83827.8", "0.13892"], ["83822.4", "3.577694"], ["83793.1", "0.004367"]], "a": [["83900.7", "0"], ["83900.9", "0.012727"], ["83901.1", "0"], ["83901.3", "0.04"], ["83915.5", "2.606292"], ["83918.3", "0.013832"], ["83944", "0"]], "u": 49890, "seq": 67553424583}, "cts": 1742561263716, "record_time": 1742561263.738298, "EXCHANGE": "BYBIT"}
{"topic": "orderbook.200.BTCUSDT", "ts": 1742561263919, "type": "delta", "data": {"s": "BTCUSDT", "b": [["83867.8", "0.071575"], ["83862.5", "0.047162"], ["83862.4", "0.018"], ["83857.9", "0.116226"], ["83856.7", "0.000298"], ["83856.4", "0"], ["83855.4", "0.05712"], ["83848.1", "0.166843"], ["83839", "0.271747"], ["83830.9", "0.152507"], ["83830.8", "3.577694"], ["83822.4", "0.003173"], ["83793.4", "0"], ["83793.3", "0"], ["83793.2", "0"], ["83793.1", "0"]], "a": [["83871.4", "0.000153"], ["83883.1", "0.119617"], ["83892.9", "0.179367"], ["83902", "0.296809"], ["83941.5", "0"], ["83942.1", "0"], ["83942.2", "0"], ["83942.9", "0"]], "u": 49891, "seq": 67553424637}, "cts": 1742561263899, "record_time": 1742561263.937188, "EXCHANGE": "BYBIT"}
{"topic": "orderbook.200.BTCUSDT", "ts": 1742561264120, "type": "delta", "data": {"s": "BTCUSDT", "b": [["83867.8", "0"], ["83862.5", "0.092566"], ["83862.4", "0.189"], ["83857.9", "0"], ["83855.5", "0.059399"], ["83848.4", "0.131471"], ["83848.1", "0"], ["83839", "0"], ["83793.4", "0.001333"], ["83793.3", "0.029816"], ["83793.2", "0.011974"]], "a": [["83870.9", "0.706975"], ["83871.4", "0"], ["83883.1", "0"], ["83891.4", "0.003"], ["83892.9", "0"], ["83900.8", "0"], ["83900.9", "0"], ["83901.1", "0.013"], ["83901.2", "0.012727"], ["83901.3", "0"], ["83901.5", "0.04"], ["83901.6", "0.04"], ["83902", "0"], ["83908.1", "0"], ["83941.5", "0.08019"], ["83942.1", "0.059399"], ["83942.2", "0.239299"], ["83942.9", "0.04"]], "u": 49892, "seq": 67553424729}, "cts": 1742561264116, "record_time": 1742561264.140583, "EXCHANGE": "BYBIT"}
{"topic": "orderbook.200.BTCUSDT", "ts": 1742561264320, "type": "delta", "data": {"s": "BTCUSDT", "b": [["83869.6", "0.071573"], ["83862.5", "0.047162"], ["83848.4", "0.09305"], ["83828.1", "0.013"], ["83828", "0.012883"], ["83827.9", "0"], ["83827.8", "0.126037"], ["83793.3", "0"], ["83793.2", "0"]], "a": [["83893", "0.001018"], ["83901", "0.013"], ["83901.1", "0.012727"], ["83901.2", "0"], ["83904.1", "0.140108"], ["83908", "0.120056"], ["83942.2", "0"], ["83942.9", "0"]], "u": 49893, "seq": 67553424786}, "cts": 1742561264310, "record_time": 1742561264.362742, "EXCHANGE": "BYBIT"}
{"topic": "orderbook.200.BTCUSDT", "ts": 1742561264520, "type": "delta", "data": {"s": "BTCUSDT", "b": [["83869.6", "0"], ["83862.5", "0.092566"], ["83828.1", "0.012883"], ["83793.3", "0.029816"]], "a": [["83892.9", "0.000998"], ["83893", "0"], ["83893.2", "0.001574"], ["83901", "0"], ["83901.2", "0.012727"]], "u": 49894, "seq": 67553424855}, "cts": 1742561264487, "record_time": 1742561264.53975, "EXCHANGE": "BYBIT"}
{"topic": "orderbook.200.BTCUSDT", "ts": 1742561264720, "type": "delta", "data": {"s": "BTCUSDT", "b": [["83870.8", "0.355975"], ["83863.7", "0.071578"], ["83861.7", "0.055691"], ["83861.4", "0.052827"], ["83859", "0"], ["83830.8", "3.608236"], ["83798.6", "0.235392"], ["83798.5", "0"]], "a": [["83892.9", "0"], ["83893.2", "0.000512"], ["83915.5", "0"], ["83924", "2.710952"], ["83927.4", "0.354255"], ["83928.3", "0.000333"], ["83942.2", "0.239299"]], "u": 49895, "seq": 67553424923}, "cts": 1742561264706, "record_time": 1742561264.737836, "EXCHANGE": "BYBIT"}
{"topic": "orderbook.200.BTCUSDT", "ts": 1742561264920, "type": "delta", "data": {"s": "BTCUSDT", "b": [], "a": [["83921.1", "2.606292"], ["83924", "0.10466"], ["83942.2", "0"]], "u": 49896, "seq": 67553424955}, "cts": 1742561264906, "record_time": 1742561264.940424, "EXCHANGE": "BYBIT"}
{"topic": "orderbook.200.BTCUSDT", "ts": 1742561265120, "type": "delta", "data": {"s": "BTCUSDT", "b": [["83830.9", "1.2261"]], "a": [["83874.2", "0.000078"], ["83895.2", "0"], ["83901", "0.013"], ["83901.2", "0"], ["83901.4", "0.04"], ["83901.6", "0"], ["83918.3", "2.620124"], ["83921.1", "0"], ["83942.2", "0.239299"]], "u": 49897, "seq": 67553424987}, "cts": 1742561265117, "record_time": 1742561265.137682, "EXCHANGE": "BYBIT"}
{"topic": "orderbook.200.BTCUSDT", "ts": 1742561265320, "type": "delta", "data": {"s": "BTCUSDT", "b": [["83870.8", "0.355803"]], "a": [["83900.9", "0.012727"], ["83901", "0.012727"], ["83901.1", "0"], ["83901.3", "0.04"], ["83901.5", "0"], ["83904.1", "0"], ["83942.9", "0.04"]], "u": 49898, "seq": 67553425020}, "cts": 1742561265291, "record_time": 1742561265.414066, "EXCHANGE": "BYBIT"}
{"topic": "orderbook.200.BTCUSDT", "ts": 1742561265520, "type": "delta", "data": {"s": "BTCUSDT", "b": [["83870.8", "0.284231"], ["83869.8", "0.071573"], ["83793.3", "0"]], "a": [["83875.1", "0.068972"], ["83878.2", "0.349089"], ["83900.8", "0.013"], ["83901", "0"], ["83901.2", "0.04"], ["83901.4", "0"], ["83904.1", "0.139807"], ["83931.2", "0.04"], ["83942.2", "0"], ["83942.9", "0"]], "u": 49899, "seq": 67553425069}, "cts": 1742561265508, "record_time": 1742561265.537596, "EXCHANGE": "BYBIT"}
{"topic": "orderbook.200.BTCUSDT", "ts": 1742561265719, "type": "delta", "data": {"s": "BTCUSDT", "b": [["83870.8", "0.282192"], ["83863.7", "0"], ["83862.5", "0.088986"], ["83859.4", "0.071582"], ["83830.8", "3.646686"], ["83828.2", "0.013"], ["83828", "0"]], "a": [["83874.2", "0"], ["83875.7", "0.02147"], ["83880.9", "0"], ["83900.8", "0"], ["83900.9", "0.013"], ["83901", "0.012727"], ["83901.2", "0"], ["83901.4", "0.04"], ["83903.6", "0.094338"], ["83909.8", "2.606292"], ["83918.3", "0.013832"]], "u": 49900, "seq": 67553425127}, "cts": 1742561265708, "record_time": 1742561265.737677, "EXCHANGE": "BYBIT"}
{"topic": "orderbook.200.BTCUSDT", "ts": 1742561265920, "type": "delta", "data": {"s": "BTCUSDT", "b": [["83862.5", "0.047162"], ["83862.4", "0.018"], ["83803.7", "1.812314"]], "a": [["83873.2", "0.000153"], ["83938", "1.788464"], ["83941.5", "0"], ["83942.1", "0"]], "u": 49901, "seq": 67553425161}, "cts": 1742561265897, "record_time": 1742561265.937613, "EXCHANGE": "BYBIT"}
{"topic": "orderbook.200.BTCUSDT", "ts": 1742561266119, "type": "delta", "data": {"s": "BTCUSDT", "b": [["83863.6", "0.071579"], ["83862.5", "0.088986"], ["83862.4", "0.189"], ["83861.6", "0"]], "a": [["83870.9", "0.712975"], ["83891.4", "0"], ["83902.8", "0"], ["83904.1", "0"], ["83941.5", "0.08019"], ["83942.1", "0.059399"], ["83942.2", "0.239299"]], "u": 49902, "seq": 67553425223}, "cts": 1742561266116, "record_time": 1742561266.137121, "EXCHANGE": "BYBIT"}
{"topic": "orderbook.200.BTCUSDT", "ts": 1742561266320, "type": "delta", "data": {"s": "BTCUSDT", "b": [], "a": [["83902.8", "0.119299"], ["83903.6", "0.065548"], ["83904.5", "0.139649"], ["83942.1", "0"], ["83942.2", "0"]], "u": 49903, "seq": 67553425260}, "cts": 1742561266309, "record_time": 1742561266.338293, "EXCHANGE": "BYBIT"}
{"topic": "orderbook.200.BTCUSDT", "ts": 1742561266520, "type": "delta", "data": {"s": "BTCUSDT", "b": [["83837.6", "0"], ["83793.3", "0.029816"]], "a": [["83874.5", "0.0002"], ["83880.7", "0.04"], ["83941.5", "0"]], "u": 49904, "seq": 67553425292}, "cts": 1742561266516, "record_time": 1742561266.537175, "EXCHANGE": "BYBIT"}
{"topic": "orderbook.200.BTCUSDT", "ts": 1742561266720, "type": "delta", "data": {"s": "BTCUSDT", "b": [["83870.8", "0.281392"], ["83869.8", "0"], ["83868.4", "0.071574"], ["83863.7", "0.043581"], ["83863.6", "0"], ["83862.5", "0"], ["83862.4", "0.018"], ["83861.8", "0.07158"], ["83830.8", "3.662109"]], "a": [["83870.9", "0.718975"], ["83873.2", "0"], ["83909.8", "0"], ["83918.3", "2.620124"], ["83941.5", "0.08019"], ["83942.1", "0.059399"]], "u": 49905, "seq": 67553425352}, "cts": 1742561266715, "record_time": 1742561266.737714, "EXCHANGE": "BYBIT"}
{"topic": "orderbook.200.BTCUSDT", "ts": 1742561266919, "type": "delta", "data": {"s": "BTCUSDT", "b": [["83870.8", "0.278536"], ["83868.7", "0.071574"], ["83868.4", "0"], ["83857.5", "0.0002"], ["83828.2", "0"], ["83828.1", "0"], ["83827.8", "0.139037"], ["83827.7", "0.132182"], ["83793.2", "0.011974"]], "a": [["83900.9", "0"], ["83901", "0"], ["83901.1", "0.012727"], ["83901.2", "0.012727"], ["83901.3", "0"], ["83901.4", "0"], ["83901.5", "0.04"], ["83901.6", "0.04"]], "u": 49906, "seq": 67553425442}, "cts": 1742561266916, "record_time": 1742561266.988472, "EXCHANGE": "BYBIT"}
{"topic": "orderbook.200.BTCUSDT", "ts": 1742561267119, "type": "delta", "data": {"s": "BTCUSDT", "b": [["83868.7", "0"], ["83863.7", "0.040818"], ["83863.5", "0.071579"], ["83861.8", "0"], ["83793.1", "0.004367"]], "a": [["83871.8", "0.000078"], ["83901.1", "0.052727"], ["83901.2", "0.052727"], ["83901.5", "0"], ["83901.6", "0"], ["83942.2", "0.239299"]], "u": 49907, "seq": 67553425495}, "cts": 1742561267117, "record_time": 1742561267.137047, "EXCHANGE": "BYBIT"}
{"topic": "orderbook.200.BTCUSDT", "ts": 1742561267320, "type": "delta", "data": {"s": "BTCUSDT", "b": [], "a": [["83900.9", "0.013"], ["83901", "0.012727"], ["83901.1", "0"], ["83901.2", "0"], ["83901.3", "0.04"], ["83901.4", "0.04"], ["83942.1", "0"], ["83942.2", "0"]], "u": 49908, "seq": 67553425519}, "cts": 1742561267291, "record_time": 1742561267.337677, "EXCHANGE": "BYBIT"}
{"topic": "orderbook.200.BTCUSDT", "ts": 1742561267519, "type": "delta", "data": {"s": "BTCUSDT", "b": [["83870.8", "0"], ["83870.7", "0"], ["83870.1", "0"], ["83867.1", "0"], ["83866", "0"], ["83864.2", "0.003679"], ["83863.7", "0"], ["83863.5", "0"], ["83862.4", "0.008"], ["83861.4", "0"], ["83860.5", "0.001333"], ["83860.4", "0"], ["83860", "0.00006"], ["83858.9", "0.01"], ["83856.9", "0.071584"], ["83855.5", "0"], ["83852.4", "0"], ["83852.1", "0.001333"], ["83851.6", "0"], ["83851.3", "0.008427"], ["83849.2", "0.171"], ["83848.4", "0"], ["83848", "0.05726"], ["83846.9", "0"], ["83846.7", "0"], ["83830.9", "1.137001"], ["83830.8", "0.003173"], ["83829.4", "0.001466"], ["83827.8", "0.126037"], ["83827.7", "0.119299"], ["83825.9", "0.013"], ["83825.8", "0.012882"], ["83824", "0.000509"], ["83793", "0.023854"], ["83792.7", "0.059399"], ["83792.5", "0.001466"], ["83791.7", "0.00051"], ["83789.9", "0.119679"], ["83789.2", "0.001333"], ["83788.9", "0.003178"], ["83787.9", "0.001466"]], "a": [["83865.6", "0.1"], ["83866.1", "1.003407"], ["83866.4", "0.021473"], ["83866.9", "0.035771"], ["83867.1", "0.172889"], ["83867.2", "0.032494"], ["83867.4", "0.23719"], ["83867.7", "0.091356"], ["83870.7", "0.248179"], ["83870.9", "0.518614"], ["83871.8", "0"], ["83872.7", "0.024715"], ["83874.5", "0.0052"], ["83874.6", "0"], ["83875.1", "0"], ["83875.7", "0"], ["83877.4", "0"], ["83877.5", "0"], ["83877.6", "0.018745"], ["83878.2", "0"], ["83879.3", "0.01"], ["83881.2", "0.023705"], ["83881.7", "0"], ["83882.7", "0.067025"], ["83882.8", "0"], ["83884.5", "0"], ["83885.2", "0"], ["83886.5", "0.059399"], ["83888.7", "0"], ["83890.1", "0.0006"], ["83896.2", "0.119299"], ["83900.9", "0.012727"], ["83902.7", "0.119299"], ["83902.8", "0"], ["83907.9", "1.078564"], ["83911", "0.476686"], ["83912.4", "0.001466"], ["83941", "0"], ["83941.5", "0"]], "u": 49909, "seq": 67553426229}, "cts": 1742561267517, "record_time": 1742561267.537873, "EXCHANGE": "BYBIT"}
{"topic": "orderbook.200.BTCUSDT", "ts": 1742561267720, "type": "delta", "data": {"s": "BTCUSDT", "b": [["83865.5", "0"], ["83865.4", "0"], ["83864.7", "0"], ["83864.3", "0"], ["83864.2", "0"], ["83862.4", "0"], ["83861.7", "0"], ["83861.2", "0"], ["83860.9", "0"], ["83860.5", "0"], ["83860.1", "0"], ["83860", "0"], ["83859.4", "0"], ["83858.9", "0"], ["83858.6", "0"], ["83857.5", "0"], ["83857.1", "0.002505"], ["83856.9", "0"], ["83856.7", "0"], ["83855.4", "0"], ["83855.3", "0"], ["83854.9", "0"], ["83854.5", "0"], ["83853.8", "0"], ["83853.2", "0"], ["83852.9", "0"], ["83852.2", "0"], ["83852", "0"], ["83851.5", "0"], ["83851.3", "0"], ["83851.2", "0"], ["83850.7", "0.034777"], ["83850.6", "0.053625"], ["83849.7", "0"], ["83849.2", "0"], ["83849.1", "0.01"], ["83848", "0"], ["83847.9", "0.002799"], ["83847", "0"], ["83846.6", "0"], ["83845.6", "0.059399"], ["83845.1", "0"], ["83844.3", "0.071595"], ["83844.1", "0"], ["83843.9", "0.003893"], ["83843.1", "0"], ["83842.6", "0.04"], ["83841.6", "0"], ["83840.5", "0.0513"], ["83840.2", "0.038747"], ["83840.1", "0.044"], ["83839.5", "0.001333"], ["83839.4", "0"], ["83838.5", "0.019007"], ["83836.5", "0"], ["83835.9", "0.085761"], ["83835.6", "0"], ["83833.9", "0"], ["83832.5", "0"], ["83831", "0"], ["83830.9", "0"], ["83825.9", "0"], ["83825.8", "0"], ["83824.5", "0"], ["83823", "0.555521"], ["83822", "0.004643"], ["83820.1", "0.509938"], ["83818.8", "0"], ["83814.1", "0"], ["83796.1", "0"], ["83795.7", "0.099807"], ["83791.6", "0.171"], ["83787.2", "3.705055"], ["83787.1", "0.00051"], ["83786.8", "0.04"], ["83786.7", "0.119299"], ["83786.5", "0.0492"], ["83785.7", "0.000333"], ["83785.4", "0.011993"], ["83785.3", "0.011993"], ["83785.2", "0.087979"], ["83785.1", "0.011993"], ["83785", "0.001333"], ["83784.8", "0.012083"], ["83784.7", "0.003178"], ["83784.6", "0.01872"], ["83784.5", "0.0381"], ["83784.4", "0.044"], ["83784.3", "0.044154"], ["83784.2", "0.048"], ["83783.4", "0.052332"], ["83783.3", "0.001466"], ["83782.9", "0.000358"], ["83782.5", "0.00051"], ["83781.7", "0.052"], ["83781.6", "0.015333"], ["83781.5", "0.119299"], ["83780.8", "0.001333"], ["83780.5", "0.003775"], ["83779", "0.205131"], ["83778.8", "0.023758"], ["83778.7", "0.001466"], ["83777.9", "0.00051"], ["83777.4", "0.000333"], ["83777", "0.0006"], ["83776.6", "0.001333"], ["83776.5", "0.059399"], ["83776.4", "0.131273"], ["83776.3", "0.003174"], ["83775.8", "0.018587"]], "a": [["83857.2", "1.017296"], ["83857.6", "0.071565"], ["83859", "0.22109"], ["83860", "0.00024"], ["83862.4", "0.184728"], ["83862.5", "0.242564"], ["83864.2", "0.021473"], ["83864.3", "0.003193"], ["83864.4", "0.06009"], ["83864.7", "0.001333"], ["83865.4", "0.000333"], ["83865.5", "0.000512"], ["83865.6", "0.05009"], ["83866", "0.054443"], ["83866.1", "0.128333"], ["83866.3", "0.001466"], ["83866.4", "0"], ["83866.9", "0"], ["83867.1", "0"], ["83867.2", "0"], ["83867.4", "0.024905"], ["83867.7", "0"], ["83868.5", "0.003193"], ["83868.9", "0.001333"], ["83869.6", "0.000333"], ["83869.7", "0.021914"], ["83870.1", "0.000512"], ["83870.7", "0"], ["83870.8", "0.073854"], ["83870.9", "0.2223"], ["83871.1", "0"], ["83871.8", "0.04"], ["83872.4", "0.003976"], ["83872.7", "0.003244"], ["83873.8", "0.000423"], ["83874.4", "0.068345"], ["83875.5", "0.092822"], ["83876.1", "0.009243"], ["83876.5", "0.0445"], ["83878.2", "0.04"], ["83878.5", "0.04"], ["83879.3", "0"], ["83880", "0.00024"], ["83881.2", "0.00018"], ["83881.7", "0.0006"], ["83881.9", "0"], ["83883.4", "0.497581"], ["83884.1", "0"], ["83885.4", "0"], ["83886", "0.0006"], ["83887.2", "0"], ["83887.4", "0"], ["83888.9", "0"], ["83889.6", "0.562549"], ["83896.4", "0"], ["83897.4", "0.063478"], ["83898.5", "0.003564"], ["83899", "1.430148"], ["83900", "0.3276"], ["83902.9", "0"], ["83905", "0"], ["83905.9", "0"], ["83907.8", "0.588097"], ["83907.9", "0.125192"], ["83908", "0"], ["83908.6", "0.082425"], ["83911", "0"], ["83912.3", "0"], ["83914.9", "0"], ["83918.3", "0"], ["83920", "0.00024"], ["83928.5", "0.013106"], ["83929.6", "1.792422"], ["83931.4", "0.030984"], ["83932.2", "0"], ["83935.9", "0"], ["83936", "0"], ["83936.5", "0"], ["83936.7", "0"], ["83937", "0"], ["83937.1", "0"], ["83938", "0"], ["83939.4", "0"], ["83939.8", "0"], ["83940.1", "0"], ["83940.2", "0"], ["83940.9", "0"]], "u": 49910, "seq": 67553427334}, "cts": 1742561267717, "record_time": 1742561267.7414, "EXCHANGE": "BYBIT"}
{"topic": "orderbook.200.BTCUSDT", "ts": 1742561267919, "type": "delta", "data": {"s": "BTCUSDT", "b": [["83857.1", "0.502751"], ["83856.2", "0.000119"], ["83851.9", "0.068492"], ["83851.8", "0.071589"], ["83850.7", "0"], ["83849.2", "0.089099"], ["83848.8", "0"], ["83848.7", "0.005"], ["83848.1", "0.045192"], ["83848", "0.071592"], ["83846.6", "0.052"], ["83844.6", "0.160082"], ["83844.5", "0.119299"], ["83844.3", "0"], ["83842.9", "0.04"], ["83841.2", "0.191306"], ["83841", "0.04"], ["83840.5", "0"], ["83840.3", "0.021714"], ["83840.2", "0.374527"], ["83840", "0.556004"], ["83838.5", "0.108106"], ["83837.9", "0.023762"], ["83837.6", "0.044"], ["83837.1", "0.509938"], ["83836.6", "0.009608"], ["83834.9", "0.0002"], ["83823", "0"], ["83820.1", "0"], ["83814.2", "0"], ["83814.1", "0.012883"], ["83814", "0.016056"], ["83812.6", "0.099774"], ["83808.5", "0"], ["83807.4", "0.014069"], ["83805.4", "3.673941"], ["83795.7", "0"], ["83784.5", "0.011993"], ["83783.2", "0.171"], ["83781.6", "0"], ["83781.5", "0"], ["83780.8", "0"], ["83780.5", "0"], ["83779", "0"], ["83778.8", "0"], ["83778.7", "0"], ["83777.9", "0"], ["83777.4", "0"], ["83777", "0"], ["83776.6", "0"], ["83776.5", "0"], ["83776.4", "0"], ["83776.3", "0"], ["83775.8", "0"]], "a": [["83857.2", "0.180785"], ["83857.6", "0"], ["83859", "0"], ["83861.9", "0.021474"], ["83862.4", "0"], ["83862.5", "0.191"], ["83864.2", "0"], ["83864.3", "0.026788"], ["83864.4", "0.03"], ["83865.6", "0.025"], ["83866", "0.020391"], ["83866.1", "0.02"], ["83867.4", "0.01"], ["83869.5", "0.031204"], ["83870.9", "0.19221"], ["83871.5", "0.04"], ["83873.2", "0.04"], ["83873.4", "0.044"], ["83874.5", "0.0002"], ["83875.5", "0.001466"], ["83876.8", "0.04"], ["83880.2", "0.000994"], ["83880.7", "0"], ["83882.4", "0"], ["83883.4", "0"], ["83886.5", "0"], ["83889.5", "0.062643"], ["83895.6", "0.497581"], ["83896.2", "0"], ["83897.4", "0"], ["83900", "0.089557"], ["83900.2", "0.063482"], ["83900.8", "0.014088"], ["83907.8", "0.001466"], ["83931.4", "0.156197"], ["83934.5", "0.044838"]], "u": 49911, "seq": 67553427636}, "cts": 1742561267917, "record_time": 1742561267.937466, "EXCHANGE": "BYBIT"}
{"topic": "orderbook.200.BTCUSDT", "ts": 1742561268119, "type": "delta", "data": {"s": "BTCUSDT", "b": [["83857.1", "0.673751"], ["83851.9", "0.041672"], ["83849.2", "0"], ["83841.5", "0.003"], ["83840.2", "0.377159"], ["83839.3", "0.044"], ["83837.9", "0.075762"], ["83823.7", "0.035783"], ["83822.5", "0.144023"], ["83812.6", "0"], ["83809.8", "0.126816"], ["83806.9", "0"], ["83806.8", "1.719462"], ["83806.5", "0"], ["83805.4", "0"], ["83786.5", "0.0045"], ["83784.3", "0"], ["83782.1", "0.125213"], ["83781.6", "0.015333"], ["83781.5", "0.119299"]], "a": [["83861.9", "0"], ["83864.3", "0.003193"], ["83867", "0.021472"], ["83869.4", "0.021472"], ["83869.5", "0"], ["83869.7", "0"], ["83870.5", "0.000078"], ["83870.8", "0.107418"], ["83871.5", "0.063645"], ["83873.9", "0.009822"], ["83875", "0.000994"], ["83876.7", "0.04"], ["83878.4", "0.038698"], ["83880.2", "0.021005"], ["83880.5", "0"], ["83882.2", "0.00009"], ["83885.8", "0"], ["83889.6", "0"], ["83893.2", "0.00516"], ["83900.2", "0"], ["83902.7", "0"], ["83903", "0.06348"], ["83904.5", "0.702198"], ["83906.5", "0.02828"], ["83934.5", "0"], ["83935.3", "0.04406"]], "u": 49912, "seq": 67553427841}, "cts": 1742561268117, "record_time": 1742561268.136901, "EXCHANGE": "BYBIT"}
{"topic": "orderbook.200.BTCUSDT", "ts": 1742561268320, "type": "delta", "data": {"s": "BTCUSDT", "b": [["83857.1", "0.685778"], ["83849.3", "0.009608"], ["83846.6", "0"], ["83836.6", "0"], ["83806.8", "0.05624"], ["83800", "0.174959"], ["83781.2", "0.0003"]], "a": [["83857.2", "0.178395"], ["83860.1", "0.021474"], ["83862.5", "0"], ["83866", "0.021473"], ["83867", "0"], ["83867.6", "0.021472"], ["83869.4", "0"], ["83871.5", "0"], ["83871.8", "0"], ["83873.2", "0"], ["83873.4", "0"], ["83875.1", "0.04"], ["83876.7", "0"], ["83876.8", "0"], ["83878.2", "0"], ["83878.4", "0.020701"], ["83878.5", "0"], ["83885.5", "0"], ["83886.6", "0.171"], ["83900.2", "0.06348"], ["83903", "0"], ["83904.4", "0.143145"], ["83924", "2.711085"], ["83935.3", "0"], ["83935.9", "0.04"], ["83936", "0.001333"], ["83936.5", "0.0045"], ["83936.7", "0.000333"], ["83937.1", "0.011992"], ["83938", "1.788464"], ["83938.7", "0.045013"], ["83939.4", "0.000512"], ["83939.8", "0.015236"], ["83940.1", "0.001466"]], "u": 49913, "seq": 67553428040}, "cts": 1742561268317, "record_time": 1742561268.338072, "EXCHANGE": "BYBIT"}
{"topic": "orderbook.200.BTCUSDT", "ts": 1742561268520, "type": "delta", "data": {"s": "BTCUSDT", "b": [["83857.1", "0"], ["83857", "0"], ["83856.3", "0"], ["83856.2", "0"], ["83855.9", "0"], ["83852.8", "0"], ["83852.5", "0"], ["83852.1", "0"], ["83851.9", "0"], ["83851.8", "0"], ["83851.7", "0"], ["83850.6", "0"], ["83849.3", "0"], ["83849.1", "0"], ["83848.1", "0"], ["83848", "0"], ["83845.6", "0"], ["83844.6", "0"], ["83844.5", "0"], ["83843.9", "0"], ["83843.6", "0"], ["83842.9", "0"], ["83842.6", "0"], ["83841.5", "0.0003"], ["83841.2", "0"], ["83841", "0"], ["83840.5", "0.047605"], ["83840.4", "0.168414"], ["83840.3", "0.181"], ["83840.2", "0.000333"], ["83840.1", "0"], ["83840", "0.000483"], ["83839.5", "0.045422"], ["83839.3", "0"], ["83839", "0.00175"], ["83838.5", "0"], ["83837.9", "0"], ["83837.6", "0"], ["83837.3", "0.052"], ["83837.2", "0.044625"], ["83837.1", "0"], ["83836.3", "0"], ["83835.9", "0"], ["83835.8", "0"], ["83834.9", "0"], ["83832", "0.003893"], ["83830", "0.04"], ["83827.8", "0.078235"], ["83827.7", "0"], ["83827.2", "0.023425"], ["83826.6", "0.047173"], ["83826.3", "0"], ["83825.1", "0.053608"], ["83825", "0.019007"], ["83824.3", "0"], ["83824.1", "0.119299"], ["83823.8", "0.059399"], ["83823.7", "0"], ["83823.4", "0"], ["83822.5", "0"], ["83822", "0"], ["83821.6", "0.0002"], ["83821.4", "0"], ["83820.5", "0"], ["83820.1", "0.001801"], ["83819.3", "0.03831"], ["83819", "0.119299"], ["83818.7", "0.072956"], ["83818.5", "0.001333"], ["83817.4", "0"], ["83816.5", "0.0045"], ["83816", "0"], ["83815.6", "0.001466"], ["83815.3", "0"], ["83814.3", "0.005"], ["83814.1", "0"], ["83814", "0.003173"], ["83812.5", "0.059399"], ["83812", "0"], ["83811.2", "0"], ["83809.8", "0.003193"], ["83805.1", "0.013"], ["83805", "0.013242"], ["83803.8", "0.059399"], ["83802.7", "0"], ["83802.2", "0"], ["83798.7", "0"], ["83798.6", "0"], ["83797.7", "0"], ["83794.9", "0"], ["83792.7", "0"], ["83787.3", "0.059399"], ["83787.2", "0"], ["83785.4", "0"], ["83784.5", "0"], ["83782.1", "0.125225"], ["83781.2", "0"], ["83780.8", "0.001333"], ["83780.6", "0.354246"], ["83780.5", "0.003775"], ["83779.8", "0.000629"], ["83778.8", "0.023758"], ["83778.7", "0.001466"], ["83777.9", "0.00051"], ["83777.4", "0.000333"], ["83777", "0.0006"], ["83776.9", "0.027564"], ["83776.6", "0.001333"], ["83776.5", "0.059399"], ["83776.4", "0.131273"], ["83776.3", "0.003174"], ["83774.2", "0.023758"], ["83774.1", "0.001466"], ["83773.3", "0.01364"], ["83773.2", "0.000333"], ["83772.6", "0.026307"], ["83772.5", "0.001333"], ["83772.1", "0.003163"], ["83771.9", "0.000689"], ["83771.4", "0.029629"], ["83771.3", "0.009"], ["83770.8", "0.089099"], ["83770.3", "0.000149"], ["83770.2", "0.099774"], ["83769.5", "0.001466"], ["83769", "0.000333"], ["83768.7", "0.00051"], ["83768.3", "0.001333"], ["83768", "0.119389"], ["83767.9", "0.003161"], ["83767.4", "0.023758"], ["83767.1", "0.00009"], ["83766.8", "0.011879"], ["83765.7", "0.120083"], ["83765.3", "0.011992"], ["83764.9", "0.060865"], ["83764.8", "0.000333"], ["83764.1", "0.001843"]], "a": [["83848.8", "1.922614"], ["83849.1", "0.133037"], ["83849.5", "0.1"], ["83849.9", "0.020859"], ["83850.7", "0.235995"], ["83851.2", "0.098008"], ["83855.9", "0.003193"], ["83856.3", "0.208954"], ["83856.4", "0.438059"], ["83857.2", "0.234478"], ["83860.1", "0.003193"], ["83860.4", "0.003976"], ["83860.5", "0.001333"], ["83860.9", "0.000512"], ["83861.2", "0.000333"], ["83861.7", "0.001466"], ["83862.2", "0.080081"], ["83862.9", "0.009243"], ["83863.9", "0.091356"], ["83864.1", "0.044"], ["83864.4", "0.02"], ["83864.8", "0.005"], ["83865.1", "0.018745"], ["83865.4", "0.000423"], ["83865.6", "0.02"], ["83866", "0.019898"], ["83866.5", "0.04"], ["83867.4", "0.04"], ["83867.6", "0"], ["83870.5", "0"], ["83870.8", "0.073854"], ["83871.6", "0.023888"], ["83872.3", "0.04"], ["83872.4", "0"], ["83872.9", "0.003576"], ["83873.8", "0.059822"], ["83873.9", "0.04"], ["83874.4", "0"], ["83875.1", "0.04159"], ["83876.1", "0"], ["83877.5", "0.497581"], ["83877.6", "0"], ["83878.3", "0.04"], ["83878.4", "0"], ["83880.2", "0"], ["83882.5", "0.139369"], ["83883.5", "0.089099"], ["83883.7", "0.562549"], ["83885.8", "0.011932"], ["83886.9", "0.023852"], ["83887.6", "0.023852"], ["83888", "0.066252"], ["83888.3", "0.003564"], ["83888.4", "0.023852"], ["83889.3", "0.023852"], ["83889.4", "0.120765"], ["83890.6", "1.430148"], ["83891.7", "0.146388"], ["83893.2", "0.000512"], ["83895.4", "0.119299"], ["83895.6", "0"], ["83896.3", "0.158635"], ["83899", "0.00009"], ["83900.2", "0"], ["83900.8", "0"], ["83904.5", "0"], ["83906.5", "0.0045"], ["83907.9", "0"], ["83910.6", "0.028069"], ["83912.1", "0.04"], ["83924", "0.10466"], ["83925.3", "3.748474"], ["83926.6", "0.000146"], ["83928.5", "0"], ["83928.6", "0"], ["83929.6", "0"], ["83930.1", "0"], ["83930.8", "0"], ["83930.9", "0"], ["83931.2", "0"], ["83931.4", "0"], ["83931.8", "0"], ["83932.1", "0"], ["83932.5", "0"], ["83932.6", "0"], ["83933.7", "0"], ["83934.7", "0"], ["83935.5", "0"], ["83935.6", "0"], ["83935.9", "0"], ["83936", "0"], ["83936.5", "0"], ["83936.7", "0"], ["83937.1", "0"], ["83938", "0"], ["83938.7", "0"], ["83939.4", "0"], ["83939.8", "0"], ["83940.1", "0"]], "u": 49914, "seq": 67553429604}, "cts": 1742561268517, "record_time": 1742561268.561863, "EXCHANGE": "BYBIT"}
{"topic": "orderbook.200.BTCUSDT", "ts": 1742561268719, "type": "delta", "data": {"s": "BTCUSDT", "b": [["83848.7", "0.005239"], ["83841.5", "0"], ["83840.6", "0.000298"], ["83840.4", "0.139619"], ["83839.5", "0.001333"], ["83839", "0"], ["83837.3", "0"], ["83837.2", "0"], ["83836.5", "0.0003"], ["83836.3", "0.071602"], ["83833.5", "0.047462"], ["83833.4", "0.059399"], ["83833.3", "0.071604"], ["83831.9", "0.04"], ["83831.6", "0.04"], ["83831.5", "0.052"], ["83830.9", "0.079812"], ["83830.2", "0.052"], ["83829.4", "0.120765"], ["83828.3", "0.044"], ["83827.8", "0.140072"], ["83827.2", "0"], ["83824.9", "0.187369"], ["83823.5", "0.000333"], ["83820.1", "0"], ["83818.9", "0"], ["83815.3", "0.178894"], ["83814.3", "0"], ["83813.8", "0.00822"], ["83809.9", "0.065879"], ["83806.8", "0.079569"], ["83805.1", "0"], ["83804.9", "0.012883"], ["83796", "0"], ["83795.3", "0.003362"], ["83779.8", "0"], ["83774.8", "0.171"], ["83772.6", "0"], ["83770.3", "0.001899"], ["83767.3", "0.000629"], ["83767.1", "0"], ["83766.8", "0"], ["83765.7", "0"], ["83765.3", "0"], ["83764.9", "0"], ["83764.8", "0"], ["83764.1", "0"]], "a": [["83848.8", "1.959116"], ["83849.1", "0.123933"], ["83850.7", "0.22109"], ["83853.3", "0.021476"], ["83853.6", "0.024117"], ["83857", "0.000333"], ["83857.2", "0.239145"], ["83859.7", "0.014876"], ["83859.8", "0.04"], ["83860", "0.04024"], ["83861.5", "0.04"], ["83862.3", "0.065416"], ["83863.3", "0.04"], ["83864.8", "0"], ["83865.2", "0.045809"], ["83866", "0.04141"], ["83866.7", "0.04"], ["83871.6", "0"], ["83876.5", "0.0045"], ["83882.4", "0.119299"], ["83883.2", "0.063481"], ["83883.8", "0"], ["83886.8", "0.013797"], ["83891.7", "0.082908"], ["83891.8", "0.024854"], ["83896.3", "0.005963"], ["83905.5", "0.04"], ["83924.2", "0"], ["83925.3", "0"], ["83925.5", "0"], ["83925.9", "0"], ["83926.3", "0"], ["83926.6", "0"], ["83927.2", "0"], ["83927.4", "0"], ["83927.6", "0"], ["83927.7", "0"], ["83927.9", "0"], ["83928.3", "0"]], "u": 49915, "seq": 67553429817}, "cts": 1742561268716, "record_time": 1742561268.739867, "EXCHANGE": "BYBIT"}
{"topic": "orderbook.200.BTCUSDT", "ts": 1742561268919, "type": "delta", "data": {"s": "BTCUSDT", "b": [["83848.7", "0.00322"], ["83845", "0.005746"], ["83843.1", "0.071596"], ["83840.5", "0.000298"], ["83840.3", "0.186"], ["83833.6", "0.032126"], ["83833.5", "0.071604"], ["83833.3", "0"], ["83831.5", "0"], ["83828.6", "0.05251"], ["83813.8", "0"], ["83805", "0.013241"], ["83798.5", "0.099775"], ["83788.4", "3.78526"], ["83770.2", "0"], ["83769.1", "0.626127"], ["83767.4", "0"], ["83767.3", "0"]], "a": [["83848.8", "1.959355"], ["83852.5", "0.006188"], ["83856.2", "0.021476"], ["83864", "0.043919"], ["83865.2", "0"], ["83867.4", "0.08"], ["83874.9", "0.004696"], ["83878.3", "0"], ["83879.5", "0.04"], ["83879.6", "0.04"], ["83887.2", "2.606455"], ["83889.9", "0.490035"], ["83901.3", "0"], ["83901.4", "0"], ["83923", "0"], ["83923.4", "0"], ["83924", "0"], ["83924.1", "0"]], "u": 49916, "seq": 67553429933}, "cts": 1742561268916, "record_time": 1742561268.937117, "EXCHANGE": "BYBIT"}
{"topic": "orderbook.200.BTCUSDT", "ts": 1742561269119, "type": "delta", "data": {"s": "BTCUSDT", "b": [["83843.1", "0"], ["83840.6", "0"], ["83840.4", "0.111707"], ["83836.3", "0"], ["83835.9", "0.071602"], ["83835", "0.065786"], ["83834.9", "0.119299"], ["83833.6", "0"], ["83827.1", "0.059031"], ["83826.9", "0.053333"], ["83824.9", "0.210634"], ["83820.1", "0.056139"], ["83813.1", "0.120414"], ["83812.8", "0.004772"], ["83795.3", "0.001688"], ["83767.9", "0"]], "a": [["83848.8", "1.962931"], ["83851.2", "0"], ["83856.3", "0.210799"], ["83856.4", "0.437803"], ["83857.1", "0.001466"], ["83857.2", "0.23609"], ["83862.1", "0.056904"], ["83865", "0.04"], ["83866", "0.074454"], ["83869.1", "0.061854"], ["83872.3", "0"], ["83872.9", "0"], ["83873.9", "0"], ["83876.1", "0.112726"], ["83882.4", "0"], ["83888", "0.023852"]], "u": 49917, "seq": 67553430060}, "cts": 1742561269118, "record_time": 1742561269.137121, "EXCHANGE": "BYBIT"}
{"success": true, "ret_msg": "subscribe", "conn_id": "00a0e314-7f81-4c90-b274-576c1d0d3f3d", "op": "subscribe", "record_time": 1742569696.166016, "EXCHANGE": "BYBIT"}
{"topic": "orderbook.200.BTCUSDT", "ts": 1742569694320, "type": "snapshot", "data": {"s": "BTCUSDT", "b": [["84044.6", "0.71535"], ["84043.9", "0.0006"], ["84043.7", "0.000153"], ["84041.4", "0.008899"], ["84040.5", "0.087018"], ["84040.4", "0.243"], ["84040", "0.00006"], ["84039", "0.002"], ["84038.6", "0.02"], ["84037.7", "0.07143"], ["84037.6", "0.183481"], ["84037.5", "0.053099"], ["84037.4", "0.000333"], ["84037.3", "0.178492"], ["84037.1", "0.014174"], ["84036.7", "0.001333"], ["84036.6", "0.0001"], ["84036.3", "0.00416"], ["84036.2", "0.06635"], ["84035.9", "0.003915"], ["84035.6", "0.178496"], ["84035.4", "0.026675"], ["84034.3", "0.118852"], ["84033.6", "0.01893"], ["84033.4", "0.0006"], ["84033.3", "0.229629"], ["84033.2", "0.000333"], ["84033.1", "0.171"], ["84032.9", "0.025418"], ["84032.5", "0.001333"], ["84032.4", "0.001466"], ["84032.1", "0.003643"], ["84031.7", "0.001116"], ["84030.8", "0.178506"], ["84030.5", "0.000999"], ["84030.2", "0.048"], ["84030.1", "0.044"], ["84030", "0.009358"], ["84029.9", "0.116558"], ["84029.4", "0.168799"], ["84029.3", "0.237876"], ["84029.2", "0.118852"], ["84029", "0.000333"], ["84028.6", "0.04"], ["84028.4", "0.044"], ["84028.3", "0.001333"], ["84028.2", "0.023947"], ["84027.9", "0.003642"], ["84027.8", "0.001466"], ["84027.7", "0.003"], ["84027", "0.000516"], ["84026.8", "0.04"], ["84026.7", "0.044"], ["84025.3", "0.178477"], ["84025.2", "0.00009"], ["84025.1", "0.04"], ["84025", "0.04"], ["84024.8", "0.000333"], ["84024.2", "0.009"], ["84024.1", "0.193527"], ["84024", "0.118852"], ["84023.9", "0.171"], ["84023.7", "0.047641"], ["84023.6", "0.052"], ["84023.4", "0.048"], ["84023.2", "0.002066"], ["84022.4", "0.000516"], ["84022.1", "0.04"], ["84021", "0.178477"], ["84020.8", "0.094196"], ["84020.6", "0.000333"], ["84020", "0.00006"], ["84019.9", "0.001333"], ["84019.5", "0.00364"], ["84018.7", "0.048"], ["84018.6", "0.001466"], ["84017.9", "0.059399"], ["84017.8", "0.000516"], ["84016.8", "0.11924"], ["84016.7", "0.407655"], ["84016.4", "0.000333"], ["84015.7", "0.001333"], ["84015.6", "0.035706"], ["84015.5", "0.089099"], ["84015.3", "0.00364"], ["84015.2", "0.171"], ["84014.3", "0.0006"], ["84014", "0.001466"], ["84013.3", "0.512611"], ["84013.2", "0.000516"], ["84013", "0.562036"], ["84012.2", "0.000333"], ["84011.8", "0.011904"], ["84011.7", "0.066806"], ["84011.6", "0.03739"], ["84011.5", "0.001333"], ["84011.1", "0.003639"], ["84010.6", "0.118852"], ["84009.3", "0.060865"], ["84008.5", "0.000516"], ["84008.4", "0.00009"], ["84008.2", "0.129045"], ["84008", "0.000333"], ["84007.5", "0.124934"], ["84007.4", "0.0016"], ["84007.3", "0.001333"], ["84007.1", "0.039635"], ["84007", "0.039635"], ["84006.9", "0.003636"], ["84006.1", "0.022837"], ["84005.8", "0.028419"], ["84005.3", "0.118852"], ["84005.2", "0.012882"], ["84005.1", "0.012882"], ["84004.7", "0.001466"], ["84004.2", "0.089238"], ["84003.9", "0.000877"], ["84003.8", "0.000333"], ["84003.1", "0.001333"], ["84002.7", "0.2395"], ["84002.6", "0.30749"], ["84002.3", "0.096174"], ["84002", "0.000118"], ["84001.6", "0.05"], ["84001.5", "0.04955"], ["84000.1", "0.179717"], ["84000", "0.218036"], ["83999.6", "0.000333"], ["83999.3", "0.00052"], ["83998.9", "0.001333"], ["83998.5", "0.003552"], ["83997.4", "0.111354"], ["83996.1", "0.000875"], ["83995.8", "0.320756"], ["83995.7", "0.103764"], ["83995.5", "0.001466"], ["83995.4", "0.000333"], ["83994.7", "0.001853"], ["83994.3", "0.003552"], ["83992.2", "0.005879"], ["83992.1", "0.178588"], ["83991.7", "0.118852"], ["83991.6", "0.120497"], ["83991.5", "0.171"], ["83991.2", "0.000333"], ["83990.9", "0.001466"], ["83990.6", "0.011995"], ["83990.5", "0.001333"], ["83990.1", "0.004072"], ["83990", "0.000237"], ["83989.1", "0.01185"], ["83989", "0.009338"], ["83987", "0.000333"], ["83986.7", "0.0237"], ["83986.6", "0.024178"], ["83986.5", "0.064895"], ["83986.3", "0.001333"], ["83986.2", "0.001466"], ["83985.9", "0.02754"], ["83985.4", "0.00052"], ["83985", "0.023799"], ["83984.4", "0.013719"], ["83984", "0.143034"], ["83983.7", "0.118852"], ["83983.6", "0.023799"], ["83983.2", "0.089342"], ["83983.1", "0.076875"], ["83983", "0.171"], ["83982.9", "0.059399"], ["83982.8", "0.015333"], ["83982.3", "0.124934"], ["83982.1", "0.001333"], ["83981.9", "0.023799"], ["83981.8", "0.000361"], ["83981.7", "0.003552"], ["83981.6", "0.001466"], ["83981.1", "0.023799"], ["83981", "0.139064"], ["83980.8", "0.00052"], ["83980.1", "0.023799"], ["83980", "0.00006"], ["83978.6", "0.000333"], ["83977.9", "0.001333"], ["83977.5", "0.003552"], ["83977.4", "0.10672"], ["83977.3", "0.353656"], ["83977", "0.001466"], ["83976.2", "0.00052"], ["83975.6", "0.003575"], ["83974.8", "0.00009"], ["83974.7", "0.118852"], ["83974.6", "0.0025"], ["83974.5", "0.171"], ["83974.4", "0.000333"], ["83973.7", "0.001333"], ["83973.3", "0.003552"], ["83972.4", "0.001466"], ["83972.2", "0.005951"], ["83971.6", "0.00052"], ["83970.2", "0.000333"]], "a": [["84044.7", "0.08984"], ["84045.1", "0.001333"], ["84045.5", "0.000516"], ["84045.8", "0.000333"], ["84046", "0.0004"], ["84046.3", "0.001466"], ["84047", "0.0006"], ["84047.8", "0.0006"], ["84048.3", "0.071421"], ["84048.8", "0.004"], ["84048.9", "0.003625"], ["84049.2", "0.022381"], ["84049.3", "0.001333"], ["84050", "0.000333"], ["84050.1", "0.001516"], ["84050.9", "0.001466"], ["84051.4", "0.01114"], ["84052", "0.000295"], ["84052.1", "0.088171"], ["84052.2", "0.106645"], ["84053.1", "0.018922"], ["84053.3", "0.171"], ["84053.5", "0.001333"], ["84053.8", "0.050468"], ["84053.9", "0.01067"], ["84054.2", "0.000333"], ["84054.8", "0.061886"], ["84055.6", "0.038745"], ["84055.7", "0.003934"], ["84055.9", "0.005"], ["84056", "0.00018"], ["84057.3", "0.003626"], ["84057.7", "0.001333"], ["84058.2", "0.071413"], ["84058.4", "0.000333"], ["84058.5", "0.04"], ["84058.7", "0.04"], ["84059", "0.260603"], ["84059.3", "0.178445"], ["84059.4", "0.000516"], ["84059.6", "0.178477"], ["84059.8", "0.000361"], ["84060.2", "0.112877"], ["84060.4", "0.04"], ["84060.9", "0.178442"], ["84061.2", "0.015"], ["84061.6", "0.003626"], ["84061.9", "0.001333"], ["84062.1", "0.080023"], ["84062.6", "0.187953"], ["84063", "0.134054"], ["84063.7", "0.075703"], ["84063.8", "0.04"], ["84064", "0.000516"], ["84064.4", "0.00009"], ["84064.8", "0.001466"], ["84064.9", "0.171"], ["84065.2", "0.04"], ["84065.4", "0.04"], ["84065.6", "0.019002"], ["84065.8", "0.003626"], ["84066", "0.05942"], ["84066.1", "0.001333"], ["84066.5", "0.004681"], ["84066.8", "0.000333"], ["84067.2", "0.263752"], ["84068.6", "0.000516"], ["84069.1", "0.023798"], ["84069.4", "0.001466"], ["84069.5", "0.55178"], ["84069.8", "0.003053"], ["84070", "0.027544"], ["84070.3", "0.001333"], ["84070.5", "0.124934"], ["84071", "0.000333"], ["84071.5", "0.178477"], ["84071.6", "0.232443"], ["84071.7", "0.517614"], ["84072.1", "0.001785"], ["84072.2", "0.178477"], ["84072.5", "0.116549"], ["84072.8", "0.00009"], ["84073.1", "0.023798"], ["84073.2", "0.0006"], ["84073.3", "0.000516"], ["84073.4", "0.171"], ["84073.6", "0.001125"], ["84073.9", "0.025008"], ["84074", "0.013945"], ["84074.1", "0.001466"], ["84074.2", "0.003628"], ["84074.5", "0.001333"], ["84074.6", "0.0025"], ["84074.8", "0.023798"], ["84075", "0.059399"], ["84075.2", "0.001933"], ["84075.6", "0.06097"], ["84075.7", "0.178477"], ["84076.6", "0.003575"], ["84077.9", "0.000516"], ["84078.4", "0.003628"], ["84078.7", "0.002799"], ["84079.1", "0.011904"], ["84079.4", "0.000333"], ["84080", "0.00024"], ["84080.2", "0.006549"], ["84081.2", "0.00009"], ["84081.8", "0.079033"], ["84081.9", "0.171361"], ["84082.5", "0.000516"], ["84082.6", "0.003628"], ["84082.7", "0.022"], ["84082.9", "0.001333"], ["84083.3", "0.001466"], ["84083.6", "0.000333"], ["84083.8", "0.059399"], ["84084.5", "0.003418"], ["84084.7", "0.515193"], ["84085.1", "0.118852"], ["84086.5", "0.04"], ["84086.6", "1.467103"], ["84086.8", "0.003629"], ["84087.1", "0.001851"], ["84087.4", "0.124934"], ["84087.6", "0.0006"], ["84087.8", "0.000333"], ["84087.9", "0.001466"], ["84088.3", "0.089238"], ["84089.6", "0.00009"], ["84089.9", "0.067117"], ["84090.1", "0.13484"], ["84090.2", "0.118852"], ["84090.3", "0.025796"], ["84090.4", "0.171"], ["84091", "0.003561"], ["84091.1", "0.00015"], ["84091.3", "0.001333"], ["84091.4", "0.002973"], ["84091.5", "0.124952"], ["84091.8", "0.000518"], ["84092", "0.000333"], ["84092.6", "0.001466"], ["84093.3", "0.091871"], ["84093.4", "0.094774"], ["84095.2", "0.003561"], ["84095.5", "0.060732"], ["84095.6", "0.118852"], ["84096.2", "0.000333"], ["84096.4", "0.000518"], ["84096.9", "0.015"], ["84097.2", "0.001466"], ["84098", "0.00018"], ["84098.9", "0.171"], ["84099.4", "0.003562"], ["84099.7", "0.001333"], ["84099.8", "0.04"], ["84100.4", "0.000333"], ["84101", "0.000518"], ["84101.3", "0.178356"], ["84101.5", "0.118852"], ["84101.8", "0.001466"], ["84103.2", "0.04"], ["84103.5", "0.001526"], ["84103.6", "0.003563"], ["84103.9", "0.001333"], ["84104", "0.000361"], ["84104.2", "0.0006"], ["84104.3", "0.12"], ["84104.6", "0.000333"], ["84105.1", "0.059399"], ["84105.6", "0.000518"], ["84105.8", "0.003575"], ["84105.9", "0.005"], ["84106.4", "0.001556"], ["84107.2", "3.754498"], ["84107.3", "0.04"], ["84107.4", "0.171"], ["84107.8", "0.003563"], ["84108", "0.05942"], ["84108.1", "0.001333"], ["84108.3", "3.446223"], ["84108.4", "0.124934"], ["84108.9", "0.000333"], ["84109.3", "0.089252"], ["84109.6", "0.247212"], ["84110.1", "0.04"], ["84110.3", "0.000518"], ["84111.1", "0.001549"], ["84111.2", "0.015"], ["84112", "0.003563"], ["84112.3", "0.120185"], ["84112.5", "0.013077"], ["84112.6", "0.0006"], ["84113.1", "0.089432"], ["84113.3", "0.353558"], ["84113.6", "0.000333"], ["84114", "0.059399"], ["84114.8", "0.00009"], ["84114.9", "0.000518"], ["84115.7", "0.001466"]], "u": 91998, "seq": 67563832495}, "cts": 1742569694317, "record_time": 1742569696.167021, "EXCHANGE": "BYBIT"}
{"topic": "orderbook.200.BTCUSDT", "ts": 1742569694519, "type": "delta", "data": {"s": "BTCUSDT", "b": [["84043.7", "0"], ["84037.6", "0.183634"], ["84030.8", "0.248639"], ["84029.4", "0.227275"], ["84024.3", "0.178477"], ["84023.7", "0.003641"], ["84022.4", "0.055251"], ["84022.1", "0"], ["84020.8", "0.070196"], ["84018.7", "0"], ["84015.4", "0.124003"], ["84010.8", "0.096174"], ["84002.3", "0"], ["84001.6", "0"], ["84001.4", "0.04955"], ["83970", "0.007148"]], "a": [["84049.2", "0"], ["84055.9", "0.076415"], ["84058.1", "0.002"], ["84058.2", "0"], ["84064.4", "0.061278"], ["84064.8", "0.060865"], ["84071.4", "0.06171"], ["84073.6", "0"], ["84073.9", "0.023798"], ["84078.4", "0.125348"], ["84116.2", "0.028203"]], "u": 91999, "seq": 67563832585}, "cts": 1742569694516, "record_time": 1742569696.16902, "EXCHANGE": "BYBIT"}
{"topic": "orderbook.200.BTCUSDT", "ts": 1742569694720, "type": "delta", "data": {"s": "BTCUSDT", "b": [["84044.6", "0.54435"], ["84037.6", "0.183481"], ["84034.3", "0"], ["84029.4", "0.168799"], ["84022.4", "0.000516"], ["84015.4", "0"], ["84003.3", "0.124934"], ["84001.6", "0.05"], ["84001.4", "0"], ["83969.5", "0.001333"]], "a": [["84044.7", "0.26084"], ["84048.3", "0"], ["84060.2", "0.041466"], ["84064.4", "0.00009"], ["84071.4", "0"], ["84075.6", "0.089939"], ["84078.4", "0.003628"], ["84105.9", "0.032752"], ["84115.9", "0.171"], ["84116.6", "0.001333"]], "u": 92000, "seq": 67563832672}, "cts": 1742569694716, "record_time": 1742569696.170021, "EXCHANGE": "BYBIT"}
{"topic": "orderbook.200.BTCUSDT", "ts": 1742569694919, "type": "delta", "data": {"s": "BTCUSDT", "b": [["84040.4", "0.223"], ["84040", "0.011963"], ["84038.6", "0"], ["84037.5", "0.033099"], ["84036.9", "0.000153"], ["84036.2", "0.04635"], ["84007.3", "0.040968"], ["84007.2", "0.039635"], ["84007.1", "0"], ["84007", "0"], ["84005.4", "0.012882"], ["84005.3", "0.131734"], ["84005.2", "0"], ["84005.1", "0"], ["84001.7", "0.04955"], ["84001.6", "0.04955"], ["84001.5", "0"], ["83969.1", "0.003552"], ["83968.9", "1.230455"]], "a": [["84044.7", "0.090078"], ["84044.8", "0.071424"], ["84048.8", "0.002"], ["84053.7", "0.071417"], ["84068", "0.003"], ["84075.6", "0.06097"], ["84084", "0.003418"], ["84084.5", "0"], ["84086", "0.04"], ["84086.1", "0.04"], ["84086.5", "0"], ["84086.6", "1.427103"], ["84115.7", "0"], ["84115.9", "0"], ["84116.2", "0"], ["84116.6", "0"]], "u": 92001, "seq": 67563832766}, "cts": 1742569694915, "record_time": 1742569696.17202, "EXCHANGE": "BYBIT"}
{"topic": "orderbook.200.BTCUSDT", "ts": 1742569695120, "type": "delta", "data": {"s": "BTCUSDT", "b": [["84001.8", "0.05"], ["84001.6", "0"]], "a": [["84084", "0"], ["84084.2", "0.003418"], ["84086", "0"], ["84086.1", "0"], ["84086.2", "0.04"], ["84086.3", "0.04"]], "u": 92002, "seq": 67563832789}, "cts": 1742569695112, "record_time": 1742569696.17402, "EXCHANGE": "BYBIT"}
{"topic": "orderbook.200.BTCUSDT", "ts": 1742569695319, "type": "delta", "data": {"s": "BTCUSDT", "b": [["84044.6", "0.232038"], ["84041.4", "0"], ["84040.4", "0.22"], ["84040", "0.00006"], ["84037.3", "0"], ["84036.9", "0"], ["84035.6", "0"], ["84034.4", "0.178498"], ["84032.7", "0.178502"], ["84031.3", "0.113889"], ["84029.3", "0"], ["84027.5", "0.114818"], ["84025.3", "0"], ["84024.3", "0"], ["84021.5", "0.171035"], ["84021", "0"], ["84020.5", "0.177853"], ["84015.5", "0"], ["84013.5", "0.29444"], ["84012.4", "0.276599"], ["84001.8", "0"], ["84001.6", "0.04955"], ["83968.2", "0.023803"]], "a": [["84044.7", "0.451478"], ["84048.8", "0"], ["84050.1", "0.000516"], ["84051.8", "0.071418"], ["84053.7", "0"], ["84056.5", "0.110023"], ["84060.4", "0.155321"], ["84066.3", "0.174693"], ["84067.4", "0.171045"], ["84074.4", "0.297523"], ["84075.4", "0.27203"], ["84084.1", "0.003418"], ["84084.2", "0"], ["84086.1", "0.04"], ["84086.3", "0"], ["84113.6", "0"], ["84114", "0"], ["84114.8", "0"], ["84114.9", "0"]], "u": 92003, "seq": 67563832909}, "cts": 1742569695317, "record_time": 1742569696.17502, "EXCHANGE": "BYBIT"}
{"topic": "orderbook.200.BTCUSDT", "ts": 1742569695520, "type": "delta", "data": {"s": "BTCUSDT", "b": [["84044.6", "0.093314"], ["84040.5", "0"], ["84040.4", "0"], ["84037.7", "0"], ["84037.6", "0.044721"], ["84036.7", "0.072764"], ["84035.9", "0"], ["84034.4", "0"], ["84033.6", "0.00009"], ["84033.4", "0.000897"], ["84033.3", "0.158195"], ["84032.7", "0"], ["84031.7", "0.001269"], ["84031.3", "0"], ["84030.8", "0.070133"], ["84030", "0"], ["84029.4", "0.106805"], ["84028.5", "0.059399"], ["84028.2", "0"], ["84027.5", "0"], ["84027.2", "0.004081"], ["84023.8", "0.01884"], ["84021.5", "0"], ["84020.5", "0"], ["84019.8", "0.009358"], ["84013.5", "0"], ["84012.5", "0.182309"], ["84012.4", "0"], ["84011.7", "0"], ["84010.8", "0"], ["84007.3", "0.001333"], ["84007.2", "0"], ["84006.6", "0.039635"], ["84006.5", "0.039635"], ["84005.4", "0"], ["84005.3", "0.118852"], ["84004.7", "0.014348"], ["84004.6", "0.012882"], ["84004.2", "0"], ["84001.7", "0"], ["84001.6", "0"], ["84001", "0.049551"], ["84000.9", "0.049551"], ["83999.5", "0.096182"], ["83967.8", "0.001466"], ["83967.3", "0.118852"], ["83967", "0.00052"], ["83966.9", "0.01002"], ["83966.8", "0.023805"], ["83966.4", "0.00018"], ["83966.1", "0.066551"], ["83966", "0.059732"], ["83965.9", "0.224383"], ["83965.3", "0.001333"]], "a": [["84044.7", "0.540561"], ["84056.4", "0.002"], ["84056.5", "0"], ["84060.4", "0.04"], ["84063", "0.279721"], ["84066.3", "0"], ["84067.2", "0.442229"], ["84067.3", "0.178477"], ["84067.4", "0"], ["84069.2", "0.003576"], ["84071.6", "0.484659"], ["84072.2", "0"], ["84074.4", "0"], ["84075.4", "0"], ["84075.7", "0"], ["84077", "0.098009"], ["84087", "0.063517"], ["84089.9", "0.0036"], ["84113.6", "0.000333"], ["84114", "0.059399"]], "u": 92004, "seq": 67563833164}, "cts": 1742569695517, "record_time": 1742569696.176525, "EXCHANGE": "BYBIT"}
{"topic": "orderbook.200.BTCUSDT", "ts": 1742569695720, "type": "delta", "data": {"s": "BTCUSDT", "b": [["84036.7", "0.001333"], ["84034.3", "0.071433"], ["84031.6", "0.071435"], ["84028.8", "0.120551"], ["84024.1", "0.130703"], ["84019", "0.175267"], ["84012.5", "0"], ["84009.9", "0.285812"], ["84001.1", "0.049551"], ["84000.9", "0"], ["83966.1", "0"], ["83966", "0"], ["83965.9", "0"], ["83965.3", "0"]], "a": [["84044.7", "0.541361"], ["84052.1", "0.132548"], ["84053.9", "0.029672"], ["84054", "0.119193"], ["84063.8", "0.222504"], ["84065.6", "0"], ["84071.6", "0.232443"], ["84072.9", "0.274221"], ["84075.6", "0.0006"], ["84087", "0"], ["84089.9", "0.067119"]], "u": 92005, "seq": 67563833229}, "cts": 1742569695715, "record_time": 1742569696.17853, "EXCHANGE": "BYBIT"}
{"topic": "orderbook.200.BTCUSDT", "ts": 1742569695920, "type": "delta", "data": {"s": "BTCUSDT", "b": [["84037.6", "0.075163"], ["84036.8", "0.071431"], ["84031.6", "0"], ["84030.5", "0"], ["84029.7", "0.023824"], ["84029.4", "0.148417"], ["84028.9", "0.17851"], ["84028.8", "0"], ["84027.2", "0.182595"], ["84019.3", "0.178477"], ["84019", "0"], ["84009.9", "0"], ["84005.1", "0.096185"], ["83999.5", "0"], ["83966.1", "0.066551"]], "a": [["84044.7", "0.281262"], ["84054", "0"], ["84063.8", "0.04"], ["84072.9", "0"], ["84114.8", "0.00009"], ["84114.9", "0.000518"]], "u": 92006, "seq": 67563833334}, "cts": 1742569695916, "record_time": 1742569696.190529, "EXCHANGE": "BYBIT"}
{"topic": "orderbook.200.BTCUSDT", "ts": 1742569696119, "type": "delta", "data": {"s": "BTCUSDT", "b": [["84044.6", "0.089012"], ["84024.3", "0.054608"], ["84019.3", "0"], ["84017.3", "0.059959"], ["84013", "0"], ["84010.3", "0.122278"], ["84008.4", "0.178567"], ["83997.2", "0.562036"], ["83966.4", "0"], ["83966.1", "0"]], "a": [["84044.7", "0.456562"], ["84059.3", "0.234034"], ["84066.3", "0.058027"], ["84073.3", "0.116108"], ["84087", "0.063519"], ["84089.9", "0.0036"], ["84114.8", "0"], ["84114.9", "0"]], "u": 92007, "seq": 67563833403}, "cts": 1742569696102, "record_time": 1742569696.38949, "EXCHANGE": "BYBIT"}
{"topic": "orderbook.200.BTCUSDT", "ts": 1742569696320, "type": "delta", "data": {"s": "BTCUSDT", "b": [["84016.7", "0.142775"], ["84006.7", "0.218112"], ["84006.5", "0"], ["84004.8", "0.012882"], ["84004.6", "0"], ["84004.2", "0.178477"], ["84000", "0.396513"], ["83966.8", "0"]], "a": [["84081.7", "0.003418"], ["84083.7", "0.04"], ["84083.8", "0.099399"], ["84084.1", "0"], ["84086.1", "0"], ["84086.2", "0"], ["84114.8", "0.00009"]], "u": 92008, "seq": 67563833427}, "cts": 1742569696315, "record_time": 1742569696.589507, "EXCHANGE": "BYBIT"}
{"topic": "orderbook.200.BTCUSDT", "ts": 1742569696520, "type": "delta", "data": {"s": "BTCUSDT", "b": [["84024.3", "0"], ["84021.7", "0.035704"], ["84017.3", "0"], ["84015.6", "0"], ["84010.3", "0"], ["84008.4", "0.00009"], ["84006.7", "0.039635"], ["84004.2", "0"], ["84000", "0.218036"], ["83966.8", "0.023805"], ["83966.4", "0.00018"], ["83966.1", "0.066551"], ["83966", "0.059732"]], "a": [["84044.7", "0.285562"], ["84059.3", "0.178445"], ["84066.3", "0"], ["84073.3", "0.000516"], ["84083.5", "0.04"], ["84083.6", "0.040333"], ["84083.7", "0"], ["84083.8", "0.059399"], ["84114.9", "0.000518"]], "u": 92009, "seq": 67563833477}, "cts": 1742569696503, "record_time": 1742569696.790167, "EXCHANGE": "BYBIT"}
{"topic": "orderbook.200.BTCUSDT", "ts": 1742569696720, "type": "delta", "data": {"s": "BTCUSDT", "b": [["84033.8", "0.008536"], ["84032.9", "0.025571"], ["84031.7", "0.001116"], ["84024.3", "0.060534"], ["84017.3", "0.056966"], ["84016.8", "0.297717"], ["84010.3", "0.124133"], ["84006.8", "0.04"], ["84006.6", "0"], ["84001.2", "0.05"], ["84001", "0"], ["83966.8", "0"], ["83966.4", "0"], ["83966.1", "0"], ["83966", "0"]], "a": [["84044.7", "0.487097"], ["84059.3", "0.233685"], ["84066.3", "0.057526"], ["84073.3", "0.117817"], ["84083.4", "0.04"], ["84083.6", "0.000333"], ["84114.8", "0"], ["84114.9", "0"]], "u": 92010, "seq": 67563833559}, "cts": 1742569696702, "record_time": 1742569696.989228, "EXCHANGE": "BYBIT"}
{"topic": "orderbook.200.BTCUSDT", "ts": 1742569696920, "type": "delta", "data": {"s": "BTCUSDT", "b": [["84033.8", "0"], ["84016.8", "0.476194"], ["84012.6", "0.178477"], ["84007.3", "0.004333"], ["84006.8", "0.039635"], ["84004.9", "0.012882"], ["84004.7", "0.001466"], ["84001.2", "0.049551"], ["83995.6", "0.353528"], ["83977.3", "0.000083"], ["83967", "0"], ["83966.9", "0"]], "a": [["84081.4", "0.003418"], ["84081.7", "0"], ["84087", "0"], ["84114.8", "0.00009"]], "u": 92011, "seq": 67563833599}, "cts": 1742569696914, "record_time": 1742569697.189928, "EXCHANGE": "BYBIT"}
{"topic": "orderbook.200.BTCUSDT", "ts": 1742569697119, "type": "delta", "data": {"s": "BTCUSDT", "b": [["84044.6", "0.160436"], ["84039", "0.001"], ["84036.8", "0"], ["84036.6", "0.071531"], ["84033.3", "0.158348"], ["84032.9", "0.025418"], ["84030.3", "0.110176"], ["84024.3", "0"], ["84020.8", "0.174005"], ["84019.8", "0.185915"], ["84017.3", "0"], ["84014.3", "0.179077"], ["84012.8", "0.293334"], ["84010.3", "0"], ["84008.4", "0.107092"], ["84006.8", "0"], ["84006.7", "0"], ["84006.6", "0.039635"], ["84006.5", "0.039635"], ["84005.1", "0.096184"], ["84004.9", "0"], ["84004.8", "0"], ["84004.7", "0.014348"], ["84004.6", "0.012882"], ["84001.2", "0"], ["84001.1", "0"], ["84001", "0.049551"], ["84000.9", "0.049551"], ["83977.4", "0"], ["83967", "0.00052"], ["83966.9", "0.01002"], ["83966.8", "0.023805"], ["83966.5", "0.002469"]], "a": [["84054.7", "0.096998"], ["84054.8", "0.114759"], ["84059.3", "0.178445"], ["84065.3", "0.169448"], ["84066.3", "0"], ["84072.3", "0.291026"], ["84073.3", "0.000516"], ["84081.4", "0"], ["84081.8", "0.082451"], ["84083.4", "0"], ["84083.5", "0"], ["84083.8", "0.099399"], ["84083.9", "0.04"], ["84084.2", "0.063519"], ["84114.8", "0"]], "u": 92012, "seq": 67563833669}, "cts": 1742569697103, "record_time": 1742569697.389623, "EXCHANGE": "BYBIT"}
{"topic": "orderbook.200.BTCUSDT", "ts": 1742569697320, "type": "delta", "data": {"s": "BTCUSDT", "b": [["84033.3", "0.158195"], ["84033.2", "0.000486"], ["84024.2", "0.18752"], ["84008.4", "0.00009"], ["83995.7", "0.204092"]], "a": [], "u": 92013, "seq": 67563833699}, "cts": 1742569697306, "record_time": 1742569697.590055, "EXCHANGE": "BYBIT"}
{"topic": "orderbook.200.BTCUSDT", "ts": 1742569697520, "type": "delta", "data": {"s": "BTCUSDT", "b": [["84044.6", "0.089612"], ["84044.1", "0.071425"], ["84039", "0"], ["84038.4", "0.021429"], ["84038.3", "0.07143"], ["84036.6", "0"], ["84035.7", "0.0002"], ["84033.2", "0.000333"], ["84031", "0.000153"], ["84030.3", "0"], ["84029.7", "0"], ["84019.8", "0.009358"], ["84016.8", "0.11924"], ["84014.3", "0.0006"], ["84012.8", "0"], ["84012.6", "0"], ["84007.4", "0"], ["84006.6", "0"], ["84006.5", "0.041235"], ["84006.4", "0.039636"], ["84004.7", "0.001466"], ["84004.5", "0.012882"], ["84003.3", "0"], ["84001", "0"], ["84000.9", "0.05"], ["84000.8", "0.049551"], ["83983.2", "0.089328"], ["83966.4", "0.00018"], ["83966.1", "0.059518"]], "a": [["84044.7", "0.456562"], ["84054.7", "0.062725"], ["84054.8", "0.000516"], ["84065.3", "0"], ["84072.3", "0"], ["84081.8", "0.079033"], ["84081.9", "0.174779"], ["84083.8", "0.059399"], ["84084", "0.04"], ["84114.8", "0.00009"]], "u": 92014, "seq": 67563833826}, "cts": 1742569697509, "record_time": 1742569697.790279, "EXCHANGE": "BYBIT"}
{"topic": "orderbook.200.BTCUSDT", "ts": 1742569697720, "type": "delta", "data": {"s": "BTCUSDT", "b": [["84044.6", "0.353681"], ["84020.8", "0.070196"], ["84009.2", "0.178477"], ["84006.7", "0.04"], ["84006.6", "0.039635"], ["84006.5", "0.0016"], ["84006.4", "0"], ["84004.8", "0.013"], ["84004.7", "0.014348"], ["84004.6", "0"], ["84004.5", "0"], ["84003.3", "0.124934"], ["84001.1", "0.05"], ["84001", "0.049551"], ["84000.9", "0"], ["84000.8", "0"], ["83966.4", "0"], ["83966.1", "0"]], "a": [["84044.7", "0.285562"], ["84062.1", "0.115727"], ["84063.7", "0.04"], ["84076.9", "0.035157"], ["84081.7", "0.003418"], ["84081.9", "0.171361"], ["84083.7", "0.04"], ["84083.8", "0.099399"], ["84083.9", "0"], ["84084", "0"], ["84114.8", "0"]], "u": 92015, "seq": 67563833897}, "cts": 1742569697717, "record_time": 1742569697.990737, "EXCHANGE": "BYBIT"}
{"topic": "orderbook.200.BTCUSDT", "ts": 1742569697919, "type": "delta", "data": {"s": "BTCUSDT", "b": [["84044.2", "0.021608"], ["84033.3", "0.23223"], ["84031", "0"], ["84030.6", "0.178506"], ["84029.9", "0.295066"], ["84028.9", "0"], ["84028.3", "0.024838"], ["84027.6", "0.178513"], ["84027.2", "0.004081"], ["84024.2", "0.009"], ["84021", "0.178477"], ["84016.8", "0.297717"], ["84009.2", "0"], ["84006.7", "0"], ["84006.6", "0"], ["84006.5", "0.041235"], ["84006.4", "0.039636"], ["84004.8", "0"], ["84004.7", "0.001466"], ["84004.6", "0.012882"], ["84004.5", "0.012882"], ["84001.1", "0"], ["84001", "0"], ["84000.9", "0.049551"], ["84000.8", "0.049551"], ["83966.5", "0"]], "a": [["84044.7", "0.346461"], ["84054.7", "0.089115"], ["84063", "0.190622"], ["84081.7", "0"], ["84081.9", "0.174779"], ["84083.7", "0"], ["84083.8", "0.059399"], ["84084.1", "0.04"], ["84084.2", "0.103519"], ["84114.8", "0.00009"]], "u": 92016, "seq": 67563833982}, "cts": 1742569697906, "record_time": 1742569698.189481, "EXCHANGE": "BYBIT"}
{"topic": "orderbook.200.BTCUSDT", "ts": 1742569698119, "type": "delta", "data": {"s": "BTCUSDT", "b": [["84044.6", "0.182681"], ["84044.2", "0"], ["84035.4", "0.026828"], ["84019.3", "0.178477"], ["84011.7", "0.066806"], ["84005.1", "0.096183"], ["84004.2", "0.089238"], ["83966.9", "0"], ["83966.8", "0"]], "a": [["84044.7", "0.300566"], ["84054.7", "0.062725"], ["84083.9", "0.04"], ["84084", "0.04"], ["84084.1", "0"], ["84084.2", "0.063519"], ["84114.8", "0"]], "u": 92017, "seq": 67563834026}, "cts": 1742569698114, "record_time": 1742569698.389341, "EXCHANGE": "BYBIT"}
{"topic": "orderbook.200.BTCUSDT", "ts": 1742569698320, "type": "delta", "data": {"s": "BTCUSDT", "b": [["84044.6", "0.113581"], ["84030.7", "0.124713"], ["84020.2", "0.171902"], ["84013.2", "0.313506"], ["83967.3", "0"], ["83967", "0"]], "a": [["84044.7", "0.284792"], ["84053.4", "0.002"], ["84055.2", "0.122005"], ["84065.7", "0.178316"], ["84069.2", "0"], ["84072.7", "0.29742"], ["84113.3", "0"], ["84113.6", "0"], ["84114", "0"]], "u": 92018, "seq": 67563834099}, "cts": 1742569698311, "record_time": 1742569698.589444, "EXCHANGE": "BYBIT"}
{"topic": "orderbook.200.BTCUSDT", "ts": 1742569698519, "type": "delta", "data": {"s": "BTCUSDT", "b": [], "a": [["84054.7", "0.091485"], ["84058.1", "0"], ["84084.2", "0"], ["84087", "0.063519"], ["84113.3", "0.353558"]], "u": 92019, "seq": 67563834125}, "cts": 1742569698510, "record_time": 1742569698.78931, "EXCHANGE": "BYBIT"}
{"topic": "orderbook.200.BTCUSDT", "ts": 1742569698720, "type": "delta", "data": {"s": "BTCUSDT", "b": [["84044.6", "0.260681"], ["84044.2", "0.021608"], ["84034.4", "0.118852"], ["84033.8", "0.008693"], ["84032.1", "0.121573"], ["84030.7", "0"], ["84021.6", "0.166284"], ["84020.2", "0"], ["84019.3", "0"], ["84014.6", "0.276539"], ["84013.2", "0.000516"], ["83968.2", "0"], ["83967.8", "0"]], "a": [["84054.7", "0.062725"], ["84055.2", "0"], ["84056.6", "0.110359"], ["84064.8", "0.001466"], ["84065.7", "0"], ["84067.1", "0.174888"], ["84071.6", "0.349476"], ["84072.7", "0"], ["84074.1", "0.305562"], ["84113.6", "0.000333"]], "u": 92020, "seq": 67563834214}, "cts": 1742569698716, "record_time": 1742569698.989671, "EXCHANGE": "BYBIT"}
{"topic": "orderbook.200.BTCUSDT", "ts": 1742569698920, "type": "delta", "data": {"s": "BTCUSDT", "b": [["84032.6", "0.178502"], ["84032.1", "0.003643"], ["84030.6", "0"], ["84027.1", "0.055347"], ["84021.8", "0.178477"], ["84021.6", "0"], ["84020.1", "0.06114"], ["84014.6", "0"], ["84013.1", "0.123051"], ["84007.3", "0.001333"], ["84006.5", "0.0016"], ["84006.4", "0"], ["84006.2", "0.039636"], ["84006.1", "0.062473"], ["84004.6", "0"], ["84004.5", "0"], ["84004.3", "0.012882"], ["84004.2", "0.10212"], ["84000.9", "0"], ["84000.7", "0.049551"], ["83968.9", "0"]], "a": [["84044.7", "0.325448"], ["84044.8", "0"], ["84045.5", "0.043107"], ["84045.6", "0.071424"], ["84050.1", "0.071936"], ["84051.8", "0"], ["84052.1", "0.203966"], ["84053.9", "0.01067"], ["84054.7", "0.028575"], ["84055.9", "0.005"], ["84056.6", "0"], ["84062.1", "0.175148"], ["84067.1", "0"], ["84069.1", "0.085758"], ["84074.1", "0.001466"], ["84076.1", "0.117637"], ["84081.9", "0.171361"], ["84082.5", "0.003934"], ["84083.9", "0"], ["84084", "0"], ["84084.5", "0.04"], ["84084.6", "0.04"], ["84087.6", "0.307779"], ["84114", "0.059399"], ["84114.8", "0.00009"]], "u": 92021, "seq": 67563834333}, "cts": 1742569698898, "record_time": 1742569699.189374, "EXCHANGE": "BYBIT"}
{"topic": "orderbook.200.BTCUSDT", "ts": 1742569699120, "type": "delta", "data": {"s": "BTCUSDT", "b": [["84036.6", "0.000153"], ["84035.4", "0.026675"], ["84034.4", "0"], ["84027.1", "0.056867"], ["84020.1", "0.055034"], ["84019.3", "0.178387"], ["84013.1", "0.111191"], ["84006.5", "0.0416"], ["84006.4", "0.039636"], ["84006.2", "0"], ["84006.1", "0.022837"], ["84005.1", "0.096181"], ["84004.6", "0.013"], ["84004.5", "0.012882"], ["84004.3", "0"], ["84004.2", "0.089238"], ["84000.9", "0.05"], ["84000.7", "0"], ["83969.5", "0"], ["83969.1", "0"]], "a": [["84053.7", "0.002"], ["84060.5", "0.019002"], ["84062.1", "0.176913"], ["84062.5", "0.059399"], ["84069.1", "0.079396"], ["84076.1", "0.112835"], ["84081.9", "0.174779"], ["84082.5", "0.000516"], ["84083.9", "0.04"], ["84084", "0.04"], ["84084.5", "0"], ["84084.6", "0"], ["84113.6", "0"], ["84114", "0"], ["84114.8", "0"]], "u": 92022, "seq": 67563834447}, "cts": 1742569699115, "record_time": 1742569699.390137, "EXCHANGE": "BYBIT"}
{"topic": "orderbook.200.BTCUSDT", "ts": 1742569699320, "type": "delta", "data": {"s": "BTCUSDT", "b": [["84020.8", "0.173398"], ["84006.5", "0.041235"], ["84004.6", "0.012882"], ["84000.9", "0.049551"]], "a": [["84081.8", "0.082451"], ["84081.9", "0.171361"]], "u": 92023, "seq": 67563834470}, "cts": 1742569699310, "record_time": 1742569699.589668, "EXCHANGE": "BYBIT"}
{"topic": "orderbook.200.BTCUSDT", "ts": 1742569699519, "type": "delta", "data": {"s": "BTCUSDT", "b": [["84044.6", "0.262787"], ["84006.6", "0.04"], ["84006.4", "0"], ["84004.7", "0.014466"], ["84004.5", "0"], ["84001", "0.05"], ["84000.8", "0"], ["83969.5", "0.001333"]], "a": [["84056.4", "0"], ["84083.8", "0.099399"], ["84084", "0"], ["84091.1", "0"], ["84095.6", "0.119002"], ["84113.6", "0.000333"], ["84114", "0.059399"], ["84114.8", "0.00009"]], "u": 92024, "seq": 67563834497}, "cts": 1742569699516, "record_time": 1742569699.789917, "EXCHANGE": "BYBIT"}
{"topic": "orderbook.200.BTCUSDT", "ts": 1742569699719, "type": "delta", "data": {"s": "BTCUSDT", "b": [["84034.4", "0.118852"], ["83969.5", "0"]], "a": [["84062.5", "0"], ["84114.9", "0.000518"]], "u": 92025, "seq": 67563834512}, "cts": 1742569699656, "record_time": 1742569700.010541, "EXCHANGE": "BYBIT"}
{"topic": "orderbook.200.BTCUSDT", "ts": 1742569699920, "type": "delta", "data": {"s": "BTCUSDT", "b": [["84044.6", "0.091787"], ["84044.2", "0"], ["84036.6", "0"], ["84035.2", "0.000153"], ["84034.4", "0"], ["84033.8", "0"], ["84032.6", "0"], ["84027.1", "0"], ["84024.1", "0.227434"], ["84021.8", "0"], ["84021", "0"], ["84020.1", "0"], ["84019.3", "0"], ["84016.8", "0.11924"], ["84013.1", "0"], ["84006.6", "0"], ["84006.4", "0.039636"], ["84005.1", "0.096173"], ["84004.7", "0.001466"], ["84004.5", "0.012882"], ["84004.2", "0"], ["83969.5", "0.001333"], ["83969.1", "0.003552"], ["83968.9", "1.230455"], ["83968.2", "0.023803"], ["83967.8", "0.001466"], ["83967.3", "0.118852"], ["83967", "0.00052"], ["83966.9", "0.01002"], ["83966.8", "0.023805"], ["83966.5", "0.002469"]], "a": [["84044.7", "0.496448"], ["84053.1", "0.018625"], ["84053.2", "0.002"], ["84062.1", "0.115727"], ["84062.5", "0.059399"], ["84069.1", "0.023798"], ["84076", "0.07008"], ["84076.1", "0"], ["84076.9", "0"], ["84081.8", "0.079033"], ["84081.9", "0.174779"], ["84083.8", "0.059399"], ["84084", "0.04"], ["84084.2", "0.063519"], ["84087", "0"], ["84114.8", "0"], ["84114.9", "0"]], "u": 92026, "seq": 67563834566}, "cts": 1742569699907, "record_time": 1742569700.190281, "EXCHANGE": "BYBIT"}
{"topic": "orderbook.200.BTCUSDT", "ts": 1742569700120, "type": "delta", "data": {"s": "BTCUSDT", "b": [["84033.3", "0.158195"], ["84029.9", "0.116558"], ["84027.6", "0"], ["84024.1", "0.130703"], ["84020.8", "0.070196"], ["84014.3", "0.179077"], ["84012.6", "0.178477"], ["84008.4", "0.178567"], ["84006.6", "0.04"], ["84006.4", "0"], ["84001", "0.049551"]], "a": [["84076", "0"], ["84083.8", "0.099399"], ["84084", "0"], ["84114.8", "0.00009"], ["84114.9", "0.000518"]], "u": 92027, "seq": 67563834612}, "cts": 1742569700117, "record_time": 1742569700.38957, "EXCHANGE": "BYBIT"}
{"topic": "orderbook.200.BTCUSDT", "ts": 1742569700320, "type": "delta", "data": {"s": "BTCUSDT", "b": [["84014.3", "0.0006"], ["84012.6", "0"], ["84004.7", "0.014466"], ["84004.5", "0"], ["83966.4", "0.00018"], ["83966.1", "0.059518"]], "a": [["84069.8", "0"], ["84081.8", "0.082451"], ["84081.9", "0.171361"], ["84099.3", "0.008285"]], "u": 92028, "seq": 67563834664}, "cts": 1742569700306, "record_time": 1742569700.589812, "EXCHANGE": "BYBIT"}
{"topic": "orderbook.200.BTCUSDT", "ts": 1742569700519, "type": "delta", "data": {"s": "BTCUSDT", "b": [["84035.2", "0"], ["84034.7", "0.000153"], ["84011.7", "0.111998"]], "a": [["84057.7", "0.004909"], ["84061.5", "0.089099"], ["84114.9", "0"]], "u": 92029, "seq": 67563834702}, "cts": 1742569700517, "record_time": 1742569700.788887, "EXCHANGE": "BYBIT"}
{"topic": "orderbook.200.BTCUSDT", "ts": 1742569700719, "type": "delta", "data": {"s": "BTCUSDT", "b": [["84044.6", "0.335487"], ["84044.2", "0.021608"], ["84037.4", "0.000486"], ["84037.3", "0.071431"], ["84034.7", "0"], ["84034.3", "0"], ["84033.4", "0.009572"], ["84032", "0.112099"], ["84022.2", "0.176662"], ["84008.4", "0.00009"], ["83966.4", "0"], ["83966.1", "0"]], "a": [["84044.7", "0.307331"], ["84045.6", "0"], ["84057.2", "0.119476"], ["84057.7", "0.001333"], ["84059.3", "0"], ["84059.6", "0"], ["84060.9", "0"], ["84062.6", "0.009515"], ["84068.6", "0.004092"], ["84114.9", "0.000518"], ["84115.7", "0.001466"], ["84116.2", "0.028203"]], "u": 92030, "seq": 67563834768}, "cts": 1742569700717, "record_time": 1742569700.989559, "EXCHANGE": "BYBIT"}
{"success": true, "ret_msg": "subscribe", "conn_id": "42090351-68c6-491c-8113-6d4f7b405345", "op": "subscribe", "record_time": 1742569756.871079, "EXCHANGE": "BYBIT"}
{"topic": "orderbook.200.BTCUSDT", "ts": 1742569754320, "type": "snapshot", "data": {"s": "BTCUSDT", "b": [["84074.2", "0.00787"], ["84074.1", "0.001466"], ["84073.3", "0.000516"], ["84072.7", "0.071401"], ["84071", "0.000333"], ["84070.3", "0.001333"], ["84070", "0.003667"], ["84069.4", "0.001466"], ["84069.2", "0.00396"], ["84068.6", "0.000516"], ["84066.9", "0.000297"], ["84066.8", "0.000333"], ["84066.7", "0.000297"], ["84066.6", "0.089919"], ["84066.5", "0.171"], ["84066.1", "0.001333"], ["84065.8", "0.018667"], ["84065.7", "0.0012"], ["84064.8", "0.001466"], ["84064", "0.000516"], ["84063.4", "0.000153"], ["84063.1", "0.071409"], ["84062.6", "0.000333"], ["84062", "0.063727"], ["84061.9", "0.045333"], ["84061.8", "0.04"], ["84061.6", "0.003668"], ["84060.2", "0.041466"], ["84060.1", "0.044"], ["84060", "0.071471"], ["84059.7", "0.03729"], ["84059.4", "0.000516"], ["84058.8", "0.154225"], ["84058.5", "0.04"], ["84058.4", "0.044333"], ["84057.7", "0.060732"], ["84057.6", "0.171"], ["84057.3", "0.003668"], ["84056.8", "0.04"], ["84056.7", "0.044028"], ["84055.6", "0.001466"], ["84055.3", "0.052"], ["84055.1", "0.048"], ["84054.8", "0.000516"], ["84054.2", "0.000333"], ["84053.5", "0.001333"], ["84053.4", "0.123348"], ["84053.1", "0.033664"], ["84052.9", "0.018767"], ["84052.1", "0.178461"], ["84051.9", "0.0003"], ["84050.9", "0.001466"], ["84050.7", "0.178412"], ["84050.4", "0.399244"], ["84050.1", "0.000516"], ["84050", "0.000333"], ["84049.3", "0.001333"], ["84048.9", "0.131953"], ["84048.5", "0.116379"], ["84048.3", "0.059399"], ["84048.2", "0.167706"], ["84048.1", "0.000361"], ["84047.9", "0.006094"], ["84047", "0.000118"], ["84046.6", "0.024434"], ["84046.4", "0.516686"], ["84046.3", "0.172466"], ["84045.8", "0.000333"], ["84045.7", "0.000691"], ["84045.5", "0.25879"], ["84045.1", "0.001333"], ["84044.7", "0.003663"], ["84044.6", "0.0006"], ["84043.9", "0.0006"], ["84043.7", "0.118852"], ["84043.5", "0.562285"], ["84042.3", "0.178414"], ["84042", "0.00009"], ["84041.7", "0.001466"], ["84041.6", "0.000333"], ["84041.4", "0.04"], ["84041.3", "0.039631"], ["84040.9", "0.001849"], ["84040.5", "0.003663"], ["84040", "0.00006"], ["84039.6", "0.147077"], ["84039.5", "0.379754"], ["84039.4", "0.01288"], ["84038.1", "0.178414"], ["84037.9", "0.118852"], ["84037.8", "0.004651"], ["84037.4", "0.000333"], ["84037.1", "0.001466"], ["84036.7", "0.001333"], ["84036.6", "0.0016"], ["84036.3", "0.00416"], ["84035.8", "0.049545"], ["84035.7", "0.049545"], ["84034.6", "0.011901"], ["84033.6", "0.00009"], ["84033.4", "0.0006"], ["84033.2", "0.252101"], ["84033.1", "0.171"], ["84032.5", "0.001333"], ["84032.4", "0.001466"], ["84032.1", "0.003643"], ["84031.7", "0.001116"], ["84031.3", "0.015"], ["84031", "0.353364"], ["84030.6", "0.096136"], ["84029.9", "0.118852"], ["84029", "0.000333"], ["84028.3", "0.001333"], ["84027.9", "0.003642"], ["84027.8", "0.001466"], ["84027.4", "0.022323"], ["84027.3", "0.059399"], ["84027", "0.000516"], ["84026.8", "0.12489"], ["84026", "0.000361"], ["84025.8", "0.014045"], ["84025.2", "0.00009"], ["84024.8", "0.000333"], ["84024.7", "0.133349"], ["84024.6", "0.127384"], ["84024.5", "0.118852"], ["84024.2", "0.009"], ["84024.1", "0.001333"], ["84023.9", "0.171"], ["84023.7", "0.003641"], ["84023.2", "0.002066"], ["84022.8", "0.005947"], ["84022.4", "0.000516"], ["84020.8", "0.070196"], ["84020.6", "0.000333"], ["84020", "0.00006"], ["84019.9", "0.001333"], ["84019.5", "0.00364"], ["84018.8", "0.023787"], ["84018.6", "0.001466"], ["84017.8", "0.059915"], ["84017.4", "0.023787"], ["84016.8", "0.118942"], ["84016.4", "0.000333"], ["84015.7", "0.02512"], ["84015.3", "0.076391"], ["84015.2", "0.171"], ["84014.9", "0.023787"], ["84014.3", "0.0006"], ["84014", "0.001466"], ["84013.8", "0.023787"], ["84013.4", "0.178543"], ["84013.2", "0.000516"], ["84012.9", "0.089207"], ["84012.6", "0.044"], ["84012.3", "0.15783"], ["84012.2", "0.321089"], ["84011.5", "0.001333"], ["84011.2", "0.015"], ["84011.1", "0.003639"], ["84010.9", "0.04"], ["84010.7", "0.044"], ["84010.6", "0.122427"], ["84009.3", "0.001466"], ["84009", "0.04"], ["84008.8", "0.044"], ["84008.5", "0.000516"], ["84008.4", "0.059579"], ["84008", "0.000333"], ["84007.3", "0.041333"], ["84007.1", "0.04"], ["84006.9", "0.055636"], ["84006.7", "0.171"], ["84005.9", "0.005"], ["84005.8", "0.124888"], ["84005.7", "0.048"], ["84005.3", "0.118852"], ["84004.7", "0.001466"], ["84003.9", "0.000877"], ["84003.8", "0.059753"], ["84003.6", "3.446265"], ["84003.1", "0.001333"], ["84002.7", "0.003636"], ["84001.9", "0.023793"], ["84000.6", "0.013095"], ["84000.1", "0.120318"], ["84000", "0.02897"], ["83999.6", "0.000333"], ["83999.3", "0.00052"], ["83998.9", "0.001333"], ["83998.5", "0.003552"], ["83998.2", "0.171"], ["83998", "0.248176"], ["83997.6", "0.01872"], ["83997.5", "3.750551"], ["83996.1", "0.000875"], ["83995.8", "0.320756"], ["83995.5", "0.001466"], ["83995.4", "0.012327"], ["83994.7", "0.001853"]], "a": [["84074.3", "0.827078"], ["84074.4", "0.226862"], ["84074.6", "0.389008"], ["84075", "0.008276"], ["84075.1", "0.071399"], ["84075.2", "0.042048"], ["84075.3", "0.02"], ["84078.5", "0.130885"], ["84078.7", "0.001333"], ["84078.9", "0.089099"], ["84079.4", "0.000536"], ["84080", "0.159183"], ["84080.1", "0.33761"], ["84081.8", "0.10659"], ["84082.2", "0.071393"], ["84082.5", "0.000516"], ["84082.6", "0.00367"], ["84082.7", "0.015"], ["84082.9", "0.001333"], ["84083.3", "0.001466"], ["84083.6", "0.000333"], ["84083.7", "0.024794"], ["84085.3", "0.06"], ["84085.9", "0.083032"], ["84086.3", "0.089099"], ["84086.6", "0.071389"], ["84086.8", "0.00367"], ["84086.9", "0.03135"], ["84087.1", "0.001849"], ["84087.3", "0.015"], ["84087.7", "0.02134"], ["84087.8", "0.000333"], ["84087.9", "0.001466"], ["84089.6", "0.00009"], ["84089.7", "0.0001"], ["84090", "0.111706"], ["84090.7", "0.178414"], ["84091", "0.234334"], ["84091.3", "0.041333"], ["84091.6", "0.0006"], ["84091.8", "0.040518"], ["84092", "0.000333"], ["84092.5", "0.178375"], ["84092.6", "0.001466"], ["84092.7", "0.217871"], ["84092.8", "0.178412"], ["84093.3", "0.019816"], ["84093.6", "0.178414"], ["84094.1", "0.178372"], ["84094.2", "0.04"], ["84095.2", "0.003561"], ["84095.5", "0.001333"], ["84095.8", "0.059399"], ["84095.9", "0.04"], ["84096", "0.11638"], ["84096.2", "0.000333"], ["84096.3", "0.04"], ["84096.4", "0.000518"], ["84096.6", "0.04"], ["84096.8", "0.04"], ["84097", "0.178412"], ["84097.2", "0.001466"], ["84097.5", "0.09763"], ["84097.6", "0.116032"], ["84097.7", "0.04"], ["84097.9", "0.0006"], ["84098", "0.00009"], ["84098.5", "0.023787"], ["84099", "0.089099"], ["84099.1", "0.178361"], ["84099.3", "0.04"], ["84099.4", "0.003562"], ["84099.7", "0.001333"], ["84099.8", "0.005946"], ["84100", "0.003576"], ["84100.3", "0.00465"], ["84100.4", "0.000333"], ["84101", "0.124039"], ["84101.5", "0.023787"], ["84101.7", "0.0006"], ["84101.8", "0.001466"], ["84102.4", "0.023787"], ["84102.5", "0.0012"], ["84102.8", "0.000297"], ["84103.1", "0.035689"], ["84103.2", "0.023787"], ["84103.5", "0.001526"], ["84103.6", "0.122415"], ["84103.7", "0.552036"], ["84103.9", "0.003436"], ["84104", "0.000361"], ["84104.2", "0.0006"], ["84104.6", "0.060723"], ["84104.9", "0.000297"], ["84105.6", "0.000518"], ["84105.9", "0.005"], ["84106.4", "0.001556"], ["84106.5", "0.003575"], ["84107.4", "0.171"], ["84107.8", "0.003563"], ["84108.1", "0.001333"], ["84108.7", "0.130829"], ["84108.9", "0.000333"], ["84109.7", "0.063523"], ["84109.9", "0.0006"], ["84110.3", "0.000518"], ["84110.9", "0.124888"], ["84111", "0.089099"], ["84111.1", "0.001549"], ["84111.2", "0.015"], ["84112", "0.003563"], ["84112.2", "0.118852"], ["84112.3", "0.004821"], ["84112.6", "0.0006"], ["84113.1", "0.000333"], ["84113.6", "0.000333"], ["84113.7", "0.785441"], ["84114", "0.059399"], ["84114.1", "0.04"], ["84114.2", "0.571176"], ["84114.5", "0.023784"], ["84114.7", "0.30708"], ["84114.8", "0.00009"], ["84114.9", "0.000518"], ["84115", "0.011899"], ["84115.1", "0.003575"], ["84115.4", "0.023784"], ["84115.7", "0.001466"], ["84115.9", "0.171"], ["84116.2", "1.45452"], ["84116.6", "0.001333"], ["84117", "0.000118"], ["84117.3", "0.000333"], ["84117.4", "0.118852"], ["84118", "0.089206"], ["84118.4", "0.023784"], ["84118.8", "0.0016"], ["84119", "0.094864"], ["84119.1", "0.195"], ["84119.3", "0.023784"], ["84119.5", "0.000518"], ["84120.1", "0.023784"], ["84120.3", "0.001466"], ["84120.4", "0.003564"], ["84120.8", "0.001333"], ["84121.1", "0.114"], ["84121.3", "0.00015"], ["84121.5", "0.000333"], ["84122.2", "0.039588"], ["84123.2", "0.00009"], ["84123.4", "0.118852"], ["84123.5", "0.059399"], ["84123.9", "0.002498"], ["84124.1", "0.000518"], ["84124.4", "0.171"], ["84124.6", "0.006049"], ["84124.9", "0.001466"], ["84125", "0.001333"], ["84125.6", "0.005946"], ["84125.7", "0.000333"], ["84126.1", "0.000361"], ["84127", "0.000204"], ["84128.6", "0.118852"], ["84128.8", "0.004067"], ["84129.2", "0.001333"], ["84129.4", "0.124865"], ["84129.6", "0.001466"], ["84129.7", "0.124865"], ["84129.9", "0.000333"], ["84130.2", "0.00315"], ["84130.8", "0.024847"], ["84131.1", "0.003575"], ["84131.6", "0.00009"], ["84132", "0.059399"], ["84132.5", "0.098009"], ["84132.9", "0.171"], ["84133", "0.003549"], ["84133.4", "0.001851"], ["84134.1", "0.003062"], ["84134.2", "0.001466"], ["84134.3", "0.178286"], ["84135.3", "0.118852"], ["84137.2", "0.003549"], ["84137.6", "0.016333"], ["84138", "0.000518"], ["84138.3", "0.000333"], ["84138.5", "0.024484"], ["84138.7", "3.685351"], ["84138.8", "0.028853"], ["84139", "0.089206"], ["84140", "0.00018"], ["84141.4", "0.171"], ["84141.5", "0.062948"], ["84141.8", "0.001333"], ["84142.5", "0.000333"], ["84142.6", "0.040518"], ["84142.9", "0.00594"], ["84143.4", "0.001466"], ["84143.5", "0.118852"], ["84143.7", "0.04"]], "u": 92297, "seq": 67563879377}, "cts": 1742569754317, "record_time": 1742569756.873081, "EXCHANGE": "BYBIT"}
{"topic": "orderbook.200.BTCUSDT", "ts": 1742569754520, "type": "delta", "data": {"s": "BTCUSDT", "b": [["84074.2", "0.103969"], ["84072.7", "0"], ["84070.4", "0.006263"], ["84067.3", "0.020307"], ["84067.2", "0.067691"], ["84065.8", "0.090073"], ["84060", "0.00006"], ["84059.4", "0.117931"], ["84041.6", "0.039963"], ["84041.5", "0.03963"], ["84041.4", "0"], ["84041.3", "0"], ["84039.7", "0.01288"], ["84039.6", "0.159957"], ["84039.5", "0.366754"], ["84039.4", "0"], ["84036", "0.049545"], ["84035.9", "0.049545"], ["84035.8", "0"], ["84035.7", "0"], ["83998", "0.023793"], ["83995.7", "0.224383"], ["83995.4", "0"], ["83994.7", "0"]], "a": [["84074.3", "0.829576"], ["84078.1", "0.005646"], ["84083.9", "0.112512"], ["84093.4", "0.04"], ["84097.6", "0.063787"], ["84103.1", "0"], ["84123.9", "0"], ["84143.7", "0"]], "u": 92298, "seq": 67563879508}, "cts": 1742569754517, "record_time": 1742569756.87408, "EXCHANGE": "BYBIT"}
{"topic": "orderbook.200.BTCUSDT", "ts": 1742569754719, "type": "delta", "data": {"s": "BTCUSDT", "b": [["84074.2", "0.202878"], ["84059.4", "0.000516"], ["84058.8", "0.224175"], ["84056.9", "0.008126"], ["84055.8", "0.118852"], ["84055.7", "0.178453"], ["84045.3", "0.178414"], ["84041.8", "0.04"], ["84041.7", "0.041096"], ["84041.6", "0.000333"], ["84041.5", "0"], ["84039.9", "0.013"], ["84039.8", "0.01288"], ["84039.7", "0"], ["84039.6", "0.147077"], ["84036.2", "0.05"], ["84036.1", "0.049544"], ["84036", "0"], ["84035.9", "0"], ["83997.5", "0"], ["83996.1", "0"], ["83995.8", "0"], ["83995.7", "0"], ["83995.5", "0"]], "a": [["84074.3", "0.656078"], ["84074.4", "0.144284"], ["84074.6", "0.12"], ["84075", "0"], ["84078.9", "0"], ["84083.9", "0"], ["84097.7", "0"], ["84099.2", "0.035691"], ["84112.3", "0.001333"], ["84112.5", "0.003488"], ["84114.1", "0"], ["84114.2", "0.531176"], ["84114.3", "0.04"], ["84114.4", "0.04"], ["84116.8", "0.002497"]], "u": 92299, "seq": 67563879629}, "cts": 1742569754712, "record_time": 1742569756.87508, "EXCHANGE": "BYBIT"}
{"topic": "orderbook.200.BTCUSDT", "ts": 1742569754919, "type": "delta", "data": {"s": "BTCUSDT", "b": [["84064.6", "0.000153"], ["84063.4", "0"], ["84054.2", "0.178789"], ["84046.5", "0.178414"], ["84046.4", "0"], ["84041.8", "0"], ["84041.6", "0.039963"], ["84039.9", "0"], ["84039.7", "0.01288"], ["84038.1", "0"], ["84036.3", "0.037621"], ["84030.6", "0.096144"], ["83997.5", "3.750551"], ["83996.1", "0.000875"]], "a": [["84074.3", "0.510546"], ["84074.4", "0"], ["84074.5", "0.105554"], ["84074.6", "0.1"], ["84075.3", "0"], ["84080.1", "0.33461"], ["84085.9", "0.043919"], ["84086.3", "0"], ["84093.2", "0.052241"], ["84094.1", "0"], ["84096.1", "0.178414"], ["84100", "0"], ["84100.3", "0.521731"], ["84103.6", "0.003563"], ["84112.5", "0"], ["84112.6", "0.004088"], ["84114.2", "0.014095"], ["84114.3", "0"], ["84114.5", "0.063784"], ["84143.7", "0.04"], ["84143.9", "0.000573"], ["84145.7", "0.003549"], ["84146", "0.001333"]], "u": 92300, "seq": 67563879708}, "cts": 1742569754912, "record_time": 1742569756.878123, "EXCHANGE": "BYBIT"}
{"topic": "orderbook.200.BTCUSDT", "ts": 1742569755120, "type": "delta", "data": {"s": "BTCUSDT", "b": [["84050.4", "0.00009"], ["84048.2", "0"], ["84047.8", "0.178414"], ["84045.3", "0"], ["84041.7", "0.001466"], ["84041.5", "0.03963"], ["84039.8", "0"], ["84039.6", "0.159957"], ["84036.2", "0"], ["84036.1", "0"], ["84036", "0.049545"], ["84035.9", "0.049545"], ["83995.8", "0.320756"]], "a": [["84074.5", "0"], ["84075.2", "0"], ["84089.9", "0.04"], ["84091.6", "0.0406"], ["84096.6", "0.217898"], ["84112.6", "0.0006"], ["84112.7", "0.003488"], ["84114.4", "0"], ["84114.6", "0.04"]], "u": 92301, "seq": 67563879753}, "cts": 1742569755109, "record_time": 1742569756.879123, "EXCHANGE": "BYBIT"}
{"topic": "orderbook.200.BTCUSDT", "ts": 1742569755319, "type": "delta", "data": {"s": "BTCUSDT", "b": [["84074.2", "0.104207"], ["84064.6", "0"], ["84062", "0.098748"], ["84059.6", "0.0238"], ["84059.4", "0.120005"], ["84055.7", "0"], ["84054.2", "0.000333"], ["84052.1", "0"], ["84048.9", "0.312432"], ["84047.8", "0"], ["84041.9", "0.283347"], ["84041.6", "0.000333"], ["84041.5", "0"], ["84041.4", "0.03963"], ["84041.3", "0.039631"], ["84039.7", "0"], ["84039.6", "0.147077"], ["84039.5", "0.379634"], ["84039.4", "0.01288"], ["84039.2", "0.516686"], ["84036", "0"], ["84035.9", "0"], ["84035.8", "0.05"], ["84035.7", "0.049545"], ["84030.6", "0"], ["84027.8", "0.09761"], ["84013.4", "0"], ["83995.7", "0.224383"], ["83995.5", "0.001466"]], "a": [["84074.5", "0.09294"], ["84077.7", "0.089099"], ["84081.1", "0.008307"], ["84083.9", "0.124243"], ["84085.2", "0.088649"], ["84085.9", "0.089099"], ["84092.5", "0"], ["84092.7", "0.322782"], ["84094.2", "0"], ["84094.4", "0.184622"], ["84095.9", "0"], ["84096.6", "0.04"], ["84099.1", "0"], ["84101.4", "0.305523"], ["84134.3", "0"], ["84145.7", "0"], ["84146", "0"]], "u": 92302, "seq": 67563879833}, "cts": 1742569755311, "record_time": 1742569756.880124, "EXCHANGE": "BYBIT"}
{"topic": "orderbook.200.BTCUSDT", "ts": 1742569755520, "type": "delta", "data": {"s": "BTCUSDT", "b": [["84074.2", "0.164007"], ["84063.9", "0.000153"], ["84062", "0.099358"], ["84059.4", "0.12204"], ["84053.4", "0.06981"], ["84048.9", "0.300679"], ["84045.3", "0.178414"], ["84041.9", "0.309672"], ["84041.4", "0"], ["84041.2", "0.039631"], ["84039.5", "0.366754"], ["84039.3", "0.01288"], ["84038.1", "0.178414"], ["83996.1", "0"], ["83995.8", "0"], ["83995.7", "0"], ["83995.5", "0"]], "a": [["84074.3", "0.681546"], ["84083.9", "0.11427"], ["84094.4", "0.171083"], ["84096.1", "0"], ["84099.1", "0.003576"], ["84101", "0.285975"], ["84101.4", "0.302472"]], "u": 92303, "seq": 67563879910}, "cts": 1742569755514, "record_time": 1742569756.882124, "EXCHANGE": "BYBIT"}
{"topic": "orderbook.200.BTCUSDT", "ts": 1742569755720, "type": "delta", "data": {"s": "BTCUSDT", "b": [["84074.2", "0.26152"], ["84066", "0.000153"], ["84063.9", "0"], ["84062", "0.100142"], ["84061.1", "0.124136"], ["84059.4", "0.000516"], ["84050.6", "0.180784"], ["84048.9", "0.131953"], ["84043.6", "0.307623"], ["84041.9", "0"], ["84041.7", "0.041466"], ["84041.6", "0.039963"], ["84041.3", "0"], ["84041.2", "0"], ["84039.8", "0.013"], ["84039.7", "0.01288"], ["84039.4", "0"], ["84039.3", "0"], ["84038.1", "0"], ["84036.1", "0.05"], ["84036", "0.049545"], ["84035.8", "0"], ["84035.7", "0"], ["83996.1", "0.000875"]], "a": [["84074.3", "0.510546"], ["84083.9", "0"], ["84085.6", "0.12339"], ["84092.7", "0.217871"], ["84094.4", "0"], ["84096.1", "0.167458"], ["84099.1", "0"], ["84101.4", "0"], ["84103.1", "0.281059"], ["84112.4", "0.003488"], ["84112.7", "0"], ["84114.2", "0.054095"], ["84114.3", "0.04"], ["84114.5", "0.023784"], ["84114.6", "0"], ["84145.7", "0.003549"]], "u": 92304, "seq": 67563879986}, "cts": 1742569755709, "record_time": 1742569756.883124, "EXCHANGE": "BYBIT"}
{"topic": "orderbook.200.BTCUSDT", "ts": 1742569755919, "type": "delta", "data": {"s": "BTCUSDT", "b": [["84074.2", "0"], ["84074.1", "0"], ["84073.3", "0"], ["84071", "0"], ["84070.4", "0"], ["84070.3", "0"], ["84070", "0"], ["84069.4", "0"], ["84069.2", "0"], ["84068.6", "0"], ["84067.3", "0"], ["84067.2", "0"], ["84066.9", "0"], ["84066.8", "0"], ["84066.7", "0"], ["84066.6", "0"], ["84066.5", "0"], ["84066.1", "0"], ["84066", "0"], ["84065.8", "0"], ["84065.7", "0"], ["84064.8", "0"], ["84064", "0"], ["84063.1", "0"], ["84062.6", "0"], ["84062", "0"], ["84061.9", "0"], ["84061.8", "0"], ["84061.6", "0.006642"], ["84061.1", "0"], ["84060.2", "0.001466"], ["84060.1", "0"], ["84059.7", "0"], ["84059.6", "0"], ["84058.8", "0"], ["84058.5", "0"], ["84058.4", "0.000333"], ["84057.7", "0.001333"], ["84057.6", "0"], ["84056.9", "0"], ["84056.8", "0"], ["84056.7", "0"], ["84055.8", "0"], ["84055.3", "0"], ["84055.1", "0"], ["84054.7", "0.015"], ["84053.4", "0"], ["84053.1", "0.003664"], ["84052.9", "0"], ["84051.9", "0.02594"], ["84051.8", "0.044"], ["84051.5", "0.04"], ["84050.7", "0"], ["84050.6", "0"], ["84050.4", "0"], ["84048.9", "0.003663"], ["84048.5", "0"], ["84048.3", "0"], ["84048.1", "0.026001"], ["84048", "0.044"], ["84047.9", "0"], ["84047", "0"], ["84046.6", "0"], ["84046.5", "0"], ["84046.3", "0.001466"], ["84046.2", "0.095432"], ["84046.1", "0.171"], ["84045.5", "0.000516"], ["84045.3", "0"], ["84044.3", "0.018767"], ["84043.7", "0"], ["84043.6", "0"], ["84043.5", "0"], ["84043.4", "0.005947"], ["84043.2", "0.052"], ["84043", "0.048"], ["84042.3", "0"], ["84041.7", "0.001466"], ["84041.6", "0.000333"], ["84041.2", "0.004035"], ["84040.4", "0.009438"], ["84039.8", "0"], ["84039.7", "0"], ["84039.6", "0"], ["84039.5", "0"], ["84039.2", "0"], ["84038", "0.044284"], ["84037.9", "0"], ["84037.8", "0"], ["84036.2", "0.035696"], ["84036.1", "0.03732"], ["84036", "0"], ["84033.9", "0.17844"], ["84033.3", "0.178251"], ["84032.7", "0.17844"], ["84031", "0"], ["84029.9", "0.116375"], ["84029.7", "0.17844"], ["84027.8", "0.001466"], ["84027.3", "0"], ["84026.8", "0"], ["84025.8", "0"], ["84025.6", "0.04"], ["84025.5", "0.039634"], ["84024.8", "0.059732"], ["84024.6", "0.0025"], ["84024.5", "0"], ["84023.7", "0.016522"], ["84023.6", "0.012881"], ["84023.2", "0.120918"], ["84022.8", "0"], ["84021", "0.023788"], ["84020.1", "0.049548"], ["84020", "0.049609"], ["84018.8", "0"], ["84017.8", "0.000516"], ["84017.4", "0"], ["84016.9", "0.118852"], ["84016.8", "0.00009"], ["84015.7", "0.001333"], ["84014.9", "0"], ["84013.8", "0"], ["84013.6", "0.059399"], ["84013.2", "0.006463"], ["84012.9", "0"], ["84012.2", "0.000333"], ["84010.6", "0.118852"], ["84008.4", "0.00018"], ["84005.8", "0.023792"], ["84005", "0.059399"], ["84004.3", "0.02379"], ["84004.1", "0.023792"], ["84003.6", "0"], ["84003.3", "0.353345"], ["84000.6", "0"], ["83998.9", "0.004908"], ["83997.5", "0"], ["83995.8", "0.320756"], ["83995.5", "0.001466"], ["83995.4", "0.012327"], ["83994.7", "0.001853"], ["83994.3", "0.003552"], ["83993.8", "0.134766"], ["83993.6", "0.4"], ["83992.6", "0.04"], ["83992.2", "0.005879"], ["83991.8", "1.23012"], ["83991.7", "0.118852"], ["83991.6", "0.059489"], ["83991.2", "0.000333"], ["83990.9", "0.001466"], ["83990.6", "0.011995"], ["83990.5", "0.001333"], ["83990.1", "0.004072"], ["83990", "0.000237"], ["83989.5", "0.043767"], ["83989.3", "0.011848"], ["83989.2", "0.011848"], ["83989.1", "0.01185"], ["83989", "0.001247"], ["83988.4", "0.224383"], ["83987", "0.000333"], ["83986.8", "0.023988"], ["83986.7", "0.0237"], ["83986.6", "0.012328"], ["83986.3", "0.001333"], ["83986.2", "0.001466"], ["83985.9", "0.052792"], ["83985.5", "0.048699"], ["83985.4", "0.00052"], ["83985.3", "0.09616"], ["83983.7", "0.118852"], ["83983.2", "0.00009"], ["83982.9", "0.059399"], ["83982.8", "0.000333"], ["83982.1", "0.001333"], ["83981.8", "0.000361"], ["83981.7", "0.003552"], ["83981.6", "0.001466"], ["83981.3", "0.003564"], ["83981.2", "0.05"], ["83980.8", "0.00052"], ["83979.7", "0.12"], ["83978.6", "0.000333"], ["83978.2", "0.011994"], ["83977.9", "0.001333"], ["83977.5", "0.123552"]], "a": [["84061.7", "0.365117"], ["84061.9", "0.134491"], ["84062", "0.02"], ["84062.7", "0.12"], ["84062.8", "0.110885"], ["84063.3", "0.000153"], ["84063.5", "0.098008"], ["84066.1", "0.001333"], ["84066.8", "0.208961"], ["84067.3", "0.135579"], ["84067.4", "0.289009"], ["84068.6", "0.000258"], ["84069.2", "0.106645"], ["84069.4", "0.001466"], ["84070", "0.00367"], ["84070.1", "0.03135"], ["84070.3", "0.001333"], ["84070.5", "0.005718"], ["84070.9", "0.02134"], ["84071.1", "0.134716"], ["84072.8", "0.00009"], ["84073.4", "0.021842"], ["84073.9", "0.04"], ["84074.1", "0.059399"], ["84074.2", "0.142432"], ["84074.3", "0.418712"], ["84074.5", "0.001333"], ["84074.6", "0"], ["84075.1", "0.04"], ["84075.2", "0.000333"], ["84075.3", "0.04"], ["84075.8", "0.015"], ["84077.6", "0.064523"], ["84077.9", "0.000516"], ["84078.1", "0"], ["84078.4", "0.00367"], ["84078.5", "0.02"], ["84078.7", "0.042799"], ["84078.9", "0.04"], ["84079.8", "0.04"], ["84079.9", "0.019816"], ["84080", "0.267585"], ["84080.1", "0.191"], ["84080.2", "0.17844"], ["84080.6", "0.17844"], ["84080.7", "0.004597"], ["84081.1", "0"], ["84081.2", "0.00009"], ["84081.8", "0"], ["84082.1", "0.552036"], ["84082.2", "0"], ["84082.7", "0"], ["84083.7", "0.0207"], ["84085", "0.517081"], ["84085.1", "0.059399"], ["84085.2", "0"], ["84085.3", "0"], ["84085.6", "0"], ["84086.3", "0.04"], ["84086.6", "0"], ["84086.9", "0"], ["84087.7", "0"], ["84090.7", "0.04"], ["84091", "0.224561"], ["84091.8", "0.000518"], ["84092.4", "0.003575"], ["84092.8", "0"], ["84093.2", "0"], ["84093.3", "0"], ["84093.6", "0"], ["84096.1", "0"], ["84096.6", "0"], ["84096.9", "0.118852"], ["84097", "0"], ["84098.1", "0.005947"], ["84099.3", "0"], ["84100.3", "0"], ["84101", "0.593105"], ["84103", "0.118852"], ["84103.1", "0"], ["84103.6", "1.42988"], ["84103.7", "0"], ["84108.7", "0.005946"], ["84109.7", "0"], ["84110.9", "0"], ["84112.4", "0"], ["84112.9", "0.003488"], ["84114.2", "0"], ["84114.3", "0"], ["84114.7", "0.04"], ["84114.8", "0.04009"], ["84116.2", "0.028203"], ["84116.5", "0.027893"], ["84118", "0"], ["84127.3", "0.085865"], ["84127.8", "3.445452"], ["84129.4", "0"], ["84130.8", "0"], ["84131.1", "0"], ["84132.5", "0"], ["84134.6", "0.614016"], ["84138", "0"], ["84138.3", "0"], ["84138.5", "0"], ["84138.7", "0"], ["84138.8", "0"], ["84139", "0"], ["84140", "0"], ["84141.4", "0"], ["84141.5", "0"], ["84141.8", "0"], ["84142.5", "0"], ["84142.6", "0"], ["84142.9", "0"], ["84143.4", "0"], ["84143.5", "0"], ["84143.7", "0"], ["84143.9", "0"], ["84145.7", "0"]], "u": 92305, "seq": 67563881645}, "cts": 1742569755917, "record_time": 1742569756.887167, "EXCHANGE": "BYBIT"}
{"topic": "orderbook.200.BTCUSDT", "ts": 1742569756119, "type": "delta", "data": {"s": "BTCUSDT", "b": [["84061.6", "0"], ["84060.2", "0"], ["84060", "0"], ["84059.4", "0"], ["84058.4", "0"], ["84057.7", "0"], ["84057.3", "0"], ["84055.6", "0"], ["84054.8", "0"], ["84054.7", "0"], ["84054.2", "0"], ["84053.5", "0"], ["84053.1", "0"], ["84051.9", "0"], ["84051.8", "0"], ["84051.5", "0"], ["84050.9", "0"], ["84050.1", "0"], ["84050", "0"], ["84049.3", "0"], ["84048.1", "0.000361"], ["84048", "0"], ["84046.2", "0"], ["84046.1", "0"], ["84044.3", "0"], ["84043.9", "0.002681"], ["84043.5", "0.015"], ["84043.2", "0"], ["84043", "0"], ["84041.3", "0.04"], ["84041.2", "0"], ["84040.5", "0.036378"], ["84040.4", "0"], ["84038.4", "0.044"], ["84037.7", "0.015891"], ["84037.2", "0.04"], ["84036.4", "0.0003"], ["84036.3", "0.00416"], ["84036.2", "0"], ["84034.6", "0"], ["84033.9", "0"], ["84033.5", "0.018767"], ["84033.4", "0.142655"], ["84033.3", "0.059399"], ["84033.2", "0.000333"], ["84032.7", "0"], ["84031.3", "0"], ["84030", "0.118852"], ["84029.7", "0"], ["84028.8", "0.071438"], ["84026.9", "0.009438"], ["84025.6", "0.011902"], ["84025.5", "0"], ["84023.7", "0.003641"], ["84023.6", "0"], ["84021", "0"], ["84020.1", "0"], ["84020", "0.00006"], ["84016.4", "0.517019"], ["84013.5", "0.562285"], ["84013.4", "0.049546"], ["84013.2", "0.000516"], ["84012.9", "0.05"], ["84012.3", "0"], ["84010.8", "0.074704"], ["84007", "0.152081"], ["84006.4", "0.004632"], ["84005.8", "0.124923"], ["84004.3", "0"], ["84004.1", "0"], ["84003.8", "0.065701"], ["84003.4", "0.159419"], ["84000", "0.02903"], ["83998.9", "0.001333"], ["83995.9", "0.023795"], ["83994.2", "0.023795"], ["83993.8", "0.230934"], ["83993.6", "0.423793"], ["83989.7", "0.171"], ["83988.4", "0"], ["83986.8", "0.011994"], ["83985.9", "0.02754"], ["83985.5", "0"], ["83985.3", "0"], ["83984.8", "0.124923"], ["83981.2", "0.171"], ["83977.3", "0.000083"], ["83977", "0.001466"], ["83976.7", "0.013098"], ["83976.6", "0.025519"], ["83976.2", "0.00052"], ["83975.9", "0.12"], ["83975.6", "0.045603"], ["83975.2", "3.446265"], ["83975", "0.224383"], ["83974.8", "0.00009"], ["83974.7", "0.118852"], ["83974.6", "0.0025"], ["83974.4", "0.000333"], ["83973.7", "0.001333"], ["83973.3", "0.003552"], ["83972.4", "0.001466"], ["83971.6", "0.00052"], ["83970.9", "0.089227"], ["83970.2", "0.000333"], ["83970", "0.007148"], ["83969.5", "0.001333"], ["83969.1", "3.754103"], ["83968.8", "0.027767"]], "a": [["84049", "0.632826"], ["84049.2", "0.098009"], ["84051.9", "0.019092"], ["84052", "0.491802"], ["84053.1", "0.000153"], ["84053.2", "0.014868"], ["84053.5", "0.001333"], ["84053.6", "0.148009"], ["84054.2", "0.000333"], ["84054.7", "0.042048"], ["84054.8", "0.050516"], ["84055.6", "0.001466"], ["84055.7", "0.05"], ["84057.3", "0.113248"], ["84057.4", "0.05"], ["84057.7", "0.001333"], ["84057.8", "0.171"], ["84058.2", "0.005335"], ["84058.4", "0.058485"], ["84059.4", "0.000516"], ["84059.9", "0.075272"], ["84060", "0.071411"], ["84060.1", "0.068007"], ["84060.2", "0.001466"], ["84060.4", "0.015675"], ["84060.7", "0.04268"], ["84060.9", "0.01045"], ["84061.1", "0.011436"], ["84061.6", "0.005225"], ["84061.7", "0.035335"], ["84061.9", "0.001333"], ["84062.6", "0.032936"], ["84062.7", "0.02"], ["84063.2", "0.033565"], ["84063.3", "0"], ["84063.4", "0.117472"], ["84063.5", "0"], ["84064", "0.000516"], ["84064.4", "0.00009"], ["84064.8", "0.001466"], ["84065.1", "0.023792"], ["84065.5", "0.09948"], ["84067.3", "0.065363"], ["84067.4", "0.191"], ["84067.6", "0.019816"], ["84069.2", "0"], ["84070.1", "0"], ["84070.5", "0.04"], ["84070.9", "0"], ["84071", "0.000333"], ["84071.1", "0"], ["84073.4", "0"], ["84073.5", "0.05948"], ["84073.8", "0.059399"], ["84074.1", "0"], ["84074.2", "0"], ["84074.3", "0.414337"], ["84074.4", "0.003575"], ["84075.5", "0.04"], ["84075.6", "0.053897"], ["84076.3", "0.04"], ["84076.8", "0.080974"], ["84076.9", "0.023519"], ["84077.1", "0.116375"], ["84077.6", "0"], ["84078.8", "0.04"], ["84079.9", "0"], ["84080.2", "0"], ["84080.6", "0"], ["84080.7", "0.023792"], ["84081.6", "0.023792"], ["84082", "0.118852"], ["84083.8", "0.003575"], ["84084.6", "0.023792"], ["84084.9", "0.218369"], ["84085.5", "0.023792"], ["84086.3", "0.063792"], ["84086.7", "0.02112"], ["84088.1", "0.013855"], ["84089.8", "0.118852"], ["84089.9", "0.124923"], ["84091.3", "0.001333"], ["84091.6", "0.0006"], ["84091.8", "0.006466"], ["84092.7", "0"], ["84093", "0.011902"], ["84093.4", "0"], ["84093.9", "1.426317"], ["84095.7", "0.064989"], ["84096", "0"], ["84096.3", "0"], ["84096.8", "0.105148"], ["84097", "0.089227"], ["84097.5", "0"], ["84097.6", "0.023787"], ["84098", "0.00018"], ["84098.3", "0.06353"], ["84101", "0.779146"], ["84103.6", "0.003563"], ["84104.9", "0.00067"], ["84106.5", "0"], ["84107.3", "0.054653"], ["84109.9", "0.00075"], ["84110.9", "0.124923"], ["84111", "0"], ["84113.7", "0"], ["84114.5", "0"], ["84115", "0"], ["84115.1", "0"], ["84115.4", "0"], ["84118", "0.089227"], ["84118.4", "0"], ["84119.3", "0"], ["84120.1", "0"], ["84120.4", "0"], ["84120.8", "0"], ["84121.1", "0"], ["84121.3", "0"], ["84121.5", "0"], ["84122.2", "0"], ["84123.2", "0"], ["84123.4", "0"], ["84123.5", "0"], ["84124.1", "0"], ["84124.4", "0"], ["84124.6", "0"], ["84124.9", "0"], ["84125", "0"], ["84125.6", "0"], ["84125.7", "0"], ["84126.1", "0"], ["84127", "0"], ["84127.3", "0"], ["84127.8", "0"], ["84128.6", "0"], ["84128.8", "0"], ["84129.2", "0"], ["84129.6", "0"], ["84129.7", "0"], ["84129.9", "0"], ["84130.2", "0"], ["84131.6", "0"], ["84132", "0"], ["84132.9", "0"], ["84133", "0"], ["84133.4", "0"], ["84134.1", "0"], ["84134.2", "0"], ["84134.6", "0"], ["84135.3", "0"], ["84137.2", "0"], ["84137.6", "0"]], "u": 92306, "seq": 67563883738}, "cts": 1742569756117, "record_time": 1742569756.888167, "EXCHANGE": "BYBIT"}
{"topic": "orderbook.200.BTCUSDT", "ts": 1742569756319, "type": "delta", "data": {"s": "BTCUSDT", "b": [["84043.9", "0.0006"], ["84043.5", "0"], ["84043.4", "0"], ["84042.5", "0.071426"], ["84042.4", "0.065651"], ["84042.1", "0.012376"], ["84041.4", "0.039058"], ["84040.5", "0.018663"], ["84038.3", "0.04"], ["84038.1", "0.044"], ["84038", "0"], ["84037.9", "0.024755"], ["84037.7", "0"], ["84037.3", "0.049151"], ["84037.2", "0"], ["84036.7", "0.041333"], ["84036.4", "0"], ["84036.3", "0.04416"], ["84033.1", "0.181941"], ["84033", "0.052"], ["84032.9", "0.048"], ["84032.7", "0.0003"], ["84031.1", "0.071436"], ["84030.2", "0.004035"], ["84029.9", "0"], ["84028.8", "0"], ["84028.4", "0.071438"], ["84027.6", "0.002081"], ["84027.5", "0.013389"], ["84027.4", "0"], ["84025.6", "0"], ["84025.3", "0.116374"], ["84025.2", "0.00183"], ["84024.7", "0.001427"], ["84024", "0.088823"], ["84022.6", "0.178467"], ["84022", "0.181952"], ["84021.3", "0.178467"], ["84020.8", "0"], ["84017.1", "0.178467"], ["84016.8", "0.011993"], ["84016.5", "0.438241"], ["84015.9", "0.079262"], ["84015.3", "0.00364"], ["84014", "0.014346"], ["84013.9", "0.01288"], ["84013.4", "0"], ["84012.9", "0"], ["84010.7", "0"], ["84010.4", "0.049545"], ["84010.3", "0.049545"], ["84008.8", "0"], ["84007.3", "0.001333"], ["84007.1", "0"], ["84006.9", "0.003636"], ["84004.4", "0.024067"], ["84003.6", "0.307486"], ["84002.3", "0.096168"], ["83996", "0.023796"], ["83993.8", "0.134766"], ["83991.8", "0"], ["83979.7", "0"], ["83977.5", "0.003552"], ["83975.6", "0"], ["83974.6", "0"], ["83974.4", "0"], ["83973.7", "0"], ["83973.3", "0"], ["83972.4", "0"], ["83971.6", "0"], ["83970.9", "0"], ["83970.2", "0"], ["83970", "0"], ["83969.5", "0"], ["83969.1", "0"], ["83968.8", "0"]], "a": [["84049", "0.602699"], ["84049.1", "0.101389"], ["84050.4", "0.000153"], ["84051.9", "0"], ["84052", "0.191"], ["84053.1", "0"], ["84054.7", "0"], ["84055.5", "0.125911"], ["84055.6", "0.072881"], ["84055.8", "0.011437"], ["84056.5", "0.04268"], ["84057.3", "0.003669"], ["84058.2", "0.02134"], ["84059.9", "0.109989"], ["84060", "0.094284"], ["84060.7", "0"], ["84061.1", "0"], ["84061.6", "0.008894"], ["84061.9", "0.111006"], ["84064.8", "0.041466"], ["84065.8", "0.003669"], ["84067.2", "0.04"], ["84068.2", "0.04"], ["84068.6", "0.000516"], ["84070.5", "0.218467"], ["84071.4", "0.04"], ["84071.7", "0.178467"], ["84073.3", "0.000516"], ["84073.8", "0.249442"], ["84073.9", "0"], ["84074.1", "0.001466"], ["84074.3", "0.412097"], ["84075.3", "0"], ["84075.6", "0"], ["84076", "0.178467"], ["84076.8", "0.114832"], ["84076.9", "0"], ["84078", "0.04"], ["84078.7", "0.002799"], ["84079.8", "0"], ["84084.5", "0.011903"], ["84086.3", "0.023792"], ["84089.7", "0.156293"], ["84090", "0"], ["84090.2", "0.30717"], ["84090.7", "0"], ["84090.9", "1.426317"], ["84093.9", "0"], ["84095.7", "0"], ["84098.3", "0"], ["84101", "0.000518"], ["84106.2", "0.178467"], ["84108.7", "0.130873"], ["84111.7", "0.023842"], ["84119", "0"], ["84119.1", "0"], ["84119.5", "0"], ["84120.3", "0"]], "u": 92307, "seq": 67563884045}, "cts": 1742569756317, "record_time": 1742569756.889167, "EXCHANGE": "BYBIT"}
{"topic": "orderbook.200.BTCUSDT", "ts": 1742569756519, "type": "delta", "data": {"s": "BTCUSDT", "b": [["84048.9", "0"], ["84048.1", "0"], ["84046.3", "0"], ["84045.8", "0"], ["84045.7", "0"], ["84045.5", "0"], ["84045.1", "0"], ["84044.7", "0"], ["84044.6", "0"], ["84043.9", "0"], ["84042.5", "0"], ["84042.4", "0"], ["84042.1", "0"], ["84042", "0"], ["84041.7", "0.000929"], ["84041.4", "0"], ["84041.3", "0"], ["84040.5", "0.003663"], ["84038.4", "0"], ["84038.3", "0"], ["84038.1", "0"], ["84037.9", "0"], ["84037.3", "0"], ["84036.7", "0.001333"], ["84036.6", "0"], ["84036.3", "0.00416"], ["84036.1", "0"], ["84034.9", "0.012317"], ["84034.6", "0.052855"], ["84033.9", "0.044"], ["84033.5", "0"], ["84033.4", "0.0006"], ["84033.3", "0.12399"], ["84033.2", "0.171333"], ["84033.1", "0"], ["84033", "0"], ["84032.9", "0"], ["84032.7", "0"], ["84031.6", "0.04"], ["84031.1", "0"], ["84030.7", "0.024636"], ["84030.2", "0"], ["84030", "0"], ["84029.9", "0.044"], ["84029.7", "0.0003"], ["84028.5", "0.071438"], ["84028.4", "0"], ["84027.6", "0"], ["84027.5", "0"], ["84027", "0.044516"], ["84026.9", "0"], ["84025.3", "0"], ["84025.2", "0.00009"], ["84024.8", "0.000333"], ["84024.7", "0"], ["84024.1", "0.060732"], ["84024", "0.128823"], ["84022.9", "0.052"], ["84022.8", "0.055371"], ["84022.6", "0"], ["84022", "0"], ["84021.3", "0"], ["84017.7", "0.071447"], ["84017.2", "0.092794"], ["84017.1", "0"], ["84017", "0.022009"], ["84016.8", "0.00009"], ["84016.4", "0.000333"], ["84015.9", "0"], ["84014.8", "0.07145"], ["84014", "0.001466"], ["84013.9", "0"], ["84013.5", "0"], ["84011.7", "0.03732"], ["84010.4", "0"], ["84010.3", "0"], ["84009", "0"], ["84008.1", "0.011904"], ["84005.8", "0"], ["84004.4", "0"], ["84003.8", "0.059753"], ["84003.7", "0.280533"], ["84003.4", "0.013"], ["84002.3", "0"], ["84001.9", "0"], ["84000.2", "0.516686"], ["84000", "0.017036"], ["83999.9", "0.049549"], ["83999.8", "0.049549"], ["83998.3", "0.174821"], ["83998", "0"], ["83997.6", "0"], ["83997.2", "0.562285"], ["83995.9", "0"], ["83995.8", "0"], ["83995.4", "0.000333"], ["83995.2", "0.005948"], ["83994.2", "0"], ["83993.6", "0.4"], ["83990.6", "0"], ["83989.3", "0"], ["83989.2", "0"], ["83988.9", "0.023795"], ["83986.8", "0"], ["83986.7", "0.01185"], ["83985.7", "0.023797"], ["83985", "0.023795"], ["83984.8", "0"], ["83984.1", "0.023795"], ["83984", "0.023797"], ["83983.5", "0.013924"], ["83982.5", "0.096168"], ["83978.2", "0"], ["83976.7", "0"], ["83975", "0"], ["83974.6", "0.0025"], ["83974.4", "0.000333"], ["83973.7", "0.001333"], ["83973.3", "0.003552"], ["83972.9", "0.001774"], ["83972.4", "0.001466"], ["83971.6", "0.00052"], ["83970.2", "0.000333"], ["83970", "0.007148"], ["83969.5", "0.001333"], ["83969.1", "3.754103"], ["83967.8", "0.001466"], ["83967.3", "0.118852"], ["83967", "0.00052"], ["83966.9", "0.01002"], ["83966.4", "0.00018"], ["83966.1", "0.059518"], ["83966", "0.059732"], ["83965.3", "0.001333"], ["83964.9", "0.003552"], ["83963.8", "0.141337"], ["83963.3", "0.05"], ["83963.1", "0.001466"], ["83962.4", "0.00052"], ["83962.2", "0.048"], ["83961.8", "0.000333"], ["83961.5", "0.002201"], ["83961.2", "0.015"], ["83961.1", "0.001333"], ["83961", "0.03571"], ["83960.9", "0.224383"], ["83960.7", "0.003552"], ["83960.4", "0.044"], ["83959.7", "0.000361"]], "a": [["84041.8", "0.524972"], ["84042.1", "0.215123"], ["84042.2", "0.291"], ["84042.5", "0.121426"], ["84042.6", "0.000153"], ["84043.1", "0.089099"], ["84043.9", "0.02"], ["84046.1", "0.098009"], ["84048.6", "0.011494"], ["84048.9", "0.082412"], ["84049", "0.221"], ["84049.1", "0"], ["84049.2", "0"], ["84049.3", "0.082526"], ["84050", "0.000333"], ["84050.1", "0.000516"], ["84050.4", "0"], ["84050.9", "0.001466"], ["84051", "0.016005"], ["84051.4", "0.01056"], ["84051.9", "0.045714"], ["84052", "0.02"], ["84052.8", "0.022987"], ["84053.1", "0.003668"], ["84053.2", "0.071417"], ["84053.6", "0.05"], ["84054.1", "0.04"], ["84055.2", "0.019816"], ["84055.6", "0.001466"], ["84055.8", "0"], ["84056", "0.00009"], ["84056.5", "0"], ["84058", "0.04"], ["84058.2", "0"], ["84059.4", "0.040516"], ["84059.8", "0.059399"], ["84059.9", "0.149989"], ["84060", "0"], ["84060.1", "0.004042"], ["84060.4", "0"], ["84060.9", "0"], ["84061.3", "0.04"], ["84061.6", "0.003669"], ["84061.7", "0.03"], ["84061.9", "0.001333"], ["84062.2", "0.004689"], ["84062.3", "0.098009"], ["84063.2", "0.063792"], ["84063.4", "0.129892"], ["84063.7", "0.04"], ["84063.9", "0.0006"], ["84064.6", "0.0006"], ["84065", "0.552036"], ["84065.1", "0"], ["84066.8", "0.000333"], ["84067.2", "0"], ["84067.3", "0.14681"], ["84067.6", "0"], ["84067.9", "0.517081"], ["84070.1", "0.04"], ["84070.4", "0.118852"], ["84070.5", "0.04"], ["84071.4", "0"], ["84071.7", "0"], ["84074.3", "0.05527"], ["84074.9", "0.005949"], ["84075.5", "0"], ["84075.7", "0.063528"], ["84075.9", "0.118852"], ["84076", "0.089241"], ["84076.3", "0"], ["84078.8", "0"], ["84078.9", "0"], ["84081.9", "0.000361"], ["84082.1", "0"], ["84083.6", "0.001024"], ["84083.7", "1.447017"], ["84085", "0"], ["84088.1", "0"], ["84089.7", "0.644815"], ["84090.9", "0"], ["84093", "0"], ["84095.1", "0.019543"], ["84097", "0.089241"], ["84097.6", "0.023937"], ["84098.1", "0"], ["84100", "0.027593"], ["84103.4", "0.04453"], ["84103.9", "0.001333"], ["84104.6", "3.739235"], ["84106.2", "0"], ["84109.9", "0.0006"], ["84111.7", "0"], ["84114", "0"], ["84114.7", "0"], ["84114.8", "0"], ["84114.9", "0"], ["84115.7", "0"], ["84115.9", "0"], ["84116.2", "0"], ["84116.5", "0"], ["84116.6", "0"], ["84116.8", "0"], ["84117", "0"], ["84117.3", "0"], ["84117.4", "0"], ["84118", "0"], ["84118.8", "0"]], "u": 92308, "seq": 67563885491}, "cts": 1742569756517, "record_time": 1742569756.891167, "EXCHANGE": "BYBIT"}
{"topic": "orderbook.200.BTCUSDT", "ts": 1742569756719, "type": "delta", "data": {"s": "BTCUSDT", "b": [["84041.7", "0.004203"], ["84033.9", "0"], ["84033.3", "0.097489"], ["84032.4", "0.072901"], ["84031.6", "0"], ["84029.9", "0"], ["84029.7", "0"], ["84028.5", "0"], ["84027.1", "0.014115"], ["84026.8", "0.04"], ["84026.6", "0.04"], ["84025.3", "0.002082"], ["84024.7", "0.001774"], ["84024.3", "0.059399"], ["84024.1", "0.144156"], ["84024", "0.158852"], ["84023.4", "0.04"], ["84023.2", "0.002066"], ["84022.8", "0.048"], ["84021.7", "0.04"], ["84021", "0.157403"], ["84020.6", "0.004368"], ["84020.5", "0.071445"], ["84019.5", "0.022407"], ["84017.7", "0"], ["84017.2", "0"], ["84016.5", "0"], ["84014.8", "0"], ["84013.8", "0.009438"], ["84013.3", "0.116374"], ["84012.9", "0.178483"], ["84012.5", "0.178483"], ["84010.9", "0"], ["84010.8", "0"], ["84008.7", "0.178483"], ["84006.4", "0"], ["84005.8", "0.124938"], ["84005.7", "0"], ["84003.4", "0"], ["84001.2", "0.04"], ["84001.1", "0.039638"], ["83999.9", "0"], ["83999.8", "0"], ["83999.3", "0.013403"], ["83999.2", "0.012883"], ["83995.7", "0.049554"], ["83995.6", "0.049554"], ["83989.5", "0"], ["83988.4", "0.004575"], ["83985.9", "0.003552"], ["83984.8", "0.124938"], ["83982.5", "0.09622"], ["83981.8", "0.001431"], ["83976.6", "0"], ["83975.9", "0"], ["83975", "0.178483"], ["83972.9", "0"], ["83972.7", "0.171"], ["83964.2", "0.171"], ["83963.3", "0"], ["83961", "0"], ["83960.9", "0"], ["83960.7", "0"], ["83960.4", "0"], ["83959.7", "0"]], "a": [["84041.8", "0.532967"], ["84042.6", "0"], ["84044.1", "0.023797"], ["84045.1", "0.004042"], ["84046.3", "0.169645"], ["84046.4", "0.142785"], ["84048", "0.04"], ["84048.9", "0"], ["84049", "0.224668"], ["84049.3", "0.189171"], ["84049.7", "0.033141"], ["84050.2", "0.04635"], ["84051", "0.026675"], ["84051.9", "0.068107"], ["84052", "0.06"], ["84053", "0.04"], ["84055.5", "0.197531"], ["84056.9", "0.04"], ["84057.9", "0.178483"], ["84058", "0.156373"], ["84059", "0.204416"], ["84059.1", "0.178483"], ["84059.9", "0.04"], ["84060.1", "0"], ["84062.6", "0.000333"], ["84063.2", "0"], ["84063.3", "0.178483"], ["84064.8", "0.001466"], ["84065.5", "0"], ["84067.3", "0.267924"], ["84068.2", "0"], ["84068.9", "0.124938"], ["84070.5", "0"], ["84073.8", "0.059399"], ["84074.2", "0.00367"], ["84074.3", "0.0516"], ["84075.1", "0"], ["84075.7", "0"], ["84075.8", "0"], ["84076.8", "0.080974"], ["84077.1", "0"], ["84078.5", "0.083534"], ["84080", "0.511498"], ["84084.9", "0"], ["84086", "0.178483"], ["84089.7", "0.156293"], ["84097.9", "0.045131"], ["84103.4", "0"], ["84110.9", "0"], ["84113.1", "0"], ["84113.6", "0"]], "u": 92309, "seq": 67563885749}, "cts": 1742569756713, "record_time": 1742569756.988788, "EXCHANGE": "BYBIT"}
{"topic": "orderbook.200.BTCUSDT", "ts": 1742569756919, "type": "delta", "data": {"s": "BTCUSDT", "b": [["84041.7", "0"], ["84041.6", "0"], ["84040.9", "0"], ["84033.6", "0"], ["84033.3", "0"], ["84033.2", "0.000333"], ["84032.4", "0.001466"], ["84032.1", "0.018643"], ["84030.8", "0.028822"], ["84030.5", "0.071436"], ["84027.1", "0.03635"], ["84026.9", "0.044"], ["84025.3", "0"], ["84024.7", "0"], ["84024.3", "0.103399"], ["84024", "0.04"], ["84021", "0"], ["84020.6", "0.075821"], ["84017.5", "0.071447"], ["84017", "0"], ["84015.3", "0.178023"], ["84012.6", "0.204682"], ["84011.9", "0.004761"], ["83993.9", "0.227696"], ["83989.8", "0.06374"], ["83988.2", "0.09622"], ["83982.5", "0"], ["83965.2", "0.023485"], ["83961", "0.03571"]], "a": [["84040.6", "0.59399"], ["84041.6", "0.319894"], ["84041.7", "0.042048"], ["84041.8", "0.327075"], ["84042.1", "0"], ["84042.2", "0.12"], ["84042.5", "0.05"], ["84045.1", "0.005375"], ["84045.5", "0.000516"], ["84045.8", "0.000333"], ["84046.3", "0.171111"], ["84049.7", "0.073141"], ["84051.9", "0.102408"], ["84053.4", "0.04"], ["84054.1", "0"], ["84054.6", "0.04"], ["84054.7", "0.04"], ["84058", "0.116373"], ["84059.9", "0"], ["84063.2", "0.233738"], ["84063.4", "0"], ["84063.7", "0"], ["84066", "0.003575"], ["84067.4", "0.204823"], ["84071.1", "0.04"], ["84073.4", "0.056042"], ["84075.7", "0.063534"], ["84075.8", "0.128474"], ["84076.8", "0"], ["84078.5", "0.02"], ["84082.5", "1.426833"], ["84083.7", "0.0207"], ["84084.5", "0.026903"], ["84085", "0.125401"], ["84091", "0.174561"], ["84092.4", "0"], ["84095", "0.044531"], ["84097.9", "0.0006"], ["84109.9", "0"], ["84110.3", "0"], ["84111.1", "0"], ["84111.2", "0"], ["84112", "0"], ["84112.2", "0"], ["84112.3", "0"], ["84112.6", "0"], ["84112.9", "0"]], "u": 92310, "seq": 67563885996}, "cts": 1742569756917, "record_time": 1742569757.187933, "EXCHANGE": "BYBIT"}
{"topic": "orderbook.200.BTCUSDT", "ts": 1742569757120, "type": "delta", "data": {"s": "BTCUSDT", "b": [["84040.5", "0.006937"], ["84032.5", "0.036522"], ["84032.4", "0.072901"], ["84030.8", "0"], ["84030.5", "0"], ["84025.3", "0.002082"], ["84024.7", "0.001774"], ["84024.2", "0"], ["84012.6", "0.160682"], ["84011.9", "0"], ["84011.4", "0.006637"], ["84001.1", "0.039637"], ["83999.3", "0.013402"], ["83995.7", "0.049552"], ["83991.9", "0.089243"], ["83986.6", "0.052328"], ["83970.9", "0.089243"], ["83961", "0"]], "a": [["84040.6", "0.56399"], ["84041.6", "0.205124"], ["84041.7", "0"], ["84047.9", "0.04"], ["84049.5", "0.04"], ["84056.9", "0"], ["84058.3", "0.178448"], ["84059.4", "0.000516"], ["84059.9", "0.178444"], ["84061.3", "0"], ["84061.6", "0.18211"], ["84078", "0"], ["84086.6", "0.04"], ["84088.3", "0.04"], ["84091.7", "0.04"], ["84093.2", "0.04"], ["84093.3", "0.04"], ["84101.4", "0.011851"], ["84107.3", "0"], ["84107.4", "0"], ["84107.8", "0"], ["84108.1", "0"], ["84108.7", "0"], ["84108.9", "0"]], "u": 92311, "seq": 67563886088}, "cts": 1742569757112, "record_time": 1742569757.388524, "EXCHANGE": "BYBIT"}
{"topic": "orderbook.200.BTCUSDT", "ts": 1742569757320, "type": "delta", "data": {"s": "BTCUSDT", "b": [["84035", "0.019552"], ["84032.5", "0.015091"], ["84032.4", "0.001466"], ["84024.2", "0.118852"], ["84023.4", "0.111442"], ["84017.5", "0"], ["84013.3", "0"], ["84012.6", "0.277062"], ["84003.6", "0.423997"], ["84000.6", "0.003341"], ["83975", "0"]], "a": [["84040.6", "0.477743"], ["84041.8", "0.324577"], ["84053.4", "0"], ["84060.8", "0.178485"], ["84061", "0.04"], ["84062.7", "0.06"], ["84066.7", "0.12494"], ["84070.1", "0"], ["84086", "0"], ["84087.7", "0.12494"], ["84088.1", "0.04"], ["84089.6", "0.015638"], ["84095", "0.000118"], ["84099.5", "0.171"], ["84100.3", "0.178358"], ["84104.9", "0"], ["84105.6", "0"], ["84105.9", "0"], ["84106.4", "0"]], "u": 92312, "seq": 67563886192}, "cts": 1742569757317, "record_time": 1742569757.588535, "EXCHANGE": "BYBIT"}
{"topic": "orderbook.200.BTCUSDT", "ts": 1742569757519, "type": "delta", "data": {"s": "BTCUSDT", "b": [["84023.4", "0.04"], ["84017.4", "0.071448"], ["84007.8", "0.064426"], ["84003.7", "0.420732"], ["83999", "0.000118"], ["83995.9", "0.049552"], ["83995.8", "0.049552"], ["83995.7", "0"], ["83995.6", "0"], ["83991", "0.09611"], ["83988.2", "0"], ["83961.5", "0"], ["83961.2", "0"], ["83961.1", "0"]], "a": [["84040.6", "0.475398"], ["84041.8", "0.294577"], ["84042.5", "0.02"], ["84048.9", "0.003668"], ["84049", "0.236"], ["84050.2", "0.03135"], ["84051.9", "0.142408"], ["84052", "0.083809"], ["84054.9", "0.04"], ["84059", "0.317694"], ["84071.1", "0"], ["84084", "0.002498"], ["84086.5", "0.04"], ["84095", "0.036097"], ["84097.8", "0.011993"], ["84103.9", "0"], ["84104", "0"], ["84104.2", "0"], ["84104.6", "0"]], "u": 92313, "seq": 67563886271}, "cts": 1742569757504, "record_time": 1742569757.788048, "EXCHANGE": "BYBIT"}
{"topic": "orderbook.200.BTCUSDT", "ts": 1742569757720, "type": "delta", "data": {"s": "BTCUSDT", "b": [["84040.5", "0.178175"], ["84035.2", "0.034552"], ["84035.1", "0.071432"], ["84035", "0"], ["84023.6", "0.071442"], ["84020.9", "0.141154"], ["84020.8", "0.178527"], ["84020.6", "0.004368"], ["84019.2", "0.008271"], ["84019.1", "0.178531"], ["84017.4", "0.178534"], ["83996.1", "0.050427"], ["83996", "0.073348"], ["83995.9", "0"], ["83995.8", "0"], ["83993.8", "0.230842"], ["83991", "0"], ["83962.4", "0"], ["83962.2", "0"], ["83961.8", "0"]], "a": [["84040.6", "0.319617"], ["84041.6", "0.085867"], ["84041.8", "0.12"], ["84043.1", "0"], ["84044.1", "0"], ["84046.1", "0"], ["84046.4", "0.023797"], ["84061", "0"], ["84062.7", "0.02"], ["84064.5", "0.003576"], ["84103.9", "0.001333"], ["84104", "0.000361"], ["84104.2", "0.0006"]], "u": 92314, "seq": 67563886368}, "cts": 1742569757715, "record_time": 1742569757.989151, "EXCHANGE": "BYBIT"}
{"topic": "orderbook.200.BTCUSDT", "ts": 1742569757919, "type": "delta", "data": {"s": "BTCUSDT", "b": [["84040.5", "0.006937"], ["84035.2", "0"], ["84035.1", "0"], ["84033", "0.071434"], ["84023.6", "0"], ["84020.9", "0.210365"], ["84018.1", "0.071447"], ["84003.6", "0.116511"], ["83999.8", "0.013"], ["83999.7", "0.012882"], ["83999.3", "0.00052"], ["83999.2", "0"], ["83996.2", "0.049552"], ["83996", "0.023796"], ["83993.8", "0.134766"], ["83991", "0.096077"], ["83963.8", "0"], ["83963.1", "0"]], "a": [["84040.6", "0.597536"], ["84044.9", "0.089099"], ["84050.3", "0.05457"], ["84073.5", "0.062895"], ["84081.1", "0.307203"], ["84090.2", "0"], ["84094.2", "0.04"], ["84099.2", "0"], ["84104", "0"], ["84104.2", "0"]], "u": 92315, "seq": 67563886437}, "cts": 1742569757914, "record_time": 1742569758.187947, "EXCHANGE": "BYBIT"}
{"topic": "orderbook.200.BTCUSDT", "ts": 1742569758120, "type": "delta", "data": {"s": "BTCUSDT", "b": [["84033.1", "0.035588"], ["84032.5", "0.001333"], ["84023.3", "0.111812"], ["84023.1", "0.071443"], ["84018.1", "0"], ["84013.5", "0.180866"], ["84004.4", "0.286779"], ["84001.2", "0"], ["84001", "0.039637"], ["83999.8", "0"], ["83999.7", "0"], ["83999.3", "0.013402"], ["83999.2", "0.012882"], ["83996.2", "0"], ["83996.1", "0.000875"], ["83995.7", "0.049552"], ["83995.6", "0.049552"], ["83965.3", "0"], ["83965.2", "0"], ["83964.9", "0"], ["83964.2", "0"]], "a": [["84040.6", "0.597383"], ["84041.1", "0.000153"], ["84046.3", "0.236152"], ["84048.5", "0.119011"], ["84058.3", "0.344226"], ["84060.4", "0.006937"], ["84067.4", "0.514889"], ["84073.4", "0.059457"], ["84073.5", "0.05948"], ["84103.5", "0"], ["84103.6", "0"], ["84103.9", "0"]], "u": 92316, "seq": 67563886509}, "cts": 1742569758103, "record_time": 1742569758.388593, "EXCHANGE": "BYBIT"}
{"topic": "orderbook.200.BTCUSDT", "ts": 1742569758320, "type": "delta", "data": {"s": "BTCUSDT", "b": [["84024.3", "0.333058"], ["84024.1", "0.066201"], ["84007", "0.212311"], ["83999.6", "0.013333"], ["83999.5", "0.012882"], ["83999.3", "0.00052"], ["83999.2", "0"], ["83995.9", "0.05"], ["83995.8", "0.049552"], ["83995.7", "0"], ["83995.6", "0"]], "a": [["84073.3", "0.003931"], ["84073.4", "0.056042"], ["84075.2", "0.040333"], ["84075.3", "0.04"], ["84083.7", "0.02"], ["84103.2", "0"]], "u": 92317, "seq": 67563886544}, "cts": 1742569758303, "record_time": 1742569758.588166, "EXCHANGE": "BYBIT"}
{"topic": "orderbook.200.BTCUSDT", "ts": 1742569758520, "type": "delta", "data": {"s": "BTCUSDT", "b": [["84001.3", "0.039637"], ["84001.2", "0.039637"], ["84001.1", "0"], ["84001", "0"], ["83999.6", "0.000333"], ["83999.4", "0.012882"], ["83995.9", "0.049552"], ["83991", "0"], ["83988.2", "0.096077"], ["83966", "0"]], "a": [["84040.6", "0.600959"], ["84060.4", "0"], ["84064.5", "0"], ["84073.3", "0.000516"], ["84073.4", "0.059457"], ["84103.2", "0.023787"], ["84103.5", "0.001526"]], "u": 92318, "seq": 67563886576}, "cts": 1742569758515, "record_time": 1742569758.788631, "EXCHANGE": "BYBIT"}
{"topic": "orderbook.200.BTCUSDT", "ts": 1742569758720, "type": "delta", "data": {"s": "BTCUSDT", "b": [["84035", "0.019552"], ["84033.1", "0.014158"], ["84033", "0"], ["84024.3", "0.242426"], ["84024.2", "0"], ["84023.3", "0"], ["84023.1", "0"], ["84022.7", "0.117276"], ["84020.9", "0.11107"], ["84020.8", "0"], ["84020.5", "0"], ["84019.6", "0.071446"], ["84019.2", "0"], ["84019.1", "0"], ["84017.4", "0"], ["84013.5", "0"], ["84012.9", "0.343408"], ["84004.4", "0"], ["84003.8", "0.365327"], ["84001.3", "0"], ["84001.2", "0"], ["84000.9", "0.039637"], ["84000.8", "0.039637"], ["83999.5", "0"], ["83999.4", "0"], ["83999.1", "0.012882"], ["83999", "0.013"], ["83995.9", "0"], ["83995.8", "0"], ["83995.5", "0.051019"], ["83995.4", "0.049886"], ["83966", "0.059732"], ["83965.3", "0.001333"], ["83965.2", "0.023485"], ["83964.9", "0.003552"], ["83963.8", "0.141337"], ["83963.1", "0.001466"], ["83962.4", "0.00052"], ["83962.2", "0.048"], ["83961.8", "0.000333"], ["83961.5", "0.002201"], ["83961.2", "0.015"]], "a": [["84041.1", "0"], ["84047.9", "0.159717"], ["84048.5", "0"], ["84057.7", "0.169855"], ["84058.2", "0.178485"], ["84058.3", "0.178448"], ["84060.8", "0"], ["84066.8", "0.284217"], ["84067.4", "0.204823"], ["84103.6", "0.003563"], ["84103.9", "0.001333"]], "u": 92319, "seq": 67563886654}, "cts": 1742569758713, "record_time": 1742569758.988521, "EXCHANGE": "BYBIT"}
{"topic": "orderbook.200.BTCUSDT", "ts": 1742569758920, "type": "delta", "data": {"s": "BTCUSDT", "b": [["84024.3", "0.295886"], ["84023", "0.118852"], ["84022.1", "0.071444"], ["84020.9", "0.069211"], ["84012.6", "0.160682"], ["84007", "0.152081"], ["83995.8", "0.05"], ["83995.7", "0.049552"], ["83995.5", "0.001466"], ["83995.4", "0.000333"], ["83964.2", "0.171"], ["83962.4", "0"], ["83962.2", "0"], ["83961.8", "0"], ["83961.5", "0"], ["83961.2", "0"]], "a": [["84041.6", "0.08602"], ["84055.5", "0.322215"], ["84060.4", "0.006937"], ["84103.9", "0"]], "u": 92320, "seq": 67563886684}, "cts": 1742569758915, "record_time": 1742569759.188317, "EXCHANGE": "BYBIT"}
{"topic": "orderbook.200.BTCUSDT", "ts": 1742569759119, "type": "delta", "data": {"s": "BTCUSDT", "b": [["84040.5", "0.007737"], ["84022.7", "0"], ["84013.4", "0.116377"], ["84012.9", "0.178483"], ["84003.8", "0.059753"], ["83999.6", "0.013333"], ["83999.5", "0.012882"], ["83999.1", "0"], ["83999", "0.000118"], ["83995.8", "0"], ["83995.6", "0.049552"], ["83993.4", "0.307524"], ["83963.1", "0"]], "a": [["84040.6", "0.712344"], ["84046.3", "0.239152"], ["84047.9", "0.04"], ["84057.7", "0.001333"], ["84062.8", "0"], ["84066.8", "0.000333"], ["84072.7", "0.003415"], ["84073.4", "0.056042"], ["84074.3", "0.0508"]], "u": 92321, "seq": 67563886728}, "cts": 1742569759112, "record_time": 1742569759.38838, "EXCHANGE": "BYBIT"}
{"topic": "orderbook.200.BTCUSDT", "ts": 1742569759320, "type": "delta", "data": {"s": "BTCUSDT", "b": [["84019.2", "0.008321"], ["84001.4", "0.04"], ["84001.3", "0.039637"], ["84000.9", "0"], ["84000.8", "0"], ["83996", "0.073796"], ["83995.9", "0.049552"], ["83995.7", "0"], ["83995.6", "0"], ["83993.9", "0.318264"], ["83991", "0.096064"], ["83988.2", "0"]], "a": [["84040.6", "0.713144"], ["84059", "0.204416"], ["84074.3", "0.05"], ["84074.5", "0.041333"], ["84074.6", "0.04"], ["84075.2", "0.000333"], ["84075.3", "0"]], "u": 92322, "seq": 67563886751}, "cts": 1742569759295, "record_time": 1742569759.58959, "EXCHANGE": "BYBIT"}
{"topic": "orderbook.200.BTCUSDT", "ts": 1742569759520, "type": "delta", "data": {"s": "BTCUSDT", "b": [["84040.5", "0.178975"], ["84035", "0.038538"], ["84034.8", "0.071433"], ["84029.4", "0.002"], ["84025", "0.071441"], ["84022.7", "0.123704"], ["84020.9", "0.113564"], ["84020.8", "0.178527"], ["84019.6", "0"], ["84015.7", "0.188898"], ["84008.7", "0.457946"], ["84001.4", "0"], ["84001.3", "0"], ["84001.1", "0.04"], ["84001", "0.039637"], ["84000.3", "0.0016"], ["83999.6", "0.000333"], ["83999.5", "0"], ["83999.3", "0.01352"], ["83999.2", "0.012882"], ["83996", "0.023796"], ["83995.9", "0"], ["83995.7", "0.05"], ["83995.6", "0.049552"], ["83966", "0"], ["83965.3", "0"], ["83965.2", "0"], ["83964.9", "0"], ["83964.2", "0"], ["83963.8", "0"]], "a": [["84040.6", "0.431649"], ["84041.6", "0.085867"], ["84044.9", "0"], ["84055.6", "0.116937"], ["84062.6", "0.172843"], ["84068.1", "0.0001"], ["84069.6", "0.297673"], ["84072.7", "0"], ["84073.4", "0.059457"], ["84074.5", "0.001333"], ["84074.6", "0"], ["84075.2", "0.040333"], ["84075.3", "0.04"], ["84089.7", "0.156193"], ["84097.2", "0.003066"]], "u": 92323, "seq": 67563886829}, "cts": 1742569759516, "record_time": 1742569759.78867, "EXCHANGE": "BYBIT"}
{"topic": "orderbook.200.BTCUSDT", "ts": 1742569759720, "type": "delta", "data": {"s": "BTCUSDT", "b": [["84040.5", "0.008429"], ["84037.5", "0.07143"], ["84036.5", "0.0208"], ["84035", "0"], ["84034.8", "0"], ["84027.7", "0.051315"], ["84027.1", "0"], ["84022.7", "0"], ["84022.4", "0.071959"], ["84022.1", "0"], ["84019.1", "0.178531"], ["84017.4", "0.178534"], ["84015.7", "0.001333"], ["84012.6", "0.226426"], ["84008.7", "0.178483"], ["83999.3", "0.013402"], ["83996.6", "0.096068"], ["83996.1", "0.050875"], ["83996", "0.073348"], ["83995.7", "0"], ["83995.6", "0"], ["83991", "0"], ["83966", "0.059732"], ["83965.3", "0.001333"]], "a": [["84040.6", "0.411649"], ["84042.2", "0.120153"], ["84046.4", "0"], ["84049", "0.206"], ["84055.6", "0.001466"], ["84058.2", "0"], ["84060.8", "0.178485"], ["84062.6", "0.000333"], ["84069.6", "0"], ["84070.4", "0"], ["84073.4", "0.056042"], ["84074", "0.003415"], ["84075.2", "0.000333"], ["84075.3", "0"], ["84075.8", "0.168474"], ["84075.9", "0.158852"], ["84103.9", "0.001333"], ["84104", "0.000361"], ["84104.2", "0.353967"]], "u": 92324, "seq": 67563886935}, "cts": 1742569759716, "record_time": 1742569759.988485, "EXCHANGE": "BYBIT"}
{"topic": "orderbook.200.BTCUSDT", "ts": 1742569759919, "type": "delta", "data": {"s": "BTCUSDT", "b": [["84040.5", "0.278555"], ["84037.6", "0.021739"], ["84037.5", "0"], ["84036.5", "0"], ["84022.9", "0.167561"], ["84013.1", "0.180604"], ["84012.6", "0.160682"], ["84004", "0.28167"], ["83996.6", "0"], ["83996.2", "0.049552"], ["83996.1", "0.050427"], ["83996", "0.023796"], ["83993.8", "0.230834"], ["83965.3", "0"]], "a": [["84040.6", "0.396783"], ["84042.2", "0.12"], ["84048.1", "0.11583"], ["84051", "0.026828"], ["84057.9", "0.362575"], ["84059.8", "0"], ["84060.4", "0"], ["84060.8", "0.200224"], ["84067", "0.291267"]], "u": 92325, "seq": 67563887014}, "cts": 1742569759917, "record_time": 1742569760.188188, "EXCHANGE": "BYBIT"}
{"topic": "orderbook.200.BTCUSDT", "ts": 1742569760119, "type": "delta", "data": {"s": "BTCUSDT", "b": [["84040.5", "0.281767"], ["84040.2", "0.021446"], ["84038.9", "0.071429"], ["84037.8", "0.021739"], ["84037.6", "0"], ["84030.3", "0.004035"], ["84027.7", "0.122754"], ["84022.9", "0.230523"], ["84022.4", "0.000516"], ["84021.7", "0.218525"], ["84020.8", "0"], ["84020.6", "0.000333"], ["84019.1", "0"], ["84013.1", "0"], ["84004", "0"], ["84001", "0.052637"], ["83999.3", "0.00052"], ["83999", "0.049666"], ["83998.9", "0.050882"], ["83996.6", "0.096062"], ["83996.2", "0"], ["83996.1", "0.000875"], ["83993.8", "0.134766"], ["83965.3", "0.001333"]], "a": [["84040.6", "0.340246"], ["84041.8", "0.1"], ["84045.1", "0.001333"], ["84048.1", "0"], ["84049.3", "0.179398"], ["84051", "0.026675"], ["84055.1", "0.000153"], ["84055.5", "0.190482"], ["84056.3", "0.009773"], ["84057.4", "0.054042"], ["84057.9", "0.178483"], ["84058.3", "0"], ["84059.9", "0"], ["84060.8", "0.178485"], ["84061.3", "0.178441"], ["84061.6", "0.003669"], ["84062.4", "0.035706"], ["84062.9", "0.178438"], ["84064.9", "0.059399"], ["84067", "0"], ["84074", "0"], ["84074.9", "0.009364"], ["84075.7", "0"], ["84075.8", "0.128474"], ["84075.9", "0.118852"], ["84076.7", "0.04"], ["84076.8", "0.04"], ["84078.5", "0.083516"], ["84104", "0"], ["84104.2", "0"]], "u": 92326, "seq": 67563887144}, "cts": 1742569760112, "record_time": 1742569760.387852, "EXCHANGE": "BYBIT"}
{"topic": "orderbook.200.BTCUSDT", "ts": 1742569760320, "type": "delta", "data": {"s": "BTCUSDT", "b": [["84013.4", "0"], ["84002.4", "0.012881"], ["84002.3", "0.012881"], ["84001", "0.039637"], ["83999.2", "0"], ["83999", "0.000118"], ["83998.9", "0.001333"], ["83998.8", "0.049549"], ["83998.7", "0.049549"], ["83996.6", "0"], ["83993.8", "0.230828"], ["83981.4", "0.178611"], ["83966", "0"], ["83965.3", "0"]], "a": [["84055", "0.000153"], ["84055.1", "0"], ["84063.3", "0.356968"], ["84064.6", "0.179034"], ["84074.9", "0.005949"], ["84075", "0.003415"], ["84075.7", "0.063518"], ["84075.9", "0"], ["84076.7", "0"], ["84076.9", "0.04"], ["84078.5", "0.02"], ["84091.3", "0.041333"], ["84093.7", "0.04"], ["84103.6", "0"], ["84103.9", "0"]], "u": 92327, "seq": 67563887212}, "cts": 1742569760311, "record_time": 1742569760.588118, "EXCHANGE": "BYBIT"}
{"topic": "orderbook.200.BTCUSDT", "ts": 1742569760520, "type": "delta", "data": {"s": "BTCUSDT", "b": [["84040.5", "0.524195"], ["84040.2", "0"], ["84038.9", "0"], ["84033.1", "0.03563"], ["84030.2", "0.071437"], ["84028.4", "0.110655"], ["84027.7", "0.051315"], ["84025.6", "0.178517"], ["84025", "0"], ["84024.6", "0.11223"], ["84022.9", "0.052"], ["84022.2", "0.178524"], ["84018.6", "0.185825"], ["84017.6", "0.173777"], ["84017.4", "0"], ["84015.3", "0.00364"], ["84015.1", "0.11639"], ["84010.6", "0.393786"], ["84009.5", "0.302691"], ["84002.6", "0.013"], ["84002.5", "0.012881"], ["84002.4", "0"], ["84002.3", "0"], ["83999", "0.050118"], ["83998.9", "0.050882"], ["83998.8", "0"], ["83998.7", "0"], ["83971.1", "0.023902"], ["83966.4", "0"], ["83966.1", "0"]], "a": [["84040.6", "0.28448"], ["84041.6", "0"], ["84041.8", "0"], ["84042.2", "0"], ["84042.5", "0"], ["84043.9", "0"], ["84049.3", "0.107978"], ["84049.7", "0.04"], ["84053.6", "0.140778"], ["84054.8", "0.020516"], ["84055", "0"], ["84055.7", "0.02"], ["84055.9", "0.071415"], ["84057.5", "0.12187"], ["84061.3", "0"], ["84062.9", "0"], ["84063.2", "0.35597"], ["84063.4", "0.163934"], ["84064.5", "0.17047"], ["84064.6", "0.0006"], ["84064.9", "0.237833"], ["84071.5", "0.284901"], ["84072.5", "0.274127"], ["84075", "0"], ["84075.7", "0"], ["84075.8", "0"], ["84076.6", "0.003415"], ["84076.8", "0"], ["84076.9", "0.118852"], ["84078.4", "0.04367"], ["84078.5", "0.06"], ["84103.6", "0.003563"], ["84103.9", "0.001333"], ["84104", "0.000361"], ["84104.2", "0.353967"], ["84104.6", "3.739235"]], "u": 92328, "seq": 67563887342}, "cts": 1742569760517, "record_time": 1742569760.787902, "EXCHANGE": "BYBIT"}
{"topic": "orderbook.200.BTCUSDT", "ts": 1742569760720, "type": "delta", "data": {"s": "BTCUSDT", "b": [["84033.1", "0.054376"], ["84032.7", "0.071434"], ["84028.4", "0"], ["84027.7", "0.098455"], ["84027.1", "0.009438"], ["84024.6", "0.368873"], ["84024.5", "0.178519"], ["84024.3", "0.103399"], ["84021.7", "0.04"], ["84018.6", "0.001466"], ["84017.6", "0"], ["84016.4", "0.119323"], ["84015", "0.178485"], ["84013.8", "0"], ["84012.5", "0"], ["84010.6", "0.118852"], ["84010.3", "0.178485"], ["84009.5", "0"], ["84007.8", "0"], ["84002.8", "0.307489"], ["83999.3", "0.050068"], ["83999.2", "0.049548"], ["83999", "0.000118"], ["83998.9", "0.001333"], ["83993.8", "0.134766"], ["83993.4", "0"], ["83988.2", "0.09606"], ["83966.9", "0"]], "a": [["84040.6", "0.227918"], ["84043.5", "0.071425"], ["84046.3", "0.129239"], ["84047.9", "0"], ["84048", "0"], ["84049", "0.186"], ["84049.5", "0"], ["84049.7", "0"], ["84050.5", "0.011903"], ["84051.9", "0.027639"], ["84052", "0.043809"], ["84053", "0"], ["84053.2", "0"], ["84053.6", "0.02"], ["84054.6", "0"], ["84054.7", "0"], ["84055.2", "0"], ["84057.5", "0"], ["84058.5", "0.071413"], ["84062.3", "0"], ["84062.4", "0"], ["84063.1", "0.019816"], ["84063.4", "0"], ["84063.8", "0.035705"], ["84064.5", "0"], ["84067.4", "0.191"], ["84071.5", "0"], ["84072.5", "0"], ["84076.6", "0"], ["84076.9", "0"], ["84078.4", "0.00367"], ["84078.5", "0.02"], ["84079.1", "0.003415"], ["84080.9", "0.04"], ["84081", "0.04"], ["84081.4", "0.063518"], ["84100.3", "0"], ["84104.9", "0.00067"], ["84105.5", "0.011993"], ["84105.6", "0.000518"], ["84105.9", "0.005"], ["84106.4", "0.001556"], ["84107.8", "0.003563"], ["84108.1", "0.001333"], ["84108.3", "0.24"], ["84108.7", "0.005946"], ["84108.8", "0.17834"]], "u": 92329, "seq": 67563887551}, "cts": 1742569760716, "record_time": 1742569760.98793, "EXCHANGE": "BYBIT"}
{"topic": "orderbook.200.BTCUSDT", "ts": 1742569760919, "type": "delta", "data": {"s": "BTCUSDT", "b": [["84040.5", "0.353195"], ["84033.1", "0.0374"], ["84032.7", "0"], ["84028.2", "0.125515"], ["84026.7", "0.07144"], ["84025.7", "0.059399"], ["84025.6", "0"], ["84025.3", "0"], ["84024.3", "0.044"], ["84023.6", "0.06145"], ["84020.9", "0.044353"], ["84016.6", "0.055014"], ["84010.3", "0"], ["84009.6", "0.111144"], ["83999.5", "0.049548"], ["83999.4", "0.049548"], ["83999.3", "0.00052"], ["83999.2", "0"], ["83967.8", "0"], ["83967.3", "0"], ["83967", "0"]], "a": [["84040.6", "0.299346"], ["84043.5", "0"], ["84046.3", "0.004466"], ["84048.9", "0.117892"], ["84050.1", "0.071936"], ["84050.5", "0"], ["84051.9", "0.045609"], ["84052.9", "0.071417"], ["84055.9", "0"], ["84057.9", "0.178636"], ["84058.5", "0"], ["84058.6", "0.060837"], ["84059", "0.131692"], ["84063.8", "0"], ["84065.5", "0.035704"], ["84065.6", "0.060668"], ["84072.6", "0.1193"], ["84075.7", "0.063518"], ["84079.1", "0"], ["84079.2", "0.003415"], ["84080.9", "0"], ["84081.1", "0.347203"], ["84081.4", "0.014011"], ["84108", "0.171"], ["84108.8", "0"]], "u": 92330, "seq": 67563887656}, "cts": 1742569760904, "record_time": 1742569761.187643, "EXCHANGE": "BYBIT"}
{"topic": "orderbook.200.BTCUSDT", "ts": 1742569761119, "type": "delta", "data": {"s": "BTCUSDT", "b": [["84040.5", "0.524195"], ["84033.1", "0.054155"], ["84032.9", "0.071434"], ["84029.8", "0.12186"], ["84028.4", "0.168016"], ["84028.3", "0.120185"], ["84027.7", "0"], ["84027.1", "0.187952"], ["84026.7", "0"], ["84024.6", "0.24394"], ["84024.5", "0"], ["84024.1", "0.001333"], ["84023.6", "0"], ["84019.3", "0.170157"], ["84016.6", "0"], ["84012.3", "0.275656"], ["84009.6", "0"], ["83996.6", "0.096044"], ["83994.5", "0.089099"], ["83988.2", "0"], ["83978.4", "0.141149"], ["83969.1", "0"]], "a": [["84040.6", "0.211862"], ["84050.1", "0.000516"], ["84050.3", "0"], ["84052", "0.023809"], ["84054.3", "0.120995"], ["84056.6", "0.071414"], ["84057.9", "0.178483"], ["84058.6", "0"], ["84064.8", "0.189248"], ["84065.6", "0"], ["84071.8", "0.312284"], ["84072.6", "0"], ["84075.7", "0"], ["84078.7", "0.066317"], ["84079.2", "0"], ["84079.5", "0.003415"], ["84081", "0"], ["84081.1", "0.307203"], ["84081.2", "0.04009"], ["84081.3", "0.04"], ["84108.8", "0.17834"], ["84108.9", "0.000333"]], "u": 92331, "seq": 67563887773}, "cts": 1742569761114, "record_time": 1742569761.388718, "EXCHANGE": "BYBIT"}
{"topic": "orderbook.200.BTCUSDT", "ts": 1742569761320, "type": "delta", "data": {"s": "BTCUSDT", "b": [["84033.1", "0.070734"], ["84029.8", "0"], ["84019.3", "0"], ["84012.3", "0"], ["84002.2", "0.049545"], ["84002.1", "0.049545"], ["83999.5", "0"], ["83999.4", "0"], ["83969.1", "3.754103"], ["83967.8", "0.001466"], ["83967.3", "0.118852"]], "a": [["84040.6", "0.226728"], ["84041.7", "0.071427"], ["84051.9", "0.043064"], ["84054.3", "0"], ["84058.9", "0.000153"], ["84064.8", "0.001466"], ["84065.5", "0"], ["84071.8", "0"], ["84079.5", "0"], ["84080.4", "0.003415"], ["84081.2", "0.00009"], ["84081.3", "0"], ["84082.1", "0.04"], ["84082.2", "0.04"]], "u": 92332, "seq": 67563887873}, "cts": 1742569761302, "record_time": 1742569761.597856, "EXCHANGE": "BYBIT"}
{"topic": "orderbook.200.BTCUSDT", "ts": 1742569761519, "type": "delta", "data": {"s": "BTCUSDT", "b": [["84046.2", "0.887883"], ["84045.4", "0.089099"], ["84045.1", "0.0813"], ["84045", "0.271"], ["84041.7", "0.051866"], ["84041.6", "0.000333"], ["84040.9", "0.001849"], ["84040.6", "0.067625"], ["84040.5", "0.225355"], ["84037.8", "0.121691"], ["84037.4", "0.071764"], ["84036.4", "0.0016"], ["84035.1", "0.059399"], ["84035", "0.178497"], ["84034.9", "0"], ["84033.6", "0.00009"], ["84033.5", "0.146754"], ["84033.4", "0.119452"], ["84033.3", "0.178501"], ["84033.2", "0.0191"], ["84033.1", "0"], ["84033", "0.089099"], ["84032.1", "0.003643"], ["84031.8", "0.04"], ["84030.7", "0"], ["84030.2", "0"], ["84029.4", "0"], ["84028.4", "0"], ["84028.2", "0"], ["84027.1", "0.009438"], ["84022.2", "0"], ["84019.7", "0.51707"], ["84019.6", "0.089099"], ["84019.5", "0.00364"], ["84019.2", "0.045631"], ["84017.9", "0.178129"], ["84016.4", "0.000333"], ["84015.6", "0.55974"], ["84015.3", "0.215542"], ["84015", "0"], ["84012.9", "0"], ["84012.6", "0"], ["84012.2", "0.307788"], ["84008.7", "0"], ["84007.3", "0.003033"], ["84005.8", "0"], ["84002.8", "0"], ["84002.5", "0.062881"], ["84002.4", "0.049544"], ["84002.2", "0"], ["84002.1", "0"], ["84000.3", "0"], ["84000.2", "0"], ["83997.2", "0"], ["83996.6", "0"], ["83991.9", "0"], ["83988.4", "0"], ["83978.6", "1.230646"], ["83971.1", "0"], ["83967.4", "0.54988"], ["83967", "0.00052"]], "a": [["84040.6", "0"], ["84041.7", "0"], ["84045.1", "0"], ["84045.5", "0"], ["84045.8", "0"], ["84046.3", "0"], ["84048.6", "0"], ["84048.9", "0.003668"], ["84049", "0"], ["84049.3", "0.001333"], ["84050.2", "0"], ["84051.3", "0.043868"], ["84051.9", "0"], ["84052", "0"], ["84052.8", "0"], ["84052.9", "0"], ["84053.5", "0.016333"], ["84053.6", "0"], ["84054.7", "0.005225"], ["84054.8", "0.000516"], ["84055.5", "0.077957"], ["84055.7", "0"], ["84056.3", "0"], ["84056.6", "0"], ["84057.1", "0.024154"], ["84057.4", "0.04"], ["84057.9", "0"], ["84058", "0"], ["84058.4", "0.028485"], ["84058.9", "0.057478"], ["84059", "0.04"], ["84059.1", "0"], ["84060.8", "0"], ["84061.7", "0"], ["84063.1", "0"], ["84063.2", "0"], ["84063.3", "0"], ["84064.9", "0"], ["84065", "0"], ["84066.6", "0.04"], ["84066.7", "0"], ["84067.3", "0.059525"], ["84067.9", "0"], ["84068.1", "0.116488"], ["84068.9", "0"], ["84069.7", "0.009337"], ["84070.9", "0.178473"], ["84073.5", "0"], ["84076", "0"], ["84077.7", "0"], ["84078.7", "0.002799"], ["84080.4", "0"], ["84081.1", "0"], ["84082", "0"], ["84082.1", "0"], ["84082.2", "0"], ["84082.5", "0.000516"], ["84085.2", "0.549476"], ["84085.9", "0"], ["84087.2", "0.517466"], ["84088.1", "0.043415"], ["84089.8", "0"], ["84089.9", "0.04"], ["84090", "0.04"], ["84092.7", "0.063518"], ["84097", "0"], ["84101.4", "0"], ["84108.7", "0"], ["84108.8", "0"], ["84109.9", "0.0006"], ["84110.3", "0.000518"], ["84111.1", "0.001549"], ["84111.2", "0.015"], ["84112", "0.003563"], ["84112.2", "0.118852"], ["84112.3", "0.001333"], ["84112.6", "0.0006"], ["84113.1", "0.000333"], ["84113.6", "0.000333"], ["84114", "0.059399"], ["84114.7", "0.614161"], ["84114.8", "0.00009"], ["84114.9", "0.000518"], ["84115.7", "0.001466"], ["84115.8", "0.085864"], ["84116.2", "0.028203"], ["84116.6", "0.001333"], ["84117.3", "0.000333"], ["84117.4", "0.118852"], ["84119.1", "0.195"], ["84119.5", "0.000518"], ["84120.3", "0.001466"], ["84120.4", "0.003564"], ["84120.8", "0.001333"], ["84121.1", "0.114"], ["84121.5", "0.003333"], ["84122.2", "0.039588"], ["84123.2", "0.00009"], ["84123.4", "0.118852"], ["84123.5", "0.085613"], ["84124.1", "0.000518"], ["84124.5", "0.356403"], ["84124.6", "0.006049"]], "u": 92333, "seq": 67563888683}, "cts": 1742569761517, "record_time": 1742569761.78882, "EXCHANGE": "BYBIT"}
{"topic": "orderbook.200.BTCUSDT", "ts": 1742569761719, "type": "delta", "data": {"s": "BTCUSDT", "b": [["84046.2", "0.934672"], ["84045.5", "0.051059"], ["84045.4", "0"], ["84045.1", "0"], ["84044.2", "0.004035"], ["84041.8", "0.135897"], ["84041.7", "0.140565"], ["84040.6", "0"], ["84037.8", "0.176141"], ["84037.3", "0.109673"], ["84037", "0.178493"], ["84036.9", "0.04"], ["84036.8", "0.011"], ["84035.9", "0.071432"], ["84035.2", "0.044"], ["84035", "0"], ["84034", "0.044"], ["84033.5", "0.230924"], ["84033.4", "0.159452"], ["84033.2", "0.000333"], ["84032.9", "0"], ["84032.1", "0.047643"], ["84031.7", "0.17962"], ["84030.4", "0.052"], ["84030.3", "0"], ["84030.2", "0.048"], ["84028.4", "0.108929"], ["84026.9", "0"], ["84026.8", "0.186314"], ["84024.6", "0.0025"], ["84021.7", "0"], ["84021.3", "0.178473"], ["84020.1", "0.178473"], ["84019.8", "0.291164"], ["84019.2", "0.03731"], ["84017.9", "0"], ["84017.2", "0.059491"], ["84017.1", "0.178473"], ["84015.3", "0.00364"], ["84011.7", "0"], ["84010.2", "0.004591"], ["84007.6", "0.049545"], ["84007.5", "0.049545"], ["84007", "0"], ["84005.8", "0.124931"], ["84003.7", "0.280533"], ["84002.5", "0.012881"], ["84002.4", "0"], ["84002.3", "0.096037"], ["83998.3", "0"], ["83998", "0.02016"], ["83993.9", "0.227696"], ["83991.9", "0.089237"], ["83983.5", "0"], ["83978.4", "0.365532"], ["83972.4", "0"], ["83971.6", "0"], ["83970.9", "0"], ["83970.2", "0"], ["83970", "0"], ["83969.5", "0"], ["83969.1", "0"], ["83967.8", "0"], ["83967.4", "0"], ["83967.3", "0"], ["83967", "0"]], "a": [["84046.3", "0.033913"], ["84053.8", "0.106645"], ["84054.1", "0.071416"], ["84054.7", "0.03135"], ["84054.9", "0"], ["84055.5", "0"], ["84056", "0"], ["84057.3", "0.066655"], ["84057.4", "0"], ["84058.9", "0.035384"], ["84059", "0"], ["84061.8", "0.120152"], ["84062.2", "0"], ["84063", "0.106056"], ["84065.5", "0.178473"], ["84066", "0"], ["84066.4", "0.071406"], ["84066.6", "0"], ["84067.3", "0.143344"], ["84067.5", "0.178473"], ["84068", "0.04"], ["84068.5", "0.004042"], ["84069.4", "0.072869"], ["84071.7", "0.178473"], ["84072.3", "0.172831"], ["84073.4", "0.178473"], ["84073.7", "0.057534"], ["84077.5", "0.004567"], ["84079.3", "0.301302"], ["84080", "0"], ["84085", "0.42404"], ["84086.5", "0"], ["84086.6", "0"], ["84088.1", "0"], ["84088.4", "0.003415"], ["84089.5", "0.118852"], ["84089.7", "0"], ["84089.9", "0.124931"], ["84090", "0"], ["84090.1", "0.04"], ["84090.2", "0.04"], ["84091.7", "0"], ["84092.7", "0"], ["84097", "0.089237"], ["84100", "0"], ["84109.1", "0.003575"], ["84110.9", "0.124931"], ["84116.5", "0.171"], ["84118", "0.089237"], ["84118.2", "0.027543"], ["84121.5", "0"], ["84122.2", "0"], ["84123.2", "0"], ["84123.4", "0"], ["84123.5", "0"], ["84124.1", "0"], ["84124.5", "0"], ["84124.6", "0"]], "u": 92334, "seq": 67563889013}, "cts": 1742569761716, "record_time": 1742569761.988741, "EXCHANGE": "BYBIT"}
{"topic": "orderbook.200.BTCUSDT", "ts": 1742569761920, "type": "delta", "data": {"s": "BTCUSDT", "b": [["84046.2", "0.936456"], ["84045.5", "0.076128"], ["84041.8", "0"], ["84041.7", "0.031466"], ["84040.6", "0.066125"], ["84040.5", "0.205355"], ["84037.3", "0"], ["84035.2", "0.084"], ["84031.7", "0.21962"], ["84028.4", "0.070529"], ["84027", "0.000516"], ["84026.8", "0"], ["84024.3", "0"], ["84024", "0"], ["84023.4", "0"], ["84022.9", "0"], ["84022.8", "0"], ["84019.8", "0"], ["84007.8", "0.05"], ["84007.7", "0.049545"], ["84007.6", "0"], ["84007.5", "0"], ["84005.1", "0.096071"], ["84002.3", "0"], ["84000.6", "0"], ["83997", "0.013694"], ["83984.2", "0.024868"], ["83972.4", "0.001466"], ["83971.6", "0.00052"], ["83970.9", "0.089243"], ["83970.2", "0.000333"], ["83970", "0.007148"], ["83969.5", "0.001333"], ["83969.1", "3.754103"]], "a": [["84046.3", "0.048779"], ["84054.1", "0"], ["84057", "0.067492"], ["84057.3", "0.026655"], ["84058.9", "0.014195"], ["84061.8", "0"], ["84063", "0.104314"], ["84064.8", "0.041466"], ["84065.7", "0.08"], ["84066.6", "0.000153"], ["84067.3", "0.211621"], ["84067.4", "0.271"], ["84069.4", "0.001466"], ["84070.8", "0.04"], ["84072.3", "0.04"], ["84079.3", "0"], ["84093.2", "0"], ["84093.7", "0"], ["84102.2", "0.04"], ["84107.3", "0.04"], ["84107.5", "0.04"], ["84108.7", "0.124931"], ["84120.4", "0"], ["84120.8", "0"], ["84121.1", "0"]], "u": 92335, "seq": 67563889134}, "cts": 1742569761916, "record_time": 1742569762.188599, "EXCHANGE": "BYBIT"}
{"topic": "orderbook.200.BTCUSDT", "ts": 1742569762119, "type": "delta", "data": {"s": "BTCUSDT", "b": [["84033.3", "0.299053"], ["84028.4", "0.099626"], ["84026.6", "0"], ["84026.3", "0.166378"], ["84019.3", "0.275252"], ["84007.9", "0.05"], ["84007.8", "0.049545"], ["84007.7", "0"], ["83969.1", "0"]], "a": [["84046.3", "0.048429"], ["84051.3", "0"], ["84063", "0.148579"], ["84064.8", "0.001466"], ["84066.2", "0.120087"], ["84069.1", "0.04"], ["84071.6", "0.162928"], ["84073.2", "0.167635"], ["84073.7", "0.019816"], ["84080.2", "0.304391"], ["84088.3", "0"], ["84089.9", "0.188449"], ["84091.3", "0.001333"], ["84093.3", "0"], ["84119.5", "0"], ["84120.3", "0"]], "u": 92336, "seq": 67563889233}, "cts": 1742569762103, "record_time": 1742569762.387857, "EXCHANGE": "BYBIT"}
{"topic": "orderbook.200.BTCUSDT", "ts": 1742569762320, "type": "delta", "data": {"s": "BTCUSDT", "b": [["84037", "0"], ["84033.5", "0.146754"], ["84033.3", "0"], ["84031.7", "0.041116"], ["84029", "0.178843"], ["84028.4", "0.156822"], ["84027.3", "0.178513"], ["84026.3", "0"], ["84025.6", "0.178517"], ["84019.3", "0"], ["84011.5", "0.014213"], ["84011.4", "0.019517"], ["84007.9", "0.049545"], ["84002.6", "0"], ["84002.5", "0"], ["83969.1", "3.754103"], ["83967.8", "0.001466"], ["83967.6", "0.0003"], ["83967.4", "0.044775"]], "a": [["84053.5", "0.001333"], ["84054.7", "0.04635"], ["84063", "0.104314"], ["84064.7", "0.000153"], ["84066.2", "0"], ["84066.6", "0"], ["84069.2", "0.04"], ["84073.2", "0"], ["84075.1", "0.0357"], ["84080.2", "0"], ["84087.9", "0.004885"], ["84088.4", "0"], ["84119.5", "0.000518"], ["84120.3", "0.001466"]], "u": 92337, "seq": 67563889314}, "cts": 1742569762317, "record_time": 1742569762.588681, "EXCHANGE": "BYBIT"}
{"topic": "orderbook.200.BTCUSDT", "ts": 1742569762519, "type": "delta", "data": {"s": "BTCUSDT", "b": [["84045.2", "0.008208"], ["84039.7", "0.071429"], ["84037.8", "0.121691"], ["84035.9", "0"], ["84032.9", "0.111338"], ["84025.9", "0.166856"], ["84022.6", "0.178473"], ["84020.1", "0"], ["84018.9", "0.305633"], ["84011.6", "0.013"], ["84011.4", "0.006637"], ["84008", "0.050333"], ["84007.8", "0"], ["84003.7", "0"], ["83967.8", "0"], ["83967.6", "0"], ["83967.4", "0"]], "a": [["84052.9", "0.071417"], ["84063", "0.143789"], ["84063.3", "0.054564"], ["84063.7", "0.071408"], ["84065.8", "0.116383"], ["84070.9", "0.218473"], ["84072.8", "0.179674"], ["84079.8", "0.299735"], ["84087.9", "0.001466"], ["84088.4", "0.003419"], ["84094.2", "0"], ["84118.2", "0"], ["84119.1", "0"], ["84119.5", "0"], ["84120.3", "0"]], "u": 92338, "seq": 67563889393}, "cts": 1742569762515, "record_time": 1742569762.788059, "EXCHANGE": "BYBIT"}
{"topic": "orderbook.200.BTCUSDT", "ts": 1742569762720, "type": "delta", "data": {"s": "BTCUSDT", "b": [["84020.9", "0.388466"], ["84013.4", "0.04"], ["84013.3", "0.039631"], ["84011.4", "0"], ["84001.1", "0"], ["84001", "0"], ["83967.8", "0.001466"]], "a": [["84052.9", "0"], ["84063.8", "0.000153"], ["84064.7", "0"], ["84066.4", "0"], ["84089.4", "0.17587"], ["84118.2", "0.027543"]], "u": 92339, "seq": 67563889435}, "cts": 1742569762717, "record_time": 1742569762.987779, "EXCHANGE": "BYBIT"}
{"topic": "orderbook.200.BTCUSDT", "ts": 1742569762920, "type": "delta", "data": {"s": "BTCUSDT", "b": [["84032.9", "0"], ["84032.8", "0.117243"], ["84025.9", "0"], ["84025.8", "0.179114"], ["84024.9", "0.035701"], ["84018.9", "0"], ["84018.8", "0.3051"], ["84005.1", "0.096062"], ["83967.8", "0"]], "a": [["84051.9", "0.071418"], ["84058.9", "0.033844"], ["84061.1", "0.071411"], ["84065.7", "0.20322"], ["84065.8", "0.003669"], ["84072.7", "0.169641"], ["84072.8", "0.00009"], ["84079.7", "0.294134"], ["84079.8", "0"], ["84090.1", "0"], ["84090.2", "0"], ["84090.3", "0.04"], ["84090.4", "0.04"], ["84117.4", "0"], ["84118", "0"], ["84118.2", "0"]], "u": 92340, "seq": 67563889507}, "cts": 1742569762864, "record_time": 1742569763.188416, "EXCHANGE": "BYBIT"}
{"topic": "orderbook.200.BTCUSDT", "ts": 1742569763120, "type": "delta", "data": {"s": "BTCUSDT", "b": [["84032.8", "0"], ["84025.8", "0"], ["84018.8", "0"], ["84013.5", "0.04"], ["84013.4", "0.03963"], ["84013.3", "0"], ["84008.1", "0.061904"], ["84008", "0.049878"], ["84007.9", "0"], ["83967.8", "0.001466"], ["83967.6", "0.0003"], ["83967.5", "0.04626"], ["83967.4", "0.05"]], "a": [["84046.3", "0.023029"], ["84065.7", "0.08"], ["84072.7", "0"], ["84079.7", "0"], ["84088.4", "0"], ["84088.5", "0.003431"], ["84090.2", "0.04"], ["84090.4", "0"], ["84117.4", "0.118852"], ["84118", "0.089237"]], "u": 92341, "seq": 67563889570}, "cts": 1742569763094, "record_time": 1742569763.387953, "EXCHANGE": "BYBIT"}
{"topic": "orderbook.200.BTCUSDT", "ts": 1742569763319, "type": "delta", "data": {"s": "BTCUSDT", "b": [["84013.5", "0"], ["84013.3", "0.039631"], ["84008.1", "0.011904"], ["84007.9", "0.049545"], ["83967.9", "0.54992"], ["83967.5", "0"], ["83967.4", "0"]], "a": [["84051.9", "0"], ["84063.8", "0"], ["84068.7", "0.000995"], ["84088.4", "0.003431"], ["84088.5", "0"], ["84118.2", "0.027543"]], "u": 92342, "seq": 67563889607}, "cts": 1742569763314, "record_time": 1742569763.588202, "EXCHANGE": "BYBIT"}
{"topic": "orderbook.200.BTCUSDT", "ts": 1742569763520, "type": "delta", "data": {"s": "BTCUSDT", "b": [["84044.9", "0.0012"], ["84036.4", "0"], ["84015.8", "0.0016"], ["84007.3", "0.001333"], ["83967.6", "0"]], "a": [["84053.2", "0.071417"], ["84058.4", "0.008485"], ["84063.9", "0.000753"], ["84068.7", "0"], ["84088.2", "1.427076"], ["84089.9", "0.124931"], ["84090.1", "0.04"], ["84090.3", "0"], ["84092.7", "0.063518"], ["84118", "0"], ["84118.2", "0"]], "u": 92343, "seq": 67563889684}, "cts": 1742569763516, "record_time": 1742569763.788447, "EXCHANGE": "BYBIT"}
{"topic": "orderbook.200.BTCUSDT", "ts": 1742569763719, "type": "delta", "data": {"s": "BTCUSDT", "b": [["84037", "0.117198"], ["84027.2", "0.178322"], ["84018.1", "0.277831"], ["84015.7", "0.298937"], ["83969.1", "0"], ["83967.9", "0"], ["83967.8", "0"]], "a": [["84052.1", "0.071418"], ["84053.2", "0"], ["84058.9", "0.067358"], ["84062.2", "0.119901"], ["84072", "0.177396"], ["84081.1", "0.29209"], ["84085", "0.777809"], ["84116.6", "0"], ["84117.3", "0"], ["84117.4", "0"]], "u": 92344, "seq": 67563889755}, "cts": 1742569763674, "record_time": 1742569763.98769, "EXCHANGE": "BYBIT"}
{"topic": "orderbook.200.BTCUSDT", "ts": 1742569763919, "type": "delta", "data": {"s": "BTCUSDT", "b": [["84046.2", "0.766256"], ["84045.2", "0"], ["84037", "0"], ["84036.9", "0.163423"], ["84027.2", "0"], ["84027.1", "0.19478"], ["84024.1", "0.001928"], ["84018.1", "0"], ["84018", "0.305044"], ["84012", "0.01288"], ["84011.9", "0.01288"], ["84011.6", "0"], ["84011.5", "0.001333"], ["84008.4", "0.049724"], ["84008.3", "0.049544"], ["84008", "0.000333"], ["84007.9", "0"], ["84005.1", "0.09606"], ["83969.1", "3.754103"], ["83967.8", "0.001466"]], "a": [["84048.7", "0.071421"], ["84052.1", "0"], ["84057.5", "0.011902"], ["84058.9", "0.136682"], ["84062.1", "0.113679"], ["84062.2", "0"], ["84063.7", "0"], ["84067.3", "0.317925"], ["84068", "0.218473"], ["84071.9", "0.180847"], ["84072", "0"], ["84081", "0.29878"], ["84081.1", "0"], ["84087.6", "0.003431"], ["84088.4", "0"]], "u": 92345, "seq": 67563889888}, "cts": 1742569763917, "record_time": 1742569764.187912, "EXCHANGE": "BYBIT"}
{"topic": "orderbook.200.BTCUSDT", "ts": 1742569764119, "type": "delta", "data": {"s": "BTCUSDT", "b": [["84046.2", "0.88621"], ["84037.6", "0.019443"], ["84036.9", "0.04"], ["84036.7", "0.117475"], ["84027.1", "0.009438"], ["84026.9", "0.178691"], ["84020.1", "0.178473"], ["84018", "0"], ["84017.8", "0.305983"], ["84015.1", "0"], ["84013.4", "0"], ["84013.2", "0.040147"], ["84012", "0"], ["84011.9", "0"], ["84011.5", "0.014213"], ["84011.4", "0.01288"], ["84008.4", "0.00018"], ["84008.3", "0"], ["84007.9", "0.049545"], ["84007.8", "0.049545"], ["83967.9", "0.549934"], ["83967.8", "0"]], "a": [["84046.3", "0.027194"], ["84048.5", "0.071421"], ["84048.7", "0"], ["84057.5", "0"], ["84058.9", "0.136331"], ["84061.9", "0.113841"], ["84062.1", "0"], ["84063", "0.104314"], ["84067.3", "0.316629"], ["84068", "0.04"], ["84068.7", "0.000996"], ["84071.7", "0.355955"], ["84071.9", "0"], ["84073.4", "0"], ["84080.8", "0.276456"], ["84081", "0"], ["84087", "0.063518"], ["84087.6", "0"], ["84088.6", "0.003431"], ["84090.1", "0"], ["84090.2", "0"], ["84090.3", "0.04"], ["84090.4", "0.04"], ["84092.7", "0"], ["84116.6", "0.001333"], ["84117.3", "0.000333"], ["84117.4", "0.118852"]], "u": 92346, "seq": 67563890006}, "cts": 1742569764116, "record_time": 1742569764.388278, "EXCHANGE": "BYBIT"}
{"topic": "orderbook.200.BTCUSDT", "ts": 1742569764319, "type": "delta", "data": {"s": "BTCUSDT", "b": [["84036.7", "0.001333"], ["84032.6", "0.058587"], ["84029.5", "0.116391"], ["84026.9", "0"], ["84025.6", "0.235997"], ["84018.6", "0.120885"], ["84017.8", "0.000516"], ["84008", "0.050333"], ["84007.8", "0"], ["84007.6", "0.003482"], ["83967.9", "0"]], "a": [["84046.3", "0.028794"], ["84048.5", "0"], ["84049.7", "0.07142"], ["84058.8", "0.057042"], ["84058.9", "0.071412"], ["84061.9", "0.001333"], ["84066.8", "0.001473"], ["84067.6", "0.058819"], ["84068.7", "0"], ["84069.2", "0.041107"], ["84071.7", "0.178473"], ["84074.6", "0.059301"], ["84080.8", "0"], ["84081.6", "0.144209"], ["84117.4", "0"]], "u": 92347, "seq": 67563890073}, "cts": 1742569764310, "record_time": 1742569764.588563, "EXCHANGE": "BYBIT"}
{"topic": "orderbook.200.BTCUSDT", "ts": 1742569764520, "type": "delta", "data": {"s": "BTCUSDT", "b": [["84046.2", "0.88551"], ["84032.9", "0.114944"], ["84032.6", "0"], ["84029.1", "0.236535"], ["84028.4", "0"], ["84025.9", "0.184018"], ["84025.6", "0.178517"], ["84020.1", "0"], ["84018.9", "0.296438"], ["84018.6", "0.001466"], ["84008.1", "0.061904"], ["84008", "0.049878"], ["84007.9", "0"]], "a": [["84049.7", "0"], ["84049.9", "0.07142"], ["84065.5", "0"], ["84065.8", "0.126465"], ["84066.8", "0.000333"], ["84067.6", "0"], ["84069.2", "0.04"], ["84070.9", "0.04"], ["84072.8", "0.186375"], ["84073.4", "0.178473"], ["84074.6", "0"], ["84079.8", "0.27511"], ["84081.6", "0.023792"], ["84088.6", "0"], ["84088.7", "0.003431"], ["84090.3", "0"], ["84090.5", "0.04"], ["84117.4", "0.118852"]], "u": 92348, "seq": 67563890147}, "cts": 1742569764516, "record_time": 1742569764.788416, "EXCHANGE": "BYBIT"}
{"topic": "orderbook.200.BTCUSDT", "ts": 1742569764719, "type": "delta", "data": {"s": "BTCUSDT", "b": [["84040.5", "0.204663"], ["84024", "0.195906"], ["84011.7", "0.013"], ["84011.6", "0.01288"], ["84011.5", "0.001333"], ["84011.4", "0"], ["83969.5", "0"], ["83969.1", "0"]], "a": [["84063.9", "0.0006"], ["84067.3", "0.211621"], ["84076", "0.178473"], ["84080", "0.086138"], ["84117.3", "0"], ["84117.4", "0"]], "u": 92349, "seq": 67563890184}, "cts": 1742569764707, "record_time": 1742569764.988258, "EXCHANGE": "BYBIT"}
{"topic": "orderbook.200.BTCUSDT", "ts": 1742569764920, "type": "delta", "data": {"s": "BTCUSDT", "b": [["84013.4", "0.03963"], ["84013.2", "0.000516"], ["84011.7", "0"], ["84011.5", "0.014213"], ["84008.1", "0.011904"], ["84007.9", "0.049545"], ["83998.3", "0.068858"], ["83970.2", "0"], ["83970", "0"]], "a": [["84059.7", "0.000153"], ["84068.5", "0.005001"], ["84070.5", "0.178473"], ["84088.7", "0"], ["84088.8", "0.003431"], ["84090.4", "0"], ["84090.6", "0.04"], ["84116.5", "0"], ["84116.6", "0"]], "u": 92350, "seq": 67563890220}, "cts": 1742569764917, "record_time": 1742569765.188944, "EXCHANGE": "BYBIT"}
{"topic": "orderbook.200.BTCUSDT", "ts": 1742569765119, "type": "delta", "data": {"s": "BTCUSDT", "b": [["84005.1", "0.096068"]], "a": [["84065.5", "0.178473"], ["84070.5", "0"], ["84070.9", "0.218473"], ["84073.4", "0"], ["84076", "0"], ["84088.8", "0"], ["84088.9", "0.003431"], ["84090.5", "0"], ["84090.7", "0.04"], ["84116.6", "0.001333"], ["84117.3", "0.000333"]], "u": 92351, "seq": 67563890263}, "cts": 1742569765093, "record_time": 1742569765.38837, "EXCHANGE": "BYBIT"}
{"topic": "orderbook.200.BTCUSDT", "ts": 1742569765319, "type": "delta", "data": {"s": "BTCUSDT", "b": [["84046.2", "0.88658"], ["84032.9", "0"], ["84025.9", "0"], ["84018.9", "0"], ["84013.4", "0"], ["84013.2", "0.040147"], ["84011.6", "0"], ["84011.4", "0.01288"], ["84008", "0.000333"], ["84007.8", "0.049545"], ["83981.8", "0.000361"], ["83970.2", "0.000333"], ["83970", "0.007148"], ["83969.5", "0.001333"]], "a": [["84046.3", "0.013928"], ["84049.9", "0"], ["84058.8", "0.035618"], ["84058.9", "0"], ["84059.7", "0"], ["84063", "0.064374"], ["84063.6", "0.071408"], ["84065.5", "0"], ["84065.8", "0.003669"], ["84067.5", "0"], ["84068.5", "0.004995"], ["84070.9", "0.04"], ["84072.8", "0.00009"], ["84073.1", "0.178473"], ["84073.4", "0.178473"], ["84076", "0.178473"], ["84076.5", "0.023796"], ["84079.8", "0"], ["84088.9", "0"], ["84089.4", "0.179301"], ["84090.6", "0"], ["84090.7", "0"], ["84091.1", "0.04"], ["84091.2", "0.04"], ["84116.5", "0.171"], ["84117.4", "0.118852"]], "u": 92352, "seq": 67563890380}, "cts": 1742569765316, "record_time": 1742569765.588182, "EXCHANGE": "BYBIT"}
{"topic": "orderbook.200.BTCUSDT", "ts": 1742569765520, "type": "delta", "data": {"s": "BTCUSDT", "b": [["84053", "0.902722"], ["84052.8", "0.030965"], ["84052.7", "0.101434"], ["84051.3", "0.0003"], ["84050", "0.235307"], ["84049.9", "0.392"], ["84048.9", "0.185659"], ["84048.8", "0.11"], ["84046.9", "0.071422"], ["84046.3", "0.001466"], ["84046.2", "0.05167"], ["84045.8", "0.000333"], ["84045.5", "0.000516"], ["84045.1", "0.001333"], ["84045", "0"], ["84044.6", "0.015"], ["84043.9", "0.044"], ["84043.7", "0.008135"], ["84042.7", "0.071426"], ["84042", "0.00009"], ["84041.1", "0.00948"], ["84040.9", "0.045849"], ["84040.8", "0.123001"], ["84040.7", "0.118852"], ["84040.6", "0"], ["84039.7", "0"], ["84038.9", "0.048"], ["84038.8", "0.052"], ["84037.8", "0"], ["84037.4", "0.000333"], ["84037", "0.073195"], ["84034.6", "0"], ["84033.1", "0.51707"], ["84029", "0.000333"], ["84027.3", "0"], ["84027.1", "0"], ["84025.6", "0"], ["84022.6", "0"], ["84021.3", "0"], ["84019.7", "0"], ["84017.1", "0"], ["84016.6", "0.011903"], ["84014.6", "0.049545"], ["84014.5", "0.049545"], ["84012.3", "0.01288"], ["84012.2", "0.320668"], ["84011.5", "0.001333"], ["84011.4", "0"], ["84008", "0.096398"], ["84007.9", "0"], ["84007.8", "0"], ["84005.1", "0"], ["84002", "0.178567"], ["83989.7", "0.174575"], ["83984.8", "0"], ["83981.4", "0"], ["83974.6", "0"], ["83974.4", "0"], ["83973.7", "0"], ["83973.3", "0"], ["83972.7", "0"], ["83972.4", "0"], ["83971.6", "0"], ["83970.9", "0"], ["83970.2", "0"], ["83970", "0"], ["83969.5", "0"]], "a": [["84046.3", "0"], ["84048.9", "0"], ["84049.3", "0"], ["84050", "0"], ["84050.1", "0"], ["84050.9", "0"], ["84051", "0"], ["84051.4", "0"], ["84053.1", "0.006062"], ["84053.8", "0"], ["84054.7", "0"], ["84057", "0"], ["84057.1", "0"], ["84057.3", "0.018669"], ["84057.8", "0"], ["84058.4", "0.000333"], ["84058.8", "0"], ["84061.1", "0"], ["84062", "0"], ["84062.7", "0"], ["84063", "0"], ["84063.3", "0"], ["84063.6", "0"], ["84064.4", "0.071408"], ["84067.3", "0.147539"], ["84068", "0"], ["84068.1", "0.0001"], ["84068.5", "0.004042"], ["84071.6", "0"], ["84071.7", "0"], ["84072.2", "0.040418"], ["84073.1", "0"], ["84073.4", "0"], ["84073.7", "0.091216"], ["84073.8", "0"], ["84074.1", "0.041466"], ["84074.4", "0"], ["84074.9", "0"], ["84075.1", "0"], ["84076", "0"], ["84076.5", "0"], ["84081.4", "0"], ["84083.5", "0.178459"], ["84085.2", "0"], ["84087", "0"], ["84087.2", "0"], ["84087.7", "0"], ["84088.2", "0"], ["84089.4", "0.17587"], ["84089.5", "0"], ["84089.9", "0"], ["84091.1", "0"], ["84091.2", "0"], ["84095", "0.000118"], ["84096.2", "0.003764"], ["84096.9", "0"], ["84097", "0"], ["84097.6", "0.023787"], ["84097.8", "0"], ["84097.9", "0.0406"], ["84098", "0.04018"], ["84099.4", "0.553038"], ["84101.4", "0.557466"], ["84104.6", "0.060723"], ["84105.5", "0"], ["84105.9", "0.045"], ["84108.9", "0.000483"], ["84111", "0.04"], ["84118", "0.089237"], ["84118.2", "0.027543"], ["84119.1", "0.195"], ["84119.5", "0.000518"], ["84120.3", "0.001466"], ["84120.4", "0.003564"], ["84120.8", "0.001333"], ["84121.1", "0.114"], ["84121.5", "0.000333"], ["84122.2", "0.039588"], ["84123.2", "0.00009"], ["84123.4", "0.118852"], ["84123.5", "0.059399"], ["84124.1", "0.000518"], ["84124.6", "0.006049"], ["84124.9", "0.001466"], ["84125", "0.001333"], ["84125.7", "0.000333"], ["84126.1", "0.000361"], ["84127", "0.000204"], ["84127.2", "0.04"], ["84127.8", "3.445452"], ["84128.6", "0.118852"], ["84128.8", "0.004067"], ["84129.2", "0.041333"], ["84129.6", "0.001466"], ["84129.8", "0.024897"], ["84129.9", "0.000333"], ["84130", "1.101208"], ["84130.2", "0.00315"], ["84130.5", "0.025878"], ["84130.6", "0.043886"], ["84131.6", "0.00309"], ["84132", "0.059399"], ["84133", "0.003549"], ["84133.1", "0.044598"], ["84133.4", "0.001851"], ["84133.8", "0.013074"], ["84134", "0.05"], ["84134.1", "0.101071"], ["84134.2", "0.001466"]], "u": 92353, "seq": 67563891631}, "cts": 1742569765516, "record_time": 1742569765.788978, "EXCHANGE": "BYBIT"}
{"topic": "orderbook.200.BTCUSDT", "ts": 1742569765719, "type": "delta", "data": {"s": "BTCUSDT", "b": [["84053", "0.84729"], ["84052.8", "0"], ["84052.7", "0"], ["84050.1", "0.011902"], ["84050", "0.172466"], ["84048.9", "0"], ["84044.7", "0.121941"], ["84044.6", "0.137286"], ["84044", "0.04"], ["84043.8", "0.005335"], ["84042.2", "0.04"], ["84042", "0.04409"], ["84041", "0.247919"], ["84040.9", "0.224334"], ["84040.8", "0"], ["84040.6", "0.04"], ["84039.2", "0.178488"], ["84037.6", "0.154844"], ["84037.5", "0.178492"], ["84037", "0"], ["84035.2", "0.04"], ["84034.8", "0.179873"], ["84034", "0"], ["84033.4", "0.119452"], ["84032.7", "0.178459"], ["84032.1", "0.003643"], ["84030.4", "0"], ["84030.2", "0"], ["84029.7", "0.178459"], ["84029.1", "0"], ["84026", "0.037711"], ["84025.7", "0.349543"], ["84025.5", "0.178459"], ["84024.7", "0"], ["84024", "0"], ["84020.9", "0.044353"], ["84019.2", "0"], ["84014.6", "0"], ["84014.5", "0"], ["84014.3", "0.050145"], ["84014.2", "0.049545"], ["84012.9", "0.089229"], ["84008", "0.000333"], ["84007.6", "0"], ["84002.3", "0.096058"], ["83975.3", "0.549867"], ["83974.8", "0"], ["83974.7", "0"]], "a": [["84053.1", "0.013201"], ["84060.4", "0.000297"], ["84060.5", "0.046408"], ["84060.6", "0.106645"], ["84061.5", "0.03135"], ["84062.3", "0.02134"], ["84064.1", "0.022985"], ["84064.4", "0"], ["84065.6", "0.025898"], ["84067.5", "0.008275"], ["84069.7", "0"], ["84069.8", "0.119784"], ["84072.2", "0.047167"], ["84073.7", "0.019816"], ["84075.5", "0.009337"], ["84079.6", "0.180046"], ["84079.9", "0.006062"], ["84080", "0.124706"], ["84080.2", "0.178459"], ["84080.3", "0.116389"], ["84083.5", "0"], ["84085", "0"], ["84088.7", "0.299098"], ["84089.4", "0"], ["84095.4", "0.014091"], ["84096.2", "0.000333"], ["84096.7", "0.118852"], ["84096.8", "0.272507"], ["84096.9", "0.003431"], ["84097", "0.089229"], ["84097.9", "0.0006"], ["84098", "0.00018"], ["84098.3", "0.063517"], ["84098.6", "0.04"], ["84098.7", "0.04"], ["84102.8", "0"], ["84106.3", "0.04"], ["84125", "0.172333"], ["84129.2", "0"], ["84129.6", "0"], ["84129.8", "0"], ["84129.9", "0"], ["84130", "0"], ["84130.2", "0"], ["84130.5", "0"], ["84130.6", "0"], ["84131.6", "0"], ["84132", "0"], ["84133", "0"], ["84133.1", "0"], ["84133.4", "0"], ["84133.8", "0"], ["84134", "0"], ["84134.1", "0"], ["84134.2", "0"]], "u": 92354, "seq": 67563891839}, "cts": 1742569765714, "record_time": 1742569765.989049, "EXCHANGE": "BYBIT"}
{"topic": "orderbook.200.BTCUSDT", "ts": 1742569765920, "type": "delta", "data": {"s": "BTCUSDT", "b": [["84051.3", "0"], ["84045.7", "0.044"], ["84045.6", "0.04"], ["84044", "0.059443"], ["84040.6", "0.08"], ["84036.9", "0"], ["84035.2", "0"], ["84033.5", "0.367702"], ["84033", "0.267558"], ["84031.8", "0"], ["84031.7", "0.001116"], ["84026.8", "0.124921"], ["84017.9", "0.013"], ["84017.8", "0.013396"], ["84012.3", "0"], ["84012.2", "0.307788"], ["84005.1", "0.096061"], ["84002.3", "0"], ["83982", "0.224383"], ["83978.4", "0.141149"], ["83977", "0.001766"]], "a": [["84067.5", "0.000153"], ["84075.6", "0.178459"], ["84076", "0.178459"], ["84078.4", "0.182129"], ["84079.5", "0.054014"], ["84087.7", "0.124921"], ["84089.9", "0.124921"], ["84095.5", "0.064852"], ["84096.5", "0.003431"], ["84096.9", "0"], ["84098.3", "0"], ["84127.2", "0"], ["84127.8", "0"], ["84128.6", "0"], ["84128.8", "0"]], "u": 92355, "seq": 67563891909}, "cts": 1742569765899, "record_time": 1742569766.188122, "EXCHANGE": "BYBIT"}
{"topic": "orderbook.200.BTCUSDT", "ts": 1742569766120, "type": "delta", "data": {"s": "BTCUSDT", "b": [["84044.7", "0.166532"], ["84044.6", "0.015"], ["84042.7", "0.136274"], ["84042.6", "0.178481"], ["84040.9", "0.001849"], ["84037.6", "0.076882"], ["84034.8", "0"], ["84033", "0.089099"], ["84025.7", "0.059399"], ["84017.9", "0.01288"], ["84013.6", "0.15546"], ["84005.1", "0.04"], ["84003.7", "0.237224"], ["83975.2", "0"]], "a": [["84057", "0.071414"], ["84065.6", "0.044119"], ["84066", "0.071406"], ["84066.5", "0.000153"], ["84067.5", "0"], ["84069", "0.054564"], ["84069.8", "0"], ["84072.2", "0.09761"], ["84075.4", "0.059399"], ["84075.6", "0"], ["84076", "0"], ["84078.4", "0.00367"], ["84079.6", "0"], ["84080.2", "0"], ["84080.9", "0.178459"], ["84083.1", "0.178459"], ["84084.4", "0.178459"], ["84088.6", "0.178459"], ["84088.7", "0"], ["84096.5", "0"], ["84096.7", "0.122283"], ["84127", "0"]], "u": 92356, "seq": 67563891995}, "cts": 1742569766116, "record_time": 1742569766.388655, "EXCHANGE": "BYBIT"}
{"topic": "orderbook.200.BTCUSDT", "ts": 1742569766319, "type": "delta", "data": {"s": "BTCUSDT", "b": [["84051.1", "0.053539"], ["84051", "0.178463"], ["84050", "0.273695"], ["84049.3", "0.178467"], ["84047.6", "0.17847"], ["84046.2", "0.052354"], ["84044.7", "0.121941"], ["84044", "0.179195"], ["84042.6", "0"], ["84041", "0"], ["84039.2", "0"], ["84037.6", "0"], ["84037.5", "0"], ["84033.5", "0.532186"], ["84026.5", "0.307354"], ["84019.8", "0.04"], ["84019.7", "0.039631"], ["84018", "0.013"], ["84017.8", "0.000516"], ["84014.4", "0.05"], ["84014.2", "0"], ["84013.3", "0"], ["84013.2", "0.000516"], ["83976.2", "0"], ["83975.3", "0"]], "a": [["84055.8", "0.071415"], ["84057", "0"], ["84057.3", "0.003669"], ["84061.5", "0.04635"], ["84063.8", "0.055008"], ["84063.9", "0.072008"], ["84065.6", "0.000297"], ["84066", "0"], ["84068.1", "0.071505"], ["84068.5", "0.127952"], ["84072.2", "0.047167"], ["84078.4", "0.182129"], ["84079", "0.173539"], ["84079.5", "0"], ["84080.9", "0"], ["84083.1", "0"], ["84084.4", "0"], ["84086", "0.280488"], ["84088.6", "0"], ["84096.6", "0.003431"], ["84096.7", "0.118852"], ["84098.3", "0.04"], ["84098.4", "0.04"], ["84098.6", "0"], ["84098.7", "0"], ["84127", "0.000204"], ["84127.2", "0.04"]], "u": 92357, "seq": 67563892090}, "cts": 1742569766306, "record_time": 1742569766.588408, "EXCHANGE": "BYBIT"}
{"topic": "orderbook.200.BTCUSDT", "ts": 1742569766520, "type": "delta", "data": {"s": "BTCUSDT", "b": [["84040.8", "0.151073"], ["84036.4", "0.019095"], ["84019.8", "0"], ["84019.7", "0"], ["84019.5", "0.04364"], ["84019.4", "0.039631"], ["84018", "0"], ["84017.9", "0"], ["84017.7", "0.013"], ["84017.6", "0.01288"], ["84014.4", "0"], ["84014.3", "0.0006"], ["84014.1", "0.05"], ["84014", "0.051012"], ["83984.2", "0"]], "a": [["84075.6", "0.178459"], ["84076", "0.178459"], ["84078.3", "0.113701"], ["84080.2", "0.178459"], ["84096.5", "0.003431"], ["84096.6", "0"], ["84125.7", "0"], ["84126.1", "0"], ["84127", "0"], ["84127.2", "0"]], "u": 92358, "seq": 67563892131}, "cts": 1742569766507, "record_time": 1742569766.805904, "EXCHANGE": "BYBIT"}
{"topic": "orderbook.200.BTCUSDT", "ts": 1742569766720, "type": "delta", "data": {"s": "BTCUSDT", "b": [["84053", "0.84916"], ["84046.2", "0.051284"], ["84044.7", "0.185219"], ["84043.1", "0.178459"], ["84030.8", "0.013201"], ["84024.9", "0"], ["84015.7", "0.321599"], ["83977", "0"]], "a": [["84067.5", "0.008138"], ["84072.2", "0.11543"], ["84098.2", "0.04"], ["84098.4", "0"], ["84099.8", "0.029927"], ["84125", "0"]], "u": 92359, "seq": 67563892189}, "cts": 1742569766716, "record_time": 1742569766.988937, "EXCHANGE": "BYBIT"}
{"topic": "orderbook.200.BTCUSDT", "ts": 1742569766920, "type": "delta", "data": {"s": "BTCUSDT", "b": [["84053", "0.846306"], ["84051.1", "0"], ["84051", "0"], ["84050.1", "0"], ["84049.9", "0.342"], ["84049.3", "0"], ["84048.8", "0.06"], ["84047.7", "0.17847"], ["84047.6", "0"], ["84046.2", "0.031284"], ["84046.1", "0.178473"], ["84044.4", "0.178477"], ["84044", "0.059443"], ["84043.1", "0"], ["84033.5", "0.367702"], ["84032.7", "0"], ["84026.9", "0.21238"], ["84026.5", "0"], ["84019.5", "0.043271"], ["84014.2", "0.05"], ["84014.1", "0.049545"], ["84014", "0.001466"], ["84010.3", "0.00107"], ["83982", "0"], ["83977", "0.001766"], ["83976.2", "0.00052"], ["83975.3", "0.044612"]], "a": [["84055.8", "0"], ["84060.5", "0.069523"], ["84061.9", "0.072743"], ["84068.1", "0.0001"], ["84068.5", "0.004042"], ["84079", "0"], ["84085.4", "0.148929"], ["84086", "0"], ["84096.5", "0"], ["84096.6", "0.003431"], ["84098.2", "0"], ["84098.3", "0"], ["84098.4", "0.04"], ["84098.5", "0.063787"], ["84125", "0.001333"], ["84125.7", "0.000333"], ["84126.1", "0.000361"]], "u": 92360, "seq": 67563892328}, "cts": 1742569766904, "record_time": 1742569767.189051, "EXCHANGE": "BYBIT"}
{"topic": "orderbook.200.BTCUSDT", "ts": 1742569767119, "type": "delta", "data": {"s": "BTCUSDT", "b": [["84053", "0.675306"], ["84050", "0.172466"], ["84049.9", "0.345"], ["84046.2", "0.001284"], ["84046.1", "0"], ["84044.4", "0"], ["84043.5", "0.178479"], ["84041.8", "0.178483"], ["84038.1", "0.178459"], ["84026.9", "0"], ["84014.6", "0.05"], ["84014.5", "0.049545"], ["84014.2", "0"], ["84014.1", "0"], ["84006.4", "0.003"], ["83975.3", "0"]], "a": [["84078.3", "0"], ["84085.4", "0"], ["84125", "0.172333"], ["84127", "0.000204"], ["84127.2", "0.04"]], "u": 92361, "seq": 67563892376}, "cts": 1742569767117, "record_time": 1742569767.388615, "EXCHANGE": "BYBIT"}
{"topic": "orderbook.200.BTCUSDT", "ts": 1742569767320, "type": "delta", "data": {"s": "BTCUSDT", "b": [["84053", "0.847376"], ["84046.2", "0.0006"], ["84017.8", "0.013396"], ["84017.7", "0.01288"], ["84017.6", "0"], ["84017.2", "0.062844"], ["84014.6", "0"], ["84014.5", "0"], ["84014.2", "0.049545"], ["84014.1", "0.049545"], ["84013.6", "0.155465"], ["84010.3", "0"], ["83975.3", "0.044612"], ["83975.2", "3.446265"]], "a": [["84061.9", "0.001333"], ["84066.5", "0"], ["84067.5", "0"], ["84094.5", "0.003431"], ["84096.6", "0"], ["84127.8", "3.445452"], ["84128.6", "0.118852"]], "u": 92362, "seq": 67563892421}, "cts": 1742569767315, "record_time": 1742569767.588349, "EXCHANGE": "BYBIT"}
{"topic": "orderbook.200.BTCUSDT", "ts": 1742569767519, "type": "delta", "data": {"s": "BTCUSDT", "b": [["84053", "0.84916"], ["84051.7", "0.0008"], ["84044.9", "0"], ["84022.6", "0.0016"], ["84017.8", "0.000516"], ["84017.6", "0.01288"], ["84015.8", "0"], ["84014.4", "0.05"], ["84014.3", "0.050145"], ["84014.2", "0"], ["84014.1", "0"], ["83984.8", "0.056982"], ["83975.2", "0"]], "a": [["84053.1", "0.01319"], ["84054.6", "0.071416"], ["84065.2", "0.000153"], ["84066.9", "0.071406"], ["84075.9", "0.116702"], ["84094.5", "0"], ["84094.8", "0.003431"], ["84095", "1.427077"], ["84127", "0"], ["84127.2", "0"], ["84127.8", "0"], ["84128.6", "0"]], "u": 92363, "seq": 67563892493}, "cts": 1742569767513, "record_time": 1742569767.788884, "EXCHANGE": "BYBIT"}
{"topic": "orderbook.200.BTCUSDT", "ts": 1742569767720, "type": "delta", "data": {"s": "BTCUSDT", "b": [["84053", "0.67816"], ["84041.7", "0.149882"], ["84040.8", "0.223079"], ["84031.2", "0.178954"], ["84024.2", "0.304851"], ["84017.9", "0.01288"], ["84017.8", "0.013396"], ["84017.7", "0"], ["84017.6", "0"], ["84014.5", "0.05"], ["84014.4", "0.049545"], ["84014.3", "0.0006"], ["83976.2", "0"], ["83975.3", "0"]], "a": [["84053.1", "0.184428"], ["84053.7", "0.071417"], ["84054.6", "0"], ["84062", "0.07141"], ["84066.2", "0.116947"], ["84066.9", "0"], ["84067.7", "0.008286"], ["84076.7", "0.164238"], ["84083.7", "0.293153"], ["84092.7", "0.063522"], ["84094.5", "0.003431"], ["84094.8", "0"], ["84095.5", "0.001333"], ["84104.2", "0.0006"], ["84124.9", "0"], ["84125", "0"], ["84125.7", "0"], ["84126.1", "0"]], "u": 92364, "seq": 67563892561}, "cts": 1742569767716, "record_time": 1742569767.988337, "EXCHANGE": "BYBIT"}
{"topic": "orderbook.200.BTCUSDT", "ts": 1742569767920, "type": "delta", "data": {"s": "BTCUSDT", "b": [["84053", "0.676376"], ["84041.7", "0.031466"], ["84031.2", "0"], ["84024.3", "0.181336"], ["84024.2", "0"], ["84014.7", "0.049545"], ["84014.6", "0.049545"], ["84014.5", "0"], ["84014.4", "0"], ["83976.2", "0.00052"]], "a": [["84053.1", "0.01669"], ["84066.2", "0"], ["84076.7", "0"], ["84083.7", "0.02"], ["84094.9", "0.451894"], ["84095.1", "0"], ["84124.9", "0.001466"], ["84125", "0.001333"]], "u": 92365, "seq": 67563892646}, "cts": 1742569767916, "record_time": 1742569768.188552, "EXCHANGE": "BYBIT"}
{"topic": "orderbook.200.BTCUSDT", "ts": 1742569768120, "type": "delta", "data": {"s": "BTCUSDT", "b": [["84053", "0.67816"], ["84024.3", "0"], ["84014.9", "0.05"], ["84014.8", "0.049545"], ["84014.7", "0"], ["84014.6", "0"], ["84013.6", "0.155476"], ["83975.3", "0.044612"]], "a": [["84053.1", "0.01319"], ["84063.3", "0.000153"], ["84065.2", "0"], ["84125", "0.172333"]], "u": 92366, "seq": 67563892717}, "cts": 1742569768108, "record_time": 1742569768.388608, "EXCHANGE": "BYBIT"}
{"topic": "orderbook.200.BTCUSDT", "ts": 1742569768320, "type": "delta", "data": {"s": "BTCUSDT", "b": [["84053", "0.100023"], ["84051.7", "0"], ["84050", "0"], ["84049.9", "0"], ["84048.8", "0"], ["84047.7", "0"], ["84046.9", "0"], ["84044.7", "0.080841"], ["84044.2", "0"], ["84044", "0.04"], ["84043.7", "0"], ["84043.5", "0"], ["84042.7", "0.064848"], ["84041.8", "0"], ["84041.7", "0.001466"], ["84041.1", "0"], ["84040.8", "0.106417"], ["84040.7", "0"], ["84040.5", "0.174663"], ["84038.1", "0"], ["84037.2", "0.026844"], ["84037.1", "0.072897"], ["84036.4", "0"], ["84035.1", "0"], ["84033.5", "0"], ["84033.4", "0.0006"], ["84033.1", "0"], ["84033", "0"], ["84032", "0.019443"], ["84030.8", "0"], ["84029.7", "0"], ["84029.6", "0.034917"], ["84028", "0.187939"], ["84027.4", "0.035699"], ["84026.8", "0"], ["84025.5", "0"], ["84019.6", "0"], ["84019.5", "0.00364"], ["84019.4", "0"], ["84019.3", "0.04"], ["84019.2", "0.039631"], ["84017.9", "0"], ["84017.8", "0.000516"], ["84017.5", "0.013"], ["84017.4", "0.01288"], ["84017.2", "0.520423"], ["84015.7", "0.298937"], ["84014.9", "0"], ["84014.8", "0"], ["84013.9", "0.05"], ["84013.8", "0.049546"], ["84013.6", "0.059399"], ["84012.9", "0"], ["84011.2", "0.039623"], ["84008.8", "0.00107"], ["84008", "0.09641"], ["84007.4", "0.044"], ["84005.8", "0.04"], ["84002.4", "0.048"], ["84002", "0"], ["83996", "0"], ["83993.8", "0.313351"], ["83991.9", "0"], ["83975.2", "3.446265"], ["83974.8", "0.00009"], ["83974.7", "0.118852"], ["83974.6", "0.0025"], ["83974.4", "0.000333"], ["83974", "0.05"], ["83973.7", "0.001333"], ["83973.3", "0.003552"], ["83973.1", "0.05"], ["83972.7", "0.001774"], ["83972.4", "0.001466"], ["83971.6", "0.00052"], ["83970.9", "0.089229"], ["83970.2", "0.000333"], ["83970.1", "0.025333"], ["83970", "0.007148"], ["83969.5", "0.001333"]], "a": [["84053.1", "0.684289"], ["84053.5", "0.004782"], ["84053.6", "0.02372"], ["84060.1", "0.155283"], ["84060.2", "0.090565"], ["84060.4", "0"], ["84060.5", "0"], ["84061.7", "0.009337"], ["84062", "0"], ["84063.3", "0"], ["84064.4", "0.00009"], ["84066.8", "0.024669"], ["84073.6", "0.089099"], ["84074", "0.178414"], ["84075.5", "0"], ["84075.9", "0.295161"], ["84077.9", "0.178922"], ["84078.4", "0.00367"], ["84082.7", "0.549476"], ["84084.7", "0.517466"], ["84089.8", "0.118852"], ["84095.3", "0.024096"], ["84099.4", "0.003562"], ["84099.8", "0.005946"], ["84101.4", "0.04"], ["84123.5", "0"], ["84124.1", "0"], ["84124.6", "0"], ["84124.9", "0"], ["84125", "0"]], "u": 92367, "seq": 67563892934}, "cts": 1742569768316, "record_time": 1742569768.588985, "EXCHANGE": "BYBIT"}
