{"success": true, "ret_msg": "subscribe", "conn_id": "66eef079-b2bf-427b-aa45-7a2115dcff7c", "op": "subscribe", "record_time": 1742142203.185055}
{"topic": "orderbook.200.BTCUSDT", "ts": 1742142203210, "type": "snapshot", "data": {"s": "BTCUSDT", "b": [["84290.34", "0.400062"], ["84289.32", "0.035388"], ["84286.72", "0.071191"], ["84285.92", "0.0002"], ["84285.91", "0.045105"], ["84284.32", "0.001467"], ["84284.16", "0.000252"], ["84283.51", "0.001333"], ["84282.44", "0.000233"], ["84281.92", "0.023088"], ["84281.91", "0.006142"], ["84281.9", "0.0006"], ["84280.86", "0.0002"], ["84279.89", "0.059408"], ["84279.69", "0.001467"], ["84279.52", "0.000252"], ["84279.3", "0.001333"], ["84279.25", "0.000614"], ["84279.2", "0.0006"], ["84279.02", "0.015082"], ["84278.33", "0.0002"], ["84278.27", "0.114477"], ["84278.2", "0.000099"], ["84278.09", "0.003"], ["84277.8", "0.001476"], ["84277.31", "0.0005"], ["84277.3", "0.000089"], ["84277.28", "0.000233"], ["84276.92", "0.060332"], ["84275.8", "0.0002"], ["84275.08", "0.001333"], ["84275.05", "0.001467"], ["84275.04", "0.000614"], ["84274.89", "0.000252"], ["84273.7", "0.04"], ["84273.5", "0.04"], ["84273.49", "0.075776"], ["84273.48", "0.162"], ["84273.27", "0.0002"], ["84273.17", "0.000233"], ["84273.14", "0.089922"], ["84272.64", "0.000233"], ["84272.03", "0.164562"], ["84271.46", "0.02"], ["84271.08", "0.00783"], ["84271.06", "0.182233"], ["84270.88", "0.068395"], ["84270.87", "0.001333"], ["84270.83", "0.000614"], ["84270.75", "0.0002"], ["84270.7", "0.02"], ["84270.53", "0.172288"], ["84270.42", "0.001467"], ["84270.25", "0.000252"], ["84270.1", "0.04"], ["84269.9", "0.02"], ["84268.96", "0.059948"], ["84268.85", "0.172377"], ["84268.53", "0.020233"], ["84268.22", "0.0002"], ["84268.01", "0.000233"], ["84267.69", "0.000297"], ["84267.23", "0.02"], ["84267.17", "0.208232"], ["84267.16", "0.23734"], ["84266.9", "0.001243"], ["84266.66", "0.001333"], ["84266.61", "0.000614"], ["84266.3", "0.04"], ["84266.13", "0.157678"], ["84265.9", "0.04"], ["84265.78", "0.001467"], ["84265.69", "0.0002"], ["84265.61", "0.000252"], ["84265.05", "0.162"], ["84264.5", "0.04"], ["84264.4", "0.04"], ["84264.3", "0.005932"], ["84264.1", "0.048"], ["84263.9", "0.000233"], ["84263.37", "0.000233"], ["84263.31", "0.237299"], ["84263.16", "0.0002"], ["84263.1", "0.321768"], ["84262.6", "0.04"], ["84262.44", "0.001333"], ["84262.4", "0.040614"], ["84261.92", "0.127301"], ["84261.15", "0.001467"], ["84260.98", "0.000252"], ["84260.63", "0.0002"], ["84260.52", "0.237299"], ["84260.4", "0.000089"], ["84260.02", "0.059948"], ["84259.7", "0.04"], ["84259.26", "0.000233"], ["84259.2", "0.04"], ["84258.74", "0.000233"], ["84258.44", "0.011746"], ["84258.23", "0.001333"], ["84258.18", "0.000614"], ["84258.11", "0.0002"], ["84257.91", "0.000335"], ["84257.57", "0.001343"], ["84257.28", "0.9"], ["84256.62", "0.162"], ["84256.51", "0.001467"], ["84256.39", "0.023729"], ["84256.35", "0.000252"], ["84256", "0.001243"], ["84255.58", "0.0002"], ["84255.21", "0.009039"], ["84255.01", "0.14017"], ["84254.92", "0.089922"], ["84254.63", "0.000233"], ["84254.1", "0.000233"], ["84254.09", "0.008453"], ["84254.02", "0.001333"], ["84253.97", "0.000614"], ["84253.47", "1.414353"], ["84253.37", "0.00893"], ["84253.05", "0.0002"], ["84252.95", "0.019876"], ["84252.49", "0.017796"], ["84252.4", "0.07122"], ["84251.95", "0.00009"], ["84251.88", "0.001467"], ["84251.71", "0.000252"], ["84251.45", "0.003"], ["84250.52", "0.0002"], ["84250", "0.000233"], ["84249.8", "0.001333"], ["84249.76", "0.000614"], ["84249.5", "0.001"], ["84249.47", "0.000233"], ["84249.31", "0.059948"], ["84249.05", "0.00338"], ["84249.03", "0.018313"], ["84249.01", "0.071223"], ["84248.07", "0.162"], ["84248", "0.0002"], ["84247.88", "0.177974"], ["84247.24", "0.001467"], ["84247.08", "0.000252"], ["84245.86", "0.000089"], ["84245.7", "0.005931"], ["84245.59", "0.001333"], ["84245.55", "0.000614"], ["84245.47", "0.0002"], ["84245.36", "0.000233"], ["84245.1", "0.001243"], ["84245", "0.000119"], ["84244.94", "0.023878"], ["84244.84", "0.000233"], ["84244.25", "0.005956"], ["84243.85", "0.32362"], ["84243.5", "0.00009"], ["84242.94", "0.0002"], ["84242.79", "0.059365"], ["84242.61", "0.001467"], ["84242.44", "0.000252"], ["84241.98", "0.017765"], ["84241.38", "0.001333"], ["84241.34", "0.000614"], ["84240.88", "0.35594"], ["84240.87", "0.059948"], ["84240.77", "0.023729"], ["84240.73", "0.000233"], ["84240.68", "0.2"], ["84240.41", "0.0002"], ["84240.21", "0.000989"], ["84240.2", "0.000233"], ["84239.64", "0.162"], ["84239.31", "0.0013"], ["84238.29", "0.004747"], ["84238.07", "0.118629"], ["84238.06", "0.11"], ["84238.04", "0.177974"], ["84237.98", "0.001467"], ["84237.89", "0.0002"], ["84237.81", "0.023981"], ["84237.69", "0.039641"], ["84237.68", "0.039641"], ["84237.49", "0.000357"], ["84237.17", "0.001333"], ["84237.12", "0.000613"], ["84236.1", "0.000233"], ["84235.8", "0.000335"], ["84235.57", "0.000233"], ["84235.36", "0.0002"], ["84235.05", "0.00009"], ["84234.81", "0.023729"], ["84234.2", "0.002401"], ["84234.01", "0.023729"], ["84233.35", "0.001467"], ["84233.18", "0.000252"], ["84233.14", "0.0025"], ["84232.95", "0.001333"], ["84232.91", "0.000613"], ["84232.83", "0.0002"]], "a": [["84290.35", "0.01266"], ["84290.97", "0.0002"], ["84291.19", "0.000233"], ["84291.71", "0.000233"], ["84291.9", "0.000614"], ["84291.94", "0.001333"], ["84292.46", "0.071186"], ["84293.43", "0.000252"], ["84293.5", "0.0002"], ["84293.59", "0.001467"], ["84295.5", "0.0005"], ["84295.82", "0.000233"], ["84296.03", "0.029799"], ["84296.11", "0.000614"], ["84296.12", "0.0001"], ["84296.15", "0.001333"], ["84296.35", "0.000233"], ["84296.44", "0.030678"], ["84297.08", "0.011862"], ["84297.15", "0.237234"], ["84298.06", "0.000252"], ["84298.23", "0.001467"], ["84298.56", "0.0002"], ["84298.6", "0.002483"], ["84300.33", "0.000614"], ["84300.37", "0.001333"], ["84300.46", "0.000233"], ["84300.87", "0.004656"], ["84300.98", "0.000233"], ["84301.09", "0.0002"], ["84301.25", "0.00783"], ["84301.35", "0.008453"], ["84301.9", "0.106697"], ["84302.62", "0.020996"], ["84302.7", "0.000252"], ["84302.87", "0.001467"], ["84303.62", "0.0002"], ["84303.78", "0.011862"], ["84303.79", "0.023724"], ["84303.85", "0.011858"], ["84304.2", "0.044"], ["84304.26", "0.237234"], ["84304.54", "0.000614"], ["84304.58", "0.001333"], ["84304.95", "0.000089"], ["84305.05", "0.001243"], ["84305.1", "0.000786"], ["84305.62", "0.000235"], ["84305.67", "0.083984"], ["84305.9", "0.044249"], ["84306.15", "0.0002"], ["84306.89", "0.115481"], ["84307.34", "0.000253"], ["84307.51", "0.001467"], ["84308.19", "0.059948"], ["84308.5", "0.009328"], ["84308.68", "0.0002"], ["84308.76", "0.000612"], ["84308.8", "0.001333"], ["84308.9", "0.068"], ["84309.1", "0.068"], ["84309.73", "0.000235"], ["84309.95", "0.189284"], ["84310.26", "0.000235"], ["84310.41", "0.015105"], ["84311.08", "0.018917"], ["84311.2", "0.0002"], ["84311.78", "0.017796"], ["84311.98", "0.000253"], ["84312.14", "0.001467"], ["84312.42", "0.023727"], ["84312.97", "0.000612"], ["84312.99", "0.140164"], ["84313.02", "0.001333"], ["84313.27", "0.000199"], ["84313.3", "0.056"], ["84313.34", "0.118617"], ["84313.46", "0.000089"], ["84313.73", "0.591478"], ["84313.74", "0.361876"], ["84313.85", "0.000335"], ["84313.9", "0.011746"], ["84313.91", "0.000989"], ["84314.16", "0.068395"], ["84314.28", "0.000759"], ["84314.37", "0.000235"], ["84314.9", "0.000235"], ["84315.32", "0.013764"], ["84315.95", "0.001243"], ["84316.26", "0.0002"], ["84316.61", "0.000253"], ["84316.78", "0.001467"], ["84316.94", "1.460986"], ["84316.97", "0.005"], ["84317.19", "0.000612"], ["84317.23", "0.001333"], ["84317.25", "0.000111"], ["84318.56", "0.024132"], ["84318.74", "0.137301"], ["84318.75", "0.237306"], ["84318.79", "0.0002"], ["84319", "0.066646"], ["84319.01", "0.000235"], ["84319.51", "0.237299"], ["84319.52", "0.059948"], ["84319.53", "0.000235"], ["84319.54", "0.00315"], ["84319.75", "0.005931"], ["84320", "0.000113"], ["84320.15", "0.005931"], ["84320.89", "0.237275"], ["84321.25", "0.000253"], ["84321.32", "0.0002"], ["84321.4", "0.000612"], ["84321.42", "0.001467"], ["84321.45", "0.001333"], ["84321.97", "0.000089"], ["84321.98", "0.162"], ["84322", "0.0006"], ["84322.11", "0.071161"], ["84322.26", "0.089922"], ["84322.29", "0.237275"], ["84322.36", "0.323318"], ["84322.7", "0.295282"], ["84322.82", "0.02465"], ["84322.94", "0.43153"], ["84323.31", "0.023728"], ["84323.65", "0.000235"], ["84323.71", "0.023728"], ["84323.85", "0.0002"], ["84324.17", "0.000235"], ["84324.62", "0.023727"], ["84325.1", "0.237275"], ["84325.62", "0.000612"], ["84325.66", "0.001333"], ["84325.89", "0.000253"], ["84325.92", "0.023729"], ["84326", "0.000119"], ["84326.06", "0.001467"], ["84326.38", "0.0002"], ["84326.41", "0.001347"], ["84326.51", "0.237275"], ["84328.04", "0.237306"], ["84328.06", "0.144041"], ["84328.28", "0.000235"], ["84328.81", "0.07139"], ["84328.91", "0.0002"], ["84329.28", "0.023729"], ["84329.5", "0.0006"], ["84329.74", "0.005972"], ["84329.84", "0.000612"], ["84329.88", "0.001333"], ["84329.99", "0.059948"], ["84330", "0.19987"], ["84330.41", "0.162"], ["84330.48", "0.000089"], ["84330.53", "0.000253"], ["84330.69", "0.001467"], ["84331.1", "0.246059"], ["84331.43", "0.001614"], ["84331.44", "0.0002"], ["84331.77", "0.026414"], ["84332.1", "0.0045"], ["84332.15", "0.177974"], ["84332.33", "0.0045"], ["84332.36", "0.0045"], ["84332.38", "0.015"], ["84332.5", "0.017796"], ["84332.56", "0.0045"], ["84332.92", "0.000235"], ["84333.12", "0.003"], ["84333.14", "0.0025"], ["84333.45", "0.000235"], ["84333.97", "0.0002"], ["84334.02", "0.000089"], ["84334.05", "0.000612"], ["84334.06", "0.237306"], ["84334.07", "1.780064"], ["84334.1", "0.001333"], ["84334.12", "0.0013"], ["84334.38", "0.022"], ["84334.93", "0.04"], ["84334.94", "0.04"], ["84335.16", "0.000253"], ["84335.3", "0.005931"], ["84335.33", "0.001467"], ["84335.96", "0.000335"], ["84336.5", "0.0002"], ["84336.55", "0.015"], ["84337.56", "0.000235"], ["84338.08", "0.000235"], ["84338.27", "0.000612"], ["84338.31", "0.001333"], ["84338.79", "0.000357"], ["84338.99", "0.000089"], ["84339.03", "0.0002"], ["84339.05", "0.0045"], ["84339.07", "0.0045"], ["84339.25", "0.0045"], ["84339.27", "0.0045"]], "u": 7510536, "seq": 66889259205}, "cts": 1742142203208, "record_time": 1742142203.18761}
{"topic": "orderbook.200.BTCUSDT", "ts": 1742142203410, "type": "delta", "data": {"s": "BTCUSDT", "b": [["84290.34", "0.400133"], ["84289.33", "0.0172"], ["84289.32", "0.021857"], ["84286.72", "0"], ["84285.91", "0"], ["84284.32", "0.07266"], ["84283.39", "0.0002"], ["84281.93", "0.01731"], ["84281.92", "0.051028"], ["84281.91", "0.005873"], ["84279.89", "0"], ["84278.76", "0.153941"], ["84278.75", "0.109447"], ["84278.47", "0.106524"], ["84278.27", "0"], ["84278.2", "0"], ["84277.11", "0.112879"], ["84276.29", "0.112736"], ["84275.5", "0.04"], ["84275", "0.04"], ["84273.49", "0.115673"], ["84273.31", "0.010973"], ["84273.14", "0"], ["84272.42", "0.237326"], ["84272.03", "0"], ["84271.7", "0.04"], ["84271.5", "0.048"], ["84270.87", "0.180382"], ["84270.67", "0.161203"], ["84270.53", "0"], ["84268.85", "0.000089"], ["84268.7", "0.04"], ["84268.5", "0.176714"], ["84268.3", "0.04"], ["84267.83", "0.160648"], ["84267.53", "0.237275"], ["84265.9", "0"], ["84264.74", "0.237275"], ["84264.5", "0"], ["84264.4", "0"], ["84264.1", "0"], ["84263.1", "0"], ["84263.08", "0.288687"], ["84262.88", "0.285993"], ["84262.6", "0"], ["84257.7", "0.265682"], ["84244.94", "0"], ["84240.88", "0"], ["84240.68", "0"], ["84234.01", "0"], ["84233.35", "0"], ["84233.18", "0"], ["84233.14", "0"], ["84232.95", "0"], ["84232.91", "0"], ["84232.83", "0"]], "a": [["84290.35", "0.0514"], ["84294.55", "0.000967"], ["84296.44", "0.000089"], ["84305.62", "0.000484"], ["84305.66", "0.101272"], ["84305.9", "0.044"], ["84306.81", "0.117977"], ["84306.89", "0"], ["84307.31", "0.106686"], ["84307.51", "0.117007"], ["84308.01", "0.024047"], ["84308.3", "0.06"], ["84309.81", "0.120206"], ["84309.95", "0"], ["84310.41", "0"], ["84311.7", "0.06"], ["84313.75", "0.169228"], ["84314.7", "0.048"], ["84315", "0.048"], ["84315.11", "0.158667"], ["84317.61", "0.175586"], ["84317.73", "0.16237"], ["84321.54", "0.290558"], ["84322.7", "0"], ["84322.9", "0.28734"], ["84323.72", "0.237275"], ["84325.41", "0.28302"], ["84327.86", "0.284682"], ["84334.93", "0"], ["84334.94", "0"], ["84335.73", "0.04"], ["84335.96", "0"], ["84336.5", "0"], ["84336.55", "0"], ["84337.56", "0"], ["84338.08", "0"], ["84338.27", "0"], ["84338.31", "0"], ["84338.79", "0"], ["84338.99", "0"], ["84339.03", "0"], ["84339.05", "0"], ["84339.07", "0"], ["84339.25", "0"], ["84339.27", "0"]], "u": 7510537, "seq": 66889259537}, "cts": 1742142203407, "record_time": 1742142203.189682}
{"topic": "orderbook.200.BTCUSDT", "ts": 1742142203610, "type": "delta", "data": {"s": "BTCUSDT", "b": [["84289.33", "0"], ["84289.32", "0"], ["84286.89", "0.033643"], ["84286.88", "0.0173"], ["84286.87", "0.071191"], ["84286.53", "0.000099"], ["84284.32", "0.001467"], ["84278.76", "0.193915"], ["84278.75", "0"], ["84278.47", "0.111161"], ["84277.12", "0.116225"], ["84277.11", "0"], ["84276.32", "0.112788"], ["84276.29", "0"], ["84271.99", "0.02"], ["84271.32", "0.02"], ["84271.2", "0.02"], ["84271.06", "0.345666"], ["84270.88", "0.249208"], ["84270.87", "0.001333"], ["84270.7", "0"], ["84270.68", "0.164261"], ["84270.67", "0"], ["84269.9", "0"], ["84269.7", "0.04"], ["84268.53", "0.190768"], ["84268.5", "0"], ["84267.84", "0.163514"], ["84267.83", "0"], ["84267.23", "0"], ["84266.3", "0"], ["84263.09", "0.27122"], ["84263.08", "0"], ["84262.88", "0.267191"], ["84262.4", "0.000614"], ["84260.73", "0.284829"], ["84259.7", "0"], ["84259.2", "0"], ["84257.71", "0.281081"], ["84257.7", "0"], ["84255.78", "0.023829"]], "a": [["84294.55", "0.011863"], ["84296.03", "0.0002"], ["84305.62", "0.000235"], ["84305.66", "0.216063"], ["84306.81", "0"], ["84306.82", "0.109592"], ["84307.31", "0"], ["84307.32", "0.111366"], ["84307.51", "0.001467"], ["84307.52", "0.117957"], ["84309.81", "0"], ["84309.84", "0.109976"], ["84313.75", "0"], ["84313.76", "0.167393"], ["84315.11", "0.164431"], ["84317.61", "0"], ["84317.64", "0.176343"], ["84317.73", "0.180054"], ["84320.89", "0"], ["84321.54", "0"], ["84321.55", "0.272227"], ["84322.9", "0"], ["84322.91", "0.282599"], ["84325.41", "0"], ["84325.44", "0.288466"], ["84327.86", "0"], ["84327.87", "0.272101"]], "u": 7510538, "seq": 66889259828}, "cts": 1742142203604, "record_time": 1742142203.190199}
{"topic": "orderbook.200.BTCUSDT", "ts": 1742142203809, "type": "delta", "data": {"s": "BTCUSDT", "b": [["84278.76", "0.257653"], ["84272.46", "0.02"], ["84271.46", "0"], ["84269.83", "0.02"], ["84268.53", "0.170768"], ["84257.29", "0.405555"], ["84240.88", "0.355937"], ["84235.05", "0"], ["84234.81", "0"], ["84234.2", "0"]], "a": [["84309.83", "0.164876"], ["84318.74", "0.29957"], ["84325.44", "0.295102"], ["84335.73", "0"]], "u": 7510539, "seq": 66889259976}, "cts": 1742142203803, "record_time": 1742142203.191229}
{"topic": "orderbook.200.BTCUSDT", "ts": 1742142204010, "type": "delta", "data": {"s": "BTCUSDT", "b": [["84295.49", "0.250295"], ["84291.72", "0.043052"], ["84291.7", "0.043093"], ["84290.97", "0.0002"], ["84290.79", "0.000071"], ["84290.35", "0.0004"], ["84290.34", "0.116846"], ["84288.99", "0.0001"], ["84288.96", "0.001467"], ["84288.79", "0.000252"], ["84288.44", "0.0002"], ["84287.72", "0.001333"], ["84287.68", "0.000616"], ["84287.07", "0.000233"], ["84287.06", "0.0005"], ["84286.89", "0"], ["84286.88", "0"], ["84286.87", "0"], ["84286.55", "0.000233"], ["84285.75", "0.000089"], ["84284.89", "0.069164"], ["84284.88", "0.11556"], ["84284.6", "0.113519"], ["84284.03", "0.107797"], ["84283.47", "0.000616"], ["84281.93", "0"], ["84281.92", "0.059986"], ["84281.91", "0.166757"], ["84281.89", "0.106917"], ["84281.04", "0.008052"], ["84279.69", "0.089231"], ["84279.68", "0.068395"], ["84279.03", "0.059948"], ["84278.76", "0"], ["84278.47", "0"], ["84277.79", "0.167396"], ["84277.34", "0.000793"], ["84277.31", "0"], ["84277.15", "0.02"], ["84277.12", "0"], ["84276.8", "0.167043"], ["84276.69", "0.02"], ["84276.32", "0"], ["84276.02", "0.02"], ["84275.89", "0.02"], ["84275.13", "0.009039"], ["84274.77", "0.089922"], ["84274.56", "0.237261"], ["84274.52", "0.02"], ["84274.09", "0.176985"], ["84273.96", "0.167509"], ["84273.31", "0"], ["84272.46", "0"], ["84272.42", "0"], ["84272.11", "0.019876"], ["84271.99", "0"], ["84271.74", "0.237261"], ["84271.32", "0"], ["84271.2", "0"], ["84271.08", "0"], ["84270.88", "0"], ["84270.68", "0"], ["84270.34", "0.237261"], ["84270", "0.295085"], ["84269.83", "0"], ["84269", "0.263339"], ["84268.53", "0.000233"], ["84268.39", "0.012078"], ["84267.84", "0"], ["84267.53", "0.237261"], ["84267.16", "0"], ["84266.3", "0.28632"], ["84266.13", "0"], ["84264.74", "0"], ["84263.83", "0.295142"], ["84263.31", "0"], ["84263.09", "0"], ["84262.88", "0"], ["84262.33", "0.016081"], ["84261.92", "0"], ["84260.82", "0.1402"], ["84260.73", "0"], ["84260.52", "0"], ["84259.06", "0.071214"], ["84258.69", "0.068395"], ["84258.44", "0"], ["84257.71", "0"], ["84257.28", "0"], ["84256.39", "0"], ["84255.21", "0"], ["84254.51", "0.323579"], ["84253.48", "0.11863"], ["84252.95", "0"], ["84250.99", "0.0013"], ["84249.03", "0"], ["84249.01", "0"], ["84248.08", "0.355911"], ["84247.88", "0"], ["84243.86", "0.118629"], ["84243.85", "0"], ["84243.23", "0.004651"], ["84240.88", "0"], ["84239.31", "0"], ["84238.07", "0"], ["84238.06", "0"], ["84238.04", "0"], ["84237.98", "0"], ["84237.89", "0"], ["84237.81", "0"], ["84237.69", "0"], ["84237.68", "0"], ["84237.49", "0"], ["84237.17", "0"], ["84237.12", "0"], ["84236.1", "0"], ["84235.8", "0"], ["84235.57", "0"], ["84235.36", "0"]], "a": [["84290.35", "0"], ["84290.97", "0"], ["84291.19", "0"], ["84291.71", "0"], ["84291.9", "0"], ["84291.94", "0"], ["84292.46", "0"], ["84293.43", "0"], ["84293.5", "0"], ["84293.59", "0"], ["84294.55", "0"], ["84295.5", "0.012909"], ["84296.12", "0"], ["84296.44", "0"], ["84297.08", "0"], ["84297.15", "0"], ["84298", "0.0002"], ["84300.87", "0"], ["84301.09", "0.02936"], ["84301.25", "0"], ["84301.35", "0"], ["84301.9", "0"], ["84302.62", "0"], ["84303.62", "0.030562"], ["84303.93", "0.0005"], ["84304.2", "0"], ["84305.23", "0.020996"], ["84305.66", "0"], ["84305.9", "0"], ["84306.82", "0"], ["84307.32", "0"], ["84307.52", "0"], ["84308.01", "0"], ["84308.19", "0"], ["84308.3", "0"], ["84308.5", "0"], ["84308.9", "0"], ["84309.1", "0"], ["84309.83", "0.137657"], ["84309.84", "0"], ["84310.99", "0.008052"], ["84311.08", "0"], ["84311.7", "0"], ["84312.94", "0.111686"], ["84312.99", "0"], ["84313.3", "0"], ["84313.44", "0.118955"], ["84313.76", "0"], ["84313.9", "0"], ["84314.16", "0"], ["84314.43", "0.116425"], ["84314.7", "0"], ["84314.92", "0.008453"], ["84315", "0"], ["84315.1", "0.044"], ["84315.11", "0"], ["84315.32", "0"], ["84315.4", "0.06"], ["84315.41", "0.113191"], ["84315.48", "0.140161"], ["84316.94", "0"], ["84317.64", "0.023796"], ["84317.73", "0"], ["84318.34", "0.00462"], ["84318.56", "0"], ["84319.51", "0"], ["84319.75", "0"], ["84320.67", "0.168851"], ["84320.79", "0.162"], ["84321.24", "0.172251"], ["84321.55", "0"], ["84321.7", "0.048"], ["84321.98", "0"], ["84322", "0.0486"], ["84322.11", "0"], ["84322.18", "0.023727"], ["84322.26", "0"], ["84322.29", "0"], ["84322.36", "0"], ["84322.91", "0"], ["84323.21", "0.172696"], ["84323.63", "0.012078"], ["84323.72", "0"], ["84323.86", "0.165235"], ["84324.04", "0.009328"], ["84325.1", "0"], ["84325.44", "0"], ["84325.75", "1.444894"], ["84326.07", "0.068395"], ["84326.51", "0"], ["84327.87", "0"], ["84328.14", "0.018917"], ["84328.46", "0.285078"], ["84328.81", "0.000235"], ["84329.03", "0.300026"], ["84329.39", "0.02374"], ["84331", "0.274256"], ["84332.15", "0"], ["84332.76", "0.013881"], ["84333.57", "0.071151"], ["84333.99", "0.264618"], ["84334.12", "0"], ["84335.96", "0.000335"], ["84336", "0.0012"], ["84336.5", "0.0002"], ["84336.55", "0.015"], ["84337.56", "0.000235"], ["84338.08", "0.000235"], ["84338.27", "0.000612"], ["84338.31", "0.001333"], ["84338.79", "0.000357"], ["84338.89", "0.071147"], ["84338.99", "0.000089"], ["84339.03", "0.0002"], ["84339.05", "0.0045"], ["84339.07", "0.0045"], ["84339.25", "0.0045"], ["84339.27", "0.0045"], ["84339.8", "0.000253"], ["84339.97", "0.001467"], ["84340.18", "0.023724"], ["84340.22", "0.003465"], ["84340.58", "0.023724"], ["84340.62", "0.059948"], ["84340.8", "0.023729"], ["84340.88", "0.000158"], ["84340.97", "0.037937"], ["84341.49", "0.023723"], ["84341.56", "0.0002"], ["84342.2", "0.000235"], ["84342.46", "0.237306"], ["84342.49", "0.000612"], ["84342.53", "0.001333"]], "u": 7510540, "seq": 66889261459}, "cts": 1742142204007, "record_time": 1742142203.192264}
{"topic": "orderbook.200.BTCUSDT", "ts": 1742142204210, "type": "delta", "data": {"s": "BTCUSDT", "b": [["84295.49", "0.253295"], ["84295.08", "0.026485"], ["84295.07", "0.071184"], ["84294.65", "0.0171"], ["84290.79", "0"], ["84287.68", "0.084252"], ["84287.57", "0.110825"], ["84287.29", "0.106403"], ["84287.07", "0.043958"], ["84286.53", "0"], ["84285.48", "0.120524"], ["84284.89", "0"], ["84284.88", "0"], ["84284.6", "0"], ["84284.04", "0.055588"], ["84284.03", "0"], ["84283.27", "0.01508"], ["84281.92", "0.007303"], ["84281.89", "0"], ["84281.17", "0.060324"], ["84279.69", "0.265106"], ["84279.55", "0.02"], ["84279.49", "0.158144"], ["84279.24", "0.160751"], ["84279.09", "0.02"], ["84279.02", "0"], ["84278.77", "0.237261"], ["84278.42", "0.02"], ["84278.29", "0.02"], ["84278.2", "0.048"], ["84278.1", "0.04"], ["84277.79", "0"], ["84277.15", "0"], ["84276.92", "0.02"], ["84276.8", "0"], ["84276.69", "0"], ["84276.66", "0.173"], ["84276.02", "0"], ["84275.95", "0.237261"], ["84275.89", "0"], ["84274.56", "0.226444"], ["84274.52", "0"], ["84274.09", "0"], ["84273.96", "0"], ["84271.7", "0.274312"], ["84271.5", "0"], ["84271.45", "0.264889"], ["84270.34", "0"], ["84270", "0"], ["84269.85", "0.276848"], ["84269", "0"], ["84267.53", "0"], ["84266.52", "0.295274"], ["84266.3", "0"], ["84265.53", "0.071209"], ["84263.83", "0"], ["84259.1", "0.177945"], ["84259.07", "0.237261"], ["84257.63", "0.023726"], ["84257.3", "0.355883"], ["84257.29", "0"], ["84254.67", "0.023726"], ["84252.4", "0"], ["84251.67", "0.023726"], ["84248.08", "0"], ["84245.33", "0.000989"], ["84243.67", "0.237261"], ["84240.41", "0"], ["84240.21", "0"], ["84240.2", "0"], ["84239.64", "0"], ["84238.29", "0"]], "a": [["84295.5", "0.011474"], ["84301.09", "0.0002"], ["84304.26", "0"], ["84304.95", "0"], ["84305.23", "0"], ["84305.67", "0"], ["84306.59", "0.071174"], ["84309.83", "0"], ["84312.42", "0"], ["84312.94", "0"], ["84313.44", "0"], ["84313.73", "0.266174"], ["84313.74", "0"], ["84313.91", "0"], ["84314.28", "0"], ["84314.43", "0"], ["84315.1", "0"], ["84315.4", "0"], ["84315.41", "0"], ["84315.64", "0.110921"], ["84315.88", "0.116215"], ["84316.13", "0.11518"], ["84317.64", "0"], ["84319.07", "0.000989"], ["84320.15", "0"], ["84320.4", "0.044"], ["84320.67", "0"], ["84320.79", "0"], ["84321.24", "0"], ["84321.7", "0"], ["84322", "0.0006"], ["84322.12", "0.169411"], ["84322.18", "0"], ["84322.4", "0.06"], ["84322.94", "0"], ["84323.21", "0"], ["84323.31", "0"], ["84323.5", "0.068"], ["84323.71", "0"], ["84323.86", "0"], ["84323.93", "0.169167"], ["84325.57", "0.016253"], ["84325.92", "0"], ["84326.55", "0.163046"], ["84328.46", "0"], ["84329.03", "0"], ["84329.28", "0"], ["84329.74", "0"], ["84329.92", "0.264125"], ["84330.59", "0.005931"], ["84331", "0"], ["84331.66", "0.023726"], ["84331.73", "0.290801"], ["84333.57", "0"], ["84333.99", "0"], ["84334.56", "0.29514"], ["84336.68", "0.292791"], ["84338.27", "0.362488"], ["84338.84", "0.162"], ["84342.72", "0.000235"], ["84342.79", "0.023724"], ["84343.72", "0.089922"], ["84343.94", "0.071142"], ["84344.09", "0.0002"], ["84344.44", "0.000253"], ["84344.61", "0.001467"], ["84345.02", "0.04"], ["84345.03", "0.04"], ["84346.06", "0.0045"], ["84346.09", "0.0045"], ["84346.15", "0.023724"], ["84346.23", "0.06093"], ["84346.26", "0.0045"], ["84346.29", "0.0045"], ["84346.62", "0.0002"]], "u": 7510541, "seq": 66889262859}, "cts": 1742142204207, "record_time": 1742142203.309692}
{"topic": "orderbook.200.BTCUSDT", "ts": 1742142204410, "type": "delta", "data": {"s": "BTCUSDT", "b": [["84295.49", "0.035533"], ["84295.08", "0"], ["84295.07", "0"], ["84294.65", "0"], ["84291.72", "0"], ["84291.7", "0"], ["84291.68", "0.000099"], ["84290.35", "0"], ["84290.34", "0.116917"], ["84288.99", "0"], ["84288.45", "0.0173"], ["84287.68", "0.000616"], ["84287.57", "0"], ["84287.29", "0"], ["84287.08", "0.013907"], ["84285.75", "0"], ["84285.48", "0"], ["84285.01", "0.071192"], ["84284.04", "0"], ["84283.27", "0"], ["84281.94", "0.000297"], ["84281.92", "0.006903"], ["84281.91", "0.001194"], ["84281.17", "0"], ["84281.04", "0"], ["84279.97", "0.000297"], ["84279.69", "0.001467"], ["84279.68", "0"], ["84279.55", "0"], ["84279.49", "0"], ["84279.24", "0"], ["84279.1", "0.04"], ["84279.09", "0"], ["84279.03", "0"], ["84278.77", "0"], ["84278.55", "0.02"], ["84278.45", "0.029006"], ["84278.42", "0"], ["84278.29", "0"], ["84278.1", "0"], ["84278.09", "0"], ["84277.46", "0.02"], ["84277.28", "0.112026"], ["84277.02", "0.02"], ["84276.92", "0"], ["84276.66", "0"], ["84276.12", "0.02"], ["84275.99", "0.02"], ["84275.95", "0"], ["84274.77", "0"], ["84274.56", "0"], ["84273.48", "0"], ["84271.74", "0"], ["84271.7", "0"], ["84271.45", "0"], ["84271.06", "0"], ["84271.02", "0.175287"], ["84270.58", "0.00818"], ["84270.11", "0.059948"], ["84269.85", "0"], ["84269.45", "0.023726"], ["84268.96", "0"], ["84268.39", "0"], ["84268.3", "0"], ["84267.69", "0"], ["84267.53", "0.237261"], ["84267.17", "0.207935"], ["84266.52", "0"], ["84265.53", "0"], ["84264.46", "0.140144"], ["84263.19", "0.263195"], ["84260.82", "0"], ["84259.1", "0"], ["84259.07", "0"], ["84259.06", "0"], ["84258.69", "0"], ["84257.94", "0.01227"], ["84257.3", "0"], ["84255.78", "0"], ["84255.01", "0"], ["84254.92", "0"], ["84253.48", "0"], ["84253.47", "0"], ["84250.87", "0.023726"], ["84250.23", "0.071222"], ["84245.87", "0.023726"], ["84243.87", "0.11863"], ["84243.86", "0"], ["84243.68", "0.071227"], ["84243.67", "0"], ["84240.41", "0.0002"], ["84240.2", "0.000233"], ["84238.29", "0.004747"], ["84238.07", "0.118629"], ["84237.98", "0.001467"], ["84237.89", "0.0002"], ["84237.81", "0.023981"], ["84237.69", "0.039641"], ["84237.68", "0.039641"], ["84237.49", "0.000357"], ["84237.17", "0.001333"], ["84237.12", "0.000613"], ["84236.65", "0.177945"], ["84236.1", "0.000233"], ["84235.8", "0.000335"], ["84235.57", "0.000233"], ["84235.36", "0.0002"], ["84235.05", "0.00009"], ["84234.81", "0.023729"], ["84234.2", "0.249421"], ["84234.01", "0.023729"], ["84233.35", "0.001467"], ["84233.18", "0.000252"], ["84233.14", "0.0025"], ["84232.95", "0.001333"], ["84232.91", "0.000613"], ["84232.83", "0.0002"], ["84232.38", "0.015"], ["84231.7", "0.118629"], ["84231.69", "0.059948"]], "a": [["84295.5", "0.150172"], ["84295.7", "0.069404"], ["84295.71", "0.071183"], ["84296.33", "0.011862"], ["84299.7", "0.011862"], ["84300.41", "0.00818"], ["84300.56", "0.11863"], ["84301.08", "0.019797"], ["84302.23", "0.011862"], ["84303.62", "0.0002"], ["84304.95", "0.000089"], ["84305.3", "0.126972"], ["84305.31", "0.089922"], ["84305.78", "0.03181"], ["84306.58", "0.297209"], ["84306.59", "0"], ["84307.81", "0.108381"], ["84310.99", "0"], ["84311.39", "0.068395"], ["84311.78", "0.018045"], ["84312.08", "0.016384"], ["84312.36", "0.162"], ["84313.01", "0.036071"], ["84313.06", "0.01227"], ["84313.73", "0.0002"], ["84314.07", "0.17784"], ["84314.1", "0.029801"], ["84314.7", "0.044"], ["84314.92", "0"], ["84315.47", "0.147809"], ["84315.48", "0"], ["84315.64", "0"], ["84315.79", "0.011474"], ["84315.88", "0"], ["84315.93", "0.020994"], ["84316.13", "0"], ["84316.58", "0.000759"], ["84317.5", "0.140144"], ["84318.04", "0.083976"], ["84318.74", "0.137301"], ["84318.8", "0.068"], ["84320.03", "0.023045"], ["84320.1", "0.044"], ["84320.2", "0.056"], ["84320.5", "0.06"], ["84320.79", "0.162"], ["84321.87", "0.089922"], ["84321.9", "0.264305"], ["84322.12", "0"], ["84322.67", "0.023572"], ["84323.63", "0"], ["84323.93", "0"], ["84324.35", "0.071159"], ["84324.62", "0"], ["84325.57", "0"], ["84326.07", "0"], ["84326.51", "0.237261"], ["84326.55", "0"], ["84326.8", "0.048"], ["84327.2", "0.048"], ["84328.5", "0.071156"], ["84329.39", "0"], ["84329.92", "0"], ["84330.72", "0.237261"], ["84331.66", "0"], ["84331.69", "0.006041"], ["84331.72", "0.355972"], ["84331.73", "0"], ["84331.77", "0"], ["84334.56", "0"], ["84335.3", "0"], ["84336.68", "0"], ["84338.89", "0"], ["84341.49", "0"], ["84341.56", "0"], ["84342.2", "0"], ["84342.46", "0"], ["84342.49", "0"], ["84342.53", "0"], ["84342.72", "0"], ["84342.79", "0"], ["84343.72", "0"], ["84343.94", "0"], ["84344.09", "0"], ["84344.44", "0"], ["84344.61", "0"], ["84345.02", "0"], ["84345.03", "0"], ["84346.06", "0"], ["84346.09", "0"], ["84346.15", "0"], ["84346.23", "0"], ["84346.26", "0"], ["84346.29", "0"], ["84346.62", "0"]], "u": 7510542, "seq": 66889264144}, "cts": 1742142204408, "record_time": 1742142203.510061}
{"topic": "orderbook.200.BTCUSDT", "ts": 1742142204609, "type": "delta", "data": {"s": "BTCUSDT", "b": [["84295.49", "0.016557"], ["84290.34", "0.116918"], ["84285.75", "0.000089"], ["84285.01", "0"], ["84284.43", "0.01508"], ["84282.34", "0.042125"], ["84282.33", "0.060323"], ["84282.21", "0.071195"], ["84281.94", "0"], ["84279.11", "0.000297"], ["84279.1", "0"], ["84278.55", "0"], ["84278.45", "0"], ["84278.2", "0"], ["84277.95", "0.02"], ["84277.46", "0"], ["84277.33", "0.11948"], ["84277.28", "0.000233"], ["84277.02", "0"], ["84276.5", "0.02"], ["84276.28", "0.02"], ["84276.12", "0"], ["84275.99", "0"], ["84275.92", "0.02"], ["84275.51", "0.057974"], ["84274.62", "0.02"], ["84273.49", "0"], ["84271.02", "0"], ["84267.8", "0.04"], ["84267.53", "0"], ["84266.09", "0.068395"], ["84263.19", "0"], ["84257.63", "0"], ["84254.67", "0"], ["84251.67", "0"], ["84246.68", "1.497168"], ["84246.48", "0.071225"], ["84243.68", "0"], ["84242.8", "0.355952"], ["84239.64", "0.162"], ["84236.65", "0"], ["84234.2", "0.002401"], ["84233.7", "0.24702"], ["84231.69", "0"]], "a": [["84295.5", "0.135492"], ["84295.7", "0"], ["84296.32", "0.101335"], ["84298.39", "0.089922"], ["84300", "0.180002"], ["84305.78", "0"], ["84306.29", "0.12019"], ["84307.81", "0"], ["84309.7", "0.152237"], ["84309.91", "0.020996"], ["84311.78", "0.017796"], ["84312.02", "0.083982"], ["84312.84", "0.03181"], ["84313.01", "0"], ["84313.1", "0.044"], ["84313.4", "0.06"], ["84314.07", "0"], ["84314.1", "0"], ["84315.47", "0"], ["84315.6", "0.029801"], ["84315.93", "0"], ["84316.8", "0.06"], ["84318.04", "0"], ["84319.8", "0.048"], ["84320.2", "0.104"], ["84320.4", "0"], ["84320.5", "0"], ["84321.9", "0"], ["84321.97", "0.07125"], ["84322.4", "0"], ["84324.35", "0"], ["84324.62", "0.023726"], ["84326.07", "0.068395"], ["84326.47", "0.003431"], ["84326.51", "0"], ["84330.72", "0"], ["84331.72", "0"], ["84335.3", "0.005931"], ["84338.26", "0.355952"], ["84340.22", "0"]], "u": 7510543, "seq": 66889264935}, "cts": 1742142204608, "record_time": 1742142203.709277}
{"topic": "orderbook.200.BTCUSDT", "ts": 1742142204809, "type": "delta", "data": {"s": "BTCUSDT", "b": [["84295.49", "0.035605"], ["84290.34", "0.116846"], ["84284.43", "0"], ["84281.53", "0.015081"], ["84279.97", "0"], ["84277.95", "0"], ["84277.81", "0.000297"], ["84277.75", "0.106136"], ["84277.74", "0.116633"], ["84277.46", "0.120962"], ["84277.43", "0.114875"], ["84277.33", "0"], ["84276.5", "0"], ["84276.28", "0"], ["84275.92", "0"], ["84275.56", "0.02"], ["84275.13", "0"], ["84275.09", "0.02"], ["84274.62", "0.105337"], ["84274.52", "0.02"], ["84274.29", "0.02"], ["84273.02", "0.02"], ["84271.4", "0.048"], ["84271.2", "0.04"], ["84271.17", "0.161149"], ["84270.12", "0.073329"], ["84269.63", "0.162057"], ["84269.45", "0"], ["84267.17", "0"], ["84266.79", "0.171515"], ["84266.78", "0.162282"], ["84266.13", "0.237261"], ["84263.34", "0.270157"], ["84263.27", "0.009039"], ["84261.92", "0.237261"], ["84261.8", "0.286149"], ["84258.96", "0.264923"], ["84256.61", "0.296878"], ["84255.49", "0.023708"], ["84254.52", "0.117352"], ["84242.8", "0"], ["84238.04", "0.177945"], ["84236.1", "0"], ["84235.8", "0"], ["84235.57", "0"], ["84235.36", "0"], ["84235.05", "0"], ["84234.81", "0"], ["84234.2", "0"], ["84234.01", "0"], ["84233.7", "0"], ["84233.35", "0"], ["84233.18", "0"], ["84233.14", "0"], ["84232.95", "0"], ["84232.91", "0"], ["84232.83", "0"], ["84232.38", "0"], ["84231.7", "0"]], "a": [["84295.5", "0.147753"], ["84305.3", "0.247194"], ["84305.92", "0.11111"], ["84306.29", "0"], ["84306.42", "0.116074"], ["84307", "0.020996"], ["84307.96", "0.11978"], ["84308.28", "0.117495"], ["84309.7", "0.151988"], ["84309.91", "0"], ["84312.46", "0.237261"], ["84313", "0.068"], ["84313.87", "0.237261"], ["84314.22", "0.177376"], ["84314.25", "0.169381"], ["84315.5", "0.056"], ["84315.59", "0.075719"], ["84316.1", "0.160124"], ["84316.67", "0.237261"], ["84316.88", "0.164361"], ["84317.5", "0"], ["84318.08", "0.237261"], ["84320.1", "0"], ["84320.2", "0.048"], ["84322.05", "0.299496"], ["84322.08", "0.295079"], ["84322.82", "0.482558"], ["84323.93", "0.290187"], ["84325", "0.023726"], ["84326.8", "0"], ["84327.06", "0.284975"], ["84327.2", "0"], ["84329.03", "0.026414"], ["84329.98", "0.35598"], ["84338.26", "0"], ["84338.79", "0"], ["84338.84", "0"], ["84338.99", "0"], ["84339.03", "0"], ["84339.05", "0"], ["84339.07", "0"], ["84339.25", "0"], ["84339.27", "0"], ["84339.8", "0"], ["84339.97", "0"], ["84340.18", "0"], ["84340.58", "0"], ["84340.62", "0"], ["84340.8", "0"], ["84340.88", "0"], ["84340.97", "0"]], "u": 7510544, "seq": 66889265387}, "cts": 1742142204808, "record_time": 1742142203.909194}
{"topic": "orderbook.200.BTCUSDT", "ts": 1742142205009, "type": "delta", "data": {"s": "BTCUSDT", "b": [["84295.49", "0"], ["84291.68", "0"], ["84290.97", "0"], ["84290.34", "0.128032"], ["84287.08", "0"], ["84287.07", "0.000233"], ["84287.06", "0"], ["84282.34", "0.02529"], ["84282.21", "0"], ["84281.92", "0.034898"], ["84281.91", "0.001694"], ["84279.11", "0"], ["84277.81", "0"], ["84277.75", "0.000297"], ["84277.74", "0"], ["84277.46", "0"], ["84277.43", "0"], ["84275.57", "0.000297"], ["84275.51", "0.079262"], ["84275.09", "0"], ["84274.69", "0.02"], ["84274.62", "0"], ["84274.52", "0"], ["84274.29", "0"], ["84274.12", "0.02"], ["84273.89", "0.02"], ["84273.02", "0"], ["84272.62", "0.02"], ["84271.18", "0.166787"], ["84271.17", "0"], ["84270.58", "0"], ["84270.12", "0"], ["84269.63", "0"], ["84266.79", "0"], ["84266.78", "0"], ["84266.13", "0"], ["84265.67", "0.008343"], ["84265.26", "0.023728"], ["84263.34", "0"], ["84261.92", "0.237275"], ["84261.8", "0"], ["84258.96", "0"], ["84257.94", "0"], ["84257.71", "0.034395"], ["84256.61", "0"], ["84255.49", "0"], ["84253.57", "0.003491"], ["84253.02", "0.012515"], ["84250.23", "0"], ["84249.05", "0"], ["84246.48", "0"], ["84245.75", "0.071225"], ["84239.2", "0.071231"], ["84238.04", "0"], ["84236.65", "0.177956"], ["84236.1", "0.000233"], ["84235.8", "0.000335"], ["84235.57", "0.000233"], ["84235.36", "0.0002"], ["84235.05", "0.00009"], ["84234.81", "0.023729"], ["84234.2", "0.002401"], ["84234.01", "0.023729"], ["84233.7", "0.24702"], ["84233.35", "0.001467"], ["84233.18", "0.000252"], ["84233.14", "0.0025"], ["84232.95", "0.001333"], ["84232.91", "0.000613"], ["84232.83", "0.0002"], ["84232.38", "0.015"], ["84231.7", "0.118629"], ["84231.69", "0.059948"], ["84231.67", "0.227168"]], "a": [["84290.35", "0.084306"], ["84291.68", "0.0004"], ["84291.69", "0.071587"], ["84293.5", "0.0002"], ["84294.03", "0.043502"], ["84295.5", "0.008343"], ["84295.71", "0"], ["84296.32", "0"], ["84297.99", "0.059261"], ["84298.38", "0.12434"], ["84298.74", "0.008453"], ["84299.7", "0"], ["84300.12", "0.0005"], ["84300.41", "0"], ["84301.07", "0.016088"], ["84301.08", "0"], ["84302.23", "0"], ["84303.93", "0"], ["84305.29", "0.037646"], ["84305.3", "0.247269"], ["84305.92", "0"], ["84306.42", "0"], ["84307.51", "0.001716"], ["84307.8", "0.083982"], ["84307.96", "0"], ["84308.22", "0.012515"], ["84308.28", "0"], ["84309.7", "0.258543"], ["84312.02", "0"], ["84312.46", "0"], ["84313.06", "0"], ["84313.22", "0.140142"], ["84313.87", "0"], ["84314.22", "0"], ["84314.25", "0"], ["84314.7", "0.112"], ["84315.28", "0.071167"], ["84316.1", "0"], ["84316.67", "0"], ["84316.88", "0"], ["84318.08", "0.237275"], ["84318.8", "0"], ["84320.89", "0.237275"], ["84322.05", "0"], ["84322.08", "0"], ["84322.29", "0.237275"], ["84323.93", "0"], ["84324.15", "0.023728"], ["84325.1", "0.237275"], ["84327.06", "0"], ["84328.5", "0"], ["84329.97", "0.355989"], ["84329.98", "0"], ["84338.79", "0.000357"], ["84338.99", "0.000089"], ["84339.03", "0.0002"], ["84339.07", "0.0045"], ["84339.27", "0.0045"], ["84339.8", "0.000253"], ["84339.97", "0.001467"]], "u": 7510545, "seq": 66889266347}, "cts": 1742142205008, "record_time": 1742142204.108945}
{"topic": "orderbook.200.BTCUSDT", "ts": 1742142205209, "type": "delta", "data": {"s": "BTCUSDT", "b": [["84286.53", "0.000099"], ["84282.34", "0"], ["84282.33", "0"], ["84281.93", "0.039749"], ["84281.92", "0.043725"], ["84280.38", "0.071196"], ["84278.11", "0.06033"], ["84277.75", "0"], ["84275.95", "0.02"], ["84275.68", "0.000297"], ["84275.56", "0"], ["84274.82", "0.02"], ["84274.12", "0"], ["84272.62", "0"], ["84272.52", "0.02"], ["84271.74", "0.237275"], ["84271.18", "0.067371"], ["84269.61", "0.237333"], ["84267.92", "0.237338"], ["84267.53", "0.237275"], ["84266.24", "0.237343"], ["84261.92", "0"], ["84260.52", "0.237275"], ["84259.1", "0.177956"], ["84257.71", "0"], ["84256.31", "0.237275"], ["84245.33", "0"], ["84240.18", "0.000989"], ["84238.04", "0.177956"], ["84233.71", "0.355984"], ["84233.35", "0"], ["84233.18", "0"], ["84233.14", "0"], ["84232.95", "0"], ["84232.91", "0"], ["84232.83", "0"], ["84232.38", "0"], ["84231.7", "0"], ["84231.69", "0"], ["84231.67", "0"]], "a": [["84290.35", "0.077202"], ["84291.18", "0.011863"], ["84294.03", "0"], ["84294.16", "0.000099"], ["84294.55", "0.011863"], ["84295.49", "0.001474"], ["84298.74", "0"], ["84301.07", "0.100832"], ["84303.73", "0.068395"], ["84304.37", "0.008453"], ["84305.3", "0.126972"], ["84305.31", "0.090171"], ["84307", "0"], ["84307.51", "0.001467"], ["84311.39", "0"], ["84312.84", "0"], ["84313.93", "0.000989"], ["84315.3", "0.237275"], ["84315.59", "0"], ["84315.6", "0"], ["84319.07", "0"], ["84319.51", "0.237275"], ["84323.5", "0"], ["84325.1", "0.269085"], ["84329.96", "0.355981"], ["84329.97", "0"], ["84332.15", "0.177956"], ["84332.49", "0.474314"], ["84338.84", "0.162"], ["84339.27", "0"], ["84339.8", "0"], ["84339.97", "0"]], "u": 7510546, "seq": 66889266861}, "cts": 1742142205205, "record_time": 1742142204.308945}
{"topic": "orderbook.200.BTCUSDT", "ts": 1742142205410, "type": "delta", "data": {"s": "BTCUSDT", "b": [["84290.34", "0.228032"], ["84282.58", "0.039818"], ["84282.57", "0.071194"], ["84281.93", "0"], ["84280.38", "0"], ["84278.12", "0.119918"], ["84277.78", "0.11358"], ["84277.49", "0.116023"], ["84276.96", "0.110955"], ["84275.51", "0.140537"], ["84275.39", "0.02"], ["84274.76", "0.113452"], ["84274.69", "0"], ["84274.59", "0.02"], ["84273.89", "0"], ["84273.22", "0.02"], ["84272.52", "0"], ["84270.71", "0.180324"], ["84269.68", "0.164912"], ["84266.94", "0.167718"], ["84266.83", "0.180503"], ["84266.13", "0.133145"], ["84262.89", "0.273859"], ["84261.86", "0.268766"], ["84259.12", "0.288188"], ["84256.67", "0.26563"], ["84252.51", "0.07122"], ["84239.38", "0.2"], ["84239.21", "0.355957"], ["84239.2", "0"], ["84237.69", "0"], ["84237.68", "0"], ["84237.49", "0"], ["84237.17", "0"], ["84237.12", "0"], ["84236.65", "0"], ["84236.1", "0"], ["84235.8", "0"], ["84235.57", "0"], ["84235.36", "0"], ["84235.05", "0"], ["84234.81", "0"], ["84234.2", "0"], ["84234.01", "0"], ["84233.71", "0"], ["84233.7", "0"]], "a": [["84290.35", "0.046384"], ["84291.69", "0.071187"], ["84295.49", "0"], ["84298.38", "0.091268"], ["84298.39", "0"], ["84301.07", "0.039143"], ["84305.3", "0.195443"], ["84305.31", "0"], ["84305.63", "0.020996"], ["84305.92", "0.118468"], ["84306.42", "0.116753"], ["84307.45", "0.107113"], ["84308.37", "0.114341"], ["84309.47", "0.2312"], ["84309.7", "0.151988"], ["84313.7", "0.179168"], ["84314.24", "0.16357"], ["84315.28", "0"], ["84316.19", "0.163936"], ["84316.87", "0.175995"], ["84321.52", "0.273747"], ["84322.06", "0.293916"], ["84324.01", "0.290316"], ["84325.1", "0.237275"], ["84325.85", "0.071158"], ["84326.07", "0"], ["84326.51", "0.237275"], ["84327.03", "0.263541"], ["84329.96", "0"], ["84336.55", "0"], ["84337.56", "0"], ["84338.08", "0"], ["84338.27", "0"], ["84338.31", "0"], ["84338.79", "0"], ["84338.84", "0"], ["84338.99", "0"], ["84339.03", "0"], ["84339.07", "0"]], "u": 7510547, "seq": 66889267264}, "cts": 1742142205407, "record_time": 1742142204.509612}
{"topic": "orderbook.200.BTCUSDT", "ts": 1742142205610, "type": "delta", "data": {"s": "BTCUSDT", "b": [["84290.34", "0.298692"], ["84288.46", "0.027889"], ["84284.78", "0.071192"], ["84282.58", "0.01846"], ["84282.57", "0"], ["84278.21", "0.11046"], ["84278.12", "0.024936"], ["84277.93", "0.118938"], ["84277.78", "0"], ["84277.49", "0"], ["84276.96", "0"], ["84276.15", "0.02"], ["84275.95", "0"], ["84275.59", "0.02"], ["84275.39", "0"], ["84275.03", "0.118098"], ["84275.02", "0.02"], ["84274.82", "0"], ["84274.79", "0.02"], ["84274.76", "0"], ["84274.59", "0"], ["84273.52", "0.02"], ["84273.22", "0"], ["84271.18", "0.376104"], ["84270.98", "0.160649"], ["84270.71", "0"], ["84270.16", "0.167852"], ["84269.68", "0"], ["84267.33", "0.175223"], ["84267.26", "0.162647"], ["84266.94", "0"], ["84266.83", "0"], ["84262.89", "0"], ["84262.39", "0.269938"], ["84261.86", "0"], ["84259.49", "0.263524"], ["84259.12", "0"], ["84257.23", "0.298689"], ["84256.67", "0"], ["84255.47", "0.023867"], ["84249.09", "0.11863"], ["84239.38", "0"], ["84239.21", "0"], ["84238.29", "0"], ["84237.69", "0.039641"], ["84237.68", "0.039641"]], "a": [["84290.35", "0.048384"], ["84291.18", "0"], ["84291.68", "0"], ["84305.3", "0.192212"], ["84305.92", "0"], ["84306.18", "0.119349"], ["84306.42", "0"], ["84306.67", "0.114566"], ["84307.34", "0.000502"], ["84307.45", "0"], ["84308.37", "0"], ["84308.44", "0.108467"], ["84313.7", "0"], ["84313.71", "0.175203"], ["84314.24", "0"], ["84314.44", "0.158757"], ["84316.19", "0"], ["84316.21", "0.158811"], ["84316.87", "0"], ["84317.05", "0.177724"], ["84321.52", "0"], ["84322.06", "0"], ["84322.21", "0.299457"], ["84322.67", "0"], ["84323.98", "0.281246"], ["84324.01", "0"], ["84326.07", "0.068395"], ["84327.03", "0"], ["84327.16", "0.277911"], ["84336.55", "0.015"], ["84337.56", "0.000235"], ["84338.08", "0.000235"], ["84338.27", "0.362488"]], "u": 7510548, "seq": 66889267536}, "cts": 1742142205607, "record_time": 1742142204.708668}
{"topic": "orderbook.200.BTCUSDT", "ts": 1742142205810, "type": "delta", "data": {"s": "BTCUSDT", "b": [["84290.34", "0.128032"], ["84288.46", "0"], ["84284.78", "0"], ["84279.02", "0.037231"], ["84278.71", "0.071198"], ["84278.21", "0"], ["84278.12", "0"], ["84277.93", "0"], ["84276.15", "0"], ["84275.59", "0"], ["84275.03", "0"], ["84275.02", "0"], ["84274.89", "0.020252"], ["84274.79", "0"], ["84274.46", "0.02"], ["84274.22", "0.02"], ["84273.99", "0.02"], ["84273.52", "0"], ["84273.42", "0.02"], ["84271.74", "0"], ["84270.98", "0"], ["84270.16", "0"], ["84269.61", "0"], ["84267.92", "0"], ["84267.53", "0"], ["84267.33", "0"], ["84267.26", "0"], ["84266.24", "0"], ["84266.13", "0"], ["84266.09", "0"], ["84262.4", "0.308703"], ["84262.39", "0"], ["84262.33", "0"], ["84260.52", "0"], ["84260.4", "0.290714"], ["84259.49", "0"], ["84259.1", "0"], ["84257.23", "0"], ["84256.31", "0"], ["84254.4", "0.267428"], ["84252.51", "0"], ["84249.63", "0.035598"], ["84249.09", "0.135869"], ["84246.68", "0"], ["84241.39", "0.071229"], ["84241.3", "0.04"], ["84241.29", "0.039646"], ["84237.69", "0"], ["84237.68", "0"], ["84237.49", "0.000357"], ["84237.17", "0.001333"], ["84237.12", "0.000613"], ["84236.65", "0.177956"], ["84236.1", "0.000233"], ["84235.8", "0.000335"], ["84235.57", "0.000233"], ["84235.36", "0.0002"], ["84235.05", "0.00009"], ["84234.81", "0.023729"], ["84234.2", "0.002401"], ["84234.01", "0.023729"], ["84233.7", "0.24702"], ["84233.35", "0.001467"], ["84233.18", "0.000252"], ["84233.14", "0.0025"], ["84232.95", "0.001333"], ["84232.91", "0.000613"], ["84232.83", "0.0002"], ["84232.38", "0.015"], ["84231.7", "0.118629"], ["84231.69", "0.059948"]], "a": [["84290.35", "0.148548"], ["84291.18", "0.011863"], ["84294.55", "0.008904"], ["84298.78", "0.0005"], ["84300.12", "0"], ["84303.96", "0.012929"], ["84306.18", "0"], ["84306.67", "0"], ["84308.22", "0"], ["84308.44", "0"], ["84309.46", "0.258829"], ["84309.7", "0"], ["84313.71", "0"], ["84314.43", "0.294976"], ["84314.44", "0"], ["84315.3", "0"], ["84315.54", "0.071166"], ["84316.21", "0"], ["84317.05", "0"], ["84319.51", "0"], ["84321.67", "0.03181"], ["84322.21", "0"], ["84323.98", "0"], ["84325.85", "0"], ["84327.16", "0"], ["84332.15", "0"], ["84335.72", "0.04"], ["84335.73", "0.04"], ["84338.26", "0.355959"], ["84338.27", "0.685745"], ["84338.31", "0.001333"], ["84338.79", "0.000357"], ["84338.99", "0.000089"], ["84339.03", "0.0002"], ["84339.07", "0.0045"], ["84339.27", "0.0045"], ["84339.8", "0.000253"]], "u": 7510549, "seq": 66889267986}, "cts": 1742142205804, "record_time": 1742142204.90909}
{"topic": "orderbook.200.BTCUSDT", "ts": 1742142206010, "type": "delta", "data": {"s": "BTCUSDT", "b": [["84290.34", "0.230032"], ["84285.54", "0.0002"], ["84279.02", "0.083676"], ["84278.71", "0"], ["84277.34", "0"], ["84276.49", "0.106175"], ["84276.21", "0.118034"], ["84275.52", "0.110122"], ["84275.51", "0.079262"], ["84273.42", "0"], ["84273.39", "0.108102"], ["84272.72", "0.02"], ["84271.74", "0.237275"], ["84271.18", "0.067371"], ["84269.3", "0.174963"], ["84268.44", "0.171076"], ["84267.53", "0.237275"], ["84265.62", "0.161192"], ["84265.61", "0.171124"], ["84263.54", "0.068395"], ["84262.4", "0.000614"], ["84261.53", "0.267888"], ["84260.67", "0.289702"], ["84260.4", "0.000089"], ["84257.85", "0.283642"], ["84255.51", "0.281763"], ["84254.4", "0"], ["84253.66", "1.488784"], ["84250.99", "0"], ["84249.63", "0"], ["84247.54", "0.0013"], ["84241.3", "0"], ["84241.29", "0"], ["84240.7", "0.04"], ["84240.69", "0.039646"], ["84236.66", "0.355973"], ["84234.81", "0"], ["84234.2", "0"], ["84234.01", "0"], ["84233.7", "0"], ["84233.35", "0"], ["84233.18", "0"], ["84233.14", "0"], ["84232.95", "0"], ["84232.91", "0"], ["84232.83", "0"], ["84232.38", "0"], ["84231.7", "0"], ["84231.69", "0"]], "a": [["84290.35", "0.152107"], ["84296.15", "0.001433"], ["84298", "0"], ["84298.87", "0.008453"], ["84301.07", "0"], ["84302.71", "0.103689"], ["84304.37", "0"], ["84304.46", "0.119729"], ["84304.96", "0.108213"], ["84305.3", "0.122021"], ["84305.82", "0.108387"], ["84305.86", "0.090171"], ["84306.8", "0.114666"], ["84307.34", "0.000253"], ["84308.19", "0.024258"], ["84310.09", "0.140137"], ["84312.04", "0.164231"], ["84312.73", "0.171578"], ["84313.22", "0"], ["84314.43", "0"], ["84314.57", "0.178607"], ["84315.34", "0.173896"], ["84319.81", "0.280975"], ["84320.5", "0.267764"], ["84321.67", "0"], ["84322.34", "0.297177"], ["84325.44", "0.280623"], ["84325.75", "0"], ["84331.71", "0.03181"], ["84334.05", "0.356583"], ["84334.15", "0.0013"], ["84335.72", "0"], ["84335.73", "0"], ["84336", "0"], ["84336.01", "0.04"], ["84336.02", "0.04"], ["84337.56", "0"], ["84338.08", "0"], ["84338.26", "0"], ["84338.27", "0"], ["84338.31", "0"], ["84338.79", "0"], ["84338.99", "0"], ["84339.03", "0"], ["84339.07", "0"], ["84339.27", "0"], ["84339.8", "0"]], "u": 7510550, "seq": 66889268508}, "cts": 1742142206007, "record_time": 1742142205.110623}
{"topic": "orderbook.200.BTCUSDT", "ts": 1742142206209, "type": "delta", "data": {"s": "BTCUSDT", "b": [["84281.53", "0"], ["84279.02", "0.120494"], ["84278.48", "0.015082"], ["84277.25", "0.116544"], ["84276.97", "0.11426"], ["84276.54", "0.117637"], ["84276.49", "0"], ["84276.21", "0"], ["84275.52", "0"], ["84275.51", "0.178968"], ["84274.13", "0.117755"], ["84273.39", "0"], ["84270.32", "0.16378"], ["84269.3", "0"], ["84269.2", "0.165491"], ["84268.44", "0"], ["84266.37", "0.162753"], ["84266.36", "0.178221"], ["84265.62", "0"], ["84265.61", "0.000252"], ["84264.16", "0.000793"], ["84262.55", "0.289503"], ["84261.53", "0"], ["84261.43", "0.275542"], ["84260.67", "0"], ["84258.59", "0.280455"], ["84257.86", "0.003394"], ["84257.85", "0"], ["84256.27", "0.278619"], ["84255.51", "0"], ["84253.57", "0"], ["84249", "0.035598"], ["84236.66", "0"], ["84235.36", "0"], ["84235.05", "0"]], "a": [["84290.35", "0.081294"], ["84302.71", "0.06958"], ["84303.96", "0"], ["84304.46", "0"], ["84304.96", "0"], ["84305.22", "0.114247"], ["84305.29", "0"], ["84305.3", "0.207938"], ["84305.72", "0.115919"], ["84305.82", "0"], ["84305.86", "0.089922"], ["84306.8", "0"], ["84306.84", "0.120036"], ["84307.54", "0.116475"], ["84308.2", "0.06"], ["84308.7", "0.013102"], ["84309.4", "0.044"], ["84312.04", "0"], ["84312.73", "0"], ["84313.06", "0.157638"], ["84313.48", "0.171811"], ["84314.57", "0"], ["84315.31", "0.180618"], ["84315.34", "0"], ["84316.1", "0.164957"], ["84319.81", "0"], ["84320.5", "0"], ["84320.83", "0.292891"], ["84321.25", "0.290001"], ["84322.34", "0"], ["84322.66", "1.449377"], ["84322.82", "0.02465"], ["84323.08", "0.291606"], ["84324.15", "0"], ["84325", "0"], ["84325.44", "0"], ["84326.2", "0.271238"], ["84332.48", "0.355973"], ["84334.05", "0.000612"]], "u": 7510551, "seq": 66889268830}, "cts": 1742142206207, "record_time": 1742142205.309031}
{"topic": "orderbook.200.BTCUSDT", "ts": 1742142206410, "type": "delta", "data": {"s": "BTCUSDT", "b": [["84280.81", "0.071196"], ["84276.45", "0.02"], ["84275.99", "0.02"], ["84275.32", "0.02"], ["84275.09", "0.02"], ["84274.89", "0.000252"], ["84274.46", "0"], ["84274.22", "0"], ["84273.99", "0"], ["84273.82", "0.02"], ["84272.72", "0"], ["84271.18", "0.228913"], ["84270.34", "0.237275"], ["84269.77", "0.237333"], ["84268.95", "0.237275"], ["84268.28", "0.237337"], ["84266.6", "0.237342"], ["84264.74", "0.237275"], ["84252.45", "0.07122"], ["84249.09", "0.017239"], ["84241.39", "0"], ["84239.33", "0.11"], ["84237.89", "0"], ["84237.81", "0"], ["84237.49", "0"], ["84237.17", "0"], ["84237.12", "0"], ["84236.65", "0"], ["84236.1", "0"], ["84235.8", "0"], ["84235.57", "0"]], "a": [["84290.35", "0.081447"], ["84305.71", "0.117586"], ["84305.72", "0"], ["84306.84", "0.119787"], ["84307.34", "0.000502"], ["84307.7", "0.044"], ["84311.5", "0.06"], ["84313.05", "0.168163"], ["84313.06", "0"], ["84313.4", "0"], ["84314.5", "0.048"], ["84314.7", "0.068"], ["84314.9", "0.048235"], ["84315.3", "0.237275"], ["84316.09", "0.165687"], ["84316.1", "0"], ["84316.8", "0"], ["84317.55", "0.008759"], ["84319.51", "0.237275"], ["84320.82", "0.264654"], ["84320.83", "0"], ["84326.19", "0.285158"], ["84326.2", "0"], ["84332.48", "0"], ["84336.02", "0"], ["84336.5", "0"], ["84336.55", "0"]], "u": 7510552, "seq": 66889269051}, "cts": 1742142206408, "record_time": 1742142205.50885}
{"topic": "orderbook.200.BTCUSDT", "ts": 1742142206610, "type": "delta", "data": {"s": "BTCUSDT", "b": [["84290.34", "0.300692"], ["84280.81", "0"], ["84279.02", "0.13968"], ["84278.05", "0.02"], ["84277.49", "0.02"], ["84277.25", "0"], ["84277.19", "0.111504"], ["84276.97", "0"], ["84276.92", "0.02"], ["84276.69", "0.02"], ["84276.54", "0"], ["84276.45", "0"], ["84275.99", "0"], ["84275.42", "0.02"], ["84275.41", "0.117302"], ["84275.32", "0"], ["84275.09", "0"], ["84274.13", "0"], ["84273.82", "0"], ["84271.18", "0.493486"], ["84270.97", "0.160411"], ["84270.32", "0"], ["84269.2", "0"], ["84267.82", "0.173593"], ["84267.64", "0.160815"], ["84266.37", "0"], ["84266.36", "0"], ["84263.2", "0.295586"], ["84262.55", "0"], ["84261.43", "0"], ["84259.87", "0.279557"], ["84258.59", "0"], ["84257.72", "0.284987"], ["84256.27", "0"], ["84243.31", "0.04"], ["84243.3", "0.039644"], ["84240.7", "0"], ["84240.69", "0"], ["84239.65", "0.355949"], ["84237.89", "0.0002"], ["84237.81", "0.023981"], ["84237.49", "0.000357"], ["84237.17", "0.001333"]], "a": [["84290.35", "0.041334"], ["84295.49", "0.000601"], ["84302.71", "0.04035"], ["84305.22", "0"], ["84305.71", "0"], ["84305.86", "0"], ["84306.84", "0"], ["84307.16", "0.109349"], ["84307.49", "0.112979"], ["84307.54", "0"], ["84308.82", "0.108521"], ["84313.05", "0"], ["84313.1", "0"], ["84313.48", "0"], ["84314.93", "0.161935"], ["84315.31", "0"], ["84316.09", "0"], ["84316.59", "0.167619"], ["84317.54", "0.179549"], ["84317.55", "0"], ["84319.8", "0"], ["84320.2", "0"], ["84320.82", "0"], ["84321.25", "0.000253"], ["84322.7", "0.265743"], ["84323.08", "0"], ["84324.36", "0.289986"], ["84326.19", "0"], ["84327.64", "0.274822"], ["84331.71", "0"], ["84332.91", "0.037753"], ["84334.52", "0.04"], ["84334.53", "0.04"], ["84336.01", "0"], ["84336.5", "0.0002"], ["84336.55", "0.015"], ["84337.56", "0.000235"], ["84338.08", "0.000235"], ["84338.27", "0.685745"]], "u": 7510553, "seq": 66889269553}, "cts": 1742142206608, "record_time": 1742142205.709735}
{"topic": "orderbook.200.BTCUSDT", "ts": 1742142206809, "type": "delta", "data": {"s": "BTCUSDT", "b": [["84279.02", "0.141532"], ["84277.59", "0.02"], ["84277.49", "0"], ["84277.19", "0"], ["84275.51", "0.079262"], ["84275.41", "0"], ["84270.97", "0"], ["84267.82", "0"], ["84267.64", "0"], ["84263.2", "0"], ["84259.87", "0"], ["84259.1", "0.177956"], ["84257.72", "0"], ["84247.88", "0.177956"], ["84243.31", "0"], ["84243.3", "0"], ["84243.21", "0.04"], ["84243.2", "0.039644"], ["84239.65", "0"], ["84237.12", "0.000613"], ["84236.65", "0.177956"], ["84236.1", "0.000233"], ["84235.8", "0.000335"], ["84235.57", "0.000233"], ["84235.36", "0.0002"], ["84235.05", "0.00009"]], "a": [["84290.35", "0.044893"], ["84305.3", "0.210185"], ["84307.16", "0"], ["84307.49", "0"], ["84308.82", "0"], ["84314.92", "0.268799"], ["84314.93", "0"], ["84316.59", "0"], ["84317.54", "0"], ["84322.7", "0"], ["84324.36", "0"], ["84327.64", "0"], ["84332.15", "0.177956"], ["84338.26", "0.355964"], ["84338.31", "0.001333"], ["84338.79", "0.000357"], ["84338.99", "0.000089"], ["84339.03", "0.0002"], ["84339.07", "0.0045"], ["84339.27", "0.0045"]], "u": 7510554, "seq": 66889269876}, "cts": 1742142206801, "record_time": 1742142205.909052}
{"topic": "orderbook.200.BTCUSDT", "ts": 1742142207009, "type": "delta", "data": {"s": "BTCUSDT", "b": [["84279.02", "0.150598"], ["84278.78", "0.116813"], ["84278.75", "0.02"], ["84278.5", "0.115235"], ["84278.29", "0.02"], ["84278.05", "0"], ["84277.72", "0.02"], ["84277.59", "0"], ["84277.49", "0.02"], ["84277.28", "0.117814"], ["84276.92", "0"], ["84276.69", "0"], ["84276.12", "0.02"], ["84275.51", "0.23781"], ["84275.42", "0"], ["84271.1", "0.167098"], ["84270.78", "0.173637"], ["84267.97", "0.171628"], ["84267.79", "0.173432"], ["84263.38", "0.296329"], ["84263.06", "0.298755"], ["84260.07", "0.298255"], ["84257.93", "0.279426"], ["84243.41", "0.04"], ["84243.4", "0.039644"], ["84243.21", "0"], ["84243.2", "0"], ["84237.81", "0"], ["84237.49", "0"], ["84237.17", "0"], ["84237.12", "0"], ["84236.65", "0"], ["84236.1", "0"], ["84235.8", "0"], ["84235.57", "0"], ["84235.36", "0"], ["84235.05", "0"]], "a": [["84306.58", "0.41353"], ["84307.08", "0.120868"], ["84307.34", "0.000253"], ["84307.4", "0.110236"], ["84308.72", "0.118768"], ["84313.58", "0.164748"], ["84314.8", "0.160041"], ["84314.92", "0"], ["84316.44", "0.177317"], ["84317.39", "0.161752"], ["84321.3", "0.264973"], ["84322.52", "0.275011"], ["84324.16", "0.294981"], ["84327.43", "0.289418"], ["84334.41", "0.04"], ["84334.42", "0.04"], ["84334.52", "0"], ["84334.53", "0"], ["84337.56", "0"], ["84338.08", "0"], ["84338.26", "0"], ["84338.27", "0"], ["84338.31", "0"], ["84338.79", "0"], ["84338.99", "0"], ["84339.03", "0"], ["84339.07", "0"], ["84339.27", "0"]], "u": 7510555, "seq": 66889270119}, "cts": 1742142207008, "record_time": 1742142206.108951}
{"topic": "orderbook.200.BTCUSDT", "ts": 1742142207210, "type": "delta", "data": {"s": "BTCUSDT", "b": [["84279.32", "0.10596"], ["84279.02", "0.047283"], ["84278.78", "0"], ["84278.5", "0"], ["84278.29", "0"], ["84278.19", "0.02"], ["84277.72", "0"], ["84277.62", "0.02"], ["84277.49", "0"], ["84277.39", "0.02"], ["84277.36", "0.115982"], ["84277.28", "0.000233"], ["84275.51", "0.122537"], ["84273.48", "0.162"], ["84271.1", "0"], ["84270.78", "0"], ["84270.35", "0.009065"], ["84269.81", "0.167409"], ["84267.97", "0"], ["84267.79", "0"], ["84266.61", "0.358186"], ["84265.67", "0"], ["84263.38", "0"], ["84263.06", "0"], ["84260.07", "0"], ["84259.49", "0.071214"], ["84257.93", "0"], ["84257.71", "0.013598"], ["84253.02", "0"], ["84245.75", "0"], ["84243.41", "0"], ["84243.4", "0"], ["84243.11", "0.04"], ["84243.1", "0.039644"], ["84239.34", "0.355949"], ["84237.81", "0.023981"], ["84237.49", "0.000357"], ["84237.17", "0.001333"], ["84237.12", "0.000613"], ["84236.65", "0.177956"]], "a": [["84290.35", "0.01965"], ["84291.18", "0.000153"], ["84291.69", "0"], ["84294.55", "0"], ["84294.98", "0.071184"], ["84298.38", "0"], ["84300.56", "0"], ["84306.58", "0.237261"], ["84307.08", "0"], ["84307.4", "0"], ["84308.19", "0"], ["84308.7", "0.013351"], ["84308.72", "0"], ["84313.58", "0"], ["84314.8", "0"], ["84315.3", "0"], ["84315.54", "0"], ["84316.44", "0"], ["84317.39", "0"], ["84318.08", "0"], ["84320.89", "0"], ["84321.3", "0"], ["84321.97", "0.000089"], ["84322.29", "0"], ["84322.52", "0"], ["84324.16", "0"], ["84325.1", "0"], ["84326.07", "0"], ["84326.51", "0"], ["84326.54", "0.071157"], ["84327.43", "0"], ["84334.41", "0"], ["84334.42", "0"], ["84336.32", "0.04"], ["84336.33", "0.04"], ["84337.56", "0.000235"], ["84338.08", "0.000235"], ["84338.27", "0.685745"], ["84338.31", "0.001333"], ["84338.79", "0.000357"], ["84338.99", "0.000089"], ["84339.03", "0.0002"], ["84339.07", "0.0045"], ["84339.27", "0.0045"], ["84339.8", "0.000253"], ["84339.97", "0.001467"], ["84340.18", "0.023724"], ["84340.58", "0.023724"], ["84340.62", "0.059948"], ["84340.8", "0.023729"], ["84340.88", "0.000158"], ["84341.49", "0.023723"], ["84341.56", "0.0002"], ["84342.2", "0.000235"], ["84342.46", "0.237306"], ["84342.49", "0.000612"], ["84342.53", "0.001333"]], "u": 7510556, "seq": 66889270425}, "cts": 1742142207207, "record_time": 1742142206.309157}
{"topic": "orderbook.200.BTCUSDT", "ts": 1742142207409, "type": "delta", "data": {"s": "BTCUSDT", "b": [["84293.49", "0.343612"], ["84290.35", "0.11997"], ["84290.34", "0.125846"], ["84289.5", "0.0171"], ["84288.45", "0"], ["84285.06", "0.0005"], ["84283.01", "0.008453"], ["84282.58", "0.105215"], ["84281.91", "0.163194"], ["84280.97", "0.118885"], ["84280.69", "0.114103"], ["84279.7", "0.163375"], ["84279.43", "0.118763"], ["84279.32", "0"], ["84279.02", "0"], ["84278.76", "0.059948"], ["84278.75", "0"], ["84278.52", "0.089922"], ["84278.42", "0.106221"], ["84278.19", "0"], ["84277.62", "0"], ["84277.5", "0.1505"], ["84277.39", "0"], ["84277.36", "0"], ["84276.94", "0.000793"], ["84276.35", "0.009072"], ["84276.12", "0"], ["84273.25", "0.159232"], ["84272.97", "0.159657"], ["84271.9", "0.068395"], ["84271.74", "0"], ["84271.57", "0.118638"], ["84270.7", "0.160264"], ["84270.35", "0"], ["84270.34", "0"], ["84270.15", "0.166976"], ["84269.81", "0"], ["84269.77", "0"], ["84268.95", "0"], ["84268.28", "0"], ["84267.53", "0"], ["84266.61", "0.000614"], ["84266.6", "0"], ["84265.24", "0.264478"], ["84264.74", "0"], ["84264.16", "0"], ["84263.71", "0.031752"], ["84263.54", "0"], ["84262.11", "0.089922"], ["84260.11", "0.294821"], ["84259.1", "0"], ["84257.71", "0"], ["84254.09", "0"], ["84253.67", "0.11863"], ["84249.32", "0.3559"], ["84249.09", "0"], ["84247.88", "0"], ["84247.35", "0.216033"], ["84243.67", "0.237275"], ["84239.46", "0.237275"], ["84239.34", "0"], ["84238.04", "0"], ["84237.12", "0"], ["84236.65", "0"]], "a": [["84290.35", "0"], ["84291.18", "0"], ["84293.5", "0.011386"], ["84294.98", "0"], ["84295.5", "0"], ["84296.33", "0"], ["84297.99", "0"], ["84298.46", "0.071181"], ["84298.78", "0"], ["84298.87", "0"], ["84301.93", "0.0005"], ["84302.71", "0"], ["84303.73", "0"], ["84305.3", "0.106572"], ["84306.76", "0.009093"], ["84307.7", "0"], ["84308.2", "0"], ["84308.7", "0"], ["84308.77", "0.108499"], ["84309.26", "0.108957"], ["84309.4", "0"], ["84309.42", "0.008453"], ["84309.46", "0.224854"], ["84309.47", "0"], ["84309.55", "0.110574"], ["84310.09", "0"], ["84311.5", "0"], ["84311.63", "0.107905"], ["84312.36", "0"], ["84312.9", "0.044"], ["84313.4", "0.06"], ["84314.5", "0"], ["84314.6", "0.044"], ["84314.9", "0.000235"], ["84315.72", "0.15934"], ["84316.7", "0.068395"], ["84316.99", "0.160534"], ["84319.35", "0.169931"], ["84319.4", "0.01364"], ["84319.51", "0"], ["84319.58", "0.168351"], ["84319.7", "0.048"], ["84320.03", "0"], ["84320.79", "0"], ["84321.38", "0.118638"], ["84321.87", "0"], ["84322.82", "0"], ["84323.45", "0.278239"], ["84323.67", "0.008976"], ["84324.71", "0.28542"], ["84327.07", "0.279978"], ["84328.86", "0.024047"], ["84331.87", "0.071153"], ["84332.15", "0"], ["84332.49", "0"], ["84332.91", "0"], ["84336.32", "0"], ["84336.33", "0"], ["84336.42", "0.04"], ["84336.43", "0.04"], ["84338.84", "0.162"], ["84342.72", "0.000235"]], "u": 7510557, "seq": 66889271197}, "cts": 1742142207407, "record_time": 1742142206.508952}
{"topic": "orderbook.200.BTCUSDT", "ts": 1742142207609, "type": "delta", "data": {"s": "BTCUSDT", "b": [["84292.72", "0.071186"], ["84292.65", "0.0174"], ["84290.35", "0.04346"], ["84289.5", "0"], ["84286.53", "0"], ["84283.32", "0.112538"], ["84283.14", "0.241294"], ["84283.05", "0.111773"], ["84282.58", "0"], ["84282.55", "0.02"], ["84281.99", "0.02"], ["84281.64", "0.115232"], ["84281.42", "0.02"], ["84281.19", "0.02"], ["84281.11", "0.112506"], ["84280.97", "0"], ["84280.69", "0"], ["84280.16", "0.237266"], ["84279.7", "0"], ["84279.43", "0"], ["84279.02", "0.02"], ["84278.77", "0.116354"], ["84278.42", "0"], ["84275.95", "0.237266"], ["84275.51", "0.240322"], ["84275.46", "0.177176"], ["84275.32", "0.162145"], ["84273.38", "0.1796"], ["84273.25", "0"], ["84272.97", "0"], ["84272.51", "0.17664"], ["84271.18", "0"], ["84270.7", "0"], ["84270.15", "0"], ["84267.74", "0.267964"], ["84267.6", "0.264111"], ["84265.66", "0.27199"], ["84265.24", "0"], ["84262.47", "0.294515"], ["84260.11", "0"], ["84258.69", "0.068395"], ["84257.71", "0.133441"], ["84249.33", "0.355904"], ["84249.32", "0"], ["84240.18", "0"], ["84239.64", "0"], ["84239.46", "0"], ["84239.33", "0"], ["84238.07", "0"], ["84237.98", "0"], ["84237.89", "0"], ["84237.81", "0"], ["84237.49", "0"], ["84237.17", "0"]], "a": [["84293.5", "0.013146"], ["84294.16", "0"], ["84298.46", "0"], ["84300.23", "0.008303"], ["84301.32", "0.071178"], ["84305.3", "0"], ["84308.77", "0"], ["84309.26", "0"], ["84309.46", "0"], ["84309.55", "0"], ["84310.9", "0.188531"], ["84311.13", "0.120677"], ["84311.62", "0.108099"], ["84311.63", "0"], ["84311.76", "0.111831"], ["84314.31", "0.112663"], ["84315.42", "0.024154"], ["84315.49", "0.140016"], ["84315.72", "0"], ["84316.48", "0.140119"], ["84316.7", "0.128395"], ["84316.99", "0"], ["84317.93", "0.180783"], ["84319.34", "0.172278"], ["84319.35", "0"], ["84319.58", "0"], ["84320", "0.048113"], ["84321.94", "0.16283"], ["84322.04", "0.172196"], ["84323.45", "0"], ["84323.67", "0"], ["84324.71", "0"], ["84325.66", "0.273392"], ["84326.54", "0"], ["84327.07", "0.274631"], ["84329.76", "0.298645"], ["84331.98", "0.28055"], ["84336.42", "0"], ["84336.43", "0"], ["84336.52", "0.04"], ["84336.53", "0.04"], ["84336.63", "0.071149"], ["84339.82", "0.059294"], ["84341.59", "0.037879"], ["84342.49", "0"], ["84342.53", "0"], ["84342.72", "0"]], "u": 7510558, "seq": 66889271572}, "cts": 1742142207601, "record_time": 1742142206.709057}
{"topic": "orderbook.200.BTCUSDT", "ts": 1742142207809, "type": "delta", "data": {"s": "BTCUSDT", "b": [["84293.49", "0.272808"], ["84292.72", "0"], ["84290.34", "0.116846"], ["84289.63", "0.000099"], ["84283.32", "0"], ["84283.29", "0.120286"], ["84283.14", "0.165285"], ["84283.05", "0"], ["84283.01", "0.111943"], ["84281.91", "0.001194"], ["84281.64", "0"], ["84281.53", "0.116969"], ["84281.11", "0"], ["84280.87", "0.106342"], ["84280.38", "0.237303"], ["84279.82", "0.02"], ["84279.02", "0"], ["84278.77", "0.172989"], ["84278.76", "0"], ["84278.52", "0"], ["84278.48", "0.023535"], ["84275.46", "0"], ["84275.36", "0.177491"], ["84275.32", "0"], ["84275.29", "0.166351"], ["84273.38", "0"], ["84273.15", "0.167095"], ["84272.51", "0"], ["84272.47", "0.158539"], ["84267.74", "0"], ["84267.63", "0.281456"], ["84267.6", "0"], ["84267.56", "0.292408"], ["84265.66", "0"], ["84265.43", "0.280909"], ["84262.47", "0"], ["84262.43", "0.292127"], ["84259.1", "0.100432"], ["84249.33", "0"], ["84243.88", "0.35592"], ["84243.67", "0"], ["84243.36", "0.000989"], ["84239.33", "0.11"]], "a": [["84294.35", "0.071184"], ["84297.36", "0.000099"], ["84298.56", "0.032633"], ["84300.23", "0.000554"], ["84301.32", "0"], ["84306.57", "0.102796"], ["84310.87", "0.182648"], ["84310.89", "0.059948"], ["84310.9", "0"], ["84311.09", "0.106922"], ["84311.13", "0"], ["84311.58", "0.108402"], ["84311.62", "0"], ["84311.65", "0.11054"], ["84311.76", "0"], ["84313.93", "0"], ["84314.08", "0.116456"], ["84314.31", "0"], ["84315.49", "0.10409"], ["84317.07", "0.000989"], ["84317.83", "0.169495"], ["84317.93", "0"], ["84318.79", "0.1622"], ["84319.31", "0.161369"], ["84319.34", "0"], ["84321.8", "0.167599"], ["84321.9", "0.177823"], ["84321.94", "0"], ["84322.04", "0"], ["84323.97", "0.008735"], ["84325.55", "0.276752"], ["84325.6", "0.071158"], ["84325.66", "0.001333"], ["84327.03", "0.290652"], ["84327.07", "0"], ["84329.53", "0.300172"], ["84329.76", "0"], ["84331.94", "0.265413"], ["84331.98", "0"], ["84336.52", "0"], ["84336.53", "0"], ["84336.63", "0"], ["84337.01", "0.04"], ["84337.02", "0.04"], ["84341.49", "0"], ["84341.56", "0"], ["84341.59", "0"], ["84342.2", "0"], ["84342.46", "0"]], "u": 7510559, "seq": 66889271955}, "cts": 1742142207807, "record_time": 1742142206.908952}
{"topic": "orderbook.200.BTCUSDT", "ts": 1742142208009, "type": "delta", "data": {"s": "BTCUSDT", "b": [["84288.99", "0.0001"], ["84285.54", "0"], ["84283.29", "0"], ["84283.14", "0.264463"], ["84283.01", "0"], ["84282.95", "0.02"], ["84282.55", "0"], ["84282.49", "0.02"], ["84281.99", "0"], ["84281.82", "0.02"], ["84281.69", "0.02"], ["84281.53", "0"], ["84281.42", "0"], ["84281.19", "0"], ["84280.87", "0"], ["84280.32", "0.02"], ["84279.82", "0"], ["84278.96", "0.112344"], ["84278.77", "0.265858"], ["84277.38", "0.237266"], ["84277.3", "0.237401"], ["84275.62", "0.237317"], ["84275.51", "0.330775"], ["84275.36", "0"], ["84275.29", "0"], ["84273.16", "0.237266"], ["84273.15", "0"], ["84272.47", "0"], ["84271.21", "0.166805"], ["84267.63", "0"], ["84267.56", "0"], ["84265.43", "0"], ["84263.47", "0.280345"], ["84262.43", "0"], ["84250.99", "0.0013"], ["84247.54", "0"], ["84241.93", "0.02357"], ["84239.64", "0.162"], ["84238.07", "0.118629"], ["84237.98", "0.001467"], ["84237.89", "0.0002"], ["84237.81", "0.023981"]], "a": [["84296.15", "0.001333"], ["84296.4", "0.0001"], ["84297.7", "0.009295"], ["84299.99", "0.11863"], ["84300", "0.18475"], ["84300.23", "0.011862"], ["84302.05", "0.000153"], ["84303.77", "0.015453"], ["84311.09", "0"], ["84311.58", "0"], ["84311.65", "0"], ["84312.26", "0.106612"], ["84314.08", "0"], ["84314.59", "0.196152"], ["84315.49", "0"], ["84317.83", "0"], ["84319.31", "0"], ["84320.01", "0.178018"], ["84321.8", "0"], ["84321.9", "0"], ["84323.72", "0.237266"], ["84325.55", "0"], ["84326.51", "0.237266"], ["84327.03", "0"], ["84327.76", "0.292876"], ["84327.94", "0.237266"], ["84329.53", "0"], ["84330.72", "0.237266"], ["84331.94", "0"], ["84334.15", "0"], ["84334.4", "0.0013"], ["84337.01", "0"], ["84337.02", "0"], ["84337.21", "0.04"], ["84337.22", "0.04"]], "u": 7510560, "seq": 66889272293}, "cts": 1742142208005, "record_time": 1742142207.107959}
{"topic": "orderbook.200.BTCUSDT", "ts": 1742142208209, "type": "delta", "data": {"s": "BTCUSDT", "b": [["84283.14", "0.267748"], ["84281.79", "0.113836"], ["84281.51", "0.112167"], ["84280.54", "0.114839"], ["84275.51", "0.240322"], ["84274.35", "0.176124"], ["84273.76", "0.165558"], ["84270.94", "0.170964"], ["84266.6", "0.291577"], ["84266.02", "0.269563"], ["84260.87", "0.269418"], ["84247.88", "0.17795"], ["84240.77", "0"], ["84240.73", "0"], ["84240.41", "0"], ["84240.2", "0"], ["84239.64", "0"], ["84239.33", "0"], ["84238.07", "0"], ["84237.98", "0"], ["84237.89", "0"], ["84237.81", "0"]], "a": [["84301.39", "0.000153"], ["84302.05", "0"], ["84309.67", "0.115539"], ["84310.17", "0.110658"], ["84310.75", "0.114079"], ["84314.59", "0.145303"], ["84316.95", "0.170517"], ["84317.91", "0.178478"], ["84320.52", "0.170507"], ["84324.69", "0.286724"], ["84325.66", "0.268216"], ["84326.51", "0"], ["84330.59", "0.278777"], ["84330.72", "0"], ["84340.18", "0"], ["84340.58", "0"], ["84340.62", "0"], ["84340.8", "0"], ["84340.88", "0"]], "u": 7510561, "seq": 66889272402}, "cts": 1742142208203, "record_time": 1742142207.309048}
{"topic": "orderbook.200.BTCUSDT", "ts": 1742142208410, "type": "delta", "data": {"s": "BTCUSDT", "b": [["84293.49", "1.290468"], ["84290.66", "0.071187"], ["84283.45", "0.02"], ["84283.14", "0.261795"], ["84282.99", "0.02"], ["84282.95", "0"], ["84282.49", "0"], ["84282.32", "0.02"], ["84282.19", "0.02"], ["84281.82", "0"], ["84281.79", "0"], ["84281.69", "0"], ["84281.51", "0"], ["84280.82", "0.02"], ["84280.54", "0"], ["84280.32", "0"], ["84278.97", "0.059948"], ["84278.96", "0"], ["84275.95", "0"], ["84274.35", "0"], ["84273.76", "0"], ["84271.21", "0"], ["84270.94", "0"], ["84266.61", "0.365614"], ["84266.6", "0"], ["84266.02", "0"], ["84263.47", "0"], ["84260.87", "0"], ["84248.08", "0.35591"], ["84243.88", "0"], ["84240.77", "0.023729"], ["84240.73", "0.000233"], ["84240.41", "0.0002"], ["84240.2", "0.000233"], ["84239.33", "0.11"], ["84239.01", "0.000237"], ["84238.07", "0.118629"], ["84237.98", "0.001467"], ["84237.89", "0.0002"], ["84237.81", "0.023981"], ["84237.49", "0.000357"]], "a": [["84294.35", "0"], ["84296.66", "0.071182"], ["84297.7", "0.00079"], ["84298.56", "0.0002"], ["84299.99", "0"], ["84300.23", "0"], ["84301.39", "0"], ["84301.49", "0.000153"], ["84303.77", "0"], ["84309.67", "0"], ["84310.17", "0"], ["84310.75", "0"], ["84312.26", "0"], ["84313", "0"], ["84314.7", "0"], ["84315.5", "0"], ["84316.95", "0"], ["84317.91", "0"], ["84320.01", "0"], ["84320.52", "0"], ["84322.65", "0.707295"], ["84324.69", "0"], ["84325.66", "0.001333"], ["84327.76", "0"], ["84330.59", "0.005931"], ["84340.18", "0.023724"], ["84340.58", "0.023724"], ["84340.62", "0.059948"], ["84340.8", "0.023729"], ["84340.88", "0.000158"], ["84341.49", "0.023723"], ["84341.56", "0.0002"], ["84341.59", "0.037879"], ["84342.2", "0.000235"], ["84342.46", "0.237306"], ["84342.49", "0.000612"], ["84342.53", "0.001333"], ["84342.72", "0.000235"], ["84342.79", "0.023724"], ["84343.72", "0.089922"]], "u": 7510562, "seq": 66889272872}, "cts": 1742142208406, "record_time": 1742142207.509955}
{"topic": "orderbook.200.BTCUSDT", "ts": 1742142208610, "type": "delta", "data": {"s": "BTCUSDT", "b": [["84293.49", "0.274808"], ["84291.24", "0.071187"], ["84290.66", "0"], ["84283.14", "0.165285"], ["84282.27", "0.116994"], ["84281.99", "0.115288"], ["84280.74", "0.111209"], ["84280.16", "0"], ["84279.99", "0.119623"], ["84274.54", "0.169243"], ["84274.24", "0.180395"], ["84273.16", "0"], ["84272.24", "0.176603"], ["84271.42", "0.162044"], ["84266.8", "0.263956"], ["84266.61", "0.000614"], ["84266.5", "0.267279"], ["84264.5", "0.296218"], ["84261.36", "0.297399"], ["84248.08", "0"], ["84243.88", "0.355921"], ["84240.73", "0"], ["84240.41", "0"], ["84240.2", "0"], ["84239.33", "0"], ["84239.01", "0"], ["84238.07", "0"], ["84237.98", "0"], ["84237.89", "0"], ["84237.81", "0"], ["84237.49", "0"]], "a": [["84293.5", "0.06318"], ["84294.5", "0.000153"], ["84296.66", "0"], ["84297.7", "0"], ["84298.56", "0.032634"], ["84300.23", "0.011862"], ["84301.49", "0"], ["84303.77", "0.015453"], ["84309.71", "0.09641"], ["84310.15", "0.114086"], ["84310.65", "0.12029"], ["84310.87", "0"], ["84310.95", "0.105555"], ["84312.87", "0.03181"], ["84313.29", "0.107553"], ["84314.59", "0"], ["84317.14", "0.172146"], ["84318.39", "0.171258"], ["84318.8", "0.068"], ["84319.7", "0.116"], ["84320.4", "0.056"], ["84321", "0.179608"], ["84321.04", "0.175799"], ["84321.63", "0.029801"], ["84324.61", "0.024761"], ["84324.89", "0.282689"], ["84326.14", "0.287834"], ["84328.79", "0.285257"], ["84328.86", "0"], ["84330.72", "0.237266"], ["84331.07", "0.298583"], ["84337.21", "0"], ["84337.22", "0"], ["84337.31", "0.04"], ["84337.32", "0.04"], ["84339.97", "0"], ["84340.18", "0"], ["84340.58", "0"], ["84340.62", "0"], ["84340.8", "0"], ["84340.88", "0"], ["84341.49", "0"], ["84341.56", "0"], ["84341.59", "0"], ["84342.2", "0"], ["84342.46", "0"], ["84342.49", "0"], ["84342.53", "0"], ["84342.72", "0"], ["84342.79", "0"], ["84343.72", "0"]], "u": 7510563, "seq": 66889273386}, "cts": 1742142208604, "record_time": 1742142207.709381}
{"topic": "orderbook.200.BTCUSDT", "ts": 1742142208810, "type": "delta", "data": {"s": "BTCUSDT", "b": [["84291.24", "0"], ["84289.14", "0.071189"], ["84284.45", "0.02"], ["84283.99", "0.02"], ["84283.45", "0"], ["84283.32", "0.02"], ["84283.19", "0.02"], ["84283.14", "0.242129"], ["84282.99", "0"], ["84282.32", "0"], ["84282.27", "0"], ["84282.19", "0"], ["84281.99", "0"], ["84281.82", "0.02"], ["84281.59", "0.237266"], ["84281.46", "0.11815"], ["84281.18", "0.109619"], ["84280.82", "0"], ["84280.74", "0"], ["84280.16", "0.237266"], ["84280.01", "0.107676"], ["84279.99", "0"], ["84279.23", "0.116969"], ["84275.95", "0.237266"], ["84274.54", "0"], ["84274.24", "0"], ["84273.81", "0.172732"], ["84273.44", "0.170659"], ["84272.24", "0"], ["84271.48", "0.173389"], ["84271.42", "0"], ["84270.62", "0.166442"], ["84266.8", "0"], ["84266.5", "0"], ["84266.06", "0.280615"], ["84265.69", "0.268976"], ["84264.5", "0"], ["84263.74", "0.295626"], ["84261.36", "0"], ["84260.55", "0.300853"], ["84240.87", "0"], ["84240.77", "0"]], "a": [["84294.2", "0.071184"], ["84298.56", "0.0002"], ["84299.99", "0.11863"], ["84309.35", "0.115075"], ["84309.71", "0.228147"], ["84309.84", "0.11731"], ["84310.15", "0"], ["84310.21", "0.112372"], ["84310.65", "0"], ["84310.95", "0"], ["84312.53", "0.110167"], ["84312.87", "0"], ["84313.29", "0"], ["84316.41", "0.160406"], ["84317.14", "0"], ["84317.59", "0.162597"], ["84318.39", "0"], ["84320.19", "0.159882"], ["84320.28", "0.16012"], ["84321", "0"], ["84321.04", "0"], ["84321.63", "0"], ["84323.97", "0"], ["84324.16", "0.30083"], ["84324.88", "0.03181"], ["84324.89", "0"], ["84325.33", "0.287027"], ["84326.14", "0"], ["84326.51", "0.237266"], ["84328.02", "0.282583"], ["84328.79", "0"], ["84330.26", "0.286734"], ["84331.07", "0"], ["84336.94", "0.029801"], ["84339.8", "0"], ["84339.82", "0"]], "u": 7510564, "seq": 66889273540}, "cts": 1742142208792, "record_time": 1742142207.90894}
{"topic": "orderbook.200.BTCUSDT", "ts": 1742142209009, "type": "delta", "data": {"s": "BTCUSDT", "b": [["84290.97", "0.0002"], ["84284.89", "0.02"], ["84284.22", "0.02"], ["84284.09", "0.02"], ["84283.99", "0"], ["84283.32", "0"], ["84283.19", "0"], ["84281.46", "0"], ["84281.18", "0"], ["84280.04", "0.111946"], ["84280.01", "0"], ["84279.23", "0"], ["84273.81", "0"], ["84273.44", "0"], ["84271.48", "0"], ["84270.62", "0"], ["84266.06", "0"], ["84265.69", "0.0002"], ["84263.74", "0"], ["84260.55", "0"], ["84245.81", "0.04"], ["84245.8", "0.039644"], ["84243.88", "0"], ["84243.12", "0.355932"], ["84243.11", "0"], ["84243.1", "0"], ["84240.87", "0.059948"], ["84240.77", "0.023729"], ["84240.73", "0.000233"], ["84240.41", "0.0002"], ["84240.2", "0.000233"], ["84239.01", "0.000237"], ["84238.07", "0.118629"], ["84238.04", "0.17795"], ["84237.98", "0.001467"]], "a": [["84293.5", "0.06027"], ["84294.5", "0"], ["84294.78", "0.000153"], ["84297.7", "0.001232"], ["84309.35", "0"], ["84309.84", "0"], ["84310.21", "0"], ["84312.53", "0"], ["84316.41", "0"], ["84316.47", "0.135355"], ["84317.59", "0"], ["84320.19", "0"], ["84320.28", "0"], ["84324.16", "0"], ["84324.19", "0.296556"], ["84325.33", "0"], ["84328.02", "0"], ["84330.26", "0"], ["84337.21", "0.04"], ["84337.22", "0.04"], ["84337.31", "0"], ["84337.32", "0"], ["84339.8", "0.000253"], ["84339.82", "0.059294"], ["84339.97", "0.001467"], ["84340.18", "0.023724"], ["84340.58", "0.023724"], ["84340.62", "0.059948"], ["84340.8", "0.023729"], ["84340.88", "0.000158"], ["84341.49", "0.023723"]], "u": 7510565, "seq": 66889273673}, "cts": 1742142209006, "record_time": 1742142208.108607}
{"topic": "orderbook.200.BTCUSDT", "ts": 1742142209210, "type": "delta", "data": {"s": "BTCUSDT", "b": [["84293.49", "0.346654"], ["84289.15", "0.003"], ["84284.9", "0.01244"], ["84284.89", "0"], ["84284.45", "0"], ["84284.22", "0"], ["84284.09", "0"], ["84281.82", "0"], ["84280.04", "0"], ["84278.77", "0.266107"], ["84275.51", "0"], ["84253.66", "0"], ["84246.41", "0.04"], ["84246.4", "0.039644"], ["84245.81", "0"], ["84245.8", "0"], ["84243.88", "0.355927"], ["84243.12", "0"], ["84239.64", "0.162"], ["84237.89", "0.0002"], ["84237.81", "0.023981"], ["84237.49", "0.000357"], ["84237.17", "0.001333"], ["84237.12", "0.000613"]], "a": [["84293.5", "0.040134"], ["84294.78", "0"], ["84297.7", "0.002195"], ["84309.58", "0.171633"], ["84309.71", "0"], ["84316.47", "0.083711"], ["84322.66", "0"], ["84324.19", "0"], ["84337.01", "0.04"], ["84337.02", "0.04"], ["84337.21", "0"], ["84337.22", "0"], ["84341.56", "0.0002"], ["84341.59", "0.037879"], ["84342.2", "0.000235"]], "u": 7510566, "seq": 66889273921}, "cts": 1742142209200, "record_time": 1742142208.309}
{"topic": "orderbook.200.BTCUSDT", "ts": 1742142209410, "type": "delta", "data": {"s": "BTCUSDT", "b": [["84285.65", "0.02"], ["84285.36", "0.02459"], ["84285.19", "0.02"], ["84284.9", "0"], ["84284.52", "0.02"], ["84284.39", "0.02"], ["84283.02", "0.02"], ["84281.79", "0.114775"], ["84281.51", "0.112679"], ["84280.18", "0.12042"], ["84279", "0.119808"], ["84275.63", "0.231257"], ["84273.94", "0.16374"], ["84273.71", "0.174047"], ["84271.2", "0.213689"], ["84266.14", "0.29452"], ["84265.92", "0.275973"], ["84263.4", "0.283545"], ["84262.04", "1.425371"], ["84260.74", "0.285562"], ["84246.42", "0.355926"], ["84243.88", "0"], ["84241.38", "0"], ["84241.34", "0"], ["84240.87", "0"], ["84240.77", "0"], ["84240.73", "0"], ["84240.41", "0"], ["84240.2", "0"], ["84239.64", "0"], ["84239.01", "0"], ["84238.07", "0"], ["84238.04", "0"], ["84237.98", "0"], ["84237.89", "0"], ["84237.81", "0"], ["84237.49", "0"], ["84237.17", "0"], ["84237.12", "0"]], "a": [["84293.5", "0.041645"], ["84297.7", "0"], ["84309.58", "0.09641"], ["84309.86", "0.114707"], ["84310.36", "0.108575"], ["84310.58", "0.113261"], ["84312.52", "0.108137"], ["84316.82", "0.166426"], ["84318.15", "0.181159"], ["84320.32", "0.173822"], ["84322.65", "0"], ["84324.62", "0.296406"], ["84325.95", "0.275931"], ["84330.91", "0.272298"], ["84340.62", "0"], ["84340.8", "0"], ["84340.88", "0"], ["84341.49", "0"], ["84341.56", "0"], ["84341.59", "0"], ["84342.2", "0"]], "u": 7510567, "seq": 66889274087}, "cts": 1742142209407, "record_time": 1742142208.509651}
{"topic": "orderbook.200.BTCUSDT", "ts": 1742142209610, "type": "delta", "data": {"s": "BTCUSDT", "b": [["84293.49", "0.217086"], ["84289.14", "0"], ["84285.9", "0.024617"], ["84285.89", "0.02"], ["84285.36", "0"], ["84285.22", "0.02"], ["84285.19", "0"], ["84285.09", "0.02"], ["84284.52", "0"], ["84284.39", "0"], ["84283.14", "0.019786"], ["84282.98", "0.237266"], ["84281.79", "0"], ["84281.59", "0"], ["84281.51", "0"], ["84281.19", "0.117475"], ["84280.91", "0.108719"], ["84280.38", "0"], ["84280.18", "0"], ["84280.16", "0"], ["84279.97", "0.107066"], ["84279", "0"], ["84278.97", "0"], ["84278.77", "0.503124"], ["84278.48", "0.015082"], ["84278.2", "0.116782"], ["84277.3", "0.000089"], ["84277.28", "0.000482"], ["84276.35", "0"], ["84276.27", "0.237315"], ["84275.95", "0"], ["84275.62", "0"], ["84274.58", "0.237319"], ["84273.94", "0"], ["84273.73", "0.166855"], ["84273.71", "0"], ["84273.12", "0.174052"], ["84272.91", "0.008453"], ["84271.58", "0.009849"], ["84271.2", "0.04"], ["84270.4", "0.174931"], ["84270.28", "0.173008"], ["84266.14", "0"], ["84265.93", "0.2728"], ["84265.92", "0"], ["84265.32", "0.28854"], ["84263.71", "0.018144"], ["84263.4", "0"], ["84262.6", "0.276211"], ["84262.05", "0.58343"], ["84260.74", "0"], ["84260.14", "0.264401"], ["84259.49", "0"], ["84259.1", "0"], ["84258.93", "0.014774"], ["84257.71", "0"], ["84253.67", "0"], ["84249.01", "0.071223"], ["84246.42", "0"], ["84246.41", "0"], ["84246.4", "0"], ["84246.11", "0.04"], ["84246.1", "0.039644"], ["84241.48", "0.2"], ["84241.38", "0.001333"], ["84241.34", "0.000614"]], "a": [["84294.33", "0.003221"], ["84295.02", "0.000153"], ["84297.7", "0.011862"], ["84299.98", "0.091738"], ["84302.32", "0.009847"], ["84306.76", "0"], ["84309.26", "0.111951"], ["84309.58", "0.217763"], ["84309.76", "0.107752"], ["84309.86", "0"], ["84310.36", "0"], ["84310.37", "0.107069"], ["84310.58", "0"], ["84311.72", "0.105575"], ["84312.52", "0"], ["84314.97", "0.01477"], ["84316.61", "0.160506"], ["84316.82", "0"], ["84317.56", "0.164181"], ["84318.15", "0"], ["84318.33", "0.03181"], ["84319.1", "0.071163"], ["84319.4", "0"], ["84319.52", "0.224211"], ["84320.18", "0.165425"], ["84320.32", "0"], ["84324.19", "0.008826"], ["84324.41", "0.276272"], ["84324.62", "0.023726"], ["84324.88", "0"], ["84325.23", "1.421676"], ["84325.35", "0.275497"], ["84325.95", "0"], ["84327.32", "0.29602"], ["84329.31", "0.086029"], ["84330.31", "0.281084"], ["84330.91", "0"], ["84331.87", "0"], ["84335.47", "0.029801"], ["84335.64", "0.474296"], ["84336.94", "0"], ["84337.01", "0"], ["84337.02", "0"], ["84337.11", "0.04"], ["84337.12", "0.04"], ["84338.99", "0"], ["84339.03", "0"], ["84339.07", "0"], ["84339.27", "0"], ["84339.8", "0"], ["84339.82", "0"], ["84339.97", "0"], ["84340.18", "0"], ["84340.58", "0"]], "u": 7510568, "seq": 66889274549}, "cts": 1742142209607, "record_time": 1742142208.709574}
{"topic": "orderbook.200.BTCUSDT", "ts": 1742142209810, "type": "delta", "data": {"s": "BTCUSDT", "b": [["84286.35", "0.02"], ["84285.65", "0"], ["84283.72", "0.02"], ["84283.14", "0.112696"], ["84283.02", "0"], ["84282.98", "0"], ["84281.22", "0.112368"], ["84281.19", "0"], ["84280.94", "0.106846"], ["84280.91", "0"], ["84280", "0.116232"], ["84279.97", "0"], ["84278.24", "0.113596"], ["84278.2", "0"], ["84278.11", "0.29764"], ["84277.5", "0.150749"], ["84277.28", "0.000233"], ["84275.95", "0.237266"], ["84273.77", "0.161688"], ["84273.73", "0"], ["84273.16", "0.237266"], ["84273.14", "0.175593"], ["84273.12", "0"], ["84271.74", "0.237266"], ["84270.45", "0.163747"], ["84270.4", "0"], ["84270.31", "0.178746"], ["84270.28", "0"], ["84265.97", "0.266018"], ["84265.93", "0"], ["84265.35", "0.299951"], ["84265.32", "0"], ["84262.65", "0.2953"], ["84262.6", "0"], ["84260.17", "0.26299"], ["84260.14", "0"], ["84259.28", "0.071214"], ["84259.1", "0.17795"], ["84249.01", "0"], ["84246.11", "0"], ["84246.1", "0"], ["84245.51", "0.04"], ["84245.5", "0.039645"], ["84241.48", "0"], ["84241.38", "0"], ["84241.34", "0"]], "a": [["84294.33", "0"], ["84299.98", "0"], ["84309.26", "0"], ["84309.29", "0.111286"], ["84309.76", "0"], ["84309.79", "0.110722"], ["84310.37", "0"], ["84310.41", "0.120538"], ["84311.72", "0"], ["84311.77", "0.110197"], ["84316.61", "0.000253"], ["84316.65", "0.176464"], ["84317.56", "0"], ["84317.59", "0.163854"], ["84318.33", "0"], ["84318.4", "0.222751"], ["84319.52", "0.059948"], ["84319.56", "0.179648"], ["84320.18", "0"], ["84320.21", "0.168199"], ["84324.4", "0.629062"], ["84324.41", "0"], ["84324.45", "0.290554"], ["84325.35", "0"], ["84325.38", "0.288776"], ["84327.32", "0"], ["84327.36", "0.269736"], ["84328.16", "0.03181"], ["84330.31", "0"], ["84330.34", "0.292104"], ["84337.11", "0"], ["84337.12", "0"], ["84337.51", "0.04"], ["84337.52", "0.04"], ["84338.79", "0"], ["84338.84", "0"]], "u": 7510569, "seq": 66889274763}, "cts": 1742142209805, "record_time": 1742142208.910523}
{"topic": "orderbook.200.BTCUSDT", "ts": 1742142210010, "type": "delta", "data": {"s": "BTCUSDT", "b": [["84287.06", "0.024747"], ["84287.05", "0.02"], ["84286.59", "0.02"], ["84286.35", "0"], ["84285.92", "0.0202"], ["84285.9", "0"], ["84285.89", "0"], ["84285.79", "0.02"], ["84285.22", "0"], ["84285.09", "0"], ["84284.42", "0.02"], ["84283.72", "0"], ["84283.14", "0.083158"], ["84281.22", "0"], ["84281.17", "0.118581"], ["84280.94", "0"], ["84280.88", "0.118405"], ["84280", "0"], ["84279.94", "0.112654"], ["84278.78", "0.456518"], ["84278.77", "0.237266"], ["84278.24", "0"], ["84278.23", "0.10615"], ["84275.63", "0.451384"], ["84273.77", "0"], ["84273.68", "0.170653"], ["84273.14", "0"], ["84273.06", "0.158909"], ["84271.74", "0"], ["84270.45", "0"], ["84270.4", "0.167204"], ["84270.31", "0"], ["84270.21", "0.172786"], ["84265.97", "0"], ["84265.86", "0.293754"], ["84265.35", "0"], ["84265.23", "0.272594"], ["84262.65", "0"], ["84262.57", "0.299719"], ["84260.17", "0"], ["84260.03", "0.276032"], ["84248.94", "0.11863"], ["84243.88", "0.355925"], ["84241.93", "0"]], "a": [["84309.29", "0"], ["84309.35", "0.106997"], ["84309.79", "0"], ["84309.85", "0.1196"], ["84310.41", "0"], ["84310.47", "0.112977"], ["84311.77", "0"], ["84311.88", "0.114799"], ["84316.47", "0.175343"], ["84316.48", "0"], ["84316.65", "0"], ["84316.73", "0.15799"], ["84317.59", "0"], ["84317.67", "0.159348"], ["84317.79", "0.140107"], ["84319", "0"], ["84319.56", "0"], ["84319.71", "0.167875"], ["84320.21", "0"], ["84320.3", "0.177108"], ["84324.45", "0"], ["84324.56", "0.275655"], ["84325.38", "0"], ["84325.5", "0.294429"], ["84327.36", "0"], ["84327.54", "0.289788"], ["84328.16", "0"], ["84330.34", "0"], ["84330.48", "0.287776"], ["84335.47", "0"], ["84338.79", "0.000357"], ["84338.99", "0.000089"], ["84339.03", "0.0002"], ["84339.07", "0.0045"]], "u": 7510570, "seq": 66889274908}, "cts": 1742142210001, "record_time": 1742142209.109018}
{"topic": "orderbook.200.BTCUSDT", "ts": 1742142210210, "type": "delta", "data": {"s": "BTCUSDT", "b": [["84289.34", "0.071189"], ["84287.05", "0"], ["84286.59", "0"], ["84285.92", "0.0002"], ["84285.79", "0"], ["84284.42", "0"], ["84283.14", "0.145666"], ["84280.16", "0.237266"], ["84278.79", "0.059948"], ["84277.8", "0.001725"], ["84277.5", "0.1505"], ["84245.52", "0.355917"], ["84243.88", "0"], ["84241.93", "0.02357"]], "a": [["84293.5", "0.040134"], ["84297.7", "0"], ["84299.99", "0"], ["84338.84", "0.162"], ["84339.27", "0.0045"]], "u": 7510571, "seq": 66889274990}, "cts": 1742142210206, "record_time": 1742142209.310078}
{"topic": "orderbook.200.BTCUSDT", "ts": 1742142210409, "type": "delta", "data": {"s": "BTCUSDT", "b": [["84293.49", "0.379931"], ["84289.34", "0"], ["84288.08", "0.065103"], ["84288.07", "0.11234"], ["84287.25", "0.02"], ["84287.06", "0"], ["84286.79", "0.02"], ["84286.12", "0.02"], ["84285.99", "0.02"], ["84284.42", "0.02"], ["84283.14", "0.143603"], ["84282.55", "0.106485"], ["84282.27", "0.117117"], ["84281.17", "0"], ["84280.88", "0"], ["84280.5", "0.10878"], ["84279.94", "0"], ["84278.33", "0.000449"], ["84278.23", "0"], ["84278.11", "0.06033"], ["84277.8", "0.001476"], ["84276.72", "0.010149"], ["84276.27", "0"], ["84274.58", "0"], ["84274.44", "0.17097"], ["84273.68", "0"], ["84273.06", "0"], ["84272.67", "0.159028"], ["84271.6", "0.173549"], ["84271.58", "0"], ["84270.4", "0"], ["84270.21", "0"], ["84266.62", "0.272278"], ["84265.86", "0"], ["84265.35", "0.071209"], ["84265.23", "0"], ["84264.85", "0.275651"], ["84264.08", "0.015224"], ["84262.57", "0"], ["84261.42", "0.264979"], ["84260.03", "0"], ["84258.93", "0"], ["84257.63", "0.023726"], ["84252.45", "0"], ["84251.67", "0.023726"], ["84249.32", "0.355902"], ["84245.52", "0"], ["84241.98", "0"], ["84241.93", "0"]], "a": [["84293.5", "0.001511"], ["84294.2", "0"], ["84295.02", "0"], ["84300.02", "0.07118"], ["84300.23", "0"], ["84302.32", "0"], ["84303.77", "0"], ["84306.57", "0"], ["84306.58", "0"], ["84306.72", "0.010162"], ["84307.79", "0.11863"], ["84309.35", "0"], ["84309.42", "0"], ["84309.85", "0"], ["84310.47", "0"], ["84310.73", "0.108985"], ["84310.89", "0"], ["84311.23", "0.113075"], ["84311.88", "0"], ["84312.73", "0.008453"], ["84312.9", "0"], ["84313.4", "0"], ["84314.16", "0.117015"], ["84314.6", "0"], ["84314.97", "0"], ["84315.42", "0"], ["84316.7", "0.068395"], ["84316.73", "0"], ["84317.67", "0"], ["84318.74", "0.369995"], ["84319.06", "0.176635"], ["84319.1", "0"], ["84319.37", "0.015244"], ["84319.7", "0.068"], ["84319.71", "0"], ["84320", "0.000113"], ["84320.3", "0"], ["84321.69", "0.162191"], ["84321.99", "0.1646"], ["84324.56", "0"], ["84325.5", "0"], ["84326.51", "0"], ["84326.89", "0.267345"], ["84327.54", "0"], ["84329.31", "0"], ["84329.81", "0.265932"], ["84330.48", "0.000089"], ["84330.72", "0"], ["84331.87", "0.292134"], ["84332.65", "0.071152"], ["84339.8", "0.000253"], ["84339.97", "0.001467"], ["84340.18", "0.023724"], ["84340.58", "0.023724"], ["84340.62", "0.059948"], ["84340.8", "0.023729"], ["84340.88", "0.000158"], ["84341.49", "0.023723"], ["84341.56", "0.0002"], ["84341.59", "0.037879"], ["84342.2", "0.000235"], ["84342.46", "0.237306"], ["84342.49", "0.000612"], ["84342.53", "0.001333"]], "u": 7510572, "seq": 66889275438}, "cts": 1742142210408, "record_time": 1742142209.509131}
{"topic": "orderbook.200.BTCUSDT", "ts": 1742142210609, "type": "delta", "data": {"s": "BTCUSDT", "b": [["84296.14", "0.433254"], ["84296.1", "0.004744"], ["84295.49", "0.064659"], ["84295.48", "0.03"], ["84294.64", "0.0172"], ["84293.5", "0.0002"], ["84293.49", "0.096548"], ["84292.9", "0.071186"], ["84292.65", "0"], ["84291.9", "0.000613"], ["84291.19", "0.000233"], ["84290.35", "0"], ["84290.34", "0"], ["84288.08", "0.106281"], ["84287.72", "0.017063"], ["84287.71", "0.0005"], ["84287.35", "0.02"], ["84287.25", "0"], ["84287.19", "0.237259"], ["84286.22", "0.02"], ["84286.12", "0"], ["84285.06", "0"], ["84284.62", "0.02"], ["84284.42", "0"], ["84284.38", "0.237259"], ["84283.43", "0.01508"], ["84283.14", "0.084965"], ["84282.98", "0.032365"], ["84282.55", "0"], ["84282.27", "0"], ["84281.92", "0"], ["84281.78", "0.010195"], ["84281.5", "0.04"], ["84281.3", "0.04"], ["84280.5", "0"], ["84278.78", "0"], ["84278.77", "0"], ["84278.48", "0"], ["84278.33", "0.0002"], ["84278.11", "0.060579"], ["84277.75", "0.217925"], ["84277.74", "0.089922"], ["84277.5", "0"], ["84276.72", "0"], ["84275.95", "0"], ["84275", "0.08"], ["84274.5", "0.04"], ["84274.44", "0"], ["84272.67", "0"], ["84271.6", "0"], ["84271.57", "0"], ["84269.14", "0.015292"], ["84266.63", "0.298964"], ["84266.62", "0"], ["84265.26", "0"], ["84264.85", "0"], ["84264.08", "0"], ["84262.57", "0.071211"], ["84261.42", "0"], ["84259.28", "0"], ["84257.71", "0.072812"], ["84254.53", "0.11863"], ["84250.14", "0.11"], ["84249.32", "0"], ["84248.08", "0.35591"], ["84242.61", "0"], ["84242.44", "0"]], "a": [["84293.5", "0"], ["84295.49", "0"], ["84295.82", "0"], ["84296.03", "0"], ["84296.11", "0"], ["84296.15", "0.00403"], ["84296.4", "0"], ["84298.56", "0.032839"], ["84300.02", "0"], ["84301.93", "0"], ["84303.92", "0.0005"], ["84304.95", "0"], ["84305.63", "0"], ["84308.03", "0.020996"], ["84309.58", "0"], ["84310.73", "0"], ["84311.23", "0"], ["84311.78", "0"], ["84311.81", "0.044222"], ["84314.16", "0"], ["84315.79", "0"], ["84316.47", "0.083711"], ["84317.78", "0.023319"], ["84318.6", "0.044"], ["84318.79", "0.0002"], ["84318.81", "0.004746"], ["84319", "0.06"], ["84319.06", "0"], ["84321.2", "0.06"], ["84321.38", "0"], ["84321.44", "0.162"], ["84321.69", "0"], ["84321.99", "0"], ["84323.07", "0.017796"], ["84324.4", "0"], ["84325.22", "0.448985"], ["84325.3", "0.048"], ["84325.6", "0"], ["84325.7", "0.048"], ["84326.07", "0.071158"], ["84326.89", "0"], ["84329.03", "0"], ["84329.81", "0"], ["84330.72", "0.237259"], ["84331.87", "0"], ["84332.15", "0.237266"], ["84333.52", "0.237259"], ["84334.93", "0.237259"], ["84335.64", "0"], ["84337.51", "0"], ["84337.52", "0"], ["84337.73", "0.237259"], ["84340.4", "0.026414"], ["84340.71", "0.04"], ["84340.72", "0.04"], ["84341.59", "0"], ["84342.72", "0.000235"], ["84342.79", "0.023724"], ["84343.72", "0.089922"], ["84344.09", "0.0002"], ["84344.44", "0.000253"], ["84344.61", "0.001467"], ["84345.62", "0.059134"], ["84345.75", "0.001308"]], "u": 7510573, "seq": 66889276386}, "cts": 1742142210608, "record_time": 1742142209.70924}
{"topic": "orderbook.200.BTCUSDT", "ts": 1742142210809, "type": "delta", "data": {"s": "BTCUSDT", "b": [["84302.86", "0.254332"], ["84298.56", "0.0002"], ["84298.06", "0.000252"], ["84297.61", "0.000964"], ["84296.16", "0.088558"], ["84296.14", "0.121501"], ["84296.11", "0.000613"], ["84296.1", "0"], ["84296.03", "0.0002"], ["84295.82", "0.000233"], ["84295.49", "0"], ["84295.31", "0.004369"], ["84295.02", "0.1379"], ["84294.64", "0"], ["84294.45", "0.089922"], ["84294.43", "0.0005"], ["84294.2", "0.000089"], ["84293.59", "0.001467"], ["84293.43", "0.000252"], ["84292.9", "0"], ["84291.94", "0.001333"], ["84291.71", "0.000233"], ["84290.3", "0.017457"], ["84289.63", "0"], ["84288.08", "0"], ["84288.07", "0"], ["84287.72", "0.001333"], ["84287.71", "0"], ["84287.35", "0"], ["84287.19", "0"], ["84286.79", "0"], ["84286.58", "0.010306"], ["84286.22", "0"], ["84285.99", "0"], ["84284.62", "0"], ["84284.38", "0"], ["84284.2", "0.162"], ["84283.43", "0"], ["84283.13", "0.015079"], ["84282.98", "0"], ["84281.91", "0.000233"], ["84281.78", "0"], ["84281.68", "0.009039"], ["84281.5", "0.040249"], ["84281.02", "0.06032"], ["84280.16", "0.23724"], ["84279.8", "0.04"], ["84279.7", "0.04"], ["84279.59", "0.068395"], ["84279.22", "0.11862"], ["84278.37", "0.118629"], ["84278.11", "0"], ["84278", "0.048"], ["84277.9", "0.04"], ["84277.75", "0.098551"], ["84276.94", "0"], ["84276.43", "0.020619"], ["84276.3", "0.08"], ["84275.63", "0.231257"], ["84275.5", "0"], ["84275.23", "0.009054"], ["84275", "0.04"], ["84273.93", "0.015459"], ["84273.7", "0"], ["84273.16", "0"], ["84271.9", "0"], ["84271.66", "0.071204"], ["84271.4", "0"], ["84271.2", "0"], ["84270.1", "0"], ["84269.7", "0"], ["84269.14", "0"], ["84268.84", "0.023724"], ["84268.7", "0"], ["84267.8", "0"], ["84266.63", "0"], ["84264.3", "0"], ["84263.71", "0"], ["84263.27", "0"], ["84262.58", "0.474492"], ["84262.57", "0"], ["84262.56", "0.00593"], ["84259.1", "0"], ["84257.71", "0"], ["84257.22", "0.237368"], ["84254.67", "0.023725"], ["84248.3", "0.24702"], ["84248.08", "0"], ["84246.89", "0.024201"], ["84245.99", "0.000989"], ["84243.36", "0"], ["84243.23", "0"], ["84242.94", "0"], ["84242.79", "0"]], "a": [["84296.15", "0"], ["84296.35", "0"], ["84297.36", "0"], ["84298.06", "0"], ["84298.23", "0"], ["84298.56", "0"], ["84298.6", "0"], ["84300", "0"], ["84300.33", "0"], ["84300.37", "0"], ["84300.46", "0"], ["84300.98", "0"], ["84301.09", "0"], ["84302.7", "0"], ["84306.72", "0"], ["84307.79", "0"], ["84307.8", "0"], ["84308.03", "0"], ["84311.81", "0"], ["84312.08", "0"], ["84312.73", "0"], ["84313.34", "0"], ["84313.46", "0.028442"], ["84313.51", "0.020996"], ["84314.9", "0.028289"], ["84315.6", "0.054408"], ["84315.61", "0.083985"], ["84316.19", "0.010307"], ["84316.47", "0"], ["84316.58", "0"], ["84316.7", "0"], ["84317.07", "0"], ["84317.78", "0"], ["84317.79", "0"], ["84318.4", "0"], ["84318.6", "0"], ["84318.74", "0.222757"], ["84318.8", "0"], ["84318.81", "0"], ["84319.37", "0"], ["84319.52", "0"], ["84319.7", "0"], ["84319.72", "0.000989"], ["84320.4", "0"], ["84321.12", "0.008453"], ["84321.2", "0"], ["84321.44", "0"], ["84323.72", "0"], ["84324.19", "0"], ["84324.61", "0"], ["84324.62", "0"], ["84324.94", "0.020609"], ["84325.3", "0"], ["84325.7", "0"], ["84326.07", "0"], ["84326.22", "0.068395"], ["84326.47", "0"], ["84327.93", "0.275583"], ["84327.94", "0"], ["84328.06", "0"], ["84328.84", "0.015461"], ["84330.39", "0.11862"], ["84330.72", "0"], ["84331.1", "0"], ["84331.19", "0.024141"], ["84332.15", "0"], ["84332.65", "0"], ["84332.99", "0.000759"], ["84333.52", "0"], ["84334.07", "0"], ["84334.93", "0"], ["84335.26", "0.07115"], ["84335.3", "0"], ["84337.73", "0"], ["84340.39", "0.03181"], ["84340.71", "0"], ["84340.72", "0"], ["84346.15", "0.023724"], ["84346.23", "0.06093"], ["84346.31", "0.352449"], ["84346.41", "0.04"], ["84346.42", "0.04"], ["84346.62", "0.0002"], ["84346.7", "0.000612"], ["84346.75", "0.001333"], ["84346.84", "0.002519"], ["84347.03", "0.001"], ["84347.36", "0.000235"], ["84347.48", "0.43153"], ["84347.5", "0.000089"], ["84348.18", "0.237306"], ["84349.08", "0.000253"], ["84349.15", "0.0002"], ["84349.25", "0.001467"], ["84350", "0.021512"], ["84350.37", "0.0045"], ["84350.5", "0.0045"], ["84350.57", "0.0045"], ["84350.7", "0.0045"], ["84350.92", "0.000612"], ["84350.96", "0.001333"], ["84351.48", "0.000235"], ["84351.68", "0.0002"], ["84352", "0.000235"], ["84352.17", "0.00593"], ["84352.66", "0.00089"], ["84353.22", "0.17795"], ["84353.24", "0.118791"], ["84353.6", "0.246059"], ["84353.72", "0.000253"], ["84353.89", "0.001467"], ["84354.92", "0.00109"], ["84355.14", "0.000612"], ["84355.18", "0.001333"], ["84356.01", "0.00009"], ["84356.12", "0.000235"], ["84356.64", "0.000235"], ["84357.02", "0.000085"], ["84357.07", "0.023729"], ["84357.47", "0.059948"], ["84358.07", "0.000335"]], "u": 7510574, "seq": 66889277789}, "cts": 1742142210808, "record_time": 1742142209.908963}
{"topic": "orderbook.200.BTCUSDT", "ts": 1742142211010, "type": "delta", "data": {"s": "BTCUSDT", "b": [["84302.86", "0.847581"], ["84302.03", "0.011862"], ["84302.02", "0.0171"], ["84301.26", "0.021808"], ["84299.18", "0.07118"], ["84299", "0.000099"], ["84298.65", "0.004369"], ["84296.16", "0.33031"], ["84295.31", "0"], ["84295.24", "0.237261"], ["84294.45", "0"], ["84294.43", "0.044225"], ["84293.55", "0.237266"], ["84292", "0.146653"], ["84291.55", "0.015078"], ["84291.4", "0.090542"], ["84290.3", "0"], ["84290", "0.04"], ["84289.99", "0.008453"], ["84289.84", "0.000793"], ["84289.75", "0.02"], ["84289.7", "0.04"], ["84289.45", "0.060313"], ["84288.52", "0.02"], ["84288.3", "0.04"], ["84288.1", "0.04"], ["84287.72", "0.021333"], ["84287.59", "0.02"], ["84286.52", "0.02"], ["84285.8", "0.23724"], ["84285.14", "0.166088"], ["84284.8", "0.08"], ["84284.21", "0.0486"], ["84283.4", "0.04"], ["84283.13", "0"], ["84283", "0.04"], ["84282.32", "0.163733"], ["84281.59", "0.23724"], ["84281.5", "0"], ["84281.02", "0"], ["84280.16", "0"], ["84279.22", "0"], ["84279.2", "0.018396"], ["84278.37", "0"], ["84277.38", "0"], ["84276.3", "0.04"], ["84275.63", "0"], ["84275", "0"], ["84274.5", "0"], ["84273.5", "0"], ["84272.91", "0"], ["84272.22", "0.283889"], ["84268.84", "0"], ["84268.32", "0.071206"], ["84265.35", "0"], ["84262.93", "0.003482"], ["84262.58", "0.11863"], ["84258.44", "0.004655"], ["84254.54", "0.355886"], ["84252.49", "0"], ["84248.3", "0"], ["84245.99", "0"], ["84245.87", "0"], ["84245.86", "0"], ["84245.7", "0"], ["84245.59", "0"], ["84245.55", "0"], ["84245.51", "0"], ["84245.5", "0"], ["84245.47", "0"], ["84245.36", "0"], ["84245.1", "0"], ["84245", "0"], ["84244.84", "0"], ["84244.25", "0"], ["84243.87", "0"], ["84243.5", "0"]], "a": [["84302.87", "0.004129"], ["84304.52", "0.071176"], ["84306.73", "0.000099"], ["84309.6", "0.000211"], ["84313.46", "0.000089"], ["84313.51", "0"], ["84314.37", "0.028588"], ["84315.6", "0.031353"], ["84316.8", "0.020996"], ["84318.73", "0.059948"], ["84318.74", "0.085456"], ["84319", "0"], ["84323.4", "0.044"], ["84326.2", "0.06"], ["84327.5", "0.044"], ["84327.7", "0.068"], ["84330.39", "0"], ["84330.5", "0.116"], ["84331.1", "0.056"], ["84332.5", "0.065796"], ["84333.09", "0.003539"], ["84333.27", "0.071151"], ["84333.35", "0.008931"], ["84333.8", "0.023724"], ["84335.26", "0"], ["84336.37", "0.23724"], ["84336.55", "0"], ["84338.26", "0.254831"], ["84338.27", "0.362488"], ["84338.96", "0.071147"], ["84340.39", "0"], ["84340.58", "0.260964"], ["84340.8", "0"], ["84342.11", "0.279787"], ["84346.31", "0"], ["84346.41", "0"], ["84346.42", "0"], ["84347.28", "0.162"], ["84348.81", "0.04"], ["84348.82", "0.04"], ["84350.5", "0"], ["84350.7", "0"], ["84353.59", "0.35588"], ["84353.89", "0"], ["84354.92", "0"], ["84355.14", "0"], ["84355.18", "0"], ["84356.01", "0"], ["84356.12", "0"], ["84356.64", "0"], ["84357.02", "0"], ["84357.07", "0"], ["84357.47", "0"], ["84358.07", "0"]], "u": 7510575, "seq": 66889278810}, "cts": 1742142211007, "record_time": 1742142210.109557}
{"topic": "orderbook.200.BTCUSDT", "ts": 1742142211209, "type": "delta", "data": {"s": "BTCUSDT", "b": [["84303.61", "0.158102"], ["84302.86", "0.199229"], ["84301.26", "0"], ["84299.18", "0"], ["84295.48", "0"], ["84293.9", "0.109136"], ["84293.62", "0.113213"], ["84292", "0.195736"], ["84291.83", "0.105839"], ["84291.68", "0.110476"], ["84291.4", "0"], ["84289.75", "0"], ["84288.6", "0.059948"], ["84288.59", "0.23724"], ["84288.52", "0"], ["84288.11", "0.218324"], ["84287.72", "0.001333"], ["84287.59", "0"], ["84286.52", "0"], ["84286.4", "0.048"], ["84286.3", "0.04"], ["84285.85", "0.160763"], ["84285.47", "0.157731"], ["84285.14", "0"], ["84284.21", "0"], ["84282.32", "0"], ["84281.3", "0"], ["84279.8", "0"], ["84279.7", "0"], ["84278.09", "0.265193"], ["84278", "0"], ["84277.9", "0"], ["84277.75", "0"], ["84276.3", "0.263033"], ["84272.22", "0"], ["84268.95", "0.17793"], ["84268.32", "0"], ["84262.04", "0"], ["84257.23", "0.355876"], ["84255.47", "0"], ["84254.54", "0"], ["84252.65", "0.000988"], ["84245.87", "0.023726"], ["84245.86", "0.000089"], ["84245.7", "0.005931"], ["84245.59", "0.001333"], ["84245.55", "0.000614"], ["84245.51", "0.04"]], "a": [["84302.87", "0"], ["84303.78", "0"], ["84303.79", "0"], ["84303.85", "0"], ["84304.52", "0"], ["84309.6", "0"], ["84313.46", "0"], ["84315.6", "0"], ["84318.73", "0"], ["84319.72", "0"], ["84321.85", "0.106946"], ["84321.97", "0.118389"], ["84322.35", "0.113483"], ["84325.22", "0.56479"], ["84325.7", "0.023371"], ["84326.46", "0.000988"], ["84328.18", "0.176613"], ["84329.5", "0.0606"], ["84330.11", "0.168152"], ["84332.72", "0.16685"], ["84332.99", "0.160294"], ["84337.88", "0.297527"], ["84338.26", "0"], ["84340.75", "0.288549"], ["84342.11", "0"], ["84342.82", "0.283022"], ["84353.59", "0"], ["84353.89", "0.001467"], ["84354.92", "0.00109"], ["84355.14", "0.000612"]], "u": 7510576, "seq": 66889279260}, "cts": 1742142211208, "record_time": 1742142210.309052}
{"topic": "orderbook.200.BTCUSDT", "ts": 1742142211410, "type": "delta", "data": {"s": "BTCUSDT", "b": [["84304.57", "0.258377"], ["84304.53", "0.007116"], ["84303.92", "0.039102"], ["84303.74", "0.011861"], ["84303.73", "0.0171"], ["84303.61", "0.101177"], ["84302.86", "0.00096"], ["84302.03", "0"], ["84302.02", "0"], ["84301.09", "0.0002"], ["84300.36", "0.00437"], ["84300.33", "0.000613"], ["84299", "0"], ["84298.65", "0"], ["84298.23", "0.001467"], ["84297.03", "0.071171"], ["84297.02", "0.237235"], ["84296.35", "0.000233"], ["84296.15", "0.001333"], ["84296.14", "0.119935"], ["84295.35", "0.105926"], ["84295.26", "0.015077"], ["84295.18", "0.0005"], ["84295.13", "0.060308"], ["84294.43", "0.043725"], ["84294", "0.04"], ["84293.9", "0"], ["84293.62", "0"], ["84292.8", "0.237235"], ["84292.36", "0.089922"], ["84292.1", "0.048"], ["84292", "0.04"], ["84291.83", "0"], ["84291.68", "0"], ["84291.55", "0"], ["84290.99", "0.02"], ["84290.98", "0.138731"], ["84290.97", "0.01067"], ["84290.95", "0.02"], ["84290.5", "0.059233"], ["84290.42", "0.02"], ["84290.29", "0.02"], ["84289.45", "0"], ["84289.27", "0.118618"], ["84289.14", "0.159908"], ["84288.77", "0.180265"], ["84288.59", "0"], ["84288.32", "0.02"], ["84288.3", "0"], ["84288.12", "0.347561"], ["84288.11", "0"], ["84287.83", "0.068395"], ["84286.58", "0"], ["84286.4", "0"], ["84286.3", "0"], ["84285.94", "0.162264"], ["84285.92", "0.00613"], ["84285.85", "0"], ["84285.47", "0"], ["84284.8", "0.04"], ["84281.59", "0"], ["84281.38", "0.269816"], ["84279.59", "0"], ["84278.33", "0.015905"], ["84278.09", "0"], ["84277.66", "0.071198"], ["84277.36", "0.023238"], ["84276.3", "0"], ["84275.85", "0.275205"], ["84274.71", "0.071201"], ["84273.93", "0"], ["84272.5", "1.417978"], ["84272.11", "0"], ["84271.66", "0"], ["84262.05", "0"], ["84260.03", "0.355866"], ["84257.86", "0"], ["84257.23", "0"], ["84255.6", "0.24702"], ["84254.31", "0.059031"], ["84252.93", "0.023937"], ["84249.31", "0"], ["84249", "0"], ["84248.94", "0"], ["84248.07", "0"], ["84248", "0"], ["84247.88", "0"], ["84247.35", "0"], ["84247.24", "0"], ["84247.08", "0"], ["84246.89", "0"], ["84245.87", "0"], ["84245.86", "0"], ["84245.7", "0"], ["84245.59", "0"], ["84245.55", "0"], ["84245.51", "0"]], "a": [["84303.62", "0"], ["84303.92", "0"], ["84304.54", "0"], ["84304.58", "0.003995"], ["84306.73", "0"], ["84310.26", "0.028605"], ["84311.31", "0.01186"], ["84312.05", "0.0005"], ["84312.49", "0.0005"], ["84314.37", "0.000235"], ["84314.9", "0.000235"], ["84315.61", "0"], ["84315.95", "0.029595"], ["84316.19", "0"], ["84316.8", "0"], ["84318.34", "0.027405"], ["84318.74", "0"], ["84320.59", "0.010482"], ["84321.68", "0.08398"], ["84321.85", "0"], ["84321.97", "0.000089"], ["84322.35", "0"], ["84323.07", "0"], ["84323.4", "0"], ["84324.04", "0"], ["84324.77", "0.109602"], ["84325.22", "0.448985"], ["84325.23", "0"], ["84325.27", "0.107781"], ["84325.64", "0.116178"], ["84325.7", "0"], ["84328.03", "0.023786"], ["84328.18", "0"], ["84328.68", "0.14009"], ["84328.84", "0"], ["84330.11", "0"], ["84330.41", "0"], ["84330.5", "0.068"], ["84331.19", "0"], ["84331.85", "0.177699"], ["84331.91", "0.004604"], ["84332.49", "0.236243"], ["84332.72", "0"], ["84332.76", "0"], ["84332.99", "0.000759"], ["84333.03", "0.16314"], ["84333.23", "0.015724"], ["84333.27", "0"], ["84333.35", "0"], ["84333.8", "0"], ["84335.49", "0.017796"], ["84335.64", "0.166701"], ["84336.37", "0"], ["84336.44", "0.008679"], ["84337", "0.005"], ["84337.21", "0.009328"], ["84337.77", "0.02384"], ["84337.88", "0"], ["84339.1", "0.118618"], ["84339.48", "0.023724"], ["84339.61", "0.282342"], ["84340.75", "0"], ["84340.8", "0.299785"], ["84342.4", "0.071144"], ["84342.82", "0"], ["84343.29", "0.266671"], ["84344.23", "1.458835"], ["84345.62", "0"], ["84345.74", "0.301662"], ["84345.75", "0"], ["84346.15", "0.037535"], ["84348.81", "0"], ["84348.82", "0"], ["84354.21", "0.0402"], ["84354.22", "0.04"], ["84355.18", "0.001333"], ["84356.01", "0.00009"]], "u": 7510577, "seq": 66889280588}, "cts": 1742142211407, "record_time": 1742142210.509595}
{"topic": "orderbook.200.BTCUSDT", "ts": 1742142211610, "type": "delta", "data": {"s": "BTCUSDT", "b": [["84303.92", "0.036656"], ["84300.71", "0.000099"], ["84296.16", "0.499228"], ["84295.7", "0.04"], ["84295.4", "0.04"], ["84295.35", "0"], ["84293.8", "0.04"], ["84291.55", "0.02"], ["84290.98", "0.205531"], ["84290.95", "0"], ["84290.5", "0.099233"], ["84290.02", "0.237235"], ["84290", "0"], ["84289.14", "0"], ["84289.1", "0.04"], ["84288.92", "0.02"], ["84288.77", "0"], ["84288.7", "0.04"], ["84288.32", "0"], ["84288.12", "0"], ["84285.94", "0"], ["84284.8", "0"], ["84283.4", "0"], ["84283", "0"], ["84281.38", "0"], ["84275.85", "0"], ["84267.73", "0.003393"], ["84260.04", "0.355864"], ["84260.03", "0"], ["84249.31", "0.059948"], ["84249", "0.035598"], ["84248.94", "0.11863"]], "a": [["84307.87", "0.071173"], ["84308.44", "0.000099"], ["84310.26", "0.000235"], ["84311.31", "0.007214"], ["84318.74", "0.104612"], ["84322.41", "0.020995"], ["84324.77", "0"], ["84325.22", "0.106841"], ["84325.27", "0"], ["84325.64", "0"], ["84329.8", "0.044"], ["84331.18", "0.004746"], ["84331.85", "0"], ["84332.49", "0"], ["84333.03", "0"], ["84333.36", "0.071151"], ["84335.64", "0"], ["84336.37", "0.237235"], ["84336.8", "0.048"], ["84339.61", "0"], ["84340.8", "0"], ["84342.4", "0"], ["84343.29", "0"], ["84343.36", "0.237235"], ["84345.74", "0"], ["84347.57", "0.237235"], ["84355.72", "0.162"]], "u": 7510578, "seq": 66889280859}, "cts": 1742142211603, "record_time": 1742142210.709042}
{"topic": "orderbook.200.BTCUSDT", "ts": 1742142211810, "type": "delta", "data": {"s": "BTCUSDT", "b": [["84304.57", "0.261377"], ["84296.2", "0.118371"], ["84295.92", "0.119559"], ["84289.7", "0"], ["84288.18", "0.16404"], ["84288.1", "0"], ["84287.84", "0.143321"], ["84283.14", "0"], ["84280.44", "0.287112"], ["84275.3", "0.294278"], ["84267.84", "0.11"], ["84262.93", "0"], ["84260.05", "0.355868"], ["84260.04", "0"], ["84254.37", "0.000988"], ["84252.65", "0"], ["84249.31", "0"], ["84249", "0"], ["84248.94", "0"]], "a": [["84308.44", "0"], ["84311.31", "0.002357"], ["84317.38", "0.000153"], ["84324.56", "0.117833"], ["84325.22", "0.039654"], ["84326.46", "0"], ["84326.93", "0.111592"], ["84328.18", "0.000988"], ["84328.68", "0"], ["84331.18", "0"], ["84331.19", "0.004746"], ["84332.3", "0.175558"], ["84334.9", "0.158667"], ["84340.04", "0.265025"], ["84355.14", "0"], ["84355.18", "0"], ["84355.72", "0"], ["84356.01", "0"]], "u": 7510579, "seq": 66889281050}, "cts": 1742142211806, "record_time": 1742142210.909609}
{"topic": "orderbook.200.BTCUSDT", "ts": 1742142212009, "type": "delta", "data": {"s": "BTCUSDT", "b": [["84304.57", "0.190717"], ["84303.92", "0.021869"], ["84303.61", "0.03"], ["84301.38", "0.071178"], ["84296.2", "0"], ["84295.92", "0"], ["84292.36", "0"], ["84292.25", "0.02"], ["84291.55", "0"], ["84290.99", "0"], ["84290.42", "0"], ["84290.39", "0.02"], ["84290.29", "0"], ["84289.72", "0.02"], ["84289.62", "0.02"], ["84289.49", "0.02"], ["84288.99", "0"], ["84288.97", "0.0001"], ["84288.92", "0"], ["84288.18", "0"], ["84280.44", "0"], ["84277.36", "0"], ["84275.3", "0"], ["84273.49", "0.474193"], ["84267.84", "0"], ["84260.05", "0"], ["84257.23", "0.355874"], ["84250.99", "0"], ["84250.97", "0.0013"], ["84249.31", "0.059948"], ["84249", "0.035598"], ["84248.94", "0.11863"], ["84248", "0.0002"], ["84247.88", "0.17795"], ["84247.35", "0.216033"]], "a": [["84305.62", "0.028608"], ["84305.82", "0.071175"], ["84306.45", "0.000153"], ["84307.87", "0"], ["84308.36", "0.000099"], ["84311.31", "0.003601"], ["84311.68", "0.0006"], ["84317.38", "0"], ["84324.55", "0.081186"], ["84324.56", "0"], ["84325.22", "0"], ["84326.93", "0"], ["84328.03", "0"], ["84328.06", "0.023338"], ["84329.9", "0.162"], ["84330.81", "0.140087"], ["84331.19", "0"], ["84332.29", "0.188951"], ["84332.3", "0"], ["84334.4", "0"], ["84334.9", "0"], ["84340.04", "0"], ["84349.68", "0.0013"], ["84355.14", "0.000612"]], "u": 7510580, "seq": 66889281325}, "cts": 1742142212006, "record_time": 1742142211.108995}
{"topic": "orderbook.200.BTCUSDT", "ts": 1742142212210, "type": "delta", "data": {"s": "BTCUSDT", "b": [["84304.57", "0.261377"], ["84303.92", "0.036656"], ["84300.36", "0.006774"], ["84296.14", "0.120435"], ["84295.18", "0"], ["84294.9", "0.105233"], ["84294.62", "0.114433"], ["84292.65", "0.108688"], ["84292.47", "0.11584"], ["84292.25", "0"], ["84292.15", "0.02"], ["84291.59", "0.02"], ["84290.92", "0.02"], ["84290.79", "0.02"], ["84290.39", "0"], ["84289.72", "0"], ["84289.62", "0"], ["84289.49", "0"], ["84289.42", "0.02"], ["84286.88", "0.170416"], ["84286.46", "0.173959"], ["84284.73", "0.162941"], ["84284.06", "0.158023"], ["84279.14", "0.284652"], ["84278.77", "0.090987"], ["84278.72", "0.273949"], ["84276.99", "0.272581"], ["84274", "0.280921"], ["84257.23", "0"], ["84254.54", "0.355885"], ["84250.14", "0"], ["84250", "0"], ["84249.8", "0"], ["84249.76", "0"], ["84249.5", "0"], ["84249.47", "0"], ["84249.31", "0"], ["84249", "0"], ["84248.94", "0"], ["84248", "0"], ["84247.88", "0"], ["84247.35", "0"]], "a": [["84306.45", "0"], ["84308.79", "0.001302"], ["84309.76", "0.023722"], ["84309.77", "0.011861"], ["84309.83", "0.011857"], ["84311.31", "0.01186"], ["84312.05", "0"], ["84313.01", "0.0005"], ["84322.76", "0.114693"], ["84322.84", "0.106557"], ["84323.26", "0.115053"], ["84324.55", "0.045836"], ["84325.75", "0.114474"], ["84329.03", "0.157805"], ["84331", "0.158085"], ["84331.18", "0.004745"], ["84332.29", "0"], ["84333.49", "0.166288"], ["84333.6", "0.166974"], ["84336.77", "0.263593"], ["84338.74", "0.281494"], ["84341.23", "0.266295"], ["84343.66", "0.280007"], ["84350.96", "0"], ["84351.48", "0"], ["84351.68", "0"], ["84352", "0"], ["84352.17", "0"], ["84352.66", "0"], ["84353.22", "0"], ["84353.24", "0"], ["84353.6", "0"], ["84353.72", "0"], ["84353.89", "0"], ["84354.21", "0"], ["84354.22", "0"], ["84354.92", "0"], ["84355.14", "0"]], "u": 7510581, "seq": 66889281585}, "cts": 1742142212199, "record_time": 1742142211.309884}
{"topic": "orderbook.200.BTCUSDT", "ts": 1742142212409, "type": "delta", "data": {"s": "BTCUSDT", "b": [["84303.74", "0"], ["84294.9", "0"], ["84294.74", "0.114735"], ["84294.62", "0"], ["84294.47", "0.119202"], ["84292.65", "0"], ["84292.48", "0.02"], ["84292.47", "0"], ["84292.44", "0.107479"], ["84292.35", "0.107406"], ["84291.92", "0.02"], ["84291.59", "0"], ["84291.49", "0.02"], ["84290.92", "0"], ["84290.79", "0"], ["84287.84", "0.2776"], ["84286.88", "0"], ["84286.73", "0.167421"], ["84286.46", "0"], ["84286.24", "0.164923"], ["84284.73", "0"], ["84284.61", "0.16312"], ["84284.06", "0"], ["84283.91", "0.172318"], ["84280.16", "0.177926"], ["84279.62", "0.773762"], ["84279.14", "0"], ["84278.99", "0.283439"], ["84278.72", "0"], ["84278.5", "0.285697"], ["84276.99", "0"], ["84276.87", "0.284588"], ["84274", "0"], ["84273.85", "0.29176"], ["84260.31", "0.04"], ["84260.3", "0.039641"], ["84259.1", "0.090887"], ["84255.61", "0.35588"], ["84254.54", "0"], ["84251.45", "0"], ["84250.97", "0"], ["84250.87", "0"], ["84250.52", "0"]], "a": [["84308.79", "0"], ["84322.61", "0.117936"], ["84322.62", "0.12011"], ["84322.75", "0.181271"], ["84322.76", "0"], ["84322.84", "0"], ["84323.11", "0.112856"], ["84323.26", "0"], ["84324.55", "0"], ["84325.63", "0.106131"], ["84325.75", "0"], ["84328.82", "0.162946"], ["84329.03", "0"], ["84330.85", "0.162497"], ["84331", "0"], ["84333.37", "0.159768"], ["84333.45", "0.161325"], ["84333.49", "0"], ["84333.6", "0"], ["84336.56", "0.295553"], ["84336.77", "0"], ["84338.59", "0.292851"], ["84338.74", "0"], ["84341.11", "0.301014"], ["84341.23", "0"], ["84341.95", "0.133155"], ["84343.51", "0.271597"], ["84343.66", "0"], ["84350.37", "0"], ["84350.57", "0"], ["84350.96", "0.001333"], ["84351.48", "0.000235"], ["84351.68", "0.0002"]], "u": 7510582, "seq": 66889281844}, "cts": 1742142212407, "record_time": 1742142211.508886}
{"topic": "orderbook.200.BTCUSDT", "ts": 1742142212610, "type": "delta", "data": {"s": "BTCUSDT", "b": [["84303.92", "0.014787"], ["84301.38", "0"], ["84300.36", "0.011862"], ["84297.84", "0.004369"], ["84294.74", "0"], ["84294.47", "0"], ["84292.85", "0.02"], ["84292.48", "0"], ["84292.44", "0"], ["84292.35", "0"], ["84292.29", "0.02"], ["84292.15", "0"], ["84291.92", "0"], ["84291.72", "0.02"], ["84290.12", "0.02"], ["84289.42", "0"], ["84286.73", "0"], ["84286.24", "0"], ["84284.61", "0"], ["84283.91", "0"], ["84278.99", "0"], ["84278.5", "0"], ["84277.66", "0"], ["84277.19", "0.023708"], ["84276.87", "0"], ["84273.85", "0"], ["84268.09", "0.071207"], ["84260.31", "0"], ["84260.3", "0"], ["84260.11", "0.04"], ["84260.1", "0.039641"], ["84255.61", "0"], ["84254.54", "0.355879"], ["84254.51", "0"], ["84251.45", "0.003"], ["84250.97", "0.0013"], ["84250.87", "0.023726"], ["84250.52", "0.0002"], ["84250.14", "0.11"], ["84250", "0.000233"], ["84249.8", "0.001333"], ["84249.76", "0.000614"], ["84249.5", "0.001"], ["84249.47", "0.000233"], ["84249.31", "0.059948"], ["84248.94", "0.11863"]], "a": [["84308.79", "0.011861"], ["84315.94", "0.014858"], ["84316.14", "0.010956"], ["84318.34", "0"], ["84320.59", "0"], ["84322.6", "0.183147"], ["84322.61", "0"], ["84322.62", "0"], ["84322.75", "0"], ["84323.11", "0"], ["84325.63", "0"], ["84328.79", "0.016435"], ["84328.82", "0"], ["84330.85", "0"], ["84333.23", "0"], ["84333.37", "0"], ["84333.45", "0.000235"], ["84336.56", "0"], ["84338.59", "0"], ["84341.11", "0"], ["84343.51", "0"], ["84346.72", "0.474234"], ["84352", "0.000235"], ["84352.17", "0.00593"], ["84352.66", "0.00089"], ["84353.22", "0.17795"], ["84353.24", "0.118791"], ["84353.6", "0.246059"], ["84353.72", "0.000253"], ["84353.8", "0.04"], ["84353.81", "0.04"]], "u": 7510583, "seq": 66889282239}, "cts": 1742142212606, "record_time": 1742142211.7096}
{"topic": "orderbook.200.BTCUSDT", "ts": 1742142212809, "type": "delta", "data": {"s": "BTCUSDT", "b": [["84303.92", "0.033983"], ["84303.74", "0.003099"], ["84302.56", "0.071177"], ["84297.84", "0.00127"], ["84294.49", "0.111496"], ["84294.21", "0.119092"], ["84293.59", "0.021467"], ["84293.02", "0.02"], ["84292.79", "0.02"], ["84292.29", "0"], ["84292.18", "0.10878"], ["84292.09", "0.108018"], ["84291.72", "0"], ["84291.49", "0"], ["84287.84", "0.143321"], ["84286.47", "0.178386"], ["84285.89", "0.170872"], ["84284.44", "0.162543"], ["84283.65", "0.170361"], ["84281.69", "0.140083"], ["84281.59", "0.237235"], ["84278.73", "0.267687"], ["84278.15", "0.285705"], ["84276.7", "0.266461"], ["84273.59", "0.292828"], ["84268.26", "0.004746"], ["84264.46", "0"], ["84256.63", "0.355878"], ["84254.54", "0"], ["84254.52", "0"], ["84252.95", "0.2"], ["84251.88", "0"], ["84251.71", "0"], ["84251.67", "0"], ["84251.45", "0"], ["84250.97", "0"], ["84250.87", "0"], ["84250.52", "0"], ["84250.14", "0"], ["84250", "0"], ["84249.8", "0"], ["84249.76", "0"], ["84249.5", "0"], ["84249.47", "0"], ["84249.31", "0"], ["84248.94", "0"]], "a": [["84304.62", "0.000153"], ["84322.27", "0.108585"], ["84322.35", "0.113173"], ["84322.6", "0.046037"], ["84322.85", "0.106952"], ["84325.46", "0.105279"], ["84328.47", "0.161203"], ["84330.59", "0.173649"], ["84333.19", "0.170507"], ["84333.2", "0.165711"], ["84336.21", "0.296724"], ["84338.33", "0.298421"], ["84340.94", "0.267414"], ["84343.25", "0.26951"], ["84350.96", "0"], ["84351.48", "0"], ["84351.68", "0"], ["84352", "0"], ["84352.17", "0"], ["84352.66", "0"], ["84353.22", "0"], ["84353.24", "0"], ["84353.6", "0"], ["84353.72", "0"], ["84353.8", "0"], ["84353.81", "0"]], "u": 7510584, "seq": 66889282405}, "cts": 1742142212808, "record_time": 1742142211.908902}
{"topic": "orderbook.200.BTCUSDT", "ts": 1742142213009, "type": "delta", "data": {"s": "BTCUSDT", "b": [["84294.15", "0.02"], ["84292.85", "0"], ["84291.42", "0.02"], ["84290.12", "0"], ["84287.84", "0.278946"], ["84281.59", "0"], ["84279.63", "0.575189"], ["84272.5", "0"], ["84260.61", "0.04"], ["84260.6", "0.039641"], ["84260.11", "0"], ["84260.1", "0"], ["84259.34", "0.11"], ["84256.63", "0"], ["84252.96", "0.355884"]], "a": [["84322.6", "0.103952"], ["84330.8", "0.297379"], ["84336.16", "1.490402"], ["84344.23", "0"], ["84350.92", "0"]], "u": 7510585, "seq": 66889282481}, "cts": 1742142213006, "record_time": 1742142212.108964}
{"topic": "orderbook.200.BTCUSDT", "ts": 1742142213210, "type": "delta", "data": {"s": "BTCUSDT", "b": [["84303.92", "0.014787"], ["84303.74", "0"], ["84302.56", "0"], ["84300.64", "0.071179"], ["84300.36", "0.00437"], ["84297.84", "0"], ["84294.75", "0.02"], ["84294.49", "0"], ["84294.21", "0"], ["84294.19", "0.02"], ["84294.15", "0"], ["84293.62", "0.02"], ["84293.59", "0.001467"], ["84293.39", "0.02"], ["84293.02", "0"], ["84292.79", "0"], ["84292.18", "0"], ["84292.09", "0.116792"], ["84292.02", "0.02"], ["84291.42", "0"], ["84286.47", "0"], ["84285.89", "0"], ["84284.44", "0"], ["84284.35", "0.178217"], ["84283.65", "0"], ["84278.73", "0"], ["84278.15", "0"], ["84276.7", "0"], ["84276.61", "0.271063"], ["84273.59", "0"], ["84273.49", "0"], ["84267.96", "0.11863"], ["84259.34", "0"], ["84254.54", "0.35588"], ["84252.96", "0"], ["84252.95", "0"], ["84251.88", "0.001467"], ["84251.71", "0.000252"], ["84251.67", "0.023726"], ["84250.97", "0.0013"], ["84250.87", "0.023726"], ["84250.52", "0.0002"], ["84250", "0.000233"], ["84249.8", "0.001333"], ["84249.76", "0.000614"], ["84249.5", "0.001"], ["84249.47", "0.000233"], ["84249.31", "0.059948"]], "a": [["84304.62", "0"], ["84321.12", "0"], ["84322.27", "0"], ["84322.35", "0"], ["84322.85", "0"], ["84324.95", "0.008453"], ["84325.37", "0.113621"], ["84325.46", "0"], ["84328.47", "0"], ["84330.59", "0.005931"], ["84333.11", "0.172617"], ["84333.19", "0"], ["84333.2", "0"], ["84336.21", "0"], ["84338.33", "0"], ["84340.85", "0.287924"], ["84340.94", "0"], ["84343.25", "0"], ["84350.92", "0.000612"], ["84350.96", "0.001333"], ["84351.48", "0.000235"], ["84351.68", "0.0002"], ["84352", "0.000235"], ["84352.17", "0.00593"], ["84352.66", "0.00089"], ["84353.22", "0.17795"], ["84353.24", "0.118791"]], "u": 7510586, "seq": 66889282723}, "cts": 1742142213202, "record_time": 1742142212.310034}
{"topic": "orderbook.200.BTCUSDT", "ts": 1742142213410, "type": "delta", "data": {"s": "BTCUSDT", "b": [["84304.57", "0.261348"], ["84303.92", "0.033983"], ["84302.56", "0.071177"], ["84300.64", "0"], ["84300.36", "0.011862"], ["84299.32", "0.14321"], ["84299.31", "0.23725"], ["84297.03", "0"], ["84295.15", "0.02"], ["84294.75", "0"], ["84294.66", "0.110068"], ["84294.59", "0.02"], ["84294.39", "0.110489"], ["84294.19", "0"], ["84294.02", "0.02"], ["84293.79", "0.02"], ["84293.62", "0"], ["84293.39", "0"], ["84292.52", "0.02"], ["84292.38", "0.108473"], ["84292.29", "0.111388"], ["84292.09", "0"], ["84292.02", "0"], ["84287.84", "0.143321"], ["84286.71", "0.173547"], ["84286.15", "0.161829"], ["84284.7", "0.179605"], ["84284.35", "0"], ["84283.92", "0.172343"], ["84281.59", "0.237235"], ["84279.63", "0"], ["84279.04", "0.2961"], ["84278.48", "0.286316"], ["84277.03", "0.284382"], ["84276.61", "0"], ["84273.94", "0.282158"], ["84273.15", "1.433999"], ["84260.61", "0"], ["84260.6", "0"], ["84260.42", "0.04"], ["84260.41", "0.039641"], ["84257.23", "0.355877"], ["84254.54", "0"], ["84251.71", "0"], ["84251.67", "0"], ["84250.97", "0"], ["84250.87", "0"], ["84250.52", "0"], ["84250", "0"], ["84249.8", "0"], ["84249.76", "0"], ["84249.5", "0"], ["84249.47", "0"], ["84249.31", "0"]], "a": [["84315.94", "0"], ["84322.23", "0.11455"], ["84322.3", "0.108192"], ["84322.79", "0.118438"], ["84325.37", "0"], ["84325.38", "0.10541"], ["84328.37", "0.162656"], ["84330.46", "0.163002"], ["84333.04", "0.17776"], ["84333.06", "0.169715"], ["84333.11", "0"], ["84336.04", "0.295765"], ["84338.14", "0.295659"], ["84340.73", "0.287519"], ["84340.85", "0"], ["84343.02", "0.278275"], ["84350.96", "0"], ["84351.48", "0"], ["84351.68", "0"], ["84352", "0"], ["84352.17", "0"], ["84352.66", "0"], ["84353.22", "0"], ["84353.24", "0"]], "u": 7510587, "seq": 66889283091}, "cts": 1742142213407, "record_time": 1742142212.509407}
{"topic": "orderbook.200.BTCUSDT", "ts": 1742142213610, "type": "delta", "data": {"s": "BTCUSDT", "b": [["84303.74", "0.001529"], ["84295.69", "0.02"], ["84294.89", "0.02"], ["84294.66", "0"], ["84294.61", "0.108065"], ["84294.59", "0"], ["84294.39", "0"], ["84294.33", "0.113643"], ["84293.79", "0"], ["84292.38", "0"], ["84292.34", "0.116513"], ["84292.29", "0"], ["84292.22", "0.117432"], ["84287.84", "0.2799"], ["84286.71", "0"], ["84286.65", "0.177635"], ["84286.15", "0"], ["84286.08", "0.161352"], ["84284.7", "0"], ["84284.66", "0.160652"], ["84283.92", "0"], ["84283.86", "0.177002"], ["84281.59", "0"], ["84279.04", "0"], ["84278.98", "0.266086"], ["84278.48", "0"], ["84278.4", "0.269307"], ["84277.03", "0"], ["84276.99", "0.296531"], ["84273.94", "0"], ["84273.88", "0.27594"], ["84257.23", "0"], ["84255.61", "0.355876"]], "a": [["84315.94", "0.014858"], ["84322.15", "0.112451"], ["84322.23", "0"], ["84322.24", "0.116172"], ["84322.3", "0"], ["84322.73", "0.118433"], ["84322.79", "0"], ["84325.34", "0.11943"], ["84325.38", "0"], ["84328.29", "0.168201"], ["84328.37", "0"], ["84330.4", "0.16149"], ["84330.46", "0"], ["84332.98", "0.169317"], ["84333.02", "0.16594"], ["84333.04", "0"], ["84333.06", "0"], ["84335.97", "0.2701"], ["84336.04", "0"], ["84338.08", "0.286876"], ["84338.14", "0"], ["84340.69", "0.266267"], ["84340.73", "0"], ["84342.96", "0.281341"], ["84343.02", "0"]], "u": 7510588, "seq": 66889283248}, "cts": 1742142213604, "record_time": 1742142212.709008}
{"topic": "orderbook.200.BTCUSDT", "ts": 1742142213809, "type": "delta", "data": {"s": "BTCUSDT", "b": [["84303.74", "0.004539"], ["84296.25", "0.02"], ["84295.24", "0"], ["84295.15", "0"], ["84295.12", "0.02"], ["84294.61", "0"], ["84294.02", "0"], ["84293.52", "0.02"], ["84292.52", "0"], ["84292.35", "0.105481"], ["84292.34", "0"], ["84292.22", "0"], ["84286.65", "0"], ["84286.08", "0"], ["84284.68", "0.166058"], ["84284.66", "0"], ["84277", "0.28677"], ["84276.99", "0"], ["84255.61", "0.355877"], ["84251.71", "0.000252"], ["84251.67", "0.023726"], ["84250.97", "0.0013"], ["84250.87", "0.023726"], ["84250.52", "0.0002"]], "a": [["84304.58", "0.003977"], ["84305.33", "0.000153"], ["84315.94", "0"], ["84322.23", "0.161082"], ["84322.24", "0"], ["84322.6", "0"], ["84325.34", "0"], ["84325.36", "0.11361"], ["84330.4", "0"], ["84333.02", "0"], ["84333.03", "0.170129"], ["84335.97", "0"], ["84340.69", "0"], ["84340.71", "0.280984"], ["84350.96", "0.001333"], ["84351.48", "0.000235"], ["84351.68", "0.0002"]], "u": 7510589, "seq": 66889283345}, "cts": 1742142213800, "record_time": 1742142212.908065}
{"topic": "orderbook.200.BTCUSDT", "ts": 1742142214010, "type": "delta", "data": {"s": "BTCUSDT", "b": [["84304.57", "0.381283"], ["84303.74", "0.011861"], ["84300.36", "0"], ["84296.95", "0.02"], ["84296.49", "0.02"], ["84296.25", "0"], ["84296.16", "0.33031"], ["84296.14", "0.0005"], ["84295.82", "0.020233"], ["84295.12", "0"], ["84294.89", "0"], ["84294.33", "0"], ["84294.32", "0.02"], ["84293.52", "0"], ["84292.35", "0"], ["84287.84", "0.143321"], ["84284.68", "0"], ["84283.86", "0"], ["84279.63", "0.575882"], ["84278.98", "0"], ["84278.4", "0"], ["84277", "0"], ["84273.88", "0"], ["84273.16", "0.11863"], ["84256.63", "0.355874"], ["84255.61", "0"], ["84250", "0.000233"], ["84249.8", "0.001333"], ["84249.76", "0.000614"], ["84249.5", "0.001"], ["84249.47", "0.000233"], ["84249.31", "0.059948"], ["84248.94", "0.11863"], ["84248", "0.0002"]], "a": [["84305.33", "0"], ["84305.62", "0.000235"], ["84308.79", "0"], ["84318.74", "0"], ["84318.75", "0"], ["84321.4", "0.028226"], ["84321.67", "0.144031"], ["84322.15", "0"], ["84322.73", "0"], ["84325.36", "0"], ["84328.29", "0"], ["84332.98", "0"], ["84333.03", "0"], ["84338.08", "0.000235"], ["84340.71", "0"], ["84341.95", "0"], ["84342.96", "0"], ["84352", "0.000235"], ["84352.17", "0.00593"], ["84352.66", "0.00089"], ["84353.22", "0.17795"], ["84353.24", "0.118791"], ["84353.6", "0.246059"], ["84353.72", "0.000253"], ["84353.8", "0.04"], ["84353.81", "0.04"], ["84353.89", "0.001467"], ["84354.21", "0.0002"], ["84354.92", "0.00109"]], "u": 7510590, "seq": 66889283490}, "cts": 1742142214007, "record_time": 1742142213.109144}
{"topic": "orderbook.200.BTCUSDT", "ts": 1742142214209, "type": "delta", "data": {"s": "BTCUSDT", "b": [["84304.57", "0.310623"], ["84303.92", "0.014787"], ["84303.74", "0"], ["84302.56", "0"], ["84300.6", "0.071179"], ["84300.36", "0.005399"], ["84297.84", "0.006462"], ["84291.95", "0.107604"], ["84285.81", "0.177444"], ["84279.63", "0"], ["84278.14", "0.272271"], ["84273.16", "0"], ["84259.34", "0.11"], ["84256.63", "0"], ["84254.54", "0.355883"], ["84249.31", "0"], ["84248.94", "0"], ["84248", "0"]], "a": [["84304.58", "0.037374"], ["84308.79", "0.011861"], ["84315.94", "0.014858"], ["84321.39", "0.059948"], ["84321.4", "0.000612"], ["84321.66", "0.06861"], ["84321.67", "0.11863"], ["84321.89", "0.107494"], ["84322.23", "0"], ["84328.03", "0.171965"], ["84330.8", "0"], ["84335.7", "0.300491"], ["84353.8", "0"], ["84353.81", "0"], ["84353.89", "0"], ["84354.21", "0"], ["84354.92", "0"]], "u": 7510591, "seq": 66889283644}, "cts": 1742142214208, "record_time": 1742142213.307921}
{"topic": "orderbook.200.BTCUSDT", "ts": 1742142214410, "type": "delta", "data": {"s": "BTCUSDT", "b": [["84300.69", "0.071179"], ["84300.6", "0"], ["84300.36", "0.011862"], ["84297.75", "0.02"], ["84297.18", "0.02"], ["84296.95", "0"], ["84296.52", "0.02"], ["84296.49", "0"], ["84296.39", "0.02"], ["84295.82", "0.000233"], ["84295.69", "0"], ["84292.03", "0.118783"], ["84291.95", "0"], ["84285.89", "0.160633"], ["84285.81", "0"], ["84278.22", "0.290766"], ["84278.14", "0"], ["84269.98", "0.015"], ["84255.61", "0.355879"], ["84254.54", "0"], ["84249.5", "0"], ["84249.47", "0"]], "a": [["84304.58", "0.037527"], ["84321.89", "0"], ["84324.93", "0.048372"], ["84328.03", "0"], ["84335.7", "0"], ["84335.78", "0.294854"], ["84347.57", "0"], ["84353.8", "0.04"], ["84353.81", "0.04"]], "u": 7510592, "seq": 66889283838}, "cts": 1742142214407, "record_time": 1742142213.509109}
{"topic": "orderbook.200.BTCUSDT", "ts": 1742142214609, "type": "delta", "data": {"s": "BTCUSDT", "b": [["84304.57", "0.381941"], ["84297.84", "0"], ["84297.75", "0"], ["84297.65", "0.02"], ["84295.02", "0.1579"], ["84294.32", "0"], ["84288.75", "0.006103"], ["84257.23", "0.355876"], ["84255.61", "0"], ["84249.5", "0.001"]], "a": [["84304.58", "0.037374"], ["84321.97", "0.111983"], ["84325.6", "0.120501"], ["84328.11", "0.157551"], ["84330.8", "0.196514"], ["84347.57", "0.237235"], ["84353.6", "0"], ["84353.72", "0"], ["84353.8", "0"], ["84353.81", "0"]], "u": 7510593, "seq": 66889283933}, "cts": 1742142214605, "record_time": 1742142213.708513}
{"topic": "orderbook.200.BTCUSDT", "ts": 1742142214810, "type": "delta", "data": {"s": "BTCUSDT", "b": [["84303.74", "0.011861"], ["84300.36", "0.00437"], ["84297.95", "0.02"], ["84297.65", "0"], ["84297.48", "0.02"], ["84297.18", "0"], ["84296.82", "0.02"], ["84296.69", "0.02"], ["84296.52", "0"], ["84296.39", "0"], ["84295.32", "0.02"], ["84295.22", "0.115326"], ["84295.02", "0.1379"], ["84294.94", "0.12066"], ["84292.41", "0.119329"], ["84292.03", "0"], ["84288.75", "0"], ["84287.27", "0.172433"], ["84286.27", "0.157509"], ["84285.89", "0"], ["84284.48", "0.179013"], ["84279.59", "0.275196"], ["84278.6", "0.288654"], ["84278.22", "0"], ["84274.5", "0.289288"], ["84273.16", "0.11863"], ["84272.58", "0.003536"], ["84267.73", "0"], ["84251.67", "0"], ["84250.97", "0"], ["84250.87", "0"], ["84250.52", "0"], ["84250", "0"], ["84249.8", "0"], ["84249.76", "0"], ["84249.5", "0"]], "a": [["84308.79", "0"], ["84315.94", "0"], ["84321.32", "0.027814"], ["84321.38", "0.113566"], ["84321.66", "0"], ["84321.97", "0.000089"], ["84322.34", "0.105481"], ["84322.85", "0.107769"], ["84323.34", "0.106753"], ["84324.93", "0.078476"], ["84328.11", "0"], ["84328.48", "0.162827"], ["84331.02", "0.175996"], ["84333.6", "0.166026"], ["84335.78", "0"], ["84336.16", "1.756488"], ["84338.69", "0.291735"], ["84343.57", "0.277174"], ["84352.17", "0"], ["84352.66", "0"], ["84353.22", "0"], ["84353.24", "0"]], "u": 7510594, "seq": 66889284054}, "cts": 1742142214807, "record_time": 1742142213.910032}
{"topic": "orderbook.200.BTCUSDT", "ts": 1742142215010, "type": "delta", "data": {"s": "BTCUSDT", "b": [["84304.57", "0.376101"], ["84303.74", "0.004901"], ["84300.36", "0.008147"], ["84298.05", "0.02"], ["84297.95", "0"], ["84296.92", "0.02"], ["84296.82", "0"], ["84287.84", "0.278092"], ["84273.49", "0.515649"], ["84273.16", "0"], ["84257.23", "0"], ["84255.61", "0.355879"]], "a": [["84308.79", "0.005405"], ["84321.38", "0.079998"], ["84322.4", "0.155379"], ["84324.93", "0"], ["84338.96", "0"]], "u": 7510595, "seq": 66889284166}, "cts": 1742142215007, "record_time": 1742142214.108752}
{"topic": "orderbook.200.BTCUSDT", "ts": 1742142215210, "type": "delta", "data": {"s": "BTCUSDT", "b": [["84303.74", "0"], ["84300.7", "0.003"], ["84300.69", "0"], ["84298.79", "0.071181"], ["84297.84", "0.007964"], ["84295.42", "0.02"], ["84295.32", "0"], ["84295.22", "0"], ["84294.94", "0"], ["84292.41", "0"], ["84291.89", "0.120594"], ["84288.75", "0.006071"], ["84287.27", "0"], ["84286.27", "0"], ["84285.75", "0.157775"], ["84284.48", "0"], ["84279.59", "0"], ["84278.6", "0"], ["84278.08", "0.294451"], ["84274.5", "0"], ["84262.15", "0.003"], ["84256.63", "0.355875"], ["84255.61", "0"], ["84253.73", "0.2"], ["84251.67", "0.023726"], ["84250.97", "0.0013"], ["84250.87", "0.023726"]], "a": [["84305.41", "0.003618"], ["84305.82", "0.074175"], ["84308.79", "0.011861"], ["84315.94", "0.015758"], ["84316.78", "0.004467"], ["84321.83", "0.107874"], ["84322.34", "0"], ["84322.85", "0"], ["84323.34", "0"], ["84327.81", "0.071156"], ["84327.97", "0.17653"], ["84328.48", "0"], ["84331.02", "0"], ["84332.81", "0.003"], ["84333.12", "0"], ["84333.6", "0"], ["84335.64", "0.298823"], ["84336.16", "1.490402"], ["84338.69", "0"], ["84343.57", "0"], ["84352.17", "0.00593"], ["84352.66", "0.00089"]], "u": 7510596, "seq": 66889284358}, "cts": 1742142215206, "record_time": 1742142214.309242}
{"topic": "orderbook.200.BTCUSDT", "ts": 1742142215409, "type": "delta", "data": {"s": "BTCUSDT", "b": [["84300.87", "0.071179"], ["84298.79", "0"], ["84298.65", "0.02"], ["84298.18", "0.02"], ["84298.05", "0"], ["84297.52", "0.02"], ["84297.48", "0"], ["84297.28", "0.02"], ["84296.92", "0"], ["84296.69", "0"], ["84296.02", "0.02"], ["84295.42", "0"], ["84294.8", "0.110997"], ["84294.52", "0.110892"], ["84291.96", "0.107384"], ["84291.89", "0"], ["84287.84", "0.143321"], ["84286.81", "0.167321"], ["84285.79", "0.179502"], ["84285.75", "0.000089"], ["84284", "0.169339"], ["84279.1", "0.278782"], ["84278.08", "0.293983"], ["84273.98", "0.287622"], ["84257.23", "0.355874"], ["84256.63", "0"], ["84253.73", "0"], ["84251.95", "0"], ["84251.88", "0"], ["84251.71", "0"], ["84251.67", "0"], ["84250.97", "0"], ["84250.87", "0"]], "a": [["84305.41", "0"], ["84305.82", "0.071175"], ["84321.83", "0"], ["84322.04", "0.120073"], ["84322.4", "0.091022"], ["84322.56", "0.120513"], ["84323.06", "0.113952"], ["84327.97", "0"], ["84328.21", "0.161048"], ["84330.77", "0.157966"], ["84333.36", "0.236694"], ["84335.64", "0"], ["84335.92", "0.274476"], ["84338.48", "0.268371"], ["84343.38", "0.289128"], ["84351.68", "0"], ["84352", "0"], ["84352.17", "0"], ["84352.66", "0"]], "u": 7510597, "seq": 66889284557}, "cts": 1742142215407, "record_time": 1742142214.508471}
{"topic": "orderbook.200.BTCUSDT", "ts": 1742142215609, "type": "delta", "data": {"s": "BTCUSDT", "b": [["84304.57", "0.305441"], ["84297.38", "0.02"], ["84297.28", "0"], ["84294.8", "0"], ["84294.75", "0.114374"], ["84294.52", "0"], ["84294.48", "0.12063"], ["84287.84", "0.229453"], ["84286.81", "0"], ["84286.76", "0.169154"], ["84284", "0"], ["84283.96", "0.172103"], ["84279.1", "0"], ["84279.05", "0.2642"], ["84273.98", "0"], ["84273.93", "0.300316"], ["84259.47", "0.11"], ["84257.23", "0"], ["84254.54", "0.355878"], ["84252.93", "0"]], "a": [["84304.58", "0.037527"], ["84322.03", "0.111133"], ["84322.04", "0"], ["84322.4", "0.149984"], ["84322.52", "0.110947"], ["84322.56", "0"], ["84323.01", "0.10709"], ["84323.06", "0"], ["84328.2", "0.179719"], ["84328.21", "0"], ["84330.72", "0.170435"], ["84330.77", "0"], ["84333.31", "0.179572"], ["84333.36", "0.071151"], ["84338.43", "0.287406"], ["84338.48", "0"], ["84343.34", "0.278057"], ["84343.38", "0"], ["84351.48", "0"]], "u": 7510598, "seq": 66889284665}, "cts": 1742142215605, "record_time": 1742142214.708836}
{"topic": "orderbook.200.BTCUSDT", "ts": 1742142215810, "type": "delta", "data": {"s": "BTCUSDT", "b": [["84304.57", "0.342647"], ["84303.74", "0.011861"], ["84300.87", "0"], ["84299.05", "0.02"], ["84298.65", "0"], ["84298.28", "0.02"], ["84298.18", "0"], ["84297.84", "0"], ["84297.72", "0.02"], ["84297.52", "0"], ["84297.48", "0.02"], ["84297.38", "0"], ["84296.42", "0.02"], ["84296.02", "0"], ["84294.75", "0"], ["84294.65", "0.118386"], ["84294.48", "0"], ["84294.37", "0.108836"], ["84291.96", "0"], ["84286.76", "0"], ["84286.65", "0.174824"], ["84285.79", "0"], ["84283.96", "0"], ["84283.83", "0.174279"], ["84279.28", "0.003413"], ["84279.05", "0"], ["84278.92", "0.28363"], ["84278.08", "0"], ["84273.93", "0"], ["84272.58", "0"], ["84262.71", "0.323547"], ["84259.47", "0"], ["84256.63", "0.355874"], ["84254.54", "0"], ["84252.93", "0.023937"], ["84251.95", "0.00009"], ["84251.88", "0.001467"], ["84251.71", "0.000252"], ["84251.67", "0.023726"]], "a": [["84304.58", "0.036741"], ["84305.62", "0.028753"], ["84308.79", "0"], ["84315.94", "0"], ["84321.39", "0"], ["84322.03", "0"], ["84322.47", "0.109078"], ["84322.52", "0"], ["84322.96", "0.111973"], ["84323.01", "0"], ["84327.81", "0"], ["84328.2", "0"], ["84330.69", "0.168703"], ["84330.72", "0"], ["84333.28", "0.160167"], ["84333.31", "0"], ["84335.92", "0"], ["84336.63", "0.071149"], ["84338.41", "0.297455"], ["84338.43", "0"], ["84343.33", "0.274239"], ["84343.34", "0"], ["84349.29", "0.323215"], ["84351.48", "0.000235"], ["84351.68", "0.0002"], ["84352", "0.000235"], ["84352.17", "0.00593"], ["84352.66", "0.00089"], ["84353.22", "0.17795"]], "u": 7510599, "seq": 66889284923}, "cts": 1742142215805, "record_time": 1742142214.908575}
{"topic": "orderbook.200.BTCUSDT", "ts": 1742142216010, "type": "delta", "data": {"s": "BTCUSDT", "b": [["84304.57", "0.33553"], ["84299.05", "0"], ["84298.85", "0.02"], ["84296.42", "0"], ["84296.12", "0.02"], ["84294.65", "0"], ["84294.37", "0"], ["84286.65", "0"], ["84283.83", "0"], ["84279.63", "0.415346"], ["84278.92", "0"], ["84256.63", "0"], ["84255.61", "0.355877"], ["84250.97", "0.0013"], ["84250.87", "0.023726"], ["84250.52", "0.0002"], ["84250", "0.000233"]], "a": [["84304.58", "0.036588"], ["84305.62", "0.000235"], ["84322.47", "0"], ["84322.96", "0"], ["84330.69", "0.001467"], ["84333.28", "0"], ["84338.41", "0"], ["84343.33", "0"], ["84353.24", "0.118791"], ["84353.6", "0.246059"], ["84353.72", "0.000253"], ["84353.89", "0.001467"], ["84353.9", "0.04"]], "u": 7510600, "seq": 66889285107}, "cts": 1742142216008, "record_time": 1742142215.109666}
{"topic": "orderbook.200.BTCUSDT", "ts": 1742142216209, "type": "delta", "data": {"s": "BTCUSDT", "b": [["84304.57", "0"], ["84304.53", "0"], ["84303.92", "0"], ["84303.74", "0"], ["84303.73", "0.036857"], ["84303.61", "0"], ["84300.7", "0"], ["84300.36", "0"], ["84299.32", "0"], ["84299.31", "0"], ["84298.85", "0"], ["84298.28", "0"], ["84297.72", "0"], ["84297.48", "0"], ["84297.02", "0"], ["84296.16", "0"], ["84296.14", "0"], ["84296.12", "0"], ["84295.7", "0"], ["84295.4", "0"], ["84295.3", "0.0005"], ["84295.26", "0"], ["84295.13", "0"], ["84295.03", "0.01372"], ["84295.02", "0"], ["84294", "0"], ["84293.8", "0"], ["84293.55", "0"], ["84293.49", "0"], ["84292.8", "0"], ["84292.11", "0.041611"], ["84292.1", "0"], ["84292", "0"], ["84290.98", "0"], ["84290.97", "0.0002"], ["84290.65", "0.02"], ["84290.5", "0"], ["84290.19", "0.02"], ["84290.02", "0.02"], ["84289.99", "0"], ["84289.84", "0"], ["84289.52", "0.02"], ["84289.27", "0"], ["84289.19", "0.02"], ["84289.15", "0"], ["84289.1", "0"], ["84288.75", "0"], ["84288.7", "0"], ["84288.6", "0"], ["84288.12", "0.015078"], ["84287.85", "0.000297"], ["84287.84", "0"], ["84287.83", "0"], ["84287.23", "0.07119"], ["84286.02", "0.060315"], ["84285.8", "0"], ["84285.07", "0.108232"], ["84284.79", "0.116528"], ["84284.2", "0"], ["84281.69", "0"], ["84281.65", "0.109851"], ["84280.79", "0.011862"], ["84280.16", "0"], ["84279.28", "0"], ["84278.77", "0"], ["84278.33", "0.0002"], ["84277.74", "0"], ["84277.19", "0"], ["84277.07", "0.171851"], ["84276.04", "0.008453"], ["84275.57", "0"], ["84275.14", "0.068395"], ["84274.71", "0"], ["84273.92", "0.17448"], ["84268.95", "0"], ["84268.26", "0"], ["84268.15", "0.017793"], ["84268.09", "0"], ["84267.96", "0"], ["84262.58", "0"], ["84262.11", "0"], ["84261.16", "0.035593"], ["84260.42", "0"], ["84260.41", "0"], ["84259.34", "0"], ["84259.1", "0"], ["84258.69", "0"], ["84258.13", "0.071215"], ["84257.22", "0"], ["84255.61", "0"], ["84254.88", "0.04"], ["84254.87", "0.039646"], ["84254.37", "0"], ["84254.31", "0"], ["84253.51", "0.000988"], ["84252.93", "0"], ["84249.8", "0.001333"], ["84249.76", "0.000614"], ["84249.5", "0.001"], ["84249.47", "0.000233"], ["84249.31", "0.059948"], ["84248.94", "0.11863"], ["84248", "0.0002"], ["84247.24", "0.001467"], ["84247.08", "0.000252"], ["84246.09", "0.023713"], ["84245.87", "0.023726"], ["84245.86", "0.000089"], ["84245.7", "0.005931"], ["84245.59", "0.001333"], ["84245.55", "0.000614"], ["84245.47", "0.0002"], ["84245.36", "0.000233"], ["84245.1", "0.001243"], ["84245", "0.000119"], ["84244.84", "0.000233"], ["84243.87", "0.11863"], ["84243.5", "0.00009"], ["84243.38", "0.014023"], ["84242.94", "0.0002"], ["84242.79", "0.059365"], ["84242.61", "0.001467"], ["84242.44", "0.000252"], ["84241.98", "0.017765"], ["84241.38", "0.001333"], ["84241.34", "0.000614"], ["84240.87", "0.059948"], ["84240.77", "0.023729"], ["84240.73", "0.000233"], ["84240.41", "0.0002"], ["84240.2", "0.000233"], ["84239.01", "0.000237"], ["84238.07", "0.118629"], ["84237.98", "0.001467"], ["84237.81", "0.023981"], ["84237.49", "0.000357"], ["84237.17", "0.001333"], ["84237.12", "1.779876"]], "a": [["84303.74", "0.247201"], ["84303.93", "0.102009"], ["84304.37", "0.029801"], ["84304.57", "0.0004"], ["84304.58", "0.001468"], ["84305.41", "0.011861"], ["84305.62", "0.012097"], ["84305.82", "0"], ["84306.23", "0.089922"], ["84308.79", "0.011861"], ["84309.76", "0"], ["84309.77", "0"], ["84309.83", "0"], ["84310.23", "0.089543"], ["84310.24", "0.11863"], ["84312.17", "0.0005"], ["84312.89", "0.107171"], ["84313.01", "0"], ["84313.02", "0.163333"], ["84313.38", "0.111712"], ["84313.46", "0.000089"], ["84313.99", "0.159756"], ["84314.24", "0.008453"], ["84314.44", "0.089922"], ["84314.87", "0.115827"], ["84315.25", "0.083986"], ["84315.93", "0.11863"], ["84315.95", "0.001243"], ["84316.14", "0"], ["84316.67", "0.004578"], ["84317.99", "0.020996"], ["84318.27", "0.017794"], ["84318.31", "0.068395"], ["84319.7", "0.000789"], ["84319.84", "0.009328"], ["84320.97", "0.163418"], ["84321.11", "0.177383"], ["84321.31", "0.059948"], ["84321.32", "0.0002"], ["84321.46", "0.162"], ["84321.68", "0"], ["84322.11", "0.071161"], ["84322.4", "0.091022"], ["84322.41", "0"], ["84322.6", "0.171805"], ["84323.7", "0.162291"], ["84324.95", "0"], ["84325.51", "0.089922"], ["84326.22", "0"], ["84327.32", "0.000988"], ["84327.63", "0.071156"], ["84328.18", "0"], ["84328.79", "0"], ["84328.83", "0.273458"], ["84330.32", "0.268971"], ["84330.81", "0.153822"], ["84331.91", "0"], ["84332.99", "0"], ["84333.36", "0"], ["84336.37", "0"], ["84336.63", "0"], ["84337", "0"], ["84337.21", "0"], ["84337.77", "0"], ["84338.26", "0.355943"], ["84339.1", "0"], ["84339.48", "0"], ["84340.58", "0.023724"], ["84343.36", "0"], ["84345.88", "0.474234"], ["84346.15", "0.023724"], ["84346.72", "0"], ["84347.57", "0"], ["84349.18", "0.059156"], ["84349.68", "0"], ["84350", "0"], ["84350.92", "0"], ["84350.96", "0"], ["84351.48", "0"], ["84351.68", "0"], ["84352", "0"], ["84352.17", "0"], ["84352.66", "0"], ["84353.22", "0"], ["84353.24", "0"], ["84353.6", "0"], ["84353.72", "0"], ["84353.89", "0"], ["84353.9", "0"]], "u": 7510601, "seq": 66889286228}, "cts": 1742142216207, "record_time": 1742142215.310172}
{"topic": "orderbook.200.BTCUSDT", "ts": 1742142216409, "type": "delta", "data": {"s": "BTCUSDT", "b": [["84300.71", "0"], ["84296.36", "0.0133"], ["84295.04", "0.022049"], ["84292.12", "0.000297"], ["84292.11", "0.156401"], ["84290.19", "0"], ["84290.09", "0.02"], ["84290.02", "0"], ["84289.09", "0.148"], ["84288.68", "0.000297"], ["84288.67", "0.237237"], ["84288.59", "0.237237"], ["84288.02", "0.02"], ["84287.85", "0"], ["84287.23", "0"], ["84286.03", "0.099828"], ["84285.1", "0.04"], ["84285.07", "0"], ["84284.79", "0"], ["84284.7", "0.04"], ["84284.45", "0.13167"], ["84284.38", "0.237237"], ["84283.3", "0.04"], ["84283", "0.04"], ["84281.66", "0.036574"], ["84281.65", "0"], ["84279.62", "0"], ["84279.6", "0.04"], ["84279.2", "0.058396"], ["84278.3", "0.04"], ["84277.9", "0.04"], ["84277.12", "0.000817"], ["84277.07", "0"], ["84275.68", "0"], ["84275.02", "0.140051"], ["84274.94", "0.019233"], ["84274.54", "0.165887"], ["84273.92", "0"], ["84271.1", "0.003392"], ["84264.24", "0.07121"], ["84261.16", "0"], ["84259.1", "0.177928"], ["84254.88", "0"], ["84254.87", "0"], ["84252.88", "0.04"], ["84252.87", "0.039647"], ["84248.18", "0.162"], ["84243.88", "0.355929"], ["84242.44", "0"], ["84241.98", "0"], ["84241.38", "0"], ["84241.34", "0"], ["84240.87", "0"], ["84240.77", "0"], ["84240.73", "0"], ["84240.41", "0"], ["84240.2", "0"], ["84239.01", "0"], ["84238.07", "0"], ["84237.98", "0"], ["84237.81", "0"], ["84237.49", "0"], ["84237.17", "0"], ["84237.12", "0"]], "a": [["84303.93", "0"], ["84304.37", "0"], ["84305.61", "0.035384"], ["84307.1", "0.008453"], ["84308.36", "0"], ["84310.23", "0.110358"], ["84312.89", "0"], ["84313.02", "0.001333"], ["84313.18", "0.020997"], ["84313.38", "0"], ["84313.99", "0.095777"], ["84314.24", "0"], ["84314.87", "0"], ["84315.29", "0.029801"], ["84317.99", "0"], ["84320.1", "0.044"], ["84320.4", "0.06"], ["84320.69", "0.175115"], ["84320.96", "0.20578"], ["84320.97", "0"], ["84321.11", "0"], ["84321.38", "0"], ["84321.7", "0.044"], ["84322.1", "0.068"], ["84322.6", "0"], ["84323.7", "0"], ["84325.4", "0.056"], ["84325.6", "0.188501"], ["84326.7", "0.048"], ["84327.1", "0.048"], ["84328.83", "0"], ["84329.8", "0"], ["84330.32", "0"], ["84330.5", "0"], ["84331.1", "0"], ["84332.5", "0.017796"], ["84334.93", "0.237237"], ["84335.05", "0.237237"], ["84336.8", "0"], ["84338.26", "0"], ["84339.15", "0.237237"], ["84339.27", "0.241737"], ["84345.87", "0.355922"], ["84349.68", "0.0013"], ["84350", "0.021512"], ["84350.92", "0.000612"]], "u": 7510602, "seq": 66889286775}, "cts": 1742142216408, "record_time": 1742142215.509071}
{"topic": "orderbook.200.BTCUSDT", "ts": 1742142216610, "type": "delta", "data": {"s": "BTCUSDT", "b": [["84299.95", "0.000099"], ["84292.11", "0.220027"], ["84291.65", "0.02"], ["84291.09", "0.02"], ["84290.65", "0"], ["84290.52", "0.02"], ["84290.19", "0.02"], ["84290.09", "0"], ["84289.52", "0"], ["84289.19", "0"], ["84289.06", "0.071189"], ["84288.92", "0.02"], ["84288.02", "0"], ["84286.03", "0.142594"], ["84285.61", "0.11632"], ["84285.33", "0.113232"], ["84284.54", "0.105938"], ["84283.04", "0.112524"], ["84281.66", "0"], ["84281.4", "0.04"], ["84280.8", "0.048"], ["84280.79", "0"], ["84279.63", "0"], ["84278.36", "0.174305"], ["84277.61", "0.163845"], ["84276.43", "0"], ["84275.32", "0.173022"], ["84275.25", "0.011863"], ["84274.81", "0.166688"], ["84274.54", "0"], ["84273.15", "0"], ["84270.64", "0.265369"], ["84270.2", "0.023438"], ["84269.9", "0.288281"], ["84268.15", "0"], ["84267.6", "0.276093"], ["84264.77", "0.275116"], ["84262.6", "0.041521"], ["84261.42", "1.412521"], ["84259.63", "0.035594"], ["84245.59", "0"], ["84245.55", "0"], ["84245.47", "0"], ["84245.36", "0"], ["84245.1", "0"], ["84245", "0"], ["84244.84", "0"], ["84243.88", "0"], ["84243.87", "0"], ["84243.5", "0"], ["84243.38", "0"], ["84242.94", "0"], ["84242.79", "0"], ["84242.61", "0"]], "a": [["84303.74", "0.213683"], ["84307.1", "0"], ["84307.52", "0.000099"], ["84310.23", "0.109906"], ["84312.18", "0.162"], ["84312.44", "0.008453"], ["84313.4", "0.114964"], ["84313.89", "0.118429"], ["84313.99", "0.15923"], ["84314.64", "0.11562"], ["84316.23", "0.115614"], ["84320.39", "0.187274"], ["84320.69", "0"], ["84320.81", "0.15943"], ["84320.96", "0"], ["84321.61", "0.168693"], ["84322.82", "1.437607"], ["84323.6", "0.06"], ["84323.95", "0.16341"], ["84324.2", "0.164418"], ["84325.6", "0.068"], ["84326.2", "0"], ["84327.5", "0"], ["84327.7", "0"], ["84328.06", "0"], ["84328.53", "0.286357"], ["84329.33", "0.276243"], ["84329.5", "0.0006"], ["84330.8", "0"], ["84331.67", "0.288115"], ["84334.24", "0.275956"], ["84336.16", "0"], ["84345.86", "0.355925"], ["84345.87", "0"], ["84348.18", "0"], ["84349.08", "0"], ["84349.15", "0"], ["84349.18", "0"], ["84349.25", "0"], ["84349.29", "0"], ["84349.68", "0"], ["84350", "0"], ["84350.92", "0"]], "u": 7510603, "seq": 66889287192}, "cts": 1742142216602, "record_time": 1742142215.70914}
{"topic": "orderbook.200.BTCUSDT", "ts": 1742142216809, "type": "delta", "data": {"s": "BTCUSDT", "b": [["84303.73", "0"], ["84302.86", "0"], ["84301.09", "0"], ["84300.33", "0"], ["84299.95", "0"], ["84298.56", "0"], ["84298.23", "0"], ["84298.06", "0"], ["84297.61", "0"], ["84296.36", "0"], ["84296.35", "0"], ["84296.15", "0"], ["84296.11", "0"], ["84296.03", "0"], ["84295.82", "0"], ["84295.3", "0"], ["84295.04", "0"], ["84295.03", "0"], ["84294.43", "0"], ["84294.2", "0"], ["84293.59", "0"], ["84293.5", "0"], ["84293.43", "0"], ["84292.12", "0"], ["84292.11", "0"], ["84291.94", "0"], ["84291.9", "0"], ["84291.71", "0"], ["84291.65", "0"], ["84291.19", "0"], ["84291.09", "0"], ["84290.97", "0"], ["84290.52", "0"], ["84290.19", "0"], ["84289.09", "0"], ["84289.06", "0"], ["84288.97", "0"], ["84288.96", "0.001186"], ["84288.92", "0"], ["84288.79", "0"], ["84288.68", "0"], ["84288.67", "0"], ["84288.59", "0"], ["84288.44", "0"], ["84288.12", "0"], ["84287.72", "0"], ["84287.68", "0.00052"], ["84286.03", "0"], ["84286.02", "0"], ["84285.92", "0.0002"], ["84285.75", "0"], ["84285.61", "0"], ["84285.33", "0"], ["84285.1", "0"], ["84284.7", "0"], ["84284.54", "0"], ["84284.45", "0"], ["84284.38", "0"], ["84283.3", "0"], ["84283.04", "0"], ["84283", "0"], ["84282.46", "0.001087"], ["84281.68", "0"], ["84281.4", "0"], ["84280.54", "0.01573"], ["84280.53", "0.0005"], ["84279.6", "0"], ["84279.21", "0.013085"], ["84279.2", "0.0406"], ["84278.79", "0"], ["84278.36", "0"], ["84278.3", "0"], ["84277.9", "0"], ["84277.61", "0"], ["84277.12", "0"], ["84276.62", "0.02"], ["84276.04", "0"], ["84275.32", "0"], ["84275.25", "0"], ["84275.23", "0"], ["84275.14", "0"], ["84275.02", "0"], ["84274.94", "0"], ["84274.81", "0"], ["84274.67", "0.0302"], ["84274.66", "0.02"], ["84274.1", "0.04"], ["84273.49", "0"], ["84273.48", "0"], ["84273.47", "0.02"], ["84271.42", "0.02"], ["84271.17", "0.02"], ["84271.1", "0"], ["84270.76", "0.000297"], ["84270.64", "0"], ["84270.2", "0"], ["84270.11", "0"], ["84269.9", "0"], ["84269.22", "0.109765"], ["84268.99", "0.005923"], ["84268.33", "0.005931"], ["84267.6", "0"], ["84265.96", "0.114494"], ["84265.05", "0"], ["84264.77", "0"], ["84264.24", "0.009039"], ["84263.68", "0.000817"], ["84262.75", "0.011865"], ["84262.71", "0"], ["84262.69", "0.176256"], ["84262.6", "0"], ["84262.56", "0"], ["84261.42", "0"], ["84261.22", "0.174248"], ["84259.63", "0"], ["84259.1", "0"], ["84258.74", "0.003632"], ["84258.44", "0"], ["84258.24", "0.1726"], ["84258.13", "0"], ["84257.14", "0.008453"], ["84256.2", "0.068395"], ["84255.6", "0"], ["84254.97", "0.281651"], ["84254.53", "0"], ["84253.51", "0"], ["84252.88", "0"], ["84252.87", "0"], ["84250.52", "0.269266"], ["84250.11", "0.017797"], ["84248.96", "0.02373"], ["84248.94", "0"], ["84248.38", "0.267831"], ["84246.09", "0"], ["84245.95", "0.000989"], ["84245.59", "0.001333"], ["84245.55", "0.000614"], ["84245.47", "0.0002"], ["84245.36", "0.000233"], ["84245.1", "0.001243"], ["84245", "0.000119"], ["84244.84", "0.000233"], ["84244.53", "0.004631"], ["84243.5", "0.00009"], ["84242.94", "0.0002"], ["84242.9", "0.24702"], ["84242.79", "0.059365"], ["84242.61", "0.001467"], ["84242.44", "0.000252"], ["84241.38", "0.001333"], ["84241.34", "0.000614"], ["84240.87", "0.059948"], ["84240.77", "0.023729"], ["84240.73", "0.000233"], ["84240.41", "0.0002"], ["84240.2", "0.000233"], ["84240.19", "0.04"], ["84240.18", "0.039652"], ["84239.01", "0.000237"], ["84238.07", "0.118629"], ["84237.98", "0.001467"], ["84237.81", "0.023981"], ["84237.49", "0.000357"], ["84237.17", "0.001333"], ["84237.12", "1.779876"], ["84236.1", "0.000233"], ["84235.8", "0.000335"], ["84235.57", "0.000233"], ["84235.05", "0.00009"], ["84234.81", "0.023729"], ["84234.2", "0.002401"], ["84234.01", "0.023729"], ["84233.35", "0.001467"], ["84233.18", "0.000252"], ["84233.14", "0.0025"], ["84232.95", "0.001333"], ["84232.91", "0.000613"], ["84232.38", "0.015"], ["84231.7", "0.118629"], ["84231.69", "0.059948"], ["84231.67", "0.227168"], ["84231.46", "0.000233"], ["84230.94", "0.000233"], ["84230.58", "0.013894"], ["84229.01", "0.023729"], ["84228.74", "0.001333"], ["84228.71", "0.001467"], ["84228.7", "0.000614"], ["84228.55", "0.000252"], ["84226.83", "0.000233"], ["84226.82", "0.237279"], ["84226.6", "0.00009"], ["84226.47", "0.118629"], ["84226.45", "0.089922"], ["84226.31", "0.000233"], ["84225", "0.068395"], ["84224.53", "0.001333"], ["84224.49", "0.000614"], ["84224.08", "0.001467"], ["84223.91", "0.000252"], ["84223.3", "0.001243"], ["84223.08", "0.000085"], ["84222.76", "0.387482"], ["84222.6", "0.237279"], ["84222.31", "0.352577"], ["84222.2", "0.000233"], ["84221.8", "0.243801"]], "a": [["84288.97", "0.207686"], ["84289.1", "0.000153"], ["84290.39", "0.001477"], ["84290.52", "0.208049"], ["84290.53", "0.143465"], ["84291.08", "0.336352"], ["84291.2", "0.062476"], ["84293.84", "0.12131"], ["84293.85", "0.368142"], ["84295.06", "0.023727"], ["84296.16", "0.002579"], ["84296.35", "0.000233"], ["84296.36", "0.059136"], ["84297", "0.105101"], ["84297.62", "0.0004"], ["84297.69", "0.126151"], ["84297.7", "0.11863"], ["84298.06", "0.000252"], ["84298.23", "0.001467"], ["84298.56", "0.0002"], ["84298.57", "0.01"], ["84299.15", "0.107215"], ["84299.44", "0.041529"], ["84299.78", "0.068395"], ["84300.33", "0.000613"], ["84300.37", "0.001333"], ["84300.46", "0.000233"], ["84300.98", "0.000233"], ["84301.09", "0.0002"], ["84301.1", "0.065274"], ["84301.35", "0.059948"], ["84302.7", "0.000252"], ["84302.87", "0.001467"], ["84303.72", "0.03767"], ["84303.73", "0.11903"], ["84303.74", "0.0002"], ["84304.54", "0.000613"], ["84304.57", "0"], ["84304.58", "0.001315"], ["84304.95", "0.000089"], ["84305.05", "0.003748"], ["84305.14", "0.161225"], ["84305.41", "0"], ["84305.44", "0.116177"], ["84305.5", "0.000789"], ["84305.61", "0"], ["84305.62", "0.000235"], ["84306.23", "0"], ["84306.86", "0.1794"], ["84307.52", "0"], ["84307.81", "0.237705"], ["84308.49", "0.140037"], ["84308.79", "0"], ["84309.04", "0.017796"], ["84309.3", "0.020996"], ["84310.22", "0.059948"], ["84310.43", "0.083986"], ["84310.54", "0.00593"], ["84311.22", "0.008912"], ["84311.31", "0"], ["84311.54", "0.019075"], ["84312.44", "0"], ["84312.49", "0"], ["84312.86", "0.270198"], ["84313.18", "0"], ["84313.2", "0.06"], ["84313.28", "0.35692"], ["84313.4", "0"], ["84313.89", "0"], ["84314.58", "0.290653"], ["84314.64", "0"], ["84314.65", "0.02371"], ["84315.1", "0.044"], ["84315.25", "0"], ["84315.29", "0"], ["84316.1", "0.071166"], ["84316.23", "0"], ["84316.67", "0"], ["84317.84", "0.288483"], ["84318.27", "0"], ["84318.3", "0.356018"], ["84318.31", "0"], ["84319.11", "0.432363"], ["84319.7", "0"], ["84319.76", "0.000989"], ["84320.31", "0.059309"], ["84320.48", "0.00593"], ["84320.5", "0.056"], ["84320.81", "0"], ["84321.61", "0"], ["84321.7", "0"], ["84322.11", "0"], ["84322.4", "0.607948"], ["84322.61", "0.026414"], ["84323.95", "0"], ["84324.2", "0"], ["84324.62", "0.023725"], ["84324.94", "0"], ["84325.4", "0"], ["84326.07", "0.068395"], ["84327.32", "0"], ["84327.63", "0"], ["84328.14", "0"], ["84328.53", "0"], ["84329.33", "0"], ["84329.77", "0.32329"], ["84330.81", "0"], ["84331.1", "0.474234"], ["84331.67", "0"], ["84331.69", "0"], ["84334.24", "0"], ["84334.93", "0"], ["84335.05", "0"], ["84335.3", "0.005931"], ["84335.49", "0"], ["84336.37", "0.237279"], ["84336.44", "0"], ["84338.27", "0.000612"], ["84339.15", "0"], ["84339.27", "0.0045"], ["84340.4", "0"], ["84340.58", "0"], ["84340.62", "0"], ["84340.88", "0"], ["84341.49", "0"], ["84341.56", "0"], ["84342.2", "0"], ["84342.46", "0"], ["84342.49", "0"], ["84342.53", "0"], ["84342.72", "0"], ["84342.79", "0"], ["84343.72", "0"], ["84344.09", "0"], ["84344.44", "0"], ["84344.61", "0"], ["84345.86", "0"], ["84345.88", "0"], ["84346.15", "0"], ["84346.23", "0"], ["84346.62", "0"], ["84346.7", "0"], ["84346.75", "0"], ["84346.84", "0"], ["84347.03", "0"], ["84347.28", "0"], ["84347.36", "0"], ["84347.48", "0"], ["84347.5", "0"]], "u": 7510604, "seq": 66889290011}, "cts": 1742142216807, "record_time": 1742142215.910686}
{"topic": "orderbook.200.BTCUSDT", "ts": 1742142217009, "type": "delta", "data": {"s": "BTCUSDT", "b": [["84288.96", "0"], ["84287.68", "0"], ["84287.07", "0"], ["84286.55", "0"], ["84285.92", "0"], ["84282.4", "0.0654"], ["84280.8", "0"], ["84280.54", "0.043725"], ["84280.53", "0"], ["84279.7", "0.0132"], ["84279.21", "0"], ["84279.2", "0.0006"], ["84276.9", "0.0005"], ["84276.62", "0"], ["84274.67", "0"], ["84274.66", "0"], ["84274.1", "0"], ["84273.47", "0"], ["84271.43", "0.031534"], ["84271.42", "0"], ["84271.17", "0"], ["84269.98", "0"], ["84269.22", "0"], ["84268.99", "0"], ["84268.94", "0.015084"], ["84268.49", "0.000297"], ["84268.33", "0"], ["84267.8", "0.04"], ["84267.63", "0.02"], ["84267.16", "0.008012"], ["84266.83", "0.06034"], ["84266.44", "0.111364"], ["84266.33", "0.02"], ["84265.97", "0.038081"], ["84265.96", "0"], ["84265.9", "0.04"], ["84264.52", "0.02"], ["84263.11", "0.02"], ["84262.75", "0"], ["84262.69", "0"], ["84262.6", "0.04"], ["84262.4", "0.040614"], ["84261.4", "0.04"], ["84261.22", "0"], ["84258.24", "0"], ["84258.14", "0.019233"], ["84257.91", "0.0122"], ["84257.63", "0"], ["84256.62", "0"], ["84256.39", "0.005844"], ["84254.97", "0"], ["84254.67", "0"], ["84254.31", "0.023728"], ["84251.67", "0"], ["84250.87", "0"], ["84250.52", "0.0002"], ["84250.11", "0"], ["84248.38", "0"], ["84245.87", "0"], ["84245.27", "0.017798"], ["84244.53", "0"], ["84242.9", "0"], ["84242.79", "0"], ["84240.2", "0.071463"], ["84240.19", "0"], ["84240.18", "0"], ["84239.75", "0.162"], ["84238.19", "0.04"], ["84238.18", "0.039645"], ["84238.07", "0"], ["84237.89", "0.0002"], ["84235.36", "0.0002"], ["84232.96", "1.404149"], ["84231.32", "0.162"], ["84230.58", "0"], ["84229.91", "0.004704"], ["84227.5", "0.24702"], ["84226.83", "0.356241"], ["84226.82", "0"], ["84225.4", "0.237286"], ["84222.89", "0.162"], ["84222.6", "0"], ["84221.8", "0"], ["84221.67", "0.000233"], ["84221.18", "0.237286"], ["84220.79", "0.647429"], ["84220.32", "0.001333"], ["84220.28", "0.000613"], ["84220.04", "0.059948"], ["84219.5", "0.04"], ["84219.45", "0.001467"], ["84219.28", "0.000252"], ["84218.15", "0.00009"]], "a": [["84284.33", "0.17985"], ["84285.3", "0.11863"], ["84285.34", "0.27348"], ["84286.55", "0.008453"], ["84286.56", "0.453213"], ["84287.39", "0.011864"], ["84288.44", "0.0002"], ["84288.97", "0.017857"], ["84289.1", "0"], ["84289.87", "0.011863"], ["84290.52", "0"], ["84290.53", "0.072277"], ["84290.97", "0.0002"], ["84291.07", "0.11863"], ["84291.19", "0.000233"], ["84291.71", "0.000233"], ["84291.9", "0.000613"], ["84291.94", "0.001333"], ["84292.6", "0.000088"], ["84293.24", "0.011863"], ["84293.43", "0.000252"], ["84293.5", "0.0002"], ["84293.59", "0.001467"], ["84293.77", "0.162"], ["84293.84", "0"], ["84293.85", "0"], ["84294.46", "0.020998"], ["84294.99", "0.0183"], ["84295.05", "0.050866"], ["84296.03", "0.0002"], ["84296.16", "0.002179"], ["84296.44", "0.000089"], ["84296.58", "0.083989"], ["84296.96", "0.120231"], ["84297", "0"], ["84297.69", "0.099856"], ["84298.57", "0"], ["84299.15", "0"], ["84300.21", "0.059321"], ["84300.43", "0.004636"], ["84301.1", "0.107744"], ["84301.4", "0.009328"], ["84303.22", "0.174445"], ["84303.42", "0.162"], ["84303.62", "0.0002"], ["84303.74", "0"], ["84305.14", "0"], ["84305.44", "0.165785"], ["84306.6", "0.06"], ["84306.86", "0"], ["84307.35", "0.071173"], ["84307.81", "0"], ["84308.3", "0.068"], ["84309.3", "0"], ["84309.6", "0.044"], ["84310.24", "0.362528"], ["84310.43", "0"], ["84311.6", "0.056"], ["84312.17", "0"], ["84312.86", "0"], ["84313.1", "0.048"], ["84313.3", "0.048"], ["84314.58", "0.013908"], ["84314.65", "0"], ["84315.24", "0.023728"], ["84316.1", "0"], ["84317.84", "0"], ["84318.08", "0.237286"], ["84318.18", "0.237286"], ["84318.3", "0"], ["84319.84", "0"], ["84320.1", "0"], ["84320.39", "0"], ["84320.5", "0"], ["84321.3", "0.356015"], ["84322.29", "0.237286"], ["84322.4", "0.679348"], ["84323.31", "0.023728"], ["84323.6", "0"], ["84323.71", "0.023728"], ["84325.92", "0.023728"], ["84326.7", "0"], ["84327.1", "0"], ["84328.69", "0.474234"], ["84329.28", "0.023728"], ["84330.59", "0"], ["84331.1", "0"], ["84333.4", "0.246059"], ["84334.05", "0"], ["84334.06", "0"], ["84334.1", "0"], ["84334.38", "0"], ["84335.16", "0"], ["84335.3", "0"], ["84335.33", "0"], ["84335.96", "0"], ["84336.37", "0"], ["84336.5", "0"], ["84337.56", "0"], ["84338.08", "0"], ["84338.27", "0"], ["84338.31", "0"], ["84338.79", "0"], ["84338.84", "0"], ["84338.99", "0"], ["84339.03", "0"], ["84339.07", "0"], ["84339.27", "0"], ["84339.8", "0"], ["84339.97", "0"], ["84340.18", "0"]], "u": 7510605, "seq": 66889291533}, "cts": 1742142217008, "record_time": 1742142216.109566}
{"topic": "orderbook.200.BTCUSDT", "ts": 1742142217210, "type": "delta", "data": {"s": "BTCUSDT", "b": [["84284.32", "0"], ["84284.16", "0"], ["84283.51", "0"], ["84283.47", "0"], ["84283.39", "0"], ["84282.46", "0"], ["84282.44", "0"], ["84282.4", "0"], ["84281.91", "0"], ["84281.9", "0"], ["84280.86", "0"], ["84280.54", "0"], ["84279.7", "0"], ["84279.69", "0"], ["84279.52", "0"], ["84279.3", "0"], ["84279.25", "0"], ["84279.2", "0"], ["84278.33", "0.000558"], ["84277.3", "0"], ["84276.9", "0"], ["84273.49", "0.043725"], ["84271.82", "0.003"], ["84271.46", "0.000543"], ["84271.43", "0"], ["84271.26", "0.0005"], ["84270.76", "0"], ["84268.94", "0"], ["84268.85", "0"], ["84268.49", "0"], ["84268.4", "0.000297"], ["84267.8", "0"], ["84267.63", "0"], ["84267.16", "0"], ["84266.83", "0"], ["84266.81", "0.028005"], ["84266.8", "0.04"], ["84266.44", "0"], ["84266.33", "0"], ["84265.97", "0"], ["84265.9", "0"], ["84264.52", "0"], ["84264.4", "0.048"], ["84264.24", "0"], ["84263.11", "0"], ["84262.71", "0.000297"], ["84262.7", "0.02"], ["84262.61", "0.056141"], ["84262.6", "0"], ["84262.4", "0.000614"], ["84262.03", "0.02"], ["84261.4", "0"], ["84261.2", "0.02"], ["84260.53", "0.02"], ["84260.02", "0"], ["84259", "0.04"], ["84258.12", "0.029879"], ["84257.91", "0.000335"], ["84257.14", "0"], ["84256.2", "0"], ["84254.31", "0"], ["84253.49", "0.005932"], ["84253.37", "0"], ["84252.98", "0.011866"], ["84252.6", "0.04"], ["84245.95", "0"], ["84245.7", "0"], ["84245.27", "0"], ["84244.98", "0.008453"], ["84243.23", "0.017796"], ["84243.06", "0.023731"], ["84240.78", "0.101752"], ["84240.34", "0.017799"], ["84240.2", "0.000233"], ["84238.19", "0"], ["84238.18", "0"], ["84235.99", "0.005932"], ["84232.83", "0.0002"], ["84231.7", "0"], ["84230.31", "0.0002"], ["84229.67", "0.071239"], ["84228.25", "0.000989"], ["84227.5", "0"], ["84226.83", "0.000233"], ["84226.8", "0.04"], ["84226.79", "0.039655"], ["84226.47", "0"], ["84225.4", "0"], ["84224", "0.24702"], ["84222.76", "0"], ["84222.32", "0.11863"], ["84221.18", "0"], ["84219.5", "0"], ["84217.56", "0.000233"], ["84217.45", "0.002853"], ["84217.16", "0.017765"], ["84217.04", "0.000233"], ["84216.97", "0.005"], ["84216.33", "0.118629"], ["84216.11", "0.001333"], ["84216.07", "0.000613"], ["84215.96", "0.014111"], ["84215.6", "0.048"], ["84214.81", "0.001467"], ["84214.65", "0.000252"], ["84214", "0.000158"], ["84213.69", "0.000335"], ["84212.93", "0.000233"], ["84212.41", "0.000233"], ["84212.4", "0.001243"], ["84211.9", "0.001333"], ["84211.85", "0.000613"], ["84211.53", "0.059948"], ["84211.27", "0.118629"], ["84210.18", "0.001467"]], "a": [["84278.34", "0.203366"], ["84278.47", "0.359689"], ["84279.69", "0.288466"], ["84279.7", "0.256766"], ["84281.9", "0.0004"], ["84281.92", "0.337279"], ["84282.33", "0.02373"], ["84282.41", "0.07066"], ["84283.39", "0.0002"], ["84283.47", "0.000613"], ["84283.51", "0.001333"], ["84284", "0.005932"], ["84284.16", "0.000252"], ["84284.32", "0.001467"], ["84284.33", "0"], ["84285.16", "0.011864"], ["84285.29", "0.17295"], ["84285.34", "0"], ["84285.92", "0.0002"], ["84286.55", "0.003233"], ["84286.56", "0.082937"], ["84287.07", "0.000233"], ["84287.58", "0.005932"], ["84287.68", "0.000613"], ["84287.72", "0.001333"], ["84287.93", "0.000089"], ["84288.79", "0.000252"], ["84288.96", "0.001467"], ["84288.97", "0.005992"], ["84289.2", "0.0006"], ["84289.49", "0.083992"], ["84289.56", "0.190241"], ["84289.85", "0.0178"], ["84290.39", "0"], ["84290.53", "0.042476"], ["84291.08", "0"], ["84291.2", "0"], ["84291.55", "0.059326"], ["84292.03", "0.068395"], ["84292.32", "0.059948"], ["84292.33", "0.020997"], ["84292.6", "0"], ["84292.75", "0.131403"], ["84292.76", "0.162"], ["84293.24", "0"], ["84293.77", "0"], ["84294.46", "0"], ["84295.05", "0"], ["84295.28", "0.003"], ["84295.57", "0.023238"], ["84295.67", "0.071183"], ["84295.7", "0.06"], ["84296.47", "0.005932"], ["84296.54", "0.005"], ["84296.58", "0"], ["84296.95", "0.13445"], ["84296.96", "0"], ["84297", "0.044"], ["84297.62", "0"], ["84297.69", "0"], ["84299.44", "0.023731"], ["84299.56", "0.100963"], ["84299.78", "0"], ["84299.8", "0.044"], ["84300.7", "0.06"], ["84301.1", "0.157799"], ["84301.61", "0.071178"], ["84301.9", "0.000989"], ["84302.05", "0.029801"], ["84303.22", "0"], ["84303.7", "0.048"], ["84303.73", "0.11863"], ["84304.1", "0.048"], ["84305.43", "0.356071"], ["84305.44", "0.116177"], ["84305.5", "0"], ["84307.35", "0"], ["84308.04", "0.003"], ["84309.6", "0"], ["84310.23", "0.325968"], ["84310.54", "0"], ["84313.1", "0.116"], ["84313.2", "0"], ["84313.99", "0.095777"], ["84315.1", "0"], ["84315.24", "0"], ["84316.78", "0.001467"], ["84318.08", "0"], ["84318.18", "0"], ["84319.76", "0"], ["84320.4", "0"], ["84320.47", "0.474234"], ["84321.3", "0"], ["84322.1", "0"], ["84322.29", "0"], ["84322.4", "0.607948"], ["84322.82", "0"], ["84328.69", "0"], ["84330", "0"], ["84330.48", "0"], ["84330.53", "0"], ["84330.69", "0"], ["84331.18", "0"], ["84331.43", "0"], ["84331.44", "0"], ["84332.1", "0"], ["84332.33", "0"], ["84332.36", "0"], ["84332.38", "0"], ["84332.5", "0"], ["84332.56", "0"], ["84332.81", "0"], ["84332.92", "0"], ["84333.09", "0"], ["84333.14", "0"], ["84333.4", "0"], ["84333.45", "0"], ["84333.97", "0"], ["84334.02", "0"]], "u": 7510606, "seq": 66889293104}, "cts": 1742142217207, "record_time": 1742142216.309825}
{"topic": "orderbook.200.BTCUSDT", "ts": 1742142217410, "type": "delta", "data": {"s": "BTCUSDT", "b": [["84278.33", "0"], ["84277.8", "0"], ["84277.28", "0"], ["84275.8", "0"], ["84275.08", "0"], ["84275.05", "0"], ["84275.04", "0"], ["84274.89", "0"], ["84273.49", "0"], ["84273.27", "0"], ["84273.17", "0"], ["84272.64", "0"], ["84271.82", "0"], ["84271.46", "0"], ["84271.26", "0"], ["84270.87", "0"], ["84270.83", "0"], ["84270.75", "0"], ["84270.42", "0"], ["84270.25", "0"], ["84268.53", "0"], ["84268.4", "0"], ["84268.22", "0"], ["84268.01", "0"], ["84266.9", "0"], ["84266.81", "0"], ["84266.8", "0"], ["84266.66", "0"], ["84266.61", "0"], ["84264.4", "0"], ["84263.68", "0"], ["84262.71", "0"], ["84262.7", "0"], ["84262.61", "0"], ["84262.15", "0"], ["84262.03", "0"], ["84261.2", "0"], ["84260.53", "0"], ["84260.4", "0"], ["84259", "0"], ["84258.74", "0.000233"], ["84258.23", "0.001833"], ["84258.14", "0"], ["84258.12", "0"], ["84257.72", "0.000961"], ["84256.39", "0"], ["84256.1", "0.04"], ["84253.72", "0.023662"], ["84253.49", "0"], ["84252.98", "0"], ["84252.6", "0"], ["84251.95", "0"], ["84250.11", "0.000297"], ["84249.31", "0"], ["84248.96", "0"], ["84248.18", "0"], ["84245", "0"], ["84244.99", "0.015667"], ["84244.98", "0"], ["84243.23", "0"], ["84243.06", "0"], ["84242", "0.04"], ["84241.37", "0.162"], ["84240.88", "0.079814"], ["84240.87", "0"], ["84240.78", "0"], ["84240.77", "0"], ["84240.34", "0"], ["84239.75", "0"], ["84237.81", "0.000252"], ["84237.49", "0"], ["84236.06", "0.023734"], ["84235.99", "0"], ["84234.81", "0"], ["84234.01", "0"], ["84232.96", "0"], ["84231.69", "0"], ["84231.08", "0.009541"], ["84230.2", "0.323672"], ["84230.13", "0.000817"], ["84229.91", "0"], ["84229.67", "0"], ["84229.01", "0"], ["84227.78", "0.0002"], ["84226.8", "0"], ["84226.79", "0"], ["84226.63", "0.019233"], ["84226.45", "0"], ["84225.25", "0.0002"], ["84225", "0"], ["84224.01", "0.059948"], ["84224", "0"], ["84222.72", "0.0002"], ["84222.32", "0"], ["84222.31", "0"], ["84220.79", "0"], ["84220.2", "0.0002"], ["84220.04", "0"], ["84219.51", "0.04"], ["84219.4", "0.039655"], ["84217.67", "0.0002"], ["84216.33", "0"], ["84215.96", "0"], ["84215.6", "0"], ["84214.46", "0.162"], ["84214.17", "0.023733"], ["84213.09", "0.005933"], ["84211.53", "0"], ["84211.27", "0"], ["84210.81", "0.023733"], ["84210.19", "0.059948"], ["84210.1", "0.089922"], ["84210.02", "0.000252"], ["84209.7", "0.00009"], ["84208.4", "0.24702"], ["84208.3", "0.000233"], ["84208.21", "0.023733"], ["84207.78", "0.000233"], ["84207.7", "0.0006"], ["84207.69", "0.001333"], ["84207.64", "0.000615"], ["84207.41", "0.023733"], ["84205.55", "0.001467"], ["84205.38", "0.000252"], ["84204.38", "0.00009"], ["84203.67", "0.000233"], ["84203.48", "0.001333"], ["84203.43", "0.000615"], ["84203.32", "0.118629"], ["84203.15", "0.000233"], ["84202.41", "0.023733"], ["84201.63", "0.059948"], ["84201.5", "0.001243"], ["84201.25", "0.00009"], ["84200.92", "0.001467"], ["84200.75", "0.000252"], ["84200.59", "0.013719"], ["84199.88", "0.12"], ["84199.27", "0.001333"], ["84199.22", "0.000615"], ["84199.04", "0.000233"], ["84198.51", "0.000233"], ["84198.5", "0.04"], ["84198.13", "0.118629"], ["84198", "0.04"], ["84196.29", "0.001467"], ["84196.12", "0.000252"], ["84195.4", "0.04"], ["84195.3", "0.382564"], ["84195.06", "0.001333"], ["84195.01", "0.000615"], ["84194.6", "0.04"], ["84194.41", "0.000233"], ["84194.4", "0.167859"], ["84193.9", "0.04"], ["84193.88", "0.000233"], ["84192.8", "0.00009"], ["84192.32", "0.457444"], ["84192", "0.04"], ["84191.66", "0.001467"], ["84191.58", "0.000335"], ["84191.49", "0.000252"], ["84191.32", "0.059948"], ["84191.31", "0.068395"], ["84191.09", "0.12"], ["84190.85", "0.001333"], ["84190.8", "0.000615"]], "a": [["84266.67", "0.204784"], ["84266.84", "0.291313"], ["84266.85", "0.359689"], ["84266.91", "0.000153"], ["84267.33", "0.11863"], ["84267.53", "0.011868"], ["84268.54", "0.059948"], ["84269.38", "0.043266"], ["84270.21", "0.333467"], ["84270.43", "0.040814"], ["84270.75", "0.0002"], ["84270.84", "0.014876"], ["84272.13", "0.005933"], ["84272.63", "0.057976"], ["84272.64", "0.118863"], ["84272.65", "0.074158"], ["84273.17", "0.000233"], ["84276.02", "0.068395"], ["84276.75", "0.000789"], ["84277.81", "0.195068"], ["84278.32", "0.059948"], ["84278.33", "0.0002"], ["84278.34", "0"], ["84278.47", "0"], ["84279.25", "0.000613"], ["84279.3", "0.001333"], ["84279.42", "0.00009"], ["84279.52", "0.000252"], ["84279.69", "0.001867"], ["84279.7", "0.11863"], ["84280.34", "0.003"], ["84280.61", "0.116952"], ["84280.86", "0.0002"], ["84280.88", "0.083987"], ["84281.89", "0.097066"], ["84281.91", "0.000233"], ["84281.92", "0.07066"], ["84281.97", "0.000099"], ["84282.33", "0"], ["84282.44", "0.000233"], ["84283.05", "0.020998"], ["84283.12", "0.032919"], ["84283.25", "0.001243"], ["84283.53", "0.162"], ["84284", "0"], ["84284.16", "0.018048"], ["84284.32", "0.007399"], ["84284.59", "0.140034"], ["84285.16", "0"], ["84285.29", "0.067519"], ["84285.37", "0.005"], ["84286.12", "0.029801"], ["84286.2", "0.06"], ["84286.23", "0.04906"], ["84286.24", "0.0178"], ["84286.63", "0.023734"], ["84286.65", "0.023733"], ["84286.71", "0.071191"], ["84287.14", "0.004609"], ["84287.39", "0"], ["84287.58", "0"], ["84289.49", "0"], ["84289.56", "0"], ["84289.65", "0.005"], ["84289.84", "0.120614"], ["84289.85", "0"], ["84289.87", "0"], ["84290.53", "0"], ["84291.55", "0"], ["84292.03", "0"], ["84292.33", "0"], ["84292.5", "0.068"], ["84292.8", "0.044"], ["84294.15", "0.001243"], ["84294.99", "0.0005"], ["84295.8", "0.056"], ["84295.82", "0.000233"], ["84296.11", "0.000613"], ["84296.15", "0.001333"], ["84296.16", "0"], ["84296.36", "0"], ["84296.48", "0.023734"], ["84296.54", "0"], ["84297.32", "0.005933"], ["84299.12", "0.005932"], ["84299.44", "0"], ["84299.8", "0"], ["84300.05", "0.017796"], ["84300.43", "0"], ["84300.71", "0.014103"], ["84301.04", "1.362085"], ["84301.4", "0"], ["84301.61", "0"], ["84302.05", "0"], ["84302.64", "0.02112"], ["84303.41", "0.356085"], ["84303.5", "0.068"], ["84303.72", "0"], ["84304.54", "0.003009"], ["84305.43", "0"], ["84306.45", "0.023731"], ["84306.6", "0"], ["84306.85", "0.023731"], ["84307.01", "0.026414"], ["84308.49", "0"], ["84308.79", "0.474234"], ["84309.04", "0"], ["84309.06", "0.023731"], ["84310.24", "0.11863"], ["84311.22", "0"], ["84311.54", "0"], ["84311.6", "0"], ["84312.42", "0.023731"], ["84313.1", "0.068"], ["84313.3", "0"], ["84313.99", "0"], ["84314.2", "0.246059"], ["84314.58", "0"], ["84317.46", "0.323337"], ["84320.47", "0"], ["84321.14", "0.009"], ["84321.32", "0"], ["84321.4", "0"], ["84321.42", "0"], ["84321.45", "0"], ["84321.46", "0"], ["84321.67", "0"], ["84321.97", "0"], ["84322", "0"], ["84322.4", "0"], ["84322.61", "0"], ["84323.31", "0"], ["84323.65", "0"], ["84323.71", "0"], ["84323.85", "0"], ["84324.17", "0"], ["84324.62", "0"], ["84325.51", "0"], ["84325.6", "0"], ["84325.62", "0"], ["84325.66", "0"], ["84325.89", "0"], ["84325.92", "0"], ["84326", "0"], ["84326.06", "0"], ["84326.07", "0"], ["84326.38", "0"], ["84326.41", "0"], ["84327.93", "0"], ["84328.04", "0"], ["84328.28", "0"], ["84328.81", "0"], ["84328.91", "0"], ["84329.28", "0"], ["84329.5", "0"], ["84329.77", "0"], ["84329.84", "0"], ["84329.88", "0"], ["84329.9", "0"], ["84329.99", "0"]], "u": 7510607, "seq": 66889294881}, "cts": 1742142217407, "record_time": 1742142216.510158}
{"topic": "orderbook.200.BTCUSDT", "ts": 1742142217609, "type": "delta", "data": {"s": "BTCUSDT", "b": [["84265.78", "0"], ["84265.69", "0"], ["84265.61", "0"], ["84263.9", "0"], ["84263.37", "0"], ["84263.16", "0"], ["84262.44", "0"], ["84262.4", "0"], ["84262.01", "0.006186"], ["84261.73", "0.0005"], ["84258.23", "0.001333"], ["84256.12", "0.031166"], ["84256.1", "0"], ["84253.72", "0"], ["84253.58", "0.0005"], ["84250.11", "0"], ["84249.45", "0.015092"], ["84248.02", "0.027596"], ["84248.01", "0.028706"], ["84247.34", "0.06037"], ["84245.71", "0.026146"], ["84245.7", "0.04"], ["84244.99", "0"], ["84244.9", "0.04"], ["84243.2", "0.04"], ["84242.25", "0.237355"], ["84241.5", "0.048"], ["84241.39", "0.049955"], ["84241.37", "0"], ["84240.88", "0"], ["84240.01", "0.02"], ["84239.9", "0.04"], ["84239.73", "0.02"], ["84239.7", "0.107803"], ["84238.7", "0.04"], ["84238.5", "0.04"], ["84238.31", "0.02"], ["84238.14", "0.008961"], ["84238.04", "0.237355"], ["84237.13", "0.542131"], ["84236.06", "0"], ["84235.79", "0.011868"], ["84233.19", "0.17723"], ["84232.83", "0.003753"], ["84231.68", "0.217159"], ["84230.2", "0"], ["84229.42", "0.068395"], ["84225.57", "0.023328"], ["84225.05", "0.298693"], ["84223.15", "0.04154"], ["84220.71", "0.008453"], ["84219.51", "0"], ["84219.4", "0"], ["84219.06", "0.006186"], ["84218.63", "0.140034"], ["84217.71", "0.015"], ["84215.41", "0.04"], ["84215.4", "0.039643"], ["84215.18", "0.071251"], ["84215.14", "0.0002"], ["84214.59", "0.004586"], ["84212.62", "0.0002"], ["84208.98", "0.071257"], ["84208.55", "0.075146"], ["84208.41", "0.11863"], ["84208.4", "0"], ["84206.03", "0.162"], ["84203.33", "0.356117"], ["84203.2", "0.24702"], ["84199.88", "0"], ["84199.22", "0"], ["84199.04", "0"], ["84198.51", "0"], ["84198.5", "0"], ["84198.13", "0"], ["84198", "0"], ["84196.29", "0"], ["84196.12", "0"], ["84195.4", "0"], ["84195.3", "0"], ["84195.06", "0"], ["84195.01", "0"], ["84194.6", "0"], ["84194.41", "0"], ["84194.4", "0"], ["84193.9", "0"], ["84193.88", "0"], ["84192.8", "0"], ["84192.32", "0"], ["84192", "0"], ["84191.66", "0"], ["84191.58", "0"], ["84191.49", "0"], ["84191.32", "0"], ["84191.31", "0"], ["84191.09", "0"], ["84190.85", "0"], ["84190.8", "0"]], "a": [["84262.02", "0.282434"], ["84262.38", "0.259166"], ["84262.39", "0.359689"], ["84265.79", "0.012067"], ["84266.61", "0.000613"], ["84266.65", "0.001333"], ["84266.67", "0"], ["84266.84", "0"], ["84266.91", "0"], ["84267.06", "0.011867"], ["84267.53", "0"], ["84268.01", "0.000233"], ["84268.22", "0.0002"], ["84268.53", "0.056184"], ["84269.33", "0.023734"], ["84270.21", "0"], ["84270.25", "0.000252"], ["84270.42", "0.001467"], ["84270.44", "0.04906"], ["84270.82", "0.000613"], ["84270.87", "0.001333"], ["84270.91", "0.00009"], ["84271.45", "0.112427"], ["84272.63", "0.100572"], ["84272.65", "0"], ["84272.72", "0.004701"], ["84272.76", "0.142404"], ["84272.78", "0.017803"], ["84273.27", "0.0002"], ["84273.82", "0.008453"], ["84273.83", "0.023738"], ["84274.52", "0.020997"], ["84275.78", "0.023632"], ["84275.8", "0.0002"], ["84276.61", "0.170136"], ["84276.62", "0.083987"], ["84277.81", "0.194668"], ["84277.96", "0.158775"], ["84278.55", "0.059335"], ["84278.6", "0.06"], ["84280.3", "0.068"], ["84280.34", "0.003461"], ["84280.88", "0"], ["84281.07", "0.005"], ["84281.97", "0"], ["84283.05", "0"], ["84283.2", "0.044"], ["84283.6", "0.056"], ["84285", "0.048"], ["84285.11", "0.008755"], ["84285.29", "0.139219"], ["84285.3", "0.16663"], ["84286.09", "0.071191"], ["84286.1", "0.26781"], ["84286.23", "0"], ["84286.24", "0"], ["84286.63", "0"], ["84287.01", "0.014103"], ["84287.14", "0"], ["84288.59", "0.237355"], ["84288.67", "0.23735"], ["84288.71", "0.35692"], ["84289.84", "0"], ["84291.9", "0.001213"], ["84292.8", "0.281355"], ["84292.88", "0.17544"], ["84293.49", "0.001225"], ["84294.54", "0.432363"], ["84295.06", "0"], ["84295.57", "0"], ["84295.67", "0"], ["84295.8", "0"], ["84296.94", "0.356112"], ["84296.95", "0.521122"], ["84297", "0"], ["84300.7", "0"], ["84300.71", "0"], ["84301.02", "0.3234"], ["84303.41", "0"], ["84303.7", "0"], ["84304.1", "0"], ["84304.14", "0.474234"], ["84308.3", "0"], ["84308.79", "0"], ["84310.23", "0"], ["84313.1", "0"], ["84313.28", "0"], ["84315.93", "0"], ["84315.95", "0"], ["84316.26", "0"], ["84316.61", "0"], ["84316.78", "0"], ["84316.97", "0"], ["84317.19", "0"], ["84317.23", "0"], ["84317.25", "0"], ["84317.46", "0"], ["84318.79", "0"], ["84319.01", "0"], ["84319.11", "0"], ["84319.53", "0"], ["84319.54", "0"], ["84320", "0"], ["84320.31", "0"], ["84320.48", "0"], ["84321.14", "0"], ["84321.25", "0"], ["84321.31", "0"]], "u": 7510608, "seq": 66889295588}, "cts": 1742142217607, "record_time": 1742142216.70969}
{"topic": "orderbook.200.BTCUSDT", "ts": 1742142217810, "type": "delta", "data": {"s": "BTCUSDT", "b": [["84256.53", "0.019735"], ["84256.52", "0.027607"], ["84255.28", "0.003848"], ["84248.03", "0.000297"], ["84245.71", "0.105735"], ["84243.5", "0.04009"], ["84241.77", "0.117399"], ["84241.71", "0.02"], ["84241.47", "0.111078"], ["84240.96", "0.119096"], ["84239.7", "0"], ["84238.31", "0"], ["84234.44", "0.167291"], ["84233.8", "0.006075"], ["84233.33", "0.175318"], ["84233.19", "0"], ["84231.68", "0"], ["84230.37", "0.173047"], ["84228.97", "0.017796"], ["84228.25", "0"], ["84226.3", "0.265795"], ["84225.57", "0"], ["84225.19", "0.284754"], ["84225.05", "0"], ["84223.14", "0.023556"], ["84221.08", "0.071246"], ["84219.79", "0.300517"], ["84219.66", "1.409904"], ["84219.06", "0"], ["84218.96", "0.006186"], ["84215.41", "0"], ["84215.4", "0"], ["84213.61", "0.04"], ["84213.6", "0.039645"], ["84211.93", "0.000989"], ["84208.98", "0"], ["84206.04", "0.3561"], ["84203.43", "0"], ["84203.33", "0"], ["84203.32", "0"], ["84203.2", "0"], ["84203.15", "0"], ["84202.41", "0"], ["84201.63", "0"], ["84201.5", "0"], ["84201.25", "0"], ["84200.92", "0"], ["84200.75", "0"], ["84200.59", "0"], ["84199.27", "0"]], "a": [["84262.38", "0"], ["84262.39", "0"], ["84262.85", "0.011867"], ["84265.65", "0.000099"], ["84266.84", "0.147056"], ["84268.53", "0.104297"], ["84270.45", "0.0183"], ["84271.07", "0.116241"], ["84271.45", "0"], ["84271.59", "0.11355"], ["84271.65", "0.153398"], ["84272.63", "0"], ["84272.71", "0.108454"], ["84272.76", "0.083069"], ["84272.78", "0"], ["84277.01", "0.017803"], ["84277.96", "0"], ["84278.2", "0.044"], ["84278.55", "0.059796"], ["84279.22", "0.171612"], ["84279.73", "0.167346"], ["84279.9", "0.044"], ["84280.34", "0.003"], ["84281.9", "0.0604"], ["84281.92", "0"], ["84282.41", "0"], ["84282.47", "0.179284"], ["84285.57", "0.000989"], ["84286.1", "0"], ["84286.12", "0"], ["84286.2", "0"], ["84287.36", "0.264674"], ["84287.87", "0.279504"], ["84288.58", "0.328418"], ["84290.1", "0.022864"], ["84292.5", "0"], ["84292.8", "0.237355"], ["84293.05", "0.286542"], ["84294.99", "0"], ["84295.7", "0"], ["84296.94", "0"], ["84297.35", "0.029801"], ["84301.9", "0"], ["84303.41", "0.356103"], ["84305.44", "0"], ["84313.85", "0"], ["84314.2", "0"], ["84314.37", "0"], ["84314.44", "0"], ["84314.9", "0"]], "u": 7510609, "seq": 66889295909}, "cts": 1742142217802, "record_time": 1742142216.908467}
{"topic": "orderbook.200.BTCUSDT", "ts": 1742142218010, "type": "delta", "data": {"s": "BTCUSDT", "b": [["84262.01", "0.106186"], ["84257.81", "0.005765"], ["84256.53", "0.012778"], ["84256.12", "0"], ["84255.28", "0.011823"], ["84255.01", "0.0013"], ["84251.95", "0.00009"], ["84251.15", "0.021426"], ["84251.14", "0.071221"], ["84250.97", "0"], ["84249.46", "0.023303"], ["84248.02", "0"], ["84248.01", "0"], ["84245.72", "0.000297"], ["84244.34", "0.107166"], ["84244.04", "0.109727"], ["84243.86", "0.106117"], ["84243.11", "0.02"], ["84241.77", "0"], ["84241.71", "0"], ["84241.51", "0.02"], ["84241.47", "0"], ["84241.39", "0.152734"], ["84241.03", "0.02"], ["84240.99", "0.105169"], ["84240.96", "0"], ["84240.01", "0"], ["84239.9", "0.08"], ["84239.73", "0"], ["84237.35", "0.170575"], ["84235.9", "0.163249"], ["84234.44", "0"], ["84233.34", "0.231602"], ["84233.33", "0"], ["84232.94", "0.175307"], ["84232.85", "0.179722"], ["84230.37", "0"], ["84229.21", "0.285544"], ["84227.76", "0.282355"], ["84226.3", "0"], ["84225.19", "0"], ["84224.71", "0.292777"], ["84222.36", "0.271901"], ["84219.79", "0"], ["84218.96", "0"], ["84218.68", "0.035611"], ["84217.01", "0.0012"], ["84208.41", "0"], ["84206.04", "0"], ["84206.03", "0"], ["84205.55", "0"], ["84205.38", "0"], ["84204.38", "0"], ["84203.67", "0"], ["84203.48", "0"]], "a": [["84265.69", "0.0002"], ["84265.79", "0.011867"], ["84266.84", "0.039149"], ["84266.85", "0"], ["84268.53", "0.056184"], ["84268.75", "0.011866"], ["84269.33", "0"], ["84271.07", "0"], ["84271.59", "0"], ["84271.65", "0.158697"], ["84272.71", "0"], ["84272.76", "0.023734"], ["84273.64", "0.120078"], ["84274.16", "0.108652"], ["84274.88", "0.000252"], ["84275.04", "0.000613"], ["84275.05", "0.001467"], ["84275.08", "0.001333"], ["84275.61", "0.110267"], ["84276", "0.105522"], ["84276.61", "0.286813"], ["84276.75", "0.00125"], ["84277.28", "0.000233"], ["84277.8", "0.000233"], ["84277.81", "0.190537"], ["84278.55", "0.059335"], ["84279.22", "0"], ["84279.73", "0"], ["84280.61", "0.183013"], ["84282.12", "0.180086"], ["84282.3", "0.161507"], ["84282.47", "0"], ["84283.2", "0"], ["84283.37", "0.237295"], ["84283.4", "0.068"], ["84284.14", "0.169865"], ["84284.45", "1.396753"], ["84285.04", "0.169397"], ["84286.75", "0.237285"], ["84287.36", "0"], ["84287.87", "0"], ["84288.59", "0"], ["84288.67", "0"], ["84290.26", "0.272899"], ["84290.44", "0.275873"], ["84292.28", "0.262557"], ["84292.8", "0"], ["84292.88", "0"], ["84293.05", "0"], ["84295.62", "0.293838"], ["84296.12", "0.0001"], ["84301.04", "0"], ["84303.41", "0"], ["84303.5", "0"], ["84310.21", "0.356095"], ["84310.43", "0.015"], ["84311.68", "0"], ["84312.18", "0"], ["84312.42", "0"], ["84312.97", "0"], ["84313.02", "0"], ["84313.27", "0"], ["84313.46", "0"], ["84313.73", "0"]], "u": 7510610, "seq": 66889296261}, "cts": 1742142218007, "record_time": 1742142217.10913}
{"topic": "orderbook.200.BTCUSDT", "ts": 1742142218210, "type": "delta", "data": {"s": "BTCUSDT", "b": [["84262.01", "0.108186"], ["84257.81", "0.006103"], ["84256.53", "0"], ["84256.52", "0"], ["84255.28", "0.004372"], ["84251.16", "0.030054"], ["84245.71", "0.210652"], ["84244.34", "0"], ["84244.04", "0"], ["84243.86", "0"], ["84243.21", "0.02"], ["84243.11", "0"], ["84240.99", "0"], ["84237.35", "0"], ["84235.9", "0"], ["84233.35", "0.061415"], ["84232.94", "0"], ["84232.85", "0"], ["84229.21", "0"], ["84227.76", "0"], ["84226.82", "0.237355"], ["84224.71", "0"], ["84222.6", "0.237355"], ["84222.36", "0"], ["84208.56", "0.356077"], ["84205.55", "0.001467"], ["84205.38", "0.000252"], ["84204.38", "0.00009"], ["84203.67", "0.000233"], ["84203.48", "0.001333"], ["84203.43", "0.000615"], ["84203.32", "0.118629"], ["84203.2", "0.24702"], ["84203.15", "0.000233"], ["84202.41", "0.023733"]], "a": [["84262.85", "0.007713"], ["84271.65", "0.132252"], ["84273.64", "0"], ["84274.16", "0"], ["84275.61", "0"], ["84276", "0"], ["84276.61", "0.170136"], ["84276.75", "0.000789"], ["84277.8", "0.000694"], ["84279.59", "0.689706"], ["84279.69", "0.001467"], ["84280.61", "0.352796"], ["84281.9", "0.06"], ["84282.12", "0"], ["84282.3", "0"], ["84284.14", "0"], ["84285.04", "0"], ["84285.06", "0.23729"], ["84285.8", "0.237355"], ["84290.02", "0.237355"], ["84290.26", "0"], ["84290.44", "0"], ["84292.28", "0"], ["84295.62", "0"], ["84296.95", "0.13445"], ["84305.44", "0.237355"], ["84305.53", "0.237355"], ["84309.66", "0.237355"], ["84309.75", "0.011986"], ["84310.43", "0"], ["84311.85", "0.162"], ["84312.42", "0.023731"], ["84312.97", "0.000612"], ["84313.02", "0.001333"], ["84313.27", "0.000199"]], "u": 7510611, "seq": 66889296587}, "cts": 1742142218202, "record_time": 1742142217.310092}
{"topic": "orderbook.200.BTCUSDT", "ts": 1742142218409, "type": "delta", "data": {"s": "BTCUSDT", "b": [["84262.01", "0.108729"], ["84257.81", "0"], ["84246.1", "0.02"], ["84245.71", "0.126966"], ["84244.41", "0.02"], ["84244.12", "0.117282"], ["84243.93", "0.02"], ["84243.82", "0.112238"], ["84243.5", "0.145869"], ["84243.21", "0"], ["84241.51", "0"], ["84241.03", "0"], ["84240.81", "0.108304"], ["84236.99", "0.172676"], ["84235.68", "0.177395"], ["84233.34", "0"], ["84232.72", "0.170766"], ["84232.67", "0.161598"], ["84228.85", "0.300053"], ["84227.54", "0.298402"], ["84224.53", "0.268166"], ["84222.14", "0.298437"], ["84208.56", "0"], ["84206.03", "0.162"], ["84205.75", "0.178016"], ["84205.38", "0"], ["84204.38", "0"], ["84203.67", "0"], ["84203.48", "0"], ["84203.43", "0"], ["84203.32", "0"], ["84203.2", "0"], ["84203.15", "0"], ["84202.41", "0"]], "a": [["84262.02", "0.270565"], ["84262.85", "0.00908"], ["84266.31", "0.011868"], ["84271.65", "0.070245"], ["84273.43", "0.120372"], ["84273.94", "0.10713"], ["84275.25", "0.120261"], ["84275.82", "0.120077"], ["84276.61", "0.390818"], ["84280.61", "0"], ["84281.76", "0.16988"], ["84282.08", "0.172404"], ["84283.96", "0.166162"], ["84284.82", "0.179324"], ["84288.58", "0"], ["84288.59", "0.237355"], ["84289.91", "0.296966"], ["84290.22", "0.27326"], ["84292.1", "0.291277"], ["84292.8", "0.237355"], ["84295.41", "0.29941"], ["84305.44", "0"], ["84305.53", "0"], ["84309.65", "0.356086"], ["84309.66", "0"], ["84309.75", "0"], ["84310.21", "0"], ["84310.26", "0"], ["84311.2", "0"], ["84311.85", "0"], ["84311.98", "0"], ["84312.14", "0"], ["84312.42", "0"], ["84312.97", "0"], ["84313.02", "0"], ["84313.27", "0"]], "u": 7510612, "seq": 66889297012}, "cts": 1742142218405, "record_time": 1742142217.509398}
{"topic": "orderbook.200.BTCUSDT", "ts": 1742142218610, "type": "delta", "data": {"s": "BTCUSDT", "b": [["84262.01", "0.108186"], ["84255.28", "0"], ["84247.26", "0.02"], ["84245.71", "0.217685"], ["84244.51", "0.02"], ["84244.41", "0"], ["84244.12", "0"], ["84243.82", "0"], ["84243.62", "0.105358"], ["84243.5", "0.04009"], ["84243.32", "0.112362"], ["84243.29", "0.110895"], ["84240.81", "0"], ["84240.41", "0.115683"], ["84236.99", "0"], ["84236.78", "0.166404"], ["84235.68", "0"], ["84235.18", "0.17769"], ["84232.72", "0"], ["84232.67", "0"], ["84232.27", "0.173392"], ["84232.22", "0.172261"], ["84228.85", "0"], ["84228.64", "0.275375"], ["84227.54", "0"], ["84227.04", "0.28142"], ["84224.53", "0.001333"], ["84224.13", "0.296544"], ["84223", "0.000119"], ["84222.14", "0"], ["84221.64", "0.273506"], ["84205.75", "0"], ["84205.55", "0"]], "a": [["84262.02", "0.315922"], ["84262.85", "0"], ["84271.65", "0.182008"], ["84271.96", "0.089922"], ["84272.93", "0.106869"], ["84273.43", "0"], ["84273.44", "0.119004"], ["84273.94", "0"], ["84275.04", "0.106315"], ["84275.25", "0"], ["84275.42", "0.107364"], ["84275.82", "0"], ["84276.75", "0.00125"], ["84277.8", "0.000233"], ["84281.55", "0.177845"], ["84281.58", "0.178734"], ["84281.76", "0"], ["84281.88", "0.322125"], ["84281.89", "0.059151"], ["84282.08", "0"], ["84283.56", "0.164275"], ["84283.96", "0"], ["84284.32", "0.172516"], ["84284.82", "0"], ["84289.69", "0.273593"], ["84289.72", "0.302116"], ["84289.91", "0"], ["84290.22", "0"], ["84291.7", "0.266398"], ["84292.1", "0"], ["84294.91", "0.273931"], ["84295.41", "0"], ["84309.64", "0.356093"], ["84309.65", "0"], ["84310.26", "0.000235"]], "u": 7510613, "seq": 66889297413}, "cts": 1742142218607, "record_time": 1742142217.70892}
{"topic": "orderbook.200.BTCUSDT", "ts": 1742142218809, "type": "delta", "data": {"s": "BTCUSDT", "b": [["84255.28", "0.011868"], ["84253.16", "0.022028"], ["84253.15", "0.071219"], ["84251.16", "0"], ["84251.15", "0"], ["84251.14", "0"], ["84248.36", "0.02"], ["84247.9", "0.02"], ["84247.35", "0.000297"], ["84247.26", "0"], ["84246.3", "0.02"], ["84246.1", "0"], ["84245.73", "0.02"], ["84245.72", "0"], ["84244.51", "0"], ["84243.93", "0"], ["84243.62", "0.116297"], ["84243.32", "0"], ["84243.29", "0"], ["84240.41", "0.0002"], ["84236.78", "0"], ["84235.48", "0.170619"], ["84235.18", "0"], ["84232.27", "0"], ["84232.22", "0"], ["84228.65", "0.244317"], ["84228.64", "0"], ["84227.04", "0"], ["84224.13", "0"], ["84221.94", "0.29937"], ["84221.64", "0"], ["84205.75", "0.178016"], ["84205.55", "0.001467"], ["84205.38", "0.000252"], ["84204.38", "0.00009"], ["84203.67", "0.000233"], ["84203.48", "0.001333"], ["84203.43", "0.000615"]], "a": [["84262.85", "0.011867"], ["84271.65", "0.121476"], ["84272.93", "0"], ["84273.44", "0"], ["84273.74", "0.120057"], ["84275.04", "0.000613"], ["84275.42", "0"], ["84276.62", "0.084448"], ["84276.75", "0.000789"], ["84281.55", "0"], ["84281.58", "0"], ["84283.56", "0"], ["84284.32", "0.007399"], ["84284.44", "0.824084"], ["84285.29", "0"], ["84289.69", "0"], ["84289.72", "0"], ["84291.7", "0"], ["84294.91", "0"], ["84309.63", "0.356093"], ["84309.64", "0"], ["84311.08", "0.178016"], ["84311.2", "0.0002"], ["84311.98", "0.000253"], ["84312.14", "0.001467"], ["84312.42", "0.023731"], ["84312.97", "0.000612"], ["84313.02", "0.001333"], ["84313.27", "0.000199"]], "u": 7510614, "seq": 66889297694}, "cts": 1742142218806, "record_time": 1742142217.908585}
{"topic": "orderbook.200.BTCUSDT", "ts": 1742142219009, "type": "delta", "data": {"s": "BTCUSDT", "b": [["84257.81", "0.007154"], ["84255.28", "0"], ["84253.17", "0.030159"], ["84249.46", "0.043303"], ["84249.45", "0"], ["84249", "0.02"], ["84248.36", "0"], ["84247.9", "0"], ["84247.3", "0.02"], ["84246.3", "0"], ["84245.71", "0.126966"], ["84244.04", "0.115348"], ["84243.79", "0.111118"], ["84243.74", "0.114128"], ["84243.62", "0"], ["84240.78", "0.107757"], ["84237.28", "0.162043"], ["84235.6", "0.162134"], ["84235.48", "0"], ["84232.64", "0.341582"], ["84231.68", "0.120058"], ["84229.14", "0.282927"], ["84228.65", "0"], ["84227.46", "0.270458"], ["84224.5", "0.273127"], ["84222.9", "0.231191"], ["84222.06", "0.276971"], ["84221.94", "0"], ["84216.97", "0.183016"], ["84206.03", "0"], ["84205.75", "0"], ["84205.55", "0"], ["84205.38", "0"], ["84204.38", "0"], ["84203.67", "0"], ["84203.48", "0"], ["84203.43", "0"]], "a": [["84262.02", "0.316075"], ["84262.85", "0.006284"], ["84271.65", "0.215929"], ["84273.35", "0.114593"], ["84273.74", "0"], ["84273.86", "0.106189"], ["84274.52", "0"], ["84275.54", "0.110887"], ["84275.78", "0.134537"], ["84276.62", "0.083987"], ["84277.01", "0.018264"], ["84281.88", "0.20918"], ["84282", "0.159532"], ["84282.02", "0.03561"], ["84282.05", "0.178609"], ["84283.92", "0.169119"], ["84284.74", "0.18071"], ["84290.14", "0.285593"], ["84290.19", "0.268348"], ["84292.06", "0.296298"], ["84295.32", "0.264031"], ["84309.62", "0.356094"], ["84309.63", "0"], ["84310.24", "0"], ["84310.26", "0"], ["84311.08", "0"], ["84311.2", "0"], ["84311.98", "0"], ["84312.14", "0"], ["84312.42", "0"], ["84312.97", "0"], ["84313.02", "0"], ["84313.27", "0"]], "u": 7510615, "seq": 66889298092}, "cts": 1742142219007, "record_time": 1742142218.108787}
{"topic": "orderbook.200.BTCUSDT", "ts": 1742142219209, "type": "delta", "data": {"s": "BTCUSDT", "b": [["84262.01", "0.178846"], ["84261.18", "0.008"], ["84255.35", "0.021755"], ["84255.34", "0.071217"], ["84253.17", "0"], ["84253.16", "0"], ["84253.15", "0"], ["84249.46", "0.02"], ["84249.44", "0.015092"], ["84249.01", "0.092638"], ["84249", "0"], ["84248.9", "0.02"], ["84247.81", "0.000297"], ["84246.83", "0.02"], ["84245.73", "0"], ["84245.71", "0.207273"], ["84245.47", "0.001017"], ["84245.15", "0.162"], ["84245.09", "0.003"], ["84244.04", "0"], ["84243.79", "0"], ["84243.74", "0"], ["84242.51", "0.23741"], ["84240.82", "0.249283"], ["84240.78", "0"], ["84239.14", "0.237419"], ["84238.17", "0.068395"], ["84238.14", "0"], ["84237.28", "0"], ["84235.79", "0"], ["84235.6", "0"], ["84232.64", "0"], ["84232.46", "0.26777"], ["84230.13", "0"], ["84229.42", "0"], ["84229.14", "0"], ["84228.19", "0.017802"], ["84227.46", "0"], ["84227.08", "0.071241"], ["84226.49", "0.003"], ["84225.96", "0.271637"], ["84224.5", "0"], ["84223.15", "0.023737"], ["84222.6", "0"], ["84222.06", "0"], ["84219.54", "0.11"], ["84215.19", "0.356046"], ["84215.18", "0"], ["84215.01", "0.04"], ["84215", "0.039644"], ["84213.61", "0"], ["84213.6", "0"], ["84208.56", "0.11863"]], "a": [["84262.02", "0.122905"], ["84262.85", "0"], ["84266.84", "0"], ["84267.06", "0"], ["84267.32", "0.003"], ["84267.33", "0"], ["84268.53", "0.000233"], ["84268.54", "0"], ["84269.37", "0.051081"], ["84271.65", "0.063155"], ["84271.96", "0"], ["84273.35", "0"], ["84273.86", "0"], ["84274.57", "0.020997"], ["84275.54", "0"], ["84275.78", "0"], ["84276.75", "0"], ["84277.01", "0"], ["84277.81", "0.028537"], ["84278.33", "0.000661"], ["84281.73", "0.017801"], ["84281.88", "0.345894"], ["84282", "0"], ["84282.05", "0"], ["84283.37", "0"], ["84283.92", "0"], ["84284.74", "0"], ["84285.06", "0"], ["84285.11", "0"], ["84285.8", "0"], ["84286.56", "0.051127"], ["84286.75", "0"], ["84288.59", "0"], ["84288.65", "0.176457"], ["84290.14", "0"], ["84290.19", "0"], ["84292.06", "0"], ["84292.8", "0"], ["84295.28", "0"], ["84295.32", "0"], ["84297.35", "0"], ["84299.23", "0.297308"], ["84306.32", "0.04"], ["84306.33", "0.04"], ["84307.42", "0.03181"], ["84308.04", "0"], ["84309.62", "0"], ["84309.77", "0.029801"], ["84310.24", "0.11863"], ["84310.26", "0.000235"], ["84310.87", "0.015"], ["84311.08", "0.178016"], ["84311.2", "0.0002"], ["84311.98", "0.000253"], ["84312.14", "0.001467"], ["84312.42", "0.023731"], ["84312.97", "0.000612"], ["84313.02", "0.001333"], ["84313.27", "0.000199"], ["84313.46", "0.000089"], ["84313.73", "0.0002"], ["84313.85", "0.000335"], ["84314.2", "0.246059"], ["84314.37", "0.000235"], ["84314.44", "0.089922"], ["84314.9", "0.000235"], ["84315.61", "0.027799"], ["84315.93", "0.11863"], ["84315.95", "0.001243"]], "u": 7510616, "seq": 66889298647}, "cts": 1742142219208, "record_time": 1742142218.309314}
{"topic": "orderbook.200.BTCUSDT", "ts": 1742142219410, "type": "delta", "data": {"s": "BTCUSDT", "b": [["84257.81", "0.011092"], ["84252.7", "0.015091"], ["84249.96", "0.02"], ["84249.5", "0.021"], ["84249.46", "0"], ["84249.44", "0"], ["84249.01", "0.061149"], ["84248.9", "0"], ["84248.06", "0.109228"], ["84247.8", "0.02"], ["84247.77", "0.117905"], ["84247.43", "0.02"], ["84247.35", "0"], ["84247.3", "0"], ["84246.83", "0"], ["84244.65", "0.11319"], ["84241.39", "0.267999"], ["84240.82", "0.237415"], ["84239.91", "0.177156"], ["84239.29", "0.005933"], ["84237.05", "0.170631"], ["84236.78", "0.169029"], ["84236.56", "0.008888"], ["84235.24", "0.237355"], ["84232.46", "0"], ["84232.04", "0.28926"], ["84231.03", "0.237355"], ["84228.91", "0.27642"], ["84226.82", "0.288091"], ["84225.96", "0"], ["84222.9", "0"], ["84219.54", "0"], ["84215.19", "0"], ["84210.2", "0.35606"], ["84208.21", "0"], ["84207.78", "0"], ["84207.7", "0"], ["84207.69", "0"], ["84207.64", "0"], ["84207.41", "0"]], "a": [["84262.02", "0.086192"], ["84266.22", "0.008289"], ["84266.31", "0"], ["84267.41", "0.11863"], ["84268.53", "0.003793"], ["84271.32", "0.020998"], ["84274.57", "0"], ["84276.02", "0"], ["84276.38", "0.118481"], ["84276.88", "0.111353"], ["84278.47", "0.113374"], ["84281.88", "0.136714"], ["84282.02", "0"], ["84283.53", "0"], ["84283.87", "0.068395"], ["84284.44", "0.598336"], ["84284.75", "0.169433"], ["84286.09", "0"], ["84286.34", "0.173601"], ["84286.71", "0"], ["84287.39", "0.177626"], ["84287.73", "0.008811"], ["84288.65", "0"], ["84290.1", "0"], ["84290.52", "0.000789"], ["84291.87", "0.03181"], ["84292.61", "0.280351"], ["84294.2", "0.283516"], ["84294.23", "0.237355"], ["84297.62", "0.276691"], ["84299.23", "0"], ["84306.32", "0"], ["84306.33", "0"], ["84307.02", "0.04"], ["84307.03", "0.04"], ["84307.42", "0"], ["84309.66", "0.237355"], ["84311.85", "0.162"], ["84313.85", "0"], ["84314.2", "0"], ["84314.37", "0"], ["84314.44", "0"], ["84314.9", "0"], ["84315.61", "0"], ["84315.93", "0"], ["84315.95", "0"]], "u": 7510617, "seq": 66889299271}, "cts": 1742142219405, "record_time": 1742142218.508811}
