{"topic": "orderbook.200.BTCUSDT", "ts": 1742142258610, "type": "delta", "data": {"s": "BTCUSDT", "b": [["84442.07", "0.338776"], ["84441.9", "0.144321"], ["84440.18", "0.081061"], ["84439.52", "0.041184"], ["84437.4", "0.015745"], ["84437.39", "0.0002"], ["84437.27", "0.000252"], ["84436.57", "0"], ["84435.55", "0.000234"], ["84435.36", "0.001333"], ["84435.31", "0.000611"], ["84435.23", "0.0002"], ["84435.02", "0.000234"], ["84434.91", "0.013188"], ["84434.01", "0.089922"], ["84433.77", "0.005"], ["84432.79", "0.001467"], ["84432.19", "0.006588"], ["84431.02", "0.106568"], ["84429.4", "0.000089"], ["84429.05", "0.0665"], ["84428.95", "0.0005"], ["84428.94", "0.162"], ["84428.93", "0.009898"], ["84428.09", "0.117328"], ["84427.99", "0.059017"], ["84427.84", "0"], ["84427.33", "0.07599"], ["84427.32", "0"], ["84426.15", "0.016393"], ["84425.97", "0"], ["84425.94", "0"], ["84425", "0"], ["84424.25", "0"], ["84423.81", "0.059948"], ["84423.51", "0.002715"], ["84423.45", "0"], ["84422.89", "0.175676"], ["84422.73", "0"], ["84422.71", "0"], ["84422.67", "0.089922"], ["84421.41", "0"], ["84420.85", "0.118431"], ["84419.96", "0.174857"], ["84419.28", "0"], ["84418.5", "0"], ["84417.99", "0"], ["84417.81", "0"], ["84417.71", "0.009882"], ["84417.34", "0"], ["84416.79", "0"], ["84415.74", "0"], ["84414.76", "0.289471"], ["84414.6", "0"], ["84414.58", "0"], ["84414.15", "0.071083"], ["84412.93", "0"], ["84410.37", "0"], ["84410.17", "0"], ["84409.68", "0"], ["84407.46", "0"], ["84407.02", "0.071089"], ["84406.47", "0"], ["84405.86", "0.565093"], ["84405.77", "0"], ["84399.8", "0"], ["84397.88", "0.023918"], ["84396.03", "0.355291"], ["84395.84", "0"], ["84395.09", "0.05"], ["84395.08", "0.049549"], ["84392.84", "0.003482"], ["84390.78", "0"], ["84390.39", "0"], ["84389.07", "0"], ["84388.35", "0"], ["84387.12", "0"], ["84386.37", "0"], ["84386.27", "0"], ["84386.21", "0"]], "a": [["84437.4", "0"], ["84437.44", "0"], ["84437.76", "0"], ["84439.53", "0"], ["84439.58", "0"], ["84439.67", "0"], ["84440.19", "0"], ["84440.3", "0"], ["84441.91", "0"], ["84444.4", "0"], ["84444.5", "0"], ["84444.58", "0"], ["84445.84", "0"], ["84445.97", "0"], ["84446.14", "0"], ["84447.51", "0"], ["84448.88", "0"], ["84448.89", "0.002136"], ["84448.95", "0"], ["84449.62", "0"], ["84450.32", "0"], ["84450.35", "0.0005"], ["84450.65", "0.005"], ["84451.06", "0"], ["84453.29", "0.07105"], ["84455.19", "0"], ["84455.24", "0"], ["84456.03", "0"], ["84457.3", "0"], ["84457.31", "0"], ["84457.69", "0"], ["84458.02", "0.099214"], ["84458.05", "0"], ["84460.32", "0.117711"], ["84460.52", "0"], ["84461.11", "0.112692"], ["84462.75", "0"], ["84463.05", "0.114623"], ["84463.22", "0"], ["84464.16", "0"], ["84465.21", "0.006595"], ["84465.45", "0"], ["84465.56", "0"], ["84465.82", "0"], ["84466.62", "0"], ["84467.42", "0"], ["84467.52", "0"], ["84467.6", "0"], ["84467.67", "0"], ["84469.24", "0.180964"], ["84470.7", "0.0002"], ["84471.35", "0"], ["84474.2", "0"], ["84474.92", "0"], ["84475.43", "0"], ["84475.81", "0.118431"], ["84477.19", "0"], ["84477.22", "0"], ["84477.64", "0"], ["84478", "0.000042"], ["84478.42", "0"], ["84478.6", "0.013176"], ["84479.67", "0.009892"], ["84483.67", "0"], ["84483.68", "0"], ["84484.2", "0"], ["84486.65", "0.000235"], ["84487.37", "0.014025"], ["84487.47", "0.04"], ["84487.48", "0.04"], ["84487.74", "0.017796"], ["84488.37", "0.000253"], ["84488.44", "0.0002"], ["84488.53", "0.001467"], ["84489.13", "0.07102"], ["84489.32", "0.0045"], ["84489.41", "0.0045"], ["84489.5", "0.427229"], ["84489.52", "0.0045"], ["84489.61", "0.0045"], ["84490", "0.002053"], ["84490.02", "0.003"], ["84490.14", "0.023682"], ["84490.21", "0.000612"], ["84490.25", "0.001333"], ["84490.73", "0.000335"], ["84490.77", "0.000235"], ["84490.96", "0.001"], ["84490.98", "0.0002"], ["84491.29", "0.000235"], ["84492.17", "0.000089"], ["84492.52", "0.00592"], ["84493.01", "0.000253"], ["84493.13", "0.000158"], ["84493.18", "0.001467"], ["84493.26", "0.059948"], ["84493.51", "0.0002"], ["84494.02", "0.204662"], ["84494.06", "0.0045"], ["84494.26", "0.0045"], ["84494.44", "0.000612"], ["84494.48", "0.001333"], ["84494.92", "0.118574"], ["84495.41", "0.000235"], ["84495.79", "0.405903"]], "u": 7510813, "seq": 66889441884}, "cts": 1742142258607, "record_time": 1742142257.709156}
{"topic": "orderbook.200.BTCUSDT", "ts": 1742142258810, "type": "delta", "data": {"s": "BTCUSDT", "b": [["84442.07", "0.644073"], ["84441.9", "0.045086"], ["84441.24", "0.011842"], ["84437.4", "0"], ["84435.32", "0.011843"], ["84434.92", "0.09898"], ["84434.91", "0"], ["84434.01", "0"], ["84433.63", "0.04945"], ["84433.62", "0"], ["84433.26", "0.118384"], ["84433.23", "0.119003"], ["84433.18", "0"], ["84432.81", "0.236875"], ["84431.3", "0.119373"], ["84431.14", "0"], ["84431.02", "0"], ["84430.92", "0.232359"], ["84430.91", "0.23688"], ["84430.66", "0"], ["84429.58", "0.016392"], ["84429.19", "0.236885"], ["84429.05", "0"], ["84428.95", "0"], ["84428.8", "0.044"], ["84428.5", "0.04"], ["84428.09", "0"], ["84427.48", "0.06557"], ["84427.33", "0.114567"], ["84427.1", "0.040248"], ["84426.8", "0.04"], ["84426.15", "0"], ["84425.63", "0"], ["84425.1", "0.181269"], ["84424.79", "0.167999"], ["84424.68", "0.02"], ["84424.4", "0.052"], ["84424.28", "0.236849"], ["84423.7", "0"], ["84423.51", "0.002467"], ["84423.4", "0.04"], ["84423.39", "0.02"], ["84422.89", "0"], ["84422.7", "0.224234"], ["84422.6", "0.04"], ["84422.19", "0.02"], ["84422.03", "0.02"], ["84422", "0.08"], ["84421.7", "0.04"], ["84420.85", "0"], ["84420.44", "0.02"], ["84420.06", "0.236849"], ["84419.96", "0"], ["84416.97", "0.289633"], ["84416.66", "0.265151"], ["84416.27", "0"], ["84415.84", "0"], ["84414.77", "0.237018"], ["84414.76", "0"], ["84411.62", "0"], ["84408.83", "0.017765"], ["84407.53", "0.005921"], ["84405.64", "0.000987"], ["84400.93", "0"], ["84398.98", "0.049545"], ["84398.97", "0.049545"], ["84395.09", "0"], ["84395.08", "0"], ["84392.1", "0.24702"], ["84390.57", "0"], ["84389.65", "0"], ["84389.12", "0"], ["84389", "0"], ["84388.97", "0"], ["84388.93", "0"], ["84388.89", "0"], ["84388.6", "0"], ["84388.34", "0"], ["84388.33", "0"], ["84387.92", "0"], ["84387.91", "0"], ["84387.16", "0"], ["84387.15", "0"]], "a": [["84442.08", "0.040173"], ["84451.59", "0.071052"], ["84452.95", "0.03773"], ["84452.96", "0.030131"], ["84453.29", "0"], ["84455", "0.019249"], ["84457.1", "0.043683"], ["84457.11", "0.076997"], ["84457.16", "0"], ["84458.02", "0"], ["84458.4", "0"], ["84459.4", "0"], ["84460", "0"], ["84460.32", "0"], ["84461.11", "0"], ["84461.32", "0.182937"], ["84461.7", "0"], ["84462.53", "0.108619"], ["84462.74", "0"], ["84463.01", "0.106238"], ["84463.05", "0"], ["84463.32", "0.117196"], ["84463.4", "0"], ["84463.7", "0.056"], ["84464.2", "0.04"], ["84464.49", "0.237018"], ["84464.5", "0"], ["84464.7", "0"], ["84465.1", "0"], ["84465.3", "0.173902"], ["84465.64", "0"], ["84467.9", "0.04"], ["84468.09", "0.13963"], ["84469.24", "0"], ["84469.5", "0.112"], ["84469.52", "0.162107"], ["84470", "0.044"], ["84470.5", "0.04"], ["84470.68", "0.073633"], ["84471.19", "0.175419"], ["84471.45", "0.167161"], ["84473.92", "0.17684"], ["84474.23", "0.641387"], ["84475.24", "0"], ["84475.81", "0"], ["84476.37", "0"], ["84477.65", "0.281051"], ["84479.13", "0.236849"], ["84479.9", "0.000987"], ["84480.03", "0.0008"], ["84482.33", "0.00951"], ["84483.35", "0.236849"], ["84484.49", "0.297029"], ["84484.63", "0"], ["84487.47", "0"], ["84487.48", "0"], ["84488.02", "0.236849"], ["84488.37", "0.040253"], ["84488.38", "0.04"], ["84489.02", "0.029772"], ["84491.14", "0.162"], ["84491.48", "0.023684"], ["84493.26", "0"], ["84493.51", "0"], ["84494.02", "0"], ["84494.06", "0"], ["84494.26", "0"], ["84494.44", "0"], ["84494.48", "0"], ["84494.92", "0"], ["84495.41", "0"], ["84495.79", "0"]], "u": 7510814, "seq": 66889442708}, "cts": 1742142258807, "record_time": 1742142257.908689}
{"topic": "orderbook.200.BTCUSDT", "ts": 1742142259009, "type": "delta", "data": {"s": "BTCUSDT", "b": [["84442.07", "0.644321"], ["84440.44", "0.000333"], ["84438.3", "0.000099"], ["84437.76", "0.0002"], ["84437.39", "0"], ["84434.92", "0.154607"], ["84434.35", "0.003"], ["84434.32", "0.016391"], ["84434.15", "0.003"], ["84433.94", "0.003"], ["84433.77", "0.120494"], ["84433.74", "0.108075"], ["84433.26", "0"], ["84433.23", "0"], ["84433.2", "0.04"], ["84432.21", "0.065566"], ["84431.66", "0.115455"], ["84431.3", "0"], ["84429.58", "0"], ["84427.48", "0"], ["84427.33", "0.261134"], ["84427.1", "0.215419"], ["84426.8", "0.08"], ["84426.4", "0.04"], ["84425.61", "0.162343"], ["84425.1", "0.0402"], ["84424.79", "0"], ["84423.8", "0"], ["84423.53", "0.168667"], ["84422.73", "0.02"], ["84422.39", "0.159764"], ["84422.03", "0"], ["84422", "0.04"], ["84421.13", "0.02"], ["84420.49", "0"], ["84420.44", "0"], ["84420.3", "0"], ["84419.7", "0"], ["84419", "0"], ["84418.69", "0.000252"], ["84418.6", "0"], ["84417.9", "0"], ["84417.48", "0.268972"], ["84417.3", "0"], ["84417", "0.023685"], ["84416.97", "0"], ["84416.9", "0"], ["84416.66", "0"], ["84415.4", "0.289675"], ["84414.39", "0"], ["84404.39", "0.05"], ["84404.38", "0.049544"], ["84398.98", "0"], ["84398.97", "0"], ["84396.74", "0.175419"], ["84390.95", "0"], ["84390.57", "0.000335"]], "a": [["84451.37", "0.031428"], ["84452.95", "0"], ["84452.96", "0.0002"], ["84455", "0"], ["84457.1", "0.026358"], ["84457.11", "0"], ["84459.73", "0.019248"], ["84461.84", "0.076992"], ["84462.32", "0.02267"], ["84462.53", "0"], ["84462.98", "0.107433"], ["84463.01", "0"], ["84463.04", "0.113276"], ["84463.32", "0"], ["84463.83", "0.109185"], ["84465.9", "0.04"], ["84466.62", "0.107742"], ["84467.56", "0"], ["84467.8", "0.052"], ["84469.52", "0"], ["84471.13", "0.023362"], ["84471.45", "0"], ["84471.96", "0.180684"], ["84473.92", "0"], ["84474.42", "0.16789"], ["84474.76", "0.174504"], ["84477.65", "0"], ["84478.99", "0.023685"], ["84479.58", "0"], ["84482.89", "0.291606"], ["84483.77", "0.035532"], ["84483.8", "0"], ["84484.49", "0"], ["84488.02", "0"], ["84488.37", "0.000253"], ["84488.38", "0"], ["84489.36", "0.04"], ["84489.37", "0.04"], ["84489.41", "0"], ["84489.61", "0"]], "u": 7510815, "seq": 66889443121}, "cts": 1742142259007, "record_time": 1742142258.108639}
{"topic": "orderbook.200.BTCUSDT", "ts": 1742142259209, "type": "delta", "data": {"s": "BTCUSDT", "b": [["84443.79", "0.321612"], ["84443.76", "0.082177"], ["84443.75", "0.106977"], ["84442.07", "0"], ["84441.9", "0"], ["84440.3", "0.0002"], ["84440.18", "0.01"], ["84439.53", "0.061191"], ["84438.04", "0.005"], ["84437.44", "0.001467"], ["84437.39", "0.006728"], ["84436.66", "0.065562"], ["84436.56", "0.014843"], ["84436.48", "0.01639"], ["84436.23", "0.105485"], ["84434.92", "0.138267"], ["84434.9", "0"], ["84434.32", "0.113491"], ["84433.77", "0.005"], ["84433.74", "0"], ["84433.64", "0.059483"], ["84433.6", "0.044"], ["84433", "0.04"], ["84432.21", "0"], ["84432.19", "0"], ["84431.66", "0"], ["84431.5", "0.04"], ["84429.1", "0.052"], ["84429.04", "0"], ["84428.8", "0"], ["84428.5", "0"], ["84428.1", "0.217652"], ["84427.99", "0"], ["84427.3", "0.04"], ["84426.8", "0.04"], ["84425.61", "0"], ["84424.87", "0.169795"], ["84424.68", "0"], ["84424.4", "0"], ["84423.53", "0"], ["84423.4", "0"], ["84423.39", "0"], ["84422.73", "0"], ["84422.6", "0"], ["84422.39", "0"], ["84422.19", "0"], ["84422.14", "0.023544"], ["84422", "0"], ["84421.7", "0"], ["84421.41", "0.023684"], ["84421.13", "0"], ["84420.58", "0.071078"], ["84419.97", "0.279791"], ["84417.71", "0"], ["84417.48", "0"], ["84417", "0"], ["84416.46", "0"], ["84415.4", "0"], ["84414.3", "0.263692"], ["84410.71", "1.576629"], ["84409.41", "0.000252"], ["84407.51", "0.023684"], ["84407.02", "0"], ["84406.04", "0.004572"], ["84405.85", "0"], ["84404.39", "0"], ["84404.38", "0"], ["84403.79", "0.05"], ["84403.78", "0.049544"], ["84401.53", "0.023684"], ["84400.72", "0.023684"], ["84400.31", "0.355272"], ["84400.22", "0.01188"], ["84400.1", "0.39838"], ["84396.03", "0"], ["84393.17", "0.013715"], ["84392.29", "0"]], "a": [["84442.08", "0"], ["84442.83", "0"], ["84443.76", "0"], ["84451.37", "0.001467"], ["84451.59", "0"], ["84455.14", "0.005"], ["84455.49", "0.040819"], ["84455.5", "0.029758"], ["84456.42", "0.031204"], ["84456.53", "0.071048"], ["84459.73", "0"], ["84461.84", "0"], ["84462.98", "0"], ["84463.04", "0"], ["84463.83", "0"], ["84464.18", "0.019248"], ["84465.52", "0.119904"], ["84466.03", "0.107993"], ["84466.29", "0.07699"], ["84466.31", "0.117943"], ["84466.62", "0"], ["84467.31", "0"], ["84468.09", "0"], ["84470.21", "0.005921"], ["84470.47", "0.139626"], ["84470.68", "0.178268"], ["84471.13", "0"], ["84471.96", "0"], ["84472.53", "0.168891"], ["84474.42", "0"], ["84474.44", "0.174388"], ["84474.76", "0"], ["84476.15", "0"], ["84476.91", "0.161454"], ["84478.5", "0"], ["84478.99", "0"], ["84479.13", "0"], ["84481.63", "0"], ["84482.89", "0"], ["84483.35", "0"], ["84483.77", "0"], ["84485.45", "0.02464"], ["84487.27", "0.023684"], ["84489.36", "0"], ["84489.37", "0"], ["84490.14", "0"], ["84490.66", "0.023684"], ["84492.86", "0.04"], ["84492.87", "0.04"], ["84493.26", "0.059948"], ["84493.51", "0.0002"], ["84493.7", "0.071016"], ["84493.96", "0.0045"], ["84494", "0.0045"], ["84494.02", "0.204662"], ["84494.16", "0.0045"], ["84494.2", "0.0045"], ["84494.44", "0.000612"]], "u": 7510816, "seq": 66889444175}, "cts": 1742142259208, "record_time": 1742142258.307738}
{"topic": "orderbook.200.BTCUSDT", "ts": 1742142259410, "type": "delta", "data": {"s": "BTCUSDT", "b": [["84443.79", "0.327531"], ["84443.76", "0.038806"], ["84443.75", "0.104058"], ["84442.96", "0.011842"], ["84439.4", "0.01639"], ["84438.8", "0.044"], ["84438.3", "0"], ["84438.1", "0.04"], ["84436.7", "0.04"], ["84436.48", "0"], ["84436.23", "0"], ["84435.9", "0.04"], ["84435.79", "0.115272"], ["84435.32", "0"], ["84434.92", "0.199154"], ["84434.81", "0.236869"], ["84434.32", "0"], ["84433.3", "0.04"], ["84433.2", "0"], ["84432.81", "0"], ["84431.9", "0.04"], ["84431.7", "0.04"], ["84431.3", "0.000797"], ["84429.28", "0.157418"], ["84428.1", "0.04"], ["84427.35", "0.118422"], ["84427.1", "0.175419"], ["84426.63", "0.010147"], ["84426.28", "0.02"], ["84425.1", "0.0002"], ["84424.99", "0.02"], ["84424.87", "0"], ["84424.33", "0.02"], ["84424.19", "0.008863"], ["84423.79", "0.02"], ["84422.73", "0.02"], ["84422.14", "0.013454"], ["84421.15", "0.293992"], ["84420.58", "0"], ["84420.06", "0"], ["84419.97", "0"], ["84418.89", "0.090472"], ["84414.3", "0"], ["84407.34", "0.000987"], ["84405.86", "0.023684"], ["84405.64", "0"], ["84404.19", "0.11"], ["84400.32", "0.355272"], ["84400.31", "0"], ["84399.01", "0.059146"], ["84397.4", "0.003368"], ["84393.15", "0"], ["84393.11", "0"], ["84392.84", "0"], ["84392.72", "0"], ["84392.68", "0"], ["84392.67", "0"], ["84392.55", "0"], ["84392.18", "0"], ["84392.1", "0"], ["84391.01", "0"], ["84390.84", "0"], ["84390.62", "0"], ["84390.57", "0"]], "a": [["84443.8", "0.002517"], ["84449.48", "0.025151"], ["84450.65", "0"], ["84453.38", "0.07105"], ["84455.14", "0.034751"], ["84455.49", "0"], ["84455.5", "0.0002"], ["84456.42", "0.000612"], ["84456.53", "0"], ["84457.1", "0"], ["84457.32", "0"], ["84458.13", "0"], ["84458.46", "0"], ["84458.77", "0.028776"], ["84460.65", "0.029311"], ["84461.32", "0.115525"], ["84464.49", "0"], ["84465.21", "0"], ["84465.51", "0.237018"], ["84465.52", "0"], ["84466.03", "0"], ["84466.31", "0"], ["84467.5", "0.118125"], ["84469.82", "0.006747"], ["84470.21", "0"], ["84472.28", "0.00588"], ["84472.53", "0"], ["84473.27", "0.008752"], ["84474", "0.179734"], ["84474.23", "0.201559"], ["84474.44", "0"], ["84476.91", "0"], ["84478.78", "0"], ["84479.67", "0"], ["84479.9", "0"], ["84481.65", "0.000987"], ["84482.13", "0.26892"], ["84482.32", "0.118422"], ["84483.98", "0.010121"], ["84484.07", "0.019104"], ["84484.81", "1.550052"], ["84489.02", "0"], ["84492.86", "0"], ["84492.87", "0"], ["84493.66", "0.04"], ["84493.67", "0.04"], ["84494.48", "0.001333"], ["84494.92", "0.118574"], ["84495.41", "0.000235"], ["84495.61", "0.0045"], ["84495.65", "0.0045"], ["84495.79", "0.405903"], ["84495.81", "0.0045"]], "u": 7510817, "seq": 66889444761}, "cts": 1742142259407, "record_time": 1742142258.509045}
{"topic": "orderbook.200.BTCUSDT", "ts": 1742142259609, "type": "delta", "data": {"s": "BTCUSDT", "b": [["84443.79", "0"], ["84443.76", "0"], ["84443.75", "0"], ["84442.96", "0"], ["84441.24", "0"], ["84440.44", "0"], ["84440.3", "0"], ["84440.18", "0"], ["84440.02", "0.000099"], ["84439.53", "0.000611"], ["84439.52", "0"], ["84439.4", "0"], ["84438.8", "0"], ["84438.1", "0"], ["84438.04", "0"], ["84437.39", "0"], ["84436.7", "0"], ["84436.66", "0"], ["84436.56", "0.011843"], ["84435.9", "0"], ["84435.79", "0"], ["84435.35", "0.0005"], ["84434.92", "0"], ["84434.81", "0"], ["84433.77", "0"], ["84433.63", "0.04895"], ["84433.6", "0"], ["84433.3", "0"], ["84433", "0"], ["84431.7", "0"], ["84431.5", "0"], ["84431.3", "0"], ["84430.92", "0.063663"], ["84430.91", "0"], ["84430.7", "0.04"], ["84429.45", "0.005"], ["84429.28", "0"], ["84429.19", "0"], ["84428.94", "0"], ["84428.9", "0.04"], ["84428.1", "0"], ["84427.98", "0.065823"], ["84427.35", "0"], ["84427.3", "0"], ["84427.1", "0"], ["84426.8", "0"], ["84426.63", "0"], ["84426.4", "0"], ["84426.28", "0"], ["84424.99", "0"], ["84424.28", "0"], ["84424.19", "0"], ["84423.81", "0"], ["84423.79", "0"], ["84423.57", "0.009828"], ["84422.7", "0.134353"], ["84422.67", "0"], ["84422.4", "0.04"], ["84422.14", "0"], ["84422.1", "0.04"], ["84421.41", "0"], ["84421.15", "0"], ["84419.03", "0.175419"], ["84418.97", "0"], ["84418.6", "0.02"], ["84417.49", "0.02"], ["84416.62", "0"], ["84416.39", "0.02"], ["84414.77", "0"], ["84414.41", "0"], ["84414.15", "0"], ["84412.39", "0.008453"], ["84410.71", "0"], ["84409.58", "0.011709"], ["84408.09", "0.013665"], ["84407.84", "0"], ["84407.53", "0"], ["84407.51", "0"], ["84407.27", "0"], ["84406.63", "0"], ["84404.68", "0.05"], ["84404.19", "0"], ["84403.79", "0"], ["84403.78", "0"], ["84402.87", "0.049548"], ["84401.53", "0"], ["84400.72", "0"], ["84400.32", "0"], ["84400.3", "0"], ["84398.3", "0"], ["84397.31", "0.162"], ["84396.74", "0"], ["84396.2", "0.24702"], ["84394.74", "0"], ["84393.15", "0.001333"], ["84393.11", "0.000613"], ["84392.72", "0.001394"], ["84392.55", "0.005951"], ["84392.18", "0.0002"], ["84391.01", "0.001467"], ["84390.95", "0.177633"], ["84390.84", "0.000252"], ["84390.62", "0.023684"], ["84390.57", "0.000335"], ["84389.65", "0.0002"], ["84389.12", "0.000234"], ["84389", "0.000119"], ["84388.97", "0.023684"], ["84388.93", "0.001333"], ["84388.89", "0.000613"], ["84388.6", "0.000234"], ["84388.33", "0.005921"], ["84387.92", "0.04"], ["84387.91", "0.03964"], ["84387.16", "0.059948"], ["84387.15", "0.000089"], ["84387.12", "0.0002"], ["84386.37", "0.001467"], ["84386.27", "0.005503"], ["84386.21", "0.237018"], ["84386.2", "0.000252"], ["84384.71", "0.001333"], ["84384.67", "0.000613"], ["84384.64", "0.023684"], ["84384.59", "0.0002"], ["84384.48", "0.000234"], ["84383.96", "0.000234"], ["84383.83", "0.023684"], ["84383.14", "0.0025"], ["84382.38", "0.015"], ["84382.05", "0.0002"], ["84381.73", "0.001467"], ["84381.56", "0.000252"], ["84381", "0.237018"], ["84380.99", "0.023684"], ["84380.49", "0.001333"], ["84380.45", "0.000611"], ["84379.84", "0.000234"], ["84379.32", "0.000234"], ["84378.79", "0.089922"], ["84378.7", "0.000089"], ["84377.09", "0.001467"], ["84376.95", "0.047984"], ["84376.92", "0.000252"], ["84376.76", "0.015"], ["84376.4", "0.000357"]], "a": [["84440.03", "0.187699"], ["84440.44", "0.003"], ["84440.45", "0.222069"], ["84441.25", "0.178505"], ["84443.11", "0.059948"], ["84443.76", "0.028423"], ["84443.79", "0.0004"], ["84443.8", "0.150897"], ["84444.88", "0.005"], ["84449.19", "0.005"], ["84449.48", "0.000234"], ["84449.62", "0.000089"], ["84450.35", "0"], ["84450.55", "0.001477"], ["84452.24", "0.001833"], ["84452.94", "0.237018"], ["84452.95", "0.053497"], ["84452.96", "0.029658"], ["84453.38", "0"], ["84454.17", "0.089922"], ["84454.68", "0.006828"], ["84455.13", "0.059948"], ["84455.14", "0"], ["84456.59", "0"], ["84457.56", "0.024647"], ["84457.78", "0.076996"], ["84458.02", "0.019249"], ["84458.13", "0.000089"], ["84458.49", "0.005921"], ["84458.74", "0.073521"], ["84458.75", "0.237018"], ["84458.77", "0.000235"], ["84460.65", "0.000612"], ["84460.7", "0.162"], ["84461.32", "0"], ["84461.81", "0.175419"], ["84462.2", "0.000848"], ["84462.32", "0"], ["84463.69", "0.035234"], ["84464.18", "0"], ["84465.31", "0"], ["84466.29", "0"], ["84467.5", "0"], ["84467.75", "0.029772"], ["84468.68", "0.010242"], ["84469.36", "0.071037"], ["84469.82", "0"], ["84470.68", "0.073633"], ["84470.82", "0.089922"], ["84471.19", "0"], ["84471.88", "0.027942"], ["84472.28", "0"], ["84473.27", "0"], ["84473.44", "0.0235"], ["84474", "0"], ["84474.23", "0"], ["84474.92", "0.236844"], ["84475.76", "0.008933"], ["84476.34", "0.005954"], ["84477.2", "0.355353"], ["84479.13", "0.236844"], ["84481.82", "0.023684"], ["84482.13", "0"], ["84482.32", "0"], ["84483.8", "0.236844"], ["84483.98", "0"], ["84488.02", "0.236844"], ["84489.13", "0"], ["84493.13", "0"], ["84493.18", "0"], ["84493.26", "0"], ["84493.51", "0"], ["84493.66", "0"], ["84493.67", "0"], ["84493.7", "0"], ["84493.96", "0"], ["84494", "0"], ["84494.02", "0"], ["84494.16", "0"], ["84494.2", "0"], ["84494.44", "0"], ["84494.48", "0"], ["84494.92", "0"], ["84495.41", "0"], ["84495.61", "0"], ["84495.65", "0"], ["84495.79", "0"], ["84495.81", "0"]], "u": 7510818, "seq": 66889446025}, "cts": 1742142259608, "record_time": 1742142258.709601}
{"topic": "orderbook.200.BTCUSDT", "ts": 1742142259809, "type": "delta", "data": {"s": "BTCUSDT", "b": [["84440.02", "0"], ["84439.53", "0.016605"], ["84436.56", "0"], ["84435.32", "0.000526"], ["84434.35", "0"], ["84434.15", "0"], ["84433.94", "0"], ["84433.64", "0.031087"], ["84432.78", "0.011843"], ["84431.9", "0"], ["84430.92", "0"], ["84430.7", "0"], ["84429.45", "0"], ["84429.1", "0"], ["84428.93", "0"], ["84428.9", "0"], ["84428.37", "0.016392"], ["84428.17", "0.037477"], ["84427.34", "0"], ["84427.33", "0"], ["84425.02", "0.005"], ["84424.76", "0"], ["84424.33", "0"], ["84423.57", "0.003"], ["84422.73", "0"], ["84422.7", "0"], ["84422.42", "0.000296"], ["84422.41", "0.052853"], ["84422.4", "0"], ["84422.1", "0"], ["84420.4", "0.044"], ["84419.04", "0.059948"], ["84419.03", "0"], ["84419", "0.006839"], ["84418.89", "0"], ["84418.61", "0.024573"], ["84418.6", "0"], ["84418.2", "0.04"], ["84418.18", "0.000547"], ["84417.49", "0"], ["84416.5", "0.04"], ["84416.39", "0"], ["84414.7", "0.04"], ["84414.23", "0"], ["84414.16", "0.000797"], ["84413.56", "0.009898"], ["84412.84", "0.118428"], ["84412.39", "0"], ["84412.05", "0.236856"], ["84411.24", "0.023686"], ["84409.79", "0.175419"], ["84409.58", "0.001467"], ["84408.78", "0.139623"], ["84407.83", "0.236856"], ["84407.52", "1.582655"], ["84407.34", "0"], ["84406.04", "0"], ["84405.86", "0"], ["84405.05", "0.008453"], ["84405.03", "0.010258"], ["84404.68", "0"], ["84403.07", "0.000987"], ["84402.87", "0"], ["84400.23", "0.237018"], ["84400.11", "0.283373"], ["84398.89", "0"], ["84397.88", "0.000234"], ["84395.99", "0.071099"], ["84394.74", "0.177642"], ["84394.51", "0.05"], ["84394.5", "0.049552"], ["84394.04", "0.005921"], ["84393.17", "0"], ["84388.92", "0.071105"], ["84388.86", "0.162"], ["84388.05", "0.004582"], ["84386.22", "0.355349"], ["84380.41", "0.162"], ["84377.09", "0"], ["84376.95", "0"], ["84376.92", "0"], ["84376.76", "0"], ["84376.4", "0"]], "a": [["84439.54", "0.145226"], ["84440.01", "0.0549"], ["84440.03", "0"], ["84440.44", "0.05"], ["84440.45", "0.005"], ["84441.25", "0.126068"], ["84442.83", "0.0002"], ["84443.11", "0"], ["84443.76", "0"], ["84443.8", "0.001333"], ["84444.62", "0.016271"], ["84444.63", "0.011842"], ["84447.89", "0.021257"], ["84449.19", "0"], ["84450.07", "0.006839"], ["84450.23", "0.035426"], ["84450.55", "0"], ["84452.93", "0.128313"], ["84452.95", "0"], ["84452.96", "0.0002"], ["84453.73", "0.019249"], ["84454.68", "0"], ["84457.56", "0"], ["84458", "0.052"], ["84458.01", "0.129829"], ["84458.02", "0"], ["84458.74", "0"], ["84459.7", "0.052"], ["84462.2", "0.0006"], ["84463.57", "0.00951"], ["84464.04", "0.010258"], ["84465.09", "0.013672"], ["84465.54", "0.019104"], ["84466.81", "0.0008"], ["84467.75", "0"], ["84468.31", "0.118428"], ["84468.68", "0"], ["84469.5", "0.06"], ["84470.37", "0.023685"], ["84471.14", "0.236856"], ["84471.88", "0"], ["84473.02", "0.071034"], ["84473.44", "0"], ["84473.76", "0.023685"], ["84474.91", "0.281136"], ["84474.92", "0"], ["84475.36", "0.236856"], ["84476.66", "0.011842"], ["84477.2", "0"], ["84477.38", "0.000987"], ["84478", "0.000161"], ["84478.6", "0"], ["84478.97", "0.029772"], ["84479.12", "0.355347"], ["84479.13", "0.177642"], ["84480.03", "0"], ["84481.65", "0"], ["84481.74", "0.023685"], ["84481.75", "0.473476"], ["84481.82", "0"], ["84482.33", "0"], ["84482.75", "0.322704"], ["84483.8", "0"], ["84484.07", "0"], ["84485.07", "0.027942"], ["84488.02", "0"], ["84490.77", "0"], ["84490.96", "0"], ["84490.98", "0"], ["84491.14", "0"], ["84491.29", "0"], ["84491.48", "0"], ["84492.17", "0"], ["84492.52", "0"], ["84493.01", "0"]], "u": 7510819, "seq": 66889447253}, "cts": 1742142259806, "record_time": 1742142258.908404}
{"topic": "orderbook.200.BTCUSDT", "ts": 1742142260009, "type": "delta", "data": {"s": "BTCUSDT", "b": [["84435.76", "0.000099"], ["84435.32", "0.011843"], ["84432.99", "0"], ["84432.43", "0.0001"], ["84428.17", "0.020247"], ["84426.07", "0.003"], ["84425.87", "0.003"], ["84422.66", "0.000296"], ["84422.44", "0.000296"], ["84422.42", "0"], ["84422.41", "0.033463"], ["84419.94", "0.105213"], ["84419.9", "0.04"], ["84419.04", "0"], ["84418.7", "0.04"], ["84416.1", "0.052"], ["84414.71", "0.059948"], ["84414.4", "0.04"], ["84413.4", "0.04"], ["84413.38", "0.164649"], ["84413.1", "0.04"], ["84407.4", "0.236856"], ["84405.19", "0.266432"], ["84403.18", "0.236856"], ["84394.99", "0"], ["84394.51", "0"], ["84394.5", "0"], ["84394.43", "0.0013"], ["84394.11", "0.05"], ["84394.1", "0.049553"], ["84386.22", "0"], ["84383.14", "0"], ["84382.38", "0"], ["84382.05", "0"], ["84381.73", "0"], ["84381.56", "0"], ["84381", "0"], ["84380.99", "0"], ["84380.49", "0"], ["84380.45", "0"], ["84380.41", "0"], ["84379.84", "0"], ["84379.32", "0"], ["84378.79", "0"], ["84378.7", "0"]], "a": [["84439.54", "0.107482"], ["84441.54", "0.0002"], ["84443.31", "0.000099"], ["84443.75", "0.011842"], ["84444.63", "0"], ["84446.29", "0.011841"], ["84450.23", "0"], ["84451.88", "0.0347"], ["84451.89", "0.11322"], ["84454.6", "0.056"], ["84456", "0.04"], ["84458.44", "0.162576"], ["84461", "0.044"], ["84461.4", "0.04"], ["84463.7", "0"], ["84464.1", "0.06"], ["84465.77", "0.000634"], ["84465.9", "0"], ["84466.63", "0.267761"], ["84467.8", "0"], ["84474.91", "0"], ["84477.2", "0.355355"], ["84479.12", "0"], ["84479.54", "0.0012"], ["84482.4", "0"], ["84489.5", "0"], ["84489.52", "0"], ["84490", "0"], ["84490.02", "0"], ["84490.21", "0"], ["84490.25", "0"], ["84490.66", "0"], ["84490.73", "0"]], "u": 7510820, "seq": 66889447428}, "cts": 1742142260006, "record_time": 1742142259.107835}
{"topic": "orderbook.200.BTCUSDT", "ts": 1742142260209, "type": "delta", "data": {"s": "BTCUSDT", "b": [["84439.53", "0"], ["84438.7", "0.003184"], ["84435.32", "0"], ["84432.78", "0"], ["84428.17", "0"], ["84422.68", "0.000296"], ["84422.67", "0.000296"], ["84422.66", "0"], ["84422.44", "0"], ["84422.41", "0.05486"], ["84421.94", "0.071077"], ["84419.94", "0"], ["84419", "0"], ["84418.61", "0.06125"], ["84418.18", "0"], ["84414.71", "0"], ["84414.63", "0.006974"], ["84413.39", "0.175413"], ["84413.38", "0"], ["84405.19", "0"], ["84400.23", "0"], ["84400.1", "0"], ["84399.01", "0"], ["84395.99", "0"], ["84394.67", "0"], ["84394.49", "0.023815"], ["84394.11", "0"], ["84394.1", "0"], ["84393.71", "0.05"], ["84393.7", "0.049553"], ["84390.83", "0.04"], ["84390.82", "0.039645"], ["84387.92", "0"], ["84387.91", "0"], ["84385", "0.071108"], ["84383.14", "0.0025"], ["84382.38", "0.015"], ["84382.05", "0.0002"], ["84381.73", "0.001467"], ["84381.56", "0.000252"], ["84381", "0.237018"], ["84380.99", "0.023684"], ["84380.49", "0.001333"], ["84380.45", "0.000611"]], "a": [["84438.71", "0.162975"], ["84439.53", "0.068253"], ["84439.54", "0.043686"], ["84440.01", "0"], ["84440.37", "0.011842"], ["84441.25", "0.055007"], ["84443.75", "0.012453"], ["84443.79", "0"], ["84444.61", "0.237018"], ["84444.62", "0.06639"], ["84444.79", "0.089922"], ["84445.26", "0.006974"], ["84445.62", "0.023685"], ["84447.99", "0.162"], ["84450.07", "0"], ["84450.94", "0.022573"], ["84451.88", "0"], ["84451.89", "0"], ["84454.3", "0.04"], ["84457.33", "0.024054"], ["84458.01", "0.185398"], ["84458.44", "0"], ["84458.98", "0.010461"], ["84462.26", "0.236856"], ["84462.42", "0.071043"], ["84464.04", "0"], ["84464.2", "0"], ["84466.48", "0.236856"], ["84466.63", "0"], ["84469.5", "0"], ["84470", "0"], ["84470.5", "0"], ["84471.85", "0.023686"], ["84473.02", "0"], ["84475.35", "0.355363"], ["84477.2", "0"], ["84480.92", "0.473476"], ["84481.75", "0"], ["84483.08", "0.04"], ["84483.09", "0.04"], ["84484.81", "0"], ["84488.37", "0"], ["84488.44", "0"], ["84488.53", "0"], ["84489.32", "0"]], "u": 7510821, "seq": 66889447779}, "cts": 1742142260207, "record_time": 1742142259.309055}
{"topic": "orderbook.200.BTCUSDT", "ts": 1742142260410, "type": "delta", "data": {"s": "BTCUSDT", "b": [["84435.76", "0"], ["84435.35", "0"], ["84434.49", "0.011843"], ["84431.95", "0.011843"], ["84430.26", "0.0005"], ["84428.72", "0.025165"], ["84426.08", "0.003"], ["84426.07", "0"], ["84425.88", "0.003"], ["84425.87", "0"], ["84425.54", "0"], ["84423.57", "0"], ["84423.37", "0"], ["84422.7", "0.000296"], ["84422.67", "0"], ["84421.94", "0"], ["84419.71", "0.007019"], ["84419.38", "0.115282"], ["84414.63", "0"], ["84414.41", "0.059948"], ["84413.39", "0.126019"], ["84407.52", "0"], ["84400.12", "0.237018"], ["84400.11", "0"], ["84397.43", "0.071097"], ["84394.81", "0.05"], ["84394.8", "0.049551"], ["84393.71", "0"], ["84393.7", "0"], ["84391.39", "0.237018"], ["84390.83", "0.039644"], ["84386.46", "0.058938"], ["84385", "0"], ["84381.01", "0.355358"], ["84380.49", "0"], ["84380.45", "0"]], "a": [["84438.71", "0.049677"], ["84439.53", "0"], ["84439.54", "0.035529"], ["84440.37", "0"], ["84443.31", "0"], ["84444.6", "0.042666"], ["84444.61", "0"], ["84444.62", "0"], ["84445.26", "0"], ["84445.62", "0"], ["84447.15", "0.0005"], ["84447.89", "0"], ["84447.99", "0"], ["84450.2", "0.007019"], ["84451.34", "0.112591"], ["84452.24", "0.001333"], ["84457.1", "0.04"], ["84457.9", "0.162109"], ["84458.2", "0.06"], ["84458.98", "0"], ["84462.26", "0"], ["84462.42", "0"], ["84463.69", "0"], ["84463.84", "0.010528"], ["84464.1", "0"], ["84465.77", "0"], ["84466.48", "0"], ["84467.9", "0"], ["84472.91", "1.568496"], ["84475.35", "0"], ["84479.12", "0.355351"], ["84479.13", "0"], ["84482.64", "0.150751"], ["84488.37", "0.000253"], ["84488.44", "0.0002"], ["84488.53", "0.001467"], ["84489.5", "0.427229"], ["84490", "0.002053"], ["84490.02", "0.003"], ["84490.21", "0.000612"], ["84490.25", "0.001333"]], "u": 7510822, "seq": 66889448016}, "cts": 1742142260407, "record_time": 1742142259.509165}
{"topic": "orderbook.200.BTCUSDT", "ts": 1742142260610, "type": "delta", "data": {"s": "BTCUSDT", "b": [["84438.7", "0"], ["84437.87", "0.013027"], ["84434.93", "0.000099"], ["84433.64", "0"], ["84426.37", "0.036854"], ["84424.8", "0.04"], ["84424.58", "0.007048"], ["84423.81", "0.058985"], ["84422.78", "0.000296"], ["84422.7", "0"], ["84422.68", "0"], ["84422.41", "0"], ["84420.96", "0.113012"], ["84420.93", "0.119398"], ["84419.9", "0"], ["84419.71", "0"], ["84419.38", "0"], ["84419.23", "0.10924"], ["84417.82", "0.175419"], ["84415.38", "0.02"], ["84414.09", "0.02"], ["84412.84", "0"], ["84412.73", "0.173592"], ["84412.67", "0.169336"], ["84409.91", "0.01056"], ["84409.79", "0"], ["84409.48", "0.17368"], ["84407.83", "0"], ["84407.4", "0"], ["84405.03", "0"], ["84404.54", "0.28446"], ["84404.48", "0.301056"], ["84403.18", "0.236858"], ["84400.56", "1.523275"], ["84398.96", "0.236858"], ["84398.83", "0.29229"], ["84394.81", "0"], ["84394.8", "0"], ["84394.74", "0"], ["84394.71", "0.0502"], ["84394.7", "0.049551"], ["84393.27", "0.071101"], ["84388.92", "0"], ["84382.38", "0"], ["84382.05", "0"], ["84381.73", "0"], ["84381.56", "0"], ["84381.01", "0"], ["84381", "0"], ["84380.99", "0"]], "a": [["84437.88", "0.131028"], ["84438.7", "0.002"], ["84438.71", "0.046103"], ["84439.53", "0.042894"], ["84440.45", "0"], ["84440.65", "0.005"], ["84442.48", "0.000099"], ["84443.75", "0.000611"], ["84444.6", "0"], ["84444.79", "0"], ["84445.46", "0.004042"], ["84446.29", "0"], ["84450.12", "0.101332"], ["84450.2", "0"], ["84450.47", "0.110016"], ["84450.94", "0"], ["84451.2", "0.108769"], ["84451.26", "0.117329"], ["84451.34", "0"], ["84454.17", "0"], ["84454.99", "0.007048"], ["84457.06", "0.023664"], ["84457.76", "0.175034"], ["84457.9", "0"], ["84459.46", "0.172585"], ["84461.8", "0.063805"], ["84461.94", "0.171889"], ["84463.84", "0"], ["84465.95", "0.292757"], ["84466.48", "0.236858"], ["84467.65", "0.289652"], ["84468.58", "0.010572"], ["84469.36", "0"], ["84470.7", "0.237058"], ["84471.14", "0"], ["84472.6", "0.28613"], ["84478.97", "0"], ["84479.11", "0.355354"], ["84479.12", "0"], ["84482.26", "0.029772"], ["84482.64", "0"], ["84485.07", "0"], ["84486.08", "0.027942"], ["84488.44", "0"], ["84488.53", "0"], ["84489.5", "0"], ["84490", "0"], ["84490.02", "0"], ["84490.21", "0"], ["84490.25", "0"]], "u": 7510823, "seq": 66889448815}, "cts": 1742142260607, "record_time": 1742142259.707831}
{"topic": "orderbook.200.BTCUSDT", "ts": 1742142260809, "type": "delta", "data": {"s": "BTCUSDT", "b": [["84437.87", "0.176359"], ["84437.83", "0.07679"], ["84437.82", "0.071063"], ["84436.61", "0.016391"], ["84434.93", "0"], ["84434.73", "0.089922"], ["84434.5", "0.065567"], ["84430.24", "0.005"], ["84430.18", "0.007111"], ["84428.72", "0.048996"], ["84428.37", "0"], ["84427.98", "0.000252"], ["84427.74", "0.089922"], ["84426.97", "0.236891"], ["84425.28", "0.236896"], ["84425.02", "0"], ["84424.8", "0.08"], ["84424.58", "0"], ["84423.99", "0.059948"], ["84420.97", "0.277782"], ["84420.96", "0"], ["84420.93", "0"], ["84420.9", "0.04"], ["84420.3", "0.04"], ["84420.22", "0.010682"], ["84420.2", "0.04"], ["84419.23", "0"], ["84418.61", "0.097142"], ["84417.35", "0.11843"], ["84417.28", "0.02"], ["84416.27", "0.236861"], ["84415.99", "0.02"], ["84415.38", "0"], ["84414.79", "0.02"], ["84414.09", "0"], ["84413.74", "0.089922"], ["84412.73", "0"], ["84412.67", "0"], ["84412.05", "0"], ["84411.55", "0.071086"], ["84411.24", "0"], ["84409.91", "0"], ["84409.48", "0"], ["84405.86", "0.023686"], ["84405.83", "0.237018"], ["84405.11", "0.071091"], ["84405.05", "0"], ["84404.55", "0.355273"], ["84404.54", "0"], ["84404.48", "0"], ["84403.18", "0"], ["84403.07", "0"], ["84401.43", "0.000987"], ["84399.26", "0.099856"], ["84398.96", "0"], ["84398.83", "0"], ["84397.87", "0.023686"], ["84397.43", "0"], ["84395.51", "0.05"], ["84395.5", "0.04955"], ["84394.74", "0.177645"], ["84394.71", "0.0002"], ["84394.7", "0"], ["84393.27", "0"], ["84384.71", "0"], ["84384.67", "0"], ["84384.64", "0"], ["84384.59", "0"], ["84384.48", "0"], ["84383.96", "0"], ["84383.83", "0"], ["84383.14", "0"]], "a": [["84437.88", "0.01499"], ["84438.7", "0"], ["84438.71", "0"], ["84439.53", "0"], ["84440.65", "0"], ["84441.25", "0"], ["84441.54", "0"], ["84442.48", "0"], ["84444.88", "0"], ["84445.46", "0"], ["84449.12", "0.005"], ["84449.62", "0"], ["84450.12", "0"], ["84450.47", "0"], ["84451.2", "0.000253"], ["84451.26", "0"], ["84452.93", "0"], ["84452.94", "0"], ["84453.73", "0"], ["84454.3", "0"], ["84454.6", "0"], ["84454.99", "0"], ["84455.13", "0"], ["84456", "0"], ["84456.42", "0.01428"], ["84456.93", "0.059948"], ["84457.06", "0"], ["84457.33", "0"], ["84457.75", "0.207543"], ["84457.76", "0"], ["84457.78", "0"], ["84458", "0"], ["84458.01", "0"], ["84458.2", "0"], ["84458.75", "0"], ["84459.45", "0.237018"], ["84459.46", "0"], ["84459.7", "0"], ["84459.9", "0.056"], ["84460.39", "0.007111"], ["84460.57", "0.000448"], ["84460.7", "0"], ["84461", "0"], ["84461.4", "0"], ["84461.81", "0"], ["84461.93", "0.019247"], ["84461.94", "0"], ["84463.57", "0"], ["84464.04", "0.076987"], ["84465.95", "0"], ["84466.1", "0.044"], ["84466.48", "0"], ["84466.6", "0.04"], ["84467.65", "0"], ["84468.31", "0"], ["84468.58", "0"], ["84469.65", "0.175419"], ["84470.37", "0"], ["84470.68", "0.725956"], ["84470.7", "0.0002"], ["84470.82", "0"], ["84471.85", "0"], ["84472.6", "0"], ["84473.76", "0"], ["84473.86", "0.010667"], ["84475.72", "0.000987"], ["84476.66", "0"], ["84477.38", "0"], ["84479.11", "0"], ["84480.09", "0.473476"], ["84480.92", "0"], ["84481.74", "0"], ["84482.26", "0"], ["84482.75", "0"], ["84483.08", "0"], ["84483.09", "0"], ["84486.08", "0"], ["84488.44", "0.0002"], ["84488.53", "0.001467"], ["84489.5", "0.427229"], ["84490", "0.002053"], ["84490.02", "0.003"], ["84490.21", "0.000612"], ["84490.25", "0.001333"], ["84490.66", "0.023684"], ["84490.73", "0.000335"], ["84490.77", "0.000235"], ["84490.96", "0.001"], ["84490.98", "0.0002"], ["84491.29", "0.000235"], ["84491.38", "0.0045"], ["84491.42", "0.0045"], ["84491.48", "0.023684"], ["84491.58", "0.0045"], ["84491.62", "0.0045"], ["84491.98", "0.04"], ["84491.99", "0.04"], ["84492.17", "0.000089"], ["84492.52", "0.00592"], ["84493.01", "0.000253"], ["84493.13", "0.000158"], ["84493.18", "0.001467"], ["84493.26", "0.059948"], ["84493.51", "0.0002"], ["84494", "0.0045"], ["84494.02", "0.204662"], ["84494.2", "0.0045"], ["84494.22", "0.02126"], ["84494.44", "0.000612"], ["84494.48", "0.001333"], ["84494.92", "0.118574"], ["84495.41", "0.000235"], ["84495.56", "0.023686"], ["84495.65", "0.0045"], ["84495.79", "0.405903"], ["84495.85", "0.0045"], ["84495.94", "0.000235"], ["84496.05", "0.0002"], ["84496.46", "0.177633"], ["84497.66", "0.000253"]], "u": 7510824, "seq": 66889450090}, "cts": 1742142260808, "record_time": 1742142259.910676}
{"topic": "orderbook.200.BTCUSDT", "ts": 1742142261010, "type": "delta", "data": {"s": "BTCUSDT", "b": [["84437.87", "0.013027"], ["84437.83", "0"], ["84437.82", "0"], ["84434.73", "0"], ["84434.51", "0.042096"], ["84434.1", "0.000099"], ["84428.72", "0"], ["84427.74", "0"], ["84426.98", "0.17951"], ["84426.97", "0"], ["84426.9", "0.175419"], ["84426.37", "0.000296"], ["84425.28", "0"], ["84425", "0.052"], ["84423.99", "0"], ["84423.17", "0.11699"], ["84422.86", "0.11172"], ["84420.98", "0.135826"], ["84420.97", "0.162"], ["84420.22", "0"], ["84420", "0.04"], ["84419.3", "0.008453"], ["84418.88", "0.02"], ["84418.7", "0"], ["84417.82", "0"], ["84417.59", "0.02"], ["84417.28", "0"], ["84416.94", "0.02"], ["84416.5", "0"], ["84416.29", "0.02"], ["84416.1", "0"], ["84415.99", "0"], ["84415.34", "0.02"], ["84415.27", "0.010758"], ["84414.79", "0"], ["84414.7", "0"], ["84414.66", "0.159675"], ["84414.4", "0"], ["84413.82", "0.160025"], ["84413.74", "0"], ["84413.4", "0"], ["84413.39", "0"], ["84413.1", "0"], ["84412.05", "0.236861"], ["84411.55", "0"], ["84408.42", "0.277936"], ["84406.47", "0.265707"], ["84405.83", "0"], ["84404.55", "0"], ["84403.17", "0.283885"], ["84402.31", "0.058959"], ["84402.3", "0.049541"], ["84401.45", "0.071094"], ["84401.44", "0.004627"], ["84395.51", "0"], ["84395.5", "0"], ["84394.74", "0"], ["84394.49", "0"], ["84388.56", "0.013881"], ["84388.05", "0"], ["84387.08", "0.035533"], ["84384.71", "0.001333"], ["84384.67", "0.000613"], ["84384.64", "0.023684"]], "a": [["84437.88", "0.063421"], ["84441.65", "0.000099"], ["84442.34", "0.000153"], ["84448.96", "0.017718"], ["84454.81", "0.114774"], ["84455.5", "0.007313"], ["84455.98", "0.007175"], ["84456.92", "0.110313"], ["84457.1", "0"], ["84457.75", "0"], ["84458.11", "0.119871"], ["84460.39", "0"], ["84461.8", "0"], ["84462.6", "0.04"], ["84463.23", "0.162"], ["84464.8", "0.06"], ["84465.3", "0.001467"], ["84466.2", "0.052"], ["84466.28", "0.16878"], ["84466.3", "0.203544"], ["84467.21", "0.089922"], ["84467.9", "0.052"], ["84469.33", "0.010763"], ["84469.9", "0.278078"], ["84470.68", "0.073633"], ["84471.14", "0.236861"], ["84473.57", "0.029772"], ["84473.86", "0"], ["84474.5", "0.293108"], ["84474.92", "0.236861"], ["84476.94", "0.26379"], ["84478.42", "0.223798"], ["84479.63", "0.027942"], ["84479.81", "0.00951"], ["84480.08", "0.355345"], ["84482.16", "0.035533"], ["84489.72", "0.0045"], ["84489.77", "0.0045"], ["84489.92", "0.0045"], ["84489.97", "0.0045"], ["84491.14", "0.162"], ["84491.42", "0"], ["84491.62", "0"], ["84491.98", "0"], ["84491.99", "0"], ["84492.52", "0"], ["84493.01", "0"], ["84493.13", "0"], ["84493.18", "0"], ["84493.26", "0"], ["84493.51", "0"], ["84494", "0"], ["84494.02", "0"], ["84494.2", "0"], ["84494.22", "0"], ["84494.44", "0"], ["84494.48", "0"], ["84494.92", "0"], ["84495.41", "0"], ["84495.56", "0"], ["84495.65", "0"], ["84495.79", "0"], ["84495.85", "0"], ["84495.94", "0"], ["84496.05", "0"], ["84496.46", "0"], ["84497.66", "0"]], "u": 7510825, "seq": 66889450835}, "cts": 1742142261006, "record_time": 1742142260.109078}
{"topic": "orderbook.200.BTCUSDT", "ts": 1742142261209, "type": "delta", "data": {"s": "BTCUSDT", "b": [["84437.87", "0"], ["84437.76", "0.003103"], ["84436.61", "0"], ["84434.51", "0"], ["84434.5", "0"], ["84433.63", "0"], ["84431.96", "0.030501"], ["84430.26", "0"], ["84430.24", "0"], ["84430.18", "0"], ["84429.78", "0.029294"], ["84429.77", "0.02833"], ["84429.76", "0.016392"], ["84429.43", "0.0005"], ["84427.66", "0.000296"], ["84427.65", "0.065573"], ["84426.99", "0.000296"], ["84426.98", "0.045021"], ["84426.9", "0"], ["84426.37", "0"], ["84425.92", "0.005"], ["84425", "0"], ["84423.81", "0"], ["84423.17", "0"], ["84422.86", "0"], ["84422.78", "0"], ["84420.97", "0"], ["84420.3", "0"], ["84420.2", "0"], ["84419.3", "0"], ["84418.88", "0"], ["84418.61", "0.140245"], ["84417.94", "0.02"], ["84417.78", "0.007217"], ["84417.59", "0"], ["84417.35", "0"], ["84417.2", "0.04"], ["84416.94", "0"], ["84416.29", "0"], ["84416.24", "0.02"], ["84416.08", "0.02"], ["84415.83", "0.175419"], ["84415.34", "0"], ["84415.27", "0"], ["84414.69", "0.02"], ["84414.66", "0"], ["84414.41", "0"], ["84413.82", "0"], ["84410.76", "0.180506"], ["84409.65", "0.008453"], ["84408.78", "0"], ["84408.42", "0"], ["84406.48", "0.059948"], ["84406.47", "0"], ["84405.82", "0"], ["84405.11", "0"], ["84403.17", "0"], ["84402.56", "0.26493"], ["84402.31", "0.008959"], ["84402.3", "0"], ["84402.07", "0.010834"], ["84401.45", "0"], ["84400.13", "0.23727"], ["84400.12", "0"], ["84399.26", "0"], ["84399.14", "0.003"], ["84396.06", "0.288939"], ["84396.01", "0.099098"], ["84395.25", "0.071099"], ["84387.08", "0.013027"], ["84385.65", "0.177505"], ["84384.59", "0.0002"], ["84384.48", "0.000234"], ["84383.96", "0.000234"], ["84383.83", "0.023684"], ["84383.14", "0.0025"], ["84382.38", "0.015"], ["84382.05", "0.0002"], ["84381.73", "0.001467"], ["84381.56", "0.000252"], ["84381", "0.237018"], ["84380.99", "0.023684"], ["84380.49", "0.001333"], ["84380.45", "0.000611"]], "a": [["84437.77", "0.087481"], ["84437.87", "0.052959"], ["84437.88", "0.15401"], ["84440.07", "0.005"], ["84440.43", "0.018667"], ["84442.09", "0.009979"], ["84442.34", "0"], ["84444.49", "0.005"], ["84444.63", "0.011842"], ["84445.1", "0.007222"], ["84446.32", "0.0005"], ["84447.15", "0"], ["84447.9", "0.05441"], ["84448.11", "0.059948"], ["84448.96", "0.000234"], ["84449.12", "0"], ["84449.62", "0.000089"], ["84450.89", "0.089922"], ["84454.11", "0.237018"], ["84454.12", "0.012864"], ["84454.78", "0.162"], ["84454.81", "0"], ["84455.04", "0.019248"], ["84455.5", "0.0002"], ["84455.98", "0"], ["84456.42", "0.00086"], ["84457.15", "0.076993"], ["84458.11", "0"], ["84458.37", "0.010834"], ["84460.4", "0.052"], ["84460.57", "0.0002"], ["84461.62", "0.175419"], ["84461.93", "0"], ["84464.04", "0.264255"], ["84464.3", "0.04"], ["84466.28", "0"], ["84466.3", "0.04"], ["84469.33", "0"], ["84469.65", "0"], ["84469.9", "0"], ["84470.7", "0.237061"], ["84470.9", "0.023317"], ["84471.14", "0"], ["84474.5", "0"], ["84474.51", "0.11843"], ["84474.92", "0"], ["84475.36", "0"], ["84476.93", "0.355363"], ["84476.94", "0"], ["84479.82", "0.023686"], ["84479.98", "0.473476"], ["84480.08", "0"], ["84480.09", "0"], ["84490.96", "0"], ["84490.98", "0"], ["84491.14", "0"], ["84491.29", "0"], ["84491.38", "0"], ["84491.48", "0"], ["84491.58", "0"], ["84492.17", "0"]], "u": 7510826, "seq": 66889451620}, "cts": 1742142261208, "record_time": 1742142260.30906}
{"topic": "orderbook.200.BTCUSDT", "ts": 1742142261409, "type": "delta", "data": {"s": "BTCUSDT", "b": [["84437.76", "0.041102"], ["84436.93", "0.007581"], ["84434.49", "0"], ["84432", "0.021791"], ["84431.99", "0.030344"], ["84431.96", "0"], ["84431.04", "0.070797"], ["84431.03", "0.071069"], ["84431.01", "0.011843"], ["84429.78", "0"], ["84429.77", "0"], ["84429.32", "0.04895"], ["84429.31", "0"], ["84429.11", "0"], ["84428.91", "0"], ["84427.88", "0.003"], ["84427.68", "0.003"], ["84427.66", "0"], ["84427.48", "0.003"], ["84426.99", "0"], ["84426.98", "0"], ["84426.08", "0"], ["84425.88", "0"], ["84424.8", "0"], ["84424.11", "0.113942"], ["84423.86", "0.036698"], ["84422.71", "0.000296"], ["84422.2", "0.04"], ["84421.63", "0.115628"], ["84420.99", "0.000296"], ["84420.98", "0"], ["84420.9", "0"], ["84420.86", "0.162"], ["84420.4", "0"], ["84420.06", "0.236861"], ["84420", "0"], ["84418.2", "0"], ["84417.94", "0"], ["84417.64", "0"], ["84417.2", "0"], ["84416.24", "0"], ["84416.08", "0"], ["84415.84", "0.236861"], ["84415.83", "0"], ["84415.63", "0.161154"], ["84415.6", "0.04"], ["84415.3", "0.04"], ["84414.69", "0"], ["84413.46", "0.173498"], ["84412.67", "0.17843"], ["84412.22", "0.139614"], ["84411.94", "0.175419"], ["84410.76", "0"], ["84410.08", "0.019095"], ["84407.83", "0.236861"], ["84407.74", "0.285409"], ["84407.46", "0.273533"], ["84406.45", "0.010904"], ["84405.86", "0"], ["84405.22", "0"], ["84402.56", "0"], ["84402.3", "0.003494"], ["84402.07", "0"], ["84401.58", "0.071094"], ["84397.87", "0"], ["84397.4", "0"], ["84397.23", "0.023338"], ["84396.06", "0"], ["84396.01", "0"], ["84395.12", "0.05"], ["84395.11", "0.04955"], ["84392.24", "0.04"], ["84392.23", "0.039642"], ["84390.83", "0"], ["84390.82", "0"], ["84387.08", "0"], ["84385.65", "0"], ["84381.01", "0.355347"], ["84380.45", "0"]], "a": [["84437.77", "0.042011"], ["84437.87", "0"], ["84437.88", "0"], ["84441.65", "0"], ["84443.07", "0.005921"], ["84445.55", "0.000153"], ["84447.9", "0.018768"], ["84450.35", "0.028136"], ["84453.52", "0.107773"], ["84453.97", "0.158644"], ["84454.12", "0"], ["84454.78", "0"], ["84455.2", "0.04"], ["84455.4", "0.056"], ["84456.42", "0.000612"], ["84456.76", "0.110731"], ["84456.9", "0.040248"], ["84458.49", "0"], ["84458.8", "0.052"], ["84461.6", "0.044"], ["84462.2", "0.0406"], ["84462.7", "0.236861"], ["84464.04", "0"], ["84464.96", "0.172657"], ["84465.77", "0.133473"], ["84466.48", "0.236861"], ["84466.92", "0.236861"], ["84467.9", "0"], ["84468.74", "0.282291"], ["84470.37", "0.023686"], ["84470.65", "0.277554"], ["84473.57", "0"], ["84473.76", "0.023686"], ["84474.58", "0.023686"], ["84475.58", "0.262808"], ["84476.93", "0"], ["84478.42", "0"], ["84479.63", "0"], ["84480.39", "0.029772"], ["84481.74", "0.023686"], ["84482.68", "0.355349"], ["84483.48", "0.04"], ["84483.49", "0.04"], ["84488.37", "0"], ["84488.44", "0"], ["84488.53", "0"], ["84489.5", "0"], ["84489.72", "0"], ["84489.77", "0"], ["84489.92", "0"], ["84489.97", "0"], ["84490", "0"], ["84490.02", "0"], ["84490.21", "0"], ["84490.25", "0"], ["84490.66", "0"], ["84490.73", "0"], ["84490.77", "0"]], "u": 7510827, "seq": 66889452963}, "cts": 1742142261407, "record_time": 1742142260.508701}
{"topic": "orderbook.200.BTCUSDT", "ts": 1742142261609, "type": "delta", "data": {"s": "BTCUSDT", "b": [["84437.76", "0.003103"], ["84436.93", "0"], ["84432.01", "0.030239"], ["84432", "0"], ["84431.95", "0"], ["84431.04", "0"], ["84431.03", "0"], ["84431.01", "0.000135"], ["84429.76", "0"], ["84427.88", "0"], ["84427.68", "0"], ["84427.48", "0"], ["84426.63", "0.016393"], ["84424.11", "0"], ["84423.86", "0"], ["84422.71", "0"], ["84422.58", "0.000296"], ["84422.2", "0"], ["84421.63", "0"], ["84420.99", "0"], ["84420.86", "0"], ["84420.06", "0"], ["84419.01", "0.000296"], ["84418.61", "0.199941"], ["84418.6", "0.04"], ["84417.6", "0.044"], ["84417.3", "0.04"], ["84415.84", "0"], ["84415.63", "0"], ["84415.6", "0"], ["84415.3", "0"], ["84415.1", "0.04"], ["84413.6", "0.04"], ["84413.46", "0"], ["84412.67", "0"], ["84409.83", "0.003422"], ["84409.54", "0.023686"], ["84407.74", "0"], ["84407.46", "0"], ["84402.3", "0"], ["84401.58", "0"], ["84400.57", "0.237018"], ["84400.13", "0.000252"], ["84397.23", "0"], ["84395.12", "0"], ["84395.11", "0"], ["84393.72", "0.05"], ["84393.71", "0.049551"], ["84392.24", "0"], ["84392.23", "0"], ["84391.62", "0.071102"], ["84391.14", "0.04"], ["84391.13", "0.039643"], ["84381.01", "0"], ["84380.45", "0.000611"], ["84379.84", "0.000234"], ["84379.32", "0.000234"], ["84378.79", "0.089922"], ["84378.7", "0.000089"], ["84377.22", "0.038585"], ["84377.09", "0.001467"], ["84376.92", "0.000252"], ["84376.76", "0.015"], ["84376.4", "0.000357"], ["84376.36", "0.001"], ["84376.27", "0.001333"], ["84376.23", "0.000611"], ["84375.9", "0.001243"], ["84375.71", "0.39838"], ["84375.2", "0.000234"]], "a": [["84437.77", "0.142011"], ["84438.59", "0.013707"], ["84438.6", "0.010162"], ["84441.54", "0.000099"], ["84444.12", "0.023686"], ["84445.55", "0"], ["84447.88", "0.089733"], ["84447.89", "0.237018"], ["84447.9", "0.0002"], ["84449.37", "0.034067"], ["84450.35", "0"], ["84451.9", "0.019249"], ["84453.52", "0"], ["84453.59", "0.04992"], ["84453.97", "0.169591"], ["84454.67", "0.162"], ["84455.04", "0"], ["84455.2", "0.040248"], ["84455.88", "0.024422"], ["84456.76", "0"], ["84456.9", "0.04"], ["84459.9", "0"], ["84462.6", "0"], ["84464.3", "0"], ["84464.96", "0"], ["84466.1", "0"], ["84466.2", "0"], ["84466.6", "0"], ["84468.74", "0"], ["84470.65", "0"], ["84470.7", "0.0002"], ["84475.58", "0"], ["84479.82", "0"], ["84479.97", "0.355364"], ["84482.68", "0"], ["84488.25", "0.027942"], ["84488.37", "0.000253"], ["84488.44", "0.0002"], ["84488.53", "0.001467"], ["84489.5", "0.427229"]], "u": 7510828, "seq": 66889453468}, "cts": 1742142261608, "record_time": 1742142260.708848}
{"topic": "orderbook.200.BTCUSDT", "ts": 1742142261810, "type": "delta", "data": {"s": "BTCUSDT", "b": [["84437.76", "0.005533"], ["84433.55", "0.003841"], ["84431.01", "0.011843"], ["84429.33", "0.034933"], ["84422.58", "0"], ["84418.87", "0.000296"], ["84418.72", "0.000296"], ["84418.61", "0.123268"], ["84418.55", "0.107546"], ["84417.3", "0"], ["84416.9", "0.04"], ["84416", "0.04"], ["84415.84", "0.236861"], ["84414", "0.052"], ["84412.3", "0.04"], ["84412.02", "0.168059"], ["84411.62", "0.236861"], ["84410.5", "0.04"], ["84410.2", "0.04"], ["84403.85", "0.295707"], ["84401.51", "0.071094"], ["84396.8", "0.024227"], ["84394.74", "0.177646"], ["84391.62", "0"], ["84379.84", "0"], ["84379.32", "0"], ["84378.79", "0"], ["84378.7", "0"], ["84377.22", "0"], ["84377.09", "0"], ["84376.92", "0"], ["84376.76", "0"], ["84376.4", "0"], ["84376.36", "0"], ["84376.27", "0"], ["84376.23", "0"], ["84375.9", "0"], ["84375.71", "0"], ["84375.2", "0"]], "a": [["84437.77", "0.141731"], ["84438.6", "0.002139"], ["84444.12", "0"], ["84447.88", "0.018628"], ["84447.89", "0"], ["84449.37", "0.065059"], ["84450.42", "0.107978"], ["84454.26", "0.236861"], ["84456.95", "0.16775"], ["84457", "0.04"], ["84458.4", "0.06"], ["84458.48", "0.236861"], ["84461.55", "0.133272"], ["84462.26", "0.236861"], ["84462.7", "0"], ["84466.92", "0"], ["84477.2", "0.355363"], ["84479.13", "0.177646"], ["84479.97", "0"], ["84488.25", "0"], ["84488.37", "0"], ["84488.44", "0"], ["84488.53", "0"], ["84489.5", "0"]], "u": 7510829, "seq": 66889453619}, "cts": 1742142261807, "record_time": 1742142260.909895}
{"topic": "orderbook.200.BTCUSDT", "ts": 1742142262010, "type": "delta", "data": {"s": "BTCUSDT", "b": [["84437.76", "0.105533"], ["84433.55", "0.005384"], ["84432.96", "0.0001"], ["84432.43", "0"], ["84432.41", "0.030228"], ["84432.4", "0.071068"], ["84432.01", "0"], ["84431.99", "0"], ["84429.43", "0"], ["84429.32", "0.04945"], ["84422.81", "0.003"], ["84422.61", "0.003"], ["84422.41", "0.003"], ["84422.11", "0.007415"], ["84420.96", "0.000296"], ["84420.04", "0.000296"], ["84419.01", "0"], ["84418.87", "0"], ["84418.72", "0"], ["84418.61", "0.223181"], ["84418.55", "0"], ["84417.78", "0"], ["84415.85", "0.059948"], ["84412.02", "0"], ["84403.85", "0"], ["84395.25", "0.121099"], ["84395.24", "0.049549"], ["84394.96", "0.0013"], ["84394.43", "0"], ["84393.72", "0"], ["84393.71", "0"], ["84381.01", "0.35536"], ["84380.19", "0.004738"]], "a": [["84437.77", "0.141567"], ["84438.6", "0.008303"], ["84440.07", "0.0051"], ["84445.1", "0"], ["84446.21", "0.0005"], ["84446.32", "0"], ["84449.37", "0.06693"], ["84450.42", "0"], ["84451.34", "0.007415"], ["84455.2", "0.04"], ["84455.4", "0.056248"], ["84456.95", "0"], ["84458.37", "0"], ["84462.7", "0.236861"], ["84464.29", "0.011122"], ["84464.8", "0"], ["84466.3", "0"], ["84470.68", "0.541973"], ["84477.2", "0"], ["84478.07", "0.0013"], ["84479.54", "0"], ["84482.68", "0.355346"], ["84488.25", "0.027942"], ["84488.37", "0.000253"], ["84488.44", "0.0002"]], "u": 7510830, "seq": 66889453850}, "cts": 1742142262007, "record_time": 1742142261.109018}
{"topic": "orderbook.200.BTCUSDT", "ts": 1742142262210, "type": "delta", "data": {"s": "BTCUSDT", "b": [["84433.55", "0.011843"], ["84432.41", "0.02132"], ["84422.26", "0.070238"], ["84422.22", "0.000296"], ["84422.2", "0.000296"], ["84420.96", "0"], ["84420.04", "0"], ["84416.27", "0"], ["84415.84", "0"], ["84412.05", "0"], ["84411.62", "0"], ["84407.83", "0"], ["84400.57", "0.796088"], ["84396.85", "0.05"], ["84396.84", "0.049548"], ["84395.25", "0.071099"], ["84395.24", "0"], ["84390.95", "0"], ["84381.01", "0.355344"], ["84380.41", "0.162"], ["84379.84", "0.000234"], ["84379.32", "0.000234"], ["84378.79", "0.089922"]], "a": [["84437.77", "0.138016"], ["84438.59", "0"], ["84438.6", "0"], ["84440.43", "0"], ["84449.37", "0.075143"], ["84450.89", "0"], ["84453.97", "0"], ["84454.26", "0"], ["84455.4", "0.056"], ["84455.85", "0.000501"], ["84458.48", "0"], ["84461.55", "0"], ["84462.26", "0"], ["84462.7", "0"], ["84465.77", "0"], ["84466.48", "0"], ["84479.13", "0"], ["84480.39", "0"], ["84482.68", "0"], ["84483.47", "0.355342"], ["84488.25", "0"], ["84488.53", "0.001467"], ["84489.5", "0.427229"], ["84489.72", "0.0045"], ["84489.77", "0.0045"], ["84489.92", "0.0045"], ["84489.97", "0.0045"], ["84490", "0.002053"], ["84490.02", "0.003"], ["84490.21", "0.000612"], ["84490.25", "0.001333"], ["84490.66", "0.023684"], ["84490.73", "0.000335"], ["84490.77", "0.000235"], ["84490.96", "0.001"], ["84490.98", "0.0002"]], "u": 7510831, "seq": 66889454226}, "cts": 1742142262207, "record_time": 1742142261.309104}
{"topic": "orderbook.200.BTCUSDT", "ts": 1742142262409, "type": "delta", "data": {"s": "BTCUSDT", "b": [["84437.76", "0.176596"], ["84436.93", "0.011843"], ["84432.41", "0"], ["84432.4", "0"], ["84430.31", "0.005"], ["84429.33", "0.134955"], ["84428.66", "0.236886"], ["84427.6", "0.003"], ["84427.4", "0.003"], ["84427.2", "0.003"], ["84426.98", "0.118003"], ["84426.97", "0.236891"], ["84426.37", "0.007516"], ["84425.28", "0.020008"], ["84424.77", "0.113415"], ["84422.27", "0.023701"], ["84422.26", "0"], ["84422.2", "0.040296"], ["84422.11", "0"], ["84421.1", "0.04"], ["84420.86", "0.162"], ["84420.12", "0.175419"], ["84420.06", "0.236861"], ["84419.3", "0.052"], ["84418.61", "0.099913"], ["84417.6", "0.084"], ["84416.9", "0"], ["84416.68", "0.02"], ["84416.25", "0.11843"], ["84416", "0"], ["84415.84", "0.236861"], ["84415.7", "0.04"], ["84415.4", "0.04"], ["84415.39", "0.02"], ["84414.74", "0.02"], ["84414.43", "0.011286"], ["84413.99", "0.02"], ["84413.33", "0.163973"], ["84411.94", "0"], ["84409.34", "0.071087"], ["84406.49", "0.237018"], ["84406.45", "0"], ["84406.05", "0.264759"], ["84405.47", "0.089922"], ["84397.35", "0.05"], ["84397.34", "0.049547"], ["84396.85", "0"], ["84396.84", "0"], ["84396.49", "0.04"], ["84396.48", "0.039638"], ["84395.25", "0"], ["84391.4", "0.355309"], ["84391.14", "0"], ["84391.13", "0"], ["84386.2", "0"], ["84384.71", "0"], ["84384.67", "0"], ["84384.64", "0"], ["84384.59", "0"], ["84384.48", "0"], ["84383.96", "0"], ["84383.83", "0"], ["84383.14", "0"], ["84382.38", "0"], ["84382.05", "0"], ["84381.73", "0"], ["84381.56", "0"], ["84381.01", "0"], ["84381", "0"], ["84380.99", "0"], ["84380.49", "0"], ["84380.45", "0"], ["84380.41", "0"], ["84380.19", "0"], ["84379.84", "0"], ["84379.32", "0"], ["84378.79", "0"]], "a": [["84437.77", "0.118097"], ["84440.07", "0"], ["84442.09", "0"], ["84444.52", "0.000865"], ["84444.63", "0"], ["84447.88", "0"], ["84448.11", "0"], ["84449.37", "0"], ["84451.34", "0"], ["84453.59", "0"], ["84454.07", "0.102396"], ["84454.11", "0"], ["84454.67", "0"], ["84455.85", "0.000253"], ["84455.88", "0"], ["84456.77", "0.007517"], ["84456.89", "0.059948"], ["84456.92", "0.162171"], ["84456.93", "0"], ["84457", "0"], ["84457.43", "0.000248"], ["84457.78", "0.139581"], ["84458.4", "0"], ["84459.44", "0.237018"], ["84459.45", "0"], ["84460.69", "0.025998"], ["84462", "0.04"], ["84463.5", "0.06"], ["84464.29", "0"], ["84467.21", "0"], ["84469.55", "0.011276"], ["84470.47", "0"], ["84473.85", "0.276457"], ["84474.51", "0"], ["84476.23", "0.291388"], ["84480.92", "0.04"], ["84480.93", "0.04"], ["84483.47", "0"], ["84483.48", "0"], ["84483.49", "0"], ["84489.49", "0.35531"], ["84489.68", "0.0045"], ["84489.72", "0"], ["84489.88", "0.0045"], ["84489.92", "0"], ["84491.29", "0.000235"], ["84491.48", "0.023684"], ["84491.79", "0.236861"], ["84492.17", "0.000089"], ["84492.52", "0.00592"], ["84493.01", "0.000253"], ["84493.13", "0.000158"]], "u": 7510832, "seq": 66889454862}, "cts": 1742142262407, "record_time": 1742142261.507626}
{"topic": "orderbook.200.BTCUSDT", "ts": 1742142262609, "type": "delta", "data": {"s": "BTCUSDT", "b": [["84437.76", "0.17944"], ["84428.66", "0"], ["84426.98", "0.087774"], ["84426.97", "0"], ["84425.28", "0"], ["84424.93", "0.106907"], ["84424.91", "0.110094"], ["84424.77", "0"], ["84422.8", "0.044"], ["84422.78", "0.118211"], ["84422.66", "0.112634"], ["84422.27", "0.197237"], ["84418.8", "0.04"], ["84418.61", "0.204127"], ["84417.08", "0.02"], ["84416.74", "0.179531"], ["84416.68", "0"], ["84415.79", "0.02"], ["84415.39", "0"], ["84414.61", "0.164099"], ["84414.39", "0.02"], ["84414", "0"], ["84413.99", "0"], ["84413.5", "0.172951"], ["84413.33", "0"], ["84412.3", "0"], ["84410.5", "0"], ["84410.2", "0"], ["84408.57", "0.288228"], ["84406.05", "0"], ["84402.88", "0.278681"], ["84400.56", "0"], ["84399.25", "0.05"], ["84399.24", "0.049545"], ["84397.35", "0"], ["84397.34", "0"], ["84396.49", "0"], ["84396.48", "0"], ["84396.38", "0.039638"], ["84396.37", "0.039638"], ["84391.4", "0"], ["84388.87", "0.355316"]], "a": [["84444.52", "0"], ["84450.79", "0.000153"], ["84454.07", "0.032285"], ["84454.34", "0.105637"], ["84454.51", "0.120153"], ["84455.13", "0.11315"], ["84456.92", "0.223797"], ["84457.43", "0"], ["84457.91", "0.109437"], ["84458.13", "0.000337"], ["84461.05", "0.178473"], ["84461.61", "0.148393"], ["84463.3", "0.158288"], ["84465.78", "0.236398"], ["84466.07", "0.174527"], ["84471.47", "0.279328"], ["84472.91", "0"], ["84473.85", "0"], ["84474.24", "0.460014"], ["84476.23", "0"], ["84480.92", "0"], ["84480.93", "0"], ["84481.02", "0.04"], ["84481.03", "0.04"], ["84487.9", "0.029772"], ["84491.14", "0.162"], ["84491.29", "0"], ["84491.48", "0"], ["84491.79", "0"], ["84492.17", "0"], ["84492.52", "0"], ["84493.01", "0"], ["84493.13", "0"]], "u": 7510833, "seq": 66889455242}, "cts": 1742142262607, "record_time": 1742142261.708858}
{"topic": "orderbook.200.BTCUSDT", "ts": 1742142262810, "type": "delta", "data": {"s": "BTCUSDT", "b": [["84437.76", "0.008377"], ["84436.93", "0"], ["84431.14", "0.034828"], ["84431.02", "0.031676"], ["84429.33", "0.034933"], ["84426.98", "0"], ["84424.93", "0"], ["84424.91", "0"], ["84424.75", "0.000296"], ["84422.81", "0.300186"], ["84422.78", "0"], ["84422.66", "0"], ["84422.27", "0"], ["84422.22", "0"], ["84422.2", "0.04"], ["84418.98", "0.02"], ["84417.84", "0.02"], ["84417.6", "0.04"], ["84417.34", "0.02"], ["84417.08", "0"], ["84416.74", "0"], ["84416.59", "0.02"], ["84415.85", "0"], ["84415.79", "0"], ["84415.74", "0.02"], ["84414.74", "0"], ["84414.61", "0"], ["84414.39", "0"], ["84413.6", "0"], ["84413.5", "0"], ["84412.05", "0.236861"], ["84409.34", "0"], ["84408.57", "0"], ["84407.83", "0.236861"], ["84407.22", "1.521558"], ["84406.49", "0"], ["84405.47", "0"], ["84403.5", "0.28101"], ["84402.88", "0"], ["84400.57", "0.237018"], ["84396.38", "0"], ["84396.37", "0"], ["84396.33", "0.04"], ["84396.32", "0.039638"], ["84396.26", "0.071098"], ["84388.87", "0"], ["84386.2", "0.000252"], ["84384.71", "0.001333"], ["84384.67", "0.000613"], ["84384.64", "0.023684"], ["84384.59", "0.0002"], ["84384.48", "0.000234"], ["84383.96", "0.000234"], ["84383.83", "0.023684"], ["84383.14", "0.0025"], ["84382.38", "0.015"]], "a": [["84437.77", "0.183157"], ["84444.52", "0.011842"], ["84449.05", "0.112877"], ["84450.05", "0.071149"], ["84452.51", "0.007638"], ["84454.06", "0.237018"], ["84454.07", "0"], ["84454.34", "0"], ["84454.51", "0"], ["84454.67", "0.162"], ["84455.13", "0"], ["84456.77", "0"], ["84456.9", "0.040248"], ["84457.91", "0"], ["84458.13", "0.000089"], ["84461.04", "0.262622"], ["84461.05", "0"], ["84461.61", "0"], ["84463.3", "0"], ["84465.17", "0.011458"], ["84465.78", "0.059948"], ["84466.07", "0"], ["84466.92", "0.236861"], ["84467.94", "0.089922"], ["84469.55", "0"], ["84470.68", "0.073633"], ["84471.14", "0.236861"], ["84471.47", "0"], ["84474.24", "0.162"], ["84478.51", "1.556329"], ["84481.01", "0.355344"], ["84481.02", "0"], ["84481.03", "0"], ["84481.12", "0.04"], ["84481.13", "0.04"], ["84489.49", "0"]], "u": 7510834, "seq": 66889455624}, "cts": 1742142262807, "record_time": 1742142261.909106}
{"topic": "orderbook.200.BTCUSDT", "ts": 1742142263010, "type": "delta", "data": {"s": "BTCUSDT", "b": [["84437.76", "0.106377"], ["84436.93", "0.011509"], ["84431.02", "0"], ["84422.82", "0.000296"], ["84420.86", "0"], ["84420.41", "0.111997"], ["84419.58", "0.02"], ["84418.98", "0"], ["84418.19", "0.02"], ["84417.84", "0"], ["84417.44", "0.02"], ["84417.34", "0"], ["84416.89", "0.02"], ["84416.59", "0"], ["84413.87", "0.175421"], ["84407.83", "0"], ["84405.71", "0.284584"], ["84403.5", "0"], ["84399.25", "0"], ["84399.24", "0"], ["84399.21", "0.05"], ["84399.2", "0.049545"], ["84382.38", "0"]], "a": [["84440.54", "0.000153"], ["84449.03", "0.068388"], ["84449.05", "0"], ["84450.05", "0"], ["84450.79", "0"], ["84452.27", "0.114704"], ["84454.05", "0.149735"], ["84456.89", "0.060196"], ["84456.9", "0.04"], ["84458.8", "0.223398"], ["84461.04", "0"], ["84465.77", "0.162688"], ["84466.48", "0.236861"], ["84466.97", "0.287542"], ["84470.7", "0.237061"], ["84481.01", "0"], ["84482.68", "0.355344"], ["84488.43", "0.027942"], ["84489.75", "0.0045"], ["84489.77", "0"], ["84489.95", "0.0045"], ["84489.97", "0"], ["84490.96", "0"], ["84490.98", "0"], ["84491.14", "0"]], "u": 7510835, "seq": 66889455989}, "cts": 1742142263008, "record_time": 1742142262.107661}
{"topic": "orderbook.200.BTCUSDT", "ts": 1742142263210, "type": "delta", "data": {"s": "BTCUSDT", "b": [["84422.91", "0.000296"], ["84422.82", "0"], ["84422.81", "0.221754"], ["84420.81", "0.111063"], ["84420.41", "0"], ["84418.89", "0.02"], ["84418.19", "0"], ["84417.64", "0.02"], ["84417.49", "0.02"], ["84417.44", "0"], ["84416.89", "0"], ["84416.27", "0.236861"], ["84415.94", "0.02"], ["84415.74", "0"], ["84414.27", "0.175441"], ["84413.87", "0"], ["84406.11", "0.28427"], ["84405.71", "0"], ["84399.32", "0.05"], ["84399.31", "0.049545"], ["84399.21", "0"], ["84399.2", "0"], ["84390.95", "0.177646"], ["84383.83", "0"], ["84383.14", "0"]], "a": [["84437.77", "0.126757"], ["84439", "0.000153"], ["84440.43", "0.018426"], ["84440.44", "0.053"], ["84440.54", "0"], ["84441.98", "0.002176"], ["84449.03", "0"], ["84452.27", "0"], ["84452.31", "0.03393"], ["84452.67", "0.117597"], ["84456.42", "0.00086"], ["84456.89", "0.059948"], ["84457.78", "0"], ["84458.8", "0.052"], ["84459.2", "0.16002"], ["84461.85", "0.139576"], ["84465.76", "0.325998"], ["84466.97", "0.005"], ["84467.37", "0.270023"], ["84482.67", "0.35534"], ["84482.68", "0"], ["84490.21", "0"], ["84490.25", "0"], ["84490.66", "0"], ["84490.73", "0"], ["84490.77", "0"]], "u": 7510836, "seq": 66889456300}, "cts": 1742142263207, "record_time": 1742142262.309107}
{"topic": "orderbook.200.BTCUSDT", "ts": 1742142263409, "type": "delta", "data": {"s": "BTCUSDT", "b": [["84437.76", "0.006377"], ["84436.93", "0"], ["84433.55", "0"], ["84431.02", "0.031676"], ["84430.31", "0"], ["84426.99", "0.003"], ["84426.37", "0"], ["84424.75", "0"], ["84422.89", "0.000296"], ["84421.95", "0.007806"], ["84420.81", "0"], ["84419.58", "0"], ["84418.89", "0"], ["84418.78", "0.02"], ["84418.24", "0.11901"], ["84418.04", "0.02"], ["84417.64", "0"], ["84417.49", "0"], ["84417.1", "0.11843"], ["84416.34", "0.02"], ["84415.94", "0"], ["84414.43", "0"], ["84414.27", "0"], ["84413.99", "0.02"], ["84409.29", "0.011709"], ["84407.23", "0.474522"], ["84406.8", "0.180441"], ["84406.11", "0"], ["84401.51", "0"], ["84400.57", "0"], ["84399.32", "0"], ["84399.31", "0"], ["84398.22", "0.05"], ["84398.21", "0.049546"], ["84397.32", "0.237631"], ["84396.33", "0"], ["84396.32", "0"], ["84395.33", "0.04"], ["84395.32", "0.039639"], ["84391.43", "0.071102"], ["84383.83", "0.023684"], ["84383.14", "0.0025"]], "a": [["84437.77", "0.272362"], ["84438.6", "0.006701"], ["84439", "0"], ["84439.53", "0.012159"], ["84439.93", "0.005"], ["84441.98", "0.011842"], ["84443", "0.089922"], ["84447.65", "0.11863"], ["84448.5", "0.237018"], ["84451.98", "0.029852"], ["84451.99", "0.089922"], ["84452.31", "0"], ["84452.67", "0"], ["84455.46", "0.024926"], ["84456.42", "0.000612"], ["84459.08", "0.178283"], ["84459.2", "0"], ["84460.69", "0.001333"], ["84467.37", "0"], ["84469.7", "0.288948"], ["84472.71", "0.118665"], ["84472.78", "0.029772"], ["84482.66", "0.355344"], ["84482.67", "0"], ["84487.9", "0"], ["84488.1", "0.037952"], ["84489.5", "0"], ["84489.68", "0"], ["84489.75", "0"], ["84489.88", "0"], ["84489.95", "0"], ["84490", "0"], ["84490.02", "0"]], "u": 7510837, "seq": 66889456756}, "cts": 1742142263408, "record_time": 1742142262.508116}
{"topic": "orderbook.200.BTCUSDT", "ts": 1742142263609, "type": "delta", "data": {"s": "BTCUSDT", "b": [["84431.2", "0.034513"], ["84431.19", "0.000296"], ["84431.18", "0.034618"], ["84431.16", "0.034723"], ["84431.14", "0"], ["84431.02", "0"], ["84431.01", "0"], ["84429.33", "0"], ["84426.64", "0.029188"], ["84425.96", "0.071073"], ["84422.91", "0"], ["84419.69", "0.11361"], ["84419.66", "0.114287"], ["84418.78", "0"], ["84418.61", "0.411764"], ["84418.24", "0"], ["84418.04", "0"], ["84416.69", "0.108583"], ["84416.34", "0"], ["84413.99", "0"], ["84412.07", "0.170496"], ["84411.49", "0.163936"], ["84408.53", "0.175469"], ["84408.25", "0.167719"], ["84406.8", "0"], ["84403.9", "0.299866"], ["84403.32", "0.278673"], ["84400.36", "0.270653"], ["84398.22", "0"], ["84398.21", "0"], ["84397.63", "0.28735"], ["84396.8", "0"], ["84396.72", "0.05"], ["84396.71", "0.049548"], ["84396.2", "0"], ["84395.33", "0"], ["84395.32", "0"], ["84393.85", "0.04"], ["84393.84", "0.039641"], ["84384.48", "0"], ["84383.96", "0"], ["84383.83", "0"], ["84383.14", "0"]], "a": [["84437.77", "0.127846"], ["84438.6", "0.011641"], ["84440.43", "0.046575"], ["84447.55", "0.007834"], ["84447.63", "0.018955"], ["84447.64", "0.059948"], ["84447.65", "0"], ["84448.49", "0.105884"], ["84449.09", "0.108019"], ["84449.88", "0.12007"], ["84450.46", "0.108441"], ["84451.82", "0.110015"], ["84451.98", "0"], ["84452.51", "0"], ["84455.4", "0.056248"], ["84455.46", "0.024678"], ["84456.8", "0.04"], ["84457", "0.180286"], ["84458.05", "0.162246"], ["84459.08", "0"], ["84459.99", "0.170404"], ["84460.22", "0.011751"], ["84460.53", "0.163367"], ["84462.7", "0.236861"], ["84465.17", "0.300467"], ["84465.76", "0"], ["84466.22", "0.290934"], ["84468.16", "0.262844"], ["84469.7", "0"], ["84471.14", "0"], ["84471.15", "0.268583"], ["84473.02", "0.001604"], ["84478.5", "0.355358"], ["84481.1", "0.322711"], ["84482.64", "0.177646"], ["84482.66", "0"], ["84485.45", "0"], ["84485.91", "0"], ["84485.99", "0"], ["84486.03", "0"], ["84486.12", "0"], ["84486.65", "0"], ["84487.27", "0"], ["84487.37", "0"], ["84487.74", "0"], ["84488.1", "0"], ["84488.37", "0"], ["84488.43", "0"], ["84488.44", "0"], ["84488.53", "0"]], "u": 7510838, "seq": 66889457242}, "cts": 1742142263605, "record_time": 1742142262.708007}
{"topic": "orderbook.200.BTCUSDT", "ts": 1742142263810, "type": "delta", "data": {"s": "BTCUSDT", "b": [["84431.25", "0.000296"], ["84431.24", "0.034303"], ["84431.22", "0.034408"], ["84431.19", "0"], ["84431.18", "0"], ["84431.16", "0"], ["84431.01", "0.010661"], ["84427.99", "0.071072"], ["84426.64", "0"], ["84425.96", "0"], ["84419.99", "0.113174"], ["84419.69", "0"], ["84419.66", "0"], ["84419.39", "0.22202"], ["84418.74", "0.120462"], ["84418.61", "0.296206"], ["84416.9", "0.105162"], ["84416.69", "0"], ["84412.07", "0"], ["84411.8", "0.166013"], ["84411.49", "0"], ["84408.53", "0"], ["84408.25", "0"], ["84403.9", "0"], ["84403.63", "0.283257"], ["84403.32", "0"], ["84400.36", "0"], ["84397.94", "0.281004"], ["84397.63", "0"], ["84396.73", "0.05"], ["84396.72", "0.049548"], ["84396.71", "0"], ["84393.85", "0"], ["84393.83", "0.039641"], ["84384.48", "0.000234"], ["84383.96", "0.000234"], ["84383.83", "0.023684"], ["84383.2", "0.24702"]], "a": [["84444.51", "0.014457"], ["84447.63", "0"], ["84448.49", "0.227697"], ["84449.09", "0"], ["84449.88", "0"], ["84450.19", "0.115099"], ["84450.46", "0"], ["84450.59", "0.108737"], ["84451.82", "0"], ["84454.06", "0.237266"], ["84455.4", "0.056"], ["84457", "0"], ["84457.13", "0.158799"], ["84458.05", "0"], ["84458.2", "0.06"], ["84459.99", "0"], ["84460.53", "0"], ["84460.83", "0.179928"], ["84462", "0"], ["84463.5", "0"], ["84465.17", "0"], ["84466.22", "0"], ["84466.52", "0.277451"], ["84468.16", "0"], ["84468.36", "0.294797"], ["84471.15", "0"], ["84471.45", "0.290383"], ["84478.5", "0"], ["84479.13", "0.177646"], ["84479.97", "0.355358"], ["84485.45", "0.02464"], ["84485.91", "0.0002"], ["84485.99", "0.000612"], ["84486.03", "0.001333"], ["84486.12", "0.000235"]], "u": 7510839, "seq": 66889457582}, "cts": 1742142263807, "record_time": 1742142262.907994}
{"topic": "orderbook.200.BTCUSDT", "ts": 1742142264009, "type": "delta", "data": {"s": "BTCUSDT", "b": [["84437.76", "0.007193"], ["84433.55", "0.011843"], ["84431.3", "0.033988"], ["84431.28", "0.034093"], ["84431.25", "0"], ["84431.24", "0"], ["84431.22", "0"], ["84431.2", "0"], ["84430.15", "0.07107"], ["84427.99", "0"], ["84420.11", "0.10943"], ["84420.08", "0.118928"], ["84419.99", "0"], ["84419.02", "0.117715"], ["84418.74", "0"], ["84417.1", "0"], ["84416.9", "0"], ["84416.25", "0"], ["84414.59", "0.02"], ["84412.49", "0.166933"], ["84412.22", "0"], ["84411.8", "0"], ["84408.86", "0.173702"], ["84404.32", "0.29904"], ["84403.75", "0.278348"], ["84403.63", "0"], ["84402.39", "0.071093"], ["84400.69", "0.274752"], ["84398.06", "0.262893"], ["84397.94", "0"], ["84394.9", "0.023578"], ["84391.43", "0"], ["84383.2", "0"]], "a": [["84437.77", "0.124448"], ["84438.6", "0.001453"], ["84440.07", "0.0001"], ["84446.22", "0.162"], ["84448.49", "0.192827"], ["84449.51", "0.108388"], ["84450.19", "0"], ["84450.3", "0.118696"], ["84450.59", "0"], ["84454.05", "0.149983"], ["84454.06", "0.237018"], ["84457.13", "0"], ["84457.41", "0.165769"], ["84458.47", "0.165812"], ["84460.31", "0.179963"], ["84460.83", "0"], ["84466.52", "0"], ["84468.36", "0"], ["84468.48", "0.288869"], ["84471.45", "0"], ["84471.56", "0.301009"], ["84472.71", "0.000235"], ["84475.76", "0"], ["84478.5", "0.355359"], ["84479.97", "0"], ["84486.12", "0"]], "u": 7510840, "seq": 66889457985}, "cts": 1742142264007, "record_time": 1742142263.115896}
{"success": true, "ret_msg": "pong", "conn_id": "66eef079-b2bf-427b-aa45-7a2115dcff7c", "op": "ping", "record_time": 1742142263.165559}
{"topic": "orderbook.200.BTCUSDT", "ts": 1742142264209, "type": "delta", "data": {"s": "BTCUSDT", "b": [["84437.76", "0.008577"], ["84433.55", "0"], ["84431.36", "0.033672"], ["84431.35", "0.000296"], ["84431.34", "0.033778"], ["84431.32", "0.033883"], ["84431.3", "0"], ["84431.28", "0"], ["84431.01", "0"], ["84430.15", "0"], ["84425.92", "0"], ["84424.88", "0.005"], ["84422.81", "0.32758"], ["84420.18", "0.00055"], ["84420.11", "0"], ["84420.08", "0"], ["84419.36", "0.110956"], ["84419.34", "0.112828"], ["84419.02", "0"], ["84418.67", "0.108906"], ["84418.61", "0"], ["84414.59", "0"], ["84412.49", "0"], ["84411.17", "0.1662"], ["84408.86", "0"], ["84408.14", "0.161882"], ["84407.93", "0.177567"], ["84407.83", "0.236861"], ["84407.38", "0.13957"], ["84404.32", "0"], ["84403.97", "0.281189"], ["84403.75", "0"], ["84403", "0.301729"], ["84402.39", "0"], ["84400.69", "0"], ["84399.97", "0.287761"], ["84398.06", "0"], ["84397.31", "0.452231"], ["84396.73", "0"], ["84396.72", "0"], ["84396.33", "0.05"], ["84396.32", "0.049548"], ["84393.84", "0"], ["84393.83", "0"], ["84393.45", "0.04"], ["84393.44", "0.039641"], ["84392.06", "0.071102"]], "a": [["84437.77", "0.127653"], ["84438.6", "0.011842"], ["84441.53", "0.02042"], ["84446.22", "0"], ["84448.49", "0.22748"], ["84449.51", "0"], ["84450.3", "0"], ["84450.52", "0.107759"], ["84453.6", "0.000483"], ["84454.05", "0.149735"], ["84457.05", "0.170531"], ["84457.41", "0"], ["84457.72", "0.163418"], ["84458.47", "0"], ["84459.59", "0.176751"], ["84460.2", "0.168286"], ["84460.31", "0"], ["84465.22", "0.27781"], ["84465.89", "0.279581"], ["84467.76", "0.296717"], ["84468.48", "0"], ["84471.56", "0"], ["84478.49", "0.355359"], ["84478.5", "0"], ["84486.03", "0"]], "u": 7510841, "seq": 66889458356}, "cts": 1742142264204, "record_time": 1742142263.307863}
{"topic": "orderbook.200.BTCUSDT", "ts": 1742142264409, "type": "delta", "data": {"s": "BTCUSDT", "b": [["84431.4", "0.033462"], ["84431.39", "0.000296"], ["84431.38", "0.033567"], ["84431.35", "0"], ["84431.34", "0"], ["84431.32", "0"], ["84431.01", "0.001319"], ["84427.36", "0.071072"], ["84426.99", "0"], ["84426.92", "0.003"], ["84426.72", "0.003"], ["84422.89", "0"], ["84422.82", "0.000296"], ["84422.81", "0.32458"], ["84422.61", "0"], ["84422.41", "0"], ["84419.95", "0.108229"], ["84419.36", "0"], ["84419.34", "0"], ["84418.67", "0"], ["84418.61", "0.202961"], ["84411.72", "0.170782"], ["84411.17", "0"], ["84408.46", "0.162658"], ["84408.14", "0"], ["84407.93", "0"], ["84403.97", "0"], ["84403", "0"], ["84400.39", "0.281946"], ["84399.97", "0"], ["84397.31", "0.162"], ["84383.2", "0.24702"], ["84383.14", "0.0025"], ["84382.38", "0.015"]], "a": [["84443", "0"], ["84448.49", "0.229874"], ["84450.52", "0"], ["84450.9", "0.11036"], ["84453.6", "0.000235"], ["84454.05", "0.149983"], ["84457.05", "0"], ["84457.72", "0"], ["84459.59", "0"], ["84460.2", "0"], ["84460.46", "0.165046"], ["84461.12", "0.157988"], ["84465.22", "0"], ["84465.71", "0.283843"], ["84465.76", "0.414125"], ["84465.89", "0"], ["84466.85", "0.297957"], ["84467.76", "0"], ["84470.9", "0"], ["84478.49", "0"], ["84481.09", "0.355354"], ["84486.03", "0.001333"], ["84486.12", "0.000235"], ["84486.65", "0.000235"], ["84487.27", "0.023684"]], "u": 7510842, "seq": 66889458690}, "cts": 1742142264407, "record_time": 1742142263.507671}
{"topic": "orderbook.200.BTCUSDT", "ts": 1742142264610, "type": "delta", "data": {"s": "BTCUSDT", "b": [["84437.76", "0"], ["84437.44", "0"], ["84437.27", "0"], ["84435.55", "0"], ["84435.36", "0"], ["84435.31", "0"], ["84435.23", "0"], ["84435.02", "0"], ["84434.1", "0"], ["84432.96", "0"], ["84432.79", "0"], ["84432.7", "0"], ["84432.62", "0"], ["84431.4", "0"], ["84431.39", "0"], ["84431.38", "0"], ["84431.36", "0"], ["84431.13", "0"], ["84431.09", "0"], ["84431.01", "0"], ["84430.9", "0"], ["84430.38", "0"], ["84430.17", "0"], ["84429.52", "0"], ["84429.4", "0"], ["84429.32", "0"], ["84428.15", "0"], ["84427.98", "0"], ["84427.65", "0"], ["84427.63", "0"], ["84427.6", "0"], ["84427.4", "0"], ["84427.36", "0"], ["84427.2", "0"], ["84426.92", "0"], ["84426.91", "0"], ["84426.87", "0"], ["84426.72", "0"], ["84426.63", "0"], ["84426.26", "0"], ["84425.74", "0"], ["84425.1", "0"], ["84424.88", "0"], ["84424.52", "0"], ["84423.51", "0"], ["84423.34", "0"], ["84422.82", "0"], ["84422.81", "0"], ["84422.8", "0"], ["84422.69", "0"], ["84422.65", "0"], ["84422.57", "0"], ["84422.2", "0"], ["84421.95", "0"], ["84421.62", "0"], ["84421.1", "0"], ["84421.09", "0"], ["84420.95", "0"], ["84420.18", "0"], ["84420.12", "0"], ["84420.06", "0"], ["84420.03", "0"], ["84419.95", "0"], ["84419.39", "0"], ["84419.3", "0"], ["84418.86", "0"], ["84418.8", "0"], ["84418.69", "0"], ["84418.61", "0"], ["84418.6", "0"], ["84418.47", "0"], ["84418.43", "0"], ["84417.6", "0"], ["84417.5", "0"], ["84416.27", "0"], ["84415.84", "0"], ["84415.7", "0"], ["84415.4", "0"], ["84415.1", "0"], ["84414.16", "0"], ["84413.56", "0"], ["84412.5", "0"], ["84412.05", "0"], ["84411.72", "0"], ["84410.08", "0"], ["84409.83", "0"], ["84409.65", "0"], ["84409.54", "0"], ["84409.29", "0"], ["84408.83", "0"], ["84408.46", "0"], ["84408.09", "0"], ["84407.83", "0"], ["84407.38", "0"], ["84407.24", "0.000296"], ["84407.23", "0"], ["84407.22", "0"], ["84406.48", "0"], ["84405.76", "0.000613"], ["84405.42", "0"], ["84404.07", "0.000296"], ["84404.06", "0.059079"], ["84404.05", "0"], ["84402.31", "0.0002"], ["84401.92", "0.005"], ["84401.44", "0"], ["84400.84", "0.071095"], ["84400.39", "0"], ["84399.5", "0"], ["84398.18", "0.008149"], ["84398.14", "0.02"], ["84397.33", "0.252334"], ["84397.32", "0.000613"], ["84397.31", "0"], ["84396.53", "0.02"], ["84396.44", "0.02"], ["84396.33", "0"], ["84396.32", "0"], ["84396.26", "0"], ["84396.02", "0"], ["84395.13", "0.01624"], ["84395.02", "0.120127"], ["84394.93", "0.02"], ["84394.9", "0"], ["84394.74", "0"], ["84394.04", "0"], ["84393.45", "0"], ["84393.44", "0"], ["84393.17", "0.003482"], ["84392.55", "0"], ["84392.06", "0"], ["84391.75", "0.110069"], ["84391.42", "0.175419"], ["84391.39", "0"], ["84390.95", "0"], ["84390.62", "0"], ["84389", "0"], ["84388.97", "0"], ["84388.56", "0"], ["84388.33", "0"], ["84387.16", "0"], ["84387.08", "0.019095"], ["84386.79", "0.180065"], ["84386.46", "0"], ["84386.21", "0"], ["84385.72", "0.004592"], ["84385.51", "0.012224"], ["84384.64", "0"], ["84383.83", "0"], ["84383.52", "0.171737"], ["84383.2", "0"], ["84382.39", "0.059948"], ["84382.05", "0.0002"], ["84381.73", "0.001467"], ["84381.56", "0.000252"], ["84380.49", "0.001333"], ["84380.45", "0.000611"], ["84379.84", "0.000234"], ["84379.52", "0.0002"], ["84379.32", "0.000234"], ["84378.7", "0.000089"], ["84378.35", "0.000797"], ["84377.46", "0.008453"], ["84377.09", "0.001467"], ["84376.99", "0.0002"], ["84376.92", "0.000252"], ["84376.36", "0.001"], ["84376.27", "0.001333"], ["84376.23", "0.000611"], ["84375.9", "0.001243"], ["84375.71", "0.39838"], ["84375.2", "0.000234"], ["84375.14", "0.05"], ["84375.13", "0.049553"], ["84374.95", "0.005922"], ["84374.68", "0.000234"], ["84374.46", "0.0002"], ["84373.22", "0.005924"], ["84372.84", "0.013777"], ["84372.72", "0.02369"], ["84372.46", "0.059948"], ["84372.45", "0.001467"], ["84372.43", "0.071118"], ["84372.35", "0.04"], ["84372.34", "0.039645"], ["84372.28", "0.000252"], ["84372.05", "0.001333"], ["84372.01", "0.000612"], ["84371.93", "0.0002"], ["84370.56", "0.000234"], ["84370.3", "0.000089"], ["84370.25", "0.000089"], ["84370.04", "0.000234"], ["84369.4", "0.0002"], ["84369.37", "0.004738"], ["84368.46", "0.000335"], ["84367.84", "0.001333"], ["84367.81", "0.001467"], ["84367.79", "0.000612"], ["84367.64", "0.000252"], ["84367.56", "0.02369"], ["84367.41", "0.237018"], ["84367.2", "0.24702"], ["84366.97", "0.005"], ["84366.84", "0.00118"], ["84366.43", "0.071124"], ["84366.25", "0.000158"], ["84365.92", "0.000234"], ["84365.65", "0.005922"], ["84365.4", "0.000234"], ["84365", "0.001243"], ["84364.74", "0.02369"], ["84363.62", "0.001333"], ["84363.57", "0.000613"], ["84363.17", "0.001467"], ["84363", "0.000252"], ["84362.18", "0.02369"], ["84361.93", "0.237018"], ["84361.8", "0.000089"], ["84361.7", "0.183749"], ["84361.35", "0.02369"], ["84361.28", "0.000234"], ["84360.96", "0.059948"], ["84360.95", "0.003"], ["84360.76", "0.000234"], ["84359.4", "0.001333"], ["84359.36", "0.000613"], ["84358.7", "0.04"], ["84358.53", "0.001467"], ["84358.36", "0.000252"], ["84356.86", "0.237018"], ["84356.8", "0.04"], ["84356.64", "0.000234"], ["84356.12", "0.000234"], ["84355.57", "0.000357"], ["84355.18", "0.001333"], ["84355.14", "0.000613"], ["84355.1", "0.04"], ["84354.9", "0.04"], ["84353.89", "0.001467"], ["84353.72", "0.000252"], ["84353.7", "0.04"], ["84353.35", "0.000089"], ["84352.4", "0.044"], ["84352", "0.000234"], ["84351.8", "0.04"], ["84351.77", "0.059948"], ["84351.73", "0.237018"], ["84351.48", "0.000234"], ["84350.96", "0.001333"], ["84350.92", "0.000613"], ["84350.4", "0.04"], ["84349.8", "0.052"], ["84349.25", "0.001467"], ["84349.08", "0.000252"], ["84347.99", "0.001"], ["84347.6", "0.04"]], "a": [["84416.99", "0.240349"], ["84417.6", "0.053"], ["84417.61", "0.015119"], ["84417.69", "0.322038"], ["84418.87", "0.03"], ["84421.1", "0.01"], ["84421.43", "0.325246"], ["84421.96", "0.005"], ["84422.57", "0.035737"], ["84422.65", "0.000611"], ["84422.69", "0.001333"], ["84423.12", "0.001979"], ["84423.21", "0.035537"], ["84423.34", "0.000252"], ["84423.35", "0.035537"], ["84423.51", "0.001467"], ["84424.11", "0.035537"], ["84424.5", "0.127003"], ["84424.51", "0.118432"], ["84424.53", "0.001"], ["84424.76", "0.059948"], ["84425.1", "0.0002"], ["84425.46", "0.118711"], ["84425.74", "0.000234"], ["84425.99", "0.035536"], ["84426.25", "0.005"], ["84426.26", "0.000234"], ["84426.87", "0.000611"], ["84426.91", "0.001333"], ["84427.13", "0.118337"], ["84427.4", "0.008144"], ["84427.63", "0.0002"], ["84427.65", "0.0004"], ["84427.98", "0.000252"], ["84428.15", "0.001467"], ["84429.61", "0.035232"], ["84430.17", "0.0002"], ["84430.38", "0.000235"], ["84430.9", "0.000235"], ["84431.09", "0.000611"], ["84431.13", "0.001333"], ["84432.31", "0.118432"], ["84432.6", "0.000089"], ["84433.69", "0.16232"], ["84435.36", "0.159537"], ["84435.54", "0.000296"], ["84435.55", "0.0004"], ["84435.56", "0.004533"], ["84435.57", "0.162"], ["84436.34", "0.00951"], ["84437.12", "0.139551"], ["84437.27", "0.000252"], ["84437.44", "0.001467"], ["84437.75", "0.17838"], ["84437.76", "0.0002"], ["84437.77", "0.274914"], ["84438.6", "0"], ["84439.04", "0.016299"], ["84439.53", "0.000611"], ["84439.58", "0.001333"], ["84439.67", "0.000235"], ["84439.93", "0"], ["84440.06", "0.012216"], ["84440.19", "0.000235"], ["84440.3", "0.0002"], ["84440.42", "0.042"], ["84440.43", "0"], ["84440.44", "0.003"], ["84441.11", "0.000089"], ["84441.91", "0.000252"], ["84441.92", "0.274896"], ["84441.98", "0"], ["84442.08", "0.001467"], ["84442.87", "0.118432"], ["84442.88", "0.089922"], ["84443.07", "0"], ["84443.3", "0.04"], ["84443.38", "0.175419"], ["84444.49", "0"], ["84444.52", "0"], ["84444.6", "0.017796"], ["84445.43", "0.023689"], ["84446.03", "0.008453"], ["84446.21", "0"], ["84446.22", "0.162"], ["84446.79", "0.029772"], ["84447.48", "0.019104"], ["84447.55", "0"], ["84447.9", "0.0522"], ["84448.48", "0.176189"], ["84448.49", "0"], ["84449.69", "0.076996"], ["84450.9", "0"], ["84451.9", "0"], ["84451.98", "0.39335"], ["84453.47", "0.023689"], ["84454.05", "0.149735"], ["84454.16", "0.027942"], ["84455.07", "0.023583"], ["84455.38", "0.017796"], ["84455.46", "0"], ["84456.75", "0.023691"], ["84456.86", "0.023689"], ["84457.15", "0"], ["84457.69", "0.023689"], ["84458.72", "0.005922"], ["84458.76", "0.004584"], ["84459.81", "0.473476"], ["84460.06", "0.430885"], ["84460.22", "0"], ["84460.46", "0"], ["84461.12", "0"], ["84461.59", "0.244524"], ["84461.62", "0"], ["84461.85", "0"], ["84462.32", "0.023688"], ["84462.7", "0"], ["84464.84", "0.023689"], ["84465.09", "0"], ["84465.32", "0.405482"], ["84465.54", "0"], ["84465.71", "0"], ["84465.77", "0"], ["84466.48", "0"], ["84466.81", "0"], ["84466.85", "0"], ["84466.92", "0"], ["84467.93", "0.322761"], ["84469.57", "0"], ["84470.12", "0.003334"], ["84470.7", "0.0002"], ["84472.77", "0.013751"], ["84472.78", "0"], ["84473.22", "0"], ["84473.24", "0"], ["84473.32", "0"], ["84473.36", "0"], ["84473.76", "0"], ["84474.24", "0"], ["84474.43", "0"], ["84474.58", "0"], ["84474.6", "0"], ["84475.15", "0"], ["84475.53", "0"], ["84475.72", "0"], ["84475.77", "0"], ["84476.34", "0"], ["84476.83", "0"], ["84477.05", "0"], ["84477.21", "0"], ["84477.35", "0"], ["84477.54", "0"], ["84477.58", "0"], ["84478", "0"], ["84478.07", "0"], ["84478.3", "0"], ["84478.51", "0"], ["84478.57", "0"], ["84479.07", "0"], ["84479.13", "0"], ["84479.22", "0"], ["84479.24", "0"], ["84479.81", "0"], ["84479.98", "0"], ["84480.84", "0"], ["84481.09", "0"], ["84481.1", "0"], ["84481.12", "0"], ["84481.13", "0"], ["84481.47", "0"], ["84481.72", "0"], ["84481.74", "0"], ["84481.76", "0"], ["84481.81", "0"], ["84482", "0"], ["84482.16", "0"], ["84482.38", "0"], ["84482.64", "0"], ["84482.69", "0"], ["84482.92", "0"], ["84483.14", "0"], ["84483.25", "0"], ["84483.29", "0"], ["84483.37", "0"], ["84483.45", "0"], ["84483.66", "0"], ["84483.72", "0"], ["84483.89", "0"], ["84484.16", "0"], ["84484.78", "0"], ["84484.79", "0"], ["84485.02", "0"], ["84485.3", "0"], ["84485.45", "0"], ["84485.91", "0"], ["84485.99", "0"], ["84486.03", "0"], ["84486.12", "0"], ["84486.65", "0"], ["84487.27", "0"]], "u": 7510843, "seq": 66889462144}, "cts": 1742142264607, "record_time": 1742142263.70965}
{"topic": "orderbook.200.BTCUSDT", "ts": 1742142264810, "type": "delta", "data": {"s": "BTCUSDT", "b": [["84416.98", "0"], ["84416.45", "0"], ["84414.97", "0"], ["84414.25", "0"], ["84414.22", "0"], ["84414.21", "0"], ["84414.05", "0"], ["84412.68", "0"], ["84412.44", "0"], ["84412.33", "0"], ["84411.81", "0"], ["84411.73", "0.171844"], ["84410.9", "0.011846"], ["84407.52", "0.011847"], ["84407.24", "0"], ["84404.99", "0.011847"], ["84404.07", "0"], ["84404.06", "0"], ["84401.92", "0"], ["84401.43", "0"], ["84401", "0.022327"], ["84400.98", "0.015954"], ["84400.84", "0"], ["84399.15", "0.06382"], ["84398.18", "0"], ["84398.14", "0"], ["84397.5", "0.005"], ["84397.33", "0"], ["84396.53", "0"], ["84396.44", "0"], ["84395.13", "0"], ["84395.02", "0"], ["84394.93", "0"], ["84394.84", "0.084948"], ["84394.83", "0.162"], ["84394.35", "0.000296"], ["84394.33", "0.120431"], ["84391.76", "0.086323"], ["84391.75", "0"], ["84391.7", "0.04"], ["84391.42", "0"], ["84390.52", "0.236934"], ["84390.4", "0.04"], ["84389.94", "0.02"], ["84389.87", "0.236934"], ["84389.4", "0.02"], ["84388.87", "0.115716"], ["84388.86", "0"], ["84388.34", "0.02"], ["84388.3", "0.04"], ["84387.75", "0.162903"], ["84387.7", "0.02"], ["84387.04", "0.175419"], ["84386.79", "0"], ["84386.3", "0.236934"], ["84386.27", "0.015401"], ["84385.72", "0"], ["84385.65", "0.236934"], ["84385.51", "0"], ["84385.46", "0.008693"], ["84385.3", "0.04"], ["84385", "0.04"], ["84383.95", "0.023693"], ["84383.53", "0.075331"], ["84383.52", "0"], ["84383.02", "1.567533"], ["84382.34", "0.016329"], ["84380.41", "0.162"], ["84379.52", "0.26907"], ["84376.91", "0.139551"], ["84375.72", "0.164374"], ["84375.43", "0.071116"], ["84375.29", "0.000987"], ["84375.14", "0"], ["84375.13", "0"], ["84373.64", "0.1777"], ["84373.22", "0"], ["84372.85", "0.118432"], ["84372.84", "0"], ["84372.47", "0.066148"], ["84372.43", "0"], ["84372.35", "0"], ["84372.34", "0"], ["84371.96", "0.162"], ["84370.44", "0.05"], ["84370.43", "0.049559"], ["84369.44", "0.071121"], ["84369.37", "0"], ["84369.33", "0.059158"], ["84368.69", "0.024078"], ["84368.41", "0.323142"], ["84367.76", "0.04"], ["84367.75", "0.03965"], ["84367.2", "0"], ["84366.87", "0.0002"], ["84366.43", "0"], ["84365.94", "0.004661"], ["84364.34", "0.0002"], ["84363.51", "0.162"], ["84361.8", "0.000289"], ["84358.71", "0.355465"], ["84358.7", "0"], ["84358.6", "0.24702"], ["84357.74", "0.013834"], ["84356.8", "0"], ["84355.75", "0.004739"], ["84355.06", "0.162"], ["84353.7", "0"], ["84353.35", "0"], ["84352.4", "0"], ["84352", "0"], ["84351.8", "0"], ["84351.77", "0"], ["84351.73", "0"], ["84351.48", "0"], ["84350.96", "0"], ["84350.92", "0"], ["84350.4", "0"], ["84349.8", "0"], ["84349.25", "0"], ["84349.08", "0"], ["84347.99", "0"], ["84347.6", "0"]], "a": [["84411.74", "0.163942"], ["84411.82", "0.004888"], ["84412.57", "0.010612"], ["84413.04", "0.005"], ["84414.97", "0.040053"], ["84414.98", "0.039821"], ["84415.95", "0.011846"], ["84416.45", "0.000234"], ["84416.98", "0.000234"], ["84416.99", "0.03"], ["84417.5", "0.0002"], ["84417.6", "0"], ["84417.61", "0.005"], ["84417.69", "0"], ["84418.43", "0.000611"], ["84418.47", "0.001333"], ["84418.48", "0.011845"], ["84418.69", "0.000252"], ["84418.86", "0.001467"], ["84420.03", "0.0002"], ["84420.27", "0.029233"], ["84421.09", "0.000234"], ["84421.43", "0"], ["84421.61", "0.050818"], ["84421.62", "0.000234"], ["84421.69", "0.02959"], ["84421.96", "0"], ["84422.57", "0.0002"], ["84423.21", "0"], ["84423.35", "0"], ["84424.09", "0.000089"], ["84424.11", "0"], ["84424.5", "0"], ["84424.53", "0"], ["84425.46", "0"], ["84425.99", "0"], ["84426.08", "0.019791"], ["84426.25", "0"], ["84426.42", "0.10758"], ["84427.13", "0.000689"], ["84427.4", "0"], ["84427.5", "0.056"], ["84427.65", "0"], ["84428.19", "0.079163"], ["84429.61", "0"], ["84430.17", "0.000448"], ["84432.7", "0.0002"], ["84433", "0.177534"], ["84433.68", "0.146726"], ["84433.69", "0"], ["84433.79", "0.0008"], ["84434.51", "0.175419"], ["84434.6", "0.044"], ["84435.23", "0.0002"], ["84435.36", "0"], ["84435.55", "0"], ["84435.56", "0.004133"], ["84436.25", "0.236934"], ["84436.6", "0.052"], ["84436.94", "0.236934"], ["84437.11", "0.194448"], ["84438", "0.000444"], ["84438.6", "0.04"], ["84439.12", "0.0046"], ["84440.06", "0"], ["84440.42", "0.212592"], ["84440.47", "0.236934"], ["84441.16", "0.236934"], ["84441.23", "0.273239"], ["84441.53", "0"], ["84441.54", "0"], ["84441.92", "0"], ["84443.38", "0"], ["84444.51", "0.111311"], ["84444.9", "0.04"], ["84446.51", "0.000335"], ["84446.79", "0"], ["84447.64", "0.178413"], ["84448.49", "0.118463"], ["84449.57", "0.000987"], ["84449.69", "0"], ["84451.97", "0.355465"], ["84451.98", "0.03789"], ["84451.99", "0"], ["84453.15", "0.013801"], ["84453.94", "0.473476"], ["84454.16", "0"], ["84455.07", "0"], ["84455.2", "0"], ["84455.39", "0.322809"], ["84455.4", "0"], ["84456.19", "0.01936"], ["84456.75", "0"], ["84456.9", "0"], ["84458.04", "0.1777"], ["84458.22", "0.029772"], ["84458.46", "0.000089"], ["84458.76", "0"], ["84458.8", "0"], ["84459.81", "0"], ["84460.4", "0"], ["84461.59", "0"], ["84464.4", "0.246059"], ["84465.76", "0"], ["84467.81", "0.078432"], ["84467.93", "0"], ["84467.94", "0"], ["84468.62", "0"], ["84469.09", "0"], ["84469.14", "0"], ["84469.56", "0"], ["84469.67", "0"], ["84469.78", "0"], ["84469.95", "0"], ["84470.12", "0"], ["84470.37", "0"], ["84470.68", "0"], ["84470.69", "0"], ["84470.7", "0"], ["84472.18", "0"], ["84472.64", "0"], ["84472.71", "0"], ["84472.77", "0"], ["84473.02", "0"]], "u": 7510844, "seq": 66889463237}, "cts": 1742142264807, "record_time": 1742142263.910474}
{"topic": "orderbook.200.BTCUSDT", "ts": 1742142265010, "type": "delta", "data": {"s": "BTCUSDT", "b": [["84411.73", "0.172803"], ["84407.99", "0.000099"], ["84407.7", "0.025081"], ["84407.69", "0.071323"], ["84401", "0.090261"], ["84396.66", "0.010977"], ["84396.46", "0.003"], ["84396.44", "0.086781"], ["84396.26", "0.003"], ["84394.84", "0.000296"], ["84394.33", "0"], ["84392.2", "0.02"], ["84392.1", "0.044"], ["84391.76", "0.162046"], ["84390.34", "0.02"], ["84390", "0.04"], ["84389.94", "0"], ["84389.4", "0"], ["84389.1", "0.052"], ["84389.04", "0.02"], ["84388.34", "0"], ["84388", "0.02"], ["84387.75", "0"], ["84387.7", "0"], ["84387.4", "0.04"], ["84386.6", "0.04"], ["84384.62", "0.017796"], ["84384", "0.011965"], ["84383.22", "0.006075"], ["84379.52", "0.0002"], ["84377.06", "0.2979"], ["84372.85", "0"], ["84370.43", "0.049548"], ["84367.76", "0"], ["84367.75", "0"], ["84367.56", "0.06369"], ["84367.55", "0.039641"], ["84367.41", "0"], ["84361.98", "0.017765"], ["84358.72", "0.355445"], ["84358.71", "0"], ["84356.64", "0"], ["84356.12", "0"], ["84355.75", "0"], ["84355.57", "0"], ["84355.18", "0"], ["84355.14", "0"], ["84355.1", "0"], ["84355.06", "0"], ["84354.9", "0"], ["84353.89", "0"], ["84353.72", "0"]], "a": [["84411.74", "0.11019"], ["84412.57", "0"], ["84414.97", "0.023972"], ["84415.48", "0.000088"], ["84415.95", "0"], ["84418.48", "0"], ["84418.61", "0.118432"], ["84424.5", "0.099008"], ["84425.06", "0.007977"], ["84426.42", "0"], ["84427.1", "0.04"], ["84427.49", "0.106314"], ["84428.34", "0.000248"], ["84428.8", "0.04"], ["84428.95", "0.006009"], ["84429.3", "0.023926"], ["84430.17", "0.0002"], ["84430.8", "0.052"], ["84432.16", "0.023443"], ["84432.5", "0.052"], ["84433", "0"], ["84434.2", "0.04"], ["84436.25", "0"], ["84436.6", "0"], ["84436.94", "0"], ["84437.72", "0.011965"], ["84440.47", "0"], ["84441.16", "0"], ["84441.23", "0"], ["84445.38", "0.236934"], ["84445.5", "0.04"], ["84447.9", "0.0002"], ["84448.9", "0.236934"], ["84449.6", "0.236934"], ["84450.9", "1.573064"], ["84451.97", "0"], ["84453.12", "0.031889"], ["84456.8", "0"], ["84458.03", "0.355645"], ["84458.04", "0"], ["84460.21", "0"], ["84461.6", "0"], ["84462.2", "0.0006"], ["84463.48", "0.0045"], ["84463.53", "0.0045"], ["84463.68", "0.0045"], ["84463.73", "0.0045"], ["84463.88", "0.0045"], ["84463.93", "0.0045"], ["84465.51", "0"], ["84465.63", "0"], ["84465.78", "0"], ["84466.64", "0"], ["84466.89", "0"], ["84466.97", "0"], ["84467.09", "0"], ["84467.54", "0"], ["84467.81", "0"], ["84468.06", "0"], ["84468.17", "0"]], "u": 7510845, "seq": 66889463660}, "cts": 1742142265007, "record_time": 1742142264.10938}
{"topic": "orderbook.200.BTCUSDT", "ts": 1742142265210, "type": "delta", "data": {"s": "BTCUSDT", "b": [["84401.01", "0.029112"], ["84401", "0"], ["84396.95", "0.159931"], ["84396.44", "0"], ["84392.2", "0"], ["84391.4", "0.02"], ["84390.84", "0.020252"], ["84390.34", "0"], ["84389.7", "0.02"], ["84389.14", "0.02"], ["84389.04", "0"], ["84388", "0"], ["84377.06", "0"], ["84363.52", "0.355428"], ["84361", "0.015"], ["84358.72", "0"], ["84356.64", "0.000234"]], "a": [["84411.74", "0.020718"], ["84411.82", "0"], ["84414.96", "0.003"], ["84414.97", "0.06553"], ["84414.98", "0"], ["84427.49", "0.102871"], ["84428.19", "0.079411"], ["84428.34", "0"], ["84432.1", "0.04"], ["84432.62", "0.000252"], ["84432.79", "0.001467"], ["84435.02", "0.000235"], ["84435.2", "0.064"], ["84435.31", "0.000611"], ["84435.36", "0.001333"], ["84435.55", "0.000235"], ["84435.56", "0"], ["84438.6", "0"], ["84440.42", "0.042"], ["84441.16", "0.236934"], ["84443.3", "0"], ["84444.9", "0"], ["84445.5", "0"], ["84448.9", "0"], ["84449.6", "0"], ["84453.12", "0"], ["84458.03", "0.0002"], ["84458.2", "0"], ["84458.22", "0"], ["84463.22", "0.355428"], ["84465.51", "0.237018"], ["84465.63", "0.0002"]], "u": 7510846, "seq": 66889464097}, "cts": 1742142265206, "record_time": 1742142264.308137}
{"topic": "orderbook.200.BTCUSDT", "ts": 1742142265409, "type": "delta", "data": {"s": "BTCUSDT", "b": [["84416.97", "0.343113"], ["84414.98", "0.023042"], ["84414.96", "0.076806"], ["84412.44", "0.0002"], ["84411.81", "0.000234"], ["84411.73", "0.000959"], ["84411.21", "0.005"], ["84408.09", "0.003"], ["84407.89", "0.003"], ["84407.7", "0"], ["84407.69", "0.003234"], ["84407.52", "0"], ["84406.53", "0.009898"], ["84406.15", "0.008108"], ["84404.99", "0"], ["84404.54", "0.015953"], ["84404.05", "0.000089"], ["84403.89", "0.190976"], ["84403.88", "0.236956"], ["84403.28", "0.162"], ["84402.19", "0.236961"], ["84401.51", "0.089922"], ["84401.01", "0.037565"], ["84400.98", "0"], ["84400.75", "0.11846"], ["84398.1", "0.04"], ["84397.5", "0"], ["84396.95", "0.054933"], ["84396.66", "0.003"], ["84396.21", "0.016227"], ["84395.6", "0.000886"], ["84395.5", "0.175419"], ["84395.17", "0.236934"], ["84393.49", "0.012163"], ["84391.77", "0.059948"], ["84391.7", "0"], ["84391.6", "0.04"], ["84391.4", "0"], ["84391.3", "0.04"], ["84390.95", "0.236934"], ["84390.84", "0.000252"], ["84390.52", "0"], ["84389.87", "0"], ["84389.7", "0"], ["84389.14", "0"], ["84388.46", "0.071105"], ["84387.04", "0"], ["84386.3", "0"], ["84386.27", "0.005503"], ["84386.04", "0.089922"], ["84385.65", "0"], ["84384", "0"], ["84383.95", "0"], ["84383.53", "0.491375"], ["84382.4", "0.07111"], ["84382.34", "0"], ["84380.99", "0.323094"], ["84378.35", "0"], ["84377.46", "0"], ["84375.73", "0.355387"], ["84375.43", "0"], ["84375.25", "0.059168"], ["84373.64", "0"], ["84369.45", "0.118432"], ["84369.44", "0"], ["84369.33", "0"], ["84368.41", "0"], ["84363.52", "0"], ["84362.57", "0.058962"], ["84360.95", "0"], ["84360.76", "0"], ["84359.4", "0"], ["84359.36", "0"], ["84358.6", "0"], ["84358.53", "0"], ["84358.36", "0"], ["84357.74", "0"], ["84356.86", "0"], ["84356.64", "0"]], "a": [["84411.74", "0"], ["84413.04", "0"], ["84414.96", "0"], ["84414.97", "0"], ["84415.48", "0"], ["84416.45", "0"], ["84416.98", "0.015217"], ["84416.99", "0"], ["84417.61", "0"], ["84418.61", "0"], ["84418.87", "0"], ["84420.27", "0"], ["84421.1", "0"], ["84421.61", "0"], ["84424.09", "0"], ["84424.24", "0.071075"], ["84424.32", "0.005923"], ["84424.5", "0"], ["84424.51", "0"], ["84424.76", "0"], ["84425.06", "0"], ["84426.08", "0"], ["84426.45", "0.118727"], ["84427.1", "0"], ["84427.49", "0"], ["84427.5", "0"], ["84428.05", "0.005"], ["84428.17", "0.048455"], ["84428.18", "0.059948"], ["84428.19", "0.079163"], ["84428.48", "0.019791"], ["84428.8", "0"], ["84428.95", "0"], ["84429.3", "0"], ["84430.8", "0"], ["84432.16", "0"], ["84432.3", "0.107312"], ["84432.5", "0"], ["84433.68", "0"], ["84433.79", "0"], ["84434.13", "0.008108"], ["84434.2", "0"], ["84434.51", "0"], ["84434.6", "0"], ["84435", "0.139546"], ["84435.57", "0"], ["84436.34", "0"], ["84437.12", "0"], ["84437.72", "0"], ["84437.77", "0"], ["84439.12", "0"], ["84440.89", "0.023749"], ["84441.16", "0"], ["84442.44", "0.005963"], ["84442.88", "0"], ["84442.96", "0.175419"], ["84444.51", "0.181392"], ["84445.38", "0"], ["84445.43", "0"], ["84446.79", "0.012163"], ["84447.64", "0.059948"], ["84448.49", "0"], ["84450.34", "0.023693"], ["84451.98", "0"], ["84453.15", "0"], ["84453.66", "0.07105"], ["84453.94", "0"], ["84455.39", "0"], ["84455.69", "0.11846"], ["84457.11", "0.071047"], ["84458.72", "0"], ["84462.67", "0.037821"], ["84463.22", "0"], ["84465.78", "0.059948"], ["84466.36", "0.029772"], ["84466.64", "0.000089"], ["84466.89", "0.0045"], ["84466.97", "0.005"], ["84467.09", "0.0045"], ["84467.54", "0.000235"], ["84468.06", "0.000235"], ["84468.17", "0.0002"], ["84468.62", "0.000335"], ["84468.94", "0.0045"], ["84469.09", "0.000612"], ["84469.14", "0.005833"], ["84469.56", "0.000111"], ["84469.67", "0.002853"], ["84469.78", "0.000253"], ["84469.95", "0.001467"], ["84470.12", "0.003334"], ["84470.37", "0.023686"], ["84470.69", "0.237018"], ["84470.7", "0.0002"], ["84472.18", "0.000235"], ["84472.64", "0.000935"], ["84472.71", "0.000235"], ["84473.02", "0.001604"], ["84473.24", "0.0002"], ["84473.26", "0.078424"], ["84473.32", "0.000612"], ["84473.36", "0.001333"], ["84473.57", "0.023988"], ["84473.76", "0.023686"]], "u": 7510847, "seq": 66889465817}, "cts": 1742142265407, "record_time": 1742142264.509001}
{"topic": "orderbook.200.BTCUSDT", "ts": 1742142265609, "type": "delta", "data": {"s": "BTCUSDT", "b": [["84422.68", "0.243178"], ["84422.66", "0.112809"], ["84422.65", "0.0004"], ["84422.57", "0.05"], ["84422.56", "0.11131"], ["84421.68", "0.063799"], ["84421.61", "0.06"], ["84420.03", "0.0002"], ["84418.46", "0.000551"], ["84418.43", "0.000611"], ["84416.99", "0.013516"], ["84416.98", "0.010532"], ["84416.97", "0.000434"], ["84416.45", "0.000234"], ["84416.14", "0.011846"], ["84415.52", "0.005"], ["84414.98", "0"], ["84414.97", "0.0002"], ["84414.96", "0.016806"], ["84414.25", "0.001333"], ["84414.22", "0.001467"], ["84414.21", "0.000611"], ["84414.05", "0.000252"], ["84413.97", "0.175419"], ["84413.79", "0.012173"], ["84413.78", "0.000797"], ["84412.5", "0.000089"], ["84412.33", "0.000234"], ["84411.21", "0"], ["84410.9", "0"], ["84410.2", "0.04"], ["84409.52", "0.016283"], ["84408.7", "0.04"], ["84408.54", "0.045453"], ["84408.14", "0.023692"], ["84407.99", "0"], ["84407.16", "0.018605"], ["84406.7", "0.089922"], ["84406.53", "0"], ["84406.48", "0.008453"], ["84406.15", "0"], ["84406.02", "0.118452"], ["84404.54", "0"], ["84404.2", "0.02"], ["84404.16", "0.059948"], ["84403.88", "0"], ["84402.94", "0.02"], ["84402.6", "0.02"], ["84402.3", "0.04"], ["84402.19", "0"], ["84402", "0.08"], ["84401.7", "0.04"], ["84401.51", "0"], ["84401.24", "0.02"], ["84401.01", "0.068225"], ["84400.75", "0"], ["84400.7", "0.044"], ["84400.19", "0.139545"], ["84399.15", "0"], ["84398.4", "0.04"], ["84397.85", "0.071097"], ["84397.19", "0.071098"], ["84396.21", "0"], ["84395.8", "0.04"], ["84395.6", "0.000089"], ["84395.5", "0"], ["84395.17", "0"], ["84393.49", "0"], ["84393.17", "0"], ["84393", "0.323048"], ["84391.76", "0.086323"], ["84390.95", "0"], ["84390.8", "0.00457"], ["84388.46", "0"], ["84388.3", "0"], ["84387.81", "0.005922"], ["84387.4", "0"], ["84387.08", "0"], ["84386.89", "0.005922"], ["84386.6", "0"], ["84385.3", "0.003417"], ["84385", "0"], ["84382.51", "0.236903"], ["84382.4", "0"], ["84381", "0.18878"], ["84380.99", "0"], ["84380.42", "0.355364"], ["84378.29", "0.236903"], ["84377.92", "0.013712"], ["84377.22", "0.177677"], ["84376.91", "0"], ["84376.3", "0.0144"], ["84376.2", "0.24702"], ["84375.74", "0.118432"], ["84375.73", "0"], ["84373.77", "0.019326"], ["84369.84", "0.177677"], ["84369.4", "0"], ["84368.69", "0"], ["84368.46", "0"], ["84367.84", "0"], ["84367.81", "0"], ["84367.79", "0"], ["84367.64", "0"], ["84367.56", "0"], ["84367.55", "0"], ["84366.97", "0"], ["84366.87", "0"], ["84366.84", "0"], ["84366.25", "0"], ["84365.94", "0"], ["84365.92", "0"], ["84365.65", "0"], ["84365.4", "0"], ["84365", "0"], ["84364.74", "0"], ["84364.34", "0"], ["84363.62", "0"], ["84363.57", "0"], ["84363.51", "0"], ["84363.17", "0"], ["84363", "0"], ["84362.57", "0"], ["84362.18", "0"], ["84361.98", "0"], ["84361.93", "0"], ["84361.8", "0"], ["84361.7", "0"], ["84361.35", "0"], ["84361.28", "0"], ["84361", "0"], ["84360.96", "0"]], "a": [["84416.98", "0"], ["84417.5", "0"], ["84418.43", "0"], ["84418.47", "0"], ["84418.69", "0"], ["84418.86", "0"], ["84420.03", "0"], ["84421.09", "0"], ["84421.62", "0"], ["84421.69", "0"], ["84422.57", "0"], ["84422.65", "0"], ["84422.69", "0.012517"], ["84424.24", "0"], ["84424.32", "0"], ["84424.98", "0.0005"], ["84426.45", "0"], ["84428.05", "0"], ["84428.17", "0"], ["84428.18", "0"], ["84428.19", "0"], ["84428.48", "0"], ["84432.1", "0"], ["84432.3", "0"], ["84432.31", "0"], ["84432.6", "0"], ["84434.13", "0"], ["84435", "0"], ["84435.2", "0"], ["84435.33", "0.005922"], ["84435.54", "0"], ["84436.78", "0.005"], ["84437.11", "0"], ["84437.3", "0.04"], ["84437.75", "0"], ["84439.04", "0"], ["84440.42", "0"], ["84440.89", "0"], ["84442.44", "0"], ["84442.85", "0.000295"], ["84442.86", "0.036409"], ["84442.96", "0"], ["84444.5", "0.059948"], ["84444.51", "0"], ["84444.59", "0.085229"], ["84444.6", "0"], ["84446.03", "0"], ["84446.22", "0"], ["84446.79", "0"], ["84447.48", "0"], ["84447.64", "0"], ["84448.48", "0.530432"], ["84450.34", "0"], ["84450.9", "0"], ["84451.31", "0.079145"], ["84451.5", "0.019787"], ["84451.76", "0.005825"], ["84452.55", "0.023543"], ["84452.9", "0.056"], ["84453.66", "0"], ["84454.26", "0.0008"], ["84454.43", "0.008115"], ["84454.9", "0.139545"], ["84455.69", "0"], ["84456.3", "0.052"], ["84456.5", "0.024526"], ["84457.11", "0"], ["84457.69", "0"], ["84458.05", "0.175419"], ["84458.18", "0.017796"], ["84459.3", "0.044"], ["84459.6", "0.04"], ["84460.06", "0"], ["84462.22", "0.071043"], ["84463.52", "0.118452"], ["84464.36", "0.018408"], ["84464.8", "0.008453"], ["84465.32", "0"], ["84466.36", "0"], ["84467.1", "0.028404"], ["84467.45", "0.029772"], ["84467.72", "0.00469"], ["84468.23", "0.071038"], ["84468.99", "0.0045"], ["84469.19", "0.0045"], ["84471.68", "0.162"], ["84473.26", "0"], ["84473.57", "0"], ["84474.43", "0.000253"], ["84474.58", "0.023686"], ["84474.6", "0.001467"], ["84475.15", "0.000089"], ["84475.46", "0.050866"], ["84475.53", "0.059948"], ["84475.62", "0.005922"], ["84475.77", "0.0002"], ["84476.83", "0.000235"], ["84477.05", "0.030367"], ["84477.21", "0.237018"], ["84477.35", "0.000235"], ["84477.54", "0.000612"], ["84477.58", "0.001333"], ["84478", "0.000161"], ["84478.07", "0.0013"], ["84479.07", "0.000253"], ["84479.24", "0.001467"], ["84481.47", "0.000235"], ["84481.74", "0.023686"]], "u": 7510848, "seq": 66889467341}, "cts": 1742142265607, "record_time": 1742142264.709687}
{"topic": "orderbook.200.BTCUSDT", "ts": 1742142265810, "type": "delta", "data": {"s": "BTCUSDT", "b": [["84426.9", "0.284493"], ["84425.82", "0.00355"], ["84425.74", "0.078963"], ["84425.73", "0.045947"], ["84424.97", "0.071074"], ["84422.69", "0.0004"], ["84422.68", "0.008115"], ["84422.66", "0"], ["84422.65", "0.000611"], ["84422.58", "0.049983"], ["84422.57", "0.0502"], ["84422.56", "0"], ["84421.85", "0.011845"], ["84421.62", "0.000234"], ["84421.61", "0"], ["84421.09", "0.000234"], ["84418.94", "0.000099"], ["84418.86", "0.001467"], ["84418.69", "0.000252"], ["84418.47", "0.013178"], ["84418.46", "0"], ["84418.34", "0.119577"], ["84418.29", "0.113193"], ["84417.5", "0.0002"], ["84416.99", "0.036539"], ["84416.98", "0.010132"], ["84416.97", "0.000234"], ["84416.7", "0.11193"], ["84416.61", "0.001491"], ["84416.15", "0.039"], ["84414.98", "0.059292"], ["84414.96", "0"], ["84414.44", "0.134656"], ["84414.24", "0.0297"], ["84414.23", "0.162"], ["84411.76", "0.025711"], ["84410.95", "0.058165"], ["84410.11", "0.075146"], ["84410.1", "0.04"], ["84409.87", "0.160749"], ["84409.76", "0.168855"], ["84409.6", "0.052"], ["84408.7", "0.08"], ["84408.54", "0"], ["84407.4", "0.236903"], ["84407.16", "0"], ["84406.39", "0.172163"], ["84406.03", "0.133507"], ["84405.08", "0.071091"], ["84404.2", "0"], ["84403.89", "0"], ["84402.94", "0"], ["84402.6", "0"], ["84401.71", "0.102827"], ["84401.34", "0.267025"], ["84401.24", "0"], ["84401.22", "0.302132"], ["84401.01", "0"], ["84398.4", "0"], ["84398.1", "0"], ["84397.71", "0.086886"], ["84397.19", "0"], ["84396.95", "0"], ["84395.29", "0.271426"], ["84393.01", "0.178624"], ["84392.51", "0.024279"], ["84392.33", "0.05"], ["84392.32", "0.049535"], ["84392.1", "0"], ["84391.76", "0"], ["84391.68", "0.11"], ["84391.6", "0"], ["84391.3", "0"], ["84390.41", "0.355333"], ["84390.4", "0"], ["84390", "0"], ["84389.68", "0.11"], ["84389", "0.000119"], ["84388.87", "0"], ["84386.73", "0.236891"], ["84386.32", "0.000987"], ["84381.01", "0.118432"], ["84380.42", "0"], ["84375.72", "0"], ["84375.71", "0"], ["84375.29", "0"], ["84375.25", "0"], ["84375.2", "0"], ["84374.95", "0"], ["84374.68", "0"], ["84374.46", "0"], ["84373.77", "0"], ["84372.72", "0"], ["84372.47", "0"], ["84372.46", "0"], ["84372.45", "0"], ["84372.28", "0"], ["84372.05", "0"], ["84372.01", "0"], ["84371.96", "0"], ["84371.93", "0"], ["84370.56", "0"], ["84370.44", "0"], ["84370.43", "0"], ["84370.3", "0"], ["84370.25", "0"], ["84370.04", "0"], ["84369.84", "0"], ["84369.45", "0"]], "a": [["84422.69", "0"], ["84423.12", "0"], ["84423.34", "0"], ["84423.51", "0"], ["84424.98", "0"], ["84425.1", "0"], ["84425.74", "0"], ["84426.26", "0"], ["84426.87", "0"], ["84426.91", "0.006333"], ["84437.28", "0.000296"], ["84437.29", "0.011946"], ["84437.3", "0"], ["84439.53", "0.000906"], ["84440.28", "0.000153"], ["84440.7", "0.058034"], ["84442.85", "0"], ["84442.86", "0"], ["84444.49", "0.019374"], ["84444.59", "0"], ["84448.48", "0"], ["84448.49", "0.111919"], ["84449.07", "0.11684"], ["84449.57", "0"], ["84449.88", "0.120006"], ["84449.99", "0.107958"], ["84451.76", "0"], ["84452.55", "0"], ["84454.67", "0"], ["84456", "0.000119"], ["84456.19", "0"], ["84456.2", "0.04"], ["84456.82", "0.179803"], ["84456.92", "0"], ["84457.9", "0.052"], ["84458.04", "0.156509"], ["84458.41", "0.164119"], ["84460.41", "0.000987"], ["84461.02", "0.167742"], ["84462.22", "0"], ["84462.77", "0.00951"], ["84463.22", "0.181948"], ["84465.36", "0.283725"], ["84465.96", "1.525313"], ["84466.95", "0.269588"], ["84467.45", "0"], ["84472.11", "0.278824"], ["84473.16", "0.071034"], ["84474.2", "0.133403"], ["84475.46", "0"], ["84478", "0.000042"], ["84481.47", "0"], ["84481.74", "0"]], "u": 7510849, "seq": 66889468371}, "cts": 1742142265807, "record_time": 1742142264.909102}
{"topic": "orderbook.200.BTCUSDT", "ts": 1742142266010, "type": "delta", "data": {"s": "BTCUSDT", "b": [["84426.9", "0.199745"], ["84426.07", "0.011844"], ["84425.82", "0"], ["84425.75", "0.035106"], ["84425.74", "0"], ["84424.9", "0.0004"], ["84420.18", "0.000551"], ["84420.16", "0.011845"], ["84418.94", "0"], ["84418.52", "0.003"], ["84418.47", "0.001333"], ["84418.46", "0.0005"], ["84418.34", "0"], ["84418.32", "0.003"], ["84418.29", "0"], ["84418.13", "0.136769"], ["84418.12", "0.003"], ["84417.58", "0.113372"], ["84417.54", "0.120097"], ["84416.99", "0"], ["84416.7", "0"], ["84416.14", "0"], ["84415.75", "0.118116"], ["84414.2", "0.044"], ["84413.8", "0.04"], ["84412.5", "0.040089"], ["84410.11", "0.309372"], ["84409.87", "0"], ["84409.76", "0"], ["84409", "0.166221"], ["84408.92", "0.180589"], ["84408.7", "0.04"], ["84407.4", "0.04"], ["84407.1", "0.04"], ["84406.39", "0"], ["84406.3", "0.04"], ["84406.2", "0.02"], ["84405.64", "0.02"], ["84405.63", "0.168049"], ["84404.6", "0.02"], ["84403.18", "0.236891"], ["84402.31", "0.118632"], ["84402", "0.04"], ["84401.7", "0"], ["84401.34", "0"], ["84401.22", "0"], ["84400.7", "0"], ["84400.47", "0.300887"], ["84400.38", "0.273897"], ["84398.96", "0.236891"], ["84395.8", "0"], ["84395.63", "0.05"], ["84395.62", "0.049536"], ["84395.3", "0.118432"], ["84395.29", "0"], ["84394.96", "0"], ["84392.33", "0"], ["84392.32", "0"], ["84391.68", "0"], ["84390.41", "0"], ["84389.68", "0"], ["84389.1", "0"], ["84386.9", "0.0013"], ["84386.74", "0.118432"], ["84383.54", "0.355342"], ["84383.02", "0"], ["84381.6", "0.015"], ["84378.29", "0"], ["84376.92", "0"], ["84376.36", "0"], ["84376.3", "0"], ["84376.27", "0"], ["84376.23", "0"], ["84376.2", "0"], ["84375.9", "0"], ["84375.74", "0"]], "a": [["84426.91", "0.007375"], ["84435.35", "0.0005"], ["84435.88", "0.000296"], ["84435.89", "0.035018"], ["84435.9", "0.071065"], ["84437.28", "0"], ["84437.29", "0"], ["84439.03", "0.000153"], ["84440.07", "0"], ["84440.11", "0.0001"], ["84440.28", "0"], ["84440.7", "0.036715"], ["84442.87", "0"], ["84448.31", "0.105335"], ["84448.5", "0"], ["84449.04", "0.104951"], ["84449.07", "0"], ["84449.12", "0.112443"], ["84449.88", "0"], ["84449.99", "0"], ["84451.99", "0.023598"], ["84452.5", "0.04"], ["84454.1", "0.04"], ["84455.87", "0.170904"], ["84456.5", "0"], ["84456.82", "0"], ["84457.66", "0.16722"], ["84457.8", "0.064"], ["84458.41", "0"], ["84460.26", "0.175655"], ["84461.02", "0"], ["84464.4", "0.541001"], ["84465.36", "0"], ["84465.96", "0"], ["84466.19", "0.300135"], ["84466.95", "0"], ["84471.36", "0.271318"], ["84472.11", "0"], ["84474.2", "0"], ["84478.07", "0"], ["84478.11", "0.0013"], ["84478.92", "0.0045"], ["84479.24", "0"]], "u": 7510850, "seq": 66889468735}, "cts": 1742142266006, "record_time": 1742142265.109826}
{"topic": "orderbook.200.BTCUSDT", "ts": 1742142266210, "type": "delta", "data": {"s": "BTCUSDT", "b": [["84435.35", "0.298845"], ["84435.02", "0.012613"], ["84435.01", "0.03"], ["84434.52", "0.011843"], ["84432.7", "0.0002"], ["84431.09", "0.000611"], ["84430.9", "0.003975"], ["84430.38", "0.01287"], ["84430.37", "0.0402"], ["84430.17", "0.0002"], ["84428.15", "0.001467"], ["84427.98", "0.000252"], ["84426.91", "0.031323"], ["84426.9", "0.0002"], ["84426.87", "0.000611"], ["84426.26", "0.000234"], ["84426.07", "0"], ["84425.8", "0.044"], ["84425.75", "0"], ["84425.74", "0.118668"], ["84425.73", "0.015947"], ["84425.5", "0.04"], ["84425.48", "0.005"], ["84425.1", "0.0002"], ["84424.97", "0"], ["84424.96", "0.059948"], ["84424.1", "0.04"], ["84423.51", "0.001467"], ["84423.34", "0.000252"], ["84423.16", "0.000099"], ["84422.69", "0.001733"], ["84422.6", "0.098869"], ["84422.58", "0"], ["84422.57", "0.0002"], ["84422.1", "0.04"], ["84421.85", "0"], ["84421.2", "0.04"], ["84420.95", "0.000089"], ["84420.29", "0.118434"], ["84420.18", "0"], ["84420.16", "0"], ["84419.2", "0.04"], ["84418.7", "0.04"], ["84418.13", "0.066798"], ["84417.58", "0"], ["84417.54", "0"], ["84416.98", "0.010366"], ["84416.97", "0"], ["84416.44", "0.00055"], ["84415.75", "0"], ["84415.52", "0"], ["84414.99", "0.118434"], ["84414.89", "0.02"], ["84414.5", "0.04"], ["84414.24", "0.02"], ["84413.98", "0.059948"], ["84413.39", "0.02"], ["84412.64", "0.02"], ["84410.96", "0.017796"], ["84410.95", "0"], ["84410.2", "0"], ["84410.11", "0.215814"], ["84410.1", "0"], ["84409.61", "0.118434"], ["84409", "0"], ["84408.92", "0"], ["84406.3", "0"], ["84406.2", "0"], ["84406.02", "0"], ["84405.64", "0"], ["84405.63", "0"], ["84404.6", "0"], ["84404.43", "0.833708"], ["84403.18", "0"], ["84402.58", "1.52835"], ["84402.3", "0"], ["84402", "0"], ["84400.47", "0"], ["84400.38", "0"], ["84398.96", "0"], ["84398.3", "0.17192"], ["84395.83", "0.05"], ["84395.82", "0.049536"], ["84395.63", "0"], ["84395.62", "0"], ["84395.49", "0.017765"], ["84393.01", "0"], ["84391.84", "0.005922"], ["84389.6", "0.023689"], ["84388.59", "0.000689"], ["84386.75", "0.355319"], ["84386.73", "0"], ["84384.62", "0"], ["84384.44", "0.023689"], ["84383.54", "0"], ["84383.53", "0.075331"], ["84382.05", "0"], ["84381.73", "0"], ["84381.6", "0"], ["84381.56", "0"], ["84381.01", "0"], ["84381", "0"], ["84380.49", "0"], ["84380.45", "0"], ["84380.41", "0"], ["84379.84", "0"], ["84379.52", "0"], ["84379.32", "0"], ["84378.7", "0"], ["84377.92", "0"], ["84377.22", "0"], ["84377.09", "0"], ["84376.99", "0"]], "a": [["84426.91", "0"], ["84427.13", "0"], ["84427.63", "0"], ["84427.98", "0"], ["84428.15", "0"], ["84430.17", "0"], ["84430.38", "0"], ["84430.9", "0"], ["84431.09", "0"], ["84431.13", "0"], ["84432.62", "0"], ["84432.7", "0"], ["84432.79", "0"], ["84435.02", "0"], ["84435.23", "0"], ["84435.31", "0"], ["84435.33", "0"], ["84435.35", "0"], ["84435.36", "0.004712"], ["84435.88", "0"], ["84435.89", "0"], ["84435.9", "0"], ["84436.78", "0"], ["84439.03", "0"], ["84439.53", "0.000611"], ["84440.44", "0"], ["84440.7", "0"], ["84441.11", "0"], ["84441.83", "0.024127"], ["84441.84", "0.07106"], ["84442.35", "0.005"], ["84443.8", "0.001833"], ["84444.49", "0"], ["84444.5", "0"], ["84448.31", "0"], ["84448.48", "0.000296"], ["84448.49", "0.050787"], ["84449.04", "0"], ["84449.12", "0"], ["84450.08", "0.019789"], ["84451.3", "0.000295"], ["84451.5", "0"], ["84451.99", "0"], ["84453.47", "0"], ["84454.06", "0"], ["84454.26", "0"], ["84455.38", "0"], ["84455.87", "0"], ["84456", "0"], ["84456.86", "0"], ["84456.89", "0"], ["84457.65", "0.294528"], ["84457.66", "0"], ["84458.04", "0"], ["84458.43", "0.005916"], ["84459.44", "0"], ["84460.26", "0"], ["84462.32", "0"], ["84462.67", "0"], ["84463.52", "0"], ["84464.35", "0.059948"], ["84464.4", "0.246059"], ["84464.8", "0"], ["84464.84", "0"], ["84465.51", "0"], ["84465.78", "0"], ["84466.19", "0"], ["84468.23", "0"], ["84470.69", "0"], ["84471.36", "0"], ["84472.09", "0.0008"], ["84472.38", "0.008453"], ["84475.62", "0"], ["84476.09", "0.023688"], ["84477.21", "0"], ["84477.77", "0.017796"], ["84477.83", "0.07103"], ["84478.3", "0.0002"], ["84479.06", "0.118434"], ["84479.13", "0.0045"], ["84479.14", "0.029772"], ["84479.24", "0.001467"], ["84480.84", "0.0002"], ["84481.47", "0.000235"], ["84481.74", "0.023686"], ["84481.76", "0.000612"], ["84481.81", "0.015404"], ["84482", "0.000235"], ["84482.16", "0.035533"], ["84482.38", "0.015"], ["84482.92", "0.0045"], ["84483.14", "0.0025"], ["84483.25", "0.0045"], ["84483.29", "0.0045"], ["84483.37", "0.0002"], ["84483.45", "0.0045"], ["84483.66", "0.000089"], ["84483.72", "0.000253"], ["84483.89", "0.001467"], ["84483.96", "0.04"], ["84483.97", "0.04"], ["84484.24", "0.430885"], ["84484.78", "0.059948"], ["84484.79", "0.118574"], ["84485.02", "0.00315"], ["84485.45", "0.02464"], ["84485.63", "0.322693"], ["84485.91", "0.0002"], ["84485.99", "0.000612"], ["84486.03", "0.001333"], ["84486.12", "0.000235"], ["84486.65", "0.000235"], ["84488.37", "0.000253"], ["84488.53", "0.001467"], ["84488.86", "0.005922"], ["84489.5", "0.405482"], ["84489.7", "0.0045"], ["84489.9", "0.0045"], ["84490", "0.002053"], ["84490.21", "0.000612"], ["84490.25", "0.001333"]], "u": 7510851, "seq": 66889470258}, "cts": 1742142266207, "record_time": 1742142265.309318}
{"topic": "orderbook.200.BTCUSDT", "ts": 1742142266409, "type": "delta", "data": {"s": "BTCUSDT", "b": [["84435.35", "0.102611"], ["84435.02", "0"], ["84435.01", "0"], ["84431.28", "0.071069"], ["84431.14", "0.011843"], ["84430.9", "0"], ["84430.38", "0.000234"], ["84430.37", "0"], ["84427.63", "0.0002"], ["84427.01", "0.003"], ["84426.9", "0"], ["84426.81", "0.003"], ["84426.61", "0.003"], ["84425.81", "0.04425"], ["84425.74", "0.000234"], ["84425.73", "0"], ["84424.96", "0"], ["84423.16", "0"], ["84422.71", "0.007106"], ["84422.6", "0.285943"], ["84421.7", "0.052"], ["84421.68", "0"], ["84420.18", "0.00055"], ["84419.2", "0.08"], ["84416.44", "0"], ["84416.04", "0.02"], ["84415.09", "0.02"], ["84414.89", "0"], ["84414.44", "0.154656"], ["84414.24", "0"], ["84414.2", "0"], ["84413.8", "0"], ["84413.49", "0.02"], ["84413.39", "0"], ["84412.64", "0"], ["84412.5", "0.000089"], ["84411.76", "0.018605"], ["84411.73", "0"], ["84410.11", "0"], ["84408.7", "0"], ["84408.09", "0"], ["84407.89", "0"], ["84407.69", "0.000234"], ["84407.4", "0"], ["84407.1", "0"], ["84406.7", "0"], ["84406.03", "0.816757"], ["84398.92", "0.000987"], ["84398.3", "0"], ["84397.03", "0.05"], ["84397.02", "0.049544"], ["84396.66", "0"], ["84396.46", "0"], ["84396.26", "0"], ["84395.83", "0"], ["84395.82", "0"], ["84392.51", "0"], ["84386.75", "0"], ["84386.73", "0.236868"], ["84386.38", "0.162"], ["84386.32", "0"], ["84382.05", "0.0002"], ["84381.73", "0.001467"], ["84381.62", "0.023689"], ["84381.6", "0.015"], ["84381.56", "0.000252"], ["84381.01", "0.118432"], ["84380.49", "0.001333"], ["84380.45", "0.000611"], ["84379.84", "0.000234"], ["84379.52", "0.0002"], ["84379.32", "0.000234"], ["84379.06", "0.023689"], ["84378.7", "0.000089"], ["84378.23", "0.023689"], ["84377.92", "0.013712"]], "a": [["84435.36", "0.138322"], ["84437.2", "0.071064"], ["84441.83", "0"], ["84441.84", "0"], ["84444.63", "0.019789"], ["84449.41", "0.005921"], ["84450.08", "0"], ["84451.31", "0"], ["84452.89", "0.166263"], ["84454.05", "0"], ["84454.89", "0.059948"], ["84457.65", "0"], ["84458.43", "0.005966"], ["84460.41", "0"], ["84461.84", "0.023917"], ["84463.2", "0.029772"], ["84466.66", "0.071039"], ["84468.94", "0"], ["84469.14", "0.001333"], ["84469.99", "0.236868"], ["84470.7", "0.237068"], ["84471.67", "0.118434"], ["84472.53", "1.522923"], ["84473.18", "0.000987"], ["84475.52", "0.355357"], ["84477.83", "0"], ["84479.14", "0"], ["84480.13", "0.162"], ["84482.27", "0.089922"], ["84482.92", "0"], ["84483.25", "0"], ["84483.45", "0"], ["84484.92", "0.027942"], ["84487.33", "0.0045"], ["84487.53", "0.0045"], ["84488.58", "0.162"], ["84489.5", "0"], ["84489.7", "0"], ["84489.9", "0"], ["84490", "0"], ["84490.21", "0"], ["84490.25", "0"]], "u": 7510852, "seq": 66889470828}, "cts": 1742142266408, "record_time": 1742142265.507931}
{"topic": "orderbook.200.BTCUSDT", "ts": 1742142266609, "type": "delta", "data": {"s": "BTCUSDT", "b": [["84437.26", "0.119972"], ["84437.2", "0.019385"], ["84437.19", "0.031184"], ["84435.35", "0"], ["84432.62", "0.000252"], ["84431.61", "0.000099"], ["84431.28", "0"], ["84431.13", "0.001333"], ["84430.9", "0.000235"], ["84430.11", "0.005"], ["84428.61", "0.011844"], ["84427.31", "0.107946"], ["84427.27", "0.107045"], ["84426.93", "0.015945"], ["84426.91", "0.030923"], ["84426.51", "0.109135"], ["84426.31", "0.17535"], ["84425.82", "0.118434"], ["84425.81", "0"], ["84424.82", "0.063785"], ["84422.72", "0.059948"], ["84422.6", "0.138869"], ["84420.18", "0"], ["84418.76", "0.176495"], ["84418.13", "0"], ["84416.62", "0.077595"], ["84416.18", "0.02"], ["84416.04", "0"], ["84415.09", "0"], ["84414.89", "0.02"], ["84414.5", "0"], ["84414.44", "0.134656"], ["84414.41", "0.089922"], ["84413.62", "0.118434"], ["84413.49", "0"], ["84413.29", "0.02"], ["84411.01", "0.071086"], ["84410.95", "0.133138"], ["84409.62", "0.066375"], ["84409.6", "0"], ["84409.13", "0.008717"], ["84405.08", "0"], ["84404.08", "0.071092"], ["84403.92", "0.023948"], ["84401.71", "0"], ["84397.85", "0"], ["84394.45", "0.04"], ["84394.44", "0.039638"], ["84388", "0.24702"], ["84386.75", "0.355335"], ["84385.46", "0"], ["84383.22", "0"], ["84383.14", "0"], ["84382.51", "0"], ["84382.39", "0"], ["84382.38", "0"], ["84382.05", "0"], ["84381.73", "0"], ["84381.62", "0"], ["84381.6", "0"], ["84381.56", "0"], ["84381.01", "0"], ["84380.49", "0"], ["84380.45", "0"], ["84379.84", "0"], ["84379.52", "0"], ["84379.32", "0"], ["84379.06", "0"], ["84378.7", "0"], ["84378.23", "0"], ["84377.92", "0"]], "a": [["84435.36", "0"], ["84435.55", "0"], ["84437.2", "0"], ["84437.27", "0.005677"], ["84440.11", "0"], ["84443.8", "0.001333"], ["84444.63", "0"], ["84445.71", "0.0005"], ["84446.98", "0.005"], ["84448.48", "0"], ["84448.49", "0"], ["84451.3", "0"], ["84451.35", "0.000296"], ["84452.38", "0.019789"], ["84452.5", "0"], ["84452.89", "0"], ["84452.9", "0"], ["84453.2", "0.000295"], ["84453.21", "0.073199"], ["84454.1", "0"], ["84454.49", "0.079157"], ["84454.89", "0"], ["84456.2", "0"], ["84456.3", "0"], ["84457.8", "0"], ["84457.89", "0.102854"], ["84457.9", "0"], ["84457.94", "0.11124"], ["84458.43", "0"], ["84458.75", "0.115859"], ["84459.3", "0"], ["84459.6", "0"], ["84459.69", "0.113986"], ["84461.84", "0"], ["84463.2", "0"], ["84464.4", "0"], ["84466.5", "0.15821"], ["84466.66", "0"], ["84467.26", "0.160018"], ["84469.85", "0.158124"], ["84469.99", "0"], ["84470.48", "0.071036"], ["84470.69", "0.638056"], ["84470.7", "0.0002"], ["84471.67", "0"], ["84473.16", "0"], ["84473.9", "0.023686"], ["84475.43", "0.118434"], ["84475.52", "0"], ["84475.77", "0.286299"], ["84479.93", "0.071028"], ["84480.91", "0.275363"], ["84482.06", "0.04"], ["84482.07", "0.04"], ["84483.96", "0"], ["84483.97", "0"], ["84484.92", "0"], ["84488.57", "0.355316"], ["84488.74", "0.015"], ["84489.5", "0.405482"], ["84490", "0.002053"], ["84490.21", "0.000612"], ["84490.25", "0.001333"], ["84490.73", "0.000335"], ["84490.77", "0.000235"], ["84490.96", "0.001"]], "u": 7510853, "seq": 66889471676}, "cts": 1742142266608, "record_time": 1742142265.708248}
{"topic": "orderbook.200.BTCUSDT", "ts": 1742142266810, "type": "delta", "data": {"s": "BTCUSDT", "b": [["84437.2", "0"], ["84436.43", "0.011843"], ["84431.61", "0"], ["84428.82", "0.0005"], ["84428.61", "0"], ["84427.58", "0.000296"], ["84427.57", "0.071067"], ["84427.56", "0.236889"], ["84427.32", "0.000296"], ["84427.31", "0"], ["84427.27", "0"], ["84426.51", "0"], ["84426.31", "0"], ["84425.84", "0.070268"], ["84425.83", "0.059003"], ["84425.82", "0"], ["84422.7", "0.114435"], ["84422.69", "0.001333"], ["84422.6", "0.04"], ["84418.77", "0.149222"], ["84418.76", "0"], ["84418.46", "0"], ["84416.62", "0"], ["84414.98", "0"], ["84414.89", "0"], ["84414.79", "0.02"], ["84414.41", "0"], ["84414.14", "0.02"], ["84413.29", "0"], ["84411.62", "0.236862"], ["84411.01", "0"], ["84407.4", "0.236862"], ["84405.24", "0.323001"], ["84400.83", "0.000987"], ["84399.15", "0.071096"], ["84398.92", "0"], ["84394.84", "0"], ["84394.35", "0"], ["84393", "0"], ["84386.75", "0"], ["84386.73", "0"], ["84385.35", "0.237008"], ["84383.54", "0.355334"], ["84383.53", "0"], ["84383.24", "0.2"], ["84383.22", "0.006075"], ["84383.14", "0.0025"], ["84382.39", "0.059948"]], "a": [["84437.27", "0.105677"], ["84439.95", "0.071062"], ["84444.01", "0.006715"], ["84453.21", "0.161129"], ["84454.89", "0.059948"], ["84457.2", "0.04"], ["84457.6", "0.056"], ["84457.89", "0.149732"], ["84457.94", "0"], ["84458.75", "0"], ["84458.8", "0.04"], ["84458.81", "0.005801"], ["84459.69", "0"], ["84461", "0.052"], ["84461.85", "0.024078"], ["84462.7", "0.052"], ["84463.1", "0.0642"], ["84463.22", "0.080937"], ["84464.1", "0.044"], ["84464.3", "0.04"], ["84465.77", "0.17909"], ["84466.48", "0.236862"], ["84466.5", "0"], ["84467.26", "0"], ["84469.85", "0"], ["84470.7", "0.237062"], ["84472.52", "0.118431"], ["84473.18", "0"], ["84475.09", "0.000987"], ["84475.77", "0.0002"], ["84480.91", "0"], ["84482.05", "0.355338"], ["84482.93", "0.029772"], ["84488.57", "0"], ["84488.74", "0"], ["84488.86", "0"], ["84489.5", "0"], ["84490", "0"], ["84490.21", "0"], ["84490.25", "0"], ["84490.73", "0"], ["84490.77", "0"], ["84490.96", "0"]], "u": 7510854, "seq": 66889472138}, "cts": 1742142266808, "record_time": 1742142265.908709}
{"topic": "orderbook.200.BTCUSDT", "ts": 1742142267009, "type": "delta", "data": {"s": "BTCUSDT", "b": [["84433.5", "0.000099"], ["84425.86", "0.149161"], ["84425.85", "0.236862"], ["84425.84", "0"], ["84424.39", "0.003"], ["84424.19", "0.003"], ["84420.49", "0.236862"], ["84418.77", "0.078336"], ["84418.08", "0.02"], ["84416.69", "0.02"], ["84416.27", "0.236862"], ["84416.18", "0"], ["84416.14", "0.02"], ["84415.09", "0.02"], ["84414.79", "0"], ["84414.44", "0.154656"], ["84414.14", "0"], ["84397.63", "0.05"], ["84397.62", "0.049546"], ["84397.03", "0"], ["84397.02", "0"], ["84394.74", "0.177647"], ["84392.34", "0.11"], ["84386.39", "0.355333"], ["84384.67", "0"], ["84384.59", "0"], ["84384.48", "0"], ["84384.44", "0"], ["84383.96", "0"], ["84383.54", "0"], ["84383.24", "0"], ["84383.22", "0"], ["84383.14", "0"], ["84382.39", "0"]], "a": [["84444.01", "0"], ["84449.17", "0.00015"], ["84453.21", "0.181917"], ["84457.89", "0.102854"], ["84458.81", "0"], ["84460.53", "0.023616"], ["84461.6", "0.04"], ["84461.85", "0"], ["84465.76", "0.142526"], ["84466.89", "0"], ["84466.92", "0.236862"], ["84467.09", "0"], ["84468.99", "0"], ["84469.19", "0"], ["84471.14", "0.236862"], ["84472.52", "0"], ["84478.92", "0"], ["84479.13", "0"], ["84482.05", "0"], ["84483.29", "0"], ["84484.23", "0.355336"], ["84487.01", "0.0045"], ["84487.05", "0.0045"], ["84487.26", "0.0045"], ["84488.74", "0.015"], ["84488.86", "0.005922"]], "u": 7510855, "seq": 66889472302}, "cts": 1742142267001, "record_time": 1742142266.107703}
{"topic": "orderbook.200.BTCUSDT", "ts": 1742142267210, "type": "delta", "data": {"s": "BTCUSDT", "b": [["84437.26", "0.114042"], ["84437.19", "0"], ["84436.43", "0.004899"], ["84432.79", "0.021456"], ["84432.78", "0.071068"], ["84425.86", "0"], ["84425.85", "0"], ["84425.84", "0.078102"], ["84422.7", "0.171189"], ["84421.13", "0.113338"], ["84420.5", "0.118431"], ["84420.29", "0"], ["84419.66", "0.11203"], ["84418.08", "0"], ["84417.78", "0.02"], ["84416.69", "0"], ["84416.39", "0.02"], ["84416.14", "0"], ["84415.84", "0.02"], ["84415.09", "0"], ["84414.79", "0.02"], ["84414.44", "0.134656"], ["84414.14", "0.02"], ["84412.85", "0.178469"], ["84411.62", "0"], ["84410.95", "0"], ["84407.4", "0"], ["84404.34", "0.29857"], ["84403.92", "0"], ["84397.83", "0.05"], ["84397.82", "0.049546"], ["84397.63", "0"], ["84397.62", "0"], ["84394.74", "0"], ["84392.34", "0"], ["84390.95", "0.177647"], ["84388.1", "0.24702"], ["84388", "0"], ["84386.39", "0"], ["84384.67", "0.000613"]], "a": [["84437.27", "0.160086"], ["84437.49", "0.071064"], ["84439.95", "0"], ["84441.48", "0.008506"], ["84444.01", "0.011842"], ["84451.35", "0"], ["84451.77", "0.073167"], ["84451.78", "0.115248"], ["84452.86", "0.11471"], ["84453.18", "0.000296"], ["84453.21", "0.073199"], ["84454.17", "0.162"], ["84459.14", "0.003"], ["84459.67", "0.163955"], ["84463.09", "0.125397"], ["84463.22", "0"], ["84464.56", "0.071041"], ["84468.19", "0.28086"], ["84472.52", "0.118431"], ["84478", "0.000161"], ["84479.93", "0"], ["84482.05", "0.355341"], ["84482.06", "0"], ["84482.07", "0"], ["84482.26", "0.04"], ["84482.27", "0.129922"], ["84484.23", "0"], ["84487.05", "0"], ["84487.26", "0"], ["84487.33", "0"], ["84487.53", "0"], ["84488.37", "0"], ["84488.53", "0"], ["84488.58", "0"], ["84488.74", "0"], ["84488.86", "0"]], "u": 7510856, "seq": 66889472628}, "cts": 1742142267206, "record_time": 1742142266.309285}
{"topic": "orderbook.200.BTCUSDT", "ts": 1742142267409, "type": "delta", "data": {"s": "BTCUSDT", "b": [["84436.43", "0.001097"], ["84426.11", "0.003"], ["84425.91", "0.003"], ["84421.13", "0"], ["84419.68", "0.113601"], ["84419.66", "0"], ["84418.91", "0.114433"], ["84418.77", "0.151603"], ["84418.18", "0.02"], ["84417.78", "0"], ["84416.89", "0.02"], ["84416.39", "0"], ["84415.19", "0.02"], ["84414.79", "0"], ["84412.9", "0.174827"], ["84412.85", "0"], ["84404.43", "0.263755"], ["84404.34", "0"], ["84401.96", "0.288018"], ["84398.38", "0.023237"], ["84385.3", "0"], ["84384.71", "0"], ["84384.67", "0"]], "a": [["84451.01", "0.000296"], ["84451.66", "0.074932"], ["84451.77", "0.000295"], ["84451.78", "0"], ["84452.71", "0.110176"], ["84452.86", "0"], ["84453.18", "0"], ["84453.2", "0"], ["84453.21", "0.12678"], ["84454.9", "0"], ["84455.33", "0.110155"], ["84459.49", "0.164579"], ["84459.67", "0"], ["84460.76", "0.139527"], ["84463.23", "0.185763"], ["84463.8", "0.16835"], ["84467.96", "0.268499"], ["84468.19", "0"], ["84469.99", "0.138505"], ["84472.27", "0.283219"], ["84479.48", "0.473488"], ["84482.04", "0.355342"], ["84482.05", "0"], ["84486.12", "0"], ["84486.65", "0"], ["84487.01", "0"]], "u": 7510857, "seq": 66889472888}, "cts": 1742142267408, "record_time": 1742142266.507632}
{"topic": "orderbook.200.BTCUSDT", "ts": 1742142267609, "type": "delta", "data": {"s": "BTCUSDT", "b": [["84436.43", "0.011843"], ["84419.86", "0.109376"], ["84419.68", "0"], ["84418.91", "0"], ["84416.24", "0.02"], ["84415.84", "0"], ["84414.54", "0.02"], ["84414.44", "0.212494"], ["84414.14", "0"], ["84413.08", "0.160413"], ["84412.9", "0"], ["84404.61", "0.280525"], ["84404.43", "0"], ["84401.96", "0"], ["84397.83", "0"], ["84397.82", "0"], ["84397.43", "0.05"], ["84397.42", "0.049546"], ["84385.3", "0.003417"], ["84384.71", "0.001333"]], "a": [["84441.48", "0"], ["84446.13", "0.000153"], ["84451.61", "0.000295"], ["84451.66", "0"], ["84451.77", "0"], ["84451.87", "0.038619"], ["84452.71", "0"], ["84452.9", "0.120096"], ["84455.33", "0"], ["84457.89", "0.173585"], ["84459.49", "0.002128"], ["84459.67", "0.161414"], ["84463.8", "0"], ["84465.76", "0.270918"], ["84467.96", "0"], ["84468.14", "0.289569"], ["84472.27", "0"], ["84472.52", "0"], ["84482.04", "0"], ["84484.77", "0.355338"], ["84486.12", "0.000235"], ["84486.65", "0.000235"], ["84487.01", "0.0045"]], "u": 7510858, "seq": 66889473079}, "cts": 1742142267607, "record_time": 1742142266.708031}
{"topic": "orderbook.200.BTCUSDT", "ts": 1742142267810, "type": "delta", "data": {"s": "BTCUSDT", "b": [["84436.43", "0"], ["84421.06", "0.11123"], ["84421.02", "0.114734"], ["84419.86", "0"], ["84419.66", "0.115105"], ["84418.68", "0.02"], ["84418.18", "0"], ["84417.39", "0.02"], ["84416.89", "0"], ["84416.74", "0.02"], ["84416.24", "0"], ["84415.69", "0.02"], ["84415.19", "0"], ["84415.04", "0.02"], ["84414.54", "0"], ["84413.73", "0.561085"], ["84413.08", "0"], ["84412.88", "0.166333"], ["84412.55", "0.161376"], ["84409.2", "0.160497"], ["84407.4", "0.236862"], ["84404.61", "0"], ["84404.41", "0.293375"], ["84404.08", "0.364623"], ["84403.18", "0.236862"], ["84398.19", "0.283554"], ["84397.83", "0.05"], ["84397.82", "0.049546"], ["84397.43", "0"], ["84397.42", "0"], ["84386.37", "0"], ["84386.27", "0"], ["84386.2", "0"], ["84386.04", "0"], ["84385.35", "0"], ["84385.3", "0"], ["84384.71", "0"]], "a": [["84441.48", "0.011842"], ["84446.13", "0"], ["84451.54", "0.071989"], ["84451.55", "0.118998"], ["84451.61", "0"], ["84451.87", "0"], ["84452.36", "0.110968"], ["84452.69", "0.105886"], ["84452.89", "0.094127"], ["84452.9", "0"], ["84453.21", "0"], ["84458.18", "0"], ["84459.47", "0.168005"], ["84459.67", "0"], ["84460.83", "0.166637"], ["84463.41", "0.162476"], ["84464.63", "0.006089"], ["84467.94", "0.286333"], ["84468.14", "0"], ["84468.18", "0.017796"], ["84469.3", "0.286987"], ["84474.42", "0.301802"], ["84482.26", "0"], ["84482.27", "0.089922"], ["84482.36", "0.04"], ["84482.37", "0.04"], ["84484.23", "0.35534"], ["84484.77", "0"], ["84485.63", "0"], ["84485.91", "0"], ["84485.99", "0"], ["84486.03", "0"], ["84486.12", "0"], ["84486.65", "0"], ["84487.01", "0"]], "u": 7510859, "seq": 66889473362}, "cts": 1742142267803, "record_time": 1742142266.908801}
{"topic": "orderbook.200.BTCUSDT", "ts": 1742142268009, "type": "delta", "data": {"s": "BTCUSDT", "b": [["84437.26", "0.021972"], ["84436.43", "0.011843"], ["84435.42", "0.000959"], ["84432.96", "0.0001"], ["84432.79", "0"], ["84432.78", "0"], ["84432.38", "0.071068"], ["84427.58", "0"], ["84427.57", "0"], ["84427.56", "0"], ["84427.02", "0.029762"], ["84425.87", "0.000296"], ["84425.86", "0.077982"], ["84425.84", "0"], ["84425.8", "0"], ["84425.5", "0"], ["84424.9", "0"], ["84424.1", "0"], ["84422.72", "0"], ["84422.7", "0.266415"], ["84422.6", "0"], ["84422.1", "0"], ["84421.7", "0"], ["84421.2", "0"], ["84421.06", "0"], ["84421.02", "0"], ["84420.5", "0"], ["84420.49", "0"], ["84419.66", "0"], ["84419.2", "0"], ["84419", "0.04"], ["84418.98", "0.02"], ["84418.7", "0"], ["84418.68", "0"], ["84417.39", "0"], ["84415.69", "0"], ["84414.99", "0.02"], ["84413.29", "0.02"], ["84412.88", "0"], ["84412.55", "0"], ["84409.2", "0"], ["84407.4", "0"], ["84404.41", "0"], ["84404.08", "0.071092"], ["84403.18", "0"], ["84400.57", "0.071095"], ["84399.15", "0"], ["84398.19", "0"], ["84395.18", "0.399172"], ["84394.96", "0.0013"], ["84386.9", "0"], ["84386.37", "0.001467"], ["84386.27", "0.005503"], ["84386.2", "0.000252"], ["84386.04", "0.089922"], ["84385.3", "0.003417"], ["84384.71", "0.001333"], ["84384.67", "0.000613"], ["84384.59", "0.0002"], ["84384.48", "0.000234"], ["84384.44", "0.023689"], ["84383.96", "0.000234"], ["84383.22", "0.006075"], ["84383.14", "0.0025"], ["84382.73", "0.035534"], ["84382.39", "0.059948"], ["84382.38", "0.015"], ["84382.05", "0.0002"], ["84381.73", "0.001467"], ["84381.62", "0.023689"], ["84381.6", "0.015"], ["84381.56", "0.000252"]], "a": [["84437.27", "0.117779"], ["84437.33", "0.071064"], ["84437.49", "0"], ["84441.48", "0"], ["84444.27", "0.0003"], ["84450.95", "0.043362"], ["84451.01", "0"], ["84451.53", "0.000295"], ["84451.54", "0"], ["84451.55", "0"], ["84452.36", "0"], ["84452.37", "0.000296"], ["84452.69", "0"], ["84452.89", "0"], ["84453.68", "0.059948"], ["84454.89", "0"], ["84459.31", "0.089922"], ["84459.47", "0"], ["84460.83", "0"], ["84463.09", "0.188733"], ["84463.41", "0"], ["84464.63", "0"], ["84465.77", "0"], ["84466.48", "0"], ["84466.91", "0.118431"], ["84467.94", "0"], ["84469.3", "0"], ["84469.99", "0"], ["84470.7", "0.0002"], ["84472.52", "0.118431"], ["84474.42", "0"], ["84478.11", "0"], ["84480.12", "0.355352"], ["84482.27", "0.091122"], ["84484.23", "0"], ["84485.63", "0.322693"], ["84485.91", "0.0002"], ["84485.99", "0.000612"], ["84486.03", "0.001333"], ["84486.12", "0.000235"], ["84486.65", "0.000235"], ["84487.01", "0.0045"], ["84487.05", "0.0045"], ["84487.2", "0.003"], ["84487.26", "0.0045"], ["84487.33", "0.0045"]], "u": 7510860, "seq": 66889474122}, "cts": 1742142268008, "record_time": 1742142267.108899}
{"topic": "orderbook.200.BTCUSDT", "ts": 1742142268210, "type": "delta", "data": {"s": "BTCUSDT", "b": [["84425.86", "0.040782"], ["84422.71", "0.028411"], ["84422.7", "0"], ["84419.56", "0.112104"], ["84419.52", "0.120127"], ["84418.98", "0"], ["84418.77", "0.078336"], ["84417.65", "0.113766"], ["84417.6", "0.04"], ["84417.3", "0.04"], ["84416.74", "0"], ["84416.38", "0.02"], ["84416.3", "0.052"], ["84415.05", "0.118431"], ["84415.04", "0"], ["84414.34", "0.02"], ["84413.8", "0.04"], ["84412.05", "0.236862"], ["84411.05", "0.179592"], ["84410.88", "0.167893"], ["84407.7", "0.177878"], ["84402.58", "1.812812"], ["84402.4", "0.297451"], ["84396.69", "0.289824"], ["84384.44", "0"], ["84383.96", "0"], ["84383.22", "0"], ["84383.14", "0"], ["84382.73", "0"], ["84382.39", "0"], ["84382.38", "0"], ["84382.05", "0"], ["84381.73", "0"], ["84381.62", "0"], ["84381.6", "0"], ["84381.56", "0"]], "a": [["84437.32", "0.033265"], ["84441.48", "0.002257"], ["84450.05", "0.198142"], ["84450.06", "0.000295"], ["84450.08", "0.000296"], ["84450.69", "0.106684"], ["84450.86", "0.107374"], ["84450.95", "0"], ["84451.53", "0"], ["84452.37", "0"], ["84454.16", "0.075941"], ["84457.46", "0.169135"], ["84459.33", "0.171692"], ["84461.91", "0.167815"], ["84462.26", "0.236862"], ["84462.7", "0.288862"], ["84465.71", "0.006009"], ["84465.76", "0.142526"], ["84465.77", "0.236862"], ["84465.93", "0.30148"], ["84466.48", "0.236862"], ["84467.8", "0.264558"], ["84469.99", "0.236862"], ["84471.14", "0"], ["84472.92", "0.264536"], ["84480.11", "0.355349"], ["84480.12", "0"], ["84484.78", "0"], ["84484.79", "0"], ["84485.02", "0"], ["84485.45", "0"], ["84485.63", "0"], ["84485.91", "0"], ["84485.99", "0"], ["84486.03", "0"], ["84486.12", "0"], ["84486.65", "0"], ["84487.01", "0"], ["84487.05", "0"], ["84487.2", "0"], ["84487.26", "0"], ["84487.33", "0"]], "u": 7510861, "seq": 66889474326}, "cts": 1742142268206, "record_time": 1742142267.308808}
{"topic": "orderbook.200.BTCUSDT", "ts": 1742142268409, "type": "delta", "data": {"s": "BTCUSDT", "b": [["84436.43", "0"], ["84434.52", "0"], ["84432.96", "0"], ["84432.38", "0"], ["84431.15", "0.032235"], ["84431.14", "0"], ["84430.11", "0"], ["84427.32", "0"], ["84427.03", "0.000296"], ["84427.02", "0.031814"], ["84426.11", "0"], ["84425.91", "0"], ["84425.87", "0"], ["84425.83", "0"], ["84425.48", "0"], ["84424.39", "0"], ["84424.19", "0"], ["84424.17", "0.071075"], ["84422.74", "0.003"], ["84422.68", "0"], ["84422.54", "0.003"], ["84419.57", "0.000296"], ["84419.56", "0"], ["84419.52", "0"], ["84419.3", "0.044"], ["84418.77", "0.201332"], ["84418.52", "0"], ["84418.32", "0"], ["84418.12", "0"], ["84417.65", "0"], ["84417.4", "0.111984"], ["84417.36", "0.106413"], ["84417.32", "0.008924"], ["84416.38", "0"], ["84416.27", "0.10736"], ["84415.5", "0.04"], ["84415.05", "0"], ["84414.99", "0"], ["84414.5", "0.04"], ["84414.34", "0"], ["84414.23", "0"], ["84414.05", "0.107766"], ["84413.79", "0"], ["84413.62", "0"], ["84413.29", "0"], ["84412.5", "0.040089"], ["84412.2", "0.04"], ["84412.05", "0"], ["84411.91", "0.162"], ["84411.05", "0"], ["84410.88", "0"], ["84409.61", "0"], ["84409.49", "0.178105"], ["84409.13", "0"], ["84408.89", "0.171517"], ["84407.83", "0.236862"], ["84407.7", "0"], ["84407.4", "0.236862"], ["84405.58", "0.169418"], ["84405.54", "0.162077"], ["84405.5", "0.013396"], ["84404.08", "0"], ["84403.61", "0.236862"], ["84403.18", "0.236862"], ["84402.58", "1.52835"], ["84402.4", "0"], ["84401.02", "0.292"], ["84400.57", "0"], ["84400.42", "0.300169"], ["84398.38", "0"], ["84397.83", "0"], ["84397.82", "0"], ["84397.11", "0.287132"], ["84396.69", "0"], ["84395.12", "0.071099"], ["84394.83", "0.212"], ["84394.82", "0.049549"], ["84394.53", "0.292633"], ["84394.45", "0"], ["84394.44", "0"], ["84393.58", "0.024192"], ["84391.95", "0.04"], ["84391.94", "0.039642"], ["84391.5", "0.071102"], ["84388.1", "0"], ["84387", "0.24702"], ["84384.44", "0.023689"], ["84383.96", "0.000234"], ["84383.22", "0.006075"], ["84383.14", "0.0025"], ["84382.39", "0.059948"], ["84382.38", "0.015"], ["84382.05", "0.0002"], ["84381.73", "0.001467"], ["84381.62", "0.023689"], ["84381.6", "0.015"], ["84381.56", "0.000252"]], "a": [["84437.27", "0.121179"], ["84438.1", "0.016842"], ["84440.56", "0.033644"], ["84440.57", "0.089922"], ["84441.48", "0.011842"], ["84445.39", "0.00893"], ["84446.98", "0"], ["84447.83", "0.05801"], ["84447.84", "0.089922"], ["84447.9", "0.106243"], ["84448.7", "0.11453"], ["84448.88", "0.00135"], ["84449.31", "0.118451"], ["84449.43", "0.041772"], ["84450.04", "0.000295"], ["84450.05", "0"], ["84450.06", "0"], ["84450.47", "0.120371"], ["84450.69", "0"], ["84450.86", "0"], ["84452.37", "0.024321"], ["84454.43", "0"], ["84454.74", "0.0008"], ["84456.08", "0.168891"], ["84457.17", "0.167052"], ["84457.46", "0"], ["84458.06", "0.013396"], ["84458.48", "0.236862"], ["84458.78", "0.071046"], ["84458.94", "0.179017"], ["84459.33", "0"], ["84459.76", "0.162866"], ["84460.53", "0"], ["84461.59", "0.118431"], ["84461.91", "0"], ["84464.55", "0.289944"], ["84465.65", "0.290984"], ["84465.71", "0.005862"], ["84465.93", "0"], ["84466.92", "0"], ["84467.1", "0.016231"], ["84467.41", "0.291143"], ["84467.8", "0"], ["84470.48", "0"], ["84470.77", "0.264249"], ["84472.09", "0"], ["84472.92", "0"], ["84475.43", "0"], ["84479.05", "0.355369"], ["84479.13", "0.177647"], ["84480.11", "0"], ["84482.36", "0"], ["84482.37", "0"], ["84482.38", "0"], ["84482.93", "0"], ["84483.14", "0"], ["84483.37", "0"], ["84483.66", "0"], ["84483.72", "0"], ["84483.89", "0"], ["84484.24", "0"]], "u": 7510862, "seq": 66889474906}, "cts": 1742142268407, "record_time": 1742142267.508087}
{"topic": "orderbook.200.BTCUSDT", "ts": 1742142268610, "type": "delta", "data": {"s": "BTCUSDT", "b": [["84437.26", "0.019972"], ["84430.52", "0.011844"], ["84428.34", "0.071071"], ["84427.03", "0"], ["84427.02", "0"], ["84425.86", "0"], ["84424.17", "0"], ["84419.31", "0.000296"], ["84418.77", "0.078336"], ["84417.4", "0"], ["84417.36", "0"], ["84416.61", "0.113006"], ["84416.27", "0"], ["84414.44", "0.341713"], ["84414.05", "0.000252"], ["84413.8", "0.160255"], ["84413.73", "0"], ["84413.38", "0.02"], ["84411.06", "0.118431"], ["84409.83", "0.161371"], ["84409.49", "0"], ["84408.89", "0"], ["84405.58", "0"], ["84405.54", "0"], ["84405.39", "0.169189"], ["84405.33", "0.167409"], ["84401.36", "0.294555"], ["84401.03", "0.22499"], ["84401.02", "0"], ["84400.85", "0.071095"], ["84400.42", "0"], ["84397.11", "0"], ["84396.86", "0.267367"], ["84394.83", "0.162"], ["84394.82", "0"], ["84394.53", "0"], ["84394.23", "0.05"], ["84394.22", "0.04955"], ["84391.95", "0"], ["84391.94", "0"], ["84391.5", "0"], ["84391.35", "0.04"], ["84391.34", "0.039643"], ["84381.01", "0.118432"], ["84380.49", "0.001333"], ["84380.45", "0.000611"], ["84379.84", "0.000234"]], "a": [["84437.27", "0.123332"], ["84447.69", "0.055962"], ["84447.74", "0.105981"], ["84447.83", "0"], ["84447.9", "0.0002"], ["84448.55", "0.107697"], ["84448.69", "0.017575"], ["84448.7", "0"], ["84449.31", "0"], ["84449.43", "0"], ["84449.64", "0.118438"], ["84450.22", "0.113053"], ["84450.47", "0"], ["84454.16", "0.114921"], ["84454.26", "0.236862"], ["84456.08", "0"], ["84456.42", "0.163617"], ["84457.02", "0.167023"], ["84457.17", "0"], ["84458.69", "0.164306"], ["84458.94", "0"], ["84459.6", "0.171599"], ["84459.76", "0"], ["84462.7", "0.052"], ["84464.55", "0"], ["84464.89", "0.296209"], ["84465.49", "0.290096"], ["84465.65", "0"], ["84467.41", "0"], ["84469.99", "0"], ["84470.61", "0.271395"], ["84470.77", "0"], ["84479.05", "0"], ["84482.26", "0.355354"], ["84482.36", "0.04"]], "u": 7510863, "seq": 66889475269}, "cts": 1742142268605, "record_time": 1742142267.708795}
{"topic": "orderbook.200.BTCUSDT", "ts": 1742142268810, "type": "delta", "data": {"s": "BTCUSDT", "b": [["84433.05", "0.005326"], ["84428.35", "0.031849"], ["84426.92", "0.031112"], ["84418.01", "0.118923"], ["84416.98", "0.127168"], ["84416.61", "0.001491"], ["84414.78", "0.02"], ["84414.5", "0.151528"], ["84414.44", "0.212494"], ["84413.8", "0.04"], ["84413.39", "0.02"], ["84413.38", "0"], ["84410.21", "0.176136"], ["84409.83", "0"], ["84406.15", "0.174722"], ["84406.03", "0.982124"], ["84405.39", "0"], ["84405.33", "0"], ["84404.69", "0.008935"], ["84401.74", "0.274243"], ["84401.36", "0"], ["84401.03", "0"], ["84397.56", "0.299345"], ["84396.86", "0"], ["84395.14", "0.291526"], ["84394.33", "0.05"], ["84394.32", "0.04955"], ["84394.23", "0"], ["84394.22", "0"], ["84382.4", "0.355347"], ["84381.6", "0"], ["84381.56", "0"], ["84381.01", "0"], ["84380.49", "0"], ["84380.45", "0"], ["84379.84", "0"]], "a": [["84447.69", "0.02762"], ["84447.74", "0"], ["84448.46", "0.155605"], ["84448.55", "0"], ["84448.69", "0"], ["84449.64", "0"], ["84450.22", "0"], ["84456.42", "0.000612"], ["84456.79", "0.164179"], ["84457.02", "0"], ["84458.69", "0"], ["84459.4", "0.163685"], ["84459.6", "0"], ["84460.36", "0.17263"], ["84464.89", "0"], ["84465.27", "0.294107"], ["84465.49", "0"], ["84467.87", "0.277851"], ["84470.61", "0"], ["84471.37", "0.28631"], ["84475.36", "0.177647"], ["84482.16", "0.075533"], ["84482.17", "0.04"], ["84482.26", "0"], ["84482.36", "0"], ["84482.38", "0.015"], ["84482.93", "0.029772"], ["84483.14", "0.0025"], ["84483.37", "0.0002"]], "u": 7510864, "seq": 66889475484}, "cts": 1742142268806, "record_time": 1742142267.908899}
{"topic": "orderbook.200.BTCUSDT", "ts": 1742142269010, "type": "delta", "data": {"s": "BTCUSDT", "b": [["84437.26", "0.119972"], ["84436.43", "0.005265"], ["84433.05", "0.011843"], ["84431.15", "0"], ["84430.8", "0.02573"], ["84430.79", "0.071069"], ["84428.35", "0"], ["84428.34", "0"], ["84427.03", "0.038595"], ["84426.92", "0"], ["84424.83", "0.059948"], ["84423.87", "0.003"], ["84423.67", "0.003"], ["84422.71", "0.101706"], ["84421.78", "0.009137"], ["84419.49", "0.117404"], ["84418.77", "0.137309"], ["84418.42", "0.111905"], ["84418.01", "0"], ["84417.32", "0"], ["84416.98", "0.010366"], ["84416.31", "0.118431"], ["84415.38", "0.02"], ["84414.78", "0"], ["84414.5", "0.04"], ["84413.99", "0.02"], ["84413.39", "0"], ["84413.34", "0.02"], ["84412.72", "0.177457"], ["84410.21", "0"], ["84409.95", "0.166959"], ["84407.83", "0"], ["84407.4", "0"], ["84406.15", "0"], ["84406.03", "0.816757"], ["84404.25", "0.271389"], ["84403.61", "0"], ["84403.18", "0"], ["84401.74", "0"], ["84401.48", "0.262643"], ["84397.56", "0"], ["84395.14", "0"], ["84394.33", "0"], ["84394.32", "0"], ["84394.23", "0.05"], ["84394.22", "0.04955"], ["84390.95", "0"], ["84386.05", "0.355332"], ["84382.4", "0"]], "a": [["84437.27", "0.107176"], ["84437.32", "0.038318"], ["84438.1", "0.005"], ["84440.02", "0.000327"], ["84440.56", "0"], ["84440.57", "0"], ["84441.48", "0"], ["84447.69", "0"], ["84447.84", "0"], ["84448.46", "0.048923"], ["84450.04", "0"], ["84451.62", "0.000295"], ["84452.53", "0.110282"], ["84453.68", "0"], ["84454.16", "0.179694"], ["84454.26", "0"], ["84454.74", "0"], ["84454.84", "0.114902"], ["84456.79", "0"], ["84457.19", "0.059948"], ["84458.05", "0"], ["84458.48", "0"], ["84458.78", "0"], ["84459.31", "0.257413"], ["84459.4", "0"], ["84460.36", "0"], ["84461.59", "0"], ["84462.26", "0"], ["84462.77", "0"], ["84463.21", "0.059215"], ["84463.31", "0.163216"], ["84464.35", "0"], ["84465.27", "0"], ["84465.75", "0.059948"], ["84465.77", "0"], ["84466.48", "0"], ["84466.51", "0.00951"], ["84466.91", "0"], ["84467.78", "0.278483"], ["84467.87", "0"], ["84469.09", "0.071649"], ["84471.37", "0"], ["84471.78", "0.263011"], ["84472.38", "0"], ["84475.36", "0"], ["84477.84", "0.008441"], ["84478", "0.000042"], ["84479.13", "0"], ["84483.66", "0.000089"], ["84483.72", "0.000253"], ["84483.89", "0.001467"], ["84484.24", "0.430885"], ["84484.78", "0.059948"], ["84484.79", "0.118574"], ["84485.02", "0.00315"], ["84485.45", "0.02464"], ["84485.63", "0.322693"], ["84485.91", "0.0002"], ["84485.99", "0.000612"], ["84486.03", "0.001333"], ["84486.12", "0.000235"], ["84486.65", "0.000235"], ["84487.2", "0.003"], ["84488.37", "0.000253"]], "u": 7510865, "seq": 66889476095}, "cts": 1742142269007, "record_time": 1742142268.108745}
{"topic": "orderbook.200.BTCUSDT", "ts": 1742142269209, "type": "delta", "data": {"s": "BTCUSDT", "b": [["84437.26", "0.019972"], ["84436.43", "0"], ["84431.14", "0.03227"], ["84430.8", "0.031743"], ["84430.79", "0.074069"], ["84424.84", "0.000296"], ["84424.83", "0"], ["84422.76", "0.030789"], ["84422.71", "0.007106"], ["84419.57", "0"], ["84419.49", "0"], ["84418.42", "0"], ["84418.32", "0.114557"], ["84418.28", "0.109671"], ["84417.55", "0.109324"], ["84415.39", "0.119313"], ["84412.72", "0"], ["84410.77", "0.177102"], ["84409.95", "0"], ["84409.81", "0.173234"], ["84409.62", "0"], ["84406.92", "0.159839"], ["84406.46", "0.161123"], ["84404.25", "0"], ["84403.18", "0.236862"], ["84402.3", "0.285768"], ["84401.48", "0"], ["84401.34", "0.286892"], ["84398.45", "0.285448"], ["84395.45", "0.279912"], ["84393.15", "0.041333"], ["84393.14", "0.039641"], ["84391.35", "0"], ["84391.34", "0"], ["84386.73", "0.236862"], ["84386.05", "0"], ["84382.39", "0"], ["84382.38", "0"], ["84382.05", "0"], ["84381.73", "0"], ["84381.62", "0"]], "a": [["84437.27", "0.181389"], ["84441.48", "0.0085"], ["84446.57", "0.02806"], ["84446.58", "0.089922"], ["84448.46", "0.10879"], ["84448.81", "0.107277"], ["84449.62", "0.105981"], ["84450.08", "0"], ["84450.58", "0.119361"], ["84451.82", "0.117678"], ["84452.23", "0.000296"], ["84452.53", "0"], ["84454.16", "0"], ["84454.84", "0"], ["84457.36", "0.177538"], ["84458.09", "0.158945"], ["84459.31", "0.089922"], ["84459.56", "0.0008"], ["84460.29", "0.161188"], ["84460.64", "0.175419"], ["84460.67", "0.163168"], ["84463.31", "0"], ["84465.77", "0.236862"], ["84465.83", "0.297893"], ["84466.48", "0.236862"], ["84466.56", "0.266038"], ["84467.78", "0"], ["84468.76", "0.289112"], ["84469.99", "0.12035"], ["84470.7", "0.237062"], ["84471.68", "0.448665"], ["84471.78", "0"], ["84479.05", "0.355352"], ["84482.05", "0.04"], ["84482.06", "0.04"], ["84482.16", "0.035533"], ["84482.17", "0"], ["84483.89", "0"], ["84484.24", "0"], ["84484.78", "0"], ["84484.79", "0"], ["84485.02", "0"], ["84485.45", "0"], ["84485.63", "0"], ["84485.91", "0"], ["84485.99", "0"], ["84486.03", "0"], ["84486.12", "0"], ["84486.65", "0"], ["84487.2", "0"], ["84488.37", "0"]], "u": 7510866, "seq": 66889476515}, "cts": 1742142269205, "record_time": 1742142268.307758}
{"topic": "orderbook.200.BTCUSDT", "ts": 1742142269410, "type": "delta", "data": {"s": "BTCUSDT", "b": [["84418.77", "0.227931"], ["84416.38", "0.02"], ["84415.38", "0"], ["84414.99", "0.02"], ["84414.84", "0.02"], ["84413.99", "0"], ["84413.39", "0.02"], ["84413.34", "0"], ["84403.18", "0"], ["84398.96", "0.236862"], ["84396.23", "0.05"], ["84396.22", "0.049548"], ["84394.23", "0"], ["84394.22", "0"], ["84386.73", "0"]], "a": [["84437.27", "0.181132"], ["84454.16", "0.073507"], ["84471.68", "0.162"], ["84479.04", "0.355361"], ["84479.05", "0"], ["84479.13", "0.177647"], ["84483.66", "0"], ["84483.72", "0"]], "u": 7510867, "seq": 66889476575}, "cts": 1742142269407, "record_time": 1742142268.508179}
{"topic": "orderbook.200.BTCUSDT", "ts": 1742142269609, "type": "delta", "data": {"s": "BTCUSDT", "b": [["84437.26", "0.121972"], ["84431.14", "0"], ["84430.8", "0"], ["84430.79", "0.003"], ["84422.77", "0.059948"], ["84422.76", "0.063769"], ["84419.77", "0.111733"], ["84418.71", "0.113166"], ["84418.58", "0.02"], ["84418.32", "0"], ["84418.28", "0"], ["84417.85", "0.236917"], ["84417.55", "0"], ["84416.79", "0.02"], ["84416.38", "0"], ["84416.16", "0.236921"], ["84415.39", "0"], ["84415.19", "0.02"], ["84414.99", "0"], ["84414.84", "0"], ["84414.44", "0.232494"], ["84413.39", "0"], ["84411.93", "0.159023"], ["84410.95", "0.236862"], ["84410.77", "0"], ["84409.81", "0"], ["84407.91", "0.164412"], ["84406.92", "0"], ["84406.81", "0.071089"], ["84406.46", "0"], ["84403.46", "0.299998"], ["84403.18", "0.236862"], ["84402.58", "0"], ["84402.3", "0"], ["84401.35", "0.311429"], ["84401.34", "0"], ["84398.45", "0"], ["84396.9", "0.284846"], ["84396.23", "0"], ["84396.22", "0"], ["84396.13", "0.05"], ["84396.12", "0.049548"], ["84395.45", "0"], ["84395.12", "0"], ["84382.39", "0.059948"], ["84382.38", "0.015"], ["84382.05", "0.0002"], ["84381.73", "0.001467"]], "a": [["84437.27", "0.110472"], ["84437.32", "0"], ["84437.33", "0"], ["84439.68", "0.071062"], ["84446.57", "0"], ["84446.58", "0"], ["84448.46", "0.08071"], ["84448.81", "0"], ["84449.62", "0.000089"], ["84450.58", "0"], ["84451.82", "0"], ["84457.36", "0"], ["84457.89", "0.279811"], ["84458.09", "0"], ["84458.52", "0.161282"], ["84460.29", "0"], ["84460.67", "0"], ["84462.13", "0.173188"], ["84465.83", "0"], ["84466.56", "0"], ["84466.99", "0.268079"], ["84468.02", "0.302149"], ["84468.76", "0"], ["84472.53", "0"], ["84473.14", "0.301412"], ["84479.04", "0"], ["84482.04", "0.355353"], ["84483.66", "0.000089"], ["84483.72", "0.000253"], ["84483.89", "0.001467"], ["84484.24", "0.430885"], ["84484.78", "0.059948"], ["84484.79", "0.118574"], ["84485.02", "0.00315"], ["84485.45", "0.02464"], ["84485.63", "0.322693"]], "u": 7510868, "seq": 66889476755}, "cts": 1742142269608, "record_time": 1742142268.708623}
{"topic": "orderbook.200.BTCUSDT", "ts": 1742142269810, "type": "delta", "data": {"s": "BTCUSDT", "b": [["84437.26", "0.192632"], ["84436.9", "0.028878"], ["84436.89", "0.071064"], ["84436.43", "0.011843"], ["84428.67", "0.005"], ["84427.03", "0.126942"], ["84426.49", "0.009351"], ["84425.38", "0.106653"], ["84424.84", "0"], ["84424.34", "0.005"], ["84423.78", "0.2369"], ["84423.68", "0.059318"], ["84422.79", "0.117509"], ["84422.78", "0.118431"], ["84422.76", "0"], ["84422.09", "0.236905"], ["84421.78", "0"], ["84420.86", "0.000296"], ["84420.36", "0.162"], ["84419.77", "0"], ["84419.31", "0"], ["84418.71", "0"], ["84418.6", "0.167619"], ["84418.58", "0"], ["84417.85", "0"], ["84416.79", "0"], ["84416.16", "0"], ["84415.19", "0"], ["84414.87", "0.014033"], ["84414.44", "0.212494"], ["84412.55", "0.071085"], ["84412.05", "0.236862"], ["84411.93", "0"], ["84407.91", "0"], ["84406.73", "0.029766"], ["84406.03", "0.133507"], ["84405.5", "0"], ["84404.06", "1.520167"], ["84403.46", "0"], ["84401.35", "0"], ["84400.85", "0"], ["84398.96", "0"], ["84396.9", "0"], ["84390.95", "0.177647"], ["84387.01", "0.355325"], ["84382.38", "0"], ["84382.05", "0"], ["84381.73", "0"]], "a": [["84437.27", "0.005682"], ["84438.1", "0"], ["84439.68", "0"], ["84441.48", "0"], ["84443.7", "0.021901"], ["84443.71", "0.071058"], ["84444.01", "0"], ["84445.39", "0"], ["84448.46", "0"], ["84448.88", "0"], ["84452.23", "0"], ["84452.37", "0"], ["84454.14", "0.000296"], ["84454.17", "0"], ["84455.27", "0.009381"], ["84457.18", "0.059948"], ["84457.19", "0"], ["84457.89", "0"], ["84458.06", "0"], ["84458.41", "0.11613"], ["84458.52", "0"], ["84458.78", "0.023928"], ["84459.31", "0"], ["84460.76", "0"], ["84462.13", "0"], ["84462.7", "0.288862"], ["84463.21", "0"], ["84464.56", "0"], ["84465.77", "0"], ["84466.48", "0"], ["84466.92", "0.236862"], ["84466.99", "0"], ["84467.94", "0.014072"], ["84468.02", "0"], ["84469.99", "0"], ["84470.69", "0"], ["84470.7", "0.0002"], ["84472.52", "0"], ["84472.76", "1.558167"], ["84473.14", "0"], ["84473.55", "0.071033"], ["84479.06", "0"], ["84479.13", "0"], ["84479.47", "0.118431"], ["84482.04", "0"], ["84482.93", "0"], ["84485.62", "0.355329"], ["84485.91", "0.0002"], ["84485.99", "0.000612"], ["84486.03", "0.001333"], ["84486.12", "0.000235"], ["84486.65", "0.000235"], ["84486.71", "0.015"], ["84488.37", "0.000253"], ["84488.53", "0.001467"], ["84488.86", "0.005922"], ["84489.29", "0.0045"], ["84489.35", "0.0045"], ["84489.49", "0.0045"], ["84489.5", "0.405482"], ["84489.55", "0.0045"], ["84490", "0.002053"], ["84490.21", "0.000612"], ["84490.25", "0.001333"], ["84490.73", "0.000335"]], "u": 7510869, "seq": 66889477135}, "cts": 1742142269806, "record_time": 1742142268.9081}
{"topic": "orderbook.200.BTCUSDT", "ts": 1742142270010, "type": "delta", "data": {"s": "BTCUSDT", "b": [["84432.96", "0.0001"], ["84427.03", "0.186967"], ["84425.47", "0.236895"], ["84425.42", "0.106568"], ["84425.38", "0"], ["84423.35", "0.003"], ["84422.79", "0.18892"], ["84418.77", "0"], ["84418.64", "0.1576"], ["84418.6", "0"], ["84418.58", "0.02"], ["84418.04", "0.02"], ["84416.49", "0.02"], ["84416.39", "0.02"], ["84416.27", "0.236862"], ["84415.84", "0.02"], ["84412.55", "0"], ["84410.17", "0.281709"], ["84403.18", "0"], ["84396.13", "0"], ["84396.12", "0"], ["84395.43", "0.05"], ["84395.42", "0.049549"], ["84394.61", "0.003473"], ["84393.15", "0.001333"], ["84393.14", "0"], ["84392.45", "0.079284"], ["84387.02", "0.355321"], ["84387.01", "0"], ["84385.3", "0"], ["84384.59", "0"], ["84384.48", "0"], ["84384.44", "0"], ["84383.96", "0"], ["84383.22", "0"], ["84383.14", "0"], ["84382.39", "0"]], "a": [["84437.27", "0.105682"], ["84439.43", "0.071062"], ["84442.47", "0.0002"], ["84443.7", "0"], ["84443.71", "0"], ["84444.27", "0"], ["84448.85", "0.000153"], ["84451.62", "0"], ["84454.15", "0.000295"], ["84454.16", "0.024907"], ["84455.53", "0.139511"], ["84457.59", "0.142482"], ["84458.41", "0"], ["84458.45", "0.115558"], ["84463.09", "0.125397"], ["84465.23", "0.166539"], ["84472.75", "0.118431"], ["84473.7", "0.28094"], ["84478", "0.000161"], ["84480.47", "0.0013"], ["84482.05", "0"], ["84482.06", "0"], ["84482.27", "0.089922"], ["84482.56", "0.04"], ["84482.66", "0.04"], ["84484.23", "0.35533"], ["84485.62", "0"], ["84488.58", "0.162"], ["84489.49", "0"], ["84489.5", "0"], ["84489.55", "0"], ["84490", "0"], ["84490.21", "0"], ["84490.25", "0"], ["84490.73", "0"]], "u": 7510870, "seq": 66889477279}, "cts": 1742142270007, "record_time": 1742142269.108685}
{"topic": "orderbook.200.BTCUSDT", "ts": 1742142270210, "type": "delta", "data": {"s": "BTCUSDT", "b": [["84437.26", "0.121972"], ["84436.9", "0"], ["84436.89", "0"], ["84436.43", "0.009106"], ["84434.86", "0.071066"], ["84427.04", "0.000296"], ["84425.42", "0"], ["84422.78", "0"], ["84420.86", "0"], ["84420.55", "0.114073"], ["84418.64", "0"], ["84418.59", "0.208428"], ["84418.04", "0"], ["84417.19", "0.02"], ["84416.64", "0.02"], ["84416.49", "0"], ["84416.39", "0"], ["84415.84", "0.236862"], ["84415.59", "0.02"], ["84414.94", "0.02"], ["84413.77", "0.160293"], ["84413.25", "0.067119"], ["84411.62", "0.236862"], ["84410.81", "0.169352"], ["84410.17", "0"], ["84405.3", "0.271073"], ["84403.06", "0.071093"], ["84392.99", "0.11"], ["84387.02", "0"], ["84386.2", "0"], ["84386.04", "0"], ["84384.71", "0"], ["84384.67", "0"]], "a": [["84437.5", "0.032825"], ["84437.51", "0.071064"], ["84439.43", "0"], ["84441.48", "0.004298"], ["84444.01", "0.011842"], ["84445.32", "0.000153"], ["84448.85", "0"], ["84453.16", "0.108123"], ["84453.45", "0.000296"], ["84453.46", "0.069981"], ["84453.47", "0.000295"], ["84453.58", "0.109652"], ["84454.14", "0"], ["84454.15", "0"], ["84454.16", "0"], ["84454.17", "0.162"], ["84458.45", "0"], ["84460.36", "0.159963"], ["84463.49", "0.071042"], ["84465.02", "0.169028"], ["84465.23", "0"], ["84468.83", "0.287967"], ["84473.55", "0"], ["84473.7", "0"], ["84476.03", "0.263457"], ["84482.26", "0.355345"], ["84482.64", "0.177647"], ["84484.23", "0"], ["84486.65", "0"], ["84486.71", "0"], ["84488.37", "0"], ["84488.53", "0"], ["84488.58", "0"], ["84488.86", "0"], ["84489.29", "0"], ["84489.35", "0"]], "u": 7510871, "seq": 66889477565}, "cts": 1742142270199, "record_time": 1742142269.308972}
{"topic": "orderbook.200.BTCUSDT", "ts": 1742142270410, "type": "delta", "data": {"s": "BTCUSDT", "b": [["84437.17", "0.071064"], ["84434.86", "0"], ["84424.75", "0.112507"], ["84423.87", "0"], ["84423.67", "0"], ["84423.56", "0.003"], ["84423.36", "0.003"], ["84423.35", "0"], ["84422.74", "0"], ["84422.54", "0"], ["84422.1", "0.118431"], ["84420.55", "0"], ["84419.28", "0.02"], ["84418.58", "0"], ["84418.04", "0.02"], ["84417.98", "0.02"], ["84417.97", "0.158862"], ["84417.19", "0"], ["84417.09", "0.02"], ["84416.64", "0"], ["84416.44", "0.02"], ["84415.59", "0"], ["84414.94", "0"], ["84413.77", "0"], ["84410.81", "0"], ["84409.5", "0.282995"], ["84405.3", "0"], ["84387.01", "0.355326"], ["84386.2", "0.000252"], ["84386.04", "0.089922"]], "a": [["84437.27", "0.005682"], ["84437.5", "0"], ["84437.51", "0"], ["84440.25", "0.071061"], ["84440.42", "0.000153"], ["84441.48", "0"], ["84444.01", "0"], ["84445.32", "0"], ["84453.16", "0"], ["84453.22", "0.000295"], ["84453.47", "0"], ["84453.58", "0"], ["84454.17", "0"], ["84457.78", "0.109169"], ["84460.36", "0"], ["84463.49", "0"], ["84464.56", "0.170157"], ["84465.02", "0"], ["84468.83", "0"], ["84471.14", "0.236862"], ["84472.49", "0.071034"], ["84473.03", "0.265744"], ["84476.03", "0"], ["84482.26", "0"], ["84482.64", "0"], ["84486.65", "0.000235"], ["84486.71", "0.015"], ["84487.94", "0.029772"], ["84488.37", "0.000253"], ["84488.53", "0.001467"], ["84488.86", "0.005922"], ["84489.35", "0.009"], ["84489.5", "0.405482"]], "u": 7510872, "seq": 66889477830}, "cts": 1742142270406, "record_time": 1742142269.507705}
{"topic": "orderbook.200.BTCUSDT", "ts": 1742142270610, "type": "delta", "data": {"s": "BTCUSDT", "b": [["84437.26", "0.021972"], ["84437.17", "0"], ["84436.43", "0"], ["84433.05", "0"], ["84431.14", "0.032277"], ["84430.79", "0"], ["84430.52", "0"], ["84428.67", "0"], ["84427.06", "0.000296"], ["84427.05", "0.03175"], ["84427.03", "0.038295"], ["84427.01", "0"], ["84426.81", "0"], ["84426.49", "0"], ["84425.47", "0"], ["84424.75", "0"], ["84423.78", "0"], ["84423.68", "0"], ["84422.79", "0"], ["84422.77", "0"], ["84422.71", "0"], ["84422.1", "0"], ["84422.09", "0"], ["84421.29", "0.009619"], ["84420.4", "0.03126"], ["84420.36", "0"], ["84419.28", "0"], ["84418.59", "0.295092"], ["84418.08", "0.02"], ["84418.04", "0"], ["84417.98", "0"], ["84417.97", "0"], ["84417.09", "0"], ["84416.44", "0"], ["84416.35", "0.118069"], ["84416.31", "0"], ["84414.87", "0"], ["84414.74", "0.02"], ["84410.95", "0"], ["84410.25", "0.014423"], ["84409.58", "0.164071"], ["84409.5", "0"], ["84406.81", "0"], ["84406.73", "0"], ["84406.03", "0.663771"], ["84404.91", "0.174614"], ["84404.65", "0.16387"], ["84403.06", "0"], ["84401.1", "0.269573"], ["84398", "0.071097"], ["84396.18", "0.270929"], ["84395.73", "0.05"], ["84395.72", "0.049548"], ["84395.43", "0"], ["84395.42", "0"], ["84393.9", "0.283753"], ["84392.99", "0"], ["84392.64", "0.071101"], ["84387.01", "0"], ["84384.71", "0.001333"], ["84384.67", "0.000613"], ["84384.59", "0.0002"], ["84384.48", "0.000234"], ["84384.44", "0.023689"], ["84383.96", "0.000234"], ["84383.25", "0.059602"], ["84383.22", "0.006075"], ["84383.14", "0.0025"], ["84382.39", "0.059948"], ["84382.38", "0.015"], ["84382.05", "0.0002"], ["84381.73", "0.001467"], ["84381.62", "0.023689"], ["84381.6", "0.015"], ["84381.56", "0.000252"], ["84381.01", "0.118432"], ["84380.49", "0.001333"]], "a": [["84437.27", "0.176495"], ["84437.76", "0.0052"], ["84438.09", "0.059654"], ["84438.1", "0.082905"], ["84438.58", "0.089922"], ["84440.25", "0"], ["84440.42", "0"], ["84441.48", "0.011842"], ["84442.34", "0.012006"], ["84443.81", "0.023686"], ["84444.01", "0.00899"], ["84447.68", "0.034563"], ["84448.58", "0.074496"], ["84448.59", "0.089922"], ["84449.88", "0.001343"], ["84450.69", "0.009608"], ["84453.44", "0.023093"], ["84454.17", "0.162"], ["84455.27", "0"], ["84456.16", "0.165295"], ["84457.54", "0.071047"], ["84457.78", "0"], ["84458.01", "0.168517"], ["84458.78", "0"], ["84459.12", "0.168017"], ["84461.72", "0.089922"], ["84462.26", "0.236862"], ["84462.69", "0.252343"], ["84463.09", "0"], ["84463.24", "0.071042"], ["84463.36", "0.014413"], ["84464.56", "0"], ["84464.63", "0.289904"], ["84465.7", "0.118431"], ["84466.48", "0.506214"], ["84467.94", "0"], ["84469.09", "0.000612"], ["84470.14", "0.298179"], ["84471.14", "0"], ["84472.49", "0"], ["84472.93", "0.029772"], ["84473.03", "0"], ["84475.52", "0.355367"], ["84484.24", "0"], ["84484.78", "0"], ["84484.79", "0"], ["84485.02", "0"], ["84485.45", "0"], ["84485.63", "0"], ["84485.91", "0"], ["84485.99", "0"], ["84486.03", "0"], ["84486.12", "0"], ["84486.65", "0"], ["84486.71", "0"], ["84487.94", "0"], ["84488.37", "0"], ["84488.53", "0"], ["84488.86", "0"], ["84489.35", "0"], ["84489.5", "0"]], "u": 7510873, "seq": 66889478361}, "cts": 1742142270607, "record_time": 1742142269.708634}
{"topic": "orderbook.200.BTCUSDT", "ts": 1742142270809, "type": "delta", "data": {"s": "BTCUSDT", "b": [["84437.26", "0"], ["84435.42", "0"], ["84433.5", "0"], ["84432.96", "0"], ["84432.7", "0"], ["84432.62", "0"], ["84431.14", "0"], ["84431.13", "0.013476"], ["84428.82", "0"], ["84427.07", "0.031803"], ["84427.06", "0"], ["84427.05", "0"], ["84427.04", "0"], ["84427.03", "0"], ["84426.76", "0.003132"], ["84426.61", "0"], ["84425.06", "0.0005"], ["84424.34", "0"], ["84423.56", "0"], ["84423.36", "0"], ["84421.7", "0.071077"], ["84420.4", "0"], ["84419.31", "0.000296"], ["84419.3", "0"], ["84419", "0"], ["84418.59", "0"], ["84418.08", "0"], ["84417.6", "0"], ["84417.3", "0"], ["84416.99", "0.019287"], ["84416.35", "0"], ["84416.3", "0"], ["84416.27", "0"], ["84416.15", "0"], ["84415.84", "0"], ["84415.5", "0"], ["84414.74", "0"], ["84414.51", "0.000296"], ["84414.5", "0"], ["84414.44", "0.338916"], ["84413.8", "0"], ["84412.5", "0.000089"], ["84412.2", "0"], ["84412.05", "0"], ["84411.91", "0"], ["84411.62", "0"], ["84411.06", "0"], ["84410.74", "0.02"], ["84410.28", "0.02"], ["84410.25", "0"], ["84409.58", "0.001467"], ["84409.34", "0.02"], ["84409.09", "0.02"], ["84409.04", "0.02"], ["84407.83", "0.236862"], ["84405.23", "0.014543"], ["84404.91", "0"], ["84404.65", "0"], ["84401.1", "0"], ["84400.83", "0"], ["84400.19", "0"], ["84398", "0"], ["84396.18", "0"], ["84395.73", "0"], ["84395.72", "0"], ["84394.7", "0.000987"], ["84394.61", "0"], ["84394.08", "0.0711"], ["84393.9", "0"], ["84393.58", "0"], ["84392.64", "0"], ["84392.45", "0"], ["84392.41", "0.05"], ["84392.4", "0.049552"], ["84389.69", "0.039641"], ["84389.5", "0.04"], ["84389.1", "0.071104"], ["84383.25", "0"], ["84380.45", "0.000611"], ["84379.84", "0.000234"], ["84379.52", "0.0002"], ["84379.32", "0.000234"], ["84379.06", "0.023689"], ["84378.7", "0.000089"], ["84378.23", "0.023689"], ["84377.92", "0.013712"], ["84377.09", "0.001467"], ["84376.99", "0.0002"], ["84376.92", "0.000252"], ["84376.36", "0.001"], ["84376.3", "0.0144"], ["84376.27", "0.001333"], ["84376.23", "0.000611"], ["84375.9", "0.001243"], ["84375.74", "0.118432"], ["84375.2", "0.000234"], ["84374.95", "0.005922"], ["84374.68", "0.000234"], ["84374.46", "0.0002"], ["84373.77", "0.019326"], ["84372.72", "0.02369"], ["84372.46", "0.059948"], ["84372.45", "0.001467"], ["84372.28", "0.000252"], ["84372.05", "0.001333"], ["84372.01", "0.000612"], ["84371.93", "0.0002"], ["84370.56", "0.000234"], ["84370.38", "0.351822"], ["84370.3", "0.000089"]], "a": [["84431.14", "0.176603"], ["84431.36", "0.226123"], ["84431.37", "0.359689"], ["84433.5", "0.0004"], ["84433.51", "0.018888"], ["84435.23", "0.0002"], ["84435.61", "0.359689"], ["84437.26", "0.0004"], ["84437.27", "0.006205"], ["84437.75", "0.016558"], ["84438.09", "0"], ["84438.1", "0.011842"], ["84438.58", "0"], ["84439.58", "0.001833"], ["84442.34", "0.042077"], ["84444.01", "0"], ["84444.64", "0.086452"], ["84445.71", "0.009688"], ["84445.72", "0.162"], ["84447.68", "0"], ["84448.58", "0.040047"], ["84448.96", "0.000482"], ["84450.69", "0"], ["84451.99", "0.071051"], ["84456.16", "0"], ["84458.01", "0"], ["84458.38", "0.014533"], ["84459.12", "0"], ["84460.63", "0.118431"], ["84463.24", "0"], ["84463.36", "0"], ["84464.63", "0"], ["84465.77", "0.236862"], ["84466.48", "0.236862"], ["84466.92", "0"], ["84468.41", "0.029772"], ["84468.96", "0.000987"], ["84470.13", "0.355393"], ["84470.14", "0"], ["84472.93", "0"], ["84473.35", "0.473488"], ["84475.09", "0"], ["84475.36", "0.177647"], ["84475.52", "0"], ["84479.48", "0"], ["84480.76", "0.027942"], ["84482.56", "0"], ["84482.66", "0"], ["84482.79", "0.04"], ["84482.8", "0.04"], ["84483.08", "0.11"], ["84483.14", "0"], ["84483.37", "0"], ["84483.66", "0"], ["84483.72", "0"], ["84483.89", "0"]], "u": 7510874, "seq": 66889479667}, "cts": 1742142270808, "record_time": 1742142269.90781}
{"topic": "orderbook.200.BTCUSDT", "ts": 1742142271009, "type": "delta", "data": {"s": "BTCUSDT", "b": [["84431.13", "0.113476"], ["84427.37", "0.000099"], ["84426.93", "0"], ["84426.76", "0.011844"], ["84426.23", "0.015946"], ["84424.39", "0.011844"], ["84421.7", "0"], ["84419.31", "0"], ["84416.99", "0"], ["84414.45", "0.029835"], ["84414.44", "0.126422"], ["84413.98", "0.178379"], ["84413.71", "0.003"], ["84413.51", "0.003"], ["84413.31", "0.003"], ["84413.25", "0"], ["84411", "0.044"], ["84410.74", "0"], ["84410.28", "0"], ["84410.08", "0.02"], ["84409.89", "0.120501"], ["84409.34", "0"], ["84409.1", "0.092903"], ["84409.09", "0"], ["84409.04", "0"], ["84408.9", "0.04"], ["84408.7", "0.02"], ["84408.24", "0.003405"], ["84408.15", "0.118431"], ["84408.14", "0.043692"], ["84407.9", "0.052"], ["84407.5", "0.04"], ["84407.2", "0.04"], ["84405.5", "0.04"], ["84405.24", "0"], ["84403.61", "0.236879"], ["84403.22", "0.139498"], ["84401.69", "0.071094"], ["84401.47", "0.158453"], ["84393.06", "0.277137"], ["84392.79", "0.023893"], ["84392.41", "0"], ["84392.4", "0"], ["84391.42", "0.05"], ["84391.41", "0.049546"], ["84389.69", "0"], ["84389.5", "0"], ["84389.1", "0"], ["84388.5", "0.04"], ["84388.49", "0.039642"], ["84381.02", "0.355364"], ["84377.93", "0.162"], ["84375.2", "0"], ["84374.95", "0"], ["84374.68", "0"], ["84374.46", "0"], ["84373.77", "0"], ["84372.72", "0"], ["84372.46", "0"], ["84372.45", "0"], ["84372.28", "0"], ["84372.05", "0"], ["84372.01", "0"], ["84371.93", "0"], ["84370.56", "0"], ["84370.38", "0"], ["84370.3", "0"]], "a": [["84431.14", "0.35744"], ["84431.36", "0"], ["84431.37", "0"], ["84434.9", "0.000099"], ["84435.35", "0.011843"], ["84435.61", "0"], ["84437.24", "0.003553"], ["84437.27", "0.002652"], ["84441.11", "0.000089"], ["84441.48", "0"], ["84442.34", "0"], ["84443.14", "0.000153"], ["84443.8", "0.042841"], ["84444.64", "0.052896"], ["84445.72", "0"], ["84446.08", "0.119656"], ["84448.96", "0.000234"], ["84449.17", "0.000398"], ["84451.46", "0.019788"], ["84451.99", "0"], ["84452.38", "0"], ["84454.49", "0.251895"], ["84458.48", "0.236879"], ["84461.4", "0.071044"], ["84462.26", "0"], ["84462.91", "0.283371"], ["84465.77", "0"], ["84466.48", "0"], ["84468.41", "0"], ["84470.13", "0"], ["84471.68", "0.191772"], ["84479.46", "0.355367"], ["84480.76", "0"], ["84482.79", "0"], ["84482.8", "0"], ["84482.89", "0.04"], ["84482.9", "0.04"], ["84483.08", "0"], ["84483.14", "0.0025"], ["84483.37", "0.0002"], ["84483.66", "0.000089"], ["84483.72", "0.000253"]], "u": 7510875, "seq": 66889480296}, "cts": 1742142271006, "record_time": 1742142270.107706}
{"topic": "orderbook.200.BTCUSDT", "ts": 1742142271209, "type": "delta", "data": {"s": "BTCUSDT", "b": [["84431.13", "0"], ["84431.09", "0"], ["84430.9", "0"], ["84427.07", "0"], ["84424.91", "0.071074"], ["84421.29", "0"], ["84420.95", "0"], ["84415.59", "0.005"], ["84415.11", "0.00984"], ["84414.45", "0.000296"], ["84414.44", "0.179322"], ["84414.3", "0.04"], ["84414.13", "0.114272"], ["84414.09", "0.116615"], ["84413.98", "0"], ["84413.97", "0"], ["84413.87", "0.003"], ["84413.37", "0.114212"], ["84412.9", "0.04"], ["84411.08", "0.02"], ["84410.96", "0"], ["84410.08", "0"], ["84409.89", "0"], ["84409.8", "0.04"], ["84409.54", "0.02"], ["84409.14", "0.02"], ["84408.7", "0"], ["84408.15", "0"], ["84408.14", "0.023692"], ["84408", "0.02"], ["84407.9", "0.092"], ["84407.83", "0"], ["84407.44", "0.02"], ["84406.64", "0.178856"], ["84405.68", "0.164231"], ["84405.23", "0"], ["84404.69", "0"], ["84404.06", "0"], ["84403.61", "0"], ["84402.93", "0.180036"], ["84402.45", "0.01476"], ["84402.35", "0.166253"], ["84402.19", "0.009002"], ["84401.69", "0"], ["84401.47", "0"], ["84401.06", "0.017796"], ["84397.37", "0.07243"], ["84394.08", "0"], ["84393.06", "0"], ["84392.79", "0"], ["84391.42", "0"], ["84391.41", "0.05"], ["84391.4", "0.049546"], ["84391.23", "0.068216"], ["84390.95", "0"], ["84389", "0"], ["84388.5", "0"], ["84388.49", "0"], ["84388.4", "0.04"], ["84388.39", "0.03964"], ["84381.02", "0"], ["84377.26", "0.035537"], ["84375.75", "0.355377"], ["84375.2", "0.000234"]], "a": [["84430.39", "0.038152"], ["84431.14", "0.267673"], ["84432.8", "0.071068"], ["84433.14", "0.005"], ["84433.5", "0"], ["84433.51", "0"], ["84434.05", "0.089922"], ["84435.28", "0.02132"], ["84435.35", "0"], ["84437.24", "0"], ["84437.26", "0"], ["84437.27", "0.002252"], ["84437.75", "0"], ["84437.87", "0.012256"], ["84437.88", "0.002201"], ["84438.1", "0"], ["84441.67", "0.00984"], ["84442.35", "0"], ["84442.8", "0.089922"], ["84443.14", "0"], ["84443.8", "0.001333"], ["84443.81", "0"], ["84444.43", "0.110378"], ["84444.61", "0.059948"], ["84444.64", "0"], ["84445.23", "0.117256"], ["84445.71", "0"], ["84446.08", "0"], ["84446.19", "0.107978"], ["84447.54", "0.106978"], ["84447.76", "0.036088"], ["84448.58", "0.013203"], ["84448.59", "0"], ["84449.17", "0.00015"], ["84449.88", "0"], ["84452.2", "0.00086"], ["84452.92", "0.17111"], ["84453.21", "0.000296"], ["84453.45", "0"], ["84453.46", "0.158575"], ["84453.64", "0.162908"], ["84454.34", "0.03444"], ["84454.49", "0.079157"], ["84455.73", "0.071048"], ["84456.21", "0.179171"], ["84457.26", "0.068216"], ["84457.54", "0"], ["84458.38", "0"], ["84458.48", "0"], ["84460.62", "0.118431"], ["84460.63", "0"], ["84460.64", "0"], ["84461.34", "0.291161"], ["84462.7", "0.052"], ["84462.91", "0"], ["84465.76", "0"], ["84467.1", "0"], ["84471.67", "0.355377"], ["84472.76", "0"], ["84475.36", "0"], ["84478.27", "0.027942"], ["84479.46", "0"], ["84483.89", "0.001467"]], "u": 7510876, "seq": 66889480880}, "cts": 1742142271207, "record_time": 1742142270.30876}
{"topic": "orderbook.200.BTCUSDT", "ts": 1742142271410, "type": "delta", "data": {"s": "BTCUSDT", "b": [["84430.38", "0"], ["84430.17", "0"], ["84428.15", "0.107651"], ["84427.37", "0"], ["84427.32", "0.002565"], ["84426.91", "0.001333"], ["84426.76", "0"], ["84424.99", "0.071074"], ["84424.91", "0"], ["84421.41", "0.011845"], ["84419.71", "0.029645"], ["84414.44", "0.053947"], ["84414.13", "0"], ["84414.09", "0"], ["84413.37", "0"], ["84412.91", "0.059948"], ["84411.08", "0"], ["84410.58", "0.02"], ["84409.54", "0"], ["84409.26", "0.068216"], ["84409.19", "0.02"], ["84409.14", "0"], ["84409.1", "0.128509"], ["84408", "0"], ["84407.51", "0.118431"], ["84407.5", "0.06"], ["84407.44", "0"], ["84407.4", "0.236888"], ["84407.14", "0.02"], ["84406.64", "0"], ["84406.48", "0"], ["84406.03", "0.300946"], ["84405.68", "0"], ["84405.44", "0.02"], ["84403.4", "0.008441"], ["84403.28", "0"], ["84403.18", "0.236888"], ["84402.93", "0"], ["84402.35", "0"], ["84402.19", "0"], ["84401.11", "1.539892"], ["84398.3", "0.236888"], ["84394.75", "0.28652"], ["84394.7", "0"], ["84394.08", "0.186991"], ["84391.72", "0.000987"], ["84391.41", "0"], ["84391.4", "0"], ["84391.31", "0.05"], ["84391.3", "0.049543"], ["84390.91", "0.071103"], ["84388.39", "0.039637"], ["84377.26", "0"], ["84375.76", "0.355383"], ["84375.75", "0"], ["84375.56", "0.006467"], ["84374.95", "0.005922"]], "a": [["84428.16", "0.158064"], ["84428.36", "0.058353"], ["84430.12", "0.07107"], ["84430.39", "0"], ["84431.14", "0.123441"], ["84431.97", "0.00904"], ["84432.7", "0.0002"], ["84432.8", "0"], ["84434.04", "0.027761"], ["84434.9", "0"], ["84435.02", "0.000235"], ["84435.28", "0"], ["84435.31", "0.00061"], ["84435.35", "0.011843"], ["84435.36", "0.001333"], ["84435.55", "0.000235"], ["84436.6", "0.0005"], ["84437.87", "0"], ["84437.88", "0"], ["84439.58", "0.001333"], ["84444.43", "0"], ["84444.6", "0.067974"], ["84445.06", "0.162"], ["84445.23", "0"], ["84446.19", "0"], ["84447.54", "0"], ["84447.76", "0"], ["84448.02", "0.001581"], ["84448.58", "0"], ["84448.62", "0.068216"], ["84452.2", "0.000612"], ["84452.92", "0"], ["84453.64", "0"], ["84453.82", "0.236888"], ["84455.52", "0.118431"], ["84456.21", "0"], ["84457.26", "0"], ["84457.34", "0.236888"], ["84457.59", "0"], ["84458.04", "0.236888"], ["84461.34", "0"], ["84461.55", "0.236888"], ["84462.69", "0"], ["84464.63", "0.28927"], ["84465.99", "0.000987"], ["84468.96", "0"], ["84470.36", "0.473488"], ["84471.66", "0.355397"], ["84471.67", "0"], ["84473.35", "0"], ["84474.19", "1.60729"], ["84476.91", "0.164722"], ["84479", "0.001344"], ["84479.13", "0.177666"], ["84482.27", "0"], ["84482.29", "0.0045"], ["84482.34", "0.0045"], ["84482.89", "0"], ["84482.9", "0"], ["84483.14", "0"], ["84483.37", "0"], ["84483.66", "0"], ["84483.72", "0"], ["84483.89", "0"]], "u": 7510877, "seq": 66889481562}, "cts": 1742142271408, "record_time": 1742142270.509139}
{"topic": "orderbook.200.BTCUSDT", "ts": 1742142271609, "type": "delta", "data": {"s": "BTCUSDT", "b": [["84427.77", "0.071072"], ["84427.32", "0.011844"], ["84425.06", "0"], ["84424.99", "0"], ["84424.39", "0.011943"], ["84421.42", "0.012577"], ["84419.71", "0.030145"], ["84413.63", "0.110303"], ["84413.6", "0.110979"], ["84412.8", "0.110791"], ["84410.73", "0.107994"], ["84408.54", "0.02"], ["84407.14", "0"], ["84406.94", "0.02"], ["84406.3", "0.174487"], ["84406.03", "0.133507"], ["84405.49", "0.159815"], ["84405.44", "0"], ["84403.33", "0.071092"], ["84402.62", "0.157654"], ["84402.26", "0.175235"], ["84401.12", "0.543553"], ["84398.19", "0.285937"], ["84397.37", "0.362749"], ["84394.75", "0"], ["84394.5", "0.288664"], ["84392.75", "0.023891"], ["84391.71", "0.266266"], ["84390.91", "0"], ["84377.94", "0.355375"], ["84377.09", "0"], ["84376.99", "0"], ["84376.92", "0"], ["84376.36", "0"], ["84376.3", "0"], ["84376.27", "0"], ["84376.23", "0"], ["84375.9", "0"], ["84375.76", "0"], ["84375.74", "0"], ["84375.56", "0"], ["84375.2", "0"], ["84374.95", "0"]], "a": [["84428.16", "0.067685"], ["84428.36", "0.053724"], ["84429.93", "0.07107"], ["84430.12", "0"], ["84431.92", "0.000099"], ["84431.97", "0"], ["84432.37", "0.000399"], ["84434.04", "0"], ["84434.05", "0"], ["84442.79", "0.02762"], ["84442.84", "0.117796"], ["84443.63", "0.107149"], ["84444.44", "0.107871"], ["84444.6", "0"], ["84444.61", "0"], ["84445.63", "0.110657"], ["84448.02", "0.001333"], ["84448.89", "0.002384"], ["84450.94", "0.177295"], ["84451.74", "0.173292"], ["84453.74", "0.16837"], ["84454.2", "0.160279"], ["84455.52", "0"], ["84459.05", "0.263609"], ["84459.86", "0.271232"], ["84461.86", "0.284931"], ["84464.63", "0"], ["84464.75", "0.281497"], ["84471.66", "0"], ["84476.9", "0.355368"], ["84481.74", "0"], ["84481.76", "0"], ["84481.81", "0"], ["84482", "0"], ["84482.16", "0"], ["84482.29", "0"], ["84482.34", "0"], ["84482.38", "0"]], "u": 7510878, "seq": 66889481937}, "cts": 1742142271601, "record_time": 1742142270.71792}
{"topic": "orderbook.200.BTCUSDT", "ts": 1742142271809, "type": "delta", "data": {"s": "BTCUSDT", "b": [["84428.15", "0.109651"], ["84427.77", "0"], ["84427.32", "0"], ["84414.44", "0.104329"], ["84413.63", "0"], ["84413.6", "0"], ["84412.8", "0"], ["84412.02", "0.117461"], ["84412", "0.105777"], ["84410.98", "0.02"], ["84410.73", "0"], ["84410.58", "0"], ["84409.59", "0.02"], ["84409.34", "0.02"], ["84409.33", "0.109014"], ["84409.19", "0"], ["84408.54", "0"], ["84407.9", "0.112"], ["84407.64", "0.02"], ["84407.5", "0.04"], ["84407.4", "0"], ["84406.94", "0"], ["84406.3", "0"], ["84405.49", "0"], ["84405.36", "0.175069"], ["84403.52", "0.9"], ["84403.33", "0"], ["84403.18", "0"], ["84402.62", "0"], ["84402.26", "0"], ["84401.78", "0.00899"], ["84400.66", "0.160751"], ["84398.3", "0.058155"], ["84398.19", "0"], ["84397.37", "0.07243"], ["84397.25", "0.263465"], ["84395.77", "0.275981"], ["84394.5", "0"], ["84394.08", "0"], ["84393.99", "0.0711"], ["84393.1", "0.301242"], ["84391.71", "0"], ["84391.51", "0.05"], ["84391.5", "0.049543"], ["84391.31", "0"], ["84391.3", "0"], ["84390.11", "0.267924"], ["84377.94", "0"], ["84377.22", "0.177666"], ["84377.09", "0.001467"], ["84376.99", "0.0002"], ["84376.92", "0.000252"], ["84376.36", "0.001"], ["84376.3", "0.0144"]], "a": [["84428.16", "0.069952"], ["84432.37", "0.011843"], ["84441.22", "0.093171"], ["84441.24", "0.114612"], ["84442.79", "0"], ["84442.84", "0"], ["84443.5", "0.110981"], ["84443.63", "0"], ["84444.21", "0.086"], ["84444.44", "0"], ["84445.63", "0"], ["84447.98", "0.000859"], ["84448.89", "0.002136"], ["84450", "0.163431"], ["84450.14", "0.172402"], ["84450.93", "0.112212"], ["84450.94", "0"], ["84451.74", "0"], ["84452.34", "0.157805"], ["84452.6", "0.176466"], ["84453.74", "0"], ["84454.2", "0"], ["84457.4", "0.04"], ["84458.11", "0.291704"], ["84459.05", "0"], ["84459.86", "0"], ["84461.86", "0"], ["84463.15", "0.294815"], ["84464.75", "0"], ["84474.18", "0.355374"], ["84476.9", "0"], ["84479", "0"], ["84481.74", "0.023686"], ["84481.76", "0.000612"]], "u": 7510879, "seq": 66889482300}, "cts": 1742142271807, "record_time": 1742142270.907702}
{"topic": "orderbook.200.BTCUSDT", "ts": 1742142272009, "type": "delta", "data": {"s": "BTCUSDT", "b": [["84427.27", "0.071072"], ["84426.05", "0.0004"], ["84421.42", "0"], ["84412.93", "0.11408"], ["84412.9", "0.150467"], ["84412.41", "0.003"], ["84412.25", "0.12054"], ["84412.21", "0.003"], ["84412.02", "0"], ["84412", "0"], ["84411.76", "0"], ["84411.25", "0.162"], ["84410.98", "0"], ["84410.78", "0.02"], ["84409.97", "0.116863"], ["84409.59", "0"], ["84409.39", "0.02"], ["84409.34", "0"], ["84409.33", "0"], ["84408.84", "0.02"], ["84407.9", "0.092"], ["84407.83", "0.236888"], ["84407.7", "0.02"], ["84407.64", "0"], ["84407.14", "0.02"], ["84405.76", "0.176355"], ["84405.36", "0"], ["84404.79", "0.161608"], ["84403.61", "0.236888"], ["84403.18", "0.236888"], ["84401.86", "0.17087"], ["84401.57", "0.173834"], ["84400.66", "0"], ["84398.3", "0"], ["84398.01", "0.018605"], ["84397.64", "0.269482"], ["84397.25", "0"], ["84396.67", "0.276411"], ["84395.77", "0"], ["84394.96", "0"], ["84393.74", "0.268463"], ["84393.1", "0"], ["84391.51", "0"], ["84391.5", "0"], ["84391.02", "0.266621"], ["84390.81", "0.05"], ["84390.8", "0.054113"], ["84390.11", "0"], ["84388.4", "0"], ["84388.39", "0"], ["84388.05", "0.0012"], ["84387.9", "0.04"], ["84387.89", "0.039637"], ["84387", "0"], ["84377.22", "0"], ["84377.09", "0"], ["84376.99", "0"], ["84376.92", "0"], ["84376.36", "0"], ["84376.3", "0"]], "a": [["84428.16", "0.07495"], ["84432.37", "0"], ["84440.06", "0.0001"], ["84440.24", "0.031174"], ["84441.22", "0"], ["84441.24", "0"], ["84442.14", "0.106688"], ["84442.47", "0"], ["84442.93", "0.105542"], ["84443.5", "0"], ["84443.9", "0.120507"], ["84444.21", "0.050134"], ["84444.87", "0.107904"], ["84445.06", "0"], ["84447.98", "0.000611"], ["84448.61", "0.059948"], ["84448.62", "0.068464"], ["84450", "0"], ["84450.14", "0"], ["84450.39", "0.179007"], ["84451.05", "0.163931"], ["84452.34", "0"], ["84452.6", "0"], ["84452.98", "0.167988"], ["84453.5", "0.164237"], ["84454.26", "0.236888"], ["84458.11", "0"], ["84458.48", "0.236888"], ["84458.51", "0.277335"], ["84459.16", "0.29256"], ["84461.55", "0"], ["84461.6", "0"], ["84463.15", "0"], ["84464.05", "0.293839"], ["84474.17", "0.355377"], ["84474.18", "0"], ["84478.06", "0.0013"], ["84480.31", "0.0045"], ["84480.35", "0.0045"], ["84480.47", "0"], ["84480.84", "0"], ["84481.47", "0"], ["84481.74", "0"], ["84481.76", "0"]], "u": 7510880, "seq": 66889482784}, "cts": 1742142272007, "record_time": 1742142271.108176}
{"topic": "orderbook.200.BTCUSDT", "ts": 1742142272209, "type": "delta", "data": {"s": "BTCUSDT", "b": [["84428.15", "0.180311"], ["84427.32", "0.011844"], ["84427.28", "0.050243"], ["84421.42", "0.012727"], ["84419.48", "0.010123"], ["84418.12", "0.040448"], ["84415.11", "0"], ["84414.87", "0.236925"], ["84414.44", "0.207234"], ["84414.08", "0.106697"], ["84413.18", "0.23693"], ["84412.93", "0"], ["84412.92", "0.118431"], ["84412.9", "0.04"], ["84412.25", "0"], ["84411.38", "0.02"], ["84410.78", "0"], ["84409.99", "0.020612"], ["84409.97", "0"], ["84409.44", "0.02"], ["84409.39", "0"], ["84408.84", "0"], ["84408.3", "0.02"], ["84407.74", "0.02"], ["84407.7", "0"], ["84407.4", "0.236888"], ["84407.14", "0"], ["84406.81", "0.015185"], ["84405.97", "0.177112"], ["84405.76", "0.000613"], ["84404.79", "0"], ["84403.14", "0.071093"], ["84402.45", "0"], ["84401.86", "0"], ["84401.57", "0"], ["84397.85", "0.27395"], ["84397.64", "0"], ["84396.67", "0"], ["84393.99", "0"], ["84393.74", "0"], ["84391.02", "0"], ["84390.95", "0.177666"], ["84390.81", "0"], ["84390.8", "0.00457"], ["84390.21", "0.05"], ["84390.2", "0.049544"], ["84387.9", "0"], ["84387.89", "0"], ["84387.3", "0.04"], ["84387.29", "0.039638"], ["84382.4", "0.355338"], ["84378.23", "0"], ["84377.93", "0"], ["84377.92", "0"]], "a": [["84428.16", "0.037325"], ["84428.36", "0"], ["84429.93", "0"], ["84434.84", "0.022104"], ["84434.85", "0.071066"], ["84434.9", "0.001616"], ["84435.35", "0"], ["84440.24", "0"], ["84441.67", "0"], ["84442.14", "0"], ["84442.8", "0"], ["84442.93", "0"], ["84443.78", "0.000295"], ["84443.9", "0"], ["84444.21", "0"], ["84444.87", "0"], ["84445.99", "0.104128"], ["84446.7", "0.000296"], ["84446.95", "0.010139"], ["84448.61", "0.183216"], ["84448.62", "0.068216"], ["84448.89", "0.002384"], ["84448.98", "0.107043"], ["84450.39", "0"], ["84450.93", "0"], ["84451.05", "0"], ["84452.98", "0"], ["84453.21", "0"], ["84453.22", "0"], ["84453.5", "0"], ["84454.26", "0"], ["84454.34", "0.01968"], ["84455.73", "0"], ["84457.09", "0.167798"], ["84458.51", "0"], ["84459.16", "0"], ["84459.39", "0.071045"], ["84459.62", "0.015209"], ["84461.4", "0"], ["84464.05", "0"], ["84465.21", "0.272826"], ["84465.44", "0.07104"], ["84474.17", "0"], ["84475.36", "0.177666"], ["84478.27", "0"], ["84480.51", "0.0045"], ["84480.55", "0.0045"], ["84480.84", "0.0002"], ["84481.47", "0.000235"], ["84481.74", "0.023686"], ["84481.76", "0.000612"], ["84481.81", "0.015404"], ["84482", "0.000235"], ["84482.16", "0.035533"], ["84482.29", "0.0045"], ["84482.34", "0.0045"], ["84482.38", "0.015"]], "u": 7510881, "seq": 66889483266}, "cts": 1742142272208, "record_time": 1742142271.307923}
{"topic": "orderbook.200.BTCUSDT", "ts": 1742142272410, "type": "delta", "data": {"s": "BTCUSDT", "b": [["84428.15", "0.109651"], ["84427.28", "0"], ["84418.12", "0.076325"], ["84414.36", "0.112641"], ["84414.34", "0.119194"], ["84414.08", "0"], ["84413.26", "0.1169"], ["84412.92", "0"], ["84412.43", "0.003"], ["84412.41", "0"], ["84412.38", "0.236932"], ["84412.23", "0.003"], ["84412.21", "0"], ["84411.68", "0.02"], ["84411.38", "0"], ["84410.29", "0.02"], ["84409.99", "0.000612"], ["84409.1", "0.250083"], ["84408.6", "0.02"], ["84408.3", "0"], ["84406.76", "0.179106"], ["84406.23", "0.180509"], ["84405.97", "0"], ["84403", "0.157698"], ["84398.65", "0.277269"], ["84398.11", "0.265724"], ["84397.85", "0"], ["84395.68", "0.298651"], ["84392.45", "0.278637"], ["84390.71", "0.05"], ["84390.7", "0.049543"], ["84390.21", "0"], ["84390.2", "0"], ["84389", "0.000119"], ["84382.4", "0"], ["84380.49", "0"], ["84380.45", "0"], ["84379.84", "0"], ["84379.52", "0"], ["84379.32", "0"], ["84379.06", "0"], ["84378.7", "0"]], "a": [["84430.97", "0.058353"], ["84430.98", "0.071069"], ["84434.84", "0"], ["84434.85", "0"], ["84434.9", "0.011843"], ["84443.57", "0.03472"], ["84443.58", "0.11379"], ["84443.78", "0"], ["84444.37", "0.11845"], ["84444.6", "0.000296"], ["84444.89", "0.036264"], ["84444.9", "0.106344"], ["84445.99", "0"], ["84446.7", "0"], ["84448.6", "0.000295"], ["84448.61", "0.139699"], ["84448.89", "0.002136"], ["84448.98", "0"], ["84451.4", "0.163318"], ["84452.48", "0.167333"], ["84454.94", "0.161816"], ["84457.09", "0"], ["84458.9", "0.064"], ["84459.51", "0.292204"], ["84460.6", "0.274314"], ["84462.7", "0.288888"], ["84463.03", "0.295939"], ["84463.1", "0.0002"], ["84465.21", "0"], ["84465.49", "0.265809"], ["84476.9", "0.355366"], ["84480.31", "0"], ["84480.51", "0"], ["84481.74", "0"], ["84481.76", "0"], ["84481.81", "0"], ["84482", "0"], ["84482.16", "0"], ["84482.29", "0"], ["84482.34", "0"], ["84482.38", "0"]], "u": 7510882, "seq": 66889483625}, "cts": 1742142272403, "record_time": 1742142271.509666}
{"topic": "orderbook.200.BTCUSDT", "ts": 1742142272610, "type": "delta", "data": {"s": "BTCUSDT", "b": [["84418.12", "0.200712"], ["84415.47", "0.117675"], ["84414.44", "0.337624"], ["84414.36", "0"], ["84414.34", "0"], ["84413.26", "0"], ["84409.74", "0.02"], ["84409.44", "0"], ["84408.98", "0.164471"], ["84408.04", "0.02"], ["84407.74", "0"], ["84406.76", "0"], ["84406.23", "0"], ["84403", "0"], ["84400.86", "0.263571"], ["84398.65", "0"], ["84398.11", "0"], ["84395.68", "0"], ["84392.45", "0"], ["84390.71", "0"], ["84390.7", "0"], ["84390.41", "0.05"], ["84390.4", "0.049544"], ["84380.49", "0.001333"], ["84380.45", "0.000611"], ["84379.84", "0.000234"], ["84379.52", "0.0002"], ["84379.32", "0.000234"], ["84379.06", "0.023689"], ["84378.7", "0.000089"]], "a": [["84428.16", "0.037478"], ["84430.97", "0.02355"], ["84431.14", "0.007432"], ["84443.57", "0"], ["84443.58", "0"], ["84444.37", "0"], ["84444.6", "0"], ["84444.89", "0"], ["84444.9", "0"], ["84446.47", "0.000295"], ["84446.71", "0.001388"], ["84446.89", "0.103244"], ["84447.12", "0.114495"], ["84448.6", "0"], ["84448.61", "0.139451"], ["84448.62", "0.068464"], ["84451.4", "0"], ["84452.48", "0"], ["84453.61", "0.165466"], ["84454.94", "0"], ["84459.51", "0"], ["84460.6", "0"], ["84461.72", "0.390646"], ["84463.03", "0"], ["84465.49", "0"], ["84473.05", "0.023689"], ["84476.9", "0"], ["84479.12", "0.355361"], ["84481.74", "0.023686"], ["84481.76", "0.000612"], ["84481.81", "0.015404"], ["84482", "0.000235"], ["84482.16", "0.035533"], ["84482.34", "0.0045"], ["84482.38", "0.015"], ["84482.54", "0.0045"]], "u": 7510883, "seq": 66889483968}, "cts": 1742142272606, "record_time": 1742142271.709081}
{"topic": "orderbook.200.BTCUSDT", "ts": 1742142272810, "type": "delta", "data": {"s": "BTCUSDT", "b": [["84428.15", "0.009651"], ["84427.27", "0"], ["84423.92", "0.071075"], ["84421.42", "0"], ["84418.12", "0.135575"], ["84415.47", "0"], ["84412.38", "0"], ["84412.08", "0.02"], ["84411.68", "0"], ["84411.25", "0"], ["84410.69", "0.02"], ["84410.34", "0.02"], ["84410.29", "0"], ["84409.74", "0"], ["84409", "0.02"], ["84408.98", "0"], ["84408.64", "0.02"], ["84408.6", "0"], ["84408.04", "0"], ["84406.03", "0.575364"], ["84403.14", "0"], ["84400.86", "0"], ["84392.81", "0.071101"], ["84390.41", "0"], ["84390.4", "0"], ["84390.21", "0.05"], ["84390.2", "0.049544"], ["84378.23", "0.023689"], ["84377.92", "0.013712"], ["84377.22", "0.177666"], ["84377.09", "0.001467"], ["84376.99", "0.0002"], ["84376.92", "0.000252"]], "a": [["84428.3", "0.071071"], ["84430.98", "0"], ["84432.37", "0.000605"], ["84445.04", "0.000296"], ["84445.05", "0.148188"], ["84445.06", "0.162"], ["84446.47", "0"], ["84446.89", "0"], ["84447.12", "0"], ["84448.02", "0.001581"], ["84448.6", "0.048308"], ["84448.61", "0.059948"], ["84448.62", "0.068216"], ["84453.45", "0.07105"], ["84453.61", "0"], ["84461.72", "0.089922"], ["84465.44", "0"], ["84476.9", "0.355366"], ["84479.12", "0"], ["84482.54", "0"]], "u": 7510884, "seq": 66889484317}, "cts": 1742142272808, "record_time": 1742142271.908019}
{"topic": "orderbook.200.BTCUSDT", "ts": 1742142273010, "type": "delta", "data": {"s": "BTCUSDT", "b": [["84427.32", "0"], ["84426.23", "0"], ["84426.05", "0"], ["84424.83", "0.028824"], ["84424.39", "0.000099"], ["84423.94", "0.008687"], ["84423.92", "0"], ["84423.61", "0.015947"], ["84421.98", "0.071077"], ["84418.12", "0"], ["84416.98", "0.000234"], ["84415.59", "0"], ["84415.2", "0.000296"], ["84414.87", "0"], ["84414.51", "0"], ["84414.44", "0.07415"], ["84413.76", "0.005"], ["84413.18", "0"], ["84412.91", "0"], ["84412.08", "0"], ["84412.01", "0.003"], ["84410.69", "0"], ["84410.34", "0"], ["84409.26", "0"], ["84409.22", "0.106949"], ["84409", "0"], ["84408.64", "0"], ["84408.03", "0.068216"], ["84407.83", "0"], ["84407.51", "0"], ["84407.4", "0"], ["84407.28", "0.02"], ["84405.5", "0.06"], ["84404.94", "0.02"], ["84403.52", "0"], ["84403.18", "0"], ["84401.78", "0"], ["84401.11", "0"], ["84399.39", "0.236888"], ["84398.32", "0.071097"], ["84397.37", "0.001333"], ["84395.49", "0"], ["84392.99", "0.285985"], ["84392.75", "0"], ["84391.39", "0.023707"], ["84391.23", "0"], ["84390.21", "0"], ["84390.2", "0"], ["84387.3", "0"], ["84387.29", "0"], ["84386.82", "0.05"], ["84386.81", "0.049548"], ["84383.9", "0.04"], ["84383.89", "0.039641"], ["84377.93", "0.162"], ["84377.22", "0"], ["84376.36", "0.001"], ["84376.3", "0.0144"], ["84376.27", "0.001333"], ["84376.23", "0.000611"], ["84375.9", "0.001243"], ["84375.74", "0.118432"], ["84375.2", "0.000234"], ["84374.95", "0.005922"], ["84374.68", "0.000234"], ["84374.46", "0.0002"], ["84374.1", "0.24702"]], "a": [["84428.16", "0.258456"], ["84428.29", "0.023551"], ["84428.99", "0.009121"], ["84430.97", "0"], ["84432.37", "0.011843"], ["84435.43", "0.027047"], ["84435.44", "0.089922"], ["84437.76", "0.0002"], ["84438.31", "0.080129"], ["84442.02", "0.010387"], ["84444.39", "0.000295"], ["84445.05", "0.055869"], ["84446.71", "0.001636"], ["84446.95", "0"], ["84448.02", "0.001333"], ["84448.57", "0.023757"], ["84448.76", "0.019788"], ["84451.46", "0"], ["84453.44", "0"], ["84454.26", "0.236888"], ["84454.68", "0.01558"], ["84455.52", "0.118431"], ["84457.5", "0.052"], ["84459.62", "0"], ["84462.7", "0"], ["84470.35", "0.355386"], ["84472.2", "0.023689"], ["84476.9", "0"], ["84477.55", "0.059283"], ["84480.35", "0"], ["84480.55", "0"], ["84481.74", "0"], ["84481.76", "0"], ["84481.81", "0"], ["84482", "0"], ["84482.16", "0"], ["84482.34", "0"], ["84482.38", "0"]], "u": 7510885, "seq": 66889484881}, "cts": 1742142273007, "record_time": 1742142272.108165}
{"topic": "orderbook.200.BTCUSDT", "ts": 1742142273209, "type": "delta", "data": {"s": "BTCUSDT", "b": [["84428.15", "0.008467"], ["84427.32", "0.001043"], ["84424.83", "0"], ["84424.82", "0"], ["84423.94", "0"], ["84423.61", "0"], ["84421.98", "0"], ["84421.41", "0"], ["84419.48", "0"], ["84417", "0.015949"], ["84415.56", "0.071082"], ["84414.44", "0"], ["84414.31", "0.046326"], ["84413.78", "0"], ["84411.52", "0.010515"], ["84409.52", "0"], ["84409.22", "0"], ["84409.1", "0"], ["84408.24", "0"], ["84408.14", "0"], ["84408.03", "0"], ["84407.48", "0.02"], ["84407.28", "0"], ["84406.81", "0"], ["84406.1", "0.02"], ["84406.03", "0.133507"], ["84405.79", "0.009898"], ["84405.5", "0.04"], ["84404.4", "0.02"], ["84404.16", "0"], ["84403.22", "0"], ["84402.31", "0.0002"], ["84401.13", "0.059948"], ["84401.12", "0"], ["84399.14", "0"], ["84398.86", "0.015773"], ["84398.32", "0"], ["84397.9", "0.000797"], ["84396.28", "0.021033"], ["84395.54", "0.003"], ["84392.99", "0"], ["84391.39", "0"], ["84389", "0"], ["84387.21", "0.05"], ["84387.2", "0.049548"], ["84387.1", "0.071106"], ["84386.82", "0"], ["84386.81", "0"], ["84372.72", "0.02369"], ["84372.52", "0.009651"], ["84372.46", "0.059948"], ["84372.45", "0.001467"], ["84372.28", "0.000252"], ["84372.11", "0.017765"], ["84372.05", "0.001333"], ["84372.01", "0.000612"], ["84371.93", "0.0002"], ["84370.56", "0.000234"]], "a": [["84428.16", "0.285472"], ["84428.3", "0"], ["84428.99", "0.011844"], ["84432.08", "0.089922"], ["84435.43", "0"], ["84435.44", "0"], ["84435.74", "0.003"], ["84437.64", "0.010515"], ["84438.31", "0"], ["84442.02", "0"], ["84442.11", "0.01979"], ["84442.98", "0.02756"], ["84442.99", "0.089922"], ["84444.32", "0.056664"], ["84445.05", "0"], ["84445.79", "0.018408"], ["84446.62", "0.003"], ["84446.71", "0"], ["84446.91", "0.071056"], ["84447.9", "0.000448"], ["84448.13", "0.00951"], ["84448.76", "0"], ["84448.99", "0.079155"], ["84450.31", "0.015773"], ["84452.1", "0.04"], ["84452.4", "0.056"], ["84453.45", "0"], ["84453.7", "0.04"], ["84454.49", "0"], ["84454.68", "0"], ["84455.51", "0.118431"], ["84455.52", "0"], ["84455.8", "0.052"], ["84457.2", "0"], ["84458.8", "0.044"], ["84459.14", "0"], ["84459.2", "0.04"], ["84459.39", "0"], ["84459.56", "0"], ["84460.61", "0.355422"], ["84461", "0"], ["84461.55", "0.236888"], ["84463.23", "0.162"], ["84464.36", "0"], ["84464.75", "1.455621"], ["84466.51", "0"], ["84470.35", "0"], ["84473.9", "0"], ["84474.19", "0"]], "u": 7510886, "seq": 66889485444}, "cts": 1742142273207, "record_time": 1742142272.30922}
{"topic": "orderbook.200.BTCUSDT", "ts": 1742142273409, "type": "delta", "data": {"s": "BTCUSDT", "b": [["84428.15", "0.109651"], ["84427.32", "0"], ["84423.94", "0.009102"], ["84422.7", "0.02882"], ["84421.41", "0.011845"], ["84419.95", "0.071078"], ["84419.72", "0.030034"], ["84417", "0"], ["84415.56", "0"], ["84415.2", "0"], ["84414.32", "0.000296"], ["84413.76", "0"], ["84412.16", "0.005"], ["84411.74", "0.003"], ["84411.42", "0.118135"], ["84411.01", "0.059948"], ["84408.91", "0.0698"], ["84408.61", "0.01595"], ["84407.48", "0"], ["84407.4", "0.236888"], ["84406.77", "0.011361"], ["84406.5", "0.063804"], ["84406.1", "0"], ["84405.9", "0.068216"], ["84404.94", "0"], ["84404.4", "0"], ["84403.62", "0.118431"], ["84403.31", "0.003461"], ["84403.18", "0.236888"], ["84400.06", "0.180363"], ["84395.8", "0.277965"], ["84395.49", "0.008748"], ["84392.81", "0"], ["84392.73", "0.071101"], ["84390.99", "0.023689"], ["84390.79", "0.139482"], ["84389.51", "0.289167"], ["84387.21", "0"], ["84387.2", "0"], ["84386.25", "0.323073"], ["84383.9", "0"], ["84383.89", "0"], ["84383.42", "0.05"], ["84383.41", "0.049552"], ["84382.4", "0.355367"], ["84380.51", "0.04"], ["84380.5", "0.039644"], ["84376.3", "0"], ["84375.9", "0"], ["84375.74", "0"], ["84375.2", "0"], ["84374.95", "0"], ["84374.68", "0"], ["84374.46", "0"], ["84374.1", "0"], ["84372.72", "0"], ["84372.52", "0"], ["84372.46", "0"], ["84372.45", "0"], ["84372.28", "0"], ["84372.11", "0"], ["84372.05", "0"], ["84372.01", "0"], ["84371.93", "0"], ["84370.56", "0"]], "a": [["84428.16", "0.23336"], ["84428.29", "0"], ["84428.99", "0"], ["84432.08", "0"], ["84437.49", "0.02666"], ["84437.5", "0.04"], ["84440.41", "0.14835"], ["84441.3", "0.052"], ["84442.11", "0"], ["84442.98", "0"], ["84446.87", "0.0008"], ["84447.9", "0.0002"], ["84448.99", "0"], ["84449.4", "0.04"], ["84451", "0.052"], ["84452", "0.180424"], ["84452.8", "0.071051"], ["84453.03", "0.004596"], ["84455.51", "0"], ["84455.8", "0"], ["84457.4", "0"], ["84457.5", "0"], ["84457.6", "0"], ["84458.48", "0"], ["84460.61", "0"], ["84461.55", "0"], ["84462.55", "0.295753"], ["84464.1", "0"], ["84464.3", "0"], ["84466.98", "0.013789"], ["84467.72", "0"], ["84471.59", "0.322747"], ["84472.2", "0"], ["84473.05", "0"], ["84476.9", "0.355367"], ["84480.34", "0.0045"], ["84480.38", "0.0045"], ["84480.54", "0.0045"], ["84480.58", "0.0045"], ["84481.74", "0.023686"]], "u": 7510887, "seq": 66889485919}, "cts": 1742142273407, "record_time": 1742142272.50786}
