{"topic": "orderbook.200.BTCUSDT", "ts": 1742458818414, "type": "snapshot", "data": {"s": "BTCUSDT", "b": [["85876.62", "0.171755"], ["85875.97", "0.000333"], ["85875.48", "0.001016"], ["85875.47", "0.000533"], ["85874.08", "0.001466"], ["85873.59", "0.008841"], ["85873.5", "0.000099"], ["85872.65", "0.001333"], ["85871.91", "0.003162"], ["85871.68", "0.000333"], ["85871.57", "0.000261"], ["85871.19", "0.00102"], ["85871.03", "0.000261"], ["85870.59", "0.011683"], ["85870.13", "0.000245"], ["85869.4", "0.032154"], ["85869.39", "0.1045"], ["85869.36", "0.001466"], ["85868.85", "0.005822"], ["85868.35", "0.001333"], ["85868.09", "0.000153"], ["85868.03", "0.005"], ["85867.63", "0.000291"], ["85867.62", "0.003162"], ["85867.6", "0.331371"], ["85867.59", "0.7315"], ["85867.38", "0.000333"], ["85867.21", "0.005409"], ["85866.89", "0.00102"], ["85866.84", "0.000261"], ["85866.3", "0.000261"], ["85866.29", "0.023367"], ["85865.82", "0.003"], ["85864.8", "0.056"], ["85864.64", "0.001466"], ["85864.4", "0.052"], ["85864.29", "0.002453"], ["85864.28", "0.156303"], ["85864.08", "0.005822"], ["85864.06", "0.001333"], ["85863.32", "0.003162"], ["85863.09", "0.000333"], ["85863.06", "0.000088"], ["85863", "0.052"], ["85862.8", "0.048"], ["85862.62", "0.121129"], ["85862.6", "0.00102"], ["85862.29", "0.003849"], ["85862.24", "0.111603"], ["85862.12", "0.000261"], ["85861.97", "0.00459"], ["85861.76", "0.005722"], ["85861.62", "0.035222"], ["85861.58", "0.000261"], ["85861.42", "0.172495"], ["85861.4", "0.0024"], ["85860", "0.000059"], ["85859.93", "0.0372"], ["85859.92", "0.001466"], ["85859.77", "0.001333"], ["85859.3", "0.04"], ["85859.1", "0.048"], ["85859.03", "0.00319"], ["85858.8", "0.052333"], ["85858.43", "0.122709"], ["85858.31", "0.001033"], ["85858.04", "0.03514"], ["85857.87", "0.377003"], ["85857.7", "0.08"], ["85857.69", "0.009885"], ["85857.4", "0.048261"], ["85857.36", "0.122774"], ["85857.11", "0.232945"], ["85857.02", "1"], ["85856.96", "0.109896"], ["85856.86", "0.000261"], ["85856.63", "0.001258"], ["85855.54", "0.058858"], ["85855.52", "0.00018"], ["85855.47", "0.001333"], ["85855.43", "0.204336"], ["85855.42", "0.23295"], ["85855.19", "0.001466"], ["85854.81", "0.001488"], ["85854.74", "0.00319"], ["85854.5", "0.000333"], ["85854.48", "0.000088"], ["85854.46", "0.003"], ["85854.28", "0.017467"], ["85854.01", "0.001033"], ["85853.69", "0.005822"], ["85853.68", "0.232954"], ["85852.78", "0.023216"], ["85852.68", "0.000261"], ["85852.44", "0.17751"], ["85852.34", "0.001258"], ["85852.14", "0.000261"], ["85852.12", "0.185486"], ["85851.92", "0.023287"], ["85851.55", "0.018287"], ["85851.43", "0.181215"], ["85851.18", "0.001333"], ["85850.5", "0.05252"], ["85850.47", "0.001466"], ["85850.45", "0.00319"], ["85850.36", "0.186591"], ["85850.28", "0.560834"], ["85850.27", "0.232892"], ["85850.21", "0.000333"], ["85849.72", "0.001033"], ["85849.23", "0.220154"], ["85849.05", "1.382291"], ["85848.13", "0.01377"], ["85847.95", "0.000261"], ["85847.42", "0.000261"], ["85846.89", "0.001333"], ["85846.84", "0.163022"], ["85846.67", "0.058858"], ["85846.15", "0.00319"], ["85846.1", "0.005823"], ["85845.92", "0.427079"], ["85845.91", "0.171"], ["85845.9", "0.000088"], ["85845.75", "0.001466"], ["85845.7", "0.0006"], ["85845.43", "0.001033"], ["85845.17", "0.005822"], ["85845.12", "0.307355"], ["85844.79", "0.034945"], ["85844.43", "0.291877"], ["85844.18", "0.0015"], ["85843.36", "0.304799"], ["85843.34", "0.30174"], ["85843.23", "0.000261"], ["85842.7", "0.000261"], ["85842.6", "0.001333"], ["85842.43", "0.002883"], ["85842.02", "0.011649"], ["85841.86", "0.00319"], ["85841.63", "0.000333"], ["85841.62", "0.005822"], ["85841.16", "0.023289"], ["85841.14", "0.001034"], ["85841.03", "0.001466"], ["85840.59", "0.017488"], ["85840", "0.000059"], ["85839.34", "0.001237"], ["85838.86", "0.06989"], ["85838.58", "0.232892"], ["85838.51", "0.000261"], ["85838.3", "0.001333"], ["85837.97", "0.000261"], ["85837.61", "0.058858"], ["85837.57", "0.00319"], ["85837.34", "0.000333"], ["85837.32", "0.000088"], ["85837.25", "0.017488"], ["85836.91", "0.02329"], ["85836.85", "0.001034"], ["85836.48", "0.014"], ["85836.31", "0.001466"], ["85835.95", "0.000088"], ["85835.86", "0.02329"], ["85835.82", "0.003476"], ["85835.54", "0.116402"], ["85834.76", "0.02329"], ["85834.28", "0.232892"], ["85834.26", "0.02329"], ["85834.01", "0.001333"], ["85833.9", "0.083738"], ["85833.89", "0.089922"], ["85833.79", "0.000261"], ["85833.56", "0.50713"], ["85833.28", "0.003189"], ["85833.27", "0.171"], ["85833.25", "0.000261"], ["85833.19", "0.069894"], ["85833.04", "0.000333"], ["85833", "0.0021"], ["85832.55", "0.001046"], ["85832.23", "0.030465"], ["85831.59", "0.001466"], ["85829.72", "0.001333"], ["85829.07", "0.000261"], ["85828.99", "0.003189"], ["85828.78", "0.575292"], ["85828.75", "0.000333"], ["85828.74", "0.000088"], ["85828.53", "0.000261"], ["85828.26", "0.001046"], ["85828", "0.005822"], ["85827.72", "0.000354"], ["85827.21", "0.116402"], ["85827.19", "0.012884"], ["85827.18", "0.012884"], ["85827.15", "0.04"], ["85827.14", "0.039645"], ["85827.01", "0.003476"], ["85826.87", "0.001466"], ["85826.6", "0.058858"]], "a": [["85876.63", "0.519193"], ["85877.22", "0.146015"], ["85877.23", "0.262741"], ["85877.48", "0.011644"], ["85879.51", "0.002001"], ["85879.91", "0.000099"], ["85880.46", "0.0004"], ["85880.47", "0.17126"], ["85880.5", "0.00157"], ["85880.86", "0.005803"], ["85881.01", "0.00026"], ["85881.2", "0.011038"], ["85881.23", "0.018799"], ["85881.53", "0.003"], ["85881.73", "0.00401"], ["85882.5", "0.0002"], ["85882.76", "0.043379"], ["85882.77", "0.034735"], ["85883.07", "0.034651"], ["85883.53", "0.001466"], ["85883.66", "0.000354"], ["85883.86", "0.011606"], ["85884.07", "0.001051"], ["85884.15", "0.014683"], ["85884.21", "0.002891"], ["85884.55", "0.003"], ["85884.56", "0.000333"], ["85884.79", "0.00157"], ["85884.95", "0.007846"], ["85885.2", "0.00026"], ["85885.22", "0.005"], ["85885.27", "0.002001"], ["85885.34", "0.002001"], ["85885.53", "0.001333"], ["85885.74", "0.000306"], ["85885.8", "0.01951"], ["85885.86", "0.139735"], ["85886.4", "0.04"], ["85886.7", "0.04"], ["85887", "0.005588"], ["85887.12", "0.114349"], ["85887.16", "0.000199"], ["85887.44", "0.124885"], ["85887.65", "0.023785"], ["85887.8", "0.0036"], ["85888.1", "0.04"], ["85888.16", "0.023211"], ["85888.25", "0.001466"], ["85888.36", "0.001051"], ["85888.4", "0.04"], ["85888.43", "0.023288"], ["85888.85", "0.000333"], ["85889.09", "0.00157"], ["85889.73", "0.000291"], ["85889.82", "0.001333"], ["85889.89", "0.009566"], ["85889.92", "0.00026"], ["85890.1", "0.275262"], ["85890.46", "0.00026"], ["85890.49", "0.02886"], ["85891.12", "0.000111"], ["85891.33", "0.116577"], ["85891.6", "0.04"], ["85891.7", "0.04"], ["85892.28", "0.000081"], ["85892.29", "0.000176"], ["85892.35", "0.058858"], ["85892.36", "0.115133"], ["85892.5", "0.04"], ["85892.6", "0.003779"], ["85892.66", "0.001051"], ["85892.98", "0.001466"], ["85893.15", "0.000333"], ["85893.3", "0.04"], ["85893.37", "0.116402"], ["85893.38", "0.00157"], ["85893.39", "0.171"], ["85893.4", "0.04"], ["85894.12", "0.001333"], ["85894.13", "0.009"], ["85894.51", "0.326595"], ["85894.64", "0.00026"], ["85895.18", "0.00026"], ["85895.63", "0.623318"], ["85896.26", "0.008822"], ["85896.95", "0.001051"], ["85897.24", "0.172651"], ["85897.44", "0.000333"], ["85897.62", "0.171232"], ["85897.68", "0.00157"], ["85897.7", "0.001466"], ["85898.26", "0.069841"], ["85898.33", "0.17746"], ["85898.41", "0.001333"], ["85898.49", "0.00033"], ["85898.56", "0.023289"], ["85898.57", "0.023516"], ["85898.72", "0.736878"], ["85898.73", "1.37473"], ["85898.98", "0.000355"], ["85899.17", "0.017488"], ["85899.36", "0.166737"], ["85899.37", "0.00026"], ["85899.45", "0.001"], ["85899.6", "0.116402"], ["85899.91", "0.00026"], ["85900", "0.004301"], ["85900.3", "0.0006"], ["85900.87", "0.000088"], ["85901.16", "0.058858"], ["85901.18", "0.483185"], ["85901.25", "0.001051"], ["85901.57", "0.003504"], ["85901.74", "0.000333"], ["85901.89", "0.005823"], ["85901.97", "0.00157"], ["85901.98", "0.171"], ["85902.43", "0.001466"], ["85902.52", "0.017488"], ["85902.71", "0.001333"], ["85902.96", "0.014683"], ["85903.01", "0.232892"], ["85903.03", "0.109903"], ["85903.85", "0.436268"], ["85903.86", "0.034941"], ["85904.09", "0.00026"], ["85904.12", "0.232892"], ["85904.18", "0.0015"], ["85904.38", "0.069836"], ["85904.61", "0.002755"], ["85904.62", "0.305706"], ["85904.63", "0.00026"], ["85905.15", "0.089922"], ["85905.33", "0.291727"], ["85905.54", "0.001051"], ["85905.77", "0.000354"], ["85906.03", "0.000333"], ["85906.21", "0.116402"], ["85906.27", "0.00157"], ["85906.34", "0.298282"], ["85906.36", "0.277219"], ["85907", "0.001333"], ["85907.15", "0.001466"], ["85907.31", "0.232892"], ["85907.9", "0.013299"], ["85907.91", "0.00088"], ["85908.64", "0.005822"], ["85908.82", "0.00026"], ["85909", "0.000119"], ["85909.36", "0.00026"], ["85909.45", "0.000088"], ["85909.84", "0.001051"], ["85910.14", "0.163025"], ["85910.33", "0.000333"], ["85910.43", "0.0004"], ["85910.56", "0.00157"], ["85910.57", "0.171"], ["85911.19", "0.058858"], ["85911.3", "0.001333"], ["85911.36", "0.000058"], ["85911.88", "0.001466"], ["85912.13", "0.04"], ["85912.14", "0.04"], ["85912.18", "0.013"], ["85912.19", "0.013"], ["85912.21", "0.00088"], ["85912.6", "0.228489"], ["85912.61", "0.57037"], ["85913.54", "0.00026"], ["85914.08", "0.00026"], ["85914.13", "0.001273"], ["85914.62", "0.000333"], ["85914.64", "0.011644"], ["85914.86", "0.00157"], ["85914.9", "0.116402"], ["85915.59", "0.001333"], ["85915.9", "0.116446"], ["85916.6", "0.001466"], ["85916.97", "0.003244"], ["85918.03", "0.000088"], ["85918.13", "0.000932"], ["85918.17", "0.000539"], ["85918.27", "0.00026"], ["85918.43", "0.001051"], ["85918.81", "0.00026"], ["85918.92", "0.023624"], ["85919.15", "0.00157"], ["85919.16", "0.171"], ["85919.18", "0.00315"], ["85919.56", "1.396656"], ["85919.78", "0.32088"], ["85919.89", "0.304632"], ["85920.12", "0.014683"], ["85920.4", "0.014"], ["85920.44", "0.01728"], ["85920.5", "0.0021"], ["85920.72", "0.011647"], ["85921.2", "0.3"], ["85921.33", "0.001466"], ["85921.77", "0.00018"]], "u": 1380042, "seq": 67411127036}, "cts": 1742458818407, "record_time": 1742458821.361298}
{"topic": "orderbook.200.BTCUSDT", "ts": 1742458818614, "type": "delta", "data": {"s": "BTCUSDT", "b": [["85868.09", "0"], ["85866.9", "0.069867"], ["85864.81", "0.002453"], ["85864.29", "0"], ["85861.41", "0.000153"], ["85857.77", "0.001157"], ["85856.63", "0"], ["85854.81", "0"], ["85853.47", "0.001157"], ["85852.34", "0"], ["85838.58", "0"], ["85834.28", "0"], ["85827.19", "0"], ["85827.18", "0"], ["85827.15", "0"], ["85827.14", "0"], ["85827.09", "0.013"], ["85827.08", "0.012884"], ["85827.05", "0.04"], ["85827.04", "0.039645"], ["85825.43", "0.001333"], ["85825.36", "0.163027"]], "a": [["85912.13", "0"], ["85912.14", "0"], ["85912.18", "0"], ["85912.19", "0"], ["85912.43", "0.04"], ["85912.44", "0.04"], ["85912.48", "0.013"], ["85912.49", "0.013"]], "u": 1380043, "seq": 67411127144}, "cts": 1742458818611, "record_time": 1742458821.363409}
{"topic": "orderbook.200.BTCUSDT", "ts": 1742458818814, "type": "delta", "data": {"s": "BTCUSDT", "b": [["85864.81", "0.002455"], ["85864.4", "0.0528"], ["85857.77", "0"], ["85855.07", "0.001449"], ["85854.84", "0.001484"], ["85854.74", "0.004689"], ["85853.47", "0"], ["85850.54", "0.001484"], ["85849.05", "0"], ["85849.02", "1.377082"], ["85838.58", "0.232892"], ["85834.28", "0.232892"], ["85833", "0"], ["85825.43", "0"], ["85825.36", "0"]], "a": [["85882.3", "0.0002"], ["85882.5", "0"], ["85894.29", "1.379775"], ["85898.73", "0"], ["85920.3", "0.0021"], ["85920.5", "0"]], "u": 1380044, "seq": 67411127287}, "cts": 1742458818807, "record_time": 1742458821.364366}
{"topic": "orderbook.200.BTCUSDT", "ts": 1742458819015, "type": "delta", "data": {"s": "BTCUSDT", "b": [["85873.59", "0.005841"], ["85867.14", "0.069867"], ["85866.9", "0"], ["85864.81", "0"], ["85864.41", "0.002453"], ["85864.28", "0.158251"], ["85862.62", "0"], ["85862.59", "0.120139"], ["85862.24", "0"], ["85862.22", "0.112028"], ["85858.43", "0"], ["85858.41", "0.118154"], ["85857.36", "0"], ["85857.33", "0.109879"], ["85855.96", "0.001331"], ["85855.66", "0.008682"], ["85855.43", "0.205734"], ["85855.07", "0"], ["85854.84", "0"], ["85854.74", "0.00319"], ["85852.44", "0"], ["85852.42", "0.185737"], ["85852.12", "0"], ["85852.09", "0.183645"], ["85851.67", "0.001331"], ["85851.43", "0"], ["85851.41", "0.185267"], ["85851.14", "0.001398"], ["85850.54", "0"], ["85850.36", "0"], ["85850.33", "0.183624"], ["85845.12", "0"], ["85845.09", "0.278912"], ["85844.43", "0"], ["85844.41", "0.311332"], ["85843.36", "0"], ["85843.34", "0"], ["85843.33", "0.271163"], ["85843.32", "0.29208"], ["85827.09", "0"], ["85827.08", "0"], ["85827.05", "0"], ["85827.04", "0"], ["85826.4", "0.0021"], ["85825.69", "0.013"], ["85825.68", "0.012885"]], "a": [["85885.86", "0.140833"], ["85887.09", "0.124551"], ["85887.12", "0"], ["85887.42", "0.118734"], ["85887.44", "0"], ["85890.1", "0.672322"], ["85891.31", "0.121506"], ["85891.33", "0"], ["85892.33", "0.11066"], ["85892.36", "0"], ["85897.22", "0.182445"], ["85897.24", "0"], ["85897.59", "0.187212"], ["85897.62", "0"], ["85898.31", "0.187323"], ["85898.33", "0"], ["85898.72", "0"], ["85899.33", "0.18674"], ["85899.36", "0"], ["85904.59", "0.296457"], ["85904.62", "0"], ["85905.31", "0.284709"], ["85905.33", "0"], ["85906.32", "0.29127"], ["85906.33", "0.283555"], ["85906.34", "0"], ["85906.36", "0"], ["85912.43", "0"], ["85912.44", "0"], ["85912.48", "0"], ["85912.49", "0"], ["85914.43", "0.04"], ["85914.44", "0.04"], ["85914.48", "0.013"], ["85914.49", "0.013"], ["85922.2", "0.116402"]], "u": 1380045, "seq": 67411127528}, "cts": 1742458819005, "record_time": 1742458821.365139}
{"topic": "orderbook.200.BTCUSDT", "ts": 1742458819215, "type": "delta", "data": {"s": "BTCUSDT", "b": [["85876.62", "0.171596"], ["85867.14", "0"], ["85865.26", "0.069868"], ["85862.22", "0"], ["85862.21", "0.117869"], ["85858.41", "0"], ["85858.4", "0.112297"], ["85856.19", "0.001305"], ["85855.96", "0"], ["85855.43", "0.204336"], ["85853.79", "0.001133"], ["85852.42", "0"], ["85852.41", "0.181678"], ["85851.9", "0.001305"], ["85851.67", "0"], ["85851.41", "0"], ["85851.4", "0.187381"], ["85851.14", "0"], ["85844.41", "0"], ["85844.4", "0.294645"], ["85843.32", "0"], ["85843.31", "0.277593"], ["85838.25", "0.321185"], ["85834.88", "0.003"], ["85825.69", "0"], ["85825.68", "0"]], "a": [["85887.41", "0.108825"], ["85887.42", "0"], ["85891.3", "0.11775"], ["85891.31", "0"], ["85897.21", "0.178044"], ["85897.22", "0"], ["85898.3", "0.185503"], ["85898.31", "0"], ["85905.3", "0.301373"], ["85905.31", "0"], ["85906.31", "0.291013"], ["85906.32", "0"], ["85914.33", "0.04"], ["85914.34", "0.04"], ["85914.37", "0.013"], ["85914.38", "0.013"], ["85914.43", "0"], ["85914.44", "0"], ["85914.48", "0"], ["85914.49", "0"], ["85916.97", "0.000244"], ["85917.71", "0.003"], ["85922.2", "0"]], "u": 1380046, "seq": 67411127627}, "cts": 1742458819205, "record_time": 1742458821.365975}
{"topic": "orderbook.200.BTCUSDT", "ts": 1742458819414, "type": "delta", "data": {"s": "BTCUSDT", "b": [["85869.4", "0.000291"], ["85856.44", "0.001278"], ["85856.19", "0"], ["85853.79", "0"], ["85852.15", "0.001278"], ["85851.9", "0"], ["85850.27", "0.267834"], ["85844.79", "0"], ["85825.79", "0.013"], ["85825.78", "0.012885"]], "a": [["85914.37", "0"], ["85914.39", "0.013"], ["85919.23", "0.11"], ["85921.77", "0"]], "u": 1380047, "seq": 67411127677}, "cts": 1742458819410, "record_time": 1742458821.366717}
{"topic": "orderbook.200.BTCUSDT", "ts": 1742458819614, "type": "delta", "data": {"s": "BTCUSDT", "b": [["85876.62", "0.173024"], ["85869.4", "0.033827"], ["85864.28", "0.099297"], ["85862.59", "0"], ["85862.53", "0.117915"], ["85862.21", "0"], ["85862.15", "0.124034"], ["85858.4", "0"], ["85857.33", "0"], ["85857.27", "0.109576"], ["85856.44", "0"], ["85856.15", "0.001309"], ["85855.76", "0.001355"], ["85852.41", "0"], ["85852.35", "0.172223"], ["85852.15", "0"], ["85852.09", "0"], ["85852.03", "0.181141"], ["85851.86", "0.001309"], ["85851.47", "0.001355"], ["85851.4", "0"], ["85850.33", "0"], ["85850.27", "0.409027"], ["85850.04", "0.034942"], ["85845.09", "0"], ["85845.03", "0.297791"], ["85844.4", "0"], ["85843.33", "0"], ["85843.31", "0"], ["85843.25", "0.308548"], ["85826.09", "0.013"], ["85826.08", "0.012885"], ["85826.05", "0.04"], ["85826.04", "0.039646"], ["85825.79", "0"], ["85825.78", "0"]], "a": [["85885.27", "0"], ["85885.34", "0"], ["85885.86", "0.070521"], ["85887.03", "0.121105"], ["85887.09", "0"], ["85887.35", "0.110778"], ["85887.41", "0"], ["85891.3", "0"], ["85892.27", "0.119297"], ["85892.33", "0"], ["85897.15", "0.170195"], ["85897.21", "0"], ["85897.53", "0.180433"], ["85897.59", "0"], ["85898.3", "0"], ["85899.27", "0.166354"], ["85899.33", "0"], ["85899.59", "0.264584"], ["85904.53", "0.30545"], ["85904.59", "0"], ["85905.3", "0"], ["85906.27", "0.2961"], ["85906.31", "0"], ["85906.33", "0"], ["85913.83", "0.04"], ["85913.84", "0.04"], ["85913.88", "0.013"], ["85913.89", "0.013"], ["85914.33", "0"], ["85914.34", "0"], ["85914.38", "0"], ["85914.39", "0"], ["85921.77", "0.00018"], ["85922.2", "0.116402"], ["85922.72", "0.001051"], ["85922.99", "0.00026"], ["85923.21", "0.000333"], ["85923.45", "0.00157"]], "u": 1380048, "seq": 67411127849}, "cts": 1742458819610, "record_time": 1742458821.367517}
{"topic": "orderbook.200.BTCUSDT", "ts": 1742458819814, "type": "delta", "data": {"s": "BTCUSDT", "b": [["85864.28", "0.157435"], ["85862.61", "0.120166"], ["85862.53", "0"], ["85862.24", "0.109281"], ["85862.15", "0"], ["85858.42", "0.11808"], ["85857.35", "0.118095"], ["85857.27", "0"], ["85856.15", "0"], ["85856.07", "0.001319"], ["85855.76", "0"], ["85852.44", "0.181662"], ["85852.35", "0"], ["85852.11", "0.165546"], ["85852.03", "0"], ["85851.86", "0"], ["85851.77", "0.001319"], ["85851.47", "0"], ["85851.42", "0.168437"], ["85850.35", "0.17672"], ["85850.27", "0.232892"], ["85845.92", "0.236766"], ["85845.11", "0.277637"], ["85845.03", "0"], ["85844.42", "0.309863"], ["85843.35", "0.308801"], ["85843.34", "0.290462"], ["85843.25", "0"], ["85826.08", "0"], ["85826.05", "0"], ["85826.04", "0"]], "a": [["85885.86", "0.135386"], ["85887.03", "0"], ["85887.11", "0.116281"], ["85887.35", "0"], ["85887.44", "0.10885"], ["85891.32", "0.11286"], ["85892.27", "0"], ["85892.35", "0.169605"], ["85897.15", "0"], ["85897.24", "0.165244"], ["85897.53", "0"], ["85897.61", "0.177957"], ["85898.32", "0.182395"], ["85899.27", "0"], ["85899.35", "0.163474"], ["85904.53", "0"], ["85904.61", "0.282729"], ["85905.32", "0.273768"], ["85906.27", "0.00157"], ["85906.34", "0.286984"], ["85906.35", "0.289865"], ["85922.19", "0.349334"], ["85922.72", "0"], ["85922.99", "0"], ["85923.21", "0"], ["85923.45", "0"]], "u": 1380049, "seq": 67411127968}, "cts": 1742458819809, "record_time": 1742458821.368347}
{"topic": "orderbook.200.BTCUSDT", "ts": 1742458820014, "type": "delta", "data": {"s": "BTCUSDT", "b": [["85867.61", "0.002457"], ["85867.2", "0.069866"], ["85865.26", "0"], ["85864.41", "0"], ["85860.24", "0.232937"], ["85860.05", "0.232892"], ["85858.52", "0.232941"], ["85857.52", "0.001177"], ["85857.11", "0"], ["85856.11", "0.001314"], ["85856.07", "0"], ["85855.76", "0.232892"], ["85855.42", "0"], ["85853.23", "0.001177"], ["85851.82", "0.001314"], ["85851.77", "0"], ["85838.58", "0"], ["85834.28", "0"], ["85829.98", "0.116446"], ["85826.6", "0"], ["85826.4", "0"], ["85826.09", "0"]], "a": [["85876.63", "0.480723"], ["85913.83", "0"], ["85913.84", "0"], ["85913.88", "0"], ["85913.89", "0"], ["85914.23", "0.04"], ["85914.24", "0.04"], ["85914.28", "0.013"], ["85914.29", "0.013"], ["85919.23", "0"], ["85922.19", "0"], ["85922.72", "0.001051"], ["85922.99", "0.00026"]], "u": 1380050, "seq": 67411128070}, "cts": 1742458820011, "record_time": 1742458821.369124}
{"topic": "orderbook.200.BTCUSDT", "ts": 1742458820215, "type": "delta", "data": {"s": "BTCUSDT", "b": [["85876.62", "0.273024"], ["85869.76", "0.009803"], ["85864.28", "0.220049"], ["85863.66", "0.111838"], ["85863.28", "0.112837"], ["85862.61", "0"], ["85862.24", "0"], ["85859.47", "0.123314"], ["85859.44", "0.017466"], ["85858.42", "0"], ["85858.4", "0.122997"], ["85857.52", "0"], ["85857.35", "0"], ["85856.29", "0.001294"], ["85856.11", "0"], ["85854.28", "0"], ["85853.48", "0.179944"], ["85853.23", "0"], ["85853.16", "0.180373"], ["85852.47", "0.183281"], ["85852.44", "0"], ["85852.11", "0"], ["85852", "0.001294"], ["85851.82", "0"], ["85851.42", "0"], ["85851.4", "0.169176"], ["85850.35", "0"], ["85846.16", "0.28195"], ["85845.47", "0.311399"], ["85845.11", "0"], ["85844.42", "0"], ["85844.4", "0.29755"], ["85844.38", "0.301795"], ["85843.35", "0"], ["85843.34", "0"], ["85826.6", "0.058858"]], "a": [["85876.63", "0.396982"], ["85877.22", "0.094385"], ["85880.47", "0.00026"], ["85885.86", "0.070521"], ["85887.11", "0"], ["85887.44", "0"], ["85888.16", "0.145735"], ["85888.48", "0.110039"], ["85891.32", "0"], ["85892.35", "0.058858"], ["85892.37", "0.113065"], ["85893.4", "0.157011"], ["85897.24", "0"], ["85897.61", "0"], ["85898.28", "0.164358"], ["85898.32", "0"], ["85898.66", "0.18336"], ["85899.35", "0"], ["85899.37", "0.173401"], ["85900.4", "0.182846"], ["85903.01", "0"], ["85904.12", "0"], ["85904.61", "0.002755"], ["85905.32", "0"], ["85905.66", "0.272897"], ["85906.34", "0"], ["85906.35", "0"], ["85906.37", "0.27758"], ["85906.7", "0.232892"], ["85907.38", "0.279781"], ["85907.4", "0.279177"], ["85914.23", "0"], ["85914.24", "0"], ["85914.28", "0"], ["85914.29", "0"], ["85914.33", "0.04"], ["85914.34", "0.04"], ["85914.38", "0.013"], ["85914.39", "0.013"], ["85915.9", "0"], ["85923.21", "0.000333"], ["85923.45", "0.00157"], ["85923.53", "0.00026"]], "u": 1380051, "seq": 67411128289}, "cts": 1742458820209, "record_time": 1742458821.369883}
{"topic": "orderbook.200.BTCUSDT", "ts": 1742458820414, "type": "delta", "data": {"s": "BTCUSDT", "b": [["85876.62", "0.272024"], ["85869.76", "0.011645"], ["85863.66", "0"], ["85863.28", "0"], ["85859.47", "0"], ["85858.4", "0"], ["85857.31", "0.001195"], ["85856.29", "0"], ["85854.82", "0.001487"], ["85854.8", "0.001489"], ["85853.48", "0"], ["85853.16", "0"], ["85853.02", "0.001195"], ["85852.47", "0"], ["85852", "0"], ["85851.4", "0"], ["85846.16", "0"], ["85845.47", "0"], ["85844.4", "0"], ["85844.38", "0"], ["85826.4", "0.0021"], ["85826.39", "0.013"], ["85826.38", "0.012885"], ["85826.35", "0.04"], ["85826.34", "0.039646"], ["85825.95", "0.030526"], ["85825.43", "0.001333"], ["85825.36", "0.163027"], ["85825.25", "0.02329"], ["85824.7", "0.003189"]], "a": [["85876.63", "0.397982"], ["85881.73", "0"], ["85885.86", "0.137616"], ["85888.16", "0.023211"], ["85888.48", "0"], ["85890.09", "0.00401"], ["85892.37", "0"], ["85893.4", "0.04"], ["85898.28", "0"], ["85898.66", "0"], ["85899.37", "0.00026"], ["85900.4", "0"], ["85905.66", "0"], ["85906.37", "0"], ["85907.38", "0"], ["85907.4", "0"], ["85911.6", "0.232892"], ["85914.33", "0"], ["85914.34", "0"], ["85914.38", "0"], ["85914.39", "0"], ["85914.53", "0.04"], ["85914.54", "0.04"], ["85914.58", "0.013"], ["85914.59", "0.013"], ["85924.13", "0.009"], ["85924.18", "0.001333"], ["85925.18", "0.005822"], ["85925.6", "0.004645"], ["85925.85", "0.058858"], ["85925.9", "0.04"], ["85926.05", "0.001466"], ["85926.61", "0.000088"]], "u": 1380052, "seq": 67411128434}, "cts": 1742458820408, "record_time": 1742458821.370864}
{"topic": "orderbook.200.BTCUSDT", "ts": 1742458820614, "type": "delta", "data": {"s": "BTCUSDT", "b": [["85869.76", "0"], ["85866.73", "0.005821"], ["85864.08", "0"], ["85863.64", "0.117457"], ["85863.27", "0.120788"], ["85859.46", "0.115386"], ["85858.38", "0.123411"], ["85857.31", "0"], ["85855.66", "0"], ["85855.53", "0.001385"], ["85855.43", "0"], ["85855.22", "0.001426"], ["85854.82", "0"], ["85854.8", "0"], ["85853.47", "0.176561"], ["85853.14", "0.176966"], ["85853.02", "0"], ["85852.46", "0.168771"], ["85851.38", "0.179774"], ["85851.23", "0.001385"], ["85850.93", "0.001426"], ["85846.14", "0.278544"], ["85845.92", "0.000333"], ["85845.46", "0.288334"], ["85844.38", "0.287296"], ["85844.37", "0.312111"], ["85826.39", "0"], ["85826.38", "0"], ["85826.35", "0"], ["85826.34", "0"], ["85825.95", "0"], ["85825.43", "0"], ["85825.36", "0"], ["85825.25", "0"], ["85824.7", "0"]], "a": [["85885.86", "0.138375"], ["85888.14", "0.121836"], ["85888.47", "0.109247"], ["85892.36", "0.121278"], ["85893.38", "0.11271"], ["85894.51", "0.226617"], ["85898.27", "0.166079"], ["85898.64", "0.172622"], ["85899.36", "0.167188"], ["85900.38", "0.185304"], ["85903.85", "0.166463"], ["85905.64", "0.307858"], ["85906.36", "0.304006"], ["85907.37", "0.298366"], ["85907.38", "0.288446"], ["85923.21", "0"], ["85923.45", "0"], ["85923.53", "0"], ["85924.13", "0"], ["85924.18", "0"], ["85925.18", "0"], ["85925.6", "0"], ["85925.85", "0"], ["85925.9", "0"], ["85926.05", "0"], ["85926.61", "0"]], "u": 1380053, "seq": 67411128577}, "cts": 1742458820604, "record_time": 1742458821.371635}
{"topic": "orderbook.200.BTCUSDT", "ts": 1742458820814, "type": "delta", "data": {"s": "BTCUSDT", "b": [["85867.61", "0"], ["85867.2", "0"], ["85865.32", "0.002457"], ["85865.31", "0.069868"], ["85863.64", "0.117311"], ["85863.27", "0.109022"], ["85860.24", "0"], ["85858.52", "0"], ["85858.38", "0.115143"], ["85858.29", "0.232942"], ["85857.26", "0.001199"], ["85856.57", "0.232947"], ["85855.53", "0"], ["85855.22", "0"], ["85855.04", "0.001453"], ["85853.47", "0.169937"], ["85853.14", "0.1784"], ["85852.97", "0.001199"], ["85851.38", "0.171769"], ["85851.23", "0"], ["85850.93", "0"], ["85850.75", "0.001453"], ["85846.14", "0.31062"], ["85844.38", "0.273112"], ["85844.37", "0.272904"], ["85826.5", "0.013"], ["85826.4", "0"]], "a": [["85885.86", "0.139463"], ["85888.14", "0.110073"], ["85888.47", "0.113941"], ["85893.38", "0.120978"], ["85898.27", "0.181422"], ["85898.64", "0.180622"], ["85900.38", "0.172602"], ["85905.64", "0.289885"], ["85907.37", "0.303288"], ["85907.38", "0.304804"], ["85914.48", "0.013"], ["85914.49", "0.013"], ["85914.58", "0"], ["85914.59", "0"], ["85921.19", "0.349339"], ["85922.99", "0"]], "u": 1380054, "seq": 67411128860}, "cts": 1742458820808, "record_time": 1742458821.37237}
{"topic": "orderbook.200.BTCUSDT", "ts": 1742458821015, "type": "delta", "data": {"s": "BTCUSDT", "b": [["85869.76", "0.001168"], ["85867.61", "0.002456"], ["85867.18", "0.069866"], ["85865.32", "0"], ["85865.31", "0"], ["85860.41", "0.232936"], ["85859.11", "0.591069"], ["85858.39", "0.112752"], ["85858.38", "0"], ["85858.29", "0"], ["85857.87", "0"], ["85855.77", "0.337866"], ["85851.39", "0.184581"], ["85851.38", "0"], ["85844.39", "0.290751"], ["85844.38", "0"], ["85826.6", "0"], ["85826.5", "0"]], "a": [["85893.38", "0.00157"], ["85893.39", "0.28014"], ["85900.38", "0"], ["85900.39", "0.180962"], ["85907.38", "0"], ["85907.39", "0.277504"], ["85921.19", "0"], ["85922.71", "0.11"]], "u": 1380055, "seq": 67411128918}, "cts": 1742458821008, "record_time": 1742458821.504175}
{"topic": "orderbook.200.BTCUSDT", "ts": 1742458821215, "type": "delta", "data": {"s": "BTCUSDT", "b": [["85869.76", "0.008409"], ["85863.65", "0.10917"], ["85863.64", "0"], ["85857.26", "0"], ["85857.05", "0.001218"], ["85855.66", "0.008875"], ["85855.04", "0"], ["85853.15", "0.174951"], ["85853.14", "0"], ["85852.97", "0"], ["85852.76", "0.001218"], ["85850.75", "0"], ["85846.15", "0.283697"], ["85846.14", "0"], ["85834.9", "0.003"], ["85834.88", "0"], ["85826.6", "0.058858"], ["85826.49", "0.012885"]], "a": [["85888.14", "0"], ["85888.15", "0.109136"], ["85898.64", "0"], ["85898.65", "0.174511"], ["85905.64", "0"], ["85905.65", "0.289867"], ["85914.43", "0.04"], ["85914.44", "0.04"], ["85914.53", "0"], ["85914.54", "0"], ["85917.68", "0.003"], ["85917.71", "0"]], "u": 1380056, "seq": 67411128995}, "cts": 1742458821212, "record_time": 1742458821.704293}
{"topic": "orderbook.200.BTCUSDT", "ts": 1742458821414, "type": "delta", "data": {"s": "BTCUSDT", "b": [["85876.62", "0.338214"], ["85869.77", "0.002459"], ["85869.76", "0"], ["85869.07", "0.069865"], ["85867.61", "0"], ["85867.18", "0"], ["85864.41", "0.058858"], ["85863.65", "0"], ["85863.27", "0"], ["85859.46", "0"], ["85859.24", "0.232939"], ["85858.39", "0"], ["85857.52", "0.232944"], ["85857.05", "0"], ["85856.57", "0"], ["85856.46", "0.001276"], ["85853.68", "0"], ["85853.47", "0"], ["85853.15", "0"], ["85852.76", "0"], ["85852.46", "0"], ["85852.17", "0.001276"], ["85851.39", "0"], ["85850.27", "0"], ["85846.85", "0.116402"], ["85846.15", "0.00319"], ["85845.46", "0"], ["85844.39", "0"], ["85844.37", "0"], ["85844.19", "0.069885"], ["85840.92", "0.116402"], ["85833.19", "0"], ["85826.49", "0"], ["85826.4", "0.0021"], ["85826.19", "0.013"], ["85826.18", "0.012885"], ["85826.15", "0.04"], ["85826.14", "0.039646"], ["85825.95", "0.030526"], ["85825.43", "0.001333"], ["85825.36", "0.163027"], ["85825.25", "0.02329"], ["85824.7", "0.003189"], ["85824.46", "0.000333"]], "a": [["85876.63", "0.450023"], ["85879.51", "0"], ["85888.15", "0"], ["85888.47", "0"], ["85892.35", "0"], ["85892.36", "0"], ["85893.39", "0.171"], ["85898.27", "0"], ["85898.65", "0"], ["85899.36", "0"], ["85900.39", "0"], ["85905.15", "0"], ["85905.65", "0"], ["85906.36", "0"], ["85907.37", "0"], ["85907.39", "0"], ["85914.43", "0"], ["85914.44", "0"], ["85914.48", "0"], ["85914.49", "0"], ["85914.73", "0.04"], ["85914.74", "0.04"], ["85914.78", "0.013"], ["85914.79", "0.013"], ["85922.99", "0.00026"], ["85923.21", "0.000333"], ["85923.45", "0.00157"], ["85923.53", "0.00026"], ["85924.13", "0.009"], ["85924.18", "0.001333"], ["85925.18", "0.005822"], ["85925.6", "0.004645"], ["85925.85", "0.058858"], ["85925.9", "0.04"], ["85926.05", "0.001466"], ["85926.61", "0.000088"], ["85927.02", "0.001051"], ["85927.22", "0.0053"]], "u": 1380057, "seq": 67411129161}, "cts": 1742458821411, "record_time": 1742458821.903894}
{"topic": "orderbook.200.BTCUSDT", "ts": 1742458821614, "type": "delta", "data": {"s": "BTCUSDT", "b": [["85869.77", "0.002461"], ["85869.76", "0.011645"], ["85869.4", "0.050595"], ["85869.05", "0.005821"], ["85866.73", "0"], ["85865.4", "0.000153"], ["85863.92", "0.108747"], ["85862.52", "0.232931"], ["85861.41", "0"], ["85860.41", "0"], ["85860.11", "0.119041"], ["85857.7", "0.081162"], ["85856.46", "0"], ["85855.77", "0"], ["85854.12", "0.169554"], ["85853.41", "0.001162"], ["85853.11", "0.169701"], ["85852.85", "0.232892"], ["85852.17", "0"], ["85846.85", "0.144864"], ["85846.11", "0.30387"], ["85845.02", "0.312083"], ["85826.19", "0.012885"], ["85825.95", "0"], ["85825.43", "0"], ["85825.36", "0"], ["85825.25", "0"], ["85824.7", "0"], ["85824.46", "0"]], "a": [["85885.86", "0.135065"], ["85889.12", "0.108969"], ["85893.01", "0.116352"], ["85898.92", "0.171855"], ["85900.01", "0.1844"], ["85901.57", "0"], ["85907.01", "0.294238"], ["85908.02", "0.303971"], ["85925.9", "0"], ["85926.05", "0"], ["85926.61", "0"], ["85927.02", "0"], ["85927.22", "0"]], "u": 1380058, "seq": 67411129288}, "cts": 1742458821606, "record_time": 1742458822.103759}
{"topic": "orderbook.200.BTCUSDT", "ts": 1742458821814, "type": "delta", "data": {"s": "BTCUSDT", "b": [["85876.62", "0.548464"], ["85872.34", "0.011645"], ["85871.72", "0.005821"], ["85870.94", "0.002462"], ["85870.93", "0.040608"], ["85869.77", "0"], ["85869.4", "0.000291"], ["85869.07", "0"], ["85869.05", "0"], ["85863.99", "0.017465"], ["85863.97", "0.122243"], ["85863.92", "0"], ["85860.16", "0.125028"], ["85860.11", "0"], ["85859.44", "0"], ["85857.7", "0.08"], ["85855.07", "0.001448"], ["85854.17", "0.170135"], ["85854.12", "0"], ["85853.41", "0"], ["85853.16", "0.172359"], ["85853.11", "0"], ["85850.78", "0.001448"], ["85846.16", "0.304904"], ["85846.11", "0"], ["85845.07", "0.297997"], ["85845.02", "0"], ["85828.79", "0.349285"], ["85826.2", "0.013"], ["85826.19", "0"], ["85826.18", "0"], ["85826.15", "0"], ["85826.14", "0"]], "a": [["85876.63", "0.412509"], ["85877.22", "0"], ["85877.23", "0.256919"], ["85877.48", "0"], ["85880.43", "0.005821"], ["85880.46", "0"], ["85881.23", "0.001333"], ["85886.87", "0.017465"], ["85889.12", "0"], ["85889.17", "0.109921"], ["85893.01", "0"], ["85893.06", "0.113376"], ["85898.92", "0"], ["85898.97", "0.168128"], ["85900.01", "0"], ["85900.06", "0.164732"], ["85906.7", "0"], ["85907.01", "0"], ["85907.06", "0.28984"], ["85907.31", "0"], ["85908.02", "0"], ["85908.07", "0.272167"], ["85910.14", "0"], ["85911.6", "0"], ["85914.73", "0"], ["85914.74", "0"], ["85914.78", "0"], ["85914.79", "0"], ["85915.03", "0.04"], ["85915.04", "0.04"], ["85915.08", "0.013"], ["85915.09", "0.013"], ["85915.9", "0.232892"], ["85925.9", "0.04"], ["85926.05", "0.001466"], ["85926.61", "0.000088"], ["85927.02", "0.001051"]], "u": 1380059, "seq": 67411129445}, "cts": 1742458821807, "record_time": 1742458822.304359}
{"topic": "orderbook.200.BTCUSDT", "ts": 1742458822015, "type": "delta", "data": {"s": "BTCUSDT", "b": [["85876.62", "0.725285"], ["85875.13", "0.052641"], ["85875.12", "0.06986"], ["85873.88", "0.000153"], ["85873.6", "0.00246"], ["85873.34", "0.089922"], ["85871.72", "0"], ["85870.94", "0"], ["85869.37", "0.017464"], ["85865.4", "0"], ["85864.09", "0.119844"], ["85863.99", "0"], ["85863.97", "0"], ["85863.2", "0.018287"], ["85860.28", "0.199494"], ["85860.16", "0"], ["85855.42", "0.232892"], ["85855.07", "0"], ["85854.29", "0.184371"], ["85854.17", "0"], ["85853.28", "0.175335"], ["85853.16", "0"], ["85852.85", "0"], ["85851.55", "0"], ["85850.78", "0"], ["85850.56", "0.06988"], ["85849.23", "0"], ["85846.86", "0.116402"], ["85846.28", "0.275686"], ["85846.16", "0"], ["85845.19", "0.277141"], ["85845.07", "0"], ["85843.29", "0.030526"], ["85838.86", "0"], ["85829.99", "0.349272"], ["85828.79", "0"], ["85826.2", "0"]], "a": [["85876.63", "0.206211"], ["85877.23", "0.187061"], ["85877.73", "0.069858"], ["85880.43", "0"], ["85880.91", "0.000235"], ["85881.2", "0"], ["85882.76", "0.025905"], ["85882.77", "0"], ["85884.15", "0"], ["85885.66", "0.007035"], ["85885.8", "0"], ["85885.86", "0.106403"], ["85886.87", "0"], ["85887.07", "0.034648"], ["85887.79", "0.005821"], ["85888.43", "0"], ["85889.17", "0"], ["85889.29", "0.118546"], ["85889.89", "0"], ["85890.98", "0.014683"], ["85892.29", "0.01764"], ["85893.06", "0"], ["85893.18", "0.11986"], ["85893.37", "0"], ["85894.28", "0.116402"], ["85897.22", "0.01951"], ["85898.26", "0"], ["85898.57", "0"], ["85898.97", "0"], ["85899.09", "0.180148"], ["85899.58", "0.009442"], ["85900.06", "0"], ["85900.18", "0.166397"], ["85901.72", "0.023285"], ["85906.08", "0.023787"], ["85907.06", "0"], ["85907.18", "0.272862"], ["85907.7", "0.069834"], ["85908.07", "0"], ["85908.19", "0.297348"], ["85915.03", "0"], ["85915.04", "0"], ["85915.08", "0"], ["85915.09", "0"], ["85915.9", "0"], ["85916.63", "0.04"], ["85916.64", "0.04"], ["85916.68", "0.013"], ["85916.69", "0.013"], ["85922.71", "0"], ["85927.22", "0.0053"]], "u": 1380060, "seq": 67411129774}, "cts": 1742458822011, "record_time": 1742458822.504629}
{"topic": "orderbook.200.BTCUSDT", "ts": 1742458822215, "type": "delta", "data": {"s": "BTCUSDT", "b": [["85875.13", "0.023964"], ["85873.6", "0"], ["85873.34", "0"], ["85870.94", "0.002467"], ["85864.47", "0.111816"], ["85864.41", "0"], ["85864.09", "0"], ["85860.66", "0.116777"], ["85860.28", "0.089922"], ["85855.91", "0.220137"], ["85854.67", "0.172792"], ["85854.29", "0"], ["85853.66", "0.167115"], ["85853.28", "0"], ["85849.02", "0"], ["85846.66", "0.279946"], ["85846.28", "0"], ["85845.57", "0.286834"], ["85845.19", "0"], ["85829.99", "0"], ["85828.91", "0.11"], ["85827.3", "0.013"], ["85827.29", "0.012884"], ["85827.25", "0.04"], ["85827.24", "0.039645"], ["85827.22", "0.349288"], ["85827.01", "0"], ["85826.87", "0"], ["85826.6", "0"], ["85826.4", "0"]], "a": [["85876.63", "0.210172"], ["85877.23", "0.020561"], ["85880.91", "0.011644"], ["85889.29", "0"], ["85889.67", "0.113398"], ["85893.18", "0"], ["85893.56", "0.122427"], ["85894.29", "0"], ["85899.09", "0"], ["85899.47", "0.18562"], ["85900.18", "0"], ["85900.56", "0.182849"], ["85903.03", "0"], ["85907.18", "0"], ["85907.56", "0.295577"], ["85908.19", "0"], ["85908.57", "0.306506"], ["85927.32", "0.232892"], ["85927.51", "0.000333"]], "u": 1380061, "seq": 67411129915}, "cts": 1742458822212, "record_time": 1742458822.704195}
{"topic": "orderbook.200.BTCUSDT", "ts": 1742458822414, "type": "delta", "data": {"s": "BTCUSDT", "b": [["85876.62", "0.439524"], ["85875.13", "0"], ["85875.12", "0"], ["85873.88", "0"], ["85872.34", "0"], ["85872", "0.042253"], ["85871.78", "0.000153"], ["85870.94", "0"], ["85870.93", "0"], ["85869.53", "0.005821"], ["85869.37", "0"], ["85867.61", "0.00246"], ["85865.93", "0.069867"], ["85864.47", "0"], ["85864.43", "0.017464"], ["85863.97", "0.112863"], ["85860.66", "0"], ["85860.28", "0"], ["85860.16", "0.108917"], ["85855", "1.336836"], ["85854.67", "0"], ["85854.17", "0.174007"], ["85853.66", "0"], ["85853.16", "0.180921"], ["85850.56", "0"], ["85850.28", "0"], ["85846.86", "0"], ["85846.66", "0"], ["85846.16", "0.287029"], ["85845.57", "0"], ["85845.07", "0.280228"], ["85844.19", "0"], ["85843.29", "0"], ["85841.08", "0.069888"], ["85835.45", "0.069892"], ["85828.91", "0"], ["85827.22", "0"], ["85827.01", "0.003476"], ["85826.87", "0.001466"], ["85826.6", "0.058858"], ["85826.42", "0.030526"], ["85826.4", "0.0021"], ["85825.58", "0.021095"]], "a": [["85876.63", "0.376672"], ["85877.48", "0.011644"], ["85877.72", "0.027248"], ["85880.43", "0.005821"], ["85880.49", "0.007035"], ["85884.19", "0.002001"], ["85885.66", "0"], ["85885.86", "0.106342"], ["85886.87", "0.017465"], ["85887.79", "0"], ["85889.17", "0.117001"], ["85889.67", "0"], ["85890.1", "0.246999"], ["85891.59", "0.058858"], ["85892.29", "0.000176"], ["85893.06", "0.112507"], ["85893.56", "0"], ["85893.83", "0.069845"], ["85898.97", "0.170137"], ["85899.07", "0.069841"], ["85899.47", "0"], ["85900.06", "0.174425"], ["85900.56", "0"], ["85901.43", "1.36713"], ["85901.78", "0.003504"], ["85903.85", "0.076754"], ["85904.38", "0"], ["85906.7", "0.232892"], ["85907.06", "0.305916"], ["85907.31", "0.232892"], ["85907.56", "0"], ["85907.7", "0"], ["85908.07", "0.286229"], ["85908.57", "0"], ["85911.6", "0.232892"], ["85916.58", "0.013"], ["85916.59", "0.013"], ["85916.68", "0"], ["85916.69", "0"], ["85925.18", "0"], ["85925.6", "0"], ["85925.85", "0"], ["85925.9", "0"], ["85926.05", "0"], ["85926.61", "0"], ["85927.02", "0"], ["85927.22", "0"], ["85927.32", "0"], ["85927.51", "0"]], "u": 1380062, "seq": 67411130178}, "cts": 1742458822410, "record_time": 1742458822.904232}
{"topic": "orderbook.200.BTCUSDT", "ts": 1742458822614, "type": "delta", "data": {"s": "BTCUSDT", "b": [["85876.62", "0.273024"], ["85876.6", "0.0006"], ["85869.4", "0.002751"], ["85868.13", "0.069866"], ["85867.61", "0"], ["85865.93", "0"], ["85863.97", "0"], ["85860.16", "0"], ["85858.56", "0.123235"], ["85855.43", "0.595984"], ["85854.17", "0"], ["85853.16", "0"], ["85852.85", "0.232892"], ["85851.56", "0.172457"], ["85846.16", "0"], ["85845.07", "0"], ["85844.56", "0.305014"], ["85827.5", "0.013"], ["85827.49", "0.012884"], ["85827.45", "0.04"], ["85827.44", "0.039645"], ["85827.3", "0"], ["85827.29", "0"], ["85827.25", "0"], ["85827.24", "0"], ["85825.43", "0.001333"]], "a": [["85880.49", "0"], ["85881.88", "0.007035"], ["85885.86", "0.17258"], ["85889.17", "0"], ["85891.59", "0"], ["85893.06", "0"], ["85893.56", "0.113407"], ["85898.97", "0"], ["85900.06", "0"], ["85900.56", "0.17556"], ["85907.06", "0"], ["85907.56", "0.27233"], ["85908.07", "0"], ["85910.14", "0.163025"], ["85915.83", "0.04"], ["85915.84", "0.04"], ["85915.88", "0.013"], ["85915.89", "0.013"], ["85916.58", "0"], ["85916.59", "0"], ["85916.63", "0"], ["85916.64", "0"], ["85925.18", "0.005822"], ["85925.6", "0.004645"], ["85925.85", "0.058858"]], "u": 1380063, "seq": 67411130319}, "cts": 1742458822611, "record_time": 1742458823.103607}
{"topic": "orderbook.200.BTCUSDT", "ts": 1742458822814, "type": "delta", "data": {"s": "BTCUSDT", "b": [["85876.62", "0.439524"], ["85872.34", "0.004288"], ["85872", "0.060564"], ["85870.6", "0.0005"], ["85870.03", "0.002461"], ["85870.02", "0.069864"], ["85869.4", "0.000291"], ["85868.13", "0"], ["85864.4", "0.052"], ["85863.97", "0.119823"], ["85860.16", "0.119229"], ["85859.08", "0.108528"], ["85858.56", "0"], ["85854.17", "0.179319"], ["85853.16", "0.176457"], ["85852.08", "0.177832"], ["85851.56", "0"], ["85845.08", "0.293391"], ["85845.07", "0.306469"], ["85844.56", "0"], ["85832.6", "0.0021"], ["85827.5", "0"], ["85827.49", "0"], ["85827.45", "0"], ["85827.44", "0"], ["85827.4", "0.013"], ["85827.39", "0.012884"], ["85827.35", "0.04"], ["85827.21", "0"], ["85827.01", "0"], ["85826.87", "0"], ["85826.6", "0"], ["85826.42", "0"], ["85826.4", "0"], ["85825.58", "0"], ["85825.43", "0"]], "a": [["85881.88", "0"], ["85881.92", "0.007035"], ["85885.86", "0.083643"], ["85889.17", "0.110059"], ["85893.06", "0.110625"], ["85893.56", "0"], ["85894.08", "0.118617"], ["85898.78", "0.109887"], ["85898.97", "0.165192"], ["85900.06", "0.177385"], ["85900.56", "0"], ["85901.08", "0.176303"], ["85907.06", "0.303135"], ["85907.56", "0"], ["85908.07", "0.278732"], ["85908.08", "0.275493"], ["85915.83", "0"], ["85915.84", "0"], ["85915.88", "0"], ["85915.89", "0"], ["85916.33", "0.04"], ["85916.34", "0.04"], ["85916.38", "0.013"], ["85916.39", "0.013"], ["85923.45", "0"], ["85923.53", "0"], ["85924.13", "0"], ["85924.18", "0"], ["85925.18", "0"], ["85925.6", "0"], ["85925.85", "0"]], "u": 1380064, "seq": 67411130477}, "cts": 1742458822811, "record_time": 1742458823.303811}
{"topic": "orderbook.200.BTCUSDT", "ts": 1742458823015, "type": "delta", "data": {"s": "BTCUSDT", "b": [["85876.62", "0.293586"], ["85872.34", "0"], ["85872", "0"], ["85871.78", "0"], ["85870.03", "0.036154"], ["85870.02", "0"], ["85869.76", "0"], ["85869.62", "0.000153"], ["85869.4", "0.002752"], ["85867.78", "0.069866"], ["85863.97", "0"], ["85863.52", "0.121613"], ["85860.16", "0"], ["85859.71", "0.116417"], ["85859.08", "0"], ["85858.64", "0.117823"], ["85857.02", "0"], ["85855", "0"], ["85854.17", "0"], ["85853.72", "0.164124"], ["85853.16", "0"], ["85852.71", "0.173579"], ["85852.08", "0"], ["85851.64", "0.165278"], ["85845.71", "0.280204"], ["85845.08", "0"], ["85845.07", "0"], ["85844.64", "0.291459"], ["85844.62", "0.285705"], ["85837.71", "0.06989"], ["85835.45", "0"], ["85827.34", "0.039645"], ["85827.21", "0.116402"], ["85827.01", "0.003476"], ["85826.87", "0.001466"]], "a": [["85876.63", "0.404826"], ["85881.92", "0"], ["85881.98", "0.007035"], ["85888.72", "0.122711"], ["85889.17", "0"], ["85891.59", "0.058858"], ["85892.61", "0.113829"], ["85893.06", "0"], ["85893.64", "0.113368"], ["85894.08", "0"], ["85898.52", "0.171651"], ["85898.67", "0.109886"], ["85898.78", "0"], ["85898.97", "0"], ["85899.61", "0.177021"], ["85900.06", "0"], ["85900.64", "0.176941"], ["85901.08", "0"], ["85906.61", "0.279534"], ["85907.06", "0"], ["85907.62", "0.300462"], ["85907.64", "0.283639"], ["85908.07", "0"], ["85908.08", "0"], ["85915.93", "0.04"], ["85915.94", "0.04"], ["85915.98", "0.013"], ["85915.99", "0.013"], ["85916.33", "0"], ["85916.34", "0"], ["85916.38", "0"], ["85916.39", "0"], ["85922.71", "0.11"], ["85922.99", "0"], ["85923.21", "0"]], "u": 1380065, "seq": 67411130620}, "cts": 1742458823006, "record_time": 1742458823.504623}
{"topic": "orderbook.200.BTCUSDT", "ts": 1742458823214, "type": "delta", "data": {"s": "BTCUSDT", "b": [["85876.62", "0.301178"], ["85873.59", "0.008841"], ["85870.03", "0.056087"], ["85869.76", "0.011645"], ["85869.69", "0.00246"], ["85869.68", "0.069864"], ["85869.4", "0.000291"], ["85867.78", "0"], ["85863.6", "0.12302"], ["85863.52", "0"], ["85859.71", "0"], ["85859.11", "0.287671"], ["85858.64", "0"], ["85855.43", "0"], ["85854.46", "0"], ["85853.8", "0.177417"], ["85853.72", "0"], ["85852.71", "0"], ["85851.64", "0"], ["85846.91", "0.003"], ["85845.71", "0"], ["85844.7", "0.279835"], ["85844.64", "0"], ["85844.62", "0"], ["85834.9", "0"], ["85827.4", "0"], ["85827.39", "0"], ["85827.35", "0"], ["85827.34", "0"], ["85827.2", "0.013"], ["85827.19", "0.012884"], ["85827.05", "0.04"], ["85827.04", "0.039645"], ["85826.6", "0.058858"], ["85826.42", "0.030526"], ["85825.58", "0.021095"], ["85825.43", "0.001333"], ["85825.36", "0.163027"], ["85825.25", "0.02329"]], "a": [["85876.63", "0.406861"], ["85881.98", "0"], ["85885.86", "0.115225"], ["85886.93", "0.028154"], ["85888.72", "0"], ["85888.8", "0.120083"], ["85891.59", "0"], ["85892.61", "0"], ["85893.64", "0"], ["85898.52", "0"], ["85898.6", "0.187338"], ["85899.61", "0"], ["85900.64", "0"], ["85906.61", "0"], ["85907.62", "0"], ["85907.64", "0"], ["85907.7", "0.291923"], ["85915.93", "0"], ["85915.94", "0"], ["85915.98", "0"], ["85915.99", "0"], ["85916.38", "0.013"], ["85916.39", "0.013"], ["85916.43", "0.04"], ["85916.44", "0.04"], ["85916.58", "0.003"], ["85917.68", "0"], ["85922.99", "0.00026"], ["85923.21", "0.000333"], ["85923.45", "0.00157"], ["85923.53", "0.00026"], ["85924.13", "0.009"], ["85924.18", "0.001333"], ["85925.18", "0.005822"]], "u": 1380066, "seq": 67411130753}, "cts": 1742458823210, "record_time": 1742458823.704429}
{"topic": "orderbook.200.BTCUSDT", "ts": 1742458823415, "type": "delta", "data": {"s": "BTCUSDT", "b": [["85876.62", "0.439524"], ["85869.69", "0"], ["85869.4", "0.002752"], ["85866.33", "0.028154"], ["85863.97", "0.120719"], ["85863.6", "0"], ["85860.16", "0.109407"], ["85859.08", "0.115549"], ["85856.82", "0.820368"], ["85854.17", "0.184238"], ["85853.8", "0"], ["85853.16", "0.169792"], ["85852.08", "0.183998"], ["85851.62", "1.335483"], ["85846.16", "0.27569"], ["85845.08", "0.304067"], ["85845.07", "0.285666"], ["85844.7", "0"], ["85828.91", "0.11"], ["85827.22", "0.349297"], ["85827.05", "0"], ["85827.04", "0"], ["85827.01", "0"], ["85826.87", "0"], ["85826.6", "0"], ["85826.42", "0"], ["85825.58", "0"], ["85825.43", "0"], ["85825.36", "0"], ["85825.25", "0"]], "a": [["85886.93", "0"], ["85888.8", "0"], ["85889.17", "0.123712"], ["85893.06", "0.112219"], ["85894.08", "0.119208"], ["85898.6", "0"], ["85898.97", "0.168126"], ["85900.06", "0.182639"], ["85901.08", "0.165017"], ["85907.06", "0.274939"], ["85907.7", "0"], ["85908.07", "0.298902"], ["85908.08", "0.311077"], ["85923.45", "0"], ["85923.53", "0"], ["85924.13", "0"], ["85924.18", "0"], ["85925.18", "0"]], "u": 1380067, "seq": 67411130843}, "cts": 1742458823411, "record_time": 1742458823.904332}
{"topic": "orderbook.200.BTCUSDT", "ts": 1742458823615, "type": "delta", "data": {"s": "BTCUSDT", "b": [["85876.62", "0.467678"], ["85866.33", "0"], ["85864.34", "0.117703"], ["85859.11", "0.49714"], ["85854.49", "0.648111"], ["85853.84", "0.183993"], ["85846.84", "0.451002"], ["85827.7", "0.013"], ["85827.69", "0.012884"], ["85827.22", "0"], ["85827.21", "0"], ["85827.2", "0"], ["85827.19", "0"]], "a": [["85876.63", "0.399826"], ["85881.73", "0.007035"], ["85882.76", "0.011705"], ["85883.07", "0"], ["85885.22", "0.039649"], ["85888.84", "0.11399"], ["85899.34", "0.181812"], ["85899.59", "0.752932"], ["85906.34", "0.295358"], ["85915.63", "0.04"], ["85915.64", "0.04"], ["85915.68", "0.013"], ["85915.69", "0.013"], ["85916.38", "0"], ["85916.39", "0"], ["85916.43", "0"], ["85916.44", "0"], ["85922.72", "0"], ["85922.99", "0"], ["85923.21", "0"]], "u": 1380068, "seq": 67411130900}, "cts": 1742458823607, "record_time": 1742458824.104606}
{"topic": "orderbook.200.BTCUSDT", "ts": 1742458823815, "type": "delta", "data": {"s": "BTCUSDT", "b": [["85865.7", "0.035221"], ["85863.56", "0.035222"], ["85861.62", "0"], ["85858.04", "0"]], "a": [["85876.63", "0.378707"], ["85881.73", "0"], ["85882.76", "0"], ["85885.22", "0.005"], ["85886.93", "0.028154"], ["85887.55", "0.034648"]], "u": 1380069, "seq": 67411130933}, "cts": 1742458823811, "record_time": 1742458824.305936}
{"topic": "orderbook.200.BTCUSDT", "ts": 1742458824014, "type": "delta", "data": {"s": "BTCUSDT", "b": [["85866.33", "0.028154"], ["85865.7", "0"], ["85863.44", "0.035222"], ["85827.69", "0"]], "a": [["85876.63", "0.406861"], ["85885.28", "0.034649"], ["85885.86", "0.159391"], ["85886.93", "0"], ["85887.55", "0"], ["85922.72", "0.001051"]], "u": 1380070, "seq": 67411130959}, "cts": 1742458824006, "record_time": 1742458824.503519}
