{"e": "depthUpdate", "E": 1742584895014, "s": "BTCUSDT", "U": 64637882183, "u": 64637887525, "b": [["84103.52000000", "5.09613000"], ["84103.51000000", "0.00048000"], ["84103.39000000", "0.00007000"], ["84103.38000000", "0.00007000"], ["84103.36000000", "0.00208000"], ["84103.35000000", "0.00007000"], ["84102.99000000", "0.00000000"], ["84102.70000000", "0.00000000"], ["84102.52000000", "0.00007000"], ["84102.47000000", "0.00021000"], ["84102.46000000", "0.04013000"], ["84102.39000000", "0.00000000"], ["84102.38000000", "0.00000000"], ["84102.37000000", "0.00000000"], ["84102.17000000", "0.00000000"], ["84102.16000000", "0.00000000"], ["84102.03000000", "0.00014000"], ["84102.02000000", "1.22742000"], ["84102.01000000", "0.00000000"], ["84102.00000000", "0.02273000"], ["84101.99000000", "2.23323000"], ["84101.98000000", "0.00000000"], ["84101.85000000", "0.01189000"], ["84101.72000000", "0.00000000"], ["84101.64000000", "0.00000000"], ["84101.63000000", "0.04006000"], ["84101.62000000", "0.00000000"], ["84101.61000000", "0.04313000"], ["84101.60000000", "0.00000000"], ["84101.57000000", "0.00000000"], ["84101.56000000", "0.00000000"], ["84101.50000000", "0.00000000"], ["84101.40000000", "0.00000000"], ["84101.39000000", "0.00000000"], ["84101.38000000", "0.00000000"], ["84101.09000000", "0.00000000"], ["84101.08000000", "0.00000000"], ["84100.87000000", "0.16286000"], ["84100.79000000", "0.00000000"], ["84100.70000000", "0.00000000"], ["84100.66000000", "0.00000000"], ["84100.60000000", "0.00024000"], ["84100.59000000", "0.33838000"], ["84100.39000000", "0.04000000"], ["84100.12000000", "0.04000000"], ["84100.00000000", "0.02266000"], ["84099.98000000", "0.00000000"], ["84099.97000000", "0.00000000"], ["84099.94000000", "0.00000000"], ["84099.92000000", "0.02538000"], ["84099.89000000", "0.00000000"], ["84099.88000000", "0.00000000"], ["84099.87000000", "0.00000000"], ["84099.61000000", "0.02378000"], ["84099.58000000", "0.00000000"], ["84099.56000000", "0.04000000"], ["84099.41000000", "0.00000000"], ["84099.34000000", "0.00000000"], ["84099.33000000", "0.00000000"], ["84099.26000000", "0.00000000"], ["84099.25000000", "0.00000000"], ["84099.13000000", "0.00000000"], ["84099.03000000", "0.00000000"], ["84099.02000000", "0.00754000"], ["84098.91000000", "0.00000000"], ["84098.80000000", "0.00000000"], ["84098.79000000", "0.00000000"], ["84098.58000000", "0.00000000"], ["84098.28000000", "0.00000000"], ["84098.26000000", "0.00000000"], ["84098.06000000", "0.43655000"], ["84098.05000000", "0.00000000"], ["84098.04000000", "0.00000000"], ["84098.03000000", "0.35968000"], ["84098.02000000", "0.00000000"], ["84098.01000000", "0.00000000"], ["84098.00000000", "0.02260000"], ["84097.89000000", "0.00000000"], ["84097.88000000", "0.03578000"], ["84097.84000000", "0.00000000"], ["84097.81000000", "0.13862000"], ["84097.43000000", "0.00000000"], ["84097.42000000", "0.04000000"], ["84097.41000000", "0.04000000"], ["84097.25000000", "0.00000000"], ["84097.24000000", "0.00000000"], ["84097.13000000", "0.00000000"], ["84096.96000000", "0.11890000"], ["84096.85000000", "0.00000000"], ["84096.80000000", "0.01189000"], ["84096.75000000", "0.00000000"], ["84096.74000000", "0.53653000"], ["84096.73000000", "0.00000000"], ["84096.57000000", "0.00000000"], ["84096.08000000", "0.00000000"], ["84096.07000000", "0.00000000"], ["84096.00000000", "0.02260000"], ["84095.97000000", "0.00000000"], ["84095.96000000", "0.08574000"], ["84095.91000000", "0.09945000"], ["84095.86000000", "0.04000000"], ["84095.75000000", "0.00000000"], ["84095.60000000", "0.00000000"], ["84095.55000000", "0.00000000"], ["84095.51000000", "0.00000000"], ["84095.50000000", "0.00000000"], ["84095.49000000", "0.00000000"], ["84095.45000000", "0.00000000"], ["84095.44000000", "0.03578000"], ["84095.39000000", "0.00000000"], ["84095.38000000", "0.00000000"], ["84095.37000000", "0.00000000"], ["84095.36000000", "0.00000000"], ["84095.34000000", "0.00000000"], ["84095.33000000", "0.00000000"], ["84095.13000000", "0.01000000"], ["84095.11000000", "0.04000000"], ["84094.96000000", "0.00000000"], ["84094.94000000", "0.00000000"], ["84094.90000000", "0.00000000"], ["84094.89000000", "0.03623000"], ["84094.80000000", "0.00000000"], ["84094.69000000", "0.00000000"], ["84094.68000000", "0.00000000"], ["84094.61000000", "0.00000000"], ["84094.60000000", "0.00000000"], ["84094.57000000", "0.00000000"], ["84094.56000000", "0.00000000"], ["84094.51000000", "0.00000000"], ["84094.50000000", "0.00000000"], ["84094.49000000", "0.04996000"], ["84094.38000000", "0.00000000"], ["84094.37000000", "0.03578000"], ["84094.20000000", "0.00000000"], ["84094.17000000", "0.00000000"], ["84094.09000000", "0.00000000"], ["84094.05000000", "0.39229000"], ["84094.04000000", "0.00000000"], ["84094.01000000", "0.00118000"], ["84094.00000000", "0.02260000"], ["84093.88000000", "0.00000000"], ["84093.87000000", "0.00000000"], ["84093.81000000", "0.00000000"], ["84093.80000000", "0.00000000"], ["84093.74000000", "0.00000000"], ["84093.70000000", "0.13548000"], ["84093.69000000", "0.03578000"], ["84093.68000000", "0.00000000"], ["84093.67000000", "0.06839000"], ["84093.66000000", "0.00000000"], ["84093.24000000", "0.00594000"], ["84093.07000000", "0.00000000"], ["84093.06000000", "0.00000000"], ["84093.05000000", "0.00000000"], ["84093.02000000", "0.00013000"], ["84092.87000000", "0.11890000"], ["84092.40000000", "0.00006000"], ["84092.39000000", "0.00000000"], ["84092.38000000", "0.00000000"], ["84092.37000000", "0.00000000"], ["84092.36000000", "0.00000000"], ["84092.01000000", "0.00000000"], ["84092.00000000", "0.02260000"], ["84091.98000000", "0.00000000"], ["84091.97000000", "0.00000000"], ["84091.91000000", "0.00000000"], ["84091.64000000", "0.00009000"], ["84091.58000000", "0.00000000"], ["84091.51000000", "0.00000000"], ["84091.49000000", "0.00000000"], ["84091.48000000", "0.03321000"], ["84091.47000000", "0.00000000"], ["84091.31000000", "0.00000000"], ["84091.13000000", "0.02000000"], ["84090.91000000", "0.01189000"], ["84090.78000000", "0.89155000"], ["84090.72000000", "0.00000000"], ["84090.71000000", "0.00000000"], ["84090.70000000", "0.00000000"], ["84090.69000000", "0.00000000"], ["84090.68000000", "0.00000000"], ["84090.67000000", "0.00000000"], ["84090.63000000", "0.04000000"], ["84090.59000000", "0.00000000"], ["84090.10000000", "0.00000000"], ["84090.09000000", "0.00013000"], ["84090.01000000", "0.00000000"], ["84090.00000000", "0.02260000"], ["84089.99000000", "0.32787000"], ["84089.95000000", "0.00000000"], ["84089.81000000", "0.00000000"], ["84089.79000000", "0.00000000"], ["84089.49000000", "0.02817000"], ["84089.42000000", "0.00307000"], ["84089.41000000", "0.99707000"], ["84089.40000000", "0.71126000"], ["84089.39000000", "0.00118000"], ["84089.38000000", "0.85664000"], ["84089.37000000", "0.47549000"], ["84089.31000000", "0.07583000"], ["84089.00000000", "0.00000000"], ["84088.96000000", "0.00000000"], ["84088.89000000", "0.04000000"], ["84088.42000000", "0.00594000"], ["84088.32000000", "0.48578000"], ["84088.31000000", "0.00000000"], ["84088.20000000", "0.00006000"], ["84088.00000000", "0.02260000"], ["84087.98000000", "0.01189000"], ["84087.97000000", "0.00000000"], ["84087.91000000", "0.00000000"], ["84087.53000000", "0.00013000"], ["84087.09000000", "0.00000000"], ["84087.06000000", "0.00013000"], ["84086.85000000", "0.10603000"], ["84086.78000000", "0.05943000"], ["84086.45000000", "0.59469000"], ["84086.44000000", "0.00000000"], ["84086.38000000", "0.00000000"], ["84086.19000000", "0.00000000"], ["84086.00000000", "0.02260000"], ["84085.94000000", "0.00000000"], ["84085.61000000", "0.94101000"], ["84085.60000000", "0.01783000"], ["84085.59000000", "0.04000000"], ["84085.44000000", "0.19578000"], ["84085.38000000", "0.35662000"], ["84085.28000000", "0.00300000"], ["84085.11000000", "0.00000000"], ["84085.05000000", "0.00000000"], ["84084.80000000", "0.03578000"], ["84084.74000000", "0.04000000"], ["84084.45000000", "0.00000000"], ["84084.28000000", "0.00000000"], ["84084.26000000", "0.00000000"], ["84084.23000000", "0.02378000"], ["84084.20000000", "0.00000000"], ["84084.00000000", "0.02266000"], ["84083.80000000", "0.00006000"], ["84083.78000000", "0.00000000"], ["84083.64000000", "0.00000000"], ["84083.22000000", "0.00009000"], ["84083.17000000", "0.00013000"], ["84083.13000000", "0.00000000"], ["84082.98000000", "0.08354000"], ["84082.97000000", "0.71126000"], ["84082.96000000", "0.85670000"], ["84082.60000000", "0.00000000"], ["84082.49000000", "0.00029000"], ["84082.44000000", "0.00000000"], ["84082.38000000", "0.00000000"], ["84082.26000000", "0.00000000"], ["84081.76000000", "0.00000000"], ["84081.31000000", "0.87543000"], ["84081.23000000", "0.00000000"], ["84080.97000000", "0.00000000"], ["84080.91000000", "0.00000000"], ["84080.81000000", "0.60359000"], ["84080.69000000", "0.00000000"], ["84080.49000000", "0.00000000"], ["84080.41000000", "0.00000000"], ["84080.32000000", "0.13418000"], ["84080.31000000", "0.00356000"], ["84080.07000000", "0.00000000"], ["84080.06000000", "0.00000000"], ["84080.00000000", "0.00006000"], ["84079.80000000", "0.00006000"], ["84079.58000000", "0.89155000"], ["84079.10000000", "0.00000000"], ["84078.99000000", "0.00000000"], ["84078.94000000", "0.00000000"], ["84078.88000000", "0.00000000"], ["84078.13000000", "0.01189000"], ["84078.00000000", "0.00000000"], ["84077.96000000", "0.00000000"], ["84077.80000000", "0.72109000"], ["84077.78000000", "0.85676000"], ["84077.20000000", "0.39427000"], ["84077.01000000", "0.00000000"], ["84076.85000000", "0.00059000"], ["84076.64000000", "0.20148000"], ["84076.43000000", "0.00581000"], ["84076.22000000", "0.00013000"], ["84076.08000000", "0.18772000"], ["84076.00000000", "0.00000000"], ["84075.77000000", "0.00000000"], ["84075.65000000", "0.00000000"], ["84075.62000000", "0.00016000"], ["84075.60000000", "0.02424000"], ["84075.59000000", "0.00000000"], ["84074.93000000", "0.00000000"], ["84074.75000000", "0.00007000"], ["84074.74000000", "0.00000000"], ["84074.69000000", "0.00000000"], ["84074.65000000", "0.00000000"], ["84074.30000000", "0.00000000"], ["84074.15000000", "0.00000000"], ["84074.00000000", "0.00000000"], ["84073.82000000", "0.00000000"], ["84073.70000000", "0.00500000"], ["84073.23000000", "0.00000000"], ["84073.13000000", "0.34972000"], ["84072.83000000", "2.31841000"], ["84072.82000000", "0.00000000"], ["84072.70000000", "0.00000000"], ["84072.56000000", "0.00000000"], ["84072.41000000", "0.00000000"], ["84072.00000000", "0.00000000"], ["84071.99000000", "0.00000000"], ["84071.82000000", "0.00000000"], ["84071.42000000", "0.00000000"], ["84071.17000000", "0.20148000"], ["84071.16000000", "0.00000000"], ["84071.14000000", "0.89155000"], ["84070.72000000", "0.00000000"], ["84070.71000000", "0.00000000"], ["84070.60000000", "0.00000000"], ["84070.57000000", "0.30853000"], ["84070.55000000", "0.00000000"], ["84070.52000000", "0.00000000"], ["84070.42000000", "0.00000000"], ["84070.35000000", "0.00000000"], ["84070.00000000", "0.00000000"], ["84069.74000000", "0.00000000"], ["84069.42000000", "0.01848000"], ["84069.38000000", "0.64133000"], ["84069.36000000", "0.45267000"], ["84068.75000000", "0.00000000"], ["84068.34000000", "0.04628000"], ["84068.23000000", "0.89155000"], ["84068.15000000", "0.00000000"], ["84068.11000000", "0.00000000"], ["84066.71000000", "0.21480000"], ["84066.22000000", "0.37692000"], ["84066.08000000", "0.00000000"], ["84065.94000000", "0.04228000"], ["84065.38000000", "0.00000000"], ["84065.06000000", "0.00000000"], ["84065.01000000", "0.00000000"], ["84065.00000000", "0.00000000"], ["84064.06000000", "0.04000000"], ["84063.76000000", "0.03202000"], ["84063.23000000", "0.04000000"], ["84062.68000000", "0.00000000"], ["84062.08000000", "0.00000000"], ["84061.78000000", "0.00000000"], ["84061.04000000", "0.36997000"], ["84061.03000000", "0.00358000"], ["84060.99000000", "0.00000000"], ["84060.67000000", "0.10196000"], ["84060.66000000", "0.00000000"], ["84060.07000000", "0.53477000"], ["84060.06000000", "0.70584000"], ["84060.04000000", "0.00000000"], ["84059.86000000", "0.04000000"], ["84059.67000000", "0.00000000"], ["84059.56000000", "0.00059000"], ["84059.03000000", "0.10794000"], ["84059.02000000", "0.04000000"], ["84059.01000000", "0.04000000"], ["84058.73000000", "0.00000000"], ["84058.09000000", "0.21971000"], ["84057.40000000", "0.05297000"], ["84057.06000000", "1.03260000"], ["84056.61000000", "0.05098000"], ["84055.66000000", "0.00000000"], ["84055.48000000", "0.46523000"], ["84055.10000000", "0.05796000"], ["84054.85000000", "0.86579000"], ["84054.00000000", "2.37274000"], ["84053.68000000", "0.05497000"], ["84053.67000000", "0.00000000"], ["84052.74000000", "0.00000000"], ["84052.04000000", "0.25689000"], ["84051.78000000", "0.00000000"], ["84051.28000000", "0.05297000"], ["84051.19000000", "0.00000000"], ["84050.85000000", "0.00000000"], ["84050.51000000", "1.13334000"], ["84050.50000000", "0.00000000"], ["84050.38000000", "0.00000000"], ["84050.15000000", "0.00000000"], ["84050.09000000", "0.47549000"], ["84049.76000000", "0.00000000"], ["84049.44000000", "0.00000000"], ["84049.18000000", "0.00272000"], ["84049.17000000", "0.00000000"], ["84048.80000000", "0.00000000"], ["84048.74000000", "0.00000000"], ["84048.58000000", "0.04498000"], ["84048.49000000", "0.00006000"], ["84048.19000000", "0.00000000"], ["84048.01000000", "0.08396000"], ["84047.45000000", "0.22190000"], ["84047.44000000", "0.27452000"], ["84046.73000000", "0.00000000"], ["84046.20000000", "0.09596000"], ["84045.89000000", "0.00000000"], ["84045.59000000", "0.04198000"], ["84044.55000000", "0.00000000"], ["84044.26000000", "0.09996000"], ["84043.19000000", "0.00000000"], ["84042.94000000", "0.00817000"], ["84042.27000000", "0.00869000"], ["84042.19000000", "0.04000000"], ["84042.18000000", "0.01189000"], ["84042.11000000", "0.00000000"], ["84041.73000000", "0.09639000"], ["84041.26000000", "0.00000000"], ["84040.73000000", "0.09706000"], ["84040.04000000", "0.18994000"], ["84040.00000000", "0.05214000"], ["84039.12000000", "0.00000000"], ["84038.82000000", "0.04000000"], ["84038.04000000", "0.00000000"], ["84037.97000000", "0.04000000"], ["84037.30000000", "0.00060000"], ["84036.42000000", "0.00000000"], ["84035.59000000", "0.00000000"], ["84034.36000000", "0.25747000"], ["84034.35000000", "0.00000000"], ["84033.60000000", "0.03575000"], ["84033.56000000", "0.00000000"], ["84033.07000000", "0.85957000"], ["84031.63000000", "0.00827000"], ["84029.91000000", "0.00000000"], ["84027.40000000", "0.00358000"], ["84026.93000000", "0.00000000"], ["84026.82000000", "0.00000000"], ["84026.37000000", "0.00000000"], ["84026.34000000", "0.03201000"], ["84026.26000000", "0.00000000"], ["84026.13000000", "0.00000000"], ["84026.06000000", "0.00822000"], ["84025.98000000", "0.00000000"], ["84025.14000000", "0.00000000"], ["84021.77000000", "0.00000000"], ["84019.43000000", "0.05188000"], ["84019.01000000", "0.00000000"], ["84019.00000000", "0.04000000"], ["84017.99000000", "0.00145000"], ["84017.61000000", "0.12899000"], ["84017.60000000", "0.50128000"], ["84017.31000000", "1.02836000"], ["84016.07000000", "0.00000000"], ["84015.39000000", "0.00000000"], ["84015.16000000", "0.00000000"], ["84014.56000000", "0.00000000"], ["84007.36000000", "0.00000000"], ["84006.58000000", "0.10000000"], ["84005.78000000", "0.00000000"], ["84004.94000000", "0.00000000"], ["84004.33000000", "0.00000000"], ["84001.63000000", "0.00000000"], ["84000.74000000", "0.00000000"], ["83996.96000000", "0.00000000"], ["83996.95000000", "0.00000000"], ["83996.54000000", "0.00400000"], ["83996.44000000", "0.14781000"], ["83994.14000000", "0.00000000"], ["83993.00000000", "0.65168000"], ["83991.08000000", "0.05497000"], ["83989.51000000", "0.00000000"], ["83989.26000000", "0.31299000"], ["83988.48000000", "0.04638000"], ["83988.26000000", "0.10595000"], ["83986.56000000", "0.15632000"], ["83986.27000000", "0.00000000"], ["83986.18000000", "0.15551000"], ["83985.42000000", "0.11544000"], ["83985.12000000", "0.00000000"], ["83984.02000000", "0.00000000"], ["83983.47000000", "0.05297000"], ["83980.06000000", "0.00000000"], ["83979.97000000", "0.00000000"], ["83979.75000000", "0.00083000"], ["83975.49000000", "0.43894000"], ["83973.48000000", "0.00000000"], ["83972.62000000", "0.00119000"], ["83972.53000000", "0.00000000"], ["83972.24000000", "0.00000000"], ["83972.03000000", "0.00000000"], ["83971.82000000", "0.00000000"], ["83971.33000000", "0.00000000"], ["83970.66000000", "0.05509000"], ["83968.72000000", "0.00000000"], ["83968.64000000", "0.00000000"], ["83968.61000000", "0.00000000"], ["83968.54000000", "0.00000000"], ["83968.48000000", "0.00000000"], ["83968.13000000", "0.00000000"], ["83968.04000000", "0.05497000"], ["83967.86000000", "0.00000000"], ["83967.81000000", "0.00000000"], ["83966.11000000", "0.10993000"], ["83966.02000000", "0.00000000"], ["83965.92000000", "0.00000000"], ["83965.40000000", "0.00000000"], ["83965.29000000", "0.00000000"], ["83965.08000000", "0.00000000"], ["83963.82000000", "0.00000000"], ["83963.32000000", "0.00000000"], ["83963.29000000", "0.00000000"], ["83963.26000000", "0.00000000"], ["83963.01000000", "0.00000000"], ["83962.97000000", "0.00000000"], ["83962.30000000", "0.00000000"], ["83961.41000000", "0.00000000"], ["83961.08000000", "0.00000000"], ["83961.04000000", "0.00000000"], ["83960.56000000", "0.00000000"], ["83960.41000000", "0.00000000"], ["83960.33000000", "0.00000000"], ["83960.06000000", "0.00000000"], ["83959.96000000", "0.05096000"], ["83959.75000000", "0.00000000"], ["83959.39000000", "0.00000000"], ["83958.75000000", "0.00000000"], ["83958.39000000", "0.00000000"], ["83958.23000000", "0.00013000"], ["83958.10000000", "0.00000000"], ["83957.94000000", "0.00000000"], ["83957.54000000", "0.00000000"], ["83956.38000000", "0.00040000"], ["83956.31000000", "0.00000000"], ["83956.25000000", "0.00000000"], ["83956.24000000", "0.00000000"], ["83956.15000000", "0.00008000"], ["83956.01000000", "0.45000000"], ["83955.94000000", "0.00000000"], ["83955.87000000", "0.00000000"], ["83955.01000000", "0.00000000"], ["83954.85000000", "0.00000000"], ["83954.73000000", "0.00000000"], ["83954.69000000", "0.21411000"], ["83954.30000000", "0.20396000"], ["83954.14000000", "0.00000000"], ["83953.96000000", "0.00000000"], ["83953.40000000", "0.04198000"], ["83953.38000000", "0.00000000"], ["83952.78000000", "0.99313000"], ["83952.77000000", "0.00000000"], ["83952.72000000", "0.00000000"], ["83952.40000000", "0.00000000"], ["83952.23000000", "0.00000000"], ["83952.21000000", "0.00000000"], ["83951.97000000", "0.00000000"], ["83951.87000000", "0.00000000"], ["83951.84000000", "0.00000000"], ["83951.79000000", "0.00000000"], ["83951.57000000", "0.00000000"], ["83951.46000000", "0.00000000"], ["83950.89000000", "0.00000000"], ["83950.85000000", "0.00000000"], ["83950.52000000", "0.00000000"], ["83949.68000000", "0.00000000"], ["83949.60000000", "0.05954000"], ["83949.31000000", "0.20410000"], ["83948.90000000", "0.04497000"], ["83948.70000000", "0.00000000"], ["83948.56000000", "0.00000000"], ["83948.41000000", "0.00000000"], ["83948.22000000", "0.00000000"], ["83948.01000000", "0.00000000"], ["83947.92000000", "0.00000000"], ["83947.90000000", "0.00000000"], ["83947.41000000", "0.00000000"], ["83947.04000000", "0.00000000"], ["83946.74000000", "0.00000000"], ["83946.72000000", "0.01000000"], ["83946.43000000", "0.00000000"], ["83946.07000000", "0.00000000"], ["83946.02000000", "0.00000000"], ["83945.91000000", "0.00000000"], ["83945.35000000", "0.00000000"], ["83945.08000000", "0.00000000"], ["83944.78000000", "0.00000000"], ["83944.73000000", "0.00000000"], ["83944.53000000", "0.00000000"], ["83944.52000000", "0.00000000"], ["83944.44000000", "0.00000000"], ["83944.19000000", "0.00000000"], ["83944.07000000", "0.00000000"], ["83943.73000000", "0.00000000"], ["83943.43000000", "0.00000000"], ["83942.59000000", "0.00000000"], ["83942.48000000", "0.00000000"], ["83941.90000000", "0.00000000"], ["83941.54000000", "0.00000000"], ["83940.16000000", "0.00007000"], ["83940.13000000", "0.00000000"], ["83940.11000000", "0.00000000"], ["83938.18000000", "0.00000000"], ["83936.03000000", "0.00000000"], ["83935.83000000", "0.00000000"], ["83934.12000000", "0.00000000"], ["83930.24000000", "0.00000000"], ["83925.85000000", "0.00000000"], ["83921.57000000", "0.00835000"], ["83915.99000000", "0.00000000"], ["83915.58000000", "0.00000000"], ["83915.06000000", "0.00000000"], ["83911.89000000", "0.00000000"], ["83900.02000000", "0.00069000"], ["83876.32000000", "0.00000000"], ["83868.63000000", "0.00000000"], ["83866.64000000", "0.20148000"], ["83863.73000000", "0.00000000"], ["83862.03000000", "0.00000000"], ["83860.22000000", "0.00000000"], ["83858.24000000", "0.20148000"], ["83856.81000000", "0.00000000"], ["83856.35000000", "0.00000000"], ["83856.33000000", "0.00000000"], ["83855.33000000", "0.00000000"], ["83854.20000000", "0.00000000"], ["83849.84000000", "0.00975000"], ["83849.48000000", "0.00008000"], ["83848.41000000", "0.00000000"], ["83847.93000000", "0.00000000"], ["83846.23000000", "0.00000000"], ["83845.28000000", "0.00000000"], ["83842.98000000", "0.00000000"], ["83840.01000000", "0.00000000"], ["83838.78000000", "0.00000000"], ["83837.83000000", "0.00000000"], ["83831.61000000", "0.00000000"], ["83740.12000000", "0.00060000"], ["83740.11000000", "0.00000000"], ["83432.65000000", "0.00000000"], ["83250.56000000", "0.00000000"], ["83147.81000000", "0.00000000"], ["83112.60000000", "0.02346000"], ["82832.28000000", "0.00100000"], ["80714.10000000", "0.00000000"], ["75692.00000000", "0.06625000"], ["75691.00000000", "0.00000000"], ["75690.00000000", "0.16071000"], ["75684.00000000", "0.00218000"], ["75683.00000000", "0.04376000"], ["75681.00000000", "0.00000000"], ["75675.00000000", "0.00042000"], ["67282.82000000", "0.00058000"], ["67274.96000000", "0.00000000"], ["67273.19000000", "0.00000000"], ["60000.00000000", "73.01913000"], ["42000.00000000", "6.84710000"], ["33000.00000000", "2.93827000"], ["30272.93000000", "0.00040000"], ["20002.00000000", "0.00000000"], ["20001.00000000", "0.02099000"]], "a": [["84091.49000000", "0.00000000"], ["84091.50000000", "0.00000000"], ["84091.52000000", "0.00000000"], ["84091.59000000", "0.00000000"], ["84091.92000000", "0.00000000"], ["84091.98000000", "0.00000000"], ["84091.99000000", "0.00000000"], ["84092.37000000", "0.00000000"], ["84092.38000000", "0.00000000"], ["84092.39000000", "0.00000000"], ["84093.05000000", "0.00000000"], ["84093.06000000", "0.00000000"], ["84093.67000000", "0.00000000"], ["84093.68000000", "0.00000000"], ["84093.69000000", "0.00000000"], ["84093.70000000", "0.00000000"], ["84093.71000000", "0.00000000"], ["84093.88000000", "0.00000000"], ["84094.05000000", "0.00000000"], ["84094.38000000", "0.00000000"], ["84094.50000000", "0.00000000"], ["84094.51000000", "0.00000000"], ["84094.52000000", "0.00000000"], ["84094.54000000", "0.00000000"], ["84094.55000000", "0.00000000"], ["84094.57000000", "0.00000000"], ["84094.58000000", "0.00000000"], ["84094.59000000", "0.00000000"], ["84094.90000000", "0.00000000"], ["84095.05000000", "0.00000000"], ["84095.06000000", "0.00000000"], ["84095.33000000", "0.00000000"], ["84095.34000000", "0.00000000"], ["84095.35000000", "0.00000000"], ["84095.38000000", "0.00000000"], ["84095.39000000", "0.00000000"], ["84095.45000000", "0.00000000"], ["84095.46000000", "0.00000000"], ["84095.53000000", "0.00000000"], ["84095.58000000", "0.00000000"], ["84095.97000000", "0.00000000"], ["84095.98000000", "0.00000000"], ["84096.29000000", "0.00000000"], ["84096.44000000", "0.00000000"], ["84096.58000000", "0.00000000"], ["84096.60000000", "0.00000000"], ["84096.74000000", "0.00000000"], ["84096.75000000", "0.00000000"], ["84096.76000000", "0.00000000"], ["84096.81000000", "0.00000000"], ["84097.14000000", "0.00000000"], ["84097.24000000", "0.00000000"], ["84097.25000000", "0.00000000"], ["84097.26000000", "0.00000000"], ["84097.42000000", "0.00000000"], ["84097.43000000", "0.00000000"], ["84097.74000000", "0.00000000"], ["84097.84000000", "0.00000000"], ["84097.85000000", "0.00000000"], ["84098.04000000", "0.00000000"], ["84098.05000000", "0.00000000"], ["84098.27000000", "0.00000000"], ["84098.48000000", "0.00000000"], ["84098.56000000", "0.00000000"], ["84098.71000000", "0.00000000"], ["84098.80000000", "0.00000000"], ["84098.81000000", "0.00000000"], ["84098.92000000", "0.00000000"], ["84099.26000000", "0.00000000"], ["84099.27000000", "0.00000000"], ["84099.34000000", "0.00000000"], ["84099.35000000", "0.00000000"], ["84099.41000000", "0.00000000"], ["84099.42000000", "0.00000000"], ["84099.68000000", "0.00000000"], ["84099.87000000", "0.00000000"], ["84099.88000000", "0.00000000"], ["84099.96000000", "0.00000000"], ["84100.31000000", "0.00000000"], ["84100.48000000", "0.00000000"], ["84100.60000000", "0.00000000"], ["84100.61000000", "0.00000000"], ["84100.67000000", "0.00000000"], ["84100.68000000", "0.00000000"], ["84100.70000000", "0.00000000"], ["84100.71000000", "0.00000000"], ["84100.80000000", "0.00000000"], ["84101.09000000", "0.00000000"], ["84101.10000000", "0.00000000"], ["84101.23000000", "0.00000000"], ["84101.39000000", "0.00000000"], ["84101.40000000", "0.00000000"], ["84101.53000000", "0.00000000"], ["84101.56000000", "0.00000000"], ["84101.57000000", "0.00000000"], ["84101.58000000", "0.00000000"], ["84101.61000000", "0.00000000"], ["84101.62000000", "0.00000000"], ["84101.65000000", "0.00000000"], ["84102.00000000", "0.00000000"], ["84102.01000000", "0.00000000"], ["84102.17000000", "0.00000000"], ["84102.18000000", "0.00000000"], ["84102.38000000", "0.00000000"], ["84102.39000000", "0.00000000"], ["84102.40000000", "0.00000000"], ["84102.53000000", "0.00000000"], ["84102.85000000", "0.00000000"], ["84102.86000000", "0.00000000"], ["84103.02000000", "0.00000000"], ["84103.10000000", "0.00000000"], ["84103.20000000", "0.00000000"], ["84103.34000000", "0.00000000"], ["84103.52000000", "0.00000000"], ["84103.53000000", "0.08183000"], ["84103.54000000", "0.00055000"], ["84103.61000000", "0.00000000"], ["84103.78000000", "0.00000000"], ["84103.82000000", "0.00042000"], ["84103.83000000", "0.00389000"], ["84103.97000000", "0.00209000"], ["84104.00000000", "0.00000000"], ["84104.18000000", "0.00007000"], ["84104.25000000", "0.00007000"], ["84104.26000000", "0.00000000"], ["84104.37000000", "0.00000000"], ["84104.46000000", "0.00007000"], ["84104.47000000", "0.00000000"], ["84104.60000000", "0.00000000"], ["84104.68000000", "0.00014000"], ["84104.69000000", "0.12835000"], ["84104.70000000", "0.00000000"], ["84104.72000000", "0.00000000"], ["84104.78000000", "0.00000000"], ["84104.80000000", "0.00000000"], ["84104.89000000", "0.00000000"], ["84104.98000000", "0.00018000"], ["84104.99000000", "0.03791000"], ["84105.00000000", "0.00000000"], ["84105.02000000", "0.00301000"], ["84105.03000000", "0.00000000"], ["84105.34000000", "0.00010000"], ["84105.35000000", "0.02425000"], ["84105.71000000", "0.00000000"], ["84105.84000000", "0.00000000"], ["84105.85000000", "0.00000000"], ["84105.87000000", "0.00007000"], ["84105.88000000", "0.00000000"], ["84105.95000000", "0.00000000"], ["84106.02000000", "0.00000000"], ["84106.03000000", "0.00000000"], ["84106.16000000", "0.00000000"], ["84106.17000000", "0.02981000"], ["84106.18000000", "0.00000000"], ["84106.28000000", "0.00000000"], ["84106.49000000", "0.00000000"], ["84106.71000000", "0.00000000"], ["84106.72000000", "0.00000000"], ["84106.89000000", "0.00000000"], ["84107.05000000", "0.00000000"], ["84107.12000000", "0.00000000"], ["84107.13000000", "0.02227000"], ["84107.23000000", "0.01116000"], ["84107.27000000", "0.00720000"], ["84107.36000000", "0.01166000"], ["84107.55000000", "0.00000000"], ["84107.63000000", "0.01493000"], ["84107.69000000", "0.00000000"], ["84107.80000000", "0.00000000"], ["84107.81000000", "0.06587000"], ["84107.82000000", "0.00000000"], ["84107.83000000", "0.00000000"], ["84107.84000000", "0.00000000"], ["84107.87000000", "0.00000000"], ["84107.91000000", "0.00000000"], ["84107.93000000", "0.00000000"], ["84107.94000000", "0.00000000"], ["84108.11000000", "0.00000000"], ["84108.28000000", "0.00000000"], ["84108.42000000", "0.00000000"], ["84108.45000000", "0.00000000"], ["84108.99000000", "0.00000000"], ["84109.01000000", "0.00000000"], ["84109.09000000", "0.00000000"], ["84109.15000000", "0.00000000"], ["84109.31000000", "0.00000000"], ["84109.35000000", "0.02205000"], ["84109.48000000", "0.00000000"], ["84109.57000000", "0.00000000"], ["84109.89000000", "0.10952000"], ["84110.31000000", "0.00000000"], ["84110.44000000", "0.00000000"], ["84110.48000000", "0.00000000"], ["84110.50000000", "0.00000000"], ["84110.51000000", "0.00000000"], ["84110.52000000", "0.00300000"], ["84110.55000000", "0.14449000"], ["84110.88000000", "0.00000000"], ["84111.40000000", "0.00000000"], ["84111.51000000", "0.00000000"], ["84111.68000000", "0.00000000"], ["84111.73000000", "0.00118000"], ["84111.83000000", "0.00000000"], ["84111.95000000", "0.45000000"], ["84112.10000000", "0.00000000"], ["84112.13000000", "0.00000000"], ["84112.15000000", "0.00000000"], ["84112.18000000", "0.00029000"], ["84112.19000000", "0.00000000"], ["84112.21000000", "0.31398000"], ["84112.22000000", "0.00000000"], ["84112.25000000", "0.00000000"], ["84112.29000000", "0.00000000"], ["84112.42000000", "0.01500000"], ["84112.58000000", "0.01500000"], ["84112.60000000", "0.00000000"], ["84112.64000000", "0.00000000"], ["84112.85000000", "0.00000000"], ["84112.98000000", "0.00000000"], ["84112.99000000", "0.00000000"], ["84113.26000000", "0.00000000"], ["84113.31000000", "0.00000000"], ["84113.49000000", "0.00000000"], ["84113.60000000", "0.00000000"], ["84113.66000000", "0.00000000"], ["84113.80000000", "0.00000000"], ["84113.86000000", "0.00000000"], ["84113.90000000", "0.00000000"], ["84114.23000000", "0.00000000"], ["84114.53000000", "0.00000000"], ["84114.64000000", "0.00000000"], ["84114.67000000", "0.00000000"], ["84114.70000000", "0.00000000"], ["84115.14000000", "0.00000000"], ["84115.18000000", "0.00000000"], ["84115.46000000", "0.00000000"], ["84115.60000000", "0.04400000"], ["84115.64000000", "0.00000000"], ["84115.65000000", "0.00000000"], ["84115.70000000", "0.06000000"], ["84115.80000000", "0.86500000"], ["84115.94000000", "0.00000000"], ["84115.95000000", "0.32213000"], ["84115.96000000", "0.00000000"], ["84116.14000000", "0.11791000"], ["84116.59000000", "0.06800000"], ["84116.84000000", "0.00000000"], ["84116.86000000", "0.17899000"], ["84117.24000000", "0.00097000"], ["84117.38000000", "0.00000000"], ["84117.57000000", "0.16344000"], ["84117.70000000", "0.00000000"], ["84117.81000000", "0.00118000"], ["84117.96000000", "0.00000000"], ["84118.09000000", "0.04400000"], ["84118.26000000", "0.00000000"], ["84118.55000000", "0.35662000"], ["84118.74000000", "0.04800000"], ["84118.93000000", "0.00300000"], ["84118.96000000", "0.00091000"], ["84119.07000000", "0.01833000"], ["84119.16000000", "0.00000000"], ["84119.17000000", "0.00000000"], ["84119.45000000", "0.00673000"], ["84119.52000000", "0.00007000"], ["84119.59000000", "0.00000000"], ["84119.65000000", "0.00000000"], ["84119.92000000", "0.00000000"], ["84120.07000000", "0.00000000"], ["84120.21000000", "0.01725000"], ["84120.24000000", "0.00000000"], ["84120.26000000", "0.00013000"], ["84120.32000000", "0.00000000"], ["84120.51000000", "0.00000000"], ["84120.79000000", "0.14160000"], ["84120.80000000", "0.06000000"], ["84120.93000000", "0.00000000"], ["84121.04000000", "0.00000000"], ["84121.05000000", "0.00000000"], ["84121.06000000", "0.00000000"], ["84121.12000000", "1.24247000"], ["84121.13000000", "0.00000000"], ["84121.19000000", "0.00000000"], ["84121.76000000", "0.00000000"], ["84121.81000000", "0.00758000"], ["84121.87000000", "0.00000000"], ["84121.88000000", "0.00000000"], ["84122.05000000", "0.05600000"], ["84122.24000000", "0.00000000"], ["84122.91000000", "0.00000000"], ["84122.94000000", "0.12000000"], ["84123.14000000", "0.05600000"], ["84123.26000000", "0.00000000"], ["84123.32000000", "1.35724000"], ["84123.84000000", "0.59437000"], ["84124.07000000", "0.16000000"], ["84124.12000000", "0.00000000"], ["84124.43000000", "0.00000000"], ["84124.49000000", "0.00000000"], ["84124.78000000", "0.00000000"], ["84124.80000000", "0.00000000"], ["84125.07000000", "0.49758000"], ["84125.71000000", "0.89155000"], ["84125.72000000", "0.16637000"], ["84125.83000000", "0.00000000"], ["84126.54000000", "0.00007000"], ["84126.69000000", "0.00507000"], ["84126.76000000", "0.00000000"], ["84127.09000000", "0.89155000"], ["84127.11000000", "0.00000000"], ["84127.26000000", "0.38952000"], ["84127.31000000", "0.00000000"], ["84127.72000000", "0.00000000"], ["84127.94000000", "0.00000000"], ["84128.55000000", "0.30902000"], ["84128.62000000", "0.00151000"], ["84128.76000000", "0.05943000"], ["84129.17000000", "0.00000000"], ["84129.32000000", "0.00000000"], ["84129.48000000", "0.00237000"], ["84130.62000000", "0.91828000"], ["84130.86000000", "0.05943000"], ["84131.43000000", "0.89155000"], ["84131.82000000", "0.00000000"], ["84131.84000000", "0.00000000"], ["84132.04000000", "0.89155000"], ["84132.31000000", "0.00000000"], ["84132.32000000", "0.00000000"], ["84132.41000000", "0.30891000"], ["84132.57000000", "0.00000000"], ["84132.60000000", "0.03077000"], ["84132.68000000", "0.00000000"], ["84133.52000000", "0.93687000"], ["84133.54000000", "0.00000000"], ["84133.58000000", "0.00000000"], ["84133.65000000", "0.00000000"], ["84133.66000000", "0.01916000"], ["84133.67000000", "0.00000000"], ["84134.22000000", "0.00000000"], ["84134.67000000", "0.00000000"], ["84134.93000000", "0.89155000"], ["84135.24000000", "0.89155000"], ["84135.56000000", "0.89155000"], ["84135.86000000", "0.00000000"], ["84136.22000000", "0.00000000"], ["84136.32000000", "0.00000000"], ["84136.60000000", "0.00000000"], ["84137.02000000", "0.00000000"], ["84137.59000000", "0.00000000"], ["84137.66000000", "0.84866000"], ["84138.09000000", "0.00000000"], ["84139.60000000", "0.00000000"], ["84139.67000000", "0.00000000"], ["84140.19000000", "0.00000000"], ["84140.36000000", "0.00356000"], ["84140.66000000", "0.00016000"], ["84140.82000000", "0.06400000"], ["84141.28000000", "0.00000000"], ["84141.30000000", "0.00000000"], ["84141.31000000", "0.00000000"], ["84141.32000000", "0.63824000"], ["84141.36000000", "0.00000000"], ["84141.50000000", "0.00000000"], ["84141.63000000", "0.12162000"], ["84141.88000000", "0.85610000"], ["84142.23000000", "0.03676000"], ["84142.57000000", "0.00000000"], ["84142.83000000", "0.00000000"], ["84142.84000000", "0.00000000"], ["84143.16000000", "0.00000000"], ["84143.41000000", "0.00000000"], ["84143.68000000", "0.00059000"], ["84144.91000000", "0.00000000"], ["84145.01000000", "0.00000000"], ["84146.22000000", "0.08354000"], ["84146.23000000", "1.33118000"], ["84146.26000000", "0.85606000"], ["84146.46000000", "0.05844000"], ["84146.99000000", "0.35788000"], ["84147.02000000", "0.00000000"], ["84147.47000000", "0.02814000"], ["84148.86000000", "0.00581000"], ["84148.87000000", "0.22951000"], ["84149.23000000", "0.00009000"], ["84149.67000000", "0.00000000"], ["84149.98000000", "0.00000000"], ["84151.43000000", "0.00000000"], ["84152.34000000", "0.39281000"], ["84152.36000000", "0.00000000"], ["84152.95000000", "0.00000000"], ["84152.99000000", "0.00000000"], ["84153.63000000", "0.00000000"], ["84154.28000000", "0.00809000"], ["84155.40000000", "0.00006000"], ["84157.18000000", "0.59466000"], ["84158.82000000", "0.00000000"], ["84158.83000000", "0.19926000"], ["84159.02000000", "0.00000000"], ["84160.23000000", "0.00000000"], ["84160.34000000", "0.00000000"], ["84161.98000000", "0.04371000"], ["84162.12000000", "0.00000000"], ["84162.34000000", "0.01196000"], ["84162.48000000", "0.00845000"], ["84162.90000000", "0.00000000"], ["84163.39000000", "0.00000000"], ["84164.30000000", "0.00000000"], ["84164.41000000", "0.00000000"], ["84164.96000000", "0.00000000"], ["84165.05000000", "0.00000000"], ["84165.18000000", "0.00000000"], ["84165.65000000", "0.05382000"], ["84165.98000000", "0.00000000"], ["84166.40000000", "0.00000000"], ["84166.46000000", "0.04651000"], ["84167.13000000", "0.80709000"], ["84167.49000000", "0.00000000"], ["84167.57000000", "0.00000000"], ["84167.98000000", "0.00000000"], ["84168.25000000", "0.01152000"], ["84168.48000000", "0.47549000"], ["84168.71000000", "0.01156000"], ["84168.73000000", "0.00000000"], ["84168.79000000", "0.00000000"], ["84169.04000000", "0.00000000"], ["84169.20000000", "0.00297000"], ["84170.89000000", "0.63630000"], ["84171.16000000", "0.00000000"], ["84171.76000000", "0.00000000"], ["84171.77000000", "0.00000000"], ["84171.95000000", "0.00000000"], ["84172.06000000", "0.00599000"], ["84172.14000000", "0.00599000"], ["84172.25000000", "0.00599000"], ["84172.38000000", "0.03971000"], ["84172.66000000", "0.00000000"], ["84174.03000000", "0.00000000"], ["84174.04000000", "0.05600000"], ["84174.70000000", "1.02644000"], ["84175.47000000", "0.00000000"], ["84175.74000000", "0.00000000"], ["84176.32000000", "0.00000000"], ["84180.35000000", "0.00000000"], ["84180.95000000", "0.00019000"], ["84180.96000000", "0.00864000"], ["84181.18000000", "0.00000000"], ["84181.19000000", "0.04400000"], ["84181.79000000", "0.00000000"], ["84182.04000000", "0.00000000"], ["84182.48000000", "0.00297000"], ["84183.34000000", "0.00151000"], ["84183.97000000", "0.00000000"], ["84184.28000000", "0.00000000"], ["84184.58000000", "0.00144000"], ["84185.13000000", "0.00000000"], ["84185.39000000", "0.00000000"], ["84186.23000000", "0.00000000"], ["84186.62000000", "0.05097000"], ["84187.15000000", "0.00000000"], ["84188.18000000", "0.00000000"], ["84188.21000000", "0.03201000"], ["84188.58000000", "0.00000000"], ["84189.15000000", "0.00000000"], ["84189.81000000", "0.00000000"], ["84189.84000000", "0.00000000"], ["84190.98000000", "0.00000000"], ["84191.49000000", "0.00000000"], ["84191.94000000", "0.04756000"], ["84192.05000000", "0.92970000"], ["84192.33000000", "0.00000000"], ["84192.41000000", "0.00000000"], ["84192.51000000", "0.00000000"], ["84192.63000000", "0.05275000"], ["84192.91000000", "0.00000000"], ["84192.99000000", "0.04637000"], ["84193.24000000", "0.00000000"], ["84193.29000000", "0.00000000"], ["84193.41000000", "0.04756000"], ["84193.48000000", "0.00000000"], ["84194.04000000", "0.00000000"], ["84194.10000000", "0.00000000"], ["84194.53000000", "0.00000000"], ["84194.60000000", "0.00000000"], ["84194.96000000", "0.00000000"], ["84195.03000000", "0.00000000"], ["84195.57000000", "0.04637000"], ["84195.74000000", "0.00000000"], ["84195.92000000", "0.00000000"], ["84196.01000000", "0.00000000"], ["84196.03000000", "0.04756000"], ["84196.11000000", "0.00000000"], ["84196.43000000", "0.00059000"], ["84196.78000000", "0.04637000"], ["84196.89000000", "0.00000000"], ["84197.15000000", "0.00000000"], ["84197.46000000", "0.00000000"], ["84197.49000000", "0.09621000"], ["84197.67000000", "0.04637000"], ["84198.15000000", "0.04637000"], ["84198.21000000", "0.04756000"], ["84198.79000000", "0.00000000"], ["84198.95000000", "0.00000000"], ["84198.97000000", "0.00000000"], ["84199.60000000", "0.00000000"], ["84200.17000000", "0.04637000"], ["84200.19000000", "0.04637000"], ["84200.21000000", "0.00000000"], ["84200.37000000", "0.00000000"], ["84200.38000000", "0.04756000"], ["84200.59000000", "0.44877000"], ["84201.09000000", "0.00000000"], ["84201.54000000", "0.04637000"], ["84201.61000000", "0.00000000"], ["84201.67000000", "0.04756000"], ["84201.74000000", "0.00000000"], ["84202.39000000", "0.00000000"], ["84202.43000000", "0.00000000"], ["84202.45000000", "0.04637000"], ["84202.82000000", "0.00000000"], ["84202.88000000", "0.00000000"], ["84203.15000000", "0.04756000"], ["84203.18000000", "0.04637000"], ["84203.69000000", "0.09512000"], ["84203.91000000", "0.04637000"], ["84204.14000000", "0.00000000"], ["84204.15000000", "0.00000000"], ["84204.40000000", "0.00000000"], ["84204.45000000", "0.04763000"], ["84205.14000000", "0.04637000"], ["84205.99000000", "0.04637000"], ["84206.49000000", "0.04756000"], ["84206.69000000", "0.04637000"], ["84206.73000000", "0.06719000"], ["84207.70000000", "0.44663000"], ["84207.82000000", "0.04756000"], ["84208.74000000", "0.05297000"], ["84208.82000000", "0.04637000"], ["84208.98000000", "0.00716000"], ["84209.43000000", "0.04756000"], ["84209.45000000", "0.04756000"], ["84210.64000000", "0.04650000"], ["84210.74000000", "0.17866000"], ["84211.66000000", "0.05497000"], ["84211.94000000", "1.19224000"], ["84212.85000000", "0.10294000"], ["84213.26000000", "0.00013000"], ["84213.35000000", "0.00000000"], ["84213.72000000", "0.00000000"], ["84214.06000000", "0.11613000"], ["84215.46000000", "0.05497000"], ["84215.65000000", "0.05497000"], ["84215.82000000", "0.05497000"], ["84215.97000000", "0.05497000"], ["84216.30000000", "0.10794000"], ["84217.79000000", "0.00000000"], ["84218.31000000", "0.05497000"], ["84218.71000000", "0.05297000"], ["84218.93000000", "0.10495000"], ["84218.94000000", "0.05497000"], ["84219.06000000", "0.05497000"], ["84219.27000000", "0.05497000"], ["84219.60000000", "0.05497000"], ["84221.05000000", "0.10395000"], ["84221.77000000", "0.05972000"], ["84222.22000000", "0.05504000"], ["84223.49000000", "0.05297000"], ["84223.88000000", "0.05098000"], ["84224.31000000", "0.05297000"], ["84224.76000000", "0.05497000"], ["84224.80000000", "0.04997000"], ["84225.10000000", "0.10494000"], ["84225.35000000", "0.05497000"], ["84226.32000000", "0.05297000"], ["84226.43000000", "0.10594000"], ["84226.81000000", "0.05297000"], ["84227.09000000", "0.05297000"], ["84227.90000000", "0.04997000"], ["84227.99000000", "0.04997000"], ["84228.68000000", "0.00000000"], ["84228.74000000", "0.00000000"], ["84228.96000000", "0.04998000"], ["84231.64000000", "0.05497000"], ["84232.67000000", "0.00000000"], ["84233.01000000", "0.00000000"], ["84233.38000000", "0.00000000"], ["84234.53000000", "0.00000000"], ["84235.27000000", "0.00006000"], ["84235.57000000", "0.00864000"], ["84235.64000000", "0.01055000"], ["84235.92000000", "0.05297000"], ["84236.03000000", "0.04498000"], ["84238.39000000", "0.02099000"], ["84239.04000000", "0.05297000"], ["84239.10000000", "0.02435000"], ["84242.99000000", "0.04998000"], ["84245.38000000", "0.00006000"], ["84247.84000000", "0.04198000"], ["84248.15000000", "0.04198000"], ["84249.76000000", "0.00000000"], ["84253.11000000", "0.00000000"], ["84255.49000000", "0.00006000"], ["84256.00000000", "0.00353000"], ["84266.45000000", "0.00000000"], ["84267.55000000", "0.00000000"], ["84270.37000000", "0.00016000"], ["84270.38000000", "0.01859000"], ["84270.43000000", "0.01152000"], ["84272.76000000", "0.00000000"], ["84279.89000000", "0.00000000"], ["84285.63000000", "0.99290000"], ["84315.38000000", "0.00118000"], ["84330.54000000", "0.00013000"], ["84334.74000000", "0.00013000"], ["84339.91000000", "0.00013000"], ["84344.11000000", "0.00013000"], ["84346.76000000", "0.00013000"], ["84349.23000000", "0.00013000"], ["84353.43000000", "0.00013000"], ["84358.81000000", "0.00000000"], ["84358.82000000", "0.00000000"], ["84370.35000000", "0.20148000"], ["84375.13000000", "0.45000000"], ["84383.55000000", "0.45000000"], ["84384.40000000", "0.20148000"], ["84392.80000000", "0.00200000"], ["84420.00000000", "0.03370000"], ["84739.20000000", "0.00006000"], ["85188.26000000", "0.00000000"], ["85308.00000000", "0.00000000"], ["85342.65000000", "0.00000000"], ["85370.40000000", "0.13197000"], ["85404.30000000", "0.00000000"], ["85413.00000000", "0.00036000"], ["85568.79000000", "0.00060000"], ["85665.41000000", "0.00060000"]], "record_time": 1742584895.130026, "EXCHANGE": "BINANCE"}
{"e": "depthUpdate", "E": 1742584896014, "s": "BTCUSDT", "U": 64637887526, "u": 64637888030, "b": [["84103.52000000", "5.14832000"], ["84103.35000000", "0.00007000"], ["84102.87000000", "0.00021000"], ["84102.86000000", "0.04020000"], ["84102.52000000", "0.00000000"], ["84102.50000000", "0.00007000"], ["84102.47000000", "0.00014000"], ["84102.02000000", "0.90276000"], ["84101.99000000", "2.23316000"], ["84100.87000000", "0.16286000"], ["84100.80000000", "0.05353000"], ["84100.59000000", "0.00000000"], ["84100.39000000", "0.04000000"], ["84099.61000000", "0.00000000"], ["84098.06000000", "0.28915000"], ["84098.03000000", "0.00000000"], ["84097.88000000", "0.00000000"], ["84096.96000000", "0.00000000"], ["84096.74000000", "0.45079000"], ["84095.96000000", "0.03578000"], ["84095.91000000", "0.04000000"], ["84095.10000000", "0.00300000"], ["84094.89000000", "0.03578000"], ["84094.49000000", "0.00000000"], ["84093.89000000", "0.00006000"], ["84093.67000000", "0.02532000"], ["84093.24000000", "0.00000000"], ["84092.87000000", "0.00000000"], ["84091.48000000", "0.03360000"], ["84090.63000000", "0.00000000"], ["84089.41000000", "0.76591000"], ["84089.38000000", "0.00000000"], ["84088.89000000", "0.00000000"], ["84088.84000000", "0.00006000"], ["84086.70000000", "0.00059000"], ["84086.45000000", "0.00000000"], ["84085.61000000", "1.04013000"], ["84085.59000000", "0.00000000"], ["84084.74000000", "0.00000000"], ["84083.27000000", "0.68083000"], ["84083.05000000", "0.05916000"], ["84082.39000000", "1.39282000"], ["84081.78000000", "0.04000000"], ["84080.82000000", "0.59474000"], ["84079.33000000", "0.04000000"], ["84079.17000000", "0.00000000"], ["84077.80000000", "0.95180000"], ["84076.85000000", "0.00000000"], ["84074.09000000", "0.85679000"], ["84073.80000000", "0.00000000"], ["84072.83000000", "1.25980000"], ["84072.80000000", "0.00500000"], ["84065.16000000", "0.00000000"], ["84064.06000000", "0.09000000"], ["84057.36000000", "0.00000000"], ["84048.55000000", "0.00000000"], ["84037.98000000", "0.04000000"], ["84025.70000000", "0.00000000"], ["84020.00000000", "0.00327000"], ["84019.00000000", "0.00000000"], ["84012.14000000", "0.01196000"], ["83996.54000000", "0.00000000"], ["83989.26000000", "0.89925000"], ["83988.73000000", "0.00000000"], ["83983.92000000", "0.69789000"], ["83983.02000000", "0.00400000"], ["83982.07000000", "0.00000000"], ["83980.36000000", "0.02286000"], ["83980.35000000", "0.06039000"], ["83979.99000000", "0.14785000"], ["83979.75000000", "0.12083000"], ["83975.29000000", "0.00000000"], ["83952.78000000", "0.00000000"], ["83946.72000000", "0.01000000"], ["83940.91000000", "0.00000000"], ["83920.59000000", "0.99313000"], ["83865.39000000", "0.00009000"], ["83861.19000000", "0.00000000"], ["83857.29000000", "0.00000000"], ["83853.09000000", "0.00000000"], ["83847.44000000", "0.00060000"], ["83847.43000000", "0.00000000"], ["83740.13000000", "0.00060000"], ["83740.12000000", "0.00000000"], ["83736.93000000", "0.00040000"], ["83736.89000000", "0.00000000"], ["83161.69000000", "0.00000000"], ["83152.49000000", "0.40000000"], ["83084.28000000", "0.00040000"], ["83084.16000000", "0.00000000"], ["82832.28000000", "0.00000000"], ["76700.00000000", "8.04588000"], ["75693.00000000", "0.00000000"], ["75692.00000000", "0.06625000"], ["67282.82000000", "0.00058000"], ["60000.00000000", "73.01903000"], ["33000.00000000", "2.93827000"], ["30277.27000000", "0.00040000"]], "a": [["84103.53000000", "1.60698000"], ["84103.54000000", "0.14033000"], ["84103.55000000", "0.09383000"], ["84103.64000000", "0.00007000"], ["84103.65000000", "0.00007000"], ["84103.66000000", "0.00007000"], ["84103.67000000", "0.00048000"], ["84103.68000000", "0.13759000"], ["84103.82000000", "0.00000000"], ["84103.83000000", "0.00382000"], ["84103.93000000", "0.00000000"], ["84103.97000000", "0.00202000"], ["84104.18000000", "0.00000000"], ["84104.25000000", "0.00000000"], ["84104.46000000", "0.00000000"], ["84104.66000000", "0.00000000"], ["84104.67000000", "0.00000000"], ["84104.68000000", "0.00000000"], ["84104.69000000", "0.00000000"], ["84104.98000000", "0.00000000"], ["84104.99000000", "0.00000000"], ["84105.02000000", "0.00308000"], ["84105.32000000", "0.00022000"], ["84105.33000000", "0.00006000"], ["84105.35000000", "0.02425000"], ["84105.40000000", "0.02205000"], ["84105.87000000", "0.00007000"], ["84106.17000000", "0.02974000"], ["84106.70000000", "0.00000000"], ["84106.71000000", "0.00000000"], ["84107.13000000", "0.02227000"], ["84107.81000000", "0.00000000"], ["84109.20000000", "0.02345000"], ["84109.35000000", "0.00000000"], ["84109.65000000", "0.00008000"], ["84110.52000000", "0.00000000"], ["84111.94000000", "0.22478000"], ["84112.21000000", "0.00000000"], ["84113.74000000", "0.00000000"], ["84115.68000000", "0.01361000"], ["84115.80000000", "0.08000000"], ["84116.94000000", "0.00851000"], ["84117.13000000", "0.03313000"], ["84117.57000000", "0.17344000"], ["84118.07000000", "0.01189000"], ["84120.35000000", "0.00059000"], ["84120.93000000", "0.02359000"], ["84125.06000000", "0.71126000"], ["84125.07000000", "0.97235000"], ["84126.58000000", "1.00000000"], ["84126.71000000", "0.01189000"], ["84127.26000000", "0.00000000"], ["84127.87000000", "0.00000000"], ["84128.76000000", "0.11886000"], ["84128.77000000", "0.00300000"], ["84129.17000000", "0.00891000"], ["84132.06000000", "0.02353000"], ["84133.52000000", "1.46769000"], ["84133.63000000", "0.85619000"], ["84134.36000000", "0.00000000"], ["84134.37000000", "0.03568000"], ["84135.67000000", "0.00000000"], ["84137.67000000", "1.56741000"], ["84140.20000000", "0.06435000"], ["84147.60000000", "0.00000000"], ["84149.75000000", "0.01010000"], ["84149.99000000", "0.27919000"], ["84151.40000000", "0.00000000"], ["84157.53000000", "0.01082000"], ["84159.00000000", "0.03971000"], ["84169.05000000", "0.06800000"], ["84172.38000000", "0.00000000"], ["84174.24000000", "0.00000000"], ["84181.19000000", "0.00000000"], ["84195.76000000", "0.00000000"], ["84196.43000000", "0.00000000"], ["84199.53000000", "0.00000000"], ["84200.84000000", "0.01598000"], ["84204.17000000", "0.01008000"], ["84204.44000000", "0.01603000"], ["84204.95000000", "0.00065000"], ["84217.99000000", "0.00904000"], ["84220.72000000", "0.01550000"], ["84220.94000000", "0.00000000"], ["84221.86000000", "0.01082000"], ["84224.47000000", "0.00000000"], ["84234.80000000", "0.01643000"], ["84242.90000000", "0.01603000"], ["84250.43000000", "0.00006000"], ["84254.01000000", "0.00000000"], ["84254.92000000", "0.00000000"], ["84262.48000000", "0.02185000"], ["84263.43000000", "0.00000000"], ["84267.30000000", "0.00480000"], ["84267.81000000", "0.00013000"], ["84271.51000000", "0.00000000"], ["84277.57000000", "0.01000000"], ["84285.63000000", "0.00000000"], ["84337.53000000", "0.00013000"], ["84349.23000000", "0.00000000"], ["84353.43000000", "0.00000000"], ["84375.58000000", "0.07460000"], ["84384.40000000", "0.00000000"], ["84392.38000000", "0.12888000"], ["84392.80000000", "0.00000000"], ["84394.44000000", "0.99294000"], ["85192.98000000", "0.60000000"], ["85365.09000000", "0.00100000"], ["85434.30000000", "0.05863000"], ["97200.00000000", "1.41536000"]], "record_time": 1742584896.127722, "EXCHANGE": "BINANCE"}
{"e": "depthUpdate", "E": 1742584897014, "s": "BTCUSDT", "U": 64637888031, "u": 64637888154, "b": [["84103.52000000", "4.55389000"], ["84102.02000000", "0.26017000"], ["84102.00000000", "0.02287000"], ["84101.99000000", "0.45006000"], ["84100.87000000", "0.16280000"], ["84100.80000000", "0.00000000"], ["84098.22000000", "0.05353000"], ["84096.60000000", "0.00006000"], ["84095.96000000", "0.00000000"], ["84095.44000000", "0.00000000"], ["84095.11000000", "0.09744000"], ["84094.89000000", "0.00000000"], ["84089.41000000", "1.22748000"], ["84089.36000000", "0.89155000"], ["84089.33000000", "0.89155000"], ["84078.30000000", "0.00059000"], ["84073.70000000", "0.00000000"], ["84069.36000000", "0.45260000"], ["84067.19000000", "0.05947000"], ["84064.64000000", "0.69181000"], ["84052.75000000", "0.00000000"], ["84050.23000000", "0.59437000"], ["83983.02000000", "0.00000000"], ["83975.55000000", "0.04757000"], ["83961.73000000", "0.00400000"], ["83776.85000000", "0.00197000"], ["83160.86000000", "0.40000000"], ["83152.49000000", "0.00000000"], ["82841.96000000", "0.00100000"], ["80730.96000000", "0.03565000"], ["75693.00000000", "0.00000000"], ["75692.00000000", "0.06625000"], ["67282.82000000", "0.00058000"], ["33000.00000000", "2.93827000"]], "a": [["84103.53000000", "1.70804000"], ["84109.76000000", "0.39090000"], ["84109.77000000", "0.78506000"], ["84109.89000000", "0.00000000"], ["84111.63000000", "0.22922000"], ["84111.64000000", "0.00000000"], ["84111.94000000", "0.00000000"], ["84121.81000000", "0.00000000"], ["84123.72000000", "0.00754000"], ["84123.88000000", "0.12741000"], ["84124.50000000", "1.15556000"], ["84124.51000000", "0.00000000"], ["84125.07000000", "0.00000000"], ["84125.78000000", "1.00000000"], ["84126.58000000", "0.00000000"], ["84128.06000000", "0.00000000"], ["84128.76000000", "0.11945000"], ["84136.50000000", "0.00000000"], ["84147.90000000", "0.59473000"], ["84157.18000000", "0.00000000"], ["84161.28000000", "0.00000000"], ["84169.28000000", "0.00000000"], ["84191.77000000", "0.00000000"], ["84200.60000000", "0.00000000"], ["84202.81000000", "0.00059000"], ["84208.30000000", "0.00979000"], ["84223.95000000", "0.00000000"], ["84226.64000000", "0.05497000"], ["84229.45000000", "0.00000000"], ["84236.46000000", "0.00000000"], ["84257.54000000", "0.00000000"], ["84268.40000000", "0.02558000"], ["84271.09000000", "0.00000000"], ["84275.67000000", "0.00000000"], ["84276.11000000", "0.02515000"], ["84288.16000000", "0.00000000"], ["84288.91000000", "0.00013000"], ["84462.00000000", "0.15445000"], ["84772.80000000", "0.05953000"], ["85192.98000000", "0.00000000"], ["85201.42000000", "0.60000000"], ["85365.09000000", "0.00000000"]], "record_time": 1742584897.127322, "EXCHANGE": "BINANCE"}
{"e": "depthUpdate", "E": 1742584898014, "s": "BTCUSDT", "U": 64637888155, "u": 64637888239, "b": [["84093.70000000", "0.00000000"], ["84075.47000000", "0.07354000"], ["84072.80000000", "0.00000000"], ["84028.30000000", "0.00000000"], ["84012.82000000", "0.63079000"], ["83989.59000000", "0.00083000"], ["83979.75000000", "0.12000000"], ["83976.82000000", "0.01861000"], ["83935.38000000", "0.00000000"], ["83921.57000000", "0.00000000"], ["83920.60000000", "0.00835000"], ["83912.01000000", "0.00069000"], ["83900.02000000", "0.00000000"], ["83776.85000000", "0.00000000"], ["82841.96000000", "0.00000000"], ["82573.26000000", "0.01749000"], ["76700.00000000", "8.04094000"], ["75693.00000000", "0.00000000"], ["75692.00000000", "0.06625000"], ["67282.82000000", "0.00058000"], ["33000.00000000", "2.93827000"], ["30277.27000000", "0.00100000"]], "a": [["84103.53000000", "1.61799000"], ["84107.70000000", "0.00500000"], ["84108.70000000", "0.08126000"], ["84109.20000000", "0.00006000"], ["84110.25000000", "0.00000000"], ["84120.12000000", "0.08354000"], ["84120.40000000", "0.00759000"], ["84123.72000000", "0.00000000"], ["84124.25000000", "0.01695000"], ["84124.30000000", "0.00377000"], ["84124.75000000", "0.02105000"], ["84128.76000000", "0.12729000"], ["84129.17000000", "0.00000000"], ["84132.42000000", "0.01861000"], ["84144.91000000", "0.01959000"], ["84149.78000000", "0.00000000"], ["84156.51000000", "0.00000000"], ["84162.09000000", "0.00990000"], ["84171.22000000", "0.02105000"], ["84174.55000000", "0.00000000"], ["84176.14000000", "0.00000000"], ["84178.99000000", "0.00000000"], ["84186.73000000", "0.01343000"], ["84194.73000000", "0.00000000"], ["84199.99000000", "0.17899000"], ["84209.45000000", "0.05927000"], ["84211.97000000", "0.00406000"], ["84213.00000000", "0.02257000"], ["84237.42000000", "0.00927000"], ["84242.90000000", "0.02267000"], ["84245.17000000", "0.00000000"], ["84250.22000000", "0.00000000"], ["84251.26000000", "0.00000000"], ["84253.50000000", "0.04198000"], ["84257.61000000", "0.00000000"], ["84262.14000000", "0.00000000"], ["84262.52000000", "0.00495000"], ["84262.77000000", "0.01979000"], ["84270.68000000", "0.00000000"], ["84274.62000000", "0.00000000"], ["84284.75000000", "0.00000000"], ["84288.20000000", "0.00000000"], ["85365.09000000", "0.00100000"]], "record_time": 1742584898.126573, "EXCHANGE": "BINANCE"}
{"e": "depthUpdate", "E": 1742584899014, "s": "BTCUSDT", "U": 64637888240, "u": 64637888340, "b": [["84103.52000000", "4.55367000"], ["84101.61000000", "0.04307000"], ["84100.87000000", "0.00000000"], ["84094.31000000", "0.16280000"], ["84089.11000000", "0.03567000"], ["84073.80000000", "0.00000000"], ["84064.50000000", "0.12168000"], ["84063.70000000", "0.00000000"], ["84058.09000000", "0.10134000"], ["84053.69000000", "0.00000000"], ["84051.18000000", "0.00000000"], ["84035.41000000", "0.02854000"], ["84007.99000000", "0.00000000"], ["83961.73000000", "0.00000000"], ["83956.41000000", "0.00400000"], ["82841.96000000", "0.00100000"], ["80000.00000000", "163.26373000"], ["75693.00000000", "0.00000000"], ["75692.00000000", "0.06625000"], ["67282.82000000", "0.00058000"], ["33000.00000000", "2.93827000"], ["30277.27000000", "0.00120000"]], "a": [["84103.53000000", "2.07381000"], ["84106.40000000", "0.00000000"], ["84107.70000000", "0.00500000"], ["84110.25000000", "0.00752000"], ["84116.25000000", "0.01341000"], ["84116.50000000", "0.00400000"], ["84119.35000000", "0.02581000"], ["84120.37000000", "0.01026000"], ["84121.83000000", "0.00000000"], ["84123.36000000", "0.01325000"], ["84125.78000000", "0.00000000"], ["84126.08000000", "1.00000000"], ["84126.18000000", "0.00000000"], ["84128.38000000", "0.01833000"], ["84128.81000000", "0.01067000"], ["84131.36000000", "0.00000000"], ["84136.71000000", "0.01370000"], ["84137.83000000", "0.00000000"], ["84147.98000000", "0.00000000"], ["84148.48000000", "0.00000000"], ["84162.84000000", "0.01648000"], ["84177.99000000", "0.00000000"], ["84187.59000000", "0.00807000"], ["84189.98000000", "0.00000000"], ["84193.20000000", "0.05503000"], ["84196.19000000", "0.02334000"], ["84196.70000000", "0.00455000"], ["84199.91000000", "0.05497000"], ["84207.60000000", "0.00000000"], ["84216.27000000", "0.01556000"], ["84224.55000000", "0.00762000"], ["84230.65000000", "0.04498000"], ["84232.70000000", "0.00000000"], ["84234.01000000", "0.00495000"], ["84234.42000000", "0.00000000"], ["84234.73000000", "0.04498000"], ["84238.09000000", "0.00000000"], ["84240.75000000", "0.05894000"], ["84241.31000000", "0.00000000"], ["84247.30000000", "0.02334000"], ["84255.15000000", "0.00000000"], ["84258.06000000", "0.01556000"], ["84259.90000000", "0.01833000"], ["84265.80000000", "0.00000000"], ["84276.06000000", "0.00852000"], ["85365.09000000", "0.00000000"]], "record_time": 1742584899.127385, "EXCHANGE": "BINANCE"}
{"e": "depthUpdate", "E": 1742584900014, "s": "BTCUSDT", "U": 64637888341, "u": 64637888466, "b": [["84103.52000000", "4.55412000"], ["84089.42000000", "0.00307000"], ["84089.31000000", "0.00000000"], ["84086.01000000", "0.59472000"], ["84082.00000000", "0.02260000"], ["84080.82000000", "0.00000000"], ["84072.80000000", "0.00500000"], ["84071.90000000", "0.00300000"], ["84070.44000000", "0.12294000"], ["84068.34000000", "0.00000000"], ["84064.50000000", "0.00000000"], ["84058.05000000", "0.04628000"], ["83966.38000000", "0.05947000"], ["83963.52000000", "0.00000000"], ["83956.41000000", "0.00000000"], ["83955.94000000", "0.00400000"], ["83949.60000000", "0.00006000"], ["83914.29000000", "0.00011000"], ["83790.62000000", "0.00000000"], ["83664.46000000", "0.00000000"], ["83661.98000000", "0.00011000"], ["82841.96000000", "0.00000000"], ["76700.00000000", "8.04270000"], ["75693.00000000", "0.00000000"], ["75692.00000000", "0.06625000"], ["67282.82000000", "0.00058000"], ["33000.00000000", "2.93827000"], ["30277.27000000", "0.00140000"], ["20002.00000000", "0.00000000"], ["20001.00000000", "0.02099000"]], "a": [["84103.53000000", "1.90046000"], ["84103.55000000", "0.33199000"], ["84103.67000000", "0.00034000"], ["84106.30000000", "0.00000000"], ["84107.70000000", "0.00000000"], ["84110.25000000", "0.00000000"], ["84113.40000000", "0.02405000"], ["84116.40000000", "0.00000000"], ["84116.50000000", "0.00000000"], ["84117.13000000", "0.03367000"], ["84120.93000000", "0.02332000"], ["84124.50000000", "0.86143000"], ["84124.71000000", "0.00000000"], ["84125.99000000", "1.00000000"], ["84126.05000000", "0.00000000"], ["84126.08000000", "0.00000000"], ["84127.48000000", "0.00000000"], ["84129.17000000", "0.00878000"], ["84139.52000000", "0.00000000"], ["84140.20000000", "0.01435000"], ["84144.60000000", "0.00000000"], ["84149.48000000", "0.01454000"], ["84153.35000000", "0.00000000"], ["84161.35000000", "0.00000000"], ["84161.46000000", "0.01251000"], ["84165.99000000", "0.02320000"], ["84175.24000000", "0.00400000"], ["84189.76000000", "0.00000000"], ["84190.87000000", "0.00555000"], ["84200.88000000", "1.19224000"], ["84211.94000000", "0.00000000"], ["84220.90000000", "0.00000000"], ["84229.77000000", "0.01098000"], ["84231.52000000", "0.18320000"], ["84232.84000000", "0.00000000"], ["84236.02000000", "0.04198000"], ["84261.50000000", "0.00000000"], ["84280.09000000", "0.00555000"], ["84394.44000000", "0.00000000"], ["84396.54000000", "0.99755000"], ["84458.38000000", "0.00000000"], ["84944.55000000", "0.00000000"], ["85365.09000000", "0.00100000"]], "record_time": 1742584900.127408, "EXCHANGE": "BINANCE"}
{"e": "depthUpdate", "E": 1742584901014, "s": "BTCUSDT", "U": 64637888467, "u": 64637888596, "b": [["84103.52000000", "3.03640000"], ["84100.53000000", "0.04000000"], ["84098.91000000", "0.15674000"], ["84095.11000000", "0.05744000"], ["84094.37000000", "0.00000000"], ["84093.69000000", "0.00000000"], ["84086.78000000", "0.00000000"], ["84086.01000000", "0.00000000"], ["84080.82000000", "0.59474000"], ["84078.28000000", "0.05943000"], ["84073.56000000", "0.04000000"], ["84071.90000000", "0.00000000"], ["84065.94000000", "0.00000000"], ["84056.45000000", "0.04228000"], ["84021.64000000", "0.00000000"], ["83995.91000000", "0.01861000"], ["83979.99000000", "0.63755000"], ["83976.82000000", "0.00000000"], ["83955.94000000", "0.00000000"], ["83950.08000000", "0.05397000"], ["83946.72000000", "0.01000000"], ["83920.60000000", "0.00000000"], ["83919.69000000", "0.00835000"], ["83220.16000000", "0.00000000"], ["82841.96000000", "0.00100000"], ["75693.00000000", "0.00000000"], ["75692.00000000", "0.06625000"], ["67282.82000000", "0.00058000"], ["33000.00000000", "2.93827000"]], "a": [["84103.53000000", "2.37543000"], ["84103.68000000", "0.13759000"], ["84105.01000000", "0.00019000"], ["84105.32000000", "0.00000000"], ["84105.33000000", "0.00000000"], ["84105.34000000", "0.00000000"], ["84105.35000000", "0.00006000"], ["84105.40000000", "0.00000000"], ["84105.87000000", "0.00000000"], ["84106.17000000", "0.02981000"], ["84106.71000000", "0.00007000"], ["84107.70000000", "0.00500000"], ["84107.90000000", "0.42728000"], ["84107.91000000", "0.78508000"], ["84109.76000000", "0.00000000"], ["84109.77000000", "0.00000000"], ["84110.25000000", "0.00752000"], ["84111.01000000", "0.16652000"], ["84115.15000000", "0.01535000"], ["84117.57000000", "0.01000000"], ["84123.85000000", "0.00000000"], ["84124.18000000", "0.00000000"], ["84125.29000000", "1.00000000"], ["84125.99000000", "0.00000000"], ["84128.03000000", "0.00000000"], ["84136.79000000", "0.00000000"], ["84137.04000000", "0.00000000"], ["84137.49000000", "0.00992000"], ["84142.22000000", "0.00000000"], ["84142.46000000", "0.00000000"], ["84145.62000000", "0.01964000"], ["84159.16000000", "0.00000000"], ["84161.56000000", "0.00000000"], ["84165.06000000", "0.00000000"], ["84166.25000000", "0.01085000"], ["84170.17000000", "0.00992000"], ["84184.35000000", "0.02660000"], ["84187.91000000", "0.00000000"], ["84195.52000000", "0.00000000"], ["84208.81000000", "0.37495000"], ["84216.91000000", "0.00000000"], ["84220.38000000", "0.00745000"], ["84225.08000000", "0.01115000"], ["84228.01000000", "0.04998000"], ["84229.95000000", "0.01482000"], ["84230.59000000", "0.00786000"], ["84242.13000000", "0.00000000"], ["84242.31000000", "0.01158000"], ["84251.51000000", "0.01158000"], ["84255.93000000", "0.00603000"], ["84267.48000000", "0.00000000"], ["84271.88000000", "0.00525000"], ["84277.57000000", "0.01000000"], ["84280.07000000", "0.02018000"], ["85365.09000000", "0.00000000"], ["85634.71000000", "0.00000000"]], "record_time": 1742584901.12749, "EXCHANGE": "BINANCE"}
{"e": "depthUpdate", "E": 1742584902014, "s": "BTCUSDT", "U": 64637888597, "u": 64637888878, "b": [["84103.52000000", "2.73710000"], ["84102.46000000", "0.04007000"], ["84102.03000000", "0.00000000"], ["84102.02000000", "0.00006000"], ["84102.01000000", "0.00014000"], ["84101.99000000", "0.45013000"], ["84098.91000000", "0.00000000"], ["84098.44000000", "0.05353000"], ["84098.22000000", "0.00000000"], ["84098.06000000", "0.17232000"], ["84097.40000000", "0.00008000"], ["84096.74000000", "0.00079000"], ["84095.63000000", "0.14739000"], ["84094.31000000", "0.00000000"], ["84093.06000000", "0.15674000"], ["84089.40000000", "0.00000000"], ["84089.38000000", "0.00000000"], ["84089.11000000", "0.00000000"], ["84088.93000000", "0.00000000"], ["84088.90000000", "0.03567000"], ["84087.83000000", "0.10601000"], ["84086.85000000", "0.00000000"], ["84086.48000000", "0.16280000"], ["84079.47000000", "0.04000000"], ["84072.80000000", "0.00000000"], ["84064.06000000", "0.04000000"], ["84059.80000000", "0.05000000"], ["84055.48000000", "0.41886000"], ["84012.82000000", "0.00000000"], ["84010.87000000", "0.04637000"], ["83995.91000000", "0.00000000"], ["83989.60000000", "0.00083000"], ["83989.59000000", "0.00000000"], ["83983.90000000", "0.09935000"], ["83983.01000000", "0.00000000"], ["83970.04000000", "0.04997000"], ["83956.85000000", "0.00000000"], ["83950.08000000", "0.04997000"], ["83949.11000000", "0.00400000"], ["83946.72000000", "0.00000000"], ["83945.59000000", "0.00000000"], ["83943.92000000", "0.00000000"], ["83943.82000000", "0.00000000"], ["83943.62000000", "0.01000000"], ["83912.02000000", "0.00069000"], ["83912.01000000", "0.00000000"], ["83815.11000000", "0.00000000"], ["83438.56000000", "0.00029000"], ["83160.86000000", "0.00000000"], ["82841.96000000", "0.00000000"], ["75693.00000000", "0.00000000"], ["75692.00000000", "0.06625000"], ["67282.82000000", "0.00058000"], ["33000.00000000", "2.93827000"], ["30277.27000000", "0.00160000"], ["30237.13000000", "0.00140000"], ["30227.83000000", "0.00000000"], ["30225.93000000", "0.00040000"], ["30223.89000000", "0.00040000"], ["30220.44000000", "0.00040000"], ["30210.81000000", "0.00000000"], ["30209.33000000", "0.00060000"], ["30208.95000000", "0.00160000"], ["30208.70000000", "0.00020000"], ["30205.46000000", "0.00040000"], ["30199.48000000", "0.00020000"], ["30198.80000000", "0.00240000"], ["30195.30000000", "0.00280000"], ["30175.54000000", "0.00080000"], ["30173.30000000", "0.00240000"], ["30172.55000000", "0.00020000"], ["30172.32000000", "0.00000000"], ["30171.74000000", "0.00300000"], ["30168.00000000", "0.00140000"], ["30166.71000000", "0.00260000"], ["30165.01000000", "0.00040000"], ["30160.79000000", "0.00040000"], ["30157.84000000", "0.00120000"], ["30156.88000000", "0.00000000"], ["30151.45000000", "0.00020000"], ["30145.14000000", "0.00140000"]], "a": [["84103.53000000", "2.12206000"], ["84103.54000000", "0.16052000"], ["84103.55000000", "0.23830000"], ["84103.58000000", "0.09296000"], ["84103.63000000", "0.00007000"], ["84103.67000000", "0.00027000"], ["84103.68000000", "0.13752000"], ["84105.52000000", "0.00000000"], ["84106.17000000", "0.02974000"], ["84106.60000000", "0.00000000"], ["84107.70000000", "0.01000000"], ["84107.90000000", "0.49487000"], ["84107.91000000", "0.78508000"], ["84108.00000000", "0.14637000"], ["84108.46000000", "0.16344000"], ["84109.88000000", "0.00000000"], ["84110.25000000", "0.01188000"], ["84111.01000000", "0.00308000"], ["84111.33000000", "0.16637000"], ["84111.95000000", "0.45000000"], ["84115.25000000", "0.00000000"], ["84118.24000000", "0.71126000"], ["84118.27000000", "0.00755000"], ["84119.01000000", "0.00000000"], ["84120.40000000", "0.00000000"], ["84120.79000000", "0.00000000"], ["84124.41000000", "0.00000000"], ["84125.29000000", "0.00000000"], ["84125.72000000", "0.00000000"], ["84125.81000000", "1.00000000"], ["84126.67000000", "0.00000000"], ["84128.00000000", "0.00000000"], ["84128.09000000", "0.00000000"], ["84128.76000000", "0.12729000"], ["84129.57000000", "1.59300000"], ["84129.58000000", "0.85623000"], ["84130.62000000", "0.00000000"], ["84131.19000000", "0.00000000"], ["84136.59000000", "0.00000000"], ["84137.31000000", "0.00000000"], ["84137.34000000", "0.00000000"], ["84137.80000000", "0.01276000"], ["84140.32000000", "0.01941000"], ["84140.87000000", "0.01642000"], ["84141.51000000", "0.00000000"], ["84141.90000000", "0.05339000"], ["84144.84000000", "0.02531000"], ["84145.23000000", "0.00000000"], ["84146.26000000", "0.00000000"], ["84153.26000000", "0.00000000"], ["84165.24000000", "0.00000000"], ["84167.05000000", "0.01173000"], ["84169.91000000", "0.02118000"], ["84182.79000000", "0.00000000"], ["84183.10000000", "0.00000000"], ["84186.72000000", "0.03921000"], ["84187.43000000", "0.00000000"], ["84187.59000000", "0.02981000"], ["84196.17000000", "0.00000000"], ["84198.64000000", "0.00000000"], ["84208.98000000", "0.00000000"], ["84214.80000000", "0.00000000"], ["84215.53000000", "0.00000000"], ["84220.17000000", "0.00000000"], ["84234.83000000", "0.02330000"], ["84245.60000000", "0.01941000"], ["84249.11000000", "0.00000000"], ["84255.15000000", "0.01708000"], ["84257.58000000", "0.00000000"], ["84258.51000000", "0.00000000"], ["84263.23000000", "0.00000000"], ["85365.09000000", "0.00100000"], ["86037.72000000", "0.00029000"]], "record_time": 1742584902.127416, "EXCHANGE": "BINANCE"}
{"e": "depthUpdate", "E": 1742584903014, "s": "BTCUSDT", "U": 64637888879, "u": 64637889772, "b": [["84103.52000000", "0.73070000"], ["84103.36000000", "0.00007000"], ["84103.35000000", "0.00209000"], ["84103.32000000", "0.00007000"], ["84103.31000000", "0.00007000"], ["84103.29000000", "0.00000000"], ["84102.87000000", "0.00000000"], ["84102.86000000", "0.00000000"], ["84102.78000000", "0.00000000"], ["84102.52000000", "0.00000000"], ["84102.50000000", "0.00000000"], ["84102.47000000", "0.00000000"], ["84102.46000000", "0.00000000"], ["84102.02000000", "0.00000000"], ["84102.01000000", "0.00023000"], ["84102.00000000", "0.02273000"], ["84101.99000000", "0.00000000"], ["84101.95000000", "0.00014000"], ["84101.94000000", "0.17285000"], ["84101.85000000", "0.00000000"], ["84101.74000000", "0.00000000"], ["84101.65000000", "0.00000000"], ["84101.64000000", "0.00000000"], ["84101.63000000", "0.00000000"], ["84101.62000000", "0.00000000"], ["84101.61000000", "0.00000000"], ["84101.43000000", "0.00014000"], ["84101.42000000", "0.30690000"], ["84101.09000000", "0.00000000"], ["84100.54000000", "0.00000000"], ["84100.53000000", "0.00000000"], ["84100.44000000", "0.00000000"], ["84100.39000000", "0.00000000"], ["84100.14000000", "0.00000000"], ["84100.13000000", "0.00006000"], ["84100.12000000", "0.00000000"], ["84100.01000000", "0.00000000"], ["84100.00000000", "0.02273000"], ["84099.99000000", "0.00000000"], ["84099.98000000", "0.00006000"], ["84099.93000000", "0.00000000"], ["84099.92000000", "0.02538000"], ["84099.68000000", "0.00000000"], ["84099.67000000", "0.07282000"], ["84099.63000000", "0.78516000"], ["84099.56000000", "0.00000000"], ["84099.18000000", "0.00000000"], ["84099.04000000", "0.00000000"], ["84099.03000000", "0.00000000"], ["84098.54000000", "0.00000000"], ["84098.53000000", "0.06417000"], ["84098.44000000", "0.00000000"], ["84098.42000000", "0.00000000"], ["84098.06000000", "0.00000000"], ["84098.04000000", "0.00000000"], ["84097.97000000", "0.00000000"], ["84097.96000000", "0.00000000"], ["84097.50000000", "0.00000000"], ["84097.42000000", "0.00000000"], ["84097.41000000", "0.00000000"], ["84096.94000000", "0.00000000"], ["84096.74000000", "0.00000000"], ["84096.60000000", "0.00000000"], ["84095.91000000", "0.00000000"], ["84095.86000000", "0.00000000"], ["84095.67000000", "0.00000000"], ["84095.63000000", "0.00000000"], ["84095.18000000", "0.04000000"], ["84095.13000000", "0.00000000"], ["84095.04000000", "0.00000000"], ["84094.21000000", "0.00000000"], ["84094.05000000", "0.00000000"], ["84094.01000000", "0.00118000"], ["84093.67000000", "0.02351000"], ["84093.60000000", "0.00000000"], ["84093.24000000", "0.11078000"], ["84093.23000000", "0.04000000"], ["84093.06000000", "0.00000000"], ["84093.01000000", "0.00000000"], ["84092.94000000", "0.02000000"], ["84092.73000000", "0.12000000"], ["84092.40000000", "0.00000000"], ["84092.39000000", "0.04000000"], ["84092.32000000", "0.00095000"], ["84091.81000000", "0.00000000"], ["84091.55000000", "0.04000000"], ["84091.54000000", "0.04000000"], ["84091.51000000", "0.00000000"], ["84091.13000000", "0.00000000"], ["84090.78000000", "0.00000000"], ["84090.51000000", "0.00000000"], ["84090.37000000", "0.05353000"], ["84090.09000000", "0.00013000"], ["84090.00000000", "0.49817000"], ["84089.51000000", "0.00000000"], ["84089.49000000", "0.00939000"], ["84089.41000000", "0.00000000"], ["84089.37000000", "0.00000000"], ["84089.36000000", "0.00000000"], ["84089.33000000", "0.00000000"], ["84089.02000000", "0.04000000"], ["84088.90000000", "0.00000000"], ["84088.89000000", "0.14739000"], ["84088.61000000", "0.04000000"], ["84088.42000000", "0.00000000"], ["84088.32000000", "0.00000000"], ["84088.31000000", "0.01000000"], ["84088.19000000", "0.04000000"], ["84088.11000000", "0.02000000"], ["84087.98000000", "0.00000000"], ["84087.83000000", "0.00000000"], ["84087.80000000", "0.15674000"], ["84087.79000000", "0.01878000"], ["84087.37000000", "0.00000000"], ["84087.35000000", "0.04000000"], ["84087.34000000", "0.04000000"], ["84087.28000000", "0.04000000"], ["84087.10000000", "0.00091000"], ["84086.68000000", "0.45000000"], ["84086.52000000", "0.00000000"], ["84085.61000000", "0.09638000"], ["84085.44000000", "0.16000000"], ["84085.38000000", "0.00000000"], ["84084.80000000", "0.00000000"], ["84084.55000000", "0.00000000"], ["84084.49000000", "0.00000000"], ["84084.38000000", "0.00000000"], ["84084.36000000", "0.00000000"], ["84084.34000000", "0.03568000"], ["84084.23000000", "0.00000000"], ["84083.27000000", "0.00000000"], ["84083.05000000", "0.00000000"], ["84082.98000000", "0.00000000"], ["84082.97000000", "0.00000000"], ["84082.96000000", "0.00000000"], ["84082.39000000", "0.00000000"], ["84082.16000000", "0.10601000"], ["84081.78000000", "0.00000000"], ["84081.42000000", "0.00090000"], ["84081.31000000", "0.57915000"], ["84080.82000000", "0.00000000"], ["84080.63000000", "0.00000000"], ["84079.59000000", "0.71126000"], ["84079.47000000", "0.00000000"], ["84079.33000000", "0.00000000"], ["84079.22000000", "0.01189000"], ["84078.90000000", "0.00000000"], ["84077.91000000", "0.00000000"], ["84077.78000000", "0.00000000"], ["84077.20000000", "0.00000000"], ["84076.65000000", "0.00000000"], ["84076.58000000", "0.89155000"], ["84076.45000000", "0.89155000"], ["84076.28000000", "0.35662000"], ["84074.96000000", "0.89155000"], ["84073.94000000", "1.32016000"], ["84073.85000000", "0.47549000"], ["84073.56000000", "0.00000000"], ["84073.13000000", "0.00000000"], ["84072.85000000", "0.59481000"], ["84071.76000000", "0.05805000"], ["84070.67000000", "0.00000000"], ["84070.45000000", "0.04000000"], ["84070.44000000", "0.00000000"], ["84069.43000000", "0.00000000"], ["84069.38000000", "0.99799000"], ["84067.19000000", "0.00000000"], ["84066.95000000", "0.85687000"], ["84066.91000000", "0.00091000"], ["84065.58000000", "0.85688000"], ["84065.50000000", "0.00000000"], ["84063.76000000", "0.00000000"], ["84063.24000000", "0.00008000"], ["84059.80000000", "0.00000000"], ["84059.10000000", "0.11405000"], ["84058.05000000", "0.00000000"], ["84056.45000000", "0.00000000"], ["84055.75000000", "0.39143000"], ["84055.10000000", "0.00000000"], ["84054.00000000", "2.31777000"], ["84053.68000000", "0.00000000"], ["84051.53000000", "0.03202000"], ["84050.38000000", "0.05948000"], ["84050.09000000", "0.00000000"], ["84049.36000000", "0.05000000"], ["84048.51000000", "0.04628000"], ["84046.20000000", "0.00600000"], ["84046.00000000", "0.05796000"], ["84045.05000000", "0.04228000"], ["84044.97000000", "0.00000000"], ["84036.00000000", "0.47759000"], ["84026.29000000", "0.00000000"], ["84022.09000000", "0.04000000"], ["84021.15000000", "0.00000000"], ["84019.00000000", "0.04000000"], ["84017.78000000", "0.00000000"], ["84016.98000000", "0.00100000"], ["84016.94000000", "0.00000000"], ["84016.93000000", "0.00000000"], ["84007.84000000", "0.00000000"], ["84005.77000000", "0.00000000"], ["83980.69000000", "0.05497000"], ["83980.50000000", "0.05497000"], ["83979.99000000", "0.80496000"], ["83970.81000000", "0.08994000"], ["83970.44000000", "0.04497000"], ["83949.11000000", "0.00000000"], ["83943.62000000", "0.00000000"], ["83943.32000000", "0.00000000"], ["83941.13000000", "0.01000000"], ["83920.59000000", "0.00000000"], ["83915.07000000", "0.99313000"], ["83914.52000000", "0.00400000"], ["83906.99000000", "0.00000000"], ["83152.49000000", "0.40000000"], ["82854.67000000", "0.00087000"], ["82841.96000000", "0.00100000"], ["80730.96000000", "0.00000000"], ["80714.10000000", "0.00000000"], ["75693.00000000", "0.00000000"], ["75692.00000000", "0.06625000"], ["67282.82000000", "0.00058000"], ["33000.00000000", "2.93827000"], ["30277.27000000", "0.00200000"]], "a": [["84103.53000000", "5.94628000"], ["84103.54000000", "0.21990000"], ["84103.55000000", "0.23836000"], ["84103.58000000", "0.18334000"], ["84103.67000000", "0.00021000"], ["84103.68000000", "0.13752000"], ["84103.84000000", "0.00000000"], ["84103.96000000", "0.00201000"], ["84103.97000000", "0.00000000"], ["84104.01000000", "0.00000000"], ["84104.04000000", "0.03389000"], ["84105.20000000", "0.00403000"], ["84105.35000000", "0.00000000"], ["84105.87000000", "0.00007000"], ["84105.97000000", "0.00006000"], ["84106.17000000", "0.02974000"], ["84106.69000000", "0.06000000"], ["84106.71000000", "0.00000000"], ["84107.63000000", "0.00000000"], ["84107.70000000", "0.01000000"], ["84107.89000000", "0.26253000"], ["84107.90000000", "0.23835000"], ["84107.91000000", "0.00000000"], ["84108.00000000", "0.02260000"], ["84108.46000000", "0.00000000"], ["84108.63000000", "0.00000000"], ["84110.95000000", "0.00000000"], ["84111.63000000", "0.45468000"], ["84111.73000000", "0.00118000"], ["84111.95000000", "0.47378000"], ["84112.42000000", "0.00000000"], ["84112.58000000", "0.00000000"], ["84112.68000000", "0.04400000"], ["84112.71000000", "0.00000000"], ["84113.04000000", "0.08992000"], ["84113.19000000", "0.71126000"], ["84113.57000000", "0.04800000"], ["84114.38000000", "0.04000000"], ["84114.40000000", "0.01189000"], ["84115.34000000", "0.00000000"], ["84115.70000000", "0.00000000"], ["84115.87000000", "0.00059000"], ["84115.88000000", "0.78243000"], ["84115.89000000", "0.00000000"], ["84115.95000000", "0.00000000"], ["84116.17000000", "0.00059000"], ["84116.88000000", "0.05600000"], ["84117.13000000", "0.00000000"], ["84117.24000000", "0.00000000"], ["84117.28000000", "1.00000000"], ["84117.49000000", "0.00000000"], ["84117.50000000", "0.00000000"], ["84117.73000000", "0.05600000"], ["84117.75000000", "0.00117000"], ["84117.77000000", "0.08000000"], ["84118.09000000", "0.00000000"], ["84118.55000000", "0.00000000"], ["84118.74000000", "0.00000000"], ["84118.96000000", "0.00000000"], ["84120.26000000", "0.05956000"], ["84120.60000000", "0.02378000"], ["84120.91000000", "0.05945000"], ["84120.95000000", "1.48298000"], ["84120.96000000", "0.00000000"], ["84121.12000000", "0.00000000"], ["84121.65000000", "0.00000000"], ["84122.05000000", "0.00000000"], ["84122.28000000", "1.34218000"], ["84122.37000000", "0.00000000"], ["84122.94000000", "0.00000000"], ["84123.14000000", "0.00000000"], ["84123.32000000", "0.00000000"], ["84123.84000000", "0.00000000"], ["84123.88000000", "0.00000000"], ["84124.50000000", "1.27370000"], ["84125.29000000", "0.85627000"], ["84125.81000000", "0.00000000"], ["84126.24000000", "0.95099000"], ["84126.68000000", "0.00506000"], ["84126.69000000", "0.00000000"], ["84126.71000000", "0.00000000"], ["84127.74000000", "0.12002000"], ["84128.16000000", "0.00000000"], ["84128.39000000", "0.00059000"], ["84128.76000000", "0.06786000"], ["84130.68000000", "0.08992000"], ["84130.97000000", "0.00000000"], ["84131.44000000", "0.35670000"], ["84133.39000000", "0.38996000"], ["84133.46000000", "0.01624000"], ["84134.36000000", "0.59481000"], ["84134.93000000", "1.74772000"], ["84135.13000000", "0.00000000"], ["84135.16000000", "0.05815000"], ["84135.59000000", "0.00000000"], ["84136.22000000", "0.00594000"], ["84136.45000000", "0.00000000"], ["84137.28000000", "0.23670000"], ["84137.67000000", "0.71126000"], ["84137.92000000", "0.05945000"], ["84138.31000000", "0.00000000"], ["84140.42000000", "0.00000000"], ["84140.59000000", "0.02972000"], ["84141.32000000", "0.38480000"], ["84141.63000000", "0.00000000"], ["84141.88000000", "0.00000000"], ["84144.81000000", "0.06915000"], ["84145.21000000", "0.03971000"], ["84146.23000000", "0.93590000"], ["84146.46000000", "0.00000000"], ["84146.99000000", "0.00000000"], ["84147.51000000", "0.00000000"], ["84147.90000000", "0.00000000"], ["84148.87000000", "0.01492000"], ["84148.90000000", "0.04371000"], ["84150.20000000", "0.00859000"], ["84152.34000000", "0.00000000"], ["84153.62000000", "0.01052000"], ["84157.77000000", "0.01879000"], ["84157.87000000", "0.01052000"], ["84159.00000000", "0.00000000"], ["84161.98000000", "0.00000000"], ["84162.48000000", "0.00000000"], ["84165.11000000", "1.02656000"], ["84165.19000000", "0.00000000"], ["84165.20000000", "0.07594000"], ["84168.48000000", "0.00000000"], ["84170.42000000", "0.00000000"], ["84170.89000000", "0.37707000"], ["84174.70000000", "0.00000000"], ["84175.02000000", "0.01384000"], ["84178.90000000", "0.02007000"], ["84179.68000000", "0.00742000"], ["84186.72000000", "0.00000000"], ["84191.69000000", "0.00000000"], ["84199.35000000", "0.00677000"], ["84200.88000000", "0.00000000"], ["84204.00000000", "0.00235000"], ["84208.74000000", "0.07102000"], ["84212.86000000", "0.00000000"], ["84216.92000000", "0.01112000"], ["84220.70000000", "0.01466000"], ["84221.31000000", "0.00000000"], ["84224.40000000", "0.00923000"], ["84225.45000000", "0.00000000"], ["84225.52000000", "0.00000000"], ["84225.99000000", "0.00913000"], ["84237.78000000", "0.00000000"], ["84246.20000000", "0.02496000"], ["84253.86000000", "0.00000000"], ["84258.60000000", "0.00675000"], ["84267.70000000", "0.01947000"], ["84276.90000000", "0.00708000"], ["84285.63000000", "0.99985000"], ["84396.54000000", "0.00000000"], ["84420.00000000", "0.06939000"], ["84462.00000000", "0.11877000"], ["84772.80000000", "0.00006000"], ["85192.99000000", "0.60000000"], ["85201.42000000", "0.00000000"], ["85365.09000000", "0.00000000"], ["85413.00000000", "0.05899000"], ["85434.30000000", "0.00000000"], ["87000.00000000", "38.94557000"]], "record_time": 1742584903.128316, "EXCHANGE": "BINANCE"}
{"e": "depthUpdate", "E": 1742584904014, "s": "BTCUSDT", "U": 64637889773, "u": 64637890016, "b": [["84103.52000000", "0.74748000"], ["84103.38000000", "0.00007000"], ["84103.37000000", "0.00015000"], ["84103.35000000", "0.00209000"], ["84103.32000000", "0.00007000"], ["84103.31000000", "0.00000000"], ["84102.56000000", "0.00000000"], ["84102.00000000", "0.02267000"], ["84101.95000000", "0.00000000"], ["84101.94000000", "0.00000000"], ["84101.90000000", "0.00014000"], ["84101.89000000", "0.17772000"], ["84101.46000000", "0.00014000"], ["84101.45000000", "0.78521000"], ["84101.43000000", "0.00000000"], ["84101.42000000", "0.00006000"], ["84100.91000000", "0.00000000"], ["84100.90000000", "0.25829000"], ["84100.13000000", "0.00000000"], ["84100.01000000", "0.00009000"], ["84100.00000000", "0.02266000"], ["84099.98000000", "0.00000000"], ["84099.93000000", "0.00011000"], ["84099.92000000", "0.02538000"], ["84099.77000000", "0.00000000"], ["84099.76000000", "0.00000000"], ["84099.68000000", "0.00013000"], ["84099.67000000", "0.07282000"], ["84099.64000000", "0.00000000"], ["84099.63000000", "0.00000000"], ["84099.58000000", "0.00000000"], ["84098.71000000", "0.00000000"], ["84089.49000000", "0.00000000"], ["84087.79000000", "0.00000000"], ["84084.81000000", "0.00000000"], ["84084.34000000", "0.00000000"], ["84084.33000000", "0.03568000"], ["84082.67000000", "0.00939000"], ["84081.32000000", "0.08354000"], ["84080.33000000", "0.00000000"], ["84079.69000000", "0.01878000"], ["84078.44000000", "0.85675000"], ["84077.80000000", "2.26628000"], ["84076.65000000", "0.59479000"], ["84076.08000000", "0.16424000"], ["84073.82000000", "0.85680000"], ["84072.85000000", "0.00000000"], ["84072.80000000", "0.00500000"], ["84065.58000000", "0.00000000"], ["84054.00000000", "2.26480000"], ["84008.72000000", "0.39428000"], ["84007.29000000", "0.63079000"], ["83976.74000000", "0.05297000"], ["83975.49000000", "0.72282000"], ["83919.69000000", "0.00000000"], ["83917.83000000", "0.00835000"], ["83914.52000000", "0.00000000"], ["83912.99000000", "0.00400000"], ["83907.93000000", "0.00000000"], ["82852.42000000", "0.00080000"], ["82841.96000000", "0.00000000"], ["75693.00000000", "0.00000000"], ["75692.00000000", "0.06625000"], ["67282.82000000", "0.00058000"], ["42000.00000000", "6.84810000"], ["33000.00000000", "2.93827000"]], "a": [["84103.53000000", "5.94798000"], ["84103.68000000", "0.13752000"], ["84104.04000000", "0.00006000"], ["84105.20000000", "0.01183000"], ["84105.97000000", "0.00000000"], ["84106.22000000", "0.02337000"], ["84107.70000000", "0.00500000"], ["84110.60000000", "0.04400000"], ["84112.28000000", "0.06800000"], ["84115.60000000", "0.00000000"], ["84115.87000000", "0.00000000"], ["84116.59000000", "0.06000000"], ["84118.19000000", "1.00000000"], ["84119.09000000", "0.00000000"], ["84120.80000000", "0.00000000"], ["84123.86000000", "0.00000000"], ["84127.00000000", "0.05000000"], ["84128.51000000", "0.00000000"], ["84128.55000000", "0.33063000"], ["84132.20000000", "0.01675000"], ["84134.36000000", "0.00000000"], ["84139.10000000", "0.59480000"], ["84149.05000000", "0.01941000"], ["84153.87000000", "0.01158000"], ["84163.16000000", "0.61954000"], ["84169.43000000", "0.00000000"], ["84182.70000000", "0.01158000"], ["84187.52000000", "0.00000000"], ["84191.50000000", "0.01664000"], ["84191.62000000", "0.01286000"], ["84194.63000000", "0.00000000"], ["84199.43000000", "0.00977000"], ["84202.75000000", "0.00000000"], ["84203.13000000", "0.00000000"], ["84204.94000000", "0.01725000"], ["84208.33000000", "0.00000000"], ["84213.62000000", "0.02664000"], ["84229.66000000", "0.00676000"], ["84237.25000000", "0.01765000"], ["84238.50000000", "0.00000000"], ["84238.52000000", "0.00914000"], ["84238.98000000", "0.01278000"], ["84241.80000000", "0.00000000"], ["84246.46000000", "0.01060000"], ["84257.65000000", "0.00000000"], ["84266.68000000", "0.00000000"], ["84267.63000000", "0.00000000"], ["84271.17000000", "0.01941000"], ["84272.23000000", "0.01988000"], ["84280.75000000", "0.01551000"], ["84570.24000000", "0.00000000"], ["84586.04000000", "0.00566000"], ["85365.09000000", "0.00100000"]], "record_time": 1742584904.126674, "EXCHANGE": "BINANCE"}
{"e": "depthUpdate", "E": 1742584905014, "s": "BTCUSDT", "U": 64637890017, "u": 64637890451, "b": [["84103.52000000", "0.03901000"], ["84103.47000000", "0.00000000"], ["84103.37000000", "0.00007000"], ["84103.35000000", "0.00216000"], ["84103.32000000", "0.00007000"], ["84102.01000000", "0.00000000"], ["84102.00000000", "0.00000000"], ["84101.90000000", "0.00000000"], ["84101.89000000", "0.00000000"], ["84101.85000000", "0.00000000"], ["84101.66000000", "0.00000000"], ["84101.46000000", "0.00000000"], ["84101.45000000", "0.00000000"], ["84101.42000000", "0.00000000"], ["84100.95000000", "0.00008000"], ["84100.90000000", "0.00000000"], ["84100.01000000", "0.00000000"], ["84100.00000000", "0.00006000"], ["84099.97000000", "0.00007000"], ["84099.93000000", "0.00024000"], ["84099.92000000", "0.02551000"], ["84099.85000000", "0.00000000"], ["84099.68000000", "0.00000000"], ["84099.67000000", "0.00000000"], ["84099.02000000", "0.00000000"], ["84098.54000000", "0.00027000"], ["84098.53000000", "0.06440000"], ["84098.00000000", "0.00000000"], ["84097.82000000", "0.00029000"], ["84097.81000000", "0.13875000"], ["84097.41000000", "0.00013000"], ["84097.40000000", "0.02234000"], ["84096.80000000", "0.00394000"], ["84096.68000000", "0.00014000"], ["84096.67000000", "0.78518000"], ["84096.64000000", "0.00000000"], ["84096.00000000", "0.00000000"], ["84095.27000000", "0.14217000"], ["84095.18000000", "0.00000000"], ["84094.97000000", "0.00758000"], ["84094.45000000", "0.00000000"], ["84094.44000000", "0.00000000"], ["84094.26000000", "0.31368000"], ["84093.24000000", "0.00000000"], ["84093.23000000", "0.00000000"], ["84092.56000000", "0.00000000"], ["84092.39000000", "0.00000000"], ["84091.55000000", "0.00000000"], ["84091.54000000", "0.00000000"], ["84091.48000000", "0.00000000"], ["84090.37000000", "0.00000000"], ["84090.00000000", "0.02260000"], ["84089.99000000", "0.00000000"], ["84089.02000000", "0.00000000"], ["84088.75000000", "0.04000000"], ["84088.61000000", "0.00000000"], ["84088.19000000", "0.00000000"], ["84087.49000000", "0.00000000"], ["84087.35000000", "0.00000000"], ["84087.34000000", "0.00000000"], ["84087.28000000", "0.00000000"], ["84087.01000000", "0.04000000"], ["84086.68000000", "0.00000000"], ["84086.48000000", "0.00000000"], ["84084.81000000", "0.05353000"], ["84084.55000000", "0.04000000"], ["84084.33000000", "0.00000000"], ["84084.22000000", "0.03568000"], ["84084.21000000", "0.04000000"], ["84083.71000000", "0.04000000"], ["84082.81000000", "0.04000000"], ["84082.67000000", "0.00000000"], ["84081.32000000", "0.00000000"], ["84080.79000000", "0.00000000"], ["84079.69000000", "0.00000000"], ["84079.59000000", "0.00000000"], ["84078.45000000", "0.00000000"], ["84078.44000000", "0.00000000"], ["84077.80000000", "1.07646000"], ["84076.71000000", "0.02817000"], ["84076.65000000", "0.00000000"], ["84075.68000000", "0.30350000"], ["84074.09000000", "0.00000000"], ["84073.94000000", "0.00000000"], ["84073.82000000", "0.00000000"], ["84073.80000000", "0.00000000"], ["84073.70000000", "0.00500000"], ["84073.31000000", "1.35545000"], ["84072.85000000", "0.00000000"], ["84072.80000000", "0.00000000"], ["84071.76000000", "0.00000000"], ["84071.07000000", "0.85682000"], ["84070.45000000", "0.00000000"], ["84067.47000000", "0.00013000"], ["84063.78000000", "0.11693000"], ["84063.70000000", "0.00000000"], ["84063.68000000", "0.85690000"], ["84062.15000000", "0.59486000"], ["84062.10000000", "0.00000000"], ["84061.10000000", "0.34855000"], ["84061.04000000", "0.26003000"], ["84059.10000000", "0.00000000"], ["84057.39000000", "0.00000000"], ["84054.00000000", "2.20983000"], ["84049.36000000", "0.00000000"], ["84047.45000000", "0.17692000"], ["84042.91000000", "0.00000000"], ["84037.30000000", "0.00000000"], ["84032.92000000", "0.00060000"], ["84026.29000000", "0.04000000"], ["84017.78000000", "0.04000000"], ["84012.14000000", "0.00000000"], ["84007.29000000", "0.00000000"], ["84002.17000000", "0.04000000"], ["84001.05000000", "0.04000000"], ["84000.14000000", "0.01196000"], ["83997.96000000", "0.04000000"], ["83982.04000000", "0.05497000"], ["83980.49000000", "0.05497000"], ["83976.36000000", "0.10494000"], ["83972.28000000", "0.18318000"], ["83967.55000000", "0.04497000"], ["83941.13000000", "0.00000000"], ["83940.93000000", "0.01000000"], ["83940.90000000", "0.00000000"], ["83912.99000000", "0.00000000"], ["83911.57000000", "0.00400000"], ["83905.81000000", "0.00000000"], ["83871.79000000", "0.20145000"], ["83858.24000000", "0.00000000"], ["83854.81000000", "0.00978000"], ["83854.20000000", "0.45000000"], ["83849.84000000", "0.00000000"], ["83262.48000000", "0.00000000"], ["83112.60000000", "0.00000000"], ["83069.99000000", "0.00000000"], ["82841.96000000", "0.00100000"], ["80714.10000000", "0.03566000"], ["75693.00000000", "0.00000000"], ["75692.00000000", "0.06625000"], ["67282.82000000", "0.00058000"], ["60000.00000000", "73.01913000"], ["42000.00000000", "6.84710000"], ["33000.00000000", "2.93827000"], ["30277.27000000", "0.00220000"], ["20002.00000000", "0.00000000"], ["20001.00000000", "0.02099000"]], "a": [["84103.53000000", "5.95323000"], ["84103.54000000", "0.02101000"], ["84103.55000000", "0.23836000"], ["84103.57000000", "0.00021000"], ["84103.65000000", "0.00007000"], ["84103.66000000", "0.00000000"], ["84103.68000000", "0.13758000"], ["84104.00000000", "0.02266000"], ["84104.04000000", "0.03361000"], ["84104.27000000", "0.04000000"], ["84105.00000000", "0.00006000"], ["84105.20000000", "0.01188000"], ["84105.64000000", "0.04400000"], ["84105.96000000", "0.08992000"], ["84106.17000000", "0.02974000"], ["84106.22000000", "0.02361000"], ["84106.40000000", "0.00000000"], ["84106.84000000", "0.05945000"], ["84107.38000000", "0.04800000"], ["84107.70000000", "0.00000000"], ["84107.94000000", "0.11890000"], ["84110.60000000", "0.00000000"], ["84110.69000000", "0.05600000"], ["84111.02000000", "0.00000000"], ["84111.31000000", "0.05945000"], ["84111.59000000", "0.08000000"], ["84113.16000000", "0.11890000"], ["84113.57000000", "0.00000000"], ["84114.85000000", "1.00000000"], ["84115.88000000", "1.40617000"], ["84115.97000000", "0.00759000"], ["84116.28000000", "1.39935000"], ["84116.50000000", "0.00000000"], ["84116.77000000", "0.00000000"], ["84116.88000000", "0.00000000"], ["84117.28000000", "0.00000000"], ["84117.30000000", "0.00000000"], ["84117.39000000", "0.00000000"], ["84118.27000000", "0.00000000"], ["84119.17000000", "0.00000000"], ["84119.65000000", "0.05943000"], ["84120.21000000", "0.00007000"], ["84120.27000000", "0.85632000"], ["84120.45000000", "0.05000000"], ["84120.48000000", "0.00000000"], ["84120.95000000", "0.74621000"], ["84122.28000000", "0.00000000"], ["84127.00000000", "0.00000000"], ["84127.74000000", "0.00000000"], ["84127.97000000", "0.59485000"], ["84128.76000000", "0.00843000"], ["84130.61000000", "0.04371000"], ["84132.31000000", "0.11529000"], ["84132.42000000", "0.00000000"], ["84132.60000000", "0.02155000"], ["84133.93000000", "0.00583000"], ["84134.93000000", "0.89155000"], ["84135.16000000", "0.00000000"], ["84138.51000000", "0.01876000"], ["84138.94000000", "0.00000000"], ["84139.10000000", "0.00000000"], ["84140.33000000", "0.05720000"], ["84140.35000000", "0.01554000"], ["84140.63000000", "0.00000000"], ["84140.65000000", "0.00938000"], ["84147.47000000", "0.00000000"], ["84148.86000000", "0.00000000"], ["84148.90000000", "0.00000000"], ["84157.13000000", "0.01943000"], ["84162.34000000", "0.00000000"], ["84163.40000000", "0.00000000"], ["84174.41000000", "0.00000000"], ["84176.53000000", "0.05247000"], ["84176.85000000", "0.00000000"], ["84179.60000000", "0.01536000"], ["84186.92000000", "0.01511000"], ["84191.22000000", "0.01918000"], ["84192.63000000", "0.00000000"], ["84194.86000000", "0.01134000"], ["84199.14000000", "0.01008000"], ["84229.68000000", "0.02496000"], ["84230.79000000", "0.00000000"], ["84234.28000000", "0.01554000"], ["84242.21000000", "0.01512000"], ["84244.54000000", "0.00000000"], ["84250.93000000", "0.00000000"], ["84251.62000000", "0.00557000"], ["84254.03000000", "0.00000000"], ["84275.87000000", "0.01000000"], ["84277.57000000", "0.00000000"], ["84439.95000000", "0.00008000"], ["84739.20000000", "0.05954000"], ["85365.09000000", "0.00000000"]], "record_time": 1742584905.126959, "EXCHANGE": "BINANCE"}
{"e": "depthUpdate", "E": 1742584906014, "s": "BTCUSDT", "U": 64637890452, "u": 64637890894, "b": [["84103.52000000", "0.03804000"], ["84103.35000000", "0.00216000"], ["84103.32000000", "0.00007000"], ["84101.71000000", "0.00000000"], ["84101.40000000", "0.00000000"], ["84101.39000000", "0.00000000"], ["84100.99000000", "0.00000000"], ["84100.95000000", "0.00000000"], ["84100.60000000", "0.00024000"], ["84099.93000000", "0.00023000"], ["84099.26000000", "0.00000000"], ["84098.99000000", "0.00000000"], ["84098.95000000", "0.00014000"], ["84098.94000000", "0.00759000"], ["84098.53000000", "0.06440000"], ["84098.19000000", "0.00000000"], ["84097.81000000", "0.13869000"], ["84097.40000000", "0.02234000"], ["84096.80000000", "0.00000000"], ["84096.68000000", "0.00000000"], ["84096.67000000", "0.00000000"], ["84096.11000000", "0.00000000"], ["84096.10000000", "0.00000000"], ["84095.28000000", "0.00000000"], ["84095.27000000", "0.00000000"], ["84094.97000000", "0.00000000"], ["84094.46000000", "0.00007000"], ["84094.45000000", "0.78520000"], ["84094.26000000", "0.00000000"], ["84094.00000000", "0.00000000"], ["84093.66000000", "0.00000000"], ["84093.65000000", "0.00000000"], ["84092.59000000", "0.00000000"], ["84092.58000000", "0.00000000"], ["84090.64000000", "0.16987000"], ["84089.78000000", "0.00000000"], ["84089.60000000", "0.34848000"], ["84088.73000000", "0.00000000"], ["84087.92000000", "0.04000000"], ["84087.80000000", "0.00000000"], ["84087.09000000", "0.04000000"], ["84087.07000000", "0.04000000"], ["84085.61000000", "0.16809000"], ["84085.36000000", "0.00013000"], ["84085.06000000", "0.15674000"], ["84084.22000000", "0.00000000"], ["84084.21000000", "0.00000000"], ["84083.48000000", "0.00000000"], ["84083.35000000", "0.03568000"], ["84082.88000000", "0.08000000"], ["84082.31000000", "0.04000000"], ["84082.00000000", "0.02260000"], ["84081.31000000", "0.37168000"], ["84079.97000000", "0.16280000"], ["84079.61000000", "0.00000000"], ["84079.58000000", "0.00000000"], ["84078.89000000", "0.00000000"], ["84076.71000000", "0.00000000"], ["84074.96000000", "0.00000000"], ["84073.70000000", "0.00000000"], ["84073.32000000", "0.85485000"], ["84072.83000000", "0.71126000"], ["84072.80000000", "0.00500000"], ["84071.90000000", "0.00000000"], ["84071.60000000", "0.00000000"], ["84070.62000000", "0.00000000"], ["84070.17000000", "0.00000000"], ["84069.42000000", "0.00000000"], ["84068.22000000", "0.11646000"], ["84068.19000000", "0.00000000"], ["84066.38000000", "0.00009000"], ["84066.35000000", "0.04000000"], ["84063.78000000", "0.89155000"], ["84062.65000000", "0.00000000"], ["84062.39000000", "0.89155000"], ["84062.15000000", "0.63486000"], ["84061.80000000", "0.00939000"], ["84061.04000000", "0.15750000"], ["84060.67000000", "0.05098000"], ["84060.06000000", "0.47161000"], ["84058.39000000", "0.01878000"], ["84058.38000000", "0.85695000"], ["84057.06000000", "0.98504000"], ["84054.00000000", "1.99195000"], ["84048.56000000", "0.00000000"], ["84048.01000000", "0.04198000"], ["84047.45000000", "0.08996000"], ["84042.94000000", "0.00000000"], ["84040.00000000", "0.00216000"], ["84029.61000000", "0.00807000"], ["84023.21000000", "0.00000000"], ["84021.15000000", "0.00000000"], ["84019.00000000", "0.00000000"], ["84017.78000000", "0.00000000"], ["84016.94000000", "0.00000000"], ["84016.93000000", "0.00000000"], ["84007.84000000", "0.00000000"], ["84005.77000000", "0.00000000"], ["84004.54000000", "0.65282000"], ["84004.53000000", "0.63079000"], ["84002.55000000", "0.00000000"], ["84002.17000000", "0.00000000"], ["84001.05000000", "0.00000000"], ["83999.31000000", "0.24891000"], ["83997.96000000", "0.00000000"], ["83993.76000000", "0.09393000"], ["83993.09000000", "0.09393000"], ["83993.08000000", "0.14149000"], ["83993.01000000", "0.04756000"], ["83987.59000000", "0.14152000"], ["83982.58000000", "0.05497000"], ["83982.04000000", "0.00000000"], ["83980.36000000", "0.05497000"], ["83979.85000000", "0.05497000"], ["83977.63000000", "0.05097000"], ["83976.36000000", "0.15991000"], ["83976.07000000", "0.05497000"], ["83974.43000000", "0.04197000"], ["83972.62000000", "0.05416000"], ["83971.73000000", "0.77504000"], ["83969.02000000", "0.04197000"], ["83967.37000000", "0.02286000"], ["83967.14000000", "0.04997000"], ["83966.37000000", "0.04497000"], ["83940.93000000", "0.01000000"], ["83911.57000000", "0.00000000"], ["83905.01000000", "0.00400000"], ["82841.96000000", "0.00000000"], ["75693.00000000", "0.00000000"], ["75692.00000000", "0.06625000"], ["67282.82000000", "0.00058000"], ["60000.00000000", "73.01903000"], ["33000.00000000", "2.93827000"], ["30277.27000000", "0.00240000"]], "a": [["84103.53000000", "6.02301000"], ["84103.54000000", "0.34918000"], ["84103.57000000", "0.00007000"], ["84104.04000000", "0.03367000"], ["84104.27000000", "0.04006000"], ["84105.30000000", "0.04000000"], ["84106.30000000", "0.00300000"], ["84106.49000000", "0.04400000"], ["84107.34000000", "0.06800000"], ["84107.88000000", "0.71126000"], ["84107.90000000", "1.13934000"], ["84109.33000000", "0.02378000"], ["84109.43000000", "0.89155000"], ["84109.81000000", "0.05945000"], ["84111.26000000", "0.89155000"], ["84111.49000000", "0.11890000"], ["84111.53000000", "0.94755000"], ["84111.54000000", "0.06000000"], ["84111.63000000", "0.72800000"], ["84112.28000000", "0.00000000"], ["84112.68000000", "0.00000000"], ["84112.72000000", "0.23404000"], ["84114.07000000", "0.00757000"], ["84114.22000000", "1.00000000"], ["84114.38000000", "0.02378000"], ["84114.85000000", "0.00000000"], ["84115.85000000", "0.01071000"], ["84115.88000000", "0.78243000"], ["84115.97000000", "0.00000000"], ["84116.11000000", "0.00057000"], ["84116.25000000", "0.01341000"], ["84116.40000000", "0.00300000"], ["84116.57000000", "0.01281000"], ["84116.59000000", "0.00000000"], ["84117.73000000", "0.00000000"], ["84117.77000000", "0.00000000"], ["84118.19000000", "0.00000000"], ["84123.51000000", "0.05945000"], ["84126.15000000", "0.05945000"], ["84127.84000000", "0.05945000"], ["84128.38000000", "0.02666000"], ["84128.63000000", "0.00000000"], ["84128.71000000", "0.02814000"], ["84131.74000000", "0.05600000"], ["84132.31000000", "0.00000000"], ["84132.59000000", "0.06000000"], ["84133.43000000", "0.02026000"], ["84136.29000000", "0.00000000"], ["84136.75000000", "0.11824000"], ["84137.66000000", "0.43617000"], ["84138.19000000", "0.00000000"], ["84138.45000000", "0.00000000"], ["84138.51000000", "0.00000000"], ["84140.65000000", "0.00000000"], ["84145.37000000", "0.11890000"], ["84150.21000000", "0.01111000"], ["84150.94000000", "0.01196000"], ["84153.01000000", "0.01042000"], ["84160.15000000", "0.04400000"], ["84173.64000000", "0.00000000"], ["84174.04000000", "0.00000000"], ["84174.88000000", "0.00000000"], ["84182.01000000", "0.00000000"], ["84184.10000000", "0.01111000"], ["84195.60000000", "0.00000000"], ["84199.78000000", "0.00059000"], ["84200.51000000", "0.00000000"], ["84203.30000000", "0.00628000"], ["84203.58000000", "0.00000000"], ["84204.95000000", "0.00006000"], ["84211.96000000", "0.01079000"], ["84216.99000000", "0.48020000"], ["84220.85000000", "0.00000000"], ["84223.92000000", "0.00000000"], ["84224.37000000", "0.00000000"], ["84235.11000000", "0.02496000"], ["84242.34000000", "0.01132000"], ["84246.20000000", "0.00000000"], ["84246.73000000", "0.00000000"], ["84249.66000000", "0.01079000"], ["84267.48000000", "0.01769000"], ["84272.01000000", "0.01144000"], ["84275.87000000", "0.01000000"], ["84279.81000000", "0.01152000"], ["84400.16000000", "0.00000000"], ["85000.00000000", "17.15619000"], ["85365.09000000", "0.00100000"]], "record_time": 1742584906.127399, "EXCHANGE": "BINANCE"}
{"e": "depthUpdate", "E": 1742584907014, "s": "BTCUSDT", "U": 64637890895, "u": 64637896130, "b": [["84103.52000000", "0.00000000"], ["84103.51000000", "0.00000000"], ["84103.39000000", "0.00000000"], ["84103.38000000", "0.00000000"], ["84103.37000000", "0.00000000"], ["84103.36000000", "0.00000000"], ["84103.35000000", "0.00000000"], ["84103.32000000", "0.00000000"], ["84100.70000000", "0.00000000"], ["84100.60000000", "0.00000000"], ["84100.06000000", "0.00000000"], ["84100.00000000", "0.00000000"], ["84099.97000000", "0.00000000"], ["84099.93000000", "0.00000000"], ["84099.92000000", "0.00000000"], ["84099.13000000", "0.00000000"], ["84098.95000000", "0.00000000"], ["84098.94000000", "0.00000000"], ["84098.54000000", "0.00000000"], ["84098.53000000", "0.00000000"], ["84098.28000000", "0.00000000"], ["84097.82000000", "0.00000000"], ["84097.81000000", "0.00000000"], ["84097.80000000", "0.00000000"], ["84097.44000000", "0.00000000"], ["84097.42000000", "0.00000000"], ["84097.41000000", "0.00000000"], ["84097.40000000", "0.00000000"], ["84096.69000000", "0.00000000"], ["84096.68000000", "0.00000000"], ["84096.59000000", "0.00000000"], ["84096.36000000", "0.00000000"], ["84096.35000000", "0.00000000"], ["84095.45000000", "0.00000000"], ["84095.12000000", "0.00000000"], ["84095.11000000", "0.00000000"], ["84095.10000000", "0.00000000"], ["84094.91000000", "0.00000000"], ["84094.46000000", "0.00000000"], ["84094.45000000", "0.00000000"], ["84094.03000000", "0.00000000"], ["84094.02000000", "0.00000000"], ["84094.01000000", "0.00000000"], ["84093.89000000", "0.00000000"], ["84093.68000000", "0.00000000"], ["84093.67000000", "0.00000000"], ["84093.66000000", "0.00000000"], ["84093.22000000", "0.00000000"], ["84093.02000000", "0.00000000"], ["84092.94000000", "0.00000000"], ["84092.73000000", "0.00000000"], ["84092.36000000", "0.00000000"], ["84092.33000000", "0.00000000"], ["84092.32000000", "0.00000000"], ["84092.24000000", "0.00000000"], ["84092.23000000", "0.00000000"], ["84092.15000000", "0.00000000"], ["84092.14000000", "0.00000000"], ["84092.13000000", "0.00000000"], ["84092.00000000", "0.00000000"], ["84091.64000000", "0.00000000"], ["84091.62000000", "0.00000000"], ["84091.53000000", "0.00000000"], ["84091.14000000", "0.00000000"], ["84091.13000000", "0.00000000"], ["84090.91000000", "0.00000000"], ["84090.71000000", "0.00000000"], ["84090.69000000", "0.00000000"], ["84090.64000000", "0.00000000"], ["84090.22000000", "0.00000000"], ["84090.09000000", "0.00000000"], ["84090.00000000", "0.00000000"], ["84089.84000000", "0.00000000"], ["84089.83000000", "0.00000000"], ["84089.82000000", "0.00000000"], ["84089.60000000", "0.00000000"], ["84089.43000000", "0.00000000"], ["84089.42000000", "0.00000000"], ["84089.39000000", "0.00000000"], ["84088.92000000", "0.00000000"], ["84088.89000000", "0.00000000"], ["84088.84000000", "0.00000000"], ["84088.75000000", "0.00000000"], ["84088.31000000", "0.00000000"], ["84088.25000000", "0.00000000"], ["84088.24000000", "0.00000000"], ["84088.23000000", "0.00000000"], ["84088.22000000", "0.00000000"], ["84088.21000000", "0.00000000"], ["84088.20000000", "0.00000000"], ["84088.16000000", "0.00000000"], ["84088.11000000", "0.00000000"], ["84088.00000000", "0.00000000"], ["84087.92000000", "0.00000000"], ["84087.53000000", "0.00000000"], ["84087.32000000", "0.00000000"], ["84087.25000000", "0.00000000"], ["84087.24000000", "0.00000000"], ["84087.10000000", "0.00000000"], ["84087.09000000", "0.00000000"], ["84087.07000000", "0.00000000"], ["84087.06000000", "0.00000000"], ["84087.01000000", "0.00000000"], ["84086.96000000", "0.00000000"], ["84086.82000000", "0.00000000"], ["84086.70000000", "0.00000000"], ["84086.45000000", "0.00000000"], ["84086.39000000", "0.00000000"], ["84086.32000000", "0.00000000"], ["84086.01000000", "0.00000000"], ["84086.00000000", "0.03478000"], ["84085.99000000", "0.00058000"], ["84085.73000000", "0.00000000"], ["84085.72000000", "0.00000000"], ["84085.61000000", "0.00000000"], ["84085.60000000", "0.00000000"], ["84085.49000000", "0.00000000"], ["84085.44000000", "0.00000000"], ["84085.40000000", "0.00021000"], ["84085.39000000", "0.02402000"], ["84085.36000000", "0.00007000"], ["84085.29000000", "0.00007000"], ["84085.28000000", "0.00307000"], ["84085.21000000", "0.00000000"], ["84085.15000000", "0.00007000"], ["84085.13000000", "0.00045000"], ["84085.12000000", "0.00000000"], ["84085.06000000", "0.00000000"], ["84084.81000000", "0.00000000"], ["84084.70000000", "0.00000000"], ["84084.69000000", "0.00000000"], ["84084.62000000", "0.00000000"], ["84084.55000000", "0.00000000"], ["84084.38000000", "0.00000000"], ["84084.37000000", "0.00000000"], ["84084.29000000", "0.00000000"], ["84084.01000000", "0.00000000"], ["84084.00000000", "0.00000000"], ["84083.93000000", "0.00000000"], ["84083.92000000", "0.00000000"], ["84083.72000000", "0.00000000"], ["84083.71000000", "0.00000000"], ["84083.49000000", "0.00000000"], ["84083.46000000", "0.00000000"], ["84083.35000000", "0.00000000"], ["84083.30000000", "0.00022000"], ["84083.29000000", "0.02219000"], ["84083.22000000", "0.00000000"], ["84083.17000000", "0.00000000"], ["84083.09000000", "0.00007000"], ["84082.88000000", "0.00000000"], ["84082.83000000", "0.00009000"], ["84082.82000000", "0.00000000"], ["84082.81000000", "0.00000000"], ["84082.68000000", "0.00000000"], ["84082.67000000", "0.00000000"], ["84082.42000000", "0.00000000"], ["84082.38000000", "0.00021000"], ["84082.37000000", "0.02552000"], ["84082.32000000", "0.00000000"], ["84082.31000000", "0.00000000"], ["84082.19000000", "0.00000000"], ["84082.18000000", "0.00000000"], ["84082.16000000", "0.00000000"], ["84082.01000000", "0.00021000"], ["84082.00000000", "0.02267000"], ["84081.83000000", "0.00000000"], ["84081.82000000", "0.00000000"], ["84081.61000000", "0.00000000"], ["84081.54000000", "0.00301000"], ["84081.53000000", "0.00000000"], ["84081.43000000", "0.00000000"], ["84081.33000000", "0.00000000"], ["84081.31000000", "0.00000000"], ["84081.25000000", "0.00000000"], ["84081.24000000", "0.00000000"], ["84081.15000000", "0.00000000"], ["84081.07000000", "0.00000000"], ["84080.92000000", "0.00000000"], ["84080.91000000", "0.00000000"], ["84080.82000000", "0.00000000"], ["84080.81000000", "0.00000000"], ["84080.79000000", "0.00000000"], ["84080.66000000", "0.00000000"], ["84080.65000000", "0.00000000"], ["84080.32000000", "0.00000000"], ["84080.31000000", "0.00000000"], ["84080.29000000", "0.00000000"], ["84080.21000000", "0.00000000"], ["84080.16000000", "0.00000000"], ["84079.97000000", "0.00000000"], ["84079.85000000", "0.00000000"], ["84079.80000000", "0.00000000"], ["84079.79000000", "0.00000000"], ["84079.72000000", "0.00000000"], ["84079.64000000", "0.00000000"], ["84079.39000000", "0.00000000"], ["84079.22000000", "0.00000000"], ["84079.01000000", "0.00000000"], ["84078.93000000", "0.00007000"], ["84078.92000000", "0.28516000"], ["84078.85000000", "0.00000000"], ["84078.74000000", "0.00000000"], ["84078.60000000", "0.04000000"], ["84078.49000000", "0.00000000"], ["84078.33000000", "0.04000000"], ["84078.31000000", "0.00000000"], ["84078.30000000", "0.00000000"], ["84078.28000000", "0.00000000"], ["84078.25000000", "0.04000000"], ["84078.21000000", "0.00000000"], ["84078.20000000", "0.00000000"], ["84078.18000000", "0.00000000"], ["84078.13000000", "0.00000000"], ["84078.11000000", "0.00000000"], ["84078.09000000", "0.00000000"], ["84078.05000000", "0.00000000"], ["84077.80000000", "0.00000000"], ["84077.77000000", "0.00000000"], ["84077.68000000", "0.00000000"], ["84077.50000000", "0.04000000"], ["84077.41000000", "0.00000000"], ["84077.39000000", "0.00000000"], ["84077.38000000", "0.00000000"], ["84077.34000000", "0.00000000"], ["84077.15000000", "0.00000000"], ["84077.01000000", "0.00000000"], ["84076.66000000", "0.04000000"], ["84076.64000000", "0.00000000"], ["84076.58000000", "0.00000000"], ["84076.45000000", "0.00000000"], ["84076.43000000", "0.00000000"], ["84076.41000000", "0.00000000"], ["84076.31000000", "0.00000000"], ["84076.29000000", "0.00000000"], ["84076.28000000", "0.00000000"], ["84076.25000000", "0.00000000"], ["84076.18000000", "0.00000000"], ["84076.09000000", "0.00000000"], ["84076.08000000", "0.12846000"], ["84075.91000000", "0.06000000"], ["84075.82000000", "0.00000000"], ["84075.74000000", "0.00000000"], ["84075.67000000", "0.00000000"], ["84075.65000000", "0.00000000"], ["84075.62000000", "0.00000000"], ["84075.60000000", "0.00006000"], ["84075.58000000", "0.00090000"], ["84075.50000000", "0.00000000"], ["84075.35000000", "0.14739000"], ["84075.20000000", "0.00000000"], ["84075.17000000", "0.00000000"], ["84075.09000000", "0.00000000"], ["84074.93000000", "0.00118000"], ["84074.81000000", "0.08000000"], ["84074.67000000", "0.00000000"], ["84074.48000000", "0.00000000"], ["84074.41000000", "0.04000000"], ["84074.35000000", "0.00000000"], ["84074.13000000", "0.04000000"], ["84073.99000000", "0.04000000"], ["84073.85000000", "0.00000000"], ["84073.66000000", "0.05430000"], ["84073.65000000", "0.04000000"], ["84073.59000000", "0.00000000"], ["84073.32000000", "0.00000000"], ["84073.31000000", "0.00000000"], ["84073.29000000", "0.04000000"], ["84072.91000000", "0.00000000"], ["84072.89000000", "0.00000000"], ["84072.84000000", "0.00000000"], ["84072.83000000", "0.00000000"], ["84072.50000000", "0.00000000"], ["84072.44000000", "0.04000000"], ["84072.39000000", "0.03000000"], ["84072.14000000", "0.00000000"], ["84071.82000000", "0.00000000"], ["84071.60000000", "0.00000000"], ["84071.32000000", "0.00097000"], ["84071.20000000", "0.00000000"], ["84071.17000000", "0.00000000"], ["84071.14000000", "0.00000000"], ["84071.07000000", "0.00000000"], ["84070.85000000", "0.00000000"], ["84070.83000000", "0.00000000"], ["84070.73000000", "0.00000000"], ["84070.69000000", "0.00000000"], ["84070.57000000", "0.00000000"], ["84070.13000000", "0.00000000"], ["84069.85000000", "0.00000000"], ["84069.69000000", "0.00000000"], ["84069.45000000", "0.00000000"], ["84069.38000000", "0.44891000"], ["84069.36000000", "0.00260000"], ["84069.24000000", "0.05353000"], ["84068.65000000", "0.16280000"], ["84068.42000000", "0.00000000"], ["84068.25000000", "0.16000000"], ["84068.23000000", "0.00000000"], ["84068.22000000", "0.00000000"], ["84067.53000000", "0.10601000"], ["84067.46000000", "0.00000000"], ["84067.26000000", "0.00922000"], ["84067.20000000", "0.00006000"], ["84066.95000000", "0.00000000"], ["84066.81000000", "0.00118000"], ["84066.71000000", "0.00000000"], ["84066.35000000", "0.00000000"], ["84065.25000000", "0.00355000"], ["84065.05000000", "0.00000000"], ["84064.64000000", "1.59020000"], ["84064.63000000", "0.00000000"], ["84064.59000000", "1.02573000"], ["84064.06000000", "0.00000000"], ["84063.86000000", "0.00000000"], ["84063.78000000", "0.00000000"], ["84063.68000000", "0.00000000"], ["84063.61000000", "0.00000000"], ["84063.26000000", "0.00007000"], ["84063.23000000", "0.00000000"], ["84063.02000000", "0.00300000"], ["84062.98000000", "0.00000000"], ["84062.91000000", "0.49228000"], ["84062.39000000", "0.00000000"], ["84062.15000000", "0.00000000"], ["84062.01000000", "0.59437000"], ["84061.80000000", "0.00000000"], ["84061.10000000", "0.00000000"], ["84061.04000000", "0.00000000"], ["84061.03000000", "0.00000000"], ["84061.02000000", "0.00000000"], ["84060.81000000", "0.00000000"], ["84060.76000000", "0.35662000"], ["84060.67000000", "0.00000000"], ["84060.63000000", "0.00000000"], ["84060.34000000", "0.00588000"], ["84060.14000000", "0.00016000"], ["84060.07000000", "0.00000000"], ["84060.06000000", "0.17899000"], ["84059.86000000", "0.00000000"], ["84059.56000000", "0.00000000"], ["84059.03000000", "0.47549000"], ["84059.02000000", "0.00000000"], ["84059.01000000", "0.00000000"], ["84058.39000000", "0.00000000"], ["84058.38000000", "0.00000000"], ["84058.09000000", "0.00000000"], ["84057.40000000", "0.00000000"], ["84057.06000000", "0.79480000"], ["84056.61000000", "0.00000000"], ["84056.44000000", "0.00000000"], ["84056.32000000", "0.89155000"], ["84056.27000000", "0.00000000"], ["84056.26000000", "0.00000000"], ["84056.06000000", "0.89155000"], ["84055.83000000", "0.00000000"], ["84055.48000000", "0.17841000"], ["84055.13000000", "0.00000000"], ["84054.85000000", "0.00000000"], ["84054.00000000", "0.00000000"], ["84053.23000000", "0.85701000"], ["84052.30000000", "0.59493000"], ["84052.29000000", "0.00000000"], ["84052.04000000", "0.20192000"], ["84051.53000000", "0.00000000"], ["84051.28000000", "0.00000000"], ["84051.27000000", "0.00000000"], ["84050.83000000", "0.00358000"], ["84050.72000000", "0.02817000"], ["84050.68000000", "0.00000000"], ["84050.51000000", "0.88844000"], ["84050.40000000", "0.89161000"], ["84050.38000000", "0.00000000"], ["84050.23000000", "0.00000000"], ["84050.01000000", "0.00146000"], ["84049.45000000", "0.89155000"], ["84049.18000000", "0.00000000"], ["84048.58000000", "0.00000000"], ["84048.51000000", "0.00000000"], ["84048.34000000", "0.85706000"], ["84048.01000000", "0.00000000"], ["84047.45000000", "0.00000000"], ["84046.90000000", "0.89155000"], ["84046.49000000", "0.85708000"], ["84046.20000000", "0.00659000"], ["84046.03000000", "0.00000000"], ["84046.00000000", "0.00000000"], ["84045.59000000", "0.00000000"], ["84045.05000000", "0.00000000"], ["84044.98000000", "0.30853000"], ["84044.27000000", "0.00000000"], ["84044.26000000", "0.00000000"], ["84043.58000000", "0.89155000"], ["84042.27000000", "0.00000000"], ["84041.75000000", "0.00000000"], ["84041.73000000", "0.00000000"], ["84040.73000000", "0.04998000"], ["84040.04000000", "0.13996000"], ["84039.12000000", "0.00000000"], ["84038.33000000", "0.00000000"], ["84038.14000000", "0.00000000"], ["84035.62000000", "0.00000000"], ["84035.61000000", "0.04228000"], ["84034.37000000", "0.00000000"], ["84034.36000000", "0.00000000"], ["84033.60000000", "0.05955000"], ["84033.07000000", "0.00000000"], ["84032.92000000", "0.00000000"], ["84032.01000000", "0.00295000"], ["84031.93000000", "0.03202000"], ["84030.48000000", "0.05796000"], ["84030.24000000", "0.00000000"], ["84029.61000000", "0.00000000"], ["84028.22000000", "0.04628000"], ["84028.06000000", "0.00060000"], ["84027.45000000", "0.23484000"], ["84026.66000000", "0.00000000"], ["84026.34000000", "0.00000000"], ["84024.16000000", "0.59437000"], ["84023.38000000", "0.00000000"], ["84023.21000000", "0.04000000"], ["84021.16000000", "0.04000000"], ["84021.15000000", "0.00000000"], ["84019.43000000", "0.00000000"], ["84019.01000000", "0.04000000"], ["84019.00000000", "0.00000000"], ["84017.99000000", "0.00000000"], ["84017.78000000", "0.00000000"], ["84017.61000000", "0.00000000"], ["84017.60000000", "0.00000000"], ["84017.31000000", "0.00000000"], ["84016.94000000", "0.08000000"], ["84016.93000000", "0.00000000"], ["84016.80000000", "0.00006000"], ["84016.31000000", "0.00823000"], ["84007.84000000", "0.04000000"], ["84005.78000000", "0.04000000"], ["84005.26000000", "0.00000000"], ["84005.13000000", "0.03201000"], ["84004.54000000", "0.50986000"], ["84004.53000000", "0.00000000"], ["84004.14000000", "0.00000000"], ["84001.80000000", "0.05220000"], ["84001.05000000", "0.00000000"], ["84000.57000000", "0.00146000"], ["84000.14000000", "0.00000000"], ["83996.11000000", "0.04637000"], ["83994.37000000", "0.10253000"], ["83993.76000000", "0.18786000"], ["83993.09000000", "0.14030000"], ["83992.90000000", "0.05496000"], ["83992.04000000", "0.05297000"], ["83991.09000000", "0.28920000"], ["83990.45000000", "0.19527000"], ["83989.79000000", "0.15232000"], ["83989.61000000", "0.05297000"], ["83989.60000000", "0.00000000"], ["83989.26000000", "0.94681000"], ["83988.99000000", "0.12899000"], ["83988.65000000", "0.10134000"], ["83988.48000000", "0.09394000"], ["83988.01000000", "0.10594000"], ["83987.59000000", "0.19648000"], ["83987.34000000", "0.01196000"], ["83986.79000000", "0.09934000"], ["83986.47000000", "0.05497000"], ["83985.42000000", "0.00000000"], ["83984.59000000", "0.05097000"], ["83984.37000000", "0.05497000"], ["83983.93000000", "0.00000000"], ["83983.26000000", "0.20728000"], ["83982.57000000", "0.10793000"], ["83981.72000000", "0.05497000"], ["83981.40000000", "0.08066000"], ["83981.34000000", "0.05497000"], ["83980.43000000", "0.05497000"], ["83980.19000000", "0.05097000"], ["83980.01000000", "0.10254000"], ["83979.76000000", "0.00083000"], ["83979.41000000", "0.05497000"], ["83979.19000000", "0.05497000"], ["83979.04000000", "0.05297000"], ["83979.03000000", "0.05496000"], ["83978.50000000", "0.05497000"], ["83977.92000000", "0.05103000"], ["83977.68000000", "0.05497000"], ["83976.95000000", "0.05097000"], ["83976.74000000", "0.10594000"], ["83976.26000000", "0.05497000"], ["83975.97000000", "0.05497000"], ["83975.61000000", "0.05496000"], ["83975.27000000", "0.05097000"], ["83975.21000000", "0.05497000"], ["83975.12000000", "0.05297000"], ["83975.04000000", "0.05497000"], ["83974.31000000", "0.09935000"], ["83973.48000000", "0.00013000"], ["83973.00000000", "0.04997000"], ["83972.98000000", "0.10000000"], ["83972.47000000", "0.05097000"], ["83972.22000000", "0.05297000"], ["83971.87000000", "0.04997000"], ["83971.84000000", "0.05297000"], ["83971.66000000", "0.16490000"], ["83971.57000000", "0.05496000"], ["83971.55000000", "0.05497000"], ["83969.78000000", "0.04997000"], ["83969.60000000", "0.04497000"], ["83969.31000000", "0.04997000"], ["83969.05000000", "0.05297000"], ["83969.04000000", "0.05297000"], ["83967.92000000", "0.04197000"], ["83967.59000000", "0.55149000"], ["83967.37000000", "0.00000000"], ["83967.36000000", "0.06783000"], ["83966.40000000", "0.04203000"], ["83966.38000000", "0.00000000"], ["83965.23000000", "0.04997000"], ["83965.06000000", "0.04497000"], ["83963.91000000", "0.08694000"], ["83963.49000000", "0.04997000"], ["83961.75000000", "0.04197000"], ["83960.52000000", "0.11672000"], ["83959.90000000", "0.04997000"], ["83959.32000000", "0.04497000"], ["83954.69000000", "0.00000000"], ["83949.60000000", "0.05954000"], ["83940.93000000", "0.00000000"], ["83940.58000000", "0.00000000"], ["83938.46000000", "0.00000000"], ["83938.18000000", "0.00006000"], ["83937.93000000", "0.00000000"], ["83937.38000000", "0.00000000"], ["83936.53000000", "0.00000000"], ["83935.78000000", "0.00000000"], ["83935.34000000", "0.00000000"], ["83934.74000000", "0.00000000"], ["83930.49000000", "0.00000000"], ["83928.45000000", "0.00050000"], ["83928.13000000", "0.21405000"], ["83912.02000000", "0.00000000"], ["83905.02000000", "0.00000000"], ["83905.01000000", "0.00000000"], ["83900.02000000", "0.00069000"], ["83884.97000000", "0.00000000"], ["83873.52000000", "0.01783000"], ["83865.70000000", "0.00013000"], ["83864.19000000", "0.00000000"], ["83861.95000000", "0.20145000"], ["83861.50000000", "0.00000000"], ["83861.30000000", "0.00013000"], ["83857.89000000", "0.00400000"], ["83857.45000000", "0.19167000"], ["83857.10000000", "0.00013000"], ["83856.81000000", "0.00000000"], ["83852.90000000", "0.00013000"], ["83851.52000000", "0.00007000"], ["83849.04000000", "0.00981000"], ["83848.70000000", "0.00013000"], ["83848.33000000", "0.00000000"], ["83847.44000000", "0.00000000"], ["83847.43000000", "0.00060000"], ["83845.79000000", "0.45000000"], ["83839.92000000", "0.00000000"], ["83837.38000000", "0.45000000"], ["83740.13000000", "0.00000000"], ["83740.12000000", "0.00060000"], ["83736.93000000", "0.00000000"], ["83736.89000000", "0.00040000"], ["83084.28000000", "0.00000000"], ["83084.16000000", "0.00040000"], ["83069.99000000", "0.02347000"], ["82824.71000000", "0.00100000"], ["80714.10000000", "0.00000000"], ["80697.27000000", "0.03566000"], ["75693.00000000", "0.00000000"], ["75692.00000000", "0.06605000"], ["75679.00000000", "0.00397000"], ["75677.00000000", "0.00020000"], ["67282.82000000", "0.00000000"], ["67270.60000000", "0.00000000"], ["67268.80000000", "0.00058000"], ["33000.00000000", "2.93827000"]], "a": [["84086.01000000", "10.25688000"], ["84086.02000000", "0.00049000"], ["84087.06000000", "0.00007000"], ["84087.07000000", "0.00000000"], ["84087.24000000", "0.00007000"], ["84087.25000000", "0.00000000"], ["84087.26000000", "0.00000000"], ["84087.27000000", "0.00007000"], ["84087.28000000", "0.00007000"], ["84087.54000000", "0.00000000"], ["84087.99000000", "0.00021000"], ["84088.00000000", "0.02280000"], ["84088.17000000", "0.00000000"], ["84088.21000000", "0.00014000"], ["84088.22000000", "0.60744000"], ["84088.23000000", "0.00000000"], ["84088.24000000", "0.00000000"], ["84088.25000000", "0.17912000"], ["84088.26000000", "1.50619000"], ["84088.27000000", "0.00000000"], ["84088.63000000", "0.00000000"], ["84088.64000000", "0.00000000"], ["84088.72000000", "0.00000000"], ["84088.73000000", "0.00000000"], ["84088.74000000", "0.00000000"], ["84088.75000000", "0.00000000"], ["84088.76000000", "0.00000000"], ["84088.98000000", "0.00000000"], ["84089.17000000", "0.00000000"], ["84089.43000000", "0.00000000"], ["84089.44000000", "0.00000000"], ["84089.64000000", "0.02233000"], ["84089.83000000", "0.00007000"], ["84089.85000000", "0.00000000"], ["84089.99000000", "0.00024000"], ["84090.00000000", "0.02266000"], ["84090.10000000", "0.00000000"], ["84090.59000000", "0.00000000"], ["84090.66000000", "0.23483000"], ["84090.67000000", "0.00000000"], ["84090.68000000", "0.00000000"], ["84090.69000000", "0.00000000"], ["84090.70000000", "0.35974000"], ["84091.00000000", "0.00006000"], ["84091.13000000", "0.00000000"], ["84091.14000000", "0.00000000"], ["84091.15000000", "0.00000000"], ["84091.54000000", "0.00000000"], ["84091.56000000", "0.00000000"], ["84091.83000000", "0.00000000"], ["84092.00000000", "0.02260000"], ["84092.03000000", "0.00000000"], ["84092.14000000", "0.00000000"], ["84092.15000000", "0.00000000"], ["84092.16000000", "0.00000000"], ["84092.37000000", "0.00000000"], ["84092.40000000", "0.00006000"], ["84092.85000000", "0.00118000"], ["84093.03000000", "0.00000000"], ["84093.23000000", "0.02326000"], ["84093.49000000", "0.16637000"], ["84093.56000000", "0.00000000"], ["84093.67000000", "0.00035000"], ["84093.68000000", "0.00000000"], ["84093.69000000", "0.00000000"], ["84093.88000000", "0.00006000"], ["84093.89000000", "0.00000000"], ["84093.90000000", "0.00000000"], ["84093.92000000", "0.00000000"], ["84093.97000000", "0.00000000"], ["84093.99000000", "0.00000000"], ["84094.00000000", "0.02260000"], ["84094.02000000", "0.00000000"], ["84094.03000000", "0.00000000"], ["84094.04000000", "0.00000000"], ["84094.78000000", "0.00000000"], ["84094.80000000", "0.00000000"], ["84094.91000000", "0.40660000"], ["84094.92000000", "0.14000000"], ["84095.11000000", "0.00000000"], ["84095.12000000", "0.45000000"], ["84095.13000000", "0.00000000"], ["84095.35000000", "0.00000000"], ["84095.46000000", "0.00000000"], ["84095.59000000", "0.04400000"], ["84095.69000000", "0.00000000"], ["84095.74000000", "0.00000000"], ["84096.00000000", "0.02260000"], ["84096.44000000", "0.04400000"], ["84096.45000000", "0.00000000"], ["84096.50000000", "0.00013000"], ["84096.52000000", "0.05943000"], ["84096.57000000", "0.00000000"], ["84096.60000000", "0.00006000"], ["84096.67000000", "0.00300000"], ["84096.68000000", "0.00000000"], ["84096.69000000", "0.03389000"], ["84096.70000000", "0.03582000"], ["84096.93000000", "0.00000000"], ["84097.07000000", "0.06400000"], ["84097.14000000", "0.00307000"], ["84097.28000000", "0.06800000"], ["84097.33000000", "0.00000000"], ["84097.40000000", "0.00000000"], ["84097.41000000", "0.00000000"], ["84097.42000000", "0.00000000"], ["84097.43000000", "0.00000000"], ["84097.44000000", "0.00000000"], ["84097.45000000", "0.00000000"], ["84097.53000000", "0.30389000"], ["84097.62000000", "0.00000000"], ["84097.63000000", "0.00000000"], ["84097.71000000", "0.00000000"], ["84097.81000000", "0.00000000"], ["84097.82000000", "0.13094000"], ["84097.83000000", "0.00000000"], ["84097.99000000", "0.00000000"], ["84098.00000000", "0.02260000"], ["84098.09000000", "0.00000000"], ["84098.28000000", "0.00000000"], ["84098.29000000", "0.00000000"], ["84098.36000000", "0.00000000"], ["84098.52000000", "0.00000000"], ["84098.53000000", "0.26253000"], ["84098.54000000", "0.00000000"], ["84098.55000000", "0.00000000"], ["84098.71000000", "0.00009000"], ["84098.92000000", "0.00006000"], ["84098.96000000", "0.00000000"], ["84099.12000000", "0.00000000"], ["84099.14000000", "0.00000000"], ["84099.26000000", "0.00013000"], ["84099.68000000", "0.00013000"], ["84099.69000000", "0.00000000"], ["84099.81000000", "0.00000000"], ["84099.92000000", "0.57525000"], ["84099.93000000", "0.00100000"], ["84099.94000000", "0.00000000"], ["84099.96000000", "0.00000000"], ["84099.97000000", "0.00000000"], ["84099.98000000", "0.00000000"], ["84100.00000000", "0.02283000"], ["84100.01000000", "0.00000000"], ["84100.07000000", "0.00000000"], ["84100.21000000", "0.00000000"], ["84100.35000000", "0.00000000"], ["84100.49000000", "0.00000000"], ["84100.60000000", "0.00000000"], ["84100.61000000", "0.04000000"], ["84100.62000000", "0.00000000"], ["84100.64000000", "0.05600000"], ["84100.71000000", "0.00000000"], ["84100.72000000", "0.05943000"], ["84100.80000000", "0.00006000"], ["84100.84000000", "0.01189000"], ["84101.19000000", "0.00000000"], ["84101.28000000", "0.05600000"], ["84101.37000000", "0.05943000"], ["84101.49000000", "0.06000000"], ["84101.52000000", "0.04800000"], ["84101.69000000", "0.89155000"], ["84101.76000000", "0.10601000"], ["84101.85000000", "0.00118000"], ["84101.92000000", "0.00000000"], ["84102.00000000", "0.02760000"], ["84102.03000000", "0.71126000"], ["84102.04000000", "0.00000000"], ["84102.08000000", "0.89155000"], ["84102.48000000", "0.00059000"], ["84102.89000000", "0.00000000"], ["84103.07000000", "0.00000000"], ["84103.12000000", "0.00000000"], ["84103.16000000", "0.00000000"], ["84103.33000000", "0.00000000"], ["84103.34000000", "0.00000000"], ["84103.35000000", "1.63457000"], ["84103.36000000", "0.00000000"], ["84103.37000000", "0.05945000"], ["84103.38000000", "0.00000000"], ["84103.39000000", "0.00000000"], ["84103.40000000", "0.00000000"], ["84103.41000000", "0.00000000"], ["84103.42000000", "0.00000000"], ["84103.43000000", "0.00000000"], ["84103.47000000", "0.00000000"], ["84103.50000000", "0.00000000"], ["84103.52000000", "0.00000000"], ["84103.53000000", "0.61815000"], ["84103.54000000", "0.02019000"], ["84103.55000000", "0.23816000"], ["84103.56000000", "0.00000000"], ["84103.57000000", "0.00000000"], ["84103.58000000", "0.00000000"], ["84103.63000000", "0.00000000"], ["84103.64000000", "0.00000000"], ["84103.65000000", "0.00000000"], ["84103.67000000", "0.00000000"], ["84103.68000000", "0.00000000"], ["84104.00000000", "0.02260000"], ["84104.04000000", "0.00000000"], ["84104.18000000", "0.00013000"], ["84104.27000000", "0.00000000"], ["84104.73000000", "0.00000000"], ["84104.78000000", "0.00000000"], ["84104.84000000", "0.00000000"], ["84104.92000000", "0.00058000"], ["84104.93000000", "0.00000000"], ["84104.94000000", "0.00000000"], ["84105.01000000", "0.00000000"], ["84105.02000000", "0.00000000"], ["84105.03000000", "0.00000000"], ["84105.17000000", "0.11890000"], ["84105.20000000", "0.00000000"], ["84105.26000000", "0.00000000"], ["84105.34000000", "0.08000000"], ["84105.36000000", "0.89155000"], ["84105.37000000", "1.36268000"], ["84105.47000000", "0.00000000"], ["84105.51000000", "0.01189000"], ["84105.64000000", "0.00000000"], ["84105.87000000", "0.00000000"], ["84105.96000000", "0.00000000"], ["84106.02000000", "0.00000000"], ["84106.24000000", "0.00000000"], ["84106.30000000", "0.00000000"], ["84106.31000000", "0.00905000"], ["84106.49000000", "0.00000000"], ["84106.66000000", "1.05155000"], ["84106.69000000", "0.00000000"], ["84107.08000000", "0.00000000"], ["84107.09000000", "0.00000000"], ["84107.11000000", "0.00118000"], ["84107.13000000", "0.00009000"], ["84107.34000000", "0.00000000"], ["84107.38000000", "0.00000000"], ["84107.87000000", "0.01284000"], ["84107.93000000", "0.00000000"], ["84108.04000000", "0.89155000"], ["84108.12000000", "0.00000000"], ["84108.24000000", "0.02814000"], ["84108.32000000", "0.00013000"], ["84108.72000000", "0.47549000"], ["84108.81000000", "0.00000000"], ["84109.01000000", "0.00006000"], ["84109.02000000", "0.05943000"], ["84109.29000000", "0.00000000"], ["84109.70000000", "0.89155000"], ["84109.81000000", "0.05945000"], ["84110.25000000", "0.00000000"], ["84110.39000000", "0.00000000"], ["84110.40000000", "0.00000000"], ["84110.46000000", "0.00000000"], ["84110.49000000", "0.00000000"], ["84110.55000000", "0.00000000"], ["84110.69000000", "0.00000000"], ["84111.01000000", "0.00000000"], ["84111.14000000", "0.00000000"], ["84111.15000000", "0.00000000"], ["84111.16000000", "0.00000000"], ["84111.33000000", "0.00000000"], ["84111.53000000", "0.89155000"], ["84111.54000000", "0.00000000"], ["84111.59000000", "0.00000000"], ["84111.63000000", "1.06089000"], ["84111.73000000", "0.00000000"], ["84111.74000000", "0.00059000"], ["84112.04000000", "0.00000000"], ["84112.72000000", "0.00000000"], ["84113.11000000", "0.00000000"], ["84114.22000000", "0.00000000"], ["84114.33000000", "0.35670000"], ["84114.40000000", "0.00000000"], ["84114.84000000", "0.00000000"], ["84115.14000000", "0.30712000"], ["84115.16000000", "0.00237000"], ["84115.32000000", "0.89155000"], ["84115.35000000", "0.00000000"], ["84115.51000000", "0.01560000"], ["84115.65000000", "0.20145000"], ["84115.66000000", "0.30673000"], ["84115.68000000", "0.05037000"], ["84115.80000000", "0.00000000"], ["84116.11000000", "0.00000000"], ["84116.14000000", "0.00000000"], ["84116.17000000", "0.59494000"], ["84116.28000000", "0.00000000"], ["84116.30000000", "0.85636000"], ["84116.40000000", "0.00000000"], ["84116.77000000", "0.00000000"], ["84116.87000000", "0.04371000"], ["84117.00000000", "0.00059000"], ["84117.57000000", "0.00000000"], ["84117.75000000", "0.00000000"], ["84117.76000000", "0.00000000"], ["84117.81000000", "0.00000000"], ["84118.07000000", "0.00000000"], ["84118.71000000", "0.01646000"], ["84119.40000000", "0.00000000"], ["84119.65000000", "0.00000000"], ["84120.15000000", "0.00059000"], ["84120.17000000", "0.11838000"], ["84120.21000000", "0.00000000"], ["84120.26000000", "0.00013000"], ["84120.27000000", "0.00000000"], ["84120.35000000", "0.00000000"], ["84120.45000000", "0.00000000"], ["84120.93000000", "0.00000000"], ["84121.73000000", "0.23675000"], ["84122.51000000", "0.00000000"], ["84123.04000000", "0.00000000"], ["84123.06000000", "0.00000000"], ["84123.07000000", "0.00000000"], ["84123.89000000", "0.00356000"], ["84124.07000000", "0.00000000"], ["84124.50000000", "0.61148000"], ["84124.72000000", "0.20145000"], ["84124.96000000", "0.00016000"], ["84125.29000000", "0.00000000"], ["84125.71000000", "0.00000000"], ["84126.24000000", "0.00000000"], ["84126.54000000", "0.00000000"], ["84126.97000000", "0.00000000"], ["84127.09000000", "0.00000000"], ["84127.97000000", "0.00000000"], ["84128.39000000", "0.00000000"], ["84128.71000000", "0.00000000"], ["84128.76000000", "0.00784000"], ["84128.77000000", "0.00000000"], ["84128.96000000", "0.00000000"], ["84129.17000000", "0.00000000"], ["84129.57000000", "0.00000000"], ["84129.58000000", "0.00000000"], ["84130.30000000", "0.00059000"], ["84130.61000000", "0.00000000"], ["84130.86000000", "0.00000000"], ["84131.24000000", "0.00000000"], ["84131.29000000", "0.00000000"], ["84131.43000000", "0.00000000"], ["84131.44000000", "0.00000000"], ["84131.92000000", "0.03971000"], ["84132.04000000", "0.00000000"], ["84132.20000000", "0.00676000"], ["84132.41000000", "0.00000000"], ["84133.52000000", "0.00000000"], ["84133.63000000", "0.00000000"], ["84134.93000000", "0.00000000"], ["84135.10000000", "0.05828000"], ["84135.56000000", "0.00000000"], ["84136.75000000", "0.00000000"], ["84137.02000000", "0.00918000"], ["84137.28000000", "0.00000000"], ["84137.87000000", "0.00864000"], ["84138.27000000", "0.00000000"], ["84138.54000000", "0.00811000"], ["84138.62000000", "0.00000000"], ["84139.18000000", "0.00000000"], ["84140.12000000", "0.00000000"], ["84140.33000000", "0.00000000"], ["84140.36000000", "0.00000000"], ["84140.66000000", "0.00000000"], ["84141.10000000", "0.03296000"], ["84142.07000000", "0.05358000"], ["84142.23000000", "0.00000000"], ["84143.68000000", "0.00000000"], ["84145.21000000", "0.00000000"], ["84150.20000000", "0.00000000"], ["84150.94000000", "0.00000000"], ["84153.00000000", "0.00000000"], ["84153.62000000", "0.07052000"], ["84153.84000000", "0.00000000"], ["84154.28000000", "0.00000000"], ["84155.36000000", "0.47331000"], ["84158.44000000", "0.00000000"], ["84161.86000000", "0.00000000"], ["84162.93000000", "0.04800000"], ["84165.11000000", "0.00000000"], ["84165.20000000", "0.01994000"], ["84165.65000000", "0.00000000"], ["84166.72000000", "0.03201000"], ["84167.74000000", "0.00146000"], ["84169.04000000", "0.06800000"], ["84169.05000000", "0.00000000"], ["84170.89000000", "0.22573000"], ["84172.77000000", "0.00000000"], ["84182.66000000", "0.00000000"], ["84183.65000000", "0.00000000"], ["84184.58000000", "0.00000000"], ["84184.87000000", "0.00059000"], ["84185.46000000", "0.05496000"], ["84186.09000000", "0.00000000"], ["84186.30000000", "0.00000000"], ["84188.21000000", "0.00000000"], ["84188.62000000", "0.11509000"], ["84189.86000000", "0.05496000"], ["84191.85000000", "0.00000000"], ["84193.89000000", "0.05496000"], ["84197.49000000", "0.00000000"], ["84197.56000000", "0.05496000"], ["84197.79000000", "0.05496000"], ["84198.05000000", "0.00000000"], ["84198.76000000", "0.09852000"], ["84199.78000000", "0.00000000"], ["84200.16000000", "0.05496000"], ["84201.67000000", "0.09512000"], ["84203.14000000", "0.04637000"], ["84203.42000000", "0.05496000"], ["84206.70000000", "0.04997000"], ["84213.26000000", "0.00000000"], ["84214.06000000", "0.00000000"], ["84217.22000000", "0.05297000"], ["84220.39000000", "0.10495000"], ["84220.49000000", "0.02186000"], ["84221.77000000", "0.05505000"], ["84223.88000000", "0.00000000"], ["84225.96000000", "0.00000000"], ["84227.09000000", "0.00000000"], ["84227.56000000", "0.00405000"], ["84227.68000000", "0.00000000"], ["84228.24000000", "0.00000000"], ["84231.64000000", "0.00000000"], ["84232.92000000", "0.00000000"], ["84235.11000000", "0.00000000"], ["84235.92000000", "0.00000000"], ["84237.24000000", "0.00000000"], ["84239.04000000", "0.00000000"], ["84241.88000000", "0.00000000"], ["84245.38000000", "0.00000000"], ["84250.43000000", "0.00000000"], ["84250.90000000", "0.00000000"], ["84259.89000000", "0.00118000"], ["84260.54000000", "0.00000000"], ["84261.63000000", "0.01000000"], ["84264.24000000", "0.00000000"], ["84264.74000000", "0.00000000"], ["84266.25000000", "0.00000000"], ["84266.82000000", "0.02040000"], ["84267.05000000", "0.00000000"], ["84267.85000000", "0.00000000"], ["84269.48000000", "0.99359000"], ["84271.36000000", "0.00000000"], ["84275.87000000", "0.00000000"], ["84285.63000000", "0.00000000"], ["84315.38000000", "0.00000000"], ["84339.91000000", "0.00000000"], ["84344.11000000", "0.00000000"], ["84346.76000000", "0.00000000"], ["84357.38000000", "0.00000000"], ["84358.04000000", "0.00000000"], ["84359.54000000", "0.00000000"], ["84362.60000000", "0.00000000"], ["84363.07000000", "0.00000000"], ["84364.91000000", "0.20149000"], ["84367.48000000", "0.00000000"], ["84370.35000000", "0.00000000"], ["84372.88000000", "0.00000000"], ["84373.31000000", "0.20149000"], ["84374.84000000", "0.00000000"], ["84375.13000000", "0.00000000"], ["84375.58000000", "0.00000000"], ["84375.89000000", "0.00000000"], ["84379.87000000", "0.00000000"], ["84381.29000000", "0.00000000"], ["84381.71000000", "0.18191000"], ["84383.55000000", "0.00000000"], ["84385.43000000", "0.00000000"], ["84392.38000000", "0.00000000"], ["84443.27000000", "0.00402000"], ["85316.86000000", "0.10000000"], ["85349.10000000", "0.11733000"], ["85365.09000000", "0.00000000"], ["85368.06000000", "0.00000000"], ["85370.40000000", "0.01467000"], ["85391.70000000", "0.05871000"], ["85413.00000000", "0.00036000"], ["150001.00000000", "0.00052000"]], "record_time": 1742584907.128919, "EXCHANGE": "BINANCE"}
{"e": "depthUpdate", "E": 1742584908014, "s": "BTCUSDT", "U": 64637896131, "u": 64637897613, "b": [["84086.00000000", "0.00000000"], ["84085.99000000", "0.00000000"], ["84085.62000000", "0.00000000"], ["84085.41000000", "0.00000000"], ["84085.40000000", "0.00000000"], ["84085.39000000", "0.00000000"], ["84085.36000000", "0.00000000"], ["84085.29000000", "0.00000000"], ["84085.28000000", "0.00000000"], ["84085.18000000", "0.00000000"], ["84085.15000000", "0.00000000"], ["84085.13000000", "0.00000000"], ["84084.78000000", "0.00000000"], ["84083.80000000", "0.00000000"], ["84083.30000000", "0.00000000"], ["84083.29000000", "0.04011000"], ["84083.28000000", "0.00059000"], ["84083.11000000", "0.00208000"], ["84083.09000000", "0.00014000"], ["84082.83000000", "0.00000000"], ["84082.66000000", "0.00046000"], ["84082.65000000", "0.00007000"], ["84082.64000000", "0.00007000"], ["84082.49000000", "0.00000000"], ["84082.38000000", "0.00000000"], ["84082.37000000", "0.00000000"], ["84082.25000000", "0.00014000"], ["84082.20000000", "0.00000000"], ["84082.19000000", "0.00000000"], ["84082.01000000", "0.00000000"], ["84082.00000000", "0.00000000"], ["84081.90000000", "0.00024000"], ["84081.89000000", "0.02436000"], ["84081.69000000", "0.00000000"], ["84081.54000000", "0.00301000"], ["84081.42000000", "0.00000000"], ["84081.37000000", "0.00000000"], ["84081.36000000", "0.00000000"], ["84080.98000000", "0.00000000"], ["84080.85000000", "0.00503000"], ["84080.70000000", "0.00027000"], ["84080.69000000", "0.06584000"], ["84080.60000000", "0.00000000"], ["84080.44000000", "0.00000000"], ["84080.34000000", "0.00030000"], ["84080.33000000", "0.13800000"], ["84080.21000000", "0.00000000"], ["84079.94000000", "0.00000000"], ["84079.93000000", "0.00000000"], ["84079.88000000", "0.00008000"], ["84079.67000000", "0.00019000"], ["84079.66000000", "0.02546000"], ["84079.61000000", "0.00014000"], ["84079.60000000", "0.27135000"], ["84079.41000000", "0.00000000"], ["84079.28000000", "0.00000000"], ["84078.93000000", "0.00000000"], ["84078.92000000", "0.00000000"], ["84078.78000000", "0.16219000"], ["84078.75000000", "0.00000000"], ["84078.61000000", "0.00000000"], ["84078.60000000", "0.00000000"], ["84078.39000000", "0.02206000"], ["84078.33000000", "0.00000000"], ["84078.25000000", "0.00000000"], ["84077.89000000", "0.00000000"], ["84077.88000000", "0.00000000"], ["84077.78000000", "0.00000000"], ["84077.77000000", "0.00000000"], ["84077.68000000", "0.00000000"], ["84077.50000000", "0.00000000"], ["84076.82000000", "0.00000000"], ["84076.81000000", "0.00000000"], ["84076.66000000", "0.00000000"], ["84076.57000000", "0.00056000"], ["84076.34000000", "0.00000000"], ["84076.09000000", "0.00000000"], ["84076.08000000", "0.00200000"], ["84075.92000000", "0.00000000"], ["84075.91000000", "0.00000000"], ["84075.68000000", "0.00000000"], ["84075.60000000", "0.00000000"], ["84075.58000000", "0.00000000"], ["84075.50000000", "0.00000000"], ["84075.35000000", "0.00000000"], ["84074.97000000", "0.00118000"], ["84074.96000000", "0.00000000"], ["84074.93000000", "0.00000000"], ["84074.81000000", "0.00000000"], ["84074.41000000", "0.00000000"], ["84074.21000000", "0.00000000"], ["84074.13000000", "0.00000000"], ["84073.99000000", "0.00000000"], ["84073.74000000", "0.04000000"], ["84073.66000000", "0.00000000"], ["84073.65000000", "0.00000000"], ["84073.61000000", "0.00000000"], ["84073.40000000", "0.00000000"], ["84073.29000000", "0.00000000"], ["84072.90000000", "0.04000000"], ["84072.80000000", "0.00000000"], ["84072.44000000", "0.00000000"], ["84072.39000000", "0.00000000"], ["84072.06000000", "0.08000000"], ["84072.00000000", "0.04000000"], ["84071.82000000", "0.00000000"], ["84071.77000000", "0.00000000"], ["84071.40000000", "0.00000000"], ["84071.29000000", "0.00000000"], ["84070.69000000", "0.01189000"], ["84070.45000000", "0.00000000"], ["84070.01000000", "0.14000000"], ["84069.59000000", "0.00007000"], ["84069.54000000", "0.04000000"], ["84069.49000000", "0.14739000"], ["84069.39000000", "0.00000000"], ["84069.38000000", "0.30185000"], ["84069.24000000", "0.00000000"], ["84069.19000000", "0.00059000"], ["84069.18000000", "0.00000000"], ["84068.69000000", "0.04000000"], ["84068.65000000", "0.00000000"], ["84068.61000000", "0.04000000"], ["84068.25000000", "0.00000000"], ["84068.07000000", "0.00000000"], ["84067.95000000", "0.00000000"], ["84067.85000000", "0.08000000"], ["84067.80000000", "0.04000000"], ["84067.53000000", "0.00000000"], ["84067.47000000", "0.15687000"], ["84067.26000000", "0.00000000"], ["84067.05000000", "0.00000000"], ["84066.47000000", "0.45000000"], ["84066.22000000", "0.00000000"], ["84066.15000000", "0.00000000"], ["84065.41000000", "0.05353000"], ["84065.38000000", "0.03000000"], ["84065.25000000", "0.00000000"], ["84064.79000000", "0.00029000"], ["84064.74000000", "0.00090000"], ["84064.64000000", "0.30728000"], ["84064.59000000", "0.13418000"], ["84063.82000000", "0.00000000"], ["84063.45000000", "0.16000000"], ["84063.23000000", "0.00000000"], ["84063.22000000", "0.00000000"], ["84062.91000000", "0.00000000"], ["84062.60000000", "0.00000000"], ["84062.14000000", "0.00000000"], ["84061.57000000", "0.00090000"], ["84061.44000000", "0.32679000"], ["84060.89000000", "0.16280000"], ["84060.77000000", "0.00300000"], ["84060.50000000", "0.00922000"], ["84060.07000000", "0.51342000"], ["84057.94000000", "0.00000000"], ["84057.32000000", "0.00000000"], ["84057.21000000", "0.05943000"], ["84056.93000000", "0.00000000"], ["84056.60000000", "0.00000000"], ["84056.32000000", "0.00000000"], ["84056.30000000", "0.10600000"], ["84056.06000000", "0.00000000"], ["84055.97000000", "0.00000000"], ["84055.96000000", "0.00000000"], ["84055.75000000", "0.00000000"], ["84055.48000000", "0.00000000"], ["84055.00000000", "0.01189000"], ["84054.85000000", "0.39649000"], ["84053.55000000", "0.01189000"], ["84053.23000000", "0.00000000"], ["84053.21000000", "0.85701000"], ["84052.30000000", "0.00000000"], ["84050.59000000", "0.00357000"], ["84050.52000000", "1.11555000"], ["84050.27000000", "0.00000000"], ["84050.01000000", "0.00000000"], ["84048.52000000", "0.04000000"], ["84048.35000000", "1.27340000"], ["84047.45000000", "0.59498000"], ["84047.44000000", "0.00000000"], ["84046.62000000", "0.00000000"], ["84046.20000000", "0.00006000"], ["84045.88000000", "0.89155000"], ["84044.32000000", "0.00000000"], ["84044.16000000", "1.48558000"], ["84043.00000000", "0.85711000"], ["84042.20000000", "0.00146000"], ["84042.18000000", "0.00000000"], ["84042.02000000", "0.54764000"], ["84041.34000000", "0.00000000"], ["84041.24000000", "0.00059000"], ["84040.73000000", "0.00000000"], ["84040.44000000", "0.89155000"], ["84040.43000000", "0.39143000"], ["84040.18000000", "0.89155000"], ["84040.04000000", "0.04000000"], ["84040.00000000", "0.37899000"], ["84038.39000000", "0.11441000"], ["84036.64000000", "0.34855000"], ["84036.00000000", "0.00210000"], ["84035.61000000", "0.00000000"], ["84035.42000000", "0.03944000"], ["84031.63000000", "0.00000000"], ["84028.06000000", "0.00000000"], ["84027.45000000", "0.22631000"], ["84026.16000000", "0.04228000"], ["84025.27000000", "0.05000000"], ["84024.85000000", "0.00000000"], ["84024.84000000", "0.00000000"], ["84024.17000000", "0.26132000"], ["84023.01000000", "0.01190000"], ["84019.64000000", "0.00000000"], ["84019.07000000", "0.09641000"], ["84018.71000000", "0.05252000"], ["84018.12000000", "0.05000000"], ["84017.83000000", "0.31936000"], ["84017.78000000", "0.04000000"], ["84014.58000000", "0.47549000"], ["84014.30000000", "0.00847000"], ["84013.16000000", "0.00061000"], ["84010.49000000", "0.00813000"], ["84007.84000000", "0.04000000"], ["84005.26000000", "0.00000000"], ["84002.17000000", "0.00000000"], ["84001.05000000", "0.00000000"], ["84000.12000000", "0.00000000"], ["83997.97000000", "0.00000000"], ["83996.75000000", "0.00000000"], ["83996.44000000", "0.50931000"], ["83995.90000000", "0.00000000"], ["83993.99000000", "1.02865000"], ["83991.08000000", "0.00000000"], ["83989.26000000", "0.89384000"], ["83988.26000000", "0.05497000"], ["83986.56000000", "0.04638000"], ["83986.18000000", "0.10254000"], ["83985.16000000", "0.63092000"], ["83984.74000000", "0.00000000"], ["83983.90000000", "0.04638000"], ["83983.47000000", "0.00000000"], ["83979.76000000", "0.00000000"], ["83979.75000000", "0.00000000"], ["83975.69000000", "1.10816000"], ["83975.49000000", "0.00000000"], ["83974.43000000", "0.00000000"], ["83972.62000000", "0.05297000"], ["83972.10000000", "0.00083000"], ["83972.09000000", "0.00000000"], ["83970.81000000", "0.04497000"], ["83970.44000000", "0.00000000"], ["83969.02000000", "0.00000000"], ["83967.92000000", "0.00000000"], ["83967.58000000", "0.10794000"], ["83967.55000000", "0.00000000"], ["83966.40000000", "0.00006000"], ["83966.37000000", "0.00000000"], ["83966.23000000", "0.04197000"], ["83966.11000000", "0.16490000"], ["83965.28000000", "0.05297000"], ["83963.21000000", "0.05097000"], ["83963.07000000", "0.04197000"], ["83962.69000000", "0.05297000"], ["83962.52000000", "0.05497000"], ["83962.38000000", "0.05497000"], ["83960.03000000", "0.04497000"], ["83959.77000000", "0.05297000"], ["83957.42000000", "0.04197000"], ["83955.73000000", "0.04497000"], ["83954.15000000", "0.04997000"], ["83951.66000000", "0.04497000"], ["83951.57000000", "0.04197000"], ["83950.69000000", "0.05003000"], ["83950.28000000", "0.04997000"], ["83945.86000000", "0.04497000"], ["83930.90000000", "0.99313000"], ["83928.45000000", "0.00000000"], ["83925.70000000", "0.00000000"], ["83925.67000000", "0.00006000"], ["83923.60000000", "0.00000000"], ["83922.26000000", "0.01000000"], ["83922.08000000", "0.00000000"], ["83915.07000000", "0.00000000"], ["83900.02000000", "0.00000000"], ["83896.02000000", "0.00069000"], ["83896.01000000", "0.00000000"], ["83869.10000000", "0.01861000"], ["83863.56000000", "0.00013000"], ["83857.89000000", "0.00000000"], ["83852.62000000", "0.00000000"], ["83851.55000000", "0.18191000"], ["83848.70000000", "0.00000000"], ["83847.42000000", "0.00400000"], ["83846.39000000", "0.00000000"], ["83844.24000000", "0.18149000"], ["83843.16000000", "0.82001000"], ["83837.99000000", "0.00000000"], ["83835.84000000", "0.02040000"], ["83432.65000000", "0.00119000"], ["82824.71000000", "0.00000000"], ["80697.27000000", "0.00000000"], ["75677.00000000", "0.00020000"], ["67268.80000000", "0.00000000"], ["67266.64000000", "0.00058000"], ["33000.00000000", "2.93827000"], ["30223.89000000", "0.00020000"], ["30215.18000000", "0.00020000"], ["30207.68000000", "0.00020000"], ["30206.67000000", "0.00020000"], ["30205.46000000", "0.00020000"], ["30198.80000000", "0.00220000"], ["30196.96000000", "0.00100000"], ["30195.30000000", "0.00260000"], ["30176.85000000", "0.00020000"], ["30176.53000000", "0.00060000"], ["30173.48000000", "0.00500000"], ["30171.04000000", "0.00080000"], ["30168.00000000", "0.00120000"], ["30166.99000000", "0.00060000"], ["30166.71000000", "0.00240000"], ["30157.57000000", "0.00100000"], ["30155.74000000", "0.00100000"], ["30155.48000000", "0.00060000"], ["30150.00000000", "0.02742000"], ["30136.27000000", "0.00000000"], ["21030.20000000", "0.00071000"]], "a": [["84083.30000000", "8.36768000"], ["84083.31000000", "0.00068000"], ["84083.72000000", "0.00209000"], ["84083.93000000", "0.00014000"], ["84083.99000000", "0.00021000"], ["84084.00000000", "0.02322000"], ["84084.25000000", "0.00021000"], ["84084.26000000", "0.01209000"], ["84084.79000000", "0.00028000"], ["84084.96000000", "0.00021000"], ["84084.97000000", "0.01230000"], ["84085.30000000", "0.00007000"], ["84085.37000000", "0.00007000"], ["84085.40000000", "0.00000000"], ["84085.41000000", "0.00000000"], ["84085.42000000", "0.00000000"], ["84085.61000000", "0.00007000"], ["84085.63000000", "0.00000000"], ["84085.89000000", "0.00000000"], ["84085.90000000", "0.00000000"], ["84085.96000000", "0.00014000"], ["84085.97000000", "0.95823000"], ["84085.98000000", "0.00000000"], ["84085.99000000", "0.00000000"], ["84086.00000000", "0.10620000"], ["84086.01000000", "2.39042000"], ["84086.02000000", "0.00000000"], ["84086.13000000", "0.00000000"], ["84086.14000000", "0.00000000"], ["84086.15000000", "0.89155000"], ["84086.92000000", "0.00007000"], ["84086.93000000", "0.02228000"], ["84087.05000000", "0.00000000"], ["84087.06000000", "0.00000000"], ["84087.24000000", "0.00000000"], ["84087.27000000", "0.00000000"], ["84087.28000000", "0.00000000"], ["84087.68000000", "0.00000000"], ["84087.83000000", "0.04800000"], ["84087.93000000", "0.16217000"], ["84087.94000000", "0.16000000"], ["84087.99000000", "0.00000000"], ["84088.00000000", "0.02260000"], ["84088.20000000", "0.00006000"], ["84088.21000000", "0.00000000"], ["84088.22000000", "0.00000000"], ["84088.24000000", "0.00000000"], ["84088.25000000", "0.17899000"], ["84088.26000000", "0.00000000"], ["84088.58000000", "0.05946000"], ["84089.09000000", "0.00000000"], ["84089.25000000", "0.02378000"], ["84089.28000000", "0.04400000"], ["84089.63000000", "0.01100000"], ["84089.64000000", "0.00000000"], ["84089.83000000", "0.00000000"], ["84089.99000000", "0.00000000"], ["84090.00000000", "0.02260000"], ["84090.02000000", "0.01189000"], ["84090.20000000", "0.00500000"], ["84090.66000000", "0.23477000"], ["84090.70000000", "0.35968000"], ["84090.96000000", "0.06400000"], ["84090.97000000", "0.06800000"], ["84091.00000000", "0.00000000"], ["84091.53000000", "0.04400000"], ["84092.29000000", "0.00118000"], ["84092.73000000", "0.00000000"], ["84092.85000000", "0.00000000"], ["84093.03000000", "0.14056000"], ["84093.08000000", "0.01189000"], ["84093.61000000", "0.00000000"], ["84093.79000000", "0.00013000"], ["84094.32000000", "0.05600000"], ["84094.90000000", "1.00000000"], ["84094.91000000", "0.70516000"], ["84094.92000000", "0.00000000"], ["84095.19000000", "0.04000000"], ["84095.59000000", "0.00000000"], ["84095.90000000", "0.01189000"], ["84095.93000000", "0.00059000"], ["84096.44000000", "0.00000000"], ["84096.57000000", "0.11600000"], ["84096.91000000", "0.71126000"], ["84097.07000000", "0.00000000"], ["84097.28000000", "0.00000000"], ["84097.52000000", "0.00058000"], ["84097.82000000", "0.21094000"], ["84098.59000000", "0.00057000"], ["84098.61000000", "0.00000000"], ["84098.77000000", "0.00000000"], ["84099.92000000", "1.31351000"], ["84100.05000000", "0.00000000"], ["84100.11000000", "0.00000000"], ["84100.61000000", "0.00000000"], ["84100.64000000", "0.00000000"], ["84100.71000000", "0.01284000"], ["84100.84000000", "0.00000000"], ["84101.28000000", "0.00000000"], ["84101.49000000", "0.00000000"], ["84101.52000000", "0.00000000"], ["84101.62000000", "0.00000000"], ["84101.76000000", "0.00000000"], ["84102.22000000", "0.00007000"], ["84102.75000000", "1.00000000"], ["84102.83000000", "0.00059000"], ["84103.42000000", "0.05000000"], ["84103.53000000", "0.61633000"], ["84103.54000000", "0.03040000"], ["84103.55000000", "0.00026000"], ["84103.82000000", "0.00000000"], ["84103.96000000", "0.00000000"], ["84103.97000000", "0.00006000"], ["84104.92000000", "0.00000000"], ["84105.30000000", "0.00000000"], ["84105.34000000", "0.00000000"], ["84105.51000000", "0.00000000"], ["84106.01000000", "0.59437000"], ["84106.66000000", "0.89155000"], ["84106.84000000", "0.00000000"], ["84107.31000000", "0.01967000"], ["84107.83000000", "0.01040000"], ["84107.87000000", "0.00000000"], ["84107.90000000", "0.79636000"], ["84108.00000000", "0.00000000"], ["84108.72000000", "0.00000000"], ["84109.43000000", "0.00000000"], ["84110.20000000", "0.20150000"], ["84111.24000000", "0.00300000"], ["84111.26000000", "0.00000000"], ["84111.53000000", "0.00000000"], ["84111.74000000", "0.00000000"], ["84111.94000000", "0.00151000"], ["84111.95000000", "0.45000000"], ["84112.25000000", "0.38996000"], ["84113.39000000", "0.11798000"], ["84113.93000000", "0.00100000"], ["84115.88000000", "0.00000000"], ["84116.16000000", "0.52917000"], ["84116.30000000", "0.00000000"], ["84116.88000000", "0.00575000"], ["84118.93000000", "0.00000000"], ["84119.52000000", "0.00000000"], ["84120.17000000", "0.00000000"], ["84120.92000000", "0.05786000"], ["84124.50000000", "0.41227000"], ["84125.34000000", "0.00059000"], ["84126.67000000", "0.00859000"], ["84126.68000000", "0.00000000"], ["84127.61000000", "0.00000000"], ["84128.44000000", "0.01188000"], ["84128.55000000", "0.02161000"], ["84128.62000000", "0.00000000"], ["84129.48000000", "0.00000000"], ["84130.30000000", "0.00000000"], ["84130.62000000", "0.37636000"], ["84133.02000000", "0.06400000"], ["84133.39000000", "0.00000000"], ["84133.52000000", "0.52017000"], ["84133.93000000", "0.00000000"], ["84135.10000000", "0.00000000"], ["84135.65000000", "0.00000000"], ["84136.21000000", "0.05297000"], ["84137.87000000", "0.00000000"], ["84138.53000000", "0.04997000"], ["84139.10000000", "0.04497000"], ["84140.58000000", "0.04497000"], ["84140.82000000", "0.00000000"], ["84141.03000000", "0.04997000"], ["84141.05000000", "0.01242000"], ["84145.62000000", "0.00776000"], ["84149.99000000", "0.53611000"], ["84151.22000000", "1.02673000"], ["84152.77000000", "0.05600000"], ["84153.02000000", "0.00000000"], ["84155.35000000", "0.04197000"], ["84159.46000000", "0.05179000"], ["84160.15000000", "0.04400000"], ["84163.16000000", "0.33755000"], ["84164.97000000", "0.00000000"], ["84165.19000000", "0.05600000"], ["84169.17000000", "0.01100000"], ["84176.44000000", "0.09623000"], ["84176.53000000", "0.00000000"], ["84178.20000000", "0.01861000"], ["84180.15000000", "0.00059000"], ["84182.60000000", "0.02380000"], ["84184.87000000", "0.00000000"], ["84188.75000000", "0.00814000"], ["84196.50000000", "0.00000000"], ["84199.60000000", "0.01967000"], ["84203.52000000", "0.00960000"], ["84207.39000000", "0.05297000"], ["84208.87000000", "0.05097000"], ["84211.39000000", "0.06238000"], ["84212.58000000", "0.00000000"], ["84212.89000000", "0.04997000"], ["84213.47000000", "0.00954000"], ["84213.96000000", "0.04997000"], ["84215.71000000", "0.05297000"], ["84215.88000000", "0.00000000"], ["84217.52000000", "0.04997000"], ["84217.78000000", "0.04497000"], ["84219.88000000", "0.06722000"], ["84220.49000000", "0.06683000"], ["84221.05000000", "0.05297000"], ["84222.45000000", "0.00954000"], ["84222.83000000", "0.02497000"], ["84226.32000000", "0.00000000"], ["84226.43000000", "0.00000000"], ["84226.81000000", "0.00000000"], ["84226.86000000", "0.00000000"], ["84227.99000000", "0.00000000"], ["84228.01000000", "0.00000000"], ["84228.31000000", "0.00000000"], ["84228.96000000", "0.00000000"], ["84232.41000000", "0.00000000"], ["84240.44000000", "0.00000000"], ["84240.75000000", "0.01396000"], ["84241.11000000", "0.00000000"], ["84242.27000000", "0.01979000"], ["84242.58000000", "0.00000000"], ["84242.99000000", "0.00000000"], ["84249.23000000", "0.01100000"], ["84256.52000000", "0.01000000"], ["84257.22000000", "0.00000000"], ["84258.03000000", "0.00000000"], ["84258.63000000", "0.00000000"], ["84258.73000000", "0.00000000"], ["84259.14000000", "0.02067000"], ["84259.42000000", "0.00999000"], ["84259.89000000", "0.00000000"], ["84261.63000000", "0.00000000"], ["84263.33000000", "0.00000000"], ["84268.52000000", "0.00119000"], ["84337.53000000", "0.00000000"], ["84370.60000000", "0.18190000"], ["84373.31000000", "0.00000000"], ["84381.71000000", "0.00000000"], ["85299.80000000", "0.10000000"], ["85347.30000000", "0.00015000"], ["85347.31000000", "0.00100000"], ["85350.99000000", "0.00006000"], ["150001.00000000", "0.00000000"]], "record_time": 1742584908.128157, "EXCHANGE": "BINANCE"}
{"e": "depthUpdate", "E": 1742584909014, "s": "BTCUSDT", "U": 64637897614, "u": 64637899327, "b": [["84083.29000000", "0.00000000"], ["84083.28000000", "0.00000000"], ["84083.19000000", "0.00000000"], ["84083.11000000", "0.00000000"], ["84083.09000000", "0.00000000"], ["84082.66000000", "0.00000000"], ["84082.65000000", "0.00000000"], ["84082.64000000", "0.00000000"], ["84082.25000000", "0.00000000"], ["84081.90000000", "0.00000000"], ["84081.89000000", "0.00000000"], ["84081.55000000", "0.00000000"], ["84081.54000000", "0.00000000"], ["84081.47000000", "0.00000000"], ["84081.41000000", "0.00000000"], ["84081.07000000", "0.00000000"], ["84080.92000000", "0.00000000"], ["84080.91000000", "0.00000000"], ["84080.90000000", "0.00000000"], ["84080.86000000", "0.00000000"], ["84080.85000000", "0.00000000"], ["84080.70000000", "0.00000000"], ["84080.69000000", "0.00000000"], ["84080.34000000", "0.00000000"], ["84080.33000000", "0.00000000"], ["84080.26000000", "0.00000000"], ["84080.15000000", "0.00000000"], ["84080.01000000", "0.00000000"], ["84080.00000000", "0.00000000"], ["84079.97000000", "0.00000000"], ["84079.88000000", "0.00000000"], ["84079.83000000", "0.00000000"], ["84079.82000000", "0.00000000"], ["84079.67000000", "0.00000000"], ["84079.66000000", "0.00000000"], ["84079.61000000", "0.00000000"], ["84079.60000000", "0.00000000"], ["84079.39000000", "0.00000000"], ["84079.11000000", "0.00000000"], ["84079.01000000", "0.00000000"], ["84078.87000000", "0.00000000"], ["84078.78000000", "0.00000000"], ["84078.48000000", "0.00000000"], ["84078.47000000", "0.00074000"], ["84078.46000000", "0.00034000"], ["84078.44000000", "0.00020000"], ["84078.40000000", "0.00000000"], ["84078.39000000", "0.00000000"], ["84077.89000000", "0.00000000"], ["84077.81000000", "0.00046000"], ["84077.80000000", "0.00014000"], ["84077.79000000", "0.00007000"], ["84077.48000000", "0.00014000"], ["84077.47000000", "0.00000000"], ["84077.30000000", "0.00000000"], ["84077.29000000", "0.00025000"], ["84077.28000000", "0.00000000"], ["84077.20000000", "0.00000000"], ["84077.19000000", "0.00000000"], ["84077.09000000", "0.00000000"], ["84077.08000000", "0.00000000"], ["84076.99000000", "0.00000000"], ["84076.93000000", "0.00000000"], ["84076.92000000", "0.00000000"], ["84076.57000000", "0.00000000"], ["84076.46000000", "0.03351000"], ["84076.30000000", "0.00016000"], ["84076.29000000", "0.00000000"], ["84076.28000000", "0.00014000"], ["84076.27000000", "0.00000000"], ["84076.22000000", "0.00000000"], ["84076.03000000", "0.00505000"], ["84075.48000000", "0.00030000"], ["84075.47000000", "0.07367000"], ["84075.25000000", "0.00014000"], ["84075.24000000", "0.14062000"], ["84074.97000000", "0.00000000"], ["84074.96000000", "0.00000000"], ["84074.84000000", "0.02546000"], ["84074.81000000", "0.00006000"], ["84074.80000000", "0.00000000"], ["84074.75000000", "0.00000000"], ["84074.19000000", "0.00000000"], ["84074.08000000", "0.00000000"], ["84073.98000000", "0.06371000"], ["84073.74000000", "0.04000000"], ["84073.66000000", "0.00301000"], ["84073.30000000", "0.02207000"], ["84072.59000000", "0.00000000"], ["84071.75000000", "0.00000000"], ["84070.69000000", "0.00000000"], ["84070.15000000", "0.00118000"], ["84069.38000000", "0.00000000"], ["84068.31000000", "0.00000000"], ["84067.90000000", "0.00000000"], ["84066.81000000", "0.00000000"], ["84066.47000000", "0.00000000"], ["84065.87000000", "0.01189000"], ["84065.41000000", "0.00000000"], ["84064.81000000", "0.05353000"], ["84064.59000000", "0.00000000"], ["84063.04000000", "0.00000000"], ["84061.82000000", "0.00118000"], ["84060.77000000", "0.66067000"], ["84060.76000000", "0.00000000"], ["84060.07000000", "0.00000000"], ["84059.77000000", "0.00885000"], ["84059.55000000", "0.00007000"], ["84058.80000000", "0.02412000"], ["84057.30000000", "0.00000000"], ["84057.26000000", "0.05855000"], ["84057.22000000", "0.00000000"], ["84057.21000000", "0.00000000"], ["84057.06000000", "0.00000000"], ["84056.94000000", "0.00101000"], ["84056.30000000", "0.00000000"], ["84054.46000000", "0.00757000"], ["84053.56000000", "0.00000000"], ["84053.21000000", "0.00000000"], ["84052.34000000", "0.05943000"], ["84051.83000000", "1.39662000"], ["84051.11000000", "0.35662000"], ["84050.83000000", "0.13418000"], ["84050.72000000", "0.00000000"], ["84050.51000000", "0.00000000"], ["84047.45000000", "0.00000000"], ["84047.44000000", "0.59498000"], ["84043.90000000", "0.00000000"], ["84043.68000000", "0.85710000"], ["84043.00000000", "0.00000000"], ["84042.62000000", "0.00000000"], ["84041.22000000", "0.00358000"], ["84038.50000000", "0.85716000"], ["84037.94000000", "0.02817000"], ["84037.39000000", "0.02376000"], ["84035.42000000", "0.30105000"], ["84034.43000000", "0.88844000"], ["84032.01000000", "0.00000000"], ["84030.48000000", "0.00000000"], ["84025.57000000", "0.05000000"], ["84025.27000000", "0.00000000"], ["84024.18000000", "0.00295000"], ["84022.82000000", "0.00000000"], ["84020.83000000", "0.05796000"], ["84020.55000000", "0.00000000"], ["84020.00000000", "0.00333000"], ["84018.12000000", "0.00000000"], ["84016.22000000", "0.00000000"], ["84013.16000000", "0.00000000"], ["84012.51000000", "0.00000000"], ["84010.87000000", "0.00000000"], ["84008.93000000", "0.00061000"], ["84006.62000000", "0.00000000"], ["84005.78000000", "0.00000000"], ["84002.55000000", "0.00297000"], ["83999.99000000", "0.03570000"], ["83987.34000000", "0.00000000"], ["83981.39000000", "0.12900000"], ["83978.44000000", "0.01196000"], ["83977.93000000", "0.04638000"], ["83930.90000000", "0.00000000"], ["83927.92000000", "0.99313000"], ["83927.55000000", "0.00006000"], ["83922.26000000", "0.00000000"], ["83921.96000000", "0.01000000"], ["83869.10000000", "0.00000000"], ["83859.90000000", "0.00000000"], ["83854.47000000", "0.00400000"], ["83853.90000000", "0.00000000"], ["83848.70000000", "0.00013000"], ["83847.42000000", "0.00000000"], ["83844.50000000", "0.00000000"], ["83842.58000000", "0.00000000"], ["83835.69000000", "0.00000000"], ["82819.69000000", "0.00100000"], ["80697.27000000", "0.03567000"], ["75677.00000000", "0.00000000"], ["75674.00000000", "0.00000000"], ["75672.00000000", "0.00897000"], ["67266.64000000", "0.00000000"], ["67264.73000000", "0.00000000"], ["67262.78000000", "0.00058000"], ["33000.00000000", "2.93827000"], ["30269.13000000", "0.00040000"], ["30225.93000000", "0.00020000"], ["30220.44000000", "0.00020000"], ["30211.76000000", "0.00100000"], ["30208.95000000", "0.00120000"], ["30195.30000000", "0.00240000"], ["30186.08000000", "0.00000000"], ["30173.48000000", "0.00480000"], ["30171.74000000", "0.00280000"], ["30166.71000000", "0.00220000"], ["30165.84000000", "0.00080000"], ["30160.76000000", "0.00000000"], ["30158.98000000", "0.00040000"], ["30154.76000000", "0.00040000"], ["30153.60000000", "0.00000000"], ["30139.08000000", "0.00020000"], ["21030.20000000", "0.00071000"]], "a": [["84078.48000000", "8.55359000"], ["84078.49000000", "0.00034000"], ["84078.86000000", "0.00014000"], ["84079.99000000", "0.00021000"], ["84080.00000000", "0.02301000"], ["84080.14000000", "0.00021000"], ["84080.15000000", "0.01209000"], ["84080.26000000", "0.00007000"], ["84080.27000000", "0.00021000"], ["84080.34000000", "0.00007000"], ["84080.35000000", "0.00000000"], ["84080.69000000", "0.00000000"], ["84080.70000000", "0.00000000"], ["84080.71000000", "0.00000000"], ["84080.80000000", "0.00014000"], ["84080.81000000", "0.41013000"], ["84080.86000000", "0.00000000"], ["84080.87000000", "0.00000000"], ["84080.90000000", "0.00014000"], ["84080.91000000", "2.27811000"], ["84080.92000000", "2.21402000"], ["84080.93000000", "0.00013000"], ["84081.20000000", "0.00000000"], ["84081.21000000", "0.04006000"], ["84081.40000000", "0.00000000"], ["84081.54000000", "0.00000000"], ["84081.55000000", "0.00000000"], ["84081.89000000", "0.00000000"], ["84081.90000000", "0.00000000"], ["84081.98000000", "0.00021000"], ["84081.99000000", "0.00000000"], ["84082.00000000", "0.02266000"], ["84082.11000000", "0.02228000"], ["84082.26000000", "0.00000000"], ["84082.30000000", "0.00000000"], ["84082.58000000", "0.00000000"], ["84082.59000000", "0.00000000"], ["84082.65000000", "0.00000000"], ["84082.66000000", "0.00000000"], ["84082.67000000", "0.00000000"], ["84083.08000000", "0.00000000"], ["84083.10000000", "0.00000000"], ["84083.12000000", "0.00000000"], ["84083.18000000", "0.00000000"], ["84083.20000000", "0.00000000"], ["84083.26000000", "0.00000000"], ["84083.27000000", "1.77703000"], ["84083.28000000", "0.00000000"], ["84083.29000000", "0.00000000"], ["84083.30000000", "2.06593000"], ["84083.31000000", "0.00000000"], ["84083.72000000", "0.00000000"], ["84083.93000000", "0.00000000"], ["84083.99000000", "0.00000000"], ["84084.00000000", "0.02266000"], ["84084.25000000", "0.00000000"], ["84084.26000000", "0.00000000"], ["84084.55000000", "0.00000000"], ["84084.79000000", "0.00000000"], ["84084.96000000", "0.00000000"], ["84084.97000000", "0.00000000"], ["84085.20000000", "0.01189000"], ["84085.30000000", "0.00000000"], ["84085.37000000", "0.00000000"], ["84085.57000000", "0.00761000"], ["84085.61000000", "0.00000000"], ["84085.96000000", "0.00000000"], ["84085.97000000", "0.00000000"], ["84086.00000000", "0.10614000"], ["84086.01000000", "0.87650000"], ["84086.15000000", "0.89155000"], ["84086.92000000", "0.00000000"], ["84086.93000000", "0.00000000"], ["84086.94000000", "0.04400000"], ["84087.06000000", "0.00013000"], ["84087.28000000", "0.03308000"], ["84087.47000000", "0.00118000"], ["84087.50000000", "0.00500000"], ["84087.64000000", "0.00000000"], ["84087.94000000", "0.29592000"], ["84089.26000000", "0.00307000"], ["84089.33000000", "0.00300000"], ["84090.02000000", "0.00000000"], ["84090.29000000", "0.00009000"], ["84090.66000000", "0.22901000"], ["84090.70000000", "0.00000000"], ["84091.08000000", "0.01189000"], ["84091.41000000", "0.00013000"], ["84091.53000000", "0.00000000"], ["84091.78000000", "0.71126000"], ["84091.98000000", "0.11600000"], ["84092.03000000", "0.08000000"], ["84092.33000000", "0.05943000"], ["84092.64000000", "0.05943000"], ["84093.03000000", "0.00000000"], ["84093.52000000", "0.00000000"], ["84094.90000000", "0.00000000"], ["84094.91000000", "1.08213000"], ["84095.16000000", "0.84138000"], ["84095.21000000", "0.01595000"], ["84095.90000000", "0.00000000"], ["84095.95000000", "0.00000000"], ["84096.57000000", "0.00000000"], ["84096.69000000", "0.00000000"], ["84097.14000000", "0.00000000"], ["84097.32000000", "0.00000000"], ["84097.46000000", "0.00000000"], ["84097.82000000", "0.13094000"], ["84098.59000000", "0.00000000"], ["84098.91000000", "0.01284000"], ["84099.67000000", "0.00000000"], ["84099.72000000", "0.02814000"], ["84099.92000000", "0.80399000"], ["84099.93000000", "0.00000000"], ["84100.71000000", "0.00000000"], ["84100.72000000", "0.00000000"], ["84101.37000000", "0.00000000"], ["84101.94000000", "0.89155000"], ["84102.00000000", "0.00000000"], ["84102.21000000", "0.00000000"], ["84102.47000000", "0.00000000"], ["84102.48000000", "0.00000000"], ["84102.75000000", "0.00000000"], ["84103.01000000", "0.00000000"], ["84103.42000000", "0.00000000"], ["84104.00000000", "0.00000000"], ["84105.37000000", "1.56419000"], ["84106.01000000", "0.00000000"], ["84106.16000000", "0.00000000"], ["84106.22000000", "0.00000000"], ["84107.11000000", "0.00000000"], ["84107.97000000", "0.04400000"], ["84108.24000000", "0.00000000"], ["84108.87000000", "0.04800000"], ["84111.24000000", "0.00000000"], ["84113.02000000", "0.05600000"], ["84113.07000000", "0.08000000"], ["84113.40000000", "0.00006000"], ["84114.07000000", "0.00000000"], ["84117.00000000", "0.00000000"], ["84118.56000000", "0.00000000"], ["84120.95000000", "0.37802000"], ["84121.36000000", "0.00000000"], ["84122.17000000", "0.00849000"], ["84127.16000000", "0.00820000"], ["84135.35000000", "0.00000000"], ["84136.54000000", "0.00000000"], ["84138.54000000", "0.00000000"], ["84139.72000000", "0.00000000"], ["84140.20000000", "0.00000000"], ["84143.17000000", "0.00000000"], ["84153.62000000", "0.07052000"], ["84154.63000000", "0.47351000"], ["84160.15000000", "0.00000000"], ["84162.93000000", "0.00000000"], ["84165.19000000", "0.00000000"], ["84167.14000000", "0.00000000"], ["84178.20000000", "0.00000000"], ["84181.59000000", "0.00000000"], ["84183.18000000", "0.01040000"], ["84190.71000000", "0.00570000"], ["84200.64000000", "0.00000000"], ["84206.32000000", "0.01466000"], ["84216.75000000", "0.00000000"], ["84226.28000000", "0.00000000"], ["84227.25000000", "0.01780000"], ["84227.90000000", "0.00000000"], ["84229.68000000", "0.00000000"], ["84237.91000000", "0.00000000"], ["84242.89000000", "0.00560000"], ["84248.49000000", "0.00000000"], ["84250.27000000", "0.00009000"], ["84254.05000000", "0.00000000"], ["84255.81000000", "0.00119000"], ["84255.82000000", "0.01000000"], ["84256.52000000", "0.00000000"], ["84264.47000000", "0.99024000"], ["84266.14000000", "0.00000000"], ["84268.52000000", "0.00000000"], ["84269.48000000", "0.00000000"], ["84278.54000000", "0.01861000"], ["84330.54000000", "0.00000000"], ["84334.74000000", "0.00000000"], ["84359.78000000", "0.00000000"], ["84359.79000000", "0.00000000"], ["84359.80000000", "0.00000000"], ["84359.81000000", "0.00000000"], ["84364.91000000", "0.00000000"], ["84368.21000000", "0.00000000"], ["84370.60000000", "0.00000000"], ["84376.61000000", "0.00000000"], ["85347.31000000", "0.00000000"], ["150001.00000000", "0.00008000"]], "record_time": 1742584909.128408, "EXCHANGE": "BINANCE"}
{"e": "depthUpdate", "E": 1742584910014, "s": "BTCUSDT", "U": 64637899328, "u": 64637900515, "b": [["84078.47000000", "0.00000000"], ["84078.46000000", "0.00000000"], ["84078.44000000", "0.00000000"], ["84078.28000000", "0.00000000"], ["84078.03000000", "0.00000000"], ["84077.81000000", "0.00000000"], ["84077.80000000", "0.00000000"], ["84077.79000000", "0.00000000"], ["84077.48000000", "0.00000000"], ["84077.47000000", "0.00000000"], ["84077.29000000", "0.00000000"], ["84077.26000000", "0.00000000"], ["84076.47000000", "0.00000000"], ["84076.46000000", "0.03844000"], ["84076.45000000", "0.00047000"], ["84076.44000000", "0.00017000"], ["84076.30000000", "0.00000000"], ["84076.28000000", "0.00000000"], ["84076.08000000", "0.00207000"], ["84076.04000000", "0.00007000"], ["84076.03000000", "0.00007000"], ["84075.53000000", "0.00000000"], ["84075.50000000", "0.00014000"], ["84075.49000000", "0.00040000"], ["84075.48000000", "0.00030000"], ["84075.47000000", "0.07367000"], ["84075.25000000", "0.00000000"], ["84075.24000000", "0.00000000"], ["84074.89000000", "0.00000000"], ["84074.84000000", "0.00000000"], ["84074.81000000", "0.00000000"], ["84074.80000000", "0.00014000"], ["84074.79000000", "0.78552000"], ["84074.44000000", "0.00000000"], ["84074.08000000", "0.00000000"], ["84074.02000000", "0.00505000"], ["84073.99000000", "0.27922000"], ["84073.98000000", "0.06377000"], ["84073.86000000", "0.17481000"], ["84073.74000000", "0.00000000"], ["84073.68000000", "0.00000000"], ["84073.31000000", "0.00016000"], ["84073.30000000", "0.02207000"], ["84073.28000000", "0.00000000"], ["84073.02000000", "0.00015000"], ["84073.01000000", "0.00000000"], ["84072.90000000", "0.00000000"], ["84072.83000000", "0.02539000"], ["84072.06000000", "0.00000000"], ["84072.00000000", "0.00000000"], ["84071.75000000", "0.00000000"], ["84070.80000000", "0.14620000"], ["84069.74000000", "0.01189000"], ["84069.59000000", "0.00000000"], ["84069.54000000", "0.00000000"], ["84069.19000000", "0.00000000"], ["84068.69000000", "0.00000000"], ["84068.61000000", "0.00000000"], ["84067.85000000", "0.00000000"], ["84067.80000000", "0.00000000"], ["84067.48000000", "0.05999000"], ["84066.15000000", "0.04000000"], ["84065.87000000", "0.00000000"], ["84065.31000000", "0.04000000"], ["84064.81000000", "0.00000000"], ["84064.64000000", "0.20527000"], ["84064.48000000", "0.04000000"], ["84064.46000000", "0.04000000"], ["84064.40000000", "0.04000000"], ["84064.21000000", "0.00000000"], ["84063.86000000", "0.01189000"], ["84062.01000000", "0.00000000"], ["84061.96000000", "0.04000000"], ["84061.53000000", "0.05353000"], ["84061.11000000", "0.04000000"], ["84061.01000000", "0.04000000"], ["84060.90000000", "0.13306000"], ["84060.77000000", "0.00000000"], ["84060.34000000", "0.00000000"], ["84060.27000000", "0.08000000"], ["84060.20000000", "0.04000000"], ["84060.14000000", "0.00000000"], ["84059.77000000", "0.00000000"], ["84059.65000000", "0.00059000"], ["84059.08000000", "0.03569000"], ["84059.03000000", "0.00000000"], ["84058.52000000", "0.00000000"], ["84056.94000000", "0.00000000"], ["84056.50000000", "0.01000000"], ["84054.85000000", "0.14165000"], ["84054.50000000", "0.00000000"], ["84054.46000000", "0.00000000"], ["84053.25000000", "0.00059000"], ["84053.24000000", "0.00300000"], ["84052.95000000", "0.10600000"], ["84052.49000000", "0.00114000"], ["84052.36000000", "0.85702000"], ["84052.35000000", "0.00000000"], ["84052.02000000", "0.00000000"], ["84051.84000000", "1.39809000"], ["84050.57000000", "0.00758000"], ["84050.52000000", "0.00000000"], ["84048.52000000", "0.00000000"], ["84047.44000000", "0.00000000"], ["84046.60000000", "0.59437000"], ["84046.49000000", "0.00000000"], ["84045.82000000", "0.00587000"], ["84044.99000000", "0.00000000"], ["84044.93000000", "0.00016000"], ["84043.62000000", "0.47549000"], ["84042.20000000", "0.00000000"], ["84041.24000000", "0.00000000"], ["84040.45000000", "0.59501000"], ["84039.11000000", "0.59195000"], ["84036.43000000", "0.00059000"], ["84035.43000000", "0.00146000"], ["84031.93000000", "0.00000000"], ["84028.22000000", "0.00000000"], ["84027.89000000", "0.23701000"], ["84026.06000000", "0.00000000"], ["84025.57000000", "0.00000000"], ["84024.17000000", "0.08301000"], ["84024.16000000", "0.00000000"], ["84022.33000000", "0.03202000"], ["84019.07000000", "0.09641000"], ["84019.06000000", "0.00000000"], ["84018.70000000", "0.04628000"], ["84014.62000000", "0.00000000"], ["84014.58000000", "0.00000000"], ["84013.52000000", "0.00000000"], ["84008.76000000", "0.59437000"], ["84005.78000000", "0.51549000"], ["84005.26000000", "0.00000000"], ["84002.17000000", "0.00000000"], ["84001.05000000", "0.00000000"], ["84000.12000000", "0.00000000"], ["83997.97000000", "0.00000000"], ["83996.75000000", "0.00000000"], ["83996.44000000", "0.61613000"], ["83995.91000000", "0.00000000"], ["83995.90000000", "0.00000000"], ["83994.26000000", "0.94844000"], ["83989.88000000", "0.00827000"], ["83989.26000000", "0.55778000"], ["83989.25000000", "0.00000000"], ["83986.81000000", "0.00000000"], ["83985.16000000", "0.00000000"], ["83972.10000000", "0.00000000"], ["83967.49000000", "0.02287000"], ["83967.36000000", "0.04497000"], ["83964.60000000", "0.00083000"], ["83960.86000000", "0.00013000"], ["83927.92000000", "0.00000000"], ["83921.96000000", "0.00000000"], ["83921.22000000", "0.00000000"], ["83917.83000000", "0.00000000"], ["83913.05000000", "0.00835000"], ["83905.29000000", "0.99313000"], ["83896.02000000", "0.00000000"], ["83888.92000000", "0.00069000"], ["83854.47000000", "0.00000000"], ["83850.65000000", "0.00000000"], ["83848.05000000", "0.00400000"], ["83844.86000000", "0.00000000"], ["83843.23000000", "0.00013000"], ["83839.03000000", "0.00013000"], ["83836.89000000", "0.00000000"], ["83736.89000000", "0.00000000"], ["83736.85000000", "0.00040000"], ["83084.16000000", "0.00000000"], ["83084.05000000", "0.00040000"], ["82819.69000000", "0.00000000"], ["80697.27000000", "0.00000000"], ["75672.00000000", "0.00877000"], ["75670.00000000", "0.00228000"], ["67262.78000000", "0.00000000"], ["67261.17000000", "0.00058000"], ["33000.00000000", "2.93827000"], ["30268.25000000", "0.00020000"], ["30267.53000000", "0.00020000"], ["20002.00000000", "0.00000000"], ["20001.00000000", "0.02099000"]], "a": [["84076.47000000", "9.75381000"], ["84076.48000000", "0.00049000"], ["84076.62000000", "0.00021000"], ["84076.63000000", "0.04020000"], ["84077.18000000", "0.00007000"], ["84077.29000000", "0.00021000"], ["84077.30000000", "0.45020000"], ["84077.48000000", "0.00000000"], ["84077.79000000", "0.00000000"], ["84077.80000000", "0.00000000"], ["84077.81000000", "0.00000000"], ["84077.82000000", "0.00000000"], ["84078.00000000", "0.02280000"], ["84078.04000000", "0.00000000"], ["84078.14000000", "0.01196000"], ["84078.29000000", "0.00000000"], ["84078.36000000", "0.00000000"], ["84078.37000000", "0.00000000"], ["84078.42000000", "0.00014000"], ["84078.43000000", "1.02123000"], ["84078.44000000", "0.00000000"], ["84078.45000000", "0.00000000"], ["84078.46000000", "0.00000000"], ["84078.47000000", "0.17905000"], ["84078.48000000", "2.15176000"], ["84078.49000000", "0.00000000"], ["84078.86000000", "0.00007000"], ["84078.89000000", "0.00201000"], ["84079.71000000", "0.00007000"], ["84079.80000000", "0.00006000"], ["84079.99000000", "0.00000000"], ["84080.00000000", "0.02266000"], ["84080.10000000", "0.02234000"], ["84080.14000000", "0.00000000"], ["84080.15000000", "0.00000000"], ["84080.26000000", "0.00000000"], ["84080.27000000", "0.00000000"], ["84080.34000000", "0.00000000"], ["84080.80000000", "0.00000000"], ["84080.81000000", "0.00000000"], ["84080.88000000", "0.00000000"], ["84080.89000000", "0.00000000"], ["84080.90000000", "0.00000000"], ["84080.91000000", "0.00000000"], ["84080.92000000", "0.04000000"], ["84080.93000000", "0.00000000"], ["84081.10000000", "0.03383000"], ["84081.21000000", "0.00000000"], ["84081.22000000", "0.00757000"], ["84081.98000000", "0.00000000"], ["84082.00000000", "0.02260000"], ["84082.11000000", "0.00000000"], ["84082.70000000", "0.00500000"], ["84082.72000000", "0.04400000"], ["84083.13000000", "0.00000000"], ["84083.19000000", "0.01189000"], ["84083.24000000", "0.02419000"], ["84083.27000000", "1.19468000"], ["84083.30000000", "2.06310000"], ["84083.43000000", "0.00922000"], ["84083.49000000", "0.13530000"], ["84083.79000000", "0.00006000"], ["84084.40000000", "0.06400000"], ["84084.41000000", "0.06800000"], ["84085.11000000", "0.11892000"], ["84085.20000000", "0.00000000"], ["84085.57000000", "0.00000000"], ["84085.81000000", "0.04000000"], ["84086.01000000", "0.82627000"], ["84086.83000000", "0.02378000"], ["84087.77000000", "0.05600000"], ["84087.94000000", "0.16000000"], ["84088.97000000", "0.00013000"], ["84089.07000000", "0.01189000"], ["84089.14000000", "0.01189000"], ["84089.28000000", "0.00000000"], ["84090.20000000", "0.00000000"], ["84090.45000000", "0.02281000"], ["84090.66000000", "0.65607000"], ["84090.96000000", "0.00000000"], ["84090.97000000", "0.00000000"], ["84091.08000000", "0.00000000"], ["84092.40000000", "0.02407000"], ["84093.29000000", "0.00059000"], ["84093.39000000", "0.00000000"], ["84093.46000000", "1.00000000"], ["84094.32000000", "0.00000000"], ["84094.58000000", "0.00522000"], ["84094.67000000", "0.00000000"], ["84094.76000000", "0.00000000"], ["84094.77000000", "0.01284000"], ["84094.78000000", "1.32302000"], ["84094.97000000", "0.00029000"], ["84095.19000000", "0.00000000"], ["84095.92000000", "0.00000000"], ["84095.93000000", "0.00000000"], ["84097.52000000", "0.00000000"], ["84098.91000000", "0.00000000"], ["84099.19000000", "0.09031000"], ["84099.25000000", "0.35670000"], ["84100.00000000", "0.00023000"], ["84101.57000000", "0.00013000"], ["84102.83000000", "0.00000000"], ["84103.35000000", "0.87380000"], ["84103.53000000", "0.72656000"], ["84103.70000000", "0.00059000"], ["84105.37000000", "0.20151000"], ["84107.94000000", "0.00000000"], ["84109.33000000", "0.00000000"], ["84109.71000000", "0.23678000"], ["84110.00000000", "0.00016000"], ["84112.18000000", "0.00000000"], ["84114.33000000", "0.00000000"], ["84114.76000000", "0.01578000"], ["84120.03000000", "0.00951000"], ["84120.15000000", "0.20151000"], ["84120.51000000", "0.00059000"], ["84121.73000000", "0.00000000"], ["84123.69000000", "0.01196000"], ["84124.96000000", "0.00000000"], ["84125.34000000", "0.00000000"], ["84129.82000000", "0.00826000"], ["84133.66000000", "0.00000000"], ["84136.05000000", "0.00994000"], ["84137.35000000", "0.00522000"], ["84137.36000000", "0.04997000"], ["84139.55000000", "0.00000000"], ["84141.10000000", "0.02100000"], ["84141.80000000", "0.01020000"], ["84150.69000000", "0.00920000"], ["84151.07000000", "0.00000000"], ["84158.95000000", "0.00000000"], ["84164.83000000", "0.00000000"], ["84168.39000000", "0.01759000"], ["84168.72000000", "0.17537000"], ["84169.04000000", "0.00000000"], ["84174.85000000", "0.00059000"], ["84177.17000000", "0.00000000"], ["84177.50000000", "0.04757000"], ["84180.05000000", "0.04757000"], ["84180.15000000", "0.00000000"], ["84180.76000000", "0.02125000"], ["84181.83000000", "0.04757000"], ["84194.16000000", "0.00000000"], ["84194.23000000", "0.00000000"], ["84194.36000000", "0.02287000"], ["84195.11000000", "0.05497000"], ["84196.62000000", "0.05497000"], ["84197.60000000", "0.00000000"], ["84198.56000000", "0.06830000"], ["84198.57000000", "0.01964000"], ["84199.53000000", "0.05497000"], ["84202.05000000", "0.05297000"], ["84203.01000000", "0.00000000"], ["84204.37000000", "0.07585000"], ["84204.88000000", "0.05297000"], ["84211.35000000", "0.00000000"], ["84211.94000000", "0.02497000"], ["84218.93000000", "0.04998000"], ["84218.94000000", "0.00000000"], ["84219.06000000", "0.00000000"], ["84219.27000000", "0.00000000"], ["84219.60000000", "0.00000000"], ["84222.83000000", "0.00000000"], ["84224.31000000", "0.00000000"], ["84224.65000000", "0.02584000"], ["84225.00000000", "0.00000000"], ["84225.07000000", "0.00000000"], ["84226.64000000", "0.00000000"], ["84227.15000000", "0.00000000"], ["84229.02000000", "0.00920000"], ["84229.62000000", "0.00000000"], ["84230.46000000", "0.00000000"], ["84231.29000000", "0.02125000"], ["84235.12000000", "0.00000000"], ["84235.27000000", "0.00000000"], ["84235.81000000", "0.00000000"], ["84238.65000000", "0.00000000"], ["84240.44000000", "0.01759000"], ["84249.07000000", "0.01141000"], ["84251.73000000", "0.45000000"], ["84254.32000000", "0.01000000"], ["84255.82000000", "0.00000000"], ["84264.47000000", "0.99110000"], ["84285.62000000", "0.00000000"], ["84323.09000000", "0.00000000"], ["84327.29000000", "0.00000000"], ["84352.36000000", "0.00000000"], ["84354.20000000", "0.00000000"], ["84355.35000000", "0.13093000"], ["84366.72000000", "0.00000000"], ["84919.25000000", "0.00000000"], ["85327.80000000", "0.11735000"], ["85337.62000000", "0.00100000"], ["85349.10000000", "0.00000000"], ["150001.00000000", "0.00016000"]], "record_time": 1742584910.127334, "EXCHANGE": "BINANCE"}
