{"e": "depthUpdate", "E": 1742377118014, "s": "BTCUSDT", "U": 64441736794, "u": 64441736929, "b": [["83533.18000000", "8.47228000"], ["83532.07000000", "0.00050000"], ["83531.75000000", "0.00000000"], ["83531.00000000", "0.00000000"], ["83530.00000000", "0.00011000"], ["83529.00000000", "0.00500000"], ["83528.54000000", "0.00912000"], ["83528.00000000", "0.00000000"], ["83525.34000000", "0.00000000"], ["83524.41000000", "0.00000000"], ["83524.36000000", "0.03592000"], ["83520.65000000", "0.04481000"], ["83520.36000000", "0.21609000"], ["83520.15000000", "0.91947000"], ["83518.89000000", "0.00000000"], ["83517.33000000", "0.00000000"], ["83516.81000000", "1.33744000"], ["83516.78000000", "0.00000000"], ["83510.42000000", "0.00000000"], ["83506.21000000", "0.86219000"], ["83503.61000000", "0.85107000"], ["83503.01000000", "0.10496000"], ["83502.54000000", "0.05298000"], ["83502.17000000", "0.05298000"], ["83496.66000000", "0.00000000"], ["83493.22000000", "0.01862000"], ["83491.41000000", "0.00059000"], ["83456.91000000", "0.00000000"], ["83429.47000000", "0.05398000"], ["83424.93000000", "0.05398000"], ["83422.29000000", "0.05198000"], ["83421.57000000", "0.05298000"], ["83421.36000000", "0.05398000"], ["83416.70000000", "0.00000000"], ["83416.08000000", "0.00013000"], ["83408.81000000", "0.99080000"], ["82292.83000000", "0.00000000"], ["80888.01000000", "0.01987000"], ["76700.00000000", "8.71692000"], ["75179.00000000", "0.00020000"], ["66826.55000000", "0.00058000"], ["33000.00000000", "2.93934000"]], "a": [["83533.19000000", "4.42038000"], ["83533.44000000", "0.13720000"], ["83535.77000000", "0.00014000"], ["83535.78000000", "0.22205000"], ["83536.73000000", "0.02496000"], ["83536.92000000", "0.00000000"], ["83538.00000000", "0.04790000"], ["83540.91000000", "0.00013000"], ["83543.61000000", "0.46360000"], ["83543.62000000", "0.78999000"], ["83544.21000000", "0.00000000"], ["83547.80000000", "0.00000000"], ["83549.89000000", "0.05988000"], ["83552.35000000", "0.27490000"], ["83553.70000000", "0.00930000"], ["83555.29000000", "0.00000000"], ["83558.31000000", "1.52861000"], ["83560.67000000", "1.34618000"], ["83566.62000000", "0.12550000"], ["83568.31000000", "0.00000000"], ["83570.94000000", "0.00000000"], ["83574.96000000", "0.00059000"], ["83583.13000000", "0.00000000"], ["83589.62000000", "0.00000000"], ["83592.96000000", "0.65063000"], ["83599.61000000", "0.00000000"], ["83606.24000000", "0.00439000"], ["83612.54000000", "0.00000000"], ["83615.66000000", "0.09200000"], ["83620.90000000", "0.00000000"], ["83620.96000000", "0.57620000"], ["83624.56000000", "0.01196000"], ["83634.91000000", "0.00000000"], ["83723.42000000", "0.00000000"], ["83723.49000000", "0.00000000"], ["83723.52000000", "0.01007000"], ["83723.82000000", "0.00000000"], ["83724.52000000", "0.00000000"], ["83724.62000000", "0.00000000"], ["83724.72000000", "0.00000000"], ["83725.42000000", "0.00000000"], ["83725.72000000", "0.07315000"], ["83731.52000000", "0.00000000"], ["83733.95000000", "0.00000000"], ["83827.52000000", "0.02460000"], ["83833.15000000", "0.00000000"], ["83870.00000000", "0.02134000"], ["84799.24000000", "0.00000000"], ["84799.99000000", "0.01298000"], ["84800.00000000", "31.38552000"]], "record_time": 1742377118.908687}
{"e": "depthUpdate", "E": 1742377119014, "s": "BTCUSDT", "U": 64441736930, "u": 64441737026, "b": [["83533.18000000", "8.47927000"], ["83527.10000000", "0.00008000"], ["83526.90000000", "0.00500000"], ["83523.25000000", "0.64078000"], ["83523.14000000", "0.00000000"], ["83522.14000000", "0.35498000"], ["83520.65000000", "0.05320000"], ["83520.15000000", "1.10518000"], ["83518.88000000", "0.86206000"], ["83517.15000000", "1.37415000"], ["83516.81000000", "0.00000000"], ["83514.72000000", "0.00000000"], ["83505.58000000", "0.00757000"], ["83504.72000000", "0.00000000"], ["83503.98000000", "0.00000000"], ["83502.06000000", "0.00756000"], ["83501.48000000", "0.00000000"], ["83500.46000000", "0.00000000"], ["83497.02000000", "0.12431000"], ["83495.01000000", "1.02854000"], ["83461.01000000", "0.39380000"], ["83457.36000000", "0.02031000"], ["83423.32000000", "0.67791000"], ["83423.17000000", "0.00000000"], ["83389.57000000", "0.01872000"], ["82280.18000000", "0.00100000"], ["76700.00000000", "9.00201000"], ["75179.86000000", "0.00025000"], ["75179.00000000", "0.00020000"], ["66826.55000000", "0.00058000"], ["33000.00000000", "2.93934000"], ["30071.95000000", "0.00020000"]], "a": [["83533.19000000", "4.35579000"], ["83534.63000000", "0.00000000"], ["83535.05000000", "0.00000000"], ["83535.77000000", "0.00014000"], ["83539.30000000", "0.00758000"], ["83539.73000000", "0.00754000"], ["83553.70000000", "0.00000000"], ["83560.67000000", "0.00000000"], ["83561.01000000", "1.40061000"], ["83566.71000000", "0.94070000"], ["83589.62000000", "0.00930000"], ["83593.26000000", "0.09200000"], ["83594.77000000", "0.00000000"], ["83599.81000000", "0.00000000"], ["83636.56000000", "0.00000000"], ["83723.51000000", "0.00258000"], ["83723.52000000", "0.00007000"], ["83723.82000000", "0.00000000"], ["83723.92000000", "0.00000000"], ["83724.12000000", "0.00000000"], ["83724.22000000", "0.00000000"], ["83724.62000000", "0.01000000"], ["83731.51000000", "0.00000000"], ["83824.80000000", "0.00000000"], ["84786.19000000", "0.00100000"], ["84799.99000000", "0.01061000"]], "record_time": 1742377119.908699}
{"e": "depthUpdate", "E": 1742377120014, "s": "BTCUSDT", "U": 64441737027, "u": 64441737101, "b": [["83533.18000000", "8.46785000"], ["83529.00000000", "0.00500000"], ["83528.54000000", "0.00000000"], ["83520.65000000", "0.04481000"], ["83520.15000000", "1.07456000"], ["83517.15000000", "1.35402000"], ["83511.84000000", "1.32562000"], ["83441.09000000", "1.80201000"], ["83419.94000000", "0.51790000"], ["83417.32000000", "0.00000000"], ["83389.57000000", "0.00000000"], ["83349.66000000", "0.00820000"], ["83346.15000000", "0.00000000"], ["83336.79000000", "0.01872000"], ["82280.18000000", "0.00000000"], ["76700.00000000", "8.71692000"], ["75179.86000000", "0.00000000"], ["75179.00000000", "0.00020000"], ["66826.55000000", "0.00058000"], ["33000.00000000", "2.93934000"], ["20002.00000000", "0.00000000"]], "a": [["83533.19000000", "4.35596000"], ["83549.11000000", "0.00000000"], ["83549.48000000", "0.00006000"], ["83549.89000000", "0.00000000"], ["83551.35000000", "0.05985000"], ["83558.24000000", "0.11976000"], ["83560.67000000", "1.38928000"], ["83561.01000000", "0.00000000"], ["83562.29000000", "0.13431000"], ["83562.74000000", "0.25956000"], ["83566.62000000", "0.00000000"], ["83585.52000000", "0.01872000"], ["83589.16000000", "0.41250000"], ["83612.54000000", "0.05981000"], ["83629.26000000", "0.03588000"], ["83657.97000000", "0.00039000"], ["83723.52000000", "0.00007000"], ["83723.82000000", "0.01000000"], ["83723.92000000", "0.00000000"], ["83724.02000000", "0.00000000"], ["83724.62000000", "0.00000000"], ["83724.82000000", "0.00000000"], ["83726.22000000", "0.00000000"], ["83726.52000000", "0.00000000"], ["84786.19000000", "0.00000000"]], "record_time": 1742377120.908881}
{"e": "depthUpdate", "E": 1742377121014, "s": "BTCUSDT", "U": 64441737102, "u": 64441737351, "b": [["83533.18000000", "8.10014000"], ["83533.02000000", "0.10563000"], ["83532.64000000", "0.07195000"], ["83532.63000000", "0.04006000"], ["83532.41000000", "0.07188000"], ["83532.37000000", "0.07188000"], ["83532.35000000", "0.07188000"], ["83531.88000000", "0.04000000"], ["83531.84000000", "0.00006000"], ["83528.42000000", "0.12631000"], ["83526.90000000", "0.00500000"], ["83526.61000000", "0.00883000"], ["83526.26000000", "0.00000000"], ["83526.25000000", "0.00000000"], ["83525.45000000", "0.00000000"], ["83525.24000000", "0.00000000"], ["83524.84000000", "0.00598000"], ["83524.63000000", "0.00000000"], ["83524.56000000", "0.00000000"], ["83524.36000000", "0.00000000"], ["83523.51000000", "0.00000000"], ["83523.34000000", "0.00000000"], ["83523.33000000", "0.00000000"], ["83523.30000000", "0.00000000"], ["83523.28000000", "0.00000000"], ["83523.25000000", "0.33568000"], ["83523.05000000", "0.03591000"], ["83522.97000000", "0.00000000"], ["83522.50000000", "0.00094000"], ["83522.15000000", "0.00419000"], ["83522.14000000", "0.00000000"], ["83521.79000000", "0.00000000"], ["83521.64000000", "0.10672000"], ["83521.47000000", "0.00000000"], ["83520.68000000", "0.00053000"], ["83520.66000000", "0.00019000"], ["83520.65000000", "0.04481000"], ["83520.50000000", "0.05388000"], ["83520.15000000", "1.07162000"], ["83519.73000000", "0.00000000"], ["83519.06000000", "0.86206000"], ["83518.88000000", "0.00000000"], ["83518.33000000", "0.00000000"], ["83517.68000000", "0.00000000"], ["83517.15000000", "0.00000000"], ["83517.14000000", "1.34422000"], ["83516.38000000", "0.52565000"], ["83515.72000000", "0.00000000"], ["83513.31000000", "0.00598000"], ["83510.42000000", "0.00000000"], ["83507.28000000", "1.08170000"], ["83504.79000000", "0.00000000"], ["83503.61000000", "0.69113000"], ["83503.01000000", "0.00000000"], ["83502.48000000", "0.89825000"], ["83499.66000000", "0.05987000"], ["83497.83000000", "0.00000000"], ["83497.09000000", "0.59851000"], ["83497.02000000", "0.00000000"], ["83496.51000000", "0.28652000"], ["83493.22000000", "0.00000000"], ["83491.25000000", "0.11686000"], ["83491.09000000", "0.05897000"], ["83491.08000000", "0.00931000"], ["83488.93000000", "0.00251000"], ["83488.84000000", "0.00000000"], ["83488.07000000", "0.01862000"], ["83478.50000000", "0.72338000"], ["83477.61000000", "0.71157000"], ["83476.67000000", "0.00000000"], ["83472.63000000", "0.05000000"], ["83467.11000000", "0.03888000"], ["83449.93000000", "0.00000000"], ["83426.42000000", "0.05198000"], ["83423.18000000", "0.05198000"], ["83422.76000000", "0.05398000"], ["83422.45000000", "0.16667000"], ["83421.94000000", "0.05398000"], ["83421.91000000", "0.05298000"], ["83417.89000000", "0.00078000"], ["83417.88000000", "0.00000000"], ["83414.53000000", "0.04298000"], ["83398.64000000", "0.00000000"], ["83393.43000000", "0.00000000"], ["83388.18000000", "0.00400000"], ["83336.80000000", "0.00065000"], ["83325.94000000", "0.00000000"], ["82280.18000000", "0.00100000"], ["76870.97000000", "0.00014000"], ["76700.00000000", "9.00943000"], ["75179.00000000", "0.00020000"], ["66826.55000000", "0.00058000"], ["42000.00000000", "6.98916000"], ["33000.00000000", "2.93934000"], ["30071.95000000", "0.00040000"]], "a": [["83533.19000000", "4.97164000"], ["83533.44000000", "0.08063000"], ["83533.45000000", "0.17903000"], ["83534.24000000", "0.00007000"], ["83534.25000000", "0.00000000"], ["83534.50000000", "0.04790000"], ["83535.77000000", "0.00000000"], ["83535.78000000", "0.00006000"], ["83536.73000000", "0.02502000"], ["83537.99000000", "0.10531000"], ["83538.00000000", "0.11916000"], ["83539.92000000", "0.00000000"], ["83541.56000000", "0.00000000"], ["83543.00000000", "0.00000000"], ["83543.06000000", "0.00091000"], ["83543.53000000", "0.46710000"], ["83543.54000000", "0.78999000"], ["83543.61000000", "0.00013000"], ["83543.62000000", "0.00000000"], ["83543.65000000", "0.01197000"], ["83546.04000000", "0.45605000"], ["83548.71000000", "0.05985000"], ["83549.26000000", "0.27251000"], ["83551.35000000", "0.00000000"], ["83552.35000000", "0.00000000"], ["83553.32000000", "0.06000000"], ["83553.42000000", "0.08000000"], ["83553.70000000", "0.00000000"], ["83554.44000000", "0.00000000"], ["83558.08000000", "0.11445000"], ["83560.67000000", "0.00000000"], ["83560.68000000", "1.36041000"], ["83561.73000000", "0.25979000"], ["83562.29000000", "0.00884000"], ["83562.74000000", "0.25956000"], ["83565.30000000", "0.00000000"], ["83570.23000000", "0.00000000"], ["83574.63000000", "0.05930000"], ["83579.53000000", "0.00000000"], ["83579.65000000", "0.35930000"], ["83579.74000000", "0.86143000"], ["83581.38000000", "0.00000000"], ["83582.69000000", "0.00000000"], ["83585.97000000", "0.00000000"], ["83586.18000000", "0.01860000"], ["83589.62000000", "0.00930000"], ["83594.71000000", "0.00000000"], ["83594.91000000", "0.00000000"], ["83597.79000000", "0.00000000"], ["83612.54000000", "0.00000000"], ["83629.26000000", "0.00000000"], ["83640.75000000", "0.00000000"], ["83647.10000000", "0.02408000"], ["83691.56000000", "0.00000000"], ["83722.52000000", "0.00000000"], ["83722.62000000", "0.00000000"], ["83723.32000000", "0.00000000"], ["83723.41000000", "0.00258000"], ["83723.42000000", "0.01000000"], ["83723.51000000", "0.00000000"], ["83723.82000000", "0.00000000"], ["83725.32000000", "0.00000000"], ["84786.18000000", "0.00000000"], ["84786.19000000", "0.00100000"]], "record_time": 1742377121.909409}
{"e": "depthUpdate", "E": 1742377122014, "s": "BTCUSDT", "U": 64441737352, "u": 64441737474, "b": [["83533.18000000", "8.04935000"], ["83530.30000000", "0.00000000"], ["83529.00000000", "0.00500000"], ["83528.42000000", "0.06325000"], ["83527.71000000", "0.00000000"], ["83525.47000000", "0.00000000"], ["83525.27000000", "0.00598000"], ["83524.84000000", "0.00000000"], ["83524.04000000", "0.00000000"], ["83523.56000000", "0.21620000"], ["83523.49000000", "0.00000000"], ["83523.05000000", "0.00000000"], ["83523.04000000", "0.03592000"], ["83520.65000000", "0.04481000"], ["83520.30000000", "0.00000000"], ["83520.15000000", "1.03762000"], ["83519.35000000", "0.00000000"], ["83519.06000000", "0.00000000"], ["83517.34000000", "0.00000000"], ["83517.14000000", "0.00000000"], ["83516.79000000", "1.35227000"], ["83515.42000000", "0.00000000"], ["83504.95000000", "0.00000000"], ["83504.59000000", "0.86221000"], ["83491.08000000", "0.00000000"], ["83488.07000000", "0.02793000"], ["83479.15000000", "0.00000000"], ["83472.63000000", "0.00000000"], ["83470.39000000", "0.01196000"], ["83442.05000000", "0.00008000"], ["82280.18000000", "0.00000000"], ["81000.00000000", "55.98493000"], ["76870.97000000", "0.00000000"], ["75179.00000000", "0.00020000"], ["66826.55000000", "0.00058000"], ["33000.00000000", "2.93934000"], ["30071.95000000", "0.00060000"]], "a": [["83533.19000000", "4.97254000"], ["83539.27000000", "0.00000000"], ["83541.64000000", "0.79000000"], ["83543.06000000", "0.00000000"], ["83543.16000000", "0.00000000"], ["83543.25000000", "0.00415000"], ["83543.54000000", "0.00000000"], ["83545.90000000", "0.75869000"], ["83546.04000000", "0.45195000"], ["83547.80000000", "0.05988000"], ["83550.00000000", "0.10736000"], ["83550.92000000", "0.00000000"], ["83556.71000000", "0.00000000"], ["83558.24000000", "0.05988000"], ["83558.31000000", "1.51819000"], ["83559.89000000", "1.37145000"], ["83560.68000000", "0.00000000"], ["83565.18000000", "0.86158000"], ["83579.74000000", "0.00000000"], ["83581.01000000", "0.00930000"], ["83589.62000000", "0.00000000"], ["83598.25000000", "0.00000000"], ["83602.51000000", "0.00000000"], ["83612.54000000", "0.05981000"], ["83619.16000000", "0.00000000"], ["83620.90000000", "0.03588000"], ["83624.29000000", "0.00000000"], ["83629.65000000", "0.58958000"], ["83640.60000000", "0.00000000"], ["83644.53000000", "0.00000000"], ["83649.38000000", "0.00000000"], ["83654.73000000", "0.00000000"], ["83661.06000000", "0.00000000"], ["83663.80000000", "0.19268000"], ["83695.54000000", "0.00000000"], ["83702.94000000", "0.00000000"], ["83722.52000000", "0.00000000"], ["83722.62000000", "0.00000000"], ["83723.22000000", "0.00000000"], ["83723.42000000", "0.00000000"], ["83723.92000000", "0.00000000"], ["83724.02000000", "0.01000000"], ["84368.51000000", "0.00000000"], ["84786.19000000", "0.00000000"]], "record_time": 1742377122.909022}
{"e": "depthUpdate", "E": 1742377123014, "s": "BTCUSDT", "U": 64441737475, "u": 64441737633, "b": [["83533.18000000", "8.39114000"], ["83533.00000000", "0.00013000"], ["83532.66000000", "0.00021000"], ["83532.65000000", "0.22288000"], ["83532.64000000", "0.07188000"], ["83532.07000000", "0.00050000"], ["83530.40000000", "0.00000000"], ["83530.28000000", "0.02394000"], ["83528.42000000", "0.16349000"], ["83526.90000000", "0.00000000"], ["83526.74000000", "0.05985000"], ["83525.94000000", "0.11970000"], ["83525.19000000", "0.12568000"], ["83525.06000000", "0.05985000"], ["83524.54000000", "0.11970000"], ["83524.28000000", "0.00000000"], ["83524.26000000", "0.00598000"], ["83524.00000000", "0.07184000"], ["83523.95000000", "0.02791000"], ["83523.92000000", "0.03590000"], ["83523.76000000", "0.00094000"], ["83523.70000000", "0.00000000"], ["83523.24000000", "0.34442000"], ["83522.50000000", "0.00000000"], ["83522.15000000", "0.00000000"], ["83522.14000000", "0.15327000"], ["83520.65000000", "0.05083000"], ["83520.40000000", "0.00000000"], ["83520.34000000", "0.05985000"], ["83519.62000000", "0.11971000"], ["83519.13000000", "0.86206000"], ["83518.93000000", "0.11971000"], ["83512.95000000", "0.31835000"], ["83510.42000000", "0.00000000"], ["83504.59000000", "0.00000000"], ["83488.07000000", "0.00000000"], ["83485.25000000", "0.05985000"], ["83419.94000000", "0.00000000"], ["83417.89000000", "0.00000000"], ["83393.82000000", "0.00400000"], ["83388.18000000", "0.00000000"], ["83336.80000000", "0.00000000"], ["83336.79000000", "0.00000000"], ["82280.18000000", "0.00100000"], ["79300.00000000", "1.09872000"], ["75179.00000000", "0.00020000"], ["66826.55000000", "0.00058000"], ["60000.00000000", "72.30369000"], ["33000.00000000", "2.93994000"], ["30071.95000000", "0.00080000"]], "a": [["83533.19000000", "4.36333000"], ["83537.40000000", "0.00000000"], ["83537.50000000", "0.00014000"], ["83537.51000000", "0.22205000"], ["83538.00000000", "0.04796000"], ["83541.63000000", "0.26330000"], ["83541.64000000", "0.00000000"], ["83542.10000000", "0.00000000"], ["83543.53000000", "0.00000000"], ["83543.58000000", "0.00000000"], ["83543.72000000", "0.00090000"], ["83547.80000000", "0.00000000"], ["83548.71000000", "0.00000000"], ["83549.89000000", "0.05988000"], ["83551.04000000", "0.05985000"], ["83557.00000000", "0.00000000"], ["83565.18000000", "0.00000000"], ["83578.45000000", "0.00000000"], ["83579.60000000", "0.94056000"], ["83579.61000000", "0.86143000"], ["83594.17000000", "0.00000000"], ["83599.81000000", "0.00000000"], ["83608.61000000", "0.00000000"], ["83612.54000000", "0.00000000"], ["83620.56000000", "0.00025000"], ["83620.90000000", "0.00000000"], ["83633.10000000", "0.00000000"], ["83633.60000000", "0.00013000"], ["83636.46000000", "0.00000000"], ["83665.68000000", "0.00000000"], ["83665.91000000", "0.00000000"], ["83700.28000000", "0.00000000"], ["83723.41000000", "0.00237000"], ["83723.62000000", "0.00000000"], ["83723.71000000", "0.00021000"], ["83723.72000000", "0.00000000"], ["83724.02000000", "0.00000000"], ["83724.52000000", "0.00000000"], ["83725.52000000", "0.01000000"], ["84786.19000000", "0.00100000"], ["85500.00000000", "30.15818000"]], "record_time": 1742377123.909473}
{"e": "depthUpdate", "E": 1742377124014, "s": "BTCUSDT", "U": 64441737634, "u": 64441737712, "b": [["83533.18000000", "8.39202000"], ["83532.07000000", "0.00050000"], ["83529.00000000", "0.00000000"], ["83526.74000000", "0.00000000"], ["83525.74000000", "0.05985000"], ["83524.67000000", "0.06582000"], ["83523.76000000", "0.00000000"], ["83523.71000000", "0.00096000"], ["83523.68000000", "0.00000000"], ["83520.64000000", "0.17965000"], ["83520.29000000", "0.05985000"], ["83507.53000000", "0.59846000"], ["83497.09000000", "0.00000000"], ["83417.90000000", "0.00078000"], ["83336.81000000", "0.00065000"], ["82280.18000000", "0.00000000"], ["75179.00000000", "0.00020000"], ["66826.55000000", "0.00058000"], ["33000.00000000", "2.93934000"], ["30071.95000000", "0.00100000"], ["20002.00000000", "0.00100000"]], "a": [["83533.19000000", "4.36339000"], ["83540.40000000", "0.00500000"], ["83542.10000000", "0.03437000"], ["83545.96000000", "0.78996000"], ["83549.89000000", "0.00000000"], ["83556.83000000", "0.00000000"], ["83558.24000000", "0.11976000"], ["83566.46000000", "0.00000000"], ["83603.57000000", "0.00000000"], ["83612.54000000", "0.05981000"], ["83620.58000000", "0.09217000"], ["83629.26000000", "0.03588000"], ["83629.65000000", "0.00000000"], ["83649.05000000", "0.00000000"], ["83658.96000000", "0.05398000"], ["83663.86000000", "0.00000000"], ["83666.34000000", "0.00000000"], ["83674.41000000", "0.00000000"], ["83698.95000000", "0.00000000"], ["83725.12000000", "0.00000000"], ["83725.42000000", "0.00000000"], ["83725.52000000", "0.00000000"], ["83725.62000000", "0.00000000"], ["83726.92000000", "0.01000000"], ["83727.33000000", "0.00000000"], ["83727.83000000", "0.00000000"], ["84786.19000000", "0.00000000"]], "record_time": 1742377124.908964}
{"e": "depthUpdate", "E": 1742377125014, "s": "BTCUSDT", "U": 64441737713, "u": 64441737975, "b": [["83533.18000000", "8.33639000"], ["83532.66000000", "0.00007000"], ["83532.65000000", "0.00021000"], ["83532.64000000", "0.07188000"], ["83532.63000000", "0.00000000"], ["83532.42000000", "0.00014000"], ["83531.88000000", "0.04006000"], ["83531.84000000", "0.00000000"], ["83531.79000000", "0.00000000"], ["83531.74000000", "0.00000000"], ["83530.28000000", "0.00000000"], ["83529.28000000", "0.00000000"], ["83528.45000000", "0.00000000"], ["83528.42000000", "0.00101000"], ["83528.06000000", "0.04000000"], ["83527.62000000", "0.04539000"], ["83527.61000000", "0.00000000"], ["83527.58000000", "0.00000000"], ["83527.57000000", "0.00000000"], ["83527.22000000", "0.04000000"], ["83527.17000000", "0.04000000"], ["83526.90000000", "0.00500000"], ["83525.94000000", "0.00000000"], ["83525.74000000", "0.00000000"], ["83525.27000000", "0.00000000"], ["83525.19000000", "0.00000000"], ["83525.06000000", "0.00000000"], ["83524.71000000", "0.04000000"], ["83524.67000000", "0.00000000"], ["83524.54000000", "0.00000000"], ["83524.32000000", "0.00000000"], ["83524.26000000", "0.00000000"], ["83523.92000000", "0.00000000"], ["83523.88000000", "0.04000000"], ["83523.51000000", "0.00598000"], ["83523.24000000", "0.28457000"], ["83523.04000000", "0.04000000"], ["83523.03000000", "0.04000000"], ["83523.00000000", "0.03591000"], ["83522.99000000", "0.04000000"], ["83522.42000000", "0.00417000"], ["83522.14000000", "0.00000000"], ["83520.65000000", "0.04481000"], ["83520.64000000", "0.00006000"], ["83520.34000000", "0.00000000"], ["83520.29000000", "0.00000000"], ["83519.62000000", "0.00000000"], ["83519.38000000", "0.00000000"], ["83518.93000000", "0.00000000"], ["83516.31000000", "0.05988000"], ["83515.08000000", "0.00000000"], ["83513.98000000", "0.00000000"], ["83510.82000000", "0.05000000"], ["83507.53000000", "0.00000000"], ["83505.43000000", "0.67369000"], ["83503.61000000", "0.99280000"], ["83502.07000000", "0.59849000"], ["83500.97000000", "0.44912000"], ["83472.39000000", "0.05000000"], ["83459.45000000", "0.04000000"], ["83457.70000000", "0.04000000"], ["83457.66000000", "0.04000000"], ["83457.36000000", "0.00000000"], ["83456.11000000", "0.04000000"], ["83455.28000000", "0.00000000"], ["83454.63000000", "0.02031000"], ["83454.42000000", "0.00000000"], ["83452.74000000", "0.00000000"], ["83447.06000000", "0.00241000"], ["83443.18000000", "0.04000000"], ["83441.09000000", "1.16935000"], ["83440.17000000", "0.00000000"], ["83417.90000000", "0.00000000"], ["83417.88000000", "0.00078000"], ["83393.82000000", "0.00000000"], ["83386.88000000", "0.00400000"], ["83364.25000000", "0.00000000"], ["83361.62000000", "0.00303000"], ["83336.82000000", "0.00065000"], ["83336.81000000", "0.00000000"], ["83325.93000000", "0.00000000"], ["83324.21000000", "0.00000000"], ["83319.39000000", "0.03591000"], ["82280.18000000", "0.00100000"], ["75181.51000000", "0.00000000"], ["75179.86000000", "0.00032000"], ["75179.00000000", "0.00020000"], ["66826.55000000", "0.00058000"], ["33000.00000000", "2.93934000"], ["30071.95000000", "0.00140000"], ["20002.00000000", "0.00000000"]], "a": [["83533.19000000", "5.02408000"], ["83534.50000000", "0.04796000"], ["83535.63000000", "0.00000000"], ["83535.78000000", "0.00000000"], ["83536.73000000", "0.02496000"], ["83537.50000000", "0.00000000"], ["83537.51000000", "0.00006000"], ["83542.80000000", "0.09200000"], ["83543.12000000", "0.00000000"], ["83543.25000000", "0.00000000"], ["83543.26000000", "0.00000000"], ["83543.34000000", "0.00412000"], ["83543.65000000", "0.08397000"], ["83543.72000000", "0.00000000"], ["83544.06000000", "0.00000000"], ["83544.48000000", "0.06800000"], ["83545.91000000", "0.00000000"], ["83545.96000000", "0.00000000"], ["83546.98000000", "0.06800000"], ["83547.03000000", "0.00000000"], ["83548.65000000", "0.08400000"], ["83548.75000000", "0.00000000"], ["83550.58000000", "0.05985000"], ["83551.04000000", "0.00000000"], ["83552.45000000", "0.00603000"], ["83556.38000000", "0.00468000"], ["83556.63000000", "1.00000000"], ["83557.57000000", "0.05988000"], ["83562.29000000", "0.00000000"], ["83562.74000000", "0.48410000"], ["83565.67000000", "0.86158000"], ["83567.59000000", "0.67369000"], ["83572.90000000", "0.00414000"], ["83573.68000000", "0.00000000"], ["83577.56000000", "0.00000000"], ["83579.60000000", "0.00000000"], ["83579.61000000", "0.00000000"], ["83579.65000000", "0.00000000"], ["83580.87000000", "0.35930000"], ["83581.74000000", "0.00000000"], ["83583.67000000", "0.00000000"], ["83594.33000000", "0.00000000"], ["83596.61000000", "0.00000000"], ["83599.91000000", "0.00000000"], ["83614.50000000", "0.00414000"], ["83629.26000000", "0.00000000"], ["83631.66000000", "0.00884000"], ["83640.89000000", "0.00468000"], ["83641.33000000", "0.02395000"], ["83646.20000000", "0.00000000"], ["83647.10000000", "0.00013000"], ["83652.02000000", "0.00674000"], ["83657.97000000", "0.00039000"], ["83661.48000000", "0.00000000"], ["83670.68000000", "0.00000000"], ["83679.16000000", "0.00000000"], ["83703.11000000", "0.00414000"], ["83722.01000000", "0.01000000"], ["83722.22000000", "0.00008000"], ["83722.72000000", "0.00000000"], ["83723.02000000", "0.00000000"], ["83725.52000000", "0.00000000"], ["83725.72000000", "0.07315000"], ["83726.92000000", "0.00000000"], ["83727.83000000", "0.00000000"], ["83810.70000000", "0.00000000"], ["83900.00000000", "9.43435000"], ["84350.00000000", "4.00037000"], ["84786.19000000", "0.00100000"]], "record_time": 1742377125.909601}
{"e": "depthUpdate", "E": 1742377413014, "s": "BTCUSDT", "U": 64441856209, "u": 64441856262, "b": [["83459.27000000", "1.24600000"], ["83459.11000000", "0.00014000"], ["83446.50000000", "0.00000000"], ["83436.57000000", "0.00000000"], ["83419.85000000", "0.00000000"], ["83332.02000000", "0.99080000"], ["83329.92000000", "0.00000000"], ["83283.72000000", "0.00000000"], ["83000.00000000", "0.68992000"], ["82207.38000000", "0.00100000"], ["79200.00000000", "7.51076000"], ["75113.00000000", "0.03999000"], ["66767.42000000", "0.00058000"], ["60000.00000000", "72.30369000"], ["33000.00000000", "2.93934000"]], "a": [["83459.58000000", "0.00000000"], ["83460.23000000", "0.00000000"], ["83460.24000000", "0.00006000"], ["83463.01000000", "0.00007000"], ["83463.40000000", "0.00500000"], ["83478.71000000", "0.11970000"], ["83503.95000000", "0.00000000"], ["83504.06000000", "0.05000000"], ["83635.06000000", "0.00000000"], ["83637.26000000", "0.99988000"], ["83637.45000000", "0.00000000"], ["83637.65000000", "0.00000000"], ["83637.75000000", "0.01000000"], ["83687.51000000", "0.00000000"], ["83722.15000000", "0.00000000"], ["84711.17000000", "0.00100000"]], "record_time": 1742377413.916838}
{"e": "depthUpdate", "E": 1742377414014, "s": "BTCUSDT", "U": 64441856263, "u": 64441856386, "b": [["83459.27000000", "1.22287000"], ["83459.11000000", "0.00021000"], ["83458.57000000", "0.00007000"], ["83457.90000000", "0.00000000"], ["83457.89000000", "0.00000000"], ["83457.68000000", "0.00071000"], ["83457.46000000", "0.00007000"], ["83455.69000000", "0.00014000"], ["83455.24000000", "0.00014000"], ["83455.23000000", "0.16927000"], ["83455.10000000", "0.00000000"], ["83454.00000000", "0.00000000"], ["83453.28000000", "0.00000000"], ["83450.68000000", "0.00000000"], ["83450.63000000", "0.00000000"], ["83449.16000000", "0.00000000"], ["83449.07000000", "0.03595000"], ["83444.22000000", "1.00000000"], ["83428.65000000", "0.00000000"], ["83372.49000000", "0.00000000"], ["83344.13000000", "0.00078000"], ["83344.01000000", "0.00000000"], ["83292.35000000", "0.01172000"], ["83268.87000000", "0.00065000"], ["83268.86000000", "0.00000000"], ["83251.50000000", "0.00000000"], ["83244.72000000", "0.00400000"], ["82624.67000000", "0.00000000"], ["82207.38000000", "0.00000000"], ["79000.00000000", "89.57021000"], ["76700.00000000", "8.71692000"], ["75113.00000000", "0.03999000"], ["66767.42000000", "0.00058000"], ["33000.00000000", "2.93934000"]], "a": [["83459.28000000", "9.34565000"], ["83459.57000000", "0.30371000"], ["83460.12000000", "0.00000000"], ["83460.99000000", "0.00000000"], ["83461.04000000", "0.00014000"], ["83461.05000000", "0.79077000"], ["83461.33000000", "0.00000000"], ["83463.01000000", "0.00000000"], ["83463.02000000", "0.00000000"], ["83466.94000000", "0.96040000"], ["83468.78000000", "0.50000000"], ["83478.71000000", "0.05985000"], ["83489.00000000", "0.00500000"], ["83503.89000000", "0.00000000"], ["83504.06000000", "0.00000000"], ["83533.12000000", "0.05987000"], ["83537.30000000", "0.00000000"], ["83541.48000000", "0.03592000"], ["83546.37000000", "0.12542000"], ["83548.44000000", "0.00000000"], ["83549.84000000", "0.00000000"], ["83576.23000000", "0.00000000"], ["83576.41000000", "0.00000000"], ["83637.75000000", "0.00000000"], ["83638.85000000", "0.01000000"], ["84711.17000000", "0.00000000"], ["85000.00000000", "139.47982000"], ["86000.00000000", "86.99145000"]], "record_time": 1742377414.916618}
{"e": "depthUpdate", "E": 1742377415014, "s": "BTCUSDT", "U": 64441856387, "u": 64441856594, "b": [["83459.27000000", "1.22287000"], ["83459.11000000", "0.00021000"], ["83452.60000000", "0.00000000"], ["83429.45000000", "0.05000000"], ["83408.24000000", "0.00013000"], ["83407.40000000", "0.02304000"], ["83372.49000000", "2.56011000"], ["83344.13000000", "0.00000000"], ["83344.02000000", "0.00078000"], ["83344.01000000", "0.00000000"], ["83331.80000000", "0.00000000"], ["83268.89000000", "0.00065000"], ["83268.88000000", "0.00000000"], ["83268.87000000", "0.00000000"], ["83250.35000000", "0.00400000"], ["83244.72000000", "0.00000000"], ["82207.38000000", "0.00100000"], ["76782.54000000", "0.00014000"], ["76700.00000000", "9.00843000"], ["75113.00000000", "0.03999000"], ["66767.42000000", "0.00058000"], ["33000.00000000", "2.93934000"], ["30045.34000000", "0.00140000"], ["20002.00000000", "0.00000000"]], "a": [["83459.28000000", "9.34006000"], ["83459.44000000", "0.00014000"], ["83459.46000000", "0.00007000"], ["83459.47000000", "0.00000000"], ["83459.54000000", "0.00021000"], ["83459.55000000", "0.07497000"], ["83459.56000000", "0.00000000"], ["83459.57000000", "0.00000000"], ["83460.00000000", "0.00011000"], ["83460.12000000", "0.00014000"], ["83460.99000000", "0.00014000"], ["83461.04000000", "0.00000000"], ["83461.05000000", "0.00000000"], ["83461.33000000", "0.00014000"], ["83462.90000000", "0.00014000"], ["83462.91000000", "0.79075000"], ["83463.40000000", "0.00000000"], ["83466.96000000", "0.00456000"], ["83478.71000000", "0.11970000"], ["83482.49000000", "0.00000000"], ["83482.57000000", "0.00000000"], ["83494.12000000", "0.00000000"], ["83503.62000000", "0.05000000"], ["83575.51000000", "0.00000000"], ["83576.31000000", "0.05397000"], ["83674.01000000", "0.03455000"], ["83674.75000000", "0.00000000"], ["84711.17000000", "0.00100000"]], "record_time": 1742377415.916981}
{"e": "depthUpdate", "E": 1742377416014, "s": "BTCUSDT", "U": 64441856595, "u": 64441856740, "b": [["83459.27000000", "1.11932000"], ["83457.67000000", "0.03693000"], ["83456.12000000", "0.00000000"], ["83455.68000000", "0.02218000"], ["83455.23000000", "0.16933000"], ["83444.22000000", "0.00000000"], ["83444.21000000", "1.00000000"], ["83442.57000000", "0.45000000"], ["83442.27000000", "0.00000000"], ["83440.38000000", "0.00000000"], ["83438.19000000", "1.34881000"], ["83438.15000000", "0.00000000"], ["83436.62000000", "0.59958000"], ["83436.61000000", "0.80947000"], ["83434.21000000", "0.00000000"], ["83432.20000000", "0.00000000"], ["83431.77000000", "0.00000000"], ["83429.45000000", "0.00000000"], ["83427.48000000", "0.00000000"], ["83426.91000000", "0.86301000"], ["83424.86000000", "0.20761000"], ["83423.18000000", "0.00931000"], ["83422.23000000", "0.00000000"], ["83421.46000000", "0.00000000"], ["83421.27000000", "0.00000000"], ["83419.85000000", "0.05000000"], ["83419.74000000", "0.01862000"], ["83419.35000000", "0.59909000"], ["83415.34000000", "0.39676000"], ["83375.71000000", "0.02064000"], ["83372.49000000", "0.00000000"], ["83370.26000000", "0.00000000"], ["83344.13000000", "0.00078000"], ["83344.02000000", "0.00000000"], ["83335.25000000", "0.45000000"], ["83268.90000000", "0.00065000"], ["83268.89000000", "0.00000000"], ["83250.35000000", "0.00000000"], ["83250.18000000", "0.00400000"], ["83243.56000000", "0.00000000"], ["83138.59000000", "0.19996000"], ["83130.25000000", "0.03399000"], ["82736.29000000", "0.00093000"], ["82736.07000000", "0.00000000"], ["82704.69000000", "0.00060000"], ["82704.47000000", "0.00000000"], ["82569.60000000", "0.00000000"], ["82527.30000000", "0.00000000"], ["82207.38000000", "0.00000000"], ["78500.00000000", "39.30131000"], ["76782.54000000", "0.00000000"], ["76700.00000000", "8.71692000"], ["75113.00000000", "0.03999000"], ["66767.42000000", "0.00058000"], ["33000.00000000", "2.93934000"], ["30045.34000000", "0.00160000"]], "a": [["83459.28000000", "9.37161000"], ["83459.55000000", "0.07503000"], ["83460.13000000", "0.04006000"], ["83460.24000000", "0.00000000"], ["83461.00000000", "0.04796000"], ["83461.34000000", "0.08998000"], ["83462.00000000", "0.07126000"], ["83466.97000000", "0.00454000"], ["83467.08000000", "0.00006000"], ["83478.71000000", "0.05985000"], ["83482.57000000", "0.03595000"], ["83484.71000000", "0.00756000"], ["83486.17000000", "0.00000000"], ["83489.00000000", "0.00500000"], ["83503.62000000", "0.00000000"], ["83503.86000000", "0.05000000"], ["83528.94000000", "0.05987000"], ["83533.12000000", "0.00000000"], ["83543.88000000", "0.09344000"], ["83546.60000000", "0.07903000"], ["83551.05000000", "0.02397000"], ["83558.95000000", "0.00000000"], ["83572.27000000", "0.14739000"], ["83573.96000000", "0.00000000"], ["83575.29000000", "0.05397000"], ["83576.31000000", "0.00000000"], ["84711.17000000", "0.00000000"], ["85000.00000000", "139.32982000"], ["149123.00000000", "0.00000000"]], "record_time": 1742377416.91737}
{"e": "depthUpdate", "E": 1742377417014, "s": "BTCUSDT", "U": 64441856741, "u": 64441856864, "b": [["83459.27000000", "1.10742000"], ["83456.40000000", "0.00000000"], ["83455.68000000", "0.02218000"], ["83455.24000000", "0.00000000"], ["83455.23000000", "0.00000000"], ["83453.28000000", "0.00014000"], ["83450.76000000", "0.00014000"], ["83450.75000000", "0.13599000"], ["83450.68000000", "0.00000000"], ["83450.63000000", "0.00000000"], ["83446.40000000", "0.00000000"], ["83444.21000000", "0.00000000"], ["83442.57000000", "0.45000000"], ["83436.57000000", "0.43866000"], ["83427.45000000", "0.00000000"], ["83423.18000000", "0.00000000"], ["83421.89000000", "0.00931000"], ["83419.85000000", "0.05000000"], ["83414.85000000", "0.00000000"], ["83369.78000000", "2.56011000"], ["83368.91000000", "0.00000000"], ["83344.13000000", "0.00078000"], ["83332.02000000", "0.00000000"], ["83329.25000000", "0.99080000"], ["83268.91000000", "0.00065000"], ["83268.90000000", "0.00000000"], ["83250.18000000", "0.00000000"], ["83237.11000000", "0.00400000"], ["82207.38000000", "0.00100000"], ["76700.00000000", "9.01544000"], ["75113.00000000", "0.03999000"], ["66767.42000000", "0.00058000"], ["33000.00000000", "2.93934000"]], "a": [["83459.28000000", "10.19572000"], ["83459.55000000", "0.31029000"], ["83460.12000000", "0.00000000"], ["83460.13000000", "0.04006000"], ["83460.61000000", "0.02458000"], ["83460.63000000", "0.00014000"], ["83460.64000000", "0.79083000"], ["83460.99000000", "0.00000000"], ["83461.33000000", "0.00000000"], ["83462.00000000", "0.07120000"], ["83462.90000000", "0.00000000"], ["83462.91000000", "0.00000000"], ["83463.40000000", "0.00500000"], ["83465.00000000", "0.00059000"], ["83470.86000000", "0.01887000"], ["83472.74000000", "0.00000000"], ["83488.00000000", "0.00400000"], ["83489.00000000", "0.00000000"], ["83497.14000000", "0.00805000"], ["83497.41000000", "0.00000000"], ["83498.00000000", "0.00400000"], ["83501.78000000", "0.05000000"], ["83503.86000000", "0.00000000"], ["83506.99000000", "0.00000000"], ["83544.63000000", "0.09344000"], ["83571.03000000", "0.00000000"], ["83574.88000000", "0.08869000"], ["83575.29000000", "0.00000000"], ["83604.95000000", "0.00040000"], ["83612.29000000", "0.00012000"], ["83613.34000000", "0.00000000"], ["84711.17000000", "0.00100000"], ["85500.00000000", "30.00806000"]], "record_time": 1742377417.917902}
{"e": "depthUpdate", "E": 1742377418014, "s": "BTCUSDT", "U": 64441856865, "u": 64441856988, "b": [["83459.27000000", "1.05182000"], ["83456.50000000", "0.00000000"], ["83450.21000000", "0.00000000"], ["83449.11000000", "0.16000000"], ["83449.07000000", "0.00000000"], ["83448.69000000", "0.00000000"], ["83448.65000000", "0.03595000"], ["83446.50000000", "0.00000000"], ["83442.57000000", "0.00000000"], ["83436.62000000", "0.00000000"], ["83436.61000000", "0.80947000"], ["83436.57000000", "0.00000000"], ["83435.96000000", "0.00000000"], ["83426.92000000", "0.23380000"], ["83422.85000000", "0.00008000"], ["83421.89000000", "0.00000000"], ["83419.85000000", "0.00000000"], ["83419.74000000", "0.00931000"], ["83418.52000000", "0.00000000"], ["83416.73000000", "0.01862000"], ["83396.47000000", "0.00000000"], ["83388.73000000", "0.00000000"], ["83387.22000000", "0.00000000"], ["83384.71000000", "0.00000000"], ["83384.65000000", "0.05197000"], ["83384.00000000", "0.09577000"], ["83381.68000000", "0.00000000"], ["83381.62000000", "0.00000000"], ["83375.71000000", "0.00000000"], ["83369.78000000", "0.00000000"], ["83358.53000000", "0.09969000"], ["83356.48000000", "0.14368000"], ["83356.37000000", "0.04672000"], ["83355.47000000", "0.04672000"], ["83355.39000000", "0.04672000"], ["83353.57000000", "0.09870000"], ["83350.44000000", "0.04672000"], ["83348.35000000", "0.04912000"], ["83056.93000000", "0.00041000"], ["83050.61000000", "1.19831000"], ["82864.24000000", "0.00000000"], ["82639.56000000", "0.00000000"], ["82633.27000000", "1.46922000"], ["82569.60000000", "0.02362000"], ["82207.38000000", "0.00000000"], ["81310.00000000", "0.00607000"], ["76700.00000000", "8.71692000"], ["75113.00000000", "0.03999000"], ["66767.42000000", "0.00058000"], ["33000.00000000", "2.93934000"]], "a": [["83459.28000000", "10.19056000"], ["83463.40000000", "0.00000000"], ["83466.58000000", "0.19941000"], ["83467.41000000", "0.00068000"], ["83468.71000000", "0.01887000"], ["83470.86000000", "0.00000000"], ["83480.59000000", "0.02790000"], ["83483.28000000", "0.00000000"], ["83488.00000000", "0.00000000"], ["83489.00000000", "0.00500000"], ["83489.19000000", "0.00000000"], ["83490.67000000", "0.00358000"], ["83490.87000000", "0.00821000"], ["83498.00000000", "0.00000000"], ["83501.23000000", "0.00000000"], ["83501.41000000", "0.04937000"], ["83504.48000000", "0.00000000"], ["83514.62000000", "0.00000000"], ["83572.27000000", "0.09342000"], ["83573.60000000", "0.00000000"], ["83687.28000000", "0.00029000"], ["83885.28000000", "1.19831000"], ["83891.66000000", "0.00000000"], ["84302.62000000", "1.79747000"], ["84309.03000000", "0.00000000"], ["84711.17000000", "0.00000000"], ["84719.96000000", "0.59916000"], ["84726.40000000", "0.00000000"], ["85767.83000000", "0.00000000"], ["85767.87000000", "0.07039000"]], "record_time": 1742377418.917517}
{"e": "depthUpdate", "E": 1742377419014, "s": "BTCUSDT", "U": 64441856989, "u": 64441858862, "b": [["83459.27000000", "0.00000000"], ["83459.26000000", "0.00000000"], ["83459.25000000", "0.00000000"], ["83459.24000000", "0.00000000"], ["83459.11000000", "0.00000000"], ["83458.60000000", "0.00000000"], ["83458.58000000", "0.00000000"], ["83458.57000000", "0.00000000"], ["83457.68000000", "0.00000000"], ["83457.67000000", "0.00000000"], ["83457.46000000", "0.00000000"], ["83457.44000000", "0.00000000"], ["83457.07000000", "0.00000000"], ["83457.01000000", "0.00000000"], ["83456.63000000", "0.00000000"], ["83456.22000000", "0.00000000"], ["83456.21000000", "0.00000000"], ["83455.80000000", "0.00000000"], ["83455.69000000", "0.00000000"], ["83455.68000000", "0.00000000"], ["83454.97000000", "0.00000000"], ["83454.92000000", "0.00000000"], ["83454.79000000", "0.00000000"], ["83454.54000000", "0.00000000"], ["83454.53000000", "0.00000000"], ["83453.89000000", "0.00000000"], ["83453.28000000", "0.00000000"], ["83453.27000000", "1.63051000"], ["83453.25000000", "0.00041000"], ["83453.24000000", "0.00044000"], ["83453.22000000", "0.00097000"], ["83453.21000000", "0.00772000"], ["83453.05000000", "0.00021000"], ["83453.04000000", "0.00760000"], ["83452.67000000", "0.00021000"], ["83452.66000000", "0.16586000"], ["83452.49000000", "0.00000000"], ["83451.90000000", "0.00000000"], ["83451.60000000", "0.00008000"], ["83451.41000000", "0.00000000"], ["83450.93000000", "0.03611000"], ["83450.83000000", "0.00007000"], ["83450.76000000", "0.00000000"], ["83450.75000000", "0.00006000"], ["83450.67000000", "0.04006000"], ["83450.63000000", "0.00000000"], ["83450.62000000", "0.08510000"], ["83450.50000000", "0.04790000"], ["83449.80000000", "0.00000000"], ["83449.71000000", "0.02212000"], ["83449.19000000", "0.00000000"], ["83449.12000000", "0.00007000"], ["83449.11000000", "0.00000000"], ["83448.66000000", "0.00006000"], ["83448.65000000", "0.00000000"], ["83448.62000000", "0.00012000"], ["83448.61000000", "0.00000000"], ["83448.51000000", "0.00101000"], ["83448.49000000", "0.00271000"], ["83448.12000000", "0.00000000"], ["83448.11000000", "0.28000000"], ["83448.00000000", "0.07355000"], ["83447.49000000", "0.00000000"], ["83447.22000000", "0.00000000"], ["83446.26000000", "0.00000000"], ["83445.99000000", "0.00300000"], ["83445.94000000", "0.00000000"], ["83445.93000000", "0.00000000"], ["83445.91000000", "0.03595000"], ["83445.34000000", "0.00000000"], ["83444.92000000", "0.45000000"], ["83442.80000000", "0.00000000"], ["83442.71000000", "0.00000000"], ["83441.61000000", "0.26329000"], ["83441.60000000", "0.32000000"], ["83440.75000000", "0.00000000"], ["83440.74000000", "0.00000000"], ["83440.39000000", "0.00000000"], ["83439.05000000", "0.00000000"], ["83438.92000000", "0.00878000"], ["83438.19000000", "0.00000000"], ["83438.02000000", "0.00094000"], ["83437.81000000", "0.00000000"], ["83437.79000000", "0.00000000"], ["83437.54000000", "0.00092000"], ["83437.00000000", "0.00000000"], ["83436.97000000", "0.00000000"], ["83436.62000000", "0.00000000"], ["83436.61000000", "0.00000000"], ["83436.60000000", "0.00000000"], ["83436.58000000", "0.00059000"], ["83436.07000000", "0.00000000"], ["83435.38000000", "0.42272000"], ["83435.37000000", "0.27826000"], ["83434.73000000", "0.86293000"], ["83433.70000000", "0.00000000"], ["83433.52000000", "0.00000000"], ["83433.35000000", "0.00000000"], ["83432.70000000", "0.00000000"], ["83432.20000000", "1.33253000"], ["83430.83000000", "0.10617000"], ["83430.07000000", "0.00503000"], ["83429.50000000", "0.04790000"], ["83429.26000000", "0.00000000"], ["83428.24000000", "0.00059000"], ["83428.23000000", "0.00300000"], ["83425.52000000", "0.00000000"], ["83423.61000000", "0.01862000"], ["83423.31000000", "0.86305000"], ["83421.62000000", "0.17956000"], ["83420.61000000", "0.00000000"], ["83419.85000000", "0.00000000"], ["83418.51000000", "0.00000000"], ["83417.54000000", "0.00000000"], ["83417.48000000", "0.07934000"], ["83416.73000000", "0.00000000"], ["83416.66000000", "0.05994000"], ["83416.09000000", "0.00000000"], ["83415.01000000", "0.00000000"], ["83413.33000000", "0.00000000"], ["83413.32000000", "0.00000000"], ["83411.57000000", "0.00000000"], ["83411.54000000", "0.00059000"], ["83410.90000000", "0.76302000"], ["83410.73000000", "0.03330000"], ["83410.00000000", "0.00019000"], ["83409.95000000", "0.00000000"], ["83407.41000000", "0.00032000"], ["83404.10000000", "0.89775000"], ["83403.07000000", "0.00000000"], ["83401.72000000", "0.89775000"], ["83399.41000000", "0.00000000"], ["83396.13000000", "0.00297000"], ["83395.99000000", "0.00000000"], ["83394.42000000", "0.00000000"], ["83393.54000000", "0.00000000"], ["83388.08000000", "0.00000000"], ["83388.00000000", "0.04786000"], ["83385.37000000", "0.00000000"], ["83383.36000000", "0.00000000"], ["83381.31000000", "0.05398000"], ["83378.22000000", "0.09343000"], ["83376.11000000", "0.00144000"], ["83374.24000000", "0.00000000"], ["83373.14000000", "0.00000000"], ["83372.18000000", "0.00000000"], ["83371.58000000", "0.04671000"], ["83370.51000000", "0.00308000"], ["83368.93000000", "0.01874000"], ["83367.66000000", "0.00000000"], ["83362.12000000", "0.00000000"], ["83359.32000000", "0.00000000"], ["83357.51000000", "0.00032000"], ["83356.44000000", "0.59958000"], ["83352.81000000", "0.00000000"], ["83350.96000000", "0.00000000"], ["83348.13000000", "0.04198000"], ["83347.01000000", "0.05298000"], ["83346.97000000", "0.04459000"], ["83344.64000000", "0.05397000"], ["83344.13000000", "0.00000000"], ["83343.87000000", "0.05298000"], ["83342.78000000", "0.04198000"], ["83341.63000000", "0.05298000"], ["83340.59000000", "0.05397000"], ["83339.07000000", "0.05298000"], ["83338.28000000", "0.04198000"], ["83337.60000000", "0.00078000"], ["83336.39000000", "0.05298000"], ["83333.12000000", "0.00013000"], ["83288.09000000", "0.00000000"], ["83284.63000000", "0.00013000"], ["83277.87000000", "0.00243000"], ["83269.29000000", "0.00000000"], ["83268.92000000", "0.00000000"], ["83268.91000000", "0.00000000"], ["83262.21000000", "0.00065000"], ["83262.20000000", "0.00064000"], ["83258.34000000", "0.00400000"], ["83237.11000000", "0.00000000"], ["83235.61000000", "0.00000000"], ["83221.19000000", "0.00000000"], ["83195.14000000", "0.00013000"], ["83192.32000000", "0.00000000"], ["83190.97000000", "0.00013000"], ["83131.11000000", "0.20138000"], ["83122.77000000", "0.23528000"], ["83114.46000000", "0.05288000"], ["82869.79000000", "0.02397000"], ["82569.60000000", "0.00000000"], ["82201.47000000", "0.00100000"], ["79200.00000000", "7.51076000"], ["76700.00000000", "9.00196000"], ["75113.00000000", "0.03979000"], ["75109.00000000", "0.00103000"], ["75107.00000000", "0.00219000"], ["66767.42000000", "0.00000000"], ["66762.62000000", "0.00058000"], ["33000.00000000", "2.93934000"], ["30043.18000000", "0.00020000"]], "a": [["83453.28000000", "7.21210000"], ["83453.29000000", "0.00014000"], ["83453.90000000", "0.00000000"], ["83453.99000000", "0.00014000"], ["83454.00000000", "0.00014000"], ["83454.14000000", "0.00021000"], ["83454.54000000", "0.00007000"], ["83454.55000000", "0.00000000"], ["83454.89000000", "0.00021000"], ["83454.90000000", "0.26873000"], ["83454.91000000", "0.00000000"], ["83454.92000000", "0.00020000"], ["83454.93000000", "0.11941000"], ["83454.96000000", "0.00007000"], ["83454.98000000", "0.00000000"], ["83455.57000000", "0.00000000"], ["83455.67000000", "0.00494000"], ["83455.68000000", "0.00020000"], ["83455.69000000", "0.57598000"], ["83455.70000000", "0.00000000"], ["83455.81000000", "0.00000000"], ["83456.00000000", "0.00000000"], ["83456.21000000", "0.00000000"], ["83456.22000000", "0.00000000"], ["83456.23000000", "0.00000000"], ["83456.34000000", "0.00006000"], ["83456.45000000", "0.00000000"], ["83456.84000000", "0.02595000"], ["83457.02000000", "0.00000000"], ["83457.08000000", "0.00000000"], ["83457.18000000", "0.00119000"], ["83457.28000000", "0.05985000"], ["83457.33000000", "0.00000000"], ["83457.44000000", "0.00000000"], ["83457.45000000", "0.05992000"], ["83457.47000000", "0.00000000"], ["83457.50000000", "0.04790000"], ["83457.57000000", "0.00000000"], ["83457.59000000", "0.00000000"], ["83457.68000000", "0.00000000"], ["83457.69000000", "0.00000000"], ["83458.00000000", "0.00000000"], ["83458.35000000", "0.00000000"], ["83458.57000000", "0.60578000"], ["83458.58000000", "0.08463000"], ["83458.59000000", "0.00000000"], ["83458.61000000", "0.00085000"], ["83458.84000000", "0.00006000"], ["83459.00000000", "0.00371000"], ["83459.04000000", "0.00000000"], ["83459.11000000", "0.00000000"], ["83459.12000000", "0.00000000"], ["83459.13000000", "0.00000000"], ["83459.24000000", "0.00000000"], ["83459.25000000", "0.00144000"], ["83459.26000000", "0.00000000"], ["83459.27000000", "0.00000000"], ["83459.28000000", "0.87540000"], ["83459.29000000", "0.00000000"], ["83459.37000000", "0.00000000"], ["83459.43000000", "0.00000000"], ["83459.44000000", "0.00000000"], ["83459.46000000", "0.00000000"], ["83459.54000000", "0.00000000"], ["83459.55000000", "0.00000000"], ["83460.00000000", "0.07131000"], ["83460.12000000", "0.00000000"], ["83460.13000000", "0.00000000"], ["83460.16000000", "0.12000000"], ["83460.61000000", "0.00000000"], ["83460.63000000", "0.00000000"], ["83460.64000000", "0.00000000"], ["83460.76000000", "0.00000000"], ["83460.99000000", "0.09600000"], ["83461.00000000", "0.04790000"], ["83461.20000000", "0.00278000"], ["83461.34000000", "0.00000000"], ["83461.35000000", "0.00000000"], ["83461.63000000", "0.00300000"], ["83461.82000000", "0.09600000"], ["83461.84000000", "0.08800000"], ["83461.92000000", "0.09200000"], ["83461.94000000", "0.00000000"], ["83462.00000000", "0.07120000"], ["83462.25000000", "0.00119000"], ["83462.59000000", "0.00013000"], ["83462.86000000", "0.00000000"], ["83462.87000000", "0.00000000"], ["83463.21000000", "0.00000000"], ["83463.31000000", "0.18325000"], ["83463.34000000", "0.00127000"], ["83463.70000000", "0.00013000"], ["83463.92000000", "0.01198000"], ["83464.34000000", "0.08400000"], ["83465.00000000", "0.00000000"], ["83465.16000000", "0.10400000"], ["83465.26000000", "0.00119000"], ["83465.68000000", "0.06000000"], ["83465.76000000", "0.00000000"], ["83466.00000000", "0.25920000"], ["83466.09000000", "0.08800000"], ["83466.58000000", "0.08000000"], ["83466.94000000", "1.45003000"], ["83466.96000000", "0.00371000"], ["83466.97000000", "0.00478000"], ["83467.05000000", "0.00000000"], ["83467.14000000", "0.00000000"], ["83467.27000000", "0.00000000"], ["83467.32000000", "0.00000000"], ["83467.41000000", "0.00009000"], ["83467.64000000", "0.00000000"], ["83467.83000000", "0.89775000"], ["83467.88000000", "0.00000000"], ["83468.64000000", "0.00000000"], ["83468.71000000", "0.00000000"], ["83468.72000000", "0.00000000"], ["83469.87000000", "0.00000000"], ["83469.97000000", "0.06044000"], ["83469.99000000", "0.67331000"], ["83470.68000000", "0.00000000"], ["83471.06000000", "0.80336000"], ["83471.07000000", "0.89775000"], ["83471.23000000", "0.00000000"], ["83471.37000000", "0.01887000"], ["83471.41000000", "0.00000000"], ["83471.54000000", "0.00000000"], ["83471.63000000", "0.00000000"], ["83473.88000000", "0.00000000"], ["83473.97000000", "0.00000000"], ["83474.04000000", "0.00000000"], ["83474.38000000", "0.00000000"], ["83474.68000000", "0.00000000"], ["83474.88000000", "0.00000000"], ["83475.69000000", "0.00000000"], ["83475.70000000", "0.00000000"], ["83475.81000000", "0.00000000"], ["83476.75000000", "0.00000000"], ["83477.15000000", "0.89775000"], ["83478.31000000", "0.05985000"], ["83478.32000000", "0.00059000"], ["83478.71000000", "0.00000000"], ["83479.02000000", "0.00000000"], ["83480.47000000", "0.00000000"], ["83480.60000000", "0.00000000"], ["83481.88000000", "0.09600000"], ["83481.98000000", "0.00267000"], ["83482.06000000", "0.23528000"], ["83482.71000000", "0.09600000"], ["83483.27000000", "0.00000000"], ["83483.87000000", "0.00000000"], ["83484.31000000", "0.00000000"], ["83484.32000000", "0.00000000"], ["83484.66000000", "0.59906000"], ["83485.23000000", "0.08400000"], ["83485.50000000", "0.00000000"], ["83486.05000000", "0.10400000"], ["83486.89000000", "0.09200000"], ["83486.98000000", "0.08800000"], ["83487.37000000", "0.00000000"], ["83488.01000000", "0.00367000"], ["83491.84000000", "0.64454000"], ["83492.96000000", "0.00000000"], ["83493.74000000", "0.35910000"], ["83494.77000000", "0.00000000"], ["83495.00000000", "0.00059000"], ["83495.65000000", "0.00000000"], ["83496.11000000", "0.01874000"], ["83496.19000000", "0.00000000"], ["83496.22000000", "0.00000000"], ["83497.01000000", "0.00000000"], ["83497.89000000", "0.00000000"], ["83499.61000000", "0.00000000"], ["83500.40000000", "0.00811000"], ["83501.01000000", "0.00000000"], ["83501.41000000", "0.00000000"], ["83501.74000000", "0.00013000"], ["83501.78000000", "0.00000000"], ["83505.02000000", "0.05000000"], ["83505.83000000", "0.05328000"], ["83506.90000000", "0.00297000"], ["83511.15000000", "0.00000000"], ["83512.51000000", "0.00000000"], ["83515.53000000", "0.04937000"], ["83519.44000000", "0.09200000"], ["83520.97000000", "0.00000000"], ["83521.64000000", "0.00000000"], ["83522.19000000", "0.35910000"], ["83523.37000000", "0.44887000"], ["83524.76000000", "0.00006000"], ["83525.51000000", "0.00000000"], ["83528.94000000", "0.00000000"], ["83529.81000000", "0.00000000"], ["83530.66000000", "0.59958000"], ["83530.81000000", "0.00000000"], ["83533.12000000", "0.00000000"], ["83533.45000000", "0.00000000"], ["83534.99000000", "0.00000000"], ["83539.48000000", "0.01196000"], ["83541.47000000", "0.00298000"], ["83541.48000000", "0.00000000"], ["83543.88000000", "0.13897000"], ["83547.66000000", "0.00000000"], ["83547.85000000", "0.09224000"], ["83548.49000000", "0.00000000"], ["83557.91000000", "0.13055000"], ["83568.88000000", "0.16193000"], ["83571.52000000", "0.15368000"], ["83572.27000000", "0.14739000"], ["83574.88000000", "0.08869000"], ["83583.35000000", "0.36779000"], ["83585.00000000", "0.00000000"], ["83586.66000000", "0.05397000"], ["83587.32000000", "0.00000000"], ["83588.46000000", "0.00143000"], ["83589.69000000", "0.00000000"], ["83590.61000000", "0.00000000"], ["83591.36000000", "0.00000000"], ["83592.97000000", "0.04198000"], ["83593.71000000", "0.04551000"], ["83594.47000000", "0.00000000"], ["83594.99000000", "0.00000000"], ["83595.59000000", "0.00000000"], ["83595.99000000", "0.00000000"], ["83598.49000000", "0.00000000"], ["83599.24000000", "0.00000000"], ["83603.60000000", "0.00000000"], ["83607.88000000", "0.18564000"], ["83610.91000000", "0.00000000"], ["83630.51000000", "0.00000000"], ["83636.74000000", "0.00000000"], ["83637.45000000", "0.00000000"], ["83638.45000000", "0.01000000"], ["83638.85000000", "0.00000000"], ["83714.60000000", "0.00000000"], ["83748.94000000", "0.06938000"], ["83804.18000000", "0.00000000"], ["84287.80000000", "0.00000000"], ["84306.12000000", "0.00000000"], ["84705.08000000", "0.00135000"], ["84811.50000000", "0.00000000"], ["84884.80000000", "0.05900000"], ["84906.00000000", "0.00000000"], ["86500.00000000", "18.32951000"], ["129882.00000000", "0.00000000"]], "record_time": 1742377419.918823}
{"e": "depthUpdate", "E": 1742377420014, "s": "BTCUSDT", "U": 64441858863, "u": 64441859168, "b": [["83453.27000000", "4.53547000"], ["83453.22000000", "0.00083000"], ["83453.21000000", "0.00014000"], ["83453.05000000", "0.00007000"], ["83453.04000000", "0.00007000"], ["83452.84000000", "0.31551000"], ["83452.67000000", "0.00014000"], ["83450.93000000", "0.07086000"], ["83449.12000000", "0.00000000"], ["83449.10000000", "0.00500000"], ["83448.38000000", "0.34145000"], ["83448.37000000", "0.33040000"], ["83448.12000000", "0.00000000"], ["83447.39000000", "0.00754000"], ["83446.97000000", "0.00758000"], ["83446.72000000", "0.00000000"], ["83444.93000000", "0.32388000"], ["83444.85000000", "0.00000000"], ["83444.40000000", "0.00000000"], ["83442.12000000", "0.00000000"], ["83441.61000000", "0.40521000"], ["83440.75000000", "0.00161000"], ["83438.68000000", "0.86289000"], ["83438.02000000", "0.00000000"], ["83437.75000000", "0.00899000"], ["83437.54000000", "0.00000000"], ["83435.37000000", "0.00000000"], ["83434.75000000", "0.03765000"], ["83432.21000000", "0.59902000"], ["83427.24000000", "0.05985000"], ["83426.40000000", "0.04000000"], ["83423.31000000", "0.00000000"], ["83422.65000000", "0.00000000"], ["83419.70000000", "0.00000000"], ["83419.35000000", "0.00000000"], ["83417.66000000", "0.08992000"], ["83417.48000000", "0.04169000"], ["83416.66000000", "0.00000000"], ["83410.15000000", "0.00000000"], ["83405.85000000", "0.00000000"], ["83402.90000000", "0.00000000"], ["83378.23000000", "0.00000000"], ["83372.37000000", "0.00000000"], ["83370.51000000", "0.00000000"], ["83368.93000000", "0.00000000"], ["83368.18000000", "0.00308000"], ["83357.51000000", "0.00000000"], ["83353.39000000", "0.00032000"], ["83335.25000000", "0.00000000"], ["83323.56000000", "0.00400000"], ["83295.64000000", "0.00000000"], ["83277.86000000", "0.00000000"], ["83272.01000000", "0.00838000"], ["83258.34000000", "0.00000000"], ["82569.60000000", "0.02362000"], ["82201.47000000", "0.00000000"], ["76700.00000000", "8.71692000"], ["75107.00000000", "0.00219000"], ["66762.62000000", "0.00058000"], ["33000.00000000", "2.93934000"], ["30043.18000000", "0.00060000"], ["20002.00000000", "0.00000000"]], "a": [["83453.28000000", "1.01633000"], ["83453.29000000", "0.00014000"], ["83453.31000000", "0.00021000"], ["83453.42000000", "0.00028000"], ["83453.43000000", "0.02907000"], ["83453.99000000", "0.00007000"], ["83454.00000000", "0.00007000"], ["83454.10000000", "0.00007000"], ["83454.14000000", "0.00007000"], ["83454.54000000", "0.00000000"], ["83454.89000000", "0.00014000"], ["83454.90000000", "0.05441000"], ["83454.92000000", "0.00000000"], ["83454.93000000", "0.00000000"], ["83455.67000000", "0.00000000"], ["83455.68000000", "0.00000000"], ["83455.69000000", "0.00000000"], ["83456.34000000", "0.00000000"], ["83456.51000000", "0.00014000"], ["83456.52000000", "0.10617000"], ["83456.91000000", "0.00000000"], ["83457.28000000", "0.00000000"], ["83457.45000000", "0.00007000"], ["83457.86000000", "0.00008000"], ["83458.56000000", "0.00014000"], ["83459.28000000", "0.44988000"], ["83460.00000000", "0.00011000"], ["83460.26000000", "0.30931000"], ["83461.64000000", "0.35910000"], ["83462.00000000", "0.00000000"], ["83463.69000000", "0.00421000"], ["83464.00000000", "0.00000000"], ["83464.94000000", "0.31935000"], ["83465.68000000", "0.00000000"], ["83466.45000000", "0.00000000"], ["83466.58000000", "0.00000000"], ["83466.93000000", "0.00000000"], ["83466.97000000", "0.00408000"], ["83467.48000000", "0.02000000"], ["83467.78000000", "0.12000000"], ["83469.97000000", "0.00059000"], ["83471.37000000", "0.00000000"], ["83473.56000000", "0.00000000"], ["83473.76000000", "0.00000000"], ["83473.93000000", "0.00000000"], ["83474.18000000", "0.35910000"], ["83475.61000000", "0.00000000"], ["83475.80000000", "0.00000000"], ["83477.14000000", "0.00267000"], ["83477.94000000", "0.00000000"], ["83478.22000000", "0.00878000"], ["83478.31000000", "0.11970000"], ["83478.71000000", "0.12724000"], ["83478.90000000", "1.37781000"], ["83479.31000000", "0.00000000"], ["83480.59000000", "0.00000000"], ["83480.86000000", "0.01887000"], ["83481.11000000", "0.00754000"], ["83481.98000000", "0.00000000"], ["83482.31000000", "0.00000000"], ["83483.67000000", "0.00000000"], ["83484.66000000", "0.00000000"], ["83484.67000000", "0.00000000"], ["83484.71000000", "0.00000000"], ["83487.68000000", "0.00006000"], ["83488.76000000", "0.00000000"], ["83489.00000000", "0.00500000"], ["83489.11000000", "0.59902000"], ["83492.63000000", "0.02790000"], ["83505.02000000", "0.00000000"], ["83510.92000000", "0.59958000"], ["83515.53000000", "0.00000000"], ["83521.96000000", "0.04937000"], ["83522.03000000", "0.00699000"], ["83531.70000000", "0.00000000"], ["83533.17000000", "0.00025000"], ["83539.23000000", "0.00000000"], ["83567.83000000", "0.17187000"], ["83591.99000000", "0.23476000"], ["83592.97000000", "0.00000000"], ["83607.16000000", "0.00021000"], ["83613.33000000", "0.00000000"], ["83637.05000000", "0.00000000"], ["83637.25000000", "0.00000000"], ["83637.35000000", "0.00000000"], ["83637.85000000", "0.00000000"], ["83638.45000000", "0.00000000"], ["83639.55000000", "0.01000000"], ["84705.08000000", "0.00035000"], ["84811.50000000", "0.00000000"]], "record_time": 1742377420.917611}
{"e": "depthUpdate", "E": 1742377421014, "s": "BTCUSDT", "U": 64441859169, "u": 64441859351, "b": [["83453.27000000", "4.12556000"], ["83443.69000000", "0.42840000"], ["83441.44000000", "0.00000000"], ["83440.71000000", "0.05000000"], ["83438.92000000", "0.00000000"], ["83438.78000000", "0.00100000"], ["83434.75000000", "0.00000000"], ["83433.35000000", "0.05993000"], ["83432.21000000", "0.00000000"], ["83432.20000000", "1.36046000"], ["83431.21000000", "0.00878000"], ["83428.69000000", "0.59903000"], ["83427.24000000", "0.00000000"], ["83425.34000000", "0.03765000"], ["83423.61000000", "0.00000000"], ["83422.85000000", "0.00000000"], ["83419.74000000", "0.00000000"], ["83337.62000000", "0.00078000"], ["83337.61000000", "0.00000000"], ["83337.60000000", "0.00000000"], ["83336.33000000", "0.99080000"], ["83335.91000000", "0.00000000"], ["83329.25000000", "0.00000000"], ["83326.38000000", "0.00400000"], ["83323.56000000", "0.00000000"], ["83262.23000000", "0.00065000"], ["83262.22000000", "0.00000000"], ["83262.21000000", "0.00000000"], ["82201.47000000", "0.00100000"], ["76782.54000000", "0.00000000"], ["76700.00000000", "9.01232000"], ["75107.00000000", "0.00219000"], ["66762.62000000", "0.00058000"], ["42000.00000000", "6.98916000"], ["33000.00000000", "2.93934000"]], "a": [["83453.28000000", "0.97602000"], ["83453.43000000", "0.02907000"], ["83453.86000000", "0.00021000"], ["83453.87000000", "0.10107000"], ["83453.88000000", "0.15464000"], ["83453.99000000", "0.00000000"], ["83454.00000000", "0.00000000"], ["83454.10000000", "0.00000000"], ["83454.14000000", "0.00000000"], ["83454.89000000", "0.00000000"], ["83454.90000000", "0.00000000"], ["83454.96000000", "0.00000000"], ["83455.14000000", "0.00012000"], ["83455.73000000", "0.00008000"], ["83456.51000000", "0.00000000"], ["83457.17000000", "0.00494000"], ["83457.53000000", "0.00000000"], ["83457.86000000", "0.00000000"], ["83458.23000000", "0.00000000"], ["83460.04000000", "0.03400000"], ["83460.48000000", "0.00100000"], ["83463.31000000", "0.25706000"], ["83464.94000000", "0.31959000"], ["83466.96000000", "0.00359000"], ["83466.97000000", "0.00384000"], ["83473.90000000", "1.00000000"], ["83478.02000000", "0.01887000"], ["83479.30000000", "0.00000000"], ["83480.86000000", "0.00000000"], ["83481.11000000", "0.00000000"], ["83482.05000000", "0.00756000"], ["83483.74000000", "0.39676000"], ["83491.38000000", "0.00000000"], ["83491.80000000", "1.03020000"], ["83491.84000000", "0.00000000"], ["83518.07000000", "0.00000000"], ["83521.67000000", "0.00000000"], ["83522.17000000", "0.00699000"], ["83533.17000000", "0.00025000"], ["83537.30000000", "0.05986000"], ["83549.84000000", "0.03592000"], ["83607.16000000", "0.00021000"], ["83637.26000000", "0.00000000"], ["83639.55000000", "0.00000000"], ["83639.65000000", "0.01009000"], ["83640.69000000", "0.99219000"], ["84287.81000000", "0.00006000"], ["84705.08000000", "0.00135000"]], "record_time": 1742377421.917114}
{"e": "depthUpdate", "E": 1742377422014, "s": "BTCUSDT", "U": 64441859352, "u": 64441859563, "b": [["83453.27000000", "1.71463000"], ["83453.26000000", "0.00028000"], ["83453.25000000", "0.00027000"], ["83453.21000000", "0.00007000"], ["83453.04000000", "0.00007000"], ["83452.85000000", "0.00000000"], ["83452.84000000", "0.00000000"], ["83450.94000000", "0.00014000"], ["83450.85000000", "0.00759000"], ["83450.43000000", "0.00755000"], ["83449.11000000", "0.00007000"], ["83449.10000000", "0.00500000"], ["83448.38000000", "0.00000000"], ["83448.37000000", "0.00000000"], ["83447.39000000", "0.00000000"], ["83447.27000000", "0.31544000"], ["83446.97000000", "0.00000000"], ["83444.93000000", "0.32388000"], ["83443.87000000", "0.00415000"], ["83443.86000000", "0.00000000"], ["83443.69000000", "0.00000000"], ["83443.41000000", "0.00096000"], ["83443.15000000", "0.00091000"], ["83442.83000000", "0.33040000"], ["83440.71000000", "0.00000000"], ["83439.78000000", "0.00000000"], ["83436.38000000", "0.34257000"], ["83432.20000000", "0.02793000"], ["83430.35000000", "0.91297000"], ["83428.69000000", "0.00000000"], ["83426.92000000", "0.38050000"], ["83425.35000000", "0.59905000"], ["83425.34000000", "0.00000000"], ["83415.06000000", "0.00000000"], ["83410.73000000", "0.00000000"], ["83410.15000000", "0.01300000"], ["83405.27000000", "0.03765000"], ["83398.67000000", "0.03330000"], ["83393.48000000", "0.00040000"], ["83393.47000000", "0.00040000"], ["83391.63000000", "0.00000000"], ["83375.71000000", "0.02065000"], ["83372.49000000", "0.00000000"], ["83337.63000000", "0.00078000"], ["83337.62000000", "0.00000000"], ["83326.38000000", "0.00000000"], ["83310.84000000", "0.00000000"], ["83299.63000000", "0.00000000"], ["83284.97000000", "0.00400000"], ["83262.24000000", "0.00065000"], ["83262.23000000", "0.00000000"], ["82878.22000000", "0.02397000"], ["82869.79000000", "0.00000000"], ["82201.47000000", "0.00000000"], ["75107.00000000", "0.00219000"], ["66762.62000000", "0.00058000"], ["33000.00000000", "2.93934000"], ["30043.18000000", "0.00120000"]], "a": [["83453.28000000", "3.32634000"], ["83453.29000000", "0.00028000"], ["83453.31000000", "0.00014000"], ["83453.87000000", "0.30719000"], ["83453.88000000", "0.15464000"], ["83455.08000000", "0.00000000"], ["83455.51000000", "0.00000000"], ["83455.59000000", "0.00000000"], ["83455.73000000", "0.00000000"], ["83456.50000000", "0.00014000"], ["83456.51000000", "0.66480000"], ["83456.83000000", "0.00494000"], ["83457.17000000", "0.00000000"], ["83457.28000000", "0.05985000"], ["83458.56000000", "0.00000000"], ["83458.86000000", "0.08992000"], ["83460.04000000", "0.00000000"], ["83463.69000000", "0.00000000"], ["83466.93000000", "0.59958000"], ["83470.09000000", "0.08992000"], ["83475.38000000", "0.01887000"], ["83478.02000000", "0.00000000"], ["83478.71000000", "0.05985000"], ["83478.90000000", "0.00000000"], ["83480.10000000", "0.79631000"], ["83482.05000000", "0.00000000"], ["83482.12000000", "0.00760000"], ["83484.52000000", "0.00753000"], ["83489.00000000", "0.00000000"], ["83491.74000000", "0.00000000"], ["83492.95000000", "0.00000000"], ["83493.74000000", "0.00000000"], ["83508.60000000", "0.04937000"], ["83515.51000000", "0.05000000"], ["83521.96000000", "0.00000000"], ["83522.14000000", "0.00699000"], ["83525.24000000", "0.00000000"], ["83551.05000000", "0.00000000"], ["83604.95000000", "0.00040000"], ["83639.65000000", "0.00009000"], ["83639.75000000", "0.01000000"], ["84705.08000000", "0.00035000"], ["84811.50000000", "0.11807000"], ["110289.00000000", "0.00000000"]], "record_time": 1742377422.917666}
{"e": "depthUpdate", "E": 1742377423014, "s": "BTCUSDT", "U": 64441859564, "u": 64441859681, "b": [["83453.27000000", "1.85311000"], ["83450.40000000", "0.00000000"], ["83448.49000000", "0.00000000"], ["83448.24000000", "0.00282000"], ["83445.84000000", "0.34312000"], ["83440.40000000", "0.00400000"], ["83438.78000000", "0.00000000"], ["83436.38000000", "0.00000000"], ["83433.25000000", "0.00000000"], ["83430.35000000", "0.86297000"], ["83410.15000000", "0.00000000"], ["83405.90000000", "0.02711000"], ["83393.48000000", "0.00000000"], ["83393.47000000", "0.00000000"], ["83362.53000000", "0.10444000"], ["83337.64000000", "0.00078000"], ["83337.63000000", "0.00000000"], ["83277.86000000", "0.00838000"], ["83272.01000000", "0.00000000"], ["83262.25000000", "0.00065000"], ["83262.24000000", "0.00000000"], ["82201.47000000", "0.00100000"], ["80072.20000000", "0.00000000"], ["75107.00000000", "0.00219000"], ["66762.62000000", "0.00058000"], ["60000.00000000", "72.30369000"], ["33000.00000000", "2.93934000"], ["30043.18000000", "0.00160000"]], "a": [["83453.28000000", "3.51589000"], ["83453.87000000", "0.29649000"], ["83455.83000000", "0.00000000"], ["83455.84000000", "0.30931000"], ["83456.50000000", "0.00000000"], ["83456.51000000", "0.00494000"], ["83456.83000000", "0.00000000"], ["83458.06000000", "0.31935000"], ["83458.56000000", "0.00000000"], ["83460.04000000", "0.03385000"], ["83460.26000000", "0.00000000"], ["83460.48000000", "0.00000000"], ["83461.20000000", "0.00000000"], ["83461.45000000", "0.00288000"], ["83463.31000000", "0.18297000"], ["83464.94000000", "0.00000000"], ["83465.16000000", "0.10425000"], ["83475.06000000", "0.02434000"], ["83478.89000000", "0.00000000"], ["83484.67000000", "0.59490000"], ["83486.18000000", "0.04251000"], ["83488.00000000", "0.00400000"], ["83489.00000000", "0.00000000"], ["83498.00000000", "0.00400000"], ["83542.37000000", "0.00000000"], ["83550.32000000", "0.10444000"], ["84705.08000000", "0.00135000"]], "record_time": 1742377423.917224}
{"e": "depthUpdate", "E": 1742377424014, "s": "BTCUSDT", "U": 64441859682, "u": 64441859795, "b": [["83453.27000000", "1.85985000"], ["83450.85000000", "0.00000000"], ["83450.50000000", "0.04790000"], ["83450.43000000", "0.00000000"], ["83449.14000000", "0.00760000"], ["83449.10000000", "0.00000000"], ["83448.72000000", "0.00756000"], ["83446.48000000", "0.00000000"], ["83441.61000000", "0.77098000"], ["83440.50000000", "0.00000000"], ["83438.86000000", "0.00100000"], ["83437.73000000", "1.91822000"], ["83437.72000000", "0.00000000"], ["83435.06000000", "0.00008000"], ["83432.20000000", "0.00000000"], ["83430.83000000", "0.00000000"], ["83428.77000000", "0.02793000"], ["83412.48000000", "0.00000000"], ["83391.20000000", "0.05000000"], ["83372.49000000", "2.56030000"], ["83337.64000000", "0.00000000"], ["83293.25000000", "0.00000000"], ["83286.29000000", "0.00400000"], ["83284.97000000", "0.00000000"], ["83262.25000000", "0.00000000"], ["83128.16000000", "0.00000000"], ["83119.45000000", "0.00158000"], ["82618.73000000", "0.00000000"], ["82201.47000000", "0.00000000"], ["80800.00000000", "9.58132000"], ["80074.27000000", "0.00082000"], ["79200.00000000", "7.51088000"], ["75107.00000000", "0.00239000"], ["66762.62000000", "0.00058000"], ["33000.00000000", "2.93934000"], ["30043.18000000", "0.00240000"]], "a": [["83453.28000000", "3.28529000"], ["83453.43000000", "0.02907000"], ["83453.84000000", "0.00015000"], ["83453.87000000", "0.29635000"], ["83453.88000000", "0.15457000"], ["83458.57000000", "0.35251000"], ["83458.84000000", "0.00000000"], ["83458.86000000", "0.00000000"], ["83460.44000000", "0.00100000"], ["83461.64000000", "0.00000000"], ["83462.74000000", "0.42177000"], ["83462.75000000", "0.79075000"], ["83463.00000000", "0.00000000"], ["83463.31000000", "0.00000000"], ["83478.88000000", "1.38915000"], ["83478.89000000", "0.00000000"], ["83479.65000000", "0.00754000"], ["83482.05000000", "0.00759000"], ["83482.12000000", "0.00000000"], ["83484.52000000", "0.00000000"], ["83493.95000000", "0.35910000"], ["83494.50000000", "0.86231000"], ["83497.80000000", "1.10396000"], ["83545.02000000", "0.07068000"], ["83639.75000000", "0.01000000"], ["84705.08000000", "0.00035000"]], "record_time": 1742377424.91743}
{"e": "depthUpdate", "E": 1742377425014, "s": "BTCUSDT", "U": 64441859796, "u": 64441859889, "b": [["83453.27000000", "3.27463000"], ["83453.26000000", "0.00041000"], ["83453.25000000", "0.00014000"], ["83450.62000000", "0.08478000"], ["83446.48000000", "0.00006000"], ["83443.87000000", "0.00000000"], ["83440.40000000", "0.00000000"], ["83438.64000000", "1.31687000"], ["83437.73000000", "0.59958000"], ["83430.38000000", "0.10618000"], ["83427.24000000", "0.00000000"], ["83411.82000000", "0.03330000"], ["83409.93000000", "0.01300000"], ["83398.67000000", "0.00000000"], ["83337.66000000", "0.00000000"], ["83337.65000000", "0.00000000"], ["83336.33000000", "0.00000000"], ["83333.83000000", "0.99080000"], ["83308.76000000", "0.00400000"], ["83293.62000000", "0.00000000"], ["83286.29000000", "0.00000000"], ["83262.27000000", "0.00000000"], ["83262.26000000", "0.00000000"], ["79200.00000000", "7.51076000"], ["75107.00000000", "0.00219000"], ["66762.62000000", "0.00058000"], ["33000.00000000", "2.93934000"], ["30043.18000000", "0.00360000"], ["20002.00000000", "0.00000000"]], "a": [["83453.28000000", "1.66146000"], ["83453.29000000", "0.00041000"], ["83458.84000000", "0.00006000"], ["83466.93000000", "0.00000000"], ["83475.73000000", "1.62860000"], ["83478.87000000", "1.39009000"], ["83478.88000000", "0.00000000"], ["83488.00000000", "0.00000000"], ["83489.00000000", "0.00500000"], ["83498.00000000", "0.00000000"], ["83499.45000000", "0.86226000"], ["83533.12000000", "0.05986000"], ["83537.30000000", "0.00000000"], ["83541.48000000", "0.03592000"], ["83545.02000000", "0.04671000"], ["83549.84000000", "0.00000000"], ["83550.92000000", "0.02397000"], ["83573.10000000", "0.19287000"], ["83575.89000000", "0.00000000"], ["83638.18000000", "0.99949000"], ["83639.55000000", "0.01000000"], ["83639.65000000", "0.00009000"], ["83639.75000000", "0.00000000"], ["83640.69000000", "0.00000000"], ["83700.00000000", "25.49839000"]], "record_time": 1742377425.917289}
{"e": "depthUpdate", "E": 1742377426014, "s": "BTCUSDT", "U": 64441859890, "u": 64441859955, "b": [["83453.27000000", "2.83153000"], ["83438.64000000", "1.37384000"], ["83427.24000000", "0.05985000"], ["83411.82000000", "0.00000000"], ["83400.87000000", "0.03330000"], ["82201.47000000", "0.00100000"], ["76782.54000000", "0.00014000"], ["75107.00000000", "0.00219000"], ["66762.62000000", "0.00058000"], ["33000.00000000", "2.93934000"], ["30043.18000000", "0.00440000"]], "a": [["83453.28000000", "1.66861000"], ["83460.04000000", "0.00000000"], ["83463.00000000", "0.00500000"], ["83466.93000000", "0.59958000"], ["83478.87000000", "1.38368000"], ["83482.00000000", "0.17400000"], ["83551.14000000", "0.59195000"], ["84705.08000000", "0.00135000"]], "record_time": 1742377426.9172}
{"e": "depthUpdate", "E": 1742377427014, "s": "BTCUSDT", "U": 64441859956, "u": 64441860020, "b": [["83453.27000000", "2.83145000"], ["83450.62000000", "0.07934000"], ["83437.73000000", "0.00000000"], ["83427.24000000", "0.05985000"], ["83394.03000000", "0.00000000"], ["83388.17000000", "0.00298000"], ["83384.97000000", "0.00000000"], ["83378.60000000", "0.00597000"], ["83372.49000000", "2.56030000"], ["83371.74000000", "0.00000000"], ["83365.36000000", "0.00895000"], ["83362.11000000", "0.00000000"], ["83355.72000000", "0.01194000"], ["83353.77000000", "0.00000000"], ["83347.38000000", "0.01493000"], ["82736.36000000", "0.00080000"], ["82736.29000000", "0.00033000"], ["82704.76000000", "0.00060000"], ["82704.69000000", "0.00000000"], ["82201.47000000", "0.00000000"], ["76782.54000000", "0.00000000"], ["75107.94000000", "0.00025000"], ["75107.00000000", "0.00219000"], ["66762.62000000", "0.00058000"], ["33000.00000000", "2.93934000"]], "a": [["83453.28000000", "1.66854000"], ["83455.83000000", "0.00494000"], ["83456.51000000", "0.00000000"], ["83489.00000000", "0.00500000"], ["83519.98000000", "0.00000000"], ["83547.76000000", "0.00298000"], ["83548.56000000", "0.00000000"], ["83556.11000000", "0.00597000"], ["83556.91000000", "0.00000000"], ["83564.46000000", "0.00895000"], ["83565.26000000", "0.00000000"], ["83572.81000000", "0.01194000"], ["83573.61000000", "0.00000000"], ["83581.16000000", "0.01493000"], ["83581.96000000", "0.00000000"], ["83604.95000000", "0.00040000"], ["83639.35000000", "0.00000000"], ["83639.45000000", "0.01000000"], ["83639.55000000", "0.00000000"], ["84500.00000000", "73.27555000"], ["84705.08000000", "0.00035000"]], "record_time": 1742377427.917361}
{"e": "depthUpdate", "E": 1742377428014, "s": "BTCUSDT", "U": 64441860021, "u": 64441860115, "b": [["83453.27000000", "2.81860000"], ["83438.86000000", "0.00000000"], ["83434.24000000", "0.05000000"], ["83427.24000000", "0.00000000"], ["83419.07000000", "0.00000000"], ["83414.85000000", "0.05766000"], ["83412.58000000", "0.04000000"], ["83309.04000000", "0.00400000"], ["83308.76000000", "0.00000000"], ["83302.34000000", "0.00000000"], ["82201.47000000", "0.00100000"], ["75107.94000000", "0.00000000"], ["75107.00000000", "0.00219000"], ["66762.62000000", "0.00058000"], ["33000.00000000", "2.93934000"], ["30043.18000000", "0.00480000"], ["29962.92000000", "0.00189000"], ["29948.38000000", "0.00105000"], ["29947.83000000", "0.00105000"], ["29947.17000000", "0.00000000"], ["29945.24000000", "0.00273000"], ["29932.25000000", "0.00105000"], ["29931.92000000", "0.00000000"], ["29930.87000000", "0.00021000"]], "a": [["83453.28000000", "1.62270000"], ["83460.13000000", "0.03425000"], ["83460.44000000", "0.00000000"], ["83463.00000000", "0.00500000"], ["83466.94000000", "1.13110000"], ["83468.78000000", "0.00000000"], ["83482.56000000", "0.59906000"], ["83485.05000000", "0.86241000"], ["83489.11000000", "0.00000000"], ["83498.31000000", "0.05908000"], ["83499.45000000", "0.00000000"], ["83502.54000000", "0.00000000"], ["83508.57000000", "0.71131000"], ["83518.41000000", "0.24577000"], ["83518.42000000", "0.00000000"], ["83542.26000000", "0.02397000"], ["83550.92000000", "0.00000000"], ["83559.91000000", "0.06157000"], ["83562.72000000", "0.19444000"], ["83564.80000000", "0.14594000"], ["83568.33000000", "0.24236000"], ["83583.82000000", "0.00000000"], ["83594.32000000", "0.00000000"], ["84705.08000000", "0.00135000"]], "record_time": 1742377428.917521}
{"e": "depthUpdate", "E": 1742377429015, "s": "BTCUSDT", "U": 64441860116, "u": 64441860298, "b": [["83453.27000000", "4.10866000"], ["83450.40000000", "0.00000000"], ["83449.10000000", "0.00000000"], ["83448.12000000", "0.33101000"], ["83443.41000000", "0.00000000"], ["83443.15000000", "0.00000000"], ["83440.40000000", "0.00000000"], ["83438.93000000", "0.00100000"], ["83438.69000000", "0.59958000"], ["83434.24000000", "0.00000000"], ["83427.24000000", "0.00000000"], ["83418.75000000", "0.03765000"], ["83414.17000000", "0.03330000"], ["83405.27000000", "0.00000000"], ["83400.87000000", "0.00000000"], ["83373.78000000", "0.01874000"], ["83372.49000000", "2.56030000"], ["83334.53000000", "0.99080000"], ["83333.83000000", "0.00000000"], ["83324.11000000", "0.00400000"], ["83316.71000000", "0.00000000"], ["83309.04000000", "0.00000000"], ["83299.45000000", "0.00000000"], ["82201.47000000", "0.00000000"], ["81459.28000000", "0.00010000"], ["75107.00000000", "0.00219000"], ["66762.62000000", "0.00058000"], ["33000.00000000", "2.93934000"], ["30043.18000000", "0.00580000"]], "a": [["83453.28000000", "1.38702000"], ["83453.31000000", "0.00021000"], ["83453.84000000", "0.00007000"], ["83453.86000000", "0.00021000"], ["83453.87000000", "0.07399000"], ["83453.88000000", "0.00000000"], ["83454.14000000", "0.00007000"], ["83455.83000000", "0.00000000"], ["83455.84000000", "0.00000000"], ["83456.34000000", "0.00000000"], ["83456.36000000", "0.00000000"], ["83456.51000000", "0.00014000"], ["83456.75000000", "0.00000000"], ["83457.27000000", "0.00000000"], ["83458.06000000", "0.00000000"], ["83458.56000000", "0.00014000"], ["83458.97000000", "0.30517000"], ["83459.39000000", "0.00000000"], ["83460.13000000", "0.00000000"], ["83460.40000000", "0.00100000"], ["83461.73000000", "0.31548000"], ["83462.74000000", "0.18455000"], ["83462.75000000", "0.00000000"], ["83463.13000000", "0.00422000"], ["83466.37000000", "0.00000000"], ["83466.44000000", "0.00000000"], ["83466.93000000", "0.00000000"], ["83467.30000000", "0.79071000"], ["83467.77000000", "0.59958000"], ["83469.20000000", "0.00000000"], ["83470.09000000", "0.00000000"], ["83474.18000000", "0.00000000"], ["83482.56000000", "0.00000000"], ["83485.05000000", "0.00000000"], ["83486.04000000", "0.59904000"], ["83488.00000000", "0.00000000"], ["83488.75000000", "0.86237000"], ["83489.00000000", "0.00000000"], ["83489.12000000", "0.46283000"], ["83489.13000000", "0.00000000"], ["83498.00000000", "0.00000000"], ["83499.90000000", "0.86225000"], ["83502.65000000", "0.00000000"], ["83515.51000000", "0.00000000"], ["83521.77000000", "0.05000000"], ["83522.19000000", "0.00000000"], ["83522.24000000", "0.35910000"], ["83533.12000000", "0.00000000"], ["83537.30000000", "0.05986000"], ["83541.48000000", "0.00000000"], ["83549.84000000", "0.03592000"], ["83638.18000000", "0.00000000"], ["83638.98000000", "0.99005000"], ["83639.45000000", "0.01000000"], ["84287.80000000", "0.00239000"], ["84705.08000000", "0.00035000"], ["84811.50000000", "0.00000000"], ["84832.65000000", "0.11805000"]], "record_time": 1742377429.918211}
{"e": "depthUpdate", "E": 1742377430014, "s": "BTCUSDT", "U": 64441860299, "u": 64441860415, "b": [["83453.27000000", "4.10142000"], ["83450.50000000", "0.04790000"], ["83449.10000000", "0.00000000"], ["83448.17000000", "0.00058000"], ["83448.13000000", "0.00058000"], ["83446.18000000", "0.00059000"], ["83444.94000000", "0.00058000"], ["83440.50000000", "0.00000000"], ["83439.94000000", "0.05000000"], ["83427.24000000", "0.05985000"], ["83414.17000000", "0.00000000"], ["83404.80000000", "0.03330000"], ["83373.78000000", "0.00000000"], ["83331.53000000", "0.00400000"], ["83324.11000000", "0.00000000"], ["83261.24000000", "0.01874000"], ["82201.47000000", "0.00100000"], ["80000.00000000", "158.91290000"], ["79200.00000000", "7.51076000"], ["75107.00000000", "0.00219000"], ["66762.62000000", "0.00058000"], ["33000.00000000", "2.93934000"], ["30043.18000000", "0.00680000"], ["20002.00000000", "0.00000000"]], "a": [["83453.28000000", "0.65106000"], ["83453.87000000", "0.11650000"], ["83455.06000000", "0.00014000"], ["83455.07000000", "0.17241000"], ["83455.34000000", "0.00000000"], ["83455.35000000", "0.00000000"], ["83456.13000000", "0.00494000"], ["83456.14000000", "0.00008000"], ["83456.50000000", "0.00000000"], ["83456.51000000", "0.00000000"], ["83457.28000000", "0.05985000"], ["83458.56000000", "0.00014000"], ["83458.57000000", "0.57646000"], ["83459.35000000", "0.00008000"], ["83460.43000000", "0.35910000"], ["83462.74000000", "0.39846000"], ["83463.00000000", "0.00000000"], ["83465.45000000", "0.79073000"], ["83467.30000000", "0.00000000"], ["83472.37000000", "0.35910000"], ["83475.38000000", "0.00000000"], ["83477.83000000", "0.01887000"], ["83478.71000000", "0.05985000"], ["83486.04000000", "0.00000000"], ["83489.11000000", "0.59902000"], ["83508.56000000", "0.63687000"], ["83509.91000000", "0.00000000"], ["83517.27000000", "0.05000000"], ["83521.77000000", "0.00000000"], ["83537.30000000", "0.00000000"], ["83551.14000000", "0.00000000"], ["83573.10000000", "0.00000000"], ["83574.49000000", "0.19287000"], ["84287.80000000", "0.00000000"], ["84705.08000000", "0.00135000"], ["84832.65000000", "0.00000000"], ["139882.00000000", "0.00000000"]], "record_time": 1742377430.917289}
{"e": "depthUpdate", "E": 1742377431014, "s": "BTCUSDT", "U": 64441860416, "u": 64441860504, "b": [["83453.27000000", "4.06475000"], ["83450.85000000", "0.00753000"], ["83450.43000000", "0.00753000"], ["83449.14000000", "0.00000000"], ["83448.72000000", "0.00000000"], ["83438.70000000", "0.08463000"], ["83412.58000000", "0.00000000"], ["83410.78000000", "0.04000000"], ["83409.93000000", "0.00000000"], ["83408.23000000", "0.01300000"], ["83391.20000000", "0.00000000"], ["82201.47000000", "0.00000000"], ["75107.00000000", "0.00219000"], ["66762.62000000", "0.00058000"], ["42000.00000000", "6.98916000"], ["33000.00000000", "2.93934000"]], "a": [["83453.28000000", "0.65103000"], ["83455.75000000", "0.00502000"], ["83455.83000000", "0.00000000"], ["83456.13000000", "0.00000000"], ["83456.14000000", "0.00000000"], ["83456.51000000", "0.00000000"], ["83456.66000000", "0.00000000"], ["83456.92000000", "0.00000000"], ["83457.28000000", "0.05985000"], ["83457.53000000", "0.00000000"], ["83462.74000000", "0.18455000"], ["83464.50000000", "0.04817000"], ["83465.16000000", "0.10400000"], ["83465.45000000", "0.00000000"], ["83467.70000000", "0.79070000"], ["83478.71000000", "0.05985000"], ["83479.65000000", "0.00000000"], ["83481.87000000", "0.00759000"], ["83482.05000000", "0.00000000"], ["83484.28000000", "0.00758000"], ["83488.74000000", "0.90275000"], ["83489.00000000", "0.00500000"], ["83489.12000000", "0.00000000"], ["83517.27000000", "0.00000000"], ["83518.47000000", "0.05000000"], ["83537.30000000", "0.05986000"], ["83639.45000000", "0.00000000"], ["83639.55000000", "0.01000000"], ["84705.08000000", "0.00035000"]], "record_time": 1742377431.917256}
{"e": "depthUpdate", "E": 1742377432014, "s": "BTCUSDT", "U": 64441860505, "u": 64441860629, "b": [["83453.27000000", "4.12967000"], ["83451.79000000", "0.00756000"], ["83451.66000000", "0.00007000"], ["83450.85000000", "0.00000000"], ["83450.62000000", "0.07878000"], ["83446.48000000", "0.00000000"], ["83444.93000000", "0.64137000"], ["83442.55000000", "0.86285000"], ["83427.24000000", "0.00000000"], ["83426.92000000", "0.23380000"], ["83426.91000000", "0.00000000"], ["83389.60000000", "0.05000000"], ["83331.53000000", "0.00000000"], ["83325.68000000", "0.24261000"], ["83278.00000000", "0.00838000"], ["83277.86000000", "0.00000000"], ["82335.16000000", "0.00007000"], ["82201.47000000", "0.00100000"], ["80000.00000000", "158.91663000"], ["76782.54000000", "0.00000000"], ["75191.54000000", "0.00016000"], ["75107.94000000", "0.00016000"], ["75107.00000000", "0.00219000"], ["66762.62000000", "0.00058000"], ["33000.00000000", "2.93934000"]], "a": [["83453.28000000", "0.81184000"], ["83453.31000000", "0.00014000"], ["83453.87000000", "0.07399000"], ["83455.06000000", "0.00000000"], ["83455.07000000", "0.00000000"], ["83455.13000000", "0.00494000"], ["83455.50000000", "0.00008000"], ["83455.75000000", "0.00000000"], ["83455.79000000", "0.00007000"], ["83456.12000000", "0.00000000"], ["83456.51000000", "0.00014000"], ["83457.28000000", "0.05985000"], ["83457.67000000", "0.00000000"], ["83458.84000000", "0.00000000"], ["83462.74000000", "0.39997000"], ["83463.00000000", "0.00500000"], ["83465.39000000", "0.79073000"], ["83465.76000000", "0.00000000"], ["83467.70000000", "0.00000000"], ["83468.17000000", "0.00000000"], ["83478.71000000", "0.05985000"], ["83500.00000000", "1.10025000"], ["83505.06000000", "0.26383000"], ["83506.06000000", "0.58200000"], ["83514.37000000", "0.17862000"], ["83515.72000000", "0.00000000"], ["83553.85000000", "0.59195000"], ["83639.55000000", "0.00000000"], ["83639.85000000", "0.00000000"], ["83639.95000000", "0.01000000"], ["84351.16000000", "0.00000000"], ["84705.08000000", "0.00135000"], ["84832.65000000", "0.11806000"], ["119982.00000000", "0.00000000"]], "record_time": 1742377432.917659}
{"e": "depthUpdate", "E": 1742377433014, "s": "BTCUSDT", "U": 64441860630, "u": 64441860708, "b": [["83453.27000000", "4.12451000"], ["83449.10000000", "0.00500000"], ["83446.48000000", "0.00006000"], ["83444.84000000", "0.00058000"], ["83427.24000000", "0.05985000"], ["83338.04000000", "0.01874000"], ["83335.53000000", "0.99080000"], ["83334.53000000", "0.00000000"], ["83330.71000000", "0.00400000"], ["83325.68000000", "0.23861000"], ["83261.24000000", "0.00000000"], ["82343.45000000", "0.40000000"], ["82201.47000000", "0.00000000"], ["81000.00000000", "55.96330000"], ["75191.54000000", "0.00000000"], ["75107.94000000", "0.00064000"], ["75107.00000000", "0.00219000"], ["66762.62000000", "0.00058000"], ["60000.00000000", "72.30369000"], ["33000.00000000", "2.93934000"]], "a": [["83453.28000000", "0.79262000"], ["83454.68000000", "0.00000000"], ["83454.83000000", "0.00000000"], ["83454.86000000", "0.00000000"], ["83454.94000000", "0.00000000"], ["83455.50000000", "0.00000000"], ["83455.51000000", "0.00000000"], ["83455.59000000", "0.00000000"], ["83457.28000000", "0.05985000"], ["83458.84000000", "0.00006000"], ["83468.09000000", "0.00000000"], ["83478.71000000", "0.05985000"], ["83489.00000000", "0.00000000"], ["83496.11000000", "0.00000000"], ["83604.95000000", "0.00040000"], ["83638.98000000", "0.00000000"], ["83639.99000000", "0.99771000"], ["84359.52000000", "0.60000000"], ["84705.08000000", "0.00035000"], ["84832.65000000", "0.00000000"]], "record_time": 1742377433.91798}
{"e": "depthUpdate", "E": 1742377434014, "s": "BTCUSDT", "U": 64441860709, "u": 64441860803, "b": [["83453.27000000", "4.12399000"], ["83449.31000000", "0.00058000"], ["83449.10000000", "0.01000000"], ["83447.81000000", "0.30402000"], ["83442.83000000", "0.00000000"], ["83439.38000000", "0.01200000"], ["83430.08000000", "0.00503000"], ["83430.07000000", "0.00000000"], ["83339.04000000", "0.00000000"], ["83338.04000000", "0.00000000"], ["83337.60000000", "0.00078000"], ["83331.34000000", "0.00400000"], ["83330.71000000", "0.00000000"], ["83316.89000000", "0.00000000"], ["83313.74000000", "0.00119000"], ["83278.01000000", "0.00300000"], ["83277.87000000", "0.00000000"], ["83262.21000000", "0.00065000"], ["82201.47000000", "0.00100000"], ["75107.00000000", "0.00219000"], ["66762.62000000", "0.00058000"], ["33000.00000000", "2.93934000"], ["30043.18000000", "0.00720000"]], "a": [["83453.28000000", "0.16765000"], ["83454.69000000", "0.00000000"], ["83455.13000000", "0.00000000"], ["83455.14000000", "0.00000000"], ["83455.78000000", "0.00494000"], ["83456.32000000", "0.00000000"], ["83457.01000000", "0.00000000"], ["83457.28000000", "0.00000000"], ["83457.39000000", "0.00008000"], ["83462.74000000", "0.18455000"], ["83463.00000000", "0.00000000"], ["83465.39000000", "0.00000000"], ["83467.49000000", "0.79071000"], ["83478.71000000", "0.11970000"], ["83505.82000000", "0.00299000"], ["83506.90000000", "0.00000000"], ["83531.26000000", "0.00267000"], ["83533.17000000", "0.00025000"], ["83537.29000000", "0.00000000"], ["83541.70000000", "0.00000000"], ["83542.26000000", "0.00000000"], ["83549.87000000", "0.03560000"], ["83550.80000000", "0.02397000"], ["83553.85000000", "0.00000000"], ["83589.98000000", "0.00119000"], ["83595.98000000", "0.00000000"], ["83606.79000000", "0.00021000"], ["83607.16000000", "0.00000000"], ["83624.30000000", "0.00119000"], ["83630.47000000", "0.00000000"], ["83639.95000000", "0.01000000"], ["84287.80000000", "0.00000000"], ["84705.08000000", "0.00135000"], ["84832.65000000", "0.11806000"]], "record_time": 1742377434.917852}
{"e": "depthUpdate", "E": 1742377435015, "s": "BTCUSDT", "U": 64441860804, "u": 64441860870, "b": [["83453.27000000", "4.57676000"], ["83450.40000000", "0.00000000"], ["83449.10000000", "0.00500000"], ["83447.86000000", "0.00058000"], ["83446.25000000", "0.00059000"], ["83444.91000000", "0.00058000"], ["83444.84000000", "0.00116000"], ["83443.32000000", "0.00058000"], ["83440.40000000", "0.00000000"], ["83337.61000000", "0.00078000"], ["83337.60000000", "0.00000000"], ["83336.61000000", "0.00400000"], ["83331.34000000", "0.00000000"], ["83262.22000000", "0.00065000"], ["83262.21000000", "0.00000000"], ["82201.47000000", "0.00000000"], ["75107.00000000", "0.00239000"], ["66762.62000000", "0.00058000"], ["33000.00000000", "2.93934000"], ["20002.00000000", "0.00000000"]], "a": [["83453.28000000", "0.16681000"], ["83453.87000000", "0.02419000"], ["83456.51000000", "0.00000000"], ["83456.52000000", "0.00000000"], ["83456.80000000", "0.00008000"], ["83456.83000000", "0.00014000"], ["83457.39000000", "0.00000000"], ["83457.49000000", "0.00014000"], ["83458.23000000", "0.00012000"], ["83459.00000000", "0.00000000"], ["83459.67000000", "0.10618000"], ["83475.06000000", "0.00000000"], ["83483.74000000", "0.00000000"], ["83485.60000000", "0.39678000"], ["83488.00000000", "0.00000000"], ["83489.00000000", "0.00000000"], ["83498.00000000", "0.00000000"], ["83571.97000000", "0.34631000"], ["83574.93000000", "0.17198000"], ["83590.00000000", "0.10034000"], ["83600.00000000", "3.87515000"], ["84705.08000000", "0.00035000"]], "record_time": 1742377435.918312}
{"e": "depthUpdate", "E": 1742377436014, "s": "BTCUSDT", "U": 64441860871, "u": 64441861060, "b": [["83453.27000000", "1.84964000"], ["83449.10000000", "0.00000000"], ["83447.81000000", "0.00000000"], ["83444.39000000", "0.00095000"], ["83444.26000000", "0.04091000"], ["83444.15000000", "0.00000000"], ["83443.57000000", "0.30402000"], ["83438.71000000", "0.00000000"], ["83438.69000000", "0.00000000"], ["83427.24000000", "0.00000000"], ["83393.35000000", "0.00040000"], ["83393.34000000", "0.00040000"], ["83372.49000000", "0.00000000"], ["83337.62000000", "0.00078000"], ["83337.61000000", "0.00000000"], ["83336.61000000", "0.00000000"], ["83330.01000000", "0.00000000"], ["83319.86000000", "0.00000000"], ["83301.77000000", "0.00400000"], ["83282.89000000", "0.00281000"], ["83282.88000000", "0.00838000"], ["83278.01000000", "0.00000000"], ["83278.00000000", "0.00000000"], ["83262.23000000", "0.00065000"], ["83262.22000000", "0.00000000"], ["82800.00000000", "0.48290000"], ["82736.45000000", "0.00060000"], ["82736.36000000", "0.00020000"], ["82704.85000000", "0.00060000"], ["82704.76000000", "0.00000000"], ["82201.47000000", "0.00100000"], ["79200.00000000", "7.51076000"], ["75107.00000000", "0.00219000"], ["66762.62000000", "0.00058000"], ["33000.00000000", "2.93934000"], ["30043.18000000", "0.00760000"]], "a": [["83453.28000000", "1.49331000"], ["83453.86000000", "0.00029000"], ["83453.87000000", "0.25615000"], ["83454.48000000", "0.00000000"], ["83455.14000000", "0.00000000"], ["83455.15000000", "0.00000000"], ["83455.73000000", "0.00014000"], ["83455.74000000", "0.85480000"], ["83455.75000000", "0.00494000"], ["83455.76000000", "0.00000000"], ["83455.77000000", "0.00000000"], ["83455.78000000", "0.00000000"], ["83455.99000000", "0.00000000"], ["83456.19000000", "0.00000000"], ["83456.59000000", "0.00000000"], ["83456.80000000", "0.00000000"], ["83456.83000000", "0.00000000"], ["83457.28000000", "0.00000000"], ["83457.49000000", "0.00000000"], ["83458.55000000", "0.00000000"], ["83458.56000000", "0.17956000"], ["83462.74000000", "0.39996000"], ["83463.00000000", "0.00500000"], ["83463.13000000", "0.00000000"], ["83464.50000000", "0.04790000"], ["83465.16000000", "0.10428000"], ["83465.57000000", "0.79072000"], ["83467.49000000", "0.00000000"], ["83478.71000000", "0.11970000"], ["83484.67000000", "0.91105000"], ["83485.03000000", "0.86241000"], ["83499.90000000", "0.00000000"], ["83513.98000000", "0.00008000"], ["83533.17000000", "0.00025000"], ["83537.30000000", "0.00000000"], ["83541.48000000", "0.00000000"], ["83553.86000000", "0.59195000"], ["83606.79000000", "0.00021000"], ["83639.25000000", "0.01000000"], ["83639.45000000", "0.00000000"], ["83639.95000000", "0.00000000"], ["84705.08000000", "0.00135000"], ["84832.65000000", "0.00000000"]], "record_time": 1742377436.918272}
{"e": "depthUpdate", "E": 1742377437014, "s": "BTCUSDT", "U": 64441861061, "u": 64441861198, "b": [["83453.27000000", "1.79939000"], ["83450.50000000", "0.04790000"], ["83449.31000000", "0.00000000"], ["83448.13000000", "0.00000000"], ["83448.12000000", "0.00000000"], ["83446.48000000", "0.00006000"], ["83444.39000000", "0.00000000"], ["83444.26000000", "0.04000000"], ["83444.23000000", "0.00094000"], ["83444.13000000", "0.00091000"], ["83443.74000000", "0.00416000"], ["83440.50000000", "0.00300000"], ["83439.94000000", "0.00000000"], ["83432.35000000", "0.05000000"], ["83427.24000000", "0.00000000"], ["83418.75000000", "0.00000000"], ["83417.66000000", "0.00000000"], ["83407.93000000", "0.03765000"], ["83337.71000000", "0.00078000"], ["83337.70000000", "0.99080000"], ["83337.62000000", "0.00000000"], ["83335.53000000", "0.00000000"], ["83301.77000000", "0.00000000"], ["83295.93000000", "0.00000000"], ["83275.47000000", "0.00400000"], ["83262.24000000", "0.00065000"], ["83262.23000000", "0.00000000"], ["82201.47000000", "0.00000000"], ["81000.00000000", "55.95923000"], ["76782.54000000", "0.00014000"], ["75107.00000000", "0.00219000"], ["66762.62000000", "0.00058000"], ["33000.00000000", "2.93934000"], ["30043.18000000", "0.00780000"]], "a": [["83453.28000000", "4.79620000"], ["83453.43000000", "0.05758000"], ["83454.58000000", "0.00494000"], ["83454.59000000", "0.08992000"], ["83454.96000000", "0.00007000"], ["83455.69000000", "0.00014000"], ["83455.70000000", "0.85480000"], ["83455.71000000", "0.00000000"], ["83455.72000000", "0.00000000"], ["83455.73000000", "0.00000000"], ["83455.74000000", "0.00000000"], ["83455.75000000", "0.00000000"], ["83455.79000000", "0.00000000"], ["83457.28000000", "0.05985000"], ["83458.84000000", "0.00000000"], ["83461.84000000", "0.08800000"], ["83462.75000000", "0.08992000"], ["83463.00000000", "0.00000000"], ["83463.61000000", "0.79074000"], ["83465.57000000", "0.00000000"], ["83467.88000000", "0.05985000"], ["83473.29000000", "0.08992000"], ["83475.09000000", "0.01887000"], ["83477.83000000", "0.00000000"], ["83478.31000000", "0.05985000"], ["83478.71000000", "0.05985000"], ["83489.00000000", "0.00500000"], ["83493.95000000", "0.00000000"], ["83542.18000000", "0.00000000"], ["83550.80000000", "0.00000000"], ["83639.99000000", "0.00000000"], ["83642.21000000", "0.99649000"], ["84705.08000000", "0.00035000"], ["84811.50000000", "0.11806000"]], "record_time": 1742377437.919188}
{"e": "depthUpdate", "E": 1742377438014, "s": "BTCUSDT", "U": 64441861199, "u": 64441861327, "b": [["83453.27000000", "1.79846000"], ["83448.17000000", "0.00000000"], ["83448.00000000", "0.00235000"], ["83447.86000000", "0.00000000"], ["83446.25000000", "0.00000000"], ["83446.18000000", "0.00000000"], ["83444.94000000", "0.00000000"], ["83444.93000000", "0.00000000"], ["83444.92000000", "0.45000000"], ["83444.91000000", "0.00000000"], ["83442.55000000", "0.00000000"], ["83440.50000000", "0.00000000"], ["83438.70000000", "0.00000000"], ["83429.25000000", "0.86298000"], ["83428.78000000", "0.04032000"], ["83426.92000000", "0.00000000"], ["83425.35000000", "0.00000000"], ["83422.23000000", "0.59907000"], ["83407.93000000", "0.00000000"], ["83399.75000000", "0.03765000"], ["83393.35000000", "0.00000000"], ["83393.34000000", "0.00000000"], ["83335.25000000", "0.45000000"], ["83276.99000000", "0.00400000"], ["83275.47000000", "0.00000000"], ["83269.92000000", "0.00000000"], ["82736.46000000", "0.00060000"], ["82736.45000000", "0.00000000"], ["82201.47000000", "0.00100000"], ["76782.54000000", "0.00000000"], ["75107.00000000", "0.00219000"], ["66762.62000000", "0.00058000"], ["33000.00000000", "2.93934000"]], "a": [["83453.28000000", "5.45868000"], ["83453.84000000", "0.00007000"], ["83453.85000000", "0.00021000"], ["83453.86000000", "0.06015000"], ["83453.87000000", "0.00000000"], ["83454.58000000", "0.00000000"], ["83454.59000000", "0.00000000"], ["83454.95000000", "0.00494000"], ["83455.69000000", "0.00000000"], ["83455.70000000", "0.00000000"], ["83457.27000000", "0.00014000"], ["83457.45000000", "0.05992000"], ["83458.55000000", "0.00014000"], ["83458.56000000", "0.17963000"], ["83458.84000000", "0.00006000"], ["83458.97000000", "0.00000000"], ["83460.91000000", "0.02354000"], ["83461.84000000", "0.91181000"], ["83462.74000000", "0.18455000"], ["83463.00000000", "0.00500000"], ["83463.61000000", "0.00000000"], ["83472.37000000", "0.00000000"], ["83472.40000000", "0.01887000"], ["83475.09000000", "0.00000000"], ["83478.71000000", "0.00000000"], ["83479.23000000", "0.02432000"], ["83501.93000000", "0.00015000"], ["83513.52000000", "0.05000000"], ["83518.47000000", "0.00000000"], ["83521.50000000", "0.35910000"], ["83522.24000000", "0.00000000"], ["83541.48000000", "0.05986000"], ["83542.18000000", "0.02397000"], ["83604.95000000", "0.00040000"], ["84401.93000000", "0.00000000"], ["84705.08000000", "0.00135000"]], "record_time": 1742377439.777314}
