{"e": "depthUpdate", "E": 1742554939014, "s": "BTCUSDT", "U": 64606997619, "u": 64606997866, "b": [["84131.96000000", "4.99138000"], ["84131.95000000", "0.00033000"], ["84130.49000000", "0.00014000"], ["84130.30000000", "0.00021000"], ["84130.29000000", "0.00446000"], ["84130.23000000", "0.44924000"], ["84129.47000000", "0.45007000"], ["84129.13000000", "0.00011000"], ["84126.75000000", "0.00000000"], ["84126.00000000", "0.02266000"], ["84122.29000000", "0.00000000"], ["84122.23000000", "0.00000000"], ["84121.95000000", "0.00000000"], ["84121.80000000", "0.02410000"], ["84120.62000000", "0.00000000"], ["84119.78000000", "0.49163000"], ["84119.35000000", "0.01076000"], ["84117.59000000", "0.00000000"], ["84115.81000000", "0.59407000"], ["84112.81000000", "0.89111000"], ["84106.64000000", "0.05940000"], ["84100.80000000", "0.00006000"], ["84098.90000000", "0.93721000"], ["84097.51000000", "0.00016000"], ["84094.23000000", "0.59457000"], ["84091.89000000", "0.00000000"], ["84085.05000000", "0.00000000"], ["84079.07000000", "0.59407000"], ["84078.56000000", "0.00000000"], ["84073.90000000", "0.45058000"], ["84070.01000000", "0.00142000"], ["84047.80000000", "0.00000000"], ["84039.09000000", "0.80400000"], ["84027.16000000", "0.00000000"], ["83994.04000000", "0.00000000"], ["83989.00000000", "0.05497000"], ["83988.71000000", "0.00000000"], ["83977.81000000", "0.00000000"], ["83959.80000000", "0.01000000"], ["83884.13000000", "0.00000000"], ["83186.05000000", "0.06004000"], ["82869.98000000", "0.00000000"], ["79900.00000000", "5.57490000"], ["75718.00000000", "0.00000000"], ["67305.57000000", "0.00058000"], ["60000.00000000", "73.17018000"], ["33000.00000000", "2.93827000"]], "a": [["84131.97000000", "1.93546000"], ["84131.98000000", "0.00045000"], ["84132.00000000", "0.00000000"], ["84132.01000000", "0.00000000"], ["84132.07000000", "0.00008000"], ["84132.31000000", "0.00014000"], ["84132.32000000", "0.08966000"], ["84133.64000000", "0.00000000"], ["84134.61000000", "0.01641000"], ["84136.88000000", "0.00000000"], ["84137.36000000", "0.02375000"], ["84139.68000000", "0.00000000"], ["84139.70000000", "0.00000000"], ["84140.14000000", "0.02415000"], ["84140.39000000", "0.45000000"], ["84142.36000000", "0.00418000"], ["84144.63000000", "0.00000000"], ["84146.59000000", "0.00000000"], ["84146.98000000", "0.00000000"], ["84147.00000000", "0.02408000"], ["84147.06000000", "0.03567000"], ["84147.07000000", "0.00029000"], ["84160.97000000", "0.00572000"], ["84161.85000000", "0.00760000"], ["84163.15000000", "0.59456000"], ["84164.03000000", "0.00000000"], ["84175.60000000", "0.21905000"], ["84178.18000000", "0.25105000"], ["84211.83000000", "0.50174000"], ["84242.19000000", "0.00000000"], ["84262.74000000", "0.05097000"], ["84286.43000000", "0.00000000"], ["84325.70000000", "0.00000000"], ["84369.53000000", "0.00000000"], ["85393.95000000", "0.00100000"]], "record_time": 1742554939.054264, "EXCHANGE": "BINANCE"}
{"e": "depthUpdate", "E": 1742554940014, "s": "BTCUSDT", "U": 64606997867, "u": 64606998047, "b": [["84131.96000000", "3.81061000"], ["84131.95000000", "0.00033000"], ["84131.81000000", "0.00021000"], ["84131.80000000", "0.01940000"], ["84130.30000000", "0.00007000"], ["84130.29000000", "0.00000000"], ["84130.24000000", "0.00014000"], ["84130.23000000", "0.23920000"], ["84130.00000000", "0.02267000"], ["84129.47000000", "0.00000000"], ["84129.20000000", "0.00000000"], ["84129.10000000", "0.00000000"], ["84128.43000000", "0.02401000"], ["84125.84000000", "0.00008000"], ["84124.40000000", "0.00000000"], ["84122.25000000", "0.00089000"], ["84122.22000000", "0.00094000"], ["84119.35000000", "0.01032000"], ["84119.10000000", "0.00000000"], ["84119.00000000", "0.00000000"], ["84117.59000000", "0.00000000"], ["84115.13000000", "0.00000000"], ["84108.69000000", "0.00016000"], ["84106.72000000", "0.06240000"], ["84106.64000000", "0.05940000"], ["84095.80000000", "0.00000000"], ["84089.34000000", "0.05000000"], ["84085.05000000", "0.00000000"], ["84079.07000000", "0.00000000"], ["84078.15000000", "0.59407000"], ["84047.58000000", "0.00298000"], ["84047.18000000", "0.00000000"], ["84039.17000000", "0.00597000"], ["84038.77000000", "0.00000000"], ["84030.76000000", "0.00904000"], ["84030.36000000", "0.00000000"], ["84022.35000000", "0.01194000"], ["84021.95000000", "0.00000000"], ["84013.95000000", "0.01493000"], ["84013.55000000", "0.00000000"], ["83989.00000000", "0.05097000"], ["83980.84000000", "0.00000000"], ["83977.34000000", "0.99313000"], ["83974.80000000", "0.00006000"], ["83964.23000000", "0.00400000"], ["83959.80000000", "0.01000000"], ["83959.70000000", "0.00000000"], ["83955.36000000", "0.00000000"], ["82869.98000000", "0.00100000"], ["75718.00000000", "0.00000000"], ["67305.57000000", "0.00058000"], ["33000.00000000", "2.93827000"]], "a": [["84131.97000000", "3.31329000"], ["84131.98000000", "0.00045000"], ["84132.32000000", "0.17375000"], ["84133.64000000", "0.01184000"], ["84134.40000000", "0.00000000"], ["84134.61000000", "0.00000000"], ["84136.20000000", "0.00500000"], ["84141.30000000", "0.00000000"], ["84142.36000000", "0.00000000"], ["84146.59000000", "0.71284000"], ["84147.06000000", "0.00000000"], ["84147.07000000", "0.00029000"], ["84151.40000000", "0.00000000"], ["84157.71000000", "0.59458000"], ["84161.80000000", "0.12833000"], ["84163.15000000", "0.00000000"], ["84163.85000000", "0.05000000"], ["84168.81000000", "0.00000000"], ["84195.90000000", "0.03609000"], ["84197.15000000", "0.00000000"], ["84205.63000000", "0.00000000"], ["84215.95000000", "0.00595000"], ["84217.97000000", "0.00000000"], ["84221.43000000", "0.00000000"], ["84224.36000000", "0.00597000"], ["84232.45000000", "0.00000000"], ["84232.78000000", "0.00895000"], ["84241.20000000", "0.01194000"], ["84244.41000000", "0.04635000"], ["84249.62000000", "0.01493000"], ["84267.64000000", "0.00660000"], ["84295.00000000", "0.00000000"], ["84303.60000000", "0.00118000"], ["84303.61000000", "0.99952000"], ["84315.57000000", "0.00000000"], ["84973.27000000", "0.00000000"], ["85393.95000000", "0.00000000"]], "record_time": 1742554940.036728, "EXCHANGE": "BINANCE"}
{"e": "depthUpdate", "E": 1742554941014, "s": "BTCUSDT", "U": 64606998048, "u": 64606998221, "b": [["84131.96000000", "3.02890000"], ["84131.95000000", "0.00033000"], ["84131.89000000", "0.00021000"], ["84131.88000000", "0.12665000"], ["84131.87000000", "0.00007000"], ["84131.81000000", "0.00007000"], ["84131.80000000", "0.00007000"], ["84131.12000000", "0.00006000"], ["84130.49000000", "0.00000000"], ["84130.30000000", "0.00000000"], ["84130.24000000", "0.00014000"], ["84130.00000000", "0.02267000"], ["84129.13000000", "0.00000000"], ["84128.43000000", "0.02401000"], ["84126.84000000", "0.00000000"], ["84126.63000000", "0.00011000"], ["84126.26000000", "0.04817000"], ["84125.92000000", "0.00000000"], ["84123.44000000", "0.02434000"], ["84123.43000000", "0.00000000"], ["84121.80000000", "0.00006000"], ["84120.77000000", "0.00000000"], ["84120.51000000", "0.00000000"], ["84089.34000000", "0.00000000"], ["84084.80000000", "0.05000000"], ["83970.09000000", "0.00000000"], ["83964.23000000", "0.00000000"], ["83962.83000000", "0.00000000"], ["83957.01000000", "0.00400000"], ["83186.05000000", "0.00000000"], ["82869.98000000", "0.00000000"], ["75718.00000000", "0.00000000"], ["67305.57000000", "0.00058000"], ["33000.00000000", "2.93827000"], ["20002.00000000", "0.00000000"], ["20001.00000000", "0.02099000"]], "a": [["84131.97000000", "3.42174000"], ["84131.98000000", "0.00059000"], ["84131.99000000", "0.00000000"], ["84132.41000000", "0.00000000"], ["84133.64000000", "0.01188000"], ["84134.40000000", "0.00000000"], ["84134.63000000", "0.00000000"], ["84135.29000000", "0.01011000"], ["84136.00000000", "0.02260000"], ["84137.28000000", "0.04817000"], ["84137.83000000", "0.00000000"], ["84144.97000000", "0.00000000"], ["84147.07000000", "0.03596000"], ["84157.71000000", "0.00000000"], ["84160.28000000", "0.59457000"], ["84189.25000000", "0.02378000"], ["84195.60000000", "0.00000000"], ["84221.30000000", "0.62970000"], ["84223.68000000", "1.10924000"], ["84349.26000000", "0.00000000"], ["85393.95000000", "0.00100000"]], "record_time": 1742554941.036591, "EXCHANGE": "BINANCE"}
{"e": "depthUpdate", "E": 1742554942014, "s": "BTCUSDT", "U": 64606998222, "u": 64606998327, "b": [["84131.96000000", "2.71068000"], ["84131.95000000", "0.00046000"], ["84131.80000000", "0.00007000"], ["84131.66000000", "0.00807000"], ["84131.13000000", "0.00000000"], ["84124.40000000", "0.00500000"], ["84120.51000000", "0.02378000"], ["84117.60000000", "0.02370000"], ["84095.80000000", "0.00500000"], ["84094.06000000", "0.00000000"], ["84090.21000000", "0.00000000"], ["84089.70000000", "0.05009000"], ["84088.50000000", "0.00000000"], ["84084.80000000", "0.00000000"], ["84082.51000000", "0.00000000"], ["84078.66000000", "0.00935000"], ["84077.81000000", "0.01870000"], ["83966.03000000", "0.00000000"], ["83957.01000000", "0.00000000"], ["83953.83000000", "0.00400000"], ["82869.98000000", "0.00100000"], ["75718.00000000", "0.00000000"], ["67305.57000000", "0.00058000"], ["33000.00000000", "2.93827000"], ["30287.51000000", "0.00020000"]], "a": [["84131.97000000", "3.45604000"], ["84132.08000000", "0.00014000"], ["84132.09000000", "0.12440000"], ["84132.20000000", "0.00000000"], ["84132.31000000", "0.00000000"], ["84132.32000000", "0.00132000"], ["84136.20000000", "0.00000000"], ["84142.34000000", "0.03704000"], ["84151.75000000", "0.00000000"], ["84189.25000000", "0.00000000"], ["84202.81000000", "0.00000000"], ["84205.63000000", "0.00041000"], ["84278.60000000", "0.00000000"], ["84281.94000000", "0.00035000"], ["85393.95000000", "0.00000000"], ["92000.00000000", "75.34985000"]], "record_time": 1742554942.057851, "EXCHANGE": "BINANCE"}
{"e": "depthUpdate", "E": 1742554943014, "s": "BTCUSDT", "U": 64606998328, "u": 64606998435, "b": [["84131.96000000", "2.34340000"], ["84131.88000000", "0.12665000"], ["84131.66000000", "0.01575000"], ["84130.23000000", "0.19119000"], ["84130.00000000", "0.02260000"], ["84089.88000000", "0.43330000"], ["84089.87000000", "0.37671000"], ["84089.70000000", "0.00009000"], ["84087.47000000", "0.00000000"], ["84085.05000000", "0.05000000"], ["84078.66000000", "0.00000000"], ["84077.81000000", "0.00000000"], ["84074.81000000", "0.02805000"], ["84069.33000000", "0.00000000"], ["84067.84000000", "0.00000000"], ["84061.96000000", "0.00000000"], ["83809.30000000", "0.00000000"], ["82869.98000000", "0.00000000"], ["75718.00000000", "0.00000000"], ["67305.57000000", "0.00058000"], ["33000.00000000", "2.93827000"]], "a": [["84131.97000000", "3.25540000"], ["84132.06000000", "0.00014000"], ["84132.07000000", "0.02812000"], ["84139.63000000", "0.00000000"], ["84142.34000000", "0.00900000"], ["84142.35000000", "0.00000000"], ["84142.83000000", "0.10702000"], ["84144.97000000", "0.00880000"], ["84145.25000000", "0.08304000"], ["84146.72000000", "0.29979000"], ["84146.95000000", "0.00000000"], ["84147.31000000", "0.05940000"], ["84155.93000000", "0.08992000"], ["84157.20000000", "0.06445000"], ["84157.91000000", "0.00000000"], ["84189.29000000", "0.02378000"], ["85393.95000000", "0.00100000"]], "record_time": 1742554943.0564, "EXCHANGE": "BINANCE"}
{"e": "depthUpdate", "E": 1742554944014, "s": "BTCUSDT", "U": 64606998436, "u": 64607000289, "b": [["84131.96000000", "0.00000000"], ["84131.95000000", "0.00000000"], ["84131.89000000", "0.00000000"], ["84131.88000000", "0.00000000"], ["84131.87000000", "0.00000000"], ["84131.81000000", "0.00000000"], ["84131.80000000", "0.00000000"], ["84131.67000000", "0.00000000"], ["84131.66000000", "0.00000000"], ["84131.12000000", "0.00000000"], ["84130.34000000", "0.00000000"], ["84130.33000000", "0.00000000"], ["84130.24000000", "0.00000000"], ["84130.23000000", "0.00000000"], ["84130.21000000", "0.00000000"], ["84130.20000000", "0.00000000"], ["84130.00000000", "0.00000000"], ["84129.64000000", "0.00000000"], ["84128.73000000", "0.00000000"], ["84128.55000000", "0.00000000"], ["84128.44000000", "0.00000000"], ["84128.43000000", "0.00000000"], ["84128.06000000", "0.00000000"], ["84128.05000000", "0.00000000"], ["84128.04000000", "0.00000000"], ["84128.00000000", "0.00000000"], ["84127.95000000", "0.00000000"], ["84127.36000000", "0.00000000"], ["84127.35000000", "0.00000000"], ["84127.34000000", "0.00000000"], ["84127.11000000", "0.00000000"], ["84126.63000000", "0.00000000"], ["84126.49000000", "0.00000000"], ["84126.27000000", "0.00000000"], ["84126.26000000", "0.00000000"], ["84126.00000000", "0.00000000"], ["84125.95000000", "0.00000000"], ["84125.84000000", "0.00000000"], ["84125.57000000", "0.00000000"], ["84125.40000000", "0.00000000"], ["84125.39000000", "0.10248000"], ["84125.38000000", "0.00015000"], ["84125.33000000", "0.00010000"], ["84125.32000000", "0.00007000"], ["84125.24000000", "0.00000000"], ["84125.07000000", "0.00007000"], ["84124.92000000", "0.00007000"], ["84124.58000000", "0.00007000"], ["84124.40000000", "0.00000000"], ["84124.33000000", "0.00000000"], ["84124.12000000", "0.00021000"], ["84124.11000000", "0.00764000"], ["84124.01000000", "0.00021000"], ["84124.00000000", "0.00000000"], ["84123.89000000", "0.00014000"], ["84123.88000000", "0.08307000"], ["84123.55000000", "0.00000000"], ["84123.47000000", "0.00000000"], ["84123.44000000", "0.00000000"], ["84123.13000000", "0.00000000"], ["84123.12000000", "0.00000000"], ["84122.72000000", "0.00000000"], ["84122.65000000", "0.00014000"], ["84122.64000000", "0.07740000"], ["84122.30000000", "0.00091000"], ["84122.19000000", "0.00000000"], ["84122.00000000", "0.00000000"], ["84121.80000000", "0.00000000"], ["84121.79000000", "0.00007000"], ["84121.35000000", "0.00000000"], ["84121.29000000", "0.00000000"], ["84121.10000000", "0.00000000"], ["84120.51000000", "0.00000000"], ["84120.10000000", "0.00000000"], ["84120.00000000", "0.02273000"], ["84119.84000000", "0.02218000"], ["84119.77000000", "0.00000000"], ["84119.62000000", "0.00011000"], ["84119.56000000", "0.00118000"], ["84119.44000000", "0.00000000"], ["84119.35000000", "0.00000000"], ["84119.22000000", "0.00000000"], ["84118.80000000", "0.00000000"], ["84118.64000000", "0.00000000"], ["84118.47000000", "0.00008000"], ["84118.02000000", "0.00000000"], ["84117.97000000", "0.00000000"], ["84117.60000000", "0.00006000"], ["84117.03000000", "0.00000000"], ["84116.71000000", "0.00000000"], ["84116.30000000", "0.00000000"], ["84116.22000000", "0.00000000"], ["84116.20000000", "0.00000000"], ["84116.12000000", "0.00000000"], ["84115.53000000", "0.00000000"], ["84115.32000000", "0.00000000"], ["84114.76000000", "0.00000000"], ["84114.74000000", "0.00000000"], ["84114.47000000", "0.04000000"], ["84114.10000000", "0.00000000"], ["84114.02000000", "0.00000000"], ["84113.40000000", "0.02412000"], ["84113.20000000", "0.00000000"], ["84113.19000000", "0.00000000"], ["84113.18000000", "0.00000000"], ["84113.12000000", "0.00000000"], ["84113.10000000", "0.00000000"], ["84113.02000000", "0.00000000"], ["84112.80000000", "0.00000000"], ["84112.08000000", "0.00000000"], ["84111.80000000", "0.00500000"], ["84111.72000000", "0.00500000"], ["84110.81000000", "0.00000000"], ["84110.80000000", "0.01007000"], ["84110.72000000", "0.01000000"], ["84110.65000000", "0.00000000"], ["84110.52000000", "0.00000000"], ["84110.41000000", "0.00000000"], ["84109.75000000", "0.00000000"], ["84109.65000000", "0.00000000"], ["84108.90000000", "0.35644000"], ["84108.73000000", "0.45000000"], ["84107.66000000", "0.00000000"], ["84107.10000000", "0.00000000"], ["84106.85000000", "0.02000000"], ["84106.72000000", "0.00300000"], ["84106.64000000", "0.00000000"], ["84106.41000000", "0.00000000"], ["84106.29000000", "0.00000000"], ["84106.15000000", "0.04000000"], ["84104.80000000", "0.00000000"], ["84104.73000000", "0.00000000"], ["84104.08000000", "0.00000000"], ["84103.47000000", "0.00000000"], ["84102.70000000", "0.00000000"], ["84102.37000000", "0.00000000"], ["84101.73000000", "0.12153000"], ["84101.71000000", "0.00000000"], ["84101.51000000", "0.89111000"], ["84101.33000000", "0.00000000"], ["84101.31000000", "0.06140000"], ["84100.93000000", "0.00000000"], ["84100.48000000", "0.00000000"], ["84100.40000000", "0.00000000"], ["84099.42000000", "0.05940000"], ["84099.17000000", "0.00476000"], ["84098.11000000", "0.00000000"], ["84097.26000000", "0.00000000"], ["84096.79000000", "0.00000000"], ["84095.80000000", "0.00500000"], ["84095.67000000", "0.89111000"], ["84095.51000000", "0.89111000"], ["84094.36000000", "0.00000000"], ["84094.23000000", "0.00000000"], ["84094.09000000", "0.02805000"], ["84092.70000000", "0.00000000"], ["84091.33000000", "0.00000000"], ["84090.33000000", "0.89117000"], ["84090.19000000", "0.00358000"], ["84089.90000000", "0.00212000"], ["84089.84000000", "0.00000000"], ["84087.47000000", "0.00000000"], ["84087.43000000", "0.45000000"], ["84085.06000000", "0.00000000"], ["84084.47000000", "0.00000000"], ["84083.99000000", "0.00000000"], ["84082.71000000", "0.33708000"], ["84082.24000000", "0.59466000"], ["84080.85000000", "0.00000000"], ["84079.64000000", "0.04942000"], ["84079.16000000", "0.00000000"], ["84078.61000000", "0.30079000"], ["84077.17000000", "0.00000000"], ["84076.79000000", "0.00296000"], ["84074.81000000", "0.00000000"], ["84070.88000000", "0.00000000"], ["84070.11000000", "0.00000000"], ["84068.48000000", "0.00000000"], ["84068.37000000", "0.66115000"], ["84067.19000000", "0.05947000"], ["84066.67000000", "0.00000000"], ["84066.37000000", "0.00296000"], ["84064.98000000", "0.00000000"], ["84063.82000000", "0.02853000"], ["84061.55000000", "0.00000000"], ["84056.54000000", "0.00358000"], ["84051.65000000", "0.00000000"], ["84041.90000000", "0.00000000"], ["84038.66000000", "0.00212000"], ["84037.07000000", "0.00000000"], ["84034.24000000", "0.00000000"], ["84004.67000000", "0.00000000"], ["84002.59000000", "0.00000000"], ["84000.18000000", "0.00183000"], ["83996.89000000", "0.00000000"], ["83992.74000000", "0.00118000"], ["83987.02000000", "0.05497000"], ["83982.36000000", "0.00118000"], ["83980.65000000", "0.00006000"], ["83959.80000000", "0.01000000"], ["83953.83000000", "0.00000000"], ["83947.80000000", "0.00400000"], ["83920.59000000", "0.00000000"], ["83917.49000000", "0.00000000"], ["83910.65000000", "0.00218000"], ["83860.60000000", "0.45007000"], ["83003.26000000", "0.40000000"], ["82994.90000000", "0.00000000"], ["82869.98000000", "0.00100000"], ["80730.96000000", "0.00000000"], ["80714.10000000", "0.03566000"], ["79900.00000000", "5.57490000"], ["75718.76000000", "0.00025000"], ["75718.00000000", "0.00000000"], ["67305.57000000", "0.00000000"], ["67301.88000000", "0.00058000"], ["66885.78000000", "0.00082000"], ["33000.00000000", "2.93827000"]], "a": [["84125.40000000", "5.46903000"], ["84125.41000000", "0.00000000"], ["84125.58000000", "2.57780000"], ["84125.85000000", "0.00000000"], ["84126.00000000", "0.02266000"], ["84126.01000000", "0.00000000"], ["84126.27000000", "0.00000000"], ["84126.28000000", "0.00000000"], ["84126.50000000", "0.00000000"], ["84126.64000000", "0.12066000"], ["84127.11000000", "0.00000000"], ["84127.12000000", "0.17586000"], ["84127.35000000", "0.00000000"], ["84127.36000000", "0.64304000"], ["84127.53000000", "0.00000000"], ["84127.84000000", "0.00000000"], ["84127.89000000", "0.00202000"], ["84127.93000000", "0.01000000"], ["84127.96000000", "0.00000000"], ["84128.00000000", "0.02266000"], ["84128.01000000", "0.00000000"], ["84128.05000000", "0.00000000"], ["84128.06000000", "0.00000000"], ["84128.07000000", "0.00000000"], ["84128.44000000", "0.00000000"], ["84128.45000000", "0.00000000"], ["84128.56000000", "0.00000000"], ["84128.62000000", "0.00000000"], ["84128.69000000", "0.00000000"], ["84128.73000000", "2.46381000"], ["84128.74000000", "0.02006000"], ["84129.03000000", "0.00000000"], ["84129.65000000", "0.00000000"], ["84129.89000000", "0.00000000"], ["84129.91000000", "0.00000000"], ["84129.92000000", "0.00000000"], ["84129.96000000", "0.00000000"], ["84130.00000000", "0.02273000"], ["84130.01000000", "0.00000000"], ["84130.21000000", "0.00000000"], ["84130.23000000", "0.00000000"], ["84130.24000000", "0.00000000"], ["84130.25000000", "0.00000000"], ["84130.34000000", "0.00000000"], ["84130.35000000", "0.21408000"], ["84130.51000000", "0.00000000"], ["84130.72000000", "0.00000000"], ["84130.97000000", "0.00000000"], ["84130.99000000", "0.04817000"], ["84131.03000000", "0.00000000"], ["84131.04000000", "0.00000000"], ["84131.12000000", "0.00000000"], ["84131.13000000", "0.03580000"], ["84131.39000000", "0.00000000"], ["84131.57000000", "0.00118000"], ["84131.67000000", "0.00000000"], ["84131.68000000", "0.00000000"], ["84131.81000000", "0.00000000"], ["84131.82000000", "0.00000000"], ["84131.87000000", "0.00000000"], ["84131.88000000", "0.00000000"], ["84131.89000000", "0.00000000"], ["84131.90000000", "0.00000000"], ["84131.96000000", "0.00000000"], ["84131.97000000", "0.72921000"], ["84131.98000000", "0.00042000"], ["84132.00000000", "0.02260000"], ["84132.06000000", "0.00000000"], ["84132.07000000", "0.00000000"], ["84132.08000000", "0.00000000"], ["84132.09000000", "0.00000000"], ["84132.26000000", "0.00000000"], ["84132.85000000", "0.00000000"], ["84132.86000000", "0.00000000"], ["84132.87000000", "0.32335000"], ["84133.01000000", "0.00000000"], ["84133.46000000", "0.08992000"], ["84133.49000000", "0.30251000"], ["84133.55000000", "0.00000000"], ["84133.56000000", "0.00000000"], ["84133.64000000", "0.00000000"], ["84133.72000000", "0.00000000"], ["84133.77000000", "0.00000000"], ["84133.86000000", "0.02352000"], ["84134.05000000", "0.00000000"], ["84134.08000000", "0.00000000"], ["84134.25000000", "0.00000000"], ["84134.36000000", "0.89111000"], ["84134.39000000", "0.00000000"], ["84134.89000000", "0.00000000"], ["84134.92000000", "0.00000000"], ["84135.29000000", "0.00000000"], ["84135.32000000", "0.00000000"], ["84135.50000000", "0.00000000"], ["84135.72000000", "0.00000000"], ["84136.09000000", "0.00058000"], ["84136.16000000", "0.00000000"], ["84136.20000000", "0.00500000"], ["84136.64000000", "0.00000000"], ["84137.28000000", "0.00000000"], ["84137.96000000", "0.00000000"], ["84138.51000000", "0.00000000"], ["84138.69000000", "0.00000000"], ["84139.90000000", "0.35644000"], ["84139.94000000", "0.59466000"], ["84139.97000000", "0.00000000"], ["84139.98000000", "0.89111000"], ["84140.05000000", "0.00118000"], ["84140.26000000", "0.89111000"], ["84140.30000000", "0.05940000"], ["84141.98000000", "0.00000000"], ["84143.44000000", "0.08992000"], ["84144.18000000", "0.05940000"], ["84144.58000000", "0.00000000"], ["84144.93000000", "0.00000000"], ["84146.58000000", "0.00000000"], ["84146.72000000", "0.00000000"], ["84147.31000000", "0.00000000"], ["84149.91000000", "0.85602000"], ["84150.05000000", "0.05940000"], ["84150.90000000", "0.00000000"], ["84152.59000000", "0.00000000"], ["84153.98000000", "0.00000000"], ["84154.07000000", "0.00000000"], ["84155.78000000", "0.00000000"], ["84157.14000000", "0.00758000"], ["84157.20000000", "0.00505000"], ["84157.72000000", "0.00000000"], ["84160.08000000", "0.00000000"], ["84160.28000000", "0.00000000"], ["84160.47000000", "0.00000000"], ["84161.85000000", "0.00000000"], ["84161.99000000", "0.00000000"], ["84162.92000000", "0.00084000"], ["84162.93000000", "0.02802000"], ["84164.33000000", "0.03609000"], ["84165.19000000", "0.00000000"], ["84165.70000000", "0.00000000"], ["84166.09000000", "0.00000000"], ["84166.44000000", "0.00000000"], ["84167.25000000", "0.00358000"], ["84168.00000000", "0.00016000"], ["84170.19000000", "0.35644000"], ["84171.23000000", "0.00000000"], ["84176.78000000", "0.00000000"], ["84179.65000000", "0.00000000"], ["84184.72000000", "0.00000000"], ["84195.90000000", "0.00000000"], ["84200.90000000", "0.00358000"], ["84203.78000000", "0.12827000"], ["84208.49000000", "0.04344000"], ["84221.99000000", "0.00296000"], ["84223.68000000", "0.00000000"], ["84225.89000000", "0.00000000"], ["84232.39000000", "0.00000000"], ["84263.16000000", "0.00000000"], ["84303.41000000", "0.99147000"], ["84303.61000000", "0.00012000"], ["85035.49000000", "0.00000000"], ["85043.92000000", "0.60000000"], ["85393.95000000", "0.00000000"], ["150001.00000000", "0.00084000"]], "record_time": 1742554944.048647, "EXCHANGE": "BINANCE"}
{"e": "depthUpdate", "E": 1742554945014, "s": "BTCUSDT", "U": 64607000290, "u": 64607004008, "b": [["84125.39000000", "0.00000000"], ["84125.38000000", "0.00000000"], ["84125.33000000", "0.00000000"], ["84125.32000000", "0.00000000"], ["84125.07000000", "0.00000000"], ["84124.92000000", "0.00000000"], ["84124.58000000", "0.00000000"], ["84124.12000000", "0.00000000"], ["84124.11000000", "0.00000000"], ["84124.10000000", "0.00000000"], ["84124.04000000", "0.00000000"], ["84124.01000000", "0.00000000"], ["84123.89000000", "0.00000000"], ["84123.88000000", "0.00000000"], ["84123.74000000", "0.00000000"], ["84123.45000000", "0.00000000"], ["84123.38000000", "0.00000000"], ["84122.66000000", "0.00000000"], ["84122.65000000", "0.00000000"], ["84122.64000000", "0.00000000"], ["84122.30000000", "0.00000000"], ["84122.25000000", "0.00000000"], ["84122.22000000", "0.00000000"], ["84122.11000000", "0.00000000"], ["84122.05000000", "0.00000000"], ["84121.81000000", "0.00000000"], ["84121.79000000", "0.00000000"], ["84121.46000000", "0.00000000"], ["84121.36000000", "0.00000000"], ["84121.30000000", "0.00000000"], ["84120.79000000", "0.00000000"], ["84120.78000000", "0.00000000"], ["84120.59000000", "0.00000000"], ["84120.58000000", "0.00000000"], ["84120.10000000", "0.00000000"], ["84120.00000000", "0.00000000"], ["84119.88000000", "0.00000000"], ["84119.87000000", "0.00000000"], ["84119.85000000", "0.00000000"], ["84119.84000000", "0.00000000"], ["84119.79000000", "0.00000000"], ["84119.78000000", "0.00000000"], ["84119.62000000", "0.00000000"], ["84119.56000000", "0.00000000"], ["84119.51000000", "0.00000000"], ["84119.49000000", "0.00000000"], ["84118.83000000", "0.00000000"], ["84118.82000000", "0.00000000"], ["84118.70000000", "0.00000000"], ["84118.63000000", "0.00000000"], ["84118.55000000", "0.00000000"], ["84118.47000000", "0.00000000"], ["84118.11000000", "0.00000000"], ["84118.05000000", "0.00000000"], ["84118.02000000", "0.00000000"], ["84118.01000000", "0.00000000"], ["84118.00000000", "0.00000000"], ["84117.74000000", "0.00000000"], ["84117.73000000", "0.00000000"], ["84117.60000000", "0.00000000"], ["84117.46000000", "0.00000000"], ["84117.23000000", "0.00000000"], ["84116.97000000", "0.00000000"], ["84116.61000000", "0.00000000"], ["84116.54000000", "0.00000000"], ["84116.00000000", "0.00000000"], ["84115.82000000", "0.00000000"], ["84115.81000000", "0.00000000"], ["84115.75000000", "0.00000000"], ["84115.14000000", "0.00000000"], ["84114.96000000", "0.00000000"], ["84114.89000000", "0.00000000"], ["84114.88000000", "0.00000000"], ["84114.79000000", "0.00000000"], ["84114.76000000", "0.00000000"], ["84114.75000000", "0.00000000"], ["84114.58000000", "0.00000000"], ["84114.57000000", "0.00000000"], ["84114.50000000", "0.00000000"], ["84114.47000000", "0.00000000"], ["84114.45000000", "0.00000000"], ["84114.44000000", "0.00000000"], ["84114.43000000", "0.00000000"], ["84114.37000000", "0.00000000"], ["84114.36000000", "0.00000000"], ["84114.01000000", "0.00000000"], ["84114.00000000", "0.00000000"], ["84113.71000000", "0.00000000"], ["84113.40000000", "0.00000000"], ["84113.10000000", "0.00000000"], ["84112.82000000", "0.00000000"], ["84112.81000000", "0.00000000"], ["84112.78000000", "0.00000000"], ["84112.66000000", "0.00000000"], ["84112.58000000", "0.00000000"], ["84112.30000000", "0.00000000"], ["84112.23000000", "0.00000000"], ["84112.01000000", "0.00000000"], ["84112.00000000", "0.00000000"], ["84111.82000000", "0.00000000"], ["84111.80000000", "0.00000000"], ["84111.76000000", "0.00000000"], ["84111.73000000", "0.00000000"], ["84111.72000000", "0.00000000"], ["84111.66000000", "0.00000000"], ["84111.61000000", "0.00000000"], ["84111.51000000", "0.00000000"], ["84111.50000000", "0.00000000"], ["84111.48000000", "0.00000000"], ["84111.45000000", "0.00000000"], ["84111.44000000", "2.80438000"], ["84111.43000000", "0.00064000"], ["84111.37000000", "0.00000000"], ["84111.36000000", "0.00000000"], ["84111.19000000", "0.00000000"], ["84111.16000000", "0.00000000"], ["84111.15000000", "0.00000000"], ["84111.12000000", "0.00139000"], ["84111.08000000", "0.00021000"], ["84111.07000000", "0.02576000"], ["84111.06000000", "0.00007000"], ["84111.05000000", "0.00007000"], ["84110.99000000", "0.00044000"], ["84110.95000000", "0.00000000"], ["84110.80000000", "0.00000000"], ["84110.72000000", "0.00000000"], ["84110.54000000", "0.00000000"], ["84110.53000000", "0.00000000"], ["84110.47000000", "0.00000000"], ["84110.18000000", "0.00000000"], ["84110.11000000", "0.00000000"], ["84110.02000000", "0.00000000"], ["84110.01000000", "0.00014000"], ["84110.00000000", "0.02273000"], ["84109.91000000", "0.00000000"], ["84109.86000000", "0.00000000"], ["84109.78000000", "0.00000000"], ["84109.77000000", "0.00000000"], ["84109.70000000", "0.00000000"], ["84109.63000000", "0.00000000"], ["84109.55000000", "0.00000000"], ["84109.34000000", "0.00000000"], ["84109.31000000", "0.00000000"], ["84109.27000000", "0.00000000"], ["84109.20000000", "0.00000000"], ["84108.99000000", "0.00000000"], ["84108.94000000", "0.00014000"], ["84108.93000000", "0.09447000"], ["84108.90000000", "0.00000000"], ["84108.84000000", "0.00000000"], ["84108.82000000", "0.00000000"], ["84108.78000000", "0.00000000"], ["84108.73000000", "0.00000000"], ["84108.71000000", "0.00029000"], ["84108.70000000", "0.00287000"], ["84108.69000000", "0.00016000"], ["84108.56000000", "0.00000000"], ["84108.43000000", "0.00000000"], ["84108.20000000", "0.00000000"], ["84108.12000000", "0.00000000"], ["84108.00000000", "0.00000000"], ["84107.92000000", "0.00000000"], ["84107.88000000", "0.00000000"], ["84107.87000000", "0.02410000"], ["84107.86000000", "0.02388000"], ["84107.70000000", "0.00007000"], ["84107.67000000", "0.00000000"], ["84107.57000000", "0.00000000"], ["84107.25000000", "0.02205000"], ["84107.12000000", "0.00014000"], ["84107.11000000", "0.22505000"], ["84106.90000000", "0.00000000"], ["84106.88000000", "0.00029000"], ["84106.85000000", "0.00000000"], ["84106.82000000", "0.00000000"], ["84106.73000000", "0.00000000"], ["84106.48000000", "0.00000000"], ["84106.45000000", "0.00000000"], ["84106.42000000", "0.00000000"], ["84106.27000000", "0.00000000"], ["84106.15000000", "0.00000000"], ["84106.07000000", "0.00000000"], ["84106.03000000", "0.00000000"], ["84106.00000000", "0.02260000"], ["84105.57000000", "0.00000000"], ["84105.54000000", "0.00000000"], ["84105.13000000", "0.02336000"], ["84105.11000000", "0.00000000"], ["84105.02000000", "0.00000000"], ["84104.85000000", "0.00000000"], ["84104.75000000", "0.00000000"], ["84104.72000000", "0.01188000"], ["84104.60000000", "0.00000000"], ["84104.57000000", "0.00000000"], ["84104.56000000", "0.00000000"], ["84104.51000000", "0.00000000"], ["84104.48000000", "0.00000000"], ["84104.42000000", "0.00000000"], ["84104.02000000", "0.00011000"], ["84103.63000000", "0.00000000"], ["84103.41000000", "0.00007000"], ["84103.40000000", "0.89111000"], ["84103.36000000", "0.00000000"], ["84103.20000000", "0.08000000"], ["84102.99000000", "0.04817000"], ["84102.68000000", "0.34598000"], ["84102.65000000", "0.16221000"], ["84102.55000000", "0.00000000"], ["84101.97000000", "0.00000000"], ["84101.88000000", "0.00078000"], ["84101.85000000", "0.00000000"], ["84101.80000000", "0.00000000"], ["84101.78000000", "0.00092000"], ["84101.75000000", "0.00208000"], ["84101.73000000", "0.00000000"], ["84101.67000000", "0.00000000"], ["84101.60000000", "0.00015000"], ["84101.59000000", "0.04000000"], ["84101.51000000", "0.00000000"], ["84101.31000000", "0.00000000"], ["84101.27000000", "0.00000000"], ["84101.20000000", "0.00091000"], ["84101.14000000", "0.00000000"], ["84101.06000000", "0.00000000"], ["84100.80000000", "0.02403000"], ["84100.77000000", "0.00000000"], ["84100.75000000", "0.04000000"], ["84100.67000000", "0.00000000"], ["84100.59000000", "0.00000000"], ["84100.47000000", "0.00000000"], ["84100.45000000", "0.00000000"], ["84100.39000000", "0.00000000"], ["84100.38000000", "0.00000000"], ["84100.28000000", "0.00000000"], ["84100.27000000", "0.00000000"], ["84100.25000000", "0.59407000"], ["84100.21000000", "0.00000000"], ["84100.15000000", "0.00300000"], ["84099.87000000", "0.00000000"], ["84099.84000000", "0.04000000"], ["84099.52000000", "0.00095000"], ["84099.42000000", "0.00000000"], ["84099.41000000", "0.00000000"], ["84099.17000000", "0.00000000"], ["84099.08000000", "0.00000000"], ["84099.06000000", "0.00000000"], ["84098.91000000", "0.00000000"], ["84098.90000000", "0.00000000"], ["84098.84000000", "0.00414000"], ["84098.83000000", "0.01189000"], ["84098.37000000", "0.04000000"], ["84098.10000000", "0.03000000"], ["84097.89000000", "0.10701000"], ["84097.76000000", "0.00059000"], ["84097.75000000", "0.85761000"], ["84097.74000000", "0.45000000"], ["84097.70000000", "0.01188000"], ["84097.52000000", "0.71284000"], ["84097.51000000", "0.00000000"], ["84097.50000000", "0.00000000"], ["84097.39000000", "0.04000000"], ["84097.26000000", "0.47526000"], ["84096.94000000", "0.00000000"], ["84096.55000000", "0.04000000"], ["84095.99000000", "0.00000000"], ["84095.97000000", "0.16019000"], ["84095.72000000", "0.04000000"], ["84095.70000000", "0.04000000"], ["84095.67000000", "0.00000000"], ["84095.63000000", "0.04000000"], ["84095.51000000", "0.00000000"], ["84095.47000000", "0.00007000"], ["84095.28000000", "0.00000000"], ["84095.19000000", "0.00118000"], ["84094.65000000", "0.06000000"], ["84094.22000000", "0.86413000"], ["84094.09000000", "0.00000000"], ["84093.82000000", "0.00000000"], ["84093.23000000", "0.00000000"], ["84093.07000000", "0.78522000"], ["84092.98000000", "0.00000000"], ["84092.85000000", "0.08000000"], ["84092.46000000", "0.00000000"], ["84092.45000000", "0.00000000"], ["84092.34000000", "0.35644000"], ["84090.92000000", "0.29027000"], ["84090.78000000", "0.89111000"], ["84090.33000000", "0.00006000"], ["84090.31000000", "0.00000000"], ["84090.22000000", "0.00000000"], ["84090.19000000", "0.00000000"], ["84089.98000000", "0.11734000"], ["84089.94000000", "0.00000000"], ["84089.90000000", "0.00000000"], ["84089.89000000", "0.00000000"], ["84089.87000000", "0.37671000"], ["84089.83000000", "0.00000000"], ["84089.35000000", "0.00059000"], ["84089.14000000", "0.00000000"], ["84088.85000000", "0.01188000"], ["84088.77000000", "0.00000000"], ["84088.76000000", "0.00582000"], ["84088.39000000", "0.00000000"], ["84088.19000000", "0.00000000"], ["84088.08000000", "0.00000000"], ["84087.99000000", "0.79169000"], ["84087.66000000", "0.00000000"], ["84086.86000000", "1.38138000"], ["84086.81000000", "0.02805000"], ["84086.78000000", "0.00000000"], ["84085.71000000", "0.00000000"], ["84085.68000000", "0.16000000"], ["84085.42000000", "0.00355000"], ["84085.40000000", "0.00000000"], ["84085.05000000", "0.00000000"], ["84084.91000000", "0.00000000"], ["84084.89000000", "0.29545000"], ["84084.88000000", "0.00000000"], ["84084.56000000", "0.00000000"], ["84084.36000000", "0.89111000"], ["84084.35000000", "0.89111000"], ["84084.26000000", "0.00000000"], ["84084.17000000", "0.89111000"], ["84084.15000000", "0.00000000"], ["84084.11000000", "0.00000000"], ["84084.02000000", "0.00000000"], ["84083.90000000", "0.00000000"], ["84083.82000000", "0.89111000"], ["84083.40000000", "0.04000000"], ["84082.56000000", "0.08000000"], ["84082.24000000", "0.00000000"], ["84082.23000000", "0.00000000"], ["84082.04000000", "0.00013000"], ["84081.97000000", "0.00000000"], ["84081.95000000", "0.00000000"], ["84081.92000000", "0.00000000"], ["84081.63000000", "0.00016000"], ["84081.59000000", "0.89111000"], ["84080.84000000", "0.00000000"], ["84080.53000000", "0.00000000"], ["84080.34000000", "0.00000000"], ["84079.99000000", "0.00000000"], ["84079.73000000", "0.89111000"], ["84079.69000000", "0.89111000"], ["84079.64000000", "0.00000000"], ["84079.16000000", "0.00212000"], ["84079.15000000", "0.00000000"], ["84079.01000000", "0.00000000"], ["84078.61000000", "0.00000000"], ["84078.53000000", "0.41059000"], ["84078.49000000", "0.00000000"], ["84078.48000000", "0.00000000"], ["84078.15000000", "0.00000000"], ["84078.09000000", "0.03855000"], ["84078.04000000", "0.00000000"], ["84077.87000000", "0.00000000"], ["84077.86000000", "0.04636000"], ["84077.85000000", "0.98426000"], ["84077.71000000", "0.00000000"], ["84077.18000000", "0.00000000"], ["84077.08000000", "0.31355000"], ["84076.79000000", "0.00000000"], ["84076.78000000", "0.04636000"], ["84076.29000000", "0.00000000"], ["84076.28000000", "0.00594000"], ["84076.09000000", "0.00000000"], ["84075.79000000", "0.00118000"], ["84075.37000000", "0.10994000"], ["84074.59000000", "0.00000000"], ["84074.58000000", "0.16491000"], ["84074.39000000", "0.89111000"], ["84074.10000000", "0.85679000"], ["84073.99000000", "0.00358000"], ["84073.91000000", "0.00000000"], ["84073.90000000", "0.00000000"], ["84073.37000000", "0.10394000"], ["84073.16000000", "0.00000000"], ["84073.15000000", "0.00000000"], ["84073.13000000", "0.00000000"], ["84073.12000000", "0.00000000"], ["84073.05000000", "0.00000000"], ["84072.65000000", "0.05197000"], ["84072.05000000", "0.00000000"], ["84070.87000000", "0.00118000"], ["84070.62000000", "0.25128000"], ["84070.59000000", "0.00000000"], ["84069.19000000", "0.05902000"], ["84068.86000000", "0.00000000"], ["84068.47000000", "0.00000000"], ["84068.38000000", "0.59476000"], ["84068.37000000", "0.62017000"], ["84067.26000000", "0.85686000"], ["84067.19000000", "0.00000000"], ["84066.37000000", "0.00000000"], ["84066.36000000", "0.00000000"], ["84065.50000000", "0.00000000"], ["84063.22000000", "0.00296000"], ["84063.21000000", "0.85690000"], ["84063.18000000", "0.10394000"], ["84062.76000000", "0.00000000"], ["84062.75000000", "0.00000000"], ["84062.05000000", "0.30079000"], ["84061.31000000", "0.05297000"], ["84061.30000000", "0.71284000"], ["84059.53000000", "0.04942000"], ["84059.37000000", "0.00000000"], ["84059.03000000", "0.00000000"], ["84058.14000000", "0.00000000"], ["84056.54000000", "0.00000000"], ["84056.23000000", "0.00118000"], ["84055.85000000", "0.00000000"], ["84055.43000000", "0.00000000"], ["84055.12000000", "0.00805000"], ["84054.86000000", "0.47526000"], ["84054.43000000", "0.14891000"], ["84054.04000000", "0.17822000"], ["84053.79000000", "0.00297000"], ["84052.01000000", "0.00000000"], ["84051.90000000", "0.45058000"], ["84051.68000000", "0.59407000"], ["84050.38000000", "0.00000000"], ["84048.59000000", "0.00000000"], ["84047.86000000", "0.00000000"], ["84047.58000000", "0.00000000"], ["84046.83000000", "0.00820000"], ["84046.64000000", "0.00826000"], ["84046.35000000", "0.00000000"], ["84045.44000000", "0.00859000"], ["84044.56000000", "0.00298000"], ["84044.06000000", "0.00000000"], ["84042.14000000", "0.00000000"], ["84041.36000000", "0.00000000"], ["84041.15000000", "0.00000000"], ["84040.85000000", "0.00000000"], ["84040.34000000", "0.00358000"], ["84039.17000000", "0.00000000"], ["84039.09000000", "0.52518000"], ["84038.66000000", "0.00000000"], ["84038.54000000", "0.00000000"], ["84037.47000000", "0.04000000"], ["84036.37000000", "0.00000000"], ["84036.24000000", "0.00000000"], ["84036.05000000", "0.00000000"], ["84035.72000000", "0.00000000"], ["84034.33000000", "0.00000000"], ["84033.60000000", "0.03574000"], ["84030.76000000", "0.00009000"], ["84030.07000000", "0.50258000"], ["84028.68000000", "0.00000000"], ["84026.36000000", "1.12465000"], ["84026.09000000", "0.05227000"], ["84024.23000000", "0.00212000"], ["84023.39000000", "0.00144000"], ["84023.38000000", "0.00000000"], ["84023.16000000", "0.03174000"], ["84022.61000000", "0.00000000"], ["84022.36000000", "0.04754000"], ["84022.35000000", "0.00000000"], ["84022.12000000", "0.00000000"], ["84020.45000000", "0.12503000"], ["84018.09000000", "0.12044000"], ["84017.51000000", "0.05496000"], ["84016.87000000", "0.14487000"], ["84015.62000000", "0.05496000"], ["84015.61000000", "0.04635000"], ["84015.51000000", "0.07728000"], ["84015.18000000", "0.05097000"], ["84015.17000000", "0.04636000"], ["84014.45000000", "0.43086000"], ["84014.23000000", "0.05111000"], ["84013.98000000", "0.09271000"], ["84013.95000000", "0.00000000"], ["84013.76000000", "0.09391000"], ["84013.61000000", "0.01196000"], ["84012.90000000", "0.10132000"], ["84012.89000000", "0.09270000"], ["84012.26000000", "0.14368000"], ["84012.18000000", "0.05296000"], ["84012.17000000", "0.24037000"], ["84010.95000000", "0.04635000"], ["84010.86000000", "0.16066000"], ["84010.48000000", "0.04754000"], ["84010.47000000", "0.04635000"], ["84010.20000000", "0.04635000"], ["84010.14000000", "0.04636000"], ["84009.48000000", "0.10252000"], ["84008.64000000", "0.04636000"], ["84008.12000000", "0.05097000"], ["84007.98000000", "0.04636000"], ["84007.93000000", "0.05496000"], ["84007.92000000", "0.05296000"], ["84007.55000000", "0.04636000"], ["84007.36000000", "0.04636000"], ["84006.47000000", "0.00000000"], ["84005.44000000", "0.04636000"], ["84005.42000000", "0.05496000"], ["84005.11000000", "0.05496000"], ["84005.06000000", "0.05296000"], ["84004.85000000", "0.05097000"], ["84004.64000000", "0.04636000"], ["84003.93000000", "0.05496000"], ["84002.15000000", "0.05296000"], ["84002.10000000", "0.05496000"], ["84001.56000000", "0.05496000"], ["84001.04000000", "0.04636000"], ["84000.18000000", "0.00000000"], ["83999.81000000", "0.05097000"], ["83999.70000000", "0.05296000"], ["83999.64000000", "0.05496000"], ["83999.62000000", "0.05096000"], ["83999.32000000", "0.04636000"], ["83999.22000000", "0.04097000"], ["83999.00000000", "0.05496000"], ["83998.81000000", "0.05196000"], ["83998.72000000", "0.00013000"], ["83997.20000000", "0.05096000"], ["83997.06000000", "0.04712000"], ["83996.99000000", "0.00000000"], ["83996.70000000", "0.05496000"], ["83996.54000000", "0.05096000"], ["83996.49000000", "0.04636000"], ["83996.31000000", "0.05097000"], ["83996.25000000", "0.05196000"], ["83996.24000000", "0.05496000"], ["83995.87000000", "0.05496000"], ["83995.69000000", "0.05496000"], ["83995.34000000", "0.05296000"], ["83995.17000000", "0.00000000"], ["83993.96000000", "0.05096000"], ["83993.94000000", "0.04636000"], ["83993.82000000", "0.04097000"], ["83993.69000000", "0.05196000"], ["83993.42000000", "0.05097000"], ["83993.21000000", "0.04097000"], ["83992.74000000", "0.00000000"], ["83992.70000000", "0.04897000"], ["83992.17000000", "0.05296000"], ["83991.69000000", "0.05196000"], ["83991.24000000", "0.10094000"], ["83990.89000000", "0.05097000"], ["83988.98000000", "0.05496000"], ["83988.66000000", "0.04206000"], ["83987.94000000", "0.05296000"], ["83987.75000000", "0.04097000"], ["83987.60000000", "0.00183000"], ["83986.10000000", "0.00013000"], ["83985.65000000", "0.04897000"], ["83984.73000000", "0.05497000"], ["83984.63000000", "0.04197000"], ["83984.14000000", "0.05196000"], ["83983.29000000", "0.04197000"], ["83982.49000000", "0.04897000"], ["83982.36000000", "0.00000000"], ["83982.18000000", "0.04097000"], ["83980.28000000", "0.04197000"], ["83979.51000000", "0.00118000"], ["83978.81000000", "0.04197000"], ["83977.34000000", "0.00000000"], ["83974.80000000", "0.12868000"], ["83968.40000000", "0.00118000"], ["83966.39000000", "0.00006000"], ["83959.80000000", "0.00000000"], ["83959.24000000", "0.00000000"], ["83957.75000000", "0.00000000"], ["83956.90000000", "0.00000000"], ["83955.01000000", "0.00000000"], ["83952.94000000", "0.99313000"], ["83952.90000000", "0.00000000"], ["83952.89000000", "0.01524000"], ["83951.41000000", "0.00000000"], ["83949.91000000", "0.00000000"], ["83949.01000000", "0.00000000"], ["83948.32000000", "0.01000000"], ["83947.82000000", "0.00000000"], ["83947.80000000", "0.00000000"], ["83947.42000000", "0.00000000"], ["83936.69000000", "0.00000000"], ["83930.12000000", "0.00000000"], ["83920.59000000", "0.00063000"], ["83916.32000000", "0.07256000"], ["83910.65000000", "0.00000000"], ["83910.10000000", "0.07219000"], ["83909.49000000", "0.00000000"], ["83907.91000000", "0.05441000"], ["83901.69000000", "0.05481000"], ["83901.18000000", "0.00000000"], ["83901.08000000", "0.00000000"], ["83899.51000000", "0.00218000"], ["83899.50000000", "0.06793000"], ["83891.61000000", "0.06793000"], ["83888.06000000", "0.00013000"], ["83883.86000000", "0.00013000"], ["83881.84000000", "0.00000000"], ["83879.66000000", "0.00013000"], ["83875.46000000", "0.00013000"], ["83872.04000000", "0.00000000"], ["83869.94000000", "0.00013000"], ["83868.32000000", "0.00400000"], ["83865.74000000", "0.00000000"], ["83865.21000000", "0.00000000"], ["83857.06000000", "0.00000000"], ["83852.95000000", "0.00000000"], ["83844.45000000", "0.00000000"], ["83843.76000000", "0.45000000"], ["83823.39000000", "0.00000000"], ["83823.38000000", "0.00452000"], ["83611.54000000", "0.00000000"], ["83611.50000000", "0.00040000"], ["83436.61000000", "0.00119000"], ["83188.38000000", "0.00000000"], ["83188.37000000", "0.00060000"], ["83183.88000000", "0.00106000"], ["83183.76000000", "0.00040000"], ["82869.98000000", "0.00000000"], ["80714.10000000", "0.00000000"], ["75718.76000000", "0.00000000"], ["75700.00000000", "6.42624000"], ["67301.88000000", "0.00000000"], ["67291.67000000", "0.00000000"], ["67289.16000000", "0.00058000"], ["42097.01000000", "0.00108000"], ["42057.29000000", "0.00027000"], ["42000.00000000", "6.85261000"], ["33000.00000000", "2.93827000"]], "a": [["84111.45000000", "6.92252000"], ["84111.46000000", "0.00040000"], ["84112.01000000", "0.00000000"], ["84112.02000000", "0.00000000"], ["84112.24000000", "0.00000000"], ["84112.46000000", "0.00058000"], ["84112.59000000", "0.00000000"], ["84113.11000000", "0.00014000"], ["84113.12000000", "0.00924000"], ["84113.59000000", "0.00000000"], ["84113.99000000", "0.00014000"], ["84114.00000000", "0.02260000"], ["84114.02000000", "0.00000000"], ["84114.23000000", "0.00014000"], ["84114.24000000", "0.04817000"], ["84114.37000000", "0.00000000"], ["84114.38000000", "0.00000000"], ["84114.48000000", "0.00000000"], ["84114.49000000", "0.00000000"], ["84114.54000000", "0.00014000"], ["84114.55000000", "1.01837000"], ["84114.56000000", "0.00000000"], ["84114.57000000", "0.00006000"], ["84114.58000000", "0.00000000"], ["84114.59000000", "2.22282000"], ["84114.60000000", "0.00000000"], ["84114.61000000", "0.00000000"], ["84114.75000000", "0.00000000"], ["84114.76000000", "0.00000000"], ["84114.96000000", "0.02345000"], ["84114.97000000", "0.00000000"], ["84114.98000000", "0.02373000"], ["84115.15000000", "0.00000000"], ["84115.60000000", "0.00000000"], ["84115.68000000", "0.00000000"], ["84115.81000000", "0.00000000"], ["84115.99000000", "0.00006000"], ["84116.00000000", "0.17745000"], ["84116.01000000", "0.00000000"], ["84116.03000000", "0.00000000"], ["84116.26000000", "0.00000000"], ["84116.38000000", "0.13525000"], ["84116.97000000", "0.00000000"], ["84116.98000000", "0.00000000"], ["84116.99000000", "0.00000000"], ["84117.03000000", "0.00000000"], ["84117.47000000", "0.00000000"], ["84117.71000000", "0.00059000"], ["84117.82000000", "0.00000000"], ["84118.00000000", "0.02260000"], ["84118.01000000", "0.13519000"], ["84118.12000000", "0.00000000"], ["84118.17000000", "0.01188000"], ["84118.71000000", "0.00000000"], ["84118.83000000", "0.04000000"], ["84118.84000000", "0.00000000"], ["84118.92000000", "0.03356000"], ["84119.36000000", "0.00000000"], ["84119.50000000", "0.00000000"], ["84119.51000000", "0.00000000"], ["84119.52000000", "0.17822000"], ["84119.59000000", "0.00000000"], ["84119.63000000", "0.00000000"], ["84119.68000000", "0.04000000"], ["84119.89000000", "0.00000000"], ["84120.00000000", "0.02266000"], ["84120.09000000", "0.00006000"], ["84120.53000000", "0.10000000"], ["84120.58000000", "0.00000000"], ["84120.59000000", "0.00000000"], ["84120.60000000", "0.00000000"], ["84120.61000000", "0.05200000"], ["84120.78000000", "0.00000000"], ["84120.79000000", "0.00000000"], ["84120.80000000", "0.00000000"], ["84120.85000000", "0.00000000"], ["84120.99000000", "0.00000000"], ["84121.02000000", "0.05940000"], ["84121.19000000", "0.00000000"], ["84121.47000000", "0.00000000"], ["84121.80000000", "0.00000000"], ["84121.81000000", "0.04000000"], ["84121.95000000", "0.00013000"], ["84122.00000000", "0.02260000"], ["84122.06000000", "0.38822000"], ["84122.07000000", "0.16000000"], ["84122.12000000", "0.00000000"], ["84122.17000000", "0.15769000"], ["84122.30000000", "0.35968000"], ["84122.39000000", "0.00118000"], ["84122.56000000", "0.00000000"], ["84122.65000000", "0.45000000"], ["84122.66000000", "0.00000000"], ["84122.88000000", "0.00000000"], ["84123.05000000", "0.07600000"], ["84123.31000000", "0.00058000"], ["84123.75000000", "0.00000000"], ["84123.89000000", "0.07200000"], ["84123.90000000", "0.00000000"], ["84123.93000000", "0.00000000"], ["84124.02000000", "0.00000000"], ["84124.03000000", "0.00000000"], ["84124.04000000", "0.00000000"], ["84124.05000000", "0.10964000"], ["84124.06000000", "0.01188000"], ["84124.07000000", "0.00000000"], ["84124.10000000", "0.00000000"], ["84124.11000000", "0.00000000"], ["84124.12000000", "0.01874000"], ["84124.13000000", "0.00000000"], ["84124.14000000", "0.00000000"], ["84124.32000000", "0.00000000"], ["84124.59000000", "0.00000000"], ["84124.65000000", "0.00202000"], ["84124.74000000", "0.06400000"], ["84124.77000000", "0.00000000"], ["84124.81000000", "0.06000000"], ["84124.84000000", "0.06400000"], ["84124.92000000", "0.00013000"], ["84124.93000000", "0.00000000"], ["84124.96000000", "0.00000000"], ["84124.97000000", "0.00000000"], ["84125.04000000", "0.00000000"], ["84125.06000000", "0.08304000"], ["84125.07000000", "0.00000000"], ["84125.08000000", "0.00000000"], ["84125.09000000", "0.00013000"], ["84125.10000000", "0.05940000"], ["84125.13000000", "0.00000000"], ["84125.15000000", "0.00000000"], ["84125.25000000", "0.00000000"], ["84125.30000000", "0.00000000"], ["84125.31000000", "0.00000000"], ["84125.33000000", "0.00000000"], ["84125.34000000", "0.00000000"], ["84125.38000000", "0.00000000"], ["84125.39000000", "0.34848000"], ["84125.40000000", "0.08438000"], ["84125.50000000", "0.89111000"], ["84125.57000000", "0.00000000"], ["84125.58000000", "0.00000000"], ["84126.00000000", "0.02266000"], ["84126.31000000", "0.02377000"], ["84126.64000000", "0.00000000"], ["84126.89000000", "0.00000000"], ["84127.04000000", "0.00000000"], ["84127.06000000", "0.00000000"], ["84127.07000000", "0.00000000"], ["84127.08000000", "0.00000000"], ["84127.12000000", "0.03580000"], ["84127.19000000", "0.00000000"], ["84127.23000000", "0.00000000"], ["84127.36000000", "0.04000000"], ["84127.37000000", "0.01188000"], ["84127.38000000", "0.00000000"], ["84127.52000000", "0.00000000"], ["84127.65000000", "0.00000000"], ["84127.66000000", "0.00009000"], ["84127.89000000", "0.00000000"], ["84127.93000000", "0.00000000"], ["84127.96000000", "0.00000000"], ["84128.00000000", "0.02260000"], ["84128.01000000", "0.00000000"], ["84128.05000000", "0.00000000"], ["84128.06000000", "0.00000000"], ["84128.27000000", "0.05940000"], ["84128.37000000", "0.00000000"], ["84128.44000000", "0.00000000"], ["84128.62000000", "0.00000000"], ["84128.63000000", "0.00000000"], ["84128.70000000", "1.08995000"], ["84128.71000000", "0.00000000"], ["84128.72000000", "0.00000000"], ["84128.73000000", "0.00000000"], ["84128.74000000", "0.00000000"], ["84128.86000000", "0.00138000"], ["84128.93000000", "0.10702000"], ["84129.14000000", "0.05940000"], ["84129.29000000", "0.00013000"], ["84129.65000000", "0.00000000"], ["84129.95000000", "0.00029000"], ["84130.00000000", "0.02260000"], ["84130.02000000", "0.00006000"], ["84130.03000000", "0.85622000"], ["84130.20000000", "0.00006000"], ["84130.34000000", "0.00000000"], ["84130.35000000", "0.21402000"], ["84130.38000000", "0.00000000"], ["84130.96000000", "0.00000000"], ["84130.99000000", "0.00000000"], ["84131.13000000", "0.03580000"], ["84131.14000000", "0.00000000"], ["84131.36000000", "0.89111000"], ["84131.41000000", "0.00059000"], ["84131.57000000", "0.00000000"], ["84131.73000000", "0.00000000"], ["84131.80000000", "0.00000000"], ["84131.81000000", "0.00000000"], ["84131.92000000", "0.67151000"], ["84131.96000000", "0.71284000"], ["84131.97000000", "0.48580000"], ["84131.98000000", "0.00000000"], ["84131.99000000", "0.05943000"], ["84132.12000000", "0.00000000"], ["84132.32000000", "0.00000000"], ["84132.57000000", "0.02377000"], ["84132.82000000", "0.00000000"], ["84132.87000000", "0.91800000"], ["84133.04000000", "0.02377000"], ["84133.49000000", "0.30264000"], ["84133.50000000", "0.00000000"], ["84133.86000000", "0.00000000"], ["84133.99000000", "0.09030000"], ["84134.04000000", "0.85618000"], ["84134.35000000", "0.00000000"], ["84134.40000000", "0.00006000"], ["84134.51000000", "0.05943000"], ["84134.68000000", "0.01188000"], ["84134.72000000", "0.00118000"], ["84134.85000000", "0.05943000"], ["84135.11000000", "0.08304000"], ["84135.55000000", "0.00831000"], ["84135.73000000", "0.89111000"], ["84136.00000000", "0.00000000"], ["84136.09000000", "0.00000000"], ["84136.24000000", "0.00000000"], ["84136.25000000", "0.89111000"], ["84136.73000000", "0.00000000"], ["84136.93000000", "1.72091000"], ["84137.36000000", "0.00000000"], ["84138.01000000", "0.00000000"], ["84138.12000000", "1.38347000"], ["84138.28000000", "0.85614000"], ["84138.66000000", "0.89111000"], ["84139.07000000", "0.00594000"], ["84139.10000000", "0.00000000"], ["84139.48000000", "0.05943000"], ["84139.60000000", "0.47526000"], ["84139.61000000", "0.71284000"], ["84139.72000000", "0.02377000"], ["84139.74000000", "0.85613000"], ["84139.82000000", "0.00059000"], ["84139.90000000", "0.00000000"], ["84139.94000000", "0.00000000"], ["84139.95000000", "0.00006000"], ["84140.05000000", "0.00000000"], ["84140.14000000", "0.00000000"], ["84140.30000000", "0.00000000"], ["84140.78000000", "0.00000000"], ["84140.80000000", "0.00000000"], ["84140.87000000", "0.00000000"], ["84141.30000000", "0.59470000"], ["84141.37000000", "0.03324000"], ["84141.40000000", "0.20427000"], ["84141.62000000", "0.00016000"], ["84141.71000000", "0.00000000"], ["84142.11000000", "0.02377000"], ["84142.22000000", "0.00000000"], ["84142.23000000", "0.00300000"], ["84142.29000000", "0.00000000"], ["84142.42000000", "0.05943000"], ["84142.45000000", "0.29303000"], ["84142.83000000", "0.00000000"], ["84143.22000000", "0.19453000"], ["84143.30000000", "0.00000000"], ["84143.53000000", "0.00000000"], ["84143.96000000", "0.00000000"], ["84144.16000000", "0.00000000"], ["84144.18000000", "0.00000000"], ["84144.97000000", "0.00000000"], ["84144.99000000", "0.00000000"], ["84145.02000000", "0.00000000"], ["84145.08000000", "0.00000000"], ["84145.20000000", "0.00577000"], ["84145.52000000", "0.02971000"], ["84146.09000000", "0.00000000"], ["84146.25000000", "0.05943000"], ["84146.42000000", "0.02971000"], ["84146.60000000", "0.00000000"], ["84146.71000000", "0.00000000"], ["84147.07000000", "0.03567000"], ["84147.31000000", "0.00000000"], ["84147.48000000", "0.00000000"], ["84147.76000000", "0.19421000"], ["84147.89000000", "0.00000000"], ["84148.63000000", "0.00084000"], ["84148.64000000", "0.05943000"], ["84149.05000000", "0.35644000"], ["84149.23000000", "0.00000000"], ["84149.26000000", "0.00000000"], ["84149.91000000", "0.00000000"], ["84149.99000000", "0.00000000"], ["84150.05000000", "0.00000000"], ["84150.15000000", "0.00000000"], ["84150.21000000", "0.00000000"], ["84150.51000000", "0.02802000"], ["84150.62000000", "0.05943000"], ["84151.05000000", "0.00000000"], ["84151.08000000", "0.05943000"], ["84151.53000000", "0.12834000"], ["84151.84000000", "0.02971000"], ["84151.99000000", "0.00820000"], ["84152.52000000", "0.00754000"], ["84153.31000000", "0.05817000"], ["84153.36000000", "0.00000000"], ["84153.62000000", "0.00825000"], ["84153.70000000", "0.00000000"], ["84153.74000000", "0.00358000"], ["84154.37000000", "0.00000000"], ["84154.91000000", "0.00000000"], ["84155.05000000", "0.02971000"], ["84155.06000000", "0.00000000"], ["84156.13000000", "0.05943000"], ["84156.93000000", "0.00000000"], ["84157.11000000", "0.05943000"], ["84157.13000000", "0.00000000"], ["84157.14000000", "0.00000000"], ["84157.20000000", "0.00000000"], ["84157.21000000", "0.00000000"], ["84158.01000000", "0.05943000"], ["84158.18000000", "0.00809000"], ["84158.36000000", "0.00000000"], ["84158.44000000", "0.00000000"], ["84158.76000000", "0.11915000"], ["84158.80000000", "0.00000000"], ["84160.29000000", "0.00000000"], ["84160.97000000", "0.00000000"], ["84161.68000000", "0.02983000"], ["84161.80000000", "0.00000000"], ["84162.29000000", "0.81559000"], ["84162.33000000", "0.00000000"], ["84162.42000000", "0.05943000"], ["84162.82000000", "0.00000000"], ["84162.92000000", "0.00000000"], ["84162.93000000", "0.00000000"], ["84163.81000000", "0.00000000"], ["84163.83000000", "0.00000000"], ["84163.85000000", "0.00000000"], ["84164.32000000", "0.00000000"], ["84164.92000000", "0.00594000"], ["84165.07000000", "0.00863000"], ["84165.15000000", "0.02971000"], ["84165.33000000", "0.59407000"], ["84165.75000000", "0.00000000"], ["84166.18000000", "0.00000000"], ["84166.43000000", "0.00000000"], ["84166.69000000", "0.00000000"], ["84167.25000000", "0.00000000"], ["84167.75000000", "0.02923000"], ["84169.82000000", "0.15540000"], ["84169.96000000", "0.00000000"], ["84170.19000000", "0.00000000"], ["84170.39000000", "0.00000000"], ["84170.74000000", "0.00000000"], ["84170.99000000", "0.01196000"], ["84171.28000000", "0.00000000"], ["84171.77000000", "0.00650000"], ["84172.53000000", "0.00000000"], ["84173.56000000", "0.05943000"], ["84174.00000000", "0.47526000"], ["84174.04000000", "0.00000000"], ["84174.54000000", "0.00000000"], ["84175.60000000", "0.11797000"], ["84175.65000000", "0.00000000"], ["84175.74000000", "0.00000000"], ["84176.02000000", "0.00000000"], ["84176.83000000", "0.00000000"], ["84176.94000000", "0.00000000"], ["84177.21000000", "0.00000000"], ["84177.26000000", "0.00000000"], ["84177.38000000", "0.00000000"], ["84178.18000000", "0.00009000"], ["84180.64000000", "0.00000000"], ["84180.76000000", "0.05200000"], ["84180.99000000", "0.00000000"], ["84181.47000000", "0.00000000"], ["84184.46000000", "0.00000000"], ["84186.87000000", "1.12251000"], ["84187.39000000", "0.00358000"], ["84187.99000000", "0.00000000"], ["84189.17000000", "0.00000000"], ["84189.71000000", "0.50187000"], ["84191.05000000", "0.03198000"], ["84191.29000000", "0.00144000"], ["84191.31000000", "0.20101000"], ["84191.81000000", "0.00298000"], ["84192.80000000", "0.00015000"], ["84194.43000000", "0.05239000"], ["84196.41000000", "0.81147000"], ["84196.42000000", "0.00000000"], ["84197.75000000", "0.00041000"], ["84199.16000000", "0.00000000"], ["84200.90000000", "0.00000000"], ["84203.64000000", "0.00084000"], ["84204.96000000", "0.73322000"], ["84205.63000000", "0.00000000"], ["84207.22000000", "0.00000000"], ["84207.50000000", "0.00000000"], ["84207.56000000", "0.00000000"], ["84207.79000000", "0.00000000"], ["84208.39000000", "0.00297000"], ["84208.40000000", "0.00296000"], ["84210.39000000", "0.00000000"], ["84211.83000000", "0.00000000"], ["84215.95000000", "0.00000000"], ["84221.07000000", "0.00000000"], ["84221.30000000", "0.35782000"], ["84221.99000000", "0.00000000"], ["84224.36000000", "0.00000000"], ["84224.98000000", "0.05496000"], ["84228.47000000", "0.05496000"], ["84232.78000000", "0.00000000"], ["84241.20000000", "0.00000000"], ["84249.62000000", "0.00000000"], ["84251.12000000", "0.00000000"], ["84273.53000000", "0.00035000"], ["84273.86000000", "0.00050000"], ["84281.94000000", "0.00000000"], ["84321.61000000", "0.00000000"], ["84332.42000000", "0.00000000"], ["84340.84000000", "0.00000000"], ["84360.66000000", "0.00000000"], ["84363.64000000", "0.00000000"], ["84366.90000000", "0.00000000"], ["84370.59000000", "0.00000000"], ["84462.00000000", "0.00000000"], ["84955.72000000", "0.00000000"], ["85370.40000000", "0.14081000"], ["85385.99000000", "0.00100000"], ["85391.70000000", "0.05871000"], ["85413.00000000", "0.00036000"], ["94094.36000000", "0.01022000"], ["150001.00000000", "0.00080000"]], "record_time": 1742554945.050597, "EXCHANGE": "BINANCE"}
{"e": "depthUpdate", "E": 1742554946014, "s": "BTCUSDT", "U": 64607004009, "u": 64607004269, "b": [["84111.44000000", "2.65374000"], ["84111.07000000", "0.04914000"], ["84110.99000000", "0.00044000"], ["84110.24000000", "0.00007000"], ["84110.00000000", "0.02273000"], ["84109.77000000", "0.00000000"], ["84108.93000000", "0.09453000"], ["84108.60000000", "0.00000000"], ["84107.87000000", "0.00000000"], ["84107.86000000", "0.02395000"], ["84107.39000000", "0.00011000"], ["84105.13000000", "0.00000000"], ["84105.00000000", "0.02396000"], ["84104.02000000", "0.00000000"], ["84101.78000000", "0.00000000"], ["84101.01000000", "0.00089000"], ["84099.87000000", "0.00000000"], ["84098.83000000", "0.01189000"], ["84098.60000000", "0.00000000"], ["84098.50000000", "0.00000000"], ["84097.89000000", "0.00000000"], ["84095.80000000", "0.00000000"], ["84093.78000000", "0.10701000"], ["84089.60000000", "0.00000000"], ["84089.51000000", "0.03567000"], ["84088.00000000", "0.08304000"], ["84087.99000000", "0.00000000"], ["84086.20000000", "0.00300000"], ["84086.03000000", "1.51324000"], ["84077.86000000", "0.00000000"], ["84077.85000000", "0.00000000"], ["84077.32000000", "0.05071000"], ["84076.78000000", "0.00000000"], ["84075.38000000", "0.59472000"], ["84074.10000000", "0.00000000"], ["84073.14000000", "0.00000000"], ["84072.91000000", "0.04942000"], ["84069.38000000", "0.00059000"], ["84068.38000000", "0.00000000"], ["84063.15000000", "0.00000000"], ["84062.05000000", "0.30079000"], ["84059.53000000", "0.85694000"], ["84055.85000000", "0.59381000"], ["84050.38000000", "0.05948000"], ["84038.37000000", "0.00000000"], ["84037.47000000", "0.00000000"], ["84035.17000000", "0.00597000"], ["84026.91000000", "0.46918000"], ["84026.04000000", "0.00895000"], ["84017.73000000", "0.12784000"], ["84012.90000000", "0.14768000"], ["84011.43000000", "0.04636000"], ["84008.13000000", "0.01194000"], ["83999.67000000", "0.04636000"], ["83994.23000000", "0.01493000"], ["83966.38000000", "0.00000000"], ["83949.60000000", "0.05953000"], ["83885.58000000", "0.00400000"], ["83877.88000000", "0.00000000"], ["83868.32000000", "0.00000000"], ["83836.16000000", "0.00008000"], ["82849.76000000", "0.00100000"], ["75779.41000000", "0.00016000"], ["75700.00000000", "6.42624000"], ["67289.16000000", "0.00058000"], ["42000.00000000", "6.85161000"], ["33000.00000000", "2.93827000"], ["20002.00000000", "0.00000000"], ["20001.00000000", "0.02099000"]], "a": [["84111.45000000", "6.39645000"], ["84112.46000000", "0.00000000"], ["84112.76000000", "0.00000000"], ["84113.11000000", "0.00000000"], ["84113.12000000", "0.00000000"], ["84113.60000000", "0.00000000"], ["84114.00000000", "0.02266000"], ["84114.24000000", "0.04823000"], ["84114.55000000", "0.68119000"], ["84114.57000000", "0.00000000"], ["84114.59000000", "2.22282000"], ["84114.96000000", "0.00000000"], ["84115.42000000", "0.00000000"], ["84115.60000000", "0.00500000"], ["84116.00000000", "0.11671000"], ["84116.38000000", "0.00000000"], ["84116.50000000", "0.00000000"], ["84117.71000000", "0.00000000"], ["84117.87000000", "0.00138000"], ["84118.00000000", "0.02266000"], ["84118.01000000", "0.00000000"], ["84118.83000000", "0.04006000"], ["84118.92000000", "0.03362000"], ["84119.52000000", "0.17828000"], ["84119.87000000", "0.00300000"], ["84121.80000000", "0.00006000"], ["84122.05000000", "0.00000000"], ["84122.13000000", "0.00000000"], ["84124.05000000", "0.05957000"], ["84125.39000000", "0.55860000"], ["84125.40000000", "0.08362000"], ["84125.67000000", "0.85627000"], ["84127.36000000", "0.00000000"], ["84128.86000000", "0.00000000"], ["84134.80000000", "0.00000000"], ["84136.20000000", "0.00000000"], ["84139.74000000", "0.00000000"], ["84140.29000000", "0.05000000"], ["84141.30000000", "0.59470000"], ["84141.48000000", "0.12836000"], ["84141.93000000", "0.00100000"], ["84150.00000000", "0.48122000"], ["84150.64000000", "0.00000000"], ["84151.40000000", "0.00000000"], ["84151.53000000", "0.00000000"], ["84153.50000000", "0.00059000"], ["84156.98000000", "0.00000000"], ["84163.96000000", "0.00000000"], ["84171.21000000", "0.03451000"], ["84172.94000000", "0.02379000"], ["84183.84000000", "0.62547000"], ["84189.17000000", "0.04000000"], ["84189.29000000", "0.00000000"], ["84200.22000000", "0.00597000"], ["84206.99000000", "0.12784000"], ["84208.64000000", "0.00895000"], ["84212.40000000", "0.17822000"], ["84217.05000000", "0.01194000"], ["84225.47000000", "0.01493000"], ["84227.39000000", "0.00000000"], ["84233.03000000", "0.00000000"], ["84239.56000000", "0.04197000"], ["84245.73000000", "0.04197000"], ["84258.33000000", "0.04097000"], ["84261.59000000", "0.00000000"], ["84269.68000000", "0.00000000"], ["84439.88000000", "0.00000000"], ["84445.80000000", "0.00000000"], ["85385.99000000", "0.00000000"], ["96666.66000000", "0.08698000"], ["98333.33000000", "0.05335000"], ["100000.00000000", "165.71948000"], ["101666.66000000", "0.05025000"], ["103333.33000000", "0.08284000"], ["105000.00000000", "133.96959000"]], "record_time": 1742554946.036522, "EXCHANGE": "BINANCE"}
{"e": "depthUpdate", "E": 1742554947014, "s": "BTCUSDT", "U": 64607004270, "u": 64607004365, "b": [["84111.44000000", "2.63464000"], ["84108.70000000", "0.00027000"], ["84107.12000000", "0.00000000"], ["84107.11000000", "0.04260000"], ["84103.41000000", "0.00000000"], ["84103.40000000", "0.00000000"], ["84102.32000000", "0.02376000"], ["84094.22000000", "1.31804000"], ["84091.88000000", "0.00000000"], ["84091.44000000", "0.44445000"], ["84089.87000000", "0.00000000"], ["84079.55000000", "0.89111000"], ["84076.66000000", "0.89111000"], ["84076.09000000", "0.59973000"], ["84075.47000000", "0.07669000"], ["84069.01000000", "0.37671000"], ["84063.91000000", "0.00441000"], ["84061.55000000", "0.00000000"], ["84061.26000000", "0.05000000"], ["84047.86000000", "0.14074000"], ["84024.19000000", "0.00100000"], ["84017.50000000", "0.64958000"], ["84017.27000000", "1.38839000"], ["83948.32000000", "0.00000000"], ["83944.32000000", "0.00000000"], ["83943.92000000", "0.01000000"], ["83943.32000000", "0.00000000"], ["83933.30000000", "0.01524000"], ["83865.96000000", "0.00000000"], ["83500.00000000", "12.12901000"], ["83196.44000000", "0.00000000"], ["83193.07000000", "0.00040000"], ["83188.37000000", "0.00000000"], ["83185.00000000", "0.00060000"], ["82859.54000000", "0.00000000"], ["82849.76000000", "0.00000000"], ["80697.27000000", "0.03566000"], ["75779.41000000", "0.00000000"], ["75700.30000000", "0.00032000"], ["75700.00000000", "6.42624000"], ["67289.16000000", "0.00058000"], ["33000.00000000", "2.93827000"]], "a": [["84111.45000000", "6.39563000"], ["84116.50000000", "0.02331000"], ["84119.52000000", "0.17822000"], ["84126.00000000", "0.04623000"], ["84127.62000000", "0.08879000"], ["84131.92000000", "0.00000000"], ["84131.97000000", "0.48646000"], ["84135.43000000", "0.05000000"], ["84136.76000000", "0.89111000"], ["84137.34000000", "0.89111000"], ["84138.20000000", "0.00000000"], ["84140.29000000", "0.00000000"], ["84141.29000000", "0.48591000"], ["84141.40000000", "0.00000000"], ["84145.65000000", "0.00000000"], ["84147.00000000", "0.00006000"], ["84160.61000000", "0.00000000"], ["84162.29000000", "0.00000000"], ["84165.31000000", "0.00000000"], ["84168.47000000", "0.26275000"], ["84169.82000000", "0.16577000"], ["84171.24000000", "0.02379000"], ["84172.94000000", "0.00000000"], ["84175.89000000", "0.03428000"], ["84185.37000000", "0.05977000"], ["84198.69000000", "0.00100000"], ["84217.00000000", "0.00000000"], ["84248.82000000", "0.02496000"], ["84273.86000000", "0.01000000"], ["84303.41000000", "0.00000000"], ["84420.00000000", "0.03815000"], ["85373.13000000", "0.00100000"], ["86300.00000000", "19.53749000"]], "record_time": 1742554947.037251, "EXCHANGE": "BINANCE"}
{"e": "depthUpdate", "E": 1742554948014, "s": "BTCUSDT", "U": 64607004366, "u": 64607004440, "b": [["84111.44000000", "2.75576000"], ["84105.95000000", "0.04817000"], ["84105.00000000", "0.02477000"], ["84103.31000000", "0.00757000"], ["84102.99000000", "0.00000000"], ["84102.32000000", "0.02343000"], ["84101.01000000", "0.00000000"], ["84087.22000000", "0.00880000"], ["84081.96000000", "1.59875000"], ["84072.91000000", "0.00000000"], ["84063.11000000", "0.04942000"], ["84061.26000000", "0.00000000"], ["84058.95000000", "0.85695000"], ["84054.40000000", "0.00000000"], ["83943.92000000", "0.00000000"], ["83942.23000000", "0.00000000"], ["83941.49000000", "0.01862000"], ["83941.43000000", "0.00000000"], ["83941.33000000", "0.01000000"], ["83941.23000000", "0.00000000"], ["83892.26000000", "0.00400000"], ["83885.58000000", "0.00000000"], ["82849.76000000", "0.00100000"], ["82848.26000000", "0.00019000"], ["75700.00000000", "6.42624000"], ["67289.16000000", "0.00058000"], ["33000.00000000", "2.93887000"]], "a": [["84111.45000000", "6.39111000"], ["84114.55000000", "0.49741000"], ["84114.58000000", "0.00014000"], ["84114.59000000", "1.62875000"], ["84115.60000000", "0.00500000"], ["84115.94000000", "0.00754000"], ["84116.50000000", "0.00000000"], ["84116.77000000", "0.02338000"], ["84118.83000000", "0.04000000"], ["84118.92000000", "0.03356000"], ["84122.15000000", "0.00414000"], ["84122.30000000", "0.00000000"], ["84124.23000000", "0.00000000"], ["84128.97000000", "0.01862000"], ["84129.73000000", "0.59407000"], ["84132.87000000", "1.44703000"], ["84134.80000000", "0.00500000"], ["84152.52000000", "0.00000000"], ["84159.04000000", "0.72500000"], ["84165.33000000", "0.00000000"], ["84167.59000000", "0.59407000"], ["84186.86000000", "0.00841000"], ["84204.96000000", "0.72481000"], ["84273.86000000", "0.01000000"], ["84278.12000000", "0.00000000"], ["84281.97000000", "0.99882000"], ["85373.13000000", "0.00000000"]], "record_time": 1742554948.045549, "EXCHANGE": "BINANCE"}
{"e": "depthUpdate", "E": 1742554949014, "s": "BTCUSDT", "U": 64607004441, "u": 64607004651, "b": [["84111.44000000", "3.38033000"], ["84111.43000000", "0.00064000"], ["84111.35000000", "0.00123000"], ["84111.34000000", "0.00007000"], ["84111.32000000", "0.00021000"], ["84111.31000000", "0.02585000"], ["84111.30000000", "0.00007000"], ["84111.29000000", "0.00007000"], ["84111.28000000", "0.00000000"], ["84111.12000000", "0.00132000"], ["84111.08000000", "0.00000000"], ["84111.07000000", "0.00006000"], ["84111.06000000", "0.00000000"], ["84111.05000000", "0.00000000"], ["84110.99000000", "0.00037000"], ["84110.01000000", "0.00014000"], ["84110.00000000", "0.02267000"], ["84108.94000000", "0.00000000"], ["84108.93000000", "0.00000000"], ["84107.87000000", "0.00014000"], ["84107.86000000", "0.02395000"], ["84107.25000000", "0.00000000"], ["84107.12000000", "0.00014000"], ["84107.11000000", "0.04267000"], ["84105.96000000", "0.00007000"], ["84102.69000000", "0.00007000"], ["84101.77000000", "0.00000000"], ["84101.75000000", "0.00118000"], ["84101.73000000", "0.00091000"], ["84099.87000000", "0.05940000"], ["84072.02000000", "0.68375000"], ["84071.65000000", "0.85682000"], ["84064.98000000", "0.05000000"], ["84058.95000000", "0.00000000"], ["84006.05000000", "1.22804000"], ["84003.24000000", "1.50897000"], ["83975.90000000", "0.01862000"], ["83941.49000000", "0.00000000"], ["83941.33000000", "0.00000000"], ["83941.23000000", "0.01000000"], ["83933.30000000", "0.00000000"], ["83931.67000000", "0.01524000"], ["83904.19000000", "0.00400000"], ["83892.26000000", "0.00000000"], ["83193.07000000", "0.00000000"], ["83187.06000000", "0.00040000"], ["83185.00000000", "0.00000000"], ["83179.00000000", "0.00060000"], ["82849.76000000", "0.00000000"], ["75700.00000000", "6.42624000"], ["67289.16000000", "0.00058000"], ["60000.00000000", "73.17018000"], ["33000.00000000", "2.93827000"], ["30280.12000000", "0.00020000"]], "a": [["84114.00000000", "0.02260000"], ["84114.23000000", "0.00000000"], ["84114.24000000", "0.00006000"], ["84114.59000000", "1.24768000"], ["84116.77000000", "0.00000000"], ["84117.57000000", "0.00008000"], ["84117.70000000", "0.04817000"], ["84123.16000000", "0.35644000"], ["84128.97000000", "0.00000000"], ["84146.58000000", "0.41651000"], ["84155.98000000", "0.25103000"], ["84168.61000000", "0.01862000"], ["84171.24000000", "0.00000000"], ["84175.25000000", "0.03428000"], ["84175.89000000", "0.00000000"], ["84187.37000000", "0.46487000"], ["84188.74000000", "0.02379000"], ["84203.89000000", "1.10939000"], ["84273.86000000", "0.01000000"], ["85373.13000000", "0.00100000"]], "record_time": 1742554949.046164, "EXCHANGE": "BINANCE"}
{"e": "depthUpdate", "E": 1742554950014, "s": "BTCUSDT", "U": 64607004652, "u": 64607004881, "b": [["84111.44000000", "4.04245000"], ["84111.43000000", "0.00064000"], ["84111.37000000", "0.00021000"], ["84111.36000000", "0.06622000"], ["84111.35000000", "0.11743000"], ["84111.32000000", "0.00007000"], ["84111.31000000", "0.00007000"], ["84111.30000000", "0.00000000"], ["84111.29000000", "0.00000000"], ["84110.70000000", "0.00011000"], ["84110.01000000", "0.00000000"], ["84110.00000000", "0.02267000"], ["84108.72000000", "0.00000000"], ["84108.71000000", "0.04853000"], ["84107.87000000", "0.00000000"], ["84107.86000000", "0.02388000"], ["84107.39000000", "0.00000000"], ["84107.16000000", "0.00000000"], ["84107.15000000", "0.11160000"], ["84107.14000000", "0.16221000"], ["84107.12000000", "0.00000000"], ["84107.11000000", "0.00000000"], ["84106.65000000", "0.00000000"], ["84106.64000000", "0.05940000"], ["84105.96000000", "0.00000000"], ["84105.95000000", "0.00000000"], ["84104.31000000", "0.00000000"], ["84102.69000000", "0.00000000"], ["84102.68000000", "0.24824000"], ["84102.65000000", "0.00000000"], ["84101.74000000", "0.00000000"], ["84101.73000000", "0.00000000"], ["84099.52000000", "0.00000000"], ["84098.83000000", "0.00000000"], ["84097.40000000", "0.08304000"], ["84095.80000000", "0.00500000"], ["84095.02000000", "0.78520000"], ["84094.22000000", "0.92316000"], ["84093.07000000", "0.00000000"], ["84089.88000000", "0.65680000"], ["84087.22000000", "0.00000000"], ["84081.97000000", "0.00000000"], ["84079.15000000", "0.59471000"], ["84076.09000000", "0.00000000"], ["84075.38000000", "0.00000000"], ["84064.98000000", "0.00000000"], ["84064.24000000", "0.64035000"], ["84058.80000000", "0.00006000"], ["84058.17000000", "0.59407000"], ["84056.00000000", "0.00235000"], ["84051.68000000", "0.00000000"], ["83975.90000000", "0.00000000"], ["83950.97000000", "0.00678000"], ["83931.67000000", "0.00000000"], ["83921.51000000", "0.00400000"], ["83915.35000000", "0.00000000"], ["83904.19000000", "0.00000000"], ["82849.76000000", "0.00100000"], ["79900.00000000", "5.57490000"], ["75700.00000000", "6.42624000"], ["67289.16000000", "0.00058000"], ["33000.00000000", "2.93827000"]], "a": [["84111.45000000", "4.79214000"], ["84111.47000000", "0.00039000"], ["84112.44000000", "0.00014000"], ["84112.45000000", "0.16171000"], ["84113.99000000", "0.00000000"], ["84114.55000000", "0.33769000"], ["84114.59000000", "1.09656000"], ["84115.60000000", "0.00000000"], ["84116.00000000", "0.18394000"], ["84116.39000000", "0.00000000"], ["84117.62000000", "0.00011000"], ["84117.70000000", "0.00000000"], ["84118.00000000", "0.02260000"], ["84118.31000000", "0.02448000"], ["84118.92000000", "0.00000000"], ["84119.69000000", "0.15112000"], ["84120.85000000", "0.04817000"], ["84121.93000000", "0.00095000"], ["84124.05000000", "0.02377000"], ["84125.39000000", "0.34848000"], ["84125.40000000", "0.04782000"], ["84125.67000000", "0.00000000"], ["84128.27000000", "0.00000000"], ["84131.96000000", "0.00000000"], ["84133.46000000", "0.00000000"], ["84133.98000000", "0.71284000"], ["84134.80000000", "0.00500000"], ["84135.43000000", "0.00000000"], ["84136.68000000", "0.05940000"], ["84139.40000000", "0.85613000"], ["84141.30000000", "0.00000000"], ["84142.79000000", "0.00000000"], ["84142.84000000", "0.05000000"], ["84145.24000000", "0.59470000"], ["84146.25000000", "0.00000000"], ["84149.18000000", "0.00678000"], ["84150.51000000", "0.00000000"], ["84153.79000000", "0.47336000"], ["84153.93000000", "0.11880000"], ["84154.36000000", "0.02802000"], ["84158.76000000", "0.00000000"], ["84168.61000000", "0.00000000"], ["84175.25000000", "0.00000000"], ["84250.03000000", "0.02496000"], ["84952.55000000", "0.00000000"], ["85373.13000000", "0.00000000"]], "record_time": 1742554950.035456, "EXCHANGE": "BINANCE"}
{"e": "depthUpdate", "E": 1742554951014, "s": "BTCUSDT", "U": 64607004882, "u": 64607005032, "b": [["84111.44000000", "3.32691000"], ["84111.36000000", "0.06608000"], ["84111.35000000", "0.00007000"], ["84110.76000000", "0.00014000"], ["84110.75000000", "0.07831000"], ["84110.00000000", "0.02267000"], ["84109.31000000", "0.02146000"], ["84108.71000000", "0.04846000"], ["84107.86000000", "0.02388000"], ["84106.64000000", "0.00000000"], ["84105.00000000", "0.00006000"], ["84104.53000000", "0.00000000"], ["84104.31000000", "0.00000000"], ["84102.32000000", "0.00000000"], ["84101.43000000", "0.00096000"], ["84101.41000000", "0.02377000"], ["84101.20000000", "0.00000000"], ["84100.62000000", "0.00092000"], ["84100.29000000", "0.00419000"], ["84098.84000000", "0.00000000"], ["84096.77000000", "0.00260000"], ["84095.02000000", "0.00000000"], ["84094.59000000", "0.78520000"], ["84087.22000000", "0.00896000"], ["84079.15000000", "0.00000000"], ["84076.67000000", "0.97060000"], ["84076.09000000", "0.59472000"], ["84075.59000000", "0.00000000"], ["84070.82000000", "0.00000000"], ["84064.05000000", "0.00000000"], ["84062.03000000", "0.85692000"], ["84059.53000000", "0.00000000"], ["83929.78000000", "0.00000000"], ["83921.51000000", "0.00000000"], ["83915.06000000", "0.00400000"], ["83188.71000000", "0.00040000"], ["83187.06000000", "0.00000000"], ["83181.47000000", "0.00060000"], ["83179.00000000", "0.00000000"], ["82849.76000000", "0.00000000"], ["80000.00000000", "154.95510000"], ["75700.00000000", "6.42624000"], ["67289.16000000", "0.00058000"], ["33000.00000000", "2.93827000"], ["20002.00000000", "0.00000000"], ["20001.00000000", "0.02099000"]], "a": [["84111.45000000", "5.82973000"], ["84112.44000000", "0.00000000"], ["84112.45000000", "0.00000000"], ["84112.76000000", "0.00000000"], ["84113.99000000", "0.00014000"], ["84114.24000000", "0.00000000"], ["84114.55000000", "0.20119000"], ["84114.58000000", "0.00014000"], ["84114.59000000", "0.64656000"], ["84116.77000000", "0.02412000"], ["84118.18000000", "0.04817000"], ["84120.85000000", "0.00000000"], ["84121.90000000", "0.00000000"], ["84121.93000000", "0.00000000"], ["84123.31000000", "0.00000000"], ["84124.05000000", "0.00000000"], ["84124.34000000", "0.00901000"], ["84125.39000000", "0.54588000"], ["84125.97000000", "0.85627000"], ["84126.31000000", "0.00000000"], ["84127.12000000", "0.00000000"], ["84136.67000000", "0.00000000"], ["84136.93000000", "2.46794000"], ["84139.40000000", "0.00000000"], ["84139.97000000", "0.59473000"], ["84141.29000000", "0.00000000"], ["84145.24000000", "0.00000000"], ["84164.33000000", "0.00000000"], ["84167.58000000", "0.46490000"], ["84168.47000000", "0.00000000"], ["84173.57000000", "0.03609000"], ["84186.86000000", "0.00000000"], ["84190.75000000", "0.00841000"], ["84203.89000000", "0.00015000"], ["85373.13000000", "0.00100000"]], "record_time": 1742554951.039522, "EXCHANGE": "BINANCE"}
{"e": "depthUpdate", "E": 1742554952014, "s": "BTCUSDT", "U": 64607005033, "u": 64607005327, "b": [["84111.44000000", "0.88631000"], ["84111.43000000", "0.00064000"], ["84111.39000000", "0.00015000"], ["84111.37000000", "0.00007000"], ["84111.36000000", "0.00007000"], ["84111.32000000", "0.00007000"], ["84111.31000000", "0.00000000"], ["84111.29000000", "0.00000000"], ["84111.28000000", "0.00000000"], ["84110.99000000", "0.00037000"], ["84110.76000000", "0.00000000"], ["84110.75000000", "0.00000000"], ["84110.71000000", "0.00000000"], ["84110.70000000", "0.00000000"], ["84110.67000000", "0.00014000"], ["84110.66000000", "0.01174000"], ["84110.02000000", "0.00000000"], ["84110.01000000", "0.00014000"], ["84110.00000000", "0.02267000"], ["84109.31000000", "0.00000000"], ["84108.72000000", "0.00000000"], ["84108.71000000", "0.00029000"], ["84108.60000000", "0.00300000"], ["84107.87000000", "0.00014000"], ["84107.86000000", "0.02395000"], ["84107.69000000", "0.00000000"], ["84107.16000000", "0.00014000"], ["84107.15000000", "0.08294000"], ["84105.13000000", "0.00011000"], ["84104.83000000", "0.04817000"], ["84104.72000000", "0.00000000"], ["84104.49000000", "0.00000000"], ["84101.72000000", "0.00091000"], ["84101.43000000", "0.00000000"], ["84101.42000000", "0.00096000"], ["84101.41000000", "0.00000000"], ["84101.40000000", "0.00000000"], ["84100.83000000", "0.00090000"], ["84100.80000000", "0.00006000"], ["84100.44000000", "0.00000000"], ["84099.87000000", "0.00000000"], ["84098.60000000", "0.00000000"], ["84098.50000000", "0.00000000"], ["84097.52000000", "0.00000000"], ["84097.41000000", "0.00000000"], ["84096.43000000", "0.78519000"], ["84096.40000000", "0.00000000"], ["84095.80000000", "0.00000000"], ["84094.59000000", "0.00000000"], ["84094.22000000", "0.92316000"], ["84086.81000000", "0.00935000"], ["84084.67000000", "0.01870000"], ["84076.09000000", "0.00000000"], ["84075.73000000", "0.85678000"], ["84075.63000000", "0.00000000"], ["84075.37000000", "0.05497000"], ["84074.58000000", "0.10994000"], ["84073.37000000", "0.00000000"], ["84072.65000000", "0.00000000"], ["84072.03000000", "0.59475000"], ["84068.37000000", "0.81845000"], ["84063.91000000", "0.00000000"], ["84062.26000000", "0.00000000"], ["84062.03000000", "0.00000000"], ["84059.00000000", "0.00000000"], ["84058.09000000", "0.09634000"], ["83997.46000000", "0.00000000"], ["83997.06000000", "0.04637000"], ["83996.84000000", "0.05496000"], ["83993.83000000", "0.00075000"], ["83991.51000000", "0.05496000"], ["83988.12000000", "0.05197000"], ["83986.07000000", "0.10394000"], ["83978.57000000", "0.18312000"], ["83976.31000000", "0.09294000"], ["83920.59000000", "0.00000000"], ["83917.49000000", "0.00063000"], ["83915.06000000", "0.00000000"], ["83895.41000000", "0.00400000"], ["82849.76000000", "0.00100000"], ["75700.00000000", "6.42644000"], ["67289.16000000", "0.00058000"], ["33000.00000000", "2.93827000"]], "a": [["84111.45000000", "6.05942000"], ["84112.27000000", "0.00011000"], ["84114.93000000", "0.00000000"], ["84115.38000000", "0.04817000"], ["84115.60000000", "0.00500000"], ["84116.77000000", "0.02354000"], ["84117.62000000", "0.00000000"], ["84118.18000000", "0.00000000"], ["84119.59000000", "0.00031000"], ["84122.06000000", "0.60051000"], ["84122.15000000", "0.00000000"], ["84122.26000000", "0.85630000"], ["84124.12000000", "0.01783000"], ["84128.69000000", "0.71284000"], ["84131.96000000", "0.59476000"], ["84134.80000000", "0.00000000"], ["84135.73000000", "0.94111000"], ["84138.28000000", "0.00000000"], ["84139.97000000", "0.00000000"], ["84141.30000000", "0.00000000"], ["84141.47000000", "0.26743000"], ["84142.84000000", "0.00000000"], ["84151.40000000", "0.00000000"], ["84159.67000000", "0.01196000"], ["84170.99000000", "0.00000000"], ["84180.48000000", "0.02379000"], ["84188.74000000", "0.00000000"], ["84281.97000000", "0.00000000"], ["84282.08000000", "0.99692000"], ["84721.43000000", "0.00060000"], ["84736.34000000", "0.00060000"], ["84747.81000000", "0.00000000"], ["84762.73000000", "0.00000000"], ["85373.13000000", "0.00000000"], ["86500.00000000", "21.87016000"], ["95000.00000000", "226.43904000"]], "record_time": 1742554952.035792, "EXCHANGE": "BINANCE"}
{"e": "depthUpdate", "E": 1742554953014, "s": "BTCUSDT", "U": 64607005328, "u": 64607006080, "b": [["84111.44000000", "0.00000000"], ["84111.43000000", "0.00000000"], ["84111.39000000", "0.00000000"], ["84111.37000000", "0.00000000"], ["84111.36000000", "0.00000000"], ["84111.35000000", "0.00000000"], ["84111.34000000", "0.00000000"], ["84111.32000000", "0.00000000"], ["84111.12000000", "0.00000000"], ["84111.08000000", "0.00000000"], ["84111.07000000", "0.00000000"], ["84110.99000000", "0.00000000"], ["84110.67000000", "0.00000000"], ["84110.66000000", "0.00000000"], ["84110.24000000", "0.00000000"], ["84110.01000000", "0.00000000"], ["84110.00000000", "0.00000000"], ["84109.39000000", "0.00000000"], ["84108.71000000", "0.00000000"], ["84108.70000000", "0.00000000"], ["84108.69000000", "0.00000000"], ["84108.68000000", "0.00000000"], ["84108.60000000", "0.00000000"], ["84107.87000000", "0.00000000"], ["84107.86000000", "0.00000000"], ["84107.70000000", "0.00000000"], ["84107.16000000", "0.00000000"], ["84107.15000000", "1.16513000"], ["84107.14000000", "0.00069000"], ["84107.08000000", "0.00209000"], ["84106.88000000", "0.00007000"], ["84106.86000000", "0.00007000"], ["84106.73000000", "0.00007000"], ["84106.72000000", "0.00307000"], ["84106.58000000", "0.00021000"], ["84106.57000000", "0.13314000"], ["84106.56000000", "0.15284000"], ["84106.54000000", "0.00009000"], ["84106.39000000", "0.00101000"], ["84106.00000000", "0.02267000"], ["84105.22000000", "0.00006000"], ["84105.15000000", "0.00014000"], ["84105.14000000", "0.27128000"], ["84105.13000000", "0.00000000"], ["84104.88000000", "0.00370000"], ["84104.83000000", "0.00000000"], ["84104.67000000", "0.00000000"], ["84104.10000000", "0.00000000"], ["84103.71000000", "0.00000000"], ["84103.70000000", "0.00000000"], ["84103.60000000", "0.02373000"], ["84103.52000000", "0.09162000"], ["84103.31000000", "0.00000000"], ["84103.20000000", "0.08000000"], ["84102.68000000", "0.24824000"], ["84102.57000000", "0.00019000"], ["84102.38000000", "0.00000000"], ["84102.29000000", "0.16221000"], ["84102.06000000", "0.00000000"], ["84102.05000000", "0.04817000"], ["84101.88000000", "0.00000000"], ["84101.87000000", "0.00000000"], ["84101.86000000", "0.02482000"], ["84101.76000000", "0.02205000"], ["84101.75000000", "0.00000000"], ["84101.72000000", "0.00000000"], ["84101.60000000", "0.00000000"], ["84100.83000000", "0.00000000"], ["84100.38000000", "0.00759000"], ["84098.73000000", "0.45000000"], ["84097.78000000", "0.00088000"], ["84097.76000000", "0.00145000"], ["84097.75000000", "0.45599000"], ["84097.74000000", "0.00000000"], ["84097.70000000", "0.00000000"], ["84097.41000000", "0.00000000"], ["84097.40000000", "0.00000000"], ["84097.38000000", "0.00000000"], ["84097.27000000", "0.00000000"], ["84096.43000000", "0.00000000"], ["84095.96000000", "0.78519000"], ["84094.21000000", "0.00000000"], ["84093.78000000", "0.00000000"], ["84093.47000000", "0.10701000"], ["84093.44000000", "0.01188000"], ["84092.69000000", "0.00000000"], ["84091.44000000", "0.00000000"], ["84089.98000000", "0.00000000"], ["84089.85000000", "0.00000000"], ["84089.81000000", "0.00000000"], ["84089.77000000", "0.00000000"], ["84089.51000000", "0.00000000"], ["84089.48000000", "0.00000000"], ["84088.65000000", "0.00029000"], ["84087.76000000", "0.00118000"], ["84087.72000000", "0.00000000"], ["84087.59000000", "0.00000000"], ["84087.41000000", "0.00000000"], ["84087.40000000", "0.00000000"], ["84087.34000000", "0.00000000"], ["84087.29000000", "0.03568000"], ["84087.22000000", "0.00000000"], ["84086.54000000", "0.00889000"], ["84085.30000000", "0.12187000"], ["84081.91000000", "0.05785000"], ["84081.35000000", "0.00504000"], ["84080.79000000", "0.05940000"], ["84079.16000000", "0.00000000"], ["84077.32000000", "0.00000000"], ["84077.22000000", "0.89111000"], ["84076.67000000", "0.64760000"], ["84075.73000000", "0.00000000"], ["84075.38000000", "0.85678000"], ["84075.37000000", "0.00000000"], ["84074.58000000", "0.00000000"], ["84072.04000000", "0.00213000"], ["84069.38000000", "0.00000000"], ["84068.15000000", "0.00000000"], ["84067.04000000", "0.05071000"], ["84066.68000000", "0.00000000"], ["84065.09000000", "0.00059000"], ["84063.22000000", "0.00000000"], ["84062.26000000", "0.00000000"], ["84056.24000000", "0.00297000"], ["84055.12000000", "0.00000000"], ["84053.79000000", "0.00000000"], ["84053.78000000", "0.00013000"], ["84052.69000000", "0.00000000"], ["84052.28000000", "0.00000000"], ["84046.78000000", "0.00000000"], ["84046.35000000", "0.00297000"], ["84042.17000000", "0.00809000"], ["84017.50000000", "0.23306000"], ["84017.27000000", "0.00000000"], ["83995.59000000", "0.05496000"], ["83993.84000000", "0.00000000"], ["83993.83000000", "0.00000000"], ["83989.47000000", "0.00075000"], ["83989.46000000", "0.05496000"], ["83987.65000000", "0.05496000"], ["83987.60000000", "0.00000000"], ["83980.22000000", "0.00172000"], ["83974.94000000", "0.04897000"], ["83970.89000000", "0.04197000"], ["83970.00000000", "0.04197000"], ["83969.98000000", "0.04197000"], ["83955.96000000", "0.00006000"], ["83940.15000000", "0.00008000"], ["83917.50000000", "0.00000000"], ["83917.49000000", "0.00000000"], ["83910.65000000", "0.00063000"], ["83902.64000000", "0.07150000"], ["83895.41000000", "0.00000000"], ["83894.23000000", "0.05555000"], ["83889.37000000", "0.00000000"], ["83887.98000000", "0.00000000"], ["83885.82000000", "0.06793000"], ["83883.63000000", "0.00000000"], ["83876.45000000", "0.00400000"], ["83872.22000000", "0.00013000"], ["83869.88000000", "0.00000000"], ["83863.24000000", "0.80000000"], ["83857.39000000", "0.00000000"], ["83835.34000000", "0.45000000"], ["83112.60000000", "0.00000000"], ["83069.99000000", "0.00000000"], ["83000.53000000", "0.00000000"], ["82849.76000000", "0.00000000"], ["82336.30000000", "0.00042000"], ["75700.00000000", "6.42624000"], ["67289.16000000", "0.00000000"], ["67285.72000000", "0.00058000"], ["33000.00000000", "2.93827000"]], "a": [["84107.16000000", "7.92234000"], ["84107.17000000", "0.00039000"], ["84107.68000000", "0.00202000"], ["84107.69000000", "0.00000000"], ["84107.87000000", "0.00000000"], ["84107.98000000", "0.00014000"], ["84107.99000000", "0.18408000"], ["84108.00000000", "0.02266000"], ["84108.61000000", "0.00000000"], ["84108.69000000", "0.00000000"], ["84108.71000000", "0.00000000"], ["84109.99000000", "0.00000000"], ["84110.00000000", "0.02266000"], ["84110.01000000", "0.00000000"], ["84110.09000000", "0.00011000"], ["84110.45000000", "0.00000000"], ["84110.67000000", "0.00000000"], ["84110.71000000", "0.00009000"], ["84110.72000000", "0.02382000"], ["84111.00000000", "0.00000000"], ["84111.09000000", "0.00000000"], ["84111.15000000", "0.00000000"], ["84111.33000000", "0.00000000"], ["84111.35000000", "0.00000000"], ["84111.36000000", "0.00000000"], ["84111.37000000", "0.00000000"], ["84111.38000000", "0.00000000"], ["84111.40000000", "0.00000000"], ["84111.43000000", "0.00000000"], ["84111.44000000", "0.00773000"], ["84111.45000000", "0.55325000"], ["84111.46000000", "0.00000000"], ["84112.06000000", "0.04823000"], ["84112.27000000", "0.00000000"], ["84112.76000000", "0.00000000"], ["84113.99000000", "0.00000000"], ["84114.00000000", "0.02266000"], ["84114.54000000", "0.00000000"], ["84114.55000000", "0.14594000"], ["84114.58000000", "0.00000000"], ["84114.59000000", "0.32506000"], ["84114.77000000", "0.15112000"], ["84114.98000000", "0.00000000"], ["84115.38000000", "0.00000000"], ["84115.94000000", "0.00000000"], ["84115.99000000", "0.00000000"], ["84116.00000000", "0.11665000"], ["84116.64000000", "0.00118000"], ["84116.77000000", "0.02354000"], ["84117.66000000", "0.00013000"], ["84117.83000000", "0.00831000"], ["84117.87000000", "0.00000000"], ["84119.24000000", "0.00009000"], ["84119.69000000", "0.00000000"], ["84121.41000000", "0.08992000"], ["84124.06000000", "0.00000000"], ["84124.11000000", "0.00377000"], ["84124.65000000", "0.00000000"], ["84126.08000000", "0.00007000"], ["84127.62000000", "0.00000000"], ["84129.14000000", "0.00000000"], ["84130.00000000", "0.00000000"], ["84131.96000000", "0.00000000"], ["84132.00000000", "0.00000000"], ["84132.39000000", "0.11880000"], ["84135.06000000", "0.19424000"], ["84135.55000000", "0.00000000"], ["84135.72000000", "0.59476000"], ["84135.73000000", "0.89111000"], ["84136.68000000", "0.00000000"], ["84138.79000000", "0.05000000"], ["84142.15000000", "0.00000000"], ["84144.33000000", "0.00000000"], ["84145.80000000", "0.02802000"], ["84147.74000000", "0.34921000"], ["84147.87000000", "0.35644000"], ["84148.47000000", "0.00000000"], ["84148.97000000", "0.00000000"], ["84149.05000000", "0.00000000"], ["84149.21000000", "0.00059000"], ["84153.50000000", "0.00000000"], ["84153.74000000", "0.01028000"], ["84154.36000000", "0.00000000"], ["84156.71000000", "0.00000000"], ["84157.76000000", "0.03451000"], ["84160.28000000", "0.03609000"], ["84163.74000000", "0.59407000"], ["84164.13000000", "0.00000000"], ["84164.17000000", "0.00000000"], ["84164.86000000", "0.00000000"], ["84167.58000000", "0.28667000"], ["84167.59000000", "0.00000000"], ["84171.21000000", "0.00000000"], ["84173.57000000", "0.00000000"], ["84185.37000000", "0.00000000"], ["84191.28000000", "0.00296000"], ["84192.58000000", "0.00000000"], ["84208.40000000", "0.00000000"], ["84218.87000000", "0.11486000"], ["84243.97000000", "0.00000000"], ["84332.41000000", "0.00000000"], ["84356.46000000", "0.00000000"], ["85368.77000000", "0.00100000"], ["150001.00000000", "0.00084000"]], "record_time": 1742554953.044191, "EXCHANGE": "BINANCE"}
{"e": "depthUpdate", "E": 1742554954014, "s": "BTCUSDT", "U": 64607006081, "u": 64607006165, "b": [["84107.15000000", "1.32227000"], ["84106.72000000", "0.00007000"], ["84106.57000000", "0.20066000"], ["84106.56000000", "0.15284000"], ["84106.18000000", "0.00014000"], ["84106.17000000", "0.34601000"], ["84106.00000000", "0.02267000"], ["84105.15000000", "0.00000000"], ["84105.14000000", "0.00000000"], ["84102.90000000", "0.00500000"], ["84101.42000000", "0.00000000"], ["84100.38000000", "0.00000000"], ["84098.73000000", "0.45000000"], ["84098.37000000", "0.00000000"], ["84097.49000000", "0.00000000"], ["84097.25000000", "0.00756000"], ["84097.24000000", "0.00094000"], ["84093.47000000", "0.00000000"], ["84092.44000000", "0.04000000"], ["84086.52000000", "0.36345000"], ["84081.91000000", "0.06085000"], ["84077.23000000", "1.24958000"], ["84076.67000000", "0.00000000"], ["84057.05000000", "0.00000000"], ["84030.25000000", "0.00000000"], ["83941.23000000", "0.01000000"], ["83880.00000000", "0.00242000"], ["83188.71000000", "0.00000000"], ["83181.83000000", "0.00060000"], ["82845.54000000", "0.00100000"], ["75696.00000000", "0.03441000"], ["67285.72000000", "0.00058000"], ["33000.00000000", "2.93827000"]], "a": [["84107.16000000", "7.23483000"], ["84111.40000000", "0.00500000"], ["84111.44000000", "0.00780000"], ["84115.60000000", "0.00000000"], ["84117.83000000", "0.00000000"], ["84123.70000000", "0.20949000"], ["84123.99000000", "0.00300000"], ["84130.23000000", "0.00831000"], ["84142.23000000", "0.00000000"], ["84163.73000000", "0.32816000"], ["84273.86000000", "0.01000000"], ["84431.56000000", "0.00000000"], ["84728.45000000", "0.00040000"], ["84736.34000000", "0.00000000"], ["85368.77000000", "0.00000000"]], "record_time": 1742554954.048861, "EXCHANGE": "BINANCE"}
{"e": "depthUpdate", "E": 1742554955014, "s": "BTCUSDT", "U": 64607006166, "u": 64607009928, "b": [["84107.15000000", "0.00000000"], ["84107.14000000", "0.00000000"], ["84107.08000000", "0.00000000"], ["84106.88000000", "0.00000000"], ["84106.86000000", "0.00000000"], ["84106.73000000", "0.00000000"], ["84106.72000000", "0.00000000"], ["84106.58000000", "0.00000000"], ["84106.57000000", "0.00000000"], ["84106.56000000", "0.00000000"], ["84106.54000000", "0.00000000"], ["84106.39000000", "0.00000000"], ["84106.18000000", "0.00000000"], ["84106.17000000", "0.00000000"], ["84106.12000000", "0.00000000"], ["84106.02000000", "0.00000000"], ["84106.00000000", "0.00000000"], ["84105.22000000", "0.00000000"], ["84105.17000000", "0.00000000"], ["84105.00000000", "0.00000000"], ["84104.89000000", "0.00000000"], ["84104.88000000", "0.00000000"], ["84104.85000000", "0.00000000"], ["84104.33000000", "0.00000000"], ["84103.61000000", "0.00000000"], ["84103.60000000", "0.00000000"], ["84103.52000000", "0.00000000"], ["84103.49000000", "0.00000000"], ["84103.21000000", "0.00000000"], ["84103.20000000", "0.00000000"], ["84102.99000000", "0.00000000"], ["84102.91000000", "0.00000000"], ["84102.90000000", "0.00000000"], ["84102.69000000", "0.00000000"], ["84102.68000000", "0.00000000"], ["84102.67000000", "0.00000000"], ["84102.65000000", "0.00000000"], ["84102.64000000", "0.00000000"], ["84102.57000000", "0.00000000"], ["84102.30000000", "0.00000000"], ["84102.29000000", "0.00000000"], ["84102.05000000", "0.00000000"], ["84101.86000000", "0.00000000"], ["84101.76000000", "0.00000000"], ["84101.69000000", "0.00000000"], ["84101.59000000", "0.00000000"], ["84101.34000000", "0.00000000"], ["84101.33000000", "0.00000000"], ["84100.95000000", "0.00000000"], ["84100.80000000", "0.00000000"], ["84100.75000000", "0.00000000"], ["84100.62000000", "0.00000000"], ["84100.46000000", "0.00000000"], ["84100.30000000", "0.00000000"], ["84100.29000000", "0.00000000"], ["84100.26000000", "0.00000000"], ["84100.25000000", "0.00000000"], ["84100.16000000", "0.00000000"], ["84100.15000000", "0.00000000"], ["84100.12000000", "0.00000000"], ["84100.11000000", "0.00000000"], ["84100.00000000", "0.00000000"], ["84099.84000000", "0.00000000"], ["84099.69000000", "0.00000000"], ["84099.68000000", "0.00000000"], ["84099.61000000", "0.00000000"], ["84099.60000000", "0.00000000"], ["84099.27000000", "0.00000000"], ["84098.91000000", "0.00000000"], ["84098.90000000", "0.00000000"], ["84098.89000000", "0.00000000"], ["84098.85000000", "0.00000000"], ["84098.73000000", "0.00000000"], ["84098.42000000", "0.00000000"], ["84098.39000000", "0.00000000"], ["84098.12000000", "0.00000000"], ["84098.10000000", "0.00000000"], ["84097.98000000", "0.00000000"], ["84097.78000000", "0.00000000"], ["84097.76000000", "0.00000000"], ["84097.75000000", "0.00000000"], ["84097.39000000", "0.00000000"], ["84097.37000000", "0.00000000"], ["84097.28000000", "0.00000000"], ["84097.27000000", "0.00000000"], ["84097.26000000", "0.00000000"], ["84097.25000000", "0.00000000"], ["84097.24000000", "0.00000000"], ["84096.78000000", "0.00000000"], ["84096.77000000", "0.00000000"], ["84096.60000000", "0.00000000"], ["84096.55000000", "0.00000000"], ["84096.31000000", "0.00000000"], ["84096.30000000", "0.00000000"], ["84096.29000000", "0.18816000"], ["84096.28000000", "0.00048000"], ["84096.17000000", "0.00000000"], ["84095.97000000", "0.00000000"], ["84095.96000000", "0.00000000"], ["84095.85000000", "0.00000000"], ["84095.81000000", "0.00015000"], ["84095.73000000", "0.00000000"], ["84095.72000000", "0.00000000"], ["84095.70000000", "0.00000000"], ["84095.63000000", "0.00000000"], ["84095.58000000", "0.00000000"], ["84095.55000000", "0.00000000"], ["84095.54000000", "0.00000000"], ["84095.53000000", "0.00000000"], ["84095.47000000", "0.00000000"], ["84095.42000000", "0.00035000"], ["84095.41000000", "0.15020000"], ["84095.40000000", "0.00007000"], ["84095.39000000", "0.00007000"], ["84095.38000000", "0.00007000"], ["84095.37000000", "0.00000000"], ["84095.29000000", "0.00000000"], ["84095.20000000", "0.00000000"], ["84095.19000000", "0.00370000"], ["84095.05000000", "0.00000000"], ["84094.84000000", "0.00000000"], ["84094.80000000", "0.00000000"], ["84094.70000000", "0.00000000"], ["84094.69000000", "0.00000000"], ["84094.65000000", "0.00000000"], ["84094.58000000", "0.00000000"], ["84094.57000000", "0.00000000"], ["84094.44000000", "0.00000000"], ["84094.35000000", "0.00031000"], ["84094.32000000", "0.00000000"], ["84094.31000000", "0.00000000"], ["84094.30000000", "0.00000000"], ["84094.29000000", "0.00000000"], ["84094.23000000", "0.00000000"], ["84094.22000000", "0.00000000"], ["84094.20000000", "0.00000000"], ["84094.17000000", "0.00000000"], ["84094.06000000", "0.00000000"], ["84093.69000000", "0.00000000"], ["84093.65000000", "0.00000000"], ["84093.49000000", "0.00000000"], ["84093.44000000", "0.00000000"], ["84093.38000000", "0.00000000"], ["84093.29000000", "0.00014000"], ["84093.28000000", "0.02219000"], ["84093.23000000", "0.00092000"], ["84093.16000000", "0.00000000"], ["84092.99000000", "0.00000000"], ["84092.97000000", "0.00000000"], ["84092.85000000", "0.00000000"], ["84092.79000000", "0.00014000"], ["84092.78000000", "0.30711000"], ["84092.72000000", "0.00014000"], ["84092.71000000", "0.02387000"], ["84092.69000000", "0.00000000"], ["84092.68000000", "0.00000000"], ["84092.52000000", "0.00000000"], ["84092.44000000", "0.00000000"], ["84092.40000000", "0.00006000"], ["84092.34000000", "0.00000000"], ["84092.28000000", "0.00000000"], ["84091.77000000", "0.00000000"], ["84091.70000000", "0.00000000"], ["84091.69000000", "0.00000000"], ["84091.68000000", "0.00000000"], ["84091.32000000", "0.00000000"], ["84091.29000000", "0.00000000"], ["84091.20000000", "0.00000000"], ["84090.93000000", "0.00000000"], ["84090.92000000", "0.29027000"], ["84090.82000000", "0.00011000"], ["84090.78000000", "0.00000000"], ["84090.49000000", "0.00000000"], ["84090.46000000", "0.00000000"], ["84090.43000000", "0.00000000"], ["84090.33000000", "0.00000000"], ["84090.28000000", "0.00000000"], ["84089.88000000", "0.29003000"], ["84089.67000000", "0.00092000"], ["84089.64000000", "0.00000000"], ["84089.57000000", "0.00000000"], ["84089.47000000", "0.00418000"], ["84089.44000000", "0.00000000"], ["84089.35000000", "0.00000000"], ["84089.29000000", "0.00000000"], ["84089.28000000", "0.00000000"], ["84089.27000000", "0.00000000"], ["84089.24000000", "0.00000000"], ["84089.23000000", "0.00000000"], ["84089.07000000", "0.04000000"], ["84089.06000000", "0.04000000"], ["84088.98000000", "0.06000000"], ["84088.85000000", "0.00000000"], ["84088.76000000", "0.00000000"], ["84088.75000000", "0.00756000"], ["84088.63000000", "0.00000000"], ["84088.43000000", "0.15633000"], ["84088.38000000", "0.01000000"], ["84088.24000000", "0.04817000"], ["84088.11000000", "0.00000000"], ["84088.06000000", "0.00000000"], ["84088.00000000", "0.00000000"], ["84087.76000000", "0.00000000"], ["84087.64000000", "0.00000000"], ["84087.58000000", "0.00118000"], ["84087.56000000", "0.00000000"], ["84087.55000000", "0.00000000"], ["84087.54000000", "0.59407000"], ["84087.43000000", "0.00000000"], ["84087.29000000", "0.00000000"], ["84087.09000000", "0.04000000"], ["84087.05000000", "0.00000000"], ["84086.86000000", "0.00000000"], ["84086.69000000", "0.00000000"], ["84086.54000000", "0.00000000"], ["84086.52000000", "0.00000000"], ["84086.37000000", "0.00091000"], ["84086.16000000", "0.10702000"], ["84086.13000000", "0.00000000"], ["84086.02000000", "0.00000000"], ["84085.96000000", "0.00007000"], ["84085.91000000", "0.00000000"], ["84085.68000000", "0.00000000"], ["84085.62000000", "0.00095000"], ["84085.42000000", "0.00000000"], ["84085.30000000", "0.00000000"], ["84085.22000000", "0.00000000"], ["84085.21000000", "0.00000000"], ["84085.01000000", "0.06000000"], ["84084.90000000", "0.16429000"], ["84084.89000000", "0.00000000"], ["84084.86000000", "0.04000000"], ["84084.37000000", "0.00000000"], ["84084.36000000", "0.00000000"], ["84084.21000000", "0.08000000"], ["84084.18000000", "0.71284000"], ["84083.94000000", "0.04000000"], ["84083.58000000", "0.00000000"], ["84083.40000000", "0.00000000"], ["84083.36000000", "0.00000000"], ["84083.29000000", "0.00000000"], ["84083.27000000", "0.35644000"], ["84082.96000000", "0.00000000"], ["84082.89000000", "0.04000000"], ["84082.88000000", "0.00000000"], ["84082.81000000", "0.00007000"], ["84082.71000000", "0.00000000"], ["84082.58000000", "0.01189000"], ["84082.56000000", "0.00000000"], ["84082.29000000", "0.00000000"], ["84082.22000000", "0.00000000"], ["84082.20000000", "0.00000000"], ["84082.07000000", "0.00000000"], ["84081.96000000", "2.28004000"], ["84081.91000000", "0.00300000"], ["84081.63000000", "0.00000000"], ["84081.44000000", "0.47526000"], ["84081.35000000", "0.00000000"], ["84081.15000000", "0.00000000"], ["84081.04000000", "0.00000000"], ["84080.79000000", "0.00000000"], ["84080.58000000", "0.00000000"], ["84080.43000000", "0.78533000"], ["84080.39000000", "0.00000000"], ["84080.03000000", "0.00000000"], ["84079.73000000", "0.00000000"], ["84079.72000000", "0.00000000"], ["84079.71000000", "0.00000000"], ["84079.69000000", "0.00000000"], ["84079.66000000", "0.00000000"], ["84079.65000000", "0.00000000"], ["84079.64000000", "0.00000000"], ["84079.56000000", "0.00000000"], ["84079.18000000", "0.00000000"], ["84079.14000000", "0.00000000"], ["84078.65000000", "0.00000000"], ["84078.53000000", "0.00000000"], ["84078.51000000", "1.33998000"], ["84078.49000000", "0.00000000"], ["84078.36000000", "0.04000000"], ["84078.34000000", "0.05940000"], ["84078.09000000", "0.00000000"], ["84078.06000000", "0.00000000"], ["84077.90000000", "0.00000000"], ["84077.87000000", "0.00000000"], ["84077.85000000", "0.00000000"], ["84077.83000000", "0.00000000"], ["84077.49000000", "0.00000000"], ["84077.44000000", "0.00000000"], ["84077.43000000", "0.89111000"], ["84077.23000000", "0.67561000"], ["84077.15000000", "0.00000000"], ["84077.12000000", "0.00000000"], ["84077.08000000", "0.00000000"], ["84076.98000000", "0.00000000"], ["84076.97000000", "0.03568000"], ["84076.88000000", "0.00000000"], ["84076.49000000", "0.00007000"], ["84075.38000000", "0.00000000"], ["84075.21000000", "0.00000000"], ["84074.39000000", "0.00000000"], ["84073.99000000", "0.00000000"], ["84073.75000000", "0.17189000"], ["84073.55000000", "0.00000000"], ["84073.27000000", "0.11471000"], ["84073.09000000", "0.74615000"], ["84073.08000000", "0.29316000"], ["84073.07000000", "0.00576000"], ["84072.46000000", "0.05940000"], ["84072.04000000", "0.00000000"], ["84072.03000000", "0.00000000"], ["84072.02000000", "0.00000000"], ["84071.65000000", "0.00000000"], ["84071.47000000", "0.00000000"], ["84071.06000000", "0.05785000"], ["84070.62000000", "0.00000000"], ["84070.49000000", "0.00511000"], ["84069.99000000", "0.00352000"], ["84069.58000000", "0.89111000"], ["84069.19000000", "0.00000000"], ["84068.45000000", "0.03855000"], ["84068.38000000", "0.00000000"], ["84068.37000000", "0.97850000"], ["84068.27000000", "0.00000000"], ["84068.11000000", "0.05940000"], ["84068.01000000", "0.00000000"], ["84068.00000000", "0.00220000"], ["84067.26000000", "0.00000000"], ["84067.05000000", "0.00000000"], ["84067.04000000", "0.00000000"], ["84066.91000000", "0.89111000"], ["84066.65000000", "0.00000000"], ["84066.54000000", "0.33708000"], ["84066.41000000", "0.00831000"], ["84066.36000000", "0.89111000"], ["84066.16000000", "0.00016000"], ["84065.87000000", "0.00000000"], ["84065.54000000", "0.00000000"], ["84065.34000000", "0.31355000"], ["84065.09000000", "0.00000000"], ["84064.24000000", "0.28478000"], ["84063.21000000", "0.00000000"], ["84063.18000000", "0.00000000"], ["84063.11000000", "0.00000000"], ["84062.07000000", "0.00213000"], ["84062.06000000", "0.00000000"], ["84062.05000000", "0.00000000"], ["84061.57000000", "0.00035000"], ["84060.56000000", "1.31179000"], ["84060.55000000", "0.89111000"], ["84060.12000000", "0.05847000"], ["84060.09000000", "0.00000000"], ["84059.61000000", "0.00000000"], ["84059.27000000", "0.85694000"], ["84059.22000000", "0.41059000"], ["84059.11000000", "0.00000000"], ["84058.92000000", "0.00000000"], ["84058.35000000", "0.00000000"], ["84058.09000000", "0.05437000"], ["84057.59000000", "0.59486000"], ["84057.23000000", "0.05071000"], ["84056.81000000", "0.00358000"], ["84056.55000000", "0.04000000"], ["84056.24000000", "0.00000000"], ["84056.15000000", "0.01300000"], ["84055.86000000", "0.00000000"], ["84055.40000000", "0.00000000"], ["84055.22000000", "0.00059000"], ["84055.20000000", "0.00000000"], ["84054.43000000", "0.00000000"], ["84053.97000000", "0.85700000"], ["84052.99000000", "0.30079000"], ["84052.69000000", "0.04942000"], ["84050.70000000", "0.00000000"], ["84050.20000000", "0.67816000"], ["84050.19000000", "0.00000000"], ["84050.03000000", "0.85704000"], ["84049.19000000", "0.00297000"], ["84046.83000000", "0.00000000"], ["84046.64000000", "0.00000000"], ["84046.35000000", "0.00000000"], ["84046.20000000", "0.00006000"], ["84045.44000000", "0.00000000"], ["84044.03000000", "0.02886000"], ["84043.69000000", "0.00000000"], ["84042.17000000", "0.00000000"], ["84042.15000000", "0.04000000"], ["84040.85000000", "0.04000000"], ["84040.00000000", "0.00241000"], ["84039.10000000", "0.00296000"], ["84038.55000000", "0.04000000"], ["84037.47000000", "0.04000000"], ["84036.37000000", "0.04000000"], ["84036.25000000", "0.04000000"], ["84035.73000000", "0.04000000"], ["84034.36000000", "0.00818000"], ["84034.34000000", "0.04000000"], ["84033.60000000", "0.00006000"], ["84032.93000000", "0.00817000"], ["84030.88000000", "0.00864000"], ["84030.58000000", "0.02830000"], ["84028.98000000", "0.00827000"], ["84026.91000000", "0.09757000"], ["84026.90000000", "0.00000000"], ["84026.36000000", "0.00000000"], ["84024.23000000", "0.00000000"], ["84023.38000000", "0.00000000"], ["84023.12000000", "0.44788000"], ["84022.13000000", "0.00000000"], ["84020.01000000", "0.00000000"], ["84019.81000000", "0.00000000"], ["84016.80000000", "0.03575000"], ["84014.97000000", "0.00213000"], ["84014.45000000", "0.88224000"], ["84013.61000000", "0.00000000"], ["84013.29000000", "0.00000000"], ["84011.53000000", "1.12485000"], ["84009.04000000", "0.00000000"], ["84005.11000000", "0.06692000"], ["84003.03000000", "0.12827000"], ["83999.92000000", "0.00000000"], ["83999.22000000", "0.00000000"], ["83997.04000000", "0.13801000"], ["83993.98000000", "0.05497000"], ["83993.36000000", "0.05496000"], ["83993.21000000", "0.00000000"], ["83992.59000000", "0.92391000"], ["83991.82000000", "1.38846000"], ["83989.47000000", "0.00000000"], ["83988.34000000", "0.05496000"], ["83985.40000000", "0.11520000"], ["83985.19000000", "0.05496000"], ["83985.17000000", "0.00075000"], ["83982.67000000", "0.05197000"], ["83980.22000000", "0.00000000"], ["83979.51000000", "0.00000000"], ["83978.99000000", "0.05496000"], ["83977.74000000", "0.05297000"], ["83977.11000000", "0.04197000"], ["83976.59000000", "0.05297000"], ["83976.37000000", "0.10094000"], ["83976.06000000", "0.04097000"], ["83974.80000000", "0.00006000"], ["83974.66000000", "0.05297000"], ["83974.37000000", "0.10194000"], ["83973.82000000", "0.05197000"], ["83973.48000000", "0.00013000"], ["83973.22000000", "0.00172000"], ["83973.21000000", "0.04897000"], ["83971.96000000", "0.05297000"], ["83971.11000000", "0.04197000"], ["83970.38000000", "0.05297000"], ["83970.13000000", "0.04097000"], ["83968.40000000", "0.00000000"], ["83967.77000000", "0.04897000"], ["83966.11000000", "0.04897000"], ["83964.05000000", "0.04897000"], ["83963.70000000", "0.00118000"], ["83962.85000000", "0.04197000"], ["83962.36000000", "0.04897000"], ["83956.49000000", "0.12870000"], ["83954.96000000", "0.00118000"], ["83952.94000000", "0.00000000"], ["83943.62000000", "0.00006000"], ["83941.23000000", "0.00000000"], ["83941.13000000", "0.00000000"], ["83940.33000000", "0.00000000"], ["83938.77000000", "0.00000000"], ["83938.53000000", "0.00000000"], ["83937.43000000", "0.00000000"], ["83937.33000000", "0.00050000"], ["83934.98000000", "0.00000000"], ["83934.36000000", "0.00000000"], ["83931.75000000", "0.99313000"], ["83910.65000000", "0.00000000"], ["83907.92000000", "0.00063000"], ["83904.00000000", "0.00235000"], ["83899.51000000", "0.00000000"], ["83894.95000000", "0.07077000"], ["83889.76000000", "0.05839000"], ["83887.50000000", "0.00230000"], ["83882.71000000", "0.00000000"], ["83881.35000000", "0.13654000"], ["83876.45000000", "0.00000000"], ["83875.10000000", "0.12420000"], ["83867.53000000", "0.00013000"], ["83864.02000000", "0.00013000"], ["83859.82000000", "0.00013000"], ["83855.70000000", "0.00000000"], ["83851.55000000", "0.00400000"], ["83846.32000000", "0.00000000"], ["83844.29000000", "0.00000000"], ["83839.74000000", "0.00000000"], ["83833.26000000", "0.00000000"], ["83826.93000000", "0.45007000"], ["83810.00000000", "0.00000000"], ["83808.40000000", "0.00000000"], ["83112.60000000", "0.00000000"], ["82995.00000000", "0.00096000"], ["82845.54000000", "0.00000000"], ["80697.27000000", "0.00000000"], ["80680.44000000", "0.03567000"], ["75696.00000000", "0.03441000"], ["75687.00000000", "0.00000000"], ["67285.72000000", "0.00000000"], ["67277.04000000", "0.00058000"], ["50460.07000000", "0.00000000"], ["42000.00000000", "6.85261000"], ["33000.00000000", "2.93827000"]], "a": [["84096.30000000", "7.56379000"], ["84096.31000000", "0.00041000"], ["84096.32000000", "0.00000000"], ["84096.61000000", "0.00000000"], ["84096.78000000", "0.00000000"], ["84096.79000000", "0.00000000"], ["84097.25000000", "0.36762000"], ["84097.26000000", "0.00000000"], ["84097.27000000", "0.00000000"], ["84097.28000000", "0.48326000"], ["84097.29000000", "0.00000000"], ["84097.30000000", "0.00000000"], ["84097.76000000", "0.00000000"], ["84097.77000000", "0.00000000"], ["84097.79000000", "0.00000000"], ["84097.92000000", "0.04823000"], ["84097.99000000", "0.00000000"], ["84098.00000000", "0.02266000"], ["84098.13000000", "0.00000000"], ["84098.34000000", "0.00000000"], ["84098.40000000", "0.00000000"], ["84098.41000000", "0.00000000"], ["84098.42000000", "0.00000000"], ["84098.43000000", "0.47861000"], ["84098.45000000", "0.00000000"], ["84098.78000000", "0.00000000"], ["84098.81000000", "0.00000000"], ["84098.86000000", "0.00000000"], ["84098.89000000", "0.00000000"], ["84098.90000000", "0.00000000"], ["84098.91000000", "0.00000000"], ["84098.92000000", "0.00000000"], ["84099.16000000", "0.00000000"], ["84099.28000000", "0.00000000"], ["84099.61000000", "0.00000000"], ["84099.62000000", "0.00000000"], ["84099.69000000", "0.00000000"], ["84099.70000000", "0.00000000"], ["84099.87000000", "0.14120000"], ["84099.88000000", "0.02388000"], ["84100.00000000", "0.02272000"], ["84100.01000000", "0.00000000"], ["84100.03000000", "0.00000000"], ["84100.07000000", "0.00000000"], ["84100.15000000", "0.00000000"], ["84100.16000000", "0.00000000"], ["84100.17000000", "0.00000000"], ["84100.18000000", "0.00000000"], ["84100.30000000", "0.00000000"], ["84100.63000000", "0.00000000"], ["84100.86000000", "0.00000000"], ["84100.96000000", "0.00000000"], ["84101.27000000", "0.00000000"], ["84101.34000000", "0.00000000"], ["84101.35000000", "0.00000000"], ["84101.42000000", "0.00000000"], ["84101.65000000", "0.00759000"], ["84102.00000000", "0.02266000"], ["84102.42000000", "0.00000000"], ["84102.53000000", "0.00000000"], ["84102.58000000", "0.00000000"], ["84102.65000000", "0.00000000"], ["84102.66000000", "0.00000000"], ["84102.67000000", "0.00000000"], ["84102.68000000", "0.00000000"], ["84102.69000000", "0.19560000"], ["84102.70000000", "0.00000000"], ["84102.71000000", "0.00000000"], ["84102.91000000", "0.00000000"], ["84102.92000000", "0.00000000"], ["84103.00000000", "0.00000000"], ["84103.21000000", "0.00000000"], ["84103.48000000", "0.00000000"], ["84103.50000000", "0.00000000"], ["84103.53000000", "0.00000000"], ["84103.60000000", "0.00000000"], ["84103.61000000", "0.00000000"], ["84103.62000000", "0.00000000"], ["84103.63000000", "0.00000000"], ["84103.81000000", "0.04006000"], ["84104.00000000", "0.02266000"], ["84104.06000000", "0.00831000"], ["84104.32000000", "0.00000000"], ["84104.80000000", "0.00000000"], ["84104.86000000", "0.00000000"], ["84104.88000000", "0.36869000"], ["84104.89000000", "0.40758000"], ["84104.90000000", "0.00000000"], ["84105.00000000", "0.00000000"], ["84105.01000000", "0.00000000"], ["84105.16000000", "0.00000000"], ["84105.18000000", "0.00000000"], ["84105.23000000", "0.00000000"], ["84106.00000000", "0.02266000"], ["84106.01000000", "0.00000000"], ["84106.03000000", "0.00000000"], ["84106.18000000", "0.00000000"], ["84106.40000000", "0.00000000"], ["84106.46000000", "0.00000000"], ["84106.49000000", "0.00000000"], ["84106.57000000", "0.00000000"], ["84106.58000000", "0.15500000"], ["84106.59000000", "0.17822000"], ["84106.64000000", "0.04000000"], ["84106.73000000", "0.00000000"], ["84106.74000000", "0.00000000"], ["84106.76000000", "0.00118000"], ["84106.80000000", "0.00013000"], ["84106.85000000", "0.00000000"], ["84106.87000000", "0.00000000"], ["84106.89000000", "0.00000000"], ["84107.04000000", "0.00000000"], ["84107.06000000", "0.00000000"], ["84107.09000000", "0.00000000"], ["84107.15000000", "0.45058000"], ["84107.16000000", "0.01601000"], ["84107.17000000", "0.00000000"], ["84107.19000000", "0.00000000"], ["84107.37000000", "0.03568000"], ["84107.48000000", "0.04000000"], ["84107.98000000", "0.00000000"], ["84107.99000000", "0.00000000"], ["84108.00000000", "0.02260000"], ["84108.41000000", "0.16647000"], ["84108.44000000", "0.00000000"], ["84108.73000000", "0.29291000"], ["84108.74000000", "0.85644000"], ["84108.93000000", "0.00013000"], ["84109.20000000", "0.00006000"], ["84109.64000000", "0.00000000"], ["84109.99000000", "0.00000000"], ["84110.00000000", "0.02260000"], ["84110.02000000", "0.00000000"], ["84110.09000000", "0.00000000"], ["84110.71000000", "0.00000000"], ["84110.72000000", "0.00000000"], ["84110.82000000", "0.00009000"], ["84111.44000000", "0.00000000"], ["84111.45000000", "0.09081000"], ["84111.74000000", "0.07600000"], ["84111.96000000", "0.05200000"], ["84111.97000000", "0.04800000"], ["84112.04000000", "0.05200000"], ["84112.06000000", "0.00000000"], ["84112.15000000", "0.05940000"], ["84112.19000000", "0.01189000"], ["84112.30000000", "0.00013000"], ["84112.53000000", "0.06400000"], ["84112.61000000", "0.06000000"], ["84112.71000000", "0.05940000"], ["84112.91000000", "0.00000000"], ["84113.09000000", "0.00000000"], ["84113.19000000", "0.00013000"], ["84113.40000000", "0.00006000"], ["84113.65000000", "0.39673000"], ["84113.66000000", "0.85639000"], ["84113.83000000", "0.14548000"], ["84114.00000000", "0.02260000"], ["84114.04000000", "0.00000000"], ["84114.24000000", "0.00000000"], ["84114.25000000", "0.35644000"], ["84114.41000000", "0.00376000"], ["84114.55000000", "0.00000000"], ["84114.59000000", "0.00000000"], ["84114.77000000", "0.00000000"], ["84115.13000000", "0.00006000"], ["84115.22000000", "0.08304000"], ["84115.30000000", "0.00000000"], ["84115.39000000", "0.00013000"], ["84115.98000000", "0.93089000"], ["84115.99000000", "0.71284000"], ["84116.00000000", "0.02260000"], ["84116.19000000", "0.10702000"], ["84116.25000000", "0.00118000"], ["84116.41000000", "0.89111000"], ["84116.64000000", "0.00000000"], ["84117.49000000", "0.85635000"], ["84117.59000000", "0.05940000"], ["84117.60000000", "0.00006000"], ["84117.86000000", "1.36737000"], ["84118.17000000", "0.00000000"], ["84118.31000000", "0.00000000"], ["84118.83000000", "0.00000000"], ["84118.88000000", "0.01188000"], ["84119.51000000", "0.00000000"], ["84119.68000000", "0.00000000"], ["84120.00000000", "0.00006000"], ["84120.40000000", "0.33538000"], ["84120.53000000", "0.00000000"], ["84120.61000000", "0.00000000"], ["84121.02000000", "0.00000000"], ["84121.40000000", "0.00000000"], ["84121.71000000", "0.00059000"], ["84121.81000000", "0.00000000"], ["84122.00000000", "0.00000000"], ["84122.06000000", "0.84790000"], ["84122.17000000", "0.00000000"], ["84122.25000000", "0.71284000"], ["84123.05000000", "0.00000000"], ["84123.16000000", "0.00000000"], ["84123.21000000", "0.47526000"], ["84123.70000000", "0.00000000"], ["84123.89000000", "0.00000000"], ["84124.11000000", "0.00000000"], ["84124.72000000", "0.83728000"], ["84124.73000000", "0.59482000"], ["84124.74000000", "0.00000000"], ["84124.81000000", "0.00000000"], ["84124.83000000", "0.05000000"], ["84124.84000000", "0.00000000"], ["84125.10000000", "0.00000000"], ["84125.17000000", "0.28985000"], ["84125.18000000", "0.19425000"], ["84125.39000000", "0.00000000"], ["84125.40000000", "0.00000000"], ["84125.80000000", "0.89111000"], ["84125.97000000", "0.00000000"], ["84126.00000000", "0.02363000"], ["84126.78000000", "0.00360000"], ["84127.08000000", "0.00016000"], ["84127.37000000", "0.00000000"], ["84127.69000000", "0.04000000"], ["84127.99000000", "0.00000000"], ["84128.00000000", "0.00000000"], ["84128.53000000", "0.04000000"], ["84128.68000000", "1.00410000"], ["84128.70000000", "0.00000000"], ["84128.84000000", "0.00000000"], ["84128.93000000", "0.00000000"], ["84129.14000000", "0.00000000"], ["84130.03000000", "0.00000000"], ["84130.12000000", "0.00059000"], ["84130.13000000", "0.00000000"], ["84130.23000000", "0.00000000"], ["84130.27000000", "0.12838000"], ["84130.49000000", "0.00573000"], ["84130.59000000", "0.19425000"], ["84131.12000000", "0.00000000"], ["84131.41000000", "0.00000000"], ["84132.39000000", "0.00000000"], ["84133.49000000", "0.00013000"], ["84133.58000000", "0.06400000"], ["84133.59000000", "0.00100000"], ["84133.66000000", "0.06000000"], ["84134.04000000", "0.00000000"], ["84134.68000000", "0.00000000"], ["84134.72000000", "0.00000000"], ["84135.72000000", "0.00000000"], ["84135.73000000", "0.00000000"], ["84136.47000000", "0.00358000"], ["84136.93000000", "1.75441000"], ["84138.12000000", "0.00000000"], ["84138.39000000", "0.35644000"], ["84138.78000000", "0.00084000"], ["84138.79000000", "0.00000000"], ["84139.33000000", "0.00059000"], ["84139.82000000", "0.00000000"], ["84139.93000000", "0.00000000"], ["84140.18000000", "0.00823000"], ["84140.38000000", "0.05780000"], ["84141.17000000", "0.00814000"], ["84141.37000000", "0.02971000"], ["84141.48000000", "0.00000000"], ["84141.62000000", "0.00000000"], ["84142.04000000", "0.12400000"], ["84142.37000000", "0.25107000"], ["84144.45000000", "0.03451000"], ["84145.20000000", "0.00000000"], ["84145.29000000", "0.00358000"], ["84145.82000000", "0.00807000"], ["84146.96000000", "0.02983000"], ["84146.97000000", "0.01196000"], ["84147.07000000", "0.00000000"], ["84147.87000000", "0.00000000"], ["84148.63000000", "0.00000000"], ["84148.80000000", "0.00000000"], ["84148.96000000", "0.00000000"], ["84149.21000000", "0.00000000"], ["84149.74000000", "0.00000000"], ["84150.42000000", "0.04800000"], ["84151.39000000", "0.00863000"], ["84151.99000000", "0.00000000"], ["84153.31000000", "0.00000000"], ["84153.62000000", "0.00000000"], ["84153.74000000", "0.00670000"], ["84153.79000000", "0.30703000"], ["84153.93000000", "0.00013000"], ["84154.68000000", "0.07200000"], ["84154.83000000", "0.00000000"], ["84155.52000000", "0.06400000"], ["84155.87000000", "0.05460000"], ["84155.98000000", "0.00000000"], ["84156.07000000", "0.59407000"], ["84156.30000000", "0.00000000"], ["84157.10000000", "0.00119000"], ["84157.31000000", "0.00000000"], ["84157.76000000", "0.00000000"], ["84158.18000000", "0.00000000"], ["84159.67000000", "0.00000000"], ["84161.68000000", "0.00000000"], ["84163.73000000", "0.14735000"], ["84163.74000000", "0.00000000"], ["84165.07000000", "0.00000000"], ["84173.24000000", "1.12269000"], ["84174.00000000", "0.00000000"], ["84175.36000000", "0.03176000"], ["84175.61000000", "0.00143000"], ["84175.73000000", "0.07200000"], ["84175.99000000", "0.00041000"], ["84178.49000000", "0.05204000"], ["84178.52000000", "0.05977000"], ["84179.81000000", "0.00347000"], ["84180.48000000", "0.00000000"], ["84180.60000000", "0.00000000"], ["84180.76000000", "0.05200000"], ["84181.13000000", "0.00013000"], ["84181.99000000", "0.00841000"], ["84182.04000000", "0.00000000"], ["84183.84000000", "0.42423000"], ["84186.87000000", "0.00000000"], ["84187.39000000", "0.00000000"], ["84188.33000000", "0.00000000"], ["84188.34000000", "0.00000000"], ["84188.54000000", "0.10258000"], ["84189.17000000", "0.00000000"], ["84190.75000000", "0.00000000"], ["84191.05000000", "0.00000000"], ["84191.29000000", "0.00000000"], ["84194.29000000", "0.00000000"], ["84194.43000000", "0.00000000"], ["84197.75000000", "0.00000000"], ["84200.55000000", "0.00000000"], ["84203.10000000", "0.00000000"], ["84217.63000000", "0.00000000"], ["84221.13000000", "0.11258000"], ["84228.45000000", "0.05497000"], ["84229.36000000", "0.05297000"], ["84231.82000000", "0.05097000"], ["84233.61000000", "0.02497000"], ["84238.50000000", "0.00000000"], ["84243.29000000", "2.00623000"], ["84248.45000000", "0.00000000"], ["84248.59000000", "0.05297000"], ["84248.82000000", "0.00000000"], ["84249.85000000", "0.00000000"], ["84250.03000000", "0.00000000"], ["84251.84000000", "0.00035000"], ["84252.17000000", "0.04904000"], ["84252.23000000", "0.00000000"], ["84252.95000000", "0.00000000"], ["84253.42000000", "0.00013000"], ["84255.16000000", "0.00000000"], ["84255.92000000", "0.00000000"], ["84256.10000000", "0.01186000"], ["84256.17000000", "0.00000000"], ["84258.77000000", "0.00000000"], ["84259.21000000", "0.00000000"], ["84259.55000000", "0.00000000"], ["84259.95000000", "0.00000000"], ["84261.75000000", "0.00000000"], ["84262.38000000", "0.00000000"], ["84262.74000000", "0.00000000"], ["84263.14000000", "0.00000000"], ["84263.30000000", "0.00000000"], ["84263.54000000", "0.00000000"], ["84264.04000000", "0.01000000"], ["84264.74000000", "0.00000000"], ["84265.24000000", "0.00000000"], ["84268.33000000", "0.00118000"], ["84268.95000000", "0.00000000"], ["84273.53000000", "0.00000000"], ["84273.86000000", "0.00000000"], ["84279.17000000", "0.00000000"], ["84282.89000000", "0.00118000"], ["84287.06000000", "0.00000000"], ["84303.60000000", "0.00000000"], ["84315.58000000", "0.00000000"], ["84324.00000000", "0.00235000"], ["84346.00000000", "0.00000000"], ["84348.46000000", "0.00000000"], ["84350.99000000", "0.00000000"], ["84354.09000000", "0.00000000"], ["84384.36000000", "0.79995000"], ["84414.59000000", "0.00000000"], ["84417.08000000", "0.00000000"], ["84419.53000000", "0.19425000"], ["84421.52000000", "0.00000000"], ["84422.25000000", "0.00000000"], ["84433.35000000", "0.08364000"], ["84739.20000000", "0.05954000"], ["84772.80000000", "0.00006000"], ["84938.24000000", "0.00000000"], ["85358.74000000", "0.00100000"], ["85370.40000000", "0.02352000"], ["150001.00000000", "0.00080000"]], "record_time": 1742554955.05399, "EXCHANGE": "BINANCE"}
{"e": "depthUpdate", "E": 1742554956014, "s": "BTCUSDT", "U": 64607009929, "u": 64607012126, "b": [["84096.29000000", "0.00000000"], ["84096.28000000", "0.00000000"], ["84095.89000000", "0.00000000"], ["84095.81000000", "0.00000000"], ["84095.42000000", "0.00000000"], ["84095.41000000", "0.00000000"], ["84095.40000000", "0.00000000"], ["84095.39000000", "0.00000000"], ["84095.38000000", "0.00000000"], ["84095.19000000", "0.00000000"], ["84095.05000000", "0.00000000"], ["84094.98000000", "0.00000000"], ["84094.36000000", "0.00000000"], ["84094.35000000", "0.00000000"], ["84094.20000000", "0.00000000"], ["84093.29000000", "0.00000000"], ["84093.28000000", "0.00000000"], ["84093.23000000", "0.00000000"], ["84092.79000000", "0.00000000"], ["84092.78000000", "0.00000000"], ["84092.76000000", "0.00000000"], ["84092.72000000", "0.00000000"], ["84092.71000000", "0.00000000"], ["84092.70000000", "0.00000000"], ["84092.52000000", "0.00000000"], ["84092.40000000", "0.00000000"], ["84092.29000000", "0.00000000"], ["84091.84000000", "0.00000000"], ["84091.83000000", "0.00000000"], ["84091.67000000", "0.00000000"], ["84091.51000000", "0.00000000"], ["84091.35000000", "0.00000000"], ["84090.94000000", "0.00000000"], ["84090.93000000", "0.00000000"], ["84090.92000000", "3.60567000"], ["84090.91000000", "0.00048000"], ["84090.89000000", "0.00016000"], ["84090.83000000", "0.00017000"], ["84090.82000000", "0.00000000"], ["84090.81000000", "0.00021000"], ["84090.80000000", "0.00514000"], ["84090.65000000", "0.00015000"], ["84090.51000000", "0.00000000"], ["84089.99000000", "0.00014000"], ["84089.89000000", "0.00022000"], ["84089.88000000", "0.17318000"], ["84089.70000000", "0.00009000"], ["84089.67000000", "0.00000000"], ["84089.47000000", "0.00000000"], ["84089.37000000", "0.00000000"], ["84089.31000000", "0.00000000"], ["84089.26000000", "0.00000000"], ["84089.14000000", "0.00007000"], ["84089.07000000", "0.00000000"], ["84089.06000000", "0.00000000"], ["84088.98000000", "0.00000000"], ["84088.75000000", "0.00000000"], ["84088.63000000", "0.00000000"], ["84088.54000000", "0.00000000"], ["84088.43000000", "0.00000000"], ["84088.38000000", "0.00000000"], ["84088.24000000", "0.00000000"], ["84088.20000000", "0.00000000"], ["84088.07000000", "0.02484000"], ["84087.90000000", "0.00011000"], ["84087.66000000", "0.00000000"], ["84087.58000000", "0.00000000"], ["84087.55000000", "0.00048000"], ["84087.54000000", "0.59420000"], ["84087.46000000", "0.00000000"], ["84087.45000000", "0.00007000"], ["84087.33000000", "0.02381000"], ["84087.09000000", "0.00000000"], ["84087.06000000", "0.00000000"], ["84086.81000000", "0.00935000"], ["84086.53000000", "0.00000000"], ["84086.39000000", "0.00000000"], ["84086.37000000", "0.00000000"], ["84086.20000000", "0.00000000"], ["84086.16000000", "0.00000000"], ["84086.04000000", "0.00000000"], ["84086.03000000", "0.08735000"], ["84086.00000000", "0.02260000"], ["84085.99000000", "0.00000000"], ["84085.96000000", "0.00007000"], ["84085.88000000", "0.00000000"], ["84085.77000000", "0.00000000"], ["84085.62000000", "0.00000000"], ["84085.50000000", "0.00371000"], ["84085.01000000", "0.00000000"], ["84084.90000000", "0.00000000"], ["84084.86000000", "0.00000000"], ["84084.80000000", "0.04817000"], ["84084.67000000", "0.01870000"], ["84084.50000000", "0.00000000"], ["84084.46000000", "0.00000000"], ["84084.40000000", "0.00000000"], ["84084.37000000", "0.00000000"], ["84084.35000000", "0.00000000"], ["84084.21000000", "0.00000000"], ["84084.18000000", "0.00000000"], ["84084.17000000", "0.00000000"], ["84084.06000000", "0.00000000"], ["84083.94000000", "0.00000000"], ["84083.82000000", "0.00000000"], ["84083.56000000", "0.00000000"], ["84083.46000000", "0.00000000"], ["84083.37000000", "0.00000000"], ["84083.29000000", "0.00000000"], ["84083.28000000", "0.00000000"], ["84083.27000000", "0.00000000"], ["84082.89000000", "0.00000000"], ["84082.81000000", "0.00000000"], ["84082.59000000", "0.00007000"], ["84082.58000000", "0.00000000"], ["84082.51000000", "0.15633000"], ["84082.32000000", "0.00091000"], ["84082.01000000", "0.04000000"], ["84081.96000000", "0.68912000"], ["84081.60000000", "0.00034000"], ["84081.59000000", "0.00000000"], ["84081.57000000", "0.00000000"], ["84081.23000000", "0.00118000"], ["84081.02000000", "0.00000000"], ["84081.01000000", "0.00000000"], ["84080.89000000", "0.04000000"], ["84080.88000000", "0.04000000"], ["84080.80000000", "0.04000000"], ["84080.47000000", "0.00756000"], ["84080.43000000", "0.00000000"], ["84080.16000000", "0.00000000"], ["84080.07000000", "0.00000000"], ["84080.02000000", "0.78534000"], ["84080.01000000", "0.00000000"], ["84079.80000000", "0.02335000"], ["84079.71000000", "0.00000000"], ["84079.47000000", "0.00359000"], ["84079.26000000", "0.01500000"], ["84079.17000000", "0.01500000"], ["84079.12000000", "0.00000000"], ["84079.08000000", "0.01189000"], ["84078.91000000", "0.00000000"], ["84078.67000000", "0.00096000"], ["84078.64000000", "0.04000000"], ["84078.59000000", "0.00000000"], ["84078.51000000", "0.00000000"], ["84078.13000000", "0.00000000"], ["84077.90000000", "0.00000000"], ["84077.80000000", "0.04000000"], ["84077.71000000", "0.00000000"], ["84077.59000000", "0.00091000"], ["84077.48000000", "0.16429000"], ["84077.45000000", "0.71284000"], ["84077.44000000", "1.16636000"], ["84077.27000000", "0.00414000"], ["84077.24000000", "0.00000000"], ["84077.23000000", "0.00000000"], ["84076.97000000", "0.00000000"], ["84076.96000000", "0.04000000"], ["84076.71000000", "0.00000000"], ["84076.67000000", "0.00000000"], ["84076.66000000", "0.89111000"], ["84076.61000000", "0.00000000"], ["84076.41000000", "0.00000000"], ["84076.22000000", "0.10702000"], ["84075.81000000", "0.04000000"], ["84075.41000000", "0.02000000"], ["84075.34000000", "0.00000000"], ["84075.25000000", "0.00000000"], ["84074.21000000", "0.00000000"], ["84074.01000000", "0.08000000"], ["84073.99000000", "0.00000000"], ["84073.75000000", "0.01189000"], ["84073.66000000", "0.00000000"], ["84073.55000000", "0.00000000"], ["84073.43000000", "0.35644000"], ["84073.27000000", "0.00000000"], ["84073.09000000", "1.64685000"], ["84072.99000000", "0.00000000"], ["84072.66000000", "0.00000000"], ["84072.59000000", "0.00000000"], ["84072.55000000", "0.00000000"], ["84072.46000000", "0.00000000"], ["84072.42000000", "0.89111000"], ["84071.45000000", "0.00000000"], ["84071.31000000", "0.20302000"], ["84071.18000000", "0.00000000"], ["84071.06000000", "0.00300000"], ["84070.99000000", "0.00000000"], ["84070.97000000", "1.31412000"], ["84070.95000000", "0.00000000"], ["84070.87000000", "0.00118000"], ["84070.67000000", "0.00000000"], ["84070.49000000", "0.00006000"], ["84070.48000000", "0.00000000"], ["84070.47000000", "0.00000000"], ["84070.46000000", "0.03568000"], ["84070.16000000", "0.00000000"], ["84070.01000000", "0.00000000"], ["84068.65000000", "0.00000000"], ["84068.45000000", "0.00000000"], ["84068.29000000", "0.89111000"], ["84067.56000000", "0.05785000"], ["84067.34000000", "0.11895000"], ["84066.75000000", "0.16000000"], ["84066.41000000", "0.00000000"], ["84065.98000000", "0.05940000"], ["84065.49000000", "0.00000000"], ["84065.27000000", "0.00306000"], ["84065.13000000", "0.00505000"], ["84064.78000000", "0.88145000"], ["84064.77000000", "0.89111000"], ["84064.24000000", "0.00000000"], ["84064.23000000", "0.00000000"], ["84062.55000000", "0.89111000"], ["84062.07000000", "0.00000000"], ["84061.31000000", "0.00000000"], ["84060.56000000", "0.84150000"], ["84060.12000000", "0.00000000"], ["84060.11000000", "0.00000000"], ["84059.62000000", "0.00831000"], ["84059.27000000", "0.00000000"], ["84059.02000000", "0.03855000"], ["84058.17000000", "0.00000000"], ["84058.15000000", "0.85696000"], ["84058.09000000", "0.00000000"], ["84057.60000000", "0.00213000"], ["84057.59000000", "0.00000000"], ["84056.55000000", "0.00000000"], ["84056.21000000", "0.00000000"], ["84056.15000000", "0.00000000"], ["84055.85000000", "0.86717000"], ["84055.22000000", "0.00000000"], ["84054.05000000", "0.59488000"], ["84052.99000000", "0.00000000"], ["84052.69000000", "0.00000000"], ["84051.90000000", "0.00000000"], ["84050.38000000", "0.00000000"], ["84049.85000000", "0.04000000"], ["84049.19000000", "0.00000000"], ["84048.87000000", "0.00059000"], ["84047.90000000", "0.37658000"], ["84047.89000000", "0.85706000"], ["84047.86000000", "0.00000000"], ["84047.62000000", "0.05838000"], ["84047.34000000", "0.25135000"], ["84047.11000000", "0.00000000"], ["84044.56000000", "0.00000000"], ["84044.15000000", "0.00000000"], ["84043.48000000", "0.25776000"], ["84043.15000000", "0.30079000"], ["84042.43000000", "0.00000000"], ["84042.27000000", "0.04942000"], ["84041.90000000", "0.00297000"], ["84040.19000000", "0.00000000"], ["84039.10000000", "0.00000000"], ["84035.82000000", "0.59407000"], ["84035.54000000", "0.25170000"], ["84035.17000000", "0.00000000"], ["84033.43000000", "0.05421000"], ["84032.80000000", "0.45058000"], ["84030.89000000", "0.00295000"], ["84028.61000000", "0.00298000"], ["84027.20000000", "0.00142000"], ["84026.09000000", "0.00000000"], ["84026.04000000", "0.00000000"], ["84025.35000000", "0.05000000"], ["84023.39000000", "0.04000000"], ["84023.16000000", "0.00000000"], ["84022.13000000", "0.04000000"], ["84019.81000000", "0.00000000"], ["84019.55000000", "0.00597000"], ["84017.51000000", "0.05496000"], ["84016.87000000", "0.09390000"], ["84015.33000000", "0.00000000"], ["84015.18000000", "0.00000000"], ["84014.97000000", "0.00000000"], ["84013.71000000", "1.00585000"], ["84013.29000000", "0.00000000"], ["84012.26000000", "0.09271000"], ["84012.18000000", "0.00000000"], ["84008.13000000", "0.00000000"], ["84008.12000000", "0.00000000"], ["84007.44000000", "0.00895000"], ["84006.81000000", "0.05235000"], ["84004.85000000", "0.00000000"], ["84004.11000000", "0.00147000"], ["84003.88000000", "0.03169000"], ["84003.04000000", "0.00213000"], ["83999.81000000", "0.00000000"], ["83999.62000000", "0.00000000"], ["83997.52000000", "0.00000000"], ["83997.43000000", "0.05097000"], ["83997.20000000", "0.00000000"], ["83996.54000000", "0.00000000"], ["83995.39000000", "0.09733000"], ["83994.23000000", "0.00000000"], ["83993.96000000", "0.00000000"], ["83993.82000000", "0.00000000"], ["83993.41000000", "0.01194000"], ["83992.70000000", "0.00000000"], ["83992.45000000", "0.05097000"], ["83991.24000000", "0.05197000"], ["83988.66000000", "0.00009000"], ["83987.95000000", "0.05097000"], ["83987.75000000", "0.00000000"], ["83985.65000000", "0.00000000"], ["83985.17000000", "0.00000000"], ["83984.63000000", "0.00000000"], ["83984.57000000", "0.01493000"], ["83984.27000000", "0.05097000"], ["83983.29000000", "0.00000000"], ["83982.49000000", "0.00000000"], ["83982.18000000", "0.00000000"], ["83980.28000000", "0.00000000"], ["83979.96000000", "0.05097000"], ["83979.36000000", "0.04197000"], ["83978.82000000", "0.00000000"], ["83978.81000000", "0.00000000"], ["83977.39000000", "0.10194000"], ["83974.47000000", "0.05097000"], ["83974.14000000", "0.08394000"], ["83973.58000000", "0.04097000"], ["83973.46000000", "0.00075000"], ["83973.22000000", "0.00000000"], ["83973.07000000", "0.05197000"], ["83972.94000000", "0.05097000"], ["83972.77000000", "0.04897000"], ["83971.87000000", "0.05097000"], ["83970.96000000", "0.04897000"], ["83969.12000000", "0.04197000"], ["83969.02000000", "0.05297000"], ["83967.50000000", "0.05297000"], ["83967.49000000", "0.04097000"], ["83965.77000000", "0.00235000"], ["83965.23000000", "0.04897000"], ["83964.89000000", "0.04197000"], ["83962.35000000", "0.04197000"], ["83962.00000000", "0.04097000"], ["83961.87000000", "0.04897000"], ["83960.86000000", "0.00013000"], ["83958.98000000", "0.04197000"], ["83937.33000000", "0.00000000"], ["83933.99000000", "0.00000000"], ["83933.14000000", "0.00000000"], ["83932.19000000", "0.00000000"], ["83931.44000000", "0.00000000"], ["83931.29000000", "0.00000000"], ["83930.34000000", "0.00000000"], ["83928.95000000", "0.00000000"], ["83928.05000000", "0.00000000"], ["83927.75000000", "0.01000000"], ["83907.92000000", "0.00000000"], ["83907.72000000", "0.00400000"], ["83902.65000000", "0.00000000"], ["83894.96000000", "0.00063000"], ["83894.81000000", "0.00000000"], ["83888.00000000", "0.00474000"], ["83886.26000000", "0.06796000"], ["83875.10000000", "0.00000000"], ["83869.85000000", "0.05624000"], ["83854.64000000", "0.00013000"], ["83851.55000000", "0.00000000"], ["83850.44000000", "0.00000000"], ["83817.63000000", "0.00000000"], ["83611.50000000", "0.00000000"], ["83611.46000000", "0.00040000"], ["83183.76000000", "0.00000000"], ["83183.64000000", "0.00040000"], ["82829.55000000", "0.00100000"], ["80680.44000000", "0.00000000"], ["79800.00000000", "8.29820000"], ["76700.00000000", "8.03713000"], ["75778.39000000", "0.00000000"], ["75686.00000000", "0.01324000"], ["75681.83000000", "0.00016000"], ["75681.00000000", "0.00000000"], ["67277.04000000", "0.00000000"], ["67272.74000000", "0.00058000"], ["42000.00000000", "6.85161000"], ["33000.00000000", "2.93827000"], ["20002.00000000", "0.00000000"], ["20001.00000000", "0.02099000"]], "a": [["84090.93000000", "3.49155000"], ["84090.94000000", "0.00039000"], ["84090.95000000", "0.00000000"], ["84091.41000000", "0.00000000"], ["84091.75000000", "0.00000000"], ["84091.85000000", "0.00000000"], ["84091.99000000", "0.00014000"], ["84092.00000000", "0.02260000"], ["84092.28000000", "0.00014000"], ["84092.29000000", "0.49070000"], ["84092.30000000", "0.00000000"], ["84092.31000000", "0.00006000"], ["84092.32000000", "0.00000000"], ["84092.38000000", "0.00000000"], ["84092.39000000", "0.00014000"], ["84092.40000000", "0.78522000"], ["84092.41000000", "0.12066000"], ["84092.53000000", "0.00000000"], ["84092.59000000", "0.00000000"], ["84092.62000000", "0.00000000"], ["84092.70000000", "0.00000000"], ["84092.71000000", "0.14006000"], ["84092.72000000", "0.00000000"], ["84092.73000000", "0.00000000"], ["84092.77000000", "0.00000000"], ["84092.79000000", "0.00000000"], ["84092.80000000", "0.34269000"], ["84093.24000000", "0.00000000"], ["84093.31000000", "0.00202000"], ["84093.35000000", "0.00007000"], ["84093.70000000", "0.15014000"], ["84093.80000000", "0.00000000"], ["84094.00000000", "0.02266000"], ["84094.06000000", "0.00000000"], ["84094.09000000", "0.00000000"], ["84094.21000000", "0.00000000"], ["84094.36000000", "0.00000000"], ["84094.37000000", "0.00000000"], ["84094.51000000", "0.00008000"], ["84094.52000000", "0.02382000"], ["84094.63000000", "0.04817000"], ["84094.70000000", "0.00000000"], ["84094.91000000", "0.00011000"], ["84094.94000000", "0.00000000"], ["84094.99000000", "0.00000000"], ["84095.05000000", "0.00000000"], ["84095.06000000", "0.00000000"], ["84095.11000000", "0.00000000"], ["84095.19000000", "0.08721000"], ["84095.20000000", "0.00000000"], ["84095.30000000", "0.00756000"], ["84095.33000000", "0.00000000"], ["84095.39000000", "0.00000000"], ["84095.40000000", "0.00000000"], ["84095.41000000", "0.00000000"], ["84095.42000000", "0.00000000"], ["84095.43000000", "0.00000000"], ["84095.82000000", "0.00000000"], ["84095.88000000", "0.00007000"], ["84095.90000000", "0.00000000"], ["84096.00000000", "0.02260000"], ["84096.17000000", "0.00000000"], ["84096.28000000", "0.00000000"], ["84096.29000000", "0.17926000"], ["84096.30000000", "0.00166000"], ["84096.31000000", "0.00000000"], ["84096.70000000", "0.00000000"], ["84096.92000000", "0.00000000"], ["84097.25000000", "0.00000000"], ["84097.28000000", "0.02707000"], ["84097.37000000", "0.01500000"], ["84097.57000000", "0.00000000"], ["84097.91000000", "0.00000000"], ["84097.92000000", "0.00000000"], ["84098.00000000", "0.02260000"], ["84098.43000000", "0.00138000"], ["84098.58000000", "0.04000000"], ["84098.63000000", "0.01500000"], ["84098.83000000", "0.00000000"], ["84099.00000000", "0.00000000"], ["84099.06000000", "0.00000000"], ["84099.43000000", "0.04000000"], ["84099.68000000", "0.00013000"], ["84099.86000000", "0.07690000"], ["84099.87000000", "0.05940000"], ["84099.88000000", "0.00000000"], ["84100.00000000", "0.02266000"], ["84100.27000000", "0.04800000"], ["84100.28000000", "0.05200000"], ["84100.35000000", "0.05200000"], ["84100.41000000", "0.00118000"], ["84100.80000000", "0.00006000"], ["84101.52000000", "0.00058000"], ["84101.65000000", "0.00000000"], ["84101.70000000", "0.00411000"], ["84102.00000000", "0.02260000"], ["84102.40000000", "0.00009000"], ["84102.69000000", "0.00000000"], ["84102.80000000", "0.07600000"], ["84102.83000000", "0.00000000"], ["84103.26000000", "0.16000000"], ["84103.30000000", "0.00013000"], ["84103.64000000", "0.07200000"], ["84103.68000000", "0.00000000"], ["84103.69000000", "0.54751000"], ["84103.70000000", "0.00000000"], ["84103.81000000", "0.04000000"], ["84104.00000000", "0.02260000"], ["84104.48000000", "0.06400000"], ["84104.49000000", "0.06400000"], ["84104.56000000", "0.06000000"], ["84104.58000000", "0.35644000"], ["84104.71000000", "0.00300000"], ["84104.72000000", "0.00376000"], ["84104.88000000", "0.00000000"], ["84104.89000000", "0.04784000"], ["84105.00000000", "0.00006000"], ["84106.00000000", "0.02260000"], ["84106.20000000", "0.00500000"], ["84106.58000000", "0.08304000"], ["84106.64000000", "0.05940000"], ["84106.76000000", "0.00000000"], ["84106.81000000", "0.01189000"], ["84106.88000000", "0.00000000"], ["84106.89000000", "0.00000000"], ["84107.15000000", "0.45000000"], ["84107.16000000", "0.00101000"], ["84107.23000000", "0.30804000"], ["84107.31000000", "0.00000000"], ["84107.48000000", "0.00000000"], ["84107.68000000", "0.00000000"], ["84107.74000000", "0.05940000"], ["84107.88000000", "0.61671000"], ["84107.89000000", "0.89111000"], ["84108.60000000", "0.09264000"], ["84108.73000000", "0.00000000"], ["84109.61000000", "0.00000000"], ["84109.90000000", "0.00118000"], ["84110.69000000", "0.89111000"], ["84111.40000000", "0.00000000"], ["84111.74000000", "0.00000000"], ["84111.96000000", "0.00000000"], ["84111.97000000", "0.00000000"], ["84112.04000000", "0.00000000"], ["84112.15000000", "0.00000000"], ["84112.53000000", "0.00000000"], ["84112.61000000", "0.00000000"], ["84112.65000000", "0.00029000"], ["84112.71000000", "0.00000000"], ["84112.77000000", "0.59407000"], ["84112.94000000", "0.97617000"], ["84112.95000000", "0.89111000"], ["84113.11000000", "0.89111000"], ["84113.12000000", "0.00359000"], ["84113.65000000", "0.00000000"], ["84113.83000000", "0.00000000"], ["84114.00000000", "0.00000000"], ["84114.25000000", "0.00000000"], ["84114.41000000", "0.00000000"], ["84115.97000000", "0.00000000"], ["84115.98000000", "1.85321000"], ["84116.00000000", "0.00000000"], ["84116.77000000", "0.00000000"], ["84117.34000000", "0.89111000"], ["84117.59000000", "0.00000000"], ["84117.86000000", "1.38129000"], ["84118.00000000", "0.00000000"], ["84118.02000000", "0.05940000"], ["84118.13000000", "0.85635000"], ["84118.14000000", "0.12840000"], ["84118.88000000", "0.00000000"], ["84119.51000000", "0.00000000"], ["84119.74000000", "0.89111000"], ["84119.87000000", "0.00000000"], ["84120.40000000", "0.00000000"], ["84120.67000000", "0.19428000"], ["84121.71000000", "0.00000000"], ["84122.06000000", "0.60051000"], ["84122.07000000", "0.00000000"], ["84122.26000000", "0.00000000"], ["84122.39000000", "0.00000000"], ["84122.64000000", "0.00000000"], ["84124.34000000", "0.00000000"], ["84124.73000000", "0.00000000"], ["84124.83000000", "0.00000000"], ["84125.99000000", "0.59484000"], ["84128.68000000", "0.69816000"], ["84129.28000000", "0.34921000"], ["84129.66000000", "0.25111000"], ["84129.73000000", "0.00000000"], ["84129.95000000", "0.00000000"], ["84130.27000000", "0.00000000"], ["84131.36000000", "0.00000000"], ["84131.83000000", "0.35644000"], ["84132.87000000", "0.91800000"], ["84132.98000000", "0.00059000"], ["84134.36000000", "0.00000000"], ["84135.25000000", "0.05929000"], ["84135.63000000", "0.11346000"], ["84136.25000000", "0.00000000"], ["84136.93000000", "1.23973000"], ["84137.13000000", "0.00000000"], ["84138.39000000", "0.00000000"], ["84138.66000000", "0.00000000"], ["84139.33000000", "0.00000000"], ["84139.98000000", "0.00000000"], ["84140.26000000", "0.00000000"], ["84140.38000000", "0.00000000"], ["84140.50000000", "0.00863000"], ["84141.47000000", "0.14866000"], ["84142.04000000", "0.00000000"], ["84142.37000000", "0.05200000"], ["84142.45000000", "0.00000000"], ["84146.30000000", "0.03609000"], ["84147.52000000", "0.59407000"], ["84147.74000000", "0.00000000"], ["84149.30000000", "0.00000000"], ["84151.39000000", "0.00000000"], ["84153.70000000", "0.24313000"], ["84153.79000000", "0.00000000"], ["84154.83000000", "0.02380000"], ["84156.07000000", "0.00000000"], ["84160.28000000", "0.00000000"], ["84163.29000000", "0.29796000"], ["84163.30000000", "0.50203000"], ["84163.73000000", "0.00000000"], ["84171.47000000", "0.04836000"], ["84171.64000000", "0.20363000"], ["84174.99000000", "0.00000000"], ["84179.50000000", "0.00000000"], ["84180.00000000", "0.02586000"], ["84184.87000000", "0.00298000"], ["84186.89000000", "0.00296000"], ["84186.90000000", "0.00000000"], ["84187.37000000", "0.33631000"], ["84189.71000000", "0.00000000"], ["84191.31000000", "0.00000000"], ["84191.81000000", "0.00000000"], ["84193.29000000", "0.00597000"], ["84195.21000000", "0.00000000"], ["84196.04000000", "0.00000000"], ["84196.93000000", "0.75274000"], ["84200.22000000", "0.00000000"], ["84201.70000000", "0.00895000"], ["84208.39000000", "0.00000000"], ["84208.64000000", "0.00000000"], ["84210.11000000", "0.01194000"], ["84217.05000000", "0.00000000"], ["84217.34000000", "0.05097000"], ["84217.62000000", "0.05297000"], ["84218.57000000", "0.01493000"], ["84219.65000000", "0.05097000"], ["84220.54000000", "0.05097000"], ["84220.59000000", "0.05097000"], ["84221.70000000", "0.05296000"], ["84221.92000000", "0.05297000"], ["84222.59000000", "0.05096000"], ["84223.12000000", "0.05097000"], ["84223.48000000", "0.05097000"], ["84223.50000000", "0.05097000"], ["84225.47000000", "0.00000000"], ["84225.75000000", "0.05096000"], ["84225.88000000", "0.00000000"], ["84226.10000000", "0.10594000"], ["84226.71000000", "0.00000000"], ["84246.07000000", "0.00000000"], ["84246.34000000", "0.00000000"], ["84246.60000000", "0.00000000"], ["84247.54000000", "0.00000000"], ["84247.72000000", "0.00000000"], ["84248.17000000", "0.00000000"], ["84248.59000000", "0.00000000"], ["84248.93000000", "0.00000000"], ["84249.81000000", "0.00000000"], ["84249.84000000", "0.00000000"], ["84250.20000000", "0.00000000"], ["84250.89000000", "0.00000000"], ["84251.52000000", "0.00000000"], ["84253.82000000", "0.00000000"], ["84254.81000000", "0.00000000"], ["84260.23000000", "0.01000000"], ["84262.14000000", "0.00000000"], ["84263.64000000", "0.00000000"], ["84264.04000000", "0.00000000"], ["84267.56000000", "0.99275000"], ["84282.08000000", "0.00000000"], ["84342.52000000", "0.00000000"], ["84414.67000000", "0.19428000"], ["84431.47000000", "0.00000000"], ["84433.35000000", "0.00000000"], ["84615.04000000", "0.00000000"], ["85358.74000000", "0.00000000"], ["85370.40000000", "0.08218000"], ["85391.70000000", "0.00007000"], ["150001.00000000", "0.00080000"]], "record_time": 1742554956.053222, "EXCHANGE": "BINANCE"}
{"e": "depthUpdate", "E": 1742554957014, "s": "BTCUSDT", "U": 64607012127, "u": 64607012238, "b": [["84090.92000000", "3.75901000"], ["84090.91000000", "0.00048000"], ["84090.90000000", "0.00015000"], ["84089.99000000", "0.00007000"], ["84089.88000000", "0.17318000"], ["84088.07000000", "0.00000000"], ["84086.03000000", "0.08742000"], ["84085.40000000", "0.00000000"], ["84080.93000000", "0.00096000"], ["84078.67000000", "0.00000000"], ["84073.10000000", "0.08304000"], ["84070.97000000", "0.00000000"], ["84068.86000000", "1.81743000"], ["84068.85000000", "1.36761000"], ["84068.37000000", "0.00000000"], ["84051.49000000", "0.00013000"], ["84041.69000000", "0.00000000"], ["84033.60000000", "0.05955000"], ["84024.19000000", "0.00000000"], ["83958.10000000", "0.00000000"], ["83949.60000000", "0.00006000"], ["83932.80000000", "0.05955000"], ["83929.24000000", "0.21406000"], ["83069.99000000", "0.02347000"], ["82829.55000000", "0.00000000"], ["80680.44000000", "0.00000000"], ["75681.83000000", "0.00032000"], ["75681.00000000", "0.00000000"], ["67272.74000000", "0.00058000"], ["33000.00000000", "2.93827000"]], "a": [["84090.97000000", "0.00008000"], ["84094.00000000", "0.02260000"], ["84094.63000000", "0.00000000"], ["84096.30000000", "0.00091000"], ["84097.28000000", "0.02682000"], ["84097.66000000", "0.04817000"], ["84112.52000000", "1.31250000"], ["84116.16000000", "0.00300000"], ["84117.86000000", "0.00000000"], ["84122.77000000", "0.05000000"], ["84123.99000000", "0.00000000"], ["84175.73000000", "0.00000000"], ["84179.68000000", "0.40999000"], ["84181.27000000", "0.00000000"], ["84192.54000000", "0.00000000"], ["84198.69000000", "0.00000000"], ["84213.76000000", "0.18314000"], ["84219.47000000", "0.05497000"], ["84223.71000000", "0.15530000"], ["84223.81000000", "0.05097000"], ["84230.59000000", "0.00000000"], ["84232.28000000", "0.00000000"], ["84232.75000000", "0.00000000"], ["84233.30000000", "0.00000000"], ["84234.32000000", "0.00000000"], ["84237.84000000", "0.00000000"], ["84240.91000000", "0.00000000"], ["84244.48000000", "0.00000000"], ["84245.72000000", "0.00000000"], ["84247.53000000", "0.00000000"], ["84248.50000000", "0.00000000"], ["84248.53000000", "0.00000000"], ["84419.53000000", "0.00000000"], ["84426.85000000", "0.00000000"], ["84606.64000000", "0.00015000"], ["85349.10000000", "0.11734000"], ["85352.30000000", "0.00100000"]], "record_time": 1742554957.065216, "EXCHANGE": "BINANCE"}
{"e": "depthUpdate", "E": 1742554958014, "s": "BTCUSDT", "U": 64607012239, "u": 64607012343, "b": [["84090.92000000", "3.57538000"], ["84090.81000000", "0.00007000"], ["84090.80000000", "0.00014000"], ["84089.88000000", "0.17318000"], ["84088.10000000", "0.00000000"], ["84088.00000000", "0.00000000"], ["84087.96000000", "0.02440000"], ["84087.54000000", "0.59414000"], ["84086.03000000", "0.08735000"], ["84085.18000000", "0.02344000"], ["84083.75000000", "0.00759000"], ["84080.47000000", "0.00000000"], ["84078.00000000", "0.00300000"], ["84077.90000000", "0.00000000"], ["84067.72000000", "0.00000000"], ["84065.70000000", "0.00059000"], ["84051.49000000", "0.00013000"], ["84048.34000000", "0.00000000"], ["84003.61000000", "0.00100000"], ["83998.25000000", "0.00000000"], ["83990.16000000", "0.01862000"], ["83970.07000000", "0.00000000"], ["83957.01000000", "0.00010000"], ["83957.00000000", "0.00113000"], ["82829.55000000", "0.00100000"], ["76700.00000000", "8.07259000"], ["75681.00000000", "0.00000000"], ["67272.74000000", "0.00058000"], ["33000.00000000", "2.93827000"]], "a": [["84090.93000000", "3.80517000"], ["84095.90000000", "0.00000000"], ["84096.60000000", "0.00006000"], ["84099.86000000", "0.12410000"], ["84101.88000000", "0.10702000"], ["84104.06000000", "0.00000000"], ["84104.73000000", "0.00911000"], ["84104.89000000", "0.02338000"], ["84106.20000000", "0.00500000"], ["84107.87000000", "0.71284000"], ["84108.10000000", "0.00000000"], ["84108.17000000", "0.01862000"], ["84111.15000000", "0.00831000"], ["84116.16000000", "0.00359000"], ["84116.19000000", "0.00000000"], ["84126.00000000", "0.00006000"], ["84130.12000000", "0.00000000"], ["84141.30000000", "0.00000000"], ["84151.40000000", "0.00000000"], ["84154.83000000", "0.00000000"], ["84172.90000000", "0.02380000"], ["84173.23000000", "0.06841000"], ["84178.23000000", "0.00100000"], ["84181.99000000", "0.00000000"], ["84209.53000000", "0.05497000"], ["84213.44000000", "0.05497000"], ["84216.29000000", "0.05497000"], ["84219.05000000", "0.05497000"], ["84219.47000000", "0.00000000"], ["84223.27000000", "0.05497000"], ["84223.71000000", "0.10033000"], ["84224.76000000", "0.00006000"], ["84224.98000000", "0.00000000"], ["84228.45000000", "0.00000000"], ["84228.47000000", "0.00000000"], ["84229.87000000", "0.00000000"], ["84231.16000000", "0.02497000"], ["84233.61000000", "0.00000000"], ["84245.33000000", "0.00000000"], ["84245.60000000", "0.00000000"], ["84245.70000000", "0.00000000"], ["84246.02000000", "0.17822000"], ["84266.13000000", "0.00000000"], ["84266.14000000", "0.00066000"], ["85352.30000000", "0.00000000"]], "record_time": 1742554958.036133, "EXCHANGE": "BINANCE"}
{"e": "depthUpdate", "E": 1742554959014, "s": "BTCUSDT", "U": 64607012344, "u": 64607012414, "b": [["84090.92000000", "3.57354000"], ["84084.00000000", "0.00000000"], ["84076.22000000", "0.00000000"], ["84068.97000000", "1.34015000"], ["84068.85000000", "0.00000000"], ["84048.69000000", "0.00000000"], ["84043.00000000", "0.00000000"], ["83998.72000000", "0.01875000"], ["83990.16000000", "0.00000000"], ["83973.47000000", "0.00075000"], ["83973.46000000", "0.00000000"], ["83927.75000000", "0.01000000"], ["83894.97000000", "0.00063000"], ["83894.96000000", "0.00000000"], ["82829.55000000", "0.00000000"], ["80680.44000000", "0.03567000"], ["75681.00000000", "0.00000000"], ["67272.74000000", "0.00058000"], ["60000.00000000", "73.17018000"], ["33000.00000000", "2.93827000"], ["30272.73000000", "0.00020000"]], "a": [["84090.93000000", "3.35619000"], ["84095.90000000", "0.02403000"], ["84096.30000000", "0.00000000"], ["84096.60000000", "0.00000000"], ["84097.05000000", "0.00008000"], ["84100.80000000", "0.02369000"], ["84105.82000000", "0.00006000"], ["84107.86000000", "1.13262000"], ["84107.87000000", "0.00000000"], ["84107.88000000", "0.00000000"], ["84108.17000000", "0.00000000"], ["84108.70000000", "0.10031000"], ["84112.52000000", "0.00000000"], ["84112.58000000", "1.32012000"], ["84117.33000000", "0.59488000"], ["84125.99000000", "0.00000000"], ["84141.31000000", "0.00000000"], ["84181.27000000", "1.10924000"], ["84260.23000000", "0.01000000"], ["84261.14000000", "0.99294000"], ["84267.56000000", "0.00000000"], ["84350.00000000", "10.20752000"], ["85352.30000000", "0.00100000"]], "record_time": 1742554959.050325, "EXCHANGE": "BINANCE"}
{"e": "depthUpdate", "E": 1742554960014, "s": "BTCUSDT", "U": 64607012415, "u": 64607012545, "b": [["84090.92000000", "3.57278000"], ["84087.33000000", "0.02381000"], ["84086.70000000", "0.01000000"], ["84082.57000000", "0.00000000"], ["84081.69000000", "0.78532000"], ["84080.93000000", "0.00000000"], ["84080.91000000", "0.00096000"], ["84080.02000000", "0.00000000"], ["84078.00000000", "0.00000000"], ["84074.71000000", "0.10703000"], ["84069.39000000", "1.35476000"], ["84068.97000000", "0.00000000"], ["84068.86000000", "1.31326000"], ["84065.34000000", "0.00000000"], ["84061.70000000", "0.85692000"], ["84057.60000000", "0.00000000"], ["84055.40000000", "0.00213000"], ["84047.90000000", "0.00000000"], ["84047.89000000", "0.00000000"], ["84047.17000000", "0.05000000"], ["84041.90000000", "0.00000000"], ["84040.01000000", "0.00297000"], ["84037.80000000", "0.00006000"], ["84030.89000000", "0.00000000"], ["84030.08000000", "0.00297000"], ["84003.04000000", "0.00000000"], ["84001.05000000", "0.00213000"], ["83998.72000000", "0.00013000"], ["83965.77000000", "0.00000000"], ["83964.06000000", "0.00235000"], ["83963.70000000", "0.00000000"], ["83955.58000000", "0.00118000"], ["83954.96000000", "0.00000000"], ["83945.90000000", "0.00118000"], ["83914.87000000", "0.00400000"], ["83907.72000000", "0.00000000"], ["83887.50000000", "0.00000000"], ["83880.01000000", "0.00167000"], ["83250.01000000", "0.00000000"], ["82829.55000000", "0.00100000"], ["76700.00000000", "8.07283000"], ["75681.84000000", "0.00000000"], ["75681.00000000", "0.00000000"], ["67272.74000000", "0.00058000"], ["33000.00000000", "2.93827000"]], "a": [["84090.93000000", "3.24947000"], ["84091.76000000", "0.00014000"], ["84091.77000000", "0.11115000"], ["84091.78000000", "0.00000000"], ["84091.82000000", "0.00000000"], ["84091.98000000", "0.00000000"], ["84091.99000000", "0.00000000"], ["84092.29000000", "0.34258000"], ["84092.39000000", "0.00014000"], ["84092.80000000", "0.04728000"], ["84093.70000000", "0.00006000"], ["84095.90000000", "0.00000000"], ["84096.16000000", "0.02429000"], ["84098.79000000", "0.15008000"], ["84101.88000000", "0.00000000"], ["84103.78000000", "0.00000000"], ["84106.20000000", "0.00000000"], ["84107.74000000", "0.00000000"], ["84107.88000000", "0.71284000"], ["84112.58000000", "0.00000000"], ["84112.59000000", "1.33005000"], ["84116.15000000", "0.05940000"], ["84117.27000000", "0.85635000"], ["84117.62000000", "0.05000000"], ["84118.13000000", "0.00000000"], ["84122.77000000", "0.00000000"], ["84125.05000000", "0.00084000"], ["84138.78000000", "0.00000000"], ["84175.35000000", "0.00296000"], ["84175.83000000", "0.04344000"], ["84176.57000000", "0.06400000"], ["84179.67000000", "0.00090000"], ["84179.68000000", "0.40999000"], ["84181.27000000", "0.00000000"], ["84184.86000000", "0.00297000"], ["84186.89000000", "0.00000000"], ["84191.28000000", "0.00000000"], ["84203.64000000", "0.00000000"], ["84208.49000000", "0.00000000"], ["84245.22000000", "0.00000000"], ["84259.45000000", "0.00118000"], ["84268.33000000", "0.00000000"], ["84269.37000000", "0.00118000"], ["84282.89000000", "0.00000000"], ["85352.30000000", "0.00000000"]], "record_time": 1742554960.037387, "EXCHANGE": "BINANCE"}
{"e": "depthUpdate", "E": 1742554961014, "s": "BTCUSDT", "U": 64607012546, "u": 64607012657, "b": [["84090.92000000", "3.51779000"], ["84084.00000000", "0.00006000"], ["84080.91000000", "0.00000000"], ["84069.46000000", "1.34361000"], ["84069.39000000", "0.00000000"], ["84047.86000000", "0.19949000"], ["84047.17000000", "0.00000000"], ["84044.20000000", "0.00000000"], ["84037.20000000", "0.00000000"], ["83775.58000000", "0.00011000"], ["83667.12000000", "0.00000000"], ["83649.45000000", "0.00011000"], ["82829.55000000", "0.00000000"], ["82150.48000000", "0.00000000"], ["75681.00000000", "0.00000000"], ["67272.74000000", "0.00058000"], ["33000.00000000", "2.93827000"], ["20002.00000000", "0.00000000"], ["20001.00000000", "0.02099000"]], "a": [["84090.93000000", "3.04554000"], ["84091.10000000", "0.00044000"], ["84091.13000000", "0.00000000"], ["84091.14000000", "0.00000000"], ["84091.15000000", "0.00000000"], ["84091.16000000", "0.00000000"], ["84091.25000000", "0.00000000"], ["84091.76000000", "0.00000000"], ["84091.77000000", "0.00000000"], ["84091.99000000", "0.00014000"], ["84095.19000000", "0.15497000"], ["84096.16000000", "0.00000000"], ["84096.60000000", "0.00006000"], ["84100.80000000", "0.00006000"], ["84101.83000000", "0.10703000"], ["84104.73000000", "0.00000000"], ["84105.27000000", "0.85648000"], ["84112.59000000", "1.37408000"], ["84117.49000000", "0.00000000"], ["84144.45000000", "0.00000000"], ["84153.93000000", "0.03464000"], ["84157.90000000", "0.02380000"], ["84172.81000000", "0.00841000"], ["84172.90000000", "0.00000000"], ["84173.23000000", "0.06000000"], ["85352.30000000", "0.00100000"]], "record_time": 1742554961.035967, "EXCHANGE": "BINANCE"}
{"e": "depthUpdate", "E": 1742554962014, "s": "BTCUSDT", "U": 64607012658, "u": 64607012813, "b": [["84090.92000000", "4.01912000"], ["84089.91000000", "0.00011000"], ["84089.88000000", "0.23866000"], ["84087.96000000", "0.02440000"], ["84087.92000000", "0.04824000"], ["84087.90000000", "0.00000000"], ["84087.33000000", "0.02374000"], ["84086.90000000", "0.15633000"], ["84086.70000000", "0.01000000"], ["84086.03000000", "0.03519000"], ["84084.80000000", "0.00008000"], ["84083.76000000", "0.00000000"], ["84082.51000000", "0.00000000"], ["84081.76000000", "0.78532000"], ["84081.69000000", "0.00000000"], ["84072.46000000", "0.00000000"], ["84067.72000000", "0.00912000"], ["84065.98000000", "0.00000000"], ["84050.06000000", "0.00000000"], ["84046.42000000", "0.00000000"], ["84037.20000000", "0.00000000"], ["83978.57000000", "0.00000000"], ["83959.16000000", "0.18315000"], ["83926.67000000", "0.00400000"], ["83921.56000000", "0.00000000"], ["83921.27000000", "0.00000000"], ["83914.87000000", "0.00000000"], ["82829.55000000", "0.00100000"], ["79800.00000000", "8.29820000"], ["75681.00000000", "0.00000000"], ["67272.74000000", "0.00058000"], ["33000.00000000", "2.93827000"]], "a": [["84090.93000000", "2.65534000"], ["84091.09000000", "0.00014000"], ["84091.10000000", "0.10430000"], ["84091.99000000", "0.00000000"], ["84092.16000000", "0.01615000"], ["84092.71000000", "0.14000000"], ["84092.80000000", "0.00728000"], ["84096.16000000", "0.00000000"], ["84104.75000000", "0.00898000"], ["84105.00000000", "0.02339000"], ["84107.88000000", "0.00000000"], ["84117.33000000", "0.00000000"], ["84120.66000000", "0.59487000"], ["84157.90000000", "0.02380000"], ["84164.17000000", "0.00041000"], ["84164.76000000", "0.05978000"], ["84175.99000000", "0.00000000"], ["84178.52000000", "0.00000000"], ["84183.84000000", "0.60768000"], ["84184.09000000", "1.10924000"], ["84239.62000000", "0.00035000"], ["84251.84000000", "0.00000000"], ["85352.30000000", "0.00000000"]], "record_time": 1742554962.036775, "EXCHANGE": "BINANCE"}
{"e": "depthUpdate", "E": 1742554963014, "s": "BTCUSDT", "U": 64607012814, "u": 64607012870, "b": [["84090.92000000", "3.82028000"], ["84072.46000000", "0.05940000"], ["84069.46000000", "0.00000000"], ["84069.45000000", "1.34115000"], ["84065.98000000", "0.00000000"], ["84050.06000000", "0.00000000"], ["84049.25000000", "0.00000000"], ["84044.55000000", "0.05000000"], ["83238.89000000", "0.00000000"], ["83237.18000000", "0.00079000"], ["82829.55000000", "0.00000000"], ["82382.73000000", "0.00030000"], ["75681.00000000", "0.00000000"], ["67272.74000000", "0.00058000"], ["33000.00000000", "2.93827000"]], "a": [["84090.93000000", "2.67271000"], ["84100.97000000", "0.00000000"], ["84112.59000000", "0.00000000"], ["84114.25000000", "1.31044000"], ["84261.14000000", "0.99069000"], ["84279.02000000", "0.00000000"], ["85352.30000000", "0.00100000"]], "record_time": 1742554963.036253, "EXCHANGE": "BINANCE"}
{"e": "depthUpdate", "E": 1742554964014, "s": "BTCUSDT", "U": 64607012871, "u": 64607013026, "b": [["84090.92000000", "4.66493000"], ["84088.10000000", "0.00000000"], ["84088.00000000", "0.00000000"], ["84086.70000000", "0.00500000"], ["84086.03000000", "0.26636000"], ["84084.00000000", "0.00006000"], ["84083.60000000", "0.00000000"], ["84083.43000000", "0.78531000"], ["84083.40000000", "0.00000000"], ["84082.32000000", "0.00000000"], ["84081.76000000", "0.00000000"], ["84080.47000000", "0.00000000"], ["84080.45000000", "0.00416000"], ["84080.42000000", "0.00000000"], ["84078.00000000", "0.00000000"], ["84077.90000000", "0.00000000"], ["84077.27000000", "0.00000000"], ["84069.45000000", "0.00000000"], ["84069.44000000", "1.36815000"], ["84065.61000000", "0.85688000"], ["84055.61000000", "0.31713000"], ["84050.20000000", "0.48119000"], ["84050.06000000", "0.00000000"], ["84050.03000000", "0.00000000"], ["84045.20000000", "0.00000000"], ["84044.55000000", "0.00000000"], ["84003.24000000", "0.00000000"], ["84000.91000000", "1.15248000"], ["84000.30000000", "1.38873000"], ["83992.59000000", "0.58812000"], ["83991.82000000", "0.00000000"], ["83952.89000000", "0.00000000"], ["83952.48000000", "0.01524000"], ["83932.43000000", "0.00400000"], ["83927.75000000", "0.01000000"], ["83926.67000000", "0.00000000"], ["83239.73000000", "0.00060000"], ["83181.83000000", "0.00000000"], ["83181.58000000", "0.00060000"], ["83181.47000000", "0.00000000"], ["83003.26000000", "0.00000000"], ["82994.90000000", "0.40000000"], ["82829.55000000", "0.00100000"], ["80100.00000000", "8.78894000"], ["75681.83000000", "0.00064000"], ["75681.00000000", "0.00050000"], ["67272.74000000", "0.00058000"], ["33000.00000000", "2.93827000"]], "a": [["84090.93000000", "2.55129000"], ["84092.16000000", "0.00000000"], ["84092.38000000", "0.00000000"], ["84092.40000000", "0.78522000"], ["84096.60000000", "0.00006000"], ["84100.93000000", "0.00096000"], ["84112.60000000", "1.33336000"], ["84114.25000000", "0.00000000"], ["84117.62000000", "0.00000000"], ["84120.66000000", "0.00000000"], ["84124.11000000", "0.59485000"], ["84139.13000000", "0.00000000"], ["84141.30000000", "0.00000000"], ["84151.40000000", "0.00000000"], ["84157.90000000", "0.00000000"], ["84172.81000000", "0.00000000"], ["84172.88000000", "0.02380000"], ["84173.23000000", "0.06841000"], ["84211.62000000", "0.01524000"], ["84212.04000000", "0.04763000"], ["84213.43000000", "0.05297000"], ["84216.29000000", "0.00000000"], ["84216.54000000", "0.05297000"], ["84217.76000000", "0.05497000"], ["84219.05000000", "0.00000000"], ["84220.53000000", "0.05497000"], ["84220.79000000", "0.05297000"], ["84223.27000000", "0.00000000"], ["84223.89000000", "0.05097000"], ["84225.40000000", "0.05497000"], ["84231.16000000", "0.00000000"], ["84242.37000000", "0.05397000"], ["84243.98000000", "0.00000000"], ["84244.01000000", "0.00000000"], ["84245.09000000", "0.00000000"], ["84259.10000000", "0.01141000"], ["84260.23000000", "0.01000000"], ["84721.43000000", "0.00000000"], ["84781.03000000", "0.00073000"], ["85035.47000000", "0.60000000"], ["85043.92000000", "0.00000000"], ["85352.30000000", "0.00000000"]], "record_time": 1742554964.036832, "EXCHANGE": "BINANCE"}
{"e": "depthUpdate", "E": 1742554965014, "s": "BTCUSDT", "U": 64607013027, "u": 64607013493, "b": [["84090.92000000", "7.06948000"], ["84090.90000000", "0.00029000"], ["84090.89000000", "0.09021000"], ["84090.65000000", "0.00015000"], ["84090.01000000", "0.00014000"], ["84090.00000000", "0.02273000"], ["84089.99000000", "0.00000000"], ["84089.88000000", "0.23866000"], ["84088.14000000", "0.02391000"], ["84087.96000000", "0.02439000"], ["84087.92000000", "0.00000000"], ["84087.55000000", "0.00034000"], ["84087.54000000", "0.02378000"], ["84087.32000000", "0.02378000"], ["84086.90000000", "0.00000000"], ["84085.88000000", "0.00000000"], ["84084.77000000", "0.08323000"], ["84083.93000000", "0.11890000"], ["84083.74000000", "0.00594000"], ["84083.73000000", "0.05945000"], ["84083.54000000", "0.00000000"], ["84083.43000000", "0.00000000"], ["84083.33000000", "0.05945000"], ["84083.30000000", "0.08323000"], ["84083.26000000", "0.00594000"], ["84082.90000000", "0.05945000"], ["84082.89000000", "0.05945000"], ["84082.83000000", "0.00594000"], ["84082.02000000", "0.08304000"], ["84081.51000000", "0.08992000"], ["84081.23000000", "0.00118000"], ["84080.93000000", "0.00000000"], ["84080.48000000", "0.00422000"], ["84080.45000000", "0.00000000"], ["84079.38000000", "0.05071000"], ["84077.36000000", "0.04942000"], ["84075.79000000", "0.00000000"], ["84074.02000000", "0.59478000"], ["84073.32000000", "0.85680000"], ["84071.53000000", "0.00118000"], ["84068.21000000", "0.59407000"], ["84066.92000000", "0.08992000"], ["84066.51000000", "0.11890000"], ["84064.12000000", "0.85690000"], ["84061.70000000", "0.00000000"], ["84061.31000000", "0.00000000"], ["84058.51000000", "0.01188000"], ["84058.15000000", "0.00000000"], ["84058.13000000", "0.00000000"], ["84057.67000000", "0.00594000"], ["84057.23000000", "0.00000000"], ["84055.61000000", "0.00006000"], ["84054.86000000", "0.00000000"], ["84054.05000000", "0.00000000"], ["84053.97000000", "0.00000000"], ["84053.23000000", "0.00000000"], ["84052.60000000", "0.00000000"], ["84051.89000000", "0.05749000"], ["84050.38000000", "0.05949000"], ["84049.86000000", "0.00000000"], ["84047.62000000", "0.00000000"], ["84042.27000000", "0.00000000"], ["84038.21000000", "0.00000000"], ["84035.82000000", "0.00000000"], ["84033.60000000", "0.00006000"], ["84006.05000000", "0.71854000"], ["84000.30000000", "0.00000000"], ["82829.55000000", "0.00000000"], ["80697.27000000", "0.03567000"], ["80680.44000000", "0.00000000"], ["75681.00000000", "0.00000000"], ["67272.74000000", "0.00058000"], ["42000.00000000", "6.85261000"], ["33000.00000000", "2.93827000"]], "a": [["84090.93000000", "0.10938000"], ["84090.97000000", "0.00000000"], ["84091.01000000", "0.00000000"], ["84091.09000000", "0.00000000"], ["84091.10000000", "0.00000000"], ["84091.66000000", "0.00007000"], ["84092.00000000", "0.00000000"], ["84092.20000000", "0.00108000"], ["84092.28000000", "0.00000000"], ["84092.29000000", "0.00000000"], ["84092.31000000", "0.00000000"], ["84092.32000000", "0.00000000"], ["84092.39000000", "0.00000000"], ["84092.40000000", "0.00000000"], ["84092.41000000", "0.00000000"], ["84092.51000000", "0.00007000"], ["84092.71000000", "0.00000000"], ["84092.79000000", "0.00014000"], ["84093.70000000", "0.00000000"], ["84094.00000000", "0.00129000"], ["84094.08000000", "0.00000000"], ["84094.09000000", "0.00000000"], ["84094.51000000", "0.00022000"], ["84094.52000000", "0.02388000"], ["84094.91000000", "0.00000000"], ["84095.18000000", "0.00000000"], ["84095.19000000", "0.00000000"], ["84095.34000000", "0.00000000"], ["84095.60000000", "0.00000000"], ["84096.00000000", "0.00000000"], ["84096.16000000", "0.00000000"], ["84096.27000000", "0.00000000"], ["84096.28000000", "0.00000000"], ["84096.29000000", "0.00104000"], ["84096.45000000", "0.00000000"], ["84096.46000000", "0.00000000"], ["84096.60000000", "0.00006000"], ["84096.89000000", "0.00000000"], ["84096.99000000", "0.00014000"], ["84097.00000000", "0.02000000"], ["84097.09000000", "0.00014000"], ["84097.10000000", "0.04000000"], ["84097.44000000", "0.00000000"], ["84097.49000000", "0.00007000"], ["84097.50000000", "0.08000000"], ["84097.66000000", "0.00000000"], ["84098.44000000", "0.00000000"], ["84098.46000000", "0.05167000"], ["84098.75000000", "0.02206000"], ["84098.79000000", "0.00000000"], ["84099.69000000", "0.00000000"], ["84099.87000000", "0.05940000"], ["84100.93000000", "0.00000000"], ["84100.96000000", "0.00095000"], ["84101.68000000", "0.00000000"], ["84101.83000000", "0.00000000"], ["84102.32000000", "0.00000000"], ["84103.81000000", "0.00000000"], ["84104.31000000", "0.00000000"], ["84104.41000000", "0.00000000"], ["84104.52000000", "0.15008000"], ["84104.75000000", "0.00000000"], ["84105.05000000", "0.00000000"], ["84105.27000000", "0.00000000"], ["84106.51000000", "0.00011000"], ["84106.64000000", "0.00000000"], ["84107.15000000", "0.00000000"], ["84107.71000000", "0.04000000"], ["84107.75000000", "0.45000000"], ["84108.60000000", "0.00000000"], ["84108.74000000", "0.00000000"], ["84110.02000000", "0.04817000"], ["84111.15000000", "0.00000000"], ["84112.60000000", "0.00000000"], ["84113.66000000", "0.00000000"], ["84115.67000000", "0.00831000"], ["84115.99000000", "0.00000000"], ["84116.40000000", "0.00000000"], ["84117.59000000", "0.00000000"], ["84118.14000000", "0.00000000"], ["84119.80000000", "0.85633000"], ["84121.41000000", "0.00000000"], ["84123.27000000", "0.00000000"], ["84124.11000000", "0.00000000"], ["84125.33000000", "0.00000000"], ["84129.27000000", "0.00000000"], ["84129.28000000", "0.00000000"], ["84134.84000000", "0.00000000"], ["84139.47000000", "0.59477000"], ["84146.30000000", "0.00000000"], ["84146.49000000", "0.34838000"], ["84153.93000000", "0.00013000"], ["84157.92000000", "0.00000000"], ["84163.60000000", "0.03451000"], ["84169.22000000", "0.03609000"], ["84175.83000000", "0.00000000"], ["84184.09000000", "0.00000000"], ["84202.82000000", "0.44500000"], ["84206.98000000", "0.05497000"], ["84211.21000000", "0.10253000"], ["84211.48000000", "0.09730000"], ["84212.99000000", "0.05297000"], ["84213.20000000", "0.05497000"], ["84214.73000000", "0.05097000"], ["84214.93000000", "0.05497000"], ["84216.11000000", "0.05097000"], ["84217.76000000", "0.00000000"], ["84217.90000000", "0.05097000"], ["84218.28000000", "0.05297000"], ["84218.40000000", "0.05503000"], ["84219.31000000", "0.00000000"], ["84220.53000000", "0.00000000"], ["84220.75000000", "0.05097000"], ["84221.94000000", "0.05497000"], ["84223.25000000", "0.00000000"], ["84225.40000000", "0.00000000"], ["84230.72000000", "0.02497000"], ["84239.49000000", "0.00000000"], ["84239.98000000", "0.00000000"], ["84241.22000000", "0.00000000"], ["84242.22000000", "0.00000000"], ["84242.37000000", "0.00000000"], ["84242.74000000", "0.00000000"], ["84243.23000000", "0.00000000"], ["84244.77000000", "0.04635000"], ["84324.00000000", "0.45235000"], ["84415.32000000", "0.00000000"], ["84544.15000000", "0.12792000"], ["84931.82000000", "0.00000000"], ["85352.30000000", "0.00100000"], ["85370.40000000", "0.02352000"], ["85391.70000000", "0.05873000"], ["150001.00000000", "0.00084000"]], "record_time": 1742554965.037087, "EXCHANGE": "BINANCE"}
{"e": "depthUpdate", "E": 1742554966014, "s": "BTCUSDT", "U": 64607013494, "u": 64607015675, "b": [["84099.85000000", "6.14278000"], ["84099.84000000", "0.00049000"], ["84099.67000000", "0.00036000"], ["84098.78000000", "0.00021000"], ["84098.77000000", "0.73545000"], ["84098.76000000", "0.00014000"], ["84098.75000000", "0.78543000"], ["84098.74000000", "0.00007000"], ["84098.43000000", "0.00000000"], ["84098.42000000", "0.45020000"], ["84098.00000000", "0.02273000"], ["84097.99000000", "0.00000000"], ["84097.49000000", "0.00000000"], ["84097.46000000", "0.00000000"], ["84097.37000000", "0.00000000"], ["84097.36000000", "0.00000000"], ["84097.28000000", "0.00000000"], ["84097.27000000", "0.00000000"], ["84097.09000000", "0.00000000"], ["84097.08000000", "0.00000000"], ["84096.99000000", "0.00000000"], ["84096.34000000", "0.00000000"], ["84096.29000000", "0.00000000"], ["84096.28000000", "0.00000000"], ["84096.27000000", "0.02380000"], ["84096.11000000", "0.00058000"], ["84096.09000000", "0.00000000"], ["84096.00000000", "0.02266000"], ["84095.83000000", "0.00000000"], ["84095.81000000", "0.00000000"], ["84095.80000000", "0.00000000"], ["84095.72000000", "0.00000000"], ["84095.71000000", "0.00000000"], ["84095.70000000", "0.00000000"], ["84095.60000000", "0.00500000"], ["84095.30000000", "0.00000000"], ["84095.29000000", "0.00000000"], ["84095.03000000", "0.00000000"], ["84094.67000000", "0.00000000"], ["84094.58000000", "0.97530000"], ["84094.57000000", "0.00000000"], ["84094.56000000", "0.80246000"], ["84094.55000000", "1.08331000"], ["84094.54000000", "0.00000000"], ["84094.52000000", "0.00059000"], ["84094.51000000", "0.00000000"], ["84094.40000000", "0.00000000"], ["84094.20000000", "0.00000000"], ["84094.01000000", "0.00000000"], ["84094.00000000", "0.02260000"], ["84093.79000000", "0.00000000"], ["84092.91000000", "0.00000000"], ["84092.89000000", "0.00000000"], ["84092.82000000", "0.00000000"], ["84092.81000000", "0.00000000"], ["84092.80000000", "0.00000000"], ["84092.79000000", "0.45000000"], ["84092.78000000", "0.00000000"], ["84092.52000000", "0.00000000"], ["84092.19000000", "0.00000000"], ["84092.05000000", "0.00000000"], ["84092.04000000", "0.16429000"], ["84092.00000000", "0.02260000"], ["84091.92000000", "0.00000000"], ["84091.90000000", "0.00118000"], ["84091.68000000", "0.08000000"], ["84091.15000000", "0.00000000"], ["84091.04000000", "0.00000000"], ["84091.02000000", "0.00000000"], ["84090.93000000", "0.17822000"], ["84090.92000000", "0.61319000"], ["84090.91000000", "0.00000000"], ["84090.90000000", "0.00000000"], ["84090.89000000", "0.00000000"], ["84090.83000000", "0.00000000"], ["84090.81000000", "0.00000000"], ["84090.80000000", "0.00000000"], ["84090.65000000", "0.00008000"], ["84090.33000000", "0.00006000"], ["84090.20000000", "0.00000000"], ["84090.09000000", "0.00035000"], ["84090.08000000", "0.04000000"], ["84090.02000000", "0.00000000"], ["84090.01000000", "0.00000000"], ["84090.00000000", "0.02260000"], ["84089.91000000", "0.00000000"], ["84089.89000000", "0.00000000"], ["84089.88000000", "0.00000000"], ["84089.71000000", "0.00000000"], ["84089.47000000", "0.00000000"], ["84089.35000000", "0.00013000"], ["84089.23000000", "0.00000000"], ["84089.14000000", "0.00000000"], ["84088.92000000", "0.00000000"], ["84088.71000000", "0.04000000"], ["84088.20000000", "0.00006000"], ["84088.16000000", "0.00000000"], ["84088.15000000", "0.00000000"], ["84088.14000000", "0.02378000"], ["84087.97000000", "0.07067000"], ["84087.96000000", "0.02433000"], ["84087.74000000", "0.03000000"], ["84087.55000000", "0.00000000"], ["84087.54000000", "0.02378000"], ["84087.45000000", "0.00000000"], ["84087.33000000", "0.00000000"], ["84087.32000000", "0.00000000"], ["84087.16000000", "0.04000000"], ["84087.12000000", "0.00059000"], ["84087.06000000", "0.00013000"], ["84086.76000000", "0.00000000"], ["84086.70000000", "0.00500000"], ["84086.44000000", "0.00118000"], ["84086.43000000", "0.01189000"], ["84086.33000000", "0.08000000"], ["84086.20000000", "0.04000000"], ["84086.04000000", "0.00000000"], ["84086.03000000", "0.86322000"], ["84085.99000000", "0.30448000"], ["84085.88000000", "0.04000000"], ["84085.29000000", "0.00000000"], ["84085.19000000", "0.00000000"], ["84085.12000000", "0.16000000"], ["84085.10000000", "0.04000000"], ["84085.00000000", "0.00000000"], ["84084.79000000", "0.00000000"], ["84084.38000000", "0.06000000"], ["84084.25000000", "0.00000000"], ["84084.12000000", "0.04000000"], ["84083.41000000", "0.04942000"], ["84083.34000000", "0.00000000"], ["84083.30000000", "0.00000000"], ["84083.09000000", "0.00000000"], ["84083.03000000", "0.77224000"], ["84083.02000000", "0.17835000"], ["84082.96000000", "0.04000000"], ["84082.94000000", "0.17835000"], ["84082.90000000", "0.00000000"], ["84082.70000000", "0.85671000"], ["84082.59000000", "0.00000000"], ["84082.54000000", "0.00000000"], ["84082.12000000", "0.04000000"], ["84082.01000000", "0.00000000"], ["84081.66000000", "0.00000000"], ["84081.60000000", "0.00000000"], ["84081.44000000", "0.00000000"], ["84081.23000000", "0.00000000"], ["84080.89000000", "0.00000000"], ["84080.88000000", "0.00000000"], ["84080.80000000", "0.00000000"], ["84080.79000000", "0.00000000"], ["84080.48000000", "0.00000000"], ["84080.47000000", "0.35644000"], ["84080.04000000", "0.00000000"], ["84079.84000000", "0.11388000"], ["84079.26000000", "0.00000000"], ["84079.25000000", "0.85674000"], ["84079.17000000", "0.00000000"], ["84078.64000000", "0.00000000"], ["84078.47000000", "0.00000000"], ["84078.34000000", "0.00000000"], ["84078.28000000", "0.00000000"], ["84077.80000000", "0.00000000"], ["84077.59000000", "0.00000000"], ["84077.48000000", "0.00000000"], ["84077.36000000", "0.00000000"], ["84077.20000000", "0.00000000"], ["84077.14000000", "0.59407000"], ["84076.96000000", "0.00000000"], ["84076.32000000", "0.50734000"], ["84075.81000000", "0.00000000"], ["84075.41000000", "0.00000000"], ["84074.63000000", "0.00059000"], ["84074.02000000", "0.00000000"], ["84074.01000000", "0.00000000"], ["84073.75000000", "0.00000000"], ["84073.62000000", "0.00101000"], ["84073.43000000", "0.00000000"], ["84073.09000000", "1.29306000"], ["84072.46000000", "0.00000000"], ["84072.45000000", "0.00000000"], ["84071.53000000", "0.00000000"], ["84071.31000000", "0.00000000"], ["84069.59000000", "0.00000000"], ["84069.39000000", "2.26130000"], ["84069.38000000", "0.00000000"], ["84068.86000000", "0.00000000"], ["84068.37000000", "0.31707000"], ["84068.32000000", "0.00000000"], ["84068.21000000", "0.00000000"], ["84067.67000000", "0.00000000"], ["84067.56000000", "0.00000000"], ["84067.34000000", "0.00000000"], ["84066.75000000", "0.00000000"], ["84066.67000000", "0.00000000"], ["84065.98000000", "0.00000000"], ["84065.70000000", "0.00000000"], ["84065.61000000", "0.00000000"], ["84064.79000000", "0.59482000"], ["84064.12000000", "0.00000000"], ["84061.06000000", "0.05794000"], ["84059.23000000", "0.00213000"], ["84055.85000000", "0.27336000"], ["84055.40000000", "0.00000000"], ["84055.34000000", "0.25133000"], ["84051.89000000", "0.00000000"], ["84050.19000000", "0.30079000"], ["84049.89000000", "0.00000000"], ["84049.76000000", "0.01300000"], ["84047.86000000", "0.00000000"], ["84047.34000000", "0.00000000"], ["84046.35000000", "0.00297000"], ["84043.48000000", "0.25776000"], ["84043.15000000", "0.00000000"], ["84042.15000000", "0.00000000"], ["84042.13000000", "0.00000000"], ["84041.15000000", "0.00000000"], ["84040.82000000", "0.00000000"], ["84040.01000000", "0.00000000"], ["84039.74000000", "0.00000000"], ["84039.14000000", "0.00000000"], ["84036.54000000", "0.00296000"], ["84033.60000000", "0.03575000"], ["84030.08000000", "0.00000000"], ["84016.80000000", "0.00006000"], ["84009.10000000", "0.00400000"], ["84005.96000000", "0.00000000"], ["84000.91000000", "0.82940000"], ["83989.23000000", "1.34287000"], ["83988.05000000", "1.50925000"], ["83980.82000000", "0.00000000"], ["83979.75000000", "0.05197000"], ["83974.43000000", "0.00000000"], ["83971.88000000", "0.00197000"], ["83966.81000000", "0.00000000"], ["83964.06000000", "0.00000000"], ["83960.86000000", "0.00000000"], ["83956.49000000", "0.00006000"], ["83950.97000000", "0.00000000"], ["83943.62000000", "0.00000000"], ["83932.43000000", "0.00000000"], ["83928.15000000", "0.01000000"], ["83927.75000000", "0.00000000"], ["83903.59000000", "0.00011000"], ["83887.18000000", "0.06760000"], ["83885.82000000", "0.00000000"], ["83882.62000000", "0.00000000"], ["83881.35000000", "0.00000000"], ["83878.78000000", "0.19311000"], ["83878.56000000", "0.00678000"], ["83874.22000000", "0.00000000"], ["83869.85000000", "0.00000000"], ["83854.64000000", "0.00000000"], ["83069.99000000", "0.00000000"], ["82829.55000000", "0.00100000"], ["80697.27000000", "0.00000000"], ["75689.00000000", "0.54435000"], ["75681.00000000", "0.00000000"], ["67279.88000000", "0.00058000"], ["67272.74000000", "0.00000000"], ["50001.00000000", "1.82097000"], ["42000.00000000", "6.85161000"], ["33000.00000000", "2.93827000"], ["30272.73000000", "0.00040000"], ["20002.00000000", "0.00000000"], ["20001.00000000", "0.02099000"], ["18475.70000000", "0.00028000"]], "a": [["84090.93000000", "0.00000000"], ["84090.94000000", "0.00000000"], ["84091.66000000", "0.00000000"], ["84092.20000000", "0.00000000"], ["84092.51000000", "0.00000000"], ["84092.79000000", "0.00000000"], ["84092.80000000", "0.00000000"], ["84093.11000000", "0.00000000"], ["84093.30000000", "0.00000000"], ["84093.31000000", "0.00000000"], ["84093.35000000", "0.00000000"], ["84093.47000000", "0.00000000"], ["84093.48000000", "0.00000000"], ["84093.80000000", "0.00000000"], ["84094.00000000", "0.00000000"], ["84094.05000000", "0.00000000"], ["84094.19000000", "0.00000000"], ["84094.51000000", "0.00000000"], ["84094.52000000", "0.00000000"], ["84094.56000000", "0.00000000"], ["84094.57000000", "0.00000000"], ["84095.04000000", "0.00000000"], ["84095.29000000", "0.00000000"], ["84095.30000000", "0.00000000"], ["84095.71000000", "0.00000000"], ["84095.72000000", "0.00000000"], ["84095.88000000", "0.00000000"], ["84096.29000000", "0.00000000"], ["84096.34000000", "0.00000000"], ["84096.35000000", "0.00000000"], ["84096.36000000", "0.00000000"], ["84096.60000000", "0.00000000"], ["84096.99000000", "0.00000000"], ["84097.00000000", "0.00000000"], ["84097.05000000", "0.00000000"], ["84097.08000000", "0.00000000"], ["84097.09000000", "0.00000000"], ["84097.10000000", "0.00000000"], ["84097.28000000", "0.00000000"], ["84097.37000000", "0.00000000"], ["84097.49000000", "0.00000000"], ["84097.50000000", "0.00000000"], ["84098.00000000", "0.00000000"], ["84098.43000000", "0.00000000"], ["84098.45000000", "0.00000000"], ["84098.46000000", "0.00000000"], ["84098.58000000", "0.00000000"], ["84098.63000000", "0.00000000"], ["84098.74000000", "0.00000000"], ["84098.75000000", "0.00000000"], ["84099.43000000", "0.00000000"], ["84099.68000000", "0.00000000"], ["84099.77000000", "0.00000000"], ["84099.85000000", "0.00000000"], ["84099.86000000", "0.08308000"], ["84099.87000000", "0.00040000"], ["84099.98000000", "0.00000000"], ["84099.99000000", "0.00000000"], ["84100.00000000", "0.00006000"], ["84100.27000000", "0.00000000"], ["84100.28000000", "0.00000000"], ["84100.35000000", "0.00000000"], ["84100.41000000", "0.00000000"], ["84100.80000000", "0.00000000"], ["84100.86000000", "0.00000000"], ["84100.96000000", "0.00000000"], ["84101.18000000", "0.00000000"], ["84101.19000000", "0.00000000"], ["84101.20000000", "0.00000000"], ["84101.26000000", "0.00000000"], ["84101.52000000", "0.00000000"], ["84101.57000000", "0.00000000"], ["84101.59000000", "0.00014000"], ["84101.60000000", "0.27536000"], ["84101.70000000", "0.00000000"], ["84101.79000000", "0.00000000"], ["84102.00000000", "0.00000000"], ["84102.15000000", "0.00000000"], ["84102.19000000", "0.00000000"], ["84102.25000000", "0.00000000"], ["84102.35000000", "0.00000000"], ["84102.40000000", "0.00000000"], ["84102.59000000", "0.00000000"], ["84102.67000000", "0.00000000"], ["84102.72000000", "0.00014000"], ["84102.73000000", "0.00000000"], ["84102.80000000", "0.00000000"], ["84102.89000000", "0.00000000"], ["84102.96000000", "0.00000000"], ["84103.01000000", "0.13390000"], ["84103.26000000", "0.00000000"], ["84103.30000000", "0.00000000"], ["84103.44000000", "0.02388000"], ["84103.64000000", "0.00000000"], ["84103.68000000", "0.00000000"], ["84103.69000000", "0.00000000"], ["84103.92000000", "0.00000000"], ["84104.00000000", "0.00000000"], ["84104.14000000", "0.00000000"], ["84104.36000000", "0.00000000"], ["84104.37000000", "0.06566000"], ["84104.48000000", "0.00000000"], ["84104.49000000", "0.00000000"], ["84104.52000000", "0.00000000"], ["84104.56000000", "0.00000000"], ["84104.58000000", "0.00000000"], ["84104.60000000", "0.00000000"], ["84104.89000000", "0.00000000"], ["84105.00000000", "0.00000000"], ["84105.73000000", "0.00000000"], ["84106.00000000", "0.02266000"], ["84106.06000000", "0.00000000"], ["84106.08000000", "0.00000000"], ["84106.11000000", "0.00000000"], ["84106.32000000", "0.00000000"], ["84106.34000000", "0.00000000"], ["84106.49000000", "0.00000000"], ["84106.51000000", "0.00000000"], ["84106.57000000", "0.78515000"], ["84106.58000000", "0.00000000"], ["84106.59000000", "0.17828000"], ["84106.62000000", "0.00000000"], ["84106.64000000", "0.00000000"], ["84106.71000000", "0.00000000"], ["84106.81000000", "0.00000000"], ["84106.90000000", "0.00000000"], ["84107.16000000", "0.00000000"], ["84107.23000000", "0.30810000"], ["84107.37000000", "0.00000000"], ["84107.54000000", "0.02224000"], ["84107.64000000", "0.00118000"], ["84107.71000000", "0.00000000"], ["84107.74000000", "0.26913000"], ["84107.75000000", "0.00000000"], ["84107.83000000", "0.00000000"], ["84107.86000000", "0.00000000"], ["84107.89000000", "0.00000000"], ["84108.15000000", "0.00000000"], ["84108.17000000", "0.00000000"], ["84108.20000000", "0.14000000"], ["84108.22000000", "0.00000000"], ["84108.23000000", "0.00000000"], ["84108.25000000", "0.00000000"], ["84108.29000000", "0.00000000"], ["84108.30000000", "0.00000000"], ["84108.41000000", "0.00000000"], ["84108.60000000", "0.00000000"], ["84108.61000000", "0.00000000"], ["84108.88000000", "0.01500000"], ["84109.07000000", "0.00000000"], ["84109.53000000", "0.35644000"], ["84109.62000000", "0.00000000"], ["84109.85000000", "0.00000000"], ["84109.90000000", "0.00000000"], ["84109.97000000", "0.01500000"], ["84110.02000000", "0.00000000"], ["84110.14000000", "0.00000000"], ["84110.25000000", "0.10703000"], ["84110.37000000", "0.00000000"], ["84110.69000000", "0.00000000"], ["84110.87000000", "0.00000000"], ["84111.06000000", "0.15008000"], ["84111.11000000", "0.00000000"], ["84111.38000000", "0.00000000"], ["84111.41000000", "0.00000000"], ["84111.45000000", "0.09092000"], ["84111.72000000", "0.00096000"], ["84112.12000000", "0.00000000"], ["84112.13000000", "0.02326000"], ["84112.19000000", "0.00000000"], ["84112.21000000", "0.00090000"], ["84112.67000000", "0.00000000"], ["84112.76000000", "0.46373000"], ["84112.79000000", "0.00000000"], ["84112.81000000", "0.00000000"], ["84112.85000000", "0.00000000"], ["84112.87000000", "0.00000000"], ["84112.88000000", "0.00000000"], ["84112.94000000", "0.00000000"], ["84112.95000000", "0.00000000"], ["84113.11000000", "0.45000000"], ["84113.44000000", "0.04817000"], ["84113.46000000", "0.05940000"], ["84113.61000000", "0.04000000"], ["84113.74000000", "0.00000000"], ["84114.69000000", "0.00415000"], ["84114.77000000", "0.16000000"], ["84115.67000000", "0.00000000"], ["84115.98000000", "0.93089000"], ["84116.15000000", "0.00000000"], ["84116.16000000", "0.00300000"], ["84116.40000000", "0.00000000"], ["84116.76000000", "0.16647000"], ["84116.92000000", "0.00000000"], ["84117.27000000", "0.00000000"], ["84117.59000000", "0.05940000"], ["84117.72000000", "0.00000000"], ["84118.02000000", "0.00000000"], ["84118.95000000", "0.00831000"], ["84119.78000000", "0.00000000"], ["84119.80000000", "0.00000000"], ["84120.67000000", "0.00000000"], ["84120.70000000", "0.00000000"], ["84120.77000000", "0.00007000"], ["84120.83000000", "0.89111000"], ["84121.02000000", "0.00000000"], ["84124.32000000", "0.00000000"], ["84124.87000000", "0.89111000"], ["84125.05000000", "0.00000000"], ["84125.08000000", "0.05940000"], ["84125.09000000", "0.00072000"], ["84126.44000000", "0.85626000"], ["84126.77000000", "0.00000000"], ["84127.54000000", "0.05200000"], ["84128.52000000", "0.00000000"], ["84128.68000000", "1.25253000"], ["84129.66000000", "0.00000000"], ["84129.68000000", "0.89111000"], ["84130.03000000", "0.89111000"], ["84130.34000000", "0.00000000"], ["84131.82000000", "0.00084000"], ["84133.04000000", "0.00000000"], ["84135.05000000", "0.59477000"], ["84135.25000000", "0.00000000"], ["84135.63000000", "0.00000000"], ["84136.93000000", "0.00000000"], ["84139.47000000", "0.00000000"], ["84139.60000000", "0.00000000"], ["84140.33000000", "0.00000000"], ["84140.50000000", "0.00000000"], ["84147.46000000", "0.12024000"], ["84148.34000000", "0.00000000"], ["84150.34000000", "0.00000000"], ["84152.93000000", "0.00864000"], ["84159.21000000", "0.47526000"], ["84164.17000000", "0.00000000"], ["84175.35000000", "0.00000000"], ["84175.73000000", "0.07200000"], ["84176.57000000", "0.00000000"], ["84178.48000000", "0.00000000"], ["84179.67000000", "0.00006000"], ["84180.76000000", "0.00000000"], ["84181.99000000", "0.00296000"], ["84183.83000000", "0.00084000"], ["84183.84000000", "0.42423000"], ["84184.86000000", "0.00000000"], ["84186.89000000", "0.00000000"], ["84186.94000000", "0.00000000"], ["84188.33000000", "0.00000000"], ["84189.17000000", "0.00000000"], ["84191.45000000", "0.00296000"], ["84192.51000000", "0.00000000"], ["84192.53000000", "0.00000000"], ["84194.28000000", "0.00000000"], ["84195.20000000", "0.00000000"], ["84197.61000000", "0.00000000"], ["84199.99000000", "0.71385000"], ["84201.01000000", "0.00000000"], ["84201.80000000", "0.00000000"], ["84225.88000000", "0.00013000"], ["84239.62000000", "0.00000000"], ["84259.45000000", "0.00000000"], ["84260.23000000", "0.00000000"], ["84261.73000000", "0.00000000"], ["84262.24000000", "0.00000000"], ["84263.45000000", "0.00000000"], ["84264.34000000", "0.00000000"], ["84265.97000000", "0.01000000"], ["84266.09000000", "0.00118000"], ["84269.37000000", "0.00000000"], ["84275.99000000", "0.00118000"], ["84341.36000000", "0.00013000"], ["84345.56000000", "0.00000000"], ["84425.77000000", "0.19395000"], ["84426.51000000", "0.12793000"], ["84434.17000000", "0.11351000"], ["84466.06000000", "0.00000000"], ["84518.09000000", "0.00000000"], ["84544.15000000", "0.00017000"], ["85349.10000000", "0.00000000"], ["85352.30000000", "0.00000000"], ["85370.40000000", "0.14084000"], ["150001.00000000", "0.00080000"]], "record_time": 1742554966.03814, "EXCHANGE": "BINANCE"}
