{"e": "depthUpdate", "E": 1742577054014, "s": "BTCUSDT", "U": 64632100481, "u": 64632101021, "b": [["83981.24000000", "1.51260000"], ["83981.18000000", "0.00007000"], ["83981.13000000", "0.07372000"], ["83980.81000000", "0.00000000"], ["83980.80000000", "0.00000000"], ["83980.65000000", "0.00000000"], ["83980.64000000", "0.00000000"], ["83980.63000000", "0.00000000"], ["83980.60000000", "0.00007000"], ["83980.53000000", "0.00000000"], ["83980.52000000", "0.00000000"], ["83980.47000000", "0.00000000"], ["83980.41000000", "0.00000000"], ["83980.40000000", "0.00000000"], ["83979.25000000", "0.00000000"], ["83979.24000000", "0.00000000"], ["83979.19000000", "0.00014000"], ["83979.18000000", "0.35287000"], ["83979.10000000", "0.00000000"], ["83979.09000000", "0.00000000"], ["83979.00000000", "0.00000000"], ["83978.98000000", "0.00000000"], ["83978.97000000", "0.00107000"], ["83978.92000000", "0.00000000"], ["83978.68000000", "0.00000000"], ["83978.50000000", "0.00000000"], ["83978.49000000", "0.02983000"], ["83978.29000000", "0.12061000"], ["83977.98000000", "0.00000000"], ["83977.79000000", "0.00000000"], ["83977.78000000", "0.04000000"], ["83977.77000000", "0.13060000"], ["83977.70000000", "0.00000000"], ["83977.69000000", "0.00000000"], ["83977.68000000", "0.08013000"], ["83977.67000000", "0.00000000"], ["83977.56000000", "0.00000000"], ["83977.30000000", "0.00000000"], ["83977.25000000", "0.00000000"], ["83977.21000000", "0.00000000"], ["83977.08000000", "0.02000000"], ["83976.69000000", "0.00000000"], ["83976.25000000", "0.00000000"], ["83975.95000000", "0.00000000"], ["83975.78000000", "0.00000000"], ["83975.77000000", "0.00000000"], ["83975.60000000", "0.00000000"], ["83975.49000000", "0.00000000"], ["83974.93000000", "0.04492000"], ["83974.81000000", "0.00000000"], ["83974.49000000", "0.02199000"], ["83974.38000000", "0.00000000"], ["83973.68000000", "0.05364000"], ["83972.48000000", "0.00119000"], ["83970.27000000", "0.00095000"], ["83970.10000000", "0.18678000"], ["83970.09000000", "0.00000000"], ["83969.11000000", "0.16172000"], ["83968.31000000", "0.20706000"], ["83968.01000000", "0.00091000"], ["83967.86000000", "0.00000000"], ["83967.79000000", "0.04013000"], ["83967.36000000", "0.00000000"], ["83966.87000000", "0.00000000"], ["83965.85000000", "0.27545000"], ["83965.64000000", "0.00000000"], ["83963.72000000", "0.00119000"], ["83963.60000000", "0.47650000"], ["83962.62000000", "0.00000000"], ["83962.18000000", "0.00000000"], ["83961.70000000", "0.74121000"], ["83961.57000000", "0.00000000"], ["83961.05000000", "0.00000000"], ["83960.94000000", "0.00000000"], ["83960.70000000", "0.85795000"], ["83960.52000000", "0.00000000"], ["83960.26000000", "0.00000000"], ["83960.22000000", "0.00000000"], ["83960.21000000", "0.00000000"], ["83960.15000000", "0.00000000"], ["83960.10000000", "0.00000000"], ["83960.07000000", "0.03573000"], ["83959.86000000", "0.10788000"], ["83959.21000000", "0.00000000"], ["83958.30000000", "0.00018000"], ["83958.23000000", "0.00000000"], ["83957.46000000", "0.35737000"], ["83957.42000000", "0.00000000"], ["83957.33000000", "0.00000000"], ["83956.92000000", "0.00000000"], ["83956.22000000", "0.00000000"], ["83954.90000000", "0.11590000"], ["83954.84000000", "0.00000000"], ["83954.35000000", "0.00000000"], ["83953.40000000", "1.08253000"], ["83952.27000000", "1.38852000"], ["83951.45000000", "0.85805000"], ["83950.48000000", "0.00000000"], ["83950.01000000", "0.00000000"], ["83949.60000000", "0.00006000"], ["83948.84000000", "0.00000000"], ["83946.58000000", "0.59570000"], ["83946.57000000", "0.00000000"], ["83944.02000000", "0.00000000"], ["83943.92000000", "0.00000000"], ["83941.01000000", "0.00000000"], ["83936.63000000", "0.00000000"], ["83936.51000000", "0.05000000"], ["83935.78000000", "0.23815000"], ["83932.80000000", "0.05962000"], ["83927.22000000", "0.06102000"], ["83920.35000000", "0.00000000"], ["83918.05000000", "0.04000000"], ["83915.99000000", "0.00000000"], ["83914.92000000", "0.00000000"], ["83912.92000000", "0.00000000"], ["83910.55000000", "0.00061000"], ["83910.52000000", "0.04490000"], ["83904.52000000", "0.09654000"], ["83899.19000000", "0.03574000"], ["83891.13000000", "0.00000000"], ["83876.79000000", "0.04762000"], ["83820.98000000", "0.00000000"], ["83809.92000000", "0.00000000"], ["83794.93000000", "0.00000000"], ["83794.19000000", "0.00000000"], ["83790.94000000", "0.00400000"], ["83790.13000000", "0.00839000"], ["83784.70000000", "0.00000000"], ["83747.34000000", "0.00000000"], ["82721.52000000", "0.00007000"], ["79500.00000000", "21.03177000"], ["75583.12000000", "0.00025000"], ["75583.00000000", "0.00000000"], ["67185.00000000", "0.00073000"], ["33000.00000000", "2.96666000"], ["30233.25000000", "0.00160000"]], "a": [["83981.25000000", "7.62762000"], ["83981.26000000", "0.31608000"], ["83981.29000000", "0.00021000"], ["83981.30000000", "0.30584000"], ["83981.31000000", "0.13708000"], ["83981.33000000", "0.00007000"], ["83981.35000000", "0.03340000"], ["83982.00000000", "0.01416000"], ["83983.58000000", "0.00000000"], ["83984.00000000", "0.01416000"], ["83984.19000000", "0.00000000"], ["83984.55000000", "0.00000000"], ["83985.10000000", "0.02323000"], ["83985.35000000", "0.00000000"], ["83986.46000000", "0.78621000"], ["83986.60000000", "0.00000000"], ["83986.86000000", "0.15590000"], ["83987.36000000", "0.00008000"], ["83987.73000000", "0.06800000"], ["83988.30000000", "0.09319000"], ["83988.98000000", "0.33196000"], ["83989.00000000", "0.00000000"], ["83989.06000000", "0.00000000"], ["83989.25000000", "0.08992000"], ["83989.99000000", "0.06800000"], ["83990.01000000", "0.07600000"], ["83991.08000000", "0.06400000"], ["83991.16000000", "0.00000000"], ["83991.96000000", "0.00000000"], ["83991.99000000", "0.26246000"], ["83992.05000000", "0.00000000"], ["83992.58000000", "0.00000000"], ["83992.61000000", "0.00000000"], ["83992.73000000", "0.00000000"], ["83992.76000000", "0.05200000"], ["83992.86000000", "0.07200000"], ["83993.35000000", "0.06000000"], ["83993.96000000", "0.00000000"], ["83994.14000000", "0.00000000"], ["83994.56000000", "0.04800000"], ["83994.94000000", "0.04000000"], ["83994.96000000", "0.00000000"], ["83995.36000000", "0.00119000"], ["83995.98000000", "0.71399000"], ["83996.79000000", "0.00000000"], ["83997.49000000", "0.00000000"], ["83997.54000000", "0.00000000"], ["83998.33000000", "0.00000000"], ["83999.17000000", "0.00000000"], ["83999.84000000", "0.00000000"], ["83999.94000000", "0.00000000"], ["84002.38000000", "0.00000000"], ["84002.70000000", "0.00500000"], ["84003.15000000", "0.00000000"], ["84003.60000000", "0.00000000"], ["84003.93000000", "0.59562000"], ["84004.57000000", "0.00000000"], ["84005.48000000", "0.08992000"], ["84007.92000000", "0.85747000"], ["84008.77000000", "0.06800000"], ["84010.81000000", "0.00000000"], ["84014.08000000", "0.00000000"], ["84014.46000000", "0.59569000"], ["84019.05000000", "0.11699000"], ["84019.38000000", "0.00000000"], ["84020.05000000", "0.00000000"], ["84021.00000000", "0.47656000"], ["84021.53000000", "0.00000000"], ["84021.73000000", "0.00000000"], ["84025.27000000", "0.58089000"], ["84028.22000000", "0.00000000"], ["84029.40000000", "0.00006000"], ["84030.27000000", "0.06155000"], ["84030.89000000", "0.00000000"], ["84032.81000000", "0.07600000"], ["84034.28000000", "0.00000000"], ["84034.30000000", "0.00000000"], ["84037.00000000", "0.06800000"], ["84037.01000000", "0.00000000"], ["84040.45000000", "0.10060000"], ["84048.51000000", "0.00000000"], ["84052.11000000", "0.43003000"], ["84052.78000000", "0.04198000"], ["84054.12000000", "1.02791000"], ["84056.18000000", "0.00000000"], ["84059.99000000", "0.00000000"], ["84061.21000000", "0.04800000"], ["84061.83000000", "0.09636000"], ["84063.31000000", "0.00000000"], ["84063.32000000", "0.00006000"], ["84064.27000000", "0.00000000"], ["84072.14000000", "0.00000000"], ["84072.50000000", "0.00000000"], ["84092.11000000", "0.01018000"], ["84094.79000000", "0.05798000"], ["84102.06000000", "0.00000000"], ["84108.22000000", "0.12000000"], ["84124.12000000", "0.00000000"], ["84140.61000000", "0.00000000"], ["84155.97000000", "0.01013000"], ["84156.17000000", "0.00000000"], ["84156.27000000", "0.00000000"], ["84165.68000000", "0.00000000"], ["84173.26000000", "0.99872000"], ["84270.25000000", "0.01186000"], ["84326.64000000", "0.00000000"], ["84336.00000000", "0.00221000"], ["85240.97000000", "0.00000000"]], "record_time": 1742577054.212628, "EXCHANGE": "BINANCE"}
{"e": "depthUpdate", "E": 1742577055014, "s": "BTCUSDT", "U": 64632101022, "u": 64632101213, "b": [["83981.24000000", "1.63265000"], ["83981.13000000", "0.07372000"], ["83980.56000000", "0.00014000"], ["83980.55000000", "0.34978000"], ["83980.40000000", "0.03321000"], ["83980.20000000", "0.13249000"], ["83980.06000000", "0.07744000"], ["83979.76000000", "0.00000000"], ["83979.19000000", "0.00000000"], ["83979.18000000", "0.00000000"], ["83979.10000000", "0.00000000"], ["83978.97000000", "0.00101000"], ["83978.92000000", "0.00007000"], ["83978.49000000", "0.02976000"], ["83978.29000000", "0.12054000"], ["83977.77000000", "0.00000000"], ["83977.25000000", "0.00007000"], ["83976.90000000", "0.02414000"], ["83974.49000000", "0.00000000"], ["83973.25000000", "0.30409000"], ["83972.84000000", "0.28849000"], ["83971.69000000", "0.00000000"], ["83959.87000000", "0.67389000"], ["83959.55000000", "0.00000000"], ["83958.63000000", "1.40153000"], ["83957.92000000", "0.00759000"], ["83952.27000000", "0.00000000"], ["83944.12000000", "0.00000000"], ["83942.13000000", "0.36353000"], ["83936.51000000", "0.00000000"], ["83934.78000000", "0.75494000"], ["83922.01000000", "0.00000000"], ["83905.75000000", "0.00000000"], ["83905.54000000", "0.31728000"], ["83897.53000000", "0.04440000"], ["83888.36000000", "0.63047000"], ["83877.93000000", "0.04802000"], ["83865.25000000", "0.00000000"], ["83857.71000000", "0.05497000"], ["83854.62000000", "0.05497000"], ["83820.00000000", "0.00242000"], ["83819.91000000", "0.01000000"], ["83799.22000000", "0.00400000"], ["83790.94000000", "0.00000000"], ["83600.00000000", "0.19238000"], ["83039.87000000", "0.00000000"], ["82721.52000000", "0.00107000"], ["75583.12000000", "0.00000000"], ["75583.00000000", "0.00000000"], ["67185.00000000", "0.00073000"], ["33000.00000000", "2.96666000"], ["30272.84000000", "0.00000000"], ["30260.61000000", "0.00040000"], ["30240.61000000", "0.00120000"], ["30212.15000000", "0.00040000"], ["30208.70000000", "0.00380000"], ["30205.06000000", "0.00020000"], ["30204.71000000", "0.00080000"], ["30202.69000000", "0.00060000"], ["30184.22000000", "0.00040000"], ["30182.32000000", "0.00080000"], ["30182.27000000", "0.00820000"], ["30175.20000000", "0.00060000"], ["30174.43000000", "0.00000000"], ["30171.03000000", "0.00040000"], ["30164.73000000", "0.00080000"], ["30164.51000000", "0.00000000"], ["30161.74000000", "0.00800000"], ["30154.82000000", "0.00040000"], ["30153.22000000", "0.00440000"], ["30148.15000000", "0.00020000"], ["20002.00000000", "0.00000000"], ["20001.00000000", "0.02099000"]], "a": [["83981.25000000", "6.52513000"], ["83981.29000000", "0.00007000"], ["83981.30000000", "0.11668000"], ["83981.31000000", "0.13702000"], ["83981.35000000", "0.00006000"], ["83982.00000000", "0.01423000"], ["83983.61000000", "0.00756000"], ["83984.42000000", "0.03322000"], ["83985.10000000", "0.02317000"], ["83986.04000000", "0.00000000"], ["83986.46000000", "0.00000000"], ["83988.54000000", "0.55093000"], ["83988.55000000", "0.78619000"], ["83988.98000000", "0.00000000"], ["83989.25000000", "0.00000000"], ["83991.12000000", "0.00922000"], ["83995.98000000", "0.00000000"], ["83997.99000000", "0.03573000"], ["83999.35000000", "0.71399000"], ["84000.01000000", "1.32289000"], ["84000.02000000", "1.00000000"], ["84001.88000000", "0.00000000"], ["84002.12000000", "1.35771000"], ["84003.93000000", "0.59562000"], ["84008.30000000", "0.00000000"], ["84012.90000000", "1.37289000"], ["84013.58000000", "0.00000000"], ["84014.46000000", "0.00000000"], ["84018.39000000", "0.59566000"], ["84029.32000000", "0.00000000"], ["84058.61000000", "0.00019000"], ["84059.98000000", "0.00000000"], ["84064.25000000", "0.03992000"], ["84064.58000000", "0.24053000"], ["84068.00000000", "0.44009000"], ["84082.53000000", "0.04643000"], ["84097.52000000", "0.00000000"], ["84109.39000000", "0.05497000"], ["84115.70000000", "0.00000000"], ["84123.47000000", "0.00000000"], ["84134.55000000", "0.00016000"], ["84135.99000000", "0.00000000"], ["84400.00000000", "0.44421000"], ["84500.00000000", "12.82974000"], ["85240.97000000", "0.00100000"], ["89153.89000000", "0.00000000"]], "record_time": 1742577055.212556, "EXCHANGE": "BINANCE"}
{"e": "depthUpdate", "E": 1742577056014, "s": "BTCUSDT", "U": 64632101214, "u": 64632101395, "b": [["83981.24000000", "1.63297000"], ["83981.13000000", "0.07372000"], ["83981.08000000", "0.00014000"], ["83981.07000000", "0.32393000"], ["83980.60000000", "0.00000000"], ["83980.56000000", "0.00000000"], ["83980.55000000", "0.00000000"], ["83980.41000000", "0.00000000"], ["83980.40000000", "0.03321000"], ["83980.20000000", "0.00000000"], ["83980.07000000", "0.00000000"], ["83980.06000000", "0.07751000"], ["83979.98000000", "0.00000000"], ["83979.97000000", "0.00000000"], ["83979.92000000", "0.17966000"], ["83979.76000000", "0.00000000"], ["83978.75000000", "0.00000000"], ["83978.74000000", "0.00000000"], ["83978.49000000", "0.02976000"], ["83978.33000000", "0.00000000"], ["83978.30000000", "0.00000000"], ["83978.29000000", "0.12054000"], ["83977.25000000", "0.00007000"], ["83977.00000000", "0.00500000"], ["83973.67000000", "0.00896000"], ["83973.25000000", "0.20321000"], ["83972.84000000", "0.28849000"], ["83961.70000000", "1.34550000"], ["83960.07000000", "0.00000000"], ["83959.94000000", "0.03572000"], ["83942.11000000", "0.05000000"], ["83921.71000000", "0.00000000"], ["83913.56000000", "0.00000000"], ["83896.59000000", "0.09496000"], ["83894.48000000", "0.08741000"], ["83889.06000000", "0.43512000"], ["83887.09000000", "0.09285000"], ["83884.97000000", "0.04643000"], ["83883.48000000", "0.04643000"], ["83882.00000000", "0.02384000"], ["83857.55000000", "0.18341000"], ["83820.01000000", "0.01000000"], ["83819.91000000", "0.00000000"], ["83799.22000000", "0.00000000"], ["83797.43000000", "0.00400000"], ["83792.32000000", "0.00000000"], ["82721.52000000", "0.00007000"], ["75583.00000000", "0.00000000"], ["67185.00000000", "0.00073000"], ["33000.00000000", "2.96666000"]], "a": [["83981.25000000", "6.48491000"], ["83981.29000000", "0.00007000"], ["83981.30000000", "0.11668000"], ["83986.63000000", "0.00000000"], ["83988.54000000", "0.51155000"], ["83988.55000000", "0.00000000"], ["83988.62000000", "0.78619000"], ["84002.23000000", "0.00000000"], ["84002.70000000", "0.00000000"], ["84006.02000000", "0.00000000"], ["84011.00000000", "0.00500000"], ["84012.95000000", "0.05000000"], ["84019.05000000", "0.00000000"], ["84023.35000000", "0.12295000"], ["84067.99000000", "0.41322000"], ["84070.77000000", "0.00000000"], ["84076.70000000", "0.02383000"], ["84084.49000000", "0.00679000"], ["84090.05000000", "0.00000000"], ["84092.11000000", "0.00000000"], ["84094.79000000", "0.00000000"], ["84107.08000000", "0.00000000"], ["84110.17000000", "0.00000000"], ["84165.67000000", "0.05805000"], ["84294.00000000", "0.03574000"], ["84821.05000000", "0.00000000"], ["85240.97000000", "0.00000000"]], "record_time": 1742577056.212329, "EXCHANGE": "BINANCE"}
{"e": "depthUpdate", "E": 1742577057014, "s": "BTCUSDT", "U": 64632101396, "u": 64632101516, "b": [["83981.24000000", "1.51354000"], ["83981.13000000", "0.07372000"], ["83981.08000000", "0.00000000"], ["83981.07000000", "0.00000000"], ["83980.60000000", "0.00007000"], ["83980.40000000", "0.00000000"], ["83980.07000000", "0.00000000"], ["83980.06000000", "0.00000000"], ["83979.92000000", "0.00000000"], ["83979.76000000", "0.00007000"], ["83978.50000000", "0.00014000"], ["83978.49000000", "0.02983000"], ["83978.39000000", "0.00014000"], ["83978.38000000", "0.00007000"], ["83978.30000000", "0.00000000"], ["83978.29000000", "0.12061000"], ["83977.78000000", "0.04000000"], ["83977.65000000", "0.15992000"], ["83977.25000000", "0.00000000"], ["83976.90000000", "0.00000000"], ["83976.83000000", "0.00000000"], ["83976.79000000", "0.00000000"], ["83976.60000000", "0.02426000"], ["83975.76000000", "0.04560000"], ["83975.73000000", "0.00000000"], ["83972.84000000", "0.28849000"], ["83966.91000000", "0.00000000"], ["83959.94000000", "0.00000000"], ["83959.86000000", "0.00000000"], ["83959.76000000", "0.03573000"], ["83959.35000000", "0.10788000"], ["83944.11000000", "0.00000000"], ["83942.11000000", "0.00000000"], ["83941.91000000", "0.05000000"], ["83869.61000000", "0.00000000"], ["83866.92000000", "0.00082000"], ["83820.01000000", "0.00000000"], ["83819.91000000", "0.01000000"], ["83793.11000000", "0.00000000"], ["83791.24000000", "0.00069000"], ["83790.13000000", "0.00000000"], ["83783.87000000", "0.00839000"], ["83500.00000000", "3.39397000"], ["83009.99000000", "0.00134000"], ["83000.00000000", "36.13225000"], ["82200.09000000", "0.36496000"], ["75583.00000000", "0.00000000"], ["67185.00000000", "0.00073000"], ["42000.00000000", "6.84810000"], ["33000.00000000", "2.96666000"], ["30233.25000000", "0.00180000"]], "a": [["83981.25000000", "7.14074000"], ["83981.29000000", "0.00021000"], ["83981.30000000", "0.34600000"], ["83986.71000000", "0.78621000"], ["83988.54000000", "0.31508000"], ["83988.62000000", "0.00000000"], ["84071.65000000", "0.74820000"], ["84073.65000000", "1.21806000"], ["84080.60000000", "0.65495000"], ["84081.95000000", "0.00000000"], ["84155.67000000", "0.01000000"], ["84155.97000000", "0.00013000"], ["84173.26000000", "0.99849000"], ["84194.60000000", "0.00000000"], ["84332.22000000", "0.00000000"], ["94200.00000000", "6.76490000"]], "record_time": 1742577057.212675, "EXCHANGE": "BINANCE"}
{"e": "depthUpdate", "E": 1742577058014, "s": "BTCUSDT", "U": 64632101517, "u": 64632101641, "b": [["83981.24000000", "1.51359000"], ["83981.13000000", "0.07372000"], ["83980.00000000", "0.00157000"], ["83979.99000000", "0.07678000"], ["83978.50000000", "0.00000000"], ["83978.49000000", "0.02983000"], ["83978.40000000", "0.00014000"], ["83978.39000000", "0.26906000"], ["83978.38000000", "0.00000000"], ["83978.30000000", "0.00000000"], ["83978.29000000", "0.00000000"], ["83977.79000000", "0.00000000"], ["83977.78000000", "0.04000000"], ["83977.69000000", "0.00000000"], ["83977.68000000", "0.08013000"], ["83977.41000000", "0.00000000"], ["83977.00000000", "0.00000000"], ["83976.84000000", "0.13747000"], ["83976.44000000", "0.14822000"], ["83976.36000000", "0.00000000"], ["83974.93000000", "0.00000000"], ["83968.30000000", "0.00000000"], ["83959.76000000", "0.00000000"], ["83959.72000000", "0.41295000"], ["83959.70000000", "0.00754000"], ["83958.63000000", "0.00000000"], ["83957.92000000", "0.00000000"], ["83956.66000000", "1.40173000"], ["83941.91000000", "0.00000000"], ["83920.01000000", "0.00000000"], ["83854.29000000", "0.00000000"], ["83850.12000000", "0.00060000"], ["83827.31000000", "0.00000000"], ["83827.30000000", "0.00060000"], ["83819.91000000", "0.01000000"], ["83810.83000000", "0.01864000"], ["83797.43000000", "0.00000000"], ["83790.72000000", "0.00400000"], ["82721.52000000", "0.00107000"], ["75583.00000000", "0.00000000"], ["75500.00000000", "37.35967000"], ["67185.00000000", "0.00073000"], ["42000.00000000", "6.84710000"], ["33000.00000000", "2.96666000"], ["30276.12000000", "0.00000000"], ["30268.56000000", "0.00000000"], ["30262.91000000", "0.00000000"], ["30260.61000000", "0.00020000"], ["30252.95000000", "0.00000000"], ["30233.25000000", "0.00200000"], ["30233.21000000", "0.00540000"], ["30227.04000000", "0.00000000"], ["30205.43000000", "0.00000000"], ["30182.27000000", "0.00800000"], ["30180.96000000", "0.00160000"], ["30178.80000000", "0.00020000"], ["30175.20000000", "0.00040000"], ["30171.03000000", "0.00020000"], ["30165.52000000", "0.00000000"], ["30163.93000000", "0.00020000"]], "a": [["83996.02000000", "0.00000000"], ["83998.12000000", "0.11912000"], ["84002.12000000", "1.35975000"], ["84002.70000000", "0.00500000"], ["84007.95000000", "0.05000000"], ["84011.00000000", "0.00500000"], ["84012.95000000", "0.00000000"], ["84027.90000000", "0.01196000"], ["84036.79000000", "0.00000000"], ["84091.78000000", "0.01864000"], ["84130.02000000", "0.00000000"], ["84131.25000000", "0.00000000"], ["84155.67000000", "0.01000000"], ["84400.00000000", "0.44544000"], ["85240.97000000", "0.00100000"], ["85402.61000000", "0.00060000"], ["85406.85000000", "0.00000000"]], "record_time": 1742577058.21312, "EXCHANGE": "BINANCE"}
{"e": "depthUpdate", "E": 1742577059014, "s": "BTCUSDT", "U": 64632101642, "u": 64632101738, "b": [["83981.24000000", "1.53164000"], ["83979.99000000", "0.07678000"], ["83979.41000000", "0.00000000"], ["83978.49000000", "0.02983000"], ["83978.40000000", "0.00000000"], ["83978.39000000", "0.00000000"], ["83978.30000000", "0.03274000"], ["83977.78000000", "0.04000000"], ["83976.60000000", "0.00000000"], ["83975.44000000", "0.31174000"], ["83971.98000000", "0.00357000"], ["83970.66000000", "0.00013000"], ["83970.10000000", "0.11564000"], ["83968.40000000", "0.00000000"], ["83968.31000000", "0.00000000"], ["83962.81000000", "0.20712000"], ["83959.70000000", "0.00000000"], ["83958.00000000", "0.00765000"], ["83956.66000000", "0.00000000"], ["83937.11000000", "0.00000000"], ["83888.36000000", "0.00000000"], ["83866.93000000", "0.00082000"], ["83866.92000000", "0.00000000"], ["83810.83000000", "0.00000000"], ["83791.25000000", "0.00069000"], ["83791.24000000", "0.00000000"], ["83756.27000000", "0.00000000"], ["82721.52000000", "0.00007000"], ["80623.19000000", "0.00000000"], ["80606.38000000", "0.00000000"], ["75583.00000000", "0.00000000"], ["73544.71000000", "0.00000000"], ["67185.00000000", "0.00073000"], ["33000.00000000", "2.96666000"], ["30233.25000000", "0.00240000"]], "a": [["83981.25000000", "7.13885000"], ["83990.49000000", "0.00364000"], ["83991.81000000", "0.00000000"], ["83997.19000000", "0.01864000"], ["84002.12000000", "0.00000000"], ["84007.95000000", "0.00000000"], ["84009.35000000", "0.05000000"], ["84011.00000000", "0.00000000"], ["84091.78000000", "0.00000000"], ["84104.90000000", "0.05297000"], ["85240.97000000", "0.00000000"], ["85958.01000000", "0.00040000"], ["86261.00000000", "0.00000000"]], "record_time": 1742577059.212515, "EXCHANGE": "BINANCE"}
{"e": "depthUpdate", "E": 1742577060014, "s": "BTCUSDT", "U": 64632101739, "u": 64632101848, "b": [["83981.24000000", "0.83837000"], ["83980.60000000", "0.00007000"], ["83979.99000000", "0.07678000"], ["83979.15000000", "0.00014000"], ["83979.14000000", "0.16503000"], ["83978.92000000", "0.00000000"], ["83978.58000000", "0.00007000"], ["83978.57000000", "0.29835000"], ["83978.49000000", "0.02976000"], ["83978.30000000", "0.03267000"], ["83977.65000000", "0.00000000"], ["83977.25000000", "0.00000000"], ["83977.03000000", "0.00000000"], ["83977.00000000", "0.00500000"], ["83976.60000000", "0.00000000"], ["83976.17000000", "0.00000000"], ["83975.44000000", "0.00000000"], ["83974.80000000", "0.00000000"], ["83957.50000000", "1.36130000"], ["83921.71000000", "0.00000000"], ["83888.36000000", "0.63047000"], ["83866.94000000", "0.00082000"], ["83866.93000000", "0.00000000"], ["83795.76000000", "0.00400000"], ["83791.26000000", "0.00069000"], ["83791.25000000", "0.00000000"], ["83790.72000000", "0.00000000"], ["82721.52000000", "0.00107000"], ["75583.00000000", "0.00000000"], ["67185.00000000", "0.00073000"], ["60000.00000000", "72.96736000"], ["33000.00000000", "2.96666000"], ["30233.25000000", "0.00260000"], ["20002.00000000", "0.00000000"], ["20001.00000000", "0.02099000"]], "a": [["83981.25000000", "7.13792000"], ["83981.29000000", "0.00007000"], ["83981.30000000", "0.11668000"], ["83982.00000000", "0.01423000"], ["83982.92000000", "0.01190000"], ["83986.71000000", "0.00000000"], ["83988.34000000", "0.55201000"], ["83988.35000000", "0.78620000"], ["83988.54000000", "0.00000000"], ["83991.60000000", "0.00019000"], ["83999.35000000", "0.71399000"], ["83999.58000000", "0.00008000"], ["84000.88000000", "1.36228000"], ["84002.70000000", "0.00500000"], ["84009.35000000", "0.00000000"], ["84012.45000000", "0.00000000"], ["84071.65000000", "0.33188000"], ["84073.65000000", "0.00000000"], ["84155.67000000", "0.00000000"], ["84155.87000000", "0.01000000"], ["85240.97000000", "0.00100000"], ["86000.00000000", "17.28523000"]], "record_time": 1742577060.21217, "EXCHANGE": "BINANCE"}
{"e": "depthUpdate", "E": 1742577061014, "s": "BTCUSDT", "U": 64632101849, "u": 64632107671, "b": [["83981.24000000", "0.00000000"], ["83981.23000000", "0.00000000"], ["83981.22000000", "0.00000000"], ["83981.20000000", "0.00000000"], ["83981.19000000", "0.00000000"], ["83981.18000000", "0.00000000"], ["83981.17000000", "0.00000000"], ["83981.15000000", "0.00000000"], ["83981.14000000", "0.00000000"], ["83981.13000000", "0.00000000"], ["83980.60000000", "0.00000000"], ["83980.00000000", "0.00000000"], ["83979.99000000", "0.00000000"], ["83979.76000000", "0.00000000"], ["83979.15000000", "0.00000000"], ["83979.14000000", "0.00000000"], ["83978.97000000", "0.00000000"], ["83978.94000000", "0.00000000"], ["83978.92000000", "0.00000000"], ["83978.58000000", "0.00000000"], ["83978.57000000", "0.00000000"], ["83978.50000000", "0.00000000"], ["83978.49000000", "0.00000000"], ["83978.48000000", "0.00000000"], ["83978.30000000", "0.00000000"], ["83978.09000000", "0.00000000"], ["83977.95000000", "0.00000000"], ["83977.79000000", "0.00000000"], ["83977.78000000", "0.00000000"], ["83977.69000000", "0.00000000"], ["83977.68000000", "0.00000000"], ["83977.40000000", "0.00000000"], ["83977.39000000", "0.00000000"], ["83977.31000000", "0.00000000"], ["83977.25000000", "0.00000000"], ["83977.16000000", "0.00000000"], ["83977.08000000", "0.00000000"], ["83977.01000000", "0.00000000"], ["83977.00000000", "0.00000000"], ["83976.99000000", "0.00000000"], ["83976.90000000", "0.00000000"], ["83976.85000000", "0.00000000"], ["83976.84000000", "0.00000000"], ["83976.45000000", "0.00000000"], ["83976.44000000", "0.00000000"], ["83976.42000000", "0.00000000"], ["83976.20000000", "0.00000000"], ["83976.17000000", "0.00000000"], ["83976.00000000", "0.00000000"], ["83975.77000000", "0.00000000"], ["83975.76000000", "0.00000000"], ["83975.58000000", "0.00000000"], ["83975.10000000", "0.00000000"], ["83974.75000000", "0.00000000"], ["83974.74000000", "0.00000000"], ["83974.73000000", "0.00000000"], ["83974.54000000", "0.00000000"], ["83974.53000000", "0.00000000"], ["83974.44000000", "0.00000000"], ["83973.76000000", "0.00000000"], ["83973.68000000", "0.00000000"], ["83973.67000000", "0.00000000"], ["83973.27000000", "0.00000000"], ["83973.25000000", "0.00000000"], ["83973.21000000", "0.00000000"], ["83973.20000000", "0.00000000"], ["83973.12000000", "0.00000000"], ["83972.90000000", "0.00000000"], ["83972.88000000", "0.00000000"], ["83972.84000000", "0.00000000"], ["83972.77000000", "0.00000000"], ["83972.67000000", "0.00000000"], ["83972.49000000", "0.00000000"], ["83972.48000000", "0.00000000"], ["83972.09000000", "0.00000000"], ["83972.08000000", "0.00000000"], ["83972.00000000", "0.00000000"], ["83971.99000000", "0.00000000"], ["83971.98000000", "0.00000000"], ["83971.97000000", "0.00000000"], ["83971.78000000", "0.00000000"], ["83971.77000000", "0.00000000"], ["83970.90000000", "0.00000000"], ["83970.89000000", "0.00000000"], ["83970.73000000", "0.00000000"], ["83970.66000000", "0.00000000"], ["83970.63000000", "0.00000000"], ["83970.62000000", "0.00000000"], ["83970.60000000", "0.00000000"], ["83970.59000000", "0.00000000"], ["83970.57000000", "0.00000000"], ["83970.56000000", "0.00000000"], ["83970.38000000", "0.00000000"], ["83970.36000000", "0.00000000"], ["83970.30000000", "0.00000000"], ["83970.27000000", "0.00000000"], ["83970.26000000", "0.00000000"], ["83970.20000000", "0.00000000"], ["83970.11000000", "0.00000000"], ["83970.10000000", "0.00000000"], ["83970.07000000", "0.00000000"], ["83970.06000000", "0.00000000"], ["83969.97000000", "0.00000000"], ["83969.96000000", "0.00000000"], ["83969.78000000", "0.00000000"], ["83969.74000000", "0.00000000"], ["83969.72000000", "0.00000000"], ["83969.58000000", "0.00000000"], ["83969.46000000", "0.00000000"], ["83969.45000000", "0.00000000"], ["83969.19000000", "0.00000000"], ["83969.11000000", "0.00000000"], ["83969.10000000", "0.00000000"], ["83969.05000000", "0.00000000"], ["83969.04000000", "0.00000000"], ["83968.90000000", "0.00000000"], ["83968.83000000", "0.00000000"], ["83968.72000000", "0.00000000"], ["83968.71000000", "0.00000000"], ["83968.48000000", "0.00000000"], ["83968.27000000", "0.00000000"], ["83968.07000000", "0.00000000"], ["83968.06000000", "0.00000000"], ["83968.01000000", "0.00000000"], ["83967.91000000", "0.00000000"], ["83967.85000000", "0.00000000"], ["83967.84000000", "0.00000000"], ["83967.79000000", "0.00000000"], ["83967.23000000", "0.00000000"], ["83967.21000000", "0.00000000"], ["83967.17000000", "0.00000000"], ["83967.16000000", "0.00000000"], ["83966.89000000", "0.00000000"], ["83966.88000000", "0.00000000"], ["83966.70000000", "0.00000000"], ["83966.52000000", "0.00000000"], ["83966.51000000", "0.00000000"], ["83966.40000000", "0.00000000"], ["83966.38000000", "0.00000000"], ["83966.28000000", "0.00000000"], ["83966.27000000", "0.23762000"], ["83966.26000000", "0.00056000"], ["83966.21000000", "0.00000000"], ["83966.15000000", "0.00000000"], ["83966.14000000", "0.00000000"], ["83966.13000000", "0.00000000"], ["83966.11000000", "0.00000000"], ["83966.07000000", "0.00021000"], ["83966.06000000", "0.78660000"], ["83965.86000000", "0.00000000"], ["83965.85000000", "0.00000000"], ["83965.67000000", "0.00000000"], ["83965.66000000", "0.00000000"], ["83965.60000000", "0.00000000"], ["83965.59000000", "0.00000000"], ["83965.51000000", "0.00007000"], ["83965.37000000", "0.00000000"], ["83965.36000000", "0.00000000"], ["83965.08000000", "0.00000000"], ["83965.06000000", "0.00000000"], ["83965.05000000", "0.00000000"], ["83964.92000000", "0.00000000"], ["83964.91000000", "0.00000000"], ["83964.89000000", "0.00000000"], ["83964.87000000", "0.00000000"], ["83964.86000000", "0.00000000"], ["83964.80000000", "0.00000000"], ["83964.77000000", "0.00007000"], ["83964.76000000", "0.03301000"], ["83964.57000000", "0.00000000"], ["83964.52000000", "0.00000000"], ["83964.34000000", "0.00000000"], ["83964.33000000", "0.00000000"], ["83964.32000000", "0.00130000"], ["83964.31000000", "0.00000000"], ["83964.18000000", "0.00000000"], ["83964.16000000", "0.00000000"], ["83964.10000000", "0.00000000"], ["83964.09000000", "0.00000000"], ["83963.97000000", "0.00000000"], ["83963.95000000", "0.00000000"], ["83963.89000000", "0.00000000"], ["83963.86000000", "0.00000000"], ["83963.75000000", "0.00000000"], ["83963.74000000", "0.00000000"], ["83963.72000000", "0.00000000"], ["83963.61000000", "0.00000000"], ["83963.60000000", "0.00000000"], ["83963.56000000", "0.00000000"], ["83963.44000000", "0.00000000"], ["83963.42000000", "0.00000000"], ["83963.41000000", "0.00000000"], ["83963.35000000", "0.13907000"], ["83963.32000000", "0.00000000"], ["83963.30000000", "0.00000000"], ["83963.28000000", "0.00000000"], ["83963.27000000", "0.00000000"], ["83963.26000000", "0.00000000"], ["83963.24000000", "0.00000000"], ["83962.93000000", "0.00000000"], ["83962.84000000", "0.00000000"], ["83962.81000000", "0.00006000"], ["83962.79000000", "0.00000000"], ["83962.78000000", "0.00000000"], ["83962.76000000", "0.00000000"], ["83962.71000000", "0.00016000"], ["83962.66000000", "0.00357000"], ["83962.48000000", "0.02445000"], ["83962.42000000", "0.00000000"], ["83962.05000000", "0.00000000"], ["83962.04000000", "0.00000000"], ["83961.99000000", "0.00000000"], ["83961.97000000", "0.00000000"], ["83961.96000000", "0.00000000"], ["83961.94000000", "0.02364000"], ["83961.89000000", "0.00000000"], ["83961.80000000", "0.00000000"], ["83961.77000000", "0.00000000"], ["83961.74000000", "0.00000000"], ["83961.70000000", "0.00000000"], ["83961.69000000", "0.00000000"], ["83961.68000000", "0.00000000"], ["83961.67000000", "0.00000000"], ["83961.61000000", "0.00000000"], ["83961.60000000", "0.00006000"], ["83961.56000000", "0.00000000"], ["83961.51000000", "0.00000000"], ["83961.39000000", "0.00000000"], ["83961.19000000", "0.00000000"], ["83961.09000000", "0.00092000"], ["83960.92000000", "0.00000000"], ["83960.82000000", "0.00000000"], ["83960.80000000", "0.00000000"], ["83960.78000000", "0.00000000"], ["83960.77000000", "0.00020000"], ["83960.76000000", "0.02000000"], ["83960.70000000", "0.00000000"], ["83960.67000000", "0.00000000"], ["83960.66000000", "0.04000000"], ["83960.61000000", "0.00000000"], ["83960.58000000", "0.00000000"], ["83960.50000000", "0.00000000"], ["83960.33000000", "0.00000000"], ["83960.14000000", "0.02213000"], ["83960.07000000", "0.00000000"], ["83960.06000000", "0.08000000"], ["83960.01000000", "0.00029000"], ["83959.99000000", "0.00000000"], ["83959.98000000", "0.00000000"], ["83959.93000000", "0.00000000"], ["83959.88000000", "0.00000000"], ["83959.87000000", "0.00000000"], ["83959.82000000", "0.00000000"], ["83959.76000000", "0.00096000"], ["83959.72000000", "0.00000000"], ["83959.35000000", "0.00000000"], ["83959.10000000", "0.00000000"], ["83958.99000000", "0.02213000"], ["83958.90000000", "0.00000000"], ["83958.87000000", "0.00000000"], ["83958.72000000", "0.00000000"], ["83958.68000000", "0.00000000"], ["83958.58000000", "0.00000000"], ["83958.52000000", "0.00000000"], ["83958.31000000", "0.00000000"], ["83958.28000000", "0.00000000"], ["83958.24000000", "0.00000000"], ["83958.00000000", "0.00006000"], ["83957.88000000", "0.00888000"], ["83957.82000000", "0.00000000"], ["83957.80000000", "0.00000000"], ["83957.79000000", "0.00000000"], ["83957.78000000", "0.00000000"], ["83957.74000000", "0.00029000"], ["83957.57000000", "0.00000000"], ["83957.56000000", "0.10993000"], ["83957.50000000", "0.00000000"], ["83957.46000000", "0.00000000"], ["83957.35000000", "0.00091000"], ["83957.02000000", "0.00000000"], ["83956.91000000", "0.00000000"], ["83956.65000000", "0.00000000"], ["83956.61000000", "0.00000000"], ["83956.60000000", "0.00000000"], ["83956.56000000", "0.00000000"], ["83956.48000000", "0.00000000"], ["83956.20000000", "0.05364000"], ["83956.17000000", "0.00000000"], ["83956.11000000", "0.00000000"], ["83956.09000000", "0.00000000"], ["83956.03000000", "0.00000000"], ["83955.73000000", "0.00000000"], ["83955.69000000", "0.00119000"], ["83955.58000000", "0.00500000"], ["83955.53000000", "0.00007000"], ["83955.40000000", "0.00000000"], ["83955.36000000", "0.00000000"], ["83955.33000000", "0.00000000"], ["83955.28000000", "0.01000000"], ["83955.01000000", "0.00000000"], ["83954.91000000", "0.00411000"], ["83954.90000000", "0.00000000"], ["83954.89000000", "0.16172000"], ["83954.82000000", "0.00500000"], ["83954.80000000", "0.00000000"], ["83954.69000000", "0.00050000"], ["83954.65000000", "0.00000000"], ["83954.52000000", "0.01000000"], ["83954.39000000", "0.04000000"], ["83954.31000000", "0.00007000"], ["83954.30000000", "0.00000000"], ["83954.16000000", "0.08000000"], ["83954.09000000", "0.04000000"], ["83953.86000000", "0.00000000"], ["83953.75000000", "0.00000000"], ["83953.71000000", "0.00000000"], ["83953.51000000", "0.16000000"], ["83953.48000000", "0.29774000"], ["83953.47000000", "0.00000000"], ["83953.40000000", "0.00000000"], ["83953.39000000", "0.00000000"], ["83953.17000000", "0.00000000"], ["83953.05000000", "0.00000000"], ["83952.62000000", "0.04000000"], ["83952.55000000", "0.00000000"], ["83952.46000000", "0.00000000"], ["83952.45000000", "0.00000000"], ["83952.31000000", "0.00000000"], ["83951.72000000", "0.00000000"], ["83951.45000000", "0.00000000"], ["83951.40000000", "0.00000000"], ["83951.38000000", "0.00000000"], ["83951.02000000", "0.00000000"], ["83950.98000000", "0.00000000"], ["83950.80000000", "0.04000000"], ["83950.02000000", "0.00000000"], ["83949.99000000", "0.00000000"], ["83949.92000000", "0.00119000"], ["83949.85000000", "0.15560000"], ["83949.55000000", "0.00000000"], ["83949.53000000", "0.00000000"], ["83949.27000000", "0.00007000"], ["83949.25000000", "0.04000000"], ["83949.18000000", "0.20706000"], ["83949.16000000", "0.35441000"], ["83949.15000000", "0.00000000"], ["83949.10000000", "0.00000000"], ["83948.66000000", "0.00000000"], ["83948.24000000", "0.00000000"], ["83948.23000000", "0.00000000"], ["83948.10000000", "0.00000000"], ["83947.60000000", "0.04000000"], ["83947.56000000", "0.04000000"], ["83947.50000000", "0.04000000"], ["83947.02000000", "0.00000000"], ["83946.58000000", "0.00000000"], ["83945.68000000", "0.85810000"], ["83945.43000000", "0.00000000"], ["83945.29000000", "0.00000000"], ["83945.07000000", "0.00300000"], ["83945.03000000", "0.00000000"], ["83944.97000000", "0.00000000"], ["83944.96000000", "1.01854000"], ["83944.88000000", "0.30231000"], ["83944.58000000", "0.00000000"], ["83944.18000000", "0.10788000"], ["83943.97000000", "0.00000000"], ["83943.81000000", "0.00000000"], ["83943.61000000", "0.00000000"], ["83943.58000000", "0.31657000"], ["83943.51000000", "0.00587000"], ["83943.39000000", "0.00754000"], ["83943.30000000", "0.00000000"], ["83943.29000000", "0.00000000"], ["83943.22000000", "0.00000000"], ["83943.18000000", "0.00000000"], ["83943.00000000", "1.33385000"], ["83942.92000000", "0.00000000"], ["83942.71000000", "0.00016000"], ["83942.52000000", "0.00000000"], ["83942.48000000", "0.00354000"], ["83942.37000000", "0.00000000"], ["83942.15000000", "0.00000000"], ["83942.13000000", "0.00000000"], ["83941.93000000", "0.12103000"], ["83941.49000000", "0.85815000"], ["83941.45000000", "0.00000000"], ["83941.36000000", "0.35737000"], ["83941.32000000", "0.00000000"], ["83940.95000000", "0.59562000"], ["83940.63000000", "0.00000000"], ["83940.57000000", "0.00000000"], ["83940.56000000", "0.00000000"], ["83940.14000000", "0.51068000"], ["83939.45000000", "0.05619000"], ["83939.40000000", "0.89344000"], ["83939.25000000", "0.00000000"], ["83939.07000000", "0.00000000"], ["83938.45000000", "0.00000000"], ["83938.11000000", "0.00000000"], ["83938.02000000", "0.00000000"], ["83938.01000000", "0.00000000"], ["83937.73000000", "0.00000000"], ["83937.52000000", "0.00000000"], ["83937.39000000", "0.00000000"], ["83936.84000000", "0.00000000"], ["83936.60000000", "0.89344000"], ["83936.11000000", "0.00000000"], ["83936.10000000", "0.00000000"], ["83935.79000000", "0.00000000"], ["83935.78000000", "0.00000000"], ["83935.77000000", "0.00000000"], ["83934.79000000", "0.00000000"], ["83934.78000000", "0.00000000"], ["83933.17000000", "0.59579000"], ["83933.15000000", "0.50932000"], ["83933.12000000", "0.00000000"], ["83933.11000000", "0.00000000"], ["83932.80000000", "0.00006000"], ["83932.61000000", "0.37731000"], ["83932.59000000", "1.14175000"], ["83932.16000000", "0.00000000"], ["83932.01000000", "0.00000000"], ["83932.00000000", "0.89554000"], ["83931.88000000", "0.00358000"], ["83931.53000000", "0.00610000"], ["83931.38000000", "0.89344000"], ["83930.99000000", "0.89344000"], ["83930.81000000", "0.00000000"], ["83930.65000000", "0.89344000"], ["83930.53000000", "0.00000000"], ["83929.51000000", "0.00000000"], ["83929.08000000", "0.00000000"], ["83929.07000000", "0.00000000"], ["83928.91000000", "0.01300000"], ["83928.84000000", "0.00000000"], ["83928.83000000", "0.89344000"], ["83928.28000000", "0.00059000"], ["83927.22000000", "0.00000000"], ["83926.53000000", "0.47650000"], ["83925.59000000", "0.00146000"], ["83925.58000000", "0.00000000"], ["83924.51000000", "0.00000000"], ["83923.00000000", "0.00000000"], ["83922.99000000", "0.20982000"], ["83922.93000000", "0.06102000"], ["83922.60000000", "0.00000000"], ["83920.67000000", "0.36791000"], ["83920.30000000", "0.00000000"], ["83920.20000000", "0.00006000"], ["83920.09000000", "0.00000000"], ["83920.00000000", "0.00216000"], ["83919.47000000", "0.03346000"], ["83919.42000000", "0.41683000"], ["83919.19000000", "0.00000000"], ["83918.95000000", "0.00000000"], ["83918.80000000", "0.00000000"], ["83918.71000000", "0.00000000"], ["83918.06000000", "0.00000000"], ["83917.84000000", "0.00000000"], ["83917.31000000", "0.00000000"], ["83916.80000000", "0.00000000"], ["83916.26000000", "0.00000000"], ["83916.25000000", "0.00000000"], ["83916.16000000", "0.00000000"], ["83915.99000000", "0.05957000"], ["83915.87000000", "0.00000000"], ["83915.86000000", "0.00000000"], ["83915.52000000", "0.00000000"], ["83914.70000000", "0.00297000"], ["83914.69000000", "0.01191000"], ["83914.32000000", "0.00000000"], ["83914.31000000", "0.00000000"], ["83914.06000000", "0.00000000"], ["83914.05000000", "0.43431000"], ["83914.04000000", "0.00000000"], ["83913.37000000", "0.21588000"], ["83913.18000000", "0.00000000"], ["83913.12000000", "0.00000000"], ["83912.65000000", "0.05098000"], ["83912.01000000", "0.00000000"], ["83911.99000000", "0.00000000"], ["83911.88000000", "0.00000000"], ["83911.68000000", "0.00000000"], ["83911.06000000", "0.00000000"], ["83910.59000000", "0.00000000"], ["83910.58000000", "0.00000000"], ["83910.55000000", "0.00000000"], ["83910.52000000", "0.00000000"], ["83910.12000000", "0.05497000"], ["83909.14000000", "0.00000000"], ["83909.04000000", "0.00000000"], ["83909.01000000", "0.89344000"], ["83908.80000000", "0.00000000"], ["83908.79000000", "0.32182000"], ["83908.45000000", "0.00000000"], ["83908.02000000", "0.00297000"], ["83908.01000000", "0.54970000"], ["83907.73000000", "0.05497000"], ["83907.37000000", "0.05497000"], ["83907.31000000", "0.00819000"], ["83906.98000000", "0.00000000"], ["83906.91000000", "0.46076000"], ["83906.90000000", "0.16091000"], ["83906.71000000", "0.00142000"], ["83906.40000000", "0.10594000"], ["83905.90000000", "0.00000000"], ["83905.84000000", "0.00000000"], ["83905.62000000", "0.02015000"], ["83905.54000000", "0.10794000"], ["83904.80000000", "0.00819000"], ["83904.79000000", "0.16291000"], ["83904.52000000", "0.00000000"], ["83904.04000000", "0.00000000"], ["83904.01000000", "0.00000000"], ["83903.98000000", "0.05297000"], ["83903.26000000", "0.00000000"], ["83903.23000000", "0.00000000"], ["83903.18000000", "0.00855000"], ["83902.91000000", "0.04000000"], ["83902.47000000", "0.05497000"], ["83902.20000000", "0.00000000"], ["83902.01000000", "0.00299000"], ["83901.36000000", "0.00000000"], ["83901.35000000", "0.46963000"], ["83901.24000000", "0.00000000"], ["83901.18000000", "0.04000000"], ["83901.17000000", "0.00000000"], ["83901.14000000", "0.04000000"], ["83900.81000000", "0.09541000"], ["83900.40000000", "0.05297000"], ["83900.36000000", "0.00000000"], ["83900.30000000", "0.59562000"], ["83900.15000000", "0.09795000"], ["83900.01000000", "0.00000000"], ["83899.27000000", "0.04000000"], ["83899.26000000", "0.15356000"], ["83899.19000000", "0.00000000"], ["83898.77000000", "0.04490000"], ["83898.31000000", "0.86900000"], ["83898.30000000", "0.71399000"], ["83898.29000000", "0.23636000"], ["83897.53000000", "0.00000000"], ["83897.45000000", "0.04598000"], ["83897.22000000", "0.00061000"], ["83897.18000000", "0.04762000"], ["83897.12000000", "0.00825000"], ["83897.03000000", "0.04000000"], ["83896.98000000", "0.04642000"], ["83896.59000000", "0.00000000"], ["83896.40000000", "0.04898000"], ["83895.93000000", "0.30913000"], ["83895.86000000", "0.00000000"], ["83895.01000000", "0.32290000"], ["83894.71000000", "0.09655000"], ["83894.49000000", "0.00000000"], ["83894.48000000", "0.04643000"], ["83894.36000000", "0.00000000"], ["83894.35000000", "0.00000000"], ["83894.01000000", "0.00000000"], ["83893.88000000", "0.39592000"], ["83893.51000000", "0.04198000"], ["83893.50000000", "0.00000000"], ["83893.29000000", "0.04000000"], ["83892.59000000", "0.14000000"], ["83892.22000000", "0.04398000"], ["83892.02000000", "0.00000000"], ["83891.86000000", "0.00000000"], ["83891.37000000", "0.04643000"], ["83889.07000000", "0.71399000"], ["83889.06000000", "0.38215000"], ["83888.70000000", "0.09405000"], ["83888.56000000", "0.14166000"], ["83888.51000000", "0.00143000"], ["83888.49000000", "0.03190000"], ["83888.36000000", "0.00000000"], ["83888.26000000", "0.04000000"], ["83888.19000000", "0.04000000"], ["83888.10000000", "0.00000000"], ["83887.67000000", "0.00000000"], ["83886.66000000", "0.00000000"], ["83886.62000000", "0.00000000"], ["83886.26000000", "0.09524000"], ["83886.20000000", "0.00101000"], ["83885.90000000", "0.00000000"], ["83885.86000000", "0.79634000"], ["83885.51000000", "0.14502000"], ["83885.30000000", "0.00000000"], ["83885.29000000", "1.02998000"], ["83884.97000000", "0.09286000"], ["83884.88000000", "0.00000000"], ["83884.68000000", "0.23569000"], ["83884.53000000", "0.05152000"], ["83884.51000000", "0.04440000"], ["83884.44000000", "0.00000000"], ["83884.00000000", "0.04997000"], ["83883.48000000", "0.14048000"], ["83883.11000000", "0.05097000"], ["83882.52000000", "0.00000000"], ["83882.38000000", "0.03574000"], ["83882.00000000", "0.07027000"], ["83881.94000000", "0.00000000"], ["83881.70000000", "0.00000000"], ["83881.63000000", "0.00000000"], ["83881.47000000", "0.04762000"], ["83881.46000000", "0.46984000"], ["83881.20000000", "0.00000000"], ["83881.13000000", "0.00000000"], ["83880.92000000", "0.04643000"], ["83880.65000000", "0.04762000"], ["83880.56000000", "0.00000000"], ["83879.94000000", "0.04643000"], ["83879.32000000", "0.71399000"], ["83879.13000000", "0.00000000"], ["83878.93000000", "0.00000000"], ["83877.97000000", "0.04643000"], ["83877.94000000", "0.04762000"], ["83877.93000000", "0.14209000"], ["83877.80000000", "0.00000000"], ["83877.79000000", "0.04643000"], ["83876.97000000", "0.00000000"], ["83876.94000000", "0.04762000"], ["83876.91000000", "0.58625000"], ["83876.90000000", "0.09525000"], ["83876.77000000", "0.00000000"], ["83876.66000000", "0.04762000"], ["83876.51000000", "0.00000000"], ["83876.41000000", "0.00000000"], ["83876.00000000", "0.04879000"], ["83875.88000000", "0.04643000"], ["83875.74000000", "0.00000000"], ["83875.60000000", "0.00000000"], ["83875.31000000", "0.09526000"], ["83875.26000000", "0.04762000"], ["83875.20000000", "0.04644000"], ["83875.19000000", "0.00000000"], ["83874.92000000", "0.09406000"], ["83874.91000000", "0.04762000"], ["83874.88000000", "0.04643000"], ["83874.75000000", "0.04762000"], ["83874.52000000", "0.05085000"], ["83874.44000000", "0.00000000"], ["83874.34000000", "0.00000000"], ["83874.27000000", "0.04762000"], ["83874.26000000", "0.04762000"], ["83874.09000000", "0.04762000"], ["83873.95000000", "0.00000000"], ["83873.53000000", "0.04763000"], ["83873.26000000", "0.04762000"], ["83873.11000000", "0.04763000"], ["83873.03000000", "0.04763000"], ["83872.87000000", "0.00000000"], ["83872.82000000", "0.39243000"], ["83872.80000000", "0.00000000"], ["83872.75000000", "0.04762000"], ["83872.73000000", "0.04763000"], ["83872.60000000", "0.04762000"], ["83872.27000000", "0.04762000"], ["83872.11000000", "0.05497000"], ["83871.86000000", "0.04644000"], ["83871.80000000", "0.00000000"], ["83871.79000000", "0.00000000"], ["83871.76000000", "0.00000000"], ["83871.75000000", "0.04644000"], ["83871.72000000", "0.00000000"], ["83871.41000000", "0.00000000"], ["83871.31000000", "0.00000000"], ["83871.12000000", "0.00146000"], ["83871.11000000", "0.04643000"], ["83870.88000000", "0.04763000"], ["83870.81000000", "0.04763000"], ["83870.53000000", "0.04763000"], ["83870.31000000", "0.04762000"], ["83870.30000000", "0.10319000"], ["83870.25000000", "0.05497000"], ["83870.19000000", "0.04763000"], ["83870.18000000", "0.00000000"], ["83870.12000000", "0.00000000"], ["83870.02000000", "0.04763000"], ["83869.66000000", "0.04763000"], ["83869.60000000", "0.50633000"], ["83869.49000000", "0.00000000"], ["83869.40000000", "0.04762000"], ["83869.38000000", "0.04763000"], ["83869.18000000", "0.04763000"], ["83869.17000000", "0.04644000"], ["83869.10000000", "0.00000000"], ["83868.97000000", "0.04762000"], ["83868.92000000", "0.04644000"], ["83868.65000000", "0.00000000"], ["83868.51000000", "0.05497000"], ["83868.36000000", "0.04643000"], ["83868.25000000", "0.00000000"], ["83866.94000000", "0.00000000"], ["83866.91000000", "0.00000000"], ["83866.85000000", "0.05497000"], ["83865.46000000", "0.04644000"], ["83865.26000000", "0.44818000"], ["83865.00000000", "0.00000000"], ["83864.91000000", "0.12900000"], ["83864.52000000", "0.04763000"], ["83864.40000000", "0.00000000"], ["83864.27000000", "0.00000000"], ["83864.26000000", "0.18196000"], ["83864.10000000", "0.04644000"], ["83863.73000000", "0.05497000"], ["83863.61000000", "0.04763000"], ["83863.26000000", "0.04763000"], ["83862.86000000", "0.05497000"], ["83862.50000000", "0.05497000"], ["83862.44000000", "0.00918000"], ["83862.17000000", "0.00000000"], ["83862.04000000", "0.04763000"], ["83861.82000000", "0.04197000"], ["83861.60000000", "0.04763000"], ["83861.09000000", "0.00000000"], ["83860.51000000", "0.04644000"], ["83860.31000000", "0.05097000"], ["83860.05000000", "0.00000000"], ["83859.80000000", "0.05497000"], ["83859.60000000", "0.05497000"], ["83859.21000000", "0.00000000"], ["83859.07000000", "0.00000000"], ["83859.01000000", "0.05097000"], ["83858.46000000", "0.00000000"], ["83858.39000000", "0.05497000"], ["83858.33000000", "0.05497000"], ["83858.12000000", "0.04197000"], ["83857.57000000", "0.05097000"], ["83857.56000000", "0.00000000"], ["83857.00000000", "0.26063000"], ["83856.38000000", "0.05497000"], ["83856.01000000", "0.00083000"], ["83855.92000000", "0.00000000"], ["83855.82000000", "0.05510000"], ["83855.68000000", "0.05097000"], ["83855.57000000", "0.05297000"], ["83855.51000000", "0.10000000"], ["83855.40000000", "0.00000000"], ["83855.36000000", "0.05497000"], ["83854.44000000", "0.04197000"], ["83854.07000000", "0.00000000"], ["83853.56000000", "0.04397000"], ["83853.06000000", "0.05097000"], ["83853.01000000", "0.05097000"], ["83853.00000000", "0.00020000"], ["83852.61000000", "0.05297000"], ["83852.59000000", "0.37767000"], ["83852.45000000", "0.05497000"], ["83851.93000000", "0.05497000"], ["83851.83000000", "0.00000000"], ["83851.46000000", "0.00000000"], ["83851.24000000", "0.05497000"], ["83850.57000000", "0.04897000"], ["83850.13000000", "0.09994000"], ["83849.51000000", "0.05297000"], ["83849.35000000", "0.05297000"], ["83849.34000000", "0.05097000"], ["83849.28000000", "0.05497000"], ["83849.07000000", "0.04897000"], ["83848.92000000", "0.09494000"], ["83848.75000000", "0.00000000"], ["83848.69000000", "0.04197000"], ["83848.29000000", "0.50497000"], ["83848.26000000", "0.04897000"], ["83847.97000000", "0.04897000"], ["83847.89000000", "0.05297000"], ["83847.24000000", "0.05497000"], ["83846.96000000", "0.05497000"], ["83846.84000000", "0.05297000"], ["83846.73000000", "0.05297000"], ["83846.33000000", "0.04897000"], ["83846.29000000", "0.05297000"], ["83846.09000000", "0.00000000"], ["83845.90000000", "0.05497000"], ["83845.78000000", "0.05097000"], ["83845.51000000", "0.05497000"], ["83845.06000000", "0.05496000"], ["83844.64000000", "0.04397000"], ["83844.62000000", "0.04397000"], ["83844.55000000", "0.05297000"], ["83844.36000000", "0.05496000"], ["83844.34000000", "0.04397000"], ["83844.23000000", "0.05297000"], ["83844.12000000", "0.05497000"], ["83843.72000000", "0.05497000"], ["83843.58000000", "0.05297000"], ["83843.26000000", "0.04197000"], ["83843.22000000", "0.05297000"], ["83843.18000000", "0.00000000"], ["83843.14000000", "0.05497000"], ["83842.95000000", "0.04197000"], ["83842.75000000", "0.05497000"], ["83842.49000000", "0.05097000"], ["83842.34000000", "0.11183000"], ["83842.03000000", "0.05497000"], ["83842.01000000", "0.05497000"], ["83841.77000000", "0.04897000"], ["83841.57000000", "0.05297000"], ["83841.56000000", "0.05497000"], ["83841.55000000", "0.05533000"], ["83841.31000000", "0.04897000"], ["83841.18000000", "0.05497000"], ["83841.00000000", "0.05297000"], ["83840.82000000", "0.04897000"], ["83840.33000000", "0.05297000"], ["83840.30000000", "0.05497000"], ["83840.29000000", "0.05497000"], ["83839.87000000", "0.05097000"], ["83839.35000000", "0.04397000"], ["83839.26000000", "0.05497000"], ["83839.12000000", "0.04397000"], ["83838.98000000", "0.04397000"], ["83838.79000000", "0.05497000"], ["83838.77000000", "0.05497000"], ["83838.60000000", "0.10994000"], ["83838.27000000", "0.05497000"], ["83838.26000000", "0.05497000"], ["83838.05000000", "0.05297000"], ["83838.01000000", "0.05497000"], ["83837.85000000", "0.05297000"], ["83837.61000000", "0.04897000"], ["83837.55000000", "0.04897000"], ["83837.53000000", "0.04897000"], ["83837.51000000", "0.04397000"], ["83837.49000000", "0.05497000"], ["83836.83000000", "0.00000000"], ["83836.53000000", "0.05097000"], ["83836.43000000", "0.04197000"], ["83836.20000000", "0.05497000"], ["83836.00000000", "0.05232000"], ["83835.99000000", "0.05497000"], ["83835.91000000", "0.04198000"], ["83835.77000000", "0.04198000"], ["83835.47000000", "0.10994000"], ["83835.41000000", "0.05297000"], ["83835.07000000", "0.05297000"], ["83834.96000000", "0.04397000"], ["83834.46000000", "0.04997000"], ["83833.80000000", "0.04198000"], ["83832.19000000", "0.05297000"], ["83832.01000000", "0.00000000"], ["83831.05000000", "0.00119000"], ["83829.98000000", "0.04397000"], ["83828.84000000", "0.04997000"], ["83828.83000000", "0.04997000"], ["83828.07000000", "0.04197000"], ["83826.90000000", "0.00006000"], ["83825.51000000", "0.09994000"], ["83824.15000000", "0.08794000"], ["83824.02000000", "0.00119000"], ["83824.01000000", "0.00264000"], ["83820.63000000", "0.21433000"], ["83820.31000000", "0.00000000"], ["83819.91000000", "0.00000000"], ["83813.22000000", "0.00000000"], ["83813.21000000", "0.00006000"], ["83811.39000000", "0.00000000"], ["83807.37000000", "0.00000000"], ["83795.76000000", "0.00000000"], ["83793.56000000", "0.99313000"], ["83791.26000000", "0.00000000"], ["83788.14000000", "0.00000000"], ["83788.13000000", "0.00000000"], ["83787.78000000", "0.16225000"], ["83786.07000000", "0.00000000"], ["83784.00000000", "0.00235000"], ["83782.67000000", "0.16225000"], ["83780.02000000", "0.00069000"], ["83774.28000000", "0.16360000"], ["83772.63000000", "0.45000000"], ["83766.40000000", "0.00000000"], ["83762.61000000", "0.00534000"], ["83758.01000000", "0.00000000"], ["83753.68000000", "0.00000000"], ["83753.58000000", "0.00013000"], ["83749.39000000", "0.00013000"], ["83746.10000000", "0.00013000"], ["83743.35000000", "0.02981000"], ["83741.91000000", "0.00013000"], ["83740.34000000", "0.00000000"], ["83735.21000000", "0.00000000"], ["83733.40000000", "0.00400000"], ["83729.38000000", "0.80000000"], ["83729.25000000", "0.00100000"], ["83729.20000000", "0.00000000"], ["83729.16000000", "0.00000000"], ["83684.82000000", "0.00000000"], ["83674.79000000", "0.01195000"], ["83612.42000000", "0.03774000"], ["83537.85000000", "0.00000000"], ["83320.75000000", "0.00119000"], ["83141.42000000", "0.00000000"], ["82721.52000000", "0.00007000"], ["80606.38000000", "0.03571000"], ["75583.00000000", "0.00000000"], ["75573.00000000", "0.00000000"], ["67185.00000000", "0.00015000"], ["67182.80000000", "0.00000000"], ["67173.02000000", "0.00058000"], ["60000.00000000", "72.96726000"], ["33000.00000000", "2.96666000"]], "a": [["83966.28000000", "7.12849000"], ["83966.29000000", "0.00034000"], ["83966.38000000", "0.00000000"], ["83966.51000000", "0.00007000"], ["83966.52000000", "0.00007000"], ["83966.53000000", "0.00000000"], ["83966.90000000", "0.00000000"], ["83967.22000000", "0.00007000"], ["83967.23000000", "0.00021000"], ["83967.24000000", "0.17919000"], ["83968.00000000", "0.01430000"], ["83968.08000000", "0.00000000"], ["83968.19000000", "0.00760000"], ["83968.91000000", "0.00000000"], ["83969.06000000", "0.00000000"], ["83969.11000000", "0.00000000"], ["83969.12000000", "0.00000000"], ["83969.26000000", "0.02356000"], ["83969.28000000", "0.00000000"], ["83969.75000000", "0.00000000"], ["83970.00000000", "0.01423000"], ["83970.07000000", "0.02338000"], ["83970.08000000", "0.00000000"], ["83970.12000000", "0.00000000"], ["83970.14000000", "0.00000000"], ["83970.15000000", "0.00000000"], ["83970.22000000", "0.00014000"], ["83970.23000000", "1.61828000"], ["83970.24000000", "0.78643000"], ["83970.27000000", "0.63000000"], ["83970.28000000", "1.66697000"], ["83970.29000000", "0.00014000"], ["83970.31000000", "0.00000000"], ["83970.54000000", "0.00000000"], ["83970.55000000", "0.00000000"], ["83970.56000000", "0.00000000"], ["83970.57000000", "0.00000000"], ["83970.58000000", "0.00000000"], ["83970.60000000", "0.00000000"], ["83970.61000000", "0.00000000"], ["83970.63000000", "0.00000000"], ["83970.64000000", "0.30035000"], ["83970.65000000", "0.00000000"], ["83970.66000000", "0.00000000"], ["83970.67000000", "0.16978000"], ["83970.78000000", "0.00000000"], ["83970.90000000", "0.00202000"], ["83970.91000000", "0.00000000"], ["83971.77000000", "0.52928000"], ["83971.78000000", "0.00000000"], ["83971.79000000", "0.00000000"], ["83971.99000000", "0.08354000"], ["83972.00000000", "0.01410000"], ["83972.01000000", "0.47650000"], ["83972.07000000", "0.35968000"], ["83972.16000000", "0.00000000"], ["83972.40000000", "0.00000000"], ["83972.41000000", "0.45000000"], ["83972.79000000", "0.00000000"], ["83972.89000000", "0.00000000"], ["83972.90000000", "0.00000000"], ["83972.91000000", "0.00000000"], ["83973.07000000", "0.00000000"], ["83973.09000000", "0.00000000"], ["83973.10000000", "0.00000000"], ["83973.12000000", "0.00000000"], ["83973.13000000", "0.00000000"], ["83973.20000000", "0.00000000"], ["83973.21000000", "0.00000000"], ["83973.22000000", "0.00000000"], ["83973.99000000", "0.00000000"], ["83974.00000000", "0.01410000"], ["83974.01000000", "0.00000000"], ["83974.04000000", "0.00000000"], ["83974.13000000", "0.00000000"], ["83974.32000000", "0.00000000"], ["83974.44000000", "0.00000000"], ["83974.45000000", "0.00000000"], ["83974.48000000", "0.00000000"], ["83974.54000000", "0.00000000"], ["83974.55000000", "0.00000000"], ["83974.56000000", "0.00029000"], ["83974.61000000", "0.00000000"], ["83974.62000000", "0.00000000"], ["83974.73000000", "0.00000000"], ["83974.74000000", "0.00000000"], ["83974.75000000", "0.00000000"], ["83974.76000000", "0.00000000"], ["83974.77000000", "0.00000000"], ["83974.82000000", "0.00000000"], ["83974.88000000", "0.00000000"], ["83975.11000000", "0.00000000"], ["83975.51000000", "0.06800000"], ["83975.57000000", "0.00000000"], ["83975.65000000", "0.00000000"], ["83975.76000000", "0.29723000"], ["83975.77000000", "0.00000000"], ["83975.78000000", "0.00000000"], ["83976.00000000", "0.01410000"], ["83976.26000000", "0.00000000"], ["83976.31000000", "0.00000000"], ["83976.43000000", "0.00000000"], ["83976.72000000", "0.14400000"], ["83976.76000000", "0.00013000"], ["83976.81000000", "0.06400000"], ["83976.82000000", "0.00000000"], ["83976.85000000", "0.00119000"], ["83976.89000000", "0.00000000"], ["83977.00000000", "0.00000000"], ["83977.01000000", "0.35968000"], ["83977.02000000", "0.00000000"], ["83977.10000000", "0.00000000"], ["83977.26000000", "0.00000000"], ["83977.36000000", "0.00000000"], ["83977.68000000", "0.00000000"], ["83977.69000000", "0.00000000"], ["83977.70000000", "0.00000000"], ["83977.72000000", "0.00000000"], ["83977.79000000", "0.00000000"], ["83977.80000000", "0.00000000"], ["83977.83000000", "0.00000000"], ["83977.84000000", "0.00000000"], ["83977.96000000", "0.00000000"], ["83977.98000000", "0.00000000"], ["83978.00000000", "0.01410000"], ["83978.09000000", "0.00000000"], ["83978.10000000", "0.00000000"], ["83978.14000000", "0.00000000"], ["83978.25000000", "0.00000000"], ["83978.26000000", "0.00595000"], ["83978.38000000", "0.00000000"], ["83978.49000000", "0.00000000"], ["83978.50000000", "0.09722000"], ["83978.51000000", "0.00000000"], ["83978.68000000", "0.00300000"], ["83978.86000000", "0.06400000"], ["83978.91000000", "0.00000000"], ["83978.93000000", "0.00000000"], ["83978.95000000", "0.00000000"], ["83978.98000000", "0.00000000"], ["83979.00000000", "0.00019000"], ["83979.01000000", "0.00000000"], ["83979.06000000", "0.05956000"], ["83979.11000000", "0.05956000"], ["83979.28000000", "0.00009000"], ["83979.77000000", "0.00000000"], ["83979.87000000", "0.00000000"], ["83979.88000000", "0.00000000"], ["83979.89000000", "0.00000000"], ["83979.92000000", "0.00000000"], ["83979.94000000", "0.00000000"], ["83979.99000000", "0.52456000"], ["83980.00000000", "0.19333000"], ["83980.01000000", "0.00000000"], ["83980.06000000", "0.00000000"], ["83980.08000000", "0.06000000"], ["83980.09000000", "0.00922000"], ["83980.17000000", "0.00000000"], ["83980.26000000", "0.00000000"], ["83980.53000000", "0.05200000"], ["83980.56000000", "0.00000000"], ["83980.60000000", "0.00000000"], ["83980.61000000", "0.08354000"], ["83980.63000000", "0.07200000"], ["83980.87000000", "0.00000000"], ["83980.91000000", "0.04800000"], ["83981.01000000", "0.00000000"], ["83981.04000000", "0.00000000"], ["83981.12000000", "0.00013000"], ["83981.13000000", "0.00000000"], ["83981.14000000", "0.45000000"], ["83981.15000000", "0.00363000"], ["83981.16000000", "0.00000000"], ["83981.18000000", "0.00000000"], ["83981.19000000", "0.00000000"], ["83981.20000000", "0.00000000"], ["83981.21000000", "0.00000000"], ["83981.23000000", "0.00000000"], ["83981.24000000", "0.00000000"], ["83981.25000000", "0.17137000"], ["83981.26000000", "0.00000000"], ["83981.28000000", "0.00000000"], ["83981.29000000", "0.00000000"], ["83981.30000000", "0.00000000"], ["83981.31000000", "0.00000000"], ["83981.32000000", "0.00000000"], ["83981.33000000", "0.00000000"], ["83981.35000000", "0.00000000"], ["83981.71000000", "0.10788000"], ["83981.77000000", "0.00000000"], ["83981.84000000", "0.30310000"], ["83982.00000000", "0.01410000"], ["83982.15000000", "0.89344000"], ["83982.26000000", "0.00000000"], ["83982.46000000", "0.05956000"], ["83982.51000000", "0.09200000"], ["83982.82000000", "0.10000000"], ["83982.91000000", "0.00000000"], ["83982.92000000", "0.00000000"], ["83982.95000000", "0.00006000"], ["83983.02000000", "0.00000000"], ["83983.09000000", "0.00000000"], ["83983.20000000", "0.00006000"], ["83983.36000000", "0.06800000"], ["83983.46000000", "0.02978000"], ["83983.48000000", "0.00000000"], ["83983.52000000", "0.00000000"], ["83983.61000000", "0.00000000"], ["83983.69000000", "0.00013000"], ["83984.00000000", "0.01410000"], ["83984.12000000", "0.04000000"], ["83984.30000000", "0.00000000"], ["83984.41000000", "0.54740000"], ["83984.42000000", "0.00000000"], ["83984.87000000", "0.04000000"], ["83984.98000000", "0.89344000"], ["83985.10000000", "0.00000000"], ["83985.21000000", "0.00000000"], ["83985.55000000", "0.00000000"], ["83985.70000000", "0.01190000"], ["83985.73000000", "0.00000000"], ["83985.80000000", "0.00000000"], ["83986.10000000", "0.00000000"], ["83986.20000000", "0.89344000"], ["83986.72000000", "0.00000000"], ["83986.77000000", "0.00000000"], ["83986.86000000", "0.00000000"], ["83987.13000000", "0.00000000"], ["83987.40000000", "0.00006000"], ["83987.49000000", "0.00013000"], ["83987.68000000", "0.00009000"], ["83987.73000000", "0.00000000"], ["83987.96000000", "0.00000000"], ["83988.00000000", "0.03274000"], ["83988.28000000", "0.48864000"], ["83988.29000000", "0.71399000"], ["83988.30000000", "0.00000000"], ["83988.34000000", "0.00000000"], ["83988.35000000", "0.00000000"], ["83988.59000000", "0.00000000"], ["83989.09000000", "0.00000000"], ["83989.21000000", "0.08992000"], ["83989.63000000", "0.00000000"], ["83989.99000000", "0.00000000"], ["83990.00000000", "0.00000000"], ["83990.01000000", "0.00000000"], ["83990.47000000", "0.00000000"], ["83990.49000000", "0.00000000"], ["83991.08000000", "0.00000000"], ["83991.09000000", "0.00000000"], ["83991.12000000", "0.00119000"], ["83991.33000000", "0.00000000"], ["83991.70000000", "0.00000000"], ["83991.74000000", "0.85763000"], ["83991.99000000", "0.85030000"], ["83992.00000000", "0.00000000"], ["83992.44000000", "0.00000000"], ["83992.76000000", "0.00000000"], ["83992.83000000", "0.00000000"], ["83992.86000000", "0.00000000"], ["83993.18000000", "0.16000000"], ["83993.35000000", "0.00000000"], ["83993.61000000", "0.71399000"], ["83993.71000000", "0.89344000"], ["83993.76000000", "0.16360000"], ["83993.84000000", "0.00000000"], ["83994.00000000", "0.00000000"], ["83994.43000000", "0.00000000"], ["83994.56000000", "0.00000000"], ["83994.94000000", "0.00000000"], ["83995.28000000", "0.00151000"], ["83995.29000000", "0.85760000"], ["83995.30000000", "0.00059000"], ["83995.36000000", "0.00000000"], ["83995.42000000", "0.89344000"], ["83995.99000000", "1.78474000"], ["83996.00000000", "0.89344000"], ["83996.15000000", "0.00914000"], ["83996.52000000", "0.89344000"], ["83996.68000000", "0.89344000"], ["83996.72000000", "0.59579000"], ["83997.19000000", "0.00000000"], ["83997.76000000", "0.28912000"], ["83997.94000000", "0.00000000"], ["83998.00000000", "0.00000000"], ["83998.12000000", "0.00238000"], ["83999.05000000", "0.00029000"], ["83999.25000000", "0.16360000"], ["83999.36000000", "0.00000000"], ["83999.59000000", "0.85755000"], ["83999.78000000", "0.00000000"], ["83999.80000000", "0.00000000"], ["83999.89000000", "0.28526000"], ["83999.93000000", "0.00059000"], ["84000.00000000", "0.00030000"], ["84000.01000000", "1.88143000"], ["84000.02000000", "0.00000000"], ["84000.60000000", "0.00000000"], ["84000.79000000", "0.85754000"], ["84000.85000000", "0.00016000"], ["84000.88000000", "0.00000000"], ["84001.07000000", "0.89344000"], ["84001.17000000", "0.00100000"], ["84002.00000000", "0.00000000"], ["84002.66000000", "0.00000000"], ["84002.78000000", "0.89344000"], ["84003.69000000", "0.00000000"], ["84003.93000000", "0.00000000"], ["84003.96000000", "0.00000000"], ["84003.98000000", "0.00000000"], ["84004.45000000", "0.00000000"], ["84004.54000000", "0.27797000"], ["84004.56000000", "0.00000000"], ["84005.08000000", "0.00000000"], ["84005.36000000", "0.02808000"], ["84005.47000000", "0.00000000"], ["84005.92000000", "0.00000000"], ["84006.19000000", "0.00000000"], ["84006.36000000", "0.00000000"], ["84006.79000000", "0.00360000"], ["84007.92000000", "0.00000000"], ["84008.10000000", "0.00575000"], ["84008.78000000", "0.00000000"], ["84009.27000000", "0.00000000"], ["84009.49000000", "0.00000000"], ["84009.79000000", "0.00000000"], ["84009.94000000", "0.00000000"], ["84009.95000000", "0.69857000"], ["84010.20000000", "0.04159000"], ["84010.31000000", "0.00000000"], ["84010.93000000", "0.21069000"], ["84011.46000000", "0.00000000"], ["84012.02000000", "0.00000000"], ["84012.26000000", "0.00059000"], ["84012.90000000", "0.00000000"], ["84013.00000000", "0.00000000"], ["84013.23000000", "0.03533000"], ["84013.35000000", "0.11901000"], ["84013.85000000", "0.00699000"], ["84013.91000000", "0.00000000"], ["84014.66000000", "0.49697000"], ["84015.67000000", "0.00000000"], ["84015.77000000", "0.00000000"], ["84015.82000000", "0.00000000"], ["84016.07000000", "0.00000000"], ["84016.87000000", "0.00000000"], ["84018.39000000", "0.52202000"], ["84018.49000000", "0.00824000"], ["84018.76000000", "0.00000000"], ["84019.04000000", "0.00000000"], ["84019.17000000", "0.00863000"], ["84019.21000000", "0.00816000"], ["84019.59000000", "0.37799000"], ["84019.79000000", "0.00000000"], ["84019.94000000", "0.04110000"], ["84020.15000000", "0.72212000"], ["84021.00000000", "0.00006000"], ["84021.18000000", "0.00000000"], ["84021.73000000", "0.09962000"], ["84021.81000000", "0.00000000"], ["84022.36000000", "0.00000000"], ["84022.80000000", "0.02877000"], ["84023.24000000", "0.00000000"], ["84023.34000000", "0.13929000"], ["84023.35000000", "0.00000000"], ["84023.43000000", "0.00000000"], ["84023.53000000", "0.00000000"], ["84023.86000000", "0.00000000"], ["84023.92000000", "0.00000000"], ["84026.26000000", "0.04643000"], ["84026.27000000", "0.00000000"], ["84026.34000000", "0.00000000"], ["84026.72000000", "0.00000000"], ["84027.89000000", "0.09524000"], ["84027.90000000", "0.00000000"], ["84028.31000000", "0.07371000"], ["84028.75000000", "0.04763000"], ["84029.26000000", "0.00000000"], ["84030.25000000", "0.13276000"], ["84030.26000000", "0.09524000"], ["84030.27000000", "0.00000000"], ["84030.29000000", "0.00000000"], ["84030.47000000", "0.00100000"], ["84030.50000000", "0.00000000"], ["84030.88000000", "0.00000000"], ["84031.14000000", "0.04763000"], ["84032.41000000", "0.04763000"], ["84032.42000000", "0.04762000"], ["84032.43000000", "0.00000000"], ["84032.80000000", "0.04763000"], ["84032.81000000", "0.00000000"], ["84034.38000000", "0.00000000"], ["84035.33000000", "0.00000000"], ["84035.37000000", "0.00000000"], ["84035.49000000", "0.00000000"], ["84035.56000000", "0.00000000"], ["84036.62000000", "0.00119000"], ["84037.00000000", "0.06800000"], ["84038.78000000", "0.42309000"], ["84039.28000000", "0.00000000"], ["84040.45000000", "0.05950000"], ["84041.00000000", "0.00000000"], ["84041.68000000", "1.02807000"], ["84042.11000000", "0.30000000"], ["84043.96000000", "0.00000000"], ["84044.51000000", "0.42124000"], ["84049.56000000", "0.03190000"], ["84049.80000000", "0.00146000"], ["84050.61000000", "0.05281000"], ["84051.59000000", "0.09637000"], ["84051.66000000", "0.04198000"], ["84052.11000000", "0.15157000"], ["84052.79000000", "0.00000000"], ["84053.82000000", "0.12900000"], ["84054.12000000", "0.00000000"], ["84054.71000000", "0.04198000"], ["84055.18000000", "0.04197000"], ["84056.04000000", "0.20457000"], ["84059.23000000", "0.10319000"], ["84061.08000000", "0.04644000"], ["84061.09000000", "0.00297000"], ["84061.83000000", "0.00000000"], ["84062.71000000", "0.00000000"], ["84064.24000000", "0.04644000"], ["84064.25000000", "0.08636000"], ["84064.58000000", "0.33653000"], ["84064.75000000", "0.08327000"], ["84066.89000000", "0.09407000"], ["84066.90000000", "0.04198000"], ["84066.91000000", "0.19428000"], ["84066.97000000", "0.12899000"], ["84067.97000000", "0.05793000"], ["84069.80000000", "0.19666000"], ["84070.58000000", "0.00000000"], ["84070.78000000", "0.00000000"], ["84070.88000000", "0.04763000"], ["84071.03000000", "0.05496000"], ["84071.24000000", "0.05496000"], ["84071.25000000", "0.00000000"], ["84071.64000000", "0.04644000"], ["84071.65000000", "0.54425000"], ["84071.88000000", "0.05297000"], ["84072.26000000", "0.11624000"], ["84073.10000000", "0.00040000"], ["84073.79000000", "0.05297000"], ["84074.08000000", "0.05496000"], ["84074.09000000", "0.00000000"], ["84074.85000000", "0.10259000"], ["84075.16000000", "0.05297000"], ["84076.70000000", "0.00000000"], ["84077.02000000", "0.04763000"], ["84077.03000000", "0.00060000"], ["84077.65000000", "0.04763000"], ["84077.66000000", "0.00000000"], ["84080.61000000", "0.00000000"], ["84081.79000000", "0.00000000"], ["84084.02000000", "0.04762000"], ["84085.21000000", "0.04397000"], ["84085.97000000", "0.05097000"], ["84089.21000000", "0.10594000"], ["84089.63000000", "0.05497000"], ["84090.71000000", "0.09294000"], ["84090.74000000", "0.00000000"], ["84091.57000000", "0.25783000"], ["84092.40000000", "0.00006000"], ["84092.67000000", "0.05097000"], ["84092.86000000", "0.02383000"], ["84093.72000000", "0.04997000"], ["84095.65000000", "0.05097000"], ["84095.67000000", "0.04642000"], ["84096.91000000", "0.04397000"], ["84097.85000000", "0.00000000"], ["84097.99000000", "0.04397000"], ["84098.52000000", "0.05097000"], ["84098.63000000", "0.04397000"], ["84099.43000000", "0.02500000"], ["84099.54000000", "0.00000000"], ["84101.51000000", "0.05097000"], ["84104.46000000", "0.00000000"], ["84105.69000000", "0.00000000"], ["84107.17000000", "0.00000000"], ["84108.54000000", "0.00000000"], ["84110.84000000", "0.00000000"], ["84114.37000000", "0.68991000"], ["84115.01000000", "0.00000000"], ["84115.72000000", "0.00000000"], ["84115.81000000", "0.04762000"], ["84115.90000000", "0.00000000"], ["84117.29000000", "0.00000000"], ["84117.33000000", "0.00000000"], ["84117.55000000", "0.00000000"], ["84117.80000000", "0.00000000"], ["84117.91000000", "0.00000000"], ["84117.99000000", "0.00000000"], ["84118.37000000", "0.00000000"], ["84118.39000000", "0.00000000"], ["84119.21000000", "0.00000000"], ["84119.55000000", "0.00000000"], ["84119.68000000", "0.00000000"], ["84119.69000000", "0.00000000"], ["84120.62000000", "0.00000000"], ["84120.65000000", "0.00000000"], ["84120.73000000", "0.00000000"], ["84121.15000000", "0.00000000"], ["84122.13000000", "0.00000000"], ["84122.49000000", "0.00000000"], ["84122.62000000", "0.00000000"], ["84122.75000000", "0.00000000"], ["84122.91000000", "0.00000000"], ["84122.94000000", "0.00000000"], ["84123.04000000", "0.00000000"], ["84123.52000000", "0.00013000"], ["84123.84000000", "0.00000000"], ["84124.16000000", "0.00000000"], ["84124.58000000", "0.00000000"], ["84124.92000000", "0.00000000"], ["84125.00000000", "0.00048000"], ["84125.93000000", "0.00000000"], ["84126.14000000", "0.00000000"], ["84126.95000000", "0.00000000"], ["84127.78000000", "0.00000000"], ["84128.36000000", "0.00000000"], ["84128.45000000", "0.00000000"], ["84129.56000000", "0.00000000"], ["84129.80000000", "0.00000000"], ["84130.00000000", "0.00000000"], ["84130.30000000", "0.00000000"], ["84131.74000000", "0.00000000"], ["84134.25000000", "0.00000000"], ["84139.23000000", "0.01000000"], ["84139.43000000", "0.00000000"], ["84152.06000000", "0.00000000"], ["84155.87000000", "0.00000000"], ["84156.66000000", "0.99129000"], ["84159.65000000", "0.00010000"], ["84159.82000000", "0.05798000"], ["84160.62000000", "0.00000000"], ["84163.93000000", "0.00787000"], ["84165.67000000", "0.00000000"], ["84167.67000000", "0.00000000"], ["84173.26000000", "0.00000000"], ["84233.20000000", "0.00000000"], ["84234.66000000", "0.03591000"], ["84235.24000000", "0.03631000"], ["84248.87000000", "0.28189000"], ["84257.53000000", "0.00000000"], ["84262.23000000", "0.16360000"], ["84262.31000000", "0.00000000"], ["84264.64000000", "0.00000000"], ["84267.72000000", "0.00000000"], ["84270.62000000", "0.16360000"], ["84271.63000000", "0.00000000"], ["84274.44000000", "0.00000000"], ["84277.19000000", "0.00000000"], ["84279.01000000", "0.06668000"], ["84282.83000000", "0.00000000"], ["84285.58000000", "0.00000000"], ["84288.16000000", "0.14319000"], ["84294.86000000", "0.00000000"], ["84295.23000000", "0.00000000"], ["84305.73000000", "0.00000000"], ["84307.61000000", "0.00100000"], ["84349.86000000", "0.00000000"], ["84359.86000000", "0.00000000"], ["84365.44000000", "0.00000000"], ["84638.40000000", "0.00006000"], ["85197.51000000", "0.10000000"], ["85240.97000000", "0.00000000"], ["85248.64000000", "0.00000000"], ["85285.20000000", "0.05872000"], ["85306.50000000", "0.00000000"], ["150001.00000000", "0.00080000"]], "record_time": 1742577061.215116, "EXCHANGE": "BINANCE"}
{"e": "depthUpdate", "E": 1742577062014, "s": "BTCUSDT", "U": 64632107672, "u": 64632108064, "b": [["83966.27000000", "0.11457000"], ["83966.26000000", "0.00069000"], ["83966.07000000", "0.00193000"], ["83966.06000000", "0.78654000"], ["83965.56000000", "0.00014000"], ["83964.76000000", "0.00007000"], ["83964.72000000", "0.00000000"], ["83964.48000000", "0.00006000"], ["83964.32000000", "0.00008000"], ["83963.35000000", "0.00000000"], ["83962.48000000", "0.02439000"], ["83962.22000000", "0.00007000"], ["83962.10000000", "0.00500000"], ["83961.94000000", "0.00000000"], ["83961.60000000", "0.00000000"], ["83960.76000000", "0.02007000"], ["83960.66000000", "0.04007000"], ["83960.14000000", "0.05217000"], ["83958.86000000", "0.00000000"], ["83958.85000000", "0.05364000"], ["83957.88000000", "0.00000000"], ["83956.20000000", "0.00000000"], ["83954.69000000", "0.00050000"], ["83953.46000000", "0.04000000"], ["83950.84000000", "0.00000000"], ["83949.85000000", "0.15057000"], ["83949.48000000", "0.00059000"], ["83947.51000000", "0.47650000"], ["83946.02000000", "0.00120000"], ["83945.85000000", "0.00506000"], ["83944.96000000", "1.36386000"], ["83944.61000000", "0.03574000"], ["83943.58000000", "0.00000000"], ["83943.39000000", "0.00000000"], ["83941.08000000", "0.00300000"], ["83940.95000000", "0.67128000"], ["83940.56000000", "0.00757000"], ["83934.77000000", "0.02502000"], ["83932.60000000", "0.08354000"], ["83928.91000000", "0.00000000"], ["83924.02000000", "0.34718000"], ["83924.01000000", "0.36353000"], ["83922.99000000", "0.00000000"], ["83919.90000000", "0.05000000"], ["83902.92000000", "0.04000000"], ["83902.91000000", "0.00000000"], ["83901.24000000", "0.04000000"], ["83893.51000000", "0.00000000"], ["83893.29000000", "0.00000000"], ["83888.26000000", "0.00000000"], ["83888.19000000", "0.00000000"], ["83871.76000000", "0.63058000"], ["83866.97000000", "0.01196000"], ["83850.12000000", "0.00000000"], ["83850.06000000", "0.00060000"], ["83827.43000000", "0.04197000"], ["83827.30000000", "0.00000000"], ["83827.24000000", "0.00060000"], ["83810.42000000", "0.00000000"], ["83807.36000000", "0.99313000"], ["83798.16000000", "0.00009000"], ["83797.74000000", "0.01527000"], ["83793.56000000", "0.00000000"], ["83768.00000000", "0.00353000"], ["83751.35000000", "0.00000000"], ["83747.34000000", "0.01864000"], ["83745.67000000", "0.00000000"], ["83745.48000000", "0.00400000"], ["83733.40000000", "0.00000000"], ["83693.33000000", "0.03711000"], ["83683.37000000", "0.00000000"], ["83618.01000000", "0.00000000"], ["83617.97000000", "0.00040000"], ["82881.54000000", "0.00000000"], ["82881.43000000", "0.00040000"], ["82706.77000000", "0.00100000"], ["75569.00000000", "0.00021000"], ["67173.02000000", "0.00058000"], ["33000.00000000", "2.96666000"], ["30227.86000000", "0.00020000"]], "a": [["83966.28000000", "8.40438000"], ["83966.29000000", "0.00047000"], ["83967.24000000", "0.17919000"], ["83967.95000000", "0.01210000"], ["83968.00000000", "0.01423000"], ["83968.19000000", "0.00000000"], ["83969.26000000", "0.00000000"], ["83969.84000000", "0.00000000"], ["83970.00000000", "0.01423000"], ["83970.07000000", "0.02338000"], ["83970.19000000", "0.00014000"], ["83970.20000000", "0.90597000"], ["83970.21000000", "0.00000000"], ["83970.22000000", "0.00000000"], ["83970.23000000", "0.00000000"], ["83970.24000000", "0.00000000"], ["83970.28000000", "1.61726000"], ["83970.29000000", "0.00000000"], ["83970.48000000", "0.03345000"], ["83970.56000000", "0.00759000"], ["83970.64000000", "0.00000000"], ["83970.67000000", "0.00000000"], ["83971.77000000", "0.52928000"], ["83971.99000000", "0.08354000"], ["83972.07000000", "0.00000000"], ["83972.24000000", "0.78635000"], ["83972.87000000", "0.00006000"], ["83972.99000000", "0.01190000"], ["83974.66000000", "0.09200000"], ["83974.80000000", "0.00006000"], ["83975.76000000", "0.22184000"], ["83978.50000000", "0.16217000"], ["83978.86000000", "0.07590000"], ["83979.11000000", "0.00000000"], ["83979.99000000", "0.74846000"], ["83981.21000000", "0.05956000"], ["83981.25000000", "0.06642000"], ["83982.51000000", "0.00000000"], ["83983.07000000", "0.00059000"], ["83983.08000000", "0.00300000"], ["83983.36000000", "0.00000000"], ["83984.36000000", "0.02348000"], ["83984.41000000", "0.78748000"], ["83985.16000000", "1.00000000"], ["83988.00000000", "0.01410000"], ["83988.28000000", "0.76905000"], ["83988.30000000", "0.00000000"], ["83988.57000000", "1.33283000"], ["83991.74000000", "0.00000000"], ["83995.30000000", "0.00000000"], ["83996.55000000", "0.00000000"], ["83996.72000000", "0.00000000"], ["84000.01000000", "1.32289000"], ["84001.88000000", "0.59578000"], ["84002.70000000", "0.00500000"], ["84004.20000000", "0.00019000"], ["84004.51000000", "0.54082000"], ["84004.52000000", "0.85750000"], ["84004.54000000", "0.00000000"], ["84008.34000000", "0.02016000"], ["84013.88000000", "0.01196000"], ["84014.66000000", "0.32335000"], ["84014.67000000", "0.00000000"], ["84015.50000000", "0.16356000"], ["84016.93000000", "0.00000000"], ["84020.81000000", "0.00699000"], ["84031.83000000", "0.09200000"], ["84032.80000000", "0.12363000"], ["84032.99000000", "0.00214000"], ["84035.02000000", "0.69152000"], ["84035.34000000", "0.08354000"], ["84036.89000000", "0.02847000"], ["84049.74000000", "0.01864000"], ["84052.88000000", "0.00000000"], ["84054.60000000", "0.00000000"], ["84063.00000000", "0.00000000"], ["84064.35000000", "0.00060000"], ["84064.75000000", "0.05496000"], ["84075.53000000", "0.00000000"], ["84077.03000000", "0.00000000"], ["84083.44000000", "0.00679000"], ["84084.49000000", "0.00000000"], ["84092.80000000", "0.04397000"], ["84098.75000000", "0.04397000"], ["84100.78000000", "0.12000000"], ["84112.30000000", "0.00000000"], ["84119.27000000", "0.00000000"], ["84139.13000000", "0.01000000"], ["84139.23000000", "0.00000000"], ["84139.33000000", "0.00000000"], ["84147.51000000", "0.99017000"], ["84156.66000000", "0.00000000"], ["84213.29000000", "0.00000000"], ["84217.48000000", "0.00000000"], ["84220.15000000", "0.00000000"], ["84223.20000000", "0.00000000"], ["84461.30000000", "0.00000000"], ["84496.97000000", "0.03676000"], ["85225.78000000", "0.00100000"]], "record_time": 1742577062.212483, "EXCHANGE": "BINANCE"}
{"e": "depthUpdate", "E": 1742577063014, "s": "BTCUSDT", "U": 64632108065, "u": 64632110500, "b": [["83966.27000000", "0.00000000"], ["83966.26000000", "0.00000000"], ["83966.07000000", "0.00000000"], ["83966.06000000", "0.00000000"], ["83965.56000000", "0.00000000"], ["83965.51000000", "0.00000000"], ["83964.86000000", "0.00000000"], ["83964.77000000", "0.00000000"], ["83964.76000000", "0.00000000"], ["83964.48000000", "0.00000000"], ["83964.38000000", "0.00000000"], ["83964.37000000", "0.00000000"], ["83964.36000000", "0.00000000"], ["83964.32000000", "0.00000000"], ["83963.89000000", "0.00000000"], ["83963.77000000", "0.00000000"], ["83963.13000000", "0.00000000"], ["83962.81000000", "0.00000000"], ["83962.79000000", "0.00000000"], ["83962.71000000", "0.00000000"], ["83962.67000000", "0.00000000"], ["83962.66000000", "0.00000000"], ["83962.49000000", "0.00000000"], ["83962.48000000", "0.00000000"], ["83962.44000000", "0.00000000"], ["83962.43000000", "0.00000000"], ["83962.29000000", "0.00000000"], ["83962.28000000", "0.00000000"], ["83962.22000000", "0.00000000"], ["83962.20000000", "0.00000000"], ["83962.16000000", "0.00000000"], ["83962.15000000", "0.00000000"], ["83962.12000000", "0.00000000"], ["83962.11000000", "0.00000000"], ["83962.10000000", "0.00000000"], ["83961.87000000", "0.00000000"], ["83961.86000000", "0.00000000"], ["83961.78000000", "0.00000000"], ["83961.55000000", "0.00000000"], ["83961.38000000", "0.00000000"], ["83961.09000000", "0.00000000"], ["83960.86000000", "0.00000000"], ["83960.77000000", "0.00000000"], ["83960.76000000", "0.00000000"], ["83960.66000000", "0.00000000"], ["83960.60000000", "0.00000000"], ["83960.59000000", "0.00000000"], ["83960.55000000", "0.00000000"], ["83960.48000000", "0.00000000"], ["83960.47000000", "0.00000000"], ["83960.39000000", "0.00000000"], ["83960.38000000", "0.00000000"], ["83960.16000000", "0.00000000"], ["83960.15000000", "0.00000000"], ["83960.14000000", "0.00000000"], ["83960.06000000", "0.00000000"], ["83960.01000000", "0.00000000"], ["83960.00000000", "0.00000000"], ["83959.76000000", "0.00000000"], ["83959.71000000", "0.00000000"], ["83959.63000000", "0.00000000"], ["83959.62000000", "0.00000000"], ["83959.57000000", "0.00000000"], ["83959.56000000", "0.00000000"], ["83959.13000000", "0.00000000"], ["83959.12000000", "0.12516000"], ["83959.11000000", "0.00037000"], ["83959.00000000", "0.00000000"], ["83958.99000000", "0.00000000"], ["83958.94000000", "0.00000000"], ["83958.85000000", "0.00000000"], ["83958.69000000", "0.00025000"], ["83958.68000000", "0.00054000"], ["83958.67000000", "0.00007000"], ["83958.57000000", "0.00000000"], ["83958.49000000", "0.00007000"], ["83958.30000000", "0.00000000"], ["83958.05000000", "0.00007000"], ["83958.00000000", "0.00000000"], ["83957.83000000", "0.00000000"], ["83957.78000000", "0.00000000"], ["83957.77000000", "0.00000000"], ["83957.74000000", "0.00000000"], ["83957.56000000", "0.00000000"], ["83957.36000000", "0.00000000"], ["83957.35000000", "0.00007000"], ["83956.87000000", "0.00037000"], ["83956.86000000", "0.00000000"], ["83956.83000000", "0.00014000"], ["83956.82000000", "0.78655000"], ["83956.77000000", "0.00017000"], ["83956.76000000", "0.00000000"], ["83956.00000000", "0.00010000"], ["83955.97000000", "0.00000000"], ["83955.96000000", "0.00000000"], ["83955.73000000", "0.00000000"], ["83955.69000000", "0.00000000"], ["83955.62000000", "0.00000000"], ["83955.58000000", "0.00000000"], ["83955.53000000", "0.00000000"], ["83955.28000000", "0.00000000"], ["83955.26000000", "0.00000000"], ["83954.91000000", "0.00000000"], ["83954.90000000", "0.00000000"], ["83954.89000000", "0.02219000"], ["83954.82000000", "0.00000000"], ["83954.72000000", "0.00000000"], ["83954.69000000", "0.00050000"], ["83954.52000000", "0.00000000"], ["83954.39000000", "0.00000000"], ["83954.37000000", "0.00000000"], ["83954.36000000", "0.14000000"], ["83954.16000000", "0.00000000"], ["83954.12000000", "0.00000000"], ["83954.09000000", "0.00000000"], ["83953.74000000", "0.00000000"], ["83953.51000000", "0.00000000"], ["83953.48000000", "0.00000000"], ["83953.46000000", "0.00000000"], ["83952.92000000", "0.00000000"], ["83952.62000000", "0.00000000"], ["83952.08000000", "0.00000000"], ["83952.05000000", "0.02213000"], ["83951.58000000", "0.00000000"], ["83951.52000000", "0.14720000"], ["83951.48000000", "0.00000000"], ["83951.41000000", "0.00000000"], ["83951.29000000", "0.00000000"], ["83951.24000000", "0.00000000"], ["83950.82000000", "0.00000000"], ["83950.80000000", "0.00000000"], ["83950.63000000", "0.00000000"], ["83950.58000000", "0.00029000"], ["83950.48000000", "0.00000000"], ["83950.39000000", "0.00000000"], ["83949.92000000", "0.00000000"], ["83949.85000000", "0.00000000"], ["83949.72000000", "0.00000000"], ["83949.62000000", "0.04000000"], ["83949.61000000", "0.04000000"], ["83949.54000000", "0.04000000"], ["83949.43000000", "0.65170000"], ["83949.42000000", "0.00000000"], ["83949.41000000", "0.00000000"], ["83949.33000000", "0.16172000"], ["83949.29000000", "0.00000000"], ["83949.25000000", "0.00096000"], ["83949.18000000", "0.00000000"], ["83949.16000000", "0.00000000"], ["83948.54000000", "0.00119000"], ["83947.99000000", "0.05364000"], ["83947.98000000", "0.01500000"], ["83947.90000000", "0.16000000"], ["83947.60000000", "0.00000000"], ["83947.56000000", "0.00000000"], ["83947.51000000", "0.00000000"], ["83947.50000000", "0.00000000"], ["83947.29000000", "0.04000000"], ["83947.22000000", "0.01500000"], ["83946.26000000", "0.03100000"], ["83946.25000000", "0.04000000"], ["83946.02000000", "0.00000000"], ["83945.86000000", "0.45000000"], ["83945.68000000", "0.00000000"], ["83944.96000000", "0.75524000"], ["83944.93000000", "0.00200000"], ["83944.61000000", "0.00000000"], ["83944.37000000", "0.00000000"], ["83944.18000000", "0.00000000"], ["83943.78000000", "0.00412000"], ["83943.56000000", "0.00000000"], ["83943.04000000", "0.00000000"], ["83943.00000000", "0.00000000"], ["83942.62000000", "0.15057000"], ["83942.37000000", "0.20846000"], ["83942.14000000", "0.00000000"], ["83942.01000000", "0.00000000"], ["83941.93000000", "0.00000000"], ["83941.81000000", "0.00120000"], ["83941.65000000", "0.00000000"], ["83941.49000000", "0.00000000"], ["83941.36000000", "0.00000000"], ["83941.26000000", "0.00000000"], ["83940.95000000", "0.59562000"], ["83940.56000000", "0.00000000"], ["83940.14000000", "0.75012000"], ["83940.13000000", "0.47650000"], ["83939.73000000", "0.00090000"], ["83938.39000000", "0.00000000"], ["83938.31000000", "0.00000000"], ["83938.25000000", "0.00000000"], ["83937.95000000", "0.00119000"], ["83937.59000000", "0.00000000"], ["83937.47000000", "0.00000000"], ["83936.61000000", "0.99749000"], ["83936.54000000", "0.00000000"], ["83936.45000000", "0.85820000"], ["83935.55000000", "0.11400000"], ["83934.78000000", "0.00000000"], ["83934.77000000", "0.00120000"], ["83933.93000000", "0.01610000"], ["83933.49000000", "1.33874000"], ["83933.23000000", "0.35737000"], ["83933.17000000", "0.00000000"], ["83933.15000000", "0.00000000"], ["83933.05000000", "0.00755000"], ["83932.60000000", "0.00000000"], ["83931.88000000", "0.00000000"], ["83931.53000000", "0.00000000"], ["83931.47000000", "0.00000000"], ["83931.41000000", "0.00101000"], ["83928.84000000", "0.00000000"], ["83928.45000000", "0.00000000"], ["83928.28000000", "0.00000000"], ["83927.51000000", "0.00000000"], ["83926.37000000", "0.00000000"], ["83925.59000000", "0.00000000"], ["83924.39000000", "0.59586000"], ["83924.01000000", "0.00000000"], ["83923.45000000", "0.00358000"], ["83922.93000000", "0.00000000"], ["83921.51000000", "0.00146000"], ["83920.21000000", "0.02200000"], ["83920.13000000", "0.00000000"], ["83920.05000000", "0.51561000"], ["83920.04000000", "0.50932000"], ["83919.42000000", "0.00000000"], ["83918.70000000", "0.00000000"], ["83918.20000000", "0.00000000"], ["83914.70000000", "0.00000000"], ["83914.05000000", "0.30598000"], ["83914.03000000", "0.00000000"], ["83913.37000000", "0.16091000"], ["83912.65000000", "0.00000000"], ["83911.80000000", "0.00006000"], ["83911.05000000", "0.00000000"], ["83908.02000000", "0.00000000"], ["83907.74000000", "0.00297000"], ["83907.73000000", "0.00000000"], ["83907.23000000", "0.00000000"], ["83905.62000000", "0.00000000"], ["83903.08000000", "0.05177000"], ["83903.00000000", "0.06102000"], ["83902.01000000", "0.00000000"], ["83901.41000000", "0.00000000"], ["83901.35000000", "0.72748000"], ["83900.82000000", "0.00297000"], ["83900.81000000", "0.04898000"], ["83900.15000000", "0.04897000"], ["83900.00000000", "0.37366000"], ["83899.90000000", "0.44492000"], ["83899.61000000", "0.00000000"], ["83899.26000000", "0.10594000"], ["83898.77000000", "0.00000000"], ["83898.31000000", "0.58922000"], ["83898.29000000", "0.10152000"], ["83898.03000000", "0.00000000"], ["83898.01000000", "0.09495000"], ["83897.45000000", "0.00000000"], ["83897.22000000", "0.00000000"], ["83897.18000000", "0.00000000"], ["83896.98000000", "0.00000000"], ["83896.40000000", "0.00000000"], ["83896.01000000", "0.00000000"], ["83895.93000000", "0.17191000"], ["83895.02000000", "0.00299000"], ["83895.01000000", "0.04198000"], ["83894.48000000", "0.00000000"], ["83894.37000000", "0.00000000"], ["83894.02000000", "0.02930000"], ["83893.88000000", "0.19371000"], ["83893.87000000", "0.00000000"], ["83893.01000000", "0.00061000"], ["83892.91000000", "0.02016000"], ["83892.59000000", "0.04597000"], ["83892.44000000", "0.00013000"], ["83892.23000000", "0.00000000"], ["83892.03000000", "0.00000000"], ["83891.87000000", "0.00000000"], ["83891.74000000", "0.00000000"], ["83891.37000000", "0.00000000"], ["83891.09000000", "0.00000000"], ["83890.23000000", "0.00000000"], ["83890.22000000", "0.04642000"], ["83890.08000000", "0.00000000"], ["83889.06000000", "0.19286000"], ["83888.70000000", "0.04762000"], ["83888.65000000", "0.00000000"], ["83888.56000000", "0.04762000"], ["83888.11000000", "0.00000000"], ["83888.01000000", "0.09404000"], ["83887.96000000", "0.00000000"], ["83887.48000000", "0.17877000"], ["83887.09000000", "0.04643000"], ["83886.65000000", "0.00000000"], ["83886.20000000", "0.00000000"], ["83885.51000000", "0.09405000"], ["83885.30000000", "0.00000000"], ["83884.89000000", "0.00000000"], ["83884.51000000", "0.00000000"], ["83883.65000000", "0.24502000"], ["83883.11000000", "0.00000000"], ["83882.70000000", "0.04499000"], ["83880.91000000", "0.00000000"], ["83880.23000000", "0.04000000"], ["83880.16000000", "0.04000000"], ["83880.12000000", "0.04000000"], ["83878.37000000", "0.00000000"], ["83876.73000000", "0.00000000"], ["83875.34000000", "0.04440000"], ["83874.89000000", "0.00000000"], ["83873.76000000", "0.05841000"], ["83873.08000000", "0.00000000"], ["83872.83000000", "0.04644000"], ["83872.69000000", "0.00000000"], ["83872.38000000", "0.00000000"], ["83871.76000000", "0.00000000"], ["83871.40000000", "0.00000000"], ["83870.89000000", "0.09288000"], ["83870.03000000", "0.00000000"], ["83869.67000000", "0.04763000"], ["83869.60000000", "0.78484000"], ["83869.59000000", "0.15845000"], ["83869.18000000", "0.14170000"], ["83868.97000000", "0.14050000"], ["83868.90000000", "0.00000000"], ["83868.36000000", "0.09406000"], ["83868.21000000", "0.00000000"], ["83867.99000000", "0.00000000"], ["83867.57000000", "0.00000000"], ["83867.48000000", "0.10260000"], ["83867.34000000", "0.09288000"], ["83867.19000000", "0.09288000"], ["83867.13000000", "0.00000000"], ["83866.83000000", "0.04763000"], ["83866.53000000", "0.05497000"], ["83866.43000000", "0.12899000"], ["83866.38000000", "0.04763000"], ["83866.24000000", "0.09288000"], ["83866.21000000", "0.04763000"], ["83865.98000000", "0.09288000"], ["83865.75000000", "0.09526000"], ["83865.43000000", "0.00000000"], ["83865.07000000", "0.00000000"], ["83864.63000000", "0.09288000"], ["83864.56000000", "0.09526000"], ["83864.26000000", "0.05297000"], ["83864.14000000", "0.04644000"], ["83863.83000000", "0.00000000"], ["83863.80000000", "0.09526000"], ["83863.50000000", "0.09526000"], ["83862.79000000", "0.00000000"], ["83862.41000000", "0.00000000"], ["83862.31000000", "0.09288000"], ["83861.60000000", "0.09407000"], ["83861.58000000", "0.04763000"], ["83861.48000000", "0.09526000"], ["83860.95000000", "0.77196000"], ["83860.80000000", "0.04763000"], ["83860.66000000", "0.00000000"], ["83860.56000000", "0.04763000"], ["83860.46000000", "0.09533000"], ["83860.16000000", "0.04763000"], ["83860.08000000", "0.04763000"], ["83860.07000000", "0.09526000"], ["83859.68000000", "0.09288000"], ["83859.24000000", "0.00000000"], ["83859.05000000", "0.04644000"], ["83857.65000000", "0.00000000"], ["83857.62000000", "0.00000000"], ["83857.59000000", "0.00000000"], ["83856.92000000", "0.05097000"], ["83856.59000000", "0.00000000"], ["83853.62000000", "0.00000000"], ["83853.31000000", "0.00000000"], ["83853.29000000", "0.00000000"], ["83852.83000000", "0.04197000"], ["83852.75000000", "0.05097000"], ["83851.96000000", "0.00000000"], ["83851.02000000", "0.00000000"], ["83850.16000000", "0.04197000"], ["83849.00000000", "0.05097000"], ["83848.80000000", "0.00006000"], ["83848.74000000", "0.00000000"], ["83847.58000000", "0.00000000"], ["83846.93000000", "0.04197000"], ["83845.84000000", "0.34540000"], ["83844.97000000", "0.05097000"], ["83843.96000000", "0.05497000"], ["83842.53000000", "0.05097000"], ["83842.45000000", "0.04397000"], ["83842.34000000", "0.15380000"], ["83841.54000000", "0.05097000"], ["83840.97000000", "0.05497000"], ["83840.80000000", "0.05497000"], ["83839.91000000", "0.10194000"], ["83839.33000000", "0.05497000"], ["83838.90000000", "0.05097000"], ["83838.68000000", "0.04197000"], ["83837.96000000", "0.05497000"], ["83837.51000000", "0.08794000"], ["83836.98000000", "0.05097000"], ["83836.97000000", "0.05097000"], ["83836.83000000", "0.05497000"], ["83836.19000000", "0.05497000"], ["83835.88000000", "0.05097000"], ["83835.48000000", "0.05297000"], ["83834.37000000", "0.04997000"], ["83833.75000000", "0.05497000"], ["83833.25000000", "0.04997000"], ["83833.06000000", "0.05497000"], ["83832.91000000", "0.04197000"], ["83832.72000000", "0.09694000"], ["83831.99000000", "0.05956000"], ["83830.75000000", "0.05297000"], ["83828.69000000", "0.04397000"], ["83828.66000000", "0.04397000"], ["83828.18000000", "0.04997000"], ["83827.74000000", "0.04997000"], ["83827.50000000", "0.04197000"], ["83825.29000000", "0.00000000"], ["83824.77000000", "0.14991000"], ["83824.44000000", "0.04997000"], ["83824.08000000", "0.04997000"], ["83824.01000000", "0.00000000"], ["83822.71000000", "0.08794000"], ["83815.61000000", "0.01527000"], ["83814.66000000", "0.00264000"], ["83807.36000000", "0.00000000"], ["83804.44000000", "0.00000000"], ["83803.39000000", "0.00000000"], ["83803.04000000", "0.00000000"], ["83802.29000000", "0.00010000"], ["83801.54000000", "0.00000000"], ["83797.75000000", "0.01193000"], ["83797.74000000", "0.00000000"], ["83769.85000000", "0.00534000"], ["83768.00000000", "0.00235000"], ["83763.83000000", "0.16363000"], ["83762.61000000", "0.00000000"], ["83750.92000000", "0.00000000"], ["83747.34000000", "0.00000000"], ["83745.48000000", "0.00000000"], ["83739.67000000", "0.00000000"], ["83739.02000000", "0.00013000"], ["83734.83000000", "0.00013000"], ["83733.35000000", "0.00000000"], ["83730.64000000", "0.00013000"], ["83726.45000000", "0.00013000"], ["83715.77000000", "0.00000000"], ["83705.33000000", "0.00400000"], ["83701.52000000", "0.99313000"], ["83682.11000000", "0.00000000"], ["83681.68000000", "0.00000000"], ["83655.87000000", "0.29244000"], ["83614.16000000", "0.03647000"], ["83612.36000000", "0.03617000"], ["82706.77000000", "0.00000000"], ["80606.38000000", "0.00000000"], ["80589.60000000", "0.03571000"], ["75569.00000000", "0.00021000"], ["67173.02000000", "0.00000000"], ["67167.30000000", "0.00058000"], ["33000.00000000", "2.96666000"], ["30227.86000000", "0.00060000"]], "a": [["83959.13000000", "8.40280000"], ["83959.14000000", "0.00021000"], ["83959.70000000", "0.00007000"], ["83959.99000000", "0.00021000"], ["83960.00000000", "0.01447000"], ["83960.01000000", "0.00007000"], ["83960.02000000", "0.00007000"], ["83960.15000000", "0.00000000"], ["83960.17000000", "0.00007000"], ["83960.21000000", "0.00014000"], ["83960.22000000", "0.08998000"], ["83960.39000000", "0.00000000"], ["83960.48000000", "0.00000000"], ["83960.49000000", "0.00000000"], ["83960.56000000", "0.00000000"], ["83960.80000000", "0.01191000"], ["83960.87000000", "0.00000000"], ["83961.10000000", "0.00000000"], ["83961.11000000", "0.00000000"], ["83961.39000000", "0.00000000"], ["83961.99000000", "0.00000000"], ["83962.00000000", "0.01416000"], ["83962.09000000", "0.00014000"], ["83962.10000000", "1.65030000"], ["83962.11000000", "2.24337000"], ["83962.12000000", "0.00000000"], ["83962.13000000", "0.00000000"], ["83962.22000000", "0.00000000"], ["83962.23000000", "0.00000000"], ["83962.28000000", "0.00000000"], ["83962.29000000", "0.00000000"], ["83962.30000000", "0.47656000"], ["83962.38000000", "0.00000000"], ["83962.48000000", "2.97204000"], ["83962.49000000", "0.00000000"], ["83962.50000000", "0.00013000"], ["83962.51000000", "0.00014000"], ["83962.54000000", "0.00000000"], ["83962.66000000", "0.08354000"], ["83962.67000000", "0.49000000"], ["83962.68000000", "0.00000000"], ["83962.72000000", "0.00201000"], ["83962.78000000", "0.78643000"], ["83963.04000000", "0.00000000"], ["83963.36000000", "0.01000000"], ["83963.39000000", "0.00000000"], ["83963.41000000", "0.00759000"], ["83963.88000000", "0.00000000"], ["83963.90000000", "0.00000000"], ["83963.99000000", "0.00000000"], ["83964.00000000", "0.01410000"], ["83964.15000000", "0.14032000"], ["83964.17000000", "0.01190000"], ["83964.22000000", "0.00000000"], ["83964.27000000", "0.00000000"], ["83964.33000000", "0.00000000"], ["83964.37000000", "0.00000000"], ["83964.38000000", "0.00000000"], ["83964.39000000", "0.05580000"], ["83964.71000000", "0.00000000"], ["83964.79000000", "0.00000000"], ["83965.57000000", "0.39548000"], ["83965.83000000", "0.00000000"], ["83965.84000000", "0.00000000"], ["83965.99000000", "0.00000000"], ["83966.00000000", "0.01410000"], ["83966.07000000", "0.00000000"], ["83966.08000000", "0.00000000"], ["83966.16000000", "0.00000000"], ["83966.27000000", "0.00000000"], ["83966.28000000", "1.35327000"], ["83966.29000000", "0.00014000"], ["83966.51000000", "0.00000000"], ["83966.52000000", "0.00000000"], ["83967.17000000", "0.00000000"], ["83967.18000000", "0.02381000"], ["83967.22000000", "0.00000000"], ["83967.23000000", "0.27640000"], ["83967.24000000", "0.17899000"], ["83967.42000000", "0.00029000"], ["83967.65000000", "0.02381000"], ["83967.83000000", "0.00006000"], ["83967.95000000", "0.00000000"], ["83967.96000000", "0.00000000"], ["83968.00000000", "0.01410000"], ["83968.18000000", "0.02332000"], ["83968.42000000", "0.00000000"], ["83968.64000000", "0.02381000"], ["83968.67000000", "0.00000000"], ["83968.99000000", "0.00000000"], ["83969.00000000", "0.10788000"], ["83969.21000000", "0.00000000"], ["83969.51000000", "0.05954000"], ["83969.61000000", "0.00013000"], ["83969.76000000", "0.05954000"], ["83969.77000000", "0.00000000"], ["83969.84000000", "0.02376000"], ["83970.00000000", "0.01410000"], ["83970.07000000", "0.00000000"], ["83970.19000000", "0.00000000"], ["83970.20000000", "0.00000000"], ["83970.24000000", "0.09200000"], ["83970.27000000", "0.00000000"], ["83970.28000000", "0.15590000"], ["83970.32000000", "0.00000000"], ["83970.48000000", "0.03339000"], ["83970.56000000", "0.00000000"], ["83970.60000000", "0.00006000"], ["83970.88000000", "0.00009000"], ["83970.90000000", "0.00000000"], ["83970.96000000", "0.00000000"], ["83971.08000000", "0.06800000"], ["83971.22000000", "0.02381000"], ["83971.30000000", "0.00000000"], ["83971.45000000", "0.05954000"], ["83971.71000000", "0.01190000"], ["83971.77000000", "0.34277000"], ["83971.92000000", "0.06800000"], ["83972.01000000", "0.00000000"], ["83972.24000000", "0.00000000"], ["83972.31000000", "0.07600000"], ["83972.39000000", "0.06400000"], ["83972.98000000", "0.00013000"], ["83972.99000000", "0.00000000"], ["83973.07000000", "0.00119000"], ["83973.39000000", "0.04000000"], ["83973.65000000", "0.05954000"], ["83973.93000000", "0.00000000"], ["83974.22000000", "0.05954000"], ["83974.44000000", "0.06400000"], ["83974.56000000", "0.00000000"], ["83974.66000000", "0.00000000"], ["83975.08000000", "0.00000000"], ["83975.32000000", "0.89344000"], ["83975.37000000", "0.05954000"], ["83975.51000000", "0.00000000"], ["83975.66000000", "0.06000000"], ["83975.76000000", "0.32509000"], ["83976.12000000", "0.10000000"], ["83976.20000000", "0.07200000"], ["83976.26000000", "0.05954000"], ["83976.56000000", "0.05956000"], ["83976.72000000", "0.00000000"], ["83976.81000000", "0.00000000"], ["83976.85000000", "0.00000000"], ["83977.01000000", "0.41924000"], ["83977.03000000", "0.06000000"], ["83977.24000000", "0.89344000"], ["83977.45000000", "0.06549000"], ["83977.91000000", "0.00006000"], ["83978.30000000", "0.05954000"], ["83978.50000000", "0.12842000"], ["83978.80000000", "0.05954000"], ["83978.86000000", "0.00000000"], ["83979.46000000", "0.00000000"], ["83979.54000000", "0.01190000"], ["83979.74000000", "0.05954000"], ["83979.98000000", "0.05954000"], ["83979.99000000", "1.22191000"], ["83980.08000000", "0.00000000"], ["83980.53000000", "0.00000000"], ["83980.63000000", "0.00000000"], ["83980.91000000", "0.00000000"], ["83981.14000000", "0.45029000"], ["83981.21000000", "0.00000000"], ["83981.63000000", "0.05954000"], ["83981.71000000", "0.00000000"], ["83982.00000000", "0.00000000"], ["83982.14000000", "0.71399000"], ["83982.45000000", "1.34361000"], ["83982.46000000", "0.05956000"], ["83982.82000000", "0.08000000"], ["83983.82000000", "0.00119000"], ["83983.89000000", "0.85771000"], ["83983.96000000", "0.00000000"], ["83984.00000000", "0.00000000"], ["83984.06000000", "0.00000000"], ["83984.12000000", "0.00000000"], ["83984.46000000", "0.00007000"], ["83984.87000000", "0.00000000"], ["83985.84000000", "0.02381000"], ["83986.00000000", "0.00000000"], ["83986.63000000", "0.44924000"], ["83987.36000000", "0.00008000"], ["83988.00000000", "0.00000000"], ["83988.16000000", "0.85767000"], ["83988.28000000", "0.48864000"], ["83988.57000000", "0.00000000"], ["83991.68000000", "0.59586000"], ["83991.69000000", "0.85763000"], ["83995.99000000", "1.17499000"], ["83996.00000000", "0.00000000"], ["83996.73000000", "0.00000000"], ["83997.51000000", "0.00000000"], ["83997.79000000", "0.00000000"], ["83998.40000000", "0.02381000"], ["83998.63000000", "0.03533000"], ["83999.05000000", "0.00000000"], ["83999.59000000", "0.00000000"], ["84000.79000000", "0.00000000"], ["84001.88000000", "0.00000000"], ["84001.89000000", "0.00000000"], ["84002.97000000", "0.00000000"], ["84003.77000000", "0.00000000"], ["84004.48000000", "0.00018000"], ["84004.51000000", "0.28357000"], ["84004.52000000", "0.00000000"], ["84007.55000000", "0.11378000"], ["84010.20000000", "0.00000000"], ["84012.26000000", "0.00000000"], ["84012.67000000", "0.00595000"], ["84013.23000000", "0.00000000"], ["84013.35000000", "0.00000000"], ["84014.55000000", "0.05321000"], ["84015.30000000", "0.05954000"], ["84018.15000000", "0.04800000"], ["84020.11000000", "0.04159000"], ["84020.15000000", "0.71399000"], ["84020.39000000", "0.01190000"], ["84034.28000000", "0.02857000"], ["84035.16000000", "0.00000000"], ["84037.44000000", "0.00000000"], ["84038.17000000", "0.00000000"], ["84038.72000000", "0.00000000"], ["84040.45000000", "0.00000000"], ["84045.44000000", "0.00297000"], ["84045.98000000", "0.00000000"], ["84046.20000000", "0.00000000"], ["84048.86000000", "0.00000000"], ["84049.26000000", "0.00000000"], ["84052.77000000", "0.00297000"], ["84057.96000000", "0.18089000"], ["84061.09000000", "0.00000000"], ["84067.97000000", "0.05496000"], ["84070.30000000", "0.00000000"], ["84073.81000000", "0.00000000"], ["84077.22000000", "0.00679000"], ["84082.58000000", "0.00000000"], ["84083.44000000", "0.00000000"], ["84085.21000000", "0.09894000"], ["84085.96000000", "0.04397000"], ["84087.54000000", "0.11302000"], ["84088.74000000", "0.46062000"], ["84089.86000000", "0.05497000"], ["84090.88000000", "0.02501000"], ["84101.47000000", "0.00000000"], ["84103.27000000", "0.04197000"], ["84108.97000000", "0.04197000"], ["84109.70000000", "0.89732000"], ["84113.20000000", "1.34447000"], ["84114.37000000", "0.00000000"], ["84115.84000000", "0.00000000"], ["84116.48000000", "0.00000000"], ["84119.11000000", "0.00000000"], ["84130.35000000", "0.01188000"], ["84135.72000000", "0.01000000"], ["84136.72000000", "0.00000000"], ["84137.12000000", "0.00000000"], ["84139.13000000", "0.00000000"], ["84153.81000000", "0.00000000"], ["84155.04000000", "0.05916000"], ["84157.23000000", "0.00010000"], ["84158.01000000", "0.00000000"], ["84159.82000000", "0.00000000"], ["84182.40000000", "0.00000000"], ["84224.80000000", "0.00000000"], ["84244.59000000", "0.79995000"], ["84252.72000000", "0.00000000"], ["84257.01000000", "0.00000000"], ["84258.45000000", "0.16363000"], ["84262.23000000", "0.00000000"], ["84263.50000000", "0.16370000"], ["84266.84000000", "0.00000000"], ["84270.62000000", "0.00000000"], ["84271.88000000", "0.06764000"], ["84275.18000000", "0.00000000"], ["84279.01000000", "0.00000000"], ["84315.15000000", "0.00402000"], ["84347.58000000", "0.00000000"], ["84359.27000000", "0.00000000"], ["84604.80000000", "0.05964000"], ["85180.48000000", "0.10000000"], ["85225.78000000", "0.00000000"], ["85231.60000000", "0.00000000"], ["85242.60000000", "0.11747000"], ["85263.90000000", "0.00000000"], ["85285.20000000", "0.00000000"], ["150001.00000000", "0.00080000"]], "record_time": 1742577063.214095, "EXCHANGE": "BINANCE"}
{"e": "depthUpdate", "E": 1742577064014, "s": "BTCUSDT", "U": 64632110501, "u": 64632111289, "b": [["83959.12000000", "1.43683000"], ["83959.11000000", "0.00064000"], ["83959.02000000", "0.00021000"], ["83959.01000000", "0.08833000"], ["83958.99000000", "0.00174000"], ["83958.98000000", "0.78661000"], ["83958.93000000", "0.17366000"], ["83958.69000000", "0.00007000"], ["83958.68000000", "0.00009000"], ["83958.67000000", "0.00000000"], ["83958.49000000", "0.00000000"], ["83958.05000000", "0.00000000"], ["83958.04000000", "0.00000000"], ["83957.95000000", "0.00000000"], ["83957.88000000", "0.00000000"], ["83957.35000000", "0.00000000"], ["83957.15000000", "0.02207000"], ["83956.93000000", "0.00000000"], ["83956.87000000", "0.00018000"], ["83956.83000000", "0.00000000"], ["83956.82000000", "0.00000000"], ["83956.77000000", "0.00017000"], ["83956.73000000", "0.00019000"], ["83956.72000000", "0.00000000"], ["83956.20000000", "0.00000000"], ["83955.95000000", "0.00006000"], ["83955.74000000", "0.03298000"], ["83955.70000000", "0.00000000"], ["83955.62000000", "0.00000000"], ["83955.53000000", "0.00007000"], ["83955.34000000", "0.00014000"], ["83955.33000000", "0.02433000"], ["83954.90000000", "0.01000000"], ["83954.89000000", "0.00000000"], ["83954.69000000", "0.00050000"], ["83954.57000000", "0.00000000"], ["83954.19000000", "0.00000000"], ["83954.00000000", "0.01410000"], ["83953.81000000", "0.00015000"], ["83953.80000000", "0.00013000"], ["83953.73000000", "0.00000000"], ["83953.40000000", "0.05364000"], ["83953.37000000", "0.02412000"], ["83953.33000000", "0.00358000"], ["83952.05000000", "0.00000000"], ["83951.53000000", "0.10120000"], ["83950.79000000", "0.16172000"], ["83950.74000000", "0.00000000"], ["83950.72000000", "0.00000000"], ["83950.25000000", "0.00873000"], ["83949.62000000", "0.00000000"], ["83949.61000000", "0.00000000"], ["83949.54000000", "0.00000000"], ["83949.43000000", "0.00000000"], ["83949.33000000", "0.00000000"], ["83949.27000000", "0.00000000"], ["83949.25000000", "0.00000000"], ["83948.98000000", "0.00094000"], ["83947.99000000", "0.00000000"], ["83947.98000000", "0.05500000"], ["83947.97000000", "0.00000000"], ["83947.91000000", "0.15112000"], ["83947.29000000", "0.00000000"], ["83946.54000000", "0.00089000"], ["83946.26000000", "0.00000000"], ["83946.25000000", "0.00000000"], ["83946.20000000", "0.00000000"], ["83946.17000000", "0.04000000"], ["83945.86000000", "0.00000000"], ["83945.85000000", "0.00000000"], ["83945.36000000", "0.00000000"], ["83945.07000000", "0.00000000"], ["83944.99000000", "0.04000000"], ["83944.96000000", "0.48039000"], ["83944.62000000", "0.04000000"], ["83944.51000000", "0.04000000"], ["83944.49000000", "0.04000000"], ["83944.42000000", "0.04000000"], ["83943.51000000", "0.00000000"], ["83943.05000000", "0.00000000"], ["83942.95000000", "0.04000000"], ["83942.84000000", "0.04000000"], ["83942.71000000", "0.00000000"], ["83942.48000000", "0.00000000"], ["83941.13000000", "0.04000000"], ["83940.68000000", "0.00922000"], ["83940.65000000", "0.00029000"], ["83940.64000000", "1.21112000"], ["83940.63000000", "0.85816000"], ["83940.30000000", "0.04000000"], ["83940.14000000", "0.00000000"], ["83939.73000000", "0.00000000"], ["83939.69000000", "0.00000000"], ["83939.45000000", "0.00000000"], ["83938.89000000", "0.00000000"], ["83938.70000000", "0.00598000"], ["83938.27000000", "0.02345000"], ["83938.01000000", "0.00000000"], ["83937.92000000", "0.00000000"], ["83937.26000000", "0.03574000"], ["83937.04000000", "0.00000000"], ["83937.03000000", "0.10788000"], ["83936.72000000", "0.85820000"], ["83936.45000000", "0.00000000"], ["83936.03000000", "0.05619000"], ["83935.33000000", "0.00000000"], ["83934.00000000", "1.00000000"], ["83933.99000000", "0.00000000"], ["83933.94000000", "0.00059000"], ["83933.93000000", "0.01910000"], ["83933.49000000", "0.00000000"], ["83933.24000000", "0.08354000"], ["83932.59000000", "1.91556000"], ["83932.51000000", "0.85824000"], ["83932.11000000", "1.35272000"], ["83930.30000000", "0.00000000"], ["83930.23000000", "0.00000000"], ["83929.66000000", "0.21090000"], ["83928.84000000", "0.00000000"], ["83928.43000000", "0.00000000"], ["83928.27000000", "0.00580000"], ["83927.45000000", "0.00016000"], ["83927.34000000", "0.00000000"], ["83927.23000000", "0.00354000"], ["83927.03000000", "0.00600000"], ["83924.41000000", "0.59584000"], ["83924.40000000", "0.24586000"], ["83924.39000000", "0.00000000"], ["83924.02000000", "0.00000000"], ["83920.83000000", "0.36353000"], ["83920.41000000", "0.01300000"], ["83919.92000000", "0.00000000"], ["83919.90000000", "0.00000000"], ["83919.47000000", "0.00000000"], ["83917.14000000", "0.00059000"], ["83914.09000000", "0.00000000"], ["83910.05000000", "0.03346000"], ["83907.31000000", "0.00000000"], ["83904.80000000", "0.00000000"], ["83903.18000000", "0.00000000"], ["83900.99000000", "0.00000000"], ["83896.06000000", "0.04490000"], ["83894.72000000", "0.12831000"], ["83893.88000000", "0.00000000"], ["83893.29000000", "0.04000000"], ["83892.01000000", "0.00822000"], ["83890.26000000", "0.00859000"], ["83890.11000000", "0.02873000"], ["83889.79000000", "0.00809000"], ["83888.26000000", "0.04000000"], ["83888.19000000", "0.04000000"], ["83885.30000000", "0.04000000"], ["83882.70000000", "0.00009000"], ["83881.90000000", "0.00000000"], ["83880.23000000", "0.00000000"], ["83880.16000000", "0.00000000"], ["83880.12000000", "0.00000000"], ["83878.26000000", "0.00000000"], ["83877.85000000", "0.04440000"], ["83877.67000000", "0.12899000"], ["83877.37000000", "0.00000000"], ["83876.02000000", "0.00000000"], ["83875.34000000", "0.00000000"], ["83872.28000000", "0.00000000"], ["83869.68000000", "0.71399000"], ["83866.43000000", "0.00000000"], ["83866.04000000", "0.00000000"], ["83865.26000000", "0.92661000"], ["83863.63000000", "0.00000000"], ["83862.48000000", "1.26647000"], ["83858.93000000", "0.00000000"], ["83856.01000000", "0.00000000"], ["83844.65000000", "0.00083000"], ["83844.19000000", "0.61567000"], ["83832.61000000", "0.11506000"], ["83832.48000000", "0.12000000"], ["83815.61000000", "0.00000000"], ["83808.46000000", "0.00000000"], ["83808.45000000", "0.00000000"], ["83807.37000000", "0.99313000"], ["83800.85000000", "0.00000000"], ["83797.89000000", "0.01527000"], ["83783.87000000", "0.00000000"], ["83780.02000000", "0.00000000"], ["83778.96000000", "0.00839000"], ["83775.75000000", "0.00012000"], ["83768.48000000", "0.00069000"], ["83765.29000000", "0.00000000"], ["83764.23000000", "0.45000000"], ["83760.00000000", "0.02534000"], ["83759.63000000", "0.00400000"], ["83756.80000000", "0.00000000"], ["83747.26000000", "0.00127000"], ["83737.95000000", "0.00000000"], ["83727.90000000", "0.00000000"], ["83726.45000000", "0.00000000"], ["83716.72000000", "0.00000000"], ["83705.33000000", "0.00000000"], ["83701.52000000", "0.00000000"], ["83550.00000000", "0.03239000"], ["82699.73000000", "0.00100000"], ["80589.60000000", "0.00000000"], ["78370.53000000", "0.00000000"], ["75563.00000000", "0.02448000"], ["67167.30000000", "0.00058000"], ["33000.00000000", "2.96666000"]], "a": [["83959.13000000", "8.72877000"], ["83959.14000000", "0.00048000"], ["83960.00000000", "0.01454000"], ["83960.17000000", "0.00007000"], ["83960.21000000", "0.00000000"], ["83960.22000000", "0.00000000"], ["83960.79000000", "0.00014000"], ["83960.80000000", "0.01073000"], ["83961.37000000", "0.00007000"], ["83961.99000000", "0.00014000"], ["83962.00000000", "0.01423000"], ["83962.06000000", "0.00014000"], ["83962.07000000", "0.26035000"], ["83962.08000000", "0.00000000"], ["83962.09000000", "0.00000000"], ["83962.10000000", "0.00035000"], ["83962.11000000", "0.92904000"], ["83962.29000000", "0.61778000"], ["83962.30000000", "0.47650000"], ["83962.46000000", "0.00000000"], ["83962.47000000", "0.00000000"], ["83962.48000000", "0.00000000"], ["83962.50000000", "0.00000000"], ["83962.51000000", "0.00000000"], ["83962.66000000", "0.08354000"], ["83962.67000000", "0.04000000"], ["83962.78000000", "0.00000000"], ["83962.92000000", "0.02332000"], ["83964.39000000", "0.02000000"], ["83964.46000000", "0.00000000"], ["83964.76000000", "0.00000000"], ["83965.11000000", "0.00000000"], ["83965.57000000", "0.00000000"], ["83966.28000000", "0.99839000"], ["83966.29000000", "0.00000000"], ["83966.40000000", "0.00019000"], ["83967.00000000", "0.48912000"], ["83967.01000000", "0.78640000"], ["83967.18000000", "0.00000000"], ["83967.23000000", "0.00000000"], ["83967.93000000", "0.07600000"], ["83968.00000000", "0.07810000"], ["83968.18000000", "0.00000000"], ["83968.64000000", "0.00000000"], ["83969.51000000", "0.00000000"], ["83970.19000000", "0.00000000"], ["83971.03000000", "0.00000000"], ["83971.22000000", "0.00000000"], ["83971.28000000", "0.06000000"], ["83971.45000000", "0.00000000"], ["83971.77000000", "0.23951000"], ["83971.83000000", "0.00363000"], ["83972.31000000", "0.00000000"], ["83972.39000000", "0.00000000"], ["83972.94000000", "0.00000000"], ["83973.39000000", "0.00000000"], ["83973.65000000", "0.00000000"], ["83974.22000000", "0.00000000"], ["83975.30000000", "0.00000000"], ["83975.31000000", "0.90818000"], ["83975.37000000", "0.00000000"], ["83975.39000000", "0.04000000"], ["83975.66000000", "0.00000000"], ["83975.76000000", "0.00000000"], ["83976.26000000", "0.54516000"], ["83977.01000000", "0.05956000"], ["83978.50000000", "0.00000000"], ["83981.15000000", "0.00000000"], ["83981.80000000", "1.07236000"], ["83981.84000000", "0.30287000"], ["83983.89000000", "0.00000000"], ["83984.32000000", "0.00059000"], ["83985.16000000", "0.00000000"], ["83988.16000000", "0.00000000"], ["83988.68000000", "0.00000000"], ["83988.91000000", "0.00000000"], ["83991.41000000", "0.85764000"], ["83991.62000000", "0.00358000"], ["83991.68000000", "1.39130000"], ["83991.69000000", "0.00000000"], ["83991.99000000", "0.00000000"], ["83992.88000000", "0.00581000"], ["83995.28000000", "0.00151000"], ["83996.38000000", "0.02808000"], ["83996.85000000", "0.00100000"], ["83996.96000000", "0.00000000"], ["83997.72000000", "0.85757000"], ["83999.89000000", "0.00000000"], ["83999.93000000", "0.00000000"], ["84000.00000000", "0.59610000"], ["84000.01000000", "0.53801000"], ["84001.11000000", "0.00059000"], ["84001.80000000", "0.85753000"], ["84002.70000000", "0.00000000"], ["84004.36000000", "0.00822000"], ["84004.77000000", "0.00870000"], ["84005.36000000", "0.00000000"], ["84006.79000000", "0.00000000"], ["84006.85000000", "0.00000000"], ["84008.10000000", "0.00000000"], ["84008.64000000", "0.00805000"], ["84011.73000000", "0.00000000"], ["84012.50000000", "0.00000000"], ["84016.63000000", "0.04159000"], ["84019.17000000", "0.00000000"], ["84019.21000000", "0.00000000"], ["84020.11000000", "0.00000000"], ["84020.22000000", "0.00000000"], ["84029.78000000", "0.06800000"], ["84040.00000000", "0.02615000"], ["84056.33000000", "0.00060000"], ["84061.21000000", "0.00000000"], ["84064.35000000", "0.00000000"], ["84070.32000000", "0.02383000"], ["84077.22000000", "0.00000000"], ["84079.80000000", "0.00000000"], ["84080.00000000", "0.00235000"], ["84083.17000000", "0.00679000"], ["84092.17000000", "0.12000000"], ["84092.86000000", "0.00000000"], ["84100.00000000", "2.05114000"], ["84105.76000000", "0.05497000"], ["84111.09000000", "0.00000000"], ["84120.00000000", "0.00235000"], ["84133.51000000", "0.01000000"], ["84133.61000000", "0.00000000"], ["84135.72000000", "0.00000000"], ["84140.00000000", "0.00609000"], ["84206.40000000", "0.00000000"], ["84209.50000000", "0.00000000"], ["84265.09000000", "0.00639000"], ["84327.97000000", "0.00000000"], ["84340.40000000", "0.00407000"], ["85218.52000000", "0.00100000"], ["85242.60000000", "0.00000000"], ["85263.90000000", "0.05873000"]], "record_time": 1742577064.236997, "EXCHANGE": "BINANCE"}
{"e": "depthUpdate", "E": 1742577142014, "s": "BTCUSDT", "U": 64632177813, "u": 64632178469, "b": [["83937.30000000", "1.38613000"], ["83937.29000000", "0.00046000"], ["83937.25000000", "0.00021000"], ["83937.24000000", "0.09499000"], ["83937.19000000", "0.00007000"], ["83937.16000000", "0.00007000"], ["83937.00000000", "0.00007000"], ["83936.66000000", "0.00014000"], ["83936.65000000", "0.78675000"], ["83936.32000000", "0.00007000"], ["83936.00000000", "0.00000000"], ["83935.97000000", "0.00007000"], ["83935.96000000", "0.00000000"], ["83935.95000000", "0.00000000"], ["83935.49000000", "0.00007000"], ["83934.90000000", "0.00000000"], ["83934.84000000", "0.00000000"], ["83934.64000000", "0.00000000"], ["83934.50000000", "0.00000000"], ["83934.49000000", "0.00006000"], ["83933.81000000", "0.00007000"], ["83933.62000000", "0.02387000"], ["83933.34000000", "0.05371000"], ["83933.21000000", "0.00000000"], ["83933.10000000", "0.00000000"], ["83932.88000000", "0.00000000"], ["83932.65000000", "0.00000000"], ["83932.60000000", "0.08741000"], ["83932.40000000", "0.00000000"], ["83932.00000000", "0.01410000"], ["83931.32000000", "0.00090000"], ["83931.31000000", "0.00007000"], ["83931.30000000", "0.06000000"], ["83931.14000000", "0.00000000"], ["83931.11000000", "0.21549000"], ["83931.10000000", "0.08000000"], ["83931.00000000", "0.02352000"], ["83930.56000000", "0.15951000"], ["83930.47000000", "0.00000000"], ["83930.05000000", "0.00000000"], ["83929.86000000", "0.00000000"], ["83929.68000000", "0.00000000"], ["83929.38000000", "0.00119000"], ["83928.90000000", "0.45000000"], ["83928.71000000", "0.00000000"], ["83927.91000000", "0.00000000"], ["83927.61000000", "0.00000000"], ["83927.49000000", "0.00000000"], ["83926.35000000", "0.00000000"], ["83926.34000000", "0.01874000"], ["83926.09000000", "0.06792000"], ["83925.70000000", "0.00000000"], ["83925.59000000", "0.00897000"], ["83925.03000000", "0.00000000"], ["83924.98000000", "0.00000000"], ["83924.89000000", "0.00000000"], ["83924.49000000", "0.00000000"], ["83923.46000000", "0.04000000"], ["83923.36000000", "0.38143000"], ["83922.93000000", "0.17899000"], ["83922.92000000", "0.00000000"], ["83922.71000000", "0.00000000"], ["83922.62000000", "0.04000000"], ["83922.60000000", "0.00000000"], ["83922.55000000", "0.00000000"], ["83921.79000000", "0.04000000"], ["83921.78000000", "0.04000000"], ["83921.69000000", "0.04000000"], ["83921.51000000", "0.02426000"], ["83921.38000000", "0.47650000"], ["83921.22000000", "0.00000000"], ["83921.09000000", "0.00000000"], ["83920.07000000", "0.26789000"], ["83920.04000000", "0.00410000"], ["83919.65000000", "0.04000000"], ["83919.51000000", "0.00937000"], ["83919.32000000", "0.04000000"], ["83918.38000000", "0.59595000"], ["83918.37000000", "0.15046000"], ["83917.79000000", "0.00050000"], ["83917.65000000", "0.04000000"], ["83917.58000000", "0.04000000"], ["83917.37000000", "0.00000000"], ["83917.01000000", "0.00120000"], ["83916.83000000", "0.00000000"], ["83915.51000000", "0.00000000"], ["83915.40000000", "0.00000000"], ["83915.18000000", "0.10788000"], ["83913.84000000", "0.71399000"], ["83913.68000000", "0.00000000"], ["83913.17000000", "0.85844000"], ["83912.52000000", "0.54902000"], ["83912.11000000", "0.00300000"], ["83911.26000000", "0.59562000"], ["83911.11000000", "1.32333000"], ["83909.92000000", "0.00000000"], ["83909.91000000", "0.00000000"], ["83905.30000000", "0.00000000"], ["83904.88000000", "0.00922000"], ["83904.86000000", "0.00000000"], ["83904.25000000", "0.85853000"], ["83903.41000000", "0.00000000"], ["83903.06000000", "1.60743000"], ["83900.56000000", "0.45221000"], ["83898.54000000", "0.00000000"], ["83898.53000000", "0.00000000"], ["83898.49000000", "1.16930000"], ["83898.48000000", "0.89344000"], ["83897.91000000", "0.00000000"], ["83897.60000000", "0.59314000"], ["83897.10000000", "0.00000000"], ["83896.49000000", "0.04000000"], ["83893.27000000", "0.05816000"], ["83892.19000000", "0.04440000"], ["83888.79000000", "0.04490000"], ["83888.09000000", "0.00000000"], ["83887.25000000", "0.00000000"], ["83886.43000000", "0.00000000"], ["83884.48000000", "0.03345000"], ["83878.09000000", "0.00000000"], ["83876.06000000", "0.00312000"], ["83875.43000000", "0.00000000"], ["83874.63000000", "0.00000000"], ["83873.49000000", "0.71286000"], ["83873.48000000", "0.59562000"], ["83873.28000000", "0.00000000"], ["83873.27000000", "0.00000000"], ["83872.29000000", "0.00000000"], ["83870.36000000", "0.04498000"], ["83868.34000000", "0.00061000"], ["83852.88000000", "0.04000000"], ["83847.86000000", "0.04000000"], ["83846.79000000", "0.00000000"], ["83846.72000000", "0.00000000"], ["83846.71000000", "0.01527000"], ["83842.63000000", "0.00000000"], ["83840.96000000", "0.00000000"], ["83839.89000000", "0.28348000"], ["83838.22000000", "0.00000000"], ["83838.16000000", "0.00000000"], ["83838.12000000", "0.00000000"], ["83832.49000000", "0.10319000"], ["83828.75000000", "0.32771000"], ["83827.26000000", "0.00000000"], ["83827.25000000", "0.16438000"], ["83823.08000000", "0.00083000"], ["83821.98000000", "0.10000000"], ["83808.12000000", "0.00000000"], ["83806.25000000", "1.01386000"], ["83796.49000000", "0.04497000"], ["83795.10000000", "0.04497000"], ["83783.46000000", "0.00000000"], ["83775.65000000", "0.00000000"], ["83772.64000000", "0.00839000"], ["83747.44000000", "0.00069000"], ["83747.25000000", "0.00000000"], ["83743.73000000", "0.00400000"], ["83718.90000000", "0.00000000"], ["83717.09000000", "0.01865000"], ["83712.41000000", "0.00000000"], ["83711.54000000", "0.00014000"], ["83705.75000000", "0.16520000"], ["83703.98000000", "0.00000000"], ["83697.36000000", "0.05637000"], ["83696.37000000", "0.00013000"], ["83692.18000000", "0.00013000"], ["82942.19000000", "0.00000000"], ["82883.63000000", "0.40000000"], ["82685.93000000", "0.00000000"], ["75543.00000000", "0.00000000"], ["67149.84000000", "0.00058000"], ["33000.00000000", "2.96666000"]], "a": [["83937.31000000", "4.97458000"], ["83937.32000000", "0.00040000"], ["83937.38000000", "0.00014000"], ["83937.39000000", "0.45253000"], ["83937.40000000", "0.00006000"], ["83937.41000000", "0.00000000"], ["83937.42000000", "0.00014000"], ["83937.43000000", "1.45522000"], ["83937.44000000", "0.00000000"], ["83938.00000000", "0.01416000"], ["83938.98000000", "0.00000000"], ["83939.22000000", "0.04000000"], ["83939.37000000", "0.00000000"], ["83939.53000000", "0.00000000"], ["83939.65000000", "0.00007000"], ["83940.00000000", "0.01416000"], ["83940.01000000", "0.00000000"], ["83940.04000000", "0.00000000"], ["83940.08000000", "0.00000000"], ["83940.20000000", "0.00000000"], ["83941.06000000", "0.00000000"], ["83941.09000000", "0.02391000"], ["83941.33000000", "0.09600000"], ["83941.45000000", "0.00000000"], ["83942.00000000", "0.01416000"], ["83942.09000000", "0.00000000"], ["83942.17000000", "0.06800000"], ["83942.29000000", "1.10567000"], ["83942.30000000", "0.89344000"], ["83942.45000000", "0.15529000"], ["83942.52000000", "0.00000000"], ["83942.77000000", "0.16412000"], ["83943.02000000", "0.07600000"], ["83943.03000000", "0.06800000"], ["83943.13000000", "0.06400000"], ["83943.16000000", "0.14984000"], ["83943.47000000", "0.10788000"], ["83943.67000000", "0.00000000"], ["83944.01000000", "0.00000000"], ["83944.55000000", "0.00000000"], ["83945.01000000", "0.00000000"], ["83945.02000000", "0.00000000"], ["83945.03000000", "0.00000000"], ["83945.12000000", "0.59562000"], ["83945.13000000", "0.00000000"], ["83945.40000000", "0.00006000"], ["83945.56000000", "0.06400000"], ["83945.61000000", "0.00000000"], ["83945.65000000", "0.20095000"], ["83945.74000000", "0.35737000"], ["83945.88000000", "0.00000000"], ["83946.38000000", "0.06000000"], ["83946.69000000", "0.00058000"], ["83947.11000000", "0.02433000"], ["83947.22000000", "0.04800000"], ["83947.23000000", "0.05200000"], ["83947.32000000", "0.07200000"], ["83947.96000000", "0.00091000"], ["83948.06000000", "0.00000000"], ["83948.34000000", "0.00419000"], ["83948.41000000", "0.00000000"], ["83949.25000000", "0.00000000"], ["83949.30000000", "0.00500000"], ["83950.09000000", "0.00000000"], ["83950.10000000", "0.00000000"], ["83950.19000000", "0.00000000"], ["83950.20000000", "0.00400000"], ["83950.60000000", "0.00000000"], ["83950.95000000", "0.89344000"], ["83951.38000000", "0.00000000"], ["83952.61000000", "0.00000000"], ["83952.67000000", "0.01191000"], ["83952.85000000", "0.00000000"], ["83952.86000000", "0.00000000"], ["83953.45000000", "0.00000000"], ["83954.10000000", "0.00300000"], ["83954.29000000", "0.00000000"], ["83954.38000000", "0.00000000"], ["83954.76000000", "0.22020000"], ["83954.79000000", "0.05956000"], ["83955.78000000", "0.00000000"], ["83956.03000000", "0.05956000"], ["83959.68000000", "0.00000000"], ["83959.98000000", "0.00000000"], ["83960.45000000", "0.00000000"], ["83961.60000000", "1.33258000"], ["83961.90000000", "0.00000000"], ["83963.21000000", "0.06800000"], ["83965.11000000", "0.00000000"], ["83966.59000000", "0.06400000"], ["83966.81000000", "0.00000000"], ["83967.78000000", "0.00000000"], ["83968.26000000", "0.05200000"], ["83970.55000000", "0.03533000"], ["83971.18000000", "0.00000000"], ["83971.48000000", "1.18295000"], ["83972.44000000", "0.00000000"], ["83972.45000000", "0.89344000"], ["83973.53000000", "0.00000000"], ["83974.10000000", "0.00000000"], ["83974.42000000", "1.33431000"], ["83974.90000000", "0.35737000"], ["83975.26000000", "0.27552000"], ["83976.41000000", "0.59595000"], ["83976.50000000", "0.00000000"], ["83977.22000000", "0.05907000"], ["83979.29000000", "0.00000000"], ["83979.34000000", "0.85776000"], ["83980.30000000", "0.00000000"], ["83982.48000000", "0.00000000"], ["83983.04000000", "0.00861000"], ["83986.47000000", "0.04159000"], ["83989.95000000", "0.47650000"], ["83990.04000000", "0.00000000"], ["83990.84000000", "0.59562000"], ["83992.52000000", "0.04110000"], ["84000.00000000", "0.07401000"], ["84000.34000000", "0.15416000"], ["84003.25000000", "0.06800000"], ["84003.26000000", "0.07600000"], ["84003.34000000", "0.06400000"], ["84003.88000000", "0.00000000"], ["84007.74000000", "0.00000000"], ["84008.02000000", "0.07200000"], ["84013.08000000", "0.00000000"], ["84013.70000000", "0.01865000"], ["84014.70000000", "0.00000000"], ["84014.76000000", "0.00000000"], ["84021.34000000", "0.10319000"], ["84174.17000000", "0.00000000"], ["84224.82000000", "0.10960000"], ["84233.22000000", "0.16212000"], ["84241.60000000", "0.03640000"], ["84917.96000000", "0.60000000"], ["85204.30000000", "0.00000000"], ["99000.00000000", "53.76920000"]], "record_time": 1742577142.213132, "EXCHANGE": "BINANCE"}
{"e": "depthUpdate", "E": 1742577143014, "s": "BTCUSDT", "U": 64632178470, "u": 64632179278, "b": [["83937.30000000", "4.41536000"], ["83937.24000000", "0.09505000"], ["83937.00000000", "0.00007000"], ["83936.99000000", "0.00000000"], ["83936.98000000", "0.00000000"], ["83936.90000000", "0.00202000"], ["83936.68000000", "0.00014000"], ["83936.67000000", "0.30966000"], ["83936.66000000", "0.00014000"], ["83936.65000000", "0.78681000"], ["83936.40000000", "0.05377000"], ["83936.01000000", "0.00000000"], ["83936.00000000", "0.01416000"], ["83935.99000000", "0.01506000"], ["83935.97000000", "0.00000000"], ["83935.49000000", "0.00000000"], ["83935.41000000", "0.01500000"], ["83934.49000000", "0.00000000"], ["83933.62000000", "0.02380000"], ["83933.44000000", "0.11912000"], ["83933.34000000", "0.00000000"], ["83932.80000000", "0.00006000"], ["83932.60000000", "0.00000000"], ["83932.32000000", "0.00595000"], ["83931.91000000", "0.42198000"], ["83931.90000000", "0.47650000"], ["83931.68000000", "0.00000000"], ["83931.31000000", "0.00000000"], ["83931.30000000", "0.00000000"], ["83931.11000000", "0.00000000"], ["83931.10000000", "0.00000000"], ["83930.99000000", "0.04000000"], ["83930.93000000", "0.11913000"], ["83930.75000000", "0.08992000"], ["83930.56000000", "0.00000000"], ["83930.29000000", "0.05956000"], ["83930.07000000", "0.04000000"], ["83929.38000000", "0.00119000"], ["83929.12000000", "0.15046000"], ["83928.91000000", "0.00000000"], ["83928.73000000", "0.02382000"], ["83928.05000000", "0.01874000"], ["83927.80000000", "0.02382000"], ["83927.78000000", "0.00595000"], ["83927.65000000", "0.11189000"], ["83927.64000000", "0.04000000"], ["83927.59000000", "0.00000000"], ["83927.19000000", "0.00000000"], ["83927.00000000", "0.00000000"], ["83926.57000000", "0.02382000"], ["83926.50000000", "0.00000000"], ["83926.09000000", "0.00000000"], ["83926.08000000", "0.00000000"], ["83925.96000000", "0.04000000"], ["83925.87000000", "0.04000000"], ["83925.81000000", "0.02382000"], ["83924.32000000", "0.02382000"], ["83924.01000000", "0.00000000"], ["83922.64000000", "0.11846000"], ["83922.23000000", "0.35737000"], ["83921.69000000", "0.00000000"], ["83921.38000000", "0.00000000"], ["83920.64000000", "0.16363000"], ["83920.52000000", "0.00000000"], ["83920.16000000", "0.49198000"], ["83920.15000000", "0.71399000"], ["83920.14000000", "0.10787000"], ["83920.09000000", "0.00000000"], ["83920.08000000", "0.59592000"], ["83920.07000000", "0.00000000"], ["83920.04000000", "0.00000000"], ["83919.51000000", "0.00000000"], ["83919.32000000", "0.00000000"], ["83918.38000000", "0.00000000"], ["83918.37000000", "0.00000000"], ["83917.79000000", "0.00050000"], ["83917.65000000", "0.00000000"], ["83917.62000000", "0.00000000"], ["83917.24000000", "0.08992000"], ["83915.18000000", "0.00000000"], ["83914.64000000", "0.91978000"], ["83914.63000000", "0.59562000"], ["83914.54000000", "0.08354000"], ["83913.84000000", "0.77355000"], ["83913.83000000", "0.00000000"], ["83912.60000000", "0.05956000"], ["83912.52000000", "0.00000000"], ["83911.99000000", "0.00013000"], ["83911.53000000", "0.00000000"], ["83911.26000000", "0.00000000"], ["83909.59000000", "0.45221000"], ["83908.78000000", "0.00000000"], ["83907.16000000", "0.00000000"], ["83906.97000000", "0.00000000"], ["83904.25000000", "0.00000000"], ["83900.56000000", "0.00000000"], ["83899.87000000", "0.05806000"], ["83899.19000000", "0.05959000"], ["83898.68000000", "0.04440000"], ["83896.85000000", "0.04490000"], ["83896.59000000", "0.00000000"], ["83894.22000000", "0.05497000"], ["83893.27000000", "0.00000000"], ["83892.45000000", "0.05497000"], ["83892.19000000", "0.00000000"], ["83892.01000000", "0.06102000"], ["83891.20000000", "0.10143000"], ["83889.68000000", "0.11091000"], ["83888.79000000", "0.00000000"], ["83888.08000000", "0.05497000"], ["83885.89000000", "0.09497000"], ["83885.81000000", "0.00000000"], ["83885.61000000", "0.06093000"], ["83884.71000000", "0.00000000"], ["83883.80000000", "0.05098000"], ["83883.61000000", "0.00000000"], ["83883.53000000", "0.10594000"], ["83882.98000000", "0.09098000"], ["83882.48000000", "0.14089000"], ["83881.37000000", "0.77875000"], ["83881.20000000", "0.49789000"], ["83874.03000000", "0.22190000"], ["83873.48000000", "0.00000000"], ["83872.29000000", "0.10000000"], ["83870.76000000", "0.40277000"], ["83868.61000000", "0.21053000"], ["83868.34000000", "0.05058000"], ["83867.80000000", "0.00000000"], ["83867.02000000", "0.00000000"], ["83865.60000000", "0.03594000"], ["83860.38000000", "0.12900000"], ["83859.13000000", "0.00000000"], ["83846.90000000", "0.00060000"], ["83846.87000000", "0.00000000"], ["83845.92000000", "0.00000000"], ["83831.41000000", "0.00000000"], ["83828.24000000", "0.00060000"], ["83827.25000000", "0.16378000"], ["83821.98000000", "0.00000000"], ["83816.56000000", "0.00000000"], ["83809.79000000", "0.00000000"], ["83805.52000000", "0.00400000"], ["83794.18000000", "0.39333000"], ["83791.69000000", "0.00000000"], ["83791.22000000", "0.00000000"], ["83787.49000000", "0.05098000"], ["83787.33000000", "0.00000000"], ["83787.05000000", "0.00000000"], ["83787.01000000", "0.00000000"], ["83785.88000000", "0.05297000"], ["83785.77000000", "0.00000000"], ["83785.68000000", "0.00000000"], ["83785.32000000", "0.00000000"], ["83784.99000000", "0.00000000"], ["83781.79000000", "0.00000000"], ["83781.50000000", "0.00000000"], ["83777.97000000", "0.00000000"], ["83775.96000000", "0.00000000"], ["83775.95000000", "0.00000000"], ["83768.31000000", "0.00000000"], ["83750.92000000", "0.00000000"], ["83747.43000000", "0.00000000"], ["83745.34000000", "0.00000000"], ["83743.73000000", "0.00000000"], ["83717.09000000", "0.00000000"], ["82678.24000000", "0.00100000"], ["80589.60000000", "0.03572000"], ["75543.00000000", "0.00000000"], ["67149.84000000", "0.00058000"], ["33000.00000000", "2.96666000"]], "a": [["83937.31000000", "0.20230000"], ["83937.38000000", "0.00000000"], ["83937.39000000", "0.00000000"], ["83937.40000000", "0.00000000"], ["83937.41000000", "0.00014000"], ["83937.42000000", "0.00022000"], ["83937.43000000", "0.65886000"], ["83937.51000000", "0.00202000"], ["83937.68000000", "0.34864000"], ["83937.93000000", "0.16957000"], ["83938.00000000", "0.00000000"], ["83938.30000000", "0.00000000"], ["83938.78000000", "0.00006000"], ["83939.14000000", "0.00000000"], ["83939.21000000", "0.00024000"], ["83939.22000000", "0.00000000"], ["83939.30000000", "0.00000000"], ["83939.32000000", "0.00000000"], ["83939.65000000", "0.00000000"], ["83939.94000000", "0.00000000"], ["83940.00000000", "0.01416000"], ["83940.20000000", "0.00000000"], ["83940.62000000", "0.07614000"], ["83941.09000000", "0.02391000"], ["83941.33000000", "0.00000000"], ["83941.50000000", "0.01000000"], ["83941.61000000", "0.02220000"], ["83941.77000000", "0.04006000"], ["83941.94000000", "0.00504000"], ["83942.00000000", "0.01416000"], ["83942.17000000", "0.00000000"], ["83942.29000000", "0.25306000"], ["83942.30000000", "0.00000000"], ["83942.45000000", "0.00000000"], ["83942.75000000", "0.00000000"], ["83942.77000000", "0.00000000"], ["83943.02000000", "0.00000000"], ["83943.03000000", "0.00000000"], ["83943.04000000", "0.00000000"], ["83943.13000000", "0.00000000"], ["83943.16000000", "0.14984000"], ["83943.47000000", "0.00000000"], ["83943.79000000", "0.00000000"], ["83943.82000000", "0.03269000"], ["83943.84000000", "0.00000000"], ["83943.98000000", "0.00000000"], ["83944.00000000", "0.01410000"], ["83944.01000000", "0.00000000"], ["83944.85000000", "0.00000000"], ["83945.05000000", "0.00000000"], ["83945.11000000", "0.08354000"], ["83945.12000000", "0.59562000"], ["83945.40000000", "0.00000000"], ["83945.56000000", "0.00000000"], ["83945.63000000", "0.00000000"], ["83945.65000000", "0.27279000"], ["83946.14000000", "0.00000000"], ["83946.15000000", "0.00000000"], ["83946.25000000", "0.00000000"], ["83946.38000000", "0.00000000"], ["83946.57000000", "0.00119000"], ["83946.69000000", "0.00000000"], ["83946.90000000", "0.47650000"], ["83947.11000000", "0.00000000"], ["83947.22000000", "0.00000000"], ["83947.23000000", "0.00000000"], ["83947.32000000", "0.00000000"], ["83947.38000000", "0.00000000"], ["83947.55000000", "0.00000000"], ["83947.65000000", "0.00000000"], ["83947.97000000", "0.10787000"], ["83948.19000000", "0.00000000"], ["83948.62000000", "0.00000000"], ["83949.05000000", "0.03000000"], ["83949.30000000", "0.00000000"], ["83950.20000000", "0.00000000"], ["83950.35000000", "0.15529000"], ["83950.64000000", "0.00000000"], ["83950.68000000", "0.00000000"], ["83950.71000000", "0.00000000"], ["83950.91000000", "0.00094000"], ["83950.94000000", "0.09600000"], ["83950.95000000", "0.00000000"], ["83951.06000000", "0.21870000"], ["83951.78000000", "0.06800000"], ["83952.63000000", "0.14400000"], ["83952.67000000", "0.00000000"], ["83952.72000000", "0.06406000"], ["83952.87000000", "0.00000000"], ["83952.98000000", "0.00000000"], ["83953.31000000", "0.00000000"], ["83953.55000000", "0.47650000"], ["83953.70000000", "0.00000000"], ["83953.82000000", "0.00000000"], ["83954.17000000", "0.00000000"], ["83954.43000000", "0.00000000"], ["83954.76000000", "0.38432000"], ["83955.15000000", "0.06400000"], ["83955.25000000", "0.00090000"], ["83955.44000000", "0.00000000"], ["83955.54000000", "0.89344000"], ["83955.99000000", "0.06000000"], ["83956.03000000", "0.05956000"], ["83956.16000000", "0.00000000"], ["83956.74000000", "0.04000000"], ["83956.82000000", "0.05200000"], ["83956.83000000", "0.04800000"], ["83956.92000000", "0.07200000"], ["83956.95000000", "0.06000000"], ["83958.28000000", "0.01191000"], ["83958.64000000", "0.00922000"], ["83958.84000000", "0.89344000"], ["83959.98000000", "0.00000000"], ["83960.31000000", "0.00091000"], ["83963.19000000", "0.00000000"], ["83963.21000000", "0.00000000"], ["83966.06000000", "0.00000000"], ["83966.59000000", "0.00000000"], ["83967.36000000", "0.89344000"], ["83968.26000000", "0.00000000"], ["83969.39000000", "0.00000000"], ["83969.46000000", "0.00000000"], ["83969.96000000", "0.00000000"], ["83970.38000000", "0.85785000"], ["83970.55000000", "0.00000000"], ["83971.48000000", "0.62197000"], ["83972.45000000", "0.00000000"], ["83974.76000000", "0.00000000"], ["83975.26000000", "0.50440000"], ["83975.28000000", "0.00000000"], ["83976.41000000", "0.00000000"], ["83977.22000000", "0.00000000"], ["83977.90000000", "0.00000000"], ["83980.54000000", "0.03533000"], ["83981.13000000", "0.00000000"], ["83983.04000000", "0.00000000"], ["83984.14000000", "0.00000000"], ["83984.23000000", "0.85771000"], ["83985.03000000", "0.05828000"], ["83985.64000000", "0.02808000"], ["83986.43000000", "0.59588000"], ["83986.47000000", "0.00000000"], ["83988.34000000", "0.89344000"], ["83989.89000000", "0.11645000"], ["83989.95000000", "0.00000000"], ["83991.33000000", "0.47650000"], ["83992.31000000", "0.04159000"], ["83992.52000000", "0.00000000"], ["83994.19000000", "0.00000000"], ["83994.25000000", "0.09209000"], ["84002.54000000", "0.04110000"], ["84005.64000000", "0.00000000"], ["84007.74000000", "0.06800000"], ["84013.08000000", "0.06400000"], ["84014.76000000", "0.05200000"], ["84021.70000000", "0.19478000"], ["84022.60000000", "0.09600000"], ["84024.26000000", "0.00000000"], ["84024.27000000", "0.00000000"], ["84024.35000000", "0.00000000"], ["84027.62000000", "0.00000000"], ["84028.47000000", "0.00000000"], ["84029.03000000", "0.00000000"], ["84029.09000000", "0.00000000"], ["84052.11000000", "0.02384000"], ["84099.13000000", "0.00050000"], ["84260.90000000", "0.00000000"], ["84294.00000000", "0.03575000"], ["84604.48000000", "0.00000000"], ["84604.80000000", "0.05965000"], ["85163.44000000", "0.00000000"], ["85196.37000000", "0.00100000"], ["85214.55000000", "0.10000000"], ["85392.41000000", "0.00000000"], ["85398.38000000", "0.00000000"], ["85448.85000000", "0.00060000"], ["85454.83000000", "0.00060000"], ["150001.00000000", "0.00072000"]], "record_time": 1742577143.212879, "EXCHANGE": "BINANCE"}
{"e": "depthUpdate", "E": 1742577144014, "s": "BTCUSDT", "U": 64632179279, "u": 64632179748, "b": [["83937.42000000", "7.83184000"], ["83937.41000000", "0.00048000"], ["83937.33000000", "0.00021000"], ["83937.32000000", "0.74873000"], ["83937.31000000", "0.00013000"], ["83937.30000000", "1.34919000"], ["83937.29000000", "0.00007000"], ["83937.25000000", "0.00007000"], ["83937.24000000", "0.09498000"], ["83937.19000000", "0.00000000"], ["83937.16000000", "0.00000000"], ["83937.02000000", "0.00202000"], ["83937.01000000", "0.00000000"], ["83937.00000000", "0.00000000"], ["83936.90000000", "0.00000000"], ["83936.68000000", "0.00000000"], ["83936.67000000", "0.00000000"], ["83936.66000000", "0.00000000"], ["83936.40000000", "0.05370000"], ["83935.41000000", "0.01506000"], ["83934.50000000", "0.00000000"], ["83933.62000000", "0.02380000"], ["83932.80000000", "0.00086000"], ["83931.92000000", "0.17899000"], ["83931.90000000", "0.00000000"], ["83931.83000000", "0.04000000"], ["83931.19000000", "0.00008000"], ["83930.16000000", "0.04000000"], ["83930.15000000", "0.04000000"], ["83929.70000000", "0.18463000"], ["83929.65000000", "0.02382000"], ["83929.43000000", "0.00595000"], ["83928.43000000", "0.12507000"], ["83928.11000000", "0.20828000"], ["83928.10000000", "0.17868000"], ["83927.97000000", "0.02382000"], ["83927.65000000", "0.00000000"], ["83926.79000000", "0.04000000"], ["83925.95000000", "0.04000000"], ["83925.69000000", "0.00595000"], ["83924.40000000", "0.00006000"], ["83923.46000000", "0.00000000"], ["83922.87000000", "0.00000000"], ["83922.71000000", "0.05956000"], ["83922.62000000", "0.00000000"], ["83922.27000000", "0.00000000"], ["83921.79000000", "0.00000000"], ["83921.78000000", "0.00000000"], ["83919.65000000", "0.00000000"], ["83918.94000000", "0.45221000"], ["83917.89000000", "0.05956000"], ["83917.58000000", "0.00000000"], ["83914.63000000", "0.00000000"], ["83913.15000000", "0.00759000"], ["83909.97000000", "0.04000000"], ["83909.59000000", "0.00000000"], ["83909.05000000", "0.04000000"], ["83906.61000000", "0.04000000"], ["83906.09000000", "0.05000000"], ["83904.94000000", "0.04000000"], ["83904.93000000", "0.04000000"], ["83899.89000000", "0.03345000"], ["83896.88000000", "0.00000000"], ["83895.81000000", "0.00000000"], ["83895.15000000", "0.00000000"], ["83885.61000000", "0.05497000"], ["83885.55000000", "0.00000000"], ["83884.48000000", "0.00000000"], ["83883.87000000", "0.00000000"], ["83875.48000000", "0.04000000"], ["83875.33000000", "0.00000000"], ["83873.81000000", "0.04498000"], ["83864.88000000", "0.00000000"], ["83863.64000000", "0.00000000"], ["83862.25000000", "0.00060000"], ["83861.97000000", "0.00000000"], ["83861.44000000", "0.00000000"], ["83854.33000000", "0.00000000"], ["83852.88000000", "0.00000000"], ["83848.71000000", "0.00400000"], ["83847.86000000", "0.00000000"], ["83846.90000000", "0.00000000"], ["83843.58000000", "0.00060000"], ["83828.24000000", "0.00000000"], ["83821.15000000", "0.00000000"], ["83813.46000000", "0.00000000"], ["83807.12000000", "0.01527000"], ["83806.25000000", "0.00000000"], ["83805.52000000", "0.00000000"], ["83796.06000000", "0.00000000"], ["83792.20000000", "0.99313000"], ["83764.97000000", "0.00000000"], ["82984.80000000", "0.02350000"], ["82678.24000000", "0.00000000"], ["81629.95000000", "0.00043000"], ["75543.00000000", "0.00000000"], ["67149.94000000", "0.00058000"], ["67149.84000000", "0.00000000"], ["33000.00000000", "2.96666000"], ["30217.47000000", "0.00140000"], ["30217.43000000", "0.00020000"]], "a": [["83937.31000000", "0.00000000"], ["83937.32000000", "0.00000000"], ["83937.41000000", "0.00000000"], ["83937.42000000", "0.00000000"], ["83937.43000000", "0.65930000"], ["83937.44000000", "0.00039000"], ["83937.51000000", "0.00000000"], ["83937.60000000", "0.00008000"], ["83937.63000000", "0.00202000"], ["83937.68000000", "0.00000000"], ["83937.93000000", "0.00000000"], ["83937.98000000", "0.00007000"], ["83938.78000000", "0.00000000"], ["83940.00000000", "0.00000000"], ["83940.60000000", "0.00014000"], ["83940.61000000", "0.03022000"], ["83941.08000000", "0.00000000"], ["83941.49000000", "0.00760000"], ["83941.50000000", "0.00500000"], ["83941.61000000", "0.02214000"], ["83941.77000000", "0.00006000"], ["83941.94000000", "0.00000000"], ["83941.98000000", "0.00014000"], ["83941.99000000", "0.14724000"], ["83942.00000000", "0.01410000"], ["83942.06000000", "0.00506000"], ["83942.15000000", "0.00014000"], ["83942.16000000", "0.32351000"], ["83942.28000000", "0.00000000"], ["83942.29000000", "0.16310000"], ["83943.15000000", "0.00000000"], ["83943.16000000", "0.14984000"], ["83943.82000000", "0.00000000"], ["83944.00000000", "0.01410000"], ["83945.11000000", "0.08354000"], ["83945.12000000", "0.00000000"], ["83945.65000000", "0.41836000"], ["83945.74000000", "0.00000000"], ["83946.49000000", "0.78659000"], ["83948.01000000", "0.03381000"], ["83948.65000000", "0.00000000"], ["83949.89000000", "0.00000000"], ["83949.90000000", "0.00000000"], ["83950.01000000", "0.00544000"], ["83950.61000000", "0.02441000"], ["83952.99000000", "0.35737000"], ["83954.76000000", "0.16412000"], ["83955.03000000", "0.00000000"], ["83956.03000000", "0.00000000"], ["83956.74000000", "0.00000000"], ["83957.52000000", "0.00000000"], ["83958.05000000", "1.02750000"], ["83959.54000000", "0.00000000"], ["83960.56000000", "0.59562000"], ["83961.24000000", "0.04000000"], ["83963.19000000", "0.05956000"], ["83979.33000000", "1.03922000"], ["83982.54000000", "0.00000000"], ["83986.42000000", "0.00000000"], ["84001.28000000", "0.01865000"], ["84013.70000000", "0.00000000"], ["84021.70000000", "0.14025000"], ["84022.60000000", "0.00000000"], ["84039.12000000", "0.02384000"], ["84052.11000000", "0.00000000"], ["84078.46000000", "0.00000000"], ["84079.46000000", "0.00679000"], ["84318.62000000", "0.00421000"], ["85196.37000000", "0.00000000"], ["85448.85000000", "0.00000000"], ["85454.83000000", "0.00000000"], ["85588.49000000", "0.00060000"], ["85594.49000000", "0.00060000"]], "record_time": 1742577144.212543, "EXCHANGE": "BINANCE"}
{"e": "depthUpdate", "E": 1742577145014, "s": "BTCUSDT", "U": 64632179749, "u": 64632180006, "b": [["83937.42000000", "7.90309000"], ["83937.30000000", "1.34513000"], ["83937.24000000", "0.00006000"], ["83936.40000000", "0.05377000"], ["83935.96000000", "0.04257000"], ["83935.41000000", "0.01500000"], ["83930.00000000", "0.01910000"], ["83922.64000000", "0.00000000"], ["83921.50000000", "0.00500000"], ["83920.16000000", "0.99164000"], ["83920.01000000", "1.36124000"], ["83918.26000000", "0.11752000"], ["83915.01000000", "0.00754000"], ["83913.15000000", "0.00000000"], ["83912.22000000", "0.05000000"], ["83911.11000000", "0.00000000"], ["83910.49000000", "0.00000000"], ["83906.09000000", "0.00000000"], ["83862.62000000", "0.00060000"], ["83862.25000000", "0.00000000"], ["83855.80000000", "0.22753000"], ["83855.17000000", "0.63080000"], ["83843.95000000", "0.00060000"], ["83843.58000000", "0.00000000"], ["83820.97000000", "0.18353000"], ["83802.24000000", "0.00000000"], ["83792.20000000", "0.00000000"], ["83772.64000000", "0.00000000"], ["83771.13000000", "0.00839000"], ["83764.97000000", "0.99313000"], ["81919.03000000", "0.00000000"], ["75543.00000000", "0.00000000"], ["67149.94000000", "0.00058000"], ["33000.00000000", "2.96666000"], ["20002.00000000", "0.00000000"], ["20001.00000000", "0.02099000"]], "a": [["83937.43000000", "0.66428000"], ["83937.60000000", "0.00000000"], ["83937.98000000", "0.00007000"], ["83938.53000000", "0.00000000"], ["83940.00000000", "0.00000000"], ["83940.01000000", "0.00000000"], ["83940.02000000", "0.00000000"], ["83940.60000000", "0.00014000"], ["83940.61000000", "0.03026000"], ["83941.08000000", "0.00000000"], ["83941.13000000", "0.00000000"], ["83941.14000000", "0.00000000"], ["83941.49000000", "0.00000000"], ["83941.50000000", "0.00000000"], ["83941.77000000", "0.00020000"], ["83941.78000000", "0.24648000"], ["83941.79000000", "0.00000000"], ["83941.80000000", "0.12627000"], ["83941.97000000", "0.00000000"], ["83941.98000000", "0.00000000"], ["83941.99000000", "0.00000000"], ["83942.15000000", "0.00000000"], ["83942.16000000", "0.00000000"], ["83942.29000000", "0.00000000"], ["83943.14000000", "0.00000000"], ["83943.15000000", "0.00000000"], ["83943.63000000", "0.00000000"], ["83943.64000000", "0.00000000"], ["83943.96000000", "0.26354000"], ["83944.59000000", "0.00759000"], ["83945.65000000", "0.27715000"], ["83945.70000000", "0.00000000"], ["83946.07000000", "0.78659000"], ["83946.49000000", "0.00000000"], ["83946.90000000", "0.00000000"], ["83947.97000000", "0.00000000"], ["83948.01000000", "0.00000000"], ["83948.52000000", "0.00000000"], ["83949.94000000", "0.47663000"], ["83950.01000000", "0.00205000"], ["83950.07000000", "0.03432000"], ["83950.61000000", "0.00000000"], ["83952.00000000", "0.10786000"], ["83953.52000000", "0.00000000"], ["83953.80000000", "0.71418000"], ["83954.04000000", "0.02391000"], ["83954.23000000", "0.45000000"], ["83958.05000000", "0.66712000"], ["83961.60000000", "0.00000000"], ["83966.52000000", "1.53895000"], ["83966.68000000", "1.35525000"], ["83984.40000000", "0.00000000"], ["83985.57000000", "0.12115000"], ["83987.94000000", "0.05000000"], ["83989.89000000", "0.00000000"], ["83992.31000000", "0.00000000"], ["84000.00000000", "0.07639000"], ["84001.28000000", "0.06024000"], ["84002.54000000", "0.00000000"], ["84012.19000000", "0.04110000"], ["84016.63000000", "0.42138000"], ["84039.12000000", "0.00000000"], ["85263.06000000", "0.00000000"], ["85263.44000000", "0.00356000"], ["85431.03000000", "0.00088000"], ["85437.01000000", "0.00060000"], ["85588.49000000", "0.00000000"], ["85594.49000000", "0.00000000"]], "record_time": 1742577145.212723, "EXCHANGE": "BINANCE"}
{"e": "depthUpdate", "E": 1742577146014, "s": "BTCUSDT", "U": 64632180007, "u": 64632180111, "b": [["83937.42000000", "7.90740000"], ["83937.32000000", "0.74879000"], ["83937.31000000", "0.00007000"], ["83937.30000000", "1.34519000"], ["83937.25000000", "0.00007000"], ["83937.24000000", "0.00000000"], ["83937.00000000", "0.00006000"], ["83936.96000000", "0.00008000"], ["83935.96000000", "0.00000000"], ["83935.41000000", "0.01506000"], ["83933.96000000", "0.07236000"], ["83924.70000000", "0.03583000"], ["83918.89000000", "0.01610000"], ["83912.22000000", "0.00000000"], ["83911.74000000", "0.00000000"], ["83910.65000000", "0.00000000"], ["83903.98000000", "0.05956000"], ["83886.79000000", "0.56466000"], ["83872.55000000", "0.00061000"], ["83870.43000000", "0.00023000"], ["83869.01000000", "0.04998000"], ["83868.34000000", "0.04997000"], ["83854.49000000", "0.00000000"], ["83098.04000000", "0.00000000"], ["82678.35000000", "0.00100000"], ["81919.41000000", "0.00363000"], ["75543.00000000", "0.00000000"], ["67149.94000000", "0.00058000"], ["33000.00000000", "2.96666000"], ["30217.47000000", "0.00180000"]], "a": [["83937.43000000", "0.00574000"], ["83938.57000000", "0.00008000"], ["83940.60000000", "0.00000000"], ["83940.61000000", "0.00014000"], ["83941.08000000", "0.00014000"], ["83941.61000000", "0.02220000"], ["83941.77000000", "0.00014000"], ["83941.78000000", "0.24654000"], ["83941.80000000", "0.12633000"], ["83942.00000000", "0.01416000"], ["83942.79000000", "0.00000000"], ["83943.16000000", "0.14990000"], ["83943.96000000", "0.00000000"], ["83944.00000000", "0.01416000"], ["83945.11000000", "0.08354000"], ["83946.07000000", "0.00000000"], ["83948.03000000", "0.78657000"], ["83950.01000000", "0.00000000"], ["83950.07000000", "0.00000000"], ["83953.80000000", "0.00019000"], ["83954.23000000", "0.45000000"], ["83954.79000000", "0.00000000"], ["83961.90000000", "0.05956000"], ["83985.64000000", "0.00000000"], ["83988.26000000", "1.07214000"], ["83990.77000000", "0.02808000"], ["84026.15000000", "0.03992000"], ["84035.37000000", "0.02384000"], ["85196.50000000", "0.00100000"]], "record_time": 1742577146.211863, "EXCHANGE": "BINANCE"}
{"e": "depthUpdate", "E": 1742577147014, "s": "BTCUSDT", "U": 64632180112, "u": 64632183013, "b": [["83945.65000000", "6.23271000"], ["83945.64000000", "0.00047000"], ["83945.51000000", "0.00007000"], ["83945.07000000", "0.00021000"], ["83945.06000000", "0.18014000"], ["83944.70000000", "0.00000000"], ["83944.67000000", "0.00014000"], ["83944.63000000", "0.00021000"], ["83944.62000000", "0.70068000"], ["83944.61000000", "0.00000000"], ["83944.60000000", "0.00000000"], ["83944.59000000", "0.00000000"], ["83944.58000000", "1.18727000"], ["83944.01000000", "0.00000000"], ["83944.00000000", "0.01423000"], ["83943.17000000", "0.00000000"], ["83943.16000000", "0.17905000"], ["83943.15000000", "0.00000000"], ["83943.14000000", "0.00000000"], ["83943.06000000", "0.00000000"], ["83942.51000000", "0.02385000"], ["83942.34000000", "0.04006000"], ["83942.18000000", "0.00000000"], ["83942.17000000", "0.00007000"], ["83942.16000000", "0.15052000"], ["83942.10000000", "0.00000000"], ["83942.07000000", "0.00000000"], ["83942.06000000", "0.23898000"], ["83942.05000000", "0.18530000"], ["83942.01000000", "0.00000000"], ["83942.00000000", "0.03795000"], ["83941.99000000", "0.33163000"], ["83941.89000000", "0.00000000"], ["83941.79000000", "0.00000000"], ["83941.78000000", "0.00000000"], ["83941.77000000", "0.00000000"], ["83941.76000000", "0.00000000"], ["83941.60000000", "0.00000000"], ["83941.59000000", "0.00000000"], ["83941.58000000", "0.00000000"], ["83941.51000000", "0.04000000"], ["83941.29000000", "0.00000000"], ["83941.08000000", "0.00000000"], ["83941.07000000", "0.00000000"], ["83940.73000000", "0.00000000"], ["83940.69000000", "0.04000000"], ["83940.67000000", "0.04000000"], ["83940.64000000", "0.23092000"], ["83940.63000000", "0.00000000"], ["83940.62000000", "0.00000000"], ["83940.61000000", "0.00000000"], ["83940.60000000", "0.00000000"], ["83940.59000000", "0.04000000"], ["83940.50000000", "0.00000000"], ["83940.49000000", "0.00000000"], ["83940.20000000", "0.00000000"], ["83940.00000000", "0.01416000"], ["83939.32000000", "0.00000000"], ["83939.21000000", "0.00057000"], ["83939.20000000", "0.00000000"], ["83938.47000000", "0.00000000"], ["83938.36000000", "0.00000000"], ["83938.35000000", "0.05000000"], ["83938.31000000", "0.00000000"], ["83938.29000000", "0.00000000"], ["83938.16000000", "0.04000000"], ["83938.07000000", "0.00000000"], ["83938.02000000", "0.00000000"], ["83938.00000000", "0.01410000"], ["83937.97000000", "0.00000000"], ["83937.71000000", "0.00000000"], ["83937.62000000", "0.00006000"], ["83937.57000000", "0.00000000"], ["83937.46000000", "0.00000000"], ["83937.45000000", "0.00000000"], ["83937.43000000", "0.00000000"], ["83937.42000000", "0.46562000"], ["83937.41000000", "0.00000000"], ["83937.33000000", "0.00000000"], ["83937.32000000", "0.00000000"], ["83937.31000000", "0.04000000"], ["83937.30000000", "0.17435000"], ["83937.29000000", "0.00000000"], ["83937.25000000", "0.00000000"], ["83936.96000000", "0.00000000"], ["83936.66000000", "0.23127000"], ["83936.65000000", "0.00000000"], ["83936.59000000", "0.00000000"], ["83936.48000000", "0.04000000"], ["83936.46000000", "0.04000000"], ["83936.42000000", "0.29134000"], ["83936.40000000", "0.00000000"], ["83936.38000000", "0.04000000"], ["83936.35000000", "0.00000000"], ["83936.34000000", "0.00000000"], ["83936.32000000", "0.00000000"], ["83936.25000000", "0.00000000"], ["83936.03000000", "0.00030000"], ["83936.00000000", "0.01410000"], ["83935.99000000", "0.01500000"], ["83935.55000000", "0.00000000"], ["83935.41000000", "0.01500000"], ["83935.31000000", "0.00000000"], ["83934.89000000", "0.00000000"], ["83934.48000000", "0.14843000"], ["83934.11000000", "0.00013000"], ["83933.97000000", "0.00000000"], ["83933.81000000", "0.00000000"], ["83933.62000000", "0.00000000"], ["83933.44000000", "0.05956000"], ["83933.40000000", "0.04257000"], ["83933.10000000", "0.00009000"], ["83932.98000000", "0.00000000"], ["83932.68000000", "0.00000000"], ["83932.59000000", "0.00006000"], ["83932.02000000", "0.71399000"], ["83932.01000000", "0.59582000"], ["83931.99000000", "0.00000000"], ["83931.91000000", "0.79909000"], ["83931.83000000", "0.00000000"], ["83931.58000000", "0.00013000"], ["83931.32000000", "0.00000000"], ["83931.11000000", "0.35737000"], ["83930.99000000", "0.00000000"], ["83930.16000000", "0.00000000"], ["83930.15000000", "0.00000000"], ["83930.07000000", "0.00000000"], ["83930.00000000", "0.01410000"], ["83929.86000000", "0.00000000"], ["83929.85000000", "0.00000000"], ["83929.66000000", "0.00000000"], ["83929.38000000", "0.00000000"], ["83929.17000000", "0.89344000"], ["83929.12000000", "0.00000000"], ["83928.86000000", "0.05956000"], ["83928.73000000", "0.02501000"], ["83928.11000000", "1.02951000"], ["83928.05000000", "0.00000000"], ["83927.79000000", "0.05956000"], ["83927.64000000", "0.00000000"], ["83927.08000000", "0.00120000"], ["83927.00000000", "0.03100000"], ["83926.79000000", "0.59314000"], ["83926.34000000", "0.00000000"], ["83925.96000000", "0.00000000"], ["83925.95000000", "0.00000000"], ["83925.87000000", "0.00000000"], ["83925.32000000", "0.08354000"], ["83925.31000000", "0.71399000"], ["83925.30000000", "0.00000000"], ["83924.72000000", "0.89344000"], ["83923.70000000", "0.00000000"], ["83923.43000000", "0.00000000"], ["83923.36000000", "0.00000000"], ["83923.35000000", "0.00000000"], ["83922.23000000", "0.00000000"], ["83922.07000000", "0.04440000"], ["83921.50000000", "0.00000000"], ["83921.32000000", "0.04000000"], ["83920.72000000", "0.05956000"], ["83920.64000000", "0.00000000"], ["83920.28000000", "0.05000000"], ["83920.08000000", "0.00000000"], ["83919.66000000", "0.04000000"], ["83919.65000000", "0.04000000"], ["83919.58000000", "0.04490000"], ["83919.05000000", "0.89344000"], ["83918.94000000", "0.00000000"], ["83918.89000000", "0.01610000"], ["83918.07000000", "0.00550000"], ["83917.79000000", "0.00000000"], ["83917.16000000", "0.16519000"], ["83916.46000000", "0.47650000"], ["83916.28000000", "0.04000000"], ["83914.66000000", "0.00000000"], ["83914.64000000", "0.46569000"], ["83913.17000000", "0.00000000"], ["83911.96000000", "0.00000000"], ["83911.40000000", "0.00000000"], ["83911.25000000", "0.00000000"], ["83910.72000000", "0.00000000"], ["83909.89000000", "0.00000000"], ["83907.87000000", "0.00358000"], ["83904.48000000", "0.05864000"], ["83903.46000000", "0.05194000"], ["83903.06000000", "0.71399000"], ["83903.05000000", "0.44481000"], ["83901.53000000", "0.00000000"], ["83900.88000000", "0.06102000"], ["83900.79000000", "0.00000000"], ["83899.87000000", "0.00000000"], ["83899.25000000", "0.00000000"], ["83898.68000000", "0.00000000"], ["83898.49000000", "0.00000000"], ["83898.48000000", "0.00000000"], ["83897.90000000", "0.94109000"], ["83897.60000000", "0.00000000"], ["83897.42000000", "0.04765000"], ["83896.85000000", "0.00000000"], ["83896.50000000", "0.09530000"], ["83895.88000000", "0.01191000"], ["83895.84000000", "0.05498000"], ["83895.22000000", "0.00814000"], ["83895.04000000", "0.04765000"], ["83894.08000000", "0.04765000"], ["83892.92000000", "0.00000000"], ["83892.45000000", "0.50343000"], ["83892.43000000", "0.04646000"], ["83892.36000000", "0.02847000"], ["83892.01000000", "0.10263000"], ["83891.90000000", "0.02847000"], ["83891.59000000", "0.00827000"], ["83891.20000000", "0.29617000"], ["83890.76000000", "1.30268000"], ["83889.68000000", "0.31950000"], ["83888.43000000", "1.11277000"], ["83888.42000000", "0.17416000"], ["83888.14000000", "0.04765000"], ["83888.01000000", "0.10995000"], ["83887.53000000", "0.04646000"], ["83887.52000000", "0.00000000"], ["83886.79000000", "0.61231000"], ["83886.43000000", "0.04646000"], ["83886.42000000", "0.72820000"], ["83885.89000000", "0.16293000"], ["83885.56000000", "0.00000000"], ["83885.31000000", "0.10996000"], ["83885.30000000", "0.00000000"], ["83885.03000000", "0.31785000"], ["83884.65000000", "0.09498000"], ["83884.00000000", "0.37417000"], ["83883.53000000", "0.20790000"], ["83882.98000000", "0.14196000"], ["83882.46000000", "0.00023000"], ["83882.38000000", "0.03575000"], ["83882.00000000", "0.07882000"], ["83881.58000000", "0.25987000"], ["83881.10000000", "0.10196000"], ["83880.70000000", "0.08396000"], ["83880.11000000", "0.28894000"], ["83878.68000000", "0.24502000"], ["83876.76000000", "0.00061000"], ["83876.50000000", "0.14732000"], ["83876.05000000", "0.00000000"], ["83876.00000000", "0.00235000"], ["83874.53000000", "0.56678000"], ["83874.06000000", "0.00358000"], ["83874.03000000", "0.26688000"], ["83873.94000000", "0.00000000"], ["83873.05000000", "0.04000000"], ["83872.56000000", "0.09996000"], ["83872.55000000", "0.00000000"], ["83872.00000000", "0.05233000"], ["83870.76000000", "0.44775000"], ["83870.57000000", "0.12899000"], ["83870.43000000", "0.00000000"], ["83870.36000000", "0.08996000"], ["83869.70000000", "0.00000000"], ["83869.44000000", "0.02859000"], ["83869.01000000", "0.09996000"], ["83867.59000000", "0.00000000"], ["83866.89000000", "0.00000000"], ["83866.25000000", "0.00000000"], ["83866.23000000", "0.63080000"], ["83865.67000000", "0.00000000"], ["83865.60000000", "0.00019000"], ["83863.23000000", "0.00000000"], ["83863.01000000", "0.00000000"], ["83860.00000000", "0.00235000"], ["83859.24000000", "0.00000000"], ["83855.80000000", "0.04379000"], ["83855.59000000", "0.01196000"], ["83855.17000000", "0.00000000"], ["83854.57000000", "0.00000000"], ["83853.30000000", "0.00400000"], ["83848.71000000", "0.00000000"], ["83847.20000000", "0.34655000"], ["83846.72000000", "0.01527000"], ["83846.71000000", "0.00000000"], ["83837.90000000", "0.00000000"], ["83831.98000000", "0.11418000"], ["83828.95000000", "0.00000000"], ["83823.07000000", "0.58914000"], ["83818.31000000", "0.00000000"], ["83816.88000000", "0.00679000"], ["83813.91000000", "0.00000000"], ["83810.19000000", "0.13328000"], ["83807.12000000", "0.00000000"], ["83806.85000000", "0.00000000"], ["83806.24000000", "0.45000000"], ["83805.44000000", "0.04767000"], ["83805.09000000", "0.00000000"], ["83804.66000000", "0.04648000"], ["83804.46000000", "0.00000000"], ["83804.40000000", "0.00000000"], ["83804.27000000", "0.04766000"], ["83804.24000000", "0.00000000"], ["83804.03000000", "0.00000000"], ["83804.00000000", "0.00235000"], ["83803.59000000", "0.00000000"], ["83803.25000000", "0.00000000"], ["83802.97000000", "0.00008000"], ["83802.18000000", "0.00000000"], ["83802.15000000", "0.00000000"], ["83801.40000000", "0.00000000"], ["83800.44000000", "0.05497000"], ["83800.41000000", "0.00000000"], ["83800.21000000", "0.00000000"], ["83800.12000000", "0.00000000"], ["83800.08000000", "0.00000000"], ["83799.20000000", "0.00000000"], ["83799.18000000", "0.05297000"], ["83798.84000000", "0.00000000"], ["83797.92000000", "0.00000000"], ["83795.69000000", "0.05497000"], ["83795.37000000", "0.00000000"], ["83795.02000000", "0.00000000"], ["83793.19000000", "0.00000000"], ["83792.60000000", "0.00000000"], ["83792.57000000", "0.00000000"], ["83792.23000000", "0.00000000"], ["83791.80000000", "0.00000000"], ["83791.32000000", "0.00000000"], ["83790.61000000", "0.00000000"], ["83790.54000000", "0.00000000"], ["83790.18000000", "0.00000000"], ["83789.76000000", "0.00000000"], ["83789.41000000", "0.00000000"], ["83789.22000000", "0.00000000"], ["83789.17000000", "0.00000000"], ["83789.03000000", "0.00000000"], ["83788.39000000", "0.00000000"], ["83788.24000000", "0.00000000"], ["83788.02000000", "0.00000000"], ["83787.90000000", "0.00000000"], ["83787.87000000", "0.00009000"], ["83787.77000000", "0.00000000"], ["83787.68000000", "0.00000000"], ["83787.49000000", "0.00000000"], ["83786.84000000", "0.00000000"], ["83785.46000000", "0.00000000"], ["83785.10000000", "0.00000000"], ["83783.70000000", "0.00000000"], ["83783.46000000", "0.01000000"], ["83782.98000000", "0.00000000"], ["83782.88000000", "0.00000000"], ["83782.15000000", "0.00000000"], ["83781.92000000", "0.00000000"], ["83781.88000000", "0.00000000"], ["83781.60000000", "0.00006000"], ["83780.62000000", "0.00000000"], ["83780.42000000", "0.00000000"], ["83779.96000000", "0.00000000"], ["83779.51000000", "0.00000000"], ["83778.96000000", "0.00000000"], ["83778.57000000", "0.00000000"], ["83777.85000000", "0.00000000"], ["83777.53000000", "0.00000000"], ["83777.10000000", "0.00000000"], ["83732.13000000", "0.00000000"], ["83725.26000000", "0.16519000"], ["83722.53000000", "0.00000000"], ["83716.87000000", "0.16519000"], ["83715.80000000", "0.00000000"], ["83714.14000000", "0.00000000"], ["83711.83000000", "0.00000000"], ["83708.48000000", "0.05646000"], ["83707.41000000", "0.00000000"], ["83705.75000000", "0.00000000"], ["83703.44000000", "0.00000000"], ["83699.46000000", "0.00000000"], ["83697.36000000", "0.00000000"], ["83696.37000000", "0.00000000"], ["83692.18000000", "0.00000000"], ["83517.39000000", "0.00000000"], ["83384.07000000", "0.00000000"], ["82883.63000000", "0.00000000"], ["82875.28000000", "0.40000000"], ["82721.52000000", "0.00000000"], ["82678.35000000", "0.00000000"], ["80606.38000000", "0.00000000"], ["80589.60000000", "0.00000000"], ["75551.08000000", "0.00064000"], ["75551.00000000", "0.10027000"], ["75546.58000000", "0.00000000"], ["67156.52000000", "0.00058000"], ["67149.94000000", "0.00000000"], ["42000.00000000", "6.84810000"], ["33000.00000000", "2.96666000"], ["30220.44000000", "0.00340000"], ["30219.14000000", "0.00020000"]], "a": [["83937.43000000", "0.00000000"], ["83937.44000000", "0.00000000"], ["83937.63000000", "0.00000000"], ["83937.72000000", "0.00000000"], ["83937.98000000", "0.00000000"], ["83938.57000000", "0.00000000"], ["83939.21000000", "0.00000000"], ["83940.60000000", "0.00000000"], ["83940.61000000", "0.00000000"], ["83940.62000000", "0.00000000"], ["83940.63000000", "0.00000000"], ["83941.08000000", "0.00000000"], ["83941.09000000", "0.00000000"], ["83941.59000000", "0.00000000"], ["83941.60000000", "0.00000000"], ["83941.61000000", "0.00000000"], ["83941.77000000", "0.00000000"], ["83941.78000000", "0.00000000"], ["83941.79000000", "0.00000000"], ["83941.80000000", "0.00000000"], ["83942.00000000", "0.00000000"], ["83942.01000000", "0.00000000"], ["83942.05000000", "0.00000000"], ["83942.06000000", "0.00000000"], ["83942.07000000", "0.00000000"], ["83943.15000000", "0.00000000"], ["83943.16000000", "0.00000000"], ["83944.00000000", "0.00000000"], ["83944.58000000", "0.00000000"], ["83944.59000000", "0.00000000"], ["83944.60000000", "0.00000000"], ["83945.07000000", "0.00000000"], ["83945.10000000", "0.00000000"], ["83945.11000000", "0.00000000"], ["83945.64000000", "0.00000000"], ["83945.65000000", "0.00000000"], ["83945.66000000", "0.07436000"], ["83945.67000000", "0.00047000"], ["83945.68000000", "0.00000000"], ["83945.69000000", "0.00000000"], ["83945.84000000", "0.00000000"], ["83946.00000000", "0.00000000"], ["83946.34000000", "0.00007000"], ["83946.36000000", "0.00000000"], ["83946.37000000", "0.00000000"], ["83946.55000000", "0.00000000"], ["83946.56000000", "0.00009000"], ["83946.57000000", "0.00000000"], ["83946.72000000", "0.00000000"], ["83947.46000000", "0.00000000"], ["83947.57000000", "0.00029000"], ["83947.58000000", "0.00046000"], ["83947.65000000", "0.00022000"], ["83947.66000000", "0.14907000"], ["83947.79000000", "0.00000000"], ["83947.96000000", "0.00000000"], ["83948.03000000", "0.00000000"], ["83948.34000000", "0.00000000"], ["83948.37000000", "0.00000000"], ["83949.05000000", "0.00000000"], ["83949.30000000", "0.00009000"], ["83949.31000000", "0.02391000"], ["83949.32000000", "0.00018000"], ["83949.33000000", "0.00000000"], ["83949.60000000", "0.00000000"], ["83949.90000000", "0.00500000"], ["83949.93000000", "0.00000000"], ["83949.94000000", "0.00000000"], ["83949.99000000", "0.00010000"], ["83950.00000000", "0.02751000"], ["83950.03000000", "0.00000000"], ["83950.04000000", "0.00000000"], ["83950.23000000", "0.00014000"], ["83950.24000000", "0.15640000"], ["83950.35000000", "0.00000000"], ["83950.48000000", "0.00000000"], ["83950.56000000", "0.00000000"], ["83950.57000000", "0.00000000"], ["83950.66000000", "0.00000000"], ["83950.67000000", "0.00000000"], ["83950.68000000", "0.00000000"], ["83950.91000000", "0.00000000"], ["83950.94000000", "0.00000000"], ["83950.95000000", "0.00000000"], ["83951.06000000", "0.00000000"], ["83951.15000000", "0.00000000"], ["83951.20000000", "0.00014000"], ["83951.21000000", "0.28985000"], ["83951.22000000", "0.00000000"], ["83951.37000000", "0.00000000"], ["83951.53000000", "0.00720000"], ["83951.78000000", "0.00000000"], ["83952.00000000", "0.00000000"], ["83952.35000000", "0.00119000"], ["83952.41000000", "0.28794000"], ["83952.63000000", "0.00000000"], ["83952.72000000", "0.00006000"], ["83952.74000000", "0.02201000"], ["83952.75000000", "0.00000000"], ["83952.84000000", "0.00029000"], ["83952.99000000", "0.00000000"], ["83953.38000000", "0.00000000"], ["83953.54000000", "0.00000000"], ["83953.80000000", "0.00013000"], ["83953.85000000", "0.32709000"], ["83954.04000000", "0.00000000"], ["83954.15000000", "0.00000000"], ["83954.23000000", "0.00000000"], ["83954.30000000", "0.00000000"], ["83954.35000000", "0.00000000"], ["83954.53000000", "0.00000000"], ["83954.76000000", "0.00000000"], ["83954.79000000", "0.00000000"], ["83954.98000000", "0.00000000"], ["83955.05000000", "0.00000000"], ["83955.15000000", "0.00000000"], ["83955.54000000", "0.00000000"], ["83955.99000000", "0.00000000"], ["83956.05000000", "0.03000000"], ["83956.14000000", "0.00000000"], ["83956.41000000", "0.00000000"], ["83956.66000000", "0.47650000"], ["83956.69000000", "0.21870000"], ["83956.73000000", "0.15529000"], ["83956.78000000", "0.10786000"], ["83956.82000000", "0.00000000"], ["83956.83000000", "0.00000000"], ["83956.92000000", "0.00000000"], ["83956.93000000", "0.00000000"], ["83956.95000000", "0.00000000"], ["83956.99000000", "0.00000000"], ["83957.17000000", "0.00000000"], ["83957.20000000", "0.00000000"], ["83957.36000000", "0.00000000"], ["83957.75000000", "0.00000000"], ["83957.94000000", "0.00000000"], ["83958.05000000", "0.49953000"], ["83958.26000000", "0.09600000"], ["83958.28000000", "0.00000000"], ["83958.30000000", "0.00000000"], ["83958.64000000", "0.00000000"], ["83958.84000000", "0.00000000"], ["83959.03000000", "0.00000000"], ["83959.07000000", "0.00000000"], ["83959.10000000", "0.06800000"], ["83959.28000000", "0.00000000"], ["83959.29000000", "0.00000000"], ["83959.95000000", "0.14400000"], ["83960.05000000", "0.06400000"], ["83960.12000000", "0.00119000"], ["83960.21000000", "0.00000000"], ["83960.22000000", "0.00000000"], ["83960.24000000", "0.00000000"], ["83960.28000000", "0.00000000"], ["83960.47000000", "0.78646000"], ["83960.56000000", "0.59562000"], ["83960.66000000", "0.00000000"], ["83961.24000000", "0.00000000"], ["83961.29000000", "0.00000000"], ["83961.35000000", "0.00000000"], ["83961.39000000", "0.00000000"], ["83961.90000000", "0.00000000"], ["83962.16000000", "0.00000000"], ["83962.22000000", "0.00000000"], ["83962.25000000", "0.00092000"], ["83962.46000000", "0.35737000"], ["83962.48000000", "0.00018000"], ["83962.62000000", "0.00096000"], ["83962.79000000", "0.06400000"], ["83962.90000000", "0.00000000"], ["83962.94000000", "0.00412000"], ["83963.02000000", "0.00000000"], ["83963.19000000", "0.00000000"], ["83963.31000000", "0.06000000"], ["83963.41000000", "0.02428000"], ["83963.79000000", "0.00000000"], ["83963.87000000", "0.00000000"], ["83963.97000000", "0.00000000"], ["83964.07000000", "0.00000000"], ["83964.15000000", "0.04800000"], ["83964.47000000", "0.05200000"], ["83964.57000000", "0.07200000"], ["83964.64000000", "0.01191000"], ["83965.07000000", "0.02000000"], ["83965.17000000", "0.00000000"], ["83965.35000000", "0.00000000"], ["83965.79000000", "0.00000000"], ["83965.99000000", "0.16412000"], ["83966.02000000", "0.00922000"], ["83966.37000000", "0.00000000"], ["83966.52000000", "1.55632000"], ["83966.57000000", "0.04000000"], ["83966.68000000", "0.00000000"], ["83966.71000000", "1.38765000"], ["83967.36000000", "0.00000000"], ["83967.37000000", "0.08000000"], ["83967.46000000", "0.00000000"], ["83968.12000000", "0.89344000"], ["83968.29000000", "0.00000000"], ["83968.33000000", "0.00000000"], ["83968.59000000", "0.00000000"], ["83969.36000000", "0.04000000"], ["83969.43000000", "0.89344000"], ["83970.34000000", "0.00000000"], ["83970.38000000", "0.00000000"], ["83970.42000000", "0.00000000"], ["83970.84000000", "0.05956000"], ["83971.82000000", "0.00000000"], ["83972.29000000", "0.00000000"], ["83972.53000000", "0.74243000"], ["83972.92000000", "0.00000000"], ["83973.92000000", "0.16000000"], ["83974.01000000", "0.89344000"], ["83974.31000000", "0.00000000"], ["83974.42000000", "0.47650000"], ["83975.90000000", "0.01191000"], ["83977.40000000", "0.89344000"], ["83977.62000000", "0.00000000"], ["83977.67000000", "0.00000000"], ["83977.97000000", "0.89344000"], ["83979.33000000", "0.00000000"], ["83979.34000000", "0.00000000"], ["83980.18000000", "0.00000000"], ["83980.37000000", "0.00000000"], ["83980.46000000", "0.00000000"], ["83980.49000000", "0.85775000"], ["83980.54000000", "0.00000000"], ["83984.63000000", "0.00000000"], ["83984.83000000", "0.00000000"], ["83985.03000000", "0.00000000"], ["83985.57000000", "0.00000000"], ["83986.43000000", "0.00000000"], ["83987.10000000", "0.00000000"], ["83987.94000000", "0.00000000"], ["83988.26000000", "1.02979000"], ["83988.34000000", "0.00000000"], ["83988.72000000", "0.85766000"], ["83989.49000000", "0.00000000"], ["83989.96000000", "0.00000000"], ["83990.39000000", "0.12088000"], ["83990.77000000", "0.00000000"], ["83991.30000000", "0.00000000"], ["83991.39000000", "0.03533000"], ["83992.05000000", "0.00000000"], ["83992.73000000", "0.59584000"], ["83992.76000000", "0.00000000"], ["83992.86000000", "0.00000000"], ["83993.46000000", "0.85762000"], ["83993.55000000", "0.00000000"], ["83993.59000000", "0.00000000"], ["83993.92000000", "0.00000000"], ["83994.19000000", "0.00000000"], ["83994.25000000", "0.08354000"], ["83995.05000000", "0.00000000"], ["83998.75000000", "0.05297000"], ["83998.89000000", "0.00000000"], ["83999.01000000", "0.00000000"], ["83999.36000000", "0.00000000"], ["83999.74000000", "0.00000000"], ["84000.60000000", "0.00000000"], ["84000.85000000", "0.89344000"], ["84001.00000000", "0.00000000"], ["84001.28000000", "0.00000000"], ["84002.65000000", "0.00000000"], ["84002.66000000", "0.00827000"], ["84002.74000000", "0.00000000"], ["84003.86000000", "0.01196000"], ["84004.38000000", "0.00000000"], ["84004.44000000", "0.00000000"], ["84004.46000000", "0.00000000"], ["84004.55000000", "1.09322000"], ["84004.99000000", "0.00859000"], ["84005.92000000", "0.00000000"], ["84007.09000000", "0.00000000"], ["84007.10000000", "0.00000000"], ["84008.32000000", "0.00000000"], ["84008.71000000", "0.00000000"], ["84009.41000000", "0.00000000"], ["84009.94000000", "0.00000000"], ["84010.00000000", "0.00000000"], ["84012.66000000", "0.00000000"], ["84012.86000000", "0.05339000"], ["84012.99000000", "0.00000000"], ["84014.27000000", "0.02808000"], ["84014.93000000", "0.00000000"], ["84016.01000000", "0.04159000"], ["84017.07000000", "0.00000000"], ["84017.29000000", "0.00000000"], ["84018.36000000", "0.00000000"], ["84020.00000000", "0.02600000"], ["84020.66000000", "0.00000000"], ["84021.69000000", "0.00000000"], ["84022.50000000", "0.00000000"], ["84022.60000000", "0.00000000"], ["84023.31000000", "0.00019000"], ["84024.27000000", "0.00000000"], ["84024.35000000", "0.00000000"], ["84025.26000000", "0.00000000"], ["84026.15000000", "0.00000000"], ["84027.58000000", "0.00000000"], ["84027.63000000", "0.00000000"], ["84028.47000000", "0.00000000"], ["84028.75000000", "0.04763000"], ["84028.78000000", "0.00000000"], ["84029.03000000", "0.00000000"], ["84030.09000000", "0.00000000"], ["84032.47000000", "0.00013000"], ["84032.63000000", "0.00000000"], ["84032.64000000", "0.94169000"], ["84034.09000000", "0.00000000"], ["84034.38000000", "0.00000000"], ["84034.46000000", "0.04762000"], ["84034.79000000", "0.00000000"], ["84035.02000000", "0.55670000"], ["84035.37000000", "0.00000000"], ["84035.78000000", "0.00000000"], ["84036.59000000", "0.00000000"], ["84037.71000000", "0.00000000"], ["84040.88000000", "0.04646000"], ["84041.96000000", "0.00000000"], ["84042.71000000", "0.00000000"], ["84045.96000000", "0.14506000"], ["84047.72000000", "0.00000000"], ["84047.89000000", "0.04646000"], ["84047.96000000", "0.00060000"], ["84047.98000000", "0.00000000"], ["84048.36000000", "0.00000000"], ["84048.96000000", "0.00000000"], ["84049.82000000", "0.04646000"], ["84050.94000000", "0.00000000"], ["84051.26000000", "0.00000000"], ["84051.68000000", "0.05241000"], ["84052.35000000", "0.00000000"], ["84052.95000000", "0.00000000"], ["84053.33000000", "0.00000000"], ["84053.76000000", "0.04646000"], ["84055.37000000", "0.04765000"], ["84055.84000000", "0.04765000"], ["84055.90000000", "0.04765000"], ["84056.47000000", "0.04498000"], ["84056.72000000", "0.09644000"], ["84057.27000000", "0.05098000"], ["84057.32000000", "0.04765000"], ["84057.60000000", "0.04765000"], ["84058.19000000", "0.00000000"], ["84058.37000000", "0.04765000"], ["84058.78000000", "0.00000000"], ["84059.01000000", "0.04646000"], ["84059.03000000", "0.04765000"], ["84059.40000000", "0.04765000"], ["84059.50000000", "0.12899000"], ["84059.93000000", "0.04498000"], ["84059.98000000", "0.04765000"], ["84060.15000000", "0.04765000"], ["84060.30000000", "0.00000000"], ["84060.35000000", "0.10262000"], ["84060.54000000", "0.04765000"], ["84061.36000000", "0.04765000"], ["84062.80000000", "0.04765000"], ["84062.83000000", "0.05098000"], ["84063.46000000", "0.75532000"], ["84064.30000000", "0.04498000"], ["84064.58000000", "0.00000000"], ["84065.05000000", "0.02383000"], ["84066.30000000", "0.10594000"], ["84066.49000000", "0.00000000"], ["84067.82000000", "0.05098000"], ["84067.88000000", "0.04498000"], ["84068.17000000", "0.04998000"], ["84069.63000000", "0.04998000"], ["84070.91000000", "0.05098000"], ["84071.57000000", "0.05011000"], ["84072.29000000", "0.04198000"], ["84072.47000000", "0.00000000"], ["84072.81000000", "0.04498000"], ["84073.94000000", "0.04998000"], ["84074.34000000", "0.05098000"], ["84076.91000000", "0.04498000"], ["84077.43000000", "0.05498000"], ["84077.50000000", "0.35566000"], ["84077.71000000", "0.04198000"], ["84077.92000000", "0.05098000"], ["84079.68000000", "0.04998000"], ["84080.34000000", "0.05498000"], ["84080.37000000", "0.05497000"], ["84080.49000000", "0.05498000"], ["84080.89000000", "0.04998000"], ["84080.96000000", "0.04498000"], ["84081.40000000", "0.05098000"], ["84082.31000000", "0.04198000"], ["84082.65000000", "0.05098000"], ["84082.85000000", "0.04998000"], ["84082.98000000", "0.05297000"], ["84086.85000000", "0.04498000"], ["84089.74000000", "0.04198000"], ["84089.82000000", "0.04198000"], ["84095.81000000", "0.04198000"], ["84095.82000000", "0.04198000"], ["84098.16000000", "0.00000000"], ["84099.13000000", "0.00000000"], ["84099.99000000", "0.00016000"], ["84128.98000000", "0.00000000"], ["84174.68000000", "0.00013000"], ["84178.87000000", "0.00013000"], ["84199.61000000", "0.45000000"], ["84236.39000000", "0.99193000"], ["84241.00000000", "0.12704000"], ["84245.45000000", "0.00000000"], ["84249.39000000", "0.03640000"], ["84253.84000000", "0.00000000"], ["84262.73000000", "0.00651000"], ["84318.62000000", "0.00000000"], ["84323.27000000", "0.00414000"], ["84909.54000000", "0.60000000"], ["84917.96000000", "0.00000000"], ["85196.50000000", "0.00000000"], ["85242.60000000", "0.00000000"], ["85263.90000000", "0.11746000"], ["85285.20000000", "0.05873000"]], "record_time": 1742577147.213338, "EXCHANGE": "BINANCE"}
{"e": "depthUpdate", "E": 1742577148014, "s": "BTCUSDT", "U": 64632183014, "u": 64632183252, "b": [["83945.65000000", "7.66543000"], ["83945.06000000", "0.18014000"], ["83944.75000000", "0.00021000"], ["83944.74000000", "0.16014000"], ["83944.63000000", "0.00014000"], ["83944.62000000", "0.70061000"], ["83944.58000000", "0.71077000"], ["83944.00000000", "0.01416000"], ["83942.92000000", "0.00058000"], ["83942.34000000", "0.04006000"], ["83942.32000000", "0.04263000"], ["83942.06000000", "0.23892000"], ["83942.05000000", "0.18524000"], ["83942.00000000", "0.03789000"], ["83941.99000000", "0.33163000"], ["83941.20000000", "0.00006000"], ["83939.48000000", "0.00119000"], ["83937.42000000", "0.45928000"], ["83937.25000000", "0.00300000"], ["83936.66000000", "0.23008000"], ["83935.99000000", "0.00000000"], ["83935.95000000", "0.00120000"], ["83935.41000000", "0.00000000"], ["83933.40000000", "0.00000000"], ["83932.80000000", "0.15888000"], ["83930.29000000", "0.00000000"], ["83927.17000000", "0.45221000"], ["83925.66000000", "0.12253000"], ["83924.55000000", "0.00000000"], ["83920.28000000", "0.00000000"], ["83919.11000000", "0.05000000"], ["83918.26000000", "0.00000000"], ["83917.01000000", "0.00000000"], ["83915.99000000", "0.05958000"], ["83915.40000000", "0.00000000"], ["83912.11000000", "0.00000000"], ["83910.53000000", "0.05760000"], ["83908.80000000", "0.48339000"], ["83905.30000000", "0.00000000"], ["83904.48000000", "0.00000000"], ["83899.19000000", "0.00000000"], ["83892.84000000", "0.00855000"], ["83889.06000000", "0.10000000"], ["83888.03000000", "0.04000000"], ["83881.32000000", "0.00061000"], ["83879.22000000", "0.00000000"], ["83876.76000000", "0.00000000"], ["83873.05000000", "0.00000000"], ["83861.40000000", "0.00000000"], ["83860.91000000", "0.00000000"], ["83859.17000000", "0.00000000"], ["83838.75000000", "0.00000000"], ["83827.79000000", "0.12000000"], ["83814.03000000", "1.17519000"], ["83797.74000000", "0.00000000"], ["83783.46000000", "0.01000000"], ["83780.85000000", "0.00000000"], ["83773.77000000", "0.00012000"], ["83745.27000000", "0.00127000"], ["83744.06000000", "0.00000000"], ["83733.04000000", "0.01865000"], ["83694.56000000", "0.00000000"], ["82686.46000000", "0.00100000"], ["75551.00000000", "0.10027000"], ["67156.52000000", "0.00058000"], ["42000.00000000", "6.84710000"], ["33000.00000000", "2.96666000"], ["30220.44000000", "0.00360000"]], "a": [["83945.66000000", "0.07403000"], ["83948.50000000", "0.00000000"], ["83949.90000000", "0.00000000"], ["83951.20000000", "0.00000000"], ["83951.21000000", "0.00000000"], ["83952.35000000", "0.00000000"], ["83952.39000000", "0.00014000"], ["83952.40000000", "0.26573000"], ["83952.71000000", "0.05866000"], ["83952.74000000", "0.05861000"], ["83953.85000000", "0.20178000"], ["83954.10000000", "0.00000000"], ["83955.18000000", "0.00119000"], ["83956.05000000", "0.00000000"], ["83956.69000000", "0.00000000"], ["83956.73000000", "0.00000000"], ["83958.24000000", "0.00174000"], ["83958.54000000", "0.03320000"], ["83958.60000000", "0.00000000"], ["83958.65000000", "0.00000000"], ["83958.73000000", "0.00000000"], ["83959.55000000", "0.03000000"], ["83960.42000000", "0.02419000"], ["83960.47000000", "0.00000000"], ["83960.69000000", "0.78645000"], ["83961.29000000", "0.15529000"], ["83962.79000000", "0.28270000"], ["83963.03000000", "0.00000000"], ["83963.06000000", "0.00000000"], ["83964.64000000", "0.00000000"], ["83965.07000000", "0.00000000"], ["83967.37000000", "0.10000000"], ["83969.36000000", "0.00000000"], ["83969.57000000", "0.29999000"], ["83970.85000000", "0.00300000"], ["83971.06000000", "0.04000000"], ["83971.48000000", "0.95007000"], ["83971.59000000", "0.01191000"], ["83973.58000000", "0.00000000"], ["83975.26000000", "1.00803000"], ["83984.13000000", "0.00000000"], ["83990.39000000", "0.00000000"], ["83992.74000000", "0.00000000"], ["83993.55000000", "0.05000000"], ["83993.58000000", "0.00000000"], ["83996.28000000", "0.12102000"], ["84000.34000000", "0.43491000"], ["84001.15000000", "0.01190000"], ["84004.86000000", "0.00470000"], ["84012.19000000", "0.00000000"], ["84013.82000000", "0.00000000"], ["84019.74000000", "0.00000000"], ["84019.75000000", "0.00000000"], ["84021.71000000", "0.06630000"], ["84024.96000000", "0.04110000"], ["84032.39000000", "0.00000000"], ["84035.00000000", "0.00000000"], ["84038.29000000", "0.00000000"], ["84039.43000000", "0.00000000"], ["84040.92000000", "0.00058000"], ["84041.07000000", "0.00000000"], ["84042.70000000", "0.00000000"], ["84045.33000000", "0.00000000"], ["84045.96000000", "0.09409000"], ["84047.02000000", "0.00000000"], ["84048.57000000", "0.00000000"], ["84049.72000000", "0.00000000"], ["84051.00000000", "0.00000000"], ["84051.21000000", "0.00000000"], ["84051.42000000", "0.00000000"], ["84053.63000000", "0.00000000"], ["84054.20000000", "0.00000000"], ["84054.22000000", "0.00000000"], ["84054.56000000", "0.00000000"], ["84055.70000000", "0.00000000"], ["84057.77000000", "0.15358000"], ["84057.78000000", "0.10261000"], ["84058.05000000", "0.04645000"], ["84058.99000000", "0.04764000"], ["84060.55000000", "0.09761000"], ["84061.53000000", "0.00000000"], ["84067.91000000", "0.05498000"], ["84068.16000000", "0.31485000"], ["84070.57000000", "0.04998000"], ["84071.09000000", "0.05498000"], ["84072.11000000", "0.04998000"], ["84073.10000000", "0.12040000"], ["84073.22000000", "0.04998000"], ["84073.87000000", "0.05497000"], ["84073.90000000", "0.05498000"], ["84074.88000000", "0.05098000"], ["84075.28000000", "0.04998000"], ["84077.36000000", "0.05498000"], ["84078.30000000", "0.05098000"], ["84080.52000000", "0.05498000"], ["84080.80000000", "0.05298000"], ["84081.40000000", "0.10196000"], ["84081.49000000", "0.04998000"], ["84082.91000000", "0.04498000"], ["84083.93000000", "0.05298000"], ["84084.17000000", "0.05098000"], ["84085.73000000", "0.04998000"], ["84089.43000000", "0.04498000"], ["84106.35000000", "0.00050000"], ["85204.85000000", "0.00100000"]], "record_time": 1742577148.213338, "EXCHANGE": "BINANCE"}
{"e": "depthUpdate", "E": 1742577149014, "s": "BTCUSDT", "U": 64632183253, "u": 64632184107, "b": [["83945.65000000", "1.11310000"], ["83945.64000000", "0.00047000"], ["83945.61000000", "0.00007000"], ["83945.60000000", "0.00007000"], ["83945.51000000", "0.00007000"], ["83945.40000000", "0.00013000"], ["83945.07000000", "0.00007000"], ["83945.06000000", "0.00007000"], ["83944.79000000", "0.00000000"], ["83944.75000000", "0.00000000"], ["83944.74000000", "0.00000000"], ["83944.69000000", "0.00000000"], ["83944.67000000", "0.00007000"], ["83944.63000000", "0.00000000"], ["83944.62000000", "0.00000000"], ["83944.59000000", "0.00000000"], ["83944.58000000", "0.00182000"], ["83944.30000000", "0.00000000"], ["83944.29000000", "0.00000000"], ["83944.15000000", "0.00000000"], ["83944.12000000", "0.00000000"], ["83944.10000000", "0.00000000"], ["83944.01000000", "0.00014000"], ["83944.00000000", "0.01423000"], ["83943.59000000", "0.00000000"], ["83943.16000000", "0.00000000"], ["83943.10000000", "0.00000000"], ["83943.00000000", "0.00000000"], ["83942.99000000", "0.00000000"], ["83942.92000000", "0.00000000"], ["83942.56000000", "0.00000000"], ["83942.52000000", "0.00014000"], ["83942.51000000", "0.02392000"], ["83942.50000000", "0.00014000"], ["83942.49000000", "0.02013000"], ["83942.40000000", "0.00014000"], ["83942.39000000", "0.04007000"], ["83942.34000000", "0.00000000"], ["83942.32000000", "0.00000000"], ["83942.20000000", "0.00000000"], ["83942.16000000", "0.00000000"], ["83942.10000000", "0.00007000"], ["83942.09000000", "0.08000000"], ["83942.07000000", "0.00000000"], ["83942.06000000", "0.15982000"], ["83942.05000000", "0.00101000"], ["83941.99000000", "0.00000000"], ["83941.88000000", "0.00000000"], ["83941.75000000", "0.05364000"], ["83941.69000000", "0.00000000"], ["83941.51000000", "0.00000000"], ["83941.37000000", "0.00000000"], ["83941.26000000", "0.05305000"], ["83941.02000000", "0.00000000"], ["83940.71000000", "0.00000000"], ["83940.69000000", "0.00000000"], ["83940.67000000", "0.00000000"], ["83940.64000000", "0.00000000"], ["83940.60000000", "0.00500000"], ["83940.59000000", "0.00000000"], ["83940.15000000", "0.02214000"], ["83940.09000000", "0.00500000"], ["83939.98000000", "0.00000000"], ["83939.48000000", "0.00000000"], ["83939.41000000", "0.00000000"], ["83938.88000000", "0.01000000"], ["83938.81000000", "0.15951000"], ["83938.35000000", "0.00000000"], ["83938.29000000", "0.01000000"], ["83938.16000000", "0.00000000"], ["83937.74000000", "0.00000000"], ["83937.73000000", "0.00119000"], ["83937.63000000", "0.47650000"], ["83937.42000000", "0.45506000"], ["83937.31000000", "0.00000000"], ["83937.30000000", "0.03407000"], ["83936.66000000", "0.32122000"], ["83936.48000000", "0.00000000"], ["83936.46000000", "0.00000000"], ["83936.38000000", "0.00000000"], ["83936.16000000", "0.05621000"], ["83935.95000000", "0.00000000"], ["83935.73000000", "0.00000000"], ["83935.43000000", "0.00095000"], ["83935.21000000", "0.00000000"], ["83935.20000000", "0.00000000"], ["83935.18000000", "0.00000000"], ["83935.04000000", "0.16000000"], ["83934.28000000", "0.00000000"], ["83933.75000000", "0.20407000"], ["83933.44000000", "0.00000000"], ["83933.25000000", "0.10786000"], ["83933.21000000", "0.00411000"], ["83932.80000000", "0.00086000"], ["83932.02000000", "0.00000000"], ["83932.01000000", "0.00000000"], ["83931.91000000", "0.78110000"], ["83930.93000000", "0.00000000"], ["83930.75000000", "0.00000000"], ["83930.16000000", "0.59562000"], ["83929.70000000", "0.00595000"], ["83929.43000000", "0.00000000"], ["83928.85000000", "0.00000000"], ["83928.73000000", "0.00119000"], ["83928.68000000", "0.15046000"], ["83928.43000000", "0.00000000"], ["83928.10000000", "0.00000000"], ["83927.79000000", "0.00000000"], ["83927.17000000", "0.00000000"], ["83927.08000000", "1.37079000"], ["83926.57000000", "0.00000000"], ["83926.01000000", "0.00000000"], ["83925.77000000", "1.00000000"], ["83925.66000000", "0.00000000"], ["83925.38000000", "0.00120000"], ["83925.31000000", "0.00000000"], ["83924.32000000", "0.00000000"], ["83922.98000000", "0.00000000"], ["83922.94000000", "0.09134000"], ["83922.71000000", "0.00000000"], ["83922.07000000", "0.00000000"], ["83921.52000000", "0.00000000"], ["83920.72000000", "0.00000000"], ["83920.46000000", "0.05956000"], ["83920.14000000", "0.00000000"], ["83920.01000000", "0.00000000"], ["83919.58000000", "0.00000000"], ["83919.11000000", "0.00000000"], ["83917.30000000", "0.11669000"], ["83917.25000000", "0.59592000"], ["83915.99000000", "0.00000000"], ["83914.14000000", "0.45221000"], ["83912.73000000", "0.00000000"], ["83912.55000000", "0.00000000"], ["83910.53000000", "0.00000000"], ["83909.98000000", "0.00000000"], ["83903.98000000", "0.00000000"], ["83903.45000000", "0.05835000"], ["83900.41000000", "0.00000000"], ["83898.30000000", "0.00000000"], ["83897.91000000", "0.70246000"], ["83896.99000000", "0.00000000"], ["83892.38000000", "0.59562000"], ["83889.06000000", "0.00000000"], ["83885.68000000", "0.04440000"], ["83882.38000000", "0.00000000"], ["83881.32000000", "0.00000000"], ["83879.83000000", "0.04490000"], ["83877.10000000", "0.00061000"], ["83870.57000000", "0.00000000"], ["83866.23000000", "0.00000000"], ["83865.60000000", "0.03594000"], ["83864.79000000", "0.00060000"], ["83862.62000000", "0.00000000"], ["83853.30000000", "0.00000000"], ["83846.12000000", "0.00060000"], ["83845.50000000", "0.12899000"], ["83843.95000000", "0.00000000"], ["83838.75000000", "0.10000000"], ["83831.49000000", "0.00083000"], ["83826.99000000", "0.00000000"], ["83823.08000000", "0.00000000"], ["83818.31000000", "0.65369000"], ["83805.67000000", "0.00000000"], ["83800.31000000", "0.00000000"], ["83788.04000000", "0.00000000"], ["83783.46000000", "0.00000000"], ["83782.32000000", "0.00000000"], ["83780.84000000", "0.00000000"], ["83780.77000000", "0.01000000"], ["83780.01000000", "0.00000000"], ["83771.98000000", "0.00400000"], ["83771.13000000", "0.00000000"], ["83767.69000000", "0.00839000"], ["83755.84000000", "0.00069000"], ["83747.44000000", "0.00000000"], ["83734.97000000", "0.00000000"], ["83733.04000000", "0.00000000"], ["83732.65000000", "0.01786000"], ["83549.45000000", "0.34774000"], ["82686.47000000", "0.00007000"], ["82686.46000000", "0.00000000"], ["80589.60000000", "0.03571000"], ["75551.00000000", "0.10027000"], ["67156.52000000", "0.00058000"], ["33000.00000000", "2.96666000"], ["30220.44000000", "0.00380000"]], "a": [["83945.66000000", "4.57048000"], ["83946.34000000", "0.00000000"], ["83946.96000000", "0.00000000"], ["83946.97000000", "0.00000000"], ["83947.05000000", "0.00014000"], ["83947.06000000", "0.10817000"], ["83947.07000000", "0.00000000"], ["83947.08000000", "0.00000000"], ["83947.27000000", "0.00000000"], ["83947.33000000", "0.00981000"], ["83947.42000000", "0.00014000"], ["83947.43000000", "0.18613000"], ["83947.55000000", "0.00000000"], ["83947.56000000", "0.00000000"], ["83947.64000000", "0.00000000"], ["83947.65000000", "0.00008000"], ["83947.66000000", "0.14907000"], ["83948.01000000", "0.00007000"], ["83948.15000000", "0.00000000"], ["83948.16000000", "0.00000000"], ["83948.62000000", "0.00000000"], ["83948.63000000", "0.00000000"], ["83949.08000000", "0.00014000"], ["83949.09000000", "0.78662000"], ["83949.19000000", "0.00000000"], ["83949.20000000", "0.00000000"], ["83949.30000000", "0.00000000"], ["83949.31000000", "0.02391000"], ["83949.65000000", "0.02354000"], ["83949.90000000", "0.01000000"], ["83949.97000000", "0.00000000"], ["83949.99000000", "0.00000000"], ["83950.00000000", "0.02745000"], ["83950.23000000", "0.00000000"], ["83950.24000000", "0.00000000"], ["83950.47000000", "0.00000000"], ["83950.48000000", "0.00000000"], ["83951.51000000", "0.00000000"], ["83951.67000000", "0.00000000"], ["83952.37000000", "0.00862000"], ["83952.39000000", "0.00000000"], ["83952.40000000", "0.25010000"], ["83952.41000000", "0.00000000"], ["83952.71000000", "0.00000000"], ["83952.74000000", "0.00000000"], ["83953.14000000", "0.16412000"], ["83953.41000000", "0.17899000"], ["83953.42000000", "0.08473000"], ["83953.43000000", "0.00000000"], ["83953.85000000", "0.31155000"], ["83954.06000000", "0.45000000"], ["83954.37000000", "0.00000000"], ["83955.18000000", "0.00000000"], ["83955.25000000", "0.00000000"], ["83956.29000000", "0.00415000"], ["83956.98000000", "0.00000000"], ["83958.05000000", "0.49734000"], ["83958.24000000", "0.01191000"], ["83958.54000000", "0.00000000"], ["83958.71000000", "0.00000000"], ["83958.84000000", "0.00119000"], ["83960.12000000", "0.00000000"], ["83960.31000000", "0.00000000"], ["83960.69000000", "0.00000000"], ["83961.08000000", "0.71399000"], ["83961.29000000", "0.00000000"], ["83962.25000000", "0.00000000"], ["83962.62000000", "0.00000000"], ["83962.79000000", "0.06400000"], ["83962.94000000", "0.00000000"], ["83964.16000000", "0.89344000"], ["83964.17000000", "0.03574000"], ["83965.99000000", "0.00000000"], ["83966.02000000", "0.00000000"], ["83966.27000000", "0.00000000"], ["83966.71000000", "0.00000000"], ["83967.89000000", "0.00000000"], ["83969.57000000", "0.00000000"], ["83971.48000000", "1.58351000"], ["83972.30000000", "0.85783000"], ["83973.46000000", "0.00000000"], ["83974.28000000", "1.39036000"], ["83975.86000000", "0.00891000"], ["83976.54000000", "0.85779000"], ["83979.99000000", "0.00000000"], ["83980.74000000", "0.00000000"], ["83981.88000000", "0.85773000"], ["83983.49000000", "0.00000000"], ["83984.23000000", "0.00000000"], ["83985.20000000", "0.04110000"], ["83985.59000000", "0.59590000"], ["83985.81000000", "0.11353000"], ["83987.41000000", "0.05815000"], ["83988.72000000", "0.00000000"], ["83989.55000000", "0.00000000"], ["83990.02000000", "0.00000000"], ["83990.23000000", "0.04159000"], ["83991.59000000", "0.37755000"], ["83992.73000000", "0.00000000"], ["83993.46000000", "0.00000000"], ["83993.55000000", "0.00000000"], ["83993.76000000", "0.19168000"], ["83994.89000000", "0.00000000"], ["83995.09000000", "0.00000000"], ["83996.28000000", "0.00000000"], ["83997.07000000", "0.00000000"], ["83998.81000000", "0.00000000"], ["84004.47000000", "0.41723000"], ["84005.72000000", "0.00000000"], ["84014.27000000", "0.00000000"], ["84016.01000000", "0.00000000"], ["84024.96000000", "0.00000000"], ["84026.27000000", "0.12899000"], ["84059.50000000", "0.00000000"], ["84128.91000000", "0.00000000"], ["84131.68000000", "0.99038000"], ["84148.68000000", "0.00000000"], ["84236.39000000", "0.00000000"], ["85204.85000000", "0.00000000"], ["85242.60000000", "0.11747000"], ["85263.90000000", "0.05873000"], ["85285.20000000", "0.00000000"], ["85431.03000000", "0.00028000"], ["85437.01000000", "0.00000000"], ["85448.85000000", "0.00060000"], ["85454.83000000", "0.00060000"]], "record_time": 1742577149.2124, "EXCHANGE": "BINANCE"}
