{"e": "depthUpdate", "E": 1742554967014, "s": "BTCUSDT", "U": 64607015676, "u": 64607016270, "b": [["84099.85000000", "5.73085000"], ["84099.67000000", "0.00015000"], ["84098.80000000", "0.00021000"], ["84098.79000000", "0.44982000"], ["84098.78000000", "0.00007000"], ["84098.77000000", "0.00007000"], ["84098.76000000", "0.00021000"], ["84098.75000000", "0.78529000"], ["84098.74000000", "0.00000000"], ["84098.00000000", "0.02267000"], ["84097.77000000", "0.00006000"], ["84096.27000000", "0.02380000"], ["84096.11000000", "0.00000000"], ["84096.09000000", "0.00000000"], ["84096.00000000", "0.02266000"], ["84095.85000000", "0.00000000"], ["84095.84000000", "0.00000000"], ["84094.60000000", "0.04006000"], ["84094.59000000", "0.46858000"], ["84094.58000000", "0.00000000"], ["84094.56000000", "0.00000000"], ["84094.55000000", "0.00000000"], ["84094.52000000", "0.00000000"], ["84094.00000000", "0.02266000"], ["84093.76000000", "0.04000000"], ["84092.93000000", "0.04000000"], ["84092.92000000", "0.04000000"], ["84092.40000000", "0.00006000"], ["84092.32000000", "0.04000000"], ["84091.44000000", "0.00300000"], ["84090.92000000", "0.47862000"], ["84090.41000000", "0.00026000"], ["84090.40000000", "0.04000000"], ["84090.09000000", "0.00008000"], ["84090.08000000", "0.00000000"], ["84089.56000000", "0.04000000"], ["84088.75000000", "0.19405000"], ["84088.74000000", "0.35644000"], ["84088.72000000", "0.04000000"], ["84088.64000000", "0.04000000"], ["84087.97000000", "0.00000000"], ["84087.16000000", "0.00000000"], ["84087.12000000", "0.00000000"], ["84086.33000000", "0.00000000"], ["84086.25000000", "0.00000000"], ["84086.03000000", "0.82440000"], ["84085.88000000", "0.00000000"], ["84085.10000000", "0.00000000"], ["84084.12000000", "0.00000000"], ["84083.41000000", "0.00000000"], ["84082.96000000", "0.00000000"], ["84082.70000000", "0.00000000"], ["84082.69000000", "0.00000000"], ["84082.33000000", "1.00000000"], ["84082.12000000", "0.00000000"], ["84082.01000000", "1.18674000"], ["84082.00000000", "1.32442000"], ["84081.96000000", "0.00000000"], ["84080.47000000", "0.00000000"], ["84079.38000000", "0.00000000"], ["84078.36000000", "0.00000000"], ["84076.32000000", "0.00000000"], ["84073.64000000", "0.00013000"], ["84072.94000000", "0.85681000"], ["84071.06000000", "0.00000000"], ["84069.88000000", "0.05071000"], ["84069.44000000", "0.00000000"], ["84069.39000000", "0.00000000"], ["84069.02000000", "1.27150000"], ["84069.00000000", "0.00000000"], ["84068.67000000", "0.85685000"], ["84068.50000000", "0.04000000"], ["84068.37000000", "0.00000000"], ["84066.54000000", "0.00000000"], ["84065.69000000", "0.00000000"], ["84064.33000000", "0.04942000"], ["84058.46000000", "0.30079000"], ["84057.80000000", "0.00059000"], ["84050.19000000", "0.00000000"], ["84048.87000000", "0.00000000"], ["84042.15000000", "0.04000000"], ["84036.37000000", "0.04000000"], ["84033.43000000", "0.00000000"], ["84023.39000000", "0.00000000"], ["84009.10000000", "0.00000000"], ["83983.85000000", "0.00000000"], ["83978.11000000", "0.00000000"], ["83975.90000000", "0.00000000"], ["83973.68000000", "0.00000000"], ["83971.37000000", "0.18316000"], ["83967.63000000", "0.00400000"], ["83967.12000000", "0.00000000"], ["83965.41000000", "0.12863000"], ["83959.16000000", "0.00000000"], ["83943.37000000", "0.00000000"], ["83943.36000000", "0.00000000"], ["83941.41000000", "0.00000000"], ["83935.14000000", "0.01000000"], ["83931.75000000", "0.00000000"], ["83930.74000000", "0.00000000"], ["83929.34000000", "0.00000000"], ["83928.15000000", "0.00000000"], ["83837.12000000", "0.00000000"], ["83761.35000000", "0.00000000"], ["83656.37000000", "0.00000000"], ["83042.35000000", "0.00042000"], ["82829.55000000", "0.00000000"], ["80697.27000000", "0.03567000"], ["79800.00000000", "8.29832000"], ["75689.00000000", "0.54435000"], ["67279.88000000", "0.00058000"], ["33000.00000000", "2.93827000"]], "a": [["84099.86000000", "2.69239000"], ["84099.98000000", "0.00008000"], ["84100.15000000", "0.00014000"], ["84100.16000000", "0.12036000"], ["84100.17000000", "0.00020000"], ["84100.18000000", "0.25685000"], ["84100.52000000", "0.00000000"], ["84100.84000000", "0.00000000"], ["84101.24000000", "0.00000000"], ["84101.25000000", "0.10171000"], ["84101.59000000", "0.00000000"], ["84101.60000000", "0.00000000"], ["84101.79000000", "0.00000000"], ["84102.24000000", "0.00000000"], ["84102.25000000", "0.00000000"], ["84102.63000000", "0.00007000"], ["84102.70000000", "0.00000000"], ["84102.72000000", "0.00000000"], ["84102.93000000", "0.00000000"], ["84103.01000000", "0.00000000"], ["84103.11000000", "0.00000000"], ["84103.15000000", "0.00000000"], ["84103.16000000", "0.00006000"], ["84103.44000000", "0.02382000"], ["84104.37000000", "0.00006000"], ["84104.71000000", "0.00000000"], ["84104.90000000", "0.00000000"], ["84104.91000000", "0.00000000"], ["84105.31000000", "0.02473000"], ["84105.99000000", "0.09927000"], ["84106.00000000", "0.02260000"], ["84106.54000000", "0.00000000"], ["84106.55000000", "0.00000000"], ["84106.56000000", "0.00000000"], ["84106.57000000", "0.00000000"], ["84106.59000000", "0.00000000"], ["84106.83000000", "0.00011000"], ["84107.23000000", "0.30804000"], ["84107.54000000", "0.00000000"], ["84107.74000000", "0.40057000"], ["84108.00000000", "0.02260000"], ["84108.27000000", "0.00000000"], ["84108.30000000", "0.00000000"], ["84108.36000000", "0.00000000"], ["84108.39000000", "0.00000000"], ["84109.09000000", "0.00000000"], ["84109.90000000", "0.04817000"], ["84110.25000000", "0.00000000"], ["84110.91000000", "0.00000000"], ["84110.96000000", "0.00000000"], ["84110.97000000", "0.00000000"], ["84110.98000000", "0.03568000"], ["84111.45000000", "0.09081000"], ["84112.16000000", "0.00000000"], ["84112.53000000", "0.00000000"], ["84113.11000000", "0.00000000"], ["84113.28000000", "0.04000000"], ["84113.44000000", "0.00000000"], ["84114.12000000", "0.04000000"], ["84114.46000000", "0.00000000"], ["84114.90000000", "0.10703000"], ["84114.97000000", "0.10000000"], ["84115.05000000", "0.05200000"], ["84115.22000000", "0.00000000"], ["84115.97000000", "0.08304000"], ["84116.45000000", "0.00000000"], ["84117.49000000", "0.07600000"], ["84117.58000000", "0.85635000"], ["84117.59000000", "0.00000000"], ["84117.90000000", "0.01189000"], ["84118.32000000", "0.07200000"], ["84119.08000000", "0.00898000"], ["84119.17000000", "0.12800000"], ["84119.25000000", "0.06000000"], ["84119.44000000", "0.00000000"], ["84120.82000000", "1.69826000"], ["84121.02000000", "0.05940000"], ["84122.06000000", "0.00000000"], ["84122.25000000", "0.00000000"], ["84122.91000000", "0.85630000"], ["84123.56000000", "0.53464000"], ["84125.09000000", "0.00372000"], ["84125.95000000", "1.35194000"], ["84126.54000000", "0.01189000"], ["84127.54000000", "0.00000000"], ["84127.69000000", "0.00000000"], ["84128.53000000", "0.00000000"], ["84131.96000000", "0.85620000"], ["84132.98000000", "0.00000000"], ["84133.58000000", "0.00000000"], ["84133.66000000", "0.00000000"], ["84134.85000000", "0.00000000"], ["84138.14000000", "0.00000000"], ["84139.48000000", "0.00000000"], ["84141.91000000", "0.00059000"], ["84145.18000000", "0.05914000"], ["84146.49000000", "0.00000000"], ["84150.34000000", "0.00000000"], ["84155.87000000", "0.00000000"], ["84158.48000000", "0.03451000"], ["84163.60000000", "0.00000000"], ["84171.64000000", "0.00000000"], ["84172.81000000", "0.00041000"], ["84173.26000000", "0.00000000"], ["84176.57000000", "0.00000000"], ["84180.76000000", "0.05200000"], ["84186.89000000", "0.00000000"], ["84188.02000000", "0.20149000"], ["84188.33000000", "0.04000000"], ["84189.17000000", "0.04000000"], ["84192.52000000", "0.00000000"], ["84192.53000000", "0.00000000"], ["84194.28000000", "0.06000000"], ["84195.20000000", "0.06400000"], ["84196.78000000", "0.00000000"], ["84225.28000000", "0.00000000"], ["84248.60000000", "0.00035000"], ["84261.14000000", "0.00000000"], ["84263.26000000", "0.00000000"], ["84264.34000000", "0.00294000"], ["84265.61000000", "0.00000000"], ["84265.97000000", "0.00000000"], ["84267.10000000", "0.00000000"], ["84267.45000000", "0.00000000"], ["84272.56000000", "0.99988000"], ["84285.11000000", "0.00000000"], ["84336.60000000", "0.00000000"], ["84338.87000000", "0.00000000"], ["84384.85000000", "0.00000000"], ["84426.51000000", "0.00000000"], ["84434.17000000", "0.00000000"], ["84437.02000000", "0.00000000"], ["84500.00000000", "5.76870000"], ["84549.18000000", "0.00000000"], ["85361.36000000", "0.00100000"], ["87000.00000000", "34.35954000"]], "record_time": 1742554967.036364, "EXCHANGE": "BINANCE"}
{"e": "depthUpdate", "E": 1742554968014, "s": "BTCUSDT", "U": 64607016271, "u": 64607016504, "b": [["84099.85000000", "5.07812000"], ["84099.67000000", "0.00015000"], ["84099.55000000", "0.00021000"], ["84099.54000000", "0.01532000"], ["84098.79000000", "0.14824000"], ["84098.78000000", "0.00007000"], ["84098.77000000", "0.00000000"], ["84098.76000000", "0.00000000"], ["84098.75000000", "0.00006000"], ["84098.43000000", "0.00014000"], ["84098.00000000", "0.02267000"], ["84097.77000000", "0.00006000"], ["84096.70000000", "0.00000000"], ["84096.66000000", "0.02405000"], ["84095.60000000", "0.01000000"], ["84094.08000000", "0.00000000"], ["84094.00000000", "0.02260000"], ["84089.41000000", "0.00091000"], ["84089.23000000", "0.00000000"], ["84086.70000000", "0.00000000"], ["84085.12000000", "0.00000000"], ["84084.77000000", "0.02378000"], ["84083.93000000", "0.05945000"], ["84083.42000000", "0.00000000"], ["84083.26000000", "0.00000000"], ["84083.03000000", "0.71284000"], ["84081.62000000", "0.16000000"], ["84079.00000000", "0.18274000"], ["84074.62000000", "0.05940000"], ["84061.37000000", "0.00000000"], ["84059.10000000", "0.00000000"], ["84055.85000000", "0.40886000"], ["84054.42000000", "0.01518000"], ["84003.61000000", "0.00000000"], ["83967.63000000", "0.00000000"], ["83962.11000000", "0.00000000"], ["83951.87000000", "0.00000000"], ["83945.31000000", "0.00400000"], ["83931.76000000", "0.99313000"], ["83918.67000000", "0.01862000"], ["83878.73000000", "0.00678000"], ["83878.56000000", "0.00000000"], ["83696.15000000", "0.00000000"], ["83682.90000000", "1.18957000"], ["83275.57000000", "0.00000000"], ["83262.38000000", "1.78437000"], ["83069.99000000", "0.02346000"], ["82854.99000000", "0.00000000"], ["82841.87000000", "0.59478000"], ["82838.35000000", "0.00100000"], ["79800.00000000", "8.29820000"], ["75689.86000000", "0.00032000"], ["75689.00000000", "0.54435000"], ["67279.88000000", "0.00058000"], ["33000.00000000", "2.93827000"]], "a": [["84099.86000000", "3.20951000"], ["84101.79000000", "0.00007000"], ["84102.63000000", "0.00000000"], ["84102.85000000", "0.00015000"], ["84107.29000000", "0.01518000"], ["84107.74000000", "0.38612000"], ["84108.27000000", "0.45000000"], ["84108.58000000", "0.00058000"], ["84109.90000000", "0.00000000"], ["84111.07000000", "0.17822000"], ["84112.21000000", "0.00000000"], ["84118.96000000", "0.01862000"], ["84135.12000000", "0.12837000"], ["84137.33000000", "0.79422000"], ["84146.94000000", "0.01518000"], ["84148.34000000", "0.00000000"], ["84149.18000000", "0.00000000"], ["84149.56000000", "0.00678000"], ["84149.74000000", "0.00000000"], ["84155.79000000", "0.03609000"], ["84169.22000000", "0.00000000"], ["84173.23000000", "0.06000000"], ["84178.23000000", "0.00000000"], ["84185.94000000", "0.00841000"], ["84190.74000000", "0.00000000"], ["84238.70000000", "0.00000000"], ["84436.26000000", "0.00008000"], ["84523.92000000", "1.18957000"], ["84537.31000000", "0.00000000"], ["84944.44000000", "1.78437000"], ["84957.89000000", "0.00000000"], ["85361.36000000", "0.00000000"], ["85364.96000000", "0.59478000"], ["85370.40000000", "0.14083000"], ["85378.48000000", "0.00000000"], ["85550.00000000", "0.00131000"]], "record_time": 1742554968.043515, "EXCHANGE": "BINANCE"}
{"e": "depthUpdate", "E": 1742554969014, "s": "BTCUSDT", "U": 64607016505, "u": 64607016930, "b": [["84099.85000000", "3.27124000"], ["84099.84000000", "0.00049000"], ["84099.83000000", "0.00007000"], ["84099.67000000", "0.00015000"], ["84099.66000000", "0.00007000"], ["84099.55000000", "0.00007000"], ["84099.54000000", "0.00007000"], ["84098.81000000", "0.00021000"], ["84098.80000000", "0.10780000"], ["84098.79000000", "0.00006000"], ["84098.78000000", "0.00000000"], ["84098.75000000", "0.00000000"], ["84098.43000000", "0.00000000"], ["84098.42000000", "0.00007000"], ["84098.20000000", "0.00000000"], ["84098.00000000", "0.02267000"], ["84097.77000000", "0.00000000"], ["84097.02000000", "0.00000000"], ["84096.69000000", "0.00014000"], ["84096.68000000", "0.08988000"], ["84096.66000000", "0.00000000"], ["84096.54000000", "0.00000000"], ["84096.51000000", "0.00006000"], ["84096.50000000", "0.00756000"], ["84096.37000000", "0.02080000"], ["84096.27000000", "0.02374000"], ["84096.00000000", "0.02260000"], ["84095.74000000", "0.00000000"], ["84095.73000000", "0.15633000"], ["84094.62000000", "0.00014000"], ["84094.61000000", "0.78520000"], ["84094.60000000", "0.00000000"], ["84094.59000000", "0.56438000"], ["84094.49000000", "0.00011000"], ["84093.99000000", "0.01518000"], ["84093.85000000", "0.00000000"], ["84093.76000000", "0.00000000"], ["84092.93000000", "0.00000000"], ["84092.92000000", "0.00000000"], ["84092.79000000", "0.00000000"], ["84092.07000000", "0.00000000"], ["84092.04000000", "0.00000000"], ["84091.68000000", "0.00000000"], ["84091.56000000", "0.00000000"], ["84091.44000000", "0.45300000"], ["84090.40000000", "0.00000000"], ["84090.19000000", "0.00000000"], ["84090.01000000", "0.04000000"], ["84089.56000000", "0.00000000"], ["84089.24000000", "0.00410000"], ["84089.18000000", "0.04000000"], ["84088.72000000", "0.00000000"], ["84088.71000000", "0.00000000"], ["84088.64000000", "0.00000000"], ["84088.45000000", "0.00089000"], ["84088.42000000", "0.00095000"], ["84088.14000000", "0.10703000"], ["84087.54000000", "0.00000000"], ["84086.90000000", "0.04000000"], ["84086.44000000", "0.00000000"], ["84085.81000000", "0.04000000"], ["84085.35000000", "0.16429000"], ["84085.08000000", "0.00000000"], ["84084.77000000", "0.00000000"], ["84084.05000000", "0.04000000"], ["84083.93000000", "0.00000000"], ["84083.75000000", "0.00000000"], ["84083.74000000", "0.00000000"], ["84083.73000000", "0.00000000"], ["84083.60000000", "0.59407000"], ["84083.33000000", "0.00000000"], ["84083.03000000", "0.00000000"], ["84083.02000000", "0.00000000"], ["84082.94000000", "0.00000000"], ["84082.89000000", "0.00000000"], ["84082.83000000", "0.00000000"], ["84082.38000000", "0.08000000"], ["84082.35000000", "0.00118000"], ["84082.01000000", "0.86725000"], ["84081.62000000", "0.00000000"], ["84081.51000000", "0.00000000"], ["84079.84000000", "0.00000000"], ["84079.25000000", "0.00000000"], ["84078.02000000", "0.00000000"], ["84077.14000000", "0.00000000"], ["84076.12000000", "0.00000000"], ["84075.02000000", "0.16000000"], ["84074.71000000", "0.00000000"], ["84074.38000000", "0.11636000"], ["84072.94000000", "0.00000000"], ["84071.21000000", "0.04000000"], ["84066.51000000", "0.05945000"], ["84065.25000000", "0.85688000"], ["84064.79000000", "0.00000000"], ["84064.33000000", "0.00000000"], ["84063.26000000", "0.85690000"], ["84060.57000000", "0.59490000"], ["84060.02000000", "0.00000000"], ["84056.99000000", "0.00000000"], ["84053.11000000", "0.04942000"], ["84047.86000000", "0.25004000"], ["84047.27000000", "0.00000000"], ["84046.42000000", "0.47526000"], ["84045.75000000", "0.59407000"], ["84022.13000000", "0.00000000"], ["84021.10000000", "0.00000000"], ["84019.81000000", "0.00000000"], ["84016.42000000", "0.04000000"], ["84014.68000000", "0.04000000"], ["84012.49000000", "0.00100000"], ["84009.87000000", "0.53747000"], ["84008.79000000", "0.00000000"], ["83945.31000000", "0.00000000"], ["83939.57000000", "0.00000000"], ["83935.14000000", "0.01000000"], ["83930.34000000", "0.00000000"], ["83920.29000000", "0.00000000"], ["83918.67000000", "0.00000000"], ["83914.40000000", "0.00400000"], ["83003.26000000", "0.40000000"], ["82994.90000000", "0.00000000"], ["82838.35000000", "0.00000000"], ["80697.27000000", "0.00000000"], ["75689.00000000", "0.54435000"], ["67279.88000000", "0.00058000"], ["60000.00000000", "73.17018000"], ["33000.00000000", "2.93827000"], ["30275.95000000", "0.00040000"]], "a": [["84099.86000000", "4.17190000"], ["84100.16000000", "0.12042000"], ["84100.17000000", "0.00014000"], ["84100.18000000", "0.25691000"], ["84101.25000000", "0.19991000"], ["84103.16000000", "0.00000000"], ["84103.44000000", "0.02382000"], ["84103.49000000", "0.00011000"], ["84104.00000000", "0.03778000"], ["84104.13000000", "0.00000000"], ["84104.37000000", "0.00000000"], ["84104.45000000", "0.15286000"], ["84104.46000000", "0.15008000"], ["84104.64000000", "0.00006000"], ["84105.31000000", "0.02473000"], ["84105.99000000", "0.00000000"], ["84106.83000000", "0.00000000"], ["84107.29000000", "0.00000000"], ["84109.93000000", "0.00000000"], ["84111.06000000", "0.00000000"], ["84111.72000000", "0.00000000"], ["84112.76000000", "0.79872000"], ["84113.72000000", "0.00000000"], ["84113.73000000", "0.85639000"], ["84114.69000000", "0.00000000"], ["84115.01000000", "0.08992000"], ["84117.59000000", "0.05940000"], ["84118.96000000", "0.00000000"], ["84120.81000000", "0.00000000"], ["84121.02000000", "0.00000000"], ["84121.80000000", "0.02415000"], ["84124.72000000", "1.55368000"], ["84125.08000000", "0.11880000"], ["84128.67000000", "0.59481000"], ["84128.77000000", "0.09187000"], ["84129.36000000", "0.00761000"], ["84131.12000000", "0.00000000"], ["84131.96000000", "0.00000000"], ["84132.87000000", "0.00000000"], ["84133.28000000", "0.00000000"], ["84135.05000000", "0.00000000"], ["84141.82000000", "0.25107000"], ["84142.78000000", "0.11433000"], ["84147.46000000", "0.00000000"], ["84148.34000000", "0.00000000"], ["84187.21000000", "0.00100000"], ["84192.53000000", "0.07600000"], ["84225.44000000", "0.05097000"], ["84228.62000000", "0.05097000"], ["84231.48000000", "0.05097000"], ["84264.34000000", "0.00294000"], ["85035.47000000", "0.00000000"], ["85043.91000000", "0.60000000"], ["85361.36000000", "0.00100000"], ["85370.40000000", "0.02352000"]], "record_time": 1742554969.036278, "EXCHANGE": "BINANCE"}
{"e": "depthUpdate", "E": 1742554970014, "s": "BTCUSDT", "U": 64607016931, "u": 64607017212, "b": [["84099.85000000", "4.17388000"], ["84099.67000000", "0.00015000"], ["84099.66000000", "0.00007000"], ["84099.55000000", "0.00007000"], ["84099.54000000", "0.00000000"], ["84099.42000000", "0.00021000"], ["84099.41000000", "0.40905000"], ["84099.40000000", "0.78523000"], ["84098.81000000", "0.00000000"], ["84098.80000000", "0.00000000"], ["84098.79000000", "0.00006000"], ["84098.43000000", "0.00011000"], ["84098.42000000", "0.00007000"], ["84098.00000000", "0.02267000"], ["84097.63000000", "0.00000000"], ["84097.62000000", "0.00000000"], ["84097.00000000", "0.00000000"], ["84096.69000000", "0.00000000"], ["84096.68000000", "0.08988000"], ["84096.37000000", "0.00000000"], ["84095.66000000", "0.02418000"], ["84095.60000000", "0.00000000"], ["84094.63000000", "0.00000000"], ["84094.62000000", "0.37340000"], ["84094.61000000", "0.00000000"], ["84094.59000000", "0.00000000"], ["84094.49000000", "0.00000000"], ["84094.20000000", "0.04818000"], ["84093.99000000", "0.00000000"], ["84088.45000000", "0.00000000"], ["84088.42000000", "0.00000000"], ["84088.35000000", "0.04000000"], ["84088.34000000", "0.04000000"], ["84086.90000000", "0.04000000"], ["84086.04000000", "0.71284000"], ["84084.98000000", "0.04000000"], ["84084.15000000", "0.04000000"], ["84079.00000000", "0.18264000"], ["84078.68000000", "0.85675000"], ["84068.50000000", "0.00000000"], ["84068.37000000", "0.59480000"], ["84063.26000000", "0.00000000"], ["84060.57000000", "0.00006000"], ["84058.70000000", "0.05000000"], ["84054.42000000", "0.00000000"], ["84050.55000000", "0.00000000"], ["84047.86000000", "0.39700000"], ["84023.38000000", "0.04000000"], ["84017.50000000", "0.23306000"], ["84016.42000000", "0.00000000"], ["84015.33000000", "0.00000000"], ["84014.68000000", "0.00000000"], ["84013.29000000", "0.00000000"], ["84009.69000000", "0.00000000"], ["83981.34000000", "0.04637000"], ["83944.77000000", "0.00400000"], ["83927.50000000", "0.00000000"], ["83914.40000000", "0.00000000"], ["83826.93000000", "0.00007000"], ["83682.90000000", "0.00000000"], ["83679.36000000", "1.18962000"], ["83262.38000000", "0.00000000"], ["83258.86000000", "1.78454000"], ["83069.99000000", "0.00000000"], ["82841.87000000", "0.00000000"], ["82838.36000000", "0.59481000"], ["82838.35000000", "0.00100000"], ["80697.27000000", "0.00000000"], ["75754.62000000", "0.00000000"], ["75689.86000000", "0.00048000"], ["75689.00000000", "0.54435000"], ["67279.88000000", "0.00058000"], ["33000.00000000", "2.93827000"], ["30275.95000000", "0.00060000"], ["30218.39000000", "0.00820000"], ["30217.09000000", "0.00149000"], ["30216.23000000", "0.00220000"], ["30197.25000000", "0.00200000"], ["30196.96000000", "0.00400000"], ["30196.08000000", "0.00160000"], ["30194.44000000", "0.00060000"], ["30191.87000000", "0.00020000"], ["30185.22000000", "0.00120000"]], "a": [["84099.86000000", "2.69176000"], ["84100.00000000", "0.00085000"], ["84100.18000000", "0.25685000"], ["84101.13000000", "0.10150000"], ["84101.22000000", "0.01263000"], ["84101.25000000", "0.00006000"], ["84103.49000000", "0.00000000"], ["84104.00000000", "0.02260000"], ["84104.64000000", "0.00069000"], ["84105.31000000", "0.00000000"], ["84105.51000000", "0.04818000"], ["84106.20000000", "0.00511000"], ["84108.10000000", "0.00500000"], ["84108.27000000", "0.00000000"], ["84110.21000000", "0.00097000"], ["84110.53000000", "0.00416000"], ["84112.76000000", "0.46373000"], ["84113.73000000", "0.00000000"], ["84115.01000000", "0.00000000"], ["84127.44000000", "0.85625000"], ["84128.67000000", "0.00000000"], ["84130.28000000", "0.00000000"], ["84131.82000000", "0.00084000"], ["84133.97000000", "0.64900000"], ["84136.75000000", "0.59477000"], ["84141.30000000", "0.00000000"], ["84146.94000000", "0.00000000"], ["84149.74000000", "0.00000000"], ["84151.40000000", "0.00000000"], ["84520.35000000", "1.18962000"], ["84523.92000000", "0.00000000"], ["84940.84000000", "0.00000000"], ["84940.85000000", "1.78457000"], ["84944.44000000", "0.00000000"], ["85349.10000000", "0.00000000"], ["85361.35000000", "0.59495000"], ["85361.36000000", "0.00000000"], ["85364.96000000", "0.00000000"], ["85370.40000000", "0.08218000"], ["85391.70000000", "0.00007000"], ["86000.00000000", "21.78562000"]], "record_time": 1742554970.037075, "EXCHANGE": "BINANCE"}
{"e": "depthUpdate", "E": 1742555026014, "s": "BTCUSDT", "U": 64607042392, "u": 64607042452, "b": [["84104.61000000", "1.20266000"], ["84098.83000000", "0.18020000"], ["84097.72000000", "0.01000000"], ["84094.19000000", "0.00000000"], ["84090.92000000", "0.00887000"], ["84087.39000000", "0.24280000"], ["84055.55000000", "0.00000000"], ["83938.73000000", "0.00000000"], ["83937.73000000", "0.01000000"], ["83915.38000000", "0.00011000"], ["83903.59000000", "0.00000000"], ["83901.95000000", "0.00000000"], ["83901.94000000", "0.00678000"], ["83181.54000000", "0.00060000"], ["83181.53000000", "0.00000000"], ["79800.00000000", "8.29820000"], ["75694.00000000", "0.00000000"], ["67283.69000000", "0.00058000"], ["42000.00000000", "6.85161000"], ["33000.00000000", "2.93827000"], ["30277.66000000", "0.00180000"], ["20002.00000000", "0.00000000"], ["20001.00000000", "0.02099000"]], "a": [["84109.96000000", "0.00059000"], ["84131.63000000", "0.00000000"], ["84143.77000000", "0.12836000"], ["84153.58000000", "0.00000000"], ["84179.25000000", "0.00841000"], ["84182.33000000", "0.00000000"], ["84214.37000000", "0.04755000"], ["84217.21000000", "0.09511000"], ["84234.85000000", "0.05497000"], ["84248.74000000", "0.00000000"], ["84251.35000000", "0.00000000"], ["84272.66000000", "0.00000000"], ["84272.82000000", "0.01141000"], ["84273.06000000", "0.00000000"], ["84273.46000000", "0.01000000"], ["84274.37000000", "0.00000000"], ["84274.65000000", "0.99270000"], ["84283.25000000", "0.00000000"]], "record_time": 1742555026.037408, "EXCHANGE": "BINANCE"}
{"e": "depthUpdate", "E": 1742555027014, "s": "BTCUSDT", "U": 64607042453, "u": 64607042574, "b": [["84104.61000000", "1.20285000"], ["84104.60000000", "0.00133000"], ["84099.85000000", "0.00481000"], ["84099.00000000", "0.00754000"], ["84098.83000000", "0.18020000"], ["84097.47000000", "0.00000000"], ["84097.38000000", "0.00000000"], ["84095.80000000", "0.00000000"], ["84094.96000000", "0.78520000"], ["84094.69000000", "0.00000000"], ["84094.66000000", "0.00000000"], ["84091.70000000", "0.00000000"], ["84055.55000000", "0.00000000"], ["84054.10000000", "0.00441000"], ["84040.60000000", "0.00000000"], ["84019.01000000", "0.09510000"], ["84017.37000000", "0.04755000"], ["84015.62000000", "0.19523000"], ["84013.98000000", "0.09390000"], ["84013.76000000", "0.04635000"], ["84012.12000000", "0.00000000"], ["84010.87000000", "0.04637000"], ["84010.48000000", "0.09509000"], ["84010.19000000", "0.00000000"], ["84009.87000000", "0.97421000"], ["84009.48000000", "0.14889000"], ["84007.77000000", "0.00000000"], ["84007.56000000", "0.10252000"], ["84007.21000000", "0.00000000"], ["84006.37000000", "0.09274000"], ["84006.33000000", "0.00000000"], ["84005.45000000", "0.04637000"], ["84005.00000000", "0.04637000"], ["84004.67000000", "0.04637000"], ["84004.36000000", "0.04755000"], ["84003.89000000", "0.04636000"], ["84003.46000000", "0.04637000"], ["84002.90000000", "0.00000000"], ["84002.71000000", "0.04637000"], ["84002.58000000", "0.00000000"], ["84001.72000000", "0.00000000"], ["84001.31000000", "0.04637000"], ["84001.17000000", "0.05097000"], ["84001.03000000", "0.00000000"], ["84000.47000000", "0.05497000"], ["83999.26000000", "0.04637000"], ["83999.02000000", "0.00000000"], ["83998.94000000", "0.00000000"], ["83998.57000000", "0.04637000"], ["83997.16000000", "0.00000000"], ["83996.16000000", "0.00000000"], ["83994.21000000", "0.00000000"], ["83254.38000000", "0.00000000"], ["75694.00000000", "0.00000000"], ["67283.69000000", "0.00058000"], ["33000.00000000", "2.93827000"], ["30277.66000000", "0.00360000"]], "a": [["84104.62000000", "6.76422000"], ["84108.80000000", "0.00500000"], ["84113.22000000", "0.01252000"], ["84114.74000000", "0.10698000"], ["84118.10000000", "0.00500000"], ["84127.03000000", "0.00000000"], ["84129.43000000", "0.00000000"], ["84131.53000000", "0.00000000"], ["84184.00000000", "0.04554000"], ["84197.61000000", "0.00000000"], ["84207.14000000", "0.00000000"], ["84208.47000000", "0.00000000"], ["84209.96000000", "0.00000000"], ["84211.68000000", "0.00000000"], ["84213.05000000", "0.04637000"], ["84213.30000000", "0.00000000"], ["84215.21000000", "0.18768000"], ["84215.96000000", "0.19086000"], ["84217.60000000", "0.04755000"], ["84217.61000000", "0.04755000"], ["84218.17000000", "0.04637000"], ["84219.77000000", "0.00000000"], ["84221.93000000", "0.04637000"], ["84224.97000000", "0.04637000"], ["84228.38000000", "0.05497000"], ["84231.45000000", "0.05497000"], ["84235.90000000", "0.05497000"], ["84243.78000000", "0.05197000"], ["84244.25000000", "0.04636000"], ["84246.85000000", "0.00000000"], ["84247.40000000", "0.00000000"], ["84273.46000000", "0.00000000"], ["84273.76000000", "0.01000000"]], "record_time": 1742555027.036289, "EXCHANGE": "BINANCE"}
{"e": "depthUpdate", "E": 1742555028014, "s": "BTCUSDT", "U": 64607042575, "u": 64607042702, "b": [["84104.61000000", "1.20030000"], ["84104.60000000", "0.00703000"], ["84102.57000000", "0.09550000"], ["84102.03000000", "0.02205000"], ["84098.83000000", "0.18020000"], ["84098.32000000", "0.00000000"], ["84098.11000000", "0.00000000"], ["84097.79000000", "0.00000000"], ["84095.89000000", "0.00000000"], ["84095.73000000", "0.00000000"], ["84094.96000000", "0.00000000"], ["84085.18000000", "0.00875000"], ["84056.49000000", "0.05000000"], ["84011.62000000", "1.38850000"], ["84008.79000000", "0.00000000"], ["84006.37000000", "0.13911000"], ["84005.01000000", "0.04637000"], ["84003.76000000", "0.00000000"], ["84002.04000000", "0.04637000"], ["84001.20000000", "0.00000000"], ["84000.39000000", "0.04637000"], ["83999.30000000", "0.00000000"], ["83997.81000000", "0.00000000"], ["83993.70000000", "0.04637000"], ["83992.35000000", "0.04637000"], ["83989.47000000", "0.04637000"], ["83987.38000000", "0.00000000"], ["83986.56000000", "0.04637000"], ["83985.16000000", "0.00000000"], ["83984.70000000", "0.00000000"], ["83982.53000000", "0.00000000"], ["83937.83000000", "0.01000000"], ["83937.73000000", "0.00000000"], ["83924.18000000", "0.01862000"], ["83892.60000000", "0.00000000"], ["83886.65000000", "0.00400000"], ["83884.40000000", "0.00008000"], ["83869.59000000", "0.00000000"], ["75694.00000000", "0.00000000"], ["67283.69000000", "0.00058000"], ["33000.00000000", "2.93827000"], ["30277.66000000", "0.00460000"]], "a": [["84104.62000000", "5.97569000"], ["84104.63000000", "1.54765000"], ["84105.99000000", "0.02601000"], ["84107.33000000", "0.04000000"], ["84108.00000000", "0.16728000"], ["84108.15000000", "0.02396000"], ["84109.33000000", "0.00000000"], ["84117.59000000", "0.05940000"], ["84118.97000000", "0.01862000"], ["84120.70000000", "0.00000000"], ["84121.02000000", "0.00000000"], ["84129.43000000", "0.00000000"], ["84129.86000000", "0.05940000"], ["84141.44000000", "0.00000000"], ["84214.41000000", "0.19368000"], ["84217.99000000", "0.00000000"], ["84218.21000000", "0.00000000"], ["84219.99000000", "0.04637000"], ["84220.46000000", "0.00000000"], ["84221.45000000", "0.00000000"], ["84222.95000000", "0.04637000"], ["84224.72000000", "0.04637000"], ["84226.43000000", "0.04637000"], ["84226.99000000", "0.04637000"], ["84243.37000000", "0.00000000"], ["84273.76000000", "0.00000000"], ["84274.07000000", "0.00000000"], ["84274.37000000", "0.01000000"]], "record_time": 1742555028.051746, "EXCHANGE": "BINANCE"}
{"e": "depthUpdate", "E": 1742555029014, "s": "BTCUSDT", "U": 64607042703, "u": 64607042770, "b": [["84104.61000000", "1.65030000"], ["84100.40000000", "0.00500000"], ["84098.33000000", "0.00000000"], ["84085.18000000", "0.00000000"], ["84080.35000000", "0.00000000"], ["84073.09000000", "0.72858000"], ["84070.30000000", "0.00000000"], ["84067.69000000", "0.00000000"], ["84065.80000000", "0.00000000"], ["84065.13000000", "0.23079000"], ["84062.70000000", "0.37675000"], ["84014.45000000", "1.28836000"], ["84009.87000000", "0.58502000"], ["83937.93000000", "0.01000000"], ["83937.83000000", "0.00000000"], ["83924.18000000", "0.00000000"], ["83239.70000000", "0.00060000"], ["83239.68000000", "0.00000000"], ["83181.55000000", "0.00060000"], ["83181.54000000", "0.00000000"], ["75694.00000000", "0.00000000"], ["67283.69000000", "0.00058000"], ["60000.00000000", "73.17018000"], ["33000.00000000", "2.93827000"], ["30277.66000000", "0.00540000"]], "a": [["84108.80000000", "0.00500000"], ["84117.59000000", "0.05940000"], ["84118.10000000", "0.00000000"], ["84118.97000000", "0.00000000"], ["84121.02000000", "0.00000000"], ["84134.43000000", "0.05000000"], ["84168.40000000", "0.01862000"], ["84235.09000000", "0.05497000"], ["84240.54000000", "0.05197000"], ["84274.37000000", "0.01000000"]], "record_time": 1742555029.099586, "EXCHANGE": "BINANCE"}
{"e": "depthUpdate", "E": 1742555030014, "s": "BTCUSDT", "U": 64607042771, "u": 64607042981, "b": [["84104.61000000", "3.49285000"], ["84104.01000000", "0.00030000"], ["84103.64000000", "0.00008000"], ["84102.57000000", "0.09550000"], ["84102.22000000", "0.00011000"], ["84102.03000000", "0.00000000"], ["84101.71000000", "0.01518000"], ["84101.70000000", "0.00400000"], ["84101.43000000", "0.00000000"], ["84099.77000000", "0.00000000"], ["84099.26000000", "0.00000000"], ["84099.04000000", "0.00000000"], ["84098.83000000", "0.39049000"], ["84098.61000000", "0.78516000"], ["84098.41000000", "0.00000000"], ["84098.37000000", "0.00000000"], ["84096.84000000", "0.00000000"], ["84096.73000000", "0.00000000"], ["84096.30000000", "0.00000000"], ["84095.08000000", "0.00000000"], ["84094.68000000", "0.00000000"], ["84094.14000000", "0.00421000"], ["84091.60000000", "0.08704000"], ["84084.08000000", "0.00000000"], ["84080.86000000", "0.85672000"], ["84080.77000000", "0.00000000"], ["84080.66000000", "0.00000000"], ["84079.87000000", "0.11406000"], ["84067.69000000", "0.00000000"], ["84066.94000000", "0.59478000"], ["84063.41000000", "0.05000000"], ["84060.74000000", "0.00000000"], ["84060.10000000", "0.00000000"], ["84056.49000000", "0.00000000"], ["84011.62000000", "0.00000000"], ["84008.79000000", "1.38850000"], ["83938.33000000", "0.01000000"], ["83937.93000000", "0.00000000"], ["83929.95000000", "0.00400000"], ["83917.92000000", "0.00000000"], ["83901.33000000", "0.00000000"], ["83886.65000000", "0.00000000"], ["83263.56000000", "0.00000000"], ["83239.77000000", "0.00060000"], ["83239.70000000", "0.00000000"], ["83181.62000000", "0.00060000"], ["83181.55000000", "0.00000000"], ["81000.00000000", "54.02382000"], ["75694.00000000", "0.00000000"], ["67283.69000000", "0.00058000"], ["33000.00000000", "2.93827000"], ["30277.66000000", "0.00620000"]], "a": [["84104.62000000", "2.91669000"], ["84105.65000000", "0.00058000"], ["84105.99000000", "0.01882000"], ["84106.00000000", "0.02260000"], ["84106.82000000", "0.00006000"], ["84106.85000000", "0.00000000"], ["84107.48000000", "0.00000000"], ["84107.69000000", "0.00007000"], ["84107.99000000", "0.00009000"], ["84108.80000000", "0.00000000"], ["84108.91000000", "0.00000000"], ["84109.54000000", "0.01518000"], ["84110.05000000", "0.00011000"], ["84111.32000000", "0.00000000"], ["84113.21000000", "0.00000000"], ["84114.00000000", "0.02278000"], ["84114.95000000", "0.00000000"], ["84117.59000000", "0.00000000"], ["84118.36000000", "0.85634000"], ["84118.52000000", "0.00000000"], ["84119.52000000", "0.00000000"], ["84121.00000000", "0.00000000"], ["84121.02000000", "0.05940000"], ["84122.77000000", "0.00000000"], ["84130.74000000", "0.00000000"], ["84131.01000000", "0.00000000"], ["84133.96000000", "0.59476000"], ["84134.43000000", "0.00000000"], ["84141.30000000", "0.00000000"], ["84143.04000000", "0.05000000"], ["84147.18000000", "0.11406000"], ["84151.39000000", "0.00000000"], ["84151.40000000", "0.00400000"], ["84166.84000000", "0.00000000"], ["84168.40000000", "0.00000000"], ["84173.39000000", "0.00000000"], ["84209.99000000", "0.05497000"], ["84214.91000000", "0.05497000"], ["84217.88000000", "0.05497000"], ["84223.53000000", "0.00000000"], ["84226.82000000", "0.00000000"], ["84274.65000000", "0.99392000"], ["84302.64000000", "0.00000000"]], "record_time": 1742555030.035766, "EXCHANGE": "BINANCE"}
{"e": "depthUpdate", "E": 1742555031014, "s": "BTCUSDT", "U": 64607042982, "u": 64607043186, "b": [["84104.61000000", "1.66506000"], ["84104.60000000", "0.00717000"], ["84104.59000000", "0.00020000"], ["84104.50000000", "0.00021000"], ["84104.49000000", "0.10621000"], ["84104.35000000", "0.00007000"], ["84104.33000000", "0.00007000"], ["84104.31000000", "0.00000000"], ["84104.25000000", "0.00000000"], ["84104.21000000", "0.00000000"], ["84104.01000000", "0.00030000"], ["84104.00000000", "0.17792000"], ["84103.99000000", "0.28245000"], ["84103.77000000", "0.00000000"], ["84103.64000000", "0.00129000"], ["84103.63000000", "0.02376000"], ["84102.57000000", "0.00000000"], ["84102.00000000", "0.03709000"], ["84101.80000000", "0.00000000"], ["84101.70000000", "0.00000000"], ["84100.86000000", "0.00000000"], ["84100.40000000", "0.00000000"], ["84098.83000000", "0.18020000"], ["84098.61000000", "0.00000000"], ["84098.50000000", "0.00000000"], ["84095.13000000", "0.00095000"], ["84094.72000000", "0.00000000"], ["84094.68000000", "0.00089000"], ["84091.70000000", "0.00300000"], ["84091.60000000", "0.08304000"], ["84091.59000000", "0.00000000"], ["84080.86000000", "0.00000000"], ["84080.75000000", "0.00000000"], ["84068.22000000", "1.03375000"], ["84068.21000000", "0.85685000"], ["84067.36000000", "0.00000000"], ["84063.41000000", "0.00000000"], ["84056.55000000", "0.00000000"], ["84039.74000000", "0.00000000"], ["84036.43000000", "0.00000000"], ["84028.02000000", "0.00000000"], ["84023.49000000", "0.00298000"], ["84019.61000000", "0.00000000"], ["84015.08000000", "0.00597000"], ["84014.45000000", "0.97718000"], ["84011.21000000", "0.00000000"], ["84006.68000000", "0.00895000"], ["84002.80000000", "0.00000000"], ["83998.27000000", "0.01194000"], ["83989.87000000", "0.01493000"], ["83929.95000000", "0.00000000"], ["83923.57000000", "0.00400000"], ["79800.00000000", "8.29820000"], ["75694.00000000", "0.00000000"], ["67283.69000000", "0.00058000"], ["33000.00000000", "2.93827000"], ["30277.66000000", "0.00740000"], ["20002.00000000", "0.00000000"], ["20001.00000000", "0.02099000"]], "a": [["84104.62000000", "4.02444000"], ["84104.63000000", "1.54778000"], ["84106.05000000", "0.02327000"], ["84106.85000000", "0.00007000"], ["84107.69000000", "0.00000000"], ["84108.80000000", "0.00500000"], ["84110.74000000", "0.00008000"], ["84116.73000000", "0.08992000"], ["84117.59000000", "0.05940000"], ["84118.10000000", "0.00000000"], ["84121.02000000", "0.00000000"], ["84121.12000000", "0.71284000"], ["84121.13000000", "1.17822000"], ["84128.00000000", "0.59478000"], ["84133.73000000", "0.05000000"], ["84133.96000000", "0.00000000"], ["84143.04000000", "0.00000000"], ["84151.40000000", "0.00000000"], ["84173.45000000", "0.02379000"], ["84191.31000000", "0.00298000"], ["84197.99000000", "0.00000000"], ["84200.22000000", "0.00597000"], ["84206.41000000", "0.00000000"], ["84208.64000000", "0.00895000"], ["84215.04000000", "0.00000000"], ["84217.05000000", "0.01194000"], ["84223.94000000", "0.00000000"], ["84225.47000000", "0.01493000"], ["84232.36000000", "0.00000000"], ["84233.43000000", "0.05097000"], ["84239.26000000", "0.05197000"], ["84239.89000000", "0.00000000"], ["85349.10000000", "0.00000000"], ["85370.40000000", "0.19949000"]], "record_time": 1742555031.036336, "EXCHANGE": "BINANCE"}
{"e": "depthUpdate", "E": 1742555032014, "s": "BTCUSDT", "U": 64607043187, "u": 64607043288, "b": [["84104.61000000", "2.23481000"], ["84104.50000000", "0.00007000"], ["84104.49000000", "0.00007000"], ["84103.99000000", "0.28245000"], ["84103.64000000", "0.09733000"], ["84102.22000000", "0.00000000"], ["84102.00000000", "0.03709000"], ["84101.71000000", "0.00000000"], ["84101.67000000", "0.00000000"], ["84099.74000000", "0.00011000"], ["84099.23000000", "0.01518000"], ["84096.01000000", "0.00000000"], ["84094.62000000", "0.57912000"], ["84094.43000000", "0.00000000"], ["84091.61000000", "0.71284000"], ["84085.17000000", "0.00887000"], ["84081.39000000", "0.00000000"], ["84068.22000000", "0.00000000"], ["84068.21000000", "0.00000000"], ["84068.10000000", "0.00000000"], ["84066.94000000", "0.00000000"], ["84063.83000000", "0.59479000"], ["84057.00000000", "0.00000000"], ["84041.30000000", "0.00332000"], ["84009.87000000", "1.01864000"], ["83938.53000000", "0.01000000"], ["83938.33000000", "0.00000000"], ["83923.57000000", "0.00000000"], ["83907.35000000", "0.00400000"], ["75694.00000000", "0.00000000"], ["67283.69000000", "0.00058000"], ["33000.00000000", "2.93827000"], ["30277.66000000", "0.00760000"]], "a": [["84104.62000000", "4.02420000"], ["84107.62000000", "0.00011000"], ["84110.05000000", "0.00000000"], ["84111.98000000", "0.35968000"], ["84114.66000000", "0.00000000"], ["84117.59000000", "0.00000000"], ["84121.01000000", "1.15487000"], ["84121.02000000", "0.05940000"], ["84127.12000000", "0.00000000"], ["84128.84000000", "0.85624000"], ["84133.73000000", "0.00000000"], ["84143.04000000", "0.00000000"], ["84145.04000000", "0.00000000"], ["84146.68000000", "0.05903000"], ["84152.44000000", "0.00000000"], ["84179.25000000", "0.00000000"], ["84182.33000000", "0.00841000"]], "record_time": 1742555032.043758, "EXCHANGE": "BINANCE"}
{"e": "depthUpdate", "E": 1742555033014, "s": "BTCUSDT", "U": 64607043289, "u": 64607043406, "b": [["84104.61000000", "2.27401000"], ["84104.60000000", "0.00731000"], ["84104.59000000", "0.00007000"], ["84104.33000000", "0.00007000"], ["84104.29000000", "0.00021000"], ["84104.28000000", "0.15175000"], ["84104.01000000", "0.00023000"], ["84103.99000000", "0.28245000"], ["84103.64000000", "0.00008000"], ["84102.00000000", "0.03709000"], ["84100.85000000", "0.02352000"], ["84100.40000000", "0.00500000"], ["84098.52000000", "0.78517000"], ["84095.08000000", "0.00000000"], ["84091.70000000", "0.00000000"], ["84080.78000000", "0.85673000"], ["84066.99000000", "0.59749000"], ["84056.55000000", "0.00000000"], ["84055.90000000", "0.00000000"], ["84054.10000000", "0.00000000"], ["84011.62000000", "1.38850000"], ["84009.87000000", "0.58502000"], ["84008.79000000", "0.00000000"], ["83912.38000000", "0.00400000"], ["83907.35000000", "0.00000000"], ["75694.00000000", "0.00000000"], ["67283.69000000", "0.00058000"], ["64849.22000000", "0.00093000"], ["33000.00000000", "2.93827000"], ["30277.66000000", "0.00780000"]], "a": [["84104.62000000", "3.33554000"], ["84106.05000000", "0.00000000"], ["84108.80000000", "0.00500000"], ["84116.73000000", "0.00000000"], ["84117.59000000", "0.00000000"], ["84117.87000000", "0.03567000"], ["84121.02000000", "0.05940000"], ["84131.47000000", "0.00000000"], ["84133.73000000", "0.05000000"]], "record_time": 1742555033.03734, "EXCHANGE": "BINANCE"}
{"e": "depthUpdate", "E": 1742555034014, "s": "BTCUSDT", "U": 64607043407, "u": 64607043538, "b": [["84104.61000000", "2.15769000"], ["84103.63000000", "0.02376000"], ["84103.01000000", "0.02100000"], ["84102.64000000", "0.00007000"], ["84100.67000000", "0.00761000"], ["84099.00000000", "0.00000000"], ["84098.83000000", "0.39078000"], ["84098.81000000", "0.00000000"], ["84098.52000000", "0.00000000"], ["84098.03000000", "0.78517000"], ["84097.20000000", "0.00000000"], ["84096.93000000", "0.00000000"], ["84094.83000000", "0.00000000"], ["84080.78000000", "0.00000000"], ["84080.29000000", "1.74784000"], ["84066.65000000", "0.00000000"], ["84063.28000000", "0.01300000"], ["84063.09000000", "0.00000000"], ["84059.20000000", "0.00000000"], ["84053.70000000", "0.00000000"], ["84052.28000000", "0.00000000"], ["84039.73000000", "0.00000000"], ["83993.14000000", "0.08834000"], ["83987.17000000", "0.04197000"], ["83980.92000000", "0.04197000"], ["83977.34000000", "0.04197000"], ["83977.11000000", "0.00000000"], ["83971.59000000", "0.04197000"], ["83970.89000000", "0.00000000"], ["83970.05000000", "0.00000000"], ["83967.43000000", "0.00000000"], ["83938.73000000", "0.01000000"], ["83938.53000000", "0.00000000"], ["83918.64000000", "0.00400000"], ["83912.38000000", "0.00000000"], ["83239.79000000", "0.00060000"], ["83239.77000000", "0.00000000"], ["83181.64000000", "0.00060000"], ["83181.62000000", "0.00000000"], ["79000.00000000", "74.38127000"], ["75694.00000000", "0.00000000"], ["67283.69000000", "0.00058000"], ["64849.22000000", "0.00186000"], ["33000.00000000", "2.93827000"], ["30277.66000000", "0.00800000"]], "a": [["84104.62000000", "3.16403000"], ["84104.63000000", "1.54791000"], ["84106.47000000", "0.00000000"], ["84106.85000000", "0.00000000"], ["84107.32000000", "0.00013000"], ["84107.69000000", "0.00007000"], ["84107.99000000", "0.00000000"], ["84111.98000000", "0.35968000"], ["84113.22000000", "0.00000000"], ["84115.11000000", "0.00000000"], ["84121.12000000", "0.71284000"], ["84127.21000000", "0.85625000"], ["84128.00000000", "0.00000000"], ["84128.84000000", "0.00000000"], ["84130.34000000", "0.59478000"], ["84133.73000000", "0.00000000"], ["84135.63000000", "0.00000000"], ["84145.04000000", "0.00000000"], ["84166.88000000", "0.00000000"], ["84173.45000000", "0.00000000"], ["84224.22000000", "0.18314000"], ["84231.78000000", "0.00000000"], ["84236.20000000", "0.02059000"], ["84238.07000000", "0.04197000"], ["84274.37000000", "0.01000000"], ["84274.65000000", "0.99092000"], ["84456.07000000", "0.00000000"]], "record_time": 1742555034.036268, "EXCHANGE": "BINANCE"}
{"e": "depthUpdate", "E": 1742555171014, "s": "BTCUSDT", "U": 64607124348, "u": 64607124494, "b": [["84076.08000000", "1.02130000"], ["84075.01000000", "0.33494000"], ["84074.53000000", "0.00000000"], ["84074.46000000", "0.17509000"], ["84072.91000000", "0.08018000"], ["84072.90000000", "0.00000000"], ["84072.84000000", "0.09510000"], ["84072.26000000", "0.02220000"], ["84071.90000000", "0.01000000"], ["84069.36000000", "0.00607000"], ["84068.49000000", "0.02353000"], ["84067.67000000", "0.45000000"], ["84055.01000000", "0.71284000"], ["84052.01000000", "0.00879000"], ["84036.01000000", "0.00000000"], ["84035.81000000", "0.00000000"], ["84029.90000000", "0.00000000"], ["84027.71000000", "0.05000000"], ["83922.95000000", "0.00000000"], ["83886.91000000", "0.00011000"], ["82626.05000000", "0.00000000"], ["75668.00000000", "0.13247000"], ["67260.87000000", "0.00058000"], ["33000.00000000", "2.93827000"], ["30218.76000000", "0.00000000"], ["30208.70000000", "0.00840000"], ["30198.36000000", "0.00420000"], ["30197.26000000", "0.00000000"], ["30197.25000000", "0.00000000"], ["30196.96000000", "0.00080000"], ["30195.91000000", "0.00080000"], ["30195.04000000", "0.00040000"], ["30194.92000000", "0.00320000"], ["30192.48000000", "0.00000000"], ["30192.35000000", "0.00020000"], ["30191.96000000", "0.00020000"], ["30187.99000000", "0.00000000"], ["20002.00000000", "0.00000000"], ["20001.00000000", "0.02099000"]], "a": [["84076.09000000", "8.46721000"], ["84078.00000000", "0.02273000"], ["84079.20000000", "0.00000000"], ["84079.21000000", "0.00000000"], ["84080.41000000", "0.00014000"], ["84081.22000000", "0.11896000"], ["84083.77000000", "0.04000000"], ["84083.97000000", "0.00877000"], ["84084.62000000", "0.04058000"], ["84085.46000000", "0.10000000"], ["84085.50000000", "0.07637000"], ["84086.50000000", "0.00000000"], ["84087.26000000", "0.78083000"], ["84087.98000000", "0.07600000"], ["84088.76000000", "0.00000000"], ["84088.82000000", "0.07200000"], ["84089.61000000", "0.00000000"], ["84089.66000000", "0.06400000"], ["84089.67000000", "0.06400000"], ["84089.71000000", "0.06000000"], ["84090.45000000", "0.00000000"], ["84090.49000000", "0.00000000"], ["84092.98000000", "0.00000000"], ["84093.82000000", "0.00000000"], ["84094.65000000", "0.00000000"], ["84094.66000000", "0.00000000"], ["84094.70000000", "0.00000000"], ["84094.90000000", "0.00000000"], ["84105.14000000", "0.00000000"], ["84136.49000000", "0.04000000"], ["84137.33000000", "0.04000000"], ["84141.83000000", "0.00000000"], ["84142.42000000", "0.10800000"], ["84142.68000000", "0.00000000"], ["84147.77000000", "0.00000000"], ["84154.81000000", "0.00000000"], ["84156.21000000", "0.00841000"], ["84160.37000000", "0.00043000"], ["84184.52000000", "0.04757000"], ["84184.53000000", "0.04757000"], ["84185.98000000", "0.04757000"], ["84185.99000000", "0.04757000"], ["84189.41000000", "0.04757000"], ["84189.42000000", "0.04757000"], ["84200.36000000", "0.05296000"], ["84200.58000000", "0.00000000"], ["84200.59000000", "0.00000000"], ["84200.72000000", "0.00000000"], ["84200.76000000", "0.00000000"], ["84203.60000000", "0.00000000"], ["84203.96000000", "0.00000000"], ["84204.17000000", "0.00000000"], ["84204.73000000", "0.00000000"], ["84205.91000000", "0.05096000"], ["84232.81000000", "0.00000000"], ["84233.06000000", "0.00000000"], ["84241.69000000", "0.00000000"], ["84248.70000000", "0.00000000"], ["84248.80000000", "0.01000000"]], "record_time": 1742555171.036062, "EXCHANGE": "BINANCE"}
{"e": "depthUpdate", "E": 1742555172014, "s": "BTCUSDT", "U": 64607124495, "u": 64607124568, "b": [["84076.08000000", "0.99930000"], ["84075.47000000", "0.07604000"], ["84075.03000000", "0.00014000"], ["84075.02000000", "0.15326000"], ["84072.91000000", "0.08011000"], ["84071.90000000", "0.01000000"], ["84069.95000000", "0.00011000"], ["84067.67000000", "0.00000000"], ["84067.25000000", "0.00000000"], ["84067.16000000", "0.00000000"], ["84063.00000000", "0.00000000"], ["84053.54000000", "0.00000000"], ["84053.33000000", "0.00000000"], ["84053.30000000", "0.00000000"], ["84053.29000000", "0.03569000"], ["84052.01000000", "0.00000000"], ["84043.45000000", "0.00754000"], ["84042.05000000", "0.00000000"], ["84036.23000000", "0.04000000"], ["84035.81000000", "0.01300000"], ["75668.00000000", "0.13247000"], ["67260.87000000", "0.00058000"], ["33000.00000000", "2.93827000"], ["30267.39000000", "0.00260000"]], "a": [["84076.09000000", "8.46713000"], ["84081.12000000", "0.11898000"], ["84084.00000000", "0.02260000"], ["84094.03000000", "0.00000000"], ["84110.81000000", "0.00424000"], ["84112.20000000", "0.01674000"], ["84115.90000000", "0.00000000"], ["84135.89000000", "0.02380000"], ["84146.22000000", "0.00000000"], ["84248.80000000", "0.00000000"]], "record_time": 1742555172.036927, "EXCHANGE": "BINANCE"}
{"e": "depthUpdate", "E": 1742555173014, "s": "BTCUSDT", "U": 64607124569, "u": 64607124739, "b": [["84076.08000000", "1.01901000"], ["84075.47000000", "0.07604000"], ["84075.03000000", "0.00000000"], ["84075.02000000", "0.00000000"], ["84075.01000000", "0.00000000"], ["84074.47000000", "0.00000000"], ["84074.46000000", "0.00000000"], ["84073.69000000", "0.00000000"], ["84072.92000000", "0.00014000"], ["84072.91000000", "0.20682000"], ["84072.85000000", "0.00000000"], ["84072.84000000", "0.09517000"], ["84072.55000000", "0.00012000"], ["84072.53000000", "0.02340000"], ["84072.44000000", "0.17389000"], ["84071.90000000", "0.01000000"], ["84071.22000000", "0.00000000"], ["84071.09000000", "0.00036000"], ["84071.08000000", "0.34804000"], ["84071.05000000", "0.00000000"], ["84070.46000000", "0.00007000"], ["84069.65000000", "0.00000000"], ["84069.64000000", "0.00000000"], ["84069.36000000", "0.00000000"], ["84068.49000000", "0.00000000"], ["84067.16000000", "0.00050000"], ["84063.00000000", "0.02374000"], ["84056.59000000", "0.00000000"], ["84055.01000000", "0.00000000"], ["84053.29000000", "0.00000000"], ["84053.28000000", "0.03569000"], ["84052.98000000", "0.10689000"], ["84050.09000000", "0.00000000"], ["84046.32000000", "0.00000000"], ["84045.14000000", "0.00000000"], ["84035.58000000", "0.00000000"], ["84033.61000000", "0.00680000"], ["84032.09000000", "0.33649000"], ["84030.02000000", "0.37686000"], ["84026.46000000", "0.22700000"], ["84026.45000000", "0.32280000"], ["84026.28000000", "0.00000000"], ["84017.99000000", "0.00000000"], ["84017.16000000", "0.00000000"], ["83989.23000000", "1.43286000"], ["83988.75000000", "2.15298000"], ["83980.51000000", "0.00000000"], ["83958.48000000", "0.00075000"], ["83958.47000000", "0.00000000"], ["83882.82000000", "0.00063000"], ["83882.81000000", "0.00000000"], ["82183.41000000", "0.00051000"], ["80673.60000000", "0.00000000"], ["80656.80000000", "0.00000000"], ["76100.00000000", "10.05807000"], ["75668.00000000", "0.13247000"], ["67260.87000000", "0.00058000"], ["33000.00000000", "2.93827000"]], "a": [["84076.09000000", "8.27208000"], ["84078.00000000", "0.02273000"], ["84078.68000000", "0.04817000"], ["84082.21000000", "0.00008000"], ["84084.00000000", "0.04671000"], ["84084.81000000", "0.02650000"], ["84093.22000000", "1.37685000"], ["84094.41000000", "0.00000000"], ["84103.26000000", "0.00000000"], ["84105.00000000", "0.00006000"], ["84117.70000000", "0.02983000"], ["84130.96000000", "0.00000000"], ["84191.46000000", "0.17699000"], ["84197.59000000", "0.05237000"], ["84198.11000000", "0.00000000"], ["84206.81000000", "0.05096000"], ["84228.11000000", "0.00000000"], ["84229.24000000", "0.00000000"], ["84248.80000000", "0.01000000"]], "record_time": 1742555173.035901, "EXCHANGE": "BINANCE"}
{"e": "depthUpdate", "E": 1742555174014, "s": "BTCUSDT", "U": 64607124740, "u": 64607125103, "b": [["84076.08000000", "0.47160000"], ["84076.00000000", "0.00227000"], ["84075.99000000", "0.00015000"], ["84075.83000000", "0.00007000"], ["84075.48000000", "0.00081000"], ["84075.47000000", "0.07604000"], ["84074.59000000", "0.00000000"], ["84073.16000000", "0.00000000"], ["84072.92000000", "0.00000000"], ["84072.91000000", "0.00000000"], ["84072.84000000", "0.00000000"], ["84072.54000000", "0.00014000"], ["84072.53000000", "0.02340000"], ["84072.45000000", "0.00000000"], ["84072.44000000", "0.00000000"], ["84072.26000000", "0.00000000"], ["84071.99000000", "0.00014000"], ["84071.98000000", "0.09054000"], ["84071.92000000", "0.00000000"], ["84071.91000000", "0.00000000"], ["84071.90000000", "0.01007000"], ["84071.09000000", "0.00036000"], ["84071.08000000", "0.00000000"], ["84070.93000000", "0.00000000"], ["84070.30000000", "0.00000000"], ["84070.29000000", "0.00000000"], ["84069.95000000", "0.00000000"], ["84069.84000000", "0.00000000"], ["84069.83000000", "0.06212000"], ["84069.82000000", "0.16654000"], ["84069.60000000", "0.00000000"], ["84069.59000000", "0.04000000"], ["84069.33000000", "0.00000000"], ["84069.31000000", "0.00000000"], ["84069.07000000", "0.00000000"], ["84069.06000000", "0.78544000"], ["84068.87000000", "0.00000000"], ["84068.82000000", "0.31725000"], ["84067.89000000", "0.00000000"], ["84067.56000000", "0.00000000"], ["84067.51000000", "0.08286000"], ["84067.44000000", "0.00000000"], ["84067.30000000", "0.00011000"], ["84067.16000000", "0.00050000"], ["84066.90000000", "0.00000000"], ["84063.00000000", "0.00006000"], ["84062.15000000", "0.00000000"], ["84059.37000000", "0.00095000"], ["84055.38000000", "0.00000000"], ["84054.37000000", "0.54303000"], ["84054.29000000", "0.35663000"], ["84053.89000000", "0.00000000"], ["84052.48000000", "1.73068000"], ["84051.92000000", "0.00878000"], ["84051.24000000", "0.00000000"], ["84051.08000000", "0.85703000"], ["84049.84000000", "1.34039000"], ["84038.76000000", "0.00000000"], ["84036.23000000", "0.00000000"], ["84035.89000000", "0.00000000"], ["84035.81000000", "0.00000000"], ["84033.61000000", "0.00000000"], ["84033.46000000", "0.00570000"], ["84032.04000000", "0.00000000"], ["84031.87000000", "0.00000000"], ["84027.34000000", "0.00000000"], ["84026.48000000", "0.00935000"], ["84024.01000000", "0.30174000"], ["84021.78000000", "0.01870000"], ["84009.10000000", "0.05000000"], ["84000.00000000", "0.26795000"], ["83974.07000000", "0.00000000"], ["83959.08000000", "0.00000000"], ["83958.49000000", "0.00075000"], ["83958.48000000", "0.00000000"], ["83948.01000000", "0.05096000"], ["83945.07000000", "0.05096000"], ["83922.38000000", "0.00000000"], ["83896.97000000", "0.00000000"], ["83882.83000000", "0.00063000"], ["83882.82000000", "0.00000000"], ["83861.08000000", "0.00000000"], ["83851.89000000", "0.00000000"], ["83851.61000000", "0.00400000"], ["83845.34000000", "0.00000000"], ["83800.00000000", "1.74924000"], ["83670.62000000", "0.00000000"], ["83634.69000000", "0.00011000"], ["83576.19000000", "0.00000000"], ["83576.07000000", "0.00359000"], ["83236.03000000", "0.00060000"], ["83235.98000000", "0.00000000"], ["83235.00000000", "0.05117000"], ["83234.95000000", "0.00000000"], ["75668.00000000", "0.13247000"], ["67260.87000000", "0.00058000"], ["33000.00000000", "2.93827000"], ["30301.14000000", "0.00780000"], ["30267.39000000", "0.00300000"], ["30226.96000000", "0.00000000"], ["30226.67000000", "0.00080000"], ["30225.41000000", "0.00220000"], ["30225.09000000", "0.00000000"], ["30223.13000000", "0.00340000"], ["30220.80000000", "0.00120000"], ["30220.73000000", "0.00080000"], ["30220.44000000", "0.00620000"], ["30219.16000000", "0.00060000"], ["30218.45000000", "0.00280000"], ["30209.92000000", "0.00000000"], ["30208.70000000", "0.00800000"], ["30207.60000000", "0.00260000"], ["30196.96000000", "0.00060000"], ["30195.91000000", "0.00060000"], ["30195.85000000", "0.00220000"], ["30194.44000000", "0.00000000"], ["30193.83000000", "0.00000000"], ["30193.41000000", "0.00000000"], ["30193.13000000", "0.00060000"], ["30192.35000000", "0.00000000"], ["30192.06000000", "0.00000000"], ["30191.96000000", "0.00000000"], ["30188.28000000", "0.00000000"], ["30186.41000000", "0.00240000"], ["30182.79000000", "0.00000000"], ["30181.32000000", "0.00000000"], ["30171.41000000", "0.00080000"]], "a": [["84076.09000000", "8.41486000"], ["84076.10000000", "0.15757000"], ["84076.19000000", "0.00014000"], ["84076.20000000", "0.04824000"], ["84077.75000000", "0.00000000"], ["84078.00000000", "0.02266000"], ["84078.68000000", "0.00000000"], ["84079.03000000", "0.08992000"], ["84079.52000000", "0.04000000"], ["84080.22000000", "0.11898000"], ["84080.32000000", "0.00000000"], ["84080.35000000", "0.04000000"], ["84080.40000000", "0.00014000"], ["84080.41000000", "0.69858000"], ["84080.42000000", "0.16000000"], ["84081.12000000", "0.00000000"], ["84081.20000000", "0.10000000"], ["84081.24000000", "0.05200000"], ["84081.65000000", "0.00000000"], ["84081.91000000", "0.00000000"], ["84082.38000000", "0.28033000"], ["84083.70000000", "0.01869000"], ["84083.71000000", "0.07600000"], ["84083.77000000", "0.00000000"], ["84084.57000000", "0.07200000"], ["84084.62000000", "0.00058000"], ["84085.39000000", "0.06400000"], ["84085.40000000", "0.06400000"], ["84085.46000000", "0.06000000"], ["84085.50000000", "0.02437000"], ["84085.57000000", "0.05947000"], ["84087.92000000", "0.00000000"], ["84087.98000000", "0.00000000"], ["84088.21000000", "0.89158000"], ["84088.82000000", "0.00000000"], ["84089.66000000", "0.00000000"], ["84089.67000000", "0.00000000"], ["84089.71000000", "0.00000000"], ["84090.73000000", "1.03242000"], ["84090.74000000", "1.00000000"], ["84091.83000000", "0.00935000"], ["84091.86000000", "0.05943000"], ["84092.57000000", "0.08304000"], ["84096.11000000", "0.00000000"], ["84098.81000000", "0.00000000"], ["84099.42000000", "0.00000000"], ["84100.21000000", "0.05000000"], ["84101.25000000", "0.00000000"], ["84104.61000000", "0.00000000"], ["84110.80000000", "0.02765000"], ["84110.81000000", "0.00000000"], ["84112.79000000", "0.00000000"], ["84113.99000000", "0.35663000"], ["84115.70000000", "0.05947000"], ["84115.92000000", "0.00000000"], ["84123.59000000", "0.00000000"], ["84136.49000000", "0.04000000"], ["84187.37000000", "0.35564000"], ["84191.54000000", "0.05044000"], ["84194.82000000", "0.04638000"], ["84200.44000000", "0.12000000"], ["84205.91000000", "0.00000000"], ["84208.85000000", "0.00000000"], ["84222.20000000", "0.00000000"], ["84225.25000000", "0.00000000"], ["84239.38000000", "0.00000000"], ["84243.16000000", "0.00000000"], ["84246.53000000", "0.99362000"], ["84247.96000000", "0.00000000"], ["84288.16000000", "0.01784000"], ["84332.29000000", "0.00000000"], ["86988.10000000", "0.00352000"], ["86988.22000000", "0.00000000"]], "record_time": 1742555174.037574, "EXCHANGE": "BINANCE"}
{"e": "depthUpdate", "E": 1742555175014, "s": "BTCUSDT", "U": 64607125104, "u": 64607125354, "b": [["84076.08000000", "1.03261000"], ["84075.47000000", "0.07604000"], ["84074.08000000", "0.00000000"], ["84074.07000000", "0.00000000"], ["84073.30000000", "0.00000000"], ["84073.20000000", "0.00000000"], ["84072.54000000", "0.00014000"], ["84072.53000000", "0.02340000"], ["84072.18000000", "0.00000000"], ["84072.17000000", "0.00000000"], ["84072.16000000", "0.00000000"], ["84072.00000000", "0.00234000"], ["84071.99000000", "0.04097000"], ["84071.98000000", "0.09054000"], ["84071.90000000", "0.00000000"], ["84071.75000000", "0.17155000"], ["84071.07000000", "0.00011000"], ["84070.97000000", "0.00000000"], ["84070.96000000", "0.00000000"], ["84069.83000000", "0.00000000"], ["84069.82000000", "0.00000000"], ["84069.80000000", "0.00007000"], ["84069.79000000", "0.27352000"], ["84069.72000000", "0.00000000"], ["84069.71000000", "0.00000000"], ["84069.59000000", "0.04000000"], ["84069.33000000", "0.00000000"], ["84068.82000000", "0.00000000"], ["84067.74000000", "0.00000000"], ["84067.30000000", "0.00000000"], ["84067.16000000", "0.00000000"], ["84063.20000000", "0.00000000"], ["84063.10000000", "0.00000000"], ["84054.38000000", "0.71284000"], ["84051.92000000", "0.00000000"], ["84036.62000000", "0.00000000"], ["84032.78000000", "0.59502000"], ["84017.50000000", "0.19148000"], ["84006.05000000", "0.22577000"], ["84002.59000000", "0.00000000"], ["83999.35000000", "0.00000000"], ["83998.95000000", "0.01193000"], ["83997.31000000", "0.00000000"], ["83996.74000000", "0.00000000"], ["83977.68000000", "1.38907000"], ["83974.78000000", "0.04638000"], ["83972.23000000", "0.04638000"], ["83969.38000000", "0.04638000"], ["83922.40000000", "0.99313000"], ["83917.76000000", "0.00050000"], ["83856.85000000", "0.00400000"], ["83851.61000000", "0.00000000"], ["80673.60000000", "0.03568000"], ["75668.00000000", "0.13247000"], ["67260.87000000", "0.00058000"], ["42000.00000000", "6.85261000"], ["33000.00000000", "2.93827000"]], "a": [["84076.09000000", "8.42997000"], ["84076.10000000", "0.00028000"], ["84076.19000000", "0.00000000"], ["84076.20000000", "0.00000000"], ["84076.73000000", "0.00014000"], ["84077.75000000", "0.00014000"], ["84077.81000000", "0.13532000"], ["84078.00000000", "0.02273000"], ["84078.26000000", "0.00014000"], ["84078.27000000", "0.08992000"], ["84079.03000000", "0.00000000"], ["84079.12000000", "0.04817000"], ["84080.00000000", "0.00006000"], ["84080.40000000", "0.00014000"], ["84081.06000000", "0.11898000"], ["84082.38000000", "0.56296000"], ["84084.80000000", "0.00000000"], ["84085.68000000", "0.85668000"], ["84094.90000000", "0.00400000"], ["84099.25000000", "0.37363000"], ["84100.21000000", "0.00000000"], ["84100.31000000", "0.00000000"], ["84101.41000000", "0.05000000"], ["84110.17000000", "0.09773000"], ["84110.80000000", "0.00000000"], ["84135.89000000", "0.00000000"], ["84146.14000000", "0.02380000"], ["84154.81000000", "0.00841000"], ["84156.21000000", "0.00000000"], ["84172.28000000", "0.00000000"], ["84182.33000000", "0.05496000"], ["84185.96000000", "0.04757000"], ["84185.97000000", "0.05496000"], ["84188.47000000", "0.04757000"], ["84189.40000000", "0.04638000"], ["84197.31000000", "0.09276000"], ["84197.58000000", "0.00000000"], ["84200.26000000", "0.05296000"], ["84200.36000000", "0.00000000"], ["84205.20000000", "0.05096000"], ["84206.88000000", "0.05196000"], ["84218.55000000", "0.00000000"], ["84219.18000000", "0.00000000"], ["84221.30000000", "0.00000000"], ["84224.51000000", "0.00000000"], ["84226.17000000", "0.04637000"], ["84241.51000000", "0.05196000"], ["84247.10000000", "0.01000000"], ["84248.80000000", "0.00000000"], ["84288.16000000", "0.00000000"], ["84916.84000000", "0.00000000"]], "record_time": 1742555175.035787, "EXCHANGE": "BINANCE"}
{"e": "depthUpdate", "E": 1742555176014, "s": "BTCUSDT", "U": 64607125355, "u": 64607125518, "b": [["84076.08000000", "1.01667000"], ["84072.53000000", "0.02340000"], ["84072.00000000", "0.00220000"], ["84071.99000000", "0.00014000"], ["84071.98000000", "0.09054000"], ["84071.90000000", "0.00500000"], ["84071.77000000", "0.00000000"], ["84071.76000000", "0.00014000"], ["84071.75000000", "0.17162000"], ["84071.07000000", "0.00000000"], ["84070.20000000", "0.02487000"], ["84069.80000000", "0.00000000"], ["84068.38000000", "0.00011000"], ["84067.53000000", "0.00000000"], ["84057.73000000", "0.00008000"], ["84054.38000000", "0.00000000"], ["84053.28000000", "0.00000000"], ["84052.87000000", "0.00000000"], ["84052.77000000", "0.03569000"], ["84051.92000000", "0.00904000"], ["84046.26000000", "0.00000000"], ["84033.41000000", "0.01300000"], ["84006.06000000", "0.47231000"], ["83998.95000000", "0.00000000"], ["83988.72000000", "0.00100000"], ["83967.75000000", "0.00000000"], ["83958.50000000", "0.00075000"], ["83958.49000000", "0.00000000"], ["83946.57000000", "0.00000000"], ["83941.09000000", "0.00119000"], ["83940.99000000", "0.00000000"], ["83930.40000000", "0.00621000"], ["83917.76000000", "0.00000000"], ["83917.56000000", "0.00050000"], ["83916.33000000", "0.00000000"], ["83882.84000000", "0.00063000"], ["83882.83000000", "0.00000000"], ["83856.85000000", "0.00000000"], ["83849.06000000", "0.00400000"], ["83095.14000000", "0.20000000"], ["82995.14000000", "0.40028000"], ["80673.60000000", "0.00000000"], ["79800.00000000", "8.29820000"], ["75668.47000000", "0.00025000"], ["75668.00000000", "0.13247000"], ["67260.87000000", "0.00058000"], ["42000.00000000", "6.85161000"], ["33000.00000000", "2.93827000"], ["30267.39000000", "0.00320000"], ["20002.00000000", "0.00000000"], ["20001.00000000", "0.02099000"]], "a": [["84076.09000000", "8.63718000"], ["84078.83000000", "0.00007000"], ["84078.84000000", "0.15409000"], ["84080.40000000", "0.00000000"], ["84082.02000000", "1.10816000"], ["84086.54000000", "0.02378000"], ["84088.89000000", "0.00000000"], ["84090.21000000", "0.71399000"], ["84097.45000000", "0.59502000"], ["84104.46000000", "0.00000000"], ["84113.26000000", "0.35663000"], ["84113.99000000", "0.00000000"], ["84115.58000000", "0.23065000"], ["84129.08000000", "0.59438000"], ["84130.87000000", "0.00000000"], ["84132.15000000", "0.00000000"], ["84163.43000000", "0.00100000"], ["84165.56000000", "0.00084000"], ["84174.67000000", "0.00000000"], ["84188.46000000", "0.04638000"], ["84189.12000000", "0.04757000"], ["84192.20000000", "0.05296000"], ["84192.42000000", "0.04638000"], ["84195.05000000", "0.00000000"], ["84195.25000000", "0.05296000"], ["84195.58000000", "0.16163000"], ["84196.85000000", "0.04638000"], ["84199.99000000", "0.76681000"], ["84217.89000000", "0.00007000"], ["84224.41000000", "0.00000000"], ["84224.52000000", "0.00000000"], ["84224.70000000", "0.00000000"], ["84226.17000000", "0.00000000"], ["84244.12000000", "0.00119000"], ["84254.08000000", "0.00119000"], ["84257.35000000", "0.00000000"], ["84267.99000000", "0.00000000"], ["84935.71000000", "0.20000000"], ["85035.71000000", "0.60118000"], ["85327.80000000", "0.17604000"], ["85349.10000000", "0.00000000"]], "record_time": 1742555176.036505, "EXCHANGE": "BINANCE"}
{"e": "depthUpdate", "E": 1742555177014, "s": "BTCUSDT", "U": 64607125519, "u": 64607125689, "b": [["84076.08000000", "1.02489000"], ["84076.07000000", "0.00050000"], ["84071.98000000", "0.09054000"], ["84071.90000000", "0.01007000"], ["84071.86000000", "0.02207000"], ["84071.77000000", "0.00014000"], ["84071.76000000", "0.15453000"], ["84071.75000000", "0.17155000"], ["84067.53000000", "0.02369000"], ["84067.51000000", "0.00000000"], ["84063.00000000", "0.02418000"], ["84054.30000000", "0.71284000"], ["84051.92000000", "0.00000000"], ["84051.08000000", "0.00000000"], ["84039.90000000", "0.69024000"], ["84038.66000000", "0.85715000"], ["84035.34000000", "0.00000000"], ["84034.35000000", "0.00000000"], ["84033.83000000", "0.00000000"], ["84033.41000000", "0.00000000"], ["84027.79000000", "0.00441000"], ["84027.71000000", "0.00000000"], ["84024.20000000", "0.00000000"], ["84016.60000000", "0.00000000"], ["84013.92000000", "0.45341000"], ["84012.60000000", "0.59438000"], ["84011.62000000", "0.47551000"], ["83949.48000000", "0.00180000"], ["83949.25000000", "0.00000000"], ["83917.56000000", "0.00000000"], ["83915.07000000", "0.00000000"], ["83854.60000000", "0.00400000"], ["83849.06000000", "0.00000000"], ["80673.60000000", "0.03568000"], ["75668.47000000", "0.00000000"], ["75668.00000000", "0.13247000"], ["70000.00000000", "155.26908000"], ["67260.87000000", "0.00058000"], ["33000.00000000", "2.93827000"], ["30267.39000000", "0.00340000"]], "a": [["84076.09000000", "8.43883000"], ["84076.10000000", "0.00014000"], ["84082.38000000", "0.34100000"], ["84083.95000000", "0.35663000"], ["84085.68000000", "0.00000000"], ["84091.86000000", "0.00000000"], ["84094.90000000", "0.00000000"], ["84095.33000000", "1.34819000"], ["84098.33000000", "0.85655000"], ["84099.42000000", "0.05943000"], ["84149.46000000", "0.00041000"], ["84158.47000000", "0.60067000"], ["84161.47000000", "0.00000000"], ["84162.07000000", "0.04197000"], ["84176.51000000", "0.05496000"], ["84181.99000000", "0.05496000"], ["84185.96000000", "0.10253000"], ["84190.75000000", "0.00000000"], ["84199.99000000", "0.71385000"], ["84200.26000000", "0.00000000"], ["84216.80000000", "0.00000000"], ["84217.57000000", "0.00000000"], ["84221.79000000", "0.00000000"], ["84224.59000000", "0.00000000"], ["84224.71000000", "0.00035000"], ["84226.21000000", "0.00000000"], ["84226.22000000", "0.00000000"], ["84237.63000000", "0.00000000"], ["84247.10000000", "0.00000000"], ["84280.00000000", "0.05235000"], ["84286.52000000", "0.00000000"]], "record_time": 1742555177.035671, "EXCHANGE": "BINANCE"}
{"e": "depthUpdate", "E": 1742555178014, "s": "BTCUSDT", "U": 64607125690, "u": 64607125777, "b": [["84076.08000000", "1.01407000"], ["84076.06000000", "0.00035000"], ["84071.98000000", "0.09054000"], ["84071.90000000", "0.00500000"], ["84071.86000000", "0.02214000"], ["84071.38000000", "0.27440000"], ["84069.79000000", "0.00000000"], ["84068.05000000", "0.01518000"], ["84066.58000000", "0.00000000"], ["84035.74000000", "0.24462000"], ["84032.78000000", "0.00000000"], ["84030.08000000", "0.59504000"], ["84018.60000000", "0.00000000"], ["84018.08000000", "0.01518000"], ["84012.88000000", "0.00000000"], ["83970.56000000", "0.01862000"], ["83915.07000000", "0.00463000"], ["83692.65000000", "0.00000000"], ["83651.31000000", "1.19005000"], ["83272.08000000", "0.00000000"], ["83230.96000000", "1.78508000"], ["82851.52000000", "0.00000000"], ["82810.60000000", "0.59503000"], ["75668.00000000", "0.13247000"], ["67260.87000000", "0.00058000"], ["33000.00000000", "2.93827000"]], "a": [["84076.09000000", "8.13843000"], ["84079.12000000", "0.00000000"], ["84088.54000000", "0.01862000"], ["84090.00000000", "0.02760000"], ["84110.56000000", "0.01518000"], ["84136.01000000", "0.02380000"], ["84146.14000000", "0.00000000"], ["84154.81000000", "0.00000000"], ["84156.54000000", "0.00960000"], ["84190.44000000", "0.18320000"], ["84194.19000000", "0.11223000"], ["84194.35000000", "0.04638000"], ["84195.24000000", "0.00000000"], ["84199.66000000", "0.00000000"], ["84205.97000000", "0.00000000"], ["84208.00000000", "0.00353000"], ["84214.41000000", "0.19368000"], ["84215.99000000", "0.00000000"], ["84222.66000000", "0.00000000"], ["84245.94000000", "0.99478000"], ["84246.53000000", "0.00000000"], ["84246.90000000", "0.01000000"], ["84247.10000000", "0.00000000"], ["84492.02000000", "1.19005000"], ["84533.77000000", "0.00000000"], ["84912.38000000", "1.78524000"], ["84954.34000000", "0.00000000"], ["85332.74000000", "0.59503000"], ["85374.90000000", "0.00000000"]], "record_time": 1742555178.035389, "EXCHANGE": "BINANCE"}
{"e": "depthUpdate", "E": 1742555179014, "s": "BTCUSDT", "U": 64607125778, "u": 64607125874, "b": [["84076.08000000", "1.01386000"], ["84075.47000000", "0.07604000"], ["84073.84000000", "0.00014000"], ["84073.83000000", "0.26906000"], ["84072.54000000", "0.00000000"], ["84072.53000000", "0.02340000"], ["84072.52000000", "0.00000000"], ["84071.99000000", "0.00000000"], ["84071.98000000", "0.09054000"], ["84071.90000000", "0.00000000"], ["84071.86000000", "0.02207000"], ["84071.77000000", "0.00000000"], ["84071.76000000", "0.07247000"], ["84071.38000000", "0.00000000"], ["84057.73000000", "0.00000000"], ["84051.80000000", "0.00897000"], ["84033.41000000", "0.01300000"], ["84001.32000000", "0.01930000"], ["83979.38000000", "0.01862000"], ["83970.56000000", "0.00000000"], ["83958.51000000", "0.00075000"], ["83958.50000000", "0.00000000"], ["83932.80000000", "0.00006000"], ["83915.99000000", "0.05950000"], ["83882.85000000", "0.00063000"], ["83882.84000000", "0.00000000"], ["83748.26000000", "0.00000000"], ["83739.77000000", "0.00149000"], ["75668.00000000", "0.13247000"], ["67260.87000000", "0.00058000"], ["60000.00000000", "73.17018000"], ["54000.00000000", "7.02457000"], ["33000.00000000", "2.93827000"], ["30267.39000000", "0.00360000"]], "a": [["84076.09000000", "8.43607000"], ["84080.20000000", "0.11898000"], ["84080.22000000", "0.00000000"], ["84081.04000000", "0.11898000"], ["84081.06000000", "0.00000000"], ["84085.80000000", "0.00500000"], ["84088.54000000", "0.00000000"], ["84112.20000000", "0.01839000"], ["84130.29000000", "0.01930000"], ["84158.47000000", "0.84327000"], ["84161.47000000", "1.10872000"], ["84205.39000000", "0.05096000"], ["92285.24000000", "0.00374000"]], "record_time": 1742555179.036264, "EXCHANGE": "BINANCE"}
{"e": "depthUpdate", "E": 1742555180014, "s": "BTCUSDT", "U": 64607125875, "u": 64607126079, "b": [["84076.08000000", "0.46350000"], ["84075.47000000", "0.07604000"], ["84073.84000000", "0.00000000"], ["84073.83000000", "0.00000000"], ["84072.54000000", "0.00014000"], ["84072.53000000", "0.02340000"], ["84072.00000000", "0.00220000"], ["84071.99000000", "0.00000000"], ["84071.98000000", "0.00000000"], ["84071.87000000", "0.00000000"], ["84071.86000000", "0.00000000"], ["84071.76000000", "0.00000000"], ["84071.75000000", "0.00000000"], ["84070.20000000", "0.02494000"], ["84069.61000000", "0.00014000"], ["84069.60000000", "0.08729000"], ["84069.59000000", "0.00000000"], ["84069.33000000", "0.00014000"], ["84069.31000000", "0.31965000"], ["84069.19000000", "0.00000000"], ["84069.06000000", "0.00000000"], ["84068.98000000", "0.02208000"], ["84068.76000000", "0.00000000"], ["84068.38000000", "0.00000000"], ["84068.05000000", "0.00000000"], ["84067.53000000", "0.00000000"], ["84066.92000000", "0.02852000"], ["84066.61000000", "0.78546000"], ["84065.83000000", "0.00011000"], ["84065.32000000", "0.01518000"], ["84064.80000000", "0.00000000"], ["84063.58000000", "0.00000000"], ["84063.00000000", "0.00006000"], ["84060.55000000", "0.04000000"], ["84059.45000000", "0.00090000"], ["84059.43000000", "0.00000000"], ["84054.30000000", "0.00000000"], ["84051.80000000", "0.00000000"], ["84050.44000000", "0.00000000"], ["84047.02000000", "0.02805000"], ["84034.15000000", "0.23088000"], ["84033.41000000", "0.00000000"], ["84031.51000000", "0.04000000"], ["84026.48000000", "0.00000000"], ["84024.11000000", "0.05000000"], ["84021.88000000", "0.04942000"], ["84021.78000000", "0.00000000"], ["84014.51000000", "0.00000000"], ["84009.10000000", "0.00000000"], ["83979.38000000", "0.00000000"], ["83952.22000000", "0.71284000"], ["83933.25000000", "1.84932000"], ["83235.31000000", "0.00000000"], ["83072.07000000", "0.00150000"], ["83072.05000000", "0.00000000"], ["83069.99000000", "0.00000000"], ["83027.38000000", "0.00000000"], ["81408.44000000", "0.00000000"], ["80673.60000000", "0.00000000"], ["80656.80000000", "0.03568000"], ["75668.00000000", "0.13247000"], ["67260.87000000", "0.00058000"], ["33000.00000000", "2.93827000"]], "a": [["84076.09000000", "9.38627000"], ["84078.42000000", "0.01189000"], ["84078.83000000", "0.00000000"], ["84080.40000000", "0.26126000"], ["84081.99000000", "0.00000000"], ["84082.38000000", "0.62241000"], ["84082.55000000", "0.02378000"], ["84083.70000000", "0.00000000"], ["84083.78000000", "0.00115000"], ["84085.11000000", "0.71284000"], ["84085.69000000", "0.01248000"], ["84086.59000000", "0.05943000"], ["84089.69000000", "0.02378000"], ["84090.00000000", "0.02760000"], ["84091.83000000", "0.00000000"], ["84091.85000000", "0.00000000"], ["84091.86000000", "0.05943000"], ["84094.37000000", "0.59503000"], ["84097.45000000", "0.00000000"], ["84099.42000000", "0.00000000"], ["84101.04000000", "0.05947000"], ["84101.11000000", "0.00358000"], ["84104.07000000", "0.00647000"], ["84106.09000000", "0.05947000"], ["84106.64000000", "0.00000000"], ["84113.26000000", "0.00000000"], ["84115.47000000", "0.00000000"], ["84116.68000000", "0.00934000"], ["84117.11000000", "0.01868000"], ["84118.58000000", "0.00000000"], ["84123.06000000", "0.03609000"], ["84129.08000000", "0.00000000"], ["84136.35000000", "0.00000000"], ["84144.18000000", "0.02854000"], ["84147.09000000", "0.00000000"], ["84185.96000000", "0.15749000"], ["84204.97000000", "0.00000000"], ["84216.98000000", "0.40593000"], ["84217.21000000", "0.14889000"], ["84280.42000000", "0.00000000"], ["84314.61000000", "0.00000000"], ["84338.86000000", "0.00000000"], ["86464.08000000", "0.00000000"], ["86464.10000000", "0.00147000"]], "record_time": 1742555180.036873, "EXCHANGE": "BINANCE"}
{"e": "depthUpdate", "E": 1742555181014, "s": "BTCUSDT", "U": 64607126080, "u": 64607126309, "b": [["84076.08000000", "0.47199000"], ["84073.30000000", "0.00000000"], ["84073.20000000", "0.00000000"], ["84072.53000000", "0.02340000"], ["84071.23000000", "0.00014000"], ["84071.22000000", "0.16320000"], ["84070.33000000", "0.00000000"], ["84070.32000000", "0.00000000"], ["84070.26000000", "0.00000000"], ["84070.25000000", "0.11886000"], ["84070.24000000", "0.28321000"], ["84070.20000000", "0.02487000"], ["84069.61000000", "0.00000000"], ["84069.60000000", "0.08722000"], ["84069.44000000", "0.00000000"], ["84069.43000000", "0.00000000"], ["84069.33000000", "0.00000000"], ["84069.31000000", "0.00000000"], ["84064.55000000", "0.00000000"], ["84063.87000000", "0.04000000"], ["84063.20000000", "0.00000000"], ["84063.10000000", "0.00000000"], ["84063.03000000", "0.04000000"], ["84058.82000000", "0.04000000"], ["84057.94000000", "0.04000000"], ["84050.97000000", "0.00899000"], ["84047.02000000", "0.00000000"], ["84044.88000000", "0.00000000"], ["84044.56000000", "0.00000000"], ["84043.59000000", "0.02805000"], ["84034.91000000", "0.03855000"], ["84033.46000000", "0.00000000"], ["84009.40000000", "0.00000000"], ["83998.72000000", "0.00013000"], ["83994.54000000", "0.00000000"], ["83993.68000000", "0.00000000"], ["83989.45000000", "0.00000000"], ["83977.68000000", "0.00000000"], ["83974.85000000", "1.38907000"], ["83922.40000000", "0.99313000"], ["83894.99000000", "0.00000000"], ["83854.60000000", "0.00000000"], ["83845.04000000", "0.00400000"], ["83236.03000000", "0.00000000"], ["83235.00000000", "0.05057000"], ["83232.03000000", "0.00060000"], ["83231.00000000", "0.00060000"], ["75668.00000000", "0.13247000"], ["67260.87000000", "0.00058000"], ["33000.00000000", "2.93827000"], ["30267.39000000", "0.00380000"], ["21199.25000000", "0.00024000"], ["20002.00000000", "0.00000000"], ["20001.00000000", "0.02099000"]], "a": [["84076.09000000", "9.38620000"], ["84077.14000000", "0.00116000"], ["84079.85000000", "0.00059000"], ["84080.41000000", "0.41345000"], ["84081.74000000", "0.00059000"], ["84082.02000000", "0.51378000"], ["84082.84000000", "0.00174000"], ["84083.95000000", "0.00000000"], ["84084.80000000", "0.00000000"], ["84085.80000000", "0.00000000"], ["84090.00000000", "0.02260000"], ["84090.31000000", "0.00000000"], ["84090.51000000", "0.00058000"], ["84094.37000000", "0.00000000"], ["84094.90000000", "0.00400000"], ["84097.45000000", "0.59502000"], ["84099.81000000", "0.05000000"], ["84101.31000000", "0.06002000"], ["84101.41000000", "0.00000000"], ["84106.41000000", "0.02802000"], ["84107.11000000", "0.00000000"], ["84112.52000000", "0.35663000"], ["84116.68000000", "0.00000000"], ["84117.11000000", "0.00000000"], ["84124.96000000", "0.19493000"], ["84127.83000000", "0.59438000"], ["84179.99000000", "0.05496000"], ["84181.98000000", "0.05496000"], ["84185.96000000", "0.26002000"], ["84188.81000000", "0.05496000"], ["84192.06000000", "0.60264000"], ["84192.97000000", "0.05496000"], ["84195.77000000", "0.05496000"], ["84198.48000000", "0.05496000"], ["84202.11000000", "0.05496000"], ["84202.18000000", "0.05496000"], ["84244.23000000", "0.01141000"], ["84771.26000000", "0.00060000"], ["84775.07000000", "0.00000000"], ["84779.78000000", "0.00040000"], ["84782.77000000", "0.00000000"]], "record_time": 1742555181.03631, "EXCHANGE": "BINANCE"}
{"e": "depthUpdate", "E": 1742555182014, "s": "BTCUSDT", "U": 64607126310, "u": 64607126436, "b": [["84076.08000000", "0.51910000"], ["84068.24000000", "0.78545000"], ["84067.77000000", "0.00011000"], ["84067.32000000", "0.01518000"], ["84066.92000000", "0.05175000"], ["84066.61000000", "0.00000000"], ["84065.83000000", "0.00000000"], ["84065.32000000", "0.00000000"], ["84058.80000000", "0.02383000"], ["84054.30000000", "0.71284000"], ["84031.08000000", "0.00480000"], ["84003.52000000", "0.00000000"], ["83995.12000000", "0.00000000"], ["83993.91000000", "0.00298000"], ["83986.71000000", "0.00000000"], ["83985.51000000", "0.00597000"], ["83978.31000000", "0.00000000"], ["83977.11000000", "0.00895000"], ["83969.91000000", "0.00000000"], ["83968.71000000", "0.01194000"], ["83959.36000000", "0.01493000"], ["83958.52000000", "0.00075000"], ["83958.51000000", "0.00000000"], ["83947.67000000", "0.00008000"], ["83929.02000000", "0.00000000"], ["83922.40000000", "0.00000000"], ["83915.07000000", "0.00000000"], ["83895.00000000", "0.00000000"], ["83882.86000000", "0.00063000"], ["83882.85000000", "0.00000000"], ["83874.88000000", "0.01525000"], ["83850.47000000", "0.00400000"], ["83845.04000000", "0.00000000"], ["83232.03000000", "0.00000000"], ["83231.00000000", "0.00000000"], ["83207.51000000", "0.00040000"], ["83198.77000000", "0.00060000"], ["83069.99000000", "0.02347000"], ["83000.00000000", "35.08888000"], ["79800.00000000", "8.29820000"], ["75668.00000000", "0.13247000"], ["67260.87000000", "0.00058000"], ["33000.00000000", "2.93827000"]], "a": [["84076.09000000", "8.74207000"], ["84076.10000000", "0.00014000"], ["84076.73000000", "0.00014000"], ["84077.75000000", "0.00014000"], ["84078.00000000", "0.02273000"], ["84078.26000000", "0.00000000"], ["84078.27000000", "0.00000000"], ["84078.83000000", "0.00014000"], ["84081.44000000", "0.00059000"], ["84081.72000000", "0.00059000"], ["84085.64000000", "0.00059000"], ["84090.00000000", "0.02760000"], ["84091.96000000", "0.59438000"], ["84097.58000000", "0.37689000"], ["84112.10000000", "0.00000000"], ["84124.96000000", "0.01899000"], ["84127.83000000", "0.00000000"], ["84129.80000000", "0.59438000"], ["84136.01000000", "0.00000000"], ["84146.07000000", "0.02380000"], ["84149.06000000", "0.01017000"], ["84152.08000000", "0.00298000"], ["84160.49000000", "0.00597000"], ["84163.56000000", "0.00000000"], ["84168.11000000", "0.00000000"], ["84168.90000000", "0.00895000"], ["84176.52000000", "0.00000000"], ["84177.31000000", "0.01194000"], ["84184.93000000", "0.33825000"], ["84185.73000000", "0.01493000"], ["84193.34000000", "0.00000000"], ["84198.74000000", "0.05296000"], ["84199.65000000", "0.00000000"], ["84201.76000000", "0.00000000"], ["84202.27000000", "0.05096000"], ["84205.27000000", "0.05096000"], ["84211.21000000", "0.09839000"], ["84213.94000000", "0.00000000"], ["84245.93000000", "0.99026000"], ["84245.94000000", "0.00000000"], ["84246.90000000", "0.00000000"], ["84334.00000000", "0.00000000"], ["84756.72000000", "0.00060000"], ["84771.26000000", "0.00000000"], ["84772.31000000", "0.00060000"], ["84779.78000000", "0.00000000"]], "record_time": 1742555182.03583, "EXCHANGE": "BINANCE"}
{"e": "depthUpdate", "E": 1742555183014, "s": "BTCUSDT", "U": 64607126437, "u": 64607126520, "b": [["84076.08000000", "0.52063000"], ["84068.24000000", "0.00000000"], ["84066.58000000", "0.78546000"], ["84054.30000000", "0.71284000"], ["84052.98000000", "0.00000000"], ["84052.77000000", "0.00000000"], ["84052.56000000", "0.03569000"], ["84050.97000000", "0.00000000"], ["84049.84000000", "1.44728000"], ["84033.53000000", "0.04000000"], ["84033.20000000", "0.00000000"], ["83977.68000000", "1.38907000"], ["83974.85000000", "0.00000000"], ["83922.42000000", "0.99313000"], ["83915.27000000", "0.00050000"], ["83915.07000000", "0.00000000"], ["83224.65000000", "0.00040000"], ["83215.91000000", "0.00060000"], ["83207.51000000", "0.00000000"], ["83198.77000000", "0.00000000"], ["75668.00000000", "0.13247000"], ["67260.87000000", "0.00058000"], ["33000.00000000", "2.93827000"], ["30267.39000000", "0.00400000"]], "a": [["84076.09000000", "8.07816000"], ["84077.14000000", "0.00058000"], ["84078.98000000", "0.08992000"], ["84083.82000000", "0.35663000"], ["84085.80000000", "0.00500000"], ["84094.90000000", "0.00000000"], ["84095.48000000", "0.00000000"], ["84099.81000000", "0.00000000"], ["84107.11000000", "0.00000000"], ["84121.00000000", "0.00000000"], ["84193.99000000", "0.09276000"], ["84194.71000000", "0.05296000"], ["84197.27000000", "0.05096000"], ["84198.74000000", "0.00000000"], ["84198.89000000", "0.05496000"], ["84200.31000000", "0.05096000"], ["84202.18000000", "0.00000000"], ["84206.81000000", "0.00000000"], ["84208.15000000", "0.04197000"], ["84240.90000000", "0.00000000"], ["84241.51000000", "0.00000000"], ["84245.90000000", "0.01000000"], ["84756.72000000", "0.00000000"], ["84769.63000000", "0.00060000"], ["84772.31000000", "0.00000000"], ["84785.22000000", "0.00060000"], ["85327.80000000", "0.11735000"], ["85349.10000000", "0.00000000"]], "record_time": 1742555183.035583, "EXCHANGE": "BINANCE"}
{"e": "depthUpdate", "E": 1742555184014, "s": "BTCUSDT", "U": 64607126521, "u": 64607126608, "b": [["84076.08000000", "0.48369000"], ["84070.25000000", "0.03372000"], ["84070.24000000", "0.00000000"], ["84069.33000000", "0.00014000"], ["84066.37000000", "0.25754000"], ["84054.30000000", "0.00000000"], ["84052.56000000", "0.00000000"], ["84052.55000000", "0.03569000"], ["84050.71000000", "0.00910000"], ["84033.53000000", "0.00000000"], ["84031.08000000", "0.00000000"], ["84028.92000000", "0.00690000"], ["84024.11000000", "0.00000000"], ["83977.68000000", "0.00000000"], ["83922.42000000", "0.00000000"], ["83895.00000000", "0.99313000"], ["83856.43000000", "0.00400000"], ["83850.47000000", "0.00000000"], ["83069.99000000", "0.00000000"], ["83027.38000000", "0.00000000"], ["75668.00000000", "0.13247000"], ["67260.87000000", "0.00058000"], ["33000.00000000", "2.93827000"], ["30267.39000000", "0.00420000"], ["21199.25000000", "0.00000000"]], "a": [["84076.09000000", "8.22811000"], ["84076.10000000", "0.00014000"], ["84078.00000000", "0.02273000"], ["84090.00000000", "0.02760000"], ["84101.91000000", "0.05000000"], ["84112.52000000", "0.00000000"], ["84112.88000000", "0.00540000"], ["84148.46000000", "0.46114000"], ["84156.54000000", "0.00119000"], ["84160.97000000", "0.00841000"], ["84164.50000000", "0.00000000"], ["84168.51000000", "0.00000000"], ["84190.83000000", "0.05296000"], ["84193.81000000", "0.04638000"], ["84195.80000000", "0.05296000"], ["84195.99000000", "0.00000000"], ["84196.54000000", "0.00000000"], ["84202.93000000", "0.05196000"], ["84239.45000000", "0.00000000"], ["84240.11000000", "0.00000000"], ["84243.99000000", "0.01000000"], ["84244.49000000", "0.00000000"], ["84245.90000000", "0.00000000"], ["84331.08000000", "0.00237000"], ["89400.00000000", "1.43653000"]], "record_time": 1742555184.036711, "EXCHANGE": "BINANCE"}
{"e": "depthUpdate", "E": 1742555185014, "s": "BTCUSDT", "U": 64607126609, "u": 64607129508, "b": [["84076.08000000", "0.00000000"], ["84076.07000000", "0.00000000"], ["84076.06000000", "0.00000000"], ["84076.00000000", "0.00000000"], ["84075.99000000", "0.00000000"], ["84075.83000000", "0.00000000"], ["84075.68000000", "0.00000000"], ["84075.49000000", "0.00000000"], ["84075.48000000", "0.00000000"], ["84075.47000000", "0.00000000"], ["84074.96000000", "0.00000000"], ["84073.48000000", "0.00000000"], ["84072.87000000", "0.00000000"], ["84072.72000000", "0.00000000"], ["84072.56000000", "0.00000000"], ["84072.55000000", "0.00000000"], ["84072.54000000", "0.00000000"], ["84072.53000000", "0.00000000"], ["84072.52000000", "0.00000000"], ["84072.01000000", "0.00000000"], ["84072.00000000", "0.00000000"], ["84071.99000000", "0.00000000"], ["84071.98000000", "0.00000000"], ["84071.85000000", "0.00000000"], ["84071.59000000", "0.00000000"], ["84071.49000000", "0.00000000"], ["84071.31000000", "0.00000000"], ["84071.23000000", "0.00000000"], ["84071.22000000", "0.00000000"], ["84071.09000000", "0.00000000"], ["84071.04000000", "0.00000000"], ["84070.46000000", "0.00000000"], ["84070.45000000", "0.00000000"], ["84070.28000000", "0.00000000"], ["84070.25000000", "0.00000000"], ["84070.21000000", "0.00000000"], ["84070.20000000", "0.00000000"], ["84070.12000000", "0.00000000"], ["84069.61000000", "0.00000000"], ["84069.60000000", "0.00000000"], ["84069.57000000", "0.00000000"], ["84069.38000000", "0.00000000"], ["84069.33000000", "0.00000000"], ["84069.32000000", "0.00000000"], ["84069.03000000", "0.00000000"], ["84069.02000000", "0.00000000"], ["84068.99000000", "0.00000000"], ["84068.98000000", "0.00000000"], ["84068.58000000", "0.00000000"], ["84068.20000000", "0.00000000"], ["84068.01000000", "0.00000000"], ["84068.00000000", "0.00000000"], ["84067.92000000", "0.00000000"], ["84067.91000000", "0.00000000"], ["84067.80000000", "0.00000000"], ["84067.77000000", "0.00000000"], ["84067.47000000", "0.00000000"], ["84067.46000000", "0.00000000"], ["84067.33000000", "0.00000000"], ["84067.32000000", "0.00000000"], ["84067.01000000", "0.00000000"], ["84066.94000000", "0.00000000"], ["84066.93000000", "0.00000000"], ["84066.92000000", "0.00000000"], ["84066.87000000", "0.00000000"], ["84066.60000000", "0.00000000"], ["84066.59000000", "0.00000000"], ["84066.58000000", "0.00000000"], ["84066.37000000", "0.00000000"], ["84065.79000000", "0.00000000"], ["84065.78000000", "0.00000000"], ["84065.53000000", "0.00000000"], ["84065.45000000", "0.00000000"], ["84065.28000000", "0.00000000"], ["84065.01000000", "0.00000000"], ["84064.87000000", "0.00000000"], ["84064.86000000", "3.30457000"], ["84064.85000000", "0.00058000"], ["84064.84000000", "0.00034000"], ["84064.67000000", "0.00257000"], ["84064.66000000", "0.00092000"], ["84064.65000000", "0.08020000"], ["84064.61000000", "0.00021000"], ["84064.60000000", "0.04020000"], ["84064.46000000", "0.00014000"], ["84064.45000000", "0.16936000"], ["84064.44000000", "0.00024000"], ["84064.38000000", "0.00000000"], ["84064.27000000", "0.00000000"], ["84064.26000000", "0.00000000"], ["84064.06000000", "0.00014000"], ["84064.05000000", "0.26205000"], ["84064.00000000", "0.00235000"], ["84063.87000000", "0.04006000"], ["84063.81000000", "0.00000000"], ["84063.49000000", "0.00000000"], ["84063.48000000", "0.00000000"], ["84063.40000000", "0.00000000"], ["84063.31000000", "0.00000000"], ["84063.19000000", "0.00321000"], ["84063.03000000", "0.04000000"], ["84063.00000000", "0.00000000"], ["84062.97000000", "0.00000000"], ["84062.96000000", "0.00006000"], ["84062.42000000", "0.00000000"], ["84062.20000000", "0.04000000"], ["84062.01000000", "0.00026000"], ["84062.00000000", "0.02379000"], ["84061.96000000", "0.00000000"], ["84061.73000000", "0.02362000"], ["84061.66000000", "0.00000000"], ["84061.58000000", "0.00000000"], ["84061.49000000", "0.00000000"], ["84061.34000000", "0.02318000"], ["84061.06000000", "0.00000000"], ["84060.97000000", "0.00000000"], ["84060.92000000", "0.00000000"], ["84060.72000000", "0.00011000"], ["84060.57000000", "0.00000000"], ["84060.55000000", "0.04000000"], ["84060.44000000", "0.04000000"], ["84060.43000000", "0.04000000"], ["84060.21000000", "0.01518000"], ["84060.18000000", "0.00000000"], ["84060.11000000", "0.00000000"], ["84060.06000000", "0.00500000"], ["84059.98000000", "0.00500000"], ["84059.93000000", "0.00000000"], ["84059.78000000", "0.00046000"], ["84059.77000000", "0.79620000"], ["84059.58000000", "0.00000000"], ["84059.27000000", "0.47551000"], ["84059.22000000", "0.16521000"], ["84059.14000000", "0.01000000"], ["84058.99000000", "0.00000000"], ["84058.80000000", "0.00006000"], ["84058.65000000", "0.00000000"], ["84058.45000000", "0.00000000"], ["84058.38000000", "0.00000000"], ["84058.25000000", "0.00000000"], ["84058.17000000", "0.78554000"], ["84058.14000000", "0.01189000"], ["84058.05000000", "0.00000000"], ["84057.96000000", "0.00000000"], ["84057.65000000", "0.00000000"], ["84057.58000000", "0.00000000"], ["84056.70000000", "0.14000000"], ["84056.40000000", "0.47601000"], ["84055.93000000", "0.00118000"], ["84055.64000000", "0.00000000"], ["84055.48000000", "0.00000000"], ["84055.44000000", "0.00000000"], ["84055.08000000", "0.00000000"], ["84054.72000000", "0.00000000"], ["84054.60000000", "0.02419000"], ["84054.56000000", "0.00007000"], ["84054.37000000", "0.00000000"], ["84053.91000000", "0.00000000"], ["84053.90000000", "0.00000000"], ["84053.67000000", "0.00000000"], ["84053.57000000", "0.00000000"], ["84053.05000000", "0.00505000"], ["84052.55000000", "0.00000000"], ["84052.47000000", "0.00000000"], ["84052.41000000", "0.00000000"], ["84052.26000000", "0.00000000"], ["84052.07000000", "0.01189000"], ["84051.89000000", "0.00000000"], ["84051.85000000", "0.00415000"], ["84051.75000000", "0.00000000"], ["84051.56000000", "0.89158000"], ["84051.43000000", "0.47150000"], ["84051.06000000", "0.00000000"], ["84050.86000000", "0.00000000"], ["84050.85000000", "0.00300000"], ["84050.76000000", "0.00050000"], ["84050.71000000", "0.00000000"], ["84050.16000000", "0.00000000"], ["84050.14000000", "0.16000000"], ["84050.10000000", "0.00000000"], ["84049.85000000", "0.71284000"], ["84049.84000000", "1.34039000"], ["84049.18000000", "0.00000000"], ["84049.12000000", "0.00000000"], ["84049.03000000", "0.00000000"], ["84048.54000000", "0.10689000"], ["84048.37000000", "0.90793000"], ["84048.05000000", "0.00059000"], ["84047.85000000", "0.00000000"], ["84047.78000000", "0.00000000"], ["84047.67000000", "0.00000000"], ["84047.61000000", "0.89158000"], ["84047.44000000", "0.11523000"], ["84047.30000000", "0.00000000"], ["84047.05000000", "0.00000000"], ["84046.99000000", "0.00118000"], ["84046.70000000", "0.00035000"], ["84046.37000000", "0.00029000"], ["84046.06000000", "0.89158000"], ["84046.02000000", "0.00000000"], ["84045.94000000", "0.05943000"], ["84045.71000000", "0.00000000"], ["84045.70000000", "0.03569000"], ["84044.74000000", "0.32101000"], ["84044.49000000", "0.00000000"], ["84044.15000000", "0.71284000"], ["84043.83000000", "0.01189000"], ["84043.81000000", "0.00000000"], ["84043.45000000", "0.00000000"], ["84043.34000000", "0.28297000"], ["84042.92000000", "0.89158000"], ["84040.98000000", "0.89158000"], ["84040.80000000", "0.00000000"], ["84040.59000000", "0.00000000"], ["84040.06000000", "0.00000000"], ["84040.05000000", "0.00000000"], ["84039.90000000", "1.05969000"], ["84039.65000000", "0.00059000"], ["84039.64000000", "0.00300000"], ["84039.43000000", "0.05809000"], ["84039.20000000", "0.89158000"], ["84038.88000000", "0.00100000"], ["84038.73000000", "0.00588000"], ["84037.00000000", "0.41248000"], ["84036.62000000", "0.00000000"], ["84036.05000000", "0.00000000"], ["84035.36000000", "0.05943000"], ["84034.04000000", "0.00000000"], ["84033.98000000", "0.85720000"], ["84033.20000000", "0.89158000"], ["84033.01000000", "0.89158000"], ["84032.29000000", "0.00759000"], ["84031.00000000", "0.05071000"], ["84030.86000000", "0.85723000"], ["84030.08000000", "0.00000000"], ["84028.92000000", "0.00000000"], ["84028.71000000", "0.00213000"], ["84028.41000000", "0.00000000"], ["84026.97000000", "0.00358000"], ["84026.47000000", "0.59506000"], ["84026.27000000", "0.00000000"], ["84026.00000000", "0.00000000"], ["84025.21000000", "0.01300000"], ["84024.23000000", "0.00000000"], ["84023.60000000", "0.00000000"], ["84023.21000000", "0.00000000"], ["84022.83000000", "0.00059000"], ["84022.21000000", "0.00000000"], ["84021.38000000", "0.00590000"], ["84021.10000000", "0.00000000"], ["84021.00000000", "0.00006000"], ["84019.89000000", "0.00000000"], ["84019.01000000", "0.00000000"], ["84017.37000000", "0.00000000"], ["84016.54000000", "0.00000000"], ["84015.62000000", "0.00000000"], ["84015.06000000", "0.00000000"], ["84014.97000000", "0.00000000"], ["84014.24000000", "0.00000000"], ["84013.98000000", "0.00000000"], ["84013.93000000", "0.00297000"], ["84012.90000000", "0.00000000"], ["84012.60000000", "0.59444000"], ["84011.63000000", "0.00000000"], ["84011.43000000", "0.00000000"], ["84010.87000000", "0.00000000"], ["84010.48000000", "0.04000000"], ["84010.23000000", "0.59482000"], ["84009.87000000", "0.00000000"], ["84009.48000000", "0.00000000"], ["84008.48000000", "0.00000000"], ["84007.82000000", "0.00013000"], ["84007.56000000", "0.00000000"], ["84006.37000000", "0.00000000"], ["84006.06000000", "0.00000000"], ["84006.05000000", "0.17822000"], ["84005.45000000", "0.00000000"], ["84005.01000000", "0.04757000"], ["84004.68000000", "0.00000000"], ["84004.67000000", "0.00000000"], ["84004.66000000", "0.01740000"], ["84004.36000000", "0.00000000"], ["84004.09000000", "0.00297000"], ["84003.93000000", "0.00807000"], ["84003.46000000", "0.00000000"], ["84003.01000000", "0.04638000"], ["84002.95000000", "0.00000000"], ["84002.71000000", "0.00000000"], ["84002.40000000", "0.00000000"], ["84002.04000000", "0.00000000"], ["84001.31000000", "0.09276000"], ["84000.41000000", "0.00000000"], ["83999.98000000", "0.00000000"], ["83999.92000000", "0.00000000"], ["83999.77000000", "0.00000000"], ["83999.53000000", "0.00000000"], ["83999.26000000", "0.00000000"], ["83998.64000000", "0.05432000"], ["83998.57000000", "0.00000000"], ["83998.13000000", "0.02814000"], ["83997.16000000", "0.00000000"], ["83993.70000000", "0.00000000"], ["83992.35000000", "0.04637000"], ["83989.48000000", "0.04757000"], ["83989.47000000", "0.00000000"], ["83988.18000000", "0.00000000"], ["83988.01000000", "0.04757000"], ["83987.60000000", "0.02121000"], ["83986.56000000", "0.00000000"], ["83986.32000000", "0.00000000"], ["83986.21000000", "0.04763000"], ["83985.55000000", "0.00000000"], ["83985.54000000", "0.00000000"], ["83985.23000000", "0.04638000"], ["83984.29000000", "0.00000000"], ["83983.92000000", "0.04638000"], ["83983.07000000", "0.04757000"], ["83982.36000000", "0.04638000"], ["83981.67000000", "0.00145000"], ["83981.58000000", "0.00000000"], ["83981.52000000", "0.04757000"], ["83981.44000000", "0.08709000"], ["83979.88000000", "0.04757000"], ["83979.39000000", "0.04638000"], ["83977.88000000", "0.04757000"], ["83977.66000000", "0.00000000"], ["83977.45000000", "0.04757000"], ["83977.37000000", "0.09395000"], ["83977.36000000", "0.04757000"], ["83976.30000000", "0.00000000"], ["83975.97000000", "0.04638000"], ["83975.64000000", "0.04757000"], ["83975.60000000", "0.00000000"], ["83975.56000000", "0.04757000"], ["83975.48000000", "0.04757000"], ["83975.15000000", "0.00213000"], ["83974.46000000", "0.00000000"], ["83974.25000000", "0.04638000"], ["83974.21000000", "0.00000000"], ["83974.01000000", "0.04638000"], ["83973.39000000", "0.04638000"], ["83973.15000000", "0.04638000"], ["83972.86000000", "0.04638000"], ["83972.83000000", "0.04638000"], ["83972.01000000", "0.04757000"], ["83971.97000000", "0.04757000"], ["83971.93000000", "0.04757000"], ["83971.80000000", "0.05496000"], ["83971.31000000", "0.04638000"], ["83971.08000000", "0.04638000"], ["83971.01000000", "0.00000000"], ["83970.99000000", "0.04638000"], ["83970.44000000", "0.04638000"], ["83970.23000000", "0.00000000"], ["83969.31000000", "0.04638000"], ["83969.23000000", "0.04638000"], ["83969.20000000", "1.38907000"], ["83968.12000000", "0.05297000"], ["83968.09000000", "0.04638000"], ["83967.89000000", "0.10134000"], ["83967.67000000", "0.55541000"], ["83967.54000000", "0.04638000"], ["83966.70000000", "0.10135000"], ["83965.95000000", "0.00000000"], ["83964.80000000", "0.00200000"], ["83964.31000000", "0.04638000"], ["83963.75000000", "0.00000000"], ["83962.39000000", "0.00000000"], ["83961.99000000", "0.04638000"], ["83960.70000000", "0.04638000"], ["83959.26000000", "0.04197000"], ["83958.52000000", "0.00000000"], ["83958.19000000", "0.04897000"], ["83957.88000000", "0.09835000"], ["83955.74000000", "0.00000000"], ["83955.41000000", "0.04638000"], ["83955.33000000", "0.04638000"], ["83954.57000000", "0.00000000"], ["83954.44000000", "0.04197000"], ["83952.40000000", "0.05496000"], ["83951.51000000", "0.04097000"], ["83950.99000000", "0.05097000"], ["83949.48000000", "0.00000000"], ["83949.12000000", "0.04197000"], ["83948.82000000", "0.00000000"], ["83948.15000000", "0.04097000"], ["83948.12000000", "0.05097000"], ["83946.57000000", "0.00075000"], ["83945.82000000", "0.00000000"], ["83945.14000000", "0.05097000"], ["83944.00000000", "0.04432000"], ["83942.46000000", "0.05296000"], ["83941.75000000", "0.04097000"], ["83941.09000000", "0.00000000"], ["83940.46000000", "0.04197000"], ["83936.70000000", "0.00213000"], ["83936.69000000", "0.00119000"], ["83936.11000000", "0.04097000"], ["83934.25000000", "0.04197000"], ["83930.12000000", "0.00000000"], ["83920.01000000", "0.00119000"], ["83919.40000000", "0.00000000"], ["83918.95000000", "0.00006000"], ["83918.38000000", "0.99313000"], ["83915.27000000", "0.00000000"], ["83914.09000000", "0.00000000"], ["83895.11000000", "0.13166000"], ["83895.00000000", "0.00000000"], ["83890.78000000", "0.00400000"], ["83884.44000000", "0.00000000"], ["83882.86000000", "0.00000000"], ["83876.61000000", "0.00063000"], ["83872.00000000", "0.00235000"], ["83860.61000000", "0.00000000"], ["83858.88000000", "0.00000000"], ["83858.15000000", "0.19170000"], ["83856.43000000", "0.00000000"], ["83852.19000000", "0.00190000"], ["83849.75000000", "0.01466000"], ["83846.70000000", "0.00000000"], ["83843.49000000", "0.00000000"], ["83840.90000000", "0.00000000"], ["83831.76000000", "0.00013000"], ["83827.56000000", "0.00013000"], ["83825.75000000", "0.00000000"], ["83823.36000000", "0.00013000"], ["83819.16000000", "0.00013000"], ["83814.96000000", "0.00013000"], ["83810.76000000", "0.00013000"], ["83805.50000000", "0.00000000"], ["83801.69000000", "0.45000000"], ["83787.02000000", "0.00000000"], ["83717.39000000", "0.15885000"], ["83224.21000000", "0.00000000"], ["75668.00000000", "0.13247000"], ["75658.00000000", "0.01321000"], ["67260.87000000", "0.00000000"], ["67251.89000000", "0.00058000"], ["42000.00000000", "6.85261000"], ["33000.00000000", "2.93827000"], ["30263.35000000", "0.00020000"]], "a": [["84064.87000000", "4.46767000"], ["84064.88000000", "0.00013000"], ["84065.22000000", "0.00008000"], ["84065.46000000", "0.00058000"], ["84065.51000000", "0.00000000"], ["84065.57000000", "0.00000000"], ["84065.58000000", "0.00006000"], ["84065.79000000", "0.00000000"], ["84065.81000000", "0.00000000"], ["84065.92000000", "0.00000000"], ["84066.02000000", "0.00000000"], ["84066.03000000", "0.00000000"], ["84066.28000000", "0.00000000"], ["84066.29000000", "0.00000000"], ["84066.35000000", "0.00007000"], ["84066.53000000", "0.00000000"], ["84066.54000000", "0.00000000"], ["84066.61000000", "0.00014000"], ["84066.62000000", "0.04007000"], ["84066.73000000", "0.00757000"], ["84066.89000000", "0.00000000"], ["84066.90000000", "0.00000000"], ["84066.93000000", "0.00000000"], ["84067.19000000", "0.00021000"], ["84067.20000000", "0.01196000"], ["84067.78000000", "0.00014000"], ["84067.79000000", "0.10857000"], ["84067.80000000", "0.13526000"], ["84067.81000000", "0.00000000"], ["84067.91000000", "0.00011000"], ["84068.00000000", "0.02260000"], ["84068.01000000", "0.00000000"], ["84068.39000000", "0.02441000"], ["84068.42000000", "0.01518000"], ["84068.63000000", "0.00000000"], ["84068.76000000", "0.00000000"], ["84068.77000000", "0.17822000"], ["84068.92000000", "0.15952000"], ["84069.03000000", "0.00000000"], ["84069.04000000", "0.00000000"], ["84070.00000000", "0.02260000"], ["84070.22000000", "0.00059000"], ["84070.86000000", "0.00000000"], ["84071.05000000", "0.00000000"], ["84071.24000000", "0.00000000"], ["84071.32000000", "0.00000000"], ["84071.50000000", "0.00000000"], ["84071.59000000", "0.01189000"], ["84071.60000000", "0.00000000"], ["84071.62000000", "0.00000000"], ["84071.86000000", "0.00000000"], ["84071.91000000", "0.00000000"], ["84071.99000000", "0.22521000"], ["84072.00000000", "0.59320000"], ["84072.01000000", "0.27390000"], ["84072.02000000", "0.00000000"], ["84072.42000000", "0.00000000"], ["84072.46000000", "0.00201000"], ["84072.52000000", "0.00000000"], ["84072.53000000", "0.00000000"], ["84072.54000000", "0.00000000"], ["84072.55000000", "0.00000000"], ["84072.56000000", "0.00115000"], ["84072.57000000", "0.00000000"], ["84072.60000000", "0.00000000"], ["84072.73000000", "0.00000000"], ["84072.88000000", "0.00000000"], ["84073.06000000", "0.00000000"], ["84073.10000000", "0.00000000"], ["84073.28000000", "0.00333000"], ["84073.40000000", "0.00058000"], ["84073.49000000", "0.00000000"], ["84073.62000000", "0.00118000"], ["84073.68000000", "0.00000000"], ["84073.94000000", "0.00000000"], ["84073.97000000", "0.00000000"], ["84074.00000000", "0.02260000"], ["84074.13000000", "0.00000000"], ["84074.34000000", "0.00000000"], ["84074.36000000", "0.00000000"], ["84074.42000000", "0.00000000"], ["84074.46000000", "0.03580000"], ["84074.47000000", "0.00000000"], ["84074.55000000", "0.00000000"], ["84074.76000000", "0.00000000"], ["84074.77000000", "0.00000000"], ["84074.85000000", "0.00000000"], ["84074.87000000", "0.00000000"], ["84074.93000000", "0.00000000"], ["84074.96000000", "0.58650000"], ["84074.97000000", "0.44250000"], ["84075.01000000", "0.00000000"], ["84075.12000000", "0.00000000"], ["84075.14000000", "0.00000000"], ["84075.23000000", "0.00000000"], ["84075.24000000", "0.00000000"], ["84075.36000000", "0.00013000"], ["84075.38000000", "0.00000000"], ["84075.44000000", "0.00006000"], ["84075.47000000", "0.00000000"], ["84075.48000000", "0.09713000"], ["84075.49000000", "0.00000000"], ["84075.50000000", "0.00000000"], ["84075.57000000", "0.00000000"], ["84075.60000000", "0.00006000"], ["84075.67000000", "0.00000000"], ["84075.68000000", "0.00000000"], ["84075.69000000", "0.00000000"], ["84075.70000000", "0.00000000"], ["84075.84000000", "0.00000000"], ["84075.94000000", "0.00000000"], ["84076.00000000", "0.02260000"], ["84076.01000000", "0.00000000"], ["84076.05000000", "0.00000000"], ["84076.07000000", "0.00000000"], ["84076.08000000", "0.00000000"], ["84076.09000000", "0.24626000"], ["84076.10000000", "0.00000000"], ["84076.30000000", "0.00000000"], ["84076.56000000", "0.11898000"], ["84076.68000000", "0.00000000"], ["84076.73000000", "0.00000000"], ["84076.74000000", "0.00000000"], ["84076.85000000", "0.00000000"], ["84076.88000000", "0.00235000"], ["84077.14000000", "0.00009000"], ["84077.32000000", "0.00000000"], ["84077.36000000", "0.00000000"], ["84077.64000000", "0.00000000"], ["84077.66000000", "0.00000000"], ["84077.75000000", "0.00000000"], ["84077.76000000", "0.00000000"], ["84077.77000000", "0.00000000"], ["84077.78000000", "0.89158000"], ["84077.80000000", "0.00000000"], ["84077.81000000", "0.00000000"], ["84078.00000000", "0.02260000"], ["84078.42000000", "0.00000000"], ["84078.73000000", "0.01189000"], ["84078.76000000", "0.00000000"], ["84078.83000000", "0.00000000"], ["84078.84000000", "0.15409000"], ["84078.98000000", "0.08992000"], ["84078.99000000", "0.00115000"], ["84079.17000000", "0.00000000"], ["84079.29000000", "0.00000000"], ["84079.52000000", "0.04000000"], ["84079.56000000", "0.00013000"], ["84079.63000000", "0.00000000"], ["84079.77000000", "0.31175000"], ["84079.80000000", "0.00006000"], ["84079.85000000", "0.00000000"], ["84080.19000000", "0.53988000"], ["84080.23000000", "0.00000000"], ["84080.40000000", "0.26132000"], ["84080.41000000", "0.00000000"], ["84080.79000000", "0.05943000"], ["84081.04000000", "0.00000000"], ["84081.07000000", "0.00000000"], ["84081.22000000", "0.00000000"], ["84081.32000000", "0.00000000"], ["84081.44000000", "0.00000000"], ["84081.56000000", "0.00000000"], ["84081.61000000", "0.00000000"], ["84081.68000000", "0.00059000"], ["84081.72000000", "0.00000000"], ["84081.74000000", "0.00000000"], ["84081.78000000", "0.85672000"], ["84082.02000000", "0.06378000"], ["84082.03000000", "0.00000000"], ["84082.38000000", "1.00505000"], ["84082.50000000", "0.00131000"], ["84082.68000000", "0.00000000"], ["84082.84000000", "0.00000000"], ["84082.89000000", "0.00000000"], ["84083.07000000", "0.01189000"], ["84083.52000000", "0.89158000"], ["84083.69000000", "0.00000000"], ["84083.78000000", "0.00007000"], ["84083.82000000", "0.00000000"], ["84084.61000000", "0.00000000"], ["84084.62000000", "0.00000000"], ["84084.81000000", "0.00011000"], ["84085.10000000", "0.00000000"], ["84085.27000000", "0.00000000"], ["84085.34000000", "0.85668000"], ["84085.50000000", "0.00000000"], ["84085.64000000", "0.00000000"], ["84085.69000000", "0.01189000"], ["84085.80000000", "0.00000000"], ["84086.43000000", "0.00000000"], ["84087.22000000", "0.89158000"], ["84087.26000000", "1.29491000"], ["84087.44000000", "0.00000000"], ["84088.00000000", "0.00000000"], ["84088.20000000", "0.00006000"], ["84088.74000000", "0.00000000"], ["84088.79000000", "0.89158000"], ["84089.05000000", "0.00000000"], ["84089.46000000", "0.00013000"], ["84090.00000000", "0.00500000"], ["84090.09000000", "0.00359000"], ["84090.21000000", "0.71284000"], ["84090.31000000", "0.05943000"], ["84090.51000000", "0.00000000"], ["84090.73000000", "1.47077000"], ["84090.74000000", "0.00000000"], ["84090.93000000", "0.00000000"], ["84091.24000000", "0.47551000"], ["84091.86000000", "0.00000000"], ["84092.56000000", "0.59505000"], ["84092.60000000", "0.00000000"], ["84092.67000000", "0.19171000"], ["84092.91000000", "0.00000000"], ["84093.51000000", "0.00118000"], ["84094.00000000", "0.00000000"], ["84094.19000000", "0.89158000"], ["84094.38000000", "0.00000000"], ["84095.33000000", "0.94262000"], ["84096.00000000", "0.00000000"], ["84096.52000000", "0.00000000"], ["84097.23000000", "0.00000000"], ["84097.45000000", "0.00000000"], ["84097.46000000", "0.45000000"], ["84098.00000000", "0.00000000"], ["84098.25000000", "0.00000000"], ["84098.33000000", "0.00000000"], ["84098.59000000", "0.00000000"], ["84099.24000000", "0.00084000"], ["84099.42000000", "0.00000000"], ["84099.67000000", "0.35347000"], ["84099.70000000", "0.05947000"], ["84100.45000000", "0.00000000"], ["84101.31000000", "0.00000000"], ["84101.63000000", "0.00000000"], ["84101.91000000", "0.00000000"], ["84103.25000000", "1.10920000"], ["84103.39000000", "0.00358000"], ["84104.97000000", "0.00000000"], ["84105.98000000", "0.00809000"], ["84106.90000000", "0.00059000"], ["84107.51000000", "0.16147000"], ["84107.97000000", "0.00000000"], ["84108.19000000", "0.19170000"], ["84109.41000000", "0.00000000"], ["84109.42000000", "0.00000000"], ["84109.88000000", "0.35663000"], ["84110.17000000", "0.00000000"], ["84110.18000000", "0.00000000"], ["84110.82000000", "0.00018000"], ["84110.84000000", "0.00000000"], ["84111.26000000", "0.00000000"], ["84112.17000000", "0.70477000"], ["84114.37000000", "0.00000000"], ["84114.72000000", "0.11481000"], ["84115.24000000", "0.00000000"], ["84116.80000000", "0.00000000"], ["84117.36000000", "0.00000000"], ["84118.13000000", "0.00000000"], ["84119.02000000", "0.00000000"], ["84120.62000000", "0.08992000"], ["84121.02000000", "0.00000000"], ["84122.65000000", "0.09980000"], ["84125.26000000", "0.00000000"], ["84125.75000000", "0.59438000"], ["84127.17000000", "0.00000000"], ["84129.80000000", "0.00000000"], ["84135.75000000", "0.02380000"], ["84139.33000000", "0.04638000"], ["84141.08000000", "0.03187000"], ["84141.38000000", "0.00145000"], ["84143.90000000", "0.01085000"], ["84144.26000000", "0.05290000"], ["84145.25000000", "0.08304000"], ["84145.62000000", "0.20476000"], ["84146.03000000", "0.51343000"], ["84146.07000000", "0.00000000"], ["84146.53000000", "0.00013000"], ["84148.46000000", "0.51010000"], ["84149.05000000", "0.00296000"], ["84149.06000000", "0.00000000"], ["84150.39000000", "0.04896000"], ["84152.99000000", "0.04896000"], ["84158.47000000", "0.84181000"], ["84158.59000000", "0.00000000"], ["84159.04000000", "0.05296000"], ["84159.98000000", "0.00000000"], ["84161.21000000", "0.00000000"], ["84161.46000000", "0.05296000"], ["84161.60000000", "0.05496000"], ["84162.11000000", "0.00000000"], ["84162.43000000", "0.00000000"], ["84163.37000000", "0.10792000"], ["84163.57000000", "0.12784000"], ["84163.75000000", "0.01017000"], ["84163.94000000", "0.12827000"], ["84165.55000000", "0.05496000"], ["84165.59000000", "0.00000000"], ["84166.40000000", "0.05296000"], ["84166.41000000", "0.00297000"], ["84167.77000000", "0.05496000"], ["84168.46000000", "0.09593000"], ["84169.78000000", "0.05496000"], ["84170.73000000", "0.05296000"], ["84172.79000000", "0.16288000"], ["84173.90000000", "0.05496000"], ["84175.71000000", "0.21584000"], ["84177.89000000", "0.36446000"], ["84178.52000000", "0.10592000"], ["84179.98000000", "0.16188000"], ["84181.97000000", "0.05296000"], ["84182.42000000", "0.10592000"], ["84183.32000000", "0.10992000"], ["84183.53000000", "0.05196000"], ["84184.66000000", "0.05296000"], ["84185.20000000", "0.10592000"], ["84186.13000000", "0.10992000"], ["84186.45000000", "0.05196000"], ["84186.84000000", "0.05097000"], ["84187.37000000", "0.50119000"], ["84188.81000000", "0.16488000"], ["84188.83000000", "0.05296000"], ["84188.90000000", "0.05196000"], ["84189.37000000", "0.05296000"], ["84189.38000000", "0.05296000"], ["84189.53000000", "0.00000000"], ["84189.69000000", "0.05196000"], ["84189.70000000", "0.05097000"], ["84191.64000000", "0.05196000"], ["84192.24000000", "0.00000000"], ["84192.29000000", "0.05496000"], ["84192.32000000", "0.05496000"], ["84192.33000000", "0.05096000"], ["84192.35000000", "0.00000000"], ["84192.43000000", "0.05196000"], ["84192.87000000", "0.10194000"], ["84194.67000000", "0.05196000"], ["84195.18000000", "0.05096000"], ["84195.46000000", "0.05196000"], ["84195.73000000", "0.10194000"], ["84196.74000000", "0.05196000"], ["84197.53000000", "0.05196000"], ["84197.83000000", "0.02498000"], ["84200.64000000", "0.00000000"], ["84205.39000000", "0.00000000"], ["84205.99000000", "0.00000000"], ["84217.09000000", "0.00013000"], ["84221.91000000", "0.00000000"], ["84224.38000000", "0.00000000"], ["84227.75000000", "0.01187000"], ["84238.68000000", "0.00000000"], ["84238.87000000", "0.00000000"], ["84239.44000000", "0.00000000"], ["84242.29000000", "0.00000000"], ["84242.49000000", "0.01000000"], ["84242.78000000", "0.00000000"], ["84243.89000000", "0.00000000"], ["84243.99000000", "0.00000000"], ["84245.54000000", "0.00000000"], ["84255.60000000", "0.00000000"], ["84260.16000000", "0.00000000"], ["84283.55000000", "0.01784000"], ["84290.90000000", "0.00007000"], ["84307.18000000", "0.00000000"], ["84317.34000000", "0.00000000"], ["84320.54000000", "0.00000000"], ["84327.55000000", "0.03602000"], ["84330.12000000", "0.00000000"], ["84350.69000000", "0.79995000"], ["84378.00000000", "0.03597000"], ["84382.24000000", "0.00000000"], ["84382.63000000", "0.00000000"], ["84400.85000000", "0.00000000"], ["84414.21000000", "0.00020000"], ["84420.00000000", "0.00246000"], ["84535.15000000", "0.00000000"], ["84543.39000000", "11.83392000"], ["84642.90000000", "0.00000000"], ["85327.80000000", "0.17604000"], ["85857.96000000", "0.00000000"], ["150001.00000000", "0.00080000"]], "record_time": 1742555185.039407, "EXCHANGE": "BINANCE"}
{"e": "depthUpdate", "E": 1742555186014, "s": "BTCUSDT", "U": 64607129509, "u": 64607129821, "b": [["84064.86000000", "2.55715000"], ["84064.84000000", "0.00034000"], ["84064.68000000", "0.00007000"], ["84064.67000000", "0.00007000"], ["84064.61000000", "0.00021000"], ["84064.60000000", "0.04013000"], ["84064.54000000", "0.00000000"], ["84064.45000000", "0.16936000"], ["84064.15000000", "0.00000000"], ["84064.06000000", "0.00014000"], ["84064.05000000", "0.26205000"], ["84063.52000000", "0.00000000"], ["84063.19000000", "0.00000000"], ["84063.12000000", "0.09987000"], ["84062.96000000", "0.00000000"], ["84062.60000000", "0.00011000"], ["84062.38000000", "0.10425000"], ["84061.73000000", "0.00000000"], ["84061.69000000", "0.00000000"], ["84060.76000000", "0.02367000"], ["84060.72000000", "0.00000000"], ["84059.56000000", "0.00000000"], ["84058.14000000", "0.01189000"], ["84056.40000000", "0.21702000"], ["84055.29000000", "0.00000000"], ["84055.00000000", "0.00000000"], ["84052.26000000", "0.01087000"], ["84051.43000000", "0.00000000"], ["84050.76000000", "0.00050000"], ["84049.85000000", "0.00000000"], ["84049.12000000", "0.59438000"], ["84048.66000000", "0.00000000"], ["84048.06000000", "0.00000000"], ["84047.61000000", "0.89158000"], ["84047.44000000", "0.00000000"], ["84047.41000000", "0.00000000"], ["84047.40000000", "0.11851000"], ["84045.70000000", "0.00000000"], ["84045.69000000", "0.00006000"], ["84045.68000000", "0.00000000"], ["84045.65000000", "0.03569000"], ["84044.16000000", "1.04153000"], ["84043.82000000", "0.00000000"], ["84043.59000000", "0.00000000"], ["84043.27000000", "0.89158000"], ["84043.21000000", "0.11692000"], ["84032.47000000", "0.00000000"], ["84032.29000000", "0.00000000"], ["84029.90000000", "0.02805000"], ["84028.44000000", "0.85726000"], ["84027.95000000", "0.00760000"], ["84023.12000000", "0.44788000"], ["84020.82000000", "0.00000000"], ["84013.92000000", "0.15136000"], ["84013.41000000", "0.00000000"], ["84012.60000000", "0.00006000"], ["84012.10000000", "0.59438000"], ["84006.06000000", "0.30638000"], ["84001.41000000", "0.00000000"], ["83992.38000000", "2.28292000"], ["83988.72000000", "0.00000000"], ["83946.58000000", "0.00081000"], ["83946.57000000", "0.00000000"], ["83936.69000000", "0.00000000"], ["83928.01000000", "0.00119000"], ["83897.64000000", "0.00000000"], ["83890.78000000", "0.00000000"], ["83890.01000000", "0.00400000"], ["83884.85000000", "0.00000000"], ["83876.61000000", "0.00000000"], ["83869.61000000", "0.00063000"], ["83864.00000000", "0.00353000"], ["83810.76000000", "0.00000000"], ["83628.40000000", "0.00000000"], ["83027.38000000", "0.02347000"], ["75658.00000000", "0.01321000"], ["67251.89000000", "0.00058000"], ["42000.00000000", "6.85161000"], ["20002.00000000", "0.00000000"], ["20001.00000000", "0.02099000"]], "a": [["84064.87000000", "5.06489000"], ["84066.35000000", "0.00000000"], ["84066.53000000", "0.00014000"], ["84066.54000000", "0.01196000"], ["84066.62000000", "0.04007000"], ["84066.73000000", "0.00000000"], ["84066.89000000", "0.00014000"], ["84066.90000000", "0.02336000"], ["84067.19000000", "0.00007000"], ["84067.79000000", "0.14946000"], ["84067.80000000", "0.13519000"], ["84068.50000000", "0.00757000"], ["84071.99000000", "0.36945000"], ["84072.01000000", "0.27300000"], ["84072.87000000", "0.11898000"], ["84073.28000000", "0.45333000"], ["84074.56000000", "0.11898000"], ["84074.96000000", "0.54650000"], ["84075.40000000", "0.11898000"], ["84076.09000000", "0.21338000"], ["84076.56000000", "0.00000000"], ["84079.31000000", "0.00831000"], ["84080.20000000", "0.00000000"], ["84080.79000000", "0.05943000"], ["84082.19000000", "0.11407000"], ["84090.00000000", "0.00500000"], ["84091.86000000", "0.00000000"], ["84092.56000000", "0.00000000"], ["84092.75000000", "0.00000000"], ["84095.32000000", "0.59504000"], ["84096.56000000", "0.02802000"], ["84097.81000000", "0.00000000"], ["84098.52000000", "0.00000000"], ["84106.41000000", "0.00000000"], ["84106.98000000", "0.00000000"], ["84110.48000000", "0.11925000"], ["84114.72000000", "0.00000000"], ["84124.96000000", "0.19386000"], ["84129.91000000", "0.47551000"], ["84132.05000000", "0.12837000"], ["84135.75000000", "0.00000000"], ["84139.91000000", "0.02380000"], ["84141.14000000", "0.49343000"], ["84142.04000000", "0.00000000"], ["84155.40000000", "0.00000000"], ["84159.66000000", "0.00678000"], ["84163.43000000", "0.00000000"], ["84163.56000000", "0.26234000"], ["84163.75000000", "0.00000000"], ["84164.00000000", "0.00210000"], ["84168.00000000", "0.00216000"], ["84172.00000000", "0.00210000"], ["84176.30000000", "0.04639000"], ["84178.63000000", "0.04639000"], ["84181.72000000", "0.04639000"], ["84184.00000000", "0.00220000"], ["84188.00000000", "0.00220000"], ["84192.00000000", "0.00220000"], ["84198.64000000", "0.12000000"], ["84207.09000000", "0.00000000"], ["84216.65000000", "0.00000000"], ["84219.03000000", "0.00000000"], ["84221.26000000", "0.00000000"], ["84237.05000000", "0.99184000"], ["84242.09000000", "0.01000000"], ["84242.39000000", "0.00000000"], ["84242.49000000", "0.00000000"], ["84245.93000000", "0.00000000"], ["84309.99000000", "0.00000000"], ["84313.14000000", "0.00000000"], ["84327.60000000", "0.00000000"], ["84395.80000000", "0.00000000"], ["84769.63000000", "0.00000000"], ["84769.67000000", "0.00060000"], ["84785.22000000", "0.00000000"], ["84785.27000000", "0.00060000"], ["85857.99000000", "0.01064000"]], "record_time": 1742555186.036528, "EXCHANGE": "BINANCE"}
{"e": "depthUpdate", "E": 1742555187014, "s": "BTCUSDT", "U": 64607129822, "u": 64607131115, "b": [["84064.86000000", "3.51940000"], ["84064.66000000", "0.00078000"], ["84064.65000000", "0.00007000"], ["84064.61000000", "0.00007000"], ["84064.60000000", "0.00000000"], ["84064.46000000", "0.00000000"], ["84064.45000000", "0.00000000"], ["84064.44000000", "0.00000000"], ["84064.07000000", "0.00000000"], ["84064.06000000", "0.00000000"], ["84064.05000000", "0.00000000"], ["84063.93000000", "0.00000000"], ["84063.87000000", "0.00000000"], ["84063.53000000", "0.00000000"], ["84063.20000000", "0.00000000"], ["84063.19000000", "0.00000000"], ["84063.12000000", "0.00000000"], ["84063.11000000", "0.00014000"], ["84063.10000000", "0.02616000"], ["84063.09000000", "0.02430000"], ["84063.03000000", "0.00000000"], ["84062.60000000", "0.00000000"], ["84062.39000000", "0.00000000"], ["84062.38000000", "0.00000000"], ["84062.21000000", "0.00000000"], ["84062.20000000", "0.00000000"], ["84062.10000000", "0.00000000"], ["84062.02000000", "0.00000000"], ["84062.01000000", "0.00040000"], ["84062.00000000", "0.02392000"], ["84061.71000000", "0.00000000"], ["84061.70000000", "0.00000000"], ["84061.49000000", "0.01525000"], ["84061.35000000", "0.00014000"], ["84061.34000000", "0.02318000"], ["84061.22000000", "0.00000000"], ["84061.14000000", "0.00011000"], ["84060.81000000", "0.00007000"], ["84060.80000000", "0.10775000"], ["84060.79000000", "0.09423000"], ["84060.76000000", "0.00000000"], ["84060.60000000", "0.00500000"], ["84060.55000000", "0.00000000"], ["84060.44000000", "0.00000000"], ["84060.43000000", "0.00000000"], ["84060.21000000", "0.00000000"], ["84060.10000000", "0.00000000"], ["84060.09000000", "0.00000000"], ["84060.08000000", "0.00000000"], ["84060.06000000", "0.00000000"], ["84060.03000000", "0.00000000"], ["84060.02000000", "0.02356000"], ["84059.98000000", "0.00000000"], ["84059.83000000", "0.00000000"], ["84059.78000000", "0.00046000"], ["84059.77000000", "0.00024000"], ["84059.76000000", "0.00000000"], ["84059.45000000", "0.00000000"], ["84059.37000000", "0.00000000"], ["84059.32000000", "0.00000000"], ["84059.27000000", "0.00000000"], ["84059.22000000", "0.00000000"], ["84059.17000000", "0.00000000"], ["84059.14000000", "0.00000000"], ["84058.90000000", "0.00000000"], ["84058.89000000", "0.00000000"], ["84058.88000000", "0.04000000"], ["84058.82000000", "0.00000000"], ["84058.80000000", "0.00000000"], ["84058.56000000", "0.00000000"], ["84058.29000000", "0.78554000"], ["84058.26000000", "0.00000000"], ["84058.22000000", "0.00000000"], ["84058.21000000", "0.00000000"], ["84058.17000000", "0.00000000"], ["84058.14000000", "0.00804000"], ["84058.05000000", "0.00000000"], ["84058.04000000", "0.04000000"], ["84057.94000000", "0.00000000"], ["84057.47000000", "0.00000000"], ["84057.20000000", "0.04000000"], ["84057.15000000", "0.00000000"], ["84057.11000000", "0.00000000"], ["84056.98000000", "0.00000000"], ["84056.96000000", "0.00000000"], ["84056.94000000", "0.00000000"], ["84056.89000000", "0.00000000"], ["84056.70000000", "0.00000000"], ["84056.55000000", "0.36480000"], ["84056.54000000", "0.00000000"], ["84056.53000000", "0.00000000"], ["84056.52000000", "0.00000000"], ["84056.41000000", "0.00000000"], ["84056.40000000", "0.00000000"], ["84056.26000000", "0.00000000"], ["84056.25000000", "0.00000000"], ["84055.93000000", "0.00118000"], ["84055.81000000", "0.00000000"], ["84055.73000000", "0.00000000"], ["84055.72000000", "0.00000000"], ["84055.55000000", "0.00000000"], ["84055.41000000", "0.00000000"], ["84055.24000000", "0.00000000"], ["84055.15000000", "0.00091000"], ["84054.63000000", "0.00000000"], ["84054.62000000", "0.00000000"], ["84054.61000000", "0.00000000"], ["84054.60000000", "0.00006000"], ["84054.29000000", "0.00000000"], ["84054.15000000", "0.00000000"], ["84054.10000000", "0.00000000"], ["84054.09000000", "0.04000000"], ["84054.05000000", "0.00000000"], ["84054.03000000", "0.04000000"], ["84053.98000000", "0.00000000"], ["84053.83000000", "0.04000000"], ["84053.81000000", "0.00000000"], ["84053.70000000", "0.00000000"], ["84053.55000000", "0.04000000"], ["84053.43000000", "0.00000000"], ["84053.30000000", "0.00000000"], ["84053.14000000", "0.00000000"], ["84053.13000000", "0.00000000"], ["84052.99000000", "0.04000000"], ["84052.94000000", "0.04000000"], ["84052.93000000", "0.00000000"], ["84052.52000000", "0.04000000"], ["84052.48000000", "0.49881000"], ["84052.26000000", "0.00510000"], ["84052.14000000", "0.00500000"], ["84052.07000000", "0.00000000"], ["84052.00000000", "0.00535000"], ["84051.98000000", "0.00500000"], ["84051.90000000", "0.00000000"], ["84051.69000000", "0.00000000"], ["84051.56000000", "0.00000000"], ["84051.40000000", "0.00000000"], ["84051.30000000", "0.01000000"], ["84051.28000000", "0.00000000"], ["84051.20000000", "0.00000000"], ["84051.14000000", "0.01000000"], ["84050.76000000", "0.00050000"], ["84050.60000000", "0.00000000"], ["84050.14000000", "0.00000000"], ["84049.87000000", "0.04000000"], ["84049.84000000", "0.00000000"], ["84049.63000000", "0.00000000"], ["84049.56000000", "0.00092000"], ["84049.00000000", "0.14000000"], ["84048.67000000", "0.00094000"], ["84048.54000000", "0.00000000"], ["84048.49000000", "0.15607000"], ["84048.37000000", "0.65012000"], ["84048.31000000", "0.00000000"], ["84047.40000000", "0.00000000"], ["84046.97000000", "0.00000000"], ["84046.61000000", "0.01189000"], ["84046.20000000", "0.02382000"], ["84046.06000000", "0.00000000"], ["84045.96000000", "0.00000000"], ["84045.94000000", "0.06034000"], ["84045.91000000", "0.00000000"], ["84045.71000000", "0.35663000"], ["84045.65000000", "0.00000000"], ["84045.64000000", "0.00000000"], ["84045.50000000", "0.00000000"], ["84044.64000000", "0.00000000"], ["84044.25000000", "0.71284000"], ["84044.24000000", "0.47551000"], ["84044.17000000", "0.00000000"], ["84044.15000000", "0.00000000"], ["84043.34000000", "0.00000000"], ["84043.28000000", "0.89158000"], ["84043.21000000", "0.00000000"], ["84043.19000000", "0.00000000"], ["84042.65000000", "0.18776000"], ["84042.14000000", "0.00000000"], ["84041.31000000", "0.00000000"], ["84041.22000000", "0.00000000"], ["84041.10000000", "0.03569000"], ["84041.04000000", "0.00013000"], ["84040.98000000", "0.00000000"], ["84040.35000000", "0.00883000"], ["84040.23000000", "0.10688000"], ["84040.14000000", "0.16000000"], ["84039.32000000", "0.04000000"], ["84039.20000000", "0.00000000"], ["84039.08000000", "0.00000000"], ["84039.04000000", "0.00355000"], ["84039.03000000", "1.31168000"], ["84038.97000000", "0.71284000"], ["84038.81000000", "0.89158000"], ["84038.66000000", "0.00000000"], ["84038.41000000", "0.89158000"], ["84037.07000000", "0.28267000"], ["84036.68000000", "0.85718000"], ["84036.64000000", "0.89158000"], ["84035.97000000", "0.11477000"], ["84035.91000000", "0.89158000"], ["84035.74000000", "0.24462000"], ["84034.91000000", "0.00000000"], ["84034.90000000", "0.00000000"], ["84034.15000000", "0.00000000"], ["84033.98000000", "0.00000000"], ["84033.77000000", "0.05071000"], ["84033.20000000", "0.00000000"], ["84032.70000000", "0.85722000"], ["84032.09000000", "0.00000000"], ["84031.88000000", "0.00000000"], ["84031.00000000", "0.00000000"], ["84030.86000000", "0.00000000"], ["84028.71000000", "0.00000000"], ["84028.61000000", "0.89158000"], ["84027.85000000", "0.85727000"], ["84026.58000000", "0.04942000"], ["84026.47000000", "0.00000000"], ["84026.46000000", "0.00000000"], ["84026.45000000", "0.00000000"], ["84025.94000000", "0.89158000"], ["84025.41000000", "0.03855000"], ["84025.21000000", "0.00000000"], ["84024.54000000", "0.05927000"], ["84024.01000000", "0.00000000"], ["84021.94000000", "0.02640000"], ["84021.89000000", "0.00000000"], ["84021.88000000", "0.00000000"], ["84021.69000000", "0.00000000"], ["84021.38000000", "0.00000000"], ["84020.20000000", "0.00000000"], ["84019.81000000", "0.00000000"], ["84019.76000000", "0.89158000"], ["84019.64000000", "0.00000000"], ["84018.10000000", "0.59512000"], ["84017.64000000", "0.34230000"], ["84016.80000000", "0.00006000"], ["84015.44000000", "0.30174000"], ["84011.46000000", "0.00000000"], ["84010.23000000", "0.00000000"], ["84010.22000000", "0.00000000"], ["84009.11000000", "0.00000000"], ["84007.37000000", "0.00000000"], ["84007.14000000", "0.00630000"], ["84007.00000000", "0.45058000"], ["84004.54000000", "0.00000000"], ["84004.08000000", "0.00000000"], ["84003.48000000", "0.00000000"], ["84003.01000000", "0.00000000"], ["84002.06000000", "0.00000000"], ["84001.31000000", "0.00000000"], ["84000.00000000", "0.27390000"], ["83999.99000000", "0.05951000"], ["83998.73000000", "0.00000000"], ["83997.26000000", "0.04000000"], ["83996.98000000", "0.04000000"], ["83996.55000000", "0.00810000"], ["83994.55000000", "0.00000000"], ["83994.52000000", "0.00000000"], ["83993.68000000", "0.00000000"], ["83993.37000000", "0.00000000"], ["83993.06000000", "0.00000000"], ["83992.86000000", "1.28035000"], ["83992.85000000", "0.00000000"], ["83992.84000000", "0.04000000"], ["83991.78000000", "0.00000000"], ["83991.72000000", "0.05459000"], ["83991.30000000", "0.00000000"], ["83991.07000000", "0.00000000"], ["83990.96000000", "0.00000000"], ["83990.37000000", "0.00000000"], ["83989.89000000", "0.00000000"], ["83989.81000000", "0.00000000"], ["83989.45000000", "0.00000000"], ["83989.09000000", "0.00000000"], ["83988.83000000", "0.00000000"], ["83988.58000000", "0.00000000"], ["83988.39000000", "0.04637000"], ["83987.27000000", "0.00000000"], ["83987.26000000", "0.00000000"], ["83987.24000000", "0.00000000"], ["83986.72000000", "0.00000000"], ["83986.22000000", "0.00000000"], ["83984.71000000", "0.00000000"], ["83984.66000000", "0.00000000"], ["83984.64000000", "0.00000000"], ["83984.09000000", "0.00000000"], ["83983.66000000", "0.00000000"], ["83982.98000000", "0.00000000"], ["83982.83000000", "0.00000000"], ["83982.29000000", "0.00000000"], ["83982.06000000", "0.00000000"], ["83981.79000000", "0.00000000"], ["83980.24000000", "0.00018000"], ["83980.14000000", "0.00000000"], ["83980.03000000", "0.00000000"], ["83979.50000000", "0.00000000"], ["83979.17000000", "0.00000000"], ["83979.09000000", "0.00000000"], ["83978.79000000", "0.00000000"], ["83978.42000000", "1.12529000"], ["83977.45000000", "0.04857000"], ["83977.16000000", "0.04637000"], ["83976.64000000", "0.05497000"], ["83975.57000000", "0.00000000"], ["83975.15000000", "0.00000000"], ["83973.00000000", "0.00000000"], ["83972.97000000", "0.00000000"], ["83972.80000000", "0.00000000"], ["83971.19000000", "0.00000000"], ["83970.31000000", "0.00007000"], ["83969.20000000", "0.00000000"], ["83967.40000000", "0.10258000"], ["83967.12000000", "0.00000000"], ["83967.09000000", "0.00000000"], ["83965.12000000", "0.12863000"], ["83964.90000000", "0.04639000"], ["83964.61000000", "0.04097000"], ["83963.77000000", "0.00000000"], ["83963.71000000", "0.00000000"], ["83963.46000000", "0.09393000"], ["83963.00000000", "0.05180000"], ["83962.92000000", "1.01202000"], ["83962.88000000", "0.00000000"], ["83962.86000000", "0.00000000"], ["83962.68000000", "0.04639000"], ["83962.60000000", "0.00996000"], ["83962.55000000", "0.00000000"], ["83962.30000000", "0.04771000"], ["83961.68000000", "0.00000000"], ["83961.12000000", "0.04639000"], ["83961.03000000", "0.04639000"], ["83960.74000000", "0.04639000"], ["83960.58000000", "0.04097000"], ["83960.08000000", "0.12827000"], ["83959.97000000", "0.05097000"], ["83959.72000000", "0.09536000"], ["83959.63000000", "0.00000000"], ["83958.49000000", "0.04097000"], ["83958.41000000", "0.14933000"], ["83958.12000000", "0.04758000"], ["83958.03000000", "0.04639000"], ["83957.98000000", "0.04197000"], ["83957.88000000", "0.04638000"], ["83957.64000000", "0.10136000"], ["83957.34000000", "0.04639000"], ["83955.80000000", "0.04639000"], ["83955.72000000", "0.04639000"], ["83955.70000000", "0.04639000"], ["83955.63000000", "0.00000000"], ["83955.16000000", "0.04097000"], ["83955.11000000", "0.00000000"], ["83954.74000000", "0.04197000"], ["83954.51000000", "0.11649000"], ["83954.23000000", "0.00000000"], ["83954.13000000", "0.04639000"], ["83953.55000000", "0.04639000"], ["83953.04000000", "0.04639000"], ["83952.90000000", "0.04639000"], ["83952.50000000", "0.04097000"], ["83951.06000000", "0.00000000"], ["83950.70000000", "0.00000000"], ["83950.19000000", "0.04639000"], ["83950.15000000", "0.04204000"], ["83949.80000000", "0.05508000"], ["83949.36000000", "0.04097000"], ["83949.24000000", "0.00000000"], ["83949.05000000", "0.00000000"], ["83949.02000000", "0.00000000"], ["83948.21000000", "0.04639000"], ["83946.59000000", "0.00075000"], ["83946.58000000", "0.00006000"], ["83946.28000000", "0.05496000"], ["83946.06000000", "0.04097000"], ["83944.87000000", "0.04197000"], ["83944.37000000", "0.04639000"], ["83943.90000000", "0.45004000"], ["83942.89000000", "0.04097000"], ["83942.42000000", "0.04897000"], ["83942.13000000", "0.71284000"], ["83941.67000000", "0.04639000"], ["83941.21000000", "0.04897000"], ["83939.74000000", "0.00000000"], ["83939.67000000", "0.05297000"], ["83939.45000000", "0.04897000"], ["83939.39000000", "0.04197000"], ["83938.28000000", "0.05096000"], ["83937.88000000", "0.04097000"], ["83937.08000000", "0.05196000"], ["83937.05000000", "0.05196000"], ["83936.88000000", "0.04097000"], ["83935.78000000", "0.04197000"], ["83935.77000000", "0.11164000"], ["83933.23000000", "0.04897000"], ["83932.06000000", "0.04097000"], ["83931.30000000", "0.04097000"], ["83930.40000000", "0.00000000"], ["83929.93000000", "0.04897000"], ["83929.89000000", "0.04197000"], ["83929.84000000", "0.04197000"], ["83929.83000000", "0.04197000"], ["83926.49000000", "0.18321000"], ["83924.48000000", "0.36242000"], ["83920.47000000", "0.00621000"], ["83908.13000000", "0.00000000"], ["83907.18000000", "0.00000000"], ["83906.18000000", "0.00000000"], ["83905.18000000", "0.00000000"], ["83904.18000000", "0.00000000"], ["83899.27000000", "0.00400000"], ["83893.86000000", "0.00000000"], ["83890.01000000", "0.00000000"], ["83882.42000000", "0.00000000"], ["83876.60000000", "0.00000000"], ["83875.72000000", "0.00000000"], ["83870.78000000", "0.00000000"], ["83869.62000000", "0.00063000"], ["83869.61000000", "0.00000000"], ["83863.73000000", "0.00000000"], ["83852.27000000", "0.17706000"], ["83843.87000000", "0.01764000"], ["83779.94000000", "0.00000000"], ["83754.80000000", "4.47303000"], ["83706.33000000", "0.03871000"], ["83598.00000000", "0.00000000"], ["83183.82000000", "0.06004000"], ["80656.80000000", "0.00000000"], ["80639.99000000", "0.00000000"], ["75658.00000000", "0.01321000"], ["67251.89000000", "0.00058000"], ["33000.00000000", "2.93827000"]], "a": [["84064.87000000", "4.17117000"], ["84065.44000000", "0.00000000"], ["84065.58000000", "0.00000000"], ["84065.67000000", "0.00000000"], ["84065.76000000", "0.00000000"], ["84065.77000000", "0.00000000"], ["84065.92000000", "0.00000000"], ["84065.94000000", "0.00000000"], ["84065.95000000", "0.00006000"], ["84065.99000000", "0.00014000"], ["84066.00000000", "0.02273000"], ["84066.17000000", "0.00000000"], ["84066.18000000", "0.00000000"], ["84066.35000000", "0.00000000"], ["84066.53000000", "0.00000000"], ["84066.54000000", "0.00000000"], ["84066.62000000", "0.04007000"], ["84066.89000000", "0.00000000"], ["84066.90000000", "0.00000000"], ["84067.20000000", "0.01202000"], ["84067.25000000", "0.00006000"], ["84067.46000000", "0.00011000"], ["84067.60000000", "0.00000000"], ["84067.78000000", "0.00014000"], ["84067.79000000", "0.14953000"], ["84067.80000000", "0.13519000"], ["84067.91000000", "0.00000000"], ["84067.97000000", "0.01518000"], ["84068.00000000", "0.02260000"], ["84068.11000000", "0.05943000"], ["84068.16000000", "0.00000000"], ["84068.42000000", "0.00000000"], ["84068.55000000", "0.10688000"], ["84068.92000000", "0.00000000"], ["84070.61000000", "0.00000000"], ["84071.24000000", "0.04000000"], ["84071.40000000", "0.00006000"], ["84071.47000000", "0.04000000"], ["84071.62000000", "0.00059000"], ["84071.97000000", "0.00000000"], ["84071.98000000", "0.08304000"], ["84072.00000000", "0.59320000"], ["84072.01000000", "0.00279000"], ["84072.37000000", "0.05200000"], ["84072.61000000", "0.04000000"], ["84072.70000000", "0.35663000"], ["84072.92000000", "0.04800000"], ["84072.93000000", "0.05200000"], ["84073.62000000", "0.00118000"], ["84074.22000000", "0.01189000"], ["84074.46000000", "0.00000000"], ["84074.84000000", "0.07600000"], ["84074.96000000", "1.00357000"], ["84074.97000000", "0.00000000"], ["84075.39000000", "0.00000000"], ["84075.40000000", "0.23796000"], ["84075.48000000", "0.01126000"], ["84075.78000000", "0.35712000"], ["84076.09000000", "0.12751000"], ["84076.29000000", "0.07200000"], ["84076.52000000", "0.06400000"], ["84076.57000000", "0.06000000"], ["84077.12000000", "0.06400000"], ["84077.77000000", "0.71284000"], ["84078.72000000", "0.00000000"], ["84078.98000000", "0.00000000"], ["84079.52000000", "0.00000000"], ["84079.58000000", "0.11886000"], ["84080.35000000", "0.00000000"], ["84081.20000000", "0.00000000"], ["84081.29000000", "0.00000000"], ["84082.02000000", "0.00000000"], ["84082.10000000", "0.00000000"], ["84082.11000000", "0.00000000"], ["84082.19000000", "0.00000000"], ["84082.24000000", "1.32555000"], ["84083.51000000", "0.00000000"], ["84083.71000000", "0.00000000"], ["84083.84000000", "0.89158000"], ["84083.96000000", "0.00000000"], ["84084.57000000", "0.00000000"], ["84085.38000000", "0.00000000"], ["84085.39000000", "0.00000000"], ["84085.40000000", "0.00000000"], ["84085.46000000", "0.00000000"], ["84085.69000000", "0.00000000"], ["84086.59000000", "0.00000000"], ["84086.71000000", "0.02802000"], ["84089.40000000", "0.00000000"], ["84089.63000000", "0.00000000"], ["84089.69000000", "0.02394000"], ["84090.00000000", "0.00000000"], ["84090.31000000", "0.00000000"], ["84090.88000000", "0.59506000"], ["84092.58000000", "0.00000000"], ["84092.61000000", "0.00000000"], ["84092.94000000", "0.00100000"], ["84093.22000000", "0.00000000"], ["84093.82000000", "0.89158000"], ["84094.31000000", "0.89158000"], ["84094.81000000", "0.00000000"], ["84095.32000000", "0.00000000"], ["84095.59000000", "0.89158000"], ["84095.83000000", "0.00000000"], ["84096.56000000", "0.00000000"], ["84099.87000000", "0.00000000"], ["84100.66000000", "0.00809000"], ["84101.27000000", "0.00000000"], ["84101.32000000", "0.35663000"], ["84103.25000000", "0.00000000"], ["84103.67000000", "0.11503000"], ["84104.45000000", "0.02983000"], ["84104.60000000", "0.05471000"], ["84104.93000000", "0.00000000"], ["84105.11000000", "0.00821000"], ["84105.34000000", "0.23276000"], ["84105.50000000", "0.00000000"], ["84106.48000000", "0.00000000"], ["84106.56000000", "0.00857000"], ["84106.81000000", "0.71284000"], ["84107.98000000", "0.00000000"], ["84108.89000000", "0.00000000"], ["84109.09000000", "0.05750000"], ["84109.88000000", "0.00000000"], ["84110.48000000", "0.00000000"], ["84112.17000000", "0.00000000"], ["84114.43000000", "0.00000000"], ["84115.16000000", "0.00000000"], ["84115.26000000", "0.01196000"], ["84115.58000000", "0.00000000"], ["84115.96000000", "0.00000000"], ["84117.04000000", "0.02883000"], ["84117.13000000", "0.59438000"], ["84117.70000000", "0.00000000"], ["84118.28000000", "0.74735000"], ["84118.99000000", "0.00000000"], ["84119.76000000", "0.00000000"], ["84119.85000000", "0.00000000"], ["84120.28000000", "0.00000000"], ["84120.62000000", "0.62259000"], ["84122.01000000", "0.03609000"], ["84123.06000000", "0.00000000"], ["84123.77000000", "0.00000000"], ["84124.96000000", "0.01899000"], ["84125.75000000", "0.00000000"], ["84128.21000000", "0.05496000"], ["84132.36000000", "2.36184000"], ["84134.66000000", "0.00000000"], ["84135.02000000", "1.20624000"], ["84137.99000000", "0.04800000"], ["84139.32000000", "0.05980000"], ["84139.90000000", "0.04639000"], ["84141.53000000", "0.00000000"], ["84142.42000000", "0.06000000"], ["84143.89000000", "0.04639000"], ["84144.23000000", "0.00000000"], ["84145.61000000", "0.04639000"], ["84147.59000000", "0.04897000"], ["84147.75000000", "0.04639000"], ["84149.46000000", "0.04238000"], ["84149.90000000", "0.04897000"], ["84149.92000000", "0.00000000"], ["84150.24000000", "0.00000000"], ["84151.12000000", "0.05038000"], ["84152.19000000", "0.04197000"], ["84152.26000000", "0.00100000"], ["84152.98000000", "0.04197000"], ["84152.99000000", "0.09793000"], ["84153.33000000", "0.04897000"], ["84157.10000000", "0.44797000"], ["84160.97000000", "0.00000000"], ["84165.54000000", "0.04097000"], ["84166.08000000", "0.04097000"], ["84167.76000000", "0.04097000"], ["84168.46000000", "0.13690000"], ["84169.15000000", "0.11630000"], ["84169.76000000", "0.04648000"], ["84169.77000000", "0.04097000"], ["84170.72000000", "0.04639000"], ["84171.99000000", "0.04639000"], ["84172.58000000", "0.69776000"], ["84174.94000000", "0.04639000"], ["84175.71000000", "0.26223000"], ["84177.31000000", "0.05833000"], ["84177.48000000", "0.04639000"], ["84179.19000000", "0.04639000"], ["84184.93000000", "0.57215000"], ["84185.40000000", "0.04639000"], ["84186.95000000", "0.24699000"], ["84188.27000000", "0.04639000"], ["84193.85000000", "0.00000000"], ["84195.58000000", "0.04638000"], ["84198.13000000", "0.00000000"], ["84199.67000000", "0.00000000"], ["84206.21000000", "4.08351000"], ["84207.80000000", "0.00000000"], ["84214.20000000", "1.33863000"], ["84220.96000000", "0.00000000"], ["84221.71000000", "0.00000000"], ["84222.59000000", "0.00000000"], ["84223.86000000", "0.00000000"], ["84224.11000000", "0.00000000"], ["84225.00000000", "0.00000000"], ["84229.52000000", "0.00000000"], ["84232.38000000", "0.00000000"], ["84234.57000000", "0.01000000"], ["84234.67000000", "0.00021000"], ["84236.60000000", "0.00000000"], ["84237.08000000", "0.00000000"], ["84237.50000000", "0.00000000"], ["84237.92000000", "0.00000000"], ["84238.28000000", "0.00000000"], ["84238.80000000", "0.00007000"], ["84239.66000000", "0.12783000"], ["84240.20000000", "0.00000000"], ["84240.76000000", "0.00000000"], ["84242.09000000", "0.00000000"], ["84242.10000000", "0.00000000"], ["84242.12000000", "0.00000000"], ["84242.36000000", "0.00000000"], ["84242.38000000", "0.00000000"], ["84242.74000000", "0.00000000"], ["84246.19000000", "0.00000000"], ["84250.15000000", "0.00000000"], ["84253.62000000", "0.00000000"], ["84254.09000000", "0.00000000"], ["84254.50000000", "0.00000000"], ["84255.34000000", "0.00000000"], ["84255.38000000", "0.00000000"], ["84256.78000000", "0.00000000"], ["84259.95000000", "0.00000000"], ["84277.30000000", "2.74601000"], ["84297.78000000", "0.00000000"], ["84328.00000000", "0.00235000"], ["84335.01000000", "0.28526000"], ["84366.69000000", "0.00641000"], ["84375.90000000", "3.81802000"], ["84381.10000000", "0.00000000"], ["84385.15000000", "0.00000000"], ["84393.23000000", "0.00000000"], ["84432.66000000", "0.00000000"], ["84607.20000000", "0.00000000"], ["85327.80000000", "0.05869000"]], "record_time": 1742555187.039489, "EXCHANGE": "BINANCE"}
{"e": "depthUpdate", "E": 1742555188014, "s": "BTCUSDT", "U": 64607131116, "u": 64607131359, "b": [["84064.86000000", "3.28728000"], ["84060.80000000", "0.07772000"], ["84058.29000000", "0.00000000"], ["84056.55000000", "0.39629000"], ["84056.34000000", "0.78556000"], ["84054.73000000", "0.15876000"], ["84052.00000000", "0.00235000"], ["84041.10000000", "0.00000000"], ["84040.58000000", "0.10688000"], ["84040.23000000", "0.00000000"], ["84039.90000000", "2.32176000"], ["84037.48000000", "0.03570000"], ["84030.08000000", "0.59505000"], ["84022.11000000", "0.00000000"], ["84020.38000000", "0.00000000"], ["84019.95000000", "0.05000000"], ["84018.10000000", "0.00000000"], ["84009.87000000", "0.43805000"], ["83998.21000000", "0.00000000"], ["83984.49000000", "0.49855000"], ["83982.62000000", "0.01193000"], ["83967.78000000", "0.01863000"], ["83960.72000000", "1.38926000"], ["83946.60000000", "0.00000000"], ["83946.59000000", "0.00000000"], ["83946.57000000", "0.00075000"], ["83899.27000000", "0.00000000"], ["83895.91000000", "0.00400000"], ["83893.10000000", "0.00000000"], ["83887.25000000", "0.00000000"], ["83874.88000000", "0.00000000"], ["83874.71000000", "0.01525000"], ["83869.63000000", "0.00000000"], ["83869.62000000", "0.00000000"], ["83869.61000000", "0.00063000"], ["83510.20000000", "0.00015000"], ["83224.65000000", "0.00000000"], ["83221.02000000", "0.00040000"], ["83215.91000000", "0.00000000"], ["83212.28000000", "0.00060000"], ["79800.00000000", "8.29820000"], ["75658.00000000", "0.01321000"], ["67251.89000000", "0.00058000"], ["33000.00000000", "2.93827000"]], "a": [["84064.87000000", "4.17101000"], ["84065.46000000", "0.00000000"], ["84065.76000000", "0.00014000"], ["84065.77000000", "0.02458000"], ["84066.00000000", "0.02267000"], ["84066.53000000", "0.00000000"], ["84066.54000000", "0.00000000"], ["84066.61000000", "0.00000000"], ["84066.62000000", "0.00000000"], ["84066.65000000", "0.00000000"], ["84066.66000000", "0.00000000"], ["84066.89000000", "0.00000000"], ["84066.90000000", "0.00000000"], ["84067.19000000", "0.00000000"], ["84067.20000000", "0.00006000"], ["84067.79000000", "0.14953000"], ["84067.80000000", "0.13526000"], ["84067.97000000", "0.01518000"], ["84070.22000000", "0.00000000"], ["84070.99000000", "0.00008000"], ["84071.62000000", "0.00000000"], ["84072.56000000", "0.00000000"], ["84078.55000000", "0.36993000"], ["84078.99000000", "0.00000000"], ["84079.58000000", "0.05943000"], ["84080.43000000", "0.00000000"], ["84081.24000000", "0.00000000"], ["84081.27000000", "0.01863000"], ["84082.23000000", "1.60967000"], ["84082.38000000", "0.00000000"], ["84090.00000000", "0.00500000"], ["84090.31000000", "0.05943000"], ["84090.88000000", "0.00000000"], ["84091.98000000", "0.00100000"], ["84092.51000000", "0.04013000"], ["84093.40000000", "0.05200000"], ["84093.81000000", "0.59505000"], ["84094.10000000", "0.05000000"], ["84095.87000000", "0.07600000"], ["84097.55000000", "0.06400000"], ["84097.60000000", "0.06000000"], ["84103.87000000", "0.65790000"], ["84120.99000000", "0.00000000"], ["84128.67000000", "1.32522000"], ["84129.17000000", "0.00000000"], ["84137.33000000", "0.00000000"], ["84138.03000000", "0.00000000"], ["84141.53000000", "0.07200000"], ["84142.42000000", "0.00000000"], ["84142.46000000", "0.00000000"], ["84144.18000000", "0.00000000"], ["84146.04000000", "0.00000000"], ["84146.63000000", "0.00000000"], ["84159.34000000", "0.00678000"], ["84159.66000000", "0.00000000"], ["84166.44000000", "0.49680000"], ["84170.72000000", "0.10135000"], ["84173.89000000", "0.04639000"], ["84190.43000000", "0.12000000"], ["84205.09000000", "0.00000000"], ["84219.34000000", "0.04636000"], ["84221.12000000", "0.00000000"], ["85306.50000000", "0.11738000"]], "record_time": 1742555188.036001, "EXCHANGE": "BINANCE"}
{"e": "depthUpdate", "E": 1742555189014, "s": "BTCUSDT", "U": 64607131360, "u": 64607131457, "b": [["84064.86000000", "3.38329000"], ["84064.85000000", "0.00071000"], ["84064.84000000", "0.00021000"], ["84060.80000000", "0.33064000"], ["84060.79000000", "0.18412000"], ["84060.60000000", "0.00000000"], ["84058.19000000", "0.78554000"], ["84056.55000000", "0.12913000"], ["84056.34000000", "0.00000000"], ["84033.42000000", "0.00756000"], ["84030.07000000", "1.32379000"], ["84028.30000000", "0.07697000"], ["84027.95000000", "0.00000000"], ["84020.49000000", "0.00000000"], ["84019.95000000", "0.00000000"], ["84019.09000000", "0.00000000"], ["83980.80000000", "0.00018000"], ["83946.58000000", "0.00081000"], ["83946.57000000", "0.00000000"], ["83901.20000000", "0.00400000"], ["83895.91000000", "0.00000000"], ["83869.62000000", "0.00063000"], ["83869.61000000", "0.00000000"], ["83221.02000000", "0.00000000"], ["83218.98000000", "0.00040000"], ["83212.28000000", "0.00000000"], ["83210.24000000", "0.00060000"], ["80656.80000000", "0.03568000"], ["75658.37000000", "0.00025000"], ["75658.00000000", "0.01321000"], ["67251.89000000", "0.00058000"], ["60000.00000000", "73.17018000"], ["33000.00000000", "2.93827000"], ["30263.35000000", "0.00040000"]], "a": [["84064.87000000", "3.85082000"], ["84064.88000000", "0.00027000"], ["84066.00000000", "0.02267000"], ["84066.67000000", "0.00000000"], ["84066.68000000", "0.00000000"], ["84066.75000000", "0.00014000"], ["84066.76000000", "0.05533000"], ["84067.19000000", "0.00007000"], ["84067.54000000", "0.02101000"], ["84067.79000000", "0.14946000"], ["84067.80000000", "0.13519000"], ["84068.53000000", "0.11899000"], ["84072.87000000", "0.00000000"], ["84073.00000000", "0.00500000"], ["84073.28000000", "0.45396000"], ["84081.27000000", "0.00000000"], ["84099.25000000", "0.52740000"], ["84124.96000000", "0.03203000"], ["84129.97000000", "0.02381000"], ["84132.95000000", "0.02854000"], ["84133.90000000", "0.01863000"], ["84139.91000000", "0.00000000"], ["84144.00000000", "0.00010000"], ["84148.00000000", "0.00010000"], ["84152.00000000", "0.00010000"], ["84175.72000000", "0.33802000"]], "record_time": 1742555189.03721, "EXCHANGE": "BINANCE"}
{"e": "depthUpdate", "E": 1742555190014, "s": "BTCUSDT", "U": 64607131458, "u": 64607131636, "b": [["84064.86000000", "3.41372000"], ["84061.38000000", "0.00230000"], ["84052.26000000", "0.00000000"], ["84040.19000000", "0.00000000"], ["84039.03000000", "0.00000000"], ["84035.74000000", "0.64659000"], ["84027.85000000", "0.00000000"], ["84027.18000000", "0.85727000"], ["84025.41000000", "0.04505000"], ["84022.46000000", "0.23299000"], ["84022.42000000", "0.04000000"], ["84020.39000000", "0.00000000"], ["84019.19000000", "0.05000000"], ["83988.83000000", "0.93238000"], ["83967.78000000", "0.00000000"], ["83901.20000000", "0.00000000"], ["83895.67000000", "0.00400000"], ["83220.11000000", "0.00040000"], ["83218.98000000", "0.00000000"], ["83211.93000000", "0.00060000"], ["83210.24000000", "0.00000000"], ["83183.82000000", "0.00000000"], ["75658.37000000", "0.00000000"], ["75658.00000000", "0.01321000"], ["67251.89000000", "0.00058000"], ["33000.00000000", "2.93827000"]], "a": [["84064.87000000", "4.45168000"], ["84065.76000000", "0.00014000"], ["84065.77000000", "0.02410000"], ["84066.00000000", "0.02365000"], ["84066.46000000", "0.00014000"], ["84066.47000000", "0.09860000"], ["84066.54000000", "0.00000000"], ["84066.55000000", "0.00000000"], ["84066.75000000", "0.00000000"], ["84066.76000000", "0.00000000"], ["84067.53000000", "0.00000000"], ["84067.54000000", "0.00000000"], ["84067.79000000", "0.14939000"], ["84067.80000000", "0.13519000"], ["84067.97000000", "0.01518000"], ["84073.06000000", "0.00229000"], ["84073.28000000", "0.45300000"], ["84074.96000000", "0.54650000"], ["84076.88000000", "0.00000000"], ["84077.77000000", "0.71284000"], ["84080.19000000", "0.39037000"], ["84080.79000000", "0.05943000"], ["84082.24000000", "0.00000000"], ["84086.71000000", "0.02802000"], ["84090.00000000", "0.00500000"], ["84091.29000000", "0.85662000"], ["84091.86000000", "0.00000000"], ["84096.13000000", "0.00000000"], ["84108.69000000", "0.49934000"], ["84129.97000000", "0.00000000"], ["84133.90000000", "0.00000000"], ["84134.53000000", "0.63779000"], ["84142.42000000", "0.02381000"], ["84180.40000000", "0.04639000"], ["84180.50000000", "0.04639000"], ["84188.78000000", "0.05096000"], ["84203.48000000", "0.00000000"], ["84205.20000000", "0.00000000"], ["84205.27000000", "0.00000000"], ["84230.16000000", "0.00000000"], ["84230.69000000", "0.00000000"], ["84232.94000000", "0.00000000"], ["84235.64000000", "0.99753000"], ["84237.05000000", "0.00000000"], ["84905.50000000", "0.00000000"]], "record_time": 1742555190.050905, "EXCHANGE": "BINANCE"}
{"e": "depthUpdate", "E": 1742555191014, "s": "BTCUSDT", "U": 64607131637, "u": 64607131801, "b": [["84064.86000000", "3.39665000"], ["84064.85000000", "0.00085000"], ["84064.84000000", "0.00007000"], ["84058.74000000", "0.00008000"], ["84050.76000000", "0.00000000"], ["84038.65000000", "0.45000000"], ["84037.48000000", "0.00000000"], ["84037.44000000", "0.03569000"], ["84034.51000000", "0.34230000"], ["84027.60000000", "0.32481000"], ["84027.19000000", "0.63147000"], ["84022.42000000", "0.00000000"], ["84022.01000000", "0.01300000"], ["84017.64000000", "0.00000000"], ["83969.20000000", "1.38926000"], ["83960.72000000", "0.00000000"], ["83903.38000000", "0.00050000"], ["83880.03000000", "0.01525000"], ["83874.71000000", "0.00000000"], ["83220.11000000", "0.00000000"], ["83212.96000000", "0.00060000"], ["82000.00000000", "66.52760000"], ["75658.00000000", "0.01321000"], ["67251.89000000", "0.00058000"], ["33000.00000000", "2.93827000"], ["30263.35000000", "0.00080000"], ["20002.00000000", "0.00000000"], ["20001.00000000", "0.02099000"]], "a": [["84064.87000000", "4.45241000"], ["84064.88000000", "0.00041000"], ["84065.76000000", "0.00000000"], ["84065.77000000", "0.00000000"], ["84066.00000000", "0.02365000"], ["84066.38000000", "0.00014000"], ["84066.39000000", "0.02437000"], ["84066.47000000", "0.09860000"], ["84066.56000000", "0.00007000"], ["84067.79000000", "0.14932000"], ["84073.00000000", "0.00500000"], ["84073.28000000", "0.45300000"], ["84073.40000000", "0.00000000"], ["84078.27000000", "0.93992000"], ["84078.28000000", "0.85675000"], ["84080.19000000", "0.00000000"], ["84080.79000000", "0.00000000"], ["84082.24000000", "0.00000000"], ["84086.05000000", "0.05126000"], ["84086.71000000", "0.00934000"], ["84089.28000000", "0.00000000"], ["84090.14000000", "0.01868000"], ["84091.29000000", "0.00000000"], ["84091.86000000", "0.00000000"], ["84112.17000000", "0.36767000"], ["84137.98000000", "0.00041000"], ["84149.46000000", "0.04197000"], ["84155.17000000", "0.00678000"], ["84159.34000000", "0.00000000"], ["84187.32000000", "0.05096000"], ["84190.36000000", "0.05096000"], ["84202.27000000", "0.00000000"], ["84202.96000000", "0.00000000"], ["84213.80000000", "0.00035000"], ["84224.71000000", "0.00000000"], ["84769.67000000", "0.00000000"], ["84775.07000000", "0.00060000"], ["84785.27000000", "0.00000000"], ["84790.67000000", "0.00060000"]], "record_time": 1742555191.097336, "EXCHANGE": "BINANCE"}
{"e": "depthUpdate", "E": 1742555192014, "s": "BTCUSDT", "U": 64607131802, "u": 64607131910, "b": [["84064.86000000", "3.41050000"], ["84040.35000000", "0.00000000"], ["84038.75000000", "0.00000000"], ["84030.02000000", "0.00000000"], ["84023.12000000", "0.73316000"], ["84018.23000000", "0.37692000"], ["83950.30000000", "0.00000000"], ["83927.31000000", "0.01525000"], ["83903.48000000", "0.00000000"], ["83903.38000000", "0.00000000"], ["83899.43000000", "0.00115000"], ["83880.03000000", "0.00000000"], ["83003.50000000", "0.40000000"], ["82995.14000000", "0.00028000"], ["82700.00000000", "5.46947000"], ["75658.00000000", "0.01341000"], ["67251.89000000", "0.00058000"], ["33000.00000000", "2.93827000"], ["30263.35000000", "0.00100000"]], "a": [["84064.87000000", "4.45241000"], ["84066.47000000", "0.09860000"], ["84066.56000000", "0.00000000"], ["84066.66000000", "0.00000000"], ["84066.68000000", "0.00000000"], ["84066.69000000", "0.00000000"], ["84066.71000000", "0.01785000"], ["84067.27000000", "0.02389000"], ["84067.79000000", "0.14932000"], ["84080.79000000", "0.05943000"], ["84082.23000000", "1.60967000"], ["84090.00000000", "0.00500000"], ["84100.28000000", "0.00006000"], ["84152.99000000", "1.20665000"], ["84155.17000000", "0.00000000"], ["84159.86000000", "0.00678000"], ["84161.47000000", "0.00000000"], ["84234.57000000", "0.00000000"], ["84234.87000000", "0.00000000"], ["85035.71000000", "0.00118000"], ["85044.13000000", "0.60000000"]], "record_time": 1742555192.035677, "EXCHANGE": "BINANCE"}
{"e": "depthUpdate", "E": 1742555193014, "s": "BTCUSDT", "U": 64607131911, "u": 64607132020, "b": [["84064.86000000", "2.75788000"], ["84063.10000000", "0.02602000"], ["84063.09000000", "0.00000000"], ["84062.10000000", "0.00300000"], ["84062.00000000", "0.02392000"], ["84061.50000000", "0.00014000"], ["84061.35000000", "0.00014000"], ["84061.34000000", "0.02325000"], ["84060.81000000", "0.00014000"], ["84060.02000000", "0.00000000"], ["84052.00000000", "0.00535000"], ["84051.90000000", "0.00000000"], ["84038.66000000", "0.00000000"], ["84030.08000000", "0.00000000"], ["84027.20000000", "0.59506000"], ["84022.42000000", "0.04000000"], ["84018.24000000", "0.35572000"], ["84017.50000000", "0.00000000"], ["83969.20000000", "0.00000000"], ["83903.48000000", "0.01000000"], ["83895.67000000", "0.00000000"], ["83883.91000000", "0.00400000"], ["79800.00000000", "8.29832000"], ["75658.00000000", "0.01321000"], ["67251.89000000", "0.00058000"], ["33000.00000000", "2.93827000"], ["30263.35000000", "0.00120000"]], "a": [["84064.87000000", "5.31241000"], ["84066.47000000", "0.09860000"], ["84066.71000000", "0.00000000"], ["84067.25000000", "0.00000000"], ["84067.27000000", "0.02396000"], ["84067.70000000", "0.00014000"], ["84067.71000000", "0.23470000"], ["84067.72000000", "0.00000000"], ["84067.78000000", "0.00000000"], ["84067.79000000", "0.00000000"], ["84069.47000000", "0.02379000"], ["84072.00000000", "0.59320000"], ["84073.00000000", "0.00500000"], ["84075.17000000", "0.08992000"], ["84082.10000000", "0.00000000"], ["84082.23000000", "1.60967000"], ["84085.87000000", "0.00594000"], ["84090.00000000", "0.00000000"], ["84101.32000000", "0.00000000"], ["84104.88000000", "0.35663000"], ["84117.13000000", "0.00000000"], ["84120.50000000", "0.66638000"], ["84129.89000000", "0.02381000"], ["84142.42000000", "0.00000000"], ["84158.47000000", "0.59921000"], ["84234.87000000", "0.00000000"], ["84236.47000000", "0.00000000"], ["84236.87000000", "0.01000000"]], "record_time": 1742555193.037403, "EXCHANGE": "BINANCE"}
{"e": "depthUpdate", "E": 1742555194014, "s": "BTCUSDT", "U": 64607132021, "u": 64607132132, "b": [["84064.86000000", "2.66908000"], ["84063.10000000", "0.02602000"], ["84063.09000000", "0.00000000"], ["84062.10000000", "0.00000000"], ["84061.50000000", "0.00014000"], ["84061.35000000", "0.00014000"], ["84061.34000000", "0.02325000"], ["84059.54000000", "0.02324000"], ["84054.60000000", "0.00000000"], ["84052.00000000", "0.00235000"], ["84048.39000000", "0.08304000"], ["84040.02000000", "0.00911000"], ["84038.23000000", "0.00000000"], ["84026.58000000", "0.00000000"], ["84022.42000000", "0.00000000"], ["84022.01000000", "0.00000000"], ["84019.32000000", "0.00000000"], ["84019.19000000", "0.00000000"], ["84018.29000000", "0.08000000"], ["84016.69000000", "0.04942000"], ["84013.92000000", "0.40514000"], ["83969.20000000", "1.38926000"], ["83915.99000000", "0.00000000"], ["83899.19000000", "0.05951000"], ["83883.91000000", "0.00000000"], ["83883.81000000", "0.00400000"], ["83878.55000000", "0.00000000"], ["79800.00000000", "8.29820000"], ["75658.00000000", "0.01321000"], ["67251.89000000", "0.00058000"], ["33000.00000000", "2.93827000"]], "a": [["84064.87000000", "5.14492000"], ["84067.71000000", "0.17561000"], ["84068.26000000", "0.10689000"], ["84068.55000000", "0.00000000"], ["84073.28000000", "0.45300000"], ["84077.77000000", "0.00000000"], ["84078.55000000", "0.00000000"], ["84080.79000000", "0.00000000"], ["84082.23000000", "1.60967000"], ["84086.71000000", "0.00000000"], ["84090.00000000", "0.00500000"], ["84090.14000000", "0.00000000"], ["84091.86000000", "0.05943000"], ["84093.56000000", "0.00000000"], ["84094.42000000", "0.02802000"], ["84112.88000000", "0.00000000"], ["84128.78000000", "0.00000000"], ["84151.12000000", "0.04197000"], ["84152.18000000", "0.00841000"], ["84235.44000000", "0.99553000"], ["84235.64000000", "0.00000000"], ["84276.84000000", "0.01784000"], ["84283.55000000", "0.00000000"]], "record_time": 1742555194.038555, "EXCHANGE": "BINANCE"}
{"e": "depthUpdate", "E": 1742555195014, "s": "BTCUSDT", "U": 64607132133, "u": 64607132340, "b": [["84064.86000000", "2.79160000"], ["84063.99000000", "0.00014000"], ["84063.98000000", "0.04980000"], ["84063.97000000", "0.10007000"], ["84063.56000000", "0.00000000"], ["84063.11000000", "0.00000000"], ["84063.10000000", "0.00000000"], ["84063.09000000", "0.02484000"], ["84062.01000000", "0.00026000"], ["84061.62000000", "0.00011000"], ["84061.50000000", "0.00000000"], ["84061.49000000", "0.01518000"], ["84061.35000000", "0.00000000"], ["84061.34000000", "0.02318000"], ["84061.14000000", "0.00000000"], ["84060.60000000", "0.00500000"], ["84043.59000000", "0.02805000"], ["84040.28000000", "0.85714000"], ["84038.68000000", "1.34223000"], ["84029.90000000", "0.00000000"], ["84027.21000000", "0.52020000"], ["84027.19000000", "0.00000000"], ["84027.18000000", "0.00000000"], ["84024.54000000", "0.00000000"], ["84022.46000000", "0.28299000"], ["84022.42000000", "0.04000000"], ["84022.01000000", "0.01300000"], ["84017.78000000", "0.05724000"], ["83903.58000000", "0.01000000"], ["83903.48000000", "0.00000000"], ["83889.19000000", "0.00400000"], ["83883.81000000", "0.00000000"], ["83224.21000000", "0.00000000"], ["75658.00000000", "0.01321000"], ["67251.89000000", "0.00058000"], ["42000.00000000", "6.85261000"], ["33000.00000000", "2.93827000"], ["30263.35000000", "0.00140000"]], "a": [["84064.87000000", "4.56475000"], ["84066.00000000", "0.02267000"], ["84066.47000000", "0.09860000"], ["84066.57000000", "0.00000000"], ["84066.59000000", "0.01788000"], ["84066.60000000", "0.00000000"], ["84066.69000000", "0.00000000"], ["84067.27000000", "0.00000000"], ["84067.71000000", "0.17561000"], ["84073.00000000", "0.00000000"], ["84073.28000000", "0.45300000"], ["84074.96000000", "1.04503000"], ["84075.17000000", "0.00000000"], ["84075.48000000", "0.00000000"], ["84077.71000000", "1.00000000"], ["84077.77000000", "0.71284000"], ["84080.79000000", "0.00000000"], ["84082.25000000", "1.35816000"], ["84091.86000000", "0.05943000"], ["84094.42000000", "0.00000000"], ["84100.84000000", "0.02802000"], ["84101.85000000", "0.05808000"], ["84109.09000000", "0.00000000"], ["84129.89000000", "0.00000000"], ["84139.78000000", "0.02381000"], ["84152.99000000", "0.09793000"], ["84169.82000000", "0.24238000"], ["84209.18000000", "0.23337000"], ["84236.67000000", "0.01000000"], ["84236.77000000", "0.00000000"], ["84236.87000000", "0.00000000"], ["84331.08000000", "0.00000000"]], "record_time": 1742555195.035451, "EXCHANGE": "BINANCE"}
{"e": "depthUpdate", "E": 1742555196014, "s": "BTCUSDT", "U": 64607132341, "u": 64607132456, "b": [["84064.86000000", "2.60735000"], ["84063.97000000", "0.10007000"], ["84063.09000000", "0.00000000"], ["84063.03000000", "0.02471000"], ["84061.49000000", "0.01518000"], ["84027.79000000", "0.00000000"], ["84022.46000000", "0.23299000"], ["84020.89000000", "0.00000000"], ["84020.61000000", "0.05000000"], ["83889.19000000", "0.00000000"], ["83882.59000000", "0.00400000"], ["76700.00000000", "8.06938000"], ["75658.00000000", "0.01321000"], ["67251.89000000", "0.00058000"], ["42000.00000000", "6.85161000"], ["33000.00000000", "2.93827000"], ["20002.00000000", "0.00000000"], ["20001.00000000", "0.02099000"]], "a": [["84064.87000000", "5.34112000"], ["84064.88000000", "0.00041000"], ["84065.99000000", "0.00014000"], ["84066.38000000", "0.00014000"], ["84066.47000000", "0.09860000"], ["84066.59000000", "0.00000000"], ["84067.27000000", "0.02386000"], ["84067.62000000", "0.00014000"], ["84067.63000000", "0.15952000"], ["84067.70000000", "0.00007000"], ["84067.71000000", "0.17561000"], ["89800.00000000", "11.31327000"], ["91100.00000000", "0.69746000"]], "record_time": 1742555196.040191, "EXCHANGE": "BINANCE"}
{"e": "depthUpdate", "E": 1742555197014, "s": "BTCUSDT", "U": 64607132457, "u": 64607132749, "b": [["84064.86000000", "2.77598000"], ["84064.85000000", "0.12349000"], ["84064.61000000", "0.00007000"], ["84063.99000000", "0.00014000"], ["84063.98000000", "0.04974000"], ["84063.97000000", "0.10007000"], ["84063.03000000", "0.02405000"], ["84062.00000000", "0.02385000"], ["84061.49000000", "0.01518000"], ["84061.34000000", "0.02318000"], ["84060.79000000", "0.00000000"], ["84060.60000000", "0.00500000"], ["84060.23000000", "0.78552000"], ["84059.54000000", "0.00000000"], ["84059.53000000", "0.02348000"], ["84058.20000000", "0.00000000"], ["84058.19000000", "0.00000000"], ["84058.14000000", "0.00000000"], ["84044.25000000", "0.71284000"], ["84044.16000000", "0.75974000"], ["84043.27000000", "0.00000000"], ["84042.65000000", "0.00000000"], ["84040.28000000", "0.00000000"], ["84040.22000000", "0.28092000"], ["84040.18000000", "0.85714000"], ["84039.64000000", "0.89458000"], ["84031.52000000", "0.59504000"], ["84028.71000000", "0.00213000"], ["84027.48000000", "0.00000000"], ["84027.21000000", "0.00000000"], ["84027.20000000", "0.00000000"], ["84023.13000000", "0.00000000"], ["84022.83000000", "0.05946000"], ["84022.52000000", "0.04000000"], ["84022.42000000", "0.00000000"], ["84022.01000000", "0.00000000"], ["84020.61000000", "0.00000000"], ["84017.78000000", "0.00000000"], ["84013.49000000", "0.00000000"], ["83998.00000000", "0.00000000"], ["83993.91000000", "0.00000000"], ["83985.51000000", "0.00000000"], ["83981.05000000", "0.00298000"], ["83977.11000000", "0.00000000"], ["83975.15000000", "0.00213000"], ["83972.64000000", "0.00597000"], ["83969.20000000", "0.00000000"], ["83968.71000000", "0.00000000"], ["83964.24000000", "0.00895000"], ["83959.36000000", "0.00000000"], ["83955.84000000", "0.01194000"], ["83947.44000000", "0.01493000"], ["83903.58000000", "0.00000000"], ["83894.07000000", "0.00400000"], ["83882.59000000", "0.00000000"], ["83876.37000000", "0.00000000"], ["75658.00000000", "0.01321000"], ["67251.89000000", "0.00058000"], ["33000.00000000", "2.93827000"], ["30263.35000000", "0.00180000"]], "a": [["84064.87000000", "4.61515000"], ["84065.69000000", "0.00000000"], ["84066.47000000", "0.09860000"], ["84066.61000000", "0.00000000"], ["84066.66000000", "0.01801000"], ["84066.72000000", "0.00000000"], ["84067.27000000", "0.02360000"], ["84067.46000000", "0.00000000"], ["84067.57000000", "0.00011000"], ["84067.62000000", "0.00000000"], ["84067.63000000", "0.00000000"], ["84067.70000000", "0.00014000"], ["84067.71000000", "0.17561000"], ["84068.08000000", "0.00000000"], ["84068.09000000", "0.00000000"], ["84068.11000000", "0.00000000"], ["84068.53000000", "0.00000000"], ["84069.09000000", "0.11899000"], ["84072.49000000", "0.00000000"], ["84073.00000000", "0.00500000"], ["84073.28000000", "0.45300000"], ["84074.96000000", "0.54650000"], ["84077.71000000", "0.00000000"], ["84077.77000000", "0.00000000"], ["84078.27000000", "0.55409000"], ["84078.28000000", "0.00000000"], ["84082.25000000", "0.00000000"], ["84082.27000000", "1.33252000"], ["84087.21000000", "0.00000000"], ["84090.00000000", "0.00000000"], ["84091.49000000", "0.85662000"], ["84091.85000000", "0.00000000"], ["84093.81000000", "0.00000000"], ["84094.10000000", "0.00000000"], ["84095.32000000", "0.59504000"], ["84100.84000000", "0.00000000"], ["84101.56000000", "0.00008000"], ["84101.85000000", "0.00000000"], ["84102.98000000", "0.00000000"], ["84106.90000000", "0.05939000"], ["84107.69000000", "0.00000000"], ["84108.98000000", "0.00000000"], ["84111.55000000", "0.00000000"], ["84112.40000000", "0.00934000"], ["84112.83000000", "0.01868000"], ["84146.07000000", "0.00298000"], ["84152.08000000", "0.00000000"], ["84152.99000000", "0.09793000"], ["84154.48000000", "0.00597000"], ["84160.49000000", "0.00000000"], ["84162.89000000", "0.00895000"], ["84168.90000000", "0.00000000"], ["84171.30000000", "0.01194000"], ["84177.31000000", "0.04639000"], ["84179.71000000", "0.01493000"], ["84179.78000000", "0.18323000"], ["84185.73000000", "0.00000000"], ["84190.44000000", "0.00000000"], ["84235.44000000", "0.00000000"], ["84236.67000000", "0.00000000"], ["84319.84000000", "0.00237000"], ["84782.77000000", "0.00040000"], ["84790.67000000", "0.00000000"]], "record_time": 1742555197.066289, "EXCHANGE": "BINANCE"}
{"e": "depthUpdate", "E": 1742555198014, "s": "BTCUSDT", "U": 64607132750, "u": 64607132926, "b": [["84064.86000000", "3.02883000"], ["84060.23000000", "0.00000000"], ["84060.00000000", "0.02501000"], ["84058.45000000", "0.78554000"], ["84054.29000000", "0.00000000"], ["84043.59000000", "0.00000000"], ["84040.22000000", "0.00000000"], ["84031.52000000", "0.00000000"], ["84028.71000000", "0.59718000"], ["84025.95000000", "0.34057000"], ["84022.63000000", "0.02805000"], ["84022.52000000", "0.00000000"], ["84020.79000000", "0.00000000"], ["84019.49000000", "0.00000000"], ["83998.09000000", "0.05000000"], ["83976.91000000", "0.01863000"], ["83938.29000000", "0.00197000"], ["83936.70000000", "0.00000000"], ["83929.90000000", "0.00119000"], ["83928.01000000", "0.00000000"], ["83903.58000000", "0.01000000"], ["76700.00000000", "8.07328000"], ["75658.00000000", "0.01321000"], ["67251.89000000", "0.00058000"], ["33000.00000000", "2.93827000"], ["30263.35000000", "0.00200000"]], "a": [["84064.87000000", "4.50680000"], ["84066.00000000", "0.02267000"], ["84066.38000000", "0.00000000"], ["84066.39000000", "0.00000000"], ["84066.47000000", "0.09860000"], ["84066.62000000", "0.01789000"], ["84066.66000000", "0.00000000"], ["84066.73000000", "0.00754000"], ["84067.27000000", "0.00000000"], ["84067.71000000", "0.17568000"], ["84068.11000000", "0.00000000"], ["84068.50000000", "0.00000000"], ["84073.28000000", "0.45300000"], ["84074.96000000", "0.30166000"], ["84077.78000000", "0.00000000"], ["84078.26000000", "0.71284000"], ["84078.27000000", "0.78482000"], ["84079.04000000", "1.00000000"], ["84079.85000000", "0.00000000"], ["84081.27000000", "0.01863000"], ["84084.13000000", "0.02804000"], ["84090.37000000", "0.89158000"], ["84097.24000000", "0.05000000"], ["84112.40000000", "0.00000000"], ["84112.83000000", "0.00000000"], ["84113.69000000", "0.00000000"], ["84114.54000000", "0.00000000"], ["84119.68000000", "0.00000000"], ["84122.66000000", "0.00006000"], ["84129.82000000", "0.02381000"], ["84139.78000000", "0.00000000"], ["84149.05000000", "0.00000000"], ["84149.45000000", "0.00295000"], ["84153.64000000", "0.00084000"], ["84159.03000000", "0.00296000"], ["84165.56000000", "0.00000000"], ["84166.41000000", "0.00000000"], ["84233.72000000", "0.00119000"], ["84235.54000000", "0.99288000"], ["84236.67000000", "0.01000000"], ["84242.93000000", "0.00119000"], ["84244.12000000", "0.00000000"], ["84254.08000000", "0.00000000"]], "record_time": 1742555198.106066, "EXCHANGE": "BINANCE"}
{"e": "depthUpdate", "E": 1742555199014, "s": "BTCUSDT", "U": 64607132927, "u": 64607133059, "b": [["84064.86000000", "2.80866000"], ["84062.10000000", "0.00000000"], ["84062.00000000", "0.02385000"], ["84060.60000000", "0.00000000"], ["84052.00000000", "0.00235000"], ["84051.90000000", "0.00000000"], ["84045.38000000", "0.31161000"], ["84040.18000000", "0.00000000"], ["84035.18000000", "0.00755000"], ["84033.42000000", "0.00000000"], ["84027.11000000", "0.59887000"], ["84027.10000000", "0.85727000"], ["84025.95000000", "0.00000000"], ["84022.11000000", "0.01300000"], ["84021.12000000", "0.00000000"], ["84017.54000000", "0.05000000"], ["83982.39000000", "0.01863000"], ["83976.91000000", "0.00000000"], ["83903.68000000", "0.01000000"], ["83903.58000000", "0.00000000"], ["79800.00000000", "8.29820000"], ["75658.00000000", "0.01321000"], ["67251.89000000", "0.00058000"], ["60000.00000000", "73.17018000"], ["33000.00000000", "2.93827000"], ["30263.35000000", "0.00220000"]], "a": [["84064.87000000", "4.68249000"], ["84066.00000000", "0.02267000"], ["84066.38000000", "0.00000000"], ["84066.39000000", "0.00000000"], ["84066.42000000", "0.00014000"], ["84066.43000000", "0.02479000"], ["84066.47000000", "0.09860000"], ["84066.57000000", "0.00000000"], ["84066.60000000", "0.00000000"], ["84066.62000000", "0.00000000"], ["84066.68000000", "0.00000000"], ["84067.71000000", "0.17568000"], ["84067.80000000", "0.13519000"], ["84068.11000000", "0.05943000"], ["84072.00000000", "0.59320000"], ["84073.00000000", "0.00500000"], ["84073.28000000", "0.45300000"], ["84081.27000000", "0.00000000"], ["84082.10000000", "0.00000000"], ["84129.82000000", "0.00000000"], ["84130.30000000", "0.01863000"], ["84142.31000000", "0.02381000"]], "record_time": 1742555199.036093, "EXCHANGE": "BINANCE"}
{"e": "depthUpdate", "E": 1742555200014, "s": "BTCUSDT", "U": 64607133060, "u": 64607133156, "b": [["84064.86000000", "2.80866000"], ["84063.97000000", "0.10007000"], ["84063.03000000", "0.00000000"], ["84062.00000000", "0.02392000"], ["84044.25000000", "0.71284000"], ["84044.17000000", "0.00000000"], ["84022.63000000", "0.00000000"], ["84022.62000000", "0.00000000"], ["84022.11000000", "0.00000000"], ["84022.01000000", "0.01300000"], ["84016.65000000", "0.00000000"], ["84015.79000000", "0.00000000"], ["84014.08000000", "0.00935000"], ["84013.22000000", "0.01870000"], ["83998.09000000", "0.00000000"], ["83997.30000000", "0.00000000"], ["83982.39000000", "0.00000000"], ["83969.20000000", "1.38926000"], ["83894.07000000", "0.00000000"], ["83888.82000000", "0.00400000"], ["76700.00000000", "8.07346000"], ["75658.00000000", "0.01321000"], ["67251.89000000", "0.00058000"], ["33000.00000000", "2.93827000"]], "a": [["84064.87000000", "5.08731000"], ["84066.47000000", "0.09860000"], ["84066.57000000", "0.00000000"], ["84067.27000000", "0.02361000"], ["84067.71000000", "0.17561000"], ["84130.30000000", "0.00000000"], ["84151.11000000", "0.00841000"], ["84152.18000000", "0.00000000"], ["84905.50000000", "0.00000000"]], "record_time": 1742555200.035849, "EXCHANGE": "BINANCE"}
{"e": "depthUpdate", "E": 1742555201014, "s": "BTCUSDT", "U": 64607133157, "u": 64607133302, "b": [["84064.86000000", "2.23343000"], ["84064.85000000", "0.12414000"], ["84064.84000000", "0.00007000"], ["84064.76000000", "0.00007000"], ["84064.65000000", "0.00007000"], ["84064.61000000", "0.00000000"], ["84064.44000000", "0.00014000"], ["84064.43000000", "0.09309000"], ["84064.42000000", "0.14224000"], ["84063.99000000", "0.00000000"], ["84063.98000000", "0.00000000"], ["84062.97000000", "0.02457000"], ["84062.00000000", "0.02385000"], ["84060.81000000", "0.00000000"], ["84060.60000000", "0.00500000"], ["84049.59000000", "0.00000000"], ["84045.31000000", "0.00935000"], ["84044.25000000", "0.00000000"], ["84044.17000000", "0.71284000"], ["84043.59000000", "0.01870000"], ["84028.71000000", "0.00213000"], ["84025.42000000", "0.59506000"], ["84022.42000000", "0.00000000"], ["84022.32000000", "0.00000000"], ["84022.01000000", "0.00000000"], ["84021.81000000", "0.01300000"], ["84014.08000000", "0.00000000"], ["84013.22000000", "0.00000000"], ["84011.09000000", "0.00000000"], ["84007.66000000", "0.00000000"], ["83938.28000000", "0.00000000"], ["83888.82000000", "0.00000000"], ["83886.91000000", "0.00000000"], ["83882.95000000", "0.00400000"], ["83875.72000000", "0.00011000"], ["82620.44000000", "0.00000000"], ["75658.00000000", "0.01321000"], ["67251.89000000", "0.00058000"], ["33000.00000000", "2.93827000"], ["30263.35000000", "0.00280000"], ["20002.00000000", "0.00000000"], ["20001.00000000", "0.02099000"]], "a": [["84064.87000000", "5.65288000"], ["84065.74000000", "0.00011000"], ["84067.57000000", "0.00000000"], ["84072.69000000", "0.08992000"], ["84073.00000000", "0.00000000"], ["84075.57000000", "0.00000000"], ["84084.13000000", "0.00000000"], ["84090.00000000", "0.00500000"], ["84092.59000000", "0.05000000"], ["84097.24000000", "0.00000000"], ["84109.83000000", "0.00934000"], ["84111.55000000", "0.01868000"], ["84113.00000000", "0.00550000"], ["84235.54000000", "0.99593000"], ["84236.37000000", "0.01000000"], ["84236.67000000", "0.00000000"]], "record_time": 1742555201.063714, "EXCHANGE": "BINANCE"}
{"e": "depthUpdate", "E": 1742555202014, "s": "BTCUSDT", "U": 64607133303, "u": 64607133424, "b": [["84064.86000000", "2.71943000"], ["84064.85000000", "0.12414000"], ["84064.66000000", "0.00078000"], ["84064.65000000", "0.00000000"], ["84064.44000000", "0.00021000"], ["84064.43000000", "0.08849000"], ["84063.97000000", "0.10007000"], ["84062.97000000", "0.00000000"], ["84062.59000000", "0.02439000"], ["84062.00000000", "0.02385000"], ["84061.62000000", "0.00000000"], ["84061.49000000", "0.00000000"], ["84060.81000000", "0.00000000"], ["84060.18000000", "0.00011000"], ["84059.67000000", "0.01518000"], ["84059.53000000", "0.00000000"], ["84059.12000000", "0.02372000"], ["84045.38000000", "0.00000000"], ["84045.31000000", "0.00000000"], ["84043.59000000", "0.02805000"], ["84038.68000000", "0.00000000"], ["84038.21000000", "1.38802000"], ["84022.32000000", "0.04000000"], ["83998.00000000", "0.00000000"], ["83969.20000000", "1.38926000"], ["83903.68000000", "0.00000000"], ["82321.02000000", "0.00030000"], ["75658.00000000", "0.01321000"], ["67251.89000000", "0.00058000"], ["33000.00000000", "2.93827000"]], "a": [["84064.87000000", "5.65274000"], ["84065.13000000", "0.00014000"], ["84065.14000000", "0.01525000"], ["84067.27000000", "0.02354000"], ["84067.97000000", "0.00000000"], ["84072.69000000", "0.00000000"], ["84073.56000000", "0.00058000"], ["84089.69000000", "0.40088000"], ["84095.33000000", "0.68705000"], ["84097.58000000", "0.00000000"], ["84102.55000000", "0.01868000"], ["84111.55000000", "0.00000000"], ["84129.79000000", "0.02381000"], ["84142.31000000", "0.00000000"], ["84234.67000000", "0.00021000"], ["84234.97000000", "0.00000000"], ["84236.37000000", "0.00000000"], ["85306.50000000", "0.00000000"], ["85327.80000000", "0.17607000"], ["89000.23000000", "0.03245000"]], "record_time": 1742555202.111321, "EXCHANGE": "BINANCE"}
{"e": "depthUpdate", "E": 1742555203014, "s": "BTCUSDT", "U": 64607133425, "u": 64607133495, "b": [["84064.86000000", "1.90651000"], ["84064.76000000", "0.00007000"], ["84064.71000000", "0.00204000"], ["84064.44000000", "0.00014000"], ["84063.97000000", "0.10007000"], ["84062.59000000", "0.00000000"], ["84060.60000000", "0.00000000"], ["84059.12000000", "0.00000000"], ["84045.14000000", "0.14558000"], ["84044.17000000", "0.00000000"], ["84040.02000000", "0.00013000"], ["84037.44000000", "0.00000000"], ["84037.42000000", "0.03570000"], ["84024.11000000", "0.00441000"], ["84003.72000000", "0.00021000"], ["83947.45000000", "0.00075000"], ["83946.58000000", "0.00006000"], ["83903.68000000", "0.00050000"], ["83869.63000000", "0.00063000"], ["83869.62000000", "0.00000000"], ["83241.09000000", "0.00000000"], ["75658.00000000", "0.01321000"], ["67251.89000000", "0.00058000"], ["33000.00000000", "2.93827000"], ["21030.00000000", "0.00071000"]], "a": [["84064.87000000", "5.67032000"], ["84069.12000000", "0.04000000"], ["84073.00000000", "0.00500000"], ["84090.00000000", "0.00500000"], ["84143.17000000", "0.04342000"], ["84171.98000000", "0.05496000"], ["84175.18000000", "0.05496000"], ["84178.42000000", "0.04758000"], ["84211.21000000", "0.05497000"], ["84212.36000000", "0.00000000"], ["84215.96000000", "0.00000000"], ["84216.52000000", "0.00000000"], ["84234.67000000", "0.01021000"], ["84276.84000000", "0.00000000"]], "record_time": 1742555203.036226, "EXCHANGE": "BINANCE"}
{"e": "depthUpdate", "E": 1742555204014, "s": "BTCUSDT", "U": 64607133496, "u": 64607133778, "b": [["84064.86000000", "0.27023000"], ["84064.85000000", "0.00085000"], ["84064.76000000", "0.00007000"], ["84064.72000000", "0.00007000"], ["84064.71000000", "0.00007000"], ["84064.66000000", "0.00071000"], ["84064.44000000", "0.00000000"], ["84064.43000000", "0.00000000"], ["84064.42000000", "0.00000000"], ["84063.99000000", "0.00000000"], ["84063.98000000", "0.00028000"], ["84063.97000000", "0.10007000"], ["84063.14000000", "0.00000000"], ["84063.13000000", "0.00000000"], ["84063.01000000", "0.00000000"], ["84062.21000000", "0.00014000"], ["84062.20000000", "0.14029000"], ["84062.07000000", "0.00000000"], ["84062.01000000", "0.00040000"], ["84062.00000000", "0.02386000"], ["84061.35000000", "0.00014000"], ["84061.34000000", "0.02325000"], ["84060.81000000", "0.00000000"], ["84060.80000000", "0.12714000"], ["84060.01000000", "0.00000000"], ["84060.00000000", "0.02501000"], ["84059.12000000", "0.26765000"], ["84059.10000000", "0.00000000"], ["84059.09000000", "0.00000000"], ["84058.78000000", "0.00000000"], ["84058.68000000", "0.09380000"], ["84058.45000000", "0.00000000"], ["84056.73000000", "0.41241000"], ["84056.72000000", "0.78556000"], ["84056.55000000", "0.00000000"], ["84044.17000000", "0.71284000"], ["84037.42000000", "0.00000000"], ["84037.41000000", "0.03569000"], ["84000.00000000", "0.27413000"], ["83969.20000000", "0.00000000"], ["83918.38000000", "0.00000000"], ["83911.39000000", "0.00000000"], ["83882.95000000", "0.00000000"], ["83877.81000000", "0.00000000"], ["83870.64000000", "0.00000000"], ["83860.86000000", "0.00400000"], ["83634.69000000", "0.00000000"], ["83623.52000000", "0.00051000"], ["83231.96000000", "0.00079000"], ["80000.00000000", "155.37294000"], ["75658.00000000", "0.01321000"], ["67251.89000000", "0.00058000"], ["33000.00000000", "2.93827000"]], "a": [["84064.87000000", "5.65255000"], ["84066.43000000", "0.02479000"], ["84066.45000000", "0.00014000"], ["84066.46000000", "0.28045000"], ["84066.47000000", "0.19365000"], ["84067.70000000", "0.00000000"], ["84067.71000000", "0.00000000"], ["84070.87000000", "0.00013000"], ["84074.38000000", "0.08992000"], ["84078.08000000", "0.85675000"], ["84080.79000000", "0.05943000"], ["84086.97000000", "0.59508000"], ["84091.49000000", "0.00000000"], ["84091.86000000", "0.00000000"], ["84095.32000000", "0.00000000"], ["84100.84000000", "0.00934000"], ["84109.83000000", "0.00000000"], ["84150.16000000", "1.10872000"], ["84191.58000000", "0.00013000"], ["84275.65000000", "0.01784000"]], "record_time": 1742555204.038901, "EXCHANGE": "BINANCE"}
{"e": "depthUpdate", "E": 1742555205014, "s": "BTCUSDT", "U": 64607133779, "u": 64607133909, "b": [["84064.86000000", "0.24687000"], ["84063.97000000", "0.10007000"], ["84062.21000000", "0.00000000"], ["84062.20000000", "0.00000000"], ["84062.10000000", "0.00000000"], ["84062.01000000", "0.00044000"], ["84062.00000000", "0.02386000"], ["84061.35000000", "0.00014000"], ["84060.81000000", "0.00014000"], ["84060.80000000", "0.12721000"], ["84060.51000000", "0.09479000"], ["84060.15000000", "0.00014000"], ["84060.14000000", "0.25343000"], ["84059.12000000", "0.00000000"], ["84058.56000000", "0.02407000"], ["84052.00000000", "0.00235000"], ["84051.90000000", "0.00000000"], ["84044.17000000", "0.00000000"], ["84043.59000000", "0.00000000"], ["84040.02000000", "0.00923000"], ["84039.74000000", "0.00000000"], ["84032.90000000", "0.00000000"], ["84031.61000000", "0.00000000"], ["84029.05000000", "0.02805000"], ["83918.41000000", "0.99313000"], ["83903.78000000", "0.00050000"], ["83903.68000000", "0.00000000"], ["79800.00000000", "8.29820000"], ["75658.00000000", "0.01321000"], ["67251.89000000", "0.00058000"], ["42000.00000000", "6.85261000"], ["33000.00000000", "2.93827000"], ["30263.35000000", "0.00320000"], ["21030.00000000", "0.00071000"]], "a": [["84064.87000000", "5.82959000"], ["84068.06000000", "0.10688000"], ["84068.26000000", "0.00000000"], ["84072.00000000", "0.59320000"], ["84073.00000000", "0.00500000"], ["84082.10000000", "0.00000000"], ["84088.85000000", "0.02802000"], ["84090.00000000", "0.00000000"], ["84100.84000000", "0.00000000"], ["84102.55000000", "0.00000000"], ["84275.65000000", "0.00000000"], ["84905.50000000", "0.00000000"]], "record_time": 1742555205.036082, "EXCHANGE": "BINANCE"}
{"e": "depthUpdate", "E": 1742555206014, "s": "BTCUSDT", "U": 64607133910, "u": 64607133987, "b": [["84064.86000000", "0.26881000"], ["84062.00000000", "0.02386000"], ["84061.41000000", "0.00030000"], ["84061.40000000", "0.13847000"], ["84061.35000000", "0.00000000"], ["84060.81000000", "0.00038000"], ["84060.80000000", "0.22287000"], ["84060.52000000", "0.00000000"], ["84060.51000000", "0.09479000"], ["84060.15000000", "0.00000000"], ["84044.17000000", "0.71284000"], ["84040.02000000", "0.00013000"], ["84037.41000000", "0.00000000"], ["84037.36000000", "0.03570000"], ["84035.18000000", "0.00000000"], ["84032.05000000", "0.00753000"], ["83918.41000000", "0.00000000"], ["83903.88000000", "0.00050000"], ["83903.78000000", "0.00000000"], ["83881.25000000", "0.00000000"], ["83800.92000000", "0.00000000"], ["83212.96000000", "0.00000000"], ["83211.93000000", "0.00000000"], ["83206.27000000", "0.00060000"], ["83205.25000000", "0.00060000"], ["75658.00000000", "0.01321000"], ["67251.89000000", "0.00058000"], ["42000.00000000", "6.85161000"], ["33000.00000000", "2.93827000"], ["30263.35000000", "0.00360000"], ["21030.00000000", "0.00000000"], ["20002.00000000", "0.00000000"], ["20001.00000000", "0.02099000"]], "a": [["84064.87000000", "5.72945000"], ["84078.07000000", "1.04279000"], ["84078.27000000", "0.00000000"], ["84079.04000000", "0.00000000"], ["84088.68000000", "0.37695000"], ["84089.69000000", "0.02394000"], ["84234.17000000", "0.01013000"], ["84234.67000000", "0.00021000"], ["84769.67000000", "0.00060000"], ["84775.07000000", "0.00000000"], ["84778.17000000", "0.00040000"], ["84782.77000000", "0.00000000"]], "record_time": 1742555206.035651, "EXCHANGE": "BINANCE"}
{"e": "depthUpdate", "E": 1742555207014, "s": "BTCUSDT", "U": 64607133988, "u": 64607134255, "b": [["84064.86000000", "0.18986000"], ["84063.97000000", "0.10007000"], ["84062.37000000", "0.00000000"], ["84062.36000000", "0.00000000"], ["84062.01000000", "0.00040000"], ["84062.00000000", "0.02386000"], ["84061.41000000", "0.00000000"], ["84061.40000000", "0.00000000"], ["84061.35000000", "0.00016000"], ["84061.34000000", "0.02325000"], ["84060.81000000", "0.00000000"], ["84060.80000000", "0.00000000"], ["84060.60000000", "0.00500000"], ["84060.53000000", "0.00000000"], ["84060.52000000", "0.00014000"], ["84060.51000000", "0.09486000"], ["84060.14000000", "0.00000000"], ["84060.00000000", "0.00241000"], ["84059.77000000", "0.00062000"], ["84059.76000000", "0.19751000"], ["84059.75000000", "0.17163000"], ["84058.56000000", "0.00000000"], ["84057.02000000", "0.25256000"], ["84056.72000000", "0.00000000"], ["84055.81000000", "0.00000000"], ["84055.03000000", "0.78557000"], ["84054.73000000", "0.00000000"], ["84048.97000000", "0.15048000"], ["84045.14000000", "0.00000000"], ["84044.17000000", "0.00000000"], ["84042.19000000", "1.00000000"], ["84039.72000000", "0.00895000"], ["84037.36000000", "0.00000000"], ["84037.13000000", "0.00000000"], ["84037.08000000", "0.00000000"], ["84036.84000000", "0.00000000"], ["84036.78000000", "0.00000000"], ["84036.70000000", "0.00000000"], ["84036.53000000", "0.08304000"], ["84036.46000000", "0.00000000"], ["84036.35000000", "0.00000000"], ["84036.27000000", "0.00000000"], ["84036.11000000", "0.00000000"], ["84035.92000000", "0.00000000"], ["84035.80000000", "0.00000000"], ["84035.68000000", "0.00000000"], ["84035.65000000", "0.00000000"], ["84035.63000000", "0.03569000"], ["84025.42000000", "0.00000000"], ["84022.84000000", "0.59508000"], ["84022.32000000", "0.00000000"], ["84022.02000000", "0.00000000"], ["84021.82000000", "0.00000000"], ["84021.81000000", "0.00000000"], ["84021.62000000", "0.00000000"], ["84021.61000000", "0.00000000"], ["84021.42000000", "0.00000000"], ["84021.32000000", "0.00000000"], ["84021.12000000", "0.00000000"], ["84020.02000000", "0.00000000"], ["83998.10000000", "0.00000000"], ["83982.62000000", "0.00000000"], ["83977.45000000", "0.04757000"], ["83967.67000000", "0.55541000"], ["83966.37000000", "0.00000000"], ["83947.45000000", "0.00075000"], ["83946.57000000", "0.00000000"], ["83918.43000000", "0.99313000"], ["83903.88000000", "0.00000000"], ["83903.38000000", "0.00000000"], ["83901.98000000", "0.00000000"], ["83869.65000000", "0.00063000"], ["83869.64000000", "0.00000000"], ["83869.63000000", "0.00000000"], ["83655.00000000", "0.00429000"], ["75658.00000000", "0.01321000"], ["67251.89000000", "0.00058000"], ["33000.00000000", "2.93827000"], ["30263.35000000", "0.00400000"]], "a": [["84064.87000000", "5.74998000"], ["84064.88000000", "0.00041000"], ["84065.13000000", "0.00014000"], ["84065.14000000", "0.01525000"], ["84065.32000000", "0.00014000"], ["84065.33000000", "0.04007000"], ["84065.99000000", "0.00014000"], ["84066.42000000", "0.00014000"], ["84066.46000000", "0.28038000"], ["84067.46000000", "0.08992000"], ["84069.12000000", "0.00000000"], ["84069.91000000", "0.15916000"], ["84071.96000000", "0.72137000"], ["84071.97000000", "0.71284000"], ["84071.99000000", "0.00000000"], ["84073.00000000", "0.00000000"], ["84073.85000000", "0.02379000"], ["84074.96000000", "0.56395000"], ["84075.56000000", "1.00000000"], ["84078.84000000", "0.00000000"], ["84081.29000000", "0.02379000"], ["84090.00000000", "0.00000000"], ["84092.59000000", "0.00000000"], ["84098.26000000", "0.00006000"], ["84098.37000000", "0.05947000"], ["84105.69000000", "0.00000000"], ["84107.02000000", "0.05947000"], ["84152.26000000", "0.00000000"], ["84176.99000000", "0.04758000"], ["84186.39000000", "0.05496000"], ["84190.50000000", "0.05496000"], ["84214.37000000", "0.00000000"], ["84215.21000000", "0.04756000"], ["84217.21000000", "0.10134000"], ["84234.07000000", "0.00000000"], ["84234.17000000", "0.00013000"], ["84242.41000000", "0.00000000"], ["85306.50000000", "0.11738000"], ["85327.80000000", "0.05869000"]], "record_time": 1742555207.036924, "EXCHANGE": "BINANCE"}
{"e": "depthUpdate", "E": 1742555208014, "s": "BTCUSDT", "U": 64607134256, "u": 64607134370, "b": [["84064.86000000", "0.18944000"], ["84064.85000000", "0.00517000"], ["84061.34000000", "0.02325000"], ["84061.04000000", "0.00014000"], ["84061.03000000", "0.13454000"], ["84060.52000000", "0.00000000"], ["84060.51000000", "0.09479000"], ["84060.21000000", "0.02439000"], ["84059.77000000", "0.00048000"], ["84059.75000000", "0.00000000"], ["84058.77000000", "0.35601000"], ["84057.02000000", "0.00000000"], ["84056.85000000", "0.02369000"], ["84033.77000000", "0.00000000"], ["84024.18000000", "0.05071000"], ["84022.84000000", "0.00000000"], ["84020.03000000", "0.59510000"], ["84020.02000000", "0.00000000"], ["84019.61000000", "0.00000000"], ["84017.54000000", "0.00000000"], ["84002.59000000", "0.00000000"], ["83985.67000000", "0.01863000"], ["83977.53000000", "0.00100000"], ["83929.83000000", "0.00000000"], ["83927.31000000", "0.00000000"], ["83903.38000000", "0.00050000"], ["83873.91000000", "0.01525000"], ["83211.68000000", "0.00060000"], ["83210.66000000", "0.00060000"], ["83206.27000000", "0.00000000"], ["83205.25000000", "0.00000000"], ["75658.00000000", "0.01321000"], ["67251.89000000", "0.00058000"], ["33000.00000000", "2.93827000"], ["21030.00000000", "0.00071000"]], "a": [["84064.87000000", "5.59906000"], ["84081.27000000", "0.01863000"], ["84087.88000000", "0.05000000"], ["84124.96000000", "0.04834000"], ["84127.65000000", "0.05980000"], ["84139.32000000", "0.00000000"], ["84152.18000000", "0.00100000"], ["84153.65000000", "0.05574000"], ["84159.86000000", "0.00000000"], ["84179.15000000", "0.04639000"], ["84179.98000000", "0.75581000"], ["84181.26000000", "0.00000000"], ["84182.07000000", "0.04639000"], ["84182.86000000", "0.05296000"], ["84183.13000000", "0.04639000"], ["84183.21000000", "0.04639000"], ["84187.04000000", "0.05296000"], ["84187.92000000", "0.12000000"], ["84200.44000000", "0.00000000"], ["84217.60000000", "0.00000000"], ["84219.99000000", "0.00000000"], ["84221.93000000", "0.00000000"], ["84222.95000000", "0.00000000"], ["84224.72000000", "0.00000000"], ["84224.97000000", "0.00000000"], ["84226.99000000", "0.00000000"], ["84232.66000000", "0.00000000"], ["84233.66000000", "0.01000000"], ["84234.07000000", "0.00000000"], ["84243.56000000", "0.00000000"], ["84319.84000000", "0.00000000"], ["84769.67000000", "0.00000000"], ["84775.07000000", "0.00060000"], ["84778.17000000", "0.00000000"], ["84782.77000000", "0.00040000"]], "record_time": 1742555208.243284, "EXCHANGE": "BINANCE"}
{"e": "depthUpdate", "E": 1742555209014, "s": "BTCUSDT", "U": 64607134371, "u": 64607134468, "b": [["84064.86000000", "0.18402000"], ["84064.02000000", "0.00014000"], ["84064.01000000", "0.02157000"], ["84061.03000000", "0.13447000"], ["84060.60000000", "0.00000000"], ["84060.53000000", "0.00000000"], ["84060.52000000", "0.00000000"], ["84060.21000000", "0.00000000"], ["84060.18000000", "0.00000000"], ["84059.85000000", "0.00007000"], ["84059.84000000", "0.35499000"], ["84059.77000000", "0.00024000"], ["84059.76000000", "0.00000000"], ["84059.67000000", "0.00000000"], ["84058.77000000", "0.00000000"], ["84057.71000000", "0.00011000"], ["84057.21000000", "0.01518000"], ["84056.85000000", "0.00000000"], ["84044.25000000", "0.00000000"], ["84020.02000000", "0.00000000"], ["84019.61000000", "0.00000000"], ["84014.69000000", "0.00000000"], ["83963.54000000", "1.38926000"], ["83920.41000000", "0.00000000"], ["83894.04000000", "0.21413000"], ["83789.73000000", "0.00008000"], ["83739.77000000", "0.00000000"], ["83728.60000000", "0.00149000"], ["75658.00000000", "0.01321000"], ["67251.89000000", "0.00058000"], ["60000.00000000", "73.17018000"], ["33000.00000000", "2.93827000"], ["21030.00000000", "0.00071000"]], "a": [["84064.87000000", "5.43432000"], ["84067.46000000", "0.00000000"], ["84073.00000000", "0.00500000"], ["84081.26000000", "0.59510000"], ["84081.27000000", "0.00000000"], ["84086.97000000", "0.00000000"], ["84090.00000000", "0.00500000"], ["84130.30000000", "0.01863000"], ["84150.16000000", "0.00000000"], ["84235.54000000", "0.00000000"]], "record_time": 1742555209.119102, "EXCHANGE": "BINANCE"}
{"e": "depthUpdate", "E": 1742555347014, "s": "BTCUSDT", "U": 64607199124, "u": 64607199427, "b": [["84061.31000000", "5.69408000"], ["84061.18000000", "0.02492000"], ["84060.98000000", "0.04013000"], ["84060.56000000", "0.42843000"], ["84060.16000000", "0.04006000"], ["84060.15000000", "0.04006000"], ["84060.14000000", "0.78558000"], ["84060.07000000", "0.04006000"], ["84060.01000000", "0.10712000"], ["84058.30000000", "0.00759000"], ["84057.91000000", "0.00000000"], ["84057.63000000", "0.04000000"], ["84057.57000000", "0.05948000"], ["84057.55000000", "0.11896000"], ["84057.18000000", "0.00594000"], ["84056.78000000", "0.04000000"], ["84055.99000000", "0.00000000"], ["84055.94000000", "0.04000000"], ["84055.88000000", "0.04000000"], ["84054.15000000", "0.00000000"], ["84054.03000000", "0.00000000"], ["84053.86000000", "0.00000000"], ["84053.67000000", "0.05948000"], ["84053.32000000", "0.00000000"], ["84053.25000000", "0.00000000"], ["84052.45000000", "0.00000000"], ["84051.85000000", "0.00000000"], ["84050.98000000", "0.15892000"], ["84050.70000000", "0.00000000"], ["84049.11000000", "0.00000000"], ["84049.07000000", "0.00000000"], ["84048.32000000", "0.00000000"], ["84048.02000000", "1.10504000"], ["84047.67000000", "0.00000000"], ["84046.60000000", "0.00500000"], ["84045.79000000", "1.31015000"], ["84044.21000000", "1.20958000"], ["84044.20000000", "0.00000000"], ["84043.31000000", "0.00000000"], ["84039.39000000", "0.00000000"], ["84036.10000000", "0.59502000"], ["84033.33000000", "0.06805000"], ["84032.48000000", "0.00000000"], ["84027.99000000", "0.00000000"], ["84022.63000000", "0.00000000"], ["84018.92000000", "0.04000000"], ["84018.73000000", "0.04000000"], ["84010.68000000", "0.04000000"], ["84010.67000000", "0.04000000"], ["84009.87000000", "0.27594000"], ["84006.26000000", "0.04000000"], ["83997.25000000", "0.00000000"], ["83989.45000000", "0.00000000"], ["83975.95000000", "0.04000000"], ["83973.51000000", "0.00000000"], ["83972.03000000", "1.38932000"], ["83958.54000000", "0.00000000"], ["83953.53000000", "0.00400000"], ["83951.07000000", "0.00000000"], ["83941.01000000", "0.12000000"], ["83927.63000000", "0.00000000"], ["83896.99000000", "0.01013000"], ["83896.69000000", "0.00000000"], ["83896.59000000", "0.00000000"], ["80673.60000000", "0.03568000"], ["75655.00000000", "0.00137000"], ["67249.05000000", "0.00058000"], ["33000.00000000", "2.93827000"]], "a": [["84061.32000000", "0.13387000"], ["84062.03000000", "0.00024000"], ["84062.13000000", "0.00007000"], ["84062.67000000", "0.00000000"], ["84063.21000000", "0.00000000"], ["84063.30000000", "0.00000000"], ["84063.90000000", "0.00000000"], ["84063.98000000", "0.00000000"], ["84064.59000000", "0.01341000"], ["84064.61000000", "0.00027000"], ["84064.62000000", "0.00000000"], ["84064.92000000", "0.00014000"], ["84064.93000000", "0.02430000"], ["84065.20000000", "0.00000000"], ["84065.32000000", "0.00756000"], ["84065.35000000", "0.00000000"], ["84065.50000000", "0.00500000"], ["84065.52000000", "0.00006000"], ["84065.53000000", "0.00000000"], ["84066.00000000", "0.00000000"], ["84066.43000000", "0.78547000"], ["84066.91000000", "0.00000000"], ["84067.79000000", "0.26287000"], ["84067.83000000", "0.00000000"], ["84068.23000000", "0.00000000"], ["84069.61000000", "0.11315000"], ["84069.65000000", "0.00000000"], ["84069.80000000", "0.14361000"], ["84070.17000000", "0.00000000"], ["84070.21000000", "0.00000000"], ["84070.55000000", "0.02465000"], ["84070.70000000", "0.00000000"], ["84073.92000000", "0.01189000"], ["84074.55000000", "0.00000000"], ["84074.98000000", "0.00000000"], ["84075.01000000", "0.00000000"], ["84075.02000000", "0.00000000"], ["84075.07000000", "0.03569000"], ["84075.37000000", "0.02336000"], ["84076.14000000", "0.04000000"], ["84076.98000000", "0.04000000"], ["84077.41000000", "0.00000000"], ["84077.59000000", "0.10676000"], ["84077.70000000", "0.35663000"], ["84079.71000000", "0.00000000"], ["84080.35000000", "0.08000000"], ["84081.19000000", "0.07600000"], ["84081.51000000", "0.04000000"], ["84082.08000000", "0.06849000"], ["84082.70000000", "0.85446000"], ["84084.38000000", "0.85669000"], ["84086.05000000", "0.22452000"], ["84089.08000000", "0.00000000"], ["84091.12000000", "1.31278000"], ["84105.09000000", "0.00000000"], ["84107.82000000", "0.00000000"], ["84135.00000000", "0.33743000"], ["84136.73000000", "0.00000000"], ["84140.87000000", "0.00000000"], ["84147.40000000", "0.02380000"], ["84152.55000000", "0.00000000"], ["84153.34000000", "0.00000000"], ["84157.52000000", "0.00000000"], ["84158.36000000", "0.00000000"], ["84159.02000000", "0.00000000"], ["84160.30000000", "0.00000000"], ["84162.56000000", "0.00000000"], ["84163.22000000", "0.00000000"], ["84166.09000000", "0.00841000"], ["84231.86000000", "0.00000000"], ["84232.12000000", "0.00000000"], ["84232.56000000", "0.00000000"], ["84232.66000000", "0.00000000"], ["84233.06000000", "0.01000000"]], "record_time": 1742555347.039582, "EXCHANGE": "BINANCE"}
