{"e": "depthUpdate", "E": 1742584911014, "s": "BTCUSDT", "U": 64637900516, "u": 64637902020, "b": [["84076.46000000", "0.00000000"], ["84076.45000000", "0.00000000"], ["84076.44000000", "0.00000000"], ["84076.16000000", "0.00000000"], ["84076.15000000", "0.00000000"], ["84076.14000000", "0.00000000"], ["84076.08000000", "0.00000000"], ["84076.04000000", "0.00000000"], ["84076.03000000", "0.00000000"], ["84075.95000000", "0.00000000"], ["84075.50000000", "0.00000000"], ["84075.49000000", "0.00000000"], ["84075.48000000", "0.00000000"], ["84075.47000000", "0.38050000"], ["84075.46000000", "0.00048000"], ["84074.80000000", "0.00000000"], ["84074.79000000", "0.00000000"], ["84074.66000000", "0.00007000"], ["84074.34000000", "0.00000000"], ["84074.17000000", "0.00000000"], ["84074.02000000", "0.00000000"], ["84073.99000000", "0.00000000"], ["84073.98000000", "0.00000000"], ["84073.93000000", "0.00007000"], ["84073.90000000", "0.00000000"], ["84073.86000000", "0.00000000"], ["84073.81000000", "0.00007000"], ["84073.80000000", "0.00007000"], ["84073.72000000", "0.00044000"], ["84073.71000000", "0.00013000"], ["84073.67000000", "0.00014000"], ["84073.66000000", "0.00301000"], ["84073.31000000", "0.00039000"], ["84073.30000000", "0.06571000"], ["84073.21000000", "0.00022000"], ["84073.20000000", "0.30558000"], ["84073.03000000", "0.00503000"], ["84073.02000000", "0.00015000"], ["84073.00000000", "0.00000000"], ["84072.97000000", "0.00000000"], ["84072.84000000", "0.00000000"], ["84072.83000000", "0.00000000"], ["84072.63000000", "0.00000000"], ["84072.62000000", "0.17757000"], ["84072.60000000", "0.00000000"], ["84072.28000000", "0.00118000"], ["84072.16000000", "0.00000000"], ["84072.15000000", "0.03390000"], ["84071.94000000", "0.00000000"], ["84071.93000000", "0.00000000"], ["84071.90000000", "0.00500000"], ["84071.85000000", "0.00000000"], ["84071.84000000", "0.02539000"], ["84071.39000000", "0.00000000"], ["84071.32000000", "0.00000000"], ["84071.26000000", "0.00000000"], ["84071.25000000", "0.02207000"], ["84071.07000000", "0.00000000"], ["84071.06000000", "0.00000000"], ["84070.81000000", "0.00000000"], ["84070.80000000", "0.14620000"], ["84070.15000000", "0.00000000"], ["84070.01000000", "0.00000000"], ["84069.79000000", "0.00000000"], ["84069.74000000", "0.00000000"], ["84069.59000000", "0.00000000"], ["84069.58000000", "0.00000000"], ["84069.49000000", "0.00000000"], ["84069.43000000", "0.00000000"], ["84069.38000000", "0.02353000"], ["84069.11000000", "0.00000000"], ["84069.08000000", "0.00118000"], ["84068.84000000", "0.00000000"], ["84068.83000000", "0.00000000"], ["84068.75000000", "0.00848000"], ["84068.38000000", "0.02973000"], ["84067.48000000", "0.00000000"], ["84067.47000000", "0.00013000"], ["84067.30000000", "0.00000000"], ["84067.20000000", "0.00000000"], ["84067.06000000", "0.00000000"], ["84066.54000000", "0.00118000"], ["84066.41000000", "0.00000000"], ["84066.29000000", "0.00000000"], ["84066.21000000", "0.00000000"], ["84065.38000000", "0.00000000"], ["84064.64000000", "0.00000000"], ["84064.21000000", "0.00000000"], ["84063.45000000", "0.00000000"], ["84063.26000000", "0.00007000"], ["84063.21000000", "0.14000000"], ["84062.50000000", "0.00400000"], ["84061.97000000", "0.17899000"], ["84061.88000000", "0.22696000"], ["84061.87000000", "0.00000000"], ["84061.82000000", "0.00000000"], ["84061.74000000", "0.15674000"], ["84061.53000000", "0.00000000"], ["84061.32000000", "0.14739000"], ["84061.14000000", "0.05353000"], ["84060.90000000", "0.04572000"], ["84060.89000000", "0.00000000"], ["84060.50000000", "0.00000000"], ["84060.06000000", "0.00000000"], ["84059.35000000", "0.00000000"], ["84059.17000000", "0.00094000"], ["84059.08000000", "0.00000000"], ["84058.80000000", "0.00006000"], ["84058.67000000", "0.03000000"], ["84058.39000000", "0.00000000"], ["84058.05000000", "0.00000000"], ["84057.61000000", "0.00000000"], ["84057.38000000", "0.00000000"], ["84057.26000000", "0.00000000"], ["84056.76000000", "0.21691000"], ["84056.75000000", "0.16000000"], ["84056.50000000", "0.00050000"], ["84055.37000000", "0.03569000"], ["84055.00000000", "0.00000000"], ["84054.85000000", "0.00000000"], ["84054.71000000", "0.00000000"], ["84053.70000000", "0.00873000"], ["84053.55000000", "0.00000000"], ["84052.49000000", "0.00013000"], ["84052.36000000", "0.00000000"], ["84051.87000000", "0.16280000"], ["84051.84000000", "1.13067000"], ["84051.83000000", "0.00000000"], ["84051.50000000", "0.00100000"], ["84051.10000000", "0.00922000"], ["84050.56000000", "0.05828000"], ["84050.24000000", "0.00300000"], ["84048.34000000", "0.00000000"], ["84048.02000000", "0.01189000"], ["84047.74000000", "0.85706000"], ["84046.90000000", "0.00000000"], ["84046.61000000", "0.59500000"], ["84042.84000000", "1.35333000"], ["84040.45000000", "0.00000000"], ["84039.20000000", "0.01189000"], ["84038.39000000", "0.00000000"], ["84038.02000000", "0.00000000"], ["84035.44000000", "0.41445000"], ["84035.43000000", "0.00000000"], ["84035.42000000", "0.00000000"], ["84034.44000000", "0.00146000"], ["84034.14000000", "0.85720000"], ["84034.03000000", "0.04628000"], ["84033.27000000", "0.12469000"], ["84028.63000000", "0.89155000"], ["84026.16000000", "0.00000000"], ["84024.18000000", "0.00000000"], ["84024.01000000", "0.00000000"], ["84021.31000000", "0.00295000"], ["84020.56000000", "0.00000000"], ["84019.07000000", "0.00000000"], ["84018.70000000", "0.00000000"], ["84016.58000000", "0.04228000"], ["84016.31000000", "0.00000000"], ["84014.34000000", "0.00295000"], ["84010.69000000", "0.09642000"], ["84008.93000000", "0.00000000"], ["84006.58000000", "0.00000000"], ["84005.13000000", "0.00000000"], ["84004.64000000", "0.00061000"], ["84002.55000000", "0.00000000"], ["84001.35000000", "0.00816000"], ["83999.32000000", "0.00296000"], ["83993.99000000", "0.00000000"], ["83987.35000000", "0.03236000"], ["83984.05000000", "1.02877000"], ["83983.26000000", "0.15631000"], ["83982.58000000", "0.00000000"], ["83981.72000000", "0.00000000"], ["83980.69000000", "0.00000000"], ["83980.50000000", "0.00000000"], ["83980.49000000", "0.00000000"], ["83980.43000000", "0.00000000"], ["83980.36000000", "0.00000000"], ["83980.19000000", "0.00000000"], ["83980.14000000", "0.00146000"], ["83979.85000000", "0.00000000"], ["83979.41000000", "0.00000000"], ["83979.19000000", "0.00000000"], ["83977.63000000", "0.00000000"], ["83976.95000000", "0.00000000"], ["83976.74000000", "0.05297000"], ["83976.36000000", "0.04997000"], ["83976.26000000", "0.00000000"], ["83976.07000000", "0.00000000"], ["83975.97000000", "0.00000000"], ["83975.12000000", "0.00000000"], ["83974.11000000", "0.00000000"], ["83973.00000000", "0.00000000"], ["83972.62000000", "0.00000000"], ["83972.22000000", "0.00000000"], ["83971.87000000", "0.00000000"], ["83971.80000000", "0.05497000"], ["83969.78000000", "0.00000000"], ["83969.60000000", "0.00000000"], ["83969.31000000", "0.00000000"], ["83968.26000000", "0.05497000"], ["83967.14000000", "0.00000000"], ["83965.23000000", "0.00000000"], ["83965.06000000", "0.00000000"], ["83963.93000000", "0.05497000"], ["83963.91000000", "0.04197000"], ["83963.15000000", "0.79082000"], ["83962.64000000", "0.05497000"], ["83961.75000000", "0.00000000"], ["83960.60000000", "1.42323000"], ["83959.75000000", "0.05497000"], ["83959.51000000", "0.05497000"], ["83959.32000000", "0.00000000"], ["83957.37000000", "0.05496000"], ["83956.91000000", "0.05097000"], ["83956.72000000", "0.05497000"], ["83956.26000000", "0.05097000"], ["83956.19000000", "0.10000000"], ["83956.02000000", "0.05497000"], ["83955.31000000", "0.05297000"], ["83955.14000000", "0.05496000"], ["83954.10000000", "0.05097000"], ["83954.03000000", "0.05497000"], ["83953.89000000", "0.05497000"], ["83953.46000000", "0.05097000"], ["83952.80000000", "0.05297000"], ["83952.65000000", "0.05497000"], ["83952.62000000", "0.05496000"], ["83950.95000000", "0.00000000"], ["83950.88000000", "0.04997000"], ["83949.63000000", "0.05297000"], ["83949.41000000", "0.10294000"], ["83949.39000000", "0.05496000"], ["83948.51000000", "0.04997000"], ["83945.36000000", "0.04997000"], ["83944.28000000", "0.04497000"], ["83942.60000000", "0.04997000"], ["83942.09000000", "0.04619000"], ["83941.94000000", "0.04997000"], ["83939.31000000", "0.04997000"], ["83939.00000000", "0.04297000"], ["83938.56000000", "0.04497000"], ["83936.46000000", "0.00263000"], ["83936.34000000", "0.04497000"], ["83913.06000000", "0.00119000"], ["83900.01000000", "0.00000000"], ["83856.33000000", "0.00008000"], ["83849.02000000", "0.00400000"], ["83848.05000000", "0.00000000"], ["83846.79000000", "0.00000000"], ["83846.57000000", "0.00013000"], ["83841.68000000", "0.00000000"], ["83837.81000000", "0.00000000"], ["83834.84000000", "0.00000000"], ["82814.33000000", "0.00100000"], ["80680.44000000", "0.00000000"], ["75670.00000000", "0.00208000"], ["75668.00000000", "0.13247000"], ["75667.00000000", "0.00152000"], ["67261.17000000", "0.00000000"], ["67260.38000000", "0.00058000"], ["33000.00000000", "2.93827000"], ["21030.20000000", "0.00071000"]], "a": [["84075.48000000", "9.26223000"], ["84075.49000000", "0.00046000"], ["84075.50000000", "0.00000000"], ["84075.51000000", "0.00000000"], ["84075.60000000", "0.00013000"], ["84075.96000000", "0.00000000"], ["84075.99000000", "0.00021000"], ["84076.00000000", "0.02274000"], ["84076.04000000", "0.00007000"], ["84076.05000000", "0.00007000"], ["84076.09000000", "0.00000000"], ["84076.10000000", "0.00021000"], ["84076.11000000", "0.65993000"], ["84076.12000000", "0.00000000"], ["84076.13000000", "0.00006000"], ["84076.14000000", "0.00000000"], ["84076.15000000", "0.00000000"], ["84076.16000000", "1.87842000"], ["84076.17000000", "0.00000000"], ["84076.35000000", "0.00000000"], ["84076.36000000", "0.00000000"], ["84076.43000000", "0.00000000"], ["84076.44000000", "0.00000000"], ["84076.45000000", "0.00000000"], ["84076.46000000", "0.08367000"], ["84076.47000000", "0.18836000"], ["84076.48000000", "0.00000000"], ["84076.56000000", "0.00201000"], ["84076.62000000", "0.00000000"], ["84076.63000000", "0.04000000"], ["84077.15000000", "0.00664000"], ["84077.18000000", "0.00007000"], ["84077.29000000", "0.00024000"], ["84077.30000000", "0.00006000"], ["84078.00000000", "0.02260000"], ["84078.14000000", "0.00000000"], ["84078.40000000", "0.00400000"], ["84078.42000000", "0.00000000"], ["84078.43000000", "0.00000000"], ["84078.46000000", "0.15949000"], ["84078.47000000", "0.17899000"], ["84078.48000000", "0.00000000"], ["84078.73000000", "0.01189000"], ["84078.86000000", "0.00000000"], ["84078.89000000", "0.00000000"], ["84078.93000000", "0.00118000"], ["84079.11000000", "0.02228000"], ["84079.24000000", "0.16637000"], ["84079.71000000", "0.00000000"], ["84079.99000000", "0.00000000"], ["84080.00000000", "0.02260000"], ["84080.10000000", "0.00000000"], ["84080.12000000", "0.03391000"], ["84080.92000000", "0.00000000"], ["84081.04000000", "0.04400000"], ["84081.10000000", "0.00000000"], ["84081.93000000", "0.04800000"], ["84082.70000000", "0.00000000"], ["84083.24000000", "0.00000000"], ["84083.26000000", "0.00000000"], ["84083.30000000", "1.78310000"], ["84083.86000000", "0.00118000"], ["84084.35000000", "0.32749000"], ["84085.99000000", "0.71126000"], ["84086.08000000", "0.11600000"], ["84086.14000000", "0.08000000"], ["84086.65000000", "0.00013000"], ["84086.71000000", "0.64663000"], ["84086.72000000", "0.00000000"], ["84086.77000000", "0.02378000"], ["84086.94000000", "0.00000000"], ["84086.97000000", "0.05943000"], ["84087.28000000", "0.00000000"], ["84087.47000000", "0.00000000"], ["84087.50000000", "0.00000000"], ["84087.83000000", "0.00000000"], ["84087.93000000", "0.00000000"], ["84088.40000000", "0.00400000"], ["84088.63000000", "0.20147000"], ["84088.73000000", "0.00057000"], ["84088.83000000", "0.00000000"], ["84090.25000000", "1.37246000"], ["84090.38000000", "0.00058000"], ["84090.66000000", "0.44396000"], ["84091.71000000", "0.00000000"], ["84091.98000000", "0.00000000"], ["84092.00000000", "0.02260000"], ["84092.02000000", "0.00000000"], ["84092.03000000", "0.00000000"], ["84092.29000000", "0.00000000"], ["84092.64000000", "0.05943000"], ["84093.08000000", "0.00000000"], ["84093.46000000", "0.00000000"], ["84093.49000000", "0.00000000"], ["84094.09000000", "1.00000000"], ["84094.21000000", "0.89155000"], ["84094.77000000", "0.52049000"], ["84094.78000000", "0.00000000"], ["84094.91000000", "0.00000000"], ["84095.16000000", "0.00000000"], ["84095.37000000", "0.00000000"], ["84097.53000000", "0.00000000"], ["84098.00000000", "0.00000000"], ["84100.44000000", "0.00000000"], ["84100.70000000", "0.00000000"], ["84101.30000000", "0.01409000"], ["84101.85000000", "0.00000000"], ["84102.36000000", "0.31044000"], ["84102.37000000", "0.30746000"], ["84103.34000000", "0.00000000"], ["84103.53000000", "0.72679000"], ["84103.93000000", "0.00151000"], ["84103.94000000", "0.00100000"], ["84107.61000000", "0.00000000"], ["84107.62000000", "0.11581000"], ["84108.87000000", "0.05155000"], ["84109.02000000", "0.00000000"], ["84111.94000000", "0.59499000"], ["84113.39000000", "0.00000000"], ["84113.95000000", "0.05881000"], ["84114.38000000", "0.00000000"], ["84115.32000000", "0.00000000"], ["84116.16000000", "0.35850000"], ["84116.17000000", "0.00000000"], ["84117.31000000", "0.00000000"], ["84117.58000000", "0.00000000"], ["84118.45000000", "0.00000000"], ["84118.46000000", "0.00000000"], ["84118.74000000", "0.02867000"], ["84120.92000000", "0.00000000"], ["84123.89000000", "0.00000000"], ["84129.82000000", "0.06123000"], ["84129.99000000", "0.03971000"], ["84130.46000000", "0.05297000"], ["84131.92000000", "0.00000000"], ["84132.45000000", "0.00000000"], ["84135.23000000", "0.04997000"], ["84141.32000000", "0.64742000"], ["84141.37000000", "1.02685000"], ["84142.43000000", "0.00000000"], ["84143.26000000", "0.00602000"], ["84143.93000000", "0.00894000"], ["84144.16000000", "0.00000000"], ["84144.54000000", "0.00297000"], ["84146.75000000", "0.00000000"], ["84147.75000000", "0.00000000"], ["84147.91000000", "0.00000000"], ["84149.06000000", "0.03236000"], ["84149.99000000", "0.27919000"], ["84151.22000000", "0.00000000"], ["84151.65000000", "0.00143000"], ["84151.99000000", "0.04297000"], ["84153.62000000", "0.07052000"], ["84155.99000000", "0.04297000"], ["84156.70000000", "0.01666000"], ["84158.49000000", "0.10319000"], ["84158.82000000", "0.00151000"], ["84159.99000000", "0.00297000"], ["84164.71000000", "0.12900000"], ["84164.76000000", "0.02380000"], ["84164.90000000", "0.00664000"], ["84166.72000000", "0.00000000"], ["84167.74000000", "0.00000000"], ["84168.14000000", "0.09624000"], ["84169.20000000", "0.00000000"], ["84169.34000000", "0.00664000"], ["84176.44000000", "0.00000000"], ["84182.48000000", "0.00000000"], ["84182.60000000", "0.00000000"], ["84183.34000000", "0.00000000"], ["84187.20000000", "0.00000000"], ["84192.94000000", "0.00000000"], ["84193.27000000", "0.00000000"], ["84196.99000000", "0.18319000"], ["84197.59000000", "0.00100000"], ["84197.94000000", "0.05297000"], ["84198.28000000", "0.00664000"], ["84201.98000000", "0.00887000"], ["84202.39000000", "0.05297000"], ["84206.85000000", "0.00000000"], ["84210.85000000", "0.00000000"], ["84212.46000000", "0.14497000"], ["84219.84000000", "0.01744000"], ["84222.13000000", "0.00000000"], ["84223.49000000", "0.00000000"], ["84224.04000000", "0.00000000"], ["84224.09000000", "0.00000000"], ["84224.20000000", "0.00000000"], ["84224.75000000", "0.00000000"], ["84224.80000000", "0.00000000"], ["84225.10000000", "0.05497000"], ["84228.62000000", "0.00119000"], ["84231.52000000", "0.00000000"], ["84234.85000000", "0.00000000"], ["84236.03000000", "0.00000000"], ["84236.40000000", "0.00000000"], ["84244.92000000", "0.01006000"], ["84250.51000000", "0.01000000"], ["84250.61000000", "0.00000000"], ["84251.11000000", "0.00000000"], ["84251.21000000", "0.00000000"], ["84252.65000000", "0.00918000"], ["84254.32000000", "0.00000000"], ["84254.55000000", "0.00000000"], ["84258.46000000", "0.99082000"], ["84259.47000000", "0.00000000"], ["84261.98000000", "0.00000000"], ["84262.95000000", "0.00000000"], ["84264.47000000", "0.00000000"], ["84285.62000000", "0.00000000"], ["84319.59000000", "0.00000000"], ["84346.55000000", "0.00000000"], ["84346.64000000", "0.20151000"], ["84348.22000000", "0.00000000"], ["84355.04000000", "0.13132000"], ["84355.35000000", "0.00000000"], ["85337.62000000", "0.00000000"], ["150001.00000000", "0.00032000"]], "record_time": 1742584911.12742, "EXCHANGE": "BINANCE"}
{"e": "depthUpdate", "E": 1742584912014, "s": "BTCUSDT", "U": 64637902021, "u": 64637902515, "b": [["84075.47000000", "3.16347000"], ["84075.46000000", "0.00047000"], ["84075.25000000", "0.00021000"], ["84075.24000000", "0.13960000"], ["84074.66000000", "0.00007000"], ["84074.62000000", "0.00007000"], ["84074.61000000", "0.00007000"], ["84074.49000000", "0.00007000"], ["84074.48000000", "0.00000000"], ["84073.93000000", "0.00000000"], ["84073.88000000", "0.00000000"], ["84073.81000000", "0.00000000"], ["84073.80000000", "0.01196000"], ["84073.72000000", "0.00037000"], ["84073.71000000", "0.00006000"], ["84073.67000000", "0.00000000"], ["84073.31000000", "0.00016000"], ["84073.30000000", "0.00000000"], ["84073.28000000", "0.00000000"], ["84073.27000000", "0.00000000"], ["84073.21000000", "0.00000000"], ["84073.20000000", "0.00000000"], ["84072.70000000", "0.00000000"], ["84072.62000000", "0.00000000"], ["84072.28000000", "0.00000000"], ["84072.16000000", "0.00000000"], ["84072.15000000", "0.03396000"], ["84071.90000000", "0.00000000"], ["84071.85000000", "0.00000000"], ["84071.84000000", "0.02546000"], ["84071.30000000", "0.00500000"], ["84071.25000000", "0.00000000"], ["84071.13000000", "0.00118000"], ["84070.81000000", "0.00014000"], ["84070.80000000", "0.14620000"], ["84070.02000000", "0.15674000"], ["84070.00000000", "0.02260000"], ["84067.07000000", "0.15606000"], ["84067.06000000", "0.45000000"], ["84066.91000000", "0.00000000"], ["84066.54000000", "0.00000000"], ["84064.02000000", "0.05353000"], ["84063.27000000", "0.16280000"], ["84063.22000000", "0.26287000"], ["84062.60000000", "0.00000000"], ["84062.50000000", "0.00000000"], ["84061.88000000", "0.00000000"], ["84061.74000000", "0.00000000"], ["84061.57000000", "0.00000000"], ["84061.14000000", "0.00000000"], ["84056.79000000", "0.68040000"], ["84056.78000000", "0.00000000"], ["84056.77000000", "0.71126000"], ["84056.76000000", "0.00000000"], ["84056.17000000", "0.01189000"], ["84056.00000000", "0.00010000"], ["84055.86000000", "0.85698000"], ["84053.71000000", "0.59496000"], ["84053.00000000", "0.05898000"], ["84051.87000000", "0.00000000"], ["84051.73000000", "0.85702000"], ["84050.56000000", "0.00000000"], ["84046.61000000", "0.00000000"], ["84044.16000000", "2.06591000"], ["84042.05000000", "0.00000000"], ["84041.59000000", "0.11453000"], ["84041.50000000", "0.00000000"], ["84039.20000000", "0.00000000"], ["84038.50000000", "0.00000000"], ["84035.44000000", "0.00000000"], ["84034.14000000", "0.00000000"], ["84033.27000000", "0.00000000"], ["84031.08000000", "0.04228000"], ["84027.26000000", "0.00000000"], ["84020.26000000", "0.00000000"], ["84016.58000000", "0.00000000"], ["84006.58000000", "0.10000000"], ["83979.63000000", "0.00000000"], ["83963.15000000", "0.48908000"], ["83956.19000000", "0.00000000"], ["83949.60000000", "0.00006000"], ["83932.80000000", "0.05955000"], ["83914.57000000", "0.01862000"], ["83900.13000000", "0.00400000"], ["83872.67000000", "0.00000000"], ["83861.69000000", "0.00000000"], ["83854.14000000", "0.00000000"], ["83849.02000000", "0.00000000"], ["83839.03000000", "0.00000000"], ["82814.33000000", "0.00000000"], ["75667.00000000", "0.00152000"], ["67260.38000000", "0.00058000"], ["33000.00000000", "2.93827000"]], "a": [["84075.48000000", "4.34049000"], ["84075.49000000", "0.00046000"], ["84076.00000000", "0.02280000"], ["84076.11000000", "0.23004000"], ["84076.13000000", "0.00000000"], ["84076.15000000", "0.00014000"], ["84076.16000000", "0.45194000"], ["84076.46000000", "0.00000000"], ["84076.47000000", "0.18843000"], ["84076.63000000", "0.04000000"], ["84077.15000000", "0.00000000"], ["84077.30000000", "0.00000000"], ["84077.90000000", "0.00006000"], ["84078.00000000", "0.02260000"], ["84078.13000000", "0.37748000"], ["84078.14000000", "0.00000000"], ["84078.40000000", "0.00000000"], ["84078.46000000", "0.00000000"], ["84078.47000000", "0.00000000"], ["84078.73000000", "0.00000000"], ["84078.78000000", "0.02000000"], ["84078.93000000", "0.00118000"], ["84079.24000000", "0.00000000"], ["84080.06000000", "0.00000000"], ["84080.12000000", "0.00000000"], ["84080.37000000", "0.78534000"], ["84080.38000000", "0.04000000"], ["84080.53000000", "0.00118000"], ["84080.68000000", "0.08000000"], ["84082.11000000", "0.16344000"], ["84082.20000000", "0.01189000"], ["84082.63000000", "0.35662000"], ["84083.19000000", "0.00000000"], ["84083.68000000", "0.14637000"], ["84085.11000000", "0.00000000"], ["84085.99000000", "0.00000000"], ["84086.01000000", "0.56687000"], ["84086.35000000", "0.03315000"], ["84087.31000000", "0.01189000"], ["84088.11000000", "0.16637000"], ["84088.40000000", "0.00000000"], ["84088.63000000", "0.00000000"], ["84088.73000000", "0.00000000"], ["84090.38000000", "0.00000000"], ["84090.40000000", "0.00000000"], ["84090.66000000", "0.63906000"], ["84090.73000000", "0.59437000"], ["84090.88000000", "0.47549000"], ["84091.51000000", "0.01900000"], ["84094.09000000", "0.00000000"], ["84095.49000000", "0.00000000"], ["84096.90000000", "0.00000000"], ["84097.30000000", "0.00000000"], ["84097.35000000", "1.00000000"], ["84097.82000000", "0.08090000"], ["84098.19000000", "0.00000000"], ["84098.89000000", "0.00000000"], ["84098.97000000", "0.00000000"], ["84099.19000000", "0.00000000"], ["84099.41000000", "0.00000000"], ["84100.50000000", "0.00000000"], ["84102.82000000", "0.85650000"], ["84103.37000000", "0.00000000"], ["84103.83000000", "0.00000000"], ["84105.17000000", "0.00000000"], ["84106.97000000", "0.00000000"], ["84107.36000000", "0.00000000"], ["84107.46000000", "0.85645000"], ["84107.62000000", "0.00000000"], ["84107.87000000", "1.36735000"], ["84107.90000000", "0.01121000"], ["84107.99000000", "0.00000000"], ["84108.87000000", "0.90799000"], ["84111.94000000", "0.00000000"], ["84112.31000000", "0.35662000"], ["84113.17000000", "0.12450000"], ["84113.95000000", "0.00000000"], ["84114.00000000", "0.01179000"], ["84114.02000000", "0.85639000"], ["84115.14000000", "0.00000000"], ["84115.16000000", "0.00000000"], ["84115.66000000", "0.00000000"], ["84115.67000000", "0.59496000"], ["84117.32000000", "0.01082000"], ["84118.24000000", "0.77033000"], ["84119.49000000", "0.00000000"], ["84119.93000000", "0.00000000"], ["84120.49000000", "0.00000000"], ["84123.31000000", "0.00000000"], ["84125.62000000", "0.00504000"], ["84126.75000000", "0.01010000"], ["84128.00000000", "0.59437000"], ["84128.15000000", "0.47549000"], ["84134.05000000", "0.05600000"], ["84135.52000000", "0.00000000"], ["84138.34000000", "0.01707000"], ["84143.06000000", "0.01010000"], ["84145.16000000", "0.00000000"], ["84150.28000000", "0.01355000"], ["84153.00000000", "0.00019000"], ["84165.42000000", "0.00000000"], ["84165.81000000", "0.00000000"], ["84172.18000000", "0.00746000"], ["84180.95000000", "0.00000000"], ["84191.23000000", "0.00000000"], ["84194.04000000", "0.00746000"], ["84199.39000000", "0.00000000"], ["84215.11000000", "0.01098000"], ["84219.89000000", "0.00000000"], ["84220.25000000", "0.00000000"], ["84228.62000000", "0.00135000"], ["84236.63000000", "0.00000000"], ["84242.25000000", "0.00000000"], ["84247.70000000", "0.00119000"], ["84247.71000000", "0.00560000"], ["84255.81000000", "0.00000000"], ["84270.37000000", "0.00000000"], ["84278.54000000", "0.00000000"], ["85327.80000000", "0.00000000"], ["85336.62000000", "0.00100000"], ["85349.10000000", "0.11734000"], ["150001.00000000", "0.00036000"]], "record_time": 1742584912.126825, "EXCHANGE": "BINANCE"}
{"e": "depthUpdate", "E": 1742584913014, "s": "BTCUSDT", "U": 64637902516, "u": 64637902639, "b": [["84075.47000000", "3.58619000"], ["84055.43000000", "0.05795000"], ["84053.00000000", "0.00000000"], ["84050.66000000", "0.27007000"], ["84050.40000000", "0.91494000"], ["84042.84000000", "0.00000000"], ["84034.44000000", "0.30223000"], ["84026.25000000", "0.00000000"], ["83984.06000000", "1.13167000"], ["83983.92000000", "0.00000000"], ["83914.58000000", "0.00835000"], ["83914.57000000", "0.00000000"], ["83913.05000000", "0.00000000"], ["83905.45000000", "0.00400000"], ["83900.13000000", "0.00000000"], ["83721.21000000", "0.00522000"], ["83161.69000000", "0.06004000"], ["82814.33000000", "0.00100000"], ["80697.27000000", "0.03566000"], ["75667.00000000", "0.00152000"], ["67260.38000000", "0.00058000"], ["33000.00000000", "2.93827000"], ["21030.20000000", "0.00071000"]], "a": [["84075.48000000", "4.33952000"], ["84082.20000000", "0.00492000"], ["84084.10000000", "0.00500000"], ["84090.25000000", "0.00000000"], ["84090.55000000", "0.59437000"], ["84090.66000000", "1.17118000"], ["84090.73000000", "0.00000000"], ["84091.54000000", "0.84220000"], ["84094.21000000", "0.89155000"], ["84094.57000000", "0.01284000"], ["84094.77000000", "0.50765000"], ["84095.98000000", "1.00000000"], ["84096.00000000", "0.02260000"], ["84097.35000000", "0.00000000"], ["84098.19000000", "0.00000000"], ["84099.92000000", "1.36197000"], ["84104.61000000", "0.00798000"], ["84106.07000000", "0.00000000"], ["84106.29000000", "0.00000000"], ["84109.18000000", "0.01363000"], ["84109.80000000", "0.01113000"], ["84113.99000000", "0.01059000"], ["84115.51000000", "0.00000000"], ["84116.86000000", "0.19853000"], ["84124.50000000", "0.63876000"], ["84128.00000000", "0.00000000"], ["84128.15000000", "0.47549000"], ["84128.39000000", "0.59437000"], ["84129.90000000", "0.01758000"], ["84132.39000000", "0.00903000"], ["84161.38000000", "0.17899000"], ["84164.43000000", "0.02386000"], ["84164.76000000", "0.00000000"], ["84173.69000000", "0.00000000"], ["84175.48000000", "0.02380000"], ["84184.12000000", "0.01883000"], ["84189.10000000", "0.01569000"], ["84195.39000000", "0.00000000"], ["84201.40000000", "0.05497000"], ["84210.91000000", "0.01113000"], ["84225.10000000", "0.00000000"], ["84230.96000000", "0.01041000"], ["84237.97000000", "0.00000000"], ["84243.60000000", "0.01883000"], ["84247.70000000", "0.00000000"], ["84260.68000000", "0.00119000"], ["84278.54000000", "0.01862000"], ["85336.62000000", "0.00000000"], ["85349.10000000", "0.00000000"]], "record_time": 1742584913.127236, "EXCHANGE": "BINANCE"}
{"e": "depthUpdate", "E": 1742584914014, "s": "BTCUSDT", "U": 64637902640, "u": 64637902835, "b": [["84075.47000000", "3.13916000"], ["84071.30000000", "0.00500000"], ["84065.18000000", "0.00000000"], ["84064.97000000", "0.00095000"], ["84059.17000000", "0.00000000"], ["84053.76000000", "0.00760000"], ["84050.57000000", "0.00000000"], ["84046.75000000", "1.34119000"], ["84032.56000000", "0.00000000"], ["84024.86000000", "0.00000000"], ["84011.21000000", "0.05000000"], ["84011.01000000", "0.00000000"], ["83982.40000000", "0.63100000"], ["83972.70000000", "0.02287000"], ["83967.49000000", "0.00000000"], ["83920.27000000", "0.00000000"], ["83913.13000000", "0.00400000"], ["83911.09000000", "0.00000000"], ["83905.45000000", "0.00000000"], ["82814.33000000", "0.00000000"], ["75667.00000000", "0.00152000"], ["67260.38000000", "0.00058000"], ["42000.00000000", "6.84810000"], ["33000.00000000", "2.93827000"], ["30267.17000000", "0.00600000"], ["21030.20000000", "0.00000000"]], "a": [["84075.48000000", "4.24858000"], ["84076.11000000", "0.06994000"], ["84076.15000000", "0.00000000"], ["84076.16000000", "0.00187000"], ["84076.46000000", "0.00014000"], ["84076.63000000", "0.04007000"], ["84076.88000000", "0.00000000"], ["84077.05000000", "0.00000000"], ["84077.20000000", "0.00000000"], ["84077.28000000", "0.00000000"], ["84077.50000000", "0.00000000"], ["84077.90000000", "0.00000000"], ["84078.12000000", "0.00014000"], ["84078.13000000", "0.35974000"], ["84078.78000000", "0.00000000"], ["84079.41000000", "0.78534000"], ["84080.37000000", "0.00000000"], ["84080.38000000", "0.00000000"], ["84081.38000000", "0.06000000"], ["84082.20000000", "0.00205000"], ["84082.28000000", "0.00000000"], ["84082.63000000", "0.00000000"], ["84086.35000000", "0.00000000"], ["84086.38000000", "0.00000000"], ["84086.71000000", "0.28353000"], ["84087.94000000", "0.00000000"], ["84089.14000000", "0.01189000"], ["84090.15000000", "0.16000000"], ["84093.95000000", "1.34835000"], ["84094.67000000", "1.00000000"], ["84095.98000000", "0.00000000"], ["84096.12000000", "0.00000000"], ["84097.30000000", "0.00000000"], ["84097.41000000", "0.00000000"], ["84098.69000000", "0.00000000"], ["84107.97000000", "0.04400000"], ["84112.13000000", "0.35662000"], ["84112.31000000", "0.00000000"], ["84113.58000000", "0.00000000"], ["84128.39000000", "0.00000000"], ["84129.60000000", "0.00693000"], ["84149.97000000", "0.00000000"], ["84150.23000000", "0.00663000"], ["84154.85000000", "0.00000000"], ["84181.88000000", "0.00000000"], ["84191.67000000", "0.02300000"], ["84194.36000000", "0.00000000"], ["84209.22000000", "0.01471000"], ["84216.02000000", "0.00000000"], ["84218.72000000", "0.00750000"], ["84223.35000000", "0.00703000"], ["84243.57000000", "0.01226000"], ["84260.68000000", "0.00000000"], ["85336.61000000", "0.00119000"], ["85336.62000000", "0.00100000"], ["85349.10000000", "0.11734000"]], "record_time": 1742584914.126736, "EXCHANGE": "BINANCE"}
{"e": "depthUpdate", "E": 1742584915014, "s": "BTCUSDT", "U": 64637902836, "u": 64637902995, "b": [["84075.47000000", "3.13916000"], ["84075.46000000", "0.00034000"], ["84075.45000000", "0.00020000"], ["84075.24000000", "0.13960000"], ["84074.61000000", "0.00007000"], ["84074.49000000", "0.00000000"], ["84073.80000000", "0.01196000"], ["84070.80000000", "0.14620000"], ["84067.06000000", "0.45000000"], ["84056.77000000", "0.00000000"], ["84055.87000000", "0.71126000"], ["84032.56000000", "0.00000000"], ["84026.81000000", "0.04000000"], ["84021.05000000", "0.00530000"], ["84011.21000000", "0.00000000"], ["84010.91000000", "0.00000000"], ["83972.70000000", "0.00000000"], ["83967.70000000", "0.02287000"], ["83913.13000000", "0.00000000"], ["83907.04000000", "0.00400000"], ["83234.71000000", "0.00000000"], ["82814.33000000", "0.00100000"], ["80697.27000000", "0.00000000"], ["80680.44000000", "0.00000000"], ["75667.00000000", "0.00152000"], ["67260.38000000", "0.00058000"], ["60000.00000000", "73.01913000"], ["42000.00000000", "6.84710000"], ["33000.00000000", "2.93827000"], ["30267.17000000", "0.00620000"], ["20002.00000000", "0.00000000"], ["20001.00000000", "0.02099000"]], "a": [["84075.48000000", "4.72294000"], ["84075.49000000", "0.00033000"], ["84079.32000000", "0.78534000"], ["84079.41000000", "0.00000000"], ["84081.24000000", "0.00000000"], ["84082.20000000", "0.01189000"], ["84083.44000000", "0.02326000"], ["84084.10000000", "0.00500000"], ["84086.38000000", "0.03352000"], ["84086.77000000", "0.00000000"], ["84086.78000000", "0.02378000"], ["84093.95000000", "2.34835000"], ["84094.22000000", "0.00000000"], ["84094.67000000", "0.00000000"], ["84094.77000000", "0.50765000"], ["84095.61000000", "0.00000000"], ["84096.06000000", "0.00000000"], ["84102.70000000", "0.00610000"], ["84106.07000000", "0.05000000"], ["84107.98000000", "0.00000000"], ["84122.49000000", "0.02551000"], ["84124.50000000", "0.41227000"], ["84128.15000000", "0.00000000"], ["84144.55000000", "0.00000000"], ["84148.87000000", "0.00000000"], ["84155.93000000", "0.01831000"], ["84157.34000000", "0.00000000"], ["84160.00000000", "0.04708000"], ["84167.69000000", "1.19224000"], ["84172.28000000", "0.01308000"], ["84175.33000000", "0.01882000"], ["84176.51000000", "0.05497000"], ["84178.55000000", "0.05497000"], ["84180.77000000", "0.05497000"], ["84182.49000000", "0.00000000"], ["84185.75000000", "0.05497000"], ["84189.74000000", "0.05497000"], ["84191.67000000", "0.00013000"], ["84192.66000000", "0.05497000"], ["84193.97000000", "0.05497000"], ["84194.37000000", "0.02287000"], ["84196.30000000", "0.05497000"], ["84200.74000000", "0.05497000"], ["84211.39000000", "0.05297000"], ["84216.09000000", "0.00000000"], ["84216.30000000", "0.05297000"], ["84217.38000000", "0.00000000"], ["84217.53000000", "0.00000000"], ["84217.67000000", "0.00000000"], ["84220.28000000", "0.00000000"], ["84220.39000000", "0.04997000"], ["84222.22000000", "0.00007000"], ["84223.93000000", "0.00000000"], ["84224.11000000", "0.00000000"], ["84225.35000000", "0.00000000"], ["84232.77000000", "0.00000000"], ["84238.14000000", "0.00000000"], ["84260.68000000", "0.00119000"], ["85336.61000000", "0.00000000"], ["85336.62000000", "0.00000000"]], "record_time": 1742584915.127371, "EXCHANGE": "BINANCE"}
{"e": "depthUpdate", "E": 1742584916014, "s": "BTCUSDT", "U": 64637902996, "u": 64637904041, "b": [["84075.47000000", "5.88038000"], ["84075.46000000", "0.00047000"], ["84075.45000000", "0.00007000"], ["84075.27000000", "0.00208000"], ["84075.26000000", "0.00021000"], ["84075.25000000", "0.26012000"], ["84075.24000000", "0.13960000"], ["84074.66000000", "0.09012000"], ["84074.62000000", "0.00000000"], ["84074.61000000", "0.00000000"], ["84074.44000000", "0.05366000"], ["84074.24000000", "0.16006000"], ["84074.03000000", "0.00000000"], ["84074.00000000", "0.02266000"], ["84073.80000000", "0.01189000"], ["84073.58000000", "0.00000000"], ["84073.37000000", "0.02378000"], ["84073.04000000", "0.00504000"], ["84073.03000000", "0.00000000"], ["84072.67000000", "0.00000000"], ["84072.38000000", "0.04182000"], ["84072.19000000", "0.00594000"], ["84072.15000000", "0.03383000"], ["84071.84000000", "0.02539000"], ["84071.30000000", "0.00000000"], ["84071.20000000", "0.00000000"], ["84070.81000000", "0.00000000"], ["84070.71000000", "0.11894000"], ["84070.12000000", "0.11893000"], ["84070.11000000", "0.04000000"], ["84070.02000000", "0.00000000"], ["84068.77000000", "0.38319000"], ["84068.76000000", "0.00000000"], ["84068.33000000", "0.05900000"], ["84067.96000000", "0.08992000"], ["84067.44000000", "0.17841000"], ["84067.39000000", "0.00000000"], ["84067.20000000", "0.00006000"], ["84067.07000000", "0.00000000"], ["84066.46000000", "0.02378000"], ["84065.32000000", "0.59488000"], ["84064.97000000", "0.00000000"], ["84064.75000000", "0.00594000"], ["84064.74000000", "0.00000000"], ["84064.57000000", "0.69791000"], ["84064.56000000", "0.85689000"], ["84064.02000000", "0.00000000"], ["84063.57000000", "0.01189000"], ["84063.22000000", "0.00000000"], ["84063.21000000", "0.00000000"], ["84062.00000000", "0.71126000"], ["84061.99000000", "0.08354000"], ["84061.98000000", "0.00000000"], ["84061.32000000", "0.00000000"], ["84061.01000000", "0.00000000"], ["84060.90000000", "0.44391000"], ["84060.76000000", "0.00594000"], ["84060.50000000", "0.85693000"], ["84059.29000000", "0.35662000"], ["84059.14000000", "0.47549000"], ["84058.67000000", "0.00000000"], ["84058.65000000", "0.11886000"], ["84057.58000000", "0.00000000"], ["84057.21000000", "0.05943000"], ["84056.79000000", "0.94239000"], ["84056.75000000", "0.00000000"], ["84056.50000000", "0.01000000"], ["84055.43000000", "0.00000000"], ["84055.31000000", "0.89155000"], ["84054.10000000", "0.17841000"], ["84053.71000000", "0.00000000"], ["84052.34000000", "0.00000000"], ["84051.61000000", "0.11509000"], ["84051.44000000", "0.08992000"], ["84051.11000000", "0.00000000"], ["84050.66000000", "0.00000000"], ["84048.53000000", "0.05000000"], ["84048.02000000", "0.00000000"], ["84047.78000000", "0.00000000"], ["84047.74000000", "0.00000000"], ["84046.75000000", "0.00000000"], ["84046.46000000", "0.02817000"], ["84046.24000000", "0.00000000"], ["84046.08000000", "0.04228000"], ["84045.76000000", "0.05947000"], ["84044.16000000", "1.44584000"], ["84043.68000000", "0.00000000"], ["84043.62000000", "0.00000000"], ["84041.59000000", "0.00000000"], ["84037.94000000", "0.00000000"], ["84037.03000000", "0.20995000"], ["84036.50000000", "0.04628000"], ["84035.99000000", "0.03202000"], ["84034.03000000", "0.00000000"], ["84032.83000000", "0.00000000"], ["84031.08000000", "0.00000000"], ["84029.01000000", "0.05796000"], ["84028.63000000", "0.00000000"], ["84027.40000000", "0.00000000"], ["84022.33000000", "0.00000000"], ["84022.31000000", "0.47549000"], ["84020.83000000", "0.00000000"], ["84016.80000000", "0.03575000"], ["84016.54000000", "0.09641000"], ["84016.14000000", "0.00820000"], ["84010.91000000", "0.00000000"], ["84010.69000000", "0.00000000"], ["84008.99000000", "0.00061000"], ["84008.76000000", "0.00000000"], ["84005.78000000", "0.04000000"], ["84004.64000000", "0.00000000"], ["84002.06000000", "0.00358000"], ["84001.35000000", "0.00000000"], ["83999.99000000", "0.00000000"], ["83992.74000000", "1.02867000"], ["83988.94000000", "0.01196000"], ["83984.06000000", "0.82304000"], ["83984.05000000", "0.00000000"], ["83982.40000000", "0.00000000"], ["83978.44000000", "0.00000000"], ["83972.28000000", "0.00000000"], ["83964.60000000", "0.00000000"], ["83961.34000000", "0.00083000"], ["83951.87000000", "0.00400000"], ["83946.24000000", "0.00000000"], ["83941.95000000", "0.18321000"], ["83940.12000000", "0.00008000"], ["83930.75000000", "0.00000000"], ["83907.04000000", "0.00000000"], ["83888.92000000", "0.00000000"], ["83883.54000000", "0.00069000"], ["83873.52000000", "0.00000000"], ["83837.38000000", "0.00000000"], ["83161.69000000", "0.00000000"], ["82814.33000000", "0.00000000"], ["75667.00000000", "0.00152000"], ["67260.38000000", "0.00058000"], ["60000.00000000", "73.01903000"], ["33000.00000000", "2.93827000"], ["30267.17000000", "0.00660000"], ["21030.20000000", "0.00071000"]], "a": [["84075.48000000", "0.05901000"], ["84075.49000000", "0.00054000"], ["84075.60000000", "0.00007000"], ["84075.87000000", "0.00208000"], ["84075.99000000", "0.00007000"], ["84076.00000000", "0.00007000"], ["84076.05000000", "0.00007000"], ["84076.10000000", "0.00000000"], ["84076.11000000", "0.00000000"], ["84076.16000000", "0.00000000"], ["84076.33000000", "0.00007000"], ["84076.46000000", "0.00000000"], ["84076.47000000", "0.00000000"], ["84076.56000000", "0.00000000"], ["84076.60000000", "0.00000000"], ["84076.61000000", "0.00000000"], ["84076.62000000", "0.00000000"], ["84076.63000000", "0.00000000"], ["84076.69000000", "0.00000000"], ["84076.80000000", "0.00000000"], ["84076.86000000", "0.00000000"], ["84077.18000000", "0.00000000"], ["84077.29000000", "0.00000000"], ["84077.33000000", "0.00024000"], ["84077.34000000", "0.00000000"], ["84077.59000000", "0.00000000"], ["84077.76000000", "0.00000000"], ["84077.99000000", "0.00000000"], ["84078.00000000", "0.00000000"], ["84078.02000000", "0.00000000"], ["84078.12000000", "0.00000000"], ["84078.13000000", "0.00000000"], ["84078.93000000", "0.00118000"], ["84079.10000000", "0.00021000"], ["84079.11000000", "0.02241000"], ["84079.32000000", "0.00000000"], ["84079.36000000", "0.00000000"], ["84079.37000000", "0.00000000"], ["84079.45000000", "0.00000000"], ["84079.68000000", "0.00000000"], ["84079.75000000", "0.00000000"], ["84079.80000000", "0.00000000"], ["84079.91000000", "0.00000000"], ["84079.92000000", "0.00000000"], ["84079.93000000", "0.00000000"], ["84080.00000000", "0.00000000"], ["84080.53000000", "0.00000000"], ["84080.66000000", "0.00000000"], ["84080.67000000", "0.00000000"], ["84080.68000000", "0.00118000"], ["84080.89000000", "0.00000000"], ["84081.04000000", "0.00000000"], ["84081.19000000", "0.00022000"], ["84081.20000000", "0.06183000"], ["84081.38000000", "0.00000000"], ["84081.66000000", "0.00000000"], ["84081.87000000", "0.00009000"], ["84081.88000000", "0.02227000"], ["84081.89000000", "0.00000000"], ["84081.91000000", "0.00008000"], ["84081.93000000", "0.00000000"], ["84081.96000000", "0.00014000"], ["84081.97000000", "0.27754000"], ["84082.00000000", "0.00000000"], ["84082.10000000", "0.00000000"], ["84082.11000000", "0.00000000"], ["84082.20000000", "0.00000000"], ["84082.23000000", "0.13689000"], ["84082.28000000", "0.00000000"], ["84082.72000000", "0.00000000"], ["84083.20000000", "0.00500000"], ["84083.26000000", "0.00000000"], ["84083.27000000", "0.16690000"], ["84083.30000000", "0.00000000"], ["84083.43000000", "0.00000000"], ["84083.44000000", "0.00000000"], ["84083.60000000", "0.00000000"], ["84083.68000000", "0.00000000"], ["84083.85000000", "0.00000000"], ["84083.89000000", "0.00000000"], ["84084.00000000", "0.02260000"], ["84084.40000000", "0.00000000"], ["84084.41000000", "0.00000000"], ["84084.90000000", "0.00000000"], ["84085.07000000", "0.00000000"], ["84085.81000000", "0.00000000"], ["84086.00000000", "0.02260000"], ["84086.01000000", "0.01086000"], ["84086.03000000", "0.00000000"], ["84086.08000000", "0.00000000"], ["84086.14000000", "0.00000000"], ["84086.15000000", "0.00000000"], ["84086.36000000", "0.00000000"], ["84086.38000000", "0.00000000"], ["84086.62000000", "0.00095000"], ["84086.71000000", "0.44391000"], ["84086.78000000", "0.00000000"], ["84086.83000000", "0.00000000"], ["84086.97000000", "0.00000000"], ["84087.06000000", "0.01713000"], ["84087.12000000", "0.00000000"], ["84087.31000000", "0.00000000"], ["84087.54000000", "0.00000000"], ["84087.62000000", "0.10602000"], ["84087.69000000", "0.00000000"], ["84087.77000000", "0.00000000"], ["84087.98000000", "0.00000000"], ["84088.08000000", "0.00000000"], ["84088.11000000", "0.00000000"], ["84088.13000000", "0.00000000"], ["84088.21000000", "0.00000000"], ["84088.40000000", "0.01500000"], ["84088.57000000", "0.01500000"], ["84088.58000000", "0.00000000"], ["84088.68000000", "0.00000000"], ["84089.07000000", "0.00000000"], ["84089.14000000", "0.00000000"], ["84089.25000000", "0.00000000"], ["84089.58000000", "0.00000000"], ["84089.63000000", "0.00000000"], ["84089.64000000", "0.78525000"], ["84089.68000000", "0.00000000"], ["84089.71000000", "0.04400000"], ["84090.05000000", "0.00000000"], ["84090.15000000", "0.00000000"], ["84090.53000000", "0.04400000"], ["84090.54000000", "0.84521000"], ["84090.66000000", "0.00000000"], ["84091.37000000", "0.06400000"], ["84091.41000000", "0.06813000"], ["84091.44000000", "0.04800000"], ["84091.49000000", "0.00091000"], ["84091.54000000", "0.00000000"], ["84091.66000000", "0.01949000"], ["84091.78000000", "0.00000000"], ["84092.18000000", "0.14000000"], ["84092.25000000", "0.14637000"], ["84092.33000000", "0.00000000"], ["84092.64000000", "0.00000000"], ["84092.84000000", "0.00000000"], ["84092.98000000", "0.00922000"], ["84093.95000000", "0.00000000"], ["84094.51000000", "0.35662000"], ["84094.64000000", "0.04000000"], ["84094.71000000", "0.01189000"], ["84094.75000000", "0.05600000"], ["84094.77000000", "1.46760000"], ["84095.02000000", "0.00000000"], ["84095.25000000", "0.00000000"], ["84095.57000000", "0.05600000"], ["84095.61000000", "0.06000000"], ["84095.64000000", "0.08000000"], ["84095.73000000", "0.00091000"], ["84096.27000000", "0.89155000"], ["84096.70000000", "0.00000000"], ["84096.87000000", "0.15168000"], ["84096.91000000", "0.00000000"], ["84097.82000000", "0.00000000"], ["84097.93000000", "1.33392000"], ["84098.14000000", "0.89155000"], ["84098.75000000", "0.16000000"], ["84099.25000000", "0.00000000"], ["84099.72000000", "0.00931000"], ["84100.70000000", "0.17829000"], ["84101.64000000", "0.89155000"], ["84102.36000000", "0.00237000"], ["84102.70000000", "0.00000000"], ["84102.82000000", "0.00000000"], ["84103.53000000", "0.67675000"], ["84103.65000000", "0.01189000"], ["84104.66000000", "0.00000000"], ["84105.02000000", "0.30683000"], ["84106.07000000", "0.00000000"], ["84107.15000000", "0.00000000"], ["84107.22000000", "0.00000000"], ["84107.46000000", "0.00000000"], ["84108.87000000", "0.05155000"], ["84109.71000000", "0.00000000"], ["84110.02000000", "0.00000000"], ["84110.37000000", "0.02814000"], ["84110.75000000", "0.04400000"], ["84111.46000000", "0.00090000"], ["84112.02000000", "0.00000000"], ["84113.04000000", "0.00000000"], ["84113.17000000", "0.00000000"], ["84114.02000000", "0.88226000"], ["84115.67000000", "0.00000000"], ["84116.16000000", "0.64325000"], ["84116.18000000", "0.00000000"], ["84116.87000000", "0.00000000"], ["84117.20000000", "0.00000000"], ["84117.58000000", "0.00000000"], ["84117.92000000", "0.35670000"], ["84118.24000000", "0.71126000"], ["84118.57000000", "0.85634000"], ["84118.70000000", "0.00000000"], ["84119.56000000", "0.00000000"], ["84119.58000000", "0.00000000"], ["84121.11000000", "0.11404000"], ["84122.16000000", "0.00000000"], ["84123.51000000", "0.00000000"], ["84123.69000000", "0.00000000"], ["84124.08000000", "0.00000000"], ["84126.70000000", "0.00000000"], ["84127.15000000", "0.59487000"], ["84129.99000000", "0.00000000"], ["84131.24000000", "0.59437000"], ["84132.86000000", "0.47549000"], ["84132.91000000", "0.01196000"], ["84133.27000000", "0.01919000"], ["84136.34000000", "0.04371000"], ["84140.32000000", "0.05912000"], ["84141.32000000", "0.38480000"], ["84141.37000000", "0.00000000"], ["84149.07000000", "1.02675000"], ["84151.99000000", "0.00000000"], ["84153.24000000", "0.00000000"], ["84154.05000000", "0.06400000"], ["84155.08000000", "0.00000000"], ["84155.77000000", "0.00627000"], ["84155.99000000", "0.00000000"], ["84158.49000000", "0.11050000"], ["84159.31000000", "0.00825000"], ["84160.14000000", "0.00000000"], ["84162.93000000", "0.00000000"], ["84164.71000000", "0.00000000"], ["84167.14000000", "0.00000000"], ["84167.69000000", "0.00000000"], ["84169.04000000", "0.00000000"], ["84169.50000000", "0.00000000"], ["84172.06000000", "0.00000000"], ["84172.14000000", "0.00000000"], ["84172.25000000", "0.00000000"], ["84173.81000000", "0.00000000"], ["84174.66000000", "0.00000000"], ["84174.85000000", "0.00000000"], ["84175.48000000", "0.00000000"], ["84175.99000000", "0.00000000"], ["84176.40000000", "0.00417000"], ["84179.43000000", "0.00059000"], ["84180.34000000", "0.00000000"], ["84186.04000000", "0.00000000"], ["84188.48000000", "0.12900000"], ["84189.84000000", "0.00429000"], ["84198.41000000", "0.02380000"], ["84198.68000000", "0.00000000"], ["84202.42000000", "0.01029000"], ["84204.96000000", "0.01781000"], ["84213.63000000", "0.01700000"], ["84213.89000000", "0.01919000"], ["84215.70000000", "0.00000000"], ["84216.35000000", "0.00000000"], ["84220.65000000", "0.00000000"], ["84227.07000000", "0.02403000"], ["84227.08000000", "0.04298000"], ["84228.61000000", "0.00000000"], ["84228.62000000", "0.00000000"], ["84233.71000000", "0.04298000"], ["84238.43000000", "0.00000000"], ["84245.16000000", "0.00118000"], ["84245.17000000", "0.00016000"], ["84245.23000000", "0.00000000"], ["84246.67000000", "0.00000000"], ["84250.51000000", "0.00000000"], ["84252.14000000", "0.00000000"], ["84255.32000000", "0.01000000"], ["84258.46000000", "0.00000000"], ["84278.54000000", "0.00000000"], ["84365.96000000", "0.00000000"], ["84400.37000000", "0.00000000"], ["84458.42000000", "0.00000000"], ["84475.37000000", "0.08591000"], ["85299.80000000", "0.00000000"], ["85336.62000000", "0.00100000"], ["85350.99000000", "0.10006000"], ["85391.70000000", "0.00007000"], ["85413.00000000", "0.05900000"]], "record_time": 1742584916.127443, "EXCHANGE": "BINANCE"}
{"e": "depthUpdate", "E": 1742584917014, "s": "BTCUSDT", "U": 64637904042, "u": 64637904553, "b": [["84075.47000000", "5.85737000"], ["84075.24000000", "0.13960000"], ["84074.66000000", "0.00007000"], ["84074.24000000", "0.16013000"], ["84074.00000000", "0.02266000"], ["84073.51000000", "0.00000000"], ["84073.37000000", "0.02384000"], ["84072.60000000", "0.00000000"], ["84072.28000000", "0.00118000"], ["84071.30000000", "0.00500000"], ["84071.13000000", "0.00000000"], ["84068.77000000", "0.94146000"], ["84068.61000000", "0.89155000"], ["84068.35000000", "0.89155000"], ["84067.44000000", "0.05947000"], ["84065.32000000", "0.00000000"], ["84064.57000000", "0.53363000"], ["84062.50000000", "0.00000000"], ["84062.01000000", "0.00000000"], ["84060.90000000", "1.35645000"], ["84059.30000000", "0.59489000"], ["84058.68000000", "1.00000000"], ["84058.23000000", "1.32768000"], ["84057.11000000", "0.00000000"], ["84056.70000000", "0.01000000"], ["84056.50000000", "0.00000000"], ["84048.53000000", "0.00000000"], ["84048.35000000", "0.00000000"], ["84046.08000000", "0.00000000"], ["84044.71000000", "0.00000000"], ["84044.16000000", "0.91091000"], ["84040.44000000", "0.00000000"], ["84040.18000000", "0.00000000"], ["84036.14000000", "0.04228000"], ["84011.01000000", "0.05000000"], ["83993.00000000", "1.07501000"], ["83961.35000000", "0.00083000"], ["83961.34000000", "0.00000000"], ["83914.90000000", "0.00835000"], ["83914.58000000", "0.00000000"], ["83885.95000000", "0.00069000"], ["83883.54000000", "0.00000000"], ["82814.33000000", "0.00100000"], ["80714.10000000", "0.00000000"], ["75667.00000000", "0.00152000"], ["67260.38000000", "0.00058000"], ["33000.00000000", "2.93827000"], ["30267.17000000", "0.00700000"], ["21030.20000000", "0.00071000"]], "a": [["84075.48000000", "0.09133000"], ["84075.49000000", "0.00054000"], ["84077.34000000", "0.00024000"], ["84077.35000000", "0.17219000"], ["84078.05000000", "0.00000000"], ["84078.06000000", "0.00000000"], ["84078.40000000", "0.00400000"], ["84078.90000000", "0.00000000"], ["84078.91000000", "0.00000000"], ["84079.10000000", "0.00008000"], ["84079.11000000", "0.02241000"], ["84079.99000000", "0.00000000"], ["84080.00000000", "0.00000000"], ["84080.02000000", "0.00000000"], ["84080.03000000", "0.00000000"], ["84080.39000000", "0.00014000"], ["84080.40000000", "0.12423000"], ["84080.41000000", "0.31981000"], ["84080.47000000", "0.00010000"], ["84080.61000000", "0.00000000"], ["84080.66000000", "0.00000000"], ["84080.93000000", "0.00000000"], ["84081.02000000", "0.00000000"], ["84081.03000000", "0.00000000"], ["84081.04000000", "0.00000000"], ["84081.19000000", "0.00000000"], ["84081.20000000", "0.06170000"], ["84081.60000000", "0.00008000"], ["84081.65000000", "0.00000000"], ["84081.87000000", "0.00000000"], ["84081.88000000", "0.02220000"], ["84081.91000000", "0.00000000"], ["84081.96000000", "0.00000000"], ["84081.97000000", "0.00000000"], ["84082.23000000", "0.00000000"], ["84082.37000000", "0.00000000"], ["84082.79000000", "0.00000000"], ["84082.80000000", "0.00000000"], ["84083.20000000", "0.00000000"], ["84083.26000000", "0.00000000"], ["84083.27000000", "0.16690000"], ["84083.87000000", "0.00000000"], ["84084.10000000", "0.00000000"], ["84087.62000000", "0.89129000"], ["84087.87000000", "0.00704000"], ["84088.08000000", "0.00649000"], ["84088.20000000", "0.00000000"], ["84088.40000000", "0.01900000"], ["84089.63000000", "0.08354000"], ["84089.64000000", "0.00000000"], ["84091.02000000", "0.15019000"], ["84092.56000000", "0.03360000"], ["84093.23000000", "0.00000000"], ["84094.20000000", "0.71126000"], ["84094.74000000", "0.00000000"], ["84094.77000000", "0.39953000"], ["84096.27000000", "0.00000000"], ["84097.10000000", "0.00905000"], ["84097.38000000", "0.01535000"], ["84097.93000000", "0.00000000"], ["84098.14000000", "0.00000000"], ["84100.39000000", "0.55444000"], ["84101.64000000", "0.00000000"], ["84104.03000000", "1.34268000"], ["84104.98000000", "0.01603000"], ["84108.59000000", "0.00500000"], ["84109.81000000", "0.91588000"], ["84110.17000000", "0.00000000"], ["84111.63000000", "1.68905000"], ["84112.20000000", "0.89155000"], ["84114.08000000", "0.89155000"], ["84114.34000000", "0.89155000"], ["84119.58000000", "0.00000000"], ["84121.27000000", "0.00905000"], ["84123.60000000", "0.85629000"], ["84124.27000000", "0.00000000"], ["84125.00000000", "0.01384000"], ["84127.07000000", "0.00000000"], ["84127.17000000", "0.00000000"], ["84134.10000000", "0.00943000"], ["84134.37000000", "0.00000000"], ["84151.99000000", "0.02656000"], ["84155.34000000", "0.00902000"], ["84159.75000000", "0.00699000"], ["84161.49000000", "0.00699000"], ["84168.50000000", "0.01420000"], ["84179.48000000", "0.00000000"], ["84180.49000000", "0.00768000"], ["84190.89000000", "0.00000000"], ["84222.27000000", "0.00765000"], ["84228.32000000", "0.00000000"], ["84230.43000000", "0.02085000"], ["84240.75000000", "0.00000000"], ["84245.26000000", "0.00000000"], ["84255.32000000", "0.00000000"], ["84257.42000000", "0.00000000"], ["84258.43000000", "0.01000000"], ["84262.52000000", "1.00328000"], ["84263.29000000", "0.00000000"], ["84368.36000000", "0.00000000"], ["85336.62000000", "0.00000000"], ["85413.00000000", "0.00036000"]], "record_time": 1742584917.127313, "EXCHANGE": "BINANCE"}
{"e": "depthUpdate", "E": 1742584918014, "s": "BTCUSDT", "U": 64637904554, "u": 64637904917, "b": [["84075.47000000", "5.26254000"], ["84072.70000000", "0.00000000"], ["84071.40000000", "0.00006000"], ["84071.30000000", "0.00500000"], ["84062.60000000", "0.00000000"], ["84059.30000000", "0.00000000"], ["84056.18000000", "0.59491000"], ["84051.61000000", "0.00000000"], ["84047.34000000", "0.11664000"], ["84046.61000000", "0.71353000"], ["84038.56000000", "0.00000000"], ["84036.50000000", "0.00000000"], ["84027.02000000", "0.04628000"], ["84022.39000000", "0.77053000"], ["84022.38000000", "0.59437000"], ["84021.30000000", "0.00000000"], ["83990.70000000", "0.63100000"], ["83951.87000000", "0.00000000"], ["83951.54000000", "0.01862000"], ["83949.60000000", "0.05954000"], ["83945.70000000", "0.12000000"], ["83944.86000000", "0.00400000"], ["83932.80000000", "0.00006000"], ["82814.33000000", "0.00000000"], ["75667.00000000", "0.00152000"], ["67260.38000000", "0.00058000"], ["33000.00000000", "2.93887000"], ["30267.17000000", "0.00740000"]], "a": [["84075.48000000", "0.04237000"], ["84075.49000000", "0.00054000"], ["84077.34000000", "0.00000000"], ["84077.35000000", "0.00000000"], ["84078.02000000", "0.00000000"], ["84078.39000000", "0.00000000"], ["84078.40000000", "0.00000000"], ["84078.61000000", "0.00014000"], ["84078.62000000", "0.14410000"], ["84079.10000000", "0.00009000"], ["84079.11000000", "0.02241000"], ["84079.43000000", "0.00024000"], ["84079.44000000", "0.12543000"], ["84079.45000000", "0.33141000"], ["84079.79000000", "0.00000000"], ["84080.39000000", "0.00000000"], ["84080.40000000", "0.00000000"], ["84080.41000000", "0.00000000"], ["84080.64000000", "0.00000000"], ["84080.68000000", "0.00000000"], ["84081.20000000", "0.06170000"], ["84081.22000000", "0.00000000"], ["84085.93000000", "0.00756000"], ["84088.08000000", "0.00000000"], ["84088.40000000", "0.01500000"], ["84090.40000000", "0.00000000"], ["84093.20000000", "0.00451000"], ["84095.21000000", "0.01595000"], ["84100.50000000", "0.00000000"], ["84103.35000000", "1.22898000"], ["84105.68000000", "0.01862000"], ["84108.57000000", "0.00000000"], ["84108.59000000", "0.00500000"], ["84108.60000000", "0.00000000"], ["84108.62000000", "0.03569000"], ["84109.61000000", "0.01891000"], ["84116.66000000", "0.11974000"], ["84117.88000000", "0.05000000"], ["84121.11000000", "0.00000000"], ["84138.79000000", "0.00451000"], ["84146.22000000", "0.10180000"], ["84162.11000000", "0.00000000"], ["84170.71000000", "0.00000000"], ["84174.09000000", "0.00000000"], ["84183.99000000", "0.01069000"], ["84186.06000000", "0.00000000"], ["84207.77000000", "0.00000000"], ["84211.46000000", "0.00000000"], ["84225.33000000", "0.00000000"], ["84226.43000000", "0.00407000"], ["84240.24000000", "0.01518000"], ["84240.39000000", "0.00944000"], ["84251.94000000", "0.00809000"], ["84262.52000000", "0.00495000"], ["84368.36000000", "0.99631000"], ["85336.62000000", "0.00100000"], ["87000.22000000", "0.02626000"]], "record_time": 1742584918.127008, "EXCHANGE": "BINANCE"}
{"e": "depthUpdate", "E": 1742584919014, "s": "BTCUSDT", "U": 64637904918, "u": 64637905668, "b": [["84078.95000000", "7.96734000"], ["84078.94000000", "0.00046000"], ["84078.01000000", "0.00021000"], ["84078.00000000", "0.02308000"], ["84077.29000000", "0.00021000"], ["84077.28000000", "0.01203000"], ["84076.33000000", "0.00007000"], ["84076.32000000", "0.00000000"], ["84076.05000000", "0.00007000"], ["84076.04000000", "0.00000000"], ["84076.03000000", "0.00000000"], ["84076.01000000", "0.00014000"], ["84076.00000000", "0.02273000"], ["84075.99000000", "0.00000000"], ["84075.98000000", "0.00000000"], ["84075.96000000", "0.00018000"], ["84075.86000000", "0.00000000"], ["84075.76000000", "0.00118000"], ["84075.59000000", "0.00000000"], ["84075.52000000", "0.00014000"], ["84075.51000000", "0.83826000"], ["84075.50000000", "0.00000000"], ["84075.49000000", "0.00006000"], ["84075.48000000", "0.90006000"], ["84075.47000000", "0.05863000"], ["84075.46000000", "0.00000000"], ["84075.45000000", "0.00000000"], ["84075.35000000", "0.02545000"], ["84075.27000000", "0.00201000"], ["84075.26000000", "0.00000000"], ["84075.25000000", "0.00000000"], ["84075.24000000", "0.13940000"], ["84074.66000000", "0.00000000"], ["84074.44000000", "0.05353000"], ["84074.24000000", "0.16000000"], ["84074.00000000", "0.02260000"], ["84073.72000000", "0.00000000"], ["84073.37000000", "0.02378000"], ["84073.31000000", "0.00000000"], ["84073.04000000", "0.00000000"], ["84073.02000000", "0.00000000"], ["84072.97000000", "0.00000000"], ["84071.85000000", "0.13552000"], ["84071.84000000", "0.00000000"], ["84071.28000000", "0.00000000"], ["84068.77000000", "0.76267000"], ["84068.75000000", "0.00000000"], ["84067.43000000", "0.11894000"], ["84066.35000000", "0.01189000"], ["84064.57000000", "0.87599000"], ["84063.86000000", "0.00000000"], ["84063.58000000", "0.00000000"], ["84060.90000000", "0.88287000"], ["84060.28000000", "0.00000000"], ["84059.28000000", "0.00759000"], ["84058.23000000", "0.00000000"], ["84057.21000000", "0.00000000"], ["84056.80000000", "0.59489000"], ["84056.78000000", "0.00000000"], ["84056.70000000", "0.00000000"], ["84056.18000000", "0.00000000"], ["84053.76000000", "0.00000000"], ["84052.34000000", "0.05943000"], ["84051.50000000", "0.00000000"], ["84042.26000000", "0.05000000"], ["84037.99000000", "0.00146000"], ["84034.44000000", "0.30077000"], ["84027.89000000", "0.00000000"], ["84024.18000000", "0.00264000"], ["84021.31000000", "0.00000000"], ["83990.70000000", "0.00000000"], ["83975.69000000", "0.00000000"], ["83973.79000000", "0.00400000"], ["83973.72000000", "0.01861000"], ["83971.73000000", "0.00000000"], ["83967.59000000", "0.00000000"], ["83963.15000000", "0.00000000"], ["83951.54000000", "0.00000000"], ["83944.86000000", "0.00000000"], ["83941.18000000", "0.00322000"], ["83936.46000000", "0.00000000"], ["83922.16000000", "0.01000000"], ["83851.55000000", "0.00000000"], ["83850.47000000", "0.20115000"], ["83849.04000000", "0.00000000"], ["83844.24000000", "0.00000000"], ["83843.16000000", "0.80000000"], ["83842.07000000", "0.20115000"], ["83835.84000000", "0.00000000"], ["83833.67000000", "0.01132000"], ["82814.33000000", "0.00100000"], ["80697.27000000", "0.03566000"], ["75671.00000000", "0.00000000"], ["75667.00000000", "0.00152000"], ["67263.16000000", "0.00058000"], ["67260.38000000", "0.00000000"], ["33000.00000000", "2.93827000"], ["30267.17000000", "0.00800000"], ["21030.20000000", "0.00000000"]], "a": [["84075.48000000", "0.00000000"], ["84075.49000000", "0.00000000"], ["84075.60000000", "0.00000000"], ["84075.87000000", "0.00000000"], ["84075.99000000", "0.00000000"], ["84076.00000000", "0.00000000"], ["84076.04000000", "0.00000000"], ["84076.05000000", "0.00000000"], ["84076.33000000", "0.00000000"], ["84077.33000000", "0.00000000"], ["84078.61000000", "0.00000000"], ["84078.62000000", "0.00000000"], ["84078.93000000", "0.00000000"], ["84078.95000000", "0.00000000"], ["84078.96000000", "1.13779000"], ["84078.97000000", "0.00060000"], ["84079.09000000", "0.00021000"], ["84079.10000000", "0.32659000"], ["84079.11000000", "0.00007000"], ["84079.22000000", "0.00000000"], ["84079.43000000", "0.00000000"], ["84079.44000000", "0.00000000"], ["84079.45000000", "0.00000000"], ["84079.87000000", "0.00000000"], ["84080.22000000", "0.00121000"], ["84080.23000000", "0.15672000"], ["84080.24000000", "0.00000000"], ["84080.47000000", "0.00017000"], ["84080.55000000", "0.00007000"], ["84080.58000000", "0.00000000"], ["84080.59000000", "0.34699000"], ["84080.74000000", "0.00000000"], ["84081.19000000", "0.00000000"], ["84081.20000000", "0.06183000"], ["84081.50000000", "0.00000000"], ["84081.51000000", "0.00000000"], ["84081.88000000", "0.02226000"], ["84082.41000000", "0.00000000"], ["84082.56000000", "0.02234000"], ["84082.70000000", "0.00118000"], ["84083.08000000", "0.00007000"], ["84083.26000000", "0.00000000"], ["84083.27000000", "0.16696000"], ["84083.49000000", "0.13536000"], ["84083.71000000", "0.00000000"], ["84083.86000000", "0.00000000"], ["84084.00000000", "0.02260000"], ["84084.10000000", "0.00500000"], ["84085.87000000", "0.00118000"], ["84085.93000000", "0.00000000"], ["84086.21000000", "0.00760000"], ["84086.40000000", "0.00000000"], ["84091.56000000", "0.01189000"], ["84093.97000000", "0.00000000"], ["84094.20000000", "0.71126000"], ["84095.45000000", "0.02392000"], ["84095.73000000", "0.00000000"], ["84100.70000000", "0.05943000"], ["84101.96000000", "0.00506000"], ["84103.53000000", "0.55730000"], ["84103.93000000", "0.00000000"], ["84104.03000000", "0.00000000"], ["84104.18000000", "0.05956000"], ["84106.16000000", "0.05943000"], ["84107.82000000", "0.00151000"], ["84108.59000000", "0.00000000"], ["84108.62000000", "0.00000000"], ["84110.04000000", "0.00540000"], ["84111.46000000", "0.00000000"], ["84112.24000000", "0.02017000"], ["84114.16000000", "0.00000000"], ["84117.92000000", "0.36546000"], ["84118.13000000", "0.01676000"], ["84127.98000000", "0.06000000"], ["84129.82000000", "0.11877000"], ["84136.24000000", "0.00000000"], ["84139.45000000", "0.01157000"], ["84139.86000000", "0.00000000"], ["84153.83000000", "0.00000000"], ["84157.96000000", "0.00000000"], ["84158.82000000", "0.00000000"], ["84159.99000000", "0.00000000"], ["84162.08000000", "0.00151000"], ["84163.58000000", "0.00296000"], ["84168.71000000", "0.00000000"], ["84173.08000000", "0.00000000"], ["84182.64000000", "0.00000000"], ["84182.86000000", "0.02380000"], ["84188.67000000", "0.04757000"], ["84194.15000000", "0.00844000"], ["84198.41000000", "0.00000000"], ["84198.84000000", "0.00000000"], ["84200.84000000", "0.02650000"], ["84204.04000000", "0.01382000"], ["84204.16000000", "0.00000000"], ["84222.18000000", "0.02516000"], ["84223.83000000", "0.00000000"], ["84227.80000000", "0.00315000"], ["84228.00000000", "0.00235000"], ["84230.28000000", "0.01307000"], ["84234.77000000", "0.00612000"], ["84244.70000000", "0.00000000"], ["84244.71000000", "0.00495000"], ["84256.92000000", "0.01000000"], ["84258.43000000", "0.00000000"], ["84260.68000000", "0.00000000"], ["84261.03000000", "0.99700000"], ["84264.17000000", "0.00118000"], ["84278.41000000", "0.00000000"], ["84368.36000000", "0.00000000"], ["85336.62000000", "0.00000000"], ["85391.70000000", "0.05871000"]], "record_time": 1742584919.127011, "EXCHANGE": "BINANCE"}
{"e": "depthUpdate", "E": 1742584920014, "s": "BTCUSDT", "U": 64637905669, "u": 64637907185, "b": [["84081.18000000", "7.45474000"], ["84081.17000000", "0.00034000"], ["84080.56000000", "0.00007000"], ["84080.46000000", "0.00007000"], ["84080.27000000", "0.00007000"], ["84080.21000000", "0.00007000"], ["84080.01000000", "0.00021000"], ["84080.00000000", "0.02280000"], ["84079.79000000", "0.00000000"], ["84079.70000000", "0.00000000"], ["84079.67000000", "0.00000000"], ["84079.52000000", "0.00014000"], ["84079.51000000", "0.01196000"], ["84079.50000000", "0.00014000"], ["84079.49000000", "0.01007000"], ["84079.41000000", "0.00014000"], ["84079.40000000", "1.40340000"], ["84079.39000000", "0.00030000"], ["84079.38000000", "0.60901000"], ["84079.37000000", "0.00013000"], ["84079.36000000", "0.00000000"], ["84079.21000000", "0.00000000"], ["84079.20000000", "0.00000000"], ["84079.19000000", "0.00201000"], ["84079.11000000", "0.00000000"], ["84079.10000000", "0.00000000"], ["84079.09000000", "0.36967000"], ["84079.08000000", "0.00000000"], ["84079.07000000", "0.00000000"], ["84079.06000000", "0.00000000"], ["84078.97000000", "0.00000000"], ["84078.96000000", "0.00000000"], ["84078.95000000", "0.14132000"], ["84078.94000000", "0.00000000"], ["84078.89000000", "0.00000000"], ["84078.01000000", "0.00000000"], ["84078.00000000", "0.02260000"], ["84077.78000000", "0.00118000"], ["84077.58000000", "0.02539000"], ["84077.29000000", "0.00000000"], ["84077.28000000", "0.00000000"], ["84076.34000000", "0.00000000"], ["84076.33000000", "0.00000000"], ["84076.05000000", "0.00000000"], ["84076.01000000", "0.00000000"], ["84076.00000000", "0.02260000"], ["84075.96000000", "0.00000000"], ["84075.54000000", "0.13728000"], ["84075.53000000", "0.00000000"], ["84075.52000000", "0.25332000"], ["84075.51000000", "0.08992000"], ["84075.49000000", "0.00000000"], ["84075.48000000", "0.45000000"], ["84075.47000000", "0.05639000"], ["84075.35000000", "0.00000000"], ["84075.27000000", "0.00000000"], ["84075.24000000", "0.00000000"], ["84074.44000000", "0.05366000"], ["84071.85000000", "0.09110000"], ["84071.30000000", "0.00000000"], ["84070.80000000", "0.00013000"], ["84070.54000000", "0.00300000"], ["84069.08000000", "0.00000000"], ["84068.58000000", "0.01189000"], ["84068.33000000", "0.00000000"], ["84068.29000000", "0.85685000"], ["84066.35000000", "0.00000000"], ["84066.13000000", "0.05805000"], ["84062.13000000", "0.00000000"], ["84061.74000000", "0.59437000"], ["84061.45000000", "0.00757000"], ["84059.28000000", "0.00000000"], ["84058.70000000", "1.38582000"], ["84057.21000000", "0.05943000"], ["84053.24000000", "0.00000000"], ["84052.34000000", "0.00000000"], ["84051.73000000", "0.00000000"], ["84044.95000000", "0.00000000"], ["84042.26000000", "0.00000000"], ["84040.53000000", "0.00000000"], ["84023.89000000", "0.00000000"], ["84023.88000000", "0.00000000"], ["84022.38000000", "0.00000000"], ["84014.08000000", "0.00061000"], ["84008.99000000", "0.00000000"], ["83997.62000000", "0.00000000"], ["83987.09000000", "0.00400000"], ["83979.99000000", "0.00000000"], ["83975.49000000", "0.61231000"], ["83973.79000000", "0.00000000"], ["83973.72000000", "0.00000000"], ["83960.86000000", "0.00000000"], ["83960.80000000", "0.00000000"], ["83955.44000000", "0.00000000"], ["83925.67000000", "0.00000000"], ["83917.83000000", "0.00835000"], ["83914.90000000", "0.00000000"], ["83867.30000000", "0.00000000"], ["83852.70000000", "0.19136000"], ["83850.47000000", "0.00000000"], ["83844.30000000", "2.95579000"], ["83842.07000000", "0.00000000"], ["83835.90000000", "0.02112000"], ["83833.67000000", "0.00000000"], ["83815.09000000", "0.00000000"], ["82814.33000000", "0.00000000"], ["80697.27000000", "0.00000000"], ["75673.00000000", "0.02708000"], ["75671.00000000", "0.00020000"], ["75670.00000000", "0.00208000"], ["75667.00000000", "0.00132000"], ["67264.95000000", "0.00058000"], ["67263.16000000", "0.00000000"], ["50001.00000000", "1.81927000"], ["33000.00000000", "2.93827000"], ["21030.20000000", "0.00071000"], ["20002.00000000", "0.00000000"], ["20001.00000000", "0.02099000"]], "a": [["84078.96000000", "0.00000000"], ["84078.97000000", "0.00000000"], ["84079.08000000", "0.00000000"], ["84079.09000000", "0.00000000"], ["84079.10000000", "0.00000000"], ["84079.11000000", "0.00000000"], ["84079.37000000", "0.00000000"], ["84079.38000000", "0.00000000"], ["84079.39000000", "0.00000000"], ["84079.40000000", "0.00000000"], ["84079.50000000", "0.00000000"], ["84079.68000000", "0.00000000"], ["84079.71000000", "0.00000000"], ["84079.80000000", "0.00000000"], ["84080.22000000", "0.00000000"], ["84080.23000000", "0.00000000"], ["84080.28000000", "0.00000000"], ["84080.47000000", "0.00000000"], ["84080.55000000", "0.00000000"], ["84080.59000000", "0.00000000"], ["84081.17000000", "0.00000000"], ["84081.18000000", "0.00000000"], ["84081.19000000", "1.56752000"], ["84081.20000000", "0.00046000"], ["84081.40000000", "0.00007000"], ["84081.60000000", "0.00015000"], ["84081.87000000", "0.00015000"], ["84081.88000000", "0.00007000"], ["84082.24000000", "0.00014000"], ["84082.55000000", "0.00037000"], ["84082.56000000", "0.00000000"], ["84082.70000000", "0.00000000"], ["84082.85000000", "0.00014000"], ["84082.86000000", "0.33636000"], ["84083.08000000", "0.00000000"], ["84083.19000000", "0.00000000"], ["84083.20000000", "0.00500000"], ["84083.26000000", "0.00010000"], ["84083.27000000", "0.16703000"], ["84083.49000000", "0.00000000"], ["84083.51000000", "0.00000000"], ["84083.52000000", "0.08162000"], ["84084.00000000", "0.02267000"], ["84084.08000000", "0.00000000"], ["84084.09000000", "0.00000000"], ["84084.34000000", "0.00000000"], ["84084.35000000", "0.32749000"], ["84084.79000000", "0.04435000"], ["84085.47000000", "0.00000000"], ["84086.21000000", "0.00000000"], ["84086.71000000", "0.39098000"], ["84087.21000000", "0.00000000"], ["84087.62000000", "0.10602000"], ["84088.21000000", "0.14476000"], ["84088.26000000", "0.00759000"], ["84088.68000000", "0.00118000"], ["84088.90000000", "0.78526000"], ["84091.56000000", "0.00000000"], ["84093.79000000", "0.01202000"], ["84094.20000000", "0.00000000"], ["84094.44000000", "0.01623000"], ["84099.15000000", "0.00000000"], ["84101.96000000", "0.00000000"], ["84102.39000000", "0.00504000"], ["84103.46000000", "1.37455000"], ["84104.18000000", "0.00013000"], ["84105.68000000", "0.00000000"], ["84106.03000000", "0.00000000"], ["84106.41000000", "0.05943000"], ["84107.82000000", "0.00000000"], ["84108.48000000", "0.02073000"], ["84109.53000000", "0.00000000"], ["84109.60000000", "0.00151000"], ["84109.90000000", "0.00000000"], ["84110.12000000", "0.00000000"], ["84110.16000000", "0.00000000"], ["84110.21000000", "0.00000000"], ["84114.89000000", "0.00000000"], ["84115.68000000", "0.01361000"], ["84116.16000000", "0.90271000"], ["84117.88000000", "0.00000000"], ["84119.38000000", "0.00000000"], ["84119.77000000", "0.85633000"], ["84123.60000000", "0.00000000"], ["84124.28000000", "0.00000000"], ["84124.93000000", "0.01179000"], ["84125.45000000", "0.03676000"], ["84128.92000000", "0.00459000"], ["84130.25000000", "0.00000000"], ["84131.96000000", "0.00000000"], ["84132.60000000", "0.00000000"], ["84135.47000000", "0.00000000"], ["84141.10000000", "0.00000000"], ["84143.91000000", "0.00000000"], ["84144.54000000", "0.00000000"], ["84148.29000000", "0.00297000"], ["84151.65000000", "0.00809000"], ["84158.57000000", "0.02355000"], ["84162.23000000", "0.03921000"], ["84165.20000000", "0.00000000"], ["84170.44000000", "0.02073000"], ["84185.88000000", "0.01861000"], ["84186.51000000", "0.00000000"], ["84191.31000000", "0.00000000"], ["84208.50000000", "0.00793000"], ["84217.44000000", "0.00793000"], ["84224.08000000", "0.00000000"], ["84224.88000000", "0.00000000"], ["84228.44000000", "0.00000000"], ["84238.20000000", "0.01362000"], ["84241.27000000", "0.00000000"], ["84250.84000000", "0.01179000"], ["84251.97000000", "0.00993000"], ["84430.08000000", "0.00153000"], ["84439.95000000", "0.00000000"], ["84919.73000000", "0.00000000"], ["85340.15000000", "0.00100000"]], "record_time": 1742584920.149401, "EXCHANGE": "BINANCE"}
{"e": "depthUpdate", "E": 1742584921014, "s": "BTCUSDT", "U": 64637907186, "u": 64637908804, "b": [["84084.33000000", "6.24603000"], ["84084.32000000", "0.00015000"], ["84084.31000000", "0.00000000"], ["84084.09000000", "0.41014000"], ["84084.00000000", "0.02274000"], ["84083.99000000", "2.99500000"], ["84083.98000000", "1.13392000"], ["84083.97000000", "0.00034000"], ["84083.93000000", "0.00007000"], ["84083.92000000", "0.00000000"], ["84083.89000000", "0.00000000"], ["84083.88000000", "0.00000000"], ["84083.80000000", "0.00202000"], ["84083.79000000", "0.00000000"], ["84083.78000000", "0.00000000"], ["84083.63000000", "0.00000000"], ["84083.53000000", "0.00000000"], ["84083.52000000", "0.00000000"], ["84083.51000000", "0.00006000"], ["84083.26000000", "0.00000000"], ["84083.19000000", "0.76726000"], ["84083.09000000", "0.00007000"], ["84082.64000000", "0.00000000"], ["84082.55000000", "0.00000000"], ["84082.54000000", "0.00000000"], ["84082.31000000", "0.01189000"], ["84082.25000000", "0.00007000"], ["84082.18000000", "0.00000000"], ["84082.00000000", "0.02260000"], ["84081.86000000", "0.00000000"], ["84081.76000000", "0.00875000"], ["84081.62000000", "0.00000000"], ["84081.61000000", "0.00000000"], ["84081.60000000", "0.00000000"], ["84081.59000000", "0.00000000"], ["84081.39000000", "0.00000000"], ["84081.30000000", "0.00000000"], ["84081.29000000", "0.00000000"], ["84081.19000000", "0.00018000"], ["84081.18000000", "0.59257000"], ["84081.17000000", "0.00014000"], ["84080.93000000", "0.00118000"], ["84080.56000000", "0.00000000"], ["84080.51000000", "0.04207000"], ["84080.46000000", "0.00000000"], ["84080.27000000", "0.00000000"], ["84080.21000000", "0.00000000"], ["84080.02000000", "0.00000000"], ["84080.01000000", "0.00000000"], ["84080.00000000", "0.02266000"], ["84079.79000000", "0.00000000"], ["84079.78000000", "0.00922000"], ["84079.59000000", "0.02539000"], ["84079.52000000", "0.00000000"], ["84079.51000000", "0.00000000"], ["84079.50000000", "0.00000000"], ["84079.49000000", "0.00000000"], ["84079.43000000", "0.00000000"], ["84079.42000000", "0.00000000"], ["84079.41000000", "0.00000000"], ["84079.40000000", "0.00000000"], ["84079.39000000", "0.00000000"], ["84079.38000000", "0.14000000"], ["84079.37000000", "0.00000000"], ["84079.19000000", "0.00000000"], ["84079.09000000", "0.00000000"], ["84078.95000000", "0.00038000"], ["84078.87000000", "0.00000000"], ["84078.21000000", "0.05353000"], ["84077.78000000", "0.00000000"], ["84077.58000000", "0.00000000"], ["84077.26000000", "0.01189000"], ["84077.00000000", "0.08992000"], ["84075.58000000", "0.24947000"], ["84075.57000000", "0.45000000"], ["84075.52000000", "0.00000000"], ["84075.51000000", "0.00000000"], ["84075.48000000", "0.00000000"], ["84074.80000000", "0.00009000"], ["84074.44000000", "0.00013000"], ["84073.80000000", "0.00000000"], ["84073.70000000", "0.00500000"], ["84073.48000000", "0.00013000"], ["84072.38000000", "0.00000000"], ["84071.85000000", "0.34032000"], ["84071.72000000", "0.85682000"], ["84071.38000000", "0.01189000"], ["84068.77000000", "1.16608000"], ["84068.58000000", "0.00000000"], ["84068.36000000", "0.71126000"], ["84066.96000000", "0.05943000"], ["84066.13000000", "0.00000000"], ["84065.32000000", "0.59486000"], ["84064.51000000", "0.00758000"], ["84063.78000000", "0.05861000"], ["84063.27000000", "0.00000000"], ["84061.45000000", "0.00000000"], ["84060.90000000", "1.24640000"], ["84057.21000000", "0.00000000"], ["84057.11000000", "0.20139000"], ["84056.80000000", "0.00000000"], ["84055.86000000", "0.00000000"], ["84054.01000000", "0.04628000"], ["84053.70000000", "0.00000000"], ["84051.10000000", "0.00000000"], ["84049.79000000", "0.04228000"], ["84046.60000000", "0.00000000"], ["84042.23000000", "0.00000000"], ["84041.52000000", "0.00000000"], ["84036.43000000", "0.00000000"], ["84036.14000000", "0.00000000"], ["84035.83000000", "0.23699000"], ["84029.10000000", "0.00300000"], ["84027.02000000", "0.00000000"], ["84024.18000000", "0.00000000"], ["84024.17000000", "0.25006000"], ["84023.75000000", "0.59437000"], ["84021.07000000", "0.00000000"], ["84021.06000000", "0.00000000"], ["83990.70000000", "0.63097000"], ["83987.35000000", "0.00000000"], ["83987.09000000", "0.00000000"], ["83979.99000000", "0.93250000"], ["83968.54000000", "0.00400000"], ["83962.09000000", "0.00000000"], ["83953.44000000", "0.18321000"], ["83947.39000000", "0.00000000"], ["83941.95000000", "0.00000000"], ["83922.85000000", "0.01000000"], ["83922.16000000", "0.00000000"], ["83868.49000000", "0.01783000"], ["83852.70000000", "0.00000000"], ["83847.11000000", "0.20139000"], ["83844.30000000", "2.75465000"], ["83838.71000000", "0.01084000"], ["83835.90000000", "0.00000000"], ["83736.89000000", "0.00040000"], ["83736.85000000", "0.00000000"], ["83084.16000000", "0.00040000"], ["83084.05000000", "0.00000000"], ["82819.96000000", "0.00100000"], ["80714.10000000", "0.00000000"], ["75675.00000000", "0.00092000"], ["75673.00000000", "0.02708000"], ["75672.00000000", "0.00897000"], ["75671.00000000", "0.00000000"], ["67267.47000000", "0.00058000"], ["67264.95000000", "0.00000000"], ["50001.00000000", "1.81967000"], ["33000.00000000", "2.93827000"], ["30269.23000000", "0.00060000"]], "a": [["84081.19000000", "0.00000000"], ["84081.20000000", "0.00000000"], ["84081.40000000", "0.00000000"], ["84081.60000000", "0.00000000"], ["84081.61000000", "0.00000000"], ["84081.62000000", "0.00000000"], ["84081.63000000", "0.00000000"], ["84081.87000000", "0.00000000"], ["84081.88000000", "0.00000000"], ["84082.24000000", "0.00000000"], ["84082.54000000", "0.00000000"], ["84082.55000000", "0.00000000"], ["84082.58000000", "0.00000000"], ["84082.59000000", "0.00000000"], ["84082.84000000", "0.00000000"], ["84082.85000000", "0.00000000"], ["84082.86000000", "0.00000000"], ["84083.08000000", "0.00000000"], ["84083.20000000", "0.00000000"], ["84083.26000000", "0.00000000"], ["84083.27000000", "0.00000000"], ["84083.52000000", "0.00000000"], ["84083.54000000", "0.00000000"], ["84083.79000000", "0.00000000"], ["84083.93000000", "0.00000000"], ["84083.98000000", "0.00000000"], ["84083.99000000", "0.00000000"], ["84084.00000000", "0.00000000"], ["84084.10000000", "0.00000000"], ["84084.32000000", "0.00000000"], ["84084.33000000", "0.00000000"], ["84084.34000000", "0.00329000"], ["84084.35000000", "0.00007000"], ["84084.41000000", "0.00209000"], ["84084.77000000", "0.00014000"], ["84084.78000000", "0.00000000"], ["84084.79000000", "0.00000000"], ["84085.61000000", "0.00014000"], ["84085.87000000", "0.00000000"], ["84085.99000000", "0.00000000"], ["84086.00000000", "0.00021000"], ["84086.01000000", "0.01100000"], ["84086.46000000", "0.00014000"], ["84086.65000000", "0.00000000"], ["84086.70000000", "0.00014000"], ["84086.71000000", "0.16092000"], ["84086.72000000", "0.00000000"], ["84086.80000000", "0.00006000"], ["84086.94000000", "0.00000000"], ["84087.00000000", "0.00000000"], ["84087.06000000", "0.01713000"], ["84087.62000000", "0.00000000"], ["84088.00000000", "0.02267000"], ["84088.08000000", "0.00118000"], ["84088.20000000", "0.00014000"], ["84088.21000000", "0.14483000"], ["84088.25000000", "0.17899000"], ["84088.26000000", "0.00000000"], ["84088.68000000", "0.00000000"], ["84088.90000000", "0.00000000"], ["84089.12000000", "0.00000000"], ["84089.24000000", "0.07001000"], ["84089.33000000", "0.07282000"], ["84089.52000000", "0.00755000"], ["84090.69000000", "0.00118000"], ["84091.72000000", "0.10602000"], ["84092.25000000", "0.00000000"], ["84092.56000000", "0.00000000"], ["84092.65000000", "0.00000000"], ["84092.98000000", "0.00000000"], ["84093.79000000", "0.00013000"], ["84094.04000000", "0.78521000"], ["84094.17000000", "0.02069000"], ["84094.64000000", "0.00000000"], ["84094.71000000", "0.00000000"], ["84095.45000000", "0.00000000"], ["84095.96000000", "0.00000000"], ["84096.46000000", "0.01189000"], ["84098.57000000", "0.04000000"], ["84098.75000000", "0.00000000"], ["84099.04000000", "0.01189000"], ["84099.38000000", "0.14637000"], ["84099.95000000", "0.16000000"], ["84102.36000000", "0.00000000"], ["84102.37000000", "0.00000000"], ["84102.39000000", "0.00000000"], ["84103.53000000", "0.52148000"], ["84104.19000000", "0.00505000"], ["84104.98000000", "0.00000000"], ["84106.16000000", "0.00000000"], ["84106.26000000", "0.00000000"], ["84106.31000000", "0.00000000"], ["84106.41000000", "0.00000000"], ["84107.23000000", "0.00000000"], ["84107.33000000", "0.29431000"], ["84109.21000000", "0.05943000"], ["84109.60000000", "0.00000000"], ["84109.69000000", "0.00000000"], ["84109.79000000", "0.00000000"], ["84109.81000000", "0.05945000"], ["84109.99000000", "0.00937000"], ["84110.04000000", "0.00000000"], ["84110.86000000", "0.00237000"], ["84110.87000000", "0.30444000"], ["84110.96000000", "0.00000000"], ["84110.97000000", "0.00000000"], ["84110.99000000", "0.00000000"], ["84111.00000000", "0.00000000"], ["84111.01000000", "0.00000000"], ["84111.94000000", "0.00151000"], ["84113.17000000", "0.00000000"], ["84113.39000000", "0.00537000"], ["84113.83000000", "0.00000000"], ["84118.70000000", "0.23676000"], ["84119.05000000", "0.85634000"], ["84119.38000000", "0.05000000"], ["84119.77000000", "0.00000000"], ["84120.51000000", "0.00000000"], ["84122.21000000", "0.01438000"], ["84127.15000000", "0.00000000"], ["84130.45000000", "0.59485000"], ["84132.39000000", "0.00009000"], ["84134.35000000", "0.02095000"], ["84134.77000000", "0.00000000"], ["84139.04000000", "0.00395000"], ["84140.32000000", "0.01941000"], ["84143.93000000", "0.00000000"], ["84147.67000000", "0.00952000"], ["84148.29000000", "0.00000000"], ["84149.06000000", "0.00000000"], ["84149.18000000", "0.00000000"], ["84149.89000000", "0.03971000"], ["84152.08000000", "0.00899000"], ["84152.76000000", "0.00296000"], ["84153.00000000", "0.00000000"], ["84155.51000000", "0.01688000"], ["84158.48000000", "0.00019000"], ["84162.08000000", "0.00000000"], ["84162.23000000", "0.00000000"], ["84163.58000000", "0.00000000"], ["84165.49000000", "0.03151000"], ["84167.74000000", "0.00151000"], ["84168.22000000", "0.00297000"], ["84168.89000000", "0.00929000"], ["84172.82000000", "0.00506000"], ["84179.43000000", "0.00000000"], ["84182.86000000", "0.00000000"], ["84183.72000000", "0.00059000"], ["84185.47000000", "0.01402000"], ["84186.29000000", "0.00000000"], ["84190.13000000", "0.02394000"], ["84193.00000000", "0.02389000"], ["84194.27000000", "0.00021000"], ["84195.20000000", "0.00000000"], ["84196.69000000", "0.01448000"], ["84198.34000000", "0.01040000"], ["84200.64000000", "0.00013000"], ["84203.37000000", "0.02446000"], ["84207.35000000", "0.02394000"], ["84207.84000000", "0.00000000"], ["84217.23000000", "0.04498000"], ["84219.79000000", "0.00000000"], ["84223.74000000", "0.06508000"], ["84234.73000000", "0.00000000"], ["84235.27000000", "0.00006000"], ["84235.97000000", "0.02095000"], ["84236.25000000", "0.00802000"], ["84244.28000000", "0.01424000"], ["84245.94000000", "0.00000000"], ["84256.92000000", "0.01000000"], ["84257.45000000", "0.00778000"], ["84318.59000000", "0.00013000"], ["84321.28000000", "0.00013000"], ["84325.48000000", "0.00013000"], ["85340.15000000", "0.00000000"]], "record_time": 1742584921.127538, "EXCHANGE": "BINANCE"}
{"e": "depthUpdate", "E": 1742584922014, "s": "BTCUSDT", "U": 64637908805, "u": 64637911071, "b": [["84088.23000000", "2.81140000"], ["84088.22000000", "0.00034000"], ["84088.16000000", "0.00021000"], ["84088.15000000", "0.78553000"], ["84088.14000000", "0.45020000"], ["84088.13000000", "0.00007000"], ["84088.05000000", "0.00208000"], ["84088.00000000", "0.02274000"], ["84087.99000000", "0.00000000"], ["84087.98000000", "0.00000000"], ["84087.97000000", "0.00000000"], ["84087.88000000", "1.55701000"], ["84087.87000000", "0.00006000"], ["84087.86000000", "0.00008000"], ["84087.85000000", "0.00013000"], ["84087.31000000", "0.00000000"], ["84087.29000000", "0.00000000"], ["84087.17000000", "0.00000000"], ["84087.16000000", "0.00000000"], ["84087.06000000", "0.00000000"], ["84087.05000000", "0.18472000"], ["84087.04000000", "0.00000000"], ["84086.74000000", "0.00000000"], ["84086.73000000", "0.00000000"], ["84086.72000000", "0.00000000"], ["84086.71000000", "0.00000000"], ["84086.70000000", "0.00000000"], ["84086.69000000", "0.00000000"], ["84086.45000000", "0.00000000"], ["84086.19000000", "0.01189000"], ["84086.12000000", "0.00000000"], ["84086.11000000", "0.00000000"], ["84086.01000000", "0.00000000"], ["84086.00000000", "0.02266000"], ["84085.99000000", "0.00000000"], ["84085.62000000", "0.00000000"], ["84085.60000000", "0.00000000"], ["84085.09000000", "0.04231000"], ["84084.87000000", "0.00042000"], ["84084.83000000", "0.00118000"], ["84084.77000000", "0.00000000"], ["84084.76000000", "0.00000000"], ["84084.75000000", "0.00000000"], ["84084.73000000", "0.08992000"], ["84084.54000000", "0.02539000"], ["84084.45000000", "0.00000000"], ["84084.44000000", "0.00000000"], ["84084.40000000", "0.00000000"], ["84084.35000000", "0.00000000"], ["84084.34000000", "0.00000000"], ["84084.33000000", "0.15060000"], ["84084.32000000", "0.00000000"], ["84084.15000000", "0.00000000"], ["84084.09000000", "0.00000000"], ["84084.01000000", "0.00000000"], ["84084.00000000", "0.02260000"], ["84083.99000000", "0.00000000"], ["84083.98000000", "0.00000000"], ["84083.97000000", "0.00000000"], ["84083.93000000", "0.00000000"], ["84083.80000000", "0.00000000"], ["84083.65000000", "0.00000000"], ["84083.51000000", "0.00000000"], ["84083.45000000", "0.00000000"], ["84083.19000000", "0.76720000"], ["84083.09000000", "0.00000000"], ["84082.61000000", "0.00000000"], ["84082.60000000", "0.00000000"], ["84082.32000000", "0.00000000"], ["84082.31000000", "0.00000000"], ["84082.25000000", "0.00000000"], ["84082.00000000", "0.02260000"], ["84081.42000000", "0.01307000"], ["84081.19000000", "0.00000000"], ["84081.18000000", "0.05613000"], ["84081.17000000", "0.00000000"], ["84080.93000000", "0.00000000"], ["84080.73000000", "0.00000000"], ["84080.52000000", "0.13243000"], ["84080.36000000", "0.13733000"], ["84079.78000000", "0.00000000"], ["84079.59000000", "0.00000000"], ["84079.28000000", "0.00000000"], ["84079.19000000", "0.00118000"], ["84078.95000000", "0.00000000"], ["84078.75000000", "0.00006000"], ["84078.64000000", "0.00300000"], ["84078.39000000", "0.04000000"], ["84078.21000000", "0.00000000"], ["84077.26000000", "0.00000000"], ["84076.73000000", "0.04000000"], ["84076.70000000", "0.04000000"], ["84076.67000000", "0.04000000"], ["84076.26000000", "0.15978000"], ["84075.97000000", "0.04000000"], ["84075.92000000", "0.00013000"], ["84075.76000000", "0.00000000"], ["84075.63000000", "0.01189000"], ["84075.58000000", "0.54108000"], ["84075.54000000", "0.00000000"], ["84075.27000000", "0.85678000"], ["84075.24000000", "0.31651000"], ["84074.18000000", "0.04000000"], ["84073.40000000", "0.00000000"], ["84073.36000000", "0.04000000"], ["84072.47000000", "0.04000000"], ["84072.28000000", "0.00000000"], ["84072.15000000", "0.00000000"], ["84071.82000000", "0.05943000"], ["84071.38000000", "0.00000000"], ["84070.93000000", "0.08000000"], ["84069.93000000", "0.01189000"], ["84069.19000000", "0.00059000"], ["84069.18000000", "0.00000000"], ["84068.67000000", "0.00760000"], ["84067.98000000", "0.00922000"], ["84067.23000000", "0.35662000"], ["84066.96000000", "0.00000000"], ["84066.44000000", "0.00000000"], ["84066.15000000", "0.00000000"], ["84066.10000000", "0.05939000"], ["84065.32000000", "0.00000000"], ["84065.31000000", "0.00000000"], ["84064.51000000", "0.00000000"], ["84064.48000000", "0.00000000"], ["84064.46000000", "0.00000000"], ["84064.40000000", "0.00000000"], ["84063.78000000", "0.00000000"], ["84062.01000000", "0.59485000"], ["84061.96000000", "0.00000000"], ["84061.83000000", "0.00059000"], ["84061.44000000", "0.00000000"], ["84061.35000000", "0.20137000"], ["84061.11000000", "0.00000000"], ["84060.90000000", "0.00000000"], ["84060.58000000", "0.00577000"], ["84060.50000000", "0.00000000"], ["84060.27000000", "0.00000000"], ["84060.20000000", "0.00000000"], ["84059.77000000", "0.00016000"], ["84059.65000000", "0.00000000"], ["84059.29000000", "0.00000000"], ["84058.68000000", "0.00000000"], ["84056.17000000", "0.00000000"], ["84053.25000000", "0.00000000"], ["84051.74000000", "0.11858000"], ["84050.38000000", "0.05949000"], ["84050.24000000", "0.00000000"], ["84049.68000000", "0.00358000"], ["84048.51000000", "0.00000000"], ["84047.34000000", "0.00000000"], ["84046.95000000", "0.60494000"], ["84046.94000000", "0.23696000"], ["84046.61000000", "0.00000000"], ["84045.82000000", "0.00000000"], ["84044.99000000", "0.00146000"], ["84044.93000000", "0.00000000"], ["84041.94000000", "0.00059000"], ["84037.99000000", "0.00000000"], ["84037.40000000", "0.04997000"], ["84036.95000000", "0.05796000"], ["84036.64000000", "0.00000000"], ["84035.83000000", "0.00000000"], ["84034.45000000", "0.00300000"], ["84033.60000000", "0.00006000"], ["84029.10000000", "0.00000000"], ["84029.01000000", "0.00000000"], ["84024.30000000", "0.43864000"], ["84022.39000000", "0.00000000"], ["84022.32000000", "0.59151000"], ["84021.16000000", "0.04000000"], ["84019.39000000", "0.00061000"], ["84019.01000000", "0.04000000"], ["84014.08000000", "0.00000000"], ["84013.30000000", "0.94823000"], ["84012.01000000", "0.00297000"], ["84005.03000000", "0.03183000"], ["84002.06000000", "0.00000000"], ["83999.32000000", "0.00000000"], ["83996.44000000", "0.21512000"], ["83994.26000000", "0.00000000"], ["83990.70000000", "0.00000000"], ["83988.21000000", "0.00000000"], ["83979.99000000", "0.00000000"], ["83973.52000000", "0.00000000"], ["83971.67000000", "0.82359000"], ["83968.54000000", "0.00000000"], ["83965.21000000", "0.00400000"], ["83953.79000000", "0.12000000"], ["83941.51000000", "0.00000000"], ["83939.31000000", "0.00000000"], ["83927.55000000", "0.00000000"], ["83926.75000000", "0.00000000"], ["83926.65000000", "0.01000000"], ["83922.85000000", "0.00000000"], ["83919.20000000", "1.34321000"], ["83890.10000000", "0.00000000"], ["83847.43000000", "0.00000000"], ["83847.42000000", "0.00060000"], ["83847.11000000", "0.00000000"], ["83846.57000000", "0.00000000"], ["83843.23000000", "0.00000000"], ["83842.95000000", "0.01086000"], ["83842.10000000", "0.00000000"], ["83838.71000000", "0.00000000"], ["83832.04000000", "0.00000000"], ["83788.87000000", "0.03705000"], ["83764.50000000", "4.60438000"], ["83740.12000000", "0.00000000"], ["83740.11000000", "0.00060000"], ["83638.40000000", "3.65177000"], ["83547.50000000", "0.00000000"], ["83421.40000000", "0.00000000"], ["82819.96000000", "0.00000000"], ["75678.00000000", "1.94652000"], ["75675.00000000", "0.00042000"], ["75672.00000000", "0.00877000"], ["67270.59000000", "0.00058000"], ["67269.64000000", "0.00000000"], ["67267.47000000", "0.00000000"], ["50001.00000000", "1.82037000"], ["33000.00000000", "2.93827000"], ["30271.76000000", "0.00020000"], ["21030.20000000", "0.00071000"]], "a": [["84084.34000000", "0.00000000"], ["84084.35000000", "0.00000000"], ["84084.41000000", "0.00000000"], ["84084.76000000", "0.00000000"], ["84084.77000000", "0.00000000"], ["84085.61000000", "0.00000000"], ["84086.00000000", "0.00000000"], ["84086.01000000", "0.00000000"], ["84086.02000000", "0.00000000"], ["84086.46000000", "0.00000000"], ["84086.62000000", "0.00000000"], ["84086.70000000", "0.00000000"], ["84086.71000000", "0.00000000"], ["84086.80000000", "0.00000000"], ["84087.05000000", "0.00000000"], ["84087.06000000", "0.00000000"], ["84087.07000000", "0.00000000"], ["84087.30000000", "0.00000000"], ["84087.86000000", "0.00000000"], ["84087.87000000", "0.00000000"], ["84087.88000000", "0.00000000"], ["84087.94000000", "0.00000000"], ["84087.99000000", "0.00000000"], ["84088.00000000", "0.00000000"], ["84088.08000000", "0.00000000"], ["84088.14000000", "0.00000000"], ["84088.15000000", "0.00000000"], ["84088.16000000", "0.00000000"], ["84088.20000000", "0.00000000"], ["84088.21000000", "0.00000000"], ["84088.23000000", "0.00000000"], ["84088.24000000", "0.51342000"], ["84088.25000000", "0.17940000"], ["84088.40000000", "0.00000000"], ["84088.57000000", "0.00000000"], ["84088.66000000", "0.00209000"], ["84088.69000000", "0.04020000"], ["84088.70000000", "0.00013000"], ["84088.71000000", "0.00007000"], ["84088.97000000", "0.00000000"], ["84088.99000000", "0.00007000"], ["84089.12000000", "0.00000000"], ["84089.24000000", "0.00000000"], ["84089.26000000", "0.00314000"], ["84089.33000000", "0.00000000"], ["84089.52000000", "0.00000000"], ["84089.56000000", "0.00000000"], ["84089.63000000", "0.00000000"], ["84089.71000000", "0.00000000"], ["84089.83000000", "0.00007000"], ["84089.99000000", "0.00030000"], ["84090.00000000", "0.02273000"], ["84090.02000000", "0.01513000"], ["84090.10000000", "0.01506000"], ["84090.45000000", "0.02287000"], ["84090.53000000", "0.00014000"], ["84090.54000000", "0.84527000"], ["84090.55000000", "0.59437000"], ["84090.66000000", "0.00000000"], ["84090.69000000", "0.00000000"], ["84090.88000000", "0.00000000"], ["84091.02000000", "0.00000000"], ["84091.30000000", "0.00500000"], ["84091.37000000", "0.00000000"], ["84091.41000000", "0.00000000"], ["84091.44000000", "0.00000000"], ["84091.51000000", "0.01900000"], ["84091.56000000", "0.07037000"], ["84091.62000000", "0.00118000"], ["84091.63000000", "0.00000000"], ["84091.75000000", "0.02227000"], ["84092.07000000", "0.33144000"], ["84092.18000000", "0.00000000"], ["84092.23000000", "0.02219000"], ["84092.40000000", "0.00006000"], ["84093.03000000", "0.13684000"], ["84093.29000000", "0.00000000"], ["84093.52000000", "0.00000000"], ["84093.89000000", "0.02000000"], ["84093.95000000", "0.00753000"], ["84093.98000000", "0.00000000"], ["84094.04000000", "0.00000000"], ["84094.58000000", "0.04922000"], ["84094.75000000", "0.00000000"], ["84094.77000000", "0.18313000"], ["84095.12000000", "0.00000000"], ["84095.38000000", "0.00118000"], ["84095.41000000", "0.04400000"], ["84095.57000000", "0.00000000"], ["84095.61000000", "0.00000000"], ["84095.64000000", "0.00000000"], ["84095.78000000", "0.00000000"], ["84096.00000000", "0.02260000"], ["84096.25000000", "0.13200000"], ["84096.32000000", "0.04800000"], ["84096.46000000", "0.00000000"], ["84096.87000000", "0.00000000"], ["84097.28000000", "0.00000000"], ["84097.29000000", "0.04000000"], ["84097.45000000", "0.15019000"], ["84097.77000000", "0.00000000"], ["84098.29000000", "0.00095000"], ["84098.56000000", "0.00000000"], ["84098.61000000", "0.00000000"], ["84099.04000000", "0.00000000"], ["84099.63000000", "0.05600000"], ["84099.92000000", "0.80399000"], ["84099.95000000", "0.00000000"], ["84100.00000000", "0.00023000"], ["84100.09000000", "0.08000000"], ["84100.34000000", "0.02377000"], ["84100.39000000", "0.00000000"], ["84100.46000000", "0.11600000"], ["84100.47000000", "0.01189000"], ["84100.51000000", "0.08000000"], ["84101.45000000", "0.00000000"], ["84101.69000000", "0.00000000"], ["84101.74000000", "0.78514000"], ["84102.02000000", "0.00000000"], ["84102.03000000", "0.00000000"], ["84102.07000000", "0.00000000"], ["84102.83000000", "0.00059000"], ["84102.95000000", "0.00000000"], ["84103.28000000", "0.01189000"], ["84103.47000000", "0.00900000"], ["84103.62000000", "0.15168000"], ["84103.70000000", "0.00000000"], ["84104.19000000", "0.00000000"], ["84104.65000000", "0.00000000"], ["84106.31000000", "0.47549000"], ["84106.66000000", "1.05155000"], ["84107.34000000", "0.00000000"], ["84107.97000000", "0.00000000"], ["84108.87000000", "0.00000000"], ["84109.01000000", "0.00006000"], ["84109.21000000", "0.00000000"], ["84109.81000000", "0.00000000"], ["84110.00000000", "0.00000000"], ["84110.06000000", "0.00505000"], ["84110.37000000", "0.00000000"], ["84110.72000000", "0.00000000"], ["84110.75000000", "0.00000000"], ["84111.23000000", "0.00000000"], ["84111.31000000", "0.00000000"], ["84111.49000000", "0.00000000"], ["84111.93000000", "0.05943000"], ["84111.94000000", "0.00000000"], ["84112.25000000", "0.00000000"], ["84112.29000000", "0.00359000"], ["84113.02000000", "0.00000000"], ["84113.07000000", "0.00000000"], ["84113.16000000", "0.00000000"], ["84113.98000000", "0.00000000"], ["84114.02000000", "0.02587000"], ["84114.26000000", "0.02516000"], ["84114.73000000", "0.00000000"], ["84114.75000000", "0.00151000"], ["84115.63000000", "0.04400000"], ["84116.46000000", "0.04400000"], ["84116.49000000", "0.89155000"], ["84117.37000000", "0.04800000"], ["84118.57000000", "0.00000000"], ["84118.74000000", "0.00000000"], ["84118.90000000", "0.02814000"], ["84119.05000000", "0.00000000"], ["84119.38000000", "0.00000000"], ["84120.23000000", "0.00000000"], ["84120.58000000", "0.00922000"], ["84120.82000000", "0.00557000"], ["84121.56000000", "0.08000000"], ["84123.88000000", "0.00355000"], ["84123.97000000", "0.85647000"], ["84124.49000000", "0.00000000"], ["84125.24000000", "0.00000000"], ["84125.96000000", "0.02094000"], ["84125.99000000", "0.00016000"], ["84126.03000000", "0.00059000"], ["84126.67000000", "0.00000000"], ["84127.16000000", "0.00000000"], ["84127.31000000", "0.85625000"], ["84128.21000000", "0.38996000"], ["84128.80000000", "0.00000000"], ["84129.08000000", "0.01902000"], ["84129.82000000", "0.06123000"], ["84130.44000000", "0.71790000"], ["84130.45000000", "0.00000000"], ["84130.59000000", "0.00000000"], ["84130.62000000", "0.00000000"], ["84134.04000000", "0.59483000"], ["84138.64000000", "0.00869000"], ["84139.29000000", "0.00823000"], ["84140.73000000", "0.00000000"], ["84141.04000000", "0.00000000"], ["84142.42000000", "0.02911000"], ["84142.54000000", "0.01128000"], ["84149.24000000", "0.01940000"], ["84151.65000000", "0.00666000"], ["84155.09000000", "0.05600000"], ["84158.48000000", "0.00000000"], ["84158.49000000", "0.00731000"], ["84159.31000000", "0.00825000"], ["84160.15000000", "0.00000000"], ["84160.53000000", "0.02173000"], ["84161.04000000", "0.00000000"], ["84162.93000000", "0.00000000"], ["84164.89000000", "0.00019000"], ["84165.60000000", "0.00000000"], ["84165.85000000", "0.00000000"], ["84167.14000000", "0.00000000"], ["84168.14000000", "0.00000000"], ["84168.72000000", "0.04638000"], ["84168.76000000", "0.00145000"], ["84169.04000000", "0.00000000"], ["84173.81000000", "0.00000000"], ["84174.66000000", "0.00000000"], ["84175.09000000", "0.00000000"], ["84178.19000000", "0.09623000"], ["84182.22000000", "0.14616000"], ["84183.72000000", "0.00000000"], ["84188.15000000", "0.00059000"], ["84192.53000000", "0.12899000"], ["84210.98000000", "0.00000000"], ["84215.89000000", "0.00000000"], ["84218.36000000", "0.00699000"], ["84223.28000000", "0.02173000"], ["84226.49000000", "0.01128000"], ["84234.20000000", "1.37068000"], ["84237.83000000", "0.00000000"], ["84237.85000000", "0.00000000"], ["84240.64000000", "0.00000000"], ["84245.13000000", "0.00000000"], ["84256.09000000", "0.01548000"], ["84256.92000000", "0.00050000"], ["84257.42000000", "0.00000000"], ["84261.03000000", "0.00000000"], ["84264.47000000", "0.00000000"], ["84271.19000000", "0.99828000"], ["84349.20000000", "0.00000000"], ["84366.72000000", "0.45000000"], ["84370.23000000", "0.00000000"], ["84381.40000000", "4.48102000"], ["84507.50000000", "0.18231000"], ["84556.10000000", "0.00000000"], ["84703.30000000", "0.00000000"], ["84854.07000000", "0.03658000"], ["84898.71000000", "0.00000000"], ["85348.37000000", "0.00100000"], ["85349.10000000", "0.00000000"], ["85370.40000000", "0.13199000"], ["87136.48000000", "0.00019000"]], "record_time": 1742584922.127741, "EXCHANGE": "BINANCE"}
{"e": "depthUpdate", "E": 1742584923014, "s": "BTCUSDT", "U": 64637911072, "u": 64637913377, "b": [["84090.44000000", "8.41601000"], ["84090.43000000", "0.00047000"], ["84090.08000000", "0.00007000"], ["84090.01000000", "0.00021000"], ["84090.00000000", "0.06280000"], ["84089.99000000", "0.00007000"], ["84089.98000000", "0.00000000"], ["84089.84000000", "0.00007000"], ["84089.82000000", "0.00000000"], ["84089.58000000", "0.00000000"], ["84089.57000000", "0.00021000"], ["84089.56000000", "0.04013000"], ["84089.52000000", "0.00014000"], ["84089.51000000", "0.60894000"], ["84089.50000000", "0.00000000"], ["84089.49000000", "0.00000000"], ["84089.48000000", "0.00000000"], ["84089.47000000", "0.78538000"], ["84089.46000000", "0.49275000"], ["84089.45000000", "0.00000000"], ["84089.44000000", "0.00000000"], ["84089.26000000", "0.00000000"], ["84089.25000000", "0.00000000"], ["84089.24000000", "0.00000000"], ["84089.17000000", "0.04006000"], ["84089.10000000", "0.00000000"], ["84089.05000000", "0.00000000"], ["84089.04000000", "0.00000000"], ["84089.01000000", "0.04000000"], ["84089.00000000", "0.00007000"], ["84088.96000000", "0.00000000"], ["84088.95000000", "0.00000000"], ["84088.94000000", "0.00000000"], ["84088.93000000", "0.00101000"], ["84088.92000000", "0.00000000"], ["84088.78000000", "0.00000000"], ["84088.77000000", "0.01189000"], ["84088.70000000", "0.00000000"], ["84088.69000000", "0.00000000"], ["84088.68000000", "0.00000000"], ["84088.67000000", "0.00000000"], ["84088.66000000", "0.00000000"], ["84088.65000000", "0.00000000"], ["84088.56000000", "0.00000000"], ["84088.35000000", "0.00000000"], ["84088.25000000", "0.00000000"], ["84088.24000000", "0.00000000"], ["84088.23000000", "0.20813000"], ["84088.22000000", "0.00000000"], ["84088.18000000", "0.00000000"], ["84088.17000000", "0.00000000"], ["84088.16000000", "0.00007000"], ["84088.15000000", "0.00000000"], ["84088.14000000", "0.00000000"], ["84088.13000000", "0.00000000"], ["84088.05000000", "0.00201000"], ["84088.00000000", "0.02260000"], ["84087.88000000", "0.00000000"], ["84087.87000000", "0.05353000"], ["84087.86000000", "0.00000000"], ["84087.85000000", "0.00000000"], ["84087.70000000", "0.00118000"], ["84087.06000000", "0.00033000"], ["84087.05000000", "0.03373000"], ["84087.00000000", "0.02378000"], ["84086.84000000", "0.02539000"], ["84086.58000000", "0.04000000"], ["84086.47000000", "0.00000000"], ["84086.40000000", "0.08992000"], ["84086.20000000", "0.00000000"], ["84086.19000000", "0.00000000"], ["84086.00000000", "0.02260000"], ["84085.86000000", "0.00118000"], ["84085.85000000", "0.00000000"], ["84085.56000000", "0.03000000"], ["84085.10000000", "0.00000000"], ["84085.09000000", "0.04231000"], ["84084.96000000", "0.08000000"], ["84084.87000000", "0.00000000"], ["84084.83000000", "0.00000000"], ["84084.81000000", "0.04000000"], ["84084.80000000", "0.14943000"], ["84084.73000000", "0.00000000"], ["84084.54000000", "0.00000000"], ["84084.34000000", "0.28212000"], ["84084.33000000", "0.14292000"], ["84084.05000000", "0.04000000"], ["84083.82000000", "0.00118000"], ["84083.80000000", "0.00006000"], ["84083.72000000", "0.01189000"], ["84083.21000000", "0.04000000"], ["84082.00000000", "0.02260000"], ["84081.54000000", "0.00307000"], ["84081.42000000", "0.00000000"], ["84081.18000000", "0.00260000"], ["84080.97000000", "0.56579000"], ["84080.96000000", "0.89155000"], ["84080.81000000", "0.04000000"], ["84080.52000000", "0.00000000"], ["84080.51000000", "0.00000000"], ["84080.36000000", "0.00000000"], ["84079.38000000", "0.00000000"], ["84079.19000000", "0.00000000"], ["84078.96000000", "0.00922000"], ["84078.78000000", "0.85675000"], ["84078.43000000", "0.00013000"], ["84078.39000000", "0.00000000"], ["84077.84000000", "0.01189000"], ["84076.76000000", "0.71126000"], ["84076.75000000", "0.85672000"], ["84076.74000000", "0.59477000"], ["84076.73000000", "0.00000000"], ["84076.70000000", "0.00000000"], ["84076.67000000", "0.00000000"], ["84075.97000000", "0.00000000"], ["84075.63000000", "0.00000000"], ["84075.60000000", "0.00006000"], ["84075.58000000", "0.00000000"], ["84075.53000000", "0.35662000"], ["84075.47000000", "0.02539000"], ["84075.10000000", "0.05792000"], ["84074.18000000", "0.00000000"], ["84073.70000000", "0.00000000"], ["84073.66000000", "0.00000000"], ["84073.37000000", "0.00000000"], ["84073.36000000", "0.00000000"], ["84072.47000000", "0.00000000"], ["84072.31000000", "0.00000000"], ["84071.90000000", "0.00000000"], ["84071.86000000", "0.08354000"], ["84070.93000000", "0.00000000"], ["84070.71000000", "0.17899000"], ["84070.69000000", "0.00758000"], ["84070.11000000", "0.00000000"], ["84069.39000000", "0.00000000"], ["84068.81000000", "0.13418000"], ["84068.71000000", "0.10602000"], ["84068.67000000", "0.00000000"], ["84067.98000000", "0.00000000"], ["84067.48000000", "0.00000000"], ["84067.23000000", "0.00000000"], ["84066.47000000", "0.00000000"], ["84066.10000000", "0.00000000"], ["84065.85000000", "0.00356000"], ["84065.12000000", "0.89155000"], ["84064.56000000", "0.00000000"], ["84064.03000000", "0.00000000"], ["84062.01000000", "0.00000000"], ["84061.26000000", "0.54764000"], ["84060.80000000", "0.11446000"], ["84059.15000000", "0.83025000"], ["84058.70000000", "0.00000000"], ["84057.32000000", "0.34855000"], ["84057.15000000", "0.04628000"], ["84056.96000000", "0.23693000"], ["84056.79000000", "0.00000000"], ["84056.72000000", "0.00000000"], ["84055.83000000", "0.02817000"], ["84055.31000000", "0.00000000"], ["84054.46000000", "0.05000000"], ["84054.01000000", "0.00000000"], ["84052.95000000", "0.00000000"], ["84051.74000000", "0.00019000"], ["84050.83000000", "0.00000000"], ["84050.59000000", "0.00000000"], ["84050.40000000", "0.89161000"], ["84049.26000000", "0.03202000"], ["84048.82000000", "0.00000000"], ["84047.93000000", "0.04000000"], ["84047.41000000", "0.00059000"], ["84046.95000000", "0.00000000"], ["84046.94000000", "0.00000000"], ["84046.46000000", "0.00000000"], ["84045.88000000", "0.00000000"], ["84045.40000000", "0.01300000"], ["84045.25000000", "0.05796000"], ["84042.02000000", "0.00000000"], ["84041.94000000", "0.00000000"], ["84041.23000000", "0.08996000"], ["84041.03000000", "0.05252000"], ["84040.43000000", "0.14992000"], ["84038.96000000", "0.00600000"], ["84036.95000000", "0.00000000"], ["84035.99000000", "0.00000000"], ["84033.60000000", "0.03575000"], ["84032.27000000", "0.00806000"], ["84031.41000000", "0.00807000"], ["84028.76000000", "0.00000000"], ["84028.33000000", "0.00296000"], ["84027.37000000", "0.10497000"], ["84027.17000000", "0.00040000"], ["84027.16000000", "0.00040000"], ["84024.31000000", "0.42224000"], ["84024.17000000", "0.00000000"], ["84023.93000000", "0.00061000"], ["84023.75000000", "0.00000000"], ["84023.38000000", "0.10000000"], ["84019.39000000", "0.00000000"], ["84018.71000000", "0.00000000"], ["84017.78000000", "0.04000000"], ["84016.98000000", "0.00000000"], ["84016.94000000", "0.04000000"], ["84016.80000000", "0.00006000"], ["84016.54000000", "0.00000000"], ["84016.14000000", "0.00000000"], ["84014.34000000", "0.00000000"], ["84014.30000000", "0.00000000"], ["84011.96000000", "0.12900000"], ["84010.49000000", "0.00000000"], ["84005.33000000", "1.02851000"], ["83998.04000000", "0.01196000"], ["83996.10000000", "0.09512000"], ["83992.74000000", "0.00000000"], ["83989.68000000", "1.42274000"], ["83988.94000000", "0.00000000"], ["83986.10000000", "0.00013000"], ["83985.41000000", "0.00400000"], ["83981.39000000", "0.00000000"], ["83980.20000000", "0.00000000"], ["83979.99000000", "0.93250000"], ["83974.09000000", "0.00000000"], ["83972.98000000", "0.00000000"], ["83965.21000000", "0.00000000"], ["83960.60000000", "0.00000000"], ["83948.17000000", "0.00000000"], ["83945.36000000", "0.00000000"], ["83942.60000000", "0.00000000"], ["83941.94000000", "0.00000000"], ["83938.56000000", "0.00000000"], ["83936.34000000", "0.00000000"], ["83932.14000000", "0.01000000"], ["83926.65000000", "0.00000000"], ["83920.44000000", "0.00835000"], ["83917.83000000", "0.00000000"], ["83866.64000000", "0.00000000"], ["83861.95000000", "0.00000000"], ["83860.47000000", "0.20137000"], ["83857.45000000", "0.00000000"], ["83854.81000000", "0.00000000"], ["83852.59000000", "0.20137000"], ["83852.07000000", "0.00000000"], ["83848.70000000", "0.00000000"], ["83844.19000000", "0.20137000"], ["83842.95000000", "0.00000000"], ["83835.80000000", "0.01113000"], ["83152.49000000", "0.00000000"], ["82829.08000000", "0.00100000"], ["80714.10000000", "0.03566000"], ["75681.00000000", "0.00020000"], ["75680.00000000", "0.31379000"], ["75679.00000000", "0.00397000"], ["75678.00000000", "1.94632000"], ["67272.36000000", "0.00058000"], ["67271.57000000", "0.00000000"], ["67270.59000000", "0.00000000"], ["50001.00000000", "1.82087000"], ["33000.00000000", "2.93827000"], ["30272.21000000", "0.00040000"], ["21030.20000000", "0.00000000"]], "a": [["84088.24000000", "0.00000000"], ["84088.25000000", "0.00000000"], ["84088.66000000", "0.00000000"], ["84088.67000000", "0.00000000"], ["84088.68000000", "0.00000000"], ["84088.69000000", "0.00000000"], ["84088.70000000", "0.00000000"], ["84088.71000000", "0.00000000"], ["84088.93000000", "0.00000000"], ["84088.94000000", "0.00000000"], ["84088.99000000", "0.00000000"], ["84089.25000000", "0.00000000"], ["84089.26000000", "0.00000000"], ["84089.45000000", "0.00000000"], ["84089.46000000", "0.00000000"], ["84089.47000000", "0.00000000"], ["84089.48000000", "0.00000000"], ["84089.83000000", "0.00000000"], ["84089.99000000", "0.00000000"], ["84090.00000000", "0.00000000"], ["84090.01000000", "0.00000000"], ["84090.02000000", "0.00000000"], ["84090.09000000", "0.00000000"], ["84090.10000000", "0.00000000"], ["84090.29000000", "0.00000000"], ["84090.44000000", "0.00000000"], ["84090.45000000", "0.02078000"], ["84090.46000000", "0.00046000"], ["84090.53000000", "0.00000000"], ["84090.54000000", "0.00000000"], ["84090.55000000", "0.00000000"], ["84090.68000000", "0.00014000"], ["84091.29000000", "0.00034000"], ["84091.30000000", "0.00007000"], ["84091.49000000", "0.00000000"], ["84091.50000000", "0.00021000"], ["84091.51000000", "0.01920000"], ["84091.52000000", "0.00014000"], ["84091.56000000", "0.00000000"], ["84091.62000000", "0.00000000"], ["84091.65000000", "0.00014000"], ["84091.66000000", "0.01962000"], ["84091.72000000", "0.00000000"], ["84091.75000000", "0.00000000"], ["84092.00000000", "0.00000000"], ["84092.02000000", "0.00000000"], ["84092.03000000", "0.00000000"], ["84092.07000000", "0.00000000"], ["84092.21000000", "0.00000000"], ["84092.22000000", "0.00000000"], ["84092.23000000", "0.00000000"], ["84092.37000000", "0.00007000"], ["84092.40000000", "0.00000000"], ["84092.55000000", "0.00000000"], ["84093.02000000", "0.00000000"], ["84093.03000000", "0.00000000"], ["84093.05000000", "0.00000000"], ["84093.06000000", "0.00000000"], ["84093.21000000", "0.00000000"], ["84093.30000000", "0.00400000"], ["84093.42000000", "0.00000000"], ["84093.47000000", "0.00118000"], ["84093.50000000", "0.00000000"], ["84093.70000000", "0.00500000"], ["84093.89000000", "0.00000000"], ["84093.95000000", "0.00000000"], ["84094.00000000", "0.00000000"], ["84094.04000000", "0.00021000"], ["84094.05000000", "0.02234000"], ["84094.12000000", "0.00000000"], ["84094.16000000", "0.00021000"], ["84094.17000000", "0.02076000"], ["84094.21000000", "0.00000000"], ["84094.30000000", "0.00007000"], ["84094.31000000", "0.31706000"], ["84094.51000000", "0.00000000"], ["84094.58000000", "0.00522000"], ["84094.77000000", "0.00000000"], ["84094.92000000", "0.00007000"], ["84094.93000000", "0.06408000"], ["84095.09000000", "0.23298000"], ["84095.10000000", "0.13950000"], ["84095.41000000", "0.00000000"], ["84095.86000000", "0.00000000"], ["84095.92000000", "0.00000000"], ["84096.00000000", "0.02260000"], ["84096.25000000", "0.00000000"], ["84096.32000000", "0.00000000"], ["84096.51000000", "0.02219000"], ["84096.52000000", "0.00000000"], ["84096.57000000", "0.00008000"], ["84097.12000000", "0.00000000"], ["84097.14000000", "0.00301000"], ["84097.20000000", "0.00000000"], ["84097.29000000", "0.00000000"], ["84097.45000000", "0.00000000"], ["84097.47000000", "0.14433000"], ["84097.62000000", "0.00000000"], ["84097.70000000", "0.00000000"], ["84097.89000000", "0.00118000"], ["84098.08000000", "0.00756000"], ["84098.25000000", "0.10840000"], ["84098.53000000", "0.17899000"], ["84098.57000000", "0.00000000"], ["84098.82000000", "0.10602000"], ["84099.19000000", "0.00000000"], ["84099.38000000", "0.00000000"], ["84099.63000000", "0.00000000"], ["84099.83000000", "0.00000000"], ["84099.92000000", "0.14737000"], ["84100.09000000", "0.00000000"], ["84100.29000000", "0.00000000"], ["84100.34000000", "0.00000000"], ["84100.42000000", "0.01500000"], ["84100.46000000", "0.00000000"], ["84100.47000000", "0.00000000"], ["84100.50000000", "0.01500000"], ["84100.51000000", "0.00000000"], ["84100.76000000", "0.00000000"], ["84101.49000000", "0.00000000"], ["84101.59000000", "0.00000000"], ["84101.65000000", "0.00000000"], ["84101.74000000", "0.00000000"], ["84101.93000000", "0.00000000"], ["84101.94000000", "0.00000000"], ["84102.06000000", "0.35662000"], ["84102.07000000", "0.00000000"], ["84102.08000000", "0.00000000"], ["84102.09000000", "0.00000000"], ["84102.79000000", "0.04400000"], ["84102.99000000", "0.00000000"], ["84103.05000000", "0.00000000"], ["84103.09000000", "0.00000000"], ["84103.19000000", "0.00000000"], ["84103.29000000", "0.04400000"], ["84103.35000000", "0.87380000"], ["84103.38000000", "0.00000000"], ["84103.40000000", "0.00400000"], ["84103.46000000", "0.00000000"], ["84103.54000000", "0.03130000"], ["84103.62000000", "0.00000000"], ["84103.63000000", "0.06400000"], ["84103.94000000", "0.00000000"], ["84104.09000000", "0.00000000"], ["84104.22000000", "0.15019000"], ["84104.29000000", "0.03087000"], ["84104.91000000", "0.00000000"], ["84104.98000000", "0.06800000"], ["84105.00000000", "0.02347000"], ["84105.02000000", "0.00000000"], ["84105.25000000", "0.00000000"], ["84105.36000000", "0.00000000"], ["84105.37000000", "0.00000000"], ["84105.59000000", "0.04000000"], ["84106.03000000", "0.00000000"], ["84106.06000000", "0.14637000"], ["84106.08000000", "0.00000000"], ["84106.47000000", "0.04800000"], ["84106.58000000", "0.00000000"], ["84106.59000000", "0.08000000"], ["84106.66000000", "0.89155000"], ["84106.89000000", "0.00000000"], ["84107.27000000", "0.00000000"], ["84107.45000000", "0.59437000"], ["84107.66000000", "0.00000000"], ["84107.82000000", "0.00000000"], ["84107.84000000", "0.11600000"], ["84107.87000000", "1.02048000"], ["84107.88000000", "0.00000000"], ["84107.99000000", "0.78508000"], ["84108.16000000", "0.00000000"], ["84108.34000000", "0.05600000"], ["84108.38000000", "0.00000000"], ["84108.58000000", "0.04000000"], ["84109.86000000", "0.15168000"], ["84109.96000000", "0.00000000"], ["84110.06000000", "0.00000000"], ["84110.07000000", "0.00000000"], ["84110.20000000", "0.00000000"], ["84110.67000000", "0.08000000"], ["84110.86000000", "0.00000000"], ["84110.87000000", "0.00000000"], ["84111.24000000", "0.00000000"], ["84111.56000000", "0.00000000"], ["84111.81000000", "1.34981000"], ["84111.93000000", "0.00000000"], ["84112.13000000", "0.00000000"], ["84112.20000000", "0.00000000"], ["84112.47000000", "0.00000000"], ["84112.58000000", "0.05943000"], ["84113.45000000", "0.00506000"], ["84113.93000000", "0.00000000"], ["84114.08000000", "0.00000000"], ["84114.16000000", "0.00000000"], ["84114.26000000", "0.16000000"], ["84114.34000000", "0.00000000"], ["84114.67000000", "0.02432000"], ["84114.75000000", "0.00000000"], ["84115.22000000", "0.89155000"], ["84115.63000000", "0.00000000"], ["84115.69000000", "0.89155000"], ["84116.21000000", "0.00000000"], ["84116.30000000", "0.00000000"], ["84116.46000000", "0.00000000"], ["84116.66000000", "0.00000000"], ["84116.88000000", "0.00000000"], ["84117.20000000", "0.00101000"], ["84117.37000000", "0.00000000"], ["84117.91000000", "0.00151000"], ["84117.93000000", "0.00237000"], ["84117.94000000", "0.30601000"], ["84117.95000000", "0.30492000"], ["84118.28000000", "0.02421000"], ["84118.70000000", "0.00000000"], ["84118.90000000", "0.00000000"], ["84119.82000000", "0.00000000"], ["84120.30000000", "0.89155000"], ["84120.42000000", "0.00000000"], ["84120.58000000", "0.00000000"], ["84120.69000000", "0.89155000"], ["84120.91000000", "0.00000000"], ["84121.56000000", "0.00000000"], ["84121.89000000", "0.00000000"], ["84122.27000000", "0.00000000"], ["84122.74000000", "0.00938000"], ["84123.59000000", "0.00000000"], ["84123.97000000", "0.00018000"], ["84124.01000000", "0.00000000"], ["84124.44000000", "0.01876000"], ["84124.73000000", "0.00878000"], ["84125.45000000", "0.00000000"], ["84125.50000000", "0.00000000"], ["84126.03000000", "0.00000000"], ["84126.78000000", "0.89155000"], ["84127.31000000", "0.00000000"], ["84127.81000000", "0.85625000"], ["84128.28000000", "0.11975000"], ["84128.44000000", "0.00000000"], ["84128.65000000", "1.37353000"], ["84128.66000000", "0.89155000"], ["84128.89000000", "0.00000000"], ["84128.92000000", "0.89614000"], ["84129.50000000", "0.00000000"], ["84129.82000000", "0.00000000"], ["84130.44000000", "0.00000000"], ["84130.46000000", "0.00000000"], ["84130.68000000", "0.00000000"], ["84131.51000000", "0.00059000"], ["84132.11000000", "1.05831000"], ["84132.12000000", "0.00000000"], ["84132.39000000", "0.02441000"], ["84132.53000000", "0.00573000"], ["84132.91000000", "0.00000000"], ["84133.79000000", "0.05000000"], ["84134.04000000", "0.00000000"], ["84134.27000000", "0.85618000"], ["84134.99000000", "0.35662000"], ["84135.23000000", "0.03676000"], ["84135.25000000", "0.00100000"], ["84135.51000000", "0.00000000"], ["84136.21000000", "0.00000000"], ["84136.34000000", "0.00000000"], ["84136.36000000", "0.00100000"], ["84136.80000000", "0.00000000"], ["84137.36000000", "0.00000000"], ["84137.65000000", "0.00000000"], ["84138.53000000", "0.00000000"], ["84139.10000000", "0.00000000"], ["84140.58000000", "0.00000000"], ["84140.72000000", "0.85612000"], ["84141.05000000", "0.00000000"], ["84141.89000000", "0.59477000"], ["84143.89000000", "0.01196000"], ["84145.57000000", "0.01188000"], ["84147.08000000", "0.04371000"], ["84149.07000000", "0.00000000"], ["84149.89000000", "0.00000000"], ["84152.76000000", "0.00000000"], ["84154.78000000", "0.00825000"], ["84155.35000000", "0.00000000"], ["84157.86000000", "0.00297000"], ["84158.83000000", "0.46808000"], ["84159.31000000", "0.05225000"], ["84159.46000000", "0.00000000"], ["84159.75000000", "0.00000000"], ["84160.15000000", "0.04400000"], ["84160.33000000", "0.03971000"], ["84161.13000000", "1.02661000"], ["84162.94000000", "0.04800000"], ["84165.11000000", "0.02644000"], ["84165.45000000", "0.01663000"], ["84167.14000000", "0.08000000"], ["84168.22000000", "0.00000000"], ["84169.04000000", "0.00000000"], ["84170.49000000", "0.00699000"], ["84173.11000000", "0.00000000"], ["84173.36000000", "0.00297000"], ["84173.71000000", "0.00000000"], ["84173.81000000", "0.00000000"], ["84174.66000000", "0.00000000"], ["84175.09000000", "0.00000000"], ["84175.89000000", "0.05291000"], ["84176.12000000", "0.00000000"], ["84177.03000000", "0.00852000"], ["84181.32000000", "0.00000000"], ["84184.16000000", "0.00811000"], ["84185.88000000", "0.02357000"], ["84188.15000000", "0.00000000"], ["84188.96000000", "0.00000000"], ["84191.44000000", "0.00000000"], ["84192.53000000", "0.12958000"], ["84194.54000000", "0.00000000"], ["84198.05000000", "0.01247000"], ["84198.56000000", "0.05497000"], ["84203.62000000", "0.00000000"], ["84216.15000000", "0.05297000"], ["84217.17000000", "0.06214000"], ["84219.20000000", "0.05297000"], ["84219.64000000", "0.00000000"], ["84220.94000000", "0.04997000"], ["84224.51000000", "0.04498000"], ["84227.18000000", "0.05297000"], ["84227.98000000", "0.04998000"], ["84229.22000000", "0.04997000"], ["84229.24000000", "0.04998000"], ["84230.48000000", "0.04498000"], ["84236.63000000", "0.01025000"], ["84238.02000000", "0.04198000"], ["84246.70000000", "0.00556000"], ["84256.92000000", "0.00000000"], ["84258.43000000", "0.00000000"], ["84259.33000000", "0.00050000"], ["84263.15000000", "0.00000000"], ["84267.40000000", "0.01516000"], ["84271.19000000", "0.00000000"], ["84351.52000000", "0.07005000"], ["84359.92000000", "0.13146000"], ["84361.54000000", "0.06991000"], ["84369.94000000", "0.13159000"], ["84370.23000000", "0.99336000"], ["85192.99000000", "0.00000000"], ["85316.86000000", "0.00000000"], ["85348.37000000", "0.00000000"], ["85368.06000000", "0.10000000"], ["85391.70000000", "0.00007000"], ["85413.00000000", "0.05900000"]], "record_time": 1742584923.128136, "EXCHANGE": "BINANCE"}
{"e": "depthUpdate", "E": 1742584924014, "s": "BTCUSDT", "U": 64637913378, "u": 64637919941, "b": [["84104.28000000", "6.94598000"], ["84104.27000000", "0.00035000"], ["84104.25000000", "0.00000000"], ["84104.24000000", "0.00000000"], ["84104.23000000", "0.00000000"], ["84104.19000000", "0.00021000"], ["84104.18000000", "2.75215000"], ["84104.17000000", "0.64440000"], ["84104.13000000", "0.36182000"], ["84104.00000000", "0.02273000"], ["84103.70000000", "0.00007000"], ["84103.69000000", "0.00000000"], ["84103.54000000", "0.17905000"], ["84103.53000000", "2.22638000"], ["84103.52000000", "0.00014000"], ["84103.39000000", "0.00000000"], ["84103.38000000", "0.00000000"], ["84103.33000000", "0.00000000"], ["84103.31000000", "0.00000000"], ["84103.29000000", "0.00000000"], ["84103.28000000", "0.03584000"], ["84103.21000000", "0.00000000"], ["84102.49000000", "0.00000000"], ["84102.27000000", "0.04006000"], ["84102.23000000", "0.00000000"], ["84102.22000000", "0.00010000"], ["84102.21000000", "0.05924000"], ["84102.00000000", "0.02266000"], ["84101.86000000", "0.01189000"], ["84101.81000000", "0.00000000"], ["84101.80000000", "0.03584000"], ["84101.57000000", "0.00000000"], ["84101.56000000", "0.04996000"], ["84101.44000000", "0.04000000"], ["84101.35000000", "0.00000000"], ["84101.34000000", "0.00000000"], ["84101.30000000", "0.02378000"], ["84101.29000000", "0.03679000"], ["84101.28000000", "0.00000000"], ["84100.71000000", "0.00000000"], ["84100.70000000", "0.00034000"], ["84100.69000000", "0.03578000"], ["84100.59000000", "0.04000000"], ["84100.57000000", "0.04000000"], ["84100.52000000", "0.04000000"], ["84100.13000000", "0.00000000"], ["84100.12000000", "0.00000000"], ["84100.10000000", "0.00000000"], ["84100.00000000", "0.02266000"], ["84099.99000000", "0.00000000"], ["84099.92000000", "0.02538000"], ["84099.83000000", "0.00000000"], ["84099.82000000", "0.00000000"], ["84099.77000000", "0.00000000"], ["84099.76000000", "0.00000000"], ["84099.75000000", "0.00000000"], ["84099.72000000", "0.00000000"], ["84099.71000000", "0.72316000"], ["84099.70000000", "0.00000000"], ["84099.67000000", "0.00000000"], ["84099.25000000", "0.00000000"], ["84099.16000000", "0.00000000"], ["84099.04000000", "0.11889000"], ["84098.98000000", "0.12483000"], ["84098.79000000", "0.00000000"], ["84098.64000000", "0.11890000"], ["84098.52000000", "0.00000000"], ["84098.51000000", "0.00000000"], ["84098.39000000", "0.00000000"], ["84098.29000000", "0.14819000"], ["84098.28000000", "0.00000000"], ["84098.26000000", "0.29711000"], ["84098.25000000", "0.00000000"], ["84098.24000000", "0.12657000"], ["84098.23000000", "0.00000000"], ["84098.06000000", "0.04000000"], ["84098.01000000", "0.00000000"], ["84098.00000000", "0.02260000"], ["84097.99000000", "0.00000000"], ["84097.89000000", "0.00000000"], ["84097.88000000", "0.00000000"], ["84097.54000000", "0.00594000"], ["84097.47000000", "0.00000000"], ["84097.46000000", "0.00000000"], ["84097.45000000", "0.00000000"], ["84097.42000000", "0.00000000"], ["84097.37000000", "0.00000000"], ["84097.35000000", "0.00118000"], ["84097.23000000", "0.59463000"], ["84097.22000000", "0.04000000"], ["84097.13000000", "0.00000000"], ["84097.09000000", "0.00000000"], ["84096.88000000", "0.00000000"], ["84096.82000000", "0.00000000"], ["84096.81000000", "0.01189000"], ["84096.66000000", "0.00000000"], ["84096.60000000", "0.00006000"], ["84096.57000000", "0.00000000"], ["84096.56000000", "0.00000000"], ["84096.49000000", "0.00000000"], ["84096.38000000", "0.04000000"], ["84096.35000000", "0.05945000"], ["84096.31000000", "0.04000000"], ["84096.30000000", "0.00000000"], ["84096.20000000", "0.00000000"], ["84096.13000000", "0.00000000"], ["84096.12000000", "0.00000000"], ["84096.11000000", "0.00000000"], ["84096.07000000", "0.00000000"], ["84096.06000000", "0.00000000"], ["84096.00000000", "0.02260000"], ["84095.88000000", "0.11890000"], ["84095.73000000", "0.00000000"], ["84095.32000000", "0.00000000"], ["84095.31000000", "0.00000000"], ["84095.29000000", "0.00000000"], ["84095.21000000", "0.00000000"], ["84095.20000000", "0.00000000"], ["84095.19000000", "0.00000000"], ["84095.14000000", "0.00000000"], ["84094.89000000", "0.00000000"], ["84094.69000000", "0.00000000"], ["84094.68000000", "0.00000000"], ["84094.62000000", "0.00118000"], ["84094.58000000", "1.15631000"], ["84094.57000000", "0.00000000"], ["84094.56000000", "0.00000000"], ["84094.55000000", "0.00000000"], ["84094.44000000", "0.00000000"], ["84094.43000000", "0.00000000"], ["84094.42000000", "0.71126000"], ["84094.41000000", "0.08354000"], ["84094.40000000", "0.89155000"], ["84094.28000000", "0.00000000"], ["84094.17000000", "0.00000000"], ["84094.16000000", "0.00000000"], ["84094.15000000", "0.00000000"], ["84094.14000000", "0.89155000"], ["84094.06000000", "0.00000000"], ["84094.05000000", "0.00000000"], ["84094.04000000", "0.00000000"], ["84094.00000000", "0.02260000"], ["84093.78000000", "0.00000000"], ["84093.73000000", "0.00000000"], ["84093.68000000", "0.00000000"], ["84093.67000000", "0.00594000"], ["84093.66000000", "0.00000000"], ["84093.64000000", "0.00000000"], ["84093.63000000", "0.00000000"], ["84093.53000000", "0.00000000"], ["84093.49000000", "0.05945000"], ["84093.41000000", "0.00000000"], ["84093.40000000", "0.00000000"], ["84093.30000000", "0.00000000"], ["84093.29000000", "0.00000000"], ["84093.28000000", "0.00000000"], ["84093.23000000", "0.00000000"], ["84093.22000000", "0.00000000"], ["84093.20000000", "0.00000000"], ["84093.19000000", "0.04231000"], ["84093.18000000", "0.00000000"], ["84093.13000000", "0.00000000"], ["84093.03000000", "0.00013000"], ["84092.87000000", "0.00300000"], ["84092.61000000", "0.00000000"], ["84092.59000000", "0.10602000"], ["84092.48000000", "0.00000000"], ["84092.47000000", "0.02378000"], ["84092.40000000", "0.00006000"], ["84092.38000000", "0.00000000"], ["84092.36000000", "0.00000000"], ["84092.29000000", "0.00000000"], ["84092.28000000", "0.00000000"], ["84092.20000000", "0.04000000"], ["84092.01000000", "0.00000000"], ["84092.00000000", "0.02260000"], ["84091.83000000", "0.16000000"], ["84091.82000000", "0.00000000"], ["84091.65000000", "0.00000000"], ["84091.64000000", "0.00009000"], ["84091.61000000", "0.00000000"], ["84091.53000000", "0.00000000"], ["84091.52000000", "0.00000000"], ["84091.51000000", "0.00000000"], ["84091.50000000", "0.00000000"], ["84091.49000000", "0.00000000"], ["84091.34000000", "0.05945000"], ["84091.29000000", "0.00000000"], ["84091.28000000", "0.00000000"], ["84090.92000000", "0.01189000"], ["84090.83000000", "0.85662000"], ["84090.79000000", "0.00000000"], ["84090.78000000", "0.00000000"], ["84090.69000000", "0.00000000"], ["84090.68000000", "0.00000000"], ["84090.67000000", "0.45000000"], ["84090.66000000", "0.00000000"], ["84090.56000000", "0.00000000"], ["84090.55000000", "0.00000000"], ["84090.50000000", "0.01189000"], ["84090.46000000", "0.42886000"], ["84090.45000000", "0.00174000"], ["84090.44000000", "0.00000000"], ["84090.43000000", "0.00000000"], ["84090.08000000", "0.00000000"], ["84090.01000000", "0.00000000"], ["84090.00000000", "0.02260000"], ["84089.99000000", "0.00000000"], ["84089.84000000", "0.00000000"], ["84089.69000000", "0.00000000"], ["84089.57000000", "0.00000000"], ["84089.56000000", "0.00000000"], ["84089.52000000", "0.00000000"], ["84089.51000000", "0.00000000"], ["84089.47000000", "0.00000000"], ["84089.46000000", "0.00000000"], ["84089.17000000", "0.04000000"], ["84089.03000000", "0.05899000"], ["84089.01000000", "0.00000000"], ["84089.00000000", "0.00000000"], ["84088.93000000", "0.00000000"], ["84088.77000000", "0.00000000"], ["84088.76000000", "0.00000000"], ["84088.61000000", "0.71126000"], ["84088.38000000", "0.00594000"], ["84088.30000000", "0.33416000"], ["84088.24000000", "0.00000000"], ["84088.23000000", "0.00007000"], ["84088.22000000", "0.00000000"], ["84088.20000000", "0.00006000"], ["84088.16000000", "0.00000000"], ["84088.05000000", "0.00000000"], ["84087.97000000", "0.17899000"], ["84087.90000000", "0.00000000"], ["84087.87000000", "0.00000000"], ["84087.74000000", "0.00013000"], ["84087.70000000", "0.00000000"], ["84087.06000000", "0.00013000"], ["84087.05000000", "0.00000000"], ["84087.00000000", "0.00000000"], ["84086.84000000", "0.00000000"], ["84086.78000000", "0.05943000"], ["84086.58000000", "0.00000000"], ["84086.47000000", "0.00000000"], ["84086.40000000", "0.00000000"], ["84086.14000000", "1.18017000"], ["84086.13000000", "0.85667000"], ["84085.86000000", "0.00000000"], ["84085.56000000", "0.00000000"], ["84085.09000000", "0.00000000"], ["84085.01000000", "0.00013000"], ["84084.97000000", "0.00000000"], ["84084.96000000", "0.00000000"], ["84084.81000000", "0.00000000"], ["84084.80000000", "0.00000000"], ["84084.34000000", "0.00000000"], ["84084.33000000", "0.02339000"], ["84084.10000000", "0.01000000"], ["84084.05000000", "0.00000000"], ["84084.00000000", "0.02266000"], ["84083.82000000", "0.00000000"], ["84083.81000000", "0.00000000"], ["84083.72000000", "0.00000000"], ["84083.56000000", "0.71126000"], ["84083.55000000", "0.00000000"], ["84083.22000000", "0.08363000"], ["84083.21000000", "0.00000000"], ["84083.10000000", "0.89155000"], ["84083.02000000", "0.89155000"], ["84082.70000000", "0.00000000"], ["84082.69000000", "0.00013000"], ["84082.44000000", "0.85671000"], ["84082.00000000", "0.00000000"], ["84081.90000000", "0.00029000"], ["84081.76000000", "0.00000000"], ["84081.57000000", "0.05796000"], ["84081.56000000", "0.01189000"], ["84081.23000000", "0.00356000"], ["84080.97000000", "0.86374000"], ["84080.82000000", "0.00000000"], ["84080.81000000", "0.00000000"], ["84080.59000000", "0.00000000"], ["84080.48000000", "0.11886000"], ["84080.00000000", "0.00006000"], ["84079.80000000", "0.00006000"], ["84079.33000000", "0.17899000"], ["84079.23000000", "0.54764000"], ["84078.96000000", "0.00000000"], ["84078.16000000", "0.04228000"], ["84078.04000000", "0.00000000"], ["84078.00000000", "0.00000000"], ["84077.84000000", "0.00000000"], ["84077.75000000", "0.00059000"], ["84077.61000000", "0.00572000"], ["84077.22000000", "0.00000000"], ["84077.12000000", "0.00000000"], ["84076.89000000", "0.34924000"], ["84076.80000000", "0.00016000"], ["84076.77000000", "0.55552000"], ["84076.75000000", "0.00000000"], ["84076.74000000", "0.00000000"], ["84076.67000000", "0.20120000"], ["84076.26000000", "0.00000000"], ["84076.00000000", "0.00000000"], ["84075.77000000", "0.04628000"], ["84075.60000000", "0.02338000"], ["84075.53000000", "0.00000000"], ["84075.28000000", "0.00000000"], ["84075.27000000", "0.00000000"], ["84075.24000000", "0.00000000"], ["84075.10000000", "0.00000000"], ["84075.09000000", "0.00000000"], ["84075.01000000", "0.02817000"], ["84074.68000000", "0.00000000"], ["84074.49000000", "0.00000000"], ["84074.37000000", "0.00007000"], ["84074.24000000", "0.00000000"], ["84074.06000000", "0.37690000"], ["84074.00000000", "0.00000000"], ["84073.38000000", "0.00759000"], ["84072.31000000", "0.00594000"], ["84072.19000000", "0.00000000"], ["84072.01000000", "0.29346000"], ["84072.00000000", "0.39225000"], ["84071.90000000", "0.00000000"], ["84071.85000000", "0.00000000"], ["84071.82000000", "0.00000000"], ["84071.72000000", "0.00000000"], ["84071.39000000", "0.20123000"], ["84070.69000000", "0.00000000"], ["84070.58000000", "0.11899000"], ["84070.19000000", "0.00000000"], ["84070.12000000", "0.00000000"], ["84070.00000000", "0.00000000"], ["84069.93000000", "0.00000000"], ["84069.38000000", "0.00000000"], ["84069.19000000", "0.00000000"], ["84068.77000000", "0.76267000"], ["84068.71000000", "0.00000000"], ["84068.61000000", "0.00000000"], ["84068.35000000", "0.00000000"], ["84068.29000000", "0.00000000"], ["84068.11000000", "0.04000000"], ["84067.63000000", "0.30853000"], ["84067.44000000", "0.00000000"], ["84067.43000000", "0.00000000"], ["84067.19000000", "0.05947000"], ["84066.79000000", "0.00358000"], ["84066.58000000", "0.89155000"], ["84066.46000000", "0.00000000"], ["84066.33000000", "0.20137000"], ["84065.85000000", "0.00000000"], ["84065.63000000", "0.00000000"], ["84065.12000000", "0.23780000"], ["84065.01000000", "0.00000000"], ["84064.93000000", "0.02200000"], ["84064.79000000", "0.00000000"], ["84064.76000000", "0.50675000"], ["84064.75000000", "0.00000000"], ["84064.59000000", "1.31913000"], ["84064.58000000", "1.22654000"], ["84064.57000000", "0.14268000"], ["84063.92000000", "0.32127000"], ["84063.91000000", "0.04000000"], ["84063.90000000", "0.04000000"], ["84063.84000000", "0.04637000"], ["84063.83000000", "0.00000000"], ["84063.57000000", "0.00000000"], ["84063.26000000", "0.00000000"], ["84063.03000000", "0.09393000"], ["84063.02000000", "0.00000000"], ["84062.95000000", "0.03202000"], ["84062.86000000", "0.00000000"], ["84062.01000000", "0.10796000"], ["84061.74000000", "0.00000000"], ["84061.26000000", "0.00000000"], ["84061.24000000", "0.88844000"], ["84060.80000000", "0.00000000"], ["84060.58000000", "0.00000000"], ["84059.77000000", "0.00000000"], ["84059.55000000", "0.00000000"], ["84059.16000000", "0.00000000"], ["84059.15000000", "0.05498000"], ["84059.14000000", "0.00000000"], ["84058.65000000", "0.00000000"], ["84058.27000000", "0.24023000"], ["84058.26000000", "0.20283000"], ["84058.25000000", "0.00000000"], ["84057.33000000", "0.15794000"], ["84057.32000000", "0.00000000"], ["84057.16000000", "0.00146000"], ["84057.15000000", "0.00000000"], ["84056.19000000", "0.00000000"], ["84055.88000000", "0.52860000"], ["84055.83000000", "0.00000000"], ["84055.37000000", "0.09066000"], ["84054.84000000", "0.49998000"], ["84054.46000000", "0.00000000"], ["84054.12000000", "0.05298000"], ["84054.11000000", "0.27085000"], ["84054.10000000", "0.23338000"], ["84053.28000000", "0.04998000"], ["84053.27000000", "0.00000000"], ["84052.29000000", "0.77274000"], ["84052.28000000", "0.91049000"], ["84051.84000000", "0.00000000"], ["84050.40000000", "0.05004000"], ["84050.38000000", "0.00000000"], ["84050.17000000", "0.04498000"], ["84049.83000000", "0.02912000"], ["84049.82000000", "0.00812000"], ["84049.79000000", "0.00000000"], ["84049.68000000", "0.00000000"], ["84049.45000000", "0.04998000"], ["84049.39000000", "0.00000000"], ["84049.26000000", "0.00000000"], ["84049.17000000", "0.00000000"], ["84048.58000000", "0.08696000"], ["84048.52000000", "0.00000000"], ["84047.93000000", "0.08998000"], ["84047.44000000", "0.29572000"], ["84047.43000000", "0.33797000"], ["84047.41000000", "0.00000000"], ["84047.13000000", "0.00000000"], ["84046.18000000", "0.00000000"], ["84045.76000000", "0.19141000"], ["84045.59000000", "0.04498000"], ["84045.25000000", "0.00000000"], ["84044.99000000", "0.00000000"], ["84044.98000000", "0.08996000"], ["84044.26000000", "0.09496000"], ["84043.59000000", "0.04198000"], ["84043.34000000", "0.09638000"], ["84041.86000000", "0.00857000"], ["84041.69000000", "0.00000000"], ["84041.23000000", "0.13994000"], ["84041.22000000", "0.00000000"], ["84041.13000000", "0.00000000"], ["84041.04000000", "0.04198000"], ["84040.78000000", "0.01189000"], ["84040.43000000", "0.19990000"], ["84040.27000000", "0.00060000"], ["84040.00000000", "0.00216000"], ["84039.92000000", "0.00000000"], ["84035.42000000", "0.02423000"], ["84034.45000000", "0.00000000"], ["84034.44000000", "0.00000000"], ["84034.43000000", "0.00000000"], ["84034.38000000", "0.00358000"], ["84033.01000000", "0.00000000"], ["84032.27000000", "0.00000000"], ["84031.41000000", "0.00000000"], ["84030.93000000", "0.94803000"], ["84029.56000000", "0.00826000"], ["84027.37000000", "0.00000000"], ["84026.29000000", "0.00000000"], ["84025.84000000", "0.00000000"], ["84024.31000000", "0.24392000"], ["84023.93000000", "0.00000000"], ["84023.87000000", "0.00000000"], ["84023.21000000", "0.00000000"], ["84023.01000000", "0.00000000"], ["84022.43000000", "0.03226000"], ["84022.31000000", "0.00000000"], ["84021.12000000", "0.12899000"], ["84020.36000000", "0.00000000"], ["84019.89000000", "0.05218000"], ["84018.55000000", "0.00400000"], ["84018.14000000", "0.01196000"], ["84018.06000000", "0.00000000"], ["84017.83000000", "0.57318000"], ["84017.82000000", "1.06404000"], ["84016.94000000", "0.00000000"], ["84013.30000000", "0.00000000"], ["84007.84000000", "0.00000000"], ["84005.78000000", "0.00000000"], ["84005.33000000", "0.00000000"], ["84005.03000000", "0.00000000"], ["84004.53000000", "0.00000000"], ["84004.43000000", "0.00000000"], ["84003.76000000", "0.00100000"], ["84001.80000000", "0.00000000"], ["84000.87000000", "0.00000000"], ["84000.57000000", "0.00000000"], ["83998.04000000", "0.00000000"], ["83993.16000000", "0.00000000"], ["83993.00000000", "1.27221000"], ["83992.54000000", "0.11561000"], ["83989.88000000", "0.00000000"], ["83989.26000000", "0.04756000"], ["83988.99000000", "0.00000000"], ["83988.66000000", "0.42055000"], ["83985.41000000", "0.00000000"], ["83984.06000000", "0.00000000"], ["83983.92000000", "0.00000000"], ["83983.27000000", "0.00083000"], ["83979.99000000", "0.00000000"], ["83977.10000000", "0.05497000"], ["83975.68000000", "0.00000000"], ["83975.56000000", "0.09735000"], ["83975.49000000", "0.00000000"], ["83974.72000000", "0.00000000"], ["83974.33000000", "0.00000000"], ["83974.31000000", "0.05297000"], ["83973.77000000", "0.00000000"], ["83973.48000000", "0.00000000"], ["83973.24000000", "0.00000000"], ["83972.91000000", "0.00000000"], ["83972.56000000", "0.00000000"], ["83972.34000000", "0.00000000"], ["83971.73000000", "0.01353000"], ["83971.67000000", "0.00000000"], ["83971.62000000", "0.00000000"], ["83971.54000000", "0.00000000"], ["83971.40000000", "0.00000000"], ["83971.21000000", "0.05296000"], ["83970.82000000", "0.00119000"], ["83970.52000000", "0.00000000"], ["83970.43000000", "0.00000000"], ["83970.06000000", "0.00000000"], ["83969.92000000", "0.00000000"], ["83969.71000000", "0.00000000"], ["83969.69000000", "0.00000000"], ["83968.26000000", "0.00000000"], ["83968.02000000", "0.00000000"], ["83967.98000000", "0.00000000"], ["83967.75000000", "0.04198000"], ["83967.58000000", "0.05297000"], ["83967.57000000", "0.00000000"], ["83967.56000000", "0.00000000"], ["83967.23000000", "0.00000000"], ["83966.71000000", "0.00000000"], ["83966.47000000", "0.12000000"], ["83966.24000000", "0.00000000"], ["83966.11000000", "0.00000000"], ["83966.05000000", "0.00000000"], ["83966.03000000", "0.04997000"], ["83965.90000000", "0.00000000"], ["83965.28000000", "0.00000000"], ["83965.13000000", "0.00000000"], ["83965.12000000", "0.00000000"], ["83964.59000000", "0.00000000"], ["83963.94000000", "0.00000000"], ["83963.93000000", "0.00000000"], ["83963.50000000", "0.00000000"], ["83963.21000000", "0.00000000"], ["83963.20000000", "0.00000000"], ["83963.17000000", "0.00000000"], ["83963.14000000", "0.00000000"], ["83962.86000000", "0.00000000"], ["83962.71000000", "0.00000000"], ["83962.69000000", "0.00000000"], ["83962.64000000", "0.00000000"], ["83962.56000000", "0.00000000"], ["83962.52000000", "0.00000000"], ["83962.38000000", "0.00000000"], ["83962.23000000", "0.00000000"], ["83961.66000000", "0.00000000"], ["83961.35000000", "0.00000000"], ["83960.96000000", "0.00000000"], ["83960.52000000", "0.00000000"], ["83960.39000000", "0.00000000"], ["83959.99000000", "0.00000000"], ["83959.96000000", "0.00000000"], ["83959.77000000", "0.00000000"], ["83959.75000000", "0.00000000"], ["83959.51000000", "0.00000000"], ["83957.37000000", "0.00000000"], ["83957.35000000", "0.00000000"], ["83957.22000000", "0.00000000"], ["83957.21000000", "0.00000000"], ["83956.91000000", "0.00000000"], ["83956.72000000", "0.00000000"], ["83956.26000000", "0.00000000"], ["83956.02000000", "0.00000000"], ["83955.31000000", "0.00000000"], ["83955.14000000", "0.00000000"], ["83954.55000000", "0.00286000"], ["83954.10000000", "0.00000000"], ["83954.03000000", "0.00000000"], ["83953.98000000", "0.00000000"], ["83953.89000000", "0.00000000"], ["83953.46000000", "0.00000000"], ["83953.40000000", "0.00000000"], ["83952.80000000", "0.00000000"], ["83952.65000000", "0.00000000"], ["83952.62000000", "0.00000000"], ["83951.66000000", "0.00000000"], ["83951.57000000", "0.00000000"], ["83950.94000000", "0.00000000"], ["83950.88000000", "0.00000000"], ["83950.69000000", "0.00006000"], ["83950.28000000", "0.00000000"], ["83950.19000000", "0.00000000"], ["83950.08000000", "0.00000000"], ["83949.75000000", "0.00000000"], ["83949.63000000", "0.00000000"], ["83949.41000000", "0.00000000"], ["83949.39000000", "0.00000000"], ["83949.20000000", "0.00000000"], ["83949.13000000", "0.00000000"], ["83948.90000000", "0.00000000"], ["83948.52000000", "0.00000000"], ["83948.51000000", "0.00000000"], ["83948.12000000", "0.00000000"], ["83945.86000000", "0.00000000"], ["83945.11000000", "0.00000000"], ["83944.28000000", "0.00000000"], ["83942.09000000", "0.00122000"], ["83941.18000000", "0.00000000"], ["83941.03000000", "0.00000000"], ["83939.00000000", "0.00000000"], ["83938.83000000", "0.00000000"], ["83938.18000000", "0.00000000"], ["83938.07000000", "0.01191000"], ["83937.33000000", "0.00000000"], ["83936.63000000", "0.00000000"], ["83932.94000000", "0.00000000"], ["83932.14000000", "0.00000000"], ["83919.71000000", "0.99313000"], ["83911.62000000", "0.00000000"], ["83905.29000000", "0.00000000"], ["83892.00000000", "0.00235000"], ["83871.79000000", "0.00000000"], ["83869.79000000", "0.00000000"], ["83868.49000000", "0.00000000"], ["83866.75000000", "0.00000000"], ["83866.41000000", "0.20120000"], ["83865.71000000", "0.00000000"], ["83864.73000000", "0.00000000"], ["83864.18000000", "0.00000000"], ["83861.39000000", "0.00000000"], ["83860.47000000", "0.00000000"], ["83858.35000000", "0.00000000"], ["83858.00000000", "0.01169000"], ["83857.10000000", "0.00000000"], ["83855.77000000", "0.00000000"], ["83854.64000000", "0.00000000"], ["83854.20000000", "0.00000000"], ["83852.99000000", "0.00000000"], ["83852.90000000", "0.00000000"], ["83852.59000000", "0.00000000"], ["83847.93000000", "0.00000000"], ["83846.24000000", "0.00000000"], ["83845.79000000", "0.00000000"], ["83844.19000000", "0.00000000"], ["83835.80000000", "0.00000000"], ["83736.93000000", "0.00040000"], ["83736.89000000", "0.00000000"], ["83432.65000000", "0.00000000"], ["83160.86000000", "0.40000000"], ["83112.60000000", "0.02346000"], ["83084.28000000", "0.00040000"], ["83084.16000000", "0.00000000"], ["83069.99000000", "0.00000000"], ["82829.08000000", "0.00000000"], ["82350.00000000", "0.29457000"], ["80714.10000000", "0.00000000"], ["75693.85000000", "0.00016000"], ["75693.00000000", "0.00000000"], ["75692.00000000", "0.06625000"], ["75690.00000000", "0.16071000"], ["75683.00000000", "0.04376000"], ["75682.00000000", "0.00000000"], ["75681.00000000", "0.00000000"], ["75636.90000000", "0.00016000"], ["67283.43000000", "0.00058000"], ["67279.77000000", "0.00000000"], ["67272.36000000", "0.00000000"], ["50001.00000000", "1.81907000"], ["42000.00000000", "6.84810000"], ["33000.00000000", "2.93827000"], ["30277.27000000", "0.00260000"]], "a": [["84090.45000000", "0.00000000"], ["84090.46000000", "0.00000000"], ["84090.68000000", "0.00000000"], ["84091.29000000", "0.00000000"], ["84091.30000000", "0.00000000"], ["84091.50000000", "0.00000000"], ["84091.51000000", "0.00000000"], ["84091.52000000", "0.00000000"], ["84091.65000000", "0.00000000"], ["84091.66000000", "0.00000000"], ["84092.29000000", "0.00000000"], ["84092.37000000", "0.00000000"], ["84093.19000000", "0.00000000"], ["84093.20000000", "0.00000000"], ["84093.21000000", "0.00000000"], ["84093.29000000", "0.00000000"], ["84093.30000000", "0.00000000"], ["84093.47000000", "0.00000000"], ["84093.64000000", "0.00000000"], ["84093.67000000", "0.00000000"], ["84093.69000000", "0.00000000"], ["84093.70000000", "0.00000000"], ["84093.74000000", "0.00000000"], ["84093.79000000", "0.00000000"], ["84093.88000000", "0.00000000"], ["84094.04000000", "0.00000000"], ["84094.05000000", "0.00000000"], ["84094.16000000", "0.00000000"], ["84094.17000000", "0.00000000"], ["84094.30000000", "0.00000000"], ["84094.31000000", "0.00000000"], ["84094.42000000", "0.00000000"], ["84094.43000000", "0.00000000"], ["84094.44000000", "0.00000000"], ["84094.56000000", "0.00000000"], ["84094.57000000", "0.00000000"], ["84094.58000000", "0.00000000"], ["84094.90000000", "0.00000000"], ["84094.92000000", "0.00000000"], ["84094.93000000", "0.00000000"], ["84094.97000000", "0.00000000"], ["84095.09000000", "0.00000000"], ["84095.10000000", "0.00000000"], ["84095.11000000", "0.00000000"], ["84095.20000000", "0.00000000"], ["84095.21000000", "0.00000000"], ["84095.22000000", "0.00000000"], ["84095.38000000", "0.00000000"], ["84095.74000000", "0.00000000"], ["84096.00000000", "0.00000000"], ["84096.13000000", "0.00000000"], ["84096.14000000", "0.00000000"], ["84096.22000000", "0.00000000"], ["84096.50000000", "0.00000000"], ["84096.51000000", "0.00000000"], ["84096.57000000", "0.00000000"], ["84096.58000000", "0.00000000"], ["84096.60000000", "0.00000000"], ["84096.67000000", "0.00000000"], ["84096.89000000", "0.00000000"], ["84096.90000000", "0.00000000"], ["84097.09000000", "0.00000000"], ["84097.10000000", "0.00000000"], ["84097.14000000", "0.00000000"], ["84097.37000000", "0.00000000"], ["84097.38000000", "0.00000000"], ["84097.43000000", "0.00000000"], ["84097.45000000", "0.00000000"], ["84097.46000000", "0.00000000"], ["84097.47000000", "0.00000000"], ["84097.60000000", "0.00000000"], ["84097.75000000", "0.00000000"], ["84097.76000000", "0.00000000"], ["84097.89000000", "0.00000000"], ["84098.08000000", "0.00000000"], ["84098.24000000", "0.00000000"], ["84098.25000000", "0.00000000"], ["84098.26000000", "0.00000000"], ["84098.27000000", "0.00000000"], ["84098.29000000", "0.00000000"], ["84098.52000000", "0.00000000"], ["84098.53000000", "0.00000000"], ["84098.71000000", "0.00000000"], ["84098.82000000", "0.00000000"], ["84098.92000000", "0.00000000"], ["84099.17000000", "0.00000000"], ["84099.26000000", "0.00000000"], ["84099.68000000", "0.00000000"], ["84099.71000000", "0.00000000"], ["84099.72000000", "0.00000000"], ["84099.73000000", "0.00000000"], ["84099.92000000", "0.00000000"], ["84099.96000000", "0.00000000"], ["84100.00000000", "0.00000000"], ["84100.12000000", "0.00000000"], ["84100.42000000", "0.00000000"], ["84100.50000000", "0.00000000"], ["84100.69000000", "0.00000000"], ["84100.70000000", "0.00000000"], ["84100.71000000", "0.00000000"], ["84100.72000000", "0.00000000"], ["84100.80000000", "0.00000000"], ["84101.23000000", "0.00000000"], ["84101.29000000", "0.00000000"], ["84101.30000000", "0.00000000"], ["84101.31000000", "0.00000000"], ["84101.54000000", "0.00000000"], ["84101.57000000", "0.00000000"], ["84101.65000000", "0.00000000"], ["84101.71000000", "0.00000000"], ["84101.78000000", "0.00000000"], ["84102.06000000", "0.00000000"], ["84102.22000000", "0.00000000"], ["84102.23000000", "0.00000000"], ["84102.34000000", "0.00000000"], ["84102.51000000", "0.00000000"], ["84102.64000000", "0.00000000"], ["84102.79000000", "0.00000000"], ["84102.81000000", "0.00000000"], ["84102.83000000", "0.00000000"], ["84103.28000000", "0.00000000"], ["84103.29000000", "0.00000000"], ["84103.31000000", "0.00000000"], ["84103.32000000", "0.00000000"], ["84103.34000000", "0.00000000"], ["84103.35000000", "0.00000000"], ["84103.39000000", "0.00000000"], ["84103.40000000", "0.00000000"], ["84103.47000000", "0.00000000"], ["84103.53000000", "0.00000000"], ["84103.54000000", "0.00000000"], ["84103.55000000", "0.00000000"], ["84103.59000000", "0.00000000"], ["84103.63000000", "0.00000000"], ["84103.64000000", "0.00000000"], ["84103.65000000", "0.00000000"], ["84103.74000000", "0.00000000"], ["84103.81000000", "0.00000000"], ["84103.90000000", "0.00000000"], ["84103.91000000", "0.00000000"], ["84103.97000000", "0.00000000"], ["84104.18000000", "0.00000000"], ["84104.22000000", "0.00000000"], ["84104.24000000", "0.00000000"], ["84104.25000000", "0.00000000"], ["84104.26000000", "0.00000000"], ["84104.28000000", "0.00000000"], ["84104.29000000", "0.01049000"], ["84104.30000000", "0.00035000"], ["84104.50000000", "0.00000000"], ["84104.54000000", "0.00000000"], ["84104.60000000", "0.00021000"], ["84104.61000000", "0.00805000"], ["84104.71000000", "0.00000000"], ["84104.74000000", "0.00208000"], ["84104.91000000", "0.00000000"], ["84104.98000000", "0.00000000"], ["84104.99000000", "0.00000000"], ["84105.00000000", "0.00000000"], ["84105.01000000", "0.00013000"], ["84105.02000000", "0.00315000"], ["84105.35000000", "0.00000000"], ["84105.59000000", "0.00000000"], ["84105.74000000", "0.00000000"], ["84105.91000000", "0.00000000"], ["84106.06000000", "0.00000000"], ["84106.08000000", "0.00034000"], ["84106.09000000", "0.00023000"], ["84106.10000000", "0.00300000"], ["84106.16000000", "0.00021000"], ["84106.17000000", "0.02987000"], ["84106.19000000", "0.00000000"], ["84106.31000000", "0.00000000"], ["84106.47000000", "0.00000000"], ["84106.59000000", "0.00000000"], ["84106.65000000", "0.00300000"], ["84106.66000000", "0.00000000"], ["84106.71000000", "0.00007000"], ["84106.84000000", "0.00000000"], ["84107.01000000", "0.00000000"], ["84107.13000000", "0.00000000"], ["84107.14000000", "0.00021000"], ["84107.15000000", "0.02240000"], ["84107.24000000", "0.00000000"], ["84107.30000000", "0.00014000"], ["84107.31000000", "0.01974000"], ["84107.32000000", "0.00000000"], ["84107.33000000", "0.00000000"], ["84107.41000000", "0.00000000"], ["84107.45000000", "0.00000000"], ["84107.49000000", "0.00000000"], ["84107.50000000", "0.00000000"], ["84107.57000000", "0.00000000"], ["84107.59000000", "0.00000000"], ["84107.69000000", "0.00000000"], ["84107.70000000", "0.00500000"], ["84107.83000000", "0.01047000"], ["84107.84000000", "0.00000000"], ["84107.86000000", "0.00000000"], ["84107.87000000", "0.00000000"], ["84107.88000000", "0.00000000"], ["84107.89000000", "0.00000000"], ["84107.94000000", "0.00000000"], ["84107.99000000", "0.00000000"], ["84108.04000000", "0.00000000"], ["84108.11000000", "0.00000000"], ["84108.24000000", "0.00000000"], ["84108.34000000", "0.00000000"], ["84108.40000000", "0.00007000"], ["84108.41000000", "0.00000000"], ["84108.47000000", "0.00007000"], ["84108.49000000", "0.00000000"], ["84108.58000000", "0.00000000"], ["84108.63000000", "0.00000000"], ["84108.69000000", "0.00007000"], ["84108.76000000", "0.00000000"], ["84109.01000000", "0.00000000"], ["84109.20000000", "0.00000000"], ["84109.69000000", "0.00000000"], ["84109.70000000", "0.00000000"], ["84109.76000000", "0.00000000"], ["84109.86000000", "0.00000000"], ["84109.89000000", "0.00118000"], ["84110.04000000", "0.00000000"], ["84110.21000000", "0.00000000"], ["84110.28000000", "0.00000000"], ["84110.43000000", "0.00000000"], ["84110.49000000", "0.00000000"], ["84110.56000000", "0.00000000"], ["84110.67000000", "0.00000000"], ["84110.74000000", "0.00000000"], ["84110.85000000", "0.00000000"], ["84110.91000000", "0.00000000"], ["84110.96000000", "0.14535000"], ["84111.04000000", "0.04195000"], ["84111.20000000", "0.00000000"], ["84111.21000000", "0.00000000"], ["84111.30000000", "0.00000000"], ["84111.35000000", "0.00000000"], ["84111.40000000", "0.00000000"], ["84111.59000000", "0.00000000"], ["84111.63000000", "0.00000000"], ["84111.64000000", "0.00000000"], ["84111.75000000", "0.00000000"], ["84111.76000000", "0.00000000"], ["84111.80000000", "0.00029000"], ["84111.81000000", "0.00000000"], ["84111.95000000", "0.00000000"], ["84112.04000000", "0.00000000"], ["84112.21000000", "0.00000000"], ["84112.29000000", "0.00300000"], ["84112.32000000", "0.00000000"], ["84112.58000000", "0.00000000"], ["84112.70000000", "0.00000000"], ["84112.73000000", "0.02218000"], ["84112.75000000", "0.00000000"], ["84112.82000000", "0.00000000"], ["84112.95000000", "0.00000000"], ["84113.14000000", "0.00000000"], ["84113.19000000", "0.00000000"], ["84113.30000000", "0.00000000"], ["84113.31000000", "0.00000000"], ["84113.33000000", "0.00000000"], ["84113.34000000", "0.00000000"], ["84113.39000000", "0.00000000"], ["84113.41000000", "0.00000000"], ["84113.45000000", "0.00000000"], ["84113.49000000", "0.00000000"], ["84113.51000000", "0.00000000"], ["84113.88000000", "0.00000000"], ["84114.12000000", "0.00000000"], ["84114.16000000", "0.00000000"], ["84114.25000000", "0.00118000"], ["84114.26000000", "0.00000000"], ["84114.44000000", "0.00000000"], ["84114.61000000", "0.00000000"], ["84114.70000000", "0.00000000"], ["84114.73000000", "0.00000000"], ["84115.22000000", "0.00000000"], ["84115.26000000", "0.00000000"], ["84115.34000000", "0.00000000"], ["84115.39000000", "0.00000000"], ["84115.43000000", "0.00000000"], ["84115.60000000", "0.00000000"], ["84115.65000000", "0.00000000"], ["84115.69000000", "0.00000000"], ["84115.74000000", "0.00000000"], ["84115.91000000", "0.00000000"], ["84115.94000000", "0.00000000"], ["84116.11000000", "0.00000000"], ["84116.16000000", "0.40350000"], ["84116.20000000", "0.00000000"], ["84116.26000000", "0.00000000"], ["84116.49000000", "0.00000000"], ["84116.73000000", "0.00000000"], ["84116.84000000", "0.00000000"], ["84117.04000000", "0.00500000"], ["84117.08000000", "0.00000000"], ["84117.17000000", "0.00007000"], ["84117.20000000", "0.00000000"], ["84117.21000000", "0.00500000"], ["84117.23000000", "0.00000000"], ["84117.24000000", "0.01000000"], ["84117.39000000", "0.00000000"], ["84117.41000000", "0.01000000"], ["84117.50000000", "0.00000000"], ["84117.90000000", "0.00000000"], ["84117.91000000", "0.00000000"], ["84117.92000000", "0.00876000"], ["84117.93000000", "0.00000000"], ["84117.94000000", "0.00000000"], ["84117.95000000", "0.00000000"], ["84117.96000000", "0.00000000"], ["84118.24000000", "0.00000000"], ["84118.40000000", "0.00000000"], ["84118.83000000", "0.00000000"], ["84119.16000000", "0.00000000"], ["84119.18000000", "0.00000000"], ["84119.30000000", "0.00000000"], ["84119.57000000", "0.00000000"], ["84119.65000000", "0.00000000"], ["84119.68000000", "0.00000000"], ["84119.80000000", "0.00000000"], ["84119.81000000", "0.00000000"], ["84119.93000000", "0.89155000"], ["84119.95000000", "0.00000000"], ["84120.01000000", "0.04400000"], ["84120.10000000", "0.00000000"], ["84120.12000000", "0.00000000"], ["84120.15000000", "0.00000000"], ["84120.19000000", "0.00094000"], ["84120.21000000", "0.00007000"], ["84120.26000000", "0.00013000"], ["84120.29000000", "0.83793000"], ["84120.30000000", "0.00000000"], ["84120.54000000", "0.00000000"], ["84120.60000000", "0.00000000"], ["84120.70000000", "0.00000000"], ["84120.75000000", "0.00000000"], ["84120.87000000", "0.04400000"], ["84120.95000000", "0.00000000"], ["84121.26000000", "0.00000000"], ["84121.40000000", "0.02000000"], ["84121.56000000", "0.47549000"], ["84121.63000000", "0.01189000"], ["84121.69000000", "0.06800000"], ["84121.70000000", "0.06400000"], ["84121.90000000", "0.12000000"], ["84121.96000000", "0.00000000"], ["84122.16000000", "0.00000000"], ["84122.20000000", "0.00000000"], ["84122.38000000", "0.00000000"], ["84122.40000000", "0.00000000"], ["84122.41000000", "0.00000000"], ["84122.68000000", "0.15019000"], ["84122.74000000", "0.00000000"], ["84123.11000000", "0.00000000"], ["84123.26000000", "0.00000000"], ["84123.44000000", "0.00000000"], ["84123.61000000", "0.00000000"], ["84123.88000000", "0.00000000"], ["84124.44000000", "0.00000000"], ["84124.47000000", "0.00000000"], ["84124.50000000", "1.02411000"], ["84124.72000000", "0.00000000"], ["84124.73000000", "0.00000000"], ["84124.76000000", "0.00000000"], ["84124.94000000", "0.00000000"], ["84125.00000000", "0.01384000"], ["84125.06000000", "0.00000000"], ["84125.19000000", "0.00000000"], ["84125.20000000", "0.02313000"], ["84125.36000000", "0.00000000"], ["84125.38000000", "0.59437000"], ["84125.54000000", "0.00000000"], ["84125.66000000", "0.02372000"], ["84125.72000000", "0.00000000"], ["84125.79000000", "0.14637000"], ["84125.90000000", "0.06000000"], ["84125.91000000", "0.05600000"], ["84125.97000000", "0.08000000"], ["84125.99000000", "0.00000000"], ["84126.00000000", "0.00006000"], ["84126.07000000", "0.89155000"], ["84126.15000000", "0.00000000"], ["84126.54000000", "0.00306000"], ["84126.55000000", "0.00505000"], ["84126.74000000", "0.00000000"], ["84126.78000000", "0.00000000"], ["84126.94000000", "0.00090000"], ["84127.11000000", "0.35662000"], ["84127.43000000", "0.00000000"], ["84127.47000000", "0.00000000"], ["84127.56000000", "0.00000000"], ["84127.81000000", "0.00000000"], ["84127.84000000", "0.00000000"], ["84127.97000000", "0.89155000"], ["84128.20000000", "0.00000000"], ["84128.21000000", "0.00000000"], ["84128.28000000", "0.00000000"], ["84128.40000000", "0.00000000"], ["84128.51000000", "0.00000000"], ["84128.52000000", "0.05943000"], ["84128.57000000", "0.00000000"], ["84128.60000000", "0.00000000"], ["84128.65000000", "1.21365000"], ["84128.66000000", "0.00000000"], ["84128.92000000", "0.00459000"], ["84129.17000000", "0.00000000"], ["84129.37000000", "0.00000000"], ["84130.00000000", "0.04000000"], ["84130.07000000", "0.00000000"], ["84130.12000000", "0.00000000"], ["84130.26000000", "0.00000000"], ["84130.29000000", "0.00101000"], ["84130.57000000", "0.01189000"], ["84130.84000000", "0.00000000"], ["84130.89000000", "1.42394000"], ["84130.92000000", "0.30865000"], ["84131.07000000", "0.16000000"], ["84131.23000000", "0.00604000"], ["84131.24000000", "0.00000000"], ["84131.51000000", "0.00000000"], ["84131.74000000", "0.00000000"], ["84132.05000000", "0.00151000"], ["84132.11000000", "0.00000000"], ["84132.12000000", "0.00000000"], ["84132.31000000", "0.00000000"], ["84132.35000000", "0.00000000"], ["84132.41000000", "0.00000000"], ["84132.53000000", "0.00000000"], ["84132.55000000", "0.89155000"], ["84132.59000000", "0.00000000"], ["84132.72000000", "0.05943000"], ["84132.86000000", "0.00000000"], ["84133.02000000", "0.00000000"], ["84133.45000000", "0.00237000"], ["84133.47000000", "0.30492000"], ["84133.48000000", "0.00000000"], ["84133.52000000", "1.05723000"], ["84133.79000000", "0.00000000"], ["84134.05000000", "0.00000000"], ["84134.27000000", "0.00000000"], ["84134.30000000", "0.00000000"], ["84134.43000000", "0.89155000"], ["84134.99000000", "0.00000000"], ["84135.23000000", "0.00000000"], ["84135.40000000", "0.89155000"], ["84136.22000000", "0.00000000"], ["84136.25000000", "0.00000000"], ["84136.36000000", "0.00000000"], ["84136.94000000", "0.00000000"], ["84137.37000000", "0.00000000"], ["84137.92000000", "0.00000000"], ["84138.60000000", "0.00006000"], ["84138.64000000", "0.00000000"], ["84138.85000000", "0.00000000"], ["84139.29000000", "0.00000000"], ["84139.84000000", "0.02503000"], ["84140.26000000", "0.89155000"], ["84140.30000000", "0.00000000"], ["84140.59000000", "0.00000000"], ["84140.65000000", "0.02814000"], ["84140.72000000", "0.00000000"], ["84141.02000000", "0.00351000"], ["84141.03000000", "0.00000000"], ["84141.32000000", "1.20438000"], ["84141.89000000", "0.00000000"], ["84142.00000000", "0.00000000"], ["84142.07000000", "0.00000000"], ["84142.09000000", "0.00016000"], ["84142.14000000", "0.89155000"], ["84142.27000000", "0.00000000"], ["84142.38000000", "0.11604000"], ["84142.40000000", "0.89155000"], ["84142.42000000", "0.00000000"], ["84143.25000000", "0.00000000"], ["84143.89000000", "0.00000000"], ["84144.18000000", "0.39078000"], ["84144.46000000", "0.89155000"], ["84144.47000000", "0.00000000"], ["84144.61000000", "0.00000000"], ["84144.68000000", "0.00000000"], ["84145.37000000", "0.00000000"], ["84146.10000000", "0.00000000"], ["84146.63000000", "0.03676000"], ["84147.08000000", "0.00000000"], ["84147.13000000", "0.23668000"], ["84147.92000000", "0.00578000"], ["84147.97000000", "0.00000000"], ["84148.76000000", "0.00000000"], ["84149.01000000", "0.35739000"], ["84149.66000000", "0.37690000"], ["84149.77000000", "0.00000000"], ["84150.15000000", "0.85602000"], ["84150.40000000", "0.00000000"], ["84150.50000000", "0.00000000"], ["84150.84000000", "0.00000000"], ["84151.50000000", "0.00000000"], ["84151.64000000", "0.00000000"], ["84153.47000000", "0.00100000"], ["84154.38000000", "0.85598000"], ["84154.43000000", "0.00000000"], ["84154.54000000", "0.59437000"], ["84154.63000000", "0.74202000"], ["84155.36000000", "0.00000000"], ["84156.16000000", "0.00000000"], ["84156.17000000", "0.47549000"], ["84157.86000000", "0.00000000"], ["84157.96000000", "0.35662000"], ["84158.64000000", "0.30492000"], ["84158.66000000", "0.30601000"], ["84158.73000000", "0.00000000"], ["84158.83000000", "0.58484000"], ["84159.37000000", "0.85593000"], ["84159.67000000", "0.01196000"], ["84160.33000000", "0.00000000"], ["84161.13000000", "0.00000000"], ["84161.49000000", "0.00000000"], ["84161.72000000", "0.59463000"], ["84161.73000000", "0.00000000"], ["84163.35000000", "0.00851000"], ["84163.69000000", "0.00000000"], ["84164.06000000", "0.00000000"], ["84164.07000000", "0.00000000"], ["84164.89000000", "0.00000000"], ["84165.49000000", "0.00000000"], ["84165.50000000", "0.00699000"], ["84165.56000000", "0.00812000"], ["84166.11000000", "0.00000000"], ["84166.46000000", "0.00013000"], ["84166.86000000", "0.02912000"], ["84166.96000000", "0.05358000"], ["84167.74000000", "0.00000000"], ["84167.75000000", "0.00000000"], ["84167.99000000", "0.00000000"], ["84168.09000000", "0.00000000"], ["84168.72000000", "0.00000000"], ["84168.76000000", "0.00000000"], ["84169.04000000", "0.06800000"], ["84169.21000000", "0.00000000"], ["84169.63000000", "0.00000000"], ["84170.16000000", "0.00297000"], ["84170.40000000", "0.01788000"], ["84170.41000000", "0.00000000"], ["84170.49000000", "0.00000000"], ["84170.89000000", "0.48812000"], ["84171.02000000", "0.00000000"], ["84171.86000000", "0.00000000"], ["84171.99000000", "0.00000000"], ["84173.35000000", "0.00000000"], ["84173.36000000", "0.00000000"], ["84173.51000000", "1.02646000"], ["84173.70000000", "0.00000000"], ["84173.81000000", "0.05600000"], ["84174.53000000", "0.00000000"], ["84174.66000000", "0.06000000"], ["84175.09000000", "0.06400000"], ["84175.10000000", "0.00000000"], ["84175.89000000", "0.00000000"], ["84175.97000000", "0.04371000"], ["84176.12000000", "0.05600000"], ["84176.39000000", "0.00000000"], ["84176.51000000", "0.00000000"], ["84178.19000000", "0.00000000"], ["84178.55000000", "0.00000000"], ["84179.51000000", "0.00000000"], ["84180.35000000", "0.00000000"], ["84180.70000000", "0.00699000"], ["84180.77000000", "0.00000000"], ["84181.18000000", "0.00019000"], ["84181.19000000", "0.04400000"], ["84181.78000000", "0.04756000"], ["84182.22000000", "0.04297000"], ["84182.78000000", "0.00000000"], ["84183.05000000", "0.03971000"], ["84183.79000000", "0.03226000"], ["84183.83000000", "0.00000000"], ["84183.98000000", "0.04800000"], ["84185.18000000", "0.00000000"], ["84185.46000000", "0.00000000"], ["84185.75000000", "0.00000000"], ["84186.62000000", "0.00000000"], ["84187.58000000", "0.00151000"], ["84187.99000000", "0.00297000"], ["84188.19000000", "0.00000000"], ["84188.22000000", "0.00143000"], ["84188.48000000", "0.00000000"], ["84188.62000000", "0.00000000"], ["84189.44000000", "0.00000000"], ["84189.74000000", "0.00000000"], ["84189.86000000", "0.00000000"], ["84191.91000000", "0.00000000"], ["84192.53000000", "0.00000000"], ["84192.66000000", "0.00000000"], ["84193.00000000", "0.00009000"], ["84193.20000000", "0.00006000"], ["84193.89000000", "0.00000000"], ["84193.97000000", "0.00000000"], ["84194.25000000", "0.00938000"], ["84195.11000000", "0.00000000"], ["84195.53000000", "0.05179000"], ["84195.88000000", "0.00000000"], ["84196.30000000", "0.00000000"], ["84196.32000000", "0.00000000"], ["84196.62000000", "0.00000000"], ["84197.56000000", "0.00000000"], ["84197.79000000", "0.00000000"], ["84197.91000000", "0.00000000"], ["84197.94000000", "0.00000000"], ["84198.18000000", "0.00000000"], ["84198.56000000", "0.00000000"], ["84198.63000000", "0.00000000"], ["84198.76000000", "0.04755000"], ["84199.02000000", "0.00000000"], ["84199.23000000", "0.09621000"], ["84199.53000000", "0.00000000"], ["84200.16000000", "0.00000000"], ["84200.45000000", "0.00059000"], ["84200.74000000", "0.00000000"], ["84201.14000000", "0.00000000"], ["84201.40000000", "0.00000000"], ["84201.43000000", "0.00000000"], ["84202.05000000", "0.00000000"], ["84202.31000000", "0.00000000"], ["84202.39000000", "0.00000000"], ["84202.47000000", "0.00000000"], ["84203.42000000", "0.00000000"], ["84203.55000000", "0.00000000"], ["84204.36000000", "0.00000000"], ["84204.88000000", "0.00000000"], ["84205.33000000", "0.00000000"], ["84205.60000000", "0.04637000"], ["84205.91000000", "0.10319000"], ["84206.44000000", "0.00000000"], ["84206.70000000", "0.00000000"], ["84206.73000000", "0.04756000"], ["84207.39000000", "0.00000000"], ["84207.47000000", "0.00000000"], ["84208.12000000", "0.04637000"], ["84208.52000000", "0.00000000"], ["84208.58000000", "0.00000000"], ["84208.72000000", "0.00000000"], ["84208.87000000", "0.00000000"], ["84208.88000000", "0.00000000"], ["84208.99000000", "0.04637000"], ["84209.19000000", "0.00000000"], ["84209.62000000", "0.00000000"], ["84209.80000000", "0.00000000"], ["84210.26000000", "0.04637000"], ["84211.16000000", "0.00000000"], ["84211.39000000", "0.00000000"], ["84211.94000000", "0.00000000"], ["84212.24000000", "0.12900000"], ["84212.28000000", "0.04637000"], ["84212.46000000", "0.12000000"], ["84212.85000000", "0.05297000"], ["84212.89000000", "0.00000000"], ["84213.11000000", "0.04756000"], ["84213.26000000", "0.00013000"], ["84213.75000000", "0.05497000"], ["84213.96000000", "0.00000000"], ["84214.04000000", "0.00000000"], ["84214.90000000", "0.07650000"], ["84215.10000000", "0.05497000"], ["84215.29000000", "0.00000000"], ["84216.10000000", "0.04756000"], ["84216.56000000", "0.12899000"], ["84216.93000000", "0.06257000"], ["84217.13000000", "0.05497000"], ["84217.23000000", "0.00000000"], ["84217.52000000", "0.00000000"], ["84217.78000000", "0.00000000"], ["84217.90000000", "0.00000000"], ["84218.45000000", "0.05497000"], ["84219.36000000", "0.05497000"], ["84219.79000000", "0.04998000"], ["84220.38000000", "0.12306000"], ["84220.49000000", "0.02186000"], ["84221.01000000", "0.05498000"], ["84221.43000000", "0.05497000"], ["84221.47000000", "0.11868000"], ["84221.68000000", "0.05497000"], ["84221.95000000", "0.05497000"], ["84223.74000000", "0.02010000"], ["84223.90000000", "0.05498000"], ["84224.33000000", "0.05497000"], ["84224.71000000", "0.05497000"], ["84225.03000000", "0.05497000"], ["84225.19000000", "0.05497000"], ["84225.22000000", "0.05497000"], ["84225.47000000", "0.05497000"], ["84225.66000000", "0.04998000"], ["84226.09000000", "0.05498000"], ["84226.14000000", "0.00813000"], ["84226.53000000", "0.05297000"], ["84226.70000000", "0.05097000"], ["84226.90000000", "0.05297000"], ["84227.08000000", "0.00000000"], ["84227.96000000", "0.05498000"], ["84229.46000000", "0.05497000"], ["84229.52000000", "0.00000000"], ["84229.57000000", "0.04998000"], ["84229.65000000", "0.04998000"], ["84229.77000000", "0.06595000"], ["84229.92000000", "0.05297000"], ["84229.98000000", "0.10794000"], ["84231.33000000", "0.05498000"], ["84231.71000000", "0.04998000"], ["84231.74000000", "0.00000000"], ["84232.05000000", "0.05010000"], ["84232.89000000", "0.05497000"], ["84232.95000000", "0.04997000"], ["84233.39000000", "0.04998000"], ["84233.71000000", "0.00000000"], ["84234.32000000", "0.05098000"], ["84234.42000000", "0.05498000"], ["84234.54000000", "0.00000000"], ["84235.61000000", "0.05498000"], ["84235.65000000", "0.01840000"], ["84236.62000000", "0.04498000"], ["84237.40000000", "0.05098000"], ["84237.41000000", "0.04498000"], ["84237.51000000", "0.04498000"], ["84237.67000000", "0.04998000"], ["84237.90000000", "0.05498000"], ["84238.02000000", "0.00000000"], ["84238.15000000", "0.05498000"], ["84238.71000000", "0.00000000"], ["84238.99000000", "0.04998000"], ["84239.32000000", "0.05497000"], ["84239.65000000", "0.05298000"], ["84239.74000000", "0.05297000"], ["84239.95000000", "0.05297000"], ["84240.31000000", "0.05098000"], ["84240.69000000", "0.05498000"], ["84240.92000000", "0.04498000"], ["84241.26000000", "0.05498000"], ["84241.56000000", "0.05498000"], ["84241.83000000", "0.02497000"], ["84241.95000000", "0.02497000"], ["84242.08000000", "0.05098000"], ["84242.20000000", "0.04998000"], ["84242.48000000", "0.05298000"], ["84242.66000000", "0.05098000"], ["84242.73000000", "0.05298000"], ["84243.20000000", "0.04998000"], ["84243.39000000", "0.05498000"], ["84243.91000000", "0.05498000"], ["84244.04000000", "0.05498000"], ["84244.48000000", "0.04498000"], ["84244.76000000", "0.05298000"], ["84244.88000000", "0.04998000"], ["84244.99000000", "0.04498000"], ["84245.16000000", "0.00000000"], ["84245.17000000", "0.00000000"], ["84245.38000000", "0.10602000"], ["84245.98000000", "0.00000000"], ["84246.53000000", "0.04998000"], ["84248.68000000", "0.00000000"], ["84249.42000000", "0.04498000"], ["84249.52000000", "0.04498000"], ["84250.43000000", "0.00006000"], ["84250.55000000", "0.04198000"], ["84250.59000000", "0.04198000"], ["84250.64000000", "0.04498000"], ["84250.83000000", "0.00000000"], ["84251.40000000", "0.00006000"], ["84251.99000000", "0.04498000"], ["84255.49000000", "0.00000000"], ["84259.31000000", "0.00016000"], ["84259.32000000", "0.00118000"], ["84259.33000000", "0.00000000"], ["84262.47000000", "0.04198000"], ["84263.95000000", "0.00006000"], ["84263.99000000", "0.00000000"], ["84264.17000000", "0.00000000"], ["84266.60000000", "0.00000000"], ["84272.23000000", "0.03174000"], ["84272.49000000", "0.01176000"], ["84274.27000000", "0.00000000"], ["84274.87000000", "0.00000000"], ["84279.19000000", "0.00000000"], ["84281.25000000", "0.00000000"], ["84281.26000000", "0.00000000"], ["84329.64000000", "0.00118000"], ["84329.65000000", "0.00013000"], ["84333.85000000", "0.00013000"], ["84338.63000000", "0.00013000"], ["84342.83000000", "0.00013000"], ["84347.18000000", "0.00013000"], ["84351.38000000", "0.00013000"], ["84365.53000000", "0.13146000"], ["84370.23000000", "0.00000000"], ["84370.99000000", "0.06978000"], ["84375.13000000", "0.45000000"], ["84376.25000000", "0.20120000"], ["84379.39000000", "0.00000000"], ["84381.36000000", "0.20120000"], ["84383.54000000", "0.45000000"], ["84385.72000000", "0.20120000"], ["84394.13000000", "0.00168000"], ["84420.00000000", "0.03370000"], ["84458.39000000", "0.00000000"], ["84739.20000000", "0.00006000"], ["84772.80000000", "0.05953000"], ["85201.42000000", "0.60000000"], ["85333.92000000", "0.00000000"], ["85365.10000000", "0.00100000"], ["85370.40000000", "0.01467000"], ["85385.14000000", "0.10000000"], ["85391.70000000", "0.11736000"], ["85413.00000000", "0.00036000"], ["150001.00000000", "0.00000000"]], "record_time": 1742584924.129844, "EXCHANGE": "BINANCE"}
{"e": "depthUpdate", "E": 1742584925014, "s": "BTCUSDT", "U": 64637919942, "u": 64637921671, "b": [["84108.69000000", "8.04867000"], ["84108.68000000", "0.01047000"], ["84108.59000000", "0.00007000"], ["84108.54000000", "0.00021000"], ["84108.53000000", "1.58971000"], ["84108.52000000", "0.00007000"], ["84108.51000000", "0.00007000"], ["84108.50000000", "0.00007000"], ["84108.49000000", "0.00000000"], ["84108.48000000", "0.00000000"], ["84108.47000000", "1.54690000"], ["84108.46000000", "0.00000000"], ["84108.41000000", "0.00000000"], ["84108.31000000", "0.00000000"], ["84108.00000000", "0.02266000"], ["84107.89000000", "0.00000000"], ["84107.83000000", "0.02383000"], ["84107.82000000", "0.00000000"], ["84107.69000000", "0.00000000"], ["84107.54000000", "0.00000000"], ["84107.31000000", "0.00000000"], ["84107.30000000", "0.00000000"], ["84107.29000000", "0.00000000"], ["84107.02000000", "0.01188000"], ["84106.72000000", "0.00007000"], ["84106.70000000", "0.00000000"], ["84106.64000000", "0.00000000"], ["84106.63000000", "0.00000000"], ["84106.17000000", "0.00000000"], ["84106.16000000", "0.71095000"], ["84106.15000000", "0.00000000"], ["84106.09000000", "0.00000000"], ["84106.08000000", "0.00000000"], ["84106.07000000", "0.00000000"], ["84106.01000000", "0.00000000"], ["84106.00000000", "0.02266000"], ["84105.05000000", "0.00000000"], ["84105.03000000", "0.00033000"], ["84105.02000000", "0.00000000"], ["84105.01000000", "0.00000000"], ["84105.00000000", "0.00000000"], ["84104.86000000", "0.02544000"], ["84104.73000000", "0.00000000"], ["84104.72000000", "0.00000000"], ["84104.71000000", "0.00000000"], ["84104.65000000", "0.00000000"], ["84104.64000000", "0.00000000"], ["84104.63000000", "0.00000000"], ["84104.62000000", "0.00000000"], ["84104.61000000", "0.00000000"], ["84104.60000000", "0.03594000"], ["84104.59000000", "0.00000000"], ["84104.49000000", "0.00000000"], ["84104.45000000", "0.00202000"], ["84104.31000000", "0.00000000"], ["84104.30000000", "0.00000000"], ["84104.29000000", "0.00000000"], ["84104.28000000", "0.00032000"], ["84104.27000000", "0.00000000"], ["84104.19000000", "0.00000000"], ["84104.18000000", "0.00000000"], ["84104.17000000", "0.08574000"], ["84104.13000000", "0.35968000"], ["84104.00000000", "0.02260000"], ["84103.70000000", "0.00000000"], ["84103.54000000", "0.17899000"], ["84103.53000000", "0.29416000"], ["84103.52000000", "0.00000000"], ["84103.41000000", "0.02377000"], ["84103.28000000", "0.03578000"], ["84103.05000000", "0.14352000"], ["84102.55000000", "0.00000000"], ["84102.28000000", "0.00000000"], ["84102.27000000", "0.04000000"], ["84102.22000000", "0.00000000"], ["84102.21000000", "0.04996000"], ["84102.10000000", "0.00000000"], ["84102.00000000", "0.02260000"], ["84101.97000000", "0.01189000"], ["84101.86000000", "0.00000000"], ["84101.80000000", "0.03578000"], ["84101.30000000", "0.36194000"], ["84101.29000000", "0.03578000"], ["84100.99000000", "0.00000000"], ["84100.97000000", "0.00118000"], ["84100.90000000", "0.00500000"], ["84100.80000000", "0.00006000"], ["84100.70000000", "0.00000000"], ["84100.27000000", "0.00300000"], ["84100.06000000", "0.00009000"], ["84099.92000000", "0.00000000"], ["84099.71000000", "0.45000000"], ["84099.68000000", "0.00013000"], ["84099.44000000", "0.00000000"], ["84098.93000000", "0.00006000"], ["84098.38000000", "0.00594000"], ["84098.29000000", "0.00000000"], ["84098.26000000", "0.58547000"], ["84098.19000000", "0.00013000"], ["84098.00000000", "0.14148000"], ["84097.90000000", "0.05944000"], ["84097.54000000", "0.12484000"], ["84097.23000000", "0.00000000"], ["84097.10000000", "0.85656000"], ["84097.05000000", "0.35662000"], ["84096.81000000", "0.00000000"], ["84096.21000000", "0.02377000"], ["84096.08000000", "0.01189000"], ["84095.84000000", "0.02377000"], ["84095.66000000", "0.00013000"], ["84094.62000000", "0.00000000"], ["84093.93000000", "0.00922000"], ["84093.89000000", "0.00006000"], ["84093.55000000", "0.00000000"], ["84093.53000000", "0.47549000"], ["84093.19000000", "0.00000000"], ["84092.64000000", "0.05943000"], ["84090.93000000", "0.59465000"], ["84090.92000000", "0.00000000"], ["84090.46000000", "0.64922000"], ["84090.45000000", "0.00056000"], ["84090.33000000", "1.00000000"], ["84089.90000000", "0.00013000"], ["84089.42000000", "0.00307000"], ["84089.34000000", "0.00059000"], ["84089.17000000", "0.00000000"], ["84088.84000000", "0.00006000"], ["84088.38000000", "0.00000000"], ["84087.41000000", "1.37141000"], ["84086.78000000", "0.00000000"], ["84086.50000000", "0.00000000"], ["84086.14000000", "1.79934000"], ["84086.00000000", "0.00000000"], ["84085.98000000", "0.00000000"], ["84085.80000000", "0.00000000"], ["84085.09000000", "0.00000000"], ["84084.46000000", "0.00000000"], ["84084.33000000", "0.00000000"], ["84084.10000000", "0.00000000"], ["84084.00000000", "0.00006000"], ["84082.44000000", "0.85671000"], ["84081.83000000", "0.20087000"], ["84081.57000000", "0.00000000"], ["84081.54000000", "0.00000000"], ["84081.20000000", "0.04000000"], ["84080.97000000", "0.56579000"], ["84080.94000000", "0.00059000"], ["84080.38000000", "0.04000000"], ["84079.53000000", "0.04000000"], ["84079.46000000", "0.04000000"], ["84078.78000000", "0.00000000"], ["84078.53000000", "0.05944000"], ["84077.75000000", "0.00000000"], ["84077.00000000", "0.12992000"], ["84076.16000000", "0.04000000"], ["84076.03000000", "0.05944000"], ["84075.91000000", "0.23688000"], ["84075.75000000", "0.00594000"], ["84075.25000000", "0.04000000"], ["84071.26000000", "0.00000000"], ["84070.54000000", "0.00000000"], ["84066.77000000", "0.05796000"], ["84066.64000000", "0.00059000"], ["84062.23000000", "0.00000000"], ["84061.83000000", "0.00000000"], ["84058.27000000", "0.16915000"], ["84056.96000000", "0.00000000"], ["84056.63000000", "0.00000000"], ["84056.48000000", "0.00000000"], ["84055.68000000", "0.47549000"], ["84054.85000000", "0.00300000"], ["84050.86000000", "0.00825000"], ["84047.44000000", "0.48541000"], ["84045.70000000", "0.43864000"], ["84044.26000000", "0.09196000"], ["84042.33000000", "0.00000000"], ["84035.46000000", "0.00145000"], ["84035.41000000", "0.00000000"], ["84032.94000000", "0.00000000"], ["84026.81000000", "0.00000000"], ["84026.29000000", "0.00000000"], ["84026.28000000", "0.00000000"], ["84024.41000000", "0.00000000"], ["84024.31000000", "0.10345000"], ["84024.30000000", "0.00000000"], ["84023.21000000", "0.00000000"], ["84022.09000000", "0.00000000"], ["84021.16000000", "0.00000000"], ["84020.84000000", "0.00000000"], ["84020.00000000", "0.00327000"], ["84019.90000000", "0.10319000"], ["84019.01000000", "0.00000000"], ["84018.55000000", "0.00000000"], ["84018.12000000", "0.00400000"], ["84017.78000000", "0.00000000"], ["84008.92000000", "0.00000000"], ["84000.62000000", "0.00000000"], ["84000.55000000", "0.22368000"], ["83996.44000000", "0.20545000"], ["83993.00000000", "0.38480000"], ["83991.07000000", "0.00000000"], ["83988.66000000", "0.00000000"], ["83986.10000000", "0.00000000"], ["83966.38000000", "0.05947000"], ["83961.73000000", "0.99313000"], ["83951.91000000", "0.01000000"], ["83951.90000000", "0.00000000"], ["83950.69000000", "0.00000000"], ["83949.60000000", "0.00006000"], ["83919.71000000", "0.00000000"], ["83898.08000000", "0.01783000"], ["83882.75000000", "0.00000000"], ["83879.99000000", "0.20087000"], ["83876.31000000", "0.00000000"], ["83871.58000000", "0.20087000"], ["83867.96000000", "0.00000000"], ["83866.41000000", "0.00000000"], ["83865.70000000", "0.00000000"], ["83863.56000000", "0.00000000"], ["83863.17000000", "0.01537000"], ["83862.62000000", "0.00000000"], ["83861.30000000", "0.00000000"], ["83858.00000000", "0.00000000"], ["83263.55000000", "0.00000000"], ["82847.05000000", "0.00110000"], ["80730.96000000", "0.03565000"], ["75697.82000000", "0.00016000"], ["75697.00000000", "0.00020000"], ["75695.00000000", "0.00241000"], ["75693.00000000", "0.00000000"], ["75692.00000000", "0.06605000"], ["75636.90000000", "0.00000000"], ["67286.96000000", "0.00058000"], ["67284.93000000", "0.00000000"], ["67283.43000000", "0.00000000"], ["60000.00000000", "73.01913000"], ["50001.00000000", "1.81977000"], ["42000.00000000", "6.84710000"], ["33000.00000000", "2.93827000"], ["30278.22000000", "0.00020000"], ["30277.66000000", "0.00020000"], ["30277.54000000", "0.00040000"], ["20002.00000000", "0.00000000"], ["20001.00000000", "0.02099000"]], "a": [["84104.29000000", "0.00000000"], ["84104.30000000", "0.00000000"], ["84104.60000000", "0.00000000"], ["84104.61000000", "0.00000000"], ["84104.62000000", "0.00000000"], ["84104.74000000", "0.00000000"], ["84105.01000000", "0.00000000"], ["84105.02000000", "0.00000000"], ["84105.06000000", "0.00000000"], ["84106.08000000", "0.00000000"], ["84106.09000000", "0.00000000"], ["84106.10000000", "0.00000000"], ["84106.16000000", "0.00000000"], ["84106.17000000", "0.00000000"], ["84106.18000000", "0.00000000"], ["84106.64000000", "0.00000000"], ["84106.65000000", "0.00000000"], ["84106.71000000", "0.00000000"], ["84107.14000000", "0.00000000"], ["84107.15000000", "0.00000000"], ["84107.30000000", "0.00000000"], ["84107.31000000", "0.00000000"], ["84107.55000000", "0.00000000"], ["84107.70000000", "0.00000000"], ["84107.82000000", "0.00000000"], ["84107.83000000", "0.00000000"], ["84107.89000000", "0.00000000"], ["84107.90000000", "0.00000000"], ["84108.21000000", "0.00000000"], ["84108.22000000", "0.00000000"], ["84108.32000000", "0.00000000"], ["84108.40000000", "0.00000000"], ["84108.47000000", "0.00000000"], ["84108.48000000", "0.00000000"], ["84108.69000000", "0.00000000"], ["84108.70000000", "0.08118000"], ["84108.71000000", "0.00060000"], ["84109.17000000", "0.00048000"], ["84109.18000000", "0.01383000"], ["84109.24000000", "0.00007000"], ["84109.59000000", "0.00013000"], ["84109.60000000", "0.00027000"], ["84109.61000000", "0.01911000"], ["84109.65000000", "0.00008000"], ["84109.77000000", "0.00000000"], ["84109.78000000", "0.00000000"], ["84109.79000000", "0.00014000"], ["84109.80000000", "0.01113000"], ["84109.89000000", "0.00000000"], ["84110.09000000", "0.00007000"], ["84110.23000000", "0.00007000"], ["84110.24000000", "0.00000000"], ["84110.52000000", "0.00014000"], ["84110.53000000", "0.35798000"], ["84110.95000000", "0.16998000"], ["84110.96000000", "0.00000000"], ["84111.04000000", "0.00000000"], ["84111.51000000", "0.00006000"], ["84111.52000000", "0.00000000"], ["84112.08000000", "0.00010000"], ["84112.09000000", "0.02227000"], ["84112.23000000", "0.00020000"], ["84112.24000000", "0.02017000"], ["84112.30000000", "0.00000000"], ["84112.72000000", "0.00016000"], ["84112.73000000", "0.07204000"], ["84112.90000000", "0.00314000"], ["84113.06000000", "0.00000000"], ["84113.40000000", "0.00000000"], ["84113.63000000", "0.02205000"], ["84114.12000000", "0.00000000"], ["84114.13000000", "0.00000000"], ["84114.78000000", "0.00000000"], ["84115.07000000", "0.00000000"], ["84115.72000000", "0.13541000"], ["84117.60000000", "0.02487000"], ["84119.07000000", "0.00000000"], ["84119.45000000", "0.00000000"], ["84120.01000000", "0.00000000"], ["84120.21000000", "0.00000000"], ["84120.29000000", "0.60906000"], ["84120.69000000", "0.00000000"], ["84120.87000000", "0.00000000"], ["84121.17000000", "0.78495000"], ["84121.69000000", "0.00000000"], ["84121.70000000", "0.00000000"], ["84121.99000000", "0.00000000"], ["84122.27000000", "0.00000000"], ["84122.99000000", "0.00059000"], ["84124.26000000", "0.10602000"], ["84124.43000000", "0.00000000"], ["84124.57000000", "0.04400000"], ["84124.61000000", "0.00000000"], ["84125.35000000", "0.00000000"], ["84125.38000000", "0.63837000"], ["84125.57000000", "0.00000000"], ["84125.66000000", "0.00000000"], ["84125.90000000", "0.00000000"], ["84125.91000000", "0.00000000"], ["84125.97000000", "0.00000000"], ["84126.22000000", "0.06400000"], ["84126.29000000", "0.04800000"], ["84126.55000000", "0.00000000"], ["84127.62000000", "0.00000000"], ["84128.65000000", "0.85209000"], ["84129.18000000", "0.02324000"], ["84129.33000000", "0.15168000"], ["84129.61000000", "0.05600000"], ["84129.84000000", "0.00000000"], ["84130.29000000", "0.00000000"], ["84130.42000000", "0.05600000"], ["84130.47000000", "0.06100000"], ["84130.49000000", "0.08000000"], ["84130.70000000", "0.00720000"], ["84130.89000000", "0.00000000"], ["84131.36000000", "0.00000000"], ["84131.40000000", "0.00059000"], ["84131.71000000", "0.00506000"], ["84132.05000000", "0.00000000"], ["84132.92000000", "0.00000000"], ["84133.65000000", "0.30601000"], ["84133.71000000", "0.11886000"], ["84133.94000000", "0.00300000"], ["84135.45000000", "0.00100000"], ["84136.07000000", "0.00593000"], ["84137.01000000", "0.00151000"], ["84137.66000000", "0.82082000"], ["84137.92000000", "0.00031000"], ["84138.28000000", "0.00000000"], ["84139.01000000", "0.89155000"], ["84139.11000000", "0.00000000"], ["84139.25000000", "1.36084000"], ["84141.90000000", "0.00539000"], ["84144.73000000", "0.85607000"], ["84145.51000000", "0.00000000"], ["84146.11000000", "0.00000000"], ["84146.35000000", "0.00000000"], ["84147.13000000", "0.00000000"], ["84149.99000000", "0.47958000"], ["84150.76000000", "0.00059000"], ["84154.78000000", "0.00000000"], ["84158.64000000", "0.00000000"], ["84158.66000000", "0.00000000"], ["84159.61000000", "0.05000000"], ["84160.42000000", "0.00000000"], ["84164.59000000", "0.00899000"], ["84168.25000000", "0.00000000"], ["84170.16000000", "0.00000000"], ["84177.49000000", "0.00297000"], ["84180.35000000", "0.04400000"], ["84180.96000000", "0.00000000"], ["84181.77000000", "0.00999000"], ["84188.19000000", "0.08000000"], ["84189.60000000", "0.47312000"], ["84191.06000000", "0.01304000"], ["84194.71000000", "0.00000000"], ["84194.76000000", "0.01819000"], ["84194.85000000", "0.00006000"], ["84195.70000000", "0.00000000"], ["84196.13000000", "0.00000000"], ["84197.17000000", "0.00000000"], ["84200.45000000", "0.00000000"], ["84200.73000000", "0.00000000"], ["84210.60000000", "0.00059000"], ["84225.88000000", "0.00013000"], ["84225.93000000", "0.00893000"], ["84235.57000000", "0.00000000"], ["84235.64000000", "0.00000000"], ["84238.39000000", "0.00000000"], ["84239.10000000", "0.00000000"], ["84239.58000000", "0.02061000"], ["84241.85000000", "0.05297000"], ["84244.68000000", "0.05297000"], ["84245.89000000", "0.01125000"], ["84247.34000000", "0.04498000"], ["84252.98000000", "0.00899000"], ["84253.19000000", "0.04498000"], ["84256.00000000", "0.00235000"], ["84270.38000000", "0.00000000"], ["84270.43000000", "0.00000000"], ["84282.03000000", "0.02199000"], ["84293.64000000", "0.00000000"], ["84336.49000000", "0.00013000"], ["84347.18000000", "0.00000000"], ["84347.45000000", "0.00013000"], ["84351.38000000", "0.00000000"], ["84351.65000000", "0.00013000"], ["84388.14000000", "0.00000000"], ["84388.16000000", "0.99515000"], ["84462.00000000", "0.15445000"], ["84477.65000000", "0.00006000"], ["85365.10000000", "0.00000000"], ["85434.30000000", "0.05862000"]], "record_time": 1742584925.12814, "EXCHANGE": "BINANCE"}
{"e": "depthUpdate", "E": 1742584926014, "s": "BTCUSDT", "U": 64637921672, "u": 64637921875, "b": [["84108.69000000", "8.16954000"], ["84108.68000000", "0.01054000"], ["84108.66000000", "0.00033000"], ["84108.53000000", "1.02136000"], ["84108.51000000", "0.00007000"], ["84108.50000000", "0.00000000"], ["84108.47000000", "1.54697000"], ["84108.00000000", "0.02273000"], ["84107.83000000", "0.00000000"], ["84106.25000000", "0.02383000"], ["84106.16000000", "0.11584000"], ["84104.28000000", "0.00000000"], ["84103.53000000", "0.25160000"], ["84103.50000000", "0.00118000"], ["84103.41000000", "0.00000000"], ["84102.50000000", "0.00500000"], ["84101.30000000", "0.24847000"], ["84098.98000000", "0.03566000"], ["84098.00000000", "0.08204000"], ["84097.30000000", "0.00307000"], ["84093.49000000", "0.00000000"], ["84090.46000000", "1.03029000"], ["84089.42000000", "0.00000000"], ["84085.98000000", "0.59437000"], ["84071.46000000", "0.00000000"], ["84040.57000000", "0.02854000"], ["84035.42000000", "0.01433000"], ["84021.12000000", "0.75974000"], ["84021.00000000", "0.00000000"], ["84018.12000000", "0.00000000"], ["84009.28000000", "0.00400000"], ["83977.65000000", "0.12000000"], ["83961.73000000", "0.00000000"], ["83951.91000000", "0.01000000"], ["83951.89000000", "0.99313000"], ["83945.70000000", "0.00000000"], ["83924.39000000", "0.00452000"], ["83924.38000000", "0.00000000"], ["83898.08000000", "0.00000000"], ["83870.23000000", "0.00000000"], ["82847.05000000", "0.00010000"], ["75697.00000000", "0.00020000"], ["67286.96000000", "0.00058000"], ["60000.00000000", "73.01903000"], ["33000.00000000", "2.93827000"], ["30279.13000000", "0.01081000"]], "a": [["84108.70000000", "0.07552000"], ["84109.61000000", "0.01911000"], ["84109.80000000", "0.01120000"], ["84110.52000000", "0.00000000"], ["84110.53000000", "0.00000000"], ["84110.94000000", "0.00000000"], ["84110.95000000", "0.00007000"], ["84112.08000000", "0.00022000"], ["84112.09000000", "0.02234000"], ["84112.23000000", "0.00023000"], ["84112.70000000", "0.00000000"], ["84112.71000000", "0.00000000"], ["84112.72000000", "0.00000000"], ["84112.73000000", "0.00000000"], ["84113.00000000", "0.30842000"], ["84113.61000000", "0.00008000"], ["84113.62000000", "0.00008000"], ["84113.63000000", "0.06374000"], ["84113.78000000", "0.00000000"], ["84113.79000000", "0.00000000"], ["84114.81000000", "0.02218000"], ["84115.68000000", "0.00000000"], ["84116.94000000", "0.00000000"], ["84120.29000000", "0.62674000"], ["84121.17000000", "0.00000000"], ["84121.18000000", "0.00914000"], ["84123.06000000", "0.00000000"], ["84123.59000000", "0.78493000"], ["84124.12000000", "0.08354000"], ["84125.87000000", "0.00000000"], ["84126.58000000", "0.02486000"], ["84129.18000000", "0.00000000"], ["84132.06000000", "0.00000000"], ["84134.58000000", "0.00382000"], ["84137.66000000", "1.18099000"], ["84144.73000000", "0.00000000"], ["84149.75000000", "0.00000000"], ["84152.01000000", "0.00000000"], ["84153.71000000", "0.00000000"], ["84154.24000000", "0.01807000"], ["84155.62000000", "0.00523000"], ["84157.53000000", "0.00000000"], ["84159.61000000", "0.00000000"], ["84160.75000000", "0.85591000"], ["84171.92000000", "0.01627000"], ["84189.33000000", "0.00914000"], ["84189.63000000", "0.01958000"], ["84193.42000000", "0.01313000"], ["84200.84000000", "0.01052000"], ["84204.17000000", "0.00000000"], ["84210.54000000", "0.00716000"], ["84217.99000000", "0.00000000"], ["84218.36000000", "0.03078000"], ["84220.72000000", "0.00000000"], ["84221.86000000", "0.00000000"], ["84223.38000000", "0.00737000"], ["84234.80000000", "0.00000000"], ["84235.18000000", "0.00382000"], ["84239.22000000", "0.01519000"], ["84261.01000000", "0.00865000"], ["84262.48000000", "0.00000000"], ["84264.00000000", "0.00353000"], ["84267.30000000", "0.00000000"], ["84285.87000000", "0.00984000"], ["84293.07000000", "0.00000000"], ["84351.65000000", "0.00000000"], ["84388.16000000", "0.99459000"], ["84445.14000000", "0.00008000"], ["85370.34000000", "0.00100000"]], "record_time": 1742584926.126444, "EXCHANGE": "BINANCE"}
{"e": "depthUpdate", "E": 1742584927014, "s": "BTCUSDT", "U": 64637921876, "u": 64637922059, "b": [["84108.69000000", "8.06799000"], ["84108.68000000", "0.01041000"], ["84108.53000000", "0.69087000"], ["84104.60000000", "0.03594000"], ["84104.31000000", "0.00756000"], ["84104.13000000", "0.00000000"], ["84100.90000000", "0.00500000"], ["84085.98000000", "0.00000000"], ["84083.19000000", "0.00000000"], ["84079.82000000", "0.05000000"], ["84073.38000000", "0.00000000"], ["84056.05000000", "0.59437000"], ["84044.63000000", "0.00060000"], ["84040.27000000", "0.00000000"], ["84009.28000000", "0.00000000"], ["84002.75000000", "0.00400000"], ["83993.00000000", "0.43436000"], ["82847.05000000", "0.00110000"], ["75697.00000000", "0.00020000"], ["67286.96000000", "0.00058000"], ["33000.00000000", "2.93827000"], ["30279.13000000", "0.01101000"]], "a": [["84108.70000000", "0.06889000"], ["84108.71000000", "0.00046000"], ["84108.72000000", "0.00020000"], ["84109.61000000", "0.01904000"], ["84109.80000000", "0.01120000"], ["84109.81000000", "0.00000000"], ["84110.53000000", "0.00000000"], ["84110.84000000", "0.00000000"], ["84111.73000000", "0.00000000"], ["84111.79000000", "0.00021000"], ["84111.80000000", "0.17079000"], ["84112.08000000", "0.00008000"], ["84112.09000000", "0.02227000"], ["84112.11000000", "0.00039000"], ["84112.12000000", "0.27173000"], ["84112.23000000", "0.00007000"], ["84112.99000000", "0.00000000"], ["84113.00000000", "0.00000000"], ["84113.61000000", "0.00000000"], ["84113.62000000", "0.00000000"], ["84120.43000000", "0.78496000"], ["84121.26000000", "0.01198000"], ["84123.59000000", "0.00000000"], ["84124.65000000", "0.00421000"], ["84125.53000000", "0.01428000"], ["84125.86000000", "0.00760000"], ["84126.06000000", "0.03310000"], ["84129.18000000", "0.00000000"], ["84133.40000000", "0.44424000"], ["84140.79000000", "0.00000000"], ["84140.80000000", "0.03567000"], ["84140.82000000", "0.00000000"], ["84144.86000000", "0.85607000"], ["84148.01000000", "0.00901000"], ["84150.00000000", "0.36522000"], ["84159.16000000", "0.02548000"], ["84160.75000000", "0.00000000"], ["84167.10000000", "0.01051000"], ["84189.29000000", "0.01113000"], ["84193.80000000", "0.00492000"], ["84204.44000000", "0.00000000"], ["84205.92000000", "0.01198000"], ["84206.62000000", "0.01725000"], ["84208.30000000", "0.00000000"], ["84227.51000000", "0.00753000"], ["84242.90000000", "0.00664000"], ["84247.35000000", "0.01941000"], ["84256.57000000", "0.01424000"], ["84260.18000000", "0.02117000"], ["84268.40000000", "0.00000000"], ["84273.32000000", "0.00401000"], ["84276.11000000", "0.00000000"], ["85370.34000000", "0.00000000"]], "record_time": 1742584927.126819, "EXCHANGE": "BINANCE"}
{"e": "depthUpdate", "E": 1742584928014, "s": "BTCUSDT", "U": 64637922060, "u": 64637922424, "b": [["84108.69000000", "6.69000000"], ["84108.68000000", "0.01028000"], ["84108.47000000", "1.49344000"], ["84106.16000000", "0.08006000"], ["84106.00000000", "0.02266000"], ["84105.72000000", "0.05359000"], ["84104.60000000", "0.03000000"], ["84104.17000000", "0.00000000"], ["84103.93000000", "0.00000000"], ["84103.54000000", "0.00000000"], ["84103.53000000", "0.20164000"], ["84103.28000000", "0.00000000"], ["84102.50000000", "0.00000000"], ["84102.21000000", "0.00000000"], ["84101.80000000", "0.00000000"], ["84101.56000000", "0.00000000"], ["84101.30000000", "0.18064000"], ["84101.29000000", "0.00000000"], ["84100.69000000", "0.00000000"], ["84099.04000000", "0.00000000"], ["84098.98000000", "0.00000000"], ["84098.38000000", "0.00000000"], ["84098.26000000", "0.29711000"], ["84098.00000000", "0.02260000"], ["84097.10000000", "0.00000000"], ["84096.35000000", "0.00000000"], ["84096.09000000", "0.00000000"], ["84095.88000000", "0.00000000"], ["84095.84000000", "0.00000000"], ["84094.58000000", "1.55716000"], ["84094.42000000", "0.00000000"], ["84093.52000000", "0.59437000"], ["84090.93000000", "0.00000000"], ["84090.46000000", "1.03500000"], ["84090.45000000", "0.00000000"], ["84088.01000000", "0.00000000"], ["84087.41000000", "0.00000000"], ["84087.39000000", "1.39073000"], ["84086.14000000", "1.18017000"], ["84083.57000000", "0.59469000"], ["84081.79000000", "0.87823000"], ["84081.78000000", "0.85672000"], ["84080.97000000", "0.00000000"], ["84079.82000000", "0.00000000"], ["84078.94000000", "0.00000000"], ["84078.16000000", "0.00000000"], ["84076.08000000", "0.08123000"], ["84075.01000000", "0.00939000"], ["84073.30000000", "0.01878000"], ["84068.07000000", "0.04228000"], ["84056.05000000", "0.00000000"], ["84055.88000000", "0.82937000"], ["84055.67000000", "0.59437000"], ["84002.75000000", "0.00000000"], ["83997.64000000", "0.00000000"], ["83993.00000000", "0.38480000"], ["83990.11000000", "0.00400000"], ["83952.01000000", "0.00000000"], ["83951.91000000", "0.00000000"], ["83935.93000000", "0.00012000"], ["83910.73000000", "0.00000000"], ["83898.26000000", "0.01783000"], ["83883.47000000", "0.01861000"], ["82847.05000000", "0.00010000"], ["80747.80000000", "0.00000000"], ["80730.96000000", "0.00000000"], ["75697.00000000", "0.00020000"], ["67286.96000000", "0.00058000"], ["40000.00000000", "16.52407000"], ["33000.00000000", "2.93827000"], ["30279.13000000", "0.01141000"]], "a": [["84108.70000000", "1.73196000"], ["84108.71000000", "0.00033000"], ["84108.72000000", "0.00033000"], ["84108.90000000", "0.00021000"], ["84108.91000000", "0.14021000"], ["84108.92000000", "0.00021000"], ["84108.93000000", "0.14587000"], ["84109.17000000", "0.00034000"], ["84109.18000000", "0.01376000"], ["84109.24000000", "0.00000000"], ["84109.36000000", "0.00000000"], ["84109.37000000", "0.09042000"], ["84109.46000000", "0.00000000"], ["84109.59000000", "0.00006000"], ["84109.60000000", "0.00006000"], ["84109.61000000", "0.01891000"], ["84109.62000000", "0.00000000"], ["84109.63000000", "0.00000000"], ["84109.79000000", "0.00000000"], ["84109.80000000", "0.01113000"], ["84110.09000000", "0.00007000"], ["84110.55000000", "0.00000000"], ["84110.56000000", "0.00000000"], ["84110.64000000", "0.00000000"], ["84110.74000000", "0.00000000"], ["84110.75000000", "0.00000000"], ["84110.93000000", "0.00000000"], ["84111.79000000", "0.00000000"], ["84111.80000000", "0.00029000"], ["84112.04000000", "0.11402000"], ["84112.05000000", "0.00000000"], ["84112.06000000", "0.00000000"], ["84112.08000000", "0.00000000"], ["84112.11000000", "0.00000000"], ["84112.12000000", "0.00000000"], ["84112.13000000", "0.00000000"], ["84112.23000000", "0.00007000"], ["84112.46000000", "0.00000000"], ["84112.90000000", "0.00801000"], ["84113.58000000", "0.00000000"], ["84113.59000000", "0.00000000"], ["84114.60000000", "0.00000000"], ["84114.61000000", "0.00000000"], ["84114.81000000", "0.00000000"], ["84120.19000000", "0.00094000"], ["84120.29000000", "0.42694000"], ["84120.43000000", "0.00000000"], ["84121.31000000", "0.01188000"], ["84122.44000000", "0.00000000"], ["84122.45000000", "0.00000000"], ["84124.25000000", "0.00000000"], ["84124.75000000", "0.00000000"], ["84125.37000000", "0.71126000"], ["84128.76000000", "0.00000000"], ["84129.18000000", "0.02368000"], ["84130.13000000", "0.01006000"], ["84133.51000000", "0.01288000"], ["84137.82000000", "0.01861000"], ["84139.25000000", "0.00000000"], ["84139.27000000", "1.38855000"], ["84140.31000000", "0.85612000"], ["84140.40000000", "0.00922000"], ["84143.42000000", "0.01810000"], ["84146.64000000", "0.02516000"], ["84150.52000000", "0.00000000"], ["84151.43000000", "0.00996000"], ["84152.22000000", "0.05807000"], ["84153.00000000", "0.59469000"], ["84154.61000000", "0.05000000"], ["84158.83000000", "0.00000000"], ["84159.01000000", "0.00996000"], ["84159.37000000", "0.00000000"], ["84161.72000000", "0.00000000"], ["84162.09000000", "0.00000000"], ["84162.62000000", "0.04371000"], ["84169.66000000", "0.03971000"], ["84171.22000000", "0.00000000"], ["84175.97000000", "0.00000000"], ["84183.05000000", "0.00000000"], ["84186.73000000", "0.00000000"], ["84196.99000000", "0.00000000"], ["84200.77000000", "0.01006000"], ["84202.81000000", "0.00000000"], ["84203.60000000", "0.00059000"], ["84209.45000000", "0.04756000"], ["84211.97000000", "0.00000000"], ["84213.00000000", "0.00270000"], ["84230.54000000", "0.00949000"], ["84235.98000000", "0.01097000"], ["84237.42000000", "0.00000000"], ["84239.05000000", "0.18319000"], ["84242.90000000", "0.00000000"], ["84262.52000000", "0.00000000"], ["84262.77000000", "0.00000000"], ["84268.48000000", "0.00949000"], ["84350.20000000", "0.00013000"], ["84354.40000000", "0.00013000"], ["84388.16000000", "0.00000000"], ["84458.40000000", "0.00000000"], ["85370.34000000", "0.00100000"], ["85391.70000000", "0.00007000"]], "record_time": 1742584928.127492, "EXCHANGE": "BINANCE"}
