{"result": null, "id": 1}
{"e": "depthUpdate", "E": 1741338227795, "s": "SOLUSDT", "U": 19256845690, "u": 19256845924, "b": [["144.28000000", "265.94600000"], ["144.27000000", "181.80500000"], ["144.26000000", "188.25600000"], ["144.25000000", "148.09700000"], ["144.24000000", "250.66000000"], ["144.23000000", "457.98000000"], ["144.22000000", "586.22100000"], ["144.21000000", "388.33600000"], ["144.20000000", "369.24900000"], ["144.19000000", "596.03500000"], ["144.18000000", "705.62100000"], ["144.17000000", "710.33700000"], ["144.16000000", "982.82700000"], ["144.15000000", "576.93600000"], ["144.14000000", "307.50500000"], ["144.13000000", "224.09500000"], ["144.12000000", "160.52200000"], ["144.11000000", "400.66500000"], ["144.07000000", "195.39000000"], ["144.05000000", "851.40000000"], ["144.04000000", "1056.54700000"], ["144.03000000", "1845.04000000"], ["144.02000000", "862.54100000"], ["144.01000000", "233.23500000"], ["144.00000000", "377.25300000"], ["143.99000000", "321.88300000"], ["143.98000000", "161.39700000"], ["143.96000000", "371.47900000"], ["143.95000000", "193.96900000"], ["143.93000000", "586.17600000"], ["143.92000000", "280.70900000"], ["143.90000000", "362.67200000"], ["143.89000000", "144.53900000"], ["143.86000000", "76.87100000"], ["143.85000000", "85.03600000"], ["143.52000000", "41.25700000"], ["143.51000000", "84.43800000"], ["51.94000000", "4.40800000"]], "a": [["144.29000000", "38.19700000"], ["144.30000000", "15.22100000"], ["144.31000000", "56.71600000"], ["144.32000000", "75.01300000"], ["144.33000000", "203.29300000"], ["144.34000000", "213.45900000"], ["144.35000000", "593.97700000"], ["144.36000000", "356.01200000"], ["144.37000000", "800.00000000"], ["144.38000000", "605.55100000"], ["144.39000000", "477.83700000"], ["144.40000000", "551.88400000"], ["144.41000000", "561.09100000"], ["144.42000000", "458.18400000"], ["144.43000000", "329.63900000"], ["144.44000000", "343.11600000"], ["144.46000000", "462.33500000"], ["144.50000000", "514.45400000"], ["144.53000000", "552.53700000"], ["144.55000000", "404.62400000"], ["144.56000000", "629.94600000"], ["144.57000000", "911.35800000"], ["144.58000000", "378.72600000"], ["144.59000000", "316.11000000"], ["144.60000000", "274.40700000"], ["144.62000000", "123.28800000"], ["144.77000000", "928.53200000"], ["144.95000000", "8.44500000"], ["144.98000000", "29.96200000"], ["145.04000000", "101.19200000"]]}
{"e": "depthUpdate", "E": 1741338228795, "s": "SOLUSDT", "U": 19256845925, "u": 19256846022, "b": [["144.28000000", "108.77700000"], ["144.27000000", "157.95100000"], ["144.26000000", "105.21600000"], ["144.25000000", "207.99900000"], ["144.24000000", "250.49700000"], ["144.19000000", "665.51300000"], ["144.05000000", "791.49800000"], ["143.97000000", "223.26000000"], ["143.91000000", "270.34200000"], ["143.44000000", "49.07800000"], ["143.01000000", "331.85300000"], ["140.00000000", "2543.75800000"], ["51.94000000", "4.52400000"]], "a": [["144.29000000", "38.19700000"], ["144.30000000", "32.54600000"], ["144.31000000", "85.63500000"], ["144.32000000", "175.01300000"], ["144.33000000", "194.67400000"], ["144.35000000", "638.55900000"], ["144.36000000", "352.92600000"], ["144.37000000", "859.69400000"], ["144.38000000", "608.98300000"], ["144.39000000", "529.67500000"], ["144.47000000", "413.01600000"], ["144.59000000", "343.49300000"], ["144.65000000", "138.36700000"]]}
{"e": "depthUpdate", "E": 1741338229795, "s": "SOLUSDT", "U": 19256846023, "u": 19256846707, "b": [["144.30000000", "47.87600000"], ["144.29000000", "79.64400000"], ["144.28000000", "246.70900000"], ["144.27000000", "254.38000000"], ["144.26000000", "489.11800000"], ["144.25000000", "430.33000000"], ["144.24000000", "273.29800000"], ["144.23000000", "573.91300000"], ["144.22000000", "175.97800000"], ["144.21000000", "203.85600000"], ["144.20000000", "382.48300000"], ["144.19000000", "701.16600000"], ["144.18000000", "708.36600000"], ["144.17000000", "834.19900000"], ["144.16000000", "1004.80800000"], ["144.15000000", "514.98000000"], ["144.14000000", "370.37500000"], ["144.13000000", "453.50400000"], ["144.12000000", "188.02500000"], ["144.11000000", "410.35700000"], ["144.10000000", "219.40500000"], ["144.09000000", "282.72000000"], ["144.08000000", "234.67000000"], ["144.06000000", "320.67900000"], ["144.05000000", "556.52900000"], ["144.04000000", "1046.90200000"], ["144.03000000", "1581.50100000"], ["144.02000000", "739.62400000"], ["144.01000000", "273.89700000"], ["144.00000000", "308.29800000"], ["143.99000000", "349.89500000"], ["143.98000000", "350.81500000"], ["143.97000000", "215.92000000"], ["143.96000000", "394.46300000"], ["143.95000000", "239.93700000"], ["143.94000000", "321.73600000"], ["143.93000000", "564.19000000"], ["143.92000000", "220.06000000"], ["143.90000000", "348.77800000"], ["143.87000000", "206.44700000"], ["143.86000000", "76.82100000"], ["143.79000000", "85.33600000"], ["143.67000000", "103.63800000"], ["143.66000000", "128.67000000"], ["143.57000000", "77.45300000"], ["143.52000000", "48.22400000"], ["143.44000000", "145.99600000"], ["143.40000000", "0.55100000"], ["143.37000000", "31.78300000"], ["143.30000000", "6.15000000"], ["143.29000000", "1130.36100000"], ["143.26000000", "127.30800000"], ["143.19000000", "323.35800000"], ["143.01000000", "8.30000000"], ["142.56000000", "7.05700000"], ["142.24000000", "0.65700000"]], "a": [["144.29000000", "0.00000000"], ["144.30000000", "0.00000000"], ["144.31000000", "154.10100000"], ["144.32000000", "45.07000000"], ["144.33000000", "82.35700000"], ["144.34000000", "107.25300000"], ["144.35000000", "416.73500000"], ["144.36000000", "269.44200000"], ["144.37000000", "379.98800000"], ["144.38000000", "722.76000000"], ["144.39000000", "443.11700000"], ["144.40000000", "436.36700000"], ["144.41000000", "553.42900000"], ["144.42000000", "424.30100000"], ["144.43000000", "539.52300000"], ["144.44000000", "379.91200000"], ["144.45000000", "346.24900000"], ["144.46000000", "260.97600000"], ["144.47000000", "262.60700000"], ["144.48000000", "430.37900000"], ["144.49000000", "552.37800000"], ["144.50000000", "536.42300000"], ["144.51000000", "420.72500000"], ["144.52000000", "429.19500000"], ["144.53000000", "513.18500000"], ["144.54000000", "488.49100000"], ["144.55000000", "497.65400000"], ["144.56000000", "673.54800000"], ["144.57000000", "885.99700000"], ["144.58000000", "400.71200000"], ["144.59000000", "400.26400000"], ["144.60000000", "384.62500000"], ["144.61000000", "249.83700000"], ["144.62000000", "185.24800000"], ["144.63000000", "371.00000000"], ["144.64000000", "189.87300000"], ["144.65000000", "231.30100000"], ["144.71000000", "181.20100000"], ["144.72000000", "288.82700000"], ["144.81000000", "110.53600000"], ["144.87000000", "4.33700000"], ["145.02000000", "1.96600000"], ["145.04000000", "1.06900000"], ["145.05000000", "114.96200000"], ["145.06000000", "11.80200000"], ["145.18000000", "104.12800000"], ["145.47000000", "2.41500000"], ["145.52000000", "1.16200000"], ["145.56000000", "14.10100000"], ["146.12000000", "818.82700000"], ["146.66000000", "146.09000000"]]}
{"e": "depthUpdate", "E": 1741338230795, "s": "SOLUSDT", "U": 19256846708, "u": 19256848168, "b": [["144.34000000", "223.61400000"], ["144.33000000", "238.43900000"], ["144.32000000", "325.68400000"], ["144.31000000", "398.47800000"], ["144.30000000", "499.88900000"], ["144.29000000", "627.21100000"], ["144.28000000", "591.31500000"], ["144.27000000", "431.73900000"], ["144.26000000", "303.67200000"], ["144.25000000", "264.21000000"], ["144.24000000", "357.98800000"], ["144.23000000", "447.91700000"], ["144.22000000", "197.87800000"], ["144.21000000", "283.49600000"], ["144.20000000", "415.18200000"], ["144.19000000", "822.59400000"], ["144.18000000", "802.22200000"], ["144.17000000", "955.60000000"], ["144.16000000", "1252.98000000"], ["144.15000000", "509.42000000"], ["144.14000000", "366.90800000"], ["144.13000000", "451.60900000"], ["144.12000000", "134.22400000"], ["144.11000000", "213.72400000"], ["144.10000000", "205.48300000"], ["144.09000000", "264.32500000"], ["144.08000000", "355.85000000"], ["144.07000000", "135.48800000"], ["144.06000000", "317.20200000"], ["144.05000000", "440.01000000"], ["144.04000000", "776.10700000"], ["144.03000000", "933.70500000"], ["144.02000000", "394.40900000"], ["143.99000000", "381.27100000"], ["143.98000000", "336.93900000"], ["143.97000000", "214.20500000"], ["143.96000000", "371.47900000"], ["143.95000000", "193.96900000"], ["143.92000000", "189.36900000"], ["143.91000000", "175.07000000"], ["143.90000000", "316.99100000"], ["143.89000000", "205.95800000"], ["143.88000000", "54.45900000"], ["143.84000000", "466.36000000"], ["143.83000000", "90.24000000"], ["143.82000000", "168.85200000"], ["143.80000000", "89.41100000"], ["143.78000000", "207.25400000"], ["143.77000000", "122.69900000"], ["143.73000000", "320.16300000"], ["143.71000000", "188.17400000"], ["143.70000000", "848.67100000"], ["143.69000000", "877.72400000"], ["143.68000000", "2.31500000"], ["143.67000000", "49.02200000"], ["143.65000000", "46.85900000"], ["143.54000000", "42.87900000"], ["143.53000000", "36.43900000"], ["143.40000000", "252.69100000"], ["143.38000000", "0.09900000"], ["143.37000000", "2.98300000"], ["143.05000000", "0.10800000"], ["143.01000000", "6.49600000"], ["142.62000000", "0.60200000"], ["141.20000000", "12.79600000"], ["51.96000000", "2.32000000"]], "a": [["144.31000000", "0.00000000"], ["144.32000000", "0.00000000"], ["144.33000000", "0.00000000"], ["144.34000000", "0.00000000"], ["144.35000000", "29.85100000"], ["144.36000000", "2.48200000"], ["144.37000000", "9.73100000"], ["144.38000000", "133.23600000"], ["144.39000000", "222.60600000"], ["144.40000000", "129.69900000"], ["144.41000000", "247.10700000"], ["144.42000000", "385.57700000"], ["144.43000000", "401.82000000"], ["144.44000000", "522.29600000"], ["144.45000000", "310.15500000"], ["144.46000000", "290.29000000"], ["144.47000000", "387.24700000"], ["144.48000000", "270.78700000"], ["144.49000000", "427.80000000"], ["144.50000000", "512.39600000"], ["144.51000000", "357.51900000"], ["144.52000000", "349.55900000"], ["144.53000000", "444.64700000"], ["144.54000000", "419.80200000"], ["144.55000000", "397.28400000"], ["144.56000000", "600.81700000"], ["144.57000000", "436.71500000"], ["144.58000000", "499.97500000"], ["144.59000000", "676.64000000"], ["144.60000000", "555.34700000"], ["144.61000000", "492.94400000"], ["144.62000000", "574.17000000"], ["144.63000000", "597.66900000"], ["144.64000000", "304.68800000"], ["144.65000000", "387.83100000"], ["144.66000000", "591.93100000"], ["144.67000000", "401.88100000"], ["144.68000000", "174.00900000"], ["144.69000000", "220.69100000"], ["144.70000000", "691.38200000"], ["144.71000000", "320.05800000"], ["144.73000000", "126.64900000"], ["144.74000000", "88.65100000"], ["144.75000000", "58.05400000"], ["144.76000000", "194.97800000"], ["144.77000000", "980.69800000"], ["144.81000000", "110.57200000"], ["144.83000000", "110.45100000"], ["144.86000000", "36.69700000"], ["144.95000000", "4.37500000"], ["144.97000000", "7.02300000"], ["144.98000000", "69.40100000"], ["145.01000000", "13.37200000"], ["145.02000000", "30.76600000"], ["145.06000000", "40.60200000"], ["145.07000000", "11.64000000"], ["145.08000000", "2.00400000"], ["145.09000000", "5.92600000"], ["145.10000000", "143.52800000"], ["145.11000000", "118.95500000"], ["145.17000000", "96.74900000"], ["145.18000000", "4.00500000"], ["145.51000000", "21.32700000"], ["145.56000000", "0.20700000"], ["145.59000000", "14.38000000"], ["145.74000000", "21.35600000"], ["149.00000000", "2133.45400000"], ["180.00000000", "37822.38200000"], ["276.52000000", "0.33400000"]]}
{"e": "depthUpdate", "E": 1741338231795, "s": "SOLUSDT", "U": 19256848169, "u": 19256848778, "b": [["144.37000000", "327.33800000"], ["144.36000000", "207.55800000"], ["144.35000000", "366.40700000"], ["144.34000000", "133.44700000"], ["144.33000000", "456.00100000"], ["144.32000000", "309.12800000"], ["144.31000000", "382.63000000"], ["144.30000000", "478.37400000"], ["144.29000000", "577.67100000"], ["144.28000000", "465.55500000"], ["144.27000000", "404.58900000"], ["144.26000000", "377.78600000"], ["144.25000000", "243.14400000"], ["144.24000000", "311.32800000"], ["144.23000000", "424.13200000"], ["144.22000000", "337.09700000"], ["144.21000000", "231.59300000"], ["144.20000000", "444.35600000"], ["144.19000000", "851.57900000"], ["144.18000000", "947.14700000"], ["144.17000000", "988.27600000"], ["144.16000000", "1220.02800000"], ["144.15000000", "412.11100000"], ["144.14000000", "366.85500000"], ["144.13000000", "391.75600000"], ["144.11000000", "197.63300000"], ["144.10000000", "195.75800000"], ["144.08000000", "354.87900000"], ["144.07000000", "138.48800000"], ["144.06000000", "427.31700000"], ["144.05000000", "425.51100000"], ["144.04000000", "726.13500000"], ["144.03000000", "750.82200000"], ["144.02000000", "372.42200000"], ["143.98000000", "333.93900000"], ["143.95000000", "194.19900000"], ["143.94000000", "321.50600000"], ["143.93000000", "439.19500000"], ["143.84000000", "465.92400000"], ["143.73000000", "265.94800000"], ["143.72000000", "166.74700000"], ["143.71000000", "133.73800000"], ["143.65000000", "46.92700000"], ["143.56000000", "5.09700000"], ["143.55000000", "113.98600000"], ["143.45000000", "10.80400000"], ["143.42000000", "0.10500000"], ["143.36000000", "0.25000000"], ["142.88000000", "1.44500000"], ["141.37000000", "3.74500000"]], "a": [["144.35000000", "0.00000000"], ["144.36000000", "0.00000000"], ["144.37000000", "0.00000000"], ["144.38000000", "3.52800000"], ["144.39000000", "5.87200000"], ["144.40000000", "45.21100000"], ["144.41000000", "195.19800000"], ["144.42000000", "192.15900000"], ["144.43000000", "574.80200000"], ["144.44000000", "470.81000000"], ["144.45000000", "288.77600000"], ["144.46000000", "362.26200000"], ["144.47000000", "387.29900000"], ["144.48000000", "293.82700000"], ["144.49000000", "446.74500000"], ["144.50000000", "408.48300000"], ["144.51000000", "213.47000000"], ["144.52000000", "262.61600000"], ["144.53000000", "357.70800000"], ["144.54000000", "371.78000000"], ["144.55000000", "318.34300000"], ["144.56000000", "579.14600000"], ["144.57000000", "324.44500000"], ["144.58000000", "455.29600000"], ["144.59000000", "740.79400000"], ["144.60000000", "646.30100000"], ["144.61000000", "521.93500000"], ["144.62000000", "657.12500000"], ["144.63000000", "644.28300000"], ["144.64000000", "352.66300000"], ["144.65000000", "415.81800000"], ["144.66000000", "795.27600000"], ["144.67000000", "449.85500000"], ["144.68000000", "246.97000000"], ["144.69000000", "257.54900000"], ["144.70000000", "691.15200000"], ["144.72000000", "289.05700000"], ["144.78000000", "97.46100000"], ["144.84000000", "30.31200000"], ["144.87000000", "3.34200000"], ["144.88000000", "110.38700000"], ["144.93000000", "110.94200000"], ["145.09000000", "106.04900000"], ["145.10000000", "43.40500000"], ["145.11000000", "121.56700000"], ["145.55000000", "7.92200000"], ["145.59000000", "0.48600000"], ["145.62000000", "14.46300000"], ["146.07000000", "1.41800000"]]}
{"e": "depthUpdate", "E": 1741338232795, "s": "SOLUSDT", "U": 19256848779, "u": 19256849837, "b": [["144.40000000", "329.69900000"], ["144.39000000", "278.56200000"], ["144.38000000", "285.43400000"], ["144.37000000", "162.27300000"], ["144.36000000", "371.19500000"], ["144.35000000", "673.72800000"], ["144.34000000", "383.33100000"], ["144.33000000", "904.96000000"], ["144.32000000", "575.40700000"], ["144.31000000", "516.39000000"], ["144.30000000", "359.64300000"], ["144.29000000", "508.95000000"], ["144.28000000", "296.22900000"], ["144.27000000", "483.94300000"], ["144.26000000", "363.20600000"], ["144.25000000", "192.48600000"], ["144.24000000", "297.14500000"], ["144.23000000", "432.16200000"], ["144.22000000", "208.66500000"], ["144.21000000", "372.26300000"], ["144.20000000", "524.11200000"], ["144.19000000", "877.02300000"], ["144.18000000", "987.91500000"], ["144.17000000", "1070.32500000"], ["144.16000000", "1124.17200000"], ["144.15000000", "393.17500000"], ["144.14000000", "525.15400000"], ["144.13000000", "391.70700000"], ["144.12000000", "134.15200000"], ["144.11000000", "259.53000000"], ["144.10000000", "324.21200000"], ["144.09000000", "223.97100000"], ["144.08000000", "193.89600000"], ["144.07000000", "106.54500000"], ["144.06000000", "280.30000000"], ["144.05000000", "309.99100000"], ["144.04000000", "347.92400000"], ["144.03000000", "276.38600000"], ["144.02000000", "253.48600000"], ["144.01000000", "187.02800000"], ["143.98000000", "334.63100000"], ["143.97000000", "114.70900000"], ["143.96000000", "326.22900000"], ["143.95000000", "80.50100000"], ["143.94000000", "162.29100000"], ["143.93000000", "377.71000000"], ["143.92000000", "172.89100000"], ["143.91000000", "174.62000000"], ["143.90000000", "320.97100000"], ["143.89000000", "205.92200000"], ["143.88000000", "54.42300000"], ["143.87000000", "211.29900000"], ["143.84000000", "461.97400000"], ["143.83000000", "91.24000000"], ["143.77000000", "121.69900000"], ["143.76000000", "33.39200000"], ["143.75000000", "9.51500000"], ["143.74000000", "73.39800000"], ["143.71000000", "28.01100000"], ["143.67000000", "35.15200000"], ["143.58000000", "0.44600000"], ["143.57000000", "77.38300000"], ["143.55000000", "147.48500000"], ["143.51000000", "36.03000000"], ["143.44000000", "468.57900000"], ["143.27000000", "68.46000000"], ["143.25000000", "73.48900000"], ["143.19000000", "0.21100000"], ["143.09000000", "14.91500000"], ["142.98000000", "0.08700000"], ["142.74000000", "67.97100000"], ["142.54000000", "1.15100000"], ["142.24000000", "0.65700000"]], "a": [["144.38000000", "0.00000000"], ["144.39000000", "0.00000000"], ["144.40000000", "0.00000000"], ["144.41000000", "37.31000000"], ["144.42000000", "3.10100000"], ["144.43000000", "70.14800000"], ["144.44000000", "97.51700000"], ["144.45000000", "188.66500000"], ["144.46000000", "466.54500000"], ["144.47000000", "257.75800000"], ["144.48000000", "438.72800000"], ["144.49000000", "618.51300000"], ["144.50000000", "413.47600000"], ["144.51000000", "219.26700000"], ["144.52000000", "459.56800000"], ["144.53000000", "276.23200000"], ["144.54000000", "365.10100000"], ["144.55000000", "259.38900000"], ["144.56000000", "479.64100000"], ["144.57000000", "344.24000000"], ["144.58000000", "339.38700000"], ["144.59000000", "628.88200000"], ["144.60000000", "624.78700000"], ["144.61000000", "556.97400000"], ["144.62000000", "688.16700000"], ["144.63000000", "561.15200000"], ["144.64000000", "386.11500000"], ["144.65000000", "538.57700000"], ["144.66000000", "878.22400000"], ["144.67000000", "600.90100000"], ["144.68000000", "418.08000000"], ["144.69000000", "464.93500000"], ["144.70000000", "644.64800000"], ["144.71000000", "447.23500000"], ["144.72000000", "388.99700000"], ["144.73000000", "242.58300000"], ["144.74000000", "119.63300000"], ["144.75000000", "89.03800000"], ["144.77000000", "170.59000000"], ["144.78000000", "151.20200000"], ["144.79000000", "96.58200000"], ["144.80000000", "112.34400000"], ["144.81000000", "219.71700000"], ["144.83000000", "210.45100000"], ["144.84000000", "313.68900000"], ["144.96000000", "30.70200000"], ["144.97000000", "4.34800000"], ["144.99000000", "117.30000000"], ["145.01000000", "824.13500000"], ["145.05000000", "117.63700000"], ["145.06000000", "36.14800000"], ["145.07000000", "15.50000000"], ["145.09000000", "21.54600000"], ["145.11000000", "121.63700000"], ["145.12000000", "18.82600000"], ["145.13000000", "3.03000000"], ["145.14000000", "110.79900000"], ["145.15000000", "4.60900000"], ["145.16000000", "0.33900000"], ["145.18000000", "104.12800000"], ["145.21000000", "232.17200000"], ["145.22000000", "5.24300000"], ["145.26000000", "1174.38200000"], ["145.27000000", "2.27200000"], ["145.28000000", "6.94200000"], ["145.56000000", "343.96800000"], ["145.59000000", "2.26800000"], ["145.62000000", "0.56900000"], ["145.64000000", "4.89600000"], ["145.66000000", "19.40500000"], ["145.81000000", "11.69900000"], ["145.96000000", "693.11500000"], ["145.97000000", "111.13200000"], ["146.36000000", "669.61900000"], ["146.38000000", "0.24000000"], ["146.49000000", "0.22900000"], ["146.79000000", "665.57200000"], ["147.47000000", "669.14700000"]]}
{"e": "depthUpdate", "E": 1741338233795, "s": "SOLUSDT", "U": 19256849838, "u": 19256850031, "b": [["144.40000000", "330.65000000"], ["144.39000000", "292.61700000"], ["144.38000000", "295.74700000"], ["144.37000000", "158.81100000"], ["144.36000000", "388.51200000"], ["144.35000000", "635.66600000"], ["144.34000000", "382.53100000"], ["144.33000000", "938.63500000"], ["144.32000000", "605.52800000"], ["144.31000000", "520.50600000"], ["144.29000000", "451.91400000"], ["144.26000000", "363.37800000"], ["144.16000000", "1120.71800000"], ["144.15000000", "362.19700000"], ["144.12000000", "141.00100000"], ["144.09000000", "223.92900000"], ["144.05000000", "323.88500000"], ["144.02000000", "253.48600000"], ["143.98000000", "333.93900000"], ["143.97000000", "98.23100000"], ["143.94000000", "148.39700000"], ["143.60000000", "10.53100000"], ["143.59000000", "44.39200000"], ["143.51000000", "287.97700000"], ["143.44000000", "145.99600000"], ["143.42000000", "14.04500000"], ["143.40000000", "0.55100000"], ["143.30000000", "329.04900000"]], "a": [["144.41000000", "4.99700000"], ["144.42000000", "3.10100000"], ["144.43000000", "70.09600000"], ["144.45000000", "171.39500000"], ["144.46000000", "451.85100000"], ["144.47000000", "177.44800000"], ["144.48000000", "432.72800000"], ["144.49000000", "644.74700000"], ["144.50000000", "306.80900000"], ["144.52000000", "462.33800000"], ["144.53000000", "284.94500000"], ["144.54000000", "374.80700000"], ["144.55000000", "258.39000000"], ["144.58000000", "308.40300000"], ["144.59000000", "573.75700000"], ["144.60000000", "593.80300000"], ["144.61000000", "533.98700000"], ["144.62000000", "640.19400000"], ["144.64000000", "363.12800000"], ["144.65000000", "513.58800000"], ["144.66000000", "830.25100000"], ["144.67000000", "527.93900000"], ["144.68000000", "464.05600000"], ["144.69000000", "489.92200000"], ["144.70000000", "692.62300000"], ["144.71000000", "472.22200000"], ["144.72000000", "498.94000000"], ["144.74000000", "175.60400000"], ["144.75000000", "143.01000000"], ["144.82000000", "531.33400000"], ["144.87000000", "3.37800000"], ["144.89000000", "4.57800000"], ["145.07000000", "38.93200000"], ["145.09000000", "5.92600000"]]}
{"e": "depthUpdate", "E": 1741338234795, "s": "SOLUSDT", "U": 19256850032, "u": 19256850203, "b": [["144.40000000", "46.66500000"], ["144.39000000", "103.01800000"], ["144.38000000", "258.31300000"], ["144.37000000", "130.54000000"], ["144.36000000", "358.16300000"], ["144.35000000", "633.31000000"], ["144.34000000", "366.25900000"], ["144.33000000", "880.32800000"], ["144.31000000", "537.65600000"], ["144.30000000", "376.62100000"], ["144.29000000", "468.15900000"], ["144.21000000", "373.40000000"], ["144.17000000", "1095.31100000"], ["144.16000000", "1145.70400000"], ["144.15000000", "387.18300000"], ["144.10000000", "327.21200000"], ["144.02000000", "254.17800000"], ["143.99000000", "378.27100000"], ["143.97000000", "97.09400000"], ["143.63000000", "77.44100000"], ["143.62000000", "0.05200000"], ["143.61000000", "38.67600000"], ["143.30000000", "329.04900000"], ["142.24000000", "0.65700000"], ["128.50000000", "4390.78300000"], ["51.99000000", "7.69200000"]], "a": [["144.41000000", "117.20400000"], ["144.42000000", "38.33700000"], ["144.43000000", "70.14800000"], ["144.44000000", "45.55800000"], ["144.45000000", "199.35800000"], ["144.46000000", "454.82000000"], ["144.47000000", "257.75800000"], ["144.48000000", "536.80500000"], ["144.49000000", "584.19300000"], ["144.50000000", "408.40100000"], ["144.51000000", "244.25300000"], ["144.52000000", "510.31100000"], ["144.53000000", "290.48500000"], ["144.54000000", "397.79200000"], ["144.55000000", "258.39000000"], ["144.56000000", "479.64100000"], ["144.57000000", "315.49700000"], ["144.66000000", "843.52800000"], ["144.67000000", "558.55500000"], ["144.69000000", "492.92200000"], ["144.71000000", "447.23500000"], ["144.72000000", "427.97700000"], ["144.73000000", "219.59500000"], ["144.74000000", "150.61700000"], ["144.75000000", "89.03800000"], ["145.07000000", "15.50000000"], ["145.18000000", "150.77900000"], ["145.19000000", "111.76300000"], ["146.11000000", "6.34700000"]]}
{"e": "depthUpdate", "E": 1741338235795, "s": "SOLUSDT", "U": 19256850204, "u": 19256850433, "b": [["144.40000000", "1.65500000"], ["144.39000000", "5.76000000"], ["144.38000000", "26.96300000"], ["144.37000000", "66.25400000"], ["144.36000000", "286.29800000"], ["144.35000000", "646.98600000"], ["144.34000000", "393.24800000"], ["144.33000000", "790.35400000"], ["144.32000000", "529.11800000"], ["144.31000000", "348.50500000"], ["144.30000000", "205.09100000"], ["144.18000000", "1016.89600000"], ["144.16000000", "1207.66400000"], ["144.15000000", "501.10900000"], ["144.14000000", "641.07900000"], ["144.13000000", "433.05000000"], ["144.12000000", "186.11800000"], ["144.10000000", "350.19700000"], ["144.09000000", "246.91400000"], ["144.06000000", "326.27000000"], ["143.96000000", "326.45900000"], ["143.95000000", "80.27100000"], ["143.87000000", "206.44700000"], ["143.64000000", "131.03600000"], ["143.63000000", "77.37100000"], ["143.42000000", "0.10500000"]], "a": [["144.41000000", "308.00400000"], ["144.42000000", "45.42900000"], ["144.43000000", "100.77500000"], ["144.44000000", "89.68800000"], ["144.45000000", "235.60700000"], ["144.46000000", "455.16600000"], ["144.47000000", "327.19200000"], ["144.48000000", "593.27200000"], ["144.49000000", "657.81000000"], ["144.50000000", "410.13200000"], ["144.53000000", "313.23200000"], ["144.54000000", "397.79200000"], ["144.57000000", "318.95900000"], ["144.59000000", "566.91400000"], ["144.72000000", "404.76200000"], ["144.73000000", "219.82500000"], ["144.74000000", "119.63300000"], ["144.75000000", "58.05400000"], ["144.79000000", "97.27500000"]]}
{"e": "depthUpdate", "E": 1741338236795, "s": "SOLUSDT", "U": 19256850434, "u": 19256850597, "b": [["144.40000000", "54.06800000"], ["144.39000000", "41.82200000"], ["144.38000000", "130.69400000"], ["144.37000000", "81.40100000"], ["144.36000000", "309.61800000"], ["144.35000000", "648.97200000"], ["144.34000000", "383.25900000"], ["144.33000000", "740.45000000"], ["144.32000000", "546.95000000"], ["144.31000000", "548.43500000"], ["144.30000000", "253.49900000"], ["144.14000000", "579.11900000"], ["144.10000000", "357.09700000"], ["144.05000000", "378.76600000"], ["144.04000000", "317.94100000"], ["143.91000000", "119.69300000"], ["143.64000000", "130.96600000"], ["143.51000000", "36.03000000"], ["143.48000000", "255.28100000"], ["139.01000000", "65.04000000"], ["138.31000000", "65.07100000"], ["120.00000000", "34918.14700000"]], "a": [["144.41000000", "128.35600000"], ["144.42000000", "40.55000000"], ["144.43000000", "68.99200000"], ["144.44000000", "79.49600000"], ["144.45000000", "203.35800000"], ["144.46000000", "454.82000000"], ["144.47000000", "292.09700000"], ["144.48000000", "562.64200000"], ["144.53000000", "312.23300000"], ["144.54000000", "398.79100000"], ["144.57000000", "329.27700000"], ["144.68000000", "467.05600000"], ["144.74000000", "150.61300000"], ["144.91000000", "9.40000000"], ["145.08000000", "30.80400000"], ["274.79000000", "78.68200000"]]}
{"e": "depthUpdate", "E": 1741338237795, "s": "SOLUSDT", "U": 19256850598, "u": 19256850722, "b": [["144.40000000", "95.67800000"], ["144.39000000", "45.28400000"], ["144.37000000", "81.43700000"], ["144.35000000", "832.51800000"], ["144.33000000", "712.41200000"], ["144.32000000", "380.37600000"], ["144.31000000", "678.01700000"], ["144.30000000", "276.52000000"], ["144.28000000", "299.70900000"], ["144.15000000", "470.12900000"], ["144.13000000", "404.06900000"], ["144.12000000", "157.13700000"], ["144.05000000", "348.78300000"], ["144.04000000", "287.95800000"], ["144.03000000", "254.39900000"], ["143.49000000", "99.12700000"], ["143.41000000", "58.51200000"], ["143.30000000", "329.04900000"], ["143.27000000", "1.22900000"], ["142.24000000", "0.65700000"]], "a": [["144.41000000", "123.85300000"], ["144.42000000", "31.21400000"], ["144.43000000", "57.24500000"], ["144.44000000", "44.45100000"], ["144.46000000", "288.24600000"], ["144.47000000", "295.57100000"], ["144.48000000", "703.03300000"], ["144.49000000", "644.30700000"], ["144.50000000", "410.13200000"], ["144.54000000", "399.02100000"], ["145.00000000", "1469.91500000"], ["145.19000000", "13.66600000"], ["145.49000000", "109.50500000"], ["145.57000000", "8.07100000"], ["145.92000000", "143.34800000"], ["146.37000000", "1.09800000"], ["146.65000000", "130.97900000"], ["148.58000000", "153.16400000"]]}
{"e": "depthUpdate", "E": 1741338238795, "s": "SOLUSDT", "U": 19256850723, "u": 19256850781, "b": [["144.40000000", "78.09300000"], ["144.39000000", "5.81200000"], ["144.38000000", "26.96300000"], ["144.36000000", "309.61800000"], ["144.33000000", "712.41200000"], ["144.32000000", "459.80000000"], ["144.26000000", "363.20600000"], ["144.00000000", "343.02000000"], ["143.78000000", "206.56100000"], ["143.41000000", "44.57100000"], ["143.30000000", "6.15000000"], ["142.24000000", "325.96200000"], ["141.37000000", "0.04200000"]], "a": [["144.41000000", "60.91300000"], ["144.42000000", "31.25600000"], ["144.45000000", "243.12700000"], ["144.48000000", "703.37900000"], ["144.49000000", "657.81000000"], ["144.91000000", "8.60000000"]]}
{"e": "depthUpdate", "E": 1741338239795, "s": "SOLUSDT", "U": 19256850782, "u": 19256850855, "b": [["144.40000000", "94.61400000"], ["144.39000000", "41.82200000"], ["144.38000000", "131.61700000"], ["144.37000000", "81.36300000"], ["144.36000000", "327.09800000"], ["144.34000000", "383.25900000"], ["144.33000000", "695.09200000"], ["144.31000000", "692.90900000"], ["144.11000000", "262.53000000"], ["144.01000000", "184.02800000"], ["143.91000000", "120.49300000"], ["143.30000000", "329.04900000"], ["142.24000000", "0.65700000"], ["141.55000000", "3.85800000"], ["127.00000000", "3646.32400000"]], "a": [["144.41000000", "168.85900000"], ["144.42000000", "31.21400000"], ["144.44000000", "44.45100000"], ["144.45000000", "243.12700000"], ["144.54000000", "402.66000000"], ["145.71000000", "7.06000000"]]}
{"e": "depthUpdate", "E": 1741338240795, "s": "SOLUSDT", "U": 19256850856, "u": 19256851208, "b": [["144.40000000", "0.00000000"], ["144.39000000", "0.00000000"], ["144.38000000", "76.94000000"], ["144.37000000", "19.60100000"], ["144.36000000", "16.32200000"], ["144.35000000", "206.75100000"], ["144.34000000", "254.17100000"], ["144.33000000", "685.09200000"], ["144.32000000", "458.01800000"], ["144.31000000", "424.08200000"], ["144.30000000", "395.58600000"], ["144.29000000", "634.73300000"], ["144.28000000", "296.92100000"], ["144.27000000", "370.19900000"], ["144.15000000", "469.50500000"], ["144.14000000", "550.13800000"], ["144.13000000", "496.99700000"], ["144.12000000", "186.11800000"], ["144.11000000", "411.41500000"], ["144.10000000", "316.69500000"], ["144.08000000", "222.87100000"], ["144.05000000", "371.76800000"], ["144.03000000", "323.65000000"], ["143.99000000", "378.23600000"], ["143.88000000", "54.45900000"], ["143.64000000", "131.03600000"], ["143.63000000", "77.44100000"], ["143.40000000", "0.55100000"], ["143.30000000", "6.15000000"], ["138.31000000", "33.20900000"]], "a": [["144.39000000", "246.40500000"], ["144.40000000", "309.62300000"], ["144.41000000", "124.28400000"], ["144.42000000", "352.87300000"], ["144.43000000", "67.74800000"], ["144.44000000", "147.55300000"], ["144.45000000", "414.21700000"], ["144.46000000", "288.24600000"], ["144.47000000", "294.87000000"], ["144.48000000", "552.28800000"], ["144.49000000", "729.71800000"], ["144.50000000", "441.10600000"], ["144.53000000", "326.50000000"], ["144.54000000", "391.95500000"], ["144.70000000", "667.63600000"], ["144.71000000", "422.24900000"], ["144.72000000", "350.79300000"], ["144.73000000", "126.87900000"], ["144.74000000", "88.65100000"], ["144.81000000", "219.19900000"], ["144.82000000", "477.08400000"], ["144.90000000", "67.08400000"], ["276.52000000", "0.33400000"]]}
{"e": "depthUpdate", "E": 1741338241795, "s": "SOLUSDT", "U": 19256851209, "u": 19256851330, "b": [["144.38000000", "77.49700000"], ["144.37000000", "21.65200000"], ["144.36000000", "54.98800000"], ["144.35000000", "192.54600000"], ["144.34000000", "258.77300000"], ["144.33000000", "686.06600000"], ["144.32000000", "414.30200000"], ["144.31000000", "441.75000000"], ["144.30000000", "453.17400000"], ["144.29000000", "547.12200000"], ["144.28000000", "299.69200000"], ["144.27000000", "456.77600000"], ["144.26000000", "487.53700000"], ["144.18000000", "1018.04900000"], ["144.15000000", "444.52100000"], ["144.12000000", "232.07300000"], ["144.10000000", "341.67700000"], ["143.99000000", "386.00500000"], ["143.91000000", "119.69300000"], ["143.88000000", "55.25900000"], ["143.60000000", "2.74600000"], ["143.30000000", "6.15000000"], ["143.00000000", "193.17700000"], ["142.32000000", "20.45200000"], ["142.24000000", "325.96200000"], ["51.98000000", "1.97200000"]], "a": [["144.39000000", "245.63900000"], ["144.40000000", "219.84500000"], ["144.41000000", "127.09100000"], ["144.42000000", "352.55300000"], ["144.44000000", "154.58000000"], ["144.45000000", "310.48600000"], ["144.48000000", "573.80800000"], ["144.50000000", "441.45200000"], ["144.53000000", "326.15400000"], ["144.55000000", "265.22000000"], ["144.57000000", "322.42100000"], ["144.67000000", "561.55500000"], ["144.69000000", "467.93500000"], ["144.75000000", "112.92000000"], ["144.81000000", "164.30400000"], ["145.13000000", "103.15300000"], ["145.15000000", "4.53900000"], ["145.16000000", "0.26900000"], ["145.18000000", "50.65600000"]]}
{"e": "depthUpdate", "E": 1741338242795, "s": "SOLUSDT", "U": 19256851331, "u": 19256851738, "b": [["144.38000000", "0.00000000"], ["144.37000000", "45.47000000"], ["144.36000000", "67.68900000"], ["144.35000000", "199.55800000"], ["144.34000000", "210.09400000"], ["144.33000000", "760.31500000"], ["144.32000000", "398.64800000"], ["144.31000000", "371.74200000"], ["144.30000000", "475.21100000"], ["144.29000000", "541.40400000"], ["144.28000000", "298.30100000"], ["144.27000000", "456.77600000"], ["144.26000000", "480.61000000"], ["144.25000000", "208.73100000"], ["144.23000000", "432.78600000"], ["144.21000000", "373.35800000"], ["144.18000000", "1003.56400000"], ["144.15000000", "459.13400000"], ["144.07000000", "126.11700000"], ["144.04000000", "309.94400000"], ["143.89000000", "205.95800000"], ["143.88000000", "54.45900000"], ["143.87000000", "207.24700000"], ["143.81000000", "130.48900000"], ["143.62000000", "0.12200000"], ["143.52000000", "8.02300000"], ["143.49000000", "421.59800000"], ["143.38000000", "14.04300000"], ["143.30000000", "6.15000000"], ["142.24000000", "0.65700000"], ["141.55000000", "0.24500000"]], "a": [["144.38000000", "97.88100000"], ["144.39000000", "80.35600000"], ["144.40000000", "106.90100000"], ["144.41000000", "124.40200000"], ["144.42000000", "352.51800000"], ["144.43000000", "171.92500000"], ["144.44000000", "337.98800000"], ["144.45000000", "273.87700000"], ["144.46000000", "349.66700000"], ["144.47000000", "345.32600000"], ["144.48000000", "598.79000000"], ["144.49000000", "760.69600000"], ["144.50000000", "439.45200000"], ["144.51000000", "229.17000000"], ["144.52000000", "441.11800000"], ["144.54000000", "413.93900000"], ["144.66000000", "785.56400000"], ["144.67000000", "532.57400000"], ["144.69000000", "464.93500000"], ["144.70000000", "621.66000000"], ["144.72000000", "319.80900000"], ["144.80000000", "111.31000000"], ["144.81000000", "110.57200000"], ["144.89000000", "4.54200000"], ["145.13000000", "3.03000000"], ["145.25000000", "102.23800000"]]}
{"e": "depthUpdate", "E": 1741338243795, "s": "SOLUSDT", "U": 19256851739, "u": 19256851847, "b": [["144.37000000", "1.11800000"], ["144.36000000", "29.44900000"], ["144.35000000", "95.82700000"], ["144.34000000", "204.09300000"], ["144.33000000", "683.13000000"], ["144.32000000", "400.30300000"], ["144.31000000", "370.74200000"], ["144.30000000", "417.03500000"], ["144.29000000", "644.49900000"], ["144.28000000", "248.66100000"], ["144.27000000", "321.79100000"], ["144.26000000", "510.09300000"], ["144.25000000", "295.32000000"], ["144.23000000", "418.17400000"], ["144.21000000", "358.74600000"], ["144.15000000", "473.74800000"], ["144.13000000", "511.61100000"], ["143.87000000", "206.44700000"], ["143.61000000", "38.74600000"], ["143.49000000", "421.59800000"], ["143.38000000", "0.09900000"], ["142.32000000", "0.03800000"], ["142.24000000", "0.65700000"], ["141.40000000", "4.84500000"], ["123.10000000", "25.54100000"]], "a": [["144.38000000", "127.05200000"], ["144.39000000", "80.40800000"], ["144.40000000", "106.82700000"], ["144.41000000", "124.67300000"], ["144.42000000", "380.86300000"], ["144.43000000", "231.82700000"], ["144.44000000", "350.91900000"], ["144.45000000", "377.26200000"], ["144.47000000", "374.30700000"], ["144.48000000", "567.98000000"], ["144.50000000", "470.43200000"], ["144.51000000", "229.17000000"], ["144.65000000", "484.60500000"], ["144.72000000", "288.82700000"], ["145.14000000", "110.72900000"]]}
{"e": "depthUpdate", "E": 1741338244795, "s": "SOLUSDT", "U": 19256851848, "u": 19256851901, "b": [["144.37000000", "0.87000000"], ["144.33000000", "670.70000000"], ["144.30000000", "427.81900000"], ["144.29000000", "645.19100000"], ["144.28000000", "247.96900000"], ["144.27000000", "370.19900000"], ["143.71000000", "31.10200000"], ["143.61000000", "38.67600000"], ["143.49000000", "418.50200000"], ["143.48000000", "3.28200000"], ["143.46000000", "252.29100000"], ["143.37000000", "16.92800000"]], "a": [["144.38000000", "227.05200000"], ["144.40000000", "106.82700000"], ["144.42000000", "417.23100000"], ["144.43000000", "236.46500000"], ["144.48000000", "627.01600000"], ["144.50000000", "468.43200000"], ["144.66000000", "788.56400000"], ["144.69000000", "461.93500000"], ["144.71000000", "328.92400000"], ["144.87000000", "5.67800000"]]}
{"e": "depthUpdate", "E": 1741338245795, "s": "SOLUSDT", "U": 19256851902, "u": 19256852502, "b": [["144.37000000", "0.00000000"], ["144.36000000", "0.00000000"], ["144.35000000", "0.00000000"], ["144.34000000", "50.24900000"], ["144.33000000", "102.30200000"], ["144.32000000", "292.78300000"], ["144.31000000", "338.30000000"], ["144.30000000", "436.24900000"], ["144.29000000", "698.35000000"], ["144.28000000", "432.83500000"], ["144.27000000", "298.92900000"], ["144.26000000", "369.27800000"], ["144.25000000", "206.64800000"], ["144.24000000", "299.91400000"], ["144.23000000", "527.60200000"], ["144.22000000", "195.04900000"], ["144.20000000", "578.84000000"], ["144.18000000", "1003.51500000"], ["144.17000000", "1034.65800000"], ["144.16000000", "1095.73300000"], ["144.15000000", "413.78900000"], ["144.14000000", "579.51000000"], ["144.13000000", "480.68600000"], ["144.12000000", "246.68700000"], ["144.10000000", "359.75700000"], ["144.09000000", "285.66900000"], ["144.08000000", "348.89500000"], ["144.07000000", "161.98200000"], ["144.06000000", "355.25100000"], ["144.05000000", "386.85700000"], ["144.04000000", "383.55800000"], ["144.01000000", "219.90800000"], ["143.90000000", "316.99100000"], ["143.84000000", "466.03400000"], ["143.83000000", "91.24000000"], ["143.61000000", "38.74600000"], ["143.60000000", "2.81600000"], ["143.59000000", "44.46200000"], ["143.50000000", "27.30200000"], ["143.49000000", "96.03100000"], ["143.37000000", "2.98300000"], ["143.19000000", "323.35800000"], ["142.24000000", "0.65700000"]], "a": [["144.35000000", "263.56100000"], ["144.36000000", "155.23500000"], ["144.37000000", "236.02900000"], ["144.38000000", "39.20300000"], ["144.39000000", "88.77600000"], ["144.40000000", "197.41000000"], ["144.41000000", "348.24500000"], ["144.42000000", "714.45900000"], ["144.43000000", "291.83800000"], ["144.44000000", "564.28800000"], ["144.45000000", "444.24900000"], ["144.46000000", "214.60200000"], ["144.47000000", "457.09300000"], ["144.48000000", "707.95200000"], ["144.49000000", "640.73700000"], ["144.50000000", "450.79300000"], ["144.51000000", "248.61000000"], ["144.52000000", "459.70000000"], ["144.53000000", "363.00200000"], ["144.54000000", "308.75000000"], ["144.55000000", "258.39000000"], ["144.57000000", "322.47000000"], ["144.58000000", "337.38400000"], ["144.60000000", "622.78400000"], ["144.62000000", "524.21500000"], ["144.63000000", "532.16900000"], ["144.64000000", "334.07300000"], ["144.65000000", "469.99300000"], ["144.68000000", "301.42700000"], ["144.69000000", "281.97200000"], ["144.70000000", "472.66100000"], ["144.71000000", "288.97500000"], ["144.77000000", "168.00900000"], ["144.78000000", "97.46100000"], ["144.79000000", "3.72400000"], ["144.80000000", "58.09400000"], ["144.87000000", "3.37800000"], ["145.01000000", "828.20500000"], ["145.07000000", "11.64000000"], ["145.08000000", "2.00400000"], ["145.10000000", "143.52800000"], ["145.12000000", "18.75600000"], ["145.13000000", "2.96000000"], ["145.25000000", "2.11500000"], ["145.61000000", "19.87800000"], ["145.66000000", "5.51100000"], ["274.79000000", "78.55000000"]]}
{"e": "depthUpdate", "E": 1741338246795, "s": "SOLUSDT", "U": 19256852503, "u": 19256852578, "b": [["144.34000000", "102.62200000"], ["144.32000000", "310.10500000"], ["144.31000000", "355.54900000"], ["144.29000000", "681.02600000"], ["144.28000000", "416.20400000"], ["144.22000000", "228.97300000"], ["144.21000000", "483.32900000"], ["144.13000000", "481.82300000"], ["144.12000000", "246.75900000"], ["144.05000000", "330.83900000"], ["144.00000000", "397.88400000"], ["143.83000000", "91.27600000"], ["143.35000000", "0.03700000"], ["135.00000000", "15985.53900000"]], "a": [["144.35000000", "17.62000000"], ["144.36000000", "67.54700000"], ["144.37000000", "120.23700000"], ["144.38000000", "39.27700000"], ["144.39000000", "87.77700000"], ["144.40000000", "197.37400000"], ["144.41000000", "347.89900000"], ["144.42000000", "749.87500000"], ["144.49000000", "763.49700000"], ["145.11000000", "121.56700000"], ["274.79000000", "78.68200000"]]}
{"e": "depthUpdate", "E": 1741338247795, "s": "SOLUSDT", "U": 19256852579, "u": 19256853002, "b": [["144.36000000", "1.59500000"], ["144.35000000", "5.69000000"], ["144.34000000", "31.16700000"], ["144.33000000", "103.95700000"], ["144.32000000", "294.70700000"], ["144.31000000", "454.40700000"], ["144.30000000", "402.24800000"], ["144.29000000", "699.04200000"], ["144.28000000", "422.43800000"], ["144.27000000", "293.00200000"], ["144.26000000", "421.26300000"], ["144.25000000", "208.73100000"], ["144.23000000", "527.60200000"], ["144.22000000", "194.04900000"], ["144.21000000", "358.74600000"], ["144.20000000", "509.49600000"], ["143.87000000", "206.44700000"], ["143.86000000", "79.62700000"], ["143.84000000", "466.03400000"], ["143.83000000", "91.24000000"], ["143.60000000", "2.74600000"], ["143.59000000", "44.39200000"], ["143.47000000", "362.95100000"], ["143.19000000", "0.21100000"], ["135.00000000", "15985.73900000"], ["130.00000000", "25659.14000000"]], "a": [["144.35000000", "0.00000000"], ["144.36000000", "0.00000000"], ["144.37000000", "154.01200000"], ["144.38000000", "57.66200000"], ["144.39000000", "65.64000000"], ["144.40000000", "47.44200000"], ["144.41000000", "288.53300000"], ["144.42000000", "604.72800000"], ["144.43000000", "321.65200000"], ["144.44000000", "563.25200000"], ["144.45000000", "373.23700000"], ["144.49000000", "763.49700000"], ["144.50000000", "388.83300000"], ["144.51000000", "248.61000000"], ["144.53000000", "356.21400000"], ["144.63000000", "590.13500000"], ["144.64000000", "348.68900000"], ["144.65000000", "472.99300000"], ["144.68000000", "298.42700000"], ["144.69000000", "312.95600000"], ["144.70000000", "503.64300000"], ["144.78000000", "152.22300000"], ["145.08000000", "30.80400000"], ["145.10000000", "43.40500000"], ["145.11000000", "121.63700000"], ["145.12000000", "18.82600000"], ["145.25000000", "102.23800000"]]}
{"e": "depthUpdate", "E": 1741338248795, "s": "SOLUSDT", "U": 19256853003, "u": 19256853279, "b": [["144.36000000", "0.00000000"], ["144.35000000", "0.00000000"], ["144.34000000", "103.52900000"], ["144.33000000", "104.30200000"], ["144.32000000", "303.78300000"], ["144.31000000", "438.48200000"], ["144.30000000", "418.24800000"], ["144.29000000", "698.35000000"], ["144.28000000", "425.55900000"], ["144.27000000", "292.00200000"], ["144.26000000", "421.78000000"], ["144.25000000", "258.53700000"], ["144.24000000", "354.26400000"], ["144.23000000", "657.34300000"], ["144.21000000", "359.74600000"], ["143.85000000", "85.03600000"], ["143.83000000", "120.07600000"], ["143.60000000", "2.81600000"], ["143.59000000", "44.46200000"], ["143.47000000", "40.43500000"], ["143.36000000", "0.25000000"], ["143.19000000", "323.35800000"]], "a": [["144.35000000", "108.90600000"], ["144.36000000", "118.17700000"], ["144.37000000", "84.15000000"], ["144.38000000", "37.11200000"], ["144.39000000", "64.45800000"], ["144.40000000", "138.64300000"], ["144.41000000", "348.43500000"], ["144.42000000", "605.07400000"], ["144.43000000", "295.30000000"], ["144.44000000", "566.39400000"], ["144.45000000", "406.04600000"], ["144.46000000", "243.58300000"], ["144.48000000", "706.54100000"], ["144.49000000", "763.49700000"], ["144.50000000", "390.56400000"], ["144.53000000", "363.08800000"], ["144.62000000", "495.23200000"], ["144.63000000", "532.16900000"], ["144.64000000", "334.07300000"], ["144.78000000", "97.46100000"], ["145.10000000", "143.52800000"], ["145.11000000", "121.56700000"], ["145.12000000", "18.75600000"], ["145.25000000", "2.11500000"], ["148.67000000", "0.56200000"]]}
{"e": "depthUpdate", "E": 1741338249795, "s": "SOLUSDT", "U": 19256853280, "u": 19256853318, "b": [["144.34000000", "74.72900000"], ["144.33000000", "107.76400000"], ["144.32000000", "292.78300000"], ["144.29000000", "698.35100000"], ["144.27000000", "395.97300000"], ["144.23000000", "654.75100000"], ["144.17000000", "1009.67400000"], ["144.11000000", "408.41500000"], ["144.09000000", "310.65500000"]], "a": [["144.35000000", "106.79400000"], ["144.36000000", "81.82400000"], ["144.39000000", "64.53000000"], ["144.41000000", "386.45300000"], ["144.42000000", "708.80500000"], ["144.64000000", "337.07300000"], ["144.67000000", "529.57400000"], ["276.52000000", "0.20300000"]]}
