{"e": "depthUpdate", "E": 1742561033014, "s": "BTCUSDT", "U": 64610511813, "u": 64610512461, "b": [["83711.99000000", "5.36470000"], ["83711.80000000", "0.45007000"], ["83711.56000000", "0.00007000"], ["83711.49000000", "0.00006000"], ["83710.80000000", "0.00000000"], ["83710.38000000", "0.00000000"], ["83710.29000000", "0.00000000"], ["83710.20000000", "0.00006000"], ["83710.00000000", "0.02820000"], ["83709.30000000", "0.00000000"], ["83708.60000000", "0.00006000"], ["83707.97000000", "0.02794000"], ["83707.93000000", "0.01500000"], ["83707.82000000", "0.00754000"], ["83707.74000000", "0.00000000"], ["83707.62000000", "0.00000000"], ["83707.20000000", "0.00000000"], ["83707.14000000", "0.00000000"], ["83706.67000000", "0.01500000"], ["83706.50000000", "0.00000000"], ["83706.33000000", "0.00000000"], ["83706.04000000", "0.42205000"], ["83706.03000000", "0.71594000"], ["83705.90000000", "0.00008000"], ["83705.72000000", "0.00000000"], ["83704.50000000", "0.06000000"], ["83703.65000000", "0.00000000"], ["83703.33000000", "0.00119000"], ["83703.06000000", "0.00000000"], ["83702.60000000", "0.08000000"], ["83702.58000000", "0.00000000"], ["83702.39000000", "0.00000000"], ["83701.94000000", "0.00000000"], ["83701.54000000", "0.00109000"], ["83701.37000000", "0.00989000"], ["83701.25000000", "0.00000000"], ["83700.96000000", "0.00000000"], ["83700.02000000", "0.51076000"], ["83699.97000000", "0.00051000"], ["83699.80000000", "0.00000000"], ["83699.52000000", "0.00000000"], ["83698.74000000", "0.00000000"], ["83698.61000000", "0.01194000"], ["83698.50000000", "0.00000000"], ["83698.49000000", "0.72509000"], ["83698.48000000", "0.80247000"], ["83698.14000000", "0.00000000"], ["83696.99000000", "0.00000000"], ["83696.09000000", "0.12304000"], ["83696.06000000", "0.16000000"], ["83695.37000000", "0.89402000"], ["83694.77000000", "1.15446000"], ["83694.76000000", "0.00000000"], ["83694.26000000", "0.00000000"], ["83694.25000000", "0.00000000"], ["83694.23000000", "0.00000000"], ["83693.93000000", "0.00000000"], ["83693.83000000", "0.00000000"], ["83693.24000000", "0.89402000"], ["83692.78000000", "1.37912000"], ["83692.13000000", "0.01000000"], ["83689.69000000", "0.00000000"], ["83689.15000000", "0.00000000"], ["83688.55000000", "0.89402000"], ["83687.78000000", "0.02351000"], ["83687.37000000", "0.00000000"], ["83683.06000000", "0.00000000"], ["83682.51000000", "0.37851000"], ["83682.11000000", "1.00874000"], ["83681.31000000", "0.59756000"], ["83680.49000000", "0.89402000"], ["83679.72000000", "0.86083000"], ["83679.18000000", "0.00313000"], ["83674.09000000", "0.47681000"], ["83672.83000000", "0.00000000"], ["83670.15000000", "0.00000000"], ["83668.19000000", "0.00000000"], ["83667.28000000", "0.00000000"], ["83666.42000000", "0.00000000"], ["83659.00000000", "0.00000000"], ["83653.67000000", "0.00000000"], ["83647.16000000", "0.65417000"], ["83636.41000000", "0.21211000"], ["83630.20000000", "0.00000000"], ["83630.17000000", "0.00000000"], ["83628.54000000", "0.00000000"], ["83626.35000000", "0.00000000"], ["83626.04000000", "0.00000000"], ["83621.32000000", "0.00000000"], ["83595.52000000", "0.00000000"], ["83588.08000000", "0.00400000"], ["83540.89000000", "0.00000000"], ["83534.11000000", "0.00000000"], ["83510.53000000", "0.00076000"], ["83510.52000000", "0.00527000"], ["83510.51000000", "0.00000000"], ["83300.00000000", "3.50891000"], ["83143.12000000", "0.00019000"], ["82504.77000000", "0.00000000"], ["82456.32000000", "0.00011000"], ["82456.31000000", "0.00100000"], ["81871.32000000", "0.00000000"], ["81242.73000000", "0.00000000"], ["80618.97000000", "0.00000000"], ["80347.44000000", "0.03582000"], ["80000.00000000", "155.65345000"], ["75340.00000000", "0.00000000"], ["75339.00000000", "0.01979000"], ["66969.60000000", "0.00058000"], ["63500.00000000", "17.50655000"], ["42000.01000000", "0.53385000"], ["42000.00000000", "6.85161000"], ["33000.00000000", "2.93827000"], ["30136.32000000", "0.00080000"]], "a": [["83712.00000000", "2.32421000"], ["83712.33000000", "0.00007000"], ["83712.67000000", "0.00014000"], ["83712.68000000", "0.28112000"], ["83712.95000000", "0.00000000"], ["83713.00000000", "0.00000000"], ["83713.01000000", "0.00000000"], ["83713.02000000", "0.00000000"], ["83713.57000000", "0.00000000"], ["83713.58000000", "0.00000000"], ["83713.66000000", "0.00007000"], ["83713.75000000", "0.00014000"], ["83713.76000000", "0.16081000"], ["83713.77000000", "0.00000000"], ["83713.94000000", "0.00000000"], ["83713.95000000", "0.00000000"], ["83713.96000000", "0.00000000"], ["83713.98000000", "0.00000000"], ["83713.99000000", "0.00013000"], ["83714.00000000", "0.02833000"], ["83714.60000000", "0.00000000"], ["83714.63000000", "0.00000000"], ["83714.64000000", "0.08011000"], ["83715.04000000", "0.00000000"], ["83715.05000000", "0.00000000"], ["83715.85000000", "0.02213000"], ["83715.94000000", "0.00007000"], ["83715.95000000", "0.02472000"], ["83715.99000000", "0.00000000"], ["83716.00000000", "0.02820000"], ["83716.20000000", "0.00500000"], ["83717.37000000", "0.00000000"], ["83717.38000000", "0.00000000"], ["83717.39000000", "0.00000000"], ["83717.46000000", "0.00000000"], ["83717.47000000", "0.25451000"], ["83717.48000000", "0.78874000"], ["83717.78000000", "0.00000000"], ["83719.26000000", "0.00000000"], ["83719.33000000", "0.00000000"], ["83719.42000000", "0.00000000"], ["83719.43000000", "0.00000000"], ["83719.87000000", "0.00000000"], ["83719.88000000", "0.00000000"], ["83720.23000000", "0.00119000"], ["83721.59000000", "0.00000000"], ["83722.15000000", "0.01827000"], ["83722.34000000", "0.00000000"], ["83722.80000000", "0.00000000"], ["83723.25000000", "0.11951000"], ["83723.48000000", "0.00000000"], ["83723.82000000", "0.00000000"], ["83724.79000000", "0.00000000"], ["83724.83000000", "0.28598000"], ["83725.48000000", "0.00000000"], ["83725.50000000", "0.00000000"], ["83725.60000000", "0.04000000"], ["83725.61000000", "0.00000000"], ["83726.41000000", "0.04000000"], ["83726.85000000", "0.00000000"], ["83727.06000000", "0.00757000"], ["83727.25000000", "0.04000000"], ["83727.28000000", "0.04000000"], ["83727.39000000", "0.04400000"], ["83727.54000000", "0.00000000"], ["83727.73000000", "0.00000000"], ["83728.01000000", "0.00000000"], ["83728.99000000", "0.00000000"], ["83729.66000000", "0.00000000"], ["83729.67000000", "0.00000000"], ["83729.69000000", "0.00000000"], ["83729.78000000", "0.04800000"], ["83729.95000000", "0.00000000"], ["83730.60000000", "0.04800000"], ["83730.72000000", "0.00000000"], ["83731.35000000", "0.00000000"], ["83731.44000000", "0.10508000"], ["83731.50000000", "0.00012000"], ["83731.56000000", "0.04400000"], ["83732.68000000", "0.00000000"], ["83732.81000000", "0.41366000"], ["83733.68000000", "0.00000000"], ["83734.10000000", "0.00000000"], ["83734.57000000", "0.00000000"], ["83734.58000000", "0.00000000"], ["83735.19000000", "0.00000000"], ["83735.53000000", "0.00000000"], ["83736.30000000", "0.00000000"], ["83736.38000000", "0.09600000"], ["83736.50000000", "0.00000000"], ["83736.62000000", "0.00000000"], ["83736.95000000", "1.69384000"], ["83737.22000000", "0.00000000"], ["83737.84000000", "0.00000000"], ["83738.66000000", "0.00000000"], ["83738.88000000", "0.00000000"], ["83738.94000000", "0.00000000"], ["83739.04000000", "0.35761000"], ["83739.20000000", "0.11920000"], ["83739.48000000", "0.00000000"], ["83739.66000000", "0.71594000"], ["83740.10000000", "0.00000000"], ["83740.69000000", "0.45000000"], ["83740.86000000", "0.86020000"], ["83742.04000000", "0.17207000"], ["83742.78000000", "1.32598000"], ["83743.14000000", "0.00500000"], ["83743.18000000", "0.00000000"], ["83743.94000000", "0.01000000"], ["83744.05000000", "0.47681000"], ["83745.40000000", "0.00500000"], ["83746.20000000", "0.01000000"], ["83746.56000000", "0.59601000"], ["83748.29000000", "0.59755000"], ["83749.29000000", "0.00000000"], ["83749.84000000", "0.01194000"], ["83749.96000000", "0.00000000"], ["83749.99000000", "0.00000000"], ["83750.64000000", "0.00000000"], ["83750.79000000", "0.00000000"], ["83750.91000000", "0.00000000"], ["83751.11000000", "0.00000000"], ["83754.98000000", "0.00000000"], ["83755.21000000", "0.14000000"], ["83756.55000000", "0.00000000"], ["83757.53000000", "0.00000000"], ["83758.45000000", "0.00000000"], ["83761.61000000", "0.00000000"], ["83761.75000000", "0.16000000"], ["83762.46000000", "0.00000000"], ["83762.47000000", "0.00000000"], ["83762.48000000", "0.00000000"], ["83762.91000000", "0.00000000"], ["83765.86000000", "0.00000000"], ["83766.17000000", "0.00000000"], ["83767.14000000", "0.12275000"], ["83772.64000000", "0.00000000"], ["83776.90000000", "0.00000000"], ["83777.37000000", "0.01826000"], ["83778.19000000", "0.00000000"], ["83786.48000000", "0.00000000"], ["83788.61000000", "0.00000000"], ["83788.97000000", "0.00000000"], ["83789.09000000", "0.00699000"], ["83793.78000000", "0.09577000"], ["83794.50000000", "0.00699000"], ["83794.63000000", "0.09600000"], ["83796.04000000", "0.00000000"], ["83796.89000000", "0.31033000"], ["83797.70000000", "0.04000000"], ["83797.89000000", "0.00000000"], ["83799.16000000", "0.00000000"], ["83800.12000000", "0.00000000"], ["83800.24000000", "0.04800000"], ["83800.58000000", "0.00041000"], ["83800.96000000", "0.24423000"], ["83811.56000000", "0.00000000"], ["83813.66000000", "0.35580000"], ["83817.03000000", "0.00060000"], ["83854.02000000", "0.04498000"], ["83875.46000000", "0.00000000"], ["83875.98000000", "0.00035000"], ["83885.30000000", "0.00000000"], ["83887.25000000", "0.00000000"], ["83888.30000000", "0.00000000"], ["83889.10000000", "0.01000000"], ["84012.52000000", "0.99915000"], ["84434.68000000", "0.00000000"], ["84967.68000000", "0.00100000"], ["85087.96000000", "0.00000000"], ["85746.30000000", "0.00000000"], ["86409.73000000", "0.00000000"], ["87078.30000000", "0.00000000"], ["87752.04000000", "0.00000000"], ["88430.99000000", "0.00000000"], ["89115.19000000", "0.00000000"], ["89804.69000000", "0.00000000"], ["90499.52000000", "0.00000000"], ["91199.73000000", "0.00000000"], ["91905.36000000", "0.00000000"], ["92616.44000000", "0.00000000"], ["93333.03000000", "0.01707000"], ["94055.16000000", "0.00000000"], ["94782.88000000", "0.00000000"], ["95516.23000000", "0.00000000"], ["96255.25000000", "0.00000000"], ["97000.00000000", "43.92812000"]], "record_time": 1742561033.178855, "EXCHANGE": "BINANCE"}
{"e": "depthUpdate", "E": 1742561034014, "s": "BTCUSDT", "U": 64610512462, "u": 64610513162, "b": [["83711.99000000", "2.68947000"], ["83711.98000000", "0.00048000"], ["83711.96000000", "0.00000000"], ["83711.90000000", "0.00007000"], ["83711.82000000", "0.17180000"], ["83711.81000000", "0.00007000"], ["83711.80000000", "0.00007000"], ["83711.62000000", "0.00000000"], ["83711.58000000", "0.00021000"], ["83711.57000000", "0.78879000"], ["83711.56000000", "0.00000000"], ["83711.49000000", "0.00000000"], ["83710.62000000", "0.00000000"], ["83710.61000000", "0.06751000"], ["83710.20000000", "0.00006000"], ["83710.00000000", "0.02820000"], ["83709.58000000", "0.00000000"], ["83709.57000000", "0.00006000"], ["83709.20000000", "0.00000000"], ["83708.60000000", "0.00000000"], ["83708.28000000", "0.02220000"], ["83708.04000000", "0.02314000"], ["83707.97000000", "0.00000000"], ["83707.93000000", "0.00000000"], ["83707.74000000", "0.00000000"], ["83706.67000000", "0.00000000"], ["83706.07000000", "0.00000000"], ["83706.05000000", "0.00000000"], ["83706.04000000", "0.23685000"], ["83706.03000000", "0.00000000"], ["83706.00000000", "0.02826000"], ["83705.03000000", "0.01500000"], ["83705.00000000", "0.00000000"], ["83704.50000000", "0.00000000"], ["83704.37000000", "0.07097000"], ["83703.77000000", "0.01500000"], ["83703.37000000", "0.00029000"], ["83703.33000000", "0.01050000"], ["83702.60000000", "0.00000000"], ["83701.54000000", "0.00013000"], ["83701.37000000", "0.00898000"], ["83701.00000000", "0.14000000"], ["83700.83000000", "0.00000000"], ["83700.79000000", "0.00092000"], ["83700.56000000", "0.00000000"], ["83700.55000000", "0.00416000"], ["83700.46000000", "0.00096000"], ["83700.33000000", "0.01863000"], ["83700.01000000", "0.89512000"], ["83698.61000000", "0.00000000"], ["83697.80000000", "0.00000000"], ["83696.18000000", "0.00059000"], ["83696.09000000", "0.00119000"], ["83696.06000000", "0.00000000"], ["83695.23000000", "0.00000000"], ["83694.25000000", "0.00000000"], ["83694.06000000", "0.16000000"], ["83693.77000000", "0.01194000"], ["83693.74000000", "0.00000000"], ["83693.53000000", "0.00000000"], ["83693.44000000", "0.00000000"], ["83693.43000000", "0.00000000"], ["83693.24000000", "0.00000000"], ["83692.13000000", "0.00000000"], ["83691.93000000", "0.00000000"], ["83691.83000000", "0.01000000"], ["83691.81000000", "0.12287000"], ["83690.33000000", "0.00000000"], ["83690.05000000", "0.86073000"], ["83689.61000000", "0.00000000"], ["83689.08000000", "0.59601000"], ["83687.85000000", "0.00000000"], ["83686.86000000", "0.05960000"], ["83684.66000000", "0.00000000"], ["83683.60000000", "0.00000000"], ["83682.00000000", "0.03583000"], ["83681.31000000", "0.00000000"], ["83680.49000000", "0.00000000"], ["83680.48000000", "0.00000000"], ["83679.76000000", "0.86083000"], ["83679.72000000", "0.00000000"], ["83678.94000000", "0.89402000"], ["83677.49000000", "0.34730000"], ["83675.68000000", "0.00000000"], ["83674.13000000", "0.05821000"], ["83673.71000000", "0.59761000"], ["83673.58000000", "0.00000000"], ["83668.12000000", "0.00000000"], ["83666.88000000", "0.05975000"], ["83666.55000000", "0.89422000"], ["83665.17000000", "0.04000000"], ["83663.11000000", "0.07181000"], ["83661.05000000", "0.00000000"], ["83658.65000000", "0.04469000"], ["83650.19000000", "0.00000000"], ["83649.92000000", "0.00000000"], ["83648.41000000", "0.59601000"], ["83642.67000000", "0.27500000"], ["83635.90000000", "0.00000000"], ["83624.21000000", "0.00000000"], ["83608.81000000", "0.00000000"], ["83600.93000000", "0.00000000"], ["83597.97000000", "0.05497000"], ["83597.88000000", "0.00091000"], ["83594.94000000", "0.04897000"], ["83588.08000000", "0.00000000"], ["83586.32000000", "0.00000000"], ["83582.80000000", "0.00000000"], ["83575.84000000", "0.00400000"], ["83540.89000000", "0.00316000"], ["83534.09000000", "0.00119000"], ["83510.54000000", "0.00000000"], ["83510.53000000", "0.00000000"], ["83510.52000000", "0.00000000"], ["83510.50000000", "0.00092000"], ["82456.31000000", "0.00000000"], ["75340.79000000", "0.00025000"], ["75340.00000000", "0.00000000"], ["75339.00000000", "0.01979000"], ["66969.60000000", "0.00058000"], ["33000.01000000", "0.00076000"], ["33000.00000000", "2.93827000"]], "a": [["83712.00000000", "3.44949000"], ["83712.07000000", "0.00007000"], ["83712.16000000", "0.00000000"], ["83712.17000000", "0.00000000"], ["83712.28000000", "0.00021000"], ["83712.29000000", "0.15758000"], ["83712.30000000", "0.14769000"], ["83712.32000000", "0.00007000"], ["83712.33000000", "0.00000000"], ["83712.65000000", "0.00000000"], ["83712.66000000", "0.00000000"], ["83712.67000000", "0.00000000"], ["83712.68000000", "0.00000000"], ["83713.21000000", "0.00000000"], ["83713.25000000", "0.00000000"], ["83713.26000000", "0.00000000"], ["83713.27000000", "0.00000000"], ["83713.48000000", "0.00336000"], ["83713.54000000", "0.00000000"], ["83713.55000000", "0.00006000"], ["83713.66000000", "0.00007000"], ["83713.75000000", "0.00000000"], ["83713.76000000", "0.00000000"], ["83713.99000000", "0.00000000"], ["83714.00000000", "0.02827000"], ["83714.36000000", "0.00014000"], ["83714.37000000", "0.78884000"], ["83714.61000000", "0.00000000"], ["83714.63000000", "0.00000000"], ["83714.64000000", "0.00000000"], ["83714.95000000", "0.00000000"], ["83714.96000000", "0.00000000"], ["83715.40000000", "0.00000000"], ["83715.41000000", "0.00006000"], ["83715.84000000", "0.00000000"], ["83715.85000000", "0.13902000"], ["83715.94000000", "0.00000000"], ["83715.95000000", "0.02478000"], ["83716.00000000", "0.02820000"], ["83716.68000000", "0.00000000"], ["83716.69000000", "0.05470000"], ["83716.70000000", "0.00000000"], ["83717.24000000", "0.00000000"], ["83717.39000000", "0.00000000"], ["83717.40000000", "0.12268000"], ["83717.44000000", "0.00000000"], ["83717.46000000", "0.00000000"], ["83717.47000000", "0.00000000"], ["83717.48000000", "0.00000000"], ["83717.75000000", "0.00000000"], ["83719.24000000", "0.00000000"], ["83719.25000000", "0.00000000"], ["83719.44000000", "0.00000000"], ["83719.45000000", "0.00000000"], ["83720.38000000", "0.45000000"], ["83721.44000000", "0.17918000"], ["83721.59000000", "0.00000000"], ["83722.15000000", "0.00000000"], ["83722.16000000", "0.01768000"], ["83722.43000000", "0.00012000"], ["83723.06000000", "0.00000000"], ["83723.07000000", "0.00000000"], ["83723.22000000", "0.00000000"], ["83724.51000000", "0.00012000"], ["83728.80000000", "0.00000000"], ["83730.37000000", "0.17207000"], ["83731.43000000", "0.08338000"], ["83731.45000000", "0.35761000"], ["83731.50000000", "0.00000000"], ["83733.22000000", "0.01194000"], ["83735.53000000", "0.03584000"], ["83736.38000000", "0.00000000"], ["83736.69000000", "0.59761000"], ["83736.70000000", "0.86025000"], ["83736.74000000", "0.00000000"], ["83736.95000000", "0.60023000"], ["83737.81000000", "0.01000000"], ["83740.01000000", "0.01194000"], ["83740.86000000", "0.00000000"], ["83741.02000000", "0.86020000"], ["83742.77000000", "1.38078000"], ["83746.20000000", "0.00000000"], ["83748.29000000", "0.00000000"], ["83749.84000000", "0.00000000"], ["83750.01000000", "0.00000000"], ["83751.20000000", "0.00500000"], ["83753.69000000", "0.00000000"], ["83754.08000000", "0.00000000"], ["83754.30000000", "0.00000000"], ["83755.21000000", "0.14000000"], ["83757.86000000", "0.05736000"], ["83762.85000000", "0.11740000"], ["83767.14000000", "0.00000000"], ["83773.32000000", "0.04062000"], ["83776.78000000", "0.00000000"], ["83778.01000000", "0.04400000"], ["83786.70000000", "0.00000000"], ["83793.07000000", "0.00699000"], ["83797.70000000", "0.00000000"], ["83800.24000000", "0.00000000"], ["83800.96000000", "0.20423000"], ["83808.75000000", "0.02390000"], ["83840.73000000", "0.08368000"], ["83841.07000000", "0.00000000"], ["83858.74000000", "0.00000000"], ["83862.91000000", "0.00000000"], ["83864.53000000", "0.00844000"], ["83889.10000000", "0.01000000"], ["83889.56000000", "0.00000000"], ["83890.51000000", "0.00000000"], ["84967.68000000", "0.00000000"], ["84990.80000000", "0.05893000"]], "record_time": 1742561034.185897, "EXCHANGE": "BINANCE"}
{"e": "depthUpdate", "E": 1742561035014, "s": "BTCUSDT", "U": 64610513163, "u": 64610513974, "b": [["83711.99000000", "0.39701000"], ["83711.98000000", "0.00048000"], ["83711.83000000", "0.00007000"], ["83711.82000000", "0.00007000"], ["83711.80000000", "0.00007000"], ["83711.60000000", "0.00007000"], ["83711.59000000", "0.00000000"], ["83711.58000000", "0.00000000"], ["83711.57000000", "0.00000000"], ["83711.50000000", "0.00201000"], ["83711.21000000", "0.00000000"], ["83711.20000000", "0.00000000"], ["83711.16000000", "0.00014000"], ["83711.15000000", "0.35985000"], ["83711.14000000", "0.00000000"], ["83711.11000000", "0.00000000"], ["83711.10000000", "0.00000000"], ["83710.62000000", "0.00000000"], ["83710.61000000", "0.00000000"], ["83710.29000000", "0.00000000"], ["83710.20000000", "0.00000000"], ["83710.01000000", "0.00000000"], ["83710.00000000", "0.00000000"], ["83709.57000000", "0.00000000"], ["83709.23000000", "0.00000000"], ["83709.22000000", "0.00000000"], ["83709.21000000", "0.00000000"], ["83709.00000000", "0.00000000"], ["83708.99000000", "0.09971000"], ["83708.98000000", "0.17213000"], ["83708.81000000", "0.00000000"], ["83708.80000000", "0.00000000"], ["83708.62000000", "0.00000000"], ["83708.61000000", "0.15448000"], ["83708.28000000", "0.00000000"], ["83708.05000000", "0.00007000"], ["83708.04000000", "0.02314000"], ["83707.83000000", "0.00000000"], ["83707.81000000", "0.00000000"], ["83707.33000000", "0.17242000"], ["83707.32000000", "0.05200000"], ["83707.02000000", "0.00007000"], ["83707.01000000", "0.02213000"], ["83706.07000000", "0.00000000"], ["83706.05000000", "0.00000000"], ["83706.04000000", "0.00000000"], ["83706.01000000", "0.00000000"], ["83706.00000000", "0.02826000"], ["83705.03000000", "0.00000000"], ["83704.37000000", "0.03097000"], ["83703.96000000", "0.00000000"], ["83703.77000000", "0.00000000"], ["83703.68000000", "0.00000000"], ["83703.62000000", "0.00000000"], ["83703.61000000", "0.45300000"], ["83703.33000000", "0.00119000"], ["83703.19000000", "0.00000000"], ["83703.12000000", "0.00000000"], ["83702.28000000", "0.00000000"], ["83702.14000000", "0.00000000"], ["83701.61000000", "0.00091000"], ["83701.37000000", "0.00000000"], ["83701.05000000", "0.00092000"], ["83701.00000000", "0.00000000"], ["83700.87000000", "0.04000000"], ["83700.33000000", "0.00000000"], ["83700.13000000", "0.00000000"], ["83700.12000000", "0.60960000"], ["83700.11000000", "0.71594000"], ["83700.02000000", "0.00000000"], ["83700.01000000", "0.17918000"], ["83699.93000000", "0.00898000"], ["83699.78000000", "0.00000000"], ["83699.55000000", "0.00018000"], ["83699.35000000", "0.00000000"], ["83699.29000000", "0.00000000"], ["83698.93000000", "0.00000000"], ["83698.67000000", "0.00000000"], ["83698.49000000", "0.13651000"], ["83698.48000000", "0.00000000"], ["83698.10000000", "0.00000000"], ["83698.09000000", "0.00000000"], ["83697.95000000", "0.00000000"], ["83697.81000000", "0.00000000"], ["83697.07000000", "0.00000000"], ["83697.01000000", "0.00000000"], ["83696.95000000", "0.00000000"], ["83696.83000000", "0.00000000"], ["83696.23000000", "0.01500000"], ["83696.18000000", "0.00000000"], ["83695.37000000", "0.00000000"], ["83694.97000000", "0.01500000"], ["83694.77000000", "0.31439000"], ["83694.48000000", "0.00000000"], ["83694.40000000", "0.02794000"], ["83694.06000000", "0.00000000"], ["83693.97000000", "0.00000000"], ["83693.96000000", "0.04009000"], ["83693.63000000", "0.00000000"], ["83693.10000000", "0.04000000"], ["83693.06000000", "0.00000000"], ["83692.88000000", "0.14000000"], ["83692.83000000", "0.00000000"], ["83692.79000000", "0.00000000"], ["83692.78000000", "0.00000000"], ["83692.72000000", "0.00000000"], ["83692.64000000", "0.00000000"], ["83692.42000000", "0.00000000"], ["83692.30000000", "0.04368000"], ["83692.23000000", "0.04000000"], ["83692.11000000", "0.04000000"], ["83691.83000000", "0.00000000"], ["83691.81000000", "0.00000000"], ["83691.56000000", "0.00000000"], ["83691.43000000", "0.00000000"], ["83691.23000000", "0.00000000"], ["83691.16000000", "0.00000000"], ["83690.52000000", "0.00119000"], ["83690.26000000", "0.00000000"], ["83690.05000000", "0.00000000"], ["83689.95000000", "0.00000000"], ["83689.84000000", "0.00000000"], ["83689.76000000", "0.04000000"], ["83689.08000000", "0.00000000"], ["83688.91000000", "0.04000000"], ["83688.55000000", "0.00000000"], ["83688.09000000", "0.04000000"], ["83688.07000000", "0.04000000"], ["83687.93000000", "0.04000000"], ["83687.36000000", "0.00000000"], ["83686.94000000", "0.59816000"], ["83686.35000000", "0.16000000"], ["83684.40000000", "0.11678000"], ["83683.40000000", "0.00000000"], ["83682.98000000", "0.00000000"], ["83682.93000000", "0.20587000"], ["83682.89000000", "0.00000000"], ["83681.42000000", "0.35761000"], ["83681.39000000", "0.00000000"], ["83681.30000000", "0.00000000"], ["83681.16000000", "0.00000000"], ["83679.20000000", "0.00000000"], ["83679.04000000", "0.00000000"], ["83678.79000000", "0.00000000"], ["83678.68000000", "0.00000000"], ["83678.22000000", "0.00000000"], ["83678.07000000", "0.00000000"], ["83677.67000000", "0.00000000"], ["83677.48000000", "0.00000000"], ["83677.20000000", "0.59601000"], ["83677.12000000", "0.00009000"], ["83677.10000000", "0.00000000"], ["83676.82000000", "0.00000000"], ["83676.22000000", "0.86087000"], ["83676.20000000", "0.89402000"], ["83676.08000000", "0.89402000"], ["83676.02000000", "0.04000000"], ["83675.87000000", "0.00000000"], ["83675.84000000", "0.00000000"], ["83674.13000000", "0.00000000"], ["83673.71000000", "0.00000000"], ["83673.49000000", "0.04000000"], ["83672.12000000", "0.04000000"], ["83671.65000000", "0.00000000"], ["83669.90000000", "0.00000000"], ["83667.00000000", "0.56274000"], ["83665.78000000", "0.00000000"], ["83665.17000000", "0.00000000"], ["83663.70000000", "0.05900000"], ["83660.01000000", "0.06494000"], ["83659.51000000", "0.00000000"], ["83658.65000000", "0.00000000"], ["83651.28000000", "0.35761000"], ["83650.16000000", "0.00008000"], ["83649.08000000", "0.04469000"], ["83648.41000000", "0.00000000"], ["83639.52000000", "0.59601000"], ["83636.95000000", "0.04000000"], ["83633.44000000", "0.03586000"], ["83630.20000000", "0.08000000"], ["83630.17000000", "0.04000000"], ["83628.54000000", "0.04000000"], ["83627.32000000", "0.04000000"], ["83626.35000000", "0.04000000"], ["83626.04000000", "0.04000000"], ["83622.65000000", "0.04000000"], ["83621.92000000", "0.04000000"], ["83615.97000000", "0.04000000"], ["83609.23000000", "0.04000000"], ["83609.20000000", "0.04000000"], ["83575.84000000", "0.00000000"], ["83557.00000000", "0.00000000"], ["83556.90000000", "0.00000000"], ["83555.21000000", "0.00000000"], ["83555.11000000", "0.00000000"], ["83554.51000000", "0.01000000"], ["83553.18000000", "0.00000000"], ["83551.31000000", "0.00000000"], ["83545.61000000", "0.00000000"], ["83539.65000000", "0.00000000"], ["83531.06000000", "0.00000000"], ["83523.66000000", "0.00400000"], ["83510.52000000", "0.00092000"], ["83510.51000000", "0.00000000"], ["83510.50000000", "0.00000000"], ["83505.91000000", "0.00076000"], ["83505.90000000", "0.00000000"], ["82844.10000000", "0.00000000"], ["82844.09000000", "0.06004000"], ["82456.31000000", "0.00100000"], ["80347.44000000", "0.00000000"], ["80330.67000000", "0.00000000"], ["80330.66000000", "0.03629000"], ["75340.79000000", "0.00000000"], ["75340.00000000", "0.00000000"], ["75339.00000000", "0.01979000"], ["66969.61000000", "0.00000000"], ["66969.60000000", "0.00058000"], ["33000.01000000", "0.00000000"], ["33000.00000000", "2.93827000"], ["30136.32000000", "0.00100000"]], "a": [["83712.00000000", "4.10397000"], ["83712.07000000", "0.00007000"], ["83712.10000000", "0.00208000"], ["83712.28000000", "0.00029000"], ["83712.29000000", "0.31289000"], ["83712.30000000", "0.14783000"], ["83712.31000000", "0.78886000"], ["83712.32000000", "0.00000000"], ["83712.50000000", "0.00000000"], ["83712.51000000", "0.00000000"], ["83714.00000000", "0.02827000"], ["83714.36000000", "0.00000000"], ["83714.37000000", "0.00000000"], ["83714.94000000", "0.00000000"], ["83714.95000000", "0.00000000"], ["83715.85000000", "0.13902000"], ["83716.08000000", "0.00000000"], ["83716.20000000", "0.00500000"], ["83718.69000000", "0.04000000"], ["83720.23000000", "0.00119000"], ["83720.35000000", "0.04000000"], ["83720.37000000", "0.04000000"], ["83720.42000000", "0.04000000"], ["83720.48000000", "0.04400000"], ["83720.72000000", "0.00000000"], ["83721.27000000", "0.04000000"], ["83721.43000000", "0.08338000"], ["83721.45000000", "0.00000000"], ["83722.29000000", "0.00000000"], ["83722.43000000", "0.00000000"], ["83722.80000000", "0.00006000"], ["83722.88000000", "0.04800000"], ["83723.25000000", "0.00000000"], ["83724.53000000", "0.08992000"], ["83724.61000000", "0.04800000"], ["83724.84000000", "0.00510000"], ["83724.97000000", "0.00760000"], ["83725.38000000", "0.00000000"], ["83725.44000000", "0.04800000"], ["83725.46000000", "0.04800000"], ["83725.56000000", "0.04400000"], ["83725.60000000", "0.00000000"], ["83726.41000000", "0.00000000"], ["83727.06000000", "0.00000000"], ["83727.39000000", "0.00000000"], ["83728.32000000", "0.00000000"], ["83729.16000000", "0.80953000"], ["83729.77000000", "0.00000000"], ["83730.60000000", "0.00000000"], ["83731.31000000", "0.00500000"], ["83731.42000000", "0.71594000"], ["83731.44000000", "0.00908000"], ["83731.56000000", "0.00000000"], ["83732.75000000", "0.86029000"], ["83734.05000000", "0.00500000"], ["83735.52000000", "0.00000000"], ["83735.55000000", "0.01000000"], ["83736.62000000", "1.00000000"], ["83736.69000000", "0.00000000"], ["83738.83000000", "0.08992000"], ["83741.01000000", "0.00000000"], ["83741.11000000", "0.06000000"], ["83742.78000000", "0.00000000"], ["83743.14000000", "0.00000000"], ["83743.93000000", "0.00000000"], ["83743.94000000", "0.00000000"], ["83745.40000000", "0.00000000"], ["83745.53000000", "0.91640000"], ["83746.55000000", "0.59758000"], ["83747.42000000", "0.05836000"], ["83749.18000000", "0.00000000"], ["83750.03000000", "0.00000000"], ["83750.04000000", "0.00000000"], ["83753.62000000", "0.00000000"], ["83755.21000000", "0.08000000"], ["83755.44000000", "0.12487000"], ["83757.86000000", "0.00000000"], ["83762.85000000", "0.00000000"], ["83831.37000000", "0.04649000"], ["83831.45000000", "0.00000000"], ["83832.31000000", "0.00000000"], ["83836.53000000", "0.00000000"], ["83840.73000000", "0.00000000"], ["83842.56000000", "0.00000000"], ["83843.16000000", "0.00000000"], ["84012.52000000", "0.00000000"], ["84948.40000000", "0.11787000"], ["84967.68000000", "0.00100000"], ["84969.60000000", "0.00000000"]], "record_time": 1742561035.208929, "EXCHANGE": "BINANCE"}
{"result": null, "id": 1, "record_time": 1742561131.139134, "EXCHANGE": "BINANCE"}
{"e": "depthUpdate", "E": 1742561132014, "s": "BTCUSDT", "U": 64610599774, "u": 64610600091, "b": [["83804.64000000", "1.44103000"], ["83804.57000000", "0.00007000"], ["83804.56000000", "0.00007000"], ["83804.55000000", "0.17597000"], ["83804.53000000", "0.00007000"], ["83804.49000000", "0.00000000"], ["83804.48000000", "0.00000000"], ["83804.24000000", "0.13964000"], ["83804.01000000", "0.32826000"], ["83803.79000000", "0.00000000"], ["83803.17000000", "0.00007000"], ["83803.16000000", "0.00000000"], ["83803.11000000", "0.00000000"], ["83803.07000000", "0.00000000"], ["83802.97000000", "0.01059000"], ["83802.92000000", "0.02214000"], ["83802.67000000", "0.00000000"], ["83802.01000000", "0.00031000"], ["83801.33000000", "0.00758000"], ["83800.91000000", "0.02391000"], ["83800.89000000", "0.04275000"], ["83800.84000000", "0.02737000"], ["83800.35000000", "0.05975000"], ["83800.02000000", "0.00000000"], ["83800.01000000", "3.73763000"], ["83800.00000000", "12.74630000"], ["83799.76000000", "0.00000000"], ["83798.54000000", "0.00008000"], ["83797.95000000", "0.00000000"], ["83796.70000000", "0.00000000"], ["83796.25000000", "0.00300000"], ["83784.10000000", "0.00000000"], ["83771.72000000", "0.00000000"], ["83766.73000000", "0.59693000"], ["83760.79000000", "0.05000000"], ["83754.12000000", "0.00000000"], ["83700.99000000", "0.00000000"], ["83653.38000000", "0.01869000"], ["83644.57000000", "0.00000000"], ["83644.07000000", "0.00000000"], ["83643.27000000", "0.00000000"], ["83642.88000000", "0.00000000"], ["83642.28000000", "0.01007000"], ["83641.28000000", "0.00000000"], ["83638.86000000", "0.08467000"], ["83624.28000000", "0.00400000"], ["83576.63000000", "0.00359000"], ["82966.59000000", "0.00000000"], ["82547.57000000", "0.00100000"], ["75424.00000000", "0.00000000"], ["75423.00000000", "1.50993000"], ["67043.72000000", "0.00058000"], ["33000.00000000", "2.93827000"], ["30169.67000000", "0.00420000"]], "a": [["83804.65000000", "3.40828000"], ["83804.81000000", "0.42338000"], ["83806.32000000", "0.00000000"], ["83806.79000000", "0.02282000"], ["83806.98000000", "0.00000000"], ["83807.48000000", "0.02430000"], ["83808.80000000", "0.01000000"], ["83811.34000000", "0.01193000"], ["83811.35000000", "0.00012000"], ["83812.45000000", "0.78785000"], ["83812.69000000", "0.46881000"], ["83813.62000000", "0.00755000"], ["83814.05000000", "0.00000000"], ["83814.28000000", "0.00000000"], ["83815.59000000", "0.00000000"], ["83816.76000000", "0.00012000"], ["83817.45000000", "0.08338000"], ["83817.46000000", "0.32497000"], ["83819.18000000", "0.00000000"], ["83820.11000000", "0.00059000"], ["83821.24000000", "1.33788000"], ["83821.65000000", "0.65165000"], ["83824.47000000", "0.00000000"], ["83825.14000000", "0.02342000"], ["83828.10000000", "0.00000000"], ["83828.52000000", "0.00000000"], ["83828.91000000", "0.00000000"], ["83829.41000000", "0.00910000"], ["83831.66000000", "0.00000000"], ["83833.84000000", "0.85925000"], ["83835.65000000", "0.05000000"], ["83846.63000000", "0.29269000"], ["83848.26000000", "0.00000000"], ["83874.19000000", "0.02388000"], ["83891.82000000", "0.00000000"], ["83893.52000000", "0.00000000"], ["83894.40000000", "0.00844000"], ["83894.82000000", "0.00000000"], ["83901.09000000", "0.07446000"], ["83901.25000000", "0.05198000"], ["83960.03000000", "0.00000000"], ["83972.41000000", "0.00000000"], ["83972.51000000", "0.01000000"], ["84212.51000000", "0.00000000"], ["84212.52000000", "0.00000000"], ["84959.38000000", "0.00000000"], ["85061.72000000", "0.00100000"], ["86987.65000000", "0.00119000"], ["86987.66000000", "0.00352000"]], "record_time": 1742561132.039255, "EXCHANGE": "BINANCE"}
{"e": "depthUpdate", "E": 1742561133014, "s": "BTCUSDT", "U": 64610600092, "u": 64610600433, "b": [["83804.64000000", "2.10554000"], ["83804.63000000", "0.13272000"], ["83804.55000000", "0.00013000"], ["83804.01000000", "0.32820000"], ["83802.92000000", "0.00006000"], ["83801.90000000", "0.00000000"], ["83801.80000000", "0.00000000"], ["83800.91000000", "0.02385000"], ["83800.89000000", "0.00000000"], ["83800.02000000", "0.00000000"], ["83800.00000000", "12.73357000"], ["83798.40000000", "0.00006000"], ["83796.25000000", "0.00300000"], ["83791.80000000", "0.00300000"], ["83791.70000000", "0.00007000"], ["83791.62000000", "0.00000000"], ["83778.88000000", "0.05592000"], ["83778.16000000", "1.32879000"], ["83777.83000000", "0.00000000"], ["83770.22000000", "0.00000000"], ["83760.79000000", "0.00000000"], ["83759.98000000", "0.05000000"], ["83752.92000000", "0.00009000"], ["83751.56000000", "0.00364000"], ["83722.98000000", "0.46234000"], ["83707.12000000", "0.59547000"], ["83706.21000000", "0.63178000"], ["83635.89000000", "0.00000000"], ["83630.67000000", "0.00000000"], ["83626.62000000", "0.00400000"], ["83624.28000000", "0.00000000"], ["83532.67000000", "0.00009000"], ["82888.35000000", "0.00000000"], ["82547.57000000", "0.00000000"], ["75424.00000000", "0.00000000"], ["75423.00000000", "1.50993000"], ["67043.72000000", "0.00058000"], ["42000.00000000", "6.85161000"], ["33000.00000000", "2.93827000"]], "a": [["83804.65000000", "3.62890000"], ["83804.66000000", "0.00046000"], ["83804.72000000", "0.00021000"], ["83804.73000000", "0.10612000"], ["83804.75000000", "0.00007000"], ["83804.80000000", "0.00014000"], ["83804.81000000", "0.25253000"], ["83805.40000000", "0.01882000"], ["83807.48000000", "0.00000000"], ["83808.64000000", "0.02403000"], ["83808.80000000", "0.00500000"], ["83811.35000000", "0.00000000"], ["83812.45000000", "0.00000000"], ["83812.69000000", "0.69240000"], ["83812.81000000", "0.78784000"], ["83814.61000000", "0.00012000"], ["83814.73000000", "0.00000000"], ["83814.94000000", "0.00000000"], ["83816.00000000", "0.00220000"], ["83816.76000000", "0.00000000"], ["83817.46000000", "0.54210000"], ["83820.32000000", "1.00000000"], ["83821.23000000", "0.96256000"], ["83821.24000000", "0.00000000"], ["83821.65000000", "0.00000000"], ["83822.63000000", "1.34927000"], ["83822.96000000", "0.00000000"], ["83825.14000000", "0.02354000"], ["83826.00000000", "0.00000000"], ["83829.00000000", "1.00000000"], ["83833.67000000", "0.85925000"], ["83833.84000000", "0.00000000"], ["83835.65000000", "0.00000000"], ["83837.66000000", "0.00000000"], ["83846.63000000", "0.29269000"], ["83847.55000000", "0.00000000"], ["83849.71000000", "0.00000000"], ["83901.00000000", "0.04654000"], ["83901.09000000", "0.00000000"], ["83972.25000000", "0.01141000"], ["84041.30000000", "0.00000000"], ["84051.40000000", "0.00300000"], ["84217.27000000", "0.00119000"], ["84217.97000000", "0.00000000"], ["85061.70000000", "0.00000000"], ["85061.71000000", "0.00000000"], ["85061.72000000", "0.00000000"], ["86987.65000000", "0.00000000"]], "record_time": 1742561133.068154, "EXCHANGE": "BINANCE"}
{"e": "depthUpdate", "E": 1742561134014, "s": "BTCUSDT", "U": 64610600434, "u": 64610601044, "b": [["83804.64000000", "0.90055000"], ["83804.63000000", "0.00048000"], ["83804.62000000", "0.00007000"], ["83804.56000000", "0.00007000"], ["83804.55000000", "0.00007000"], ["83804.53000000", "0.00000000"], ["83804.31000000", "0.78799000"], ["83804.25000000", "0.00000000"], ["83804.24000000", "0.00000000"], ["83804.22000000", "0.00209000"], ["83804.01000000", "0.00000000"], ["83803.95000000", "0.00000000"], ["83803.80000000", "0.00000000"], ["83803.79000000", "0.00000000"], ["83803.67000000", "0.00000000"], ["83803.66000000", "0.00000000"], ["83803.17000000", "0.00000000"], ["83803.11000000", "0.00000000"], ["83802.97000000", "0.00000000"], ["83802.92000000", "0.00000000"], ["83802.70000000", "0.00000000"], ["83802.65000000", "0.00009000"], ["83802.50000000", "0.00000000"], ["83802.49000000", "0.07978000"], ["83802.33000000", "0.14212000"], ["83802.26000000", "0.00000000"], ["83802.17000000", "0.00000000"], ["83802.16000000", "0.00000000"], ["83802.15000000", "0.02222000"], ["83802.07000000", "0.34745000"], ["83801.36000000", "0.04293000"], ["83801.33000000", "0.00000000"], ["83800.92000000", "0.00000000"], ["83800.91000000", "0.02391000"], ["83800.85000000", "0.00000000"], ["83800.84000000", "0.02737000"], ["83800.58000000", "0.00000000"], ["83800.36000000", "0.00000000"], ["83800.35000000", "0.05975000"], ["83800.02000000", "0.00000000"], ["83800.01000000", "3.81357000"], ["83800.00000000", "12.71204000"], ["83799.90000000", "0.02849000"], ["83799.89000000", "0.00760000"], ["83799.15000000", "0.00000000"], ["83798.67000000", "0.02435000"], ["83797.95000000", "0.00340000"], ["83792.08000000", "0.00000000"], ["83791.80000000", "0.00000000"], ["83791.62000000", "0.00012000"], ["83791.61000000", "0.21184000"], ["83791.07000000", "0.00000000"], ["83789.62000000", "0.00000000"], ["83787.86000000", "0.45000000"], ["83787.33000000", "0.00000000"], ["83787.23000000", "0.00000000"], ["83785.29000000", "1.07906000"], ["83785.05000000", "0.12318000"], ["83784.10000000", "0.00500000"], ["83783.76000000", "0.00000000"], ["83783.14000000", "0.00000000"], ["83783.06000000", "0.85977000"], ["83778.97000000", "0.00000000"], ["83778.88000000", "0.00000000"], ["83778.02000000", "0.00000000"], ["83774.74000000", "0.00000000"], ["83774.73000000", "0.00000000"], ["83774.68000000", "0.00000000"], ["83773.82000000", "0.01864000"], ["83773.73000000", "0.85987000"], ["83773.39000000", "0.01864000"], ["83773.19000000", "0.85987000"], ["83770.37000000", "0.00514000"], ["83766.73000000", "0.00000000"], ["83766.46000000", "0.00000000"], ["83762.44000000", "0.59697000"], ["83759.98000000", "0.00000000"], ["83759.78000000", "0.00000000"], ["83751.85000000", "0.00000000"], ["83750.00000000", "0.20353000"], ["83749.71000000", "0.05969000"], ["83726.89000000", "0.00000000"], ["83722.76000000", "0.00000000"], ["83713.36000000", "0.01196000"], ["83712.04000000", "0.00998000"], ["83707.12000000", "0.43701000"], ["83706.21000000", "0.00000000"], ["83669.92000000", "0.00000000"], ["83653.38000000", "0.00000000"], ["83647.54000000", "0.00000000"], ["83646.77000000", "0.00400000"], ["83642.28000000", "0.00007000"], ["83642.18000000", "0.01000000"], ["83641.08000000", "0.00000000"], ["83640.98000000", "0.00000000"], ["83626.62000000", "0.00000000"], ["83623.25000000", "0.00000000"], ["83616.08000000", "0.00011000"], ["83561.56000000", "0.00000000"], ["83555.00000000", "4.21933000"], ["83546.49000000", "0.45000000"], ["75424.00000000", "0.00000000"], ["75423.00000000", "1.50993000"], ["67043.72000000", "0.00058000"], ["33000.00000000", "2.93827000"], ["30169.67000000", "0.00440000"]], "a": [["83804.65000000", "3.31771000"], ["83804.73000000", "0.21250000"], ["83804.82000000", "0.52007000"], ["83805.02000000", "0.00000000"], ["83805.05000000", "0.00000000"], ["83805.40000000", "0.00000000"], ["83805.63000000", "0.00007000"], ["83805.72000000", "0.00000000"], ["83806.00000000", "0.02827000"], ["83806.19000000", "0.00000000"], ["83806.32000000", "0.00000000"], ["83806.77000000", "0.00033000"], ["83808.62000000", "0.00000000"], ["83809.47000000", "0.00000000"], ["83809.61000000", "0.00000000"], ["83810.17000000", "0.00000000"], ["83810.36000000", "0.00008000"], ["83810.47000000", "0.78786000"], ["83810.96000000", "0.00000000"], ["83812.70000000", "0.08992000"], ["83812.81000000", "0.00000000"], ["83813.43000000", "0.04800000"], ["83813.48000000", "0.00059000"], ["83813.76000000", "0.00059000"], ["83814.03000000", "0.00000000"], ["83814.56000000", "0.00000000"], ["83815.16000000", "0.00000000"], ["83816.40000000", "0.00058000"], ["83816.76000000", "0.00012000"], ["83817.71000000", "0.00000000"], ["83818.78000000", "0.00000000"], ["83819.10000000", "0.00000000"], ["83819.13000000", "0.00000000"], ["83820.14000000", "0.00059000"], ["83821.88000000", "0.00000000"], ["83821.99000000", "0.15487000"], ["83822.38000000", "0.00000000"], ["83822.48000000", "0.00000000"], ["83822.64000000", "0.00000000"], ["83823.04000000", "0.00000000"], ["83823.42000000", "0.00000000"], ["83824.83000000", "0.08992000"], ["83825.14000000", "0.02342000"], ["83825.88000000", "0.00000000"], ["83825.97000000", "0.05735000"], ["83826.37000000", "0.00000000"], ["83826.51000000", "0.00000000"], ["83827.34000000", "0.00000000"], ["83827.56000000", "1.00000000"], ["83827.94000000", "0.00000000"], ["83828.25000000", "0.00000000"], ["83828.86000000", "0.00000000"], ["83829.00000000", "0.00000000"], ["83829.34000000", "0.00000000"], ["83830.31000000", "0.00000000"], ["83830.49000000", "0.00000000"], ["83830.51000000", "0.00000000"], ["83831.20000000", "0.00000000"], ["83831.38000000", "0.59694000"], ["83834.43000000", "0.00000000"], ["83835.52000000", "0.00000000"], ["83836.05000000", "0.00000000"], ["83836.06000000", "0.00000000"], ["83836.19000000", "0.00000000"], ["83837.24000000", "0.00000000"], ["83837.49000000", "0.00000000"], ["83839.66000000", "0.00000000"], ["83839.69000000", "0.00000000"], ["83839.84000000", "0.04400000"], ["83839.99000000", "0.00000000"], ["83842.53000000", "0.00000000"], ["83842.96000000", "0.00000000"], ["83843.08000000", "0.85915000"], ["83843.17000000", "0.00000000"], ["83843.50000000", "0.00000000"], ["83844.48000000", "0.00000000"], ["83845.69000000", "0.00000000"], ["83846.83000000", "0.00000000"], ["83847.66000000", "0.00000000"], ["83848.45000000", "0.00000000"], ["83848.58000000", "0.00000000"], ["83851.34000000", "0.00000000"], ["83851.52000000", "0.00000000"], ["83851.66000000", "0.00000000"], ["83852.02000000", "0.04081000"], ["83853.01000000", "0.00000000"], ["83855.16000000", "0.00000000"], ["83855.66000000", "0.00013000"], ["83855.86000000", "0.00000000"], ["83855.99000000", "0.00000000"], ["83856.76000000", "0.00000000"], ["83856.96000000", "0.00000000"], ["83856.98000000", "0.04062000"], ["83857.25000000", "0.00000000"], ["83859.53000000", "0.00000000"], ["83859.75000000", "0.00000000"], ["83859.83000000", "0.00000000"], ["83861.24000000", "0.00000000"], ["83864.45000000", "0.00000000"], ["83864.54000000", "0.00000000"], ["83864.94000000", "0.00000000"], ["83864.98000000", "0.00000000"], ["83868.54000000", "0.00000000"], ["83869.17000000", "0.00000000"], ["83869.19000000", "0.00000000"], ["83869.54000000", "0.00000000"], ["83872.01000000", "0.00000000"], ["83872.38000000", "0.00000000"], ["83873.18000000", "0.00000000"], ["83873.82000000", "0.00000000"], ["83876.23000000", "0.00000000"], ["83877.20000000", "0.00007000"], ["83877.93000000", "0.00000000"], ["83877.95000000", "0.00000000"], ["83880.97000000", "0.00000000"], ["83881.11000000", "0.00000000"], ["83881.42000000", "0.00000000"], ["83882.16000000", "0.00000000"], ["83885.09000000", "0.00000000"], ["83885.14000000", "0.00000000"], ["83885.22000000", "0.00000000"], ["83886.46000000", "0.00000000"], ["83889.06000000", "0.00000000"], ["83889.26000000", "0.00000000"], ["83889.58000000", "0.00931000"], ["83889.66000000", "0.00000000"], ["83889.98000000", "0.00000000"], ["83890.64000000", "0.05198000"], ["83892.16000000", "0.03723000"], ["83893.29000000", "0.04774000"], ["83893.42000000", "0.00000000"], ["83894.68000000", "0.00000000"], ["83894.77000000", "0.00000000"], ["83898.32000000", "0.00000000"], ["83898.54000000", "0.00000000"], ["83898.80000000", "0.00000000"], ["83901.00000000", "0.00000000"], ["83901.51000000", "0.00000000"], ["83901.67000000", "0.04655000"], ["83903.33000000", "0.00000000"], ["83903.38000000", "0.00000000"], ["83905.84000000", "0.00000000"], ["83906.08000000", "0.00000000"], ["83906.20000000", "0.00000000"], ["83906.92000000", "0.04654000"], ["83909.75000000", "0.00000000"], ["83909.78000000", "0.04654000"], ["83910.98000000", "0.00000000"], ["83911.35000000", "0.00000000"], ["83914.35000000", "0.00000000"], ["83915.72000000", "0.00000000"], ["83915.74000000", "0.04397000"], ["83915.91000000", "0.00000000"], ["83918.29000000", "0.00000000"], ["83918.40000000", "0.00969000"], ["83919.43000000", "0.00000000"], ["83919.76000000", "0.00000000"], ["83922.77000000", "0.00529000"], ["83923.33000000", "0.00000000"], ["83923.51000000", "0.00000000"], ["83923.66000000", "0.00000000"], ["83927.38000000", "0.00000000"], ["83928.20000000", "0.00000000"], ["83928.27000000", "0.00000000"], ["83928.38000000", "0.00000000"], ["83931.49000000", "0.00000000"], ["83931.66000000", "0.00000000"], ["83932.42000000", "0.00000000"], ["83932.54000000", "0.00000000"], ["83935.57000000", "0.00000000"], ["83935.81000000", "0.00000000"], ["83936.17000000", "0.00000000"], ["83936.76000000", "0.00000000"], ["83939.40000000", "0.00000000"], ["83939.71000000", "0.00000000"], ["83940.45000000", "0.00000000"], ["83941.07000000", "0.00000000"], ["83943.77000000", "0.00000000"], ["83944.09000000", "0.00000000"], ["83944.66000000", "0.00000000"], ["83944.93000000", "0.00000000"], ["83947.98000000", "0.00000000"], ["83948.09000000", "0.00000000"], ["83948.49000000", "0.00000000"], ["83949.01000000", "0.00000000"], ["83951.72000000", "0.00000000"], ["83952.65000000", "0.00000000"], ["83953.37000000", "0.00000000"], ["83953.78000000", "0.00000000"], ["83956.55000000", "0.00000000"], ["83957.21000000", "0.00000000"], ["83957.76000000", "0.00000000"], ["83957.77000000", "0.00000000"], ["83960.28000000", "0.00000000"], ["83960.88000000", "0.00000000"], ["83961.15000000", "0.00000000"], ["83961.43000000", "0.00000000"], ["83964.42000000", "0.00000000"], ["83964.77000000", "0.00000000"], ["83964.78000000", "0.00000000"], ["83965.11000000", "0.00000000"], ["83972.51000000", "0.01000000"], ["84051.40000000", "0.00000000"]], "record_time": 1742561134.115617, "EXCHANGE": "BINANCE"}
{"e": "depthUpdate", "E": 1742561135014, "s": "BTCUSDT", "U": 64610601045, "u": 64610601347, "b": [["83804.64000000", "4.60761000"], ["83804.31000000", "0.78799000"], ["83804.30000000", "0.17185000"], ["83804.22000000", "0.00202000"], ["83803.59000000", "0.00000000"], ["83803.25000000", "0.00000000"], ["83803.11000000", "0.00000000"], ["83802.98000000", "0.00008000"], ["83802.97000000", "0.01193000"], ["83802.65000000", "0.00000000"], ["83802.49000000", "0.20769000"], ["83802.33000000", "0.00000000"], ["83802.26000000", "0.00007000"], ["83802.15000000", "0.00000000"], ["83802.07000000", "0.00000000"], ["83801.97000000", "0.00000000"], ["83800.58000000", "0.00007000"], ["83800.35000000", "0.00000000"], ["83800.02000000", "0.17918000"], ["83800.00000000", "12.71216000"], ["83797.95000000", "0.00000000"], ["83796.25000000", "0.45300000"], ["83791.62000000", "0.00000000"], ["83791.61000000", "0.46021000"], ["83791.34000000", "0.85968000"], ["83791.10000000", "0.00500000"], ["83787.61000000", "0.85972000"], ["83785.83000000", "0.01864000"], ["83783.26000000", "0.01864000"], ["83782.92000000", "0.04469000"], ["83781.69000000", "0.04460000"], ["83776.35000000", "0.59688000"], ["83774.73000000", "0.71594000"], ["83773.82000000", "0.00000000"], ["83773.73000000", "0.00000000"], ["83773.39000000", "0.00000000"], ["83773.19000000", "0.00000000"], ["83763.36000000", "0.00000000"], ["83762.44000000", "0.00000000"], ["83757.28000000", "0.00000000"], ["83756.64000000", "0.00000000"], ["83753.28000000", "0.00000000"], ["83749.71000000", "0.00000000"], ["83704.68000000", "0.26646000"], ["83703.38000000", "0.00000000"], ["83650.16000000", "0.00000000"], ["83646.77000000", "0.00000000"], ["83643.27000000", "0.01000000"], ["83642.18000000", "0.00000000"], ["83642.08000000", "0.00000000"], ["83631.49000000", "0.00400000"], ["83628.66000000", "0.00000000"], ["83625.72000000", "0.00000000"], ["83056.14000000", "0.00060000"], ["83056.13000000", "0.00000000"], ["82547.57000000", "0.00100000"], ["79600.00000000", "1.03841000"], ["75424.00000000", "0.00000000"], ["75423.00000000", "1.50993000"], ["67043.72000000", "0.00058000"], ["33000.00000000", "2.93827000"], ["30169.67000000", "0.00480000"]], "a": [["83804.65000000", "0.19549000"], ["83804.72000000", "0.00007000"], ["83804.73000000", "0.00007000"], ["83804.75000000", "0.00021000"], ["83804.78000000", "0.00007000"], ["83804.80000000", "0.00000000"], ["83804.81000000", "0.00045000"], ["83804.83000000", "0.00202000"], ["83804.88000000", "0.00000000"], ["83805.57000000", "0.00000000"], ["83806.00000000", "0.02827000"], ["83806.79000000", "0.00000000"], ["83807.96000000", "0.02992000"], ["83808.00000000", "0.03037000"], ["83808.64000000", "0.00000000"], ["83808.80000000", "0.00000000"], ["83809.20000000", "0.00000000"], ["83809.32000000", "0.00000000"], ["83809.39000000", "0.06683000"], ["83810.34000000", "0.00000000"], ["83810.47000000", "0.00000000"], ["83810.99000000", "0.62466000"], ["83811.06000000", "0.02207000"], ["83811.34000000", "0.00000000"], ["83812.23000000", "0.00000000"], ["83812.46000000", "0.00000000"], ["83812.69000000", "0.00000000"], ["83812.70000000", "0.00000000"], ["83813.03000000", "0.49588000"], ["83813.04000000", "0.00000000"], ["83814.09000000", "0.00000000"], ["83814.61000000", "0.00000000"], ["83815.85000000", "0.00000000"], ["83816.76000000", "0.00000000"], ["83817.45000000", "0.00000000"], ["83817.74000000", "0.00000000"], ["83817.91000000", "0.00012000"], ["83819.71000000", "0.05975000"], ["83822.41000000", "0.71594000"], ["83822.83000000", "0.00000000"], ["83824.83000000", "0.00000000"], ["83825.14000000", "0.02354000"], ["83826.33000000", "0.00000000"], ["83827.56000000", "0.00000000"], ["83831.38000000", "0.00000000"], ["83833.65000000", "0.00000000"], ["83833.67000000", "0.00000000"], ["83835.65000000", "0.00000000"], ["83835.73000000", "0.00000000"], ["83836.81000000", "0.00000000"], ["83837.63000000", "0.00000000"], ["83842.77000000", "0.59688000"], ["83847.04000000", "0.85911000"], ["83852.02000000", "0.00000000"], ["83854.47000000", "0.14485000"], ["83869.19000000", "0.04081000"], ["83884.62000000", "0.06168000"], ["83885.75000000", "0.00000000"], ["83889.58000000", "0.00000000"], ["83891.99000000", "0.00000000"], ["83892.07000000", "0.00000000"], ["83892.16000000", "0.00000000"], ["83894.40000000", "0.00000000"], ["83894.82000000", "0.00844000"], ["83896.72000000", "0.00000000"], ["83898.01000000", "0.00000000"], ["83900.58000000", "0.00000000"], ["83915.65000000", "0.12827000"], ["83922.07000000", "0.23270000"], ["84217.27000000", "0.00000000"], ["85061.71000000", "0.00119000"], ["85061.72000000", "0.00100000"]], "record_time": 1742561135.039619, "EXCHANGE": "BINANCE"}
{"e": "depthUpdate", "E": 1742561185014, "s": "BTCUSDT", "U": 64610665860, "u": 64610666205, "b": [["83792.45000000", "1.74666000"], ["83792.08000000", "0.00008000"], ["83791.90000000", "0.00009000"], ["83791.89000000", "0.13417000"], ["83791.81000000", "0.39581000"], ["83791.80000000", "0.25266000"], ["83791.29000000", "0.00000000"], ["83791.19000000", "0.09759000"], ["83791.17000000", "0.78805000"], ["83790.84000000", "0.00000000"], ["83790.83000000", "0.00000000"], ["83790.78000000", "0.00131000"], ["83790.73000000", "0.00000000"], ["83790.45000000", "0.00007000"], ["83789.58000000", "0.00000000"], ["83789.57000000", "0.00000000"], ["83789.34000000", "0.00000000"], ["83789.33000000", "0.00000000"], ["83788.77000000", "0.02369000"], ["83788.76000000", "0.00007000"], ["83788.68000000", "0.08712000"], ["83788.53000000", "0.00732000"], ["83788.17000000", "0.00012000"], ["83788.02000000", "0.00000000"], ["83787.36000000", "0.02778000"], ["83787.00000000", "0.00000000"], ["83786.78000000", "0.00000000"], ["83786.37000000", "0.05975000"], ["83785.87000000", "0.00000000"], ["83785.76000000", "0.02405000"], ["83784.07000000", "0.00000000"], ["83783.61000000", "0.00000000"], ["83783.24000000", "0.00012000"], ["83782.22000000", "0.00000000"], ["83781.53000000", "0.00000000"], ["83778.06000000", "0.11180000"], ["83774.86000000", "0.00000000"], ["83770.45000000", "1.12373000"], ["83770.34000000", "0.00000000"], ["83769.67000000", "0.85991000"], ["83764.28000000", "0.00000000"], ["83761.93000000", "0.84677000"], ["83760.54000000", "1.41437000"], ["83756.17000000", "0.00000000"], ["83746.99000000", "0.05000000"], ["83686.42000000", "0.63187000"], ["83631.89000000", "0.00050000"], ["83631.79000000", "0.00000000"], ["83623.03000000", "0.00400000"], ["83617.07000000", "0.00000000"], ["83615.18000000", "0.00000000"], ["83609.76000000", "0.00000000"], ["83604.67000000", "0.00119000"], ["83600.34000000", "0.00000000"], ["83600.02000000", "0.00058000"], ["83600.01000000", "0.00092000"], ["83586.21000000", "0.00000000"], ["83586.19000000", "0.00076000"], ["82535.56000000", "0.00107000"], ["75413.00000000", "0.30120000"], ["75412.00000000", "0.00034000"], ["67033.97000000", "0.00000000"], ["67033.96000000", "0.00058000"], ["33000.00000000", "2.93827000"]], "a": [["83792.46000000", "2.27852000"], ["83792.59000000", "0.25344000"], ["83793.95000000", "0.00000000"], ["83794.13000000", "0.00000000"], ["83794.20000000", "0.00034000"], ["83794.23000000", "0.00000000"], ["83795.04000000", "0.00012000"], ["83795.46000000", "0.04007000"], ["83796.14000000", "0.02411000"], ["83796.19000000", "0.00014000"], ["83796.29000000", "0.04000000"], ["83797.13000000", "0.04000000"], ["83797.28000000", "0.00000000"], ["83797.76000000", "0.05975000"], ["83798.09000000", "0.00000000"], ["83798.19000000", "0.00000000"], ["83798.47000000", "0.00000000"], ["83800.44000000", "0.00000000"], ["83800.50000000", "0.04800000"], ["83801.25000000", "0.02381000"], ["83801.33000000", "0.09600000"], ["83801.44000000", "0.04400000"], ["83802.10000000", "0.00000000"], ["83803.28000000", "0.00000000"], ["83803.40000000", "0.00000000"], ["83804.37000000", "0.35956000"], ["83804.64000000", "0.00000000"], ["83805.46000000", "0.00000000"], ["83806.29000000", "0.00000000"], ["83806.31000000", "0.00000000"], ["83808.02000000", "1.00000000"], ["83808.38000000", "0.00012000"], ["83808.44000000", "0.00259000"], ["83809.01000000", "1.43945000"], ["83809.81000000", "0.00000000"], ["83812.61000000", "0.00000000"], ["83813.31000000", "0.00023000"], ["83814.05000000", "0.00000000"], ["83814.32000000", "0.71594000"], ["83816.26000000", "0.00000000"], ["83816.46000000", "0.04000000"], ["83821.51000000", "0.04800000"], ["83822.93000000", "0.92255000"], ["83824.24000000", "0.85935000"], ["83831.50000000", "0.00500000"], ["83835.01000000", "0.00000000"], ["83845.63000000", "0.00000000"], ["83854.13000000", "0.09103000"], ["83854.74000000", "0.00000000"], ["83855.00000000", "0.49201000"], ["83859.27000000", "0.00000000"], ["83861.02000000", "0.04400000"], ["83863.96000000", "0.02388000"], ["83864.28000000", "0.00013000"], ["83900.80000000", "0.00000000"], ["83901.70000000", "0.00844000"], ["83905.38000000", "0.73502000"], ["83906.95000000", "0.00000000"], ["83907.55000000", "0.04654000"], ["83909.44000000", "0.04654000"], ["83918.00000000", "0.16653000"], ["83921.04000000", "0.05397000"], ["83927.02000000", "0.00000000"], ["83941.17000000", "0.00155000"], ["83942.35000000", "0.05197000"], ["83943.13000000", "0.00000000"], ["83961.79000000", "0.00000000"], ["83961.89000000", "0.01000000"], ["84003.94000000", "0.00000000"], ["85049.35000000", "0.00100000"]], "record_time": 1742561185.142683, "EXCHANGE": "BINANCE"}
{"e": "depthUpdate", "E": 1742561186014, "s": "BTCUSDT", "U": 64610666206, "u": 64610666788, "b": [["83792.45000000", "4.48657000"], ["83792.34000000", "0.22880000"], ["83792.00000000", "0.02826000"], ["83791.94000000", "0.05981000"], ["83791.89000000", "0.13417000"], ["83791.81000000", "0.39587000"], ["83791.80000000", "0.25272000"], ["83791.65000000", "0.00000000"], ["83791.62000000", "0.00012000"], ["83791.19000000", "0.00000000"], ["83791.17000000", "0.78811000"], ["83791.06000000", "0.00012000"], ["83790.78000000", "0.00957000"], ["83790.08000000", "0.02386000"], ["83790.00000000", "0.02820000"], ["83789.66000000", "0.12111000"], ["83789.34000000", "0.00000000"], ["83789.26000000", "0.00000000"], ["83788.76000000", "0.00000000"], ["83788.69000000", "0.00000000"], ["83788.68000000", "0.00000000"], ["83788.53000000", "0.00000000"], ["83788.17000000", "0.00000000"], ["83787.59000000", "0.08353000"], ["83787.36000000", "0.14022000"], ["83786.37000000", "0.00000000"], ["83785.76000000", "0.02405000"], ["83784.07000000", "0.45000000"], ["83783.57000000", "0.00119000"], ["83783.24000000", "0.00000000"], ["83783.06000000", "0.53134000"], ["83782.25000000", "0.00000000"], ["83781.91000000", "0.00000000"], ["83781.62000000", "0.00000000"], ["83781.17000000", "0.00000000"], ["83780.67000000", "0.00000000"], ["83780.49000000", "0.00000000"], ["83780.04000000", "0.00058000"], ["83780.00000000", "0.06793000"], ["83778.69000000", "0.85641000"], ["83778.06000000", "0.00000000"], ["83776.17000000", "0.08338000"], ["83776.11000000", "0.85984000"], ["83774.74000000", "0.69880000"], ["83773.90000000", "0.12151000"], ["83773.59000000", "0.11934000"], ["83772.18000000", "0.00119000"], ["83772.16000000", "0.89506000"], ["83771.23000000", "0.89506000"], ["83770.25000000", "0.89506000"], ["83769.79000000", "0.00000000"], ["83767.74000000", "0.00000000"], ["83767.60000000", "0.00000000"], ["83766.99000000", "0.00758000"], ["83766.81000000", "0.85994000"], ["83766.49000000", "0.08992000"], ["83765.36000000", "0.04195000"], ["83764.28000000", "0.00000000"], ["83763.41000000", "0.00100000"], ["83762.11000000", "0.59700000"], ["83761.92000000", "0.00000000"], ["83758.25000000", "0.04469000"], ["83757.98000000", "0.60548000"], ["83757.12000000", "0.17918000"], ["83754.83000000", "0.04229000"], ["83749.01000000", "0.00000000"], ["83747.92000000", "0.00000000"], ["83746.99000000", "0.00000000"], ["83745.29000000", "0.00000000"], ["83744.89000000", "0.35732000"], ["83744.84000000", "0.00000000"], ["83744.37000000", "0.00000000"], ["83744.36000000", "0.00000000"], ["83743.26000000", "0.00000000"], ["83740.28000000", "0.35802000"], ["83736.39000000", "0.23303000"], ["83735.10000000", "0.00000000"], ["83734.59000000", "0.00000000"], ["83734.38000000", "0.00000000"], ["83700.20000000", "0.00086000"], ["83686.42000000", "0.00000000"], ["83678.29000000", "0.00000000"], ["83659.33000000", "0.00415000"], ["83651.97000000", "0.00178000"], ["83631.89000000", "0.01000000"], ["83625.13000000", "0.00000000"], ["83623.03000000", "0.00000000"], ["83614.35000000", "0.00119000"], ["83608.50000000", "0.32371000"], ["83604.67000000", "0.00119000"], ["83586.20000000", "0.00007000"], ["83586.19000000", "0.00000000"], ["83529.71000000", "0.00000000"], ["82911.23000000", "0.00000000"], ["82747.49000000", "0.00000000"], ["82535.56000000", "0.00007000"], ["75413.00000000", "0.30120000"], ["75412.00000000", "0.00034000"], ["75259.10000000", "0.00119000"], ["67033.96000000", "0.00058000"], ["60000.01000000", "0.00439000"], ["60000.00000000", "73.06385000"], ["33000.00000000", "2.93827000"], ["30165.28000000", "0.00280000"], ["20002.00000000", "0.00000000"], ["20001.00000000", "0.02099000"]], "a": [["83792.46000000", "0.09617000"], ["83792.57000000", "0.00000000"], ["83792.58000000", "0.00000000"], ["83792.59000000", "0.00000000"], ["83792.65000000", "0.00000000"], ["83792.66000000", "0.00202000"], ["83792.97000000", "0.00007000"], ["83793.09000000", "0.00000000"], ["83793.10000000", "0.00000000"], ["83794.13000000", "0.00000000"], ["83794.20000000", "0.00000000"], ["83794.33000000", "0.00000000"], ["83794.66000000", "0.00035000"], ["83795.03000000", "0.00000000"], ["83795.04000000", "0.00000000"], ["83795.24000000", "0.00000000"], ["83795.46000000", "0.00000000"], ["83796.13000000", "0.00022000"], ["83796.14000000", "0.02417000"], ["83796.19000000", "0.00000000"], ["83796.20000000", "0.00000000"], ["83796.29000000", "0.00000000"], ["83796.35000000", "0.00000000"], ["83796.57000000", "0.00014000"], ["83796.58000000", "0.26841000"], ["83796.59000000", "0.23894000"], ["83797.13000000", "0.00000000"], ["83797.42000000", "0.00000000"], ["83797.43000000", "0.23894000"], ["83797.76000000", "0.00000000"], ["83797.97000000", "0.00000000"], ["83798.23000000", "0.23887000"], ["83798.43000000", "0.00000000"], ["83798.47000000", "0.00000000"], ["83798.52000000", "0.00000000"], ["83798.85000000", "0.00000000"], ["83798.86000000", "0.06264000"], ["83799.09000000", "0.02214000"], ["83799.15000000", "0.00000000"], ["83799.65000000", "0.00000000"], ["83799.95000000", "0.00000000"], ["83800.00000000", "0.39744000"], ["83800.33000000", "0.00000000"], ["83800.50000000", "0.00000000"], ["83800.57000000", "0.00000000"], ["83800.84000000", "0.00300000"], ["83801.25000000", "0.00000000"], ["83801.30000000", "0.00000000"], ["83801.33000000", "0.00000000"], ["83801.44000000", "0.00000000"], ["83801.58000000", "0.04000000"], ["83802.40000000", "0.04000000"], ["83802.80000000", "0.78794000"], ["83802.95000000", "0.00091000"], ["83803.03000000", "0.00097000"], ["83803.04000000", "0.00091000"], ["83803.17000000", "0.00000000"], ["83803.49000000", "0.00091000"], ["83803.99000000", "0.00000000"], ["83804.61000000", "0.00000000"], ["83804.95000000", "0.04800000"], ["83805.00000000", "0.00000000"], ["83805.02000000", "0.01193000"], ["83805.78000000", "0.04800000"], ["83806.00000000", "0.00500000"], ["83806.37000000", "0.00012000"], ["83806.62000000", "0.09600000"], ["83806.72000000", "0.04400000"], ["83806.90000000", "0.00000000"], ["83806.96000000", "0.00419000"], ["83807.09000000", "0.00000000"], ["83807.50000000", "0.00000000"], ["83807.95000000", "0.00000000"], ["83808.03000000", "0.00000000"], ["83808.17000000", "0.06475000"], ["83808.38000000", "0.00000000"], ["83808.43000000", "0.00000000"], ["83808.91000000", "0.00000000"], ["83808.97000000", "0.00000000"], ["83809.03000000", "0.00000000"], ["83809.35000000", "0.00000000"], ["83809.38000000", "0.00000000"], ["83809.39000000", "0.00000000"], ["83809.48000000", "0.00000000"], ["83809.51000000", "0.00000000"], ["83809.58000000", "0.00000000"], ["83810.56000000", "0.00000000"], ["83811.10000000", "0.00000000"], ["83811.39000000", "0.02417000"], ["83812.15000000", "0.00000000"], ["83812.60000000", "0.00000000"], ["83814.06000000", "0.00000000"], ["83814.27000000", "1.12865000"], ["83814.32000000", "0.00000000"], ["83815.35000000", "0.35802000"], ["83815.92000000", "0.00000000"], ["83815.93000000", "0.00000000"], ["83816.39000000", "0.00000000"], ["83816.76000000", "0.02395000"], ["83817.58000000", "0.00000000"], ["83817.64000000", "0.00000000"], ["83818.45000000", "0.00000000"], ["83818.57000000", "0.00000000"], ["83818.79000000", "0.00000000"], ["83819.70000000", "0.59671000"], ["83820.70000000", "0.00000000"], ["83822.93000000", "0.00000000"], ["83822.94000000", "0.00000000"], ["83824.19000000", "0.00897000"], ["83824.24000000", "0.00000000"], ["83824.59000000", "0.85934000"], ["83826.22000000", "0.00000000"], ["83826.85000000", "0.10992000"], ["83828.35000000", "0.00000000"], ["83828.53000000", "0.85930000"], ["83831.39000000", "0.00000000"], ["83832.12000000", "0.85927000"], ["83834.50000000", "0.00000000"], ["83836.65000000", "0.59694000"], ["83836.96000000", "0.00000000"], ["83840.25000000", "0.00000000"], ["83841.66000000", "0.12122000"], ["83843.29000000", "0.45170000"], ["83844.54000000", "0.37606000"], ["83850.21000000", "0.00000000"], ["83852.03000000", "0.04292000"], ["83855.84000000", "0.00000000"], ["83863.96000000", "0.00000000"], ["83864.28000000", "0.04813000"], ["83867.01000000", "0.04081000"], ["83868.09000000", "0.00000000"], ["83871.89000000", "0.00000000"], ["83872.02000000", "0.04000000"], ["83872.09000000", "0.00000000"], ["83873.14000000", "0.04800000"], ["83873.24000000", "0.04400000"], ["83877.06000000", "0.00041000"], ["83877.07000000", "0.00000000"], ["83880.92000000", "0.00000000"], ["83881.25000000", "0.00000000"], ["83883.81000000", "0.04800000"], ["83898.54000000", "0.23263000"], ["83924.07000000", "0.04897000"], ["83926.12000000", "0.00000000"], ["83930.77000000", "0.00000000"], ["83952.48000000", "0.00035000"], ["83952.49000000", "0.00000000"], ["83961.89000000", "0.00000000"], ["83964.86000000", "0.00000000"], ["83966.40000000", "0.00006000"], ["83966.50000000", "0.01000000"], ["83968.09000000", "0.00000000"], ["84003.31000000", "0.01865000"], ["84950.97000000", "0.00000000"], ["84959.38000000", "0.60000000"], ["85021.25000000", "0.00000000"], ["85042.50000000", "0.17665000"], ["85049.35000000", "0.00000000"]], "record_time": 1742561186.151272, "EXCHANGE": "BINANCE"}
{"e": "depthUpdate", "E": 1742561187014, "s": "BTCUSDT", "U": 64610666789, "u": 64610667132, "b": [["83792.45000000", "4.48084000"], ["83791.90000000", "0.45840000"], ["83791.89000000", "0.13411000"], ["83791.81000000", "0.00017000"], ["83791.62000000", "0.00000000"], ["83791.46000000", "0.03726000"], ["83790.08000000", "0.02386000"], ["83789.70000000", "0.00300000"], ["83789.66000000", "0.00000000"], ["83789.60000000", "0.00000000"], ["83788.52000000", "0.00000000"], ["83788.44000000", "0.00000000"], ["83785.76000000", "0.00000000"], ["83785.68000000", "0.00000000"], ["83783.32000000", "0.04000000"], ["83783.24000000", "0.00012000"], ["83783.06000000", "0.28310000"], ["83782.66000000", "0.04000000"], ["83782.02000000", "0.00097000"], ["83781.88000000", "0.00091000"], ["83781.64000000", "0.04000000"], ["83781.63000000", "0.04000000"], ["83781.55000000", "0.04000000"], ["83780.81000000", "0.00419000"], ["83779.60000000", "0.00300000"], ["83779.50000000", "0.00000000"], ["83779.12000000", "0.04000000"], ["83778.50000000", "0.04000000"], ["83777.94000000", "0.00000000"], ["83777.65000000", "0.04000000"], ["83777.46000000", "0.04000000"], ["83777.39000000", "0.04000000"], ["83777.07000000", "0.00000000"], ["83776.25000000", "0.00000000"], ["83776.16000000", "0.00000000"], ["83773.76000000", "0.00000000"], ["83772.89000000", "0.00000000"], ["83772.08000000", "0.00000000"], ["83772.05000000", "0.00000000"], ["83771.97000000", "0.00000000"], ["83770.45000000", "1.66890000"], ["83758.25000000", "0.00000000"], ["83757.98000000", "0.96590000"], ["83754.99000000", "0.00000000"], ["83748.55000000", "0.04469000"], ["83747.98000000", "0.05000000"], ["83724.07000000", "0.04000000"], ["83715.46000000", "0.04000000"], ["83694.91000000", "0.53924000"], ["83694.90000000", "0.63187000"], ["83694.48000000", "0.00000000"], ["83678.30000000", "0.00091000"], ["83659.33000000", "0.00015000"], ["83651.82000000", "0.00000000"], ["83645.09000000", "0.00000000"], ["83637.83000000", "0.00400000"], ["83632.99000000", "0.01000000"], ["83632.81000000", "0.00000000"], ["83631.89000000", "0.00000000"], ["83614.37000000", "0.00537000"], ["83614.36000000", "0.00133000"], ["83614.35000000", "0.00000000"], ["83608.50000000", "0.32072000"], ["83608.47000000", "0.00000000"], ["83604.67000000", "0.00000000"], ["83586.22000000", "0.00000000"], ["83586.21000000", "0.00000000"], ["83586.20000000", "0.00083000"], ["82954.52000000", "0.00000000"], ["82919.58000000", "0.40000000"], ["82535.56000000", "0.00107000"], ["79600.00000000", "1.06505000"], ["75413.01000000", "0.00000000"], ["75413.00000000", "0.30120000"], ["75412.00000000", "0.00034000"], ["67033.98000000", "0.00000000"], ["67033.97000000", "0.00000000"], ["67033.96000000", "0.00058000"], ["33000.01000000", "0.00000000"], ["33000.00000000", "2.93827000"]], "a": [["83792.46000000", "1.29544000"], ["83792.97000000", "0.00008000"], ["83793.99000000", "0.00042000"], ["83794.00000000", "0.02043000"], ["83794.66000000", "0.00007000"], ["83796.57000000", "0.00023000"], ["83796.58000000", "0.49941000"], ["83796.59000000", "0.00000000"], ["83796.94000000", "0.00014000"], ["83796.95000000", "0.78806000"], ["83797.43000000", "0.00006000"], ["83798.23000000", "0.23881000"], ["83798.79000000", "0.00000000"], ["83798.86000000", "0.00000000"], ["83799.09000000", "0.00000000"], ["83799.15000000", "0.00182000"], ["83799.26000000", "0.23880000"], ["83800.00000000", "0.41660000"], ["83800.01000000", "0.00100000"], ["83800.64000000", "0.23880000"], ["83800.84000000", "0.45300000"], ["83800.95000000", "0.00000000"], ["83801.05000000", "0.04000000"], ["83802.73000000", "0.04000000"], ["83802.79000000", "0.04400000"], ["83802.80000000", "0.00000000"], ["83802.95000000", "0.00000000"], ["83803.03000000", "0.00000000"], ["83803.04000000", "0.00000000"], ["83803.32000000", "0.00012000"], ["83803.49000000", "0.00000000"], ["83804.37000000", "0.10986000"], ["83804.90000000", "0.14070000"], ["83805.00000000", "0.00000000"], ["83805.12000000", "0.05975000"], ["83806.00000000", "0.00000000"], ["83808.02000000", "0.00000000"], ["83808.03000000", "0.02262000"], ["83808.17000000", "0.00500000"], ["83809.48000000", "0.00000000"], ["83809.49000000", "0.00000000"], ["83809.52000000", "0.00000000"], ["83809.54000000", "0.03581000"], ["83810.75000000", "0.00008000"], ["83813.53000000", "1.00000000"], ["83815.00000000", "0.00400000"], ["83816.46000000", "0.00000000"], ["83816.76000000", "0.88325000"], ["83817.58000000", "0.67057000"], ["83820.51000000", "0.85939000"], ["83821.51000000", "0.00000000"], ["83821.74000000", "0.05755000"], ["83827.77000000", "0.05000000"], ["83828.97000000", "0.00000000"], ["83831.50000000", "0.00000000"], ["83832.12000000", "0.00000000"], ["83834.80000000", "0.00000000"], ["83843.05000000", "0.04773000"], ["83852.49000000", "0.00000000"], ["83853.40000000", "0.04081000"], ["83859.27000000", "0.04000000"], ["83859.82000000", "0.07453000"], ["83867.01000000", "0.00000000"], ["83872.02000000", "0.00000000"], ["83873.14000000", "0.00000000"], ["83873.24000000", "0.00000000"], ["83873.35000000", "0.02388000"], ["83881.91000000", "0.00000000"], ["83882.00000000", "0.00000000"], ["83883.81000000", "0.00000000"], ["83894.16000000", "0.01861000"], ["83894.59000000", "0.01861000"], ["83898.54000000", "0.00000000"], ["83901.50000000", "0.00000000"], ["83935.53000000", "0.00000000"], ["83942.94000000", "0.00000000"], ["83966.50000000", "0.00000000"], ["83966.80000000", "0.01000000"], ["83981.79000000", "0.00000000"], ["83990.25000000", "0.00000000"], ["83995.11000000", "0.00000000"], ["85049.35000000", "0.00100000"], ["89432.00000000", "2.21779000"]], "record_time": 1742561187.172099, "EXCHANGE": "BINANCE"}
{"e": "depthUpdate", "E": 1742561188014, "s": "BTCUSDT", "U": 64610667133, "u": 64610667396, "b": [["83792.45000000", "2.99992000"], ["83791.62000000", "0.00000000"], ["83791.17000000", "0.78805000"], ["83790.08000000", "0.00000000"], ["83788.44000000", "0.00000000"], ["83788.43000000", "0.02238000"], ["83787.60000000", "0.00000000"], ["83787.59000000", "0.00000000"], ["83785.68000000", "0.00000000"], ["83785.66000000", "0.02338000"], ["83783.24000000", "0.00012000"], ["83780.00000000", "0.00826000"], ["83778.69000000", "0.56997000"], ["83776.11000000", "0.00000000"], ["83773.79000000", "0.85986000"], ["83769.87000000", "0.00760000"], ["83768.62000000", "1.00000000"], ["83766.99000000", "0.00000000"], ["83766.81000000", "0.00000000"], ["83766.74000000", "1.36105000"], ["83766.49000000", "0.00000000"], ["83762.12000000", "0.45960000"], ["83762.11000000", "0.00000000"], ["83761.93000000", "0.00000000"], ["83761.29000000", "0.85999000"], ["83760.54000000", "0.00000000"], ["83757.13000000", "0.59915000"], ["83748.98000000", "0.00000000"], ["83748.55000000", "0.00000000"], ["83747.98000000", "0.00000000"], ["83738.94000000", "0.04469000"], ["83694.91000000", "0.00000000"], ["83694.90000000", "0.00000000"], ["83669.09000000", "0.01869000"], ["83643.74000000", "0.00000000"], ["83637.83000000", "0.00000000"], ["83635.24000000", "0.00000000"], ["83633.09000000", "0.01000000"], ["83632.99000000", "0.00000000"], ["83624.84000000", "0.00400000"], ["83614.37000000", "0.00000000"], ["82790.00000000", "0.10824000"], ["82789.99000000", "0.00000000"], ["82535.56000000", "0.00007000"], ["82432.63000000", "0.00000000"], ["80431.24000000", "0.00000000"], ["80414.46000000", "0.00000000"], ["75413.00000000", "0.30120000"], ["67033.96000000", "0.00058000"], ["33000.00000000", "2.93827000"], ["30293.18000000", "0.00000000"]], "a": [["83792.46000000", "1.22665000"], ["83792.49000000", "0.00014000"], ["83792.50000000", "0.12536000"], ["83792.53000000", "0.00000000"], ["83792.92000000", "0.00014000"], ["83792.93000000", "0.32665000"], ["83792.94000000", "0.34647000"], ["83792.97000000", "0.00008000"], ["83793.08000000", "0.00820000"], ["83793.82000000", "0.00007000"], ["83793.98000000", "0.00000000"], ["83793.99000000", "0.00000000"], ["83794.00000000", "0.00000000"], ["83794.66000000", "0.00007000"], ["83795.59000000", "0.00000000"], ["83795.60000000", "0.78800000"], ["83796.13000000", "0.00008000"], ["83796.14000000", "0.02410000"], ["83796.57000000", "0.00009000"], ["83796.58000000", "0.14867000"], ["83796.61000000", "0.00000000"], ["83796.94000000", "0.00000000"], ["83796.95000000", "0.00000000"], ["83797.37000000", "0.00000000"], ["83797.38000000", "0.00000000"], ["83797.43000000", "0.00000000"], ["83797.55000000", "0.00000000"], ["83798.23000000", "0.23881000"], ["83799.12000000", "0.00000000"], ["83799.15000000", "0.00000000"], ["83799.52000000", "0.00755000"], ["83800.00000000", "0.37354000"], ["83800.84000000", "0.45300000"], ["83805.02000000", "0.01193000"], ["83806.00000000", "0.00500000"], ["83808.42000000", "0.67815000"], ["83809.01000000", "0.00000000"], ["83809.54000000", "0.00000000"], ["83812.59000000", "0.08992000"], ["83813.09000000", "0.03581000"], ["83813.52000000", "1.83796000"], ["83814.27000000", "0.00000000"], ["83814.49000000", "0.01869000"], ["83814.86000000", "1.39928000"], ["83815.00000000", "0.00000000"], ["83816.17000000", "0.85943000"], ["83816.76000000", "0.02383000"], ["83823.15000000", "0.59701000"], ["83827.77000000", "0.00000000"], ["83828.15000000", "0.00000000"], ["83831.11000000", "0.00000000"], ["83836.65000000", "0.00000000"], ["83901.70000000", "0.00000000"], ["83903.26000000", "0.00844000"], ["85049.35000000", "0.00000000"]], "record_time": 1742561188.135029, "EXCHANGE": "BINANCE"}
{"e": "depthUpdate", "E": 1742561189014, "s": "BTCUSDT", "U": 64610667397, "u": 64610667770, "b": [["83792.45000000", "3.11735000"], ["83792.40000000", "0.12993000"], ["83792.39000000", "0.00000000"], ["83792.34000000", "0.00006000"], ["83792.00000000", "0.02820000"], ["83791.94000000", "0.00006000"], ["83791.90000000", "0.38540000"], ["83791.46000000", "0.00000000"], ["83791.30000000", "0.00000000"], ["83791.06000000", "0.00000000"], ["83790.78000000", "0.01193000"], ["83790.03000000", "0.00000000"], ["83789.74000000", "0.00000000"], ["83789.70000000", "0.00000000"], ["83789.43000000", "0.00012000"], ["83788.43000000", "0.00000000"], ["83788.34000000", "0.02246000"], ["83788.30000000", "0.00500000"], ["83787.63000000", "0.05975000"], ["83787.36000000", "0.00000000"], ["83785.88000000", "0.00000000"], ["83785.76000000", "0.00000000"], ["83785.66000000", "0.00000000"], ["83785.58000000", "0.02344000"], ["83784.08000000", "0.14358000"], ["83784.07000000", "0.45000000"], ["83783.57000000", "0.00000000"], ["83783.24000000", "0.00012000"], ["83782.87000000", "0.00000000"], ["83780.67000000", "0.00119000"], ["83780.04000000", "0.00000000"], ["83779.60000000", "0.00000000"], ["83778.69000000", "0.76735000"], ["83777.57000000", "0.00000000"], ["83776.17000000", "0.00000000"], ["83775.56000000", "0.00000000"], ["83775.43000000", "0.03581000"], ["83775.14000000", "0.15837000"], ["83774.75000000", "0.08338000"], ["83773.79000000", "0.00000000"], ["83773.56000000", "0.85987000"], ["83772.64000000", "0.00000000"], ["83770.44000000", "0.85622000"], ["83765.19000000", "0.00000000"], ["83763.84000000", "0.85997000"], ["83762.65000000", "0.00897000"], ["83762.12000000", "0.28050000"], ["83762.10000000", "0.00000000"], ["83761.29000000", "0.00000000"], ["83760.42000000", "0.00000000"], ["83757.13000000", "0.00214000"], ["83754.83000000", "0.00000000"], ["83752.23000000", "0.59703000"], ["83744.66000000", "0.04229000"], ["83744.59000000", "0.05000000"], ["83742.70000000", "0.00000000"], ["83694.48000000", "0.28964000"], ["83678.30000000", "0.00000000"], ["83678.29000000", "0.00091000"], ["83639.47000000", "0.00000000"], ["83635.07000000", "0.00400000"], ["83633.64000000", "0.00000000"], ["83633.09000000", "0.00000000"], ["83631.89000000", "0.01000000"], ["83629.61000000", "0.00000000"], ["83624.85000000", "0.00418000"], ["83624.84000000", "0.00000000"], ["83616.05000000", "0.00119000"], ["83616.04000000", "0.00000000"], ["83586.20000000", "0.00007000"], ["82790.00000000", "0.10363000"], ["82535.56000000", "0.00107000"], ["75413.00000000", "0.30120000"], ["75412.00000000", "0.00034000"], ["67033.96000000", "0.00058000"], ["33000.00000000", "2.93827000"], ["30165.28000000", "0.00300000"]], "a": [["83792.46000000", "1.14148000"], ["83792.49000000", "0.00000000"], ["83792.50000000", "0.00000000"], ["83792.62000000", "0.00014000"], ["83792.63000000", "0.10390000"], ["83792.93000000", "0.13245000"], ["83792.94000000", "0.34640000"], ["83793.08000000", "0.18029000"], ["83793.77000000", "0.00000000"], ["83793.82000000", "0.00007000"], ["83794.13000000", "0.00000000"], ["83794.66000000", "0.00000000"], ["83795.04000000", "0.04000000"], ["83795.59000000", "0.00000000"], ["83795.60000000", "0.00000000"], ["83795.63000000", "0.00000000"], ["83796.13000000", "0.00000000"], ["83796.57000000", "0.00000000"], ["83796.58000000", "0.14867000"], ["83797.83000000", "0.08338000"], ["83797.84000000", "0.00000000"], ["83797.88000000", "0.00012000"], ["83798.54000000", "0.05975000"], ["83799.15000000", "0.00000000"], ["83800.08000000", "0.00000000"], ["83800.84000000", "0.00300000"], ["83801.53000000", "0.00000000"], ["83801.88000000", "0.00000000"], ["83803.32000000", "0.00000000"], ["83803.90000000", "0.00416000"], ["83804.37000000", "0.23311000"], ["83804.86000000", "0.00000000"], ["83805.12000000", "0.00000000"], ["83806.96000000", "0.00000000"], ["83807.26000000", "0.35802000"], ["83808.03000000", "0.02289000"], ["83811.39000000", "0.02408000"], ["83813.09000000", "0.00000000"], ["83813.13000000", "0.03581000"], ["83813.53000000", "0.00000000"], ["83814.27000000", "0.00000000"], ["83814.62000000", "0.00000000"], ["83815.35000000", "0.00000000"], ["83816.17000000", "0.00000000"], ["83816.85000000", "0.85942000"], ["83818.54000000", "0.05811000"], ["83818.74000000", "0.00000000"], ["83819.69000000", "0.71594000"], ["83821.74000000", "0.00000000"], ["83823.14000000", "0.86153000"], ["83823.47000000", "0.00000000"], ["83826.81000000", "0.85932000"], ["83828.53000000", "0.00000000"], ["83829.62000000", "0.00000000"], ["83832.36000000", "0.00000000"], ["83837.41000000", "0.11460000"], ["83838.91000000", "0.35802000"], ["83841.66000000", "0.00000000"], ["83877.05000000", "0.00000000"], ["83877.06000000", "0.00000000"], ["83885.23000000", "0.23263000"], ["83894.16000000", "0.00000000"], ["83894.59000000", "0.00000000"], ["83915.54000000", "0.18383000"], ["83929.30000000", "0.00000000"], ["83952.47000000", "0.00000000"], ["83952.48000000", "0.00000000"], ["83964.49000000", "0.01000000"], ["83964.79000000", "0.00000000"], ["83966.80000000", "0.00000000"], ["84003.31000000", "0.00075000"], ["84005.09000000", "0.01790000"], ["84500.00000000", "5.44129000"], ["85049.35000000", "0.00100000"]], "record_time": 1742561189.174593, "EXCHANGE": "BINANCE"}
{"e": "depthUpdate", "E": 1742561190014, "s": "BTCUSDT", "U": 64610667771, "u": 64610668350, "b": [["83792.45000000", "4.43804000"], ["83792.40000000", "0.12999000"], ["83792.34000000", "0.00000000"], ["83792.00000000", "0.02826000"], ["83791.94000000", "0.00000000"], ["83791.90000000", "0.38546000"], ["83791.89000000", "0.13417000"], ["83791.81000000", "0.00011000"], ["83791.17000000", "0.78811000"], ["83791.01000000", "0.05981000"], ["83790.09000000", "0.02392000"], ["83789.43000000", "0.00000000"], ["83788.57000000", "0.00000000"], ["83788.45000000", "0.00000000"], ["83787.63000000", "0.00000000"], ["83787.60000000", "0.08353000"], ["83783.24000000", "0.00000000"], ["83781.88000000", "0.00000000"], ["83781.72000000", "0.00091000"], ["83780.00000000", "0.06793000"], ["83779.20000000", "0.00897000"], ["83775.14000000", "0.00000000"], ["83773.90000000", "0.00000000"], ["83770.65000000", "0.35802000"], ["83769.66000000", "0.12524000"], ["83767.10000000", "0.00932000"], ["83766.24000000", "0.00000000"], ["83764.95000000", "0.14913000"], ["83764.94000000", "0.08992000"], ["83762.98000000", "0.00000000"], ["83762.65000000", "0.00000000"], ["83752.22000000", "0.25157000"], ["83749.87000000", "0.00000000"], ["83744.59000000", "0.00000000"], ["83740.28000000", "0.00000000"], ["83740.00000000", "0.00813000"], ["83739.64000000", "0.35802000"], ["83738.94000000", "0.00000000"], ["83698.21000000", "0.97025000"], ["83697.73000000", "0.63187000"], ["83669.09000000", "0.00000000"], ["83664.47000000", "0.00008000"], ["83650.74000000", "0.00400000"], ["83644.36000000", "0.00000000"], ["83635.07000000", "0.00000000"], ["83633.49000000", "0.00000000"], ["83633.09000000", "0.01000000"], ["83631.89000000", "0.00000000"], ["83616.08000000", "0.00000000"], ["83616.07000000", "0.00000000"], ["83616.06000000", "0.00000000"], ["83616.05000000", "0.00000000"], ["83569.50000000", "0.00119000"], ["83569.49000000", "0.00076000"], ["83569.48000000", "0.00000000"], ["83075.41000000", "0.00008000"], ["83075.37000000", "0.00060000"], ["83056.09000000", "0.00000000"], ["83056.04000000", "0.00060000"], ["83000.00000000", "35.34949000"], ["82790.01000000", "0.00000000"], ["82790.00000000", "0.10287000"], ["82789.99000000", "0.02355000"], ["82535.56000000", "0.00007000"], ["82000.02000000", "0.00619000"], ["82000.01000000", "0.01257000"], ["82000.00000000", "64.49845000"], ["80414.46000000", "0.03579000"], ["75413.00000000", "0.30120000"], ["75412.00000000", "0.00034000"], ["67033.96000000", "0.00058000"], ["33000.00000000", "2.93827000"], ["30165.29000000", "0.00000000"], ["30165.28000000", "0.00380000"]], "a": [["83792.46000000", "0.04440000"], ["83792.62000000", "0.00000000"], ["83792.63000000", "0.00000000"], ["83792.92000000", "0.00000000"], ["83792.93000000", "0.00000000"], ["83792.94000000", "0.00000000"], ["83792.97000000", "0.00015000"], ["83793.07000000", "0.00000000"], ["83793.08000000", "0.00000000"], ["83793.82000000", "0.00000000"], ["83794.69000000", "0.00014000"], ["83794.70000000", "0.01217000"], ["83794.71000000", "0.00000000"], ["83794.72000000", "0.00000000"], ["83794.73000000", "0.00000000"], ["83795.03000000", "0.00007000"], ["83795.04000000", "0.00006000"], ["83795.50000000", "0.00007000"], ["83795.97000000", "0.00014000"], ["83795.98000000", "0.28564000"], ["83796.13000000", "0.00007000"], ["83796.14000000", "0.02417000"], ["83796.57000000", "0.00023000"], ["83796.58000000", "0.37024000"], ["83796.82000000", "0.00000000"], ["83796.83000000", "0.00000000"], ["83797.69000000", "0.00000000"], ["83797.70000000", "0.00000000"], ["83797.74000000", "0.06117000"], ["83797.78000000", "0.00000000"], ["83797.79000000", "0.00000000"], ["83797.81000000", "0.78804000"], ["83797.83000000", "0.00000000"], ["83797.88000000", "0.00000000"], ["83798.23000000", "0.23881000"], ["83798.54000000", "0.00000000"], ["83798.88000000", "0.00000000"], ["83799.26000000", "0.23880000"], ["83799.31000000", "0.02208000"], ["83799.74000000", "0.00000000"], ["83800.00000000", "0.21878000"], ["83800.84000000", "0.00300000"], ["83800.90000000", "0.00000000"], ["83801.75000000", "0.00007000"], ["83803.13000000", "0.00012000"], ["83803.23000000", "0.00092000"], ["83804.37000000", "0.10986000"], ["83804.93000000", "0.05975000"], ["83805.02000000", "0.01084000"], ["83806.00000000", "0.00500000"], ["83807.26000000", "0.00000000"], ["83808.03000000", "0.00000000"], ["83808.94000000", "0.00000000"], ["83811.39000000", "0.00000000"], ["83811.63000000", "1.08338000"], ["83812.55000000", "0.00000000"], ["83812.59000000", "0.00000000"], ["83813.13000000", "0.00000000"], ["83813.16000000", "0.00000000"], ["83813.21000000", "0.00000000"], ["83813.26000000", "0.00000000"], ["83813.27000000", "0.00000000"], ["83813.31000000", "0.00023000"], ["83813.32000000", "0.00000000"], ["83813.33000000", "0.03581000"], ["83814.62000000", "0.00000000"], ["83816.17000000", "0.35802000"], ["83816.84000000", "0.00000000"], ["83816.85000000", "0.00000000"], ["83817.58000000", "0.00000000"], ["83819.69000000", "0.71594000"], ["83823.15000000", "0.00000000"], ["83829.17000000", "0.00000000"], ["83829.69000000", "0.59697000"], ["83829.95000000", "0.85929000"], ["83836.39000000", "0.00000000"], ["83845.37000000", "0.00000000"], ["83853.40000000", "0.00000000"], ["83862.87000000", "0.04081000"], ["83873.98000000", "0.00000000"], ["83876.13000000", "0.13963000"], ["83877.03000000", "0.00000000"], ["83877.04000000", "0.00000000"], ["83877.07000000", "0.00041000"], ["83885.14000000", "0.00000000"], ["83885.23000000", "0.00000000"], ["83890.73000000", "0.00000000"], ["83892.02000000", "0.00000000"], ["83894.09000000", "0.00000000"], ["83894.17000000", "0.00000000"], ["83897.18000000", "0.00000000"], ["83902.68000000", "0.00000000"], ["83909.98000000", "0.35475000"], ["83909.99000000", "0.00000000"], ["83910.97000000", "0.00000000"], ["83952.45000000", "0.00000000"], ["83952.46000000", "0.00000000"], ["83952.49000000", "0.00035000"], ["83964.49000000", "0.00000000"], ["83964.59000000", "0.00000000"], ["83965.16000000", "0.00000000"], ["83965.90000000", "0.00000000"], ["83966.65000000", "0.00000000"], ["83966.80000000", "0.01000000"], ["83966.85000000", "0.00000000"], ["83968.57000000", "0.00000000"], ["85049.35000000", "0.00000000"]], "record_time": 1742561190.221861, "EXCHANGE": "BINANCE"}
{"e": "depthUpdate", "E": 1742561191014, "s": "BTCUSDT", "U": 64610668351, "u": 64610670759, "b": [["83800.79000000", "5.52355000"], ["83800.78000000", "0.00041000"], ["83800.76000000", "0.41006000"], ["83800.73000000", "0.00000000"], ["83800.65000000", "0.62852000"], ["83800.64000000", "0.78796000"], ["83800.63000000", "0.00000000"], ["83800.62000000", "0.00000000"], ["83800.00000000", "0.02844000"], ["83799.55000000", "0.00000000"], ["83799.13000000", "0.00736000"], ["83799.12000000", "0.01193000"], ["83798.89000000", "0.00007000"], ["83798.87000000", "0.00000000"], ["83798.67000000", "0.00000000"], ["83798.64000000", "0.00009000"], ["83798.56000000", "0.00000000"], ["83798.55000000", "0.45006000"], ["83798.02000000", "0.00000000"], ["83798.00000000", "0.02820000"], ["83797.79000000", "0.00000000"], ["83797.75000000", "0.00000000"], ["83797.74000000", "0.00006000"], ["83797.73000000", "0.21834000"], ["83797.72000000", "0.28056000"], ["83797.71000000", "0.00000000"], ["83797.49000000", "0.00000000"], ["83797.46000000", "0.00000000"], ["83797.45000000", "0.00000000"], ["83797.40000000", "0.00013000"], ["83797.39000000", "0.00000000"], ["83797.38000000", "0.00000000"], ["83797.31000000", "0.00000000"], ["83797.30000000", "0.00000000"], ["83797.29000000", "0.00000000"], ["83797.20000000", "0.00000000"], ["83797.15000000", "0.02368000"], ["83796.56000000", "0.00000000"], ["83796.47000000", "0.00000000"], ["83796.46000000", "0.00000000"], ["83796.35000000", "0.00000000"], ["83796.34000000", "0.00557000"], ["83796.26000000", "0.00000000"], ["83796.25000000", "0.00000000"], ["83796.23000000", "0.00000000"], ["83796.14000000", "0.00008000"], ["83796.13000000", "0.23251000"], ["83796.12000000", "0.00000000"], ["83796.00000000", "0.02820000"], ["83795.76000000", "0.00000000"], ["83795.74000000", "0.00000000"], ["83795.73000000", "0.00000000"], ["83795.65000000", "0.00000000"], ["83795.64000000", "0.00000000"], ["83795.63000000", "0.00000000"], ["83795.62000000", "0.00000000"], ["83795.61000000", "0.00000000"], ["83795.51000000", "0.00000000"], ["83794.45000000", "0.00000000"], ["83794.00000000", "0.02820000"], ["83793.82000000", "0.00000000"], ["83793.81000000", "0.00000000"], ["83793.63000000", "0.14587000"], ["83793.62000000", "0.00000000"], ["83793.61000000", "0.00000000"], ["83792.98000000", "0.00000000"], ["83792.96000000", "0.00000000"], ["83792.88000000", "0.00000000"], ["83792.77000000", "0.00000000"], ["83792.66000000", "0.00000000"], ["83792.65000000", "0.45000000"], ["83792.58000000", "0.00000000"], ["83792.56000000", "0.00000000"], ["83792.47000000", "0.00000000"], ["83792.46000000", "0.00000000"], ["83792.45000000", "0.00000000"], ["83792.44000000", "0.00000000"], ["83792.41000000", "0.00000000"], ["83792.40000000", "0.00000000"], ["83792.36000000", "0.00029000"], ["83792.08000000", "0.00000000"], ["83792.00000000", "0.02820000"], ["83791.90000000", "0.00000000"], ["83791.89000000", "0.00000000"], ["83791.83000000", "0.00119000"], ["83791.81000000", "0.00000000"], ["83791.80000000", "0.00000000"], ["83791.70000000", "0.00007000"], ["83791.62000000", "0.00012000"], ["83791.17000000", "0.00000000"], ["83791.03000000", "0.00000000"], ["83791.02000000", "0.08821000"], ["83791.01000000", "0.00000000"], ["83790.78000000", "0.00000000"], ["83790.45000000", "0.00000000"], ["83790.33000000", "0.00013000"], ["83790.17000000", "0.00000000"], ["83790.09000000", "0.02386000"], ["83789.53000000", "0.00000000"], ["83789.37000000", "0.00000000"], ["83788.78000000", "0.00000000"], ["83788.77000000", "0.00000000"], ["83788.76000000", "0.00000000"], ["83788.38000000", "0.00058000"], ["83788.30000000", "0.00000000"], ["83788.01000000", "0.00000000"], ["83787.95000000", "0.02386000"], ["83787.77000000", "0.00000000"], ["83787.72000000", "0.04000000"], ["83787.60000000", "0.08353000"], ["83787.59000000", "0.04000000"], ["83786.76000000", "0.36993000"], ["83786.75000000", "0.71594000"], ["83786.68000000", "0.00007000"], ["83786.58000000", "0.00009000"], ["83786.40000000", "0.01500000"], ["83786.05000000", "0.08000000"], ["83785.94000000", "0.04000000"], ["83785.80000000", "0.00006000"], ["83785.79000000", "0.00000000"], ["83785.66000000", "0.00013000"], ["83785.55000000", "0.11184000"], ["83785.48000000", "0.01500000"], ["83785.06000000", "0.02000000"], ["83784.62000000", "0.00119000"], ["83784.34000000", "0.00000000"], ["83784.08000000", "0.00000000"], ["83783.86000000", "0.05967000"], ["83783.76000000", "0.04000000"], ["83783.53000000", "0.04000000"], ["83783.25000000", "0.00008000"], ["83783.24000000", "0.00000000"], ["83782.96000000", "0.00000000"], ["83782.55000000", "0.00000000"], ["83782.02000000", "0.00000000"], ["83781.88000000", "0.04000000"], ["83781.80000000", "0.04000000"], ["83781.72000000", "0.00000000"], ["83781.64000000", "0.00000000"], ["83781.55000000", "0.00000000"], ["83780.81000000", "0.00000000"], ["83780.67000000", "0.00000000"], ["83780.19000000", "0.00758000"], ["83779.79000000", "0.00119000"], ["83779.36000000", "0.00000000"], ["83779.20000000", "0.00000000"], ["83778.92000000", "0.85981000"], ["83778.69000000", "0.56997000"], ["83777.83000000", "0.00000000"], ["83777.71000000", "0.00000000"], ["83777.46000000", "0.00000000"], ["83777.23000000", "0.00000000"], ["83777.12000000", "0.00000000"], ["83776.23000000", "0.00000000"], ["83775.72000000", "0.00000000"], ["83775.03000000", "0.00897000"], ["83774.47000000", "0.85986000"], ["83774.18000000", "0.11693000"], ["83773.56000000", "0.00000000"], ["83772.18000000", "0.00000000"], ["83771.85000000", "0.00000000"], ["83771.82000000", "0.00000000"], ["83771.78000000", "0.08992000"], ["83770.87000000", "0.00572000"], ["83770.67000000", "0.04469000"], ["83769.87000000", "0.00000000"], ["83769.66000000", "0.00354000"], ["83769.57000000", "0.00101000"], ["83769.16000000", "0.85991000"], ["83769.06000000", "0.20185000"], ["83768.77000000", "1.38696000"], ["83767.31000000", "0.00300000"], ["83767.10000000", "0.00000000"], ["83766.74000000", "0.00000000"], ["83765.89000000", "0.00000000"], ["83765.37000000", "0.00214000"], ["83764.96000000", "0.59697000"], ["83764.95000000", "0.00000000"], ["83764.94000000", "0.00000000"], ["83764.29000000", "0.00016000"], ["83763.84000000", "0.00000000"], ["83762.19000000", "0.20685000"], ["83762.12000000", "0.28050000"], ["83760.98000000", "0.04229000"], ["83758.90000000", "0.00000000"], ["83757.66000000", "0.21749000"], ["83757.13000000", "0.00000000"], ["83756.35000000", "0.00000000"], ["83755.24000000", "0.89506000"], ["83754.57000000", "0.00000000"], ["83753.98000000", "0.00000000"], ["83752.23000000", "0.00000000"], ["83752.22000000", "0.00000000"], ["83750.35000000", "0.00000000"], ["83744.66000000", "0.00000000"], ["83744.49000000", "0.35802000"], ["83742.41000000", "0.00000000"], ["83739.64000000", "0.00000000"], ["83734.87000000", "0.00827000"], ["83731.70000000", "0.18782000"], ["83730.99000000", "0.00061000"], ["83726.62000000", "0.00000000"], ["83724.99000000", "0.12827000"], ["83721.22000000", "0.00000000"], ["83717.45000000", "0.00000000"], ["83716.35000000", "0.12901000"], ["83715.37000000", "0.00000000"], ["83712.94000000", "0.00000000"], ["83711.41000000", "0.80559000"], ["83707.97000000", "1.12893000"], ["83705.43000000", "0.00000000"], ["83698.21000000", "0.62675000"], ["83697.73000000", "0.00000000"], ["83697.28000000", "0.00000000"], ["83695.70000000", "0.00000000"], ["83695.46000000", "0.00000000"], ["83686.16000000", "0.00000000"], ["83679.00000000", "0.01186000"], ["83669.58000000", "0.05210000"], ["83665.92000000", "0.00000000"], ["83650.74000000", "0.00000000"], ["83648.27000000", "0.99313000"], ["83642.17000000", "0.00000000"], ["83638.57000000", "0.00000000"], ["83633.39000000", "0.00000000"], ["83633.29000000", "0.01000000"], ["83633.09000000", "0.00000000"], ["83625.12000000", "0.00000000"], ["83624.85000000", "0.00119000"], ["83609.72000000", "0.00242000"], ["83587.38000000", "0.00000000"], ["83585.34000000", "0.20185000"], ["83579.00000000", "0.03185000"], ["83576.97000000", "0.19068000"], ["83576.55000000", "0.00000000"], ["83571.46000000", "0.00000000"], ["82919.58000000", "0.00000000"], ["82535.56000000", "0.00107000"], ["80414.46000000", "0.00000000"], ["75420.00000000", "0.01037000"], ["75413.00000000", "0.30120000"], ["75412.00000000", "0.00014000"], ["67040.64000000", "0.00058000"], ["67033.96000000", "0.00000000"], ["33000.00000000", "2.93827000"], ["20002.00000000", "0.00000000"], ["20001.00000000", "0.02099000"]], "a": [["83792.46000000", "0.00000000"], ["83792.47000000", "0.00000000"], ["83792.66000000", "0.00000000"], ["83792.97000000", "0.00000000"], ["83793.28000000", "0.00000000"], ["83793.29000000", "0.00000000"], ["83793.62000000", "0.00000000"], ["83793.63000000", "0.00000000"], ["83793.64000000", "0.00000000"], ["83793.82000000", "0.00000000"], ["83794.69000000", "0.00000000"], ["83794.70000000", "0.00000000"], ["83795.03000000", "0.00000000"], ["83795.04000000", "0.00000000"], ["83795.50000000", "0.00000000"], ["83795.62000000", "0.00000000"], ["83795.63000000", "0.00000000"], ["83795.64000000", "0.00000000"], ["83795.97000000", "0.00000000"], ["83795.98000000", "0.00000000"], ["83796.13000000", "0.00000000"], ["83796.14000000", "0.00000000"], ["83796.35000000", "0.00000000"], ["83796.57000000", "0.00000000"], ["83796.58000000", "0.00000000"], ["83797.19000000", "0.00000000"], ["83797.30000000", "0.00000000"], ["83797.31000000", "0.00000000"], ["83797.39000000", "0.00000000"], ["83797.40000000", "0.00000000"], ["83797.46000000", "0.00000000"], ["83797.73000000", "0.00000000"], ["83797.74000000", "0.00000000"], ["83797.76000000", "0.00000000"], ["83797.77000000", "0.00000000"], ["83797.80000000", "0.00000000"], ["83797.81000000", "0.00000000"], ["83797.90000000", "0.00000000"], ["83797.91000000", "0.00000000"], ["83798.03000000", "0.00000000"], ["83798.22000000", "0.00000000"], ["83798.23000000", "0.00000000"], ["83798.40000000", "0.00000000"], ["83798.56000000", "0.00000000"], ["83798.88000000", "0.00000000"], ["83799.25000000", "0.00000000"], ["83799.26000000", "0.00000000"], ["83799.31000000", "0.00000000"], ["83799.52000000", "0.00000000"], ["83799.72000000", "0.00000000"], ["83800.00000000", "0.00000000"], ["83800.01000000", "0.00000000"], ["83800.57000000", "0.00000000"], ["83800.63000000", "0.00000000"], ["83800.64000000", "0.00000000"], ["83800.70000000", "0.00000000"], ["83800.79000000", "0.00000000"], ["83800.80000000", "1.22943000"], ["83800.81000000", "0.00042000"], ["83800.84000000", "0.00300000"], ["83800.88000000", "0.00000000"], ["83801.05000000", "0.00000000"], ["83801.16000000", "0.00000000"], ["83801.24000000", "0.00008000"], ["83801.58000000", "0.00000000"], ["83801.70000000", "0.00020000"], ["83801.71000000", "0.07741000"], ["83801.72000000", "0.00006000"], ["83801.73000000", "0.00000000"], ["83801.77000000", "0.00000000"], ["83802.25000000", "0.00007000"], ["83802.40000000", "0.00000000"], ["83802.73000000", "0.00000000"], ["83802.79000000", "0.00000000"], ["83802.91000000", "0.00000000"], ["83802.92000000", "0.00000000"], ["83802.93000000", "0.00000000"], ["83803.05000000", "0.00000000"], ["83803.07000000", "0.00014000"], ["83803.08000000", "0.25644000"], ["83803.13000000", "0.00000000"], ["83803.23000000", "0.00000000"], ["83803.29000000", "0.00000000"], ["83803.90000000", "0.00000000"], ["83803.93000000", "0.00089000"], ["83804.19000000", "0.00000000"], ["83804.29000000", "0.00000000"], ["83804.36000000", "0.00014000"], ["83804.37000000", "0.28590000"], ["83804.44000000", "0.02411000"], ["83804.54000000", "0.00000000"], ["83804.90000000", "0.00000000"], ["83804.93000000", "0.00000000"], ["83804.95000000", "0.00000000"], ["83805.02000000", "0.00000000"], ["83805.62000000", "0.04740000"], ["83805.78000000", "0.00000000"], ["83806.00000000", "0.00500000"], ["83806.12000000", "0.00754000"], ["83806.14000000", "0.00000000"], ["83806.37000000", "0.00000000"], ["83806.42000000", "0.04000000"], ["83806.46000000", "0.00000000"], ["83806.62000000", "0.00000000"], ["83806.72000000", "0.00000000"], ["83806.74000000", "0.02221000"], ["83807.49000000", "0.00000000"], ["83807.50000000", "0.78789000"], ["83808.11000000", "0.00000000"], ["83808.17000000", "0.00000000"], ["83808.19000000", "0.00000000"], ["83808.39000000", "0.13986000"], ["83808.42000000", "0.16152000"], ["83808.47000000", "0.00000000"], ["83808.55000000", "0.04000000"], ["83808.94000000", "0.00000000"], ["83809.04000000", "0.00119000"], ["83809.10000000", "0.00200000"], ["83809.14000000", "0.00029000"], ["83809.16000000", "0.00000000"], ["83809.32000000", "0.02281000"], ["83809.58000000", "0.00013000"], ["83809.60000000", "0.00000000"], ["83809.79000000", "0.00000000"], ["83809.90000000", "0.00000000"], ["83810.22000000", "0.04000000"], ["83810.23000000", "0.04000000"], ["83810.29000000", "0.00000000"], ["83810.31000000", "0.04400000"], ["83810.62000000", "0.04800000"], ["83810.69000000", "0.00007000"], ["83810.73000000", "0.00000000"], ["83810.85000000", "0.04800000"], ["83810.96000000", "0.00000000"], ["83811.06000000", "0.04400000"], ["83811.30000000", "0.00000000"], ["83811.46000000", "0.04800000"], ["83811.51000000", "0.00007000"], ["83811.63000000", "0.00000000"], ["83811.66000000", "0.00000000"], ["83811.82000000", "0.00012000"], ["83812.55000000", "0.02376000"], ["83812.64000000", "0.01500000"], ["83812.69000000", "0.00000000"], ["83812.73000000", "0.04800000"], ["83813.00000000", "0.00000000"], ["83813.33000000", "0.00000000"], ["83813.36000000", "0.01193000"], ["83813.40000000", "0.60501000"], ["83813.41000000", "1.31592000"], ["83813.47000000", "0.00000000"], ["83813.52000000", "0.00000000"], ["83813.58000000", "0.00000000"], ["83814.07000000", "0.01500000"], ["83814.13000000", "0.00000000"], ["83814.22000000", "0.00119000"], ["83814.28000000", "0.00000000"], ["83814.33000000", "0.05967000"], ["83814.49000000", "0.00000000"], ["83814.53000000", "0.05975000"], ["83814.63000000", "0.00000000"], ["83814.86000000", "0.00000000"], ["83814.99000000", "0.00000000"], ["83815.10000000", "0.00419000"], ["83816.76000000", "0.00012000"], ["83816.82000000", "0.56520000"], ["83817.02000000", "0.00007000"], ["83817.59000000", "0.00000000"], ["83818.12000000", "0.00000000"], ["83818.54000000", "0.00000000"], ["83818.77000000", "0.01193000"], ["83819.00000000", "0.00000000"], ["83819.01000000", "0.00000000"], ["83819.69000000", "0.08338000"], ["83819.86000000", "0.00000000"], ["83820.51000000", "0.00000000"], ["83820.75000000", "0.05941000"], ["83820.76000000", "0.00000000"], ["83821.26000000", "0.00000000"], ["83821.41000000", "0.00000000"], ["83821.45000000", "0.00000000"], ["83822.22000000", "0.06000000"], ["83822.86000000", "0.00000000"], ["83823.14000000", "0.00000000"], ["83823.35000000", "0.00007000"], ["83823.69000000", "0.00000000"], ["83824.49000000", "0.00000000"], ["83824.59000000", "0.00000000"], ["83825.06000000", "0.00000000"], ["83825.14000000", "0.00000000"], ["83825.31000000", "0.89506000"], ["83825.96000000", "0.20185000"], ["83825.97000000", "0.05967000"], ["83826.25000000", "0.89506000"], ["83826.81000000", "0.00000000"], ["83826.84000000", "0.00000000"], ["83826.85000000", "0.71594000"], ["83827.37000000", "0.89506000"], ["83827.50000000", "0.00000000"], ["83829.21000000", "0.89506000"], ["83829.68000000", "0.00000000"], ["83829.69000000", "0.00000000"], ["83829.95000000", "0.00000000"], ["83830.15000000", "0.00000000"], ["83830.49000000", "0.00000000"], ["83830.74000000", "0.85928000"], ["83831.49000000", "0.00000000"], ["83831.50000000", "0.00500000"], ["83831.63000000", "0.00000000"], ["83833.17000000", "0.00000000"], ["83833.37000000", "0.00000000"], ["83833.52000000", "0.00000000"], ["83834.04000000", "0.00357000"], ["83834.08000000", "0.89506000"], ["83834.65000000", "0.00000000"], ["83834.76000000", "0.00084000"], ["83834.77000000", "0.59694000"], ["83834.78000000", "0.00000000"], ["83834.90000000", "0.00583000"], ["83834.93000000", "0.85924000"], ["83835.65000000", "0.00000000"], ["83837.07000000", "0.00000000"], ["83837.41000000", "0.00000000"], ["83837.88000000", "0.04653000"], ["83838.52000000", "0.63969000"], ["83838.53000000", "0.00000000"], ["83838.98000000", "0.30293000"], ["83839.26000000", "0.85919000"], ["83839.57000000", "0.03401000"], ["83839.63000000", "0.07030000"], ["83841.90000000", "0.11772000"], ["83843.50000000", "0.00000000"], ["83843.51000000", "0.00000000"], ["83844.81000000", "0.02120000"], ["83846.31000000", "0.48759000"], ["83846.56000000", "0.00000000"], ["83847.10000000", "0.00000000"], ["83847.11000000", "0.18731000"], ["83848.18000000", "0.00817000"], ["83849.28000000", "0.00000000"], ["83850.74000000", "0.00848000"], ["83851.19000000", "0.00000000"], ["83853.52000000", "0.00298000"], ["83855.00000000", "0.14681000"], ["83855.77000000", "0.00000000"], ["83856.33000000", "0.00000000"], ["83856.81000000", "0.00000000"], ["83858.60000000", "0.00000000"], ["83859.81000000", "0.00000000"], ["83860.65000000", "0.04897000"], ["83860.71000000", "0.17918000"], ["83860.94000000", "0.04000000"], ["83861.98000000", "0.00000000"], ["83862.44000000", "0.00000000"], ["83862.64000000", "0.00000000"], ["83862.87000000", "0.00000000"], ["83863.92000000", "0.00000000"], ["83864.69000000", "0.15291000"], ["83867.64000000", "1.12678000"], ["83867.98000000", "0.00298000"], ["83868.09000000", "0.00000000"], ["83868.69000000", "0.09394000"], ["83868.98000000", "0.00000000"], ["83870.44000000", "0.19653000"], ["83872.02000000", "0.04000000"], ["83872.10000000", "0.09197000"], ["83873.14000000", "0.04800000"], ["83873.24000000", "0.04400000"], ["83873.39000000", "0.00000000"], ["83873.44000000", "0.00000000"], ["83873.66000000", "0.04081000"], ["83874.25000000", "0.04397000"], ["83876.13000000", "0.00000000"], ["83876.39000000", "0.00000000"], ["83876.47000000", "0.00000000"], ["83877.08000000", "0.00000000"], ["83878.25000000", "0.03180000"], ["83878.95000000", "0.05301000"], ["83879.75000000", "0.31010000"], ["83880.25000000", "0.04000000"], ["83880.93000000", "0.00000000"], ["83880.94000000", "0.15075000"], ["83881.91000000", "0.04000000"], ["83881.95000000", "0.00000000"], ["83882.00000000", "0.00000000"], ["83882.18000000", "0.00000000"], ["83883.69000000", "0.00000000"], ["83883.81000000", "0.00000000"], ["83885.15000000", "0.00000000"], ["83885.26000000", "0.00000000"], ["83886.70000000", "0.00000000"], ["83888.42000000", "0.02063000"], ["83888.61000000", "0.00000000"], ["83889.38000000", "0.00084000"], ["83891.00000000", "0.00000000"], ["83892.76000000", "0.00000000"], ["83893.15000000", "0.00000000"], ["83897.44000000", "0.00000000"], ["83897.88000000", "0.00000000"], ["83899.16000000", "0.03724000"], ["83901.71000000", "0.10994000"], ["83901.72000000", "0.00000000"], ["83905.28000000", "0.00000000"], ["83905.30000000", "0.05497000"], ["83910.36000000", "0.05497000"], ["83910.61000000", "0.00000000"], ["83911.97000000", "0.00348000"], ["83912.16000000", "0.04897000"], ["83913.46000000", "0.04897000"], ["83913.55000000", "0.05497000"], ["83914.79000000", "0.04653000"], ["83915.13000000", "0.00000000"], ["83915.81000000", "0.05497000"], ["83915.98000000", "0.04654000"], ["83916.10000000", "0.04654000"], ["83916.68000000", "0.04897000"], ["83918.85000000", "0.00000000"], ["83920.84000000", "0.04654000"], ["83922.99000000", "0.04897000"], ["83923.71000000", "0.17918000"], ["83926.88000000", "0.04198000"], ["83927.06000000", "0.00000000"], ["83927.09000000", "0.04897000"], ["83928.32000000", "0.05197000"], ["83930.34000000", "0.04198000"], ["83931.29000000", "0.05197000"], ["83932.22000000", "0.05497000"], ["83933.57000000", "0.05197000"], ["83933.76000000", "0.00013000"], ["83935.38000000", "0.00000000"], ["83935.42000000", "0.04198000"], ["83939.55000000", "0.00000000"], ["83941.31000000", "0.04198000"], ["83944.31000000", "0.00000000"], ["83947.80000000", "0.00000000"], ["83952.50000000", "0.00000000"], ["83956.88000000", "0.00000000"], ["83959.97000000", "0.00000000"], ["83972.43000000", "0.00000000"], ["83976.65000000", "0.00000000"], ["83981.83000000", "0.00000000"], ["83986.25000000", "0.00000000"], ["83991.11000000", "0.00000000"], ["83994.36000000", "0.00000000"], ["83998.27000000", "0.00000000"], ["84127.42000000", "0.02131000"], ["84129.95000000", "0.00000000"], ["84139.15000000", "0.00000000"], ["84959.38000000", "0.00000000"], ["85042.50000000", "0.00000000"], ["85049.35000000", "0.00100000"], ["85063.75000000", "0.05887000"]], "record_time": 1742561191.039904, "EXCHANGE": "BINANCE"}
{"result": null, "id": 1, "record_time": 1742561259.117828, "EXCHANGE": "BINANCE"}
{"e": "depthUpdate", "E": 1742561260014, "s": "BTCUSDT", "U": 64610727633, "u": 64610728118, "b": [["83864.70000000", "1.70630000"], ["83864.65000000", "0.00007000"], ["83864.64000000", "0.00007000"], ["83864.49000000", "0.00015000"], ["83864.43000000", "0.00000000"], ["83864.36000000", "0.00000000"], ["83864.35000000", "0.00000000"], ["83864.33000000", "0.00000000"], ["83864.32000000", "0.00000000"], ["83864.08000000", "0.00000000"], ["83864.07000000", "0.00000000"], ["83863.86000000", "0.00014000"], ["83863.85000000", "0.36650000"], ["83863.84000000", "0.78749000"], ["83863.45000000", "0.05579000"], ["83863.03000000", "0.00276000"], ["83862.91000000", "0.14473000"], ["83862.65000000", "0.00760000"], ["83862.63000000", "0.00000000"], ["83862.43000000", "0.20510000"], ["83862.00000000", "0.02820000"], ["83861.80000000", "0.00000000"], ["83861.63000000", "0.00012000"], ["83860.47000000", "0.02218000"], ["83860.08000000", "0.00000000"], ["83859.83000000", "0.05975000"], ["83859.10000000", "0.00000000"], ["83858.49000000", "0.05644000"], ["83858.05000000", "0.00000000"], ["83858.00000000", "0.02820000"], ["83856.33000000", "0.00000000"], ["83856.32000000", "0.00000000"], ["83856.31000000", "0.00000000"], ["83855.14000000", "0.00119000"], ["83852.98000000", "0.00095000"], ["83852.64000000", "0.00000000"], ["83852.05000000", "0.00006000"], ["83851.90000000", "0.00091000"], ["83851.80000000", "0.00000000"], ["83850.96000000", "0.00421000"], ["83850.22000000", "0.43385000"], ["83849.66000000", "0.00012000"], ["83849.16000000", "0.00000000"], ["83847.02000000", "0.00006000"], ["83846.71000000", "0.00000000"], ["83846.24000000", "0.00000000"], ["83845.18000000", "0.05897000"], ["83844.65000000", "0.30878000"], ["83844.31000000", "0.00000000"], ["83843.25000000", "0.00000000"], ["83843.21000000", "0.00000000"], ["83843.15000000", "0.03578000"], ["83842.84000000", "0.00000000"], ["83842.82000000", "0.00000000"], ["83841.49000000", "1.13920000"], ["83841.30000000", "0.35802000"], ["83839.69000000", "0.00000000"], ["83839.68000000", "0.00000000"], ["83839.03000000", "1.32360000"], ["83838.95000000", "0.00000000"], ["83838.77000000", "0.00000000"], ["83835.83000000", "0.00000000"], ["83835.82000000", "0.00000000"], ["83835.56000000", "0.00898000"], ["83835.38000000", "0.89506000"], ["83835.18000000", "0.00000000"], ["83832.84000000", "0.85926000"], ["83830.42000000", "0.59650000"], ["83828.56000000", "0.00000000"], ["83826.00000000", "0.89506000"], ["83824.35000000", "0.17931000"], ["83822.87000000", "0.89506000"], ["83822.29000000", "0.00000000"], ["83818.08000000", "0.00000000"], ["83817.78000000", "0.00000000"], ["83817.10000000", "0.00000000"], ["83815.84000000", "0.11928000"], ["83814.18000000", "0.00000000"], ["83811.10000000", "0.35802000"], ["83808.98000000", "0.00000000"], ["83808.21000000", "0.03896000"], ["83804.24000000", "0.03687000"], ["83786.21000000", "0.00296000"], ["83783.57000000", "0.00000000"], ["83777.24000000", "0.00298000"], ["83776.61000000", "0.00100000"], ["83774.04000000", "0.00000000"], ["83771.35000000", "0.00000000"], ["83765.60000000", "0.00000000"], ["83750.36000000", "0.00000000"], ["83750.35000000", "0.00000000"], ["83719.11000000", "0.00000000"], ["83711.07000000", "0.00000000"], ["83703.05000000", "0.00119000"], ["83702.19000000", "0.00000000"], ["83702.09000000", "0.00000000"], ["83700.99000000", "0.01000000"], ["83699.71000000", "0.00000000"], ["83698.64000000", "0.00000000"], ["83693.34000000", "0.00119000"], ["83690.01000000", "0.00000000"], ["83673.73000000", "0.00000000"], ["83673.72000000", "0.00000000"], ["83671.56000000", "0.00400000"], ["83551.39000000", "0.00006000"], ["83538.94000000", "0.00006000"], ["82874.99000000", "0.00000000"], ["82832.49000000", "0.00000000"], ["82606.72000000", "0.00000000"], ["80488.80000000", "0.00164000"], ["76700.00000000", "8.06876000"], ["75478.00000000", "0.00000000"], ["75477.00000000", "0.00120000"], ["67091.76000000", "0.00058000"], ["33000.00000000", "2.93827000"], ["30191.29000000", "0.00400000"]], "a": [["83864.71000000", "4.32407000"], ["83864.72000000", "0.24784000"], ["83864.73000000", "0.35035000"], ["83864.75000000", "0.00007000"], ["83864.76000000", "0.00007000"], ["83864.79000000", "0.00007000"], ["83864.80000000", "0.00000000"], ["83864.81000000", "0.00008000"], ["83864.86000000", "0.00000000"], ["83865.08000000", "0.00000000"], ["83865.09000000", "0.01273000"], ["83865.19000000", "0.00000000"], ["83865.20000000", "0.16243000"], ["83865.59000000", "0.01230000"], ["83866.14000000", "0.00000000"], ["83866.15000000", "0.00000000"], ["83866.38000000", "0.00000000"], ["83866.45000000", "0.22452000"], ["83868.00000000", "0.03055000"], ["83868.01000000", "0.26577000"], ["83868.24000000", "0.00000000"], ["83868.90000000", "0.00500000"], ["83869.17000000", "0.78731000"], ["83869.23000000", "0.00012000"], ["83869.58000000", "0.01260000"], ["83871.34000000", "0.00000000"], ["83871.41000000", "0.01192000"], ["83871.71000000", "0.00000000"], ["83871.74000000", "0.00000000"], ["83871.75000000", "0.62705000"], ["83872.04000000", "0.05975000"], ["83872.47000000", "0.00000000"], ["83872.64000000", "0.08338000"], ["83873.05000000", "0.00000000"], ["83873.10000000", "0.45000000"], ["83873.14000000", "0.28679000"], ["83874.02000000", "0.00000000"], ["83874.67000000", "0.00000000"], ["83874.68000000", "0.00000000"], ["83874.83000000", "0.00012000"], ["83874.88000000", "0.00000000"], ["83874.94000000", "0.00000000"], ["83875.23000000", "0.00000000"], ["83875.70000000", "0.02185000"], ["83875.82000000", "0.00000000"], ["83875.85000000", "0.00000000"], ["83877.13000000", "0.08992000"], ["83877.28000000", "0.01192000"], ["83879.75000000", "0.69127000"], ["83880.83000000", "0.00000000"], ["83881.13000000", "0.00000000"], ["83881.29000000", "0.48666000"], ["83881.98000000", "0.89506000"], ["83883.22000000", "0.00000000"], ["83884.38000000", "0.71594000"], ["83884.39000000", "0.88666000"], ["83886.04000000", "1.36939000"], ["83889.85000000", "0.00000000"], ["83890.18000000", "0.02131000"], ["83890.32000000", "0.08992000"], ["83891.30000000", "0.85866000"], ["83891.66000000", "0.00000000"], ["83891.93000000", "0.00000000"], ["83893.59000000", "0.89506000"], ["83894.06000000", "0.59650000"], ["83897.79000000", "0.00000000"], ["83898.78000000", "0.04654000"], ["83899.91000000", "0.04835000"], ["83900.88000000", "0.76388000"], ["83901.42000000", "0.00000000"], ["83902.36000000", "0.00000000"], ["83903.45000000", "0.00000000"], ["83903.68000000", "0.00590000"], ["83905.55000000", "0.00000000"], ["83906.10000000", "0.00000000"], ["83907.65000000", "0.00000000"], ["83911.44000000", "0.00014000"], ["83911.49000000", "0.35802000"], ["83913.63000000", "0.00000000"], ["83914.05000000", "0.00000000"], ["83915.72000000", "0.00000000"], ["83916.20000000", "0.00000000"], ["83916.47000000", "0.00000000"], ["83924.75000000", "0.47736000"], ["83953.26000000", "0.01952000"], ["83953.81000000", "0.00100000"], ["83978.39000000", "0.61899000"], ["84032.96000000", "0.01000000"], ["85122.69000000", "0.00000000"], ["92222.00000000", "1.29027000"]], "record_time": 1742561260.039411, "EXCHANGE": "BINANCE"}
{"e": "depthUpdate", "E": 1742561261014, "s": "BTCUSDT", "U": 64610728119, "u": 64610728273, "b": [["83864.70000000", "2.00113000"], ["83863.88000000", "0.00007000"], ["83863.87000000", "0.93773000"], ["83863.86000000", "0.00007000"], ["83863.85000000", "0.36643000"], ["83863.45000000", "0.05579000"], ["83862.91000000", "0.00000000"], ["83862.43000000", "0.20510000"], ["83862.00000000", "0.02820000"], ["83859.10000000", "0.00500000"], ["83858.49000000", "0.05644000"], ["83857.08000000", "0.00006000"], ["83856.31000000", "0.45000000"], ["83848.13000000", "0.05863000"], ["83845.18000000", "0.00000000"], ["83844.65000000", "0.00000000"], ["83812.08000000", "0.05000000"], ["83765.60000000", "0.63132000"], ["83750.37000000", "0.00091000"], ["83700.99000000", "0.00000000"], ["83698.99000000", "0.00000000"], ["83698.69000000", "0.01000000"], ["83678.13000000", "0.00400000"], ["83673.74000000", "0.00076000"], ["83671.56000000", "0.00000000"], ["83364.88000000", "0.00006000"], ["83352.46000000", "0.00006000"], ["82606.72000000", "0.00100000"], ["82504.55000000", "0.00138000"], ["80481.52000000", "0.00000000"], ["75478.00000000", "0.00000000"], ["75477.00000000", "0.00120000"], ["67091.76000000", "0.00058000"], ["33000.00000000", "2.93827000"], ["20002.00000000", "0.00000000"], ["20001.00000000", "0.02099000"]], "a": [["83864.71000000", "4.14139000"], ["83868.25000000", "0.00012000"], ["83869.23000000", "0.00000000"], ["83869.37000000", "0.00000000"], ["83870.05000000", "0.05975000"], ["83871.41000000", "0.01192000"], ["83872.04000000", "0.00000000"], ["83874.83000000", "0.00012000"], ["83876.47000000", "0.00058000"], ["83890.18000000", "0.95781000"], ["83890.65000000", "0.01024000"], ["83899.52000000", "0.00000000"], ["83901.06000000", "0.00759000"], ["83901.12000000", "0.00000000"], ["83908.08000000", "0.00000000"], ["83913.59000000", "0.05754000"], ["83915.79000000", "0.42542000"], ["83930.94000000", "0.02386000"], ["83943.86000000", "0.00000000"], ["83947.27000000", "0.00000000"], ["83947.48000000", "0.00041000"], ["83947.49000000", "0.00000000"], ["83951.18000000", "0.00844000"], ["83952.96000000", "0.00000000"], ["83953.04000000", "0.00000000"], ["83953.21000000", "0.00000000"], ["83953.26000000", "0.00084000"], ["83960.18000000", "0.06517000"], ["83960.26000000", "0.07448000"], ["83993.78000000", "0.18369000"], ["83999.72000000", "0.00000000"], ["84000.00000000", "0.50753000"], ["84031.97000000", "0.00035000"], ["84031.98000000", "0.00000000"], ["85122.69000000", "0.00100000"], ["85127.50000000", "0.05884000"]], "record_time": 1742561261.038614, "EXCHANGE": "BINANCE"}
{"e": "depthUpdate", "E": 1742561262014, "s": "BTCUSDT", "U": 64610728274, "u": 64610728487, "b": [["83864.70000000", "2.39513000"], ["83863.90000000", "0.00007000"], ["83863.89000000", "0.33015000"], ["83863.88000000", "0.00000000"], ["83863.87000000", "0.00000000"], ["83863.85000000", "0.00007000"], ["83863.45000000", "0.05579000"], ["83862.65000000", "0.00000000"], ["83862.43000000", "0.00000000"], ["83862.03000000", "0.02060000"], ["83862.00000000", "0.02826000"], ["83861.63000000", "0.00000000"], ["83861.40000000", "0.07867000"], ["83861.27000000", "0.00756000"], ["83860.47000000", "0.00000000"], ["83859.53000000", "0.00012000"], ["83858.49000000", "0.18440000"], ["83856.31000000", "0.45000000"], ["83850.22000000", "0.65494000"], ["83847.00000000", "0.85911000"], ["83842.62000000", "0.16111000"], ["83832.85000000", "1.31931000"], ["83832.84000000", "0.00000000"], ["83832.03000000", "0.00000000"], ["83817.08000000", "0.00000000"], ["83815.98000000", "0.00000000"], ["83814.42000000", "0.00081000"], ["83812.08000000", "0.00000000"], ["83772.54000000", "0.00000000"], ["83698.99000000", "0.01000000"], ["83698.69000000", "0.00000000"], ["83686.60000000", "0.00400000"], ["83678.13000000", "0.00000000"], ["83590.23000000", "0.00008000"], ["83255.52000000", "0.00000000"], ["83026.05000000", "0.00000000"], ["82832.49000000", "0.02353000"], ["82606.72000000", "0.00000000"], ["75539.01000000", "0.00000000"], ["75538.50000000", "0.00000000"], ["75478.23000000", "0.00048000"], ["75478.00000000", "0.00000000"], ["75477.00000000", "0.00120000"], ["67091.76000000", "0.00058000"], ["33000.00000000", "2.93827000"], ["30191.29000000", "0.00440000"]], "a": [["83864.71000000", "4.13616000"], ["83868.90000000", "0.00500000"], ["83869.17000000", "0.00000000"], ["83869.19000000", "0.78731000"], ["83871.12000000", "0.00000000"], ["83871.41000000", "0.01192000"], ["83875.69000000", "0.01748000"], ["83877.13000000", "0.00000000"], ["83884.38000000", "0.00000000"], ["83892.16000000", "0.00000000"], ["83894.06000000", "0.00000000"], ["83897.90000000", "0.59649000"], ["83899.01000000", "0.00755000"], ["83899.91000000", "0.00000000"], ["83901.06000000", "0.00000000"], ["83912.49000000", "0.04835000"], ["83928.38000000", "0.03038000"], ["83929.57000000", "0.00495000"], ["83936.54000000", "0.01620000"], ["83947.31000000", "0.00041000"], ["83947.48000000", "0.00000000"], ["83960.18000000", "0.00000000"], ["83960.26000000", "0.00000000"], ["83963.18000000", "0.00000000"], ["83963.61000000", "0.00000000"], ["83967.40000000", "0.06328000"], ["83967.82000000", "0.03724000"], ["84010.30000000", "0.00000000"], ["84017.53000000", "0.00000000"], ["84019.15000000", "0.00000000"], ["84031.96000000", "0.00035000"], ["84031.97000000", "0.00000000"], ["85106.25000000", "0.00000000"], ["85106.73000000", "0.00000000"], ["85122.69000000", "0.00000000"], ["87000.00000000", "35.61342000"]], "record_time": 1742561262.038171, "EXCHANGE": "BINANCE"}
{"e": "depthUpdate", "E": 1742561263014, "s": "BTCUSDT", "U": 64610728488, "u": 64610728744, "b": [["83864.70000000", "2.38106000"], ["83863.84000000", "0.78749000"], ["83863.45000000", "0.00000000"], ["83863.38000000", "0.00000000"], ["83862.03000000", "0.04433000"], ["83862.00000000", "0.02833000"], ["83860.90000000", "0.01846000"], ["83860.82000000", "0.00012000"], ["83860.01000000", "0.00006000"], ["83859.53000000", "0.00000000"], ["83859.10000000", "0.00000000"], ["83858.49000000", "0.05644000"], ["83857.67000000", "0.00000000"], ["83856.31000000", "0.00000000"], ["83855.01000000", "0.00000000"], ["83850.22000000", "0.43385000"], ["83849.66000000", "0.00012000"], ["83847.00000000", "0.00000000"], ["83843.15000000", "0.00000000"], ["83843.10000000", "0.03578000"], ["83841.49000000", "0.67185000"], ["83840.94000000", "1.38253000"], ["83839.03000000", "0.00000000"], ["83833.16000000", "0.85926000"], ["83824.36000000", "0.33754000"], ["83821.08000000", "0.05000000"], ["83797.23000000", "0.00000000"], ["83796.59000000", "0.00298000"], ["83796.49000000", "0.00000000"], ["83794.00000000", "0.01729000"], ["83788.20000000", "0.00597000"], ["83788.10000000", "0.00000000"], ["83779.82000000", "0.00895000"], ["83779.72000000", "0.00000000"], ["83771.44000000", "0.01194000"], ["83771.34000000", "0.00000000"], ["83763.06000000", "0.01493000"], ["83762.96000000", "0.00000000"], ["83733.96000000", "0.00011000"], ["83708.32000000", "0.00000000"], ["83699.69000000", "0.01000000"], ["83698.99000000", "0.00000000"], ["83686.60000000", "0.00000000"], ["83679.62000000", "0.00764000"], ["83660.50000000", "0.00000000"], ["83600.00000000", "2.63943000"], ["82919.58000000", "0.00000000"], ["82911.23000000", "0.40000000"], ["82677.19000000", "0.00030000"], ["82606.72000000", "0.00100000"], ["82188.88000000", "0.00372000"], ["80481.52000000", "0.03576000"], ["79600.00000000", "1.06505000"], ["75478.00000000", "0.00000000"], ["75477.00000000", "0.00120000"], ["67091.76000000", "0.00058000"], ["42000.00000000", "6.85161000"], ["33000.00000000", "2.93827000"], ["30191.29000000", "0.00460000"]], "a": [["83864.71000000", "4.13616000"], ["83864.73000000", "0.35035000"], ["83864.87000000", "0.00000000"], ["83865.09000000", "0.00000000"], ["83865.20000000", "0.16250000"], ["83865.59000000", "0.00000000"], ["83866.00000000", "0.02827000"], ["83867.38000000", "0.28831000"], ["83867.39000000", "0.78733000"], ["83867.73000000", "0.00000000"], ["83868.01000000", "0.00000000"], ["83868.90000000", "0.01000000"], ["83869.19000000", "0.00000000"], ["83869.41000000", "0.00000000"], ["83869.58000000", "0.00000000"], ["83870.15000000", "0.00000000"], ["83872.11000000", "0.23860000"], ["83872.65000000", "0.00000000"], ["83874.25000000", "0.00000000"], ["83874.35000000", "0.00000000"], ["83874.51000000", "0.00000000"], ["83876.54000000", "0.00000000"], ["83876.85000000", "0.00000000"], ["83877.63000000", "0.00000000"], ["83880.94000000", "0.00000000"], ["83881.84000000", "0.00000000"], ["83884.39000000", "0.54638000"], ["83885.55000000", "0.00000000"], ["83886.04000000", "0.00000000"], ["83886.79000000", "0.00000000"], ["83886.98000000", "0.00000000"], ["83889.36000000", "0.00000000"], ["83889.38000000", "1.37106000"], ["83890.23000000", "0.45000000"], ["83890.64000000", "0.00000000"], ["83891.45000000", "0.00000000"], ["83892.02000000", "0.00000000"], ["83893.28000000", "0.00000000"], ["83894.87000000", "0.00000000"], ["83897.91000000", "0.00000000"], ["83898.13000000", "0.00000000"], ["83899.00000000", "0.00000000"], ["83902.08000000", "0.00000000"], ["83903.64000000", "0.00000000"], ["83903.67000000", "0.00000000"], ["83905.93000000", "0.00000000"], ["83906.93000000", "0.00000000"], ["83907.00000000", "0.00000000"], ["83910.10000000", "0.00000000"], ["83910.17000000", "0.00000000"], ["83911.29000000", "0.00000000"], ["83914.41000000", "0.00000000"], ["83914.46000000", "0.00000000"], ["83915.57000000", "0.00000000"], ["83918.71000000", "0.00000000"], ["83919.11000000", "0.00000000"], ["83919.88000000", "0.00000000"], ["83922.90000000", "0.00000000"], ["83924.31000000", "0.00000000"], ["83924.54000000", "0.00000000"], ["83927.81000000", "0.00000000"], ["83927.83000000", "0.00000000"], ["83930.94000000", "0.00000000"], ["83931.79000000", "0.00000000"], ["83931.97000000", "0.00000000"], ["83932.95000000", "0.00000000"], ["83936.64000000", "0.00000000"], ["83936.82000000", "0.00000000"], ["83936.95000000", "0.00000000"], ["83939.03000000", "0.00000000"], ["83939.53000000", "0.00298000"], ["83940.09000000", "0.00000000"], ["83940.65000000", "0.00000000"], ["83941.27000000", "0.00000000"], ["83943.88000000", "0.00000000"], ["83944.16000000", "0.00000000"], ["83944.82000000", "0.00000000"], ["83947.40000000", "0.02386000"], ["83949.42000000", "0.00000000"], ["83949.45000000", "0.00000000"], ["83949.47000000", "0.00000000"], ["83949.86000000", "0.02131000"], ["83950.36000000", "0.00597000"], ["83952.06000000", "0.00000000"], ["83952.65000000", "0.04651000"], ["83953.03000000", "0.00000000"], ["83956.73000000", "0.00000000"], ["83956.91000000", "0.00000000"], ["83958.02000000", "0.00000000"], ["83960.55000000", "0.00000000"], ["83961.44000000", "0.00000000"], ["83961.86000000", "0.00000000"], ["83962.14000000", "0.08153000"], ["83962.79000000", "0.00000000"], ["83964.40000000", "0.00895000"], ["83964.51000000", "0.00000000"], ["83964.65000000", "0.46586000"], ["83964.86000000", "0.00000000"], ["83965.56000000", "0.00000000"], ["83965.82000000", "0.05498000"], ["83969.41000000", "0.00000000"], ["83970.01000000", "0.00519000"], ["83970.85000000", "0.00000000"], ["83972.80000000", "0.01194000"], ["83973.01000000", "0.00000000"], ["83973.38000000", "0.00000000"], ["83974.59000000", "0.00000000"], ["83975.05000000", "0.00000000"], ["83975.28000000", "0.05397000"], ["83977.31000000", "0.00000000"], ["83977.79000000", "0.00000000"], ["83979.02000000", "0.00000000"], ["83981.28000000", "0.01493000"], ["83982.73000000", "0.00000000"], ["83982.76000000", "0.00000000"], ["83983.08000000", "0.00000000"], ["83983.34000000", "0.00000000"], ["83985.77000000", "0.00000000"], ["83986.54000000", "0.00000000"], ["83987.10000000", "0.00000000"], ["83990.30000000", "0.00000000"], ["83991.11000000", "0.00000000"], ["83994.26000000", "0.00000000"], ["83994.50000000", "0.00000000"], ["83994.75000000", "0.00000000"], ["83997.70000000", "0.00000000"], ["83999.43000000", "0.00000000"], ["83999.47000000", "0.00000000"], ["83999.61000000", "0.00000000"], ["84001.00000000", "0.00006000"], ["84001.01000000", "0.07952000"], ["84002.84000000", "0.00000000"], ["84003.13000000", "0.05297000"], ["84003.15000000", "0.00000000"], ["84007.33000000", "0.00000000"], ["84008.63000000", "0.00000000"], ["84008.69000000", "0.00000000"], ["84011.71000000", "0.00000000"], ["84011.81000000", "0.00000000"], ["84011.82000000", "0.00000000"], ["84016.34000000", "0.00000000"], ["84016.88000000", "0.00000000"], ["84017.04000000", "0.00000000"], ["84951.01000000", "0.60000000"], ["84959.43000000", "0.00000000"], ["85038.82000000", "0.04748000"], ["85122.69000000", "0.00100000"]], "record_time": 1742561263.038291, "EXCHANGE": "BINANCE"}
{"e": "depthUpdate", "E": 1742561264014, "s": "BTCUSDT", "U": 64610728745, "u": 64610728894, "b": [["83864.70000000", "1.86333000"], ["83863.03000000", "0.00084000"], ["83861.40000000", "0.07867000"], ["83858.49000000", "0.05644000"], ["83858.00000000", "0.03012000"], ["83856.31000000", "0.00000000"], ["83841.49000000", "0.98891000"], ["83839.34000000", "0.10256000"], ["83829.04000000", "0.00000000"], ["83750.37000000", "0.00000000"], ["83680.00000000", "0.09921000"], ["83679.62000000", "0.00364000"], ["83673.74000000", "0.00000000"], ["83672.18000000", "0.00400000"], ["83252.49000000", "0.00079000"], ["83226.40000000", "0.00000000"], ["82606.72000000", "0.00000000"], ["75478.00000000", "0.00000000"], ["75477.00000000", "0.00120000"], ["67091.76000000", "0.00058000"], ["33000.00000000", "2.93827000"]], "a": [["83864.71000000", "4.13592000"], ["83866.38000000", "0.00000000"], ["83868.90000000", "0.01000000"], ["83881.29000000", "0.35802000"], ["83900.85000000", "0.00000000"], ["83929.40000000", "0.08383000"], ["83944.38000000", "0.00844000"], ["83947.31000000", "0.00000000"], ["83951.18000000", "0.00000000"], ["83955.04000000", "1.34056000"], ["83967.40000000", "0.05397000"], ["83967.82000000", "0.00000000"], ["84031.96000000", "0.00000000"], ["85122.69000000", "0.00000000"], ["85127.50000000", "0.05884000"]], "record_time": 1742561264.038366, "EXCHANGE": "BINANCE"}
{"e": "depthUpdate", "E": 1742561265014, "s": "BTCUSDT", "U": 64610728895, "u": 64610729037, "b": [["83864.70000000", "1.86350000"], ["83863.93000000", "0.00007000"], ["83863.92000000", "0.66131000"], ["83863.91000000", "0.93813000"], ["83863.90000000", "0.00000000"], ["83863.89000000", "0.00000000"], ["83863.88000000", "0.00000000"], ["83863.87000000", "0.16573000"], ["83863.86000000", "0.00000000"], ["83863.85000000", "0.00000000"], ["83863.84000000", "0.78749000"], ["83863.03000000", "0.00000000"], ["83862.61000000", "0.02279000"], ["83862.03000000", "0.04426000"], ["83862.00000000", "0.02826000"], ["83861.90000000", "0.00000000"], ["83858.49000000", "0.05644000"], ["83858.05000000", "0.00012000"], ["83858.00000000", "0.02820000"], ["83856.31000000", "0.00000000"], ["83851.80000000", "0.00000000"], ["83850.22000000", "0.65494000"], ["83849.66000000", "0.00000000"], ["83847.41000000", "0.85911000"], ["83839.34000000", "0.00000000"], ["83838.05000000", "0.26108000"], ["83833.16000000", "0.00000000"], ["83821.08000000", "0.00000000"], ["83808.78000000", "0.00000000"], ["83742.45000000", "0.18368000"], ["83739.69000000", "0.00000000"], ["83699.69000000", "0.01000000"], ["83684.15000000", "0.00400000"], ["83677.74000000", "0.00000000"], ["83672.18000000", "0.00000000"], ["83590.23000000", "0.00000000"], ["82606.72000000", "0.00100000"], ["81570.68000000", "0.00043000"], ["75478.00000000", "0.00000000"], ["75477.00000000", "0.00120000"], ["67091.76000000", "0.00058000"], ["33000.00000000", "2.93827000"], ["30191.29000000", "0.00500000"]], "a": [["83864.71000000", "4.13279000"], ["83865.20000000", "0.16250000"], ["83865.30000000", "0.00000000"], ["83866.00000000", "0.02827000"], ["83867.39000000", "0.00000000"], ["83868.18000000", "0.00000000"], ["83868.90000000", "0.00500000"], ["83869.18000000", "0.78731000"], ["83869.34000000", "0.02225000"], ["83872.13000000", "0.02415000"], ["83879.01000000", "0.12799000"], ["83890.76000000", "0.00000000"], ["83891.83000000", "0.00000000"], ["83955.04000000", "0.00000000"], ["83969.11000000", "0.38695000"], ["84032.96000000", "0.01000000"], ["85122.69000000", "0.00100000"]], "record_time": 1742561265.040104, "EXCHANGE": "BINANCE"}
{"e": "depthUpdate", "E": 1742561266014, "s": "BTCUSDT", "U": 64610729038, "u": 64610729149, "b": [["83864.70000000", "1.86303000"], ["83863.92000000", "0.37980000"], ["83863.91000000", "0.00000000"], ["83863.85000000", "0.00007000"], ["83863.84000000", "0.78749000"], ["83862.61000000", "0.00000000"], ["83862.03000000", "0.04433000"], ["83861.80000000", "0.00000000"], ["83861.40000000", "0.07873000"], ["83851.80000000", "0.00000000"], ["83841.50000000", "1.14615000"], ["83841.49000000", "1.36565000"], ["83840.94000000", "0.00000000"], ["83839.34000000", "0.13986000"], ["83838.05000000", "0.00000000"], ["83821.68000000", "0.00000000"], ["83808.78000000", "0.00000000"], ["83760.48000000", "0.14597000"], ["83758.11000000", "0.37641000"], ["83716.20000000", "0.09429000"], ["83700.00000000", "0.18874000"], ["83684.15000000", "0.00000000"], ["83678.19000000", "0.00000000"], ["83673.00000000", "0.00400000"], ["83076.15000000", "0.00060000"], ["83075.53000000", "0.00000000"], ["83056.83000000", "0.00060000"], ["83056.21000000", "0.00000000"], ["82606.72000000", "0.00000000"], ["75478.00000000", "0.00000000"], ["75477.00000000", "0.00120000"], ["71888.00000000", "10.00506000"], ["67091.76000000", "0.00058000"], ["60000.00000000", "73.06385000"], ["33000.00000000", "2.93827000"], ["30191.29000000", "0.00520000"], ["20002.00000000", "0.00000000"], ["20001.00000000", "0.02099000"]], "a": [["83864.71000000", "4.13815000"], ["83867.46000000", "0.78733000"], ["83868.90000000", "0.00500000"], ["83869.18000000", "0.00000000"], ["83879.01000000", "0.00000000"], ["83879.04000000", "0.12776000"], ["83889.37000000", "1.35576000"], ["83889.38000000", "0.00000000"], ["83889.79000000", "0.05000000"], ["83891.26000000", "0.00000000"], ["83906.10000000", "0.00000000"], ["83916.20000000", "0.00000000"], ["83929.87000000", "0.02386000"], ["83944.50000000", "0.04316000"], ["83947.40000000", "0.00000000"], ["83951.27000000", "0.74972000"], ["83952.21000000", "1.46883000"], ["85106.25000000", "0.11766000"], ["85122.69000000", "0.00000000"], ["85755.19000000", "0.00000000"]], "record_time": 1742561266.039104, "EXCHANGE": "BINANCE"}
{"e": "depthUpdate", "E": 1742561267014, "s": "BTCUSDT", "U": 64610729150, "u": 64610729298, "b": [["83864.70000000", "1.38230000"], ["83863.92000000", "0.37980000"], ["83863.87000000", "0.00000000"], ["83863.86000000", "0.00007000"], ["83863.84000000", "0.78749000"], ["83863.19000000", "0.14976000"], ["83863.01000000", "0.00000000"], ["83862.94000000", "0.00012000"], ["83862.61000000", "0.00000000"], ["83862.27000000", "0.02287000"], ["83862.03000000", "0.00000000"], ["83862.00000000", "0.02826000"], ["83861.40000000", "0.07867000"], ["83861.16000000", "0.34971000"], ["83860.90000000", "0.04754000"], ["83860.82000000", "0.00000000"], ["83860.19000000", "0.00000000"], ["83859.81000000", "0.02218000"], ["83858.49000000", "0.04204000"], ["83856.31000000", "0.00000000"], ["83855.72000000", "0.02408000"], ["83847.41000000", "0.00000000"], ["83847.00000000", "0.85911000"], ["83839.34000000", "0.13986000"], ["83833.98000000", "0.00000000"], ["83824.75000000", "0.00000000"], ["83818.68000000", "0.00000000"], ["83702.79000000", "0.00000000"], ["83702.67000000", "0.00000000"], ["83702.39000000", "0.01000000"], ["83701.49000000", "0.00000000"], ["83701.09000000", "0.00000000"], ["83699.69000000", "0.00000000"], ["82606.72000000", "0.00100000"], ["81000.00000000", "53.23998000"], ["80500.00000000", "17.85249000"], ["80000.00000000", "155.35468000"], ["75478.00000000", "0.00000000"], ["75477.00000000", "0.00120000"], ["67091.76000000", "0.00058000"], ["33000.00000000", "2.93827000"]], "a": [["83864.71000000", "4.13666000"], ["83868.25000000", "0.00000000"], ["83868.90000000", "0.01000000"], ["83870.37000000", "0.00012000"], ["83879.04000000", "0.00000000"], ["83879.44000000", "0.12764000"], ["83887.30000000", "0.71594000"], ["83887.31000000", "0.85870000"], ["83889.79000000", "0.00000000"], ["83900.72000000", "0.00000000"], ["83900.88000000", "0.33563000"], ["83901.46000000", "0.00000000"], ["83950.00000000", "0.01252000"], ["83951.27000000", "0.41274000"], ["83952.21000000", "0.12827000"], ["84703.34000000", "0.00000000"], ["85122.69000000", "0.00100000"], ["87504.65000000", "0.00000000"]], "record_time": 1742561267.038608, "EXCHANGE": "BINANCE"}
{"e": "depthUpdate", "E": 1742561268014, "s": "BTCUSDT", "U": 64610729299, "u": 64610734032, "b": [["83864.70000000", "0.00000000"], ["83864.69000000", "0.00000000"], ["83864.68000000", "0.00000000"], ["83864.65000000", "0.00000000"], ["83864.64000000", "0.00000000"], ["83864.57000000", "0.00000000"], ["83864.56000000", "0.00000000"], ["83864.49000000", "0.00000000"], ["83864.34000000", "0.00000000"], ["83863.93000000", "0.00000000"], ["83863.92000000", "0.00000000"], ["83863.86000000", "0.00000000"], ["83863.85000000", "0.00000000"], ["83863.84000000", "0.00000000"], ["83863.19000000", "0.00000000"], ["83863.01000000", "0.00000000"], ["83862.94000000", "0.00000000"], ["83862.27000000", "0.00000000"], ["83862.18000000", "0.00000000"], ["83862.17000000", "0.00000000"], ["83862.00000000", "0.00000000"], ["83861.41000000", "0.00000000"], ["83861.40000000", "0.00000000"], ["83861.33000000", "0.00000000"], ["83861.27000000", "0.00000000"], ["83861.16000000", "0.00000000"], ["83860.97000000", "0.00000000"], ["83860.96000000", "0.00000000"], ["83860.91000000", "0.00000000"], ["83860.90000000", "0.00000000"], ["83860.48000000", "0.00000000"], ["83860.01000000", "0.00000000"], ["83860.00000000", "0.00000000"], ["83859.99000000", "0.00000000"], ["83859.84000000", "0.00000000"], ["83859.83000000", "0.00000000"], ["83859.82000000", "0.00000000"], ["83859.81000000", "0.00000000"], ["83859.64000000", "0.00000000"], ["83859.49000000", "0.00000000"], ["83858.63000000", "0.00000000"], ["83858.62000000", "0.00000000"], ["83858.60000000", "0.00000000"], ["83858.50000000", "0.00000000"], ["83858.49000000", "0.00000000"], ["83858.48000000", "0.00000000"], ["83858.28000000", "0.00000000"], ["83858.05000000", "0.00000000"], ["83858.00000000", "0.00000000"], ["83857.95000000", "0.00000000"], ["83857.66000000", "0.00000000"], ["83857.65000000", "0.00000000"], ["83857.64000000", "0.00000000"], ["83857.20000000", "0.00000000"], ["83857.08000000", "0.00000000"], ["83856.77000000", "0.00000000"], ["83856.76000000", "0.00000000"], ["83856.48000000", "0.00000000"], ["83856.41000000", "0.00000000"], ["83856.40000000", "0.00000000"], ["83856.29000000", "0.00000000"], ["83856.00000000", "0.00000000"], ["83855.99000000", "0.00000000"], ["83855.72000000", "0.00000000"], ["83855.14000000", "0.00000000"], ["83855.00000000", "0.00000000"], ["83854.60000000", "0.00000000"], ["83854.58000000", "0.00000000"], ["83854.22000000", "0.00000000"], ["83854.18000000", "0.00000000"], ["83854.15000000", "0.00000000"], ["83854.14000000", "0.00000000"], ["83854.13000000", "0.00000000"], ["83854.01000000", "0.00000000"], ["83854.00000000", "0.00000000"], ["83853.99000000", "0.00000000"], ["83853.94000000", "0.00000000"], ["83853.89000000", "0.00000000"], ["83853.77000000", "0.00000000"], ["83853.76000000", "0.00000000"], ["83853.73000000", "0.00000000"], ["83853.63000000", "0.00000000"], ["83853.40000000", "0.00000000"], ["83853.21000000", "0.00000000"], ["83853.09000000", "0.00000000"], ["83853.01000000", "0.00000000"], ["83853.00000000", "0.00000000"], ["83852.98000000", "0.00000000"], ["83852.94000000", "0.00000000"], ["83852.93000000", "0.00000000"], ["83852.92000000", "0.00000000"], ["83852.89000000", "0.00000000"], ["83852.71000000", "0.00000000"], ["83852.63000000", "0.00000000"], ["83852.59000000", "0.00000000"], ["83852.40000000", "0.00000000"], ["83852.39000000", "0.00000000"], ["83852.24000000", "0.00000000"], ["83852.21000000", "0.00000000"], ["83852.11000000", "0.00000000"], ["83852.09000000", "0.00000000"], ["83852.05000000", "0.00000000"], ["83852.04000000", "0.00000000"], ["83852.00000000", "0.00000000"], ["83851.90000000", "0.00000000"], ["83851.73000000", "0.00000000"], ["83851.59000000", "0.00000000"], ["83851.46000000", "0.00000000"], ["83851.38000000", "0.00000000"], ["83851.33000000", "0.00000000"], ["83851.31000000", "0.00000000"], ["83851.05000000", "0.00000000"], ["83850.96000000", "0.00000000"], ["83850.93000000", "0.00000000"], ["83850.91000000", "0.00000000"], ["83850.25000000", "0.00000000"], ["83850.24000000", "0.00000000"], ["83850.23000000", "0.00000000"], ["83850.22000000", "3.52429000"], ["83850.21000000", "0.00068000"], ["83850.18000000", "0.00007000"], ["83850.15000000", "0.00033000"], ["83850.14000000", "0.27192000"], ["83850.03000000", "0.05989000"], ["83850.00000000", "0.02834000"], ["83849.81000000", "0.00000000"], ["83849.70000000", "0.00014000"], ["83849.69000000", "0.43524000"], ["83849.68000000", "0.16302000"], ["83849.66000000", "0.00012000"], ["83849.58000000", "0.00000000"], ["83849.55000000", "0.00000000"], ["83849.35000000", "0.00000000"], ["83849.33000000", "0.00012000"], ["83849.30000000", "0.00000000"], ["83849.29000000", "0.00000000"], ["83849.21000000", "0.00000000"], ["83849.20000000", "0.78756000"], ["83849.14000000", "0.00000000"], ["83848.81000000", "0.00000000"], ["83848.80000000", "0.00506000"], ["83848.75000000", "0.00000000"], ["83848.67000000", "0.00007000"], ["83848.60000000", "0.00000000"], ["83848.41000000", "0.00000000"], ["83848.40000000", "0.00000000"], ["83848.38000000", "0.00000000"], ["83848.37000000", "0.00000000"], ["83848.20000000", "0.00000000"], ["83848.13000000", "0.00000000"], ["83848.04000000", "0.00000000"], ["83848.01000000", "0.00009000"], ["83848.00000000", "0.02826000"], ["83847.90000000", "0.00000000"], ["83847.83000000", "0.00031000"], ["83847.81000000", "0.00000000"], ["83847.71000000", "0.00000000"], ["83847.55000000", "0.00000000"], ["83847.54000000", "0.02385000"], ["83847.52000000", "0.00000000"], ["83847.30000000", "0.00000000"], ["83847.23000000", "0.00000000"], ["83847.22000000", "0.00000000"], ["83847.20000000", "0.00000000"], ["83847.09000000", "0.00000000"], ["83847.02000000", "0.00017000"], ["83847.01000000", "0.02445000"], ["83847.00000000", "0.00000000"], ["83846.81000000", "0.00000000"], ["83846.73000000", "0.00000000"], ["83846.67000000", "0.00000000"], ["83846.61000000", "0.00000000"], ["83846.60000000", "0.29679000"], ["83846.58000000", "0.00000000"], ["83846.54000000", "0.02396000"], ["83846.36000000", "0.00000000"], ["83846.31000000", "0.00000000"], ["83846.30000000", "0.00000000"], ["83846.27000000", "0.00000000"], ["83846.03000000", "0.00000000"], ["83846.00000000", "0.05205000"], ["83845.90000000", "0.08992000"], ["83845.89000000", "0.00000000"], ["83845.82000000", "0.00000000"], ["83845.76000000", "0.00282000"], ["83845.74000000", "0.00000000"], ["83845.61000000", "0.00000000"], ["83845.58000000", "0.00000000"], ["83845.25000000", "0.00000000"], ["83845.24000000", "0.28426000"], ["83845.20000000", "0.00000000"], ["83844.83000000", "0.00000000"], ["83844.78000000", "0.02385000"], ["83844.59000000", "0.00000000"], ["83844.53000000", "0.00000000"], ["83844.50000000", "0.00000000"], ["83844.48000000", "0.00000000"], ["83844.46000000", "0.00000000"], ["83844.41000000", "0.00000000"], ["83844.11000000", "0.00000000"], ["83843.99000000", "0.00000000"], ["83843.91000000", "0.00000000"], ["83843.88000000", "0.00000000"], ["83843.83000000", "0.00058000"], ["83843.75000000", "0.00000000"], ["83843.65000000", "0.04000000"], ["83843.59000000", "0.04000000"], ["83843.57000000", "0.00000000"], ["83843.53000000", "0.00000000"], ["83843.38000000", "0.00000000"], ["83843.31000000", "0.04000000"], ["83843.24000000", "0.00000000"], ["83843.10000000", "0.00000000"], ["83843.03000000", "0.00000000"], ["83843.00000000", "0.00000000"], ["83842.96000000", "0.02385000"], ["83842.93000000", "0.00500000"], ["83842.87000000", "0.00000000"], ["83842.86000000", "0.00000000"], ["83842.62000000", "0.00000000"], ["83842.51000000", "0.00500000"], ["83842.23000000", "0.01000000"], ["83842.07000000", "0.00000000"], ["83841.94000000", "0.71594000"], ["83841.93000000", "0.04000000"], ["83841.90000000", "0.00000000"], ["83841.86000000", "0.00059000"], ["83841.83000000", "0.00029000"], ["83841.81000000", "0.01000000"], ["83841.64000000", "0.04000000"], ["83841.58000000", "0.05963000"], ["83841.54000000", "0.04000000"], ["83841.50000000", "0.11796000"], ["83841.49000000", "0.00000000"], ["83841.30000000", "0.00000000"], ["83841.27000000", "0.00000000"], ["83841.16000000", "0.00059000"], ["83841.10000000", "0.00000000"], ["83840.60000000", "0.02981000"], ["83840.39000000", "0.00000000"], ["83840.03000000", "0.00000000"], ["83839.79000000", "0.04000000"], ["83839.75000000", "0.00000000"], ["83839.74000000", "0.00000000"], ["83839.54000000", "0.00000000"], ["83839.50000000", "0.00000000"], ["83839.49000000", "0.00000000"], ["83839.45000000", "0.04000000"], ["83839.41000000", "0.00000000"], ["83839.40000000", "0.04000000"], ["83839.34000000", "0.00000000"], ["83839.32000000", "0.00000000"], ["83839.14000000", "0.04000000"], ["83839.00000000", "0.00200000"], ["83838.75000000", "0.04000000"], ["83838.67000000", "0.05963000"], ["83838.65000000", "0.00000000"], ["83838.60000000", "0.00119000"], ["83838.51000000", "0.00000000"], ["83838.50000000", "0.91864000"], ["83838.48000000", "0.00000000"], ["83838.31000000", "0.05963000"], ["83838.16000000", "0.00000000"], ["83837.96000000", "0.00000000"], ["83837.75000000", "0.00000000"], ["83837.71000000", "0.02361000"], ["83837.70000000", "0.00000000"], ["83837.54000000", "0.00000000"], ["83837.25000000", "0.00000000"], ["83837.22000000", "0.00058000"], ["83837.17000000", "0.00000000"], ["83837.11000000", "0.00000000"], ["83836.99000000", "0.00000000"], ["83836.98000000", "0.00000000"], ["83836.88000000", "0.85222000"], ["83836.87000000", "0.71594000"], ["83836.86000000", "0.00000000"], ["83836.85000000", "0.00000000"], ["83836.78000000", "0.00000000"], ["83836.70000000", "0.04000000"], ["83836.60000000", "0.02000000"], ["83836.49000000", "0.00000000"], ["83836.48000000", "0.00000000"], ["83836.45000000", "0.00000000"], ["83836.41000000", "0.00000000"], ["83836.38000000", "0.00000000"], ["83836.30000000", "0.00000000"], ["83836.25000000", "0.00000000"], ["83836.01000000", "0.00007000"], ["83835.76000000", "0.01192000"], ["83835.62000000", "0.00892000"], ["83835.56000000", "0.00000000"], ["83835.54000000", "0.00000000"], ["83835.48000000", "0.00000000"], ["83835.40000000", "0.08000000"], ["83835.38000000", "0.00000000"], ["83835.37000000", "0.00000000"], ["83835.17000000", "0.00898000"], ["83835.10000000", "0.08338000"], ["83835.09000000", "1.32574000"], ["83835.02000000", "0.00000000"], ["83834.97000000", "0.00028000"], ["83834.71000000", "0.00000000"], ["83834.55000000", "0.00000000"], ["83834.29000000", "0.17918000"], ["83833.81000000", "0.00000000"], ["83833.46000000", "0.00000000"], ["83833.45000000", "0.68718000"], ["83833.44000000", "0.00000000"], ["83832.92000000", "0.12738000"], ["83832.88000000", "0.00000000"], ["83832.85000000", "0.00000000"], ["83832.73000000", "0.00000000"], ["83832.45000000", "0.00000000"], ["83832.02000000", "0.00000000"], ["83832.00000000", "0.00056000"], ["83831.89000000", "0.00000000"], ["83831.18000000", "0.00000000"], ["83831.07000000", "0.00000000"], ["83831.06000000", "0.00000000"], ["83830.96000000", "0.00000000"], ["83830.67000000", "0.00000000"], ["83830.42000000", "0.00000000"], ["83830.41000000", "0.00000000"], ["83830.28000000", "0.11452000"], ["83830.21000000", "0.85929000"], ["83830.17000000", "0.00000000"], ["83830.05000000", "0.02981000"], ["83829.85000000", "0.00000000"], ["83829.75000000", "0.00000000"], ["83829.69000000", "0.00007000"], ["83829.25000000", "0.00000000"], ["83829.22000000", "0.08992000"], ["83828.86000000", "0.59656000"], ["83828.85000000", "0.16000000"], ["83828.61000000", "0.00000000"], ["83828.55000000", "0.00000000"], ["83828.24000000", "0.84336000"], ["83828.11000000", "0.72008000"], ["83828.09000000", "0.00000000"], ["83827.98000000", "0.35802000"], ["83827.72000000", "0.00000000"], ["83827.70000000", "0.00238000"], ["83827.65000000", "0.00000000"], ["83827.41000000", "0.00000000"], ["83826.97000000", "0.00119000"], ["83826.87000000", "0.00000000"], ["83826.86000000", "0.00000000"], ["83826.78000000", "0.00000000"], ["83826.72000000", "0.00000000"], ["83826.55000000", "0.00000000"], ["83826.52000000", "0.00000000"], ["83826.15000000", "0.00000000"], ["83826.00000000", "0.00000000"], ["83825.89000000", "0.85933000"], ["83825.39000000", "0.00000000"], ["83825.07000000", "0.00059000"], ["83825.06000000", "0.05967000"], ["83823.92000000", "0.01192000"], ["83823.89000000", "0.11190000"], ["83822.88000000", "0.00000000"], ["83821.56000000", "0.59671000"], ["83821.47000000", "0.04000000"], ["83821.18000000", "0.00579000"], ["83821.01000000", "0.03896000"], ["83820.64000000", "0.04000000"], ["83820.57000000", "0.89506000"], ["83820.03000000", "0.00000000"], ["83819.81000000", "0.00355000"], ["83819.64000000", "0.89506000"], ["83819.50000000", "0.00000000"], ["83819.47000000", "0.00000000"], ["83819.46000000", "0.89506000"], ["83818.12000000", "0.04000000"], ["83818.10000000", "0.05963000"], ["83817.89000000", "0.00000000"], ["83817.28000000", "0.04000000"], ["83817.25000000", "0.00000000"], ["83816.81000000", "0.89506000"], ["83816.75000000", "0.89506000"], ["83816.74000000", "0.00000000"], ["83816.45000000", "0.04000000"], ["83816.44000000", "0.04013000"], ["83816.34000000", "0.04000000"], ["83815.74000000", "0.00000000"], ["83815.46000000", "0.03687000"], ["83815.45000000", "0.89506000"], ["83815.31000000", "0.00000000"], ["83814.50000000", "0.03437000"], ["83812.71000000", "0.00000000"], ["83812.60000000", "0.36598000"], ["83811.45000000", "0.00000000"], ["83811.31000000", "0.42660000"], ["83811.10000000", "0.00000000"], ["83810.78000000", "0.00000000"], ["83810.72000000", "0.00000000"], ["83809.89000000", "0.00000000"], ["83808.21000000", "0.00000000"], ["83808.10000000", "0.89506000"], ["83807.78000000", "0.04651000"], ["83807.41000000", "0.47736000"], ["83807.16000000", "0.00000000"], ["83804.38000000", "0.00000000"], ["83804.24000000", "0.00000000"], ["83803.30000000", "0.00000000"], ["83802.16000000", "0.00000000"], ["83802.02000000", "0.05963000"], ["83799.99000000", "0.00000000"], ["83798.88000000", "0.00000000"], ["83798.28000000", "0.13956000"], ["83798.13000000", "0.00000000"], ["83797.78000000", "0.35802000"], ["83797.62000000", "0.33409000"], ["83797.30000000", "0.00000000"], ["83797.29000000", "0.00000000"], ["83797.12000000", "0.09303000"], ["83795.70000000", "0.00000000"], ["83795.30000000", "0.00822000"], ["83795.12000000", "1.05903000"], ["83794.20000000", "0.16399000"], ["83793.67000000", "0.00000000"], ["83792.53000000", "0.10909000"], ["83792.10000000", "0.00818000"], ["83788.72000000", "0.05498000"], ["83787.81000000", "0.00000000"], ["83787.77000000", "0.00061000"], ["83786.40000000", "0.00864000"], ["83786.21000000", "0.00000000"], ["83784.32000000", "0.00817000"], ["83784.08000000", "0.00000000"], ["83783.81000000", "0.59671000"], ["83783.74000000", "0.00000000"], ["83783.58000000", "0.00000000"], ["83781.84000000", "0.05497000"], ["83781.76000000", "0.00000000"], ["83780.01000000", "0.00000000"], ["83779.92000000", "0.04000000"], ["83779.09000000", "0.00298000"], ["83779.07000000", "0.04000000"], ["83778.65000000", "0.10150000"], ["83778.24000000", "0.04000000"], ["83778.22000000", "0.09302000"], ["83778.13000000", "0.00000000"], ["83778.12000000", "0.09298000"], ["83777.86000000", "0.00000000"], ["83777.24000000", "0.00000000"], ["83775.74000000", "0.00000000"], ["83775.56000000", "0.00000000"], ["83774.87000000", "0.09198000"], ["83774.76000000", "0.32673000"], ["83774.06000000", "0.17951000"], ["83774.04000000", "0.04000000"], ["83773.95000000", "0.04000000"], ["83773.03000000", "0.00000000"], ["83772.31000000", "0.00000000"], ["83772.06000000", "0.00000000"], ["83769.66000000", "0.21494000"], ["83769.18000000", "0.00000000"], ["83766.80000000", "0.12893000"], ["83766.72000000", "0.03193000"], ["83765.98000000", "0.00248000"], ["83765.60000000", "0.00000000"], ["83762.41000000", "0.00297000"], ["83762.19000000", "0.91919000"], ["83760.44000000", "1.12822000"], ["83756.70000000", "0.04898000"], ["83752.42000000", "0.09303000"], ["83747.14000000", "0.04769000"], ["83745.33000000", "0.20657000"], ["83745.06000000", "0.00013000"], ["83744.68000000", "0.15036000"], ["83742.45000000", "0.33284000"], ["83742.14000000", "0.04769000"], ["83740.97000000", "0.04651000"], ["83739.72000000", "0.17497000"], ["83737.43000000", "0.81743000"], ["83732.78000000", "0.14800000"], ["83731.26000000", "0.10169000"], ["83729.89000000", "0.04297000"], ["83727.24000000", "0.04098000"], ["83727.16000000", "0.05397000"], ["83726.95000000", "0.04098000"], ["83723.90000000", "0.04297000"], ["83723.02000000", "0.04897000"], ["83719.83000000", "0.12993000"], ["83718.11000000", "0.14827000"], ["83716.23000000", "0.00000000"], ["83714.92000000", "0.04774000"], ["83711.42000000", "0.00000000"], ["83708.51000000", "0.00400000"], ["83704.68000000", "0.15447000"], ["83703.05000000", "0.00000000"], ["83702.39000000", "0.00000000"], ["83701.87000000", "0.00000000"], ["83701.26000000", "0.00007000"], ["83699.45000000", "0.00000000"], ["83697.66000000", "0.00000000"], ["83697.39000000", "0.00000000"], ["83697.32000000", "0.00000000"], ["83695.75000000", "0.00000000"], ["83695.19000000", "0.00119000"], ["83694.78000000", "0.25856000"], ["83693.34000000", "0.00000000"], ["83692.59000000", "0.00000000"], ["83690.52000000", "0.00000000"], ["83685.46000000", "0.00119000"], ["83682.13000000", "0.00306000"], ["83680.00000000", "0.09803000"], ["83673.00000000", "0.00000000"], ["83664.95000000", "0.99313000"], ["83660.49000000", "0.01868000"], ["83657.32000000", "0.00000000"], ["83656.24000000", "0.00009000"], ["83645.12000000", "0.00008000"], ["83643.45000000", "0.11668000"], ["83635.07000000", "0.20303000"], ["83629.18000000", "0.08672000"], ["83628.53000000", "0.00013000"], ["83624.34000000", "0.00023000"], ["83623.29000000", "0.00000000"], ["83621.86000000", "0.00013000"], ["83617.67000000", "0.00000000"], ["83607.78000000", "0.00000000"], ["83596.81000000", "0.45000000"], ["83549.65000000", "0.00011000"], ["83340.04000000", "0.00020000"], ["83250.00000000", "0.24291000"], ["82919.58000000", "0.40000000"], ["82911.23000000", "0.00000000"], ["82606.72000000", "0.00000000"], ["80481.52000000", "0.00000000"], ["80464.74000000", "0.00000000"], ["79600.00000000", "1.06517000"], ["75478.00000000", "0.00000000"], ["75477.00000000", "0.00120000"], ["67091.76000000", "0.00000000"], ["67089.82000000", "0.00000000"], ["67080.18000000", "0.00058000"], ["33000.00000000", "2.93827000"]], "a": [["83850.23000000", "0.35540000"], ["83850.24000000", "0.00054000"], ["83850.25000000", "0.00028000"], ["83850.27000000", "0.00021000"], ["83850.28000000", "0.06952000"], ["83850.35000000", "0.00021000"], ["83850.91000000", "0.00007000"], ["83850.92000000", "0.00028000"], ["83850.96000000", "0.00007000"], ["83850.97000000", "0.00021000"], ["83851.05000000", "0.00000000"], ["83851.19000000", "0.00007000"], ["83851.39000000", "0.00014000"], ["83851.40000000", "0.00000000"], ["83851.46000000", "0.00000000"], ["83851.47000000", "0.00007000"], ["83851.99000000", "0.00000000"], ["83852.00000000", "0.00021000"], ["83852.19000000", "0.00008000"], ["83852.70000000", "0.00000000"], ["83852.71000000", "0.00000000"], ["83852.88000000", "0.00007000"], ["83852.94000000", "0.00007000"], ["83853.09000000", "0.00000000"], ["83853.10000000", "0.00000000"], ["83853.11000000", "0.00000000"], ["83853.12000000", "0.00000000"], ["83853.77000000", "0.00000000"], ["83853.78000000", "0.00000000"], ["83853.91000000", "0.00007000"], ["83853.92000000", "0.02373000"], ["83853.95000000", "0.00000000"], ["83853.99000000", "0.00000000"], ["83854.00000000", "0.00000000"], ["83854.01000000", "0.00000000"], ["83854.02000000", "0.00000000"], ["83854.13000000", "0.00000000"], ["83854.14000000", "0.00000000"], ["83854.15000000", "0.00000000"], ["83854.16000000", "0.00000000"], ["83854.21000000", "0.00000000"], ["83854.38000000", "0.00000000"], ["83854.57000000", "0.00000000"], ["83854.81000000", "0.00000000"], ["83855.06000000", "0.00000000"], ["83855.41000000", "0.00000000"], ["83855.46000000", "0.00000000"], ["83855.99000000", "0.00016000"], ["83856.00000000", "0.02820000"], ["83856.05000000", "0.00007000"], ["83856.06000000", "0.11581000"], ["83856.07000000", "0.00000000"], ["83856.08000000", "0.00000000"], ["83856.40000000", "0.00000000"], ["83856.41000000", "0.00000000"], ["83856.42000000", "0.00000000"], ["83856.49000000", "0.00000000"], ["83856.65000000", "0.00000000"], ["83856.76000000", "0.00000000"], ["83856.77000000", "0.00000000"], ["83856.78000000", "0.00000000"], ["83857.09000000", "0.00000000"], ["83857.21000000", "0.00000000"], ["83857.65000000", "0.00000000"], ["83857.66000000", "0.00000000"], ["83857.67000000", "0.00000000"], ["83857.96000000", "0.00000000"], ["83858.00000000", "0.02820000"], ["83858.05000000", "0.00000000"], ["83858.24000000", "0.00000000"], ["83858.28000000", "0.00013000"], ["83858.34000000", "0.00000000"], ["83858.38000000", "0.00000000"], ["83858.49000000", "0.00000000"], ["83858.50000000", "0.00000000"], ["83858.51000000", "0.00000000"], ["83858.60000000", "0.00000000"], ["83858.61000000", "0.00000000"], ["83858.62000000", "0.00000000"], ["83858.63000000", "0.00029000"], ["83858.64000000", "0.00000000"], ["83858.65000000", "0.00000000"], ["83858.68000000", "0.00000000"], ["83859.63000000", "0.00007000"], ["83859.64000000", "0.14255000"], ["83859.65000000", "0.00000000"], ["83859.66000000", "0.00000000"], ["83859.70000000", "0.00000000"], ["83859.73000000", "0.00000000"], ["83859.81000000", "0.00000000"], ["83859.82000000", "0.00000000"], ["83859.83000000", "0.00000000"], ["83859.84000000", "0.00000000"], ["83859.85000000", "0.00000000"], ["83860.00000000", "0.02820000"], ["83860.01000000", "0.00000000"], ["83860.02000000", "0.00000000"], ["83860.27000000", "0.00288000"], ["83860.49000000", "0.00000000"], ["83860.56000000", "0.00000000"], ["83860.70000000", "0.00013000"], ["83860.81000000", "0.00000000"], ["83860.86000000", "0.00000000"], ["83860.91000000", "0.00000000"], ["83860.96000000", "0.00000000"], ["83860.97000000", "0.00000000"], ["83860.98000000", "0.00000000"], ["83861.03000000", "0.00000000"], ["83861.28000000", "0.00000000"], ["83861.29000000", "0.00000000"], ["83861.34000000", "0.00000000"], ["83861.40000000", "0.00006000"], ["83861.41000000", "0.00000000"], ["83861.42000000", "0.00000000"], ["83861.52000000", "0.00416000"], ["83861.90000000", "0.00000000"], ["83861.95000000", "0.00000000"], ["83862.00000000", "0.02820000"], ["83862.01000000", "0.00000000"], ["83862.16000000", "0.00000000"], ["83862.18000000", "0.00000000"], ["83862.19000000", "0.00000000"], ["83862.27000000", "0.00000000"], ["83862.28000000", "0.00000000"], ["83862.32000000", "0.00092000"], ["83862.35000000", "0.00007000"], ["83862.36000000", "0.78738000"], ["83862.38000000", "0.00000000"], ["83862.56000000", "0.00000000"], ["83862.65000000", "0.00119000"], ["83862.78000000", "0.00095000"], ["83862.84000000", "0.00000000"], ["83862.90000000", "0.00000000"], ["83862.94000000", "0.00000000"], ["83862.95000000", "0.00000000"], ["83863.01000000", "0.00000000"], ["83863.02000000", "0.00000000"], ["83863.20000000", "0.00000000"], ["83863.33000000", "0.00090000"], ["83863.45000000", "0.00091000"], ["83863.49000000", "0.00485000"], ["83863.73000000", "0.00000000"], ["83863.84000000", "0.00000000"], ["83863.85000000", "0.00000000"], ["83863.86000000", "0.00000000"], ["83863.87000000", "0.00000000"], ["83863.92000000", "0.23692000"], ["83863.93000000", "0.00000000"], ["83863.94000000", "0.00000000"], ["83864.00000000", "0.02820000"], ["83864.23000000", "0.00000000"], ["83864.25000000", "0.00000000"], ["83864.34000000", "0.00000000"], ["83864.35000000", "0.00000000"], ["83864.50000000", "0.00000000"], ["83864.57000000", "0.00000000"], ["83864.58000000", "0.00000000"], ["83864.59000000", "0.00000000"], ["83864.62000000", "0.00013000"], ["83864.65000000", "0.00000000"], ["83864.66000000", "0.00000000"], ["83864.68000000", "0.00000000"], ["83864.69000000", "0.00000000"], ["83864.70000000", "0.17918000"], ["83864.71000000", "0.00602000"], ["83864.72000000", "0.00000000"], ["83864.73000000", "0.00000000"], ["83864.75000000", "0.00000000"], ["83864.76000000", "0.00000000"], ["83864.77000000", "0.00012000"], ["83864.78000000", "0.00000000"], ["83864.79000000", "0.00000000"], ["83864.81000000", "0.00000000"], ["83865.20000000", "0.00000000"], ["83865.45000000", "0.35802000"], ["83865.58000000", "0.00000000"], ["83865.60000000", "0.00006000"], ["83865.76000000", "0.00000000"], ["83866.00000000", "0.02820000"], ["83866.36000000", "0.00000000"], ["83866.44000000", "0.00000000"], ["83866.45000000", "0.00000000"], ["83866.50000000", "0.00000000"], ["83866.64000000", "0.00009000"], ["83867.02000000", "0.00000000"], ["83867.14000000", "0.00006000"], ["83867.29000000", "0.23859000"], ["83867.35000000", "0.00000000"], ["83867.36000000", "0.00000000"], ["83867.38000000", "0.54965000"], ["83867.46000000", "0.00000000"], ["83867.59000000", "0.00000000"], ["83867.62000000", "0.00000000"], ["83867.82000000", "0.00000000"], ["83867.99000000", "0.00000000"], ["83868.00000000", "0.92561000"], ["83868.31000000", "0.05975000"], ["83868.36000000", "0.00000000"], ["83868.45000000", "0.00000000"], ["83868.83000000", "0.05967000"], ["83868.84000000", "0.00000000"], ["83868.89000000", "0.00000000"], ["83868.90000000", "0.01383000"], ["83868.93000000", "0.89506000"], ["83868.97000000", "0.00013000"], ["83869.05000000", "0.00000000"], ["83869.28000000", "0.00000000"], ["83869.34000000", "0.00000000"], ["83869.56000000", "0.01500000"], ["83869.99000000", "0.00000000"], ["83870.04000000", "0.00000000"], ["83870.05000000", "0.00000000"], ["83870.37000000", "0.00000000"], ["83870.56000000", "0.01500000"], ["83870.67000000", "0.00000000"], ["83870.77000000", "0.00000000"], ["83870.86000000", "0.00013000"], ["83870.88000000", "0.47736000"], ["83871.23000000", "0.00000000"], ["83871.41000000", "0.00000000"], ["83871.73000000", "0.00000000"], ["83871.74000000", "0.00000000"], ["83871.75000000", "1.36362000"], ["83871.84000000", "0.89506000"], ["83872.32000000", "0.00000000"], ["83872.67000000", "0.00000000"], ["83872.71000000", "0.00000000"], ["83873.13000000", "0.00000000"], ["83873.20000000", "0.00000000"], ["83873.23000000", "0.00000000"], ["83873.30000000", "0.00000000"], ["83873.38000000", "0.59671000"], ["83873.40000000", "0.00119000"], ["83873.44000000", "0.89506000"], ["83873.65000000", "0.89506000"], ["83873.66000000", "0.00000000"], ["83873.98000000", "0.00000000"], ["83874.54000000", "0.00000000"], ["83874.83000000", "0.00012000"], ["83875.38000000", "0.09967000"], ["83875.39000000", "0.00059000"], ["83875.46000000", "0.01192000"], ["83875.56000000", "0.00000000"], ["83875.57000000", "1.04929000"], ["83875.58000000", "0.00000000"], ["83875.70000000", "0.00000000"], ["83876.22000000", "0.00000000"], ["83876.46000000", "0.00000000"], ["83876.47000000", "0.00000000"], ["83876.51000000", "0.00826000"], ["83876.59000000", "0.00000000"], ["83877.08000000", "0.04000000"], ["83877.28000000", "0.00000000"], ["83877.42000000", "0.00000000"], ["83878.20000000", "0.14006000"], ["83878.28000000", "0.00000000"], ["83878.41000000", "0.00119000"], ["83878.65000000", "0.00000000"], ["83878.69000000", "0.00000000"], ["83878.78000000", "0.00000000"], ["83878.95000000", "0.01868000"], ["83879.38000000", "0.00000000"], ["83879.96000000", "0.00000000"], ["83880.30000000", "0.00000000"], ["83880.75000000", "0.00000000"], ["83881.28000000", "0.00000000"], ["83881.29000000", "0.00000000"], ["83881.47000000", "0.71594000"], ["83881.87000000", "0.00000000"], ["83882.31000000", "0.00000000"], ["83882.45000000", "0.20303000"], ["83882.92000000", "0.00898000"], ["83883.22000000", "0.00000000"], ["83883.28000000", "0.85874000"], ["83883.32000000", "0.00298000"], ["83883.37000000", "0.00000000"], ["83883.47000000", "0.00355000"], ["83884.04000000", "0.00084000"], ["83884.05000000", "0.01196000"], ["83884.35000000", "0.00577000"], ["83884.65000000", "0.00016000"], ["83884.66000000", "0.00000000"], ["83884.75000000", "0.16000000"], ["83884.93000000", "0.00000000"], ["83885.32000000", "0.00000000"], ["83885.50000000", "0.00000000"], ["83885.98000000", "0.00000000"], ["83886.57000000", "0.00300000"], ["83886.63000000", "0.00000000"], ["83886.67000000", "0.00000000"], ["83887.15000000", "0.00000000"], ["83887.85000000", "0.00000000"], ["83887.99000000", "0.00000000"], ["83888.01000000", "0.00000000"], ["83888.08000000", "0.00000000"], ["83888.52000000", "0.37309000"], ["83888.55000000", "0.00000000"], ["83888.83000000", "0.00000000"], ["83889.15000000", "0.00000000"], ["83889.48000000", "0.00000000"], ["83889.86000000", "0.00000000"], ["83890.06000000", "0.03401000"], ["83890.18000000", "0.02131000"], ["83890.64000000", "0.00000000"], ["83890.70000000", "0.35802000"], ["83891.30000000", "0.00000000"], ["83891.48000000", "0.00000000"], ["83891.51000000", "0.32471000"], ["83891.73000000", "0.00000000"], ["83892.18000000", "0.00013000"], ["83892.52000000", "0.00000000"], ["83893.24000000", "0.59652000"], ["83893.26000000", "0.00000000"], ["83893.54000000", "0.00000000"], ["83893.59000000", "0.00000000"], ["83894.07000000", "0.00000000"], ["83894.54000000", "0.00000000"], ["83895.42000000", "0.00000000"], ["83895.47000000", "0.00557000"], ["83896.34000000", "0.00000000"], ["83896.52000000", "0.00000000"], ["83897.31000000", "0.00756000"], ["83897.38000000", "0.00000000"], ["83897.39000000", "0.00000000"], ["83897.90000000", "0.00000000"], ["83898.23000000", "0.11499000"], ["83898.52000000", "0.00000000"], ["83898.75000000", "0.00000000"], ["83898.76000000", "0.00819000"], ["83898.78000000", "0.00000000"], ["83899.01000000", "0.00824000"], ["83899.10000000", "0.00000000"], ["83899.38000000", "0.00000000"], ["83899.40000000", "0.20652000"], ["83899.58000000", "0.00000000"], ["83899.60000000", "0.00863000"], ["83899.74000000", "0.00000000"], ["83900.04000000", "0.00000000"], ["83900.28000000", "0.00822000"], ["83900.39000000", "0.00000000"], ["83900.50000000", "0.00000000"], ["83902.89000000", "0.00000000"], ["83903.35000000", "0.00000000"], ["83903.72000000", "0.00000000"], ["83904.01000000", "0.00000000"], ["83905.36000000", "0.00000000"], ["83905.44000000", "0.00000000"], ["83905.68000000", "0.04897000"], ["83906.26000000", "0.04835000"], ["83906.40000000", "0.00000000"], ["83906.90000000", "0.00000000"], ["83907.32000000", "0.47736000"], ["83907.88000000", "0.00000000"], ["83908.28000000", "0.00000000"], ["83908.41000000", "0.49897000"], ["83908.55000000", "0.00000000"], ["83908.67000000", "0.00298000"], ["83909.02000000", "0.00120000"], ["83909.03000000", "0.04000000"], ["83909.12000000", "0.00000000"], ["83909.82000000", "0.59671000"], ["83910.03000000", "0.00000000"], ["83910.99000000", "0.04654000"], ["83911.49000000", "0.00000000"], ["83912.49000000", "0.00000000"], ["83913.34000000", "0.00000000"], ["83913.59000000", "0.00000000"], ["83913.70000000", "0.04657000"], ["83913.79000000", "0.00000000"], ["83913.94000000", "0.00000000"], ["83915.79000000", "0.00000000"], ["83916.19000000", "0.00000000"], ["83916.22000000", "0.00000000"], ["83917.28000000", "0.00000000"], ["83917.38000000", "0.00000000"], ["83918.08000000", "0.00000000"], ["83918.51000000", "0.00000000"], ["83920.45000000", "1.12607000"], ["83923.70000000", "0.00000000"], ["83924.75000000", "0.00000000"], ["83926.45000000", "0.00146000"], ["83926.59000000", "0.12869000"], ["83926.93000000", "0.03193000"], ["83927.65000000", "0.05193000"], ["83928.87000000", "0.00358000"], ["83929.40000000", "0.00000000"], ["83932.53000000", "0.00000000"], ["83932.62000000", "0.00000000"], ["83934.86000000", "0.47215000"], ["83934.87000000", "0.00000000"], ["83939.17000000", "0.00084000"], ["83939.18000000", "0.15189000"], ["83939.19000000", "0.00358000"], ["83940.37000000", "0.00000000"], ["83943.26000000", "0.00000000"], ["83945.07000000", "0.00000000"], ["83945.17000000", "0.00000000"], ["83945.84000000", "0.05397000"], ["83948.73000000", "0.05397000"], ["83949.01000000", "0.00000000"], ["83949.74000000", "0.00000000"], ["83949.80000000", "0.00012000"], ["83951.22000000", "0.05397000"], ["83953.26000000", "0.00000000"], ["83953.54000000", "0.05497000"], ["83954.10000000", "0.00000000"], ["83955.46000000", "0.05397000"], ["83957.59000000", "0.05497000"], ["83958.24000000", "0.05397000"], ["83958.92000000", "0.04651000"], ["83959.22000000", "0.04650000"], ["83960.38000000", "0.05497000"], ["83962.40000000", "0.05397000"], ["83962.74000000", "0.05197000"], ["83963.06000000", "0.05497000"], ["83964.28000000", "0.00060000"], ["83965.59000000", "0.05197000"], ["83966.53000000", "0.05497000"], ["83969.29000000", "0.00000000"], ["83970.16000000", "0.09302000"], ["83972.73000000", "0.00000000"], ["83975.18000000", "0.04898000"], ["83975.30000000", "0.00013000"], ["83977.58000000", "0.00000000"], ["83980.19000000", "0.00000000"], ["83983.20000000", "0.00006000"], ["83986.10000000", "0.00000000"], ["83986.24000000", "0.00000000"], ["83987.79000000", "0.00000000"], ["83988.41000000", "0.00000000"], ["83990.10000000", "0.19886000"], ["83990.17000000", "0.00000000"], ["83991.48000000", "0.00000000"], ["83992.12000000", "0.00000000"], ["83992.28000000", "0.00000000"], ["83993.12000000", "0.00000000"], ["83994.91000000", "0.00000000"], ["83995.43000000", "0.00000000"], ["83996.06000000", "0.00000000"], ["83996.25000000", "0.00000000"], ["83996.29000000", "0.00000000"], ["83996.37000000", "0.00000000"], ["84000.52000000", "0.00000000"], ["84002.22000000", "0.00000000"], ["84002.68000000", "0.00000000"], ["84002.78000000", "0.00000000"], ["84004.03000000", "0.00000000"], ["84005.06000000", "0.00000000"], ["84006.66000000", "0.00000000"], ["84007.46000000", "0.21468000"], ["84007.47000000", "0.00000000"], ["84008.15000000", "0.00000000"], ["84013.19000000", "0.00000000"], ["84013.24000000", "0.00000000"], ["84026.15000000", "0.01000000"], ["84030.16000000", "0.00000000"], ["84032.96000000", "0.00000000"], ["84098.57000000", "0.00013000"], ["84110.71000000", "0.00000000"], ["84111.91000000", "0.00000000"], ["84114.90000000", "0.00000000"], ["84118.20000000", "0.00000000"], ["84122.39000000", "0.00000000"], ["84177.10000000", "0.03579000"], ["84180.09000000", "0.00000000"], ["84181.47000000", "0.00000000"], ["84184.13000000", "0.19021000"], ["84187.22000000", "0.00000000"], ["84188.47000000", "0.00000000"], ["84219.00000000", "0.00000000"], ["84951.01000000", "0.00000000"], ["84959.43000000", "0.60000000"], ["85106.25000000", "0.11766000"], ["85122.69000000", "0.00000000"], ["85127.50000000", "0.00000000"], ["85861.64000000", "0.00000000"], ["150001.00000000", "0.00092000"]], "record_time": 1742561268.041391, "EXCHANGE": "BINANCE"}
