{"e": "depthUpdate", "E": 1742576908014, "s": "BTCUSDT", "U": 64631961749, "u": 64631961915, "b": [["83945.64000000", "4.00045000"], ["83944.81000000", "0.25161000"], ["83944.76000000", "0.06043000"], ["83944.00000000", "0.01416000"], ["83943.10000000", "0.00000000"], ["83941.10000000", "0.19033000"], ["83940.91000000", "0.00000000"], ["83940.34000000", "0.00000000"], ["83932.81000000", "0.00000000"], ["83932.13000000", "0.92635000"], ["83928.62000000", "0.00000000"], ["83924.99000000", "0.59586000"], ["83921.22000000", "0.00000000"], ["83915.88000000", "0.71241000"], ["83913.13000000", "0.04000000"], ["83861.40000000", "0.00000000"], ["83827.04000000", "0.00000000"], ["83821.40000000", "0.12000000"], ["83819.46000000", "0.00400000"], ["83809.92000000", "0.00000000"], ["83809.47000000", "0.00000000"], ["83806.20000000", "0.01018000"], ["83726.74000000", "0.01865000"], ["83703.31000000", "0.00000000"], ["83022.73000000", "0.00000000"], ["82984.80000000", "0.02350000"], ["82686.45000000", "0.00000000"], ["75726.69000000", "0.00132000"], ["75551.08000000", "0.00032000"], ["75551.00000000", "0.10027000"], ["67156.52000000", "0.00058000"], ["42000.00000000", "6.84710000"], ["33000.00000000", "2.96666000"], ["30220.43000000", "0.00060000"]], "a": [["83945.65000000", "0.89338000"], ["83945.67000000", "0.16859000"], ["83945.68000000", "0.00007000"], ["83947.17000000", "0.00007000"], ["83947.25000000", "0.00021000"], ["83947.26000000", "0.47528000"], ["83947.72000000", "0.00014000"], ["83948.00000000", "0.01427000"], ["83948.24000000", "0.00015000"], ["83948.25000000", "0.00006000"], ["83949.00000000", "0.00000000"], ["83949.61000000", "0.44135000"], ["83949.80000000", "0.01000000"], ["83950.00000000", "0.01352000"], ["83954.05000000", "0.45000000"], ["83958.23000000", "0.00000000"], ["83963.86000000", "0.00000000"], ["83966.54000000", "0.86234000"], ["83967.58000000", "0.01955000"], ["83968.60000000", "0.00000000"], ["83973.31000000", "0.00000000"], ["83973.47000000", "0.00914000"], ["83988.68000000", "0.00000000"], ["83989.40000000", "0.00000000"], ["83992.10000000", "0.38810000"], ["83992.11000000", "0.59583000"], ["83992.12000000", "0.00000000"], ["83992.55000000", "0.12469000"], ["83994.10000000", "0.05000000"], ["83997.45000000", "0.00000000"], ["84088.31000000", "0.00000000"], ["84092.85000000", "0.01018000"], ["84173.13000000", "0.00000000"], ["85204.84000000", "0.00000000"]], "record_time": 1742576908.214334, "EXCHANGE": "BINANCE"}
{"e": "depthUpdate", "E": 1742576909014, "s": "BTCUSDT", "U": 64631961916, "u": 64631962109, "b": [["83945.64000000", "2.91993000"], ["83945.63000000", "0.00047000"], ["83944.76000000", "0.03984000"], ["83943.09000000", "0.00000000"], ["83942.80000000", "0.00000000"], ["83940.23000000", "0.15329000"], ["83938.23000000", "0.00000000"], ["83937.32000000", "0.05619000"], ["83934.96000000", "0.00000000"], ["83934.43000000", "0.00419000"], ["83934.08000000", "0.02351000"], ["83933.95000000", "0.00000000"], ["83932.80000000", "0.04006000"], ["83928.52000000", "1.86082000"], ["83927.65000000", "0.00000000"], ["83926.49000000", "0.00000000"], ["83925.74000000", "1.36819000"], ["83924.99000000", "0.00000000"], ["83924.34000000", "1.11171000"], ["83923.40000000", "0.11409000"], ["83922.76000000", "0.00000000"], ["83921.22000000", "0.59587000"], ["83920.61000000", "0.85836000"], ["83913.65000000", "0.00000000"], ["83909.29000000", "0.00000000"], ["83900.99000000", "0.00000000"], ["83819.46000000", "0.00000000"], ["83806.64000000", "0.01018000"], ["83806.20000000", "0.00000000"], ["83802.04000000", "0.00400000"], ["83726.74000000", "0.00000000"], ["82984.80000000", "0.00000000"], ["82686.45000000", "0.00100000"], ["75551.00000000", "0.10027000"], ["67156.52000000", "0.00058000"], ["33000.00000000", "2.96666000"], ["30220.43000000", "0.00120000"]], "a": [["83945.65000000", "2.49850000"], ["83945.66000000", "0.08791000"], ["83945.67000000", "0.16859000"], ["83945.68000000", "0.00007000"], ["83946.12000000", "0.00042000"], ["83946.13000000", "0.14628000"], ["83946.30000000", "0.00021000"], ["83946.31000000", "0.35859000"], ["83946.71000000", "0.00000000"], ["83947.17000000", "0.00000000"], ["83947.25000000", "0.00000000"], ["83947.26000000", "0.00000000"], ["83947.99000000", "0.00013000"], ["83948.00000000", "0.01426000"], ["83948.24000000", "0.00000000"], ["83948.25000000", "0.00000000"], ["83949.46000000", "0.02305000"], ["83949.80000000", "0.00500000"], ["83950.46000000", "0.00000000"], ["83951.88000000", "0.00000000"], ["83954.04000000", "0.71724000"], ["83954.44000000", "0.78651000"], ["83957.10000000", "0.00000000"], ["83957.50000000", "0.00000000"], ["83957.55000000", "0.00000000"], ["83957.72000000", "0.00000000"], ["83957.96000000", "0.00000000"], ["83958.21000000", "0.39121000"], ["83958.23000000", "0.01191000"], ["83958.85000000", "0.00000000"], ["83959.20000000", "0.15227000"], ["83966.54000000", "0.84649000"], ["83966.87000000", "0.00000000"], ["83967.09000000", "0.00000000"], ["83967.58000000", "0.01865000"], ["83968.11000000", "1.31519000"], ["83968.60000000", "0.00000000"], ["83974.48000000", "0.85781000"], ["83982.55000000", "0.59589000"], ["83987.70000000", "0.05000000"], ["83988.05000000", "0.00000000"], ["83992.10000000", "0.00000000"], ["83992.11000000", "0.00000000"], ["83992.83000000", "0.18613000"], ["83993.42000000", "0.00000000"], ["83993.62000000", "0.00000000"], ["83993.92000000", "0.04000000"], ["83994.10000000", "0.00000000"], ["83995.95000000", "0.02808000"], ["84038.42000000", "1.21633000"], ["84040.46000000", "1.22254000"], ["84092.85000000", "0.00000000"], ["84093.38000000", "0.01018000"], ["84281.44000000", "0.00008000"], ["85204.84000000", "0.00100000"], ["98400.00000000", "6.13217000"]], "record_time": 1742576909.214484, "EXCHANGE": "BINANCE"}
{"e": "depthUpdate", "E": 1742576910014, "s": "BTCUSDT", "U": 64631962110, "u": 64631962564, "b": [["83945.64000000", "0.99043000"], ["83945.63000000", "0.00047000"], ["83945.62000000", "0.00007000"], ["83945.61000000", "0.00007000"], ["83945.56000000", "0.00007000"], ["83945.51000000", "0.00007000"], ["83945.20000000", "0.00000000"], ["83945.19000000", "0.00000000"], ["83944.82000000", "0.00000000"], ["83944.81000000", "0.00000000"], ["83944.79000000", "0.00000000"], ["83944.78000000", "0.00014000"], ["83944.77000000", "0.78673000"], ["83944.76000000", "0.03484000"], ["83944.69000000", "0.00000000"], ["83944.19000000", "0.00000000"], ["83944.00000000", "0.01423000"], ["83943.85000000", "0.00000000"], ["83943.77000000", "0.00000000"], ["83943.01000000", "0.00024000"], ["83943.00000000", "0.02384000"], ["83942.59000000", "0.00000000"], ["83942.31000000", "0.00000000"], ["83942.00000000", "0.01416000"], ["83941.89000000", "0.00000000"], ["83941.84000000", "0.02468000"], ["83941.10000000", "0.00000000"], ["83941.08000000", "0.00000000"], ["83940.96000000", "0.00000000"], ["83940.91000000", "0.00000000"], ["83940.49000000", "0.00000000"], ["83940.24000000", "0.00000000"], ["83940.23000000", "0.00000000"], ["83940.07000000", "0.00000000"], ["83939.91000000", "0.00000000"], ["83939.65000000", "0.00000000"], ["83939.50000000", "0.00000000"], ["83939.49000000", "0.04000000"], ["83939.12000000", "0.05363000"], ["83939.07000000", "0.00000000"], ["83938.91000000", "0.00500000"], ["83938.65000000", "0.00000000"], ["83938.49000000", "0.00500000"], ["83938.35000000", "0.27025000"], ["83937.67000000", "0.01000000"], ["83937.65000000", "0.04000000"], ["83937.33000000", "0.17899000"], ["83937.25000000", "0.03000000"], ["83937.24000000", "0.45000000"], ["83937.21000000", "0.00000000"], ["83936.91000000", "0.46433000"], ["83936.89000000", "0.02382000"], ["83936.69000000", "0.15329000"], ["83936.50000000", "0.00000000"], ["83934.65000000", "0.00095000"], ["83934.29000000", "0.00000000"], ["83934.18000000", "0.00000000"], ["83934.08000000", "0.00000000"], ["83932.78000000", "0.00000000"], ["83932.30000000", "0.00000000"], ["83932.13000000", "0.53361000"], ["83931.98000000", "0.00089000"], ["83931.88000000", "0.04000000"], ["83931.84000000", "0.00000000"], ["83931.65000000", "0.00000000"], ["83931.60000000", "0.00000000"], ["83931.54000000", "0.85825000"], ["83930.47000000", "0.00000000"], ["83930.44000000", "0.17510000"], ["83929.67000000", "0.00000000"], ["83929.50000000", "0.00000000"], ["83929.20000000", "0.00000000"], ["83927.98000000", "0.85829000"], ["83927.97000000", "0.00000000"], ["83926.55000000", "0.00000000"], ["83924.98000000", "0.00000000"], ["83924.82000000", "0.00000000"], ["83924.34000000", "0.77284000"], ["83923.40000000", "0.00000000"], ["83921.22000000", "0.00000000"], ["83921.21000000", "0.00000000"], ["83921.17000000", "0.85835000"], ["83920.61000000", "0.00000000"], ["83920.45000000", "0.05959000"], ["83918.90000000", "0.00000000"], ["83918.50000000", "0.11510000"], ["83916.43000000", "0.00000000"], ["83914.93000000", "0.00000000"], ["83913.28000000", "0.59593000"], ["83908.01000000", "0.00000000"], ["83907.10000000", "0.00000000"], ["83906.57000000", "0.00000000"], ["83906.29000000", "0.00000000"], ["83902.99000000", "0.00000000"], ["83902.34000000", "0.05815000"], ["83898.45000000", "0.00000000"], ["83894.90000000", "0.04490000"], ["83894.15000000", "0.00000000"], ["83884.68000000", "0.04480000"], ["83882.38000000", "0.00000000"], ["83865.60000000", "0.03581000"], ["83855.17000000", "0.00000000"], ["83802.04000000", "0.00000000"], ["83772.51000000", "0.00400000"], ["83120.16000000", "0.00007000"], ["82959.99000000", "0.00000000"], ["82686.45000000", "0.00100000"], ["80589.60000000", "0.00000000"], ["80572.80000000", "0.00000000"], ["75551.08000000", "0.00057000"], ["75551.00000000", "0.10027000"], ["67156.52000000", "0.00058000"], ["60000.00000000", "72.96736000"], ["33000.00000000", "2.96666000"], ["20002.00000000", "0.00000000"], ["20001.00000000", "0.02099000"]], "a": [["83945.65000000", "4.54618000"], ["83945.67000000", "0.12381000"], ["83945.68000000", "0.00007000"], ["83945.86000000", "0.04014000"], ["83946.13000000", "0.14622000"], ["83946.30000000", "0.00007000"], ["83946.31000000", "0.00006000"], ["83948.00000000", "0.01426000"], ["83949.20000000", "0.14359000"], ["83949.43000000", "0.00000000"], ["83949.61000000", "0.64059000"], ["83949.80000000", "0.01000000"], ["83949.83000000", "0.04000000"], ["83950.00000000", "0.02762000"], ["83950.07000000", "0.00000000"], ["83950.47000000", "0.00000000"], ["83951.15000000", "0.00000000"], ["83951.81000000", "0.78654000"], ["83952.03000000", "0.00119000"], ["83952.21000000", "0.00000000"], ["83952.35000000", "0.00595000"], ["83952.36000000", "0.00000000"], ["83953.80000000", "0.00019000"], ["83954.04000000", "0.39577000"], ["83954.33000000", "0.00000000"], ["83954.44000000", "0.00000000"], ["83954.96000000", "0.06800000"], ["83955.62000000", "0.00000000"], ["83955.77000000", "0.06400000"], ["83955.79000000", "0.06800000"], ["83955.85000000", "0.06800000"], ["83956.13000000", "0.00000000"], ["83956.15000000", "0.00013000"], ["83956.33000000", "0.00000000"], ["83956.44000000", "0.00000000"], ["83957.26000000", "0.00000000"], ["83958.21000000", "0.82039000"], ["83958.61000000", "0.83946000"], ["83959.20000000", "0.05600000"], ["83959.82000000", "0.00000000"], ["83959.99000000", "0.04400000"], ["83960.04000000", "0.00000000"], ["83960.87000000", "0.00000000"], ["83960.89000000", "0.15211000"], ["83961.43000000", "0.71486000"], ["83962.47000000", "0.00000000"], ["83965.08000000", "0.00000000"], ["83966.02000000", "0.00000000"], ["83969.95000000", "0.00000000"], ["83970.52000000", "0.08992000"], ["83970.97000000", "0.00000000"], ["83975.60000000", "0.00000000"], ["83978.91000000", "0.00000000"], ["83981.13000000", "0.59591000"], ["83982.55000000", "0.00000000"], ["83983.22000000", "0.74586000"], ["83983.23000000", "0.85772000"], ["83983.26000000", "0.00000000"], ["83985.68000000", "0.12087000"], ["83986.01000000", "0.04119000"], ["83986.28000000", "0.00000000"], ["83986.30000000", "0.05815000"], ["83987.70000000", "0.00000000"], ["83988.02000000", "0.00000000"], ["83990.35000000", "0.00000000"], ["83990.53000000", "0.00000000"], ["83992.55000000", "0.00000000"], ["83999.60000000", "0.00000000"], ["83999.63000000", "0.47675000"], ["83999.64000000", "0.04110000"], ["83999.97000000", "0.00000000"], ["84000.53000000", "0.00000000"], ["84000.54000000", "0.00000000"], ["84040.46000000", "0.00000000"], ["84046.77000000", "0.02384000"], ["84062.52000000", "0.00000000"], ["85204.84000000", "0.00100000"], ["85233.75000000", "0.00000000"], ["85242.60000000", "0.00000000"]], "record_time": 1742576910.214682, "EXCHANGE": "BINANCE"}
{"e": "depthUpdate", "E": 1742576911015, "s": "BTCUSDT", "U": 64631962565, "u": 64631962772, "b": [["83945.64000000", "0.50893000"], ["83945.51000000", "0.00007000"], ["83945.43000000", "0.00000000"], ["83945.42000000", "0.00000000"], ["83944.78000000", "0.00032000"], ["83944.76000000", "0.03484000"], ["83944.59000000", "0.25248000"], ["83944.00000000", "0.01423000"], ["83943.44000000", "0.00000000"], ["83943.19000000", "0.00021000"], ["83943.18000000", "0.06273000"], ["83943.01000000", "0.00000000"], ["83943.00000000", "0.02370000"], ["83942.49000000", "0.00000000"], ["83942.00000000", "0.01410000"], ["83941.84000000", "0.04682000"], ["83938.35000000", "0.13526000"], ["83937.24000000", "0.00000000"], ["83937.00000000", "0.04006000"], ["83932.13000000", "0.28448000"], ["83931.54000000", "0.00000000"], ["83929.89000000", "0.00000000"], ["83926.48000000", "0.00000000"], ["83925.43000000", "0.71486000"], ["83924.34000000", "0.54123000"], ["83924.33000000", "0.00000000"], ["83918.66000000", "0.85838000"], ["83905.09000000", "0.00000000"], ["83887.18000000", "0.00000000"], ["83782.17000000", "0.00000000"], ["83782.07000000", "0.01000000"], ["83779.81000000", "0.00000000"], ["83772.51000000", "0.00000000"], ["83770.46000000", "0.00839000"], ["83763.18000000", "0.00400000"], ["83575.00000000", "0.00682000"], ["83106.18000000", "0.00000000"], ["82686.45000000", "0.00000000"], ["75551.08000000", "0.00032000"], ["75551.00000000", "0.10027000"], ["67156.52000000", "0.00058000"], ["60000.00000000", "72.96726000"], ["33000.00000000", "2.96666000"], ["19357.79000000", "0.00000000"]], "a": [["83945.65000000", "5.39575000"], ["83947.32000000", "0.00000000"], ["83949.60000000", "0.00014000"], ["83949.83000000", "0.00000000"], ["83950.12000000", "0.78655000"], ["83951.81000000", "0.00000000"], ["83952.36000000", "0.01191000"], ["83956.14000000", "0.18658000"], ["83956.86000000", "0.08992000"], ["83958.78000000", "0.00000000"], ["83960.93000000", "0.00000000"], ["83966.02000000", "0.00000000"], ["83970.45000000", "0.85785000"], ["83973.34000000", "0.00000000"], ["83983.22000000", "0.00000000"], ["83983.23000000", "0.00000000"], ["83983.26000000", "0.48854000"], ["83985.24000000", "0.00000000"], ["83998.64000000", "0.47675000"], ["83998.83000000", "0.00000000"], ["83999.63000000", "0.00000000"], ["84017.47000000", "0.00000000"], ["84095.22000000", "0.00000000"], ["84101.83000000", "0.00000000"], ["85204.84000000", "0.00000000"], ["85242.60000000", "0.05875000"], ["85263.90000000", "0.00000000"]], "record_time": 1742576911.215015, "EXCHANGE": "BINANCE"}
{"e": "depthUpdate", "E": 1742576912014, "s": "BTCUSDT", "U": 64631962773, "u": 64631962946, "b": [["83945.64000000", "0.79049000"], ["83944.76000000", "0.03478000"], ["83944.59000000", "0.00006000"], ["83943.18000000", "0.06280000"], ["83943.00000000", "0.02370000"], ["83942.37000000", "0.00000000"], ["83942.17000000", "0.00007000"], ["83941.16000000", "0.00031000"], ["83939.76000000", "0.00759000"], ["83938.35000000", "0.13526000"], ["83938.34000000", "0.00000000"], ["83937.24000000", "0.00000000"], ["83935.88000000", "0.00000000"], ["83934.20000000", "0.00000000"], ["83934.14000000", "0.00000000"], ["83933.87000000", "0.04000000"], ["83933.25000000", "0.00000000"], ["83932.18000000", "0.43851000"], ["83932.13000000", "0.00000000"], ["83931.41000000", "0.04000000"], ["83929.73000000", "0.04000000"], ["83929.67000000", "0.04000000"], ["83925.70000000", "0.02357000"], ["83917.33000000", "0.00000000"], ["83914.87000000", "0.00000000"], ["83913.19000000", "0.00000000"], ["83913.13000000", "0.00000000"], ["83912.92000000", "0.04000000"], ["83910.40000000", "0.04000000"], ["83908.73000000", "0.04000000"], ["83908.72000000", "0.04000000"], ["83900.29000000", "0.00000000"], ["83888.48000000", "0.05000000"], ["83870.94000000", "0.04000000"], ["83862.87000000", "0.00000000"], ["83859.77000000", "0.04000000"], ["83858.17000000", "0.00000000"], ["83856.77000000", "0.04000000"], ["83855.60000000", "0.04000000"], ["83812.00000000", "0.00242000"], ["83782.07000000", "0.01000000"], ["83768.73000000", "0.00400000"], ["83763.18000000", "0.00000000"], ["83682.35000000", "0.01865000"], ["82942.19000000", "0.00000000"], ["82883.64000000", "0.00000000"], ["82686.45000000", "0.00100000"], ["80589.60000000", "0.03572000"], ["75551.00000000", "0.10027000"], ["67156.52000000", "0.00058000"], ["33000.00000000", "2.96666000"], ["30220.43000000", "0.00160000"]], "a": [["83945.65000000", "5.69645000"], ["83946.13000000", "0.14622000"], ["83947.26000000", "0.00000000"], ["83949.61000000", "0.62023000"], ["83949.80000000", "0.01000000"], ["83950.12000000", "0.00000000"], ["83950.48000000", "0.00000000"], ["83951.03000000", "0.00000000"], ["83951.89000000", "0.00000000"], ["83952.36000000", "0.01191000"], ["83952.50000000", "0.00000000"], ["83953.27000000", "0.78652000"], ["83956.86000000", "0.00000000"], ["83966.02000000", "0.00000000"], ["83967.53000000", "0.00000000"], ["83970.45000000", "0.00000000"], ["83970.64000000", "0.00000000"], ["83970.90000000", "0.00000000"], ["83972.51000000", "0.00000000"], ["83973.33000000", "0.05000000"], ["83980.00000000", "0.02602000"], ["83982.84000000", "0.37751000"], ["83983.87000000", "0.00000000"], ["83984.17000000", "0.85771000"], ["83991.05000000", "0.47775000"], ["83998.64000000", "0.00000000"], ["83998.65000000", "0.00000000"], ["83999.18000000", "0.00000000"], ["84025.69000000", "0.00019000"], ["84102.30000000", "0.00016000"], ["84109.86000000", "0.00050000"], ["84113.53000000", "0.01141000"], ["84917.96000000", "0.00000000"], ["85204.84000000", "0.00100000"], ["85221.30000000", "0.00000000"], ["85242.60000000", "0.00000000"]], "record_time": 1742576912.214505, "EXCHANGE": "BINANCE"}
{"e": "depthUpdate", "E": 1742576913014, "s": "BTCUSDT", "U": 64631962947, "u": 64631963072, "b": [["83945.64000000", "0.31489000"], ["83945.51000000", "0.00007000"], ["83945.24000000", "0.00202000"], ["83944.36000000", "0.00000000"], ["83943.00000000", "0.02364000"], ["83942.80000000", "0.00000000"], ["83942.01000000", "0.30829000"], ["83941.03000000", "0.00000000"], ["83932.70000000", "0.00000000"], ["83930.05000000", "0.00000000"], ["83925.43000000", "0.71486000"], ["83913.28000000", "0.00000000"], ["83912.85000000", "0.04000000"], ["83909.74000000", "0.59595000"], ["83901.09000000", "0.05000000"], ["83888.48000000", "0.00000000"], ["83865.63000000", "0.00000000"], ["83856.77000000", "0.00000000"], ["83855.60000000", "0.00000000"], ["83849.64000000", "0.63073000"], ["83768.73000000", "0.00000000"], ["83762.85000000", "0.00000000"], ["83757.81000000", "0.00400000"], ["83751.76000000", "0.01865000"], ["83682.35000000", "0.00000000"], ["82875.30000000", "0.40000000"], ["82686.45000000", "0.00100000"], ["75551.00000000", "0.10027000"], ["67156.52000000", "0.00058000"], ["33000.00000000", "2.96666000"]], "a": [["83945.65000000", "6.37956000"], ["83945.68000000", "0.00007000"], ["83945.84000000", "0.00209000"], ["83946.13000000", "0.14622000"], ["83946.30000000", "0.00000000"], ["83947.32000000", "0.00117000"], ["83949.80000000", "0.00500000"], ["83950.17000000", "0.00503000"], ["83950.18000000", "0.00000000"], ["83966.04000000", "0.00000000"], ["83970.97000000", "0.59595000"], ["83971.33000000", "0.05000000"], ["83973.33000000", "0.00000000"], ["83977.90000000", "0.00000000"], ["83981.13000000", "0.00000000"], ["83983.26000000", "0.68479000"], ["83985.20000000", "0.00400000"], ["83995.30000000", "0.00000000"], ["83998.55000000", "0.00000000"], ["84000.80000000", "0.03979000"], ["84001.94000000", "0.00000000"], ["84046.77000000", "0.00000000"], ["84061.66000000", "0.02384000"], ["84909.55000000", "0.60000000"], ["85204.84000000", "0.00100000"]], "record_time": 1742576913.214823, "EXCHANGE": "BINANCE"}
{"e": "depthUpdate", "E": 1742576914014, "s": "BTCUSDT", "U": 64631963073, "u": 64631966915, "b": [["83958.22000000", "3.97380000"], ["83958.21000000", "0.00048000"], ["83958.20000000", "0.00007000"], ["83958.12000000", "0.00000000"], ["83958.06000000", "0.00021000"], ["83958.05000000", "0.50557000"], ["83958.04000000", "0.00007000"], ["83958.03000000", "0.00007000"], ["83958.02000000", "0.00007000"], ["83958.01000000", "0.00000000"], ["83958.00000000", "0.01423000"], ["83957.99000000", "0.00000000"], ["83957.75000000", "0.00000000"], ["83957.71000000", "0.00000000"], ["83957.70000000", "0.05376000"], ["83957.35000000", "0.00000000"], ["83956.98000000", "0.00000000"], ["83956.67000000", "0.00000000"], ["83956.57000000", "0.00000000"], ["83956.56000000", "0.00000000"], ["83956.37000000", "0.00000000"], ["83956.25000000", "0.00000000"], ["83956.16000000", "0.00000000"], ["83956.15000000", "0.00000000"], ["83956.13000000", "0.00000000"], ["83956.00000000", "0.01423000"], ["83955.99000000", "0.00000000"], ["83955.88000000", "0.00000000"], ["83955.84000000", "0.00000000"], ["83955.78000000", "0.00000000"], ["83955.77000000", "0.00000000"], ["83955.76000000", "0.00000000"], ["83955.65000000", "0.00014000"], ["83955.64000000", "0.89398000"], ["83955.53000000", "0.00000000"], ["83955.14000000", "0.00000000"], ["83955.04000000", "0.00000000"], ["83955.00000000", "0.00000000"], ["83954.95000000", "0.00000000"], ["83954.90000000", "0.00000000"], ["83954.76000000", "0.00000000"], ["83954.56000000", "0.00000000"], ["83954.46000000", "0.02488000"], ["83954.45000000", "0.00000000"], ["83954.44000000", "0.00000000"], ["83954.35000000", "0.00000000"], ["83954.34000000", "0.00000000"], ["83954.28000000", "0.00000000"], ["83954.27000000", "0.11916000"], ["83954.24000000", "0.00000000"], ["83954.18000000", "0.00000000"], ["83954.16000000", "0.00000000"], ["83954.10000000", "0.00000000"], ["83954.07000000", "0.00000000"], ["83954.04000000", "0.00000000"], ["83954.03000000", "0.00000000"], ["83954.00000000", "0.01416000"], ["83953.79000000", "0.00000000"], ["83953.72000000", "0.00595000"], ["83953.68000000", "0.00000000"], ["83953.65000000", "0.00000000"], ["83953.59000000", "0.00000000"], ["83953.31000000", "0.00000000"], ["83953.18000000", "0.00000000"], ["83953.13000000", "0.00000000"], ["83953.07000000", "0.00000000"], ["83953.04000000", "0.00000000"], ["83952.98000000", "0.76758000"], ["83952.97000000", "0.89398000"], ["83952.79000000", "0.00000000"], ["83952.78000000", "0.00000000"], ["83952.71000000", "0.00000000"], ["83952.66000000", "0.08000000"], ["83952.36000000", "0.00000000"], ["83952.35000000", "0.00000000"], ["83952.34000000", "0.00000000"], ["83952.33000000", "0.00000000"], ["83952.29000000", "0.00000000"], ["83952.28000000", "0.00000000"], ["83952.19000000", "0.00000000"], ["83952.17000000", "0.00000000"], ["83952.16000000", "0.20263000"], ["83952.00000000", "0.01410000"], ["83951.91000000", "0.00000000"], ["83951.71000000", "0.89392000"], ["83951.67000000", "0.00000000"], ["83951.63000000", "0.14570000"], ["83951.15000000", "0.04000000"], ["83951.13000000", "0.00000000"], ["83950.73000000", "0.16466000"], ["83950.56000000", "0.00000000"], ["83950.51000000", "0.11910000"], ["83950.45000000", "0.00000000"], ["83950.30000000", "0.04000000"], ["83950.29000000", "0.00000000"], ["83950.21000000", "0.02382000"], ["83950.20000000", "0.00000000"], ["83950.05000000", "0.00000000"], ["83950.00000000", "0.01410000"], ["83949.90000000", "0.00009000"], ["83949.84000000", "0.00000000"], ["83949.73000000", "0.00000000"], ["83949.72000000", "0.00000000"], ["83949.70000000", "0.00000000"], ["83949.61000000", "0.00029000"], ["83949.60000000", "0.00000000"], ["83949.59000000", "0.47675000"], ["83949.51000000", "0.02382000"], ["83949.49000000", "0.00000000"], ["83949.47000000", "0.04000000"], ["83949.46000000", "0.00000000"], ["83949.45000000", "0.00000000"], ["83949.19000000", "0.00000000"], ["83949.12000000", "0.00000000"], ["83949.10000000", "0.00000000"], ["83949.09000000", "0.00000000"], ["83949.02000000", "0.00000000"], ["83948.85000000", "0.00000000"], ["83948.79000000", "0.00000000"], ["83948.77000000", "0.04000000"], ["83948.76000000", "0.00000000"], ["83948.46000000", "0.00000000"], ["83948.40000000", "0.00000000"], ["83948.38000000", "0.00000000"], ["83948.01000000", "0.00500000"], ["83948.00000000", "0.01410000"], ["83947.99000000", "0.00000000"], ["83947.70000000", "0.00006000"], ["83947.59000000", "0.00500000"], ["83947.40000000", "0.00000000"], ["83947.39000000", "0.00000000"], ["83947.30000000", "0.00000000"], ["83946.80000000", "0.00000000"], ["83946.75000000", "0.04000000"], ["83946.67000000", "0.00000000"], ["83946.65000000", "0.81230000"], ["83946.64000000", "0.10810000"], ["83946.32000000", "0.00119000"], ["83946.30000000", "0.00000000"], ["83946.23000000", "0.00000000"], ["83946.12000000", "0.00000000"], ["83946.11000000", "0.00000000"], ["83946.10000000", "0.00000000"], ["83946.07000000", "0.01000000"], ["83946.04000000", "0.00000000"], ["83946.00000000", "0.01410000"], ["83945.85000000", "0.00000000"], ["83945.84000000", "0.00000000"], ["83945.83000000", "0.00000000"], ["83945.79000000", "0.05955000"], ["83945.76000000", "0.00000000"], ["83945.74000000", "0.35535000"], ["83945.68000000", "0.00013000"], ["83945.67000000", "0.00000000"], ["83945.66000000", "0.00000000"], ["83945.65000000", "0.03000000"], ["83945.64000000", "0.48346000"], ["83945.63000000", "0.00000000"], ["83945.62000000", "0.89392000"], ["83945.61000000", "0.00000000"], ["83945.60000000", "0.00000000"], ["83945.59000000", "0.00000000"], ["83945.58000000", "0.00000000"], ["83945.57000000", "0.00000000"], ["83945.56000000", "0.00000000"], ["83945.51000000", "0.00000000"], ["83945.42000000", "0.05959000"], ["83945.40000000", "0.00006000"], ["83944.93000000", "0.60904000"], ["83944.92000000", "0.89392000"], ["83944.78000000", "0.00000000"], ["83944.77000000", "0.00000000"], ["83944.76000000", "0.00000000"], ["83944.74000000", "0.00000000"], ["83944.67000000", "0.00000000"], ["83944.59000000", "0.00000000"], ["83944.52000000", "0.00000000"], ["83944.14000000", "0.00000000"], ["83944.00000000", "0.01410000"], ["83943.64000000", "0.01635000"], ["83943.60000000", "0.16000000"], ["83943.19000000", "0.00000000"], ["83943.18000000", "0.00000000"], ["83943.16000000", "0.00000000"], ["83943.04000000", "0.00000000"], ["83943.00000000", "0.00000000"], ["83942.91000000", "0.35756000"], ["83942.66000000", "0.00006000"], ["83942.58000000", "0.00000000"], ["83942.43000000", "0.00922000"], ["83942.18000000", "0.00000000"], ["83942.17000000", "0.00000000"], ["83942.05000000", "0.00000000"], ["83942.01000000", "0.00000000"], ["83941.84000000", "0.00000000"], ["83941.80000000", "0.00000000"], ["83941.50000000", "0.00009000"], ["83941.49000000", "0.00013000"], ["83941.22000000", "0.05959000"], ["83941.20000000", "0.00019000"], ["83941.19000000", "0.00414000"], ["83940.76000000", "0.00000000"], ["83940.73000000", "0.00000000"], ["83940.22000000", "0.00000000"], ["83939.75000000", "0.71131000"], ["83939.74000000", "0.47675000"], ["83939.47000000", "0.08992000"], ["83939.36000000", "0.00013000"], ["83939.12000000", "0.00000000"], ["83939.09000000", "0.00587000"], ["83939.01000000", "0.00359000"], ["83938.92000000", "0.89334000"], ["83938.91000000", "0.00000000"], ["83938.49000000", "0.00000000"], ["83938.35000000", "0.00000000"], ["83938.31000000", "0.04000000"], ["83938.17000000", "0.05955000"], ["83938.16000000", "0.00059000"], ["83937.67000000", "0.00000000"], ["83937.65000000", "0.00000000"], ["83937.49000000", "0.12135000"], ["83937.25000000", "0.00000000"], ["83937.24000000", "0.45000000"], ["83937.14000000", "0.00000000"], ["83937.01000000", "0.00000000"], ["83936.91000000", "0.00000000"], ["83936.89000000", "0.00000000"], ["83936.69000000", "0.00000000"], ["83936.56000000", "0.00000000"], ["83936.33000000", "0.02277000"], ["83936.26000000", "0.85820000"], ["83936.03000000", "0.00000000"], ["83936.00000000", "0.00000000"], ["83935.90000000", "0.04000000"], ["83935.69000000", "0.04743000"], ["83935.56000000", "0.54723000"], ["83935.55000000", "0.59594000"], ["83935.20000000", "0.00000000"], ["83935.19000000", "0.00000000"], ["83935.17000000", "0.00013000"], ["83934.71000000", "0.47675000"], ["83934.65000000", "0.00000000"], ["83934.51000000", "0.00000000"], ["83934.43000000", "0.00000000"], ["83934.26000000", "0.00000000"], ["83934.22000000", "0.04000000"], ["83933.97000000", "0.00000000"], ["83933.87000000", "0.00000000"], ["83933.67000000", "0.05955000"], ["83932.53000000", "0.00000000"], ["83932.17000000", "0.00000000"], ["83932.00000000", "0.00000000"], ["83931.98000000", "0.00000000"], ["83931.88000000", "0.00000000"], ["83931.61000000", "0.00029000"], ["83931.50000000", "0.00000000"], ["83931.41000000", "0.00000000"], ["83930.54000000", "0.00000000"], ["83930.44000000", "0.00000000"], ["83930.00000000", "0.00000000"], ["83929.77000000", "0.00059000"], ["83929.74000000", "0.59581000"], ["83929.73000000", "0.00000000"], ["83929.69000000", "0.89392000"], ["83929.49000000", "0.00000000"], ["83929.35000000", "0.00000000"], ["83928.97000000", "0.32061000"], ["83928.61000000", "0.00000000"], ["83928.52000000", "1.16888000"], ["83928.38000000", "0.08992000"], ["83928.21000000", "0.00000000"], ["83928.08000000", "0.00000000"], ["83928.00000000", "0.00000000"], ["83927.98000000", "0.00000000"], ["83927.66000000", "0.85829000"], ["83927.45000000", "0.00000000"], ["83927.35000000", "0.15717000"], ["83927.15000000", "0.39189000"], ["83926.54000000", "0.04515000"], ["83926.26000000", "0.00000000"], ["83926.00000000", "0.00000000"], ["83925.44000000", "0.00000000"], ["83925.43000000", "0.00000000"], ["83924.81000000", "0.00000000"], ["83924.35000000", "0.00000000"], ["83924.34000000", "0.00000000"], ["83924.31000000", "0.00000000"], ["83924.26000000", "0.00000000"], ["83923.72000000", "0.09228000"], ["83923.71000000", "0.26756000"], ["83922.58000000", "0.00000000"], ["83921.17000000", "0.00000000"], ["83920.61000000", "0.00000000"], ["83920.60000000", "0.00000000"], ["83920.45000000", "0.00000000"], ["83920.10000000", "0.65379000"], ["83919.63000000", "0.03346000"], ["83919.54000000", "0.00000000"], ["83918.89000000", "0.00000000"], ["83918.66000000", "0.00000000"], ["83918.50000000", "0.00000000"], ["83917.19000000", "0.05247000"], ["83916.58000000", "0.00000000"], ["83916.45000000", "0.04764000"], ["83916.44000000", "0.00000000"], ["83916.30000000", "0.00018000"], ["83916.07000000", "0.00000000"], ["83916.01000000", "0.04000000"], ["83915.99000000", "0.05958000"], ["83915.88000000", "0.34707000"], ["83915.66000000", "0.00358000"], ["83915.21000000", "0.00000000"], ["83915.20000000", "0.00000000"], ["83914.88000000", "0.00000000"], ["83914.37000000", "0.04000000"], ["83914.19000000", "0.00000000"], ["83913.92000000", "0.00000000"], ["83913.71000000", "0.00000000"], ["83913.14000000", "0.09528000"], ["83913.04000000", "0.08713000"], ["83912.68000000", "0.35756000"], ["83912.00000000", "0.04764000"], ["83911.99000000", "0.00000000"], ["83911.66000000", "0.00000000"], ["83911.65000000", "0.00000000"], ["83911.48000000", "0.04764000"], ["83911.47000000", "0.53183000"], ["83911.22000000", "0.00000000"], ["83910.89000000", "0.00000000"], ["83910.82000000", "0.08992000"], ["83910.40000000", "0.08764000"], ["83909.74000000", "0.00000000"], ["83909.73000000", "0.49764000"], ["83908.44000000", "0.00000000"], ["83907.73000000", "0.05497000"], ["83906.95000000", "0.10848000"], ["83906.62000000", "0.00000000"], ["83906.52000000", "0.00000000"], ["83905.85000000", "0.00000000"], ["83904.86000000", "0.05497000"], ["83904.85000000", "0.00000000"], ["83904.36000000", "0.00000000"], ["83903.62000000", "0.00000000"], ["83903.37000000", "0.00000000"], ["83903.09000000", "0.16091000"], ["83903.08000000", "0.00000000"], ["83903.07000000", "0.00000000"], ["83902.34000000", "0.00000000"], ["83902.13000000", "0.00000000"], ["83902.01000000", "0.10594000"], ["83901.39000000", "0.00815000"], ["83901.33000000", "0.41905000"], ["83901.15000000", "0.00000000"], ["83901.12000000", "0.00000000"], ["83901.09000000", "0.00000000"], ["83900.68000000", "0.05911000"], ["83900.50000000", "0.10594000"], ["83900.49000000", "0.05794000"], ["83900.48000000", "0.00000000"], ["83900.40000000", "0.05497000"], ["83899.34000000", "0.10994000"], ["83899.28000000", "0.00000000"], ["83899.19000000", "0.00000000"], ["83898.87000000", "0.00000000"], ["83898.06000000", "0.05097000"], ["83897.99000000", "0.05757000"], ["83897.86000000", "0.00000000"], ["83897.54000000", "0.05497000"], ["83897.45000000", "0.30812000"], ["83897.36000000", "0.01191000"], ["83896.80000000", "0.00000000"], ["83895.93000000", "0.16491000"], ["83895.65000000", "0.06797000"], ["83895.62000000", "0.21908000"], ["83895.04000000", "0.02848000"], ["83895.01000000", "0.10994000"], ["83895.00000000", "0.00006000"], ["83894.90000000", "0.00000000"], ["83894.71000000", "0.00000000"], ["83894.06000000", "0.05356000"], ["83893.53000000", "0.00000000"], ["83892.74000000", "0.02924000"], ["83892.36000000", "0.04398000"], ["83892.23000000", "0.00000000"], ["83891.16000000", "0.00000000"], ["83890.95000000", "0.00000000"], ["83890.64000000", "0.00847000"], ["83890.59000000", "0.04398000"], ["83890.58000000", "0.37574000"], ["83890.47000000", "0.00000000"], ["83890.08000000", "0.04645000"], ["83889.52000000", "0.24647000"], ["83889.06000000", "0.10000000"], ["83888.85000000", "0.09656000"], ["83888.61000000", "0.04897000"], ["83888.60000000", "0.44492000"], ["83888.53000000", "0.04645000"], ["83888.06000000", "0.04680000"], ["83888.05000000", "0.00007000"], ["83887.68000000", "0.04385000"], ["83886.82000000", "0.00000000"], ["83886.78000000", "0.04645000"], ["83886.11000000", "0.00000000"], ["83886.10000000", "0.00000000"], ["83885.90000000", "0.54602000"], ["83885.89000000", "0.00000000"], ["83884.79000000", "0.05284000"], ["83884.72000000", "0.49543000"], ["83884.68000000", "0.00000000"], ["83884.67000000", "0.20445000"], ["83883.95000000", "0.19037000"], ["83883.94000000", "0.00061000"], ["83883.39000000", "0.09895000"], ["83883.38000000", "0.00000000"], ["83882.38000000", "0.03575000"], ["83882.08000000", "0.00358000"], ["83882.00000000", "0.16571000"], ["83880.89000000", "1.03004000"], ["83880.78000000", "0.37627000"], ["83880.46000000", "0.00000000"], ["83880.43000000", "0.12800000"], ["83880.20000000", "0.00000000"], ["83879.92000000", "0.13940000"], ["83879.91000000", "0.00000000"], ["83879.56000000", "0.04645000"], ["83879.39000000", "0.09497000"], ["83878.95000000", "0.03194000"], ["83877.78000000", "0.18173000"], ["83877.65000000", "0.07623000"], ["83877.63000000", "0.26676000"], ["83877.45000000", "0.12899000"], ["83877.11000000", "0.04764000"], ["83877.10000000", "0.00000000"], ["83877.08000000", "0.04645000"], ["83877.07000000", "0.12900000"], ["83876.98000000", "0.00000000"], ["83876.79000000", "0.04645000"], ["83876.61000000", "0.04764000"], ["83876.51000000", "0.00000000"], ["83876.50000000", "0.45238000"], ["83875.87000000", "0.09409000"], ["83875.56000000", "0.00146000"], ["83874.06000000", "0.04764000"], ["83873.07000000", "0.30356000"], ["83873.06000000", "0.23463000"], ["83873.05000000", "0.00000000"], ["83872.30000000", "0.00000000"], ["83871.42000000", "0.18652000"], ["83871.36000000", "0.04764000"], ["83871.27000000", "0.00000000"], ["83870.95000000", "0.04764000"], ["83869.60000000", "0.30876000"], ["83869.56000000", "0.00000000"], ["83868.47000000", "0.25900000"], ["83868.46000000", "0.00000000"], ["83868.11000000", "0.59173000"], ["83868.07000000", "0.00000000"], ["83866.43000000", "0.00000000"], ["83866.40000000", "0.00000000"], ["83865.60000000", "0.00006000"], ["83865.49000000", "0.24029000"], ["83864.79000000", "0.14388000"], ["83863.57000000", "0.00000000"], ["83863.43000000", "0.00000000"], ["83863.02000000", "0.00000000"], ["83859.77000000", "0.00000000"], ["83858.89000000", "0.00000000"], ["83856.68000000", "0.00000000"], ["83856.30000000", "0.48772000"], ["83856.29000000", "1.07540000"], ["83855.57000000", "0.00000000"], ["83855.05000000", "0.00000000"], ["83853.00000000", "0.35582000"], ["83851.08000000", "0.00000000"], ["83850.85000000", "0.00000000"], ["83849.64000000", "0.00000000"], ["83848.32000000", "0.71486000"], ["83846.84000000", "0.19473000"], ["83845.01000000", "0.00000000"], ["83844.99000000", "0.00000000"], ["83844.48000000", "0.00000000"], ["83844.36000000", "0.40363000"], ["83843.49000000", "0.00400000"], ["83841.56000000", "0.00000000"], ["83841.34000000", "0.09044000"], ["83840.89000000", "0.04765000"], ["83839.22000000", "0.11171000"], ["83838.75000000", "0.00000000"], ["83837.95000000", "0.22820000"], ["83837.89000000", "0.00000000"], ["83835.72000000", "0.09395000"], ["83831.48000000", "0.88042000"], ["83830.14000000", "0.04765000"], ["83829.37000000", "0.00000000"], ["83826.08000000", "0.14538000"], ["83825.22000000", "0.10943000"], ["83824.01000000", "0.10594000"], ["83823.40000000", "1.10673000"], ["83823.06000000", "0.54412000"], ["83822.94000000", "2.14312000"], ["83821.98000000", "0.00000000"], ["83820.54000000", "0.00000000"], ["83820.45000000", "0.05497000"], ["83820.26000000", "0.04765000"], ["83819.45000000", "0.03551000"], ["83818.22000000", "0.00000000"], ["83816.00000000", "0.00235000"], ["83815.22000000", "0.00000000"], ["83814.86000000", "0.00000000"], ["83814.56000000", "0.00000000"], ["83814.18000000", "0.00000000"], ["83813.25000000", "0.83006000"], ["83812.89000000", "0.00000000"], ["83812.88000000", "0.00000000"], ["83812.50000000", "0.00818000"], ["83812.12000000", "0.00000000"], ["83811.87000000", "0.00000000"], ["83811.61000000", "0.21457000"], ["83811.00000000", "0.15398000"], ["83810.23000000", "0.48502000"], ["83808.43000000", "0.00000000"], ["83808.00000000", "0.00235000"], ["83807.31000000", "0.00000000"], ["83806.90000000", "0.00000000"], ["83806.17000000", "0.00000000"], ["83806.10000000", "0.00000000"], ["83805.74000000", "0.00000000"], ["83804.97000000", "0.00000000"], ["83804.18000000", "0.00306000"], ["83800.73000000", "0.00000000"], ["83800.53000000", "0.71486000"], ["83800.33000000", "0.00000000"], ["83800.04000000", "0.00000000"], ["83800.03000000", "0.00000000"], ["83800.01000000", "0.00000000"], ["83799.74000000", "0.00000000"], ["83799.41000000", "0.00000000"], ["83799.25000000", "0.00000000"], ["83799.01000000", "0.00000000"], ["83798.36000000", "0.00000000"], ["83798.15000000", "0.99320000"], ["83798.08000000", "0.00000000"], ["83797.71000000", "0.00000000"], ["83796.98000000", "0.00000000"], ["83796.74000000", "0.00000000"], ["83796.62000000", "0.00013000"], ["83796.56000000", "0.00000000"], ["83796.54000000", "0.01000000"], ["83796.45000000", "0.01193000"], ["83796.21000000", "0.00000000"], ["83795.94000000", "0.00000000"], ["83795.32000000", "0.00000000"], ["83793.10000000", "0.00112000"], ["83792.37000000", "0.04897000"], ["83791.98000000", "0.00000000"], ["83791.95000000", "0.00000000"], ["83791.63000000", "0.00000000"], ["83791.49000000", "0.00000000"], ["83790.45000000", "0.71486000"], ["83789.91000000", "0.00000000"], ["83789.57000000", "0.00000000"], ["83789.56000000", "0.00000000"], ["83789.45000000", "0.00000000"], ["83789.19000000", "0.00000000"], ["83789.13000000", "0.00000000"], ["83788.64000000", "0.00000000"], ["83788.16000000", "0.00000000"], ["83788.15000000", "0.15717000"], ["83787.81000000", "0.00000000"], ["83787.64000000", "0.00000000"], ["83787.40000000", "0.00000000"], ["83787.09000000", "0.00000000"], ["83787.00000000", "0.00000000"], ["83786.54000000", "0.00000000"], ["83786.49000000", "0.00000000"], ["83786.11000000", "0.00000000"], ["83786.04000000", "0.02384000"], ["83784.87000000", "0.00000000"], ["83784.80000000", "0.00000000"], ["83784.47000000", "0.00000000"], ["83784.09000000", "0.71486000"], ["83784.08000000", "0.00000000"], ["83783.75000000", "0.00000000"], ["83783.20000000", "0.00000000"], ["83782.88000000", "0.00000000"], ["83782.58000000", "0.00000000"], ["83782.26000000", "0.00000000"], ["83782.07000000", "0.00000000"], ["83781.90000000", "0.00000000"], ["83780.20000000", "0.00000000"], ["83779.76000000", "0.15717000"], ["83779.69000000", "0.00000000"], ["83779.50000000", "0.00000000"], ["83777.26000000", "0.00000000"], ["83777.19000000", "0.00000000"], ["83775.45000000", "0.00000000"], ["83774.01000000", "0.71499000"], ["83773.70000000", "0.00000000"], ["83773.28000000", "0.00000000"], ["83772.74000000", "0.00000000"], ["83771.37000000", "0.15831000"], ["83770.45000000", "0.00000000"], ["83769.28000000", "0.00000000"], ["83765.67000000", "0.00000000"], ["83765.22000000", "0.00000000"], ["83764.18000000", "0.00000000"], ["83763.93000000", "0.71486000"], ["83762.98000000", "0.15831000"], ["83758.33000000", "0.00000000"], ["83758.22000000", "0.00000000"], ["83757.81000000", "0.00000000"], ["83754.59000000", "0.15831000"], ["83753.85000000", "0.71486000"], ["83751.76000000", "0.00000000"], ["83750.43000000", "0.00000000"], ["83747.44000000", "0.00000000"], ["83746.20000000", "0.15831000"], ["83742.04000000", "0.00000000"], ["83737.81000000", "0.14670000"], ["83736.72000000", "0.01786000"], ["83727.71000000", "0.00000000"], ["83706.14000000", "0.00000000"], ["83689.35000000", "0.00000000"], ["83687.83000000", "0.00000000"], ["83672.57000000", "0.00000000"], ["83655.76000000", "0.28862000"], ["83614.12000000", "0.03805000"], ["83592.54000000", "0.35117000"], ["83590.77000000", "0.00007000"], ["83555.84000000", "0.00000000"], ["83536.47000000", "0.00000000"], ["83526.10000000", "0.00283000"], ["83456.85000000", "1.60000000"], ["83440.37000000", "0.00000000"], ["83405.24000000", "0.00000000"], ["82942.19000000", "0.00000000"], ["82686.45000000", "0.00000000"], ["75551.00000000", "0.10027000"], ["67166.58000000", "0.00058000"], ["67156.52000000", "0.00000000"], ["42028.45000000", "0.00000000"], ["42014.15000000", "0.00000000"], ["41979.11000000", "0.00162000"], ["41935.60000000", "0.00054000"], ["33000.00000000", "2.96666000"]], "a": [["83945.65000000", "0.00000000"], ["83945.66000000", "0.00000000"], ["83945.67000000", "0.00000000"], ["83945.68000000", "0.00000000"], ["83945.84000000", "0.00000000"], ["83945.86000000", "0.00000000"], ["83946.12000000", "0.00000000"], ["83946.13000000", "0.00000000"], ["83946.31000000", "0.00000000"], ["83947.32000000", "0.00000000"], ["83947.72000000", "0.00000000"], ["83947.99000000", "0.00000000"], ["83948.00000000", "0.00000000"], ["83948.48000000", "0.00000000"], ["83949.13000000", "0.00000000"], ["83949.20000000", "0.00000000"], ["83949.46000000", "0.00000000"], ["83949.57000000", "0.00000000"], ["83949.60000000", "0.00000000"], ["83949.61000000", "0.00000000"], ["83949.80000000", "0.00000000"], ["83950.00000000", "0.00000000"], ["83950.17000000", "0.00000000"], ["83951.14000000", "0.00000000"], ["83951.17000000", "0.00000000"], ["83951.53000000", "0.00000000"], ["83951.67000000", "0.00000000"], ["83951.87000000", "0.00000000"], ["83952.00000000", "0.00000000"], ["83952.03000000", "0.00000000"], ["83952.17000000", "0.00000000"], ["83952.29000000", "0.00000000"], ["83952.34000000", "0.00000000"], ["83952.35000000", "0.00000000"], ["83952.36000000", "0.00000000"], ["83952.72000000", "0.00000000"], ["83952.79000000", "0.00000000"], ["83952.80000000", "0.00000000"], ["83952.86000000", "0.00000000"], ["83953.07000000", "0.00000000"], ["83953.27000000", "0.00000000"], ["83953.69000000", "0.00000000"], ["83953.80000000", "0.00000000"], ["83953.97000000", "0.00000000"], ["83954.04000000", "0.00000000"], ["83954.05000000", "0.00000000"], ["83954.08000000", "0.00000000"], ["83954.45000000", "0.00000000"], ["83954.46000000", "0.00000000"], ["83954.57000000", "0.00000000"], ["83954.77000000", "0.00000000"], ["83954.91000000", "0.00000000"], ["83954.96000000", "0.00000000"], ["83954.99000000", "0.00000000"], ["83955.01000000", "0.00000000"], ["83955.77000000", "0.00000000"], ["83955.78000000", "0.00000000"], ["83955.79000000", "0.00000000"], ["83955.85000000", "0.00000000"], ["83955.89000000", "0.00000000"], ["83956.00000000", "0.00000000"], ["83956.14000000", "0.00000000"], ["83956.15000000", "0.00000000"], ["83956.16000000", "0.00000000"], ["83956.57000000", "0.00000000"], ["83956.68000000", "0.00000000"], ["83956.99000000", "0.00000000"], ["83957.68000000", "0.00000000"], ["83957.71000000", "0.00000000"], ["83957.76000000", "0.00000000"], ["83958.00000000", "0.00000000"], ["83958.03000000", "0.00000000"], ["83958.21000000", "0.00000000"], ["83958.23000000", "2.65454000"], ["83958.24000000", "0.00111000"], ["83958.39000000", "0.00007000"], ["83958.40000000", "0.00007000"], ["83958.41000000", "0.00007000"], ["83958.59000000", "0.00021000"], ["83958.60000000", "0.00365000"], ["83958.61000000", "0.00007000"], ["83958.67000000", "0.00000000"], ["83959.00000000", "0.00000000"], ["83959.03000000", "0.00000000"], ["83959.04000000", "0.00000000"], ["83959.11000000", "0.00000000"], ["83959.12000000", "0.00000000"], ["83959.17000000", "0.00067000"], ["83959.19000000", "0.00000000"], ["83959.20000000", "0.00000000"], ["83959.21000000", "0.00000000"], ["83959.22000000", "0.00000000"], ["83959.38000000", "0.00000000"], ["83959.39000000", "0.00000000"], ["83959.53000000", "0.00014000"], ["83959.54000000", "0.14644000"], ["83959.70000000", "0.00000000"], ["83959.98000000", "0.00041000"], ["83959.99000000", "0.08155000"], ["83960.00000000", "0.02598000"], ["83960.04000000", "0.00000000"], ["83960.05000000", "0.00000000"], ["83960.24000000", "0.00000000"], ["83960.29000000", "0.00000000"], ["83960.33000000", "0.00000000"], ["83960.45000000", "0.00000000"], ["83960.50000000", "0.00000000"], ["83960.54000000", "0.00007000"], ["83960.72000000", "0.00000000"], ["83960.83000000", "0.00000000"], ["83960.88000000", "0.00018000"], ["83960.89000000", "0.00000000"], ["83961.17000000", "0.00000000"], ["83961.18000000", "0.00000000"], ["83961.43000000", "0.00000000"], ["83961.44000000", "0.00000000"], ["83961.52000000", "0.00006000"], ["83961.53000000", "0.00000000"], ["83961.70000000", "0.00000000"], ["83961.79000000", "0.00000000"], ["83961.90000000", "0.00000000"], ["83961.91000000", "0.05295000"], ["83961.98000000", "0.00000000"], ["83961.99000000", "0.02292000"], ["83962.00000000", "0.01410000"], ["83962.10000000", "0.00000000"], ["83962.11000000", "0.00000000"], ["83962.20000000", "0.00000000"], ["83962.24000000", "0.00000000"], ["83962.25000000", "0.00000000"], ["83962.33000000", "0.00408000"], ["83962.40000000", "0.00500000"], ["83962.47000000", "0.00000000"], ["83962.48000000", "0.00000000"], ["83962.55000000", "0.00000000"], ["83962.56000000", "0.00000000"], ["83962.88000000", "0.00000000"], ["83962.89000000", "0.00000000"], ["83962.90000000", "0.00000000"], ["83962.93000000", "0.00000000"], ["83962.94000000", "0.05700000"], ["83962.95000000", "0.14023000"], ["83963.26000000", "0.00000000"], ["83963.31000000", "0.00000000"], ["83963.32000000", "0.00000000"], ["83963.38000000", "0.00000000"], ["83964.00000000", "0.01620000"], ["83964.22000000", "0.00000000"], ["83964.39000000", "0.00000000"], ["83964.50000000", "0.00000000"], ["83964.55000000", "0.00000000"], ["83964.89000000", "0.00000000"], ["83964.92000000", "0.00000000"], ["83964.94000000", "0.00000000"], ["83964.96000000", "0.00000000"], ["83964.97000000", "0.00000000"], ["83965.06000000", "0.00000000"], ["83965.15000000", "0.00000000"], ["83965.40000000", "0.03000000"], ["83965.68000000", "0.00000000"], ["83965.81000000", "0.00000000"], ["83965.82000000", "0.00000000"], ["83966.02000000", "0.00000000"], ["83966.04000000", "0.00000000"], ["83966.05000000", "0.00000000"], ["83966.06000000", "0.00000000"], ["83966.22000000", "0.00000000"], ["83966.40000000", "0.00019000"], ["83966.44000000", "0.00029000"], ["83966.54000000", "0.00000000"], ["83966.55000000", "0.00000000"], ["83966.62000000", "0.13661000"], ["83966.63000000", "0.45000000"], ["83966.90000000", "0.00000000"], ["83967.42000000", "0.00000000"], ["83967.58000000", "0.00000000"], ["83968.05000000", "0.00000000"], ["83968.11000000", "0.00000000"], ["83968.32000000", "0.00000000"], ["83968.57000000", "0.00000000"], ["83968.67000000", "0.00000000"], ["83968.71000000", "0.00013000"], ["83968.75000000", "0.00000000"], ["83968.98000000", "0.00000000"], ["83970.43000000", "0.00000000"], ["83970.52000000", "0.00000000"], ["83970.81000000", "0.00808000"], ["83970.88000000", "0.00000000"], ["83970.97000000", "0.00000000"], ["83970.98000000", "0.00000000"], ["83970.99000000", "0.00000000"], ["83971.06000000", "0.00000000"], ["83971.07000000", "0.00000000"], ["83971.11000000", "0.00000000"], ["83971.33000000", "0.00000000"], ["83971.39000000", "0.06800000"], ["83971.61000000", "0.00000000"], ["83971.66000000", "0.00000000"], ["83971.67000000", "0.00000000"], ["83971.98000000", "0.00000000"], ["83972.04000000", "0.02336000"], ["83972.06000000", "0.00000000"], ["83972.25000000", "0.06000000"], ["83972.59000000", "0.23611000"], ["83972.60000000", "0.71486000"], ["83972.78000000", "0.00000000"], ["83972.79000000", "0.00000000"], ["83972.84000000", "0.00000000"], ["83972.90000000", "0.00013000"], ["83973.07000000", "0.00000000"], ["83973.21000000", "0.00000000"], ["83973.47000000", "0.00000000"], ["83973.76000000", "0.00000000"], ["83973.96000000", "0.00000000"], ["83973.98000000", "0.00000000"], ["83973.99000000", "0.06000000"], ["83974.08000000", "0.00000000"], ["83974.42000000", "0.00000000"], ["83974.48000000", "0.00000000"], ["83974.66000000", "0.00000000"], ["83974.78000000", "0.01191000"], ["83974.79000000", "0.00000000"], ["83974.98000000", "0.00000000"], ["83975.02000000", "0.67207000"], ["83975.03000000", "0.45000000"], ["83975.04000000", "0.00000000"], ["83975.06000000", "0.35756000"], ["83975.09000000", "0.00000000"], ["83975.60000000", "0.00000000"], ["83975.61000000", "0.00000000"], ["83975.62000000", "0.15937000"], ["83975.66000000", "0.00000000"], ["83975.67000000", "0.00000000"], ["83975.90000000", "0.14000000"], ["83976.10000000", "0.00000000"], ["83976.44000000", "0.05600000"], ["83976.85000000", "0.33052000"], ["83976.96000000", "0.05600000"], ["83977.09000000", "0.00013000"], ["83977.12000000", "0.00000000"], ["83977.22000000", "0.00000000"], ["83977.23000000", "0.00000000"], ["83977.35000000", "0.00000000"], ["83977.54000000", "0.00000000"], ["83977.60000000", "0.00000000"], ["83977.64000000", "0.71486000"], ["83977.95000000", "0.00000000"], ["83978.13000000", "0.04400000"], ["83978.19000000", "0.06000000"], ["83978.48000000", "0.17899000"], ["83978.56000000", "0.00000000"], ["83978.64000000", "0.00000000"], ["83978.72000000", "0.00000000"], ["83979.01000000", "0.11918000"], ["83979.28000000", "0.00009000"], ["83979.37000000", "0.00000000"], ["83979.72000000", "0.00000000"], ["83979.73000000", "0.00000000"], ["83979.74000000", "0.00000000"], ["83979.76000000", "0.00000000"], ["83979.77000000", "0.00000000"], ["83979.87000000", "0.00000000"], ["83979.94000000", "0.00000000"], ["83980.01000000", "0.00000000"], ["83980.63000000", "0.00000000"], ["83980.64000000", "0.00000000"], ["83980.67000000", "0.00000000"], ["83980.96000000", "0.00000000"], ["83981.00000000", "0.50714000"], ["83981.01000000", "0.47675000"], ["83981.15000000", "0.00100000"], ["83981.22000000", "0.00000000"], ["83981.28000000", "0.00013000"], ["83981.29000000", "0.00000000"], ["83981.76000000", "0.00000000"], ["83982.46000000", "0.16000000"], ["83982.56000000", "0.00000000"], ["83982.74000000", "0.00000000"], ["83982.84000000", "0.00000000"], ["83982.86000000", "0.08354000"], ["83982.89000000", "0.00000000"], ["83982.99000000", "0.71486000"], ["83983.16000000", "0.00000000"], ["83983.17000000", "0.04000000"], ["83983.21000000", "0.62482000"], ["83983.22000000", "0.89392000"], ["83983.26000000", "0.00000000"], ["83983.27000000", "0.00000000"], ["83983.49000000", "0.00000000"], ["83983.68000000", "0.00000000"], ["83983.98000000", "0.00000000"], ["83983.99000000", "0.00000000"], ["83984.08000000", "0.35756000"], ["83984.12000000", "0.00000000"], ["83984.17000000", "0.00000000"], ["83984.21000000", "0.00000000"], ["83984.44000000", "0.00000000"], ["83984.67000000", "0.00119000"], ["83985.07000000", "0.00000000"], ["83985.20000000", "0.00000000"], ["83985.46000000", "0.00000000"], ["83985.47000000", "0.00013000"], ["83985.57000000", "0.00000000"], ["83985.67000000", "0.16069000"], ["83985.68000000", "0.58816000"], ["83986.01000000", "0.00000000"], ["83986.26000000", "0.00000000"], ["83986.29000000", "0.00000000"], ["83986.30000000", "0.00000000"], ["83986.49000000", "0.00000000"], ["83986.76000000", "0.00000000"], ["83987.08000000", "0.00000000"], ["83987.37000000", "0.10810000"], ["83988.09000000", "0.79698000"], ["83988.10000000", "0.71486000"], ["83988.69000000", "0.00000000"], ["83988.70000000", "0.00000000"], ["83988.94000000", "0.00000000"], ["83989.60000000", "0.00000000"], ["83989.82000000", "0.00000000"], ["83989.85000000", "0.89392000"], ["83990.14000000", "0.00000000"], ["83990.58000000", "0.00000000"], ["83990.88000000", "1.43079000"], ["83991.05000000", "0.00100000"], ["83991.10000000", "0.59579000"], ["83991.11000000", "0.00000000"], ["83991.98000000", "0.00000000"], ["83992.09000000", "0.00000000"], ["83992.50000000", "0.86310000"], ["83992.51000000", "0.89392000"], ["83992.83000000", "0.00000000"], ["83993.16000000", "0.71486000"], ["83993.25000000", "0.00000000"], ["83993.32000000", "0.89392000"], ["83993.73000000", "0.00000000"], ["83993.92000000", "0.00000000"], ["83994.07000000", "0.15717000"], ["83994.36000000", "0.00000000"], ["83995.38000000", "0.00000000"], ["83995.39000000", "0.00000000"], ["83995.56000000", "0.00000000"], ["83995.95000000", "0.00000000"], ["83996.18000000", "0.00351000"], ["83996.35000000", "1.55425000"], ["83996.61000000", "0.89392000"], ["83996.86000000", "0.89392000"], ["83996.95000000", "0.00000000"], ["83997.20000000", "0.00000000"], ["83997.34000000", "0.89392000"], ["83997.89000000", "0.00000000"], ["83998.37000000", "0.00000000"], ["83998.38000000", "0.00000000"], ["83998.45000000", "0.00000000"], ["83998.50000000", "0.89392000"], ["83998.65000000", "0.00000000"], ["83998.88000000", "0.03979000"], ["83998.92000000", "0.00000000"], ["83999.17000000", "0.86969000"], ["83999.53000000", "0.00100000"], ["83999.61000000", "0.00000000"], ["83999.64000000", "0.00000000"], ["84000.80000000", "0.32735000"], ["84001.27000000", "0.00016000"], ["84002.45000000", "0.15717000"], ["84002.59000000", "0.00582000"], ["84002.70000000", "0.02808000"], ["84002.91000000", "0.00000000"], ["84003.24000000", "0.71486000"], ["84003.25000000", "0.00000000"], ["84003.49000000", "0.02118000"], ["84003.91000000", "0.00000000"], ["84004.15000000", "0.85751000"], ["84004.20000000", "0.00006000"], ["84004.21000000", "0.66973000"], ["84004.35000000", "0.01190000"], ["84004.72000000", "0.89392000"], ["84005.12000000", "0.06000000"], ["84005.34000000", "0.00000000"], ["84006.32000000", "0.00000000"], ["84006.37000000", "0.00814000"], ["84006.50000000", "0.34274000"], ["84006.56000000", "0.00360000"], ["84007.80000000", "0.12104000"], ["84008.35000000", "0.39035000"], ["84008.43000000", "0.74043000"], ["84008.67000000", "0.02859000"], ["84009.42000000", "0.00000000"], ["84009.44000000", "0.00000000"], ["84009.45000000", "0.00000000"], ["84009.88000000", "0.85745000"], ["84010.09000000", "0.89392000"], ["84010.10000000", "0.00000000"], ["84010.17000000", "0.00000000"], ["84010.66000000", "0.00000000"], ["84010.85000000", "0.15831000"], ["84011.28000000", "0.01196000"], ["84011.46000000", "0.00000000"], ["84011.52000000", "0.00119000"], ["84012.30000000", "0.00000000"], ["84012.31000000", "0.00000000"], ["84012.49000000", "0.00000000"], ["84012.57000000", "0.00000000"], ["84012.60000000", "0.00000000"], ["84012.97000000", "0.00000000"], ["84013.12000000", "0.00000000"], ["84013.38000000", "0.00000000"], ["84013.69000000", "0.00000000"], ["84014.01000000", "0.00856000"], ["84014.57000000", "0.00000000"], ["84014.58000000", "0.00000000"], ["84014.65000000", "0.00000000"], ["84014.71000000", "0.03533000"], ["84015.00000000", "0.00000000"], ["84015.02000000", "0.47675000"], ["84015.39000000", "0.00000000"], ["84015.40000000", "0.00000000"], ["84015.71000000", "0.00000000"], ["84015.81000000", "0.00000000"], ["84015.88000000", "0.00510000"], ["84016.06000000", "0.00808000"], ["84016.21000000", "0.00000000"], ["84016.89000000", "0.00000000"], ["84016.91000000", "0.00000000"], ["84016.92000000", "0.00000000"], ["84016.93000000", "0.00000000"], ["84016.96000000", "0.00000000"], ["84017.11000000", "0.00000000"], ["84017.48000000", "0.00000000"], ["84017.90000000", "0.00000000"], ["84017.91000000", "0.00000000"], ["84018.24000000", "0.00000000"], ["84018.35000000", "0.37513000"], ["84018.36000000", "0.71486000"], ["84018.48000000", "0.00000000"], ["84018.51000000", "0.00013000"], ["84018.59000000", "0.37751000"], ["84018.69000000", "0.04110000"], ["84018.83000000", "0.00000000"], ["84018.86000000", "0.00000000"], ["84018.91000000", "0.00000000"], ["84019.17000000", "0.00000000"], ["84019.32000000", "0.00000000"], ["84019.47000000", "0.05391000"], ["84019.82000000", "0.00000000"], ["84020.13000000", "0.08400000"], ["84020.21000000", "0.00000000"], ["84020.38000000", "0.00000000"], ["84020.39000000", "0.00000000"], ["84020.46000000", "0.00000000"], ["84020.63000000", "0.00000000"], ["84020.64000000", "0.00000000"], ["84020.71000000", "0.00000000"], ["84020.90000000", "0.00000000"], ["84020.94000000", "0.00013000"], ["84020.96000000", "0.06000000"], ["84021.09000000", "0.00000000"], ["84021.68000000", "0.00000000"], ["84021.73000000", "0.00000000"], ["84021.82000000", "0.06000000"], ["84021.92000000", "0.00000000"], ["84021.94000000", "0.00000000"], ["84022.13000000", "0.00000000"], ["84022.17000000", "0.00000000"], ["84022.21000000", "0.00000000"], ["84022.27000000", "0.00000000"], ["84022.52000000", "0.00000000"], ["84022.98000000", "0.00000000"], ["84023.10000000", "0.00821000"], ["84023.13000000", "0.00000000"], ["84023.20000000", "0.00000000"], ["84023.92000000", "0.04646000"], ["84023.98000000", "0.00000000"], ["84024.08000000", "0.00000000"], ["84024.28000000", "0.00000000"], ["84024.34000000", "0.00000000"], ["84024.39000000", "0.00000000"], ["84024.52000000", "0.00000000"], ["84024.93000000", "0.00000000"], ["84025.16000000", "0.00000000"], ["84025.26000000", "0.00000000"], ["84025.50000000", "0.00000000"], ["84025.69000000", "0.00000000"], ["84026.00000000", "0.04400000"], ["84026.13000000", "0.06000000"], ["84026.31000000", "0.55299000"], ["84026.57000000", "0.00000000"], ["84026.63000000", "0.00000000"], ["84027.00000000", "0.00000000"], ["84027.28000000", "0.02016000"], ["84027.46000000", "0.06000000"], ["84027.47000000", "0.00000000"], ["84027.52000000", "0.00000000"], ["84027.64000000", "0.00000000"], ["84027.84000000", "0.00000000"], ["84027.86000000", "0.00000000"], ["84027.90000000", "0.00000000"], ["84028.26000000", "0.00000000"], ["84028.39000000", "0.00000000"], ["84028.73000000", "0.00000000"], ["84029.57000000", "0.00000000"], ["84029.62000000", "0.00000000"], ["84030.05000000", "0.00000000"], ["84030.08000000", "0.04646000"], ["84030.09000000", "0.00000000"], ["84030.32000000", "0.00000000"], ["84030.50000000", "0.00000000"], ["84030.94000000", "0.28588000"], ["84032.02000000", "0.00000000"], ["84032.03000000", "0.00000000"], ["84032.75000000", "0.00000000"], ["84032.87000000", "0.02794000"], ["84033.29000000", "0.00000000"], ["84033.64000000", "0.99362000"], ["84033.74000000", "0.00000000"], ["84034.16000000", "0.04645000"], ["84034.17000000", "0.00000000"], ["84034.61000000", "0.00000000"], ["84034.85000000", "0.00000000"], ["84034.93000000", "0.09165000"], ["84035.00000000", "1.02815000"], ["84035.17000000", "0.00000000"], ["84035.18000000", "0.00143000"], ["84035.26000000", "0.05497000"], ["84035.37000000", "0.03856000"], ["84035.67000000", "0.04646000"], ["84036.38000000", "0.04764000"], ["84036.60000000", "0.00000000"], ["84037.32000000", "0.10142000"], ["84037.39000000", "0.00000000"], ["84037.43000000", "0.11446000"], ["84037.86000000", "0.00000000"], ["84037.92000000", "0.00000000"], ["84038.00000000", "0.05600000"], ["84038.09000000", "0.04764000"], ["84038.29000000", "0.00000000"], ["84038.42000000", "0.67987000"], ["84038.71000000", "0.09943000"], ["84038.81000000", "0.00000000"], ["84039.03000000", "0.05497000"], ["84039.10000000", "0.04764000"], ["84039.38000000", "0.00000000"], ["84039.39000000", "0.04765000"], ["84039.54000000", "0.00058000"], ["84039.76000000", "0.00000000"], ["84039.84000000", "0.00000000"], ["84039.87000000", "0.00013000"], ["84039.95000000", "0.00000000"], ["84040.08000000", "0.04645000"], ["84040.39000000", "0.04765000"], ["84040.49000000", "0.00000000"], ["84040.50000000", "0.00000000"], ["84040.75000000", "0.00000000"], ["84041.09000000", "0.00000000"], ["84041.27000000", "0.04764000"], ["84041.81000000", "0.05497000"], ["84042.06000000", "0.00000000"], ["84042.21000000", "0.00000000"], ["84042.45000000", "0.00000000"], ["84042.55000000", "0.00000000"], ["84042.76000000", "0.76385000"], ["84042.78000000", "0.00000000"], ["84042.88000000", "0.00000000"], ["84043.06000000", "0.00000000"], ["84043.12000000", "0.00000000"], ["84043.15000000", "0.09638000"], ["84043.34000000", "0.00000000"], ["84043.37000000", "0.05497000"], ["84043.73000000", "0.00000000"], ["84043.75000000", "0.00000000"], ["84043.86000000", "0.04898000"], ["84043.89000000", "0.00000000"], ["84044.11000000", "0.00000000"], ["84044.22000000", "0.00000000"], ["84044.25000000", "0.04764000"], ["84044.46000000", "0.03175000"], ["84044.50000000", "0.43774000"], ["84044.52000000", "0.00297000"], ["84044.53000000", "0.05014000"], ["84044.76000000", "0.00000000"], ["84044.77000000", "0.05221000"], ["84044.97000000", "0.00000000"], ["84045.01000000", "0.00000000"], ["84045.50000000", "0.00000000"], ["84045.59000000", "0.00000000"], ["84045.60000000", "0.04764000"], ["84045.61000000", "0.05497000"], ["84045.62000000", "0.00000000"], ["84045.80000000", "0.00000000"], ["84045.83000000", "0.00000000"], ["84045.95000000", "0.00000000"], ["84046.17000000", "0.04765000"], ["84046.20000000", "0.00000000"], ["84046.34000000", "0.00000000"], ["84046.35000000", "0.04645000"], ["84046.37000000", "0.00000000"], ["84046.48000000", "0.00018000"], ["84046.51000000", "0.04764000"], ["84046.98000000", "0.00000000"], ["84047.07000000", "0.00000000"], ["84047.20000000", "0.00000000"], ["84047.27000000", "0.00000000"], ["84047.30000000", "0.00000000"], ["84047.58000000", "0.00000000"], ["84047.64000000", "0.00000000"], ["84047.65000000", "0.04764000"], ["84047.67000000", "0.00000000"], ["84048.03000000", "0.04645000"], ["84048.08000000", "0.00000000"], ["84048.17000000", "0.00000000"], ["84048.20000000", "0.00000000"], ["84048.34000000", "0.00000000"], ["84048.48000000", "0.04770000"], ["84048.55000000", "0.00000000"], ["84048.67000000", "0.05497000"], ["84048.69000000", "0.20569000"], ["84048.84000000", "0.00000000"], ["84048.88000000", "0.05497000"], ["84049.06000000", "0.04658000"], ["84049.11000000", "0.00000000"], ["84049.19000000", "0.00000000"], ["84049.51000000", "0.00000000"], ["84049.63000000", "0.00000000"], ["84049.84000000", "0.00000000"], ["84050.13000000", "0.04764000"], ["84050.62000000", "0.04764000"], ["84050.71000000", "0.53646000"], ["84051.13000000", "0.04645000"], ["84051.18000000", "0.00000000"], ["84051.47000000", "0.00297000"], ["84051.48000000", "0.00000000"], ["84051.52000000", "0.00000000"], ["84051.86000000", "0.00000000"], ["84052.22000000", "0.00000000"], ["84052.31000000", "0.00000000"], ["84052.51000000", "0.04764000"], ["84052.59000000", "0.04764000"], ["84052.81000000", "0.00000000"], ["84052.85000000", "0.71486000"], ["84053.37000000", "0.00000000"], ["84053.47000000", "0.05497000"], ["84053.57000000", "0.04645000"], ["84053.92000000", "0.05497000"], ["84054.59000000", "0.00000000"], ["84054.88000000", "0.05106000"], ["84054.95000000", "0.05497000"], ["84055.22000000", "0.04764000"], ["84055.28000000", "0.00000000"], ["84055.43000000", "0.51737000"], ["84055.85000000", "0.00000000"], ["84055.91000000", "0.00000000"], ["84056.67000000", "0.00013000"], ["84056.78000000", "0.00000000"], ["84056.85000000", "0.05497000"], ["84056.99000000", "0.00000000"], ["84058.21000000", "0.00000000"], ["84058.44000000", "0.05497000"], ["84058.50000000", "0.05497000"], ["84059.47000000", "0.00000000"], ["84059.74000000", "0.05497000"], ["84059.99000000", "0.52464000"], ["84060.78000000", "0.05497000"], ["84060.94000000", "0.00000000"], ["84061.50000000", "0.00000000"], ["84061.54000000", "0.05497000"], ["84061.58000000", "0.71486000"], ["84061.66000000", "0.00000000"], ["84061.68000000", "0.00000000"], ["84061.74000000", "0.00000000"], ["84061.86000000", "0.00000000"], ["84062.05000000", "0.05097000"], ["84063.28000000", "0.00009000"], ["84064.02000000", "0.05497000"], ["84064.12000000", "0.50860000"], ["84065.63000000", "0.00000000"], ["84066.02000000", "0.12900000"], ["84066.40000000", "0.12899000"], ["84067.09000000", "0.00000000"], ["84067.10000000", "0.05097000"], ["84067.30000000", "0.04645000"], ["84067.61000000", "0.29314000"], ["84067.62000000", "0.05497000"], ["84067.78000000", "0.05497000"], ["84068.38000000", "0.00000000"], ["84068.45000000", "0.00000000"], ["84068.68000000", "0.05097000"], ["84069.01000000", "0.00000000"], ["84070.56000000", "0.04645000"], ["84071.48000000", "0.04645000"], ["84071.56000000", "0.00178000"], ["84071.65000000", "0.57577000"], ["84071.66000000", "0.71486000"], ["84071.90000000", "0.05297000"], ["84072.15000000", "0.05097000"], ["84072.72000000", "0.00000000"], ["84074.05000000", "0.04645000"], ["84074.07000000", "0.00000000"], ["84074.11000000", "0.04397000"], ["84074.37000000", "0.04645000"], ["84075.33000000", "0.05097000"], ["84076.05000000", "0.05297000"], ["84076.19000000", "0.05497000"], ["84076.87000000", "0.32652000"], ["84076.88000000", "0.04645000"], ["84077.65000000", "0.04764000"], ["84078.24000000", "0.04397000"], ["84078.66000000", "0.04897000"], ["84078.82000000", "0.04645000"], ["84079.09000000", "0.05497000"], ["84079.44000000", "0.05097000"], ["84079.69000000", "0.04645000"], ["84079.80000000", "0.00013000"], ["84079.90000000", "0.04764000"], ["84080.09000000", "0.35919000"], ["84080.11000000", "0.00000000"], ["84080.47000000", "0.05297000"], ["84080.67000000", "0.04645000"], ["84081.28000000", "0.04764000"], ["84081.37000000", "0.53133000"], ["84081.38000000", "0.17899000"], ["84081.74000000", "0.71486000"], ["84081.78000000", "0.04764000"], ["84082.23000000", "0.04645000"], ["84082.47000000", "0.05497000"], ["84082.86000000", "0.04764000"], ["84082.93000000", "0.04764000"], ["84083.03000000", "0.05497000"], ["84083.08000000", "0.04764000"], ["84083.31000000", "0.04764000"], ["84083.41000000", "0.04645000"], ["84083.51000000", "0.05097000"], ["84083.63000000", "0.04645000"], ["84083.64000000", "0.04897000"], ["84083.83000000", "0.05297000"], ["84083.88000000", "0.04397000"], ["84083.93000000", "0.04764000"], ["84084.08000000", "0.03998000"], ["84084.10000000", "0.04397000"], ["84084.18000000", "0.04897000"], ["84084.67000000", "0.11175000"], ["84085.21000000", "0.04645000"], ["84085.37000000", "0.04398000"], ["84085.39000000", "0.04764000"], ["84085.43000000", "0.05497000"], ["84085.60000000", "0.05497000"], ["84085.68000000", "0.00119000"], ["84085.82000000", "0.04897000"], ["84085.94000000", "0.05497000"], ["84085.99000000", "0.05497000"], ["84086.19000000", "0.04764000"], ["84086.63000000", "0.04764000"], ["84086.75000000", "0.04645000"], ["84087.02000000", "0.04645000"], ["84087.09000000", "0.05097000"], ["84087.34000000", "0.04897000"], ["84087.57000000", "0.04397000"], ["84087.58000000", "0.08862000"], ["84087.60000000", "0.09395000"], ["84087.85000000", "0.04645000"], ["84087.98000000", "0.04764000"], ["84088.28000000", "0.04645000"], ["84088.44000000", "0.05297000"], ["84088.68000000", "0.08354000"], ["84088.77000000", "0.04397000"], ["84088.78000000", "0.04397000"], ["84089.18000000", "0.04764000"], ["84089.30000000", "0.04897000"], ["84089.50000000", "0.05097000"], ["84089.68000000", "0.03998000"], ["84089.72000000", "0.04764000"], ["84089.74000000", "0.05097000"], ["84089.83000000", "0.04764000"], ["84090.04000000", "0.04398000"], ["84090.67000000", "0.04764000"], ["84090.68000000", "0.00000000"], ["84090.89000000", "0.05297000"], ["84091.38000000", "0.03998000"], ["84091.42000000", "0.04764000"], ["84091.43000000", "0.05297000"], ["84091.55000000", "0.04897000"], ["84091.82000000", "0.71486000"], ["84092.06000000", "0.04764000"], ["84092.28000000", "0.21988000"], ["84092.44000000", "0.05497000"], ["84092.58000000", "0.04397000"], ["84092.74000000", "0.04764000"], ["84092.78000000", "0.04397000"], ["84092.82000000", "0.05097000"], ["84092.84000000", "0.04897000"], ["84093.00000000", "0.04897000"], ["84093.25000000", "0.04897000"], ["84093.46000000", "0.10194000"], ["84093.47000000", "0.04764000"], ["84093.59000000", "0.04398000"], ["84094.13000000", "0.04764000"], ["84094.39000000", "0.04764000"], ["84094.58000000", "0.10594000"], ["84095.49000000", "0.04897000"], ["84095.81000000", "0.04764000"], ["84096.00000000", "0.00235000"], ["84098.17000000", "0.17899000"], ["84098.78000000", "0.04397000"], ["84098.81000000", "0.04397000"], ["84099.60000000", "0.04398000"], ["84099.99000000", "0.71486000"], ["84102.30000000", "0.00000000"], ["84103.78000000", "0.03998000"], ["84105.47000000", "0.08354000"], ["84109.68000000", "0.00000000"], ["84109.86000000", "0.00000000"], ["84110.02000000", "0.18351000"], ["84110.13000000", "0.03998000"], ["84113.06000000", "0.00000000"], ["84113.07000000", "0.00000000"], ["84113.87000000", "0.00000000"], ["84114.96000000", "0.17899000"], ["84115.17000000", "0.00000000"], ["84115.82000000", "0.00000000"], ["84115.92000000", "0.00000000"], ["84116.02000000", "0.00000000"], ["84116.12000000", "0.00000000"], ["84117.63000000", "0.00000000"], ["84122.26000000", "0.08354000"], ["84122.59000000", "0.00000000"], ["84126.40000000", "0.00000000"], ["84127.12000000", "0.02383000"], ["84127.40000000", "0.00000000"], ["84128.71000000", "0.00119000"], ["84128.72000000", "0.00000000"], ["84131.75000000", "0.17899000"], ["84134.46000000", "0.01188000"], ["84139.99000000", "0.00119000"], ["84146.16000000", "0.75000000"], ["84147.85000000", "0.21442000"], ["84174.02000000", "0.00013000"], ["84178.21000000", "0.00013000"], ["84182.40000000", "0.00013000"], ["84186.59000000", "0.00013000"], ["84190.78000000", "0.00013000"], ["84194.97000000", "0.00013000"], ["84199.16000000", "0.00013000"], ["84201.29000000", "0.00020000"], ["84224.80000000", "0.45000000"], ["84233.20000000", "0.00000000"], ["84242.62000000", "0.00000000"], ["84245.76000000", "0.34261000"], ["84254.15000000", "0.15831000"], ["84262.54000000", "0.15831000"], ["84265.74000000", "0.00637000"], ["84268.01000000", "2.59453000"], ["84270.93000000", "0.15831000"], ["84279.32000000", "0.15831000"], ["84287.71000000", "0.01787000"], ["84698.46000000", "0.00000000"], ["84785.48000000", "0.00278000"], ["85000.00000000", "19.11954000"], ["85180.48000000", "0.00000000"], ["85204.84000000", "0.00000000"], ["85231.60000000", "0.10000000"], ["85242.60000000", "0.00000000"], ["85263.90000000", "0.00000000"], ["98400.00000000", "6.15249000"]], "record_time": 1742576914.218937, "EXCHANGE": "BINANCE"}
{"e": "depthUpdate", "E": 1742576915014, "s": "BTCUSDT", "U": 64631966916, "u": 64631967475, "b": [["83958.22000000", "5.54317000"], ["83958.21000000", "0.00459000"], ["83958.20000000", "0.02014000"], ["83958.11000000", "0.00021000"], ["83958.10000000", "0.02014000"], ["83958.05000000", "0.34063000"], ["83958.04000000", "0.00007000"], ["83958.03000000", "0.00000000"], ["83958.02000000", "0.00000000"], ["83957.70000000", "0.05369000"], ["83956.00000000", "0.01416000"], ["83955.40000000", "0.00000000"], ["83952.97000000", "0.89392000"], ["83951.98000000", "0.04000000"], ["83950.91000000", "0.08992000"], ["83950.29000000", "0.04000000"], ["83950.24000000", "0.04000000"], ["83949.82000000", "0.80415000"], ["83949.80000000", "0.05955000"], ["83949.60000000", "0.00006000"], ["83948.07000000", "0.02382000"], ["83948.00000000", "0.13320000"], ["83947.78000000", "0.04000000"], ["83947.52000000", "0.02382000"], ["83946.95000000", "0.04000000"], ["83946.65000000", "0.80867000"], ["83946.11000000", "0.08000000"], ["83945.65000000", "0.88810000"], ["83945.64000000", "0.46567000"], ["83945.40000000", "0.00006000"], ["83943.16000000", "0.05959000"], ["83942.46000000", "0.02353000"], ["83941.42000000", "0.00300000"], ["83940.97000000", "0.85815000"], ["83939.74000000", "0.00000000"], ["83939.53000000", "0.00008000"], ["83939.49000000", "0.00000000"], ["83938.31000000", "0.00000000"], ["83938.28000000", "0.33521000"], ["83937.84000000", "0.00000000"], ["83937.69000000", "0.05955000"], ["83937.00000000", "0.00006000"], ["83936.99000000", "0.00000000"], ["83936.27000000", "1.07287000"], ["83935.90000000", "0.00000000"], ["83935.69000000", "0.00000000"], ["83935.56000000", "0.00000000"], ["83935.03000000", "1.47260000"], ["83934.92000000", "0.05955000"], ["83934.46000000", "0.00000000"], ["83934.22000000", "0.00000000"], ["83933.99000000", "0.89392000"], ["83932.80000000", "0.00006000"], ["83932.52000000", "0.82493000"], ["83932.51000000", "0.85824000"], ["83932.18000000", "0.00000000"], ["83930.14000000", "0.04000000"], ["83928.52000000", "0.41114000"], ["83928.05000000", "0.05000000"], ["83927.66000000", "0.00000000"], ["83926.54000000", "0.00025000"], ["83925.94000000", "0.04000000"], ["83925.74000000", "0.00000000"], ["83925.70000000", "0.00000000"], ["83925.42000000", "0.00000000"], ["83925.39000000", "0.00000000"], ["83921.39000000", "0.04743000"], ["83919.53000000", "0.05869000"], ["83918.15000000", "0.00000000"], ["83917.17000000", "0.04490000"], ["83916.84000000", "0.00000000"], ["83916.24000000", "0.00059000"], ["83899.33000000", "0.00000000"], ["83893.36000000", "0.04000000"], ["83892.35000000", "0.00000000"], ["83892.18000000", "0.00061000"], ["83887.72000000", "0.04000000"], ["83886.63000000", "0.00000000"], ["83883.94000000", "0.00000000"], ["83881.92000000", "0.00007000"], ["83880.00000000", "0.00016000"], ["83879.39000000", "0.05497000"], ["83876.00000000", "0.00010000"], ["83872.00000000", "0.00010000"], ["83871.35000000", "0.00000000"], ["83870.94000000", "0.00000000"], ["83870.26000000", "0.71486000"], ["83869.80000000", "0.00000000"], ["83869.60000000", "0.52141000"], ["83869.00000000", "0.63073000"], ["83868.01000000", "0.00000000"], ["83865.17000000", "0.01196000"], ["83863.80000000", "0.00400000"], ["83860.18000000", "0.71486000"], ["83853.79000000", "0.00000000"], ["83846.67000000", "0.01527000"], ["83846.66000000", "0.00000000"], ["83843.49000000", "0.00000000"], ["83796.84000000", "0.01000000"], ["83796.64000000", "0.00000000"], ["83796.54000000", "0.00000000"], ["83715.81000000", "0.00000000"], ["83711.62000000", "0.00000000"], ["83707.43000000", "0.00000000"], ["83617.97000000", "0.00040000"], ["83617.93000000", "0.00000000"], ["83500.00000000", "2.38931000"], ["82881.43000000", "0.00040000"], ["82881.31000000", "0.00000000"], ["82698.84000000", "0.00100000"], ["80606.38000000", "0.03571000"], ["80589.60000000", "0.00000000"], ["75693.37000000", "0.00016000"], ["75562.00000000", "0.00000000"], ["67166.58000000", "0.00058000"], ["33000.00000000", "2.96666000"], ["30224.96000000", "0.00060000"], ["20002.00000000", "0.00000000"], ["20001.00000000", "0.02099000"]], "a": [["83958.23000000", "0.09678000"], ["83958.24000000", "0.00111000"], ["83958.35000000", "0.00280000"], ["83958.36000000", "0.00007000"], ["83958.37000000", "0.00007000"], ["83958.41000000", "0.00007000"], ["83958.59000000", "0.00000000"], ["83958.60000000", "0.00079000"], ["83958.61000000", "0.00000000"], ["83959.52000000", "0.00000000"], ["83959.53000000", "0.00000000"], ["83959.54000000", "0.00000000"], ["83959.98000000", "0.00041000"], ["83959.99000000", "0.06779000"], ["83960.00000000", "0.02605000"], ["83961.89000000", "0.00014000"], ["83961.90000000", "0.16945000"], ["83961.91000000", "0.00000000"], ["83961.98000000", "0.00000000"], ["83961.99000000", "0.02299000"], ["83962.00000000", "0.01410000"], ["83962.93000000", "0.00000000"], ["83962.94000000", "0.17438000"], ["83962.95000000", "0.44330000"], ["83965.34000000", "0.00000000"], ["83965.58000000", "0.00000000"], ["83966.62000000", "0.02681000"], ["83966.63000000", "0.00000000"], ["83967.50000000", "0.00000000"], ["83968.07000000", "0.02213000"], ["83968.68000000", "0.00000000"], ["83969.15000000", "0.02212000"], ["83969.70000000", "0.08400000"], ["83970.81000000", "0.00000000"], ["83970.88000000", "0.00009000"], ["83971.39000000", "0.12800000"], ["83971.56000000", "0.00119000"], ["83971.79000000", "0.00000000"], ["83972.04000000", "0.00000000"], ["83972.17000000", "0.00000000"], ["83972.58000000", "0.08354000"], ["83972.59000000", "0.40257000"], ["83973.29000000", "0.47675000"], ["83974.21000000", "0.00000000"], ["83974.32000000", "0.00007000"], ["83974.78000000", "0.02382000"], ["83975.02000000", "0.93061000"], ["83975.10000000", "0.00000000"], ["83975.59000000", "0.04400000"], ["83977.39000000", "0.00000000"], ["83978.12000000", "0.00000000"], ["83978.79000000", "0.78629000"], ["83978.96000000", "0.00000000"], ["83979.35000000", "0.69405000"], ["83979.36000000", "0.00000000"], ["83979.81000000", "0.00000000"], ["83981.00000000", "0.00000000"], ["83981.79000000", "0.00000000"], ["83981.80000000", "0.00000000"], ["83982.44000000", "0.59594000"], ["83983.42000000", "0.00300000"], ["83984.08000000", "0.00000000"], ["83985.41000000", "0.00898000"], ["83987.07000000", "1.49878000"], ["83988.09000000", "0.79698000"], ["83990.88000000", "0.00000000"], ["83991.10000000", "0.00000000"], ["83995.41000000", "0.00000000"], ["83999.60000000", "0.00000000"], ["83999.75000000", "0.89392000"], ["84000.21000000", "0.00059000"], ["84000.80000000", "0.56493000"], ["84001.94000000", "0.59574000"], ["84003.50000000", "0.05789000"], ["84007.47000000", "0.35756000"], ["84007.76000000", "0.00000000"], ["84008.43000000", "1.11073000"], ["84009.76000000", "0.05000000"], ["84009.88000000", "1.33420000"], ["84009.96000000", "0.04000000"], ["84011.07000000", "0.85744000"], ["84011.52000000", "0.00000000"], ["84013.38000000", "0.54659000"], ["84014.57000000", "0.85740000"], ["84018.35000000", "0.55353000"], ["84020.22000000", "0.59594000"], ["84021.80000000", "0.25952000"], ["84021.82000000", "0.06000000"], ["84021.93000000", "0.03856000"], ["84025.16000000", "0.05600000"], ["84034.93000000", "0.04765000"], ["84035.11000000", "0.00599000"], ["84035.37000000", "0.00000000"], ["84037.43000000", "0.04646000"], ["84038.00000000", "0.00000000"], ["84038.30000000", "0.00019000"], ["84047.76000000", "0.00000000"], ["84059.68000000", "0.00060000"], ["84093.88000000", "0.00006000"], ["84108.96000000", "0.00000000"], ["84112.00000000", "0.00360000"], ["84113.97000000", "0.00016000"], ["84139.23000000", "0.00000000"], ["84245.62000000", "0.99645000"], ["85217.61000000", "0.00100000"]], "record_time": 1742576915.215314, "EXCHANGE": "BINANCE"}
{"e": "depthUpdate", "E": 1742576916014, "s": "BTCUSDT", "U": 64631967476, "u": 64631967974, "b": [["83958.22000000", "2.37833000"], ["83958.20000000", "0.02020000"], ["83958.19000000", "0.00007000"], ["83958.10000000", "0.02014000"], ["83958.06000000", "0.00007000"], ["83958.05000000", "0.00013000"], ["83958.04000000", "0.00000000"], ["83958.01000000", "0.00014000"], ["83958.00000000", "0.01417000"], ["83957.70000000", "0.00006000"], ["83956.92000000", "0.00000000"], ["83956.91000000", "0.00000000"], ["83956.01000000", "0.00007000"], ["83956.00000000", "0.01423000"], ["83955.65000000", "0.31572000"], ["83954.46000000", "0.02482000"], ["83954.27000000", "0.00006000"], ["83954.00000000", "0.01410000"], ["83953.80000000", "0.00006000"], ["83953.72000000", "0.00000000"], ["83953.13000000", "0.00000000"], ["83952.98000000", "0.76752000"], ["83952.97000000", "0.89392000"], ["83952.73000000", "0.05363000"], ["83952.67000000", "0.18351000"], ["83952.16000000", "0.02364000"], ["83950.91000000", "0.00000000"], ["83950.51000000", "0.00000000"], ["83950.21000000", "0.02382000"], ["83949.88000000", "0.10810000"], ["83949.80000000", "0.00000000"], ["83949.63000000", "0.00000000"], ["83949.59000000", "0.00000000"], ["83949.51000000", "0.00000000"], ["83948.07000000", "0.00000000"], ["83948.00000000", "0.01410000"], ["83947.89000000", "0.47675000"], ["83947.53000000", "0.00000000"], ["83947.52000000", "0.00000000"], ["83946.65000000", "0.57643000"], ["83946.64000000", "0.00000000"], ["83945.79000000", "0.00000000"], ["83945.75000000", "0.17899000"], ["83945.65000000", "0.03000000"], ["83945.53000000", "0.00418000"], ["83945.42000000", "0.00000000"], ["83944.60000000", "0.00500000"], ["83943.16000000", "0.00000000"], ["83942.91000000", "0.00000000"], ["83942.43000000", "0.00000000"], ["83941.42000000", "0.36056000"], ["83940.98000000", "0.00000000"], ["83940.97000000", "0.00000000"], ["83939.47000000", "0.00000000"], ["83938.28000000", "0.00000000"], ["83938.17000000", "0.00000000"], ["83936.34000000", "0.00000000"], ["83934.71000000", "0.00000000"], ["83934.21000000", "0.00922000"], ["83933.16000000", "0.00000000"], ["83932.83000000", "0.05959000"], ["83930.49000000", "0.85826000"], ["83929.74000000", "0.00000000"], ["83928.52000000", "0.74527000"], ["83928.05000000", "0.00000000"], ["83926.05000000", "0.47675000"], ["83925.86000000", "0.85831000"], ["83924.37000000", "0.40574000"], ["83924.36000000", "0.47675000"], ["83923.72000000", "0.01191000"], ["83921.40000000", "0.59586000"], ["83921.39000000", "0.00000000"], ["83920.00000000", "0.00125000"], ["83917.17000000", "0.00000000"], ["83912.68000000", "0.00000000"], ["83911.19000000", "0.35756000"], ["83909.97000000", "0.04743000"], ["83906.96000000", "0.00297000"], ["83906.95000000", "0.27371000"], ["83904.38000000", "0.59594000"], ["83903.81000000", "0.04490000"], ["83901.16000000", "0.00720000"], ["83900.49000000", "0.05497000"], ["83899.35000000", "0.00296000"], ["83897.45000000", "0.30515000"], ["83894.07000000", "0.00311000"], ["83889.52000000", "0.00013000"], ["83888.27000000", "0.24634000"], ["83888.06000000", "0.04398000"], ["83882.01000000", "0.71486000"], ["83873.07000000", "0.30356000"], ["83871.93000000", "0.71486000"], ["83870.26000000", "0.00000000"], ["83869.60000000", "0.30876000"], ["83869.00000000", "0.00000000"], ["83863.80000000", "0.00000000"], ["83860.19000000", "0.60864000"], ["83859.26000000", "0.00000000"], ["83844.01000000", "0.00083000"], ["83834.28000000", "0.12000000"], ["83828.76000000", "0.00000000"], ["83822.98000000", "0.00119000"], ["83819.03000000", "0.00000000"], ["83816.01000000", "0.00119000"], ["83815.19000000", "0.05958000"], ["83815.11000000", "0.00000000"], ["83811.27000000", "0.00400000"], ["83810.29000000", "0.00307000"], ["83804.18000000", "0.00000000"], ["83802.27000000", "0.00000000"], ["83798.38000000", "0.00000000"], ["83795.33000000", "0.00000000"], ["83768.48000000", "0.00069000"], ["83753.32000000", "0.00000000"], ["83500.00000000", "2.38910000"], ["82984.80000000", "0.02350000"], ["82698.84000000", "0.00100000"], ["82500.00000000", "19.58208000"], ["80606.38000000", "0.00000000"], ["76700.00000000", "8.07589000"], ["75693.37000000", "0.00000000"], ["75562.40000000", "0.00032000"], ["75562.00000000", "0.00000000"], ["67166.58000000", "0.00058000"], ["33000.00000000", "2.96666000"], ["30224.96000000", "0.00100000"]], "a": [["83958.23000000", "4.36008000"], ["83959.12000000", "0.00000000"], ["83959.13000000", "0.00000000"], ["83959.70000000", "0.00000000"], ["83959.96000000", "0.00014000"], ["83959.97000000", "0.02950000"], ["83959.98000000", "0.00027000"], ["83959.99000000", "0.00020000"], ["83960.00000000", "0.02599000"], ["83960.22000000", "0.00000000"], ["83960.23000000", "0.00000000"], ["83960.45000000", "0.00000000"], ["83960.46000000", "0.00000000"], ["83960.54000000", "0.00007000"], ["83961.52000000", "0.00006000"], ["83961.53000000", "0.00000000"], ["83961.89000000", "0.00000000"], ["83961.90000000", "0.00000000"], ["83961.98000000", "0.00014000"], ["83961.99000000", "0.02293000"], ["83962.00000000", "0.01417000"], ["83962.83000000", "0.00000000"], ["83962.93000000", "0.00014000"], ["83962.94000000", "0.19294000"], ["83962.95000000", "0.14023000"], ["83964.94000000", "0.00000000"], ["83965.80000000", "0.00000000"], ["83965.81000000", "0.47675000"], ["83966.62000000", "0.40849000"], ["83966.63000000", "0.45000000"], ["83967.37000000", "0.71486000"], ["83968.07000000", "0.00000000"], ["83968.98000000", "0.16453000"], ["83969.15000000", "0.00000000"], ["83970.04000000", "0.17899000"], ["83970.81000000", "0.01190000"], ["83971.68000000", "0.18180000"], ["83972.17000000", "0.02411000"], ["83972.27000000", "0.00000000"], ["83972.59000000", "0.60058000"], ["83972.70000000", "0.78634000"], ["83973.78000000", "0.89392000"], ["83974.27000000", "0.00000000"], ["83976.68000000", "0.00000000"], ["83978.79000000", "0.00000000"], ["83979.19000000", "0.00000000"], ["83981.00000000", "0.00000000"], ["83981.89000000", "0.03573000"], ["83982.46000000", "0.21959000"], ["83983.21000000", "0.91053000"], ["83987.06000000", "0.00000000"], ["83991.80000000", "0.59582000"], ["83991.81000000", "0.00922000"], ["83996.04000000", "0.08992000"], ["83996.86000000", "0.00000000"], ["83997.13000000", "0.04110000"], ["83998.23000000", "0.05000000"], ["83999.41000000", "0.85756000"], ["84001.90000000", "0.00720000"], ["84001.94000000", "0.00000000"], ["84006.54000000", "0.03856000"], ["84009.76000000", "0.00000000"], ["84009.88000000", "0.85745000"], ["84012.92000000", "0.00000000"], ["84013.38000000", "0.33071000"], ["84014.57000000", "0.00000000"], ["84018.69000000", "0.00000000"], ["84021.93000000", "0.00000000"], ["84035.05000000", "0.00599000"], ["84035.11000000", "0.01198000"], ["84086.00000000", "0.27381000"], ["84128.71000000", "0.00000000"], ["84131.74000000", "0.00119000"], ["84139.45000000", "0.99818000"], ["84245.62000000", "0.00000000"], ["84797.80000000", "0.00000000"], ["85217.61000000", "0.00100000"], ["85242.60000000", "0.11747000"], ["85285.20000000", "0.05873000"]], "record_time": 1742576916.215007, "EXCHANGE": "BINANCE"}
{"e": "depthUpdate", "E": 1742576917014, "s": "BTCUSDT", "U": 64631967975, "u": 64631968114, "b": [["83958.22000000", "2.31628000"], ["83958.19000000", "0.00007000"], ["83958.13000000", "0.00007000"], ["83958.05000000", "0.00006000"], ["83958.00000000", "0.01417000"], ["83956.03000000", "0.00007000"], ["83956.02000000", "0.05370000"], ["83956.01000000", "0.00000000"], ["83956.00000000", "0.01416000"], ["83955.66000000", "0.17899000"], ["83955.65000000", "0.31565000"], ["83954.30000000", "0.00754000"], ["83954.27000000", "0.00000000"], ["83952.73000000", "0.00000000"], ["83950.21000000", "0.00000000"], ["83939.76000000", "0.00000000"], ["83937.07000000", "0.23180000"], ["83935.90000000", "0.00500000"], ["83935.03000000", "0.00000000"], ["83934.06000000", "1.50137000"], ["83923.65000000", "0.05000000"], ["83916.89000000", "0.00007000"], ["83882.01000000", "1.80567000"], ["83881.79000000", "0.00000000"], ["83873.07000000", "0.44409000"], ["83869.60000000", "0.50938000"], ["83866.23000000", "0.63064000"], ["83811.27000000", "0.00000000"], ["83805.35000000", "0.00400000"], ["83797.24000000", "0.01000000"], ["83796.84000000", "0.00000000"], ["83778.96000000", "0.00839000"], ["83770.46000000", "0.00000000"], ["83748.00000000", "0.00241000"], ["83704.61000000", "0.00000000"], ["82875.30000000", "0.00000000"], ["82698.84000000", "0.00000000"], ["82000.00000000", "67.29159000"], ["80606.38000000", "0.03571000"], ["75562.00000000", "0.00000000"], ["67166.58000000", "0.00058000"], ["42000.00000000", "6.84810000"], ["33000.00000000", "2.96666000"], ["30224.96000000", "0.00140000"]], "a": [["83958.23000000", "4.76932000"], ["83959.97000000", "0.01921000"], ["83962.00000000", "0.01417000"], ["83962.40000000", "0.00000000"], ["83962.82000000", "0.00014000"], ["83962.83000000", "0.03350000"], ["83964.94000000", "0.00467000"], ["83975.98000000", "0.02425000"], ["83976.56000000", "0.05959000"], ["83983.21000000", "0.62482000"], ["83983.42000000", "0.00359000"], ["83984.24000000", "1.46397000"], ["83987.07000000", "0.00000000"], ["83996.95000000", "0.00760000"], ["83997.98000000", "0.05000000"], ["83998.23000000", "0.00000000"], ["84039.54000000", "0.00000000"], ["84057.51000000", "0.02383000"], ["84127.12000000", "0.00000000"], ["84909.55000000", "0.00000000"], ["85217.61000000", "0.00000000"]], "record_time": 1742576917.214948, "EXCHANGE": "BINANCE"}
{"e": "depthUpdate", "E": 1742576918014, "s": "BTCUSDT", "U": 64631968115, "u": 64631968185, "b": [["83958.22000000", "2.22512000"], ["83953.07000000", "0.15951000"], ["83944.60000000", "0.00500000"], ["83940.54000000", "0.85816000"], ["83934.92000000", "0.00000000"], ["83928.52000000", "0.41114000"], ["83925.86000000", "0.00000000"], ["83802.06000000", "0.00622000"], ["83784.22000000", "0.00000000"], ["83782.51000000", "0.00012000"], ["83742.02000000", "0.01872000"], ["83714.20000000", "0.00000000"], ["82883.64000000", "0.40000000"], ["82698.84000000", "0.00100000"], ["76700.00000000", "8.07145000"], ["75562.00000000", "0.00000000"], ["67166.58000000", "0.00058000"], ["42000.00000000", "6.84710000"], ["33000.00000000", "2.96666000"], ["30224.96000000", "0.00160000"]], "a": [["83958.23000000", "4.35070000"], ["83962.00000000", "0.01417000"], ["83962.82000000", "0.00000000"], ["83962.83000000", "0.00000000"], ["83964.94000000", "0.00000000"], ["83976.56000000", "0.00000000"], ["83976.58000000", "0.10809000"], ["83978.27000000", "0.08627000"], ["83982.90000000", "0.01865000"], ["83983.21000000", "0.90026000"], ["83987.37000000", "0.00000000"], ["83997.13000000", "0.00000000"], ["83997.20000000", "0.05000000"], ["83997.98000000", "0.00000000"], ["84006.84000000", "0.04110000"], ["84029.04000000", "0.00178000"], ["84038.30000000", "0.00000000"], ["84049.69000000", "0.00058000"], ["84071.56000000", "0.00000000"], ["84085.78000000", "0.12000000"], ["84113.97000000", "0.00000000"], ["84917.96000000", "0.60000000"], ["85217.61000000", "0.00100000"]], "record_time": 1742576918.214173, "EXCHANGE": "BINANCE"}
{"e": "depthUpdate", "E": 1742576919014, "s": "BTCUSDT", "U": 64631968186, "u": 64631968281, "b": [["83958.22000000", "2.15965000"], ["83958.13000000", "0.00521000"], ["83955.30000000", "0.00400000"], ["83945.64000000", "0.46560000"], ["83945.30000000", "0.00400000"], ["83943.64000000", "0.00000000"], ["83939.12000000", "0.05959000"], ["83935.90000000", "0.00000000"], ["83931.35000000", "0.01635000"], ["83904.41000000", "0.59594000"], ["83904.38000000", "0.00000000"], ["83844.02000000", "0.00083000"], ["83844.01000000", "0.00000000"], ["83837.02000000", "0.18350000"], ["83812.57000000", "0.00000000"], ["83797.54000000", "0.01000000"], ["83797.24000000", "0.00000000"], ["83768.49000000", "0.00069000"], ["83768.48000000", "0.00000000"], ["83742.02000000", "0.00007000"], ["82698.84000000", "0.00000000"], ["81000.00000000", "55.75299000"], ["75562.00000000", "0.00000000"], ["67166.58000000", "0.00058000"], ["33000.00000000", "2.96666000"]], "a": [["83958.23000000", "4.88060000"], ["83958.83000000", "0.00008000"], ["83962.40000000", "0.00000000"], ["83963.88000000", "0.03287000"], ["83964.94000000", "0.00000000"], ["83966.40000000", "0.00013000"], ["83970.66000000", "0.78636000"], ["83972.70000000", "0.00000000"], ["83973.29000000", "0.00000000"], ["83976.56000000", "0.05959000"], ["83985.20000000", "0.00400000"], ["83994.98000000", "0.85760000"], ["83995.30000000", "0.00400000"], ["83997.20000000", "0.00000000"], ["84001.75000000", "0.00000000"], ["84001.92000000", "0.11461000"], ["84007.80000000", "0.00000000"], ["84008.43000000", "1.29178000"], ["84011.07000000", "0.00000000"], ["84038.30000000", "0.00019000"], ["84050.71000000", "0.86209000"], ["84054.29000000", "0.00000000"], ["84113.97000000", "0.00016000"], ["85217.61000000", "0.00000000"]], "record_time": 1742576919.214986, "EXCHANGE": "BINANCE"}
{"e": "depthUpdate", "E": 1742576920014, "s": "BTCUSDT", "U": 64631968282, "u": 64631968379, "b": [["83958.22000000", "2.15990000"], ["83958.20000000", "0.02020000"], ["83958.19000000", "0.00007000"], ["83958.16000000", "0.00165000"], ["83958.13000000", "0.00007000"], ["83958.10000000", "0.02014000"], ["83958.06000000", "0.00000000"], ["83958.05000000", "0.00006000"], ["83955.64000000", "0.89392000"], ["83944.60000000", "0.00500000"], ["83905.16000000", "0.59594000"], ["83905.04000000", "0.00000000"], ["83904.41000000", "0.00000000"], ["83887.05000000", "0.71486000"], ["82698.84000000", "0.00100000"], ["76700.00000000", "8.07645000"], ["75562.00000000", "0.00000000"], ["67166.58000000", "0.00058000"], ["60000.00000000", "72.96736000"], ["33000.00000000", "2.96666000"], ["30224.96000000", "0.00180000"], ["20002.00000000", "0.00000000"], ["20001.00000000", "0.02099000"]], "a": [["83958.23000000", "4.76006000"], ["83964.94000000", "0.00617000"], ["83976.56000000", "0.05959000"], ["84001.25000000", "0.05000000"], ["84001.46000000", "0.03533000"], ["84014.71000000", "0.00000000"], ["84018.53000000", "0.26726000"], ["84050.71000000", "0.00000000"], ["84052.11000000", "0.53431000"], ["84057.51000000", "0.00000000"], ["84073.35000000", "0.02383000"], ["84085.70000000", "0.80115000"], ["84119.29000000", "2.13557000"], ["84128.00000000", "0.01235000"], ["85217.61000000", "0.00100000"]], "record_time": 1742576920.214835, "EXCHANGE": "BINANCE"}
{"e": "depthUpdate", "E": 1742576921014, "s": "BTCUSDT", "U": 64631968380, "u": 64631968491, "b": [["83958.22000000", "2.15034000"], ["83958.16000000", "0.00007000"], ["83958.10000000", "0.02014000"], ["83958.08000000", "0.00000000"], ["83958.00000000", "0.01417000"], ["83956.04000000", "0.00007000"], ["83956.03000000", "0.08815000"], ["83956.02000000", "0.05363000"], ["83956.00000000", "0.01410000"], ["83955.65000000", "0.00000000"], ["83955.64000000", "0.00000000"], ["83955.40000000", "0.00000000"], ["83955.30000000", "0.00000000"], ["83952.97000000", "0.00000000"], ["83952.11000000", "0.00008000"], ["83950.73000000", "0.00000000"], ["83945.40000000", "0.00006000"], ["83945.30000000", "0.00000000"], ["83944.93000000", "0.87510000"], ["83944.60000000", "0.00000000"], ["83944.50000000", "0.15465000"], ["83942.85000000", "0.59594000"], ["83942.77000000", "0.89392000"], ["83940.55000000", "1.13495000"], ["83939.75000000", "0.00000000"], ["83939.44000000", "0.89392000"], ["83937.69000000", "0.00000000"], ["83935.55000000", "0.00000000"], ["83930.15000000", "0.59581000"], ["83924.37000000", "0.24199000"], ["83923.65000000", "0.00000000"], ["83921.40000000", "0.00000000"], ["83912.81000000", "0.00000000"], ["83905.16000000", "0.00000000"], ["83905.10000000", "0.59594000"], ["83905.07000000", "0.00000000"], ["83890.58000000", "0.71789000"], ["83805.35000000", "0.00000000"], ["83799.23000000", "0.00400000"], ["83118.63000000", "0.00000000"], ["82698.84000000", "0.00100000"], ["75562.00000000", "0.00000000"], ["67166.58000000", "0.00058000"], ["60000.00000000", "72.96726000"], ["33000.00000000", "2.96666000"], ["30224.96000000", "0.00200000"]], "a": [["83958.23000000", "4.75911000"], ["83962.40000000", "0.00500000"], ["83964.94000000", "0.00576000"], ["83970.66000000", "0.00000000"], ["83972.57000000", "0.78634000"], ["83985.20000000", "0.00000000"], ["83995.14000000", "0.00759000"], ["83995.30000000", "0.00000000"], ["83996.95000000", "0.00000000"], ["83996.98000000", "0.00000000"], ["83997.51000000", "0.00000000"], ["84001.25000000", "0.00000000"], ["84019.61000000", "0.00000000"], ["84019.62000000", "0.00000000"], ["84051.78000000", "0.62392000"], ["84127.90000000", "0.01000000"], ["84128.00000000", "0.00235000"], ["85217.61000000", "0.00100000"], ["85550.00000000", "0.12294000"]], "record_time": 1742576921.21441, "EXCHANGE": "BINANCE"}
{"e": "depthUpdate", "E": 1742576922014, "s": "BTCUSDT", "U": 64631968492, "u": 64631968863, "b": [["83958.22000000", "3.63755000"], ["83958.00000000", "0.01417000"], ["83957.77000000", "0.00000000"], ["83957.76000000", "0.00000000"], ["83957.06000000", "0.00000000"], ["83956.03000000", "0.23793000"], ["83954.09000000", "0.00000000"], ["83953.88000000", "0.00000000"], ["83953.66000000", "0.00000000"], ["83953.33000000", "0.00000000"], ["83953.14000000", "0.00000000"], ["83953.07000000", "0.00000000"], ["83952.67000000", "0.00000000"], ["83952.48000000", "0.00000000"], ["83950.52000000", "0.00000000"], ["83950.21000000", "0.02382000"], ["83948.42000000", "0.02382000"], ["83948.07000000", "0.02382000"], ["83947.89000000", "0.00000000"], ["83946.33000000", "0.02382000"], ["83945.95000000", "0.00000000"], ["83945.79000000", "0.05955000"], ["83945.53000000", "0.00000000"], ["83944.60000000", "0.00500000"], ["83943.86000000", "0.00000000"], ["83943.64000000", "0.01635000"], ["83939.58000000", "0.01874000"], ["83938.93000000", "0.00000000"], ["83937.70000000", "0.05955000"], ["83937.32000000", "0.00000000"], ["83936.85000000", "0.00000000"], ["83936.27000000", "0.00000000"], ["83935.61000000", "0.00000000"], ["83935.60000000", "1.50394000"], ["83934.06000000", "0.00000000"], ["83933.76000000", "0.05955000"], ["83931.48000000", "0.59580000"], ["83931.47000000", "0.03747000"], ["83931.35000000", "0.00000000"], ["83930.50000000", "0.08354000"], ["83930.15000000", "0.00000000"], ["83930.07000000", "0.47675000"], ["83927.91000000", "0.00000000"], ["83924.37000000", "0.00000000"], ["83924.36000000", "0.00000000"], ["83923.29000000", "0.00000000"], ["83922.57000000", "0.04490000"], ["83920.10000000", "0.00000000"], ["83919.31000000", "0.89392000"], ["83918.70000000", "0.00000000"], ["83915.53000000", "0.35756000"], ["83915.20000000", "0.04743000"], ["83914.91000000", "0.00000000"], ["83911.19000000", "0.00000000"], ["83909.97000000", "0.00000000"], ["83906.95000000", "0.10848000"], ["83905.10000000", "0.00000000"], ["83904.36000000", "0.00000000"], ["83903.81000000", "0.00000000"], ["83894.06000000", "0.26601000"], ["83892.40000000", "0.71486000"], ["83827.30000000", "0.00400000"], ["83799.23000000", "0.00000000"], ["83797.54000000", "0.01000000"], ["83690.82000000", "0.01865000"], ["82698.84000000", "0.00000000"], ["81250.00000000", "0.83204000"], ["80606.38000000", "0.00000000"], ["80589.60000000", "0.00000000"], ["75562.00000000", "0.00000000"], ["67166.58000000", "0.00058000"], ["33000.00000000", "2.96666000"]], "a": [["83958.23000000", "3.55027000"], ["83958.61000000", "0.00500000"], ["83959.67000000", "0.00000000"], ["83959.68000000", "0.00000000"], ["83959.96000000", "0.00000000"], ["83959.97000000", "0.00000000"], ["83959.98000000", "0.00041000"], ["83959.99000000", "0.01944000"], ["83960.00000000", "0.02622000"], ["83961.98000000", "0.00014000"], ["83961.99000000", "0.02293000"], ["83962.00000000", "0.01417000"], ["83962.38000000", "0.00014000"], ["83962.39000000", "0.07696000"], ["83962.93000000", "0.00000000"], ["83962.94000000", "0.00014000"], ["83962.95000000", "0.14023000"], ["83963.52000000", "0.00000000"], ["83963.88000000", "0.00000000"], ["83964.94000000", "0.00000000"], ["83965.11000000", "0.00000000"], ["83965.81000000", "0.00000000"], ["83966.61000000", "0.00000000"], ["83966.62000000", "0.23381000"], ["83966.63000000", "0.45000000"], ["83967.37000000", "0.00000000"], ["83968.97000000", "0.00000000"], ["83970.04000000", "0.00000000"], ["83970.81000000", "0.01190000"], ["83971.67000000", "0.26650000"], ["83972.17000000", "0.00000000"], ["83972.29000000", "0.47675000"], ["83972.57000000", "0.00000000"], ["83972.59000000", "0.00000000"], ["83972.60000000", "0.00000000"], ["83972.73000000", "0.71486000"], ["83973.78000000", "0.00000000"], ["83974.84000000", "0.17899000"], ["83974.85000000", "0.78632000"], ["83975.02000000", "0.67266000"], ["83976.56000000", "0.00000000"], ["83977.64000000", "0.00000000"], ["83977.95000000", "0.71486000"], ["83978.48000000", "0.00000000"], ["83979.01000000", "0.05959000"], ["83981.11000000", "0.05959000"], ["83982.46000000", "0.16000000"], ["83983.21000000", "0.62482000"], ["83984.24000000", "0.00000000"], ["83984.70000000", "0.00000000"], ["83991.80000000", "0.59579000"], ["83994.62000000", "0.89392000"], ["83994.98000000", "0.00000000"], ["83995.41000000", "0.00000000"], ["83997.78000000", "0.00000000"], ["83998.02000000", "0.02808000"], ["83998.75000000", "0.00000000"], ["84000.79000000", "0.00000000"], ["84002.70000000", "0.00000000"], ["84006.54000000", "0.00000000"], ["84006.84000000", "0.00000000"], ["84008.43000000", "1.27849000"], ["84009.94000000", "0.85745000"], ["84009.96000000", "0.00000000"], ["84014.24000000", "0.00000000"], ["84019.81000000", "0.00000000"], ["84019.82000000", "0.00000000"], ["84020.24000000", "0.04110000"], ["84024.22000000", "0.03856000"], ["84037.33000000", "0.04646000"], ["84038.61000000", "0.00000000"], ["84051.78000000", "0.60612000"], ["84059.99000000", "0.82582000"], ["84062.59000000", "1.27551000"], ["84070.87000000", "0.04645000"], ["84078.02000000", "0.05097000"], ["84082.15000000", "0.05097000"], ["84085.71000000", "0.05097000"], ["84088.57000000", "0.05097000"], ["84127.90000000", "0.01000000"], ["84224.80000000", "0.00000000"], ["85217.61000000", "0.00000000"]], "record_time": 1742576922.215109, "EXCHANGE": "BINANCE"}
{"e": "depthUpdate", "E": 1742576923014, "s": "BTCUSDT", "U": 64631968864, "u": 64631969083, "b": [["83958.22000000", "3.32301000"], ["83958.16000000", "0.00007000"], ["83958.14000000", "0.00007000"], ["83958.10000000", "0.02007000"], ["83958.04000000", "0.00000000"], ["83958.00000000", "0.01432000"], ["83956.05000000", "0.00007000"], ["83956.04000000", "0.08804000"], ["83956.03000000", "0.00000000"], ["83954.30000000", "0.00000000"], ["83952.63000000", "0.15951000"], ["83952.30000000", "0.00756000"], ["83951.45000000", "0.18351000"], ["83948.42000000", "0.00000000"], ["83948.07000000", "0.00000000"], ["83947.00000000", "0.00414000"], ["83946.33000000", "0.00000000"], ["83945.79000000", "0.00000000"], ["83940.54000000", "0.00000000"], ["83940.50000000", "0.85816000"], ["83936.27000000", "1.19275000"], ["83935.90000000", "0.00500000"], ["83931.48000000", "0.00000000"], ["83927.36000000", "0.59582000"], ["83926.09000000", "0.00000000"], ["83924.15000000", "0.00000000"], ["83922.57000000", "0.00000000"], ["83915.20000000", "0.00000000"], ["83911.80000000", "0.04496000"], ["83904.54000000", "0.04743000"], ["83894.06000000", "0.00000000"], ["83892.40000000", "0.00000000"], ["83827.30000000", "0.00000000"], ["83816.22000000", "0.00000000"], ["83810.50000000", "0.05497000"], ["83797.54000000", "0.00000000"], ["83797.44000000", "0.01000000"], ["83781.09000000", "0.00716000"], ["83762.94000000", "0.01865000"], ["83694.91000000", "0.00000000"], ["83690.82000000", "0.00000000"], ["82883.64000000", "0.00000000"], ["82852.33000000", "0.00080000"], ["82849.86000000", "0.00000000"], ["82698.84000000", "0.00100000"], ["75562.00000000", "0.00000000"], ["67166.58000000", "0.00058000"], ["33000.00000000", "2.96666000"]], "a": [["83958.23000000", "4.08010000"], ["83958.41000000", "0.00007000"], ["83958.59000000", "0.00014000"], ["83958.60000000", "0.06088000"], ["83958.61000000", "0.13481000"], ["83959.98000000", "0.00027000"], ["83959.99000000", "0.00006000"], ["83961.98000000", "0.00000000"], ["83962.00000000", "0.01410000"], ["83962.37000000", "0.08621000"], ["83962.38000000", "0.00000000"], ["83962.39000000", "0.00000000"], ["83962.40000000", "0.00000000"], ["83962.94000000", "0.00000000"], ["83964.78000000", "0.00000000"], ["83964.94000000", "0.00091000"], ["83965.11000000", "0.03365000"], ["83965.77000000", "0.00000000"], ["83966.62000000", "0.40188000"], ["83967.64000000", "0.71486000"], ["83971.67000000", "0.66090000"], ["83972.77000000", "0.78634000"], ["83974.84000000", "1.20508000"], ["83974.85000000", "0.00000000"], ["83975.02000000", "0.00059000"], ["83982.46000000", "0.21959000"], ["83984.77000000", "1.45626000"], ["84004.43000000", "0.00000000"], ["84005.74000000", "0.04110000"], ["84007.60000000", "0.00000000"], ["84010.95000000", "0.03856000"], ["84020.24000000", "0.00000000"], ["84024.22000000", "0.00000000"], ["84030.47000000", "0.00000000"], ["84057.65000000", "0.00000000"], ["84073.35000000", "0.00000000"], ["84116.92000000", "0.00713000"], ["84276.00000000", "0.00215000"], ["84917.96000000", "0.00000000"], ["85217.61000000", "0.00100000"]], "record_time": 1742576923.214933, "EXCHANGE": "BINANCE"}
{"e": "depthUpdate", "E": 1742576924014, "s": "BTCUSDT", "U": 64631969084, "u": 64631969313, "b": [["83958.22000000", "2.86895000"], ["83953.03000000", "0.47675000"], ["83944.60000000", "0.00000000"], ["83936.27000000", "0.00000000"], ["83935.99000000", "1.46771000"], ["83935.60000000", "0.00000000"], ["83933.00000000", "0.00000000"], ["83930.07000000", "0.00000000"], ["83929.50000000", "0.47675000"], ["83923.29000000", "0.00000000"], ["83920.10000000", "0.59965000"], ["83917.20000000", "0.00146000"], ["83916.36000000", "0.00000000"], ["83902.01000000", "0.26485000"], ["83895.65000000", "0.12094000"], ["83894.06000000", "0.05825000"], ["83863.04000000", "0.00146000"], ["83857.83000000", "0.24846000"], ["83856.67000000", "0.16291000"], ["83856.29000000", "0.54970000"], ["83850.12000000", "0.00000000"], ["83849.28000000", "0.05297000"], ["83846.67000000", "0.07024000"], ["83846.06000000", "0.09411000"], ["83845.00000000", "0.26854000"], ["83842.95000000", "0.05097000"], ["83842.67000000", "0.15559000"], ["83841.92000000", "0.05297000"], ["83840.01000000", "0.05497000"], ["83839.77000000", "0.05297000"], ["83839.27000000", "0.05097000"], ["83839.06000000", "0.00000000"], ["83837.35000000", "0.05297000"], ["83835.88000000", "0.05097000"], ["83834.73000000", "0.05297000"], ["83831.78000000", "0.05297000"], ["83810.91000000", "0.00400000"], ["83810.50000000", "0.05097000"], ["83805.32000000", "0.00000000"], ["83779.81000000", "0.00839000"], ["83778.96000000", "0.00000000"], ["83762.94000000", "0.00000000"], ["83690.82000000", "0.00000000"], ["82875.30000000", "0.40000000"], ["82698.84000000", "0.00100000"], ["80589.60000000", "0.00000000"], ["75562.00000000", "0.00000000"], ["67166.58000000", "0.00058000"], ["33000.00000000", "2.96666000"], ["30224.96000000", "0.00220000"]], "a": [["83958.23000000", "3.14038000"], ["83958.60000000", "0.06074000"], ["83958.61000000", "0.00000000"], ["83959.91000000", "0.00014000"], ["83959.92000000", "0.06936000"], ["83959.99000000", "0.00006000"], ["83960.00000000", "0.02622000"], ["83960.92000000", "0.02094000"], ["83961.99000000", "0.02286000"], ["83962.36000000", "0.00000000"], ["83962.37000000", "0.05852000"], ["83962.40000000", "0.00500000"], ["83962.94000000", "0.00000000"], ["83964.94000000", "0.00000000"], ["83965.11000000", "0.00000000"], ["83966.00000000", "0.00000000"], ["83968.51000000", "0.02414000"], ["83971.65000000", "0.00091000"], ["83974.84000000", "0.93676000"], ["83975.21000000", "0.10807000"], ["83976.58000000", "0.00000000"], ["83982.90000000", "0.00000000"], ["83983.21000000", "0.62482000"], ["83984.77000000", "0.00000000"], ["83984.85000000", "1.49766000"], ["83987.64000000", "0.00151000"], ["83997.65000000", "0.00000000"], ["83998.02000000", "0.00000000"], ["83999.95000000", "0.05000000"], ["84005.29000000", "0.00000000"], ["84007.66000000", "0.00000000"], ["84008.28000000", "0.00936000"], ["84009.13000000", "0.00000000"], ["84009.56000000", "0.01872000"], ["84020.20000000", "0.00000000"], ["84020.21000000", "0.00000000"], ["84024.35000000", "0.00000000"], ["84027.23000000", "0.00405000"], ["84029.02000000", "0.00405000"], ["84035.72000000", "0.01865000"], ["84041.26000000", "0.00151000"], ["84054.29000000", "1.22254000"], ["84057.65000000", "0.02383000"], ["84062.59000000", "0.05297000"], ["84086.46000000", "0.00008000"], ["84089.34000000", "0.18348000"], ["84110.02000000", "0.00000000"], ["84177.73000000", "0.00006000"], ["84184.18000000", "0.00000000"], ["84313.94000000", "0.00000000"], ["84408.19000000", "0.00000000"], ["84550.49000000", "0.00000000"], ["84737.21000000", "0.00000000"], ["84909.55000000", "0.60000000"], ["85217.61000000", "0.00100000"], ["85500.00000000", "9.59469000"]], "record_time": 1742576924.214561, "EXCHANGE": "BINANCE"}
{"e": "depthUpdate", "E": 1742577043014, "s": "BTCUSDT", "U": 64632092533, "u": 64632096373, "b": [["83994.23000000", "0.00000000"], ["83994.21000000", "0.00000000"], ["83994.20000000", "0.00000000"], ["83994.11000000", "0.00000000"], ["83993.96000000", "0.00000000"], ["83993.90000000", "0.00000000"], ["83993.89000000", "0.00000000"], ["83993.88000000", "0.00000000"], ["83993.13000000", "0.00000000"], ["83993.04000000", "0.00000000"], ["83991.99000000", "0.00000000"], ["83991.98000000", "0.00000000"], ["83991.67000000", "0.00000000"], ["83991.60000000", "0.00000000"], ["83991.46000000", "0.00000000"], ["83990.64000000", "0.00000000"], ["83990.62000000", "0.00000000"], ["83990.43000000", "0.00000000"], ["83990.42000000", "0.00000000"], ["83990.39000000", "0.00000000"], ["83990.38000000", "0.00000000"], ["83989.93000000", "0.00000000"], ["83989.92000000", "0.00000000"], ["83989.57000000", "0.00000000"], ["83989.56000000", "0.00000000"], ["83989.43000000", "0.00000000"], ["83989.00000000", "0.00000000"], ["83988.95000000", "0.00000000"], ["83988.44000000", "0.00000000"], ["83988.43000000", "0.00000000"], ["83988.07000000", "0.00000000"], ["83988.03000000", "0.00000000"], ["83988.02000000", "0.00000000"], ["83988.00000000", "0.00000000"], ["83987.82000000", "0.00000000"], ["83987.81000000", "0.00000000"], ["83987.80000000", "0.00000000"], ["83987.69000000", "0.00000000"], ["83987.68000000", "0.00000000"], ["83987.40000000", "0.00000000"], ["83987.30000000", "0.00000000"], ["83987.29000000", "0.00000000"], ["83987.28000000", "0.00000000"], ["83987.17000000", "0.00000000"], ["83987.16000000", "0.00000000"], ["83987.15000000", "0.00000000"], ["83987.14000000", "0.00000000"], ["83986.86000000", "0.00000000"], ["83986.82000000", "0.00000000"], ["83986.61000000", "0.00000000"], ["83986.60000000", "0.00000000"], ["83986.55000000", "0.00000000"], ["83986.44000000", "0.00000000"], ["83986.27000000", "0.00000000"], ["83986.18000000", "0.00000000"], ["83986.10000000", "0.00000000"], ["83985.70000000", "0.00000000"], ["83985.61000000", "0.00000000"], ["83985.55000000", "0.00000000"], ["83984.99000000", "0.00000000"], ["83984.98000000", "0.00000000"], ["83984.92000000", "0.00000000"], ["83984.82000000", "0.00000000"], ["83984.77000000", "0.00000000"], ["83984.65000000", "0.00000000"], ["83984.42000000", "0.00000000"], ["83984.36000000", "0.00000000"], ["83984.12000000", "0.00000000"], ["83984.11000000", "0.00000000"], ["83984.07000000", "0.00000000"], ["83984.06000000", "0.26428000"], ["83984.05000000", "0.00066000"], ["83983.94000000", "0.00014000"], ["83983.85000000", "0.00000000"], ["83983.78000000", "0.00000000"], ["83983.62000000", "0.00000000"], ["83983.57000000", "0.00080000"], ["83983.56000000", "0.00007000"], ["83983.50000000", "0.00000000"], ["83983.33000000", "0.00007000"], ["83983.32000000", "0.00007000"], ["83983.31000000", "0.00007000"], ["83983.30000000", "0.00000000"], ["83983.20000000", "0.00000000"], ["83983.19000000", "0.00000000"], ["83983.18000000", "0.00000000"], ["83983.10000000", "0.00007000"], ["83982.98000000", "0.00000000"], ["83982.97000000", "0.00000000"], ["83982.96000000", "0.00006000"], ["83982.89000000", "0.00000000"], ["83982.88000000", "0.00000000"], ["83982.85000000", "0.00000000"], ["83982.84000000", "0.00000000"], ["83982.78000000", "0.00000000"], ["83982.75000000", "0.00000000"], ["83982.74000000", "0.00000000"], ["83982.62000000", "0.00000000"], ["83982.56000000", "0.00000000"], ["83982.50000000", "0.00000000"], ["83982.27000000", "0.00000000"], ["83982.22000000", "0.00000000"], ["83982.21000000", "0.00018000"], ["83982.20000000", "0.00000000"], ["83982.17000000", "0.00000000"], ["83982.07000000", "0.00000000"], ["83982.05000000", "0.00000000"], ["83982.04000000", "0.00000000"], ["83981.97000000", "0.00000000"], ["83981.96000000", "0.00000000"], ["83981.94000000", "0.00000000"], ["83981.83000000", "0.00000000"], ["83981.82000000", "0.00000000"], ["83981.78000000", "0.00000000"], ["83981.74000000", "0.00000000"], ["83981.72000000", "0.00000000"], ["83981.68000000", "0.00000000"], ["83981.64000000", "0.00000000"], ["83981.61000000", "0.00000000"], ["83981.33000000", "0.00014000"], ["83981.32000000", "0.00408000"], ["83981.30000000", "0.00000000"], ["83981.22000000", "0.00014000"], ["83981.21000000", "0.14448000"], ["83981.20000000", "0.00000000"], ["83981.14000000", "0.00036000"], ["83981.13000000", "0.07371000"], ["83980.96000000", "0.00000000"], ["83980.88000000", "0.00000000"], ["83980.86000000", "0.00000000"], ["83980.74000000", "0.00000000"], ["83980.69000000", "0.00000000"], ["83980.65000000", "0.00000000"], ["83980.64000000", "0.00000000"], ["83980.60000000", "0.00000000"], ["83980.56000000", "0.00014000"], ["83980.55000000", "0.34721000"], ["83980.47000000", "0.00000000"], ["83980.36000000", "0.00000000"], ["83980.27000000", "0.00000000"], ["83980.22000000", "0.00000000"], ["83980.20000000", "0.00026000"], ["83980.19000000", "0.02447000"], ["83979.72000000", "0.00000000"], ["83979.67000000", "0.00000000"], ["83979.66000000", "0.00000000"], ["83979.46000000", "0.00000000"], ["83979.39000000", "0.00000000"], ["83979.27000000", "0.02399000"], ["83979.21000000", "0.00000000"], ["83979.00000000", "0.00013000"], ["83978.95000000", "0.00000000"], ["83978.82000000", "0.00000000"], ["83978.69000000", "0.05364000"], ["83978.62000000", "0.00000000"], ["83978.50000000", "0.00000000"], ["83978.49000000", "0.02976000"], ["83978.18000000", "0.00000000"], ["83978.17000000", "0.06262000"], ["83977.98000000", "0.00000000"], ["83977.86000000", "0.00000000"], ["83977.85000000", "0.00000000"], ["83977.84000000", "0.00000000"], ["83977.79000000", "0.00000000"], ["83977.78000000", "0.00000000"], ["83977.75000000", "0.00000000"], ["83977.66000000", "0.02212000"], ["83977.62000000", "0.04000000"], ["83977.52000000", "0.00000000"], ["83977.44000000", "0.00000000"], ["83977.17000000", "0.00000000"], ["83977.00000000", "0.00000000"], ["83976.93000000", "0.00000000"], ["83976.92000000", "0.14000000"], ["83976.77000000", "0.00000000"], ["83976.76000000", "0.00000000"], ["83976.72000000", "0.00000000"], ["83976.44000000", "0.14822000"], ["83976.38000000", "0.00000000"], ["83976.18000000", "0.00000000"], ["83976.17000000", "0.00000000"], ["83976.06000000", "0.00000000"], ["83976.01000000", "0.00887000"], ["83975.88000000", "0.00000000"], ["83975.78000000", "0.00000000"], ["83975.51000000", "0.00029000"], ["83975.41000000", "0.00000000"], ["83975.26000000", "0.00000000"], ["83975.04000000", "0.00000000"], ["83974.81000000", "0.00000000"], ["83974.65000000", "0.04000000"], ["83974.33000000", "0.00000000"], ["83974.28000000", "0.48754000"], ["83974.19000000", "0.00423000"], ["83974.17000000", "0.16172000"], ["83973.81000000", "0.00000000"], ["83973.80000000", "0.00000000"], ["83973.21000000", "0.00000000"], ["83972.99000000", "0.04000000"], ["83972.97000000", "0.04000000"], ["83972.88000000", "0.04006000"], ["83972.85000000", "0.00000000"], ["83972.71000000", "0.00119000"], ["83972.55000000", "0.00000000"], ["83972.36000000", "0.00000000"], ["83971.69000000", "0.00050000"], ["83971.68000000", "0.00000000"], ["83971.46000000", "0.39275000"], ["83971.01000000", "0.00000000"], ["83970.62000000", "0.01500000"], ["83970.46000000", "0.04000000"], ["83970.38000000", "0.00059000"], ["83970.36000000", "0.16000000"], ["83970.10000000", "0.00007000"], ["83970.09000000", "0.00095000"], ["83970.07000000", "0.00000000"], ["83970.03000000", "0.00092000"], ["83969.97000000", "0.04000000"], ["83969.78000000", "0.01500000"], ["83969.61000000", "0.26476000"], ["83969.04000000", "0.00300000"], ["83968.94000000", "0.00083000"], ["83968.93000000", "0.00000000"], ["83968.79000000", "0.04000000"], ["83968.77000000", "0.00000000"], ["83968.70000000", "0.20706000"], ["83968.68000000", "0.04000000"], ["83968.67000000", "0.00000000"], ["83968.13000000", "0.00000000"], ["83967.79000000", "0.00132000"], ["83967.61000000", "0.00000000"], ["83967.60000000", "0.02356000"], ["83967.58000000", "0.00000000"], ["83967.51000000", "0.00000000"], ["83967.41000000", "0.00069000"], ["83967.40000000", "0.00000000"], ["83967.37000000", "0.00000000"], ["83967.26000000", "0.00300000"], ["83967.04000000", "0.00000000"], ["83967.03000000", "0.00000000"], ["83967.02000000", "0.00000000"], ["83966.98000000", "0.00000000"], ["83966.86000000", "0.00000000"], ["83966.75000000", "0.00000000"], ["83966.72000000", "0.00120000"], ["83966.55000000", "0.00000000"], ["83966.51000000", "0.00000000"], ["83966.45000000", "0.00000000"], ["83965.95000000", "0.00000000"], ["83965.85000000", "0.34074000"], ["83965.62000000", "0.00000000"], ["83964.92000000", "0.04000000"], ["83964.91000000", "0.15057000"], ["83964.54000000", "0.00000000"], ["83963.80000000", "0.00000000"], ["83963.64000000", "0.00504000"], ["83963.38000000", "0.00000000"], ["83962.65000000", "0.00000000"], ["83962.21000000", "0.00000000"], ["83962.15000000", "0.03573000"], ["83961.92000000", "0.00000000"], ["83961.80000000", "0.00007000"], ["83961.70000000", "0.70661000"], ["83961.44000000", "0.10787000"], ["83960.75000000", "0.00000000"], ["83960.71000000", "0.00000000"], ["83960.14000000", "0.05956000"], ["83958.87000000", "0.00000000"], ["83958.86000000", "0.00300000"], ["83958.78000000", "0.00000000"], ["83957.67000000", "0.35737000"], ["83957.66000000", "0.00000000"], ["83957.56000000", "1.06080000"], ["83957.55000000", "0.00000000"], ["83957.45000000", "1.36503000"], ["83957.43000000", "0.00753000"], ["83956.92000000", "0.00000000"], ["83956.91000000", "0.85799000"], ["83956.90000000", "0.00000000"], ["83956.89000000", "0.00000000"], ["83956.87000000", "0.00000000"], ["83956.56000000", "0.89344000"], ["83956.36000000", "0.00000000"], ["83956.05000000", "0.12150000"], ["83955.97000000", "0.00000000"], ["83955.36000000", "0.00120000"], ["83954.49000000", "0.00000000"], ["83954.29000000", "0.00000000"], ["83953.74000000", "0.59564000"], ["83953.40000000", "1.10041000"], ["83953.17000000", "0.00000000"], ["83952.93000000", "0.00000000"], ["83952.03000000", "0.00000000"], ["83952.02000000", "0.00000000"], ["83951.48000000", "0.85804000"], ["83951.33000000", "0.00000000"], ["83951.30000000", "0.36353000"], ["83951.02000000", "0.89344000"], ["83950.48000000", "0.00922000"], ["83950.01000000", "0.00000000"], ["83949.60000000", "0.00006000"], ["83949.11000000", "0.00358000"], ["83948.39000000", "0.00000000"], ["83948.38000000", "0.00000000"], ["83948.27000000", "0.00000000"], ["83948.11000000", "0.13619000"], ["83947.76000000", "0.00000000"], ["83946.65000000", "0.00000000"], ["83945.66000000", "0.00146000"], ["83945.65000000", "0.08441000"], ["83945.47000000", "0.00000000"], ["83945.29000000", "0.36636000"], ["83945.17000000", "0.00059000"], ["83944.96000000", "1.27199000"], ["83944.21000000", "0.00000000"], ["83943.97000000", "0.89344000"], ["83943.33000000", "0.05621000"], ["83943.15000000", "0.00000000"], ["83943.12000000", "0.00000000"], ["83942.92000000", "0.21086000"], ["83942.52000000", "0.89344000"], ["83942.37000000", "0.50932000"], ["83940.56000000", "0.04762000"], ["83940.09000000", "0.00000000"], ["83939.73000000", "0.04643000"], ["83938.93000000", "0.03346000"], ["83938.45000000", "0.04643000"], ["83938.25000000", "0.02552000"], ["83938.14000000", "0.00000000"], ["83938.01000000", "0.09405000"], ["83937.52000000", "0.00470000"], ["83937.51000000", "0.05000000"], ["83937.46000000", "0.00000000"], ["83937.39000000", "0.00000000"], ["83937.14000000", "0.00000000"], ["83936.84000000", "0.04762000"], ["83936.63000000", "0.00297000"], ["83936.62000000", "0.00000000"], ["83936.54000000", "0.92378000"], ["83936.10000000", "0.01191000"], ["83935.78000000", "0.28578000"], ["83935.30000000", "0.00000000"], ["83934.79000000", "0.04762000"], ["83933.98000000", "0.00000000"], ["83932.59000000", "0.26716000"], ["83932.55000000", "0.00000000"], ["83930.54000000", "0.00000000"], ["83930.03000000", "0.00000000"], ["83929.95000000", "0.00000000"], ["83929.90000000", "0.00000000"], ["83928.45000000", "0.05162000"], ["83928.01000000", "0.00294000"], ["83927.93000000", "0.00000000"], ["83927.84000000", "0.04490000"], ["83927.43000000", "0.06102000"], ["83926.84000000", "0.00000000"], ["83926.81000000", "0.00000000"], ["83925.59000000", "0.00000000"], ["83924.51000000", "0.00810000"], ["83924.39000000", "0.00000000"], ["83923.62000000", "0.00000000"], ["83923.56000000", "0.00000000"], ["83923.10000000", "0.00000000"], ["83922.99000000", "0.13219000"], ["83922.98000000", "0.00000000"], ["83922.62000000", "0.00000000"], ["83922.60000000", "0.00813000"], ["83922.19000000", "0.04000000"], ["83922.15000000", "0.04000000"], ["83920.81000000", "0.00000000"], ["83920.01000000", "0.00263000"], ["83919.92000000", "0.02846000"], ["83919.19000000", "0.02015000"], ["83919.08000000", "0.00000000"], ["83918.95000000", "0.00816000"], ["83918.70000000", "0.44492000"], ["83918.20000000", "0.02890000"], ["83918.06000000", "0.10138000"], ["83917.40000000", "0.00000000"], ["83916.26000000", "0.05097000"], ["83916.16000000", "0.00857000"], ["83915.99000000", "0.00000000"], ["83915.56000000", "0.00061000"], ["83915.52000000", "0.00358000"], ["83915.08000000", "0.00000000"], ["83914.79000000", "0.00000000"], ["83914.35000000", "0.24502000"], ["83914.30000000", "0.04000000"], ["83914.05000000", "0.60276000"], ["83913.04000000", "0.25862000"], ["83912.92000000", "0.09653000"], ["83912.65000000", "0.15356000"], ["83912.36000000", "0.00000000"], ["83912.26000000", "0.00000000"], ["83911.68000000", "0.20452000"], ["83910.60000000", "0.10616000"], ["83910.59000000", "0.04761000"], ["83910.12000000", "0.24918000"], ["83910.03000000", "0.04440000"], ["83909.32000000", "0.84383000"], ["83909.20000000", "0.00000000"], ["83908.79000000", "0.46681000"], ["83906.90000000", "0.83015000"], ["83906.40000000", "0.20115000"], ["83906.32000000", "0.00000000"], ["83905.54000000", "0.37225000"], ["83904.79000000", "0.26549000"], ["83904.04000000", "0.05279000"], ["83903.98000000", "0.27085000"], ["83903.26000000", "0.18803000"], ["83902.90000000", "0.00000000"], ["83902.48000000", "0.00000000"], ["83901.34000000", "0.10594000"], ["83901.23000000", "0.00000000"], ["83901.16000000", "0.00000000"], ["83901.13000000", "0.00000000"], ["83900.61000000", "0.00000000"], ["83899.42000000", "0.00000000"], ["83899.27000000", "0.00000000"], ["83898.31000000", "1.35627000"], ["83898.30000000", "1.74381000"], ["83898.29000000", "0.27876000"], ["83898.02000000", "0.00000000"], ["83898.01000000", "0.14393000"], ["83897.45000000", "0.09495000"], ["83897.01000000", "0.00000000"], ["83896.59000000", "0.14139000"], ["83895.01000000", "0.36488000"], ["83894.14000000", "0.04762000"], ["83892.23000000", "0.09524000"], ["83892.04000000", "0.04762000"], ["83891.09000000", "0.14166000"], ["83890.58000000", "0.58604000"], ["83890.23000000", "0.05097000"], ["83890.21000000", "0.00000000"], ["83889.06000000", "0.38869000"], ["83888.92000000", "0.00000000"], ["83888.70000000", "0.14902000"], ["83888.65000000", "0.04762000"], ["83888.56000000", "0.09404000"], ["83888.11000000", "0.05097000"], ["83888.01000000", "0.18927000"], ["83887.48000000", "0.27162000"], ["83887.09000000", "0.04642000"], ["83886.62000000", "0.01196000"], ["83886.30000000", "0.00000000"], ["83886.26000000", "0.04762000"], ["83885.89000000", "0.04762000"], ["83885.86000000", "0.52661000"], ["83885.67000000", "0.04762000"], ["83885.51000000", "0.05097000"], ["83884.68000000", "0.18926000"], ["83883.27000000", "0.00013000"], ["83883.11000000", "0.10394000"], ["83883.02000000", "0.00000000"], ["83882.90000000", "0.00000000"], ["83882.85000000", "0.04762000"], ["83882.47000000", "0.05497000"], ["83882.46000000", "0.00000000"], ["83882.00000000", "0.07027000"], ["83881.45000000", "0.00000000"], ["83880.91000000", "0.05097000"], ["83880.43000000", "0.14299000"], ["83880.25000000", "0.00000000"], ["83878.80000000", "0.05497000"], ["83877.81000000", "0.04762000"], ["83877.68000000", "0.00000000"], ["83876.81000000", "0.05497000"], ["83876.73000000", "0.05097000"], ["83876.51000000", "0.34748000"], ["83875.67000000", "0.05503000"], ["83875.13000000", "0.04762000"], ["83874.44000000", "0.05297000"], ["83874.42000000", "0.00000000"], ["83874.15000000", "0.00000000"], ["83873.56000000", "0.05497000"], ["83873.32000000", "0.05497000"], ["83872.80000000", "0.05097000"], ["83872.69000000", "0.05097000"], ["83872.29000000", "0.10000000"], ["83871.68000000", "0.00000000"], ["83871.46000000", "0.00000000"], ["83871.40000000", "0.04198000"], ["83871.19000000", "0.00000000"], ["83870.87000000", "0.00000000"], ["83870.18000000", "0.05097000"], ["83868.82000000", "0.05497000"], ["83868.81000000", "0.05497000"], ["83868.21000000", "0.05097000"], ["83867.99000000", "0.04198000"], ["83867.57000000", "0.04597000"], ["83867.48000000", "0.05497000"], ["83866.91000000", "0.05097000"], ["83865.49000000", "0.05497000"], ["83865.26000000", "0.31372000"], ["83865.00000000", "0.09495000"], ["83864.72000000", "0.05497000"], ["83864.53000000", "0.05497000"], ["83864.26000000", "0.05297000"], ["83864.13000000", "0.05097000"], ["83863.83000000", "0.04198000"], ["83863.69000000", "0.05497000"], ["83863.15000000", "0.05497000"], ["83862.64000000", "0.05497000"], ["83862.41000000", "0.04597000"], ["83861.98000000", "0.05297000"], ["83861.38000000", "0.05497000"], ["83861.32000000", "0.05097000"], ["83860.95000000", "0.54133000"], ["83860.82000000", "0.05497000"], ["83860.38000000", "0.05497000"], ["83860.35000000", "0.05497000"], ["83860.05000000", "0.04597000"], ["83859.64000000", "0.05297000"], ["83859.21000000", "0.04897000"], ["83858.93000000", "0.11722000"], ["83858.13000000", "0.05097000"], ["83857.65000000", "0.04597000"], ["83857.62000000", "0.04198000"], ["83857.59000000", "0.04897000"], ["83857.56000000", "0.04197000"], ["83857.49000000", "0.05497000"], ["83857.08000000", "0.05303000"], ["83857.00000000", "0.12126000"], ["83856.99000000", "0.05497000"], ["83856.02000000", "0.00000000"], ["83855.92000000", "0.04897000"], ["83855.23000000", "0.00000000"], ["83854.13000000", "0.05297000"], ["83854.07000000", "0.04597000"], ["83853.62000000", "0.04597000"], ["83852.59000000", "0.17817000"], ["83852.01000000", "0.00000000"], ["83851.96000000", "0.04897000"], ["83851.02000000", "0.04198000"], ["83848.74000000", "0.04897000"], ["83848.25000000", "0.70728000"], ["83847.58000000", "0.04597000"], ["83846.71000000", "0.00000000"], ["83846.70000000", "0.01526000"], ["83840.54000000", "0.00324000"], ["83838.19000000", "0.00006000"], ["83837.28000000", "0.00000000"], ["83833.20000000", "0.00000000"], ["83831.75000000", "0.00000000"], ["83829.32000000", "0.00000000"], ["83828.93000000", "0.00000000"], ["83825.29000000", "0.01192000"], ["83823.81000000", "0.00000000"], ["83818.88000000", "0.00000000"], ["83811.39000000", "0.99313000"], ["83792.16000000", "0.16356000"], ["83789.43000000", "0.45000000"], ["83783.76000000", "0.00135000"], ["83770.67000000", "0.00013000"], ["83762.32000000", "0.00000000"], ["83756.94000000", "0.00000000"], ["83756.93000000", "0.00000000"], ["83755.70000000", "0.00013000"], ["83753.92000000", "0.00000000"], ["83751.82000000", "0.00400000"], ["83751.51000000", "0.00013000"], ["83747.69000000", "0.00000000"], ["83747.34000000", "0.00000000"], ["83618.05000000", "0.00000000"], ["83618.01000000", "0.00040000"], ["83343.13000000", "0.00119000"], ["82881.66000000", "0.00000000"], ["82881.54000000", "0.00040000"], ["82848.34000000", "0.00000000"], ["82724.29000000", "0.00100000"], ["75594.00000000", "0.00000000"], ["67195.39000000", "0.00000000"], ["67189.74000000", "0.00000000"], ["67187.25000000", "0.00058000"], ["33000.00000000", "2.96666000"], ["30234.26000000", "0.00060000"]], "a": [["83984.07000000", "8.99736000"], ["83984.08000000", "0.00047000"], ["83984.12000000", "0.00007000"], ["83984.66000000", "0.00007000"], ["83984.76000000", "0.00007000"], ["83985.00000000", "0.00021000"], ["83985.01000000", "0.77634000"], ["83985.02000000", "0.00007000"], ["83985.03000000", "0.00000000"], ["83985.45000000", "0.00000000"], ["83985.46000000", "0.00000000"], ["83985.56000000", "0.00000000"], ["83985.74000000", "0.01190000"], ["83985.99000000", "0.00000000"], ["83986.00000000", "0.01416000"], ["83986.06000000", "0.00000000"], ["83986.07000000", "0.00000000"], ["83986.45000000", "0.00000000"], ["83986.87000000", "0.00000000"], ["83986.88000000", "0.78627000"], ["83987.04000000", "0.00000000"], ["83987.05000000", "0.00000000"], ["83987.06000000", "0.00000000"], ["83987.13000000", "0.00000000"], ["83987.14000000", "0.00000000"], ["83987.15000000", "0.00000000"], ["83987.16000000", "0.00000000"], ["83987.17000000", "0.45006000"], ["83987.18000000", "1.46295000"], ["83987.19000000", "0.00000000"], ["83987.26000000", "0.00000000"], ["83987.27000000", "0.00000000"], ["83987.28000000", "0.00000000"], ["83987.29000000", "0.00000000"], ["83987.30000000", "0.00000000"], ["83987.31000000", "0.00000000"], ["83987.41000000", "0.00000000"], ["83987.69000000", "0.00000000"], ["83987.70000000", "0.00000000"], ["83987.81000000", "0.00000000"], ["83987.82000000", "0.00000000"], ["83987.83000000", "0.00000000"], ["83987.94000000", "0.02323000"], ["83988.00000000", "0.01416000"], ["83988.01000000", "0.00000000"], ["83988.02000000", "0.00000000"], ["83988.03000000", "0.00000000"], ["83988.04000000", "0.00000000"], ["83988.22000000", "0.02441000"], ["83988.53000000", "0.00760000"], ["83988.85000000", "0.00000000"], ["83988.94000000", "0.00000000"], ["83988.96000000", "0.00000000"], ["83989.00000000", "0.58243000"], ["83989.01000000", "0.51236000"], ["83989.02000000", "0.00000000"], ["83989.09000000", "0.13505000"], ["83989.29000000", "0.00000000"], ["83989.32000000", "0.00000000"], ["83989.40000000", "0.00000000"], ["83989.43000000", "0.00000000"], ["83989.44000000", "0.00000000"], ["83989.45000000", "0.00000000"], ["83989.47000000", "0.00000000"], ["83989.56000000", "0.17899000"], ["83989.57000000", "0.04000000"], ["83989.82000000", "0.00000000"], ["83989.92000000", "0.00000000"], ["83989.93000000", "0.53580000"], ["83989.94000000", "0.00000000"], ["83990.00000000", "0.01410000"], ["83990.13000000", "0.15590000"], ["83990.29000000", "0.00000000"], ["83990.36000000", "0.00922000"], ["83990.39000000", "0.00000000"], ["83990.40000000", "0.00000000"], ["83990.42000000", "0.00000000"], ["83990.43000000", "0.08580000"], ["83990.44000000", "0.00000000"], ["83990.65000000", "0.00000000"], ["83990.68000000", "0.00000000"], ["83990.97000000", "0.00000000"], ["83991.05000000", "0.00000000"], ["83991.06000000", "0.00000000"], ["83991.25000000", "0.00000000"], ["83991.35000000", "0.00000000"], ["83991.40000000", "0.00000000"], ["83991.47000000", "0.08580000"], ["83991.60000000", "0.00013000"], ["83991.67000000", "0.00000000"], ["83991.68000000", "0.00000000"], ["83991.70000000", "0.00000000"], ["83991.86000000", "0.00000000"], ["83991.98000000", "0.00000000"], ["83991.99000000", "0.34249000"], ["83992.00000000", "0.09990000"], ["83992.14000000", "0.00000000"], ["83992.37000000", "0.00029000"], ["83992.49000000", "0.00000000"], ["83992.57000000", "0.00000000"], ["83993.02000000", "0.00000000"], ["83993.03000000", "0.00006000"], ["83993.05000000", "0.00000000"], ["83993.11000000", "0.06800000"], ["83993.14000000", "0.13080000"], ["83993.29000000", "0.09200000"], ["83993.48000000", "0.06000000"], ["83993.58000000", "0.00000000"], ["83993.65000000", "0.00000000"], ["83993.73000000", "0.00000000"], ["83993.74000000", "0.00000000"], ["83993.89000000", "0.00000000"], ["83993.90000000", "0.00000000"], ["83993.91000000", "0.09500000"], ["83993.95000000", "0.00000000"], ["83993.96000000", "0.00000000"], ["83993.97000000", "0.00000000"], ["83994.00000000", "0.01410000"], ["83994.05000000", "0.00000000"], ["83994.06000000", "0.03580000"], ["83994.12000000", "0.00000000"], ["83994.21000000", "0.00000000"], ["83994.22000000", "0.00000000"], ["83994.23000000", "0.00000000"], ["83994.24000000", "0.10811000"], ["83994.25000000", "0.08354000"], ["83994.26000000", "0.00000000"], ["83994.49000000", "0.00201000"], ["83994.50000000", "0.00000000"], ["83994.55000000", "0.00013000"], ["83994.95000000", "0.14400000"], ["83995.06000000", "0.06400000"], ["83995.12000000", "0.03284000"], ["83995.31000000", "0.00119000"], ["83995.47000000", "0.00000000"], ["83995.48000000", "0.08000000"], ["83995.62000000", "0.00000000"], ["83995.63000000", "0.00000000"], ["83995.64000000", "0.00000000"], ["83995.72000000", "0.00000000"], ["83995.80000000", "0.00006000"], ["83995.82000000", "0.10787000"], ["83995.90000000", "0.00000000"], ["83995.91000000", "0.00000000"], ["83995.99000000", "0.64387000"], ["83996.00000000", "0.90754000"], ["83996.08000000", "0.00009000"], ["83996.72000000", "0.00000000"], ["83997.48000000", "0.06400000"], ["83997.58000000", "0.00000000"], ["83997.79000000", "0.05956000"], ["83997.93000000", "0.00000000"], ["83997.94000000", "0.02346000"], ["83997.97000000", "0.17899000"], ["83997.98000000", "0.00000000"], ["83998.00000000", "0.01410000"], ["83998.07000000", "0.00006000"], ["83998.11000000", "0.00000000"], ["83998.14000000", "0.04800000"], ["83998.26000000", "0.00000000"], ["83998.31000000", "0.06000000"], ["83998.50000000", "0.00013000"], ["83998.53000000", "0.00000000"], ["83998.71000000", "0.00000000"], ["83998.76000000", "0.45000000"], ["83999.17000000", "0.05200000"], ["83999.25000000", "0.07200000"], ["83999.26000000", "0.00000000"], ["83999.36000000", "0.35742000"], ["83999.51000000", "0.00000000"], ["83999.65000000", "0.00000000"], ["84000.00000000", "0.01440000"], ["84000.60000000", "0.05956000"], ["84000.86000000", "0.11912000"], ["84001.11000000", "0.02808000"], ["84001.18000000", "0.00000000"], ["84001.60000000", "0.00000000"], ["84001.88000000", "0.87472000"], ["84001.89000000", "0.89344000"], ["84001.98000000", "0.00013000"], ["84002.01000000", "0.00000000"], ["84002.02000000", "0.00000000"], ["84002.04000000", "0.16000000"], ["84002.47000000", "0.00414000"], ["84002.54000000", "0.00000000"], ["84002.66000000", "0.01190000"], ["84002.85000000", "0.00000000"], ["84002.95000000", "0.00000000"], ["84002.97000000", "0.00007000"], ["84002.98000000", "0.00000000"], ["84003.14000000", "0.00000000"], ["84003.15000000", "0.10495000"], ["84003.60000000", "0.04000000"], ["84003.77000000", "0.89344000"], ["84003.95000000", "0.71399000"], ["84003.96000000", "0.89344000"], ["84003.98000000", "0.00059000"], ["84004.20000000", "0.02371000"], ["84004.26000000", "0.00000000"], ["84004.31000000", "0.00000000"], ["84004.34000000", "0.55845000"], ["84005.37000000", "0.00000000"], ["84005.78000000", "0.00000000"], ["84006.21000000", "0.00000000"], ["84006.27000000", "0.00000000"], ["84006.83000000", "0.00000000"], ["84006.95000000", "0.05000000"], ["84007.03000000", "0.00000000"], ["84007.05000000", "0.00000000"], ["84007.06000000", "0.00000000"], ["84007.14000000", "0.00000000"], ["84007.37000000", "0.00000000"], ["84007.46000000", "0.00000000"], ["84007.47000000", "0.00000000"], ["84007.56000000", "0.00000000"], ["84007.60000000", "1.34533000"], ["84008.00000000", "0.00000000"], ["84008.11000000", "0.00000000"], ["84008.94000000", "0.17899000"], ["84009.05000000", "0.00000000"], ["84009.95000000", "0.99414000"], ["84009.97000000", "0.00000000"], ["84009.99000000", "0.17456000"], ["84010.00000000", "0.00644000"], ["84010.82000000", "0.00000000"], ["84011.00000000", "0.00500000"], ["84011.04000000", "0.00000000"], ["84011.10000000", "0.00013000"], ["84011.49000000", "0.85743000"], ["84011.66000000", "0.00000000"], ["84011.69000000", "0.00000000"], ["84011.84000000", "0.01864000"], ["84012.00000000", "0.00000000"], ["84012.53000000", "0.00000000"], ["84012.58000000", "0.00000000"], ["84012.68000000", "0.00000000"], ["84012.88000000", "0.00160000"], ["84012.89000000", "0.00000000"], ["84012.90000000", "1.35785000"], ["84013.00000000", "0.89344000"], ["84013.12000000", "0.00000000"], ["84013.36000000", "0.00000000"], ["84014.00000000", "0.00000000"], ["84014.66000000", "0.00000000"], ["84014.67000000", "0.28699000"], ["84014.88000000", "0.00000000"], ["84015.29000000", "0.00000000"], ["84015.50000000", "0.45530000"], ["84015.56000000", "0.00000000"], ["84015.67000000", "0.89344000"], ["84016.87000000", "0.71182000"], ["84016.93000000", "0.00238000"], ["84017.69000000", "0.00000000"], ["84018.07000000", "0.00000000"], ["84018.38000000", "0.00000000"], ["84018.66000000", "0.00000000"], ["84018.67000000", "0.00000000"], ["84019.20000000", "0.00000000"], ["84019.45000000", "0.00000000"], ["84020.68000000", "0.00640000"], ["84021.48000000", "0.05858000"], ["84021.56000000", "0.00000000"], ["84021.66000000", "0.00000000"], ["84021.87000000", "0.00000000"], ["84022.88000000", "0.00000000"], ["84023.43000000", "0.00000000"], ["84024.19000000", "0.00000000"], ["84024.82000000", "0.00000000"], ["84025.27000000", "0.58089000"], ["84026.27000000", "0.21066000"], ["84026.72000000", "0.03533000"], ["84026.78000000", "0.00059000"], ["84027.41000000", "0.00000000"], ["84027.85000000", "0.00000000"], ["84028.21000000", "0.00000000"], ["84028.25000000", "0.00000000"], ["84029.17000000", "0.00072000"], ["84029.59000000", "0.00000000"], ["84030.03000000", "0.00000000"], ["84030.93000000", "0.00000000"], ["84032.22000000", "0.12039000"], ["84032.43000000", "0.00852000"], ["84032.64000000", "1.41670000"], ["84033.31000000", "0.00000000"], ["84033.60000000", "0.00006000"], ["84034.38000000", "0.00815000"], ["84034.46000000", "0.04762000"], ["84034.57000000", "0.00000000"], ["84034.58000000", "0.00000000"], ["84035.01000000", "0.04643000"], ["84035.16000000", "0.06800000"], ["84035.33000000", "0.74854000"], ["84035.34000000", "0.17554000"], ["84035.35000000", "0.50343000"], ["84035.56000000", "0.00805000"], ["84036.54000000", "0.00000000"], ["84036.79000000", "0.01204000"], ["84037.01000000", "0.14400000"], ["84037.18000000", "0.00000000"], ["84038.17000000", "0.05306000"], ["84038.64000000", "0.09286000"], ["84038.78000000", "0.15621000"], ["84039.21000000", "0.00000000"], ["84039.97000000", "0.00000000"], ["84040.19000000", "0.04800000"], ["84040.37000000", "0.06000000"], ["84041.00000000", "0.00828000"], ["84041.31000000", "0.07200000"], ["84041.97000000", "0.16383000"], ["84042.11000000", "0.41323000"], ["84043.41000000", "0.00000000"], ["84044.03000000", "0.00000000"], ["84045.97000000", "0.04198000"], ["84046.42000000", "0.04110000"], ["84049.74000000", "0.00000000"], ["84049.77000000", "0.00000000"], ["84050.11000000", "0.00000000"], ["84051.67000000", "0.04198000"], ["84054.72000000", "0.04198000"], ["84055.19000000", "1.05170000"], ["84059.21000000", "0.04597000"], ["84059.99000000", "0.07925000"], ["84061.23000000", "0.04597000"], ["84061.39000000", "0.06000000"], ["84062.70000000", "0.00000000"], ["84063.31000000", "0.60835000"], ["84063.32000000", "1.02786000"], ["84063.43000000", "0.00000000"], ["84063.80000000", "0.04597000"], ["84064.41000000", "0.00000000"], ["84064.47000000", "0.00000000"], ["84064.75000000", "0.02831000"], ["84065.30000000", "0.04897000"], ["84065.39000000", "0.00000000"], ["84066.92000000", "0.09494000"], ["84067.99000000", "0.04597000"], ["84069.91000000", "0.09494000"], ["84072.50000000", "0.09635000"], ["84072.84000000", "0.04897000"], ["84073.80000000", "0.04597000"], ["84074.01000000", "0.00000000"], ["84074.86000000", "0.09859000"], ["84075.47000000", "0.04762000"], ["84076.27000000", "0.09359000"], ["84077.67000000", "0.14302000"], ["84078.14000000", "0.04762000"], ["84079.40000000", "0.04762000"], ["84079.42000000", "0.00000000"], ["84079.99000000", "0.18764000"], ["84080.26000000", "0.04762000"], ["84080.27000000", "0.00000000"], ["84080.60000000", "0.65495000"], ["84081.07000000", "0.09405000"], ["84081.08000000", "0.00000000"], ["84081.09000000", "0.00000000"], ["84081.10000000", "0.00000000"], ["84081.79000000", "0.00060000"], ["84082.24000000", "0.00000000"], ["84082.54000000", "0.14421000"], ["84082.57000000", "0.05059000"], ["84083.99000000", "0.09894000"], ["84084.02000000", "0.17662000"], ["84084.46000000", "0.00000000"], ["84085.22000000", "0.09659000"], ["84085.30000000", "0.00000000"], ["84085.98000000", "0.09859000"], ["84086.85000000", "0.09659000"], ["84087.96000000", "0.09894000"], ["84088.48000000", "0.04915000"], ["84090.10000000", "0.10394000"], ["84090.71000000", "0.04897000"], ["84092.08000000", "0.00000000"], ["84092.46000000", "0.00000000"], ["84092.68000000", "0.04597000"], ["84093.44000000", "0.56543000"], ["84093.45000000", "0.63149000"], ["84093.67000000", "0.10394000"], ["84095.67000000", "0.17541000"], ["84095.99000000", "0.04597000"], ["84096.82000000", "0.15291000"], ["84099.53000000", "0.05097000"], ["84100.49000000", "0.04897000"], ["84101.07000000", "0.05297000"], ["84101.47000000", "0.05497000"], ["84102.14000000", "0.04597000"], ["84103.21000000", "0.10394000"], ["84104.03000000", "0.05016000"], ["84105.00000000", "0.00000000"], ["84106.17000000", "0.04897000"], ["84109.40000000", "0.00000000"], ["84110.17000000", "0.04643000"], ["84110.71000000", "0.05497000"], ["84110.76000000", "0.00000000"], ["84111.37000000", "0.00000000"], ["84112.15000000", "0.04897000"], ["84112.40000000", "0.00000000"], ["84112.73000000", "0.00000000"], ["84112.74000000", "0.00000000"], ["84113.07000000", "0.05497000"], ["84113.33000000", "0.05297000"], ["84113.40000000", "0.00000000"], ["84113.67000000", "0.00000000"], ["84113.87000000", "0.00000000"], ["84114.24000000", "0.00000000"], ["84115.38000000", "0.00000000"], ["84115.56000000", "0.10394000"], ["84115.83000000", "0.04761000"], ["84115.86000000", "0.00000000"], ["84116.14000000", "0.00000000"], ["84116.43000000", "0.00000000"], ["84117.31000000", "0.00000000"], ["84117.52000000", "0.00000000"], ["84117.91000000", "0.40460000"], ["84117.92000000", "0.00000000"], ["84119.04000000", "0.00000000"], ["84119.66000000", "0.04597000"], ["84120.28000000", "0.00000000"], ["84120.41000000", "0.00000000"], ["84121.10000000", "0.00000000"], ["84121.25000000", "0.00000000"], ["84121.27000000", "0.00000000"], ["84121.72000000", "0.00000000"], ["84121.83000000", "0.00000000"], ["84122.38000000", "0.00000000"], ["84122.39000000", "0.00000000"], ["84122.48000000", "0.00000000"], ["84122.62000000", "0.68750000"], ["84123.40000000", "0.00000000"], ["84123.51000000", "0.00000000"], ["84123.90000000", "0.00000000"], ["84123.95000000", "0.00000000"], ["84124.22000000", "0.00000000"], ["84124.27000000", "0.00000000"], ["84124.32000000", "0.00000000"], ["84124.33000000", "0.00000000"], ["84124.71000000", "0.00000000"], ["84125.17000000", "0.00000000"], ["84125.22000000", "0.00000000"], ["84125.24000000", "0.00000000"], ["84125.43000000", "0.00000000"], ["84125.48000000", "0.00000000"], ["84125.93000000", "1.54832000"], ["84125.96000000", "0.00000000"], ["84126.01000000", "0.00000000"], ["84126.02000000", "0.00000000"], ["84126.04000000", "0.00000000"], ["84126.07000000", "0.00000000"], ["84126.33000000", "0.00000000"], ["84126.36000000", "0.00119000"], ["84126.75000000", "0.00000000"], ["84126.85000000", "0.00000000"], ["84126.97000000", "0.00000000"], ["84127.06000000", "0.00000000"], ["84127.22000000", "0.00000000"], ["84127.42000000", "0.00000000"], ["84127.50000000", "0.00000000"], ["84127.63000000", "0.00000000"], ["84127.74000000", "0.00000000"], ["84127.87000000", "0.00000000"], ["84127.92000000", "0.00000000"], ["84128.20000000", "0.00000000"], ["84128.55000000", "0.00000000"], ["84128.57000000", "0.00000000"], ["84128.80000000", "0.00000000"], ["84128.81000000", "0.00000000"], ["84129.02000000", "0.00000000"], ["84129.03000000", "0.00000000"], ["84129.29000000", "0.00000000"], ["84129.60000000", "0.00000000"], ["84129.63000000", "0.00000000"], ["84129.94000000", "0.00000000"], ["84130.21000000", "0.00000000"], ["84130.49000000", "0.00000000"], ["84130.69000000", "0.00000000"], ["84130.89000000", "0.00000000"], ["84131.57000000", "0.00000000"], ["84131.73000000", "0.00000000"], ["84131.80000000", "0.00000000"], ["84133.15000000", "0.00000000"], ["84133.20000000", "0.00000000"], ["84133.34000000", "0.00000000"], ["84133.43000000", "0.00000000"], ["84133.55000000", "0.00000000"], ["84133.71000000", "0.00000000"], ["84134.08000000", "0.00000000"], ["84134.62000000", "0.00000000"], ["84134.85000000", "0.00000000"], ["84134.98000000", "0.00000000"], ["84135.09000000", "0.00000000"], ["84135.11000000", "0.00000000"], ["84135.59000000", "0.00000000"], ["84135.60000000", "0.00000000"], ["84136.05000000", "0.00000000"], ["84136.55000000", "0.00000000"], ["84136.61000000", "0.00000000"], ["84136.78000000", "0.00000000"], ["84136.87000000", "0.00000000"], ["84137.05000000", "0.00000000"], ["84137.23000000", "0.00000000"], ["84137.86000000", "0.00000000"], ["84137.88000000", "0.00000000"], ["84138.09000000", "0.00000000"], ["84138.32000000", "0.00000000"], ["84138.74000000", "0.00000000"], ["84138.77000000", "0.00000000"], ["84139.24000000", "0.00000000"], ["84139.35000000", "0.00000000"], ["84139.41000000", "0.00000000"], ["84139.53000000", "0.00000000"], ["84140.68000000", "0.00000000"], ["84140.72000000", "0.00000000"], ["84140.89000000", "0.00000000"], ["84141.72000000", "0.00000000"], ["84141.74000000", "0.00000000"], ["84142.11000000", "0.00000000"], ["84142.60000000", "0.00000000"], ["84142.78000000", "0.00000000"], ["84143.18000000", "0.00000000"], ["84143.25000000", "0.00000000"], ["84143.37000000", "0.00000000"], ["84143.38000000", "0.00000000"], ["84144.01000000", "0.00000000"], ["84144.27000000", "0.00000000"], ["84144.35000000", "0.00000000"], ["84144.67000000", "0.00000000"], ["84145.26000000", "0.00016000"], ["84145.81000000", "0.00023000"], ["84147.00000000", "0.00000000"], ["84147.82000000", "0.00000000"], ["84147.98000000", "0.00000000"], ["84148.98000000", "0.00000000"], ["84149.40000000", "0.00000000"], ["84157.07000000", "0.01000000"], ["84157.57000000", "0.00000000"], ["84158.01000000", "0.01188000"], ["84165.81000000", "0.00000000"], ["84166.00000000", "0.00044000"], ["84170.06000000", "0.00000000"], ["84171.27000000", "0.00000000"], ["84171.69000000", "0.99922000"], ["84184.71000000", "0.00000000"], ["84188.07000000", "0.00000000"], ["84234.34000000", "0.00046000"], ["84236.72000000", "0.00017000"], ["84240.91000000", "0.00000000"], ["84243.35000000", "0.00000000"], ["84245.65000000", "0.00000000"], ["84266.67000000", "0.00000000"], ["84269.09000000", "0.00000000"], ["84271.63000000", "0.16359000"], ["84273.92000000", "0.00000000"], ["84275.07000000", "0.00000000"], ["84275.22000000", "0.00000000"], ["84280.03000000", "0.16359000"], ["84282.14000000", "0.00115000"], ["84283.13000000", "0.00000000"], ["84288.41000000", "0.16359000"], ["84290.54000000", "0.00000000"], ["84291.53000000", "0.00000000"], ["84296.81000000", "0.07144000"], ["84298.94000000", "0.00000000"], ["84336.00000000", "0.00221000"], ["84375.44000000", "0.00000000"], ["85214.55000000", "0.10000000"], ["85243.84000000", "0.00100000"], ["85265.69000000", "0.00000000"], ["85285.20000000", "0.00000000"], ["150001.00000000", "0.00000000"]], "record_time": 1742577043.214337, "EXCHANGE": "BINANCE"}
{"e": "depthUpdate", "E": 1742577044014, "s": "BTCUSDT", "U": 64632096374, "u": 64632096906, "b": [["83984.06000000", "0.70288000"], ["83983.94000000", "0.00014000"], ["83983.89000000", "0.00007000"], ["83983.32000000", "0.00007000"], ["83983.31000000", "0.00000000"], ["83983.21000000", "0.00000000"], ["83983.20000000", "0.00000000"], ["83983.10000000", "0.00007000"], ["83982.94000000", "0.00000000"], ["83982.79000000", "0.00000000"], ["83982.31000000", "0.00000000"], ["83982.30000000", "0.00000000"], ["83982.27000000", "0.00000000"], ["83982.21000000", "0.00000000"], ["83982.20000000", "0.00000000"], ["83982.13000000", "0.00014000"], ["83982.12000000", "0.03295000"], ["83982.10000000", "0.00000000"], ["83982.09000000", "0.00000000"], ["83981.97000000", "0.00000000"], ["83981.94000000", "0.17466000"], ["83981.47000000", "0.00000000"], ["83981.46000000", "0.00000000"], ["83981.33000000", "0.00000000"], ["83981.22000000", "0.00000000"], ["83981.21000000", "0.00000000"], ["83981.14000000", "0.00028000"], ["83981.13000000", "0.07378000"], ["83980.88000000", "0.00014000"], ["83980.87000000", "0.00000000"], ["83980.65000000", "0.00028000"], ["83980.64000000", "0.33185000"], ["83980.60000000", "0.00000000"], ["83980.56000000", "0.00000000"], ["83980.55000000", "0.00000000"], ["83980.20000000", "0.00014000"], ["83980.19000000", "0.02447000"], ["83979.27000000", "0.00000000"], ["83979.19000000", "0.02435000"], ["83978.70000000", "0.00000000"], ["83978.69000000", "0.05364000"], ["83978.61000000", "0.00000000"], ["83978.49000000", "0.02976000"], ["83978.19000000", "0.00000000"], ["83978.18000000", "0.12679000"], ["83977.95000000", "0.00008000"], ["83975.93000000", "0.00119000"], ["83974.80000000", "0.00000000"], ["83974.65000000", "0.00000000"], ["83974.33000000", "0.00007000"], ["83974.28000000", "0.68088000"], ["83972.99000000", "0.00000000"], ["83972.97000000", "0.00000000"], ["83972.88000000", "0.00006000"], ["83972.71000000", "0.00000000"], ["83971.47000000", "0.71399000"], ["83971.46000000", "0.00000000"], ["83970.46000000", "0.00000000"], ["83969.61000000", "0.34616000"], ["83969.56000000", "0.04000000"], ["83969.02000000", "0.00000000"], ["83968.79000000", "0.00000000"], ["83968.68000000", "0.00000000"], ["83967.89000000", "0.04000000"], ["83967.87000000", "0.04000000"], ["83967.80000000", "0.47650000"], ["83967.77000000", "0.04000000"], ["83965.36000000", "0.04000000"], ["83964.51000000", "0.04000000"], ["83963.70000000", "0.04000000"], ["83963.57000000", "0.04000000"], ["83962.85000000", "0.00000000"], ["83962.15000000", "0.00000000"], ["83962.14000000", "0.00000000"], ["83962.05000000", "0.00000000"], ["83961.87000000", "0.03573000"], ["83961.57000000", "0.10787000"], ["83961.44000000", "0.00000000"], ["83960.87000000", "0.00000000"], ["83953.75000000", "0.08354000"], ["83951.26000000", "0.00000000"], ["83948.37000000", "0.00000000"], ["83946.22000000", "0.00000000"], ["83932.80000000", "0.05963000"], ["83927.84000000", "0.00000000"], ["83926.16000000", "0.00000000"], ["83917.52000000", "0.04490000"], ["83914.04000000", "0.27085000"], ["83910.03000000", "0.00000000"], ["83909.21000000", "0.04000000"], ["83906.32000000", "0.04000000"], ["83904.01000000", "0.13962000"], ["83902.90000000", "0.00000000"], ["83901.23000000", "0.00000000"], ["83901.16000000", "0.00000000"], ["83901.13000000", "0.00000000"], ["83899.27000000", "0.00000000"], ["83899.19000000", "0.03574000"], ["83897.01000000", "0.00000000"], ["83882.38000000", "0.00000000"], ["83865.60000000", "0.51260000"], ["83825.68000000", "0.00622000"], ["83819.46000000", "0.00000000"], ["83806.25000000", "0.00000000"], ["83781.03000000", "0.45000000"], ["83778.96000000", "0.00839000"], ["83758.93000000", "0.00013000"], ["83751.82000000", "0.00000000"], ["83746.40000000", "0.00400000"], ["83500.00000000", "3.39360000"], ["82984.80000000", "0.02349000"], ["82859.27000000", "0.00080000"], ["82724.29000000", "0.00000000"], ["75585.00000000", "0.03323000"], ["67187.25000000", "0.00058000"], ["33000.00000000", "2.96666000"], ["30234.26000000", "0.00100000"]], "a": [["83984.07000000", "10.22120000"], ["83984.12000000", "0.00007000"], ["83984.46000000", "0.00007000"], ["83984.47000000", "0.00013000"], ["83985.00000000", "0.00021000"], ["83985.01000000", "0.58191000"], ["83985.02000000", "0.00000000"], ["83985.60000000", "0.00007000"], ["83985.74000000", "0.01197000"], ["83986.00000000", "0.01423000"], ["83986.88000000", "0.00000000"], ["83987.17000000", "0.45013000"], ["83988.00000000", "0.80036000"], ["83988.22000000", "0.02374000"], ["83989.00000000", "0.58243000"], ["83989.01000000", "0.47650000"], ["83989.57000000", "0.00000000"], ["83990.78000000", "0.01190000"], ["83991.60000000", "0.00019000"], ["83994.25000000", "0.09608000"], ["83996.66000000", "0.01190000"], ["84002.40000000", "0.00000000"], ["84002.70000000", "0.00500000"], ["84003.15000000", "0.00000000"], ["84004.34000000", "0.94620000"], ["84004.57000000", "1.00000000"], ["84006.95000000", "0.00000000"], ["84007.03000000", "0.00000000"], ["84008.19000000", "0.00000000"], ["84011.84000000", "0.00000000"], ["84020.22000000", "0.00100000"], ["84022.34000000", "0.85732000"], ["84033.43000000", "0.00000000"], ["84044.59000000", "0.00000000"], ["84071.40000000", "0.00000000"], ["84112.30000000", "0.12000000"], ["84126.03000000", "0.00000000"], ["84156.07000000", "0.01000000"], ["84156.27000000", "0.00000000"], ["84156.37000000", "0.00000000"], ["84156.57000000", "0.00000000"], ["84157.07000000", "0.00000000"], ["84230.15000000", "0.00000000"], ["84294.00000000", "0.03574000"], ["84638.40000000", "0.05963000"], ["85243.84000000", "0.00000000"], ["85263.90000000", "0.11744000"]], "record_time": 1742577044.213098, "EXCHANGE": "BINANCE"}
{"e": "depthUpdate", "E": 1742577045014, "s": "BTCUSDT", "U": 64632096907, "u": 64632097767, "b": [["83984.06000000", "0.00000000"], ["83984.05000000", "0.00116000"], ["83984.04000000", "0.00048000"], ["83983.94000000", "0.00007000"], ["83983.89000000", "0.00007000"], ["83983.76000000", "0.00021000"], ["83983.75000000", "0.00061000"], ["83983.74000000", "0.00000000"], ["83983.70000000", "0.00208000"], ["83983.57000000", "0.00007000"], ["83983.56000000", "0.00000000"], ["83983.33000000", "0.00000000"], ["83983.32000000", "0.00000000"], ["83983.28000000", "0.00000000"], ["83983.20000000", "0.00000000"], ["83983.19000000", "0.00000000"], ["83983.10000000", "0.00007000"], ["83982.53000000", "0.00000000"], ["83982.13000000", "0.00000000"], ["83982.12000000", "0.00000000"], ["83981.95000000", "0.00000000"], ["83981.94000000", "0.00000000"], ["83981.82000000", "0.00000000"], ["83981.81000000", "0.00000000"], ["83981.46000000", "0.00000000"], ["83981.45000000", "0.00000000"], ["83981.33000000", "0.00014000"], ["83981.25000000", "0.00000000"], ["83981.14000000", "0.00036000"], ["83981.13000000", "0.07378000"], ["83981.06000000", "0.00000000"], ["83980.97000000", "0.00000000"], ["83980.88000000", "0.00000000"], ["83980.65000000", "0.00000000"], ["83980.64000000", "0.00000000"], ["83980.60000000", "0.00007000"], ["83980.55000000", "0.00000000"], ["83980.20000000", "0.00032000"], ["83980.19000000", "0.02454000"], ["83979.91000000", "0.00014000"], ["83979.90000000", "0.26150000"], ["83979.20000000", "0.13013000"], ["83979.19000000", "0.00000000"], ["83978.70000000", "0.00000000"], ["83978.69000000", "0.00000000"], ["83978.68000000", "0.00000000"], ["83978.50000000", "0.00000000"], ["83978.49000000", "0.02983000"], ["83978.19000000", "0.00000000"], ["83978.18000000", "0.00000000"], ["83978.17000000", "0.06262000"], ["83978.11000000", "0.00000000"], ["83978.10000000", "0.00000000"], ["83977.66000000", "0.02212000"], ["83977.62000000", "0.00000000"], ["83976.93000000", "0.00000000"], ["83976.01000000", "0.00000000"], ["83975.90000000", "0.05364000"], ["83975.66000000", "0.00000000"], ["83975.24000000", "0.00873000"], ["83974.80000000", "0.00006000"], ["83974.33000000", "0.00000000"], ["83974.28000000", "0.00000000"], ["83974.17000000", "0.00000000"], ["83973.21000000", "0.15697000"], ["83973.12000000", "0.04000000"], ["83971.69000000", "0.00050000"], ["83971.47000000", "0.00000000"], ["83971.22000000", "0.00000000"], ["83969.83000000", "0.16172000"], ["83969.61000000", "0.22476000"], ["83967.80000000", "0.00000000"], ["83967.60000000", "0.00000000"], ["83967.36000000", "0.71399000"], ["83967.35000000", "0.38001000"], ["83965.85000000", "0.34074000"], ["83965.84000000", "0.00000000"], ["83963.65000000", "0.47650000"], ["83963.64000000", "0.00000000"], ["83963.63000000", "0.00502000"], ["83963.41000000", "0.02349000"], ["83962.61000000", "0.00000000"], ["83962.36000000", "0.00000000"], ["83962.35000000", "0.00000000"], ["83962.08000000", "0.00476000"], ["83961.87000000", "0.00000000"], ["83961.24000000", "0.03746000"], ["83959.63000000", "0.00000000"], ["83958.87000000", "0.00059000"], ["83957.68000000", "0.00000000"], ["83957.56000000", "1.50440000"], ["83956.60000000", "0.59562000"], ["83953.76000000", "0.00000000"], ["83953.74000000", "0.00000000"], ["83951.30000000", "0.00000000"], ["83950.01000000", "0.59567000"], ["83948.24000000", "0.40423000"], ["83948.23000000", "0.89344000"], ["83948.12000000", "0.00000000"], ["83948.11000000", "0.00000000"], ["83945.66000000", "0.00000000"], ["83945.03000000", "0.47650000"], ["83943.33000000", "0.00000000"], ["83943.30000000", "0.00146000"], ["83942.15000000", "0.00000000"], ["83940.14000000", "0.46551000"], ["83940.13000000", "0.36353000"], ["83939.73000000", "0.00000000"], ["83939.71000000", "0.00000000"], ["83938.93000000", "0.00000000"], ["83938.01000000", "0.04762000"], ["83936.63000000", "0.00000000"], ["83932.81000000", "0.00297000"], ["83932.59000000", "0.09797000"], ["83931.13000000", "0.00000000"], ["83929.07000000", "0.03346000"], ["83928.06000000", "0.00387000"], ["83928.01000000", "0.00000000"], ["83926.26000000", "0.00000000"], ["83925.59000000", "0.00297000"], ["83919.42000000", "0.91298000"], ["83918.80000000", "0.59562000"], ["83917.52000000", "0.00000000"], ["83914.35000000", "0.00000000"], ["83907.23000000", "0.24502000"], ["83905.38000000", "0.04490000"], ["83904.01000000", "0.09522000"], ["83894.13000000", "0.00000000"], ["83893.89000000", "0.00000000"], ["83893.51000000", "0.08396000"], ["83893.27000000", "0.00000000"], ["83891.13000000", "0.00000000"], ["83890.25000000", "0.12899000"], ["83888.71000000", "0.00146000"], ["83885.51000000", "0.09740000"], ["83882.86000000", "0.04643000"], ["83879.31000000", "0.04762000"], ["83856.01000000", "0.00000000"], ["83849.29000000", "0.00000000"], ["83848.75000000", "0.00119000"], ["83846.27000000", "0.00000000"], ["83841.56000000", "0.00119000"], ["83840.54000000", "0.00000000"], ["83836.01000000", "0.00324000"], ["83820.13000000", "0.00000000"], ["83765.62000000", "0.00013000"], ["83757.11000000", "0.00000000"], ["83748.10000000", "0.00400000"], ["83746.40000000", "0.00000000"], ["83741.25000000", "0.00000000"], ["83650.00000000", "0.02601000"], ["83500.00000000", "3.39382000"], ["82883.64000000", "0.40000000"], ["82875.30000000", "0.00000000"], ["82724.28000000", "0.00100000"], ["75585.00000000", "0.03323000"], ["67187.25000000", "0.00000000"], ["67187.24000000", "0.00058000"], ["33000.00000000", "2.96666000"], ["30234.26000000", "0.00120000"], ["20002.00000000", "0.00000000"], ["20001.00000000", "0.02099000"]], "a": [["83984.06000000", "9.64722000"], ["83984.07000000", "3.39870000"], ["83984.08000000", "0.00007000"], ["83984.12000000", "0.00007000"], ["83984.30000000", "0.00208000"], ["83984.47000000", "0.00007000"], ["83984.66000000", "0.00007000"], ["83984.76000000", "0.00000000"], ["83985.00000000", "0.00000000"], ["83985.01000000", "0.00000000"], ["83985.60000000", "0.00000000"], ["83985.74000000", "0.01197000"], ["83986.00000000", "0.01423000"], ["83986.27000000", "0.02394000"], ["83986.75000000", "0.02387000"], ["83986.89000000", "0.00000000"], ["83987.17000000", "0.00000000"], ["83987.18000000", "0.00000000"], ["83987.19000000", "0.78621000"], ["83987.47000000", "0.09206000"], ["83987.94000000", "0.02323000"], ["83988.00000000", "0.01416000"], ["83988.18000000", "0.06806000"], ["83988.22000000", "0.02416000"], ["83988.61000000", "0.05959000"], ["83989.00000000", "0.31969000"], ["83989.01000000", "0.06800000"], ["83989.09000000", "0.13505000"], ["83989.11000000", "0.00000000"], ["83989.18000000", "0.07600000"], ["83989.56000000", "0.17899000"], ["83989.58000000", "0.05953000"], ["83989.93000000", "0.45000000"], ["83990.00000000", "0.01410000"], ["83990.36000000", "0.00000000"], ["83990.43000000", "0.00000000"], ["83990.85000000", "0.00000000"], ["83991.23000000", "0.00000000"], ["83991.47000000", "0.05000000"], ["83991.78000000", "0.06400000"], ["83992.19000000", "0.00119000"], ["83992.37000000", "0.06029000"], ["83993.11000000", "0.00000000"], ["83993.14000000", "0.08580000"], ["83993.22000000", "0.04800000"], ["83993.23000000", "0.05200000"], ["83993.29000000", "0.00000000"], ["83993.30000000", "0.07200000"], ["83993.91000000", "0.05000000"], ["83994.49000000", "0.00000000"], ["83994.95000000", "0.00000000"], ["83995.06000000", "0.00000000"], ["83995.12000000", "0.00000000"], ["83995.31000000", "0.00000000"], ["83997.48000000", "0.00000000"], ["83998.11000000", "0.00922000"], ["83998.14000000", "0.00000000"], ["83998.31000000", "0.00000000"], ["83999.25000000", "0.00000000"], ["84001.11000000", "0.00000000"], ["84008.95000000", "0.00000000"], ["84009.27000000", "0.00059000"], ["84009.95000000", "0.69857000"], ["84010.76000000", "0.05000000"], ["84011.00000000", "0.00500000"], ["84011.49000000", "0.00000000"], ["84011.68000000", "0.85743000"], ["84019.04000000", "0.02808000"], ["84021.53000000", "0.85733000"], ["84021.87000000", "0.00007000"], ["84022.34000000", "0.00000000"], ["84025.58000000", "0.00000000"], ["84026.78000000", "0.00000000"], ["84031.15000000", "0.06400000"], ["84033.08000000", "0.04110000"], ["84046.42000000", "0.00000000"], ["84059.23000000", "0.00000000"], ["84061.39000000", "0.00000000"], ["84067.98000000", "0.00151000"], ["84070.58000000", "0.00297000"], ["84073.91000000", "0.06400000"], ["84076.54000000", "0.02383000"], ["84077.66000000", "0.00297000"], ["84082.57000000", "0.04762000"], ["84090.73000000", "0.00000000"], ["84092.69000000", "0.00000000"], ["84093.68000000", "0.00000000"], ["84155.54000000", "0.00119000"], ["84163.92000000", "0.00119000"], ["84171.68000000", "0.99623000"], ["84171.69000000", "0.00000000"], ["84184.23000000", "0.00000000"], ["84194.62000000", "0.00000000"], ["84365.44000000", "0.00419000"], ["84909.59000000", "0.00000000"], ["84917.99000000", "0.60000000"], ["85243.83000000", "0.00100000"], ["85263.90000000", "0.00000000"]], "record_time": 1742577045.213793, "EXCHANGE": "BINANCE"}
{"e": "depthUpdate", "E": 1742577046014, "s": "BTCUSDT", "U": 64632097768, "u": 64632098756, "b": [["83984.05000000", "0.00000000"], ["83984.04000000", "0.00000000"], ["83983.94000000", "0.00000000"], ["83983.89000000", "0.00000000"], ["83983.76000000", "0.00000000"], ["83983.75000000", "0.00000000"], ["83983.70000000", "0.00000000"], ["83983.57000000", "0.00000000"], ["83983.10000000", "0.00000000"], ["83982.96000000", "0.00000000"], ["83982.27000000", "0.00000000"], ["83981.33000000", "0.00000000"], ["83981.32000000", "0.00000000"], ["83981.25000000", "0.00000000"], ["83981.24000000", "1.44182000"], ["83981.23000000", "0.00062000"], ["83981.15000000", "0.00019000"], ["83981.14000000", "0.00074000"], ["83981.13000000", "0.07385000"], ["83980.65000000", "0.00021000"], ["83980.64000000", "0.16141000"], ["83980.60000000", "0.00000000"], ["83980.41000000", "0.00021000"], ["83980.40000000", "0.11661000"], ["83980.20000000", "0.00000000"], ["83980.19000000", "0.00000000"], ["83980.00000000", "0.00024000"], ["83979.91000000", "0.00000000"], ["83979.90000000", "0.00000000"], ["83979.76000000", "0.00007000"], ["83979.59000000", "0.12061000"], ["83979.21000000", "0.00000000"], ["83979.20000000", "0.00000000"], ["83979.00000000", "0.00000000"], ["83978.97000000", "0.00101000"], ["83978.92000000", "0.00007000"], ["83978.68000000", "0.02369000"], ["83978.67000000", "0.05364000"], ["83978.49000000", "0.02982000"], ["83978.40000000", "0.00000000"], ["83978.17000000", "0.00000000"], ["83977.92000000", "0.00000000"], ["83977.67000000", "0.13497000"], ["83977.66000000", "0.07801000"], ["83977.39000000", "0.02447000"], ["83977.25000000", "0.00007000"], ["83977.00000000", "0.00500000"], ["83976.92000000", "0.14000000"], ["83976.44000000", "0.14822000"], ["83976.20000000", "0.00000000"], ["83975.93000000", "0.00000000"], ["83975.90000000", "0.00000000"], ["83975.51000000", "0.00000000"], ["83975.24000000", "0.00000000"], ["83974.81000000", "0.00000000"], ["83973.23000000", "0.37313000"], ["83973.22000000", "0.71399000"], ["83973.21000000", "0.00000000"], ["83973.19000000", "0.00119000"], ["83972.84000000", "0.28849000"], ["83972.77000000", "0.00030000"], ["83970.90000000", "0.00096000"], ["83970.66000000", "0.00421000"], ["83970.09000000", "0.00000000"], ["83970.03000000", "0.00000000"], ["83969.61000000", "0.41334000"], ["83969.48000000", "0.00091000"], ["83968.94000000", "0.00000000"], ["83968.30000000", "0.00000000"], ["83967.86000000", "0.38009000"], ["83967.41000000", "0.00069000"], ["83967.35000000", "0.00000000"], ["83967.26000000", "0.00000000"], ["83966.72000000", "0.00000000"], ["83963.63000000", "0.00000000"], ["83962.08000000", "0.00000000"], ["83961.25000000", "0.00113000"], ["83960.82000000", "0.00503000"], ["83960.80000000", "0.00120000"], ["83960.26000000", "0.03573000"], ["83960.14000000", "0.00000000"], ["83959.73000000", "0.00000000"], ["83956.04000000", "0.00300000"], ["83956.03000000", "0.05956000"], ["83951.73000000", "0.59565000"], ["83951.72000000", "0.00000000"], ["83950.01000000", "0.00000000"], ["83945.17000000", "0.00000000"], ["83943.30000000", "0.00000000"], ["83940.57000000", "0.00146000"], ["83939.25000000", "0.00059000"], ["83928.60000000", "0.00019000"], ["83920.47000000", "0.00000000"], ["83920.01000000", "0.00000000"], ["83916.80000000", "0.00279000"], ["83915.56000000", "0.00000000"], ["83910.71000000", "0.00061000"], ["83910.59000000", "0.09251000"], ["83905.38000000", "0.00000000"], ["83900.00000000", "0.37360000"], ["83898.47000000", "0.04440000"], ["83894.49000000", "0.12899000"], ["83890.25000000", "0.00000000"], ["83889.72000000", "0.00000000"], ["83869.61000000", "0.00082000"], ["83865.60000000", "0.51273000"], ["83836.01000000", "0.00000000"], ["83832.01000000", "0.00308000"], ["83825.70000000", "0.00006000"], ["83804.77000000", "0.00000000"], ["83804.05000000", "0.01018000"], ["83795.09000000", "0.00011000"], ["83793.11000000", "0.00069000"], ["83792.00000000", "0.00235000"], ["83782.24000000", "0.00000000"], ["83771.75000000", "0.00400000"], ["83751.51000000", "0.00000000"], ["83749.20000000", "0.00000000"], ["83748.10000000", "0.00000000"], ["83733.52000000", "0.00000000"], ["83720.03000000", "0.00000000"], ["82724.28000000", "0.00000000"], ["80623.19000000", "0.00000000"], ["80606.38000000", "0.00000000"], ["75585.00000000", "0.03323000"], ["75583.00000000", "0.00000000"], ["67187.24000000", "0.00000000"], ["67185.00000000", "0.00073000"], ["33000.00000000", "2.96666000"], ["30233.25000000", "0.00020000"]], "a": [["83981.25000000", "8.20390000"], ["83981.26000000", "0.00048000"], ["83981.28000000", "0.00021000"], ["83981.29000000", "0.94529000"], ["83981.30000000", "0.00007000"], ["83981.31000000", "0.00007000"], ["83981.32000000", "0.00007000"], ["83981.33000000", "0.59052000"], ["83981.42000000", "0.00000000"], ["83981.46000000", "0.00008000"], ["83982.00000000", "0.01423000"], ["83982.92000000", "0.00000000"], ["83983.09000000", "0.00000000"], ["83983.11000000", "0.00000000"], ["83983.58000000", "0.00000000"], ["83983.71000000", "0.00000000"], ["83983.76000000", "0.00000000"], ["83983.77000000", "0.00000000"], ["83983.90000000", "0.00000000"], ["83983.95000000", "0.00000000"], ["83984.00000000", "0.01423000"], ["83984.05000000", "0.12066000"], ["83984.06000000", "1.42498000"], ["83984.07000000", "0.31428000"], ["83984.08000000", "0.00000000"], ["83984.12000000", "0.00000000"], ["83984.30000000", "0.00201000"], ["83984.46000000", "0.00000000"], ["83984.47000000", "0.00000000"], ["83984.66000000", "0.00000000"], ["83985.03000000", "0.00000000"], ["83985.10000000", "0.02323000"], ["83985.41000000", "0.00000000"], ["83985.73000000", "0.00027000"], ["83985.74000000", "0.00000000"], ["83985.88000000", "0.00000000"], ["83986.00000000", "0.01410000"], ["83986.27000000", "0.00000000"], ["83986.75000000", "0.00000000"], ["83987.19000000", "0.00000000"], ["83987.47000000", "0.09200000"], ["83987.94000000", "0.00000000"], ["83987.96000000", "0.01190000"], ["83987.99000000", "0.00006000"], ["83988.00000000", "0.01410000"], ["83988.03000000", "0.03343000"], ["83988.18000000", "0.06800000"], ["83988.22000000", "0.00000000"], ["83988.30000000", "0.00119000"], ["83988.61000000", "0.00000000"], ["83989.00000000", "0.51948000"], ["83989.04000000", "0.00000000"], ["83989.58000000", "0.00000000"], ["83989.63000000", "0.00029000"], ["83990.46000000", "0.78618000"], ["83990.78000000", "0.00000000"], ["83991.47000000", "0.00000000"], ["83991.73000000", "0.00013000"], ["83991.81000000", "0.00414000"], ["83991.82000000", "0.05956000"], ["83991.99000000", "0.23136000"], ["83992.00000000", "0.01410000"], ["83992.17000000", "0.00000000"], ["83992.37000000", "0.06000000"], ["83992.42000000", "0.00000000"], ["83992.73000000", "0.00419000"], ["83993.14000000", "0.03580000"], ["83993.42000000", "0.00000000"], ["83993.84000000", "0.01190000"], ["83994.24000000", "0.00000000"], ["83996.02000000", "0.05956000"], ["83996.66000000", "0.00000000"], ["83996.73000000", "0.01190000"], ["83996.79000000", "0.59562000"], ["83999.17000000", "0.00000000"], ["84000.86000000", "0.00000000"], ["84002.47000000", "0.00000000"], ["84002.70000000", "0.00000000"], ["84004.00000000", "0.00000000"], ["84006.00000000", "0.00000000"], ["84008.18000000", "0.00000000"], ["84008.72000000", "0.16359000"], ["84010.36000000", "0.39528000"], ["84010.76000000", "0.00000000"], ["84011.68000000", "0.00000000"], ["84011.93000000", "0.85743000"], ["84011.95000000", "0.00000000"], ["84013.46000000", "0.00000000"], ["84019.26000000", "0.00000000"], ["84021.48000000", "0.00000000"], ["84023.09000000", "0.00000000"], ["84023.24000000", "0.00059000"], ["84026.77000000", "0.00000000"], ["84029.17000000", "0.00013000"], ["84033.08000000", "0.00000000"], ["84034.10000000", "0.00000000"], ["84037.44000000", "0.01189000"], ["84044.13000000", "0.04110000"], ["84055.76000000", "0.00000000"], ["84056.18000000", "0.06800000"], ["84061.10000000", "0.00993000"], ["84061.38000000", "0.00019000"], ["84061.39000000", "0.06000000"], ["84064.25000000", "0.03992000"], ["84073.91000000", "0.00000000"], ["84081.19000000", "0.00679000"], ["84082.55000000", "0.00000000"], ["84094.19000000", "0.00000000"], ["84095.26000000", "0.05750000"], ["84103.71000000", "0.00000000"], ["84109.70000000", "0.51078000"], ["84109.92000000", "0.18338000"], ["84111.09000000", "0.12000000"], ["84125.93000000", "1.42832000"], ["84137.44000000", "0.00016000"], ["84139.95000000", "0.00000000"], ["84266.81000000", "0.00000000"], ["84277.19000000", "0.16359000"], ["84280.03000000", "0.00000000"], ["84285.58000000", "0.07144000"], ["84288.41000000", "0.00000000"], ["84296.81000000", "0.00000000"], ["84300.00000000", "1.65356000"], ["84821.05000000", "0.00000000"], ["85243.83000000", "0.00000000"], ["85263.90000000", "0.00000000"], ["150001.00000000", "0.00008000"]], "record_time": 1742577046.213549, "EXCHANGE": "BINANCE"}
{"e": "depthUpdate", "E": 1742577047014, "s": "BTCUSDT", "U": 64632098757, "u": 64632099005, "b": [["83981.24000000", "2.46936000"], ["83981.23000000", "0.00062000"], ["83981.19000000", "0.00021000"], ["83981.18000000", "0.13328000"], ["83981.17000000", "0.00099000"], ["83981.13000000", "0.07385000"], ["83980.80000000", "0.00014000"], ["83980.79000000", "0.15792000"], ["83980.78000000", "0.00000000"], ["83980.66000000", "0.00000000"], ["83980.65000000", "0.00000000"], ["83980.64000000", "0.16134000"], ["83980.41000000", "0.00000000"], ["83980.40000000", "0.00000000"], ["83979.76000000", "0.00000000"], ["83979.59000000", "0.12054000"], ["83978.49000000", "0.02976000"], ["83978.40000000", "0.00000000"], ["83977.66000000", "0.00000000"], ["83976.00000000", "0.01410000"], ["83974.81000000", "0.00883000"], ["83973.25000000", "0.50784000"], ["83973.24000000", "0.71399000"], ["83973.23000000", "0.00000000"], ["83973.22000000", "0.00000000"], ["83972.84000000", "0.73849000"], ["83970.90000000", "0.00000000"], ["83969.48000000", "0.00000000"], ["83968.40000000", "0.00000000"], ["83965.85000000", "0.68269000"], ["83962.22000000", "1.37833000"], ["83957.45000000", "0.00000000"], ["83957.43000000", "0.00000000"], ["83953.73000000", "0.18658000"], ["83937.51000000", "0.00000000"], ["83935.51000000", "0.00000000"], ["83932.81000000", "0.00000000"], ["83929.08000000", "0.00295000"], ["83925.59000000", "0.00000000"], ["83923.00000000", "0.00297000"], ["83913.73000000", "0.04440000"], ["83898.47000000", "0.00000000"], ["83888.71000000", "0.00000000"], ["83888.36000000", "0.63047000"], ["83885.90000000", "0.00146000"], ["83865.60000000", "0.45319000"], ["83848.80000000", "0.05961000"], ["83841.56000000", "0.00000000"], ["83836.83000000", "0.00119000"], ["83797.66000000", "0.00400000"], ["83784.00000000", "0.00353000"], ["83783.87000000", "0.00839000"], ["83782.38000000", "0.00000000"], ["83778.96000000", "0.00000000"], ["83771.75000000", "0.00000000"], ["83755.51000000", "0.00000000"], ["83755.50000000", "0.00502000"], ["83645.31000000", "0.00008000"], ["82721.52000000", "0.00100000"], ["75583.00000000", "0.00000000"], ["67185.00000000", "0.00073000"], ["42000.00000000", "6.84810000"], ["33000.00000000", "2.96666000"], ["30233.25000000", "0.00040000"]], "a": [["83981.25000000", "5.46286000"], ["83981.33000000", "0.41058000"], ["83984.06000000", "1.52993000"], ["83986.20000000", "0.00757000"], ["83986.58000000", "0.16441000"], ["83986.76000000", "0.20178000"], ["83987.96000000", "0.00000000"], ["83988.03000000", "0.00000000"], ["83988.53000000", "0.00000000"], ["83988.59000000", "0.00000000"], ["83989.00000000", "0.31948000"], ["83990.46000000", "0.00000000"], ["83991.99000000", "0.39811000"], ["83992.05000000", "0.00095000"], ["83992.35000000", "0.78616000"], ["83992.61000000", "0.00091000"], ["83993.14000000", "0.00000000"], ["83993.91000000", "0.00000000"], ["84003.76000000", "0.71399000"], ["84003.95000000", "0.00000000"], ["84004.34000000", "0.00000000"], ["84005.30000000", "1.39731000"], ["84007.60000000", "0.00000000"], ["84009.94000000", "0.00151000"], ["84009.95000000", "0.98671000"], ["84009.99000000", "0.00000000"], ["84011.00000000", "0.00500000"], ["84011.93000000", "0.00000000"], ["84012.88000000", "0.00009000"], ["84014.46000000", "0.00000000"], ["84016.85000000", "0.00000000"], ["84019.38000000", "0.35737000"], ["84026.46000000", "0.85728000"], ["84034.28000000", "0.59562000"], ["84034.35000000", "0.00000000"], ["84108.60000000", "0.05297000"], ["84132.83000000", "0.00000000"], ["84138.66000000", "0.21432000"], ["84180.66000000", "0.00000000"], ["84227.39000000", "0.00000000"], ["85240.97000000", "0.00100000"]], "record_time": 1742577047.212541, "EXCHANGE": "BINANCE"}
{"e": "depthUpdate", "E": 1742577048014, "s": "BTCUSDT", "U": 64632099006, "u": 64632099666, "b": [["83981.24000000", "3.92286000"], ["83981.23000000", "0.00706000"], ["83981.20000000", "0.00021000"], ["83981.19000000", "0.11119000"], ["83981.18000000", "0.13334000"], ["83981.17000000", "0.00007000"], ["83981.14000000", "0.00053000"], ["83981.13000000", "0.07378000"], ["83980.80000000", "0.00000000"], ["83980.79000000", "0.00000000"], ["83980.65000000", "0.00000000"], ["83980.64000000", "0.16134000"], ["83980.12000000", "0.00000000"], ["83979.59000000", "0.00000000"], ["83978.68000000", "0.02375000"], ["83978.67000000", "0.00000000"], ["83978.56000000", "0.00000000"], ["83978.49000000", "0.02982000"], ["83978.06000000", "0.08998000"], ["83977.67000000", "0.13503000"], ["83977.59000000", "0.11911000"], ["83977.34000000", "0.00595000"], ["83977.00000000", "0.00000000"], ["83976.92000000", "0.00000000"], ["83975.81000000", "0.05953000"], ["83975.49000000", "0.00119000"], ["83975.05000000", "0.05953000"], ["83974.19000000", "0.00000000"], ["83974.01000000", "0.11907000"], ["83973.19000000", "0.00000000"], ["83972.94000000", "0.11907000"], ["83972.51000000", "0.00595000"], ["83971.69000000", "0.00050000"], ["83971.39000000", "0.00000000"], ["83971.38000000", "0.02381000"], ["83970.98000000", "0.00595000"], ["83970.46000000", "0.02381000"], ["83970.29000000", "0.08992000"], ["83970.14000000", "0.02381000"], ["83970.10000000", "0.62841000"], ["83970.09000000", "0.47650000"], ["83970.06000000", "0.06547000"], ["83969.83000000", "0.00000000"], ["83969.61000000", "0.00000000"], ["83967.88000000", "0.02381000"], ["83966.91000000", "0.03100000"], ["83965.64000000", "0.00595000"], ["83964.52000000", "0.00016000"], ["83964.32000000", "0.05953000"], ["83963.71000000", "0.00000000"], ["83963.65000000", "0.00000000"], ["83962.42000000", "0.11912000"], ["83962.23000000", "0.08354000"], ["83962.18000000", "0.17859000"], ["83960.52000000", "0.12138000"], ["83960.27000000", "0.59561000"], ["83959.21000000", "0.17859000"], ["83958.30000000", "0.05971000"], ["83957.42000000", "0.05953000"], ["83957.33000000", "0.08992000"], ["83956.22000000", "0.05953000"], ["83956.05000000", "0.00000000"], ["83955.41000000", "0.00758000"], ["83954.35000000", "0.05953000"], ["83953.73000000", "0.17899000"], ["83953.40000000", "0.51895000"], ["83951.73000000", "0.00000000"], ["83951.48000000", "0.00000000"], ["83949.60000000", "0.05962000"], ["83948.84000000", "0.00595000"], ["83946.57000000", "0.36353000"], ["83941.01000000", "0.05000000"], ["83940.14000000", "0.32770000"], ["83940.13000000", "0.00000000"], ["83936.57000000", "0.00000000"], ["83932.80000000", "0.00006000"], ["83931.11000000", "0.04490000"], ["83925.04000000", "0.04440000"], ["83922.62000000", "0.10000000"], ["83914.92000000", "0.00061000"], ["83913.73000000", "0.00000000"], ["83911.07000000", "0.10616000"], ["83910.71000000", "0.00000000"], ["83910.60000000", "0.00000000"], ["83910.59000000", "0.04761000"], ["83899.19000000", "0.00000000"], ["83872.29000000", "0.00000000"], ["83845.88000000", "0.00400000"], ["83839.99000000", "0.00000000"], ["83826.06000000", "0.00000000"], ["83820.05000000", "0.00000000"], ["83813.63000000", "0.01864000"], ["83798.96000000", "0.00000000"], ["83797.66000000", "0.00000000"], ["83789.93000000", "0.00000000"], ["83781.03000000", "0.00000000"], ["82721.52000000", "0.00000000"], ["80623.19000000", "0.03570000"], ["75583.00000000", "0.00000000"], ["67185.00000000", "0.00073000"], ["42000.00000000", "6.84710000"], ["33000.00000000", "2.96666000"]], "a": [["83981.25000000", "1.14266000"], ["83981.28000000", "0.00007000"], ["83981.29000000", "0.00007000"], ["83981.32000000", "0.00021000"], ["83981.33000000", "0.13005000"], ["83981.46000000", "0.00000000"], ["83981.77000000", "0.00008000"], ["83982.00000000", "0.01423000"], ["83982.80000000", "0.00000000"], ["83983.05000000", "0.00000000"], ["83983.54000000", "0.00014000"], ["83983.55000000", "0.12664000"], ["83983.56000000", "0.00000000"], ["83983.57000000", "0.00014000"], ["83983.58000000", "0.28539000"], ["83984.00000000", "0.01416000"], ["83984.04000000", "0.00000000"], ["83984.05000000", "0.00000000"], ["83984.06000000", "0.00101000"], ["83984.07000000", "0.00593000"], ["83984.32000000", "0.00000000"], ["83984.97000000", "0.00000000"], ["83985.10000000", "0.02317000"], ["83985.47000000", "0.00000000"], ["83986.00000000", "0.06209000"], ["83986.57000000", "0.00000000"], ["83986.58000000", "0.00000000"], ["83986.76000000", "0.00000000"], ["83986.99000000", "0.01997000"], ["83987.47000000", "0.00000000"], ["83988.18000000", "0.00000000"], ["83989.00000000", "0.19010000"], ["83989.01000000", "0.00000000"], ["83989.18000000", "0.00000000"], ["83989.56000000", "0.00000000"], ["83989.93000000", "0.00000000"], ["83990.13000000", "0.00000000"], ["83990.47000000", "0.03000000"], ["83991.16000000", "0.47650000"], ["83991.62000000", "0.00000000"], ["83991.78000000", "0.00000000"], ["83991.99000000", "0.35292000"], ["83992.19000000", "0.00000000"], ["83992.35000000", "0.00000000"], ["83992.37000000", "0.00000000"], ["83992.44000000", "0.35737000"], ["83992.58000000", "0.20178000"], ["83992.61000000", "0.16532000"], ["83993.22000000", "0.00000000"], ["83993.23000000", "0.00000000"], ["83993.30000000", "0.00000000"], ["83993.48000000", "0.00000000"], ["83993.84000000", "0.01190000"], ["83993.96000000", "0.09200000"], ["83994.06000000", "0.00000000"], ["83994.14000000", "0.06800000"], ["83994.43000000", "0.10788000"], ["83994.80000000", "0.00000000"], ["83994.96000000", "0.14400000"], ["83995.02000000", "0.00000000"], ["83995.36000000", "0.00119000"], ["83995.48000000", "0.00000000"], ["83995.82000000", "0.00000000"], ["83995.90000000", "0.00000000"], ["83995.99000000", "0.92579000"], ["83996.02000000", "0.00000000"], ["83996.71000000", "0.00091000"], ["83996.82000000", "0.00000000"], ["83997.10000000", "0.00000000"], ["83997.49000000", "0.06400000"], ["83997.54000000", "0.15590000"], ["83998.11000000", "0.00000000"], ["83998.12000000", "0.05956000"], ["83998.33000000", "0.06000000"], ["83998.40000000", "0.00000000"], ["83999.17000000", "0.04800000"], ["83999.78000000", "0.47650000"], ["83999.80000000", "0.14000000"], ["83999.84000000", "0.05200000"], ["83999.94000000", "0.07200000"], ["84002.04000000", "0.00000000"], ["84002.60000000", "0.00090000"], ["84002.70000000", "0.00500000"], ["84003.15000000", "0.00922000"], ["84003.66000000", "0.00000000"], ["84003.76000000", "0.00000000"], ["84004.56000000", "1.06034000"], ["84004.96000000", "0.00000000"], ["84006.36000000", "0.16000000"], ["84010.00000000", "0.00000000"], ["84010.82000000", "0.09200000"], ["84011.79000000", "0.07600000"], ["84012.90000000", "0.70119000"], ["84015.85000000", "0.06000000"], ["84015.98000000", "0.06800000"], ["84016.77000000", "0.07200000"], ["84018.51000000", "0.06400000"], ["84019.61000000", "0.00000000"], ["84020.20000000", "0.05200000"], ["84022.87000000", "0.00000000"], ["84026.53000000", "0.00000000"], ["84028.22000000", "0.12035000"], ["84029.40000000", "0.47656000"], ["84029.88000000", "0.85724000"], ["84032.22000000", "0.00000000"], ["84032.42000000", "0.59556000"], ["84034.30000000", "0.47650000"], ["84041.36000000", "0.00000000"], ["84044.13000000", "0.00000000"], ["84052.54000000", "0.04159000"], ["84055.40000000", "0.04110000"], ["84058.02000000", "0.00000000"], ["84058.39000000", "0.00000000"], ["84060.06000000", "0.00000000"], ["84060.07000000", "0.00000000"], ["84061.39000000", "0.00000000"], ["84066.93000000", "0.00000000"], ["84071.45000000", "0.00000000"], ["84073.15000000", "0.00000000"], ["84076.54000000", "0.00000000"], ["84077.20000000", "0.00000000"], ["84080.67000000", "0.02382000"], ["84081.09000000", "0.00000000"], ["84085.29000000", "0.00000000"], ["84091.78000000", "0.01864000"], ["84092.47000000", "0.00000000"], ["84095.26000000", "0.00000000"], ["84102.06000000", "0.05862000"], ["84156.07000000", "0.01000000"], ["84171.68000000", "0.00000000"], ["84194.60000000", "0.99353000"], ["84294.00000000", "0.00000000"], ["84336.00000000", "0.03795000"], ["85240.97000000", "0.00000000"], ["85285.20000000", "0.11743000"], ["94107.04000000", "0.00000000"], ["150001.00000000", "0.00024000"]], "record_time": 1742577048.213316, "EXCHANGE": "BINANCE"}
{"e": "depthUpdate", "E": 1742577049014, "s": "BTCUSDT", "U": 64632099667, "u": 64632099857, "b": [["83981.24000000", "4.26751000"], ["83979.00000000", "0.00006000"], ["83978.49000000", "0.02976000"], ["83978.06000000", "0.00006000"], ["83977.59000000", "0.11905000"], ["83977.00000000", "0.00500000"], ["83975.81000000", "0.00000000"], ["83975.80000000", "0.05953000"], ["83972.94000000", "0.00000000"], ["83972.93000000", "0.11907000"], ["83968.70000000", "0.00000000"], ["83966.87000000", "0.35737000"], ["83957.67000000", "0.00000000"], ["83953.40000000", "0.72771000"], ["83950.51000000", "0.00000000"], ["83949.47000000", "0.00000000"], ["83941.01000000", "0.00000000"], ["83936.63000000", "0.06102000"], ["83927.43000000", "0.00000000"], ["83925.04000000", "0.00000000"], ["83915.29000000", "0.04440000"], ["83857.70000000", "0.00000000"], ["83853.81000000", "0.01864000"], ["83851.83000000", "0.04398000"], ["83848.85000000", "0.00400000"], ["83845.88000000", "0.00000000"], ["83813.63000000", "0.00000000"], ["83770.02000000", "0.00000000"], ["82721.52000000", "0.00100000"], ["75583.00000000", "0.00000000"], ["67185.00000000", "0.00073000"], ["33000.00000000", "2.96666000"], ["30233.25000000", "0.00060000"]], "a": [["83981.25000000", "1.56322000"], ["83981.29000000", "0.00021000"], ["83981.30000000", "0.18568000"], ["83981.31000000", "0.13702000"], ["83981.32000000", "0.00007000"], ["83981.33000000", "0.00007000"], ["83981.99000000", "0.00000000"], ["83982.00000000", "0.01417000"], ["83982.69000000", "0.00014000"], ["83982.70000000", "0.33607000"], ["83982.89000000", "0.00000000"], ["83982.90000000", "0.00000000"], ["83983.54000000", "0.00000000"], ["83983.55000000", "0.00000000"], ["83983.57000000", "0.00000000"], ["83983.58000000", "0.00006000"], ["83983.88000000", "0.00000000"], ["83984.00000000", "0.01416000"], ["83984.07000000", "0.00000000"], ["83985.10000000", "0.02317000"], ["83989.00000000", "0.30808000"], ["83989.65000000", "0.45000000"], ["83991.82000000", "0.00000000"], ["83991.99000000", "0.57189000"], ["83992.98000000", "0.78615000"], ["83993.84000000", "0.01190000"], ["83994.14000000", "0.10106000"], ["83994.99000000", "0.00000000"], ["83996.02000000", "0.05956000"], ["84004.55000000", "0.00000000"], ["84011.00000000", "0.00000000"], ["84012.90000000", "0.97065000"], ["84015.82000000", "0.85739000"], ["84026.87000000", "0.05000000"], ["84029.88000000", "0.00000000"], ["84101.46000000", "0.24398000"], ["84101.48000000", "0.00000000"], ["84104.49000000", "0.04398000"], ["84108.72000000", "0.04993000"], ["84113.04000000", "0.04398000"], ["84119.80000000", "0.04398000"], ["85240.97000000", "0.00100000"]], "record_time": 1742577049.212567, "EXCHANGE": "BINANCE"}
{"e": "depthUpdate", "E": 1742577050014, "s": "BTCUSDT", "U": 64632099858, "u": 64632099941, "b": [["83981.24000000", "4.06652000"], ["83977.00000000", "0.01000000"], ["83975.80000000", "0.00000000"], ["83975.77000000", "0.20706000"], ["83974.01000000", "0.00000000"], ["83973.73000000", "0.11907000"], ["83972.93000000", "0.00000000"], ["83958.22000000", "0.00755000"], ["83955.41000000", "0.00000000"], ["83943.01000000", "0.05000000"], ["83916.79000000", "0.00000000"], ["83915.99000000", "0.03574000"], ["83853.81000000", "0.00000000"], ["83804.05000000", "0.00000000"], ["83798.16000000", "0.01535000"], ["83794.19000000", "0.00839000"], ["83783.87000000", "0.00000000"], ["82721.52000000", "0.00000000"], ["82681.74000000", "0.00000000"], ["75583.00000000", "0.00000000"], ["67185.00000000", "0.00073000"], ["60000.00000000", "72.96736000"], ["33000.00000000", "2.96666000"], ["30233.25000000", "0.00080000"], ["20002.00000000", "0.00000000"], ["20001.00000000", "0.02099000"]], "a": [["83981.25000000", "1.56536000"], ["83986.20000000", "0.00000000"], ["83988.35000000", "0.00755000"], ["83989.65000000", "0.45000000"], ["84002.70000000", "0.00000000"], ["84003.92000000", "0.00000000"], ["84004.55000000", "0.71399000"], ["84025.27000000", "0.94139000"], ["84032.64000000", "1.27503000"], ["84036.79000000", "0.01196000"], ["84064.25000000", "0.00000000"], ["84072.14000000", "0.01018000"], ["84081.19000000", "0.00000000"], ["84081.95000000", "1.21806000"], ["84088.87000000", "0.04762000"], ["84089.23000000", "0.04762000"], ["84091.78000000", "0.01864000"], ["84093.08000000", "0.00000000"], ["84108.54000000", "0.05497000"], ["84110.71000000", "0.00000000"], ["84111.79000000", "0.00000000"], ["84156.07000000", "0.00000000"], ["84156.27000000", "0.01000000"], ["84173.26000000", "0.99292000"], ["84194.60000000", "0.00000000"], ["85240.97000000", "0.00000000"]], "record_time": 1742577050.212832, "EXCHANGE": "BINANCE"}
{"e": "depthUpdate", "E": 1742577051014, "s": "BTCUSDT", "U": 64632099942, "u": 64632100134, "b": [["83981.24000000", "3.85136000"], ["83981.23000000", "0.00720000"], ["83981.22000000", "0.10493000"], ["83981.20000000", "0.00052000"], ["83981.19000000", "0.11099000"], ["83981.18000000", "0.00013000"], ["83981.14000000", "0.00046000"], ["83980.64000000", "0.16134000"], ["83978.94000000", "0.00023000"], ["83978.93000000", "0.00000000"], ["83978.06000000", "0.00000000"], ["83977.68000000", "0.00013000"], ["83977.67000000", "0.13497000"], ["83977.59000000", "0.00000000"], ["83977.34000000", "0.00000000"], ["83977.00000000", "0.01000000"], ["83975.78000000", "0.00019000"], ["83975.05000000", "0.00000000"], ["83973.73000000", "0.00000000"], ["83972.84000000", "0.28849000"], ["83970.98000000", "0.00000000"], ["83970.29000000", "0.00000000"], ["83970.14000000", "0.00000000"], ["83970.06000000", "0.00413000"], ["83967.88000000", "0.00000000"], ["83967.41000000", "0.00000000"], ["83964.32000000", "0.00000000"], ["83961.25000000", "0.00000000"], ["83960.27000000", "0.00000000"], ["83956.92000000", "0.59563000"], ["83948.61000000", "0.00000000"], ["83944.02000000", "0.01300000"], ["83943.01000000", "0.00000000"], ["83915.56000000", "0.01243000"], ["83893.57000000", "0.00100000"], ["83848.85000000", "0.00000000"], ["83839.33000000", "0.00400000"], ["83781.03000000", "0.45000000"], ["83770.36000000", "0.00000000"], ["83769.65000000", "0.01785000"], ["83141.42000000", "0.00000000"], ["82721.52000000", "0.00100000"], ["80000.00000000", "163.11169000"], ["75583.00000000", "0.00000000"], ["67185.00000000", "0.00073000"], ["60000.00000000", "72.96726000"], ["33000.00000000", "2.96666000"]], "a": [["83981.25000000", "3.83602000"], ["83981.26000000", "0.31602000"], ["83981.29000000", "0.00007000"], ["83981.30000000", "0.06423000"], ["83981.81000000", "0.00000000"], ["83981.86000000", "0.00000000"], ["83982.00000000", "0.01417000"], ["83982.69000000", "0.00000000"], ["83982.70000000", "0.00000000"], ["83983.09000000", "0.00000000"], ["83984.00000000", "0.01416000"], ["83986.00000000", "0.01410000"], ["83986.99000000", "0.00000000"], ["83987.96000000", "0.00884000"], ["84002.60000000", "0.00000000"], ["84021.73000000", "0.59564000"], ["84024.34000000", "0.00000000"], ["84025.42000000", "0.37727000"], ["84026.87000000", "0.00000000"], ["84029.58000000", "0.00000000"], ["84032.42000000", "0.00000000"], ["84032.64000000", "1.22741000"], ["84046.28000000", "0.00000000"], ["84047.16000000", "0.66012000"], ["84047.87000000", "0.00000000"], ["84069.81000000", "0.00100000"], ["84080.60000000", "0.91202000"], ["84089.22000000", "0.04762000"], ["84101.46000000", "0.29895000"], ["84104.46000000", "0.05497000"], ["84107.17000000", "0.05497000"], ["84110.84000000", "0.05497000"], ["84250.00000000", "0.15828000"], ["84258.40000000", "0.00000000"], ["85240.97000000", "0.00100000"], ["86500.00000000", "30.20705000"], ["88500.00000000", "11.51785000"]], "record_time": 1742577051.213455, "EXCHANGE": "BINANCE"}
{"e": "depthUpdate", "E": 1742577052014, "s": "BTCUSDT", "U": 64632100135, "u": 64632100288, "b": [["83981.24000000", "3.40234000"], ["83981.22000000", "0.10493000"], ["83981.20000000", "0.00038000"], ["83981.19000000", "0.00007000"], ["83981.14000000", "0.00060000"], ["83980.65000000", "0.00014000"], ["83980.64000000", "0.16128000"], ["83980.31000000", "0.00208000"], ["83980.21000000", "0.00000000"], ["83980.12000000", "0.00000000"], ["83979.98000000", "0.00000000"], ["83979.76000000", "0.00000000"], ["83978.93000000", "0.00000000"], ["83978.69000000", "0.00000000"], ["83978.68000000", "0.02376000"], ["83978.40000000", "0.00000000"], ["83977.00000000", "0.00500000"], ["83976.39000000", "0.00000000"], ["83975.60000000", "0.16172000"], ["83972.84000000", "0.73849000"], ["83972.08000000", "0.04000000"], ["83971.97000000", "0.04000000"], ["83968.71000000", "0.04000000"], ["83968.30000000", "0.00000000"], ["83967.87000000", "0.00000000"], ["83967.79000000", "0.04132000"], ["83967.77000000", "0.00000000"], ["83964.51000000", "0.00000000"], ["83963.57000000", "0.00000000"], ["83946.91000000", "0.05000000"], ["83942.11000000", "0.00000000"], ["83931.11000000", "0.00000000"], ["83920.35000000", "0.04490000"], ["83839.33000000", "0.00000000"], ["83829.93000000", "0.00400000"], ["83770.35000000", "0.00000000"], ["83769.65000000", "0.00000000"], ["82721.52000000", "0.00007000"], ["75583.00000000", "0.00000000"], ["67185.00000000", "0.00073000"], ["33000.00000000", "2.96666000"], ["30233.25000000", "0.00100000"]], "a": [["83981.25000000", "3.62506000"], ["83989.00000000", "0.52918000"], ["83990.96000000", "0.78617000"], ["83991.99000000", "0.35292000"], ["83992.98000000", "0.00000000"], ["83996.71000000", "0.00000000"], ["84002.70000000", "0.00500000"], ["84012.02000000", "0.85743000"], ["84019.93000000", "0.00000000"], ["84024.09000000", "0.05000000"], ["84026.46000000", "0.00000000"], ["84030.28000000", "0.90107000"], ["84038.90000000", "0.04110000"], ["84039.28000000", "0.04159000"], ["84052.54000000", "0.00000000"], ["84055.40000000", "0.00000000"], ["84080.67000000", "0.00000000"], ["84241.60000000", "0.00000000"], ["85240.97000000", "0.00000000"]], "record_time": 1742577052.212865, "EXCHANGE": "BINANCE"}
{"e": "depthUpdate", "E": 1742577053014, "s": "BTCUSDT", "U": 64632100289, "u": 64632100480, "b": [["83981.24000000", "2.99813000"], ["83981.23000000", "0.00706000"], ["83981.22000000", "0.00007000"], ["83981.13000000", "0.07378000"], ["83980.81000000", "0.00014000"], ["83980.80000000", "0.07845000"], ["83980.67000000", "0.00000000"], ["83980.64000000", "0.16128000"], ["83980.31000000", "0.00000000"], ["83980.00000000", "0.00143000"], ["83979.76000000", "0.00007000"], ["83979.24000000", "0.01735000"], ["83978.68000000", "0.02369000"], ["83978.40000000", "0.00000000"], ["83977.30000000", "0.05364000"], ["83977.00000000", "0.00500000"], ["83973.76000000", "0.04000000"], ["83973.25000000", "0.20321000"], ["83973.24000000", "0.00000000"], ["83972.84000000", "0.28849000"], ["83972.51000000", "0.00000000"], ["83972.09000000", "0.04000000"], ["83971.69000000", "0.00050000"], ["83971.38000000", "0.00000000"], ["83970.46000000", "0.00000000"], ["83969.58000000", "0.04000000"], ["83969.56000000", "0.00000000"], ["83968.40000000", "0.00000000"], ["83967.91000000", "0.04000000"], ["83967.89000000", "0.00000000"], ["83965.85000000", "0.57737000"], ["83965.36000000", "0.00000000"], ["83963.70000000", "0.00000000"], ["83962.62000000", "1.35458000"], ["83962.23000000", "0.00000000"], ["83962.22000000", "0.00000000"], ["83961.24000000", "0.00000000"], ["83959.55000000", "0.00757000"], ["83958.22000000", "0.00000000"], ["83957.39000000", "0.00000000"], ["83956.11000000", "0.05619000"], ["83949.11000000", "0.00000000"], ["83946.91000000", "0.00000000"], ["83944.02000000", "0.00000000"], ["83943.92000000", "0.01300000"], ["83941.01000000", "0.05000000"], ["83940.63000000", "0.00358000"], ["83922.62000000", "0.00000000"], ["83920.00000000", "0.00210000"], ["83918.03000000", "0.00000000"], ["83915.29000000", "0.00000000"], ["83905.75000000", "0.04440000"], ["83891.13000000", "0.63047000"], ["83888.36000000", "0.00000000"], ["83872.29000000", "0.10000000"], ["83829.93000000", "0.00000000"], ["83820.98000000", "0.00400000"], ["83770.30000000", "0.01785000"], ["83747.34000000", "0.01864000"], ["83039.87000000", "0.06004000"], ["82721.52000000", "0.00107000"], ["75583.00000000", "0.00000000"], ["67185.00000000", "0.00073000"], ["33000.00000000", "2.96666000"], ["30233.25000000", "0.00120000"]], "a": [["83981.25000000", "4.24863000"], ["83981.33000000", "0.00007000"], ["83981.47000000", "0.00000000"], ["83982.00000000", "0.01417000"], ["83982.92000000", "0.01190000"], ["83983.09000000", "0.00007000"], ["83986.04000000", "0.00759000"], ["83987.96000000", "0.01190000"], ["83988.35000000", "0.00000000"], ["83988.59000000", "0.02441000"], ["83988.99000000", "0.17899000"], ["83989.06000000", "0.78619000"], ["83990.96000000", "0.00000000"], ["83995.32000000", "0.00000000"], ["84002.23000000", "0.01864000"], ["84004.56000000", "0.64115000"], ["84005.30000000", "0.00000000"], ["84008.30000000", "1.33286000"], ["84020.05000000", "0.05000000"], ["84024.09000000", "0.00000000"], ["84038.90000000", "0.00000000"], ["84048.51000000", "0.04110000"], ["84049.26000000", "0.02857000"], ["84057.03000000", "0.00000000"], ["84059.98000000", "0.00019000"], ["84061.38000000", "0.00000000"], ["84090.05000000", "0.02382000"], ["84091.78000000", "0.00000000"], ["84092.08000000", "0.00058000"], ["84135.99000000", "0.00016000"], ["84137.44000000", "0.00000000"], ["84144.34000000", "0.00000000"], ["84156.27000000", "0.01000000"], ["84173.26000000", "0.99238000"], ["85240.97000000", "0.00100000"], ["85263.90000000", "0.11744000"], ["85285.20000000", "0.00000000"]], "record_time": 1742577053.212815, "EXCHANGE": "BINANCE"}
