{"e": "depthUpdate", "E": 1742577150014, "s": "BTCUSDT", "U": 64632184108, "u": 64632184389, "b": [["83945.65000000", "1.62958000"], ["83945.40000000", "0.00013000"], ["83945.21000000", "0.00015000"], ["83945.07000000", "0.00007000"], ["83945.06000000", "0.00000000"], ["83944.80000000", "0.00000000"], ["83943.86000000", "0.00000000"], ["83942.90000000", "0.00000000"], ["83942.49000000", "0.02013000"], ["83942.41000000", "0.00014000"], ["83942.40000000", "0.08209000"], ["83942.39000000", "0.04000000"], ["83942.06000000", "0.00000000"], ["83941.88000000", "0.00000000"], ["83941.85000000", "0.00754000"], ["83940.16000000", "0.00081000"], ["83940.15000000", "0.00000000"], ["83939.98000000", "0.00000000"], ["83939.54000000", "0.00008000"], ["83939.21000000", "0.00000000"], ["83937.64000000", "0.16823000"], ["83937.42000000", "0.00506000"], ["83937.06000000", "0.04000000"], ["83936.23000000", "0.04000000"], ["83935.45000000", "0.00000000"], ["83935.43000000", "0.00000000"], ["83935.39000000", "0.08000000"], ["83935.37000000", "0.00000000"], ["83935.29000000", "0.04000000"], ["83933.25000000", "0.00000000"], ["83932.80000000", "0.00386000"], ["83932.56000000", "0.04000000"], ["83932.03000000", "0.04000000"], ["83931.19000000", "0.04008000"], ["83930.88000000", "0.04000000"], ["83930.80000000", "0.04000000"], ["83929.71000000", "0.10786000"], ["83929.70000000", "0.00000000"], ["83929.65000000", "0.00000000"], ["83927.97000000", "0.00000000"], ["83927.09000000", "0.00000000"], ["83926.79000000", "0.00000000"], ["83925.82000000", "0.71399000"], ["83922.96000000", "0.25810000"], ["83922.95000000", "0.59589000"], ["83922.94000000", "0.00000000"], ["83921.32000000", "0.00000000"], ["83919.66000000", "0.00000000"], ["83919.65000000", "0.00000000"], ["83917.25000000", "0.00000000"], ["83916.28000000", "0.00000000"], ["83915.01000000", "0.00000000"], ["83914.28000000", "0.59314000"], ["83907.09000000", "0.00000000"], ["83899.19000000", "0.05959000"], ["83898.92000000", "0.04440000"], ["83894.21000000", "0.62297000"], ["83894.07000000", "0.08490000"], ["83885.68000000", "0.00000000"], ["83879.83000000", "0.00000000"], ["83874.73000000", "0.04000000"], ["83873.05000000", "0.08000000"], ["83869.70000000", "0.04000000"], ["83869.44000000", "0.00000000"], ["83867.02000000", "0.00000000"], ["83864.79000000", "0.00000000"], ["83864.44000000", "0.00060000"], ["83863.64000000", "0.00000000"], ["83861.97000000", "0.00000000"], ["83854.46000000", "0.00000000"], ["83852.88000000", "0.00000000"], ["83847.85000000", "0.00000000"], ["83846.12000000", "0.00000000"], ["83845.77000000", "0.00060000"], ["83785.42000000", "0.00000000"], ["83778.41000000", "0.00000000"], ["83777.69000000", "0.00400000"], ["83771.98000000", "0.00000000"], ["83766.65000000", "0.00000000"], ["83735.39000000", "0.01786000"], ["83734.85000000", "0.00000000"], ["83732.65000000", "0.00000000"], ["82686.46000000", "0.00100000"], ["75551.00000000", "0.10027000"], ["67156.52000000", "0.00058000"], ["60000.00000000", "72.96736000"], ["33000.00000000", "2.96666000"], ["20002.00000000", "0.00000000"], ["20001.00000000", "0.02099000"]], "a": [["83945.66000000", "4.21962000"], ["83946.91000000", "0.00014000"], ["83946.92000000", "0.12008000"], ["83946.93000000", "0.00000000"], ["83947.05000000", "0.00000000"], ["83947.06000000", "0.00006000"], ["83947.33000000", "0.01191000"], ["83947.42000000", "0.00014000"], ["83947.66000000", "0.14901000"], ["83948.13000000", "0.04000000"], ["83948.86000000", "0.00000000"], ["83949.08000000", "0.00000000"], ["83949.09000000", "0.00006000"], ["83949.31000000", "0.02385000"], ["83949.65000000", "0.00000000"], ["83949.89000000", "0.00000000"], ["83949.90000000", "0.00500000"], ["83950.19000000", "0.02327000"], ["83950.45000000", "0.15529000"], ["83951.16000000", "0.00000000"], ["83951.38000000", "0.64701000"], ["83951.39000000", "0.78654000"], ["83951.42000000", "0.21870000"], ["83952.40000000", "0.00000000"], ["83953.11000000", "0.00357000"], ["83955.68000000", "0.00922000"], ["83955.92000000", "0.00000000"], ["83955.99000000", "0.00091000"], ["83956.23000000", "0.00000000"], ["83956.29000000", "0.00000000"], ["83956.37000000", "0.00422000"], ["83961.31000000", "0.00757000"], ["83961.43000000", "0.46762000"], ["83968.58000000", "0.00000000"], ["83972.06000000", "0.85783000"], ["83972.30000000", "0.00000000"], ["83978.25000000", "0.85777000"], ["83980.49000000", "0.00000000"], ["83981.13000000", "0.80668000"], ["83981.69000000", "0.85774000"], ["83981.88000000", "0.00000000"], ["83983.30000000", "0.00000000"], ["83985.20000000", "0.00000000"], ["83986.20000000", "0.05000000"], ["83993.76000000", "0.16360000"], ["83994.81000000", "0.00000000"], ["84000.17000000", "0.02808000"], ["84004.93000000", "0.04110000"], ["84058.69000000", "0.02384000"], ["84065.05000000", "0.00000000"], ["85204.85000000", "0.00100000"], ["85864.47000000", "0.00000000"]], "record_time": 1742577150.211968, "EXCHANGE": "BINANCE"}
{"e": "depthUpdate", "E": 1742577151014, "s": "BTCUSDT", "U": 64632184390, "u": 64632184603, "b": [["83945.65000000", "1.21326000"], ["83945.07000000", "0.00007000"], ["83944.71000000", "0.00014000"], ["83944.70000000", "0.05628000"], ["83942.50000000", "0.00000000"], ["83942.49000000", "0.02013000"], ["83942.41000000", "0.00000000"], ["83942.40000000", "0.00014000"], ["83942.10000000", "0.00007000"], ["83941.85000000", "0.00000000"], ["83939.99000000", "0.02214000"], ["83938.64000000", "0.00757000"], ["83936.16000000", "0.00000000"], ["83935.05000000", "0.00412000"], ["83933.21000000", "0.00000000"], ["83932.80000000", "0.00086000"], ["83932.57000000", "0.00000000"], ["83927.09000000", "0.59588000"], ["83925.82000000", "0.00000000"], ["83925.77000000", "0.00000000"], ["83922.96000000", "0.01192000"], ["83922.95000000", "0.00000000"], ["83917.61000000", "0.37753000"], ["83914.64000000", "0.72019000"], ["83910.79000000", "0.00000000"], ["83906.09000000", "0.00000000"], ["83899.80000000", "0.00000000"], ["83877.66000000", "0.02859000"], ["83864.51000000", "0.00060000"], ["83864.44000000", "0.00000000"], ["83860.92000000", "0.44383000"], ["83857.93000000", "0.63073000"], ["83845.84000000", "0.00060000"], ["83845.77000000", "0.00000000"], ["83784.96000000", "0.00000000"], ["83777.69000000", "0.00000000"], ["83772.11000000", "0.00400000"], ["83735.39000000", "0.00000000"], ["83732.78000000", "0.01786000"], ["83106.19000000", "0.00000000"], ["82686.46000000", "0.00000000"], ["82500.00000000", "19.59548000"], ["82100.09000000", "0.14616000"], ["75551.00000000", "0.10027000"], ["67156.52000000", "0.00058000"], ["60000.00000000", "72.96726000"], ["33000.00000000", "2.96666000"]], "a": [["83945.66000000", "4.21312000"], ["83947.33000000", "0.01191000"], ["83949.90000000", "0.01000000"], ["83950.19000000", "0.00000000"], ["83951.38000000", "0.53601000"], ["83951.39000000", "0.00000000"], ["83951.41000000", "0.00000000"], ["83951.58000000", "0.78654000"], ["83953.12000000", "0.00000000"], ["83954.06000000", "0.45000000"], ["83956.09000000", "0.00000000"], ["83956.63000000", "0.00000000"], ["83956.77000000", "0.03099000"], ["83961.31000000", "0.00000000"], ["83961.43000000", "0.00000000"], ["83975.26000000", "1.46241000"], ["83985.59000000", "0.00000000"], ["83989.64000000", "0.59586000"], ["83990.23000000", "0.00000000"], ["83999.79000000", "0.04319000"], ["84000.17000000", "0.00000000"], ["84004.44000000", "0.00000000"], ["84007.86000000", "0.00936000"], ["84009.57000000", "0.01872000"], ["84021.71000000", "0.07329000"], ["84043.71000000", "0.00060000"], ["84047.96000000", "0.00000000"], ["84106.25000000", "0.00050000"], ["84106.35000000", "0.00000000"], ["85204.85000000", "0.00000000"], ["85410.23000000", "0.00060000"], ["85416.21000000", "0.00060000"], ["85448.85000000", "0.00000000"], ["85454.83000000", "0.00000000"], ["85864.50000000", "0.01457000"], ["86913.13000000", "0.00385000"]], "record_time": 1742577151.212142, "EXCHANGE": "BINANCE"}
{"e": "depthUpdate", "E": 1742577152014, "s": "BTCUSDT", "U": 64632184604, "u": 64632184809, "b": [["83945.65000000", "1.36492000"], ["83945.61000000", "0.00021000"], ["83945.60000000", "0.34265000"], ["83945.21000000", "0.00015000"], ["83945.07000000", "0.00000000"], ["83944.73000000", "0.00000000"], ["83944.72000000", "0.00000000"], ["83944.71000000", "0.00000000"], ["83944.70000000", "0.05635000"], ["83944.67000000", "0.00007000"], ["83944.01000000", "0.00000000"], ["83942.52000000", "0.00000000"], ["83942.51000000", "0.02392000"], ["83942.49000000", "0.02006000"], ["83942.40000000", "0.00000000"], ["83942.10000000", "0.00000000"], ["83941.88000000", "0.04000000"], ["83935.62000000", "0.00000000"], ["83935.36000000", "0.00090000"], ["83935.23000000", "0.00096000"], ["83928.11000000", "0.55083000"], ["83927.84000000", "0.77652000"], ["83927.09000000", "0.00000000"], ["83927.08000000", "0.00120000"], ["83924.08000000", "0.66522000"], ["83924.07000000", "1.34295000"], ["83922.97000000", "0.59589000"], ["83922.96000000", "0.00000000"], ["83921.51000000", "0.13908000"], ["83917.30000000", "0.00000000"], ["83909.70000000", "0.00000000"], ["83905.45000000", "0.05000000"], ["83868.78000000", "0.00000000"], ["83811.53000000", "0.04498000"], ["83777.65000000", "0.00400000"], ["83772.11000000", "0.00000000"], ["83767.69000000", "0.00000000"], ["83756.55000000", "0.00839000"], ["83734.66000000", "0.01786000"], ["83732.78000000", "0.00000000"], ["83665.96000000", "0.01865000"], ["82883.63000000", "0.40000000"], ["82875.28000000", "0.00000000"], ["82686.46000000", "0.00100000"], ["75551.08000000", "0.00080000"], ["75551.00000000", "0.10027000"], ["75542.38000000", "0.00000000"], ["75539.09000000", "0.00064000"], ["67156.52000000", "0.00058000"], ["33000.00000000", "2.96666000"], ["30220.44000000", "0.00420000"]], "a": [["83945.66000000", "4.43089000"], ["83945.67000000", "0.00705000"], ["83946.58000000", "0.00000000"], ["83946.59000000", "0.00000000"], ["83947.33000000", "0.00408000"], ["83949.28000000", "0.02407000"], ["83950.45000000", "0.00000000"], ["83951.42000000", "0.00000000"], ["83951.52000000", "0.47650000"], ["83953.80000000", "0.00019000"], ["83953.85000000", "0.20178000"], ["83955.82000000", "0.00000000"], ["83955.99000000", "0.00000000"], ["83956.66000000", "0.00000000"], ["83958.42000000", "0.06400000"], ["83958.90000000", "0.00059000"], ["83958.93000000", "0.00058000"], ["83958.95000000", "0.00059000"], ["83960.10000000", "0.05200000"], ["83960.19000000", "0.07200000"], ["83961.00000000", "0.00031000"], ["83961.08000000", "0.71458000"], ["83961.21000000", "0.00851000"], ["83961.53000000", "0.00028000"], ["83961.67000000", "0.04000000"], ["83962.79000000", "0.00000000"], ["83964.08000000", "1.00000000"], ["83964.47000000", "0.00000000"], ["83964.57000000", "0.00000000"], ["83967.28000000", "1.38269000"], ["83971.06000000", "0.00000000"], ["83971.48000000", "0.00000000"], ["83972.05000000", "1.06452000"], ["83974.28000000", "0.00000000"], ["83974.42000000", "0.00000000"], ["83989.64000000", "1.07236000"], ["84106.15000000", "0.00050000"], ["84106.25000000", "0.00000000"], ["84909.54000000", "0.00000000"], ["84917.96000000", "0.60000000"], ["85204.85000000", "0.00100000"]], "record_time": 1742577152.211611, "EXCHANGE": "BINANCE"}
{"e": "depthUpdate", "E": 1742577153014, "s": "BTCUSDT", "U": 64632184810, "u": 64632185043, "b": [["83945.65000000", "1.25267000"], ["83945.61000000", "0.00007000"], ["83945.60000000", "0.00007000"], ["83945.59000000", "0.00021000"], ["83945.58000000", "0.27398000"], ["83945.40000000", "0.00007000"], ["83945.26000000", "0.00202000"], ["83945.21000000", "0.00008000"], ["83944.71000000", "0.00000000"], ["83944.70000000", "0.05628000"], ["83944.58000000", "0.00000000"], ["83944.01000000", "0.00000000"], ["83942.52000000", "0.00000000"], ["83942.49000000", "0.02006000"], ["83942.40000000", "0.00000000"], ["83942.10000000", "0.00000000"], ["83941.88000000", "0.00000000"], ["83941.75000000", "0.00000000"], ["83940.18000000", "0.04000000"], ["83939.12000000", "0.05364000"], ["83937.42000000", "0.00000000"], ["83937.02000000", "0.00000000"], ["83936.40000000", "0.00500000"], ["83935.74000000", "0.00095000"], ["83935.36000000", "0.00000000"], ["83935.23000000", "0.00000000"], ["83928.11000000", "0.34242000"], ["83927.84000000", "0.00000000"], ["83922.97000000", "0.00000000"], ["83918.90000000", "0.59592000"], ["83909.79000000", "0.00000000"], ["83905.45000000", "0.00000000"], ["83904.95000000", "0.00146000"], ["83895.83000000", "0.00000000"], ["83894.23000000", "0.00297000"], ["83889.68000000", "0.31654000"], ["83886.80000000", "0.00296000"], ["83882.59000000", "0.00000000"], ["83881.59000000", "0.00280000"], ["83876.06000000", "0.00000000"], ["83864.54000000", "0.00060000"], ["83864.51000000", "0.00000000"], ["83850.01000000", "0.00146000"], ["83845.87000000", "0.00060000"], ["83845.84000000", "0.00000000"], ["83827.32000000", "0.00000000"], ["83810.43000000", "0.00119000"], ["83803.44000000", "0.00119000"], ["83797.63000000", "0.00268000"], ["83787.06000000", "0.00000000"], ["83783.16000000", "0.00000000"], ["83780.77000000", "0.00000000"], ["83780.57000000", "0.01000000"], ["83780.17000000", "0.00000000"], ["83777.65000000", "0.00000000"], ["83775.48000000", "0.00400000"], ["83769.42000000", "0.00000000"], ["83769.02000000", "0.00000000"], ["83744.02000000", "0.01865000"], ["83665.96000000", "0.00000000"], ["83450.00000000", "0.24744000"], ["82686.46000000", "0.00000000"], ["75551.08000000", "0.00096000"], ["75551.00000000", "0.10027000"], ["67156.52000000", "0.00058000"], ["33000.00000000", "2.96666000"], ["30240.61000000", "0.00000000"], ["30226.30000000", "0.00000000"], ["30221.20000000", "0.00000000"], ["30220.44000000", "0.00460000"], ["30212.15000000", "0.00000000"], ["30208.70000000", "0.00280000"], ["30204.07000000", "0.00120000"], ["30201.86000000", "0.00040000"], ["30199.25000000", "0.01180000"], ["30194.34000000", "0.00060000"], ["30188.72000000", "0.00000000"], ["30186.27000000", "0.00040000"], ["30183.84000000", "0.00080000"], ["30179.79000000", "0.00120000"], ["30178.80000000", "0.00000000"], ["30178.07000000", "0.00000000"], ["30175.90000000", "0.00120000"], ["30173.48000000", "0.00240000"], ["30171.19000000", "0.00000000"], ["30171.03000000", "0.00000000"], ["30168.84000000", "0.00400000"], ["30165.28000000", "0.00800000"], ["30154.88000000", "0.00020000"], ["30151.80000000", "0.00000000"], ["30150.98000000", "0.00060000"], ["30036.01000000", "0.00080000"]], "a": [["83945.66000000", "4.62072000"], ["83945.86000000", "0.00201000"], ["83947.33000000", "0.01191000"], ["83949.83000000", "0.00000000"], ["83949.84000000", "0.00000000"], ["83949.90000000", "0.00500000"], ["83951.58000000", "0.00000000"], ["83951.73000000", "0.78654000"], ["83955.03000000", "0.00058000"], ["83956.33000000", "0.00000000"], ["83956.37000000", "0.00000000"], ["83956.49000000", "0.00000000"], ["83957.38000000", "0.00417000"], ["83967.90000000", "0.00000000"], ["83975.77000000", "0.00507000"], ["83980.86000000", "0.05000000"], ["83985.80000000", "0.13972000"], ["83986.20000000", "0.00000000"], ["84020.71000000", "0.01865000"], ["84021.71000000", "0.05464000"], ["84027.84000000", "0.00000000"], ["84031.87000000", "0.00297000"], ["84032.64000000", "0.89526000"], ["84034.81000000", "0.00000000"], ["84038.09000000", "0.77473000"], ["84039.30000000", "0.00297000"], ["84040.46000000", "1.21806000"], ["84052.19000000", "0.00000000"], ["84058.69000000", "0.00000000"], ["84106.15000000", "0.00050000"], ["84111.80000000", "0.00000000"], ["84115.99000000", "0.00119000"], ["84119.85000000", "0.00000000"], ["84123.51000000", "0.00119000"], ["84281.45000000", "0.00008000"], ["85204.85000000", "0.00000000"]], "record_time": 1742577153.211915, "EXCHANGE": "BINANCE"}
{"e": "depthUpdate", "E": 1742577154014, "s": "BTCUSDT", "U": 64632185044, "u": 64632185136, "b": [["83945.65000000", "1.37231000"], ["83941.78000000", "0.05364000"], ["83940.16000000", "0.00835000"], ["83939.12000000", "0.00000000"], ["83938.64000000", "0.00000000"], ["83935.46000000", "0.00000000"], ["83924.08000000", "0.27475000"], ["83924.07000000", "0.00000000"], ["83923.77000000", "0.52246000"], ["83921.27000000", "1.31198000"], ["83915.40000000", "0.00000000"], ["83908.29000000", "0.00000000"], ["83905.30000000", "0.00000000"], ["83903.89000000", "0.00000000"], ["83882.46000000", "0.00000000"], ["83878.95000000", "0.00023000"], ["83864.54000000", "0.00000000"], ["83864.49000000", "0.00060000"], ["83845.87000000", "0.00000000"], ["83845.82000000", "0.00073000"], ["83816.95000000", "0.00679000"], ["83816.88000000", "0.00000000"], ["83744.02000000", "0.00000000"], ["83667.36000000", "0.00000000"], ["82686.46000000", "0.00100000"], ["75551.00000000", "0.10027000"], ["75537.00000000", "0.00000000"], ["75533.77000000", "0.00000000"], ["67156.52000000", "0.00058000"], ["33000.00000000", "2.96666000"], ["30220.44000000", "0.00500000"]], "a": [["83945.66000000", "4.58709000"], ["83946.26000000", "0.00014000"], ["83946.27000000", "0.03332000"], ["83947.33000000", "0.00000000"], ["83948.50000000", "0.00000000"], ["83949.28000000", "0.00000000"], ["83949.90000000", "0.00000000"], ["83951.73000000", "0.00000000"], ["83953.81000000", "0.73137000"], ["83953.82000000", "0.78652000"], ["83953.85000000", "0.00000000"], ["83958.60000000", "0.00000000"], ["83967.28000000", "0.00000000"], ["83967.29000000", "1.36705000"], ["83980.86000000", "0.00000000"], ["83984.47000000", "0.05000000"], ["84056.69000000", "0.02384000"], ["84079.46000000", "0.00000000"], ["84079.54000000", "0.00679000"], ["84106.05000000", "0.00050000"], ["84106.15000000", "0.00000000"], ["85204.85000000", "0.00100000"]], "record_time": 1742577154.212164, "EXCHANGE": "BINANCE"}
{"e": "depthUpdate", "E": 1742577155014, "s": "BTCUSDT", "U": 64632185137, "u": 64632185300, "b": [["83945.65000000", "1.26192000"], ["83945.59000000", "0.00007000"], ["83945.58000000", "0.00007000"], ["83944.94000000", "0.00014000"], ["83944.93000000", "0.28190000"], ["83944.71000000", "0.00000000"], ["83944.70000000", "0.00000000"], ["83944.67000000", "0.00000000"], ["83944.01000000", "0.00000000"], ["83942.52000000", "0.00000000"], ["83942.50000000", "0.00000000"], ["83942.49000000", "0.02013000"], ["83942.40000000", "0.00000000"], ["83942.39000000", "0.04000000"], ["83942.10000000", "0.00000000"], ["83936.40000000", "0.00500000"], ["83935.74000000", "0.00000000"], ["83935.71000000", "0.00096000"], ["83935.54000000", "0.00000000"], ["83929.99000000", "0.25978000"], ["83929.71000000", "0.00000000"], ["83926.33000000", "0.10784000"], ["83924.08000000", "0.47726000"], ["83923.77000000", "0.00000000"], ["83903.89000000", "0.05000000"], ["83834.82000000", "0.00000000"], ["83793.02000000", "0.00622000"], ["83768.78000000", "0.00000000"], ["83756.55000000", "0.00000000"], ["83755.84000000", "0.00908000"], ["82686.46000000", "0.00000000"], ["75551.00000000", "0.10027000"], ["70500.00000000", "21.84431000"], ["67156.52000000", "0.00058000"], ["33000.00000000", "2.96666000"], ["30220.44000000", "0.00520000"], ["20002.00000000", "0.00000000"], ["20001.00000000", "0.02099000"]], "a": [["83945.66000000", "4.58680000"], ["83946.26000000", "0.00000000"], ["83946.27000000", "0.00000000"], ["83947.10000000", "0.03281000"], ["83947.33000000", "0.00067000"], ["83947.65000000", "0.00008000"], ["83949.09000000", "0.00000000"], ["83949.28000000", "0.00000000"], ["83949.31000000", "0.02448000"], ["83949.90000000", "0.00500000"], ["83949.94000000", "0.02423000"], ["83953.86000000", "0.00058000"], ["83955.85000000", "0.06400000"], ["83956.41000000", "0.00000000"], ["83960.05000000", "0.00000000"], ["83961.08000000", "0.71517000"], ["83961.20000000", "0.00399000"], ["83961.21000000", "0.00952000"], ["83961.82000000", "0.00059000"], ["83980.97000000", "0.05000000"], ["83984.47000000", "0.00000000"], ["83985.40000000", "0.00000000"], ["84003.34000000", "0.00000000"], ["84007.86000000", "0.00000000"], ["84009.14000000", "0.00936000"], ["84011.00000000", "0.00000000"], ["84031.59000000", "0.03992000"], ["84038.09000000", "0.47036000"], ["84040.46000000", "0.00000000"], ["84043.23000000", "1.27303000"], ["85204.85000000", "0.00000000"], ["87300.00000000", "4.76741000"]], "record_time": 1742577155.212396, "EXCHANGE": "BINANCE"}
{"e": "depthUpdate", "E": 1742577156014, "s": "BTCUSDT", "U": 64632185301, "u": 64632185421, "b": [["83945.65000000", "0.97009000"], ["83942.90000000", "0.00000000"], ["83940.00000000", "0.01422000"], ["83939.54000000", "0.00000000"], ["83936.40000000", "0.00000000"], ["83935.85000000", "0.00000000"], ["83935.76000000", "0.00000000"], ["83935.71000000", "0.00000000"], ["83935.56000000", "0.00000000"], ["83932.80000000", "0.00086000"], ["83913.04000000", "0.02123000"], ["83908.09000000", "0.00000000"], ["83903.89000000", "0.00000000"], ["83898.92000000", "0.00000000"], ["83887.82000000", "0.04440000"], ["83870.36000000", "0.04498000"], ["83857.95000000", "0.00100000"], ["83810.33000000", "0.04498000"], ["83783.82000000", "0.00000000"], ["83777.21000000", "0.00400000"], ["83775.48000000", "0.00000000"], ["83500.00000000", "3.43552000"], ["83106.19000000", "0.00000000"], ["83022.37000000", "0.06004000"], ["82686.46000000", "0.00100000"], ["76700.00000000", "8.07090000"], ["75551.00000000", "0.10027000"], ["67156.52000000", "0.00058000"], ["33000.00000000", "2.96666000"], ["30220.44000000", "0.00540000"]], "a": [["83945.66000000", "4.36263000"], ["83947.10000000", "0.03315000"], ["83947.33000000", "0.00000000"], ["83949.94000000", "0.00000000"], ["83950.35000000", "0.15529000"], ["83954.06000000", "0.54600000"], ["83954.90000000", "0.06800000"], ["83955.74000000", "0.14400000"], ["83955.75000000", "0.00000000"], ["83955.89000000", "0.00000000"], ["83955.98000000", "0.00089000"], ["83955.99000000", "0.00000000"], ["83958.26000000", "0.00000000"], ["83959.10000000", "0.06000000"], ["83959.94000000", "0.04800000"], ["83959.95000000", "0.00000000"], ["83963.31000000", "0.00000000"], ["83964.15000000", "0.00000000"], ["83978.27000000", "0.08627000"], ["83980.97000000", "0.00000000"], ["83982.54000000", "0.00000000"], ["83985.80000000", "0.23551000"], ["83985.91000000", "0.37751000"], ["83991.59000000", "0.00000000"], ["84003.34000000", "0.06400000"], ["84020.71000000", "0.00000000"], ["84034.27000000", "0.00100000"], ["84042.11000000", "0.73388000"], ["84105.95000000", "0.00050000"], ["84106.05000000", "0.00000000"], ["85204.85000000", "0.00100000"]], "record_time": 1742577156.211785, "EXCHANGE": "BINANCE"}
{"e": "depthUpdate", "E": 1742577157014, "s": "BTCUSDT", "U": 64632185422, "u": 64632185488, "b": [["83945.65000000", "1.40094000"], ["83908.89000000", "0.00000000"], ["83903.89000000", "0.00000000"], ["83857.93000000", "0.63073000"], ["83780.77000000", "0.01000000"], ["83780.67000000", "0.00000000"], ["83780.57000000", "0.00000000"], ["83734.66000000", "0.00000000"], ["82686.46000000", "0.00000000"], ["75551.00000000", "0.10027000"], ["67156.52000000", "0.00058000"], ["42000.00000000", "6.84810000"], ["33000.00000000", "2.96666000"], ["30220.44000000", "0.00560000"]], "a": [["83945.66000000", "4.14383000"], ["83947.10000000", "0.00000000"], ["83947.33000000", "0.00000000"], ["83947.37000000", "0.03384000"], ["83949.90000000", "0.01000000"], ["83950.13000000", "0.00000000"], ["83951.15000000", "0.22961000"], ["83955.66000000", "0.00000000"], ["83961.20000000", "0.00637000"], ["83974.31000000", "0.00151000"], ["83983.04000000", "0.00000000"], ["83985.04000000", "0.05000000"], ["84009.14000000", "0.00000000"], ["84009.57000000", "0.00000000"], ["84015.55000000", "0.02808000"], ["84028.72000000", "0.00151000"], ["85204.85000000", "0.00000000"]], "record_time": 1742577157.219295, "EXCHANGE": "BINANCE"}
{"e": "depthUpdate", "E": 1742577158014, "s": "BTCUSDT", "U": 64632185489, "u": 64632187021, "b": [["83945.65000000", "0.00000000"], ["83945.64000000", "0.00000000"], ["83945.61000000", "0.00000000"], ["83945.60000000", "0.00000000"], ["83945.59000000", "0.00000000"], ["83945.58000000", "0.00000000"], ["83945.51000000", "0.00000000"], ["83945.40000000", "0.00000000"], ["83945.26000000", "0.00000000"], ["83945.21000000", "0.00000000"], ["83944.94000000", "0.00000000"], ["83944.93000000", "0.00000000"], ["83944.67000000", "0.00000000"], ["83944.60000000", "0.00000000"], ["83944.00000000", "0.00000000"], ["83943.84000000", "0.00000000"], ["83942.52000000", "0.00000000"], ["83942.51000000", "0.00000000"], ["83942.50000000", "0.00000000"], ["83942.49000000", "0.00000000"], ["83942.40000000", "0.00000000"], ["83942.39000000", "2.16074000"], ["83942.38000000", "0.00048000"], ["83942.17000000", "0.00007000"], ["83942.11000000", "0.00018000"], ["83942.10000000", "0.00007000"], ["83942.09000000", "0.00007000"], ["83942.05000000", "0.00108000"], ["83942.04000000", "0.00015000"], ["83942.01000000", "0.00000000"], ["83942.00000000", "0.00000000"], ["83941.79000000", "0.00000000"], ["83941.78000000", "0.00000000"], ["83941.71000000", "0.00000000"], ["83941.59000000", "0.00000000"], ["83941.55000000", "0.00000000"], ["83941.54000000", "0.00000000"], ["83941.33000000", "0.00007000"], ["83941.26000000", "0.00000000"], ["83941.20000000", "0.00000000"], ["83940.62000000", "0.00000000"], ["83940.60000000", "0.00000000"], ["83940.50000000", "0.00000000"], ["83940.39000000", "0.00000000"], ["83940.38000000", "0.00014000"], ["83940.37000000", "0.02359000"], ["83940.20000000", "0.00014000"], ["83940.19000000", "0.09079000"], ["83940.18000000", "0.04007000"], ["83940.16000000", "0.00000000"], ["83940.09000000", "0.00000000"], ["83940.00000000", "0.00012000"], ["83939.99000000", "0.00000000"], ["83939.94000000", "0.00000000"], ["83939.03000000", "0.00014000"], ["83939.02000000", "0.05867000"], ["83938.96000000", "0.00000000"], ["83938.95000000", "0.00000000"], ["83938.88000000", "0.00000000"], ["83938.83000000", "0.00007000"], ["83938.82000000", "0.00000000"], ["83938.81000000", "0.00000000"], ["83938.77000000", "0.00007000"], ["83938.76000000", "0.02379000"], ["83938.38000000", "0.00000000"], ["83938.30000000", "0.00007000"], ["83938.29000000", "0.02000000"], ["83938.00000000", "0.01410000"], ["83937.99000000", "0.12000000"], ["83937.98000000", "0.00000000"], ["83937.89000000", "0.05364000"], ["83937.84000000", "0.00000000"], ["83937.73000000", "0.00000000"], ["83937.64000000", "0.00000000"], ["83937.63000000", "0.00000000"], ["83937.48000000", "0.00000000"], ["83937.31000000", "0.00123000"], ["83937.30000000", "0.03407000"], ["83937.08000000", "0.00000000"], ["83937.06000000", "0.00000000"], ["83936.78000000", "0.00000000"], ["83936.66000000", "0.00000000"], ["83936.50000000", "0.00755000"], ["83936.42000000", "0.00000000"], ["83936.27000000", "0.00000000"], ["83936.23000000", "0.00000000"], ["83936.03000000", "0.00000000"], ["83936.00000000", "0.00000000"], ["83935.75000000", "0.00095000"], ["83935.39000000", "0.00000000"], ["83935.29000000", "0.00000000"], ["83935.18000000", "0.00119000"], ["83935.08000000", "0.01500000"], ["83935.04000000", "0.00000000"], ["83934.91000000", "0.00000000"], ["83934.75000000", "0.00000000"], ["83934.64000000", "0.00090000"], ["83934.57000000", "0.01500000"], ["83934.49000000", "0.20165000"], ["83934.09000000", "0.00029000"], ["83934.03000000", "0.00000000"], ["83933.99000000", "0.45000000"], ["83933.75000000", "0.00000000"], ["83933.74000000", "0.00000000"], ["83933.44000000", "0.00000000"], ["83932.56000000", "0.00000000"], ["83932.32000000", "0.00000000"], ["83932.11000000", "0.00000000"], ["83932.10000000", "0.04000000"], ["83932.04000000", "0.47650000"], ["83932.03000000", "0.00000000"], ["83931.92000000", "0.17899000"], ["83931.86000000", "0.16253000"], ["83931.44000000", "0.16000000"], ["83931.19000000", "0.00008000"], ["83931.11000000", "0.00000000"], ["83930.88000000", "0.00000000"], ["83930.80000000", "0.00000000"], ["83930.43000000", "0.08000000"], ["83930.33000000", "0.04000000"], ["83929.99000000", "0.00000000"], ["83928.90000000", "0.00000000"], ["83928.86000000", "0.00000000"], ["83928.11000000", "0.49208000"], ["83927.95000000", "0.21181000"], ["83927.90000000", "0.04000000"], ["83927.84000000", "0.04000000"], ["83927.80000000", "0.00000000"], ["83927.78000000", "0.00000000"], ["83927.08000000", "0.00000000"], ["83927.07000000", "0.04000000"], ["83926.33000000", "0.00000000"], ["83926.23000000", "0.08000000"], ["83926.14000000", "0.04000000"], ["83925.81000000", "0.00000000"], ["83925.69000000", "0.00000000"], ["83925.38000000", "0.00000000"], ["83925.32000000", "0.00000000"], ["83925.30000000", "0.45000000"], ["83924.73000000", "0.71399000"], ["83924.08000000", "0.50069000"], ["83923.77000000", "0.20292000"], ["83923.51000000", "1.32476000"], ["83922.12000000", "0.00240000"], ["83921.90000000", "0.35737000"], ["83921.56000000", "0.10784000"], ["83921.51000000", "0.02426000"], ["83921.27000000", "0.00000000"], ["83920.46000000", "0.00000000"], ["83920.17000000", "0.59593000"], ["83920.16000000", "0.49198000"], ["83920.15000000", "0.00000000"], ["83919.06000000", "0.71399000"], ["83918.90000000", "0.00000000"], ["83918.07000000", "0.00000000"], ["83917.89000000", "0.00000000"], ["83917.33000000", "0.05956000"], ["83917.24000000", "0.00000000"], ["83916.52000000", "0.33315000"], ["83916.09000000", "0.12100000"], ["83914.65000000", "0.00000000"], ["83914.14000000", "0.00000000"], ["83909.98000000", "0.00000000"], ["83909.89000000", "0.00000000"], ["83908.56000000", "0.45221000"], ["83904.95000000", "0.00000000"], ["83901.46000000", "0.00146000"], ["83900.88000000", "0.00000000"], ["83896.09000000", "0.00000000"], ["83895.22000000", "0.00000000"], ["83894.23000000", "0.00000000"], ["83893.45000000", "0.04440000"], ["83892.84000000", "0.00000000"], ["83891.68000000", "0.06102000"], ["83891.59000000", "0.00000000"], ["83891.49000000", "0.00387000"], ["83890.77000000", "0.00297000"], ["83890.58000000", "0.05956000"], ["83887.82000000", "0.00000000"], ["83886.80000000", "0.00000000"], ["83886.79000000", "0.47055000"], ["83884.01000000", "0.00297000"], ["83883.72000000", "0.10454000"], ["83881.59000000", "0.00000000"], ["83880.43000000", "0.44396000"], ["83880.23000000", "0.00826000"], ["83879.99000000", "0.00000000"], ["83877.67000000", "0.00273000"], ["83877.28000000", "0.04198000"], ["83877.18000000", "0.00858000"], ["83877.10000000", "0.00000000"], ["83876.63000000", "0.00806000"], ["83874.03000000", "0.22490000"], ["83873.81000000", "0.00000000"], ["83872.28000000", "0.00061000"], ["83870.76000000", "0.40277000"], ["83870.36000000", "0.00000000"], ["83867.02000000", "0.00000000"], ["83863.64000000", "0.00000000"], ["83861.97000000", "0.00000000"], ["83860.92000000", "0.27361000"], ["83857.93000000", "0.00000000"], ["83855.59000000", "0.00000000"], ["83854.46000000", "0.00000000"], ["83853.71000000", "0.00000000"], ["83852.88000000", "0.00000000"], ["83852.04000000", "0.00000000"], ["83850.01000000", "0.00000000"], ["83848.69000000", "0.00000000"], ["83847.85000000", "0.00000000"], ["83847.21000000", "0.00146000"], ["83846.10000000", "0.01196000"], ["83841.14000000", "0.09411000"], ["83839.42000000", "0.04883000"], ["83838.75000000", "0.14645000"], ["83831.49000000", "0.00000000"], ["83828.01000000", "0.00083000"], ["83819.40000000", "0.05497000"], ["83816.78000000", "0.05497000"], ["83816.28000000", "0.05497000"], ["83810.19000000", "0.80573000"], ["83808.87000000", "0.04198000"], ["83808.83000000", "0.04198000"], ["83805.91000000", "0.04497000"], ["83805.77000000", "0.04497000"], ["83802.90000000", "0.04497000"], ["83797.63000000", "0.00000000"], ["83794.55000000", "0.00263000"], ["83788.24000000", "0.00006000"], ["83780.77000000", "0.00000000"], ["83779.57000000", "0.00000000"], ["83777.57000000", "0.00000000"], ["83777.21000000", "0.00000000"], ["83776.77000000", "0.01000000"], ["83769.84000000", "0.99313000"], ["83764.97000000", "0.00000000"], ["83764.87000000", "0.00000000"], ["83759.59000000", "0.00400000"], ["83755.84000000", "0.00839000"], ["83749.26000000", "0.00000000"], ["83747.43000000", "0.00000000"], ["83745.28000000", "0.00069000"], ["83738.66000000", "0.00000000"], ["83734.50000000", "0.01786000"], ["83688.84000000", "0.01865000"], ["83022.37000000", "0.00000000"], ["82984.80000000", "0.00000000"], ["82942.19000000", "0.00000000"], ["82683.25000000", "0.00100000"], ["81350.00000000", "2.25566000"], ["80589.60000000", "0.00000000"], ["80572.80000000", "0.00000000"], ["76700.00000000", "8.07900000"], ["75551.00000000", "0.10027000"], ["67156.52000000", "0.00000000"], ["67153.92000000", "0.00058000"], ["42000.00000000", "6.84710000"], ["33000.00000000", "2.96666000"], ["30219.26000000", "0.00020000"]], "a": [["83942.40000000", "3.97419000"], ["83942.41000000", "0.00040000"], ["83942.49000000", "0.00014000"], ["83942.50000000", "0.02943000"], ["83942.51000000", "0.00006000"], ["83942.52000000", "0.00000000"], ["83942.53000000", "0.00008000"], ["83942.64000000", "0.00000000"], ["83942.66000000", "0.00000000"], ["83942.75000000", "0.00000000"], ["83942.76000000", "0.00000000"], ["83943.23000000", "0.00000000"], ["83943.25000000", "0.00000000"], ["83943.65000000", "0.00000000"], ["83943.78000000", "0.00000000"], ["83943.85000000", "0.00000000"], ["83943.99000000", "0.00014000"], ["83944.00000000", "0.01416000"], ["83944.07000000", "0.00000000"], ["83944.27000000", "0.00000000"], ["83944.35000000", "0.00000000"], ["83944.61000000", "0.00000000"], ["83944.68000000", "0.00000000"], ["83944.81000000", "0.00000000"], ["83944.84000000", "0.00000000"], ["83944.87000000", "0.00000000"], ["83944.93000000", "0.00000000"], ["83944.94000000", "0.00014000"], ["83944.95000000", "0.08360000"], ["83945.25000000", "0.00000000"], ["83945.26000000", "0.00000000"], ["83945.27000000", "0.00000000"], ["83945.29000000", "0.00000000"], ["83945.40000000", "0.00000000"], ["83945.41000000", "0.00000000"], ["83945.52000000", "0.00000000"], ["83945.54000000", "0.00000000"], ["83945.57000000", "0.00014000"], ["83945.58000000", "0.40324000"], ["83945.59000000", "0.00006000"], ["83945.60000000", "0.00000000"], ["83945.61000000", "0.00000000"], ["83945.62000000", "0.00000000"], ["83945.64000000", "0.00000000"], ["83945.65000000", "0.00000000"], ["83945.66000000", "0.00273000"], ["83945.67000000", "0.00658000"], ["83945.99000000", "0.00000000"], ["83946.00000000", "0.01416000"], ["83946.03000000", "0.02385000"], ["83946.41000000", "0.00023000"], ["83946.42000000", "0.00000000"], ["83946.45000000", "0.00011000"], ["83946.46000000", "0.47650000"], ["83946.56000000", "0.00000000"], ["83946.62000000", "0.00000000"], ["83946.67000000", "0.00000000"], ["83946.68000000", "0.00000000"], ["83946.87000000", "0.00000000"], ["83946.91000000", "0.00000000"], ["83946.92000000", "0.00000000"], ["83947.06000000", "0.00000000"], ["83947.33000000", "0.00000000"], ["83947.36000000", "0.00009000"], ["83947.37000000", "0.03384000"], ["83947.42000000", "0.00000000"], ["83947.43000000", "0.00000000"], ["83947.57000000", "0.00000000"], ["83947.58000000", "0.00000000"], ["83947.66000000", "0.14901000"], ["83948.01000000", "0.00000000"], ["83948.13000000", "0.00000000"], ["83948.25000000", "0.00000000"], ["83949.11000000", "0.00000000"], ["83949.31000000", "0.00000000"], ["83949.32000000", "0.00000000"], ["83949.60000000", "0.00006000"], ["83949.87000000", "0.64898000"], ["83949.88000000", "0.00000000"], ["83950.13000000", "0.00000000"], ["83950.35000000", "0.00000000"], ["83950.41000000", "0.00058000"], ["83950.60000000", "0.00058000"], ["83950.64000000", "0.00029000"], ["83950.75000000", "0.03000000"], ["83951.15000000", "0.00000000"], ["83951.38000000", "0.00000000"], ["83951.52000000", "0.00000000"], ["83951.67000000", "0.00119000"], ["83951.92000000", "0.00000000"], ["83951.98000000", "0.00000000"], ["83952.37000000", "0.00000000"], ["83952.84000000", "0.00000000"], ["83953.01000000", "0.00758000"], ["83953.42000000", "0.08354000"], ["83953.52000000", "0.35737000"], ["83953.63000000", "0.00000000"], ["83953.81000000", "0.82489000"], ["83953.82000000", "0.00000000"], ["83953.86000000", "0.00000000"], ["83954.34000000", "0.00000000"], ["83954.98000000", "0.01191000"], ["83955.68000000", "0.72321000"], ["83955.98000000", "0.00000000"], ["83956.77000000", "0.02345000"], ["83957.38000000", "0.00000000"], ["83957.59000000", "0.04000000"], ["83957.75000000", "0.01191000"], ["83958.24000000", "0.00000000"], ["83958.39000000", "0.02000000"], ["83959.55000000", "0.00000000"], ["83960.14000000", "0.05956000"], ["83964.08000000", "0.00000000"], ["83964.54000000", "0.00000000"], ["83965.04000000", "0.00000000"], ["83966.57000000", "0.00000000"], ["83967.29000000", "1.35958000"], ["83967.37000000", "0.08000000"], ["83967.94000000", "0.05956000"], ["83968.55000000", "0.00000000"], ["83970.59000000", "0.00000000"], ["83970.84000000", "0.00000000"], ["83971.48000000", "0.00151000"], ["83972.06000000", "0.00000000"], ["83974.31000000", "0.00000000"], ["83974.90000000", "0.00000000"], ["83975.90000000", "0.00000000"], ["83976.54000000", "0.85779000"], ["83977.51000000", "0.85778000"], ["83977.55000000", "0.00000000"], ["83978.25000000", "0.00000000"], ["83978.55000000", "0.59594000"], ["83978.56000000", "0.13659000"], ["83980.83000000", "0.00000000"], ["83981.13000000", "0.54936000"], ["83981.37000000", "0.85774000"], ["83981.69000000", "0.00000000"], ["83985.04000000", "0.00000000"], ["83985.60000000", "0.53650000"], ["83986.04000000", "0.00000000"], ["83987.97000000", "0.01512000"], ["83988.26000000", "0.00000000"], ["83989.64000000", "0.00000000"], ["83990.35000000", "0.00854000"], ["83990.67000000", "0.00806000"], ["83991.33000000", "0.00000000"], ["83991.85000000", "0.01196000"], ["83996.34000000", "0.47650000"], ["83997.90000000", "0.04110000"], ["84002.48000000", "0.02808000"], ["84002.66000000", "0.00000000"], ["84003.86000000", "0.00000000"], ["84004.93000000", "0.00000000"], ["84004.99000000", "0.00000000"], ["84015.55000000", "0.00000000"], ["84020.71000000", "0.01865000"], ["84042.11000000", "0.46009000"], ["84043.23000000", "0.05497000"], ["84048.87000000", "0.00000000"], ["84056.69000000", "0.00000000"], ["84072.24000000", "0.12000000"], ["84105.85000000", "0.00050000"], ["84105.95000000", "0.00000000"], ["84106.02000000", "0.00000000"], ["84229.91000000", "0.12878000"], ["84233.22000000", "0.03640000"], ["84238.31000000", "0.16638000"], ["84241.00000000", "0.00000000"], ["84241.60000000", "0.00000000"], ["84246.69000000", "0.03160000"], ["84249.39000000", "0.00000000"], ["85163.44000000", "0.10000000"], ["85201.54000000", "0.00100000"], ["85214.55000000", "0.00000000"], ["150001.00000000", "0.00072000"]], "record_time": 1742577158.212812, "EXCHANGE": "BINANCE"}
{"e": "depthUpdate", "E": 1742577159014, "s": "BTCUSDT", "U": 64632187022, "u": 64632187230, "b": [["83942.39000000", "2.16393000"], ["83942.04000000", "0.00015000"], ["83941.62000000", "0.00014000"], ["83941.61000000", "0.11355000"], ["83941.28000000", "0.00014000"], ["83941.27000000", "0.05371000"], ["83940.50000000", "0.00007000"], ["83940.38000000", "0.00000000"], ["83940.37000000", "0.02359000"], ["83940.21000000", "0.00014000"], ["83940.20000000", "0.12614000"], ["83940.19000000", "0.00007000"], ["83940.18000000", "0.04000000"], ["83939.03000000", "0.00000000"], ["83939.02000000", "0.05860000"], ["83938.00000000", "0.01410000"], ["83937.89000000", "0.00000000"], ["83937.12000000", "0.16253000"], ["83935.75000000", "0.00000000"], ["83935.05000000", "0.00000000"], ["83934.64000000", "0.00000000"], ["83934.49000000", "0.18973000"], ["83931.86000000", "0.00000000"], ["83928.11000000", "0.72349000"], ["83923.77000000", "0.00000000"], ["83923.52000000", "0.08354000"], ["83923.51000000", "0.00000000"], ["83907.34000000", "0.04440000"], ["83906.09000000", "0.05000000"], ["83901.88000000", "0.00000000"], ["83893.45000000", "0.00000000"], ["83890.58000000", "0.00000000"], ["83784.56000000", "0.00400000"], ["83779.31000000", "0.00000000"], ["83777.67000000", "0.00000000"], ["83777.57000000", "0.01000000"], ["83776.77000000", "0.00000000"], ["83759.59000000", "0.00000000"], ["83688.84000000", "0.00000000"], ["83667.66000000", "0.00008000"], ["82683.25000000", "0.00000000"], ["75548.00000000", "0.00000000"], ["67153.92000000", "0.00058000"], ["33000.00000000", "2.96666000"], ["30219.26000000", "0.00080000"]], "a": [["83942.40000000", "3.85838000"], ["83944.95000000", "0.08354000"], ["83945.57000000", "0.00014000"], ["83945.58000000", "0.30386000"], ["83946.45000000", "0.00011000"], ["83946.60000000", "0.01000000"], ["83947.36000000", "0.00000000"], ["83947.37000000", "0.00000000"], ["83947.38000000", "0.03406000"], ["83948.38000000", "0.15084000"], ["83949.11000000", "0.00722000"], ["83949.45000000", "0.22961000"], ["83949.60000000", "0.00006000"], ["83949.87000000", "0.59260000"], ["83949.90000000", "0.00000000"], ["83950.13000000", "0.02389000"], ["83950.41000000", "0.00000000"], ["83950.60000000", "0.00000000"], ["83951.92000000", "0.78654000"], ["83953.59000000", "0.00095000"], ["83953.65000000", "0.00416000"], ["83953.75000000", "0.00090000"], ["83954.36000000", "0.00000000"], ["83955.03000000", "0.00000000"], ["83958.05000000", "0.77406000"], ["83958.90000000", "0.00000000"], ["83958.93000000", "0.00000000"], ["83958.95000000", "0.00000000"], ["83960.76000000", "1.00000000"], ["83961.08000000", "0.71399000"], ["83961.20000000", "0.00000000"], ["83961.21000000", "0.00000000"], ["83961.53000000", "0.00000000"], ["83961.82000000", "0.00000000"], ["83963.88000000", "0.01865000"], ["83967.29000000", "0.00000000"], ["83969.34000000", "0.85786000"], ["83969.48000000", "0.00000000"], ["83973.10000000", "0.85782000"], ["83977.51000000", "0.00000000"], ["83978.55000000", "0.00000000"], ["83982.17000000", "0.00000000"], ["83982.32000000", "0.59591000"], ["83984.13000000", "0.00000000"], ["84020.71000000", "0.00000000"], ["84058.87000000", "0.07681000"], ["84072.37000000", "0.00000000"], ["85163.44000000", "0.10000000"], ["85201.54000000", "0.00000000"], ["85214.55000000", "0.00000000"]], "record_time": 1742577159.21192, "EXCHANGE": "BINANCE"}
{"e": "depthUpdate", "E": 1742577160014, "s": "BTCUSDT", "U": 64632187231, "u": 64632187452, "b": [["83942.39000000", "1.43919000"], ["83942.04000000", "0.00015000"], ["83941.62000000", "0.00000000"], ["83941.61000000", "0.00000000"], ["83941.28000000", "0.00000000"], ["83941.27000000", "0.00000000"], ["83940.50000000", "0.00000000"], ["83940.38000000", "0.00014000"], ["83940.37000000", "0.02359000"], ["83940.21000000", "0.00000000"], ["83940.20000000", "0.00000000"], ["83940.19000000", "0.00021000"], ["83940.18000000", "0.04007000"], ["83939.03000000", "0.00014000"], ["83939.02000000", "0.05867000"], ["83938.76000000", "0.02386000"], ["83938.36000000", "0.00014000"], ["83938.35000000", "0.05364000"], ["83938.00000000", "0.01417000"], ["83937.34000000", "0.02214000"], ["83937.12000000", "0.00000000"], ["83934.49000000", "0.06665000"], ["83933.99000000", "0.00000000"], ["83932.41000000", "0.16253000"], ["83932.22000000", "0.00000000"], ["83931.63000000", "0.00090000"], ["83930.33000000", "0.04414000"], ["83927.85000000", "0.20486000"], ["83926.01000000", "0.00000000"], ["83924.73000000", "0.00000000"], ["83924.08000000", "0.21629000"], ["83920.17000000", "0.59593000"], ["83920.16000000", "0.88860000"], ["83919.95000000", "1.34180000"], ["83916.53000000", "0.00000000"], ["83915.90000000", "0.00000000"], ["83915.40000000", "0.00000000"], ["83907.34000000", "0.00000000"], ["83906.09000000", "0.00000000"], ["83905.30000000", "0.00000000"], ["83901.59000000", "0.05000000"], ["83901.45000000", "0.89344000"], ["83897.76000000", "0.00000000"], ["83890.58000000", "0.00000000"], ["83885.61000000", "0.09937000"], ["83864.54000000", "0.00060000"], ["83864.49000000", "0.00000000"], ["83862.87000000", "0.01200000"], ["83845.87000000", "0.00060000"], ["83845.82000000", "0.00013000"], ["83843.82000000", "0.00006000"], ["83784.56000000", "0.00000000"], ["83762.67000000", "0.00400000"], ["83753.52000000", "0.00011000"], ["83715.78000000", "0.00000000"], ["82984.80000000", "0.02350000"], ["82683.25000000", "0.00100000"], ["80589.60000000", "0.03572000"], ["76700.00000000", "8.07612000"], ["75548.15000000", "0.00025000"], ["75548.00000000", "0.00000000"], ["67153.92000000", "0.00058000"], ["60000.00000000", "72.96736000"], ["33000.00000000", "2.96666000"], ["30219.26000000", "0.00160000"], ["20002.00000000", "0.00000000"], ["20001.00000000", "0.02099000"]], "a": [["83942.40000000", "4.94912000"], ["83944.07000000", "0.00000000"], ["83945.30000000", "0.00400000"], ["83945.58000000", "0.22385000"], ["83946.45000000", "0.00018000"], ["83946.60000000", "0.00500000"], ["83947.38000000", "0.03470000"], ["83947.95000000", "0.00000000"], ["83948.00000000", "0.01410000"], ["83948.38000000", "0.00000000"], ["83949.11000000", "0.01191000"], ["83949.45000000", "0.00000000"], ["83949.79000000", "0.59432000"], ["83949.80000000", "0.00000000"], ["83949.87000000", "0.00000000"], ["83950.16000000", "0.78655000"], ["83951.92000000", "0.00000000"], ["83953.29000000", "0.00415000"], ["83953.59000000", "0.00000000"], ["83953.65000000", "0.00000000"], ["83953.75000000", "0.00000000"], ["83955.30000000", "0.00400000"], ["83956.77000000", "0.00000000"], ["83957.48000000", "0.00000000"], ["83963.69000000", "1.32181000"], ["83977.25000000", "0.05000000"], ["83981.13000000", "0.91679000"], ["83982.40000000", "0.00000000"], ["83984.96000000", "0.00154000"], ["83994.84000000", "0.00000000"], ["83996.34000000", "0.00000000"], ["83997.25000000", "0.47650000"], ["84110.27000000", "0.01141000"], ["85201.54000000", "0.00100000"]], "record_time": 1742577160.212171, "EXCHANGE": "BINANCE"}
{"e": "depthUpdate", "E": 1742577161014, "s": "BTCUSDT", "U": 64632187453, "u": 64632187510, "b": [["83942.39000000", "1.46815000"], ["83934.49000000", "0.19332000"], ["83933.99000000", "0.45000000"], ["83932.65000000", "0.00000000"], ["83920.16000000", "1.24157000"], ["83917.61000000", "0.00000000"], ["83909.43000000", "0.37751000"], ["83890.58000000", "0.00000000"], ["83852.40000000", "0.63076000"], ["83778.57000000", "0.01000000"], ["83778.37000000", "0.00000000"], ["83777.57000000", "0.00000000"], ["83769.00000000", "0.00400000"], ["83762.67000000", "0.00000000"], ["83755.84000000", "0.00000000"], ["83754.43000000", "0.00839000"], ["83102.96000000", "0.00000000"], ["82683.25000000", "0.00000000"], ["75548.15000000", "0.00000000"], ["75548.00000000", "0.00000000"], ["67153.92000000", "0.00058000"], ["60000.00000000", "72.96726000"], ["33000.00000000", "2.96666000"]], "a": [["83942.40000000", "4.94900000"], ["83945.30000000", "0.00000000"], ["83946.60000000", "0.01000000"], ["83955.30000000", "0.00000000"], ["83977.25000000", "0.00000000"], ["83977.56000000", "0.05000000"], ["83988.26000000", "0.59826000"], ["84105.85000000", "0.00000000"], ["84106.15000000", "0.00050000"], ["85201.54000000", "0.00000000"]], "record_time": 1742577161.211984, "EXCHANGE": "BINANCE"}
{"e": "depthUpdate", "E": 1742577162014, "s": "BTCUSDT", "U": 64632187511, "u": 64632187661, "b": [["83942.39000000", "0.68561000"], ["83942.38000000", "0.00048000"], ["83942.37000000", "0.00021000"], ["83942.36000000", "0.03403000"], ["83942.05000000", "0.00101000"], ["83942.04000000", "0.00008000"], ["83940.38000000", "0.00000000"], ["83940.37000000", "0.00000000"], ["83940.18000000", "0.04007000"], ["83939.71000000", "0.00014000"], ["83939.70000000", "0.15991000"], ["83939.67000000", "0.02331000"], ["83939.60000000", "0.00000000"], ["83939.03000000", "0.00000000"], ["83939.02000000", "0.00000000"], ["83938.83000000", "0.00000000"], ["83938.76000000", "0.02379000"], ["83938.36000000", "0.00000000"], ["83938.35000000", "0.05364000"], ["83938.00000000", "0.01410000"], ["83937.34000000", "0.05052000"], ["83936.68000000", "0.02214000"], ["83934.51000000", "0.06516000"], ["83934.50000000", "0.00000000"], ["83934.49000000", "0.00000000"], ["83933.99000000", "0.00000000"], ["83932.24000000", "0.00095000"], ["83929.50000000", "0.00000000"], ["83890.58000000", "0.05956000"], ["83769.00000000", "0.00000000"], ["83763.12000000", "0.00400000"], ["83667.37000000", "0.01865000"], ["82883.63000000", "0.00000000"], ["82875.28000000", "0.40000000"], ["82683.25000000", "0.00100000"], ["75548.00000000", "0.00000000"], ["67153.92000000", "0.00058000"], ["33000.00000000", "2.96666000"], ["30219.26000000", "0.00180000"]], "a": [["83942.40000000", "4.95291000"], ["83944.06000000", "0.00014000"], ["83944.07000000", "0.01191000"], ["83945.58000000", "0.43033000"], ["83946.45000000", "0.00011000"], ["83946.60000000", "0.00500000"], ["83948.40000000", "0.78657000"], ["83949.79000000", "0.40955000"], ["83950.16000000", "0.00000000"], ["83953.29000000", "0.00000000"], ["83963.88000000", "0.00000000"], ["83977.56000000", "0.00000000"], ["83978.65000000", "0.05000000"], ["83983.58000000", "0.00154000"], ["83984.96000000", "0.00000000"], ["83985.59000000", "0.41392000"], ["83985.80000000", "0.00000000"], ["84020.71000000", "0.01865000"], ["84190.07000000", "0.00000000"], ["84909.54000000", "0.60000000"], ["84917.96000000", "0.00000000"], ["85201.54000000", "0.00100000"]], "record_time": 1742577162.211388, "EXCHANGE": "BINANCE"}
{"e": "depthUpdate", "E": 1742577163014, "s": "BTCUSDT", "U": 64632187662, "u": 64632187812, "b": [["83942.39000000", "0.81114000"], ["83942.36000000", "0.03403000"], ["83941.81000000", "0.00071000"], ["83941.80000000", "0.14007000"], ["83941.33000000", "0.00000000"], ["83940.19000000", "0.00007000"], ["83940.18000000", "0.04007000"], ["83939.71000000", "0.00000000"], ["83939.70000000", "0.00000000"], ["83939.67000000", "0.02331000"], ["83938.83000000", "0.00007000"], ["83937.31000000", "0.00000000"], ["83934.53000000", "0.08627000"], ["83934.52000000", "0.00000000"], ["83934.51000000", "0.00000000"], ["83933.99000000", "0.00000000"], ["83932.46000000", "0.00094000"], ["83932.25000000", "0.00090000"], ["83932.24000000", "0.00000000"], ["83931.63000000", "0.00000000"], ["83930.00000000", "0.01910000"], ["83920.16000000", "0.83684000"], ["83919.95000000", "1.31286000"], ["83902.04000000", "0.00000000"], ["83890.58000000", "0.05956000"], ["83890.54000000", "0.00000000"], ["83885.61000000", "0.05497000"], ["83845.50000000", "0.00000000"], ["83778.57000000", "0.01000000"], ["83744.87000000", "0.01865000"], ["83667.37000000", "0.00000000"], ["82840.57000000", "0.00000000"], ["82683.25000000", "0.00000000"], ["75548.15000000", "0.00032000"], ["75548.00000000", "0.00000000"], ["75539.09000000", "0.00032000"], ["67153.92000000", "0.00058000"], ["33000.00000000", "2.96666000"], ["30219.26000000", "0.00200000"]], "a": [["83942.40000000", "4.93436000"], ["83944.06000000", "0.00014000"], ["83944.07000000", "0.01191000"], ["83945.58000000", "0.43033000"], ["83946.45000000", "0.00011000"], ["83946.60000000", "0.00500000"], ["83948.00000000", "0.80067000"], ["83948.40000000", "0.00000000"], ["83949.79000000", "0.40955000"], ["83950.08000000", "0.00000000"], ["83953.22000000", "0.00000000"], ["83957.81000000", "0.00059000"], ["83958.05000000", "1.14427000"], ["83961.29000000", "1.36061000"], ["83963.69000000", "0.00000000"], ["83978.65000000", "0.00000000"], ["83979.65000000", "0.05000000"], ["83981.11000000", "0.00154000"], ["83983.58000000", "0.00000000"], ["83999.79000000", "0.00160000"], ["84026.27000000", "0.00000000"], ["84038.09000000", "0.77698000"], ["84040.46000000", "1.21806000"], ["84106.15000000", "0.00050000"], ["85201.54000000", "0.00000000"]], "record_time": 1742577163.211864, "EXCHANGE": "BINANCE"}
{"e": "depthUpdate", "E": 1742577164014, "s": "BTCUSDT", "U": 64632187813, "u": 64632187884, "b": [["83942.39000000", "1.38339000"], ["83941.80000000", "0.14007000"], ["83941.59000000", "0.00014000"], ["83941.58000000", "0.08949000"], ["83939.67000000", "0.02324000"], ["83936.68000000", "0.00000000"], ["83934.53000000", "0.19086000"], ["83933.99000000", "0.45000000"], ["83932.46000000", "0.00000000"], ["83932.25000000", "0.00000000"], ["83920.16000000", "0.82492000"], ["83890.58000000", "0.00000000"], ["83768.56000000", "0.00400000"], ["83763.12000000", "0.00000000"], ["83744.87000000", "0.00000000"], ["82849.31000000", "0.00080000"], ["82683.25000000", "0.00100000"], ["75548.00000000", "0.00000000"], ["67153.92000000", "0.00058000"], ["33000.00000000", "2.96666000"]], "a": [["83942.40000000", "4.81335000"], ["83944.06000000", "0.00000000"], ["83944.07000000", "0.00000000"], ["83945.58000000", "0.22385000"], ["83946.45000000", "0.00018000"], ["83947.38000000", "0.00000000"], ["83947.65000000", "0.00074000"], ["83948.00000000", "0.01410000"], ["83949.79000000", "0.58715000"], ["83950.03000000", "0.78655000"], ["83950.13000000", "0.02431000"], ["83952.77000000", "0.00416000"], ["83979.65000000", "0.00000000"], ["84106.05000000", "0.00050000"], ["84106.15000000", "0.00000000"], ["85201.54000000", "0.00100000"]], "record_time": 1742577164.211975, "EXCHANGE": "BINANCE"}
{"e": "depthUpdate", "E": 1742577165014, "s": "BTCUSDT", "U": 64632187885, "u": 64632188024, "b": [["83942.39000000", "0.93272000"], ["83941.80000000", "0.14007000"], ["83941.59000000", "0.00000000"], ["83941.58000000", "0.00000000"], ["83939.67000000", "0.02331000"], ["83937.80000000", "0.06452000"], ["83934.53000000", "0.08627000"], ["83933.99000000", "0.45000000"], ["83932.56000000", "0.00094000"], ["83931.96000000", "0.00091000"], ["83930.00000000", "0.01910000"], ["83928.55000000", "0.21683000"], ["83927.85000000", "0.00000000"], ["83921.56000000", "0.00000000"], ["83920.17000000", "0.00000000"], ["83920.16000000", "1.30637000"], ["83916.53000000", "0.59594000"], ["83905.89000000", "0.00000000"], ["83901.59000000", "0.05000000"], ["83890.58000000", "0.05956000"], ["83864.55000000", "0.00060000"], ["83864.54000000", "0.00000000"], ["83852.40000000", "0.63076000"], ["83845.88000000", "0.00060000"], ["83845.87000000", "0.00000000"], ["83778.57000000", "0.00000000"], ["83778.47000000", "0.01000000"], ["83768.56000000", "0.00000000"], ["83762.57000000", "0.00400000"], ["83501.70000000", "0.00011000"], ["83481.87000000", "0.00000000"], ["82683.25000000", "0.00000000"], ["75548.00000000", "0.00000000"], ["75539.09000000", "0.00016000"], ["67153.92000000", "0.00058000"], ["33000.00000000", "2.96666000"], ["20002.00000000", "0.00000000"], ["20001.00000000", "0.02099000"]], "a": [["83942.40000000", "4.93680000"], ["83944.07000000", "0.00000000"], ["83945.58000000", "0.43023000"], ["83945.86000000", "0.00267000"], ["83946.45000000", "0.00011000"], ["83946.60000000", "0.00500000"], ["83947.65000000", "0.00008000"], ["83947.82000000", "0.03363000"], ["83948.24000000", "0.78657000"], ["83949.79000000", "0.40955000"], ["83950.03000000", "0.00000000"], ["83950.13000000", "0.02413000"], ["83952.77000000", "0.00000000"], ["83975.43000000", "0.00000000"], ["83980.49000000", "0.00000000"], ["83996.35000000", "0.47650000"], ["83997.25000000", "0.00000000"], ["84033.98000000", "0.00008000"], ["84052.46000000", "0.00000000"], ["84058.87000000", "0.05297000"], ["84106.05000000", "0.00050000"], ["84106.90000000", "0.00000000"], ["85201.54000000", "0.00000000"]], "record_time": 1742577165.211474, "EXCHANGE": "BINANCE"}
{"e": "depthUpdate", "E": 1742577166014, "s": "BTCUSDT", "U": 64632188025, "u": 64632188406, "b": [["83942.39000000", "0.38103000"], ["83942.37000000", "0.00007000"], ["83942.36000000", "0.00007000"], ["83942.17000000", "0.00014000"], ["83941.81000000", "0.00000000"], ["83941.80000000", "0.00000000"], ["83941.33000000", "0.00007000"], ["83940.38000000", "0.00000000"], ["83940.37000000", "0.00000000"], ["83940.19000000", "0.00024000"], ["83940.18000000", "0.04013000"], ["83939.97000000", "0.00000000"], ["83939.96000000", "0.00000000"], ["83939.67000000", "0.00000000"], ["83938.83000000", "0.00007000"], ["83938.77000000", "0.00027000"], ["83938.76000000", "0.02392000"], ["83938.75000000", "0.00000000"], ["83938.36000000", "0.00000000"], ["83938.35000000", "0.00000000"], ["83938.30000000", "0.00000000"], ["83938.29000000", "0.00000000"], ["83938.00000000", "0.01423000"], ["83937.99000000", "0.00000000"], ["83937.80000000", "0.00000000"], ["83937.51000000", "0.00000000"], ["83937.50000000", "0.00000000"], ["83937.40000000", "0.00014000"], ["83937.39000000", "0.03399000"], ["83937.35000000", "0.00123000"], ["83937.34000000", "0.00000000"], ["83937.30000000", "0.00000000"], ["83936.04000000", "0.00016000"], ["83936.03000000", "0.00000000"], ["83935.80000000", "0.00014000"], ["83935.79000000", "0.04893000"], ["83935.78000000", "0.00014000"], ["83935.77000000", "0.14000000"], ["83935.24000000", "0.05364000"], ["83935.08000000", "0.00000000"], ["83934.79000000", "0.02214000"], ["83934.57000000", "0.00000000"], ["83934.53000000", "0.00000000"], ["83933.99000000", "0.00000000"], ["83932.56000000", "0.00000000"], ["83932.41000000", "0.00000000"], ["83932.16000000", "0.01500000"], ["83932.04000000", "0.00000000"], ["83931.99000000", "0.00096000"], ["83931.91000000", "0.00000000"], ["83931.66000000", "0.01500000"], ["83931.44000000", "0.00000000"], ["83930.00000000", "0.01410000"], ["83929.32000000", "0.16000000"], ["83929.17000000", "0.00000000"], ["83928.68000000", "0.00000000"], ["83928.55000000", "0.00000000"], ["83928.11000000", "0.23141000"], ["83924.72000000", "0.00000000"], ["83923.52000000", "0.00000000"], ["83921.16000000", "0.10783000"], ["83920.65000000", "0.15719000"], ["83919.06000000", "0.71399000"], ["83918.69000000", "0.35219000"], ["83916.53000000", "0.00000000"], ["83915.40000000", "0.00000000"], ["83914.64000000", "1.14157000"], ["83914.05000000", "0.89344000"], ["83913.05000000", "0.59597000"], ["83912.55000000", "0.00000000"], ["83909.53000000", "0.89344000"], ["83908.56000000", "0.00000000"], ["83905.30000000", "0.00000000"], ["83903.45000000", "0.00000000"], ["83901.59000000", "0.00000000"], ["83900.96000000", "0.05000000"], ["83890.58000000", "0.05956000"], ["83890.19000000", "0.00000000"], ["83881.58000000", "0.21789000"], ["83852.40000000", "0.00000000"], ["83849.64000000", "0.63076000"], ["83809.61000000", "0.04197000"], ["83762.57000000", "0.00000000"], ["83752.62000000", "0.00400000"], ["83102.96000000", "0.00000000"], ["82984.80000000", "0.00000000"], ["82942.19000000", "0.02350000"], ["82683.25000000", "0.00100000"], ["80589.60000000", "0.00000000"], ["80572.80000000", "0.03572000"], ["75548.15000000", "0.00096000"], ["75548.00000000", "0.00000000"], ["75539.09000000", "0.00000000"], ["67153.92000000", "0.00058000"], ["33000.00000000", "2.96666000"], ["30219.26000000", "0.00240000"]], "a": [["83942.40000000", "6.64716000"], ["83942.50000000", "0.02949000"], ["83942.51000000", "0.00000000"], ["83944.06000000", "0.00014000"], ["83944.07000000", "0.01191000"], ["83944.95000000", "0.08360000"], ["83945.30000000", "0.00000000"], ["83945.37000000", "0.04006000"], ["83945.58000000", "0.31429000"], ["83945.59000000", "0.00000000"], ["83945.96000000", "0.78665000"], ["83946.00000000", "0.01416000"], ["83946.41000000", "0.00016000"], ["83946.46000000", "0.00000000"], ["83947.27000000", "0.00039000"], ["83947.28000000", "0.08992000"], ["83948.24000000", "0.00000000"], ["83950.60000000", "0.00058000"], ["83951.22000000", "0.00000000"], ["83952.69000000", "0.00000000"], ["83955.30000000", "0.00000000"], ["83955.67000000", "0.00058000"], ["83957.95000000", "0.00319000"], ["83958.27000000", "0.00028000"], ["83958.56000000", "0.00059000"], ["83960.24000000", "0.26532000"], ["83960.56000000", "0.00000000"], ["83962.46000000", "0.00000000"], ["83965.07000000", "0.59562000"], ["83966.01000000", "0.85790000"], ["83971.48000000", "0.59748000"], ["83975.35000000", "0.89344000"], ["83975.54000000", "0.05000000"], ["83979.28000000", "0.35746000"], ["83981.13000000", "0.54936000"], ["83981.37000000", "0.00000000"], ["83981.83000000", "0.05819000"], ["83982.32000000", "0.00000000"], ["83982.79000000", "0.37750000"], ["83984.39000000", "0.04110000"], ["83984.76000000", "0.00000000"], ["83985.59000000", "0.30067000"], ["83985.60000000", "0.06000000"], ["83985.91000000", "0.00000000"], ["83987.41000000", "0.00000000"], ["83990.84000000", "0.00000000"], ["83996.35000000", "0.00000000"], ["83997.90000000", "0.00000000"], ["84000.34000000", "0.15416000"], ["84000.85000000", "0.00000000"], ["84019.99000000", "0.00019000"], ["84023.31000000", "0.00000000"], ["84038.09000000", "0.47036000"], ["84039.34000000", "0.00060000"], ["84040.46000000", "0.00000000"], ["84043.71000000", "0.00000000"], ["84056.90000000", "0.02438000"], ["84095.22000000", "0.00016000"], ["84099.99000000", "0.00000000"], ["85201.54000000", "0.00100000"], ["150001.00000000", "0.00060000"]], "record_time": 1742577166.212443, "EXCHANGE": "BINANCE"}
{"e": "depthUpdate", "E": 1742577167014, "s": "BTCUSDT", "U": 64632188407, "u": 64632190345, "b": [["83942.39000000", "0.00000000"], ["83942.38000000", "0.00000000"], ["83942.37000000", "0.00000000"], ["83942.36000000", "0.00000000"], ["83942.17000000", "0.00000000"], ["83942.11000000", "0.00000000"], ["83942.10000000", "0.00000000"], ["83942.09000000", "0.00000000"], ["83942.05000000", "0.00000000"], ["83942.04000000", "0.00000000"], ["83942.00000000", "0.00000000"], ["83941.33000000", "0.00000000"], ["83941.28000000", "0.00000000"], ["83940.19000000", "0.00000000"], ["83940.18000000", "0.00000000"], ["83940.00000000", "0.00000000"], ["83938.83000000", "0.00000000"], ["83938.77000000", "0.00000000"], ["83938.76000000", "0.00000000"], ["83938.00000000", "0.00000000"], ["83937.62000000", "0.00000000"], ["83937.40000000", "0.00000000"], ["83937.39000000", "0.00000000"], ["83937.35000000", "0.00000000"], ["83937.28000000", "0.00000000"], ["83937.27000000", "0.00000000"], ["83937.26000000", "0.00000000"], ["83937.25000000", "0.00000000"], ["83937.16000000", "0.00000000"], ["83937.00000000", "0.00000000"], ["83936.51000000", "0.00000000"], ["83936.50000000", "0.00000000"], ["83936.49000000", "0.00000000"], ["83936.47000000", "0.00000000"], ["83936.32000000", "0.00000000"], ["83936.04000000", "0.00000000"], ["83935.80000000", "0.00000000"], ["83935.79000000", "0.00000000"], ["83935.78000000", "0.00000000"], ["83935.77000000", "1.47607000"], ["83935.76000000", "0.00049000"], ["83935.75000000", "0.14644000"], ["83935.49000000", "0.00007000"], ["83935.37000000", "0.00208000"], ["83935.24000000", "0.00000000"], ["83935.18000000", "0.00000000"], ["83934.79000000", "0.00007000"], ["83934.65000000", "0.00014000"], ["83934.63000000", "0.00007000"], ["83934.62000000", "0.00363000"], ["83934.56000000", "0.00000000"], ["83934.55000000", "0.00000000"], ["83934.49000000", "0.00000000"], ["83934.48000000", "0.00000000"], ["83934.11000000", "0.00000000"], ["83934.09000000", "0.00000000"], ["83933.99000000", "0.00000000"], ["83933.98000000", "0.00000000"], ["83933.97000000", "0.00021000"], ["83933.96000000", "0.07249000"], ["83933.81000000", "0.00007000"], ["83933.63000000", "0.00000000"], ["83933.62000000", "0.00000000"], ["83933.38000000", "0.00000000"], ["83933.27000000", "0.06927000"], ["83933.10000000", "0.00000000"], ["83932.80000000", "0.00080000"], ["83932.59000000", "0.00000000"], ["83932.48000000", "0.00007000"], ["83932.47000000", "0.14007000"], ["83932.30000000", "0.00500000"], ["83932.16000000", "0.02365000"], ["83932.14000000", "0.00007000"], ["83932.10000000", "0.00000000"], ["83932.08000000", "0.00000000"], ["83932.00000000", "0.00000000"], ["83931.98000000", "0.00000000"], ["83931.96000000", "0.00000000"], ["83931.92000000", "0.00000000"], ["83931.66000000", "0.00000000"], ["83931.58000000", "0.00000000"], ["83931.01000000", "0.70007000"], ["83931.00000000", "0.02352000"], ["83930.43000000", "0.00000000"], ["83930.34000000", "0.00081000"], ["83930.33000000", "0.00000000"], ["83930.18000000", "0.00000000"], ["83930.16000000", "0.00000000"], ["83930.00000000", "0.01910000"], ["83929.70000000", "0.00000000"], ["83929.32000000", "0.00000000"], ["83929.07000000", "0.00000000"], ["83928.94000000", "0.00000000"], ["83928.93000000", "0.14170000"], ["83928.86000000", "0.01500000"], ["83928.73000000", "0.00000000"], ["83928.49000000", "0.04412000"], ["83928.48000000", "0.04000000"], ["83928.36000000", "0.01500000"], ["83928.11000000", "0.00000000"], ["83927.95000000", "0.00000000"], ["83927.90000000", "0.00000000"], ["83927.85000000", "0.00119000"], ["83927.84000000", "0.00000000"], ["83927.58000000", "0.19750000"], ["83927.57000000", "0.00000000"], ["83927.48000000", "0.00000000"], ["83927.38000000", "0.00000000"], ["83927.37000000", "0.45000000"], ["83927.28000000", "0.05364000"], ["83927.22000000", "0.00029000"], ["83927.07000000", "0.00000000"], ["83927.00000000", "0.00000000"], ["83926.23000000", "0.00000000"], ["83926.14000000", "0.00000000"], ["83925.92000000", "0.00000000"], ["83925.59000000", "0.00897000"], ["83925.30000000", "0.00000000"], ["83924.70000000", "0.00009000"], ["83924.42000000", "0.16000000"], ["83923.62000000", "0.16253000"], ["83923.54000000", "0.04000000"], ["83923.28000000", "0.00000000"], ["83922.70000000", "0.04000000"], ["83922.12000000", "0.00000000"], ["83921.90000000", "0.00000000"], ["83921.86000000", "0.08000000"], ["83921.73000000", "0.00000000"], ["83921.63000000", "0.47650000"], ["83921.60000000", "0.21181000"], ["83921.16000000", "0.00000000"], ["83921.12000000", "0.00092000"], ["83920.97000000", "0.04000000"], ["83920.24000000", "0.00000000"], ["83920.16000000", "0.58603000"], ["83920.02000000", "0.04421000"], ["83919.95000000", "0.00000000"], ["83919.94000000", "0.04000000"], ["83919.93000000", "0.00000000"], ["83919.42000000", "0.00000000"], ["83919.34000000", "0.00000000"], ["83919.33000000", "0.03575000"], ["83919.06000000", "0.00000000"], ["83918.89000000", "0.00000000"], ["83918.69000000", "0.00000000"], ["83918.49000000", "0.04000000"], ["83918.26000000", "0.04000000"], ["83917.66000000", "0.04000000"], ["83917.33000000", "0.00000000"], ["83917.16000000", "0.00000000"], ["83916.79000000", "0.59562000"], ["83916.46000000", "0.00000000"], ["83916.23000000", "0.00120000"], ["83914.64000000", "0.00000000"], ["83914.54000000", "0.00000000"], ["83914.46000000", "0.71399000"], ["83914.45000000", "0.76837000"], ["83914.44000000", "1.38259000"], ["83914.33000000", "0.10783000"], ["83914.29000000", "0.00000000"], ["83914.28000000", "0.00000000"], ["83914.05000000", "0.00000000"], ["83913.84000000", "0.00000000"], ["83913.05000000", "0.00000000"], ["83912.89000000", "0.35737000"], ["83912.60000000", "0.00000000"], ["83911.96000000", "0.05956000"], ["83911.50000000", "0.46114000"], ["83911.33000000", "0.00059000"], ["83910.66000000", "0.59601000"], ["83910.65000000", "0.01610000"], ["83909.97000000", "0.00000000"], ["83909.53000000", "0.00000000"], ["83909.05000000", "0.00000000"], ["83908.50000000", "0.45221000"], ["83907.87000000", "0.00000000"], ["83906.62000000", "0.00000000"], ["83906.61000000", "0.00000000"], ["83906.39000000", "0.89344000"], ["83904.97000000", "0.00120000"], ["83904.94000000", "0.00000000"], ["83904.93000000", "0.00000000"], ["83903.46000000", "0.00000000"], ["83902.90000000", "0.00000000"], ["83901.87000000", "0.89344000"], ["83901.46000000", "0.00000000"], ["83901.09000000", "0.47650000"], ["83900.96000000", "0.00000000"], ["83900.92000000", "0.59314000"], ["83900.90000000", "0.04000000"], ["83900.11000000", "0.00000000"], ["83899.89000000", "0.00000000"], ["83899.19000000", "0.00000000"], ["83899.17000000", "0.00000000"], ["83898.21000000", "0.00358000"], ["83896.51000000", "0.00146000"], ["83895.86000000", "0.04000000"], ["83894.21000000", "0.14140000"], ["83894.09000000", "0.05862000"], ["83894.07000000", "0.04000000"], ["83893.10000000", "0.00000000"], ["83892.45000000", "0.39347000"], ["83892.38000000", "0.00000000"], ["83892.36000000", "0.00000000"], ["83891.68000000", "0.00000000"], ["83891.20000000", "0.24319000"], ["83890.77000000", "0.00000000"], ["83890.58000000", "0.00000000"], ["83890.39000000", "0.03345000"], ["83890.20000000", "0.00000000"], ["83889.68000000", "0.15560000"], ["83888.43000000", "1.01014000"], ["83888.42000000", "0.11918000"], ["83888.14000000", "0.00000000"], ["83888.01000000", "0.05497000"], ["83886.79000000", "0.32879000"], ["83885.90000000", "0.00296000"], ["83885.31000000", "0.05498000"], ["83885.03000000", "0.26687000"], ["83884.65000000", "0.04000000"], ["83884.12000000", "0.04490000"], ["83884.01000000", "0.00000000"], ["83884.00000000", "0.27721000"], ["83883.80000000", "0.11058000"], ["83883.53000000", "0.10594000"], ["83882.67000000", "0.06102000"], ["83882.17000000", "0.05209000"], ["83882.00000000", "0.02384000"], ["83881.58000000", "0.10794000"], ["83881.37000000", "0.99733000"], ["83881.10000000", "0.00000000"], ["83881.09000000", "0.00000000"], ["83880.70000000", "0.04198000"], ["83880.43000000", "0.38899000"], ["83880.11000000", "0.17899000"], ["83879.06000000", "0.00297000"], ["83879.01000000", "0.59562000"], ["83878.68000000", "0.00000000"], ["83877.67000000", "0.00000000"], ["83874.53000000", "0.47682000"], ["83874.06000000", "0.00000000"], ["83874.03000000", "0.17992000"], ["83873.50000000", "0.00283000"], ["83872.56000000", "0.04998000"], ["83872.29000000", "0.10000000"], ["83872.28000000", "0.00000000"], ["83872.00000000", "0.00235000"], ["83869.32000000", "0.87357000"], ["83867.81000000", "0.00000000"], ["83867.39000000", "0.00000000"], ["83867.04000000", "0.00061000"], ["83867.02000000", "0.07576000"], ["83865.60000000", "0.00019000"], ["83864.63000000", "0.00358000"], ["83863.64000000", "0.04000000"], ["83863.31000000", "0.24502000"], ["83862.87000000", "0.00000000"], ["83861.97000000", "0.04000000"], ["83854.46000000", "0.00000000"], ["83853.72000000", "0.00000000"], ["83852.88000000", "0.00000000"], ["83852.04000000", "0.00000000"], ["83849.64000000", "0.00000000"], ["83848.69000000", "0.00000000"], ["83847.86000000", "0.00000000"], ["83847.21000000", "0.00000000"], ["83846.72000000", "0.00000000"], ["83846.71000000", "0.01527000"], ["83841.56000000", "0.00146000"], ["83832.50000000", "0.04765000"], ["83830.13000000", "0.05361000"], ["83829.20000000", "0.14058000"], ["83828.75000000", "0.37536000"], ["83828.01000000", "0.05497000"], ["83823.91000000", "0.05497000"], ["83821.91000000", "0.00000000"], ["83821.50000000", "0.00083000"], ["83821.18000000", "0.05097000"], ["83821.08000000", "0.05497000"], ["83820.02000000", "0.05497000"], ["83819.88000000", "0.05497000"], ["83818.39000000", "0.05097000"], ["83818.35000000", "0.05497000"], ["83817.80000000", "0.05097000"], ["83817.40000000", "0.05497000"], ["83817.13000000", "0.05497000"], ["83816.42000000", "0.05497000"], ["83815.85000000", "0.05297000"], ["83815.84000000", "0.05497000"], ["83815.73000000", "0.05097000"], ["83815.17000000", "0.05097000"], ["83814.70000000", "0.05111000"], ["83814.01000000", "0.10994000"], ["83813.37000000", "0.05497000"], ["83813.29000000", "0.05497000"], ["83812.87000000", "0.05297000"], ["83812.65000000", "0.05497000"], ["83812.60000000", "0.05497000"], ["83811.96000000", "0.05497000"], ["83810.43000000", "0.00000000"], ["83810.19000000", "0.84770000"], ["83809.23000000", "0.05297000"], ["83807.30000000", "0.04997000"], ["83807.07000000", "0.04997000"], ["83806.71000000", "0.04497000"], ["83804.78000000", "0.04197000"], ["83803.67000000", "0.04997000"], ["83803.44000000", "0.00000000"], ["83803.33000000", "0.04997000"], ["83802.26000000", "0.00119000"], ["83801.07000000", "0.04497000"], ["83800.85000000", "0.04497000"], ["83795.45000000", "0.00119000"], ["83794.55000000", "0.00000000"], ["83789.81000000", "0.00305000"], ["83778.47000000", "0.00000000"], ["83775.68000000", "0.01000000"], ["83754.43000000", "0.00000000"], ["83752.62000000", "0.00000000"], ["83750.90000000", "0.00839000"], ["83747.43000000", "0.45000000"], ["83745.29000000", "0.00069000"], ["83745.28000000", "0.00000000"], ["83744.83000000", "0.00000000"], ["83717.02000000", "0.00400000"], ["83711.77000000", "0.00000000"], ["83707.41000000", "0.10872000"], ["83699.03000000", "0.00013000"], ["83699.02000000", "0.05647000"], ["83694.84000000", "0.00013000"], ["83674.27000000", "0.00000000"], ["83500.00000000", "3.41756000"], ["82942.19000000", "0.00000000"], ["82883.63000000", "0.40000000"], ["82875.28000000", "0.00000000"], ["82683.25000000", "0.00000000"], ["80572.80000000", "0.00000000"], ["75542.00000000", "0.00000000"], ["67153.92000000", "0.00000000"], ["67148.62000000", "0.00058000"], ["42000.00000000", "6.84810000"], ["33000.00000000", "2.96666000"], ["30219.26000000", "0.00260000"]], "a": [["83935.78000000", "7.39281000"], ["83935.79000000", "0.00027000"], ["83935.97000000", "0.00201000"], ["83935.99000000", "0.00014000"], ["83936.00000000", "0.01410000"], ["83936.32000000", "0.00000000"], ["83936.33000000", "0.00000000"], ["83936.37000000", "0.00000000"], ["83936.38000000", "0.00000000"], ["83936.39000000", "0.00000000"], ["83936.47000000", "0.00014000"], ["83936.48000000", "0.80230000"], ["83936.49000000", "0.00006000"], ["83936.50000000", "0.08360000"], ["83936.51000000", "0.49006000"], ["83936.52000000", "0.00000000"], ["83937.15000000", "0.00007000"], ["83937.26000000", "0.12066000"], ["83937.27000000", "0.00000000"], ["83937.28000000", "0.32107000"], ["83937.29000000", "0.00000000"], ["83937.36000000", "0.00000000"], ["83937.41000000", "0.00000000"], ["83937.45000000", "0.00000000"], ["83937.50000000", "0.00000000"], ["83937.51000000", "0.00000000"], ["83937.62000000", "0.00000000"], ["83937.63000000", "0.00006000"], ["83937.98000000", "0.00007000"], ["83938.00000000", "0.01410000"], ["83938.15000000", "0.00000000"], ["83938.18000000", "0.00000000"], ["83938.22000000", "0.00000000"], ["83938.24000000", "0.00000000"], ["83938.25000000", "0.00000000"], ["83938.77000000", "0.00000000"], ["83938.78000000", "0.00000000"], ["83939.10000000", "0.00000000"], ["83939.19000000", "0.00000000"], ["83939.21000000", "0.00000000"], ["83939.22000000", "0.00000000"], ["83939.26000000", "0.00000000"], ["83939.39000000", "0.02399000"], ["83939.54000000", "0.15526000"], ["83939.55000000", "0.00000000"], ["83939.89000000", "0.00485000"], ["83940.00000000", "0.01410000"], ["83940.01000000", "0.00000000"], ["83940.35000000", "0.00000000"], ["83940.55000000", "0.00505000"], ["83941.06000000", "0.00000000"], ["83941.09000000", "0.00000000"], ["83941.34000000", "0.00000000"], ["83941.65000000", "0.03000000"], ["83941.70000000", "0.09600000"], ["83941.71000000", "0.00000000"], ["83941.83000000", "0.14597000"], ["83941.93000000", "0.00000000"], ["83941.94000000", "0.00000000"], ["83941.96000000", "0.00000000"], ["83942.00000000", "0.01410000"], ["83942.05000000", "0.60037000"], ["83942.06000000", "0.62899000"], ["83942.10000000", "0.00000000"], ["83942.11000000", "0.00000000"], ["83942.12000000", "0.00000000"], ["83942.17000000", "0.00000000"], ["83942.18000000", "0.00000000"], ["83942.26000000", "0.00000000"], ["83942.27000000", "0.00000000"], ["83942.28000000", "0.00000000"], ["83942.37000000", "0.00000000"], ["83942.38000000", "0.00000000"], ["83942.39000000", "0.00000000"], ["83942.40000000", "0.51726000"], ["83942.41000000", "0.00000000"], ["83942.49000000", "0.00000000"], ["83942.50000000", "0.00000000"], ["83942.53000000", "0.00000000"], ["83942.54000000", "0.06800000"], ["83942.86000000", "0.78662000"], ["83943.14000000", "0.10783000"], ["83943.39000000", "0.14400000"], ["83943.48000000", "0.06400000"], ["83943.71000000", "0.35737000"], ["83943.99000000", "0.00000000"], ["83944.00000000", "0.01410000"], ["83944.06000000", "0.00000000"], ["83944.35000000", "0.00000000"], ["83944.36000000", "0.00000000"], ["83944.52000000", "0.00059000"], ["83944.71000000", "0.00058000"], ["83944.93000000", "0.00000000"], ["83944.94000000", "0.00000000"], ["83944.95000000", "0.08354000"], ["83945.37000000", "0.04000000"], ["83945.39000000", "0.00119000"], ["83945.40000000", "0.00006000"], ["83945.57000000", "0.00000000"], ["83945.58000000", "0.61693000"], ["83945.66000000", "0.08692000"], ["83945.68000000", "0.00009000"], ["83945.86000000", "0.00000000"], ["83945.88000000", "0.00095000"], ["83945.91000000", "0.89344000"], ["83945.95000000", "0.00000000"], ["83945.96000000", "0.00000000"], ["83946.00000000", "0.01410000"], ["83946.03000000", "0.00000000"], ["83946.41000000", "0.00000000"], ["83946.45000000", "0.00000000"], ["83946.59000000", "0.00000000"], ["83946.60000000", "0.00000000"], ["83946.74000000", "0.06000000"], ["83946.81000000", "0.06400000"], ["83947.27000000", "0.00000000"], ["83947.28000000", "0.00000000"], ["83947.58000000", "0.04800000"], ["83947.65000000", "0.00000000"], ["83947.66000000", "0.00000000"], ["83947.68000000", "0.07200000"], ["83947.75000000", "0.05956000"], ["83947.77000000", "0.00000000"], ["83947.87000000", "0.00013000"], ["83948.49000000", "0.05200000"], ["83949.00000000", "0.04000000"], ["83949.10000000", "0.00000000"], ["83949.15000000", "0.71399000"], ["83949.20000000", "0.10000000"], ["83949.39000000", "0.00000000"], ["83949.52000000", "0.00595000"], ["83949.78000000", "0.00058000"], ["83950.00000000", "0.06319000"], ["83950.33000000", "0.89644000"], ["83950.41000000", "0.00000000"], ["83950.60000000", "0.00000000"], ["83950.64000000", "0.00000000"], ["83950.75000000", "0.00000000"], ["83950.92000000", "0.00059000"], ["83951.07000000", "0.00000000"], ["83951.08000000", "0.00000000"], ["83951.16000000", "0.00000000"], ["83951.19000000", "0.00059000"], ["83951.33000000", "0.00319000"], ["83951.38000000", "0.05956000"], ["83951.65000000", "0.00028000"], ["83951.67000000", "0.00000000"], ["83951.77000000", "0.00000000"], ["83951.86000000", "0.01191000"], ["83951.92000000", "0.00059000"], ["83951.94000000", "0.00059000"], ["83952.01000000", "0.59562000"], ["83952.06000000", "0.00059000"], ["83952.63000000", "0.04000000"], ["83953.14000000", "0.00000000"], ["83953.16000000", "0.00119000"], ["83953.29000000", "0.05956000"], ["83953.52000000", "0.00000000"], ["83953.55000000", "0.00000000"], ["83953.81000000", "1.50542000"], ["83954.06000000", "0.45000000"], ["83954.30000000", "0.89344000"], ["83954.42000000", "0.00000000"], ["83954.49000000", "0.89344000"], ["83954.90000000", "0.00000000"], ["83954.98000000", "0.00000000"], ["83955.36000000", "0.00000000"], ["83955.56000000", "0.16000000"], ["83955.64000000", "0.00000000"], ["83955.67000000", "0.00000000"], ["83955.74000000", "0.00000000"], ["83955.85000000", "0.00000000"], ["83956.03000000", "0.00000000"], ["83956.78000000", "0.00000000"], ["83957.59000000", "0.00000000"], ["83957.81000000", "0.00000000"], ["83957.91000000", "0.00000000"], ["83957.95000000", "0.00000000"], ["83958.27000000", "0.00000000"], ["83958.39000000", "0.00000000"], ["83958.42000000", "0.00000000"], ["83958.45000000", "0.47650000"], ["83958.56000000", "0.00000000"], ["83959.10000000", "0.00000000"], ["83959.94000000", "0.00000000"], ["83960.10000000", "0.00000000"], ["83960.14000000", "0.00000000"], ["83960.19000000", "0.00000000"], ["83960.42000000", "0.00000000"], ["83960.76000000", "0.00000000"], ["83961.27000000", "1.35478000"], ["83961.29000000", "0.00000000"], ["83961.66000000", "0.00000000"], ["83961.67000000", "0.00000000"], ["83961.69000000", "0.00059000"], ["83961.76000000", "0.85794000"], ["83963.55000000", "0.06800000"], ["83964.17000000", "0.00000000"], ["83965.06000000", "0.00595000"], ["83965.07000000", "0.00000000"], ["83965.78000000", "0.00000000"], ["83966.00000000", "0.00151000"], ["83966.51000000", "0.00000000"], ["83966.52000000", "0.91931000"], ["83967.37000000", "0.00000000"], ["83967.94000000", "0.00000000"], ["83968.12000000", "0.00000000"], ["83969.43000000", "0.00000000"], ["83970.30000000", "0.00000000"], ["83970.77000000", "0.85785000"], ["83970.78000000", "0.00000000"], ["83971.48000000", "0.59600000"], ["83971.59000000", "0.00000000"], ["83972.05000000", "0.00000000"], ["83973.02000000", "0.35737000"], ["83973.10000000", "0.00000000"], ["83973.92000000", "0.00000000"], ["83974.89000000", "0.26684000"], ["83975.26000000", "1.00803000"], ["83975.54000000", "0.00000000"], ["83975.77000000", "0.00000000"], ["83976.54000000", "0.00000000"], ["83977.40000000", "0.00000000"], ["83977.97000000", "0.00000000"], ["83978.14000000", "0.03533000"], ["83978.27000000", "0.00000000"], ["83979.00000000", "0.00019000"], ["83979.27000000", "0.00308000"], ["83979.28000000", "0.00009000"], ["83980.44000000", "0.12403000"], ["83981.08000000", "0.00823000"], ["83981.11000000", "0.00000000"], ["83982.85000000", "0.00000000"], ["83984.38000000", "0.10194000"], ["83985.59000000", "0.00000000"], ["83985.81000000", "0.00000000"], ["83985.87000000", "0.02382000"], ["83987.81000000", "0.38115000"], ["83988.26000000", "0.00000000"], ["83989.09000000", "0.59562000"], ["83989.64000000", "0.05354000"], ["83991.39000000", "0.00000000"], ["83995.85000000", "0.00000000"], ["84004.47000000", "0.27239000"], ["84004.55000000", "0.71399000"], ["84006.61000000", "0.06000000"], ["84007.74000000", "0.00000000"], ["84012.86000000", "0.00000000"], ["84014.76000000", "0.05200000"], ["84023.99000000", "0.00297000"], ["84031.07000000", "0.00297000"], ["84031.59000000", "0.00000000"], ["84031.86000000", "0.04646000"], ["84031.87000000", "0.00000000"], ["84034.46000000", "0.04822000"], ["84039.30000000", "0.00000000"], ["84039.34000000", "0.00000000"], ["84045.47000000", "0.05497000"], ["84049.88000000", "0.05497000"], ["84051.30000000", "0.05097000"], ["84053.49000000", "0.05497000"], ["84055.01000000", "0.05097000"], ["84058.77000000", "0.05097000"], ["84061.55000000", "0.05097000"], ["84063.43000000", "0.00013000"], ["84067.20000000", "0.00006000"], ["84074.90000000", "0.02501000"], ["84085.85000000", "0.00000000"], ["84106.05000000", "0.01000000"], ["84121.60000000", "0.99764000"], ["84131.68000000", "0.00000000"], ["84172.52000000", "0.00013000"], ["84174.68000000", "0.00000000"], ["84178.87000000", "0.00000000"], ["84229.91000000", "0.00000000"], ["84232.41000000", "0.16518000"], ["84233.22000000", "0.00000000"], ["84238.31000000", "0.00120000"], ["84240.81000000", "0.16518000"], ["84246.69000000", "0.00000000"], ["84248.46000000", "0.03160000"], ["84260.90000000", "0.03576000"], ["84294.00000000", "0.00000000"], ["84317.70000000", "0.00411000"], ["84323.27000000", "0.00000000"], ["84604.48000000", "0.05960000"], ["84604.80000000", "0.00006000"], ["84909.54000000", "0.00000000"], ["84917.96000000", "0.60000000"], ["85201.54000000", "0.00000000"], ["85242.60000000", "0.00000000"], ["150001.00000000", "0.00064000"]], "record_time": 1742577167.213291, "EXCHANGE": "BINANCE"}
{"e": "depthUpdate", "E": 1742577168014, "s": "BTCUSDT", "U": 64632190346, "u": 64632190492, "b": [["83935.77000000", "1.45385000"], ["83935.76000000", "0.00049000"], ["83935.75000000", "0.14630000"], ["83933.00000000", "0.00300000"], ["83932.30000000", "0.00000000"], ["83931.02000000", "0.00000000"], ["83931.01000000", "0.00007000"], ["83930.74000000", "0.05364000"], ["83927.28000000", "0.00000000"], ["83924.08000000", "0.40135000"], ["83923.77000000", "0.18521000"], ["83922.90000000", "0.00300000"], ["83911.50000000", "0.00000000"], ["83910.67000000", "0.96533000"], ["83910.58000000", "0.00300000"], ["83908.80000000", "0.00000000"], ["83887.75000000", "0.00000000"], ["83848.30000000", "0.58338000"], ["83846.87000000", "0.63081000"], ["83775.68000000", "0.01000000"], ["83742.68000000", "0.00000000"], ["83738.55000000", "0.00000000"], ["83737.49000000", "0.00400000"], ["83736.50000000", "0.00000000"], ["83731.41000000", "0.00000000"], ["83717.02000000", "0.00000000"], ["83715.09000000", "0.01865000"], ["83667.66000000", "0.00000000"], ["82942.19000000", "0.02350000"], ["82676.73000000", "0.00100000"], ["75542.00000000", "0.00000000"], ["67148.62000000", "0.00058000"], ["42000.00000000", "6.84710000"], ["33000.00000000", "2.96666000"]], "a": [["83935.78000000", "7.98942000"], ["83936.48000000", "0.36990000"], ["83936.50000000", "0.08374000"], ["83937.25000000", "0.00021000"], ["83941.20000000", "0.00006000"], ["83942.06000000", "0.17899000"], ["83944.18000000", "0.45000000"], ["83944.52000000", "0.00000000"], ["83944.71000000", "0.00000000"], ["83945.37000000", "0.00000000"], ["83947.75000000", "0.00000000"], ["83949.52000000", "0.00000000"], ["83949.78000000", "0.00000000"], ["83949.79000000", "0.86151000"], ["83950.00000000", "0.02745000"], ["83950.01000000", "0.03574000"], ["83950.92000000", "0.00000000"], ["83951.19000000", "0.00000000"], ["83951.33000000", "0.00000000"], ["83951.92000000", "0.00000000"], ["83951.94000000", "0.00000000"], ["83952.01000000", "0.00000000"], ["83952.06000000", "0.00000000"], ["83952.57000000", "0.00300000"], ["83953.24000000", "1.00000000"], ["83958.45000000", "1.07212000"], ["83970.76000000", "1.26947000"], ["83970.85000000", "0.00000000"], ["83970.94000000", "0.05000000"], ["83971.48000000", "0.00000000"], ["83973.02000000", "0.00000000"], ["83973.92000000", "0.00000000"], ["83975.25000000", "0.59597000"], ["83988.09000000", "0.00000000"], ["83988.13000000", "0.00000000"], ["83988.16000000", "0.00000000"], ["83989.09000000", "0.00000000"], ["83989.90000000", "0.59562000"], ["84065.84000000", "0.12000000"], ["84106.05000000", "0.00000000"], ["84106.45000000", "0.01000000"], ["85194.82000000", "0.00100000"], ["85221.30000000", "0.11750000"]], "record_time": 1742577168.211329, "EXCHANGE": "BINANCE"}
{"e": "depthUpdate", "E": 1742584882014, "s": "BTCUSDT", "U": 64637870992, "u": 64637871482, "b": [["84069.36000000", "1.09256000"], ["84069.35000000", "0.12287000"], ["84069.34000000", "0.00020000"], ["84069.30000000", "0.00007000"], ["84069.16000000", "0.00209000"], ["84069.15000000", "0.00021000"], ["84069.14000000", "0.29855000"], ["84068.94000000", "0.00007000"], ["84068.93000000", "0.14666000"], ["84068.66000000", "0.00000000"], ["84068.59000000", "0.00036000"], ["84068.58000000", "0.78552000"], ["84068.50000000", "0.00000000"], ["84068.39000000", "0.00024000"], ["84068.38000000", "0.02979000"], ["84068.16000000", "0.00000000"], ["84068.12000000", "0.00011000"], ["84068.11000000", "0.03380000"], ["84067.82000000", "0.00000000"], ["84067.81000000", "0.00000000"], ["84067.69000000", "0.00798000"], ["84067.61000000", "0.00000000"], ["84067.60000000", "0.00000000"], ["84066.91000000", "0.00000000"], ["84066.90000000", "0.00000000"], ["84066.73000000", "0.00000000"], ["84066.72000000", "0.00000000"], ["84066.62000000", "0.00000000"], ["84066.60000000", "0.00000000"], ["84066.51000000", "0.00000000"], ["84066.20000000", "0.00022000"], ["84066.09000000", "0.00030000"], ["84066.05000000", "0.00000000"], ["84065.88000000", "0.00000000"], ["84065.87000000", "0.14794000"], ["84065.79000000", "0.02539000"], ["84065.42000000", "0.00007000"], ["84065.41000000", "0.00000000"], ["84065.33000000", "0.00000000"], ["84065.32000000", "0.00000000"], ["84065.10000000", "0.00500000"], ["84063.84000000", "0.00000000"], ["84063.83000000", "0.00000000"], ["84060.54000000", "0.05353000"], ["84060.05000000", "0.26414000"], ["84059.35000000", "0.04000000"], ["84058.81000000", "0.16614000"], ["84057.75000000", "0.00000000"], ["84056.50000000", "0.00000000"], ["84054.57000000", "0.00000000"], ["84054.31000000", "0.04000000"], ["84052.92000000", "0.00000000"], ["84052.29000000", "0.99635000"], ["84048.57000000", "0.08354000"], ["84047.85000000", "0.00000000"], ["84047.60000000", "0.01189000"], ["84047.26000000", "0.05818000"], ["84046.74000000", "0.00000000"], ["84044.69000000", "0.85709000"], ["84044.15000000", "0.71185000"], ["84044.13000000", "0.06243000"], ["84043.24000000", "1.38182000"], ["84042.68000000", "0.00000000"], ["84040.55000000", "0.59503000"], ["84035.60000000", "0.53464000"], ["84034.04000000", "0.00000000"], ["84033.20000000", "0.85721000"], ["84029.56000000", "0.00000000"], ["84029.46000000", "0.01300000"], ["84029.10000000", "0.00000000"], ["84027.32000000", "0.00059000"], ["84022.91000000", "0.04241000"], ["84017.37000000", "0.00000000"], ["84012.87000000", "0.00000000"], ["84011.89000000", "0.04628000"], ["84008.72000000", "0.31200000"], ["84005.78000000", "0.04000000"], ["84005.56000000", "0.00000000"], ["83998.62000000", "0.09180000"], ["83998.57000000", "0.00000000"], ["83993.53000000", "0.00000000"], ["83986.81000000", "0.00000000"], ["83983.01000000", "0.00100000"], ["83967.76000000", "0.79793000"], ["83962.24000000", "0.00000000"], ["83960.27000000", "0.63100000"], ["83954.85000000", "0.00083000"], ["83949.60000000", "0.00006000"], ["83932.80000000", "0.05955000"], ["83920.44000000", "0.00000000"], ["83904.73000000", "0.00835000"], ["83885.96000000", "0.00000000"], ["83882.38000000", "0.00400000"], ["83877.03000000", "0.00000000"], ["83876.32000000", "0.00069000"], ["83867.35000000", "0.00000000"], ["83855.50000000", "0.00000000"], ["83823.66000000", "0.00000000"], ["83156.18000000", "0.40000000"], ["82814.93000000", "0.00000000"], ["80680.44000000", "0.03567000"], ["75668.00000000", "0.13247000"], ["75662.00000000", "0.00202000"], ["67255.49000000", "0.00058000"], ["33000.00000000", "2.93827000"], ["30264.97000000", "0.00040000"]], "a": [["84069.37000000", "4.17744000"], ["84069.38000000", "0.00034000"], ["84069.58000000", "0.00007000"], ["84069.83000000", "0.00007000"], ["84069.91000000", "0.00021000"], ["84069.92000000", "0.86971000"], ["84069.93000000", "0.00007000"], ["84069.94000000", "0.00000000"], ["84069.95000000", "0.00006000"], ["84069.96000000", "0.00000000"], ["84069.99000000", "0.45013000"], ["84070.00000000", "0.02267000"], ["84071.04000000", "0.00000000"], ["84071.27000000", "0.00000000"], ["84071.40000000", "0.00006000"], ["84071.67000000", "0.22948000"], ["84072.00000000", "0.02260000"], ["84072.31000000", "0.00000000"], ["84072.86000000", "0.00000000"], ["84072.94000000", "0.02228000"], ["84074.87000000", "0.14160000"], ["84075.24000000", "0.00000000"], ["84076.08000000", "0.05913000"], ["84076.09000000", "0.05528000"], ["84076.37000000", "0.00000000"], ["84077.78000000", "0.00300000"], ["84082.19000000", "0.00000000"], ["84082.20000000", "0.00532000"], ["84083.20000000", "0.89655000"], ["84083.62000000", "0.00000000"], ["84085.43000000", "1.00000000"], ["84086.78000000", "0.05943000"], ["84089.10000000", "0.06000000"], ["84090.04000000", "0.00000000"], ["84091.29000000", "1.28024000"], ["84092.07000000", "0.59437000"], ["84092.30000000", "0.00000000"], ["84092.86000000", "0.00000000"], ["84093.97000000", "0.00000000"], ["84094.59000000", "0.00088000"], ["84095.57000000", "0.00000000"], ["84099.42000000", "0.01489000"], ["84101.09000000", "0.00580000"], ["84101.11000000", "0.04400000"], ["84102.04000000", "0.00100000"], ["84103.83000000", "0.00382000"], ["84104.11000000", "0.00000000"], ["84106.29000000", "0.00708000"], ["84106.40000000", "0.59502000"], ["84106.61000000", "0.00000000"], ["84106.68000000", "0.35662000"], ["84107.36000000", "0.01166000"], ["84107.99000000", "0.01452000"], ["84110.76000000", "0.20212000"], ["84111.40000000", "0.00059000"], ["84111.83000000", "0.00308000"], ["84112.29000000", "0.00000000"], ["84113.92000000", "0.00000000"], ["84115.24000000", "0.00000000"], ["84115.95000000", "0.55789000"], ["84118.12000000", "0.00000000"], ["84119.49000000", "0.01851000"], ["84119.93000000", "0.01418000"], ["84120.49000000", "0.00793000"], ["84121.65000000", "0.00000000"], ["84123.31000000", "0.01047000"], ["84124.75000000", "0.03971000"], ["84125.26000000", "0.00000000"], ["84135.52000000", "0.01057000"], ["84141.32000000", "0.75875000"], ["84145.16000000", "0.01057000"], ["84155.40000000", "0.00000000"], ["84165.42000000", "0.00867000"], ["84165.81000000", "0.00847000"], ["84167.49000000", "0.04639000"], ["84167.81000000", "0.00059000"], ["84168.10000000", "0.00000000"], ["84169.63000000", "0.04638000"], ["84169.98000000", "0.00000000"], ["84172.76000000", "0.00000000"], ["84173.16000000", "0.00000000"], ["84187.07000000", "0.00000000"], ["84190.44000000", "0.00000000"], ["84191.23000000", "0.01820000"], ["84194.51000000", "0.00000000"], ["84199.39000000", "0.02190000"], ["84200.23000000", "0.12000000"], ["84203.15000000", "0.00000000"], ["84218.47000000", "0.00000000"], ["84219.89000000", "0.00875000"], ["84220.25000000", "0.01166000"], ["84236.63000000", "0.00433000"], ["84240.91000000", "0.00000000"], ["84242.25000000", "0.01057000"], ["84247.80000000", "0.01000000"], ["84248.10000000", "0.00000000"], ["84248.90000000", "0.00000000"], ["84249.00000000", "0.00000000"], ["84253.97000000", "0.00000000"], ["84254.55000000", "0.99677000"], ["84279.12000000", "0.00000000"], ["84313.99000000", "0.00000000"], ["84316.97000000", "0.00000000"], ["85196.70000000", "0.60000000"], ["85330.42000000", "0.00100000"]], "record_time": 1742584882.134201, "EXCHANGE": "BINANCE"}
{"e": "depthUpdate", "E": 1742584883014, "s": "BTCUSDT", "U": 64637871483, "u": 64637871636, "b": [["84069.36000000", "0.98885000"], ["84069.35000000", "0.12287000"], ["84069.30000000", "0.00007000"], ["84069.28000000", "0.01683000"], ["84069.15000000", "0.00007000"], ["84069.14000000", "0.00007000"], ["84068.94000000", "0.00014000"], ["84068.59000000", "0.00050000"], ["84068.38000000", "0.02979000"], ["84068.13000000", "0.28963000"], ["84067.69000000", "0.00000000"], ["84067.05000000", "0.00000000"], ["84067.00000000", "0.00000000"], ["84065.88000000", "0.00019000"], ["84046.20000000", "0.02436000"], ["84044.16000000", "1.37998000"], ["84040.55000000", "0.00000000"], ["84037.09000000", "0.59505000"], ["84020.37000000", "0.05000000"], ["84019.71000000", "0.00000000"], ["84019.36000000", "0.00000000"], ["84008.10000000", "0.09642000"], ["84006.55000000", "0.05000000"], ["84002.55000000", "0.40208000"], ["83979.90000000", "0.00804000"], ["83932.80000000", "0.00006000"], ["83915.99000000", "0.05950000"], ["82808.31000000", "0.00100000"], ["75662.00000000", "0.00202000"], ["67255.49000000", "0.00058000"], ["33000.00000000", "2.93827000"], ["30264.97000000", "0.00100000"]], "a": [["84069.37000000", "3.82086000"], ["84070.00000000", "0.02267000"], ["84070.11000000", "0.00000000"], ["84071.04000000", "0.00000000"], ["84071.27000000", "0.00007000"], ["84074.34000000", "0.00000000"], ["84074.86000000", "0.12268000"], ["84075.60000000", "0.02340000"], ["84076.08000000", "0.00000000"], ["84076.09000000", "0.04606000"], ["84083.67000000", "0.00000000"], ["84084.36000000", "0.00000000"], ["84089.61000000", "0.00922000"], ["84092.07000000", "0.00000000"], ["84095.85000000", "0.05000000"], ["84096.60000000", "0.00006000"], ["84098.04000000", "0.01012000"], ["84100.37000000", "0.02378000"], ["84100.98000000", "0.00000000"], ["84103.53000000", "0.01861000"], ["84104.26000000", "1.42641000"], ["84111.39000000", "0.00308000"], ["84111.83000000", "0.00000000"], ["84115.51000000", "0.01560000"], ["84122.66000000", "0.00000000"], ["84122.69000000", "0.00000000"], ["84124.76000000", "0.00000000"], ["84126.41000000", "0.00000000"], ["84132.39000000", "0.00700000"], ["84143.75000000", "0.00000000"], ["84161.38000000", "0.18941000"], ["84164.31000000", "0.00000000"], ["84173.69000000", "0.02503000"], ["84191.01000000", "0.00000000"], ["84195.39000000", "0.01012000"], ["84199.28000000", "0.00000000"], ["84206.41000000", "0.00000000"], ["84229.45000000", "0.02463000"], ["84232.12000000", "0.00000000"], ["84236.31000000", "0.00000000"], ["84237.97000000", "0.02546000"], ["84271.27000000", "0.00000000"], ["84705.60000000", "0.06068000"], ["85330.42000000", "0.00000000"]], "record_time": 1742584883.127245, "EXCHANGE": "BINANCE"}
{"e": "depthUpdate", "E": 1742584884014, "s": "BTCUSDT", "U": 64637871637, "u": 64637871751, "b": [["84069.36000000", "0.98633000"], ["84067.69000000", "0.00000000"], ["84065.10000000", "0.00500000"], ["84063.24000000", "0.00008000"], ["84055.02000000", "0.03569000"], ["84047.28000000", "0.00760000"], ["84043.48000000", "0.00000000"], ["84039.11000000", "0.76040000"], ["84000.62000000", "0.23553000"], ["83940.91000000", "0.12000000"], ["83887.79000000", "0.00000000"], ["83882.38000000", "0.00000000"], ["83880.77000000", "0.00400000"], ["82808.31000000", "0.00000000"], ["82600.01000000", "0.00017000"], ["75662.00000000", "0.00202000"], ["67255.49000000", "0.00058000"], ["42000.00000000", "6.84810000"], ["33000.00000000", "2.93887000"], ["30264.97000000", "0.00120000"]], "a": [["84069.37000000", "5.11489000"], ["84069.92000000", "0.57811000"], ["84070.00000000", "0.02267000"], ["84070.76000000", "0.03364000"], ["84071.04000000", "0.00155000"], ["84071.27000000", "0.00007000"], ["84072.51000000", "0.17899000"], ["84072.74000000", "0.00000000"], ["84074.34000000", "0.02362000"], ["84074.86000000", "0.21857000"], ["84077.28000000", "0.35662000"], ["84083.20000000", "0.89655000"], ["84092.02000000", "0.00000000"], ["84092.07000000", "1.06986000"], ["84095.85000000", "0.00000000"], ["84097.68000000", "0.05000000"], ["84106.68000000", "0.00000000"], ["84107.44000000", "0.44165000"], ["84121.63000000", "0.00000000"], ["84121.71000000", "0.00000000"], ["84123.33000000", "0.00000000"], ["84139.07000000", "0.04497000"], ["84140.34000000", "0.00000000"], ["84149.97000000", "0.00373000"], ["84158.83000000", "0.54343000"], ["84159.39000000", "1.19224000"], ["84181.88000000", "0.02420000"], ["84189.76000000", "0.18321000"], ["84213.79000000", "0.00000000"], ["84216.02000000", "0.00957000"], ["84223.13000000", "0.00000000"], ["84230.18000000", "0.00000000"], ["84239.07000000", "0.00016000"], ["84239.11000000", "0.00119000"], ["84241.16000000", "0.00000000"], ["84250.24000000", "0.00000000"], ["84254.56000000", "0.00119000"], ["84265.79000000", "0.00000000"], ["84279.84000000", "0.00000000"], ["84304.88000000", "0.00000000"], ["84400.16000000", "0.00402000"], ["84447.14000000", "0.00000000"], ["85330.41000000", "0.00000000"], ["85330.42000000", "0.00100000"]], "record_time": 1742584884.127606, "EXCHANGE": "BINANCE"}
{"e": "depthUpdate", "E": 1742584885014, "s": "BTCUSDT", "U": 64637871752, "u": 64637872009, "b": [["84069.36000000", "1.73047000"], ["84069.35000000", "0.12287000"], ["84069.28000000", "0.00007000"], ["84068.38000000", "0.02986000"], ["84068.13000000", "0.00000000"], ["84067.69000000", "0.01024000"], ["84065.07000000", "0.03516000"], ["84064.00000000", "0.02270000"], ["84058.80000000", "0.00000000"], ["84054.85000000", "0.39645000"], ["84052.66000000", "0.85701000"], ["84052.29000000", "1.23285000"], ["84049.41000000", "0.05849000"], ["84048.74000000", "0.85705000"], ["84047.96000000", "0.00091000"], ["84047.26000000", "0.00000000"], ["84046.13000000", "0.00000000"], ["84044.76000000", "0.59501000"], ["84044.75000000", "0.20167000"], ["84039.11000000", "0.39912000"], ["84038.18000000", "0.00000000"], ["84037.09000000", "0.00000000"], ["84035.60000000", "0.27748000"], ["84033.20000000", "0.00000000"], ["84020.37000000", "0.00000000"], ["84010.92000000", "0.00000000"], ["84010.63000000", "0.00339000"], ["83996.44000000", "0.15651000"], ["83980.35000000", "0.08326000"], ["83980.23000000", "0.00000000"], ["83980.00000000", "0.00235000"], ["83914.90000000", "0.00835000"], ["83905.16000000", "0.00400000"], ["83904.73000000", "0.00000000"], ["83893.68000000", "0.00000000"], ["83886.69000000", "0.00000000"], ["83880.77000000", "0.00000000"], ["83228.66000000", "0.00000000"], ["82808.31000000", "0.00100000"], ["75662.00000000", "0.00202000"], ["67255.49000000", "0.00058000"], ["60000.00000000", "73.01913000"], ["42000.00000000", "6.84710000"], ["33000.00000000", "2.93827000"], ["30264.97000000", "0.00160000"], ["20002.00000000", "0.00000000"], ["20001.00000000", "0.02099000"]], "a": [["84069.37000000", "2.73343000"], ["84069.92000000", "0.18520000"], ["84069.93000000", "0.00007000"], ["84069.95000000", "0.00000000"], ["84069.98000000", "0.00000000"], ["84069.99000000", "0.00006000"], ["84070.00000000", "0.02267000"], ["84070.29000000", "0.00014000"], ["84070.30000000", "0.11027000"], ["84070.44000000", "0.00000000"], ["84070.45000000", "0.10733000"], ["84070.76000000", "0.00000000"], ["84071.00000000", "0.00031000"], ["84071.04000000", "0.00000000"], ["84071.65000000", "0.00000000"], ["84071.66000000", "0.14000000"], ["84071.67000000", "0.00000000"], ["84072.00000000", "0.02260000"], ["84073.33000000", "0.00000000"], ["84074.34000000", "0.00000000"], ["84074.86000000", "0.41522000"], ["84075.07000000", "0.78538000"], ["84075.20000000", "0.00000000"], ["84076.09000000", "0.04159000"], ["84076.86000000", "0.00000000"], ["84076.94000000", "0.00000000"], ["84081.08000000", "0.00010000"], ["84086.78000000", "0.00000000"], ["84092.07000000", "0.47549000"], ["84092.64000000", "0.05943000"], ["84092.98000000", "0.00000000"], ["84093.52000000", "0.00000000"], ["84095.60000000", "0.85657000"], ["84107.45000000", "1.21307000"], ["84108.29000000", "0.00000000"], ["84111.01000000", "0.00308000"], ["84111.39000000", "0.00000000"], ["84121.87000000", "0.49396000"], ["84121.92000000", "0.59437000"], ["84123.06000000", "0.47549000"], ["84124.23000000", "0.00000000"], ["84131.24000000", "0.00000000"], ["84144.55000000", "0.02582000"], ["84147.76000000", "0.00000000"], ["84148.87000000", "0.01492000"], ["84152.30000000", "0.00000000"], ["84157.34000000", "0.02477000"], ["84182.49000000", "0.00941000"], ["84193.88000000", "0.00000000"], ["84194.23000000", "0.02287000"], ["84194.96000000", "0.05097000"], ["84204.04000000", "0.01010000"], ["84208.27000000", "0.00000000"], ["84211.39000000", "0.00941000"], ["84215.52000000", "0.00000000"], ["84219.02000000", "0.00000000"], ["84220.94000000", "0.00904000"], ["84223.64000000", "0.00000000"], ["84223.93000000", "0.00500000"], ["84232.77000000", "0.01033000"], ["84236.47000000", "0.00000000"], ["84238.14000000", "0.01492000"], ["84257.71000000", "0.00000000"], ["84265.71000000", "0.00000000"], ["84273.77000000", "0.00000000"], ["84279.69000000", "0.00000000"], ["85330.42000000", "0.00000000"]], "record_time": 1742584885.127313, "EXCHANGE": "BINANCE"}
{"e": "depthUpdate", "E": 1742584886014, "s": "BTCUSDT", "U": 64637872010, "u": 64637872236, "b": [["84069.36000000", "1.28263000"], ["84069.28000000", "0.00007000"], ["84069.21000000", "0.00782000"], ["84069.15000000", "0.00007000"], ["84069.14000000", "0.00000000"], ["84069.06000000", "0.00008000"], ["84068.93000000", "0.14666000"], ["84068.60000000", "0.00000000"], ["84068.59000000", "0.00050000"], ["84068.38000000", "0.02986000"], ["84065.10000000", "0.00000000"], ["84065.07000000", "0.00000000"], ["84044.76000000", "0.00000000"], ["84043.24000000", "0.00000000"], ["84041.31000000", "0.59501000"], ["84026.66000000", "0.63111000"], ["84019.56000000", "0.05000000"], ["83976.87000000", "0.63105000"], ["83960.27000000", "0.00000000"], ["83941.51000000", "0.12000000"], ["83905.16000000", "0.00000000"], ["83896.95000000", "0.00400000"], ["82808.31000000", "0.00000000"], ["80697.27000000", "0.03567000"], ["80680.44000000", "0.00000000"], ["75662.00000000", "0.00202000"], ["67255.49000000", "0.00058000"], ["60000.00000000", "73.01903000"], ["33000.00000000", "2.93827000"]], "a": [["84069.37000000", "2.70911000"], ["84069.77000000", "0.00209000"], ["84069.83000000", "0.00021000"], ["84069.84000000", "0.13016000"], ["84069.92000000", "0.33740000"], ["84069.93000000", "0.00000000"], ["84069.99000000", "0.00006000"], ["84070.00000000", "0.02267000"], ["84070.29000000", "0.00000000"], ["84070.30000000", "0.00000000"], ["84070.45000000", "0.00000000"], ["84071.66000000", "0.14007000"], ["84072.00000000", "0.02260000"], ["84073.12000000", "0.78540000"], ["84074.86000000", "0.20693000"], ["84075.07000000", "0.00000000"], ["84076.09000000", "0.04606000"], ["84082.12000000", "1.14505000"], ["84083.20000000", "0.89655000"], ["84084.65000000", "0.00000000"], ["84085.54000000", "0.59437000"], ["84086.78000000", "0.05943000"], ["84089.01000000", "0.00000000"], ["84092.64000000", "0.00000000"], ["84092.98000000", "0.00000000"], ["84092.99000000", "0.03569000"], ["84095.26000000", "0.68778000"], ["84097.68000000", "0.00000000"], ["84099.27000000", "0.02170000"], ["84100.48000000", "0.05000000"], ["84113.78000000", "0.37576000"], ["84116.18000000", "0.00932000"], ["84119.56000000", "0.01807000"], ["84121.67000000", "0.00000000"], ["84121.92000000", "0.00000000"], ["84122.79000000", "0.00000000"], ["84123.37000000", "0.59437000"], ["84124.08000000", "0.01818000"], ["84137.68000000", "0.00000000"], ["84150.57000000", "0.00000000"], ["84153.24000000", "0.01562000"], ["84158.83000000", "0.19926000"], ["84159.39000000", "0.00000000"], ["84162.13000000", "0.00000000"], ["84168.73000000", "0.04757000"], ["84169.50000000", "0.00932000"], ["84186.04000000", "0.02346000"], ["84198.68000000", "0.01090000"], ["84210.71000000", "0.00000000"], ["84215.70000000", "0.01818000"], ["84216.35000000", "0.01194000"], ["84220.65000000", "0.02643000"], ["84237.30000000", "0.00000000"], ["84238.43000000", "0.02162000"], ["84246.67000000", "0.02342000"], ["84247.80000000", "0.01000000"], ["84288.51000000", "0.00000000"], ["85330.42000000", "0.00100000"]], "record_time": 1742584886.127601, "EXCHANGE": "BINANCE"}
{"e": "depthUpdate", "E": 1742584887014, "s": "BTCUSDT", "U": 64637872237, "u": 64637872442, "b": [["84069.36000000", "0.15856000"], ["84069.35000000", "0.00042000"], ["84069.28000000", "0.00007000"], ["84069.22000000", "0.00007000"], ["84069.21000000", "0.00007000"], ["84069.16000000", "0.00209000"], ["84069.15000000", "0.00000000"], ["84068.94000000", "0.00021000"], ["84068.59000000", "0.00057000"], ["84068.39000000", "0.00015000"], ["84068.38000000", "0.02986000"], ["84068.12000000", "0.00000000"], ["84068.11000000", "0.03387000"], ["84067.69000000", "0.00000000"], ["84067.28000000", "0.07545000"], ["84066.50000000", "0.00000000"], ["84066.06000000", "0.32594000"], ["84065.84000000", "0.02208000"], ["84056.40000000", "0.00000000"], ["84055.02000000", "0.00000000"], ["84054.80000000", "0.00000000"], ["84051.18000000", "0.03569000"], ["84042.02000000", "1.31732000"], ["84041.31000000", "0.00000000"], ["84037.95000000", "0.00000000"], ["84035.60000000", "0.42657000"], ["84034.36000000", "0.59506000"], ["83976.87000000", "0.00000000"], ["83896.95000000", "0.00000000"], ["83884.24000000", "0.00400000"], ["83156.18000000", "0.00000000"], ["82808.31000000", "0.00100000"], ["80697.27000000", "0.00000000"], ["75662.00000000", "0.00202000"], ["67255.49000000", "0.00058000"], ["33000.00000000", "2.93827000"], ["30264.97000000", "0.00200000"]], "a": [["84069.37000000", "4.30496000"], ["84070.00000000", "0.02267000"], ["84071.04000000", "0.01196000"], ["84071.37000000", "0.08992000"], ["84071.66000000", "0.14000000"], ["84073.11000000", "0.00020000"], ["84074.34000000", "0.02390000"], ["84074.87000000", "0.00000000"], ["84080.81000000", "0.00896000"], ["84081.42000000", "0.01930000"], ["84082.16000000", "0.08992000"], ["84082.20000000", "0.00532000"], ["84083.08000000", "1.33318000"], ["84083.20000000", "0.89655000"], ["84085.54000000", "0.00000000"], ["84091.95000000", "0.85661000"], ["84092.07000000", "1.06986000"], ["84092.30000000", "0.00000000"], ["84092.99000000", "0.00000000"], ["84094.42000000", "0.05000000"], ["84096.38000000", "0.03569000"], ["84098.92000000", "0.59524000"], ["84100.48000000", "0.00000000"], ["84106.40000000", "0.00000000"], ["84107.44000000", "0.00151000"], ["84107.45000000", "0.35662000"], ["84121.87000000", "0.75456000"], ["84121.97000000", "0.00000000"], ["84123.37000000", "0.00000000"], ["84127.07000000", "0.01017000"], ["84127.17000000", "0.00988000"], ["84132.26000000", "0.00000000"], ["84139.92000000", "0.00000000"], ["84143.97000000", "0.00000000"], ["84165.02000000", "0.00000000"], ["84177.66000000", "0.00000000"], ["84179.48000000", "0.00896000"], ["84183.62000000", "0.00000000"], ["84186.95000000", "0.00000000"], ["84190.89000000", "0.00744000"], ["84190.97000000", "0.00000000"], ["84200.12000000", "0.00000000"], ["84208.67000000", "0.00000000"], ["84228.32000000", "0.01832000"], ["84233.37000000", "0.00000000"], ["84240.75000000", "0.01396000"], ["84245.26000000", "0.01930000"], ["84247.80000000", "0.00000000"], ["84248.10000000", "0.01000000"], ["84250.98000000", "0.00000000"], ["84262.16000000", "0.00000000"], ["84267.44000000", "0.00000000"], ["84267.54000000", "0.00000000"], ["84270.49000000", "0.00000000"], ["84279.21000000", "0.00000000"], ["84291.42000000", "0.00000000"], ["84475.52000000", "0.00000000"], ["85196.70000000", "0.00000000"], ["85330.42000000", "0.00000000"]], "record_time": 1742584887.135613, "EXCHANGE": "BINANCE"}
{"e": "depthUpdate", "E": 1742584888014, "s": "BTCUSDT", "U": 64637872443, "u": 64637872776, "b": [["84069.36000000", "2.30339000"], ["84069.35000000", "0.00041000"], ["84068.94000000", "0.00014000"], ["84068.59000000", "0.00050000"], ["84068.38000000", "0.02986000"], ["84068.15000000", "0.04286000"], ["84068.11000000", "0.03380000"], ["84067.73000000", "0.00000000"], ["84067.69000000", "0.01189000"], ["84067.28000000", "0.14889000"], ["84066.60000000", "0.00300000"], ["84066.06000000", "0.00000000"], ["84065.84000000", "0.00000000"], ["84064.01000000", "0.03498000"], ["84060.05000000", "0.52198000"], ["84056.89000000", "0.00000000"], ["84056.50000000", "0.00000000"], ["84054.85000000", "0.39645000"], ["84054.74000000", "0.00000000"], ["84052.83000000", "0.00000000"], ["84052.29000000", "1.12121000"], ["84050.73000000", "0.00091000"], ["84047.96000000", "0.00000000"], ["84045.59000000", "0.00000000"], ["84043.88000000", "0.85710000"], ["84041.31000000", "0.59502000"], ["84040.54000000", "0.00000000"], ["84035.60000000", "0.00000000"], ["84034.87000000", "0.00000000"], ["84034.38000000", "0.00092000"], ["84034.36000000", "0.00000000"], ["84029.46000000", "0.00000000"], ["84028.30000000", "0.07362000"], ["84025.30000000", "0.04628000"], ["84019.56000000", "0.00000000"], ["84011.89000000", "0.00000000"], ["84011.16000000", "0.00000000"], ["84011.15000000", "0.00000000"], ["84008.37000000", "0.00000000"], ["84006.55000000", "0.00000000"], ["83960.69000000", "0.01862000"], ["83914.85000000", "0.00400000"], ["83897.38000000", "0.00000000"], ["83884.24000000", "0.00000000"], ["83147.81000000", "0.40000000"], ["82808.31000000", "0.00000000"], ["80680.44000000", "0.03567000"], ["75662.00000000", "0.00202000"], ["67255.49000000", "0.00058000"], ["33000.00000000", "2.93827000"], ["30264.97000000", "0.00220000"]], "a": [["84069.37000000", "2.38729000"], ["84069.38000000", "0.00049000"], ["84069.39000000", "0.12493000"], ["84069.40000000", "0.00007000"], ["84069.58000000", "0.00007000"], ["84069.83000000", "0.00007000"], ["84069.84000000", "0.00007000"], ["84069.91000000", "0.00014000"], ["84069.92000000", "0.11622000"], ["84070.00000000", "0.02267000"], ["84071.04000000", "0.00000000"], ["84071.37000000", "0.00000000"], ["84071.66000000", "0.14007000"], ["84072.00000000", "0.02260000"], ["84073.11000000", "0.00000000"], ["84073.12000000", "0.00000000"], ["84074.34000000", "0.00000000"], ["84074.56000000", "0.16344000"], ["84074.86000000", "0.20693000"], ["84076.09000000", "0.12366000"], ["84077.10000000", "0.78537000"], ["84077.74000000", "0.00000000"], ["84077.77000000", "0.00000000"], ["84077.96000000", "0.14160000"], ["84078.28000000", "0.55312000"], ["84078.90000000", "0.00000000"], ["84081.06000000", "0.06400000"], ["84082.16000000", "0.00000000"], ["84082.20000000", "0.00532000"], ["84083.20000000", "0.89655000"], ["84085.27000000", "0.05600000"], ["84085.28000000", "0.00000000"], ["84085.33000000", "0.08000000"], ["84086.78000000", "0.00000000"], ["84089.55000000", "0.00000000"], ["84089.61000000", "0.00000000"], ["84090.38000000", "0.01862000"], ["84091.95000000", "0.00000000"], ["84092.30000000", "0.00000000"], ["84092.64000000", "0.05943000"], ["84094.07000000", "0.00000000"], ["84094.42000000", "0.00000000"], ["84094.73000000", "0.00000000"], ["84095.26000000", "0.46359000"], ["84095.60000000", "0.00000000"], ["84096.38000000", "0.03569000"], ["84098.42000000", "0.37690000"], ["84098.92000000", "0.00019000"], ["84102.98000000", "0.00922000"], ["84103.52000000", "0.00000000"], ["84107.72000000", "0.56545000"], ["84107.73000000", "0.85645000"], ["84108.70000000", "0.00000000"], ["84108.86000000", "0.85644000"], ["84109.46000000", "0.59500000"], ["84122.81000000", "0.00008000"], ["84123.01000000", "0.59437000"], ["84131.77000000", "0.00000000"], ["84144.05000000", "0.00000000"], ["84146.74000000", "0.00019000"], ["84160.82000000", "0.00000000"], ["84162.11000000", "0.00779000"], ["84170.71000000", "0.01155000"], ["84173.38000000", "0.00017000"], ["84174.09000000", "0.00794000"], ["84174.26000000", "0.00000000"], ["84183.34000000", "0.00000000"], ["84186.06000000", "0.01967000"], ["84203.17000000", "0.00000000"], ["84207.77000000", "0.00386000"], ["84211.46000000", "0.02058000"], ["84229.80000000", "0.00000000"], ["84232.24000000", "0.04497000"], ["84239.07000000", "0.00000000"], ["84240.74000000", "0.00016000"], ["84253.38000000", "0.00000000"], ["84261.82000000", "0.00000000"], ["84262.89000000", "0.00000000"], ["84266.64000000", "0.00000000"], ["84270.60000000", "0.00000000"], ["84276.18000000", "0.00000000"], ["84280.56000000", "0.00000000"], ["84288.00000000", "0.00256000"], ["84293.30000000", "0.00000000"], ["85188.26000000", "0.60000000"], ["85330.42000000", "0.00100000"], ["150001.00000000", "0.00128000"]], "record_time": 1742584888.126638, "EXCHANGE": "BINANCE"}
{"e": "depthUpdate", "E": 1742584889014, "s": "BTCUSDT", "U": 64637872777, "u": 64637873090, "b": [["84069.36000000", "1.90465000"], ["84069.30000000", "0.00021000"], ["84069.29000000", "0.11655000"], ["84069.16000000", "0.00202000"], ["84069.06000000", "0.00008000"], ["84068.38000000", "0.02986000"], ["84068.15000000", "0.04279000"], ["84067.28000000", "0.00000000"], ["84066.60000000", "0.00000000"], ["84065.10000000", "0.00500000"], ["84060.05000000", "0.26414000"], ["84042.80000000", "1.36589000"], ["84042.02000000", "0.00000000"], ["84034.36000000", "0.27070000"], ["84029.56000000", "0.00000000"], ["84025.30000000", "0.00000000"], ["84020.36000000", "0.05000000"], ["84015.33000000", "0.04628000"], ["84006.65000000", "0.00000000"], ["83976.87000000", "0.63105000"], ["83914.85000000", "0.00000000"], ["83906.96000000", "0.00400000"], ["82808.31000000", "0.00100000"], ["81799.50000000", "0.00043000"], ["75662.00000000", "0.00202000"], ["67255.49000000", "0.00058000"], ["33000.00000000", "2.93827000"]], "a": [["84069.37000000", "2.38584000"], ["84072.20000000", "0.16344000"], ["84072.57000000", "0.00757000"], ["84073.96000000", "0.00000000"], ["84074.56000000", "0.00000000"], ["84074.86000000", "0.39747000"], ["84076.09000000", "0.12816000"], ["84078.28000000", "0.36547000"], ["84081.32000000", "0.02162000"], ["84082.94000000", "1.33591000"], ["84083.08000000", "0.00000000"], ["84089.49000000", "0.00000000"], ["84089.58000000", "0.00446000"], ["84093.70000000", "0.00772000"], ["84095.62000000", "0.85657000"], ["84096.38000000", "0.00000000"], ["84099.31000000", "0.05000000"], ["84102.84000000", "0.00000000"], ["84105.74000000", "0.59502000"], ["84107.44000000", "0.52502000"], ["84107.72000000", "0.00000000"], ["84108.86000000", "0.00000000"], ["84109.46000000", "0.00000000"], ["84114.16000000", "0.02650000"], ["84124.28000000", "0.00939000"], ["84127.98000000", "0.08135000"], ["84132.02000000", "0.00000000"], ["84136.16000000", "0.00000000"], ["84136.24000000", "0.01664000"], ["84139.86000000", "0.00849000"], ["84152.92000000", "0.00000000"], ["84153.83000000", "0.00714000"], ["84157.96000000", "0.00772000"], ["84168.71000000", "0.05794000"], ["84169.74000000", "0.06400000"], ["84173.08000000", "0.00779000"], ["84175.18000000", "0.00000000"], ["84182.53000000", "0.00000000"], ["84182.64000000", "0.02608000"], ["84183.13000000", "0.00000000"], ["84183.61000000", "0.04997000"], ["84185.86000000", "0.04997000"], ["84187.62000000", "0.04997000"], ["84189.37000000", "0.04997000"], ["84195.00000000", "0.04997000"], ["84195.84000000", "0.00000000"], ["84198.40000000", "0.04997000"], ["84198.84000000", "0.00435000"], ["84204.16000000", "0.01951000"], ["84204.21000000", "0.00000000"], ["84215.94000000", "0.00000000"], ["84216.00000000", "0.20913000"], ["84217.50000000", "0.00000000"], ["84217.78000000", "0.00000000"], ["84219.75000000", "0.00000000"], ["84223.83000000", "0.01226000"], ["84226.62000000", "0.00000000"], ["84227.80000000", "0.01979000"], ["84228.00000000", "0.00863000"], ["84228.71000000", "0.00000000"], ["84229.07000000", "0.00000000"], ["84229.32000000", "0.00000000"], ["84231.21000000", "0.00000000"], ["84232.00000000", "0.00235000"], ["84232.15000000", "0.00000000"], ["84242.31000000", "0.00000000"], ["84246.43000000", "0.00000000"], ["84253.94000000", "0.00000000"], ["84276.48000000", "0.00000000"], ["84287.11000000", "0.00000000"], ["85330.42000000", "0.00000000"]], "record_time": 1742584889.127694, "EXCHANGE": "BINANCE"}
{"e": "depthUpdate", "E": 1742584890014, "s": "BTCUSDT", "U": 64637873091, "u": 64637873269, "b": [["84069.36000000", "1.90458000"], ["84065.10000000", "0.01000000"], ["84044.75000000", "0.00000000"], ["84030.40000000", "0.00000000"], ["84028.33000000", "0.00146000"], ["84022.82000000", "0.00650000"], ["84011.30000000", "0.00000000"], ["84008.73000000", "0.00296000"], ["84006.55000000", "0.00000000"], ["84006.45000000", "0.05000000"], ["84001.27000000", "0.02854000"], ["83995.60000000", "0.00000000"], ["83993.08000000", "0.00296000"], ["83979.83000000", "0.00000000"], ["83976.37000000", "0.00000000"], ["83974.11000000", "0.00146000"], ["83951.46000000", "0.05097000"], ["83937.14000000", "0.00000000"], ["83924.70000000", "0.00270000"], ["83912.14000000", "0.00400000"], ["83906.96000000", "0.00000000"], ["82808.31000000", "0.00000000"], ["75662.00000000", "0.00202000"], ["67255.49000000", "0.00058000"], ["33000.00000000", "2.93827000"], ["30225.93000000", "0.00060000"], ["30224.44000000", "0.00040000"], ["30223.89000000", "0.00060000"], ["30211.89000000", "0.00000000"], ["30211.08000000", "0.00260000"], ["30208.95000000", "0.00200000"], ["30198.80000000", "0.00280000"], ["30195.30000000", "0.00340000"], ["30176.53000000", "0.00080000"], ["30174.55000000", "0.00000000"], ["30171.74000000", "0.00340000"], ["30169.72000000", "0.00100000"], ["30166.71000000", "0.00280000"], ["30161.52000000", "0.00080000"], ["30158.98000000", "0.00060000"], ["30150.00000000", "0.02762000"], ["30136.03000000", "0.00000000"], ["20002.00000000", "0.00000000"], ["20001.00000000", "0.02099000"]], "a": [["84069.37000000", "2.38802000"], ["84069.58000000", "0.00007000"], ["84069.69000000", "0.00007000"], ["84069.83000000", "0.00007000"], ["84069.84000000", "0.00000000"], ["84071.00000000", "0.00006000"], ["84071.27000000", "0.00000000"], ["84075.49000000", "0.00008000"], ["84076.09000000", "0.11627000"], ["84083.20000000", "0.89155000"], ["84084.81000000", "0.01041000"], ["84085.45000000", "0.02519000"], ["84094.58000000", "0.01173000"], ["84095.26000000", "0.78631000"], ["84096.38000000", "0.00000000"], ["84097.84000000", "0.00151000"], ["84101.62000000", "0.01895000"], ["84104.47000000", "0.00500000"], ["84107.44000000", "0.52351000"], ["84109.90000000", "0.02155000"], ["84131.96000000", "0.02661000"], ["84132.60000000", "0.02155000"], ["84135.47000000", "0.00997000"], ["84136.69000000", "0.00000000"], ["84137.46000000", "0.02854000"], ["84138.27000000", "0.00297000"], ["84141.10000000", "0.02100000"], ["84143.91000000", "0.02457000"], ["84148.77000000", "0.00000000"], ["84152.54000000", "0.00151000"], ["84153.80000000", "0.00297000"], ["84155.99000000", "0.00000000"], ["84158.59000000", "0.00000000"], ["84161.04000000", "0.00000000"], ["84165.20000000", "0.01994000"], ["84169.22000000", "0.00000000"], ["84174.87000000", "0.00000000"], ["84177.97000000", "0.00000000"], ["84178.86000000", "0.00000000"], ["84186.51000000", "0.01041000"], ["84189.08000000", "0.00000000"], ["84191.31000000", "0.02313000"], ["84196.78000000", "0.00000000"], ["84199.14000000", "0.00000000"], ["84204.04000000", "0.00000000"], ["84205.37000000", "0.00000000"], ["84207.10000000", "0.00000000"], ["84216.52000000", "0.00000000"], ["84219.79000000", "0.01491000"], ["84224.07000000", "0.00000000"], ["84224.08000000", "0.00903000"], ["84224.88000000", "0.02078000"], ["84228.44000000", "0.01003000"], ["84229.65000000", "0.00000000"], ["84239.08000000", "0.00000000"], ["84239.09000000", "0.00016000"], ["84239.10000000", "0.00119000"], ["84239.11000000", "0.00000000"], ["84240.74000000", "0.00000000"], ["84240.95000000", "0.00000000"], ["84241.27000000", "0.01659000"], ["84246.38000000", "0.00000000"], ["84254.56000000", "0.00119000"], ["84280.32000000", "0.00000000"], ["84910.05000000", "0.00000000"], ["85330.42000000", "0.00100000"], ["87999.99000000", "0.30401000"], ["88000.00000000", "83.34263000"]], "record_time": 1742584890.126576, "EXCHANGE": "BINANCE"}
{"e": "depthUpdate", "E": 1742584891014, "s": "BTCUSDT", "U": 64637873270, "u": 64637873445, "b": [["84069.36000000", "1.90458000"], ["84069.35000000", "0.00054000"], ["84069.34000000", "0.00007000"], ["84065.10000000", "0.00500000"], ["84046.06000000", "0.00000000"], ["84020.36000000", "0.00000000"], ["84019.57000000", "0.05000000"], ["84013.83000000", "0.00000000"], ["83980.93000000", "0.09395000"], ["83976.87000000", "0.00000000"], ["83973.08000000", "0.04639000"], ["83972.66000000", "0.00000000"], ["83971.11000000", "0.00000000"], ["83970.43000000", "0.04639000"], ["83960.69000000", "0.00000000"], ["82808.31000000", "0.00100000"], ["75662.00000000", "0.00202000"], ["67255.49000000", "0.00058000"], ["33000.00000000", "2.93827000"], ["30264.97000000", "0.00260000"]], "a": [["84069.37000000", "2.44682000"], ["84069.38000000", "0.00063000"], ["84072.20000000", "0.00000000"], ["84075.42000000", "0.78538000"], ["84076.09000000", "0.11627000"], ["84077.10000000", "0.00000000"], ["84083.20000000", "0.89655000"], ["84085.18000000", "0.01784000"], ["84093.06000000", "0.01784000"], ["84096.38000000", "0.00000000"], ["84107.23000000", "0.01116000"], ["84109.69000000", "0.02533000"], ["84109.79000000", "0.01197000"], ["84132.39000000", "0.01594000"], ["84134.77000000", "0.02634000"], ["84143.93000000", "0.00894000"], ["84145.89000000", "0.00000000"], ["84149.18000000", "0.02035000"], ["84152.55000000", "0.00000000"], ["84164.96000000", "0.04757000"], ["84166.31000000", "0.00000000"], ["84170.25000000", "0.00000000"], ["84171.95000000", "0.04639000"], ["84186.29000000", "0.01150000"], ["84188.58000000", "0.05497000"], ["84191.32000000", "0.00000000"], ["84191.49000000", "0.05497000"], ["84194.27000000", "0.02342000"], ["84195.20000000", "0.02315000"], ["84203.43000000", "0.00000000"], ["84207.84000000", "0.02035000"], ["84210.38000000", "0.00000000"], ["84214.08000000", "0.00000000"], ["84215.72000000", "0.00000000"], ["84215.97000000", "0.00000000"], ["84216.68000000", "0.00000000"], ["84219.98000000", "0.05497000"], ["84239.08000000", "0.00000000"], ["84239.09000000", "0.00000000"], ["84239.10000000", "0.00000000"], ["84240.87000000", "0.00000000"], ["84245.94000000", "0.01150000"], ["84248.10000000", "0.01000000"], ["84254.55000000", "0.99812000"], ["84254.56000000", "0.00119000"], ["84288.38000000", "0.00000000"], ["85330.42000000", "0.00000000"]], "record_time": 1742584891.126713, "EXCHANGE": "BINANCE"}
{"e": "depthUpdate", "E": 1742584892014, "s": "BTCUSDT", "U": 64637873446, "u": 64637873554, "b": [["84069.36000000", "1.88025000"], ["84065.10000000", "0.00000000"], ["84049.76000000", "0.00759000"], ["84049.60000000", "0.00000000"], ["84047.28000000", "0.00000000"], ["84029.56000000", "0.01300000"], ["83976.87000000", "0.63105000"], ["83915.58000000", "0.00835000"], ["83914.90000000", "0.00000000"], ["83847.43000000", "0.00060000"], ["83847.42000000", "0.00000000"], ["82808.31000000", "0.00000000"], ["75662.00000000", "0.00202000"], ["67255.49000000", "0.00058000"], ["33000.00000000", "2.93827000"], ["30237.13000000", "0.00280000"], ["30220.44000000", "0.00060000"], ["30211.08000000", "0.00240000"], ["30208.95000000", "0.00180000"], ["30205.44000000", "0.00000000"], ["30195.30000000", "0.00300000"], ["30175.54000000", "0.00100000"], ["30173.30000000", "0.00260000"], ["30168.40000000", "0.00100000"], ["30160.79000000", "0.00060000"], ["30158.37000000", "0.00020000"]], "a": [["84069.37000000", "2.44603000"], ["84076.09000000", "0.11627000"], ["84079.82000000", "0.04400000"], ["84080.70000000", "0.06800000"], ["84082.00000000", "0.01253000"], ["84083.20000000", "0.90155000"], ["84084.05000000", "0.00000000"], ["84084.89000000", "0.06000000"], ["84084.91000000", "0.00000000"], ["84089.10000000", "0.00000000"], ["84096.38000000", "0.00000000"], ["84101.58000000", "0.00483000"], ["84110.72000000", "0.00641000"], ["84136.20000000", "0.00000000"], ["84136.49000000", "0.00000000"], ["84140.73000000", "0.02642000"], ["84141.04000000", "0.02479000"], ["84141.37000000", "0.00000000"], ["84145.20000000", "0.00000000"], ["84148.00000000", "0.07035000"], ["84149.63000000", "0.00000000"], ["84161.04000000", "0.01653000"], ["84165.60000000", "0.01346000"], ["84165.85000000", "0.00535000"], ["84187.04000000", "0.00000000"], ["84191.54000000", "0.00000000"], ["84203.62000000", "0.01054000"], ["84210.98000000", "0.01384000"], ["84215.89000000", "0.01346000"], ["84216.45000000", "0.00000000"], ["84219.87000000", "0.00000000"], ["84237.83000000", "0.00450000"], ["84237.85000000", "0.02051000"], ["84238.40000000", "0.00000000"], ["84239.09000000", "0.00016000"], ["84239.10000000", "0.00119000"], ["84240.64000000", "0.00641000"], ["84245.13000000", "0.00483000"], ["84246.73000000", "0.02463000"], ["84254.55000000", "0.99677000"], ["84254.56000000", "0.00119000"], ["84258.01000000", "0.00000000"], ["84259.25000000", "0.00010000"], ["84270.61000000", "0.00000000"], ["84283.44000000", "0.00000000"], ["84287.27000000", "0.00000000"], ["84297.56000000", "0.00000000"], ["84359.99000000", "0.00000000"], ["84360.00000000", "0.01013000"], ["85330.42000000", "0.00100000"]], "record_time": 1742584892.12656, "EXCHANGE": "BINANCE"}
{"e": "depthUpdate", "E": 1742584893014, "s": "BTCUSDT", "U": 64637873555, "u": 64637876221, "b": [["84076.08000000", "7.68487000"], ["84076.07000000", "0.00047000"], ["84076.00000000", "0.02280000"], ["84075.59000000", "0.00007000"], ["84075.58000000", "0.00007000"], ["84075.51000000", "0.70860000"], ["84075.50000000", "0.00007000"], ["84075.49000000", "0.01014000"], ["84075.48000000", "2.00551000"], ["84075.47000000", "0.00000000"], ["84075.32000000", "0.35974000"], ["84074.66000000", "0.00007000"], ["84074.00000000", "0.02266000"], ["84073.83000000", "0.00024000"], ["84073.82000000", "0.04501000"], ["84073.81000000", "0.01189000"], ["84073.70000000", "0.05359000"], ["84073.56000000", "0.00000000"], ["84072.97000000", "0.00007000"], ["84072.95000000", "0.00000000"], ["84072.93000000", "0.00000000"], ["84072.92000000", "0.00000000"], ["84072.91000000", "0.00000000"], ["84072.70000000", "0.36071000"], ["84072.69000000", "0.00000000"], ["84072.68000000", "0.00000000"], ["84072.67000000", "0.00000000"], ["84072.60000000", "0.00000000"], ["84072.57000000", "0.00000000"], ["84072.56000000", "0.18263000"], ["84072.55000000", "0.00000000"], ["84072.53000000", "0.02539000"], ["84072.49000000", "0.00000000"], ["84072.17000000", "0.00000000"], ["84072.16000000", "0.00000000"], ["84072.15000000", "0.00000000"], ["84072.01000000", "0.00000000"], ["84072.00000000", "0.02260000"], ["84071.49000000", "0.00000000"], ["84071.40000000", "0.00000000"], ["84071.39000000", "0.00000000"], ["84071.17000000", "0.02817000"], ["84070.89000000", "0.00000000"], ["84070.57000000", "0.00000000"], ["84070.54000000", "0.00000000"], ["84070.43000000", "0.00000000"], ["84070.42000000", "0.39546000"], ["84070.36000000", "0.14476000"], ["84070.13000000", "0.04000000"], ["84070.08000000", "0.00000000"], ["84070.00000000", "0.02260000"], ["84069.91000000", "0.00000000"], ["84069.76000000", "0.00000000"], ["84069.68000000", "0.00000000"], ["84069.57000000", "0.00000000"], ["84069.48000000", "0.00000000"], ["84069.45000000", "0.00118000"], ["84069.39000000", "0.00000000"], ["84069.38000000", "0.27732000"], ["84069.37000000", "0.23600000"], ["84069.36000000", "0.49717000"], ["84069.35000000", "0.00008000"], ["84069.34000000", "0.00000000"], ["84069.33000000", "0.00000000"], ["84069.32000000", "0.00000000"], ["84069.31000000", "0.00000000"], ["84069.30000000", "0.00000000"], ["84069.29000000", "0.00000000"], ["84069.28000000", "0.00000000"], ["84069.22000000", "0.00000000"], ["84069.21000000", "0.00000000"], ["84069.17000000", "0.00202000"], ["84069.16000000", "0.00000000"], ["84069.06000000", "0.00000000"], ["84068.94000000", "0.00000000"], ["84068.93000000", "0.00000000"], ["84068.90000000", "0.16280000"], ["84068.76000000", "0.01189000"], ["84068.74000000", "0.00150000"], ["84068.66000000", "0.00006000"], ["84068.60000000", "0.00000000"], ["84068.59000000", "0.00000000"], ["84068.58000000", "0.00000000"], ["84068.44000000", "0.04000000"], ["84068.39000000", "0.04000000"], ["84068.38000000", "0.02973000"], ["84068.36000000", "0.00000000"], ["84068.15000000", "0.00000000"], ["84068.11000000", "0.03380000"], ["84068.06000000", "0.00594000"], ["84068.00000000", "0.02270000"], ["84067.91000000", "0.04000000"], ["84067.69000000", "0.00000000"], ["84067.09000000", "0.00000000"], ["84067.06000000", "0.00000000"], ["84067.05000000", "0.00000000"], ["84067.04000000", "0.00000000"], ["84066.99000000", "0.00000000"], ["84066.87000000", "0.00000000"], ["84066.57000000", "0.00000000"], ["84066.53000000", "0.00000000"], ["84066.38000000", "0.00009000"], ["84066.20000000", "0.00000000"], ["84066.09000000", "0.00000000"], ["84065.88000000", "0.00000000"], ["84065.87000000", "0.00000000"], ["84065.84000000", "0.00000000"], ["84065.79000000", "0.00000000"], ["84065.70000000", "0.04000000"], ["84065.65000000", "0.00000000"], ["84065.58000000", "0.00000000"], ["84065.42000000", "0.00000000"], ["84065.09000000", "0.04000000"], ["84064.98000000", "0.00013000"], ["84064.73000000", "0.00000000"], ["84064.64000000", "0.50069000"], ["84064.63000000", "0.85689000"], ["84064.28000000", "0.00000000"], ["84064.18000000", "0.04000000"], ["84064.10000000", "0.00000000"], ["84064.01000000", "0.00000000"], ["84063.82000000", "0.03000000"], ["84063.62000000", "0.00006000"], ["84063.41000000", "0.00118000"], ["84063.36000000", "0.00000000"], ["84063.33000000", "0.00000000"], ["84063.00000000", "0.00006000"], ["84062.95000000", "0.00000000"], ["84062.94000000", "0.00000000"], ["84062.88000000", "0.01189000"], ["84062.71000000", "0.00922000"], ["84062.64000000", "0.00000000"], ["84062.50000000", "0.00400000"], ["84062.14000000", "0.71126000"], ["84061.48000000", "0.00000000"], ["84060.95000000", "0.00013000"], ["84060.93000000", "0.00000000"], ["84060.73000000", "1.13979000"], ["84060.72000000", "0.85693000"], ["84060.65000000", "0.04000000"], ["84060.54000000", "0.00000000"], ["84060.19000000", "0.35662000"], ["84060.06000000", "0.17899000"], ["84060.05000000", "0.00000000"], ["84059.96000000", "0.00000000"], ["84059.94000000", "0.01189000"], ["84059.77000000", "0.00000000"], ["84059.38000000", "0.00000000"], ["84059.35000000", "0.00000000"], ["84059.34000000", "0.00000000"], ["84058.81000000", "0.00000000"], ["84058.80000000", "0.00006000"], ["84058.76000000", "0.59490000"], ["84058.73000000", "0.02378000"], ["84058.58000000", "0.00064000"], ["84058.46000000", "0.00000000"], ["84058.21000000", "0.00000000"], ["84057.90000000", "0.00000000"], ["84057.89000000", "0.00000000"], ["84057.39000000", "0.08992000"], ["84057.21000000", "0.05943000"], ["84057.06000000", "0.79480000"], ["84057.02000000", "0.85697000"], ["84056.81000000", "0.00000000"], ["84056.76000000", "0.00000000"], ["84056.60000000", "0.00594000"], ["84056.47000000", "0.00000000"], ["84056.46000000", "0.85697000"], ["84055.15000000", "0.00000000"], ["84055.14000000", "0.00000000"], ["84054.85000000", "0.00000000"], ["84054.31000000", "0.00000000"], ["84054.05000000", "0.00000000"], ["84053.96000000", "0.00000000"], ["84052.66000000", "0.00000000"], ["84052.34000000", "0.00000000"], ["84051.30000000", "0.01189000"], ["84051.27000000", "0.00101000"], ["84050.73000000", "0.00000000"], ["84050.71000000", "0.00000000"], ["84050.61000000", "0.00007000"], ["84050.54000000", "0.00358000"], ["84050.50000000", "0.04228000"], ["84050.44000000", "0.11886000"], ["84049.41000000", "0.00000000"], ["84048.98000000", "0.04628000"], ["84048.91000000", "0.00000000"], ["84048.74000000", "0.00000000"], ["84048.56000000", "0.00000000"], ["84048.47000000", "0.11370000"], ["84048.22000000", "0.00000000"], ["84047.60000000", "0.00000000"], ["84046.91000000", "0.10604000"], ["84046.90000000", "0.00000000"], ["84046.34000000", "0.00000000"], ["84046.06000000", "0.00000000"], ["84045.96000000", "0.00000000"], ["84045.23000000", "0.00000000"], ["84045.14000000", "0.00000000"], ["84044.69000000", "0.00000000"], ["84044.13000000", "0.00300000"], ["84043.88000000", "0.00000000"], ["84043.82000000", "0.34972000"], ["84043.43000000", "0.00000000"], ["84043.30000000", "0.00000000"], ["84042.98000000", "0.00000000"], ["84041.46000000", "0.00506000"], ["84041.45000000", "0.00000000"], ["84041.34000000", "0.08992000"], ["84041.31000000", "0.00000000"], ["84039.50000000", "0.00000000"], ["84039.47000000", "0.00000000"], ["84035.72000000", "0.03202000"], ["84035.66000000", "0.00000000"], ["84034.62000000", "0.00000000"], ["84034.38000000", "0.00000000"], ["84034.37000000", "0.00146000"], ["84034.36000000", "0.26909000"], ["84034.33000000", "0.21488000"], ["84033.70000000", "0.00000000"], ["84033.60000000", "0.05956000"], ["84033.40000000", "0.00000000"], ["84029.91000000", "0.05796000"], ["84029.56000000", "0.00000000"], ["84028.92000000", "0.00000000"], ["84028.76000000", "0.01300000"], ["84028.33000000", "0.00000000"], ["84027.32000000", "0.00000000"], ["84026.40000000", "0.00000000"], ["84024.21000000", "0.00000000"], ["84022.91000000", "0.00013000"], ["84022.08000000", "0.00000000"], ["84021.78000000", "0.00272000"], ["84020.44000000", "0.00000000"], ["84019.57000000", "0.00000000"], ["84019.33000000", "0.00000000"], ["84018.06000000", "0.00000000"], ["84017.62000000", "0.01242000"], ["84016.80000000", "0.00006000"], ["84015.33000000", "0.00000000"], ["84014.77000000", "0.09642000"], ["84014.57000000", "0.00000000"], ["84014.56000000", "0.00000000"], ["84013.74000000", "0.00853000"], ["84012.95000000", "0.00809000"], ["84012.71000000", "0.00000000"], ["84008.10000000", "0.00000000"], ["84006.58000000", "0.10000000"], ["84006.45000000", "0.00000000"], ["84001.63000000", "0.05298000"], ["84000.47000000", "0.00000000"], ["83999.99000000", "0.03570000"], ["83999.76000000", "0.00145000"], ["83998.62000000", "0.08354000"], ["83984.64000000", "0.00000000"], ["83984.04000000", "0.01196000"], ["83983.42000000", "0.00000000"], ["83983.19000000", "0.00000000"], ["83982.26000000", "0.00000000"], ["83978.24000000", "0.13313000"], ["83976.95000000", "0.00000000"], ["83976.87000000", "0.00000000"], ["83975.15000000", "0.00000000"], ["83971.67000000", "0.17933000"], ["83971.43000000", "0.00000000"], ["83967.76000000", "0.00000000"], ["83963.30000000", "0.00000000"], ["83956.19000000", "0.00000000"], ["83952.81000000", "0.04997000"], ["83940.90000000", "0.18323000"], ["83939.31000000", "0.00000000"], ["83935.38000000", "0.63105000"], ["83934.13000000", "0.00314000"], ["83924.70000000", "0.00000000"], ["83913.17000000", "0.00000000"], ["83912.14000000", "0.00000000"], ["83906.26000000", "0.00000000"], ["83839.23000000", "0.19749000"], ["83835.79000000", "0.00000000"], ["83835.70000000", "0.00000000"], ["83830.83000000", "0.20192000"], ["83830.82000000", "0.00000000"], ["83828.97000000", "0.00000000"], ["83827.39000000", "0.00000000"], ["83827.30000000", "0.00000000"], ["83822.43000000", "0.01189000"], ["83822.42000000", "0.00000000"], ["83821.82000000", "0.00000000"], ["83733.08000000", "0.00008000"], ["83161.69000000", "0.06004000"], ["82808.31000000", "0.00100000"], ["82600.00000000", "8.39554000"], ["80697.27000000", "0.03567000"], ["80680.44000000", "0.00000000"], ["75662.00000000", "0.00202000"], ["67260.87000000", "0.00058000"], ["67255.49000000", "0.00000000"], ["33000.00000000", "2.93827000"], ["30264.97000000", "0.00300000"]], "a": [["84069.37000000", "0.00000000"], ["84069.38000000", "0.00000000"], ["84069.39000000", "0.00000000"], ["84069.40000000", "0.00000000"], ["84069.49000000", "0.00000000"], ["84069.58000000", "0.00000000"], ["84069.69000000", "0.00000000"], ["84069.77000000", "0.00000000"], ["84069.83000000", "0.00000000"], ["84069.91000000", "0.00000000"], ["84069.92000000", "0.00000000"], ["84069.99000000", "0.00000000"], ["84070.00000000", "0.00000000"], ["84070.29000000", "0.00000000"], ["84070.43000000", "0.00000000"], ["84070.46000000", "0.00000000"], ["84070.72000000", "0.00000000"], ["84070.91000000", "0.00000000"], ["84071.00000000", "0.00000000"], ["84071.08000000", "0.00000000"], ["84071.40000000", "0.00000000"], ["84071.65000000", "0.00000000"], ["84071.66000000", "0.00000000"], ["84072.00000000", "0.00000000"], ["84072.08000000", "0.00000000"], ["84072.09000000", "0.00000000"], ["84072.16000000", "0.00000000"], ["84072.17000000", "0.00000000"], ["84072.18000000", "0.00000000"], ["84072.19000000", "0.00000000"], ["84072.26000000", "0.00000000"], ["84072.35000000", "0.00000000"], ["84072.36000000", "0.00000000"], ["84072.50000000", "0.00000000"], ["84072.51000000", "0.00000000"], ["84072.56000000", "0.00000000"], ["84072.57000000", "0.00000000"], ["84072.58000000", "0.00000000"], ["84072.92000000", "0.00000000"], ["84072.93000000", "0.00000000"], ["84072.94000000", "0.00000000"], ["84072.96000000", "0.00000000"], ["84073.57000000", "0.00000000"], ["84073.82000000", "0.00000000"], ["84073.83000000", "0.00000000"], ["84073.98000000", "0.00000000"], ["84074.00000000", "0.00000000"], ["84074.13000000", "0.00000000"], ["84074.14000000", "0.00000000"], ["84074.50000000", "0.00000000"], ["84074.65000000", "0.00000000"], ["84074.66000000", "0.00000000"], ["84074.85000000", "0.00000000"], ["84074.86000000", "0.00000000"], ["84075.00000000", "0.00000000"], ["84075.16000000", "0.00000000"], ["84075.31000000", "0.00000000"], ["84075.38000000", "0.00000000"], ["84075.42000000", "0.00000000"], ["84075.48000000", "0.00000000"], ["84075.49000000", "0.00000000"], ["84075.50000000", "0.00000000"], ["84075.51000000", "0.00000000"], ["84075.59000000", "0.00000000"], ["84075.60000000", "0.00000000"], ["84076.01000000", "0.00000000"], ["84076.08000000", "0.00000000"], ["84076.09000000", "0.08398000"], ["84076.10000000", "0.00047000"], ["84076.20000000", "0.00000000"], ["84076.33000000", "0.00007000"], ["84076.37000000", "0.00000000"], ["84076.40000000", "0.00000000"], ["84077.27000000", "0.00000000"], ["84077.28000000", "0.00000000"], ["84077.40000000", "0.00000000"], ["84077.63000000", "0.00021000"], ["84077.64000000", "0.00013000"], ["84077.77000000", "0.00007000"], ["84077.78000000", "0.00307000"], ["84077.96000000", "0.00000000"], ["84077.98000000", "0.00043000"], ["84077.99000000", "0.00000000"], ["84078.00000000", "0.00000000"], ["84078.02000000", "0.00000000"], ["84078.07000000", "0.00000000"], ["84078.08000000", "0.00000000"], ["84078.17000000", "0.00000000"], ["84078.20000000", "0.00000000"], ["84078.27000000", "0.00000000"], ["84078.28000000", "0.00000000"], ["84078.37000000", "0.00000000"], ["84078.40000000", "0.00000000"], ["84078.59000000", "0.00000000"], ["84078.67000000", "0.00000000"], ["84078.68000000", "0.00000000"], ["84078.69000000", "0.00000000"], ["84078.72000000", "0.00000000"], ["84078.73000000", "0.00000000"], ["84078.74000000", "0.00000000"], ["84078.88000000", "0.00000000"], ["84078.89000000", "0.00000000"], ["84079.04000000", "0.00000000"], ["84079.09000000", "0.00000000"], ["84079.24000000", "0.00008000"], ["84079.59000000", "0.00000000"], ["84079.60000000", "0.00000000"], ["84079.63000000", "0.00000000"], ["84079.64000000", "0.02241000"], ["84079.71000000", "0.00007000"], ["84079.72000000", "0.00000000"], ["84079.74000000", "0.00000000"], ["84079.75000000", "0.00000000"], ["84079.77000000", "0.00000000"], ["84079.82000000", "0.00000000"], ["84079.99000000", "0.00009000"], ["84080.00000000", "0.02273000"], ["84080.16000000", "0.00000000"], ["84080.40000000", "0.00000000"], ["84080.57000000", "0.00000000"], ["84080.63000000", "0.00000000"], ["84080.68000000", "0.00000000"], ["84080.70000000", "0.00000000"], ["84080.87000000", "0.00010000"], ["84080.88000000", "0.07115000"], ["84081.05000000", "0.00000000"], ["84081.06000000", "0.00000000"], ["84081.13000000", "0.00000000"], ["84081.17000000", "0.02219000"], ["84081.22000000", "0.00000000"], ["84081.32000000", "0.02162000"], ["84081.34000000", "0.16190000"], ["84081.42000000", "0.01930000"], ["84081.58000000", "0.00000000"], ["84081.73000000", "0.00000000"], ["84081.97000000", "0.00000000"], ["84082.01000000", "0.00118000"], ["84082.04000000", "0.00000000"], ["84082.09000000", "0.00091000"], ["84082.11000000", "0.00000000"], ["84082.12000000", "0.55782000"], ["84082.20000000", "0.01032000"], ["84082.30000000", "0.01000000"], ["84082.37000000", "0.00500000"], ["84082.47000000", "0.01000000"], ["84082.70000000", "0.00095000"], ["84082.83000000", "0.00000000"], ["84082.94000000", "0.00000000"], ["84083.11000000", "0.14151000"], ["84083.19000000", "0.00000000"], ["84083.20000000", "0.00500000"], ["84083.32000000", "0.00000000"], ["84083.45000000", "0.00000000"], ["84083.52000000", "0.10604000"], ["84083.91000000", "0.00000000"], ["84083.93000000", "0.00000000"], ["84083.96000000", "0.00000000"], ["84084.77000000", "0.00000000"], ["84084.83000000", "0.00000000"], ["84084.88000000", "0.06000000"], ["84084.89000000", "0.00000000"], ["84085.05000000", "0.00000000"], ["84085.17000000", "0.00000000"], ["84085.27000000", "0.00000000"], ["84085.33000000", "0.00000000"], ["84085.37000000", "0.00000000"], ["84085.43000000", "0.00000000"], ["84085.57000000", "0.00000000"], ["84085.77000000", "0.00000000"], ["84085.78000000", "0.00000000"], ["84085.79000000", "0.00000000"], ["84086.18000000", "0.00000000"], ["84086.28000000", "0.08000000"], ["84086.31000000", "0.04400000"], ["84086.35000000", "0.00000000"], ["84086.91000000", "0.00000000"], ["84086.97000000", "0.00000000"], ["84086.98000000", "0.60726000"], ["84087.16000000", "0.04400000"], ["84087.24000000", "0.00000000"], ["84087.26000000", "0.00000000"], ["84087.57000000", "0.16344000"], ["84087.63000000", "0.00000000"], ["84088.00000000", "0.09060000"], ["84088.01000000", "0.06400000"], ["84088.05000000", "0.04800000"], ["84088.14000000", "0.00000000"], ["84088.40000000", "0.00400000"], ["84088.41000000", "0.00000000"], ["84088.69000000", "0.00000000"], ["84088.95000000", "0.00000000"], ["84089.21000000", "0.00000000"], ["84089.28000000", "0.29803000"], ["84089.35000000", "0.00007000"], ["84090.28000000", "0.14160000"], ["84090.38000000", "0.00000000"], ["84090.63000000", "0.01189000"], ["84091.28000000", "0.00000000"], ["84091.31000000", "0.00000000"], ["84091.36000000", "0.05600000"], ["84091.45000000", "0.00000000"], ["84091.59000000", "0.00013000"], ["84091.84000000", "0.00000000"], ["84092.20000000", "0.06000000"], ["84092.21000000", "0.05600000"], ["84092.27000000", "0.08000000"], ["84092.33000000", "0.00000000"], ["84092.39000000", "0.35567000"], ["84092.58000000", "0.78522000"], ["84092.64000000", "0.00000000"], ["84092.85000000", "1.36820000"], ["84092.93000000", "0.35662000"], ["84093.08000000", "0.00000000"], ["84093.75000000", "0.00000000"], ["84093.85000000", "0.00000000"], ["84093.91000000", "0.04000000"], ["84094.33000000", "0.00000000"], ["84094.37000000", "0.00000000"], ["84094.69000000", "0.00000000"], ["84095.11000000", "0.00000000"], ["84095.25000000", "0.00000000"], ["84095.26000000", "0.46359000"], ["84095.28000000", "0.00000000"], ["84095.62000000", "0.00000000"], ["84096.15000000", "0.16000000"], ["84096.40000000", "0.16637000"], ["84096.85000000", "0.00000000"], ["84096.94000000", "0.00000000"], ["84097.08000000", "0.00000000"], ["84097.46000000", "0.00000000"], ["84097.53000000", "0.00000000"], ["84097.79000000", "0.00000000"], ["84097.84000000", "0.00000000"], ["84097.99000000", "0.00000000"], ["84098.19000000", "0.89155000"], ["84098.33000000", "0.00000000"], ["84098.53000000", "0.00000000"], ["84098.54000000", "0.00000000"], ["84099.07000000", "0.00000000"], ["84099.22000000", "0.00000000"], ["84099.27000000", "0.03359000"], ["84099.31000000", "0.00000000"], ["84099.34000000", "0.00000000"], ["84099.35000000", "0.01083000"], ["84099.65000000", "0.00000000"], ["84100.09000000", "0.30831000"], ["84100.37000000", "0.30827000"], ["84100.71000000", "0.11886000"], ["84101.07000000", "0.00000000"], ["84101.08000000", "0.00000000"], ["84101.09000000", "0.00000000"], ["84101.11000000", "0.00000000"], ["84101.43000000", "0.89155000"], ["84101.72000000", "0.00000000"], ["84102.37000000", "0.00000000"], ["84102.85000000", "0.00000000"], ["84103.30000000", "0.89155000"], ["84103.56000000", "0.89155000"], ["84103.63000000", "0.00000000"], ["84104.25000000", "0.00151000"], ["84104.26000000", "0.00000000"], ["84104.47000000", "0.00000000"], ["84105.00000000", "0.00006000"], ["84105.74000000", "0.00000000"], ["84106.41000000", "0.00000000"], ["84107.27000000", "0.00720000"], ["84107.35000000", "0.00000000"], ["84107.43000000", "0.00000000"], ["84107.44000000", "0.00000000"], ["84107.73000000", "0.00000000"], ["84108.19000000", "0.04400000"], ["84108.96000000", "0.00000000"], ["84109.17000000", "0.00000000"], ["84109.32000000", "0.00000000"], ["84109.46000000", "0.00000000"], ["84109.47000000", "0.00000000"], ["84109.60000000", "0.02172000"], ["84110.38000000", "0.00000000"], ["84110.67000000", "0.00000000"], ["84111.40000000", "0.00000000"], ["84111.57000000", "0.03676000"], ["84111.84000000", "0.00000000"], ["84112.46000000", "0.35788000"], ["84112.94000000", "0.00000000"], ["84113.24000000", "0.05600000"], ["84113.30000000", "0.08000000"], ["84113.31000000", "0.85639000"], ["84113.41000000", "0.00000000"], ["84113.77000000", "0.00000000"], ["84114.14000000", "0.00000000"], ["84114.26000000", "0.01926000"], ["84114.72000000", "0.00000000"], ["84117.38000000", "0.12200000"], ["84117.64000000", "0.85635000"], ["84117.72000000", "0.00000000"], ["84117.76000000", "0.00573000"], ["84117.81000000", "0.39281000"], ["84118.44000000", "0.05496000"], ["84119.00000000", "0.00000000"], ["84119.32000000", "0.05296000"], ["84119.51000000", "0.00000000"], ["84119.82000000", "0.00509000"], ["84120.26000000", "0.05766000"], ["84121.03000000", "0.00000000"], ["84124.75000000", "0.00000000"], ["84125.06000000", "0.59489000"], ["84125.50000000", "0.01792000"], ["84125.72000000", "0.00000000"], ["84127.21000000", "0.00860000"], ["84127.86000000", "0.00000000"], ["84128.46000000", "0.04371000"], ["84128.89000000", "0.00750000"], ["84130.83000000", "0.00821000"], ["84132.12000000", "0.00000000"], ["84135.43000000", "0.00000000"], ["84135.51000000", "0.00839000"], ["84136.36000000", "0.00000000"], ["84136.38000000", "0.02814000"], ["84138.27000000", "0.00000000"], ["84142.08000000", "0.00000000"], ["84142.11000000", "0.00000000"], ["84142.21000000", "0.00000000"], ["84144.52000000", "0.00000000"], ["84145.00000000", "0.00297000"], ["84146.74000000", "0.00000000"], ["84152.36000000", "0.03971000"], ["84152.54000000", "0.00000000"], ["84153.80000000", "0.00000000"], ["84154.86000000", "0.00599000"], ["84155.79000000", "0.00151000"], ["84159.31000000", "0.05225000"], ["84160.35000000", "0.05176000"], ["84161.03000000", "0.00296000"], ["84161.24000000", "0.10319000"], ["84162.93000000", "0.04800000"], ["84165.19000000", "0.00000000"], ["84166.36000000", "0.00000000"], ["84167.41000000", "0.00000000"], ["84167.81000000", "0.00000000"], ["84169.04000000", "0.06800000"], ["84169.74000000", "0.00000000"], ["84172.40000000", "0.00059000"], ["84173.11000000", "0.02380000"], ["84173.71000000", "0.02290000"], ["84174.01000000", "0.00000000"], ["84174.03000000", "0.05600000"], ["84174.87000000", "0.06000000"], ["84179.25000000", "0.00000000"], ["84181.32000000", "0.00839000"], ["84183.35000000", "0.63446000"], ["84186.22000000", "0.00000000"], ["84188.96000000", "0.01792000"], ["84189.08000000", "0.04400000"], ["84190.77000000", "0.00000000"], ["84191.44000000", "0.01425000"], ["84193.27000000", "0.12900000"], ["84194.54000000", "0.01112000"], ["84195.05000000", "0.00000000"], ["84198.05000000", "0.02380000"], ["84198.56000000", "0.01333000"], ["84212.30000000", "0.00000000"], ["84216.00000000", "0.20795000"], ["84219.64000000", "0.00574000"], ["84224.44000000", "0.00000000"], ["84239.09000000", "0.00000000"], ["84239.10000000", "0.00119000"], ["84248.10000000", "0.00000000"], ["84248.37000000", "0.00000000"], ["84249.39000000", "0.00000000"], ["84251.41000000", "0.00000000"], ["84252.21000000", "0.00000000"], ["84254.55000000", "0.00000000"], ["84254.56000000", "0.00119000"], ["84256.32000000", "0.01000000"], ["84266.84000000", "0.00000000"], ["84283.90000000", "0.00000000"], ["84296.56000000", "0.00000000"], ["84346.55000000", "0.07527000"], ["84352.36000000", "0.07527000"], ["84357.38000000", "0.05136000"], ["84358.81000000", "0.99890000"], ["84360.76000000", "0.00000000"], ["84363.93000000", "0.00000000"], ["84705.59000000", "0.00000000"], ["84705.60000000", "0.00117000"], ["84739.20000000", "0.05956000"], ["85299.80000000", "0.00000000"], ["85327.80000000", "0.00000000"], ["85330.42000000", "0.00000000"], ["85349.10000000", "0.11735000"], ["85350.99000000", "0.10006000"]], "record_time": 1742584893.12868, "EXCHANGE": "BINANCE"}
{"e": "depthUpdate", "E": 1742584894014, "s": "BTCUSDT", "U": 64637876222, "u": 64637882182, "b": [["84091.48000000", "3.42211000"], ["84091.47000000", "0.00033000"], ["84091.31000000", "0.00208000"], ["84090.69000000", "2.70845000"], ["84090.68000000", "0.00013000"], ["84090.67000000", "0.00007000"], ["84090.59000000", "0.00007000"], ["84090.37000000", "0.00000000"], ["84090.00000000", "0.02280000"], ["84089.99000000", "0.18001000"], ["84089.82000000", "0.00000000"], ["84089.81000000", "0.01196000"], ["84089.57000000", "0.00000000"], ["84089.56000000", "0.00000000"], ["84089.38000000", "0.00006000"], ["84089.37000000", "1.52914000"], ["84089.32000000", "0.00000000"], ["84089.31000000", "0.07589000"], ["84089.25000000", "0.00000000"], ["84089.24000000", "0.00000000"], ["84089.00000000", "0.00007000"], ["84088.98000000", "0.00000000"], ["84088.83000000", "0.00000000"], ["84088.82000000", "0.00000000"], ["84088.45000000", "0.00000000"], ["84088.44000000", "0.00000000"], ["84088.43000000", "0.00000000"], ["84088.42000000", "0.00594000"], ["84088.37000000", "0.00000000"], ["84088.36000000", "0.00000000"], ["84088.33000000", "0.00000000"], ["84088.32000000", "1.90210000"], ["84088.31000000", "0.00014000"], ["84088.16000000", "0.00000000"], ["84088.14000000", "0.00000000"], ["84088.00000000", "0.02260000"], ["84087.91000000", "0.00000000"], ["84087.09000000", "0.00000000"], ["84086.65000000", "0.00000000"], ["84086.57000000", "0.00000000"], ["84086.38000000", "0.00042000"], ["84086.19000000", "0.11890000"], ["84086.00000000", "0.02260000"], ["84085.61000000", "1.08234000"], ["84085.60000000", "0.04783000"], ["84085.56000000", "0.00000000"], ["84085.45000000", "0.00000000"], ["84085.44000000", "0.24070000"], ["84085.43000000", "0.00000000"], ["84085.27000000", "0.00000000"], ["84085.20000000", "0.00000000"], ["84085.17000000", "0.00000000"], ["84085.16000000", "0.00000000"], ["84085.15000000", "0.00000000"], ["84085.11000000", "0.04000000"], ["84085.05000000", "0.14689000"], ["84084.92000000", "0.00000000"], ["84084.91000000", "0.00000000"], ["84084.87000000", "0.00000000"], ["84084.81000000", "0.00000000"], ["84084.80000000", "0.75660000"], ["84084.79000000", "0.00000000"], ["84084.76000000", "0.00000000"], ["84084.45000000", "0.16280000"], ["84084.00000000", "0.02260000"], ["84083.93000000", "0.00118000"], ["84083.88000000", "0.00000000"], ["84083.87000000", "0.00000000"], ["84083.80000000", "0.00000000"], ["84083.79000000", "0.00000000"], ["84083.78000000", "0.02378000"], ["84083.64000000", "0.35968000"], ["84083.26000000", "0.00000000"], ["84083.13000000", "0.01189000"], ["84083.09000000", "0.00000000"], ["84082.60000000", "0.14275000"], ["84082.39000000", "0.00000000"], ["84082.38000000", "0.05946000"], ["84082.28000000", "0.00000000"], ["84082.27000000", "0.00000000"], ["84082.26000000", "0.08181000"], ["84082.23000000", "0.00000000"], ["84082.20000000", "0.00000000"], ["84082.19000000", "0.00000000"], ["84082.18000000", "0.00000000"], ["84082.00000000", "0.02260000"], ["84081.99000000", "0.00000000"], ["84081.98000000", "0.00000000"], ["84081.82000000", "0.00000000"], ["84081.53000000", "0.00000000"], ["84081.52000000", "0.00000000"], ["84081.45000000", "0.00000000"], ["84081.42000000", "0.00000000"], ["84081.41000000", "0.00000000"], ["84081.40000000", "0.00000000"], ["84081.39000000", "0.00000000"], ["84081.32000000", "0.00000000"], ["84081.31000000", "0.91825000"], ["84081.30000000", "0.00000000"], ["84081.29000000", "0.00000000"], ["84081.28000000", "0.00000000"], ["84081.27000000", "0.00000000"], ["84081.26000000", "0.00000000"], ["84081.23000000", "0.02539000"], ["84081.17000000", "0.00000000"], ["84081.16000000", "0.00000000"], ["84081.15000000", "0.00000000"], ["84081.07000000", "0.00000000"], ["84080.98000000", "0.00013000"], ["84080.97000000", "0.02817000"], ["84080.80000000", "0.00000000"], ["84080.79000000", "0.03578000"], ["84080.69000000", "0.04000000"], ["84080.41000000", "0.00118000"], ["84080.21000000", "0.00000000"], ["84080.07000000", "0.04000000"], ["84080.01000000", "0.00000000"], ["84080.00000000", "0.02266000"], ["84079.85000000", "0.00000000"], ["84079.70000000", "0.00000000"], ["84079.65000000", "0.00000000"], ["84079.64000000", "0.17899000"], ["84079.63000000", "0.00000000"], ["84079.62000000", "0.00000000"], ["84079.61000000", "0.03578000"], ["84079.17000000", "0.11892000"], ["84079.10000000", "0.00951000"], ["84079.01000000", "0.00000000"], ["84078.99000000", "0.04000000"], ["84078.94000000", "0.04000000"], ["84078.90000000", "0.85674000"], ["84078.89000000", "0.03578000"], ["84078.88000000", "0.00000000"], ["84078.87000000", "0.00013000"], ["84078.75000000", "0.00006000"], ["84078.19000000", "0.00000000"], ["84078.09000000", "0.00000000"], ["84078.08000000", "0.00000000"], ["84078.02000000", "0.00000000"], ["84078.01000000", "0.00000000"], ["84078.00000000", "0.02260000"], ["84077.98000000", "0.00000000"], ["84077.97000000", "0.00000000"], ["84077.96000000", "0.85675000"], ["84077.91000000", "0.71126000"], ["84077.89000000", "0.00000000"], ["84077.88000000", "0.00000000"], ["84077.80000000", "0.52382000"], ["84077.79000000", "0.00000000"], ["84077.78000000", "0.00000000"], ["84077.77000000", "0.48578000"], ["84077.76000000", "0.00000000"], ["84077.75000000", "0.00000000"], ["84077.74000000", "0.00000000"], ["84077.63000000", "0.00000000"], ["84077.62000000", "0.00000000"], ["84077.59000000", "0.00000000"], ["84077.32000000", "0.00000000"], ["84077.01000000", "0.35662000"], ["84076.43000000", "0.00000000"], ["84076.33000000", "0.00000000"], ["84076.32000000", "0.00000000"], ["84076.20000000", "0.00000000"], ["84076.19000000", "0.00000000"], ["84076.11000000", "0.00000000"], ["84076.10000000", "0.00000000"], ["84076.09000000", "0.00000000"], ["84076.08000000", "0.22113000"], ["84076.07000000", "0.00000000"], ["84076.00000000", "0.02260000"], ["84075.77000000", "0.59477000"], ["84075.76000000", "0.00000000"], ["84075.74000000", "0.00889000"], ["84075.72000000", "0.00000000"], ["84075.65000000", "0.04000000"], ["84075.60000000", "0.00006000"], ["84075.59000000", "0.00502000"], ["84075.58000000", "0.00000000"], ["84075.51000000", "0.00000000"], ["84075.50000000", "0.00000000"], ["84075.49000000", "0.00000000"], ["84075.48000000", "0.00000000"], ["84075.33000000", "0.00000000"], ["84075.32000000", "0.00000000"], ["84075.27000000", "0.00000000"], ["84075.24000000", "0.00000000"], ["84074.93000000", "0.04000000"], ["84074.80000000", "0.00009000"], ["84074.74000000", "0.04000000"], ["84074.69000000", "0.10603000"], ["84074.66000000", "0.00000000"], ["84074.65000000", "0.00059000"], ["84074.44000000", "0.00013000"], ["84074.30000000", "0.02378000"], ["84074.21000000", "0.00000000"], ["84074.15000000", "0.32147000"], ["84074.01000000", "0.00000000"], ["84074.00000000", "0.02260000"], ["84073.83000000", "0.00000000"], ["84073.82000000", "0.00301000"], ["84073.81000000", "0.00000000"], ["84073.80000000", "0.00500000"], ["84073.71000000", "0.00006000"], ["84073.70000000", "0.00000000"], ["84073.30000000", "0.00000000"], ["84073.28000000", "0.00013000"], ["84073.23000000", "0.01189000"], ["84073.00000000", "0.00300000"], ["84072.97000000", "0.00000000"], ["84072.92000000", "0.00000000"], ["84072.86000000", "0.00000000"], ["84072.84000000", "0.08354000"], ["84072.83000000", "0.71126000"], ["84072.82000000", "0.89155000"], ["84072.70000000", "0.90743000"], ["84072.56000000", "0.89155000"], ["84072.53000000", "0.00000000"], ["84072.41000000", "0.04000000"], ["84072.20000000", "0.00000000"], ["84072.01000000", "0.00000000"], ["84071.99000000", "0.85681000"], ["84071.82000000", "0.05943000"], ["84071.42000000", "0.05947000"], ["84071.40000000", "0.00006000"], ["84071.17000000", "0.00000000"], ["84070.90000000", "0.00000000"], ["84070.80000000", "0.00013000"], ["84070.72000000", "0.04000000"], ["84070.71000000", "0.04000000"], ["84070.67000000", "0.30185000"], ["84070.62000000", "0.00594000"], ["84070.52000000", "0.89155000"], ["84070.42000000", "0.03578000"], ["84070.36000000", "0.00000000"], ["84070.29000000", "0.00000000"], ["84070.19000000", "0.00000000"], ["84070.17000000", "0.11892000"], ["84070.13000000", "0.00000000"], ["84069.74000000", "0.11892000"], ["84069.45000000", "0.00000000"], ["84069.39000000", "0.17899000"], ["84069.38000000", "0.77238000"], ["84069.37000000", "0.00000000"], ["84069.36000000", "0.48845000"], ["84069.17000000", "0.00000000"], ["84068.90000000", "0.00000000"], ["84068.76000000", "0.00000000"], ["84068.75000000", "0.05947000"], ["84068.74000000", "0.00000000"], ["84068.45000000", "0.00000000"], ["84068.44000000", "0.00000000"], ["84068.39000000", "0.00000000"], ["84068.15000000", "0.85685000"], ["84068.06000000", "0.00000000"], ["84068.00000000", "0.00010000"], ["84067.98000000", "0.00000000"], ["84067.91000000", "0.00000000"], ["84067.47000000", "0.00013000"], ["84067.46000000", "0.71126000"], ["84067.20000000", "0.00006000"], ["84066.68000000", "0.00000000"], ["84066.39000000", "0.00000000"], ["84066.38000000", "0.05955000"], ["84066.16000000", "0.00000000"], ["84066.08000000", "0.00594000"], ["84065.94000000", "0.00000000"], ["84065.93000000", "0.00000000"], ["84065.70000000", "0.00000000"], ["84065.09000000", "0.00000000"], ["84065.01000000", "0.00357000"], ["84064.80000000", "0.00000000"], ["84064.63000000", "0.20189000"], ["84064.59000000", "0.89155000"], ["84064.50000000", "0.00000000"], ["84064.23000000", "0.00000000"], ["84064.18000000", "0.00000000"], ["84064.00000000", "0.00010000"], ["84063.82000000", "0.00000000"], ["84063.69000000", "0.00000000"], ["84063.41000000", "0.00000000"], ["84063.35000000", "0.00000000"], ["84063.22000000", "0.54764000"], ["84063.20000000", "0.00000000"], ["84062.89000000", "0.00000000"], ["84062.88000000", "0.00000000"], ["84062.71000000", "0.00000000"], ["84062.68000000", "0.04628000"], ["84062.50000000", "0.00000000"], ["84062.08000000", "0.00059000"], ["84061.78000000", "0.00584000"], ["84061.50000000", "0.00000000"], ["84061.27000000", "0.00000000"], ["84060.99000000", "0.00016000"], ["84060.73000000", "0.00000000"], ["84060.72000000", "0.00000000"], ["84060.66000000", "0.34972000"], ["84060.65000000", "0.00000000"], ["84060.60000000", "0.00000000"], ["84060.19000000", "0.00000000"], ["84060.04000000", "0.13418000"], ["84059.94000000", "0.00000000"], ["84059.81000000", "0.00000000"], ["84058.76000000", "0.00000000"], ["84058.75000000", "0.00000000"], ["84058.58000000", "0.00006000"], ["84058.51000000", "0.00000000"], ["84057.94000000", "0.04000000"], ["84057.61000000", "0.00000000"], ["84057.35000000", "0.00000000"], ["84057.21000000", "0.00000000"], ["84057.05000000", "0.00000000"], ["84057.02000000", "0.00000000"], ["84056.93000000", "0.20189000"], ["84056.82000000", "0.00000000"], ["84056.52000000", "0.00000000"], ["84056.46000000", "0.00000000"], ["84055.66000000", "0.60618000"], ["84055.65000000", "0.00000000"], ["84055.48000000", "0.17841000"], ["84054.24000000", "0.00000000"], ["84053.67000000", "0.11476000"], ["84053.17000000", "0.00000000"], ["84052.82000000", "0.00000000"], ["84052.75000000", "0.00059000"], ["84052.35000000", "0.00000000"], ["84052.34000000", "0.00000000"], ["84052.31000000", "0.00000000"], ["84052.04000000", "0.20192000"], ["84051.78000000", "0.39427000"], ["84051.30000000", "0.00000000"], ["84051.19000000", "0.00358000"], ["84050.81000000", "0.00000000"], ["84050.70000000", "0.00000000"], ["84050.61000000", "0.00000000"], ["84050.54000000", "0.00000000"], ["84050.51000000", "0.88844000"], ["84050.44000000", "0.00000000"], ["84050.27000000", "0.05946000"], ["84049.17000000", "0.03202000"], ["84048.98000000", "0.00000000"], ["84048.80000000", "0.21485000"], ["84048.74000000", "0.30853000"], ["84048.47000000", "0.00000000"], ["84047.44000000", "0.27452000"], ["84047.33000000", "0.04000000"], ["84047.18000000", "0.00000000"], ["84046.92000000", "0.00000000"], ["84046.91000000", "0.00000000"], ["84046.73000000", "0.05796000"], ["84046.62000000", "0.05277000"], ["84046.20000000", "0.03030000"], ["84046.18000000", "0.00000000"], ["84045.30000000", "0.00000000"], ["84045.16000000", "0.00000000"], ["84044.16000000", "0.44818000"], ["84044.15000000", "0.71126000"], ["84044.13000000", "0.00000000"], ["84043.82000000", "0.00000000"], ["84043.47000000", "0.16503000"], ["84043.40000000", "0.00000000"], ["84043.19000000", "0.00146000"], ["84043.13000000", "0.04000000"], ["84042.80000000", "0.00000000"], ["84042.11000000", "0.00358000"], ["84041.46000000", "0.00000000"], ["84041.30000000", "0.00000000"], ["84040.73000000", "0.05508000"], ["84040.04000000", "0.13996000"], ["84039.37000000", "0.00000000"], ["84038.46000000", "0.00000000"], ["84038.04000000", "0.47549000"], ["84036.98000000", "0.00000000"], ["84035.72000000", "0.00000000"], ["84034.37000000", "0.00000000"], ["84034.36000000", "0.00000000"], ["84034.33000000", "0.00000000"], ["84034.05000000", "0.00000000"], ["84033.60000000", "0.00006000"], ["84033.56000000", "0.00400000"], ["84032.52000000", "0.00000000"], ["84030.32000000", "0.17899000"], ["84029.91000000", "0.09640000"], ["84027.58000000", "0.00000000"], ["84027.30000000", "0.00000000"], ["84027.28000000", "0.00000000"], ["84026.93000000", "0.00850000"], ["84026.82000000", "0.00272000"], ["84026.66000000", "0.11869000"], ["84026.37000000", "0.00060000"], ["84026.13000000", "0.00822000"], ["84025.71000000", "0.00000000"], ["84025.56000000", "0.00000000"], ["84024.85000000", "0.00040000"], ["84024.84000000", "0.00040000"], ["84024.62000000", "0.00000000"], ["84024.01000000", "0.00296000"], ["84023.95000000", "0.00000000"], ["84023.87000000", "0.02900000"], ["84023.38000000", "0.10000000"], ["84022.13000000", "0.00000000"], ["84021.78000000", "0.00000000"], ["84021.30000000", "0.41595000"], ["84019.64000000", "0.05000000"], ["84019.01000000", "0.04000000"], ["84017.44000000", "0.00000000"], ["84015.16000000", "0.85976000"], ["84014.77000000", "0.00000000"], ["84014.56000000", "0.04000000"], ["84014.51000000", "0.00000000"], ["84013.74000000", "0.00000000"], ["84012.97000000", "0.00000000"], ["84012.95000000", "0.00000000"], ["84012.51000000", "0.00297000"], ["84011.29000000", "0.00000000"], ["84010.00000000", "0.00000000"], ["84008.73000000", "0.00000000"], ["84008.48000000", "0.00000000"], ["84007.99000000", "0.02854000"], ["84007.85000000", "0.00000000"], ["84006.62000000", "0.12900000"], ["84006.58000000", "0.13200000"], ["84004.67000000", "0.00000000"], ["84001.74000000", "0.00000000"], ["84001.27000000", "0.00000000"], ["84001.04000000", "0.04637000"], ["84000.92000000", "0.00000000"], ["84000.74000000", "0.04000000"], ["84000.61000000", "0.00000000"], ["83999.99000000", "0.00000000"], ["83999.76000000", "0.00000000"], ["83999.00000000", "0.00000000"], ["83996.96000000", "0.46544000"], ["83996.95000000", "1.02861000"], ["83996.44000000", "0.00000000"], ["83995.69000000", "0.00000000"], ["83994.14000000", "0.01196000"], ["83993.08000000", "0.00000000"], ["83993.00000000", "0.00000000"], ["83992.80000000", "0.00000000"], ["83989.25000000", "1.29004000"], ["83988.48000000", "0.30553000"], ["83987.75000000", "0.00000000"], ["83987.52000000", "0.00000000"], ["83984.49000000", "0.00000000"], ["83984.04000000", "0.00000000"], ["83979.97000000", "0.43566000"], ["83978.24000000", "0.00013000"], ["83975.71000000", "0.00000000"], ["83972.98000000", "0.00000000"], ["83971.67000000", "0.00000000"], ["83960.86000000", "0.00000000"], ["83959.14000000", "0.00000000"], ["83950.95000000", "0.00314000"], ["83945.11000000", "0.12000000"], ["83940.01000000", "0.00000000"], ["83937.49000000", "0.00000000"], ["83936.65000000", "0.00000000"], ["83934.13000000", "0.00000000"], ["83933.87000000", "0.00000000"], ["83930.24000000", "0.01000000"], ["83928.25000000", "0.00000000"], ["83927.55000000", "0.00000000"], ["83926.95000000", "0.00000000"], ["83926.05000000", "0.00000000"], ["83925.86000000", "0.00000000"], ["83925.67000000", "0.00000000"], ["83915.57000000", "0.00000000"], ["83915.06000000", "0.99313000"], ["83901.91000000", "0.00000000"], ["83857.51000000", "0.00000000"], ["83856.35000000", "0.20067000"], ["83853.62000000", "0.00000000"], ["83852.84000000", "0.00000000"], ["83849.07000000", "0.00000000"], ["83847.95000000", "0.00000000"], ["83846.23000000", "0.20189000"], ["83845.79000000", "0.00000000"], ["83844.44000000", "0.00000000"], ["83844.19000000", "0.00000000"], ["83840.67000000", "0.00000000"], ["83839.55000000", "0.00000000"], ["83839.23000000", "0.00000000"], ["83837.83000000", "0.00817000"], ["83837.38000000", "0.00000000"], ["83836.26000000", "0.00000000"], ["83836.05000000", "0.00000000"], ["83833.64000000", "0.00000000"], ["83832.52000000", "0.00000000"], ["83832.06000000", "0.00000000"], ["83831.15000000", "0.00000000"], ["83830.83000000", "0.00000000"], ["83827.86000000", "0.00000000"], ["83827.65000000", "0.00000000"], ["83824.12000000", "0.00000000"], ["83822.43000000", "0.00000000"], ["83736.89000000", "0.00040000"], ["83736.85000000", "0.00000000"], ["83393.00000000", "0.00000000"], ["83197.20000000", "2.30488000"], ["83084.16000000", "0.00040000"], ["83084.05000000", "0.00000000"], ["83069.99000000", "0.00000000"], ["82808.31000000", "0.00000000"], ["80697.27000000", "0.00000000"], ["75675.00000000", "0.00062000"], ["75674.00000000", "0.00000000"], ["75672.00000000", "0.00877000"], ["75671.00000000", "0.00000000"], ["75668.00000000", "0.13247000"], ["75662.00000000", "0.00182000"], ["67273.19000000", "0.00058000"], ["67265.13000000", "0.00000000"], ["67260.87000000", "0.00000000"], ["50001.00000000", "1.81897000"], ["42000.00000000", "6.84810000"], ["33000.00000000", "2.93827000"]], "a": [["84076.09000000", "0.00000000"], ["84076.10000000", "0.00000000"], ["84076.33000000", "0.00000000"], ["84077.63000000", "0.00000000"], ["84077.64000000", "0.00000000"], ["84077.77000000", "0.00000000"], ["84077.78000000", "0.00000000"], ["84077.79000000", "0.00000000"], ["84077.98000000", "0.00000000"], ["84078.02000000", "0.00000000"], ["84078.20000000", "0.00000000"], ["84078.88000000", "0.00000000"], ["84078.89000000", "0.00000000"], ["84078.90000000", "0.00000000"], ["84078.91000000", "0.00000000"], ["84079.24000000", "0.00000000"], ["84079.62000000", "0.00000000"], ["84079.63000000", "0.00000000"], ["84079.64000000", "0.00000000"], ["84079.71000000", "0.00000000"], ["84079.80000000", "0.00000000"], ["84079.86000000", "0.00000000"], ["84079.99000000", "0.00000000"], ["84080.00000000", "0.00000000"], ["84080.45000000", "0.00000000"], ["84080.80000000", "0.00000000"], ["84080.81000000", "0.00000000"], ["84080.86000000", "0.00000000"], ["84080.87000000", "0.00000000"], ["84080.88000000", "0.00000000"], ["84081.08000000", "0.00000000"], ["84081.16000000", "0.00000000"], ["84081.17000000", "0.00000000"], ["84081.31000000", "0.00000000"], ["84081.32000000", "0.00000000"], ["84081.33000000", "0.00000000"], ["84081.34000000", "0.00000000"], ["84081.40000000", "0.00000000"], ["84081.41000000", "0.00000000"], ["84081.42000000", "0.00000000"], ["84081.43000000", "0.00000000"], ["84081.50000000", "0.00000000"], ["84081.87000000", "0.00000000"], ["84081.99000000", "0.00000000"], ["84082.00000000", "0.00000000"], ["84082.01000000", "0.00000000"], ["84082.09000000", "0.00000000"], ["84082.11000000", "0.00000000"], ["84082.12000000", "0.00000000"], ["84082.19000000", "0.00000000"], ["84082.20000000", "0.00000000"], ["84082.21000000", "0.00000000"], ["84082.24000000", "0.00000000"], ["84082.27000000", "0.00000000"], ["84082.30000000", "0.00000000"], ["84082.37000000", "0.00000000"], ["84082.47000000", "0.00000000"], ["84082.70000000", "0.00000000"], ["84082.85000000", "0.00000000"], ["84083.08000000", "0.00000000"], ["84083.10000000", "0.00000000"], ["84083.11000000", "0.00000000"], ["84083.20000000", "0.00000000"], ["84083.52000000", "0.00000000"], ["84083.79000000", "0.00000000"], ["84083.80000000", "0.00000000"], ["84083.86000000", "0.00000000"], ["84083.87000000", "0.00000000"], ["84083.88000000", "0.00000000"], ["84083.89000000", "0.00000000"], ["84084.00000000", "0.00000000"], ["84084.30000000", "0.00000000"], ["84084.47000000", "0.00000000"], ["84084.50000000", "0.00000000"], ["84084.76000000", "0.00000000"], ["84084.77000000", "0.00000000"], ["84084.80000000", "0.00000000"], ["84084.81000000", "0.00000000"], ["84084.82000000", "0.00000000"], ["84084.88000000", "0.00000000"], ["84084.89000000", "0.00000000"], ["84085.16000000", "0.00000000"], ["84085.17000000", "0.00000000"], ["84085.18000000", "0.00000000"], ["84085.44000000", "0.00000000"], ["84085.45000000", "0.00000000"], ["84085.48000000", "0.00000000"], ["84085.49000000", "0.00000000"], ["84085.61000000", "0.00000000"], ["84085.90000000", "0.00000000"], ["84085.92000000", "0.00000000"], ["84085.94000000", "0.00000000"], ["84086.07000000", "0.00000000"], ["84086.14000000", "0.00000000"], ["84086.28000000", "0.00000000"], ["84086.31000000", "0.00000000"], ["84086.45000000", "0.00000000"], ["84086.46000000", "0.00000000"], ["84086.58000000", "0.00000000"], ["84086.80000000", "0.00000000"], ["84086.97000000", "0.00000000"], ["84086.98000000", "0.00000000"], ["84087.06000000", "0.00000000"], ["84087.16000000", "0.00000000"], ["84087.20000000", "0.00000000"], ["84087.21000000", "0.00000000"], ["84087.23000000", "0.00000000"], ["84087.30000000", "0.00000000"], ["84087.35000000", "0.00000000"], ["84087.36000000", "0.00000000"], ["84087.57000000", "0.00000000"], ["84087.83000000", "0.00000000"], ["84088.00000000", "0.00000000"], ["84088.01000000", "0.00000000"], ["84088.05000000", "0.00000000"], ["84088.15000000", "0.00000000"], ["84088.20000000", "0.00000000"], ["84088.32000000", "0.00000000"], ["84088.33000000", "0.00000000"], ["84088.34000000", "0.00000000"], ["84088.37000000", "0.00000000"], ["84088.38000000", "0.00000000"], ["84088.40000000", "0.00000000"], ["84088.45000000", "0.00000000"], ["84088.46000000", "0.00000000"], ["84088.53000000", "0.00000000"], ["84088.54000000", "0.00000000"], ["84088.83000000", "0.00000000"], ["84088.84000000", "0.00000000"], ["84088.99000000", "0.00000000"], ["84089.00000000", "0.00000000"], ["84089.17000000", "0.00000000"], ["84089.18000000", "0.00000000"], ["84089.25000000", "0.00000000"], ["84089.26000000", "0.00000000"], ["84089.28000000", "0.00000000"], ["84089.31000000", "0.00000000"], ["84089.32000000", "0.00000000"], ["84089.35000000", "0.00000000"], ["84089.38000000", "0.00000000"], ["84089.57000000", "0.00000000"], ["84089.58000000", "0.00000000"], ["84089.75000000", "0.00000000"], ["84089.83000000", "0.00000000"], ["84090.00000000", "0.00000000"], ["84090.28000000", "0.00000000"], ["84090.29000000", "0.00000000"], ["84090.31000000", "0.00000000"], ["84090.40000000", "0.00000000"], ["84090.45000000", "0.00000000"], ["84090.50000000", "0.00000000"], ["84090.60000000", "0.00000000"], ["84090.63000000", "0.00000000"], ["84090.67000000", "0.00000000"], ["84090.68000000", "0.00000000"], ["84090.69000000", "0.00000000"], ["84090.71000000", "0.00000000"], ["84090.86000000", "0.00000000"], ["84091.23000000", "0.00000000"], ["84091.29000000", "0.00000000"], ["84091.30000000", "0.00000000"], ["84091.34000000", "0.00000000"], ["84091.36000000", "0.00000000"], ["84091.49000000", "0.00163000"], ["84091.50000000", "0.00035000"], ["84091.55000000", "0.00000000"], ["84091.56000000", "0.00000000"], ["84091.59000000", "0.00020000"], ["84091.77000000", "0.00000000"], ["84091.88000000", "0.00000000"], ["84091.92000000", "0.00208000"], ["84091.98000000", "0.00021000"], ["84091.99000000", "0.01337000"], ["84092.07000000", "0.00000000"], ["84092.20000000", "0.00000000"], ["84092.21000000", "0.00000000"], ["84092.27000000", "0.00000000"], ["84092.28000000", "0.00000000"], ["84092.29000000", "0.00000000"], ["84092.31000000", "0.00000000"], ["84092.32000000", "0.00000000"], ["84092.34000000", "0.00000000"], ["84092.38000000", "0.00021000"], ["84092.39000000", "0.00643000"], ["84092.40000000", "0.00000000"], ["84092.47000000", "0.00000000"], ["84092.58000000", "0.00000000"], ["84092.65000000", "0.00000000"], ["84092.71000000", "0.00000000"], ["84092.80000000", "0.00000000"], ["84092.85000000", "0.00000000"], ["84092.87000000", "0.00000000"], ["84092.89000000", "0.00000000"], ["84092.91000000", "0.00000000"], ["84092.92000000", "0.00000000"], ["84092.93000000", "0.00000000"], ["84093.05000000", "0.00014000"], ["84093.06000000", "0.01797000"], ["84093.08000000", "0.00000000"], ["84093.09000000", "0.00000000"], ["84093.19000000", "0.00000000"], ["84093.39000000", "0.00000000"], ["84093.51000000", "0.00000000"], ["84093.57000000", "0.00000000"], ["84093.67000000", "0.00000000"], ["84093.79000000", "0.00000000"], ["84093.87000000", "0.00000000"], ["84093.91000000", "0.00000000"], ["84094.07000000", "0.00000000"], ["84094.13000000", "0.00000000"], ["84094.30000000", "0.00000000"], ["84094.48000000", "0.00000000"], ["84094.51000000", "0.00014000"], ["84094.52000000", "0.02220000"], ["84094.58000000", "0.01180000"], ["84094.59000000", "0.00029000"], ["84094.60000000", "0.00000000"], ["84094.78000000", "0.00000000"], ["84094.90000000", "0.00007000"], ["84095.02000000", "0.00000000"], ["84095.04000000", "0.00000000"], ["84095.22000000", "0.00000000"], ["84095.25000000", "0.00000000"], ["84095.26000000", "0.00000000"], ["84095.31000000", "0.00000000"], ["84095.33000000", "0.00000000"], ["84095.34000000", "0.00019000"], ["84095.35000000", "0.14619000"], ["84095.47000000", "0.00000000"], ["84095.72000000", "0.00000000"], ["84095.86000000", "0.00000000"], ["84095.99000000", "0.00000000"], ["84096.04000000", "0.00000000"], ["84096.15000000", "0.00000000"], ["84096.22000000", "0.00000000"], ["84096.29000000", "0.05946000"], ["84096.31000000", "0.00000000"], ["84096.40000000", "0.00000000"], ["84096.44000000", "0.00000000"], ["84096.48000000", "0.00000000"], ["84096.51000000", "0.00000000"], ["84096.55000000", "0.00000000"], ["84096.68000000", "0.00000000"], ["84096.77000000", "0.00000000"], ["84096.80000000", "0.00000000"], ["84096.88000000", "0.00000000"], ["84096.99000000", "0.00000000"], ["84097.04000000", "0.00000000"], ["84097.13000000", "0.00000000"], ["84097.14000000", "0.00301000"], ["84097.74000000", "0.00118000"], ["84097.84000000", "0.00000000"], ["84098.13000000", "0.00000000"], ["84098.19000000", "0.00000000"], ["84098.21000000", "0.00000000"], ["84098.24000000", "0.00000000"], ["84098.38000000", "0.00000000"], ["84098.42000000", "0.00000000"], ["84098.48000000", "0.00000000"], ["84098.49000000", "0.00000000"], ["84098.84000000", "0.00000000"], ["84098.93000000", "0.00000000"], ["84098.94000000", "0.00000000"], ["84099.12000000", "0.00000000"], ["84099.27000000", "0.02170000"], ["84099.41000000", "0.00000000"], ["84099.42000000", "0.01489000"], ["84099.55000000", "0.00000000"], ["84099.59000000", "0.00000000"], ["84099.81000000", "0.00000000"], ["84100.09000000", "0.00000000"], ["84100.17000000", "0.00000000"], ["84100.31000000", "0.01500000"], ["84100.37000000", "0.00000000"], ["84100.39000000", "0.00000000"], ["84100.48000000", "0.01500000"], ["84100.55000000", "0.00000000"], ["84100.59000000", "0.00000000"], ["84100.61000000", "0.00000000"], ["84100.68000000", "0.06392000"], ["84100.69000000", "0.00000000"], ["84100.71000000", "0.00000000"], ["84100.74000000", "0.00000000"], ["84100.86000000", "0.00000000"], ["84101.08000000", "0.00000000"], ["84101.23000000", "0.00007000"], ["84101.34000000", "0.00000000"], ["84101.41000000", "0.00000000"], ["84101.42000000", "0.00000000"], ["84101.43000000", "0.00000000"], ["84101.49000000", "0.00000000"], ["84101.85000000", "0.00000000"], ["84102.04000000", "0.00000000"], ["84102.22000000", "0.00000000"], ["84102.29000000", "0.00000000"], ["84102.33000000", "0.00000000"], ["84102.55000000", "0.00000000"], ["84102.58000000", "0.00000000"], ["84102.64000000", "0.00000000"], ["84102.86000000", "0.04400000"], ["84102.97000000", "0.00000000"], ["84102.98000000", "0.00000000"], ["84103.00000000", "0.00000000"], ["84103.06000000", "0.00000000"], ["84103.30000000", "0.00000000"], ["84103.35000000", "0.00000000"], ["84103.52000000", "0.00000000"], ["84103.55000000", "0.00000000"], ["84103.56000000", "0.00000000"], ["84103.59000000", "0.00000000"], ["84103.79000000", "0.00000000"], ["84104.00000000", "0.00118000"], ["84104.03000000", "0.00000000"], ["84104.25000000", "0.00000000"], ["84104.26000000", "0.38730000"], ["84104.27000000", "0.00000000"], ["84104.29000000", "0.00000000"], ["84104.30000000", "0.00000000"], ["84104.37000000", "0.00007000"], ["84104.44000000", "0.00000000"], ["84104.60000000", "0.04800000"], ["84104.72000000", "0.00091000"], ["84104.78000000", "0.00095000"], ["84104.82000000", "0.00000000"], ["84104.89000000", "0.02000000"], ["84104.91000000", "0.00000000"], ["84105.07000000", "0.00000000"], ["84105.15000000", "0.00000000"], ["84105.43000000", "0.00000000"], ["84105.61000000", "0.00000000"], ["84105.72000000", "0.00000000"], ["84105.75000000", "0.00000000"], ["84105.95000000", "0.16344000"], ["84106.02000000", "0.17899000"], ["84106.03000000", "0.01189000"], ["84106.16000000", "0.00000000"], ["84106.53000000", "0.00000000"], ["84106.59000000", "0.00000000"], ["84106.65000000", "0.00300000"], ["84106.68000000", "0.00000000"], ["84106.81000000", "0.00000000"], ["84106.89000000", "0.12000000"], ["84106.93000000", "0.00000000"], ["84107.06000000", "0.00000000"], ["84107.27000000", "0.00720000"], ["84107.28000000", "0.00000000"], ["84107.45000000", "0.00000000"], ["84107.49000000", "0.00000000"], ["84107.50000000", "0.00000000"], ["84107.55000000", "0.00007000"], ["84107.67000000", "0.00000000"], ["84107.71000000", "0.00000000"], ["84107.83000000", "0.54816000"], ["84107.84000000", "0.59437000"], ["84107.91000000", "0.05600000"], ["84107.96000000", "0.00000000"], ["84108.06000000", "0.00000000"], ["84108.19000000", "0.00000000"], ["84108.26000000", "0.00000000"], ["84108.45000000", "0.14160000"], ["84108.69000000", "0.00000000"], ["84109.15000000", "0.89155000"], ["84109.33000000", "0.00000000"], ["84109.36000000", "0.00000000"], ["84109.60000000", "0.00000000"], ["84109.78000000", "0.00000000"], ["84110.03000000", "0.00000000"], ["84110.46000000", "0.00000000"], ["84110.51000000", "0.35662000"], ["84110.65000000", "0.00000000"], ["84110.76000000", "0.00000000"], ["84110.83000000", "0.00000000"], ["84110.84000000", "0.00000000"], ["84110.93000000", "0.00000000"], ["84110.96000000", "0.00000000"], ["84111.16000000", "0.32077000"], ["84111.40000000", "0.08000000"], ["84111.57000000", "0.00000000"], ["84111.70000000", "0.00000000"], ["84111.83000000", "0.04000000"], ["84111.88000000", "0.00000000"], ["84111.92000000", "0.00000000"], ["84112.05000000", "0.00000000"], ["84112.16000000", "0.00000000"], ["84112.22000000", "0.89155000"], ["84112.46000000", "0.00000000"], ["84112.52000000", "0.00000000"], ["84112.64000000", "0.78503000"], ["84112.98000000", "0.76163000"], ["84112.99000000", "0.89155000"], ["84113.24000000", "0.00000000"], ["84113.30000000", "0.00000000"], ["84113.31000000", "0.00000000"], ["84113.37000000", "0.00000000"], ["84113.55000000", "0.00000000"], ["84113.65000000", "0.00000000"], ["84113.66000000", "0.89155000"], ["84113.78000000", "0.00000000"], ["84113.79000000", "0.00000000"], ["84113.86000000", "1.54433000"], ["84114.21000000", "0.00000000"], ["84114.23000000", "0.05943000"], ["84114.60000000", "0.00000000"], ["84114.67000000", "0.01189000"], ["84114.94000000", "0.00000000"], ["84115.16000000", "0.00000000"], ["84115.64000000", "0.00000000"], ["84116.61000000", "0.00000000"], ["84116.81000000", "0.00000000"], ["84117.07000000", "0.00000000"], ["84117.36000000", "0.00000000"], ["84117.38000000", "0.00000000"], ["84117.64000000", "0.00000000"], ["84117.70000000", "0.89155000"], ["84117.76000000", "0.05943000"], ["84117.81000000", "0.00000000"], ["84118.13000000", "0.00000000"], ["84118.44000000", "0.00000000"], ["84118.71000000", "0.00000000"], ["84119.11000000", "0.00006000"], ["84119.32000000", "0.00000000"], ["84119.92000000", "0.00151000"], ["84120.26000000", "0.00013000"], ["84120.29000000", "0.00000000"], ["84120.45000000", "0.00000000"], ["84120.54000000", "0.00000000"], ["84121.04000000", "0.00237000"], ["84121.05000000", "0.31813000"], ["84121.06000000", "0.30852000"], ["84121.13000000", "0.89155000"], ["84121.36000000", "0.89155000"], ["84122.41000000", "0.01674000"], ["84122.78000000", "0.00000000"], ["84122.85000000", "0.00000000"], ["84123.01000000", "0.00000000"], ["84123.44000000", "0.37693000"], ["84123.47000000", "0.00000000"], ["84124.09000000", "0.00000000"], ["84124.49000000", "0.00356000"], ["84124.80000000", "0.00016000"], ["84125.06000000", "0.00000000"], ["84125.25000000", "0.00000000"], ["84125.99000000", "0.00000000"], ["84126.40000000", "0.00000000"], ["84126.74000000", "0.00000000"], ["84126.75000000", "0.00000000"], ["84126.97000000", "0.00000000"], ["84127.21000000", "0.00000000"], ["84127.28000000", "0.00000000"], ["84127.70000000", "0.00000000"], ["84127.93000000", "0.00000000"], ["84128.06000000", "0.00907000"], ["84128.45000000", "0.00000000"], ["84128.46000000", "0.00000000"], ["84128.66000000", "0.00000000"], ["84128.78000000", "0.00000000"], ["84129.21000000", "0.17899000"], ["84129.32000000", "0.35788000"], ["84130.56000000", "0.00000000"], ["84130.83000000", "0.00000000"], ["84130.91000000", "0.00000000"], ["84130.92000000", "0.00000000"], ["84130.97000000", "0.35662000"], ["84131.24000000", "0.89155000"], ["84131.82000000", "0.11513000"], ["84132.19000000", "0.00000000"], ["84132.31000000", "0.03676000"], ["84132.45000000", "0.00100000"], ["84132.57000000", "0.00587000"], ["84132.94000000", "0.00000000"], ["84133.52000000", "0.28237000"], ["84133.59000000", "0.00000000"], ["84134.22000000", "0.05857000"], ["84134.67000000", "0.39281000"], ["84134.76000000", "0.00000000"], ["84134.86000000", "0.00000000"], ["84135.65000000", "0.00100000"], ["84136.29000000", "0.89155000"], ["84136.38000000", "0.00000000"], ["84136.60000000", "0.85616000"], ["84136.68000000", "0.00000000"], ["84137.03000000", "0.00000000"], ["84137.59000000", "0.05000000"], ["84137.91000000", "0.00000000"], ["84138.09000000", "0.02814000"], ["84138.19000000", "0.89155000"], ["84138.24000000", "0.00000000"], ["84138.45000000", "0.89155000"], ["84139.07000000", "0.00000000"], ["84139.67000000", "0.30891000"], ["84140.19000000", "0.59477000"], ["84140.54000000", "0.00000000"], ["84140.97000000", "0.00000000"], ["84141.29000000", "0.00000000"], ["84141.31000000", "0.30852000"], ["84141.32000000", "0.38480000"], ["84141.89000000", "0.00000000"], ["84142.57000000", "0.00817000"], ["84143.56000000", "0.00000000"], ["84143.93000000", "0.03758000"], ["84145.00000000", "0.00000000"], ["84145.62000000", "0.01188000"], ["84146.22000000", "0.55903000"], ["84147.51000000", "0.59437000"], ["84149.67000000", "0.00868000"], ["84151.02000000", "0.00000000"], ["84151.07000000", "0.00818000"], ["84151.42000000", "0.00000000"], ["84153.34000000", "0.00000000"], ["84153.63000000", "0.04371000"], ["84154.86000000", "0.00000000"], ["84154.88000000", "0.00000000"], ["84155.79000000", "0.00000000"], ["84155.80000000", "0.00000000"], ["84158.82000000", "0.00019000"], ["84158.83000000", "0.52310000"], ["84159.02000000", "1.02663000"], ["84160.15000000", "0.04400000"], ["84160.34000000", "0.00297000"], ["84160.35000000", "0.00000000"], ["84161.02000000", "0.00000000"], ["84161.03000000", "0.00000000"], ["84161.23000000", "0.00000000"], ["84161.24000000", "0.00000000"], ["84161.86000000", "0.06400000"], ["84163.69000000", "0.01485000"], ["84164.07000000", "0.00823000"], ["84165.19000000", "0.05600000"], ["84166.11000000", "0.01372000"], ["84166.23000000", "0.00000000"], ["84166.39000000", "0.00000000"], ["84167.14000000", "0.08000000"], ["84167.57000000", "0.00146000"], ["84167.75000000", "0.01953000"], ["84168.05000000", "0.00000000"], ["84169.04000000", "0.06800000"], ["84171.76000000", "0.00151000"], ["84171.77000000", "0.03211000"], ["84172.40000000", "0.00000000"], ["84172.61000000", "0.00000000"], ["84172.66000000", "0.00297000"], ["84172.77000000", "0.42906000"], ["84174.54000000", "0.00000000"], ["84174.87000000", "0.00000000"], ["84174.88000000", "0.06000000"], ["84175.11000000", "0.00000000"], ["84175.40000000", "0.00013000"], ["84175.74000000", "0.09623000"], ["84175.75000000", "0.00000000"], ["84176.32000000", "0.05216000"], ["84179.24000000", "0.00000000"], ["84179.76000000", "0.00000000"], ["84180.34000000", "0.00000000"], ["84180.80000000", "0.00000000"], ["84181.18000000", "0.00000000"], ["84181.56000000", "0.00000000"], ["84182.28000000", "0.00000000"], ["84182.65000000", "0.00000000"], ["84182.91000000", "0.00009000"], ["84183.61000000", "0.00000000"], ["84183.97000000", "0.00000000"], ["84185.39000000", "0.00059000"], ["84185.81000000", "0.00000000"], ["84185.86000000", "0.00000000"], ["84186.15000000", "0.00000000"], ["84187.20000000", "0.10319000"], ["84187.62000000", "0.00000000"], ["84188.18000000", "0.00000000"], ["84189.08000000", "0.00000000"], ["84189.27000000", "0.00000000"], ["84189.37000000", "0.00000000"], ["84194.81000000", "0.04638000"], ["84195.00000000", "0.00000000"], ["84196.82000000", "0.00000000"], ["84197.60000000", "0.12899000"], ["84198.10000000", "0.04638000"], ["84198.40000000", "0.00000000"], ["84200.13000000", "0.00000000"], ["84200.15000000", "0.04638000"], ["84200.64000000", "0.00013000"], ["84206.73000000", "0.01963000"], ["84208.72000000", "0.05297000"], ["84213.72000000", "0.04997000"], ["84214.90000000", "0.05498000"], ["84215.76000000", "0.04998000"], ["84216.46000000", "0.04998000"], ["84216.82000000", "0.04998000"], ["84217.38000000", "0.05498000"], ["84217.59000000", "0.05297000"], ["84217.67000000", "0.05498000"], ["84217.90000000", "0.04498000"], ["84218.33000000", "0.04998000"], ["84218.93000000", "0.04998000"], ["84219.66000000", "0.05497000"], ["84220.28000000", "0.05497000"], ["84220.39000000", "0.05498000"], ["84220.54000000", "0.04998000"], ["84222.88000000", "0.04998000"], ["84223.70000000", "0.04997000"], ["84223.74000000", "0.04498000"], ["84223.87000000", "0.04998000"], ["84224.11000000", "0.05498000"], ["84224.13000000", "0.00000000"], ["84224.75000000", "0.04998000"], ["84227.15000000", "0.04998000"], ["84228.01000000", "0.07424000"], ["84228.31000000", "0.04998000"], ["84228.63000000", "0.04498000"], ["84228.74000000", "0.04198000"], ["84228.90000000", "0.04498000"], ["84229.52000000", "0.01458000"], ["84229.68000000", "0.00000000"], ["84230.76000000", "0.04205000"], ["84231.74000000", "0.01361000"], ["84233.74000000", "0.04498000"], ["84234.13000000", "0.00000000"], ["84234.29000000", "0.00000000"], ["84234.53000000", "0.00016000"], ["84234.54000000", "0.00709000"], ["84234.72000000", "0.04498000"], ["84234.85000000", "0.04498000"], ["84236.02000000", "0.05286000"], ["84238.71000000", "0.00859000"], ["84239.09000000", "0.00000000"], ["84239.10000000", "0.00000000"], ["84240.00000000", "0.02618000"], ["84240.10000000", "0.04198000"], ["84240.32000000", "0.00006000"], ["84241.86000000", "0.04198000"], ["84242.05000000", "0.00000000"], ["84242.87000000", "0.04198000"], ["84245.20000000", "0.04198000"], ["84245.71000000", "0.04198000"], ["84246.62000000", "0.00000000"], ["84248.68000000", "0.01764000"], ["84249.37000000", "0.00000000"], ["84253.11000000", "0.00050000"], ["84254.54000000", "0.00000000"], ["84254.55000000", "0.00118000"], ["84254.56000000", "0.00000000"], ["84254.95000000", "0.21406000"], ["84256.32000000", "0.00000000"], ["84260.33000000", "0.00000000"], ["84262.60000000", "0.00000000"], ["84264.18000000", "0.00000000"], ["84266.45000000", "0.00118000"], ["84266.46000000", "0.00000000"], ["84289.02000000", "0.00000000"], ["84292.78000000", "0.00000000"], ["84297.21000000", "0.00000000"], ["84315.38000000", "0.00000000"], ["84315.39000000", "0.00013000"], ["84319.59000000", "0.00013000"], ["84323.09000000", "0.00013000"], ["84327.29000000", "0.00013000"], ["84354.20000000", "0.07529000"], ["84358.04000000", "0.07524000"], ["84358.81000000", "0.99594000"], ["84362.60000000", "0.12684000"], ["84363.07000000", "0.07505000"], ["84366.72000000", "0.45000000"], ["84374.84000000", "0.12688000"], ["84379.87000000", "0.12746000"], ["84489.18000000", "0.35736000"], ["84559.70000000", "0.00000000"], ["84703.30000000", "0.18231000"], ["85316.86000000", "0.00000000"], ["85342.65000000", "0.00100000"], ["85349.10000000", "0.00000000"], ["85368.06000000", "0.10000000"], ["85391.70000000", "0.00007000"], ["85413.00000000", "0.05900000"], ["150001.00000000", "0.00000000"]], "record_time": 1742584894.129644, "EXCHANGE": "BINANCE"}
