{"e": "depthUpdate", "E": 1742555348014, "s": "BTCUSDT", "U": 64607199428, "u": 64607199702, "b": [["84061.31000000", "5.52452000"], ["84060.01000000", "0.04764000"], ["84059.97000000", "0.05948000"], ["84057.78000000", "0.00058000"], ["84057.55000000", "0.00000000"], ["84056.44000000", "0.00000000"], ["84055.40000000", "0.00500000"], ["84054.54000000", "0.15067000"], ["84048.02000000", "1.11058000"], ["84047.32000000", "0.00000000"], ["84045.79000000", "1.32862000"], ["84036.10000000", "0.00000000"], ["84033.39000000", "0.85721000"], ["84033.02000000", "0.59504000"], ["84031.48000000", "0.00000000"], ["84022.69000000", "0.08992000"], ["83987.05000000", "0.00000000"], ["83985.21000000", "0.01930000"], ["83984.80000000", "0.00000000"], ["83984.43000000", "1.18018000"], ["83984.35000000", "0.00000000"], ["83982.73000000", "0.00000000"], ["83982.58000000", "0.00000000"], ["83981.53000000", "0.05497000"], ["83981.09000000", "0.10994000"], ["83981.08000000", "0.00000000"], ["83979.69000000", "0.00000000"], ["83979.57000000", "0.00000000"], ["83979.40000000", "0.05497000"], ["83979.20000000", "0.11588000"], ["83977.45000000", "0.26645000"], ["83977.07000000", "0.00000000"], ["83975.95000000", "0.00000000"], ["83975.89000000", "0.00000000"], ["83975.70000000", "0.16491000"], ["83975.69000000", "0.00000000"], ["83975.46000000", "0.00000000"], ["83975.02000000", "0.05397000"], ["83973.40000000", "0.16491000"], ["83973.15000000", "0.15531000"], ["83972.26000000", "0.00000000"], ["83972.14000000", "0.00000000"], ["83972.04000000", "0.00000000"], ["83971.45000000", "0.05497000"], ["83970.65000000", "0.10994000"], ["83970.61000000", "0.00000000"], ["83970.42000000", "0.00000000"], ["83969.70000000", "0.00000000"], ["83969.39000000", "0.05397000"], ["83969.28000000", "0.00000000"], ["83968.98000000", "0.00000000"], ["83968.89000000", "0.05497000"], ["83967.89000000", "0.04638000"], ["83967.77000000", "0.00000000"], ["83967.36000000", "0.04758000"], ["83966.81000000", "0.10994000"], ["83966.71000000", "0.00000000"], ["83966.70000000", "0.04638000"], ["83966.05000000", "0.00000000"], ["83965.33000000", "0.00000000"], ["83965.24000000", "0.10255000"], ["83965.18000000", "0.05397000"], ["83965.10000000", "0.00000000"], ["83963.46000000", "0.04097000"], ["83963.16000000", "0.00000000"], ["83962.32000000", "0.00000000"], ["83961.89000000", "0.10994000"], ["83961.73000000", "0.00000000"], ["83961.64000000", "0.05397000"], ["83961.54000000", "0.00895000"], ["83961.20000000", "0.05497000"], ["83960.79000000", "0.00000000"], ["83959.22000000", "0.00000000"], ["83958.83000000", "0.10994000"], ["83958.47000000", "0.05397000"], ["83958.38000000", "0.00000000"], ["83957.82000000", "0.05497000"], ["83957.65000000", "0.00000000"], ["83957.48000000", "0.04198000"], ["83956.39000000", "0.00000000"], ["83956.14000000", "0.00000000"], ["83956.01000000", "0.10036000"], ["83955.71000000", "0.00000000"], ["83954.38000000", "0.05497000"], ["83953.87000000", "0.00000000"], ["83953.53000000", "0.00000000"], ["83953.43000000", "0.00000000"], ["83952.57000000", "0.05097000"], ["83952.07000000", "0.04198000"], ["83951.99000000", "0.00000000"], ["83951.93000000", "0.05397000"], ["83951.24000000", "0.00000000"], ["83950.69000000", "0.05497000"], ["83949.34000000", "0.05097000"], ["83949.16000000", "0.10794000"], ["83947.71000000", "0.00000000"], ["83947.64000000", "0.00400000"], ["83946.87000000", "0.04198000"], ["83945.08000000", "0.05397000"], ["83945.07000000", "0.10493000"], ["83944.40000000", "0.00000000"], ["83943.91000000", "0.00075000"], ["83943.64000000", "0.00000000"], ["83943.28000000", "0.04198000"], ["83941.54000000", "0.00000000"], ["83940.45000000", "0.04098000"], ["83937.52000000", "0.04198000"], ["83932.57000000", "0.00000000"], ["83898.59000000", "0.01000000"], ["83896.99000000", "0.00013000"], ["83890.78000000", "0.01863000"], ["83866.64000000", "0.00063000"], ["83856.01000000", "0.00000000"], ["75655.00000000", "0.00137000"], ["67249.05000000", "0.00058000"], ["33000.00000000", "2.93827000"]], "a": [["84061.32000000", "0.34597000"], ["84062.03000000", "0.00000000"], ["84062.07000000", "0.00000000"], ["84062.13000000", "0.00000000"], ["84062.31000000", "0.00030000"], ["84062.79000000", "0.00014000"], ["84062.80000000", "0.78556000"], ["84063.15000000", "0.00000000"], ["84063.75000000", "0.31781000"], ["84063.82000000", "0.00000000"], ["84064.02000000", "0.13665000"], ["84064.58000000", "0.00000000"], ["84064.59000000", "0.01341000"], ["84064.64000000", "0.07248000"], ["84064.91000000", "0.00000000"], ["84064.92000000", "0.00000000"], ["84064.93000000", "0.02430000"], ["84065.32000000", "0.00000000"], ["84065.50000000", "0.00000000"], ["84065.51000000", "0.00000000"], ["84066.42000000", "0.00000000"], ["84066.43000000", "0.00000000"], ["84066.77000000", "0.00754000"], ["84066.92000000", "0.00000000"], ["84067.79000000", "0.00000000"], ["84068.00000000", "0.02266000"], ["84068.58000000", "0.05330000"], ["84068.59000000", "0.00000000"], ["84069.61000000", "0.09740000"], ["84069.80000000", "0.00000000"], ["84070.15000000", "0.00000000"], ["84070.55000000", "0.00000000"], ["84070.86000000", "0.16641000"], ["84071.01000000", "0.00000000"], ["84071.35000000", "0.00000000"], ["84077.22000000", "0.00011000"], ["84077.73000000", "0.01518000"], ["84079.94000000", "0.00000000"], ["84080.44000000", "0.00000000"], ["84082.92000000", "0.01863000"], ["84090.90000000", "1.78912000"], ["84091.12000000", "1.36201000"], ["84097.45000000", "0.59504000"], ["84100.59000000", "0.00000000"], ["84105.09000000", "0.00000000"], ["84106.18000000", "0.00000000"], ["84139.34000000", "0.00000000"], ["84141.11000000", "0.00000000"], ["84141.14000000", "0.72921000"], ["84144.22000000", "0.04638000"], ["84145.24000000", "0.00000000"], ["84145.63000000", "0.04638000"], ["84153.03000000", "0.00008000"], ["84181.60000000", "0.04758000"], ["84184.63000000", "0.04758000"], ["84185.85000000", "0.04639000"], ["84190.89000000", "0.04639000"], ["84192.07000000", "0.24124000"], ["84198.10000000", "0.05397000"], ["84233.06000000", "0.01000000"], ["85327.80000000", "0.17605000"]], "record_time": 1742555348.039314, "EXCHANGE": "BINANCE"}
{"e": "depthUpdate", "E": 1742555349014, "s": "BTCUSDT", "U": 64607199703, "u": 64607200146, "b": [["84061.31000000", "4.18915000"], ["84061.18000000", "0.02486000"], ["84060.98000000", "0.00006000"], ["84060.57000000", "0.00014000"], ["84060.56000000", "0.29019000"], ["84060.16000000", "0.00000000"], ["84060.15000000", "0.00020000"], ["84060.14000000", "0.78559000"], ["84060.07000000", "0.00006000"], ["84060.01000000", "0.00000000"], ["84060.00000000", "0.02266000"], ["84059.97000000", "0.00000000"], ["84059.71000000", "0.04000000"], ["84057.98000000", "0.00000000"], ["84057.70000000", "0.00000000"], ["84057.63000000", "0.00000000"], ["84057.57000000", "0.00000000"], ["84057.32000000", "0.00000000"], ["84057.18000000", "0.00000000"], ["84057.14000000", "0.00000000"], ["84056.78000000", "0.00000000"], ["84056.31000000", "0.21666000"], ["84055.94000000", "0.00000000"], ["84055.88000000", "0.00000000"], ["84055.46000000", "0.00000000"], ["84055.04000000", "0.00000000"], ["84054.99000000", "0.00000000"], ["84054.94000000", "0.04000000"], ["84054.90000000", "0.00000000"], ["84054.11000000", "0.04000000"], ["84054.10000000", "0.04000000"], ["84054.04000000", "0.04000000"], ["84053.78000000", "0.00000000"], ["84053.67000000", "0.00000000"], ["84053.34000000", "0.00000000"], ["84053.26000000", "0.00000000"], ["84053.24000000", "0.08992000"], ["84053.23000000", "0.00000000"], ["84053.12000000", "0.00000000"], ["84053.01000000", "0.00000000"], ["84052.96000000", "0.02379000"], ["84052.94000000", "0.00000000"], ["84052.35000000", "0.42728000"], ["84051.60000000", "0.00000000"], ["84051.59000000", "0.04000000"], ["84051.26000000", "0.00000000"], ["84050.98000000", "0.00000000"], ["84050.74000000", "0.04000000"], ["84050.01000000", "0.00000000"], ["84049.92000000", "0.00000000"], ["84049.89000000", "0.04000000"], ["84049.82000000", "0.04000000"], ["84049.43000000", "0.00000000"], ["84048.92000000", "0.00000000"], ["84048.71000000", "0.00328000"], ["84048.02000000", "0.63462000"], ["84047.60000000", "0.00009000"], ["84046.60000000", "0.00000000"], ["84046.27000000", "0.00000000"], ["84045.79000000", "0.00000000"], ["84044.37000000", "1.36446000"], ["84043.70000000", "0.00000000"], ["84043.46000000", "0.00000000"], ["84042.10000000", "0.85712000"], ["84041.83000000", "0.00000000"], ["84041.80000000", "0.00000000"], ["84040.95000000", "0.08992000"], ["84038.61000000", "0.47551000"], ["84037.56000000", "0.12313000"], ["84037.50000000", "0.00000000"], ["84037.31000000", "0.00000000"], ["84036.97000000", "0.00000000"], ["84033.40000000", "0.59504000"], ["84033.02000000", "0.00000000"], ["84031.78000000", "0.05071000"], ["84029.86000000", "0.00000000"], ["84028.74000000", "0.00000000"], ["84028.12000000", "0.00000000"], ["84027.20000000", "0.00000000"], ["84026.01000000", "0.00213000"], ["84025.08000000", "0.00000000"], ["84021.15000000", "0.00000000"], ["84010.28000000", "0.00297000"], ["84009.12000000", "0.00000000"], ["84004.01000000", "0.00000000"], ["84000.46000000", "0.00297000"], ["83989.65000000", "0.04000000"], ["83989.64000000", "0.00000000"], ["83989.24000000", "0.00000000"], ["83985.23000000", "0.08638000"], ["83982.05000000", "0.00000000"], ["83975.95000000", "0.00000000"], ["83974.01000000", "0.04638000"], ["83973.51000000", "0.00000000"], ["83973.49000000", "0.00000000"], ["83971.81000000", "0.04000000"], ["83971.60000000", "1.40100000"], ["83960.25000000", "0.00000000"], ["83958.37000000", "0.00000000"], ["83954.34000000", "0.00000000"], ["83953.60000000", "0.00000000"], ["83950.97000000", "0.04997000"], ["83950.76000000", "0.05197000"], ["83949.47000000", "0.00000000"], ["83949.25000000", "0.04997000"], ["83948.72000000", "0.00000000"], ["83948.56000000", "0.05197000"], ["83947.64000000", "0.00000000"], ["83947.54000000", "0.04997000"], ["83945.81000000", "0.00000000"], ["83945.55000000", "0.05196000"], ["83941.96000000", "0.04997000"], ["83938.77000000", "0.04997000"], ["83927.53000000", "0.00400000"], ["83925.73000000", "0.00119000"], ["83920.01000000", "0.00000000"], ["83915.56000000", "0.00119000"], ["83904.57000000", "0.00000000"], ["83890.78000000", "0.00000000"], ["83879.46000000", "0.00000000"], ["83848.71000000", "0.00194000"], ["83843.60000000", "0.00000000"], ["82995.14000000", "0.00028000"], ["80673.60000000", "0.00000000"], ["80656.80000000", "0.00000000"], ["75655.00000000", "0.00137000"], ["67249.05000000", "0.00058000"], ["60000.00000000", "73.17018000"], ["33000.00000000", "2.93827000"]], "a": [["84061.32000000", "1.08994000"], ["84061.73000000", "0.00009000"], ["84061.75000000", "0.00014000"], ["84061.76000000", "0.17450000"], ["84062.67000000", "0.00000000"], ["84062.68000000", "0.00000000"], ["84062.73000000", "0.00014000"], ["84062.74000000", "0.27782000"], ["84062.75000000", "0.00000000"], ["84062.76000000", "0.35648000"], ["84062.79000000", "0.00000000"], ["84062.80000000", "0.00006000"], ["84062.95000000", "0.00000000"], ["84062.96000000", "0.00000000"], ["84062.97000000", "0.00000000"], ["84063.75000000", "0.00000000"], ["84063.82000000", "0.00007000"], ["84064.02000000", "0.00000000"], ["84064.20000000", "0.00000000"], ["84064.59000000", "0.01891000"], ["84064.62000000", "0.00000000"], ["84064.63000000", "0.00000000"], ["84064.64000000", "0.07242000"], ["84064.82000000", "0.02207000"], ["84064.92000000", "0.00000000"], ["84064.93000000", "0.80972000"], ["84065.50000000", "0.00000000"], ["84065.51000000", "0.00007000"], ["84066.76000000", "0.00000000"], ["84067.24000000", "0.00000000"], ["84067.97000000", "0.00000000"], ["84067.98000000", "0.00000000"], ["84067.99000000", "0.00000000"], ["84068.00000000", "0.02260000"], ["84068.03000000", "0.00000000"], ["84068.58000000", "0.00000000"], ["84069.33000000", "0.00000000"], ["84069.61000000", "0.09740000"], ["84069.73000000", "0.00000000"], ["84070.53000000", "0.00011000"], ["84070.55000000", "0.02484000"], ["84071.04000000", "0.01518000"], ["84071.05000000", "0.00000000"], ["84072.16000000", "0.00090000"], ["84073.67000000", "0.00000000"], ["84074.18000000", "0.00000000"], ["84074.30000000", "0.00000000"], ["84077.22000000", "0.00000000"], ["84077.73000000", "0.00000000"], ["84077.91000000", "0.72460000"], ["84080.02000000", "0.71284000"], ["84080.60000000", "0.00000000"], ["84082.92000000", "0.00000000"], ["84089.87000000", "1.36187000"], ["84091.12000000", "0.00000000"], ["84093.58000000", "0.00000000"], ["84094.06000000", "0.85659000"], ["84100.24000000", "0.00212000"], ["84102.20000000", "0.00000000"], ["84103.89000000", "0.00000000"], ["84104.83000000", "0.12240000"], ["84107.48000000", "0.05865000"], ["84109.07000000", "0.00000000"], ["84109.70000000", "0.00000000"], ["84114.10000000", "0.00000000"], ["84120.87000000", "0.03609000"], ["84121.79000000", "0.03451000"], ["84134.77000000", "0.00000000"], ["84135.55000000", "0.00000000"], ["84140.66000000", "0.01863000"], ["84144.22000000", "0.00000000"], ["84145.23000000", "0.00000000"], ["84145.24000000", "0.00297000"], ["84145.63000000", "0.00000000"], ["84145.90000000", "0.04342000"], ["84147.76000000", "0.00000000"], ["84148.61000000", "0.00000000"], ["84149.47000000", "0.00000000"], ["84155.97000000", "0.00295000"], ["84155.99000000", "0.00000000"], ["84183.19000000", "0.04639000"], ["84185.67000000", "0.04639000"], ["84187.24000000", "0.00000000"], ["84187.74000000", "0.04639000"], ["84190.74000000", "0.05497000"], ["84191.26000000", "0.09278000"], ["84192.64000000", "0.05197000"], ["84193.79000000", "0.05497000"], ["84195.88000000", "0.05197000"], ["84197.24000000", "0.05497000"], ["84197.34000000", "0.05497000"], ["84199.61000000", "0.05197000"], ["84201.48000000", "0.00000000"], ["84203.26000000", "0.05197000"], ["84204.60000000", "0.00000000"], ["84204.95000000", "0.00000000"], ["84208.05000000", "0.04638000"], ["84209.99000000", "0.00035000"], ["84210.74000000", "0.04897000"], ["84225.53000000", "0.00000000"], ["84229.42000000", "0.00119000"], ["84234.16000000", "0.00000000"], ["84239.49000000", "0.00119000"], ["85035.70000000", "0.00000000"]], "record_time": 1742555349.0389, "EXCHANGE": "BINANCE"}
{"e": "depthUpdate", "E": 1742555350014, "s": "BTCUSDT", "U": 64607200147, "u": 64607200288, "b": [["84061.31000000", "5.00675000"], ["84061.18000000", "0.02492000"], ["84060.98000000", "0.00000000"], ["84060.56000000", "0.29025000"], ["84060.15000000", "0.00014000"], ["84060.14000000", "0.78565000"], ["84060.07000000", "0.00000000"], ["84060.00000000", "0.02272000"], ["84058.50000000", "0.00000000"], ["84055.40000000", "0.00500000"], ["84054.54000000", "0.00000000"], ["84052.39000000", "0.00000000"], ["84051.76000000", "0.00000000"], ["84049.54000000", "0.20993000"], ["84048.40000000", "0.00000000"], ["84048.02000000", "0.75805000"], ["84047.56000000", "0.15067000"], ["84047.36000000", "0.00000000"], ["84046.82000000", "0.00418000"], ["84045.10000000", "1.38554000"], ["84044.37000000", "0.00000000"], ["84032.85000000", "0.00000000"], ["84026.09000000", "0.00000000"], ["84025.92000000", "0.37697000"], ["84024.61000000", "0.04942000"], ["84019.90000000", "0.00000000"], ["83989.65000000", "0.00000000"], ["83985.23000000", "0.04638000"], ["83982.64000000", "0.00298000"], ["83978.97000000", "0.00000000"], ["83974.24000000", "0.00597000"], ["83974.08000000", "0.00100000"], ["83971.81000000", "0.00000000"], ["83970.38000000", "0.00000000"], ["83965.84000000", "0.00895000"], ["83961.54000000", "0.00000000"], ["83957.44000000", "0.01194000"], ["83953.14000000", "0.00000000"], ["83944.74000000", "0.00000000"], ["83933.63000000", "0.00400000"], ["83927.53000000", "0.00000000"], ["83003.50000000", "0.40000000"], ["79800.00000000", "8.29820000"], ["76668.79000000", "0.00000000"], ["75655.00000000", "0.00137000"], ["67249.05000000", "0.00058000"], ["33000.00000000", "2.93827000"], ["30262.07000000", "0.00340000"]], "a": [["84061.32000000", "1.14543000"], ["84061.76000000", "0.17456000"], ["84062.31000000", "0.00006000"], ["84062.74000000", "0.27788000"], ["84062.76000000", "0.35654000"], ["84062.80000000", "0.00000000"], ["84063.59000000", "0.00000000"], ["84063.82000000", "0.00000000"], ["84063.87000000", "0.16647000"], ["84064.59000000", "0.01915000"], ["84064.61000000", "0.00000000"], ["84064.64000000", "0.07248000"], ["84064.82000000", "0.02213000"], ["84064.93000000", "0.80978000"], ["84068.00000000", "0.02260000"], ["84068.52000000", "0.00424000"], ["84068.69000000", "0.00000000"], ["84069.61000000", "0.05375000"], ["84070.53000000", "0.00000000"], ["84070.86000000", "0.00000000"], ["84071.04000000", "0.00000000"], ["84073.13000000", "0.00011000"], ["84073.63000000", "0.01518000"], ["84089.87000000", "1.32601000"], ["84100.79000000", "0.05000000"], ["84121.79000000", "0.00000000"], ["84131.59000000", "0.03451000"], ["84140.66000000", "0.00000000"], ["84146.07000000", "0.00000000"], ["84148.54000000", "0.00100000"], ["84149.60000000", "0.00298000"], ["84154.48000000", "0.00000000"], ["84158.64000000", "1.10829000"], ["84159.16000000", "0.00597000"], ["84162.89000000", "0.00000000"], ["84167.70000000", "0.00895000"], ["84171.30000000", "0.05197000"], ["84173.91000000", "0.00000000"], ["84177.86000000", "0.00000000"], ["84178.39000000", "0.04758000"], ["84179.71000000", "0.00000000"], ["84182.85000000", "0.04758000"], ["84183.99000000", "0.00000000"], ["84186.00000000", "0.00000000"], ["84186.01000000", "0.00000000"], ["84188.87000000", "0.04639000"], ["84189.13000000", "0.00000000"], ["84192.41000000", "0.05397000"], ["84193.88000000", "0.04198000"], ["84196.52000000", "0.00000000"], ["84199.84000000", "0.04198000"], ["84202.09000000", "0.00000000"], ["84208.15000000", "0.00000000"], ["85044.13000000", "0.60000000"], ["102000.00000000", "50.29510000"]], "record_time": 1742555350.038236, "EXCHANGE": "BINANCE"}
{"e": "depthUpdate", "E": 1742555351014, "s": "BTCUSDT", "U": 64607200289, "u": 64607200377, "b": [["84061.31000000", "4.18835000"], ["84053.24000000", "0.00000000"], ["84048.02000000", "0.79906000"], ["84045.10000000", "0.00000000"], ["84045.02000000", "1.37155000"], ["84030.35000000", "0.00000000"], ["84026.09000000", "0.05000000"], ["84021.90000000", "0.40568000"], ["83949.03000000", "0.01493000"], ["83933.63000000", "0.00000000"], ["83928.12000000", "0.00000000"], ["83921.81000000", "0.00400000"], ["83875.45000000", "0.00000000"], ["83872.18000000", "0.00011000"], ["83789.46000000", "0.00000000"], ["83197.33000000", "0.00060000"], ["83197.32000000", "0.00176000"], ["83197.11000000", "0.00000000"], ["83197.09000000", "0.00000000"], ["82794.53000000", "0.00000000"], ["82183.41000000", "0.00021000"], ["80673.60000000", "0.03568000"], ["75655.00000000", "0.00187000"], ["67249.05000000", "0.00058000"], ["33000.00000000", "2.93827000"], ["20002.00000000", "0.00000000"], ["20001.00000000", "0.02099000"]], "a": [["84061.32000000", "0.61301000"], ["84062.74000000", "0.39930000"], ["84062.76000000", "0.35654000"], ["84063.87000000", "0.00025000"], ["84064.59000000", "0.01891000"], ["84065.50000000", "0.00500000"], ["84066.55000000", "0.16641000"], ["84077.59000000", "0.00000000"], ["84086.05000000", "0.00000000"], ["84089.87000000", "1.38541000"], ["84153.34000000", "0.00841000"], ["84166.09000000", "0.00000000"], ["84169.60000000", "0.04758000"], ["84171.96000000", "0.09516000"], ["84174.13000000", "0.04758000"], ["84175.99000000", "0.04758000"], ["84176.11000000", "0.01194000"], ["84178.38000000", "0.04758000"], ["84182.86000000", "0.04758000"], ["84184.52000000", "0.53036000"], ["84184.53000000", "0.00000000"], ["84185.98000000", "0.00000000"], ["84185.99000000", "0.05197000"], ["84189.27000000", "0.04639000"], ["84189.41000000", "0.00000000"], ["84189.42000000", "0.00000000"], ["84192.46000000", "0.05397000"], ["84194.19000000", "0.16320000"], ["84195.39000000", "0.00000000"], ["84198.27000000", "0.00000000"], ["84901.92000000", "0.00000000"]], "record_time": 1742555351.038529, "EXCHANGE": "BINANCE"}
{"e": "depthUpdate", "E": 1742555352014, "s": "BTCUSDT", "U": 64607200378, "u": 64607200447, "b": [["84061.31000000", "4.14021000"], ["84055.40000000", "0.00500000"], ["84048.02000000", "0.78805000"], ["84045.02000000", "1.33485000"], ["84038.61000000", "0.47551000"], ["84009.61000000", "0.00000000"], ["83610.00000000", "0.03596000"], ["82800.39000000", "0.00007000"], ["82451.88000000", "0.00030000"], ["75655.00000000", "0.00137000"], ["67249.05000000", "0.00058000"], ["33000.00000000", "2.93827000"], ["30262.07000000", "0.00360000"]], "a": [["84061.32000000", "1.26476000"], ["84062.74000000", "0.39924000"], ["84062.76000000", "0.00006000"], ["84063.06000000", "0.00014000"], ["84063.07000000", "0.78550000"], ["84063.87000000", "0.00000000"], ["84064.59000000", "0.01916000"], ["84064.93000000", "0.02430000"], ["84065.46000000", "0.00757000"], ["84066.54000000", "0.04551000"], ["84066.55000000", "0.16641000"], ["84066.77000000", "0.00000000"], ["84068.03000000", "0.00388000"], ["84076.46000000", "0.10675000"], ["84085.01000000", "1.00000000"], ["84089.87000000", "0.00000000"], ["84089.88000000", "1.32465000"], ["84098.80000000", "0.00212000"], ["84100.24000000", "0.00000000"], ["84147.40000000", "0.00000000"]], "record_time": 1742555352.03841, "EXCHANGE": "BINANCE"}
{"e": "depthUpdate", "E": 1742555353014, "s": "BTCUSDT", "U": 64607200448, "u": 64607200902, "b": [["84061.31000000", "3.06613000"], ["84061.30000000", "0.00048000"], ["84061.29000000", "0.00007000"], ["84061.24000000", "0.00018000"], ["84061.19000000", "0.00021000"], ["84061.18000000", "0.02466000"], ["84060.82000000", "0.00014000"], ["84060.81000000", "0.78559000"], ["84060.74000000", "0.00000000"], ["84060.59000000", "0.00000000"], ["84060.58000000", "0.29746000"], ["84060.57000000", "0.08313000"], ["84060.56000000", "0.00006000"], ["84060.19000000", "0.00500000"], ["84060.15000000", "0.00000000"], ["84060.14000000", "0.00000000"], ["84060.00000000", "0.02266000"], ["84059.86000000", "0.00500000"], ["84059.71000000", "0.00000000"], ["84059.66000000", "0.00000000"], ["84059.64000000", "0.01189000"], ["84059.59000000", "0.01000000"], ["84059.26000000", "0.01000000"], ["84058.73000000", "0.00000000"], ["84058.63000000", "0.00000000"], ["84058.39000000", "0.00000000"], ["84058.38000000", "0.00000000"], ["84058.36000000", "0.01518000"], ["84058.03000000", "0.00000000"], ["84057.78000000", "0.00000000"], ["84057.31000000", "0.00000000"], ["84057.19000000", "0.00000000"], ["84056.32000000", "0.00000000"], ["84056.31000000", "0.21666000"], ["84056.30000000", "0.00000000"], ["84056.29000000", "0.47439000"], ["84055.73000000", "0.02000000"], ["84055.53000000", "0.12000000"], ["84053.55000000", "0.00000000"], ["84053.47000000", "0.04000000"], ["84052.96000000", "0.00000000"], ["84050.10000000", "0.00091000"], ["84049.71000000", "0.00000000"], ["84049.54000000", "0.00000000"], ["84049.48000000", "0.00899000"], ["84048.71000000", "0.00328000"], ["84048.60000000", "0.01190000"], ["84048.02000000", "0.54225000"], ["84047.58000000", "0.04000000"], ["84046.24000000", "0.47551000"], ["84045.73000000", "0.00000000"], ["84045.12000000", "0.61488000"], ["84045.02000000", "0.00000000"], ["84044.54000000", "0.59438000"], ["84044.21000000", "0.90327000"], ["84043.88000000", "1.34069000"], ["84043.50000000", "0.00000000"], ["84042.11000000", "0.71284000"], ["84042.10000000", "0.00000000"], ["84041.63000000", "0.85712000"], ["84040.95000000", "0.00000000"], ["84039.32000000", "1.20360000"], ["84038.61000000", "0.00000000"], ["84038.21000000", "0.00000000"], ["84038.05000000", "0.85716000"], ["84037.56000000", "0.00000000"], ["84036.53000000", "0.13375000"], ["84033.40000000", "0.00000000"], ["84033.39000000", "0.00000000"], ["84033.33000000", "0.04000000"], ["84031.78000000", "0.00000000"], ["84031.26000000", "0.11991000"], ["84029.27000000", "0.85725000"], ["84028.31000000", "0.00000000"], ["84026.09000000", "0.00000000"], ["84025.50000000", "0.00000000"], ["84025.08000000", "0.59509000"], ["84023.40000000", "0.00000000"], ["84022.96000000", "0.00000000"], ["84022.63000000", "0.00000000"], ["84021.34000000", "0.00935000"], ["84020.89000000", "0.00000000"], ["84018.80000000", "0.05743000"], ["84017.79000000", "0.00000000"], ["84017.49000000", "0.21270000"], ["84009.87000000", "0.38410000"], ["84009.67000000", "0.00000000"], ["84009.65000000", "0.00000000"], ["84009.60000000", "0.00000000"], ["84009.49000000", "0.59438000"], ["84008.50000000", "0.47551000"], ["83977.69000000", "0.04000000"], ["83972.03000000", "0.00000000"], ["83972.02000000", "0.00000000"], ["83921.81000000", "0.00000000"], ["83916.37000000", "0.00000000"], ["83898.59000000", "0.00000000"], ["83898.29000000", "0.01000000"], ["83875.32000000", "0.00400000"], ["83197.33000000", "0.00000000"], ["83197.32000000", "0.00116000"], ["83194.61000000", "0.00060000"], ["83194.59000000", "0.00060000"], ["80673.60000000", "0.00000000"], ["80656.80000000", "0.03568000"], ["75655.00000000", "0.00137000"], ["67249.05000000", "0.00058000"], ["33000.00000000", "2.93827000"], ["30255.65000000", "0.00340000"], ["30231.01000000", "0.00040000"], ["30225.60000000", "0.00060000"], ["30220.73000000", "0.00040000"], ["30217.11000000", "0.00040000"], ["30216.23000000", "0.00160000"], ["30208.70000000", "0.00700000"], ["30207.09000000", "0.00460000"], ["30205.46000000", "0.00160000"], ["30199.10000000", "0.00000000"], ["30195.85000000", "0.00180000"], ["30191.84000000", "0.00000000"], ["30185.20000000", "0.00000000"]], "a": [["84061.32000000", "4.09899000"], ["84061.74000000", "0.00216000"], ["84061.75000000", "0.14316000"], ["84061.76000000", "0.17450000"], ["84062.13000000", "0.00059000"], ["84062.73000000", "0.00000000"], ["84062.74000000", "0.00006000"], ["84062.76000000", "0.00000000"], ["84062.97000000", "0.00000000"], ["84062.99000000", "0.00000000"], ["84063.06000000", "0.00000000"], ["84063.07000000", "0.00000000"], ["84063.82000000", "0.00032000"], ["84064.00000000", "0.02266000"], ["84064.43000000", "0.00000000"], ["84064.59000000", "0.01891000"], ["84064.64000000", "0.22959000"], ["84064.82000000", "0.00000000"], ["84064.93000000", "0.02424000"], ["84065.50000000", "0.00500000"], ["84065.51000000", "0.00000000"], ["84066.00000000", "0.02260000"], ["84066.54000000", "0.07237000"], ["84066.55000000", "0.00000000"], ["84068.03000000", "0.00719000"], ["84068.11000000", "0.05943000"], ["84069.18000000", "0.15409000"], ["84069.60000000", "0.00011000"], ["84069.61000000", "0.19779000"], ["84069.73000000", "0.00000000"], ["84070.11000000", "0.01518000"], ["84070.90000000", "0.00096000"], ["84070.94000000", "0.00000000"], ["84071.00000000", "0.00000000"], ["84071.19000000", "0.00000000"], ["84071.38000000", "0.00000000"], ["84072.16000000", "0.00000000"], ["84072.38000000", "0.00417000"], ["84073.13000000", "0.00000000"], ["84073.63000000", "0.00000000"], ["84075.60000000", "0.01195000"], ["84076.72000000", "0.00000000"], ["84078.13000000", "0.06002000"], ["84080.52000000", "0.85673000"], ["84080.90000000", "0.00000000"], ["84083.49000000", "0.01189000"], ["84086.67000000", "0.00000000"], ["84086.95000000", "2.11704000"], ["84089.66000000", "1.32085000"], ["84089.88000000", "0.00000000"], ["84089.91000000", "0.85663000"], ["84090.75000000", "0.08992000"], ["84090.90000000", "1.29252000"], ["84091.70000000", "0.00000000"], ["84093.94000000", "0.00000000"], ["84094.06000000", "0.00000000"], ["84094.56000000", "0.00000000"], ["84095.99000000", "0.00000000"], ["84098.43000000", "0.00212000"], ["84098.52000000", "0.12468000"], ["84098.80000000", "0.00000000"], ["84100.79000000", "0.00000000"], ["84102.79000000", "0.00000000"], ["84102.88000000", "0.05880000"], ["84104.83000000", "0.00000000"], ["84107.48000000", "0.00000000"], ["84109.01000000", "0.00000000"], ["84119.81000000", "0.03451000"], ["84131.04000000", "0.04098000"], ["84131.51000000", "0.04098000"], ["84131.59000000", "0.00000000"], ["84139.26000000", "0.00000000"], ["84158.64000000", "0.00000000"], ["84161.47000000", "0.00000000"], ["84183.44000000", "0.05497000"], ["84191.46000000", "0.08304000"], ["84231.76000000", "0.00000000"], ["84233.06000000", "0.01000000"], ["84234.96000000", "0.00000000"], ["84378.00000000", "0.03597000"], ["84420.00000000", "0.00246000"], ["84768.00000000", "0.00000000"], ["85768.00000000", "0.52584000"]], "record_time": 1742555353.038799, "EXCHANGE": "BINANCE"}
{"e": "depthUpdate", "E": 1742555354014, "s": "BTCUSDT", "U": 64607200903, "u": 64607201079, "b": [["84061.31000000", "2.93487000"], ["84061.18000000", "0.14475000"], ["84060.90000000", "0.00000000"], ["84060.89000000", "0.00000000"], ["84060.84000000", "0.00000000"], ["84060.83000000", "0.00014000"], ["84060.82000000", "0.27139000"], ["84060.81000000", "0.00000000"], ["84060.58000000", "0.00000000"], ["84060.57000000", "0.00000000"], ["84060.00000000", "0.02273000"], ["84059.64000000", "0.01175000"], ["84059.02000000", "0.78553000"], ["84058.36000000", "0.00000000"], ["84055.40000000", "0.00500000"], ["84050.10000000", "0.00000000"], ["84048.71000000", "0.00349000"], ["84046.91000000", "0.10675000"], ["84045.58000000", "0.59438000"], ["84045.37000000", "0.00000000"], ["84044.54000000", "0.00000000"], ["84044.21000000", "1.44970000"], ["84020.89000000", "0.00000000"], ["84019.64000000", "0.05000000"], ["84009.87000000", "0.54889000"], ["84009.49000000", "0.00000000"], ["84009.44000000", "0.59438000"], ["83977.69000000", "0.00000000"], ["83950.76000000", "0.00000000"], ["83946.41000000", "0.05197000"], ["83904.60000000", "0.00000000"], ["83898.29000000", "0.00000000"], ["83897.61000000", "0.00400000"], ["83897.19000000", "0.00000000"], ["83897.00000000", "0.00000000"], ["83896.59000000", "0.01000000"], ["83875.32000000", "0.00000000"], ["83786.20000000", "0.00008000"], ["83623.26000000", "0.00000000"], ["83619.99000000", "0.00011000"], ["83194.61000000", "0.00000000"], ["83194.59000000", "0.00000000"], ["83192.36000000", "0.00060000"], ["83192.35000000", "0.00060000"], ["83003.50000000", "0.00000000"], ["75655.00000000", "0.00157000"], ["67249.05000000", "0.00058000"], ["33000.00000000", "2.93887000"]], "a": [["84061.32000000", "4.00906000"], ["84063.92000000", "0.00000000"], ["84064.17000000", "0.02426000"], ["84066.93000000", "0.00000000"], ["84068.03000000", "0.01189000"], ["84069.61000000", "0.19751000"], ["84069.73000000", "0.45000000"], ["84071.40000000", "0.00006000"], ["84078.13000000", "0.00059000"], ["84089.65000000", "0.00212000"], ["84096.10000000", "0.05000000"], ["84098.43000000", "0.00000000"], ["84119.81000000", "0.00000000"], ["84130.18000000", "0.03451000"], ["84144.06000000", "0.02380000"], ["84147.60000000", "0.00841000"], ["84153.34000000", "0.00000000"], ["84186.75000000", "0.04639000"], ["84188.90000000", "0.04639000"], ["84191.54000000", "0.00000000"], ["84194.82000000", "0.00000000"], ["84195.24000000", "0.05197000"], ["84197.59000000", "0.00000000"], ["84202.64000000", "0.00000000"], ["84232.46000000", "0.01000000"], ["84232.76000000", "0.00000000"], ["84233.06000000", "0.00000000"], ["84737.34000000", "0.00000000"], ["84740.31000000", "0.00060000"], ["84744.00000000", "0.00000000"], ["84746.97000000", "0.00040000"], ["85044.13000000", "0.00000000"]], "record_time": 1742555354.038184, "EXCHANGE": "BINANCE"}
{"e": "depthUpdate", "E": 1742555355014, "s": "BTCUSDT", "U": 64607201080, "u": 64607201196, "b": [["84061.31000000", "2.93802000"], ["84061.04000000", "0.00210000"], ["84060.87000000", "0.00000000"], ["84060.85000000", "0.00000000"], ["84060.82000000", "0.27125000"], ["84060.46000000", "0.00000000"], ["84059.03000000", "0.00014000"], ["84052.35000000", "0.42728000"], ["84049.48000000", "0.00000000"], ["84048.55000000", "0.00000000"], ["84047.60000000", "0.00009000"], ["84041.64000000", "0.00000000"], ["84041.63000000", "0.00000000"], ["84037.50000000", "0.00400000"], ["84028.72000000", "0.85726000"], ["84025.92000000", "0.00000000"], ["84022.78000000", "0.37697000"], ["84021.34000000", "0.00000000"], ["84017.92000000", "0.00935000"], ["84017.49000000", "0.19400000"], ["84016.64000000", "0.01870000"], ["83974.78000000", "0.00000000"], ["83972.23000000", "0.00000000"], ["83972.03000000", "1.38932000"], ["83969.38000000", "0.00000000"], ["83966.07000000", "0.10135000"], ["83963.59000000", "0.04639000"], ["83960.72000000", "0.04639000"], ["83949.39000000", "0.05097000"], ["83948.01000000", "0.00000000"], ["83946.83000000", "0.05097000"], ["83945.07000000", "0.05397000"], ["83897.61000000", "0.00000000"], ["83890.55000000", "0.00400000"], ["82995.14000000", "0.40028000"], ["82957.49000000", "0.00096000"], ["75655.00000000", "0.00137000"], ["67249.05000000", "0.00058000"], ["42000.00000000", "6.85261000"], ["33000.00000000", "2.93827000"], ["30262.07000000", "0.00380000"]], "a": [["84061.32000000", "4.03877000"], ["84061.33000000", "0.00060000"], ["84062.74000000", "0.00032000"], ["84062.97000000", "0.00007000"], ["84063.82000000", "0.00000000"], ["84064.18000000", "0.00757000"], ["84064.20000000", "0.00400000"], ["84065.46000000", "0.00000000"], ["84065.50000000", "0.00000000"], ["84066.93000000", "0.02351000"], ["84068.11000000", "0.05943000"], ["84074.30000000", "0.00400000"], ["84078.13000000", "0.00059000"], ["84079.86000000", "0.02802000"], ["84092.28000000", "0.00000000"], ["84144.06000000", "0.00000000"], ["84150.26000000", "0.02380000"], ["84185.96000000", "0.21245000"], ["84188.47000000", "0.00000000"], ["84901.92000000", "0.00000000"], ["85035.70000000", "0.60000000"]], "record_time": 1742555355.03883, "EXCHANGE": "BINANCE"}
{"e": "depthUpdate", "E": 1742555356014, "s": "BTCUSDT", "U": 64607201197, "u": 64607201394, "b": [["84061.31000000", "4.80082000"], ["84061.18000000", "0.14481000"], ["84061.04000000", "0.00000000"], ["84061.01000000", "0.00000000"], ["84060.82000000", "0.27131000"], ["84060.74000000", "0.00014000"], ["84060.73000000", "0.78565000"], ["84060.56000000", "0.00000000"], ["84060.00000000", "0.02273000"], ["84059.64000000", "0.01168000"], ["84059.03000000", "0.00000000"], ["84059.02000000", "0.00000000"], ["84058.50000000", "0.00000000"], ["84055.40000000", "0.00000000"], ["84052.95000000", "0.02379000"], ["84049.33000000", "0.00885000"], ["84048.71000000", "0.00596000"], ["84048.40000000", "0.00000000"], ["84045.58000000", "0.00000000"], ["84041.58000000", "0.85713000"], ["84035.48000000", "0.11530000"], ["84033.84000000", "0.59505000"], ["84031.26000000", "0.00000000"], ["84028.72000000", "0.00000000"], ["84025.08000000", "0.00000000"], ["84024.18000000", "0.00000000"], ["84019.64000000", "0.00000000"], ["84009.44000000", "0.00000000"], ["84008.72000000", "0.59438000"], ["83977.18000000", "0.01196000"], ["83971.73000000", "0.00000000"], ["83915.85000000", "0.00400000"], ["83897.41000000", "0.00000000"], ["83890.55000000", "0.00000000"], ["80673.60000000", "0.00000000"], ["80656.80000000", "0.00000000"], ["79800.00000000", "8.29820000"], ["75655.00000000", "0.00137000"], ["67249.05000000", "0.00058000"], ["42000.00000000", "6.85161000"], ["33000.00000000", "2.93827000"], ["30262.07000000", "0.00400000"], ["30256.16000000", "0.00340000"], ["30252.45000000", "0.00020000"], ["30233.21000000", "0.01180000"], ["30232.80000000", "0.00320000"], ["30231.46000000", "0.00060000"], ["30230.05000000", "0.00120000"], ["30223.65000000", "0.00160000"], ["30220.44000000", "0.00560000"], ["30219.16000000", "0.00040000"], ["30216.23000000", "0.00140000"], ["30215.65000000", "0.00020000"], ["30213.32000000", "0.00460000"], ["30208.70000000", "0.00680000"], ["30203.47000000", "0.00000000"], ["30201.91000000", "0.00000000"], ["30198.13000000", "0.00100000"], ["30196.96000000", "0.00040000"], ["30194.62000000", "0.00060000"], ["30190.63000000", "0.00020000"], ["30182.27000000", "0.00000000"], ["20002.00000000", "0.00000000"], ["20001.00000000", "0.02099000"]], "a": [["84061.32000000", "3.29767000"], ["84061.33000000", "0.00060000"], ["84061.75000000", "0.22586000"], ["84061.76000000", "0.17456000"], ["84062.74000000", "0.00000000"], ["84062.87000000", "0.06787000"], ["84063.25000000", "0.30622000"], ["84064.00000000", "0.02266000"], ["84064.17000000", "0.00000000"], ["84064.23000000", "0.00000000"], ["84064.49000000", "0.01148000"], ["84064.59000000", "0.01885000"], ["84064.64000000", "0.00006000"], ["84064.93000000", "0.02424000"], ["84065.36000000", "0.00000000"], ["84065.50000000", "0.00500000"], ["84066.00000000", "0.02260000"], ["84066.54000000", "0.07237000"], ["84066.93000000", "0.00000000"], ["84068.03000000", "0.00000000"], ["84068.11000000", "0.00000000"], ["84069.60000000", "0.00000000"], ["84069.61000000", "0.05375000"], ["84069.73000000", "0.00000000"], ["84070.11000000", "0.00000000"], ["84072.90000000", "0.00011000"], ["84073.41000000", "0.01518000"], ["84096.10000000", "0.00000000"], ["84098.52000000", "0.00000000"], ["84102.74000000", "0.12232000"], ["84107.80000000", "0.00000000"], ["84182.33000000", "0.05097000"], ["84183.69000000", "0.04639000"], ["84185.97000000", "0.00006000"], ["84186.51000000", "0.04639000"], ["84186.93000000", "0.05397000"], ["84188.22000000", "0.09278000"], ["84189.12000000", "0.00000000"], ["84189.40000000", "0.00000000"], ["84191.33000000", "0.05397000"], ["84192.42000000", "0.00000000"], ["84195.27000000", "0.05497000"], ["84195.58000000", "0.00000000"], ["84197.31000000", "0.00000000"], ["84206.88000000", "0.00000000"]], "record_time": 1742555356.038737, "EXCHANGE": "BINANCE"}
{"e": "depthUpdate", "E": 1742555357014, "s": "BTCUSDT", "U": 64607201395, "u": 64607201522, "b": [["84061.31000000", "4.47459000"], ["84049.33000000", "0.00000000"], ["84046.24000000", "0.00000000"], ["84039.39000000", "0.00000000"], ["84039.32000000", "1.66923000"], ["84038.61000000", "0.59438000"], ["84037.50000000", "0.00000000"], ["84036.54000000", "0.59503000"], ["84033.84000000", "0.00000000"], ["84024.31000000", "0.05000000"], ["84021.89000000", "0.00000000"], ["84009.87000000", "0.27594000"], ["84009.70000000", "0.00000000"], ["84009.56000000", "0.00000000"], ["84009.16000000", "0.47551000"], ["84008.72000000", "0.00000000"], ["84008.71000000", "0.00000000"], ["84008.50000000", "0.00000000"], ["83923.50000000", "0.00000000"], ["83915.85000000", "0.00000000"], ["83909.19000000", "0.00400000"], ["83870.10000000", "0.01525000"], ["83786.20000000", "0.00000000"], ["83576.30000000", "0.00044000"], ["83192.36000000", "0.00000000"], ["83192.35000000", "0.00000000"], ["83187.23000000", "0.00060000"], ["83187.21000000", "0.00060000"], ["75655.00000000", "0.00137000"], ["67249.05000000", "0.00058000"], ["33000.00000000", "2.93827000"], ["30262.07000000", "0.00420000"]], "a": [["84061.32000000", "3.44040000"], ["84061.33000000", "0.00066000"], ["84063.05000000", "0.00000000"], ["84063.14000000", "0.00000000"], ["84063.15000000", "0.00848000"], ["84063.16000000", "0.00000000"], ["84063.19000000", "0.00000000"], ["84064.20000000", "0.00000000"], ["84064.49000000", "0.00000000"], ["84064.59000000", "0.01891000"], ["84064.64000000", "0.00000000"], ["84064.93000000", "0.02430000"], ["84065.50000000", "0.01000000"], ["84066.00000000", "0.02266000"], ["84066.54000000", "0.07237000"], ["84068.11000000", "0.00000000"], ["84074.30000000", "0.00000000"], ["84094.59000000", "0.05000000"], ["84097.45000000", "0.00000000"], ["84099.98000000", "0.62729000"], ["84099.99000000", "0.59503000"], ["84101.17000000", "0.00000000"], ["84134.62000000", "0.00041000"], ["84134.63000000", "0.00000000"], ["84134.64000000", "0.00000000"], ["84139.80000000", "0.00678000"], ["84147.60000000", "0.00000000"], ["84148.51000000", "0.00841000"], ["84149.56000000", "0.00000000"], ["84158.64000000", "1.10829000"], ["84179.22000000", "0.04758000"], ["84180.43000000", "0.04758000"], ["84184.40000000", "0.04639000"], ["84187.03000000", "0.05397000"], ["84188.14000000", "0.04639000"], ["84188.46000000", "0.00000000"], ["84188.73000000", "0.04639000"], ["84191.21000000", "0.05397000"], ["84196.85000000", "0.04197000"], ["84209.97000000", "0.00035000"], ["84209.98000000", "0.00000000"], ["84209.99000000", "0.00000000"], ["86988.33000000", "0.00000000"]], "record_time": 1742555357.038427, "EXCHANGE": "BINANCE"}
{"e": "depthUpdate", "E": 1742555358014, "s": "BTCUSDT", "U": 64607201523, "u": 64607202258, "b": [["84064.17000000", "8.08505000"], ["84064.16000000", "0.00028000"], ["84064.01000000", "0.00021000"], ["84064.00000000", "0.02280000"], ["84063.99000000", "0.00014000"], ["84063.98000000", "0.00035000"], ["84062.12000000", "0.00000000"], ["84062.01000000", "0.00021000"], ["84062.00000000", "0.02280000"], ["84061.73000000", "0.00000000"], ["84061.43000000", "0.00000000"], ["84061.33000000", "0.00014000"], ["84061.32000000", "1.66238000"], ["84061.31000000", "3.07504000"], ["84061.30000000", "0.00028000"], ["84061.29000000", "0.00000000"], ["84061.25000000", "0.00000000"], ["84061.24000000", "0.00000000"], ["84061.21000000", "0.00000000"], ["84061.19000000", "0.00000000"], ["84061.18000000", "0.25911000"], ["84060.83000000", "0.00000000"], ["84060.82000000", "0.42511000"], ["84060.74000000", "0.00000000"], ["84060.73000000", "0.00000000"], ["84060.64000000", "0.02340000"], ["84060.45000000", "0.00000000"], ["84060.19000000", "0.00000000"], ["84060.01000000", "0.14281000"], ["84060.00000000", "0.02272000"], ["84059.86000000", "0.00000000"], ["84059.82000000", "0.08992000"], ["84059.64000000", "0.14275000"], ["84059.59000000", "0.00000000"], ["84059.53000000", "0.00594000"], ["84059.37000000", "0.01189000"], ["84059.26000000", "0.00000000"], ["84058.91000000", "0.02379000"], ["84058.54000000", "0.05948000"], ["84057.96000000", "0.02974000"], ["84057.91000000", "0.11896000"], ["84057.89000000", "0.04245000"], ["84057.71000000", "0.00000000"], ["84057.53000000", "0.00000000"], ["84056.81000000", "0.00000000"], ["84056.31000000", "0.36649000"], ["84056.29000000", "0.02439000"], ["84055.86000000", "0.15630000"], ["84055.73000000", "0.00000000"], ["84055.61000000", "0.00006000"], ["84055.53000000", "0.00000000"], ["84055.43000000", "0.05948000"], ["84055.33000000", "0.06542000"], ["84055.25000000", "0.05948000"], ["84054.70000000", "0.05948000"], ["84054.60000000", "0.00006000"], ["84053.75000000", "0.09516000"], ["84053.68000000", "0.00000000"], ["84053.65000000", "0.00594000"], ["84053.41000000", "0.00594000"], ["84053.12000000", "0.05948000"], ["84053.04000000", "0.05948000"], ["84052.35000000", "0.97038000"], ["84050.50000000", "0.11896000"], ["84050.44000000", "0.00000000"], ["84050.09000000", "0.00024000"], ["84050.02000000", "0.00062000"], ["84050.01000000", "0.71284000"], ["84049.58000000", "0.00006000"], ["84049.57000000", "0.85704000"], ["84049.55000000", "0.05948000"], ["84049.20000000", "0.00013000"], ["84049.18000000", "0.00896000"], ["84048.92000000", "0.11896000"], ["84048.79000000", "0.11896000"], ["84048.71000000", "0.00000000"], ["84048.60000000", "0.00000000"], ["84047.56000000", "0.00000000"], ["84047.35000000", "0.05943000"], ["84047.19000000", "0.00000000"], ["84047.18000000", "0.00000000"], ["84046.50000000", "0.00000000"], ["84046.21000000", "0.85708000"], ["84044.97000000", "0.00000000"], ["84044.37000000", "0.08992000"], ["84042.67000000", "0.59501000"], ["84040.68000000", "0.12339000"], ["84040.51000000", "0.04942000"], ["84039.43000000", "0.05809000"], ["84038.62000000", "0.05948000"], ["84038.61000000", "0.00000000"], ["84036.54000000", "0.00000000"], ["84036.31000000", "0.11896000"], ["84036.09000000", "0.00000000"], ["84035.59000000", "0.77080000"], ["84035.48000000", "0.00000000"], ["84034.54000000", "0.00000000"], ["84033.84000000", "0.00000000"], ["84032.19000000", "0.00000000"], ["84029.27000000", "0.00000000"], ["84028.71000000", "0.00213000"], ["84026.05000000", "0.01870000"], ["84026.01000000", "0.00000000"], ["84024.61000000", "0.00000000"], ["84024.31000000", "0.00000000"], ["84016.64000000", "0.00000000"], ["84016.19000000", "0.00000000"], ["84009.16000000", "0.00000000"], ["84009.11000000", "0.00000000"], ["84006.22000000", "0.00866000"], ["83993.37000000", "0.00000000"], ["83957.42000000", "0.00400000"], ["83946.62000000", "0.00000000"], ["83937.63000000", "0.00203000"], ["83934.44000000", "0.03998000"], ["83934.27000000", "0.00000000"], ["83932.16000000", "0.00000000"], ["83909.19000000", "0.00000000"], ["83906.61000000", "0.00000000"], ["83896.59000000", "0.01000000"], ["83886.38000000", "0.00000000"], ["83882.56000000", "0.01863000"], ["83852.01000000", "0.00199000"], ["83848.71000000", "0.00000000"], ["83848.70000000", "0.00970000"], ["83840.30000000", "0.00000000"], ["83576.30000000", "0.00403000"], ["83195.08000000", "0.00048000"], ["83187.35000000", "0.00060000"], ["83187.23000000", "0.00000000"], ["83187.21000000", "0.00000000"], ["80673.60000000", "0.00000000"], ["75655.00000000", "0.00137000"], ["72500.00000000", "48.81567000"], ["67251.34000000", "0.00058000"], ["67249.05000000", "0.00000000"], ["50001.00000000", "1.82097000"], ["33000.00000000", "2.93827000"]], "a": [["84061.32000000", "0.00000000"], ["84061.33000000", "0.00000000"], ["84061.69000000", "0.00000000"], ["84061.73000000", "0.00000000"], ["84061.74000000", "0.00000000"], ["84061.75000000", "0.00000000"], ["84061.76000000", "0.00000000"], ["84061.92000000", "0.00000000"], ["84062.13000000", "0.00000000"], ["84062.31000000", "0.00000000"], ["84062.87000000", "0.00000000"], ["84062.97000000", "0.00000000"], ["84063.12000000", "0.00000000"], ["84063.15000000", "0.00000000"], ["84063.25000000", "0.00000000"], ["84063.61000000", "0.00000000"], ["84063.62000000", "0.00000000"], ["84063.82000000", "0.00000000"], ["84063.98000000", "0.00000000"], ["84063.99000000", "0.00000000"], ["84064.00000000", "0.00000000"], ["84064.17000000", "0.00000000"], ["84064.18000000", "0.00849000"], ["84064.19000000", "0.00028000"], ["84064.27000000", "0.00000000"], ["84064.57000000", "0.00014000"], ["84064.58000000", "0.00014000"], ["84064.59000000", "0.01891000"], ["84064.66000000", "0.00007000"], ["84064.86000000", "0.00000000"], ["84064.92000000", "0.00000000"], ["84064.93000000", "0.00000000"], ["84065.49000000", "0.00014000"], ["84065.50000000", "0.01000000"], ["84065.51000000", "0.00007000"], ["84065.68000000", "0.00000000"], ["84065.99000000", "0.00000000"], ["84066.00000000", "0.00000000"], ["84066.35000000", "0.00007000"], ["84066.53000000", "0.00000000"], ["84066.54000000", "0.00000000"], ["84067.70000000", "0.00014000"], ["84067.71000000", "0.02430000"], ["84067.99000000", "0.00014000"], ["84068.00000000", "0.02266000"], ["84068.11000000", "0.00000000"], ["84068.12000000", "0.00000000"], ["84068.15000000", "0.00000000"], ["84068.16000000", "0.00000000"], ["84068.17000000", "0.00000000"], ["84068.40000000", "0.00000000"], ["84069.03000000", "0.00007000"], ["84069.04000000", "0.15545000"], ["84069.18000000", "0.00000000"], ["84069.61000000", "0.05375000"], ["84069.86000000", "0.34918000"], ["84070.11000000", "0.05128000"], ["84070.38000000", "0.78543000"], ["84070.55000000", "0.00000000"], ["84070.99000000", "0.00000000"], ["84071.30000000", "0.00091000"], ["84071.40000000", "0.00000000"], ["84071.63000000", "0.00092000"], ["84072.17000000", "0.02208000"], ["84072.90000000", "0.00000000"], ["84073.41000000", "0.00000000"], ["84073.92000000", "0.00000000"], ["84075.07000000", "0.00000000"], ["84075.09000000", "0.00000000"], ["84075.37000000", "0.00000000"], ["84075.38000000", "0.00000000"], ["84075.60000000", "0.00006000"], ["84077.27000000", "0.01518000"], ["84077.91000000", "0.34375000"], ["84078.38000000", "0.00000000"], ["84078.93000000", "0.01863000"], ["84079.24000000", "0.00011000"], ["84079.66000000", "0.15344000"], ["84079.86000000", "0.00000000"], ["84080.02000000", "0.00000000"], ["84080.29000000", "0.00000000"], ["84080.52000000", "0.00000000"], ["84082.30000000", "0.00831000"], ["84083.49000000", "0.00000000"], ["84084.38000000", "0.00000000"], ["84085.86000000", "0.02802000"], ["84086.25000000", "0.01190000"], ["84086.53000000", "0.00000000"], ["84086.76000000", "0.00000000"], ["84089.91000000", "0.00000000"], ["84090.14000000", "0.00000000"], ["84090.31000000", "0.05943000"], ["84090.75000000", "0.00000000"], ["84091.83000000", "0.27653000"], ["84094.59000000", "0.00000000"], ["84094.85000000", "0.85658000"], ["84094.96000000", "0.00000000"], ["84095.33000000", "0.00000000"], ["84097.30000000", "0.85656000"], ["84098.43000000", "0.00084000"], ["84099.98000000", "0.00000000"], ["84099.99000000", "0.00000000"], ["84102.74000000", "0.00000000"], ["84106.18000000", "0.59498000"], ["84107.95000000", "0.12076000"], ["84120.70000000", "0.05000000"], ["84120.87000000", "0.00000000"], ["84130.64000000", "0.03609000"], ["84139.80000000", "0.00000000"], ["84144.58000000", "0.02380000"], ["84145.24000000", "0.00000000"], ["84145.90000000", "0.00000000"], ["84148.50000000", "0.00296000"], ["84149.99000000", "0.00000000"], ["84150.26000000", "0.00000000"], ["84151.07000000", "0.02287000"], ["84153.34000000", "0.00084000"], ["84155.97000000", "0.00000000"], ["84158.29000000", "0.00296000"], ["84158.64000000", "0.00000000"], ["84174.71000000", "0.05497000"], ["84175.40000000", "0.00013000"], ["84176.51000000", "0.00000000"], ["84177.84000000", "0.05497000"], ["84180.39000000", "0.04758000"], ["84181.99000000", "0.00000000"], ["84184.36000000", "0.00000000"], ["84185.96000000", "0.15749000"], ["84186.43000000", "0.04639000"], ["84198.98000000", "0.05197000"], ["84208.39000000", "0.03998000"], ["84232.46000000", "0.01000000"], ["84233.88000000", "0.99301000"], ["84234.64000000", "0.00000000"], ["84378.00000000", "0.00027000"], ["84420.00000000", "0.03816000"], ["85327.80000000", "0.05869000"], ["85349.10000000", "0.00000000"], ["86988.33000000", "0.00352000"]], "record_time": 1742555358.038947, "EXCHANGE": "BINANCE"}
{"e": "depthUpdate", "E": 1742555359014, "s": "BTCUSDT", "U": 64607202259, "u": 64607203276, "b": [["84064.58000000", "4.99014000"], ["84064.57000000", "0.00047000"], ["84064.56000000", "0.00007000"], ["84064.31000000", "0.00007000"], ["84064.30000000", "0.00007000"], ["84064.24000000", "0.00021000"], ["84064.23000000", "1.20727000"], ["84064.22000000", "0.00007000"], ["84064.21000000", "0.00000000"], ["84064.20000000", "0.00000000"], ["84064.19000000", "0.78562000"], ["84064.18000000", "0.53093000"], ["84064.17000000", "0.96553000"], ["84064.16000000", "0.00000000"], ["84064.01000000", "0.00000000"], ["84064.00000000", "0.02266000"], ["84063.99000000", "0.00000000"], ["84063.98000000", "0.00000000"], ["84062.46000000", "0.04276000"], ["84062.01000000", "0.00000000"], ["84062.00000000", "0.02266000"], ["84061.41000000", "0.00000000"], ["84061.40000000", "0.04006000"], ["84061.35000000", "0.00000000"], ["84061.34000000", "0.00000000"], ["84061.33000000", "0.00000000"], ["84061.32000000", "0.17828000"], ["84061.31000000", "0.61742000"], ["84061.30000000", "0.00000000"], ["84061.18000000", "0.25905000"], ["84061.15000000", "0.00760000"], ["84060.82000000", "0.27118000"], ["84060.64000000", "0.02334000"], ["84060.55000000", "0.04000000"], ["84060.01000000", "0.14275000"], ["84060.00000000", "0.02266000"], ["84059.82000000", "0.08992000"], ["84059.71000000", "0.08000000"], ["84059.65000000", "0.04000000"], ["84059.37000000", "0.00000000"], ["84058.30000000", "0.00000000"], ["84057.89000000", "0.00000000"], ["84057.20000000", "0.04000000"], ["84056.35000000", "0.04000000"], ["84056.31000000", "0.29580000"], ["84056.24000000", "0.01189000"], ["84055.51000000", "0.08000000"], ["84055.45000000", "0.04000000"], ["84054.94000000", "0.00000000"], ["84054.44000000", "0.15124000"], ["84054.11000000", "0.00000000"], ["84054.10000000", "0.00000000"], ["84054.04000000", "0.00000000"], ["84053.67000000", "0.00013000"], ["84053.47000000", "0.00000000"], ["84053.16000000", "0.00000000"], ["84052.31000000", "0.00000000"], ["84051.59000000", "0.00000000"], ["84051.19000000", "1.00000000"], ["84050.74000000", "0.00000000"], ["84049.89000000", "0.00000000"], ["84049.82000000", "0.00000000"], ["84049.58000000", "0.00000000"], ["84049.04000000", "0.59438000"], ["84048.05000000", "0.47551000"], ["84047.76000000", "0.00300000"], ["84047.58000000", "0.00000000"], ["84047.35000000", "0.05943000"], ["84046.60000000", "0.00500000"], ["84045.12000000", "0.00000000"], ["84042.67000000", "0.00000000"], ["84040.02000000", "0.85727000"], ["84039.93000000", "0.00358000"], ["84038.08000000", "0.59500000"], ["84038.05000000", "0.00000000"], ["84037.01000000", "0.00000000"], ["84036.36000000", "0.27677000"], ["84036.20000000", "0.03855000"], ["84031.09000000", "0.00000000"], ["84031.07000000", "0.00000000"], ["84028.19000000", "0.00935000"], ["84026.00000000", "0.00000000"], ["84022.93000000", "0.00000000"], ["84022.17000000", "0.00008000"], ["84017.92000000", "0.00000000"], ["84013.76000000", "0.00000000"], ["84012.47000000", "0.00000000"], ["84011.48000000", "0.47551000"], ["84010.83000000", "0.00821000"], ["84009.73000000", "0.00816000"], ["84006.43000000", "0.04000000"], ["84006.26000000", "0.04000000"], ["84004.33000000", "0.00821000"], ["83998.85000000", "0.00000000"], ["83997.55000000", "0.00072000"], ["83997.28000000", "0.00000000"], ["83995.93000000", "0.00000000"], ["83992.84000000", "0.00000000"], ["83992.80000000", "0.00000000"], ["83991.37000000", "0.00000000"], ["83989.03000000", "0.05189000"], ["83975.98000000", "0.00000000"], ["83971.44000000", "0.00000000"], ["83970.94000000", "0.00400000"], ["83957.42000000", "0.00000000"], ["83941.61000000", "0.12000000"], ["83935.02000000", "0.00000000"], ["83911.35000000", "0.99313000"], ["83906.35000000", "0.00000000"], ["83899.49000000", "0.01000000"], ["83899.19000000", "0.05951000"], ["83896.59000000", "0.00000000"], ["83887.23000000", "0.00000000"], ["83882.56000000", "0.00000000"], ["83851.97000000", "0.19323000"], ["83851.56000000", "0.00000000"], ["83848.70000000", "0.00000000"], ["83843.57000000", "0.06944000"], ["83843.16000000", "0.00000000"], ["83812.70000000", "0.00000000"], ["83003.50000000", "0.40000000"], ["82995.14000000", "0.00028000"], ["75658.00000000", "0.01321000"], ["75657.00000000", "0.00000000"], ["67251.67000000", "0.00058000"], ["67251.34000000", "0.00000000"], ["60000.00000000", "73.17018000"], ["50001.00000000", "1.82097000"], ["33000.00000000", "2.93827000"]], "a": [["84064.18000000", "0.00000000"], ["84064.19000000", "0.00000000"], ["84064.57000000", "0.00000000"], ["84064.58000000", "0.00000000"], ["84064.59000000", "0.01659000"], ["84064.60000000", "0.00042000"], ["84065.49000000", "0.00014000"], ["84065.50000000", "0.00500000"], ["84065.69000000", "0.00000000"], ["84065.94000000", "0.00000000"], ["84066.35000000", "0.00000000"], ["84066.69000000", "0.00000000"], ["84066.82000000", "0.00000000"], ["84067.71000000", "0.03183000"], ["84068.00000000", "0.02266000"], ["84068.48000000", "0.00000000"], ["84068.72000000", "0.00000000"], ["84068.98000000", "0.00014000"], ["84068.99000000", "0.78550000"], ["84069.03000000", "0.00000000"], ["84069.04000000", "0.15551000"], ["84069.61000000", "0.00000000"], ["84069.84000000", "0.00000000"], ["84069.85000000", "0.00027000"], ["84069.86000000", "0.34924000"], ["84070.00000000", "0.02260000"], ["84070.11000000", "0.00000000"], ["84070.38000000", "0.00000000"], ["84070.96000000", "0.00000000"], ["84071.63000000", "0.00000000"], ["84072.17000000", "0.05004000"], ["84072.38000000", "0.00417000"], ["84072.63000000", "0.00000000"], ["84072.78000000", "0.15496000"], ["84072.98000000", "0.00000000"], ["84073.10000000", "0.02220000"], ["84073.76000000", "0.03000000"], ["84074.13000000", "0.00000000"], ["84074.14000000", "0.00090000"], ["84074.18000000", "0.00091000"], ["84074.78000000", "0.00000000"], ["84075.63000000", "0.00000000"], ["84075.67000000", "0.00000000"], ["84075.72000000", "0.00000000"], ["84075.77000000", "0.00000000"], ["84075.79000000", "0.00000000"], ["84075.80000000", "0.00000000"], ["84075.82000000", "0.00000000"], ["84075.86000000", "0.00000000"], ["84075.93000000", "0.00000000"], ["84076.19000000", "0.00000000"], ["84076.26000000", "0.00000000"], ["84076.30000000", "0.00000000"], ["84076.34000000", "0.00000000"], ["84076.35000000", "0.00000000"], ["84076.36000000", "0.00000000"], ["84076.37000000", "0.01775000"], ["84077.64000000", "0.00000000"], ["84078.05000000", "0.00505000"], ["84078.93000000", "0.00000000"], ["84079.07000000", "0.00118000"], ["84079.80000000", "0.00006000"], ["84082.70000000", "0.60583000"], ["84083.11000000", "0.01189000"], ["84085.01000000", "0.00000000"], ["84085.86000000", "0.00000000"], ["84087.14000000", "0.00000000"], ["84088.09000000", "0.00000000"], ["84088.65000000", "0.00101000"], ["84088.95000000", "1.00000000"], ["84089.39000000", "0.05943000"], ["84090.57000000", "0.00000000"], ["84091.88000000", "0.00000000"], ["84092.71000000", "0.00000000"], ["84094.42000000", "0.00934000"], ["84095.28000000", "0.00006000"], ["84097.42000000", "0.01868000"], ["84099.51000000", "0.67018000"], ["84099.52000000", "0.85653000"], ["84102.24000000", "0.00352000"], ["84104.43000000", "0.00000000"], ["84105.03000000", "0.00000000"], ["84106.19000000", "0.00000000"], ["84106.21000000", "0.00588000"], ["84106.61000000", "0.05000000"], ["84107.66000000", "0.00000000"], ["84114.56000000", "0.00810000"], ["84114.94000000", "0.00827000"], ["84115.73000000", "0.02983000"], ["84120.70000000", "0.00000000"], ["84134.62000000", "0.00000000"], ["84142.69000000", "0.01863000"], ["84194.35000000", "0.00000000"], ["84194.81000000", "0.04639000"], ["84209.97000000", "0.00000000"], ["84232.46000000", "0.00000000"], ["84232.52000000", "0.00000000"], ["84232.66000000", "0.00000000"], ["84233.06000000", "0.01000000"], ["84291.36000000", "0.00013000"], ["84298.61000000", "0.00000000"], ["85035.70000000", "0.00000000"], ["85044.13000000", "0.60000000"], ["85517.80000000", "0.00595000"], ["85517.92000000", "0.00000000"]], "record_time": 1742555359.039502, "EXCHANGE": "BINANCE"}
{"e": "depthUpdate", "E": 1742556562014, "s": "BTCUSDT", "U": 64607716437, "u": 64607716640, "b": [["83961.00000000", "1.88898000"], ["83960.94000000", "0.00007000"], ["83960.66000000", "0.00021000"], ["83960.65000000", "0.33669000"], ["83960.16000000", "0.32084000"], ["83960.03000000", "0.00000000"], ["83960.02000000", "0.00000000"], ["83959.39000000", "0.01508000"], ["83959.35000000", "0.00000000"], ["83958.98000000", "0.00000000"], ["83958.94000000", "0.01507000"], ["83958.56000000", "0.00000000"], ["83958.55000000", "0.00000000"], ["83958.28000000", "0.00035000"], ["83958.27000000", "0.78648000"], ["83958.26000000", "0.06807000"], ["83957.97000000", "0.10145000"], ["83957.44000000", "0.00000000"], ["83957.41000000", "0.00000000"], ["83957.35000000", "0.02383000"], ["83956.93000000", "0.01922000"], ["83956.80000000", "0.01000000"], ["83956.73000000", "0.00000000"], ["83955.82000000", "0.04826000"], ["83951.25000000", "0.00000000"], ["83950.02000000", "0.00000000"], ["83950.01000000", "0.89106000"], ["83942.18000000", "0.00000000"], ["83941.84000000", "0.00874000"], ["83941.83000000", "0.41764000"], ["83939.29000000", "0.10627000"], ["83937.98000000", "0.00000000"], ["83931.65000000", "0.00000000"], ["83931.22000000", "0.00000000"], ["83929.95000000", "0.00759000"], ["83927.97000000", "0.59578000"], ["83918.33000000", "0.00000000"], ["83912.71000000", "0.00000000"], ["83909.06000000", "0.00000000"], ["83777.65000000", "0.00000000"], ["83772.22000000", "0.00400000"], ["83766.94000000", "0.00000000"], ["83545.97000000", "0.00000000"], ["83541.26000000", "1.19163000"], ["83126.14000000", "0.00000000"], ["83121.45000000", "1.78744000"], ["83121.39000000", "0.00000000"], ["82706.31000000", "0.00000000"], ["82701.65000000", "0.59582000"], ["79700.00000000", "1.69319000"], ["75564.00000000", "0.00000000"], ["67168.80000000", "0.00058000"], ["33000.00000000", "2.93827000"], ["30225.96000000", "0.00360000"]], "a": [["83961.01000000", "6.06563000"], ["83966.30000000", "0.04826000"], ["83966.41000000", "0.37963000"], ["83966.57000000", "0.00000000"], ["83974.86000000", "0.27820000"], ["83974.87000000", "0.00000000"], ["83976.83000000", "0.47612000"], ["83977.33000000", "0.00000000"], ["83979.24000000", "1.07523000"], ["83980.97000000", "0.00000000"], ["83981.20000000", "0.89273000"], ["83983.68000000", "0.95224000"], ["83984.84000000", "0.00935000"], ["83989.97000000", "0.01869000"], ["84001.42000000", "0.00000000"], ["84012.33000000", "0.00000000"], ["84012.37000000", "0.47612000"], ["84012.80000000", "0.00000000"], ["84012.81000000", "0.00000000"], ["84014.56000000", "0.03418000"], ["84046.36000000", "0.19557000"], ["84051.09000000", "0.27042000"], ["84054.01000000", "0.00000000"], ["84135.42000000", "0.01000000"], ["84138.13000000", "0.00000000"], ["84184.00000000", "0.00235000"], ["84380.86000000", "1.19163000"], ["84385.61000000", "0.00000000"], ["84800.66000000", "1.78744000"], ["84805.44000000", "0.00000000"], ["85220.47000000", "0.59582000"], ["85225.27000000", "0.00000000"]], "record_time": 1742556562.039434, "EXCHANGE": "BINANCE"}
{"e": "depthUpdate", "E": 1742556563014, "s": "BTCUSDT", "U": 64607716641, "u": 64607716724, "b": [["83961.00000000", "1.70336000"], ["83960.94000000", "0.00007000"], ["83960.74000000", "0.00021000"], ["83960.73000000", "0.01934000"], ["83960.66000000", "0.00014000"], ["83958.94000000", "0.01500000"], ["83958.28000000", "0.00021000"], ["83958.00000000", "0.00000000"], ["83941.84000000", "0.00000000"], ["83918.08000000", "0.00000000"], ["83917.72000000", "0.05000000"], ["83867.40000000", "1.39117000"], ["83843.39000000", "0.00076000"], ["83843.38000000", "0.00000000"], ["83830.95000000", "0.00000000"], ["83829.59000000", "0.18345000"], ["83772.22000000", "0.00000000"], ["83766.73000000", "0.00400000"], ["83760.73000000", "0.00063000"], ["83760.72000000", "0.00038000"], ["82995.16000000", "0.03213000"], ["75564.00000000", "0.00000000"], ["67168.80000000", "0.00058000"], ["33000.00000000", "2.93827000"], ["30225.96000000", "0.00380000"]], "a": [["83961.01000000", "6.22688000"], ["83974.86000000", "0.48088000"], ["83979.24000000", "1.06331000"], ["83983.68000000", "0.35709000"], ["84003.44000000", "0.12419000"], ["84007.65000000", "0.00000000"], ["84009.68000000", "0.82543000"], ["84012.04000000", "0.00000000"], ["84012.05000000", "0.00000000"], ["84012.50000000", "0.59515000"], ["84104.00000000", "0.00353000"], ["84135.12000000", "0.01000000"], ["84135.22000000", "0.00000000"], ["84135.32000000", "0.00000000"], ["84135.42000000", "0.00000000"], ["85035.66000000", "0.00000000"]], "record_time": 1742556563.039739, "EXCHANGE": "BINANCE"}
{"e": "depthUpdate", "E": 1742556564014, "s": "BTCUSDT", "U": 64607716725, "u": 64607716919, "b": [["83961.00000000", "4.03076000"], ["83960.94000000", "0.00021000"], ["83960.93000000", "0.39192000"], ["83960.92000000", "0.78652000"], ["83960.86000000", "0.11134000"], ["83960.83000000", "0.00000000"], ["83960.82000000", "0.00000000"], ["83960.75000000", "0.00000000"], ["83960.74000000", "0.00000000"], ["83960.66000000", "0.00000000"], ["83960.65000000", "0.33662000"], ["83960.17000000", "0.00000000"], ["83960.16000000", "0.00016000"], ["83959.39000000", "0.01501000"], ["83958.27000000", "0.00000000"], ["83958.26000000", "0.00000000"], ["83958.00000000", "0.00006000"], ["83956.93000000", "0.00000000"], ["83956.80000000", "0.01000000"], ["83949.41000000", "0.54527000"], ["83947.49000000", "0.00000000"], ["83945.06000000", "1.32440000"], ["83941.83000000", "0.41764000"], ["83941.76000000", "0.00895000"], ["83940.75000000", "0.85815000"], ["83931.67000000", "0.08992000"], ["83927.42000000", "0.00831000"], ["83924.36000000", "0.00000000"], ["83924.28000000", "0.64903000"], ["83924.27000000", "0.00000000"], ["83917.72000000", "0.00000000"], ["83811.14000000", "0.99313000"], ["83801.14000000", "0.00400000"], ["83790.58000000", "0.00000000"], ["83775.25000000", "0.00000000"], ["83766.73000000", "0.00000000"], ["83003.52000000", "0.40000000"], ["75564.00000000", "0.00000000"], ["67168.80000000", "0.00058000"], ["33000.00000000", "2.93827000"], ["30225.96000000", "0.00400000"]], "a": [["83961.01000000", "4.00127000"], ["83962.00000000", "0.02267000"], ["83964.51000000", "0.04007000"], ["83964.54000000", "0.02468000"], ["83971.28000000", "0.00090000"], ["83971.63000000", "0.00000000"], ["83977.01000000", "0.59515000"], ["83977.80000000", "0.06010000"], ["83982.12000000", "0.00000000"], ["83983.61000000", "2.16478000"], ["83983.68000000", "0.35709000"], ["83986.46000000", "1.32311000"], ["83987.99000000", "0.47006000"], ["83988.15000000", "0.05951000"], ["83989.14000000", "0.00000000"], ["83993.63000000", "0.00000000"], ["83996.57000000", "0.59577000"], ["83998.93000000", "0.00000000"], ["84012.06000000", "0.00000000"], ["84012.28000000", "0.59515000"], ["84012.50000000", "0.00000000"], ["84029.25000000", "0.41399000"], ["84045.01000000", "0.00000000"], ["84105.41000000", "0.45743000"], ["84106.17000000", "0.99263000"], ["84135.12000000", "0.01000000"], ["85044.08000000", "0.60000000"]], "record_time": 1742556564.03982, "EXCHANGE": "BINANCE"}
{"e": "depthUpdate", "E": 1742556565014, "s": "BTCUSDT", "U": 64607716920, "u": 64607717120, "b": [["83961.00000000", "2.29398000"], ["83960.98000000", "0.00021000"], ["83960.97000000", "0.12082000"], ["83960.94000000", "0.00029000"], ["83960.93000000", "0.39178000"], ["83960.92000000", "0.00000000"], ["83960.86000000", "0.00000000"], ["83960.65000000", "0.33669000"], ["83960.16000000", "0.00000000"], ["83958.95000000", "0.78647000"], ["83958.91000000", "0.04826000"], ["83958.20000000", "0.00000000"], ["83958.10000000", "0.00000000"], ["83956.80000000", "0.00000000"], ["83955.82000000", "0.00000000"], ["83952.62000000", "0.00595000"], ["83948.10000000", "0.00700000"], ["83945.09000000", "1.34540000"], ["83945.06000000", "0.00000000"], ["83941.76000000", "0.00000000"], ["83940.75000000", "0.00000000"], ["83938.68000000", "0.02382000"], ["83927.21000000", "0.85829000"], ["83923.92000000", "0.00000000"], ["83923.07000000", "0.00000000"], ["83890.62000000", "0.00298000"], ["83884.64000000", "0.01692000"], ["83882.22000000", "0.00603000"], ["83873.83000000", "0.00895000"], ["83867.40000000", "0.00000000"], ["83865.44000000", "0.01194000"], ["83857.05000000", "0.01493000"], ["83817.59000000", "0.00000000"], ["83810.15000000", "0.00000000"], ["83806.21000000", "0.00000000"], ["83802.52000000", "0.00000000"], ["83801.14000000", "0.00000000"], ["83795.33000000", "0.00400000"], ["75564.00000000", "0.00000000"], ["67168.80000000", "0.00058000"], ["42000.00000000", "6.85261000"], ["33000.00000000", "2.93827000"]], "a": [["83961.01000000", "4.76423000"], ["83961.12000000", "0.00007000"], ["83961.29000000", "0.00007000"], ["83961.33000000", "0.78652000"], ["83962.00000000", "0.02267000"], ["83962.71000000", "0.00000000"], ["83962.80000000", "0.00000000"], ["83963.06000000", "0.00000000"], ["83963.08000000", "0.00000000"], ["83963.41000000", "0.00000000"], ["83963.45000000", "0.00000000"], ["83964.26000000", "0.00007000"], ["83964.51000000", "0.00000000"], ["83964.54000000", "0.02475000"], ["83966.30000000", "0.00000000"], ["83967.99000000", "0.00000000"], ["83969.19000000", "0.04826000"], ["83970.64000000", "0.00000000"], ["83977.80000000", "0.00059000"], ["83978.30000000", "0.00000000"], ["83983.68000000", "0.00000000"], ["83986.19000000", "0.05951000"], ["83986.46000000", "0.00000000"], ["83987.28000000", "1.36499000"], ["83988.40000000", "0.00000000"], ["83996.57000000", "0.00000000"], ["83996.93000000", "0.35709000"], ["84000.08000000", "0.59574000"], ["84007.50000000", "0.00400000"], ["84012.28000000", "0.00000000"], ["84017.60000000", "0.00000000"], ["84049.80000000", "0.00298000"], ["84050.80000000", "0.00000000"], ["84058.20000000", "0.00597000"], ["84059.21000000", "0.00000000"], ["84066.60000000", "0.00895000"], ["84067.61000000", "0.00000000"], ["84075.01000000", "0.01194000"], ["84076.01000000", "0.00000000"], ["84083.81000000", "0.01493000"], ["84084.41000000", "0.00000000"], ["85858.79000000", "0.00000000"]], "record_time": 1742556565.039708, "EXCHANGE": "BINANCE"}
{"e": "depthUpdate", "E": 1742556566014, "s": "BTCUSDT", "U": 64607717121, "u": 64607717277, "b": [["83961.00000000", "2.58424000"], ["83960.98000000", "0.00007000"], ["83960.97000000", "0.00007000"], ["83960.93000000", "0.39178000"], ["83960.73000000", "0.00000000"], ["83960.66000000", "0.00014000"], ["83960.65000000", "0.33669000"], ["83960.00000000", "0.08189000"], ["83959.82000000", "0.00000000"], ["83959.40000000", "0.00010000"], ["83959.39000000", "0.01508000"], ["83959.03000000", "0.00000000"], ["83958.99000000", "0.00989000"], ["83958.95000000", "0.78647000"], ["83958.32000000", "0.00000000"], ["83958.28000000", "0.00000000"], ["83957.35000000", "0.00000000"], ["83957.28000000", "0.00000000"], ["83956.80000000", "0.00500000"], ["83952.62000000", "0.00000000"], ["83948.10000000", "0.00000000"], ["83945.09000000", "1.34143000"], ["83941.76000000", "0.00000000"], ["83932.55000000", "0.00760000"], ["83929.95000000", "0.00000000"], ["83928.43000000", "1.07422000"], ["83921.09000000", "0.00000000"], ["83920.96000000", "0.05000000"], ["83884.64000000", "0.00000000"], ["83861.74000000", "1.39117000"], ["83843.40000000", "0.00000000"], ["83843.39000000", "0.00000000"], ["83795.33000000", "0.00000000"], ["83789.27000000", "0.00000000"], ["83788.78000000", "0.00400000"], ["83781.33000000", "0.00000000"], ["83760.74000000", "0.00000000"], ["83760.73000000", "0.00000000"], ["83542.00000000", "0.01212000"], ["83150.00000000", "0.54705000"], ["75564.00000000", "0.00000000"], ["67168.80000000", "0.00058000"], ["60000.00000000", "73.14793000"], ["42000.00000000", "6.85161000"], ["33000.00000000", "2.93827000"], ["30225.96000000", "0.00460000"], ["20002.00000000", "0.00000000"], ["20001.00000000", "0.02099000"]], "a": [["83961.01000000", "4.55063000"], ["83966.00000000", "0.02285000"], ["83966.41000000", "0.37940000"], ["83971.28000000", "0.00000000"], ["83977.01000000", "0.00000000"], ["83977.80000000", "0.06010000"], ["83978.26000000", "0.00091000"], ["83983.68000000", "0.59515000"], ["83987.28000000", "1.33873000"], ["83988.15000000", "0.00000000"], ["84007.50000000", "0.00000000"], ["84012.97000000", "0.00000000"], ["85858.83000000", "0.01065000"]], "record_time": 1742556566.039781, "EXCHANGE": "BINANCE"}
{"e": "depthUpdate", "E": 1742556567014, "s": "BTCUSDT", "U": 64607717278, "u": 64607717361, "b": [["83961.00000000", "2.86459000"], ["83960.65000000", "0.33669000"], ["83960.04000000", "0.01925000"], ["83959.39000000", "0.01501000"], ["83959.04000000", "0.00000000"], ["83958.99000000", "0.00000000"], ["83957.26000000", "0.02430000"], ["83945.09000000", "1.37844000"], ["83843.41000000", "0.00076000"], ["83790.02000000", "0.00008000"], ["83760.75000000", "0.00063000"], ["83649.80000000", "0.00019000"], ["83625.15000000", "0.00150000"], ["83218.38000000", "0.00000000"], ["83218.34000000", "0.00060000"], ["83208.53000000", "0.00000000"], ["83208.49000000", "0.00060000"], ["83121.39000000", "0.00000000"], ["75564.00000000", "0.00000000"], ["67168.80000000", "0.00058000"], ["33000.00000000", "2.93827000"], ["30225.96000000", "0.00500000"]], "a": [["83961.01000000", "4.71101000"], ["83966.41000000", "0.14213000"], ["83966.42000000", "0.02078000"], ["83967.88000000", "0.00000000"], ["83968.72000000", "0.00000000"], ["83969.56000000", "0.00000000"], ["83977.80000000", "0.00059000"], ["83983.68000000", "0.00000000"], ["83984.73000000", "0.00000000"], ["83986.54000000", "1.36306000"], ["83987.28000000", "0.00000000"], ["83988.15000000", "0.05951000"], ["84012.46000000", "0.59515000"], ["84013.04000000", "0.00000000"], ["84013.05000000", "0.00000000"], ["84014.56000000", "0.00000000"], ["84135.02000000", "0.01000000"], ["84135.12000000", "0.00000000"]], "record_time": 1742556567.039273, "EXCHANGE": "BINANCE"}
{"e": "depthUpdate", "E": 1742556568014, "s": "BTCUSDT", "U": 64607717362, "u": 64607717475, "b": [["83961.00000000", "2.76755000"], ["83960.95000000", "0.00021000"], ["83960.94000000", "0.11717000"], ["83960.93000000", "0.39178000"], ["83960.78000000", "0.00014000"], ["83960.77000000", "0.78652000"], ["83960.66000000", "0.00000000"], ["83960.04000000", "0.01918000"], ["83960.00000000", "0.00299000"], ["83959.79000000", "0.00000000"], ["83958.95000000", "0.00000000"], ["83956.80000000", "0.01000000"], ["83945.09000000", "1.33777000"], ["83941.60000000", "0.00909000"], ["83940.91000000", "0.85815000"], ["83927.21000000", "0.00000000"], ["83922.51000000", "0.05000000"], ["83920.96000000", "0.00000000"], ["83912.71000000", "0.00000000"], ["83843.42000000", "0.00076000"], ["83843.41000000", "0.00000000"], ["83802.76000000", "0.00000000"], ["83796.81000000", "0.00400000"], ["83795.08000000", "0.00000000"], ["83788.78000000", "0.00000000"], ["83776.47000000", "0.01865000"], ["83760.76000000", "0.00063000"], ["83760.75000000", "0.00000000"], ["83000.00000000", "35.26414000"], ["79700.00000000", "1.69319000"], ["75564.00000000", "0.00000000"], ["67168.80000000", "0.00058000"], ["33000.00000000", "2.93827000"], ["30225.96000000", "0.00520000"]], "a": [["83961.01000000", "4.09543000"], ["83966.41000000", "0.45730000"], ["83967.88000000", "0.23830000"], ["83968.72000000", "0.23830000"], ["83969.56000000", "0.23830000"], ["83970.40000000", "0.23830000"], ["83970.87000000", "0.00092000"], ["83974.86000000", "0.46896000"], ["83981.74000000", "0.01865000"], ["83986.54000000", "0.00000000"], ["83987.27000000", "1.37167000"], ["84014.56000000", "0.03418000"], ["84034.22000000", "0.00041000"], ["84034.23000000", "0.00000000"], ["84046.36000000", "0.19699000"], ["84046.51000000", "0.81882000"], ["84048.36000000", "1.10680000"], ["84080.74000000", "0.18345000"], ["84082.65000000", "0.00000000"], ["84106.17000000", "0.99831000"], ["84109.77000000", "0.00035000"], ["84109.78000000", "0.00000000"], ["84147.72000000", "0.03097000"]], "record_time": 1742556568.039736, "EXCHANGE": "BINANCE"}
{"e": "depthUpdate", "E": 1742556569014, "s": "BTCUSDT", "U": 64607717476, "u": 64607717600, "b": [["83961.00000000", "3.14629000"], ["83960.94000000", "0.11796000"], ["83945.10000000", "1.35110000"], ["83945.09000000", "0.00000000"], ["83941.83000000", "0.41764000"], ["83933.70000000", "0.59574000"], ["83928.43000000", "0.71781000"], ["83927.97000000", "0.00000000"], ["83922.51000000", "0.00000000"], ["83912.71000000", "0.00000000"], ["83884.64000000", "0.01692000"], ["83866.65000000", "0.19267000"], ["83865.75000000", "0.00000000"], ["83851.77000000", "0.00000000"], ["83849.11000000", "0.04645000"], ["83845.02000000", "0.05097000"], ["83842.22000000", "0.05097000"], ["83780.14000000", "0.00000000"], ["83776.47000000", "0.00000000"], ["83729.62000000", "0.00000000"], ["83003.52000000", "0.00000000"], ["75564.00000000", "0.00000000"], ["67168.80000000", "0.00058000"], ["33000.00000000", "2.93827000"], ["30353.47000000", "0.00020000"], ["30341.98000000", "0.00160000"], ["30341.81000000", "0.00220000"], ["30338.78000000", "0.00120000"], ["30336.73000000", "0.00040000"], ["30336.48000000", "0.00000000"], ["30336.06000000", "0.00020000"], ["30333.40000000", "0.00120000"], ["30328.68000000", "0.00060000"], ["30327.87000000", "0.00060000"], ["30326.24000000", "0.00680000"], ["30321.82000000", "0.00000000"], ["30320.64000000", "0.00040000"], ["30313.36000000", "0.00060000"], ["30312.66000000", "0.00180000"], ["30312.63000000", "0.00140000"], ["30312.00000000", "0.00840000"], ["30311.53000000", "0.00020000"], ["30307.48000000", "0.00000000"], ["30306.07000000", "0.00000000"], ["30296.42000000", "0.00320000"], ["30296.05000000", "0.00000000"], ["30295.98000000", "0.00020000"], ["30292.34000000", "0.00040000"], ["30290.87000000", "0.00540000"], ["30286.54000000", "0.00000000"], ["30284.73000000", "0.00000000"], ["30284.25000000", "0.00000000"], ["30283.40000000", "0.00000000"], ["30225.96000000", "0.00540000"]], "a": [["83961.01000000", "4.08245000"], ["83961.12000000", "0.00007000"], ["83961.28000000", "0.00007000"], ["83961.29000000", "0.00007000"], ["83961.32000000", "0.30510000"], ["83964.54000000", "0.02475000"], ["83970.84000000", "0.00000000"], ["83970.86000000", "0.00092000"], ["83970.87000000", "0.00000000"], ["83981.74000000", "0.00000000"], ["83981.96000000", "0.71284000"], ["83983.68000000", "0.59515000"], ["83987.27000000", "1.32949000"], ["84012.46000000", "0.00000000"], ["84032.51000000", "0.01865000"], ["84063.96000000", "0.19487000"], ["84087.77000000", "0.00000000"], ["84090.84000000", "0.00000000"], ["84135.02000000", "0.01000000"], ["85044.08000000", "0.00000000"]], "record_time": 1742556569.040471, "EXCHANGE": "BINANCE"}
{"e": "depthUpdate", "E": 1742556570014, "s": "BTCUSDT", "U": 64607717601, "u": 64607717680, "b": [["83961.00000000", "2.45459000"], ["83960.98000000", "0.00021000"], ["83960.97000000", "0.12142000"], ["83960.95000000", "0.00007000"], ["83960.94000000", "0.00029000"], ["83960.04000000", "0.01918000"], ["83956.80000000", "0.00000000"], ["83945.10000000", "1.34971000"], ["83933.70000000", "0.00000000"], ["83931.22000000", "0.59576000"], ["83920.12000000", "0.00000000"], ["83918.08000000", "0.00000000"], ["83796.81000000", "0.00000000"], ["83791.56000000", "0.00400000"], ["82995.16000000", "0.43213000"], ["75564.00000000", "0.00000000"], ["67168.80000000", "0.00058000"], ["33000.00000000", "2.93827000"], ["30225.96000000", "0.00580000"]], "a": [["83961.01000000", "4.53370000"], ["83970.86000000", "0.00000000"], ["83976.39000000", "0.00000000"], ["83983.68000000", "0.59515000"], ["83987.27000000", "1.31017000"], ["83988.55000000", "0.00000000"], ["83997.65000000", "0.00000000"], ["84008.50000000", "0.00500000"], ["84012.34000000", "0.00000000"], ["84012.42000000", "0.00000000"], ["84032.51000000", "0.00000000"], ["84135.02000000", "0.00000000"], ["84136.62000000", "0.00000000"], ["84137.02000000", "0.01000000"], ["84444.64000000", "11.84776000"], ["84543.39000000", "0.00000000"], ["85035.65000000", "0.60000000"]], "record_time": 1742556570.040667, "EXCHANGE": "BINANCE"}
{"e": "depthUpdate", "E": 1742556571014, "s": "BTCUSDT", "U": 64607717681, "u": 64607717771, "b": [["83961.00000000", "2.28857000"], ["83958.82000000", "0.01920000"], ["83958.20000000", "0.00000000"], ["83958.10000000", "0.00400000"], ["83948.10000000", "0.00400000"], ["83941.60000000", "0.00000000"], ["83932.24000000", "0.51280000"], ["83923.08000000", "0.05000000"], ["83921.70000000", "0.01300000"], ["83872.88000000", "0.93014000"], ["83870.23000000", "1.39117000"], ["83861.74000000", "0.00000000"], ["83797.81000000", "0.00400000"], ["83791.56000000", "0.00000000"], ["82000.00000000", "65.11690000"], ["75564.00000000", "0.00000000"], ["67168.80000000", "0.00058000"], ["57880.71000000", "0.00000000"], ["55836.29000000", "0.00000000"], ["53864.07000000", "0.00000000"], ["51961.52000000", "0.00020000"], ["50126.17000000", "0.00000000"], ["48355.64000000", "0.00000000"], ["46647.65000000", "0.00000000"], ["45000.00000000", "17.49032000"], ["33000.00000000", "2.93827000"], ["20002.00000000", "0.00000000"], ["20001.00000000", "0.02099000"]], "a": [["83961.01000000", "4.53354000"], ["83961.28000000", "0.00021000"], ["83961.29000000", "0.01911000"], ["83964.54000000", "0.02468000"], ["83964.70000000", "0.04000000"], ["83967.88000000", "0.00000000"], ["83968.72000000", "0.00000000"], ["83969.56000000", "0.00000000"], ["83970.40000000", "0.00000000"], ["83970.82000000", "0.00000000"], ["83970.83000000", "0.00000000"], ["83971.79000000", "0.02407000"], ["83978.30000000", "0.00000000"], ["83979.30000000", "0.00000000"], ["83979.72000000", "0.85776000"], ["83988.40000000", "0.00000000"], ["83993.19000000", "0.00000000"], ["84007.50000000", "0.00000000"], ["84008.50000000", "0.00000000"], ["84017.60000000", "0.00400000"]], "record_time": 1742556571.04116, "EXCHANGE": "BINANCE"}
{"e": "depthUpdate", "E": 1742556572014, "s": "BTCUSDT", "U": 64607717772, "u": 64607717841, "b": [["83961.00000000", "2.88725000"], ["83958.82000000", "0.00000000"], ["83958.10000000", "0.00000000"], ["83948.10000000", "0.00000000"], ["83939.29000000", "0.00000000"], ["83938.06000000", "0.10627000"], ["83923.08000000", "0.00000000"], ["83908.15000000", "0.00000000"], ["83899.61000000", "0.00000000"], ["83804.05000000", "0.00400000"], ["83797.81000000", "0.00000000"], ["83655.00000000", "0.00418000"], ["81800.00000000", "6.02108000"], ["78000.00000000", "145.91530000"], ["75564.00000000", "0.00000000"], ["67168.80000000", "0.00058000"], ["33000.00000000", "2.93827000"], ["30225.96000000", "0.00600000"]], "a": [["83961.01000000", "3.75929000"], ["83966.41000000", "0.15405000"], ["83971.07000000", "0.00000000"], ["83983.68000000", "0.00000000"], ["84008.50000000", "0.00500000"], ["84013.28000000", "0.21276000"], ["84013.29000000", "0.59515000"], ["84014.56000000", "0.00000000"], ["84017.60000000", "0.00000000"], ["84087.99000000", "0.00000000"], ["84088.04000000", "0.05497000"], ["84088.84000000", "0.00000000"], ["84089.13000000", "0.00000000"], ["84089.68000000", "0.00841000"], ["84091.40000000", "0.05497000"], ["84092.94000000", "0.00000000"], ["84095.85000000", "0.05497000"], ["84105.41000000", "0.45735000"], ["84106.17000000", "0.99238000"], ["84260.44000000", "0.00000000"], ["84800.61000000", "0.00000000"], ["85000.00000000", "12.58618000"]], "record_time": 1742556572.039592, "EXCHANGE": "BINANCE"}
{"e": "depthUpdate", "E": 1742556573014, "s": "BTCUSDT", "U": 64607717842, "u": 64607717904, "b": [["83961.00000000", "2.69972000"], ["83937.33000000", "0.00000000"], ["83937.30000000", "0.03574000"], ["83921.23000000", "0.00000000"], ["83920.02000000", "0.00000000"], ["83919.69000000", "0.26526000"], ["83919.48000000", "0.37740000"], ["83918.82000000", "0.00000000"], ["83804.05000000", "0.00000000"], ["83797.33000000", "0.00400000"], ["75564.00000000", "0.00000000"], ["67168.80000000", "0.00058000"], ["33000.00000000", "2.93827000"]], "a": [["83961.01000000", "4.53206000"], ["83974.94000000", "0.00000000"], ["83979.30000000", "0.00500000"], ["83983.68000000", "0.59515000"], ["83991.33000000", "0.00000000"], ["83993.67000000", "0.05000000"], ["83995.65000000", "0.00119000"], ["84000.00000000", "0.00072000"], ["84010.44000000", "0.00000000"], ["84012.34000000", "0.00000000"], ["84013.28000000", "0.00000000"], ["84013.29000000", "0.00000000"], ["84014.56000000", "0.03418000"], ["84048.36000000", "1.10680000"], ["84052.61000000", "0.00008000"], ["84372.40000000", "0.00000000"]], "record_time": 1742556573.040555, "EXCHANGE": "BINANCE"}
{"e": "depthUpdate", "E": 1742556574014, "s": "BTCUSDT", "U": 64607717905, "u": 64607717972, "b": [["83961.00000000", "2.91134000"], ["83956.80000000", "0.00500000"], ["83941.83000000", "0.41764000"], ["83941.26000000", "0.00889000"], ["83921.70000000", "0.00000000"], ["83919.12000000", "0.05000000"], ["83915.58000000", "0.00000000"], ["83003.52000000", "0.40000000"], ["82995.16000000", "0.03213000"], ["79700.00000000", "1.69319000"], ["75564.00000000", "0.00000000"], ["67168.80000000", "0.00058000"], ["33000.00000000", "2.93827000"]], "a": [["83961.01000000", "4.07894000"], ["83961.02000000", "0.00048000"], ["83983.68000000", "0.00000000"], ["84008.50000000", "0.00000000"], ["84012.18000000", "0.59515000"], ["84012.31000000", "0.00000000"], ["84042.27000000", "0.57538000"], ["84045.53000000", "1.10680000"], ["84046.51000000", "0.58512000"], ["84048.36000000", "0.00000000"], ["84083.66000000", "0.04645000"], ["84088.04000000", "0.00000000"], ["84088.63000000", "0.05497000"], ["84091.40000000", "0.00000000"], ["84091.86000000", "0.05497000"], ["84095.85000000", "0.00000000"], ["84096.11000000", "0.05497000"], ["84123.98000000", "0.00000000"], ["84126.34000000", "0.00000000"], ["84137.02000000", "0.01000000"], ["85035.65000000", "0.00000000"], ["85044.08000000", "0.60000000"]], "record_time": 1742556574.04013, "EXCHANGE": "BINANCE"}
{"e": "depthUpdate", "E": 1742556575014, "s": "BTCUSDT", "U": 64607717973, "u": 64607718150, "b": [["83961.00000000", "3.11839000"], ["83956.80000000", "0.01000000"], ["83952.62000000", "0.09587000"], ["83945.18000000", "2.78300000"], ["83944.56000000", "0.85821000"], ["83937.04000000", "0.59573000"], ["83932.24000000", "0.36761000"], ["83931.22000000", "0.00000000"], ["83928.43000000", "0.46032000"], ["83927.96000000", "0.00000000"], ["83923.97000000", "0.00000000"], ["83921.80000000", "0.00000000"], ["83919.12000000", "0.00000000"], ["83821.86000000", "0.00400000"], ["83811.00000000", "0.00000000"], ["83803.29000000", "0.00000000"], ["83797.33000000", "0.00000000"], ["80411.00000000", "0.00000000"], ["79900.00000000", "5.54236000"], ["78990.00000000", "0.22392000"], ["77990.00000000", "0.03582000"], ["76990.00000000", "0.00344000"], ["75990.00000000", "1.01075000"], ["75564.00000000", "0.00000000"], ["74990.00000000", "0.07068000"], ["67168.80000000", "0.00058000"], ["42000.00000000", "6.85261000"], ["33000.00000000", "2.93827000"], ["30225.96000000", "0.00640000"]], "a": [["83961.01000000", "1.11683000"], ["83961.32000000", "0.30496000"], ["83961.33000000", "0.00000000"], ["83962.00000000", "0.02267000"], ["83962.71000000", "0.00014000"], ["83962.72000000", "0.78651000"], ["83962.95000000", "0.00000000"], ["83962.96000000", "0.00000000"], ["83963.13000000", "0.08084000"], ["83963.41000000", "0.00007000"], ["83963.71000000", "0.15313000"], ["83964.26000000", "0.00000000"], ["83964.35000000", "0.02213000"], ["83964.59000000", "0.00000000"], ["83964.60000000", "0.00000000"], ["83966.06000000", "0.00000000"], ["83966.41000000", "0.26431000"], ["83968.70000000", "0.00011000"], ["83969.19000000", "0.00000000"], ["83969.47000000", "0.35709000"], ["83970.58000000", "0.00096000"], ["83971.38000000", "0.00090000"], ["83972.06000000", "0.04826000"], ["83976.01000000", "0.00000000"], ["83976.14000000", "0.59515000"], ["83977.23000000", "0.00000000"], ["83978.27000000", "0.12464000"], ["83979.30000000", "0.00000000"], ["83979.72000000", "0.00000000"], ["83981.96000000", "0.00000000"], ["83992.35000000", "0.85763000"], ["83992.43000000", "0.00000000"], ["83993.67000000", "0.00000000"], ["83994.03000000", "0.00000000"], ["83996.71000000", "0.00000000"], ["84002.83000000", "0.00000000"], ["84003.10000000", "0.02383000"], ["84034.21000000", "0.00041000"], ["84034.22000000", "0.00000000"], ["84039.75000000", "0.04335000"], ["84042.27000000", "0.30446000"], ["84045.20000000", "0.00000000"], ["84045.53000000", "0.00000000"], ["84059.66000000", "0.81030000"], ["84059.67000000", "1.10680000"], ["84060.22000000", "0.05397000"], ["84088.62000000", "0.05497000"], ["84088.63000000", "0.00000000"], ["84091.86000000", "0.05497000"], ["84092.79000000", "0.30767000"], ["84093.82000000", "0.05097000"], ["84096.11000000", "0.00000000"], ["84096.25000000", "0.05497000"], ["84109.76000000", "0.00035000"], ["84109.77000000", "0.00000000"], ["84122.89000000", "0.00000000"], ["84134.34000000", "0.00000000"]], "record_time": 1742556575.04286, "EXCHANGE": "BINANCE"}
{"e": "depthUpdate", "E": 1742556576014, "s": "BTCUSDT", "U": 64607718151, "u": 64607718238, "b": [["83961.00000000", "3.11764000"], ["83956.80000000", "0.01000000"], ["83952.62000000", "0.00595000"], ["83949.58000000", "0.58628000"], ["83949.57000000", "1.00000000"], ["83949.41000000", "0.00000000"], ["83945.65000000", "0.10790000"], ["83937.04000000", "0.00000000"], ["83933.97000000", "0.59573000"], ["83928.45000000", "0.00000000"], ["83926.68000000", "0.00000000"], ["83790.02000000", "0.00000000"], ["76700.00000000", "8.07799000"], ["75564.00000000", "0.00000000"], ["67168.80000000", "0.00058000"], ["60000.00000000", "73.14793000"], ["42000.00000000", "6.85161000"], ["33000.00000000", "2.93827000"], ["30225.96000000", "0.00660000"], ["20002.00000000", "0.00000000"], ["20001.00000000", "0.02099000"]], "a": [["83961.01000000", "1.65759000"], ["83964.70000000", "0.00000000"], ["83966.41000000", "0.14213000"], ["83968.36000000", "0.00000000"], ["83969.47000000", "0.00000000"], ["83970.54000000", "0.00097000"], ["83970.58000000", "0.00000000"], ["83974.47000000", "0.15105000"], ["83982.13000000", "0.00000000"], ["83996.93000000", "0.00000000"], ["83997.79000000", "0.35709000"], ["84007.57000000", "0.00640000"], ["84008.44000000", "0.00000000"], ["84034.20000000", "0.00041000"], ["84034.21000000", "0.00000000"], ["84039.75000000", "0.00000000"], ["84083.51000000", "0.00000000"], ["84084.87000000", "0.00000000"], ["84087.97000000", "0.00000000"], ["84088.62000000", "0.00000000"], ["84089.13000000", "0.00841000"], ["84089.68000000", "0.00000000"], ["84091.86000000", "0.00000000"], ["84092.23000000", "0.05497000"], ["84095.92000000", "0.05497000"], ["84096.25000000", "0.00000000"], ["84106.17000000", "0.99458000"], ["84109.75000000", "0.00035000"], ["84109.76000000", "0.00000000"], ["84120.00000000", "0.00235000"], ["84120.89000000", "0.00000000"], ["84128.92000000", "0.01141000"]], "record_time": 1742556576.040661, "EXCHANGE": "BINANCE"}
{"e": "depthUpdate", "E": 1742556577014, "s": "BTCUSDT", "U": 64607718239, "u": 64607718411, "b": [["83961.00000000", "3.70035000"], ["83958.30000000", "0.00000000"], ["83958.20000000", "0.00000000"], ["83958.10000000", "0.00000000"], ["83957.29000000", "0.02382000"], ["83956.80000000", "0.00000000"], ["83954.04000000", "0.00000000"], ["83953.84000000", "0.05962000"], ["83953.02000000", "0.05955000"], ["83952.61000000", "0.17865000"], ["83952.01000000", "0.05955000"], ["83951.94000000", "0.00595000"], ["83950.79000000", "0.17865000"], ["83948.10000000", "0.00000000"], ["83941.26000000", "0.00000000"], ["83941.13000000", "0.00897000"], ["83928.78000000", "0.00595000"], ["83927.61000000", "0.00000000"], ["83917.71000000", "0.00000000"], ["83892.04000000", "0.05955000"], ["83827.11000000", "0.00000000"], ["83821.86000000", "0.00000000"], ["83818.11000000", "0.00400000"], ["83576.43000000", "0.00000000"], ["83575.99000000", "0.00360000"], ["83072.43000000", "0.00000000"], ["83071.99000000", "0.00150000"], ["75564.00000000", "0.00000000"], ["67168.80000000", "0.00058000"], ["33000.00000000", "2.93827000"], ["30225.96000000", "0.00680000"]], "a": [["83961.01000000", "1.56739000"], ["83961.32000000", "0.36514000"], ["83962.00000000", "0.02267000"], ["83962.71000000", "0.00000000"], ["83962.72000000", "0.00000000"], ["83962.87000000", "0.00000000"], ["83962.88000000", "0.00000000"], ["83963.12000000", "0.00000000"], ["83963.13000000", "0.08091000"], ["83963.24000000", "0.00014000"], ["83963.25000000", "0.78643000"], ["83963.33000000", "0.04000000"], ["83963.69000000", "0.00000000"], ["83963.70000000", "0.00000000"], ["83964.66000000", "0.00000000"], ["83964.67000000", "0.00000000"], ["83965.16000000", "0.00755000"], ["83968.70000000", "0.00000000"], ["83969.31000000", "0.00011000"], ["83972.06000000", "0.04826000"], ["83978.30000000", "0.00000000"], ["83979.30000000", "0.00000000"], ["83981.96000000", "0.71284000"], ["83982.34000000", "0.00000000"], ["83988.40000000", "0.00000000"], ["83990.48000000", "0.37740000"], ["83991.15000000", "0.00000000"], ["83993.07000000", "0.06000000"], ["83996.37000000", "0.08000000"], ["84007.50000000", "0.00000000"], ["84008.44000000", "0.05000000"], ["84017.60000000", "0.00400000"], ["84023.09000000", "0.01895000"], ["84042.94000000", "0.00000000"], ["84046.26000000", "0.00000000"], ["84800.61000000", "0.00000000"], ["86463.46000000", "0.00000000"], ["86464.02000000", "0.00147000"], ["86988.02000000", "0.00352000"], ["86988.46000000", "0.00000000"]], "record_time": 1742556577.040319, "EXCHANGE": "BINANCE"}
{"e": "depthUpdate", "E": 1742556578014, "s": "BTCUSDT", "U": 64607718412, "u": 64607718783, "b": [["83961.00000000", "4.30836000"], ["83960.97000000", "0.12148000"], ["83960.93000000", "0.39184000"], ["83960.77000000", "0.78658000"], ["83960.65000000", "0.33675000"], ["83960.27000000", "0.00000000"], ["83960.04000000", "0.01924000"], ["83960.00000000", "0.02565000"], ["83959.39000000", "0.01507000"], ["83958.94000000", "0.01506000"], ["83958.91000000", "0.04832000"], ["83956.92000000", "0.00595000"], ["83956.80000000", "0.00500000"], ["83955.68000000", "0.08992000"], ["83953.56000000", "0.15686000"], ["83952.72000000", "0.17865000"], ["83948.88000000", "0.00000000"], ["83948.24000000", "0.85808000"], ["83946.30000000", "0.08992000"], ["83944.33000000", "0.00595000"], ["83941.13000000", "0.00886000"], ["83935.71000000", "0.04534000"], ["83932.24000000", "0.12434000"], ["83932.23000000", "0.00000000"], ["83930.25000000", "0.02805000"], ["83928.62000000", "0.00000000"], ["83920.41000000", "0.00000000"], ["83918.11000000", "0.00000000"], ["83896.86000000", "0.01895000"], ["83839.27000000", "0.12000000"], ["83839.20000000", "0.00400000"], ["83830.85000000", "0.00000000"], ["83824.22000000", "0.00000000"], ["83818.11000000", "0.00000000"], ["83752.23000000", "0.01865000"], ["80572.80000000", "0.00000000"], ["80555.99000000", "0.00000000"], ["76700.00000000", "8.07170000"], ["75564.00000000", "0.00000000"], ["67168.80000000", "0.00058000"], ["33000.00000000", "2.93827000"], ["30225.96000000", "0.00720000"]], "a": [["83961.01000000", "0.49174000"], ["83961.29000000", "0.01911000"], ["83961.31000000", "0.00000000"], ["83961.32000000", "0.00000000"], ["83961.69000000", "0.00007000"], ["83961.72000000", "0.00000000"], ["83961.99000000", "0.00000000"], ["83962.00000000", "0.00000000"], ["83962.57000000", "0.00000000"], ["83962.76000000", "0.00000000"], ["83963.12000000", "0.00000000"], ["83963.13000000", "0.00000000"], ["83963.21000000", "0.00014000"], ["83963.22000000", "0.08075000"], ["83963.23000000", "0.00000000"], ["83963.24000000", "0.00000000"], ["83963.25000000", "0.00000000"], ["83963.32000000", "0.00000000"], ["83963.33000000", "0.00000000"], ["83963.70000000", "0.00000000"], ["83963.71000000", "0.00000000"], ["83963.75000000", "0.00000000"], ["83963.76000000", "0.00000000"], ["83964.35000000", "0.00006000"], ["83964.53000000", "0.00014000"], ["83964.54000000", "0.02481000"], ["83964.90000000", "0.00014000"], ["83964.91000000", "0.10107000"], ["83965.36000000", "0.00000000"], ["83965.64000000", "0.00000000"], ["83966.40000000", "0.00014000"], ["83966.41000000", "0.47595000"], ["83966.42000000", "0.08336000"], ["83967.24000000", "0.02213000"], ["83968.29000000", "0.35709000"], ["83968.34000000", "0.15313000"], ["83969.31000000", "0.00000000"], ["83969.66000000", "0.78637000"], ["83972.30000000", "0.00011000"], ["83976.28000000", "0.00000000"], ["83977.81000000", "0.45300000"], ["83979.24000000", "0.66455000"], ["83981.65000000", "0.01865000"], ["83981.96000000", "0.00000000"], ["83982.27000000", "0.00000000"], ["83983.19000000", "0.00000000"], ["83984.84000000", "0.00000000"], ["83985.69000000", "0.00000000"], ["83986.12000000", "0.00000000"], ["83986.55000000", "0.00000000"], ["83987.83000000", "0.00000000"], ["83987.99000000", "0.33360000"], ["83988.05000000", "0.00000000"], ["83988.76000000", "0.85766000"], ["83989.59000000", "0.00000000"], ["83989.97000000", "0.00000000"], ["83992.11000000", "0.02804000"], ["83992.24000000", "0.00000000"], ["83995.26000000", "0.02383000"], ["83996.88000000", "0.85758000"], ["83998.61000000", "0.00000000"], ["84000.08000000", "0.00000000"], ["84000.14000000", "0.05200000"], ["84003.09000000", "0.59572000"], ["84003.10000000", "0.00000000"], ["84008.44000000", "0.00000000"], ["84012.36000000", "0.00000000"], ["84017.60000000", "0.00000000"], ["84026.76000000", "0.04017000"], ["84048.36000000", "0.00000000"], ["84048.43000000", "0.05979000"], ["84059.66000000", "0.47826000"], ["84059.67000000", "0.00000000"]], "record_time": 1742556578.039782, "EXCHANGE": "BINANCE"}
{"e": "depthUpdate", "E": 1742556579014, "s": "BTCUSDT", "U": 64607718784, "u": 64607719112, "b": [["83961.00000000", "4.04884000"], ["83960.05000000", "0.00694000"], ["83960.01000000", "0.00058000"], ["83960.00000000", "0.02559000"], ["83959.39000000", "0.00006000"], ["83958.91000000", "0.04826000"], ["83955.68000000", "0.00000000"], ["83953.15000000", "0.00075000"], ["83948.24000000", "0.00000000"], ["83941.83000000", "0.41764000"], ["83935.71000000", "0.00000000"], ["83935.50000000", "0.85821000"], ["83933.97000000", "0.00000000"], ["83932.24000000", "0.29594000"], ["83930.30000000", "0.59575000"], ["83925.71000000", "0.05000000"], ["83924.36000000", "0.00008000"], ["83924.22000000", "0.04534000"], ["83921.81000000", "0.00000000"], ["83845.13000000", "0.00000000"], ["83839.44000000", "0.00000000"], ["83839.20000000", "0.00000000"], ["83827.34000000", "0.00400000"], ["83752.23000000", "0.00000000"], ["83003.52000000", "0.00000000"], ["80000.00000000", "155.39243000"], ["79700.00000000", "1.69331000"], ["78000.00000000", "145.91402000"], ["75564.00000000", "0.00020000"], ["67168.80000000", "0.00058000"], ["33000.00000000", "2.93827000"], ["30225.96000000", "0.00740000"]], "a": [["83961.01000000", "1.48241000"], ["83961.02000000", "0.00048000"], ["83961.07000000", "0.00015000"], ["83961.29000000", "0.01911000"], ["83961.33000000", "0.00014000"], ["83961.34000000", "0.53906000"], ["83961.35000000", "0.35689000"], ["83961.63000000", "0.00000000"], ["83961.64000000", "0.08735000"], ["83961.69000000", "0.00000000"], ["83961.72000000", "0.00000000"], ["83962.43000000", "0.00000000"], ["83962.44000000", "0.00000000"], ["83962.45000000", "0.00000000"], ["83962.48000000", "0.00000000"], ["83962.49000000", "0.00000000"], ["83962.57000000", "0.00000000"], ["83963.20000000", "0.00000000"], ["83963.21000000", "0.00000000"], ["83963.22000000", "0.00000000"], ["83963.28000000", "0.00000000"], ["83963.29000000", "0.00000000"], ["83963.41000000", "0.00000000"], ["83963.61000000", "0.00000000"], ["83963.62000000", "0.00000000"], ["83964.14000000", "0.00000000"], ["83964.26000000", "0.00000000"], ["83964.53000000", "0.00000000"], ["83964.54000000", "0.02474000"], ["83964.90000000", "0.00000000"], ["83964.91000000", "0.10100000"], ["83965.78000000", "0.78641000"], ["83966.40000000", "0.00000000"], ["83966.41000000", "0.47666000"], ["83967.24000000", "0.00000000"], ["83967.72000000", "0.00000000"], ["83968.71000000", "0.00000000"], ["83969.55000000", "0.00000000"], ["83969.66000000", "0.00000000"], ["83970.39000000", "0.00000000"], ["83971.23000000", "0.00000000"], ["83979.30000000", "0.00500000"], ["83981.65000000", "0.00000000"], ["83981.96000000", "0.71284000"], ["83982.16000000", "0.00000000"], ["83982.51000000", "0.03573000"], ["83985.14000000", "0.85770000"], ["83986.05000000", "0.00000000"], ["83989.45000000", "0.00000000"], ["83994.20000000", "0.00000000"], ["83995.26000000", "0.00000000"], ["83996.57000000", "0.00000000"], ["83998.26000000", "0.02383000"], ["83999.37000000", "0.59574000"], ["84000.23000000", "0.33777000"], ["84000.68000000", "0.00000000"], ["84001.48000000", "0.00000000"], ["84003.09000000", "0.00000000"], ["84018.65000000", "0.00000000"], ["84092.23000000", "0.00000000"], ["84092.24000000", "0.05497000"], ["84092.91000000", "0.05097000"], ["84095.84000000", "0.05497000"], ["84095.92000000", "0.00000000"], ["84105.41000000", "0.18245000"], ["84106.17000000", "0.00000000"], ["84107.07000000", "0.99713000"], ["84117.46000000", "0.05097000"], ["84117.47000000", "0.00000000"], ["84137.02000000", "0.01000000"], ["85044.08000000", "0.00000000"]], "record_time": 1742556579.040034, "EXCHANGE": "BINANCE"}
{"e": "depthUpdate", "E": 1742556580014, "s": "BTCUSDT", "U": 64607719113, "u": 64607719306, "b": [["83961.00000000", "4.27782000"], ["83956.80000000", "0.00000000"], ["83948.33000000", "0.00000000"], ["83941.83000000", "0.42714000"], ["83935.50000000", "0.00000000"], ["83935.44000000", "0.85821000"], ["83925.71000000", "0.00000000"], ["83922.34000000", "0.01300000"], ["83919.07000000", "0.00000000"], ["83890.62000000", "0.00298000"], ["83882.22000000", "0.00603000"], ["83873.83000000", "0.00895000"], ["83865.44000000", "0.01194000"], ["83857.05000000", "0.01493000"], ["83839.37000000", "0.16297000"], ["83837.38000000", "0.00400000"], ["83834.28000000", "0.00000000"], ["83832.35000000", "0.00000000"], ["83827.34000000", "0.00000000"], ["83600.00000000", "2.81938000"], ["82995.16000000", "0.43213000"], ["80572.80000000", "0.03572000"], ["79700.00000000", "1.69319000"], ["76700.00000000", "8.07953000"], ["75564.00000000", "0.00000000"], ["67168.80000000", "0.00058000"], ["33000.00000000", "2.93827000"]], "a": [["83961.01000000", "1.16761000"], ["83961.28000000", "0.00007000"], ["83961.29000000", "0.00007000"], ["83961.34000000", "0.07418000"], ["83961.35000000", "0.00000000"], ["83961.63000000", "0.00014000"], ["83961.64000000", "0.08735000"], ["83963.41000000", "0.00014000"], ["83963.42000000", "0.16525000"], ["83963.54000000", "0.00014000"], ["83963.55000000", "0.32320000"], ["83964.54000000", "0.02474000"], ["83964.90000000", "0.00000000"], ["83964.91000000", "0.10100000"], ["83965.16000000", "0.00000000"], ["83965.70000000", "0.78641000"], ["83965.78000000", "0.00000000"], ["83966.40000000", "0.00000000"], ["83966.41000000", "0.50037000"], ["83967.11000000", "0.00756000"], ["83967.47000000", "0.00000000"], ["83967.60000000", "0.00000000"], ["83971.13000000", "0.00011000"], ["83971.79000000", "0.00000000"], ["83972.06000000", "0.00000000"], ["83972.30000000", "0.00000000"], ["83973.11000000", "0.04826000"], ["83975.98000000", "0.02362000"], ["83981.15000000", "0.00000000"], ["83981.96000000", "0.00000000"], ["83982.51000000", "0.00000000"], ["83984.75000000", "0.00831000"], ["83984.90000000", "0.85770000"], ["83985.14000000", "0.00000000"], ["83995.86000000", "1.59127000"], ["83997.17000000", "0.05000000"], ["83998.14000000", "0.00000000"], ["84008.50000000", "0.00500000"], ["84034.20000000", "0.00000000"], ["84049.80000000", "0.00000000"], ["84053.51000000", "0.00298000"], ["84058.20000000", "0.00000000"], ["84061.91000000", "0.00597000"], ["84066.60000000", "0.00000000"], ["84070.31000000", "0.00895000"], ["84075.01000000", "0.00000000"], ["84078.71000000", "0.01194000"], ["84083.81000000", "0.00000000"], ["84087.11000000", "0.01493000"], ["84089.13000000", "0.00000000"], ["84090.14000000", "0.05097000"], ["84091.97000000", "0.00841000"], ["84092.24000000", "0.00000000"], ["84092.99000000", "0.05097000"], ["84093.17000000", "0.05497000"], ["84095.84000000", "0.00000000"], ["84096.79000000", "0.05497000"], ["84105.41000000", "0.45878000"], ["84109.75000000", "0.00000000"], ["84115.29000000", "0.00000000"], ["84117.46000000", "0.00000000"], ["84137.02000000", "0.00000000"], ["84138.65000000", "0.00000000"], ["84138.93000000", "0.01000000"], ["85035.65000000", "0.60000000"]], "record_time": 1742556580.039915, "EXCHANGE": "BINANCE"}
{"e": "depthUpdate", "E": 1742556581014, "s": "BTCUSDT", "U": 64607719307, "u": 64607719481, "b": [["83961.00000000", "4.11045000"], ["83956.80000000", "0.00500000"], ["83948.24000000", "0.85808000"], ["83937.04000000", "0.59571000"], ["83935.44000000", "0.00000000"], ["83930.30000000", "0.00000000"], ["83928.08000000", "0.00000000"], ["83922.34000000", "0.00000000"], ["83909.07000000", "0.00000000"], ["83908.57000000", "0.00295000"], ["83837.93000000", "0.00400000"], ["83837.38000000", "0.00000000"], ["83830.81000000", "0.00000000"], ["82643.23000000", "0.00022000"], ["80572.80000000", "0.00000000"], ["75564.00000000", "0.00000000"], ["67168.80000000", "0.00058000"], ["33000.00000000", "2.93827000"], ["30225.96000000", "0.00760000"], ["20002.00000000", "0.00000000"], ["20001.00000000", "0.02099000"]], "a": [["83961.01000000", "0.97472000"], ["83961.28000000", "0.00007000"], ["83961.29000000", "0.00000000"], ["83961.33000000", "0.00000000"], ["83961.34000000", "0.00000000"], ["83961.63000000", "0.00007000"], ["83961.64000000", "0.00000000"], ["83961.72000000", "0.00000000"], ["83963.40000000", "0.00014000"], ["83963.41000000", "0.18508000"], ["83963.54000000", "0.00014000"], ["83964.54000000", "0.02481000"], ["83965.00000000", "0.00754000"], ["83965.70000000", "0.00000000"], ["83965.72000000", "0.07271000"], ["83966.00000000", "0.02260000"], ["83966.41000000", "0.50043000"], ["83967.11000000", "0.00000000"], ["83967.47000000", "0.02415000"], ["83967.52000000", "0.78639000"], ["83979.30000000", "0.00000000"], ["83982.63000000", "0.00000000"], ["83992.11000000", "0.00000000"], ["83994.68000000", "0.02804000"], ["83999.37000000", "0.00000000"], ["84000.09000000", "0.72475000"], ["84002.13000000", "0.59572000"], ["84034.19000000", "0.00041000"], ["84045.20000000", "0.04335000"], ["84051.09000000", "0.55754000"], ["84051.19000000", "1.10680000"], ["84109.74000000", "0.00035000"]], "record_time": 1742556581.03969, "EXCHANGE": "BINANCE"}
{"e": "depthUpdate", "E": 1742556582014, "s": "BTCUSDT", "U": 64607719482, "u": 64607719898, "b": [["83961.00000000", "3.24648000"], ["83960.99000000", "0.12516000"], ["83960.98000000", "0.00007000"], ["83960.97000000", "0.00013000"], ["83960.96000000", "0.00027000"], ["83960.95000000", "0.00007000"], ["83960.05000000", "0.00000000"], ["83960.04000000", "0.01924000"], ["83960.01000000", "0.00000000"], ["83959.07000000", "0.00000000"], ["83958.94000000", "0.01500000"], ["83958.91000000", "0.00000000"], ["83958.30000000", "0.00000000"], ["83957.29000000", "0.00000000"], ["83956.92000000", "0.00595000"], ["83956.80000000", "0.01000000"], ["83953.84000000", "0.00007000"], ["83953.56000000", "0.00000000"], ["83953.15000000", "0.00017000"], ["83952.72000000", "0.17865000"], ["83952.01000000", "0.00000000"], ["83950.02000000", "0.71284000"], ["83950.01000000", "0.17822000"], ["83948.78000000", "0.15686000"], ["83948.24000000", "0.00000000"], ["83946.49000000", "0.08992000"], ["83946.30000000", "0.00000000"], ["83944.56000000", "0.00009000"], ["83944.53000000", "0.85812000"], ["83937.04000000", "0.00000000"], ["83935.30000000", "0.85821000"], ["83933.97000000", "0.00000000"], ["83932.24000000", "0.28485000"], ["83930.29000000", "0.00000000"], ["83930.26000000", "0.59575000"], ["83928.88000000", "0.00000000"], ["83924.22000000", "0.00000000"], ["83923.72000000", "0.00000000"], ["83914.74000000", "0.04534000"], ["83913.64000000", "0.00000000"], ["83909.06000000", "0.01520000"], ["83901.35000000", "0.00570000"], ["83869.67000000", "0.00000000"], ["83837.93000000", "0.00000000"], ["83803.38000000", "0.00400000"], ["83796.84000000", "0.00000000"], ["83547.41000000", "1.19154000"], ["83541.26000000", "0.00000000"], ["83127.57000000", "1.78730000"], ["83121.45000000", "0.00000000"], ["82707.73000000", "0.59577000"], ["82701.65000000", "0.00000000"], ["80555.99000000", "0.00000000"], ["76608.00000000", "0.04175000"], ["75564.00000000", "0.00000000"], ["67168.80000000", "0.00058000"], ["33000.00000000", "2.93827000"], ["30225.96000000", "0.00800000"]], "a": [["83961.01000000", "3.53977000"], ["83961.28000000", "0.00007000"], ["83961.29000000", "0.00007000"], ["83961.63000000", "0.00000000"], ["83962.00000000", "0.00000000"], ["83962.01000000", "0.00000000"], ["83962.47000000", "0.00000000"], ["83962.48000000", "0.00000000"], ["83962.57000000", "0.00000000"], ["83963.40000000", "0.00014000"], ["83963.41000000", "0.26311000"], ["83963.42000000", "0.00000000"], ["83963.54000000", "0.00000000"], ["83963.55000000", "0.00014000"], ["83963.56000000", "0.15320000"], ["83964.54000000", "0.02481000"], ["83964.91000000", "0.10107000"], ["83964.98000000", "0.00000000"], ["83964.99000000", "0.00000000"], ["83965.24000000", "0.00014000"], ["83965.25000000", "0.78641000"], ["83965.72000000", "0.00000000"], ["83966.41000000", "0.27934000"], ["83966.42000000", "0.02078000"], ["83966.96000000", "0.00000000"], ["83967.52000000", "0.00000000"], ["83968.26000000", "0.00011000"], ["83968.34000000", "0.00000000"], ["83968.76000000", "0.01520000"], ["83969.41000000", "0.00000000"], ["83970.47000000", "0.00000000"], ["83970.54000000", "0.00000000"], ["83971.13000000", "0.00000000"], ["83971.51000000", "0.00013000"], ["83973.11000000", "0.00000000"], ["83973.82000000", "0.00199000"], ["83981.96000000", "0.71284000"], ["83982.63000000", "0.00000000"], ["83984.86000000", "0.85770000"], ["83984.90000000", "0.00000000"], ["83987.53000000", "0.00000000"], ["83988.00000000", "0.00000000"], ["83993.01000000", "0.00000000"], ["83997.17000000", "0.00000000"], ["83997.42000000", "0.59575000"], ["83998.04000000", "0.00000000"], ["83998.26000000", "0.00000000"], ["84001.42000000", "0.01520000"], ["84002.13000000", "0.00000000"], ["84003.14000000", "0.00000000"], ["84008.50000000", "0.00000000"], ["84009.14000000", "0.00000000"], ["84012.41000000", "0.04017000"], ["84026.76000000", "0.00000000"], ["84052.61000000", "0.00000000"], ["84055.68000000", "0.00000000"], ["84056.89000000", "0.00000000"], ["84074.83000000", "0.05510000"], ["84077.65000000", "0.16091000"], ["84080.53000000", "0.04645000"], ["84080.74000000", "0.00000000"], ["84082.45000000", "0.18346000"], ["84093.15000000", "0.05497000"], ["84093.17000000", "0.00000000"], ["84093.66000000", "0.05097000"], ["84096.79000000", "0.00000000"], ["84096.82000000", "0.05497000"], ["84113.98000000", "0.04642000"], ["84130.76000000", "0.00000000"], ["84380.86000000", "0.00000000"], ["84387.07000000", "1.19176000"], ["84800.61000000", "0.00000000"], ["84800.66000000", "0.00000000"], ["84806.90000000", "1.78730000"], ["85220.47000000", "0.00000000"], ["85226.74000000", "0.59603000"]], "record_time": 1742556582.124595, "EXCHANGE": "BINANCE"}
{"e": "depthUpdate", "E": 1742556583014, "s": "BTCUSDT", "U": 64607719899, "u": 64607720302, "b": [["83961.00000000", "0.39064000"], ["83960.99000000", "0.00067000"], ["83960.97000000", "0.00007000"], ["83960.94000000", "0.00015000"], ["83960.93000000", "0.00007000"], ["83960.80000000", "0.00000000"], ["83960.79000000", "0.00000000"], ["83960.78000000", "0.00000000"], ["83960.77000000", "0.00000000"], ["83960.65000000", "0.00000000"], ["83960.05000000", "0.00000000"], ["83960.04000000", "0.00006000"], ["83960.01000000", "0.00014000"], ["83960.00000000", "0.02566000"], ["83959.44000000", "0.00000000"], ["83959.06000000", "0.00000000"], ["83958.95000000", "0.00014000"], ["83958.94000000", "0.01507000"], ["83958.32000000", "0.00000000"], ["83958.20000000", "0.00014000"], ["83958.19000000", "0.01507000"], ["83958.10000000", "0.00000000"], ["83957.97000000", "0.00000000"], ["83957.82000000", "0.00000000"], ["83957.78000000", "0.00014000"], ["83957.77000000", "0.08007000"], ["83957.26000000", "0.00000000"], ["83957.13000000", "0.00000000"], ["83957.00000000", "0.00000000"], ["83956.92000000", "0.00000000"], ["83956.80000000", "0.00000000"], ["83956.78000000", "0.00007000"], ["83955.99000000", "0.04823000"], ["83955.45000000", "0.00011000"], ["83954.95000000", "0.01533000"], ["83954.26000000", "0.02213000"], ["83953.39000000", "0.78652000"], ["83953.02000000", "0.00000000"], ["83952.72000000", "0.00000000"], ["83952.62000000", "0.00000000"], ["83952.61000000", "0.00000000"], ["83951.94000000", "0.00000000"], ["83951.45000000", "0.00097000"], ["83950.93000000", "1.00000000"], ["83950.85000000", "0.00091000"], ["83950.79000000", "0.00000000"], ["83950.02000000", "0.00000000"], ["83950.01000000", "0.17822000"], ["83949.58000000", "0.28647000"], ["83949.57000000", "0.00000000"], ["83948.10000000", "0.00400000"], ["83946.49000000", "0.00000000"], ["83945.18000000", "4.16346000"], ["83945.10000000", "0.00000000"], ["83944.53000000", "0.00000000"], ["83944.33000000", "0.00000000"], ["83941.13000000", "0.00000000"], ["83940.91000000", "0.00000000"], ["83938.68000000", "0.00000000"], ["83938.06000000", "0.00000000"], ["83936.94000000", "0.00000000"], ["83935.30000000", "0.00000000"], ["83931.67000000", "0.00000000"], ["83930.56000000", "0.85826000"], ["83930.26000000", "0.00000000"], ["83930.25000000", "0.00000000"], ["83927.42000000", "0.00000000"], ["83927.01000000", "0.59577000"], ["83925.72000000", "0.85831000"], ["83922.12000000", "0.00000000"], ["83921.27000000", "0.00935000"], ["83918.41000000", "0.00000000"], ["83916.13000000", "0.01870000"], ["83873.49000000", "0.00000000"], ["83872.88000000", "0.58605000"], ["83870.23000000", "0.00000000"], ["83803.38000000", "0.00000000"], ["83780.83000000", "0.00400000"], ["83219.61000000", "0.00000000"], ["82352.20000000", "0.00030000"], ["75564.00000000", "0.00000000"], ["67168.80000000", "0.00058000"], ["33000.00000000", "2.93827000"], ["30225.96000000", "0.00840000"]], "a": [["83961.01000000", "6.42873000"], ["83961.29000000", "0.00007000"], ["83962.84000000", "0.00011000"], ["83963.26000000", "0.00014000"], ["83963.27000000", "0.33211000"], ["83963.28000000", "0.00000000"], ["83963.35000000", "0.01527000"], ["83963.40000000", "0.00000000"], ["83963.41000000", "0.00007000"], ["83963.55000000", "0.00000000"], ["83963.56000000", "0.00000000"], ["83964.91000000", "0.10107000"], ["83965.24000000", "0.00000000"], ["83965.25000000", "0.00000000"], ["83965.84000000", "0.00000000"], ["83966.34000000", "0.00000000"], ["83968.07000000", "0.00000000"], ["83968.26000000", "0.00000000"], ["83968.76000000", "0.00000000"], ["83969.41000000", "0.45000000"], ["83970.40000000", "0.00000000"], ["83970.41000000", "0.00000000"], ["83971.14000000", "0.00199000"], ["83971.15000000", "0.00000000"], ["83971.38000000", "0.00000000"], ["83973.76000000", "0.08992000"], ["83973.82000000", "0.00000000"], ["83974.85000000", "0.71284000"], ["83975.40000000", "0.03573000"], ["83975.98000000", "0.88141000"], ["83976.14000000", "0.00000000"], ["83977.80000000", "0.06010000"], ["83978.30000000", "0.00000000"], ["83979.30000000", "0.00000000"], ["83983.68000000", "0.59515000"], ["83985.26000000", "0.02804000"], ["83988.15000000", "0.08992000"], ["83988.40000000", "0.00300000"], ["83991.48000000", "0.02383000"], ["83992.22000000", "0.59577000"], ["83992.35000000", "0.00000000"], ["83994.68000000", "0.00000000"], ["83995.86000000", "1.16449000"], ["83996.88000000", "0.00000000"], ["83997.17000000", "0.00000000"], ["83997.42000000", "0.00000000"], ["83997.79000000", "0.00000000"], ["84000.08000000", "0.00000000"], ["84007.50000000", "0.00400000"], ["84012.18000000", "0.00000000"], ["84017.60000000", "0.00400000"], ["84046.51000000", "0.83556000"], ["84048.36000000", "0.00000000"], ["84048.51000000", "0.00000000"], ["84051.09000000", "0.27042000"], ["84051.19000000", "0.00000000"], ["84087.46000000", "0.05497000"], ["84090.47000000", "0.00841000"], ["84090.56000000", "0.05497000"], ["84091.97000000", "0.00000000"], ["84093.43000000", "0.05497000"], ["84097.24000000", "0.05497000"], ["84097.86000000", "0.00000000"], ["84105.41000000", "0.45733000"], ["84107.07000000", "0.99229000"], ["84234.83000000", "0.01187000"], ["84287.01000000", "0.00000000"]], "record_time": 1742556583.160212, "EXCHANGE": "BINANCE"}
{"e": "depthUpdate", "E": 1742556584014, "s": "BTCUSDT", "U": 64607720303, "u": 64607720663, "b": [["83961.00000000", "2.53476000"], ["83960.94000000", "0.00007000"], ["83960.93000000", "0.00007000"], ["83960.64000000", "0.00014000"], ["83960.63000000", "0.15675000"], ["83960.05000000", "0.00017000"], ["83960.02000000", "0.00014000"], ["83960.01000000", "0.25310000"], ["83960.00000000", "0.02566000"], ["83959.95000000", "0.01963000"], ["83959.74000000", "0.00000000"], ["83959.73000000", "0.00000000"], ["83959.68000000", "0.00000000"], ["83959.40000000", "0.00000000"], ["83959.35000000", "0.00024000"], ["83959.34000000", "0.78647000"], ["83958.95000000", "0.00000000"], ["83958.94000000", "0.01500000"], ["83958.20000000", "0.00000000"], ["83958.19000000", "0.01500000"], ["83957.81000000", "0.00019000"], ["83957.78000000", "0.00007000"], ["83957.77000000", "0.08000000"], ["83957.43000000", "0.08162000"], ["83957.42000000", "0.00000000"], ["83957.41000000", "0.00000000"], ["83956.80000000", "0.00500000"], ["83956.78000000", "0.00036000"], ["83955.38000000", "0.00000000"], ["83953.39000000", "0.00000000"], ["83953.21000000", "0.00000000"], ["83953.15000000", "0.00000000"], ["83951.13000000", "0.00000000"], ["83950.93000000", "0.00000000"], ["83950.85000000", "0.00000000"], ["83948.10000000", "0.00000000"], ["83946.89000000", "0.40109000"], ["83941.83000000", "0.42714000"], ["83938.94000000", "0.85817000"], ["83936.49000000", "0.10627000"], ["83934.55000000", "0.85822000"], ["83928.78000000", "0.00000000"], ["83928.43000000", "0.83651000"], ["83927.66000000", "0.00013000"], ["83925.12000000", "0.00000000"], ["83923.42000000", "0.00000000"], ["83922.98000000", "0.00935000"], ["83921.65000000", "0.00000000"], ["83921.46000000", "0.00000000"], ["83921.27000000", "0.00000000"], ["83916.99000000", "0.00000000"], ["83916.13000000", "0.01870000"], ["83897.16000000", "0.05000000"], ["83897.15000000", "0.00000000"], ["83884.64000000", "0.00000000"], ["83873.91000000", "0.00100000"], ["83793.43000000", "0.00400000"], ["83780.83000000", "0.00000000"], ["83777.45000000", "0.00000000"], ["83769.96000000", "0.00000000"], ["83758.19000000", "0.00000000"], ["83206.43000000", "0.00079000"], ["83088.48000000", "0.06004000"], ["80555.99000000", "0.03572000"], ["75564.00000000", "0.00000000"], ["67168.80000000", "0.00058000"], ["33000.00000000", "2.93827000"], ["30225.96000000", "0.00880000"]], "a": [["83961.01000000", "6.10625000"], ["83961.12000000", "0.00007000"], ["83961.15000000", "0.00000000"], ["83961.29000000", "0.01946000"], ["83963.25000000", "0.00014000"], ["83963.26000000", "0.05480000"], ["83963.27000000", "0.00000000"], ["83963.34000000", "0.00014000"], ["83963.35000000", "0.01527000"], ["83964.34000000", "0.01007000"], ["83964.53000000", "0.00014000"], ["83964.54000000", "0.02474000"], ["83964.90000000", "0.00014000"], ["83964.91000000", "0.10100000"], ["83966.00000000", "0.02260000"], ["83966.40000000", "0.00007000"], ["83967.42000000", "0.00162000"], ["83967.47000000", "0.02386000"], ["83968.29000000", "0.00000000"], ["83970.84000000", "0.00414000"], ["83972.69000000", "0.00058000"], ["83973.28000000", "0.00000000"], ["83973.76000000", "0.00000000"], ["83974.84000000", "0.48348000"], ["83974.85000000", "0.00000000"], ["83974.86000000", "0.00000000"], ["83975.98000000", "0.02362000"], ["83977.80000000", "0.00059000"], ["83979.24000000", "0.66455000"], ["83979.70000000", "0.00000000"], ["83979.85000000", "0.00000000"], ["83981.96000000", "0.71284000"], ["83983.12000000", "0.02804000"], ["83983.68000000", "0.35709000"], ["83985.26000000", "0.00000000"], ["83988.15000000", "0.14943000"], ["83989.51000000", "0.85766000"], ["83989.54000000", "0.00000000"], ["83992.22000000", "0.00000000"], ["83992.23000000", "0.00000000"], ["83993.64000000", "0.00000000"], ["83994.16000000", "0.93370000"], ["83994.60000000", "0.85760000"], ["83997.76000000", "0.59574000"], ["84007.50000000", "0.00000000"], ["84012.34000000", "0.00000000"], ["84012.79000000", "0.59515000"], ["84017.60000000", "0.00000000"], ["84046.51000000", "0.58512000"], ["84048.09000000", "0.00100000"], ["84092.27000000", "0.12000000"], ["84096.93000000", "0.30513000"], ["84096.95000000", "0.00000000"], ["84106.10000000", "0.00000000"], ["84138.93000000", "0.01000000"]], "record_time": 1742556584.052486, "EXCHANGE": "BINANCE"}
{"e": "depthUpdate", "E": 1742556585014, "s": "BTCUSDT", "U": 64607720664, "u": 64607720770, "b": [["83961.00000000", "2.37652000"], ["83951.44000000", "0.00091000"], ["83940.65000000", "0.00904000"], ["83932.55000000", "0.00000000"], ["83929.23000000", "0.00756000"], ["83916.64000000", "0.05000000"], ["83867.40000000", "1.39117000"], ["83793.43000000", "0.00000000"], ["83787.20000000", "0.00400000"], ["81718.14000000", "0.00000000"], ["79700.00000000", "1.69319000"], ["75564.00000000", "0.00000000"], ["67168.80000000", "0.00058000"], ["42000.00000000", "6.85261000"], ["33000.00000000", "2.93827000"], ["30225.96000000", "0.00900000"]], "a": [["83961.01000000", "5.88565000"], ["83961.28000000", "0.00021000"], ["83962.84000000", "0.00014000"], ["83962.85000000", "0.00759000"], ["83963.26000000", "0.05480000"], ["83963.34000000", "0.00000000"], ["83963.35000000", "0.00000000"], ["83964.53000000", "0.00014000"], ["83964.54000000", "0.02481000"], ["83965.00000000", "0.00000000"], ["83965.49000000", "0.00011000"], ["83966.00000000", "0.03780000"], ["83966.40000000", "0.00000000"], ["83966.41000000", "0.51156000"], ["83967.85000000", "0.00000000"], ["83968.69000000", "0.00000000"], ["83969.53000000", "0.00000000"], ["83970.37000000", "0.00000000"], ["83970.84000000", "0.00000000"], ["83976.30000000", "0.59515000"], ["83979.30000000", "0.00500000"], ["83987.99000000", "0.73984000"], ["83988.40000000", "0.00000000"], ["83992.43000000", "0.05000000"], ["83993.83000000", "0.00000000"], ["83997.65000000", "0.00008000"], ["84012.78000000", "0.21276000"], ["84014.56000000", "0.00000000"], ["84088.56000000", "0.05497000"], ["84090.56000000", "0.00000000"], ["84092.05000000", "0.05497000"], ["84093.15000000", "0.00000000"], ["84093.43000000", "0.00000000"], ["84096.82000000", "0.00000000"], ["84097.24000000", "0.00000000"], ["84105.42000000", "0.00000000"], ["84107.73000000", "0.00000000"], ["84111.57000000", "0.04761000"], ["84113.96000000", "0.00000000"], ["84113.97000000", "0.00000000"], ["86400.00000000", "6.64787000"], ["86950.00000000", "0.13254000"]], "record_time": 1742556585.040459, "EXCHANGE": "BINANCE"}
{"e": "depthUpdate", "E": 1742556586014, "s": "BTCUSDT", "U": 64607720771, "u": 64607720828, "b": [["83961.00000000", "2.48505000"], ["83957.26000000", "0.02407000"], ["83956.80000000", "0.00000000"], ["83881.92000000", "0.01689000"], ["83827.53000000", "0.04198000"], ["83750.01000000", "0.04915000"], ["83750.00000000", "4.41731000"], ["83749.16000000", "0.00000000"], ["83088.48000000", "0.00000000"], ["75564.00000000", "0.00000000"], ["67168.80000000", "0.00058000"], ["60000.00000000", "73.14793000"], ["42000.00000000", "6.85161000"], ["33000.00000000", "2.93827000"], ["30225.96000000", "0.00920000"], ["20002.00000000", "0.00000000"], ["20001.00000000", "0.02099000"]], "a": [["83961.01000000", "5.87373000"], ["83966.41000000", "0.27934000"], ["83967.03000000", "0.10656000"], ["83967.42000000", "0.00132000"], ["83991.48000000", "0.00000000"], ["83998.71000000", "0.02383000"], ["84008.50000000", "0.00500000"], ["84089.02000000", "0.05097000"], ["84089.68000000", "0.00841000"], ["84090.47000000", "0.00000000"], ["84093.82000000", "0.00000000"], ["84094.41000000", "0.04643000"], ["84094.42000000", "0.00000000"], ["84095.34000000", "0.04198000"], ["84096.94000000", "0.00000000"], ["84100.93000000", "0.00000000"]], "record_time": 1742556586.040169, "EXCHANGE": "BINANCE"}
{"e": "depthUpdate", "E": 1742556587014, "s": "BTCUSDT", "U": 64607720829, "u": 64607720912, "b": [["83961.00000000", "2.93990000"], ["83957.84000000", "0.00011000"], ["83957.33000000", "0.01520000"], ["83957.30000000", "0.00000000"], ["83957.29000000", "0.00000000"], ["83957.28000000", "0.00000000"], ["83957.27000000", "0.00000000"], ["83957.26000000", "0.00000000"], ["83956.80000000", "0.00500000"], ["83955.45000000", "0.00000000"], ["83954.95000000", "0.00013000"], ["83951.52000000", "0.00000000"], ["83951.51000000", "0.00000000"], ["83951.50000000", "0.00720000"], ["83951.44000000", "0.00000000"], ["83940.65000000", "0.00000000"], ["83921.88000000", "0.04000000"], ["83792.67000000", "0.00400000"], ["83787.20000000", "0.00000000"], ["83772.09000000", "0.00011000"], ["83520.21000000", "0.00011000"], ["83121.39000000", "0.00000000"], ["75564.00000000", "0.00000000"], ["67168.80000000", "0.00058000"], ["33000.00000000", "2.93827000"]], "a": [["83961.01000000", "5.77393000"], ["83970.76000000", "0.00000000"], ["83970.82000000", "0.00414000"], ["83979.30000000", "0.00000000"], ["83992.43000000", "0.00000000"], ["83998.53000000", "0.00000000"], ["84000.00000000", "0.02449000"], ["84042.27000000", "0.55737000"], ["84045.53000000", "1.10680000"], ["84081.19000000", "0.23643000"], ["84082.45000000", "0.00000000"]], "record_time": 1742556587.05953, "EXCHANGE": "BINANCE"}
{"e": "depthUpdate", "E": 1742556588014, "s": "BTCUSDT", "U": 64607720913, "u": 64607720999, "b": [["83961.00000000", "1.14898000"], ["83957.26000000", "0.00000000"], ["83956.80000000", "0.01000000"], ["83951.35000000", "0.00090000"], ["83928.07000000", "0.03695000"], ["83924.36000000", "0.00000000"], ["83920.00000000", "0.05256000"], ["83866.91000000", "0.10277000"], ["83843.43000000", "0.00076000"], ["83843.42000000", "0.00000000"], ["83809.66000000", "0.01865000"], ["83792.67000000", "0.00000000"], ["83778.36000000", "0.00406000"], ["83760.77000000", "0.00063000"], ["83760.76000000", "0.00000000"], ["75564.00000000", "0.00000000"], ["67168.80000000", "0.00058000"], ["33000.00000000", "2.93827000"], ["30225.96000000", "0.00940000"]], "a": [["83961.01000000", "5.93058000"], ["83970.82000000", "0.00000000"], ["83981.58000000", "0.01865000"], ["83993.17000000", "0.00000000"], ["84006.58000000", "0.03142000"], ["84008.50000000", "0.00000000"], ["84055.83000000", "0.10258000"], ["84079.92000000", "0.05097000"], ["84081.89000000", "0.00000000"], ["84082.78000000", "0.05097000"], ["84083.51000000", "0.05097000"], ["84085.93000000", "0.05497000"], ["84085.97000000", "0.05110000"], ["84086.71000000", "0.00000000"], ["84086.75000000", "0.05097000"], ["84087.46000000", "0.00000000"], ["84088.56000000", "0.00000000"], ["84088.62000000", "0.05497000"], ["84089.09000000", "0.05097000"], ["84089.39000000", "0.00000000"], ["84090.02000000", "0.05097000"], ["84090.07000000", "0.09740000"], ["84090.14000000", "0.00000000"], ["84091.99000000", "0.09286000"], ["84092.05000000", "0.00000000"], ["84092.10000000", "0.05497000"], ["84092.32000000", "0.00000000"], ["84092.57000000", "0.00000000"], ["84092.87000000", "0.00000000"], ["84092.91000000", "0.00000000"], ["84092.99000000", "0.00000000"], ["84093.66000000", "0.00000000"]], "record_time": 1742556588.039529, "EXCHANGE": "BINANCE"}
{"e": "depthUpdate", "E": 1742556589014, "s": "BTCUSDT", "U": 64607721000, "u": 64607721070, "b": [["83961.00000000", "1.14387000"], ["83959.95000000", "0.01963000"], ["83959.84000000", "0.00014000"], ["83959.83000000", "0.30597000"], ["83959.39000000", "0.00000000"], ["83959.35000000", "0.00010000"], ["83958.20000000", "0.00300000"], ["83958.10000000", "0.00000000"], ["83956.80000000", "0.00000000"], ["83950.02000000", "0.71284000"], ["83948.10000000", "0.00000000"], ["83941.83000000", "0.42714000"], ["83940.43000000", "0.48498000"], ["83919.44000000", "0.00600000"], ["83844.11000000", "0.01865000"], ["83809.66000000", "0.00000000"], ["83003.52000000", "0.40000000"], ["82995.16000000", "0.03213000"], ["75564.00000000", "0.00000000"], ["67168.80000000", "0.00058000"], ["33000.00000000", "2.93827000"], ["30225.96000000", "0.01000000"]], "a": [["83961.01000000", "5.93121000"], ["83978.30000000", "0.00300000"], ["83979.24000000", "1.01926000"], ["83981.04000000", "0.85774000"], ["83981.58000000", "0.00000000"], ["83983.10000000", "0.17822000"], ["83987.99000000", "0.47540000"], ["83988.40000000", "0.00000000"], ["83989.51000000", "0.00000000"], ["83998.71000000", "0.00000000"], ["84007.50000000", "0.00000000"], ["84007.57000000", "0.00000000"], ["84007.89000000", "0.00470000"], ["84017.60000000", "0.00000000"], ["84138.93000000", "0.01000000"], ["85035.65000000", "0.00000000"], ["85044.08000000", "0.60000000"]], "record_time": 1742556589.039543, "EXCHANGE": "BINANCE"}
{"e": "depthUpdate", "E": 1742560335014, "s": "BTCUSDT", "U": 64609818718, "u": 64609818976, "b": [["84163.02000000", "5.12322000"], ["84159.38000000", "0.00007000"], ["84159.37000000", "0.05940000"], ["84158.03000000", "0.06000000"], ["84157.54000000", "0.17821000"], ["84155.08000000", "0.17820000"], ["84155.06000000", "0.39101000"], ["84154.76000000", "0.11880000"], ["84154.06000000", "0.11880000"], ["84153.58000000", "0.00000000"], ["84153.41000000", "0.17820000"], ["84153.40000000", "0.01500000"], ["84152.31000000", "0.01500000"], ["84151.90000000", "0.00000000"], ["84149.78000000", "0.00594000"], ["84149.41000000", "0.00006000"], ["84149.04000000", "0.00000000"], ["84148.94000000", "0.08000000"], ["84146.32000000", "0.00000000"], ["84146.18000000", "0.05933000"], ["84145.71000000", "0.05940000"], ["84144.23000000", "0.00000000"], ["84143.80000000", "0.00000000"], ["84143.14000000", "0.00000000"], ["84139.70000000", "0.00000000"], ["84139.48000000", "0.00757000"], ["84138.21000000", "0.00000000"], ["84137.78000000", "0.00059000"], ["84134.52000000", "0.59433000"], ["84132.63000000", "0.05943000"], ["84132.45000000", "0.00000000"], ["84131.82000000", "0.00000000"], ["84125.38000000", "0.00000000"], ["84122.28000000", "0.04710000"], ["84115.80000000", "0.00000000"], ["84100.01000000", "0.30697000"], ["84099.69000000", "0.00000000"], ["84098.96000000", "0.03566000"], ["84090.60000000", "0.12844000"], ["84090.25000000", "1.12380000"], ["84086.60000000", "0.01689000"], ["84082.10000000", "0.00000000"], ["84081.99000000", "0.00000000"], ["84078.47000000", "0.36846000"], ["84078.46000000", "0.00000000"], ["84078.07000000", "0.00000000"], ["84027.62000000", "0.00000000"], ["84021.61000000", "0.00000000"], ["84019.47000000", "0.00000000"], ["84018.08000000", "0.00400000"], ["84012.98000000", "0.00000000"], ["82900.57000000", "0.00100000"], ["75746.00000000", "0.00020000"], ["67330.42000000", "0.00058000"], ["33000.00000000", "2.93827000"], ["30298.69000000", "0.00160000"]], "a": [["84163.03000000", "2.46755000"], ["84163.80000000", "0.00000000"], ["84164.56000000", "0.00007000"], ["84164.57000000", "0.03518000"], ["84164.58000000", "0.00000000"], ["84164.59000000", "0.00007000"], ["84164.67000000", "0.00000000"], ["84164.68000000", "0.00000000"], ["84164.97000000", "0.00000000"], ["84164.98000000", "0.00000000"], ["84165.07000000", "0.00006000"], ["84165.46000000", "0.00000000"], ["84165.47000000", "0.00000000"], ["84165.95000000", "0.00000000"], ["84165.96000000", "0.00000000"], ["84166.16000000", "0.00000000"], ["84166.17000000", "0.00000000"], ["84166.76000000", "0.00000000"], ["84166.77000000", "0.00056000"], ["84166.90000000", "0.00000000"], ["84166.91000000", "0.00000000"], ["84167.17000000", "0.00000000"], ["84167.18000000", "0.00000000"], ["84167.20000000", "0.00007000"], ["84167.90000000", "0.00000000"], ["84167.99000000", "0.00007000"], ["84168.00000000", "0.40483000"], ["84169.31000000", "0.00000000"], ["84169.68000000", "0.00007000"], ["84169.69000000", "0.78450000"], ["84169.93000000", "0.02000000"], ["84171.00000000", "0.01000000"], ["84171.45000000", "0.45000000"], ["84171.48000000", "0.00000000"], ["84171.54000000", "0.00000000"], ["84171.55000000", "0.00000000"], ["84172.95000000", "0.02426000"], ["84174.47000000", "0.00000000"], ["84174.48000000", "0.06000000"], ["84175.88000000", "0.08000000"], ["84179.35000000", "0.00000000"], ["84180.59000000", "0.71286000"], ["84180.98000000", "0.00000000"], ["84181.14000000", "0.00000000"], ["84181.84000000", "0.00000000"], ["84181.85000000", "0.03565000"], ["84181.90000000", "0.00000000"], ["84182.45000000", "0.16000000"], ["84183.90000000", "0.04000000"], ["84201.85000000", "1.03786000"], ["84203.95000000", "0.59433000"], ["84205.47000000", "0.00000000"], ["84206.07000000", "0.05820000"], ["84212.49000000", "0.00000000"], ["84212.78000000", "0.00000000"], ["84234.88000000", "0.00041000"], ["84235.48000000", "0.00000000"], ["84248.18000000", "0.01689000"], ["84258.03000000", "0.00000000"], ["84258.11000000", "0.66417000"], ["84260.14000000", "0.02377000"], ["84260.44000000", "0.00000000"], ["84310.51000000", "0.00035000"], ["84310.85000000", "0.00000000"], ["84700.00000000", "0.45253000"], ["85425.48000000", "0.00100000"], ["86862.05000000", "0.00065000"]], "record_time": 1742560335.040012, "EXCHANGE": "BINANCE"}
{"e": "depthUpdate", "E": 1742560336014, "s": "BTCUSDT", "U": 64609818977, "u": 64609819067, "b": [["84163.02000000", "5.12371000"], ["84162.00000000", "0.02834000"], ["84161.35000000", "0.00007000"], ["84160.86000000", "0.00000000"], ["84160.02000000", "0.00007000"], ["84160.00000000", "0.02833000"], ["84151.99000000", "0.00000000"], ["84151.89000000", "0.00000000"], ["84148.24000000", "0.00000000"], ["84141.11000000", "0.00759000"], ["84139.48000000", "0.00000000"], ["84129.19000000", "0.05000000"], ["84110.65000000", "0.59339000"], ["84091.41000000", "0.65238000"], ["84075.11000000", "0.00100000"], ["84002.14000000", "0.01000000"], ["84000.44000000", "0.05921000"], ["82900.57000000", "0.00000000"], ["75746.00000000", "0.00020000"], ["67330.42000000", "0.00058000"], ["60000.00000000", "73.06385000"], ["33000.00000000", "2.93827000"], ["20002.00000000", "0.00000000"], ["20001.00000000", "0.02099000"]], "a": [["84163.03000000", "2.46751000"], ["84173.02000000", "0.00000000"], ["84173.12000000", "0.00000000"], ["84175.36000000", "0.00095000"], ["84177.19000000", "0.00091000"], ["84177.24000000", "0.04000000"], ["84177.33000000", "0.00000000"], ["84177.34000000", "0.04000000"], ["84181.55000000", "0.04000000"], ["84185.06000000", "1.02656000"], ["84194.09000000", "0.00000000"], ["84198.40000000", "0.00000000"], ["84203.17000000", "0.05000000"], ["84238.75000000", "0.04000000"], ["84243.03000000", "0.00000000"], ["84250.93000000", "0.00100000"], ["84258.12000000", "0.21822000"], ["84262.96000000", "0.00000000"], ["84263.27000000", "1.24533000"], ["84266.18000000", "0.00841000"], ["84328.87000000", "0.00000000"], ["84330.47000000", "0.99734000"], ["84336.62000000", "0.00000000"], ["84337.02000000", "0.00000000"], ["84337.32000000", "0.01119000"], ["85004.65000000", "0.00000000"], ["85391.70000000", "0.11733000"], ["85425.48000000", "0.00000000"], ["86862.05000000", "0.00000000"]], "record_time": 1742560336.039242, "EXCHANGE": "BINANCE"}
{"e": "depthUpdate", "E": 1742560337014, "s": "BTCUSDT", "U": 64609819068, "u": 64609819159, "b": [["84163.02000000", "5.12373000"], ["84158.80000000", "0.01000000"], ["84142.39000000", "0.00000000"], ["84141.92000000", "0.00000000"], ["84141.40000000", "1.32305000"], ["84139.70000000", "0.59432000"], ["84134.52000000", "0.00000000"], ["82900.57000000", "0.00100000"], ["75746.00000000", "0.00020000"], ["67330.42000000", "0.00058000"], ["33000.00000000", "2.93827000"]], "a": [["84163.03000000", "2.15986000"], ["84167.52000000", "0.00755000"], ["84168.00000000", "0.29841000"], ["84169.76000000", "0.00009000"], ["84171.00000000", "0.00000000"], ["84171.45000000", "0.00000000"], ["84172.18000000", "0.00000000"], ["84173.03000000", "0.00000000"], ["84176.39000000", "0.00000000"], ["84176.40000000", "0.04006000"], ["84177.25000000", "0.04000000"], ["84180.61000000", "0.04000000"], ["84185.06000000", "1.01824000"], ["84186.63000000", "0.00000000"], ["84186.66000000", "1.32146000"], ["84193.26000000", "0.00000000"], ["84193.49000000", "0.00000000"], ["84197.46000000", "0.00000000"], ["84197.80000000", "0.00000000"], ["84200.29000000", "0.00000000"], ["84201.69000000", "0.04000000"], ["84203.95000000", "0.00000000"], ["84206.06000000", "0.00000000"], ["84207.03000000", "0.59432000"], ["84210.14000000", "0.00000000"], ["84214.30000000", "0.00000000"], ["84217.22000000", "0.00000000"], ["84221.32000000", "0.00000000"], ["84226.93000000", "0.00000000"], ["84231.05000000", "0.00000000"], ["84234.00000000", "0.00000000"], ["84237.90000000", "0.04000000"], ["84238.95000000", "0.00000000"], ["84243.03000000", "0.04000000"], ["84243.53000000", "0.00000000"], ["84247.23000000", "0.00000000"], ["84251.36000000", "0.00000000"], ["84255.53000000", "0.00000000"], ["84255.73000000", "0.00000000"], ["84257.05000000", "0.04000000"], ["84258.12000000", "0.17822000"], ["84259.10000000", "0.00000000"], ["84262.04000000", "0.65964000"], ["84263.92000000", "0.00000000"], ["84268.06000000", "0.00000000"], ["84272.55000000", "0.00000000"], ["84276.34000000", "0.00000000"], ["84281.74000000", "0.00000000"], ["84285.24000000", "0.00000000"], ["84288.75000000", "0.00000000"], ["84294.45000000", "0.00000000"], ["84298.58000000", "0.00000000"], ["84302.35000000", "0.00000000"], ["84307.42000000", "0.00000000"], ["84311.66000000", "0.00000000"], ["84314.22000000", "0.00000000"], ["84319.07000000", "0.00000000"], ["84324.02000000", "0.00000000"], ["84326.84000000", "0.00000000"], ["85425.46000000", "0.00007000"], ["85425.48000000", "0.00100000"], ["86862.05000000", "0.00065000"]], "record_time": 1742560337.039249, "EXCHANGE": "BINANCE"}
{"e": "depthUpdate", "E": 1742560338014, "s": "BTCUSDT", "U": 64609819160, "u": 64609821661, "b": [["84173.90000000", "3.74857000"], ["84173.89000000", "0.00014000"], ["84173.76000000", "0.00007000"], ["84173.75000000", "1.61171000"], ["84173.74000000", "4.89942000"], ["84173.52000000", "0.00000000"], ["84173.39000000", "0.00015000"], ["84173.38000000", "0.21873000"], ["84172.00000000", "0.02834000"], ["84171.03000000", "0.00000000"], ["84170.75000000", "0.00019000"], ["84170.15000000", "0.00000000"], ["84170.04000000", "0.49477000"], ["84170.03000000", "0.73685000"], ["84170.02000000", "0.00028000"], ["84170.01000000", "0.00000000"], ["84170.00000000", "0.02820000"], ["84169.87000000", "0.00000000"], ["84169.86000000", "0.00000000"], ["84169.85000000", "0.00000000"], ["84169.84000000", "0.00000000"], ["84169.70000000", "0.00000000"], ["84169.69000000", "0.23320000"], ["84169.68000000", "0.29788000"], ["84169.67000000", "0.35992000"], ["84169.66000000", "0.00000000"], ["84169.58000000", "0.00000000"], ["84168.77000000", "0.00000000"], ["84168.76000000", "0.00000000"], ["84168.73000000", "0.02970000"], ["84168.61000000", "0.05940000"], ["84168.46000000", "0.00000000"], ["84168.01000000", "0.00000000"], ["84168.00000000", "0.02820000"], ["84167.99000000", "0.00000000"], ["84167.98000000", "0.00000000"], ["84167.63000000", "0.00000000"], ["84167.60000000", "0.00000000"], ["84167.59000000", "0.00000000"], ["84167.53000000", "0.27898000"], ["84167.52000000", "0.00000000"], ["84167.51000000", "0.00000000"], ["84167.50000000", "0.00000000"], ["84167.49000000", "0.00000000"], ["84167.48000000", "0.00000000"], ["84167.20000000", "0.00000000"], ["84167.19000000", "0.00000000"], ["84166.96000000", "0.00000000"], ["84166.86000000", "0.00000000"], ["84166.85000000", "0.00000000"], ["84166.84000000", "0.14000000"], ["84166.78000000", "0.00000000"], ["84166.77000000", "0.00000000"], ["84166.76000000", "0.00000000"], ["84166.32000000", "0.00000000"], ["84166.07000000", "0.00000000"], ["84166.01000000", "0.00000000"], ["84166.00000000", "0.02820000"], ["84165.59000000", "0.00000000"], ["84165.56000000", "0.04168000"], ["84165.19000000", "0.00000000"], ["84165.08000000", "0.00000000"], ["84165.07000000", "0.00000000"], ["84165.06000000", "0.00000000"], ["84164.95000000", "0.06000000"], ["84164.71000000", "0.00000000"], ["84164.69000000", "0.00000000"], ["84164.63000000", "0.35603000"], ["84164.61000000", "0.00000000"], ["84164.60000000", "0.00000000"], ["84164.59000000", "0.00000000"], ["84164.58000000", "0.00000000"], ["84164.57000000", "0.00000000"], ["84164.56000000", "0.00000000"], ["84164.55000000", "0.00006000"], ["84164.51000000", "0.00000000"], ["84164.50000000", "0.00000000"], ["84164.49000000", "0.00000000"], ["84164.48000000", "0.08333000"], ["84164.40000000", "0.00000000"], ["84164.39000000", "0.00000000"], ["84164.34000000", "0.00000000"], ["84164.21000000", "0.06400000"], ["84164.13000000", "0.05200000"], ["84164.03000000", "0.04400000"], ["84164.02000000", "0.04800000"], ["84164.00000000", "0.02820000"], ["84163.76000000", "0.00245000"], ["84163.17000000", "0.00118000"], ["84163.06000000", "0.00000000"], ["84163.04000000", "0.23775000"], ["84163.03000000", "0.45000000"], ["84163.02000000", "0.05583000"], ["84163.01000000", "0.00000000"], ["84162.89000000", "0.00201000"], ["84162.20000000", "0.01500000"], ["84162.03000000", "0.00000000"], ["84162.02000000", "0.00000000"], ["84162.01000000", "0.00000000"], ["84162.00000000", "0.02820000"], ["84161.72000000", "0.30898000"], ["84161.43000000", "0.00000000"], ["84161.35000000", "0.00000000"], ["84161.19000000", "0.01500000"], ["84161.02000000", "0.00000000"], ["84160.46000000", "0.00000000"], ["84160.45000000", "0.00000000"], ["84160.27000000", "0.16000000"], ["84160.02000000", "0.00000000"], ["84160.00000000", "0.02826000"], ["84159.99000000", "0.04000000"], ["84159.95000000", "0.00000000"], ["84159.89000000", "0.04000000"], ["84159.72000000", "0.04000000"], ["84159.60000000", "0.00006000"], ["84159.50000000", "0.00006000"], ["84159.38000000", "0.17822000"], ["84159.33000000", "0.00000000"], ["84159.32000000", "0.53460000"], ["84159.29000000", "0.00000000"], ["84159.28000000", "0.00000000"], ["84159.27000000", "0.00000000"], ["84159.19000000", "0.04168000"], ["84159.17000000", "0.00013000"], ["84159.15000000", "0.04000000"], ["84159.10000000", "0.00000000"], ["84158.81000000", "0.00000000"], ["84158.80000000", "0.00500000"], ["84158.32000000", "0.04000000"], ["84158.03000000", "0.00000000"], ["84157.90000000", "0.00000000"], ["84157.74000000", "0.11553000"], ["84157.49000000", "0.00000000"], ["84157.44000000", "0.00000000"], ["84157.10000000", "0.00000000"], ["84157.06000000", "0.00009000"], ["84156.91000000", "0.00059000"], ["84156.51000000", "0.00000000"], ["84156.32000000", "0.85596000"], ["84156.30000000", "0.00000000"], ["84156.27000000", "0.00013000"], ["84156.19000000", "0.00000000"], ["84155.92000000", "0.35603000"], ["84155.86000000", "0.11881000"], ["84155.50000000", "0.59422000"], ["84155.49000000", "0.05941000"], ["84155.40000000", "0.00006000"], ["84155.11000000", "0.97217000"], ["84155.10000000", "0.71286000"], ["84155.09000000", "0.00000000"], ["84155.06000000", "0.00000000"], ["84154.46000000", "0.00000000"], ["84154.20000000", "0.05940000"], ["84153.70000000", "0.00000000"], ["84153.40000000", "0.00000000"], ["84152.83000000", "0.00000000"], ["84152.77000000", "0.00000000"], ["84152.45000000", "0.00000000"], ["84152.31000000", "0.00000000"], ["84151.81000000", "0.85600000"], ["84151.28000000", "0.08992000"], ["84150.72000000", "0.74339000"], ["84150.64000000", "0.00000000"], ["84150.41000000", "0.00000000"], ["84150.26000000", "0.00000000"], ["84149.40000000", "0.08316000"], ["84148.94000000", "0.00000000"], ["84148.76000000", "0.00000000"], ["84148.58000000", "0.00000000"], ["84148.56000000", "0.00000000"], ["84148.52000000", "0.00118000"], ["84148.50000000", "0.00059000"], ["84148.45000000", "0.00000000"], ["84148.33000000", "0.00000000"], ["84148.25000000", "0.00000000"], ["84147.48000000", "0.00000000"], ["84146.73000000", "0.00000000"], ["84146.31000000", "0.00000000"], ["84146.19000000", "0.00000000"], ["84145.97000000", "0.19642000"], ["84145.37000000", "0.00016000"], ["84144.86000000", "0.00000000"], ["84143.85000000", "0.11540000"], ["84143.79000000", "0.00000000"], ["84142.95000000", "0.00755000"], ["84142.58000000", "0.00000000"], ["84142.38000000", "0.00000000"], ["84141.74000000", "0.19644000"], ["84141.40000000", "0.00000000"], ["84141.11000000", "0.00000000"], ["84140.91000000", "0.00000000"], ["84140.29000000", "0.00000000"], ["84139.70000000", "0.00000000"], ["84139.55000000", "0.33063000"], ["84139.54000000", "0.00000000"], ["84139.17000000", "0.00000000"], ["84138.62000000", "0.00212000"], ["84138.35000000", "0.91388000"], ["84137.78000000", "0.00000000"], ["84137.77000000", "0.00000000"], ["84137.25000000", "0.04546000"], ["84137.09000000", "0.00000000"], ["84136.94000000", "0.23804000"], ["84136.79000000", "0.00000000"], ["84135.97000000", "0.05068000"], ["84134.39000000", "0.00000000"], ["84133.71000000", "0.00000000"], ["84133.67000000", "0.01300000"], ["84130.51000000", "0.03324000"], ["84130.37000000", "0.00000000"], ["84129.19000000", "0.00000000"], ["84128.26000000", "0.05397000"], ["84128.18000000", "0.05397000"], ["84127.95000000", "0.00059000"], ["84126.79000000", "0.15891000"], ["84126.44000000", "0.00000000"], ["84126.10000000", "0.00358000"], ["84125.68000000", "0.05297000"], ["84125.67000000", "0.00000000"], ["84125.37000000", "0.00000000"], ["84124.77000000", "0.00000000"], ["84123.10000000", "0.00000000"], ["84122.54000000", "0.00000000"], ["84122.28000000", "0.00000000"], ["84121.90000000", "0.00000000"], ["84121.26000000", "0.14065000"], ["84119.01000000", "0.00000000"], ["84118.81000000", "0.05436000"], ["84118.24000000", "0.00000000"], ["84117.25000000", "0.00000000"], ["84116.98000000", "0.00000000"], ["84115.59000000", "0.00827000"], ["84114.95000000", "0.00000000"], ["84113.27000000", "0.00826000"], ["84113.06000000", "0.00000000"], ["84111.68000000", "0.00000000"], ["84110.65000000", "0.00000000"], ["84107.79000000", "0.00857000"], ["84106.74000000", "0.00000000"], ["84106.02000000", "0.00000000"], ["84104.06000000", "0.69676000"], ["84103.27000000", "0.95254000"], ["84102.92000000", "0.00000000"], ["84102.46000000", "0.00000000"], ["84100.77000000", "0.00000000"], ["84096.82000000", "0.00000000"], ["84093.64000000", "0.00000000"], ["84092.06000000", "0.00000000"], ["84089.88000000", "0.00119000"], ["84087.72000000", "0.28519000"], ["84085.34000000", "0.00000000"], ["84083.55000000", "0.00000000"], ["84079.14000000", "0.01196000"], ["84075.99000000", "0.00000000"], ["84071.00000000", "0.00000000"], ["84069.64000000", "0.00000000"], ["84068.17000000", "0.00000000"], ["84061.62000000", "0.00400000"], ["84037.64000000", "0.00000000"], ["84037.63000000", "0.00000000"], ["84037.16000000", "0.00000000"], ["84037.00000000", "0.00000000"], ["84032.66000000", "0.00000000"], ["84032.65000000", "0.00000000"], ["84018.08000000", "0.00000000"], ["84015.64000000", "0.00000000"], ["84013.25000000", "0.00000000"], ["84007.33000000", "0.01000000"], ["84007.03000000", "0.00000000"], ["84006.83000000", "0.00000000"], ["84002.53000000", "0.00000000"], ["84002.14000000", "0.00000000"], ["83980.42000000", "0.00000000"], ["83933.24000000", "0.00000000"], ["83931.48000000", "0.17576000"], ["83928.61000000", "0.00000000"], ["83928.21000000", "0.00000000"], ["83924.56000000", "0.00000000"], ["83923.97000000", "0.00013000"], ["83923.08000000", "0.00000000"], ["83921.73000000", "0.00000000"], ["83919.80000000", "0.00000000"], ["83916.14000000", "0.00000000"], ["83914.67000000", "0.00000000"], ["83913.32000000", "0.00000000"], ["83753.02000000", "0.00040000"], ["83752.98000000", "0.00000000"], ["83578.46000000", "0.00060000"], ["83578.45000000", "0.00000000"], ["83481.65000000", "0.00000000"], ["83184.11000000", "0.00040000"], ["83183.99000000", "0.00000000"], ["83112.60000000", "0.00000000"], ["82900.57000000", "0.00000000"], ["80781.46000000", "0.03563000"], ["80764.63000000", "0.00000000"], ["75753.00000000", "0.00173000"], ["75746.00000000", "0.00000000"], ["67339.12000000", "0.00058000"], ["67330.42000000", "0.00000000"], ["33000.00000000", "2.93827000"]], "a": [["84163.03000000", "0.00000000"], ["84163.04000000", "0.00000000"], ["84163.16000000", "0.00000000"], ["84163.50000000", "0.00000000"], ["84164.12000000", "0.00000000"], ["84164.23000000", "0.00000000"], ["84164.49000000", "0.00000000"], ["84164.50000000", "0.00000000"], ["84164.56000000", "0.00000000"], ["84164.57000000", "0.00000000"], ["84164.59000000", "0.00000000"], ["84164.60000000", "0.00000000"], ["84165.07000000", "0.00000000"], ["84166.77000000", "0.00000000"], ["84166.78000000", "0.00000000"], ["84166.85000000", "0.00000000"], ["84166.86000000", "0.00000000"], ["84166.87000000", "0.00000000"], ["84167.20000000", "0.00000000"], ["84167.21000000", "0.00000000"], ["84167.49000000", "0.00000000"], ["84167.50000000", "0.00000000"], ["84167.51000000", "0.00000000"], ["84167.52000000", "0.00000000"], ["84167.60000000", "0.00000000"], ["84167.99000000", "0.00000000"], ["84168.00000000", "0.00000000"], ["84168.30000000", "0.00000000"], ["84168.45000000", "0.00000000"], ["84168.77000000", "0.00000000"], ["84168.78000000", "0.00000000"], ["84169.18000000", "0.00000000"], ["84169.29000000", "0.00000000"], ["84169.59000000", "0.00000000"], ["84169.67000000", "0.00000000"], ["84169.68000000", "0.00000000"], ["84169.69000000", "0.00000000"], ["84169.70000000", "0.00000000"], ["84169.76000000", "0.00000000"], ["84169.79000000", "0.00000000"], ["84169.85000000", "0.00000000"], ["84169.86000000", "0.00000000"], ["84169.93000000", "0.00000000"], ["84170.00000000", "0.00000000"], ["84170.04000000", "0.00000000"], ["84170.05000000", "0.00000000"], ["84170.13000000", "0.00000000"], ["84170.53000000", "0.00000000"], ["84170.98000000", "0.00000000"], ["84171.40000000", "0.00000000"], ["84171.45000000", "0.00000000"], ["84171.61000000", "0.00000000"], ["84171.62000000", "0.00000000"], ["84171.66000000", "0.00000000"], ["84171.76000000", "0.00000000"], ["84171.77000000", "0.00000000"], ["84171.78000000", "0.00000000"], ["84171.82000000", "0.00000000"], ["84172.00000000", "0.00000000"], ["84172.20000000", "0.00000000"], ["84172.21000000", "0.00000000"], ["84172.22000000", "0.00000000"], ["84172.23000000", "0.00000000"], ["84172.42000000", "0.00000000"], ["84172.58000000", "0.00000000"], ["84172.95000000", "0.00000000"], ["84173.12000000", "0.00000000"], ["84173.13000000", "0.00000000"], ["84173.22000000", "0.00000000"], ["84173.40000000", "0.00000000"], ["84173.41000000", "0.00000000"], ["84173.51000000", "0.00000000"], ["84173.74000000", "0.00000000"], ["84173.75000000", "0.00000000"], ["84173.80000000", "0.00000000"], ["84173.85000000", "0.00000000"], ["84173.91000000", "0.00037000"], ["84173.92000000", "0.08532000"], ["84173.99000000", "0.00000000"], ["84174.00000000", "0.00000000"], ["84174.03000000", "0.00000000"], ["84174.04000000", "0.00000000"], ["84174.12000000", "0.00000000"], ["84174.18000000", "0.00000000"], ["84174.21000000", "0.00000000"], ["84174.22000000", "0.00000000"], ["84174.29000000", "0.00000000"], ["84174.35000000", "0.00006000"], ["84174.43000000", "0.00000000"], ["84174.48000000", "0.00000000"], ["84174.57000000", "0.00000000"], ["84174.86000000", "0.00000000"], ["84174.87000000", "0.00000000"], ["84174.94000000", "0.00000000"], ["84174.97000000", "0.00000000"], ["84175.11000000", "0.00000000"], ["84175.14000000", "0.00000000"], ["84175.36000000", "0.00000000"], ["84175.40000000", "0.00000000"], ["84175.64000000", "0.00000000"], ["84175.78000000", "0.00000000"], ["84175.88000000", "0.00000000"], ["84175.97000000", "0.00000000"], ["84175.99000000", "0.00016000"], ["84176.09000000", "0.00000000"], ["84176.11000000", "0.00239000"], ["84176.40000000", "0.00006000"], ["84176.84000000", "0.00000000"], ["84176.87000000", "0.00048000"], ["84176.88000000", "0.13623000"], ["84176.89000000", "0.00000000"], ["84177.19000000", "0.00000000"], ["84177.24000000", "0.00000000"], ["84177.25000000", "0.00000000"], ["84177.26000000", "0.00000000"], ["84177.34000000", "0.00000000"], ["84177.39000000", "0.00007000"], ["84177.40000000", "0.29794000"], ["84177.45000000", "0.00000000"], ["84177.46000000", "0.02315000"], ["84177.48000000", "0.00000000"], ["84177.53000000", "0.14681000"], ["84177.70000000", "0.00029000"], ["84177.99000000", "0.00000000"], ["84178.17000000", "0.00000000"], ["84178.28000000", "0.00000000"], ["84178.35000000", "0.00000000"], ["84178.36000000", "0.00000000"], ["84178.37000000", "0.00000000"], ["84178.45000000", "0.00000000"], ["84178.60000000", "0.00000000"], ["84178.74000000", "0.03000000"], ["84179.29000000", "0.00000000"], ["84179.57000000", "0.00000000"], ["84179.70000000", "0.00000000"], ["84179.74000000", "0.00000000"], ["84179.86000000", "0.00000000"], ["84179.91000000", "0.02215000"], ["84180.01000000", "0.00000000"], ["84180.40000000", "0.00000000"], ["84180.57000000", "0.00000000"], ["84180.59000000", "0.00000000"], ["84180.60000000", "0.33402000"], ["84180.61000000", "0.00000000"], ["84180.88000000", "0.00000000"], ["84181.08000000", "0.00000000"], ["84181.23000000", "0.00096000"], ["84181.30000000", "0.00000000"], ["84181.48000000", "0.00000000"], ["84181.55000000", "0.00000000"], ["84181.60000000", "0.00000000"], ["84181.70000000", "0.00000000"], ["84181.71000000", "0.00009000"], ["84181.73000000", "0.04000000"], ["84181.74000000", "0.00000000"], ["84181.83000000", "0.00000000"], ["84181.85000000", "0.00000000"], ["84181.94000000", "0.00000000"], ["84182.08000000", "0.00092000"], ["84182.14000000", "0.00000000"], ["84182.23000000", "0.00000000"], ["84182.36000000", "0.00029000"], ["84182.38000000", "0.78438000"], ["84182.39000000", "0.04000000"], ["84182.45000000", "0.00000000"], ["84182.69000000", "0.00000000"], ["84182.81000000", "0.00000000"], ["84182.87000000", "0.00000000"], ["84183.16000000", "0.00000000"], ["84183.20000000", "0.06000000"], ["84183.22000000", "0.00506000"], ["84183.26000000", "0.00013000"], ["84183.42000000", "0.00000000"], ["84183.49000000", "0.00000000"], ["84183.90000000", "0.00000000"], ["84184.05000000", "0.00000000"], ["84184.10000000", "0.08000000"], ["84184.12000000", "0.00000000"], ["84184.23000000", "0.00000000"], ["84184.27000000", "0.00000000"], ["84184.39000000", "0.04000000"], ["84184.62000000", "0.00417000"], ["84184.80000000", "0.00006000"], ["84184.82000000", "0.00000000"], ["84184.97000000", "0.00000000"], ["84185.06000000", "0.71063000"], ["84185.15000000", "0.00118000"], ["84185.62000000", "0.00000000"], ["84185.65000000", "0.00892000"], ["84185.90000000", "0.00000000"], ["84186.01000000", "0.00091000"], ["84186.07000000", "0.04000000"], ["84186.09000000", "0.04000000"], ["84186.21000000", "0.00000000"], ["84186.66000000", "0.00000000"], ["84186.72000000", "0.00000000"], ["84187.08000000", "0.00000000"], ["84187.24000000", "0.00000000"], ["84187.42000000", "0.59339000"], ["84187.43000000", "0.00000000"], ["84187.80000000", "0.00000000"], ["84188.27000000", "0.00000000"], ["84188.28000000", "0.00000000"], ["84188.45000000", "0.00000000"], ["84188.46000000", "0.00000000"], ["84188.49000000", "0.00000000"], ["84188.60000000", "0.04000000"], ["84188.91000000", "0.00000000"], ["84189.05000000", "0.00000000"], ["84189.11000000", "0.00012000"], ["84189.44000000", "0.04000000"], ["84189.73000000", "0.00000000"], ["84189.84000000", "0.00000000"], ["84190.02000000", "0.00000000"], ["84190.12000000", "0.35603000"], ["84190.20000000", "0.00000000"], ["84190.29000000", "0.04000000"], ["84190.30000000", "0.04000000"], ["84190.40000000", "0.04000000"], ["84190.68000000", "0.16000000"], ["84190.93000000", "0.00000000"], ["84191.58000000", "0.00013000"], ["84191.76000000", "0.00000000"], ["84191.79000000", "0.47471000"], ["84192.01000000", "0.00000000"], ["84192.10000000", "0.05937000"], ["84192.48000000", "0.00000000"], ["84192.64000000", "0.00000000"], ["84192.65000000", "0.71286000"], ["84192.66000000", "0.53593000"], ["84192.68000000", "0.00000000"], ["84192.74000000", "0.00000000"], ["84193.25000000", "2.22663000"], ["84193.90000000", "0.00000000"], ["84194.54000000", "0.00000000"], ["84194.71000000", "0.00000000"], ["84194.93000000", "0.00000000"], ["84195.19000000", "0.00000000"], ["84195.40000000", "0.89009000"], ["84195.66000000", "0.89009000"], ["84195.90000000", "0.04000000"], ["84195.98000000", "0.00000000"], ["84196.03000000", "0.00000000"], ["84196.25000000", "0.00000000"], ["84196.29000000", "0.89009000"], ["84196.50000000", "1.33724000"], ["84196.53000000", "0.00000000"], ["84196.68000000", "0.00000000"], ["84196.94000000", "0.00000000"], ["84197.18000000", "0.89009000"], ["84198.33000000", "0.00000000"], ["84199.00000000", "0.11925000"], ["84199.35000000", "0.29044000"], ["84199.42000000", "0.00013000"], ["84199.98000000", "0.00000000"], ["84200.00000000", "5.02437000"], ["84200.28000000", "0.00000000"], ["84200.70000000", "0.00000000"], ["84201.34000000", "0.00000000"], ["84201.37000000", "0.00000000"], ["84201.56000000", "0.00000000"], ["84201.59000000", "0.01861000"], ["84201.69000000", "0.00000000"], ["84201.73000000", "0.00000000"], ["84201.84000000", "0.67977000"], ["84201.85000000", "0.85549000"], ["84202.45000000", "0.00000000"], ["84203.17000000", "0.00000000"], ["84203.70000000", "0.00000000"], ["84203.96000000", "0.00000000"], ["84203.97000000", "0.00000000"], ["84204.27000000", "0.00000000"], ["84204.86000000", "0.00000000"], ["84204.87000000", "0.00000000"], ["84205.29000000", "0.00000000"], ["84206.03000000", "0.85545000"], ["84206.07000000", "0.00000000"], ["84206.80000000", "0.03514000"], ["84207.03000000", "0.00000000"], ["84207.04000000", "0.00000000"], ["84207.87000000", "0.00000000"], ["84208.42000000", "0.00084000"], ["84208.43000000", "0.00000000"], ["84209.04000000", "0.00000000"], ["84210.03000000", "0.00000000"], ["84210.45000000", "0.85541000"], ["84211.27000000", "0.00000000"], ["84211.42000000", "0.00296000"], ["84211.43000000", "0.00359000"], ["84211.76000000", "0.00000000"], ["84212.10000000", "0.00000000"], ["84212.14000000", "0.00000000"], ["84212.69000000", "0.00000000"], ["84212.78000000", "0.00000000"], ["84213.07000000", "0.00000000"], ["84213.16000000", "0.00000000"], ["84213.17000000", "0.00000000"], ["84213.54000000", "0.00000000"], ["84213.74000000", "0.85537000"], ["84214.75000000", "0.00000000"], ["84215.14000000", "0.00000000"], ["84215.15000000", "0.00000000"], ["84215.95000000", "0.00295000"], ["84216.57000000", "0.00000000"], ["84216.69000000", "0.11797000"], ["84216.88000000", "0.00935000"], ["84220.00000000", "0.44771000"], ["84220.01000000", "0.00000000"], ["84220.03000000", "0.00000000"], ["84220.10000000", "0.00821000"], ["84220.43000000", "0.35603000"], ["84221.16000000", "0.01870000"], ["84221.70000000", "0.00814000"], ["84223.87000000", "0.59538000"], ["84225.00000000", "0.00010000"], ["84225.30000000", "0.59339000"], ["84226.39000000", "0.00818000"], ["84226.92000000", "0.00865000"], ["84231.50000000", "0.00000000"], ["84232.57000000", "0.01584000"], ["84234.88000000", "0.00000000"], ["84237.18000000", "0.00000000"], ["84237.56000000", "0.00000000"], ["84240.45000000", "0.00000000"], ["84241.79000000", "0.00041000"], ["84242.95000000", "0.04000000"], ["84243.85000000", "0.03976000"], ["84245.60000000", "0.00013000"], ["84250.00000000", "2.29803000"], ["84250.47000000", "0.04000000"], ["84252.60000000", "0.00200000"], ["84252.84000000", "0.00000000"], ["84254.69000000", "0.04000000"], ["84255.54000000", "0.04000000"], ["84255.61000000", "0.03236000"], ["84255.94000000", "0.00144000"], ["84257.05000000", "0.00000000"], ["84258.13000000", "0.00000000"], ["84258.57000000", "0.04000000"], ["84258.71000000", "0.05280000"], ["84258.97000000", "0.04000000"], ["84259.82000000", "0.00000000"], ["84260.14000000", "0.00000000"], ["84262.04000000", "0.32520000"], ["84263.27000000", "0.00000000"], ["84264.03000000", "0.00000000"], ["84264.11000000", "0.04000000"], ["84281.24000000", "0.00000000"], ["84291.21000000", "0.00118000"], ["84303.31000000", "0.51055000"], ["84303.33000000", "0.14991000"], ["84303.74000000", "0.04897000"], ["84304.70000000", "0.04898000"], ["84306.27000000", "0.09795000"], ["84307.50000000", "0.04898000"], ["84310.51000000", "0.00000000"], ["84310.61000000", "0.05197000"], ["84317.65000000", "0.00035000"], ["84322.88000000", "0.04098000"], ["84337.32000000", "0.01119000"], ["84338.78000000", "0.00000000"], ["84342.37000000", "0.00000000"], ["84413.55000000", "0.45000000"], ["84414.11000000", "0.00013000"], ["84417.11000000", "0.00013000"], ["84419.03000000", "0.00000000"], ["84421.31000000", "0.00013000"], ["84486.50000000", "0.13377000"], ["84486.96000000", "0.06267000"], ["84493.73000000", "0.00000000"], ["84494.91000000", "0.06303000"], ["84806.24000000", "0.00000000"], ["84839.92000000", "0.05943000"], ["85391.70000000", "0.00007000"], ["85413.00000000", "0.11761000"], ["85425.48000000", "0.00000000"], ["85434.30000000", "0.05862000"], ["86862.05000000", "0.00065000"]], "record_time": 1742560338.040759, "EXCHANGE": "BINANCE"}
{"e": "depthUpdate", "E": 1742560339014, "s": "BTCUSDT", "U": 64609821662, "u": 64609822000, "b": [["84173.90000000", "4.62159000"], ["84173.89000000", "0.00049000"], ["84173.78000000", "0.00216000"], ["84173.77000000", "0.74266000"], ["84173.76000000", "0.00007000"], ["84173.75000000", "0.00007000"], ["84173.74000000", "0.91611000"], ["84173.39000000", "0.00015000"], ["84173.38000000", "0.00000000"], ["84172.67000000", "0.00000000"], ["84172.00000000", "0.02827000"], ["84170.75000000", "0.00012000"], ["84170.04000000", "0.00000000"], ["84170.03000000", "0.61783000"], ["84170.02000000", "0.00000000"], ["84169.68000000", "0.15691000"], ["84169.67000000", "0.35968000"], ["84166.32000000", "0.00013000"], ["84165.48000000", "0.00309000"], ["84163.80000000", "0.00006000"], ["84163.40000000", "0.00013000"], ["84163.04000000", "0.32857000"], ["84162.89000000", "0.00000000"], ["84161.60000000", "0.00000000"], ["84159.49000000", "0.01188000"], ["84159.32000000", "0.75379000"], ["84159.19000000", "0.00000000"], ["84158.80000000", "0.00000000"], ["84156.90000000", "0.05933000"], ["84156.35000000", "0.58403000"], ["84155.92000000", "0.00000000"], ["84153.61000000", "0.00000000"], ["84153.25000000", "0.00000000"], ["84153.24000000", "1.41694000"], ["84152.76000000", "0.00000000"], ["84152.65000000", "0.00000000"], ["84152.47000000", "0.04546000"], ["84151.50000000", "0.00000000"], ["84150.20000000", "0.01188000"], ["84149.62000000", "0.04710000"], ["84146.98000000", "0.00000000"], ["84146.74000000", "0.56221000"], ["84145.96000000", "0.29534000"], ["84142.26000000", "1.90528000"], ["84137.25000000", "0.00000000"], ["84135.97000000", "0.00358000"], ["84135.35000000", "0.00000000"], ["84133.81000000", "0.00000000"], ["84133.18000000", "0.35603000"], ["84131.35000000", "0.00000000"], ["84131.34000000", "0.00000000"], ["84131.03000000", "0.05899000"], ["84125.66000000", "0.00000000"], ["84125.65000000", "0.32228000"], ["84124.47000000", "0.09266000"], ["84115.80000000", "0.00821000"], ["84111.44000000", "0.06000000"], ["84110.59000000", "0.05200000"], ["84107.59000000", "0.00000000"], ["84102.32000000", "0.00000000"], ["84096.82000000", "0.04800000"], ["84089.33000000", "0.00000000"], ["84089.05000000", "0.00000000"], ["84087.72000000", "0.64799000"], ["84085.14000000", "0.93426000"], ["84080.71000000", "0.00000000"], ["84072.30000000", "0.00000000"], ["84064.11000000", "0.00000000"], ["84063.89000000", "0.00013000"], ["84061.62000000", "0.00000000"], ["84057.24000000", "0.00400000"], ["84055.47000000", "0.00000000"], ["84040.02000000", "0.00000000"], ["84039.31000000", "0.00000000"], ["84038.90000000", "0.00000000"], ["83920.57000000", "0.00000000"], ["83918.89000000", "0.08481000"], ["83916.37000000", "0.00000000"], ["83912.42000000", "0.00000000"], ["83908.22000000", "0.00000000"], ["82911.29000000", "0.00100000"], ["75756.00000000", "0.01000000"], ["75755.00000000", "0.01369000"], ["75753.00000000", "0.00153000"], ["67339.12000000", "0.00058000"], ["33000.00000000", "2.93827000"]], "a": [["84173.91000000", "0.06043000"], ["84173.92000000", "0.08559000"], ["84174.35000000", "0.00006000"], ["84174.39000000", "0.00202000"], ["84175.20000000", "0.00006000"], ["84175.99000000", "0.00000000"], ["84176.00000000", "0.00000000"], ["84176.04000000", "0.00000000"], ["84176.40000000", "0.00000000"], ["84176.80000000", "0.00000000"], ["84176.87000000", "0.00031000"], ["84176.88000000", "0.00006000"], ["84177.39000000", "0.00000000"], ["84177.40000000", "0.00000000"], ["84177.45000000", "0.00017000"], ["84177.51000000", "0.00000000"], ["84177.52000000", "0.00000000"], ["84177.53000000", "0.00000000"], ["84177.99000000", "0.00016000"], ["84178.00000000", "0.00000000"], ["84178.10000000", "0.01000000"], ["84178.44000000", "0.00000000"], ["84178.73000000", "0.00009000"], ["84179.91000000", "0.00000000"], ["84180.59000000", "0.00007000"], ["84180.60000000", "0.33396000"], ["84181.62000000", "0.04845000"], ["84181.73000000", "0.00000000"], ["84182.38000000", "0.00000000"], ["84182.39000000", "0.00000000"], ["84183.14000000", "0.02201000"], ["84183.15000000", "0.01806000"], ["84183.22000000", "0.00000000"], ["84184.10000000", "0.00000000"], ["84184.17000000", "0.00000000"], ["84185.65000000", "0.00000000"], ["84185.93000000", "0.02402000"], ["84185.99000000", "0.78435000"], ["84186.90000000", "0.00000000"], ["84187.09000000", "0.00506000"], ["84187.30000000", "0.08000000"], ["84188.64000000", "0.00066000"], ["84189.04000000", "0.00893000"], ["84189.11000000", "0.00000000"], ["84190.05000000", "0.00000000"], ["84190.62000000", "0.01188000"], ["84190.68000000", "0.00000000"], ["84190.75000000", "0.00300000"], ["84191.42000000", "0.00012000"], ["84192.66000000", "0.45013000"], ["84193.78000000", "0.00000000"], ["84193.98000000", "0.16000000"], ["84195.57000000", "0.27443000"], ["84195.90000000", "0.00000000"], ["84196.50000000", "0.00000000"], ["84197.90000000", "0.04000000"], ["84199.17000000", "0.00300000"], ["84199.91000000", "0.01188000"], ["84200.24000000", "1.37016000"], ["84201.59000000", "0.00000000"], ["84201.84000000", "0.00000000"], ["84201.85000000", "0.00000000"], ["84205.46000000", "0.04000000"], ["84209.68000000", "0.04000000"], ["84210.44000000", "1.07699000"], ["84210.52000000", "0.04000000"], ["84211.38000000", "0.04000000"], ["84212.13000000", "0.00059000"], ["84213.80000000", "0.00100000"], ["84215.43000000", "0.85536000"], ["84216.88000000", "0.00935000"], ["84220.02000000", "0.00000000"], ["84225.79000000", "0.00000000"], ["84227.04000000", "0.01196000"], ["84240.71000000", "0.00000000"], ["84241.79000000", "0.00000000"], ["84243.85000000", "0.00000000"], ["84244.12000000", "0.00000000"], ["84250.47000000", "0.00000000"], ["84250.52000000", "0.03840000"], ["84252.54000000", "0.00000000"], ["84252.60000000", "0.00000000"], ["84253.79000000", "0.03976000"], ["84254.69000000", "0.00000000"], ["84255.54000000", "0.00000000"], ["84256.40000000", "0.00200000"], ["84258.57000000", "0.00000000"], ["84258.97000000", "0.00000000"], ["84260.97000000", "0.00000000"], ["84264.11000000", "0.00000000"], ["84266.18000000", "0.00000000"], ["84269.23000000", "0.02377000"], ["84269.39000000", "0.00000000"], ["84270.77000000", "0.00841000"], ["84277.81000000", "0.00000000"], ["84302.06000000", "0.04752000"], ["84317.65000000", "0.00000000"], ["84417.11000000", "0.00000000"], ["84421.31000000", "0.00000000"], ["85436.52000000", "0.00100000"], ["86862.05000000", "0.00000000"]], "record_time": 1742560339.039348, "EXCHANGE": "BINANCE"}
