{"e": "depthUpdate", "E": 1742560340014, "s": "BTCUSDT", "U": 64609822001, "u": 64609825252, "b": [["84190.26000000", "4.88996000"], ["84190.25000000", "0.00047000"], ["84190.12000000", "0.00000000"], ["84190.10000000", "0.00000000"], ["84190.01000000", "0.00014000"], ["84190.00000000", "0.02834000"], ["84189.54000000", "0.00014000"], ["84189.53000000", "0.05951000"], ["84189.48000000", "0.00000000"], ["84189.40000000", "0.00000000"], ["84189.39000000", "0.00000000"], ["84189.38000000", "0.00000000"], ["84189.37000000", "0.00000000"], ["84189.30000000", "0.00539000"], ["84189.29000000", "0.00014000"], ["84189.28000000", "0.11014000"], ["84189.27000000", "0.00000000"], ["84188.95000000", "0.00000000"], ["84188.94000000", "0.00000000"], ["84188.91000000", "0.00000000"], ["84188.71000000", "0.00006000"], ["84188.62000000", "0.00000000"], ["84188.00000000", "0.02827000"], ["84187.07000000", "0.00000000"], ["84186.97000000", "0.00000000"], ["84186.86000000", "0.00007000"], ["84186.85000000", "0.28587000"], ["84186.84000000", "0.00000000"], ["84186.60000000", "0.00000000"], ["84186.59000000", "0.00000000"], ["84186.47000000", "0.02451000"], ["84186.15000000", "0.00000000"], ["84186.06000000", "0.00000000"], ["84186.05000000", "0.00000000"], ["84186.00000000", "0.02820000"], ["84185.83000000", "0.00000000"], ["84185.45000000", "0.00000000"], ["84185.38000000", "0.00000000"], ["84185.36000000", "0.00000000"], ["84185.17000000", "0.00000000"], ["84185.15000000", "0.00000000"], ["84185.06000000", "0.00000000"], ["84185.05000000", "0.00000000"], ["84185.04000000", "0.00000000"], ["84184.89000000", "0.00000000"], ["84184.61000000", "0.00000000"], ["84184.60000000", "0.00000000"], ["84184.49000000", "0.00000000"], ["84184.37000000", "0.00000000"], ["84184.00000000", "0.02820000"], ["84183.96000000", "0.00000000"], ["84183.86000000", "0.00015000"], ["84183.83000000", "0.00000000"], ["84183.72000000", "0.28538000"], ["84183.71000000", "0.04090000"], ["84183.70000000", "0.00000000"], ["84183.29000000", "0.00000000"], ["84183.25000000", "0.00000000"], ["84183.24000000", "0.00000000"], ["84183.14000000", "0.00000000"], ["84183.13000000", "0.45181000"], ["84182.88000000", "0.04193000"], ["84182.78000000", "0.00000000"], ["84182.77000000", "0.00000000"], ["84182.76000000", "0.08304000"], ["84182.75000000", "0.00000000"], ["84182.73000000", "0.05939000"], ["84182.62000000", "0.11877000"], ["84182.08000000", "0.02969000"], ["84182.07000000", "0.00000000"], ["84182.01000000", "0.00000000"], ["84182.00000000", "0.02820000"], ["84181.94000000", "0.00000000"], ["84181.88000000", "0.00000000"], ["84181.87000000", "0.00000000"], ["84181.86000000", "0.00000000"], ["84181.85000000", "0.00000000"], ["84181.73000000", "0.00000000"], ["84181.71000000", "0.00000000"], ["84181.70000000", "0.00000000"], ["84181.63000000", "0.00000000"], ["84181.62000000", "0.00000000"], ["84181.61000000", "0.00000000"], ["84181.59000000", "0.00000000"], ["84181.58000000", "0.00000000"], ["84181.56000000", "0.06400000"], ["84181.22000000", "0.00000000"], ["84181.01000000", "0.00000000"], ["84180.71000000", "0.00000000"], ["84180.60000000", "0.00000000"], ["84180.59000000", "0.00000000"], ["84180.58000000", "0.00000000"], ["84180.56000000", "0.08992000"], ["84180.37000000", "0.24823000"], ["84180.36000000", "0.17817000"], ["84180.27000000", "0.00000000"], ["84180.11000000", "0.00000000"], ["84180.01000000", "0.00000000"], ["84180.00000000", "0.02826000"], ["84179.99000000", "0.35603000"], ["84179.98000000", "0.00000000"], ["84179.90000000", "0.05200000"], ["84179.88000000", "0.04800000"], ["84179.73000000", "0.00000000"], ["84179.70000000", "0.00006000"], ["84179.54000000", "0.00000000"], ["84179.15000000", "0.00000000"], ["84179.14000000", "0.00000000"], ["84178.95000000", "0.00013000"], ["84178.94000000", "0.00000000"], ["84178.76000000", "0.00013000"], ["84178.74000000", "0.00000000"], ["84178.73000000", "0.03580000"], ["84178.60000000", "0.00000000"], ["84178.56000000", "0.06000000"], ["84178.33000000", "0.04193000"], ["84178.12000000", "0.00000000"], ["84178.10000000", "0.00593000"], ["84178.00000000", "0.02820000"], ["84177.90000000", "0.00000000"], ["84177.60000000", "0.04400000"], ["84177.46000000", "0.00000000"], ["84177.45000000", "0.03580000"], ["84177.35000000", "0.04000000"], ["84176.89000000", "0.00000000"], ["84176.88000000", "0.00000000"], ["84176.87000000", "0.00000000"], ["84176.80000000", "0.00000000"], ["84176.75000000", "0.03562000"], ["84176.51000000", "0.04000000"], ["84176.48000000", "0.05939000"], ["84176.40000000", "0.00006000"], ["84176.34000000", "0.00013000"], ["84176.10000000", "0.00000000"], ["84176.00000000", "0.02820000"], ["84175.84000000", "0.01187000"], ["84175.58000000", "0.04000000"], ["84175.53000000", "0.00000000"], ["84175.50000000", "0.00000000"], ["84175.47000000", "0.04000000"], ["84175.44000000", "0.06000000"], ["84175.43000000", "0.00118000"], ["84175.19000000", "0.00000000"], ["84175.15000000", "0.33597000"], ["84175.14000000", "0.34005000"], ["84174.98000000", "0.00000000"], ["84174.65000000", "0.00006000"], ["84174.38000000", "0.00000000"], ["84174.36000000", "0.00000000"], ["84174.35000000", "0.00000000"], ["84174.34000000", "0.00000000"], ["84174.25000000", "0.00000000"], ["84174.07000000", "0.00000000"], ["84174.02000000", "0.00000000"], ["84174.00000000", "0.02820000"], ["84173.92000000", "0.00000000"], ["84173.91000000", "0.00000000"], ["84173.90000000", "0.66787000"], ["84173.89000000", "0.00000000"], ["84173.87000000", "0.00037000"], ["84173.78000000", "0.00202000"], ["84173.77000000", "0.00000000"], ["84173.76000000", "0.00000000"], ["84173.75000000", "0.00000000"], ["84173.74000000", "0.08304000"], ["84173.50000000", "0.04000000"], ["84173.42000000", "0.05933000"], ["84173.39000000", "0.00000000"], ["84173.21000000", "0.00013000"], ["84172.56000000", "0.00000000"], ["84172.23000000", "0.00000000"], ["84172.20000000", "0.00006000"], ["84172.01000000", "0.00000000"], ["84172.00000000", "0.02820000"], ["84171.66000000", "0.00000000"], ["84171.25000000", "0.00029000"], ["84170.96000000", "1.06085000"], ["84170.95000000", "0.00000000"], ["84170.94000000", "0.71286000"], ["84170.93000000", "0.89009000"], ["84170.89000000", "0.01500000"], ["84170.75000000", "0.00000000"], ["84170.64000000", "0.01500000"], ["84170.31000000", "0.89009000"], ["84170.04000000", "0.17822000"], ["84170.03000000", "0.00000000"], ["84170.01000000", "0.00245000"], ["84169.75000000", "0.89009000"], ["84169.69000000", "0.00000000"], ["84169.68000000", "0.08025000"], ["84169.67000000", "0.00000000"], ["84169.60000000", "0.00006000"], ["84169.53000000", "0.05938000"], ["84169.41000000", "0.00000000"], ["84169.01000000", "0.00013000"], ["84168.73000000", "0.00000000"], ["84168.71000000", "0.01187000"], ["84168.61000000", "0.00000000"], ["84168.01000000", "0.00000000"], ["84168.00000000", "0.00006000"], ["84167.90000000", "1.37747000"], ["84167.79000000", "0.68141000"], ["84167.78000000", "0.89009000"], ["84167.53000000", "0.00000000"], ["84167.52000000", "0.59339000"], ["84167.37000000", "1.00000000"], ["84166.86000000", "0.00000000"], ["84166.85000000", "0.59413000"], ["84166.84000000", "0.08000000"], ["84166.30000000", "0.00059000"], ["84166.29000000", "0.05933000"], ["84166.16000000", "0.00013000"], ["84166.00000000", "0.00000000"], ["84165.90000000", "0.00000000"], ["84165.56000000", "0.00000000"], ["84165.54000000", "0.71286000"], ["84165.49000000", "0.00884000"], ["84164.96000000", "0.00000000"], ["84164.95000000", "0.00000000"], ["84164.74000000", "0.00000000"], ["84164.63000000", "0.00000000"], ["84164.50000000", "0.00000000"], ["84164.48000000", "0.08304000"], ["84164.14000000", "0.00000000"], ["84164.13000000", "0.00000000"], ["84164.03000000", "0.00000000"], ["84164.02000000", "0.00000000"], ["84164.00000000", "0.00000000"], ["84163.80000000", "0.02385000"], ["84163.76000000", "0.00000000"], ["84163.17000000", "0.00000000"], ["84163.04000000", "0.61228000"], ["84163.02000000", "0.03840000"], ["84162.78000000", "0.25945000"], ["84162.32000000", "0.19605000"], ["84162.31000000", "0.29525000"], ["84162.20000000", "0.00000000"], ["84162.08000000", "0.05933000"], ["84162.07000000", "0.00016000"], ["84162.00000000", "0.00000000"], ["84161.94000000", "0.01936000"], ["84161.72000000", "0.00000000"], ["84161.64000000", "0.00893000"], ["84161.19000000", "0.00000000"], ["84160.46000000", "0.00118000"], ["84160.28000000", "0.71286000"], ["84160.00000000", "0.00006000"], ["84159.99000000", "0.00000000"], ["84159.89000000", "0.00000000"], ["84159.74000000", "0.12048000"], ["84159.72000000", "0.00000000"], ["84159.49000000", "0.00000000"], ["84159.37000000", "0.00000000"], ["84159.32000000", "1.28389000"], ["84159.15000000", "0.00000000"], ["84158.37000000", "0.89009000"], ["84158.01000000", "0.00585000"], ["84158.00000000", "0.00000000"], ["84157.91000000", "0.89009000"], ["84157.74000000", "0.05613000"], ["84157.54000000", "0.00000000"], ["84156.95000000", "0.47471000"], ["84156.91000000", "0.00000000"], ["84156.90000000", "0.00000000"], ["84156.78000000", "0.35275000"], ["84156.37000000", "0.04710000"], ["84156.35000000", "0.00000000"], ["84156.32000000", "0.00000000"], ["84155.86000000", "1.00890000"], ["84155.56000000", "0.02969000"], ["84155.51000000", "0.33063000"], ["84155.50000000", "0.00000000"], ["84155.49000000", "0.00000000"], ["84155.11000000", "1.60562000"], ["84155.05000000", "0.19641000"], ["84154.93000000", "0.00355000"], ["84154.20000000", "0.06058000"], ["84154.00000000", "0.00000000"], ["84153.98000000", "0.00000000"], ["84153.72000000", "0.89009000"], ["84153.24000000", "0.00000000"], ["84153.18000000", "0.40645000"], ["84152.84000000", "0.89009000"], ["84152.40000000", "0.00000000"], ["84151.98000000", "0.00000000"], ["84151.81000000", "0.00000000"], ["84151.62000000", "0.00062000"], ["84151.49000000", "0.00000000"], ["84150.95000000", "0.00000000"], ["84150.72000000", "0.00000000"], ["84150.53000000", "0.19605000"], ["84150.20000000", "0.00000000"], ["84149.96000000", "0.52322000"], ["84149.95000000", "0.23800000"], ["84149.62000000", "0.00000000"], ["84149.46000000", "0.05942000"], ["84149.44000000", "0.35603000"], ["84148.96000000", "0.08304000"], ["84148.52000000", "0.00000000"], ["84148.17000000", "0.00059000"], ["84147.93000000", "0.00000000"], ["84147.00000000", "0.00006000"], ["84146.74000000", "0.00000000"], ["84146.44000000", "0.03324000"], ["84146.18000000", "0.00000000"], ["84145.98000000", "0.09912000"], ["84145.96000000", "0.00237000"], ["84145.37000000", "0.00000000"], ["84145.24000000", "0.05850000"], ["84144.96000000", "0.00000000"], ["84144.92000000", "0.00358000"], ["84144.76000000", "0.05497000"], ["84144.59000000", "0.00000000"], ["84144.47000000", "0.00000000"], ["84144.38000000", "0.00000000"], ["84143.85000000", "0.00000000"], ["84143.37000000", "0.00000000"], ["84143.03000000", "0.00000000"], ["84142.26000000", "0.00000000"], ["84142.02000000", "1.05408000"], ["84142.00000000", "0.02376000"], ["84141.87000000", "0.27490000"], ["84141.75000000", "0.10996000"], ["84141.31000000", "0.10794000"], ["84141.30000000", "0.29088000"], ["84140.01000000", "0.80569000"], ["84139.89000000", "0.00000000"], ["84139.70000000", "0.05398000"], ["84139.68000000", "0.00000000"], ["84139.56000000", "0.05498000"], ["84139.55000000", "0.00000000"], ["84139.06000000", "0.00000000"], ["84138.79000000", "0.09930000"], ["84138.62000000", "0.00212000"], ["84138.61000000", "0.00000000"], ["84138.35000000", "0.00000000"], ["84138.24000000", "0.00000000"], ["84137.44000000", "0.00000000"], ["84137.08000000", "0.19605000"], ["84136.95000000", "0.64487000"], ["84136.94000000", "0.00000000"], ["84136.33000000", "0.00237000"], ["84136.01000000", "0.04633000"], ["84135.97000000", "0.00000000"], ["84135.96000000", "0.00000000"], ["84135.60000000", "0.45058000"], ["84134.87000000", "0.00650000"], ["84134.51000000", "0.00000000"], ["84134.19000000", "0.00000000"], ["84133.68000000", "0.04898000"], ["84133.37000000", "0.11298000"], ["84133.18000000", "0.00000000"], ["84132.76000000", "0.13899000"], ["84132.75000000", "0.19592000"], ["84132.63000000", "0.00000000"], ["84132.21000000", "0.00820000"], ["84132.12000000", "0.10096000"], ["84132.01000000", "0.04898000"], ["84131.68000000", "0.10495000"], ["84131.34000000", "0.04000000"], ["84131.03000000", "0.00000000"], ["84130.51000000", "0.00000000"], ["84130.43000000", "0.00827000"], ["84129.87000000", "0.50050000"], ["84129.44000000", "0.00822000"], ["84128.26000000", "0.10595000"], ["84128.17000000", "0.00000000"], ["84127.95000000", "0.00000000"], ["84126.79000000", "0.20524000"], ["84126.78000000", "0.00000000"], ["84126.10000000", "0.00000000"], ["84126.07000000", "0.00000000"], ["84124.68000000", "0.00853000"], ["84122.77000000", "0.00054000"], ["84119.28000000", "0.04298000"], ["84117.20000000", "0.55244000"], ["84117.08000000", "0.04400000"], ["84115.80000000", "0.00000000"], ["84115.59000000", "0.00000000"], ["84113.27000000", "0.00000000"], ["84111.87000000", "0.86522000"], ["84111.86000000", "1.12351000"], ["84111.83000000", "0.12841000"], ["84111.25000000", "0.00358000"], ["84111.06000000", "0.00000000"], ["84110.82000000", "0.05274000"], ["84109.10000000", "0.00000000"], ["84108.88000000", "0.00000000"], ["84108.59000000", "0.00143000"], ["84108.28000000", "0.12827000"], ["84108.09000000", "0.04000000"], ["84107.87000000", "0.03172000"], ["84107.79000000", "0.00000000"], ["84106.28000000", "0.04000000"], ["84103.38000000", "0.00000000"], ["84102.41000000", "0.17822000"], ["84100.00000000", "0.06273000"], ["84099.81000000", "0.00000000"], ["84098.96000000", "0.00000000"], ["84095.77000000", "0.10258000"], ["84095.68000000", "0.12784000"], ["84095.48000000", "0.00000000"], ["84093.73000000", "0.00298000"], ["84091.91000000", "0.00000000"], ["84091.41000000", "0.33757000"], ["84090.94000000", "0.01196000"], ["84090.60000000", "0.00000000"], ["84090.25000000", "0.00000000"], ["84087.72000000", "0.28519000"], ["84086.79000000", "0.00000000"], ["84085.77000000", "0.00000000"], ["84085.28000000", "0.00597000"], ["84085.14000000", "0.00000000"], ["84084.05000000", "0.00000000"], ["84083.85000000", "0.00000000"], ["84079.14000000", "0.00000000"], ["84076.87000000", "0.00895000"], ["84070.51000000", "0.09265000"], ["84068.45000000", "0.01194000"], ["84066.92000000", "0.12000000"], ["84066.83000000", "0.00000000"], ["84066.69000000", "0.00000000"], ["84066.22000000", "0.04633000"], ["84062.58000000", "0.00000000"], ["84060.04000000", "0.01493000"], ["84057.24000000", "0.00000000"], ["84052.91000000", "0.00204000"], ["84052.65000000", "0.00000000"], ["84051.73000000", "0.00000000"], ["84047.88000000", "0.00000000"], ["84047.27000000", "0.00000000"], ["84047.23000000", "0.05497000"], ["84046.86000000", "0.00000000"], ["84046.36000000", "0.00400000"], ["84046.04000000", "0.00000000"], ["84045.43000000", "0.04633000"], ["84044.59000000", "0.00000000"], ["84044.16000000", "0.00000000"], ["84042.39000000", "0.00000000"], ["84042.32000000", "0.00000000"], ["84042.25000000", "0.00000000"], ["84042.16000000", "0.10394000"], ["84042.09000000", "0.00000000"], ["84041.86000000", "0.00000000"], ["84041.67000000", "0.00000000"], ["84041.00000000", "0.00000000"], ["84040.98000000", "0.00000000"], ["84040.28000000", "0.00000000"], ["84039.82000000", "0.00000000"], ["84039.44000000", "0.00000000"], ["84039.43000000", "0.00000000"], ["84039.35000000", "0.10394000"], ["84039.12000000", "0.04297000"], ["84039.04000000", "0.00000000"], ["84038.92000000", "0.00000000"], ["84038.65000000", "0.00000000"], ["84038.45000000", "0.00000000"], ["84038.12000000", "0.00000000"], ["84036.75000000", "0.00000000"], ["84036.73000000", "0.00000000"], ["84036.72000000", "0.00000000"], ["84036.40000000", "0.00000000"], ["84036.30000000", "0.00000000"], ["84036.23000000", "0.00000000"], ["84036.15000000", "0.00000000"], ["84036.08000000", "0.00000000"], ["84036.07000000", "0.00000000"], ["84036.06000000", "0.00000000"], ["84035.84000000", "0.00000000"], ["84035.68000000", "0.00000000"], ["84034.78000000", "0.04297000"], ["84034.44000000", "0.00000000"], ["84033.64000000", "0.00000000"], ["84033.45000000", "0.00000000"], ["84033.32000000", "0.00000000"], ["84033.21000000", "0.00000000"], ["84033.09000000", "0.00000000"], ["84032.52000000", "0.00000000"], ["84031.19000000", "0.00000000"], ["84025.97000000", "0.00000000"], ["84025.77000000", "0.00000000"], ["84024.20000000", "0.01000000"], ["84022.20000000", "0.00000000"], ["84022.00000000", "0.00000000"], ["84017.22000000", "0.00000000"], ["84016.73000000", "0.99313000"], ["84007.33000000", "0.00000000"], ["83994.95000000", "0.00013000"], ["83992.12000000", "0.00000000"], ["83960.47000000", "0.19605000"], ["83957.08000000", "0.00000000"], ["83954.02000000", "0.00451000"], ["83954.01000000", "0.00000000"], ["83952.06000000", "0.11768000"], ["83950.51000000", "0.00000000"], ["83946.06000000", "0.00000000"], ["83944.79000000", "0.00000000"], ["83942.45000000", "0.80000000"], ["83941.65000000", "0.00000000"], ["83940.27000000", "0.00000000"], ["83937.65000000", "0.00000000"], ["83937.02000000", "0.00000000"], ["83932.98000000", "0.00000000"], ["83931.48000000", "0.00000000"], ["83926.81000000", "0.00000000"], ["83923.97000000", "0.00000000"], ["83918.89000000", "0.00000000"], ["83918.00000000", "0.00000000"], ["83753.06000000", "0.00040000"], ["83753.02000000", "0.00000000"], ["83546.79000000", "0.00060000"], ["83546.78000000", "0.00000000"], ["83184.23000000", "0.00040000"], ["83184.11000000", "0.00000000"], ["83136.88000000", "0.02345000"], ["82911.29000000", "0.00000000"], ["80798.32000000", "0.03562000"], ["80781.46000000", "0.00000000"], ["79900.00000000", "5.54236000"], ["75771.00000000", "0.00020000"], ["75755.00000000", "0.01349000"], ["67352.21000000", "0.00058000"], ["67339.12000000", "0.00000000"], ["33000.00000000", "2.93827000"], ["30308.50000000", "0.00020000"]], "a": [["84173.91000000", "0.00000000"], ["84173.92000000", "0.00000000"], ["84174.35000000", "0.00000000"], ["84174.39000000", "0.00000000"], ["84175.20000000", "0.00000000"], ["84176.11000000", "0.00000000"], ["84176.78000000", "0.00000000"], ["84176.87000000", "0.00000000"], ["84176.88000000", "0.00000000"], ["84177.45000000", "0.00000000"], ["84177.46000000", "0.00000000"], ["84177.70000000", "0.00000000"], ["84177.99000000", "0.00000000"], ["84178.10000000", "0.00000000"], ["84178.18000000", "0.00000000"], ["84178.73000000", "0.00000000"], ["84178.74000000", "0.00000000"], ["84178.95000000", "0.00000000"], ["84179.69000000", "0.00000000"], ["84179.99000000", "0.00000000"], ["84180.00000000", "0.00000000"], ["84180.52000000", "0.00000000"], ["84180.59000000", "0.00000000"], ["84180.60000000", "0.00000000"], ["84181.02000000", "0.00000000"], ["84181.23000000", "0.00000000"], ["84181.48000000", "0.00000000"], ["84181.51000000", "0.00000000"], ["84181.58000000", "0.00000000"], ["84181.59000000", "0.00000000"], ["84181.62000000", "0.00000000"], ["84181.71000000", "0.00000000"], ["84181.86000000", "0.00000000"], ["84181.87000000", "0.00000000"], ["84181.95000000", "0.00000000"], ["84182.08000000", "0.00000000"], ["84182.36000000", "0.00000000"], ["84182.76000000", "0.00000000"], ["84182.79000000", "0.00000000"], ["84183.13000000", "0.00000000"], ["84183.14000000", "0.00000000"], ["84183.15000000", "0.00000000"], ["84183.20000000", "0.00000000"], ["84183.26000000", "0.00000000"], ["84183.63000000", "0.00000000"], ["84183.71000000", "0.00000000"], ["84183.72000000", "0.00000000"], ["84183.73000000", "0.00000000"], ["84184.30000000", "0.00000000"], ["84184.31000000", "0.00000000"], ["84184.38000000", "0.00000000"], ["84184.39000000", "0.00000000"], ["84184.61000000", "0.00000000"], ["84184.62000000", "0.00000000"], ["84184.80000000", "0.00000000"], ["84184.84000000", "0.00000000"], ["84184.90000000", "0.00000000"], ["84184.92000000", "0.00000000"], ["84184.93000000", "0.00000000"], ["84185.05000000", "0.00000000"], ["84185.06000000", "0.00000000"], ["84185.15000000", "0.00000000"], ["84185.16000000", "0.00000000"], ["84185.93000000", "0.00000000"], ["84185.96000000", "0.00000000"], ["84185.99000000", "0.00000000"], ["84186.01000000", "0.00000000"], ["84186.05000000", "0.00000000"], ["84186.06000000", "0.00000000"], ["84186.07000000", "0.00000000"], ["84186.09000000", "0.00000000"], ["84186.10000000", "0.00000000"], ["84186.56000000", "0.00000000"], ["84186.60000000", "0.00000000"], ["84186.81000000", "0.00000000"], ["84186.85000000", "0.00000000"], ["84186.86000000", "0.00000000"], ["84186.87000000", "0.00000000"], ["84186.96000000", "0.00000000"], ["84187.01000000", "0.00000000"], ["84187.08000000", "0.00000000"], ["84187.09000000", "0.00000000"], ["84187.29000000", "0.00000000"], ["84187.30000000", "0.00000000"], ["84187.42000000", "0.00000000"], ["84187.74000000", "0.00000000"], ["84187.85000000", "0.00000000"], ["84188.50000000", "0.00000000"], ["84188.51000000", "0.00000000"], ["84188.60000000", "0.00000000"], ["84188.62000000", "0.00000000"], ["84188.63000000", "0.00000000"], ["84188.64000000", "0.00000000"], ["84188.66000000", "0.00000000"], ["84188.70000000", "0.00000000"], ["84188.80000000", "0.00000000"], ["84188.92000000", "0.00000000"], ["84188.94000000", "0.00000000"], ["84188.95000000", "0.00000000"], ["84188.97000000", "0.00000000"], ["84188.99000000", "0.00000000"], ["84189.00000000", "0.00000000"], ["84189.04000000", "0.00000000"], ["84189.11000000", "0.00000000"], ["84189.27000000", "0.00000000"], ["84189.28000000", "0.00000000"], ["84189.44000000", "0.00000000"], ["84189.54000000", "0.00000000"], ["84189.91000000", "0.00000000"], ["84190.00000000", "0.00000000"], ["84190.12000000", "0.00000000"], ["84190.22000000", "0.00000000"], ["84190.27000000", "1.59132000"], ["84190.28000000", "0.00039000"], ["84190.29000000", "0.00000000"], ["84190.30000000", "0.00000000"], ["84190.38000000", "0.00000000"], ["84190.40000000", "0.00000000"], ["84190.51000000", "0.00000000"], ["84190.62000000", "0.00000000"], ["84190.64000000", "0.00023000"], ["84190.65000000", "0.00000000"], ["84190.71000000", "0.00062000"], ["84191.16000000", "0.00000000"], ["84191.23000000", "0.00006000"], ["84191.39000000", "0.00000000"], ["84191.42000000", "0.00000000"], ["84191.43000000", "0.00000000"], ["84191.47000000", "0.00000000"], ["84191.48000000", "0.00000000"], ["84191.49000000", "0.00000000"], ["84191.50000000", "0.00000000"], ["84191.51000000", "0.00000000"], ["84191.52000000", "0.00000000"], ["84191.58000000", "0.00000000"], ["84191.76000000", "0.00000000"], ["84191.78000000", "0.00000000"], ["84191.79000000", "0.00000000"], ["84191.87000000", "0.00007000"], ["84191.88000000", "0.03440000"], ["84191.89000000", "0.00000000"], ["84192.07000000", "0.00000000"], ["84192.10000000", "0.00000000"], ["84192.18000000", "0.00000000"], ["84192.25000000", "0.00000000"], ["84192.26000000", "0.00000000"], ["84192.52000000", "0.00000000"], ["84192.65000000", "0.00000000"], ["84192.66000000", "0.00000000"], ["84192.79000000", "0.00000000"], ["84192.84000000", "0.00007000"], ["84192.85000000", "0.02214000"], ["84193.12000000", "0.00239000"], ["84193.16000000", "0.00000000"], ["84193.17000000", "0.00000000"], ["84193.24000000", "0.00016000"], ["84193.25000000", "0.05803000"], ["84193.31000000", "0.00000000"], ["84193.61000000", "0.00000000"], ["84193.68000000", "0.00000000"], ["84193.76000000", "0.00006000"], ["84193.97000000", "0.00000000"], ["84193.98000000", "0.02301000"], ["84194.37000000", "0.00037000"], ["84194.42000000", "0.00007000"], ["84194.43000000", "0.33800000"], ["84194.54000000", "0.00000000"], ["84194.68000000", "0.00000000"], ["84194.96000000", "0.00000000"], ["84195.00000000", "0.00000000"], ["84195.01000000", "0.00000000"], ["84195.28000000", "0.00000000"], ["84195.32000000", "0.00000000"], ["84195.40000000", "0.00000000"], ["84195.48000000", "0.00000000"], ["84195.49000000", "0.00000000"], ["84195.51000000", "0.00000000"], ["84195.57000000", "0.00000000"], ["84195.61000000", "0.00000000"], ["84195.66000000", "0.00000000"], ["84195.94000000", "0.00000000"], ["84195.95000000", "0.00000000"], ["84196.00000000", "0.02820000"], ["84196.01000000", "0.00422000"], ["84196.09000000", "0.00000000"], ["84196.29000000", "0.00000000"], ["84196.48000000", "0.00000000"], ["84196.51000000", "0.00000000"], ["84196.65000000", "0.00000000"], ["84196.66000000", "0.00000000"], ["84196.71000000", "0.00000000"], ["84196.72000000", "0.00000000"], ["84196.73000000", "0.04000000"], ["84197.00000000", "0.00000000"], ["84197.01000000", "0.00000000"], ["84197.06000000", "0.00000000"], ["84197.18000000", "0.00000000"], ["84197.20000000", "0.00000000"], ["84197.21000000", "0.14000000"], ["84197.29000000", "0.00000000"], ["84197.40000000", "0.00006000"], ["84197.68000000", "0.00007000"], ["84197.70000000", "0.00000000"], ["84197.71000000", "0.00000000"], ["84197.86000000", "0.00000000"], ["84197.90000000", "0.00000000"], ["84197.96000000", "0.00000000"], ["84197.99000000", "0.00000000"], ["84198.00000000", "0.00000000"], ["84198.08000000", "0.00000000"], ["84198.11000000", "0.00000000"], ["84198.19000000", "0.00032000"], ["84198.29000000", "0.00000000"], ["84198.40000000", "0.00029000"], ["84198.43000000", "0.00000000"], ["84198.45000000", "0.78423000"], ["84198.64000000", "0.02354000"], ["84198.71000000", "0.00000000"], ["84198.73000000", "0.00000000"], ["84199.00000000", "0.00000000"], ["84199.27000000", "0.04000000"], ["84199.29000000", "0.00500000"], ["84199.35000000", "0.00000000"], ["84199.54000000", "0.00000000"], ["84199.71000000", "0.00500000"], ["84199.77000000", "0.00000000"], ["84199.84000000", "0.00090000"], ["84199.91000000", "0.00000000"], ["84199.96000000", "0.00012000"], ["84199.98000000", "0.00000000"], ["84199.99000000", "0.01000000"], ["84200.00000000", "5.02425000"], ["84200.11000000", "0.04000000"], ["84200.13000000", "0.04000000"], ["84200.24000000", "0.04000000"], ["84200.41000000", "0.01000000"], ["84200.43000000", "0.00000000"], ["84200.44000000", "0.00000000"], ["84200.73000000", "0.00000000"], ["84200.94000000", "0.04000000"], ["84201.08000000", "0.00000000"], ["84201.35000000", "0.00000000"], ["84201.70000000", "0.00000000"], ["84201.77000000", "0.05937000"], ["84202.18000000", "0.00000000"], ["84202.54000000", "0.00000000"], ["84202.76000000", "0.00000000"], ["84202.87000000", "0.00000000"], ["84202.93000000", "0.65344000"], ["84202.94000000", "0.59352000"], ["84203.02000000", "0.00095000"], ["84203.04000000", "0.00006000"], ["84203.45000000", "0.00506000"], ["84203.46000000", "0.00000000"], ["84203.49000000", "0.04000000"], ["84203.78000000", "0.16000000"], ["84203.90000000", "0.00000000"], ["84203.98000000", "0.00000000"], ["84203.99000000", "0.00000000"], ["84204.00000000", "0.05933000"], ["84204.04000000", "0.00118000"], ["84204.13000000", "0.00000000"], ["84204.20000000", "0.00000000"], ["84204.33000000", "0.00000000"], ["84204.34000000", "0.04000000"], ["84204.45000000", "0.04000000"], ["84204.57000000", "0.00000000"], ["84205.24000000", "0.00090000"], ["84205.38000000", "0.00029000"], ["84205.40000000", "0.35603000"], ["84205.46000000", "0.00000000"], ["84205.52000000", "0.89009000"], ["84206.03000000", "0.00000000"], ["84206.06000000", "0.04000000"], ["84206.14000000", "0.00000000"], ["84206.52000000", "0.00000000"], ["84206.69000000", "0.00000000"], ["84206.80000000", "0.00000000"], ["84206.87000000", "0.00000000"], ["84206.98000000", "0.01187000"], ["84207.19000000", "0.47471000"], ["84207.45000000", "0.62527000"], ["84207.46000000", "0.71286000"], ["84207.56000000", "0.00000000"], ["84207.67000000", "0.00000000"], ["84207.80000000", "0.00000000"], ["84207.95000000", "0.00000000"], ["84208.39000000", "0.00000000"], ["84208.42000000", "0.00012000"], ["84208.43000000", "0.00000000"], ["84208.92000000", "0.00000000"], ["84209.37000000", "0.00006000"], ["84209.44000000", "0.89009000"], ["84209.68000000", "0.00000000"], ["84209.90000000", "0.04000000"], ["84209.97000000", "0.21706000"], ["84210.29000000", "0.00000000"], ["84210.32000000", "0.00893000"], ["84210.44000000", "1.96708000"], ["84210.45000000", "0.00000000"], ["84210.50000000", "0.00000000"], ["84210.52000000", "0.00000000"], ["84210.58000000", "1.35127000"], ["84210.59000000", "0.00000000"], ["84210.74000000", "0.00013000"], ["84210.79000000", "0.00000000"], ["84210.97000000", "0.89009000"], ["84211.00000000", "0.89009000"], ["84211.26000000", "0.00000000"], ["84211.38000000", "0.00000000"], ["84211.42000000", "0.00000000"], ["84211.43000000", "0.00000000"], ["84212.11000000", "0.00000000"], ["84212.13000000", "0.00000000"], ["84212.19000000", "0.35856000"], ["84212.88000000", "0.00000000"], ["84213.74000000", "0.00000000"], ["84213.87000000", "0.00118000"], ["84214.12000000", "0.00000000"], ["84214.68000000", "0.00000000"], ["84214.76000000", "1.06880000"], ["84214.77000000", "0.00000000"], ["84215.17000000", "0.89009000"], ["84215.30000000", "0.00000000"], ["84215.43000000", "0.00000000"], ["84215.52000000", "0.11866000"], ["84215.57000000", "0.00000000"], ["84215.94000000", "0.00000000"], ["84215.95000000", "0.00000000"], ["84215.96000000", "0.00000000"], ["84215.99000000", "0.29037000"], ["84216.27000000", "0.01187000"], ["84216.69000000", "0.00000000"], ["84216.84000000", "0.00000000"], ["84216.88000000", "0.00000000"], ["84217.74000000", "0.00000000"], ["84218.07000000", "0.85533000"], ["84218.50000000", "0.00000000"], ["84218.70000000", "0.00000000"], ["84218.82000000", "0.03514000"], ["84218.94000000", "0.00000000"], ["84219.35000000", "0.00000000"], ["84219.60000000", "0.00016000"], ["84220.00000000", "0.54737000"], ["84220.10000000", "0.00000000"], ["84220.16000000", "0.00000000"], ["84220.34000000", "0.00000000"], ["84220.43000000", "0.00000000"], ["84220.62000000", "0.31079000"], ["84221.16000000", "0.00000000"], ["84221.59000000", "0.00935000"], ["84221.69000000", "0.00084000"], ["84221.70000000", "0.00000000"], ["84221.94000000", "0.00000000"], ["84222.16000000", "0.85529000"], ["84222.77000000", "0.00000000"], ["84222.78000000", "1.74670000"], ["84222.80000000", "0.89009000"], ["84222.87000000", "0.00000000"], ["84222.97000000", "0.00000000"], ["84223.06000000", "0.89009000"], ["84223.14000000", "0.00574000"], ["84223.57000000", "0.00100000"], ["84223.68000000", "0.89009000"], ["84223.85000000", "0.00000000"], ["84223.87000000", "0.00000000"], ["84225.30000000", "0.00000000"], ["84225.83000000", "0.00293000"], ["84225.98000000", "0.85525000"], ["84226.35000000", "0.00358000"], ["84226.39000000", "0.00000000"], ["84226.83000000", "0.89009000"], ["84226.92000000", "0.00000000"], ["84227.04000000", "0.00000000"], ["84227.65000000", "0.00353000"], ["84228.31000000", "0.00000000"], ["84228.39000000", "0.23778000"], ["84228.71000000", "0.55427000"], ["84229.44000000", "0.05927000"], ["84229.94000000", "0.85521000"], ["84231.00000000", "0.01876000"], ["84231.03000000", "0.00000000"], ["84231.04000000", "0.00000000"], ["84231.07000000", "0.00296000"], ["84232.37000000", "0.00059000"], ["84232.57000000", "0.00000000"], ["84233.60000000", "0.00000000"], ["84234.30000000", "0.26145000"], ["84234.31000000", "0.00000000"], ["84234.32000000", "0.00000000"], ["84234.89000000", "0.00000000"], ["84235.20000000", "0.11844000"], ["84235.49000000", "0.00000000"], ["84235.72000000", "0.35603000"], ["84235.88000000", "0.00000000"], ["84237.05000000", "0.57217000"], ["84237.50000000", "0.04818000"], ["84237.57000000", "0.59409000"], ["84237.58000000", "0.00815000"], ["84238.20000000", "0.47471000"], ["84238.26000000", "0.36332000"], ["84239.32000000", "0.00000000"], ["84239.48000000", "0.00853000"], ["84239.91000000", "0.00000000"], ["84240.00000000", "0.42625000"], ["84240.82000000", "0.59339000"], ["84242.97000000", "0.00808000"], ["84243.04000000", "0.01196000"], ["84243.13000000", "0.00000000"], ["84244.16000000", "0.00298000"], ["84247.03000000", "0.00000000"], ["84250.48000000", "0.04000000"], ["84250.52000000", "0.00000000"], ["84252.13000000", "0.05447000"], ["84252.25000000", "0.00000000"], ["84253.02000000", "0.08547000"], ["84253.03000000", "0.00000000"], ["84253.79000000", "0.00000000"], ["84254.69000000", "0.04000000"], ["84255.54000000", "0.04000000"], ["84255.61000000", "0.00000000"], ["84255.94000000", "0.00000000"], ["84256.32000000", "0.00597000"], ["84256.40000000", "0.00000000"], ["84256.92000000", "0.00000000"], ["84257.06000000", "0.04000000"], ["84257.59000000", "0.00000000"], ["84258.11000000", "0.35830000"], ["84258.13000000", "0.04000000"], ["84258.57000000", "0.04000000"], ["84258.71000000", "0.00000000"], ["84258.77000000", "0.00000000"], ["84258.97000000", "0.00000000"], ["84259.83000000", "0.00000000"], ["84260.02000000", "0.00358000"], ["84260.27000000", "0.00000000"], ["84261.33000000", "0.00000000"], ["84261.47000000", "0.00000000"], ["84262.03000000", "0.00041000"], ["84263.98000000", "0.00000000"], ["84264.03000000", "0.00000000"], ["84264.11000000", "0.00000000"], ["84264.43000000", "0.00000000"], ["84264.79000000", "0.00699000"], ["84265.17000000", "0.00000000"], ["84266.16000000", "0.00895000"], ["84266.30000000", "0.00000000"], ["84268.57000000", "0.02214000"], ["84268.66000000", "0.02874000"], ["84268.87000000", "0.00000000"], ["84269.23000000", "0.00000000"], ["84269.40000000", "0.00000000"], ["84269.92000000", "0.03976000"], ["84270.32000000", "0.00084000"], ["84270.33000000", "0.00000000"], ["84270.77000000", "0.04681000"], ["84270.89000000", "0.00000000"], ["84271.59000000", "0.00000000"], ["84272.80000000", "0.00200000"], ["84272.87000000", "0.03225000"], ["84273.11000000", "0.00145000"], ["84273.57000000", "0.10994000"], ["84274.89000000", "0.00000000"], ["84275.75000000", "0.00000000"], ["84275.96000000", "0.05279000"], ["84276.32000000", "0.00000000"], ["84276.33000000", "0.00000000"], ["84276.78000000", "0.10258000"], ["84277.66000000", "0.00000000"], ["84277.67000000", "0.78028000"], ["84278.79000000", "0.20459000"], ["84278.99000000", "0.00000000"], ["84279.32000000", "0.18624000"], ["84279.65000000", "0.00000000"], ["84280.42000000", "0.01194000"], ["84280.46000000", "0.00000000"], ["84281.83000000", "0.00000000"], ["84283.86000000", "0.00000000"], ["84284.02000000", "1.12121000"], ["84284.58000000", "0.12814000"], ["84285.46000000", "0.00000000"], ["84287.58000000", "0.00000000"], ["84290.86000000", "0.00000000"], ["84291.21000000", "0.00000000"], ["84295.21000000", "0.01493000"], ["84299.29000000", "0.12784000"], ["84299.61000000", "0.12827000"], ["84302.22000000", "0.00000000"], ["84304.49000000", "0.00118000"], ["84305.11000000", "0.05497000"], ["84305.25000000", "0.00013000"], ["84305.46000000", "0.10794000"], ["84307.50000000", "0.00000000"], ["84308.25000000", "0.04751000"], ["84308.43000000", "0.05497000"], ["84309.87000000", "0.10794000"], ["84311.08000000", "0.04751000"], ["84311.46000000", "0.04633000"], ["84311.63000000", "0.05497000"], ["84311.83000000", "0.05497000"], ["84313.31000000", "0.04632000"], ["84313.90000000", "0.02377000"], ["84315.19000000", "0.00118000"], ["84315.20000000", "0.05497000"], ["84315.34000000", "0.05497000"], ["84317.88000000", "0.00013000"], ["84317.99000000", "0.04098000"], ["84318.53000000", "0.00000000"], ["84319.12000000", "0.11289000"], ["84321.30000000", "0.00000000"], ["84323.01000000", "0.04898000"], ["84324.09000000", "0.04098000"], ["84324.59000000", "0.04098000"], ["84325.58000000", "0.02494000"], ["84330.47000000", "0.00000000"], ["84336.34000000", "0.04098000"], ["84337.32000000", "0.00119000"], ["84338.26000000", "0.00035000"], ["84343.31000000", "0.99233000"], ["84344.04000000", "0.21383000"], ["84346.20000000", "0.00000000"], ["84350.41000000", "0.00000000"], ["84352.36000000", "0.00023000"], ["84353.82000000", "0.00000000"], ["84354.37000000", "0.00000000"], ["84355.52000000", "0.00000000"], ["84356.47000000", "0.01000000"], ["84417.19000000", "0.00013000"], ["84421.39000000", "0.00013000"], ["84421.97000000", "0.45000000"], ["84425.34000000", "0.00027000"], ["84429.05000000", "0.00237000"], ["84429.54000000", "0.00013000"], ["84431.77000000", "0.00013000"], ["84435.97000000", "0.00013000"], ["84440.17000000", "0.00013000"], ["84444.37000000", "0.00013000"], ["84493.49000000", "0.13302000"], ["84494.70000000", "0.00000000"], ["84501.90000000", "0.19605000"], ["84510.33000000", "0.06443000"], ["84536.80000000", "0.03565000"], ["85413.00000000", "0.00036000"], ["85421.35000000", "0.11723000"], ["85436.52000000", "0.00000000"], ["86862.05000000", "0.00065000"]], "record_time": 1742560340.043655, "EXCHANGE": "BINANCE"}
{"e": "depthUpdate", "E": 1742560341014, "s": "BTCUSDT", "U": 64609825253, "u": 64609825394, "b": [["84190.26000000", "5.48633000"], ["84186.86000000", "0.00018000"], ["84186.61000000", "0.00759000"], ["84183.86000000", "0.00000000"], ["84183.73000000", "0.17822000"], ["84181.84000000", "0.00300000"], ["84180.76000000", "0.00245000"], ["84180.60000000", "0.00006000"], ["84180.36000000", "0.05939000"], ["84178.33000000", "0.00000000"], ["84175.15000000", "0.50348000"], ["84174.01000000", "0.00000000"], ["84173.42000000", "0.06233000"], ["84170.97000000", "0.59412000"], ["84170.01000000", "0.00000000"], ["84167.79000000", "1.14888000"], ["84167.52000000", "0.00000000"], ["84166.85000000", "0.00000000"], ["84165.01000000", "0.00059000"], ["84164.24000000", "0.11717000"], ["84161.07000000", "0.05000000"], ["84159.74000000", "0.00000000"], ["84155.11000000", "1.60774000"], ["84153.17000000", "0.00000000"], ["84148.50000000", "0.00000000"], ["84145.96000000", "0.00000000"], ["84144.75000000", "0.00000000"], ["84142.95000000", "0.00000000"], ["84138.62000000", "0.00000000"], ["84138.41000000", "0.59339000"], ["84105.00000000", "0.00000000"], ["84100.17000000", "0.00212000"], ["84069.06000000", "0.00000000"], ["84066.87000000", "0.00051000"], ["84062.22000000", "0.00218000"], ["84052.91000000", "0.00000000"], ["84052.66000000", "0.00400000"], ["84046.36000000", "0.00000000"], ["84039.66000000", "0.00000000"], ["84035.69000000", "0.21386000"], ["84031.60000000", "0.05942000"], ["83997.91000000", "0.00000000"], ["83993.45000000", "0.00000000"], ["83989.79000000", "0.00042000"], ["83976.01000000", "0.00181000"], ["83960.07000000", "0.00000000"], ["83946.07000000", "0.00000000"], ["83937.48000000", "0.00000000"], ["83933.98000000", "0.00000000"], ["83931.58000000", "0.00000000"], ["83929.11000000", "0.00000000"], ["83348.35000000", "0.00359000"], ["82927.40000000", "0.00100000"], ["75771.00000000", "0.00020000"], ["67352.21000000", "0.00058000"], ["33000.00000000", "2.93827000"], ["20002.00000000", "0.00000000"], ["20001.00000000", "0.02099000"]], "a": [["84190.27000000", "1.58995000"], ["84190.75000000", "0.00000000"], ["84191.16000000", "0.00007000"], ["84191.17000000", "0.03997000"], ["84191.18000000", "0.13049000"], ["84191.23000000", "0.00000000"], ["84191.87000000", "0.00000000"], ["84191.88000000", "0.00000000"], ["84192.33000000", "0.00007000"], ["84192.34000000", "0.31565000"], ["84192.84000000", "0.00000000"], ["84192.85000000", "0.00000000"], ["84193.24000000", "0.00029000"], ["84193.25000000", "0.16578000"], ["84193.53000000", "0.00000000"], ["84193.54000000", "0.00000000"], ["84193.76000000", "0.00000000"], ["84194.42000000", "0.00000000"], ["84194.43000000", "0.00000000"], ["84194.50000000", "0.01000000"], ["84194.75000000", "0.06511000"], ["84195.86000000", "0.01745000"], ["84195.99000000", "0.00038000"], ["84196.83000000", "0.02200000"], ["84198.19000000", "0.00000000"], ["84199.96000000", "0.00000000"], ["84201.77000000", "0.00000000"], ["84204.52000000", "0.05937000"], ["84205.57000000", "0.00757000"], ["84207.11000000", "0.00359000"], ["84208.44000000", "0.17822000"], ["84212.63000000", "0.02336000"], ["84215.53000000", "0.00059000"], ["84221.69000000", "0.00000000"], ["84225.82000000", "0.00084000"], ["84225.83000000", "0.00000000"], ["84227.64000000", "0.00296000"], ["84231.07000000", "0.00000000"], ["84232.05000000", "0.00295000"], ["84237.50000000", "0.09818000"], ["84270.32000000", "0.00000000"], ["84278.99000000", "0.00084000"], ["84304.49000000", "0.00000000"], ["84311.62000000", "0.00118000"], ["84444.37000000", "0.00000000"], ["85453.13000000", "0.00100000"], ["86862.05000000", "0.00000000"]], "record_time": 1742560341.040566, "EXCHANGE": "BINANCE"}
{"e": "depthUpdate", "E": 1742560342014, "s": "BTCUSDT", "U": 64609825395, "u": 64609826296, "b": [["84193.11000000", "4.36015000"], ["84193.10000000", "0.00020000"], ["84192.01000000", "0.00014000"], ["84192.00000000", "0.02848000"], ["84191.23000000", "0.00007000"], ["84191.22000000", "0.00035000"], ["84191.20000000", "0.00014000"], ["84191.19000000", "0.55544000"], ["84191.18000000", "0.00014000"], ["84191.17000000", "0.00042000"], ["84190.63000000", "0.00000000"], ["84190.39000000", "0.00000000"], ["84190.28000000", "0.00007000"], ["84190.27000000", "0.59346000"], ["84190.26000000", "0.50966000"], ["84190.25000000", "0.00026000"], ["84190.16000000", "0.00202000"], ["84190.01000000", "0.00000000"], ["84190.00000000", "0.02820000"], ["84189.55000000", "0.00000000"], ["84189.54000000", "0.00007000"], ["84189.53000000", "0.00000000"], ["84189.33000000", "0.02451000"], ["84189.30000000", "0.00000000"], ["84189.29000000", "0.00000000"], ["84189.28000000", "0.00000000"], ["84188.71000000", "0.00000000"], ["84188.06000000", "0.00761000"], ["84188.00000000", "0.02820000"], ["84187.85000000", "0.07011000"], ["84187.84000000", "0.08992000"], ["84187.77000000", "0.11877000"], ["84186.86000000", "0.00000000"], ["84186.85000000", "0.00000000"], ["84186.61000000", "0.00000000"], ["84186.47000000", "0.00000000"], ["84185.21000000", "0.00000000"], ["84185.00000000", "0.11876000"], ["84184.75000000", "0.00006000"], ["84184.34000000", "0.14000000"], ["84183.90000000", "0.08313000"], ["84183.74000000", "0.00029000"], ["84183.13000000", "0.45000000"], ["84182.88000000", "0.00000000"], ["84182.60000000", "0.00013000"], ["84182.32000000", "0.00009000"], ["84181.87000000", "0.00000000"], ["84180.64000000", "0.01500000"], ["84180.37000000", "0.42627000"], ["84180.34000000", "0.00118000"], ["84179.54000000", "0.01500000"], ["84177.77000000", "0.16000000"], ["84176.77000000", "0.71286000"], ["84176.76000000", "0.59409000"], ["84176.27000000", "0.05992000"], ["84175.44000000", "0.00000000"], ["84175.43000000", "0.00000000"], ["84175.15000000", "0.36724000"], ["84173.78000000", "0.00000000"], ["84173.42000000", "0.00300000"], ["84173.35000000", "0.47471000"], ["84172.33000000", "0.12299000"], ["84171.33000000", "0.00007000"], ["84170.97000000", "0.00000000"], ["84170.96000000", "1.06085000"], ["84170.89000000", "0.00000000"], ["84170.64000000", "0.00000000"], ["84170.00000000", "0.00000000"], ["84169.28000000", "0.05613000"], ["84167.91000000", "0.00000000"], ["84167.90000000", "0.00000000"], ["84167.88000000", "1.34343000"], ["84167.52000000", "0.00000000"], ["84166.84000000", "0.00000000"], ["84166.30000000", "0.00000000"], ["84164.24000000", "0.00000000"], ["84163.23000000", "0.00000000"], ["84161.07000000", "0.00000000"], ["84161.02000000", "0.00000000"], ["84160.27000000", "0.00000000"], ["84160.25000000", "0.00000000"], ["84157.92000000", "0.00212000"], ["84157.74000000", "0.00000000"], ["84155.11000000", "1.60562000"], ["84154.79000000", "0.00358000"], ["84154.76000000", "0.00000000"], ["84152.84000000", "0.94894000"], ["84149.47000000", "0.05497000"], ["84149.40000000", "0.00000000"], ["84148.97000000", "0.05497000"], ["84146.70000000", "0.10994000"], ["84145.24000000", "0.00000000"], ["84141.26000000", "0.00000000"], ["84140.34000000", "0.00000000"], ["84140.01000000", "0.86066000"], ["84139.56000000", "0.10995000"], ["84139.10000000", "0.00000000"], ["84138.41000000", "0.00000000"], ["84137.93000000", "0.05322000"], ["84134.87000000", "0.11244000"], ["84133.04000000", "0.02815000"], ["84132.22000000", "0.04897000"], ["84132.01000000", "0.09795000"], ["84131.34000000", "0.09197000"], ["84129.44000000", "0.06019000"], ["84115.80000000", "0.00000000"], ["84114.83000000", "0.06281000"], ["84113.00000000", "0.00119000"], ["84103.19000000", "0.00000000"], ["84100.01000000", "0.30697000"], ["84099.54000000", "0.01196000"], ["84099.28000000", "0.00000000"], ["84090.94000000", "0.00000000"], ["84084.13000000", "0.00400000"], ["84077.06000000", "0.11258000"], ["84073.78000000", "0.05197000"], ["84069.41000000", "0.12000000"], ["84065.24000000", "0.00218000"], ["84062.22000000", "0.00000000"], ["84052.66000000", "0.00000000"], ["84049.16000000", "0.10250000"], ["84047.87000000", "0.00000000"], ["84047.23000000", "0.00000000"], ["84047.21000000", "0.00000000"], ["84045.68000000", "0.00000000"], ["84043.05000000", "0.00000000"], ["84042.90000000", "0.00000000"], ["84041.74000000", "0.00000000"], ["84041.27000000", "0.00000000"], ["84040.23000000", "0.00000000"], ["84038.75000000", "0.00000000"], ["84038.61000000", "0.00000000"], ["84038.29000000", "0.00000000"], ["84036.51000000", "0.00000000"], ["84036.42000000", "0.00000000"], ["84023.42000000", "0.00000000"], ["84021.96000000", "0.00000000"], ["83999.16000000", "0.00013000"], ["83960.47000000", "0.00000000"], ["83954.91000000", "0.19601000"], ["83952.06000000", "0.00000000"], ["83946.50000000", "0.11772000"], ["83941.40000000", "0.00000000"], ["83575.70000000", "0.00000000"], ["83504.17000000", "0.00000000"], ["83179.60000000", "0.00000000"], ["83136.88000000", "0.00000000"], ["82927.40000000", "0.00000000"], ["80815.16000000", "0.00000000"], ["80798.32000000", "0.00000000"], ["75773.00000000", "0.00000000"], ["75771.00000000", "0.00020000"], ["67354.49000000", "0.00058000"], ["67352.21000000", "0.00000000"], ["33000.00000000", "2.93827000"], ["30309.52000000", "0.00020000"]], "a": [["84190.27000000", "0.00000000"], ["84190.28000000", "0.00000000"], ["84190.38000000", "0.00000000"], ["84190.64000000", "0.00000000"], ["84190.71000000", "0.00000000"], ["84190.77000000", "0.00000000"], ["84191.16000000", "0.00000000"], ["84191.17000000", "0.00000000"], ["84191.18000000", "0.00000000"], ["84191.23000000", "0.00000000"], ["84192.33000000", "0.00000000"], ["84192.34000000", "0.00000000"], ["84193.12000000", "1.89168000"], ["84193.13000000", "0.00028000"], ["84193.20000000", "0.00000000"], ["84193.23000000", "0.00000000"], ["84193.24000000", "0.00011000"], ["84193.25000000", "0.00000000"], ["84193.76000000", "0.00000000"], ["84193.97000000", "0.00000000"], ["84193.98000000", "0.00000000"], ["84194.37000000", "0.00000000"], ["84194.48000000", "0.00007000"], ["84194.49000000", "0.01369000"], ["84194.73000000", "0.00034000"], ["84194.74000000", "0.00000000"], ["84194.75000000", "0.00000000"], ["84194.96000000", "0.00000000"], ["84195.86000000", "0.00000000"], ["84195.99000000", "0.00016000"], ["84196.01000000", "0.00000000"], ["84196.73000000", "0.00000000"], ["84196.83000000", "0.00000000"], ["84197.21000000", "0.00000000"], ["84198.19000000", "0.00032000"], ["84198.40000000", "0.00000000"], ["84198.45000000", "0.00000000"], ["84198.64000000", "0.00000000"], ["84199.27000000", "0.00000000"], ["84199.29000000", "0.00000000"], ["84199.63000000", "0.00000000"], ["84199.64000000", "0.00000000"], ["84199.71000000", "0.00000000"], ["84199.80000000", "0.00000000"], ["84199.91000000", "0.00007000"], ["84199.96000000", "0.00000000"], ["84199.99000000", "0.00000000"], ["84200.11000000", "0.00000000"], ["84200.13000000", "0.00000000"], ["84200.19000000", "0.00000000"], ["84200.24000000", "0.00000000"], ["84200.41000000", "0.00000000"], ["84200.43000000", "0.00000000"], ["84200.61000000", "0.00000000"], ["84200.90000000", "0.00010000"], ["84200.91000000", "0.00000000"], ["84200.94000000", "0.00000000"], ["84200.96000000", "0.00000000"], ["84201.48000000", "0.00000000"], ["84201.75000000", "0.00029000"], ["84202.03000000", "0.00000000"], ["84202.22000000", "0.00000000"], ["84202.66000000", "0.02392000"], ["84202.70000000", "0.00000000"], ["84203.08000000", "0.00000000"], ["84203.29000000", "0.00000000"], ["84203.49000000", "0.00000000"], ["84203.71000000", "0.00000000"], ["84203.78000000", "0.00000000"], ["84204.34000000", "0.00000000"], ["84204.45000000", "0.00000000"], ["84204.52000000", "0.00000000"], ["84204.53000000", "0.06000000"], ["84204.63000000", "0.08000000"], ["84204.89000000", "0.00000000"], ["84205.26000000", "0.00000000"], ["84205.31000000", "0.00000000"], ["84205.57000000", "0.00000000"], ["84205.79000000", "0.00000000"], ["84205.92000000", "0.04000000"], ["84206.06000000", "0.00000000"], ["84206.21000000", "0.00000000"], ["84206.96000000", "0.76490000"], ["84206.97000000", "0.00000000"], ["84206.98000000", "0.00000000"], ["84207.00000000", "0.00000000"], ["84207.45000000", "0.00000000"], ["84207.46000000", "0.00000000"], ["84207.65000000", "0.00760000"], ["84207.79000000", "0.00500000"], ["84207.99000000", "0.01000000"], ["84208.03000000", "0.00000000"], ["84208.22000000", "0.00500000"], ["84208.42000000", "0.01000000"], ["84208.46000000", "0.00012000"], ["84208.92000000", "0.00000000"], ["84209.09000000", "0.00000000"], ["84209.31000000", "0.00419000"], ["84209.90000000", "0.00000000"], ["84209.97000000", "0.00000000"], ["84210.03000000", "0.01187000"], ["84210.14000000", "0.04000000"], ["84210.37000000", "0.00000000"], ["84210.38000000", "0.00000000"], ["84210.39000000", "0.00000000"], ["84210.46000000", "0.00000000"], ["84210.58000000", "0.00000000"], ["84210.97000000", "0.93009000"], ["84211.08000000", "0.05937000"], ["84211.70000000", "0.16000000"], ["84211.92000000", "0.00000000"], ["84213.16000000", "0.00000000"], ["84213.73000000", "0.00000000"], ["84213.80000000", "0.00000000"], ["84213.87000000", "0.00000000"], ["84214.46000000", "0.00000000"], ["84214.60000000", "0.04000000"], ["84214.66000000", "0.00000000"], ["84214.76000000", "0.64424000"], ["84215.52000000", "0.00000000"], ["84215.60000000", "0.00100000"], ["84216.84000000", "0.00012000"], ["84218.07000000", "0.00000000"], ["84218.37000000", "0.11866000"], ["84218.82000000", "0.00000000"], ["84220.00000000", "0.33233000"], ["84220.65000000", "0.00118000"], ["84221.59000000", "0.00000000"], ["84222.16000000", "0.00000000"], ["84225.82000000", "0.00000000"], ["84225.86000000", "0.85525000"], ["84225.98000000", "0.00000000"], ["84227.63000000", "0.00084000"], ["84227.64000000", "0.00000000"], ["84229.25000000", "0.03514000"], ["84229.44000000", "0.00000000"], ["84231.00000000", "0.00006000"], ["84231.07000000", "0.00295000"], ["84231.08000000", "0.00000000"], ["84231.89000000", "0.05000000"], ["84232.05000000", "0.00000000"], ["84232.07000000", "0.49560000"], ["84232.08000000", "0.85519000"], ["84233.57000000", "0.00000000"], ["84234.29000000", "0.00296000"], ["84234.30000000", "0.00000000"], ["84234.42000000", "0.00000000"], ["84235.20000000", "0.00006000"], ["84236.56000000", "0.00935000"], ["84237.05000000", "0.62960000"], ["84237.50000000", "0.04818000"], ["84237.57000000", "0.00000000"], ["84238.27000000", "0.01870000"], ["84240.00000000", "0.62460000"], ["84240.51000000", "0.00000000"], ["84240.89000000", "0.00000000"], ["84241.79000000", "0.59408000"], ["84248.18000000", "0.00000000"], ["84259.03000000", "0.00000000"], ["84261.32000000", "0.00000000"], ["84262.02000000", "0.00041000"], ["84262.03000000", "0.00000000"], ["84263.90000000", "0.00000000"], ["84267.01000000", "0.00000000"], ["84270.78000000", "0.00000000"], ["84271.56000000", "0.04000000"], ["84272.80000000", "0.00000000"], ["84274.93000000", "0.00000000"], ["84275.27000000", "0.00000000"], ["84275.70000000", "0.00200000"], ["84275.77000000", "0.04000000"], ["84275.97000000", "0.00000000"], ["84276.62000000", "0.04000000"], ["84277.57000000", "0.28820000"], ["84278.99000000", "0.00000000"], ["84279.00000000", "0.00000000"], ["84279.01000000", "0.00000000"], ["84279.25000000", "0.00000000"], ["84279.99000000", "0.00013000"], ["84280.47000000", "0.71287000"], ["84281.25000000", "0.00000000"], ["84282.08000000", "0.00084000"], ["84282.43000000", "0.00000000"], ["84283.53000000", "0.00000000"], ["84284.37000000", "0.00000000"], ["84285.12000000", "0.00000000"], ["84286.22000000", "0.00000000"], ["84286.23000000", "0.00000000"], ["84286.71000000", "0.00000000"], ["84287.11000000", "0.00000000"], ["84287.28000000", "0.00000000"], ["84289.58000000", "0.00000000"], ["84290.21000000", "0.00000000"], ["84290.43000000", "0.00000000"], ["84290.88000000", "0.00006000"], ["84291.22000000", "0.00000000"], ["84292.23000000", "0.00000000"], ["84292.43000000", "0.00000000"], ["84292.74000000", "0.05497000"], ["84292.75000000", "0.00000000"], ["84292.76000000", "0.00000000"], ["84293.22000000", "0.04897000"], ["84294.09000000", "0.00000000"], ["84294.16000000", "0.05497000"], ["84294.29000000", "0.00000000"], ["84294.57000000", "0.14018000"], ["84294.89000000", "0.77812000"], ["84295.03000000", "0.00000000"], ["84295.69000000", "0.00000000"], ["84296.29000000", "0.05497000"], ["84296.80000000", "0.00000000"], ["84297.49000000", "0.00000000"], ["84297.75000000", "0.00000000"], ["84298.35000000", "0.05497000"], ["84298.36000000", "0.00000000"], ["84298.59000000", "0.00000000"], ["84299.80000000", "0.00000000"], ["84299.83000000", "0.00000000"], ["84300.50000000", "0.00000000"], ["84300.53000000", "0.05497000"], ["84300.81000000", "0.00000000"], ["84301.23000000", "0.00000000"], ["84301.58000000", "0.00000000"], ["84302.93000000", "0.00000000"], ["84303.56000000", "0.05497000"], ["84303.93000000", "0.00000000"], ["84304.63000000", "0.10394000"], ["84306.77000000", "0.05197000"], ["84307.62000000", "0.10130000"], ["84308.52000000", "0.05197000"], ["84309.09000000", "0.05397000"], ["84311.00000000", "0.04897000"], ["84311.49000000", "0.05197000"], ["84311.62000000", "0.00000000"], ["84312.35000000", "0.04897000"], ["84312.67000000", "0.05497000"], ["84312.71000000", "0.05197000"], ["84312.98000000", "0.10029000"], ["84314.24000000", "0.04897000"], ["84314.68000000", "0.00118000"], ["84315.82000000", "0.05397000"], ["84315.91000000", "0.05197000"], ["84316.57000000", "0.05497000"], ["84316.65000000", "0.05197000"], ["84317.28000000", "0.05397000"], ["84317.38000000", "0.05397000"], ["84318.46000000", "0.05397000"], ["84319.38000000", "0.05197000"], ["84319.64000000", "0.05197000"], ["84319.83000000", "0.04897000"], ["84320.36000000", "0.05397000"], ["84320.66000000", "0.05397000"], ["84322.87000000", "0.05397000"], ["84323.03000000", "0.05197000"], ["84323.20000000", "0.04897000"], ["84323.33000000", "0.04897000"], ["84324.06000000", "0.05197000"], ["84325.21000000", "0.04298000"], ["84325.54000000", "0.05397000"], ["84325.55000000", "0.05197000"], ["84325.64000000", "0.05497000"], ["84325.70000000", "0.05397000"], ["84325.73000000", "0.05397000"], ["84326.93000000", "0.05197000"], ["84327.24000000", "0.04897000"], ["84327.41000000", "0.00000000"], ["84328.56000000", "0.05497000"], ["84329.64000000", "0.05197000"], ["84330.10000000", "0.05197000"], ["84330.11000000", "0.05397000"], ["84330.52000000", "0.04897000"], ["84331.39000000", "0.05497000"], ["84332.28000000", "0.04298000"], ["84332.34000000", "0.05197000"], ["84332.42000000", "0.04297000"], ["84333.37000000", "0.05197000"], ["84334.98000000", "0.05497000"], ["84335.39000000", "0.05197000"], ["84337.73000000", "0.05197000"], ["84338.25000000", "0.00035000"], ["84338.26000000", "0.00000000"], ["84347.93000000", "0.04098000"], ["84508.76000000", "0.13158000"], ["84515.41000000", "0.13147000"], ["84517.17000000", "0.06460000"], ["84523.82000000", "0.06473000"], ["85421.35000000", "0.00000000"], ["85453.13000000", "0.00000000"], ["86862.05000000", "0.00065000"], ["86987.73000000", "0.00000000"]], "record_time": 1742560342.040218, "EXCHANGE": "BINANCE"}
{"e": "depthUpdate", "E": 1742560343014, "s": "BTCUSDT", "U": 64609826297, "u": 64609826562, "b": [["84193.11000000", "4.88132000"], ["84193.10000000", "0.00048000"], ["84191.22000000", "0.00049000"], ["84191.21000000", "0.25005000"], ["84191.20000000", "0.00007000"], ["84191.19000000", "0.00021000"], ["84190.26000000", "0.01844000"], ["84190.25000000", "0.00000000"], ["84189.74000000", "0.04193000"], ["84187.85000000", "0.14790000"], ["84187.84000000", "0.00000000"], ["84187.79000000", "0.06400000"], ["84187.77000000", "0.11877000"], ["84186.94000000", "0.06000000"], ["84186.10000000", "0.05200000"], ["84186.09000000", "0.04800000"], ["84185.99000000", "0.04400000"], ["84184.80000000", "0.00006000"], ["84183.58000000", "0.04000000"], ["84182.72000000", "0.04000000"], ["84181.94000000", "0.00000000"], ["84181.90000000", "0.04000000"], ["84181.88000000", "0.04000000"], ["84181.77000000", "0.04000000"], ["84181.56000000", "0.00000000"], ["84180.37000000", "0.42627000"], ["84179.90000000", "0.00000000"], ["84179.88000000", "0.00000000"], ["84178.56000000", "0.00000000"], ["84177.60000000", "0.00000000"], ["84177.35000000", "0.00000000"], ["84176.76000000", "0.00000000"], ["84176.51000000", "0.00000000"], ["84175.58000000", "0.00000000"], ["84175.47000000", "0.00000000"], ["84175.15000000", "0.77024000"], ["84173.50000000", "0.00000000"], ["84173.30000000", "1.00000000"], ["84172.01000000", "0.59410000"], ["84167.89000000", "1.25683000"], ["84167.79000000", "0.00000000"], ["84167.37000000", "0.00000000"], ["84165.84000000", "0.06000000"], ["84165.00000000", "0.05200000"], ["84164.99000000", "0.04800000"], ["84163.08000000", "0.00000000"], ["84162.48000000", "0.04000000"], ["84160.80000000", "0.04000000"], ["84160.66000000", "0.04000000"], ["84160.18000000", "0.05000000"], ["84153.76000000", "0.00650000"], ["84146.71000000", "0.15602000"], ["84145.98000000", "0.00000000"], ["84143.83000000", "0.04400000"], ["84140.56000000", "0.04000000"], ["84139.56000000", "0.15795000"], ["84122.75000000", "0.04400000"], ["84118.48000000", "0.00000000"], ["84117.90000000", "0.00000000"], ["84117.08000000", "0.00000000"], ["84111.44000000", "0.00000000"], ["84110.59000000", "0.00000000"], ["84108.09000000", "0.00000000"], ["84106.84000000", "0.00000000"], ["84106.28000000", "0.00000000"], ["84096.82000000", "0.00000000"], ["84096.01000000", "0.00000000"], ["84093.73000000", "0.00000000"], ["84093.45000000", "0.00000000"], ["84085.28000000", "0.00000000"], ["84084.13000000", "0.00000000"], ["84076.87000000", "0.00000000"], ["84068.45000000", "0.00000000"], ["84060.04000000", "0.00000000"], ["84049.92000000", "0.00000000"], ["84048.78000000", "0.00400000"], ["84044.20000000", "0.00000000"], ["84038.74000000", "0.00000000"], ["84037.84000000", "0.00000000"], ["84028.30000000", "0.00000000"], ["84027.80000000", "0.00000000"], ["84027.60000000", "0.00000000"], ["84027.30000000", "0.01000000"], ["84024.20000000", "0.00000000"], ["83945.37000000", "0.00000000"], ["83941.68000000", "0.00000000"], ["83576.10000000", "0.00359000"], ["82930.21000000", "0.00100000"], ["75773.00000000", "0.00000000"], ["67354.49000000", "0.00058000"], ["42000.00000000", "6.85161000"], ["33000.00000000", "2.93827000"]], "a": [["84193.12000000", "1.84998000"], ["84193.13000000", "0.00056000"], ["84193.32000000", "0.00007000"], ["84193.33000000", "0.16593000"], ["84193.34000000", "0.16719000"], ["84193.72000000", "0.00023000"], ["84193.73000000", "0.32114000"], ["84194.48000000", "0.00000000"], ["84194.49000000", "0.00000000"], ["84194.50000000", "0.00000000"], ["84194.59000000", "0.00000000"], ["84194.60000000", "0.00006000"], ["84194.73000000", "0.00000000"], ["84195.15000000", "0.08294000"], ["84195.45000000", "0.00006000"], ["84195.99000000", "0.00009000"], ["84196.83000000", "0.02201000"], ["84196.90000000", "0.02301000"], ["84197.30000000", "0.01000000"], ["84199.17000000", "0.00000000"], ["84199.91000000", "0.00000000"], ["84200.90000000", "0.00010000"], ["84201.09000000", "0.00009000"], ["84201.10000000", "0.78421000"], ["84201.62000000", "0.00059000"], ["84202.50000000", "0.00012000"], ["84203.45000000", "0.00000000"], ["84204.31000000", "0.05937000"], ["84205.40000000", "0.35603000"], ["84206.30000000", "0.00507000"], ["84206.75000000", "0.04000000"], ["84206.96000000", "0.48068000"], ["84207.21000000", "0.00000000"], ["84207.27000000", "0.00059000"], ["84207.60000000", "0.08000000"], ["84207.70000000", "0.04000000"], ["84208.42000000", "0.01012000"], ["84208.46000000", "0.00000000"], ["84211.08000000", "0.00000000"], ["84211.81000000", "0.04000000"], ["84211.83000000", "0.04000000"], ["84211.92000000", "0.04000000"], ["84214.50000000", "0.00000000"], ["84214.56000000", "0.00000000"], ["84216.45000000", "0.27483000"], ["84216.82000000", "0.00000000"], ["84216.84000000", "0.00000000"], ["84217.68000000", "0.00000000"], ["84218.38000000", "0.00300000"], ["84220.00000000", "0.69443000"], ["84220.18000000", "1.34515000"], ["84221.88000000", "0.00000000"], ["84221.96000000", "0.00000000"], ["84221.99000000", "0.85529000"], ["84231.89000000", "0.00000000"], ["84232.12000000", "0.00000000"], ["84235.28000000", "0.00100000"], ["84235.60000000", "0.05000000"], ["84240.13000000", "0.00530000"], ["84242.42000000", "0.11632000"], ["84244.16000000", "0.00000000"], ["84248.23000000", "0.00000000"], ["84250.31000000", "0.00000000"], ["84255.73000000", "0.01954000"], ["84256.32000000", "0.00000000"], ["84258.98000000", "0.04000000"], ["84259.83000000", "0.04000000"], ["84262.02000000", "0.00000000"], ["84264.03000000", "0.04000000"], ["84264.11000000", "0.04000000"], ["84264.78000000", "0.00041000"], ["84266.16000000", "0.00000000"], ["84269.92000000", "0.00000000"], ["84270.77000000", "0.00000000"], ["84271.56000000", "0.00000000"], ["84275.77000000", "0.00000000"], ["84275.95000000", "0.00841000"], ["84276.62000000", "0.00000000"], ["84277.16000000", "0.03976000"], ["84278.14000000", "0.00000000"], ["84278.29000000", "0.01688000"], ["84279.21000000", "0.00000000"], ["84279.65000000", "0.00000000"], ["84280.42000000", "0.00000000"], ["84287.03000000", "0.02377000"], ["84295.21000000", "0.00000000"], ["84313.90000000", "0.00000000"], ["84315.19000000", "0.00000000"], ["84318.27000000", "0.00118000"], ["84332.96000000", "0.05197000"], ["84338.25000000", "0.00000000"], ["84343.30000000", "0.00035000"], ["84356.47000000", "0.00163000"], ["84356.82000000", "0.00000000"], ["85456.02000000", "0.00100000"], ["86862.05000000", "0.00000000"], ["86988.13000000", "0.00352000"]], "record_time": 1742560343.080041, "EXCHANGE": "BINANCE"}
{"e": "depthUpdate", "E": 1742560344014, "s": "BTCUSDT", "U": 64609826563, "u": 64609826840, "b": [["84193.11000000", "3.99786000"], ["84192.00000000", "0.02834000"], ["84191.22000000", "0.00014000"], ["84191.21000000", "0.03494000"], ["84191.20000000", "0.00007000"], ["84191.19000000", "0.00000000"], ["84191.18000000", "0.00000000"], ["84191.17000000", "0.00000000"], ["84190.30000000", "0.00000000"], ["84190.28000000", "0.00000000"], ["84190.27000000", "0.00007000"], ["84190.01000000", "0.00007000"], ["84190.00000000", "0.02827000"], ["84189.75000000", "0.00007000"], ["84187.86000000", "0.00007000"], ["84187.85000000", "0.08888000"], ["84187.77000000", "0.00000000"], ["84185.00000000", "0.00000000"], ["84181.99000000", "0.00411000"], ["84181.96000000", "0.00000000"], ["84180.60000000", "0.02394000"], ["84180.56000000", "0.00000000"], ["84180.37000000", "0.66363000"], ["84180.20000000", "0.00300000"], ["84178.03000000", "0.00000000"], ["84177.67000000", "0.59339000"], ["84177.22000000", "0.00000000"], ["84177.21000000", "0.00000000"], ["84173.09000000", "0.85579000"], ["84172.01000000", "0.00000000"], ["84170.37000000", "0.00000000"], ["84169.29000000", "0.00000000"], ["84169.03000000", "0.85583000"], ["84168.10000000", "0.00000000"], ["84166.30000000", "0.59412000"], ["84163.95000000", "0.85588000"], ["84163.80000000", "0.00006000"], ["84163.35000000", "0.85588000"], ["84163.11000000", "0.00000000"], ["84162.01000000", "0.00000000"], ["84160.18000000", "0.00000000"], ["84158.65000000", "0.00000000"], ["84156.95000000", "0.00000000"], ["84141.92000000", "0.00000000"], ["84141.74000000", "0.19644000"], ["84140.26000000", "0.59339000"], ["84133.37000000", "0.58769000"], ["84132.63000000", "0.03565000"], ["84131.24000000", "0.00000000"], ["84130.74000000", "0.05000000"], ["84108.98000000", "0.00298000"], ["84100.57000000", "0.00597000"], ["84100.01000000", "0.53329000"], ["84099.28000000", "0.93400000"], ["84092.16000000", "0.00895000"], ["84083.74000000", "0.01194000"], ["84075.40000000", "0.12000000"], ["84075.33000000", "0.01493000"], ["84057.46000000", "0.00000000"], ["84053.14000000", "0.00000000"], ["84048.78000000", "0.00000000"], ["84046.39000000", "0.04633000"], ["84041.15000000", "0.00000000"], ["84027.30000000", "0.00000000"], ["84027.20000000", "0.01000000"], ["84024.34000000", "0.00400000"], ["83602.84000000", "0.00000000"], ["83244.11000000", "0.06004000"], ["83136.88000000", "0.02344000"], ["82930.21000000", "0.00000000"], ["80798.32000000", "0.03562000"], ["75773.00000000", "0.00020000"], ["75771.00000000", "0.00000000"], ["67354.49000000", "0.00058000"], ["33000.00000000", "2.93827000"]], "a": [["84193.12000000", "2.54149000"], ["84193.15000000", "0.00039000"], ["84193.17000000", "0.00000000"], ["84193.18000000", "0.00000000"], ["84193.44000000", "0.00008000"], ["84193.66000000", "0.00000000"], ["84194.60000000", "0.00000000"], ["84195.15000000", "0.00000000"], ["84195.45000000", "0.00000000"], ["84196.67000000", "0.00000000"], ["84196.83000000", "0.00000000"], ["84196.96000000", "0.00000000"], ["84197.09000000", "0.00000000"], ["84197.30000000", "0.00500000"], ["84197.40000000", "0.00000000"], ["84197.87000000", "0.00000000"], ["84197.95000000", "0.00000000"], ["84197.98000000", "0.00000000"], ["84198.08000000", "0.00000000"], ["84198.19000000", "0.00032000"], ["84198.22000000", "0.00000000"], ["84198.47000000", "0.78423000"], ["84198.98000000", "0.00000000"], ["84199.82000000", "0.01737000"], ["84199.91000000", "0.00000000"], ["84200.33000000", "0.00012000"], ["84200.50000000", "0.00006000"], ["84200.51000000", "0.00000000"], ["84200.58000000", "0.00000000"], ["84200.59000000", "0.00000000"], ["84200.90000000", "0.00000000"], ["84201.09000000", "0.00000000"], ["84201.10000000", "0.00000000"], ["84201.11000000", "0.00013000"], ["84202.50000000", "0.00000000"], ["84210.42000000", "0.69868000"], ["84214.51000000", "0.00000000"], ["84214.52000000", "0.00000000"], ["84214.53000000", "0.00000000"], ["84214.66000000", "0.00886000"], ["84216.45000000", "0.00000000"], ["84218.00000000", "0.85533000"], ["84218.06000000", "0.00000000"], ["84231.49000000", "0.52088000"], ["84231.50000000", "0.00000000"], ["84232.07000000", "0.00000000"], ["84232.08000000", "0.00000000"], ["84235.60000000", "0.00000000"], ["84244.16000000", "0.00298000"], ["84244.40000000", "0.00000000"], ["84252.31000000", "0.00000000"], ["84260.89000000", "0.00000000"], ["84262.97000000", "0.14670000"], ["84264.85000000", "0.05794000"], ["84270.77000000", "0.03840000"], ["84277.13000000", "0.00000000"], ["84277.16000000", "0.00000000"], ["84278.52000000", "0.00895000"], ["84289.67000000", "0.01194000"], ["84309.06000000", "0.01493000"], ["84343.31000000", "0.00000000"], ["84356.47000000", "0.00199000"], ["84361.11000000", "0.99974000"], ["85442.70000000", "0.00000000"], ["85456.02000000", "0.00000000"], ["86862.05000000", "0.00000000"]], "record_time": 1742560344.039394, "EXCHANGE": "BINANCE"}
{"e": "depthUpdate", "E": 1742560345014, "s": "BTCUSDT", "U": 64609826841, "u": 64609827007, "b": [["84193.11000000", "5.03992000"], ["84187.08000000", "0.11877000"], ["84184.31000000", "0.11876000"], ["84180.76000000", "0.00000000"], ["84180.20000000", "0.00000000"], ["84179.11000000", "0.05613000"], ["84177.67000000", "0.00000000"], ["84177.30000000", "0.85574000"], ["84175.15000000", "1.15628000"], ["84174.51000000", "0.00484000"], ["84174.01000000", "0.00000000"], ["84170.97000000", "0.59411000"], ["84170.37000000", "0.59339000"], ["84170.10000000", "0.00000000"], ["84169.81000000", "0.07951000"], ["84169.57000000", "1.36492000"], ["84169.28000000", "0.00000000"], ["84167.89000000", "0.85143000"], ["84167.88000000", "0.00000000"], ["84166.30000000", "0.00000000"], ["84163.35000000", "0.00000000"], ["84152.53000000", "0.00000000"], ["84150.53000000", "0.19605000"], ["84141.90000000", "0.00000000"], ["84141.77000000", "0.00000000"], ["84140.26000000", "0.00000000"], ["84130.74000000", "0.00000000"], ["84124.92000000", "0.02851000"], ["84124.46000000", "0.00000000"], ["84122.64000000", "0.00000000"], ["84042.32000000", "0.00400000"], ["84033.42000000", "0.00000000"], ["84031.32000000", "0.00000000"], ["84027.20000000", "0.00000000"], ["84027.10000000", "0.01000000"], ["84024.73000000", "0.00000000"], ["84024.34000000", "0.00000000"], ["84018.00000000", "0.00000000"], ["83790.07000000", "0.00000000"], ["83136.88000000", "0.00000000"], ["82930.21000000", "0.00100000"], ["79900.00000000", "5.54248000"], ["75773.00000000", "0.00020000"], ["67354.49000000", "0.00058000"], ["33000.00000000", "2.93827000"]], "a": [["84193.12000000", "2.64993000"], ["84193.14000000", "0.00007000"], ["84193.15000000", "0.11927000"], ["84193.42000000", "0.00000000"], ["84195.70000000", "0.02201000"], ["84196.00000000", "0.02820000"], ["84197.30000000", "0.01000000"], ["84198.42000000", "0.00000000"], ["84198.47000000", "0.00000000"], ["84198.92000000", "0.78423000"], ["84199.37000000", "0.00477000"], ["84199.91000000", "0.00007000"], ["84200.50000000", "0.00000000"], ["84200.59000000", "0.00000000"], ["84200.71000000", "0.00000000"], ["84200.72000000", "0.00000000"], ["84200.73000000", "0.00000000"], ["84201.11000000", "0.00000000"], ["84206.10000000", "0.00000000"], ["84206.53000000", "0.08439000"], ["84212.63000000", "0.00000000"], ["84214.50000000", "0.00000000"], ["84214.51000000", "0.03564000"], ["84216.17000000", "1.37479000"], ["84218.00000000", "0.00000000"], ["84220.18000000", "0.00000000"], ["84231.49000000", "0.00000000"], ["84231.73000000", "0.85519000"], ["84234.72000000", "0.05000000"], ["84235.60000000", "0.11886000"], ["84236.56000000", "0.00000000"], ["84238.27000000", "0.00000000"], ["84242.42000000", "0.00000000"], ["84242.55000000", "0.02805000"], ["84257.23000000", "0.00000000"], ["84262.97000000", "0.10694000"], ["84268.68000000", "0.00000000"], ["84270.77000000", "0.00000000"], ["84272.50000000", "0.03976000"], ["84356.47000000", "0.00308000"], ["85456.02000000", "0.00100000"], ["86862.05000000", "0.00065000"]], "record_time": 1742560345.039358, "EXCHANGE": "BINANCE"}
{"e": "depthUpdate", "E": 1742560346014, "s": "BTCUSDT", "U": 64609827008, "u": 64609827178, "b": [["84193.11000000", "5.03350000"], ["84187.47000000", "0.11877000"], ["84187.43000000", "0.00000000"], ["84187.08000000", "0.00000000"], ["84179.91000000", "0.05938000"], ["84170.97000000", "0.00000000"], ["84170.96000000", "1.84942000"], ["84170.37000000", "0.59339000"], ["84166.30000000", "0.59412000"], ["84156.66000000", "0.05000000"], ["84152.53000000", "0.00000000"], ["84147.06000000", "0.00000000"], ["84141.93000000", "0.00000000"], ["84141.70000000", "0.00000000"], ["84108.98000000", "0.00298000"], ["84100.57000000", "0.00597000"], ["84092.16000000", "0.00895000"], ["84083.74000000", "0.01194000"], ["84075.33000000", "0.01493000"], ["84075.11000000", "0.00000000"], ["84042.33000000", "0.05297000"], ["84042.32000000", "0.00000000"], ["84036.43000000", "0.00000000"], ["83881.94000000", "0.00000000"], ["83244.11000000", "0.00000000"], ["83072.53000000", "0.00000000"], ["83072.10000000", "0.00150000"], ["82930.21000000", "0.00000000"], ["79900.00000000", "5.54236000"], ["75773.00000000", "0.00020000"], ["67354.49000000", "0.00058000"], ["60000.00000000", "73.06385000"], ["33000.00000000", "2.93827000"], ["20002.00000000", "0.00000000"], ["20001.00000000", "0.02099000"]], "a": [["84193.12000000", "2.64903000"], ["84198.83000000", "0.00000000"], ["84198.92000000", "0.00000000"], ["84200.33000000", "0.00000000"], ["84200.79000000", "0.00009000"], ["84200.80000000", "0.00000000"], ["84201.64000000", "0.00012000"], ["84203.45000000", "0.05937000"], ["84204.31000000", "0.00000000"], ["84208.42000000", "0.01012000"], ["84214.50000000", "0.00000000"], ["84214.51000000", "0.00000000"], ["84214.63000000", "0.00000000"], ["84214.65000000", "0.00000000"], ["84214.66000000", "0.00881000"], ["84231.72000000", "0.52084000"], ["84234.72000000", "0.00000000"], ["84240.22000000", "0.00000000"], ["84242.43000000", "0.00019000"], ["84244.16000000", "0.00000000"], ["84250.93000000", "0.00000000"], ["84258.87000000", "0.03976000"], ["84260.72000000", "0.03840000"], ["84261.14000000", "0.00298000"], ["84264.77000000", "0.00041000"], ["84264.78000000", "0.00000000"], ["84264.85000000", "0.05197000"], ["84271.29000000", "0.00597000"], ["84272.50000000", "0.00000000"], ["84274.62000000", "0.00000000"], ["84275.00000000", "0.00010000"], ["84275.95000000", "0.00000000"], ["84276.84000000", "0.06038000"], ["84278.52000000", "0.00000000"], ["84280.29000000", "0.00895000"], ["84289.67000000", "0.00000000"], ["84290.82000000", "1.01095000"], ["84294.38000000", "1.24533000"], ["84298.34000000", "0.01194000"], ["84309.06000000", "0.00000000"], ["84311.17000000", "0.01493000"], ["84340.13000000", "0.00048000"], ["84343.30000000", "0.00000000"], ["84356.47000000", "0.00344000"], ["84359.28000000", "0.00000000"], ["84411.25000000", "0.00000000"], ["85035.04000000", "0.00000000"], ["85456.02000000", "0.00000000"], ["86463.56000000", "0.00000000"], ["86464.13000000", "0.00147000"], ["86862.05000000", "0.00065000"]], "record_time": 1742560346.039848, "EXCHANGE": "BINANCE"}
{"e": "depthUpdate", "E": 1742560347014, "s": "BTCUSDT", "U": 64609827179, "u": 64609827369, "b": [["84193.11000000", "3.63275000"], ["84191.21000000", "0.04828000"], ["84189.31000000", "0.00007000"], ["84189.30000000", "0.05937000"], ["84188.01000000", "0.01694000"], ["84187.86000000", "0.00000000"], ["84187.85000000", "0.00000000"], ["84187.79000000", "0.00000000"], ["84187.47000000", "0.00000000"], ["84186.94000000", "0.00000000"], ["84186.10000000", "0.00000000"], ["84186.09000000", "0.00000000"], ["84185.99000000", "0.00000000"], ["84184.31000000", "0.00000000"], ["84183.90000000", "0.02375000"], ["84183.58000000", "0.00000000"], ["84182.72000000", "0.00000000"], ["84181.90000000", "0.00000000"], ["84181.88000000", "0.00000000"], ["84181.79000000", "0.06400000"], ["84181.77000000", "0.00000000"], ["84180.97000000", "0.06000000"], ["84180.13000000", "0.05200000"], ["84180.10000000", "0.04800000"], ["84180.03000000", "0.04400000"], ["84179.91000000", "0.00000000"], ["84178.86000000", "0.05938000"], ["84177.60000000", "0.04000000"], ["84177.23000000", "0.00000000"], ["84176.77000000", "0.00000000"], ["84176.75000000", "0.07562000"], ["84176.43000000", "0.59339000"], ["84175.93000000", "0.04000000"], ["84175.91000000", "0.04000000"], ["84175.80000000", "0.04000000"], ["84170.37000000", "0.00000000"], ["84165.84000000", "0.00000000"], ["84165.00000000", "0.00000000"], ["84164.99000000", "0.00000000"], ["84162.48000000", "0.00000000"], ["84160.80000000", "0.00000000"], ["84160.66000000", "0.00000000"], ["84156.66000000", "0.00000000"], ["84156.37000000", "0.00000000"], ["84152.18000000", "0.00000000"], ["84146.44000000", "0.08034000"], ["84141.85000000", "0.59339000"], ["84140.73000000", "0.00000000"], ["84118.48000000", "0.04800000"], ["84112.29000000", "0.06400000"], ["84111.44000000", "0.06000000"], ["84110.59000000", "0.05200000"], ["84110.26000000", "0.04000000"], ["84108.09000000", "0.04000000"], ["84106.28000000", "0.04000000"], ["84105.02000000", "0.00100000"], ["84101.67000000", "0.00000000"], ["84093.44000000", "0.00000000"], ["84091.91000000", "0.00000000"], ["84042.33000000", "0.04897000"], ["84031.38000000", "0.00400000"], ["84003.68000000", "0.00011000"], ["83999.22000000", "0.00000000"], ["83989.95000000", "0.00038000"], ["83626.74000000", "0.00100000"], ["83179.60000000", "0.00000000"], ["82930.21000000", "0.00100000"], ["75773.00000000", "0.00020000"], ["67354.49000000", "0.00058000"], ["33000.00000000", "2.93827000"], ["30309.52000000", "0.00040000"]], "a": [["84193.12000000", "2.90063000"], ["84193.22000000", "0.00000000"], ["84193.31000000", "0.00000000"], ["84193.62000000", "0.00000000"], ["84193.63000000", "0.00000000"], ["84193.69000000", "0.00000000"], ["84194.42000000", "0.00000000"], ["84194.47000000", "0.00000000"], ["84194.60000000", "0.00000000"], ["84195.70000000", "0.00000000"], ["84196.86000000", "0.00000000"], ["84197.30000000", "0.01000000"], ["84197.60000000", "0.00000000"], ["84198.13000000", "0.00012000"], ["84198.19000000", "0.00032000"], ["84198.84000000", "0.78423000"], ["84199.49000000", "0.00000000"], ["84199.94000000", "0.05937000"], ["84201.64000000", "0.00000000"], ["84203.45000000", "0.00000000"], ["84214.63000000", "0.00000000"], ["84214.64000000", "0.00000000"], ["84214.65000000", "0.00000000"], ["84216.84000000", "0.02384000"], ["84217.71000000", "0.00000000"], ["84218.03000000", "0.00000000"], ["84226.35000000", "0.00000000"], ["84231.56000000", "0.52191000"], ["84231.57000000", "0.85519000"], ["84231.65000000", "0.00000000"], ["84231.72000000", "0.00000000"], ["84231.73000000", "0.00000000"], ["84232.05000000", "0.59414000"], ["84233.99000000", "0.00000000"], ["84235.10000000", "0.00358000"], ["84238.90000000", "0.00000000"], ["84240.00000000", "0.00010000"], ["84241.79000000", "0.00000000"], ["84279.25000000", "0.04321000"], ["84281.20000000", "0.00100000"], ["84296.30000000", "0.75909000"], ["85421.35000000", "0.11722000"], ["85456.02000000", "0.00100000"], ["86862.05000000", "0.00000000"], ["94000.00000000", "71.02890000"]], "record_time": 1742560347.039427, "EXCHANGE": "BINANCE"}
{"e": "depthUpdate", "E": 1742560348014, "s": "BTCUSDT", "U": 64609827370, "u": 64609827490, "b": [["84193.11000000", "4.25776000"], ["84177.98000000", "0.05938000"], ["84176.44000000", "0.71286000"], ["84174.01000000", "0.59411000"], ["84173.90000000", "0.53588000"], ["84169.57000000", "0.00000000"], ["84168.06000000", "1.40758000"], ["84166.30000000", "0.00000000"], ["84152.18000000", "0.00000000"], ["84112.29000000", "0.00000000"], ["84069.79000000", "0.00051000"], ["84066.87000000", "0.00000000"], ["84036.72000000", "0.00400000"], ["84031.38000000", "0.00000000"], ["84027.10000000", "0.00000000"], ["84027.00000000", "0.00000000"], ["84025.80000000", "0.01000000"], ["84011.35000000", "0.01860000"], ["83993.81000000", "0.00042000"], ["83989.79000000", "0.00000000"], ["83751.10000000", "0.00011000"], ["83746.65000000", "0.00000000"], ["83655.90000000", "0.00196000"], ["82930.21000000", "0.00000000"], ["75773.00000000", "0.00020000"], ["67354.49000000", "0.00058000"], ["33000.00000000", "2.93827000"], ["30309.52000000", "0.00060000"]], "a": [["84193.12000000", "2.31634000"], ["84194.25000000", "0.01846000"], ["84194.60000000", "0.00006000"], ["84194.66000000", "0.00000000"], ["84194.70000000", "0.00000000"], ["84196.81000000", "0.00000000"], ["84198.00000000", "0.02820000"], ["84198.19000000", "0.00025000"], ["84198.84000000", "0.00000000"], ["84203.04000000", "0.00000000"], ["84206.94000000", "0.73071000"], ["84206.95000000", "0.71286000"], ["84206.96000000", "0.00000000"], ["84210.43000000", "1.83721000"], ["84210.44000000", "0.89009000"], ["84214.26000000", "1.34914000"], ["84214.56000000", "0.00000000"], ["84214.57000000", "0.00000000"], ["84214.58000000", "0.00000000"], ["84214.59000000", "0.00000000"], ["84216.17000000", "0.00000000"], ["84218.28000000", "0.00000000"], ["84221.14000000", "0.01860000"], ["84231.54000000", "0.85532000"], ["84231.57000000", "0.00000000"], ["84232.05000000", "0.00000000"], ["84232.69000000", "0.00000000"], ["84233.99000000", "0.00000000"], ["84235.59000000", "0.59412000"], ["84240.00000000", "0.46737000"], ["84247.44000000", "0.03840000"], ["84260.72000000", "0.00000000"], ["84356.47000000", "0.01000000"], ["84358.51000000", "0.99615000"], ["84361.11000000", "0.00000000"], ["85456.02000000", "0.00000000"], ["86862.05000000", "0.00065000"]], "record_time": 1742560348.039238, "EXCHANGE": "BINANCE"}
{"e": "depthUpdate", "E": 1742560349014, "s": "BTCUSDT", "U": 64609827491, "u": 64609827570, "b": [["84193.11000000", "3.81559000"], ["84180.37000000", "0.93164000"], ["84176.44000000", "0.00000000"], ["84174.01000000", "0.00000000"], ["84170.97000000", "0.00000000"], ["84168.07000000", "0.59412000"], ["84154.04000000", "0.00000000"], ["84153.18000000", "0.40645000"], ["84099.28000000", "0.00000000"], ["84096.45000000", "0.93400000"], ["84036.72000000", "0.00000000"], ["84029.91000000", "0.00000000"], ["84029.54000000", "0.00400000"], ["84011.35000000", "0.00000000"], ["83136.88000000", "0.02345000"], ["82930.21000000", "0.00100000"], ["75773.00000000", "0.00020000"], ["67354.49000000", "0.00058000"], ["33000.00000000", "2.93827000"], ["30309.52000000", "0.00100000"]], "a": [["84193.12000000", "2.95702000"], ["84194.25000000", "0.00000000"], ["84194.60000000", "0.00000000"], ["84197.30000000", "0.01000000"], ["84197.55000000", "0.00000000"], ["84198.19000000", "0.00032000"], ["84199.30000000", "0.78423000"], ["84218.25000000", "0.00000000"], ["84221.14000000", "0.00000000"], ["84231.45000000", "0.85519000"], ["84231.53000000", "0.52195000"], ["84231.54000000", "0.00013000"], ["84231.56000000", "0.00000000"], ["84234.50000000", "0.00000000"], ["84238.90000000", "0.00000000"], ["84276.77000000", "0.00841000"], ["84276.84000000", "0.05197000"], ["84300.65000000", "0.00010000"], ["85456.02000000", "0.00100000"], ["86862.05000000", "0.00065000"]], "record_time": 1742560349.039077, "EXCHANGE": "BINANCE"}
{"e": "depthUpdate", "E": 1742560350014, "s": "BTCUSDT", "U": 64609827571, "u": 64609827709, "b": [["84193.11000000", "4.26582000"], ["84191.20000000", "0.00007000"], ["84190.67000000", "0.00012000"], ["84190.30000000", "0.00300000"], ["84189.31000000", "0.00000000"], ["84183.90000000", "0.00000000"], ["84183.16000000", "0.00012000"], ["84180.20000000", "0.00000000"], ["84177.98000000", "0.00000000"], ["84177.57000000", "0.02375000"], ["84176.44000000", "0.71286000"], ["84176.27000000", "0.00059000"], ["84167.85000000", "0.05933000"], ["84167.56000000", "0.00118000"], ["84158.18000000", "0.00000000"], ["84154.94000000", "0.05000000"], ["84154.20000000", "0.05940000"], ["84145.87000000", "0.00178000"], ["84103.63000000", "0.00000000"], ["84029.55000000", "0.00400000"], ["84029.54000000", "0.00000000"], ["84024.39000000", "0.00000000"], ["83083.45000000", "0.40000000"], ["83075.08000000", "0.00000000"], ["82930.21000000", "0.00100000"], ["75860.09000000", "0.00000000"], ["75773.80000000", "0.00032000"], ["75773.00000000", "0.00020000"], ["67354.49000000", "0.00058000"], ["33000.00000000", "2.93827000"], ["30309.52000000", "0.00120000"]], "a": [["84193.12000000", "2.50640000"], ["84193.33000000", "0.16593000"], ["84193.72000000", "0.00023000"], ["84196.88000000", "0.00000000"], ["84196.96000000", "0.00000000"], ["84196.98000000", "0.00000000"], ["84197.17000000", "0.00000000"], ["84197.30000000", "0.00500000"], ["84197.33000000", "0.00000000"], ["84197.38000000", "0.00000000"], ["84197.58000000", "0.00000000"], ["84198.19000000", "0.00032000"], ["84198.85000000", "0.00000000"], ["84198.98000000", "0.00000000"], ["84199.07000000", "0.00000000"], ["84199.30000000", "0.00000000"], ["84204.04000000", "0.00000000"], ["84206.88000000", "0.00118000"], ["84214.58000000", "0.00000000"], ["84217.83000000", "0.00000000"], ["84217.87000000", "0.00000000"], ["84217.88000000", "0.00000000"], ["84218.03000000", "0.00000000"], ["84218.17000000", "0.00000000"], ["84218.23000000", "0.00000000"], ["84231.45000000", "0.00000000"], ["84231.46000000", "0.00000000"], ["84231.48000000", "0.00000000"], ["84231.50000000", "0.00000000"], ["84231.53000000", "0.00000000"], ["84234.32000000", "0.22731000"], ["84238.90000000", "0.05000000"], ["84243.87000000", "0.36790000"], ["84247.32000000", "0.00000000"], ["85116.34000000", "0.00000000"], ["85456.02000000", "0.00100000"], ["86862.05000000", "0.00000000"]], "record_time": 1742560350.039353, "EXCHANGE": "BINANCE"}
{"e": "depthUpdate", "E": 1742560351014, "s": "BTCUSDT", "U": 64609827710, "u": 64609827890, "b": [["84193.11000000", "4.44869000"], ["84190.30000000", "0.00000000"], ["84189.31000000", "0.00007000"], ["84183.73000000", "0.00000000"], ["84183.39000000", "0.00000000"], ["84180.38000000", "0.17822000"], ["84180.20000000", "0.00000000"], ["84179.11000000", "0.00000000"], ["84178.50000000", "0.05938000"], ["84176.76000000", "0.00000000"], ["84176.44000000", "0.71286000"], ["84176.43000000", "0.00000000"], ["84174.01000000", "0.00000000"], ["84170.97000000", "0.59411000"], ["84170.37000000", "0.00000000"], ["84170.10000000", "0.00000000"], ["84168.07000000", "0.00000000"], ["84159.38000000", "0.17822000"], ["84154.94000000", "0.00000000"], ["84153.18000000", "0.40645000"], ["84147.43000000", "0.05616000"], ["84141.85000000", "0.00000000"], ["84141.75000000", "0.10996000"], ["84141.42000000", "0.59339000"], ["84141.33000000", "0.00000000"], ["84096.33000000", "0.00000000"], ["84096.29000000", "0.01523000"], ["84040.86000000", "0.00000000"], ["84035.76000000", "0.00400000"], ["84035.46000000", "0.00000000"], ["84029.55000000", "0.00000000"], ["83179.60000000", "0.00000000"], ["83136.88000000", "0.00000000"], ["82930.21000000", "0.00000000"], ["79900.00000000", "5.54236000"], ["75773.80000000", "0.00057000"], ["75773.00000000", "0.00000000"], ["69500.00000000", "13.87269000"], ["67354.49000000", "0.00058000"], ["33000.00000000", "2.93827000"], ["20002.00000000", "0.00000000"], ["20001.00000000", "0.02099000"]], "a": [["84193.12000000", "2.95571000"], ["84193.14000000", "0.00000000"], ["84193.15000000", "0.00000000"], ["84193.99000000", "0.00000000"], ["84194.16000000", "0.00000000"], ["84194.60000000", "0.00000000"], ["84194.89000000", "0.09463000"], ["84195.45000000", "0.00006000"], ["84195.47000000", "0.00000000"], ["84196.00000000", "0.02820000"], ["84196.51000000", "0.00000000"], ["84197.30000000", "0.01000000"], ["84198.19000000", "0.00032000"], ["84198.71000000", "0.78423000"], ["84199.91000000", "0.00000000"], ["84200.64000000", "0.00008000"], ["84200.65000000", "0.00000000"], ["84200.79000000", "0.00000000"], ["84201.11000000", "0.00011000"], ["84206.10000000", "0.00000000"], ["84206.38000000", "0.00000000"], ["84208.95000000", "0.00935000"], ["84210.23000000", "0.01871000"], ["84218.22000000", "0.00000000"], ["84218.23000000", "0.00000000"], ["84231.28000000", "0.00000000"], ["84231.66000000", "0.52191000"], ["84231.67000000", "0.00000000"], ["84234.32000000", "0.00000000"], ["84237.00000000", "0.05000000"], ["84238.90000000", "0.00000000"], ["84242.55000000", "0.00000000"], ["84244.95000000", "0.00000000"], ["84311.36000000", "0.00000000"], ["84355.90000000", "0.01523000"], ["84355.94000000", "0.00000000"], ["85035.04000000", "0.00000000"], ["85124.78000000", "0.60000000"], ["85456.02000000", "0.00000000"], ["86862.05000000", "0.00065000"]], "record_time": 1742560351.039461, "EXCHANGE": "BINANCE"}
{"e": "depthUpdate", "E": 1742560352014, "s": "BTCUSDT", "U": 64609827891, "u": 64609827971, "b": [["84193.11000000", "4.24991000"], ["84170.37000000", "0.59339000"], ["84159.18000000", "0.05000000"], ["84153.18000000", "0.40645000"], ["84141.42000000", "0.00000000"], ["82930.21000000", "0.00100000"], ["75773.80000000", "0.00032000"], ["75773.00000000", "0.00020000"], ["67354.49000000", "0.00058000"], ["33000.00000000", "2.93827000"]], "a": [["84193.12000000", "2.94505000"], ["84194.67000000", "0.10801000"], ["84194.89000000", "0.00000000"], ["84195.11000000", "0.00000000"], ["84196.98000000", "0.00000000"], ["84198.71000000", "0.00000000"], ["84201.62000000", "0.00000000"], ["84205.00000000", "0.00031000"], ["84207.27000000", "0.00000000"], ["84208.95000000", "0.00000000"], ["84209.80000000", "0.00935000"], ["84214.55000000", "0.00000000"], ["84214.56000000", "0.03564000"], ["84218.18000000", "0.00000000"], ["84231.66000000", "0.00000000"], ["84231.72000000", "0.00000000"], ["84234.32000000", "0.22731000"], ["84276.77000000", "0.00000000"], ["84277.53000000", "0.00841000"], ["84291.55000000", "1.24533000"], ["84294.38000000", "0.00000000"], ["85456.02000000", "0.00100000"], ["86862.05000000", "0.00065000"]], "record_time": 1742560352.043284, "EXCHANGE": "BINANCE"}
{"e": "depthUpdate", "E": 1742560353014, "s": "BTCUSDT", "U": 64609827972, "u": 64609828112, "b": [["84193.11000000", "3.60938000"], ["84180.37000000", "0.61301000"], ["84178.28000000", "0.59339000"], ["84177.84000000", "0.85574000"], ["84177.30000000", "0.00000000"], ["84176.44000000", "0.00000000"], ["84173.90000000", "0.48589000"], ["84170.37000000", "0.00000000"], ["84163.21000000", "0.00000000"], ["84159.18000000", "0.00000000"], ["84153.41000000", "0.17820000"], ["84152.88000000", "0.00000000"], ["84141.92000000", "0.00000000"], ["84141.88000000", "0.00000000"], ["84141.78000000", "0.00000000"], ["84141.73000000", "0.00000000"], ["84141.60000000", "0.59339000"], ["84107.81000000", "0.01755000"], ["84077.88000000", "0.00000000"], ["84035.76000000", "0.00000000"], ["84027.50000000", "0.01000000"], ["84027.21000000", "0.00400000"], ["84026.10000000", "0.00000000"], ["84025.80000000", "0.00000000"], ["83136.88000000", "0.02345000"], ["82930.21000000", "0.00100000"], ["81600.00000000", "6.41546000"], ["75773.00000000", "0.00020000"], ["67354.49000000", "0.00058000"], ["42000.00000000", "6.85161000"], ["33000.00000000", "2.93827000"], ["30309.52000000", "0.00140000"]], "a": [["84193.12000000", "3.08024000"], ["84193.28000000", "0.00007000"], ["84193.29000000", "0.12338000"], ["84194.48000000", "0.00000000"], ["84194.49000000", "0.00000000"], ["84194.53000000", "0.00000000"], ["84194.60000000", "0.00000000"], ["84194.67000000", "0.00000000"], ["84195.45000000", "0.00000000"], ["84196.86000000", "0.00000000"], ["84196.92000000", "0.00000000"], ["84197.19000000", "0.00000000"], ["84197.20000000", "0.00000000"], ["84197.21000000", "0.00000000"], ["84197.28000000", "0.00000000"], ["84197.30000000", "0.01000000"], ["84198.19000000", "0.00032000"], ["84198.95000000", "0.00000000"], ["84209.80000000", "0.00000000"], ["84210.66000000", "0.00935000"], ["84214.54000000", "0.00000000"], ["84214.55000000", "0.00000000"], ["84214.56000000", "0.00000000"], ["84214.58000000", "0.03564000"], ["84217.77000000", "0.00000000"], ["84218.04000000", "0.00000000"], ["84218.05000000", "0.00000000"], ["84218.12000000", "0.00000000"], ["84231.48000000", "0.00000000"], ["84231.56000000", "0.00000000"], ["84356.47000000", "0.00050000"], ["85456.02000000", "0.00100000"], ["86862.05000000", "0.00000000"]], "record_time": 1742560353.041181, "EXCHANGE": "BINANCE"}
{"e": "depthUpdate", "E": 1742560773014, "s": "BTCUSDT", "U": 64610145665, "u": 64610146615, "b": [["83910.39000000", "7.91708000"], ["83910.38000000", "0.00046000"], ["83910.26000000", "0.00007000"], ["83910.24000000", "0.00007000"], ["83910.01000000", "0.00014000"], ["83910.00000000", "0.02834000"], ["83909.71000000", "0.00007000"], ["83909.63000000", "0.00007000"], ["83909.61000000", "0.00000000"], ["83909.60000000", "0.00000000"], ["83909.45000000", "0.00000000"], ["83909.41000000", "0.00000000"], ["83909.40000000", "0.00000000"], ["83909.23000000", "0.00000000"], ["83909.15000000", "0.00007000"], ["83909.14000000", "1.13410000"], ["83909.13000000", "0.00006000"], ["83909.12000000", "0.78707000"], ["83909.11000000", "0.85524000"], ["83909.10000000", "0.00000000"], ["83908.92000000", "0.00000000"], ["83908.91000000", "0.00000000"], ["83908.90000000", "0.00000000"], ["83908.85000000", "0.00201000"], ["83908.59000000", "0.00000000"], ["83908.58000000", "0.00000000"], ["83908.56000000", "0.00000000"], ["83908.39000000", "0.00012000"], ["83908.25000000", "0.00000000"], ["83908.09000000", "0.00000000"], ["83908.08000000", "0.00000000"], ["83908.00000000", "0.02826000"], ["83907.71000000", "0.23699000"], ["83907.63000000", "0.00101000"], ["83906.89000000", "0.00000000"], ["83906.87000000", "0.23693000"], ["83906.80000000", "0.02283000"], ["83906.65000000", "0.09040000"], ["83906.64000000", "0.10087000"], ["83905.51000000", "0.00000000"], ["83903.94000000", "0.04359000"], ["83903.85000000", "0.00000000"], ["83901.80000000", "0.08992000"], ["83901.34000000", "0.00119000"], ["83900.79000000", "0.32356000"], ["83900.07000000", "0.00000000"], ["83898.61000000", "0.00000000"], ["83898.05000000", "0.11887000"], ["83897.26000000", "0.85860000"], ["83893.41000000", "0.00000000"], ["83893.38000000", "0.10755000"], ["83892.97000000", "0.85864000"], ["83888.88000000", "0.89360000"], ["83887.72000000", "0.00000000"], ["83883.21000000", "0.05956000"], ["83881.96000000", "0.00000000"], ["83880.43000000", "0.45143000"], ["83880.31000000", "0.00000000"], ["83880.07000000", "0.00000000"], ["83879.44000000", "0.00000000"], ["83878.77000000", "0.00000000"], ["83876.21000000", "0.00000000"], ["83874.10000000", "0.00223000"], ["83872.06000000", "0.03895000"], ["83871.81000000", "0.00000000"], ["83871.37000000", "0.00000000"], ["83871.19000000", "0.00000000"], ["83869.74000000", "0.00000000"], ["83868.63000000", "0.00000000"], ["83868.19000000", "0.05885000"], ["83867.02000000", "0.05962000"], ["83866.99000000", "0.00000000"], ["83862.73000000", "0.00000000"], ["83861.05000000", "0.00000000"], ["83859.30000000", "0.00807000"], ["83846.27000000", "0.00000000"], ["83835.35000000", "0.00400000"], ["83831.26000000", "0.00297000"], ["83830.55000000", "0.05201000"], ["83830.11000000", "0.00147000"], ["83829.88000000", "0.03243000"], ["83828.76000000", "0.00000000"], ["83820.22000000", "0.31635000"], ["83819.38000000", "0.00213000"], ["83814.77000000", "0.00000000"], ["83813.67000000", "0.63099000"], ["83812.77000000", "0.00000000"], ["83812.10000000", "0.00000000"], ["83812.02000000", "0.00000000"], ["83810.38000000", "0.00000000"], ["83808.18000000", "0.00000000"], ["83807.64000000", "0.00229000"], ["83798.63000000", "0.00000000"], ["83798.62000000", "0.00000000"], ["83786.35000000", "0.12000000"], ["83786.13000000", "0.00051000"], ["83764.58000000", "0.99470000"], ["83757.43000000", "0.00156000"], ["83749.19000000", "0.00000000"], ["83748.12000000", "0.01000000"], ["83747.52000000", "0.00000000"], ["83747.12000000", "0.00000000"], ["83744.01000000", "0.00000000"], ["83720.01000000", "0.00091000"], ["83712.01000000", "0.00000000"], ["83708.01000000", "0.00042000"], ["83679.63000000", "0.00000000"], ["83672.53000000", "0.00154000"], ["83672.52000000", "0.06242000"], ["83671.24000000", "0.00000000"], ["83662.85000000", "0.00000000"], ["83655.96000000", "0.00000000"], ["83586.96000000", "0.00000000"], ["83574.74000000", "0.00150000"], ["83491.01000000", "0.00000000"], ["83071.94000000", "0.00000000"], ["82650.47000000", "0.00100000"], ["75519.00000000", "0.00000000"], ["75518.02000000", "0.00000000"], ["75518.01000000", "0.00000000"], ["75518.00000000", "0.00020000"], ["67128.32000000", "0.00058000"], ["67127.30000000", "0.00000000"], ["67127.29000000", "0.00000000"], ["42000.00000000", "6.85161000"], ["33000.01000000", "0.00119000"], ["33000.00000000", "2.93827000"], ["30207.74000000", "0.00020000"]], "a": [["83909.12000000", "0.00000000"], ["83909.13000000", "0.00000000"], ["83909.41000000", "0.00000000"], ["83909.42000000", "0.00000000"], ["83909.46000000", "0.00000000"], ["83909.61000000", "0.00000000"], ["83909.62000000", "0.00000000"], ["83909.64000000", "0.00000000"], ["83909.71000000", "0.00000000"], ["83909.72000000", "0.00000000"], ["83909.73000000", "0.00000000"], ["83910.25000000", "0.00000000"], ["83910.39000000", "0.00000000"], ["83910.40000000", "0.12294000"], ["83910.41000000", "0.00060000"], ["83911.09000000", "0.00018000"], ["83911.10000000", "0.00014000"], ["83911.80000000", "0.00000000"], ["83911.91000000", "0.00007000"], ["83911.92000000", "0.00007000"], ["83911.94000000", "0.00007000"], ["83912.00000000", "0.00007000"], ["83912.01000000", "0.00000000"], ["83912.14000000", "0.00000000"], ["83912.15000000", "0.00021000"], ["83912.16000000", "0.04502000"], ["83912.39000000", "0.00826000"], ["83912.42000000", "0.00000000"], ["83912.51000000", "0.00000000"], ["83912.71000000", "0.00000000"], ["83912.72000000", "0.00000000"], ["83912.79000000", "0.00007000"], ["83912.88000000", "0.00000000"], ["83912.89000000", "0.00000000"], ["83913.04000000", "0.00016000"], ["83913.05000000", "0.11025000"], ["83913.32000000", "0.00000000"], ["83913.39000000", "0.00000000"], ["83913.42000000", "0.00000000"], ["83913.98000000", "0.00011000"], ["83913.99000000", "0.02501000"], ["83914.00000000", "0.02833000"], ["83914.50000000", "0.00007000"], ["83914.51000000", "0.26819000"], ["83914.65000000", "0.00000000"], ["83914.88000000", "0.00000000"], ["83914.92000000", "0.00000000"], ["83914.93000000", "0.00000000"], ["83914.94000000", "0.00000000"], ["83914.95000000", "0.00000000"], ["83915.22000000", "0.00000000"], ["83915.23000000", "0.00008000"], ["83915.44000000", "0.00000000"], ["83915.54000000", "0.00000000"], ["83915.56000000", "0.12645000"], ["83915.62000000", "0.00000000"], ["83915.67000000", "0.00000000"], ["83915.75000000", "0.00000000"], ["83916.28000000", "0.00000000"], ["83916.34000000", "0.00000000"], ["83916.49000000", "0.00000000"], ["83916.62000000", "0.05686000"], ["83916.72000000", "0.02000000"], ["83917.13000000", "0.00000000"], ["83917.52000000", "0.01000000"], ["83917.55000000", "0.00000000"], ["83917.66000000", "0.02215000"], ["83917.87000000", "0.00000000"], ["83918.21000000", "0.00000000"], ["83918.66000000", "0.25588000"], ["83918.83000000", "0.00030000"], ["83919.05000000", "0.00000000"], ["83919.12000000", "0.00000000"], ["83919.14000000", "0.00094000"], ["83919.15000000", "0.00119000"], ["83919.19000000", "0.00000000"], ["83919.25000000", "0.00090000"], ["83919.37000000", "0.00000000"], ["83919.56000000", "0.00421000"], ["83920.32000000", "0.00000000"], ["83920.55000000", "0.06000000"], ["83920.65000000", "0.08000000"], ["83920.87000000", "0.00000000"], ["83921.01000000", "0.00000000"], ["83921.04000000", "0.00000000"], ["83921.25000000", "0.00091000"], ["83921.65000000", "0.00000000"], ["83921.95000000", "0.78682000"], ["83922.03000000", "0.00000000"], ["83922.54000000", "0.10755000"], ["83922.80000000", "0.00000000"], ["83922.87000000", "0.00000000"], ["83923.11000000", "0.03576000"], ["83923.23000000", "0.00506000"], ["83923.56000000", "0.00000000"], ["83923.95000000", "0.00000000"], ["83924.04000000", "0.00000000"], ["83924.10000000", "0.00000000"], ["83924.41000000", "0.00000000"], ["83924.68000000", "0.00000000"], ["83924.95000000", "0.00000000"], ["83924.97000000", "0.00000000"], ["83925.17000000", "0.00000000"], ["83925.26000000", "0.00000000"], ["83925.40000000", "0.00000000"], ["83926.36000000", "0.30238000"], ["83926.37000000", "0.00000000"], ["83926.66000000", "0.00000000"], ["83927.20000000", "0.16000000"], ["83927.82000000", "0.00012000"], ["83927.86000000", "0.05943000"], ["83928.12000000", "0.04000000"], ["83928.14000000", "0.00000000"], ["83928.18000000", "0.00000000"], ["83928.46000000", "0.00000000"], ["83928.49000000", "0.00000000"], ["83928.84000000", "0.00000000"], ["83929.89000000", "0.02352000"], ["83930.40000000", "0.00132000"], ["83931.75000000", "0.75930000"], ["83932.32000000", "0.04800000"], ["83933.17000000", "0.04800000"], ["83933.56000000", "0.00838000"], ["83934.07000000", "0.00000000"], ["83934.16000000", "0.04400000"], ["83934.56000000", "1.33771000"], ["83934.60000000", "0.00000000"], ["83934.78000000", "0.00000000"], ["83935.62000000", "0.35740000"], ["83936.37000000", "2.16379000"], ["83936.38000000", "0.00000000"], ["83936.39000000", "0.00000000"], ["83936.40000000", "0.00000000"], ["83939.54000000", "0.00000000"], ["83939.55000000", "0.00000000"], ["83940.02000000", "0.27278000"], ["83940.52000000", "0.00000000"], ["83943.17000000", "0.00000000"], ["83943.61000000", "0.05000000"], ["83944.67000000", "0.00000000"], ["83944.78000000", "0.00000000"], ["83945.11000000", "0.02805000"], ["83945.79000000", "0.89352000"], ["83947.08000000", "0.59612000"], ["83950.56000000", "0.00000000"], ["83951.05000000", "0.85805000"], ["83953.32000000", "0.00000000"], ["83954.74000000", "0.85801000"], ["83954.76000000", "0.04647000"], ["83955.73000000", "0.04647000"], ["83955.90000000", "0.00000000"], ["83958.99000000", "0.00000000"], ["83959.66000000", "0.00000000"], ["83960.05000000", "0.00297000"], ["83961.06000000", "0.00827000"], ["83964.73000000", "0.14416000"], ["83964.74000000", "0.00000000"], ["83965.93000000", "0.00000000"], ["83969.42000000", "0.12000000"], ["83971.79000000", "0.00000000"], ["83975.77000000", "0.00000000"], ["83976.43000000", "0.00000000"], ["83976.90000000", "0.00000000"], ["83977.07000000", "0.47654000"], ["83977.59000000", "0.00000000"], ["83977.60000000", "0.00000000"], ["83978.74000000", "0.00041000"], ["83980.41000000", "0.00297000"], ["83982.46000000", "0.00000000"], ["83983.13000000", "0.00000000"], ["83984.27000000", "0.00000000"], ["83985.54000000", "0.00000000"], ["83987.69000000", "0.00000000"], ["83990.75000000", "0.00000000"], ["83991.21000000", "0.03155000"], ["83991.25000000", "0.00000000"], ["83992.68000000", "0.04000000"], ["83996.14000000", "0.00000000"], ["83997.17000000", "0.04800000"], ["83998.16000000", "0.04400000"], ["83998.55000000", "0.00000000"], ["83999.99000000", "0.00000000"], ["84001.06000000", "0.04800000"], ["84007.66000000", "0.00000000"], ["84012.15000000", "0.00000000"], ["84016.48000000", "0.00060000"], ["84017.62000000", "0.00826000"], ["84020.47000000", "0.00000000"], ["84022.55000000", "0.00000000"], ["84030.59000000", "0.04647000"], ["84031.15000000", "0.00000000"], ["84036.70000000", "0.04647000"], ["84036.98000000", "0.04647000"], ["84037.21000000", "0.04647000"], ["84037.43000000", "0.04297000"], ["84038.60000000", "0.04647000"], ["84038.75000000", "0.04797000"], ["84042.51000000", "0.04297000"], ["84042.58000000", "0.05097000"], ["84044.35000000", "0.04797000"], ["84045.68000000", "0.05097000"], ["84046.73000000", "0.04297000"], ["84047.59000000", "0.04797000"], ["84048.87000000", "0.05097000"], ["84050.28000000", "0.14792000"], ["84051.72000000", "0.05097000"], ["84052.95000000", "0.00000000"], ["84053.02000000", "0.04297000"], ["84053.96000000", "0.03998000"], ["84054.57000000", "0.00035000"], ["84054.78000000", "0.05297000"], ["84059.24000000", "0.03998000"], ["84061.62000000", "0.00000000"], ["84063.99000000", "0.00000000"], ["84064.09000000", "0.05731000"], ["84065.43000000", "0.03998000"], ["84067.49000000", "0.00119000"], ["84074.37000000", "0.00000000"], ["84080.89000000", "0.00050000"], ["84140.13000000", "0.00013000"], ["84142.95000000", "0.00013000"], ["84147.14000000", "0.00000000"], ["84241.88000000", "0.19721000"], ["84260.90000000", "0.03577000"], ["84313.09000000", "0.01180000"], ["84607.88000000", "0.00000000"], ["85148.75000000", "0.11762000"], ["85167.76000000", "0.00100000"], ["86463.97000000", "0.00000000"]], "record_time": 1742560773.03927, "EXCHANGE": "BINANCE"}
{"e": "depthUpdate", "E": 1742560774014, "s": "BTCUSDT", "U": 64610146616, "u": 64610147341, "b": [["83910.39000000", "7.34759000"], ["83910.00000000", "0.02840000"], ["83909.63000000", "0.00007000"], ["83909.15000000", "0.00007000"], ["83909.14000000", "0.48103000"], ["83909.13000000", "0.00007000"], ["83909.11000000", "0.46795000"], ["83908.58000000", "0.00007000"], ["83908.39000000", "0.00012000"], ["83908.00000000", "0.02826000"], ["83907.71000000", "0.23693000"], ["83906.92000000", "0.00761000"], ["83906.87000000", "0.00000000"], ["83903.94000000", "0.02070000"], ["83903.40000000", "0.00006000"], ["83901.80000000", "0.00000000"], ["83900.80000000", "0.71493000"], ["83900.17000000", "0.00000000"], ["83900.01000000", "0.00000000"], ["83899.57000000", "0.00413000"], ["83897.26000000", "0.00000000"], ["83897.14000000", "0.10755000"], ["83893.38000000", "0.00000000"], ["83892.98000000", "0.17822000"], ["83892.97000000", "0.00000000"], ["83892.45000000", "1.75875000"], ["83890.80000000", "0.00006000"], ["83889.33000000", "1.32669000"], ["83888.94000000", "0.85868000"], ["83888.76000000", "0.00000000"], ["83888.26000000", "0.00000000"], ["83887.89000000", "0.00000000"], ["83886.35000000", "0.00000000"], ["83886.22000000", "0.00585000"], ["83885.75000000", "0.00016000"], ["83883.22000000", "0.00000000"], ["83881.61000000", "0.85876000"], ["83879.25000000", "0.00000000"], ["83877.44000000", "0.85880000"], ["83877.29000000", "0.00000000"], ["83874.90000000", "0.59615000"], ["83874.09000000", "0.00000000"], ["83872.74000000", "0.00090000"], ["83872.54000000", "0.05000000"], ["83872.31000000", "0.00000000"], ["83871.84000000", "0.00000000"], ["83871.19000000", "0.60798000"], ["83861.82000000", "0.00000000"], ["83857.63000000", "0.00000000"], ["83856.35000000", "0.00936000"], ["83855.92000000", "0.01872000"], ["83835.35000000", "0.00000000"], ["83830.19000000", "0.00000000"], ["83824.00000000", "1.21457000"], ["83823.99000000", "1.12737000"], ["83823.58000000", "0.00000000"], ["83822.67000000", "0.00000000"], ["83811.71000000", "0.00400000"], ["83751.81000000", "0.01000000"], ["83751.51000000", "0.00050000"], ["83751.31000000", "0.00000000"], ["83750.61000000", "0.00000000"], ["83749.71000000", "0.05962000"], ["83748.12000000", "0.00000000"], ["83732.96000000", "0.00000000"], ["83701.15000000", "0.00040000"], ["83701.11000000", "0.00000000"], ["83672.53000000", "0.00000000"], ["83657.22000000", "0.00154000"], ["83657.21000000", "0.00000000"], ["83657.20000000", "0.00000000"], ["83493.90000000", "0.00119000"], ["83479.78000000", "0.00000000"], ["83479.77000000", "0.00040000"], ["83479.65000000", "0.00000000"], ["83072.38000000", "0.00150000"], ["82650.47000000", "0.00000000"], ["75519.02000000", "0.00000000"], ["75519.01000000", "0.00000000"], ["75519.00000000", "0.00020000"], ["75518.00000000", "0.00000000"], ["67128.33000000", "0.00000000"], ["67128.32000000", "0.00058000"], ["33000.01000000", "0.00000000"], ["33000.00000000", "2.93827000"], ["30207.74000000", "0.00060000"]], "a": [["83910.40000000", "1.48027000"], ["83910.41000000", "0.00060000"], ["83910.47000000", "0.00014000"], ["83910.48000000", "0.12859000"], ["83910.50000000", "0.00007000"], ["83910.51000000", "0.00007000"], ["83910.52000000", "0.00007000"], ["83910.55000000", "0.00022000"], ["83910.56000000", "0.09223000"], ["83910.57000000", "0.13612000"], ["83911.09000000", "0.00000000"], ["83911.10000000", "0.00000000"], ["83911.29000000", "0.00000000"], ["83911.89000000", "0.00000000"], ["83911.90000000", "0.00000000"], ["83911.91000000", "0.00000000"], ["83911.92000000", "0.00000000"], ["83911.94000000", "0.00000000"], ["83912.00000000", "0.00000000"], ["83912.13000000", "0.00000000"], ["83912.14000000", "0.00000000"], ["83912.15000000", "0.00014000"], ["83912.16000000", "0.04502000"], ["83912.23000000", "0.00000000"], ["83912.24000000", "0.00000000"], ["83912.76000000", "0.00000000"], ["83912.79000000", "0.00007000"], ["83913.04000000", "0.00017000"], ["83913.05000000", "0.11012000"], ["83913.18000000", "0.00000000"], ["83913.19000000", "0.00000000"], ["83913.32000000", "0.00000000"], ["83913.63000000", "0.00000000"], ["83913.69000000", "0.00000000"], ["83913.86000000", "0.00000000"], ["83913.87000000", "0.00000000"], ["83913.98000000", "0.00018000"], ["83913.99000000", "0.02488000"], ["83914.00000000", "0.00000000"], ["83914.14000000", "0.00000000"], ["83914.15000000", "0.00000000"], ["83914.17000000", "0.00000000"], ["83914.45000000", "0.00000000"], ["83914.48000000", "0.00007000"], ["83914.49000000", "0.50085000"], ["83914.50000000", "0.78689000"], ["83914.51000000", "0.00000000"], ["83914.55000000", "0.00000000"], ["83914.60000000", "0.00500000"], ["83914.78000000", "0.00000000"], ["83915.56000000", "0.00000000"], ["83915.83000000", "0.00000000"], ["83915.84000000", "0.00000000"], ["83915.99000000", "0.00009000"], ["83916.00000000", "0.02820000"], ["83916.62000000", "0.00000000"], ["83917.46000000", "0.00000000"], ["83917.47000000", "0.00006000"], ["83917.66000000", "0.00000000"], ["83918.23000000", "0.12172000"], ["83918.24000000", "0.00000000"], ["83918.65000000", "0.00000000"], ["83918.66000000", "0.00000000"], ["83918.80000000", "0.00000000"], ["83918.82000000", "0.04797000"], ["83919.13000000", "0.00000000"], ["83919.14000000", "0.00000000"], ["83919.25000000", "0.00000000"], ["83919.27000000", "0.00000000"], ["83919.38000000", "0.00000000"], ["83919.56000000", "0.00000000"], ["83920.07000000", "0.00000000"], ["83920.12000000", "0.00000000"], ["83920.40000000", "0.00000000"], ["83920.84000000", "0.00012000"], ["83920.87000000", "0.02424000"], ["83921.95000000", "0.00000000"], ["83922.29000000", "0.43394000"], ["83922.30000000", "0.00000000"], ["83922.54000000", "0.00000000"], ["83922.55000000", "0.00000000"], ["83922.79000000", "0.00000000"], ["83923.82000000", "0.10763000"], ["83923.92000000", "0.00760000"], ["83924.60000000", "0.05943000"], ["83924.65000000", "0.00000000"], ["83924.77000000", "0.00000000"], ["83924.97000000", "0.00000000"], ["83925.17000000", "0.00012000"], ["83926.36000000", "0.36786000"], ["83927.20000000", "0.61000000"], ["83927.82000000", "0.00000000"], ["83927.86000000", "0.00000000"], ["83928.96000000", "0.04000000"], ["83929.79000000", "0.04800000"], ["83929.80000000", "0.04000000"], ["83929.96000000", "0.04400000"], ["83931.57000000", "0.36016000"], ["83931.73000000", "0.69455000"], ["83931.74000000", "0.71493000"], ["83931.75000000", "0.00000000"], ["83932.07000000", "0.00000000"], ["83933.56000000", "0.00826000"], ["83933.99000000", "0.04400000"], ["83934.01000000", "0.04400000"], ["83934.56000000", "0.00000000"], ["83936.14000000", "0.00000000"], ["83936.80000000", "1.32829000"], ["83937.26000000", "0.72072000"], ["83938.72000000", "0.05763000"], ["83939.31000000", "0.85817000"], ["83940.39000000", "0.59615000"], ["83942.00000000", "0.00500000"], ["83943.61000000", "0.05000000"], ["83944.36000000", "0.85812000"], ["83947.08000000", "0.00000000"], ["83951.72000000", "0.38417000"], ["83953.06000000", "0.00000000"], ["83954.74000000", "0.00000000"], ["83954.76000000", "0.00000000"], ["83955.73000000", "0.00000000"], ["83956.14000000", "0.05088000"], ["83960.06000000", "0.00000000"], ["83964.33000000", "0.01196000"], ["83969.50000000", "0.00000000"], ["83973.37000000", "0.71436000"], ["83976.43000000", "0.00000000"], ["83976.52000000", "0.00000000"], ["83978.73000000", "0.00041000"], ["83978.74000000", "0.00000000"], ["83989.61000000", "0.59514000"], ["83992.01000000", "0.00000000"], ["83992.17000000", "0.05246000"], ["83992.68000000", "0.00000000"], ["83994.91000000", "0.00000000"], ["83996.19000000", "0.00000000"], ["83997.17000000", "0.00000000"], ["83997.95000000", "0.00000000"], ["83997.96000000", "0.00000000"], ["83998.16000000", "0.00000000"], ["84001.06000000", "0.00000000"], ["84035.90000000", "0.04647000"], ["84048.07000000", "0.05397000"], ["84054.56000000", "0.00035000"], ["84054.57000000", "0.00000000"], ["84055.91000000", "0.02502000"], ["84074.37000000", "0.00000000"], ["84080.89000000", "0.00000000"], ["84081.99000000", "0.00000000"], ["84082.19000000", "0.00000000"], ["84082.54000000", "0.00000000"], ["84082.69000000", "0.01000000"], ["84234.36000000", "0.19359000"], ["84241.88000000", "0.00000000"], ["84242.75000000", "0.00362000"], ["85167.76000000", "0.00000000"], ["86463.41000000", "0.00156000"], ["86521.90000000", "0.00907000"]], "record_time": 1742560774.072582, "EXCHANGE": "BINANCE"}
{"e": "depthUpdate", "E": 1742560775014, "s": "BTCUSDT", "U": 64610147342, "u": 64610147692, "b": [["83910.39000000", "4.70948000"], ["83910.38000000", "0.00046000"], ["83910.37000000", "0.00007000"], ["83910.00000000", "0.02834000"], ["83909.71000000", "0.00007000"], ["83909.63000000", "0.00000000"], ["83909.38000000", "0.00000000"], ["83909.37000000", "0.00006000"], ["83909.19000000", "0.00007000"], ["83909.18000000", "0.01517000"], ["83909.11000000", "0.46788000"], ["83908.39000000", "0.00000000"], ["83904.01000000", "0.01730000"], ["83903.94000000", "0.00000000"], ["83903.63000000", "0.00000000"], ["83902.38000000", "0.00006000"], ["83900.80000000", "0.71493000"], ["83900.69000000", "0.66254000"], ["83900.67000000", "0.03580000"], ["83900.28000000", "0.00095000"], ["83900.10000000", "0.00000000"], ["83900.00000000", "1.81410000"], ["83899.65000000", "0.00091000"], ["83898.05000000", "0.00000000"], ["83897.34000000", "0.00006000"], ["83890.10000000", "1.00000000"], ["83889.60000000", "0.11866000"], ["83888.94000000", "0.00000000"], ["83888.82000000", "0.85869000"], ["83879.25000000", "0.78532000"], ["83874.90000000", "0.00000000"], ["83873.39000000", "0.00000000"], ["83872.54000000", "0.00000000"], ["83872.06000000", "0.00000000"], ["83871.20000000", "0.59619000"], ["83870.61000000", "0.00000000"], ["83865.23000000", "0.00000000"], ["83862.54000000", "0.03895000"], ["83860.78000000", "0.03434000"], ["83855.92000000", "0.00000000"], ["83853.35000000", "0.01872000"], ["83815.76000000", "0.54310000"], ["83813.67000000", "0.00000000"], ["83811.71000000", "0.00000000"], ["83811.29000000", "0.00000000"], ["83810.84000000", "0.63111000"], ["83805.33000000", "0.00000000"], ["83790.88000000", "0.00000000"], ["83787.95000000", "0.12100000"], ["83783.28000000", "0.00000000"], ["83772.61000000", "0.00400000"], ["83751.81000000", "0.00000000"], ["83751.61000000", "0.01000000"], ["83672.53000000", "0.00000000"], ["83672.52000000", "0.19724000"], ["83664.13000000", "0.14641000"], ["83657.26000000", "0.00154000"], ["83657.22000000", "0.00000000"], ["83493.90000000", "0.00000000"], ["83487.95000000", "0.00119000"], ["83442.68000000", "0.00000000"], ["83433.38000000", "0.00000000"], ["83433.37000000", "0.00060000"], ["83402.53000000", "0.00000000"], ["83393.23000000", "0.00040000"], ["82651.74000000", "0.00000000"], ["82651.73000000", "0.00100000"], ["79700.00000000", "1.69288000"], ["75519.01000000", "0.00000000"], ["75519.00000000", "0.00020000"], ["75503.90000000", "0.00018000"], ["67128.32000000", "0.00058000"], ["33000.00000000", "2.93827000"], ["30207.74000000", "0.00100000"]], "a": [["83910.40000000", "3.78247000"], ["83910.41000000", "0.00060000"], ["83910.46000000", "0.00022000"], ["83910.47000000", "0.34728000"], ["83910.48000000", "0.12865000"], ["83910.51000000", "0.00007000"], ["83910.52000000", "0.00000000"], ["83910.55000000", "0.00000000"], ["83910.56000000", "0.00007000"], ["83910.57000000", "0.13618000"], ["83912.16000000", "0.04502000"], ["83912.42000000", "0.00000000"], ["83912.43000000", "0.78691000"], ["83912.59000000", "0.00000000"], ["83912.60000000", "0.00000000"], ["83912.80000000", "0.00000000"], ["83912.81000000", "0.00000000"], ["83913.05000000", "0.11018000"], ["83913.97000000", "0.04797000"], ["83913.99000000", "0.02488000"], ["83914.48000000", "0.00000000"], ["83914.49000000", "0.26478000"], ["83914.50000000", "0.00000000"], ["83916.75000000", "0.00000000"], ["83918.23000000", "0.25616000"], ["83918.41000000", "0.00012000"], ["83918.68000000", "0.00000000"], ["83918.80000000", "0.45000000"], ["83918.82000000", "0.00000000"], ["83919.15000000", "0.00119000"], ["83919.24000000", "0.00000000"], ["83919.32000000", "0.05943000"], ["83920.07000000", "0.01786000"], ["83920.53000000", "0.00000000"], ["83920.84000000", "0.00000000"], ["83920.87000000", "0.00000000"], ["83921.25000000", "0.00000000"], ["83921.82000000", "0.00000000"], ["83923.92000000", "0.00000000"], ["83924.60000000", "0.00000000"], ["83925.00000000", "0.00055000"], ["83925.51000000", "0.00119000"], ["83925.65000000", "0.00760000"], ["83925.92000000", "0.37471000"], ["83926.36000000", "0.37826000"], ["83929.60000000", "0.00896000"], ["83929.69000000", "0.00000000"], ["83930.40000000", "0.00013000"], ["83931.57000000", "0.00000000"], ["83932.07000000", "0.00908000"], ["83933.16000000", "0.59618000"], ["83933.87000000", "0.05902000"], ["83935.25000000", "0.85821000"], ["83937.61000000", "0.00006000"], ["83938.72000000", "0.00000000"], ["83940.39000000", "0.00000000"], ["83942.03000000", "0.05088000"], ["83943.61000000", "0.00000000"], ["83951.05000000", "0.00000000"], ["83956.14000000", "0.00000000"], ["83958.04000000", "0.04655000"], ["83959.67000000", "0.00000000"], ["83960.14000000", "0.00000000"], ["83961.07000000", "0.11767000"], ["83969.42000000", "0.00000000"], ["83973.21000000", "0.00000000"], ["83976.43000000", "0.02385000"], ["83987.31000000", "0.14512000"], ["83988.71000000", "0.00000000"], ["84019.44000000", "0.00500000"], ["84042.95000000", "0.00000000"], ["84043.56000000", "0.00844000"], ["84082.77000000", "0.00000000"], ["84088.27000000", "0.99145000"], ["84950.79000000", "0.00040000"], ["84992.06000000", "0.00060000"], ["85098.75000000", "0.00000000"], ["85140.93000000", "0.00010000"], ["85169.06000000", "0.00100000"], ["85500.00000000", "6.00880000"]], "record_time": 1742560775.120167, "EXCHANGE": "BINANCE"}
{"e": "depthUpdate", "E": 1742560776014, "s": "BTCUSDT", "U": 64610147693, "u": 64610147959, "b": [["83910.39000000", "2.18250000"], ["83910.00000000", "0.02834000"], ["83909.19000000", "0.00000000"], ["83909.18000000", "0.00000000"], ["83909.14000000", "0.34643000"], ["83909.13000000", "0.00000000"], ["83909.12000000", "0.00000000"], ["83909.11000000", "0.00040000"], ["83908.66000000", "0.01790000"], ["83908.38000000", "0.00000000"], ["83908.00000000", "0.02827000"], ["83907.71000000", "0.00000000"], ["83907.37000000", "0.06856000"], ["83907.30000000", "0.00007000"], ["83907.29000000", "0.78695000"], ["83907.25000000", "0.05943000"], ["83906.55000000", "0.02108000"], ["83906.20000000", "0.00500000"], ["83904.01000000", "0.15013000"], ["83903.40000000", "0.00000000"], ["83901.99000000", "0.45000000"], ["83900.67000000", "0.00000000"], ["83900.00000000", "1.32830000"], ["83899.20000000", "0.00000000"], ["83896.38000000", "0.36583000"], ["83895.54000000", "0.00000000"], ["83894.38000000", "0.00000000"], ["83892.32000000", "0.00000000"], ["83888.82000000", "0.00000000"], ["83888.27000000", "0.35740000"], ["83885.21000000", "0.05956000"], ["83882.02000000", "0.70329000"], ["83875.00000000", "0.85903000"], ["83868.24000000", "0.00000000"], ["83862.07000000", "0.00000000"], ["83858.06000000", "0.35840000"], ["83856.43000000", "0.00000000"], ["83856.35000000", "0.00000000"], ["83853.44000000", "0.00000000"], ["83853.35000000", "0.00000000"], ["83851.73000000", "0.00000000"], ["83849.59000000", "0.00936000"], ["83846.60000000", "0.00007000"], ["83845.74000000", "0.01872000"], ["83845.32000000", "0.00000000"], ["83821.69000000", "0.00100000"], ["83772.61000000", "0.00000000"], ["83765.52000000", "0.00000000"], ["83742.52000000", "0.00400000"], ["83697.51000000", "0.45000000"], ["83657.26000000", "0.00160000"], ["83487.95000000", "0.00000000"], ["83487.88000000", "0.00119000"], ["83487.30000000", "0.00000000"], ["83389.73000000", "0.00000000"], ["83389.72000000", "0.00006000"], ["83373.04000000", "0.00000000"], ["82651.73000000", "0.00000000"], ["76700.01000000", "0.00000000"], ["76700.00000000", "8.07891000"], ["75519.02000000", "0.00000000"], ["75519.01000000", "0.00000000"], ["75519.00000000", "0.00020000"], ["67128.32000000", "0.00058000"], ["60000.00000000", "73.06385000"], ["33000.00000000", "2.93827000"], ["30207.75000000", "0.00000000"], ["30207.74000000", "0.00180000"], ["20002.00000000", "0.00000000"], ["20001.00000000", "0.02099000"]], "a": [["83910.40000000", "5.11406000"], ["83910.47000000", "0.15872000"], ["83910.56000000", "0.00014000"], ["83912.15000000", "0.00007000"], ["83912.16000000", "0.04502000"], ["83912.43000000", "0.00000000"], ["83913.04000000", "0.04806000"], ["83913.97000000", "0.00000000"], ["83913.98000000", "0.00009000"], ["83914.60000000", "0.00500000"], ["83915.91000000", "0.00012000"], ["83915.99000000", "0.00000000"], ["83918.23000000", "0.40331000"], ["83918.41000000", "0.00000000"], ["83920.20000000", "0.00000000"], ["83921.27000000", "0.02345000"], ["83921.51000000", "0.52000000"], ["83922.29000000", "0.68174000"], ["83924.10000000", "0.00755000"], ["83925.65000000", "0.00000000"], ["83925.97000000", "0.64824000"], ["83930.92000000", "1.15128000"], ["83930.93000000", "0.00000000"], ["83931.72000000", "0.71493000"], ["83931.73000000", "0.00000000"], ["83931.74000000", "0.00000000"], ["83935.62000000", "0.00000000"], ["83936.13000000", "0.02805000"], ["83940.61000000", "0.05000000"], ["83942.00000000", "0.00000000"], ["83942.03000000", "0.00000000"], ["83944.83000000", "0.85811000"], ["83945.11000000", "0.00000000"], ["83947.88000000", "0.40647000"], ["83948.71000000", "0.00000000"], ["83951.74000000", "0.05088000"], ["83956.16000000", "0.20182000"], ["83958.23000000", "0.35740000"], ["83971.43000000", "0.00008000"], ["83978.72000000", "0.00041000"], ["83978.73000000", "0.00000000"], ["83988.04000000", "0.00000000"], ["83999.09000000", "0.05397000"], ["84015.26000000", "0.00000000"], ["84054.55000000", "0.00035000"], ["84054.56000000", "0.00000000"], ["84950.79000000", "0.00000000"], ["84992.06000000", "0.00000000"], ["85098.75000000", "0.00040000"], ["85140.93000000", "0.00070000"], ["85169.06000000", "0.00000000"], ["94700.00000000", "1.94073000"]], "record_time": 1742560776.039092, "EXCHANGE": "BINANCE"}
{"e": "depthUpdate", "E": 1742560777014, "s": "BTCUSDT", "U": 64610147960, "u": 64610148193, "b": [["83910.39000000", "2.94366000"], ["83910.24000000", "0.00007000"], ["83910.22000000", "0.00014000"], ["83910.21000000", "0.12535000"], ["83910.19000000", "0.00007000"], ["83910.08000000", "0.00113000"], ["83910.01000000", "0.00000000"], ["83910.00000000", "0.02827000"], ["83909.71000000", "0.00000000"], ["83909.14000000", "0.34643000"], ["83909.11000000", "0.00034000"], ["83909.09000000", "0.00007000"], ["83909.08000000", "0.78701000"], ["83908.66000000", "0.01783000"], ["83908.38000000", "0.02352000"], ["83908.00000000", "0.02820000"], ["83907.37000000", "0.00000000"], ["83907.30000000", "0.00000000"], ["83907.29000000", "0.00000000"], ["83906.55000000", "0.00000000"], ["83906.40000000", "0.00000000"], ["83900.00000000", "1.32867000"], ["83889.11000000", "0.85868000"], ["83875.00000000", "0.00020000"], ["83870.54000000", "0.00000000"], ["83865.62000000", "0.45000000"], ["83862.55000000", "0.04099000"], ["83849.59000000", "0.00000000"], ["83845.74000000", "0.00000000"], ["83845.32000000", "0.00000000"], ["83841.90000000", "0.02816000"], ["83774.39000000", "0.18358000"], ["83762.00000000", "0.00400000"], ["83757.42000000", "0.00000000"], ["83751.61000000", "0.00000000"], ["83751.41000000", "0.00000000"], ["83748.50000000", "0.00000000"], ["83748.02000000", "0.00000000"], ["83747.12000000", "0.00000000"], ["83747.02000000", "0.01000000"], ["83742.59000000", "0.00000000"], ["83742.52000000", "0.00000000"], ["83736.73000000", "0.00000000"], ["83697.51000000", "0.00000000"], ["83657.27000000", "0.00160000"], ["83657.26000000", "0.00000000"], ["83489.64000000", "0.00119000"], ["83487.88000000", "0.00000000"], ["83479.38000000", "0.00000000"], ["83469.87000000", "0.00011000"], ["83453.18000000", "0.00036000"], ["83435.48000000", "0.00060000"], ["83433.37000000", "0.00000000"], ["83394.63000000", "0.00040000"], ["83393.23000000", "0.00000000"], ["83083.54000000", "0.00000000"], ["83075.18000000", "0.00000000"], ["83075.17000000", "0.40000000"], ["82651.73000000", "0.00100000"], ["75519.00000000", "0.00020000"], ["67128.32000000", "0.00058000"], ["33000.00000000", "2.93827000"], ["30207.74000000", "0.00280000"]], "a": [["83910.40000000", "2.53301000"], ["83910.47000000", "0.36160000"], ["83910.56000000", "0.00007000"], ["83912.16000000", "0.04502000"], ["83912.46000000", "0.00000000"], ["83912.47000000", "0.78691000"], ["83913.05000000", "0.11012000"], ["83918.80000000", "0.00000000"], ["83921.91000000", "0.00756000"], ["83923.37000000", "0.04000000"], ["83924.10000000", "0.00000000"], ["83924.21000000", "0.04000000"], ["83925.00000000", "0.00031000"], ["83925.03000000", "0.04800000"], ["83925.04000000", "0.04000000"], ["83925.21000000", "0.04400000"], ["83927.14000000", "0.02805000"], ["83927.58000000", "0.04800000"], ["83928.12000000", "0.00000000"], ["83928.42000000", "0.04800000"], ["83928.96000000", "0.00000000"], ["83929.23000000", "0.04400000"], ["83929.25000000", "0.04400000"], ["83929.42000000", "0.04400000"], ["83929.79000000", "0.00000000"], ["83929.80000000", "0.00000000"], ["83929.96000000", "0.00000000"], ["83930.92000000", "0.00000000"], ["83931.72000000", "0.00000000"], ["83932.32000000", "0.00000000"], ["83933.16000000", "0.00000000"], ["83933.17000000", "0.00000000"], ["83933.99000000", "0.00000000"], ["83934.01000000", "0.00000000"], ["83934.16000000", "0.00000000"], ["83936.13000000", "0.00000000"], ["83936.14000000", "0.59617000"], ["83944.35000000", "0.00084000"], ["83951.74000000", "0.00000000"], ["83961.48000000", "0.05088000"], ["83967.60000000", "0.04000000"], ["83970.98000000", "0.00000000"], ["83972.81000000", "0.04000000"], ["83976.93000000", "0.00000000"], ["83978.71000000", "0.00042000"], ["83978.72000000", "0.00000000"], ["83998.93000000", "0.00084000"], ["84006.14000000", "0.00793000"], ["84035.73000000", "0.01017000"], ["84054.55000000", "0.00000000"], ["84082.69000000", "0.01000000"], ["84749.49000000", "0.00000000"], ["85124.68000000", "0.00040000"], ["85169.06000000", "0.00100000"]], "record_time": 1742560777.04008, "EXCHANGE": "BINANCE"}
{"e": "depthUpdate", "E": 1742560778014, "s": "BTCUSDT", "U": 64610148194, "u": 64610148324, "b": [["83910.39000000", "3.00309000"], ["83910.21000000", "0.12535000"], ["83910.19000000", "0.00007000"], ["83910.08000000", "0.00000000"], ["83909.98000000", "0.00000000"], ["83909.95000000", "0.00127000"], ["83909.11000000", "0.00034000"], ["83909.09000000", "0.00007000"], ["83909.08000000", "0.78701000"], ["83908.39000000", "0.00012000"], ["83907.60000000", "0.00000000"], ["83907.50000000", "0.00000000"], ["83907.25000000", "0.00000000"], ["83906.20000000", "0.00000000"], ["83900.00000000", "1.32855000"], ["83897.50000000", "0.00000000"], ["83897.40000000", "0.00400000"], ["83894.38000000", "0.00912000"], ["83889.11000000", "0.00000000"], ["83888.60000000", "0.85869000"], ["83875.08000000", "0.00000000"], ["83862.73000000", "0.00000000"], ["83801.01000000", "0.10170000"], ["83657.27000000", "0.00160000"], ["83489.64000000", "0.00000000"], ["83435.48000000", "0.00000000"], ["83435.00000000", "0.00208000"], ["83434.99000000", "0.00060000"], ["83394.63000000", "0.00000000"], ["83394.10000000", "0.00040000"], ["82651.73000000", "0.00000000"], ["76700.00000000", "8.07712000"], ["75519.01000000", "0.00000000"], ["75519.00000000", "0.00020000"], ["75503.90000000", "0.00018000"], ["67128.32000000", "0.00058000"], ["33000.00000000", "2.93827000"], ["30207.74000000", "0.00360000"]], "a": [["83910.40000000", "1.82549000"], ["83912.78000000", "0.04797000"], ["83913.04000000", "0.00009000"], ["83914.60000000", "0.00000000"], ["83915.91000000", "0.00000000"], ["83918.23000000", "0.28601000"], ["83918.46000000", "0.00000000"], ["83918.80000000", "0.00000000"], ["83919.32000000", "0.00000000"], ["83919.90000000", "0.00413000"], ["83920.60000000", "0.00012000"], ["83922.32000000", "0.10759000"], ["83922.41000000", "0.05943000"], ["83923.82000000", "0.00000000"], ["83925.92000000", "0.01731000"], ["83929.61000000", "0.01866000"], ["83929.67000000", "0.35740000"], ["83930.00000000", "0.00400000"], ["83931.75000000", "0.43207000"], ["83942.00000000", "0.00500000"], ["83958.04000000", "0.00000000"], ["83967.57000000", "0.04655000"], ["83979.82000000", "0.00528000"], ["83998.95000000", "0.62771000"], ["84000.28000000", "0.00000000"], ["84041.30000000", "0.00000000"], ["84043.56000000", "0.00000000"], ["84043.96000000", "0.00844000"], ["84051.40000000", "0.00000000"], ["84054.57000000", "0.00035000"], ["84057.33000000", "0.00808000"], ["84937.54000000", "0.00040000"], ["84979.64000000", "0.00060000"], ["85098.75000000", "0.00000000"], ["85116.26000000", "0.60000000"], ["85140.93000000", "0.00010000"], ["85169.06000000", "0.00000000"]], "record_time": 1742560778.040162, "EXCHANGE": "BINANCE"}
{"e": "depthUpdate", "E": 1742560779014, "s": "BTCUSDT", "U": 64610148325, "u": 64610148503, "b": [["83910.39000000", "2.90063000"], ["83910.22000000", "0.00007000"], ["83910.21000000", "0.00007000"], ["83910.19000000", "0.00007000"], ["83910.01000000", "0.00007000"], ["83910.00000000", "0.02827000"], ["83909.95000000", "0.00000000"], ["83909.14000000", "0.11972000"], ["83909.11000000", "0.00022000"], ["83909.09000000", "0.00000000"], ["83909.08000000", "0.00000000"], ["83908.69000000", "0.00007000"], ["83908.68000000", "0.05565000"], ["83908.66000000", "0.01790000"], ["83907.33000000", "0.01995000"], ["83907.00000000", "0.00000000"], ["83906.99000000", "0.00000000"], ["83906.98000000", "0.00000000"], ["83900.00000000", "1.32867000"], ["83888.60000000", "0.00000000"], ["83888.20000000", "1.26281000"], ["83874.26000000", "0.85883000"], ["83868.49000000", "0.00000000"], ["83862.73000000", "0.00000000"], ["83841.90000000", "0.00008000"], ["83837.71000000", "0.00000000"], ["83836.85000000", "0.02808000"], ["83801.37000000", "0.05396000"], ["83801.01000000", "0.08304000"], ["83762.00000000", "0.00000000"], ["83752.55000000", "0.00000000"], ["83743.03000000", "0.00400000"], ["83730.42000000", "0.00000000"], ["83434.99000000", "0.00000000"], ["83430.01000000", "0.00060000"], ["83394.10000000", "0.00000000"], ["83389.87000000", "0.00040000"], ["82651.73000000", "0.00100000"], ["75519.00000000", "0.00020000"], ["67128.32000000", "0.00058000"], ["33000.00000000", "2.93827000"], ["30207.74000000", "0.00380000"]], "a": [["83910.40000000", "4.70276000"], ["83910.41000000", "0.00060000"], ["83910.43000000", "0.00014000"], ["83910.44000000", "0.29998000"], ["83910.47000000", "0.15865000"], ["83910.50000000", "0.00007000"], ["83910.51000000", "0.00000000"], ["83910.56000000", "0.00000000"], ["83912.16000000", "0.04495000"], ["83912.47000000", "0.00000000"], ["83912.54000000", "0.04797000"], ["83912.78000000", "0.00000000"], ["83915.16000000", "0.02805000"], ["83918.80000000", "0.45000000"], ["83925.78000000", "0.00789000"], ["83927.14000000", "0.00000000"], ["83929.61000000", "0.00000000"], ["83930.62000000", "0.85826000"], ["83943.73000000", "1.35355000"], ["83944.32000000", "0.05088000"], ["83944.83000000", "0.00000000"], ["83947.12000000", "0.26297000"], ["83950.48000000", "0.00822000"], ["83954.13000000", "0.01866000"], ["83956.18000000", "0.00471000"], ["83961.48000000", "0.00000000"], ["83978.71000000", "0.00000000"], ["84002.06000000", "0.00471000"], ["84022.60000000", "0.00822000"], ["84042.84000000", "0.00822000"], ["84048.26000000", "0.00715000"], ["84054.57000000", "0.00000000"], ["84081.74000000", "0.00471000"], ["84086.65000000", "0.00822000"], ["84937.54000000", "0.00000000"], ["84979.64000000", "0.00000000"], ["85098.75000000", "0.00040000"], ["85140.93000000", "0.00070000"], ["85169.06000000", "0.00100000"]], "record_time": 1742560779.044433, "EXCHANGE": "BINANCE"}
{"e": "depthUpdate", "E": 1742560780014, "s": "BTCUSDT", "U": 64610148504, "u": 64610148764, "b": [["83910.39000000", "1.35706000"], ["83910.19000000", "0.00007000"], ["83910.14000000", "0.00201000"], ["83909.14000000", "0.34081000"], ["83908.86000000", "0.00000000"], ["83908.85000000", "0.00000000"], ["83908.69000000", "0.00000000"], ["83908.68000000", "0.00000000"], ["83908.66000000", "0.01790000"], ["83908.38000000", "0.00000000"], ["83908.00000000", "0.02827000"], ["83907.33000000", "0.00000000"], ["83907.25000000", "0.00007000"], ["83907.24000000", "0.78696000"], ["83907.04000000", "0.00000000"], ["83905.69000000", "0.04801000"], ["83905.36000000", "0.00000000"], ["83904.69000000", "0.02215000"], ["83904.01000000", "0.01730000"], ["83901.99000000", "0.00000000"], ["83900.80000000", "0.71493000"], ["83899.20000000", "0.00006000"], ["83897.40000000", "0.00000000"], ["83888.52000000", "0.00000000"], ["83875.06000000", "0.85883000"], ["83874.26000000", "0.00000000"], ["83866.62000000", "0.05000000"], ["83857.19000000", "0.00000000"], ["83836.85000000", "0.00000000"], ["83833.52000000", "0.06391000"], ["83824.11000000", "0.02808000"], ["83810.84000000", "0.00013000"], ["83787.58000000", "0.00051000"], ["83786.13000000", "0.00000000"], ["83749.58000000", "0.00000000"], ["83743.03000000", "0.00000000"], ["83736.91000000", "0.00000000"], ["83720.98000000", "0.00400000"], ["83712.01000000", "0.00042000"], ["83708.01000000", "0.00000000"], ["83697.51000000", "0.45000000"], ["83657.27000000", "0.00000000"], ["83435.01000000", "0.00279000"], ["83435.00000000", "0.00089000"], ["82651.73000000", "0.00000000"], ["82500.00000000", "19.87083000"], ["79700.00000000", "1.69300000"], ["76700.00000000", "8.07086000"], ["75519.00000000", "0.00020000"], ["67128.33000000", "0.00000000"], ["67128.32000000", "0.00058000"], ["30207.74000000", "0.00420000"]], "a": [["83910.40000000", "6.60392000"], ["83910.41000000", "0.00060000"], ["83910.42000000", "0.00014000"], ["83910.43000000", "0.24071000"], ["83910.44000000", "0.29998000"], ["83910.46000000", "0.00015000"], ["83910.47000000", "0.00013000"], ["83910.48000000", "0.25286000"], ["83910.50000000", "0.00000000"], ["83910.74000000", "0.00202000"], ["83912.98000000", "0.01781000"], ["83914.49000000", "0.02475000"], ["83914.60000000", "0.00500000"], ["83915.16000000", "0.00000000"], ["83917.48000000", "0.00000000"], ["83918.03000000", "0.00012000"], ["83918.23000000", "0.40185000"], ["83918.84000000", "0.05943000"], ["83919.90000000", "0.00013000"], ["83920.20000000", "0.00006000"], ["83920.60000000", "0.00000000"], ["83921.58000000", "0.02249000"], ["83922.41000000", "0.00000000"], ["83930.00000000", "0.00000000"], ["83930.62000000", "0.00494000"], ["83931.18000000", "0.71493000"], ["83931.19000000", "0.69641000"], ["83931.20000000", "0.85825000"], ["83931.25000000", "0.02288000"], ["83931.75000000", "0.00000000"], ["83933.75000000", "0.02351000"], ["83938.63000000", "0.01563000"], ["83942.00000000", "0.00500000"], ["83944.32000000", "0.00000000"], ["83944.62000000", "0.00000000"], ["83953.92000000", "0.05088000"], ["83954.13000000", "0.00000000"], ["83956.04000000", "0.02288000"], ["83966.76000000", "0.00640000"], ["83976.61000000", "0.01143000"], ["83978.70000000", "0.00042000"], ["83981.66000000", "0.02216000"], ["83985.09000000", "0.00594000"], ["83994.28000000", "0.02216000"], ["83997.96000000", "0.02288000"], ["84014.27000000", "0.00452000"], ["84019.49000000", "0.01387000"], ["84022.80000000", "0.02351000"], ["84038.91000000", "0.00452000"], ["84042.82000000", "0.02502000"], ["84054.57000000", "0.00035000"], ["84055.91000000", "0.00000000"], ["84067.49000000", "0.00000000"], ["84068.36000000", "0.02168000"], ["84073.76000000", "0.00494000"], ["84081.99000000", "0.00119000"], ["85127.50000000", "0.11763000"], ["85148.75000000", "0.00000000"], ["85169.06000000", "0.00000000"]], "record_time": 1742560780.039248, "EXCHANGE": "BINANCE"}
{"e": "depthUpdate", "E": 1742560781014, "s": "BTCUSDT", "U": 64610148765, "u": 64610148950, "b": [["83910.39000000", "0.56986000"], ["83910.00000000", "0.02827000"], ["83909.97000000", "0.00007000"], ["83909.96000000", "0.28063000"], ["83909.42000000", "0.00000000"], ["83909.41000000", "0.01198000"], ["83908.66000000", "0.01783000"], ["83908.38000000", "0.00000000"], ["83908.00000000", "0.02820000"], ["83907.83000000", "0.00000000"], ["83907.82000000", "0.00000000"], ["83907.32000000", "0.00007000"], ["83907.31000000", "0.05943000"], ["83907.25000000", "0.00000000"], ["83907.11000000", "0.00000000"], ["83901.99000000", "0.00000000"], ["83900.00000000", "1.37822000"], ["83889.33000000", "0.00000000"], ["83883.31000000", "1.25949000"], ["83883.30000000", "1.34266000"], ["83882.02000000", "0.00000000"], ["83877.84000000", "0.04400000"], ["83876.96000000", "0.04000000"], ["83876.84000000", "0.04009000"], ["83873.66000000", "0.04000000"], ["83872.81000000", "0.04000000"], ["83872.79000000", "0.04008000"], ["83868.96000000", "0.00000000"], ["83868.19000000", "0.00000000"], ["83866.62000000", "0.00000000"], ["83864.61000000", "0.37766000"], ["83863.79000000", "0.05887000"], ["83854.59000000", "0.00346000"], ["83849.40000000", "0.00000000"], ["83831.38000000", "0.00000000"], ["83828.01000000", "0.00000000"], ["83825.88000000", "0.00000000"], ["83820.33000000", "0.00000000"], ["83810.84000000", "0.63111000"], ["83781.03000000", "0.10514000"], ["83712.02000000", "0.00000000"], ["83712.01000000", "0.00000000"], ["83695.34000000", "0.00042000"], ["83657.29000000", "0.00000000"], ["83657.28000000", "0.00000000"], ["83487.84000000", "0.00000000"], ["83487.82000000", "0.00000000"], ["83487.33000000", "0.00000000"], ["83435.01000000", "0.00000000"], ["82651.74000000", "0.00261000"], ["82651.73000000", "0.00100000"], ["79700.00000000", "1.69288000"], ["75519.03000000", "0.00000000"], ["75519.02000000", "0.00000000"], ["75519.01000000", "0.00000000"], ["75519.00000000", "0.00020000"], ["75503.90000000", "0.00018000"], ["67128.32000000", "0.00058000"], ["33000.00000000", "2.93827000"], ["30207.74000000", "0.00540000"], ["20002.00000000", "0.00000000"], ["20001.00000000", "0.02099000"]], "a": [["83910.40000000", "6.67197000"], ["83912.14000000", "0.04797000"], ["83912.38000000", "0.00000000"], ["83912.54000000", "0.00000000"], ["83912.75000000", "0.02404000"], ["83915.42000000", "0.00058000"], ["83915.74000000", "0.00012000"], ["83916.00000000", "0.02826000"], ["83918.03000000", "0.00000000"], ["83921.12000000", "0.00754000"], ["83923.29000000", "0.00058000"], ["83926.36000000", "0.84268000"], ["83927.01000000", "1.33225000"], ["83932.60000000", "0.00000000"], ["83936.80000000", "0.00000000"], ["83937.61000000", "0.05006000"], ["83938.23000000", "0.00998000"], ["83940.61000000", "0.00000000"], ["83947.31000000", "0.00705000"], ["83954.15000000", "0.04655000"], ["83963.56000000", "0.00690000"], ["83964.81000000", "0.00916000"], ["83967.57000000", "0.00000000"], ["83968.78000000", "0.00725000"], ["83969.01000000", "0.02503000"], ["83973.26000000", "0.00705000"], ["83976.20000000", "0.00998000"], ["83990.22000000", "0.00916000"], ["83993.43000000", "0.00754000"], ["83996.61000000", "0.00690000"], ["84010.35000000", "0.00998000"], ["84010.87000000", "0.18996000"], ["84012.12000000", "0.00060000"], ["84016.48000000", "0.00000000"], ["84019.06000000", "0.00697000"], ["84030.44000000", "0.02279000"], ["84030.83000000", "0.00615000"], ["84044.44000000", "0.00916000"], ["84047.87000000", "0.01679000"], ["84056.12000000", "0.02503000"], ["84057.29000000", "0.00000000"], ["84059.93000000", "0.01679000"], ["84069.88000000", "0.00725000"], ["84076.41000000", "0.00672000"], ["85169.06000000", "0.00100000"]], "record_time": 1742560781.038776, "EXCHANGE": "BINANCE"}
{"e": "depthUpdate", "E": 1742560782014, "s": "BTCUSDT", "U": 64610148951, "u": 64610151546, "b": [["83910.39000000", "0.00000000"], ["83910.38000000", "0.00000000"], ["83910.37000000", "0.00000000"], ["83910.26000000", "0.00000000"], ["83910.24000000", "0.00000000"], ["83910.22000000", "0.00000000"], ["83910.21000000", "0.00000000"], ["83910.19000000", "0.00000000"], ["83910.14000000", "0.00000000"], ["83910.01000000", "0.00000000"], ["83910.00000000", "0.00000000"], ["83909.97000000", "0.00000000"], ["83909.96000000", "0.00000000"], ["83909.69000000", "0.00000000"], ["83909.42000000", "0.00000000"], ["83909.41000000", "0.00000000"], ["83909.37000000", "0.00000000"], ["83909.15000000", "0.00000000"], ["83909.14000000", "0.00000000"], ["83909.12000000", "0.00000000"], ["83909.11000000", "0.00000000"], ["83909.09000000", "0.00000000"], ["83909.05000000", "0.00000000"], ["83908.67000000", "0.00000000"], ["83908.66000000", "0.00000000"], ["83908.58000000", "0.00000000"], ["83908.39000000", "0.00000000"], ["83908.38000000", "0.00000000"], ["83908.32000000", "0.00000000"], ["83908.01000000", "0.00000000"], ["83908.00000000", "0.00000000"], ["83907.69000000", "0.00000000"], ["83907.68000000", "0.00000000"], ["83907.63000000", "0.00000000"], ["83907.33000000", "0.00000000"], ["83907.32000000", "0.00000000"], ["83907.31000000", "0.00000000"], ["83907.25000000", "0.00000000"], ["83907.24000000", "0.00000000"], ["83906.92000000", "0.00000000"], ["83906.89000000", "0.00000000"], ["83906.81000000", "0.00000000"], ["83906.80000000", "0.00000000"], ["83906.65000000", "0.00000000"], ["83906.64000000", "0.00000000"], ["83906.01000000", "0.00000000"], ["83906.00000000", "0.00000000"], ["83905.87000000", "0.00000000"], ["83905.86000000", "0.00000000"], ["83905.85000000", "0.00000000"], ["83905.78000000", "0.00000000"], ["83905.69000000", "0.00000000"], ["83905.48000000", "0.00000000"], ["83905.20000000", "0.00000000"], ["83904.96000000", "0.00000000"], ["83904.95000000", "0.00000000"], ["83904.72000000", "0.00000000"], ["83904.71000000", "0.00000000"], ["83904.70000000", "0.00000000"], ["83904.69000000", "0.00000000"], ["83904.66000000", "0.00000000"], ["83904.65000000", "0.00000000"], ["83904.62000000", "0.00000000"], ["83904.61000000", "0.00000000"], ["83904.36000000", "0.00000000"], ["83904.28000000", "0.00000000"], ["83904.01000000", "0.00000000"], ["83904.00000000", "0.00000000"], ["83903.98000000", "0.00000000"], ["83903.97000000", "0.00000000"], ["83903.16000000", "0.00000000"], ["83902.71000000", "0.00000000"], ["83902.70000000", "0.00000000"], ["83902.69000000", "0.00000000"], ["83902.45000000", "0.00000000"], ["83902.38000000", "0.00000000"], ["83902.01000000", "0.00000000"], ["83902.00000000", "0.00000000"], ["83901.99000000", "0.00000000"], ["83901.91000000", "0.00000000"], ["83901.90000000", "0.00000000"], ["83901.48000000", "0.00000000"], ["83901.34000000", "0.00000000"], ["83901.04000000", "0.00000000"], ["83900.94000000", "0.00000000"], ["83900.93000000", "0.00000000"], ["83900.83000000", "0.00000000"], ["83900.82000000", "0.58724000"], ["83900.81000000", "0.00046000"], ["83900.80000000", "0.00007000"], ["83900.79000000", "0.00000000"], ["83900.75000000", "0.00000000"], ["83900.71000000", "0.00307000"], ["83900.70000000", "0.00000000"], ["83900.69000000", "0.00000000"], ["83900.28000000", "0.00000000"], ["83900.24000000", "0.00007000"], ["83900.23000000", "0.00007000"], ["83900.20000000", "0.00000000"], ["83900.12000000", "0.00007000"], ["83900.11000000", "0.00007000"], ["83900.10000000", "0.00010000"], ["83900.02000000", "0.00110000"], ["83900.01000000", "0.48014000"], ["83900.00000000", "1.55673000"], ["83899.77000000", "0.00000000"], ["83899.75000000", "0.00051000"], ["83899.65000000", "0.00000000"], ["83899.57000000", "0.00000000"], ["83899.37000000", "0.00000000"], ["83899.36000000", "0.00000000"], ["83899.22000000", "0.00000000"], ["83899.20000000", "0.00000000"], ["83899.04000000", "0.00000000"], ["83898.65000000", "0.00028000"], ["83898.64000000", "0.00000000"], ["83898.45000000", "0.00007000"], ["83898.28000000", "0.02439000"], ["83898.11000000", "0.78711000"], ["83897.86000000", "0.00000000"], ["83897.76000000", "0.00000000"], ["83897.50000000", "0.00000000"], ["83897.35000000", "0.00024000"], ["83897.34000000", "0.00000000"], ["83897.31000000", "0.00035000"], ["83897.30000000", "0.01191000"], ["83897.14000000", "0.00000000"], ["83896.95000000", "0.04836000"], ["83896.87000000", "0.00012000"], ["83896.85000000", "0.00000000"], ["83896.76000000", "0.00007000"], ["83896.39000000", "0.00009000"], ["83896.38000000", "0.01585000"], ["83896.02000000", "0.00000000"], ["83895.79000000", "0.05943000"], ["83895.76000000", "0.00000000"], ["83895.58000000", "0.00008000"], ["83895.18000000", "0.00000000"], ["83895.17000000", "0.00000000"], ["83895.16000000", "0.02216000"], ["83895.07000000", "0.00760000"], ["83895.03000000", "0.00000000"], ["83895.00000000", "0.00000000"], ["83894.91000000", "0.00000000"], ["83894.66000000", "0.00000000"], ["83894.64000000", "0.00000000"], ["83894.38000000", "0.00000000"], ["83894.29000000", "0.00000000"], ["83894.07000000", "0.00000000"], ["83893.92000000", "0.00000000"], ["83893.88000000", "0.00000000"], ["83893.80000000", "0.00091000"], ["83893.63000000", "0.00000000"], ["83893.55000000", "0.00000000"], ["83893.03000000", "0.00000000"], ["83892.98000000", "0.00000000"], ["83892.78000000", "0.00000000"], ["83892.71000000", "0.00000000"], ["83892.63000000", "0.00000000"], ["83892.61000000", "0.00000000"], ["83892.53000000", "0.00000000"], ["83892.46000000", "0.00029000"], ["83892.45000000", "0.23022000"], ["83892.44000000", "0.00000000"], ["83892.42000000", "0.45000000"], ["83892.31000000", "0.00006000"], ["83892.17000000", "0.00000000"], ["83892.04000000", "0.04000000"], ["83891.61000000", "0.00012000"], ["83891.60000000", "0.00000000"], ["83891.28000000", "0.00000000"], ["83890.99000000", "0.00000000"], ["83890.60000000", "0.00000000"], ["83890.18000000", "0.00000000"], ["83890.10000000", "0.00000000"], ["83889.88000000", "0.00000000"], ["83889.68000000", "0.00000000"], ["83889.63000000", "0.00000000"], ["83889.60000000", "0.00000000"], ["83889.43000000", "0.00000000"], ["83888.88000000", "0.00008000"], ["83888.57000000", "0.00418000"], ["83888.45000000", "0.00097000"], ["83888.27000000", "0.00000000"], ["83888.20000000", "0.00000000"], ["83888.02000000", "0.04400000"], ["83887.78000000", "0.00000000"], ["83887.28000000", "0.00000000"], ["83886.82000000", "0.00090000"], ["83886.68000000", "0.00000000"], ["83886.64000000", "0.00007000"], ["83886.61000000", "0.00000000"], ["83886.50000000", "0.00000000"], ["83886.32000000", "0.00000000"], ["83886.22000000", "0.00000000"], ["83886.09000000", "1.02583000"], ["83886.08000000", "0.89352000"], ["83885.75000000", "0.00000000"], ["83885.54000000", "0.00000000"], ["83885.40000000", "0.00896000"], ["83885.27000000", "0.00000000"], ["83885.21000000", "0.00000000"], ["83884.86000000", "0.00000000"], ["83884.78000000", "0.00000000"], ["83884.56000000", "0.00000000"], ["83884.49000000", "0.00000000"], ["83884.48000000", "0.73129000"], ["83884.23000000", "0.01500000"], ["83884.17000000", "0.00875000"], ["83883.93000000", "0.00000000"], ["83883.79000000", "0.04000000"], ["83883.31000000", "0.61351000"], ["83883.30000000", "0.00000000"], ["83883.20000000", "0.45200000"], ["83883.01000000", "0.04000000"], ["83882.99000000", "0.04000000"], ["83882.96000000", "0.01000000"], ["83882.79000000", "0.04000000"], ["83881.88000000", "0.14000000"], ["83881.61000000", "0.00000000"], ["83881.33000000", "0.00000000"], ["83881.31000000", "0.00000000"], ["83881.17000000", "0.00119000"], ["83881.03000000", "0.00000000"], ["83880.82000000", "0.11606000"], ["83880.68000000", "0.00000000"], ["83880.33000000", "0.00000000"], ["83880.31000000", "0.00007000"], ["83879.25000000", "1.44619000"], ["83878.86000000", "0.89352000"], ["83878.78000000", "0.89352000"], ["83878.53000000", "0.89352000"], ["83878.44000000", "0.35740000"], ["83878.41000000", "0.00000000"], ["83878.23000000", "0.00000000"], ["83878.16000000", "0.29945000"], ["83877.84000000", "0.00000000"], ["83876.32000000", "0.01191000"], ["83875.64000000", "0.05956000"], ["83875.33000000", "0.16000000"], ["83874.10000000", "0.00010000"], ["83873.82000000", "0.00000000"], ["83873.66000000", "0.00000000"], ["83872.81000000", "0.00000000"], ["83872.61000000", "0.00000000"], ["83871.96000000", "0.00578000"], ["83871.73000000", "0.00000000"], ["83871.72000000", "0.85886000"], ["83871.49000000", "0.00016000"], ["83871.20000000", "0.00000000"], ["83870.13000000", "0.00013000"], ["83869.92000000", "0.89352000"], ["83867.15000000", "0.00006000"], ["83867.02000000", "0.00000000"], ["83866.89000000", "0.00000000"], ["83866.44000000", "0.00000000"], ["83866.35000000", "0.00360000"], ["83866.24000000", "0.00015000"], ["83865.64000000", "0.00213000"], ["83865.28000000", "0.00000000"], ["83864.96000000", "0.00000000"], ["83863.86000000", "0.34747000"], ["83863.79000000", "0.00000000"], ["83862.54000000", "0.00000000"], ["83862.01000000", "0.00000000"], ["83860.96000000", "0.37711000"], ["83860.78000000", "0.00000000"], ["83859.30000000", "0.00000000"], ["83858.06000000", "0.00100000"], ["83857.97000000", "0.47663000"], ["83857.36000000", "0.59630000"], ["83857.35000000", "0.00000000"], ["83855.30000000", "0.05803000"], ["83854.84000000", "0.02518000"], ["83852.92000000", "0.03895000"], ["83851.07000000", "0.05000000"], ["83850.73000000", "0.03434000"], ["83850.27000000", "0.05962000"], ["83848.23000000", "0.35749000"], ["83846.75000000", "0.00000000"], ["83845.81000000", "0.00819000"], ["83845.63000000", "0.00000000"], ["83842.28000000", "0.00061000"], ["83841.67000000", "0.42808000"], ["83841.66000000", "0.59568000"], ["83840.65000000", "0.00000000"], ["83836.97000000", "0.05663000"], ["83836.06000000", "0.00000000"], ["83833.52000000", "0.02814000"], ["83831.26000000", "0.00000000"], ["83831.25000000", "0.04400000"], ["83830.55000000", "0.00000000"], ["83830.47000000", "0.04000000"], ["83830.11000000", "0.00000000"], ["83829.88000000", "0.00000000"], ["83828.01000000", "0.04000000"], ["83825.88000000", "0.04000000"], ["83824.00000000", "0.00235000"], ["83823.99000000", "0.00000000"], ["83822.99000000", "0.00297000"], ["83820.33000000", "0.00000000"], ["83820.21000000", "0.25837000"], ["83819.38000000", "0.00000000"], ["83815.25000000", "0.04000000"], ["83813.10000000", "0.05243000"], ["83812.64000000", "0.00000000"], ["83812.58000000", "1.00407000"], ["83811.24000000", "0.00213000"], ["83810.84000000", "0.00013000"], ["83809.86000000", "0.09496000"], ["83807.64000000", "0.00000000"], ["83805.24000000", "0.00000000"], ["83799.45000000", "0.00229000"], ["83787.58000000", "0.00000000"], ["83787.56000000", "0.00000000"], ["83764.58000000", "0.00157000"], ["83749.19000000", "0.99313000"], ["83747.02000000", "0.00000000"], ["83744.02000000", "0.00000000"], ["83737.28000000", "0.00119000"], ["83720.98000000", "0.00000000"], ["83720.01000000", "0.00000000"], ["83711.07000000", "0.00000000"], ["83709.58000000", "0.00091000"], ["83709.57000000", "0.00000000"], ["83701.15000000", "0.00000000"], ["83701.11000000", "0.00040000"], ["83695.36000000", "0.00000000"], ["83695.35000000", "0.00000000"], ["83695.34000000", "0.00000000"], ["83689.11000000", "0.45000000"], ["83686.55000000", "0.00584000"], ["83679.74000000", "0.14426000"], ["83665.90000000", "0.02978000"], ["83664.13000000", "0.00000000"], ["83662.96000000", "0.00215000"], ["83659.89000000", "0.00013000"], ["83655.70000000", "0.00013000"], ["83479.77000000", "0.00000000"], ["83479.65000000", "0.00040000"], ["83432.31000000", "0.00060000"], ["83430.01000000", "0.00000000"], ["83391.40000000", "0.00040000"], ["83389.87000000", "0.00000000"], ["83071.28000000", "0.00000000"], ["82651.77000000", "0.00261000"], ["82651.76000000", "0.00000000"], ["82651.75000000", "0.00000000"], ["82651.74000000", "0.00000000"], ["82651.73000000", "0.00000000"], ["80522.38000000", "0.00000000"], ["80505.60000000", "0.03584000"], ["75519.01000000", "0.00000000"], ["75519.00000000", "0.00020000"], ["75503.90000000", "0.00018000"], ["67128.33000000", "0.00000000"], ["67128.32000000", "0.00000000"], ["67120.66000000", "0.00058000"], ["33000.00000000", "2.93827000"], ["30207.74000000", "0.00560000"]], "a": [["83900.83000000", "6.37049000"], ["83900.84000000", "0.00020000"], ["83901.49000000", "0.00000000"], ["83902.01000000", "0.00000000"], ["83902.39000000", "0.00000000"], ["83902.46000000", "0.00000000"], ["83902.70000000", "0.00000000"], ["83903.17000000", "0.00000000"], ["83903.47000000", "0.00019000"], ["83903.84000000", "0.00014000"], ["83903.85000000", "0.05963000"], ["83903.98000000", "0.00000000"], ["83903.99000000", "0.00014000"], ["83904.00000000", "0.02840000"], ["83904.01000000", "0.00000000"], ["83904.29000000", "0.00000000"], ["83904.37000000", "0.00000000"], ["83904.66000000", "0.00000000"], ["83904.67000000", "0.00000000"], ["83904.87000000", "0.00000000"], ["83904.97000000", "0.00000000"], ["83905.15000000", "0.00014000"], ["83905.16000000", "0.04007000"], ["83905.21000000", "0.00000000"], ["83905.72000000", "0.00000000"], ["83905.75000000", "0.00000000"], ["83905.76000000", "0.00007000"], ["83905.77000000", "0.41013000"], ["83905.84000000", "0.00058000"], ["83905.85000000", "0.00007000"], ["83905.86000000", "2.76190000"], ["83905.87000000", "1.83043000"], ["83905.88000000", "0.00026000"], ["83905.99000000", "0.00000000"], ["83906.00000000", "0.02820000"], ["83906.01000000", "0.00000000"], ["83906.02000000", "0.00000000"], ["83906.11000000", "0.04195000"], ["83906.38000000", "0.00000000"], ["83906.70000000", "0.00000000"], ["83906.71000000", "0.00000000"], ["83906.80000000", "0.00000000"], ["83906.81000000", "0.00000000"], ["83906.82000000", "0.00000000"], ["83906.88000000", "0.00000000"], ["83906.90000000", "0.00000000"], ["83907.33000000", "0.00000000"], ["83907.59000000", "0.00000000"], ["83907.64000000", "0.00000000"], ["83907.67000000", "0.00058000"], ["83908.00000000", "0.02820000"], ["83908.19000000", "0.00000000"], ["83908.39000000", "0.00000000"], ["83908.47000000", "0.00000000"], ["83908.58000000", "0.00000000"], ["83908.59000000", "0.97700000"], ["83909.06000000", "0.00000000"], ["83909.10000000", "0.16000000"], ["83909.26000000", "0.00029000"], ["83909.29000000", "0.00000000"], ["83909.41000000", "0.00000000"], ["83909.42000000", "0.04000000"], ["83909.43000000", "0.00000000"], ["83909.69000000", "0.00000000"], ["83909.86000000", "0.00000000"], ["83910.00000000", "0.02820000"], ["83910.09000000", "0.04000000"], ["83910.10000000", "0.00000000"], ["83910.14000000", "0.00000000"], ["83910.15000000", "0.00000000"], ["83910.20000000", "0.00000000"], ["83910.22000000", "0.00000000"], ["83910.23000000", "0.00000000"], ["83910.25000000", "0.00000000"], ["83910.27000000", "0.00000000"], ["83910.38000000", "1.09566000"], ["83910.39000000", "0.62822000"], ["83910.40000000", "1.02140000"], ["83910.41000000", "0.00000000"], ["83910.42000000", "0.00000000"], ["83910.43000000", "0.00000000"], ["83910.44000000", "0.29984000"], ["83910.46000000", "0.00000000"], ["83910.47000000", "0.00000000"], ["83910.48000000", "0.00000000"], ["83910.57000000", "0.00000000"], ["83910.76000000", "0.00119000"], ["83910.86000000", "0.00000000"], ["83911.04000000", "0.00000000"], ["83911.31000000", "0.00013000"], ["83911.36000000", "0.00758000"], ["83911.62000000", "0.00000000"], ["83911.80000000", "0.00006000"], ["83911.82000000", "0.00000000"], ["83911.96000000", "0.00000000"], ["83912.00000000", "0.02820000"], ["83912.14000000", "0.00000000"], ["83912.16000000", "0.00000000"], ["83912.33000000", "0.00059000"], ["83912.35000000", "0.00013000"], ["83912.39000000", "0.00826000"], ["83912.44000000", "0.00006000"], ["83912.75000000", "0.02361000"], ["83912.79000000", "0.00000000"], ["83912.98000000", "0.01781000"], ["83912.99000000", "0.02488000"], ["83913.00000000", "0.00000000"], ["83913.04000000", "0.00000000"], ["83913.05000000", "0.11012000"], ["83913.72000000", "0.00058000"], ["83913.98000000", "0.24507000"], ["83913.99000000", "0.00000000"], ["83914.01000000", "0.35740000"], ["83914.29000000", "0.00000000"], ["83914.49000000", "0.00000000"], ["83914.60000000", "0.00000000"], ["83914.81000000", "0.00000000"], ["83915.34000000", "0.00000000"], ["83915.42000000", "0.00000000"], ["83915.56000000", "0.00119000"], ["83915.65000000", "0.00000000"], ["83915.74000000", "0.00000000"], ["83916.35000000", "0.00013000"], ["83916.40000000", "0.00000000"], ["83916.72000000", "0.00000000"], ["83916.78000000", "0.00012000"], ["83917.14000000", "0.08992000"], ["83917.28000000", "0.04800000"], ["83917.41000000", "0.00000000"], ["83917.51000000", "0.32633000"], ["83917.52000000", "0.00000000"], ["83917.61000000", "0.05956000"], ["83917.66000000", "0.00059000"], ["83917.98000000", "0.02383000"], ["83918.23000000", "0.59171000"], ["83918.27000000", "0.04400000"], ["83918.76000000", "0.00059000"], ["83918.83000000", "0.00000000"], ["83918.84000000", "0.00000000"], ["83919.15000000", "0.00000000"], ["83919.96000000", "0.04000000"], ["83920.18000000", "0.00000000"], ["83920.32000000", "0.00059000"], ["83920.55000000", "0.00000000"], ["83920.65000000", "0.00000000"], ["83921.39000000", "0.85835000"], ["83921.53000000", "0.00059000"], ["83921.89000000", "0.00000000"], ["83921.91000000", "0.00000000"], ["83921.94000000", "0.00000000"], ["83922.29000000", "1.05279000"], ["83922.47000000", "0.01191000"], ["83922.98000000", "0.00000000"], ["83923.22000000", "0.00504000"], ["83923.23000000", "0.00000000"], ["83923.27000000", "0.00000000"], ["83923.29000000", "0.00000000"], ["83923.59000000", "0.00000000"], ["83925.01000000", "0.04400000"], ["83925.17000000", "0.00000000"], ["83925.51000000", "0.00000000"], ["83925.60000000", "0.05000000"], ["83925.90000000", "0.71493000"], ["83925.91000000", "0.59623000"], ["83926.00000000", "0.05956000"], ["83926.21000000", "0.00000000"], ["83926.60000000", "0.85830000"], ["83926.77000000", "0.08992000"], ["83926.81000000", "0.89352000"], ["83927.00000000", "0.00000000"], ["83927.20000000", "0.45000000"], ["83928.42000000", "0.00000000"], ["83928.58000000", "0.00058000"], ["83928.95000000", "0.19724000"], ["83929.18000000", "0.00000000"], ["83929.25000000", "0.00000000"], ["83929.27000000", "0.00589000"], ["83929.67000000", "0.00000000"], ["83930.22000000", "0.00000000"], ["83930.93000000", "0.00000000"], ["83932.06000000", "0.35165000"], ["83932.60000000", "0.00000000"], ["83932.68000000", "0.00000000"], ["83933.87000000", "0.00000000"], ["83934.00000000", "0.19733000"], ["83934.29000000", "0.00000000"], ["83934.56000000", "0.01068000"], ["83936.14000000", "0.00000000"], ["83937.47000000", "0.00373000"], ["83937.61000000", "0.00006000"], ["83937.90000000", "0.05088000"], ["83939.31000000", "0.00000000"], ["83941.18000000", "0.00084000"], ["83942.00000000", "0.00500000"], ["83943.73000000", "0.60624000"], ["83943.75000000", "0.00000000"], ["83944.04000000", "0.08992000"], ["83944.27000000", "0.35740000"], ["83944.35000000", "0.00000000"], ["83944.36000000", "0.00000000"], ["83945.63000000", "0.00000000"], ["83945.79000000", "0.00000000"], ["83945.89000000", "0.00822000"], ["83946.89000000", "0.00000000"], ["83947.96000000", "0.12047000"], ["83948.02000000", "0.01090000"], ["83949.68000000", "0.00809000"], ["83949.91000000", "0.00358000"], ["83950.12000000", "0.04655000"], ["83951.44000000", "0.00298000"], ["83952.34000000", "0.02632000"], ["83952.49000000", "0.00000000"], ["83953.28000000", "0.05096000"], ["83953.92000000", "0.00000000"], ["83954.15000000", "0.00000000"], ["83954.33000000", "0.02273000"], ["83956.03000000", "0.04647000"], ["83956.16000000", "0.12144000"], ["83956.37000000", "0.00000000"], ["83958.23000000", "0.00000000"], ["83960.05000000", "0.00000000"], ["83960.28000000", "0.00000000"], ["83960.76000000", "0.02385000"], ["83960.92000000", "0.00000000"], ["83961.06000000", "0.00000000"], ["83961.07000000", "0.00000000"], ["83963.61000000", "0.00000000"], ["83964.33000000", "0.00000000"], ["83971.68000000", "0.00298000"], ["83972.89000000", "0.03197000"], ["83973.37000000", "0.42632000"], ["83973.54000000", "0.05167000"], ["83975.16000000", "0.00000000"], ["83976.43000000", "0.00000000"], ["83976.79000000", "0.00000000"], ["83977.07000000", "0.00000000"], ["83979.39000000", "0.12861000"], ["83980.41000000", "0.00000000"], ["83983.39000000", "0.00000000"], ["83988.04000000", "0.04317000"], ["83988.56000000", "0.01068000"], ["83990.29000000", "0.00000000"], ["83991.21000000", "0.00000000"], ["83992.17000000", "0.00000000"], ["84001.77000000", "0.01090000"], ["84005.66000000", "0.02204000"], ["84013.08000000", "0.04647000"], ["84019.30000000", "0.04647000"], ["84030.89000000", "0.06827000"], ["84038.25000000", "0.00000000"], ["84052.27000000", "0.10162000"], ["84055.07000000", "0.00100000"], ["84055.76000000", "0.00119000"], ["84060.32000000", "0.00701000"], ["84062.93000000", "0.00000000"], ["84063.32000000", "0.00000000"], ["84064.99000000", "0.00000000"], ["84065.83000000", "0.00000000"], ["84076.97000000", "0.02204000"], ["84081.99000000", "0.00000000"], ["84082.69000000", "0.01000000"], ["84142.95000000", "0.00000000"], ["84217.63000000", "0.00000000"], ["84219.00000000", "0.03577000"], ["84230.17000000", "0.00000000"], ["84230.98000000", "0.00384000"], ["84234.36000000", "0.00000000"], ["84236.03000000", "0.00000000"], ["84236.81000000", "0.00000000"], ["84242.75000000", "0.00000000"], ["84244.42000000", "0.00000000"], ["84260.90000000", "0.00000000"], ["84570.96000000", "0.00000000"], ["84933.04000000", "0.00040000"], ["84974.39000000", "0.00060000"], ["85098.75000000", "0.00000000"], ["85140.93000000", "0.00010000"], ["85169.06000000", "0.00000000"]], "record_time": 1742560782.041121, "EXCHANGE": "BINANCE"}
{"e": "depthUpdate", "E": 1742560783014, "s": "BTCUSDT", "U": 64610151547, "u": 64610152126, "b": [["83900.82000000", "3.32518000"], ["83900.81000000", "0.00072000"], ["83900.71000000", "0.00007000"], ["83900.49000000", "0.00014000"], ["83900.48000000", "0.12068000"], ["83900.24000000", "0.00014000"], ["83900.23000000", "0.84822000"], ["83900.22000000", "0.78715000"], ["83900.12000000", "0.00000000"], ["83900.11000000", "0.00000000"], ["83900.02000000", "0.00013000"], ["83900.01000000", "0.00025000"], ["83900.00000000", "1.55685000"], ["83899.76000000", "0.00012000"], ["83898.89000000", "0.05943000"], ["83898.28000000", "0.02432000"], ["83898.23000000", "0.00000000"], ["83898.17000000", "0.00000000"], ["83898.11000000", "0.00000000"], ["83897.30000000", "0.01191000"], ["83897.23000000", "0.02283000"], ["83896.95000000", "0.00000000"], ["83896.87000000", "0.00000000"], ["83896.38000000", "0.01585000"], ["83895.80000000", "0.00006000"], ["83895.79000000", "0.00000000"], ["83895.58000000", "0.00000000"], ["83895.16000000", "0.00000000"], ["83895.08000000", "0.00007000"], ["83893.80000000", "0.00000000"], ["83892.45000000", "0.33648000"], ["83891.61000000", "0.00000000"], ["83888.80000000", "0.04400000"], ["83887.16000000", "0.04000000"], ["83887.14000000", "0.04000000"], ["83887.01000000", "0.04000000"], ["83884.62000000", "0.04000000"], ["83884.49000000", "0.08338000"], ["83883.32000000", "0.10760000"], ["83883.20000000", "0.45000000"], ["83882.96000000", "0.00000000"], ["83882.76000000", "0.01000000"], ["83881.45000000", "0.01191000"], ["83881.27000000", "0.85876000"], ["83879.51000000", "1.00000000"], ["83878.20000000", "0.00219000"], ["83876.96000000", "0.00000000"], ["83876.84000000", "0.00009000"], ["83875.64000000", "0.06256000"], ["83872.79000000", "0.00008000"], ["83871.19000000", "1.31011000"], ["83868.62000000", "1.32368000"], ["83868.40000000", "0.59623000"], ["83867.95000000", "0.00000000"], ["83866.80000000", "0.03895000"], ["83864.69000000", "0.00000000"], ["83858.87000000", "0.00059000"], ["83857.36000000", "0.00000000"], ["83854.99000000", "0.00000000"], ["83853.84000000", "0.05000000"], ["83852.92000000", "0.00000000"], ["83851.07000000", "0.00000000"], ["83842.28000000", "0.00000000"], ["83836.91000000", "0.00061000"], ["83831.38000000", "0.04000000"], ["83823.58000000", "0.86004000"], ["83820.34000000", "0.04000000"], ["83815.93000000", "0.00000000"], ["83815.25000000", "0.00000000"], ["83812.69000000", "0.00144000"], ["83812.34000000", "0.03199000"], ["83811.72000000", "0.00000000"], ["83810.75000000", "1.12755000"], ["83809.86000000", "0.05496000"], ["83805.19000000", "0.63101000"], ["83802.74000000", "0.01196000"], ["83783.05000000", "0.00051000"], ["83745.84000000", "0.00000000"], ["83741.45000000", "0.00400000"], ["83738.95000000", "0.00000000"], ["83736.44000000", "0.00000000"], ["83709.58000000", "0.00000000"], ["83701.12000000", "0.00091000"], ["83696.55000000", "0.00000000"], ["83689.12000000", "0.00042000"], ["83686.55000000", "0.00184000"], ["83662.97000000", "0.00143000"], ["83655.70000000", "0.00000000"], ["83479.66000000", "0.00119000"], ["83272.32000000", "0.00000000"], ["82651.77000000", "0.00000000"], ["82642.30000000", "0.00100000"], ["81383.81000000", "0.00025000"], ["75519.00000000", "0.00000000"], ["75510.00000000", "0.05235000"], ["67120.66000000", "0.00058000"], ["42000.00000000", "6.85161000"], ["33000.00000000", "2.93827000"], ["30204.30000000", "0.00040000"]], "a": [["83900.83000000", "2.65456000"], ["83900.84000000", "0.00048000"], ["83902.64000000", "0.00014000"], ["83902.65000000", "0.78720000"], ["83903.47000000", "0.00007000"], ["83903.83000000", "0.00007000"], ["83903.84000000", "0.02833000"], ["83903.85000000", "0.00007000"], ["83903.99000000", "0.00000000"], ["83904.00000000", "0.02833000"], ["83904.15000000", "0.00000000"], ["83904.41000000", "0.00000000"], ["83904.42000000", "0.02501000"], ["83905.15000000", "0.00000000"], ["83905.16000000", "0.04006000"], ["83905.76000000", "0.00000000"], ["83905.77000000", "0.00000000"], ["83905.82000000", "0.00000000"], ["83905.83000000", "0.75937000"], ["83905.84000000", "0.00000000"], ["83905.85000000", "0.00000000"], ["83905.86000000", "0.00000000"], ["83905.87000000", "1.19811000"], ["83905.88000000", "0.00000000"], ["83906.00000000", "0.02826000"], ["83906.11000000", "0.04201000"], ["83906.45000000", "0.00000000"], ["83907.40000000", "0.00006000"], ["83907.60000000", "0.00006000"], ["83907.67000000", "0.00000000"], ["83908.00000000", "0.02826000"], ["83908.26000000", "0.00000000"], ["83908.59000000", "0.04026000"], ["83908.69000000", "0.00000000"], ["83909.23000000", "0.45300000"], ["83909.42000000", "0.00000000"], ["83910.38000000", "0.37831000"], ["83910.39000000", "0.17822000"], ["83910.40000000", "0.89341000"], ["83910.44000000", "0.00000000"], ["83911.38000000", "0.05943000"], ["83911.93000000", "0.00012000"], ["83912.15000000", "0.00000000"], ["83912.21000000", "0.04000000"], ["83912.33000000", "0.00000000"], ["83912.99000000", "0.00000000"], ["83913.10000000", "0.04000000"], ["83913.90000000", "0.04800000"], ["83913.93000000", "0.04000000"], ["83913.98000000", "0.57014000"], ["83914.01000000", "0.00000000"], ["83914.09000000", "0.04400000"], ["83915.38000000", "0.49506000"], ["83915.56000000", "0.00000000"], ["83915.80000000", "0.08338000"], ["83915.81000000", "1.31405000"], ["83916.42000000", "0.04800000"], ["83917.14000000", "0.00000000"], ["83917.50000000", "0.01191000"], ["83917.66000000", "0.00000000"], ["83918.12000000", "0.04400000"], ["83918.14000000", "0.04400000"], ["83918.23000000", "0.82565000"], ["83918.54000000", "0.35740000"], ["83918.76000000", "0.00000000"], ["83919.84000000", "0.00119000"], ["83919.96000000", "0.00000000"], ["83920.07000000", "0.00000000"], ["83920.32000000", "0.00000000"], ["83920.46000000", "0.59568000"], ["83921.35000000", "0.47654000"], ["83921.53000000", "0.00000000"], ["83922.29000000", "0.00000000"], ["83923.37000000", "0.00000000"], ["83924.21000000", "0.00000000"], ["83924.35000000", "0.00000000"], ["83925.01000000", "0.00000000"], ["83925.03000000", "0.00000000"], ["83925.04000000", "0.00000000"], ["83925.21000000", "0.00000000"], ["83925.91000000", "0.00000000"], ["83925.97000000", "0.00000000"], ["83926.77000000", "0.00000000"], ["83927.01000000", "0.00000000"], ["83927.40000000", "0.05821000"], ["83927.58000000", "0.00000000"], ["83928.58000000", "0.00000000"], ["83929.23000000", "0.00000000"], ["83929.42000000", "0.00000000"], ["83929.59000000", "0.59624000"], ["83933.98000000", "0.00000000"], ["83934.30000000", "0.00000000"], ["83936.32000000", "0.00000000"], ["83936.83000000", "0.00000000"], ["83937.49000000", "0.04800000"], ["83937.90000000", "0.00000000"], ["83942.78000000", "0.00059000"], ["83948.00000000", "0.05088000"], ["83948.61000000", "0.00000000"], ["83950.12000000", "0.00000000"], ["83953.27000000", "0.06890000"], ["83960.76000000", "0.00000000"], ["83961.47000000", "0.47654000"], ["83962.13000000", "0.06386000"], ["83962.98000000", "0.59568000"], ["83966.46000000", "1.12545000"], ["83972.64000000", "0.04400000"], ["83976.18000000", "0.02385000"], ["83976.99000000", "0.39587000"], ["83977.00000000", "0.00000000"], ["83980.03000000", "0.00000000"], ["84004.56000000", "0.00060000"], ["84012.12000000", "0.00000000"], ["84076.96000000", "0.99298000"], ["84080.48000000", "0.00000000"], ["84080.58000000", "0.00000000"], ["84080.68000000", "0.01000000"], ["84082.69000000", "0.00000000"], ["84088.27000000", "0.00000000"], ["84140.13000000", "0.00000000"], ["85159.35000000", "0.00206000"]], "record_time": 1742560783.039357, "EXCHANGE": "BINANCE"}
{"e": "depthUpdate", "E": 1742560784014, "s": "BTCUSDT", "U": 64610152127, "u": 64610152319, "b": [["83900.82000000", "3.30974000"], ["83900.81000000", "0.12039000"], ["83900.80000000", "0.00007000"], ["83900.71000000", "0.00007000"], ["83900.54000000", "0.00007000"], ["83900.52000000", "0.00007000"], ["83900.49000000", "0.00007000"], ["83900.48000000", "0.00007000"], ["83900.24000000", "0.00007000"], ["83900.23000000", "0.84815000"], ["83900.00000000", "1.55667000"], ["83898.89000000", "0.05943000"], ["83898.00000000", "0.00000000"], ["83897.90000000", "0.00000000"], ["83896.60000000", "0.00000000"], ["83891.61000000", "0.00012000"], ["83890.80000000", "0.00000000"], ["83889.83000000", "0.00059000"], ["83888.00000000", "0.00356000"], ["83887.90000000", "0.00000000"], ["83885.40000000", "0.00000000"], ["83874.67000000", "0.00896000"], ["83871.08000000", "1.36264000"], ["83868.62000000", "0.00000000"], ["83866.80000000", "0.00000000"], ["83862.55000000", "0.12459000"], ["83857.29000000", "0.03895000"], ["83855.49000000", "0.00000000"], ["83853.84000000", "0.00000000"], ["83816.74000000", "0.03578000"], ["83783.05000000", "0.00000000"], ["83777.97000000", "0.00051000"], ["83756.37000000", "0.00400000"], ["83749.71000000", "0.00000000"], ["83741.45000000", "0.00000000"], ["83732.96000000", "0.05963000"], ["83701.13000000", "0.00042000"], ["83689.12000000", "0.00000000"], ["83267.26000000", "0.00079000"], ["82961.52000000", "0.00000000"], ["82677.95000000", "0.00285000"], ["82642.30000000", "0.00000000"], ["75510.00000000", "0.05235000"], ["67120.66000000", "0.00058000"], ["33000.00000000", "2.93827000"], ["30204.30000000", "0.00060000"]], "a": [["83900.83000000", "2.73006000"], ["83900.84000000", "0.00048000"], ["83902.63000000", "0.00014000"], ["83902.64000000", "0.26457000"], ["83902.65000000", "0.78720000"], ["83902.66000000", "0.00014000"], ["83903.47000000", "0.00007000"], ["83903.70000000", "0.00000000"], ["83903.83000000", "0.00007000"], ["83903.84000000", "0.00000000"], ["83903.85000000", "0.00000000"], ["83905.83000000", "0.45708000"], ["83906.00000000", "0.02826000"], ["83906.06000000", "0.01823000"], ["83908.59000000", "0.04020000"], ["83909.23000000", "0.45300000"], ["83913.72000000", "0.00000000"], ["83913.80000000", "0.00000000"], ["83913.98000000", "0.70771000"], ["83915.81000000", "0.00000000"], ["83915.83000000", "1.33149000"], ["83917.61000000", "0.00000000"], ["83919.59000000", "0.05000000"], ["83922.66000000", "0.77543000"], ["83925.60000000", "0.00000000"], ["83926.00000000", "0.11912000"], ["83942.00000000", "0.00500000"], ["83961.39000000", "0.72331000"], ["83978.70000000", "0.00000000"], ["84041.30000000", "0.00000000"], ["84042.50000000", "0.00844000"], ["84043.96000000", "0.00000000"], ["84051.40000000", "0.00000000"], ["84054.57000000", "0.00000000"], ["84079.78000000", "0.00000000"], ["84080.28000000", "0.01000000"], ["84080.68000000", "0.00000000"], ["84537.44000000", "0.05963000"], ["84933.04000000", "0.00000000"], ["84933.11000000", "0.00040000"], ["84974.39000000", "0.00000000"], ["84974.49000000", "0.00060000"], ["85138.60000000", "0.00284000"], ["85159.35000000", "0.00106000"], ["85431.72000000", "0.00000000"], ["86521.90000000", "0.00000000"]], "record_time": 1742560784.038674, "EXCHANGE": "BINANCE"}
{"e": "depthUpdate", "E": 1742561032014, "s": "BTCUSDT", "U": 64610509383, "u": 64610511812, "b": [["83711.99000000", "5.74978000"], ["83711.98000000", "0.00048000"], ["83711.83000000", "0.00021000"], ["83711.82000000", "0.17180000"], ["83711.81000000", "0.00021000"], ["83711.80000000", "0.45007000"], ["83711.62000000", "0.00007000"], ["83711.56000000", "0.00013000"], ["83711.14000000", "0.00007000"], ["83710.80000000", "0.00000000"], ["83710.00000000", "0.02826000"], ["83709.99000000", "0.00000000"], ["83709.98000000", "0.00000000"], ["83709.43000000", "0.00000000"], ["83708.82000000", "0.00000000"], ["83708.62000000", "0.00000000"], ["83708.47000000", "0.00000000"], ["83708.04000000", "0.02314000"], ["83707.99000000", "0.00000000"], ["83707.98000000", "0.00000000"], ["83707.97000000", "0.02794000"], ["83707.81000000", "0.00485000"], ["83707.74000000", "0.02407000"], ["83707.63000000", "0.00000000"], ["83707.62000000", "0.00006000"], ["83707.61000000", "0.00000000"], ["83707.59000000", "0.00000000"], ["83706.95000000", "0.00000000"], ["83706.92000000", "0.00000000"], ["83706.05000000", "0.00000000"], ["83706.04000000", "0.42205000"], ["83706.03000000", "0.71600000"], ["83706.02000000", "0.00000000"], ["83706.01000000", "0.00000000"], ["83706.00000000", "0.02826000"], ["83705.99000000", "0.00000000"], ["83705.82000000", "0.00000000"], ["83705.73000000", "0.00000000"], ["83705.72000000", "0.00006000"], ["83705.62000000", "0.00000000"], ["83705.29000000", "0.00000000"], ["83705.28000000", "0.00000000"], ["83704.49000000", "0.00000000"], ["83704.38000000", "0.00000000"], ["83704.37000000", "0.07097000"], ["83704.21000000", "0.00000000"], ["83704.10000000", "0.00000000"], ["83704.09000000", "0.00000000"], ["83703.99000000", "0.00000000"], ["83703.98000000", "0.00000000"], ["83703.96000000", "0.04000000"], ["83703.84000000", "0.00000000"], ["83703.83000000", "0.00000000"], ["83703.78000000", "0.00000000"], ["83703.71000000", "0.00000000"], ["83703.69000000", "0.00410000"], ["83703.68000000", "0.45165000"], ["83703.67000000", "0.00000000"], ["83703.65000000", "0.01500000"], ["83703.61000000", "0.00300000"], ["83703.37000000", "0.17947000"], ["83703.36000000", "0.00000000"], ["83703.35000000", "0.00000000"], ["83703.34000000", "0.00000000"], ["83703.33000000", "0.00000000"], ["83703.21000000", "0.00000000"], ["83703.19000000", "0.00201000"], ["83703.12000000", "0.04000000"], ["83702.70000000", "0.00000000"], ["83702.58000000", "0.00119000"], ["83702.45000000", "0.00000000"], ["83702.39000000", "0.01500000"], ["83702.38000000", "0.00009000"], ["83702.28000000", "0.08000000"], ["83702.14000000", "0.04000000"], ["83702.13000000", "0.00000000"], ["83702.00000000", "0.05209000"], ["83701.80000000", "0.00006000"], ["83701.54000000", "0.00013000"], ["83701.37000000", "0.00898000"], ["83701.26000000", "0.00007000"], ["83701.25000000", "0.00090000"], ["83701.14000000", "0.00000000"], ["83700.96000000", "0.00095000"], ["83700.81000000", "0.00000000"], ["83700.73000000", "0.00000000"], ["83700.42000000", "0.00000000"], ["83700.10000000", "0.05094000"], ["83700.02000000", "0.51832000"], ["83700.01000000", "0.71594000"], ["83700.00000000", "0.70763000"], ["83699.99000000", "0.00000000"], ["83699.80000000", "0.02000000"], ["83699.78000000", "0.04000000"], ["83699.74000000", "0.00000000"], ["83699.53000000", "0.00065000"], ["83699.52000000", "0.04206000"], ["83699.51000000", "0.34861000"], ["83699.35000000", "0.00020000"], ["83699.30000000", "0.00000000"], ["83699.25000000", "0.00000000"], ["83699.19000000", "0.00133000"], ["83699.05000000", "0.01761000"], ["83698.93000000", "0.04000000"], ["83698.74000000", "0.02389000"], ["83698.72000000", "0.00000000"], ["83698.64000000", "0.00000000"], ["83698.50000000", "0.04000000"], ["83698.14000000", "0.19868000"], ["83698.13000000", "0.00000000"], ["83698.12000000", "0.00000000"], ["83698.10000000", "0.04000000"], ["83698.09000000", "0.04000000"], ["83697.95000000", "0.04000000"], ["83697.86000000", "0.00000000"], ["83697.81000000", "0.02389000"], ["83697.17000000", "0.00013000"], ["83697.07000000", "0.02389000"], ["83696.30000000", "0.00007000"], ["83696.29000000", "0.02342000"], ["83696.16000000", "0.00000000"], ["83696.09000000", "0.00119000"], ["83695.82000000", "0.00000000"], ["83695.80000000", "0.31403000"], ["83695.30000000", "0.00000000"], ["83695.23000000", "0.05960000"], ["83695.15000000", "0.00000000"], ["83695.14000000", "0.00000000"], ["83695.08000000", "0.00000000"], ["83694.77000000", "0.76633000"], ["83694.76000000", "1.33587000"], ["83694.67000000", "0.00000000"], ["83694.57000000", "0.00000000"], ["83694.37000000", "0.00000000"], ["83694.26000000", "0.11531000"], ["83694.23000000", "0.01194000"], ["83693.95000000", "0.08338000"], ["83693.94000000", "0.71609000"], ["83693.93000000", "0.01000000"], ["83693.89000000", "0.00000000"], ["83693.83000000", "0.00000000"], ["83693.74000000", "0.02389000"], ["83693.44000000", "0.05973000"], ["83693.41000000", "0.00000000"], ["83693.12000000", "0.00000000"], ["83692.73000000", "0.00000000"], ["83692.72000000", "0.05973000"], ["83692.69000000", "0.00000000"], ["83692.65000000", "0.00000000"], ["83692.63000000", "0.00000000"], ["83692.42000000", "0.02986000"], ["83692.33000000", "0.00000000"], ["83692.01000000", "0.00000000"], ["83691.92000000", "0.00000000"], ["83691.18000000", "0.00016000"], ["83691.17000000", "0.00000000"], ["83691.14000000", "0.00000000"], ["83690.87000000", "0.00000000"], ["83690.57000000", "0.00013000"], ["83690.46000000", "0.00007000"], ["83690.33000000", "0.86072000"], ["83690.19000000", "0.00000000"], ["83689.87000000", "0.00358000"], ["83689.69000000", "0.08000000"], ["83689.61000000", "0.05973000"], ["83689.39000000", "0.02389000"], ["83689.35000000", "0.00000000"], ["83689.11000000", "0.00000000"], ["83688.43000000", "0.00006000"], ["83688.30000000", "0.00000000"], ["83687.85000000", "0.11946000"], ["83687.66000000", "0.00000000"], ["83687.37000000", "0.59753000"], ["83687.36000000", "0.35761000"], ["83687.20000000", "0.00000000"], ["83686.93000000", "0.11920000"], ["83686.68000000", "0.00000000"], ["83686.42000000", "0.00000000"], ["83685.92000000", "0.05973000"], ["83685.73000000", "0.80142000"], ["83685.72000000", "0.86077000"], ["83685.23000000", "0.00033000"], ["83685.22000000", "0.00000000"], ["83684.84000000", "0.00000000"], ["83684.66000000", "0.86078000"], ["83684.50000000", "0.00000000"], ["83684.34000000", "0.00000000"], ["83684.33000000", "0.00000000"], ["83684.26000000", "0.00000000"], ["83684.24000000", "0.00141000"], ["83683.87000000", "0.00100000"], ["83683.60000000", "0.05975000"], ["83682.98000000", "0.04000000"], ["83682.89000000", "0.00597000"], ["83682.58000000", "0.00000000"], ["83682.55000000", "0.00000000"], ["83682.43000000", "0.11976000"], ["83682.15000000", "0.03445000"], ["83682.11000000", "0.00000000"], ["83681.31000000", "0.00000000"], ["83681.30000000", "0.04000000"], ["83681.16000000", "0.04000000"], ["83681.10000000", "0.00000000"], ["83680.48000000", "0.05973000"], ["83680.09000000", "0.00000000"], ["83680.06000000", "0.00000000"], ["83679.55000000", "0.00000000"], ["83679.04000000", "0.05973000"], ["83678.79000000", "0.04000000"], ["83678.68000000", "0.08992000"], ["83678.56000000", "0.00000000"], ["83678.40000000", "0.00000000"], ["83678.37000000", "0.00000000"], ["83678.36000000", "0.00000000"], ["83678.07000000", "0.02986000"], ["83677.49000000", "0.05973000"], ["83677.19000000", "0.00000000"], ["83677.12000000", "0.04009000"], ["83677.10000000", "0.04000000"], ["83676.49000000", "0.00214000"], ["83676.48000000", "0.24081000"], ["83676.03000000", "0.00000000"], ["83675.05000000", "0.01531000"], ["83675.01000000", "0.05973000"], ["83673.69000000", "0.00000000"], ["83673.17000000", "0.00000000"], ["83672.83000000", "0.05746000"], ["83671.53000000", "0.00490000"], ["83670.62000000", "0.00013000"], ["83670.49000000", "0.00000000"], ["83670.04000000", "0.01732000"], ["83669.16000000", "0.00000000"], ["83668.00000000", "0.02262000"], ["83667.89000000", "0.00000000"], ["83667.71000000", "0.00000000"], ["83667.66000000", "0.00000000"], ["83667.55000000", "0.00000000"], ["83666.88000000", "0.00000000"], ["83664.64000000", "0.11946000"], ["83663.93000000", "0.45597000"], ["83662.51000000", "0.00000000"], ["83661.05000000", "0.04460000"], ["83660.72000000", "0.00022000"], ["83659.51000000", "0.35761000"], ["83659.07000000", "0.00813000"], ["83657.89000000", "0.00821000"], ["83655.44000000", "0.00000000"], ["83653.41000000", "0.00000000"], ["83652.67000000", "0.00849000"], ["83650.19000000", "0.04469000"], ["83650.16000000", "0.03593000"], ["83649.59000000", "0.00061000"], ["83647.64000000", "0.00000000"], ["83645.52000000", "0.00000000"], ["83643.62000000", "0.04000000"], ["83642.95000000", "0.00000000"], ["83642.65000000", "0.00000000"], ["83642.19000000", "0.00000000"], ["83641.36000000", "0.05973000"], ["83640.23000000", "0.05973000"], ["83639.90000000", "0.00000000"], ["83639.09000000", "0.00000000"], ["83638.77000000", "0.70594000"], ["83638.07000000", "0.00000000"], ["83636.94000000", "0.00000000"], ["83636.86000000", "0.00000000"], ["83636.04000000", "0.00000000"], ["83635.48000000", "0.00000000"], ["83634.44000000", "0.00298000"], ["83634.17000000", "0.96327000"], ["83633.44000000", "0.00000000"], ["83632.93000000", "0.05973000"], ["83631.31000000", "0.00000000"], ["83627.32000000", "0.00000000"], ["83626.35000000", "0.04000000"], ["83625.73000000", "0.01196000"], ["83625.22000000", "0.00000000"], ["83622.71000000", "0.00214000"], ["83621.92000000", "0.00000000"], ["83621.38000000", "0.00000000"], ["83617.50000000", "0.00000000"], ["83616.83000000", "0.00000000"], ["83612.64000000", "0.00000000"], ["83610.81000000", "0.00230000"], ["83597.97000000", "0.05588000"], ["83595.52000000", "0.00400000"], ["83588.44000000", "0.00000000"], ["83564.30000000", "0.00000000"], ["83551.49000000", "0.00024000"], ["83551.39000000", "0.00000000"], ["83550.21000000", "0.00000000"], ["83542.88000000", "0.00000000"], ["83540.89000000", "0.00119000"], ["83540.88000000", "0.00000000"], ["83534.11000000", "0.00316000"], ["83534.10000000", "0.00000000"], ["83522.40000000", "0.00000000"], ["83510.51000000", "0.00168000"], ["83510.50000000", "0.00000000"], ["83492.32000000", "0.00000000"], ["83473.16000000", "0.00000000"], ["83469.79000000", "0.00000000"], ["83469.64000000", "0.00000000"], ["83467.51000000", "0.00000000"], ["83466.96000000", "0.00000000"], ["83466.10000000", "0.20003000"], ["83464.79000000", "0.00000000"], ["83460.13000000", "0.00000000"], ["83457.73000000", "0.20003000"], ["83449.37000000", "0.01226000"], ["82448.12000000", "0.00000000"], ["80330.66000000", "0.00047000"], ["75340.00000000", "0.00000000"], ["75339.01000000", "0.00000000"], ["75339.00000000", "0.01979000"], ["75332.00000000", "0.00433000"], ["66969.61000000", "0.00000000"], ["66969.60000000", "0.00058000"], ["66962.95000000", "0.00000000"], ["50001.00000000", "1.81927000"], ["33000.00000000", "2.93827000"], ["30136.32000000", "0.00020000"]], "a": [["83703.69000000", "0.00000000"], ["83703.70000000", "0.00000000"], ["83703.72000000", "0.00000000"], ["83703.79000000", "0.00000000"], ["83703.84000000", "0.00000000"], ["83703.85000000", "0.00000000"], ["83703.99000000", "0.00000000"], ["83704.00000000", "0.00000000"], ["83704.38000000", "0.00000000"], ["83704.85000000", "0.00000000"], ["83704.86000000", "0.00000000"], ["83705.29000000", "0.00000000"], ["83705.30000000", "0.00000000"], ["83705.63000000", "0.00000000"], ["83705.81000000", "0.00000000"], ["83705.82000000", "0.00000000"], ["83705.99000000", "0.00000000"], ["83706.00000000", "0.00000000"], ["83706.02000000", "0.00000000"], ["83706.06000000", "0.00000000"], ["83707.22000000", "0.00000000"], ["83707.59000000", "0.00000000"], ["83707.60000000", "0.00000000"], ["83707.62000000", "0.00000000"], ["83707.63000000", "0.00000000"], ["83707.75000000", "0.00000000"], ["83707.99000000", "0.00000000"], ["83708.00000000", "0.00000000"], ["83708.02000000", "0.00000000"], ["83708.03000000", "0.00000000"], ["83708.48000000", "0.00000000"], ["83708.82000000", "0.00000000"], ["83708.83000000", "0.00000000"], ["83709.44000000", "0.00000000"], ["83709.66000000", "0.00000000"], ["83709.99000000", "0.00000000"], ["83710.00000000", "0.00000000"], ["83710.15000000", "0.00000000"], ["83710.68000000", "0.00000000"], ["83710.76000000", "0.00000000"], ["83710.77000000", "0.00000000"], ["83710.78000000", "0.00000000"], ["83710.81000000", "0.00000000"], ["83711.13000000", "0.00000000"], ["83711.29000000", "0.00000000"], ["83711.63000000", "0.00000000"], ["83711.98000000", "0.00000000"], ["83711.99000000", "0.00000000"], ["83712.00000000", "2.49661000"], ["83712.01000000", "0.00077000"], ["83712.06000000", "0.00043000"], ["83712.07000000", "0.00007000"], ["83712.13000000", "0.00000000"], ["83712.16000000", "0.00007000"], ["83712.17000000", "0.00007000"], ["83712.32000000", "0.00007000"], ["83712.33000000", "0.00007000"], ["83712.40000000", "0.00000000"], ["83712.68000000", "0.00000000"], ["83712.81000000", "0.00000000"], ["83712.99000000", "0.00000000"], ["83713.00000000", "0.00000000"], ["83713.01000000", "0.00000000"], ["83713.16000000", "0.00000000"], ["83713.17000000", "0.00000000"], ["83713.28000000", "0.00000000"], ["83713.48000000", "0.00336000"], ["83713.66000000", "0.00007000"], ["83713.82000000", "0.00000000"], ["83713.84000000", "0.00000000"], ["83713.85000000", "0.00000000"], ["83713.92000000", "0.00000000"], ["83713.95000000", "0.00014000"], ["83713.96000000", "0.01504000"], ["83713.97000000", "0.00000000"], ["83713.98000000", "0.00000000"], ["83713.99000000", "0.00021000"], ["83714.00000000", "0.02827000"], ["83714.14000000", "0.00000000"], ["83714.15000000", "0.00000000"], ["83714.39000000", "0.00000000"], ["83714.40000000", "0.00000000"], ["83714.74000000", "0.00000000"], ["83714.75000000", "0.00000000"], ["83714.76000000", "0.00000000"], ["83714.77000000", "0.00000000"], ["83715.08000000", "0.00000000"], ["83715.17000000", "0.00000000"], ["83715.21000000", "0.00000000"], ["83715.22000000", "0.00000000"], ["83715.31000000", "0.00000000"], ["83715.38000000", "0.00000000"], ["83715.47000000", "0.00000000"], ["83715.59000000", "0.00000000"], ["83715.74000000", "0.00000000"], ["83715.75000000", "0.00000000"], ["83715.94000000", "0.00021000"], ["83715.95000000", "0.02479000"], ["83715.99000000", "0.00014000"], ["83716.00000000", "0.02827000"], ["83716.02000000", "0.00000000"], ["83716.03000000", "0.00000000"], ["83716.26000000", "0.00000000"], ["83716.27000000", "0.00000000"], ["83716.32000000", "0.00000000"], ["83716.34000000", "0.00000000"], ["83716.71000000", "0.00000000"], ["83716.73000000", "0.00000000"], ["83717.07000000", "0.00000000"], ["83717.08000000", "0.00000000"], ["83717.11000000", "0.00000000"], ["83717.12000000", "0.00000000"], ["83717.19000000", "0.00000000"], ["83717.37000000", "0.00007000"], ["83717.38000000", "0.37798000"], ["83717.39000000", "0.78874000"], ["83717.61000000", "0.00000000"], ["83717.87000000", "0.00000000"], ["83717.91000000", "0.00000000"], ["83717.99000000", "0.00000000"], ["83718.00000000", "0.02820000"], ["83718.20000000", "0.00000000"], ["83718.23000000", "0.00000000"], ["83718.24000000", "0.00000000"], ["83718.34000000", "0.00000000"], ["83718.46000000", "0.00000000"], ["83718.52000000", "0.00000000"], ["83718.60000000", "0.00000000"], ["83718.84000000", "0.00000000"], ["83718.87000000", "0.00000000"], ["83718.99000000", "0.00000000"], ["83719.04000000", "0.00000000"], ["83719.14000000", "0.00000000"], ["83719.17000000", "0.00000000"], ["83719.19000000", "0.00000000"], ["83719.22000000", "0.00000000"], ["83719.23000000", "0.00000000"], ["83719.24000000", "0.00000000"], ["83719.26000000", "0.00756000"], ["83719.29000000", "0.00000000"], ["83719.88000000", "0.11951000"], ["83720.00000000", "0.02844000"], ["83720.38000000", "0.00000000"], ["83720.39000000", "0.00029000"], ["83720.40000000", "0.00000000"], ["83720.44000000", "0.00000000"], ["83720.45000000", "0.00000000"], ["83720.47000000", "0.00000000"], ["83720.59000000", "0.00000000"], ["83720.72000000", "0.11951000"], ["83720.86000000", "0.00000000"], ["83721.02000000", "0.00000000"], ["83721.03000000", "0.00000000"], ["83721.34000000", "0.00007000"], ["83721.39000000", "0.00000000"], ["83721.45000000", "0.11951000"], ["83721.59000000", "0.00119000"], ["83721.60000000", "0.57201000"], ["83721.61000000", "0.00000000"], ["83722.15000000", "0.00000000"], ["83722.24000000", "0.00000000"], ["83722.26000000", "0.00000000"], ["83722.29000000", "0.11951000"], ["83722.66000000", "0.00000000"], ["83723.04000000", "0.00000000"], ["83723.06000000", "0.00091000"], ["83723.34000000", "0.00000000"], ["83723.35000000", "0.00000000"], ["83723.37000000", "0.00000000"], ["83723.66000000", "0.00000000"], ["83723.82000000", "0.04000000"], ["83723.87000000", "0.00000000"], ["83724.79000000", "0.04000000"], ["83724.85000000", "0.00000000"], ["83724.86000000", "0.00000000"], ["83725.06000000", "0.00000000"], ["83725.09000000", "0.00000000"], ["83725.10000000", "0.00000000"], ["83725.48000000", "0.04000000"], ["83725.50000000", "0.04000000"], ["83725.61000000", "0.04400000"], ["83725.87000000", "0.00000000"], ["83725.92000000", "0.00000000"], ["83726.41000000", "0.00000000"], ["83726.61000000", "0.89402000"], ["83726.85000000", "0.00877000"], ["83727.17000000", "0.00000000"], ["83727.23000000", "0.00000000"], ["83727.41000000", "0.00000000"], ["83727.73000000", "0.35761000"], ["83727.87000000", "0.00000000"], ["83728.01000000", "0.04800000"], ["83728.32000000", "0.00420000"], ["83728.47000000", "0.00119000"], ["83728.49000000", "0.00000000"], ["83728.68000000", "0.00000000"], ["83728.71000000", "0.00000000"], ["83728.83000000", "0.00000000"], ["83728.96000000", "0.00000000"], ["83728.99000000", "0.04800000"], ["83729.16000000", "0.54726000"], ["83729.31000000", "0.00000000"], ["83729.47000000", "0.00000000"], ["83729.58000000", "0.00000000"], ["83729.66000000", "0.04800000"], ["83729.67000000", "0.04800000"], ["83729.68000000", "0.00000000"], ["83729.77000000", "0.04000000"], ["83729.92000000", "0.00000000"], ["83729.95000000", "0.04400000"], ["83730.64000000", "0.00000000"], ["83730.72000000", "0.00012000"], ["83730.97000000", "0.00000000"], ["83731.02000000", "0.00000000"], ["83731.58000000", "0.00000000"], ["83731.62000000", "0.00000000"], ["83731.84000000", "0.00000000"], ["83731.96000000", "0.00000000"], ["83732.18000000", "0.00000000"], ["83732.28000000", "0.00000000"], ["83732.29000000", "0.00000000"], ["83732.74000000", "0.00000000"], ["83732.81000000", "0.90911000"], ["83732.84000000", "0.00000000"], ["83733.12000000", "0.00000000"], ["83733.22000000", "0.00000000"], ["83733.68000000", "0.01195000"], ["83733.88000000", "0.00000000"], ["83734.02000000", "0.00000000"], ["83734.42000000", "0.00000000"], ["83734.57000000", "0.71594000"], ["83734.58000000", "1.35962000"], ["83734.75000000", "0.00007000"], ["83734.92000000", "0.00000000"], ["83734.98000000", "0.20862000"], ["83735.24000000", "0.00000000"], ["83735.38000000", "0.00000000"], ["83735.77000000", "0.00000000"], ["83735.78000000", "0.00000000"], ["83735.88000000", "0.00000000"], ["83736.15000000", "0.00000000"], ["83736.22000000", "0.00000000"], ["83736.28000000", "0.00000000"], ["83736.30000000", "0.01194000"], ["83736.38000000", "1.00000000"], ["83736.62000000", "0.01000000"], ["83736.63000000", "0.00000000"], ["83736.64000000", "0.00000000"], ["83736.68000000", "0.00000000"], ["83736.90000000", "0.89402000"], ["83737.11000000", "0.11920000"], ["83737.12000000", "0.00300000"], ["83737.18000000", "0.00000000"], ["83737.22000000", "0.00500000"], ["83737.75000000", "0.89402000"], ["83737.78000000", "0.00000000"], ["83737.94000000", "0.02372000"], ["83738.25000000", "0.00000000"], ["83738.48000000", "0.00000000"], ["83738.66000000", "0.17207000"], ["83738.88000000", "0.01000000"], ["83739.05000000", "0.00000000"], ["83739.31000000", "0.00000000"], ["83739.48000000", "0.00500000"], ["83739.66000000", "0.71594000"], ["83739.67000000", "0.89402000"], ["83739.88000000", "0.00000000"], ["83740.14000000", "0.00000000"], ["83740.27000000", "0.26872000"], ["83740.35000000", "0.00000000"], ["83740.69000000", "1.31020000"], ["83741.74000000", "0.00000000"], ["83741.75000000", "0.00000000"], ["83742.88000000", "0.27190000"], ["83743.17000000", "0.89402000"], ["83743.18000000", "0.17207000"], ["83743.31000000", "0.00898000"], ["83743.48000000", "0.00000000"], ["83744.32000000", "0.00000000"], ["83744.48000000", "0.00000000"], ["83744.54000000", "0.00000000"], ["83744.73000000", "0.00000000"], ["83744.91000000", "0.71607000"], ["83744.99000000", "0.86016000"], ["83745.38000000", "0.00000000"], ["83745.42000000", "0.00000000"], ["83745.82000000", "0.00084000"], ["83746.39000000", "0.00000000"], ["83746.49000000", "0.00000000"], ["83746.93000000", "0.00000000"], ["83746.95000000", "0.01196000"], ["83746.99000000", "0.00000000"], ["83747.90000000", "0.00000000"], ["83749.29000000", "0.06000000"], ["83749.39000000", "0.00000000"], ["83749.72000000", "0.00000000"], ["83749.96000000", "0.04800000"], ["83749.98000000", "0.00000000"], ["83749.99000000", "0.08000000"], ["83750.03000000", "1.18715000"], ["83750.04000000", "0.86011000"], ["83750.64000000", "0.04800000"], ["83750.79000000", "0.04800000"], ["83751.01000000", "0.00000000"], ["83751.03000000", "0.00000000"], ["83751.09000000", "0.00000000"], ["83751.20000000", "0.00500000"], ["83751.25000000", "0.00000000"], ["83752.49000000", "0.00000000"], ["83753.53000000", "0.00000000"], ["83753.69000000", "0.86007000"], ["83753.91000000", "0.00013000"], ["83753.92000000", "0.00000000"], ["83755.08000000", "0.00016000"], ["83755.76000000", "0.04000000"], ["83756.43000000", "0.00000000"], ["83756.54000000", "0.00297000"], ["83756.55000000", "0.05772000"], ["83757.07000000", "0.00000000"], ["83757.53000000", "0.16000000"], ["83759.62000000", "0.00813000"], ["83760.66000000", "0.00000000"], ["83761.64000000", "0.00811000"], ["83762.47000000", "0.59747000"], ["83766.17000000", "0.11947000"], ["83767.47000000", "0.00000000"], ["83768.16000000", "0.00816000"], ["83768.26000000", "0.00000000"], ["83768.37000000", "0.00000000"], ["83768.77000000", "0.34640000"], ["83770.65000000", "0.47681000"], ["83775.40000000", "0.59601000"], ["83778.38000000", "0.00000000"], ["83781.07000000", "0.00297000"], ["83782.35000000", "0.00000000"], ["83782.50000000", "0.04081000"], ["83786.70000000", "0.04062000"], ["83788.61000000", "0.00699000"], ["83790.22000000", "0.00000000"], ["83792.02000000", "0.00000000"], ["83793.78000000", "0.04777000"], ["83794.17000000", "0.00000000"], ["83794.63000000", "0.04800000"], ["83795.71000000", "0.00000000"], ["83796.04000000", "0.00000000"], ["83796.89000000", "0.31033000"], ["83797.70000000", "0.00000000"], ["83797.88000000", "0.00000000"], ["83799.16000000", "0.00000000"], ["83800.00000000", "0.03801000"], ["83800.12000000", "0.00041000"], ["83800.24000000", "0.00000000"], ["83800.59000000", "0.00084000"], ["83800.96000000", "0.20423000"], ["83801.64000000", "0.00000000"], ["83801.97000000", "0.04778000"], ["83804.00000000", "0.00210000"], ["83806.95000000", "0.00000000"], ["83811.56000000", "0.00060000"], ["83811.81000000", "0.00000000"], ["83814.75000000", "0.00000000"], ["83815.61000000", "0.00000000"], ["83828.59000000", "0.00000000"], ["83828.68000000", "0.00000000"], ["83830.82000000", "0.12784000"], ["83831.21000000", "0.12827000"], ["83832.55000000", "0.00000000"], ["83837.74000000", "0.00000000"], ["83838.00000000", "0.00013000"], ["83839.87000000", "0.00119000"], ["83841.07000000", "0.13948000"], ["83850.96000000", "0.00000000"], ["83851.89000000", "0.00000000"], ["83864.27000000", "0.00119000"], ["83875.46000000", "0.00035000"], ["83875.98000000", "0.00000000"], ["83881.79000000", "0.00000000"], ["83885.30000000", "0.00050000"], ["83885.95000000", "0.00000000"], ["83894.48000000", "0.00000000"], ["83905.45000000", "0.00000000"], ["83934.06000000", "0.00013000"], ["83938.24000000", "0.00013000"], ["84002.91000000", "0.45000000"], ["84010.81000000", "0.20003000"], ["84033.22000000", "0.00000000"], ["84033.27000000", "0.00000000"], ["84035.61000000", "0.07547000"], ["84041.59000000", "0.00000000"], ["84549.10000000", "0.00000000"], ["84948.40000000", "0.00000000"], ["84961.12000000", "0.00000000"], ["84969.60000000", "0.11787000"], ["84990.80000000", "0.00000000"]], "record_time": 1742561032.178328, "EXCHANGE": "BINANCE"}
